File: 01_Data/Cinder_Block/STA/N2/3K_min/Cinder_Block_STA_N2_3KData_230828_R1.csv
##Temp./Â°C,Time/min,DSC/(mW/mg),Mass loss/mg
29.0,16.39389785399906,0.010442873410790199,-0.0014419785417896236
30.40000000000002,17.0729755481815,0.02010796492765543,-0.002276355386251261
31.80000000000004,17.648095454604444,0.02218611234908696,-0.004280955501253736
33.20000000000006,18.206123041902686,0.025585601133359503,-0.0022743222496393045
34.60000000000008,18.74102339040221,0.030864736973480245,-0.004994567297909036
36.0000000000001,19.255117233145537,0.028194070781841774,-0.003528092290368434
37.40000000000012,19.76855096276049,0.030615580266663667,-0.004944241557155671
38.80000000000014,20.26687485599262,0.033300372560126856,-0.00415292438046766
40.20000000000016,20.761640147067816,0.03508773139045207,-0.006671387968602005
41.60000000000018,21.24997340553345,0.03641180557524493,-0.007239002671498795
43.0000000000002,21.74056339748872,0.03611050897699375,-0.006581113911566128
44.40000000000022,22.222809750599737,0.03670972614035284,-0.007238164267727498
45.80000000000024,22.704697001065743,0.03649297507319815,-0.008559949996846505
47.20000000000026,23.18109586174584,0.03574701527743729,-0.008550064556181347
48.60000000000028,23.655296508559992,0.03443901060322396,-0.009879879786498513
50.0000000000003,24.133626238102543,0.03441990099121828,-0.011177497658964697
51.40000000000032,24.604533076163946,0.03140357755755829,-0.00988155637102306
52.80000000000034,25.082302329381985,0.02951085180416202,-0.010537743350664819
54.20000000000036,25.55394966900576,0.0283923872001135,-0.012510019987385768
55.60000000000038,26.0184621086988,0.027091422539667676,-0.012854448662870332
57.0000000000004,26.502623010607046,0.026971754302262507,-0.012322783887212196
58.40000000000042,26.9745198970204,0.025990216899662855,-0.012760946265869322
59.80000000000044,27.445837540857756,0.023723117346362788,-0.013481234548025078
61.20000000000046,27.917014700232027,0.02300946495372802,-0.01552275095191824
62.60000000000048,28.384899985115197,0.023689581498706147,-0.015441019283876756
64.0000000000005,28.85674431849774,0.02340373215015923,-0.014497800962994134
65.40000000000052,29.324709149528413,0.022235768530594058,-0.01613989500742541
66.80000000000054,29.796128776050455,0.024584916048372207,-0.017525743876207756
68.20000000000056,30.258623814215262,0.02275779000588063,-0.016117443757049266
69.60000000000058,30.727080615779435,0.024464700124745775,-0.018770105000000648
71.0000000000006,31.19408301921664,0.022777485763222582,-0.020080072428307005
72.40000000000062,31.668340728705953,0.02127452624947823,-0.0210799355483422
73.80000000000064,32.13707125827385,0.021580979911679066,-0.02027019111877859
75.20000000000066,32.601612099107676,0.020347216233107535,-0.02008114418505791
76.60000000000068,33.069530855876906,0.02135044458070734,-0.02009244983800418
78.0000000000007,33.53377161343663,0.019520912313739203,-0.022719840000032576
79.40000000000072,33.99815700649892,0.020176573082440363,-0.02272007013370736
80.80000000000074,34.45600465911846,0.019491028071139116,-0.023379914500570642
82.20000000000076,34.9364789534666,0.017546880369891493,-0.024700980261186167
83.60000000000078,35.40237512660044,0.01909836376611862,-0.022060050894067373
85.0000000000008,35.87126420590952,0.017330928142083923,-0.024700025641965162
86.40000000000082,36.33558697424616,0.017990197703657618,-0.024674011907736215
87.80000000000084,36.800940107050934,0.015954390678765584,-0.024689790058887162
89.20000000000086,37.26959336079456,0.013515454665810722,-0.023827657385915302
90.60000000000088,37.73128240963808,0.01450449445408264,-0.02634987044642756
92.0000000000009,38.20028263855445,0.014567678450981614,-0.025680166863780052
93.40000000000092,38.66011638923722,0.014917195175388365,-0.027000164999996024
94.80000000000094,39.1226795160771,0.015711913105840747,-0.026151768205269654
96.20000000000095,39.590000000000295,0.013273633275306507,-0.028979830178946564
97.60000000000097,40.06158019955582,0.013321698061038667,-0.0276700949975881
99.000000000001,40.51735506128361,0.01057417916718495,-0.027009767839519583
100.40000000000101,40.979697437382605,0.012391266432200121,-0.02935935911824661
101.80000000000103,41.442431516829075,0.011442713788604841,-0.029639868736639485
103.20000000000105,41.89923927272249,0.008026601969512992,-0.028520152418749056
104.60000000000107,42.35494174873601,0.00846927451726609,-0.02873710239952665
106.0000000000011,42.82651127911366,0.010060443989844847,-0.02842017774742711
107.40000000000111,43.28652634050575,0.010441860712437467,-0.02974018495404085
108.80000000000113,43.75047369065577,0.00809318520206137,-0.030390542380994923
110.20000000000115,44.207998378297326,0.00907704172590229,-0.028654837638881325
111.60000000000117,44.67174827761116,0.0071351746736671995,-0.03008020480768181
113.0000000000012,45.13069015364447,0.006795208835273625,-0.0317808023226922
114.40000000000121,45.59314918637502,0.005191029012985959,-0.030729964852451275
115.80000000000123,46.053873591340775,0.0055218319645127245,-0.03040308673219627
117.20000000000125,46.515178927346604,0.004616437329320711,-0.0317201106842635
118.60000000000127,46.9755668228115,0.004777218159998986,-0.0313709915383118
120.0000000000013,47.4354034062969,0.0034479704457368587,-0.03205950310430428
121.40000000000131,47.897793553745956,0.0016510291735356564,-0.03304510298008889
122.80000000000133,48.36056494902424,0.0018663550527366901,-0.03333376402106136
124.20000000000135,48.815867476166446,-0.0005757192962183577,-0.031720203860369445
125.60000000000137,49.27720877165218,-0.0016994002351884419,-0.03238017999999965
127.00000000000139,49.738770264773336,-0.0033019615871103802,-0.03510571219784531
128.4000000000014,50.19329615257503,-0.002022973359048663,-0.03370003001275279
129.80000000000143,50.65601309378872,-0.003750111792180988,-0.0337081384603275
131.20000000000147,51.115340790438076,-0.004986846757282892,-0.033700101381057834
132.60000000000147,51.57450532811846,-0.004638462312719804,-0.03499197117738451
134.00000000000148,52.03474988772263,-0.004819725287651178,-0.03509626380811781
135.4000000000015,52.49321152532802,-0.003486101614933901,-0.03336973975458246
136.80000000000155,52.952168409357284,-0.0023945364358330945,-0.03359631881256053
138.20000000000155,53.399575040902235,-0.004536964435854163,-0.03534988528952532
139.60000000000156,53.861832898072414,-0.005619070586754704,-0.035708719259208266
141.0000000000016,54.31326001095359,-0.004106097088783844,-0.03404596866073373
142.40000000000163,54.78131312652859,-0.005562603156200607,-0.03661559068845843
143.80000000000163,55.24421056102629,-0.006214018087506101,-0.037318480089567174
145.20000000000164,55.70252611695842,-0.006343276877923909,-0.036329990673661605
146.60000000000167,56.15753851115212,-0.0067618980651302785,-0.036297356164783245
148.0000000000017,56.615592523907885,-0.0068739417712979645,-0.03703419737567781
149.4000000000017,57.072565694398975,-0.008754203561013973,-0.03711504496329088
150.80000000000172,57.5286675371587,-0.012343663649554637,-0.03798001453638289
152.20000000000175,57.98672386125154,-0.0107386520078534,-0.03593523640615981
153.60000000000178,58.44286942317106,-0.009995426030999122,-0.037871409716129456
155.0000000000018,58.88450078282508,-0.00888333765017646,-0.036999922112447514
156.4000000000018,59.35204686256738,-0.00824284610520154,-0.0364919036103597
157.80000000000183,59.8128882632077,-0.009788982899578968,-0.03568362711126216
159.20000000000186,60.26447733045482,-0.009564607402066772,-0.03666029959822481
160.60000000000187,60.723667614041105,-0.011248585482020124,-0.03699002498050952
162.00000000000188,61.17402011179211,-0.010092172096656249,-0.03842139297232183
163.4000000000019,61.640006765896324,-0.011207904589270568,-0.037760152842832184
164.80000000000194,62.094441240415996,-0.011992900039616616,-0.038089799968089366
166.20000000000195,62.55119360610317,-0.011978430277712393,-0.03890320229717936
167.60000000000196,63.00619833055761,-0.01444833977737181,-0.03732285761469445
169.000000000002,63.455555303551805,-0.015626732593138737,-0.037760054893197115
170.40000000000202,63.91782182526539,-0.01602819909571629,-0.037760159999122855
171.80000000000203,64.36765302218443,-0.01516810978524652,-0.03940421775299807
173.20000000000203,64.8244882268001,-0.0172330956045752,-0.04005768999320125
174.60000000000207,65.28262422939201,-0.01680395451674266,-0.03907016000038066
176.0000000000021,65.7385617692802,-0.01750855758039549,-0.04171327721678342
177.4000000000021,66.19030896842662,-0.018731496546228854,-0.03974287103121554
178.80000000000211,66.64448253698697,-0.019939015617399747,-0.04006782699333833
180.20000000000215,67.10084068383951,-0.021160914269507725,-0.04151152019647952
181.60000000000218,67.55654638119327,-0.020511909361409675,-0.04062005000000912
183.0000000000022,68.00606511570969,-0.01863086489393906,-0.040939999999999976
184.4000000000022,68.46781869143152,-0.019560003470842968,-0.040290002618271537
185.80000000000223,68.92340200984242,-0.01902208036088804,-0.042265364506688385
187.20000000000226,69.37928884464414,-0.02192200435093139,-0.04129389063349986
188.60000000000227,69.83425302588432,-0.021149680296946194,-0.04288414346865643
190.00000000000227,70.28584291089649,-0.023063009179707272,-0.04160982500000188
191.4000000000023,70.7418738119,-0.021227784117828774,-0.04160983242053273
192.80000000000234,71.19460026639848,-0.02280689405370162,-0.0429199750541045
194.20000000000235,71.64000000000088,-0.025094332018331444,-0.04390989999999917
195.60000000000235,72.1026360035505,-0.024638396511008187,-0.04408661336864572
197.0000000000024,72.55184974515566,-0.026158487295180333,-0.04360649629175217
198.40000000000242,72.9950077502212,-0.02442139058092363,-0.043669893300049445
199.80000000000243,73.45511902360737,-0.02409620871609719,-0.04391000371631737
201.20000000000243,73.90344901423619,-0.02474578622219581,-0.044331183206767655
202.60000000000247,74.3523718569253,-0.02671198773306993,-0.04382264242866096
204.0000000000025,74.7963714345752,-0.02799523677643423,-0.04357235901005119
205.4000000000025,75.2603300092387,-0.02989698554462983,-0.0480095985758453
206.8000000000025,75.71434427289431,-0.027925401953017515,-0.04621990003929355
208.20000000000255,76.16960306395889,-0.02686580019900764,-0.047200034873465135
209.60000000000258,76.62344013920695,-0.030728364545260956,-0.044568241748834225
211.0000000000026,77.06902933395735,-0.02769489678909043,-0.04587280637432478
212.4000000000026,77.51907464013384,-0.029840299193240494,-0.04589000499999418
213.80000000000263,77.9732032501291,-0.030124211122126487,-0.04588939986180929
215.20000000000266,78.42742121370419,-0.030320743538196915,-0.046870005244831425
216.60000000000267,78.87771663750091,-0.03112608034374742,-0.0472000799999126
218.00000000000267,79.33254450333794,-0.0289723347460642,-0.047239515359073
219.4000000000027,79.79492432463425,-0.025856737160153687,-0.04848105818700876
220.80000000000274,80.26728322425453,-0.025388277853453323,-0.046870080012832105
222.20000000000275,80.72213928850685,-0.02734365363141955,-0.04918797462974478
223.60000000000275,81.18671905010733,-0.028900095770334477,-0.04819340571483899
225.00000000000279,81.64086812738388,-0.031176337276681343,-0.04753013915897508
226.40000000000282,82.09825912401749,-0.03279368418309936,-0.04859287643256227
227.80000000000283,82.54592770814723,-0.03405288489011893,-0.04852007999999852
229.20000000000283,83.00143520955407,-0.03332405418242468,-0.049839721294587136
230.60000000000286,83.45430363190482,-0.03226019880696285,-0.04852008000000119
232.0000000000029,83.9089510164332,-0.033047413983810614,-0.048521565766850294
233.4000000000029,84.36366246247441,-0.03443045185665716,-0.050163246884205925
234.8000000000029,84.81869995970709,-0.034088989351169996,-0.049013072701018956
236.20000000000294,85.27214605019326,-0.03482213057199557,-0.05061659283417619
237.60000000000298,85.74724740343,-0.037465119035951844,-0.04812201415066131
239.00000000000298,86.18294529888492,-0.036868381338891254,-0.050610159353534634
240.400000000003,86.63835808687955,-0.03582289214341916,-0.05192998031251639
241.80000000000302,87.09610829108007,-0.036334088099442274,-0.05094008000000061
243.20000000000306,87.55314683440196,-0.039428879025817265,-0.05094008000223349
244.60000000000306,88.00664626764149,-0.041125181888324036,-0.05192008000023307
246.00000000000307,88.46020033469598,-0.04136080438314771,-0.05159989995370662
247.4000000000031,88.91459992894386,-0.04186609281963083,-0.05165439184064624
248.80000000000314,89.37270584082209,-0.04180865869750572,-0.05290989999999951
250.20000000000314,89.829701405996,-0.043189929935113724,-0.05225916257656138
251.60000000000315,90.28759559374853,-0.04392304815176851,-0.051589392148152946
253.00000000000318,90.7309702436553,-0.043770916582570596,-0.05225995195030464
254.40000000000322,91.19866738915694,-0.042962965440125345,-0.05326964071379292
255.80000000000322,91.64966220805358,-0.04362859672037067,-0.05323982498967217
257.20000000000323,92.1028760930497,-0.04599431127415743,-0.05191946227466682
258.60000000000326,92.56128665966123,-0.044459944869425616,-0.053239824985277906
260.0000000000033,93.01398637602031,-0.04535253675047257,-0.05422755183371297
261.4000000000033,93.46970332113816,-0.04771908236328426,-0.054560033137971864
262.8000000000033,93.92389550892318,-0.04926744376670267,-0.053240803622733424
264.20000000000334,94.3763500708807,-0.04817612688034045,-0.05456005000000852
265.6000000000034,94.83454591322405,-0.050373423792001715,-0.05260130802068508
267.0000000000034,95.29156006829446,-0.05043160041607608,-0.054218664586131116
268.4000000000034,95.74758007087853,-0.048492817457764126,-0.05332013067238517
269.8000000000034,96.20418497134838,-0.0521887582781404,-0.05400980404672584
271.20000000000346,96.65868048773633,-0.051203925097416336,-0.054669975045817054
272.60000000000343,97.11850711940653,-0.05174536788206896,-0.054532736887867195
274.00000000000347,97.57747473803657,-0.05239287696569117,-0.05433989998884847
275.4000000000035,98.0300024246228,-0.05521976012012675,-0.054474999913622035
276.80000000000354,98.48635588886768,-0.05600050718581029,-0.05632034543729292
278.20000000000357,98.94392837885418,-0.05594468278262066,-0.05444990636634506
279.60000000000355,99.40135813857418,-0.05786405413598961,-0.05542998658610809
281.0000000000036,99.85561145032538,-0.05578544532827623,-0.05511049180776961
282.4000000000036,100.31675619388845,-0.05323804641170882,-0.0551099749999997
283.8000000000036,100.77482251408198,-0.059525159352826984,-0.05576036928922079
285.2000000000036,101.23118337749612,-0.05962123282191634,-0.05776629569974645
286.60000000000366,101.68937382288445,-0.06150283425594205,-0.05510948892673451
288.0000000000037,102.14174522381632,-0.0642017539121944,-0.05576881155289293
289.40000000000373,102.60111873529499,-0.0625531100815735,-0.05510982499981143
290.8000000000037,103.058658441285,-0.06476369827803019,-0.05510982495571781
292.20000000000374,103.51024690102766,-0.06504573708726458,-0.053787162983671255
293.6000000000038,103.96577577438677,-0.06605843458466576,-0.05576997500042724
295.00000000000375,104.41889928785498,-0.06604150167351386,-0.05610049859562771
296.4000000000038,104.87603713436766,-0.0672035850344288,-0.0561006275855882
297.8000000000038,105.33211918214387,-0.06560422835658009,-0.0570900092648583
299.20000000000385,105.79042710680444,-0.06891017537224986,-0.05748415814847174
300.6000000000039,106.2446207572794,-0.06792134944784478,-0.05707980161779913
302.00000000000387,106.70853544648641,-0.07141079691279395,-0.05839876945545619
303.4000000000039,107.16337040677448,-0.07180383758996078,-0.05707982495538255
304.80000000000393,107.61602777532448,-0.0702534852435499,-0.058399819999995106
306.2000000000039,108.07800419501443,-0.07215295884776252,-0.05774006050434144
307.60000000000394,108.53801000477223,-0.07185341218027652,-0.058069415402022706
309.000000000004,108.98897606907866,-0.07280735801103999,-0.0596545862297031
310.400000000004,109.44674915897708,-0.07428238591740954,-0.05789226555526383
311.80000000000405,109.90202092689424,-0.0746401036073272,-0.05916997000100288
313.200000000004,110.35999625160335,-0.07741967899003432,-0.05917011999991706
314.60000000000406,110.81880649380447,-0.07649576024860472,-0.060162485106696195
316.0000000000041,111.28231959949666,-0.07677896836705611,-0.06082948944760158
317.40000000000407,111.73584517747548,-0.07893303463541623,-0.060819934878460824
318.8000000000041,112.18623105020961,-0.07785725090442752,-0.0602644072948908
320.20000000000414,112.64318447476889,-0.0790704722525537,-0.06042112447970238
321.6000000000042,113.09709256345258,-0.08184212442733774,-0.0614799399999999
323.0000000000042,113.55661786261919,-0.08318122027401209,-0.060819939917476695
324.4000000000042,114.01761274391843,-0.0812571598424694,-0.06148009000016508
325.8000000000042,114.47717273884712,-0.08233956016923183,-0.06226947627398838
327.20000000000425,114.93580853599502,-0.08214346324654342,-0.06247045308925614
328.60000000000423,115.38941123478978,-0.08468172395098073,-0.06181042941579751
330.00000000000426,115.85450115068446,-0.08393262047289674,-0.06311986009062887
331.4000000000043,116.31556517964022,-0.08645113993519749,-0.06245921257402465
332.80000000000433,116.77675019934084,-0.08634418117167875,-0.06246990999948032
334.20000000000437,117.23171483830956,-0.08709015342306259,-0.06246990999931912
335.60000000000434,117.6858917874705,-0.08772278892233198,-0.06345990996131601
337.0000000000044,118.1443499389823,-0.0876977628586495,-0.062144384453067136
338.4000000000044,118.60301496099721,-0.08832732584354441,-0.06312991002792456
339.8000000000044,119.06453290195654,-0.08885268439908445,-0.06214018652442821
341.2000000000044,119.52172217041466,-0.08916660072857563,-0.06279023048685817
342.60000000000446,119.9861917094975,-0.0912973744540273,-0.0634073471012524
344.0000000000045,120.44220065650468,-0.09176197729519187,-0.06378008500002386
345.4000000000045,120.90520055244072,-0.09281392833803626,-0.06378008499999899
346.8000000000045,121.36421875674809,-0.09376448866683074,-0.06378008499940391
348.20000000000454,121.8269778199084,-0.09356044663831864,-0.06411003869207432
349.60000000000457,122.28365295749705,-0.09315049658245478,-0.06310075078816979
351.00000000000455,122.74649821732477,-0.09521618135664811,-0.06444016000677477
352.4000000000046,123.19767083668381,-0.09607064315872438,-0.06410996624948773
353.8000000000046,123.66139881683304,-0.09686278065785192,-0.06443994238495421
355.20000000000465,124.12480968915193,-0.09449936582084617,-0.06316580509226055
356.6000000000047,124.57706599083862,-0.09411893078681333,-0.06344933752381321
358.00000000000466,125.04206965026725,-0.09655665687493142,-0.062461402308672476
359.4000000000047,125.50050701839454,-0.09731694333675178,-0.0651000549999976
360.80000000000473,125.96719078666003,-0.09764055403290794,-0.06609645699327604
362.2000000000047,126.43144677190422,-0.09691260027564885,-0.0651000550252121
363.60000000000474,126.89274942331701,-0.09891603154390194,-0.06410983001651793
365.0000000000048,127.35501012709393,-0.10176097341908896,-0.06543117063966442
366.4000000000048,127.81398101664628,-0.10357647734260134,-0.06377970232360797
367.80000000000484,128.2731357181743,-0.10328039075743534,-0.06544000510180537
369.2000000000048,128.737295290209,-0.10173948769613195,-0.06609316197639803
370.60000000000485,129.19473115999767,-0.10474897680432926,-0.06477005977346417
372.0000000000049,129.65867606574844,-0.10477842919947178,-0.0657601131557124
373.40000000000487,130.12208067128566,-0.10207954422626964,-0.06509980000009286
374.8000000000049,130.58756711316875,-0.10584079884189967,-0.06641979992002289
376.20000000000493,131.04971217924316,-0.1049987325830477,-0.06707996399527616
377.60000000000497,131.51358466953022,-0.10718675677575584,-0.06509980000000626
379.000000000005,131.97394326153125,-0.10801881813663838,-0.06674891028665142
380.400000000005,132.43377158802681,-0.107782666812406,-0.06644926747073265
381.800000000005,132.89512115968216,-0.1091724252531654,-0.06641385551192425
383.20000000000505,133.35550367399586,-0.11118261105305205,-0.06603600764984785
384.600000000005,133.82200685114253,-0.10914620421665444,-0.06839021055476868
386.00000000000506,134.2790241552725,-0.10927286359799249,-0.06609094372330437
387.4000000000051,134.7366869032404,-0.10800152205216929,-0.06748627549897313
388.8000000000051,135.19494656390947,-0.10805275278357662,-0.06737214852489659
390.20000000000516,135.6599968697216,-0.1077972470852897,-0.06838986999999719
391.60000000000514,136.12820143417008,-0.10917053655546027,-0.06838987766560223
393.0000000000052,136.5930926918659,-0.10798253641483635,-0.06839018853698864
394.4000000000052,137.05698563667804,-0.10957569125522637,-0.06925826577085248
395.8000000000052,137.52398136136762,-0.11383742757418247,-0.06839658915009306
397.2000000000052,137.9842001087809,-0.11556487899437928,-0.06905016999910396
398.60000000000525,138.44717360928118,-0.11672136255136523,-0.06938016992757268
400.0000000000053,138.91026826991876,-0.12110690217351139,-0.0680601851886129
401.4000000000053,139.37822632534295,-0.12194732300362054,-0.06904941206787019
402.8000000000053,139.83105926650572,-0.12124878628330493,-0.06905017050750661
404.20000000000533,140.29370027239747,-0.12491964061277416,-0.07037006499975185
405.60000000000537,140.7556306927313,-0.12540136030353533,-0.07004006500000193
407.00000000000534,141.22102581546955,-0.1265373589457608,-0.07140284424110543
408.4000000000054,141.68110809388202,-0.12966823402026684,-0.07069045619211511
409.8000000000054,142.14322127411205,-0.13085952690140124,-0.07060605853131108
411.20000000000545,142.60819757951867,-0.12964498004820646,-0.07206242332850588
412.6000000000055,143.07427722948344,-0.13007982843109755,-0.07101982424756992
414.00000000000546,143.5363171501302,-0.13007025457914612,-0.06993783069715054
415.4000000000055,144.00142262767406,-0.13156104218250508,-0.07114670124334088
416.8000000000055,144.46246285410058,-0.13272246880389837,-0.07059027338762469
418.2000000000055,144.9273904393112,-0.13171477826860212,-0.07178522391130393
419.60000000000554,145.39587588013427,-0.131993254336493,-0.07190005999998395
421.00000000000557,145.86000000000246,-0.13068666516353988,-0.07190006000000082
422.4000000000056,146.33303540843644,-0.13595930456511707,-0.0725598069732829
423.80000000000564,146.79368402778846,-0.13529215847977216,-0.07156993130420464
425.2000000000056,147.2544720043607,-0.13391526538615994,-0.07157078592337873
426.60000000000565,147.71332667413324,-0.13820555695173709,-0.07223003064714062
428.0000000000057,148.17710676835205,-0.13515374994209473,-0.07355003426130091
429.40000000000566,148.64604082203547,-0.13638438602294922,-0.07453727777391883
430.8000000000057,149.10524860497304,-0.13832340646139896,-0.07486992474261633
432.20000000000573,149.56769605679108,-0.13980687105161005,-0.07190497875381396
433.60000000000576,150.03730139613248,-0.14079291018571727,-0.07310424288295048
435.0000000000058,150.50335742740697,-0.14114003151918997,-0.07355080322571306
436.4000000000058,150.96773857052003,-0.1436565287031506,-0.073879098791791
437.8000000000058,151.43517242589994,-0.14260825159615975,-0.07388007500014737
439.20000000000584,151.89772863329102,-0.14117929658688366,-0.07517607068759125
440.6000000000058,152.37125274846167,-0.1432481995289785,-0.07617991999990137
442.00000000000585,152.83034024792494,-0.1429456310711401,-0.0755199555519317
443.4000000000059,153.29455296046027,-0.14443527286453084,-0.07683959046309052
444.8000000000059,153.76152158220577,-0.14750605915769976,-0.0758497761018293
446.20000000000596,154.22293706682356,-0.14746291954100688,-0.07637228560363774
447.60000000000593,154.69465802373693,-0.14796360498631178,-0.07659865012504508
449.00000000000597,155.15475917705655,-0.14993148802840173,-0.07782760169236269
450.400000000006,155.6192695180116,-0.15261434157649756,-0.07887674095103314
451.800000000006,156.0791840804947,-0.15227777071198068,-0.0771809002747803
453.200000000006,156.55557847462833,-0.14866615084049695,-0.07849011495554592
454.60000000000605,157.02743004797549,-0.14915963082900374,-0.07783010956459124
456.0000000000061,157.49220872942854,-0.1488064207851758,-0.07859013435080087
457.4000000000061,157.96229809674813,-0.14888115381984401,-0.07827001846022297
458.8000000000061,158.42654502511343,-0.1486143779339575,-0.07860002475806205
460.2000000000061,158.89270684127916,-0.1515590823582904,-0.08024936116433468
461.60000000000616,159.35414598456975,-0.1517224284709826,-0.08087767027423132
463.00000000000614,159.82152518924005,-0.1547852499878708,-0.0795901083248789
464.4000000000062,160.28773201696285,-0.1520252878861954,-0.08057915298177765
465.8000000000062,160.75701094826144,-0.15467282562907725,-0.08024993001904068
467.20000000000624,161.22293649436006,-0.1540763355475261,-0.08029033130310781
468.6000000000063,161.69337279898073,-0.1550830754158099,-0.08020293800656164
470.00000000000625,162.15820828067748,-0.1565046424057983,-0.08222997344677241
471.4000000000063,162.62392733827147,-0.15607348684216849,-0.0823858125209469
472.8000000000063,163.09167332414302,-0.1599649910664369,-0.08409011160529412
474.2000000000063,163.5605832150928,-0.16274888379525443,-0.08511476861974243
475.60000000000633,164.02814599362935,-0.1625532998585646,-0.08442041044892568
477.00000000000637,164.49876615921465,-0.1642065762369591,-0.08538218612434267
478.4000000000064,164.97055304532492,-0.16618851382862232,-0.08411262405268038
479.80000000000643,165.4424134258094,-0.16632964243890402,-0.08540924108490167
481.2000000000064,165.91472542114045,-0.16550853433522672,-0.0857388934022758
482.60000000000645,166.37439960193188,-0.16897708093160535,-0.08631265633333207
484.0000000000065,166.8386558482721,-0.17210844349538723,-0.08672006073792637
485.40000000000646,167.30123721204944,-0.17562773134476029,-0.08803993598424231
486.8000000000065,167.7678701488327,-0.18134047474680282,-0.08915948307033261
488.2000000000065,168.23531383074206,-0.1789861152275387,-0.08969041197359662
489.60000000000656,168.70897505748616,-0.1797734106450597,-0.0883700882293117
491.0000000000066,169.17538542101778,-0.18087535575770453,-0.09103271228552767
492.40000000000657,169.64463383676264,-0.17961298555155292,-0.08887171868150157
493.8000000000066,170.1189264463608,-0.18223612803882316,-0.09164682523354051
495.20000000000664,170.58842097171143,-0.18145483855639633,-0.09099677195982592
496.6000000000066,171.05408823518565,-0.1829836959023048,-0.09100041634436717
498.00000000000665,171.5200000000023,-0.1832490855402491,-0.09165994500408692
499.4000000000067,171.9844926699207,-0.1844306794088606,-0.0923141983945861
500.8000000000067,172.4517993827469,-0.1872399104834246,-0.09362872992744453
502.20000000000675,172.9199966429383,-0.18954431878866718,-0.09363987921001904
503.60000000000673,173.38283959751132,-0.18939113641960414,-0.0942998735691094
505.00000000000676,173.85162065444217,-0.18994037588911672,-0.0952784046017201
506.4000000000068,174.32493711625136,-0.19244774535923703,-0.0956104261336641
507.8000000000068,174.79571398916397,-0.1883373613165178,-0.09568423365198919
509.2000000000068,175.27085526982145,-0.19015800723487963,-0.09791992499995583
510.60000000000684,175.7365872741058,-0.19025976872078987,-0.09824991240644021
512.0000000000068,176.2058071739824,-0.18896335621509186,-0.09726987947252619
513.4000000000069,176.6719819796596,-0.19272778676217017,-0.09890984469036646
514.8000000000069,177.14368800170647,-0.1954700840736039,-0.09895613731357589
516.2000000000069,177.61145920957338,-0.19630248636487657,-0.10023017931621592
517.600000000007,178.0787301227333,-0.1937031924633077,-0.10023469546167263
519.0000000000069,178.54709917861013,-0.19465094943871586,-0.10187462086480847
520.4000000000069,179.01346538163435,-0.19427045578114832,-0.1006530942456969
521.800000000007,179.48257017021578,-0.19874853234144707,-0.10056013067072023
523.2000000000071,179.9559662065021,-0.19832345678750363,-0.10220003489210372
524.6000000000071,180.42267482897537,-0.19700313389649482,-0.10318471594257961
526.000000000007,180.89622604250576,-0.19871109926288355,-0.1045104686992584
527.4000000000071,181.36467671747124,-0.1975296775106843,-0.10382251526314956
528.8000000000071,181.83758006395036,-0.1984927574982973,-0.10516939781683865
530.2000000000071,182.3079831074246,-0.19817905072297926,-0.10583012500000155
531.6000000000072,182.77873669826675,-0.2010028364294052,-0.10714206938142956
533.0000000000072,183.245836658769,-0.2033252503665821,-0.10714021017139119
534.4000000000071,183.72089355606477,-0.20386223358874833,-0.10782270758073942
535.8000000000072,184.19504680474603,-0.20379502774345948,-0.10812980133621863
537.2000000000072,184.6653377156689,-0.2057074278220954,-0.11043998510144082
538.6000000000072,185.13531870693248,-0.2096887120978601,-0.10977998499836561
540.0000000000073,185.60645712922465,-0.2126323565086179,-0.1104300289721083
541.4000000000073,186.07853250690738,-0.20878748809280978,-0.1124099086277699
542.8000000000073,186.54688514628475,-0.2139840268946518,-0.11306468292153404
544.2000000000073,187.0138083428597,-0.21520392656185683,-0.11280417146719701
545.6000000000073,187.48139398776667,-0.21471078211395023,-0.1133999514702495
547.0000000000074,187.93163581651427,-0.21152020953592965,-0.11328163581630601
548.4000000000074,188.4238469349571,-0.2141223165475079,-0.11471991703556395
549.8000000000075,188.89579681634967,-0.21129365060742167,-0.11603009500000061
551.2000000000074,189.36412108894024,-0.2147274599862481,-0.11701993019779433
552.6000000000074,189.8364515497406,-0.21400823795854285,-0.11757032840257287
554.0000000000075,190.30585030139363,-0.22256600231286328,-0.11911572238671875
555.4000000000075,190.77417472600445,-0.22093078248897635,-0.12032030582459763
556.8000000000075,191.2441488624799,-0.22194808040884784,-0.12103073582673929
558.2000000000075,191.71969075294555,-0.22390152411962516,-0.1209803598799084
559.6000000000075,192.19666226161803,-0.223503608507039,-0.12295999029143845
561.0000000000075,192.66255520590767,-0.2236829974379697,-0.1235098818093987
562.4000000000076,193.1356598930616,-0.22403764887133182,-0.12454896064594356
563.8000000000076,193.60588495883837,-0.22525239208107228,-0.12492996637060738
565.2000000000077,194.0775452065252,-0.2294704364078819,-0.12591919638783633
566.6000000000076,194.55309353881685,-0.2280748072124963,-0.12690998560401656
568.0000000000076,195.0260736344778,-0.23034186543039903,-0.12954018549491053
569.4000000000077,195.49467410414522,-0.23543205322183836,-0.1295400743420263
570.8000000000077,195.9686570184806,-0.23347608056629232,-0.1321800491587437
572.2000000000078,196.4418536016744,-0.23030413652073856,-0.13196003858515803
573.6000000000078,196.91563837049128,-0.23429500234669387,-0.1329400284454696
575.0000000000077,197.39103785348533,-0.23711520304261624,-0.13458994368399235
576.4000000000078,197.8649400427705,-0.23704265145331327,-0.1355778430788499
577.8000000000078,198.33911279152798,-0.23725050777566858,-0.13692301182946753
579.2000000000078,198.8072982088141,-0.23873648941848957,-0.13798983018808064
580.6000000000079,199.28000677351164,-0.23858589504288874,-0.1383198057798416
582.0000000000078,199.75000000000338,-0.24124177762155297,-0.14129266251743156
583.4000000000078,200.21701486612466,-0.240182784729444,-0.14127031700261483
584.8000000000079,200.69042662687144,-0.23841846183010862,-0.1416229888315952
586.2000000000079,201.1629836689594,-0.2381886069453154,-0.1442501357845467
587.600000000008,201.6343260144988,-0.23732677016004766,-0.14528312329947957
589.000000000008,202.1106739217006,-0.23768375798339703,-0.14754003005317795
590.4000000000079,202.57446697853334,-0.23509705416387972,-0.14919485925902176
591.800000000008,203.05003270995337,-0.23948245416745895,-0.1493982835423724
593.200000000008,203.53638859979338,-0.24233280329142737,-0.15412992332634667
594.6000000000081,204.00368384174766,-0.23984891153004906,-0.15412986754031133
596.0000000000081,204.47778941085835,-0.23452525365706078,-0.15741993527061826
597.400000000008,204.9537605196545,-0.232422433729512,-0.15938862413295452
598.8000000000081,205.42788686416114,-0.22799698451844108,-0.16006001995952257
600.2000000000081,205.89838022832896,-0.22889035197090823,-0.1628335979791875
601.6000000000081,206.36847740891702,-0.22651303314856142,-0.16501262557481633
603.0000000000082,206.8434137498587,-0.22389657176437394,-0.16892970247834693
604.4000000000082,207.3199931201579,-0.22588432898832433,-0.17158001993648186
605.8000000000081,207.79084524468786,-0.2238111681148447,-0.17289753114011663
607.2000000000082,208.26787301559222,-0.22169972881255307,-0.17585789163791343
608.6000000000082,208.74293586354628,-0.22382875189417817,-0.17943682844316333
610.0000000000083,209.21041117623076,-0.21817206240591513,-0.1820814494386438
611.4000000000083,209.68936936339227,-0.21705876612926822,-0.1853561717497927
612.8000000000083,210.16204088308893,-0.21200541896750602,-0.18937064920567748
614.2000000000083,210.63703461057196,-0.21190703093854468,-0.19068956148063743
615.6000000000083,211.11454143353873,-0.20976550485359802,-0.19424475617812398
617.0000000000084,211.591264677991,-0.2033792476350449,-0.20011020190652085
618.4000000000084,212.06417984363364,-0.20512391962985266,-0.20426271948067942
619.8000000000084,212.53487755045995,-0.20345575093110257,-0.20747987028875903
621.2000000000085,213.0114787519234,-0.19798842119307247,-0.2087998441778418
622.6000000000084,213.4806183327776,-0.1926282726567008,-0.21407784536460328
624.0000000000084,213.953511547541,-0.18655360933642617,-0.21800893836320778
625.4000000000085,214.43304056189942,-0.18414852912493362,-0.22395817469899848
626.8000000000085,214.90784973944054,-0.17693867324647394,-0.2279091568893734
628.2000000000085,215.38773960521507,-0.17433155670146405,-0.23251985623402582
629.6000000000085,215.86099143249768,-0.16706749295975953,-0.23775341179988763
631.0000000000085,216.3340064189,-0.157092042423574,-0.2424000615408861
632.4000000000086,216.81316722170845,-0.15352275168075336,-0.2494971351415738
633.8000000000086,217.28357235459396,-0.14737516274863793,-0.2559062275421531
635.2000000000086,217.75820173600732,-0.1379173980818469,-0.26249126845640447
636.6000000000087,218.2334936901897,-0.1298102113483166,-0.26677014663639387
638.0000000000086,218.70663764681262,-0.12232154111472893,-0.27464628061956375
639.4000000000087,219.17947956128464,-0.11176127618331222,-0.28059992321540506
640.8000000000087,219.6564318351868,-0.10535062113788873,-0.2898430410960211
642.2000000000087,220.13039937802066,-0.09145840115331128,-0.2964126072972624
643.6000000000088,220.61330967011662,-0.08076801890271179,-0.30460190774494356
645.0000000000088,221.08823619669346,-0.07140638675172584,-0.3132103609639061
646.4000000000087,221.56163864136906,-0.0603959997042578,-0.32178011067501444
647.8000000000088,222.0368661256224,-0.050709628925996064,-0.330269585703896
649.2000000000088,222.515282419476,-0.039542883526503037,-0.3400782697733775
650.6000000000088,222.98863683351223,-0.02865468284963857,-0.3500698090536454
652.0000000000089,223.46308989792328,-0.016257469476037123,-0.35933132788363586
653.4000000000088,223.93977211618264,-0.0030163788549626425,-0.3687590256363493
654.8000000000089,224.4184842304601,0.008398250060871693,-0.3815218850063862
656.2000000000089,224.89814218462294,0.025118320805973315,-0.3939946769924969
657.6000000000089,225.3769855887507,0.03868703203473656,-0.4032268255130398
659.000000000009,225.84776531193148,0.05447817248264508,-0.41668578449279314
660.400000000009,226.3215042297058,0.06795386208914644,-0.43026435745171954
661.800000000009,226.80047947787784,0.08702539404006204,-0.44422301325710345
663.200000000009,227.27383575111705,0.025104863993657744,-0.456837308457954
664.600000000009,227.75030096679427,0.03358497306225994,-0.47339879852162614
666.0000000000091,228.22000000000233,0.049238761913455775,-0.48929081222879267
667.4000000000091,228.69540476066177,0.06432444571283957,-0.5052878479757226
668.800000000009,229.17000421857875,0.08497020211525408,-0.5199303333353291
670.2000000000091,229.64734681875515,0.10226065954742536,-0.5398929959021284
671.6000000000091,230.12602536852575,0.12476217202948581,-0.5578859667340148
673.0000000000091,230.60059277711096,0.14338421325994366,-0.57738132935842
674.4000000000092,231.07760576129277,0.2542863696699236,-0.5964550464520055
675.8000000000092,231.55462040110152,0.2993322900340556,-0.6156625766116925
677.2000000000093,232.03249449896722,0.31523623633327125,-0.6371134119285684
678.6000000000092,232.5132272196454,0.3411037741342744,-0.6588578815182178
680.0000000000092,232.99199221596223,0.3676749708133631,-0.6813760019383448
681.4000000000093,233.4753349724341,0.39822964543738326,-0.7060654711331469
682.8000000000093,233.9535643184683,0.41890764771142885,-0.72985016253919
684.2000000000094,234.42741871046172,0.44116429114111533,-0.7536068873935169
685.6000000000093,234.90206736551977,0.4620362139878571,-0.7795438159058743
687.0000000000093,235.37424761143527,0.487229418001891,-0.804363797185951
688.4000000000094,235.85390125793694,0.5112053275272315,-0.8313811012556611
689.8000000000094,236.33456028536557,0.5369280881233531,-0.8604580487231828
691.2000000000094,236.81493917919724,0.5578174987125588,-0.8902160512742459
692.6000000000095,237.2965556244049,0.5791193059949311,-0.9188891458010828
694.0000000000094,237.77742963669562,0.5923009820459186,-0.9508127891781908
695.4000000000094,238.25883797409008,0.6020854176698434,-0.9818143292032837
696.8000000000095,238.73472913832865,0.6113872812027141,-1.0114269247208374
698.2000000000095,239.21083643003612,0.6109376246974243,-1.041939191349274
699.6000000000096,239.68669248427207,0.6118170710926063,-1.076314089898593
701.0000000000095,240.1616019348081,0.5971387365907046,-1.1059007584314933
702.4000000000095,240.63636351020256,0.5674453630943073,-1.1363148421234621
703.8000000000096,241.11285219156696,0.5229863342911552,-1.1666067988130764
705.2000000000096,241.5720395009463,0.46275592212454475,-1.1927757470607645
706.6000000000097,242.04240335742946,0.39070819907543486,-1.2197210573281945
708.0000000000097,242.51207376103397,0.29935920239888203,-1.2412799499514202
709.4000000000096,242.979409457099,0.19079270815449156,-1.2625795252836909
710.8000000000097,243.44729185137487,0.10196358049849552,-1.2791421277197768
712.2000000000097,243.91823642675507,0.010619506039307058,-1.2962197812759833
713.6000000000097,244.3846378919429,-0.0845078479591157,-1.3078073686890317
715.0000000000098,244.85321159871594,-0.16808946356188947,-1.3176814695202648
716.4000000000098,245.32629373505227,-0.2431118133725536,-1.3251931151543248
717.8000000000097,245.79896481500782,-0.30527087538484254,-1.3308016735523651
719.2000000000098,246.26884971228657,-0.34844148117940366,-1.3348312722826172
720.6000000000098,246.73615233775317,-0.3762311277380723,-1.3374419516855447
722.0000000000099,247.2065365052034,-0.3995466541769326,-1.3404473218814128
723.4000000000099,247.68446650912995,-0.41810033636014454,-1.341760191202562
724.8000000000098,248.15750745872714,-0.4310014894659102,-1.3431421004208026
726.2000000000099,248.63130698002294,-0.4337078952975557,-1.3444024037194935
727.6000000000099,249.1140032850336,-0.43628791122265254,-1.3453798230508816
729.00000000001,249.5861642498069,-0.442420676406059,-1.3440769541462005
730.40000000001,250.06503222470522,-0.44915883736403606,-1.3444098043685555
731.80000000001,250.54271510848957,-0.45354736926977335,-1.3457058168595069
733.20000000001,251.01372250632062,-0.45423659498306534,-1.3450598883438092
734.60000000001,251.4938561857702,-0.4537763372636596,-1.345720040000085
736.00000000001,251.97128343174438,-0.45715020244960547,-1.3447192481770376
737.4000000000101,252.44379172650213,-0.4593237163666064,-1.3444000400000005
738.8000000000101,252.93137005761446,-0.4638085612782814,-1.3444000604973887
740.20000000001,253.40842912689604,-0.47096533769148463,-1.3460492925907226
741.6000000000101,253.88178054949606,-0.4689609084443811,-1.3447299349998492
743.0000000000101,254.35715889855734,-0.47325933290476296,-1.3467062986618168
744.4000000000102,254.83343812257525,-0.47276786477147326,-1.3450591138149726
745.8000000000102,255.31269514411113,-0.47458003322951825,-1.3434188185564544
747.2000000000102,255.79366309988598,-0.4728149618159301,-1.3453932071944137
748.6000000000103,256.27235775848334,-0.4741492427055656,-1.3447301821211455
750.0000000000102,256.74679889258243,-0.47318422464185117,-1.3447373650681587
751.4000000000103,257.21924335270404,-0.4749419568670117,-1.34374990496271
752.8000000000103,257.6973143649928,-0.48106234260717917,-1.3434213841104814
754.2000000000103,258.1760206169706,-0.4792111694339032,-1.3457200550000006
755.6000000000104,258.65963413415585,-0.48755150324534435,-1.3463298093102107
757.0000000000103,259.1338845306036,-0.4873180051372823,-1.3438612475177796
758.4000000000103,259.6127345678169,-0.490764014383668,-1.345169902289749
759.8000000000104,260.0892417059012,-0.49613552970299546,-1.3448500849647584
761.2000000000104,260.56226735924963,-0.49466213336766707,-1.3441665920719679
762.6000000000104,261.03687777164066,-0.4980659562550178,-1.3468185547600524
764.0000000000105,261.51330690571626,-0.49460076799310926,-1.345172745243849
765.4000000000104,261.995711920022,-0.49864128144104836,-1.3468205894564789
766.8000000000105,262.4761085528794,-0.5000197874219805,-1.3455940122484842
768.2000000000105,262.9522902789839,-0.4966782965204617,-1.349193459956327
769.6000000000105,263.43036001043384,-0.4955479522404507,-1.3481401074382204
771.0000000000106,263.90159617489513,-0.4928270051037065,-1.346928530964472
772.4000000000106,264.3759631295093,-0.49486758502421857,-1.3472598399999995
773.8000000000106,264.86162972864486,-0.497440896448341,-1.3469195365772593
775.2000000000106,265.34533314536657,-0.5035586049578935,-1.3476460223147448
776.6000000000106,265.81711773191967,-0.5060343418688094,-1.3475796378203433
778.0000000000107,266.2951909762775,-0.5095629147530132,-1.3485701589145145
779.4000000000107,266.770650932341,-0.5138045228898189,-1.3485701627773716
780.8000000000106,267.2457023055479,-0.5174989950010045,-1.3475910166017213
782.2000000000107,267.7235315703042,-0.520869028507509,-1.346600194897654
783.6000000000107,268.1992139470507,-0.5232501676787233,-1.3469298576802062
785.0000000000107,268.6785180666369,-0.5271225333610903,-1.346910619930512
786.4000000000108,269.1599926333247,-0.5288094400987,-1.348250626321744
787.8000000000108,269.6457796460504,-0.5293049631361169,-1.3475897300807653
789.2000000000108,270.12877343956467,-0.5344792854278726,-1.3485800428743513
790.6000000000108,270.59926628367793,-0.5367429739491603,-1.3472652125151452
792.0000000000108,271.07110969979044,-0.5424538831238128,-1.3482500219909626
793.4000000000109,271.5499921698921,-0.5498254824202582,-1.3485800280478517
794.8000000000109,272.0310021594781,-0.5514007673326886,-1.3472600299999993
796.200000000011,272.50968214076204,-0.5493059597127634,-1.3462754277364208
797.6000000000109,272.99199684612466,-0.552063457163877,-1.3465065220778012
799.0000000000109,273.46765214671075,-0.5549972398181247,-1.3482401218083107
800.400000000011,273.9459403879781,-0.5525547806280353,-1.345570890353847
801.800000000011,274.42413490704536,-0.5578821247520169,-1.348570019119831
803.200000000011,274.89839021317715,-0.5590201729480473,-1.3495825715834573
804.600000000011,275.3756430183587,-0.5588219171230415,-1.3482360234252573
806.000000000011,275.85143789420033,-0.5616105073590165,-1.349230247890354
807.400000000011,276.3320414549937,-0.5570546143778747,-1.347911015496273
808.8000000000111,276.80432115491413,-0.5611346291462631,-1.3492404653879722
810.2000000000111,277.2855632010612,-0.5630957203343261,-1.3498999761693415
811.6000000000112,277.7600072577409,-0.567445168386401,-1.349899890914453
813.0000000000111,278.24090412182625,-0.5672425218230517,-1.348579889999129
814.4000000000111,278.715340710275,-0.5658486465189614,-1.3492401450051528
815.8000000000112,279.192932840461,-0.5689423791659154,-1.349890072620795
817.2000000000112,279.67679761583304,-0.5731720851576867,-1.3487039545229322
818.6000000000113,280.15545233849684,-0.5797598295523394,-1.3492307220205495
820.0000000000113,280.6264635163549,-0.5851008566792064,-1.348569744025549
821.4000000000112,281.10795349594883,-0.5828577529003924,-1.3508799422311033
822.8000000000113,281.5900044962013,-0.5824793735123333,-1.3492299504526981
824.2000000000113,282.0635396339375,-0.5854066479326625,-1.3508800878433989
825.6000000000113,282.54225510061684,-0.5877332896996728,-1.3495598690170945
827.0000000000114,283.02218068021375,-0.5872109825360319,-1.3508061461437575
828.4000000000113,283.502038480942,-0.5866184699998658,-1.3495403497624117
829.8000000000113,283.9743896394005,-0.5859225551043021,-1.350946966449801
831.2000000000114,284.45080237425634,-0.5883362867296578,-1.349900155005873
832.6000000000114,284.93672865815654,-0.5917547870259954,-1.3515301106561273
834.0000000000115,285.4200000000054,-0.586721292917388,-1.35055018
835.4000000000115,285.89798078899753,-0.5850638039764564,-1.3505501802315845
836.8000000000114,286.3716042401818,-0.5895834486422289,-1.3502179998804045
838.2000000000115,286.8485424104364,-0.5971517997628077,-1.3502208943434284
839.6000000000115,287.3212615246092,-0.5994040919641126,-1.3502200000000002
841.0000000000116,287.80640341887965,-0.6046981612140763,-1.350220000000041
842.4000000000116,288.2817402867826,-0.6084905342424518,-1.3512098200825573
843.8000000000116,288.76429800652045,-0.613408573904469,-1.3501792762891518
845.2000000000116,289.2397017066882,-0.6153136540174522,-1.350549969999986
846.6000000000116,289.72230297832004,-0.6168110983198618,-1.3508799960927087
848.0000000000116,290.204141242849,-0.6187587080584223,-1.3498926563759088
849.4000000000117,290.68853732766627,-0.6169773971333252,-1.3502199586429162
850.8000000000117,291.1687020775304,-0.6237751170714754,-1.3502205494046335
852.2000000000116,291.64650123991214,-0.6242794354245249,-1.349890194999933
853.6000000000117,292.12060079847936,-0.6270220455096491,-1.349890194999999
855.0000000000117,292.5954495252509,-0.6318646054570909,-1.3498898560638968
856.4000000000118,293.07673788337365,-0.6349149811751276,-1.3508883355005072
857.8000000000118,293.55660297955484,-0.6384575543426161,-1.3508800148068976
859.2000000000118,294.0353356731507,-0.6423901072877243,-1.3508927173416696
860.6000000000118,294.51384798280304,-0.641696550586313,-1.3505432950961782
862.0000000000118,294.994957473587,-0.6393841163982499,-1.3513927235603345
863.4000000000119,295.4718599370284,-0.6458631166653865,-1.3502201150010777
864.8000000000119,295.95457223608264,-0.6464174714327684,-1.3515165780478258
866.2000000000119,296.42883437905715,-0.6457763346663219,-1.3502503893379516
867.600000000012,296.9013845025578,-0.6456919842404014,-1.3505596369251704
869.0000000000119,297.3807750046426,-0.6467814575603339,-1.3521991352826332
870.4000000000119,297.85590589977176,-0.6436791948444696,-1.3508003906332644
871.800000000012,298.337111392918,-0.6464164528335172,-1.3508800588138334
873.200000000012,298.81695344877704,-0.6475002942938786,-1.3495728335792392
874.600000000012,299.2978005919067,-0.6471197766050634,-1.3508801492738343
876.000000000012,299.7745785275194,-0.6485961041648789,-1.3502301303838231
877.400000000012,300.2545652325561,-0.6433102575003362,-1.35055922323677
878.8000000000121,300.73046506551145,-0.6470819565628894,-1.3515399000000001
880.2000000000121,301.2078899980291,-0.6403704011885343,-1.351565954939094
881.6000000000121,301.6848946155898,-0.6431637188319215,-1.352293196664101
883.0000000000122,302.1646297172433,-0.6388124572508054,-1.3505500382808724
884.4000000000121,302.6485032768248,-0.6369056452892878,-1.3515912189350838
885.8000000000122,303.13267233827906,-0.6406284015569876,-1.3515413525434
887.2000000000122,303.60768973781217,-0.6372565588838475,-1.351210024224112
888.6000000000122,304.08321316147016,-0.6379066884012232,-1.3515400951867709
890.0000000000123,304.5676891869288,-0.6408334073872632,-1.3514925643167568
891.4000000000123,305.0443443044885,-0.6425177713835684,-1.3518698367880009
892.8000000000122,305.5215716831985,-0.6402050656869478,-1.3515329622949062
894.0000000000123,305.9309696287376,-0.6487180254544591,-1.3519860441153497