File: 01_Data/Nylon_Carpet_Low_Pile/STA/N2/30K_min/Nylon_Carpet_Low_Pile_STA_N2_30KData_220107_R2.csv
##Temp./Â°C,Time/min,DSC/(mW/mg),Mass loss/mg
49.0,10.503912977487325,0.03287912021099937,0.005432608331041866
50.30000000000002,10.73374827205202,0.09284518997266777,0.006141031872350489
51.60000000000004,10.871641563050904,0.14000890192444682,0.0013973826960897995
52.900000000000055,10.97957672198477,0.1840895224535083,0.004028756366678099
54.200000000000074,11.07049068515956,0.22295699512979905,0.004953407839464408
55.50000000000009,11.151593991922347,0.254368755850981,0.008410367729046353
56.80000000000011,11.226412953736126,0.28539469979282217,0.008907195988089978
58.10000000000013,11.295794110067504,0.3140029115312788,0.003943098841110437
59.40000000000015,11.361268998688,0.34120590140455265,0.004002585846416995
60.700000000000166,11.42344641861993,0.3662517144444247,0.0027186841121964456
62.000000000000185,11.483708751637039,0.3866903122838118,0.005767486514687281
63.3000000000002,11.541521374428184,0.40813984040971774,0.0029634710042798496
64.60000000000022,11.597277631156592,0.42839659574945493,0.0026679687758353055
65.90000000000023,11.652778973101078,0.44933166441942124,0.003820826048689163
67.20000000000026,11.70568088298868,0.4661372608696782,0.002978506563963812
68.50000000000028,11.757849716741923,0.48338894098711643,0.0022310642966627547
69.8000000000003,11.809797314258736,0.5007406906891794,-0.00021816819671371945
71.1000000000003,11.860624946645736,0.516381238942712,0.0003915972188517358
72.40000000000033,11.9106761917464,0.5298477808481581,-0.0004827842884833622
73.70000000000036,11.960468974428276,0.5420837521302515,0.002364660185892209
75.00000000000037,12.009092799037996,0.5548786150493658,0.0033062011437792194
76.30000000000038,12.057734689967656,0.5662156460429996,0.004786879722690873
77.6000000000004,12.105301467965605,0.5747200568248206,0.006346746717207807
78.90000000000043,12.152707143825742,0.5872339985720736,0.0032211018036090167
80.20000000000044,12.200057495955626,0.5955296633877575,0.004599683600523985
81.50000000000045,12.247555488870006,0.6058539833329529,0.006157968531474101
82.80000000000048,12.293825709586052,0.6127507257705185,0.008355220491032878
84.1000000000005,12.33999288233973,0.623264480394772,0.01056850616057714
85.40000000000052,12.38592430578824,0.6280836468778959,0.010438342916562426
86.70000000000053,12.431513444319405,0.6364166408316436,0.010432243292658239
88.00000000000055,12.4774115940847,0.6447245156828838,0.009617344489059043
89.30000000000058,12.523105243794378,0.6543405709889176,0.008348752120558522
90.60000000000059,12.567854510755772,0.6588175484580483,0.00679822382967421
91.9000000000006,12.613039556532133,0.6686101006806896,0.002623948230337181
93.20000000000063,12.657722221664462,0.6794061026108216,-0.000870078894467774
94.50000000000065,12.70263786873855,0.6868227572788994,-0.002992752500158069
95.80000000000067,12.746788569554344,0.6951181315643578,-0.0016171426863968996
97.10000000000068,12.791250012008405,0.7008060535419101,0.00037828059246169943
98.4000000000007,12.835573966901748,0.709899611287789,0.0029859537197935992
99.70000000000073,12.879570311567818,0.7140571455770728,0.005028812972881269
101.00000000000074,12.923703330017968,0.719426489148124,0.006006527463562783
102.30000000000075,12.966895558317926,0.7244301410415949,0.005796288038355524
103.60000000000078,13.010215225780488,0.7299594119898332,0.004280311402958148
104.9000000000008,13.055487179968695,0.7354346859931977,0.004059287218414198
106.20000000000081,13.099751790936093,0.7399002906879825,0.0036802283372106004
107.50000000000082,13.143193896603394,0.7431116203867066,0.0013760884754905334
108.80000000000085,13.186778653344147,0.7474453957133045,0.0014432742132872711
110.10000000000088,13.230238315848693,0.7497538392724105,0.002738958381049983
111.40000000000089,13.274351203580391,0.7514972625600003,0.0027398166815824077
112.7000000000009,13.318054896719374,0.7528264130497578,0.002721549434688608
114.00000000000092,13.361461014927697,0.7563487078300702,0.0014011683560015697
115.30000000000095,13.404751035132128,0.7578527578830729,0.0027386969814076068
116.60000000000096,13.448412181909259,0.7612790761601812,0.0027489528704212063
117.90000000000097,13.491468752755024,0.7629726294562968,0.0022869594861845144
119.200000000001,13.53539196711705,0.7634701377896113,0.0014304366239996646
120.50000000000102,13.578264472713332,0.7664895744550809,0.0006780554734775457
121.80000000000103,13.621258794039166,0.7657486462152723,0.00012728423191488147
123.10000000000105,13.664372839520919,0.7679394646822701,-0.0012006183498378675
124.40000000000107,13.707495389401933,0.7689356224903057,-0.0011993213598286978
125.7000000000011,13.750057277803036,0.7694046394613864,4.409111297265511e-05
127.00000000000111,13.793097645508228,0.7727226573745649,0.003036294632555947
128.30000000000112,13.835694539021526,0.7737647640913896,0.004770264276965808
129.60000000000116,13.87849854098501,0.7728965967250305,0.004708836448921172
130.90000000000117,13.921191143791027,0.7772585576554464,0.003724432875026551
132.20000000000118,13.96373938631661,0.781336763341497,0.0011342680199795119
133.5000000000012,14.00586419895473,0.7819656869776848,-0.0010492897811440471
134.8000000000012,14.048449015986515,0.7865872701431268,-0.0009829345259930733
136.10000000000124,14.090563712658431,0.7890205183731953,0.00033068247666756534
137.40000000000126,14.132492190679237,0.7901662424446353,0.0015705828350385254
138.70000000000127,14.174495110314718,0.793911201483769,0.0016545792424063066
140.0000000000013,14.216645138901653,0.7983104777689973,0.002985163988166839
141.30000000000132,14.258406952957912,0.8030264393162678,0.0029626056741509643
142.60000000000133,14.29997174839757,0.8078658500118139,0.0016917800287186147
143.90000000000134,14.341720158505867,0.8125186339835486,-0.0012553348584840585
145.20000000000135,14.383399578635427,0.8190920885841868,-0.0012100618070580715
146.5000000000014,14.424881720776384,0.824667592597853,-0.0012099598691448499
147.8000000000014,14.46667760901836,0.832261539303046,-0.0012099601875736887
149.10000000000142,14.507991586562975,0.84204119026051,-0.0012100219006687674
150.40000000000146,14.549456025287967,0.8517470188218756,-0.0012252925971405482
151.70000000000147,14.59084335389396,0.860031632652202,-0.002211698649099869
153.00000000000148,14.63175550290609,0.8733272385392108,-0.002199885906192911
154.3000000000015,14.673500649546655,0.8848156883152557,-0.0021898339358696894
155.6000000000015,14.714545803328384,0.9027974167980612,-0.0007749376475283398
156.90000000000154,14.75590215263986,0.9221264312466536,-0.0031950581392874433
158.20000000000155,14.797037186840262,0.9389311532120349,-0.005579113672224523
159.50000000000156,14.838422533628206,0.9637687924172146,-0.006801421153567411
160.8000000000016,14.879553557998136,0.9854633798539929,-0.008318772147654752
162.10000000000161,14.920481078184094,1.0036263725628667,-0.006978048132656678
163.40000000000163,14.961709414837527,1.0167549117045855,-0.00823739920510258
164.70000000000164,15.002542270010144,1.019102797805561,-0.006970027361325126
166.00000000000165,15.043544699706109,1.0116821988463944,-0.004488784605698903
167.3000000000017,15.083992685963464,0.9996108778589109,-0.0006227271765433251
168.6000000000017,15.125108658010396,0.9791252240111713,0.0005947232261065416
169.9000000000017,15.16587508257513,0.9597110442005434,0.000525248138204315
171.20000000000175,15.206557087895904,0.942563604682574,0.0004981750331358725
172.50000000000176,15.246685118187571,0.9228563682249418,-0.0007417061065124742
173.80000000000177,15.288086223839795,0.9108061310658734,0.0006458745431641155
175.10000000000178,15.328088584995449,0.8979627527090417,0.0019820667563892336
176.4000000000018,15.36910946061215,0.8930153068167476,0.0014713975497109288
177.70000000000184,15.409533433116216,0.8877048529876876,0.0002241866996310904
179.00000000000185,15.44972865895568,0.8840411656840204,-0.00012793637292141113
180.30000000000186,15.490410785636442,0.880868913176465,-0.0004392121872198729
181.6000000000019,15.530691666038397,0.8823648497454148,0.0009471591892249442
182.9000000000019,15.570983637515564,0.8843840476085436,0.0008800805659565647
184.20000000000192,15.611206494581761,0.884204786461432,0.0008548584139300708
185.50000000000193,15.6519300088764,0.8891908551779281,-0.0017973201297274422
186.80000000000194,15.691641930216367,0.8940286003415064,-0.0017475321786086795
188.10000000000198,15.731713649537811,0.8975718067857197,-0.0030179004637926887
189.400000000002,15.772029815208818,0.9006433060996787,-0.004470688305296733
190.700000000002,15.811702051970018,0.9049204761310128,-0.0057489024832784175
192.00000000000205,15.851806271634228,0.9077549880019032,-0.007511975644887148
193.30000000000206,15.891978004863395,0.9142875550361707,-0.00836415871676488
194.60000000000207,15.93196131760241,0.9171971347258588,-0.008439565695970153
195.90000000000208,15.971660349498391,0.9238042568044926,-0.008425717136342215
197.2000000000021,16.011552003766035,0.9303917895061006,-0.007087785943675318
198.50000000000213,16.051742832213662,0.9353929843165961,-0.007129420951510923
199.80000000000214,16.091721189313837,0.9409258100884927,-0.007082309789021135
201.10000000000215,16.131280956770873,0.9478456955110104,-0.008427562185885584
202.4000000000022,16.171309733423836,0.9568674176145934,-0.008439951290327041
203.7000000000022,16.210878340504703,0.9644973793028176,-0.008481367775598159
205.00000000000222,16.250727073008665,0.9758686279730858,-0.009762913759431946
206.30000000000223,16.290765459857724,0.9865261165325209,-0.011057041315204241
207.60000000000224,16.330414508445912,1.000270791856885,-0.012404421473465987
208.90000000000228,16.37004559335124,1.017867833604773,-0.011700840922142408
210.2000000000023,16.40992167418957,1.0377515202700882,-0.009332306318998285
211.5000000000023,16.449976509793743,1.0753123615190001,-0.00943076040701829
212.80000000000234,16.48962875551458,1.1261065683912206,-0.009371955334361637
214.10000000000235,16.529264231164248,1.2008839075464568,-0.00943017340917729
215.40000000000236,16.569020792511896,1.2978493785686673,-0.010749422946145781
216.70000000000238,16.60889985219506,1.4151160790116293,-0.010750048982931304
218.0000000000024,16.648732710046055,1.5471195378528964,-0.010750054951183419
219.30000000000243,16.68854916385306,1.6768395188647844,-0.01075005499963444
220.60000000000244,16.728380173463645,1.7652283634203747,-0.010750055001774061
221.90000000000245,16.768466421116653,1.7842066300875405,-0.010750055307968243
223.2000000000025,16.80796474174628,1.7276117189815836,-0.010750150693485505
224.5000000000025,16.84798543795165,1.6334955432866896,-0.009244753242570347
225.8000000000025,16.887611893771165,1.5325358824264461,-0.007904331486360938
227.10000000000252,16.927028079379834,1.4360317319668694,-0.007887927983262877
228.40000000000254,16.96644174920164,1.351090645310607,-0.006554640113261456
229.70000000000258,17.005930580568286,1.2708066169833239,-0.006884480341866173
231.0000000000026,17.045364605162362,1.2073447386148135,-0.008116861250714091
232.3000000000026,17.084644770804818,1.1598682520253312,-0.008278145035358175
233.60000000000264,17.124125182522693,1.117496860552614,-0.00846290968523622
234.90000000000265,17.163482298995476,1.0861606369045824,-0.009767008148949596
236.20000000000266,17.202680152662086,1.0664819816765758,-0.009729662809332407
237.50000000000267,17.24219077219992,1.0495253743039845,-0.008443667035821889
238.80000000000268,17.281420535483065,1.035313405446625,-0.008450751698719117
240.10000000000272,17.320594628273433,1.0230059791467827,-0.00854644827836859
241.40000000000273,17.36004579477544,1.0177942952888561,-0.010276848464195076
242.70000000000275,17.399021732384515,1.0140488122924076,-0.011181686151784831
244.00000000000279,17.437638336321594,1.0072811745435066,-0.012509098873398461
245.3000000000028,17.47773071471451,1.0062366114821517,-0.013719421888718664
246.6000000000028,17.517147392974096,1.0050239016837734,-0.013819049380654036
247.90000000000282,17.55615606108559,1.0024394558161456,-0.013808153384477162
249.20000000000283,17.595627944756128,1.0022080355724003,-0.012477736076733414
250.50000000000287,17.634891653613874,0.999483256448386,-0.010103973300169766
251.80000000000288,17.67431164417103,1.0009838381468255,-0.009600497379954831
253.1000000000029,17.713528462565595,0.9981859429288151,-0.008546978294133645
254.40000000000293,17.75259225476361,1.000122926120018,-0.00861506992882477
255.70000000000294,17.791808774526537,1.0012952045899066,-0.008902290575266036
257.00000000000296,17.831506866659566,1.0003528164452375,-0.00899615497256434
258.30000000000297,17.870513210788182,1.0012682416344634,-0.010252012739320193
259.600000000003,17.90974599306006,1.0014488558378785,-0.011510425535894875
260.90000000000305,17.949018846637326,1.0000686105612773,-0.013513897739263037
262.200000000003,17.988566055762732,1.0027469366909751,-0.014158422673075766
263.50000000000307,18.027632697191816,1.0042566240546629,-0.015486818071619446
264.8000000000031,18.066928744459613,1.0034143860293072,-0.016218812851745312
266.1000000000031,18.106177515531627,1.0051706176555415,-0.016306716065202842
267.4000000000031,18.145016421498056,1.004977003786391,-0.015022717593502044
268.7000000000031,18.18456368781126,1.005650904431659,-0.015275980484897644
270.0000000000031,18.224102020020844,1.0051886412842497,-0.015677928583542666
271.30000000000314,18.263298553305564,1.0066530644015048,-0.01650594667190175
272.6000000000032,18.302672575279836,1.0057060892336642,-0.017106405083205267
273.90000000000316,18.341960186676737,1.005990744581213,-0.015709985942061078
275.20000000000323,18.3812873160635,1.0062429026831563,-0.015799683342245796
276.50000000000324,18.42059411394661,1.0066310752881393,-0.01580007881634815
277.80000000000325,18.459764424832304,1.0064484230387445,-0.015800030553281275
279.10000000000326,18.499319106638595,1.0076855511215765,-0.015797795603345488
280.4000000000033,18.538809296765685,1.008141406816071,-0.017221337690779936
281.70000000000334,18.578124900877306,1.007854771629398,-0.017220176049599356
283.0000000000033,18.61724160416251,1.0114917815964821,-0.01722190746063612
284.30000000000337,18.65681686262166,1.0080450521903261,-0.018584289775389617
285.6000000000034,18.696384322232067,1.0084086767285836,-0.018540488336357352
286.9000000000034,18.735539244528784,1.0094590858224108,-0.018549448436041338
288.2000000000034,18.774972535688303,1.009324671548519,-0.01724242852659197
289.5000000000034,18.814313465242208,1.0087979645809813,-0.018094292805995504
290.8000000000034,18.85303986018315,1.009576201612694,-0.0185322944251336
292.10000000000343,18.892998909261376,1.0093455180186848,-0.0198341307763803
293.4000000000035,18.932687547380016,1.0086513721736263,-0.019167603651778276
294.70000000000346,18.97218918313161,1.0088538955663588,-0.017918892502521988
296.0000000000035,19.011742197182915,1.007972533632236,-0.018536035671703477
297.30000000000354,19.05114812410645,1.0087632004972629,-0.018525953275973617
298.60000000000355,19.090654475261015,1.011665672597841,-0.018518956112546725
299.90000000000356,19.129900262893848,1.0107024171012646,-0.01999311738816223
301.20000000000357,19.169576323268732,1.0114140008046149,-0.020982306406787554
302.50000000000364,19.20910962941634,1.011880279942918,-0.021275244837085427
303.8000000000036,19.24863478564658,1.012653496236108,-0.022580174477214943
305.10000000000366,19.28784384997774,1.013935403173286,-0.022527534517906567
306.4000000000037,19.327577568186744,1.0148154779332998,-0.02390709353954934
307.7000000000037,19.36705503415488,1.0171713864211125,-0.02513342661270368
309.0000000000037,19.40664693239903,1.0165891421974915,-0.025214676585454843
310.3000000000037,19.445854755587106,1.0188053258341259,-0.02592730113432795
311.6000000000037,19.485447384328996,1.0187599672613756,-0.02588243209667551
312.90000000000373,19.525168046446947,1.0202475060934006,-0.026504823332069716
314.2000000000038,19.56495817626549,1.019355238858259,-0.02786199954259061
315.5000000000038,19.604235338496782,1.021639970401647,-0.027860034343442752
316.8000000000038,19.64403623782601,1.0201190655498371,-0.027860022062032197
318.10000000000383,19.68337686879217,1.0241491033945729,-0.027860023613113682
319.40000000000384,19.72330316649851,1.0230481314801005,-0.02786026684790599
320.70000000000385,19.76277931916533,1.0261843315792298,-0.02789911178406479
322.00000000000387,19.802328224216463,1.0274016477701444,-0.0279265941636897
323.3000000000039,19.84174597384478,1.030086533603295,-0.02644722019594825
324.6000000000039,19.8814671304244,1.0318869584057426,-0.02644486706880267
325.90000000000396,19.92110885336036,1.0362998675241495,-0.026445064664607276
327.20000000000397,19.960737698147167,1.0343613390664117,-0.027753791372346903
328.500000000004,20.000382747476493,1.0372004100082224,-0.030127835293075833
329.800000000004,20.040142883074765,1.0385938895953537,-0.031282810543346695
331.100000000004,20.079894295112386,1.0444964112425623,-0.033004955940478364
332.400000000004,20.11973387554852,1.048699085825553,-0.03535702668668117
333.700000000004,20.15933140988178,1.0524415554162996,-0.03707536031799252
335.0000000000041,20.198827051847168,1.0550478357713262,-0.0386131287240552
336.3000000000041,20.238899934675427,1.0613229281085093,-0.04004230850245438
337.6000000000041,20.278482233799732,1.0685543839110339,-0.0414432396103277
338.9000000000041,20.31849183603201,1.0717462284005252,-0.04217206853833799
340.20000000000414,20.358066003298237,1.0774794566282313,-0.042879086353608376
341.50000000000415,20.397852319965313,1.0827352164487918,-0.04411030500366042
342.80000000000416,20.437737030330997,1.0904377530450224,-0.044197112996597454
344.1000000000042,20.47761769794276,1.0978007423521015,-0.04546224561023671
345.4000000000042,20.517323000679596,1.1057996025502963,-0.04649654102172862
346.70000000000425,20.55740080146889,1.1152734655021876,-0.049001060023563525
348.00000000000426,20.59713745619839,1.123584076855936,-0.051567331940626904
349.3000000000043,20.636997322586527,1.1321328706194946,-0.05487605914471416
350.6000000000043,20.676810945580872,1.1420360322569003,-0.05848311240253734
351.9000000000043,20.716818389303185,1.1555137078611548,-0.0613389177777286
353.2000000000043,20.7568732147606,1.1654696376129061,-0.06432879837167294
354.5000000000043,20.796518643070673,1.177305774763236,-0.06671841656750699
355.8000000000044,20.836562262174724,1.192166842454936,-0.0706630361916396
357.1000000000044,20.876195143648545,1.2050384560047334,-0.0733691545242725
358.4000000000044,20.916554875395423,1.2203358584734572,-0.07756454471387775
359.7000000000044,20.956502526576983,1.2366760475298433,-0.08306428213661299
361.00000000000443,20.99639772457611,1.2525138560477738,-0.08905448062083776
362.30000000000445,21.036537168829327,1.2702251655638712,-0.09454353770431911
363.60000000000446,21.076705699264558,1.288809372849021,-0.098038859279729
364.90000000000447,21.116525000309192,1.3069511800002334,-0.10376041526401014
366.2000000000045,21.156718285972087,1.3294720307945342,-0.1096630139055792
367.50000000000455,21.197003570385565,1.3519483106105619,-0.11585810052913592
368.80000000000456,21.23678875143327,1.375203882792522,-0.1222450930658141
370.10000000000457,21.27709593928778,1.3979549909827567,-0.12869601413645126
371.4000000000046,21.317285938463275,1.4251013043647092,-0.13647018967514057
372.7000000000046,21.35754671760571,1.4480697232662958,-0.1432539306273819
374.0000000000046,21.39759898126649,1.4738927396200119,-0.15166997987653508
375.3000000000046,21.437350340848496,1.4994520497380202,-0.16104661618033012
376.6000000000047,21.477385394017244,1.5299110284487165,-0.16997321469383797
377.9000000000047,21.518383367709582,1.5561869447591385,-0.1792404832499983
379.2000000000047,21.55840640632064,1.5842054762422306,-0.1907252390147085
380.5000000000047,21.598495192516616,1.6155656474635265,-0.20161972379668036
381.80000000000473,21.638765817615475,1.6429846956636487,-0.213219843933528
383.10000000000474,21.678900141367418,1.6733515896285478,-0.22489475864031538
384.40000000000475,21.719073447254555,1.7056313054018908,-0.23700108718265378
385.70000000000476,21.75939141357015,1.7350064844746387,-0.24960928114103043
387.0000000000048,21.79965244115838,1.767237729515656,-0.26252324917573766
388.30000000000484,21.840345908062346,1.7975855246647032,-0.27530551726088204
389.60000000000485,21.880647535754736,1.8317771259877493,-0.2898228244187102
390.90000000000487,21.921069008306862,1.864733173095363,-0.3051743570034353
392.2000000000049,21.96127003471286,1.901649682814899,-0.3212482894512032
393.5000000000049,22.001748511865465,1.934661792271807,-0.3381623983120403
394.8000000000049,22.041906478369004,1.9689620526320704,-0.3546678229506459
396.1000000000049,22.08273600223517,2.009035970296425,-0.37294961616332767
397.400000000005,22.12315326006899,2.0479048213770725,-0.3910476040911486
398.700000000005,22.163485820814593,2.0850689521078714,-0.412342692643187
400.000000000005,22.204456873555895,2.12662215466146,-0.43316426331036606
401.300000000005,22.24466056389527,2.169280854582138,-0.45364944690839826
402.600000000005,22.285035137709983,2.2084551822898826,-0.47682289379425447
403.90000000000504,22.325934730389935,2.2504166007269686,-0.4993683198623877
405.20000000000505,22.366559686202574,2.2954140074162908,-0.5234186576662894
406.50000000000506,22.407242687247482,2.335762709953794,-0.548644925154413
407.80000000000507,22.447995642021667,2.3802312844712716,-0.5760422466325994
409.10000000000514,22.488604221876955,2.4224607837288463,-0.6030701737609752
410.40000000000515,22.529264150382517,2.464430675148735,-0.630113303664821
411.70000000000516,22.570116821427828,2.506467611624219,-0.6620314649217942
413.0000000000052,22.610732786770445,2.5474792616095003,-0.6926675237105413
414.3000000000052,22.651511818780456,2.5793290400536346,-0.7248498253649478
415.6000000000052,22.69212970828896,2.6135016581861477,-0.7567906320084208
416.9000000000052,22.733019630177083,2.6403425768484285,-0.7884074490644233
418.2000000000053,22.77385910299999,2.663059809093487,-0.8221859668653599
419.5000000000053,22.814615577238875,2.6812393492487736,-0.85600250957763
420.8000000000053,22.85538279052669,2.690388565108778,-0.8910250088688754
422.1000000000053,22.89639228010609,2.6919869408304695,-0.9267622462665108
423.4000000000053,22.937214660086195,2.679209538830649,-0.9649999510114116
424.70000000000533,22.977645652188674,2.6597211681767714,-1.0017646589225504
426.00000000000534,23.018919578007072,2.623628724834324,-1.0381629390960674
427.30000000000535,23.059654836977355,2.574604069435623,-1.0730385460347698
428.60000000000537,23.10034893168615,2.5037332558599044,-1.1093071536156867
429.90000000000543,23.141288842339886,2.421913721660223,-1.146570123773011
431.20000000000545,23.182293870399022,2.3226387460507723,-1.1812217886511949
432.50000000000546,23.22300369111785,2.2131037061751835,-1.213711000028483
433.80000000000547,23.263603380484177,2.095196605086916,-1.246598128766676
435.1000000000055,23.30446094170718,1.9647350838309958,-1.2743138371674627
436.4000000000055,23.345254454745675,1.839118579450532,-1.2999240215854364
437.7000000000055,23.385663805750696,1.7205668345231944,-1.3217957933390325
439.00000000000557,23.426555964007406,1.6051483240631044,-1.344428056233308
440.3000000000056,23.46720406516543,1.5049328782088902,-1.3647329977155902
441.6000000000056,23.50813693980969,1.4150518483187966,-1.3834505778136905
442.9000000000056,23.548736434786314,1.33859159258522,-1.4011954037018848
444.2000000000056,23.58973792576049,1.274006198775367,-1.418293674964119
445.5000000000056,23.630420782362926,1.2141690016881619,-1.4319585680809883
446.80000000000564,23.671143314622945,1.1700443275453476,-1.4449792185685468
448.10000000000565,23.711962206592876,1.1320913573940061,-1.4575173511605115
449.40000000000566,23.75272887634949,1.101686498459057,-1.4698489614435117
450.70000000000573,23.793644851799215,1.0769477652008965,-1.480899319516169
452.00000000000574,23.834442621640186,1.0556166856850273,-1.4924090232897846
453.30000000000575,23.87550173860048,1.0387587888280427,-1.5055652473932621
454.60000000000576,23.916574694626682,1.0232899128141935,-1.5166410438602709
455.9000000000058,23.957475722281234,1.0078152531353257,-1.5272024796598607
457.2000000000058,23.998291076059473,0.998389554464644,-1.5375754400819068
458.5000000000058,24.039607272119913,0.9894129154873472,-1.54712793882035
459.80000000000587,24.080718118133618,0.9840482430822692,-1.5591960227976385
461.1000000000059,24.121754241232736,0.9778596421802648,-1.570713567497299
462.4000000000059,24.162860891005,0.9741370551935802,-1.582740338235539
463.7000000000059,24.203924349902678,0.9707634972693078,-1.5932600541916506
465.0000000000059,24.24492274906925,0.9656358764532256,-1.6047213487906804
466.3000000000059,24.286113902492367,0.9615816717439674,-1.6150403475390758
467.60000000000593,24.327363683314957,0.9588167658469211,-1.6256367681078334
468.90000000000595,24.368350221375685,0.9565442280463339,-1.637502625452933
470.20000000000596,24.409647690640554,0.9520378266572398,-1.6468090549006922
471.500000000006,24.45090769688208,0.9503375766670181,-1.6576473878595794
472.80000000000604,24.492312241769614,0.9463099044133858,-1.6696859632828684
474.10000000000605,24.533455682345824,0.943913304924543,-1.6808821555964175
475.40000000000606,24.574850824609346,0.9420524287365728,-1.6938465919059795
476.70000000000607,24.615729915231874,0.9351644720710195,-1.7052318592830233
478.0000000000061,24.65732153078769,0.9323295828923479,-1.717689952202769
479.3000000000061,24.698625527005238,0.9280130531061297,-1.7290217619882813
480.60000000000616,24.740061357243768,0.9199316511823716,-1.741570222796418
481.9000000000062,24.781177523589466,0.9158326123528637,-1.755122770073117
483.2000000000062,24.822603527865024,0.907209898602364,-1.7665855580427428
484.5000000000062,24.864259651735157,0.8995577510004946,-1.7790743599536056
485.8000000000062,24.905734457152107,0.8926351390433784,-1.7916775156258704
487.1000000000062,24.94727547439465,0.8795545033823389,-1.803364173525496
488.40000000000623,24.988486083860796,0.8681325856393256,-1.8153790261851168
489.70000000000624,25.03004173768551,0.8554305371462712,-1.827456618956706
491.00000000000625,25.07158644278433,0.8367099531204742,-1.8390333032502229
492.3000000000063,25.113043896575782,0.8146878922907952,-1.8515701972389769
493.60000000000633,25.154387313709456,0.78903885876182,-1.8628703341081012
494.90000000000634,25.19610749979142,0.7584037629332179,-1.871982716866583
496.20000000000636,25.237430997789836,0.7181803974777814,-1.8807350401811411
497.50000000000637,25.27901064514402,0.6780705926233315,-1.8900781313046622
498.8000000000064,25.319860404752298,0.6364709147967738,-1.8988001144459212
500.1000000000064,25.361980839091306,0.5897676306832778,-1.9058566859333967
501.40000000000646,25.403713816793523,0.5446580355130695,-1.912283088752985
502.70000000000647,25.445617675958403,0.49782094623914186,-1.9168144377980307
504.0000000000065,25.487062605897403,0.4580766468174209,-1.921097897478448
505.3000000000065,25.528497914540505,0.4200675514938932,-1.9224459668554634
506.6000000000065,25.570370439466217,0.3905753926233533,-1.9241206075072879
507.9000000000065,25.612024158312344,0.3650653667743202,-1.9254437511851106
509.2000000000065,25.65373973349562,0.3434859261543386,-1.92680074833121
510.50000000000654,25.69538721522924,0.3274982840719345,-1.926766879099865
511.80000000000655,25.73727343267174,0.31414353725166344,-1.9287245284860828
513.1000000000066,25.778820189293057,0.3035726291974552,-1.928707668347168
514.4000000000067,25.820609886407194,0.2903568347425136,-1.929372531509134
515.7000000000066,25.86246132548085,0.28572144883083017,-1.9293800265830634
517.0000000000066,25.904105875487378,0.27832675730942613,-1.9293800520720592
518.3000000000067,25.946045374244935,0.2722648711003215,-1.9293788899338544
519.6000000000067,25.987875175578473,0.2699727869731494,-1.9303131806036822
520.9000000000067,26.029656386955683,0.26360838133043485,-1.9303548462440152
522.2000000000068,26.07158724161404,0.2604710563769044,-1.9290439963828239
523.5000000000068,26.113550797769236,0.25505340580461544,-1.929049896251683
524.8000000000068,26.155303999231357,0.25509511587761624,-1.9290190258635982
526.1000000000067,26.196938793145943,0.24565705970154506,-1.9307174807111047
527.4000000000068,26.239331202495144,0.23854640445747544,-1.9313730114114342
528.7000000000069,26.28123308911982,0.22730887955614065,-1.9320817491296118
530.0000000000068,26.3232302609863,0.22163013131271025,-1.9346404228140819
531.3000000000068,26.364965720520356,0.2216427634930298,-1.9360399648660804
532.6000000000068,26.406736992287186,0.22444178123212843,-1.9359601748119242
533.9000000000069,26.448604998541718,0.23260756727415854,-1.9345747353596816
535.2000000000069,26.490395231445532,0.2418869069303553,-1.9346493411865717
536.5000000000069,26.532360453252668,0.25393476559061456,-1.9346497713479813
537.800000000007,26.574673756656093,0.2634206429562833,-1.9346429206131974
539.100000000007,26.61626042796001,0.27375058495231164,-1.935451172677353
540.4000000000069,26.658329261454064,0.2802677723452791,-1.9369421278073262
541.700000000007,26.700265475735364,0.28542014388453696,-1.9382673880702828
543.000000000007,26.742209405754267,0.29044636250469935,-1.9375385624682422
544.300000000007,26.784310800512078,0.2925357099610153,-1.9375299878261338
545.6000000000071,26.826194883246945,0.2906622393810183,-1.9362862057119719
546.9000000000071,26.86843375505105,0.290790704353066,-1.936294393659531
548.2000000000071,26.91057003159087,0.28781936316165524,-1.9362973316085252
549.500000000007,26.952468790599827,0.2869041881729979,-1.936289876537523
550.8000000000071,26.99471662250716,0.2837517063283457,-1.9362898430780127
552.1000000000072,27.036789704417487,0.2785933173651891,-1.9362898411708875
553.4000000000071,27.078968752258074,0.2799708892809414,-1.9362897971448048
554.7000000000072,27.1210445172083,0.27313135564097335,-1.937694683266761
556.0000000000073,27.16321640653482,0.27160957514670603,-1.937610313180555
557.3000000000072,27.20504332691005,0.2686705290285647,-1.9376019044524142
558.6000000000072,27.247446563100105,0.26680804015559634,-1.936616602938038
559.9000000000073,27.289399970529796,0.2668015267080741,-1.9379308442251917
561.2000000000073,27.33149171102212,0.26351908916017885,-1.9379299984150107
562.5000000000073,27.3737880711945,0.2655487346520098,-1.9379299682793225
563.8000000000073,27.415983580973865,0.26190379702893596,-1.937929994277336
565.1000000000073,27.458272177042183,0.25787900365846816,-1.9379331702697096
566.4000000000074,27.500595113118372,0.2549403840288802,-1.938023218662698
567.7000000000073,27.54269485693753,0.2525715706092524,-1.9379200846261524
569.0000000000074,27.58509201027298,0.25022394200861253,-1.936567474723292
570.3000000000075,27.627239449056393,0.24911825937645427,-1.9365784737765992
571.6000000000074,27.669170637696297,0.2518903554105947,-1.9379274730984601
572.9000000000075,27.71202309231308,0.24776404875714864,-1.9375650826555955
574.2000000000074,27.754362161119598,0.24473747478236918,-1.936608266008815
575.5000000000075,27.796679878144285,0.24119665607899776,-1.93587846027981
576.8000000000075,27.838818617243724,0.23607196838268596,-1.9353006232561882
578.1000000000075,27.88112440840617,0.23332208041749114,-1.9366984367692361
579.4000000000076,27.923548156949018,0.22968681526009682,-1.9366386611257944
580.7000000000075,27.965983496180055,0.2264272608428599,-1.9379291320083927
582.0000000000076,28.008241702780772,0.2187956379323035,-1.9379298612589486
583.3000000000076,28.050647498450623,0.21568420480439254,-1.9379298676245216
584.6000000000076,28.092986344323972,0.2133437373182563,-1.9379296779532842
585.9000000000076,28.13523715660602,0.21228375445091263,-1.9389779309953066
587.2000000000077,28.177874983387436,0.21021287379205011,-1.9407753866886996
588.5000000000076,28.22055029722037,0.20591622134603993,-1.9434594764075581
589.8000000000077,28.263085340217042,0.21074708653830632,-1.9434204387258216
591.1000000000078,28.305407429115807,0.20953639063627127,-1.9433869234996348
592.4000000000077,28.347837374286122,0.20928787215660893,-1.9420869381465455
593.7000000000078,28.3902159104034,0.20907102894360863,-1.940817912848933
595.0000000000077,28.432788097704783,0.21329491700450154,-1.9421005271942375
596.3000000000078,28.475266021259156,0.21808770293033053,-1.9421001945758976
597.6000000000078,28.517736717846198,0.2189342474351923,-1.9421172787888104
598.9000000000078,28.560612042288387,0.22119554288093823,-1.9444036470250126
600.2000000000078,28.602791753608965,0.22489597373738723,-1.9415292900395538
601.5000000000078,28.645523959305308,0.228051445780594,-1.9438736549337143
602.8000000000079,28.687973484189172,0.23415134022056794,-1.9442889928731018
604.1000000000079,28.730347939939048,0.23577696293343964,-1.9441099414810061
605.4000000000079,28.773257515290897,0.24371791256533282,-1.9428285850905809
606.7000000000079,28.815917616941174,0.2464650607637875,-1.9441711882262838
608.000000000008,28.85864082471,0.25694716901990367,-1.944179811867314
609.3000000000079,28.901474513695383,0.26405758158099424,-1.9441766716547595
610.600000000008,28.943791805629193,0.2699697092060531,-1.9454191949482893
611.900000000008,28.986807783294136,0.2776175286580296,-1.9441736557926514
613.200000000008,29.029471094101215,0.2847356733983428,-1.94417313761919
614.5000000000081,29.071788548564413,0.29185079270189274,-1.9448849806873496
615.800000000008,29.114790599611148,0.3009549657964974,-1.944081879547765
617.1000000000081,29.15764365635975,0.3098876156298873,-1.9440801745103542
618.400000000008,29.199933885710337,0.31779210827571847,-1.9440796811366319
619.7000000000081,29.242635667292518,0.32467336376258293,-1.945012556901121
621.0000000000082,29.28548750585965,0.3363837754397059,-1.9454043566741928
622.3000000000081,29.32847299690176,0.34404774871565547,-1.9467159727388936
623.6000000000082,29.371164261825825,0.35344263647378504,-1.946721669688706
624.9000000000082,29.413976080265304,0.3642198826596843,-1.948026450062168
626.2000000000082,29.456583192908287,0.37227460394480794,-1.948020013853403
627.5000000000082,29.499369330515695,0.3818024947524856,-1.9480199959343132
628.8000000000083,29.54235443393604,0.3936485955878477,-1.9480197695780515
630.1000000000082,29.58506561121069,0.40534219397908977,-1.948976803755452
631.4000000000083,29.627749130533466,0.41623810297333996,-1.949333179230992
632.7000000000083,29.6706371766316,0.42678917687838247,-1.9514393984104799
634.0000000000083,29.713300248650672,0.43600481224213805,-1.9529613896386162
635.3000000000084,29.75647473353331,0.448715819026277,-1.9534429942613354
636.6000000000083,29.799170662314445,0.45833298037449755,-1.9539799623558514
637.9000000000084,29.84219364093556,0.4707688085074886,-1.955288711778461
639.2000000000083,29.885183149909384,0.4827603594571621,-1.9560611581094762
640.5000000000084,29.92824820294699,0.49516444378744495,-1.9573758703634434
641.8000000000084,29.97116037824204,0.5054179695735179,-1.9573436738021255
643.1000000000084,30.013842441766624,0.5188189069212314,-1.9572914080661201
644.4000000000085,30.056746982983924,0.5316085836944251,-1.958665366460469
645.7000000000085,30.0996699854709,0.5453741697033165,-1.9599770434751482
647.0000000000085,30.142722482576005,0.5601030225713863,-1.960835679218099
648.3000000000085,30.185738155677758,0.5765008051852494,-1.9626096376185802
649.6000000000085,30.228309487722928,0.5952741627531113,-1.9640421421063339
650.9000000000085,30.27101687316657,0.6131213221525207,-1.9653270827254756
652.2000000000086,30.314332541729456,0.6370233634367959,-1.9676902245602448
653.5000000000086,30.357110090734302,0.6580737208981193,-1.9693634211487279
654.8000000000086,30.399863573377818,0.6813900425734571,-1.9706142290178472
656.1000000000087,30.44301895134968,0.7081455755198056,-1.9718413803180561
657.4000000000086,30.485914568365065,0.7338811600144304,-1.972491618108955
658.7000000000087,30.529169661881852,0.7604402632337481,-1.9735803533568514
660.0000000000086,30.57156243215521,0.7866284485465092,-1.9749187224457736
661.3000000000087,30.61477101218515,0.8105807704617924,-1.976267418286001
662.6000000000088,30.65732917745754,0.837890312894888,-1.9786522418800536
663.9000000000087,30.70061687567298,0.8702542779900804,-1.9808030210363285
665.2000000000088,30.743232546082226,0.8970800262591254,-1.982704574293391
666.5000000000088,30.78633273455716,0.9289367495115717,-1.9850366338910457
667.8000000000088,30.829039304786154,0.9657380586435194,-1.985968084429685
669.1000000000088,30.87229350952165,0.9992035400853312,-1.987653597817795
670.4000000000088,30.915083362541846,1.03620198605525,-1.9881471882550517
671.7000000000088,30.95813517773734,1.0749797327475736,-1.98933669462347
673.0000000000089,31.001031614471042,1.1114232767866987,-1.989997227241099
674.3000000000089,31.04400423396055,1.1460603436522856,-1.991037729492145
675.6000000000089,31.086986787247454,1.18634617001507,-1.992995221435415
676.900000000009,31.129748063119656,1.2195309665187484,-1.9948759111416212
678.2000000000089,31.173017250074963,1.2621954756298428,-1.997568474925242
679.500000000009,31.2161412244986,1.3013349940041428,-2.0011375670704314
680.8000000000089,31.259301838196993,1.3410626224708029,-2.0051847368330917
682.100000000009,31.30240285739811,1.3850870377483582,-2.010224035729128
683.400000000009,31.345346755462675,1.429016279194253,-2.0146268717394613
684.700000000009,31.388348214547513,1.475517486936119,-2.0176177962564057
686.0000000000091,31.43146736221275,1.520155026224625,-2.0192045654633946
687.300000000009,31.474745832512777,1.569050751636604,-2.019566842616422
688.6000000000091,31.517594464700576,1.6202906276043523,-2.0212718050792535
689.9000000000091,31.56102324086099,1.6717049851987134,-2.0231288107215555
691.2000000000091,31.604205161497315,1.7253748443343802,-2.0291316900944962
692.5000000000091,31.64740527931647,1.7835086489846304,-2.032930155681023
693.8000000000092,31.690685721324463,1.8408707007284764,-2.036930995429694
695.1000000000092,31.733753181416986,1.9041801568749315,-2.043940708705334
696.4000000000092,31.777350470461638,1.9677164907538378,-2.048666502088022
697.7000000000093,31.819391036468502,2.0333969988892044,-2.053677939283997
699.0000000000092,31.863169278043195,2.0976992985411025,-2.0586505646499895
700.3000000000093,31.9068764241809,2.1724404120453884,-2.063861878849279
701.6000000000092,31.950265169359188,2.247444018962874,-2.0687229402482554
702.9000000000093,31.99359579039458,2.3239744930907613,-2.0738383688996738
704.2000000000094,32.03673285813694,2.4050265586043826,-2.0797160329938196
705.5000000000093,32.07992727424338,2.485432363868881,-2.0852233973527063
706.8000000000094,32.12336225292932,2.5753032115562666,-2.092715273286757
708.1000000000093,32.1666884220982,2.6641495030369766,-2.0969953180034504
709.4000000000094,32.2098430063489,2.763855571031119,-2.10302420158252
710.7000000000094,32.25330018621817,2.8595905264946504,-2.1088103564225795
712.0000000000094,32.296755451315896,2.9651125809384262,-2.1163217157613614
713.3000000000094,32.33986104212191,3.0693718872423412,-2.122582386127693
714.6000000000095,32.383403813291785,3.1768407674102543,-2.1305604514298344
715.9000000000095,32.42668675976343,3.2932326514692254,-2.1391170608171146
717.2000000000095,32.470256320058574,3.4123388490530164,-2.1480884647365217
718.5000000000095,32.513577091889736,3.535657547126878,-2.1579632026376174
719.8000000000095,32.55723225496111,3.6562895416758696,-2.1686979560138195
721.1000000000096,32.60071982967897,3.7860171555973894,-2.1773574628790495
722.4000000000095,32.64422553266285,3.9112042447984727,-2.1848814137597246
723.7000000000096,32.68756434130343,4.036270048172551,-2.195534416134772
725.0000000000095,32.731006433571466,4.159886087727678,-2.2052235192049015
726.3000000000096,32.7742630877796,4.2856709572479605,-2.214423331264033
727.6000000000097,32.818036341868634,4.408835540695315,-2.2286359632786716
728.9000000000096,32.86103517455975,4.528134773907672,-2.242406120455913
730.2000000000097,32.90478802806284,4.648882695092528,-2.2556031922089983
731.5000000000097,32.948169993671684,4.766888511138038,-2.267253105578152
732.8000000000097,32.99148579246317,4.881281414663748,-2.2796213694260747
734.1000000000097,33.03501894197005,4.996045368765001,-2.2915663165144173
735.4000000000098,33.07871847264452,5.1091626294039125,-2.3032016266594173
736.7000000000098,33.12223158044374,5.219915022878143,-2.3151892995031007
738.0000000000098,33.16566251878041,5.333149716047151,-2.330199810672392
739.3000000000098,33.20913594562796,5.439655707155443,-2.346186584294653
740.6000000000098,33.252245078287686,5.5453388548317655,-2.3594764230035246
741.9000000000099,33.29604710448106,5.646743197588277,-2.374665912533312
743.2000000000098,33.338784677314614,5.747119017619711,-2.388203188084084
744.5000000000099,33.383111529244985,5.848555155442607,-2.4020621707435805
745.80000000001,33.426534924257034,5.937962713188838,-2.419146900678146
747.1000000000099,33.46990570684278,6.023577853494073,-2.4337072227681986
748.40000000001,33.51360468434229,6.107953074850894,-2.449149153538505
749.7000000000099,33.557317356968994,6.185146850965873,-2.4652574856610645
751.00000000001,33.600689165617226,6.256511277003003,-2.482055553441182
752.30000000001,33.64344616944743,6.317499326482041,-2.4968772323438015
753.60000000001,33.68792834752001,6.376984997280102,-2.51389739989855
754.90000000001,33.73138334974348,6.421755436053784,-2.5322016853660796
756.20000000001,33.77487879821955,6.455313346366736,-2.549089964444112
757.5000000000101,33.81829719055836,6.478369928283955,-2.5679847574043224
758.8000000000101,33.86194347134198,6.484506253658433,-2.5855730514268944
760.1000000000101,33.90529811168502,6.471035879546455,-2.6018015065553515
761.4000000000101,33.94887597478284,6.441936696374762,-2.619520661341677
762.7000000000102,33.992475744639265,6.387108281533484,-2.636727999158442
764.0000000000101,34.03598316720995,6.295092674777193,-2.6548209171298818
765.3000000000102,34.079787795314104,6.163002689025145,-2.6718280322006933
766.6000000000101,34.123026433425004,5.979211229398634,-2.6888494104193272
767.9000000000102,34.166110366309624,5.7156852507912514,-2.704557857645929
769.2000000000103,34.209433272032975,5.324973146021421,-2.719762711292139
770.5000000000102,34.25276161875257,4.73058476466225,-2.733334236209609
771.8000000000103,34.295954630306966,3.75007090563139,-2.745337853164883
773.1000000000103,34.33879996014434,2.2750771186362315,-2.7524157798035116
774.4000000000103,34.38146755894985,1.3215130662155055,-2.7587010738907205
775.7000000000103,34.42423353198166,0.7919685286878013,-2.760121953124428
777.0000000000103,34.46710052644247,0.4898136004279383,-2.762761529667714
778.3000000000104,34.510137453641384,0.3135209959901104,-2.7614161914835407
779.6000000000104,34.55243123626826,0.20630299358050364,-2.7628981288028522
780.9000000000104,34.59659515049995,0.13352775291411056,-2.762935000506435
782.2000000000104,34.64003946105112,0.08296906294193107,-2.7615602037823477
783.5000000000105,34.68368607919059,0.05633271893649461,-2.7608539644621546
784.8000000000104,34.727271473857094,0.03174191287080097,-2.7587825874254426
786.1000000000105,34.77108676218004,0.019481214849257356,-2.7586573745960603
787.4000000000106,34.814495166309364,0.012372524771480098,-2.7602070530962615
788.7000000000105,34.85846571531849,0.004947305390600842,-2.760140342823395
790.0000000000106,34.90184814090068,-0.0016363636482830124,-2.7599324156503324
791.3000000000105,34.945176704373104,-0.0036194281772474746,-2.758883980247782
792.6000000000106,34.98903316082054,-0.0007541045819832171,-2.75884500785825
793.9000000000106,35.032772834152595,-0.004388610268550863,-2.7590040793299537
795.2000000000106,35.07627549888147,0.0018222885461978144,-2.7601413730080124
796.5000000000106,35.11981747797526,-0.00011971577711733516,-2.760853504359417
797.8000000000106,35.16344427090175,-0.001040023243637389,-2.761514638440706
799.1000000000107,35.20707535384929,-0.0020306789997510677,-2.7628243881596246
800.4000000000107,35.250729553291315,-0.005618850516449392,-2.76155533914388
801.7000000000107,35.29443151705615,0.001001824475317381,-2.76277066438423
803.0000000000107,35.338019444759446,0.0028865693498496547,-2.7627716970889225
804.3000000000108,35.38187204625495,0.00279314816612386,-2.7610140579130404
805.6000000000107,35.42553746965084,0.011533969762528962,-2.760803113502191
806.9000000000108,35.469203183248204,0.010451582695458761,-2.762123749795565
808.2000000000107,35.513008731538854,0.01737235250333935,-2.7634989780609724
809.5000000000108,35.556565933364794,0.01578801239665495,-2.7636526732883713
810.8000000000109,35.60023026852416,0.014561403773504455,-2.7621226541799464
812.1000000000108,35.643802034874064,0.020020105823367995,-2.7594306479514343
813.4000000000109,35.687446685131775,0.021183622831529636,-2.760541936446667
814.7000000000108,35.73124053172306,0.019733699075222155,-2.7620997407335395
816.0000000000109,35.77469407868626,0.01976446716356728,-2.7608839846371453
817.3000000000109,35.81825214393075,0.016959171271703433,-2.7594809622714
818.6000000000109,35.862207273172324,0.020748372437903395,-2.7604564724518643
819.900000000011,35.90582549610503,0.01994252670721286,-2.7648868037609473
821.200000000011,35.949505282777736,0.020269650612142254,-2.7673725939941516
822.500000000011,35.993250472299366,0.021533849308849273,-2.768754333951623
823.800000000011,36.037002660375606,0.020881359009040423,-2.7686984871319975
825.100000000011,36.08070541768461,0.021963826034960388,-2.767397605951219
826.400000000011,36.124597747167336,0.01717162756599011,-2.7673799210529433
827.7000000000111,36.168258487020566,0.021099500211644084,-2.767367924493617
829.0000000000111,36.21188961029832,0.019738611435113906,-2.7652833942151145
830.3000000000111,36.25559685370641,0.01950674140979025,-2.7642842137607273
831.6000000000112,36.299101464263885,0.02133423199087492,-2.7631673846464215
832.9000000000111,36.342855057173246,0.021637314613236924,-2.7624393711276665
834.2000000000112,36.38671899025342,0.023213675972972858,-2.7633806479442335
835.5000000000111,36.430345765141915,0.020019939671875875,-2.7647406653984214
836.8000000000112,36.47425243394856,0.021699578158615118,-2.7643870577921175
838.1000000000112,36.518280611762144,0.022224394785977708,-2.7634296873213984
839.4000000000112,36.562182549875395,0.023983865124170833,-2.763429932715452
840.7000000000113,36.605901183447756,0.023223909524891617,-2.7634299320294238
842.0000000000113,36.64987704948322,0.02436206435307131,-2.763429929717881
843.3000000000113,36.69338906942736,0.020978234879363455,-2.7634269672352882
844.6000000000113,36.73724861149088,0.021894897942594582,-2.764679823934105
845.9000000000113,36.78116604379928,0.020650245297564318,-2.763406685132569
847.2000000000113,36.825188043589826,0.019244321409612297,-2.7647388285264034
848.5000000000114,36.86883005132868,0.019992180626056566,-2.764749977912535
849.8000000000113,36.912767786337255,0.024674421657811862,-2.764750080808566
851.1000000000114,36.956740868189144,0.024358930897592224,-2.7647731019490127
852.4000000000115,37.00061973794882,0.02363647682957737,-2.766058916944258
853.7000000000114,37.0444013649926,0.03335580710676567,-2.766060074181255
855.0000000000115,37.08840953052433,0.03307068421438064,-2.7660600820226238
856.3000000000114,37.13230378866334,0.034046440324101646,-2.7660600257195442
857.6000000000115,37.17650148305468,0.03865881548752892,-2.7660434910523217
858.9000000000115,37.220355377233616,0.04062106922743158,-2.763771340957426
860.2000000000115,37.26434501625752,0.045434455655500194,-2.7637601349626113
861.5000000000116,37.30824903851675,0.045015374123233975,-2.7637598618666943
862.8000000000116,37.35212312595092,0.04367639963980707,-2.7638889606566606
864.1000000000116,37.396156235901714,0.04758370716681437,-2.7650742441461023
865.4000000000116,37.44004297814098,0.05017308142674093,-2.7663784076078977
866.7000000000116,37.48414113638808,0.05168527216724872,-2.7663899312303846
868.0000000000116,37.52782314617978,0.05320690638049985,-2.7663838072084266
869.3000000000117,37.57171787574477,0.05080117932457817,-2.7678691793680987
870.6000000000117,37.61575495854799,0.05424613306771686,-2.769020294323893
871.9000000000117,37.6596790441837,0.051133373229543366,-2.7690197814670348
873.2000000000118,37.70367821123642,0.04902688477410155,-2.7676040549295626
874.5000000000117,37.74759884373838,0.05339768073452866,-2.76769871976761
875.8000000000118,37.79153709906671,0.05279122836029426,-2.7668639080276627
877.1000000000117,37.83546486507841,0.051391534736719535,-2.7658086300770575
878.4000000000118,37.87946972029311,0.05555455733206127,-2.7650668089362282
879.7000000000118,37.92338641567334,0.06123988975171013,-2.7660553116671047
881.0000000000118,37.96730276281587,0.06307295072063734,-2.7660599191551407
882.3000000000119,38.011208720098644,0.061463927306762756,-2.766059928027831
883.6000000000118,38.055019506893395,0.06326713971538744,-2.7660599282604847
884.9000000000119,38.09906583318662,0.07250202005504303,-2.7660599309040803
886.2000000000119,38.14297688594349,0.0748600107139783,-2.7660313930072906
887.5000000000119,38.18672692669779,0.08060410643046545,-2.7663911151935205
888.8000000000119,38.230637338182895,0.08464719391473974,-2.766389859740395
890.100000000012,38.274772312685315,0.08866820188274893,-2.766403934643975
891.0000000000119,38.30511251100894,0.08655242029561805,-2.767558533741745