File: 01_Data/Nylon_Carpet_Low_Pile/STA/N2/30K_min/Nylon_Carpet_Low_Pile_STA_N2_30KData_220105_R1.csv
##Temp./Â°C,Time/min,DSC/(mW/mg),Mass loss/mg
49.0,10.516320613736367,0.01898066779593388,-0.02072733637328117
50.100000000000016,10.71619298509904,0.07632866099749913,-0.018590648799649223
51.20000000000003,10.840791112687382,0.12383784285850774,-0.0177844992222429
52.30000000000005,10.938670371137867,0.16329022508829005,-0.018488480784315975
53.40000000000006,11.02287748597931,0.2014479276956751,-0.019321927399246874
54.50000000000008,11.096881331786827,0.23518538542778927,-0.0185983356175754
55.600000000000094,11.164254559590907,0.2623965156719812,-0.017646514946778602
56.70000000000011,11.227292618882199,0.29044065666363794,-0.017030525356136472
57.800000000000125,11.287069878549229,0.3155467126385509,-0.018599513966050196
58.90000000000014,11.34328234923493,0.33988101590843117,-0.01794361376362552
60.000000000000156,11.397234307745732,0.36212882359415594,-0.01881509028525219
61.10000000000017,11.449133066678321,0.3831879908836629,-0.018950265907585084
62.20000000000019,11.499001453765226,0.40357267997061597,-0.018592075984263268
63.3000000000002,11.548320808791926,0.4216332939788675,-0.018886514321987846
64.40000000000022,11.594906316783991,0.43941197776445373,-0.017803458072743972
65.50000000000023,11.642383760215859,0.4533186942006249,-0.01956385595517407
66.60000000000025,11.688051216464038,0.47290269452627415,-0.01947982331811904
67.70000000000027,11.732588624060039,0.48706939154403506,-0.019224303679588495
68.80000000000028,11.776817056567019,0.5033415272063982,-0.018436056697263226
69.90000000000029,11.820797512616359,0.5152492391657586,-0.018856353558862615
71.00000000000031,11.863335955198433,0.5298510288367452,-0.017543336287503486
72.10000000000034,11.90622126733457,0.5430210454660066,-0.019287795508796002
73.20000000000034,11.948456466617422,0.554316376717995,-0.019554601612045808
74.30000000000035,11.990149751697443,0.5625986247123569,-0.01964104047609716
75.40000000000038,12.031205997728298,0.5749350031679131,-0.020362270621904877
76.5000000000004,12.071987174243812,0.5856145993081829,-0.019027135780831372
77.6000000000004,12.112449673222939,0.5936521067277964,-0.019504013879701354
78.70000000000041,12.15258443938643,0.6033715904768029,-0.018789830448948663
79.80000000000044,12.193217181846148,0.6147933840727537,-0.018293779572585933
80.90000000000046,12.23312961484766,0.622410702850228,-0.019271185246948264
82.00000000000047,12.272543043147122,0.6303109622526217,-0.02160773529319293
83.10000000000048,12.311407652598964,0.6384658396152824,-0.021331836946961502
84.2000000000005,12.351477436842577,0.6456079352403205,-0.020219926709999392
85.30000000000052,12.389759369706711,0.6536722820992942,-0.021119151396594482
86.40000000000053,12.428824294461954,0.6596065350730993,-0.019835721296079356
87.50000000000054,12.467766295957222,0.6673218271465602,-0.019978807076500793
88.60000000000056,12.505916096727889,0.6741310354572465,-0.020420517626630108
89.70000000000059,12.544351580647973,0.68151942198643,-0.02158096931530995
90.8000000000006,12.582485082026778,0.6866240702921775,-0.021109599740229967
91.9000000000006,12.620809829962433,0.6935900539835193,-0.02044508861382255
93.00000000000063,12.65841863794428,0.6992224561410373,-0.02159056596420239
94.10000000000065,12.696385665679335,0.7061768225604602,-0.020118992346763065
95.20000000000066,12.734282297690434,0.7095898922983901,-0.02126494502642462
96.30000000000067,12.771704172339446,0.7184107266149318,-0.02017612869104024
97.40000000000069,12.809186179748066,0.7217904803965609,-0.020205217973297884
98.50000000000071,12.846674534541187,0.7292829764965701,-0.021377952644677123
99.60000000000072,12.884003093944958,0.7345156540202153,-0.021146556885856427
100.70000000000073,12.92127563620891,0.7386017578342832,-0.020945179324601604
101.80000000000075,12.958924119922752,0.7453033567441616,-0.021593996633809454
102.90000000000077,12.995939135408388,0.749122294904368,-0.021512955221699492
104.00000000000078,13.033103268913663,0.7549331156257921,-0.022427360221547232
105.10000000000079,13.070269359337663,0.7557731057317025,-0.022810273035765327
106.20000000000081,13.107579144161308,0.7605085085630685,-0.02141835159227501
107.30000000000084,13.144310146325092,0.7649078129019771,-0.022814936676470055
108.40000000000084,13.181814507912163,0.766707431423736,-0.022817007892909302
109.50000000000085,13.218653528392437,0.7692447809081087,-0.023833098619976845
110.60000000000088,13.255616184372721,0.7742364451201678,-0.024129553975898332
111.7000000000009,13.29284071798903,0.7729506723238674,-0.024375509297139608
112.8000000000009,13.329447388421999,0.7762947620322027,-0.024131135614415378
113.90000000000092,13.36606715533996,0.7775897299134737,-0.02417757189023728
115.00000000000094,13.403195285624486,0.7781541401421035,-0.023798162065747697
116.10000000000096,13.4399647425427,0.7815763053789779,-0.023156217621439268
117.20000000000097,13.476767666751067,0.7833892511999248,-0.02414405532764352
118.30000000000098,13.513574898631376,0.7851807418457539,-0.02413028011642382
119.400000000001,13.550100361258076,0.7857581365286286,-0.024457061125487733
120.50000000000102,13.586474739596357,0.7866495802427733,-0.024781430944736726
121.60000000000103,13.62310898816261,0.7891397812590222,-0.024098801244458734
122.70000000000104,13.660193424582953,0.7903092626181935,-0.024130060095187922
123.80000000000106,13.696041740476533,0.7907943249416441,-0.02413069822439784
124.90000000000109,13.732324422016315,0.7911238761809973,-0.024053676910098964
126.0000000000011,13.768837414637268,0.7926410775787135,-0.02544994978064441
127.1000000000011,13.80490237570605,0.7956151330504331,-0.026813399076137223
128.20000000000113,13.84036801057814,0.7959693045407347,-0.02676885895142256
129.30000000000115,13.877155270392317,0.7983810187429783,-0.026770061140860335
130.40000000000117,13.913488659291978,0.803592037068435,-0.026770262913208498
131.50000000000117,13.948716795667828,0.8028491463093756,-0.026762826778496063
132.6000000000012,13.985024177358998,0.8048912311076157,-0.025459978314159137
133.7000000000012,14.020552770396478,0.8082057104431286,-0.026758495130762228
134.8000000000012,14.056529432926155,0.8124916214775748,-0.026757742624021752
135.90000000000123,14.092586053171075,0.8155548557755912,-0.028122771568485305
137.00000000000125,14.127778928945583,0.8169680911418432,-0.02808073742730155
138.10000000000127,14.163281440307722,0.820499040847736,-0.028080173715033574
139.2000000000013,14.199040447501476,0.8218565807818998,-0.028080174952273218
140.3000000000013,14.23480110666301,0.825079187052801,-0.028080175000018137
141.4000000000013,14.269582520175677,0.8306668347593673,-0.028080174998917684
142.50000000000134,14.30519570657626,0.8337856867854279,-0.028080174172554706
143.60000000000133,14.340807409101641,0.837726108887155,-0.028080150365694223
144.70000000000135,14.375245172932658,0.8428939589363955,-0.028087764524825864
145.80000000000138,14.41134342053607,0.8484158806504045,-0.028403799307797684
146.9000000000014,14.446049291727352,0.8522366401941697,-0.028409983543694395
148.00000000000142,14.481312631560415,0.8575033696845343,-0.028409813336032208
149.10000000000142,14.516316576145927,0.8655263756243046,-0.028407191107887364
150.20000000000144,14.55130023737817,0.8719000322195753,-0.029096218551751818
151.30000000000146,14.586497524895126,0.8823530998825228,-0.029720884098559885
152.40000000000146,14.621681055640847,0.8919875474795694,-0.02967517088997962
153.50000000000148,14.656437581306326,0.9031706404847334,-0.031027931292001654
154.6000000000015,14.691122068912277,0.9159959859478318,-0.03104002027280739
155.70000000000152,14.72592416888546,0.9312756023757311,-0.03103984601881482
156.80000000000155,14.760422292340154,0.9460406130979965,-0.031039844980560893
157.90000000000154,14.795734563132399,0.9629369888427439,-0.03103984499990453
159.00000000000156,14.83049073419772,0.98081779313905,-0.031039845000038646
160.1000000000016,14.865164131630483,0.999879352659356,-0.031039845008455913
161.20000000000158,14.900061628133798,1.0154734930479943,-0.031039844552284812
162.3000000000016,14.934687799648254,1.0301406307267662,-0.031039776448505307
163.40000000000163,14.969402650586995,1.041750806819865,-0.031045136416568475
164.50000000000165,15.00407282586672,1.0448297358640826,-0.033072318557520575
165.60000000000167,15.038446649802525,1.038599023552698,-0.033018593739222446
166.70000000000167,15.073212619827272,1.0296535442726622,-0.03301995244749545
167.8000000000017,15.108199416580131,1.0150421007949793,-0.03299927916615619
168.9000000000017,15.142353396546532,0.9998414275956775,-0.033345762715415894
170.0000000000017,15.176804114247606,0.9865941044635338,-0.033350026335741134
171.10000000000173,15.21115681462088,0.9709197797170147,-0.03335007080333341
172.20000000000175,15.245420764145683,0.9545883721287929,-0.03335007000011814
173.30000000000177,15.280126231102606,0.9437880135450184,-0.03335007063843065
174.4000000000018,15.31462698020815,0.932607338538225,-0.03335006211578495
175.5000000000018,15.348804057118674,0.9245103396116775,-0.03334450004368428
176.6000000000018,15.383026574444775,0.9176580936295646,-0.034695399456770026
177.70000000000184,15.41732779220091,0.9156643181547426,-0.034660494829801713
178.80000000000183,15.451359446202275,0.9098792259590489,-0.03466006371910968
179.90000000000185,15.485231859908415,0.9072710058374742,-0.034660068758271656
181.00000000000188,15.519725974267773,0.9091294586581224,-0.03466008026431133
182.1000000000019,15.553789912115965,0.9097953855841503,-0.03466997405895267
183.20000000000192,15.587739118917847,0.9096045306411804,-0.03587516748263209
184.30000000000192,15.621727083808649,0.9113885814648754,-0.035969325040370315
185.40000000000194,15.655571312675278,0.9125682481293992,-0.035978054799714165
186.50000000000196,15.689012469502615,0.9158086441069595,-0.034606114368954444
187.60000000000196,15.723272427453402,0.9168093034311169,-0.034660126442759065
188.70000000000198,15.757294973348571,0.9192329931656928,-0.0346580888897261
189.800000000002,15.791251145414382,0.9229579395257195,-0.03501612711752866
190.90000000000202,15.825131896317828,0.9261845749678702,-0.03596984068971043
192.00000000000205,15.858792225411023,0.9295849989103679,-0.03596976793624318
193.10000000000204,15.892514984408576,0.9330496315854422,-0.03596984064661335
194.20000000000206,15.926283621138275,0.936520909066129,-0.03596984000322667
195.3000000000021,15.960209963493153,0.942404813266377,-0.03596983999414416
196.40000000000208,15.993922456921997,0.9459028143258483,-0.03596984667773295
197.5000000000021,16.02776681988516,0.9526997362521831,-0.03596947856628763
198.60000000000213,16.061371721361446,0.9565611370794839,-0.036428132974604566
199.70000000000215,16.09504930811326,0.9626314862317468,-0.03729681304565258
200.80000000000217,16.12862760508162,0.9701710065741347,-0.03728534392420979
201.90000000000217,16.162254973011816,0.9778313872874274,-0.03799028678403982
203.0000000000022,16.195942265118806,0.9802426301292263,-0.03917025551744224
204.1000000000022,16.22974566172954,0.9901842794389815,-0.03926913536818777
205.2000000000022,16.263490048180085,0.998290221607435,-0.03931168546205477
206.30000000000223,16.29681663938207,1.0071432693864077,-0.03795912647054411
207.40000000000225,16.330604811137043,1.0199348518911804,-0.03794963454550704
208.50000000000227,16.364206930631216,1.0331400245752123,-0.03794973122945233
209.6000000000023,16.397703455621773,1.0519681966112633,-0.037957885585628404
210.7000000000023,16.431401664519154,1.078866017078274,-0.038273615233825
211.8000000000023,16.46468831262877,1.111271409170331,-0.03827785663285166
212.90000000000234,16.498456313019936,1.1632785537379475,-0.039369454752799626
214.00000000000233,16.532302668498833,1.2358810568363048,-0.03926838281911316
215.10000000000235,16.565525726095018,1.3169798709969185,-0.039269962178307694
216.20000000000238,16.599305280322515,1.416985551330877,-0.03926995957041779
217.3000000000024,16.632852621685895,1.5290473429847395,-0.03927000827419658
218.40000000000242,16.666733210658276,1.6504917772515149,-0.03927080692227669
219.50000000000242,16.700000000000077,1.7543664600133309,-0.03963548582454646
220.60000000000244,16.73364775985288,1.82117643681236,-0.03959959404543234
221.70000000000246,16.767381885713917,1.82933560641353,-0.039599958723974815
222.80000000000246,16.80142552031176,1.7763405473404816,-0.03959996048699921
223.90000000000248,16.83484888475067,1.6960556349297071,-0.039599934524249925
225.0000000000025,16.868568410239497,1.6049205714681567,-0.039598879489807004
226.10000000000252,16.901890276169603,1.5193777708270049,-0.03990332177533418
227.20000000000255,16.93557807121288,1.4374607865891953,-0.04026228576612123
228.30000000000254,16.9687604938517,1.3644485476837347,-0.04023888918935281
229.40000000000256,17.00241992745204,1.2968975989362241,-0.04059212191823924
230.5000000000026,17.035362944248597,1.242674716866932,-0.04066183948250135
231.60000000000258,17.06908427842084,1.1953544802328728,-0.04189583106142525
232.7000000000026,17.102155818274547,1.157270815691894,-0.041829603048194386
233.80000000000263,17.135697585680973,1.1243016826089902,-0.04255242781162849
234.90000000000265,17.169009397366747,1.1004931808792908,-0.0425595918347641
236.00000000000267,17.202527376885026,1.081209011914789,-0.04253431400965635
237.10000000000267,17.235925198415373,1.0645090102676775,-0.04392845696842684
238.2000000000027,17.268678296108895,1.0518028923340432,-0.04387012947134039
239.3000000000027,17.302066009990746,1.0425288922713545,-0.04258602706275827
240.4000000000027,17.33512927572504,1.0343382392776974,-0.042529265743114664
241.50000000000273,17.36858023041589,1.0282097296519699,-0.043868256799791006
242.60000000000275,17.401541093888227,1.0224862314883258,-0.04388035968900006
243.70000000000277,17.434833977114547,1.0215452387665445,-0.04388010363917072
244.8000000000028,17.467965024181108,1.0196226394202355,-0.043880104881320214
245.9000000000028,17.501367018712596,1.0171426021385535,-0.043880099110827686
247.0000000000028,17.534557630844656,1.015934944797864,-0.04388119120155487
248.10000000000284,17.567896970847983,1.0155298053791983,-0.04382906410232579
249.20000000000283,17.601055508779158,1.0162287563561976,-0.04486759519000039
250.30000000000285,17.634207745982046,1.0147252430200009,-0.0448703184596404
251.40000000000288,17.667692893909003,1.0154011039350213,-0.044394525927869743
252.5000000000029,17.70086588583032,1.0150815596848095,-0.043543118941892445
253.60000000000292,17.734173511735897,1.013804638923987,-0.043675808423010665
254.70000000000292,17.767193959328864,1.0144012621972185,-0.043871370560040646
255.80000000000294,17.80015031361646,1.014984573959833,-0.04386987590671332
256.90000000000293,17.833507297458063,1.0149616931235697,-0.04386998642426754
258.00000000000296,17.86679900034437,1.015228536829068,-0.04386255696603225
259.100000000003,17.900122110674495,1.018956128541498,-0.04482203022036746
260.200000000003,17.933244614845464,1.0193254258430253,-0.04620510144531842
261.300000000003,17.96661847893273,1.0209312512249111,-0.04614796396035192
262.40000000000305,17.99951844438306,1.020594424122024,-0.046509406543314036
263.50000000000307,18.032855900681767,1.0193985293381742,-0.046510052415479564
264.6000000000031,18.0657139961609,1.020675891312444,-0.04651681170262467
265.7000000000031,18.098859810664493,1.0225217179002892,-0.04714969497701205
266.8000000000031,18.13162461370238,1.0223746829415532,-0.04716347692494516
267.9000000000031,18.16543632836448,1.0236423830643164,-0.04820555222979728
269.0000000000031,18.198560736199305,1.0224433960614319,-0.048480343247112145
270.10000000000315,18.232103312211624,1.0236701311593837,-0.04846908631151159
271.2000000000032,18.265115681884495,1.023143270555298,-0.04916457224406212
272.30000000000314,18.298238557476562,1.0229799382322065,-0.049139898015970296
273.40000000000316,18.33136452783669,1.0258633813163283,-0.04914033510252214
274.5000000000032,18.364636305805696,1.0254022679541195,-0.049091210857508116
275.6000000000032,18.39778954124351,1.0261505426665687,-0.05045210337638162
276.70000000000323,18.430178950059247,1.0264715949467427,-0.04916806376260219
277.80000000000325,18.464121246292276,1.0252254565002614,-0.04913988450022355
278.9000000000033,18.497447677107026,1.0276772366472116,-0.04913979428143023
280.0000000000033,18.530562872298592,1.027699327266902,-0.049138955431017095
281.1000000000033,18.563965184709712,1.0295385803924981,-0.05055988288892177
282.20000000000334,18.59732426086079,1.0307118413929885,-0.050459162896120624
283.30000000000337,18.63041248360001,1.0309899550470427,-0.05046013779189673
284.40000000000333,18.663717510531136,1.0281910050837941,-0.050460138161048995
285.50000000000335,18.697062613133546,1.0306918846896367,-0.05046027382745688
286.6000000000034,18.730267546193087,1.0294212091955637,-0.050461324951799114
287.7000000000034,18.763577559319643,1.028766732789885,-0.051672606497140006
288.8000000000034,18.79688840981873,1.0273373367505194,-0.05206033901800833
289.9000000000034,18.830091852841697,1.0318825736386887,-0.05308870183845382
291.0000000000034,18.863098206976954,1.0306943453811326,-0.0531184885465672
292.10000000000343,18.896741963815778,1.0312491031080204,-0.05438223190750291
293.20000000000346,18.92999968178333,1.0297134211049923,-0.05449055108435408
294.3000000000035,18.963440775918183,1.0324451018345724,-0.05308991898304383
295.4000000000035,18.99652384534766,1.0302813262582973,-0.0530898489909335
296.5000000000035,19.030182553847062,1.0311014268410141,-0.05308318087449315
297.60000000000355,19.063291365917813,1.0306193509008743,-0.05406798416139047
298.70000000000357,19.09654730830737,1.0303442288179563,-0.05434586636049765
299.8000000000036,19.13006000227139,1.0317482701739527,-0.05571961390737323
300.9000000000036,19.163229115310717,1.031533598211637,-0.05572034667402059
302.0000000000036,19.196752218163294,1.030339795973958,-0.05572379694306928
303.1000000000036,19.230029637917184,1.0326484452922529,-0.05525771591887718
304.2000000000036,19.263446807262707,1.033821325073018,-0.056260889295666416
305.30000000000365,19.296779759832873,1.032898832616378,-0.05637022940280989
306.4000000000037,19.330305919819388,1.0307488129421636,-0.056371369589301334
307.5000000000037,19.363566449365447,1.0313900022862421,-0.05766524563977704
308.60000000000366,19.396988270238037,1.0335506651341388,-0.057690453520933715
309.7000000000037,19.429969751765043,1.033325139258297,-0.05769017495360451
310.8000000000037,19.463436630662557,1.033437730005833,-0.05769015222937979
311.90000000000373,19.49702893224783,1.034680566719171,-0.05769183623228402
313.00000000000375,19.530615331272227,1.0348887306188737,-0.0590416689206843
314.1000000000038,19.563875076495876,1.0389890351514655,-0.05900821649042287
315.2000000000038,19.597292349173312,1.0360006637204788,-0.05901026038751134
316.3000000000038,19.6307551806679,1.0377563815369002,-0.05901483914212502
317.40000000000384,19.663943308097572,1.0400694045545174,-0.06029593298708624
318.5000000000038,19.697554046678306,1.037828906831651,-0.06032007632866998
319.60000000000383,19.731342163681244,1.041433107596912,-0.06032034763501448
320.70000000000385,19.76450550972633,1.0429505456437673,-0.06023613924078708
321.8000000000039,19.79796349697617,1.0422854519413205,-0.06270806592705958
322.9000000000039,19.83118731198621,1.044571525508566,-0.06340231203711966
324.0000000000039,19.86497890666387,1.0481582389827662,-0.06428014963130257
325.10000000000394,19.89819000369697,1.0487560571594083,-0.06509048490600922
326.2000000000039,19.9319862758782,1.0509507868318952,-0.0655903991324367
327.30000000000393,19.965436712347195,1.0535307581160467,-0.0655860523816667
328.40000000000396,19.999115169729205,1.0526979103981027,-0.06617648692654132
329.500000000004,20.03256997419436,1.0548469396363882,-0.06692686939656145
330.600000000004,20.066006229249922,1.0575837419982421,-0.06818052280931841
331.700000000004,20.099627345188203,1.0592703110442292,-0.06821849958023485
332.80000000000405,20.133119278380136,1.06252361778219,-0.06940431922668022
333.90000000000407,20.166662353636784,1.0683161790436373,-0.06993068163497007
335.0000000000041,20.200282391784054,1.0693696827638075,-0.07086190375648282
336.10000000000406,20.23393563707564,1.0750723215335796,-0.0722111757190671
337.2000000000041,20.26743251861219,1.0769038339741088,-0.0736199152119914
338.3000000000041,20.30117642130783,1.0804534569003006,-0.07467783397056049
339.4000000000041,20.334647990185115,1.0855286597219178,-0.07537490415184323
340.50000000000415,20.368405839080914,1.089259135887231,-0.07728119462862626
341.6000000000042,20.40187557423763,1.09502857531277,-0.07840627161306735
342.7000000000042,20.435711727796704,1.101971376625323,-0.07939422388979533
343.80000000000416,20.469345675805712,1.1058360750637999,-0.0805797042558778
344.9000000000042,20.50318579816301,1.1102379675737255,-0.0828720010429107
346.0000000000042,20.536739503115797,1.1168207822107836,-0.08524920175845363
347.10000000000423,20.57081000614453,1.1286333842022909,-0.08698777209784359
348.20000000000425,20.604545702988762,1.1307227251945218,-0.08841611457529996
349.3000000000043,20.637959405461512,1.1372132805235406,-0.08991231213666584
350.4000000000043,20.671598317524754,1.144594256151593,-0.09161774677495416
351.5000000000043,20.705586324404422,1.1540501322409804,-0.09481086282486029
352.60000000000434,20.73948558253442,1.1614462875458138,-0.09705082693301659
353.7000000000043,20.773011444538614,1.170710625362795,-0.10012844530514586
354.80000000000433,20.80674821876681,1.180233811199701,-0.10386470906847212
355.90000000000435,20.84046443245213,1.1900017844547144,-0.10646156206074009
357.0000000000044,20.87479046300644,1.2017048455213635,-0.1084601492652224
358.1000000000044,20.90826567432873,1.210864611997566,-0.11242282313930474
359.2000000000044,20.941946138909845,1.2236835445194916,-0.1159195772090027
360.30000000000445,20.97610018943156,1.2376813594111686,-0.11908964496648933
361.4000000000044,21.00969468788231,1.2491022222616341,-0.12262056135679256
362.50000000000443,21.04371251230316,1.2640270005669463,-0.12694300086277766
363.60000000000446,21.077746115362764,1.2784539503020864,-0.13218403752461727
364.7000000000045,21.11153114260006,1.292932369448165,-0.13762636098983094
365.8000000000045,21.14551006792958,1.3097665436425228,-0.14263684118659414
366.9000000000045,21.179303192429174,1.329298800419035,-0.14691488194089874
368.00000000000455,21.21318699020024,1.344644555000143,-0.15188190845613558
369.10000000000457,21.24703005011198,1.3642854066184487,-0.1571382806034891
370.2000000000046,21.28118343361047,1.3817324125350892,-0.16271051720716123
371.30000000000456,21.31526863153242,1.4003356329780026,-0.16883973136665986
372.4000000000046,21.349367571848735,1.421762445569701,-0.17516412714974017
373.5000000000046,21.383303281479535,1.4422111238742852,-0.18178612843270514
374.6000000000046,21.41710144413897,1.4641654152399957,-0.1895589855842017
375.70000000000465,21.451064912467544,1.4836807411780126,-0.1951935072512212
376.8000000000047,21.485158665258687,1.5061723230747672,-0.2021491215719391
377.9000000000047,21.519395735242874,1.532124335098669,-0.21098344016223303
379.00000000000466,21.553251346592994,1.552680280142143,-0.21854413187850819
380.1000000000047,21.587194420204465,1.5753955790866456,-0.2282444649680455
381.2000000000047,21.621368479562566,1.602834545280449,-0.23746229388393347
382.30000000000473,21.65537128535665,1.6268141658032333,-0.24705304400428663
383.40000000000475,21.689531526422293,1.6512538051661036,-0.25634115610863173
384.5000000000048,21.723657537483188,1.6809934951624301,-0.26578253292577214
385.6000000000048,21.757890923436435,1.706402106547759,-0.27611485612278397
386.7000000000048,21.791775833776715,1.7303065885311377,-0.2867860928504373
387.80000000000484,21.8260651766268,1.7612720217489715,-0.298387707488728
388.9000000000048,21.860060776017765,1.7896285443560875,-0.3097711714383493
390.00000000000483,21.894412471964955,1.8158327943387529,-0.32150937330630924
391.10000000000485,21.928478214212618,1.8472906496438126,-0.33235696038566775
392.2000000000049,21.96271842663672,1.8765022357919552,-0.3443783511980101
393.3000000000049,21.99707836630145,1.9072033968351279,-0.3581785353820113
394.4000000000049,22.031140806749498,1.9378553023739151,-0.3731897833116937
395.50000000000495,22.065375510484152,1.9709353687030593,-0.3876887116821175
396.6000000000049,22.099474375596706,2.0038740092667435,-0.40285178357824636
397.70000000000493,22.1336323251277,2.039513959819252,-0.41720183431507873
398.80000000000496,22.168195778864195,2.0726813128723967,-0.4325589975142523
399.900000000005,22.20234351638344,2.107556412598682,-0.4491811122772402
401.000000000005,22.236592438723644,2.14631861693844,-0.46592156060450396
402.100000000005,22.271035149709313,2.1821416993453284,-0.48372647452309225
403.20000000000505,22.305363229347794,2.2199137411851892,-0.5021131503278271
404.30000000000507,22.339906116486446,2.2598070145423677,-0.5216141465126198
405.4000000000051,22.373858721106693,2.297334060630654,-0.5406866122144924
406.50000000000506,22.40843835395934,2.3400580999081484,-0.560723902676874
407.6000000000051,22.442769183567535,2.379617360951433,-0.5809798708751202
408.7000000000051,22.477212219536906,2.4171301235967197,-0.6026993492544062
409.8000000000051,22.511422369688326,2.4576661446080728,-0.6254567873374133
410.90000000000515,22.545730771329826,2.4978773737505664,-0.6495916227931424
412.0000000000052,22.580126899295728,2.539048214629954,-0.6738880309136608
413.1000000000052,22.61470788525319,2.5756731676210194,-0.6980166067000995
414.20000000000516,22.649428539417734,2.6104135959053814,-0.7234168274150607
415.3000000000052,22.683859100207478,2.6457576126019813,-0.7498615629901435
416.4000000000052,22.718246271439558,2.678575784170834,-0.7773913690628032
417.50000000000523,22.752653675168453,2.704639215986564,-0.8056956482805582
418.60000000000525,22.787446052748567,2.731695517532046,-0.8353187649265732
419.7000000000053,22.821929217192938,2.7531672263399427,-0.8660786815962904
420.8000000000053,22.856265478497807,2.770133512903321,-0.8961804078802627
421.9000000000053,22.890652447591425,2.7812550389635753,-0.9251102804982745
423.00000000000534,22.925491992918204,2.7874332279041845,-0.9558092470604871
424.1000000000053,22.95999969483565,2.7880799276693473,-0.9881754737573782
425.20000000000533,22.99428159567787,2.7777009700867907,-1.021455495326708
426.30000000000535,23.028867287813828,2.75628966475423,-1.0544535509309578
427.4000000000054,23.063460018818546,2.7299199904783387,-1.0876234677781786
428.5000000000054,23.098053058402677,2.6876259679705763,-1.121220755860545
429.6000000000054,23.13206543711404,2.6397941409927577,-1.151494641484787
430.70000000000545,23.16717130617058,2.5710206780649694,-1.182947872797652
431.8000000000054,23.20165035585231,2.4925641925317024,-1.2140681362658783
432.90000000000543,23.236389370225787,2.4063700765449534,-1.2451693147440581
434.00000000000546,23.270883923676084,2.308444932343484,-1.274262013937006
435.1000000000055,23.305399448212523,2.2056850904632426,-1.301963605520799
436.2000000000055,23.339903524811252,2.0948234280106153,-1.3292161594658665
437.3000000000055,23.37410355854996,1.9847351939256728,-1.3530828019412624
438.40000000000555,23.409085733806954,1.8727312106216096,-1.3766244233779874
439.50000000000557,23.443435889835772,1.7636899927335927,-1.3984253076449726
440.6000000000056,23.47810429512902,1.6618554796200917,-1.4187852371596463
441.70000000000556,23.51232150671062,1.5678901027816416,-1.4373895107746915
442.8000000000056,23.54672974383382,1.4799971224745807,-1.4547166752989655
443.9000000000056,23.58163599766577,1.4036578660529186,-1.4711323744594615
445.0000000000056,23.61591297679346,1.3365603192794797,-1.4849825300656057
446.10000000000565,23.650118912692307,1.2829355204826112,-1.4981538660548366
447.2000000000057,23.684756229012965,1.2302327317250865,-1.510865689186156
448.3000000000057,23.71946679615791,1.1879003599039002,-1.5227952171206383
449.40000000000566,23.754228030319688,1.1528666641759164,-1.5339512774610107
450.5000000000057,23.788456557432223,1.1216607106418526,-1.5457518614828514
451.6000000000057,23.82269716512697,1.095779646354523,-1.556295945369306
452.70000000000573,23.858034112896974,1.0732923180735685,-1.5668994424381086
453.80000000000575,23.89240172451943,1.0548682221858612,-1.5763751555408176
454.9000000000058,23.927001922456448,1.0417958009144022,-1.585472436518848
456.0000000000058,23.961773301959088,1.0266973358362048,-1.5950439408284582
457.1000000000058,23.99627561522818,1.0130996312355103,-1.6050006928488707
458.20000000000584,24.0310028693287,1.004436932270628,-1.6149355703077437
459.3000000000058,24.065887110356687,0.9959651664166786,-1.6256676649927
460.40000000000583,24.100620153811718,0.9880072075173982,-1.6354783614458284
461.50000000000585,24.135139708843194,0.9821692050001161,-1.6448071089874592
462.6000000000059,24.170123554172914,0.9763145347814708,-1.6546567543255142
463.7000000000059,24.20490520886788,0.9719377130587736,-1.66301046411643
464.8000000000059,24.239483648403024,0.9707246714562094,-1.672786698132804
465.90000000000595,24.274193759087222,0.9657560131425,-1.6825512019213722
467.0000000000059,24.309113997430295,0.9640065971369318,-1.692363341297355
468.10000000000593,24.3439616811203,0.9605221023113482,-1.7032585278839671
469.20000000000596,24.37873848181136,0.9589740947173979,-1.7135872148850293
470.300000000006,24.413787633418632,0.9566122555022374,-1.72277073868351
471.400000000006,24.448886325106063,0.9526857812253391,-1.732764194193182
472.500000000006,24.483477031108418,0.9525853781157734,-1.7425016452626285
473.60000000000605,24.518825317470835,0.9512753965426972,-1.7517048380546272
474.70000000000607,24.553485589535885,0.950688326168269,-1.7620487493121781
475.8000000000061,24.588460509815025,0.9424226984117918,-1.7730127431432519
476.90000000000606,24.623465985559807,0.941514043185159,-1.7835855261476645
478.0000000000061,24.65830578454298,0.937907634503498,-1.7935004215644756
479.1000000000061,24.693391611287577,0.932968748348123,-1.8032938157750493
480.2000000000061,24.72847440953611,0.9311002258211101,-1.8141247226370143
481.30000000000615,24.763537516814846,0.924773411004012,-1.825111761234926
482.4000000000062,24.79841664626985,0.9175892856208225,-1.8352663864113836
483.5000000000062,24.83379661817425,0.9122939616080856,-1.8460869620515132
484.60000000000616,24.86875268988151,0.9033717465966933,-1.8570190953124488
485.7000000000062,24.903586378875918,0.8977289669577209,-1.866811888845508
486.8000000000062,24.938681499778184,0.889906532967607,-1.8767674597096735
487.90000000000623,24.973628459352582,0.8779700049476642,-1.8871898569840844
489.00000000000625,25.009054392933955,0.8663785971220452,-1.8971384378485894
490.1000000000063,25.043833519968363,0.8526213269661611,-1.907372204909271
491.2000000000063,25.079169249383362,0.8342340108420125,-1.9169744060212022
492.3000000000063,25.11412260131243,0.8171168516247607,-1.9266739568823317
493.40000000000634,25.148956771771882,0.7920987935046502,-1.9363965898259496
494.5000000000063,25.184205145659377,0.7714547586587914,-1.9457301619160736
495.60000000000633,25.219434280905666,0.7418250262823403,-1.954894787770924
496.70000000000636,25.254603970058213,0.7088550241190239,-1.9633343799248033
497.8000000000064,25.28961757745401,0.6761687409552133,-1.9710634493586414
498.9000000000064,25.324967605172247,0.6381811876035846,-1.978510390982699
500.0000000000064,25.360030985180302,0.5993164347342246,-1.984443714867497
501.10000000000645,25.395048592651218,0.5587853398235738,-1.9904134753787952
502.2000000000064,25.430190673286994,0.5203194629003822,-1.9952146231257832
503.30000000000643,25.46517890503537,0.48243645740042984,-2.000467013875561
504.40000000000646,25.500533263070707,0.4467089526966874,-2.0034260814252383
505.5000000000065,25.53584017908949,0.4159689186954756,-2.0049803169292923
506.6000000000065,25.57084669408648,0.38666717748568624,-2.0075791685634483
507.7000000000065,25.60608251283064,0.3619806392184157,-2.010385629459557
508.80000000000655,25.641379301532716,0.3391732858322569,-2.0119574325957257
509.90000000000657,25.67656828366132,0.32158136837403783,-2.0133592245166803
511.0000000000066,25.711755293998674,0.3082041089191243,-2.01357213564562
512.1000000000065,25.747078448725585,0.2954394006650811,-2.0145593216864235
513.2000000000066,25.782304710385233,0.28670523555655225,-2.0159048018051204
514.3000000000065,25.817577494761174,0.2748963465701555,-2.0164591987966007
515.4000000000067,25.85286713466296,0.26781958557498076,-2.015924431740741
516.5000000000066,25.88843239573249,0.2618931800092885,-2.015919659001375
517.6000000000067,25.923670108271125,0.2554656058346143,-2.016222515406012
518.7000000000066,25.959125043636185,0.24966116741137223,-2.017241262725068
519.8000000000067,25.99455076081709,0.24619693572456902,-2.0172398826861646
520.9000000000067,26.02942954033767,0.24390060263826285,-2.017240474922587
522.0000000000067,26.064980259007182,0.23708151471212324,-2.01690811114767
523.1000000000067,26.10047464479962,0.23695888030337797,-2.0172394368163213
524.2000000000068,26.135895467490766,0.23209705144737747,-2.0172365338151628
525.3000000000068,26.171149855530345,0.22982884808242576,-2.01798596102262
526.4000000000068,26.206506683963298,0.22865954595836602,-2.0185524256251886
527.5000000000068,26.24176483386442,0.22700789696889068,-2.01854992900671
528.6000000000068,26.277333797474956,0.2268466498584245,-2.0185499210136557
529.7000000000069,26.31260344927734,0.23101375233255794,-2.018554173814512
530.8000000000068,26.347904512755825,0.23796895106692562,-2.019560565646902
531.9000000000069,26.383562994688837,0.24457587059778207,-2.019539021608643
533.0000000000068,26.418733878450475,0.251622609076126,-2.019539910931362
534.100000000007,26.454222615405936,0.2543824325891473,-2.0195399150635174
535.2000000000069,26.489314596445404,0.2609497874343101,-2.019539915139279
536.300000000007,26.525065950885324,0.26551246786709126,-2.019539983065187
537.4000000000069,26.5603195061193,0.26675362879324194,-2.019540660466199
538.5000000000069,26.59582465374608,0.2714806382759467,-2.020655924813904
539.600000000007,26.631082776578115,0.27683304171871725,-2.020859308051417
540.700000000007,26.666790047027494,0.27887216923640157,-2.02085982126691
541.800000000007,26.702159982993834,0.28212631439927405,-2.020863579373141
542.900000000007,26.737791643548555,0.28836861616060316,-2.020089277436602
544.000000000007,26.77329478355398,0.28829010107057895,-2.0195374930718564
545.1000000000071,26.80893557707783,0.2857017357801066,-2.0195379225739223
546.2000000000071,26.84459097548424,0.2895740579203303,-2.0200233119317272
547.300000000007,26.879871612295474,0.28718835546134036,-2.0218429039960943
548.4000000000071,26.915509865679926,0.2863426892063261,-2.0221804463341333
549.500000000007,26.950831677467182,0.28116462643713724,-2.022180110425427
550.6000000000072,26.986610053116973,0.27817967077516714,-2.0221801099739674
551.7000000000071,27.02239310290643,0.27384414304286997,-2.022180109996708
552.8000000000072,27.058179690365478,0.26759500539948844,-2.022180110266927
553.9000000000071,27.093551493055205,0.26280059504690634,-2.0221801607702226
555.0000000000072,27.12948035502249,0.2592533345630752,-2.0221791263099944
556.1000000000072,27.16511441887407,0.25566758351074315,-2.0232287393371715
557.2000000000072,27.200754660141026,0.24944929032821372,-2.023489467975981
558.3000000000072,27.2364514013649,0.2486324771491777,-2.0234898947358424
559.4000000000073,27.272227312834943,0.24493006146529783,-2.0234898800889987
560.5000000000073,27.307596798094774,0.2360516750316326,-2.023489879999002
561.6000000000073,27.343527672246132,0.23811587318848604,-2.0234898799999894
562.7000000000073,27.379443164775513,0.23567877064242992,-2.023489880000006
563.8000000000073,27.41469966064571,0.22949733149314744,-2.0234898800033116
564.9000000000074,27.4498422752246,0.2264662421327781,-2.023489879981621
566.0000000000074,27.485410238295273,0.22489995017336772,-2.023489843786327
567.1000000000074,27.522442506349073,0.21915970070391078,-2.0234866481716876
568.2000000000073,27.55819277911144,0.2157370310698612,-2.0243074927499562
569.3000000000073,27.593699581503678,0.21249151478581663,-2.0248105681492232
570.4000000000074,27.62957198600881,0.21086173116587403,-2.024810179475281
571.5000000000074,27.665617809121287,0.21382499850104164,-2.024810180002787
572.6000000000074,27.70135170125621,0.20763539952322807,-2.0248101818247264
573.7000000000074,27.73705120337098,0.20364409987629983,-2.0248098246926602
574.8000000000075,27.77313327797956,0.20309219955694457,-2.0247644565458893
575.9000000000075,27.809102078031177,0.19672524061956365,-2.025467413221382
577.0000000000075,27.844874762678156,0.1958236078132627,-2.025783803266733
578.1000000000075,27.880792537435944,0.19454675263708676,-2.0261193758871467
579.2000000000075,27.916955642442417,0.18865284570480778,-2.026120060258768
580.3000000000076,27.95243667763673,0.18417157089361602,-2.0261053924552117
581.4000000000076,27.98849348968103,0.1847089030597897,-2.025110947389771
582.5000000000076,28.024317776647415,0.1836496094587372,-2.025152148553941
583.6000000000076,28.06035822903845,0.18425267207931606,-2.0264515434972914
584.7000000000077,28.096155919239862,0.1828874742313893,-2.02644972224246
585.8000000000077,28.132030204296953,0.18049171386438712,-2.0264498416599874
586.9000000000076,28.16817673647465,0.1802638298630006,-2.02644944430579
588.0000000000076,28.203818011615823,0.18127719114341234,-2.0267445489598517
589.1000000000076,28.23970351258678,0.1831143413402221,-2.027758163307259
590.2000000000077,28.27596830958973,0.18761166903930038,-2.029079181955338
591.3000000000077,28.31221843529648,0.18764697488753823,-2.027781984292092
592.4000000000077,28.34817827142004,0.1926598728803901,-2.0277759855380766
593.5000000000077,28.383995286487487,0.19592507957400196,-2.026449122857608
594.6000000000078,28.42016278836274,0.19574004311729087,-2.026475325759581
595.7000000000078,28.455875072345524,0.19703688390120755,-2.0277742847649947
596.8000000000078,28.49181675189143,0.20198934730910656,-2.0277701013772926
597.9000000000078,28.528076969422766,0.20563387476779393,-2.027770129402539
599.0000000000078,28.56413087202406,0.2073275354248496,-2.0277671281112286
600.1000000000079,28.60037100279276,0.2118713410912898,-2.0284526303236463
601.2000000000079,28.63640672488946,0.21430413992011044,-2.0292545268536784
602.3000000000079,28.672571275064286,0.21999483528363317,-2.0300716851608014
603.4000000000078,28.708785096732022,0.22042283662395068,-2.030329672933097
604.5000000000078,28.744758867377083,0.2246646937516359,-2.0310651537595135
605.6000000000079,28.781205427923798,0.23023764330102914,-2.030031815387315
606.7000000000079,28.817117812849336,0.23837011536435382,-2.0303152548940786
607.8000000000079,28.85352686128947,0.24173411968470448,-2.030399076045976
608.9000000000079,28.889765518559386,0.24526767747510148,-2.0304000666448645
610.000000000008,28.9258019022549,0.2520288006198874,-2.030958201863701
611.100000000008,28.96202016096562,0.2510328703847815,-2.031720367216653
612.200000000008,28.998241338268233,0.25558992661959623,-2.031720107975439
613.300000000008,29.034794933715755,0.2600329257472014,-2.0317201099709647
614.400000000008,29.07063959762003,0.25920958783407144,-2.0317201099809963
615.5000000000081,29.107138768965772,0.2656896786050895,-2.031720108371361
616.6000000000081,29.143046024733522,0.2736657897339003,-2.031720260058435
617.7000000000081,29.179460013451006,0.2786779280936318,-2.0317515024736843
618.8000000000081,29.21578747703176,0.2839148972946899,-2.0323226075770853
619.9000000000082,29.252152936793372,0.2910617937340003,-2.032698697350988
621.0000000000082,29.288406023025257,0.29390799391687406,-2.032663714785454
622.1000000000081,29.324692637502412,0.30056627461626606,-2.0340066963770713
623.2000000000081,29.36092488889636,0.30726201430269473,-2.034020030280164
624.3000000000081,29.397659369863426,0.31388585448662365,-2.0341955293480027
625.4000000000082,29.43367033149013,0.31856432748667185,-2.03535897338724
626.5000000000082,29.470000000000265,0.3280143693586419,-2.034989055839225
627.6000000000082,29.506328130564828,0.32982697255997895,-2.0346737210636454
628.7000000000082,29.542601610723338,0.33453960392210513,-2.0346461756232235
629.8000000000083,29.57881422702225,0.3434813140918287,-2.036112131415183
630.9000000000083,29.6151153685623,0.3514437660859824,-2.0371621888627924
632.0000000000083,29.651572936314746,0.35806409362390257,-2.0374194935632524
633.1000000000083,29.68782928851656,0.36457187881208064,-2.037375468754558
634.2000000000083,29.724081999268595,0.3709334806735436,-2.038716122353627
635.3000000000084,29.760500978245773,0.3790738757234413,-2.0387294596239784
636.4000000000084,29.797092284649505,0.3837010808599537,-2.0394248638751025
637.5000000000084,29.833032863800938,0.3895181535581407,-2.040051533115244
638.6000000000083,29.869578875643878,0.4008446666872558,-2.040027088520403
639.7000000000083,29.905973459311323,0.40837947010144005,-2.0413550094495942
640.8000000000084,29.942250130146196,0.4166956437836338,-2.0422044894799494
641.9000000000084,29.978724779936343,0.42631371214763103,-2.042680952334269
643.0000000000084,30.01491077652809,0.43348017198089517,-2.0426798120948835
644.1000000000084,30.05081648953462,0.44256735452023,-2.042672832762328
645.2000000000085,30.08751026771364,0.45052647086812714,-2.044026784996936
646.3000000000085,30.12390312645916,0.46236390985013864,-2.045411684513976
647.4000000000085,30.160323274864144,0.4701156316633255,-2.044804142480687
648.5000000000085,30.19660479125689,0.48020163558531603,-2.044778032120282
649.6000000000085,30.232881083823866,0.48979879340496435,-2.0446944657746
650.7000000000086,30.26932997727199,0.5056398505564066,-2.045976283748172
651.8000000000086,30.30567899251121,0.5184677987224569,-2.0469049115740687
652.9000000000086,30.342014693100296,0.5336856374978018,-2.04821949828014
654.0000000000086,30.3782568350765,0.5470849661350865,-2.049837148923457
655.1000000000087,30.41442876991674,0.5638932339288294,-2.0498357345599048
656.2000000000087,30.451033040001064,0.5803188073075791,-2.0512196648192207
657.3000000000086,30.48740189398353,0.6026359534304442,-2.052564368349514
658.4000000000086,30.523621568064446,0.6217367256774429,-2.053975304124404
659.5000000000086,30.560229313835322,0.6398540837749351,-2.0538867264301324
660.6000000000087,30.596189721846766,0.6577565719389673,-2.0551278711794954
661.7000000000087,30.632518478922368,0.6782208534761649,-2.05650363688891
662.8000000000087,30.668407818656632,0.7001674578644215,-2.0577650623592225
663.9000000000087,30.70558529714446,0.7225842634982915,-2.058969806609331
665.0000000000088,30.741876630423665,0.7468245026655773,-2.05908948147193
666.1000000000088,30.77841551754772,0.7715729733380248,-2.060648339873185
667.2000000000088,30.81464336991192,0.7936553919844092,-2.0618071951334374
668.3000000000088,30.850730175814853,0.8241679047721333,-2.0628506087698133
669.4000000000088,30.887470733638413,0.8505381938815648,-2.066138058160216
670.5000000000089,30.923811619186793,0.8802740626276031,-2.0668103624250995
671.6000000000089,30.960000642969682,0.9109032264577959,-2.067911539944558
672.7000000000089,30.99644951658584,0.9377790963312576,-2.068516668031306
673.8000000000088,31.032017624259975,0.9630387743708568,-2.070488884603363
674.9000000000088,31.069327796282863,0.9928946487509829,-2.0723132888093447
676.0000000000089,31.10564771249406,1.022998180863532,-2.0738803561561285
677.1000000000089,31.142001570049135,1.0496291502081547,-2.075333083568519
678.2000000000089,31.178590134343295,1.0736297788900249,-2.0773204964218728
679.3000000000089,31.215156356305858,1.1051257958008103,-2.07965919498377
680.400000000009,31.25141426577421,1.1319535936975966,-2.0815195881969935
681.500000000009,31.28776300318984,1.1602566324430375,-2.083185605294477
682.600000000009,31.324263094505973,1.189487394470076,-2.0857126344937047
683.700000000009,31.36055675588999,1.2220135987373606,-2.087884411263787
684.800000000009,31.397126547722273,1.2525961696481351,-2.090270766946169
685.9000000000091,31.43377184872904,1.2862637983045313,-2.0928104903936724
687.0000000000091,31.47050040339708,1.3216000743978125,-2.095379523841156
688.1000000000091,31.5070051166532,1.3569052451069372,-2.0985809966042552
689.2000000000091,31.54317321021889,1.3950752608911858,-2.101327213293852
690.3000000000092,31.580281095021405,1.4327111706818494,-2.1031222543413417
691.4000000000092,31.616362804821915,1.4734424981924037,-2.1053808718951528
692.5000000000091,31.653067633317043,1.5131679100712887,-2.108247020512385
693.6000000000091,31.689455353889134,1.5547143501490859,-2.1098340934141357
694.7000000000091,31.726272164887654,1.5953663113498884,-2.1130027864874195
695.8000000000092,31.762697974160893,1.6382351023348631,-2.116340475459925
696.9000000000092,31.799508113864192,1.6868265794112594,-2.1210578900731254
698.0000000000092,31.835800615072802,1.7329496418844372,-2.123163223676192
699.1000000000092,31.872356451245764,1.7848525215498596,-2.125772882085261
700.2000000000093,31.90903349480108,1.836297346532044,-2.129874236355059
701.3000000000093,31.945521530313062,1.8878443508903162,-2.13264813014044
702.4000000000093,31.981874927611617,1.9425040282901813,-2.136394467615574
703.5000000000093,32.01858740457495,1.9969554096761293,-2.1407382224899756
704.6000000000093,32.05552107541821,2.0586810029684277,-2.1449868497601594
705.7000000000094,32.09205751074996,2.1181848211783114,-2.1496641730757484
706.8000000000094,32.1288583037187,2.17990569767228,-2.1539516232081857
707.9000000000094,32.165368507668894,2.2469586992412833,-2.1574818516772463
709.0000000000093,32.20183904053037,2.311639368888799,-2.161760664218397
710.1000000000093,32.23842557602906,2.3801865838385927,-2.167412014466709
711.2000000000094,32.275122264621,2.455403255553693,-2.1730138617056713
712.3000000000094,32.311702761442625,2.528159712289454,-2.177389160544588
713.4000000000094,32.34808612951282,2.6029152272897598,-2.1803481375589024
714.5000000000094,32.38493612664408,2.6808277870955015,-2.186428089605965
715.6000000000095,32.420777211845774,2.763853817967743,-2.19224958854442
716.7000000000095,32.45828709727526,2.8536754394791175,-2.198728656757913
717.8000000000095,32.49493826951188,2.9385103857824904,-2.204215572084234
718.9000000000095,32.53177265700951,3.0310037836005783,-2.210203342362327
720.0000000000095,32.568400598013156,3.117298392018985,-2.2155735543475767
721.1000000000096,32.605007362735485,3.21173289764003,-2.2226222277784675
722.2000000000096,32.64187109150993,3.3059419529261844,-2.229942156821918
723.3000000000096,32.678864316317956,3.4040698414394286,-2.237488970948205
724.4000000000096,32.71566034034528,3.5022673937045385,-2.242776178086096
725.5000000000097,32.75218561243556,3.599155848340322,-2.2502435422856673
726.6000000000097,32.78906464109296,3.6993080010639643,-2.2585245181250846
727.7000000000096,32.82597163747736,3.800681727662061,-2.266966609804704
728.8000000000096,32.86252692619832,3.902882188339448,-2.273111481729585
729.9000000000096,32.899250728770106,4.0041951366232444,-2.281365482258999
731.0000000000097,32.9361381449281,4.106752203289268,-2.2911217555398853
732.1000000000097,32.972970398855004,4.207221889491869,-2.3020449774898695
733.2000000000097,33.00993110425112,4.308126746514615,-2.310520330984962
734.3000000000097,33.046557719772245,4.402565596877247,-2.319830823064503
735.4000000000098,33.083167520802895,4.500000136071334,-2.3291978824651554
736.5000000000098,33.120265080192,4.605619447840079,-2.3384524759091896
737.6000000000098,33.157319047272814,4.703092736921453,-2.3476532104080317
738.7000000000098,33.194210275194045,4.801142766425273,-2.3585737103593774
739.8000000000098,33.23091381156204,4.897122659219358,-2.368983367223798
740.9000000000099,33.26750895146808,4.990687420095674,-2.380378145888159
742.0000000000099,33.30457667361079,5.088409927741193,-2.393084355900265