File: 01_Data/Nylon_Carpet_Low_Pile/STA/N2/30K_min/Nylon_Carpet_Low_Pile_STA_N2_30KData_220107_R3.csv
##Temp./Â°C,Time/min,DSC/(mW/mg),Mass loss/mg
49.0,10.499490168168508,0.020115629118383827,-0.012404774029595167
50.30000000000002,10.730904172306268,0.08613737031051694,-0.010941512587255176
51.60000000000004,10.869644933941125,0.14215485089598934,-0.011842739330877539
52.900000000000055,10.97732000854522,0.19040333271351306,-0.010688734923140597
54.200000000000074,11.06852879504619,0.23325964462687088,-0.012484540322412307
55.50000000000009,11.150328537423542,0.271031908198845,-0.012888903108530858
56.80000000000011,11.224605393551983,0.30445811031486864,-0.013811825225749974
58.10000000000013,11.294626927958253,0.33483125925769014,-0.0134062626012601
59.40000000000015,11.359840531102384,0.36426599051959174,-0.013306544800292919
60.700000000000166,11.422017125391966,0.39146128770846034,-0.013083475422465352
62.000000000000185,11.482552405873587,0.4153406525426099,-0.012545992905416359
63.3000000000002,11.540122276242608,0.4383295109961062,-0.012061099384344853
64.60000000000022,11.596190613652286,0.461706435874031,-0.013473048372503182
65.90000000000023,11.65089829336796,0.48225213438763714,-0.0142716792221389
67.20000000000026,11.70498749346909,0.5029712160763145,-0.014285590014630145
68.50000000000028,11.756646934429922,0.5215750402124844,-0.013202386927609222
69.8000000000003,11.809053147194145,0.5395197033357158,-0.013626926136738327
71.1000000000003,11.859391991501083,0.5526664684872153,-0.011269498849731718
72.40000000000033,11.909504257492603,0.5664595114960687,-0.006738161287255906
73.70000000000036,11.959094367199166,0.5801685745011314,-0.004063756246914352
75.00000000000037,12.008219579645132,0.592452912592005,-0.005963412703061444
76.30000000000038,12.056866818401192,0.6054088015307619,-0.006844337454091409
77.6000000000004,12.104461094190402,0.6183409541516323,-0.012212395683364186
78.90000000000043,12.152648543056866,0.6302724730145606,-0.01526752996023717
80.20000000000044,12.199767538773203,0.6413688707087244,-0.01546089359746139
81.50000000000045,12.246856142999627,0.6534374086466774,-0.015561585307852788
82.80000000000048,12.29333360445093,0.6621425622952024,-0.01616097254617843
84.1000000000005,12.339645379650614,0.6704425243949494,-0.017160853011950028
85.40000000000052,12.385885167097602,0.681695480414477,-0.016005984589546163
86.70000000000053,12.43150476315444,0.6916157921958354,-0.015444446807908907
88.00000000000055,12.476675793121585,0.7002794319490764,-0.014054527062667077
89.30000000000058,12.521930554468023,0.7087307637235258,-0.01294439947680992
90.60000000000059,12.567165206003667,0.7148939228207586,-0.012248485506830331
91.9000000000006,12.612069779665717,0.7245991369242822,-0.012179621799403684
93.20000000000063,12.656626488241187,0.7345056909439144,-0.01355834701569103
94.50000000000065,12.70184639882105,0.7403743958350057,-0.014802269364899256
95.80000000000067,12.745893342284411,0.7495783480055112,-0.014923290283191726
97.10000000000068,12.790388171803299,0.7582396446280425,-0.016204951130971423
98.4000000000007,12.83458806690034,0.7652851416790646,-0.01685733753985552
99.70000000000073,12.878905682249705,0.7715537443460868,-0.018618993776305715
101.00000000000074,12.922929768742483,0.7770222980242234,-0.017025163410863353
102.30000000000075,12.96693076018271,0.7818034751010657,-0.015948308250719023
103.60000000000078,13.010796733178159,0.7882935956957359,-0.0145219402294261
104.9000000000008,13.054948388458518,0.7931294850679174,-0.01364659963919257
106.20000000000081,13.0988291845324,0.7992809439129667,-0.014308533003422497
107.50000000000082,13.14226695964622,0.8010017039122991,-0.015479718095098072
108.80000000000085,13.185972282049816,0.8059584212856608,-0.016001652023666768
110.10000000000088,13.229445748235198,0.8072901685364091,-0.016382794092929753
111.40000000000089,13.273476731508795,0.8108613791468272,-0.016011445783813194
112.7000000000009,13.31736171429624,0.8141892193745599,-0.016010107921411443
114.00000000000092,13.360529219649898,0.8147948284266122,-0.01601079059078314
115.30000000000095,13.404420844564118,0.8196924268737267,-0.015645369454406755
116.60000000000096,13.447246347154191,0.8205411287741661,-0.01569943555285569
117.90000000000097,13.491453695725793,0.8228978572325456,-0.01712102192430809
119.200000000001,13.534327395815465,0.8227855989216524,-0.01711982937078327
120.50000000000102,13.577388158934635,0.8240998342308696,-0.018430459644282582
121.80000000000103,13.620689215499453,0.8260231416573646,-0.0184361344167856
123.10000000000105,13.664005247142292,0.8265716021323741,-0.017003295664436813
124.40000000000107,13.707116944873135,0.829068932483276,-0.015863325196138423
125.7000000000011,13.75007009629454,0.8295153216750868,-0.01568186127193938
127.00000000000111,13.792579131321201,0.8335093591486123,-0.01646926765760659
128.30000000000112,13.835778229413242,0.8358696176386605,-0.01773059998851023
129.60000000000116,13.87811306915102,0.8400543382572403,-0.019412655209271712
130.90000000000117,13.921004642441424,0.8428552614347486,-0.02039513792803671
132.20000000000118,13.963327432553193,0.8445331078284418,-0.02203662828522379
133.5000000000012,14.005650346547354,0.8465157152853975,-0.020015328352823047
134.8000000000012,14.04780887340609,0.8495164847856046,-0.01700332775881952
136.10000000000124,14.090170034056664,0.8542166093646639,-0.017015320008564316
137.40000000000126,14.132159793589372,0.8542923156050437,-0.017439491831194864
138.70000000000127,14.17442451732598,0.8608117107497826,-0.01700131442637165
140.0000000000013,14.21675594152808,0.8633198726509095,-0.018086178184438584
141.30000000000132,14.258650561290771,0.8704176920284836,-0.018319738541921815
142.60000000000133,14.300143502002411,0.8717459877083686,-0.018319812181191164
143.90000000000134,14.34218321092538,0.8785044039115817,-0.018319522897081164
145.20000000000135,14.383787433913195,0.8869885515257471,-0.018233247159901822
146.5000000000014,14.425555114634903,0.8915194214272554,-0.018655370372148372
147.8000000000014,14.46708073579575,0.897672222627097,-0.018923619247366297
149.10000000000142,14.508646810868422,0.9091230896541602,-0.01911774511082509
150.40000000000146,14.550176658531763,0.9166502329827473,-0.020294869295446993
151.70000000000147,14.591609840934677,0.9309690008324613,-0.019439279187396075
153.00000000000148,14.632708371003586,0.9407043243804917,-0.020415938433153258
154.3000000000015,14.674365313417892,0.9565357511058715,-0.02161243230285148
155.6000000000015,14.715936298485907,0.9731636112440611,-0.021609813208557593
156.90000000000154,14.756858569890227,0.9934358344501273,-0.021609372790607928
158.20000000000155,14.79802756208833,1.010076204052119,-0.0215574181489675
159.50000000000156,14.83956888506922,1.0300402516967828,-0.022930787335964542
160.8000000000016,14.88021971684856,1.053242467088648,-0.0215278794922642
162.10000000000161,14.921653885021561,1.0717337710148047,-0.0213966372695662
163.40000000000163,14.962763344549243,1.08856194366146,-0.020175752217382215
164.70000000000164,15.003619540891886,1.094150293503457,-0.02017356241424917
166.00000000000165,15.044764890611729,1.0900545481282644,-0.02145419907452517
167.3000000000017,15.085594323273236,1.0768943010726706,-0.02150585968794072
168.6000000000017,15.126772277808058,1.0632951829701573,-0.02084359992954221
169.9000000000017,15.167794422478384,1.0439460896555381,-0.020838459801050035
171.20000000000175,15.208288483823347,1.024287498640299,-0.022815502006693134
172.50000000000176,15.248430572213413,1.0063914492196986,-0.022819862004975988
173.80000000000177,15.289806901359247,0.9934416348442121,-0.022823410847189418
175.10000000000178,15.330667853800426,0.9800049666476258,-0.02248815281591643
176.4000000000018,15.37124456181371,0.9697654069684015,-0.02248986946660736
177.70000000000184,15.411598413091621,0.9646925672812219,-0.022489632886300903
179.00000000000185,15.45139461274613,0.9604239915513922,-0.022434604619736565
180.30000000000186,15.492736299266765,0.9607636255119069,-0.025114591874295655
181.6000000000019,15.53320598578084,0.9561643505117979,-0.025115439667025008
182.9000000000019,15.572942123747207,0.9602280905471996,-0.023897059024521994
184.20000000000192,15.613327480309822,0.9623692719187471,-0.023753204695870167
185.50000000000193,15.653796260445683,0.9640065658619364,-0.025778632041919103
186.80000000000194,15.693627497267935,0.9669283626882935,-0.02576984139352323
188.10000000000198,15.733918944277338,0.9706632180904506,-0.025740135228768946
189.400000000002,15.773977442339,0.9736950947898861,-0.025634062765127474
190.700000000002,15.813938472525159,0.975221153533175,-0.025443484707170505
192.00000000000205,15.853821685536023,0.9803152904128704,-0.022486931830309587
193.30000000000206,15.893865059555432,0.9854764485391219,-0.02149518548978424
194.60000000000207,15.93392858403542,0.9891608610647601,-0.020076774401944775
195.90000000000208,15.973764211348172,0.9955113157016999,-0.020490356921775366
197.2000000000021,16.01387256425014,1.001708840252039,-0.021503329297154483
198.50000000000213,16.05350389956569,1.0074783288539386,-0.02149401798380879
199.80000000000214,16.093309008663393,1.0143680571775537,-0.0226853791832462
201.10000000000215,16.133152026208563,1.022702227837383,-0.024226784982187777
202.4000000000022,16.17274758853676,1.0311284203364213,-0.024546752485000933
203.7000000000022,16.212733960627272,1.0400077378159283,-0.025494023535447052
205.00000000000222,16.252691898500206,1.0499079077886146,-0.02730368191495991
206.30000000000223,16.292153978775254,1.0630438350081106,-0.029507249304895122
207.60000000000224,16.33195662499881,1.0771692694413446,-0.030395561207434252
208.90000000000228,16.371740407810655,1.0933649309397564,-0.028923298742576264
210.2000000000023,16.411274552399842,1.115806054409188,-0.026891936586008303
211.5000000000023,16.45134084712144,1.1502494292017347,-0.02532519997994953
212.80000000000234,16.490648708772138,1.1984795303162303,-0.024492865564009314
214.10000000000235,16.52978174306367,1.270427534788279,-0.024021028047173765
215.40000000000236,16.57015646925902,1.3655468693983268,-0.024017963703210743
216.70000000000238,16.609720082474034,1.4814260137397186,-0.025097656707965044
218.0000000000024,16.64961741845623,1.6137433463320823,-0.025988035143888588
219.30000000000243,16.689598344037186,1.7495273373734999,-0.024654972374615447
220.60000000000244,16.728884337713733,1.8491891550612158,-0.02468020768364676
221.90000000000245,16.769009020558315,1.8929706039766985,-0.024680190763495702
223.2000000000025,16.80874540293563,1.8596986188069402,-0.024680183302663306
224.5000000000025,16.848599483116665,1.776649809806269,-0.02467835572957444
225.8000000000025,16.888517911893278,1.6724787625057325,-0.025929074538209917
227.10000000000252,16.927966997710925,1.5689449263879798,-0.025991378166873247
228.40000000000254,16.967364250565524,1.4750372703577868,-0.026736196856074645
229.70000000000258,17.007010635114714,1.390430516101901,-0.027817487949477027
231.0000000000026,17.04633184286893,1.3231127751001117,-0.02929845924767971
232.3000000000026,17.0854944211544,1.2669588673730652,-0.029688339708018763
233.60000000000264,17.125214888056313,1.2219800673984795,-0.02926815955262274
234.90000000000265,17.164593236859023,1.1866035727307755,-0.02937151869645538
236.20000000000266,17.203905815550765,1.1636657727662825,-0.02928046332108636
237.50000000000267,17.243089948154037,1.1420369177480478,-0.02854925361000138
238.80000000000268,17.282269906445354,1.1305934437555354,-0.02808830657526551
240.10000000000272,17.321943052539066,1.1168116174160914,-0.02939343985503662
241.40000000000273,17.36113128245325,1.109081570815171,-0.029390016583588974
242.70000000000275,17.40043791017687,1.1042912356157748,-0.02940194938062879
244.00000000000279,17.439584591894953,1.0983249944695899,-0.02807625584158213
245.3000000000028,17.479012089318644,1.094194187335273,-0.02938478327224381
246.6000000000028,17.51830913871371,1.092614369949537,-0.029390978434344905
247.90000000000282,17.55746499411163,1.089044587694024,-0.027924562336314906
249.20000000000283,17.59648390742476,1.0886107062049362,-0.0263698449157328
250.50000000000287,17.63591166715502,1.0889591264498955,-0.025982967425310033
251.80000000000288,17.67549984168981,1.0868005915294687,-0.02695007345456757
253.1000000000029,17.714691835445077,1.08850057651705,-0.02764028700093224
254.40000000000293,17.75399628145262,1.0889489118641802,-0.0275867927383886
255.70000000000294,17.793490702921524,1.090319017263674,-0.029955437789806805
257.00000000000296,17.832286749093413,1.0905946576293282,-0.030296975383192315
258.30000000000297,17.87176047798907,1.0912491811200666,-0.031595541786266335
259.600000000003,17.91103514469004,1.0924610064016278,-0.0315164825525156
260.90000000000305,17.95001057931785,1.092946173899887,-0.029848484837120548
262.200000000003,17.989473151543987,1.0926720899169733,-0.029403266702273
263.50000000000307,18.028693732069087,1.0968519619687958,-0.028746801828005708
264.8000000000031,18.06801910799135,1.0969628484243685,-0.030500255411858745
266.1000000000031,18.10734479448798,1.0995021211361795,-0.0320469971143269
267.4000000000031,18.14667110445029,1.0997618089796393,-0.03333527759787902
268.7000000000031,18.18573930804475,1.101715657938151,-0.03335090250243011
270.0000000000031,18.224993277051993,1.1007797121152982,-0.033347116940631416
271.30000000000314,18.264385028043787,1.1031370929927586,-0.03455069014767753
272.6000000000032,18.303684273163682,1.1048773248851491,-0.038289581743190304
273.90000000000316,18.34272440488253,1.107726650769309,-0.0420366864121986
275.20000000000323,18.38191473734145,1.1094671209249145,-0.04341335873936769
276.50000000000324,18.42133935880997,1.1087526265600454,-0.04258853145121
277.80000000000325,18.460748452161905,1.1101847509653,-0.042111011771259754
279.10000000000326,18.50008964105396,1.1111958624014333,-0.042123572322675606
280.4000000000033,18.538860598926323,1.1116567523028273,-0.03922724001059441
281.70000000000334,18.578460520694755,1.1102012797413612,-0.03482348038305849
283.0000000000033,18.61778193389837,1.1104687958034212,-0.03204173375997499
284.30000000000337,18.657225197088344,1.114583906581671,-0.030710810102262176
285.6000000000034,18.69630483975372,1.1130134658056297,-0.030127998483802543
286.9000000000034,18.735856985900842,1.1133769675884848,-0.029389969323474485
288.2000000000034,18.77528248944144,1.114566032700407,-0.030698411684124238
289.5000000000034,18.814142067075114,1.1157683924187836,-0.032786809424107055
290.8000000000034,18.853794512047187,1.1176258457587538,-0.034786384870967524
292.10000000000343,18.89332396691146,1.1197575323368627,-0.03714067861812831
293.4000000000035,18.932383130107787,1.1204521736791344,-0.03739860273358664
294.70000000000346,18.971455585778646,1.1204695677363128,-0.038511895285205267
296.0000000000035,19.010898675905796,1.123673852059036,-0.04004138370413868
297.30000000000354,19.05063364751942,1.1232147863348223,-0.04144091049221288
298.60000000000355,19.089559265254366,1.1242673425242977,-0.04146164619544512
299.90000000000356,19.129291034533153,1.127448727358457,-0.042772692190358175
301.20000000000357,19.168588773774943,1.1252856057374974,-0.04273630218443625
302.50000000000364,19.208065122691078,1.1269279037302329,-0.04276541614402918
303.8000000000036,19.24734122026365,1.1260929036305716,-0.040032699057077625
305.10000000000366,19.28662897032096,1.1285051764748493,-0.04004097022498421
306.4000000000037,19.32620810758312,1.1272854213844494,-0.04046169748418027
307.7000000000037,19.365283009253346,1.1295446207381958,-0.041352893637818244
309.0000000000037,19.40492995382781,1.13049397774577,-0.04135012216341938
310.3000000000037,19.444075964595253,1.1315797196900639,-0.04134832574099745
311.6000000000037,19.48371793789793,1.1326288307332197,-0.04120119939623912
312.90000000000373,19.52303079113512,1.1320132306197466,-0.04262607203324542
314.2000000000038,19.562533814271646,1.1341742568663848,-0.04390220834533487
315.5000000000038,19.602025629685084,1.1355110465943665,-0.043266143899893805
316.8000000000038,19.64142340748574,1.1357452789690479,-0.042637008302643054
318.10000000000383,19.680638006086873,1.137130671841827,-0.04293716788407176
319.40000000000384,19.720266017776396,1.1421828680387465,-0.04411264164931472
320.70000000000385,19.75978306335378,1.14342260489826,-0.04631428952423455
322.00000000000387,19.799048131649748,1.1448403363110353,-0.047817260386293636
323.3000000000039,19.838601159951878,1.147041037479173,-0.049096655789491184
324.6000000000039,19.878296947851908,1.1511160641083638,-0.05192083516523205
325.90000000000396,19.917812235881303,1.1531321346056655,-0.05331194873723666
327.20000000000397,19.956681381613407,1.155444052529817,-0.0528505704484199
328.500000000004,19.996975290463,1.1579359286081283,-0.05317816212064841
329.800000000004,20.03669610437903,1.1579016154728232,-0.052180564746739044
331.100000000004,20.075940763257787,1.1628909666940659,-0.05312817410961035
332.400000000004,20.11551101734958,1.1669604668950493,-0.05465459226539293
333.700000000004,20.155389185684168,1.1667085461009457,-0.05473764955080407
335.0000000000041,20.195007374149643,1.16966011943429,-0.055953752990936856
336.3000000000041,20.234777000320086,1.1741601799531987,-0.057441879124157325
337.6000000000041,20.27450111104593,1.1772782263549315,-0.05980329028826592
338.9000000000041,20.31421143444713,1.1805365131993566,-0.061763421656576334
340.20000000000414,20.354067318547756,1.1828912612794815,-0.06322976964683313
341.50000000000415,20.39374031860276,1.1867599073231814,-0.06509538172984763
342.80000000000416,20.43302141544685,1.1904114284326668,-0.06722714156705578
344.1000000000042,20.473142828346077,1.1941431250841046,-0.06569092530298493
345.4000000000042,20.513037737602456,1.1957825762769565,-0.0627404474394786
346.70000000000425,20.552646676020363,1.2009469946890337,-0.06396174583414371
348.00000000000426,20.592585003337472,1.2067727131559016,-0.0678808567867839
349.3000000000043,20.63247915750851,1.2130793890524931,-0.07077953781793545
350.6000000000043,20.672112419335473,1.2175381831664516,-0.07298514746616558
351.9000000000043,20.712364612898018,1.2245554698083467,-0.07519153538029144
353.2000000000043,20.75224630153987,1.230061825077887,-0.07758936353381518
354.5000000000043,20.79210833360245,1.2365249884037317,-0.0807289215770326
355.8000000000044,20.832146653113558,1.2433856641981196,-0.08609280481978177
357.1000000000044,20.872302312350254,1.2510315417721407,-0.09391909864949932
358.4000000000044,20.91205225652965,1.2577391692329396,-0.10198281780732232
359.7000000000044,20.95200877959103,1.2657832412703767,-0.10522283493736495
361.00000000000443,20.991972288261806,1.2734181355804979,-0.10811552318128381
362.30000000000445,21.0322926799744,1.281393143892408,-0.11111956693587377
363.60000000000446,21.072420015457894,1.2911586488724958,-0.11454546311396197
364.90000000000447,21.112429492413288,1.3027978408597716,-0.11735507680418555
366.2000000000045,21.152162605127316,1.3119068175228357,-0.12205091290555004
367.50000000000455,21.19259922620505,1.3208172301478673,-0.12561532296809075
368.80000000000456,21.232862697502092,1.332117195015242,-0.1313651968132672
370.10000000000457,21.27209380759214,1.344299428137431,-0.13952605451652822
371.4000000000046,21.313037635549914,1.3586019021503488,-0.14633014278612544
372.7000000000046,21.353047383267032,1.375995990750076,-0.15383897013779624
374.0000000000046,21.393287193057102,1.3921267182175372,-0.163383013685225
375.3000000000046,21.433640822487916,1.4126424664917867,-0.17379407846302097
376.6000000000047,21.473852751109057,1.4317245482944732,-0.18474053829995984
377.9000000000047,21.514109486025472,1.4536337909989836,-0.19427771556357953
379.2000000000047,21.55406746760331,1.4772059826338821,-0.20428092527302955
380.5000000000047,21.59446693830779,1.5070762421431647,-0.21253156339061618
381.80000000000473,21.634954901440068,1.535714634311409,-0.21922576307131036
383.10000000000474,21.675176285329695,1.5695821295585475,-0.22537669103126534
384.40000000000475,21.715101717671324,1.6062073153079486,-0.23762424976772767
385.70000000000476,21.755957995552144,1.643832598710801,-0.2507398461215544
387.0000000000048,21.796244373800075,1.6843364296117187,-0.2620236563912708
388.30000000000484,21.83676585088366,1.7257875534004947,-0.2741503889758423
389.60000000000485,21.877017033423762,1.769290220454709,-0.289831217519934
390.90000000000487,21.91735246069116,1.814709901323612,-0.3044762251143651
392.2000000000049,21.957729320049438,1.8615802314577115,-0.32158231937947024
393.5000000000049,21.99842307400399,1.9110197359533607,-0.33829944255801037
394.8000000000049,22.038790104112888,1.9630428559060813,-0.35534514676621587
396.1000000000049,22.079355598932086,2.0196505456760034,-0.3714751873572517
397.400000000005,22.11954710604347,2.0793430031368487,-0.38649538925268345
398.700000000005,22.16060516199558,2.1397559160876725,-0.4026519743591459
400.000000000005,22.201263334813973,2.198298102400826,-0.4223962585716281
401.300000000005,22.241581624804656,2.2577401305929388,-0.44407123311816044
402.600000000005,22.28220849139086,2.3152501776846126,-0.4650110313625606
403.90000000000504,22.322895700884335,2.368419954136507,-0.4874387763980277
405.20000000000505,22.363650172191345,2.423186255044973,-0.5106714499121039
406.50000000000506,22.40416552219274,2.4725829283652887,-0.5351740080408134
407.80000000000507,22.445030465007346,2.527548520011376,-0.559521751274592
409.10000000000514,22.485750128025707,2.5763975297066652,-0.5848111405027412
410.40000000000515,22.526478697148328,2.626129822953475,-0.6124488093417058
411.70000000000516,22.567106543554363,2.67357964252651,-0.639209890948095
413.0000000000052,22.60800459597822,2.7179811251199393,-0.6682109839350052
414.3000000000052,22.648512145186782,2.764755081207517,-0.6981338930788938
415.6000000000052,22.689418228749627,2.8032728730887975,-0.7286524586115628
416.9000000000052,22.730054250838997,2.838052284351088,-0.760984268681109
418.2000000000053,22.771183092836097,2.87319710957389,-0.7946648891469037
419.5000000000053,22.811599160221547,2.8993515479863987,-0.829400124888525
420.8000000000053,22.852780730960212,2.9218128617595838,-0.8657923694660115
422.1000000000053,22.89388091611024,2.935290222826972,-0.9016227571039384
423.4000000000053,22.934577206657607,2.940276932389504,-0.9401715901677705
424.70000000000533,22.975477105055944,2.932548055050701,-0.978308436641826
426.00000000000534,23.016262002310448,2.916768697470379,-1.0163502688464883
427.30000000000535,23.05704720174976,2.8882163946421695,-1.0520152722839855
428.60000000000537,23.09789358047582,2.8413963842598315,-1.0900842437175284
429.90000000000543,23.13834779266746,2.78029875948494,-1.1267769546030975
431.20000000000545,23.17938860370335,2.7006897654153628,-1.163726898816488
432.50000000000546,23.22029376456683,2.6047531124966534,-1.1983818098463557
433.80000000000547,23.261299352753877,2.4983051721194025,-1.2351912144265138
435.1000000000055,23.30117762708624,2.379449940388912,-1.2671509418457187
436.4000000000055,23.3428208158874,2.2487709160395646,-1.3017054796529104
437.7000000000055,23.383281942926924,2.1183031691260608,-1.3291982353152525
439.00000000000557,23.424231462847292,1.988321679777717,-1.3560867794535718
440.3000000000056,23.465055718921747,1.8699036844969987,-1.3795014641733467
441.6000000000056,23.50554201242496,1.7583658550176173,-1.4001453515934537
442.9000000000056,23.546384479277293,1.6564665792566564,-1.4187273760999135
444.2000000000056,23.58717500356041,1.5719885923697532,-1.4367927490867003
445.5000000000056,23.627779214918366,1.4988137366047642,-1.4546195556921502
446.80000000000564,23.668690832836763,1.4356733450556929,-1.470637064266613
448.10000000000565,23.709297546069806,1.3857013424872235,-1.4848556050101744
449.40000000000566,23.750201057028548,1.3403391991513307,-1.498468962519857
450.70000000000573,23.79049099576818,1.3030007298521447,-1.5097302030546595
452.00000000000574,23.8320589720692,1.2732833888586539,-1.5225408194165828
453.30000000000575,23.872553288754474,1.248383875509733,-1.5350513593869168
454.60000000000576,23.91389688837046,1.2272255171356443,-1.5480633471235774
455.9000000000058,23.954917961684796,1.207400448394557,-1.5603400575825646
457.2000000000058,23.995878361779912,1.194331386472258,-1.5713702538844325
458.5000000000058,24.03673860673247,1.1830855319526745,-1.5833659125536856
459.80000000000587,24.078016126792583,1.1677089967674505,-1.5946611027177626
461.1000000000059,24.11942920529008,1.162544449778372,-1.6068555292008355
462.4000000000059,24.16035843961949,1.1548252897113147,-1.6174860208775148
463.7000000000059,24.201368850287146,1.1478256126687483,-1.6285129013816717
465.0000000000059,24.242355969333783,1.1420232925392084,-1.6423778327586955
466.3000000000059,24.283713900499674,1.1370847155475876,-1.6536916882767452
467.60000000000593,24.32493026354422,1.131828948509009,-1.665739336938545
468.90000000000595,24.366167653722684,1.1286627505845555,-1.6773097633810061
470.20000000000596,24.40737399967111,1.122349502037793,-1.6904034221306867
471.500000000006,24.448634714413192,1.1207773705295243,-1.701935944753596
472.80000000000604,24.490043320901666,1.1141229567984834,-1.71281467782189
474.10000000000605,24.531335735756933,1.1129858851715742,-1.724276520808464
475.40000000000606,24.572823222592866,1.107379653406239,-1.7360458942982997
476.70000000000607,24.613911725750345,1.1020494011271869,-1.7454581531793165
478.0000000000061,24.65522725352492,1.0965801586334951,-1.7574158851985504
479.3000000000061,24.696349547513933,1.087229154792242,-1.768449889335193
480.60000000000616,24.737898128175903,1.0819867091813113,-1.781331278375064
481.9000000000062,24.778985641270012,1.0738929444221168,-1.7907151225129305
483.2000000000062,24.820781535635877,1.0654425838888648,-1.8022074602023954
484.5000000000062,24.86216503061109,1.0550938905977558,-1.8161200679702958
485.8000000000062,24.903097079704477,1.0460160929722193,-1.8293863777166566
487.1000000000062,24.944824403772785,1.0331573707208845,-1.8435489341491085
488.40000000000623,24.98644134369143,1.0179482401280637,-1.8549566444161107
489.70000000000624,25.02801505941884,1.0051483212072707,-1.8670080067263197
491.00000000000625,25.06949121029408,0.98239081741809,-1.8844584954225105
492.3000000000063,25.1108156095149,0.9595294433810886,-1.8957943839491125
493.60000000000633,25.15266042439574,0.9314289051018707,-1.9060009894538466
494.90000000000634,25.193939840811577,0.8988049792219912,-1.9147384676362824
496.20000000000636,25.23571817512374,0.8589994890958423,-1.922811099953985
497.50000000000637,25.276958338221363,0.8208357298493427,-1.9319588842458884
498.8000000000064,25.318819653480414,0.773766685661333,-1.9432882653420829
500.1000000000064,25.360357212810353,0.7234732653920364,-1.9500614580938151
501.40000000000646,25.401807413383565,0.6741001495671926,-1.953213923678112
502.70000000000647,25.44306057316824,0.6262505033854535,-1.9580099268973208
504.0000000000065,25.484093950504306,0.5811101048140224,-1.9653248909684335
505.3000000000065,25.52670502634284,0.5365699334002068,-1.9714967814527058
506.6000000000065,25.568129493724843,0.49971361969050143,-1.9755976460955407
507.9000000000065,25.610068302154666,0.46688284692206916,-1.9797314654249334
509.2000000000065,25.651335132935827,0.4387177036557508,-1.9811568882263542
510.50000000000654,25.693535613185407,0.41668682015143865,-1.9813617033445534
511.80000000000655,25.734736454824894,0.3953751970265649,-1.9824623111845772
513.1000000000066,25.77671327907932,0.3785547714705175,-1.9810004608878113
514.4000000000067,25.818511210053114,0.36681763774196474,-1.9798391921933605
515.7000000000066,25.859854297773992,0.3552922349506962,-1.9798397683833646
517.0000000000066,25.9017844911678,0.3456882430681594,-1.9798248478654212
518.3000000000067,25.943624396844626,0.3349182852764685,-1.9770929737947691
519.6000000000067,25.985466121496348,0.32587640704338994,-1.9782766956659765
520.9000000000067,26.027190720244356,0.32312791272893593,-1.979922927649441
522.2000000000068,26.069267124727162,0.314009563757949,-1.981235354859829
523.5000000000068,26.111026948071707,0.30666523242909927,-1.982581429005763
524.8000000000068,26.15265954205096,0.3024500038627618,-1.98278363703283
526.1000000000067,26.19462843956442,0.2951992202839331,-1.980410276927476
527.4000000000068,26.236671194736324,0.2889294546835197,-1.9809403864232284
528.7000000000069,26.27839657284351,0.28340996116030537,-1.9836920928685386
530.0000000000068,26.320277793790375,0.2725162501041487,-1.9855664963303123
531.3000000000068,26.362503333677747,0.26841765865030043,-1.985540447844211
532.6000000000068,26.40439799939803,0.26084844680780583,-1.9855401952432605
533.9000000000069,26.446101423292692,0.25977996377115997,-1.985540194002143
535.2000000000069,26.48805163872447,0.26482798340004043,-1.9855401937854942
536.5000000000069,26.529833209360348,0.27275833323950116,-1.9855402272017484
537.800000000007,26.571434739190153,0.2817321448889849,-1.9855674116675859
539.100000000007,26.613698806555337,0.2878676041993642,-1.9842332689949789
540.4000000000069,26.655568696210455,0.29129704992945205,-1.9837900375546598
541.700000000007,26.697523646565656,0.2992209164539614,-1.9829032570927243
543.000000000007,26.73938496358515,0.2993113661464495,-1.9839088119290578
544.300000000007,26.781575729362903,0.29767645855740765,-1.984220143207141
545.6000000000071,26.823426660612817,0.2975846773948956,-1.9842212003516537
546.9000000000071,26.865674094465934,0.29780553188278835,-1.9856147961875346
548.2000000000071,26.90742412229999,0.29067318867381275,-1.985522871490776
549.500000000007,26.949650745542144,0.28538069151755874,-1.9842237670413199
550.8000000000071,26.991671574339946,0.28512814835887856,-1.9843333918897357
552.1000000000072,27.033934507010482,0.2813641881770752,-1.9855436222821674
553.4000000000071,27.076101946434875,0.2812570943280819,-1.9855405839796991
554.7000000000072,27.118152196959937,0.2801339409378971,-1.987097067343004
556.0000000000073,27.160109368231613,0.2790345619744634,-1.9870392268182897
557.3000000000072,27.20236188913655,0.2753168383514639,-1.9869703661045541
558.6000000000072,27.244821401735344,0.2720549590272332,-1.9860427789333777
559.9000000000073,27.286637279700553,0.27475068148213566,-1.984268307508489
561.2000000000073,27.329268896614636,0.2683725756062225,-1.9856493580003125
562.5000000000073,27.371417094206652,0.26683701492607903,-1.9856506684715107
563.8000000000073,27.413469303333866,0.26336528863148057,-1.9860336691834068
565.1000000000073,27.45588915666496,0.26266398356294984,-1.9855281706032604
566.4000000000074,27.49806735735724,0.2581260841316686,-1.9868209088555675
567.7000000000073,27.54061519799248,0.25457051662390406,-1.9855349868125924
569.0000000000074,27.58276307023122,0.25486544421695023,-1.9857092514842387
570.3000000000075,27.62517439151336,0.25246085999029955,-1.9872384837229258
571.6000000000074,27.66769347338023,0.25536345814261385,-1.9868844597417676
572.9000000000075,27.7096161419975,0.2508113625368549,-1.9881729134739743
574.2000000000074,27.7523891101823,0.24633460470671187,-1.9893887616501407
575.5000000000075,27.794415660384,0.24244108696674305,-1.989491070613031
576.8000000000075,27.836960896167255,0.23735866961781604,-1.987290128557357
578.1000000000075,27.87930154295451,0.2316236603302757,-1.9858496754967496
579.4000000000076,27.921847924329256,0.22736641691166937,-1.9858584135268251
580.7000000000075,27.964082967680024,0.22418506648999892,-1.9869056843203188
582.0000000000076,28.00657999380635,0.21926741030520125,-1.9886206965736672
583.3000000000076,28.048935430547402,0.21554637186023262,-1.9903658704627785
584.6000000000076,28.091498281475598,0.2096913402598508,-1.9882601763347925
585.9000000000076,28.133787269485076,0.20900766562449258,-1.988610717834245
587.2000000000077,28.176524909878555,0.21087082857023143,-1.9900965142082327
588.5000000000076,28.219102945517445,0.20574239084840262,-1.9908517628600784
589.8000000000077,28.26159565341538,0.20304619987454764,-1.9897628353068288
591.1000000000078,28.304049821544442,0.19875676123822394,-1.9883947134583582
592.4000000000077,28.346653586382306,0.20109892998697498,-1.9875214497281308
593.7000000000078,28.389236626759864,0.20256630331458347,-1.988389841300727
595.0000000000077,28.431927377627495,0.20623434152431086,-1.988606987549609
596.3000000000078,28.474439805479005,0.20692992282599465,-1.9899926313838634
597.6000000000078,28.517228386659472,0.21236943542849795,-1.9898895931301852
598.9000000000078,28.559585825992862,0.21383406819762452,-1.990067435239427
600.2000000000078,28.60245633137124,0.22283896528833158,-1.9912837786421296
601.5000000000078,28.645118312549393,0.22442062519216766,-1.992508204266767
602.8000000000079,28.68762882393095,0.23310623732743307,-1.9950884292140691
604.1000000000079,28.73075062752655,0.2415418516149681,-1.9967064908374361
605.4000000000079,28.77315327682494,0.2424774232755489,-1.9967353748938952
606.7000000000079,28.81576917086334,0.25223143804028636,-1.9967586139271347
608.000000000008,28.858506082529992,0.25793694205224527,-1.9973634925692436
609.3000000000079,28.901304188248705,0.26647895655805987,-1.9974019931988902
610.600000000008,28.943957568635476,0.27566896281419373,-1.9960730217565539
611.900000000008,28.986773177776758,0.2819870132561544,-1.99630381313274
613.200000000008,29.029567005706454,0.29037550162154724,-1.9976065924948223
614.5000000000081,29.0724681226455,0.29441712650308904,-1.9976099620091592
615.800000000008,29.115343472551935,0.2993839982295945,-1.9976132211834048
617.1000000000081,29.158352401368823,0.3086869569326529,-1.9976093827423131
618.400000000008,29.201106935242635,0.31622259006569253,-1.9976000712093382
619.7000000000081,29.243764243232416,0.3235506619584476,-1.998460542197686
621.0000000000082,29.28671421198736,0.327450608719668,-1.9991983267147893
622.3000000000081,29.329606717087845,0.33624967552921525,-2.000339389982915
623.6000000000082,29.372157424353908,0.34572567991521175,-2.0003397594970345
624.9000000000082,29.414995694958243,0.35028897864865827,-2.002089296453446
626.2000000000082,29.457696537683315,0.36278025138129943,-2.004455856920103
627.5000000000082,29.50058132711806,0.3650323936618902,-2.0031455180365763
628.8000000000083,29.543687084462924,0.3755855572794349,-2.0029770338289947
630.1000000000082,29.586458219172883,0.3786689546300117,-2.0029807696014514
631.4000000000083,29.629537461929473,0.390554140555861,-2.0043067337409797
632.7000000000083,29.672284964068126,0.3967988020697075,-2.0056202819686035
634.0000000000083,29.715260980513342,0.40318023919657886,-2.0039385856325422
635.3000000000084,29.757959585530386,0.41096586308039784,-2.001903219615705
636.6000000000083,29.80124747853572,0.41631695473194164,-1.9993646894414745
637.9000000000084,29.84387189307472,0.425276565250436,-1.998259338063153
639.2000000000083,29.887039558086308,0.4393018020874795,-1.9982601441066539
640.5000000000084,29.929605905539187,0.4505911075004092,-1.9973292380117131
641.8000000000084,29.97256795884199,0.4604011089701152,-2.000721844503906
643.1000000000084,30.015575850133065,0.46982856307705667,-2.0038999855899737
644.4000000000085,30.058614456539893,0.47795672215154017,-2.006490848050193
645.7000000000085,30.101649711919144,0.4896667132612711,-2.0072880509864635
647.0000000000085,30.144699756465,0.5005065160650877,-2.0077132599162004
648.3000000000085,30.18742138319182,0.5151344194496024,-2.0095832542378944
649.6000000000085,30.230288477108818,0.526189563392522,-2.011054964475348
650.9000000000085,30.27331300502097,0.5437188526166441,-2.0122959185584355
652.2000000000086,30.316236253927716,0.5581627741243875,-2.0147278281831094
653.5000000000086,30.35956530231873,0.5766132760211855,-2.0147100613935827
654.8000000000086,30.401939761587514,0.5973438965440594,-2.014984113983143
656.1000000000087,30.44540181682771,0.6183004336279523,-2.0126201482406865
657.4000000000086,30.48827026037414,0.6430540327367198,-2.0126668233977707
658.7000000000087,30.531583825744285,0.6631350313371582,-2.0154528526454496
660.0000000000086,30.57413262918256,0.6899280570559512,-2.018140847018035
661.3000000000087,30.61732821823649,0.713484122058833,-2.020865563574898
662.6000000000088,30.660262611766264,0.7355320553474449,-2.0221623075872284
663.9000000000087,30.703384036843623,0.765732594022674,-2.0235664004169136
665.2000000000088,30.746579766229,0.7858723753049763,-2.024925566035983
666.5000000000088,30.789234198107195,0.8050418593303403,-2.027777037534199
667.8000000000088,30.83268266397328,0.8341450341145538,-2.0291426784523967
669.1000000000088,30.875453329555686,0.8648233724337695,-2.0283369889394818
670.4000000000088,30.918412906149975,0.8926534678543412,-2.028468607223431
671.7000000000088,30.961364916667716,0.9245371814581222,-2.0282551836261717
673.0000000000089,31.004387710865824,0.9552838196052424,-2.030937002178831
674.3000000000089,31.04732637194613,0.9909965785195913,-2.033591282655454
675.6000000000089,31.09067012542005,1.0251645259036084,-2.0356018774785607
676.900000000009,31.133422890139112,1.0570736294480323,-2.039946591322172
678.2000000000089,31.17663511000311,1.0878504622874665,-2.0437795244198007
679.500000000009,31.219661596875202,1.1231371803902221,-2.0471056196249515
680.8000000000089,31.26303867897241,1.1563991356328671,-2.049370856907225
682.100000000009,31.306144565229218,1.1908974290240382,-2.0519008490765795
683.400000000009,31.349202705543547,1.2281205065993328,-2.054521964194514
684.700000000009,31.392290046155527,1.26445837983543,-2.0557954261202296
686.0000000000091,31.435207374700948,1.3018325927726169,-2.059476427540105
687.300000000009,31.478619923085038,1.3345686795291418,-2.0608338731759397
688.6000000000091,31.52171525729051,1.3788360706307445,-2.062939689499708
689.9000000000091,31.564766669174357,1.4238383404814696,-2.0645751673361206
691.2000000000091,31.607943562314517,1.468710691042741,-2.06672030433364
692.5000000000091,31.651202887868553,1.5165974929895287,-2.070743246257959
693.8000000000092,31.694615553804443,1.5630982276730863,-2.074512692336079
695.1000000000092,31.73775963273382,1.6168877298144104,-2.0754103210485586
696.4000000000092,31.780830680705275,1.6673408822210831,-2.079732581770349
697.7000000000093,31.82399594496171,1.7232028842827147,-2.083015684058166
699.0000000000092,31.86745585723295,1.7815128849954576,-2.0876107160430317
700.3000000000093,31.910749176902286,1.8369326073006138,-2.090396557359956
701.6000000000092,31.953863110137647,1.8978146497093125,-2.0952560911737517
702.9000000000093,31.99725990360103,1.9623181662623326,-2.1037047142605108
704.2000000000094,32.04081815847429,2.0308648426729508,-2.108079690509422
705.5000000000093,32.083864605085246,2.0985235842728707,-2.1107132519112426
706.8000000000094,32.127453947200564,2.168947871656825,-2.1175144981928544
708.1000000000093,32.17057784485755,2.2460412956158136,-2.122162410722572
709.4000000000094,32.214057584573304,2.3239721969506975,-2.1247103684980146
710.7000000000094,32.25721781179701,2.401947793677632,-2.128464750182922
712.0000000000094,32.30050034022163,2.4906429040002553,-2.1362027051512045
713.3000000000094,32.34415856506237,2.5816431719511277,-2.145628441542116
714.6000000000095,32.38730844958486,2.6764883289468755,-2.1529504048498915
715.9000000000095,32.43027222863989,2.7679457324655723,-2.162288172238851
717.2000000000095,32.47441324477668,2.869444111243422,-2.1690129530044175
718.5000000000095,32.517548504532044,2.9710013608413717,-2.1730506420554807
719.8000000000095,32.560093800529074,3.0750160615108437,-2.181283421317675
721.1000000000096,32.60432828857231,3.183130919185289,-2.189755951101149
722.4000000000095,32.64768213330672,3.2938933603793594,-2.196889562042812
723.7000000000096,32.6911295683105,3.405234402509942,-2.202872744977141
725.0000000000095,32.73492298564191,3.5171539061465302,-2.2119915615606063
726.3000000000096,32.77813675776763,3.6293671741214184,-2.2227198079057757
727.6000000000097,32.82166794781718,3.7373362308810636,-2.2313514792083886
728.9000000000096,32.865042366472004,3.8517128515435246,-2.237597926892379
730.2000000000097,32.90853172111586,3.9580406107412816,-2.2458844873424293
731.5000000000097,32.951981471825945,4.069269408913849,-2.2538994318906544
732.8000000000097,32.99553936767354,4.176905793554304,-2.264824946527468
734.1000000000097,33.03903404355599,4.2893391463636785,-2.277008998209306
735.4000000000098,33.08246721048223,4.39441835113327,-2.290698910981713
736.7000000000098,33.12596682784633,4.501226958125434,-2.3045653613832067
738.0000000000098,33.169595690748565,4.611291933042912,-2.318621389723482
739.3000000000098,33.213112813289676,4.716775163142842,-2.3295783586325043
740.6000000000098,33.25646473966323,4.8192539751945525,-2.34008872504375
741.9000000000099,33.30038424394418,4.934127848378284,-2.3537147523222615
743.2000000000098,33.34357241889987,5.038976325941669,-2.365721717134128
744.5000000000099,33.38696121959999,5.144181730063236,-2.3799182272647235
745.80000000001,33.43055603008157,5.251847204205367,-2.3933844408191822
747.1000000000099,33.474281385997436,5.353565589209916,-2.4086736882918633
748.40000000001,33.517792274926265,5.459674829791903,-2.4223502431213095
749.7000000000099,33.56126232593735,5.554569126488332,-2.435530287425486
751.00000000001,33.60460436065899,5.651987281877123,-2.4506852323974853
752.30000000001,33.6483279846945,5.746885813959236,-2.4657868482795413
753.60000000001,33.691994836692935,5.837127929238936,-2.481004689046714
754.90000000001,33.73577791761514,5.928205457840864,-2.4960672831363175
756.20000000001,33.77903708085132,6.00874156549146,-2.5126294440590717
757.5000000000101,33.82267431300082,6.083119188478863,-2.528983623881635
758.8000000000101,33.86629840952868,6.151325219878011,-2.5446548458597142
760.1000000000101,33.90985386454124,6.211218892853692,-2.5627236345473623
761.4000000000101,33.95331911775878,6.264873658617254,-2.577797952953321
762.7000000000102,33.99716325111842,6.305796695230695,-2.5930817459104136
764.0000000000101,34.040566854051946,6.339349946236599,-2.6082639081976886
765.3000000000102,34.084080117899646,6.357918023895799,-2.624513091050396
766.6000000000101,34.12781913162232,6.365751027171342,-2.645459315964272
767.9000000000102,34.17048312574916,6.359590030634328,-2.6629147005723364
769.2000000000103,34.214814353781065,6.337764159339823,-2.678519534685189
770.5000000000102,34.25838076783307,6.2982476651722745,-2.695772598515375
771.8000000000103,34.30177545785531,6.234119578827228,-2.714827480498747
773.1000000000103,34.34455780390442,6.139944193569193,-2.7314123196930655
774.4000000000103,34.38790622683352,6.000641337840907,-2.74785043565516
775.7000000000103,34.43234284050618,5.797662532040778,-2.7624519436364006
777.0000000000103,34.475555065371694,5.504364604236997,-2.7764142347974436
778.3000000000104,34.51907110466354,5.049473852982789,-2.788750704040953
779.6000000000104,34.562077276651664,4.3402101057106215,-2.8032114854491232
780.9000000000104,34.60524412655701,2.9918689497536604,-2.8142607274414377
782.2000000000104,34.64806215326286,1.6403701797037438,-2.8250519231008027
783.5000000000105,34.69092318157491,0.8880582363573448,-2.827932688987537
784.8000000000104,34.733191165644506,0.46938795335815,-2.8283430790256947
786.1000000000105,34.77654795184924,0.21771125249648327,-2.831281902940387
787.4000000000106,34.819706438802974,0.07197169091895672,-2.8312229249106733
788.7000000000105,34.86279261301915,-0.012509404961064341,-2.832200050398459
790.0000000000106,34.90618976029706,-0.059266734432963375,-2.82916895677489
791.3000000000105,34.94953626246256,-0.08742719832184198,-2.8285802367607134
792.6000000000106,34.99312389759455,-0.102344544710955,-2.828579812623354
793.9000000000106,35.03673925602733,-0.10831799580734236,-2.829705600558
795.2000000000106,35.07990481587079,-0.11453705091421051,-2.8299000763232662
796.5000000000106,35.123423337740725,-0.11088772558790527,-2.829899885606899
797.8000000000106,35.166987266644966,-0.10900745491862596,-2.8298998835742006
799.1000000000107,35.21028502761957,-0.10776289852026588,-2.829899784770367
800.4000000000107,35.25419703742224,-0.10541478741684562,-2.8298123353937212
801.7000000000107,35.29733873836882,-0.1091795250656058,-2.8306455814933376
803.0000000000107,35.34095049304732,-0.10785525709998778,-2.8299008903386507
804.3000000000108,35.384239579021994,-0.10180714476508879,-2.8298994327706772
805.6000000000107,35.42764013327299,-0.09715406860538733,-2.8312061517616396
806.9000000000108,35.47125803488368,-0.09109043133916339,-2.8313605897613687
808.2000000000107,35.51473842814684,-0.09203711942496495,-2.8312057057055
809.5000000000108,35.55747493597917,-0.091052321665269,-2.8300184591538375
810.8000000000109,35.601896752094405,-0.08392955455467366,-2.8311926369118696
812.1000000000108,35.64537201604974,-0.08338595717584285,-2.8307213012521544
813.4000000000109,35.68870630219041,-0.08175377646564641,-2.828564034779231
814.7000000000108,35.732503443118624,-0.07382217499074528,-2.8272373662516133
816.0000000000109,35.776213546471446,-0.06935286173997746,-2.82594178592188
817.3000000000109,35.81986607626013,-0.07344807459828484,-2.827031764594035
818.6000000000109,35.862725651851655,-0.06753027429069292,-2.8302086960960464
819.900000000011,35.906946651689864,-0.06635340280422941,-2.8307950090393277
821.200000000011,35.94983943448443,-0.06326370395367586,-2.8307901669783373
822.500000000011,35.99416550651956,-0.05932337455671455,-2.8292893098127356
823.800000000011,36.03778645955451,-0.05658869688470913,-2.828028108704114
825.100000000011,36.08156252250003,-0.06066185650256806,-2.8280620272715424
826.400000000011,36.12496734322664,-0.055587606768681574,-2.8277084617310817
827.7000000000111,36.1687103965008,-0.05240727754341723,-2.8280316035917883
829.0000000000111,36.21256642923514,-0.05315097659605339,-2.828365965721779
830.3000000000111,36.25592706613494,-0.0555305741903962,-2.827749020259921
831.6000000000112,36.2998100170489,-0.05178976199005669,-2.829027282209494
832.9000000000111,36.34355979046781,-0.05529375891723731,-2.830323679790795
834.2000000000112,36.386897059719914,-0.05161232131668214,-2.8303401608180723
835.5000000000111,36.43099078907302,-0.04849753443353544,-2.8308450689001567
836.8000000000112,36.47489760202062,-0.04875234023844799,-2.830475038937335
838.1000000000112,36.51865852160488,-0.050003499208011615,-2.830274487423717
839.4000000000112,36.56255903732934,-0.048149931239549026,-2.8284037782984552
840.7000000000113,36.60640033463038,-0.04535945889228277,-2.8274799611182244
842.0000000000113,36.6501389290912,-0.04641978561097648,-2.8274859322075194
843.3000000000113,36.69337041038207,-0.04719340320728582,-2.828835989521547
844.6000000000113,36.73763154214938,-0.04107968559721975,-2.8287997642329517
845.9000000000113,36.78149042834921,-0.03989182322957063,-2.8295291690733935
847.2000000000113,36.82552431219064,-0.040477229724603436,-2.829460221764398
848.5000000000114,36.86917000000038,-0.03824906182604071,-2.8294601107580295
849.8000000000113,36.91302522332019,-0.029154035633776054,-2.8298006938392364
851.1000000000114,36.95697475991642,-0.030033543834576903,-2.8294545005240272
852.4000000000115,37.00095414023519,-0.0251526125872088,-2.8291464503155757
853.7000000000114,37.04447101224788,-0.02612054559877608,-2.827701902821253
855.0000000000115,37.088579511199214,-0.02633254612457181,-2.826278211694226
856.3000000000114,37.1322243192905,-0.022642276042346587,-2.8262247174626784
857.6000000000115,37.17616454900705,-0.0204504630346376,-2.82770676359823
858.9000000000115,37.220377600203605,-0.020656052725172902,-2.827707600374749
860.2000000000115,37.2639189685054,-0.019371427707802535,-2.8297511151742496
861.5000000000116,37.308004364353174,-0.01893724426325738,-2.8318857808616222
862.8000000000116,37.35203543370689,-0.011988205420697451,-2.831841925384889
864.1000000000116,37.39595727971214,-0.008907876049386143,-2.834355138786806
865.4000000000116,37.439683186454346,-0.011138219000855543,-2.8345132066723497
866.7000000000116,37.483669686351355,-0.0025693438517091494,-2.8332312397003916
868.0000000000116,37.527416072149364,-0.0008734710842177584,-2.83318839649149
869.3000000000117,37.571170350311455,-0.001063787474114175,-2.8318934797309936
870.6000000000117,37.61532298878762,-0.004245595103127275,-2.831857521143621
871.9000000000117,37.659136406468,0.003416192060553769,-2.830561326627793
873.2000000000118,37.70308940273761,-8.804894098890514e-05,-2.8305600541351374
874.5000000000117,37.74699348623754,0.005067175454564143,-2.8305609185451917
875.8000000000118,37.79105639956894,0.007523437708329084,-2.8313760910367396
877.1000000000117,37.8351478179125,0.002198288200511378,-2.831869117709647
878.4000000000118,37.87887064131117,0.0030151735796422052,-2.831896434349394
879.7000000000118,37.922954919742004,0.0027668993466574143,-2.8368910251282076
881.0000000000118,37.96689351460394,0.0031229486676256357,-2.8364751135561934
882.3000000000119,38.01104368177772,0.0008786204210635695,-2.833782151021373
883.6000000000118,38.05352367228414,0.004577881177561416,-2.834923165504638
884.9000000000119,38.09889775048076,0.005767490327473368,-2.834950235745898
886.2000000000119,38.14263543144187,0.002434267170500437,-2.836348408045355
887.5000000000119,38.18646055012132,0.009265436737508903,-2.8376962849746
888.8000000000119,38.23053124220491,0.006085930999337741,-2.8350880539945087
890.100000000012,38.27392529287912,0.007835609761323692,-2.8332882750938344
891.0000000000119,38.304765764422825,0.006011997239248945,-2.833186669004074