File: 01_Data/Nylon_Carpet_Low_Pile/STA/N2/30K_min/Nylon_Carpet_Low_Pile_STA_N2_30KData_220107_R4.csv
##Temp./Â°C,Time/min,DSC/(mW/mg),Mass loss/mg
49.0,10.493873916403386,0.007471822101888792,0.0021445659238121806
50.30000000000002,10.729541712888949,0.06591965471718086,0.00321478126857766
51.60000000000004,10.865241482044864,0.11513201996795175,0.000909705046774345
52.900000000000055,10.974405485475875,0.15550154820892859,0.0008821151954858664
54.200000000000074,11.066688072007189,0.19014413838114808,0.005296038187195151
55.50000000000009,11.147627157920478,0.22226627187118214,0.006446772826933067
56.80000000000011,11.222125566841491,0.2531277269437495,0.005733122042434591
58.10000000000013,11.29193107120713,0.2785231818169286,0.006752468001076206
59.40000000000015,11.357248147568132,0.30174588300571004,0.010929735361285609
60.700000000000166,11.41949993981545,0.32716193120051196,0.007981843205014716
62.000000000000185,11.478996353435694,0.3461421560992216,0.007926021787020954
63.3000000000002,11.536608761935895,0.36547794317241533,0.0077888848814327005
64.60000000000022,11.593209831506345,0.38608510035572763,0.007673347035939138
65.90000000000023,11.647728044323502,0.4025463576063364,0.007646103287370032
67.20000000000026,11.70169000508016,0.42119747134702507,0.006445862579542272
68.50000000000028,11.753864144369205,0.435727000443674,0.006239710589088787
69.8000000000003,11.805495921974536,0.4507564005450954,0.006517493429018639
71.1000000000003,11.855723700310321,0.4660952398214584,0.006313475327993423
72.40000000000033,11.906194075971014,0.4810909212172072,0.003939637780061567
73.70000000000036,11.955715709176468,0.49331172921734345,0.0045128143236805585
75.00000000000037,12.004454964273956,0.5015917703938291,0.0034758420366380882
76.30000000000038,12.053273884998923,0.5172621558827614,0.0016444285359833444
77.6000000000004,12.101416121154553,0.5244158521329509,-3.352877966378287e-07
78.90000000000043,12.148847451922654,0.5337176555781614,0.001489425722280835
80.20000000000044,12.196760063002351,0.5415605804628358,0.002304379683189417
81.50000000000045,12.243409194714468,0.5496601565440205,0.004597004956160777
82.80000000000048,12.289822687492526,0.5579001191258005,0.005795095045474596
84.1000000000005,12.336574250201403,0.5670717477750677,0.007360251510363458
85.40000000000052,12.382662587496228,0.5734450360511082,0.007770787324103079
86.70000000000053,12.42808233315785,0.5802280357083516,0.0065871857281467605
88.00000000000055,12.473501170796865,0.5881669811242477,0.006974878650274352
89.30000000000058,12.519030563062914,0.5965951805484254,0.005404986105902676
90.60000000000059,12.564252410296014,0.6009952866818168,0.00696194065279343
91.9000000000006,12.609241996984206,0.6085983015740437,0.007491549995074731
93.20000000000063,12.654100462345346,0.6133557320593249,0.007462043285766384
94.50000000000065,12.69869369047395,0.6192070812019623,0.006059442462922782
95.80000000000067,12.743180225647754,0.6257150707356898,0.005192443123670731
97.10000000000068,12.78746201066529,0.6318873820170957,0.0028966822938056858
98.4000000000007,12.832113415951339,0.6390605492191639,0.004286908596482952
99.70000000000073,12.875995276906975,0.6436725469331295,0.0042781159586753326
101.00000000000074,12.920378697339592,0.6474704347979138,0.004279588556887148
102.30000000000075,12.964030741440043,0.6523291244151125,0.005638503700379882
103.60000000000078,13.008192729896411,0.6584266506716737,0.005548267881913649
104.9000000000008,13.051951531038949,0.661666601568252,0.006771886376319536
106.20000000000081,13.096093241959782,0.6626034825557614,0.006260895156654733
107.50000000000082,13.139572625666688,0.6688908740960859,0.006887495275736288
108.80000000000085,13.18364291715104,0.6714704593729798,0.0043599085893415435
110.10000000000088,13.227373134474128,0.67306809164993,0.0036127712236622145
111.40000000000089,13.271054950563217,0.6769340113110407,0.0012889344659963164
112.7000000000009,13.314777627296754,0.6787464802986163,0.00031712131826866496
114.00000000000092,13.358277811528314,0.6779124759756975,0.0004325186913578527
115.30000000000095,13.40197988064089,0.6811518405611087,0.0005552102539496673
116.60000000000096,13.445334742229416,0.6810876635475164,0.0016397121411606541
117.90000000000097,13.488902829049147,0.6835371538693615,0.0016184331084572179
119.200000000001,13.532357841867753,0.6827540032754689,0.0013170520935847918
120.50000000000102,13.575308302635905,0.6859128180091115,0.0012636469714655263
121.80000000000103,13.618435587318693,0.686658365781724,0.0026229422238683853
123.10000000000105,13.66183155101237,0.6878412799806111,0.0026303466094850236
124.40000000000107,13.704809254316425,0.6875147673623829,0.0016754563163621228
125.7000000000011,13.74764312319212,0.6884755617575447,0.0018613681893211442
127.00000000000111,13.79055967731282,0.6904025496853782,0.0016792875677280605
128.30000000000112,13.833126774873822,0.6934645268381441,0.0016351961417888639
129.60000000000116,13.876230520897236,0.6946040654696005,0.00036655152353093357
130.90000000000117,13.918431459887543,0.6952008631079643,-0.0009802583214812977
132.20000000000118,13.961452307308466,0.697526546198352,-0.0006291449395123827
133.5000000000012,14.004000464398898,0.6991828805004698,-0.0006599261256856614
134.8000000000012,14.046179463917314,0.7014615428317197,-0.0006661083497379039
136.10000000000124,14.088327061284735,0.7015770095856109,0.0006224401767167542
137.40000000000126,14.130369432293945,0.7057499836388095,0.0016395328581793045
138.70000000000127,14.172672783259234,0.7083299477657368,0.002630908138207655
140.0000000000013,14.215057625900528,0.7106422543374477,0.0026299603011175066
141.30000000000132,14.256654911137282,0.7162568738587214,0.0026185756344556665
142.60000000000133,14.29839528653095,0.7200850646902721,0.0013131662348082607
143.90000000000134,14.340573095834433,0.7246444572779601,0.0011874830384548396
145.20000000000135,14.38207384117514,0.7297150220824484,0.0003257267519214402
146.5000000000014,14.423874666340664,0.7384145797962917,0.0008103737386204735
147.8000000000014,14.465448852322393,0.7435911414257506,-0.0010527586597075533
149.10000000000142,14.506994997214258,0.7507911009466582,-0.0012909672159935326
150.40000000000146,14.548702729553165,0.7607285525716456,0.00010003287890825163
151.70000000000147,14.589876998252548,0.770823538016534,0.0008204933255342439
153.00000000000148,14.631439993067135,0.7837789098206888,0.0014190034691763387
154.3000000000015,14.672969191844873,0.798433187040287,0.001419870559133507
155.6000000000015,14.71405655234884,0.8143177757330622,0.001419875972749729
156.90000000000154,14.75535277196164,0.8321370205405035,0.0014198735996351353
158.20000000000155,14.796645483311433,0.8506932916971748,0.001418771806593444
159.50000000000156,14.83751595352069,0.8716277261264731,1.2409713452399274e-05
160.8000000000016,14.878752317902814,0.8924955838739324,0.0004420987402085075
162.10000000000161,14.92012583211716,0.9092473538093802,0.00044015508058947717
163.40000000000163,14.960734287268329,0.9203482110521103,0.0004533012167664552
164.70000000000164,15.002166755804366,0.9219081259076249,-0.0008656943445739529
166.00000000000165,15.0437326964883,0.9144393000978911,-0.0022873420092199837
167.3000000000017,15.084304184410701,0.9026790942378263,-0.0015954018475845544
168.6000000000017,15.125143286766216,0.8819585472972201,-0.0028562031058187998
169.9000000000017,15.166013898225069,0.8633414967986638,-0.004230638152414645
171.20000000000175,15.20704243782697,0.8452437702133153,-0.00368598901814865
172.50000000000176,15.247702233506907,0.827175338173736,-0.003429219042477172
173.80000000000177,15.288722376192341,0.8126422936440196,-0.004098851285834648
175.10000000000178,15.329169687327797,0.8027549120901643,-0.00547877656861484
176.4000000000018,15.369859127861574,0.7952279635184597,-0.0041776219649798385
177.70000000000184,15.410165932686898,0.7899535422590096,-0.00417016944855364
179.00000000000185,15.450835294100802,0.7858827076530791,-0.0041680722200134745
180.30000000000186,15.491194924921084,0.7823891356636222,-0.0054558822627877035
181.6000000000019,15.531863677580366,0.783114235813306,-0.006835485919983508
182.9000000000019,15.571954422698656,0.7816259028929802,-0.00811973008640443
184.20000000000192,15.612337680772912,0.7843010091455289,-0.008125932805642666
185.50000000000193,15.652688470800214,0.7839155991544526,-0.0067399080548473655
186.80000000000194,15.693132824925382,0.7865567455161702,-0.005333195925830925
188.10000000000198,15.733280874887331,0.7899317478215088,-0.004631061705030248
189.400000000002,15.773386155175372,0.7904196976677205,-0.004061895320848663
190.700000000002,15.813293629478505,0.7951926805793185,-0.004060121719986043
192.00000000000205,15.853426778694647,0.7987133006491904,-0.004063971265067412
193.30000000000206,15.89349653185616,0.8041447970280219,-0.00277500463402669
194.60000000000207,15.933263235509589,0.8075477874452366,-0.0027424316191679843
195.90000000000208,15.972920626498333,0.8113562911964118,-0.0039703542221558585
197.2000000000021,16.0128604563539,0.8189044591836473,-0.005355110447005096
198.50000000000213,16.0528391334574,0.8231286048844171,-0.004049507697772015
199.80000000000214,16.09275110838446,0.8311182125431141,-0.005386616509832631
201.10000000000215,16.132954903835532,0.8377633082265278,-0.00532997798496071
202.4000000000022,16.17259609731544,0.8478053532798517,-0.006609053235224316
203.7000000000022,16.212634917209517,0.8540212629615462,-0.008007703094809138
205.00000000000222,16.252564283371466,0.8634809056842523,-0.008013006524643984
206.30000000000223,16.29201793694747,0.8735680385923427,-0.008840842597213516
207.60000000000224,16.332394581707664,0.8881790233879127,-0.010645724937718537
208.90000000000228,16.371862362669628,0.9069790513373691,-0.009488720398719952
210.2000000000023,16.4119592370513,0.9309998076076249,-0.009422023528401713
211.5000000000023,16.451268327984508,0.9690327959526273,-0.008005470734624431
212.80000000000234,16.49125846970199,1.0272197185676877,-0.009253199378423727
214.10000000000235,16.530648308441883,1.1046570004919545,-0.009329577496572927
215.40000000000236,16.57069618075403,1.2087256140897036,-0.009311534676155198
216.70000000000238,16.61010703012022,1.328440472340631,-0.008001575635414149
218.0000000000024,16.649993419969803,1.4617631120607515,-0.008083800931239171
219.30000000000243,16.689629967819574,1.5774455416401518,-0.007022384942930948
220.60000000000244,16.729446674675863,1.645868564374596,-0.0070297902100668885
221.90000000000245,16.76920052113667,1.6481744833931053,-0.007029825418936486
223.2000000000025,16.80904711740787,1.5846629182541254,-0.0070316391571743075
224.5000000000025,16.8489888266228,1.493687755615233,-0.008340430070048921
225.8000000000025,16.88861518456482,1.3912345535097588,-0.008340195861276545
227.10000000000252,16.928090153960763,1.2981574410237442,-0.008340192041066175
228.40000000000254,16.96767289300104,1.2115029991986197,-0.008340192002215918
229.70000000000258,17.006944345161195,1.1361106353132746,-0.008340192493097032
231.0000000000026,17.046136021482344,1.077244450417103,-0.008340307067601138
232.3000000000026,17.08572536317694,1.026334468981695,-0.008456142931443367
233.60000000000264,17.12492295503999,0.9876818861530338,-0.009410311408774685
234.90000000000265,17.16458084218755,0.958540911258852,-0.008152720202675656
236.20000000000266,17.20380485417257,0.934694906102804,-0.0077131712323388335
237.50000000000267,17.242803471689147,0.919774368689446,-0.007351392853940375
238.80000000000268,17.282522844803314,0.9060012114222197,-0.0073780430812546705
240.10000000000272,17.32153455146492,0.8944649672022948,-0.008670957422164172
241.40000000000273,17.360915411202924,0.8871359128008802,-0.009786434336782612
242.70000000000275,17.399950729311936,0.8832589081924427,-0.010000524604602212
244.00000000000279,17.43917000000009,0.8798880235032016,-0.011341598042370116
245.3000000000028,17.47888765155148,0.8777864201975563,-0.01130048949785012
246.6000000000028,17.518099616626728,0.8724447625194798,-0.011314072488519678
247.90000000000282,17.55761885841239,0.8725756170461683,-0.009782384702428981
249.20000000000283,17.596724886072572,0.8700625891909917,-0.00845320894708701
250.50000000000287,17.635861179125154,0.871776381667754,-0.008447524579527244
251.80000000000288,17.675216127755817,0.8715037247925423,-0.00976498257625158
253.1000000000029,17.714401838836334,0.8732037018868941,-0.009653528272499656
254.40000000000293,17.753522356194626,0.8752865844095583,-0.012848635894464167
255.70000000000294,17.792775204199177,0.8730224665156019,-0.015027336398825142
257.00000000000296,17.8321502918622,0.8734086778334988,-0.015983109466143564
258.30000000000297,17.871294528410573,0.8745726311646851,-0.01603271992498234
259.600000000003,17.910589830384122,0.8760136486766426,-0.015913354131747326
260.90000000000305,17.949881720665427,0.8784546878844723,-0.016236366467451635
262.200000000003,17.989482649682724,0.8753604720449188,-0.016240019256776872
263.50000000000307,18.028479291406118,0.8782055639084858,-0.016240773617526294
264.8000000000031,18.067496204222593,0.8791979591550059,-0.017625111571248464
266.1000000000031,18.106828414537485,0.8794938013832114,-0.016571640537683674
267.4000000000031,18.14627984873854,0.8815773924066945,-0.016094570732293256
268.7000000000031,18.18535486741005,0.8821458352259532,-0.014702791026319328
270.0000000000031,18.224772633685134,0.881637708778829,-0.013390454266314133
271.30000000000314,18.26371877529686,0.8814012132122455,-0.013380162734258239
272.6000000000032,18.30304952264878,0.8794656745037677,-0.013379997933669063
273.90000000000316,18.34246368138097,0.8822162104194671,-0.013379978773343737
275.20000000000323,18.381691472033285,0.8817217655608862,-0.013495738096116483
276.50000000000324,18.420802030009053,0.8813206964657057,-0.01528865624707132
277.80000000000325,18.460219840405557,0.8821523511891081,-0.016234727572832508
279.10000000000326,18.499354550864954,0.883527940822594,-0.01655934532295289
280.4000000000033,18.538145602867775,0.8846495879481395,-0.017844391419225225
281.70000000000334,18.57739894794725,0.8867162944867635,-0.018388081020338287
283.0000000000033,18.617374786655855,0.8850897432802347,-0.019201508098229958
284.30000000000337,18.65683495770498,0.8834863086791511,-0.019200006275578385
285.6000000000034,18.696178754768503,0.884573325803903,-0.019199999114173583
286.9000000000034,18.7357072738603,0.8846831327170279,-0.01920062523332966
288.2000000000034,18.77476049050653,0.8860342026618544,-0.019382634366927665
289.5000000000034,18.81420138382122,0.8875222338718263,-0.0194636515680382
290.8000000000034,18.853472486018607,0.8865801451774207,-0.020506328142849473
292.10000000000343,18.892734140160584,0.8862035569915148,-0.021934610566756163
293.4000000000035,18.9321239852623,0.8871412738252538,-0.02325458780521439
294.70000000000346,18.971326094064835,0.8888314087008782,-0.023256863690465757
296.0000000000035,19.010777706030858,0.890081990447281,-0.02456261284770811
297.30000000000354,19.050389370265872,0.8912467984990078,-0.02466334861291175
298.60000000000355,19.08976054010343,0.8933520833510129,-0.025890357673620024
299.90000000000356,19.128986462067402,0.8938460729204976,-0.025897106992246233
301.20000000000357,19.16842413011284,0.8940866070544617,-0.024595174618164517
302.50000000000364,19.208037088494887,0.8936266555717882,-0.023081102602097392
303.8000000000036,19.24721994066491,0.8932746521292791,-0.020772014905080294
305.10000000000366,19.286517360210183,0.8940293294534318,-0.01973898974263033
306.4000000000037,19.32651081430774,0.8942850919459853,-0.019739985399854554
307.7000000000037,19.36543014414788,0.895788431455675,-0.019702819568342633
309.0000000000037,19.40541548107573,0.895583001205202,-0.021743205883109518
310.3000000000037,19.444607332951445,0.8992906410045138,-0.023630181398996086
311.6000000000037,19.484155846415508,0.9005595769997163,-0.025119069814171446
312.90000000000373,19.523708865591427,0.8990259805010821,-0.025199545888147323
314.2000000000038,19.563245101124465,0.9022348981124817,-0.027061998034219048
315.5000000000038,19.60264276451911,0.902583999004049,-0.027417154183418724
316.8000000000038,19.64226059182436,0.9014921272231322,-0.027786796772637956
318.10000000000383,19.68178807452456,0.9037023712943026,-0.02907268519090289
319.40000000000384,19.721479999166107,0.9093450007714119,-0.030481757906374085
320.70000000000385,19.76046133655848,0.9095203029796144,-0.030391496546751107
322.00000000000387,19.80022890517083,0.9130124203578787,-0.03141265774771762
323.3000000000039,19.840002839632877,0.9149940097986891,-0.031706261389929935
324.6000000000039,19.87943893471983,0.9169259417898088,-0.03173648236636728
325.90000000000396,19.91917031418124,0.9210051367719505,-0.03435029424842728
327.20000000000397,19.95878706923316,0.9225186981452296,-0.03528669574628163
328.500000000004,19.998549665726014,0.9249365573298451,-0.03564872587846413
329.800000000004,20.037867006691762,0.9274889753901674,-0.037015068890518865
331.100000000004,20.07760000643311,0.931976582778776,-0.039015483317403454
332.400000000004,20.117594798786204,0.9358124988006165,-0.042274017655922425
333.700000000004,20.157261371193503,0.9409793738367247,-0.04430046686508238
335.0000000000041,20.196674487971872,0.9444109095948603,-0.04309382984516974
336.3000000000041,20.23651274115861,0.9478613150307262,-0.041459555143938065
337.6000000000041,20.276156653943197,0.9520398941489305,-0.04016714846139324
338.9000000000041,20.31599909363073,0.9559241008990456,-0.04125410864699752
340.20000000000414,20.355452709443448,0.9643469150093227,-0.0425946624274216
341.50000000000415,20.3955281601947,0.9707937034738605,-0.04372637721126571
342.80000000000416,20.435435497376027,0.9784560349163454,-0.04584676316479763
344.1000000000042,20.475216414218185,0.9830636285883296,-0.04819291436418682
345.4000000000042,20.51495731829775,0.9918715735991948,-0.05003747647459367
346.70000000000425,20.55511919259427,0.9990685643170469,-0.05453778404374843
348.00000000000426,20.59456842454459,1.0042342465959468,-0.05712014622466155
349.3000000000043,20.634755305106385,1.0184218984510516,-0.06009421638814105
350.6000000000043,20.67433467312289,1.0258479342191642,-0.061199682446607895
351.9000000000043,20.714366706533408,1.0374431965734559,-0.06472682163821775
353.2000000000043,20.754237521014414,1.0463457613561802,-0.06813093183692098
354.5000000000043,20.79386759808361,1.0570781643423437,-0.0697990435453879
355.8000000000044,20.83425725956826,1.069953597406432,-0.0736642065676083
357.1000000000044,20.874311063794682,1.084315895391535,-0.07806005660313975
358.4000000000044,20.91455519833088,1.0992824920234463,-0.08263414769382882
359.7000000000044,20.954426307595767,1.116414081230674,-0.08617735714538188
361.00000000000443,20.994518651491518,1.1314923030565363,-0.08989980787232943
362.30000000000445,21.034350026726276,1.1477945056939411,-0.09697105964528774
363.60000000000446,21.07442153966407,1.16602174443409,-0.10199983527771384
364.90000000000447,21.114358779897394,1.1886370641450141,-0.10816179881364762
366.2000000000045,21.15451199691917,1.205464463972839,-0.11336669730346527
367.50000000000455,21.19486139200956,1.2248412117010912,-0.12051509354222079
368.80000000000456,21.234920402321354,1.248503116366159,-0.12791511537293276
370.10000000000457,21.275169049554098,1.2716472455490357,-0.13592479089464016
371.4000000000046,21.31505945879891,1.296980924513327,-0.14165010068111128
372.7000000000046,21.35550024609811,1.3231515328570764,-0.15074884315282588
374.0000000000046,21.395550568972507,1.3456173444287463,-0.15959758387462042
375.3000000000046,21.435827005470305,1.370186303724817,-0.16794119836519084
376.6000000000047,21.476234069060077,1.399555274503424,-0.17625872845540735
377.9000000000047,21.51650947622637,1.4268744896326424,-0.18577063299456542
379.2000000000047,21.555721507650397,1.4512579812904727,-0.19674685270643133
380.5000000000047,21.596828209357177,1.483941439070892,-0.20725990268923988
381.80000000000473,21.636867225567457,1.5125010271031574,-0.218231847878684
383.10000000000474,21.677392006783876,1.5427660782962713,-0.23146563189555325
384.40000000000475,21.71773364212207,1.5729437777843323,-0.24220195363490227
385.70000000000476,21.758333488697613,1.6031060835565163,-0.2551165678742091
387.0000000000048,21.79874258702377,1.6386698132475024,-0.2687185531628975
388.30000000000484,21.839233181067236,1.6721031546039036,-0.2826790486654285
389.60000000000485,21.879569893072468,1.7033422001982228,-0.29815884983525676
390.90000000000487,21.919841546227854,1.7393139185138053,-0.3141120148569061
392.2000000000049,21.96047696444354,1.7741032460089523,-0.328159040313464
393.5000000000049,22.000624375378916,1.8086939395622945,-0.3448201541338838
394.8000000000049,22.041551813215722,1.8484853922297428,-0.3623447121688099
396.1000000000049,22.081904343390057,1.8854752675497384,-0.3818079924292759
397.400000000005,22.12253899987746,1.9214874932705839,-0.4015234109532866
398.700000000005,22.163037772241786,1.9621944880481197,-0.42046176569596705
400.000000000005,22.203528567080923,2.0042227606795975,-0.4407952359602949
401.300000000005,22.2441307380705,2.0443732727779516,-0.4625019810292761
402.600000000005,22.28453237679591,2.0863197153646773,-0.48414255293338293
403.90000000000504,22.325520264032914,2.128023568984295,-0.507111335649292
405.20000000000505,22.3660358428877,2.1719042054504945,-0.5302191797948832
406.50000000000506,22.406307795769006,2.2157709638108845,-0.554572483595396
407.80000000000507,22.447434182130937,2.261886919177025,-0.5817092236025942
409.10000000000514,22.487946798268926,2.302339247695511,-0.6103530098328793
410.40000000000515,22.528608882573316,2.3439728218207785,-0.6368106938034721
411.70000000000516,22.569551842159,2.3893475664773343,-0.665439515679993
413.0000000000052,22.610035776165017,2.4282580980225,-0.6970320871571718
414.3000000000052,22.651114214430372,2.462283280846186,-0.7290280990837239
415.6000000000052,22.691857180407194,2.494190439301474,-0.7600061341536519
416.9000000000052,22.732352027270867,2.52076583214805,-0.7948828746721883
418.2000000000053,22.772997197632467,2.5480609181291323,-0.8298432635257775
419.5000000000053,22.814118298977338,2.561566511076771,-0.8655355385881087
420.8000000000053,22.854860326358622,2.570844251171189,-0.9011551281017924
422.1000000000053,22.895464081973874,2.5715587471244827,-0.9370610454441066
423.4000000000053,22.9361082826378,2.5593222113598646,-0.9739999753441992
424.70000000000533,22.977028585358187,2.531956224724178,-1.0122314292761851
426.00000000000534,23.018057716509503,2.4913553329305693,-1.04987326871165
427.30000000000535,23.058567461107184,2.4380927416045637,-1.086344256292676
428.60000000000537,23.099663841850763,2.3641563895392332,-1.1230239358558611
429.90000000000543,23.14030340177299,2.27483324829489,-1.1554911861374588
431.20000000000545,23.1809388330441,2.171304381161255,-1.1898845529707032
432.50000000000546,23.22183440364907,2.0540711205200424,-1.2245844141738305
433.80000000000547,23.262382529316014,1.9313850553554541,-1.2549335183159878
435.1000000000055,23.303083644199262,1.8045935633814816,-1.2845607163593358
436.4000000000055,23.343753786849277,1.6805411204070013,-1.309251931739936
437.7000000000055,23.384427308546588,1.5589024499237616,-1.331725000341931
439.00000000000557,23.425030987593594,1.4464258815208808,-1.3534223270432513
440.3000000000056,23.465760854338246,1.3480668431246516,-1.3714307567343083
441.6000000000056,23.506372199530816,1.2592432708553094,-1.3889422061634251
442.9000000000056,23.546993563974766,1.1858417234326895,-1.4059006826957843
444.2000000000056,23.587839780938502,1.1215895443956871,-1.421305814752623
445.5000000000056,23.62824798473806,1.069372839381817,-1.4367762642827806
446.80000000000564,23.669582979793105,1.0243358674417111,-1.4522852001883573
448.10000000000565,23.710549691049472,0.9912256028475948,-1.4662815092287604
449.40000000000566,23.75086704505222,0.9601056852989869,-1.4774800084527056
450.70000000000573,23.791800125493914,0.9366111384109936,-1.488923416925311
452.00000000000574,23.832876582734393,0.9124088649516968,-1.5000542039039129
453.30000000000575,23.87353366007611,0.8990159779249447,-1.5114839494656227
454.60000000000576,23.91451724890228,0.8845517545503787,-1.522599674998962
455.9000000000058,23.955164502835746,0.8727183840637245,-1.5327977089224034
457.2000000000058,23.996452429398328,0.8632852143180338,-1.5462582766897146
458.5000000000058,24.03729215327732,0.8566426366044471,-1.558166568492164
459.80000000000587,24.07824463886544,0.8501547387823427,-1.5702616771520508
461.1000000000059,24.119138816208782,0.8429343118590549,-1.5823423193974686
462.4000000000059,24.160398465501686,0.8353898532328625,-1.5929203993583734
463.7000000000059,24.201481136904885,0.8343332255886748,-1.605135355257549
465.0000000000059,24.24253118097813,0.828772671074949,-1.6149368247669145
466.3000000000059,24.283857676196106,0.8273007482998935,-1.6248743777963672
467.60000000000593,24.324942892679083,0.8233017672718266,-1.6342167404727475
468.90000000000595,24.36640298298251,0.8218986321957191,-1.6455862354254425
470.20000000000596,24.407300962644083,0.8183789782659532,-1.6578920862722577
471.500000000006,24.448349841479523,0.8171399591832449,-1.6715526355246078
472.80000000000604,24.48951811331347,0.8135758636839585,-1.6821302435890346
474.10000000000605,24.53089364715354,0.8088047603101352,-1.69338562906476
475.40000000000606,24.572295613778238,0.8075352889386795,-1.7055401857738546
476.70000000000607,24.613565990195646,0.8019458735672138,-1.7181081204523903
478.0000000000061,24.654865714704712,0.7974262634609344,-1.730398553914216
479.3000000000061,24.69612954807091,0.7873155847379294,-1.7411094065098314
480.60000000000616,24.737524059941077,0.7825088185888753,-1.7496181409730247
481.9000000000062,24.77888542711175,0.7741101373684403,-1.761678321325233
483.2000000000062,24.820318375236074,0.7671867243650898,-1.7723344359533342
484.5000000000062,24.861795822666487,0.7602485048407515,-1.7857836229203325
485.8000000000062,24.90325131406742,0.7465184836583778,-1.7991787561351553
487.1000000000062,24.944592288980573,0.7381957176244955,-1.8106113916061704
488.40000000000623,24.98615624770993,0.7244346461552182,-1.822543581488984
489.70000000000624,25.027666249288643,0.7082456425055508,-1.8341561636546606
491.00000000000625,25.068876942177475,0.6905075880788802,-1.8456786210834126
492.3000000000063,25.110288536180004,0.6650720766451668,-1.8569616501617099
493.60000000000633,25.151941363197132,0.6405120592884126,-1.8685137936382574
494.90000000000634,25.193188743449465,0.6086051404868384,-1.8791082263949792
496.20000000000636,25.23465434742227,0.5695907746716324,-1.8890285216687013
497.50000000000637,25.276114579720222,0.529472942105484,-1.8984366539725932
498.8000000000064,25.31761138998866,0.48473140916266977,-1.9061999228335846
500.1000000000064,25.358875760337458,0.4403997276373848,-1.913110996570487
501.40000000000646,25.400660617069487,0.3906753627930337,-1.9193495690234261
502.70000000000647,25.442478029288,0.35031666978645415,-1.9256526496005626
504.0000000000065,25.484050770018648,0.30920686135742326,-1.9283339934088546
505.3000000000065,25.525347852114155,0.27428606432818325,-1.9319168268930147
506.6000000000065,25.566983422796774,0.24458571356248382,-1.9336763936382142
507.9000000000065,25.60865390584499,0.22021492111777552,-1.9351965905092352
509.2000000000065,25.650269564736586,0.1984944898979475,-1.936535095908047
510.50000000000654,25.692090476204832,0.18328533559137616,-1.936511434279522
511.80000000000655,25.733730319467977,0.1680304970048161,-1.9369248403137367
513.1000000000066,25.775311496448467,0.15800006020201884,-1.939194100994965
514.4000000000067,25.81719803584137,0.14820610493233133,-1.9391172095300369
515.7000000000066,25.858941690387187,0.1400590473371417,-1.937813008259428
517.0000000000066,25.900868111577775,0.13407672719082098,-1.937637145736411
518.3000000000067,25.942783859328614,0.12762062645437533,-1.9361120441126625
519.6000000000067,25.984526878260596,0.12336372800543205,-1.9373957214120447
520.9000000000067,26.026471947318672,0.11935604241840503,-1.9373894542417402
522.2000000000068,26.068309984246408,0.11606530757278266,-1.9372971487731259
523.5000000000068,26.110102935695792,0.10844212278105525,-1.9386988361423887
524.8000000000068,26.15192395264137,0.10514617673556059,-1.9386998280390872
526.1000000000067,26.19363202588219,0.1020586213219905,-1.9391578658231516
527.4000000000068,26.23578263178266,0.09730491737070501,-1.9402733438136432
528.7000000000069,26.277663060917753,0.09074282256150368,-1.9419777452544786
530.0000000000068,26.319529672437344,0.08608482848781662,-1.942760345808916
531.3000000000068,26.361620462849494,0.08278614098430692,-1.9415278281477417
532.6000000000068,26.403050077682707,0.0861737703791654,-1.9414501450499664
533.9000000000069,26.445069932605037,0.0950659441482169,-1.941014611348506
535.2000000000069,26.486857967456416,0.10131212407289159,-1.940792218914
536.5000000000069,26.529170000000228,0.11755841404259892,-1.9417730278303797
537.800000000007,26.570758990667226,0.123851899429408,-1.9435246426070494
539.100000000007,26.61265778320731,0.13166149662646998,-1.9435399697808164
540.4000000000069,26.654792063853495,0.1316450317940423,-1.9435400824744664
541.700000000007,26.696692018294492,0.1356758354723988,-1.94358653133764
543.000000000007,26.73887801598376,0.13288916466139433,-1.9422294072972388
544.300000000007,26.78090135350313,0.13185356094539102,-1.942252898479245
545.6000000000071,26.823059886201165,0.12417636692286482,-1.9418658916758664
546.9000000000071,26.86506578228791,0.12402904118689762,-1.9422429812184188
548.2000000000071,26.907045387845354,0.12027091171022652,-1.9412341252935965
549.500000000007,26.94907237022194,0.11678220975854803,-1.9412264815967832
550.8000000000071,26.991240830974842,0.11777396560179598,-1.942601155775467
552.1000000000072,27.033656342030387,0.11736784706108905,-1.9440736456918724
553.4000000000071,27.07589835406221,0.11533015853957362,-1.9447005922226346
554.7000000000072,27.11793548751472,0.11382777801334232,-1.9447063555076953
556.0000000000073,27.160370470530175,0.11347185211702904,-1.9434110576861108
557.3000000000072,27.202211408566207,0.11071626839168269,-1.9434084196789403
558.6000000000072,27.244398326449716,0.11199332037941012,-1.9434472534572325
559.9000000000073,27.28663024205192,0.10866769100347184,-1.9443904027204542
561.2000000000073,27.329267475145823,0.10634532480725989,-1.9457090671481727
562.5000000000073,27.371141951069976,0.10431595823297357,-1.9457286035645307
563.8000000000073,27.41353026528423,0.10016814152640308,-1.9446768998134512
565.1000000000073,27.455676528140742,0.09850233730202085,-1.9447417663429496
566.4000000000074,27.498155368363552,0.09574789331298161,-1.9457268061397297
567.7000000000073,27.539446792051553,0.08945568665372061,-1.9475135383583173
569.0000000000074,27.582268337871934,0.08864992766907065,-1.9490857770985723
570.3000000000075,27.624884317518834,0.08722042982895539,-1.95042982134713
571.6000000000074,27.667348103238385,0.0883217082136607,-1.9510020441725828
572.9000000000075,27.709826313359205,0.08336768953336371,-1.9511550157198472
574.2000000000074,27.752174251195758,0.07598553960448173,-1.9497847569214577
575.5000000000075,27.79438229356234,0.07034940685771263,-1.948476297952861
576.8000000000075,27.836876220784923,0.06542499898336152,-1.9473278810772339
578.1000000000075,27.879233251286422,0.056958572995409185,-1.947149993575707
579.4000000000076,27.92153957592929,0.053130220766922864,-1.9465881995801078
580.7000000000075,27.963542893874052,0.04746313483718234,-1.9458322058111133
582.0000000000076,28.006672547891508,0.04350982851233143,-1.9458486813697724
583.3000000000076,28.04823399925683,0.04279668035705564,-1.9471557671142188
584.6000000000076,28.091687531459762,0.03787013000105066,-1.9471501508054287
585.9000000000076,28.13426107892022,0.034696794384824425,-1.947150140610721
587.2000000000077,28.1766063770344,0.03214201743077982,-1.9471502573922455
588.5000000000076,28.219039939951344,0.03313490466468183,-1.9474691594733176
589.8000000000077,28.26194619309095,0.03410386498264817,-1.9493827610635721
591.1000000000078,28.30433583750804,0.02968357308265812,-1.9516149167253412
592.4000000000077,28.346882959579542,0.03155044326611822,-1.9530820908380635
593.7000000000078,28.389591451547446,0.035548230957374916,-1.9527414092579658
595.0000000000077,28.432569976375834,0.033787546923164324,-1.9512697787962794
596.3000000000078,28.47504296477929,0.03721222318969941,-1.9493336846724647
597.6000000000078,28.51765405742207,0.04282796208877704,-1.9485800084051461
598.9000000000078,28.560292560502642,0.04309041650012935,-1.9485410203767213
600.2000000000078,28.60304227160951,0.046097908874381144,-1.9472563883677014
601.5000000000078,28.645302627232336,0.05282768962741491,-1.9473693281724733
602.8000000000079,28.687958745196994,0.057907834155371596,-1.9472914015538496
604.1000000000079,28.731023594120966,0.0652673321845314,-1.9490835176998225
605.4000000000079,28.773591925644915,0.0702388376870351,-1.9498048510685875
606.7000000000079,28.81602877245373,0.07609348715612807,-1.95115432755397
608.000000000008,28.85907243509815,0.08238188974737781,-1.9525282238680042
609.3000000000079,28.901477427436284,0.09088588475268189,-1.953883815493402
610.600000000008,28.944296460645763,0.0964227861328153,-1.9543174386245763
611.900000000008,28.98712731095774,0.1040227389334758,-1.955162329879228
613.200000000008,29.02984497950064,0.11010016337254402,-1.9540376278834044
614.5000000000081,29.07270429553536,0.11828265372314029,-1.9552160324506027
615.800000000008,29.11545201827942,0.12375904196954224,-1.9538373590955636
617.1000000000081,29.158267485241936,0.1289090820998542,-1.9550781623320246
618.400000000008,29.20111272628552,0.1373869815018689,-1.9577264579017792
619.7000000000081,29.243896351296225,0.14509871446663558,-1.9577923206557757
621.0000000000082,29.286529621766405,0.15461323807423932,-1.95648361450424
622.3000000000081,29.328429227093352,0.16289425743758068,-1.9564699434558572
623.6000000000082,29.37206555719715,0.17003800870145236,-1.9562408237176627
624.9000000000082,29.41462058274922,0.17533486819301025,-1.9557920136500737
626.2000000000082,29.458118598238386,0.18465426702534105,-1.9564847983665143
627.5000000000082,29.500756327824845,0.19309478560978954,-1.9564534025595757
628.8000000000083,29.5436876451865,0.20310223734808153,-1.957784854360709
630.1000000000082,29.586743158892897,0.20889088573947934,-1.9581200297326218
631.4000000000083,29.629732165936552,0.2202739654452177,-1.958508348109187
632.7000000000083,29.672621356814837,0.2286218184392217,-1.961254198265583
634.0000000000083,29.715546681329844,0.23836579618011555,-1.9625807706432439
635.3000000000084,29.75857035820234,0.248276566325782,-1.963270823894522
636.6000000000083,29.801298805911795,0.25900543265937204,-1.9621122253476229
637.9000000000084,29.844434126807574,0.265411359373787,-1.9619465089878756
639.2000000000083,29.887125392002776,0.27747590152794643,-1.963186099462822
640.5000000000084,29.93035948134647,0.2871183603063976,-1.9633483212860297
641.8000000000084,29.97292503935399,0.29781657415294926,-1.9645852720272157
643.1000000000084,30.016198722106093,0.31187669430471265,-1.9658740540897928
644.4000000000085,30.05913763804771,0.3241086764275569,-1.9658998593233252
645.7000000000085,30.10211492144069,0.3368304178356878,-1.9658976608284509
647.0000000000085,30.14508992545154,0.3483642740913355,-1.9670158981525039
648.3000000000085,30.187794447152267,0.36298003616561747,-1.9672157614746668
649.6000000000085,30.231201111077567,0.37825973154844794,-1.9686409036543298
650.9000000000085,30.27364287521833,0.3967751308216725,-1.9701510384079701
652.2000000000086,30.31673050421229,0.4160456742010785,-1.9714888883095827
653.5000000000086,30.359496541969623,0.43484993704996056,-1.9721772866128349
654.8000000000086,30.402523851660316,0.45728038501127655,-1.9728096357384797
656.1000000000087,30.44524325787493,0.48194169572923107,-1.976049845455535
657.4000000000086,30.488232537121522,0.5072430588477372,-1.980409357694847
658.7000000000087,30.531188917252578,0.5346500245476773,-1.983955534305394
660.0000000000086,30.574127861039607,0.5615931655738877,-1.9845868495078065
661.3000000000087,30.616960811881317,0.5914513558999066,-1.9855587325291122
662.6000000000088,30.660261508772518,0.6205205889280241,-1.9869473962623747
663.9000000000087,30.70283205871527,0.6501831573563885,-1.9876323670180616
665.2000000000088,30.74590219542567,0.6803158706972137,-1.9872768046878462
666.5000000000088,30.78880895965264,0.7151033602974914,-1.9873062089853075
667.8000000000088,30.831883183948417,0.7479104112297414,-1.989768184581536
669.1000000000088,30.874772588401694,0.7792659630013952,-1.9916376837920569
670.4000000000088,30.917725323105277,0.811779826051485,-1.993465847318905
671.7000000000088,30.960702891953165,0.8529775558119712,-1.9946621992906102
673.0000000000089,31.003529532302526,0.890128741830317,-1.9976419740953568
674.3000000000089,31.046509741766478,0.9300083890675004,-1.9993959882822767
675.6000000000089,31.08946771366201,0.9715029298993136,-2.002223855879281
676.900000000009,31.132484503043734,1.0119168713361706,-2.006915213502397
678.2000000000089,31.175633452471413,1.0513494083010806,-2.0093528690873472
679.500000000009,31.218703540614502,1.0914275201751407,-2.0134672812822165
680.8000000000089,31.26173925663976,1.1307813646311766,-2.0168773294985507
682.100000000009,31.304548773287706,1.175069045645265,-2.0189501070754248
683.400000000009,31.347757240457334,1.2135054615873524,-2.021189395619391
684.700000000009,31.39129017338241,1.2597603378598885,-2.0226730189409494
686.0000000000091,31.434090247479443,1.3050763031263957,-2.02592379591134
687.300000000009,31.47728336433648,1.3543852756976942,-2.0297273155083864
688.6000000000091,31.520685147006954,1.4051637148444591,-2.0339310270242885
689.9000000000091,31.563444036936197,1.4496045978441288,-2.037074650630119
691.2000000000091,31.606490225301528,1.5043759731369373,-2.040158117199148
692.5000000000091,31.64953797705464,1.5612986790292744,-2.0435761332273916
693.8000000000092,31.693158638284423,1.6199915152141369,-2.0473284489495436
695.1000000000092,31.73611981070825,1.6774943554930748,-2.052133426572347
696.4000000000092,31.779370325661382,1.7405522245628728,-2.055315000220663
697.7000000000093,31.822529462508225,1.804561588812414,-2.0587897182706785
699.0000000000092,31.865476082258258,1.8711661466984664,-2.0642589226594685
700.3000000000093,31.909203503961535,1.9419844274362026,-2.068803068316881
701.6000000000092,31.95221097981587,2.0120169185231465,-2.073472699204581
702.9000000000093,31.995516098140854,2.0868018454945916,-2.0794347852817987
704.2000000000094,32.038638880366435,2.166671932163309,-2.085795949582651
705.5000000000093,32.081884032761934,2.2474712068129,-2.093047953142653
706.8000000000094,32.12528192722052,2.33616994053691,-2.0999763553567234
708.1000000000093,32.16850689193055,2.4215220120419,-2.1051461254658967
709.4000000000094,32.21186069142499,2.516711313259039,-2.1096885636474956
710.7000000000094,32.25533121904709,2.6100314297966003,-2.1164059158124413
712.0000000000094,32.29876953646276,2.7091023749224923,-2.1247545370698475
713.3000000000094,32.34170033158681,2.817949892755356,-2.1331147954184466
714.6000000000095,32.3854143784187,2.927776600865153,-2.1438202679009732
715.9000000000095,32.42882841153521,3.040089921969168,-2.1513428307275224
717.2000000000095,32.47203271335555,3.1523361832476566,-2.156372814938482
718.5000000000095,32.51569644769641,3.2691468622372946,-2.1602815207025055
719.8000000000095,32.55926717406765,3.3960665769006146,-2.1687416007957516
721.1000000000096,32.602642310933746,3.5138529722359837,-2.1770425185298747
722.4000000000095,32.64525553108699,3.637054106687611,-2.190752912068227
723.7000000000096,32.68964138109556,3.7627537688231687,-2.206348999604196
725.0000000000095,32.733320655822844,3.8796970900540853,-2.2178620804380964
726.3000000000096,32.7765967450923,3.9984584094312416,-2.2316291571563966
727.6000000000097,32.82032219643654,4.1172352009389055,-2.2437440274686757
728.9000000000096,32.86375420888915,4.2301727575387105,-2.2550406072228126
730.2000000000097,32.90723735133952,4.3401506802583665,-2.2677433470041137
731.5000000000097,32.951022527610114,4.449461602388556,-2.2791071676691206
732.8000000000097,32.994650565941534,4.55886519806143,-2.288996851239507
734.1000000000097,33.03797245656572,4.66187310567477,-2.301199788007925
735.4000000000098,33.08173981579627,4.769106526702117,-2.3127920786943097
736.7000000000098,33.12519231557305,4.871281791008677,-2.3262457259840206
738.0000000000098,33.16893546728843,4.976842675798364,-2.3386473313868676
739.3000000000098,33.21233438572635,5.075776922214517,-2.3523870852310305
740.6000000000098,33.25587427375468,5.17374188999892,-2.363830455218644
741.9000000000099,33.299677031228164,5.268584544934024,-2.3759862783406582
743.2000000000098,33.34293962702873,5.365277946828637,-2.391663322182326
744.5000000000099,33.386627923640106,5.460876689356043,-2.408158363946799
745.80000000001,33.43037507526303,5.548044947964801,-2.4271469976834363
747.1000000000099,33.47368409209258,5.631285123278383,-2.4423402148850886
748.40000000001,33.51734744305045,5.704197307944414,-2.4558322091034586
749.7000000000099,33.560919142440795,5.77858815926095,-2.471557250059038
751.00000000001,33.604704901682865,5.843473627163091,-2.4892050931278886
752.30000000001,33.64801830645802,5.896476724063977,-2.5050147551221467
753.60000000001,33.691493157571976,5.945454206588751,-2.5195754640914205
754.90000000001,33.734859040658435,5.990289846780839,-2.5373431173842587
756.20000000001,33.778574482626034,6.014909032977933,-2.5546831468181708
757.5000000000101,33.82194788465057,6.029297091178712,-2.571365797076881
758.8000000000101,33.865610808778655,6.031192766372087,-2.590386678025935
760.1000000000101,33.90920402112299,6.014256004095269,-2.605819067386251
761.4000000000101,33.95285159037262,5.982626653245796,-2.620874176004813
762.7000000000102,33.99629650160301,5.924583893223177,-2.639798087092493
764.0000000000101,34.039583223903506,5.837344761452206,-2.6570700860525918
765.3000000000102,34.08332091147771,5.709744880088612,-2.67127871802141
766.6000000000101,34.12678782000767,5.538419169000609,-2.6864861398376627
767.9000000000102,34.170291915812186,5.298899072017547,-2.7024557675809575
769.2000000000103,34.213289316471304,4.9779363730832635,-2.7166138733435763
770.5000000000102,34.25678799131413,4.528896658769392,-2.730756414996663
771.8000000000103,34.29963182573672,3.8795481143322,-2.743176558900535
773.1000000000103,34.34300978954683,2.8302989895792092,-2.7552121599998403
774.4000000000103,34.38594921125639,1.5727585656900085,-2.7609604996114236
775.7000000000103,34.42872515751754,0.8327601424783855,-2.764955500924974
777.0000000000103,34.470758095340074,0.42282326155048056,-2.766280834985397
778.3000000000104,34.51435472592845,0.17199083635621948,-2.7662801279631193
779.6000000000104,34.55698190242003,0.0264390239013923,-2.7662801239274173
780.9000000000104,34.600726557816095,-0.07345186021469452,-2.766280134784437
782.2000000000104,34.64411239945933,-0.13519227818685042,-2.766289904840902
783.5000000000105,34.687627662342756,-0.16871252237883594,-2.766693491888452
784.8000000000104,34.73088036520385,-0.18854916694834056,-2.767698249621893
786.1000000000105,34.774361138896644,-0.20387270073329633,-2.7664137464826877
787.4000000000106,34.81770451029078,-0.20805586306006196,-2.7663596342040195
788.7000000000105,34.8614206095689,-0.21087067864058362,-2.7677646782177625
790.0000000000106,34.90440802570682,-0.21512709548550113,-2.76771987155912
791.3000000000105,34.94776018882724,-0.2116483229948254,-2.766948440568751
792.6000000000106,34.991960492011444,-0.2127836780110557,-2.7677116745650174
793.9000000000106,35.03523839033807,-0.21480953324233631,-2.7690629041770367
795.2000000000106,35.07873749294542,-0.21000508738327595,-2.7677228071219897
796.5000000000106,35.12231261693199,-0.20844170123589878,-2.766348786520759
797.8000000000106,35.16593586198678,-0.21457381380122387,-2.766399751251717
799.1000000000107,35.20949080131835,-0.20499726380195682,-2.7663911525283202
800.4000000000107,35.25316342888468,-0.20594290431915008,-2.7657858364598793
801.7000000000107,35.29664839620293,-0.2062934843305828,-2.7663987895749855
803.0000000000107,35.33998227816792,-0.19878202443482085,-2.766454052375771
804.3000000000108,35.38369434725489,-0.19540369512339018,-2.767710505388751
805.6000000000107,35.42739954754331,-0.1976805893049569,-2.767710148649534
806.9000000000108,35.47053491563422,-0.1920921873917516,-2.767710156373291
808.2000000000107,35.51438760867117,-0.1872292441670984,-2.7677114528809423
809.5000000000108,35.55796565482112,-0.18411337999788424,-2.7687997699449336
810.8000000000109,35.60140684564283,-0.1814304161414766,-2.7690297913826445
812.1000000000108,35.64520916324091,-0.1779237332604251,-2.7680245076437417
813.4000000000109,35.68894141123754,-0.17709353724919108,-2.769030483245958
814.7000000000108,35.732591046843176,-0.17565353981843268,-2.7678317242231167
816.0000000000109,35.77597064848049,-0.17501223403816502,-2.767705444374748
817.3000000000109,35.81981736892312,-0.17316827874366414,-2.7691439849248294
818.6000000000109,35.86345160523516,-0.1726574878746625,-2.769241063421093
819.900000000011,35.90692149572108,-0.16910957654320447,-2.7691397004623957
821.200000000011,35.95040490874705,-0.17037690633796787,-2.769133235153066
822.500000000011,35.99438299823506,-0.16874099897168682,-2.767998778115746
823.800000000011,36.038054799620646,-0.16696092507298754,-2.7670747486052827
825.100000000011,36.081825907110975,-0.16895676237479318,-2.769691211009095
826.400000000011,36.12528060848305,-0.1674810084779721,-2.770031829154257
827.7000000000111,36.169235952254944,-0.16828792019074568,-2.7715503236570065
829.0000000000111,36.2129214722459,-0.1664571507894177,-2.7704986168256314
830.3000000000111,36.25636127283775,-0.16635090542242903,-2.7702398741294525
831.6000000000112,36.30001136450197,-0.16718968352324426,-2.7702634138800075
832.9000000000111,36.34370500484955,-0.16898474558926013,-2.770746226120833
834.2000000000112,36.38721480049623,-0.17163178895763886,-2.7702310050248453
835.5000000000111,36.43108490804688,-0.17480791722486044,-2.77018923932745
836.8000000000112,36.47517457343942,-0.17219987278971516,-2.7717622284091394
838.1000000000112,36.518789465451746,-0.17402348366804254,-2.7728065075228487
839.4000000000112,36.56256736144024,-0.17100180327227132,-2.7703606255320077
840.7000000000113,36.60622263631862,-0.17339049197644485,-2.7704521282219234
842.0000000000113,36.65010897595949,-0.17544141038998706,-2.7719789942764175
843.3000000000113,36.694001009969654,-0.1807097355442573,-2.7731275869150513
844.6000000000113,36.73766291088122,-0.1852320665020306,-2.7724655498909256
845.9000000000113,36.781656664236294,-0.18828365429250837,-2.7702627834379454
847.2000000000113,36.82525052134284,-0.1904558384768249,-2.7658626435700544
848.5000000000114,36.869473475103796,-0.19953661059767036,-2.7646442429056246
849.8000000000113,36.913296088724515,-0.19725020358347667,-2.7656300930295608
851.1000000000114,36.956937596309146,-0.19388445335127358,-2.7659594098631866
852.4000000000115,37.0007893611951,-0.19531721795620083,-2.765959578188788
853.7000000000114,37.04477528150156,-0.18964654438686956,-2.7658520290173594
855.0000000000115,37.08851565407394,-0.19362611022784293,-2.7659622770437204
856.3000000000114,37.13224156305557,-0.18559120654927863,-2.765960152725751
857.6000000000115,37.17634350037256,-0.18825792937032393,-2.7659678842476145
858.9000000000115,37.22047462866664,-0.18634758969456833,-2.764638857360381
860.2000000000115,37.26384999655241,-0.1847473576527019,-2.764851138930831
861.5000000000116,37.30838899434577,-0.17604391439333789,-2.7681262813175618
862.8000000000116,37.35227070197145,-0.1776000608199917,-2.769810938118873
864.1000000000116,37.39614333695038,-0.17510981312335883,-2.772544098092146
865.4000000000116,37.440404188481395,-0.17055653170424545,-2.7738721234326964
866.7000000000116,37.483839530169554,-0.1719760139470221,-2.7738539225974117
868.0000000000116,37.52811771187875,-0.1735530999563819,-2.773910577571257
869.3000000000117,37.57199217590273,-0.1681952630953658,-2.7738531070028527
870.6000000000117,37.61597065563504,-0.1656918495702575,-2.775022668653285
871.9000000000117,37.66009512164612,-0.1622270970857569,-2.775280387676085
873.2000000000118,37.704006243696035,-0.16387691535272442,-2.7749152963212653
874.5000000000117,37.74790351256671,-0.16946330051893188,-2.7704937793598017
875.8000000000118,37.79181598899757,-0.16960386165204167,-2.7684377899266606
877.1000000000117,37.83583196172872,-0.1621702541201122,-2.768260380570524
878.4000000000118,37.87979191787171,-0.1633657882005144,-2.7682601789236863
879.7000000000118,37.923787954011985,-0.1665576998752396,-2.768252005318499
881.0000000000118,37.967756228607286,-0.16374643091642227,-2.7679324418270994
882.3000000000119,38.011698141811316,-0.16319512176720696,-2.769584714899354
883.6000000000118,38.055661039348834,-0.16178704757753248,-2.769461451617179
884.9000000000119,38.09978115066252,-0.1602825519659712,-2.7688019954102803
886.2000000000119,38.14358085821583,-0.16350434499984257,-2.7674826453919703
887.5000000000119,38.18754499263697,-0.15910397456801384,-2.767692738071015
888.8000000000119,38.23157290001503,-0.15793094487590942,-2.770223318814622
890.100000000012,38.275571421622956,-0.15848451236387184,-2.770236369123379
891.0000000000119,38.30601636890027,-0.15993706140839326,-2.7706273136913087