File: 01_Data/Face_Shield/STA/N2/10K_min/Face_Shield_STA_N2_10KData_221121_R3.csv
##Temp./Â°C,Time/min,DSC/(mW/mg),Mass loss/mg
51.0,10.445729105501561,-0.007241410923777947,0.013492845835441969
52.000000000000014,10.989170000000005,0.03557073801946542,0.01898725231918519
53.00000000000003,11.248038296569293,0.057445586028116,0.017992811379045293
54.00000000000004,11.452475936054109,0.07005628891125482,0.018734161168950436
55.00000000000006,11.631325284388156,0.08355348998174983,0.019182422675100952
56.00000000000007,11.79293373232061,0.09422049430629698,0.0203445586825044
57.000000000000085,11.94595532392161,0.10060704057071179,0.020089540443247067
58.0000000000001,12.091046836477211,0.10835483759116227,0.02047197266156875
59.000000000000114,12.232012375078021,0.11495808766914517,0.0194875016857603
60.00000000000013,12.366457676030754,0.12093274364118822,0.020219271167039032
61.00000000000014,12.497974556846174,0.12223317551338142,0.0201823055645578
62.000000000000156,12.627276120117163,0.12730001741340047,0.020574954722566652
63.00000000000017,12.754322103447532,0.13049771218920925,0.022144192847846966
64.00000000000018,12.879170000000023,0.13401508560618836,0.02150316997218038
65.0000000000002,13.001798231793147,0.13526904498472003,0.020413580892615357
66.00000000000021,13.121133660382046,0.13835918317590035,0.020463380960502597
67.00000000000023,13.244447751086447,0.13863644307944,0.02174206652533961
68.00000000000024,13.361793254110635,0.1432969129396937,0.021764400226107483
69.00000000000026,13.479170000000028,0.1452121551937251,0.021850355404732014
70.00000000000027,13.59606161187072,0.14760162424079626,0.02203888709031787
71.00000000000028,13.708344744650294,0.1496522777762439,0.022060054145869756
72.0000000000003,13.825208356637146,0.15074648281488967,0.023194440781044712
73.00000000000031,13.93694337864268,0.15216782628380243,0.022097421258897576
74.00000000000033,14.047667665454878,0.1553856969650511,0.020788538078877927
75.00000000000034,14.1612196333021,0.15648484461788725,0.023481552690584273
76.00000000000036,14.270792394451018,0.15877960486653975,0.02473761056248236
77.00000000000037,14.381269494008746,0.1593132196316578,0.021630774816906673
78.00000000000038,14.491178356426062,0.16323213422843508,0.02207217920029869
79.0000000000004,14.597300478947943,0.16446420027241926,0.024639521171901713
80.00000000000041,14.708335413819183,0.1658956897550492,0.02327974840650615
81.00000000000043,14.81400224860581,0.16658668544149968,0.023306297465181203
82.00000000000044,14.921256888354243,0.16925941152193624,0.023281153040086267
83.00000000000045,15.028460397403496,0.1681498226808571,0.022682069160592455
84.00000000000047,15.133380288402702,0.1700844729364469,0.020682682773790262
85.00000000000048,15.237358520548193,0.17085524483618397,0.02189124517754415
86.0000000000005,15.343510862903608,0.17106260160599573,0.02197137017214068
87.00000000000051,15.446046178387391,0.17390672076996538,0.022629524343119378
88.00000000000053,15.551838262119585,0.17337551938618334,0.024109579130565884
89.00000000000054,15.653911597178206,0.17210933747745993,0.023714659832274165
90.00000000000055,15.755901841936746,0.1740341089317473,0.023850446543959514
91.00000000000057,15.858003189857639,0.17407306681151602,0.02323531667538603
92.00000000000058,15.959914819916385,0.1731149889648015,0.02327274821395431
93.0000000000006,16.062905793088632,0.17515065510993588,0.023284903577799554
94.00000000000061,16.162392774681752,0.1748067912874779,0.023362922797253383
95.00000000000063,16.265038176318516,0.1774660674114159,0.023278737311335007
96.00000000000064,16.363291908072206,0.1778233651690524,0.023235903792336643
97.00000000000065,16.46569746510878,0.17675466515183713,0.023243726427129907
98.00000000000067,16.56558037179217,0.17797845556229352,0.02327984182703169
99.00000000000068,16.664019008357997,0.1781037693508737,0.02433726969885086
100.0000000000007,16.764219501519896,0.1801741777014828,0.024653090055464233
101.00000000000071,16.863005249774304,0.18075194238170023,0.021960912627948304
102.00000000000072,16.962865329165098,0.18047022075232433,0.023280101412923138
103.00000000000074,17.06253758177334,0.18099915346255213,0.02393111053395991
104.00000000000075,17.16038751084628,0.1800487881104994,0.023270068348261397
105.00000000000077,17.258441638302365,0.18172189737165223,0.02328039609626309
106.00000000000078,17.35660277667399,0.1810087025513587,0.021859099107592428
107.0000000000008,17.45710986421925,0.18274528918399402,0.023211944333954904
108.00000000000081,17.555004196653737,0.18286056482612933,0.023276840615566563
109.00000000000082,17.653327362954272,0.18408144024785789,0.023276390941492586
110.00000000000084,17.749801740133996,0.1836744812256338,0.023633533887005065
111.00000000000085,17.84789127383639,0.1867052190149745,0.024924024789738652
112.00000000000087,17.94617022553507,0.186750981368622,0.023278691236221505
113.00000000000088,18.045245209953283,0.18706250821003845,0.02326962581522629
114.0000000000009,18.14187611059177,0.1865391827054821,0.02459128518029363
115.00000000000091,18.239951680321226,0.1892488041500805,0.023275273052621337
116.00000000000092,18.338061715855964,0.19143480411849823,0.023279845058544524
117.00000000000094,18.434173037127618,0.19149728584109893,0.0232727278473579
118.00000000000095,18.532673651792585,0.19244970720149668,0.022954896867877217
119.00000000000097,18.629969672850255,0.1948270045820989,0.021985209327456623
120.00000000000098,18.72501158414127,0.19347713604508665,0.023270095682721426
121.000000000001,18.824309662345993,0.1965225254618791,0.023270463920004758
122.00000000000101,18.921582926582875,0.1967656424310632,0.023189451404411088
123.00000000000102,19.018051434018886,0.20010608897316073,0.023280181406499345
124.00000000000104,19.1168306635008,0.20069088632154475,0.024640044640973358
125.00000000000105,19.213182535170056,0.1986517459280317,0.023675409477880827
126.00000000000107,19.31177023453372,0.19734436344305462,0.023270593914451965
127.00000000000108,19.407827174713816,0.1964688489084172,0.024589601071959066
128.00000000000108,19.50465978485989,0.19854271289413217,0.024388449151439673
129.0000000000011,19.602027454070015,0.19667252187726192,0.02324561055928598
130.00000000000114,19.697568632864392,0.19720127387949216,0.024599567994655125
131.00000000000114,19.795187623662144,0.19672740620347318,0.023267458083012116
132.00000000000114,19.89217594038887,0.19862621571482675,0.023271082529889853
133.00000000000117,19.987839229974927,0.19926925322675582,0.024589806201881892
134.0000000000012,20.084810708793267,0.19960863837993026,0.024565785278356067
135.0000000000012,20.180620595074053,0.19838555572287941,0.023280158376325133
136.0000000000012,20.27490631979029,0.19898556810919077,0.02327871596989528
137.00000000000122,20.373515502592863,0.20081594302102768,0.02432199997571871
138.00000000000125,20.47018506681477,0.20117301389326192,0.023826615259482153
139.00000000000125,20.565682330748647,0.20123360801666512,0.02390642506667806
140.00000000000125,20.662353596161132,0.2023328192267847,0.023260027511208925
141.00000000000128,20.758208619311308,0.20275992566317802,0.02287249770987465
142.0000000000013,20.854537559476608,0.20237726439557202,0.02457734513571097
143.0000000000013,20.95030269046297,0.20389031361438859,0.023930378137577257
144.0000000000013,21.044953097508806,0.20416123150141474,0.022641049759948295
145.00000000000134,21.14162065156606,0.2067738115926343,0.02258731733790409
146.00000000000136,21.236869944777656,0.20794728435082588,0.023280186517930623
147.00000000000136,21.332155975107266,0.2069567312253674,0.02196080173260384
148.00000000000136,21.42849637707163,0.20717029796162056,0.02194459862933762
149.0000000000014,21.52330806428792,0.20714079388151663,0.021959031957896613
150.00000000000142,21.618056143920718,0.20989579638482714,0.02193866197880645
151.00000000000142,21.71343590822637,0.20841579502744145,0.021960198516847385
152.00000000000142,21.809360944979588,0.21099169384870864,0.023291234214109835
153.00000000000145,21.90489892383696,0.21090617836075343,0.023327585878488044
154.00000000000148,21.999714952990548,0.2124049922710174,0.023976299074905505
155.00000000000148,22.095156105346195,0.21224836819543924,0.024589370869903426
156.00000000000148,22.18979165721902,0.21233006478703065,0.024256303643746868
157.0000000000015,22.28515129337064,0.212985030799415,0.024317110259495678
158.00000000000153,22.379948232565038,0.21279519203624053,0.022100129425779436
159.00000000000153,22.474790184075815,0.21562507524361685,0.021960007505698265
160.00000000000153,22.569355368332786,0.21361512716332554,0.022956769565944946
161.00000000000156,22.663968798099813,0.2136855516320687,0.02426995603832527
162.0000000000016,22.760252394091744,0.21521434264898853,0.024323292440078248
163.0000000000016,22.85469730136375,0.21337387405011943,0.023265151437281695
164.0000000000016,22.950257265282442,0.21231217398925228,0.02296164595242356
165.00000000000162,23.045092966203836,0.21333232257277923,0.022935783089286232
166.00000000000165,23.13973961099743,0.2119441259092305,0.024260105880367533
167.00000000000165,23.234336600449474,0.21239099987957233,0.02286924055938311
168.00000000000165,23.329075549646788,0.21394292239001023,0.024269976334344356
169.00000000000168,23.42482669376559,0.21421118014107432,0.024931529972723965
170.0000000000017,23.52017621307866,0.21337013572388797,0.0242643896355057
171.0000000000017,23.61502754772386,0.21420456967010104,0.024271438555999225
172.0000000000017,23.710349934114348,0.21349291356484135,0.025609685393732207
173.00000000000173,23.80500225139755,0.2137708657189039,0.02555967315962082
174.00000000000176,23.899697569498574,0.2159264343294114,0.02557814550440085
175.00000000000176,23.99504767474143,0.21631951093809143,0.02295116352836679
176.00000000000176,24.090592007079934,0.21651386870489975,0.024267521392054014
177.0000000000018,24.184268829029918,0.21714076207345134,0.022950052300067192
178.00000000000182,24.279658327438646,0.21720075679971518,0.02383633968125487
179.00000000000182,24.37495398573769,0.21857055105293777,0.02426086877869782
180.00000000000182,24.469441946201247,0.21813683067898004,0.024259983084227166
181.00000000000185,24.56406468289811,0.21932712135027044,0.022949756889426354
182.00000000000188,24.657918761430434,0.22010154869946952,0.022939963206049185
183.00000000000188,24.753406201594334,0.2217317805628184,0.023219440887834786
184.00000000000188,24.847877097695395,0.22048308997099575,0.024260720543048286
185.0000000000019,24.94306323747632,0.22177178719132784,0.024173172525014053
186.00000000000193,25.03792586814262,0.22115934053607922,0.024270051769031298
187.00000000000193,25.13144387566123,0.2247462890197448,0.022897654363990938
188.00000000000193,25.22709064651321,0.22408346370976517,0.024250933159172483
189.00000000000196,25.32180202244295,0.22907788293329862,0.02294990099976424
190.000000000002,25.416211536055346,0.23013864284181446,0.02294994463657396
191.000000000002,25.509627477281594,0.23389697832361633,0.023602034435473485
192.000000000002,25.607315733126747,0.23581497594654893,0.02285231097626994
193.00000000000202,25.70001738262639,0.23862822904698872,0.02293992823915314
194.00000000000205,25.795073591288094,0.24210336434761232,0.022951476510587376
195.00000000000205,25.890736466990127,0.2460469475168996,0.02226487535637034
196.00000000000205,25.985872447451854,0.25083161024434963,0.023300673086311008
197.00000000000207,26.080294342812913,0.2547357188425337,0.023280023092119073
198.0000000000021,26.17531936361381,0.2537352952748439,0.02328002300000076
199.0000000000021,26.27068801250618,0.2559073394622484,0.023280023000584293
200.0000000000021,26.365267200663663,0.26226423567453316,0.023279637768858663
201.00000000000213,26.45896198389449,0.26087417634997545,0.024269972449876498
202.00000000000216,26.55446401002735,0.25594590205100815,0.024245321652148988
203.00000000000216,26.648563068069027,0.251637592332418,0.022940193314823
204.00000000000216,26.74350225032878,0.251434022559295,0.022940598569825
205.0000000000022,26.838708786085803,0.24881640075713923,0.022951115349600926
206.00000000000222,26.93334978838429,0.24975172875473473,0.023175600613973835
207.00000000000222,27.028162349365005,0.24810327635743346,0.02395599179943897
208.00000000000222,27.122728991623717,0.2510202314697737,0.022046619890251584
209.00000000000225,27.216818350904234,0.2507246102504475,0.021959784243341218
210.00000000000227,27.312399039169172,0.25131496890767807,0.02078579684719184
211.00000000000227,27.40701125714737,0.25338591752529166,0.021960048689445344
212.00000000000227,27.501862383407982,0.25125319414277,0.02196005310903626
213.0000000000023,27.59642990160816,0.2537134614266104,0.021290162255984235
214.00000000000233,27.692073879805836,0.25358727969137285,0.021629759940765325
215.00000000000233,27.78734741668917,0.2547321956195529,0.02063676144369886
216.00000000000233,27.88111108910033,0.25588697390659315,0.021939141353040092
217.00000000000236,27.975699104769095,0.2558781098309857,0.02195992211656783
218.0000000000024,28.071269898024834,0.25432091638073756,0.021601695662964104
219.0000000000024,28.165252672475393,0.2562710721593992,0.021644069038606162
220.0000000000024,28.26036138968368,0.25551206054666326,0.0201785910797323
221.00000000000242,28.35418409309485,0.2556020132128482,0.0215201134685854
222.00000000000244,28.449554768991888,0.25803514457957794,0.021520110069312537
223.00000000000244,28.543648531119747,0.25995811987087347,0.021163886409794053
224.00000000000244,28.639727987906202,0.26160939930236493,0.021567306889615168
225.00000000000247,28.733801557579937,0.25960198009985824,0.021849920392488897
226.0000000000025,28.827644522807173,0.26178909192990596,0.021519615088109845
227.0000000000025,28.922945586367877,0.2618096455577009,0.021205215983034265
228.0000000000025,29.017848125367156,0.26309448371207833,0.021520789353550285
229.00000000000253,29.113187234069215,0.2621287234688725,0.020180452078956357
230.00000000000256,29.206656493171852,0.2613790317923157,0.021518938468222615
231.00000000000256,29.302473285704366,0.2639544653141259,0.021518930339312625
232.00000000000256,29.39695228317524,0.26484320492672325,0.022509935006450377
233.0000000000026,29.491766114972027,0.2638319485004497,0.021183000531935114
234.00000000000261,29.5867642519933,0.2646192574112065,0.02183919297275949
235.00000000000261,29.680743570114,0.26367828647636515,0.021935838387836526
236.00000000000261,29.7764516251266,0.26511157639072447,0.022515583322477717
237.00000000000264,29.869965352870754,0.2651807541946298,0.021192923124780272
238.00000000000267,29.965976644725504,0.26654401052946786,0.02119269054157602
239.00000000000267,30.061717792991672,0.26735072362710244,0.021189917657969737
240.00000000000267,30.155762199001938,0.26887954053321816,0.021385420649274955
241.0000000000027,30.250181605378387,0.26803489703706634,0.021850061253609887
242.00000000000273,30.344062574279395,0.26685552936356527,0.022508890267976867
243.00000000000273,30.44037279046149,0.26818124455148035,0.022282344160950984
244.00000000000273,30.534877369686516,0.2696964322033388,0.022508283143162444
245.00000000000276,30.62856999477973,0.27055669638923757,0.02087789031473264
246.00000000000279,30.724438548190783,0.26930589931578375,0.02215089295916073
247.00000000000279,30.819170000000256,0.2684614357300469,0.02217997677355843
248.00000000000279,30.91364560346855,0.26614689230526534,0.022179976548407865
249.0000000000028,31.009357736811882,0.2678391696186112,0.02086539695836276
250.00000000000284,31.10417482181261,0.2678709649340975,0.019552279950335816
251.00000000000284,31.199795719480804,0.2697033697276272,0.020848034942184235
252.00000000000284,31.294197808185878,0.26883249563461975,0.022179821205404515
253.00000000000287,31.388884837119456,0.2698330451146762,0.022179820000538975
254.0000000000029,31.483562280486634,0.27047381320516056,0.02218146628876294
255.0000000000029,31.578684814046262,0.2709158622768511,0.023489844747510702
256.0000000000029,31.673733017412776,0.26890688631849474,0.022171470940315352
257.00000000000296,31.767525335770745,0.27137319700334783,0.020874088880061592
258.00000000000296,31.86278684726801,0.27304619452874046,0.021952501285605663
259.00000000000296,31.958709219090007,0.27119346703552144,0.021152235216814752
260.00000000000296,32.05368489637112,0.2726650652433335,0.022180106276122658
261.00000000000296,32.148064863046216,0.27289870317879944,0.02315825518386294
262.000000000003,32.24262603091344,0.27326631824285463,0.021849862173286994
263.000000000003,32.33806601950742,0.2718781845664353,0.02184987899999591
264.000000000003,32.432158170052254,0.2730112491276682,0.02184987899996038
265.00000000000307,32.52817840881828,0.2714991981763009,0.021849876002632662
266.00000000000307,32.62269162659368,0.2719814371749841,0.02087143749094711
267.00000000000307,32.71767458988932,0.27228790372206696,0.020859878544936983
268.00000000000307,32.81185737050893,0.2751564682091817,0.021220533966704203
269.00000000000307,32.907419953501766,0.2726094095068002,0.021189940676038965
270.0000000000031,33.00305181117158,0.27417236980975407,0.022160436210922008
271.0000000000031,33.097408437524216,0.27321513191478275,0.02217971684757991
272.0000000000031,33.1914970353803,0.2753719979929946,0.02316895587621559
273.0000000000032,33.28888587764631,0.2736866341118941,0.023018142774413164
274.0000000000032,33.38250871058831,0.27375475278440925,0.021373026129649197
275.0000000000032,33.47806073267603,0.2730379156354311,0.020530192896973887
276.0000000000032,33.57147479386224,0.27477258438959584,0.020530200265584497
277.0000000000032,33.66808463781183,0.27228311654893417,0.01956412578649669
278.00000000000324,33.76320018499677,0.2742911233108915,0.02085840496186986
279.00000000000324,33.85745842234876,0.27460946023266597,0.01955019380245382
280.00000000000324,33.95345089060857,0.2746536066426364,0.020858706382463232
281.0000000000033,34.048382964951784,0.274431368948627,0.02062510574009302
282.0000000000033,34.14453688171091,0.27410084567870674,0.01953675705572344
283.0000000000033,34.23926173020052,0.27327380581596805,0.020527155021364152
284.0000000000033,34.33472480295829,0.27439893067012194,0.018528473089414632
285.0000000000033,34.429737670778955,0.2738239994603863,0.01855333188730235
286.00000000000335,34.52524933404016,0.2720656199556034,0.019208355423653067
287.00000000000335,34.62049240408119,0.2740653247830891,0.017893665263778225
288.00000000000335,34.717013258913695,0.2718633379592957,0.017900063987049464
289.0000000000034,34.81138325657853,0.2696345563246117,0.01790006398640731
290.0000000000034,34.90750033828583,0.27122631459014757,0.01790341926573724
291.0000000000034,35.00223110654623,0.2717826914724922,0.01921994168589425
292.0000000000034,35.09822161843155,0.27206902759315055,0.019219902945621925
293.0000000000034,35.193575123871454,0.27279511111384125,0.01790262582903246
294.00000000000347,35.289269148016686,0.273218338457744,0.01790896851865842
295.00000000000347,35.384830766429566,0.2745601750807565,0.017901131955730953
296.00000000000347,35.48064524120995,0.2750047859121143,0.01791541218304271
297.0000000000035,35.57586428289613,0.27499331275012345,0.017930150515883092
298.0000000000035,35.67208969515291,0.2750012443972522,0.018890084865086365
299.0000000000035,35.76722460451545,0.2741005457496739,0.018895793380145243
300.0000000000035,35.863893383731416,0.27713929749818955,0.01756985289417301
301.0000000000035,35.95908100536515,0.27463465465113174,0.017569844000723478
302.0000000000036,36.0548229802084,0.27446607711682713,0.017570508995627065
303.0000000000036,36.151294177786596,0.2756321819494763,0.017570270775783214
304.0000000000036,36.24649502223735,0.27566269070634597,0.01757009599884185
305.00000000000364,36.3415815475987,0.27603080013204623,0.017568287451162234
306.00000000000364,36.43801706597031,0.27588512750089256,0.016250083860319897
307.00000000000364,36.53294234804037,0.2788868686257213,0.017060023299253935
308.00000000000364,36.627869713012046,0.27795111049077725,0.01724106691626659
309.00000000000364,36.7243983284675,0.27710398537571984,0.018537324937086375
310.0000000000037,36.82020287918959,0.2755749724711279,0.0160397600933031
311.0000000000037,36.916761833390794,0.2772482035628098,0.01591885140329019
312.0000000000037,37.01290979898813,0.2767942013829598,0.0169089971217673
313.00000000000375,37.108078375844926,0.2761022480856776,0.015600051557711048
314.00000000000375,37.20402319788514,0.2756834326721961,0.016909796042684277
315.00000000000375,37.29977352485004,0.278016904265453,0.016909875998654122
316.00000000000375,37.394546435778516,0.2781916152460686,0.01691044927939256
317.00000000000375,37.48966950928771,0.2775495354333849,0.015599830309126261
318.0000000000038,37.587230156375234,0.2796316550583593,0.015599876000064405
319.0000000000038,37.68459706927257,0.2791533769041906,0.015599912151831319
320.0000000000038,37.77927221316079,0.27884386626960433,0.014280168246677327
321.00000000000387,37.87479990691865,0.28168988940555495,0.015600705820002503
322.00000000000387,37.97052416267922,0.2833888209740473,0.01592008882064544
323.00000000000387,38.06730584313931,0.28047563244581125,0.014600567750569837
324.00000000000387,38.16345350396379,0.2805974456775936,0.014601413185367562
325.00000000000387,38.258587310075946,0.28168324451223514,0.016580819927550117
326.0000000000039,38.354928733421495,0.2837079291287117,0.01526193375674012
327.0000000000039,38.4517328250859,0.2828412960465778,0.015249067342306688
328.0000000000039,38.547093212826965,0.28205018280438243,0.01394017087615218
329.000000000004,38.64313842332069,0.2836008240385981,0.014269542677058489
330.000000000004,38.740118520044696,0.2821044650115363,0.01427018590260154
331.000000000004,38.835754755548855,0.28234766166697167,0.01435674314015678
332.000000000004,38.931155524576326,0.285109795869406,0.012960159370241975
333.000000000004,39.025938405697026,0.28751452457711946,0.01296015896395275
334.00000000000404,39.12450453710448,0.2888688114824288,0.011929006355803295
335.00000000000404,39.22021238011721,0.28775736138618113,0.011640159527486205
336.00000000000404,39.31780525052248,0.286321349266796,0.011640122669092534
337.0000000000041,39.413579018019426,0.2880248542230952,0.011315458238570386
338.0000000000041,39.509769157214905,0.28681671086793803,0.010320086482744628
339.0000000000041,39.604866310417826,0.28734367083210954,0.0116845627602844
340.0000000000041,39.702229773366646,0.2876370840191111,0.01032296034659641
341.0000000000041,39.79984088618458,0.2892817488637399,0.01163973017202391
342.00000000000415,39.895888445113876,0.28770654675530594,0.012310152583173917
343.00000000000415,39.99205831798481,0.2863873881563539,0.012300046544464038
344.00000000000415,40.08888378788443,0.288597187752389,0.01097987468744055
345.0000000000042,40.184807176573116,0.28848376589050984,0.010980096023280872
346.0000000000042,40.280582986925694,0.28941246021002054,0.01098010233198643
347.0000000000042,40.37828857523558,0.2894858197655792,0.009666861110528835
348.0000000000042,40.47413525383373,0.29189383169872674,0.009004270245569934
349.0000000000042,40.57130289089374,0.28949737234097506,0.009009969238613635
350.00000000000426,40.667786405614436,0.29126603288137753,0.009540841648978393
351.00000000000426,40.76367025305258,0.29165502971468277,0.01098010412660777
352.00000000000426,40.860403390687665,0.292248474106927,0.009679991037934599
353.0000000000043,40.95675576639273,0.29255833213863974,0.009007863993645948
354.0000000000043,41.0535629689184,0.29482677496942944,0.009341486286684741
355.0000000000043,41.14936585579018,0.2963729984095036,0.008679843555598588
356.0000000000043,41.24621080895199,0.2963241883544665,0.007357585874688155
357.0000000000043,41.342742608758556,0.29576049418509137,0.0071479261992069
358.0000000000044,41.43906342855532,0.29681084334871155,0.006699844100849894
359.0000000000044,41.5356541945186,0.2984743130122523,0.006700217140237719
360.0000000000044,41.63215992992,0.2987007462331588,0.005380138028571402
361.00000000000443,41.72944765120808,0.3001627065646738,0.006701317981396393
362.00000000000443,41.82539376611487,0.3003967365291439,0.0077499198309896045
363.00000000000443,41.92213440005567,0.3017933421340938,0.006700020216624303
364.00000000000443,42.01838793059388,0.30104913169030667,0.00670000099993473
365.00000000000443,42.1148541150068,0.30216616259448675,0.006699880239347422
366.0000000000045,42.21219940849617,0.3028885445360761,0.005379525815528474
367.0000000000045,42.30877911773893,0.30404683310312836,0.005373923688165583
368.0000000000045,42.40440282015118,0.30316515484927903,0.004069971340762812
369.00000000000455,42.5027943338323,0.3032409499858235,0.0026626656041734975
370.00000000000455,42.59945700743789,0.3043492786582447,0.0027499740573677656
371.00000000000455,42.69494369535789,0.3018240168989871,0.002087572615055322
372.00000000000455,42.7919521790934,0.3011472757211359,0.001533657935436139
373.00000000000455,42.888108774223426,0.3032080912962173,0.001430131061293416
374.0000000000046,42.98475597523386,0.3029533300355394,0.0014227102794448498
375.0000000000046,43.082242346480996,0.3040800377491023,7.49630299061721e-05
376.0000000000046,43.17888891762531,0.30351290573456224,0.0006726617851269268
377.00000000000466,43.276242077781454,0.3035924645508038,0.00011221285734386299
378.00000000000466,43.372085806859864,0.30514765025781165,-0.0012100674899020447
379.00000000000466,43.469463108577685,0.3038419730081034,-0.0012341711413030865
380.00000000000466,43.56680856498604,0.3043372456377289,-0.0012099840110089133
381.00000000000466,43.662677137008664,0.30413818866424913,-0.0028532502156251027
382.0000000000047,43.76018238706032,0.3055728806179183,-0.0035195356917698817
383.0000000000047,43.856354125676546,0.3065634639681893,-0.0035205697640279254
384.0000000000047,43.954192936572866,0.3061631625838445,-0.0028612981067359655
385.0000000000048,44.050404969404205,0.3072671963292095,-0.0029003837047563152
386.0000000000048,44.14788126959613,0.3074772144813618,-0.0028599795759225444
387.0000000000048,44.24449193845966,0.30824222838552573,-0.003809000218564229
388.0000000000048,44.341373180296834,0.3076454498596187,-0.0041701533015627845
389.0000000000048,44.43822479031936,0.3073779426378614,-0.004170216957756878
390.00000000000483,44.53547043427398,0.3093345040217785,-0.0054899707909905615
391.00000000000483,44.63203790172653,0.3087784503629786,-0.005489872234896609
392.00000000000483,44.72927055805317,0.3079956481396141,-0.006810040905625314
393.0000000000049,44.82544724138223,0.30836400518696394,-0.00681061632097002
394.0000000000049,44.92226577468081,0.30755481453654876,-0.008120136166136938
395.0000000000049,45.020653317734556,0.30797624223912745,-0.009444336486330585
396.0000000000049,45.11793954291233,0.30728279231295585,-0.009440502785472482
397.0000000000049,45.2132419901459,0.30739362479505444,-0.010750342126680579
398.00000000000495,45.31101113727947,0.3068661662192672,-0.01075001900032202
399.00000000000495,45.408227457063454,0.3087704188035634,-0.010750019019742041
400.00000000000495,45.505658399413306,0.306566672770703,-0.010858856872061118
401.000000000005,45.602063187845516,0.30635841429212657,-0.01206653451210471
402.000000000005,45.698535461568305,0.30707286971978603,-0.011409945076296779
403.000000000005,45.79684488263626,0.30852855654930117,-0.013056631707520694
404.000000000005,45.891741896633434,0.3075203661562044,-0.012848595970881505
405.000000000005,45.99109751829286,0.30971712485242614,-0.015369688201857912
406.00000000000506,46.088596901801914,0.308004409994938,-0.01404957720002642
407.00000000000506,46.185057053663634,0.30948272895766976,-0.01404991342716233
408.00000000000506,46.28298372327318,0.31122586065329494,-0.015358716925624627
409.0000000000051,46.3806193538475,0.3109232802596474,-0.018002720454988186
410.0000000000051,46.477794394441744,0.3109766736354459,-0.017999826994160806
411.0000000000051,46.57454126368184,0.3105623745444896,-0.017999426677465458
412.0000000000051,46.672216047107675,0.31226173512670946,-0.01828877427868303
413.0000000000051,46.76908340778106,0.3137167611310474,-0.01833394186813031
414.0000000000052,46.86634190606304,0.3144864135192328,-0.019319912813855034
415.0000000000052,46.96464220679378,0.312128854367724,-0.019319943040380316
416.0000000000052,47.061303248780106,0.3118052517594654,-0.021924507315462805
417.00000000000523,47.158232012739944,0.312180487894318,-0.022939117161310918
418.00000000000523,47.25592725163418,0.313076134476292,-0.023263449750784204
419.00000000000523,47.35414944037815,0.3125922570285888,-0.025909883262266398
420.00000000000523,47.44926617149514,0.3099987603905358,-0.024589840113020678
421.00000000000523,47.548750456976215,0.3088803569073274,-0.026876854423264263
422.0000000000053,47.646401289000394,0.3090960001877905,-0.028209793204429623
423.0000000000053,47.74386726840843,0.3075859337629888,-0.0282098749836317
424.0000000000053,47.841788623097926,0.3064414761265878,-0.028191248615012654
425.00000000000534,47.93831674484414,0.3043665494999892,-0.028202248495007964
426.00000000000534,48.037663208843036,0.3051707450499582,-0.029530093838125104
427.00000000000534,48.13541775633057,0.304881295237902,-0.03085061819276458
428.00000000000534,48.2314619736528,0.30631942031397236,-0.032160431354514074
429.00000000000534,48.32807937443313,0.30654498423079835,-0.030833584181538143
430.0000000000054,48.427699869942316,0.30654508143941994,-0.03269997072094988
431.0000000000054,48.52505525648514,0.3068456299218281,-0.03347919108862207
432.0000000000054,48.62286922552391,0.3072083997033721,-0.03248949923843103
433.00000000000546,48.720474533056645,0.3079256540231728,-0.035017898619836174
434.00000000000546,48.8178047483047,0.3093154711336791,-0.03791852561817777
435.00000000000546,48.91541811735603,0.31109293212816447,-0.03930058914660428
436.00000000000546,49.013017279207304,0.3102588160166609,-0.03930020749103935
437.00000000000546,49.110962532471646,0.31213618262117465,-0.040627461844369606
438.0000000000055,49.20790433288887,0.315222702412032,-0.04216674630861661
439.0000000000055,49.306281832121755,0.31443304036262726,-0.04324493042757904
440.0000000000055,49.40405348636669,0.3134199965690918,-0.04574837262610565
441.00000000000557,49.50098694956838,0.3177795782012306,-0.04588375662310451
442.00000000000557,49.598903156011524,0.3182193581352432,-0.046487332851377516
443.00000000000557,49.696092748083075,0.3191326210127997,-0.049831649497130925
444.00000000000557,49.79218361650612,0.3195057685244362,-0.05114995645531817
445.00000000000557,49.892696235564955,0.3188276942091153,-0.05286583013687096
446.0000000000056,49.99058269751046,0.3192281307964168,-0.05571105222898609
447.0000000000056,50.088585198727394,0.3227734174894395,-0.05927935496223746
448.0000000000056,50.18545354674557,0.32345410833954724,-0.05968165054547825
449.0000000000057,50.2847635197795,0.325631046099196,-0.062112112905704286
450.0000000000057,50.38293609933566,0.3284820934923489,-0.0648809272576969
451.0000000000057,50.48079407712937,0.33286274293072515,-0.06751891319365466
452.0000000000057,50.57961653877969,0.3347313722704738,-0.07325035878121255
453.0000000000057,50.67758000909098,0.337805766537231,-0.07561236111618364
454.00000000000574,50.77593668483136,0.34222295865851277,-0.07788702446498608
455.00000000000574,50.874098537936106,0.3460256860393963,-0.08216666260620809
456.00000000000574,50.97149733983812,0.3482388924168031,-0.08633134823368138
457.0000000000058,51.07046169253739,0.35290600711636,-0.09090456285512838
458.0000000000058,51.169074156964506,0.3564543566628838,-0.09605719334094243
459.0000000000058,51.26635563224408,0.36241220664662566,-0.09865316081306608
460.0000000000058,51.364571765067566,0.36657356866173646,-0.10513449949002407
461.0000000000058,51.462844074828325,0.3746854869135293,-0.11046712823047322
462.00000000000585,51.56048022744069,0.38190164207769184,-0.11507343842995654
463.00000000000585,51.65685863280159,0.38871995783774954,-0.12230119268461692
464.00000000000585,51.75655715889282,0.39616454525168393,-0.1290474375309758
465.0000000000059,51.855082117451474,0.4079478504945312,-0.13574688498102994
466.0000000000059,51.95253314176777,0.4150990535569702,-0.1433767865119373
467.0000000000059,52.051467170037874,0.4241853015491045,-0.15209022887910972
468.0000000000059,52.14871642932838,0.43279373305192326,-0.16210210046327678
469.0000000000059,52.24748769568241,0.44383766812059094,-0.1717213534114519
470.00000000000597,52.34565919971668,0.45627065301806313,-0.18096359293961228
471.00000000000597,52.443857890352184,0.4696826761325854,-0.1932898982125204
472.00000000000597,52.542053929611626,0.48342328457758604,-0.20566390501229304
473.000000000006,52.63948001992857,0.49677646879912885,-0.22016410876331127
474.000000000006,52.737494532862584,0.5140106136662871,-0.233479329128226
475.000000000006,52.835288988435245,0.529829597435667,-0.2502892012273965
476.000000000006,52.933977308745206,0.5462031099707106,-0.2648482356409625
477.000000000006,53.031939781728624,0.5643563700126639,-0.28497344936793034
478.0000000000061,53.13017789358159,0.5822222207071337,-0.304898749697589
479.0000000000061,53.22743784318379,0.6011818646196112,-0.32729299113875454
480.0000000000061,53.32570172611848,0.6217161872073009,-0.351587983671795
481.00000000000614,53.42374516767096,0.6454026382212181,-0.3750005279021509
482.00000000000614,53.52125154931556,0.6705383031349808,-0.4018345749552976
483.00000000000614,53.62084037679297,0.6988118161006325,-0.4317865830121064
484.00000000000614,53.71827725342815,0.7262832164236148,-0.4644998986353941
485.00000000000614,53.81606839330067,0.754546250540667,-0.49783217800020374
486.0000000000062,53.914658237342834,0.781271588608017,-0.5343032313584484
487.0000000000062,54.0133387902481,0.8110633352618608,-0.5764046893555914
488.0000000000062,54.11120287215048,0.8359153751661663,-0.6174817828908079
489.00000000000625,54.21071348526179,0.8639614034902157,-0.6633973475362116
490.00000000000625,54.3088117922316,0.889237592979691,-0.7122101635958535
491.00000000000625,54.40746498277039,0.9158899768325098,-0.764040341183926
492.00000000000625,54.50634719114234,0.9377545814752326,-0.819355300649864
493.00000000000625,54.60461943913476,0.9557864558502688,-0.8755973477336454
494.0000000000063,54.70206129281613,0.9732439070770589,-0.9317423855204261
495.0000000000063,54.80104532595399,0.9860720211228708,-0.9947945776975469
496.0000000000063,54.89917000000061,0.9960654359762274,-1.0600600872230896
497.00000000000637,54.99846128207543,0.9985278549757572,-1.1279039109795752
498.00000000000637,55.09629392488016,0.995143971196119,-1.1956645992122725
499.00000000000637,55.19510219286904,0.9825509400193713,-1.2636762949376354
500.00000000000637,55.29326987890525,0.9686673353532462,-1.3345135974573177
501.00000000000637,55.39183800466075,0.9421208775655081,-1.4051074120477929
502.0000000000064,55.48944415603158,0.9111900631537109,-1.474906806855584
503.0000000000064,55.588294504621146,0.8750456721071889,-1.5416648074142203
504.0000000000064,55.68590134895979,0.8287615066093095,-1.610088417373344
505.0000000000065,55.78397127851341,0.7798925998233968,-1.6711737461110716
506.0000000000065,55.8817784633932,0.7298476952387999,-1.7335987898989211
507.0000000000065,55.98067365801039,0.6739352805815941,-1.78980581809153
508.0000000000065,56.07861214624538,0.6195337635413192,-1.843125169579329
509.0000000000065,56.17643415078316,0.5709633285118176,-1.892232941604405
510.00000000000654,56.27563078804745,0.5189134138468839,-1.938605407003295
511.00000000000654,56.37350587997423,0.4753570512297565,-1.9817722177717476
512.0000000000066,56.47198244794823,0.4349857249534431,-2.0215212641922333
513.0000000000066,56.56973397891944,0.3989273030129849,-2.057624314245147
514.0000000000066,56.66865037593266,0.3661240228813989,-2.0899437896194892
515.0000000000066,56.766564785704745,0.33874293346931295,-2.1225661334033807
516.0000000000066,56.86589151886226,0.3060974784267809,-2.1492470814878253
517.0000000000066,56.96299656726898,0.2844124806053886,-2.1771696856724376
518.0000000000066,57.06076821699854,0.2623950933331202,-2.2015799437688974
519.0000000000066,57.159944079954954,0.23745528145929412,-2.2251179778236585
520.0000000000066,57.25877729695859,0.21706897920762638,-2.2501432331127407
521.0000000000067,57.35853667744395,0.20063087832535273,-2.2713847299692116
522.0000000000067,57.456122171648374,0.1805408950133376,-2.2894158364647277
523.0000000000067,57.55436320311618,0.16582812193798802,-2.308273794336361
524.0000000000067,57.65330456398675,0.1469309066166179,-2.3271263300484115
525.0000000000067,57.752262178856974,0.13161377651210238,-2.3444549112001654
526.0000000000068,57.85030237241099,0.1151823762744163,-2.3601146383004292
527.0000000000068,57.94927400690871,0.10188090035309577,-2.374181839374663
528.0000000000068,58.04837369663262,0.09080187239929977,-2.388673630429011
529.0000000000068,58.14645149003115,0.0787731917084094,-2.402453084843625
530.0000000000068,58.245991935885755,0.06566671459682955,-2.41441229820425
531.0000000000068,58.34419359241542,0.05777792786347291,-2.4254256730023256
532.0000000000068,58.44381076841455,0.04797830985207335,-2.4366902531616947
533.0000000000068,58.54249937063367,0.03845114866592253,-2.4478587767789106
534.0000000000068,58.641188248950144,0.027356281386990422,-2.4589176684333913
535.0000000000068,58.74018461823793,0.021403134169117877,-2.470053039674818
536.0000000000068,58.83859760051509,0.01426422058499921,-2.4799488920022865
537.0000000000069,58.93777148808792,0.007927263001088869,-2.48926901581173
538.0000000000069,59.03712569739541,0.000688630236427068,-2.4963113642162145
539.0000000000069,59.13565746085303,-0.006714302904091085,-2.5061096057413144
540.0000000000069,59.23502486272235,-0.01093733892674692,-2.5138249224649583
541.0000000000069,59.33383419900347,-0.018060998244823878,-2.521470987298068
542.000000000007,59.430990361927,-0.021963098199388187,-2.5286999873695217
543.000000000007,59.530841970142255,-0.02471497826000485,-2.536245506873633
544.000000000007,59.63146951265562,-0.028106860064879946,-2.543775205340147
545.000000000007,59.73027351450515,-0.032660738923477206,-2.552015734404393
546.000000000007,59.82917000000066,-0.03706925909291564,-2.5590390017752225
547.000000000007,59.92926213151481,-0.03878129610622677,-2.5644062410881037
548.000000000007,60.02908138682927,-0.043865241824707246,-2.569685361190632
549.000000000007,60.127101437405386,-0.04367690441376104,-2.5766895179695575
550.000000000007,60.22705654383011,-0.04665563523527744,-2.5834771513447565
551.000000000007,60.325222208214036,-0.047472871400742134,-2.588705647846573
552.000000000007,60.42451976958217,-0.049989482926591666,-2.5944116373728368
553.0000000000072,60.52373371871392,-0.051254700153533506,-2.5994072036801903
554.0000000000072,60.62268849353094,-0.05337236613762758,-2.6040728790000034
555.0000000000072,60.720878235602285,-0.053469518586786,-2.609379769069477
556.0000000000072,60.8205466045681,-0.05680642516056744,-2.615422346049761
557.0000000000072,60.920926204618524,-0.056666417242354106,-2.619608095990882
558.0000000000073,61.01812295702732,-0.06116800242102155,-2.624266675534781
559.0000000000073,61.118863992518,-0.0638049584863356,-2.6280616921970488
560.0000000000073,61.21774506947915,-0.06422964013236498,-2.6330313936196914
561.0000000000073,61.31566062013155,-0.06440256154554524,-2.6362656525052635
562.0000000000073,61.415307353202344,-0.06612426774773583,-2.641125395653885
563.0000000000073,61.514664752984054,-0.06789250502965305,-2.6471593565582436
564.0000000000073,61.61358362454445,-0.06734637106223645,-2.6502571608238155
565.0000000000073,61.712216683216205,-0.06981464451419866,-2.6547597304365667
566.0000000000073,61.81197263805645,-0.07012023158007397,-2.6594489035902287
567.0000000000073,61.9107501576279,-0.07282385771874095,-2.66271131475455
568.0000000000074,62.01064574329069,-0.07300294020360693,-2.6659124253401405
569.0000000000074,62.109356542205134,-0.07377649708888906,-2.66936762907035
570.0000000000074,62.207934359548254,-0.0766933423856867,-2.674870773511236
571.0000000000074,62.30747626701196,-0.0764379002064483,-2.6765083734841526
572.0000000000074,62.40687933350188,-0.07721643627196956,-2.682262381377825
573.0000000000074,62.5065304313066,-0.0758453583517898,-2.684168201671027
574.0000000000074,62.60571335085999,-0.0759813784473633,-2.6861358296988795
575.0000000000075,62.702769434540464,-0.07759390960069734,-2.6909060438509367
576.0000000000075,62.80375157273001,-0.07642623393258163,-2.6948408126897174
577.0000000000075,62.90322020754267,-0.07553250503906933,-2.6965744347927245
578.0000000000075,63.00231636861886,-0.07607423060833868,-2.699607738292851
579.0000000000075,63.1024583330469,-0.07753794654810159,-2.701222308435889
580.0000000000075,63.20158311694995,-0.0781372978764377,-2.7050112167891145
581.0000000000075,63.30089387898082,-0.07814795256919138,-2.7077329957107885
582.0000000000075,63.398759171203764,-0.07810536309045457,-2.711276304948475
583.0000000000075,63.49906494591343,-0.0774932256249321,-2.714943274453306
584.0000000000076,63.59961762603839,-0.08086666299845147,-2.7176779702119562
585.0000000000076,63.698783034123885,-0.0763715892866863,-2.721070129745668
586.0000000000076,63.797360578481474,-0.07434130994703042,-2.7229614695950994
587.0000000000076,63.89788942248924,-0.07414179777271812,-2.725679157240276
588.0000000000076,63.99781595672741,-0.07454812299568753,-2.728349401439216
589.0000000000076,64.09588987770982,-0.0743162169518567,-2.7313420451493826
590.0000000000076,64.19554177659292,-0.07364475790791042,-2.7336291572044638
591.0000000000077,64.29620199129589,-0.07340979630376698,-2.7361751334497475
592.0000000000077,64.39565180867274,-0.07426482932502604,-2.7389285893639754
593.0000000000077,64.49485500720552,-0.07223241313630685,-2.740449358087985
594.0000000000077,64.59454392829826,-0.07310814516435143,-2.7431620628522055
595.0000000000077,64.69478259728295,-0.07403553878780017,-2.745772185188881
596.0000000000077,64.79479618425088,-0.07130453787500068,-2.7511051846827224
597.0000000000077,64.89380861752686,-0.06974050395222026,-2.751038379741922
598.0000000000077,64.99332109638486,-0.06882376919593614,-2.753145663348307
599.0000000000077,65.09379210432468,-0.07151824719092159,-2.7549317556873882
600.0000000000078,65.192260006019,-0.06849680918296175,-2.7563194579670207
601.0000000000078,65.2916314625073,-0.06713199413687121,-2.759186635987292
602.0000000000078,65.39011856901695,-0.0657880346877614,-2.7617002806483932
603.0000000000078,65.49165059878351,-0.062438585913735134,-2.763057290127361
604.0000000000078,65.59034186861683,-0.06393370042807417,-2.763071268285816
605.0000000000078,65.69007998868537,-0.0626812214848792,-2.7656506180010485
606.0000000000078,65.79013585845897,-0.0625972847570499,-2.7669674878216695
607.000000000008,65.88858193176125,-0.06413404258507721,-2.7697158532338078
608.000000000008,65.98781044224621,-0.06361509125886566,-2.7715748925334767
609.000000000008,66.08770571874099,-0.06246522692409612,-2.7722598619188394
610.000000000008,66.18700348826178,-0.06392980241050389,-2.7762173370437493
611.000000000008,66.28679188458474,-0.06194629275723257,-2.7776349515169576
612.000000000008,66.38647046547436,-0.061025132087939915,-2.7803110317363977
613.000000000008,66.48529195478336,-0.06042501195583411,-2.7815647300261794
614.000000000008,66.58538039197482,-0.058655108444522874,-2.7827977982391983
615.000000000008,66.68430662776194,-0.059836815175105196,-2.785578227644494
616.0000000000081,66.78192739789839,-0.059515961360394,-2.7847907673212604
617.0000000000081,66.8830134115112,-0.05914250618757744,-2.7875733211868514
618.0000000000081,66.98354679420675,-0.05969931343662305,-2.788772037092775
619.0000000000081,67.08262590733904,-0.06240739812903978,-2.7928675214343297
620.0000000000081,67.18204942188426,-0.06308349734754265,-2.792849052836196
621.0000000000081,67.28126564218486,-0.06252781135376634,-2.794189827747781
622.0000000000081,67.3806628400849,-0.06366163430136196,-2.7955100339444945
623.0000000000082,67.48011317085317,-0.06324276412105934,-2.7968304137709805
624.0000000000082,67.57994415137773,-0.062222066395469455,-2.798144195317679
625.0000000000082,67.68013928309048,-0.06011197577244842,-2.800448536017522
626.0000000000082,67.778736120624,-0.06070798687325196,-2.801764546685335
627.0000000000082,67.8788494712598,-0.06321296230106543,-2.801774869956186
628.0000000000082,67.97677628293276,-0.06334831304679012,-2.8030792029659706
629.0000000000082,68.07686082776655,-0.06525619101886587,-2.803651722598515
630.0000000000082,68.1779231564442,-0.06287906096239237,-2.8052769479656856
631.0000000000082,68.27736557702806,-0.06414149698301352,-2.805721233163093
632.0000000000083,68.37706358351332,-0.061251640490291415,-2.807039338716569
633.0000000000083,68.47696357506172,-0.08112817637537345,-2.8083831028131305
634.0000000000083,68.57660045649527,-0.08912071906525099,-2.810016331476903
635.0000000000083,68.67626420409302,-0.10153012973861453,-2.810010117017879
636.0000000000083,68.77688944138966,-0.10024193869191111,-2.811190563706515
637.0000000000083,68.87590839971068,-0.10121866524490247,-2.81132640566776
638.0000000000083,68.9767291119877,-0.09965270675555649,-2.811246554634579
639.0000000000084,69.07406921561287,-0.10396897550960593,-2.8131556244126585
640.0000000000084,69.17553219588876,-0.10038443337329767,-2.813636999978135
641.0000000000084,69.27449622947384,-0.10267028846509446,-2.8139536738941215
642.0000000000084,69.3744370631163,-0.10094252631288625,-2.815279994996562
643.0000000000084,69.47424319429858,-0.10532139199703744,-2.8165864855589753
644.0000000000084,69.5719173274727,-0.10611913118375882,-2.81794254754305
645.0000000000084,69.67271941327772,-0.10813459615040177,-2.819230036928892
646.0000000000084,69.77264188239107,-0.10999775585362742,-2.8206594420798035
647.0000000000084,69.87219713619808,-0.10790322515222156,-2.819895969791201
648.0000000000085,69.97167762805469,-0.10928062758007562,-2.8212313054322387