File: 01_Data/Face_Shield/STA/N2/10K_min/Face_Shield_STA_N2_10KData_221116_R2.csv
##Temp./Â°C,Time/min,DSC/(mW/mg),Mass loss/mg
51.0,10.568810692945972,0.02465141241012625,0.010394777596077542
52.100000000000016,11.063449871690409,0.07540520787176819,0.007286063681054333
53.20000000000003,11.321478660193664,0.10074892787177037,0.008352255944476639
54.30000000000005,11.532030846844632,0.11928180915519082,0.011209442211336906
55.40000000000006,11.721236141378096,0.13384002409363638,0.008598464002847361
56.50000000000008,11.895847854570256,0.14802105509932284,0.004272305399573018
57.600000000000094,12.05677899986655,0.16016188685663657,0.0037397828537009126
58.70000000000011,12.211508666740803,0.16851608414089592,0.004725755542627663
59.800000000000125,12.361812045210597,0.1751515205595804,0.005664226544501272
60.90000000000014,12.509608929153048,0.183327651530929,0.008300422568220611
62.000000000000156,12.652047737999531,0.18766909100271412,0.007689076994929156
63.10000000000017,12.790143491552461,0.194598230819512,0.005854569053206582
64.20000000000019,12.928288287645831,0.19911789642771582,0.0074435327077617686
65.30000000000021,13.061877395816673,0.2036072325998981,0.006021163569601029
66.40000000000022,13.19446043737626,0.20764606659435736,0.00608025637540921
67.50000000000023,13.32584792877656,0.20965889912752167,0.006594091294557902
68.60000000000025,13.452287176934767,0.2137042127825941,0.009520875579716037
69.70000000000027,13.581844120703558,0.2168025653237693,0.008183238798953774
70.80000000000028,13.709035399371615,0.2191770967903659,0.008440951371907257
71.90000000000029,13.833207071833925,0.22424696620298246,0.007725798062617528
73.00000000000031,13.959296648391051,0.2297113651886442,0.005820602789872176
74.10000000000034,14.080708788787401,0.23090475222511397,0.00783865396866501
75.20000000000034,14.20390357494182,0.23483328111666069,0.007843546003133639
76.30000000000035,14.325022842925405,0.23886360366159543,0.005159615263696793
77.40000000000038,14.443893740495737,0.24085826435850421,0.0050262300237857716
78.5000000000004,14.566267103298443,0.24345235728458292,0.00650789717873046
79.6000000000004,14.685593781023968,0.24869745210103344,0.00542662262168081
80.70000000000041,14.804577493757273,0.2516308908236935,0.005458125312261419
81.80000000000044,14.92136402058962,0.2532619038634464,0.00518218883314292
82.90000000000046,15.037423930555091,0.25677952563175643,0.005697736515757779
84.00000000000047,15.155507809569812,0.2585982300635292,0.006478748332351181
85.10000000000048,15.267911537476195,0.2589794191824131,0.0064800508946945
86.2000000000005,15.384906330712736,0.26207822561393,0.0065038979745377645
87.30000000000052,15.499443170394787,0.2628281248546285,0.007786638017222458
88.40000000000053,15.6127022542714,0.26521299570961965,0.008112496011077663
89.50000000000054,15.724878388043928,0.2664332967419808,0.009506442706168627
90.60000000000056,15.839886463782017,0.27034597320063203,0.00907910121226907
91.70000000000059,15.950549388668865,0.2704955550370227,0.00746010105909134
92.8000000000006,16.061957655170062,0.26984067360011343,0.007974767926147486
93.9000000000006,16.172631338460807,0.2738818244366872,0.008457320436285443
95.00000000000063,16.28448953192669,0.2760067452863637,0.008803356125401951
96.10000000000065,16.39484909410599,0.2774217206266604,0.008835514474638817
97.20000000000066,16.505818328507203,0.2784750665329392,0.008106764416060841
98.30000000000067,16.615947824741813,0.2803203450211096,0.007459937136667261
99.40000000000069,16.725541449022224,0.28310094626287163,0.008439681053125536
100.50000000000071,16.8345812631903,0.28467676088327265,0.007416686375111059
101.60000000000072,16.94387215272774,0.28442045822974993,0.008716616434809143
102.70000000000073,17.052637840712375,0.2843775551095906,0.008779061248589848
103.80000000000075,17.162337893137924,0.28927217130292726,0.008379307636465327
104.90000000000077,17.269380722571878,0.2911394189288037,0.00747188033417201
106.00000000000078,17.3784216882506,0.29181437204589555,0.006281647183975281
107.10000000000079,17.486403247130262,0.2932577174665677,0.006156902472551629
108.20000000000081,17.594309269070827,0.29632875589070684,0.004829268259534114
109.30000000000084,17.701647452736005,0.2988944125271499,0.0061397560831917275
110.40000000000084,17.808963276588493,0.2986397405324086,0.0061499976632668485
111.50000000000085,17.916158553419915,0.30188236135758284,0.007508644202370629
112.60000000000088,18.02553058699868,0.30588835575803763,0.007480212075779313
113.7000000000009,18.13277920226521,0.30434180915306197,0.007090105589653284
114.8000000000009,18.240716498350903,0.30689698686776745,0.004788715646597552
115.90000000000092,18.34707799253305,0.3073974526001828,0.006099438955161851
117.00000000000094,18.454787223643905,0.30918488325356674,0.008786534326065798
118.10000000000096,18.56235917038741,0.312177108815474,0.008387974939011222
119.20000000000097,18.667522349088784,0.31062888796706356,0.007781541141716364
120.30000000000098,18.776326465430706,0.312888773014097,0.007403308492091032
121.400000000001,18.882827890960954,0.3150129368073057,0.005280139881647106
122.50000000000102,18.99034157673732,0.31748525390361704,0.006700088849739938
123.60000000000103,19.09657741980025,0.3177164396149553,0.008023669491862062
124.70000000000104,19.20328355718822,0.31968723711706126,0.007043459663813145
125.80000000000106,19.31093682947613,0.31982955570780724,0.008360808233661476
126.90000000000109,19.416715339096005,0.32125346182794734,0.009697970126188782
128.00000000000108,19.522928302025406,0.3205365220917503,0.008678986757620688
129.1000000000011,19.629168977979766,0.32254637827280597,0.006699710902569489
130.20000000000113,19.734975679570457,0.3237031616947216,0.0067028104429027735
131.30000000000115,19.840448996084117,0.3266383122844333,0.009100606945488199
132.40000000000117,19.94693348613411,0.3282252585329304,0.011637733418916163
133.50000000000117,20.051591131230705,0.3293926669650893,0.007679813369163568
134.6000000000012,20.156290257669397,0.32977226988652075,0.007677106571941206
135.7000000000012,20.263466039851597,0.33332040745220404,0.0020708481561984016
136.8000000000012,20.36998427118339,0.33398655723282955,0.0050876568399429445
137.90000000000123,20.47539979050698,0.3349409260372014,0.00936452237239882
139.00000000000125,20.58082019256594,0.3346188625329586,0.011978063297003239
140.10000000000127,20.686187768901764,0.335412654721588,0.009527838341429007
141.2000000000013,20.79220077395666,0.3367684614866361,0.006859075649250368
142.3000000000013,20.89791005537195,0.3369492042578932,0.006908747177802876
143.4000000000013,21.002537561666962,0.3394740971012147,0.004297704652624912
144.50000000000134,21.10774028572094,0.3426516865558282,0.005608967699775036
145.60000000000133,21.211957114368353,0.3417861748610532,0.006485253676936864
146.70000000000135,21.316989637584648,0.34528224100125515,0.008166132136371296
147.80000000000138,21.421841466627633,0.34679346234349306,0.010121823220490267
148.9000000000014,21.52609033795402,0.3476600814640328,0.00822136834138254
150.00000000000142,21.63129690464343,0.3499027371224649,0.005600768752731078
151.10000000000142,21.735648298251927,0.35235099984014995,0.008152039127633959
152.20000000000144,21.8407269050549,0.3542473147509474,0.009550031661385905
153.30000000000146,21.944214227203663,0.35603228375796125,0.009789780249452207
154.40000000000146,22.04973945195402,0.35437884125499886,0.008867201901040733
155.50000000000148,22.154754517315244,0.3577577700311194,0.008240080202499112
156.6000000000015,22.259169035288952,0.3555482655737512,0.009550168676910165
157.70000000000152,22.362557455517397,0.3569952202748312,0.009406027248770155
158.80000000000155,22.46758519003844,0.3585103250091007,0.009547108839214058
159.90000000000154,22.572268780287004,0.3618135186917967,0.00954982104210167
161.00000000000156,22.67667385074545,0.3623640464269178,0.009549757085251187
162.1000000000016,22.781706678197583,0.36262739114847514,0.008816050611066828
163.20000000000158,22.88470173174681,0.36209932705180037,0.010210006495237511
164.3000000000016,22.989965143033047,0.36390250368707483,0.008554511871412984
165.40000000000163,23.09416806464927,0.36713946855440255,0.009715674299831889
166.50000000000165,23.198334167714236,0.3667978845348315,0.008559748929275024
167.60000000000167,23.303449940923322,0.36699861458749605,0.009874517372507885
168.70000000000167,23.408014734350896,0.3684829255979909,0.012510568458255822
169.8000000000017,23.512509023235094,0.37060973251522983,0.01119684075829408
170.9000000000017,23.61742814777065,0.3689664596846959,0.010791323017485865
172.0000000000017,23.72131877173882,0.3717139224387069,0.00848250114979221
173.10000000000173,23.82650523177794,0.37373514453686096,0.007316036178159457
174.20000000000175,23.93094135866044,0.3739118700536867,0.00986327612519089
175.30000000000177,24.035539135812982,0.3748961307270944,0.011089990697872754
176.4000000000018,24.1401087853084,0.3732616220658167,0.011741023850111887
177.5000000000018,24.245662337041352,0.3750989295040455,0.011651666872036337
178.6000000000018,24.349281497677335,0.37859089932887696,0.009770093408620006
179.70000000000184,24.45391142586822,0.37958603092927734,0.009189446052725092
180.80000000000183,24.5579626733322,0.37787502810493756,0.00846133909313318
181.90000000000185,24.660827889841034,0.38208126956025895,0.009268304394705051
183.00000000000188,24.76734424799572,0.3834462237825581,0.008461875538531505
184.1000000000019,24.87210443075853,0.3840250396621364,0.00935796483242779
185.20000000000192,24.97616229025573,0.3859580759784329,0.011086426907549907
186.30000000000192,25.078610598434523,0.38473109668092337,0.011751277224864243
187.40000000000194,25.184937253678864,0.38910980736303447,0.013730304342189914
188.50000000000196,25.28813586545117,0.39227131994960013,0.01241018121341897
189.60000000000196,25.393292305862303,0.39454615286857353,0.011658451482122967
190.70000000000198,25.497098063550997,0.39660355762653265,0.009770235248811154
191.800000000002,25.601871087757118,0.40026028355218884,0.011126069435523078
192.90000000000202,25.706510034912295,0.40570452063884177,0.01108998396249783
194.00000000000205,25.810445425716104,0.4088563173269282,0.009077289074752581
195.10000000000204,25.915052475334893,0.4171272275418403,0.009120254273222717
196.20000000000206,26.018612342261278,0.4213881507885959,0.010430406492431654
197.3000000000021,26.122699996776856,0.422075234310543,0.012468074211188451
198.40000000000208,26.227388863009082,0.42537845633133353,0.012434237595357
199.5000000000021,26.331476556446137,0.4260263943568691,0.013729972394667112
200.60000000000213,26.43515941609207,0.42916714851354965,0.012407759767853577
201.70000000000215,26.53878377527256,0.4286530958954924,0.009040007332043132
202.80000000000217,26.64297153987165,0.4321347567406661,0.007140857331668027
203.90000000000217,26.747195207728787,0.4326668429194174,0.008608227257069334
205.0000000000022,26.85123878657915,0.4317723942712463,0.0097635502848612
206.1000000000022,26.955959941767837,0.43526204375822813,0.011081742960456165
207.2000000000022,27.059170000000208,0.43533874264979855,0.01240703719498848
208.30000000000223,27.16385749579213,0.4358633214656482,0.011092468350955897
209.40000000000225,27.266268025719384,0.43489225665489545,0.010100244009630277
210.50000000000227,27.368247900825224,0.43649291631339354,0.011085805108754787
211.6000000000023,27.473420931126377,0.43773458380288566,0.009770139034259717
212.7000000000023,27.579557016535098,0.4379700133109323,0.011113130921533543
213.8000000000023,27.683817217684364,0.4372032945923149,0.009795374457427286
214.90000000000234,27.78814659736628,0.4394916223681085,0.009744060022732093
216.00000000000233,27.893003586759413,0.44176737870286287,0.011119251987873113
217.10000000000235,27.99449969884812,0.44198067658976975,0.01109007011451224
218.20000000000238,28.100347489878715,0.4424843604641086,0.009147890199288522
219.3000000000024,28.20512638724058,0.4432832018796319,0.00881846469424552
220.40000000000242,28.30889562850042,0.4429718312497043,0.011410216642795845
221.50000000000242,28.412573999647243,0.44442912245831406,0.011399096532421993
222.60000000000244,28.518085791178343,0.44907614556456327,0.010105453043040669
223.70000000000246,28.62020345223118,0.44555544616296583,0.009366493607591675
224.80000000000246,28.725426253289072,0.4492762298512679,0.012413058339281413
225.90000000000248,28.829171052422154,0.4475316806278872,0.012681763810692193
227.0000000000025,28.932022154440787,0.44869068788792243,0.011365863539532395
228.10000000000252,29.0365369648936,0.44786282405006395,0.009224033011979493
229.20000000000255,29.14201458594117,0.4494813840315466,0.011493506686380162
230.30000000000254,29.245968017925588,0.45124639549025025,0.011409903398964971
231.40000000000256,29.35187383736561,0.4511481278758687,0.01024184382993365
232.5000000000026,29.455274303106847,0.45089135907408795,0.011329371591586757
233.60000000000258,29.55937130492904,0.452674471546662,0.014159929346993394
234.7000000000026,29.661499339719015,0.45479433256497614,0.012845048336365128
235.80000000000263,29.76716492556417,0.45397241408832223,0.010206249191552441
236.90000000000265,29.871445635581754,0.45438262325377676,0.010870107220006364
238.00000000000267,29.977071370832945,0.4541137808555005,0.01146153075778722
239.10000000000267,30.080688776819272,0.454967731283687,0.014282836522886644
240.2000000000027,30.185315647672596,0.45540721755742825,0.01547759871434895
241.3000000000027,30.289988169287014,0.4555234227352215,0.013837229928550965
242.4000000000027,30.394176948875685,0.45572072589265356,0.010947270451895363
243.50000000000273,30.49785489474106,0.4566234200011855,0.010979934590107376
244.60000000000275,30.601288890795388,0.45788911539737276,0.012382138542656573
245.70000000000277,30.706719850046202,0.4588839208473622,0.01229019953263899
246.8000000000028,30.810772959568713,0.45707830066507116,0.012289650338287217
247.9000000000028,30.91444494675337,0.45778306932354595,0.010979978226365983
249.0000000000028,31.018878666970515,0.4582101353786441,0.010979362275946425
250.10000000000284,31.123544932994314,0.45791183545351427,0.013666496399196149
251.20000000000283,31.227174870722056,0.460139645119707,0.013610136366050796
252.30000000000285,31.331614368055025,0.459070212049136,0.01257159184204637
253.40000000000288,31.435822373091035,0.46016677176722465,0.011301235134213439
254.5000000000029,31.53797904778807,0.4618392350733892,0.012614295592937363
255.60000000000292,31.64511424768766,0.4611318610798355,0.012290259989799157
256.7000000000029,31.749569051456263,0.4608305568577973,0.013727111321539809
257.8000000000029,31.853459711604383,0.46194664727734713,0.011418416683516952
258.90000000000293,31.95838378699065,0.4637473039320069,0.011904331910337795
260.00000000000296,32.06258874180214,0.46366960765353005,0.012410128866673809
261.100000000003,32.16595463078692,0.4648972483965341,0.012405294245652065
262.200000000003,32.272079001503656,0.4602640132046536,0.013860736620318281
263.300000000003,32.375384341021494,0.4651927858541789,0.012405823556482787
264.40000000000305,32.48006783722219,0.4634186695776041,0.01109119892702859
265.50000000000307,32.58509216418762,0.46364976770954797,0.012330039103728652
266.6000000000031,32.68956082810802,0.46364140041267654,0.012400147720784904
267.7000000000031,32.793912146993385,0.46460708859098937,0.0109802156787695
268.8000000000031,32.898144699400454,0.4624502812650274,0.01213079109535009
269.9000000000031,33.00268551356641,0.46472114513278007,0.013013241843170764
271.0000000000031,33.10855031719553,0.46518886258009595,0.008999800598555652
272.10000000000315,33.212742582096396,0.4646933667419968,0.01032353988000434
273.2000000000032,33.3182229756317,0.4661253110985505,0.011056705965429625
274.30000000000314,33.42228335850254,0.46553393022222056,0.01164426257177853
275.40000000000316,33.527943640545764,0.46871598880936216,0.011322964473146957
276.5000000000032,33.63217849436415,0.4690754098660527,0.012944681395838487
277.6000000000032,33.73656180356622,0.47001330592741886,0.011517358241790898
278.70000000000323,33.83869507235741,0.470306040569072,0.012948933292597165
279.80000000000325,33.94652125751763,0.469809566718605,0.014307903265672994
280.9000000000033,34.050624063037034,0.47264190362722136,0.01196986222446661
282.0000000000033,34.155854307812845,0.4736171547668083,0.013795707828808457
283.1000000000033,34.26171545049743,0.47418580110734854,0.011183571016118332
284.20000000000334,34.36666584777367,0.47527517548757336,0.011516133289250607
285.30000000000337,34.471493518659045,0.4733061227638658,0.008888194907027636
286.40000000000333,34.575670220031526,0.4744112168611587,0.011822066408599952
287.50000000000335,34.68128803892908,0.474229294647047,0.014379768759174905
288.6000000000034,34.78691200147761,0.47535452136007494,0.011597919360005982
289.7000000000034,34.89156745942509,0.4787038408024009,0.010209850578508206
290.8000000000034,34.99688386039226,0.47597107181406745,0.008890695629512724
291.9000000000034,35.10162349592605,0.47805513904719543,0.012195542708686613
293.0000000000034,35.20597557859733,0.48015793043942656,0.010867289782889422
294.10000000000343,35.3115138389411,0.48048333318140424,0.012416107435764268
295.20000000000346,35.416987696881236,0.48046682007772396,0.013391069061428063
296.3000000000035,35.522171133976656,0.47982165407388355,0.012189814297707269
297.4000000000035,35.627017680104494,0.48166128929656105,0.012189814664524512
298.5000000000035,35.732719789584195,0.4819268877356653,0.01124554779169129
299.60000000000355,35.83691495454127,0.4823919334606741,0.011652694245783746
300.70000000000357,35.942043372150465,0.48360155278083294,0.013516609072764751
301.8000000000036,36.046779380204256,0.48494707781476576,0.014829876613232429
302.9000000000036,36.15307491947309,0.4863065665987046,0.013524369848856299
304.0000000000036,36.258564809382406,0.488129028467861,0.01076482394704703
305.1000000000036,36.36132383856743,0.4846098946119358,0.013402228578626385
306.2000000000036,36.4682947100819,0.4882226680462153,0.012079840722604374
307.30000000000365,36.57279854489955,0.4891956131682714,0.012074665724004507
308.4000000000037,36.67818134674812,0.48992537154072274,0.01077326094824782
309.5000000000037,36.78293128430964,0.49021209102918895,0.013069920996453543
310.60000000000366,36.88926348251645,0.48997914325200514,0.012080204782533688
311.7000000000037,36.99487381138185,0.4907956328235502,0.01339880320665765
312.8000000000037,37.09975699827342,0.4897009045386752,0.01095515980166839
313.90000000000373,37.2050412708954,0.49166189370094027,0.01075952180360984
315.00000000000375,37.30996746937337,0.492344082875806,0.011750104272896689
316.1000000000038,37.415998112075904,0.49347328410415964,0.011743293201679883
317.2000000000038,37.52111953192131,0.49204136985362346,0.01173890322735005
318.3000000000038,37.6268577483209,0.4931465184185577,0.013069894304630125
319.40000000000384,37.731583034443105,0.4935722805789152,0.01305606454396413
320.5000000000038,37.83726483197967,0.49437009534494053,0.013730106150922072
321.60000000000383,37.94272491231605,0.4952433243618553,0.013426046674533065
322.70000000000385,38.04809311318562,0.49748260801726396,0.01097705531098958
323.8000000000039,38.153869676599285,0.4962145591865731,0.014066228628319521
324.9000000000039,38.260256564580956,0.4988179704561412,0.011667231302656678
326.0000000000039,38.36565303724707,0.5004924895711336,0.00924325478774568
327.10000000000394,38.47078240123711,0.5001653196166498,0.012613144899282336
328.2000000000039,38.57634889807448,0.4989390675043265,0.01063966793034643
329.30000000000393,38.682360921156445,0.5000367262953124,0.010683047621643293
330.40000000000396,38.78619786560797,0.49946863450751866,0.011969259192347703
331.500000000004,38.893198171596445,0.502718030374381,0.010650212420356908
332.600000000004,38.99853107050299,0.501918887167623,0.01129700380890819
333.700000000004,39.105544593658635,0.5010544754235534,0.012699288479342652
334.80000000000405,39.211708406657614,0.5024262969957767,0.011191491028527789
335.90000000000407,39.318083212012326,0.5041112272935298,0.012630045112048904
337.0000000000041,39.423596900905366,0.5039320515001781,0.012405653565611185
338.10000000000406,39.529416151663796,0.5028479904735077,0.011309468391512922
339.2000000000041,39.63527022337035,0.5064105660460093,0.008664399312753979
340.3000000000041,39.74109146953771,0.505699943751818,0.00867013844719855
341.4000000000041,39.847072886691365,0.5056096270091356,0.00899999237741822
342.50000000000415,39.952646749264396,0.5049314287601325,0.008999914841515189
343.6000000000042,40.06010213201167,0.5072741293151218,0.007680142339541618
344.7000000000042,40.16602969577827,0.5074749554702216,0.007685706385383018
345.80000000000416,40.27125613560286,0.508671440459514,0.008339994997544231
346.9000000000042,40.37745388418896,0.5088316883151562,0.008302284204730892
348.0000000000042,40.48392189515542,0.5086385152961157,0.00968853895655375
349.10000000000423,40.59067460730468,0.5084576103214774,0.009660158307171596
350.20000000000425,40.69653070991746,0.510468635825646,0.00811923665827985
351.3000000000043,40.802841450952556,0.5125230734996428,0.005819903016386352
352.4000000000043,40.90844552889314,0.5109146531174884,0.007130781403185349
353.5000000000043,41.014651658193536,0.512320772824982,0.005786094039219147
354.60000000000434,41.12059220740685,0.5132221514422568,0.00844591440472442
355.7000000000043,41.22648930098749,0.5124913100904497,0.007312428392076686
356.80000000000433,41.33339935019699,0.5122718330099221,0.006032266099809558
357.90000000000435,41.43701910290996,0.5150230252619118,0.006471751656543123
359.0000000000044,41.54574836240546,0.5131923967681412,0.00551537618023934
360.1000000000044,41.65126628834538,0.5137425624145309,0.0038829555658375092
361.2000000000044,41.759349467277815,0.5134042095262706,0.00417983842182057
362.30000000000445,41.864431649939505,0.5149878233835208,0.004499921433710252
363.4000000000044,41.96985757512874,0.5162675457636445,0.004509827985198722
364.50000000000443,42.077203063045424,0.5162619166966046,0.0031893714429491737
365.60000000000446,42.1836808010389,0.5162514970256364,0.002850533040620551
366.7000000000045,42.28972921769753,0.5151535897134484,0.004180316580164156
367.8000000000045,42.395935265961796,0.5159314528625709,0.0014794617033451196
368.9000000000045,42.50284996886454,0.5163888771094527,0.003831668815200473
370.00000000000455,42.60994244676037,0.5153000881622546,0.002529908228144251
371.10000000000457,42.71628524402418,0.515926352980198,0.0028612204153648513
372.2000000000046,42.82261792850443,0.5157007859121215,0.0019069906612485532
373.30000000000456,42.929670292010734,0.5134027910453108,0.0015217382359526965
374.4000000000046,43.0356924864237,0.5089519154456885,-0.0010993983727871637
375.5000000000046,43.14275259107436,0.5132250363648739,-2.3547117195210632e-05
376.6000000000046,43.249265677613735,0.510405493226977,0.00022016102256028347
377.70000000000465,43.35527349108251,0.5132976935427002,0.00022016099673116685
378.8000000000047,43.4593685269639,0.513702603170821,-0.00012749995781558
379.9000000000047,43.56827954233356,0.5133977847448652,-0.001089934530440928
381.00000000000466,43.67399782108507,0.5151608014196358,0.0002188205483495409
382.1000000000047,43.78155114745824,0.5166937320535252,-0.001066802401358924
383.2000000000047,43.8886368992701,0.515319293134026,-0.0038397572578898753
384.30000000000473,43.99557972672729,0.517820932808566,-0.0025182150346494403
385.40000000000475,44.10318845528403,0.5168104826040139,-0.0025199329794167724
386.5000000000048,44.21007831540227,0.5178737124309153,-0.0011451117676912759
387.6000000000048,44.315555901634916,0.5173761910751983,-0.0025239742603151427
388.7000000000048,44.42284352593922,0.5175982693735983,-0.0025206446186416542
389.80000000000484,44.52995249050596,0.5211835323716114,-0.0038399451058270806
390.9000000000048,44.636741093582316,0.5199559809342602,-0.005082592474470626
392.00000000000483,44.743511120619424,0.5213093348750569,-0.010523708236505502
393.10000000000485,44.850468408093846,0.5189886277575887,-0.009111588835088114
394.2000000000049,44.956640858083794,0.5203569653042007,-0.008120376648119265
395.3000000000049,45.0640431036302,0.5200105386228646,-0.008119987806003426
396.4000000000049,45.1700404542391,0.5196686142885362,-0.009416376492019207
397.50000000000495,45.277622237576715,0.5221562294490665,-0.010793239174005542
398.6000000000049,45.38411031835214,0.5217528249037134,-0.01336427477659008
399.70000000000493,45.491352088173024,0.5220949340377781,-0.012711089185918123
400.80000000000496,45.59822241858375,0.5210284150878889,-0.01142227971488552
401.900000000005,45.70521756391086,0.5241578534792916,-0.0114203138662754
403.000000000005,45.812339010049826,0.5240210949251084,-0.009365956784944895
404.100000000005,45.918292547913765,0.5242956718777768,-0.010760072144163413
405.20000000000505,46.02575678473043,0.5285211644093109,-0.012075474557957655
406.30000000000507,46.132994570925774,0.5278442944265634,-0.014663359725689329
407.4000000000051,46.23953710011031,0.529079377256607,-0.014710190010808422
408.50000000000506,46.34658000241427,0.52745286995483,-0.014728743594464522
409.6000000000051,46.454336853315795,0.5301575646219144,-0.017339896922786924
410.7000000000051,46.56149428911079,0.5312115564876732,-0.017264043678892005
411.8000000000051,46.66732834776722,0.5327102190745331,-0.018330255494318326
412.90000000000515,46.775934363696216,0.5328140999618771,-0.018174988665560665
414.0000000000052,46.88252987227624,0.5310246471778284,-0.018303535303385576
415.1000000000052,46.9889851537884,0.5334873530450424,-0.017340027507849243
416.20000000000516,47.09673942464215,0.5340706859789459,-0.018660188621831164
417.3000000000052,47.20331559115632,0.5335170375887247,-0.019982262770634307
418.4000000000052,47.31108113949681,0.536232439868492,-0.021630283802232864
419.50000000000523,47.417254210754265,0.5362076021821518,-0.0239284584800048
420.60000000000525,47.52475836423758,0.5391894287402947,-0.023929814218971224
421.7000000000053,47.63243599159483,0.5365391508417509,-0.02287924254118101
422.8000000000053,47.73994700834954,0.5369583368552747,-0.024260129619042115
423.9000000000053,47.84752795573435,0.5398808932730578,-0.02557988654091048
425.00000000000534,47.954076760681474,0.5391928645949301,-0.02690351606636332
426.1000000000053,48.061906429548735,0.5431632374930967,-0.028884600957764572
427.20000000000533,48.16990535156918,0.5419389342229567,-0.028891760051952264
428.30000000000535,48.27616389924246,0.5418579611294815,-0.02887001872784367
429.4000000000054,48.38399446477909,0.540375066605046,-0.02986167811903906
430.5000000000054,48.49002880736005,0.5428977287379296,-0.031730116481242465
431.6000000000054,48.59877484369995,0.5427923912031901,-0.03304010027815263
432.70000000000545,48.70553435115174,0.5422204786125118,-0.03310478619776758
433.8000000000054,48.81385893127893,0.5403125135050318,-0.0343617232495288
434.90000000000543,48.92105396796576,0.5385857393650573,-0.03703052767692361
436.00000000000546,49.028705394328725,0.5399624791506096,-0.036984589942250956
437.1000000000055,49.13703717658451,0.53950819458285,-0.039851542072524726
438.2000000000055,49.243546592779325,0.5371752392348441,-0.03921121353272694
439.3000000000055,49.34997605549537,0.5406989997017739,-0.040251066966462634
440.40000000000555,49.45990072257435,0.5412189334364107,-0.04463453838371079
441.50000000000557,49.56693497323413,0.5462705713394584,-0.04458844357639391
442.6000000000056,49.67518635059161,0.5460692263180991,-0.04588960482160909
443.70000000000556,49.78306470524112,0.5448176911621752,-0.04774892703453304
444.8000000000056,49.89021124084925,0.5500346373800948,-0.050527605833299294
445.9000000000056,49.99828963713099,0.5521063815415913,-0.051810957635891164
447.0000000000056,50.10574817020107,0.554143641407717,-0.05448800032859413
448.10000000000565,50.21356879816567,0.5569047152530389,-0.058241319205112774
449.2000000000057,50.321592868930935,0.5611320243350172,-0.06079967333274672
450.3000000000057,50.42839515535453,0.5626163004866747,-0.061266905477529665
451.40000000000566,50.53589428467954,0.5651993675312694,-0.06465925942717554
452.5000000000057,50.64340216165843,0.5668843595783077,-0.06667390975262855
453.6000000000057,50.75221671913616,0.5706748038653189,-0.06926714882047502
454.70000000000573,50.85907086314606,0.5755765292141422,-0.07321913493955501
455.80000000000575,50.96675047978537,0.5806734189260848,-0.0774612223922242
456.9000000000058,51.07440910348093,0.5851067860141774,-0.08055253514231175
458.0000000000058,51.181605730451565,0.5922280732259662,-0.08480561754678018
459.1000000000058,51.290726165329296,0.5977510751045129,-0.09038898508695592
460.20000000000584,51.39798903498224,0.6022892890405187,-0.0948476731465635
461.3000000000058,51.505486662293734,0.6102906940854365,-0.10252874895071606
462.40000000000583,51.613374287930235,0.6170193313276799,-0.10825149206353268
463.50000000000585,51.720955582664175,0.6222177194427295,-0.1147998346123944
464.6000000000059,51.82949100763201,0.6333986421632788,-0.11947963686495866
465.7000000000059,51.93788831119034,0.6437948181625833,-0.12701714670497255
466.8000000000059,52.0461044444996,0.6518228179476182,-0.13876972087266592
467.90000000000595,52.154520980697356,0.661974216406416,-0.14642888003778243
469.0000000000059,52.262893585471275,0.672152615912086,-0.15490572632870547
470.10000000000593,52.371313731477386,0.6846835508829179,-0.16436267007876504
471.20000000000596,52.48006410901939,0.7008918720407078,-0.17693636057324102
472.300000000006,52.58719003100242,0.7146049132549358,-0.19076019931460442
473.400000000006,52.69494062759553,0.7315045703205478,-0.20318764985776427
474.500000000006,52.80250455681883,0.7493058470275485,-0.2239135350580348
475.60000000000605,52.910875414136264,0.7660023656691692,-0.23587071087453326
476.70000000000607,53.01948293023659,0.785073463291877,-0.25146267972521663
477.8000000000061,53.12803134720177,0.8054365785159152,-0.2733923292910361
478.90000000000606,53.236554633911396,0.826742420235058,-0.29744732957536346
480.0000000000061,53.34468454035481,0.8513760380494639,-0.31884453059705375
481.1000000000061,53.4533326704718,0.8726737871748098,-0.34116946544817406
482.2000000000061,53.56222621001152,0.8996882770314889,-0.37027019623876356
483.30000000000615,53.66998133292445,0.9285242261790213,-0.4008070030502786
484.4000000000062,53.776492215700166,0.9576146436156752,-0.43038683632818886
485.5000000000062,53.88487512896549,0.9871923038349781,-0.4648402920636103
486.60000000000616,53.99374593784196,1.0141646276877916,-0.503757779031019
487.7000000000062,54.10306666587359,1.0465182453718178,-0.5456594693832164
488.8000000000062,54.21162978477853,1.077725845997535,-0.5904186211239786
489.90000000000623,54.31946380613479,1.109150294367616,-0.6377270241612449
491.00000000000625,54.428866300528576,1.1352989352582872,-0.6881829977323091
492.1000000000063,54.53625082502905,1.1622331807371067,-0.7388378863107481
493.2000000000063,54.644762158655084,1.1893105990945108,-0.7957403783822916
494.3000000000063,54.752944783368285,1.206180162507673,-0.8609105061115274
495.40000000000634,54.86135855100816,1.2236584850609775,-0.9239856480042099
496.5000000000063,54.969913492500666,1.2364991655464161,-0.9865010081607695
497.60000000000633,55.07828420941513,1.241744869050285,-1.050184233618308
498.70000000000636,55.183982467310905,1.2387909471090042,-1.1216512829721936
499.8000000000064,55.29404568966129,1.2299631586147357,-1.1963007417109055
500.9000000000064,55.403020586609166,1.2126956145993248,-1.2705534818780233
502.0000000000064,55.510846742235344,1.1875909841540948,-1.3438974557230092
503.10000000000645,55.61916901614152,1.152875459769307,-1.4147793674706306
504.2000000000064,55.72675756085664,1.1099679119067667,-1.4857916135415938
505.30000000000643,55.83539613383592,1.0587917129588738,-1.5510519550350108
506.40000000000646,55.94403583627775,1.0050490585554592,-1.6169944837684196
507.5000000000065,56.05076948195925,0.9501190486088535,-1.6751662425742602
508.6000000000065,56.15994107269374,0.8897302815570307,-1.7332405385212803
509.7000000000065,56.26650538828136,0.8320137889244974,-1.7854558566007137
510.80000000000655,56.37509797447934,0.7815080992292273,-1.833191139922746
511.90000000000657,56.482571177236146,0.73210495071179,-1.8841412765858156
513.0000000000066,56.590517807201536,0.6869699778425895,-1.9248807838912714
514.1000000000065,56.698658391475476,0.6465048345313414,-1.9654053428460303
515.2000000000066,56.80774624774052,0.6091568237099483,-1.9959629721598997
516.3000000000065,56.91497671621747,0.5776125605270215,-2.0280239298491005
517.4000000000067,57.023112380059175,0.5486130231369304,-2.058434909582511
518.5000000000066,57.132581450793154,0.5212830579750602,-2.0845652051954815
519.6000000000067,57.24053942164143,0.49694474955138623,-2.111402630048212
520.7000000000066,57.34806188342444,0.4739529574339726,-2.136556834965669
521.8000000000067,57.45715567788072,0.4498503869774409,-2.1617785410377675
522.9000000000067,57.5644835978567,0.4342941843252197,-2.1837639381485774
524.0000000000067,57.6735296347538,0.4135998685127793,-2.202540991970235
525.1000000000067,57.780705205195616,0.3941320559304687,-2.2209596962500857
526.2000000000068,57.88950230158046,0.37850510608850757,-2.2391807075810983
527.3000000000068,57.99804130279204,0.36171402313786455,-2.256812652275424
528.4000000000068,58.10628422873486,0.35074257118629415,-2.2713765981696796
529.5000000000068,58.215754449052255,0.3329025781456477,-2.2869300184122068
530.6000000000068,58.32411390719302,0.3204877682103417,-2.300067858077181
531.7000000000069,58.43168599189255,0.31055061793021094,-2.314647134240307
532.8000000000068,58.541082220190795,0.30024896585402744,-2.331158807577463
533.9000000000069,58.646580191694746,0.28941503958165743,-2.34324228813173
535.0000000000068,58.757315824200475,0.28193909780659165,-2.35662996925232
536.100000000007,58.86603134593065,0.27428542021237423,-2.361951938299237
537.2000000000069,58.97465258889433,0.26270345120051447,-2.376029973838489
538.300000000007,59.08397553628965,0.2563763453420971,-2.384979959964734
539.4000000000069,59.19279865033798,0.24965834370475384,-2.395749296643297
540.5000000000069,59.300510570959794,0.24323901852224683,-2.40418103532673
541.600000000007,59.41015218020757,0.2332023295641801,-2.4119288413594617
542.700000000007,59.51793832139558,0.22661242153149014,-2.4193867893601464
543.800000000007,59.62683397427509,0.22147344864683782,-2.42753663236919
544.900000000007,59.73546456740421,0.21709672042308845,-2.4367392234594325
546.000000000007,59.844304077161006,0.2124371591378673,-2.4426282697345587
547.1000000000071,59.95253360318801,0.20863050988198956,-2.4509689904536724
548.2000000000071,60.06124710707265,0.20604344610549402,-2.4582290277494567
549.300000000007,60.169777463903266,0.20157172203967433,-2.468272377413591
550.4000000000071,60.278781384674076,0.19544675821239113,-2.473402339119004
551.500000000007,60.38763022469846,0.19396934643235297,-2.4790533307108875
552.6000000000072,60.49661258694988,0.1910456470891193,-2.4831113798416493
553.7000000000071,60.605384285274994,0.18484036345791072,-2.488875010755516
554.8000000000072,60.7150222454458,0.1817334381854377,-2.4954058141555775
555.9000000000071,60.82315123111007,0.18062982236678918,-2.501864724731263
557.0000000000072,60.932722027087074,0.17784782774025337,-2.5084565697325574
558.1000000000072,61.04157430171217,0.176233953858766,-2.5142075366379224
559.2000000000072,61.15107845973426,0.17008104009203256,-2.519973803374721
560.3000000000072,61.259269070010475,0.16822889311875858,-2.525119949731216
561.4000000000073,61.368395893370206,0.16712176909475104,-2.5306504136275216
562.5000000000073,61.475316077272495,0.16342613084161878,-2.5323599338756697
563.6000000000073,61.58836324699197,0.15991760663020915,-2.536934996955028
564.7000000000073,61.69582189968294,0.16031381376693854,-2.5430203668892055
565.8000000000073,61.80548732404655,0.15788959870344715,-2.545266992850499
566.9000000000074,61.91433938264129,0.15715026483177785,-2.548394830051601
568.0000000000074,62.02458702405596,0.15247129831029077,-2.552122612033827
569.1000000000074,62.13319402201529,0.15230512425303755,-2.5590881637546734
570.2000000000073,62.242167120199134,0.15145253618118065,-2.564421826529312
571.3000000000073,62.35173512816801,0.14947977465744605,-2.5670875493370686
572.4000000000074,62.46103892829737,0.14814374927238527,-2.572840207105381
573.5000000000074,62.5700015912847,0.14625816254849622,-2.573397944382055
574.6000000000074,62.679273513685516,0.1454783983167644,-2.5778110538568004
575.7000000000074,62.78830384631354,0.14433636886293288,-2.5863300411270935
576.8000000000075,62.896425256997745,0.14567641967144704,-2.587283552057184
577.9000000000075,63.00650006191914,0.1448539737733449,-2.5876966281620035
579.0000000000075,63.11581583303851,0.1429792377719043,-2.590550267488096
580.1000000000075,63.2236615001771,0.1445072308930574,-2.5919645691670508
581.2000000000075,63.33395913148978,0.14560265640394612,-2.5959484036478897
582.3000000000076,63.44197749262659,0.14754618475160164,-2.60656431055774
583.4000000000076,63.551686398880854,0.14744661021620242,-2.6084495758287307
584.5000000000076,63.66069751179875,0.14428867443916366,-2.6082725570615723
585.6000000000076,63.770232559902084,0.1463791431095151,-2.611628850483256
586.7000000000077,63.87887193746876,0.14730071750703788,-2.6125915149370513
587.8000000000077,63.98712077479103,0.15012893466450283,-2.6172955313256283
588.9000000000076,64.09709788797976,0.15010697967668485,-2.620236930315534
590.0000000000076,64.20632835460958,0.15057348316569924,-2.6243760244287415
591.1000000000076,64.31442008392705,0.15132231217235328,-2.626186126868171
592.2000000000077,64.42250436655031,0.15271485781405758,-2.6299401071544093
593.3000000000077,64.53367193848317,0.15324630889792223,-2.6285666631334483
594.4000000000077,64.64227166843995,0.1525316596179045,-2.632235997734634
595.5000000000077,64.75033537945556,0.15200956794616405,-2.6390753337719155
596.6000000000078,64.86160499676211,0.14934638724714694,-2.640719861874788
597.7000000000078,64.97072577878778,0.1494953586957165,-2.6443731852005623
598.8000000000078,65.08057102076683,0.1512444462490945,-2.6453643769045105
599.9000000000078,65.18974343718195,0.1536989650986582,-2.64471852403331
601.0000000000078,65.29936467357041,0.15305597950883845,-2.648297526833236
602.1000000000079,65.40849969208942,0.15561044202979624,-2.649607550656578
603.2000000000079,65.51825192276213,0.15423773348485093,-2.6509259968869903
604.3000000000079,65.62836704783007,0.1572089339672763,-2.653529229308883
605.4000000000078,65.73802079398274,0.15919940001510013,-2.6532668218363575
606.5000000000078,65.84815882200499,0.16086439375425465,-2.6572012226558117
607.6000000000079,65.95839184080447,0.16329022719533698,-2.6608283896309377
608.7000000000079,66.06766482216806,0.16715973707705975,-2.662143582708609
609.8000000000079,66.1781079846462,0.16960386561359453,-2.6634022340346846
610.9000000000079,66.28730376550992,0.17092755443190433,-2.665999325401299
612.000000000008,66.39849698912157,0.1722258518638739,-2.670369330142711
613.100000000008,66.50716876671908,0.17161372858965077,-2.672921358591287
614.200000000008,66.61743277039872,0.17381033979686544,-2.6729999380254235
615.300000000008,66.72722604160643,0.17209477858249173,-2.6729998660479137
616.400000000008,66.83732533044513,0.1707363968127367,-2.674410554528829
617.5000000000081,66.94854766116264,0.1721981164110815,-2.6770586749086265
618.6000000000081,67.05680688600198,0.17210502140842143,-2.6787111065543625
619.7000000000081,67.16740185063959,0.1742098843620617,-2.6810373138944845
620.8000000000081,67.27689014999363,0.173791903955605,-2.6824797928696604
621.9000000000082,67.38668802103132,0.17637604301146517,-2.6836277709458756
623.0000000000082,67.49724133865112,0.17846345774335534,-2.685957875032716
624.1000000000081,67.60667730490928,0.18133566568738246,-2.688576535241202
625.2000000000081,67.71607954366661,0.1815656753788647,-2.6890059563472075
626.3000000000081,67.82465231001787,0.1775640720484454,-2.6879299678691364
627.4000000000082,67.93415810419083,0.17880255859205155,-2.6889894792613207
628.5000000000082,68.04309039434638,0.18410557592527915,-2.690555818316117
629.6000000000082,68.15371064476307,0.18557885761461007,-2.6928952015515994
630.7000000000082,68.2625726602273,0.18969877733099033,-2.6956075468937053
631.8000000000083,68.37287264236754,0.19236145793131487,-2.6985375448751445
632.9000000000083,68.48196922186297,0.19168481650570232,-2.6990804608569796
634.0000000000083,68.5913963433588,0.1926674307548917,-2.699009563219005
635.1000000000083,68.7013996816629,0.19802740197581623,-2.696403544083973
636.2000000000083,68.80852138772343,0.19916404164068538,-2.6963971366815844
637.3000000000084,68.91788380328424,0.20013894130511917,-2.6989715308858475
638.4000000000084,69.02965862096082,0.20066899573001867,-2.7016609642282057
639.5000000000084,69.13777147080077,0.20237319834246725,-2.7017602338247464
640.6000000000083,69.24937281998879,0.20259797349237382,-2.704388525251014
641.7000000000083,69.35898790388545,0.200678285097945,-2.7057102511021736
642.8000000000084,69.4680038662294,0.20482119908509713,-2.7066984879945823
643.9000000000084,69.57796777831203,0.20415149483657127,-2.7080112321059406
645.0000000000084,69.68776126391566,0.20640458646933757,-2.708351722177701
646.1000000000084,69.79753121329124,0.20725481601616508,-2.710138191591073
647.2000000000085,69.90679146468342,0.20467279704440922,-2.708306334495803
648.3000000000085,70.01596845503751,0.20517382306403512,-2.708373268699982
649.4000000000085,70.12597706979761,0.19989623519065094,-2.708340111366261
650.5000000000085,70.23485403554676,0.2060533068685058,-2.709329937000055
651.6000000000085,70.34474243805344,0.20718628226971375,-2.7083600018133334
652.7000000000086,70.45436381663453,0.20342947889202773,-2.708096427687111
653.8000000000086,70.56439483127251,0.20196710329963086,-2.707052449737429
654.9000000000086,70.67397723697547,0.2033706003779224,-2.708107957011341
656.0000000000086,70.78474322122061,0.20147877718549267,-2.7124428030664927
657.1000000000087,70.89402751025177,0.20210323409533212,-2.7163106372110644
658.2000000000087,71.00327334426456,0.20149764414908955,-2.7152602830359482
659.3000000000086,71.1136974848455,0.19858085772503037,-2.7179862424789336
660.4000000000086,71.22349278881309,0.19945937643645353,-2.718345085782757
661.5000000000086,71.33361630195832,0.19686130598322613,-2.7150031250386
662.6000000000087,71.44342988908859,0.19896036666933692,-2.718549663786983
663.7000000000087,71.55338502979349,0.19811091219639015,-2.7204418611858423
664.8000000000087,71.66274187391886,0.19382854920102893,-2.723046877408091
665.9000000000087,71.7720220307236,0.19554925292530703,-2.7257869307120313
667.0000000000088,71.88313831052277,0.19513344586390283,-2.723809447153016
668.1000000000088,71.99259614582432,0.19645491087001138,-2.7194874668339795
669.2000000000088,72.10417282269108,0.19426850597191067,-2.724422741125714
670.3000000000088,72.21236418986288,0.19417679386792644,-2.725978834724288
671.4000000000088,72.3214312296628,0.193074099563848,-2.722105029154207
672.5000000000089,72.43349742947323,0.19100411283239252,-2.717922260381062
673.6000000000089,72.5429610918443,0.188931067370734,-2.722700357810618
674.7000000000089,72.65398643369603,0.19042126976101703,-2.724430832010717
675.8000000000088,72.76415030566099,0.18963219949803295,-2.727010696443472
676.9000000000088,72.87402946918381,0.18922759055026764,-2.7261518467221433
678.0000000000089,72.98296069487314,0.18744978393670586,-2.7245869564832903
679.1000000000089,73.09473326061236,0.1888258055392487,-2.7273885832245504
680.2000000000089,73.20445331291292,0.18719117562495233,-2.728648297970021
681.3000000000089,73.31425760885759,0.1847909107374742,-2.7306298528810924
682.400000000009,73.42472328615663,0.18924901876331307,-2.7293155401756515
683.500000000009,73.53488249723252,0.1847416918079813,-2.729319856322893
684.600000000009,73.64502015457053,0.18942268883843522,-2.727999796984091
685.700000000009,73.75555898070473,0.1852943447155012,-2.7266873957050133
686.800000000009,73.86561421694779,0.18683779802328826,-2.729912354774056
687.9000000000091,73.97545449630327,0.18592560952742299,-2.7310704157954087
689.0000000000091,74.08567617284848,0.1865190696957417,-2.7348811631595833
690.1000000000091,74.19481173699502,0.1883257433235686,-2.7349271527142625
691.2000000000091,74.30523826949806,0.18722870113483928,-2.7335999698668907
692.3000000000092,74.41449669342548,0.1894667485014986,-2.7335995047520165
693.4000000000092,74.5247561906054,0.187282180562717,-2.7347983388414017
694.5000000000091,74.6344183187967,0.18547373080179327,-2.7350195616535053
695.6000000000091,74.74497170010254,0.18076420501285584,-2.736429701764594
696.7000000000091,74.8551253176752,0.18200006832079274,-2.739054614834071
697.8000000000092,74.96517235962476,0.179282374184386,-2.736333521867688
698.9000000000092,75.0748130354339,0.18159842480922514,-2.7363439534558838
700.0000000000092,75.18384144681247,0.17969011889820058,-2.73764908869557
701.1000000000092,75.292587249037,0.17859247330143196,-2.7376538062432143
702.2000000000093,75.40581022384455,0.17778503373310217,-2.738981116601277
703.3000000000093,75.51592269613346,0.1757992920002122,-2.7389798511811794
704.4000000000093,75.62618577394403,0.17543027060102828,-2.7403000045501753
705.5000000000093,75.73628097591556,0.17902782819343757,-2.742315562305686
706.6000000000093,75.8464574978942,0.17405466120570087,-2.7442497703719098
707.7000000000094,75.95644426779864,0.17284733676612646,-2.7469178407340884
708.8000000000094,76.0668135720341,0.17035183922235048,-2.7474322253157375
709.9000000000094,76.1772235360538,0.1743665300749163,-2.7470698287496966
711.0000000000093,76.28840495928513,0.16848661491823103,-2.7494814798173444
712.1000000000093,76.39781138936102,0.16635430207061508,-2.7435029168715923
713.2000000000094,76.50906448682801,0.1636777816035755,-2.7439099166245513
714.3000000000094,76.61947673153367,0.16846468990378105,-2.7445710125320155
715.4000000000094,76.72927188871671,0.16517302038583312,-2.7445699893875637
716.5000000000094,76.83967855665983,0.1632870198123946,-2.745890084591127
717.6000000000095,76.94926486072012,0.1635460154804834,-2.7482076097918355
718.7000000000095,77.05945058631755,0.16499479081516571,-2.7485302560616605
719.8000000000095,77.16917107333725,0.16517121079541267,-2.749509927611557
720.9000000000095,77.28009078116182,0.16348568324267349,-2.748085259420386
722.0000000000095,77.3904336927736,0.16280978496114631,-2.7494898340509826
723.1000000000096,77.50032069521266,0.1628494698774885,-2.7552995803993867
724.2000000000096,77.609895608554,0.16401901963512144,-2.7591711009100504
725.3000000000096,77.72088433944072,0.16281449036659612,-2.75390051845978
726.4000000000096,77.83126604074819,0.15997044629342494,-2.7507735955647856
727.5000000000097,77.94012430835976,0.1593834926429818,-2.7486408651004552
728.6000000000097,78.05025674322246,0.16030979417333907,-2.7486209187516297
729.7000000000096,78.16204514931003,0.15627348085796455,-2.7514045409882897
730.8000000000096,78.27142931033917,0.1627088009932806,-2.75248580236277
731.9000000000096,78.38292330106998,0.1617244832388391,-2.7557676326383516
733.0000000000097,78.49256830869228,0.1558366543889452,-2.755661569148317
734.1000000000097,78.6028339577917,0.15576650321932503,-2.7553098256147157
735.2000000000097,78.71394651470555,0.15617875829627978,-2.754338814399424
736.3000000000097,78.82380781856773,0.15859052166429916,-2.7566486258701066
737.4000000000098,78.9348710417365,0.15609597772317832,-2.7566635256068865
738.5000000000098,79.0459963891554,0.15350292940980015,-2.7579718430595523
739.6000000000098,79.15624182260653,0.14922566792598468,-2.757956727700718
740.7000000000098,79.2670489969454,0.1478781472960346,-2.7605999559475607
741.8000000000098,79.37815863111119,0.14837840266251073,-2.76059995496421
742.9000000000099,79.48877599216954,0.14741566907689535,-2.760678455708508
744.0000000000099,79.59779460367912,0.1512934725908633,-2.7592807124173246
745.1000000000099,79.70917200414281,0.15066219995196978,-2.761852072673496
746.2000000000098,79.82001955286292,0.14834476705683672,-2.7619300243532137
747.0000000000099,79.9012045467393,0.1486350832403982,-2.7619320301899606