File: 01_Data/Face_Shield/STA/N2/10K_min/Face_Shield_STA_N2_10KData_221116_R1.csv
##Temp./Â°C,Time/min,DSC/(mW/mg),Mass loss/mg
51.0,10.439062839069441,-0.006075049290546586,-0.030815368923740927
52.100000000000016,11.00934553558852,0.051927206273056026,-0.02606510786096905
53.20000000000003,11.285362869496508,0.08383419695285399,-0.023574013093108803
54.30000000000005,11.501810489559475,0.10790757269819529,-0.02473707151625426
55.40000000000006,11.69190788505293,0.1248358954633848,-0.021782607879133664
56.50000000000008,11.867881361847617,0.13749446140607802,-0.02463338900350287
57.600000000000094,12.033308519969987,0.14773647489917074,-0.024959966029316938
58.70000000000011,12.18875894986303,0.15687112635741496,-0.027564898157245388
59.800000000000125,12.339756696588196,0.16642022450356242,-0.026548747580211085
60.90000000000014,12.485726756454875,0.17131247192126864,-0.026557328153042903
62.000000000000156,12.63043735499547,0.1764314978446735,-0.029833188353536322
63.10000000000017,12.769990803049618,0.18397110452705112,-0.030787650360821317
64.20000000000019,12.90719639253118,0.18707780297113685,-0.03023379967349893
65.30000000000021,13.042040008649357,0.19227935108333538,-0.028829715789020938
66.40000000000022,13.172924981583767,0.19477895306969328,-0.02666260476790594
67.50000000000023,13.306795608914063,0.19811661502724864,-0.02637527485416591
68.60000000000025,13.435418431288824,0.20211226403834837,-0.02534486214789755
69.70000000000027,13.565895080987213,0.20378596504780977,-0.02785299629656368
70.80000000000028,13.693887211522593,0.20984034859842393,-0.027871180024102493
71.90000000000029,13.81841050696627,0.21148508626256457,-0.02807213265745645
73.00000000000031,13.943136187831362,0.21818024381221712,-0.02754974720951342
74.10000000000034,14.067248515135267,0.2207844793751459,-0.02969693767621706
75.20000000000034,14.189170000000033,0.22472141566205894,-0.03014462368526427
76.30000000000035,14.308378537895962,0.22581404611504907,-0.027223586674820943
77.40000000000038,14.43117427281414,0.23030247019355032,-0.02668592437968975
78.5000000000004,14.550862635463604,0.23352189079207486,-0.02467119598279055
79.6000000000004,14.669347864686928,0.23473940034116725,-0.026119190050112984
80.70000000000041,14.786195077499482,0.23857515293128673,-0.02915486571887005
81.80000000000044,14.905150212758343,0.24202016916886782,-0.02836348597596494
82.90000000000046,15.02188057316217,0.24478210928456423,-0.027000001348056912
84.00000000000047,15.138650664184876,0.24776375796061234,-0.027000248181533237
85.10000000000048,15.252832071270896,0.24817418156635007,-0.02701310745601848
86.2000000000005,15.368678054734513,0.25068263356386833,-0.0256816168754197
87.30000000000052,15.484557907791313,0.2528449434804694,-0.027011251023190574
88.40000000000053,15.597159478247995,0.2544943485714779,-0.03091805485159327
89.50000000000054,15.710952068273725,0.25647174791937033,-0.030660330316565343
90.60000000000056,15.824897782570407,0.25724436467676004,-0.030712166975873423
91.70000000000059,15.936630511798272,0.25637314914104026,-0.03151356732884292
92.8000000000006,16.048575278263485,0.2577943678651934,-0.030509644006222914
93.9000000000006,16.15952458006875,0.258868707542528,-0.029190032383834108
95.00000000000063,16.270176142107896,0.25914562606118974,-0.028766126921826896
96.10000000000065,16.381455109105417,0.25991579428914513,-0.029740213167211316
97.20000000000066,16.491264909324308,0.2625267006971328,-0.030953013441389565
98.30000000000067,16.60171913610326,0.2647684096181001,-0.02963927672569877
99.40000000000069,16.710672123036566,0.2676305689902202,-0.029642108801218647
100.50000000000071,16.82009052945167,0.26670325311817533,-0.03226359930179168
101.60000000000072,16.93056288810085,0.26978037685969614,-0.030959997593914323
102.70000000000073,17.038965308300234,0.27322671673732934,-0.029646738441634568
103.80000000000075,17.148087282895315,0.2727748822869668,-0.02955925775589563
104.90000000000077,17.255134252418088,0.27881520894528644,-0.032481093013279505
106.00000000000078,17.364556980259806,0.2803229332395044,-0.031033650544076252
107.10000000000079,17.472345708677825,0.27840457749535297,-0.029739934390348388
108.20000000000081,17.580451386688022,0.2787065590181821,-0.03212595695873066
109.30000000000084,17.68755937336982,0.2820609264690571,-0.03510215719291221
110.40000000000084,17.797066801695586,0.2835033070861559,-0.030809189716949348
111.50000000000085,17.904794729509767,0.28386254870207317,-0.029646769143656826
112.60000000000088,18.01081266284569,0.2859819624554192,-0.031508026309582604
113.7000000000009,18.118887750742033,0.2865676073387513,-0.03256935550482343
114.8000000000009,18.226386024927024,0.28849651803574705,-0.032501293212177984
115.90000000000092,18.33437610826382,0.2887188387947417,-0.03072163425859742
117.00000000000094,18.442001273758045,0.29178649772535703,-0.029516938570718132
118.10000000000096,18.5497282863431,0.2929697784692833,-0.032556368554683246
119.20000000000097,18.656007113454113,0.29292893564650535,-0.0322783797696804
120.30000000000098,18.763525797136445,0.2925181260692139,-0.02831968305870003
121.400000000001,18.87006907018623,0.29428627091369475,-0.0310697449178452
122.50000000000102,18.977665713274174,0.29523384664902463,-0.03228811562549172
123.60000000000103,19.08504100563351,0.29742643281223424,-0.03390985205667274
124.70000000000104,19.19197690181061,0.3008546161607961,-0.033291409480603384
125.80000000000106,19.298367227414747,0.30007176019484383,-0.033244826529845284
126.90000000000109,19.404006445431285,0.3015344442050655,-0.0360004156417526
128.00000000000108,19.510629900390942,0.30321183240926675,-0.03732470468306204
129.1000000000011,19.618077984303163,0.30265183198818557,-0.03732005273408845
130.20000000000113,19.722204111550496,0.30561880437782807,-0.034719157336759565
131.30000000000115,19.83137871238569,0.30819198460235353,-0.03590128042148155
132.40000000000117,19.93633016435711,0.3087126074823794,-0.03190511015172515
133.50000000000117,20.04396529820315,0.3083877636221696,-0.030800162863750202
134.6000000000012,20.14801870483445,0.31107193962880164,-0.03489525491719725
135.7000000000012,20.254342471112544,0.3114014018787412,-0.036205916856568265
136.8000000000012,20.361349313482826,0.3104166990064635,-0.030497346334265707
137.90000000000123,20.46579079196191,0.31428344123112817,-0.029873341775631168
139.00000000000125,20.57132827646094,0.31752575264078753,-0.03408715702016085
140.10000000000127,20.676550782047084,0.3190399159889856,-0.0362249596909372
141.2000000000013,20.78152116782202,0.31925712860800326,-0.03889498927948054
142.3000000000013,20.886846784819024,0.3193667234884816,-0.03441531154055788
143.4000000000013,20.989171139908887,0.3219749706070214,-0.0344638327569875
144.50000000000134,21.097140985335155,0.3232048871361529,-0.03676930129626221
145.60000000000133,21.20214263183777,0.32573534722582087,-0.036687010628101646
146.70000000000135,21.305927893197076,0.3256023141508263,-0.036128047650337614
147.80000000000138,21.411503013148693,0.32576437459857344,-0.033475906745195516
148.9000000000014,21.51735109803903,0.3254720185000509,-0.032305954186989005
150.00000000000142,21.621006434568265,0.33031560516198266,-0.03345602360990174
151.10000000000142,21.72686136207094,0.32910855262423966,-0.034790105297817675
152.20000000000144,21.832086716800802,0.3286490993152128,-0.036110631166381246
153.30000000000146,21.935424465502898,0.33208684686903145,-0.03480137166896924
154.40000000000146,22.04138248358226,0.33230693978639736,-0.03397582816087841
155.50000000000148,22.1450526705635,0.33202560774245904,-0.036687528987189744
156.6000000000015,22.25089205863962,0.336451611917441,-0.0361030703341223
157.70000000000152,22.354191996139143,0.336050251113449,-0.036111108120357116
158.80000000000155,22.45772619044835,0.3389295770998848,-0.034779502504757254
159.90000000000154,22.56347384790152,0.34132876834849357,-0.03347237935801317
161.00000000000156,22.66716530076371,0.33801458557172426,-0.034915771146771135
162.1000000000016,22.771300063205274,0.340199250757255,-0.03239190999274477
163.20000000000158,22.875952959929233,0.3422192021012386,-0.03361883786258435
164.3000000000016,22.98052376509841,0.34333504175222895,-0.03616542806335765
165.40000000000163,23.083863622343134,0.34598648137479016,-0.03764865625425351
166.50000000000165,23.189522938449024,0.3446781287981821,-0.03623703994728711
167.60000000000167,23.294862107964434,0.3450647781259972,-0.03369180864877208
168.70000000000167,23.399558804144878,0.344693646542476,-0.03511554137983541
169.8000000000017,23.503827264614344,0.34529401350997624,-0.03469235859656816
170.9000000000017,23.608326705765208,0.3480343166733894,-0.036589777092373765
172.0000000000017,23.712908905851442,0.3485932158152787,-0.03863638272832315
173.10000000000173,23.81692529889346,0.3513470496588763,-0.0399372463113048
174.20000000000175,23.919357313745106,0.35075900766844026,-0.03676910323490201
175.30000000000177,24.025783790607747,0.35165740493431,-0.03643749471534008
176.4000000000018,24.129870010174336,0.3516317204544453,-0.03775939195549238
177.5000000000018,24.23560133188805,0.35463218327697205,-0.03908094220264058
178.6000000000018,24.33874936727991,0.35448998158847034,-0.04038977420989376
179.70000000000184,24.44362625649727,0.35699766425601637,-0.038048324922736576
180.80000000000183,24.547868298892972,0.3578776543272407,-0.03676882471899123
181.90000000000185,24.653272484440183,0.35727135468763227,-0.0351117426944203
183.00000000000188,24.757552872609,0.35955191906648787,-0.03414013805605709
184.1000000000019,24.859515354015926,0.3604033846681952,-0.03546426775990241
185.20000000000192,24.966938876452414,0.36082098193063816,-0.03282130770045111
186.30000000000192,25.07099488247693,0.36269205813336486,-0.03545403378383316
187.40000000000194,25.174552492095426,0.3633805471571418,-0.03541882244367933
188.50000000000196,25.279612901793282,0.36569203053744326,-0.03545484069144145
189.60000000000196,25.383383519923647,0.36995645876643224,-0.03546008000482548
190.70000000000198,25.48970495552229,0.37425138750931275,-0.03546244881351068
191.800000000002,25.591513228095508,0.37880242718760126,-0.035453172637654795
192.90000000000202,25.696595725265567,0.38227034488935124,-0.03676752466897959
194.00000000000205,25.801277947402255,0.3868760472401111,-0.03805554377813447
195.10000000000204,25.905692590688453,0.39150513622954886,-0.03940229487303171
196.20000000000206,26.00877450424224,0.39690400244376306,-0.03677188347904359
197.3000000000021,26.112992188210015,0.39985698112400103,-0.03392534397961544
198.40000000000208,26.218101148544445,0.4009505309909363,-0.03402072698436509
199.5000000000021,26.32264612057519,0.401955549640512,-0.034908857989282005
200.60000000000213,26.427239578680393,0.40337872627173665,-0.03590827186424672
201.70000000000215,26.528899174531432,0.40726107799419453,-0.03755121707276121
202.80000000000217,26.634990960258456,0.4042401631006503,-0.037173608842528516
203.90000000000217,26.740062571711885,0.4041930489468288,-0.035790063241809555
205.0000000000022,26.844497697890596,0.40440219754731965,-0.03389705264205656
206.1000000000022,26.947006686303986,0.40568253846864144,-0.034588901299618335
207.2000000000022,27.052980486690224,0.40496221189673454,-0.03858981134002182
208.30000000000223,27.156235415612535,0.40617984476079316,-0.03854358551193471
209.40000000000225,27.261196659289855,0.4067760324854794,-0.03854903355957706
210.50000000000227,27.36669690879507,0.40902008280633384,-0.039079848318573696
211.6000000000023,27.471215567776355,0.40840552928742957,-0.038993734481550746
212.7000000000023,27.576979631453376,0.4082608839312125,-0.03511734204098094
213.8000000000023,27.67926852550793,0.41193027253332676,-0.03643961479473834
214.90000000000234,27.785175990250863,0.4105772749128276,-0.03775997546053311
216.00000000000233,27.88898565519112,0.41100335313542724,-0.0381034741702404
217.10000000000235,27.99348548662173,0.41324104673025847,-0.037745901159668804
218.20000000000238,28.097951054126646,0.4114803121583774,-0.035618784549207305
219.3000000000024,28.200165961163034,0.41153978823413956,-0.033811624373528915
220.40000000000242,28.305396297170102,0.4135543275626916,-0.036766351635624694
221.50000000000242,28.409264681155165,0.41410474121516877,-0.0380899973971891
222.60000000000244,28.51384232885896,0.4158097259607397,-0.03938524102178942
223.70000000000246,28.61760501927795,0.4132517398928951,-0.03674415394608843
224.80000000000246,28.722562322232726,0.4150407588923933,-0.03738783093743692
225.90000000000248,28.826549332528202,0.41665161130137224,-0.03808005481831778
227.0000000000025,28.93068443172951,0.41494531234337106,-0.03742031992227712
228.10000000000252,29.03516320310483,0.41552333757822524,-0.038629309692354674
229.20000000000255,29.139170000000245,0.4158991299004742,-0.03873995006444364
230.30000000000254,29.24444490381294,0.41821927175008305,-0.03723539311170043
231.40000000000256,29.348443907235435,0.41818189427344615,-0.04181213422159136
232.5000000000026,29.45327369812529,0.4159988126311829,-0.040668825792695706
233.60000000000258,29.555789029931066,0.4187573216379634,-0.040687712635504525
234.7000000000026,29.66195482593757,0.415795524815541,-0.042083712660029526
235.80000000000263,29.76490703362209,0.4180729703012118,-0.03816485484820742
236.90000000000265,29.870660037530104,0.415546005967256,-0.036577716983507536
238.00000000000267,29.97617083288449,0.4197385958245253,-0.036526857186871986
239.10000000000267,30.07983771499852,0.41981754447364317,-0.03654513914361601
240.2000000000027,30.184029261307117,0.41948844292303006,-0.03681670649721358
241.3000000000027,30.28946829722881,0.41978104159224394,-0.039176930307698754
242.4000000000027,30.392276241937747,0.4215989873332463,-0.04182819791039716
243.50000000000273,30.497711885566545,0.4234171490175831,-0.03875648577992585
244.60000000000275,30.602409243442878,0.42254974636823106,-0.03624777168124371
245.70000000000277,30.70744233836212,0.4240486337701651,-0.038532834267106075
246.8000000000028,30.811696564326958,0.4228730043843799,-0.0373198146340421
247.9000000000028,30.915723282720005,0.4251955736039683,-0.03736622102834186
249.0000000000028,31.020420215842936,0.4215206493398995,-0.039950901431192065
250.10000000000284,31.123635391760455,0.42375846473422457,-0.038702894822534084
251.20000000000283,31.228842171421288,0.42024704893351383,-0.03940478487354593
252.30000000000285,31.33462427956301,0.42528924292553505,-0.03671326632990368
253.40000000000288,31.437219501721486,0.4267550994399225,-0.03482452504792022
254.5000000000029,31.541046009354208,0.4246974465066099,-0.0376690854257804
255.60000000000292,31.64581806169863,0.4271215215432441,-0.04028994276868936
256.7000000000029,31.75045417993362,0.42650440029128556,-0.03920575642313473
257.8000000000029,31.854664859848334,0.42529922746036153,-0.03809866864781242
258.90000000000293,31.958346208604254,0.42781825208061197,-0.037647168006059495
260.00000000000296,32.06293114968626,0.4290810928559991,-0.03928132088831493
261.100000000003,32.16789081857674,0.42868390909355625,-0.042136377316431606
262.200000000003,32.271694277091875,0.43013938055802603,-0.040868298796133296
263.300000000003,32.376540584140386,0.42595285729304483,-0.03514558663407552
264.40000000000305,32.48035068906364,0.4250817771217191,-0.03655129039024008
265.50000000000307,32.58517084315632,0.4270017672935055,-0.03635806259779084
266.6000000000031,32.68860898915677,0.4273733164043061,-0.03786943960298039
267.7000000000031,32.79353282763559,0.428054157318143,-0.0365481661417304
268.8000000000031,32.89527137056693,0.4279897044563187,-0.0384199562170533
269.9000000000031,33.002656092566625,0.4310141956951722,-0.038358771346575615
271.0000000000031,33.10804590335038,0.429259450656852,-0.03842004475301852
272.10000000000315,33.21214944372263,0.43080866084290265,-0.04307389571215747
273.2000000000032,33.31603811288437,0.429607807379035,-0.04445012298949713
274.30000000000314,33.42000354310388,0.4293211158245185,-0.044444014070895044
275.40000000000316,33.526001425975785,0.4269893352314592,-0.04179385891184584
276.5000000000032,33.630029176215196,0.4293588195723889,-0.039189895195724134
277.6000000000032,33.73552171603199,0.4284133810609012,-0.04037211170957633
278.70000000000323,33.839481147849185,0.4297816584946306,-0.03918910079124327
279.80000000000325,33.94460159344554,0.42807098686290884,-0.03919003396617082
280.9000000000033,34.049840614531696,0.42943216177549914,-0.040504213365958996
282.0000000000033,34.15479280503018,0.4300429448370471,-0.040500193794343
283.1000000000033,34.259888933241186,0.4327155976610916,-0.04181820405265935
284.20000000000334,34.364546407782974,0.43093258491474185,-0.039101266976175886
285.30000000000337,34.468876704333525,0.43236820365961237,-0.03722412079430715
286.40000000000333,34.57454563430336,0.43226797565029407,-0.036505510354742476
287.50000000000335,34.67948382551362,0.4305256943835332,-0.040481804926542075
288.6000000000034,34.784835603056514,0.43107249822035454,-0.04182030581368057
289.7000000000034,34.889502985269004,0.43161482075336394,-0.04313997638073985
290.8000000000034,34.993676786667464,0.4308988854496694,-0.04174862986451355
291.9000000000034,35.09897721133678,0.43257509924877696,-0.04182028765427148
293.0000000000034,35.20336309046372,0.4320620904384793,-0.04310405807511586
294.10000000000343,35.30916901925786,0.4339470591744971,-0.04443933890936691
295.20000000000346,35.41419005457505,0.4337743624544569,-0.042149985621134256
296.3000000000035,35.51935367997061,0.43242488159445813,-0.04346508911204516
297.4000000000035,35.621941649969756,0.432580047876489,-0.044767205632607165
298.5000000000035,35.72875155406659,0.4350457951600437,-0.044893211417906365
299.60000000000355,35.83424820377132,0.4336219845565899,-0.045870653942134965
300.70000000000357,35.939077080902,0.4348354835524654,-0.03897849526709862
301.8000000000036,36.044672973767895,0.43564909874617397,-0.03825235226655099
302.9000000000036,36.148073638058555,0.43656841057543894,-0.04357960870313349
304.0000000000036,36.25357985155613,0.4370483977301577,-0.043585501381321556
305.1000000000036,36.35916899150651,0.43514160481115854,-0.042258736856709334
306.2000000000036,36.46449591322531,0.4373929044937883,-0.044874446224092424
307.30000000000365,36.56812418658811,0.43807711463602717,-0.04490868745397947
308.4000000000037,36.674925261792815,0.43882348202744176,-0.0411597756395512
309.5000000000037,36.780049721374155,0.44104231440056396,-0.040939383027269294
310.60000000000366,36.88489590329697,0.4391854093253564,-0.0435812667792268
311.7000000000037,36.987626001057606,0.4433090615362151,-0.044897029767525076
312.8000000000037,37.09546243586806,0.44378994750097034,-0.04357242255188609
313.90000000000373,37.20115422442258,0.44261194072854665,-0.04643023126830137
315.00000000000375,37.305046954124435,0.44536286604712183,-0.04419766163555394
316.1000000000038,37.410502981029616,0.4434942820578112,-0.04239560711042145
317.2000000000038,37.516476756384954,0.4421718382446487,-0.041088976297409374
318.3000000000038,37.62220218208571,0.44350908355618784,-0.03974381831129925
319.40000000000384,37.72698026561987,0.4459964824267617,-0.041270149474444295
320.5000000000038,37.83254779843876,0.4437670761622966,-0.04292256936346561
321.60000000000383,37.9368763060099,0.4422986064160086,-0.04028229405076189
322.70000000000385,38.043031424931414,0.44402910997738265,-0.04027987502779862
323.8000000000039,38.14806803662598,0.44538438458377083,-0.040772580550606285
324.9000000000039,38.25578448671888,0.4480624365576753,-0.04302925842065619
326.0000000000039,38.36006670651779,0.44835551055636746,-0.045712813481353365
327.10000000000394,38.46573786000233,0.44919581486948035,-0.04697442153214837
328.2000000000039,38.57199930274163,0.44970654898932577,-0.0449626373756562
329.30000000000393,38.6777628621384,0.4535071411008475,-0.039417934169437174
330.40000000000396,38.782635171104914,0.4520797538719571,-0.03513513394214218
331.500000000004,38.888479083863885,0.4536792985319658,-0.03933095873463177
332.600000000004,38.99414777791935,0.4558608877544934,-0.041928646527668256
333.700000000004,39.10004895918542,0.45661338964013676,-0.043243542623416786
334.80000000000405,39.206749186924256,0.45795375923683046,-0.04186493400114344
335.90000000000407,39.312279391517635,0.45834966412739875,-0.04192960575084825
337.0000000000041,39.418261216479905,0.46085474046122954,-0.04258987497057021
338.10000000000406,39.52303576427754,0.4625068409193969,-0.04624614502376012
339.2000000000041,39.629377842008545,0.46188586483193467,-0.04189752981174877
340.3000000000041,39.736389160713784,0.46166655227774583,-0.04344399559433931
341.4000000000041,39.84065957038621,0.46387757591804146,-0.044790030473869535
342.50000000000415,39.947497759266064,0.46638354934446247,-0.04281761564533504
343.6000000000042,40.05272392034648,0.4657223263274157,-0.04208128182176729
344.7000000000042,40.159776100143525,0.4660470895858396,-0.04247763760399703
345.80000000000416,40.265587983855625,0.46911612183211476,-0.04378904384190552
346.9000000000042,40.371139923372716,0.47093269030302704,-0.046950896371476425
348.0000000000042,40.477669661761915,0.46991624374465363,-0.047758673986353806
349.10000000000423,40.58386875298463,0.46976341374202685,-0.046429797766673
350.20000000000425,40.6897329650619,0.4712444183674605,-0.04642980676633446
351.3000000000043,40.79648477529452,0.47005999316227565,-0.047752123372760025
352.4000000000043,40.90193438414535,0.4703817366813301,-0.04905615431951382
353.5000000000043,41.00975661573408,0.4709287303616392,-0.047640095956947626
354.60000000000434,41.11522392495005,0.47086071174981636,-0.04728374006462399
355.7000000000043,41.222113438133725,0.47073274931752773,-0.047308254282611095
356.80000000000433,41.32825015974314,0.46965475211493446,-0.04730621133854562
357.90000000000435,41.434207783131626,0.46983972400508467,-0.04731435142577567
359.0000000000044,41.54110714328628,0.47092795703321016,-0.049988868420179244
360.1000000000044,41.647123528716946,0.47179966562802506,-0.05126019639480983
361.2000000000044,41.75356754018351,0.47313576245097666,-0.049711162639400897
362.30000000000445,41.86163013455401,0.4769042231454757,-0.04698278489971397
363.4000000000044,41.96728007261991,0.47810958865243686,-0.047003775454570906
364.50000000000443,42.073458436134956,0.473960200688087,-0.049606276336183974
365.60000000000446,42.178155049208385,0.4781710683252117,-0.05153862716954949
366.7000000000045,42.28682808931016,0.479356876792295,-0.05224999168103395
367.8000000000045,42.392002092551245,0.47721542542494244,-0.052121405280144195
368.9000000000045,42.498769108988235,0.48124188332657136,-0.04830101937672371
370.00000000000455,42.60550921614508,0.4806593820169704,-0.04830124938351332
371.10000000000457,42.71232317734345,0.48064388944049563,-0.04960801054843422
372.2000000000046,42.816613764936385,0.4823931165350229,-0.05367168574913084
373.30000000000456,42.924787890296635,0.4824023488773986,-0.053801863267972205
374.4000000000046,43.03103178372835,0.4823852942393948,-0.05396740955561752
375.5000000000046,43.13819635913777,0.480739529370671,-0.05246211509560883
376.6000000000046,43.24427257355913,0.4823820458910902,-0.05378962483012728
377.70000000000465,43.350782117193624,0.4833856356622572,-0.0537897995396488
378.8000000000047,43.457251648865416,0.4830785126464177,-0.05503649068314331
379.9000000000047,43.56457928544456,0.48190699410602533,-0.05642696548631454
381.00000000000466,43.672005973014684,0.4831691053401358,-0.05707351609307221
382.1000000000047,43.77803530123863,0.4841623977775384,-0.05704785384307076
383.2000000000047,43.88409414660296,0.4828535508524151,-0.057079860038619756
384.30000000000473,43.9896986365127,0.48395616200978375,-0.05576149818124421
385.40000000000475,44.09874315109258,0.48544739995713554,-0.05707240941036629
386.5000000000048,44.20481192951591,0.48520059016519107,-0.058733996471491245
387.6000000000048,44.3127937717919,0.48163067139201304,-0.059736530124923526
388.7000000000048,44.41958520361888,0.47940569985535614,-0.05837267454607176
389.80000000000484,44.52491894836067,0.48313529137300765,-0.05807294311007549
390.9000000000048,44.633358839505696,0.4833441405110902,-0.05839999734913803
392.00000000000483,44.74052632389396,0.48277481806220096,-0.059725935271779385
393.10000000000485,44.84671133390925,0.48438185228803216,-0.06187354249986754
394.2000000000049,44.95398859172281,0.4853239217483255,-0.06404434957189453
395.3000000000049,45.061104891658935,0.48582512222453655,-0.06640468318478954
396.4000000000049,45.16792774546879,0.48442049725383285,-0.06367866057610483
397.50000000000495,45.27534954917515,0.48550744304048715,-0.05949128180885754
398.6000000000049,45.38241173215583,0.4868704483103723,-0.060938976758350805
399.70000000000493,45.48937200014165,0.48551127957280554,-0.06345010800809536
400.80000000000496,45.597062435290745,0.4847275459975951,-0.06475007367904828
401.900000000005,45.702915389137,0.4840298401262476,-0.0644029919826119
403.000000000005,45.809360601631546,0.487275431592595,-0.06675039630035196
404.100000000005,45.91748070257178,0.4869900746923951,-0.06674948150339866
405.20000000000505,46.024723822635416,0.4883573110003596,-0.06541806044157372
406.30000000000507,46.131472593972,0.48640723863348423,-0.06443949245744962
407.4000000000051,46.237610470060126,0.4903492734371084,-0.06889483859688017
408.50000000000506,46.34598827836027,0.4903009660721753,-0.07202619658211828
409.6000000000051,46.450873707797854,0.4882082651896683,-0.06882903497292636
410.7000000000051,46.55875444434538,0.4877237745070405,-0.06619151132660361
411.8000000000051,46.66833652259987,0.4883118084958355,-0.06751016951024669
412.90000000000515,46.774510253254576,0.48630668036822056,-0.06892690907214183
414.0000000000052,46.88329104037292,0.4874416257507735,-0.07332332274167808
415.1000000000052,46.990672314842016,0.4876810421453493,-0.07429010291766414
416.20000000000516,47.09738552560087,0.4894339457829322,-0.07563483693446527
417.3000000000052,47.205226292247495,0.49116090588157,-0.07431295512660085
418.4000000000052,47.312731295139514,0.4933022437938804,-0.07298572861181807
419.50000000000523,47.4204483697825,0.49251251983596034,-0.07300392102138842
420.60000000000525,47.5282819296707,0.49122286664563153,-0.07301088629994101
421.7000000000053,47.63524380818133,0.492112684321389,-0.07704392290408402
422.8000000000053,47.74089918638735,0.49412125135977664,-0.07957989944302879
423.9000000000053,47.8505944763395,0.4920567945502835,-0.08192194458215152
425.00000000000534,47.9573948864644,0.492011926365863,-0.08135614310148176
426.1000000000053,48.06452398849504,0.49132384631721426,-0.0812297099792163
427.20000000000533,48.172163983509094,0.4901510181616102,-0.08192082959817926
428.30000000000535,48.27927188954655,0.4920961013432394,-0.08299939533662215
429.4000000000054,48.38725640597893,0.4944239320694314,-0.0843532017275681
430.5000000000054,48.492884025293534,0.4939532883231909,-0.08825827448932344
431.6000000000054,48.60213218854269,0.49294536827344515,-0.08760141310444647
432.70000000000545,48.709169020747495,0.49340231564435255,-0.08784453901122902
433.8000000000054,48.81726168842077,0.49231289930431593,-0.08759943702523332
434.90000000000543,48.92537019638115,0.49368476309674647,-0.09160998184068792
436.00000000000546,49.030996485656964,0.4949530833857469,-0.0900185805595406
437.1000000000055,49.139893993924495,0.49441006287290784,-0.08573421200662956
438.2000000000055,49.24498921668227,0.4959482108462501,-0.08739703249299113
439.3000000000055,49.35515656733963,0.4987776036670246,-0.09033693278935839
440.40000000000555,49.461986155000154,0.49921782803130155,-0.09445292584906628
441.50000000000557,49.56970245101667,0.5016093505021895,-0.09848749353759478
442.6000000000056,49.67686288177907,0.504701499926721,-0.1020428295570186
443.70000000000556,49.785012647876705,0.5055524654853938,-0.10467036736227442
444.8000000000056,49.891698838524455,0.5067134873561823,-0.10767195579264133
445.9000000000056,50.00015344019309,0.5075902799725601,-0.1075437840372584
447.0000000000056,50.1080266439964,0.5089626113769179,-0.10467188511009562
448.10000000000565,50.213602469551574,0.5084915477978978,-0.10694476784705476
449.2000000000057,50.32277754313748,0.5110070324635485,-0.11280104987145112
450.3000000000057,50.43016376935443,0.5145956511368913,-0.11710542552641234
451.40000000000566,50.538162664651125,0.5168575085314635,-0.12065127148990218
452.5000000000057,50.64650494020982,0.5205733980585008,-0.12477388094638009
453.6000000000057,50.75418850752007,0.5246487953294823,-0.12750481321517304
454.70000000000573,50.862522391949824,0.5271722966658888,-0.13023931560197477
455.80000000000575,50.96970251836573,0.5334948407282832,-0.13603497085809302
456.9000000000058,51.07753801246069,0.5375977808875073,-0.13890135342633902
458.0000000000058,51.18588554448388,0.5427230503753918,-0.14406149139562574
459.1000000000058,51.29398296037662,0.5498449652432522,-0.14964845573996222
460.20000000000584,51.40168104772425,0.5561374913169462,-0.1559102860473951
461.3000000000058,51.50937884868452,0.5628385205835204,-0.16374361559601835
462.40000000000583,51.61821276010496,0.5701545106987519,-0.17410433920577484
463.50000000000585,51.72619839544039,0.5793057128041321,-0.18050706138210915
464.6000000000059,51.83308875633494,0.5877629358586587,-0.1890624763153701
465.7000000000059,51.94102874224524,0.5945748679270824,-0.18676479494093723
466.8000000000059,52.048704745591245,0.6067929312811797,-0.1978485689599827
467.90000000000595,52.156546234816695,0.6211517734572274,-0.21397241562592395
469.0000000000059,52.2648885093253,0.630891837093475,-0.220629761724064
470.10000000000593,52.37222946657238,0.6458088395345674,-0.23436754616020083
471.20000000000596,52.48050926417805,0.6568042244986422,-0.24952877107449867
472.300000000006,52.58843211389053,0.672732999264114,-0.2647930536947505
473.400000000006,52.69647030105053,0.685927005760479,-0.2771479177940739
474.500000000006,52.804289960883395,0.7001942745265404,-0.28801407563302783
475.60000000000605,52.91369371097575,0.7147984136352163,-0.3105122220945744
476.70000000000607,53.02100694942447,0.7316216517666322,-0.3309248013170212
477.8000000000061,53.12938618311577,0.7509799702476514,-0.354309575825154
478.90000000000606,53.23826602596365,0.7735255742867443,-0.3815997470122112
480.0000000000061,53.34593771008824,0.7949012589386146,-0.4095368181533421
481.1000000000061,53.45414738853808,0.8182209617377438,-0.4316387723698316
482.2000000000061,53.56299434317942,0.8413017553312546,-0.4562691845894298
483.30000000000615,53.67142299466487,0.8684634723048033,-0.4961593354466207
484.4000000000062,53.77956478045232,0.9002025223891645,-0.5351048094226298
485.5000000000062,53.88660644491167,0.9286372660669586,-0.5736171662660916
486.60000000000616,53.99604436953848,0.9593289052976165,-0.6171285282970675
487.7000000000062,54.104303604838314,0.9896859789595591,-0.6612925103482947
488.8000000000062,54.212719664591944,1.017596780817196,-0.7109910660768017
489.90000000000623,54.3206215372017,1.044339501966154,-0.7617242363716143
491.00000000000625,54.42886082091725,1.071047937072808,-0.8203798339564905
492.1000000000063,54.537160547296686,1.0953671682274728,-0.8823532744831484
493.2000000000063,54.64694295966139,1.1145415896662878,-0.949651874901547
494.3000000000063,54.75624891960467,1.1308599075790853,-1.0179550551248515
495.40000000000634,54.86284141157159,1.1434796356303005,-1.0904630224467593
496.5000000000063,54.97260050381106,1.149520619053683,-1.1631067760928175
497.60000000000633,55.082135425468834,1.1486510464962825,-1.2406285455560226
498.70000000000636,55.19018298532081,1.1391391574883003,-1.318336464534212
499.8000000000064,55.298588797018525,1.1215224484796367,-1.39622561656808
500.9000000000064,55.40639913499172,1.0993044321310825,-1.4737020569594677
502.0000000000064,55.515562526803144,1.0643197054204345,-1.55015293014318
503.10000000000645,55.62390663825334,1.025436703896002,-1.6255610924185904
504.2000000000064,55.73225316492401,0.9785549540122105,-1.7018138955172155
505.30000000000643,55.83999267474838,0.9265488387924964,-1.7712909995322996
506.40000000000646,55.94803305014831,0.8713747728160457,-1.8360250398538511
507.5000000000065,56.05640689844004,0.8127655102429105,-1.898187526848388
508.6000000000065,56.16477016979174,0.7562296888276909,-1.953920178499854
509.7000000000065,56.27231781149629,0.702747012592225,-2.002265769129572
510.80000000000655,56.38067456057884,0.6568529946212116,-2.04969990875156
511.90000000000657,56.488259255824566,0.6113971368210511,-2.091937691400928
513.0000000000066,56.5965307123107,0.573445117333809,-2.134555518538729
514.1000000000065,56.70468868668353,0.5381493747271356,-2.172373867796659
515.2000000000066,56.81280868319037,0.5069627234001555,-2.2018463305320735
516.3000000000065,56.92067331669726,0.4820708006732059,-2.232522907604225
517.4000000000067,57.02771290718935,0.45823856097971394,-2.2621165469039473
518.5000000000066,57.13782483016744,0.4375016790266501,-2.288129520379739
519.6000000000067,57.245658419396115,0.41740790991929705,-2.312749140158165
520.7000000000066,57.35466861913419,0.3961864264080879,-2.3375797871095516
521.8000000000067,57.46228241823311,0.37831232494921974,-2.3581609022014205
522.9000000000067,57.57164556682831,0.3621346934406812,-2.375545650702835
524.0000000000067,57.67724992154072,0.34734077955543813,-2.393889570570647
525.1000000000067,57.78871785598923,0.33227814607595485,-2.4096616118055287
526.2000000000068,57.89727774149188,0.31561312872254277,-2.4262891239064897
527.3000000000068,58.00544329768406,0.3030323184098366,-2.445274676189219
528.4000000000068,58.11391131386429,0.30488101624920755,-2.457715608267018
529.5000000000068,58.22337783132883,0.291743067388445,-2.4708111403616924
530.6000000000068,58.33109631398138,0.2806985403897245,-2.4857092258916285
531.7000000000069,58.440305090532995,0.2768081779500597,-2.4975357255805513
532.8000000000068,58.548138199510916,0.2662917572979436,-2.5073189519243115
533.9000000000069,58.657418370290934,0.2618751668781314,-2.519140542509132
535.0000000000068,58.76517778014086,0.2579803137597984,-2.5296018229779995
536.100000000007,58.8740718015725,0.2509021321825934,-2.5387515218203807
537.2000000000069,58.98283924151664,0.24460828719014605,-2.5498811194328224
538.300000000007,59.0913998903688,0.24611760103909955,-2.5576197225783135
539.4000000000069,59.19964729558345,0.23735536102591892,-2.5673030283867595
540.5000000000069,59.309455582152076,0.23103923593901834,-2.572442198139978
541.600000000007,59.41689918591601,0.22647928280936103,-2.5843723434211796
542.700000000007,59.52638915522296,0.21996492866676942,-2.593053513197542
543.800000000007,59.63470452039632,0.21489738245725923,-2.6002433565468075
544.900000000007,59.74254324337242,0.21186231758885246,-2.606576700893268
546.000000000007,59.852833351886254,0.20726476568425864,-2.615419507318613
547.1000000000071,59.961148670583896,0.20766086975713904,-2.6213834464974015
548.2000000000071,60.06946204408925,0.206007128471996,-2.6250315952166003
549.300000000007,60.178516129670456,0.20388538221387212,-2.631384593741461
550.4000000000071,60.287183669944326,0.20279950814660808,-2.6376129734985305
551.500000000007,60.395667257360685,0.2022893997662888,-2.6421223526445696
552.6000000000072,60.5033211692189,0.20314295165223797,-2.6498248992961937
553.7000000000071,60.612599696199645,0.20212966411259375,-2.6530715360337016
554.8000000000072,60.72198754525175,0.20378589942764555,-2.6579129650464006
555.9000000000071,60.82858104359213,0.2031608410741077,-2.663858974717159
557.0000000000072,60.93820752157616,0.20132629150939624,-2.667199051919611
558.1000000000072,61.046807391034406,0.20415404723486655,-2.6762380428671126
559.2000000000072,61.15605530595967,0.20309589553390722,-2.6844239374709717
560.3000000000072,61.26540892374459,0.20404956801291843,-2.688711356658993
561.4000000000073,61.37339589692389,0.20695532616211026,-2.692049338829306
562.5000000000073,61.4820275024566,0.2076222128165563,-2.6919858450375873
563.6000000000073,61.591096314218426,0.20854419356743484,-2.7000588430127697
564.7000000000073,61.69970697990131,0.20416289790212888,-2.7019809993346167
565.8000000000073,61.80886844739437,0.20690228640069636,-2.7037237977772293
566.9000000000074,61.918072493568,0.2102823955059511,-2.709350141205554
568.0000000000074,62.025579454700846,0.21134715367928858,-2.715238531485121
569.1000000000074,62.13635770133295,0.21097586904471968,-2.718105277196581
570.2000000000073,62.244035849111796,0.2024524800421271,-2.7218021117517184
571.3000000000073,62.35328797550004,0.17734848127241754,-2.7262280469314684
572.4000000000074,62.45985574310305,0.16011585264324213,-2.7308471870998448
573.5000000000074,62.57056427422172,0.1521294068157063,-2.735913018994274
574.6000000000074,62.679666414680824,0.13770569497577906,-2.7392287864045577
575.7000000000074,62.788787556287936,0.12800821713523527,-2.742383539380448
576.8000000000075,62.89787803100601,0.1282668415259403,-2.7432299156909945
577.9000000000075,63.00699603850809,0.1274082219075472,-2.7470436293853067
579.0000000000075,63.115539553803096,0.12599725002643739,-2.752031157654787
580.1000000000075,63.224595193330245,0.12600932553262864,-2.7536329653144724
581.2000000000075,63.33417326823512,0.12720998280131204,-2.7584811590184852
582.3000000000076,63.4446374130047,0.12656091322720786,-2.761165425431139
583.4000000000076,63.5519469810058,0.12649430033732104,-2.7656171165761347
584.5000000000076,63.66259704341969,0.1276419318055506,-2.7699412435047748
585.6000000000076,63.77250328204322,0.12843616302933342,-2.771623728353926
586.7000000000077,63.8814838574536,0.12813975302321168,-2.775501886058744
587.8000000000077,63.991943057119684,0.12150580453758436,-2.7771950856472296
588.9000000000076,64.10041226294956,0.10533785485654959,-2.777059439033583
590.0000000000076,64.20954474854024,0.09918736867182079,-2.781784037117631
591.1000000000076,64.318991176056,0.09498455652113058,-2.782670021179549
592.2000000000077,64.4284590404628,0.0947421703101784,-2.7866777875135122
593.3000000000077,64.53813401208369,0.0938766111463995,-2.791297807375613
594.4000000000077,64.64795082310073,0.07921763666961157,-2.796989104602307
595.5000000000077,64.75773220903699,0.0755716243998438,-2.7975426278297766
596.6000000000078,64.86692060152804,0.09663577081339877,-2.7989101220711397
597.7000000000078,64.97676246446672,0.10920135261507363,-2.8006964213077223
598.8000000000078,65.08543802870005,0.11803457579831192,-2.8028728644849332
599.9000000000078,65.19598959299412,0.12211813330263893,-2.804324238456961
601.0000000000078,65.30646923341618,0.12505971851462658,-2.80646543292574
602.1000000000079,65.41481557181517,0.1303651857097463,-2.8108889516366364
603.2000000000079,65.52520773056182,0.13499193489503825,-2.8109459840964126
604.3000000000079,65.6345911732259,0.1356143730825653,-2.8107640005548236
605.4000000000078,65.74477531403484,0.13936534288309035,-2.8139300899895843
606.5000000000078,65.8549358118718,0.14164052955381282,-2.8179105640710294
607.6000000000079,65.96408234399482,0.14621338798421996,-2.820533658501085
608.7000000000079,66.07403342743103,0.1419809285290442,-2.8217371791863375
609.8000000000079,66.18417143993827,0.1417135878518246,-2.8191236808296782
610.9000000000079,66.29378174989897,0.14572587873023415,-2.819109212945154
612.000000000008,66.40378902110328,0.14448389392915886,-2.824978118968028
613.100000000008,66.51236138367211,0.15063368334982088,-2.8340685070128413
614.200000000008,66.62238960569728,0.1512771778009612,-2.8332825949780513
615.300000000008,66.7328888589935,0.1535656971692561,-2.831152803779773
616.400000000008,66.8430518222349,0.15544194697516472,-2.8283481185048465
617.5000000000081,66.95334914182091,0.15710492398676074,-2.828273049846977
618.6000000000081,67.06285300761992,0.15796912005781433,-2.8367719564818232
619.7000000000081,67.1730800648752,0.1641572829691269,-2.840725805842628
620.8000000000081,67.28355625888534,0.16588540651288808,-2.83727604694681
621.9000000000082,67.39311791527778,0.16906390832816917,-2.8376604030827846
623.0000000000082,67.50256741479383,0.17534340210944588,-2.837937536820854
624.1000000000081,67.61224617620844,0.18114071150236621,-2.844025989655666
625.2000000000081,67.72222042214621,0.18162486815734546,-2.8443105666384705
626.3000000000081,67.83100651135376,0.18694807862010465,-2.8468896172988427
627.4000000000082,67.94133084630987,0.18848758043555713,-2.846890059551593
628.5000000000082,68.05026285981732,0.19303942977753966,-2.8477780226594875
629.6000000000082,68.15964244664464,0.20272702248192281,-2.8502269687531303
630.7000000000082,68.268971715426,0.20126655646538733,-2.8496301168813467
631.8000000000083,68.37906645834569,0.21071559026178108,-2.849626452302227
632.9000000000083,68.48804481174508,0.21742963618970051,-2.8522554258135435
634.0000000000083,68.59752844593643,0.22223718021031214,-2.8512975234572204
635.1000000000083,68.70753838296436,0.22861697561822336,-2.853954317515562
636.2000000000083,68.81665085163044,0.23030662223428433,-2.855241450933562
637.3000000000084,68.92535383316668,0.23204308278711092,-2.8587437698172677
638.4000000000084,69.03564672681883,0.23290548317654297,-2.8618219913486107
639.5000000000084,69.144031539398,0.2347435394482406,-2.8617306730775782
640.6000000000083,69.25381442028696,0.23819945703816148,-2.8630685111041267
641.7000000000083,69.3610585048254,0.238909499137228,-2.864061840493157
642.8000000000084,69.4736678142331,0.23526816421462052,-2.861381919013448
643.9000000000084,69.58066363490501,0.23951601436980213,-2.861165162933867
645.0000000000084,69.69002438198441,0.2409478517748782,-2.8636388520832106
646.1000000000084,69.80048644983802,0.2439597292075074,-2.86378961225129
647.2000000000085,69.91196050494362,0.2470721638090735,-2.8638026709918654
648.3000000000085,70.02158395637275,0.251906645217546,-2.865110140535351
649.4000000000085,70.13061110101026,0.25025555061528004,-2.8651064457079576
650.5000000000085,70.24160790461465,0.251851514980303,-2.8657453482500914
651.6000000000085,70.35029204863604,0.25411208801141877,-2.8708715594089456
652.7000000000086,70.46090707945623,0.2531084647198221,-2.8721398834287575
653.8000000000086,70.56989112626385,0.252930565943388,-2.873459121005909
654.9000000000086,70.68066667000707,0.25898776560561715,-2.8747612571267305
656.0000000000086,70.78840391019344,0.25255783469755205,-2.8734498648845235
657.1000000000087,70.90002834513145,0.2538816337647874,-2.8747286171254443
658.2000000000087,71.00817228739065,0.2516236064291506,-2.8815605209660076
659.3000000000086,71.11945978488514,0.2514374295148901,-2.8749813318878585
660.4000000000086,71.22895651740895,0.2516549820389947,-2.878762683123158
661.5000000000086,71.33874756431413,0.2539734327058443,-2.8787300895105927
662.6000000000087,71.44873182921047,0.25371908833406237,-2.8779372470361313
663.7000000000087,71.55936117617225,0.24812766593216987,-2.8773004707451593
664.8000000000087,71.6694021151256,0.24949772005157722,-2.879086798374657
665.9000000000087,71.77849818946282,0.2516644698307019,-2.883119956671015
667.0000000000088,71.88845704562736,0.24891645944861615,-2.8817051525929607
668.1000000000088,71.99945567376963,0.2511419497487645,-2.8754176401375413
669.2000000000088,72.10916910859493,0.25411824451379594,-2.8780655258737244
670.3000000000088,72.2177046206639,0.25767651981741413,-2.883309142701033
671.4000000000088,72.32955369249714,0.25968032299032107,-2.8852422012484142
672.5000000000089,72.43936421798414,0.2573739663779649,-2.885859154006252
673.6000000000089,72.5504164230485,0.25367495627478004,-2.8848872804208003
674.7000000000089,72.65926920594234,0.2582299787189579,-2.8889576848464618
675.8000000000088,72.76958008893827,0.2537030317160581,-2.888268828203019
676.9000000000088,72.88026817598526,0.257165558504643,-2.8885400865957243
678.0000000000089,72.99019217296419,0.256673452400025,-2.8893201311910826
679.1000000000089,73.09847693729728,0.25510906963348445,-2.886861312503515
680.2000000000089,73.20865089325652,0.2585079297432867,-2.8858614610656623
681.3000000000089,73.31839025571075,0.26237767387621064,-2.887631950120673
682.400000000009,73.43070867454426,0.2536930292368846,-2.8924464967282306
683.500000000009,73.54117681246632,0.2364400229655707,-2.8950770957991603
684.600000000009,73.65089888441003,0.22243848019930304,-2.893760193283908
685.700000000009,73.76016651396462,0.2232175174924302,-2.893775592934521
686.800000000009,73.87003028638134,0.22301879774495068,-2.896423805252967
687.9000000000091,73.98002840952272,0.22411898281785808,-2.8967582652638932
689.0000000000091,74.08917000000092,0.21644367445962157,-2.8961550271079983
690.1000000000091,74.20079433545921,0.21181200373031506,-2.89457433522282
691.2000000000091,74.30983049659916,0.20828610432121675,-2.8926570451893463
692.3000000000092,74.42104167003755,0.21155982042184268,-2.8904758149892276
693.4000000000092,74.5296866657829,0.20903644437102065,-2.89321927892325
694.5000000000091,74.64027661302026,0.2086361961110342,-2.894548818253476
695.6000000000091,74.74955967929618,0.20644654659475326,-2.8972718425244626
696.7000000000091,74.86152548249372,0.2087252074767966,-2.899906976169902
697.8000000000092,74.97082687424218,0.20816943938679033,-2.901230129429563
698.9000000000092,75.08283721578866,0.21041551465859096,-2.9012309871762185
700.0000000000092,75.19119810097527,0.20891725037776257,-2.901231193585056
701.1000000000092,75.30276610249457,0.21142342073632023,-2.901264943111217
702.2000000000093,75.41243391860762,0.20902973945152792,-2.899910032105894
703.3000000000093,75.52265485849608,0.2050672170129761,-2.9011743281147764
704.4000000000093,75.63357122165849,0.20478754635035035,-2.90535647454944
705.5000000000093,75.74367456636166,0.2040322267038156,-2.9039579454161166
706.6000000000093,75.8527295611646,0.20745338424938845,-2.901232267007444
707.7000000000094,75.96376991515493,0.21092164966743226,-2.89990999314651
708.8000000000094,76.07492626034346,0.21428441197803527,-2.9041103019898067
709.9000000000094,76.18491573180698,0.2178049979378338,-2.9055099388415266
711.0000000000093,76.2955343810698,0.2205033377631197,-2.905941081898198
712.1000000000093,76.40526671135795,0.21983588051943262,-2.9044337779031197
713.2000000000094,76.51833096449597,0.22073141163984739,-2.9028891189242927
714.3000000000094,76.62937632633458,0.22179795547951842,-2.905535338377902
715.4000000000094,76.73797808265144,0.22649964367640144,-2.905520406294001
716.5000000000094,76.85012343555817,0.22720252113809652,-2.904933328823814
717.6000000000095,76.96091759668796,0.22827758259405365,-2.907248322107747
718.7000000000095,77.07046710764791,0.23249233091560695,-2.912100158770429
719.8000000000095,77.1817258769047,0.2366503599765864,-2.913969314710036
720.9000000000095,77.29245385004491,0.2369481310697314,-2.912649815327052
722.0000000000095,77.40260246873272,0.23982543432600456,-2.9127001968970228
723.1000000000096,77.51160081546372,0.24271774895772064,-2.9139356367149345
724.2000000000096,77.62401674566006,0.24787909913252656,-2.9148370673004087
725.3000000000096,77.7332643176191,0.24803911110842114,-2.9148646028395246
726.4000000000096,77.84252498829218,0.24911048772858008,-2.9158250094717393
727.5000000000097,77.95349784242359,0.256345015206054,-2.9168721123222006
728.6000000000097,78.06302056161029,0.2569776264101499,-2.918139870804853
729.7000000000096,78.17381598627952,0.25853602870682924,-2.9167937484622373
730.8000000000096,78.28398112090746,0.2607313987295163,-2.9151093655690663
731.9000000000096,78.39392366902848,0.2646937765972154,-2.918028643214527
733.0000000000097,78.50531309593802,0.26725327012437805,-2.918363086964834
734.1000000000097,78.61530754518962,0.2710815669838077,-2.9193501347316433
735.2000000000097,78.72477191980816,0.2716480081717098,-2.919350194195289
736.3000000000097,78.83538496947074,0.27594623632380855,-2.921277286184152
737.4000000000098,78.94610058297147,0.2766145496203172,-2.9227868414235267
738.5000000000098,79.05619518529683,0.2815964590866359,-2.920334915057844
739.6000000000098,79.1673227934011,0.2800684822349616,-2.920403301562615
740.7000000000098,79.27725013314488,0.2834037367578902,-2.920352430621482
741.8000000000098,79.3877269330833,0.2846403349939165,-2.9216503490997927
742.9000000000099,79.49855358770101,0.28393713573592655,-2.923299653259404
744.0000000000099,79.60869355108402,0.28670739727456634,-2.921975472764495
745.1000000000099,79.72026810008283,0.291615478446978,-2.9197471336069394
746.2000000000098,79.8306096453071,0.29473641313566645,-2.9219773678304306
747.0000000000099,79.91071121988435,0.2945599486123544,-2.923290065372111