File: 01_Data/Concrete_Block/STA/N2/3K_min/Concrete_Block_STA_N2_3KData_230831_R1.csv
##Temp./Â°C,Time/min,DSC/(mW/mg),Mass loss/mg
29.0,16.400751462350577,0.012283046910742002,0.005225727456186213
30.40000000000002,17.08000000000001,0.02009270220826176,0.004619624353383145
31.80000000000004,17.65816768857909,0.022651417142862673,0.005938041205943101
33.20000000000006,18.205193157154348,0.02635412766628642,0.0055881567196500725
34.60000000000008,18.732482961878418,0.026995436853301413,0.0042813129407850425
36.0000000000001,19.267286441022843,0.03228468387692507,0.0055817257703729695
37.40000000000012,19.77193530068658,0.033520400830840735,0.005590176529758573
38.80000000000014,20.263411087776497,0.0354528430794141,0.003721960766944754
40.20000000000016,20.764050359996386,0.036142559593622,0.004942322570015811
41.60000000000018,21.25227131383156,0.0393770436555374,0.005323274204116046
43.0000000000002,21.736730538006952,0.04050688691844906,0.003945274428739154
44.40000000000022,22.216848014151985,0.04154628372811153,0.003949899988886507
45.80000000000024,22.700267977175162,0.041887551839063786,0.003958613659062138
47.20000000000026,23.18160982363648,0.04723829101865018,0.00394386376822542
48.60000000000028,23.66039496797906,0.047214479220596406,0.0017157163694196953
50.0000000000003,24.130000000000138,0.04581550530540346,0.003299969995291363
51.40000000000032,24.608440379068043,0.04591407130325287,0.0009894198479658556
52.80000000000034,25.071255774049323,0.04533601901481488,1.7199999913231068e-07
54.20000000000036,25.546672583410754,0.04699958501215784,3.0893194553627268e-06
55.60000000000038,26.021209500478264,0.04721516707805584,-0.00026259750814983107
57.0000000000004,26.493239718384128,0.04704859189811472,-0.002190047382063298
58.40000000000042,26.951482297031905,0.046334722983382814,-0.0035098171685348234
59.80000000000044,27.43258588846644,0.04731097252942851,-0.0035636899829967206
61.20000000000046,27.89705528603709,0.049046757727317924,-0.004830331777799124
62.60000000000048,28.377001036872482,0.04830447042964314,-0.0051599700256605985
64.0000000000005,28.839807519226355,0.04883248308944266,-0.005819955355904405
65.40000000000052,29.320000000000242,0.04779302924233475,-0.005810564967172027
66.80000000000054,29.78288469475954,0.04907649364358946,-0.005159767303615226
68.20000000000056,30.248877913397937,0.048010674142959786,-0.00811515202213453
69.60000000000058,30.716006063270825,0.04874278104363272,-0.007830505547064881
71.0000000000006,31.187323541386856,0.04850136630267965,-0.009220064286655116
72.40000000000062,31.653857737976644,0.0485243123747825,-0.009485889103912015
73.80000000000064,32.12311742298599,0.048327394832206494,-0.008572992316008055
75.20000000000066,32.5881345728503,0.046411705230875455,-0.011200183185557933
76.60000000000068,33.05079652718863,0.046878264486131194,-0.012190141990793713
78.0000000000007,33.512085000693666,0.045900410366499056,-0.013169663236941354
79.40000000000072,33.993392178748756,0.04380605171130014,-0.012179974042819453
80.80000000000074,34.459367722278856,0.04518953021573058,-0.012839932303492674
82.20000000000076,34.92805598870518,0.04424850401700198,-0.01300029046764628
83.60000000000078,35.39497422280211,0.0431278622033644,-0.014160046500232504
85.0000000000008,35.857166434146755,0.040431760772529746,-0.013507438366401558
86.40000000000082,36.31649033276564,0.040082789654746875,-0.01514950502016621
87.80000000000084,36.78760014507131,0.04278719362164596,-0.0158094825287165
89.20000000000086,37.25645666777396,0.04082445992979,-0.015355445059438644
90.60000000000088,37.71922567300165,0.040900142439421305,-0.016689790484990752
92.0000000000009,38.183149487961,0.0416540564790413,-0.018003862271500637
93.40000000000092,38.64624200053822,0.04176887484594016,-0.01767999541399856
94.80000000000094,39.11169755416564,0.04057559540175859,-0.01967890636659675
96.20000000000095,39.57000000000013,0.04306990145376033,-0.020815927226412345
97.60000000000097,40.03751588908447,0.04055348874107523,-0.01964982800000037
99.000000000001,40.492307193078354,0.04232898669259377,-0.018660101483605196
100.40000000000101,40.96224909689503,0.042748599012856436,-0.020036415547547204
101.80000000000103,41.42362466766712,0.040741596098597066,-0.021298684979586202
103.20000000000105,41.889227862309724,0.03868795541331438,-0.022620269401848248
104.60000000000107,42.3480152649336,0.03653923877831211,-0.021132570218610702
106.0000000000011,42.810000000000414,0.036484114485272556,-0.02094587623111055
107.40000000000111,43.271405338190924,0.03971714541417848,-0.023599450191198912
108.80000000000113,43.73251130095976,0.03644915909854207,-0.022290051011701895
110.20000000000115,44.19373993282523,0.03618091966382697,-0.023255313894788632
111.60000000000117,44.65232461367594,0.035448300930191357,-0.022294700780570498
113.0000000000012,45.115414558820746,0.03470701045250357,-0.024918598796420888
114.40000000000121,45.575748821089036,0.03469159578382719,-0.02510289523793441
115.80000000000123,46.040682800705056,0.035234049737521866,-0.02319962213499016
117.20000000000125,46.502197887728144,0.035118299562639566,-0.023820159363074467
118.60000000000127,46.96265809846186,0.03459069838548867,-0.024150392477027882
120.0000000000013,47.421893106892654,0.03208305821613777,-0.024150034211225524
121.40000000000131,47.88472122728324,0.032406224710169074,-0.024810230371319353
122.80000000000133,48.33987195518312,0.032293819807260205,-0.024579715476559016
124.20000000000135,48.80138504334423,0.03237515013559067,-0.02316987929643144
125.60000000000137,49.261969865504874,0.03145988915785858,-0.02480991599999882
127.00000000000139,49.71957812475048,0.03180872381766786,-0.024482606704747667
128.4000000000014,50.168862576399206,0.03307131001691399,-0.026460192000000937
129.80000000000143,50.63629290641956,0.03008166371414589,-0.026460191973152192
131.20000000000147,51.09563011069514,0.02996274028011281,-0.02712010801490461
132.60000000000147,51.54993296034351,0.030989421609433743,-0.025803418834684066
134.00000000000148,52.017644330451965,0.02964600222126812,-0.028430107999139143
135.4000000000015,52.47833808288873,0.028078401514201046,-0.02876012487341706
136.80000000000155,52.93934021528567,0.028083755684065403,-0.026790024843751592
138.20000000000155,53.39769795963419,0.028678045080399617,-0.02711397933462134
139.60000000000156,53.8541348243267,0.027300341660541516,-0.027439897999999463
141.0000000000016,54.30950290510147,0.027470750364064545,-0.028599126707438582
142.40000000000163,54.764978999057206,0.028583743309507303,-0.028749012166628063
143.80000000000163,55.22305495543768,0.026586255504514877,-0.028429852783836473
145.20000000000164,55.68000000000088,0.027555921233377134,-0.029749855999998243
146.60000000000167,56.13976411652712,0.026903467890806665,-0.0283518857797036
148.0000000000017,56.59664747194874,0.02616753501710578,-0.029099491178499193
149.4000000000017,57.03255543099307,0.02464398766766651,-0.02910069750222055
150.80000000000172,57.51128229990761,0.025414582794545115,-0.02910006703628909
152.20000000000175,57.96227277640462,0.024762776800729247,-0.03041005599999913
153.60000000000178,58.41754454323525,0.024940287690452978,-0.0304110292165527
155.0000000000018,58.874329000621316,0.026202789161076545,-0.03049885632770888
156.4000000000018,59.33137461815556,0.02616791533398044,-0.03041029421309238
157.80000000000183,59.789571016883954,0.02511277489284125,-0.03137959179287808
159.20000000000186,60.2518345230358,0.02906370432328398,-0.033050090813240285
160.60000000000187,60.70474275385747,0.02636975895115179,-0.03173017584452431
162.00000000000188,61.16106062870853,0.023060129769467697,-0.033966316130435104
163.4000000000019,61.624363361125546,0.02342930131770493,-0.0313998576869543
164.80000000000194,62.07441793342332,0.023352385516394847,-0.033006563245810305
166.20000000000195,62.53220834310986,0.025925161143348863,-0.03188766736298465
167.60000000000196,62.99170436009676,0.02411869230026964,-0.03288215461963162
169.000000000002,63.44296788195639,0.023549255759205412,-0.03292842871592505
170.40000000000202,63.896767634008874,0.024197702563550694,-0.03425005412368343
171.80000000000203,64.34598558602323,0.02277207911361656,-0.03297195013476184
173.20000000000203,64.79363054086915,0.026550224668814737,-0.031609996027501364
174.60000000000207,65.26345070171267,0.02831269054771135,-0.03424993180321412
176.0000000000021,65.7212802034293,0.0269478886323562,-0.03457560806965354
177.4000000000021,66.17454258922463,0.0270874447618914,-0.033260163983688695
178.80000000000211,66.63191675777159,0.025595995628301615,-0.034580672829490844
180.20000000000215,67.10624844880357,0.02646686160970857,-0.03490981458427456
181.60000000000218,67.54117553590721,0.022953606636585855,-0.03590007936634043
183.0000000000022,67.99882458880785,0.026163059765843544,-0.03556933628594727
184.4000000000022,68.4513348353062,0.028246364007190605,-0.0342501215776454
185.80000000000223,68.90940422587695,0.027520626293275674,-0.0362311511859712
187.20000000000226,69.361117979442,0.02840862650258491,-0.03525154071852299
188.60000000000227,69.8168342254996,0.026689191023206105,-0.03760686901110599
190.00000000000227,70.27703286577042,0.02812462682549577,-0.03779454656041148
191.4000000000023,70.73237308136548,0.027693603975658787,-0.03623012200049569
192.80000000000234,71.1882662208417,0.02721499883981382,-0.03882927413863824
194.20000000000235,71.64819121084773,0.028471782664475143,-0.03688980384671359
195.60000000000235,72.09825383003881,0.02798016242558199,-0.037540668607455085
197.0000000000024,72.55633841024775,0.02814111682579168,-0.04017989000228006
198.40000000000242,73.01162646393772,0.027376314885794617,-0.03842048508326723
199.80000000000243,73.4693389485002,0.025871209181620003,-0.03655757306030649
201.20000000000243,73.94840120067639,0.027299435647360593,-0.039520122131591506
202.60000000000247,74.37157794809559,0.027668534616606566,-0.04025267436613067
204.0000000000025,74.83071146869855,0.028003010806106676,-0.03864364456052005
205.4000000000025,75.28506669450157,0.029785627904953538,-0.04059517425600445
206.8000000000025,75.7384636460464,0.0318879401091865,-0.038531269474977314
208.20000000000255,76.19530385931262,0.02898619447237194,-0.039299948293068265
209.60000000000258,76.64590099077319,0.028462265344680437,-0.03963016400002095
211.0000000000026,77.10126530111538,0.03065145630586774,-0.04095016399968543
212.4000000000026,77.55307209500214,0.032171983753646494,-0.03990457137674852
213.80000000000263,78.0031607020463,0.032241098673444935,-0.04195608398034967
215.20000000000266,78.46472944082998,0.03196400100092189,-0.042698525928322795
216.60000000000267,78.91999733222855,0.033209519882885896,-0.042394339962699146
218.00000000000267,79.37380322956133,0.03446852717425575,-0.044019972738520874
219.4000000000027,79.82958587795503,0.033701982167451794,-0.0440225578892699
220.80000000000274,80.2870936593566,0.03399175028717716,-0.043849388025334335
222.20000000000275,80.73610425719939,0.03355323866794335,-0.04266370281877574
223.60000000000275,81.19227390852527,0.03247345304175031,-0.04446003164088497
225.00000000000279,81.64290611143026,0.03430929598023291,-0.04381001389542005
226.40000000000282,82.10124982250613,0.03608309635343221,-0.04412847355429994
227.80000000000283,82.55551037672069,0.036242234463907064,-0.04564816110202363
229.20000000000283,83.01328005872706,0.034739597658195676,-0.04644013999999741
230.60000000000286,83.47123090231302,0.03555218286053208,-0.04611018076679407
232.0000000000029,83.92398854886352,0.03351819285505919,-0.04676982199986934
233.4000000000029,84.38205503494288,0.03426087356626595,-0.045938901959144296
234.8000000000029,84.83515894233412,0.03293172895785412,-0.047650140148078
236.20000000000294,85.28325165387852,0.0325068358031122,-0.044904267485874616
237.60000000000298,85.73472288635057,0.03504632624276227,-0.04831599037111811
239.00000000000298,86.18212107863246,0.03683798511054914,-0.04730981400000056
240.400000000003,86.64061815369747,0.03849655302105992,-0.04994973959143101
241.80000000000302,87.09492972393265,0.038483068623339056,-0.04618729216905848
243.20000000000306,87.55000000000099,0.037215195656729705,-0.05122811998115351
244.60000000000306,87.99876459696483,0.037422809386153943,-0.048629902529128355
246.00000000000307,88.46241222073614,0.038590972048309524,-0.048739313609359236
247.4000000000031,88.91910519866815,0.03897000855438493,-0.04928998164824572
248.80000000000314,89.37301754976389,0.039214220503978714,-0.04862956266081042
250.20000000000314,89.82691902588121,0.03924378482165469,-0.050337660920578564
251.60000000000315,90.27482729258492,0.039411415203208566,-0.05190738885043
253.00000000000318,90.73062716059356,0.039751738230988876,-0.050297759393912234
254.40000000000322,91.18643821649141,0.03975778602732061,-0.05019248031856982
255.80000000000322,91.64540149676377,0.03864646767235702,-0.052785496678182664
257.20000000000323,92.08017601835417,0.03820393336780392,-0.05325012506420235
258.60000000000326,92.55355210095418,0.04002361434253099,-0.05259036542206896
260.0000000000033,93.0080726891934,0.04063256957556183,-0.051952804035094946
261.4000000000033,93.46193247363172,0.03939418055205879,-0.052871626540875294
262.8000000000033,93.92090507620203,0.03965068074273459,-0.05292008697661332
264.20000000000334,94.37700599712856,0.04173114015865331,-0.053579832000089755
265.6000000000034,94.83526225481167,0.04243206614010764,-0.05423991590673394
267.0000000000034,95.28966320880365,0.04185127672819622,-0.0554596647074157
268.4000000000034,95.77222988340763,0.03940430345848811,-0.055548056071915486
269.8000000000034,96.19655613142544,0.04139622420503142,-0.05535842984118222
271.20000000000346,96.65742534019655,0.04147892424579602,-0.0548999702122166
272.60000000000343,97.11034302609528,0.0467565699181689,-0.05543998300057895
274.00000000000347,97.571099327203,0.04378366169405967,-0.056642807198048484
275.4000000000035,98.02759816647172,0.044786339725519264,-0.05511016174502714
276.80000000000354,98.48394378796695,0.04583171271660946,-0.056409959093718154
278.20000000000357,98.94141409566343,0.04447283623305931,-0.05579988565453009
279.60000000000355,99.38547046896949,0.04259559347118813,-0.056775623146120946
281.0000000000036,99.85484183215615,0.04579766504144023,-0.05708097985105898
282.4000000000036,100.31198511682106,0.045297737512653535,-0.05742238550962808
283.8000000000036,100.77107820232807,0.045375574174139954,-0.056437002442120576
285.2000000000036,101.22821117477261,0.04796462302446525,-0.0574115157261903
286.60000000000366,101.679997374314,0.04789764772831884,-0.056300040274689156
288.0000000000037,102.14358402644936,0.04778721498634719,-0.060379992022087325
289.40000000000373,102.60442863538186,0.05126683511388164,-0.057749853111586535
290.8000000000037,103.05581779294096,0.05036885092279597,-0.059080946513722754
292.20000000000374,103.51651285031515,0.0509910265924034,-0.058743579733128826
293.6000000000038,103.97481748280029,0.05043793366740723,-0.05984009008475688
295.00000000000375,104.4318365444054,0.051235636721001176,-0.05874114304883582
296.4000000000038,104.89176454271303,0.05225398798219216,-0.06166440412615737
297.8000000000038,105.34775579025897,0.051482065429106605,-0.05994016846728556
299.20000000000385,105.78964462102167,0.050704907232633545,-0.06059980429413514
300.6000000000039,106.26159345725014,0.050465122579581356,-0.06356820762785231
302.00000000000387,106.7209734660089,0.05528426542502052,-0.06132964167028465
303.4000000000039,107.17067150657287,0.05588909419789201,-0.0625687250217899
304.80000000000393,107.63486143312853,0.05765079165337439,-0.06080161314443977
306.2000000000039,108.0926631015232,0.056841984192616435,-0.06181742964271386
307.60000000000394,108.54969686582962,0.05660809418731039,-0.06476965267990087
309.000000000004,109.01000000000195,0.05824068169684571,-0.06474988890509792
310.400000000004,109.46116021689156,0.060020135453938916,-0.06160287205934445
311.80000000000405,109.91916069369562,0.061264362221106206,-0.06165203086185844
313.200000000004,110.37760205469071,0.06130178204631753,-0.06345980448815869
314.60000000000406,110.83415920613537,0.061869558459334284,-0.061778046704433986
316.0000000000041,111.28315422175328,0.062218519567583064,-0.06400006238412015
317.40000000000407,111.7481617068863,0.06449477797524494,-0.06335452873994418
318.8000000000041,112.20882126631001,0.06715746672922118,-0.0630224072367298
320.20000000000414,112.66827031256953,0.06810283146368268,-0.06433987807263675
321.6000000000042,113.12999686371772,0.06631324340687295,-0.06597991139198989
323.0000000000042,113.5874828285192,0.06881699556352117,-0.06742840243703307
324.4000000000042,114.04569009463424,0.06786679721296696,-0.06598149461238911
325.8000000000042,114.48440348315214,0.06832346707950188,-0.06837910944098846
327.20000000000425,114.96329793943158,0.0688539117607645,-0.06535302645958119
328.60000000000423,115.42103819423224,0.06939067089354811,-0.06685937027080469
330.00000000000426,115.8833261394981,0.06973172763974644,-0.06817007021799482
331.4000000000043,116.34034777503405,0.06974411545305581,-0.06653007199995598
332.80000000000433,116.7981725158212,0.07208627411993129,-0.06621566815859481
334.20000000000437,117.25894259262306,0.07392996035154709,-0.06816968123268508
335.60000000000434,117.71893829077908,0.07512037347920963,-0.0694898948940077
337.0000000000044,118.17377718245207,0.07512017704208529,-0.06849524193833689
338.4000000000044,118.63642626188482,0.07793464374573156,-0.06787027761324538
339.8000000000044,119.09814782434458,0.07865618440556665,-0.0681806465943251
341.2000000000044,119.5593360832628,0.078287095512096,-0.06916048336619518
342.60000000000446,120.02584085500828,0.07979906214114885,-0.06913854442879286
344.0000000000045,120.48374427888928,0.07643444525599441,-0.0687941525637199
345.4000000000045,120.94335333753936,0.07738607076507864,-0.06916914381080064
346.8000000000045,121.39491427175379,0.08007757116761072,-0.0684620997607559
348.20000000000454,121.8547911927988,0.07813406406511736,-0.07081050174380099
349.60000000000457,122.31194199543975,0.0787062759069379,-0.0708100319161522
351.00000000000455,122.77092714416459,0.07868967020096562,-0.07339781904844012
352.4000000000046,123.23487753098203,0.07920279391563545,-0.07211989000000152
353.8000000000046,123.68917587970908,0.0783258306169683,-0.07146901060301358
355.20000000000465,124.154713900929,0.07859966321824685,-0.0701517690622464
356.6000000000047,124.61415862659094,0.08207622477163223,-0.0701374489150659
358.00000000000466,125.07263888507387,0.08145839078679828,-0.07243997429314941
359.4000000000047,125.52897412116074,0.08338701183671748,-0.07168646690454406
360.80000000000473,125.99061347677885,0.08404594192818515,-0.06904993568725981
362.2000000000047,126.45758967091102,0.08577005908784052,-0.07322855562220232
363.60000000000474,126.91964958435231,0.08838129922173699,-0.07113538201845726
365.0000000000048,127.38111947799061,0.08595059388773829,-0.07103002651102308
366.4000000000048,127.83572841198233,0.08668740538208408,-0.07235011365957256
367.80000000000484,128.30000282390898,0.08739456042425608,-0.07410014140738097
369.2000000000048,128.75999547055162,0.08878171399303536,-0.07307134256836134
370.60000000000485,129.222064308757,0.09186169623474094,-0.07432979396315753
372.0000000000049,129.68445225565515,0.09169913815048414,-0.072145291824814
373.40000000000487,130.14532393114712,0.09343940035663723,-0.07190990256488883
374.8000000000049,130.60346402823154,0.09400569368980416,-0.07320739948609356
376.20000000000493,131.0671074693939,0.09794165576738312,-0.07353563307939215
377.60000000000497,131.52932435536422,0.09720876412548507,-0.0748529362704895
379.000000000005,131.99519854490623,0.10021529876097013,-0.0723644211572343
380.400000000005,132.45770678652062,0.10262885424475932,-0.0745401099997367
381.800000000005,132.92054821796359,0.10158627288029276,-0.07321867176595731
383.20000000000505,133.38453942113796,0.10272157859813302,-0.07441026221399172
384.600000000005,133.84628244924664,0.10371633089572607,-0.07858837449756306
386.00000000000506,134.31191392838818,0.10227164770716857,-0.07619692528120225
387.4000000000051,134.77628689960068,0.10542804975927389,-0.07374623349411014
388.8000000000051,135.23980908673445,0.1078308205564027,-0.07497992033407064
390.20000000000516,135.70022933428788,0.11020490137170125,-0.07729018032783985
391.60000000000514,136.15692002295773,0.10987277652106653,-0.07521008476224278
393.0000000000052,136.6161994022081,0.11281267556642383,-0.07661977566288458
394.4000000000052,137.08283360294698,0.11596064970830189,-0.07663011033483302
395.8000000000052,137.5492797558457,0.11826534268961919,-0.07729840709690539
397.2000000000052,138.00707991125492,0.1197143925536659,-0.07673984320359706
398.60000000000525,138.47317152676416,0.12081989546724459,-0.07739899040303522
400.0000000000053,138.94245065538414,0.11878452426734842,-0.0757501962221161
401.4000000000053,139.4052737866253,0.11806379379882403,-0.07698791070005218
402.8000000000053,139.86681742946504,0.1216648655583823,-0.07761946648027118
404.20000000000533,140.32489862111944,0.1234316548655896,-0.0768500959833962
405.60000000000537,140.78260585664566,0.11986442739027336,-0.08113013817145598
407.00000000000534,141.2539919576019,0.1251574130071007,-0.07817077626206625
408.4000000000054,141.7170106965279,0.12802066255515543,-0.0814622600805941
409.8000000000054,142.1716091163854,0.128097719015696,-0.080425757830767
411.20000000000545,142.64679880853515,0.12786992409949538,-0.08276124890461833
412.6000000000055,143.1109306320298,0.12694257863516478,-0.08111788713134693
414.00000000000546,143.57557010628872,0.13077281172429944,-0.08170812327682242
415.4000000000055,144.04077737730253,0.1303484043236196,-0.08332634805703076
416.8000000000055,144.50069754671745,0.13283499540056898,-0.08167951803953155
418.2000000000055,144.96585419616275,0.13252815713843336,-0.08299977855032115
419.60000000000554,145.42391488753933,0.13315494966743868,-0.08299987200009573
421.00000000000557,145.9020260249714,0.13639896254463824,-0.08234057320062105
422.4000000000056,146.3649607174467,0.13574367939777465,-0.0852865297663814
423.80000000000564,146.8339708653228,0.1384427720076682,-0.08497015844883382
425.2000000000056,147.2955846730906,0.13928150913891302,-0.08497096813113147
426.60000000000565,147.75791267915884,0.14023931640537057,-0.08562363567438513
428.0000000000057,148.21472537835632,0.1423818546631863,-0.08726951212433809
429.40000000000566,148.68680974198713,0.14537647361508754,-0.08661992399388829
430.8000000000057,149.15164711598908,0.14632259324024366,-0.08793998033505801
432.20000000000573,149.6183378087546,0.14668672177461373,-0.08662166684479367
433.60000000000576,150.08411851101513,0.1435338120300862,-0.0872800092736532
435.0000000000058,150.55262496990196,0.1441598733937104,-0.08922999921443209
436.4000000000058,151.01470395237916,0.14618943713105081,-0.08590702278591866
437.8000000000058,151.4797065238082,0.14653836476594573,-0.08926012644836634
439.20000000000584,151.94045122265996,0.1489897767623103,-0.08870994330782134
440.6000000000058,152.4079035587509,0.15116235090308283,-0.09034993274207981
442.00000000000585,152.8800000000016,0.1532671415977891,-0.09100791007613607
443.4000000000059,153.34252749811773,0.1556797973211106,-0.09122455007110819
444.8000000000059,153.81115454753106,0.15555855079325087,-0.08861324076580424
446.20000000000596,154.28486881667175,0.16134766717066995,-0.09287856961746899
447.60000000000593,154.75196817330402,0.1626892932681563,-0.09120445889048634
449.00000000000597,155.2200000000022,0.16124228855717404,-0.09089995199999956
450.400000000006,155.6868052734791,0.1618851025012329,-0.09090907053916153
451.800000000006,156.15242062263405,0.16172319802566237,-0.09354009944263986
453.200000000006,156.61366925634755,0.16191049126662183,-0.09189019988585789
454.60000000000605,157.07021241015056,0.1663080277194826,-0.09221981227612552
456.0000000000061,157.54265815430034,0.16736713502621647,-0.09485252068161376
457.4000000000061,158.00410037240607,0.1711428562601338,-0.09222131693189972
458.8000000000061,158.4760451559872,0.17206485756320955,-0.09222064941634267
460.2000000000061,158.9413375693042,0.17008799226405014,-0.09518981413918848
461.60000000000616,159.40819961443432,0.175987948676531,-0.0951898119999055
463.00000000000614,159.87148055427517,0.17973670959538657,-0.09517992997297853
464.4000000000062,160.34150567579232,0.1787956052420685,-0.09782000497312815
465.8000000000062,160.80128617900192,0.18035103625467608,-0.09823407464598333
467.20000000000624,161.27121251038602,0.17979253840436504,-0.09890996642876448
468.6000000000063,161.73925405841536,0.1813043858608938,-0.09825993911282493
470.00000000000625,162.20662861162162,0.184645548378628,-0.09693965847848007
471.4000000000063,162.6726746695183,0.18309061113753322,-0.09870019603659408
472.8000000000063,163.1412654400143,0.18589529603591792,-0.10066723324073967
474.2000000000063,163.61265134976065,0.1871968742951462,-0.09803019205115326
475.60000000000633,164.07663066967152,0.1838188457615222,-0.0998154621344658
477.00000000000637,164.54033694156814,0.1872787419172952,-0.10001888053755881
478.4000000000064,165.01048673980793,0.18808734848951758,-0.10133042199918219
479.80000000000643,165.48128187972267,0.18504844627800665,-0.10396980800898792
481.2000000000064,165.9457587592096,0.19463799228181689,-0.10395805215040044
482.60000000000645,166.41756695659163,0.19721460774384525,-0.10317126882207761
484.0000000000065,166.88682171947406,0.19789563701069923,-0.10266309760868086
485.40000000000646,167.34196030158427,0.19924948988241287,-0.10672879729425011
486.8000000000065,167.82513543279128,0.20025924305476828,-0.10674994168712981
488.2000000000065,168.29292359617259,0.20251381468320107,-0.1057200131600684
489.60000000000656,168.76846324437076,0.20508558600009597,-0.106195314385094
491.0000000000066,169.23544816346336,0.20608373827736592,-0.10901283106606696
492.40000000000657,169.70143852192547,0.2070554922476675,-0.10933993421624155
493.8000000000066,170.16823732239854,0.20878953400625022,-0.1100099655664124
495.20000000000664,170.6422159649297,0.21032237781793084,-0.11130212084434055
496.6000000000066,171.11321109628136,0.21433825137088247,-0.11131976969075019
498.00000000000665,171.5961633313233,0.2193575358779305,-0.11264015278381834
499.4000000000067,172.05515772859127,0.21847112405151448,-0.11495666184247
500.8000000000067,172.52124750196313,0.21891882743579005,-0.11438322019487668
502.20000000000675,172.98891559177918,0.22104838703386553,-0.11368489765807333
503.60000000000673,173.4571465943686,0.22500424091646432,-0.11615010000086423
505.00000000000676,173.91988349446007,0.2272851071489721,-0.11779991057786754
506.4000000000068,174.395031756338,0.2262070215015517,-0.11779816226068851
507.8000000000068,174.8634834347665,0.22422349411868048,-0.11788349229613271
509.2000000000068,175.33651604893475,0.22639743946086144,-0.12042845598499996
510.60000000000684,175.80259883626093,0.23253194441926883,-0.11944002461314351
512.0000000000068,176.27218775711634,0.23327320758119097,-0.12188416019238257
513.4000000000069,176.74115289116344,0.23490580558080332,-0.12240997799978537
514.8000000000069,177.21165932621847,0.23763286800399452,-0.12306022084170776
516.2000000000069,177.68070502482087,0.2381486456614459,-0.12405013244479735
517.600000000007,178.15000952016763,0.2403139422047662,-0.12422130258508846
519.0000000000069,178.615838354692,0.24215438553680624,-0.12768020304562544
520.4000000000069,179.08529013551797,0.24491672012722843,-0.1257103003879947
521.800000000007,179.557078783162,0.24425381558344617,-0.12966488701805012
523.2000000000071,180.0234596807233,0.24934573291791828,-0.1288219330632434
524.6000000000071,180.49623451161713,0.24893610202088867,-0.13239997399961112
526.000000000007,180.96517835299323,0.2482446776313263,-0.13107998313275004
527.4000000000071,181.43475805780363,0.25630734749981077,-0.13370978533935363
528.8000000000071,181.90759647038246,0.2586099200787326,-0.13339003637678415
530.2000000000071,182.38238565719018,0.2591297822414802,-0.13536187151377677
531.6000000000072,182.85262575259404,0.2576328037970117,-0.13667632080410375
533.0000000000072,183.3206938922512,0.2609682034957803,-0.13669565692621521
534.4000000000071,183.78854922426223,0.2613702054893374,-0.1380211741583346
535.8000000000072,184.25685163363406,0.2651408753228952,-0.1393320452593021
537.2000000000072,184.72501454677132,0.2709108093091044,-0.1412898117901631
538.6000000000072,185.19590240045548,0.2707823818179862,-0.1419131477367701
540.0000000000073,185.66964003608285,0.27436548105931546,-0.1435998730912269
541.4000000000073,186.1347839253365,0.276418189535784,-0.14524003199257773
542.8000000000073,186.60671933521942,0.2791608605599398,-0.1479208596371162
544.2000000000073,187.07543161559798,0.27917739121603447,-0.14916302522001912
545.6000000000073,187.54690327125468,0.28403693485810555,-0.1480273395441447
547.0000000000074,188.0178991782678,0.2880449204965374,-0.15182233816982604
548.4000000000074,188.4862295769488,0.28574815962051225,-0.15320203347984673
549.8000000000075,188.95446655258942,0.28592898748856266,-0.1555298291053906
551.2000000000074,189.42209632461308,0.28777441833208783,-0.15429995596091794
552.6000000000074,189.89592990812204,0.2898339507373229,-0.15710001154225317
554.0000000000075,190.37892132572563,0.29647952558768376,-0.16035511111171363
555.4000000000075,190.85623261406553,0.2965178511610307,-0.16197127057282845
556.8000000000075,191.31941886247085,0.3025509907378914,-0.16433993999192564
558.2000000000075,191.7924817072618,0.3052381738708845,-0.1656634998389781
559.6000000000075,192.2596876551108,0.3041502651824137,-0.166999615113109
561.0000000000075,192.72885603365484,0.3082146519981812,-0.1689501598632459
562.4000000000076,193.20363258285406,0.3115354420676524,-0.1722491695349735
563.8000000000076,193.67298198259306,0.3143960977609188,-0.1722489622662038
565.2000000000077,194.14547723927475,0.31520373293931536,-0.1743207568236418
566.6000000000076,194.62570988501673,0.3218179549242097,-0.17488965126263345
568.0000000000076,195.0952610710446,0.32626564839218597,-0.17845532937922437
569.4000000000077,195.56604924457372,0.32521094206697887,-0.1795000900007997
570.8000000000077,196.03616100554837,0.32604874021707975,-0.183034318933319
572.2000000000078,196.50529813901863,0.33654541933562987,-0.1837801834602617
573.6000000000078,196.97673461875308,0.36193406280386897,-0.18773694998643853
575.0000000000077,197.44629719749,0.4036725965264125,-0.1903700184478514
576.4000000000078,197.91925030366474,0.4043653653583372,-0.19169009013725402
577.8000000000078,198.39364904615508,0.4109615955062189,-0.19303290419123353
579.2000000000078,198.87124089507864,0.4133323230814727,-0.19565760277554878
580.6000000000079,199.3400114692075,0.4149599861218429,-0.198269975790196
582.0000000000078,199.8115346753007,0.4170152920306496,-0.20090015871564493
583.4000000000078,200.2847046457717,0.42088826404083957,-0.2022212738185587
584.8000000000079,200.75543207145208,0.4234962559461728,-0.20454288662930242
586.2000000000079,201.22372893887615,0.4267811813522555,-0.20877888871628292
587.600000000008,201.70031553127546,0.43245259319125395,-0.20921473356472342
589.000000000008,202.17519219641292,0.4384824616510947,-0.21265013059422433
590.4000000000079,202.64038046888192,0.4427975527188215,-0.21744628656710496
591.800000000008,203.11738297251748,0.4515995743250887,-0.2206701367173638
593.200000000008,203.5946581433923,0.45514606032827665,-0.21956859549752838
594.6000000000081,204.06695399449663,0.46119728333208165,-0.22593256249977145
596.0000000000081,204.54061604205566,0.4676480639382219,-0.23074282800395896
597.400000000008,205.0111710623402,0.4733784294526764,-0.23229989316860244
598.8000000000081,205.4883572135683,0.4809689553523637,-0.23689546936084227
600.2000000000081,205.9619110631177,0.48303336263261576,-0.24086931435479642
601.6000000000081,206.43611214255637,0.49293474927793524,-0.24710466508507167
603.0000000000082,206.9119063587983,0.49877239244197913,-0.25200320567410595
604.4000000000082,207.38945664165394,0.510404612811024,-0.2560195819563593
605.8000000000081,207.86598725451609,0.5263311701213937,-0.2612678309429728
607.2000000000082,208.34042042229666,0.5375557554583961,-0.26535151002764934
608.6000000000082,208.81126969626104,0.5450361435744528,-0.27325212899691786
610.0000000000083,209.287862042,0.5607330290340267,-0.2798926409001088
611.4000000000083,209.76407675931446,0.5716609941455952,-0.28642786618086724
612.8000000000083,210.2370387830347,0.5813527380262982,-0.2916996836562107
614.2000000000083,210.71480602414897,0.5940811232712417,-0.3005016903661506
615.6000000000083,211.190352441805,0.6087246680203813,-0.30489805267262504
617.0000000000084,211.661813580091,0.6197512361386046,-0.3170545827996629
618.4000000000084,212.1380231677696,0.6305767625873795,-0.323102318268365
619.8000000000084,212.60933086394095,0.6437242483096326,-0.3325420147781939
621.2000000000085,213.0884672775352,0.6579097795134752,-0.3404540150867015
622.6000000000084,213.5645281067811,0.6686995492795087,-0.34975687776134823
624.0000000000084,214.03756721437838,0.6857210768247852,-0.3604097824005894
625.4000000000085,214.5133817374758,0.7010735260805303,-0.3709940407492516
626.8000000000085,214.98956115117855,0.7167462428643239,-0.38296843570382855
628.2000000000085,215.46595117118068,0.7291635484501668,-0.3927805210367574
629.6000000000085,215.94113649074066,0.745880569066629,-0.40289933020391766
631.0000000000085,216.41979259122166,0.7615494930828337,-0.41686162734053456
632.4000000000086,216.89256944766376,0.7810116511183729,-0.43040555193066954
633.8000000000086,217.37107527970267,0.7975102486620376,-0.4419649826511787
635.2000000000086,217.84922598646983,0.8108204169976916,-0.4575422252297763
636.6000000000087,218.32525236816787,0.8294875480605914,-0.4713158272508484
638.0000000000086,218.80186071598777,0.8431288151252718,-0.48515967898370427
639.4000000000087,219.27765519070817,0.8624726386677977,-0.5012920038582691
640.8000000000087,219.75000516923066,0.8713531122004952,-0.5177410097530557
642.2000000000087,220.22322836360485,0.8918121486704691,-0.5343475310646304
643.6000000000088,220.69810443885333,0.9142283301201677,-0.5515675950340926
645.0000000000088,221.17780557493316,0.9349806805297205,-0.5690850554226201
646.4000000000087,221.65114125373532,0.9517589833952744,-0.5892002476871254
647.8000000000088,222.12941442334628,0.9669701129305892,-0.6055041270009758
649.2000000000088,222.60534542499852,0.9861301046249449,-0.6263168270132229
650.6000000000088,223.07969329841742,1.001921338163073,-0.6473612377864697
652.0000000000089,223.55792190794097,1.0195160776334036,-0.6664533497146392
653.4000000000088,224.03322198380533,1.0328411693450787,-0.6882672400695595
654.8000000000089,224.51000382616326,1.042327981791919,-0.7095307726451745
656.2000000000089,224.98497235504877,1.0637198254121465,-0.7333507346216215
657.6000000000089,225.4588774251418,1.0810945722128085,-0.7556853474584724
659.000000000009,225.93865040978636,1.0973147570213753,-0.7813060407147412
660.400000000009,226.4131516982306,1.1137068565107167,-0.8032157427480229
661.800000000009,226.88967838065636,1.1275807384127572,-0.8273063765006707
663.200000000009,227.36380686907566,1.1413975257201319,-0.8546090182461943
664.600000000009,227.83865610415572,1.15310560417476,-0.8797005635808448
666.0000000000091,228.30816529538055,1.1650319799213742,-0.9081680200474169
667.4000000000091,228.78856403107193,1.176561873293232,-0.9289409192427063
668.800000000009,229.2669445663842,1.1834164009292198,-0.9612683861468287
670.2000000000091,229.74330616116484,1.1984047836478493,-0.9850909718455676
671.6000000000091,230.21596858858345,1.2008681825174725,-1.0129858292813667
673.0000000000091,230.6884055722539,1.2078115210212585,-1.0393148660548133
674.4000000000092,231.16547925005247,1.206098338155034,-1.0679606610257886
675.8000000000092,231.64150186756058,1.2097992138675484,-1.0970951571110312
677.2000000000093,232.12022983914977,1.187296342479661,-1.120616926615782
678.6000000000092,232.5864499499165,1.158892022738494,-1.1498682621120104
680.0000000000092,233.06103377268073,1.1611295566444326,-1.1766091281819349
681.4000000000093,233.52865488750996,1.1732022472535926,-1.202072694501783
682.8000000000093,234.0054526182911,1.1841719299164266,-1.2337457634133702
684.2000000000094,234.4777319211395,1.2027682897806309,-1.25950170751356
685.6000000000093,234.95034135451513,1.2158038973070435,-1.287453407569036
687.0000000000093,235.42700807761616,1.2285616275981721,-1.3168415612137676
688.4000000000094,235.90625936284107,1.234277191570997,-1.3456605206130527
689.8000000000094,236.39146885182282,1.2291710493525891,-1.3747022027198046
691.2000000000094,236.87330044255987,1.2010745459259171,-1.4009891177105938
692.6000000000095,237.34570357230282,1.1411148857307696,-1.428989480463723
694.0000000000094,237.807251679347,1.034377103679057,-1.4509016623189792
695.4000000000094,238.26138425090775,0.881875373806793,-1.467795841021931
696.8000000000095,238.70653602456102,0.5792687313081597,-1.4813864857917403
698.2000000000095,239.16924936498663,0.41695615173915046,-1.4840501516391655
699.6000000000096,239.64259833941531,0.39442567588164534,-1.4853787749649774
701.0000000000095,240.12502244955715,0.38296218192171505,-1.4850404426297148
702.4000000000095,240.59880031166927,0.3766570072938533,-1.4855321506593309
703.8000000000096,241.074567826285,0.37903931161882864,-1.4864822492781777
705.2000000000096,241.55434726521486,0.37790146493116916,-1.487021570120811
706.6000000000097,242.02383052164257,0.3801029905766873,-1.4876801288600632
708.0000000000097,242.504377098297,0.38039511741359,-1.4903171412372376
709.4000000000096,242.98406653040132,0.3815610398239211,-1.4870198315825864
710.8000000000097,243.4634217033033,0.3830800458034682,-1.4888547248302544
712.2000000000097,243.9376600538192,0.38207939902321275,-1.4861437763281375
713.6000000000097,244.41853896619685,0.3868376520923533,-1.4889957561692997
715.0000000000098,244.89213301758588,0.39210251994676293,-1.4880003651976428
716.4000000000098,245.36939674031845,0.3882314922899499,-1.4873401790160807
717.8000000000097,245.84668763448633,0.3907517333855717,-1.4876799507316925
719.2000000000098,246.3118007829926,0.38527083732764833,-1.4889950273151533
720.6000000000098,246.79701761986277,0.3801870292823075,-1.4903095386143077
722.0000000000099,247.27129382420048,0.3802661074780005,-1.4880361541027631
723.4000000000099,247.74886954548856,0.3790778256893401,-1.4906401124525268
724.8000000000098,248.229570026754,0.382720240424161,-1.4909601043650471
726.2000000000099,248.70663188186666,0.3840245139186833,-1.490767825622291
727.6000000000099,249.18000933987614,0.37945791950111385,-1.4926051069112103
729.00000000001,249.65146363183314,0.375903818557787,-1.4896498700000005
730.40000000001,250.13205993203584,0.3743575447222116,-1.4899799120000008
731.80000000001,250.60420329967707,0.37773041192751,-1.490640037538122
733.20000000001,251.08138065748804,0.38031717691484523,-1.4916296501543167
734.60000000001,251.5551466673268,0.3846428212114579,-1.491198901964566
736.00000000001,252.03366358419896,0.38327961747928363,-1.4896510388262936
737.4000000000101,252.50918626665137,0.3819083964953083,-1.4890879964929389
738.8000000000101,252.98926657741941,0.3841245800002602,-1.4899352379511144
740.20000000001,253.46338575449573,0.39192361534042774,-1.4887799411452556
741.6000000000101,253.94269046407624,0.39071284775115656,-1.4910852211951195
743.0000000000101,254.42084136460676,0.39344528787132527,-1.4915320380483181
744.4000000000102,254.901205628676,0.3941025319735574,-1.489028867590061
745.8000000000102,255.36273952256184,0.39533806445038655,-1.4903100478825273
747.2000000000102,255.84895224716095,0.396153092090211,-1.4901983312086373
748.6000000000103,256.3343540954157,0.3936916331462599,-1.4917194143914116
750.0000000000102,256.8093737509047,0.39857571402391256,-1.4910798100178702
751.4000000000103,257.2849377954362,0.3936691410328814,-1.4900900985865717
752.8000000000103,257.75918965115096,0.3997202281550738,-1.491298925556153
754.2000000000103,258.2450422468967,0.3986500923415681,-1.4909704962132708
755.6000000000104,258.7231118777187,0.39411317438532034,-1.4909707705976425
757.0000000000103,259.2000000000055,0.38968782513852096,-1.4888799399999963
758.4000000000103,259.6686849036384,0.387309041651029,-1.4901999419564698
759.8000000000104,260.1603286772018,0.386029975850517,-1.4905300736958953
761.2000000000104,260.6408403185292,0.3771376246833671,-1.490530107995062
762.6000000000104,261.1200068672334,0.378138943943922,-1.4931599079688942
764.0000000000105,261.5960252581685,0.37657473698709154,-1.49315825619657
765.4000000000104,262.0688030423522,0.37801565505430945,-1.4941502264046154
766.8000000000105,262.54614924661956,0.37732361810987536,-1.4928299489593533
768.2000000000105,263.02209354143844,0.376271530449646,-1.4944847280429756
769.6000000000105,263.50128158716035,0.37200153578100226,-1.493820076
771.0000000000106,263.9805357080438,0.3713702952124289,-1.4925100760039203
772.4000000000106,264.45936734350124,0.36876946145348777,-1.4934998000074882
773.8000000000106,264.9407743391455,0.36520284688062965,-1.493499740248562
775.2000000000106,265.42113528079955,0.36225193528127475,-1.4928927823182443
776.6000000000106,265.8987850918448,0.35959669937388306,-1.4937870088155019
778.0000000000107,266.37447539630637,0.35792659616228706,-1.4928101527262898
779.4000000000107,266.85042944224176,0.3586325973299731,-1.4958069561884386
780.8000000000106,267.33000353300287,0.3550696744491031,-1.494149960678211
782.2000000000107,267.8114061618079,0.358357450176638,-1.494150393351835
783.6000000000107,268.2928787749243,0.35318191979098,-1.4941524601346652
785.0000000000107,268.77491587682835,0.3455190242366588,-1.491509692570936
786.4000000000108,269.2542437685114,0.34764630086593895,-1.4924702006039974
787.8000000000108,269.73403551178785,0.34905746247642844,-1.4924886267320057
789.2000000000108,270.2089824779052,0.3499663175962011,-1.4938129617071816
790.6000000000108,270.6851541715259,0.3478747176762895,-1.494149279320934
792.0000000000108,271.1570681171319,0.34576237888510075,-1.4944799360000784
793.4000000000109,271.63828300506174,0.3459841326631685,-1.4961199706511081
794.8000000000109,272.1163600378071,0.3458075000283918,-1.4921703422056418
796.200000000011,272.5936408231375,0.34536800110850896,-1.494490062786368
797.6000000000109,273.0740368304258,0.3455665321705337,-1.4941606250811645
799.0000000000109,273.55115419886266,0.34216390285173137,-1.4918414549585104
800.400000000011,274.02650804193723,0.34476891564753886,-1.4948097925854111
801.800000000011,274.5023157014059,0.347111366961264,-1.4928298989866602
803.200000000011,274.9778009946056,0.34213966035182564,-1.4923209076262962
804.600000000011,275.45903503460227,0.3425133561554006,-1.493816418604665
806.000000000011,275.9300000000066,0.34251830533660543,-1.4918499895502526
807.400000000011,276.4090842049833,0.3386396530208424,-1.4944820172588584
808.8000000000111,276.88826921461146,0.3407879641538192,-1.4954698800000004
810.2000000000111,277.3693315354179,0.3364666696731211,-1.4950399439927256
811.6000000000112,277.84409279725696,0.33287984209403065,-1.4958000231435422
813.0000000000111,278.3213694899129,0.3318049762570068,-1.494536623085342
814.4000000000111,278.80130379213375,0.3355862938186842,-1.4967978726681763
815.8000000000112,279.28331901952885,0.3311017440065984,-1.4945899979023731
817.2000000000112,279.7569434679486,0.33202036471621366,-1.4932446140804432
818.6000000000113,280.2393446784642,0.3287906826326492,-1.4959212156513573
820.0000000000113,280.71347591878936,0.3209571136176006,-1.4966789370164038
821.4000000000112,281.1950885160918,0.3222693728301147,-1.4961397528324558
822.8000000000113,281.6714135571598,0.3214764568597248,-1.4954119060459883
824.2000000000113,282.1540744890923,0.3146089155917702,-1.4957150570363158
825.6000000000113,282.62929223964693,0.3158635768660445,-1.4970100581520578
827.0000000000114,283.1128470540975,0.32133016468640285,-1.4970030516634467
828.4000000000113,283.59103986226984,0.3169416542154062,-1.495046198917632
829.8000000000113,284.0666828981549,0.31473836958452095,-1.495690133540716
831.2000000000114,284.5428475237548,0.31287068187691824,-1.49709391713158
832.6000000000114,285.02000414377085,0.31211741346624766,-1.4983128814386548
834.0000000000115,285.49430317682607,0.31206491988379215,-1.497000179106693
835.4000000000115,285.97751593542466,0.3182035790300639,-1.4943712118998325
836.8000000000114,286.4600035233953,0.31788933250617735,-1.4959130703317807
838.2000000000115,286.9345123559785,0.31557218014460586,-1.4972119934320132
839.6000000000115,287.41784975249345,0.3143550676074933,-1.4959094801861141
841.0000000000116,287.8995869401948,0.30973936834848814,-1.5007269443611815
842.4000000000116,288.3777833016083,0.31840246442123465,-1.4964575693486513
843.8000000000116,288.85418341075666,0.3128869850811702,-1.4961299943112834
845.2000000000116,289.3235877277363,0.31330541618727725,-1.4984301517209118
846.6000000000116,289.8053573904191,0.31105521900854605,-1.4981038001076725
848.0000000000116,290.28311064614326,0.3118678034092106,-1.4964513984330052
849.4000000000117,290.76362954089467,0.311499449582211,-1.4967167951516966
850.8000000000117,291.2434845497533,0.30641944451606706,-1.4988667283451198
852.2000000000116,291.7243214369854,0.30823133328678987,-1.4949199853853194
853.6000000000117,292.1994731491779,0.3091789833004497,-1.4959220206115802
855.0000000000117,292.68030744694147,0.3051179786966354,-1.4985598443167114
856.4000000000118,293.1592900818491,0.3010070163299261,-1.4985499699488556
857.8000000000118,293.63545422765594,0.2978001899352032,-1.4977762073726146
859.2000000000118,294.1143222864387,0.29248554727044906,-1.4988716486186044
860.6000000000118,294.59000577446136,0.2908381695491902,-1.4991992183778855
862.0000000000118,295.069130853416,0.2885736853394021,-1.4990901395155989
863.4000000000119,295.54245762170194,0.2870776080458408,-1.4968370405138618
864.8000000000119,296.02597604829486,0.2839095817027868,-1.4983595661077547
866.2000000000119,296.5064018012057,0.28142520565944595,-1.4968459401330887
867.600000000012,296.984756364616,0.27589730733071205,-1.4984299380172414
869.0000000000119,297.4618691136578,0.27421626735744553,-1.497119935951214
870.4000000000119,297.9413830631907,0.27340007583687287,-1.4971222111244078
871.800000000012,298.41745130987385,0.2669928908382677,-1.497767326552157
873.200000000012,298.89778437411854,0.26706052595089425,-1.4977801899999998
874.600000000012,299.38340209506293,0.2737669069287132,-1.4984398693712682
876.000000000012,299.86112110379867,0.27219915103489445,-1.496899856580479
877.400000000012,300.33959852267543,0.26756850031687174,-1.4978804456772026
878.8000000000121,300.81631383844285,0.26172934285489635,-1.4985397755840397
880.2000000000121,301.2956440644897,0.2587734687459382,-1.498870115370769
881.6000000000121,301.77558146611,0.2586172821916719,-1.4988701620846103
883.0000000000122,302.2532272129259,0.2645150420425342,-1.4985494520197786
884.4000000000121,302.7260200333484,0.2604053639842463,-1.50084988200354
885.8000000000122,303.2112607751057,0.2600498008909753,-1.4969206874100371
887.2000000000122,303.6879538519777,0.25918343263462473,-1.4985102794813239
888.6000000000122,304.17034901215874,0.2610307347890015,-1.501510311604683
890.0000000000123,304.6446629921815,0.26085306200176595,-1.4972221513504413
891.4000000000123,305.12861492996757,0.25975679066831914,-1.4987601498294034
892.8000000000122,305.6079025502122,0.2616552777054335,-1.498786558910596
893.0000000000123,305.6763031098179,0.2610108981434309,-1.4974397308060716