File: 01_Data/Polyester_Carpet_High_Pile/STA/N2/10K_min/Polyester_Carpet_High_Pile_STA_N2_10KData_220912_R3.csv
##Temp./Â°C,Time/min,DSC/(mW/mg),Mass loss/mg
51.0,10.856630592501688,0.05167619998762829,0.030262498244026936
52.100000000000016,11.185466163047026,0.080029430391515,0.02977958290238014
53.20000000000003,11.428455330780217,0.10778540155072291,0.02840874039570629
54.30000000000005,11.630518627898589,0.12339603893202278,0.029941483257912793
55.40000000000006,11.81240495708732,0.13807685937019398,0.029664907550219333
56.50000000000008,11.984427384178504,0.1513338385770906,0.030493894371373287
57.600000000000094,12.145679902385629,0.16038812977886985,0.02916361289735203
58.70000000000011,12.300196501472191,0.16719306273033996,0.03069037825918386
59.800000000000125,12.449170000000015,0.17529857053625153,0.03056788055253623
60.90000000000014,12.594696963867156,0.179980307552557,0.030781127332437208
62.000000000000156,12.738032210279634,0.1852180129628036,0.029117473451452547
63.10000000000017,12.876559186753559,0.19345602797666506,0.029208590407360013
64.20000000000019,13.014189464291716,0.1976960129197467,0.030537421804943676
65.30000000000021,13.14795799896448,0.20216458808413784,0.03128731479351021
66.40000000000022,13.27999621671319,0.20729032315737572,0.03063965281629155
67.50000000000023,13.41180621420276,0.21153929726537712,0.030603575136352035
68.60000000000025,13.541456139370837,0.2155935911074669,0.030617569290138924
69.70000000000027,13.67038984259793,0.21985942067527953,0.031720008957395684
70.80000000000028,13.796791480231326,0.22389003227157334,0.03070370415835022
71.90000000000029,13.9212019976733,0.2265628348827854,0.030607806358161405
73.00000000000031,14.045742463076149,0.23120011835872645,0.03077443235081745
74.10000000000034,14.168234229682696,0.2334482746055564,0.030721057805341623
75.20000000000034,14.292349019478017,0.23527154823410434,0.031930633498372885
76.30000000000035,14.415157291099167,0.2388225295197981,0.03115724865490943
77.40000000000038,14.53540619711314,0.23795266117534386,0.032182856662101855
78.5000000000004,14.654776436464868,0.23817113015303104,0.030630402663929246
79.6000000000004,14.77301923359176,0.2377969510421395,0.03203745387938994
80.70000000000041,14.892802632589754,0.23851268939206527,0.032104577277509705
81.80000000000044,15.010182716045096,0.23778552190687352,0.03062868286764342
82.90000000000046,15.126067098595808,0.23680130762241136,0.03169286575668551
84.00000000000047,15.2416786341842,0.23896615067658844,0.03194983255065509
85.10000000000048,15.357085575132958,0.23998179903694417,0.032117045449429504
86.2000000000005,15.472984612488602,0.23987776049636644,0.03331118254963705
87.30000000000052,15.586016644308607,0.2417818623679503,0.033258608645728494
88.40000000000053,15.701430592853526,0.2419488295227329,0.03252590613054007
89.50000000000054,15.815219010339433,0.2439193303880396,0.03091957411502655
90.60000000000056,15.928662158942721,0.24419041068269864,0.03250065548194403
91.70000000000059,16.040875304777497,0.24396926763633275,0.03259965219800698
92.8000000000006,16.152071094562988,0.24552944444159752,0.03378755322070237
93.9000000000006,16.263529003284347,0.245082579303313,0.03331097253365378
95.00000000000063,16.376171319528364,0.2446506695737326,0.03282999995499658
96.10000000000065,16.484804144022714,0.2470297934823521,0.03328239742724648
97.20000000000066,16.594637942752325,0.24752267074433232,0.033274931546737996
98.30000000000067,16.70550165981895,0.2510104587447326,0.032423430476695714
99.40000000000069,16.81475637392567,0.25476333282928865,0.03338080017852629
100.50000000000071,16.924101571964393,0.2558589998507024,0.03337705819628933
101.60000000000072,17.034279196693642,0.2578790833991659,0.03467430709072694
102.70000000000073,17.1410186824209,0.2598720072519699,0.034659580797200995
103.80000000000075,17.25058465226661,0.26210111409012926,0.03465550696710995
104.90000000000077,17.359639135096234,0.26728646071775763,0.03468973681416898
106.00000000000078,17.467637879289736,0.2653637507255314,0.03468893752847446
107.10000000000079,17.575323920844575,0.26717575004850835,0.033450495090602494
108.20000000000081,17.6831224980356,0.2691981816336645,0.034698602577858395
109.30000000000084,17.792398120570397,0.2705832711745787,0.0335708990585184
110.40000000000084,17.89863025744384,0.27231926514566074,0.03336163168185369
111.50000000000085,18.006113481443876,0.2730412695176866,0.03427765639615998
112.60000000000088,18.114781861095707,0.2748837326735528,0.034689773270320856
113.7000000000009,18.221908825565396,0.2772593340216569,0.034704657268221695
114.8000000000009,18.32570858436602,0.2791076284663653,0.03542552231273799
115.90000000000092,18.436982551654694,0.28078902247413295,0.03600573520120065
117.00000000000094,18.54354544582268,0.2825999023804182,0.03469679209176402
118.10000000000096,18.651927901074504,0.28497968006007324,0.036043738445698636
119.20000000000097,18.758597982229478,0.28520124022028426,0.03334338270286441
120.30000000000098,18.865529008626325,0.28561577103767255,0.03470005238343443
121.400000000001,18.97317668205838,0.2864429472903317,0.03577953614165175
122.50000000000102,19.07917000000011,0.289302887924178,0.03469010827582153
123.60000000000103,19.186718689651915,0.2895923084609705,0.03600876254262353
124.70000000000104,19.294284452936548,0.2915252285023119,0.03601200543008076
125.80000000000106,19.400327930552155,0.2915007157836301,0.036082977371560965
126.90000000000109,19.505572818558413,0.29390526889951096,0.03567980853820263
128.00000000000108,19.614307110377517,0.29538616993299094,0.034678514141225136
129.1000000000011,19.71938416249269,0.2970974779785115,0.03469005477653475
130.20000000000113,19.824855117947138,0.29786640854946955,0.03600215711963983
131.30000000000115,19.93129629862836,0.3012958449494576,0.036174357308374816
132.40000000000117,20.03824164007237,0.30211708040645247,0.03601116645955038
133.50000000000117,20.142609026741503,0.30503920463308554,0.03600725974675267
134.6000000000012,20.24972617555175,0.306630488486186,0.03593673777257855
135.7000000000012,20.355249337486363,0.30797230091090433,0.036010059924277193
136.8000000000012,20.461084789380628,0.3102270786230935,0.03690821393614119
137.90000000000123,20.567792358705468,0.3114798661969974,0.036187550350459396
139.00000000000125,20.673705175618384,0.3119878412205628,0.03533860396488642
140.10000000000127,20.77898082941227,0.3139429518190834,0.03743101325820408
141.2000000000013,20.883866030997495,0.3141304238199957,0.03743965687316475
142.3000000000013,20.98874774965263,0.31533742311209967,0.03801290775958499
143.4000000000013,21.094525125979555,0.31719120021308644,0.037440271155712246
144.50000000000134,21.199755786333693,0.3194976791828731,0.03611998659142923
145.60000000000133,21.30435387832809,0.3211881776897558,0.03612082405706207
146.70000000000135,21.408302240758676,0.322292198611149,0.03612083112938258
147.80000000000138,21.514368716228127,0.3242954034073374,0.037440444381179105
148.9000000000014,21.617745906994518,0.3264363436303752,0.03714719352946538
150.00000000000142,21.72419361469529,0.32855522087117006,0.03611964531671852
151.10000000000142,21.829350818316673,0.33311669148229234,0.03710985934985711
152.20000000000144,21.934981686032174,0.33672561360734493,0.037164411235480976
153.30000000000146,22.038770312060503,0.33953491121321283,0.03609668997900428
154.40000000000146,22.143782466817093,0.3453280223636563,0.03742996215389027
155.50000000000148,22.248601515109165,0.34989265526477964,0.03631103279348391
156.6000000000015,22.352824284348614,0.35634157457132803,0.03743982192109829
157.70000000000152,22.456770619994654,0.36291028163526334,0.0387421462933375
158.80000000000155,22.56195516347477,0.3718374153854401,0.037435732289560875
159.90000000000154,22.667165341000356,0.3800002803490048,0.036778213559044204
161.00000000000156,22.77115517302963,0.3919949479965587,0.037372150560849526
162.1000000000016,22.87650501354704,0.3993345635041049,0.03742453717727656
163.20000000000158,22.98096066296665,0.4075209965424939,0.03742992800194944
164.3000000000016,23.085745479686896,0.41312716882681366,0.0374273650059056
165.40000000000163,23.190123864719308,0.416589732766863,0.038751796916217884
166.50000000000165,23.29461525303071,0.41713749401435024,0.03744021547191689
167.60000000000167,23.400045382438613,0.4075171536925058,0.03749681389531201
168.70000000000167,23.505007912669278,0.3922700464102323,0.038760076729157156
169.8000000000017,23.606992901048066,0.3766725098834421,0.03879413300403378
170.9000000000017,23.71263521710419,0.36369620575598327,0.03841898224592377
172.0000000000017,23.817055343295035,0.3556333592653478,0.03743012518257949
173.10000000000173,23.92232606173848,0.34937001238792703,0.03875066085503409
174.20000000000175,24.026586111064184,0.3454145999619634,0.038749893325707774
175.30000000000177,24.130303552669506,0.34057011420348365,0.0373795130880854
176.4000000000018,24.235490886043767,0.3411133048847461,0.037421272392831995
177.5000000000018,24.34054470861087,0.3405449730125076,0.03744027399214289
178.6000000000018,24.441734187120673,0.34065905654845297,0.03876345195033082
179.70000000000184,24.549616494852252,0.34301252482166983,0.03876117275634794
180.80000000000183,24.651378315019972,0.34436747829643366,0.0374361531020142
181.90000000000185,24.757915459667842,0.3441394975334411,0.038756613238543736
183.00000000000188,24.86354687606739,0.34582742950663825,0.037430018890254324
184.1000000000019,24.966931234757162,0.34558927052002036,0.03742443886041258
185.20000000000192,25.072067280805594,0.34720619699071675,0.03808946312932271
186.30000000000192,25.175935321977217,0.34745386722621546,0.038084526710806976
187.40000000000194,25.277876750767618,0.3466693285570788,0.03885999390560624
188.50000000000196,25.385098361716448,0.3470181728150365,0.03775176040492223
189.60000000000196,25.48962353980668,0.34829653442694036,0.036745571885854034
190.70000000000198,25.593967895895698,0.3484676969119518,0.038179932669391015
191.800000000002,25.697716604106148,0.3511814262546631,0.03765245326680233
192.90000000000202,25.80337592911615,0.3511793448124639,0.03710982877076052
194.00000000000205,25.907123472127854,0.35151919218554456,0.03813463357346514
195.10000000000204,26.01056502520648,0.3520934651285761,0.03676989111581541
196.20000000000206,26.114937103574494,0.35236993820064333,0.03676565060825698
197.3000000000021,26.22011578328445,0.35590044256764275,0.038090112603994086
198.40000000000208,26.32460388694736,0.3545947802487936,0.03743903418637551
199.5000000000021,26.42926485007563,0.355651950135053,0.03677547471828646
200.60000000000213,26.532314059437425,0.3573950819209106,0.03678144688044149
201.70000000000215,26.637684216884757,0.35810747385653663,0.038099290838908395
202.80000000000217,26.741803199912752,0.3595152332105273,0.036780164411401195
203.90000000000217,26.84660531712478,0.35998847574821397,0.03546015485121501
205.0000000000022,26.949986011090807,0.3597539299980368,0.03578894425849466
206.1000000000022,27.054637126154972,0.3616285100020195,0.03578513333924693
207.2000000000022,27.159941062121224,0.3614755040083251,0.03711034195102503
208.30000000000223,27.262683444927717,0.3617851133707932,0.036805806812826525
209.40000000000225,27.36844311829458,0.3634970914037045,0.03546019968166991
210.50000000000227,27.473149810818533,0.36430740555228147,0.03546902797656415
211.6000000000023,27.576459651615867,0.3659611319115323,0.03538153516330844
212.7000000000023,27.681593223927827,0.36760441267343946,0.035472400178243824
213.8000000000023,27.784916422873277,0.36647140030927605,0.03546009443497766
214.90000000000234,27.88982713816459,0.36930302370739937,0.03413575300901606
216.00000000000233,27.994011540217166,0.37058747940327064,0.03551281530280459
217.10000000000235,28.098137367817458,0.37522502987568346,0.03546007100877002
218.20000000000238,28.20345215453919,0.3755341323867264,0.035447297301485214
219.3000000000024,28.307552830278194,0.37775521579995075,0.034470071230097155
220.40000000000242,28.41144979794195,0.3811748400849306,0.03441776220220216
221.50000000000242,28.516707029397857,0.38201829100590246,0.03545990726489645
222.60000000000244,28.620597380930775,0.3844381823411592,0.03413995174991946
223.70000000000246,28.725299012754075,0.3851861094436868,0.034139914009664984
224.80000000000246,28.83004036960902,0.38823664346084175,0.03412846054193164
225.90000000000248,28.934411166166445,0.3900197054094267,0.03348991303386217
227.0000000000025,29.038198632760505,0.39169050746706624,0.034805827302963444
228.10000000000252,29.142751535503038,0.3923340653907562,0.03415101414378796
229.20000000000255,29.248003712067625,0.3954635262396922,0.03415022263769174
230.30000000000254,29.352230388111735,0.398219634535071,0.033196119119345724
231.40000000000256,29.45648389410959,0.40137753652491254,0.03315982005016238
232.5000000000026,29.56045771217908,0.4047619787740303,0.03314991766110875
233.60000000000258,29.66573005854815,0.40942218820445336,0.03411277454656947
234.7000000000026,29.770208757791448,0.4144599924865149,0.03282019294580696
235.80000000000263,29.875041830964875,0.4170764493050215,0.032820192999999165
236.90000000000265,29.978365391651344,0.42194195124320616,0.032820193028474165
238.00000000000267,30.083792620429954,0.4300330752034821,0.032861341105913766
239.10000000000267,30.187881846317175,0.4397198058704604,0.032489655053045574
240.2000000000027,30.293195637459647,0.4450345900618087,0.03149443387731665
241.3000000000027,30.396176599040572,0.45652015902144094,0.03281559863077188
242.4000000000027,30.501181075897218,0.4665609174602185,0.032818849342762135
243.50000000000273,30.60536355396067,0.4847400118989319,0.03150283661874376
244.60000000000275,30.71134096893099,0.5052209246680028,0.031510047965181975
245.70000000000277,30.815647658453507,0.5353220692869305,0.031510051469844313
246.8000000000028,30.92017032628624,0.5739616641202769,0.03051943468337104
247.9000000000028,31.02484392533755,0.6230908583746487,0.02952992446683389
249.0000000000028,31.129524936363662,0.6728245669721338,0.03085149437401391
250.10000000000284,31.23462543489037,0.7061922474514445,0.030317033811155802
251.20000000000283,31.340555525778225,0.7107347283371281,0.030522640966118786
252.30000000000285,31.44487580591563,0.6775689173497612,0.030614758559017297
253.40000000000288,31.55007218945968,0.6261326285157298,0.02924147894667506
254.5000000000029,31.653321320632884,0.5725407458137398,0.03021497534288553
255.60000000000292,31.758868047677694,0.524035010565702,0.03018987900479786
256.7000000000029,31.862619940850283,0.4897530368551005,0.030175805891689222
257.8000000000029,31.967654480800256,0.4634258246418459,0.02919987899933396
258.90000000000293,32.07146467849404,0.4438580593322313,0.029201581019242973
260.00000000000296,32.17656448545714,0.43097473372901174,0.02803880854706442
261.100000000003,32.28090095778504,0.4227345729150779,0.029192419222373367
262.200000000003,32.38517486099535,0.41479523954399583,0.029531548530542295
263.300000000003,32.490321257045714,0.41257467886857135,0.028776258919410935
264.40000000000305,32.59467822472625,0.40744747825294725,0.02718402238913953
265.50000000000307,32.69926625556715,0.40755624353242903,0.02722981600169394
266.6000000000031,32.80304104879482,0.40561289407504203,0.027229815999999296
267.7000000000031,32.907956587900976,0.40423751938052654,0.027229816000000184
268.8000000000031,33.01268738396461,0.4044588890595452,0.02722981599578933
269.9000000000031,33.118625134013506,0.4036145554882694,0.027239523505183882
271.0000000000031,33.222433050404895,0.4057957637232421,0.025923012810596724
272.10000000000315,33.327860589576254,0.40447114171198467,0.026900027779394264
273.2000000000032,33.43240602467361,0.40545741824245674,0.025579528857591072
274.30000000000314,33.53782785093508,0.4063793809450563,0.02558015488171339
275.40000000000316,33.643094876361936,0.4065204316839378,0.02425985593498048
276.5000000000032,33.747971214579266,0.40539758205634474,0.02426016200051606
277.6000000000032,33.85281172142611,0.4055405357820342,0.02426016199999914
278.70000000000323,33.957701992021924,0.4061601900773654,0.0242601620808518
279.80000000000325,34.06232559289451,0.4074059107955555,0.02309058161257216
280.9000000000033,34.16896843907247,0.4072384537383917,0.022950151572069366
282.0000000000033,34.27446703903546,0.4099978636334298,0.02229403426826071
283.1000000000033,34.37855936200524,0.408928277997052,0.022610036728907268
284.20000000000334,34.483375810111355,0.40931110828958256,0.02261004540771605
285.30000000000337,34.587364105074414,0.41059536692799775,0.021952056453606872
286.40000000000333,34.69357471673096,0.41051125465019167,0.021942398245616168
287.50000000000335,34.79917000000037,0.4104479163988035,0.02063990999993237
288.6000000000034,34.9048322982509,0.4118075075041507,0.020639909965771253
289.7000000000034,35.00898461757617,0.41398606253842085,0.02063991000001053
290.8000000000034,35.11424505633355,0.4162001705928067,0.02063977097582903
291.9000000000034,35.219866533238296,0.4170277180174222,0.018040623802841438
293.0000000000034,35.32544909115433,0.418763346732826,0.01800988537324777
294.10000000000343,35.43041861358462,0.4201081637433795,0.020318094493525507
295.20000000000346,35.536119068333086,0.42088063339632126,0.02007945511116027
296.3000000000035,35.641715875449734,0.4221954585078397,0.017676709921280676
297.4000000000035,35.74705809459905,0.42471078232763126,0.01767463833502969
298.5000000000035,35.8524705533108,0.4249646194783009,0.016192710287851853
299.60000000000355,35.95750617488409,0.4285982140742479,0.015217738727594465
300.70000000000357,36.06277748069397,0.430893502950748,0.01539589889863624
301.8000000000036,36.16797626230967,0.43161684911821835,0.015039976773290498
302.9000000000036,36.27296830316772,0.43422008618746644,0.015039822262813196
304.0000000000036,36.37935822898841,0.43710651715613014,0.013720136453371445
305.1000000000036,36.48208652527119,0.437535292527896,0.012401461672565617
306.2000000000036,36.589079839484995,0.44012795584153463,0.012399914208604201
307.30000000000365,36.6947957252559,0.443569297190702,0.011079881729492591
308.4000000000037,36.79917094039816,0.4458581520187468,0.011079882065988755
309.5000000000037,36.9057352134174,0.44690026537111877,0.009769967472320396
310.60000000000366,37.01041531124432,0.45023969787592427,0.009722075132263974
311.7000000000037,37.11573293836453,0.452164480144921,0.008582030987550837
312.8000000000037,37.22102901513513,0.45533521422870193,0.006198839280695978
313.90000000000373,37.32635015386469,0.455550116203694,0.005810616680165914
315.00000000000375,37.42959185350469,0.4560485170203384,0.0045003600820203715
316.1000000000038,37.5370920488538,0.45528303511624324,0.0031868063552611403
317.2000000000038,37.64378704727753,0.45764300348623965,0.002838719966542058
318.3000000000038,37.7502329280079,0.45707172859669154,9.059960176660553e-05
319.40000000000384,37.85523465352444,0.4568834336986059,-0.0011947441106947565
320.5000000000038,37.96105686948019,0.4553268246484915,-0.002414696297075025
321.60000000000383,38.06538392150257,0.4562036988886575,-0.0036641359465283685
322.70000000000385,38.1728238772585,0.45692179468888894,-0.0077409712580589485
323.8000000000039,38.27907293394839,0.45574974257343615,-0.008995496857081342
324.9000000000039,38.38361771741133,0.4561867661656837,-0.010229891165709937
326.0000000000039,38.48969318796109,0.45583529235682463,-0.012948123539306522
327.10000000000394,38.595890950360236,0.4555693121470785,-0.016787426145213225
328.2000000000039,38.702396480266955,0.4566495760472343,-0.019570578069521005
329.30000000000393,38.807922498425874,0.4571271318617031,-0.022090648965797932
330.40000000000396,38.913746088198586,0.45654088656503156,-0.024894719495064166
331.500000000004,39.01906702799263,0.45674148039779694,-0.028312506531111836
332.600000000004,39.126086824428725,0.4575206808785736,-0.031094488002834098
333.700000000004,39.23187773882743,0.4553525974301734,-0.03621978012737692
334.80000000000405,39.33466855185151,0.4545591252533521,-0.0373609122406906
335.90000000000407,39.44365351490226,0.45431940446589586,-0.04171837095112885
337.0000000000041,39.549263881646326,0.4533759507984199,-0.04731882857139347
338.10000000000406,39.655742986259305,0.4506891566754582,-0.05162602310905218
339.2000000000041,39.76135766399417,0.4493867650053272,-0.05598535398574089
340.3000000000041,39.867823205148916,0.45004798995603695,-0.059492967901838334
341.4000000000041,39.97387389166084,0.44775813855900337,-0.06609985902780835
342.50000000000415,40.07964912280332,0.44651124046695395,-0.07047078842177346
343.6000000000042,40.18624548484604,0.4445151119415645,-0.07476753123356605
344.7000000000042,40.29298347312498,0.44551092726149655,-0.08006326242415618
345.80000000000416,40.39947787410797,0.44582524695590636,-0.08477014462878962
346.9000000000042,40.50563883582956,0.4461156736036175,-0.09193234787603854
348.0000000000042,40.61176641833108,0.44690256416421104,-0.09665614763944674
349.10000000000423,40.717240903335124,0.44814720871280633,-0.10172014298395027
350.20000000000425,40.823878219744124,0.44538813328857046,-0.10736808181078361
351.3000000000043,40.93043189103645,0.44834766277849003,-0.11289266888049587
352.4000000000043,41.036235669119215,0.4484299981252424,-0.11806369278707063
353.5000000000043,41.14367186781612,0.44962259804786453,-0.12465305888725631
354.60000000000434,41.24878460869822,0.4523602341613762,-0.1292099285893702
355.7000000000043,41.35498862129233,0.45484005654221793,-0.13562417003615845
356.80000000000433,41.462432253721104,0.45289060814905835,-0.1416806216074189
357.90000000000435,41.569070747432505,0.4526221423215507,-0.14798654503193331
359.0000000000044,41.67493581320312,0.4549036936104435,-0.15526435472189304
360.1000000000044,41.782259751288706,0.45405332323034514,-0.15985031887753776
361.2000000000044,41.88916904489391,0.455353901880331,-0.166431840657566
362.30000000000445,41.995691350061506,0.4567164852370439,-0.1727910277683704
363.4000000000044,42.101528130137844,0.45822154987142366,-0.17758003900272845
364.50000000000443,42.20795731904816,0.4601022476266866,-0.18546629790746794
365.60000000000446,42.31533875799915,0.4592914743293528,-0.18950501907337713
366.7000000000045,42.42173787258795,0.4582588276004137,-0.19532205733283892
367.8000000000045,42.52888248272825,0.4608018732601754,-0.20264613968314737
368.9000000000045,42.63564957422656,0.46004528149253665,-0.20934583932125594
370.00000000000455,42.74155123861627,0.46052094222333423,-0.21522091665844378
371.10000000000457,42.847919903258074,0.46051679537417267,-0.2208668018584845
372.2000000000046,42.955377488305494,0.4595000288683582,-0.22691692417899567
373.30000000000456,43.06188059541771,0.458531751513361,-0.23303015107107816
374.4000000000046,43.16860669274273,0.4571616318393364,-0.2395870767721271
375.5000000000046,43.27554791730029,0.4570878731001017,-0.24680438320677522
376.6000000000046,43.38205903325041,0.45555627701180607,-0.2546136884319594
377.70000000000465,43.48899100040599,0.45586741038548784,-0.2608343673893301
378.8000000000047,43.59575901396187,0.45814697187808107,-0.26605889116747905
379.9000000000047,43.70127317212385,0.4530940784133424,-0.2724433754180784
381.00000000000466,43.809066571183074,0.4526667456997506,-0.27948897934309747
382.1000000000047,43.91697896209983,0.45392159186005143,-0.28706494252548875
383.2000000000047,44.023364829402794,0.4530632199437734,-0.2916770851620436
384.30000000000473,44.12967384622887,0.45429326874793197,-0.3006899466071111
385.40000000000475,44.23640028428519,0.45491558669721305,-0.30743682159513686
386.5000000000048,44.342688113174965,0.454063860885317,-0.31483374105340634
387.6000000000048,44.450481684452505,0.45411268228713536,-0.3213751513894123
388.7000000000048,44.55640997997939,0.45191635080177617,-0.3286597959203883
389.80000000000484,44.664111074895736,0.45392568399823097,-0.3369851106378614
390.9000000000048,44.77095913656759,0.4535492497462559,-0.34552637419317556
392.00000000000483,44.877870946630125,0.45151575593837434,-0.3540409703366709
393.10000000000485,44.98477647766523,0.4530984430525289,-0.362648216782004
394.2000000000049,45.0914623747084,0.45204278900979955,-0.3710703197888252
395.3000000000049,45.19856265716108,0.45092562510568257,-0.3795772041318686
396.4000000000049,45.30509902340212,0.4524844201853004,-0.388255702673181
397.50000000000495,45.412445164395784,0.45124251863008097,-0.398022859578107
398.6000000000049,45.51946058654679,0.45362514308811674,-0.4078729671007064
399.70000000000493,45.626475744429996,0.45334298465277956,-0.4189568753172459
400.80000000000496,45.733660066776054,0.4543652536449679,-0.4290323064889119
401.900000000005,45.840112987328965,0.45576245735552534,-0.4391480335054263
403.000000000005,45.94694993125525,0.45820738355533236,-0.4502123676691183
404.100000000005,46.05522607888636,0.46034303167487073,-0.4607718089398469
405.20000000000505,46.161212336721526,0.46208847809172227,-0.4739167213149398
406.30000000000507,46.26701734820525,0.46337435033345575,-0.4855674656361755
407.4000000000051,46.37524816430477,0.4655697508450352,-0.49892804187367634
408.50000000000506,46.482565208115574,0.4692572054704636,-0.5128931256710154
409.6000000000051,46.589718331326104,0.4727714686365593,-0.5245873164738946
410.7000000000051,46.69773893181968,0.47709705715952144,-0.540057252445667
411.8000000000051,46.8033587638993,0.48041624488640167,-0.553596951490706
412.90000000000515,46.911664117963944,0.48691270103684836,-0.5692493883172802
414.0000000000052,47.01839367468326,0.4940900056856528,-0.5855594509570841
415.1000000000052,47.12659083058962,0.5023447973726602,-0.602105226588745
416.20000000000516,47.232919405108646,0.5070199536475157,-0.6198887695436355
417.3000000000052,47.340602297063946,0.515368190230451,-0.6375022054514514
418.4000000000052,47.4475398179927,0.520160144038952,-0.6559184362112891
419.50000000000523,47.554866215976936,0.528708273184269,-0.6742656434106964
420.60000000000525,47.662476640165465,0.5360957667313992,-0.6948040631777506
421.7000000000053,47.76907662566887,0.5387881464709463,-0.714769508141829
422.8000000000053,47.87664563649181,0.5466038311749725,-0.7377415316926466
423.9000000000053,47.983654756601275,0.5504098154390846,-0.758072069211349
425.00000000000534,48.092132079250874,0.5566586349835015,-0.7803951224561709
426.1000000000053,48.1989880253481,0.5625426327840263,-0.8042359835813295
427.20000000000533,48.305020412477745,0.5670114076045589,-0.8294753762577383
428.30000000000535,48.413544723018255,0.5713701205779718,-0.8541611228513846
429.4000000000054,48.520281145189614,0.5790867762897326,-0.8785892773030706
430.5000000000054,48.62842362787116,0.5827510393070361,-0.9061805855412763
431.6000000000054,48.73536524094062,0.5861810842918509,-0.9339028838538481
432.70000000000545,48.843119776785606,0.5901476415453272,-0.9617573238126225
433.8000000000054,48.95033376889145,0.590799249572185,-0.9878759981948084
434.90000000000543,49.05702044605394,0.5949020027788388,-1.0157785946861253
436.00000000000546,49.16629047367576,0.5959884525335604,-1.0480362021072436
437.1000000000055,49.27200023794487,0.5941557572304064,-1.0764411770742779
438.2000000000055,49.38068420294026,0.5932141742027544,-1.1032298309525763
439.3000000000055,49.48766615489193,0.5921595695889762,-1.1318560789046583
440.40000000000555,49.59547182163341,0.5889097033869696,-1.1591666696547112
441.50000000000557,49.70366436049905,0.5853014223928457,-1.186300410380956
442.6000000000056,49.811142911679,0.5778902066678324,-1.210466223323463
443.70000000000556,49.918875839401,0.5699773402649959,-1.235203080550352
444.8000000000056,50.02547005321271,0.559585416727238,-1.2567046317502837
445.9000000000056,50.133610036363955,0.5488336204308917,-1.2787740104418686
447.0000000000056,50.24046562152374,0.538812147602071,-1.2963702861933801
448.10000000000565,50.34907143736544,0.521213176282815,-1.313431149159392
449.2000000000057,50.457098802976276,0.5067566863486769,-1.3283267159437289
450.3000000000057,50.56379645734226,0.4916404497272741,-1.3419675575546566
451.40000000000566,50.67146013720699,0.47865395735913446,-1.3545741282421466
452.5000000000057,50.778066642341656,0.4646472085022811,-1.3681062248491074
453.6000000000057,50.885146216762095,0.4556091253985862,-1.3792456167391487
454.70000000000573,50.99521168074445,0.44746669818800705,-1.389066361498398
455.80000000000575,51.10227165038814,0.4388469779338471,-1.4002313173235565
456.9000000000058,51.2095710262968,0.433974983643842,-1.4114044078558283
458.0000000000058,51.317534702482995,0.43182117016171145,-1.4217000986407218
459.1000000000058,51.42404503734937,0.42837988272494204,-1.431523471158655
460.20000000000584,51.533109756579606,0.42691986919144975,-1.442078944846838
461.3000000000058,51.640579959220766,0.42742164857497117,-1.451972934110874
462.40000000000583,51.7500097675016,0.43050267281895643,-1.463718508358899
463.50000000000585,51.85717404459378,0.4310804145895153,-1.4747170567592751
464.6000000000059,51.965830234333,0.4337703883142112,-1.4865714631382336
465.7000000000059,52.073517519813045,0.4346994938053415,-1.4973098793459862
466.8000000000059,52.18211258138328,0.4387399355154342,-1.5100626790368978
467.90000000000595,52.28989508987727,0.4431794251925495,-1.524916503958449
469.0000000000059,52.40025705077837,0.4414959845074958,-1.5367707399105308
470.10000000000593,52.5069376469986,0.4438043310051212,-1.551125310520253
471.20000000000596,52.61583178311277,0.44244588604003054,-1.5653761553932384
472.300000000006,52.723486655964365,0.4405210644644409,-1.5796026800229992
473.400000000006,52.83177553180342,0.4373863013320123,-1.5939153836877709
474.500000000006,52.939852557905716,0.4285881801043822,-1.6089493763473723
475.60000000000605,53.04828923854713,0.4156149400523985,-1.620419661409429
476.70000000000607,53.15668171706515,0.40096070576819404,-1.6321548521379832
477.8000000000061,53.264289293871435,0.3825490784748368,-1.6412415843104609
478.90000000000606,53.37221899846603,0.3605768188014785,-1.6472535752117712
480.0000000000061,53.479562869747,0.3363661768031152,-1.6543157168708253
481.1000000000061,53.588649667764216,0.31237805285553233,-1.6591009270002264
482.2000000000061,53.69630753221042,0.2961663578489958,-1.6634820784309503
483.30000000000615,53.80474269236647,0.2806062386075884,-1.6647513415036959
484.4000000000062,53.91342217563892,0.2678930733503764,-1.6676545785375514
485.5000000000062,54.02094748709155,0.25840503297852996,-1.6703554196260604
486.60000000000616,54.130480316422805,0.25428467695296325,-1.671672573961088
487.7000000000062,54.23886200521875,0.25238947093436476,-1.6739440187836285
488.8000000000062,54.34749156656249,0.2509495485221177,-1.6756113142268716
489.90000000000623,54.455156746151395,0.24978545316456438,-1.6769310844548997
491.00000000000625,54.56351653836531,0.25118808532905423,-1.6782499802002238
492.1000000000063,54.67179690892419,0.25119566024496676,-1.6795775890115436
493.2000000000063,54.78131346844891,0.2513604472274221,-1.6795721060308337
494.3000000000063,54.88732489566852,0.25167853206182944,-1.6822329136264509
495.40000000000634,54.99657781277669,0.25407669754557544,-1.682853263897539
496.5000000000063,55.104513463595374,0.2534542106188438,-1.684180551021536
497.60000000000633,55.21486242245292,0.25369706095624245,-1.6841808678926187
498.70000000000636,55.321703643013294,0.2526020038409265,-1.6854898601361166
499.8000000000064,55.43012458907685,0.25385539194578866,-1.6868137403384793
500.9000000000064,55.53868128001055,0.2565381552646663,-1.686538387304052
502.0000000000064,55.647396861478654,0.2557701606117438,-1.6876950349881907
503.10000000000645,55.754992515696905,0.25774606199856925,-1.6904191413790817
504.2000000000064,55.86241961532995,0.2602497391705654,-1.6917588311821339
505.30000000000643,55.969403758577776,0.2629110853717316,-1.6930799697623904
506.40000000000646,56.07972336982501,0.2629048269655124,-1.6943926408650412
507.5000000000065,56.18713198185854,0.2615218116354179,-1.6953741551622885
508.6000000000065,56.294025634927586,0.2637513773064043,-1.6957576008052206
509.7000000000065,56.4036182472458,0.26823699856156674,-1.6977271895904416
510.80000000000655,56.511756602694184,0.2734022891773297,-1.6969209381958064
511.90000000000657,56.61841908966419,0.27459810421335373,-1.6984567726257485
513.0000000000066,56.72817612851215,0.2775626331154909,-1.7004298372493052
514.1000000000065,56.837046040777444,0.2779600563559439,-1.7017510817139518
515.2000000000066,56.94479165798926,0.27795521330051814,-1.7021293540427633
516.3000000000065,57.053064123381596,0.2781255007670524,-1.7033999528487112
517.4000000000067,57.161599866142225,0.2783967897056564,-1.704710666812637
518.5000000000066,57.26956369092623,0.27971464602194646,-1.7060446706632924
519.6000000000067,57.3785008553756,0.2804047681670035,-1.7070072988226532
520.7000000000066,57.487442232095546,0.28133586096087926,-1.7083277087379911
521.8000000000067,57.59579731403121,0.2812503691146731,-1.7096515595903696
522.9000000000067,57.70370087462696,0.28409578545795233,-1.709637083140776
524.0000000000067,57.81295686951833,0.2805648142326302,-1.7109304333559798
525.1000000000067,57.9212181964512,0.2834072590451785,-1.7149246733939107
526.2000000000068,58.030740226520514,0.28257299003899644,-1.7139298589962757
527.3000000000068,58.13800791030449,0.2814914879686744,-1.7165822512875146
528.4000000000068,58.24779861422212,0.285196172000836,-1.7177968593945039
529.5000000000068,58.35712943280788,0.2859850981568326,-1.7191865321945352
530.6000000000068,58.46594450848315,0.2854059218741097,-1.7202233621402279
531.7000000000069,58.57475919011377,0.2851788052658932,-1.7215105316161932
532.8000000000068,58.683917347793006,0.2852402687132336,-1.7214810312610878
533.9000000000069,58.792826874171155,0.2854566643619125,-1.7241396527903965
535.0000000000068,58.901608890808724,0.2854362564538893,-1.7241528248060303
536.100000000007,59.010410520980564,0.28381320209307037,-1.7254628113783186
537.2000000000069,59.119377177921656,0.2830319000374937,-1.72677548206586
538.300000000007,59.228338723190994,0.2828145344756356,-1.7280885346945047
539.4000000000069,59.337421988878454,0.28343311391368387,-1.7294293984278428
540.5000000000069,59.446609491631754,0.2836514673558378,-1.7307582158558943
541.600000000007,59.55523556595437,0.2838268341283601,-1.7326124565158545
542.700000000007,59.66481414729693,0.2837726770243937,-1.734703153013136
543.800000000007,59.77407295653032,0.2824194655326204,-1.7359716630169322
544.900000000007,59.88398516069644,0.28438111084926376,-1.7368148206947454
546.000000000007,59.99175880182896,0.28314986901052097,-1.7389686292868762
547.1000000000071,60.10112066027338,0.28625886280536095,-1.7402921816647767
548.2000000000071,60.210864283494146,0.2864904964556967,-1.742924335239385
549.300000000007,60.31926537571114,0.287788691548276,-1.7449079915088013
550.4000000000071,60.427656963900496,0.2873755359642627,-1.7468914087893586
551.500000000007,60.5373873194674,0.2878107266894859,-1.747522404433861
552.6000000000072,60.64622285689361,0.2864703084670544,-1.7501360352553657
553.7000000000071,60.75558124155683,0.28652556408227414,-1.7519751781407584
554.8000000000072,60.86497330348959,0.28690777780808413,-1.753456505415715
555.9000000000071,60.97333463444205,0.28684754334206686,-1.7561616043152934
557.0000000000072,61.08404970735931,0.28831223352904417,-1.7584516744368774
558.1000000000072,61.19169145574587,0.2892691959229743,-1.7601548427326823
559.2000000000072,61.300761866875234,0.28973784193438623,-1.7639964489329802
560.3000000000072,61.41030235437599,0.2911996830575723,-1.7666575413408667
561.4000000000073,61.51967817499781,0.29326965631601415,-1.7673077698473376
562.5000000000073,61.628665532906496,0.29485385966447003,-1.770864853615576
563.6000000000073,61.73683371305858,0.29273948693377716,-1.7738724658394531
564.7000000000073,61.84755111120947,0.2944109014841169,-1.776644890706081
565.8000000000073,61.9560180225779,0.2951600478585451,-1.7800402370038633
566.9000000000074,62.065551377317774,0.29792723353334644,-1.7826294345333795
568.0000000000074,62.17454973575643,0.3001232040089098,-1.786747571899891
569.1000000000074,62.284303183102,0.30424490561308815,-1.7894983179221238
570.2000000000073,62.392929093237036,0.3078505972154294,-1.7907832994509034
571.3000000000073,62.502866682875165,0.3127923337077657,-1.7964944129317209
572.4000000000074,62.612131679486716,0.31553688478562664,-1.7993660456110074
573.5000000000074,62.72252792335506,0.32146901737183603,-1.803754023359594
574.6000000000074,62.83124701239044,0.325942628511172,-1.8083486380616254
575.7000000000074,62.939557706714524,0.3308881225309729,-1.8118124600459384
576.8000000000075,63.049263179414204,0.3360119761852131,-1.8171467568822943
577.9000000000075,63.15886105918788,0.3403985255287554,-1.823270436329378
579.0000000000075,63.267914342591816,0.3450577834385922,-1.8293015753331443
580.1000000000075,63.37733816633731,0.3466839428813167,-1.8347019371337692
581.2000000000075,63.48642415452677,0.34691770224333507,-1.8397522322067439
582.3000000000076,63.59583796154182,0.3509083189332898,-1.8477967181964603
583.4000000000076,63.70624799900025,0.35166577586856285,-1.8548065847000719
584.5000000000076,63.815393729262325,0.35064594679866423,-1.8602367214268227
585.6000000000076,63.923951069215505,0.35291551680893896,-1.8678828743303204
586.7000000000077,64.03372503432705,0.35260791742566644,-1.8751451209936976
587.8000000000077,64.1427597430294,0.35258159136612255,-1.883149664347906
588.9000000000076,64.25204866510705,0.35617607122710976,-1.890246833078519
590.0000000000076,64.36114870577099,0.3583822425057415,-1.8980356970977956
591.1000000000076,64.4710273086666,0.3598140213403599,-1.9054365810409166
592.2000000000077,64.57994175122269,0.3618692483977308,-1.9144466516769665
593.3000000000077,64.68907215954673,0.3590566884052151,-1.9228400360331621
594.4000000000077,64.7985765707962,0.3636210727731922,-1.930914128824086
595.5000000000077,64.90628728333607,0.3662783148671165,-1.9403746607664845
596.6000000000078,65.01650259557405,0.3632432801484952,-1.9490780479463585
597.7000000000078,65.12636109564848,0.3643245636063266,-1.9581386708294897
598.8000000000078,65.23561969151528,0.3647887033356449,-1.966967244545121
599.9000000000078,65.34587944916329,0.3632526408076823,-1.9769356113654326
601.0000000000078,65.45506158026781,0.3638165678023666,-1.9865376138674873
602.1000000000079,65.5639646940355,0.36321353476631013,-1.9969230328984002
603.2000000000079,65.67360394081935,0.3618905942975505,-2.005385524207266
604.3000000000079,65.78393078269562,0.35840451660620526,-2.012124010334036
605.4000000000078,65.89295698290162,0.3566612317253254,-2.0219531313746812
606.5000000000078,66.00292815161963,0.3541132983890626,-2.0304014960789187
607.6000000000079,66.1116886862072,0.34907166475125884,-2.036872812374609
608.7000000000079,66.22225645565338,0.3481714042174953,-2.0412876455850157
609.8000000000079,66.33126275061193,0.3480920407223649,-2.046476604918931
610.9000000000079,66.43905994865918,0.3509213543705786,-2.051291897029419
612.000000000008,66.55103071734128,0.35031190899403625,-2.053940265803978
613.100000000008,66.66012180452812,0.3509219316722494,-2.054271183481576
614.200000000008,66.76980528089025,0.3476956428131279,-2.055578947855002
615.300000000008,66.8789775329408,0.34940960123901293,-2.056569476868553
616.400000000008,66.98866491127401,0.35796757717672756,-2.0578660407300435
617.5000000000081,67.09815881514866,0.3618403024811195,-2.0592000614264188
618.6000000000081,67.20556954234576,0.369444987223209,-2.0605543544777123
619.7000000000081,67.31715354157323,0.3779560934125392,-2.062816556804832
620.8000000000081,67.42651940916255,0.3826366386318807,-2.062477559304927
621.9000000000082,67.53655344329685,0.38880987650569304,-2.064528978568706
623.0000000000082,67.64656595906612,0.3927933498421051,-2.0643892477670214
624.1000000000081,67.75685293573669,0.39523645816259617,-2.067087867281145
625.2000000000081,67.86635016508899,0.4010644847921471,-2.0684200786538476
626.3000000000081,67.97605079090116,0.4073087515523589,-2.0697342810245773
627.4000000000082,68.08549295275125,0.4111974046396127,-2.072482638117093
628.5000000000082,68.19623847551549,0.4165301933542241,-2.0724835863362254
629.6000000000082,68.30566690282154,0.4186010711050848,-2.0748414161264463
630.7000000000082,68.41546377730893,0.4241961325590921,-2.076710550152844
631.8000000000083,68.52453853484718,0.4322806352823488,-2.0774284473340954
632.9000000000083,68.63352554033189,0.4381033376909578,-2.0787415991264004
634.0000000000083,68.74445260412418,0.4431476827098438,-2.0799799968276105
635.1000000000083,68.85375585189696,0.4516345861826052,-2.082688050385674
636.2000000000083,68.96478228444123,0.4617298223571073,-2.0840098629316595
637.3000000000084,69.07386183922394,0.465652552030993,-2.0853773109749842
638.4000000000084,69.18145480758685,0.4725976065928809,-2.0878831630979664
639.5000000000084,69.29380122198683,0.481115438938591,-2.089938580230893
640.6000000000083,69.40313511056097,0.4900226632761383,-2.092634609101408
641.7000000000083,69.51330924527261,0.4990044877081662,-2.0932826162985343
642.8000000000084,69.62170346869841,0.5109335209705426,-2.0951421804554973
643.9000000000084,69.73250802476856,0.5203707294762484,-2.099203826630885
645.0000000000084,69.84289961857924,0.530944598984842,-2.10162507224072
646.1000000000084,69.95256563343497,0.5469849543084305,-2.105846811367215
647.2000000000085,70.06255803828948,0.5589970015061717,-2.108119689749015
648.3000000000085,70.17234493772122,0.5749003858024565,-2.1099598712169665
649.4000000000085,70.28255989522447,0.5908922412054884,-2.1138577997562624
650.5000000000085,70.39221554932499,0.604612469394311,-2.1153205123441428
651.6000000000085,70.50248685696393,0.6220723877766501,-2.1195053860929116
652.7000000000086,70.61268359827652,0.6408946256434095,-2.120711992869806
653.8000000000086,70.7230173254445,0.6618951013893257,-2.1248290603386852
654.9000000000086,70.83159527037954,0.6824717629548225,-2.128576964935074
656.0000000000086,70.94211606916245,0.6995717337245323,-2.132676635386624
657.1000000000087,71.05354034051167,0.7165357147377098,-2.1371213647410814
658.2000000000087,71.16293768839829,0.7378667972811811,-2.1421001171204437
659.3000000000086,71.27357360526707,0.7574739951575042,-2.1451616049385733
660.4000000000086,71.38444808232867,0.7778873974445342,-2.150560316625941
661.5000000000086,71.49298049363846,0.7991219450245874,-2.154806853042686
662.6000000000087,71.60436671778977,0.8234012777407758,-2.159586017038668
663.7000000000087,71.71400475449909,0.8467325692174894,-2.164431068506885
664.8000000000087,71.82508238751905,0.8704640682408221,-2.169580263516158
665.9000000000087,71.9339845621551,0.89017999946747,-2.1741315614232084
667.0000000000088,72.04486044782982,0.9168703082300935,-2.180582907574628
668.1000000000088,72.15550985728089,0.940444763145142,-2.185142033651075
669.2000000000088,72.26462035329519,0.9619699984842347,-2.190930588655026
670.3000000000088,72.37542636194381,0.9873572683736309,-2.1957676658776784
671.4000000000088,72.4847972517333,1.010001523333238,-2.2023770835992966
672.5000000000089,72.59489302955352,1.035657464937067,-2.209202422749639
673.6000000000089,72.70621663016304,1.0615783100380298,-2.215660890417704
674.7000000000089,72.81590915736908,1.0846256279527582,-2.2209122951689655
675.8000000000088,72.92560867979583,1.108962604539151,-2.2288479868898383
676.9000000000088,73.03620595038088,1.1377542195217858,-2.235689030626806
678.0000000000089,73.14639139722352,1.1674936514030572,-2.242999289941022
679.1000000000089,73.25652056227288,1.1943967647240497,-2.2502585113154607
680.2000000000089,73.36709699429419,1.2165029041503206,-2.2574202150104465
681.3000000000089,73.47744815667399,1.241575611661937,-2.2659816321024966
682.400000000009,73.58748112110675,1.271085384476753,-2.273027458068845
683.500000000009,73.69714234139529,1.2996247321827168,-2.2824357205224013
684.600000000009,73.80703963343308,1.3286717185454335,-2.291179762788753
685.700000000009,73.9166465279386,1.3537061541258386,-2.2991455235692957
686.800000000009,74.02788400827906,1.380357770023368,-2.3072886568569757
687.9000000000091,74.13813398713643,1.404003303277235,-2.3161179523837587
689.0000000000091,74.24676267850468,1.4341868436221903,-2.3258346448870855
690.1000000000091,74.35644918294398,1.4588353047216172,-2.334857713045559
691.2000000000091,74.46702218509604,1.4858565683292704,-2.3433867803071196
692.3000000000092,74.57647070875788,1.5166865858035126,-2.3537511296995346
693.4000000000092,74.68614116601012,1.546857024201596,-2.3638517645239996
694.5000000000091,74.79723773715938,1.5787433291900346,-2.3737962374364185
695.6000000000091,74.90633086751535,1.6074639799215276,-2.3842888932697863
696.7000000000091,75.01618980117931,1.6388724293493542,-2.3957441951657077
697.8000000000092,75.12692352102515,1.6730892019622892,-2.4054438633470236
698.9000000000092,75.23717362163418,1.7078201907572965,-2.4155143605600538
700.0000000000092,75.34754319758747,1.7439049083141944,-2.4269682542699584
701.1000000000092,75.45805197585456,1.781127962239335,-2.436535451724803
702.2000000000093,75.56798267570488,1.820412054104408,-2.4491502219807666
703.3000000000093,75.678882648264,1.8577246658538598,-2.4597752524617884
704.4000000000093,75.78896261090783,1.8991919061929021,-2.4726125874386016
705.5000000000093,75.89917000000094,1.9361708341322261,-2.4843900650000927
706.6000000000093,76.01030872656153,1.9781531591325028,-2.4966751763680692
707.7000000000094,76.12056229001696,2.0126442886148106,-2.509351390862088
708.8000000000094,76.23126078925871,2.0446439865556365,-2.521960726822336
709.9000000000094,76.34152776353632,2.0760907407644154,-2.5350822053002147
711.0000000000093,76.45023154750714,2.1005299226920635,-2.5479948724554387
712.1000000000093,76.56174531453878,2.1278330145980124,-2.560723424808661
713.2000000000094,76.67260592552623,2.141733492164727,-2.573647751161624
714.3000000000094,76.7815621294349,2.1528136314361257,-2.5871772268055944
715.4000000000094,76.89220196736618,2.153850969418835,-2.600951307594716
716.5000000000094,77.00313346325498,2.1509945771400907,-2.6149427924332262
717.6000000000095,77.11379195636694,2.1342759978439907,-2.6277719430042215
718.7000000000095,77.22287061760541,2.1058727153990286,-2.640585709374921
719.8000000000095,77.33327466881332,2.068371922157565,-2.6528194359186834
720.9000000000095,77.44335796250758,2.019868978030698,-2.6664338297564285
722.0000000000095,77.55333482539412,1.9483574251297258,-2.6781479257616816
723.1000000000096,77.66284198177276,1.8611050119998442,-2.689045907898012
724.2000000000096,77.77228933807177,1.7483967750254499,-2.699819192233932
725.3000000000096,77.88242889732255,1.6058040332277956,-2.710553186076481
726.4000000000096,77.99247919009531,1.3926660798842025,-2.7199138867258057
727.5000000000097,78.10190702130387,1.0021813176683716,-2.727869491655987
728.6000000000097,78.21069077045907,0.5629537674025538,-2.7318345579845893
729.7000000000096,78.3204364374437,0.3431764781055092,-2.733144098656983
730.8000000000096,78.43019034951831,0.248647649044306,-2.7344698013786206
731.9000000000096,78.53970202508127,0.2063860885150981,-2.7357902272341823
733.0000000000097,78.64926631764794,0.17869149154095865,-2.737109962551565
734.1000000000097,78.75957351597961,0.1607160307646216,-2.7378128899656424
735.2000000000097,78.8699223596132,0.14874832555112222,-2.7371198080923644
736.3000000000097,78.9801686584753,0.14408084812859906,-2.737759798420112
737.4000000000098,79.09135512143018,0.13847584621189613,-2.738429514467045
738.5000000000098,79.2011260069711,0.1325819536746774,-2.7383500948508397
739.6000000000098,79.31197220098767,0.13103635796294116,-2.738751637858531
740.7000000000098,79.42252673214702,0.12978027542814535,-2.7387707736072064
741.8000000000098,79.53256097170865,0.1275791237851847,-2.739389509222474
742.9000000000099,79.64405066892346,0.13026629245511967,-2.7401025723262746
744.0000000000099,79.75453311825677,0.1313744248055851,-2.7400596331817946
745.1000000000099,79.86418252176902,0.12911178454171124,-2.740392095331219
746.0000000000099,79.95535266246877,0.13235134101886464,-2.740347958928398