File: 01_Data/Polyester_Carpet_High_Pile/STA/N2/10K_min/Polyester_Carpet_High_Pile_STA_N2_10KData_220907_R1.csv
##Temp./Â°C,Time/min,DSC/(mW/mg),Mass loss/mg
51.0,10.844870410139501,0.03593641759824462,-0.006238001475406207
52.100000000000016,11.186170941633602,0.06686932989490346,-0.007169266910659999
53.20000000000003,11.428308743625747,0.08895522284779966,-0.00691448961119967
54.30000000000005,11.631369371294689,0.10417893895955088,-0.007035679604758371
55.40000000000006,11.816758464492617,0.11999134596179539,-0.006354623777585999
56.50000000000008,11.986857609805545,0.12972463777268817,-0.006993917793237436
57.600000000000094,12.14695040041938,0.13992812996194792,-0.005234751138661231
58.70000000000011,12.300825123904737,0.14845885645553847,-0.00549496682968087
59.800000000000125,12.446871337063682,0.15489593781144406,-0.005832103918823606
60.90000000000014,12.598151999492016,0.16055331559821218,-0.005983200049165305
62.000000000000156,12.739862843993205,0.16631759358285958,-0.0057388771925648285
63.10000000000017,12.879747451992749,0.17040546125164613,-0.005731654345657589
64.20000000000019,13.016714145616318,0.17666867534654074,-0.005759306996020008
65.30000000000021,13.151000098306719,0.17852721433484176,-0.007759235750528504
66.40000000000022,13.285850487729473,0.1825459540638441,-0.006473359106928811
67.50000000000023,13.416270197392521,0.18640226864899923,-0.007282215217103705
68.60000000000025,13.54204817718195,0.1908039499466192,-0.007914898340959375
69.70000000000027,13.673638090931382,0.19508607846302695,-0.007335854138057485
70.80000000000028,13.799076343132644,0.19559579829105422,-0.007349644058753491
71.90000000000029,13.9258052630774,0.20115614263621395,-0.007365444604411131
73.00000000000031,14.04963020432398,0.2042975234117812,-0.005997017243667635
74.10000000000034,14.174316662220372,0.20911017566554435,-0.0066995585068090335
75.20000000000034,14.296923947990548,0.21000886813716357,-0.007414780260284637
76.30000000000035,14.416699405286963,0.21209166403057667,-0.0074702806032336255
77.40000000000038,14.538497279621454,0.21058542926128498,-0.007491472091333939
78.5000000000004,14.657837606291764,0.21147073698001917,-0.008607278174191713
79.6000000000004,14.776895334543658,0.21133103670862552,-0.007503099360520515
80.70000000000041,14.894440949830535,0.2107918905773788,-0.008816363519601467
81.80000000000044,15.012917107092381,0.21198385900258487,-0.010090215548817838
82.90000000000046,15.130142905986357,0.20852804490028565,-0.008782422030181536
84.00000000000047,15.24574762005602,0.211055787925424,-0.009183475106426364
85.10000000000048,15.361723866427685,0.21120277569281787,-0.010127641455591974
86.2000000000005,15.477134767370188,0.21143518444222142,-0.009708716887980806
87.30000000000052,15.591637801908453,0.21092256874794968,-0.009314192021256495
88.40000000000053,15.705166144194592,0.21040278627642495,-0.010848848018562673
89.50000000000054,15.817708879111866,0.2128454285188277,-0.008789552916960375
90.60000000000056,15.93010761434151,0.21185264599386988,-0.01117605342200445
91.70000000000059,16.042790653485767,0.2128849044940595,-0.009445081662811994
92.8000000000006,16.155589495555315,0.2122691769198023,-0.010205022138241926
93.9000000000006,16.266038739405854,0.21249063819427816,-0.010531902128725346
95.00000000000063,16.37788342556013,0.21604368223924308,-0.011450517834581397
96.10000000000065,16.487392040373194,0.21437225584169184,-0.010104060589104069
97.20000000000066,16.596021885852885,0.21689003363474735,-0.010200478450014483
98.30000000000067,16.706295669157935,0.21656798479720607,-0.008849320306617336
99.40000000000069,16.81865509885866,0.21981364072574006,-0.01142319894317989
100.50000000000071,16.92768769954109,0.2182820045404421,-0.011565214773235688
101.60000000000072,17.03633966969671,0.21996793292965977,-0.0114043131721977
102.70000000000073,17.145876945414653,0.22137561804236017,-0.01142136586918685
103.80000000000075,17.25476291491063,0.22203537624366865,-0.011793050343248623
104.90000000000077,17.364320337771787,0.2250291781881566,-0.012680815262321232
106.00000000000078,17.472032958942986,0.22607317395624849,-0.010269968598935808
107.10000000000079,17.580000000000073,0.2281185638684362,-0.011421213429998467
108.20000000000081,17.688130598221907,0.23087797592260728,-0.011422814317661789
109.30000000000084,17.795790660956882,0.23377896593774639,-0.012729421171272293
110.40000000000084,17.9047348517409,0.23281738014234077,-0.011421375797758593
111.50000000000085,18.01133234798796,0.23513926927371465,-0.011432776376887333
112.60000000000088,18.120386057599198,0.23471912551070073,-0.012746701615614864
113.7000000000009,18.228235122778113,0.23374413888592793,-0.011424714078532627
114.8000000000009,18.335288306786993,0.237652483097751,-0.011420895013340981
115.90000000000092,18.442607691150165,0.23947978336678355,-0.011420112770553992
117.00000000000094,18.550966870205635,0.24025950147012842,-0.011425759556975112
118.10000000000096,18.657254440318304,0.24025860694357648,-0.012209952538153601
119.20000000000097,18.76461093937761,0.24225210709082645,-0.01141668960513087
120.30000000000098,18.871771037183528,0.2445331492284989,-0.012731902958770025
121.400000000001,18.979796171472145,0.24292773513525667,-0.012738264280375056
122.50000000000102,19.0872366011826,0.24523014499728535,-0.012745626797704634
123.60000000000103,19.19340871741549,0.24533871172974608,-0.01153355469316697
124.70000000000104,19.297699626550106,0.2459193036475973,-0.01404370873067462
125.80000000000106,19.407898867379917,0.2469193647790805,-0.014060590451986599
126.90000000000109,19.514536050787804,0.2494720196627429,-0.012738180959042555
128.00000000000108,19.62136320162549,0.2522819980651324,-0.014165845960722123
129.1000000000011,19.727523364175802,0.25212627495903006,-0.014059760419108613
130.20000000000113,19.83341768512662,0.2523716596303711,-0.012749684207179257
131.30000000000115,19.94080221091575,0.25291496163920046,-0.014060007817461084
132.40000000000117,20.045481586764346,0.2564603722212694,-0.014060291526107882
133.50000000000117,20.15258259935905,0.2560959585769462,-0.01277041914702215
134.6000000000012,20.258472416761634,0.25885965841473346,-0.0140388617806817
135.7000000000012,20.36451468179048,0.26103037172914023,-0.014039762507653819
136.8000000000012,20.470202132656432,0.26243248460330815,-0.014048741241670992
137.90000000000123,20.575391756736614,0.26492395752316156,-0.01406016965095791
139.00000000000125,20.680976131785037,0.2635515594247221,-0.014973571901531813
140.10000000000127,20.787206261529185,0.2661989006343851,-0.014057613525868096
141.2000000000013,20.892322196142036,0.26849171660535354,-0.015365249088692412
142.3000000000013,20.997941799887975,0.2677823289065522,-0.014060027021636667
143.4000000000013,21.102170907475006,0.2696868951677249,-0.014061046736383087
144.50000000000134,21.20749677638899,0.27254234866088256,-0.014050100024273426
145.60000000000133,21.312327164810878,0.2742879029558033,-0.012702632213133835
146.70000000000135,21.41828211102352,0.2761120306386837,-0.013964463470453214
147.80000000000138,21.523081665084256,0.2764123795092751,-0.014059909899634793
148.9000000000014,21.627559573894878,0.28021743171691893,-0.014059322527852025
150.00000000000142,21.731980499080827,0.28288342819311296,-0.012740890984072273
151.10000000000142,21.836778465839426,0.2857189531145947,-0.014060074958106128
152.20000000000144,21.94137178754897,0.28977221747010695,-0.013967924062888049
153.30000000000146,22.04684329892146,0.2923540512009871,-0.014050547216475806
154.40000000000146,22.150688054441932,0.299288926488652,-0.015367156595324172
155.50000000000148,22.256336214454464,0.30295194860967845,-0.01405992123708133
156.6000000000015,22.360313699346964,0.30844486113072483,-0.013291782669700325
157.70000000000152,22.464342933507744,0.3154688441089988,-0.014390137539643355
158.80000000000155,22.570000000000164,0.3242487499781267,-0.015479210265000987
159.90000000000154,22.673737741086224,0.3326466754627636,-0.01408421978217067
161.00000000000156,22.77971248506744,0.34162381488985655,-0.015367204165628756
162.1000000000016,22.882978596836626,0.3487411858108488,-0.01405058685678684
163.20000000000158,22.987957480780715,0.35527588342417754,-0.015370042265880457
164.3000000000016,23.093596325848097,0.36160183469665086,-0.01555053472599921
165.40000000000163,23.196631303999727,0.3658696758270479,-0.015379972454507396
166.50000000000165,23.302001824795926,0.36194689025714616,-0.0166073493791572
167.60000000000167,23.40694447075379,0.3511914730052018,-0.015379891703169779
168.70000000000167,23.510189485974806,0.33481246711691975,-0.01537985919220608
169.8000000000017,23.61587711075827,0.321527440756203,-0.015369274336435979
170.9000000000017,23.720190591900344,0.3088926723778787,-0.01541895690283912
172.0000000000017,23.824109844642095,0.29767166655386434,-0.01630526507484431
173.10000000000173,23.929907493317597,0.2948285445363923,-0.01537057435143696
174.20000000000175,24.031841847199114,0.2896532886136353,-0.016030506909322728
175.30000000000177,24.137962169467837,0.2856904774580643,-0.01537314520937727
176.4000000000018,24.242526307661148,0.28514785607138476,-0.016370039683045068
177.5000000000018,24.34621003415099,0.2837966121901049,-0.01563561551554038
178.6000000000018,24.452733597634385,0.2847640622834658,-0.01669036028886195
179.70000000000184,24.556298987006908,0.283914220934609,-0.01674356340537342
180.80000000000183,24.66214909427056,0.28398183531691057,-0.015699881641653146
181.90000000000185,24.765491897698755,0.2841105942337119,-0.01571285794864208
183.00000000000188,24.869570158855456,0.2872933840308956,-0.01740291397139959
184.1000000000019,24.972836992689324,0.28659098681900663,-0.016699764339477063
185.20000000000192,25.07778619335573,0.2877888491992464,-0.016700192999461017
186.30000000000192,25.1817918830416,0.2872100134756886,-0.016699783401767476
187.40000000000194,25.286234149309198,0.2899703435199443,-0.016713348459702182
188.50000000000196,25.390407694946614,0.29025045944745537,-0.016647946824246862
189.60000000000196,25.495141932228215,0.29012943554380943,-0.017677463829626205
190.70000000000198,25.599401012299687,0.28884542692747417,-0.016354151693909635
191.800000000002,25.703163929183138,0.2888972840111318,-0.017672807266692736
192.90000000000202,25.808359830534073,0.2890007387589011,-0.017677719821348692
194.00000000000205,25.912981278325805,0.29059876495523446,-0.01767957080022553
195.10000000000204,26.01596180615851,0.2916126453423441,-0.01774866905897854
196.20000000000206,26.122693036091405,0.2918752650177422,-0.017683481665260015
197.3000000000021,26.224667027338427,0.2912306623617103,-0.01863785618071212
198.40000000000208,26.32971864509666,0.2913809583736845,-0.018659873878755118
199.5000000000021,26.433328516823252,0.29448612656301065,-0.01763551415359288
200.60000000000213,26.537443627787756,0.29489151796016194,-0.017679664336349266
201.70000000000215,26.642800455837687,0.29590976401159463,-0.019000127568158387
202.80000000000217,26.747406403244437,0.2966077082038812,-0.017651571442770297
203.90000000000217,26.851777031570844,0.29836499456979115,-0.017677472314362674
205.0000000000022,26.95626299180118,0.2990955806895855,-0.019000128745231493
206.1000000000022,27.059361196483014,0.29879016252951696,-0.0189996680313671
207.2000000000022,27.163963504204045,0.30072454465516457,-0.01899994382023662
208.30000000000223,27.26856058194008,0.30068693379963074,-0.019590358574071765
209.40000000000225,27.37301901496748,0.3022061451227971,-0.019660090192370916
210.50000000000227,27.476417794557484,0.3045092220882038,-0.019968483254916958
211.6000000000023,27.582267080362147,0.3050072565431985,-0.01964996893323878
212.7000000000023,27.685643384746182,0.3075315909156743,-0.019317814482560536
213.8000000000023,27.789823077439465,0.3073053460384175,-0.019319927501788126
214.90000000000234,27.89470744121418,0.3081628270517006,-0.020598402052273368
216.00000000000233,27.998912961262455,0.30939892474496594,-0.020711446952544232
217.10000000000235,28.10327439202573,0.31062969892224535,-0.02064993094461487
218.20000000000238,28.207792881273306,0.3123523720533961,-0.020648213722633812
219.3000000000024,28.312035358596294,0.3125336076078504,-0.02064983856159408
220.40000000000242,28.41549620458333,0.312484456516157,-0.020649797950957005
221.50000000000242,28.52109521578243,0.312574760725653,-0.021959814207362705
222.60000000000244,28.625334007665266,0.313597275886685,-0.02196005460778494
223.70000000000246,28.730695007827773,0.3151429006405962,-0.020640029496292733
224.80000000000246,28.834646733112738,0.31526002124589186,-0.02064014799952174
225.90000000000248,28.938845136419726,0.31882259353904346,-0.02064014647610035
227.0000000000025,29.04274458198458,0.31956818899007344,-0.021288300999059206
228.10000000000252,29.147864827376146,0.3219698330360337,-0.02130026588503542
229.20000000000255,29.25296667687733,0.32350321245731306,-0.02261995121501137
230.30000000000254,29.35727969697182,0.32583546895901055,-0.021960133992392716
231.40000000000256,29.461313237600866,0.327077139854203,-0.0227323657821481
232.5000000000026,29.56750464482175,0.32989809074247733,-0.022585917799283983
233.60000000000258,29.67050375195597,0.33248754928100793,-0.020968835678495612
234.7000000000026,29.775806000878667,0.3370511951998818,-0.022619672585289408
235.80000000000263,29.880093305611346,0.3402454771445916,-0.02393985982397906
236.90000000000265,29.985486763539118,0.3456031652735332,-0.02263180676897747
238.00000000000267,30.09000000000027,0.35010739112315453,-0.022545550105346646
239.10000000000267,30.195124092709367,0.35540318341023225,-0.02393998891999294
240.2000000000027,30.300204625091936,0.365583684686838,-0.023939988999999606
241.3000000000027,30.403984715613248,0.37549630417113955,-0.023939988999980066
242.4000000000027,30.509689787860946,0.3880991796053981,-0.023939961847792013
243.50000000000273,30.61344275091996,0.40449563056698673,-0.023939083232052294
244.60000000000275,30.718476896815346,0.42189663283106593,-0.023939897018434575
245.70000000000277,30.82380870243502,0.4525467735571264,-0.023947670082018035
246.8000000000028,30.928770933858686,0.49136346760678706,-0.025259896944595628
247.9000000000028,31.034291901521758,0.5406473205114838,-0.025259896999999754
249.0000000000028,31.138217486828744,0.5865146169560974,-0.025259896999600517
250.10000000000284,31.243452399129175,0.6128056946298649,-0.025259629605027367
251.20000000000283,31.348997848115662,0.6080650575893701,-0.026570222381939956
252.30000000000285,31.450787456392412,0.574027821173654,-0.025911898481319806
253.40000000000288,31.55650261587846,0.5239915808935088,-0.02499795639238167
254.5000000000029,31.66291265124063,0.47217026167839693,-0.025909855705045448
255.60000000000292,31.766807369509227,0.43088231703979485,-0.025254120271720915
256.7000000000029,31.87132562418934,0.3995701866628951,-0.026239811930458323
257.8000000000029,31.975065327728867,0.3738433334554491,-0.02659119346426131
258.90000000000293,32.08057594846465,0.35717278715324674,-0.026569805051140705
260.00000000000296,32.18508265459199,0.3444413748205333,-0.02656980499048478
261.100000000003,32.290618940005515,0.3327403739108955,-0.026504950211847067
262.200000000003,32.394273435900324,0.32818850684223877,-0.027796384039662225
263.300000000003,32.499405583013186,0.32478985177961267,-0.028596288082979093
264.40000000000305,32.60379777345615,0.3200142511127718,-0.02920471666130897
265.50000000000307,32.70898712300277,0.3202433824222345,-0.029540035205968707
266.6000000000031,32.81383092584519,0.31766651503577714,-0.02936024651784619
267.7000000000031,32.91860980932289,0.3165914634485404,-0.029539844748598387
268.8000000000031,33.023883060710254,0.31693985966589294,-0.030268673566855586
269.9000000000031,33.12799333109025,0.31642167092260637,-0.03216822511512252
271.0000000000031,33.23296965357944,0.3179365772132917,-0.030861621121162308
272.10000000000315,33.338531834668416,0.3190862270419347,-0.030863419376354617
273.2000000000032,33.44371801454057,0.31866946813223607,-0.032169894140089195
274.30000000000314,33.54836315072074,0.31888253159628055,-0.031147198118141706
275.40000000000316,33.652784268971665,0.31899968424862424,-0.03248308327267457
276.5000000000032,33.75896102744359,0.31910319837245504,-0.033486670059828416
277.6000000000032,33.86434038898513,0.3199121781396358,-0.03348989699787985
278.70000000000323,33.96909485123793,0.3194751013172393,-0.03349675741273028
279.80000000000325,34.074502377623666,0.320611094704714,-0.03480989820450109
280.9000000000033,34.179456582427704,0.3183422010874638,-0.03480989699999926
282.0000000000033,34.28226715477315,0.32009543781608746,-0.03480989700020176
283.1000000000033,34.389705900883875,0.3193332910903256,-0.034809670717824925
284.20000000000334,34.49455448310811,0.3211442283086511,-0.03612988494876568
285.30000000000337,34.600174265052594,0.32298051016387375,-0.03613019130560646
286.40000000000333,34.70544855535029,0.3232846204073735,-0.03645991727948816
287.50000000000335,34.811091295977086,0.32295571795157085,-0.037213203240085146
288.6000000000034,34.91602503967471,0.3238957569838814,-0.037780195154986984
289.7000000000034,35.021048278000066,0.3240486958812302,-0.038765114345088225
290.8000000000034,35.12749752006171,0.32476224753292104,-0.03739530633567556
291.9000000000034,35.231878851192455,0.3271700116445717,-0.03973869953371523
293.0000000000034,35.337741908213474,0.32813215770949467,-0.0397400329979658
294.10000000000343,35.4406122665914,0.3287862496368309,-0.03974003299999973
295.20000000000346,35.54652501371025,0.3331278977957291,-0.039740033051249846
296.3000000000035,35.65203389336395,0.3326907321656172,-0.03968984256184882
297.4000000000035,35.75679515041889,0.33610228684163507,-0.0410575167397611
298.5000000000035,35.86377336260609,0.33872639743909394,-0.041389451225920304
299.60000000000355,35.97009039998717,0.33965346829415877,-0.042380126987811906
300.70000000000357,36.074218217011286,0.34317915710685537,-0.04362570067568772
301.8000000000036,36.18062609493363,0.34400348093650324,-0.045015712644098205
302.9000000000036,36.285136102174064,0.3473558284424554,-0.045019838977430116
304.0000000000036,36.39008589512797,0.3486004205775523,-0.045019843861228814
305.1000000000036,36.49539626756785,0.3516680456746877,-0.04661799826312807
306.2000000000036,36.601531363452246,0.3547195325120285,-0.04666993097941985
307.30000000000365,36.704372960295366,0.3574761066427635,-0.046625471922913775
308.4000000000037,36.81154317834537,0.36110013141008424,-0.04798723677021588
309.5000000000037,36.91768144354715,0.3645052451693639,-0.050436477536679014
310.60000000000366,37.02353495916599,0.36776150471946556,-0.050620075480253934
311.7000000000037,37.128156808551694,0.37065485709232493,-0.051284444857222056
312.8000000000037,37.2344447698768,0.37621025466470825,-0.051273999329626285
313.90000000000373,37.33938449958893,0.37698458886940645,-0.05392593353253394
315.00000000000375,37.44499981539738,0.38035370355975,-0.055219875229329585
316.1000000000038,37.55056887095761,0.3800823188615653,-0.056540198154962695
317.2000000000038,37.656239173208746,0.3785027245873679,-0.05755771547356403
318.3000000000038,37.762045286023984,0.3771142706520786,-0.05916805198828268
319.40000000000384,37.8681805853026,0.37480333669325616,-0.06048934235942749
320.5000000000038,37.97381719814337,0.3740523822241963,-0.06182443075654076
321.60000000000383,38.08009631016383,0.37085124669040914,-0.06543038903500387
322.70000000000385,38.186570409269336,0.3685462475906473,-0.06674795645687537
323.8000000000039,38.292663462391474,0.3673420409321805,-0.06865669238879057
324.9000000000039,38.39809479104275,0.36399591205844967,-0.0706932988941853
326.0000000000039,38.50415921835345,0.36321164242995,-0.0730013759077508
327.10000000000394,38.608247657281396,0.3620604541853353,-0.07467120823188722
328.2000000000039,38.71328123389283,0.36171334513237197,-0.07729162193373806
329.30000000000393,38.8192859159892,0.3600689363417609,-0.08025833104904168
330.40000000000396,38.929122642662854,0.36091455572912545,-0.08288465901641873
331.500000000004,39.03430040773363,0.3592587788607221,-0.08600335134602943
332.600000000004,39.1394205830472,0.35842894119082575,-0.08958596929523122
333.700000000004,39.243938166717896,0.3569198887789952,-0.09440744851611882
334.80000000000405,39.35156316054179,0.35591576928636387,-0.09771952781466853
335.90000000000407,39.4572011549403,0.3540276414649763,-0.10177865361430571
337.0000000000041,39.56344317313858,0.3551362279015727,-0.10602276125008236
338.10000000000406,39.6702138082137,0.351722426881027,-0.11023249410589875
339.2000000000041,39.77339890663199,0.3489985014758818,-0.1135860850213839
340.3000000000041,39.88175561167953,0.35111161694781423,-0.11906227581754969
341.4000000000041,39.988338268345444,0.34940167036799574,-0.12298511869000706
342.50000000000415,40.0934315994082,0.34775505363623405,-0.12943081088330244
343.6000000000042,40.19894047424237,0.3483213757871785,-0.13241606978258602
344.7000000000042,40.30471990026801,0.34532155835793354,-0.13727590879128693
345.80000000000416,40.41073236887551,0.34721942669010597,-0.14369921009918185
346.9000000000042,40.51727743126092,0.34899779692206107,-0.14775679403436914
348.0000000000042,40.62366110459957,0.3474557098707746,-0.15291476177984897
349.10000000000423,40.73019817453458,0.3470537705808665,-0.15963590301590935
350.20000000000425,40.8363160828776,0.3506491006592616,-0.1639228135583517
351.3000000000043,40.942395444397,0.3503639359316382,-0.17035210331548534
352.4000000000043,41.04833101364695,0.3509502163787263,-0.17656897440138275
353.5000000000043,41.15478300904706,0.3509229694314986,-0.181275714102485
354.60000000000434,41.26176030268935,0.3513999445296345,-0.18691170187436645
355.7000000000043,41.36656632143663,0.351778069008966,-0.19332828866223206
356.80000000000433,41.47442338196029,0.35369614518012926,-0.19790080276984812
357.90000000000435,41.58052693440161,0.3544051416459635,-0.20447014461017865
359.0000000000044,41.68690063940408,0.35492539943155,-0.20946933642548204
360.1000000000044,41.79243860403312,0.3555332746994292,-0.2165898995515465
361.2000000000044,41.9012074991999,0.3561208800582317,-0.22297882568777316
362.30000000000445,42.00698253031912,0.35582340883037356,-0.22836068803020382
363.4000000000044,42.11368225159117,0.3558963246344273,-0.23416249348324802
364.50000000000443,42.219592757276715,0.35559526626100446,-0.23918464484216173
365.60000000000446,42.32728617869485,0.35478730634848776,-0.24627915063139527
366.7000000000045,42.43312624005228,0.3558243898373421,-0.2512127735002436
367.8000000000045,42.540364347563255,0.35589678922480006,-0.25755149259751287
368.9000000000045,42.646513993117914,0.3549239965260148,-0.2637495957115088
370.00000000000455,42.75373325903224,0.35463441358549797,-0.2704700769005415
371.10000000000457,42.85937253956901,0.3546061179562766,-0.2755038844024198
372.2000000000046,42.96648996176735,0.35319553959712635,-0.2823272238678949
373.30000000000456,43.07306775293958,0.3515389937379926,-0.2862015088550929
374.4000000000046,43.1793859262329,0.35171239664896753,-0.2953174318877392
375.5000000000046,43.286833418770144,0.3516548184081728,-0.29990878440495816
376.6000000000046,43.39267655892083,0.35024346653413224,-0.30678726244354193
377.70000000000465,43.50029656686692,0.34949306650448714,-0.3132125665739163
378.8000000000047,43.60590577155149,0.34839097509344674,-0.31930680942855405
379.9000000000047,43.71323186156086,0.34684939936023707,-0.32550727957405945
381.00000000000466,43.8194626749216,0.3468863968675435,-0.3334955042049481
382.1000000000047,43.92761110587719,0.34623345918572523,-0.3399129423002183
383.2000000000047,44.03464354838922,0.34544043552648274,-0.3468164207554114
384.30000000000473,44.14141440617122,0.34598244334634504,-0.35217404590499646
385.40000000000475,44.247692583030734,0.3468472809511911,-0.3587933500380731
386.5000000000048,44.354731630498335,0.3423646878040025,-0.36710756339903305
387.6000000000048,44.46225106249238,0.3424607441473969,-0.37370493866972865
388.7000000000048,44.5686319885584,0.3424622531385317,-0.3824941822127972
389.80000000000484,44.6756218616693,0.34302938299595387,-0.38982309693718786
390.9000000000048,44.78218222086777,0.3401697543788407,-0.3982091924921365
392.00000000000483,44.88957755697257,0.3416620363918398,-0.4059347957785602
393.10000000000485,44.99621175823886,0.34227310763192076,-0.4135246703930675
394.2000000000049,45.10310569201245,0.341502575814514,-0.4232850296054047
395.3000000000049,45.2097973300576,0.34161538049886325,-0.4312065367398654
396.4000000000049,45.317206209625574,0.34349122189804815,-0.4409014963734039
397.50000000000495,45.42392545361919,0.34327073723287466,-0.44818570820597703
398.6000000000049,45.53010474503414,0.3421260205572615,-0.4590214474285932
399.70000000000493,45.637398318292014,0.3423803298690519,-0.4686115853515429
400.80000000000496,45.74464662938309,0.3433485754456806,-0.4807959190417379
401.900000000005,45.85221868763677,0.34492508983918035,-0.4912536316906442
403.000000000005,45.9585061884413,0.34757650441296345,-0.5027967438486711
404.100000000005,46.066182218326006,0.346842307094162,-0.5129317377554323
405.20000000000505,46.17372700264276,0.3496827584653944,-0.524603599155097
406.30000000000507,46.27970606763534,0.35074537720556515,-0.5373655007215783
407.4000000000051,46.386557404250105,0.35633104044250336,-0.5511955534402113
408.50000000000506,46.493842052844364,0.3598612699597326,-0.5631985609734622
409.6000000000051,46.60079776433497,0.36186547569436467,-0.5769993019621444
410.7000000000051,46.708261289133134,0.3652751241223286,-0.5906532164455802
411.8000000000051,46.81443677706396,0.37118872330492647,-0.6052494008537921
412.90000000000515,46.92178573179133,0.3764906216563461,-0.6202322142583432
414.0000000000052,47.030094610484255,0.38160745602799856,-0.6372247979972441
415.1000000000052,47.13588498519589,0.38861965011744476,-0.6528212897792005
416.20000000000516,47.24292020765515,0.39329876583031775,-0.6702221584461028
417.3000000000052,47.349692312009516,0.4007325576725556,-0.6877415916571712
418.4000000000052,47.45588889918161,0.40738332781266046,-0.704975888627386
419.50000000000523,47.56194147222287,0.41456484926604864,-0.7255038335180783
420.60000000000525,47.67129376709114,0.4208187590604489,-0.7448206472473857
421.7000000000053,47.77832554156701,0.424569394635669,-0.7639693132838192
422.8000000000053,47.88624979271647,0.4269445000658487,-0.7842434856429792
423.9000000000053,47.993759636469846,0.4336817112466545,-0.806232415717322
425.00000000000534,48.100635760552315,0.43855768034231507,-0.8308140047031616
426.1000000000053,48.20727837907991,0.4425147973092444,-0.8532572144132464
427.20000000000533,48.31577430928751,0.4477568167623511,-0.8756025536219378
428.30000000000535,48.42251099060121,0.45245487268734125,-0.9020602558213984
429.4000000000054,48.53123536523519,0.4559507823772885,-0.9282922045566773
430.5000000000054,48.63899837168089,0.45939361946342616,-0.9527258487957893
431.6000000000054,48.74661899645127,0.46375378787456006,-0.9808545306914147
432.70000000000545,48.854919980333875,0.46435388116756443,-1.0076087434993153
433.8000000000054,48.962123005289435,0.4658759119430869,-1.0345796694788612
434.90000000000543,49.06947121215835,0.4667493746906757,-1.0644000218811627
436.00000000000546,49.179124506698166,0.46873600389000364,-1.091740452680165
437.1000000000055,49.286621000316785,0.4669744050846635,-1.1206192945324496
438.2000000000055,49.39244271843762,0.46756509464768437,-1.1487140188834624
439.3000000000055,49.503389999151665,0.46508663647931303,-1.1764535900367514
440.40000000000555,49.608516286178364,0.46056747761378536,-1.2031164412276545
441.50000000000557,49.716550035850666,0.4553604633933466,-1.229550976151308
442.6000000000056,49.82454330176887,0.4491503265526143,-1.2551618051510793
443.70000000000556,49.933279477082664,0.43845548819051644,-1.2783562302688223
444.8000000000056,50.04065924958831,0.43113445785096716,-1.2994923801568112
445.9000000000056,50.14886602487277,0.42249939662167435,-1.319434122079032
447.0000000000056,50.25793228350145,0.4111627320762311,-1.3385468284362112
448.10000000000565,50.366534399867874,0.3963590727263956,-1.3544076773979272
449.2000000000057,50.47314464431391,0.3814538228893065,-1.3684086151148507
450.3000000000057,50.582059462610886,0.36617852929623684,-1.382370803566678
451.40000000000566,50.689898922693814,0.35123158854529724,-1.3962172097098393
452.5000000000057,50.79787441113697,0.3424000676067232,-1.4069224460979974
453.6000000000057,50.90597059722024,0.33150422221299025,-1.417881833152248
454.70000000000573,51.01323527359915,0.3232139265726932,-1.4296935209492
455.80000000000575,51.119699912894006,0.3182101968946095,-1.4388003433837082
456.9000000000058,51.228839068347256,0.30957558671904467,-1.4498150784345034
458.0000000000058,51.33896737872759,0.31052174886707984,-1.4606908387829742
459.1000000000058,51.445621877263484,0.3055633497522154,-1.471788018649021
460.20000000000584,51.551869314266604,0.3069219946862534,-1.4808123587102964
461.3000000000058,51.66234015722057,0.30729423225521035,-1.4922553051507195
462.40000000000583,51.7687481025656,0.3072863396012926,-1.50325774771038
463.50000000000585,51.87820156925187,0.30657095020185576,-1.5129939012236289
464.6000000000059,51.98648739300384,0.3121869107214622,-1.5264693438796284
465.7000000000059,52.0949113712866,0.3149634287799241,-1.5383476724189138
466.8000000000059,52.201983477435476,0.31679936009498944,-1.5513670222176126
467.90000000000595,52.30971416124122,0.31657746575426937,-1.563736530131655
469.0000000000059,52.41897756636598,0.3194872968786569,-1.575635160097832
470.10000000000593,52.5257682413115,0.3200707601314404,-1.590255522061514
471.20000000000596,52.6340877307729,0.31797172526733547,-1.6044933911951125
472.300000000006,52.74165143536419,0.3135093233902749,-1.619286874572004
473.400000000006,52.84947787296007,0.30981171103436644,-1.631566702955228
474.500000000006,52.95727861242772,0.29858084760880504,-1.6448440057080127
475.60000000000605,53.06607399974922,0.2850254820590697,-1.659148647747846
476.70000000000607,53.17450840219408,0.27340451664316423,-1.6682956759011724
477.8000000000061,53.282862883938336,0.25926212758446654,-1.678575527366994
478.90000000000606,53.390509584999606,0.23826523373314668,-1.6848438491560542
480.0000000000061,53.49870035109295,0.21755166978770213,-1.691285578369854
481.1000000000061,53.606115986887275,0.19666190357615446,-1.697008821997903
482.2000000000061,53.71452186858244,0.179118929268318,-1.7002563958499097
483.30000000000615,53.82239238245872,0.16247123075533598,-1.7049266595362624
484.4000000000062,53.93019547026471,0.150855691769802,-1.7065802088528574
485.5000000000062,54.03839892575832,0.14166418323373703,-1.7091032058580087
486.60000000000616,54.145653361617704,0.13541103414125438,-1.7105158728979108
487.7000000000062,54.254318758081794,0.13384952214725088,-1.7118457354119285
488.8000000000062,54.36322364336411,0.13351245317904137,-1.7131701796675824
489.90000000000623,54.47193770218747,0.13106811628607343,-1.7135900217566977
491.00000000000625,54.580287689590286,0.13164337759088005,-1.715477296539674
492.1000000000063,54.6886609008854,0.13548288574588943,-1.7161399823081869
493.2000000000063,54.79747764644955,0.13704179972030334,-1.7174617492066857
494.3000000000063,54.90473153919645,0.1416371327560277,-1.718732916750652
495.40000000000634,55.012984440695995,0.147999957916489,-1.7200897937216046
496.5000000000063,55.12156847598712,0.1521188045181117,-1.7214113701147822
497.60000000000633,55.230093697370705,0.15184055727483203,-1.7227302114181788
498.70000000000636,55.33748814374904,0.1532663445993419,-1.724040076193306
499.8000000000064,55.446224234729996,0.15454328714462798,-1.725340475342045
500.9000000000064,55.55447892047223,0.15695370028326938,-1.7253815113620137
502.0000000000064,55.66270005778904,0.15881485050724278,-1.7281082955958853
503.10000000000645,55.77052700693388,0.1586585647817975,-1.729128245079738
504.2000000000064,55.87885268177296,0.15892924890953422,-1.729429842935403
505.30000000000643,55.98650738552992,0.16045731546645253,-1.7307399695641017
506.40000000000646,56.096579472055005,0.16074944356434812,-1.7309326797143454
507.5000000000065,56.203585982374214,0.16490795138633016,-1.7321239390637344
508.6000000000065,56.31305033730186,0.16648827799102237,-1.7333683257324282
509.7000000000065,56.42142148680962,0.16768899859278774,-1.733358196654882
510.80000000000655,56.53000084201532,0.16959292561374278,-1.7346899131537472
511.90000000000657,56.638254477049095,0.17162135696251596,-1.7360076855312325
513.0000000000066,56.74724684236563,0.17025862439658856,-1.7374665944533256
514.1000000000065,56.855936786078665,0.1741691422646899,-1.7386368502192648
515.2000000000066,56.96410208904875,0.17336795591989368,-1.7398912905402226
516.3000000000065,57.07239564745212,0.1733800670402948,-1.7412807811490585
517.4000000000067,57.180699392185254,0.17442775104829733,-1.74259020133697
518.5000000000066,57.28927547837836,0.17614828176172734,-1.7439104764631987
519.6000000000067,57.399096647056744,0.17898257716336674,-1.7439161660840687
520.7000000000066,57.507615563367345,0.17818630131503,-1.7452290790715344
521.8000000000067,57.61629513643,0.17588811339304733,-1.746540812434966
522.9000000000067,57.7245786970508,0.17652751820209236,-1.747859045098492
524.0000000000067,57.833430685538325,0.17732358414142835,-1.749463626192468
525.1000000000067,57.94282402415955,0.17639745756138342,-1.750493463850698
526.2000000000068,58.048286608163245,0.17891415799856514,-1.7526805515846409
527.3000000000068,58.15715245601533,0.17898896554817914,-1.7531316230512122
528.4000000000068,58.26855439873709,0.1770616977392751,-1.7544500940363346
529.5000000000068,58.37722404168857,0.1765533351483852,-1.7558000076477298
530.6000000000068,58.48651089955392,0.17945112624716492,-1.7574670593967072
531.7000000000069,58.5958506943255,0.1770305365544348,-1.7587305177245467
532.8000000000068,58.70478863076149,0.17654700864325668,-1.759338229788312
533.9000000000069,58.81331058798112,0.1762569391185228,-1.760930459812673
535.0000000000068,58.92223013868147,0.17482593704852525,-1.7623520867576268
536.100000000007,59.03061130338075,0.17152487265708521,-1.7643279942512287
537.2000000000069,59.139894261594016,0.17354347176983137,-1.7656500576732914
538.300000000007,59.24979986356827,0.1728907974999185,-1.765640318118975
539.4000000000069,59.35756327384236,0.1764136592438424,-1.7669558390244289
540.5000000000069,59.46742910620726,0.1729458534230024,-1.7682955635206783
541.600000000007,59.57725286277912,0.1736156113476931,-1.7695920463533747
542.700000000007,59.68644690530846,0.17474088670535076,-1.7715381918595674
543.800000000007,59.795583070837566,0.17489104225512753,-1.773553777260899
544.900000000007,59.904165657176094,0.17498289173703963,-1.7748720446659294
546.000000000007,60.014234070365475,0.17528626189623453,-1.7774750715701657
547.1000000000071,60.12304368749523,0.17480649520265376,-1.7788215817409592
548.2000000000071,60.23130720041926,0.17491632354707318,-1.7788753608532266
549.300000000007,60.34050254839021,0.1738856706562118,-1.7814612320466927
550.4000000000071,60.45010661375699,0.17637052570643807,-1.7831187210588166
551.500000000007,60.559700461902125,0.1774389705309729,-1.7853889474858002
552.6000000000072,60.66793498965491,0.1757634693231155,-1.7868916652190734
553.7000000000071,60.77733506670238,0.17679956209532793,-1.7902427477683398
554.8000000000072,60.88605683928916,0.17929142741338772,-1.791766792959196
555.9000000000071,60.995159964345866,0.1795609110862178,-1.7943074086788915
557.0000000000072,61.104342964038565,0.18025071266423537,-1.7969517126247911
558.1000000000072,61.21200072177331,0.17895699799095155,-1.799129048208644
559.2000000000072,61.32328980509412,0.1780988392074297,-1.8019215578627992
560.3000000000072,61.43225674109444,0.17526004707526216,-1.803802450854143
561.4000000000073,61.54078257560983,0.17645942500523237,-1.805787570144818
562.5000000000073,61.65039976225962,0.17355754922881494,-1.808019750858568
563.6000000000073,61.75937456026245,0.17407834034311306,-1.8130159421313614
564.7000000000073,61.86867659121877,0.17268391904020658,-1.8159862030007745
565.8000000000073,61.977280807282455,0.17033202683543208,-1.8198598048006907
566.9000000000074,62.086716561998976,0.1703275545380301,-1.8234538726335492
568.0000000000074,62.19504424336627,0.17432549009501308,-1.8273789552617843
569.1000000000074,62.30374587361338,0.17534351594444797,-1.8315996169933055
570.2000000000073,62.412346784645266,0.179805779866337,-1.8330425963002188
571.3000000000073,62.521881159555434,0.1801703377051208,-1.837565774894363
572.4000000000074,62.63088560531208,0.1853891412733195,-1.8437713085058163
573.5000000000074,62.73945191262962,0.19031838283002217,-1.8473931254328484
574.6000000000074,62.847884471305484,0.19412185586375816,-1.8515614041057171
575.7000000000074,62.95769325412238,0.19795463282370396,-1.8559460164078616
576.8000000000075,63.06682804254577,0.2010254865900189,-1.861859602013567
577.9000000000075,63.17606637812812,0.20603843263009933,-1.8682300519129482
579.0000000000075,63.28537442506157,0.20898201074455452,-1.8755184306207058
580.1000000000075,63.39492826730581,0.20691705163620833,-1.8818504243495195
581.2000000000075,63.5040141612334,0.20638412463432187,-1.8890115407078576
582.3000000000076,63.61293140053367,0.20661095754249342,-1.8958016353306033
583.4000000000076,63.72360019968576,0.20514666442202956,-1.901839076495318
584.5000000000076,63.83216816073516,0.2067360901672341,-1.909970362406368
585.6000000000076,63.94226740618468,0.20644355768465328,-1.9178890817022571
586.7000000000077,64.05176877194604,0.20721005097043022,-1.9267919916431664
587.8000000000077,64.16072651630338,0.20911420517177412,-1.9335840229824246
588.9000000000076,64.27060908045348,0.20872732017193835,-1.9418808664501634
590.0000000000076,64.37978768346369,0.20601231626882147,-1.9489872836216793
591.1000000000076,64.48990076906202,0.20820583208461435,-1.957760300208335
592.2000000000077,64.59977377852742,0.20845886132322408,-1.9673042463684562
593.3000000000077,64.70788669081401,0.20802657752381049,-1.9739906671342502
594.4000000000077,64.81727313656428,0.20978447211258464,-1.9837278966019118
595.5000000000077,64.92663300750807,0.20850779582971196,-1.9929796502144175
596.6000000000078,65.03717340097278,0.20558627965134213,-2.0019434895083954
597.7000000000078,65.14732384120053,0.20524270616777443,-2.011622585514611
598.8000000000078,65.25621235430228,0.20544987505231121,-2.0216377453582552
599.9000000000078,65.36619988840089,0.2060369578744446,-2.0318410809863368
601.0000000000078,65.47470261593477,0.20564632943119737,-2.0380653938239908
602.1000000000079,65.58536765373313,0.20321781499390415,-2.047839884727247
603.2000000000079,65.69380662032589,0.20008086246119614,-2.0568527301118147
604.3000000000079,65.80384413442707,0.19659043888138628,-2.0644581912050772
605.4000000000078,65.91315443732894,0.19346355420797381,-2.073919483448221
606.5000000000078,66.02280161436218,0.1869410575891531,-2.0805912297609477
607.6000000000079,66.13030328685109,0.183236592823016,-2.0851137652974416
608.7000000000079,66.24226241137671,0.1848392151305445,-2.0913276786037858
609.8000000000079,66.35000117855606,0.19182377552455357,-2.093900140115157
610.9000000000079,66.46096884827821,0.19398711853927597,-2.09528115995258
612.000000000008,66.57143756528482,0.19611714073524628,-2.0968584566726722
613.100000000008,66.68010082640753,0.19794921805929422,-2.0968706261049475
614.200000000008,66.78999885167642,0.20404715823046768,-2.0995001555029034
615.300000000008,66.89959027660241,0.20775581574395968,-2.0997958245405153
616.400000000008,67.00801631513426,0.21148321635377798,-2.101787240567341
617.5000000000081,67.11981977968614,0.21656044782306594,-2.1022943257716817
618.6000000000081,67.23009970926765,0.22277444632949767,-2.1034501289951537
619.7000000000081,67.33942894997925,0.226105614572245,-2.104770191845838
620.8000000000081,67.44941531392101,0.22686444883556622,-2.105734380636833
621.9000000000082,67.55978983836646,0.23267084768884747,-2.10706834826082
623.0000000000082,67.66940729487433,0.2351935227200604,-2.107400107126123
624.1000000000081,67.77902907555911,0.23887299597156203,-2.108982000495183
625.2000000000081,67.88924034156206,0.24339149356225048,-2.1109492964867607
626.3000000000081,67.99878098999605,0.2493577476426187,-2.112667459512291
627.4000000000082,68.10978217098899,0.25219438399042077,-2.1139901122800455
628.5000000000082,68.21796826187952,0.25882481030366317,-2.1152953290276577
629.6000000000082,68.32942102571106,0.26247276378349604,-2.118217843129398
630.7000000000082,68.43932382457572,0.26942672525074257,-2.118239940933961
631.8000000000083,68.54969142086328,0.27836203367101964,-2.1199038879236936
632.9000000000083,68.65902842764393,0.2810772792650793,-2.1214802579708545
634.0000000000083,68.76881032219453,0.2892691062052762,-2.122904032439652
635.1000000000083,68.87941612283194,0.29843292839972707,-2.1251254415201513
636.2000000000083,68.98874496266808,0.30660015210644775,-2.1268260744427647
637.3000000000084,69.09836697082889,0.31540358097686394,-2.129237398572567
638.4000000000084,69.20768467797876,0.3229444035455206,-2.12990321890048
639.5000000000084,69.31774578219196,0.3329817274704784,-2.1330962818400003
640.6000000000083,69.42710211641459,0.3422103489663638,-2.135779159818031
641.7000000000083,69.53736242364818,0.35148374253963005,-2.138495500226078
642.8000000000084,69.64769255136929,0.3649492887855239,-2.1397690817193578
643.9000000000084,69.7563080392308,0.3762953717856382,-2.14113029556912
645.0000000000084,69.8663235563023,0.3902449058490869,-2.1452580645935826
646.1000000000084,69.97639434154979,0.402919640656461,-2.148932532964612
647.2000000000085,70.08636426881112,0.41904592596972046,-2.1506305854183143
648.3000000000085,70.19568722447057,0.43073657825536366,-2.154466454730381
649.4000000000085,70.30599109071996,0.4496091452776101,-2.157622434775932
650.5000000000085,70.41634326245101,0.46755637403667694,-2.160161585706669
651.6000000000085,70.5253869325845,0.4811676806962106,-2.163702675050887
652.7000000000086,70.63603966331162,0.5005384322614517,-2.1672321722156296
653.8000000000086,70.74583307642789,0.5163882686295665,-2.170074454603838
654.9000000000086,70.85585251393313,0.5353445415990277,-2.173975436959378
656.0000000000086,70.96396299180283,0.5559006890295959,-2.1806858470901695
657.1000000000087,71.07489955338117,0.572578440786935,-2.1830146665160735
658.2000000000087,71.1846413246789,0.5948186807666227,-2.18602791366786
659.3000000000086,71.29491906842398,0.6108094957877827,-2.1901389290397946
660.4000000000086,71.4050364519048,0.631968524266278,-2.1946677490382562
661.5000000000086,71.51482923047075,0.6519645616307784,-2.2010067581744686
662.6000000000087,71.62503859159482,0.6732991373177282,-2.204477017705088
663.7000000000087,71.73529643943183,0.6928602492263082,-2.210585698146191
664.8000000000087,71.84538028856129,0.717525453140212,-2.2161101253631834
665.9000000000087,71.95468840660165,0.7362025153953178,-2.2208133874672438
667.0000000000088,72.06621827744927,0.7605258084545237,-2.2269108653284944
668.1000000000088,72.1760262661772,0.7820648536372763,-2.231851271483193
669.2000000000088,72.28711315091368,0.8091584382668611,-2.238216642537049
670.3000000000088,72.39546144305554,0.8323983125727911,-2.2444911317460785
671.4000000000088,72.50726592697912,0.8539928330590898,-2.24952370773463
672.5000000000089,72.61670892507503,0.8738197516294194,-2.256640086179064
673.6000000000089,72.72710443973492,0.90147203860714,-2.263570798426376
674.7000000000089,72.8381736726119,0.9249130852498695,-2.27052073955263
675.8000000000088,72.9477611615583,0.9492023737822286,-2.276277372278823
676.9000000000088,73.05774524037048,0.9708657967489747,-2.2835309481922406
678.0000000000089,73.16625280141562,0.9923033953276359,-2.2910766829802816
679.1000000000089,73.27505281006131,1.018520054551792,-2.2989157679707866
680.2000000000089,73.38565300405529,1.0386301176806112,-2.305345742565846
681.3000000000089,73.49631553118397,1.0671978220327647,-2.314041066842903
682.400000000009,73.60585902067767,1.0892287917151124,-2.3223610854058627
683.500000000009,73.71650089393945,1.1140931786543284,-2.3307722404856737
684.600000000009,73.82620821789645,1.138354749746342,-2.3401602684212017
685.700000000009,73.93656796289996,1.1644429024311362,-2.347992200232382
686.800000000009,74.04624869625972,1.1839488843905803,-2.357225907386552
687.9000000000091,74.15728258563307,1.2088082452225628,-2.3662384785680386
689.0000000000091,74.26678996005714,1.2352150743204782,-2.374899472481499
690.1000000000091,74.37721738931785,1.2554597864937929,-2.3831253003733455
691.2000000000091,74.48754453225929,1.2786706584467105,-2.3929751960278223
692.3000000000092,74.5976087119337,1.3086882830570084,-2.40300635964627
693.4000000000092,74.70789303949852,1.3348308704206495,-2.4111515058496464
694.5000000000091,74.81758545895796,1.3644983943263282,-2.4216557595942128
695.6000000000091,74.92914173289674,1.3960514494736371,-2.4317039535178058
696.7000000000091,75.03906333835378,1.4265518872656417,-2.4431377640176053
697.8000000000092,75.1493084966843,1.4608620070924176,-2.4520538086282215
698.9000000000092,75.26030101450459,1.4924439016095066,-2.4631322431979354
700.0000000000092,75.37067528504745,1.5258446584979746,-2.4738245833340646
701.1000000000092,75.4807789346565,1.566389643724292,-2.4860001452391467
702.2000000000093,75.58968736307612,1.6039991019943622,-2.498308262339504
703.3000000000093,75.70192427483057,1.6417070481773237,-2.5100761905168856
704.4000000000093,75.8118961564418,1.6770990342310075,-2.521261509707782
705.5000000000093,75.92271892254395,1.707385992056128,-2.5343292834552584
706.6000000000093,76.03333202545022,1.7376030322516853,-2.5468889532121155
707.7000000000094,76.14414745625055,1.7637173370148158,-2.559508645312839
708.8000000000094,76.25401767689323,1.7885398391001421,-2.5708697387717194
709.9000000000094,76.36332603611912,1.8140048841041263,-2.5840288211694595
711.0000000000093,76.47453016516582,1.8314671293639992,-2.597116874662485
712.1000000000093,76.58520924660958,1.8407615102715245,-2.611152099073551
713.2000000000094,76.69569346947254,1.8417990602742231,-2.623585405663741
714.3000000000094,76.80576007106693,1.8385073065010609,-2.6375791843101783
715.4000000000094,76.91674573915863,1.822753214265738,-2.6506510255757227
716.5000000000094,77.02660365908825,1.8019406468493564,-2.664238670757431
717.6000000000095,77.1369885654809,1.770902686543952,-2.6746476275601068
718.7000000000095,77.24801397875775,1.729418293877422,-2.68722718403712
719.8000000000095,77.35861498482807,1.680643661025494,-2.69899003051557
720.9000000000095,77.46822105545509,1.6198923528154956,-2.7107448008604567
722.0000000000095,77.57826468598496,1.539823534632733,-2.7209350910596743
723.1000000000096,77.68888628781752,1.4309747267655564,-2.7320734490957643
724.2000000000096,77.79857536888736,1.284512706192413,-2.742904605285302
725.3000000000096,77.90835273503426,1.0469972859076309,-2.7515051734208864
726.4000000000096,78.01847484214169,0.6311094068375007,-2.7574161288889436
727.5000000000097,78.12498338631406,0.26553753784086537,-2.761390743577249
728.6000000000097,78.23606037065629,0.10337934571991057,-2.7627593944384654
729.7000000000096,78.34588013650627,0.03373246058082749,-2.7631162385765857
730.8000000000096,78.45584961248778,0.0006293830909008813,-2.765769737022557
731.9000000000096,78.56529381303436,-0.023241076208163167,-2.765742119305857
733.0000000000097,78.6753064671191,-0.03271591606723001,-2.7660915380485678
734.1000000000097,78.78607884448566,-0.04123478626711663,-2.7670898938532225
735.2000000000097,78.8959393064131,-0.045699644636536876,-2.767840019758468
736.3000000000097,79.00592549071415,-0.05041238902243435,-2.7674200290271624
737.4000000000098,79.11714939566286,-0.0555134844467015,-2.767090008285119
738.5000000000098,79.22713699484528,-0.059050369509525524,-2.7682812404081245
739.6000000000098,79.3366441846357,-0.060687585404498076,-2.7669774311930926
740.7000000000098,79.44763865838027,-0.06326441133037036,-2.767086512908822
741.8000000000098,79.55746419369557,-0.06590456437874984,-2.769719166472906
742.9000000000099,79.66820713459947,-0.07047985248512947,-2.7691790782192274
744.0000000000099,79.77764421783631,-0.0676676745496321,-2.7697201519953847
745.1000000000099,79.8887652699684,-0.07102009176173356,-2.7697179600699116
746.0000000000099,79.97819478018754,-0.07153402239694437,-2.771039936420931