File: 01_Data/Plastic_Laminate_Countertop_Particle_Board/STA/N2/10K_min/Plastic_Laminate_Countertop_Particle_Board_STA_N2_10KData_221004_R2.csv
##Temp./Â°C,Time/min,DSC/(mW/mg),Mass loss/mg
51.0,10.723141508650759,0.004246201900040436,-0.06376830955039647
52.100000000000016,11.112661496661184,0.04422165971724579,-0.06389332360419164
53.20000000000003,11.368163541030295,0.07008094468410664,-0.06541555052466741
54.30000000000005,11.5775491210659,0.09026639356158661,-0.06559934905730724
55.40000000000006,11.7614171560994,0.1033451839951054,-0.06641594345874013
56.50000000000008,11.938660851535282,0.11857629209143172,-0.0670745016839045
57.600000000000094,12.100684311132882,0.12861701212487042,-0.06798169246961461
58.70000000000011,12.254228068103966,0.13534162930898885,-0.06937955196081047
59.800000000000125,12.406583173504876,0.14532055912493247,-0.067456814744276
60.90000000000014,12.552396733138487,0.1499712422866033,-0.0671015567129305
62.000000000000156,12.696351742821427,0.15599100866082072,-0.06881821987855563
63.10000000000017,12.835893584578857,0.16223031386949693,-0.06849480395495622
64.20000000000019,12.972355638486336,0.16723239116927946,-0.06844703944939567
65.30000000000021,13.108680998984976,0.17396357586923594,-0.07100584920788444
66.40000000000022,13.241014809142326,0.1782729383985744,-0.07134558106241862
67.50000000000023,13.37254236515415,0.18362354247769153,-0.07196738823863313
68.60000000000025,13.502729633844368,0.18846685082267212,-0.07277866218650164
69.70000000000027,13.632358943516603,0.19542543412126445,-0.07277888353914674
70.80000000000028,13.759467906746197,0.19966772841427327,-0.0714848950929663
71.90000000000029,13.884899476949224,0.2028946623305734,-0.07340182225684666
73.00000000000031,14.009288088872085,0.20778053119753603,-0.07417131490542728
74.10000000000034,14.13371487719498,0.21322925949156635,-0.07552907533521713
75.20000000000034,14.254296605269351,0.2180257223840577,-0.075523971699051
76.30000000000035,14.376827086593597,0.2216340456918514,-0.07603280086419062
77.40000000000038,14.497475783939791,0.22534923563019282,-0.07815840232600291
78.5000000000004,14.617588891650502,0.2291913733174088,-0.0794586487506046
79.6000000000004,14.736499600471898,0.23347336130693885,-0.08063391303641376
80.70000000000041,14.855228123181536,0.2349235987732302,-0.0808501241557118
81.80000000000044,14.972665563246801,0.23695397139296237,-0.08086193566373412
82.90000000000046,15.089787587464011,0.23825022678848795,-0.08222942178641457
84.00000000000047,15.20630379735201,0.24068845707836817,-0.08223890558242841
85.10000000000048,15.320973559606546,0.24190240468475244,-0.08354053867787048
86.2000000000005,15.437425209937368,0.24361073185298776,-0.08222756064397085
87.30000000000052,15.552036951052784,0.24324545570410117,-0.0848724217950001
88.40000000000053,15.665863154436504,0.24291062055471224,-0.08616320601117122
89.50000000000054,15.779616922617342,0.24508396065761529,-0.08663910055024893
90.60000000000056,15.893773970080142,0.24304068873724194,-0.08734784175903654
91.70000000000059,16.005026591410985,0.24285935396975322,-0.08738859564603185
92.8000000000006,16.118005091383573,0.2433620363955391,-0.08811403655008876
93.9000000000006,16.2288738636682,0.24382879220366183,-0.08884618643007913
95.00000000000063,16.339906528017032,0.23981718687423104,-0.09002999922332089
96.10000000000065,16.44773108175886,0.23860554386711863,-0.09002487574543139
97.20000000000066,16.561550303635425,0.23989063427750834,-0.09002137746026273
98.30000000000067,16.67169507618323,0.23710166848795267,-0.09063742653671003
99.40000000000069,16.781765112372142,0.2367770371690755,-0.0919500842078862
100.50000000000071,16.892037744771788,0.2325145831789982,-0.09239989387620007
101.60000000000072,17.000291328332732,0.2345357459084001,-0.09180557656714061
102.70000000000073,17.109639227594915,0.23271553040117487,-0.09266039650931202
103.80000000000075,17.219164316059693,0.23031602757331393,-0.09509658982313729
104.90000000000077,17.327071364523462,0.22949310169298254,-0.09397550196882865
106.00000000000078,17.437132392123274,0.23088362866118262,-0.09397020905854037
107.10000000000079,17.543564303708393,0.22690099020117682,-0.09397930282884559
108.20000000000081,17.651087819350536,0.22539925625618418,-0.09288528126768414
109.30000000000084,17.76142991083056,0.22385890077346493,-0.09269463305069836
110.40000000000084,17.869484382753427,0.22291223297445006,-0.09561803510900813
111.50000000000085,17.977855154535778,0.22302761058460663,-0.09694529747692426
112.60000000000088,18.084141189315197,0.22177243998557616,-0.09694006305934799
113.7000000000009,18.19294674489766,0.22171998840221574,-0.09825329744177136
114.8000000000009,18.3009337102161,0.22134082970924418,-0.0969398614081265
115.90000000000092,18.40800457679837,0.21899047331601695,-0.09693953498284014
117.00000000000094,18.51731983560014,0.21913293215972862,-0.09692972934126232
118.10000000000096,18.623626793471967,0.2198770275538322,-0.09693803000653389
119.20000000000097,18.731829081306795,0.21876073157394504,-0.0969398686271905
120.30000000000098,18.838722092115113,0.2201310558359355,-0.09691180435092228
121.400000000001,18.94548642759284,0.21748908711629467,-0.09731844109312471
122.50000000000102,19.05269607285454,0.2181193355084904,-0.09828500935501205
123.60000000000103,19.15971193175944,0.21866185605752964,-0.0982602188653221
124.70000000000104,19.266398620296602,0.21838414964286068,-0.09827889226625741
125.80000000000106,19.373259104822573,0.21949383745732454,-0.0995698802726741
126.90000000000109,19.481222359273268,0.21903622311998938,-0.09956981659908415
128.00000000000108,19.586414111157367,0.2179517846954503,-0.09890714032235559
129.1000000000011,19.692535773650246,0.21945228600455202,-0.09957351430667227
130.20000000000113,19.800198633483454,0.22134856221997568,-0.0995800185423188
131.30000000000115,19.9059582292306,0.22196887022350043,-0.10090018709528303
132.40000000000117,20.01054144420664,0.222160934391048,-0.10183275678878623
133.50000000000117,20.11812467752922,0.2226352513405241,-0.09953293825646847
134.6000000000012,20.224119165719525,0.22151734242724164,-0.10089024822005799
135.7000000000012,20.3295881589818,0.22211772086438497,-0.10192120323196008
136.8000000000012,20.435819885615004,0.2258022668357661,-0.10150448100081366
137.90000000000123,20.54067900901824,0.22499503864627501,-0.10221078016533935
139.00000000000125,20.64637601543864,0.22563546333228923,-0.10089989767878382
140.10000000000127,20.751302630055573,0.22736102919945533,-0.1021899220135647
141.2000000000013,20.856327493912527,0.22674336895225167,-0.1028399899312209
142.3000000000013,20.9621845446945,0.2292724914056028,-0.10256269842181354
143.4000000000013,21.06715394323427,0.22916522086708635,-0.10254598998366582
144.50000000000134,21.172284117441347,0.2299764398905585,-0.10386080573095136
145.60000000000133,21.278730664049213,0.2308121475227135,-0.1051750739884385
146.70000000000135,21.383559777882116,0.2322277215292482,-0.1048556408549528
147.80000000000138,21.487884850247095,0.23521508821912973,-0.10483112966669506
148.9000000000014,21.5934485672,0.23714045046121557,-0.1048399171613017
150.00000000000142,21.698849379856764,0.23859230070117943,-0.1045095358540249
151.10000000000142,21.80188857422609,0.2370949740197129,-0.10353089664181692
152.20000000000144,21.90662891735237,0.23952460440095602,-0.1048505508648887
153.30000000000146,22.01145208255545,0.24084719862781334,-0.10483151801455026
154.40000000000146,22.11692356506465,0.2407818505633097,-0.10484104057974264
155.50000000000148,22.221957395840978,0.24253446019240843,-0.10616096968348598
156.6000000000015,22.325472507371288,0.2445272248886976,-0.10844770578865148
157.70000000000152,22.431921215941582,0.24563532261278798,-0.1071539219305917
158.80000000000155,22.535394552171734,0.24883764718299817,-0.10715002846114263
159.90000000000154,22.64046950821943,0.24995364160605105,-0.10846858367941437
161.00000000000156,22.74557364771507,0.2511446287021244,-0.10714984368297298
162.1000000000016,22.84928713775669,0.25395008452424517,-0.1084379726768594
163.20000000000158,22.953852927791193,0.25373108662729926,-0.10978011483675632
164.3000000000016,23.05689577014935,0.2573099606000521,-0.10978673803465622
165.40000000000163,23.16273116410626,0.2583099246661115,-0.11077012376920559
166.50000000000165,23.266791296884506,0.25893028425055353,-0.11005785107007071
167.60000000000167,23.37026977726048,0.2627090111227848,-0.11010988736193461
168.70000000000167,23.47662554360992,0.26476995175645357,-0.10983011275347465
169.8000000000017,23.582113709875042,0.2693992280525643,-0.11241840403975134
170.9000000000017,23.685620784868124,0.2723052583048026,-0.11241993226836033
172.0000000000017,23.790089567561918,0.274864300558419,-0.11374035056462084
173.10000000000173,23.89381729809053,0.2766402109036735,-0.11340002484045941
174.20000000000175,23.997837984094094,0.2802472258597067,-0.11242004994303612
175.30000000000177,24.103194062732978,0.2836663741366894,-0.1137168900554828
176.4000000000018,24.20837746993285,0.28572927357461514,-0.11505950091205097
177.5000000000018,24.310000000000187,0.290406834925415,-0.11509776841442276
178.6000000000018,24.416954889235736,0.29216517508721757,-0.11636181060867568
179.70000000000184,24.522374940587344,0.29708174498732953,-0.1171103582838775
180.80000000000183,24.626610290781393,0.299947770836276,-0.11722609917852189
181.90000000000185,24.729043466998778,0.3058087580891603,-0.11901525097036103
183.00000000000188,24.835547992629,0.3096876284387282,-0.12032997717282257
184.1000000000019,24.940776193998154,0.313356112254321,-0.12032990822077672
185.20000000000192,25.044562332408162,0.31598968583614045,-0.12227654286755252
186.30000000000192,25.14846724836672,0.3217300154213353,-0.12361986568153016
187.40000000000194,25.252763219814156,0.3246073456070426,-0.12361989906546622
188.50000000000196,25.35762717857834,0.32761145275064163,-0.12494205610282805
189.60000000000196,25.461866301557635,0.3322385642320643,-0.12625017839141162
190.70000000000198,25.56677764234085,0.3366749228100645,-0.12624668907394776
191.800000000002,25.671271487939787,0.3394842606006524,-0.12757018252784347
192.90000000000202,25.775701777695843,0.34379749763071155,-0.127568994703942
194.00000000000205,25.88069362508343,0.34742512901442985,-0.12889456490885554
195.10000000000204,25.984990913432835,0.35088282946345284,-0.13284178637591992
196.20000000000206,26.088103894114212,0.35474210274030843,-0.13284015399908222
197.3000000000021,26.192857239879242,0.35708725254573465,-0.13284013870321276
198.40000000000208,26.297122284418112,0.35986542618037487,-0.13428414469916072
199.5000000000021,26.402285739425732,0.3609394881705093,-0.13675704901889363
200.60000000000213,26.507264664548906,0.3640792987049715,-0.13942190947260302
201.70000000000215,26.610989694660006,0.3647729678393908,-0.14008231513759917
202.80000000000217,26.715669288810517,0.3682367024837574,-0.13999549514862863
203.90000000000217,26.820295341132926,0.3698682244201988,-0.14206009628153415
205.0000000000022,26.924956371063086,0.36974466194637917,-0.14335803011085524
206.1000000000022,27.030086305991873,0.3714371294695624,-0.1446996701362555
207.2000000000022,27.13273675974087,0.3713652162768467,-0.14713993965795913
208.30000000000223,27.237817475710713,0.37306193940599963,-0.14855885210799524
209.40000000000225,27.342740870354454,0.37547674395757974,-0.1515483218539253
210.50000000000227,27.446571234119,0.3751859587742926,-0.15370055559527618
211.6000000000023,27.55117537505331,0.3770292655648273,-0.15533948381827445
212.7000000000023,27.65529823487508,0.37761112585046197,-0.15643667802228567
213.8000000000023,27.760814740728513,0.37953525009064193,-0.15806049613232265
214.90000000000234,27.865608416339963,0.37830681053337456,-0.16022078488855573
216.00000000000233,27.970848315986334,0.3813729660568191,-0.1613049716463042
217.10000000000235,28.07311972103569,0.38156034487791535,-0.16456058539216656
218.20000000000238,28.178307380981565,0.38421209902008013,-0.16837981515768297
219.3000000000024,28.28435812879748,0.38453394123975204,-0.16851023443935764
220.40000000000242,28.389708566856093,0.38720981337406324,-0.16854203542905832
221.50000000000242,28.492557225030364,0.38902312446059545,-0.17128758694100554
222.60000000000244,28.59720169885553,0.39083129898910995,-0.17378081655704536
223.70000000000246,28.70156634283647,0.39232113615612263,-0.1753974691023683
224.80000000000246,28.80590318794002,0.3922463853783065,-0.17916842532490262
225.90000000000248,28.910713390691203,0.393660552133466,-0.18021621409788624
227.0000000000025,29.015568458129533,0.39482209441599836,-0.1824650511790189
228.10000000000252,29.11990030787905,0.39591414064513175,-0.18663041176221862
229.20000000000255,29.223954685710407,0.3975251753033817,-0.19063375387936654
230.30000000000254,29.329296057892986,0.39501868480787533,-0.19201509033317432
231.40000000000256,29.434016603262044,0.39576012833744995,-0.1956164507296001
232.5000000000026,29.538760038381728,0.39731534816175806,-0.1973034825485973
233.60000000000258,29.643734163333825,0.39602351055047136,-0.20033363792616665
234.7000000000026,29.7484635733785,0.3962151993042251,-0.20258313817096774
235.80000000000263,29.85199196608497,0.3957873945978165,-0.20648045531652537
236.90000000000265,29.95761658263693,0.39348570532297766,-0.2104976593104233
238.00000000000267,30.062279699373704,0.39198315972029196,-0.2130880709602354
239.10000000000267,30.167872001386215,0.3931914754703625,-0.21569920397891673
240.2000000000027,30.270670777627444,0.39089626990377935,-0.21870629934213603
241.3000000000027,30.37641804236347,0.3898531562133103,-0.22428749191584885
242.4000000000027,30.481827600848423,0.38689480812334276,-0.22900401276303972
243.50000000000273,30.58617348522831,0.3861419101634754,-0.23194030617671935
244.60000000000275,30.690662655281137,0.38633749448046095,-0.23604611360586025
245.70000000000277,30.794965723213277,0.3854622681637422,-0.2405790553521756
246.8000000000028,30.9003990566249,0.38507623886571896,-0.2455169253023537
247.9000000000028,31.005006690087708,0.3862852267517901,-0.24956187979083522
249.0000000000028,31.10990423497713,0.38359901657563067,-0.25666985036391443
250.10000000000284,31.21454631374038,0.3843598367375083,-0.26138301914419815
251.20000000000283,31.318796721490642,0.3831639261391837,-0.26621184663468345
252.30000000000285,31.424657725674425,0.38441511123652916,-0.2718634134898772
253.40000000000288,31.52906167612795,0.385051010117016,-0.2795214263747301
254.5000000000029,31.633765350504902,0.38402283626033695,-0.2830715055549522
255.60000000000292,31.739298917276752,0.3844122960696702,-0.28768161009362414
256.7000000000029,31.84276428178081,0.38568475623507353,-0.29440800019755997
257.8000000000029,31.948035816942994,0.3833110865926099,-0.3019021479535473
258.90000000000293,32.05361264400664,0.381175811431034,-0.3065192049051606
260.00000000000296,32.156849169844804,0.3817781385569857,-0.31369530595639317
261.100000000003,32.262422511639585,0.377631872899886,-0.3188769768242028
262.200000000003,32.36820355233514,0.37761092926112916,-0.3274332726937983
263.300000000003,32.47156316636372,0.37741244974424526,-0.33420366294221004
264.40000000000305,32.57728796470032,0.3772341693401188,-0.34207971663684766
265.50000000000307,32.68224323447985,0.3752299807184787,-0.3499393109244968
266.6000000000031,32.786407021404706,0.37104373465507895,-0.3571137977348089
267.7000000000031,32.891172139459705,0.37122227142777475,-0.36460790463258563
268.8000000000031,32.99544236292488,0.36890881853963087,-0.3725840415301618
269.9000000000031,33.10167192536947,0.36640014367662055,-0.38338870897360433
271.0000000000031,33.20695165089171,0.36180806723075565,-0.39414195104530414
272.10000000000315,33.31132054360568,0.3585377288955647,-0.4021103166347202
273.2000000000032,33.41593778091729,0.35445739788752817,-0.41226851340197257
274.30000000000314,33.521851717685834,0.3503068914824675,-0.42248648302917013
275.40000000000316,33.62636444418876,0.3481192163297072,-0.43295038287166676
276.5000000000032,33.73207315344083,0.34320681462864044,-0.44272881026276023
277.6000000000032,33.837072954808846,0.3388170381716244,-0.4562389043806543
278.70000000000323,33.94214454706321,0.33283838057221493,-0.4682373139483782
279.80000000000325,34.04730512514009,0.3272745253897996,-0.47962852910635334
280.9000000000033,34.151992137454144,0.3220322345348329,-0.4910576814991945
282.0000000000033,34.2542127202887,0.316331090387292,-0.5033990730984121
283.1000000000033,34.36134781599392,0.3108662380791819,-0.5164551859738986
284.20000000000334,34.466814076006976,0.30275909495119824,-0.5289220130797099
285.30000000000337,34.572178665142225,0.2987286094547368,-0.5439689416551454
286.40000000000333,34.67748041350304,0.29126440843685697,-0.5566212050450225
287.50000000000335,34.78247588056203,0.2884443584533789,-0.571921552123515
288.6000000000034,34.88720592217377,0.2796042039088985,-0.5852321333149995
289.7000000000034,34.993876862604154,0.2740159789564268,-0.6006480657722824
290.8000000000034,35.0986378441317,0.2707667722691491,-0.6148738221792276
291.9000000000034,35.20427699665911,0.2646904757545031,-0.6322331327870128
293.0000000000034,35.30920695895003,0.2596690535787831,-0.646433126997715
294.10000000000343,35.41580189042849,0.2546886896997061,-0.661735288604425
295.20000000000346,35.520277740660326,0.2482601713804923,-0.6777482272715125
296.3000000000035,35.6261045158754,0.24593590654185438,-0.6950729298954932
297.4000000000035,35.73145724233652,0.23997450976602622,-0.7119422534492394
298.5000000000035,35.8380738226341,0.23550023395921169,-0.728463422560262
299.60000000000355,35.94301498167666,0.23283612498849543,-0.7462850041690143
300.70000000000357,36.0478936936091,0.23051463442608167,-0.7649384663337582
301.8000000000036,36.15454949284663,0.22930034914898328,-0.7825203647730654
302.9000000000036,36.25991150127968,0.22595154560203512,-0.8014071088006665
304.0000000000036,36.36468164762793,0.22296681992205758,-0.8198299610352131
305.1000000000036,36.470871695971205,0.22115621397679128,-0.8397283092765013
306.2000000000036,36.57592783591498,0.2176515392318022,-0.8586524746417954
307.30000000000365,36.68181247362081,0.21628705678727075,-0.8790139161940562
308.4000000000037,36.78795923850517,0.21751061796318685,-0.8980763183236387
309.5000000000037,36.89267589637111,0.21459659799439962,-0.9189936062658077
310.60000000000366,36.999696977551636,0.21356456633146972,-0.9398944259641402
311.7000000000037,37.10450794223406,0.21436684589526622,-0.9612145974515034
312.8000000000037,37.21098524854441,0.2146127453043775,-0.9815354641500509
313.90000000000373,37.31717516025602,0.21421695229168508,-1.0053656634705588
315.00000000000375,37.42267537015848,0.21768370292628625,-1.0286997953171628
316.1000000000038,37.52882710742055,0.2185714665600722,-1.0516245245871851
317.2000000000038,37.63531881527525,0.22025213329146615,-1.0757119967975979
318.3000000000038,37.74028899771606,0.22104243981801439,-1.0978909945904514
319.40000000000384,37.846562992818235,0.2241676149600033,-1.122198913899926
320.5000000000038,37.953660433351295,0.22619237602824246,-1.145869010482182
321.60000000000383,38.05868425928014,0.2293253004466029,-1.1692599986341534
322.70000000000385,38.1657727553766,0.23324897533160507,-1.1957635187447186
323.8000000000039,38.271049702532096,0.23433152299929585,-1.2212243744679987
324.9000000000039,38.376933205941434,0.2388481342576906,-1.2459449195525165
326.0000000000039,38.4838991048848,0.24348972761914817,-1.2719914082987667
327.10000000000394,38.589163564560586,0.24720160086343032,-1.2983184409241604
328.2000000000039,38.69578025269058,0.2520713392140509,-1.3238345976203352
329.30000000000393,38.80182104527212,0.2565993538331508,-1.351833317988337
330.40000000000396,38.90744946639285,0.2620713085531334,-1.3794546185905951
331.500000000004,39.012835545086915,0.2673625413919488,-1.408014687359005
332.600000000004,39.12084428507618,0.27321007571753936,-1.4404427158998905
333.700000000004,39.22662350405363,0.2788073779051223,-1.4685439563418656
334.80000000000405,39.33165936744063,0.28318418087882,-1.4979525171117767
335.90000000000407,39.43804184887024,0.28884152348910386,-1.5271869147416988
337.0000000000041,39.54482087148514,0.2944402702435739,-1.5569740870153113
338.10000000000406,39.65129376709518,0.30104379486768384,-1.5878273791266841
339.2000000000041,39.758620852649365,0.3084173113576489,-1.6207398728826847
340.3000000000041,39.8647760337778,0.3117293806245435,-1.6539875563457116
341.4000000000041,39.970270148015864,0.3174696925603339,-1.685800296135508
342.50000000000415,40.074014698409066,0.32172966687144655,-1.7180816038094684
343.6000000000042,40.18307888322098,0.32500805475320954,-1.753761461086603
344.7000000000042,40.289240800474566,0.33057814915475237,-1.7877914690720944
345.80000000000416,40.39668800898511,0.33640377686643164,-1.8242250050045747
346.9000000000042,40.50304603037178,0.34079385749700725,-1.859944106667299
348.0000000000042,40.608200782427986,0.34594182389218603,-1.8954460473888082
349.10000000000423,40.71456017627625,0.3510308288255023,-1.9333761715603273
350.20000000000425,40.82255128258636,0.35460038787704007,-1.9712496342740526
351.3000000000043,40.928158701877855,0.3609576257906179,-2.007814535773952
352.4000000000043,41.034685261649656,0.363015740611241,-2.047489001929451
353.5000000000043,41.14137726973342,0.3675780107594679,-2.085919041285025
354.60000000000434,41.24797094368169,0.3688424446611736,-2.125945754620328
355.7000000000043,41.35264007915112,0.36985759676753316,-2.1657453847256924
356.80000000000433,41.461979841849946,0.36731282710778157,-2.206139806953669
357.90000000000435,41.56676007811903,0.36774521309260455,-2.2451076738828633
359.0000000000044,41.671456697077645,0.36365670554245605,-2.285425772783249
360.1000000000044,41.78048650006471,0.35782270230842866,-2.3247424010256164
361.2000000000044,41.8885524770526,0.34947043487721996,-2.3633627711843754
362.30000000000445,41.99214146700055,0.3382392760551177,-2.4029632286782046
363.4000000000044,42.101104822329,0.3247054780099816,-2.44241331465409
364.50000000000443,42.20704709613057,0.30971853236652686,-2.4792340072633525
365.60000000000446,42.31387780561597,0.2904021008890718,-2.514525892880096
366.7000000000045,42.42034776313241,0.2691493574422262,-2.5487580622560584
367.8000000000045,42.52535934934833,0.24524902051878555,-2.5825863249067305
368.9000000000045,42.63369475621512,0.2188514120467243,-2.6143754272443207
370.00000000000455,42.73974544503758,0.19191613440377203,-2.6424010811089236
371.10000000000457,42.84726549258057,0.16094508496555202,-2.6693873687311194
372.2000000000046,42.95404053330062,0.13190176565731088,-2.693214626127969
373.30000000000456,43.060288104465606,0.09987155191579528,-2.7124717721771496
374.4000000000046,43.16731433219106,0.07241793834888785,-2.7304959847169723
375.5000000000046,43.27338325520352,0.04485581327340571,-2.7471934712349997
376.6000000000046,43.38145829481783,0.01756405898818758,-2.759511792496196
377.70000000000465,43.48690332474495,0.00011701926626256354,-2.769924889874744
378.8000000000047,43.59412638807606,-0.02062745615520728,-2.7793788962902592
379.9000000000047,43.700466276846946,-0.033416574084029815,-2.7883403840072507
381.00000000000466,43.808105104028925,-0.047558231766680004,-2.797160068074174
382.1000000000047,43.91511505254981,-0.056322145830538906,-2.8025644901058753
383.2000000000047,44.021380915434904,-0.06215520078813902,-2.8072386792369763
384.30000000000473,44.129133197716165,-0.06807958164783312,-2.8147367127822402
385.40000000000475,44.23567589164646,-0.07503098865483304,-2.818779822930573
386.5000000000048,44.34302624977669,-0.07858673262537241,-2.823367399012929
387.6000000000048,44.448081777587134,-0.0810432423023083,-2.8259791606677505
388.7000000000048,44.55497008699128,-0.08623303940488214,-2.8295326136155405
389.80000000000484,44.661648733394074,-0.08908601422694745,-2.833482437813407
390.9000000000048,44.769020468437795,-0.09032470537820425,-2.8378956663174733
392.00000000000483,44.876104240180375,-0.09441539212496408,-2.841213081652402
393.10000000000485,44.983565049694654,-0.0982043787578028,-2.8448360221416715
394.2000000000049,45.09188133896034,-0.1028880117802986,-2.84757471975043
395.3000000000049,45.19859808810908,-0.10462453576636083,-2.8527816771688714
396.4000000000049,45.30669646485753,-0.10671729216073894,-2.856319364854979
397.50000000000495,45.41274563935328,-0.10977461791865833,-2.8605966103298663
398.6000000000049,45.5218014549584,-0.11121603062412422,-2.8632530650990344
399.70000000000493,45.629184517351156,-0.11110176979372755,-2.867490990363527
400.80000000000496,45.736761508034505,-0.1172153061637366,-2.870167721776792
401.900000000005,45.84519320852602,-0.11956387905646759,-2.873188948427722
403.000000000005,45.95239570305567,-0.12162312365335076,-2.8764435782203917
404.100000000005,46.06028534139103,-0.12382345431637315,-2.8798302535508387
405.20000000000505,46.16729814737071,-0.1259547267209135,-2.8837752048409993
406.30000000000507,46.27527658439511,-0.1273171731351992,-2.8867753625499204
407.4000000000051,46.38344205893832,-0.12661376777929534,-2.8930584335055265
408.50000000000506,46.491244525316034,-0.12959511842315996,-2.895536652610838
409.6000000000051,46.59910346393352,-0.13020412097749223,-2.897896908952191
410.7000000000051,46.70641320187292,-0.1326623643970521,-2.9005792705196365
411.8000000000051,46.814380156295734,-0.134321294221334,-2.901273725039329
412.90000000000515,46.92208667524377,-0.13542862184472265,-2.905261860453817
414.0000000000052,47.03000000000049,-0.1331081590147996,-2.911206560568311
415.1000000000052,47.136508839204566,-0.13570971432511014,-2.916653316404839
416.20000000000516,47.243923151752995,-0.13483703595143876,-2.919478757349292
417.3000000000052,47.351632807165586,-0.1330775138757237,-2.9222968737652453
418.4000000000052,47.458316493292294,-0.13395022992163674,-2.9229646539851486
419.50000000000523,47.56577802012097,-0.1334204094983693,-2.9263897482927055
420.60000000000525,47.67358803690834,-0.13559625457815722,-2.930768021964838
421.7000000000053,47.779999023949834,-0.13656609608547798,-2.9343910052687914
422.8000000000053,47.88868604288,-0.13462561819380592,-2.9383472957391654
423.9000000000053,47.99444184384966,-0.13662220387316504,-2.941068453452739
425.00000000000534,48.10317568474993,-0.13590189879341533,-2.943976764516267
426.1000000000053,48.21105441122019,-0.1383690244241891,-2.949256280863834
427.20000000000533,48.31795705386945,-0.13559515312150042,-2.9508487556808083
428.30000000000535,48.425368827569805,-0.13475971492924138,-2.9519200832179
429.4000000000054,48.53373736705284,-0.13335148436350708,-2.954609684806165
430.5000000000054,48.64028662785133,-0.13247131607567253,-2.958544388239397
431.6000000000054,48.74735004306362,-0.13337280671382742,-2.9611690251450717
432.70000000000545,48.85579226863619,-0.1326164267223773,-2.963860940407689
433.8000000000054,48.96311788126011,-0.1306184817445211,-2.967472865151676
434.90000000000543,49.071414611524496,-0.12976649531344575,-2.969296678348352
436.00000000000546,49.18000000000051,-0.12861716636606868,-2.971830074578559
437.1000000000055,49.2877131084159,-0.12768357785881293,-2.9730566854807856
438.2000000000055,49.39612759204132,-0.12512690043954097,-2.9771023179007945
439.3000000000055,49.50391679975357,-0.12280394765407468,-2.9797631047043414
440.40000000000555,49.61140239727609,-0.1220923255391505,-2.9814788171225164
441.50000000000557,49.71707154482289,-0.11712225004065879,-2.985530678380168
442.6000000000056,49.82811027026061,-0.11600472408880366,-2.9881931182872075
443.70000000000556,49.93553534882542,-0.11429639982575024,-2.9900181677911344
444.8000000000056,50.043799565677126,-0.11458383674983927,-2.993106959785425
445.9000000000056,50.15185527035265,-0.1144591223639943,-2.994787931960955
447.0000000000056,50.260762094506816,-0.11177584155496806,-2.997567960866114
448.10000000000565,50.367685829788776,-0.11047946418548679,-3.001608254487467
449.2000000000057,50.475704451400716,-0.10680537146289598,-3.0026825982603693
450.3000000000057,50.58508780607548,-0.10478534574945417,-3.0041917599769192
451.40000000000566,50.693220504277654,-0.10364618892681271,-3.0056841633330613
452.5000000000057,50.80103321373812,-0.10148050088244143,-3.0108249392719917
453.6000000000057,50.90854316564162,-0.10026532284627504,-3.012766696798337
454.70000000000573,51.0179932246116,-0.09577227410933029,-3.0146759043035525
455.80000000000575,51.126111396641676,-0.09425264892421728,-3.015814240790626
456.9000000000058,51.23441381809215,-0.09327252731001759,-3.017165775454499
458.0000000000058,51.342513021053946,-0.0910826360855371,-3.0198645812515155
459.1000000000058,51.45068729231875,-0.09042758560549138,-3.021119502720451
460.20000000000584,51.55919426091846,-0.09048791661375871,-3.0237689030016504
461.3000000000058,51.66783219463171,-0.08766601971091706,-3.025042123672811
462.40000000000583,51.77605215833806,-0.0881422831300962,-3.0271640377357287
463.50000000000585,51.88343953327701,-0.08983464589681397,-3.029466230965165
464.6000000000059,51.99033706418854,-0.08623533298687486,-3.030674495902375
465.7000000000059,52.10049351816372,-0.08479485045404184,-3.0347019212096944
466.8000000000059,52.20971321568359,-0.08245935442664945,-3.035939335183085
467.90000000000595,52.31769643266536,-0.08362595209538856,-3.0375997514731274
469.0000000000059,52.42633772723399,-0.08133656787477109,-3.039874994149998
470.10000000000593,52.5345354507161,-0.08209484298550085,-3.0398792110053656
471.20000000000596,52.64294304290911,-0.08058647061866614,-3.041355036966074
472.300000000006,52.75093388578882,-0.07977506394722986,-3.0438382497610874
473.400000000006,52.860956298228785,-0.0789618966250418,-3.0451623436917528
474.500000000006,52.9669205614356,-0.0783748559445897,-3.0476962511330274
475.60000000000605,53.076469890446845,-0.07714062100843286,-3.049112069749835
476.70000000000607,53.18599118453615,-0.07633300035049784,-3.0504421886707633
477.8000000000061,53.29248236006731,-0.07709731056256355,-3.052116750371722
478.90000000000606,53.40246871730547,-0.07463007735327293,-3.0540787181653997
480.0000000000061,53.51159671024947,-0.07525908312644994,-3.056676609803028
481.1000000000061,53.61907183905132,-0.07474838441624429,-3.057025159027021
482.2000000000061,53.72779665657132,-0.07474913875621803,-3.05964461142191
483.30000000000615,53.835665125859826,-0.07481573394472166,-3.059651452418165
484.4000000000062,53.94488635446295,-0.0755301615687912,-3.06234497526434
485.5000000000062,54.051983643123535,-0.07120697643344173,-3.0650227915693593
486.60000000000616,54.16179337111471,-0.07276580015134596,-3.0648908868000193
487.7000000000062,54.26944319614618,-0.0732694660346748,-3.0675657515583037
488.8000000000062,54.37801291448268,-0.07207271716791136,-3.068912977946281
489.90000000000623,54.48714584764791,-0.07036679514183752,-3.0700731496707476
491.00000000000625,54.59532196397669,-0.06518938469305882,-3.071603140545931
492.1000000000063,54.70489245831649,-0.061496337844068355,-3.0731609693089963
493.2000000000063,54.81289272438455,-0.058565150089421286,-3.0747484493410298
494.3000000000063,54.922966177827355,-0.05297751653462998,-3.0740864653262547
495.40000000000634,55.03037418859714,-0.05420514484635888,-3.078099881653539
496.5000000000063,55.139700190691414,-0.050649668606228854,-3.078433019952924
497.60000000000633,55.24837005869197,-0.05013263373911975,-3.0797414812509727
498.70000000000636,55.35757021078901,-0.04676454111390885,-3.082039803222785
499.8000000000064,55.465989176814325,-0.0460326349589644,-3.0827061047007636
500.9000000000064,55.57457711986605,-0.043914273919392954,-3.0826718429792095
502.0000000000064,55.68391418260353,-0.04397197193039437,-3.0867489911772443
503.10000000000645,55.79259948020307,-0.040641574173019224,-3.0866695504243666
504.2000000000064,55.90136987782859,-0.04325757057440391,-3.0886161142759896
505.30000000000643,56.011055654955044,-0.041062480556250947,-3.0886385530339013
506.40000000000646,56.1195894568717,-0.041529389231509894,-3.0885886520781742
507.5000000000065,56.229044437862534,-0.041451513763209324,-3.0899579551487713
508.6000000000065,56.33751933134442,-0.04118720439974813,-3.0932750122100687
509.7000000000065,56.443841155170745,-0.03848841918475082,-3.094248462303933
510.80000000000655,56.555342341666176,-0.038233597736698655,-3.0946056293020656
511.90000000000657,56.66381474969912,-0.037541591389183615,-3.094923808717087
513.0000000000066,56.7734920702404,-0.03591921990341704,-3.0981903843485936
514.1000000000065,56.88051510214793,-0.03658540040169217,-3.0995286662231294
515.2000000000066,56.99149619550432,-0.03745906508375271,-3.0995097610504074
516.3000000000065,57.10104806547977,-0.03608332410305451,-3.102197761979595
517.4000000000067,57.210302356292665,-0.03508371165855878,-3.1011854380210715
518.5000000000066,57.319500569054554,-0.03343409672270198,-3.103594711235403
519.6000000000067,57.427848711022094,-0.032513474831925765,-3.1049992843934326
520.7000000000066,57.53782592605263,-0.036639502453227224,-3.1063098732657783
521.8000000000067,57.64680417179605,-0.036841063481838215,-3.1056087288419727
522.9000000000067,57.755577482280735,-0.03587351668762906,-3.1069699424328
524.0000000000067,57.86399061101496,-0.03743372265309139,-3.1082900805429876
525.1000000000067,57.974568369495984,-0.036777487990126284,-3.110459726908159
526.2000000000068,58.08358769017952,-0.038555090727087654,-3.1125181251658622
527.3000000000068,58.19337161976541,-0.039150339142675655,-3.1150390666090635
528.4000000000068,58.303354605879775,-0.04044932828489414,-3.1136695620499024
529.5000000000068,58.412097066647256,-0.043356355126722784,-3.1136693843081544
530.6000000000068,58.52108521897247,-0.04278802139317185,-3.114978504450323
531.7000000000069,58.63109235379067,-0.044078454137876935,-3.116293457197821
532.8000000000068,58.740000989755266,-0.04658645229966504,-3.1162999926748967
533.9000000000069,58.849618787932684,-0.048199033193355084,-3.1179183662173333
535.0000000000068,58.95947078446241,-0.04838711094392936,-3.118859692753034
536.100000000007,59.06885987730699,-0.05224468493595717,-3.1189394330092735
537.2000000000069,59.17660674729335,-0.053530518265379745,-3.120259849851927
538.300000000007,59.28638356076395,-0.055946913098943035,-3.1215803727423688
539.4000000000069,59.39638822258503,-0.05627860609756069,-3.1239678578402117
540.5000000000069,59.50611925294525,-0.05749427129062602,-3.124786873209736
541.600000000007,59.61505450004342,-0.0601315752610074,-3.123879742508574
542.700000000007,59.72340955493055,-0.06476996985025958,-3.1259069061026556
543.800000000007,59.832683326431074,-0.06747684060768364,-3.1258580695800444
544.900000000007,59.93999828013738,-0.06930303907501971,-3.1284898363778755
546.000000000007,60.05082260902887,-0.0725317894050425,-3.1298032928299513
547.1000000000071,60.15886682266569,-0.07611909721583561,-3.13078066190174
548.2000000000071,60.268083906259115,-0.07758521802744209,-3.13112994700722
549.300000000007,60.37770742279999,-0.08127603115619568,-3.1311299502309033
550.4000000000071,60.48738676668339,-0.08505430965140941,-3.132440543116642
551.500000000007,60.595836592528826,-0.0869952027187074,-3.1324542958490826
552.6000000000072,60.704927179406575,-0.09071775069821023,-3.13376000825629
553.7000000000071,60.814213241782305,-0.09462285714621718,-3.1349675976069613
554.8000000000072,60.92307417640472,-0.09469380190964057,-3.136398562192487
555.9000000000071,61.03218418313062,-0.09765058350530458,-3.136411011667226
557.0000000000072,61.14222670921078,-0.10010282816809443,-3.137371951613572
558.1000000000072,61.25177638245357,-0.10295745515478345,-3.138700204850731
559.2000000000072,61.36066377123094,-0.10529703085291096,-3.1400197779558883
560.3000000000072,61.46918799707313,-0.10608330602687019,-3.1403403654899296
561.4000000000073,61.579076908589286,-0.10674172419513123,-3.1416743844546664
562.5000000000073,61.689074860144636,-0.11173737005648851,-3.141625076090751
563.6000000000073,61.798143249353345,-0.11365048084120376,-3.142988221773525
564.7000000000073,61.907347388305894,-0.11691997890817515,-3.1449599691535672
565.8000000000073,62.01657863614881,-0.11727904199748866,-3.144747124413793
566.9000000000074,62.125932959942766,-0.12019598416586343,-3.147674829075056
568.0000000000074,62.235187173627025,-0.12375292249429705,-3.147773405376539
569.1000000000074,62.34527024653605,-0.12661943560260253,-3.1481490348833416
570.2000000000073,62.454491451094675,-0.12701110903548657,-3.1493583174797397
571.3000000000073,62.564292230642764,-0.13038325557198346,-3.1506556457297914
572.4000000000074,62.67391583920483,-0.1330918098729866,-3.15131960699998
573.5000000000074,62.784137318579425,-0.13644988478063735,-3.1516473847707505
574.6000000000074,62.89239981680435,-0.13673431573434794,-3.1511826033150228
575.7000000000074,63.00296045193635,-0.1394487606432454,-3.1529315601445482
576.8000000000075,63.11256055454372,-0.14282438235695788,-3.153577196101149
577.9000000000075,63.221397567867676,-0.14582805544217248,-3.15494003221618
579.0000000000075,63.33136533568407,-0.14663074188801248,-3.156025225599553
580.1000000000075,63.441053787125526,-0.1489294464262903,-3.155615699826605
581.2000000000075,63.55021365401524,-0.1497954359550192,-3.157936581461186
582.3000000000076,63.660806627673956,-0.14994471517242144,-3.158250156007381
583.4000000000076,63.77028762734617,-0.1521567675886961,-3.1582501564521
584.5000000000076,63.87971301690845,-0.15603246578885663,-3.1595593042989853
585.6000000000076,63.98808491360053,-0.16142763491792644,-3.160879819112367
586.7000000000077,64.09932751679624,-0.16294180319315926,-3.161807523548613
587.8000000000077,64.20861952833995,-0.166162430636902,-3.1621636803720996
588.9000000000076,64.31899816756018,-0.16999624703514368,-3.1621486084038755
590.0000000000076,64.42785623210837,-0.16921319366873017,-3.1635135490547235
591.1000000000076,64.53825812709783,-0.17274302162144384,-3.164793336520871
592.2000000000077,64.64750389783808,-0.17207384689679567,-3.165159734026117
593.3000000000077,64.75708987490817,-0.17651041542341522,-3.1651595827744075
594.4000000000077,64.8667181778092,-0.17732995259089399,-3.1664718490501587
595.5000000000077,64.97759947729273,-0.17888103477490286,-3.1677900712777163
596.6000000000078,65.08705563577668,-0.18007234457761317,-3.1676616601327985
597.7000000000078,65.19686441791147,-0.17885260104088657,-3.168625992075949
598.8000000000078,65.30619560835714,-0.1811176057285418,-3.168779984117723
599.9000000000078,65.41507013351641,-0.1816231495898968,-3.1686664931071986
601.0000000000078,65.52566747188133,-0.1835490210452172,-3.1691100050931933
602.1000000000079,65.63522113578117,-0.185573266122151,-3.170015584575806
603.2000000000079,65.74468266995503,-0.1862378655216174,-3.171402364351113
604.3000000000079,65.85513420582488,-0.19117309975371422,-3.1720706657393407
605.4000000000078,65.96499221225123,-0.19042349335067194,-3.1733899804814003
606.5000000000078,66.07422046575242,-0.19160444675501728,-3.174678565928315
607.6000000000079,66.18452565270124,-0.19334410424662074,-3.1758297261852277
608.7000000000079,66.29496586685518,-0.19783662174919436,-3.1763496776295885
609.8000000000079,66.40378836109217,-0.19846469997912472,-3.1763598198195675
610.9000000000079,66.51287236941023,-0.19837141342105835,-3.175354410283532
612.000000000008,66.62415348242611,-0.20105956443242348,-3.1753839087519036
613.100000000008,66.73370874937368,-0.20155305851207508,-3.1769868836080253
614.200000000008,66.84159157594284,-0.20342738719173717,-3.1793372024027486
615.300000000008,66.95139761014941,-0.20628785430961014,-3.1789850478235864
616.400000000008,67.06265800551127,-0.20747234980139317,-3.1799800134363347
617.5000000000081,67.17328838828551,-0.21115018166342242,-3.1799798739935072
618.6000000000081,67.28181845487373,-0.21255191234143828,-3.1799978012408388
619.7000000000081,67.38990669608347,-0.2143112762972142,-3.180970170427984
620.8000000000081,67.50247401252388,-0.21544586106680463,-3.181613749250128
621.9000000000082,67.61190144669247,-0.21445763648210336,-3.1829433161329432
623.0000000000082,67.72123146843111,-0.22022212378996817,-3.182939835040577
624.1000000000081,67.83115062645359,-0.2222712165001085,-3.182282707274266
625.2000000000081,67.94065350414795,-0.22374195331438773,-3.183600310923524
626.3000000000081,68.05216047793913,-0.22541752175700336,-3.1836004774088518
627.4000000000082,68.16125946255282,-0.22999380673130804,-3.184577691462606
628.5000000000082,68.2708069486053,-0.23091695939457738,-3.1829317859175665
629.6000000000082,68.38079807612952,-0.23235100586673862,-3.1842628083615248
630.7000000000082,68.4908348348862,-0.23282027732630214,-3.1865624919822815
631.8000000000083,68.60030661735686,-0.23359919236110785,-3.1852499604610927
632.9000000000083,68.70990249592495,-0.23361606829021836,-3.1865705078834257
634.0000000000083,68.82019561485201,-0.2342642758497107,-3.1868995314122355
635.1000000000083,68.92703525694384,-0.2370302864698804,-3.188544646019969
636.2000000000083,69.03914599070794,-0.23817817793335913,-3.1878220673454107
637.3000000000084,69.14899721684377,-0.23528825785583102,-3.19018095901066
638.4000000000084,69.25938436017331,-0.2397485901306674,-3.191495384592608
639.5000000000084,69.36583906547904,-0.24257847567379157,-3.191579941516787
640.6000000000083,69.47876082888499,-0.2428298122321234,-3.194141930904744
641.7000000000083,69.58814833738343,-0.24239466263470175,-3.1942245293965392
642.8000000000084,69.69869626157242,-0.24627840436062595,-3.194140040417195
643.9000000000084,69.80890403670026,-0.2512005675450615,-3.192202267089145
645.0000000000084,69.91887279893082,-0.25270047787345706,-3.1934930739936442
646.1000000000084,70.02911260144482,-0.25395231126798956,-3.195137668634649
647.2000000000085,70.14009292194878,-0.2576605158196701,-3.1938104036473405
648.3000000000085,70.2493609608295,-0.26080739851470147,-3.195129799935779
649.4000000000085,70.35989904181682,-0.260693098028313,-3.196128819561395
650.5000000000085,70.470817569181,-0.26297789467778393,-3.1958460573406233
651.6000000000085,70.58000212654191,-0.265262795999426,-3.197429979491957
652.7000000000086,70.69052513338357,-0.26576936970544174,-3.1974262851295636
653.8000000000086,70.79980934671057,-0.26732551409834954,-3.1987501797919897
654.9000000000086,70.91082888519091,-0.2701499092321755,-3.1987501801149185
656.0000000000086,71.02087632608341,-0.26983134787643703,-3.2000591790543558
657.1000000000087,71.13151081181803,-0.274598340083188,-3.201388575131856
658.2000000000087,71.24216372610546,-0.2745474669389998,-3.2024504486763847
659.3000000000086,71.35052868065068,-0.27668660472650936,-3.2021050927489583
660.4000000000086,71.46321652337262,-0.27761824802305096,-3.2027003101896327
661.5000000000086,71.57280938931666,-0.2798219966719127,-3.204018857222865
662.6000000000087,71.68268844871633,-0.28032706194580725,-3.203992152792997
663.7000000000087,71.79340410095756,-0.2797052763176172,-3.2026985875616796
664.8000000000087,71.90335361206262,-0.2827735003256741,-3.2027288347254284
665.9000000000087,72.01333343765657,-0.28224506407220623,-3.202709965991177
667.0000000000088,72.12495763267961,-0.2836692360586394,-3.202709775015737
668.1000000000088,72.23459594368163,-0.28362387055605154,-3.203879290698084
669.2000000000088,72.3462062751681,-0.2895967930411223,-3.2047289570520836
670.3000000000088,72.45549073929517,-0.29253695688206827,-3.204126648178671
671.4000000000088,72.56664481821146,-0.2929597361598917,-3.202396773496882
672.5000000000089,72.67639516812504,-0.295937513274764,-3.2027000014433487
673.6000000000089,72.78638690368332,-0.2957602855696584,-3.205037309579381
674.7000000000089,72.89719990355549,-0.29423279501588384,-3.206660109664818
675.8000000000088,73.00697263953609,-0.2944944743376063,-3.2079716016061535
676.9000000000088,73.11776367736593,-0.295918831792073,-3.207970113237506
678.0000000000089,73.22682071657208,-0.29665223428319626,-3.2092768134987204
679.1000000000089,73.3382804127604,-0.29802397440500117,-3.2092897458088343
680.2000000000089,73.44804302851887,-0.2985027221386019,-3.20951593306724
681.3000000000089,73.56021335356546,-0.29709244316733224,-3.2092901320012976
682.400000000009,73.66960338940555,-0.2955692905014631,-3.2093684523250148
683.500000000009,73.77926358691468,-0.3003407155371792,-3.210609150519044
684.600000000009,73.89010433327694,-0.30139665582799385,-3.2105999498871824
685.700000000009,74.00021237604152,-0.29822143438796966,-3.2119197934710573
686.800000000009,74.109714922085,-0.3019632235679889,-3.2119198875363435
687.9000000000091,74.21909592703875,-0.3020796015753332,-3.2106182752847072
689.0000000000091,74.32888586369327,-0.30369658681207606,-3.211781303850768
690.1000000000091,74.4393433634668,-0.30248279920882754,-3.2102979928914714
691.2000000000091,74.5480308983689,-0.3006634200099782,-3.211260123088514
692.3000000000092,74.65785199701988,-0.3040809146727399,-3.212571290648345
693.4000000000092,74.76808557359954,-0.30362354757618204,-3.2138610309444204
694.5000000000091,74.87839800686896,-0.3047529133029736,-3.212572408950619
695.6000000000091,74.9880611003297,-0.30598323454424786,-3.212531441083268
696.7000000000091,75.09826020142108,-0.3046219143833217,-3.2143808389256563
697.8000000000092,75.20946132055418,-0.31097306663320834,-3.2165128060978185
698.9000000000092,75.31716420531637,-0.3116515275338201,-3.216553044281996
700.0000000000092,75.4292529674382,-0.3128844518202658,-3.215219925866387
701.1000000000092,75.5399028596598,-0.315291797988674,-3.216540358025407
702.2000000000093,75.64989456716697,-0.31772396048432433,-3.2178597867147696
703.3000000000093,75.76048506627157,-0.31814060604311156,-3.217229218066252
704.4000000000093,75.87123034372429,-0.3194160257363536,-3.216539814086447
705.5000000000093,75.98123218735667,-0.3198737709896794,-3.21653977496571
706.6000000000093,76.09237208105546,-0.3208118592841623,-3.216530395246736
707.7000000000094,76.20158430614927,-0.32388082993623646,-3.2165301021775403
708.8000000000094,76.31302609997444,-0.3249360784513895,-3.217518262368031
709.9000000000094,76.42249421871267,-0.3239380243118951,-3.216525604504134
711.0000000000093,76.53446170817753,-0.3266337919822086,-3.218182145951095
712.1000000000093,76.64536819865548,-0.3311812629723451,-3.2191706130537825
713.2000000000094,76.75614943368733,-0.3336384489080359,-3.219127322737778
714.3000000000094,76.86623429324253,-0.3328453851468396,-3.2191700790727813
715.4000000000094,76.97766959819705,-0.3365400881178647,-3.21936249737693
716.5000000000094,77.08785070778276,-0.33588527912783733,-3.219357594813587
717.6000000000095,77.19755064759855,-0.3399123132005382,-3.220122504357076
718.7000000000095,77.30825657482048,-0.33973875229646333,-3.21944052337253
719.8000000000095,77.4192450930058,-0.34405040694748146,-3.220304565442473
720.9000000000095,77.5294905801136,-0.3445713041716695,-3.220490112074395
722.0000000000095,77.6412546028535,-0.34751801561426354,-3.2204898927705727
723.1000000000096,77.75174214824105,-0.351462194354748,-3.2231343370291548
724.2000000000096,77.85974765385521,-0.3543445606352201,-3.221810004327315
725.3000000000096,77.97320363227652,-0.3552790225425567,-3.2231200647693186
726.4000000000096,78.08385817028828,-0.3599934351551816,-3.221466539659316
727.5000000000097,78.19436517262133,-0.363628168607473,-3.220397844462233
728.6000000000097,78.30502908649882,-0.3643813670085281,-3.222483564377351
729.7000000000096,78.4158109248048,-0.36675140600542616,-3.2236250915143487
730.8000000000096,78.52435410682145,-0.3705045654422402,-3.2244396600128327
731.9000000000096,78.63796015382027,-0.37293150439909817,-3.2244557493717565
733.0000000000097,78.74865356889417,-0.37176500336375295,-3.2244490948159408
734.1000000000097,78.85753170962828,-0.3712099455826374,-3.2244498600000666
735.2000000000097,78.97062349540651,-0.36710146730133036,-3.2244504965578384
736.3000000000097,79.08096676079656,-0.36980621399221447,-3.2261591485204315
737.4000000000098,79.19097994881369,-0.3726545756551608,-3.225760018011874
738.5000000000098,79.3020388118355,-0.37664428644767756,-3.224441666682213
739.6000000000098,79.4124899987451,-0.3759448548696248,-3.225749954528087
740.7000000000098,79.52414425824973,-0.3763460039483553,-3.2272690457002304
741.8000000000098,79.63518337223701,-0.3783135245103014,-3.2284847353375627
742.9000000000099,79.74498780109644,-0.3820896797921224,-3.2257438685422506
744.0000000000099,79.8555943208849,-0.38110451099653836,-3.2270798392199045
745.0000000000099,79.95604675049073,-0.3809679460139857,-3.2281099061801295