File: 01_Data/Plastic_Laminate_Countertop_Particle_Board/STA/N2/10K_min/Plastic_Laminate_Countertop_Particle_Board_STA_N2_10KData_221004_R3.csv
##Temp./Â°C,Time/min,DSC/(mW/mg),Mass loss/mg
51.0,10.657513256794646,0.029592394198940886,-0.03802459571309802
52.100000000000016,11.065100866763373,0.057322095517757576,-0.04083253305724721
53.20000000000003,11.349676131987884,0.09759611175892546,-0.03891496250502735
54.30000000000005,11.562213866796025,0.11651818366701949,-0.039660211250562405
55.40000000000006,11.74880534753452,0.1312786411770117,-0.03938403789136613
56.50000000000008,11.920000000000021,0.14552844538789111,-0.03995852808622358
57.600000000000094,12.08652781020911,0.15903197999382646,-0.04031402563982578
58.70000000000011,12.243091643970377,0.16785439327560536,-0.040000857282809665
59.800000000000125,12.394395286801975,0.17624273681005387,-0.04109495105882033
60.90000000000014,12.539592210082532,0.18511540318610442,-0.04132801889310311
62.000000000000156,12.682144362977319,0.18860516451412312,-0.04063285789372584
63.10000000000017,12.819915767318514,0.19534116878296404,-0.04275655331234507
64.20000000000019,12.963450060198818,0.2037542343530665,-0.040807326038990954
65.30000000000021,13.096595501146613,0.20821028338758296,-0.042104510843567144
66.40000000000022,13.23035100705425,0.214689908264718,-0.04305546328723686
67.50000000000023,13.361867086801057,0.2202636354269245,-0.04356795370594835
68.60000000000025,13.491807652584594,0.22720844884179758,-0.044792226078703035
69.70000000000027,13.62011367405198,0.23161241043634018,-0.046228066936837564
70.80000000000028,13.747117730984819,0.2357214969484076,-0.0462293725626326
71.90000000000029,13.873731200758407,0.24267241709349574,-0.04736974801447902
73.00000000000031,13.998009601461401,0.24593029252140808,-0.04739428969545534
74.10000000000034,14.12057407962026,0.2498455757875354,-0.04906256784458485
75.20000000000034,14.241743624052187,0.25395796138555815,-0.05024877822571838
76.30000000000035,14.363023502883593,0.25810687726461845,-0.05049110420475644
77.40000000000038,14.487655212284936,0.2618267917127427,-0.04962167229144576
78.5000000000004,14.606990456015026,0.2647969203050159,-0.049058811651510936
79.6000000000004,14.727360219478962,0.26924843729283565,-0.051680921060250906
80.70000000000041,14.845321735687152,0.2691355712843311,-0.05174475656158517
81.80000000000044,14.9637008310347,0.27211310477577233,-0.05434850251731316
82.90000000000046,15.081728864675462,0.27473127457267177,-0.053020009946911806
84.00000000000047,15.194255402093159,0.27485341140093744,-0.053023917203977255
85.10000000000048,15.31371278023937,0.2791329730169745,-0.05311961890557537
86.2000000000005,15.429290292479894,0.2802527393177551,-0.05514088573621745
87.30000000000052,15.543863680224856,0.2827465038706799,-0.05565582075396858
88.40000000000053,15.658126907419474,0.2801791042681918,-0.05573008907036048
89.50000000000054,15.77176680617196,0.28196295835661,-0.056985787087197703
90.60000000000056,15.88281512127098,0.2811870986182323,-0.05698974518697453
91.70000000000059,15.996273093572738,0.28375993975375435,-0.058285935780687304
92.8000000000006,16.10923226449686,0.280961838555541,-0.05696833122276601
93.9000000000006,16.218191286262513,0.27963683736258715,-0.05974972946539481
95.00000000000063,16.332060825361022,0.28086882231031296,-0.05961008331121764
96.10000000000065,16.442871381798494,0.2784490263786876,-0.05951375589809249
97.20000000000066,16.554053561909058,0.27809361215709316,-0.05950238673379804
98.30000000000067,16.664008995151924,0.2773759263768708,-0.06083353380171408
99.40000000000069,16.77328014548172,0.27789942798626355,-0.05959176049236614
100.50000000000071,16.883107034288212,0.27673286550386644,-0.06085274816907704
101.60000000000072,16.992350846767128,0.2764171967774276,-0.0595099399481569
102.70000000000073,17.102262328733083,0.27454164143383175,-0.05951018776058792
103.80000000000075,17.209814916425245,0.27364855352524153,-0.05811325465281625
104.90000000000077,17.316766872984118,0.2714829878181584,-0.06081834232238714
106.00000000000078,17.42718967566253,0.2730845381006375,-0.06082841220783708
107.10000000000079,17.535803525039945,0.27331327001102224,-0.06081063788980101
108.20000000000081,17.64405652673911,0.2690137718275547,-0.06184996258481945
109.30000000000084,17.751578901988868,0.2695479697150953,-0.06212444122678429
110.40000000000084,17.86072040237274,0.268920000741215,-0.06214007425133028
111.50000000000085,17.967418454990025,0.2709696017563342,-0.062139653093591374
112.60000000000088,18.075181652483064,0.27002899033141836,-0.06211911445840901
113.7000000000009,18.18272194687205,0.2705473607835399,-0.06219486130461105
114.8000000000009,18.2907477604702,0.26841844904655043,-0.06214368830027528
115.90000000000092,18.3986508835736,0.2694282100249591,-0.062147487685439984
117.00000000000094,18.505845390706885,0.26983475480184216,-0.06346000767438831
118.10000000000096,18.612741792326343,0.27031148535414584,-0.06476531822596021
119.20000000000097,18.718749587189272,0.2673882846520661,-0.06474394295013752
120.30000000000098,18.828353678866932,0.2678264789134739,-0.06345682516380036
121.400000000001,18.93487697439335,0.2692011248087359,-0.06345662313549338
122.50000000000102,19.0418249998353,0.269925900384574,-0.06286085353139947
123.60000000000103,19.148359989729652,0.2699428940059876,-0.06477025699701011
124.70000000000104,19.25538388914308,0.268756403503003,-0.0641907935502295
125.80000000000106,19.36263336712172,0.26936749212244393,-0.06208013163911641
126.90000000000109,19.469287390449452,0.26801184258428057,-0.06214176447761499
128.00000000000108,19.57563067802372,0.26945652801062603,-0.06415996132795909
129.1000000000011,19.68301412977491,0.27044440100691136,-0.0648129165719733
130.20000000000113,19.789356249859207,0.2718623169001433,-0.06510060058020128
131.30000000000115,19.89518706249871,0.2739259566159272,-0.0662347860706296
132.40000000000117,20.00072953012622,0.27360128870853895,-0.06474080118626135
133.50000000000117,20.10741126690339,0.27517674844758466,-0.06608977892779144
134.6000000000012,20.21371195127363,0.27825194218428373,-0.06575991522953828
135.7000000000012,20.31915426262838,0.2768722863916353,-0.06477506983701797
136.8000000000012,20.424896358376806,0.27853489361505146,-0.06708339978720268
137.90000000000123,20.530745051054122,0.27996510753018566,-0.0670690822231883
139.00000000000125,20.636898378136404,0.2796016845748447,-0.06639226523325403
140.10000000000127,20.742211077542844,0.2798868666443395,-0.06673689882909928
141.2000000000013,20.846649567114998,0.2805173879905165,-0.06608969775647067
142.3000000000013,20.953077524603934,0.2827757385869186,-0.06477025934612968
143.4000000000013,21.058769355101596,0.28351757862435956,-0.06579315257979879
144.50000000000134,21.163079486438043,0.2827347703165285,-0.06576005229511317
145.60000000000133,21.26660150709283,0.2855185446766375,-0.06575987992692989
146.70000000000135,21.37300897298981,0.28678706575052726,-0.06576013315426854
147.80000000000138,21.47841378108809,0.2896521800939851,-0.0683907569821609
148.9000000000014,21.583636349565616,0.2874065651064187,-0.06839004499983092
150.00000000000142,21.68880400072465,0.2888112614492715,-0.068389983768252
151.10000000000142,21.792778093377294,0.28889719772352596,-0.06707028688392525
152.20000000000144,21.89880006365785,0.28932848738879935,-0.0670810361094496
153.30000000000146,22.00236579576497,0.29033652673864696,-0.06707942706194103
154.40000000000146,22.10686094500692,0.29183796927928574,-0.06669501483820461
155.50000000000148,22.212834765267253,0.2922568008724099,-0.06840365373312718
156.6000000000015,22.317265757665844,0.29567318004513465,-0.06840004575662828
157.70000000000152,22.42226765561861,0.2968909301538559,-0.06974219072963095
158.80000000000155,22.527205817300324,0.2967066558933711,-0.07103017752805663
159.90000000000154,22.632514535613254,0.2982266795405538,-0.07102698612137459
161.00000000000156,22.736814937066047,0.30080738648118277,-0.07102995512073917
162.1000000000016,22.837518546881938,0.305258316577006,-0.07107647874250533
163.20000000000158,22.9460585273315,0.30536080811325406,-0.0707011944652578
164.3000000000016,23.051818284680795,0.30973470805734465,-0.07101926309555573
165.40000000000163,23.155774647202236,0.3100395525874096,-0.07233993624930513
166.50000000000165,23.260385830815522,0.3129923598538239,-0.07233986251196933
167.60000000000167,23.363134533202718,0.31589268586911573,-0.07365986080074194
168.70000000000167,23.470662078493916,0.31789576578124207,-0.07365986501301602
169.8000000000017,23.57483587684147,0.3210518690149464,-0.07365986499999977
170.9000000000017,23.67919239972986,0.3233474975596368,-0.07497886909321894
172.0000000000017,23.783911108755227,0.3253012865222711,-0.0749709815412456
173.10000000000173,23.888124337150554,0.32916772068452205,-0.07362613193035328
174.20000000000175,23.993887876150772,0.333348854793361,-0.07497663841536006
175.30000000000177,24.099581124676533,0.3333683912604172,-0.07628962478553225
176.4000000000018,24.203601448609668,0.3389041828694088,-0.07562979987286456
177.5000000000018,24.30856073381865,0.34187635259017435,-0.07563758584000801
178.6000000000018,24.41210325366398,0.34657985154825216,-0.07826988486054054
179.70000000000184,24.518916278128742,0.35095721527197354,-0.07958848126374285
180.80000000000183,24.622505728254733,0.3519851806760233,-0.07958990988233072
181.90000000000185,24.72747840685507,0.3573649856617882,-0.07960739932980321
183.00000000000188,24.83141816431778,0.3600184992913969,-0.07925982286187105
184.1000000000019,24.936792104828918,0.36689913320078327,-0.07926500724691543
185.20000000000192,25.04074510867453,0.3700350592855972,-0.08227431389389483
186.30000000000192,25.144914327464665,0.374389781180478,-0.08364792889108053
187.40000000000194,25.249495174846658,0.37787896429443607,-0.08486000206697186
188.50000000000196,25.353597862370346,0.37977348951058904,-0.08486000379437364
189.60000000000196,25.458194976018277,0.3850325834728936,-0.08619805835145655
190.70000000000198,25.563093679493033,0.38760715542479945,-0.08617236773573422
191.800000000002,25.66716990628295,0.39344419862045316,-0.08749237930924858
192.90000000000202,25.77173361793178,0.3956185079257149,-0.08877043765060799
194.00000000000205,25.875557643958587,0.3981443196619289,-0.08980022379858532
195.10000000000204,25.97841076728578,0.40019177088677527,-0.0914492543918417
196.20000000000206,26.08452576731066,0.40385670669316076,-0.09204928616426189
197.3000000000021,26.188779608141807,0.4084907604397786,-0.09274248145659714
198.40000000000208,26.293261823991262,0.4122046910698466,-0.0950662427753457
199.5000000000021,26.398025046788685,0.41525361680482825,-0.09540014021911425
200.60000000000213,26.501969419069365,0.41791058232272793,-0.09682963896627239
201.70000000000215,26.606342853784973,0.4198921064640492,-0.10069097462391063
202.80000000000217,26.70828894330588,0.42226868859153627,-0.10066926859527126
203.90000000000217,26.813443562609223,0.4224540108009206,-0.10067037594511596
205.0000000000022,26.91681008043896,0.4259925605473487,-0.1033330050749246
206.1000000000022,27.01936851645483,0.4267710708273427,-0.10594280038375414
207.2000000000022,27.1271301364345,0.42640202638585595,-0.10725863269023472
208.30000000000223,27.23152490726204,0.4280387100803064,-0.10857334982080102
209.40000000000225,27.335640870134437,0.42760100606173623,-0.1111783658449772
210.50000000000227,27.44026777421895,0.4279537488232973,-0.11220408781725189
211.6000000000023,27.544926145349063,0.4309033279278606,-0.11351051054799344
212.7000000000023,27.64990857259938,0.42956576760054477,-0.113840248563577
213.8000000000023,27.753873804036598,0.43206026155437394,-0.11659649690922347
214.90000000000234,27.85784896916845,0.4317921673988462,-0.11790307221576102
216.00000000000233,27.962421897078332,0.43410056888220894,-0.11922008243264903
217.10000000000235,28.06712091739704,0.4353100687601478,-0.12179959198938217
218.20000000000238,28.17126961753479,0.4363507129131522,-0.12329009628741883
219.3000000000024,28.275673523679384,0.4394980178753341,-0.12459339224359312
220.40000000000242,28.38059800070398,0.43910940909422214,-0.1269588495135876
221.50000000000242,28.485043142917895,0.44233583289438566,-0.12994460071141845
222.60000000000244,28.58891992905687,0.44336002212400605,-0.12988016948508685
223.70000000000246,28.69361067182354,0.4443632218715007,-0.13244720519220676
224.80000000000246,28.797868089424068,0.44697181043568857,-0.13514682207728956
225.90000000000248,28.901878943466972,0.44612423233010445,-0.13907727733545272
227.0000000000025,29.00696120115218,0.4481809152435984,-0.14109405001923214
228.10000000000252,29.111781834487342,0.4489998982468485,-0.1436835883266152
229.20000000000255,29.216387536242653,0.44789993331769995,-0.14616426877579247
230.30000000000254,29.32072230072339,0.4495551116058858,-0.14961019355024696
231.40000000000256,29.423674194206097,0.4513071993068577,-0.15106039085665568
232.5000000000026,29.529611363030877,0.4495276399581675,-0.15540665575170332
233.60000000000258,29.63503944901526,0.44908576667598643,-0.1578794221822335
234.7000000000026,29.74000000000025,0.4490009115329332,-0.1590801400000008
235.80000000000263,29.84247818509684,0.4492725629570292,-0.16231860864868608
236.90000000000265,29.94963672475664,0.4494450317442635,-0.16588292012083894
238.00000000000267,30.054713342266474,0.4484920663119006,-0.16852640491977722
239.10000000000267,30.158840741854195,0.4473127604704551,-0.17257878667130644
240.2000000000027,30.263091159643757,0.44780265014151327,-0.17645742032821898
241.3000000000027,30.36637476451172,0.4464366188873092,-0.18066825406708897
242.4000000000027,30.472345509104276,0.4472181218259417,-0.1861477484827141
243.50000000000273,30.57817042747896,0.4442332884447833,-0.18884330014704176
244.60000000000275,30.68207146642861,0.44650342113435754,-0.19299864975258618
245.70000000000277,30.78704325870784,0.44460289489376736,-0.19626935900479214
246.8000000000028,30.892765190876062,0.4439431258594595,-0.19992751440379086
247.9000000000028,30.996547094698386,0.4424107195490887,-0.2043686738631596
249.0000000000028,31.101689738432828,0.44338877374943486,-0.21009777768102733
250.10000000000284,31.20585221539986,0.4427619930394421,-0.21548375859650282
251.20000000000283,31.309090185981894,0.4421249855093711,-0.22194698465701368
252.30000000000285,31.41556298013164,0.44399689694054834,-0.22646926930142763
253.40000000000288,31.52125932433422,0.4442838001753152,-0.231558889272645
254.5000000000029,31.626271101519436,0.44263208609437915,-0.23669969728672813
255.60000000000292,31.73035063964317,0.4421082333883526,-0.24095929997386412
256.7000000000029,31.83307818351669,0.4445196181798997,-0.24683537972665714
257.8000000000029,31.939618914945548,0.4425336557838312,-0.2556322182980346
258.90000000000293,32.04379301567722,0.443736999549203,-0.25972646147523504
260.00000000000296,32.14864598110762,0.4441718690863471,-0.2657879189960801
261.100000000003,32.254449073490306,0.4414290367370698,-0.2733549330889824
262.200000000003,32.35844580578734,0.4415139526223911,-0.28038894353785304
263.300000000003,32.463229136146396,0.44005567639251075,-0.28537464627643017
264.40000000000305,32.567787192634725,0.44070770979585205,-0.29338762125969575
265.50000000000307,32.67263022036201,0.4402641652932238,-0.30103145912133256
266.6000000000031,32.7769703561246,0.4376208234193843,-0.3077824050432456
267.7000000000031,32.88248185332878,0.4349947204728407,-0.31486647056279704
268.8000000000031,32.98385610821189,0.43298692155515917,-0.32332925311078053
269.9000000000031,33.092424919761584,0.4297237111623092,-0.33330000612171906
271.0000000000031,33.197258435099755,0.4302302594605727,-0.34419852739743373
272.10000000000315,33.30122642928931,0.4251599020803468,-0.3524628519585806
273.2000000000032,33.40392189842867,0.42242241176701106,-0.36228020372968883
274.30000000000314,33.51131252141574,0.4191238635617211,-0.37343295479325933
275.40000000000316,33.61646460094245,0.41660360267905755,-0.38449568509369936
276.5000000000032,33.72131661986503,0.4131127830383705,-0.3941418404834196
277.6000000000032,33.82659038901519,0.40853636707500285,-0.4041590089669542
278.70000000000323,33.93093869419925,0.4022143335395169,-0.41545892925602423
279.80000000000325,34.036044392576436,0.3977123317090583,-0.42829825255706133
280.9000000000033,34.14097652189457,0.39221650977825895,-0.4410300258607416
282.0000000000033,34.24629707744509,0.3853506958056606,-0.452633497633534
283.1000000000033,34.35031058481857,0.3799772638897263,-0.46749907497276855
284.20000000000334,34.45630712083979,0.3739751981256113,-0.4796254729292415
285.30000000000337,34.561419955945034,0.3697282154312219,-0.49303719896235876
286.40000000000333,34.666877942998056,0.36342730957723257,-0.5063393165942491
287.50000000000335,34.771898060144686,0.3578431121527455,-0.5194776276507391
288.6000000000034,34.87691491954958,0.35472183231336385,-0.5329848997978024
289.7000000000034,34.982336469377124,0.34833336350116206,-0.5465440394622392
290.8000000000034,35.08778184157286,0.3418461562453434,-0.5598989907646663
291.9000000000034,35.192320780369535,0.33853193850009006,-0.5779917749200489
293.0000000000034,35.297928856560624,0.33314511134198,-0.5925862025786359
294.10000000000343,35.40223138533865,0.32935919070470143,-0.6086668839210292
295.20000000000346,35.50734836067747,0.32418899991651595,-0.623815610052822
296.3000000000035,35.61191922118883,0.3206309852352285,-0.641535581802545
297.4000000000035,35.717490932372066,0.3162586755708625,-0.6575402332122047
298.5000000000035,35.82468611641195,0.31244761445250613,-0.6743024494523571
299.60000000000355,35.930821111528,0.30986617031403785,-0.6916580524214955
300.70000000000357,36.03593221490859,0.30579417422086397,-0.7088722873251809
301.8000000000036,36.140717609444856,0.3039558010216775,-0.7260359791694069
302.9000000000036,36.246948371746676,0.303575002385508,-0.7432545964705066
304.0000000000036,36.351947678335,0.30306863058284206,-0.7621561473175844
305.1000000000036,36.45742158978109,0.2995089223678211,-0.7795574161279251
306.2000000000036,36.562277049884585,0.2996641968017266,-0.8005273119386449
307.30000000000365,36.668595479708756,0.2963923894620706,-0.8209689861769549
308.4000000000037,36.773884895251264,0.29703859811874367,-0.8380478613602604
309.5000000000037,36.880364677170114,0.2953753522153556,-0.8585374389837619
310.60000000000366,36.986060561580445,0.29572228354087227,-0.8802518580705092
311.7000000000037,37.09109465309314,0.2971709209710304,-0.9012309129021996
312.8000000000037,37.19715329624333,0.297409208725002,-0.9222188212619273
313.90000000000373,37.302615891904985,0.2985329796878251,-0.9441770149383055
315.00000000000375,37.408422605962365,0.29900337151386636,-0.9667443930571489
316.1000000000038,37.513480381669986,0.30211928770190466,-0.98899666752272
317.2000000000038,37.619999004362484,0.30462017867431596,-1.010769788443488
318.3000000000038,37.72646587377935,0.3072172140555378,-1.033201705026432
319.40000000000384,37.83237400064816,0.31017156822882885,-1.058238615452435
320.5000000000038,37.9385878324655,0.31299032483177486,-1.0804030733728927
321.60000000000383,38.044804480792195,0.31606614311364223,-1.1055087439215403
322.70000000000385,38.15059238070279,0.32105948034282844,-1.1284944279433073
323.8000000000039,38.256463903139284,0.32275888205065345,-1.1519311210516991
324.9000000000039,38.36162181681555,0.32423564760280177,-1.177971665169097
326.0000000000039,38.46694734520868,0.33088733528170655,-1.2021330883583627
327.10000000000394,38.575308764094984,0.33437106107443726,-1.2290311482870293
328.2000000000039,38.680704917519215,0.33958255806000864,-1.2549025498626474
329.30000000000393,38.78734692701443,0.34231123054109747,-1.281674248590765
330.40000000000396,38.89308291495105,0.3466659758631957,-1.3078589462942292
331.500000000004,38.999816631381584,0.35225816845579194,-1.3363302641825334
332.600000000004,39.10508065855791,0.3536478496309665,-1.3634878661813663
333.700000000004,39.209998787523205,0.3598444268303126,-1.3927094832441629
334.80000000000405,39.318559426028685,0.3669842134285597,-1.421209242997683
335.90000000000407,39.42535716059103,0.3726199729932246,-1.452308725639674
337.0000000000041,39.53030990925746,0.37708249724418774,-1.4794137180018732
338.10000000000406,39.637467391228164,0.3828119073911381,-1.509817117114964
339.2000000000041,39.74351337048143,0.3884540328978464,-1.5432466264193008
340.3000000000041,39.851263097678256,0.3934011197728591,-1.5769319248486626
341.4000000000041,39.9573621408607,0.39994668073120027,-1.6082506846050517
342.50000000000415,40.06370838211912,0.4080608144246152,-1.639323456914561
343.6000000000042,40.169614334927445,0.4134060267278102,-1.6720864809390212
344.7000000000042,40.27692006520625,0.4203640282587522,-1.70533860384992
345.80000000000416,40.384461768723156,0.42661445570302065,-1.7410843372133749
346.9000000000042,40.49019703279099,0.4301375546553593,-1.776138644767387
348.0000000000042,40.59657072086371,0.43520529284753373,-1.8119854707046725
349.10000000000423,40.703019412866524,0.43912142202831456,-1.8462665557086315
350.20000000000425,40.810817033774654,0.445562530402717,-1.8852335992407854
351.3000000000043,40.91725965194454,0.44920235557014127,-1.920201602854375
352.4000000000043,41.02295129927125,0.45441498699348026,-1.9579664456311554
353.5000000000043,41.13009601356151,0.45676061943051227,-1.9965203916068759
354.60000000000434,41.23656801218204,0.45936760804269516,-2.0351489914597565
355.7000000000043,41.343523089653125,0.4597982574401868,-2.073180767492601
356.80000000000433,41.449485308562885,0.45953613002492455,-2.1133450259529054
357.90000000000435,41.556596437653596,0.457515209151576,-2.151033526104425
359.0000000000044,41.66409558762447,0.4526240250841949,-2.1903393707668615
360.1000000000044,41.76939144046118,0.44779575177402453,-2.2321881235167647
361.2000000000044,41.87715606220019,0.43957274651109296,-2.269658915606433
362.30000000000445,41.98359706596715,0.4303774423037828,-2.307674746432318
363.4000000000044,42.088094814576216,0.41642211745113594,-2.345850025767297
364.50000000000443,42.19598432837659,0.400196732141622,-2.381293775279425
365.60000000000446,42.30265126990117,0.38070664226174605,-2.4176715680261305
366.7000000000045,42.41009765496228,0.3606167857241484,-2.4517031938723433
367.8000000000045,42.51667877549222,0.334645838475341,-2.4821327387940393
368.9000000000045,42.6230134694555,0.3049144357925589,-2.512608815930185
370.00000000000455,42.72958795511947,0.2779127611900972,-2.541549966390787
371.10000000000457,42.83538844569705,0.24749867581115437,-2.5675270102044614
372.2000000000046,42.94293761582598,0.21541064605946886,-2.591182957620285
373.30000000000456,43.04950473156679,0.18318232705230314,-2.610868207971622
374.4000000000046,43.15605638322139,0.15313680671371566,-2.6290474891126885
375.5000000000046,43.26160247295876,0.12343624015171034,-2.6447602300180266
376.6000000000046,43.36920157733199,0.09469472193546802,-2.656449655294866
377.70000000000465,43.476147364915235,0.07542044361805272,-2.6683655546866785
378.8000000000047,43.58293597737193,0.055438597715468996,-2.6766669711875655
379.9000000000047,43.68965111951304,0.037787786754367336,-2.6854784657758
381.00000000000466,43.79537010339789,0.02687215406246335,-2.6928473318903405
382.1000000000047,43.90309743964225,0.016952409964350934,-2.698568784540787
383.2000000000047,44.010495313278575,0.008919080223084963,-2.7039983140564408
384.30000000000473,44.116697114597486,0.0018438289131023633,-2.7080175402997195
385.40000000000475,44.224645057593314,-0.0022698819823857574,-2.711188322309961
386.5000000000048,44.331883041903936,-0.005319543734491172,-2.7167506668067043
387.6000000000048,44.43961583617666,-0.009807590603077954,-2.723101122992709
388.7000000000048,44.546725051681435,-0.013897538754389871,-2.7265013878193374
389.80000000000484,44.654087793698835,-0.01580466136764641,-2.729101840006331
390.9000000000048,44.759197603393126,-0.01642368278663181,-2.7325321203928725
392.00000000000483,44.86822206512682,-0.021531935772371114,-2.734718617580156
393.10000000000485,44.975650293124964,-0.025900323865282182,-2.740505391860484
394.2000000000049,45.082389240686034,-0.02459420889707381,-2.744908335840686
395.3000000000049,45.18607145209678,-0.028900265436596295,-2.7473341087035843
396.4000000000049,45.296121567131124,-0.03099588685598692,-2.7499857854888012
397.50000000000495,45.40389188179508,-0.03402823190167259,-2.7541925664792783
398.6000000000049,45.51066600971045,-0.03691913311586681,-2.7583478125084797
399.70000000000493,45.618202636487766,-0.0377872866057955,-2.76189186691363
400.80000000000496,45.72585998388107,-0.03842548573767002,-2.765739149767053
401.900000000005,45.83317278883676,-0.039759928301290715,-2.769180452086646
403.000000000005,45.939446317903595,-0.04274928417951118,-2.770497632090101
404.100000000005,46.04598090042046,-0.04222706085234457,-2.7730589957058833
405.20000000000505,46.155318027147395,-0.04519933864673009,-2.778382289677005
406.30000000000507,46.26234506252971,-0.0457840059607979,-2.782571672595255
407.4000000000051,46.37120460377712,-0.04827361396248919,-2.784631753515651
408.50000000000506,46.47805662477617,-0.046695883200418675,-2.787382947670972
409.6000000000051,46.58520041659651,-0.04878903246229982,-2.79068272429454
410.7000000000051,46.69180749894431,-0.05025929015295888,-2.794136402240211
411.8000000000051,46.80029411848023,-0.05172815180308882,-2.7972619191130974
412.90000000000515,46.90800331291222,-0.05314280997646953,-2.801276926309362
414.0000000000052,47.01483560399318,-0.052103879649155915,-2.8042323467910317
415.1000000000052,47.12211084602972,-0.053695072627774565,-2.8075298280142347
416.20000000000516,47.23055783286077,-0.05501274796073119,-2.81033815882837
417.3000000000052,47.337029014022136,-0.05493844532417075,-2.812861482852311
418.4000000000052,47.445444633773945,-0.05419485638716848,-2.8156168565610535
419.50000000000523,47.5506515264785,-0.05451878222161838,-2.8197680126866915
420.60000000000525,47.65920926092494,-0.05434092269405583,-2.8224209449138575
421.7000000000053,47.766208846280705,-0.05502328138445933,-2.825046554458121
422.8000000000053,47.87444690822576,-0.0538617596141574,-2.8276774732217045
423.9000000000053,47.98241297076325,-0.05420591183531076,-2.830315790607119
425.00000000000534,48.08948310925768,-0.054134585566575466,-2.8342757416306377
426.1000000000053,48.197246613145474,-0.051833624509967535,-2.8356984309399786
427.20000000000533,48.30557897005825,-0.05040424724421122,-2.8401705871949
428.30000000000535,48.41444453182581,-0.05038105136631993,-2.844111080215087
429.4000000000054,48.518386986942964,-0.04925219244204837,-2.8476478762833723
430.5000000000054,48.629117419037115,-0.047847703479512615,-2.8489955864525305
431.6000000000054,48.73636012802633,-0.04420847110802856,-2.8507378050698122
432.70000000000545,48.84486794170767,-0.0446195340345199,-2.8547323825749538
433.8000000000054,48.95239480270578,-0.04216031741202947,-2.8573590360409487
434.90000000000543,49.06037250540242,-0.039089792236583376,-2.8593009236680667
436.00000000000546,49.168840721706175,-0.03961459330753292,-2.860620856266748
437.1000000000055,49.27687689781251,-0.036874396132666964,-2.862445727990565
438.2000000000055,49.38537529999409,-0.036050370405711074,-2.862567737372232
439.3000000000055,49.492104183185525,-0.03020914614943282,-2.8684623154519366
440.40000000000555,49.59930309004865,-0.028350472284395245,-2.872038979483268
441.50000000000557,49.70759359136543,-0.024321675405603815,-2.8746729633500108
442.6000000000056,49.81586441859541,-0.023786078820600964,-2.8774093396622367
443.70000000000556,49.92480846122658,-0.020155309294173918,-2.87920393468658
444.8000000000056,50.03030550200861,-0.017287638154169283,-2.8813796587156717
445.9000000000056,50.138726723128556,-0.01696423190716384,-2.8839173215413583
447.0000000000056,50.2470085648781,-0.012274755759387412,-2.8842587381507094
448.10000000000565,50.35463002206815,-0.012329354864409392,-2.885343434349177
449.2000000000057,50.46337148762826,-0.010810974247422889,-2.888879521066193
450.3000000000057,50.57116460879838,-0.010194829654613047,-2.8920080029289297
451.40000000000566,50.68021685393856,-0.008167943751826001,-2.8946502839222914
452.5000000000057,50.78835197032885,-0.0067401134491670844,-2.8959764233371996
453.6000000000057,50.89611217074311,-0.006079569269908658,-2.897366014621058
454.70000000000573,51.00489682355169,-0.004214438545426358,-2.9010900935159505
455.80000000000575,51.11262346323564,-0.0017223994133743759,-2.903979124597099
456.9000000000058,51.22051815494087,0.0012902322077777417,-2.9053001779623053
458.0000000000058,51.328823513008444,0.003101399840327701,-2.9066074625483287
459.1000000000058,51.438346235253654,0.004939115629293334,-2.909267795420245
460.20000000000584,51.54679545985501,0.006088528307434782,-2.9120646445887717
461.3000000000058,51.65449423138142,0.0067717375673465585,-2.9133220420992094
462.40000000000583,51.76266791373389,0.007824645652082185,-2.913520719978177
463.50000000000585,51.86898407245382,0.011472197724634314,-2.9143327420268115
464.6000000000059,51.98020672831057,0.014750579547667175,-2.917369884650312
465.7000000000059,52.08707188913276,0.017071353747435736,-2.918575811966239
466.8000000000059,52.1964514367082,0.018665732824942327,-2.9196796761767745
467.90000000000595,52.303659682702204,0.018682062171493263,-2.921198263027468
469.0000000000059,52.41277525672015,0.019808198995891313,-2.9228295206350547
470.10000000000593,52.52194338435952,0.02051090730854921,-2.9245577656428132
471.20000000000596,52.63087905923212,0.022360762172417004,-2.9259931843311513
472.300000000006,52.738978213736445,0.021288592719143684,-2.926906097665431
473.400000000006,52.84693369986637,0.023521341550140296,-2.9295594852362585
474.500000000006,52.95569211441925,0.025576445717525265,-2.9316357995295705
475.60000000000605,53.06443924337975,0.025440550733811407,-2.932879381945161
476.70000000000607,53.17288929324832,0.02544962533309636,-2.9348179795348095
477.8000000000061,53.28127257072745,0.028220609210206693,-2.9348799412976416
478.90000000000606,53.39030716701994,0.027311319532486666,-2.936165741012138
480.0000000000061,53.49822130162764,0.02722492646635738,-2.936484927036602
481.1000000000061,53.60562916282496,0.029661422795053904,-2.9398890097610946
482.2000000000061,53.71516083848768,0.029367963244464113,-2.9417750422563294
483.30000000000615,53.82342147162277,0.030949146904534874,-2.94325958030179
484.4000000000062,53.93159681746735,0.032586755197044404,-2.9443229807950138
485.5000000000062,54.04000000000065,0.03416919345676628,-2.945699845064565
486.60000000000616,54.14822732150653,0.03567857944517577,-2.9478264788835005
487.7000000000062,54.255820636603765,0.03722917053569097,-2.9483531135177814
488.8000000000062,54.365369231170135,0.039002559894119215,-2.949649806598467
489.90000000000623,54.47342395793137,0.04456098656734092,-2.9496507326245096
491.00000000000625,54.58173046136735,0.04909516863995844,-2.9522834171828904
492.1000000000063,54.68865398358342,0.053703143441566764,-2.952279844174473
493.2000000000063,54.798493013662906,0.05511932354272492,-2.9536128349511634
494.3000000000063,54.907434406029296,0.05724499484562337,-2.9549205795277285
495.40000000000634,55.01605818572531,0.06043317642928131,-2.956252031797191
496.5000000000063,55.12541893483599,0.062177889711167306,-2.957188577661963
497.60000000000633,55.23408024073418,0.06547753652226793,-2.960177796695766
498.70000000000636,55.34340007211228,0.0677923102315188,-2.961847185726333
499.8000000000064,55.449913647422306,0.07045306341656415,-2.963800786542584
500.9000000000064,55.56000114673932,0.06958231706802684,-2.9624900112460173
502.0000000000064,55.66971333579495,0.07079619345426466,-2.9638105694631194
503.10000000000645,55.77857716914182,0.07299577057576107,-2.9634825119225736
504.2000000000064,55.887342229479785,0.07530150674421851,-2.9637577516133273
505.30000000000643,55.996210350821784,0.0748470248122281,-2.967757361591361
506.40000000000646,56.10520453928389,0.07623460981964736,-2.969063960160138
507.5000000000065,56.21408596886487,0.07769507709963558,-2.970393038409175
508.6000000000065,56.32387859067276,0.0793135692705251,-2.9713552284918725
509.7000000000065,56.43309569874367,0.07884554603475147,-2.9717196537566326
510.80000000000655,56.54179387400409,0.07587166786622368,-2.9730188712962966
511.90000000000657,56.65065640202411,0.07880439050707488,-2.973537611061367
513.0000000000066,56.75971296579963,0.07889624370320092,-2.9743498099187575
514.1000000000065,56.86904761801519,0.07784791208570341,-2.9756710728247464
515.2000000000066,56.97739855783701,0.07806159534330298,-2.9770020463493436
516.3000000000065,57.08679241229404,0.08023759974389846,-2.978312006537193
517.4000000000067,57.195149999974184,0.08059065313802768,-2.9793729011123817
518.5000000000066,57.3043563380345,0.07928037043563663,-2.981916739586098
519.6000000000067,57.41376448898769,0.08247754997714679,-2.983144988780622
520.7000000000066,57.5225063431641,0.08316953208683278,-2.980939154721141
521.8000000000067,57.63146420394969,0.08193968046650688,-2.9823098663544014
522.9000000000067,57.740714775297896,0.08352603381021803,-2.9848900147509485
524.0000000000067,57.84916566275453,0.08150118895361741,-2.986213759088031
525.1000000000067,57.959692737444364,0.07970420025025282,-2.987200175819257
526.2000000000068,58.06574812234416,0.08147143554773531,-2.9871882961433895
527.3000000000068,58.1769986754108,0.07961440698187222,-2.9898329320664816
528.4000000000068,58.285089538141,0.08074636018709319,-2.990564106572175
529.5000000000068,58.395528350586936,0.08044967971346809,-2.990489816721297
530.6000000000068,58.505295033692114,0.07771130893719924,-2.9918328631058073
531.7000000000069,58.61484714709267,0.07605601565405973,-2.9928290831059017
532.8000000000068,58.72407792520535,0.07588007681830466,-2.9931341761442987
533.9000000000069,58.83404410108944,0.07579254036551522,-2.9965324137509146
535.0000000000068,58.94304712660977,0.07577303698957194,-2.9950604318401965
536.100000000007,59.04989156276364,0.07281516635643634,-2.9950999462800745
537.2000000000069,59.16194961553482,0.0697871105343057,-2.995759967332174
538.300000000007,59.26982862218482,0.06810621695806884,-2.9970695020203064
539.4000000000069,59.381110496115596,0.06740457073241715,-2.9983604165869244
540.5000000000069,59.49065870904671,0.06587514792194024,-2.9997190361556108
541.600000000007,59.59847995705947,0.061868008520683915,-3.000247043375306
542.700000000007,59.70904993371896,0.060016115300892375,-2.9997117954867702
543.800000000007,59.81807276643607,0.05786960885657466,-3.000699854740807
544.900000000007,59.92784241559109,0.05633460068255694,-3.002022399326216
546.000000000007,60.036827404108124,0.05359270880720049,-3.0032937510109488
547.1000000000071,60.14649428955978,0.052884143111692206,-3.00334245595534
548.2000000000071,60.254540901869845,0.051231149827789424,-3.003339884778055
549.300000000007,60.36343334721813,0.05057673784232683,-3.0046185335397317
550.4000000000071,60.47286154095518,0.05042539943925042,-3.0079082345961936
551.500000000007,60.583182356141315,0.05000391489329517,-3.0086101351962684
552.6000000000072,60.692920685460926,0.05253671522813705,-3.0086113385969746
553.7000000000071,60.80031629045283,0.05019636530318264,-3.0099296804440874
554.8000000000072,60.91230515952215,0.04705896997165862,-3.01036460799011
555.9000000000071,61.021171207324194,0.04866561270994069,-3.0125990170321666
557.0000000000072,61.130935467412606,0.04890212427980015,-3.014216507307782
558.1000000000072,61.24028971054253,0.047607715565488734,-3.012348042017713
559.2000000000072,61.34879310047909,0.04332441032805165,-3.011573687468383
560.3000000000072,61.45894669529093,0.04584349549033462,-3.012803199717448
561.4000000000073,61.56725513066843,0.04528637317343631,-3.015519859478941
562.5000000000073,61.67633251725373,0.042254179444444095,-3.015582177402288
563.6000000000073,61.78645001012177,0.040464737726541106,-3.0158498351940684
564.7000000000073,61.897055967415014,0.04007286015593181,-3.0184763378567836
565.8000000000073,62.0061758530853,0.03933906277742205,-3.021108673794795
566.9000000000074,62.11450188273987,0.03717473794405782,-3.0224390110247956
568.0000000000074,62.22466627066943,0.040197634784690045,-3.0214489105721585
569.1000000000074,62.3344535789113,0.03688002872039173,-3.0214498980376057
570.2000000000073,62.4432719410529,0.03922984182985137,-3.0224300346614505
571.3000000000073,62.55443535251368,0.039630876463594894,-3.0250699229282074
572.4000000000074,62.66372148256964,0.03693903873934912,-3.025068834043622
573.5000000000074,62.772619768843406,0.039822790354640536,-3.025070010000495
574.6000000000074,62.883500281275246,0.03922775585801214,-3.0250700168205706
575.7000000000074,62.99270317341433,0.03425676252979809,-3.0250765758354365
576.8000000000075,63.1026869884855,0.03251125977006708,-3.026389921996279
577.9000000000075,63.21061719705608,0.031046656820293672,-3.0271070184724995
579.0000000000075,63.322361318142676,0.03049701429870741,-3.027744795267771
580.1000000000075,63.43260354942527,0.030360397348337953,-3.0290653709437594
581.2000000000075,63.541644746289855,0.028529191906753543,-3.0303501920676275
582.3000000000076,63.65146313709911,0.02707580011600827,-3.0316599428397217
583.4000000000076,63.75999796695663,0.028132747236600447,-3.03165990643762
584.5000000000076,63.87156597312302,0.026225877077897974,-3.032320629610503
585.6000000000076,63.98102539312049,0.02300429493283232,-3.031653873972431
586.7000000000077,64.09093073160969,0.02002967948307044,-3.03166027198306
587.8000000000077,64.20091898206113,0.02011992670174023,-3.0329748910378096
588.9000000000076,64.31087543162694,0.021126791543649298,-3.035280117855133
590.0000000000076,64.42131467013122,0.020727645099551495,-3.0369302719385445
591.1000000000076,64.53000189404479,0.022038889452247135,-3.036930179984609
592.2000000000077,64.63999892299003,0.01966640505133732,-3.036930454696879
593.3000000000077,64.74784324590922,0.01935472025970425,-3.0379189396870316
594.4000000000077,64.85622972637745,0.015964480803374426,-3.0379198676630557
595.5000000000077,64.96824073876887,0.01802740808536063,-3.0392284370131737
596.6000000000078,65.07795148829086,0.016673903050660493,-3.0405688034265896
597.7000000000078,65.18677407906068,0.01528413995750455,-3.039231904700459
598.8000000000078,65.29788854822142,0.015064704570838,-3.0419263171456077
599.9000000000078,65.40710634583593,0.015963205438128653,-3.043016759839782
601.0000000000078,65.51617156314856,0.013614759072565125,-3.042630212044492
602.1000000000079,65.62591470904262,0.012627072435864223,-3.041919978357966
603.2000000000079,65.73557219639727,0.012316831290034136,-3.0445837570185916
604.3000000000079,65.84505511027984,0.012432314518455279,-3.044619951539743
605.4000000000078,65.95454934052,0.0124530586379141,-3.0453353783321475
606.5000000000078,66.06380354172882,0.008038515898505544,-3.045269899702983
607.6000000000079,66.17405878348612,0.008799826456145271,-3.045265352432423
608.7000000000079,66.28370704614318,0.007004359331149762,-3.0465899777569088
609.8000000000079,66.39335875083894,0.007259208566895298,-3.0465899750002996
610.9000000000079,66.50299273440916,0.0038537210254282195,-3.046589278551602
612.000000000008,66.61343539585067,0.005859081159787088,-3.04675339474262
613.100000000008,66.72237705259364,0.0023101218973018423,-3.0492051243006744
614.200000000008,66.83258138459088,0.001745392210529384,-3.0505399695728053
615.300000000008,66.94269688427777,0.002247890280442616,-3.051859236570244
616.400000000008,67.05200578521142,0.0027971938998958834,-3.0505396857341176
617.5000000000081,67.16272031432545,-0.00048324075491371077,-3.0505398179215626
618.6000000000081,67.27320510789427,-0.0032782913719899,-3.050537152066906
619.7000000000081,67.3821988021204,-0.0028815499451345927,-3.0518604526777158
620.8000000000081,67.4930790646161,-0.005566632058684351,-3.0518598498976077
621.9000000000082,67.60045982149985,-0.00677702680991113,-3.0518949482105326
623.0000000000082,67.71194758554046,-0.008974507700950846,-3.0545785325287387
624.1000000000081,67.8233656506529,-0.012671072182961152,-3.0567413341106744
625.2000000000081,67.93277384468227,-0.011451918795503169,-3.0573641944076604
626.3000000000081,68.04312499112045,-0.014238979055030132,-3.057130949138325
627.4000000000082,68.15310897806388,-0.01739535478266213,-3.057097073951635
628.5000000000082,68.2624089008255,-0.015218748967776502,-3.057240644525737
629.6000000000082,68.37372407911879,-0.01665007426213283,-3.058440138281445
630.7000000000082,68.48338475661939,-0.018957303564171107,-3.0584472144015433
631.8000000000083,68.59130717359243,-0.01840080212115419,-3.0584498815671717
632.9000000000083,68.70332506120519,-0.018376116458664105,-3.059769802402514
634.0000000000083,68.81299285111405,-0.020794559217544417,-3.0587803003888796
635.1000000000083,68.922131838003,-0.020431691324182683,-3.0600898602696773
636.2000000000083,69.0314905909219,-0.01645460763633666,-3.0600902480045127
637.3000000000084,69.1422982006893,-0.01945790369829739,-3.0597053220929546
638.4000000000084,69.25296417363295,-0.019050428010014664,-3.059225114551605
639.5000000000084,69.36146265414585,-0.022495316447866204,-3.0597384728303694
640.6000000000083,69.46969227748792,-0.023837431675654247,-3.0610802424699646
641.7000000000083,69.5823771050649,-0.02035889259861612,-3.062397122977446
642.8000000000084,69.69081972753412,-0.023247323506388973,-3.063060732412193
643.9000000000084,69.8015035329276,-0.021254333025449768,-3.065690950877535
645.0000000000084,69.9126918439859,-0.026698244054246784,-3.0655699344690666
646.1000000000084,70.0226951301923,-0.025064144278161476,-3.0643700809454115
647.2000000000085,70.13207036236903,-0.028825966338201586,-3.0643699845265076
648.3000000000085,70.24217767775,-0.029100870573231657,-3.0646989348918368
649.4000000000085,70.35228995024103,-0.03231784367940904,-3.066019532439943
650.5000000000085,70.46261835318894,-0.03571869612502343,-3.0646957482036377
651.6000000000085,70.57362271723348,-0.03700586023600247,-3.064700156248845
652.7000000000086,70.68282090393316,-0.036363540684814316,-3.0673269571412223
653.8000000000086,70.79244472302108,-0.03874191311949271,-3.06718254330463
654.9000000000086,70.90317979982704,-0.040950596930047684,-3.0646666043839508
656.0000000000086,71.01326185818078,-0.03942052592344239,-3.0669344117093886
657.1000000000087,71.1225937784562,-0.042027095283312665,-3.0666918812031057
658.2000000000087,71.2328668988614,-0.04534096774756685,-3.069319462247342
659.3000000000086,71.343043370602,-0.044776677366036716,-3.069320165002196
660.4000000000086,71.45301097986135,-0.046186157127481337,-3.0693171772705954
661.5000000000086,71.5635948849352,-0.0456817376615406,-3.0706323255357044
662.6000000000087,71.67270503999413,-0.0424840278893894,-3.0693100777518567
663.7000000000087,71.78347875535916,-0.04798056548727411,-3.0706187563270717
664.8000000000087,71.89449174646057,-0.045848179187667426,-3.071950104814868
665.9000000000087,72.00494674208528,-0.044973844240121935,-3.071868116219452
667.0000000000088,72.11459196634283,-0.04645670321727813,-3.073269866270085
668.1000000000088,72.22449827234746,-0.0476708474841189,-3.07390843112083
669.2000000000088,72.33576493825962,-0.051632456054772874,-3.073594799728722
670.3000000000088,72.44588522380641,-0.051974459725391636,-3.074910529806409
671.4000000000088,72.55670609530924,-0.054373231245910814,-3.07626299420345
672.5000000000089,72.66687747975159,-0.05470793536502608,-3.0735840666799668
673.6000000000089,72.77659567461708,-0.055292104471502596,-3.0742466148182093
674.7000000000089,72.88727479174116,-0.055448012519793866,-3.071607717497255
675.8000000000088,72.99773592713558,-0.05611364759747661,-3.074250115383389
676.9000000000088,73.10875935994237,-0.05863171844570164,-3.0731730802351853
678.0000000000089,73.21843103678975,-0.05735902448297253,-3.0742553493659877
679.1000000000089,73.32980040039268,-0.05740093212283651,-3.0755751293350237
680.2000000000089,73.43871171629678,-0.054655050740661903,-3.074817520782805
681.3000000000089,73.5494040763213,-0.05813995218938811,-3.074909944211507
682.400000000009,73.65937376070228,-0.05621131059078274,-3.077240107380854
683.500000000009,73.77009894067079,-0.057401231708046535,-3.076692067106539
684.600000000009,73.88093561402485,-0.05735425459144469,-3.0752441886504744
685.700000000009,73.98955996699036,-0.05763698418647331,-3.076559642320926
686.800000000009,74.10208721979025,-0.059157754153716074,-3.075249679091316
687.9000000000091,74.21227797139218,-0.05938896451182693,-3.076563862587964
689.0000000000091,74.3200000000009,-0.06380548192742333,-3.0765599432741504
690.1000000000091,74.43289658921091,-0.06486640624192835,-3.077879879257385
691.2000000000091,74.54358017648316,-0.06668822662182788,-3.079190058090219
692.3000000000092,74.65460106514904,-0.06539090734722511,-3.0805103914934664
693.4000000000092,74.76423554570707,-0.06889227409243734,-3.0790819162741734
694.5000000000091,74.87483463034924,-0.07018947181787119,-3.0805956250958744
695.6000000000091,74.98595055710369,-0.06965955634789911,-3.081828668194108
696.7000000000091,75.09581332649543,-0.07088153222122642,-3.081830130000748
697.8000000000092,75.20776121844459,-0.0727425962225324,-3.0818301299999997
698.9000000000092,75.3180842352196,-0.07384534815847821,-3.08183013
700.0000000000092,75.42841203945966,-0.07162879942999031,-3.08183013
701.1000000000092,75.53724268138781,-0.07237729596238726,-3.0818301299977406
702.2000000000093,75.6481724408254,-0.07427786819660145,-3.0818362292360857
703.3000000000093,75.76029538727045,-0.0716210846079435,-3.081736893313124
704.4000000000093,75.86970943863821,-0.07148655672088258,-3.084103155551952
705.5000000000093,75.980283741516,-0.0724373221126208,-3.0831584487773624
706.6000000000093,76.09061524492401,-0.07459322177154407,-3.083202904658866
707.7000000000094,76.20066295567098,-0.07379225692985977,-3.08182503269982
708.8000000000094,76.31150854315766,-0.0750448655805688,-3.081725471762468
709.9000000000094,76.420843794625,-0.0740680535632395,-3.0840132002812197
711.0000000000093,76.53045770839725,-0.07278811636271998,-3.08435082899664
712.1000000000093,76.64079638275652,-0.07346449210912817,-3.0869755054887364
713.2000000000094,76.75154219519287,-0.0765744233244284,-3.086990129695418
714.3000000000094,76.86299667840021,-0.0757272591560118,-3.08567012427223
715.4000000000094,76.97275793991474,-0.07575957338107431,-3.085670130000002
716.5000000000094,77.0833317509722,-0.07576773976564238,-3.085670129999418
717.6000000000095,77.1941701071219,-0.07783059791099137,-3.085671675073577
718.7000000000095,77.30361228523805,-0.07739626297125204,-3.0856248647089934
719.8000000000095,77.41570179371347,-0.0796433011632586,-3.086990199643226
720.9000000000095,77.5259460215939,-0.07711877563185296,-3.086989861488882
722.0000000000095,77.63732273696614,-0.08076088497585471,-3.0870264964576126
723.1000000000096,77.74806549475807,-0.07779787556364204,-3.0869901414770053
724.2000000000096,77.85802592537054,-0.07908368757900408,-3.087986652931987
725.3000000000096,77.96944681322685,-0.07873612523092655,-3.0896312730349837
726.4000000000096,78.08041532611787,-0.08203499580183626,-3.0909401874124955
727.5000000000097,78.18928670805131,-0.08424041827617959,-3.0886843675952793
728.6000000000097,78.30204332250061,-0.08532447653880126,-3.0883099149679287
729.7000000000096,78.41368175832048,-0.08828540573952903,-3.088304424571348
730.8000000000096,78.52411613214835,-0.0885121073094636,-3.0896201303647692
731.9000000000096,78.63468229896293,-0.09040427118295402,-3.089629153142396
733.0000000000097,78.7457948722858,-0.09457683975280912,-3.0896772203979292
734.1000000000097,78.85618308829915,-0.09585672208208185,-3.0893006081224925
735.2000000000097,78.96710198147267,-0.09894315000830242,-3.089619825130355
736.3000000000097,79.07825409758794,-0.09792090837854317,-3.089554369573469
737.4000000000098,79.1878346447751,-0.1001931496708871,-3.089619880727284
738.5000000000098,79.29932110827382,-0.10162383285182305,-3.0906107104481757
739.6000000000098,79.40981017456693,-0.10179883786337396,-3.0896315703614317
740.7000000000098,79.52089277887086,-0.1023735546737381,-3.0900053051378227
741.8000000000098,79.63091086568933,-0.09990050463846978,-3.090613356985158
742.9000000000099,79.74147694706471,-0.10232513135725177,-3.091964242207837
744.0000000000099,79.85309158319954,-0.10649876529343555,-3.0892860233209207
745.0000000000099,79.95323822503696,-0.1061743188654733,-3.0906099419303037