File: 01_Data/Plastic_Laminate_Countertop_Particle_Board/STA/N2/10K_min/Plastic_Laminate_Countertop_Particle_Board_STA_N2_10KData_221004_R1.csv
##Temp./Â°C,Time/min,DSC/(mW/mg),Mass loss/mg
51.0,10.776525012274757,0.05527238368125009,0.0012827638039603073
52.100000000000016,11.137959806543327,0.08560939553841207,-0.0009626503731867686
53.20000000000003,11.383509849831164,0.10939492833170594,-0.0021855956266918497
54.30000000000005,11.594240432782179,0.13011791023011066,-0.004283250532221672
55.40000000000006,11.777483422505636,0.14428106948140718,-0.0018951339577997217
56.50000000000008,11.954181016452427,0.15685546737299738,-0.0023262724313175553
57.600000000000094,12.114372231992983,0.1706719309974607,-0.00429165650302199
58.70000000000011,12.268221661552777,0.18043388900454405,-0.001958193148907661
59.800000000000125,12.416101297547865,0.18642657905158422,-0.0005253000078306869
60.90000000000014,12.564726267717775,0.1948270546653974,-0.0035751617077117714
62.000000000000156,12.708416196638785,0.20194903946263487,-0.004458414838852676
63.10000000000017,12.846272227021354,0.20926464442394188,-0.0032679171660410233
64.20000000000019,12.981761560814542,0.21584028827444657,-0.005252069980575591
65.30000000000021,13.117527800735544,0.22091816293386524,-0.004602576242347389
66.40000000000022,13.251266555602434,0.2274823877822737,-0.002067292349495986
67.50000000000023,13.382121843788347,0.23082762713476934,-0.0032478565634033174
68.60000000000025,13.512619709689899,0.23839045403834802,-0.003986253372689319
69.70000000000027,13.641851851737913,0.24299069842292043,-0.004617787207246593
70.80000000000028,13.767001040333632,0.24888644587221842,-0.007578869160531632
71.90000000000029,13.893838844367444,0.2555091856048741,-0.0073887690824747665
73.00000000000031,14.015528726531338,0.26074281810652433,-0.005983253110184883
74.10000000000034,14.14114637581948,0.2627125103896323,-0.006329045070210704
75.20000000000034,14.265233940464327,0.26806249441446306,-0.006370179373723417
76.30000000000035,14.38528268752785,0.27441777552515667,-0.007692441271185402
77.40000000000038,14.50811019826853,0.27852496426060935,-0.006372243095746022
78.5000000000004,14.626284076106973,0.28517339505258676,-0.0063472258987591346
79.6000000000004,14.745459146813964,0.2902888467469137,-0.007681576762756492
80.70000000000041,14.865139168450185,0.29294053795965347,-0.009007638147442876
81.80000000000044,14.981765275241939,0.29361728502909956,-0.009010114454083507
82.90000000000046,15.099580059709911,0.29854470322473836,-0.009279206252736039
84.00000000000047,15.216005329489482,0.30048180171106365,-0.010356267900642813
85.10000000000048,15.331863770979362,0.3027215977821528,-0.010508151119840825
86.2000000000005,15.446230852621598,0.3053316348299798,-0.010318300024112936
87.30000000000052,15.561771811620527,0.3065199819471597,-0.010265659415096273
88.40000000000053,15.675085118691335,0.3070099685828823,-0.011552313378745183
89.50000000000054,15.787702706564168,0.309477533180907,-0.010534437070394809
90.60000000000056,15.899796606907094,0.3112920482842767,-0.011546982570690645
91.70000000000059,16.013257309391847,0.3110408020560469,-0.014168992119015122
92.8000000000006,16.125750066432694,0.3119443598201005,-0.014138572380636205
93.9000000000006,16.235551765359048,0.30960697819907745,-0.014166521602323456
95.00000000000063,16.347927113595073,0.31036166728090997,-0.012768132803502752
96.10000000000065,16.459170000000064,0.30815471941832884,-0.012852691170600394
97.20000000000066,16.56791806096559,0.30748133634116526,-0.013774048969143138
98.30000000000067,16.678677425126576,0.3058297189207474,-0.015517153034892317
99.40000000000069,16.786711785119337,0.3070384422944926,-0.013499492886731801
100.50000000000071,16.898919704369817,0.3051228762170113,-0.016289739360662026
101.60000000000072,17.00863219677393,0.30512463456569827,-0.014936260853719574
102.70000000000073,17.11628379680892,0.30607132904803047,-0.01626348837002567
103.80000000000075,17.2257820101082,0.3039532719346054,-0.018215012672297526
104.90000000000077,17.33378897255497,0.30395945681269065,-0.016962149709023322
106.00000000000078,17.443063690541045,0.3030265423198477,-0.01856453009754766
107.10000000000079,17.55081424912575,0.30110883198962946,-0.01856017246079844
108.20000000000081,17.65974560065667,0.3001879189023777,-0.016579038291489212
109.30000000000084,17.768008818115728,0.29978378070526523,-0.016570234671253736
110.40000000000084,17.875537095909007,0.2999181701104442,-0.01657914939374283
111.50000000000085,17.982934810731127,0.29950701183899797,-0.015745691235028225
112.60000000000088,18.0908933665872,0.299155594948057,-0.01789793653139249
113.7000000000009,18.19917000000009,0.2977188844966224,-0.01808369881971217
114.8000000000009,18.306127333266407,0.29894479401991947,-0.01921827624766692
115.90000000000092,18.413969935919763,0.2991258470156075,-0.016829540484900818
117.00000000000094,18.521204980805916,0.29903115142611914,-0.01664132918506045
118.10000000000096,18.6283388720004,0.29723258213348136,-0.01691258090453296
119.20000000000097,18.736210526548525,0.29772242494079515,-0.016927137951294746
120.30000000000098,18.843021282559118,0.2986641837628201,-0.017800458813356457
121.400000000001,18.952650334596907,0.29872014214415177,-0.01693166295316928
122.50000000000102,19.057516080456605,0.2993614983692445,-0.019009571536068748
123.60000000000103,19.164799917916174,0.2991379178908915,-0.01927304743539171
124.70000000000104,19.272214061272837,0.3008321262319301,-0.019219974530764183
125.80000000000106,19.37787182818629,0.3029119542053791,-0.017900458889180015
126.90000000000109,19.484858393850246,0.3010982098403763,-0.017923610481013874
128.00000000000108,19.59316486390268,0.3030577571613329,-0.01787224651163477
129.1000000000011,19.700391293137333,0.30351647785460356,-0.017900150709920126
130.20000000000113,19.80599497716399,0.3011084497970232,-0.016567424319856805
131.30000000000115,19.91196010628735,0.30458881085884215,-0.01922040344956244
132.40000000000117,20.01670071681835,0.30524179686366293,-0.018228844723568116
133.50000000000117,20.122444534575084,0.3056162389490007,-0.01822981600055673
134.6000000000012,20.228382418978093,0.3094062106084886,-0.01822980825533449
135.7000000000012,20.33415825302558,0.308803108443646,-0.016911124591261206
136.8000000000012,20.442994713978415,0.31119188082455207,-0.017879994408732003
137.90000000000123,20.547654647487207,0.31314751343568004,-0.017899929697284378
139.00000000000125,20.65326143428338,0.3143607108501004,-0.01652377608940636
140.10000000000127,20.758928668253937,0.31547242784132723,-0.017900024779567758
141.2000000000013,20.864291256653612,0.3149947347961793,-0.01789988699203171
142.3000000000013,20.970116923344506,0.3164124288066998,-0.01789990928139229
143.4000000000013,21.075279550923902,0.31786391781964846,-0.01922034783078974
144.50000000000134,21.17958445615718,0.3205481814179908,-0.019206071528675928
145.60000000000133,21.28521381189129,0.3216879285568835,-0.019219887930226776
146.70000000000135,21.38994158015799,0.32229054988736217,-0.019220417597703765
147.80000000000138,21.496433354347033,0.3229783767016643,-0.018801327789408795
148.9000000000014,21.600773722544098,0.32374373754728564,-0.020012424248025518
150.00000000000142,21.705724317082307,0.32539673299095473,-0.020540087913126115
151.10000000000142,21.81091310213783,0.32651939595298685,-0.019550791049749883
152.20000000000144,21.915407306983735,0.32932489526598463,-0.019329502180726266
153.30000000000146,22.020351111849482,0.33024583585751743,-0.01921884355136605
154.40000000000146,22.122565706686622,0.3329563589923917,-0.02161195920746195
155.50000000000148,22.229804902306263,0.3329570283012993,-0.022954248018150825
156.6000000000015,22.332680350013458,0.33322595221195045,-0.021625390901113928
157.70000000000152,22.43727035403706,0.33911436206495055,-0.02029206574459197
158.80000000000155,22.54126733573179,0.33812179385014274,-0.02165231258549305
159.90000000000154,22.6472175840414,0.34310562393514704,-0.020319921324386314
161.00000000000156,22.752866481471813,0.34427484481072795,-0.020319398617397955
162.1000000000016,22.85651824291375,0.3445226706848364,-0.02015131830080019
163.20000000000158,22.960535665533968,0.34878606353954966,-0.020310384085082678
164.3000000000016,23.06599223202667,0.35126752514258897,-0.022948903844741242
165.40000000000163,23.17027368411148,0.35325298535683086,-0.022946866373078745
166.50000000000165,23.274013169649145,0.3545320920460813,-0.021630069195071933
167.60000000000167,23.379721996510153,0.35730208612712794,-0.021628418902547963
168.70000000000167,23.48269261137768,0.3615700927182813,-0.021949314729034164
169.8000000000017,23.587027030989645,0.36329035424737255,-0.022949767026684942
170.9000000000017,23.69169491591813,0.3665050454511174,-0.023748365546157224
172.0000000000017,23.795335182585795,0.3676274228939497,-0.024589959378495507
173.10000000000173,23.899960267492666,0.3723927928770396,-0.02458814226127437
174.20000000000175,24.004409634065993,0.37671189008627826,-0.02590994872653729
175.30000000000177,24.108729864453277,0.376144308154499,-0.02590995999632595
176.4000000000018,24.21384859980523,0.3806134297534282,-0.025936755080598672
177.5000000000018,24.318424552693465,0.3856801403642926,-0.027230128529188935
178.6000000000018,24.42203907018858,0.3880992739561274,-0.028549842152284732
179.70000000000184,24.52598483950698,0.3931154706792792,-0.02724363290089915
180.80000000000183,24.62956511865236,0.3949000546579868,-0.028532951211202473
181.90000000000185,24.73546364976868,0.3978901846943994,-0.029860127501978972
183.00000000000188,24.83906449973278,0.4029141960709275,-0.029860227465745126
184.1000000000019,24.945635966972517,0.4066888976062185,-0.031187777950196782
185.20000000000192,25.048786312594853,0.41049468415836265,-0.030732708236782535
186.30000000000192,25.153722157706618,0.41333193875536256,-0.031760438022372384
187.40000000000194,25.259072503963843,0.4192236648378204,-0.03283662344677207
188.50000000000196,25.36240621770105,0.4243195859990844,-0.03514031599488909
189.60000000000196,25.46688603546643,0.4270528456220039,-0.035140627741980346
190.70000000000198,25.570748942975374,0.43067542260651714,-0.03678833244117685
191.800000000002,25.676648493540533,0.4372335459305151,-0.03777018274965993
192.90000000000202,25.781341881051755,0.44047378722597774,-0.03907746977804649
194.00000000000205,25.883817889819547,0.44243115705761726,-0.040399934349387934
195.10000000000204,25.98837268913428,0.44719858517229183,-0.04246421964865377
196.20000000000206,26.092408260515416,0.4492955522594648,-0.043039010159804825
197.3000000000021,26.19811617569914,0.4522994747518462,-0.04532666486832637
198.40000000000208,26.301319551923388,0.45524706117687064,-0.045349832661131906
199.5000000000021,26.406696216302922,0.4554108346421202,-0.045680907058177844
200.60000000000213,26.510276356993124,0.45613089438724735,-0.04574729495659913
201.70000000000215,26.61470076432696,0.46102242946081334,-0.04699894304039187
202.80000000000217,26.717802616092243,0.4620292207466159,-0.05018321488563959
203.90000000000217,26.82284865964376,0.4647177447220177,-0.051276440125047174
205.0000000000022,26.927482767253885,0.46556237626613256,-0.053793348280545494
206.1000000000022,27.031520452310556,0.46590674269821114,-0.054968861011921444
207.2000000000022,27.136404769201626,0.4687358723984508,-0.05625409279468885
208.30000000000223,27.241036675971156,0.46938067117928695,-0.057530024226337684
209.40000000000225,27.344562664251104,0.4697515469424893,-0.057507908722400636
210.50000000000227,27.448353279105994,0.47179426261520874,-0.06007297130823552
211.6000000000023,27.552609308606993,0.471395112578495,-0.06147723684521322
212.7000000000023,27.658320571765916,0.4721852971582242,-0.06280091829009216
213.8000000000023,27.761050480362666,0.4740047956607609,-0.06507969861611551
214.90000000000234,27.864322595906966,0.4739257531528885,-0.06594046599203063
216.00000000000233,27.96906587285653,0.4768041986493533,-0.06806995080978995
217.10000000000235,28.07337414083524,0.4789216480954263,-0.06827906854754717
218.20000000000238,28.177489863560986,0.4805666397759515,-0.07202338591783919
219.3000000000024,28.282333026069615,0.4826171418012404,-0.07465026801225116
220.40000000000242,28.386403108965077,0.48261331870883284,-0.07834158482936004
221.50000000000242,28.490027709593296,0.48580178712674194,-0.0799324733036686
222.60000000000244,28.593995147825357,0.4844464200991724,-0.07860719466768762
223.70000000000246,28.698078952667434,0.48782073424769895,-0.08125500035321753
224.80000000000246,28.802010892041338,0.4887530625835648,-0.08268960767231226
225.90000000000248,28.90694760738391,0.48833058528044787,-0.08532843249357658
227.0000000000025,29.00990482283231,0.49045269811680037,-0.08925292886669567
228.10000000000252,29.11569452543931,0.4906820772809674,-0.09254091309885437
229.20000000000255,29.220347893082668,0.49423168818234736,-0.09628864522690694
230.30000000000254,29.325327967172367,0.49250942357597727,-0.09988012935154789
231.40000000000256,29.42898525035695,0.49138593755681864,-0.10166449158329272
232.5000000000026,29.534452562429152,0.49029010358323266,-0.10386251524815604
233.60000000000258,29.63749621272983,0.489756437688357,-0.10398681880128002
234.7000000000026,29.742533789673697,0.48755693551282303,-0.10641439554361698
235.80000000000263,29.846313636050446,0.4890411421408991,-0.11107840172024241
236.90000000000265,29.95027185828396,0.48859394170014797,-0.11487748053095004
238.00000000000267,30.05544475176624,0.48786423310345245,-0.12039303338609209
239.10000000000267,30.1597061361278,0.48800861935379497,-0.1216332200066974
240.2000000000027,30.26419467645933,0.48724394617360517,-0.12484315319899775
241.3000000000027,30.369262722627262,0.48547090881296806,-0.12966479730861957
242.4000000000027,30.472937715510103,0.4862959212373779,-0.1333388364074244
243.50000000000273,30.576305241805795,0.48625013836148795,-0.13689457724148513
244.60000000000275,30.68113169109083,0.48636607420735645,-0.14087068783105794
245.70000000000277,30.7840108976979,0.48776169399700153,-0.14497470213245967
246.8000000000028,30.88964854493316,0.4872069455391615,-0.15056671073573513
247.9000000000028,30.994150440864296,0.48608903718822516,-0.155624074125305
249.0000000000028,31.099504563744883,0.4875016503905982,-0.15952971247794068
250.10000000000284,31.203328314982667,0.4871330140332311,-0.16445618064156475
251.20000000000283,31.307545999266814,0.4867473215477797,-0.16964750217075153
252.30000000000285,31.412755534718816,0.4862867741663205,-0.1748798805215932
253.40000000000288,31.51649981997337,0.4862730271862879,-0.18001919423115265
254.5000000000029,31.62126136839374,0.4838122971525409,-0.185969524643955
255.60000000000292,31.725141727626625,0.483881713619618,-0.19065509598928942
256.7000000000029,31.82946049681349,0.48297945954259414,-0.19619493888024264
257.8000000000029,31.934968059928632,0.4824312634243663,-0.20302556263646387
258.90000000000293,32.03985599686853,0.4809288135632612,-0.20960261039710337
260.00000000000296,32.14420034188332,0.4808786507813475,-0.21621056498423696
261.100000000003,32.248630312392315,0.4794666182516159,-0.22275722122258612
262.200000000003,32.354189774946185,0.4786754402482545,-0.22799229365082052
263.300000000003,32.458785827061895,0.47556688359507016,-0.23346882713024764
264.40000000000305,32.563134749808825,0.47389280843647447,-0.24044591987993202
265.50000000000307,32.66665010408169,0.473740420085774,-0.24643508931168867
266.6000000000031,32.7727126990383,0.4707550563116533,-0.2563737649832598
267.7000000000031,32.87727501890766,0.46898858979074043,-0.26546548156616634
268.8000000000031,32.981341615766425,0.46651464390048947,-0.27446540362268035
269.9000000000031,33.086170298175844,0.4656386542980071,-0.28363003398082975
271.0000000000031,33.19164474746254,0.46085509427537147,-0.29399981604226655
272.10000000000315,33.295959458110396,0.4590972149947351,-0.30308022707892857
273.2000000000032,33.40029077808336,0.45454163907497847,-0.31203973096079984
274.30000000000314,33.50392336075885,0.4519541060096693,-0.3250366746467175
275.40000000000316,33.609429800294734,0.44940794530530953,-0.33312561432640075
276.5000000000032,33.71419773859033,0.44083166170915083,-0.3432698321352752
277.6000000000032,33.81871737315039,0.43755455514116126,-0.3546628573259172
278.70000000000323,33.92414208628622,0.4325731092249751,-0.3672456941830462
279.80000000000325,34.02814336712015,0.42855770173196234,-0.3789677042828137
280.9000000000033,34.133788357842,0.4226615801972396,-0.3921950260965077
282.0000000000033,34.239663358708675,0.41771458971211306,-0.40318549793545433
283.1000000000033,34.343813785013,0.41156804381061957,-0.4141179559924293
284.20000000000334,34.449665910850996,0.40333864992733337,-0.4288309691979917
285.30000000000337,34.55397280864075,0.39842138445058134,-0.4407175096138314
286.40000000000333,34.65866631303706,0.39166137703994086,-0.45410256974096574
287.50000000000335,34.76381452543776,0.38467077172261893,-0.4690822439330713
288.6000000000034,34.86845016957341,0.37870049633051434,-0.48338046544243385
289.7000000000034,34.97414799232784,0.3741653039265058,-0.4980938454910402
290.8000000000034,35.079466796606916,0.368407350041502,-0.5143865072590703
291.9000000000034,35.18408665354144,0.3625180433426393,-0.5291076831535655
293.0000000000034,35.288870908643446,0.356577385934378,-0.5441777982919533
294.10000000000343,35.39465987834223,0.35043135785983676,-0.5589117713659055
295.20000000000346,35.49859095824208,0.3461716520191682,-0.576829691661251
296.3000000000035,35.60392147039161,0.33984241402877535,-0.5919969360375572
297.4000000000035,35.71025999484763,0.33424414890427184,-0.6108529163380716
298.5000000000035,35.81503829404321,0.3327884529783082,-0.6268102868523822
299.60000000000355,35.91994124108012,0.32868431995549346,-0.6431148967556002
300.70000000000357,36.02295746133127,0.32810121319725477,-0.6601901764097291
301.8000000000036,36.13106731138938,0.3244480207670856,-0.677430990243947
302.9000000000036,36.23648970562467,0.3199488063670196,-0.6980342668207196
304.0000000000036,36.34059537177048,0.3184011144366584,-0.7175669016368964
305.1000000000036,36.44691923004955,0.31677682370535076,-0.7365712571559384
306.2000000000036,36.55196877313612,0.31463476197538237,-0.7556653852342619
307.30000000000365,36.65855132449384,0.3128725352122637,-0.7756102569409995
308.4000000000037,36.763426544266856,0.31314341605397383,-0.7940071830639646
309.5000000000037,36.86877180814673,0.3116136590692683,-0.8157035268337056
310.60000000000366,36.97533206838396,0.3103926057116008,-0.8371582927797512
311.7000000000037,37.08095879131876,0.3110405238317986,-0.8547915431161588
312.8000000000037,37.18604021745607,0.31180498052010397,-0.8766877117951588
313.90000000000373,37.29094210179233,0.3148508626444341,-0.8984677956734282
315.00000000000375,37.39637627571654,0.31378280354562277,-0.9206645274794036
316.1000000000038,37.502513658607505,0.31663269997654825,-0.9439072144495735
317.2000000000038,37.60897599955701,0.3167711643426215,-0.9674809268556612
318.3000000000038,37.71390030831714,0.32027671050953516,-0.9911452443887372
319.40000000000384,37.82062624511773,0.3205420572699566,-1.0150053786727478
320.5000000000038,37.925928530792575,0.3250407197047339,-1.0384863803701219
321.60000000000383,38.03208183258635,0.32742428526511314,-1.0610401881174818
322.70000000000385,38.13766661579971,0.33066489800682697,-1.0868653275063656
323.8000000000039,38.244745254701,0.3329878820817951,-1.1104411468188982
324.9000000000039,38.3515381134827,0.3369665238052375,-1.1377393040347683
326.0000000000039,38.456507834240924,0.3385956402310526,-1.1632054739091293
327.10000000000394,38.56289489837404,0.3433112170450301,-1.1888435974612297
328.2000000000039,38.669269121692416,0.34738841909448825,-1.2154380166450776
329.30000000000393,38.774994954335874,0.3497246600000216,-1.2430228432344288
330.40000000000396,38.88115059139009,0.35520160267800505,-1.2695892438114145
331.500000000004,38.98698142024628,0.3593867664633258,-1.297669977961088
332.600000000004,39.09301300978406,0.36643752851718053,-1.3278982414984655
333.700000000004,39.19964430030349,0.36862989885536235,-1.355326362285754
334.80000000000405,39.30533876599442,0.37349377495405073,-1.383901553057047
335.90000000000407,39.41101256312425,0.37788761465498805,-1.4141791326227344
337.0000000000041,39.51760897216701,0.38322541586725983,-1.4428431499947032
338.10000000000406,39.62441582343193,0.3855024309826363,-1.4749280496764912
339.2000000000041,39.73183836206346,0.3900951194117469,-1.5071420667006747
340.3000000000041,39.83698792919401,0.3983376201726798,-1.5368127787286125
341.4000000000041,39.944135982821905,0.40309231300064524,-1.56965335771506
342.50000000000415,40.04980246906671,0.40798383614045297,-1.6033589890238433
343.6000000000042,40.15629583016889,0.41284725437015285,-1.6382291233207273
344.7000000000042,40.26216309214671,0.42228115171781216,-1.671253031159221
345.80000000000416,40.369070572661634,0.4287652803401568,-1.7066768334046798
346.9000000000042,40.474810452843585,0.4344225740843298,-1.7420182637331054
348.0000000000042,40.582450561574134,0.4422414533479726,-1.7771595528477104
349.10000000000423,40.688352938278115,0.44726287993734065,-1.814204840463633
350.20000000000425,40.795808348600936,0.4550064078814968,-1.8531409328566841
351.3000000000043,40.8999280088811,0.463911292055546,-1.8891480199737205
352.4000000000043,41.00775296618805,0.46727716774923417,-1.9294323520484413
353.5000000000043,41.11490034727215,0.47188457128383987,-1.9667510408125453
354.60000000000434,41.2213996380409,0.47588413122472445,-2.005691102875533
355.7000000000043,41.328175555872505,0.4758376888559661,-2.046091346616428
356.80000000000433,41.43460678878695,0.47786202010644313,-2.0849293416030443
357.90000000000435,41.54021767199684,0.47606712314554034,-2.124191849342739
359.0000000000044,41.64733605786689,0.4730381842633047,-2.165721309159095
360.1000000000044,41.75440330945356,0.465708888454792,-2.20376652507881
361.2000000000044,41.86145419697692,0.45752400385242037,-2.244192174702283
362.30000000000445,41.9672277011019,0.44813522332231304,-2.283239401445749
363.4000000000044,42.07303625078289,0.4364281956351192,-2.319276069266309
364.50000000000443,42.179939198451756,0.4211859212017139,-2.356491517918946
365.60000000000446,42.28517616329226,0.40212654200351794,-2.3927593947554504
366.7000000000045,42.393835684068435,0.3830643767229696,-2.4260896147352864
367.8000000000045,42.50045602922933,0.35844125001709576,-2.459541221749143
368.9000000000045,42.60545114468447,0.33370742402618775,-2.4903455482483148
370.00000000000455,42.71377270030416,0.3073806646718982,-2.5215182199547455
371.10000000000457,42.82045503269149,0.27964998992029433,-2.546675954278598
372.2000000000046,42.92490279593085,0.25226787200467,-2.5713839760165187
373.30000000000456,43.03389623962043,0.2210318649307002,-2.593348166240649
374.4000000000046,43.13945301250033,0.1916617934659785,-2.6099213336893006
375.5000000000046,43.248171674946796,0.16188989538582138,-2.625159937632035
376.6000000000046,43.35542895309935,0.138647827444964,-2.638435372217816
377.70000000000465,43.46177522061776,0.11508448016295997,-2.6497554610099265
378.8000000000047,43.56925958500874,0.09575559454025018,-2.660052448287043
379.9000000000047,43.67568298866467,0.08145684285660215,-2.6675304253388434
381.00000000000466,43.78330707671975,0.06840676219628175,-2.675744137519729
382.1000000000047,43.89004627651703,0.05814363638688039,-2.6811649481673694
383.2000000000047,43.997107946645414,0.04894490061622009,-2.68917191749435
384.30000000000473,44.10475846597012,0.04409121326589327,-2.6917709627341835
385.40000000000475,44.21248601378378,0.038417703205592235,-2.6951204321182587
386.5000000000048,44.31896232240451,0.0338299810166752,-2.70055212013177
387.6000000000048,44.426249758067236,0.031044107555396966,-2.703915001489158
388.7000000000048,44.53223229145298,0.0274743421859939,-2.7093098885656746
389.80000000000484,44.64086702875378,0.026539894722952068,-2.7133212297934097
390.9000000000048,44.74754057420759,0.02365733130461095,-2.716619646881764
392.00000000000483,44.85659075964978,0.022714243970226006,-2.7207440673775896
393.10000000000485,44.961270304312926,0.021957255659420083,-2.7235771074237425
394.2000000000049,45.06979723153413,0.017344303969373115,-2.725810690490036
395.3000000000049,45.17663651166605,0.01926415244432314,-2.730550307711818
396.4000000000049,45.28330758977618,0.016762882070712637,-2.7351000512623056
397.50000000000495,45.391233184830966,0.015101447187214595,-2.7388557825617865
398.6000000000049,45.49784317029872,0.012315504943355982,-2.743234013496473
399.70000000000493,45.604712695179124,0.011799403054139457,-2.7470480124661507
400.80000000000496,45.7119868503516,0.010492484909707889,-2.7504416349827014
401.900000000005,45.81724291134241,0.008615068677899435,-2.7523904092599434
403.000000000005,45.92675178253068,0.005556255767667773,-2.755885206786619
404.100000000005,46.0338774894829,0.0029486433637959386,-2.7585550907628997
405.20000000000505,46.140147796124246,0.0023648411219885923,-2.761431250919749
406.30000000000507,46.24623478540552,0.0013860215960880828,-2.7656237968111284
407.4000000000051,46.35410461297625,-0.00011087042016891258,-2.7684156563642546
408.50000000000506,46.462705141755926,-0.0035924469380750057,-2.7712392481064114
409.6000000000051,46.56947842343201,-0.006379436518591103,-2.7751116465124417
410.7000000000051,46.67720624344652,-0.00435988767540002,-2.7793086194614034
411.8000000000051,46.78457591868325,-0.00657180742656141,-2.7820799961994718
412.90000000000515,46.89288664563533,-0.009994706663403102,-2.7856795245108903
414.0000000000052,47.0000337046037,-0.008224233297647432,-2.790098869038051
415.1000000000052,47.10674114934473,-0.008844685086868947,-2.7934367581433173
416.20000000000516,47.21436423017986,-0.007046935859932157,-2.796134009978082
417.3000000000052,47.32172442998759,-0.009339604733814344,-2.7978123239913937
418.4000000000052,47.42699585662908,-0.008267211036498662,-2.801268268156284
419.50000000000523,47.53507479569811,-0.009342681278667275,-2.8046288123917797
420.60000000000525,47.644350389708514,-0.007419383614233971,-2.808185535177828
421.7000000000053,47.75217357612438,-0.008262098479569963,-2.8102935106809355
422.8000000000053,47.859270503757564,-0.00956289096861232,-2.8145153263206786
423.9000000000053,47.96783941593206,-0.004833846645535628,-2.8171360010088886
425.00000000000534,48.075503801973845,-0.006883085452369958,-2.8199399348787617
426.1000000000053,48.18285513195607,-0.005738062174363984,-2.8227777914307457
427.20000000000533,48.29072859396789,-0.00641303323175077,-2.825556918639603
428.30000000000535,48.39861908617727,-0.004207666524411208,-2.829776454807229
429.4000000000054,48.506431202309905,-0.003021628749548283,-2.8311301392324104
430.5000000000054,48.61512888962165,0.001281358393117299,-2.8337201465541244
431.6000000000054,48.72373713017573,0.0008293787101819328,-2.836604626114352
432.70000000000545,48.831357533872826,0.0021661628595698035,-2.8400509344735565
433.8000000000054,48.938772971594794,0.004934948738421874,-2.8418381619849105
434.90000000000543,49.046233058985365,0.008672246110177528,-2.8446141270187058
436.00000000000546,49.15484209086232,0.01023278246357659,-2.8471837584409125
437.1000000000055,49.26328705330696,0.013028412519450083,-2.8488042322050635
438.2000000000055,49.37128906792713,0.015078477089899928,-2.8511823461810537
439.3000000000055,49.47951275878532,0.01640524687849551,-2.8538126030461335
440.40000000000555,49.587409769387214,0.01945444031474408,-2.858282254974957
441.50000000000557,49.69514754287997,0.021538813299790294,-2.860347473391546
442.6000000000056,49.80178102460615,0.02353682399013965,-2.8629372509053166
443.70000000000556,49.91173532096745,0.026592426778143524,-2.8656893927667944
444.8000000000056,50.01992515770592,0.028450182198053287,-2.8687752969385434
445.9000000000056,50.12821763143848,0.031664520133441204,-2.871381264469936
447.0000000000056,50.235567487010194,0.033247498351090254,-2.8730493270633706
448.10000000000565,50.342197651833764,0.035751659774232,-2.8767082827872152
449.2000000000057,50.45270673124031,0.03836062208337271,-2.8779595637049704
450.3000000000057,50.5607259314973,0.039431167919728116,-2.880665223499114
451.40000000000566,50.66877784958685,0.04304221682137396,-2.8815930624841073
452.5000000000057,50.776689950489875,0.04354224863339454,-2.884207387586961
453.6000000000057,50.88506469678707,0.046755159865257814,-2.8855457968706726
454.70000000000573,50.993580207217406,0.04786614482323792,-2.88808846849047
455.80000000000575,51.101468702749095,0.050849056392259326,-2.8909953610893084
456.9000000000058,51.20994016661643,0.049727455983144514,-2.893457938670848
458.0000000000058,51.31928261397339,0.05344877082876752,-2.8960813915861183
459.1000000000058,51.42598489591932,0.05529675763615101,-2.8973827485149917
460.20000000000584,51.53561785049421,0.05546259255474764,-2.900003612218878
461.3000000000058,51.644040556612424,0.05799042932320424,-2.900034058241209
462.40000000000583,51.753163116671416,0.0580109007008848,-2.90341620401838
463.50000000000585,51.8595148306573,0.0585892928543795,-2.9049800364715623
464.6000000000059,51.96994353204067,0.0585626752042189,-2.906303110732602
465.7000000000059,52.07937540108517,0.06051729957358348,-2.9076147934616197
466.8000000000059,52.18786925352645,0.060361002592686966,-2.9103307613967684
467.90000000000595,52.296701483020726,0.06286632529415132,-2.9122055143267827
469.0000000000059,52.40601974656,0.06417494909033568,-2.913564676401747
470.10000000000593,52.51430134507803,0.0641757959925771,-2.916127751052865
471.20000000000596,52.623738470279825,0.06583178888274899,-2.9162040057269936
472.300000000006,52.73247229805959,0.06619047696405111,-2.918811903040753
473.400000000006,52.840580047732615,0.06662369350928658,-2.9209093931861827
474.500000000006,52.94976079435269,0.06914651429804956,-2.9224330723513408
475.60000000000605,53.05829969440725,0.06952700465776987,-2.923034354375374
476.70000000000607,53.166969085456124,0.06946689659382255,-2.9251310801138075
477.8000000000061,53.27586143332798,0.0713335178679727,-2.9254409070015
478.90000000000606,53.38480541578002,0.07123954627332515,-2.9277016515519856
480.0000000000061,53.49335826312524,0.0742222720329066,-2.9301690446607314
481.1000000000061,53.60249317078268,0.0741557103370381,-2.9322182263422834
482.2000000000061,53.71106749447137,0.07544124181778325,-2.934956069478331
483.30000000000615,53.8195804512841,0.0758861642858155,-2.9362690230855106
484.4000000000062,53.9288618230339,0.07891425846759134,-2.936260909578371
485.5000000000062,54.037045225162295,0.07888423481681803,-2.937580028581434
486.60000000000616,54.146636650922176,0.08042508268747944,-2.937927177478179
487.7000000000062,54.25541447046167,0.08534002294122497,-2.9391739137838853
488.8000000000062,54.36102416315924,0.08781741457839083,-2.9410562240540368
489.90000000000623,54.47204835009612,0.09017274561935959,-2.943155891223957
491.00000000000625,54.58032611757266,0.09421244101065096,-2.94448292144674
492.1000000000063,54.690255561830426,0.09716819420716051,-2.947132676286893
493.2000000000063,54.798261711661475,0.09715926173883371,-2.94949928740556
494.3000000000063,54.90839155516249,0.10068551143488293,-2.9507552310459815
495.40000000000634,55.01555589639066,0.10539485593853133,-2.95075276162509
496.5000000000063,55.12555400579656,0.10650144076273736,-2.951118708769101
497.60000000000633,55.23529082929322,0.10902789569194829,-2.9533888032600446
498.70000000000636,55.34416994903911,0.11096989666093394,-2.9547038944534787
499.8000000000064,55.45282084771271,0.1133928513737764,-2.9560205615831907
500.9000000000064,55.56249494392336,0.11528989754614101,-2.9572814434277417
502.0000000000064,55.671201168362316,0.11578630712770847,-2.959970273342181
503.10000000000645,55.77996887781962,0.11632223442775436,-2.960564347639532
504.2000000000064,55.890179346212214,0.11759350762093644,-2.960278577493348
505.30000000000643,55.999371113806276,0.11794838563226565,-2.9616198304696564
506.40000000000646,56.10789561683551,0.12020537301495901,-2.964258333546609
507.5000000000065,56.21831047193499,0.11776880886097066,-2.9642518631367105
508.6000000000065,56.327314958872705,0.11962741372883576,-2.9655708752398873
509.7000000000065,56.436441349162095,0.11924616325918647,-2.965579527869888
510.80000000000655,56.54552050062619,0.1198407653160041,-2.9668996286070115
511.90000000000657,56.6556010138868,0.12094384039827985,-2.9682101949457325
513.0000000000066,56.76442062484905,0.1215157211818824,-2.972111275344451
514.1000000000065,56.87130057232818,0.1229783051590126,-2.9721649743387233
515.2000000000066,56.983634245309666,0.12392517233832975,-2.974797945258181
516.3000000000065,57.092920297010465,0.12347307522486627,-2.973480072310025
517.4000000000067,57.201402499386376,0.12538198456926858,-2.9748093654252337
518.5000000000066,57.31106654195316,0.12615426385566697,-2.9761181802082612
519.6000000000067,57.42058096835637,0.1266632093166438,-2.9774411460105403
520.7000000000066,57.52952273138684,0.12603901984290808,-2.9787496600366787
521.8000000000067,57.637952602047584,0.12694789517459146,-2.9787360586826743
522.9000000000067,57.748464288876,0.12612975633008672,-2.9800707111225933
524.0000000000067,57.85788953541375,0.12860140838486872,-2.9806277319837875
525.1000000000067,57.96769751789244,0.126791293970625,-2.984016825518266
526.2000000000068,58.07661179548387,0.12102317245238314,-2.9853358388737274
527.3000000000068,58.186318740681074,0.12380940619369757,-2.9867338151980602
528.4000000000068,58.29597924871585,0.12178739994711038,-2.986659696840668
529.5000000000068,58.40533539929454,0.12173405503759095,-2.986650274370053
530.6000000000068,58.514711204242744,0.12292891525558619,-2.9879086542085815
531.7000000000069,58.62419225823888,0.1209691300430228,-2.987868144475553
532.8000000000068,58.73320740398956,0.11873740693478566,-2.9894290624299975
533.9000000000069,58.841640890921205,0.11586290736671455,-2.991588089121051
535.0000000000068,58.95157623228456,0.11315308633123689,-2.991663947635413
536.100000000007,59.06089021521011,0.1116164679135506,-2.993300483290773
537.2000000000069,59.16992760903253,0.10914332659279659,-2.993899967429699
538.300000000007,59.27926431284905,0.10789846131502073,-2.995220171128765
539.4000000000069,59.3892784770305,0.10710677732244861,-2.996530563620995
540.5000000000069,59.49896780378539,0.10260020095114539,-2.996864254890659
541.600000000007,59.60896332286328,0.10167784522934761,-2.996199051495093
542.700000000007,59.718086983239814,0.10111389138986634,-2.9977780764851176
543.800000000007,59.82811180337463,0.09728176252252349,-3.001390652615947
544.900000000007,59.937017487397185,0.09547062849990473,-3.001484092979598
546.000000000007,60.046770933640396,0.09259171467266214,-3.0014820565114
547.1000000000071,60.15667950523806,0.08984297771307076,-3.004109761733778
548.2000000000071,60.26644305450275,0.09223709916681747,-3.0041109321951387
549.300000000007,60.375650154020065,0.08940920342428335,-3.0043954810637032
550.4000000000071,60.48588195465389,0.08356046831078023,-3.0064116905682012
551.500000000007,60.596344553199096,0.08554275238657483,-3.0077298660881366
552.6000000000072,60.704270386394704,0.0811064786391255,-3.009038864887697
553.7000000000071,60.814154525703515,0.08301053433161348,-3.0090506772198955
554.8000000000072,60.92389445890574,0.07741772168516031,-3.0090501215988192
555.9000000000071,61.03357070650653,0.07596697046820466,-3.0102759760856266
557.0000000000072,61.14288524121889,0.07711803289533081,-3.0113508220593945
558.1000000000072,61.25429302422342,0.07693627682077994,-3.0126700281528986
559.2000000000072,61.36325212888884,0.07393211217120621,-3.0126707295730286
560.3000000000072,61.4728073388772,0.06948245682346879,-3.012638842402745
561.4000000000073,61.582539164351196,0.0673508167721385,-3.014028840932986
562.5000000000073,61.69149209664627,0.06781564041241608,-3.0139901131007316
563.6000000000073,61.80130907994022,0.06589158617052394,-3.015319622105163
564.7000000000073,61.909833407148064,0.06284750294762174,-3.016957415499016
565.8000000000073,62.02105983612361,0.06361149073679577,-3.018128500358744
566.9000000000074,62.131028051963014,0.059571126310489726,-3.0187316273930755
568.0000000000074,62.23944675019949,0.05792094409130627,-3.0189298129352995
569.1000000000074,62.34730638931244,0.058038858636975915,-3.0215711019803004
570.2000000000073,62.45916900230928,0.057370522212175395,-3.0215667851253825
571.3000000000073,62.56898225426508,0.058709933547526315,-3.0202500489745145
572.4000000000074,62.67762107139397,0.054840553505990444,-3.020834477500821
573.5000000000074,62.78766602770068,0.05282717080867599,-3.0231005468123837
574.6000000000074,62.89792511577762,0.05098701459138459,-3.024080791733428
575.7000000000074,63.00660023205851,0.05059595214297574,-3.025793064663175
576.8000000000075,63.116153051800914,0.04973048810530438,-3.0245331765435504
577.9000000000075,63.2254837551531,0.05161744416684884,-3.0258433825116944
579.0000000000075,63.336132120097524,0.047342241319040676,-3.0271598032290985
580.1000000000075,63.44592144060837,0.045296453829414066,-3.028470632003562
581.2000000000075,63.555362349766675,0.044849351172371904,-3.0294596377516863
582.3000000000076,63.66546127458089,0.04473527438741747,-3.029732620546675
583.4000000000076,63.77405931867869,0.040999235848116385,-3.0297898610554315
584.5000000000076,63.88362479313568,0.040864334050462685,-3.031096129178861
585.6000000000076,63.99373237846622,0.040337522657215935,-3.031440126265906
586.7000000000077,64.10391116295132,0.03724258399671151,-3.031892229940201
587.8000000000077,64.21419166315418,0.03885550016321525,-3.032586237170504
588.9000000000076,64.32352552841498,0.0377422011058874,-3.0340722814229832
590.0000000000076,64.4338378782851,0.03519898974749639,-3.034079720884978
591.1000000000076,64.543640316014,0.03529209673611676,-3.0340736494136618
592.2000000000077,64.65474255253423,0.031207758334205412,-3.035497047690747
593.3000000000077,64.7640962696453,0.029110107437395453,-3.036806147732459
594.4000000000077,64.87473540565819,0.027294021088623995,-3.038031058048237
595.5000000000077,64.98353007353822,0.026765553667080808,-3.039349884403946
596.6000000000078,65.09328215865169,0.02717043632825375,-3.0393498080704227
597.7000000000078,65.20337729829618,0.027057653911504703,-3.0386894054242317
598.8000000000078,65.31357486473819,0.024401970971458863,-3.0400105650819986
599.9000000000078,65.42119433147674,0.024542101488614496,-3.040945684075661
601.0000000000078,65.53305234371199,0.023302876666904643,-3.041001183522847
602.1000000000079,65.64279953187621,0.02322678988858595,-3.042683911651798
603.2000000000079,65.75146522420083,0.02123065144069798,-3.0439572724831425
604.3000000000079,65.86171910708333,0.02086846404088805,-3.042970154294824
605.4000000000078,65.97218346088954,0.020073638161509946,-3.0426401963813055
606.5000000000078,66.08222816054526,0.020662965883505937,-3.044971561927516
607.6000000000079,66.19224674032758,0.021110981249959426,-3.045282578621727
608.7000000000079,66.3015173804565,0.01889159762256471,-3.0452965485227406
609.8000000000079,66.41180995447003,0.018306659620736923,-3.048505724035901
610.9000000000079,66.52083743931651,0.017969843679835756,-3.0479105428374234
612.000000000008,66.63057089707293,0.017207183415569458,-3.0479094745643995
613.100000000008,66.7405369771867,0.018412978058247584,-3.0485650208678505
614.200000000008,66.85115405529133,0.015559365739301827,-3.0492301795456602
615.300000000008,66.95833085380627,0.015537596522113152,-3.049562287149967
616.400000000008,67.07008553467098,0.014195889889319024,-3.0495498980061133
617.5000000000081,67.18042755025817,0.011424654231116202,-3.049550178978513
618.6000000000081,67.29047696967073,0.012409671091232179,-3.0508701146125854
619.7000000000081,67.3999491251355,0.011880178388870455,-3.051897116881513
620.8000000000081,67.51085890460341,0.011243144743789672,-3.0505489869773426
621.9000000000082,67.62091001745526,0.00946430853056171,-3.052985492933985
623.0000000000082,67.73123236904449,0.010519380297741118,-3.052190268011424
624.1000000000081,67.84053022891327,0.009486244581073382,-3.053509840762284
625.2000000000081,67.95086804939822,0.010340776265822471,-3.0548263217661216
626.3000000000081,68.06016865541059,0.009253624006613469,-3.054830051516986
627.4000000000082,68.17154093613335,0.007836428870086898,-3.0552639220327764
628.5000000000082,68.28178148687192,0.00971465323527438,-3.056479768424603
629.6000000000082,68.3926534818751,0.010788698873389138,-3.055170001349443
630.7000000000082,68.50207697800914,0.007899369248272912,-3.0567098694815438
631.8000000000083,68.6125856070094,0.008761875405838351,-3.0580715045707962
632.9000000000083,68.72222740120954,0.004479724735795172,-3.05911621933977
634.0000000000083,68.8331597170672,0.003704256353017507,-3.059835330404179
635.1000000000083,68.94383423425684,0.004458201857079451,-3.0605954559099
636.2000000000083,69.05306493432809,0.003717842668459745,-3.0604194613192677
637.3000000000084,69.16340279376314,0.006921417265123901,-3.0630605477247395
638.4000000000084,69.27344803166628,0.0034474082837022066,-3.0620232322093943
639.5000000000084,69.38312970567266,0.0024376017973112563,-3.0617387555407785
640.6000000000083,69.49460648006168,0.0023937893423318854,-3.0641464557093006
641.7000000000083,69.60398083989007,0.001995748389344812,-3.0640496471507594
642.8000000000084,69.71466994995961,0.00019129189833661658,-3.065369901144418
643.9000000000084,69.82432518591177,-0.0042509036145712414,-3.0653018072098677
645.0000000000084,69.93402281258996,-0.004313097650392846,-3.0640468873916866
646.1000000000084,70.04438237002523,-0.004918838011136739,-3.064049974001028
647.2000000000085,70.15490264614161,-0.004462642436961872,-3.0640499750980563
648.3000000000085,70.26437073385152,-0.0048006264956495515,-3.0653628288617476
649.4000000000085,70.3730692728804,-0.004458419268475962,-3.06539104695435
650.5000000000085,70.48451694708234,-0.00541206459805095,-3.066688900805191
651.6000000000085,70.59521417778814,-0.003689582529598945,-3.065370458682813
652.7000000000086,70.70614019514794,-0.00660643019572426,-3.066685815758001
653.8000000000086,70.8148348050203,-0.007982558335103807,-3.0679969330190753
654.9000000000086,70.92492288428373,-0.009921542090527938,-3.067881170199916
656.0000000000086,71.03518824373667,-0.008350190793616777,-3.067999894970494
657.1000000000087,71.14566832395099,-0.009358686705272817,-3.0679999177537827
658.2000000000087,71.25496696895246,-0.009716839538108688,-3.0676266439438313
659.3000000000086,71.36629158736542,-0.010953230744859134,-3.0676706743697877
660.4000000000086,71.4768335403913,-0.00994309613405868,-3.0693224504869825
661.5000000000086,71.58703404839646,-0.011927566604578645,-3.0693201260098872
662.6000000000087,71.69754973467062,-0.013194234015973846,-3.0706344673553043
663.7000000000087,71.80781568776347,-0.010934493580970074,-3.0719495003557578
664.8000000000087,71.91926537601248,-0.011105125196558555,-3.071950012149861
665.9000000000087,72.02926677699877,-0.011179874820725418,-3.0719191155819328
667.0000000000088,72.13856089581816,-0.010460044750463741,-3.070640716830649
668.1000000000088,72.24958011008934,-0.010673379609236748,-3.071971501413909
669.2000000000088,72.36000227423499,-0.010409712131864791,-3.071959945971047
670.3000000000088,72.4697739672335,-0.012725524142866693,-3.0719812602487115
671.4000000000088,72.58099160652756,-0.012148754454033774,-3.0732664510232537
672.5000000000089,72.69022114486847,-0.012490783731009932,-3.0732612959895143
673.6000000000089,72.80205111578842,-0.011521586686520965,-3.074255359060221
674.7000000000089,72.91311087203178,-0.013413063842179468,-3.0745882099045954
675.8000000000088,73.02313646964856,-0.013311437651604405,-3.0746123536008128
676.9000000000088,73.13364466687277,-0.014890364206606395,-3.075910165886844
678.0000000000089,73.2431119293275,-0.01922096686346913,-3.0759102334624204
679.1000000000089,73.35409589856242,-0.01697735530742473,-3.0772191827564157
680.2000000000089,73.46422621604934,-0.019419676391818567,-3.078543581768611
681.3000000000089,73.5735345821235,-0.01788993713713974,-3.077550282306045
682.400000000009,73.68369520601044,-0.017161733289140516,-3.078569148680659
683.500000000009,73.79438533769017,-0.019657848582228292,-3.0788698157832393
684.600000000009,73.905676684312,-0.02275153913534654,-3.0787367945745636
685.700000000009,74.01584464375256,-0.02230973028037092,-3.078467653075664
686.800000000009,74.12706552472565,-0.023066563062921,-3.0795794149498494
687.9000000000091,74.23771619343862,-0.022265664696128666,-3.079860158990366
689.0000000000091,74.34756799533292,-0.024793301128341855,-3.080849363065345
690.1000000000091,74.45851785274623,-0.02692112024464688,-3.0798598409789246
691.2000000000091,74.56867506083327,-0.02545888850837672,-3.0811848989443202
692.3000000000092,74.6797144300919,-0.02589628038775929,-3.0824982550537547
693.4000000000092,74.78966703123493,-0.02495976424880489,-3.0822081062985114
694.5000000000091,74.90036118611029,-0.027263835779508486,-3.0824998021542496
695.6000000000091,75.01105528359282,-0.02695320602446962,-3.0836008331691014
696.7000000000091,75.12151072253917,-0.02735194947899587,-3.0846642628980994
697.8000000000092,75.23223205849,-0.029146136281046044,-3.083809827030973
698.9000000000092,75.34282314305716,-0.03127653376577511,-3.085238335380513
700.0000000000092,75.45366304320133,-0.031399992364470275,-3.0846074405397808
701.1000000000092,75.56404950816598,-0.030784062672616415,-3.0856995698972396
702.2000000000093,75.67497903777014,-0.03214189674885819,-3.0864393023084666
703.3000000000093,75.78453368715336,-0.032844775102070976,-3.0890863244038456
704.4000000000093,75.89470553894745,-0.0342663168139553,-3.086536349147449
705.5000000000093,76.0055120944131,-0.03392952946214147,-3.0891101369619807
706.6000000000093,76.11549600594773,-0.034445929236983905,-3.0880139141300686
707.7000000000094,76.22609611152956,-0.035101761168863474,-3.087422313619626
708.8000000000094,76.33626270547508,-0.03530543877019498,-3.088750118489081
709.9000000000094,76.4458333526269,-0.03476035788100711,-3.0899030483496106
711.0000000000093,76.55816719580841,-0.037483826067049655,-3.0894155261659852
712.1000000000093,76.66744457417226,-0.03964445398206684,-3.0907300016354626
713.2000000000094,76.77788369150018,-0.03871008704753302,-3.0897399998842756
714.3000000000094,76.88800382037816,-0.038648994922333715,-3.0896720305214305
715.4000000000094,76.99815286354838,-0.04123288046763573,-3.0907399551526114
716.5000000000094,77.10786434744479,-0.04048954109972688,-3.0920499333782905
717.6000000000095,77.2191720976604,-0.04156223639164216,-3.0907235449013517
718.7000000000095,77.3294762508805,-0.04324482916779095,-3.0920377730778927
719.8000000000095,77.44021403226415,-0.04158891259889783,-3.092040054190746
720.9000000000095,77.55028386293945,-0.04487591405620174,-3.0933600819086533
722.0000000000095,77.66096025059535,-0.04582449423410763,-3.0946799811535035
723.1000000000096,77.7725537733397,-0.047275358061353565,-3.093352534791649
724.2000000000096,77.88257984120227,-0.046758412063231114,-3.0946800027496932
725.3000000000096,77.99297458289293,-0.05140551388734657,-3.094679986002209
726.4000000000096,78.10436486477224,-0.05228297127336268,-3.094673957371763
727.5000000000097,78.21452593703368,-0.05245000249622769,-3.0959836795840596
728.6000000000097,78.32480269459049,-0.056105608582156574,-3.0971038904443655
729.7000000000096,78.4357288141503,-0.0572869214486752,-3.094998954355294
730.8000000000096,78.54629052766185,-0.05798612894421394,-3.0963416943722333
731.9000000000096,78.6565050938836,-0.05718404418056087,-3.0960000380179564
733.0000000000097,78.76760152884047,-0.057332847675438614,-3.096000711714807
734.1000000000097,78.87841129077253,-0.05783932642375666,-3.097319794450255
735.2000000000097,78.99007681964359,-0.05944218729469444,-3.096673874647332
736.3000000000097,79.10015321745831,-0.060685165362539956,-3.0963297255575175
737.4000000000098,79.21163885468911,-0.05919872032479402,-3.0989677370624045
738.5000000000098,79.32196790593984,-0.05957148893348697,-3.0989699671089856
739.6000000000098,79.43208176994787,-0.06022687044516286,-3.097696874375962
740.7000000000098,79.54280100904663,-0.06367632719862823,-3.0976326206701703
741.8000000000098,79.65362498820004,-0.06307915581026866,-3.097640089955882
742.9000000000099,79.76399033151932,-0.06447122301541681,-3.097736395769677
744.0000000000099,79.87472034721118,-0.06259117904828823,-3.0979697610504884
745.0000000000099,79.97504177169378,-0.06207815073033967,-3.097969855999836