File: 01_Data/Rebond_Foam_Carpet_Pad/STA/N2/10K_min/Rebond_Foam_Carpet_Pad_STA_N2_10KData_221017_R3.csv
##Temp./Â°C,Time/min,DSC/(mW/mg),Mass loss/mg
51.0,10.77,0.027523551884800934,-0.01139131627402401
51.90000000000001,11.08554270800177,0.06940614047618388,-0.012271544662853184
52.800000000000026,11.303693118860037,0.10150617573095921,-0.010550382875835318
53.70000000000004,11.48418387264117,0.12408300254364169,-0.010867276974091844
54.60000000000005,11.645313080070114,0.1429871780814933,-0.011377654599317832
55.500000000000064,11.795213197966728,0.1601611432447494,-0.010509429266743808
56.40000000000008,11.935165373218679,0.17199199585815483,-0.011495649515484985
57.30000000000009,12.06958175442014,0.18224325350960635,-0.01129630368529222
58.2000000000001,12.19966701695042,0.19271284594561622,-0.011059972793775241
59.100000000000115,12.323229328013326,0.2000408088658323,-0.009684075095008904
60.00000000000013,12.44598579712655,0.20536434210707677,-0.011018260554196413
60.90000000000014,12.56599028737946,0.21291033397749692,-0.011294277383224749
61.80000000000015,12.681867274666326,0.2196950750647204,-0.009845754267685969
62.700000000000166,12.792490918701603,0.2222125576624654,-0.01075791780811608
63.60000000000018,12.910000000000023,0.22743415919279197,-0.009921133366366686
64.5000000000002,13.022505583822133,0.23174653905871234,-0.010277226334661993
65.4000000000002,13.13261974653915,0.23531513339027055,-0.011956177989878913
66.30000000000021,13.241855441887637,0.24156330820474925,-0.010921361809959507
67.20000000000023,13.349080094996765,0.24279748833803838,-0.011657895591683953
68.10000000000025,13.456243010147466,0.24611307192910736,-0.011970508377754818
69.00000000000026,13.56156813629171,0.24957643831040688,-0.011117638390777618
69.90000000000026,13.665554391177183,0.2537618983566301,-0.009738240121348607
70.80000000000028,13.770374890749832,0.2575751206200907,-0.01238630292720222
71.7000000000003,13.872965556900432,0.26082115864786926,-0.013737974655360308
72.6000000000003,13.974844137905501,0.2645564198076973,-0.012369604143679602
73.50000000000031,14.073694265507005,0.26673599566575246,-0.012252596035862595
74.40000000000033,14.176146607602165,0.2703591958194962,-0.012346615731051003
75.30000000000035,14.276240315195823,0.27269425878730835,-0.014913820941761635
76.20000000000036,14.377749304673937,0.2765314490281716,-0.013761091257980418
77.10000000000036,14.47404461885665,0.2776341294599991,-0.013331482754365798
78.00000000000038,14.57336402621453,0.2775668420073948,-0.012404090810170132
78.9000000000004,14.67307564537153,0.28107974639591593,-0.012424778534961156
79.80000000000041,14.769508983034797,0.28315412093621894,-0.013774775514349802
80.70000000000041,14.865911711439006,0.28643281113457897,-0.01372854452844452
81.60000000000043,14.962100647759954,0.28848871105147755,-0.01375834237831386
82.50000000000045,15.058557447605372,0.28828568576972724,-0.013718946492176531
83.40000000000046,15.1538974811073,0.2892659132602511,-0.013719647874530061
84.30000000000047,15.247954805163975,0.29067994749328085,-0.013695445719105859
85.20000000000049,15.34223398539809,0.2931279936295026,-0.013997663598158905
86.1000000000005,15.436962248312334,0.29314005331756077,-0.014888310186660814
87.00000000000051,15.52971426014013,0.2945859178951893,-0.015021227943765147
87.90000000000052,15.624410273922251,0.2953397386937794,-0.01514548093624235
88.80000000000054,15.71850369856109,0.29786938392556284,-0.016365731656473148
89.70000000000056,15.81091184835081,0.30098065320973066,-0.015966667168197723
90.60000000000056,15.902336408572978,0.3016891995911195,-0.014595325316047791
91.50000000000057,15.994158199188796,0.3049732410845728,-0.013773909632115888
92.40000000000059,16.08598855899586,0.30569030249080553,-0.01546794228623316
93.30000000000061,16.177161558121576,0.3062702685432078,-0.015231746144432456
94.20000000000061,16.26910381014903,0.3104372918654742,-0.015074494369562874
95.10000000000062,16.360000000000067,0.3122714531786237,-0.016038205241855064
96.00000000000064,16.450881165026424,0.31419648929961075,-0.01576944207398423
96.90000000000066,16.539469487965427,0.3176642800813678,-0.015032459077819027
97.80000000000067,16.630505163993444,0.3168521538085086,-0.01503876045766983
98.70000000000067,16.719073560637778,0.3180406859478797,-0.015039287253320932
99.60000000000069,16.81127245135898,0.32034123995991937,-0.01499880618949545
100.50000000000071,16.898997053456863,0.3234409557715402,-0.015049961729325378
101.40000000000072,16.989513629102767,0.3245224977988701,-0.01507691572260228
102.30000000000072,17.077883478109,0.32672487746025425,-0.01503984615686571
103.20000000000074,17.166953361783595,0.32861715787848433,-0.016476197631571488
104.10000000000076,17.25621095154931,0.32859310713328904,-0.01636616823165271
105.00000000000077,17.345496443089743,0.32928889022934205,-0.016359260937005793
105.90000000000077,17.434364335247576,0.3312139139997372,-0.01765980639387088
106.8000000000008,17.522959189086926,0.331083203969997,-0.016360167040551765
107.70000000000081,17.610197692014456,0.3325849433202255,-0.01504488611342758
108.60000000000082,17.70043334919262,0.3322868270360757,-0.016361562651396877
109.50000000000082,17.788362479406445,0.3330217033929348,-0.01632244868042365
110.40000000000084,17.878184587041417,0.33462151485228775,-0.016360150844584975
111.30000000000086,17.964584795482757,0.33645831240282054,-0.016608857293064716
112.20000000000087,18.05341416170491,0.3379431625085414,-0.01774666672336611
113.10000000000088,18.140370487396208,0.33907178457471454,-0.01635903087952295
114.0000000000009,18.229476990682656,0.3387925329238367,-0.017681046937374933
114.90000000000092,18.317804305163435,0.34035433897935397,-0.01635306753793131
115.80000000000092,18.40526376601341,0.34164438957473375,-0.01767127444619554
116.70000000000093,18.49346618375778,0.3422811269417746,-0.018060976164747
117.60000000000095,18.581434173351095,0.34461632632946937,-0.01871577024651172
118.50000000000097,18.669275992038408,0.345623834652971,-0.017683371281651095
119.40000000000097,18.756609981778247,0.3483680291647614,-0.018999412770304147
120.30000000000098,18.843649352360046,0.349388462977013,-0.018981818134750306
121.200000000001,18.930415234311344,0.35006798607853984,-0.01832629420626608
122.10000000000102,19.01979636401214,0.35027221149124677,-0.018990734130285514
123.00000000000102,19.10560289389727,0.3510460617190675,-0.017725359080076775
123.90000000000103,19.19306745536099,0.34570075197057515,-0.017682357495184764
124.80000000000105,19.2800948446272,0.34787687989842275,-0.01767909634883935
125.70000000000107,19.368041077655736,0.3477462681293685,-0.019031908036258205
126.60000000000107,19.45502857288738,0.3455477606558497,-0.017680038406830523
127.50000000000108,19.541259436382198,0.34396482530737205,-0.01768006591421134
128.4000000000011,19.628880487013028,0.3449003142283228,-0.018604296928416364
129.30000000000112,19.71604544461934,0.34506043248638774,-0.019990886399518626
130.20000000000113,19.802624016753953,0.3457305127076885,-0.01898226432921879
131.10000000000113,19.88895870036476,0.3460687266573611,-0.01898984691785799
132.00000000000114,19.975911939731684,0.3455371230442754,-0.018909290121313038
132.90000000000117,20.063947179660957,0.347237473864873,-0.019617114574585592
133.80000000000118,20.148881627455808,0.34828836103316985,-0.018999394721565643
134.70000000000118,20.236125005704217,0.3486204435098458,-0.020309485735885424
135.60000000000122,20.3225033241065,0.34890230898619823,-0.021047985863083873
136.50000000000122,20.409687274281364,0.34861493890863793,-0.020309890494277116
137.40000000000123,20.49639885928909,0.351501879332786,-0.02028934842453456
138.30000000000123,20.581261133250162,0.35132376537611787,-0.020299993277468342
139.20000000000124,20.667953526114637,0.3516068326396088,-0.021613281286473107
140.10000000000127,20.754024340408126,0.3517048373486249,-0.022620032099943455
141.00000000000128,20.840261147030255,0.35196519916757096,-0.02261998301019119
141.90000000000128,20.926922540226947,0.35395748632969004,-0.02262763011663438
142.80000000000132,21.012252477686424,0.3544956062919111,-0.021325874633737474
143.70000000000132,21.0998998149114,0.35722161581669587,-0.021299786340869264
144.60000000000133,21.184808022041846,0.35473868215924775,-0.02262844824757826
145.50000000000134,21.26958521928924,0.355432750805743,-0.022666752784322952
146.40000000000134,21.356029762437107,0.3575672478977703,-0.02360989965341176
147.30000000000138,21.441852022737535,0.35676344164661977,-0.02394783043122617
148.20000000000138,21.527308183960788,0.3575908771356806,-0.02393981486128638
149.1000000000014,21.613464770258613,0.36127301043327775,-0.025272565162675953
150.00000000000142,21.699321858363827,0.36015913355523155,-0.025249832852457743
150.90000000000143,21.784847989174356,0.361119629405794,-0.025308834602484342
151.80000000000143,21.87165273100234,0.3639897071671867,-0.02557992978404311
152.70000000000144,21.956290807840276,0.3642020639385547,-0.025250259581413026
153.60000000000144,22.041985038283745,0.36589272192558353,-0.025156791019516955
154.50000000000148,22.12646339868517,0.36811308833081857,-0.02393100864958253
155.40000000000148,22.21346428108748,0.3694733954008683,-0.025249241215639984
156.3000000000015,22.298844032230786,0.37004380514892765,-0.0255786880293023
157.20000000000152,22.38429255666287,0.37022194361050054,-0.02655592059573708
158.10000000000153,22.47009534550491,0.3717489512163673,-0.026570191026270784
159.00000000000153,22.553836449519093,0.3722524301720983,-0.0278864963503187
159.90000000000154,22.640001047146686,0.37136706784399165,-0.027880180002608057
160.80000000000155,22.72626831017353,0.3707331339507356,-0.02657171943677339
161.70000000000158,22.812519071344482,0.36871978342305967,-0.02656989404077592
162.6000000000016,22.896521459062956,0.36981147793598246,-0.027885970668894533
163.5000000000016,22.98382536510873,0.3699925048694429,-0.027884880939953227
164.40000000000163,23.067213967586095,0.3684675662746494,-0.027556989865188175
165.30000000000163,23.15327450256511,0.36812441872274015,-0.028879525015458096
166.20000000000164,23.23824801052551,0.36895640139175123,-0.029251181785788116
167.10000000000164,23.325221970141754,0.37071106507633955,-0.02986663150460167
168.00000000000165,23.40959615707563,0.3693247521749595,-0.029931915756157945
168.90000000000168,23.496005090130804,0.37237444883377946,-0.03117987667702682
169.8000000000017,23.58040453511433,0.3722402618032032,-0.031178033100696112
170.7000000000017,23.667134701445452,0.3711137080234324,-0.03377956590230413
171.60000000000173,23.753639766809975,0.3722083414020953,-0.03251761130127706
172.50000000000173,23.83768917637146,0.37332859232019944,-0.032507788867662146
173.40000000000174,23.923986731834034,0.3729959942321568,-0.033930233396666676
174.30000000000175,24.008378201550535,0.37666015801875924,-0.0339433161814382
175.20000000000175,24.09356171377855,0.37459473906217355,-0.03395102924853166
176.10000000000178,24.17982433026775,0.3751421122753231,-0.03525044505851094
177.0000000000018,24.265165470796454,0.3761914042819384,-0.03555260201653487
177.9000000000018,24.349797348230787,0.376976032378484,-0.03556986813013108
178.80000000000183,24.43582103651816,0.37736624856822354,-0.03559693308028633
179.70000000000184,24.52180756012562,0.3773621685492164,-0.0378704937639216
180.60000000000184,24.604650382187533,0.3806099161982533,-0.03852887599178034
181.50000000000185,24.692035711076635,0.380268966302331,-0.03852756900237919
182.40000000000185,24.778752735886947,0.38101888089158964,-0.03885839784163192
183.3000000000019,24.86265657704154,0.3820461257519594,-0.04018020078809492
184.2000000000019,24.94827323718092,0.38277465905927593,-0.04018017995150691
185.1000000000019,25.031689130371422,0.381322409840795,-0.04035462464474193
186.00000000000193,25.11971245559098,0.3811735697924494,-0.04346907406630507
186.90000000000194,25.205307878461472,0.38428747819569614,-0.04348002058299105
187.80000000000194,25.28906340838018,0.3837080385083899,-0.0436425415873809
188.70000000000195,25.37525505169549,0.3844592763861359,-0.04420373727856175
189.60000000000196,25.459744838567456,0.38404430595517813,-0.045789211443488576
190.500000000002,25.545153270479673,0.38549969821591706,-0.04764999200393172
191.400000000002,25.630914178495054,0.3863306850040605,-0.047649981999914104
192.300000000002,25.716152264500373,0.38603501389151657,-0.047649981929991814
193.20000000000203,25.802841309856298,0.3879378187167287,-0.04765870478508294
194.10000000000204,25.886137321743917,0.38808901530106527,-0.048970107725144096
195.00000000000205,25.972549051187347,0.3896116029375012,-0.048965709673675306
195.90000000000205,26.056243838065686,0.38986471454841337,-0.05153331164829167
196.80000000000206,26.14250612998627,0.3906794806152111,-0.051600082422325944
197.7000000000021,26.227193353239667,0.39053252440279196,-0.05158932486787293
198.6000000000021,26.311809788063947,0.39252848791218237,-0.054228265722475744
199.5000000000021,26.39723930203617,0.39243749013018125,-0.05423003684454386
200.40000000000214,26.482740664591464,0.39424646996407847,-0.05524682335247055
201.30000000000214,26.568315888660667,0.39637156753881764,-0.05687100200232109
202.20000000000215,26.653511204700596,0.3972021121382782,-0.05781825274050689
203.10000000000215,26.73889764548705,0.3993609615521623,-0.05819016955215428
204.00000000000216,26.82430133001773,0.39848387172779437,-0.05953058374871523
204.9000000000022,26.905607953107747,0.39924345712902154,-0.060834296315622094
205.8000000000022,26.993984258378983,0.40343912372648927,-0.0621506427056997
206.7000000000022,27.080093378886595,0.4035351097948928,-0.0634599053822158
207.60000000000224,27.164549211384607,0.4055040176458726,-0.06344970390583837
208.50000000000225,27.25000000000024,0.4062987679597946,-0.06609013127516361
209.40000000000225,27.33590436676824,0.409815480274525,-0.068697658919739
210.30000000000226,27.421481162249883,0.4116081576807395,-0.06982179932695809
211.20000000000226,27.50661541985942,0.41284447248461154,-0.07003713752469265
212.1000000000023,27.59108679885847,0.41516156237544355,-0.07134793441816978
213.0000000000023,27.676523609711,0.4142282545440715,-0.07333921747024208
213.9000000000023,27.76058074979544,0.4185872100765077,-0.07464997747214053
214.80000000000234,27.846245908180002,0.42063937248778466,-0.075965586965693
215.70000000000235,27.93368517070645,0.4233137069426471,-0.07728979759963428
216.60000000000235,28.019250837515372,0.42550111082305825,-0.07856881232097646
217.50000000000236,28.105075333853623,0.42540895010963836,-0.08059244283769251
218.40000000000236,28.190303392789126,0.428664935594965,-0.0842362693257468
219.3000000000024,28.274533290614148,0.4316124082159277,-0.08578350020653591
220.2000000000024,28.3597088544786,0.4319398062054123,-0.0858084831962187
221.1000000000024,28.445959704366366,0.43643240828175794,-0.08915286346262041
222.00000000000244,28.53216412759316,0.4399493685984595,-0.09130910507485046
222.90000000000245,28.61735662984288,0.4399042529983107,-0.09329620441869846
223.80000000000246,28.702148790355768,0.444841960070026,-0.09573693531341032
224.70000000000246,28.787675113417507,0.447586730094235,-0.09781221618655733
225.60000000000247,28.873705581204796,0.4481099918197154,-0.10047352914841179
226.5000000000025,28.958247057379545,0.4523665263790261,-0.10375110893748918
227.4000000000025,29.044156357361743,0.455110961464387,-0.10526267058124983
228.3000000000025,29.129640872241012,0.4580515643818957,-0.10869631593596507
229.20000000000255,29.21549916625841,0.46342928548636686,-0.11139613038571872
230.10000000000255,29.30077613264463,0.4662236498585933,-0.11408882480351412
231.00000000000256,29.38624406317721,0.47005619558349804,-0.11543709392499935
231.90000000000256,29.472500754054277,0.4748232102386542,-0.12147338307266553
232.80000000000257,29.55739131815979,0.47827266307309624,-0.12329697384830451
233.7000000000026,29.644471763822786,0.4834995472248623,-0.12640312117767882
234.6000000000026,29.728246146574723,0.4877073120770623,-0.12768613106806148
235.50000000000261,29.814143096666086,0.4918144816332416,-0.130563972080747
236.40000000000265,29.900983771346205,0.4977726599142437,-0.13486864247394914
237.30000000000265,29.98617699348978,0.49872974459922675,-0.13863575198993017
238.20000000000266,30.071687188170845,0.5043242641946188,-0.14149695897425296
239.10000000000267,30.158154439101054,0.5095147154460241,-0.14461813554455416
240.00000000000267,30.243008752154743,0.5141172300011997,-0.14915979156969916
240.9000000000027,30.327795139421802,0.5183791578370831,-0.1544937895390226
241.8000000000027,30.41424953576109,0.5243231247987872,-0.15755881750945466
242.70000000000272,30.499330711259542,0.5284830901279152,-0.1602979841847625
243.60000000000275,30.583344046219207,0.536385748449777,-0.16467368450878483
244.50000000000276,30.67159599680556,0.5430147115839774,-0.16797543251809843
245.40000000000276,30.757618980769323,0.5554556577630566,-0.17281127970101595
246.30000000000277,30.84160031519345,0.5666156817208658,-0.17716985437960853
247.20000000000277,30.928308232928632,0.5769034844295202,-0.18106102514733013
248.1000000000028,31.0136285505206,0.5908997232078997,-0.18478984427645884
249.0000000000028,31.099263859992345,0.5970410246002977,-0.18846512069708687
249.90000000000282,31.185948669694792,0.594892994744307,-0.1928031259588585
250.80000000000285,31.270611733129456,0.5882201872245167,-0.1975364877594612
251.70000000000286,31.356560571135144,0.5821636674390924,-0.20257663801492942
252.60000000000286,31.440429800536382,0.5774033868856103,-0.2074267827214693
253.50000000000287,31.527171955425743,0.5767763593509295,-0.211386176483356
254.40000000000288,31.61246513605447,0.5761139150809534,-0.2158029398441017
255.3000000000029,31.699172294960984,0.5765359980736766,-0.22053301505520784
256.2000000000029,31.784044577793026,0.5781539005922949,-0.22764362934194482
257.1000000000029,31.86972859206849,0.5803499424198331,-0.23260490904676123
258.00000000000296,31.95699286721762,0.583836339889303,-0.2384949867682189
258.90000000000293,32.041036104320305,0.5884951798080014,-0.24471752107558453
259.80000000000297,32.12708337150042,0.5912044297340797,-0.24957748528228718
260.700000000003,32.21380201686438,0.596903281106893,-0.2573887643466839
261.600000000003,32.298435273128725,0.601897303408831,-0.26199056976415624
262.500000000003,32.38468155212696,0.6102803502151412,-0.2691594205574881
263.40000000000305,32.47131545573935,0.61495519069132,-0.27573291243863807
264.300000000003,32.55486780884664,0.6208297146803989,-0.28343862092891836
265.20000000000306,32.64269184099768,0.6271608511224449,-0.2913791685471234
266.1000000000031,32.72475476506061,0.6325996580335329,-0.29558850725624275
267.00000000000307,32.81399586263151,0.6409506826882493,-0.30452349464445927
267.90000000000305,32.90035510200033,0.6463365033490205,-0.3121458165217499
268.8000000000031,32.98568884214228,0.653796327046115,-0.31992278761214177
269.7000000000031,33.071468862491265,0.6609945014838023,-0.3283036297902169
270.6000000000031,33.1575349508297,0.6720239114726112,-0.3363800954837046
271.5000000000031,33.243371801813126,0.6788022530960773,-0.34432889850651316
272.40000000000316,33.329484827466615,0.6903119586367097,-0.3542592030459537
273.30000000000314,33.41466138601489,0.7009367652841634,-0.3633243229732406
274.2000000000032,33.50130765130867,0.7148676169194011,-0.37232485491805845
275.1000000000032,33.587629380879115,0.7250563348395661,-0.38265276641484336
276.0000000000032,33.67319973981324,0.7363470575726934,-0.3947356326935574
276.9000000000032,33.75848460875105,0.7495013165406541,-0.4050523488300275
277.80000000000325,33.84501326111552,0.7620234711370282,-0.41596311251706286
278.70000000000323,33.931666758202944,0.7739741692090816,-0.42885266016727286
279.60000000000326,34.01607581502816,0.7876483609329116,-0.4398969360840925
280.5000000000033,34.10341364429414,0.799185617827262,-0.4518477141302757
281.4000000000033,34.18952572248409,0.8128084306992,-0.46334699549617175
282.30000000000325,34.27534300153785,0.8237658642853153,-0.4753097850532697
283.2000000000033,34.36202524745106,0.8365412859091339,-0.49045474850653514
284.1000000000033,34.446879002181646,0.8441856947693938,-0.5020855527084107
285.0000000000033,34.53416063327632,0.8543704971170334,-0.5162363283164626
285.90000000000333,34.6191565916219,0.8630510020475204,-0.5283115354835504
286.80000000000337,34.70544818799275,0.8715069730771363,-0.5432193444862317
287.70000000000334,34.7924589825699,0.8807039571285273,-0.5539786806355935
288.6000000000034,34.87847205234105,0.885380201580487,-0.5683476919783534
289.5000000000034,34.96447306052719,0.8887973347219612,-0.582083867061221
290.4000000000034,35.050335804551544,0.8927880529353838,-0.597089270878854
291.3000000000034,35.13614234389386,0.8903665844158282,-0.6118075509305503
292.20000000000346,35.222200508108436,0.8877651386369447,-0.6254984834040065
293.10000000000343,35.30828666143825,0.8828249704747652,-0.6409003000028979
294.00000000000347,35.39503146642463,0.870994920445443,-0.6542414820037417
294.9000000000035,35.48051195249163,0.854376531418287,-0.6695329194278679
295.8000000000035,35.5670421091301,0.8353497833163143,-0.6817443248199933
296.70000000000346,35.65246992740537,0.8125038134712093,-0.6965235012096884
297.6000000000035,35.739713804618795,0.7857683452199425,-0.7105546495357626
298.5000000000035,35.825790781000926,0.7603757107631159,-0.7239983148678157
299.4000000000035,35.911793363173445,0.7360660395425134,-0.7353346476094544
300.30000000000354,35.997975181387766,0.7127569572393653,-0.7466069014168881
301.20000000000357,36.08384957020542,0.6941498923035124,-0.7605993151534096
302.10000000000355,36.17010222424434,0.6771155773592026,-0.7715943714168105
303.0000000000036,36.25658587227621,0.6570936975168374,-0.7838848165718626
303.9000000000036,36.3423092797271,0.6428712033364663,-0.7946967178078865
304.8000000000036,36.42777207381301,0.6293367358743744,-0.8047925921850085
305.7000000000036,36.51391407681907,0.6151463212111098,-0.8144573452221153
306.60000000000366,36.600526076671166,0.6020866712537221,-0.8247405976460604
307.50000000000364,36.686865280810096,0.5907339609411704,-0.8351268002305061
308.4000000000037,36.772036724996404,0.579083453404831,-0.8437907429231957
309.30000000000365,36.85779013116342,0.5678685655850924,-0.8534662046069141
310.2000000000037,36.94555366867989,0.5553846378749006,-0.8636254150129972
311.1000000000037,37.03090120147447,0.5436478472261442,-0.8736054032849245
312.0000000000037,37.117439908985645,0.5332835990682521,-0.8825497256129489
312.90000000000373,37.20360830230216,0.5233572976904353,-0.8895377139104026
313.8000000000037,37.291046930311396,0.5108281434238022,-0.8973649271574922
314.70000000000374,37.376894696509936,0.5010373884668996,-0.906177300173066
315.6000000000038,37.462006286070086,0.490689482829203,-0.9138729297721442
316.50000000000375,37.54841426715744,0.4803360847125858,-0.9207878452947456
317.4000000000038,37.63605798392071,0.47166553773243614,-0.9294380037781287
318.3000000000038,37.721182360213454,0.45862668895035164,-0.9370897738044168
319.2000000000038,37.80810838544292,0.4525950652065076,-0.9454837403892493
320.10000000000383,37.89341465296557,0.4438284361229112,-0.9508222759006304
321.00000000000387,37.980779236839055,0.43309901831741104,-0.9583898471403862
321.90000000000384,38.06608508637076,0.4251032447577997,-0.9647918809050671
322.8000000000039,38.154190740325504,0.4181688377229198,-0.9734333624432967
323.70000000000385,38.2399039388111,0.41040381875576665,-0.9798090078491901
324.6000000000039,38.32546859099124,0.40240813511602236,-0.9863755584889398
325.5000000000039,38.41246377090369,0.3937971988568826,-0.9934620202234345
326.4000000000039,38.498841654636266,0.3884464033055611,-0.9999409154377727
327.30000000000393,38.58547881449611,0.3801647892974425,-1.0066613204649237
328.2000000000039,38.67159967161942,0.37582394771642996,-1.0130925883288642
329.10000000000394,38.75787692227916,0.3684982094503496,-1.019658194312826
330.000000000004,38.84510683141171,0.3620406886494527,-1.029019376044681
330.90000000000396,38.932070490526975,0.35738789037649243,-1.0358381695534455
331.800000000004,39.01827533970469,0.35306094350451434,-1.0422575472719555
332.700000000004,39.10538871629047,0.348398925663224,-1.0496750031645732
333.600000000004,39.19191664588455,0.34352166882125595,-1.0559056064243006
334.50000000000404,39.279111400800424,0.3386702625173239,-1.0620537262150322
335.40000000000407,39.366314170479164,0.3341293471249767,-1.0686800822144376
336.30000000000405,39.45261434594045,0.3333316444740518,-1.0759570216826781
337.2000000000041,39.53980678243776,0.327213986960639,-1.0835533159511876
338.10000000000406,39.62577024601139,0.3259997890926597,-1.0907020752295629
339.0000000000041,39.713379083390286,0.3208449322484839,-1.0976991491831973
339.9000000000041,39.799905058960576,0.3192890038542628,-1.1056267016812575
340.8000000000041,39.884315700704754,0.31794095404628203,-1.1111616242563827
341.70000000000414,39.97336458473271,0.3113003735453489,-1.1188523052726178
342.6000000000041,40.06036432830305,0.3104980710109924,-1.1248359534466355
343.50000000000415,40.14686786581178,0.3070741463438954,-1.131454593352068
344.4000000000042,40.234373081227005,0.3046711483396099,-1.138726590369827
345.30000000000416,40.31976338059547,0.3028644757292859,-1.1445778682584167
346.2000000000042,40.40729252015637,0.30115181261191615,-1.1525059278194396
347.10000000000423,40.49238405980213,0.3001004766829508,-1.15843061264474
348.0000000000042,40.58081278051058,0.29703540972910103,-1.1663260582938197
348.90000000000424,40.669259885804564,0.2971093920798517,-1.1723443402927867
349.8000000000043,40.75534303342791,0.2974841954372135,-1.1789750701064081
350.70000000000425,40.84266270222183,0.29752793477612205,-1.186093080637706
351.6000000000043,40.927590140498815,0.2969621206297247,-1.1931442226592384
352.50000000000426,41.01638218645056,0.29785872109406925,-1.1998192566257617
353.4000000000043,41.10367678369419,0.29907082680400965,-1.2063416468576311
354.30000000000433,41.18789675594563,0.30070472192311387,-1.2157756046358497
355.2000000000043,41.27778548414031,0.3022967663052816,-1.2235789043994285
356.10000000000434,41.364326635041124,0.303968282431306,-1.2299262372090491
357.0000000000043,41.45080461667267,0.30658163404540767,-1.2366207898802979
357.90000000000435,41.53889555916794,0.30693865165311907,-1.246183736690206
358.8000000000044,41.625922976025905,0.31170537447089247,-1.2543817904732304
359.70000000000437,41.71373803945043,0.31291727121078716,-1.2652672790500228
360.6000000000044,41.801060947974044,0.31671329774877616,-1.2731440017967524
361.50000000000443,41.88765645689466,0.3223588488878219,-1.2822638047644208
362.4000000000044,41.97509398526733,0.322782355479094,-1.2907376517432314
363.30000000000445,42.06177071966682,0.3274994349019209,-1.2996916068899127
364.2000000000045,42.14846848567244,0.32995213114351407,-1.3105175913820255
365.10000000000446,42.23696891182664,0.3340033489132236,-1.3219259835623514
366.0000000000045,42.32050065623506,0.33829386956694807,-1.3328249050154635
366.90000000000447,42.410394490001465,0.34302608234513576,-1.3448691038166891
367.8000000000045,42.49701537954992,0.3505605148002072,-1.3579160840188136
368.70000000000454,42.58448473817071,0.35375631585315714,-1.3714337074331708
369.6000000000045,42.67227577678366,0.36137771737370916,-1.3860031979660952
370.50000000000455,42.75933004239727,0.36571441995489745,-1.3988350206993116
371.4000000000045,42.84624765373462,0.3727434902518478,-1.413965851469837
372.30000000000456,42.9340195989615,0.38188142176708284,-1.4290222449021406
373.2000000000046,43.02156066761851,0.3858746030836425,-1.4471045819707924
374.10000000000457,43.10792508050419,0.39410360775738085,-1.4627639810386954
375.0000000000046,43.19503402523882,0.4021177012992305,-1.4796291779503106
375.90000000000464,43.28293840963956,0.4110091758947281,-1.4977891808480348
376.8000000000046,43.370842703766534,0.419902215350913,-1.5163914944538948
377.70000000000465,43.45775781842786,0.42750742473477177,-1.5341546946733966
378.6000000000047,43.54590331804478,0.4376168832753706,-1.5540664194904177
379.50000000000466,43.63294760328758,0.44644609924007395,-1.577353028367646
380.4000000000047,43.72058435477949,0.4569353832661048,-1.5998116349798934
381.3000000000047,43.80860415060275,0.4658629181483668,-1.6254387913739996
382.2000000000047,43.89587496555335,0.47646823205516653,-1.6509542538447488
383.10000000000474,43.98393816351373,0.4889000255381572,-1.675888210354251
384.0000000000047,44.07047768026411,0.4969483286693671,-1.7040992908087116
384.90000000000475,44.15838600395696,0.5059740399141811,-1.7307821977892788
385.80000000000473,44.24601116267377,0.5186891099807269,-1.7586369411561846
386.70000000000476,44.33246901995846,0.5307593703236786,-1.7872063204347302
387.6000000000048,44.42178423758101,0.540209522046632,-1.8184984793073626
388.5000000000048,44.50594336476186,0.549768381028415,-1.8494537760093186
389.4000000000048,44.5967026889163,0.5597107762192016,-1.8843400169084825
390.30000000000484,44.684108338624036,0.5684253526980378,-1.919626862480285
391.2000000000048,44.77263994939427,0.5773891779932849,-1.9547699883930378
392.10000000000485,44.860609348775675,0.585486773033663,-1.9912963070534782
393.0000000000049,44.9481704900927,0.5945950072704039,-2.0286597233939627
393.90000000000487,45.03491683819526,0.6009144262469412,-2.066911239934224
394.8000000000049,45.12359717353115,0.6079938283693394,-2.106105874618919
395.7000000000049,45.21159154462559,0.611702744422559,-2.144613672824595
396.6000000000049,45.298752156156894,0.6153516430461421,-2.183460524778065
397.50000000000495,45.384934586434156,0.6163414177614059,-2.222008762055986
398.4000000000049,45.47351808410593,0.6148627506077006,-2.263262395374228
399.30000000000496,45.5604811856056,0.6104873063034504,-2.301048155038546
400.20000000000493,45.64924335998494,0.6046091343127423,-2.340211434294969
401.10000000000497,45.736970175029086,0.5984452384726788,-2.3792796460518453
402.000000000005,45.82398165093549,0.5907826264335042,-2.416680449358678
402.900000000005,45.913446066745855,0.5791919573595682,-2.4556820284893877
403.800000000005,45.99810819926183,0.569548192195506,-2.4932601074008476
404.70000000000505,46.08790194357846,0.554516990145712,-2.5315123686041594
405.600000000005,46.175864257845795,0.5431528925818611,-2.5651914212814217
406.50000000000506,46.26355438872094,0.5269597149942926,-2.601309099879424
407.4000000000051,46.35172253417122,0.5113189944255465,-2.6366802309658603
408.30000000000507,46.43810287713562,0.49550332114635487,-2.6696232087120446
409.2000000000051,46.52800082836468,0.4800107776319455,-2.704129453918598
410.1000000000051,46.61544016192395,0.4640014273844908,-2.733760176170846
411.0000000000051,46.70257292893728,0.4470671308479838,-2.7646493856841907
411.90000000000515,46.791254151477816,0.4262779905005204,-2.795893894438179
412.8000000000051,46.87854478126822,0.4098834467111651,-2.8243583357404063
413.70000000000516,46.966637731164504,0.39469724536182493,-2.8524398828212485
414.60000000000514,47.054489889717445,0.37523035538232996,-2.8789848548590427
415.5000000000052,47.14162249663895,0.36131730546020746,-2.903746674857455
416.4000000000052,47.22899549069462,0.3418136504723974,-2.927493888042757
417.3000000000052,47.31733748398758,0.3287070447696768,-2.951932207331995
418.2000000000052,47.40568164268096,0.30937867937087526,-2.9735796745867047
419.10000000000525,47.492925560410164,0.29565371354781866,-2.99457055949841
420.00000000000523,47.58066444323996,0.27836728385182397,-3.0143677141197567
420.90000000000526,47.668997513416095,0.26581822931937177,-3.033386165378338
421.8000000000053,47.75602089795877,0.25194850374537126,-3.0516889772031845
422.7000000000053,47.844396111633245,0.23725793256334698,-3.0686311787863234
423.6000000000053,47.93188853171755,0.22649365634915158,-3.0858876560580004
424.5000000000053,48.020414794675986,0.2122607475311008,-3.1018965466191544
425.4000000000053,48.107527953074026,0.2016772897846657,-3.117320673481193
426.30000000000535,48.19536568771502,0.18838930070694898,-3.128606518126891
427.20000000000533,48.28382342733986,0.17746970537057877,-3.1408721479726838
428.10000000000537,48.37144920739615,0.16487107173407,-3.1538698968726604
429.00000000000534,48.45916898956766,0.1572225368616042,-3.166173242595211
429.9000000000054,48.547022092677835,0.1476352165112319,-3.178943350629036
430.8000000000054,48.635186019486135,0.13667430302294098,-3.1892627052737472
431.7000000000054,48.72313372198702,0.1271798891860324,-3.1977103848024857
432.6000000000054,48.812138022990624,0.11942911762161079,-3.2062974262027186
433.50000000000546,48.89980070211786,0.11200417815964991,-3.214210801604641
434.40000000000543,48.98766818018898,0.10524379565678588,-3.2217481118577505
435.30000000000547,49.075806980946474,0.09771988236306539,-3.2300989502698254
436.2000000000055,49.16367278829443,0.09284287902448835,-3.2354109989388515
437.1000000000055,49.25201834134527,0.0878066565091134,-3.242984162391596
438.0000000000055,49.33959859774215,0.08212743232251274,-3.2480218806503123
438.9000000000055,49.427200464149706,0.07784837982288212,-3.2512870875038713
439.8000000000055,49.51577051181849,0.07430812212527937,-3.256346895747023
440.70000000000556,49.6035890584345,0.0684151013039026,-3.2603366997205367
441.60000000000554,49.69209647257587,0.0674164051403936,-3.264852397327284
442.50000000000557,49.78009927880401,0.06474324348921895,-3.2689025712391664
443.40000000000555,49.8680260282405,0.060516932357673636,-3.272985375684358
444.3000000000056,49.956035507599566,0.0601763660198929,-3.2788650148590013
445.2000000000056,50.04438703547991,0.056185665011120156,-3.2841415152647846
446.1000000000056,50.1324489897794,0.055252200228287696,-3.2887695815161635
447.0000000000056,50.22010221325242,0.05190498368345864,-3.2910906471496655
447.90000000000566,50.308073434644314,0.05061010585927822,-3.2947078069025793
448.80000000000564,50.3970547619025,0.04758551420608259,-3.2976278175082228
449.7000000000057,50.48472174184649,0.0478410281585786,-3.3010455903755354
450.6000000000057,50.57389558131505,0.04862646329291698,-3.3067611080330455
451.5000000000057,50.66222018451157,0.044850470931102504,-3.3102145160208916
452.4000000000057,50.749173879223534,0.043932914965847336,-3.313925590923603
453.3000000000057,50.83854969830329,0.044493926015293284,-3.318247058466733
454.20000000000573,50.927468984682775,0.04271236028897718,-3.322431928856455
455.10000000000576,51.01521124090026,0.04216971062541092,-3.327328467425667
456.00000000000574,51.1038890475069,0.04099710589663447,-3.3326407225206163
456.9000000000058,51.19231260689905,0.039060353415350246,-3.3352206835386706
457.80000000000575,51.28010407269943,0.03773857749432419,-3.3379588942803173
458.7000000000058,51.36990592488453,0.03778320356512316,-3.342236972330146
459.6000000000058,51.45737380642108,0.03717509079763104,-3.3447985550027153
460.5000000000058,51.54515147083072,0.03656951964578481,-3.3483803233327496
461.40000000000583,51.63429559485944,0.03640878305210099,-3.354197065107558
462.30000000000587,51.723129241424004,0.035864990917541306,-3.357917330099156
463.20000000000584,51.811153523733125,0.03631985341191646,-3.3623916170198482
464.1000000000059,51.89908642377203,0.035580248837706274,-3.3654361940451727
465.0000000000059,51.98767045348296,0.03428096100132427,-3.368893023757008
465.9000000000059,52.07586425157176,0.034883875938678255,-3.372510158118793
466.8000000000059,52.16409066486161,0.03327215569460623,-3.37566583831601
467.7000000000059,52.25315189299991,0.03378860371195441,-3.38019203300375
468.60000000000593,52.342170504872904,0.033616064814728785,-3.383337701159843
469.50000000000597,52.43000000000063,0.030558971997700746,-3.3872499187879623
470.40000000000595,52.5182277588743,0.028997298972241903,-3.3920445737472664
471.300000000006,52.606809077524396,0.028869009188086048,-3.3957513788626943
472.20000000000596,52.69558262482758,0.027592699643106622,-3.3972683395496235
473.100000000006,52.78414437190607,0.026386127156806716,-3.4011402929816685
474.000000000006,52.87266501179921,0.02558808645186289,-3.4036647779627645
474.900000000006,52.961832424288424,0.025705996621597227,-3.407315095442732
475.80000000000604,53.048926866922685,0.023356690852385675,-3.411089375853929
476.70000000000607,53.13780017514113,0.02024015639083976,-3.414190138341441
477.60000000000605,53.22661858112484,0.017952711056227533,-3.418750619490762
478.5000000000061,53.3144515600993,0.01690699172577187,-3.42228509801451
479.4000000000061,53.40325764573266,0.01295706716167666,-3.424108771765263
480.3000000000061,53.49223852649586,0.013471547207794476,-3.426312801763828
481.2000000000061,53.58061669675094,0.010745126129046823,-3.4288589847747026
482.1000000000061,53.66809677758239,0.010107829338354524,-3.43151486935373
483.00000000000614,53.75748556839292,0.00541059597009419,-3.4315472405629586
483.9000000000062,53.846309614501685,0.005060711561641007,-3.4328299793799832
484.80000000000615,53.934321329984485,0.0024868617563631457,-3.4368927537794587
485.7000000000062,54.02364816707784,-0.0002620978851011202,-3.440726482149216
486.60000000000616,54.11183619012197,-0.002543164587974156,-3.441335728356611
487.5000000000062,54.200209030421675,-0.0035214751032406344,-3.4434560003273647
488.40000000000623,54.286679175793196,-0.00624857749284935,-3.443446764547293
489.3000000000062,54.37766846102709,-0.004842990698982252,-3.444769172013574
490.20000000000624,54.465487755577705,-0.008287764495126193,-3.4447720203115613
491.1000000000063,54.55442336243922,-0.010411117617139198,-3.447403456874393
492.00000000000625,54.64332797976458,-0.013420950802072673,-3.450061027779371
492.9000000000063,54.731641687047535,-0.013786066020594012,-3.4500448677191335
493.8000000000063,54.820823132985815,-0.011357782069071953,-3.4513545463608217
494.7000000000063,54.909373367646644,-0.013376739590476638,-3.4526793912157876
495.60000000000633,54.99579821853849,-0.013009471268919603,-3.4528629948351766
496.5000000000063,55.0859287679923,-0.014429929115188755,-3.4544137819192207
497.40000000000634,55.175938520070886,-0.015330311664084717,-3.4556286901911095
498.3000000000064,55.26242968954002,-0.01935836945066427,-3.455665489584549
499.20000000000636,55.35346819259562,-0.019422564337677306,-3.459671161350824
500.1000000000064,55.438434057237565,-0.016605421262942344,-3.46091035544581
501.00000000000637,55.53090709454117,-0.017767159196881877,-3.4609489947914773
501.9000000000064,55.6177292528247,-0.017188715585849668,-3.461690725491672
502.80000000000643,55.708394696176995,-0.019117262570883142,-3.4649676008522605
503.7000000000064,55.79709336436395,-0.015927898860512046,-3.466290116754765
504.60000000000645,55.884937446082446,-0.018267914878847102,-3.46628994402348
505.5000000000065,55.97437829581628,-0.017914586226009332,-3.4662865930116844
506.40000000000646,56.06265210219149,-0.020508699743005787,-3.469035072670176
507.3000000000065,56.15107262252832,-0.019846688589130856,-3.470350477673784
508.2000000000065,56.24020797371041,-0.019677179065164918,-3.4716888405731394
509.1000000000065,56.32904104578486,-0.0203641720170869,-3.472330212142202
510.00000000000654,56.41771415140642,-0.02121347942523466,-3.4729283283688837
510.9000000000065,56.50642809493891,-0.02060163167103246,-3.474309925967195
511.80000000000655,56.59558788119808,-0.021216575191787435,-3.473692392057133
512.7000000000066,56.68303845981658,-0.023125137045344246,-3.4741243413291616
513.6000000000065,56.77191974219136,-0.024141046614828077,-3.476287580180448
514.5000000000066,56.86180936275676,-0.024766715291132724,-3.4749553188772726
515.4000000000066,56.950827341667726,-0.02588814858505345,-3.4769384021447047
516.3000000000065,57.0396947286315,-0.026565043721143544,-3.4782508602987687
517.2000000000066,57.128563117955856,-0.025236957180023722,-3.4796328646193873
518.1000000000066,57.21763052618447,-0.026804053719824417,-3.479623432936837
519.0000000000066,57.30772124011668,-0.027949728573484378,-3.4808902230847054
519.9000000000067,57.39637981309759,-0.027553829332119806,-3.480890041020378
520.8000000000067,57.48432399857228,-0.029883842257611204,-3.480887221744539
521.7000000000066,57.57391927026177,-0.029991725626949295,-3.482210460857275
522.6000000000067,57.662888613064155,-0.03227604515586224,-3.4822176846868187
523.5000000000067,57.751130133478505,-0.031643071664124556,-3.484507845210355
524.4000000000067,57.840870529377035,-0.030826377098255253,-3.4858144450427138
525.3000000000068,57.930436791218106,-0.03315923240439428,-3.487162271319057
526.2000000000068,58.01689691017886,-0.03196160057072145,-3.4884788998924754
527.1000000000067,58.10823062255326,-0.03103407139698039,-3.489841292483561
528.0000000000068,58.19673157095145,-0.03362674350573852,-3.488478406602802
528.9000000000068,58.285124473701195,-0.03342602877812961,-3.4897878212663462
529.8000000000068,58.37521345420473,-0.03519416237130968,-3.4904337949450923
530.7000000000069,58.46383765070748,-0.037410239286434444,-3.491760047858583
531.6000000000068,58.55399008828818,-0.03641586396001861,-3.4914583868883287
532.5000000000068,58.64316450845606,-0.03767364821733504,-3.4924212680369155
533.4000000000069,58.730885587115964,-0.03661285569978057,-3.493740090256729
534.3000000000069,58.82103936318045,-0.038893873072598006,-3.4937445276682038
535.2000000000069,58.91071927443682,-0.03990669073444447,-3.4924222580299658
536.100000000007,59.0005825135335,-0.03764166402573871,-3.495439409160582
537.0000000000069,59.0895012074254,-0.03836742700366241,-3.497691241564987
537.9000000000069,59.179232192398494,-0.038423467268252076,-3.498603964101209
538.800000000007,59.26739814055532,-0.040487028554854365,-3.499009922024413
539.7000000000069,59.35714236344828,-0.040277144614386085,-3.4990117581380793
540.600000000007,59.44627733543064,-0.03940853652287196,-3.500338480628407
541.500000000007,59.53554297336697,-0.041091794735931386,-3.499669899962612
542.4000000000069,59.62526973633116,-0.03983942398266094,-3.5009901252868807
543.300000000007,59.713639075239094,-0.04005343654679916,-3.502300463484479
544.200000000007,59.80281144086655,-0.039663308136786035,-3.50081914555958
545.100000000007,59.893183042906045,-0.04111208201901795,-3.5018529941487104
546.000000000007,59.982796914294454,-0.037321918584206304,-3.5043601910265463
546.900000000007,60.071003695691886,-0.035718678091069433,-3.505710148691554
547.800000000007,60.16144394984405,-0.03789969362192552,-3.507029995028771
548.7000000000071,60.250199525483396,-0.03937292840572493,-3.5070221097148675
549.6000000000071,60.33905257978569,-0.03826554527058651,-3.508342244273448
550.500000000007,60.428213013136784,-0.04034614619117166,-3.508911693455484
551.4000000000071,60.517907958530415,-0.03656609260838012,-3.509329364632324
552.3000000000071,60.60698150986092,-0.037801680819511574,-3.508010066073855
553.2000000000071,60.69684245553215,-0.03859294092882076,-3.5080178240012128
554.1000000000072,60.786184169047786,-0.03747745943230241,-3.5083532417956715
555.0000000000072,60.87521596042173,-0.03852079787191298,-3.5096542688016994
555.9000000000071,60.96498932765135,-0.04024477436898971,-3.5119598329116855
556.8000000000072,61.05356221218793,-0.04203193922835463,-3.5119600016367296
557.7000000000072,61.14313345671303,-0.04373948209491346,-3.5131482057909116
558.6000000000072,61.2322499007633,-0.04516067884838948,-3.5126171645645705
559.5000000000073,61.32165860636082,-0.04707260472882702,-3.5127358368331416
560.4000000000073,61.41124901938921,-0.047162608274605056,-3.5139400625642736
561.3000000000072,61.50019730759993,-0.05054201816614773,-3.514723472724828
562.2000000000073,61.5908314044499,-0.05152949184052541,-3.514643396127419
563.1000000000073,61.6782867646256,-0.05441618501953249,-3.5141075334985667
564.0000000000073,61.76786382621295,-0.054065744861317266,-3.514318398649956
564.9000000000073,61.85719659382883,-0.0559029069120171,-3.5142592575170006
565.8000000000073,61.94662649358977,-0.05535429382016438,-3.5155798724446505
566.7000000000073,62.03579328022174,-0.05639002325034437,-3.5162795072859128
567.6000000000073,62.12489046477231,-0.0568531836986661,-3.5178665469280985
568.5000000000074,62.21438461163114,-0.05817731094154799,-3.52061849806181
569.4000000000074,62.30341058335014,-0.05826700404963525,-3.520520082936243
570.3000000000073,62.39371966876477,-0.05892482538462701,-3.5206247986459855
571.2000000000074,62.48246150879798,-0.05927601279872324,-3.5218394610602117
572.1000000000074,62.57124722828002,-0.05997730107261823,-3.521842749919114
573.0000000000074,62.66018710383303,-0.06036481010205641,-3.5231592056977066
573.9000000000075,62.750206077326105,-0.06290791618360142,-3.5216759001790705
574.8000000000075,62.839550209090774,-0.06349297412157334,-3.520259867475844
575.7000000000074,62.92867330042826,-0.06251388523021201,-3.5203271355204557
576.6000000000074,63.017830630252455,-0.06164914200286831,-3.521578537480988
577.5000000000075,63.107918811863776,-0.06174079566405366,-3.526168413452964
578.4000000000075,63.196943696241625,-0.05617148643650477,-3.5264495740748942
579.3000000000075,63.28595716279209,-0.05296829328834318,-3.5245898199113497
580.2000000000075,63.37516929096306,-0.05333401582689484,-3.524563188262305
581.1000000000075,63.464632763431965,-0.05155210450115805,-3.5245881843905638
582.0000000000075,63.55363803030426,-0.053696390921399995,-3.5231881697394845
582.9000000000076,63.64329258380119,-0.05349217382433202,-3.5246302004661434
583.8000000000076,63.7327709999698,-0.05351633453621407,-3.5283010406753887
584.7000000000075,63.82275875559779,-0.0516881919601056,-3.5285400536493787
585.6000000000076,63.91160289976435,-0.05135003267779659,-3.5282103389572725
586.5000000000076,64.00028801797637,-0.04925151347000817,-3.5285654261831945
587.4000000000076,64.089562732934,-0.046577769183250906,-3.529530044231845
588.3000000000077,64.17934339581855,-0.046716132029849866,-3.5308439900379582
589.2000000000077,64.26933910391554,-0.04778790999649196,-3.530850919049928
590.1000000000076,64.3585964116231,-0.04547813737753703,-3.530882818680211
591.0000000000077,64.44829029498898,-0.04346305184148469,-3.5282092644728826
591.9000000000077,64.53715323794262,-0.04193875494888938,-3.528352890480176
592.8000000000077,64.62629912460257,-0.04352757764559362,-3.5308363891180505
593.7000000000077,64.71563850143494,-0.040276978473642644,-3.5319338470059027
594.6000000000078,64.80531597692556,-0.040375107793577725,-3.5334750134776103
595.5000000000077,64.89457799347839,-0.036594237240754335,-3.534272965641329
596.0000000000077,64.94488376797919,-0.03808400710897941,-3.533789577213507