File: 01_Data/Rebond_Foam_Carpet_Pad/STA/N2/10K_min/Rebond_Foam_Carpet_Pad_STA_N2_10KData_221017_R2.csv
##Temp./Â°C,Time/min,DSC/(mW/mg),Mass loss/mg
51.0,10.812600397215954,0.057862564821941076,0.05040151694872197
51.90000000000001,11.113100041909739,0.08797249755095904,0.049774143505109336
52.800000000000026,11.322389418060613,0.11021840283558726,0.0479563740799378
53.70000000000004,11.500260369197475,0.13152896118525859,0.049164641369540796
54.60000000000005,11.662938676436776,0.1483492151484216,0.04866133366092562
55.500000000000064,11.811039876869565,0.16169338071646666,0.04893699734693335
56.40000000000008,11.951763281443041,0.17134162604032022,0.049737341897842846
57.30000000000009,12.085274376633835,0.18406523087473037,0.04813443045110777
58.2000000000001,12.21321189625115,0.19218508468530038,0.04987039444812069
59.100000000000115,12.334432777790777,0.19890301617813422,0.04889771224665829
60.00000000000013,12.458744212313077,0.2042598395940809,0.05014146711429568
60.90000000000014,12.576603899174417,0.20833994806584122,0.049228517523239645
61.80000000000015,12.695162288549852,0.21549910225660618,0.04919282169601136
62.700000000000166,12.807590634783818,0.21893464727811685,0.050594386751239284
63.60000000000018,12.921277813127494,0.22371271112908198,0.050553710100993854
64.5000000000002,13.032831748559543,0.22867768329818228,0.048888073359935724
65.4000000000002,13.142515585329114,0.23336556907525585,0.04989729319925473
66.30000000000021,13.249017171389223,0.23753660446754332,0.050275618992386306
67.20000000000023,13.36015816112966,0.2407326485518464,0.05263013429162999
68.10000000000025,13.463568294855865,0.24403982858125173,0.05107382970621188
69.00000000000026,13.570899845250834,0.24926174463457595,0.05082369197242276
69.90000000000026,13.675911678975734,0.2518059600437179,0.052783247324520666
70.80000000000028,13.780211549861587,0.2543566816660585,0.05071365099319092
71.7000000000003,13.882595487479888,0.2574863982795763,0.05047038005131732
72.6000000000003,13.98330314738374,0.26107572906322796,0.05151256145585226
73.50000000000031,14.085898245411517,0.26717996315036774,0.051487770189099
74.40000000000033,14.18753086180445,0.2697239513672678,0.05201111994571672
75.30000000000035,14.284636204277934,0.27299508897226366,0.052946974035858574
76.20000000000036,14.386344292858679,0.27521605810972916,0.051596351835621945
77.10000000000036,14.486230095426235,0.27691407179210903,0.05319228697329592
78.00000000000038,14.581425664127728,0.27849345997357866,0.0524872820465454
78.9000000000004,14.680944785089313,0.2804238578085263,0.05183504279327256
79.80000000000041,14.778505557647708,0.28377258916260595,0.05316571842931772
80.70000000000041,14.87489110114342,0.28437413327150274,0.0531690080121523
81.60000000000043,14.971066434527295,0.2869238920810425,0.05314700780328696
82.50000000000045,15.066362375576773,0.28965039432196926,0.05194755003303442
83.40000000000046,15.16217671407956,0.2891345664597056,0.053013810448115706
84.30000000000047,15.257145761740595,0.2914869935559845,0.054496119158419454
85.20000000000049,15.349170000000072,0.2938963478580805,0.05443873109734021
86.1000000000005,15.445191729730501,0.2948821247742498,0.0544503647085719
87.00000000000051,15.537795146400885,0.29730047359543565,0.05443637662202683
87.90000000000052,15.632328787218922,0.29937321769885505,0.05616941907852446
88.80000000000054,15.724719780499926,0.30042084421432946,0.05570213398083812
89.70000000000056,15.818244494737591,0.30237286625838955,0.05553630460604708
90.60000000000056,15.909598493731812,0.3055655356339323,0.05574169916735361
91.50000000000057,16.00321068443741,0.3060555657490105,0.05576410872573767
92.40000000000059,16.092208854756393,0.308461360325505,0.055767144967799
93.30000000000061,16.184816380598207,0.31051848512435487,0.05582796827237857
94.20000000000061,16.275267994826503,0.31408385840919384,0.056391370272364405
95.10000000000062,16.36608304923958,0.3153056222779369,0.05568412673591272
96.00000000000064,16.45507161588152,0.31848095524565323,0.05577975882119368
96.90000000000066,16.546236231896074,0.3209608622751865,0.05633487275151161
97.80000000000067,16.635649454106748,0.32348158029587026,0.05680800057570501
98.70000000000067,16.7244569782239,0.32441542569760995,0.057425830580228876
99.60000000000069,16.81589062140972,0.3258270284357828,0.05839924346028624
100.50000000000071,16.905512425449626,0.32703310887295656,0.05709075650749451
101.40000000000072,16.99375852527752,0.32903612251486436,0.058419194566914356
102.30000000000072,17.082694027459766,0.32939818869914816,0.057088836437388935
103.20000000000074,17.172158213888057,0.33128721947373974,0.05797767835044443
104.10000000000076,17.260549492667053,0.3325153973411813,0.058396215257882744
105.00000000000077,17.348890167897178,0.33327661133475006,0.05771414889784943
105.90000000000077,17.439170000000118,0.334860472545069,0.058409844922088006
106.8000000000008,17.525570917795587,0.3354031486016389,0.0583719817407129
107.70000000000081,17.615643670851917,0.3348902262381823,0.05983266308961532
108.60000000000082,17.70047228780405,0.3364083161867616,0.05850974086566829
109.50000000000082,17.79183329766914,0.3389613160098879,0.05718410769849047
110.40000000000084,17.880541984822596,0.3397143880563329,0.05587952982756761
111.30000000000086,17.968986112282845,0.3392736664018384,0.05851330537699173
112.20000000000087,18.057864500880818,0.34115943728860576,0.05851365786628726
113.10000000000088,18.14521096287921,0.34190246040527006,0.05986837153830926
114.0000000000009,18.233221406946598,0.3430141022242654,0.05918488625803153
114.90000000000092,18.321431641601635,0.34389179593467245,0.059214141828479505
115.80000000000092,18.408401520476065,0.34564524543039976,0.05686410824465682
116.70000000000093,18.496020784191803,0.3476628049411271,0.05787225082551206
117.60000000000095,18.584608998706635,0.350067088678752,0.05830563812190359
118.50000000000097,18.672757138430775,0.35112186274431245,0.05760692965710312
119.40000000000097,18.75801707234189,0.35315243769787763,0.05825351753573571
120.30000000000098,18.84687185136496,0.35251884531135147,0.058301944869484146
121.200000000001,18.933981268250932,0.35343160244406235,0.058290382943472
122.10000000000102,19.02192377443242,0.35285206856311413,0.05937464640389045
123.00000000000102,19.11064450510475,0.3536086848184212,0.059608566814915775
123.90000000000103,19.19861638193133,0.35252380983558906,0.0582843644886184
124.80000000000105,19.284990360339577,0.35065147613405456,0.05829015975212215
125.70000000000107,19.371630077837505,0.35351223197244175,0.05989555271991431
126.60000000000107,19.459933580185204,0.3522511265220656,0.06049171592349101
127.50000000000108,19.547293533805274,0.3504305564400211,0.061150476521715014
128.4000000000011,19.633414263636393,0.3521907446492284,0.06015923605900486
129.30000000000112,19.720662997797,0.35199580949930287,0.0599031939391832
130.20000000000113,19.806545185293068,0.35327155084186224,0.05791480706354957
131.10000000000113,19.893947434522442,0.3541629978739752,0.05752992865461426
132.00000000000114,19.980155343583498,0.3568882435547154,0.057529927272645054
132.90000000000117,20.06770078668246,0.3568517396616302,0.05793950456537367
133.80000000000118,20.15456613660161,0.35752568708792176,0.05883916901993658
134.70000000000118,20.240200873939,0.35852560501022623,0.058840013805828484
135.60000000000122,20.327050714161015,0.3585822650411351,0.057519752878720354
136.50000000000122,20.412881089215183,0.35975855025903714,0.05887464351282912
137.40000000000123,20.500640923945927,0.36050303516059,0.05753008498574541
138.30000000000123,20.585628668778885,0.36111872800591793,0.058883297871436646
139.20000000000124,20.672882710849542,0.35956820185388016,0.057821856080155776
140.10000000000127,20.758864578796075,0.3612390439194275,0.057359909998196734
141.00000000000128,20.84547657230801,0.3622785331867764,0.05873566026538857
141.90000000000128,20.931000410811365,0.36224867686984275,0.05873003558739587
142.80000000000132,21.01755209833123,0.36448674947496473,0.05956657221850925
143.70000000000132,21.10309410307192,0.3644733433366405,0.06004991005386273
144.60000000000133,21.19003437231509,0.3637470360785843,0.05874950307010973
145.50000000000134,21.275299754551682,0.36450478687694976,0.05835023397107175
146.40000000000134,21.360643582574102,0.3676175935244457,0.0598299878109243
147.30000000000138,21.44744197263895,0.3682738347781359,0.06108487847059685
148.20000000000138,21.532142830141648,0.3699055497509227,0.0598445071246676
149.1000000000014,21.618616352648196,0.3695835150381911,0.05982764656322903
150.00000000000142,21.70364419062022,0.3704329218420579,0.05851946439573208
150.90000000000143,21.787356495989304,0.3729034677234784,0.057101185003673116
151.80000000000143,21.873924038108072,0.3749234177036673,0.05720008031128998
152.70000000000144,21.959903760866716,0.3755513773632746,0.05669352936562433
153.60000000000144,22.04615766623587,0.3772273118090418,0.05585095281321539
154.50000000000148,22.132451506834336,0.37797653078241944,0.05730016493224799
155.40000000000148,22.21701350476696,0.37804185007760227,0.057300223270631
156.3000000000015,22.302740818298663,0.379461617777203,0.05730508838296622
157.20000000000152,22.38793915139803,0.38065610120883697,0.05863004005008943
158.10000000000153,22.473247761827018,0.38182609943610946,0.057639926847248724
159.00000000000153,22.55858861940945,0.38212729478365304,0.05763992893643355
159.90000000000154,22.644152721296454,0.382774884128981,0.05762931984919728
160.80000000000155,22.729930828531838,0.3819909441762426,0.055670702751262624
161.70000000000158,22.815537251475902,0.3846783834520142,0.05494654253769227
162.6000000000016,22.90038869505378,0.38339265723290505,0.054999849794478806
163.5000000000016,22.98490911373353,0.3853392483562583,0.05427454910519458
164.40000000000163,23.071786698680075,0.38340908571246257,0.055660051471936534
165.30000000000163,23.156501089915466,0.3837527404230059,0.05435298873264749
166.20000000000164,23.241572816080804,0.3837289844341031,0.05565964177538607
167.10000000000164,23.327428080604644,0.3855507477921144,0.05565981234267259
168.00000000000165,23.412587796760643,0.38463707311198614,0.054571874725804825
168.90000000000168,23.498501834554215,0.38497441724565384,0.05302451497519378
169.8000000000017,23.585313795274402,0.3863267040231919,0.0530198239529609
170.7000000000017,23.66972079250706,0.3864341383839027,0.05301981708615511
171.60000000000173,23.755037612152098,0.38712525573709144,0.05165660079574064
172.50000000000173,23.840739726565257,0.3876118880963625,0.05301056642486035
173.40000000000174,23.92716906220594,0.3877282126789797,0.05301982277299455
174.30000000000175,24.011000774880426,0.3873762534595905,0.05219210264651952
175.20000000000175,24.09562208317055,0.38946447032771014,0.05045780065722205
176.10000000000178,24.182957373481194,0.3910240513282305,0.051000409916630574
177.0000000000018,24.267726139188373,0.39082363414723786,0.05038827815940028
177.9000000000018,24.35382196959938,0.39415343273988657,0.048661954266615126
178.80000000000183,24.438143487611747,0.392168827251669,0.048420145296134365
179.70000000000184,24.52465640417011,0.39234971299683996,0.048420143999425846
180.60000000000184,24.610287795401202,0.39348595043307033,0.048420129602905426
181.50000000000185,24.695058255498132,0.39523093515810115,0.04776856216166259
182.40000000000185,24.77816076638674,0.39673236534669676,0.046440493872551336
183.3000000000019,24.865881394860956,0.39721254048963517,0.045119956583901555
184.2000000000019,24.951124082423267,0.39689081071564425,0.04513092014550235
185.1000000000019,25.037357467163016,0.39910305594247464,0.04381127087398262
186.00000000000193,25.12193806399346,0.39903516247500936,0.04478982415581889
186.90000000000194,25.20813629620892,0.40036729487332956,0.043469246682933615
187.80000000000194,25.29276069969224,0.4031833956889961,0.042052310175431096
188.70000000000195,25.377695192449085,0.4032817273732514,0.04216388896162648
189.60000000000196,25.463550417991154,0.4039123820720719,0.040839725167726826
190.500000000002,25.548521943619747,0.4036499463033151,0.040839975972849274
191.400000000002,25.633464895818218,0.4042403748522255,0.04084644326364728
192.300000000002,25.71637977969348,0.4061441215284698,0.0385298768200979
193.20000000000203,25.80454363028063,0.405941532747471,0.03820079346799776
194.10000000000204,25.887839209374548,0.4071181336831413,0.03820014485396417
195.00000000000205,25.97393363997724,0.4083567572685888,0.03721476673088997
195.90000000000205,26.059586013098826,0.40922537306642215,0.0355821052375731
196.80000000000206,26.1451696357468,0.40865436684643464,0.035641615301951646
197.7000000000021,26.229535795659924,0.4091420909194464,0.031616931369345735
198.6000000000021,26.313824219738134,0.4093312938263214,0.032612912999053556
199.5000000000021,26.399359487222025,0.41082880754436313,0.0326249209804681
200.40000000000214,26.485071800552557,0.41425923607280535,0.03303252680685187
201.30000000000214,26.570037315945438,0.41507134825387115,0.0302609130124587
202.20000000000215,26.656538466845547,0.415710730019315,0.028981304399223973
203.10000000000215,26.740310966226353,0.41774113163910576,0.027683868749383223
204.00000000000216,26.82603922923591,0.41791692919686585,0.025046601217066033
204.9000000000022,26.911983629102373,0.41845555591523065,0.023703891857738135
205.8000000000022,26.997642420298913,0.42183717528218745,0.02261027475735844
206.7000000000022,27.081972585033327,0.42263904373114436,0.021069948659078186
207.60000000000224,27.16749218167388,0.42808732289236584,0.02056258875249828
208.50000000000225,27.25346159590703,0.4278392450930243,0.018770672636073904
209.40000000000225,27.338044658549418,0.43081035854894767,0.018437846114816026
210.30000000000226,27.423583296221647,0.43280391377134786,0.01625770016184358
211.20000000000226,27.50846548964728,0.4336144948103876,0.014490572677237523
212.1000000000023,27.594814160921604,0.43676556374273034,0.013153140137931452
213.0000000000023,27.679059063099935,0.44195834647742605,0.012511232608026113
213.9000000000023,27.765086055743556,0.44094098464983944,0.01073243208278285
214.80000000000234,27.848642329159947,0.4438239754223674,0.009220503702361604
215.70000000000235,27.935072157871414,0.4453608345562625,0.007900427074269523
216.60000000000235,28.019168960384434,0.4485444922300882,0.006589875217080987
217.50000000000236,28.105771665301457,0.4522101026360675,0.005273141169532813
218.40000000000236,28.19089906986481,0.4527778212129588,0.002633747080778903
219.3000000000024,28.276559141197954,0.45601916608705484,0.0001003183328158741
220.2000000000024,28.36226031066795,0.45716504058206847,-0.0016611715884629064
221.1000000000024,28.446882002663575,0.4591637803019733,-0.00402697191994239
222.00000000000244,28.532486895579147,0.46372194652310433,-0.006677081740731339
222.90000000000245,28.618959601952728,0.46667504827691114,-0.006689007829474569
223.80000000000246,28.703792644092136,0.46967430040348623,-0.010539866778911389
224.70000000000246,28.7894639182532,0.47300366515039505,-0.01197035131379831
225.60000000000247,28.873395064739857,0.47744358981353213,-0.013312644792983441
226.5000000000025,28.96006075843283,0.4804581219944374,-0.016026427944860977
227.4000000000025,29.04495476455542,0.4832999475472746,-0.01734680071733763
228.3000000000025,29.13036945504332,0.4850318377929328,-0.021431023404057115
229.20000000000255,29.215158353046338,0.49116773872328967,-0.025241863502634132
230.10000000000255,29.301667833772278,0.4940692140329204,-0.026792248697558918
231.00000000000256,29.387656920957614,0.4972262579479435,-0.02964158964861241
231.90000000000256,29.472739342129433,0.5006328173126915,-0.03247578527387596
232.80000000000257,29.55841685782358,0.5043152644840979,-0.03370413957575291
233.7000000000026,29.643336550755432,0.5103450366454981,-0.03647403091838797
234.6000000000026,29.728610705681508,0.5109869179324152,-0.04073493915563908
235.50000000000261,29.81430577099385,0.5171495029864048,-0.04397295817623181
236.40000000000265,29.89961936406082,0.5196859413704495,-0.047579653693266444
237.30000000000265,29.98522137311615,0.5235282028276795,-0.05075692416387856
238.20000000000266,30.070954143219677,0.5305175416539023,-0.05220052657167429
239.10000000000267,30.15656473383025,0.5334809084718095,-0.056483947448678684
240.00000000000267,30.24213723868679,0.5378894343145322,-0.05997926069028203
240.9000000000027,30.326770235901144,0.5443905593827026,-0.06232303521261162
241.8000000000027,30.412357417174807,0.5491311841922206,-0.06509624322974794
242.70000000000272,30.497956842797972,0.5564629328900033,-0.07101939577265348
243.60000000000275,30.583961422202016,0.560336557427054,-0.07389170075768536
244.50000000000276,30.666345708752424,0.568400492854727,-0.07682349704642011
245.40000000000276,30.754672500972305,0.5806794029625824,-0.08084265375663335
246.30000000000277,30.84008324320575,0.5936981091365843,-0.08453556767053083
247.20000000000277,30.926265104795384,0.6001098110907607,-0.08953963062595882
248.1000000000028,31.011235599060125,0.614968952938082,-0.09433592309574923
249.0000000000028,31.096730906981527,0.6202101216093153,-0.09709333704600276
249.90000000000282,31.182967383662987,0.6142009440531906,-0.10165093992092711
250.80000000000285,31.269068659604763,0.6065251949678975,-0.1057083941595911
251.70000000000286,31.354291589253442,0.6028817621454257,-0.11267758882859935
252.60000000000286,31.438901297487945,0.5988175065424681,-0.11614082745954635
253.50000000000287,31.524708893542382,0.5965438154053802,-0.12191898049080363
254.40000000000288,31.61143467265243,0.5954009869365491,-0.1268213564231302
255.3000000000029,31.696584927230358,0.5944251205346403,-0.1314428423172438
256.2000000000029,31.781309461006128,0.5973352474399712,-0.13638095751573376
257.1000000000029,31.86776995190361,0.6003115444859406,-0.14235522559928837
258.00000000000296,31.953371632356564,0.6046618938355783,-0.14831847372733487
258.90000000000293,32.03906641891588,0.6058564793103336,-0.1540282026572215
259.80000000000297,32.124161286818875,0.61407009149977,-0.15852378453605054
260.700000000003,32.21103056833825,0.6198474434885997,-0.1645524376598444
261.600000000003,32.29541532870774,0.6255089037122593,-0.17082941139823138
262.500000000003,32.38212677532102,0.63055933910297,-0.17953812915748246
263.40000000000305,32.46726536265783,0.6371935099324479,-0.18650364242228035
264.300000000003,32.554535958790346,0.6431199864473495,-0.192329649134666
265.20000000000306,32.637797887389546,0.651513423800697,-0.19937228904413162
266.1000000000031,32.72602926469752,0.6553447963344796,-0.2077731849676927
267.00000000000307,32.81074514205175,0.6653246080839738,-0.21515559839892173
267.90000000000305,32.89779553189799,0.6723963471726688,-0.2225288313330127
268.8000000000031,32.98275911412916,0.6784243001696315,-0.23062579642604408
269.7000000000031,33.06864994574703,0.6873314832081574,-0.2386726453039274
270.6000000000031,33.15490798776472,0.6974430264182325,-0.24924839588561332
271.5000000000031,33.24063220799099,0.7094501112641228,-0.2584712841325625
272.40000000000316,33.32551564294908,0.7172521860902732,-0.26695819699345513
273.30000000000314,33.4119828655823,0.7296419396252101,-0.2763781030946202
274.2000000000032,33.49802133940293,0.7409032987325896,-0.28698991807870744
275.1000000000032,33.584616248453656,0.7519300512351244,-0.29663164925017727
276.0000000000032,33.669817310879395,0.7635023134406733,-0.3080140438956751
276.9000000000032,33.75684216140862,0.7750423462562208,-0.3191960373556437
277.80000000000325,33.84156581353986,0.7874690013796516,-0.33132746067139784
278.70000000000323,33.9281383438327,0.8019079921558646,-0.3431427611062041
279.60000000000326,34.01402183404866,0.816289019595752,-0.3559856445196079
280.5000000000033,34.099925244522844,0.8271730830182882,-0.3652633029010288
281.4000000000033,34.186069489617594,0.8393282922982952,-0.38042643342174287
282.30000000000325,34.271921323289,0.8517435810788018,-0.39250237299377577
283.2000000000033,34.35862413926266,0.8616062083729877,-0.40545974855106204
284.1000000000033,34.44408417105728,0.8712803409972619,-0.4175900221289961
285.0000000000033,34.531502880402314,0.8835146532269982,-0.4305480673777917
285.90000000000333,34.6167435287905,0.8913380431034048,-0.44630336733591314
286.80000000000337,34.70315947964815,0.8994090144156965,-0.4603671322301399
287.70000000000334,34.79090711744533,0.908647436495074,-0.4741999288505587
288.6000000000034,34.876299920900045,0.9144056631436447,-0.48753100780696323
289.5000000000034,34.962295045600435,0.9199337109569514,-0.5019436958405556
290.4000000000034,35.048453393998884,0.923332921536742,-0.5164848130364392
291.3000000000034,35.135425378805714,0.9236705746509848,-0.5311422014285645
292.20000000000346,35.22101289541395,0.9202283101665436,-0.5456725373103994
293.10000000000343,35.30732506562246,0.9141833763245037,-0.5615146302031588
294.00000000000347,35.39465156370722,0.9033457314982455,-0.5741492303734872
294.9000000000035,35.47976691848897,0.8895902070448551,-0.5873829759387403
295.8000000000035,35.56722655833855,0.8697712885435216,-0.604695425027864
296.70000000000346,35.652276307973196,0.8476543520905317,-0.6180870790719988
297.6000000000035,35.7385807333109,0.8224482308027963,-0.6342026836122558
298.5000000000035,35.824809159519184,0.796624035131545,-0.6471465350917409
299.4000000000035,35.91111864269705,0.7737661229682944,-0.6598943332674159
300.30000000000354,35.99680914397166,0.7501838352111817,-0.6713458976568214
301.20000000000357,36.08249457165904,0.7305855897649269,-0.6832516522029319
302.10000000000355,36.16865838738277,0.7103672266760624,-0.6960779424659287
303.0000000000036,36.2544853703556,0.6917435297089212,-0.7075172109606123
303.9000000000036,36.34041149168105,0.6763930919867722,-0.7190209988209117
304.8000000000036,36.42723204159363,0.6599412155746998,-0.7315068075753812
305.7000000000036,36.512494536037785,0.6476141681195264,-0.7429125184519307
306.60000000000366,36.598769390835834,0.6342693900780565,-0.752840675204264
307.50000000000364,36.68347225794694,0.622799482846826,-0.7631963488733966
308.4000000000037,36.77141927510011,0.6092551631571302,-0.7744319683926437
309.30000000000365,36.85725541850547,0.5984630332954153,-0.7836167612852214
310.2000000000037,36.94382436519663,0.588045994392201,-0.7912529741772092
311.1000000000037,37.02998203464776,0.5779306120181116,-0.8005121707205705
312.0000000000037,37.11585294513438,0.5666244215647646,-0.8096353771140601
312.90000000000373,37.20200759150503,0.5555933088358487,-0.8186221924744554
313.8000000000037,37.287437150835665,0.545733535331907,-0.8262312112144632
314.70000000000374,37.374710680957875,0.5356864911889747,-0.8357576258191455
315.6000000000038,37.459859531659184,0.5256430961767112,-0.8425274665546394
316.50000000000375,37.54645096802647,0.5163069318696294,-0.8520117036523955
317.4000000000038,37.6332476903281,0.5063551107873492,-0.860365356334237
318.3000000000038,37.719356184079764,0.497091072300997,-0.8675173058276044
319.2000000000038,37.8054689363988,0.4878685296860727,-0.8751426497928834
320.10000000000383,37.89240519467389,0.4777447666084482,-0.8827240286774924
321.00000000000387,37.97786983126062,0.4705559819124529,-0.8893954301309499
321.90000000000384,38.06579961662948,0.4616163638453318,-0.8953934980436551
322.8000000000039,38.151381459261394,0.45329075545337405,-0.9031290156187444
323.70000000000385,38.237343358120256,0.447121056832654,-0.908957409269556
324.6000000000039,38.325025200000674,0.43879538466544016,-0.9175770535268017
325.5000000000039,38.411467969283386,0.43244493017139507,-0.9242207588921145
326.4000000000039,38.498213777589385,0.4247731137774665,-0.9318990266111076
327.30000000000393,38.58421305437243,0.4178249927637844,-0.9367306163222757
328.2000000000039,38.67116182917462,0.4109780820649921,-0.945510448652688
329.10000000000394,38.75737340909619,0.40355106901374455,-0.9516020596197405
330.000000000004,38.844011560090145,0.3994975514571495,-0.9584504528181825
330.90000000000396,38.92815062337808,0.39253432287944695,-0.9658867277559939
331.800000000004,39.01727086395906,0.3885174208929692,-0.9727073643102386
332.700000000004,39.10302850521227,0.383601187766614,-0.9803975316001612
333.600000000004,39.19122492739885,0.37867230430324356,-0.9881578214512352
334.50000000000404,39.27714964750081,0.3712593378649166,-0.9944930675197003
335.40000000000407,39.36356754377993,0.3682525125432518,-1.0011534541738212
336.30000000000405,39.450757145731444,0.36319729911386145,-1.0086318299408337
337.2000000000041,39.53816786128402,0.3588926548422929,-1.016715712784971
338.10000000000406,39.62527616914528,0.3553263624890974,-1.0267432225203303
339.0000000000041,39.71149090921567,0.350250993904518,-1.0317549171826874
339.9000000000041,39.79814747544653,0.3474993368638526,-1.0389263257733714
340.8000000000041,39.88593496449335,0.34703455298972763,-1.04536605534991
341.70000000000414,39.970235782311605,0.34407537997813475,-1.0535396625756284
342.6000000000041,40.059359602652954,0.340969935406574,-1.0617367495470376
343.50000000000415,40.146414951133686,0.34253696497743313,-1.0674417785872463
344.4000000000042,40.23377890524873,0.3411515884098212,-1.0737416209378505
345.30000000000416,40.321353372687554,0.3400964119036775,-1.081603958657741
346.2000000000042,40.40861243754164,0.33612191125768187,-1.0874132431314525
347.10000000000423,40.494422011459605,0.33577944512714447,-1.0934159872014444
348.0000000000042,40.581730585616064,0.3349624552250459,-1.1003513120627764
348.90000000000424,40.66679265288119,0.33495671938706373,-1.108505397595045
349.8000000000043,40.75563473930547,0.33466379979770117,-1.1150854116395217
350.70000000000425,40.84221459650218,0.3349107613421749,-1.1217292287093774
351.6000000000043,40.93034502291518,0.3395318035779319,-1.1267049384341132
352.50000000000426,41.01654159083692,0.3445839506012781,-1.135395075725282
353.4000000000043,41.10378681936295,0.34524149575873253,-1.1422969348145267
354.30000000000433,41.189871064054074,0.3489650606980697,-1.1499201410152984
355.2000000000043,41.27735739765189,0.3528217742388976,-1.1573897511897298
356.10000000000434,41.36346766386874,0.3570735655759635,-1.166839112699912
357.0000000000043,41.450434163143306,0.3610279304171713,-1.175083173562221
357.90000000000435,41.53751510295868,0.36435323711588524,-1.1828651609363274
358.8000000000044,41.62602354863447,0.36764743577038156,-1.1903046514743174
359.70000000000437,41.712797229851105,0.3725316539855963,-1.198515741738547
360.6000000000044,41.79999078114521,0.3765510190479158,-1.2071412207652203
361.50000000000443,41.886801216702985,0.3829069647505078,-1.217870373590194
362.4000000000044,41.97490101575715,0.38510467396901504,-1.2287757915859263
363.30000000000445,42.06125979637782,0.39057431871049403,-1.2393921120602478
364.2000000000045,42.14787452491385,0.3954386138202777,-1.2495043403405948
365.10000000000446,42.233925407555695,0.4018763465690172,-1.2604861243297383
366.0000000000045,42.32000737162049,0.40667757494842827,-1.2707475381950704
366.90000000000447,42.40888417811058,0.40955867184227146,-1.2842035781567551
367.8000000000045,42.496400271508705,0.41598659235333474,-1.2965313318993315
368.70000000000454,42.583633334055,0.42194721039539496,-1.308913244012746
369.6000000000045,42.67068751627327,0.4275267141680357,-1.322972430724353
370.50000000000455,42.75626282715842,0.43507528183545974,-1.3374441987441186
371.4000000000045,42.84452731437389,0.44261853430157866,-1.351911852459751
372.30000000000456,42.930526801360536,0.4522413233232732,-1.3678603652678434
373.2000000000046,43.0189667090701,0.46153572547076915,-1.3828899489425832
374.10000000000457,43.10614937556453,0.46719130517571006,-1.4019109778571064
375.0000000000046,43.193657347264505,0.4759879180672734,-1.4185094860871161
375.90000000000464,43.28063794211586,0.4879203114859615,-1.4381189767832812
376.8000000000046,43.368209956578326,0.4976579450419023,-1.456685013578435
377.70000000000465,43.45624301615077,0.5087173707888142,-1.4784216575984197
378.6000000000047,43.54430837431784,0.5209551754275747,-1.4999534819994067
379.50000000000466,43.63026210735694,0.531753623088814,-1.521108637411316
380.4000000000047,43.718857790337196,0.5462367133958902,-1.5457332273593072
381.3000000000047,43.805603126661964,0.5542981060868277,-1.5709001433465621
382.2000000000047,43.89322892168624,0.5656011239272083,-1.596350770887835
383.10000000000474,43.98036811223388,0.578773773081855,-1.6233511142793327
384.0000000000047,44.06878950023642,0.5875415670427814,-1.6490382797758945
384.90000000000475,44.15608651119436,0.6031455928471273,-1.6784523509322793
385.80000000000473,44.2436193333623,0.6110145691218993,-1.709821442242284
386.70000000000476,44.33108705783491,0.6239679991506512,-1.7420666479738602
387.6000000000048,44.41916907868156,0.6370440203918815,-1.7729996321196153
388.5000000000048,44.507031838051056,0.6468327639843351,-1.8066440560898944
389.4000000000048,44.5924367254663,0.6590605510395039,-1.8403693966583248
390.30000000000484,44.68269765371602,0.6703231691739192,-1.8788020004028105
391.2000000000048,44.76927115405603,0.680131959369582,-1.9148861381970574
392.10000000000485,44.85767617243225,0.6875754410135293,-1.95371702355801
393.0000000000049,44.945355973391614,0.6967031590582144,-1.9924395908729475
393.90000000000487,45.03281756449962,0.7028429624795689,-2.033573898809146
394.8000000000049,45.12030896693606,0.7097454969176492,-2.0740331074001266
395.7000000000049,45.209266407086545,0.714736370670236,-2.115234193711987
396.6000000000049,45.295924625072246,0.7182521735130892,-2.156380072474012
397.50000000000495,45.38401850480544,0.717927894144747,-2.1973692027343175
398.4000000000049,45.47191983169359,0.7165845700965503,-2.2369618526867825
399.30000000000496,45.55987749433659,0.7154989649679985,-2.278633767113051
400.20000000000493,45.64760282634006,0.7105469964492888,-2.3206375613077
401.10000000000497,45.7353336733062,0.7006877201139621,-2.3613722747548467
402.000000000005,45.823072248921505,0.6928939949584981,-2.4027001290518286
402.900000000005,45.910830156296534,0.6815880081340896,-2.442529992737653
403.800000000005,45.99696824000791,0.6693677765307379,-2.4820514380945013
404.70000000000505,46.08572501951946,0.6561935455977642,-2.521173613274406
405.600000000005,46.17316264168114,0.6443252717516137,-2.5585186682134538
406.50000000000506,46.260414293823985,0.6266890024529089,-2.5937253399390157
407.4000000000051,46.34668441334471,0.6127642113163332,-2.6285459065202827
408.30000000000507,46.43510099568359,0.5949892312942323,-2.6641677928161087
409.2000000000051,46.5225757196847,0.5795829446013135,-2.6999239707259974
410.1000000000051,46.609839615377545,0.563568345500766,-2.7325197226738265
411.0000000000051,46.698542543323995,0.5462839215651979,-2.7651545574011527
411.90000000000515,46.78559381270778,0.5285161628908784,-2.7953577109373224
412.8000000000051,46.873212812598176,0.5113318404980751,-2.825577134096645
413.70000000000516,46.96005478477372,0.4943661434297132,-2.8537357666359853
414.60000000000514,47.04877078394305,0.4768270163224255,-2.8824752019864492
415.5000000000052,47.13596965970535,0.4588034142396091,-2.9089341404343623
416.4000000000052,47.223066347303615,0.4416594962538433,-2.9327512872107335
417.3000000000052,47.31153719861825,0.424636441499904,-2.9596296683718295
418.2000000000052,47.39916898102659,0.41040420826238944,-2.9825973896314024
419.10000000000525,47.48658482883071,0.39227935783337725,-3.0041745917440714
420.00000000000523,47.574597260178805,0.3779792448045514,-3.0248197407327106
420.90000000000526,47.66235609325884,0.36113411677242596,-3.045476897050842
421.8000000000053,47.75035307152708,0.34770008954590087,-3.064248518461328
422.7000000000053,47.83773490162682,0.3345275139435586,-3.082770936786275
423.6000000000053,47.9264194695629,0.32142789646193354,-3.1000388767432483
424.5000000000053,48.01259596697451,0.3076295139253442,-3.1167105768903736
425.4000000000053,48.101375627777514,0.2948949042469345,-3.131610500316274
426.30000000000535,48.18886687705757,0.28428120186136807,-3.1453465747208424
427.20000000000533,48.27732204596671,0.272689297309605,-3.1599882394493064
428.10000000000537,48.3651674563644,0.2597353148821191,-3.173204667518189
429.00000000000534,48.452826086998236,0.24959254594813218,-3.1843870327544597
429.9000000000054,48.54011839693635,0.2395179355746475,-3.19567781102124
430.8000000000054,48.628244341925665,0.23300095791782516,-3.204484976329075
431.7000000000054,48.716790698987054,0.22360422530591562,-3.215299084589927
432.6000000000054,48.80422466433782,0.21530660787019307,-3.226035340814968
433.50000000000546,48.89128206007263,0.20577605853616,-3.234987865776087
434.40000000000543,48.9793419028388,0.2004712516055729,-3.241575934634035
435.30000000000547,49.06666115863351,0.1938856389037137,-3.2491862914983547
436.2000000000055,49.15508343883932,0.18954178686249523,-3.2566314039454936
437.1000000000055,49.24175068280288,0.1843302579734475,-3.261826014120904
438.0000000000055,49.33060087011981,0.178778517910261,-3.2688668026261456
438.9000000000055,49.41934653769488,0.17460786636207581,-3.276043516996674
439.8000000000055,49.50769785012815,0.17153756569979695,-3.280214361280087
440.70000000000556,49.596114211093564,0.16720453640268518,-3.2854296019909697
441.60000000000554,49.68448812938464,0.16354135082824384,-3.2912781029866034
442.50000000000557,49.772789611735206,0.15929658876260544,-3.296274369622424
443.40000000000555,49.86189934629492,0.15875500403480747,-3.2995277360548574
444.3000000000056,49.950820359346174,0.1563839385566318,-3.303552500796096
445.2000000000056,50.039825723449134,0.15309254399790406,-3.30819717457304
446.1000000000056,50.12679341783609,0.15101493017933276,-3.3135057884925176
447.0000000000056,50.21603048770288,0.15114472113566657,-3.3165738309320627
447.90000000000566,50.304510509704706,0.1483052249611284,-3.3228559173005134
448.80000000000564,50.392680660051255,0.14798391704238134,-3.324204461640853
449.7000000000057,50.48134679148698,0.1449861106255561,-3.327530278011398
450.6000000000057,50.56999405143785,0.14463954447763072,-3.33028632070885
451.5000000000057,50.65850261512208,0.1436064917380644,-3.333530020199871
452.4000000000057,50.74682866825529,0.14443889370783392,-3.336310745149122
453.3000000000057,50.83423355535101,0.1447338008823602,-3.3418488976850305
454.20000000000573,50.923089637069964,0.143882351003361,-3.3453748987615524
455.10000000000576,51.01196237626735,0.14414509387845653,-3.3505869423185293
456.00000000000574,51.099550935064016,0.14301905805458082,-3.3534313580627195
456.9000000000058,51.18787288098352,0.14351894282044753,-3.3567232491285837
457.80000000000575,51.27615478776528,0.14464494629838753,-3.358555574457027
458.7000000000058,51.36511756927037,0.14187417870234842,-3.3623623868278916
459.6000000000058,51.453421473330636,0.14458753904297905,-3.366898709877683
460.5000000000058,51.54132376810657,0.14290891917654658,-3.3697464175664003
461.40000000000583,51.63052437568817,0.14345633988037565,-3.3724083299976657
462.30000000000587,51.71897709679263,0.14417471080517497,-3.37516816266442
463.20000000000584,51.80854841691556,0.14449416781365199,-3.3790566027480153
464.1000000000059,51.896369416923896,0.14374066660758955,-3.3827891241605164
465.0000000000059,51.98455763353219,0.14133343639705187,-3.384246045598747
465.9000000000059,52.07258260268202,0.140018256630971,-3.3891243909248634
466.8000000000059,52.16168542919004,0.14047827004836655,-3.393739259284942
467.7000000000059,52.25026534108571,0.13980512090942554,-3.397238348709502
468.60000000000593,52.33916897991304,0.13895039042177548,-3.4012897683133216
469.50000000000597,52.42809918011208,0.13833797141940118,-3.4045641631548147
470.40000000000595,52.51563963280617,0.13755317273813972,-3.4071578680894907
471.300000000006,52.60630264123974,0.13537441798231398,-3.4119004597234444
472.20000000000596,52.69456957257514,0.13527947612314728,-3.413198223653351
473.100000000006,52.78286903335311,0.1330058272988729,-3.4160384115392386
474.000000000006,52.871331010877505,0.1314372833570584,-3.4202475904686276
474.900000000006,52.96136228457011,0.13198025687713355,-3.4229840426222893
475.80000000000604,53.05009066998782,0.1286782570321724,-3.4258940132543616
476.70000000000607,53.13878713520348,0.12736542275806506,-3.429744454363888
477.60000000000605,53.22789237885753,0.12503149797450896,-3.431043313121502
478.5000000000061,53.31586355322501,0.12458666569099863,-3.4349820593610403
479.4000000000061,53.404209904869894,0.12260721302859567,-3.436822325993554
480.3000000000061,53.49263029800215,0.11931582579388511,-3.4407001117101093
481.2000000000061,53.58213614439624,0.118228455790789,-3.4437415586323867
482.1000000000061,53.67080019202904,0.11659011215116444,-3.4449722568595487
483.00000000000614,53.75959215644178,0.11412230818010649,-3.447652639037547
483.9000000000062,53.84793532545655,0.11111829084515557,-3.4489689628838542
484.80000000000615,53.93608585639798,0.10834657657570823,-3.4514270605068216
485.7000000000062,54.02490269075609,0.1063808615077585,-3.453555423873367
486.60000000000616,54.11446500690366,0.10634212435990242,-3.4575594141596224
487.5000000000062,54.200030275144734,0.1038753621179801,-3.4605130449731245
488.40000000000623,54.2911292989351,0.10262866066145193,-3.4604690004061345
489.3000000000062,54.380280705589094,0.10121257945894757,-3.460889911936001
490.20000000000624,54.46916906675569,0.09886796669636311,-3.4643971450453015
491.1000000000063,54.558241341323246,0.09882696907369892,-3.4644209677424485
492.00000000000625,54.64664846214853,0.09512804817714104,-3.4670598566248554
492.9000000000063,54.73447599011066,0.09536258773568751,-3.469060269097936
493.8000000000063,54.823424348317864,0.09293979274139663,-3.4697587498675517
494.7000000000063,54.91217079195598,0.09329432785363256,-3.471915482737707
495.60000000000633,55.001901027415926,0.09216849866313248,-3.471335049590821
496.5000000000063,55.08966787533395,0.090064498506779,-3.4730922041243293
497.40000000000634,55.17897923390994,0.0911561241044212,-3.474412978971894
498.3000000000064,55.26865032165303,0.09020963236042179,-3.4757309043325018
499.20000000000636,55.35588603290634,0.08894050997518543,-3.48151064818593
500.1000000000064,55.445751811081706,0.08559919503050961,-3.4804639059780724
501.00000000000637,55.53296686947895,0.08296969482140648,-3.480452172520886
501.9000000000064,55.62413307844109,0.08110768119548384,-3.4814550407976426
502.80000000000643,55.711800520694915,0.08088882956890109,-3.4814454299186135
503.7000000000064,55.80198505158793,0.07939442345135406,-3.484060155812317
504.60000000000645,55.8904863279964,0.08005082802929675,-3.4853941991174477
505.5000000000065,55.97917000000067,0.0770022029392794,-3.4863762714061988
506.40000000000646,56.06854482154225,0.07710713274037795,-3.487699411253236
507.3000000000065,56.15831941856705,0.07536117543384391,-3.4864562650850806
508.2000000000065,56.246904258100656,0.07419339353802235,-3.4877474079104847
509.1000000000065,56.33575267343572,0.07356934290059103,-3.489096093738307
510.00000000000654,56.42455909390509,0.07192064410953103,-3.4827513552194986
510.9000000000065,56.51335899843713,0.07261546054504564,-3.4895001947513604
511.80000000000655,56.60139825865358,0.06956148804720996,-3.4912145741084193
512.7000000000066,56.69115364347062,0.06859004956673265,-3.48989063500655
513.6000000000065,56.780211629976776,0.06713043167734911,-3.4911865777025644
514.5000000000066,56.869264144252,0.0666839865216049,-3.4938403277929697
515.4000000000066,56.95875842826263,0.06517576368110967,-3.4925174600830857
516.3000000000065,57.04695424094995,0.06230723371611868,-3.492520084591754
517.2000000000066,57.13597823070512,0.06006761218452261,-3.4938371568704962
518.1000000000066,57.225200705148055,0.06277260624586212,-3.4938490493134076
519.0000000000066,57.313296189280926,0.062251425015243056,-3.4978926277685036
519.9000000000067,57.40201119219886,0.06245403630112911,-3.4993490844240855
520.8000000000067,57.49214286291902,0.06132695036118874,-3.500516663962639
521.7000000000066,57.58052044534275,0.05938897534344412,-3.49945875672358
522.6000000000067,57.67008489802058,0.05902208892316407,-3.4994400488243667
523.5000000000067,57.758773900131374,0.05725115780415313,-3.49936942922327
524.4000000000067,57.84804683240083,0.056446771492437375,-3.4983973446904013
525.3000000000068,57.93489048045711,0.056259452536270405,-3.5017484496690914
526.2000000000068,58.02594018414217,0.05855643463615423,-3.500438458422021
527.1000000000067,58.115226576119206,0.05249468656868783,-3.500441463170805
528.0000000000068,58.20401060187238,0.05227815263338531,-3.501746755186299
528.9000000000068,58.29370182892515,0.051195185426298195,-3.5051804876569745
529.8000000000068,58.381410876272355,0.04869496780703075,-3.507026037002192
530.7000000000069,58.471525365057,0.04805021036115109,-3.50718887683
531.6000000000068,58.56034599452891,0.04725891473954835,-3.509665517757699
532.5000000000068,58.64866901049589,0.0462943820878805,-3.5083399040915086
533.4000000000069,58.73839014395597,0.045573586682049916,-3.510149068967147
534.3000000000069,58.82768008051851,0.04441300071080001,-3.5119778180174723
535.2000000000069,58.91737297912799,0.04398483289980781,-3.5119600990730557
536.100000000007,59.00552370534059,0.04218508636787521,-3.5132689429937223
537.0000000000069,59.09453007087208,0.043848409112682174,-3.5132694372354347
537.9000000000069,59.18348364721216,0.04163402517784842,-3.513279978999
538.800000000007,59.272335811590025,0.04196883279196173,-3.5159041493135463
539.7000000000069,59.36221511263041,0.042084599658252286,-3.515959630412279
540.600000000007,59.45172441957676,0.03908062206079044,-3.5149311266035284
541.500000000007,59.541737109105114,0.040852878771420964,-3.5162500078166987
542.4000000000069,59.630757286664256,0.039555399986085815,-3.5162418676648355
543.300000000007,59.72019929882127,0.035940805404458875,-3.517228982662858
544.200000000007,59.80916906346799,0.03552645736072746,-3.517559815530035
545.100000000007,59.89814040961531,0.03454200052689216,-3.5187982225272108
546.000000000007,59.987578352902155,0.03455540391015355,-3.5198666128512492
546.900000000007,60.07693429425836,0.0331050381464697,-3.5211906732190887
547.800000000007,60.16594378665435,0.03681888350648921,-3.5211786999831522
548.7000000000071,60.25593814394245,0.03418061854587473,-3.5224999839935114
549.6000000000071,60.3450123992951,0.030646008741760822,-3.523815424588883
550.500000000007,60.43465244699869,0.032984600414109,-3.522513766403468
551.4000000000071,60.52415969552051,0.03028589689945138,-3.5236517520672517
552.3000000000071,60.61292954133403,0.030585294613991065,-3.523820129187196
553.2000000000071,60.702585817198376,0.0298880149949442,-3.5238202123859903
554.1000000000072,60.79158396715929,0.027876357958177445,-3.5251273541079913
555.0000000000072,60.88096940501066,0.026497398274799022,-3.5264439413558746
555.9000000000071,60.971031012928655,0.026307642604107895,-3.527905388338498
556.8000000000072,61.060214169521764,0.025206955070286474,-3.5304340037460125
557.7000000000072,61.14980714839531,0.02427344288489175,-3.5290899895849206
558.6000000000072,61.239266976424105,0.02026366211402275,-3.5300707589016165
559.5000000000073,61.32896645127603,0.020279060317816344,-3.530069849583417
560.4000000000073,61.41867164694362,0.019213252189549612,-3.5303727418456567
561.3000000000072,61.5079840307031,0.017669333688563715,-3.5317198922730353
562.2000000000073,61.598046916655555,0.01367353330476817,-3.530397582524066
563.1000000000073,61.68701903718087,0.01094812282839297,-3.530355045773336
564.0000000000073,61.776636550693574,0.010466188539895782,-3.5335014655493246
564.9000000000073,61.86341566532146,0.008172929896866354,-3.5357796295130957
565.8000000000073,61.954877069208344,0.008231148904261354,-3.5347522452326645
566.7000000000073,62.043441400911604,0.005746581389897365,-3.5361114428546343
567.6000000000073,62.1340907528922,0.005848609808236538,-3.53742979631434
568.5000000000074,62.22281252391295,0.002214423288220191,-3.537732407990168
569.4000000000074,62.310766969692345,0.0016277421382135948,-3.5387491793250603
570.3000000000073,62.40105384921313,-0.0016334727126217086,-3.5384246795017207
571.2000000000074,62.49096098638186,-0.0027270758789478267,-3.5374299364621464
572.1000000000074,62.57935455889819,-0.003123957289738688,-3.536786177794526
573.0000000000074,62.669170000000705,-0.005131331073205292,-3.5374299361039223
573.9000000000075,62.75835281051871,-0.004622161259827062,-3.5387561952114424
574.8000000000075,62.84834558134268,-0.005780464932920726,-3.540004819985519
575.7000000000074,62.93606795813079,-0.005783352866899127,-3.5386730209218427
576.6000000000074,63.02645044377384,-0.0038230976149672413,-3.5399745818128823
577.5000000000075,63.11506412141804,-0.005795455320332543,-3.5413863038187587
578.4000000000075,63.20417306406814,-0.004102169869619421,-3.540059824022926
579.3000000000075,63.29344447560781,-0.002488644435319376,-3.5413809306664787
580.2000000000075,63.38235541452929,-0.0011057678925260328,-3.5417104776144663
581.1000000000075,63.473235648316134,-0.0023232307971722266,-3.5420455582451336
582.0000000000075,63.56238484820155,-0.0020189325240806966,-3.5426898951894676
582.9000000000076,63.6511715177568,-0.0023510637380218524,-3.541724320838953
583.8000000000076,63.74149863171614,-0.00459294222229345,-3.5418705773149832
584.7000000000075,63.82980533126096,-0.002654681161118555,-3.543054427535952
585.6000000000076,63.920739848979466,-0.0035774109641873997,-3.54434062664683
586.5000000000076,64.00864998272426,-0.003660913544948796,-3.5443381296079233
587.4000000000076,64.09916804979895,-0.0012555704184564753,-3.545010171495515
588.3000000000077,64.18879094339198,-0.0019428979301988614,-3.5450102000451835
589.2000000000077,64.2774308461125,-0.002724942904026584,-3.5450102962262964
590.1000000000076,64.36654488880755,-0.0029191032836082265,-3.5443454515692214
591.0000000000077,64.45590816145143,-0.0028014344606823727,-3.545141765461674
591.9000000000077,64.54526110964305,-0.003405160464544865,-3.5453299524075863
592.8000000000077,64.63483040580813,-0.002495419929029019,-3.54550717573459
593.7000000000077,64.72440483209326,-0.002523292385456455,-3.5464796391784974
594.6000000000078,64.81388771506296,-0.004480736162176591,-3.5456955741155483
595.5000000000077,64.90296988288672,-0.005167678941904841,-3.545645583230937
596.0000000000077,64.95325252583164,-0.006790713238020718,-3.5466625901227653