File: 01_Data/Rebond_Foam_Carpet_Pad/STA/N2/10K_min/Rebond_Foam_Carpet_Pad_STA_N2_10KData_221013_R1.csv
##Temp./Â°C,Time/min,DSC/(mW/mg),Mass loss/mg
51.0,10.735930523482905,0.020465282204588098,-0.004857514561608323
52.100000000000016,11.131342522570412,0.08736850167134813,-2.0120346334806527e-05
53.20000000000003,11.377160886165422,0.12282876210276972,-0.00033256879260568084
54.30000000000005,11.5894791679429,0.14789140033378767,0.0010292752306790831
55.40000000000006,11.773958425313376,0.16831652833813426,0.0013790322012137146
56.50000000000008,11.94606547031069,0.18628919550777767,-0.00024298048117321613
57.600000000000094,12.109228820766829,0.20049295976814974,0.0016290142230115379
58.70000000000011,12.264504950076399,0.20882097584765358,0.0023589778821522245
59.800000000000125,12.415259812808843,0.2187501833721246,0.002085069421403851
60.90000000000014,12.561787409407984,0.22701734320201594,0.0014259605593847091
62.000000000000156,12.705277343058105,0.2322240909671085,0.0032659159054042597
63.10000000000017,12.845119987950527,0.24113945820159577,0.002831628479432524
64.20000000000019,12.981950669848517,0.2483787555469168,0.002583508402480117
65.30000000000021,13.11690525202973,0.2544023121860888,0.002255088070658662
66.40000000000022,13.24973630370386,0.2576844576197921,0.002827145185027913
67.50000000000023,13.380631458566551,0.2652197526979314,0.0029487361718234517
68.60000000000025,13.510875236337313,0.2673244318252974,0.0018861235505158724
69.70000000000027,13.637615453692355,0.27314943453864804,0.0025079719690603852
70.80000000000028,13.765610264272462,0.27683264121827167,0.002946784067181074
71.90000000000029,13.891294608431306,0.2810456814858874,0.0018808904102960433
73.00000000000031,14.016561971978899,0.28347226123947644,0.0032133415611306226
74.10000000000034,14.139194142420937,0.28619357273164947,0.0018316681006900204
75.20000000000034,14.262443313496822,0.28938701776129794,0.0018840812224971693
76.30000000000035,14.383437055678435,0.2946915360739981,0.0021708204285766364
77.40000000000038,14.501933672048896,0.29633437146231556,0.003335167057342936
78.5000000000004,14.624953374112406,0.30088911368926596,0.001866556995970381
79.6000000000004,14.741639854919367,0.3055847913760199,0.003182449251998065
80.70000000000041,14.86190241472352,0.3067660340756194,0.00301426093682311
81.80000000000044,14.979066241504443,0.30588072226040763,0.0018728374952043936
82.90000000000046,15.095939698446713,0.31023655854206833,0.0018996949753327108
84.00000000000047,15.211946133749967,0.31266453414958806,0.0017862119734171067
85.10000000000048,15.328918922720046,0.31411908007045997,0.0018701219194285912
86.2000000000005,15.443441481613881,0.3147148290401408,0.001860502888258786
87.30000000000052,15.558021769650855,0.3177089569670095,0.0005621133623181507
88.40000000000053,15.672204993557612,0.319984471438718,0.001083083504870519
89.50000000000054,15.783989357655365,0.32293648663186314,0.0019025171407336394
90.60000000000056,15.896571735583858,0.3231906187501471,0.0020859722481367804
91.70000000000059,16.009896060925833,0.32509609425586317,0.0018702853376093564
92.8000000000006,16.12083560276662,0.3280486154775456,0.0005826540540647684
93.9000000000006,16.232756357161733,0.3297558441861075,0.0018688999406379914
95.00000000000063,16.34481868851346,0.3322223179894932,0.0011041424556945678
96.10000000000065,16.455650124021673,0.3365506180910075,0.0017954949370180273
97.20000000000066,16.565954582598096,0.3383471702000923,0.0018016222550625294
98.30000000000067,16.67557155814965,0.34186956826768855,0.0005533090675107211
99.40000000000069,16.782197448640204,0.3426752708955314,0.0018662178412980346
100.50000000000071,16.89405933431947,0.3444425534905323,0.0018857551238853354
101.60000000000072,17.00441165148575,0.34713418812458463,0.0018668118070994666
102.70000000000073,17.112407412794113,0.34758832436605036,0.001866287078388762
103.80000000000075,17.222088252988257,0.3499084950956086,0.0022209539324093974
104.90000000000077,17.331431940944196,0.3512629658091787,0.0015400778189014197
106.00000000000078,17.439005010445882,0.3524559780147455,0.001882541456570408
107.10000000000079,17.548432183532388,0.35375487937760863,0.0012199922278268716
108.20000000000081,17.65563010263889,0.35466566972386904,0.001273704565931233
109.30000000000084,17.76510180871239,0.3569014788295659,0.0016150189561110473
110.40000000000084,17.873201895074505,0.3597966249217157,0.001876088042112034
111.50000000000085,17.98018577742002,0.35945030247578913,0.0006582240221706392
112.60000000000088,18.08935090028273,0.36199609229334917,0.0008791308827920119
113.7000000000009,18.19679270859772,0.3619678797435373,0.0008773695955142102
114.8000000000009,18.304136684419298,0.36605004746979264,0.0005519890588296938
115.90000000000092,18.411456321879815,0.36792217247917314,0.0005633406288603204
117.00000000000094,18.51914878020747,0.3694195455471576,0.0014628008143446891
118.10000000000096,18.624792532623598,0.3725100795771068,0.001916411174010868
119.20000000000097,18.734917783268802,0.37493792183092756,0.0017821671255706661
120.30000000000098,18.84202341400244,0.3776703513670968,0.003285978427621572
121.400000000001,18.94853972758515,0.37843245251105995,0.0031396828888672346
122.50000000000102,19.055845124861705,0.3773158218610785,0.0015229014595203871
123.60000000000103,19.15812036705547,0.3763535142357002,0.0018939195641891615
124.70000000000104,19.268332278264804,0.3758468941689681,0.0005695403271412935
125.80000000000106,19.375793048171815,0.37397893322065034,0.0018603462921933378
126.90000000000109,19.48261401333764,0.37479996045196007,0.0011930891848748182
128.00000000000108,19.588980965625346,0.3742755032036291,0.0018683577123383976
129.1000000000011,19.695000685290243,0.3737677922545115,0.001539649340358995
130.20000000000113,19.803705113981657,0.37515905921038495,0.00021989458918802995
131.30000000000115,19.907429281284475,0.37440493399956254,0.0005498523349558582
132.40000000000117,20.014267874392548,0.37547783455881034,0.0005484024588384706
133.50000000000117,20.121148946034495,0.3772073104059229,0.0001211336986459699
134.6000000000012,20.225884400753984,0.37782613012321553,0.0005499396535375567
135.7000000000012,20.33192922256275,0.37746137884032616,0.0005185935206282188
136.8000000000012,20.438292283510272,0.37858349016547266,-0.0007361090709689933
137.90000000000123,20.543126301255963,0.3827155446528959,0.0018707608433179423
139.00000000000125,20.649037661087917,0.38221512753290987,0.000551009723687379
140.10000000000127,20.754301234233132,0.3831197324568274,-0.0007658592473345216
141.2000000000013,20.859732988000687,0.3858036019097103,-0.0004121463510409207
142.3000000000013,20.964635897800747,0.38477572003607996,0.00018088966878160306
143.4000000000013,21.070677027009822,0.38541012210905046,-0.0004049752776245086
144.50000000000134,21.17495081670158,0.38485586886148415,-0.0007664139166485562
145.60000000000133,21.28193675417551,0.38737101804908136,-0.0006708709737734964
146.70000000000135,21.385638783434043,0.38792052531475474,-0.0007701218063038695
147.80000000000138,21.491088004357245,0.3909878447364724,-0.0007701310269458972
148.9000000000014,21.59585760596636,0.3909323504107859,-0.0008022711781676684
150.00000000000142,21.700903129260812,0.3951781950775317,-0.000720012890456978
151.10000000000142,21.805496335261708,0.397341560782813,-0.0007542712377688332
152.20000000000144,21.91009424889324,0.39703109368696954,-0.0007076001128307752
153.30000000000146,22.014456452743545,0.3990307104402825,-0.002169888052870661
154.40000000000146,22.120778705830954,0.3996434380594821,-0.0013603440147078594
155.50000000000148,22.225921550942907,0.4016014455957539,-0.0027501831265648313
156.6000000000015,22.330181309819142,0.40400320756824437,-0.0027501810247714253
157.70000000000152,22.435167425690135,0.4043971228180605,-0.004074970326432226
158.80000000000155,22.539548956035603,0.4064463674354627,-0.0034095472206634447
159.90000000000154,22.64395946697454,0.4072946935091889,-0.0033902499869409297
161.00000000000156,22.74869379469693,0.4068495290498797,-0.0033984438015708385
162.1000000000016,22.85279020265095,0.40559054250595894,-0.004719542946382216
163.20000000000158,22.95822701961154,0.40431580297449665,-0.0057103046805293545
164.3000000000016,23.063265874747934,0.4031527133202653,-0.0057992145146053
165.40000000000163,23.16873906773757,0.40480858941695536,-0.005711165266399476
166.50000000000165,23.272513164849894,0.4066735910001076,-0.0068877415555888
167.60000000000167,23.377272773107162,0.40734115780053626,-0.006359255547601084
168.70000000000167,23.481509292601476,0.4075574531107718,-0.0073497973661527105
169.8000000000017,23.586285020635785,0.40805565572159863,-0.007387239128635148
170.9000000000017,23.69126122953481,0.40696313750518304,-0.007350492875993098
172.0000000000017,23.795619524228243,0.4085831134056596,-0.008009942662899672
173.10000000000173,23.899268185490484,0.4117251931857055,-0.008010275733798977
174.20000000000175,24.004592016096588,0.4114770464741458,-0.010650095216040878
175.30000000000177,24.108340802151627,0.41338141678923357,-0.010649503821098527
176.4000000000018,24.21333449580413,0.41606729471624193,-0.00959533145972813
177.5000000000018,24.31537270040566,0.4174077201912343,-0.011960040554136686
178.6000000000018,24.4226872219509,0.41886290421646194,-0.011960033721527985
179.70000000000184,24.527463444130852,0.41994923429284425,-0.01328050563224048
180.80000000000183,24.63125665637809,0.4218999243454366,-0.013280132998578775
181.90000000000185,24.735185214196825,0.42147449434442386,-0.013265155852353328
183.00000000000188,24.839278880436336,0.4247000307872322,-0.015920150525566612
184.1000000000019,24.944582899575025,0.42380836891099244,-0.015920158043570165
185.20000000000192,25.048739235088366,0.4249195835439527,-0.01615510033005263
186.30000000000192,25.150643370943953,0.4261388768308695,-0.018560286441003715
187.40000000000194,25.257846138605387,0.4267976211627602,-0.01856018176449048
188.50000000000196,25.361815558196067,0.4276187177750413,-0.019532480193902746
189.60000000000196,25.46645475516409,0.4292550647068547,-0.02146554294896008
190.70000000000198,25.570369583234307,0.42994204363573896,-0.021180068050496104
191.800000000002,25.675102018038285,0.43078886041938524,-0.022509115488019038
192.90000000000202,25.778155105644608,0.43105990284898776,-0.023819912149530165
194.00000000000205,25.883578838998478,0.43382395667707113,-0.023819896472342617
195.10000000000204,25.986920207843152,0.43378073952169827,-0.02645895785960395
196.20000000000206,26.09195992878531,0.43616323943770974,-0.026460038100161842
197.3000000000021,26.196309811948193,0.43582269834389437,-0.029088511573835962
198.40000000000208,26.300270570618114,0.43801602397505696,-0.02909068833298889
199.5000000000021,26.40506707630905,0.4401037811849203,-0.030423480266398517
200.60000000000213,26.508847777937763,0.440961408307578,-0.03270920938371935
201.70000000000215,26.614406075704743,0.4433569186172138,-0.03369622523444438
202.80000000000217,26.71817484271526,0.44502112932357407,-0.03567992807967579
203.90000000000217,26.822153964102117,0.4457161894354557,-0.03699009684190413
205.0000000000022,26.92561986634197,0.4482961074798041,-0.03831641448074086
206.1000000000022,27.030739755265017,0.45242614043956736,-0.04066990574838769
207.2000000000022,27.135588631314903,0.4555111232941884,-0.04227011422990534
208.30000000000223,27.238338231467104,0.45727726661736956,-0.0432075422639131
209.40000000000225,27.344291751854794,0.45939496114784467,-0.04456392658994268
210.50000000000227,27.448665663478494,0.4618827091514319,-0.04720593017699182
211.6000000000023,27.553160581912515,0.4658146489917865,-0.047593385292194146
212.7000000000023,27.657212961985334,0.4708599812330715,-0.05020546292354933
213.8000000000023,27.76143598509641,0.4713203046875785,-0.05280059962330741
214.90000000000234,27.8657080568438,0.47430026255901464,-0.05411983288098332
216.00000000000233,27.970513671301738,0.4763826105435053,-0.056813790008063414
217.10000000000235,28.074824181458187,0.4788999659530438,-0.05798671938103128
218.20000000000238,28.17925002813259,0.48092832139266717,-0.060709470829434675
219.3000000000024,28.283355129699356,0.48279850567163785,-0.06428018417773584
220.40000000000242,28.387452714124912,0.486916491272811,-0.0659130300668318
221.50000000000242,28.492101635095008,0.49188745122375915,-0.06842911297171295
222.60000000000244,28.598023447905508,0.4953490541294403,-0.07121906582097903
223.70000000000246,28.703075691455783,0.49771439620309954,-0.07179741909389303
224.80000000000246,28.805827457861714,0.5044817420183327,-0.07575919761323302
225.90000000000248,28.910418463145806,0.5050969015905215,-0.0796071960102509
227.0000000000025,29.01517765800226,0.509840275768281,-0.08117475696199028
228.10000000000252,29.119434580701416,0.514713038257485,-0.08486065757332328
229.20000000000255,29.22392080570034,0.5174757320443415,-0.08769081610903484
230.30000000000254,29.32907282805425,0.5232667975286601,-0.09024519999061775
231.40000000000256,29.432678762237472,0.5287372407495483,-0.09349132604009514
232.5000000000026,29.537861715177794,0.5298083054720437,-0.09700887458067387
233.60000000000258,29.643916494046124,0.5356456804641172,-0.10245242870968196
234.7000000000026,29.74430219848702,0.5417448903573604,-0.10600876592103337
235.80000000000263,29.851707858370112,0.5439309892378545,-0.1078007732993016
236.90000000000265,29.954088534749065,0.549951154095283,-0.1109237358712667
238.00000000000267,30.061195355067376,0.5575603039322705,-0.11602352720724918
239.10000000000267,30.16566353792287,0.5621366148805507,-0.12033701980662626
240.2000000000027,30.27081802082398,0.5685577682185423,-0.12475995846236687
241.3000000000027,30.374800022475796,0.5787438850714536,-0.12894331985980445
242.4000000000027,30.480932929017076,0.5836183330402009,-0.13207626663419525
243.50000000000273,30.58378460786591,0.5923506069948901,-0.13737189964035634
244.60000000000275,30.690187774828917,0.6051180796938505,-0.1415082287617757
245.70000000000277,30.794708435991932,0.6193814618886904,-0.14636869704934785
246.8000000000028,30.900793721527105,0.6329255180301626,-0.15066112354589656
247.9000000000028,31.005197229002874,0.6485874628985594,-0.15735185533242912
249.0000000000028,31.109902059397296,0.6608565913739399,-0.16237063924953477
250.10000000000284,31.215683738657717,0.6535022138776455,-0.16693072079100268
251.20000000000283,31.321547977912587,0.647329952508402,-0.17302146840924637
252.30000000000285,31.42538827027812,0.6437292915117323,-0.17913086184025495
253.40000000000288,31.52982785229456,0.6400446584440971,-0.18486123965156853
254.5000000000029,31.63489204414567,0.6382293021593917,-0.19160149718872566
255.60000000000292,31.739998857877723,0.6397793736291497,-0.19684002896013064
256.7000000000029,31.845470077987816,0.6403029659126772,-0.20450586678362148
257.8000000000029,31.950089760797834,0.6442054115002036,-0.21078217260935128
258.90000000000293,32.05427048611987,0.6502661562588555,-0.21678071797370446
260.00000000000296,32.160299900659595,0.6551429304190823,-0.22542093886420567
261.100000000003,32.265234940731744,0.6623749077225006,-0.2322893553512233
262.200000000003,32.369999085309665,0.6689777685205127,-0.2395397220975095
263.300000000003,32.47535457500332,0.6751387163213763,-0.24805273552539298
264.40000000000305,32.580684893859036,0.6839375962269564,-0.256068864825882
265.50000000000307,32.68583633634415,0.6899773794236789,-0.2647832556122771
266.6000000000031,32.79036871549702,0.7010563203543616,-0.274035757582463
267.7000000000031,32.89522448479096,0.7085961275849747,-0.28472043537009695
268.8000000000031,33.00080518303073,0.719919829789152,-0.2943072525412993
269.9000000000031,33.105605517025566,0.7291566132041504,-0.3041065084415506
271.0000000000031,33.20728143539382,0.7388081253979658,-0.3146472903370099
272.10000000000315,33.31567703966359,0.7503255968393506,-0.3263347143355393
273.2000000000032,33.42079810478268,0.7643894527959421,-0.3374022131732368
274.30000000000314,33.525796748568325,0.7800048266724424,-0.3500479753394252
275.40000000000316,33.63153822548413,0.7922098839185987,-0.36197535141872184
276.5000000000032,33.734764240246314,0.806838360653297,-0.3755840140174853
277.6000000000032,33.842493141139535,0.8249608334856708,-0.3898792235761026
278.70000000000323,33.947786246197936,0.8407140773318148,-0.40261349816507863
279.80000000000325,34.05287786563231,0.8557194645798933,-0.41842233891396985
280.9000000000033,34.15870628761337,0.8693238423886621,-0.4337886231648409
282.0000000000033,34.264251133016096,0.8844640103169812,-0.4479221810280265
283.1000000000033,34.3696121249509,0.9005595689136053,-0.464217696998674
284.20000000000334,34.47391867509141,0.914982986918822,-0.47950269370550824
285.30000000000337,34.580430530510526,0.9244456447888572,-0.4966182838782567
286.40000000000333,34.68335172111166,0.9362522476079063,-0.5124319760853826
287.50000000000335,34.790794555854795,0.9445224364380604,-0.528672599477015
288.6000000000034,34.896818989943185,0.9519891051133529,-0.5462315294707243
289.7000000000034,35.00257152881451,0.9550925097477965,-0.5642773104908367
290.8000000000034,35.10697779280544,0.9575439136049252,-0.5812053274683309
291.9000000000034,35.211897912532294,0.9539990425654097,-0.5979046863971615
293.0000000000034,35.31776406295896,0.9448411901900424,-0.6143865773826014
294.10000000000343,35.42351118239498,0.9314671150350009,-0.63169866389444
295.20000000000346,35.52942613859051,0.90701201184986,-0.6507893675252605
296.3000000000035,35.633925982339086,0.8784921075474483,-0.6662623960592717
297.4000000000035,35.73930395773168,0.8441307867213687,-0.6813666769516851
298.5000000000035,35.84537113133211,0.8134668119178341,-0.6981318551542754
299.60000000000355,35.94990127675934,0.7837243316002228,-0.7115548826039069
300.70000000000357,36.056352808606356,0.7601118104696807,-0.7260065869825332
301.8000000000036,36.16108464834964,0.7407582929420785,-0.7404882604854488
302.9000000000036,36.26703534132437,0.7201922768650506,-0.7546164116344145
304.0000000000036,36.37132145314912,0.7029653596305625,-0.7675164314859706
305.1000000000036,36.47739206040941,0.6843436908141902,-0.7800499651708535
306.2000000000036,36.581196340507304,0.6709762043067231,-0.7953662596592661
307.30000000000365,36.68815903148981,0.6544806343134814,-0.8061606803494339
308.4000000000037,36.792838260652154,0.6429187646187638,-0.8158056782778065
309.5000000000037,36.89849881435303,0.6321939487180898,-0.8283328310606746
310.60000000000366,37.00350875121713,0.6213605841311495,-0.8391058492455108
311.7000000000037,37.11071045492671,0.6096315692754117,-0.8505208835532865
312.8000000000037,37.21484968965457,0.5963885302336105,-0.8612734176432792
313.90000000000373,37.320386996530765,0.5879901026546902,-0.8730939354061524
315.00000000000375,37.42571599148774,0.5753696718896366,-0.88239858737419
316.1000000000038,37.53162194795298,0.5616576132518107,-0.8906682433466289
317.2000000000038,37.6365091100426,0.5529363632364015,-0.9006067483118283
318.3000000000038,37.741658026991765,0.5403937678178584,-0.9099539746172312
319.40000000000384,37.84689686080014,0.5305270997815231,-0.9178030239137867
320.5000000000038,37.952284861629494,0.5208706332871517,-0.928009042684574
321.60000000000383,38.05869988083576,0.509553969259945,-0.9367960529881505
322.70000000000385,38.1640331810661,0.4988742737448061,-0.9453855555909709
323.8000000000039,38.270100789264156,0.4899124232738341,-0.9526765782505797
324.9000000000039,38.37541869413906,0.4827332791508748,-0.9628912295522185
326.0000000000039,38.48090286716143,0.47175668125218606,-0.9707898986738375
327.10000000000394,38.58781433522666,0.46366957392436625,-0.9802634259266139
328.2000000000039,38.69286900993509,0.45808898472494963,-0.9886655769235206
329.30000000000393,38.798973457810874,0.45085173189223865,-0.9973666823785949
330.40000000000396,38.9052715220429,0.4437611736983709,-1.005497923491823
331.500000000004,39.01164112432528,0.4386386478545561,-1.0153737559807992
332.600000000004,39.11693945554622,0.43153518803492724,-1.0229954870765248
333.700000000004,39.22290859755757,0.42516430306384934,-1.0333666413896494
334.80000000000405,39.32937311074812,0.4205352621683333,-1.040344801793624
335.90000000000407,39.43536493519379,0.41586894790264406,-1.0512188067573907
337.0000000000041,39.540716662404805,0.41009142224823336,-1.06067517453018
338.10000000000406,39.64803348410139,0.4061653498374437,-1.0691710999300974
339.2000000000041,39.75313544106017,0.4027574205073599,-1.0791760788043314
340.3000000000041,39.859552194067405,0.3995294897643942,-1.087583033901101
341.4000000000041,39.966444406167746,0.39592159706969643,-1.0967833148015305
342.50000000000415,40.07168724838653,0.3941600841195819,-1.1042242799812745
343.6000000000042,40.17840420131675,0.3913218530519833,-1.111943041197288
344.7000000000042,40.2850445388396,0.3897359007135577,-1.1214425560158614
345.80000000000416,40.39080391013467,0.3867945577112265,-1.12932487483058
346.9000000000042,40.49681937620568,0.3849932182581209,-1.137569793014897
348.0000000000042,40.60283209222418,0.3854570268528699,-1.1473749316736548
349.10000000000423,40.71019532224252,0.38316822281432383,-1.1552507501024958
350.20000000000425,40.81639959549441,0.38224759380500134,-1.1627404358853193
351.3000000000043,40.922523683378785,0.38222434359375546,-1.1696348403667822
352.4000000000043,41.029101371947384,0.38302221908266476,-1.1782172577515717
353.5000000000043,41.1349588682697,0.38397402542523157,-1.186947908738217
354.60000000000434,41.24147396477424,0.3846152789817152,-1.1970018617330176
355.7000000000043,41.348193793065015,0.3884482898861603,-1.206228594201864
356.80000000000433,41.45504442255746,0.3911611672514643,-1.215041060087481
357.90000000000435,41.561020768141255,0.39532752064797894,-1.2252783260210771
359.0000000000044,41.667577672693355,0.4004190530279056,-1.2358846880930718
360.1000000000044,41.77443698380771,0.4018098246889232,-1.245948292162184
361.2000000000044,41.88111971332535,0.4062298763679718,-1.2591444310116326
362.30000000000445,41.98824700656306,0.40996373426153876,-1.2709208942746564
363.4000000000044,42.094104205306984,0.4147309254249161,-1.2848218801244013
364.50000000000443,42.201396227408324,0.4207709764967554,-1.2978604835520993
365.60000000000446,42.30869902369094,0.42419603213646295,-1.3096440981455362
366.7000000000045,42.41452326215135,0.4323182208493228,-1.324648464087196
367.8000000000045,42.52138804276764,0.4382356384637772,-1.3396964091727765
368.9000000000045,42.62800003937931,0.44464819551214874,-1.3560761327213977
370.00000000000455,42.73384678927128,0.45195831767306827,-1.373695568941868
371.10000000000457,42.84193982500541,0.46072143212216654,-1.3901330437366424
372.2000000000046,42.948489127084706,0.4679235278478915,-1.4080673842066167
373.30000000000456,43.05611051187108,0.47561213120704826,-1.4277662773145328
374.4000000000046,43.16248566976461,0.483244619962736,-1.4479810387290284
375.5000000000046,43.269513557344396,0.4926131200026831,-1.4693360097458257
376.6000000000046,43.37641127182047,0.5044510855034354,-1.4933733423827253
377.70000000000465,43.48243629049639,0.517594129034732,-1.516877570139636
378.8000000000047,43.59040200855795,0.5262249998763622,-1.5433279961876822
379.9000000000047,43.69659001348565,0.5394396868197323,-1.568933616401757
381.00000000000466,43.80406440971064,0.5497464725175194,-1.597832364026646
382.1000000000047,43.91083569199929,0.5621945697042565,-1.6280109174571566
383.2000000000047,44.01879748381705,0.5742795077087588,-1.6607063791956658
384.30000000000473,44.12512730387947,0.585910342231207,-1.6914519752716535
385.40000000000475,44.232331066193986,0.6010694015142672,-1.7269740493596637
386.5000000000048,44.339256112529235,0.6138953795689618,-1.763581402872406
387.6000000000048,44.447297597646056,0.628309791955711,-1.8021802859707385
388.7000000000048,44.554560169813314,0.6423576213383728,-1.8418152996968948
389.80000000000484,44.65889071830372,0.65235457736336,-1.8825777433721829
390.9000000000048,44.768703934118605,0.6677811452101783,-1.9266228656045472
392.00000000000483,44.87622244634542,0.6778059047407433,-1.9711051963591746
393.10000000000485,44.98367974354063,0.6904334294736991,-2.0171275574005856
394.2000000000049,45.09105514226412,0.7004139383724343,-2.0639022634632083
395.3000000000049,45.198349488733726,0.7078223994131498,-2.11220499840801
396.4000000000049,45.30492665621708,0.7130416949205709,-2.1598927809936255
397.50000000000495,45.41241189055793,0.7162566888698949,-2.208423287041983
398.6000000000049,45.52019379680991,0.7159127637830477,-2.2569800563694686
399.70000000000493,45.62632378549673,0.7149421174512854,-2.3060287656000726
400.80000000000496,45.73478263751878,0.7081252307315457,-2.3540980239950065
401.900000000005,45.83979773252744,0.7002082030749803,-2.4019751810972556
403.000000000005,45.948716938248275,0.6920653431989344,-2.449859257042824
404.100000000005,46.05594890852408,0.6758381431674868,-2.495507665184152
405.20000000000505,46.16399153401227,0.6603682830639006,-2.5422493168832654
406.30000000000507,46.27186224875071,0.644847584753165,-2.5868110192277745
407.4000000000051,46.37890930706676,0.6263125159888638,-2.6285865606873955
408.50000000000506,46.48642329507482,0.605251378997478,-2.6710173485409276
409.6000000000051,46.59274534150899,0.587083599552924,-2.7121733833253967
410.7000000000051,46.700277712944605,0.5674021412351586,-2.7509532297679753
411.8000000000051,46.806997279607565,0.5470638073201828,-2.785764849067909
412.90000000000515,46.914919361641566,0.525621028050508,-2.822495708523723
414.0000000000052,47.02092630962682,0.501169118128848,-2.8550289052186835
415.1000000000052,47.12922148323843,0.48101493894540615,-2.888166045064307
416.20000000000516,47.23572530634094,0.46248873530232276,-2.919082695353324
417.3000000000052,47.343608279857776,0.4433665705605164,-2.949387832693692
418.4000000000052,47.44990551868226,0.4214076050238458,-2.9771771377955973
419.50000000000523,47.55771184611278,0.4034192162941744,-3.003407802484272
420.60000000000525,47.66581590853622,0.3860155301190853,-3.0284404950264996
421.7000000000053,47.773142884558546,0.36592535018614347,-3.050555147093294
422.8000000000053,47.87989799633098,0.3477889522114904,-3.071496977099267
423.9000000000053,47.98691372650353,0.3318467309830805,-3.090375077000726
425.00000000000534,48.09521101436282,0.317328513804847,-3.109183830428936
426.1000000000053,48.20204207225388,0.30162717370966463,-3.126631794099562
427.20000000000533,48.309998940070244,0.2885726176871286,-3.1452799346914797
428.30000000000535,48.41607318736912,0.2744904663229003,-3.160585913290948
429.4000000000054,48.524438559250704,0.26481754222308745,-3.174757999326691
430.5000000000054,48.63292761357534,0.25401190430172754,-3.1881062731915213
431.6000000000054,48.741365514554005,0.24225608057833836,-3.1998537628778645
432.70000000000545,48.8481622151988,0.23335976619336252,-3.2100177303160713
433.8000000000054,48.952687215658585,0.22323873637414576,-3.219274780034739
434.90000000000543,49.063323207760185,0.21546631075862727,-3.22906080033276
436.00000000000546,49.17095092615393,0.20660029223952725,-3.234418989720881
437.1000000000055,49.27899409951948,0.20114352794839657,-3.2398248046811746
438.2000000000055,49.386593177686066,0.1965407406536408,-3.250411202459314
439.3000000000055,49.49166087953051,0.19217730709719977,-3.2589019276976225
440.40000000000555,49.60184647102265,0.1897899922444627,-3.266732291600445
441.50000000000557,49.70989160941561,0.18513680892749068,-3.273395411251173
442.6000000000056,49.817807242848794,0.18084627106827061,-3.2798756116470873
443.70000000000556,49.92493718376493,0.18003454175075312,-3.2860529272636887
444.8000000000056,50.03324339387881,0.17586592257100003,-3.290855204177999
445.9000000000056,50.141262307372344,0.1743640738684582,-3.296520209413194
447.0000000000056,50.24866223117685,0.17218455065615385,-3.3021484270201245
448.10000000000565,50.356769315190874,0.17131110695321144,-3.307225317274935
449.2000000000057,50.463420200657836,0.17160351942333474,-3.3120071661469828
450.3000000000057,50.57277982741364,0.1679214698702583,-3.3164586764541943
451.40000000000566,50.68009111343978,0.16941123909907374,-3.320495951316775
452.5000000000057,50.78850612014674,0.1678023770572703,-3.3248922630082114
453.6000000000057,50.896066518600136,0.16527789845556057,-3.330546029243748
454.70000000000573,51.004427015685714,0.1656972771728194,-3.335409293939879
455.80000000000575,51.11235832433423,0.16376318773179888,-3.3374595977226456
456.9000000000058,51.219592098854456,0.16623133686311647,-3.34166790851704
458.0000000000058,51.32866406881386,0.16698675346381292,-3.345795910302006
459.1000000000058,51.43561241021538,0.16274810858509803,-3.3512746834645792
460.20000000000584,51.54432212303868,0.1639987712456613,-3.354761612939224
461.3000000000058,51.65225985305306,0.16402287813561833,-3.3586211416385336
462.40000000000583,51.7608887737189,0.1625822363485861,-3.3639490532238137
463.50000000000585,51.868912535357055,0.16353736007303787,-3.369336395194547
464.6000000000059,51.977207797470086,0.16266770089354848,-3.372574690735858
465.7000000000059,52.08443844663683,0.1629522514229132,-3.3755244030060343
466.8000000000059,52.19277264495923,0.16210780376781353,-3.3806721025047404
467.90000000000595,52.30128288387113,0.15767494171822966,-3.384588457542465
469.0000000000059,52.40961612292348,0.15885412009974936,-3.3884700713897917
470.10000000000593,52.51831749595952,0.15735425353821347,-3.3930581424972717
471.20000000000596,52.625962592894446,0.15793170612823137,-3.397056473681729
472.300000000006,52.734125283032824,0.1561408672215292,-3.4019826748884356
473.400000000006,52.84279889589344,0.15345209355539213,-3.4065360389802533
474.500000000006,52.9504012539259,0.1521098797391362,-3.4109567614204823
475.60000000000605,53.05908410947865,0.1494635569624841,-3.415093545055481
476.70000000000607,53.16761191296828,0.14652373661338097,-3.419401247693947
477.8000000000061,53.27520675784216,0.1478000113266864,-3.4230237342596377
478.90000000000606,53.3844058185093,0.14475263326427956,-3.4272141914336327
480.0000000000061,53.493386505579636,0.1423450586459865,-3.429646332095563
481.1000000000061,53.60135279968611,0.14053526062550803,-3.430608431196002
482.2000000000061,53.70949030706524,0.1390811692991029,-3.4346326300839687
483.30000000000615,53.81730745444665,0.13841341158505188,-3.438330679375421
484.4000000000062,53.925830728992196,0.13664146221138102,-3.440902773483418
485.5000000000062,54.03353038528808,0.13728253630290838,-3.445319202014721
486.60000000000616,54.143178635144345,0.1333991773829416,-3.4481533835956393
487.7000000000062,54.25224601434349,0.13028850535991743,-3.450710785961376
488.8000000000062,54.36053177927798,0.12966091305565142,-3.4510519147610497
489.90000000000623,54.46839729371492,0.1305314142730291,-3.4522637654949184
491.00000000000625,54.57790588366022,0.12786152103777232,-3.45498512600543
492.1000000000063,54.68632498992156,0.12789391400488292,-3.457311463659321
493.2000000000063,54.79475016383614,0.12774273302326755,-3.4599057553129158
494.3000000000063,54.90353311764312,0.12708925775366864,-3.460561267293506
495.40000000000634,55.0113400484002,0.12726052176593944,-3.4619066607395936
496.5000000000063,55.119129954211026,0.12369902187542647,-3.463220853991645
497.60000000000633,55.229095397155895,0.12471115825834983,-3.4638796486450403
498.70000000000636,55.33720742095769,0.12403085980716638,-3.4651871322203207
499.8000000000064,55.44553966093554,0.12361444492421769,-3.4665099078795434
500.9000000000064,55.55555933907363,0.12291025392858473,-3.467831597140645
502.0000000000064,55.663540565845295,0.12270366053970905,-3.469139970453124
503.10000000000645,55.772909300001174,0.12383998809531394,-3.4704603915404624
504.2000000000064,55.88184768306453,0.1211816177336496,-3.471781286205115
505.30000000000643,55.98956890182792,0.12175995136203654,-3.4730999616661307
506.40000000000646,56.09846692295087,0.12095911105389634,-3.4744202896520697
507.5000000000065,56.20853004047675,0.12130021670052687,-3.475730448989867
508.6000000000065,56.3166507086246,0.12045372234360213,-3.4770498177035374
509.7000000000065,56.42576312088985,0.12207327126058742,-3.478349878287565
510.80000000000655,56.53479557614564,0.12031333648639686,-3.4796780405127894
511.90000000000657,56.64316980308529,0.12087051263824833,-3.481000074925316
513.0000000000066,56.752972367357536,0.12317613085925411,-3.482318289182673
514.1000000000065,56.862194343038205,0.121041995561041,-3.482490676889269
515.2000000000066,56.97074548602269,0.12249072243686071,-3.4839590985495805
516.3000000000065,57.08118170228047,0.11977432045698955,-3.4852802074445
517.4000000000067,57.18936429916582,0.12003821037000434,-3.487565555052238
518.5000000000066,57.29883054645129,0.1176277015983122,-3.486568940609381
519.6000000000067,57.408705419496926,0.11727715242809067,-3.4866011625438023
520.7000000000066,57.517584597942204,0.1193484233006667,-3.489249956774356
521.8000000000067,57.62516227397637,0.12119890265597771,-3.490309652979235
522.9000000000067,57.73530262613995,0.11814159850385808,-3.4905499375491233
524.0000000000067,57.84367161324991,0.11993011559153843,-3.491870480208584
525.1000000000067,57.95262696081212,0.12337618231369146,-3.4931904150739843
526.2000000000068,58.060855018123554,0.12162779400694351,-3.4931886323775347
527.3000000000068,58.17061703400905,0.12241534262129677,-3.4945001205177517
528.4000000000068,58.28009733454247,0.12109978059895316,-3.4958202673036807
529.5000000000068,58.3878984224991,0.12138213969326123,-3.4967147870534725
530.6000000000068,58.49792144601635,0.12099406359547088,-3.4981199556044196
531.7000000000069,58.60679474088539,0.12122603432881751,-3.4981238538545436
532.8000000000068,58.71568260203922,0.12408659164528013,-3.4994409460597122
533.9000000000069,58.824257405606,0.12342788762284918,-3.5007608303609716
535.0000000000068,58.93251013200757,0.12385619962944067,-3.501738423906779
536.100000000007,59.04255484319301,0.12409526972372259,-3.50108865823156
537.2000000000069,59.15195892028833,0.12397428392330156,-3.5024799559073996
538.300000000007,59.26084609623044,0.12533091162330112,-3.5043834143818193
539.4000000000069,59.36966230703291,0.12633788736547297,-3.5057002082693676
540.5000000000069,59.47970606439774,0.12519120460997363,-3.5063348798588008
541.600000000007,59.588650284879215,0.1264233114034688,-3.5063598758369325
542.700000000007,59.69563779265637,0.12795791029328746,-3.508008592260195
543.800000000007,59.80745850122844,0.1280230235988164,-3.5080099296822067
544.900000000007,59.91788164464597,0.1282333871903043,-3.509330820122418
546.000000000007,60.02706260994969,0.12963875801405417,-3.5106534555129283
547.1000000000071,60.13655525027026,0.12984315838953048,-3.5120475278270415
548.2000000000071,60.24522233959328,0.12934815874081834,-3.5106400990112543
549.300000000007,60.35500855529322,0.1294427597065143,-3.511959792312451
550.4000000000071,60.46424785055825,0.13057478324677407,-3.512034821721255
551.500000000007,60.57397887801203,0.13279037984199166,-3.5138380486644936
552.6000000000072,60.68370618954741,0.12871864057933935,-3.513940054658775
553.7000000000071,60.79243197048222,0.13015790134284738,-3.515250568122995
554.8000000000072,60.90198026310681,0.12696482202623172,-3.517232367645759
555.9000000000071,61.01207923213242,0.12832729180966068,-3.5185523369028235
557.0000000000072,61.12108342842352,0.12930041561708905,-3.517886163823897
558.1000000000072,61.23033774427547,0.12734635209547213,-3.519209856239492
559.2000000000072,61.339723766654565,0.1265166986589002,-3.5205192855390415
560.3000000000072,61.44935030670585,0.1252531745178061,-3.521176237290505
561.4000000000073,61.55899178564524,0.12384681063968866,-3.5211797639398594
562.5000000000073,61.66597586278759,0.1228577733892055,-3.522500045710381
563.6000000000073,61.777931726951955,0.12226434512684187,-3.5225178162786177
564.7000000000073,61.88696604845606,0.1192584978669694,-3.5224998971154977
565.8000000000073,61.99612831001992,0.11855832424638424,-3.5238201406967136
566.9000000000074,62.1063282409432,0.12154674058808024,-3.523809332146576
568.0000000000074,62.21491178610682,0.12527812892161788,-3.525113624764149
569.1000000000074,62.32363112911532,0.12747356107307317,-3.525665854870499
570.2000000000073,62.43426076526463,0.12810004965464833,-3.5257608124330027
571.3000000000073,62.54245019539968,0.12695752614936662,-3.5264501938178507
572.4000000000074,62.65206820381336,0.1303892786733059,-3.5277573386552947
573.5000000000074,62.76203904000673,0.13018283664353086,-3.5277823698195783
574.6000000000074,62.87167012159962,0.13368426815645917,-3.5290898294055637
575.7000000000074,62.981242487897504,0.1321137749962642,-3.5290899350000453
576.8000000000075,63.09071676288376,0.13174613502822696,-3.5290899349990323
577.9000000000075,63.199694395320435,0.1336518238888823,-3.5290892119621473
579.0000000000075,63.308624507647366,0.13568849808286187,-3.5304098578931513
580.1000000000075,63.4185722601163,0.1378169307119616,-3.530401006597811
581.2000000000075,63.52778800916223,0.13670427696770127,-3.530398583139533
582.3000000000076,63.637159972001626,0.13800561300981545,-3.533040470524419
583.4000000000076,63.746167008764246,0.13905998463716168,-3.53306460460977
584.5000000000076,63.85532209508224,0.1406233660962728,-3.5343601089891687
585.6000000000076,63.964826850185915,0.1419370622364623,-3.5330339802640176
586.7000000000077,64.07359071496843,0.1404022138619463,-3.5343782085088487
587.8000000000077,64.18424748381099,0.14639357318491752,-3.5356698376232054
588.9000000000076,64.29249932098733,0.14058954211900748,-3.5356698380000045
590.0000000000076,64.40198596225315,0.14081765077716762,-3.535669807174209
591.1000000000076,64.51169101860044,0.14384923084697349,-3.5359999318299846
592.2000000000077,64.62135497821461,0.1410098405948848,-3.5359998629999305
593.3000000000077,64.7315390019816,0.14210050258696366,-3.5359998065415277
594.4000000000077,64.8399979111954,0.14460023437886815,-3.5369897530576044
595.5000000000077,64.95098389942443,0.14212691042709352,-3.5383100487136483
596.6000000000078,65.06048144174298,0.14222714133802128,-3.5379792889879473
597.7000000000078,65.17010240845363,0.14432283527174522,-3.5366604858480253
598.8000000000078,65.27719105795495,0.14184680569225872,-3.5392798989865737
599.9000000000078,65.38916454985774,0.13979601761439536,-3.5392901686410925
601.0000000000078,65.50113655555771,0.14066306091520553,-3.5400054180839122
602.1000000000079,65.60931853159036,0.1395439367302645,-3.5393005502327495
603.2000000000079,65.7201858591435,0.13852141802304618,-3.5419285536192384
604.3000000000079,65.82960422895832,0.13554198407167295,-3.5406099234134083
605.4000000000078,65.93705633520311,0.13504472397326528,-3.541576878866177
606.5000000000078,66.05032181907775,0.13268201043088684,-3.543242185725325
607.6000000000079,66.15901337619441,0.13056860237864293,-3.543239884004196
608.7000000000079,66.26819400582426,0.13134156570585348,-3.5432398184054383
609.8000000000079,66.37900210203009,0.13118421299217964,-3.5422583839706343
610.9000000000079,66.48954314969548,0.1298946517385675,-3.543580158269595
612.000000000008,66.5998996752321,0.12858680177925474,-3.544240126547123
613.100000000008,66.70958515609965,0.12678825239498076,-3.5442401199932343
614.200000000008,66.8196871758377,0.12824239904511303,-3.544258238952681
615.300000000008,66.92898324124901,0.12663737910432987,-3.5445706285344416
616.400000000008,67.03988946276729,0.12514400458758024,-3.5458807038187783
617.5000000000081,67.14970398889594,0.125159761200903,-3.545900218315209
618.6000000000081,67.26072156952348,0.12832917942270589,-3.5456086393417756
619.7000000000081,67.37011236909042,0.12513189101427774,-3.5475305426738206
620.8000000000081,67.48000104514655,0.12429143930005065,-3.5468823517397166
621.9000000000082,67.58951242154093,0.12324978458275526,-3.548187761895297
623.0000000000082,67.70087771572807,0.1218515556915174,-3.548189292542443
624.1000000000081,67.810913179201,0.12085366857581548,-3.5491801369414158
625.2000000000081,67.91990050682335,0.11803765403241234,-3.549180653446475
626.3000000000081,68.03009398373547,0.11809828738997097,-3.5508193703097595
627.4000000000082,68.14010529702227,0.12008138964776288,-3.5521460610265705
628.5000000000082,68.24858710753973,0.12162259916164497,-3.551499436071948
629.6000000000082,68.35878566769486,0.12096119367903985,-3.550434910451029
630.7000000000082,68.46870827523924,0.12006248558764443,-3.5518115194572752
631.8000000000083,68.57941834749052,0.11782377439697639,-3.5518101052107007
632.9000000000083,68.68834027162247,0.1183465545251342,-3.5527884221452215
634.0000000000083,68.79807761847543,0.11840242986326693,-3.552737766176236
635.1000000000083,68.90708822711889,0.11906747714521515,-3.5541099256485635
636.2000000000083,69.01758328857828,0.11660077134689412,-3.554127939691525
637.3000000000084,69.12778993622777,0.11456689469371517,-3.554780106526585
638.4000000000084,69.23714929009958,0.11441791840722437,-3.5547814550597714
639.5000000000084,69.34729360738483,0.11279751611683675,-3.5554314459454646
640.6000000000083,69.45842277728096,0.11223977436333216,-3.556750667032834
641.7000000000083,69.56805911293448,0.11136639423005801,-3.5580700677084254
642.8000000000084,69.6783305737768,0.10924657275468957,-3.5580698982227585
643.9000000000084,69.78768492935765,0.10848478615061391,-3.559241560835637
645.0000000000084,69.89820098723223,0.10650595984840083,-3.558730119166246
646.1000000000084,70.00809846213383,0.10448474716183193,-3.558730923471869
647.2000000000085,70.11823577744404,0.1020990656752725,-3.560050118128576
648.3000000000085,70.22801365131879,0.09892955470675202,-3.5600502387443775
649.4000000000085,70.33871258827257,0.09542653017770775,-3.5607188827762584
650.5000000000085,70.44749001088795,0.09159080852259616,-3.562048516200666
651.6000000000085,70.55898184620915,0.08744885876432867,-3.5620239137664464
652.7000000000086,70.6684096489545,0.08650449610820093,-3.5606998556225875
653.8000000000086,70.77835608616337,0.08187501229908117,-3.5610264524180995
654.9000000000086,70.8876388588523,0.07555111059190178,-3.561909016281976
656.0000000000086,70.99724498768943,0.07406734328299897,-3.560717358966313
657.1000000000087,71.10802331137471,0.07480452495767509,-3.562019989902912
658.2000000000087,71.21871055880172,0.07226798799321121,-3.562019921999982
659.3000000000086,71.32870783017748,0.07231962999942165,-3.562019909931851
660.4000000000086,71.43869471821004,0.06994565820534371,-3.5626677583602224
661.5000000000086,71.5490308294947,0.06621580071064248,-3.5620031760560327
662.6000000000087,71.65901134103592,0.06644738329063732,-3.563335396398405
663.7000000000087,71.76908172916629,0.06488296094773949,-3.5633401013366672
664.8000000000087,71.87814135816325,0.06260276959748884,-3.5646597740650576
665.9000000000087,71.98862910759631,0.06582027521204681,-3.5646559214565485
667.0000000000088,72.09803813964714,0.0689057721611056,-3.5659857391292737
668.1000000000088,72.20818148791457,0.0686790007656714,-3.564657232003883
669.2000000000088,72.31791076350208,0.07110624085606548,-3.5646359855301935
670.3000000000088,72.42805599384917,0.06960837193117336,-3.5646600970121325
671.4000000000088,72.53788607922496,0.06991138742276143,-3.564660408568664
672.5000000000089,72.64770380887038,0.07167081051796148,-3.565970192253846
673.6000000000089,72.75739404180419,0.07461780779703375,-3.565970064052963
674.7000000000089,72.86765732080093,0.07252704148722511,-3.5646635227086643
675.8000000000088,72.97917199598487,0.07513387604895383,-3.5646502025937186
676.9000000000088,73.08924278693752,0.07749311554706051,-3.5646502163825966
678.0000000000089,73.19930659001324,0.0794824377942368,-3.564980127231955
679.1000000000089,73.3103201590094,0.07954202567653962,-3.565970035938409
680.2000000000089,73.4206903340896,0.07783472821845938,-3.5659699327412455
681.3000000000089,73.53049673164396,0.08018881528323468,-3.5649797905494314
682.400000000009,73.64087949076394,0.07967472809846482,-3.5649801290045415
683.500000000009,73.75191669705009,0.08217964449567217,-3.5649617888362766
684.600000000009,73.85976212148691,0.08035908883292153,-3.5659698499631607
685.700000000009,73.9724906542558,0.08053843081544287,-3.5655841894320064
686.800000000009,74.08258705951319,0.0796562339765644,-3.564329946976377
687.9000000000091,74.19283878293736,0.08315045098410978,-3.565217676632032
689.0000000000091,74.30306011080266,0.08530285371224583,-3.5669605218319393
690.1000000000091,74.41328707418889,0.08312319886926856,-3.5669600679997604
691.2000000000091,74.52424607975642,0.08519907034168234,-3.5669600757740296
692.3000000000092,74.63511850168439,0.08536158885113804,-3.56696427983194
693.4000000000092,74.74570927072494,0.08525981926461107,-3.567503720832429
694.5000000000091,74.85439838915441,0.08531943311035761,-3.5682801179685537
695.6000000000091,74.96635626261983,0.08875203935982878,-3.5682801183945747
696.7000000000091,75.07800325124404,0.09266847812086787,-3.5695880102441535
697.8000000000092,75.18589493775275,0.09523637865579593,-3.5694534195252405
698.9000000000092,75.29883075479263,0.09644706130403174,-3.5682801430458793
700.0000000000092,75.409392707592,0.09761895863944925,-3.5682801430000284
701.1000000000092,75.52031877624084,0.09714085851179544,-3.568280090789849
702.2000000000093,75.63041931931899,0.10434329670881065,-3.567290393995166
703.3000000000093,75.74147387604494,0.10363964479054555,-3.56728933081585
704.4000000000093,75.85269708096584,0.10260660965597762,-3.56859986177098
705.5000000000093,75.96293242362748,0.1029346758425313,-3.5685998641970484
706.6000000000093,76.07332585371297,0.10384898980134832,-3.5699183317174823
707.7000000000094,76.18365191651174,0.1033684655251425,-3.5699192311935617
708.8000000000094,76.29419263826765,0.10266790901079359,-3.5695862276282635
709.9000000000094,76.40516429694009,0.10069790021662123,-3.570510078798509
711.0000000000093,76.51540872713917,0.10102257562954392,-3.5705957779634288
712.1000000000093,76.62675248182357,0.10272526369395629,-3.5692700381044835
713.2000000000094,76.73578661232813,0.10162578756237306,-3.5704712139644044
714.3000000000094,76.84726057178861,0.09857508830839556,-3.570590023480461
715.4000000000094,76.95734822860305,0.09857929750904892,-3.5718980865855228
716.5000000000094,77.06807520483267,0.1013828014082292,-3.5705900184303743
717.6000000000095,77.17938297451822,0.1009261441971746,-3.5692700139818623
718.7000000000095,77.2891208179776,0.10013256523399472,-3.57058134139578
719.8000000000095,77.40021584826843,0.10032518533857882,-3.5705800721894163
720.9000000000095,77.51084987304087,0.10429200370928915,-3.569215463854652
722.0000000000095,77.62166797173391,0.10333738427968586,-3.5705805496064738
723.1000000000096,77.73319808315678,0.10668217765276733,-3.5705198728228935
724.2000000000096,77.84330516518588,0.11037224196486983,-3.57190016420939
725.3000000000096,77.95347714249459,0.11351039960365816,-3.5719056990917983
726.4000000000096,78.06373716447362,0.12239828396959462,-3.5717834259931833
727.5000000000097,78.17504883415155,0.12983710752461863,-3.571904479242526
728.6000000000097,78.28631777145553,0.13555482377992378,-3.5711974556989134
729.7000000000096,78.39617630481756,0.15388463377751277,-3.5725613462015695
730.8000000000096,78.50623755001978,0.1932750162593252,-3.5732191684302537
731.9000000000096,78.6159908864876,0.21807151554469834,-3.5718998920306024
733.0000000000097,78.7259487244238,0.22971938556851373,-3.5718998918613494
734.1000000000097,78.83723205059563,0.23192550811200613,-3.572392921814888
735.2000000000097,78.94695383510121,0.23218072303039516,-3.5725891692443144
736.3000000000097,79.05774362214787,0.23842487020832281,-3.5728975839805823
737.4000000000098,79.16881386324611,0.24058670126754544,-3.572890231376168
738.5000000000098,79.27835279920252,0.24647119449959254,-3.572560182200322
739.6000000000098,79.38872810829471,0.24685495657840778,-3.5723396867423536
740.7000000000098,79.49875378360647,0.2504679396243774,-3.572890158444995
741.8000000000098,79.60889050651961,0.25022929270456173,-3.574170294505241
742.9000000000099,79.7195722183369,0.24955953026962396,-3.573845776327884
744.0000000000099,79.82980890253793,0.2535780342827406,-3.5724400673170296
745.0000000000099,79.93101520829984,0.2537219290202222,-3.5725598558859795