File: 01_Data/PU_Aerogel/STA/N2/10K_min/PU_Aerogel_STA_N2_10KData_230201_R1.csv
##Temp./Â°C,Time/min,DSC/(mW/mg),Mass loss/mg
50.0,10.873179885092936,0.05048268475573603,0.024361338850902747
51.100000000000016,11.188359617866396,0.07605798291112098,0.022322579835086565
52.20000000000003,11.417355830195534,0.09602945567606591,0.021470748962497233
53.30000000000005,11.61577833993147,0.10953606318304843,0.020285259759046603
54.40000000000006,11.79187675525564,0.11727493061609695,0.02030500546106584
55.50000000000008,11.963023824221326,0.13118017038486918,0.02082186567520594
56.600000000000094,12.118777835736728,0.13658652957949857,0.022435910142024618
57.70000000000011,12.270106359055266,0.14295073497049526,0.024043442977093044
58.800000000000125,12.416418616934047,0.14664057112514994,0.022852099494003575
59.90000000000014,12.559287043311869,0.15318829564671077,0.021633493325335706
61.000000000000156,12.699653733572084,0.15520854899430825,0.021349201171122267
62.10000000000017,12.83353723203239,0.16151982360707007,0.021068954008216068
63.20000000000019,12.968987563150044,0.1630474489152829,0.02305108217109275
64.30000000000021,13.101795409080777,0.17006894380384363,0.02205029999985264
65.40000000000022,13.231169825600661,0.1726395294297931,0.0221681283735089
66.50000000000023,13.361955440319495,0.17168386724498652,0.022171635839418613
67.60000000000025,13.490114912148602,0.17664445277608776,0.022031784151133493
68.70000000000027,13.61548137777475,0.17934106893978918,0.01967860550281575
69.80000000000028,13.739677271652793,0.18208736015828508,0.020373059351030953
70.90000000000029,13.863997589943388,0.1850742666594436,0.02087209476946228
72.00000000000031,13.988275949372952,0.1876994561828791,0.02084556233738244
73.10000000000034,14.108628149454324,0.18765019319629372,0.021741447467328534
74.20000000000034,14.229656012125261,0.18952511975240682,0.020855176429493305
75.30000000000035,14.350000000000037,0.19146120333579053,0.0222809497934211
76.40000000000038,14.469493407177108,0.19387105743903277,0.021589847331272338
77.5000000000004,14.587483266020056,0.19422349600243094,0.020961354061217463
78.6000000000004,14.706422273538122,0.19486718845614326,0.020966196219359468
79.70000000000041,14.822082101715015,0.19535687581077732,0.021504055640403585
80.80000000000044,14.939544810346927,0.1966049311837097,0.02279370327149266
81.90000000000046,15.054835733205554,0.1958306899138118,0.022302627547603926
83.00000000000047,15.167751743849458,0.19724900400712797,0.022311832778227902
84.10000000000048,15.284473970822864,0.19832779141947987,0.0208729067329676
85.2000000000005,15.396472669565252,0.20134771611426494,0.02095828083404072
86.30000000000052,15.51088616680774,0.20117271591157682,0.02093224146581729
87.40000000000053,15.623458998081022,0.20116444488823837,0.02227386595563008
88.50000000000054,15.735139341184986,0.20101237559371454,0.02233614108059534
89.60000000000056,15.846233897134782,0.20242401042419966,0.023599609451707693
90.70000000000059,15.95696551592145,0.20362498238507665,0.02360021563717929
91.8000000000006,16.06845433552218,0.20565451527730017,0.023538607925903676
92.9000000000006,16.17642514932872,0.20578227716387332,0.02492006684441872
94.00000000000063,16.287300980960197,0.20507202886557918,0.024910115668877353
95.10000000000065,16.397810365625,0.20616650321392593,0.02301606758494934
96.20000000000066,16.505880028034902,0.20663530842830113,0.022837069041895752
97.30000000000067,16.614501901735164,0.20955801441291133,0.02468522553532093
98.40000000000069,16.722869773847645,0.20741818274806945,0.026850022895904324
99.50000000000071,16.831101594240945,0.20755622519827355,0.025576063607459787
100.60000000000072,16.938977395395362,0.2087753616989686,0.02694983332478973
101.70000000000073,17.046933953310333,0.21003824325504772,0.02556654416991755
102.80000000000075,17.154694076989728,0.2102581788048551,0.024204292174951014
103.90000000000077,17.2627379360332,0.21247175633475013,0.024251064613616258
105.00000000000078,17.36855771163901,0.21292219425886394,0.02425996328460922
106.10000000000079,17.477156881145,0.2153852289500684,0.02422440885576993
107.20000000000081,17.580590353665983,0.21464454353932538,0.022910569907825362
108.30000000000084,17.69018956118783,0.21624520274603387,0.02295998261480303
109.40000000000084,17.796176055835733,0.21652159342406085,0.02333127679632785
110.50000000000085,17.904376144130428,0.215785777573961,0.024183303586357674
111.60000000000088,18.010102275096287,0.21814665650954546,0.02450264673133784
112.7000000000009,18.11762138945391,0.2203396496714609,0.022934794159458427
113.8000000000009,18.221555046973613,0.21909001445914233,0.025579669210381795
114.90000000000092,18.32701002217893,0.22162616553773906,0.026036154621472463
116.00000000000094,18.435938408962738,0.22347694628463033,0.024261687245588526
117.10000000000096,18.54191557628479,0.22241631949406382,0.022610392407104385
118.20000000000097,18.646546911477028,0.22532458124603116,0.02261072034687661
119.30000000000098,18.754995577810163,0.22514612064577488,0.022615472438112683
120.400000000001,18.86030713071485,0.2242227463995612,0.023929954092953842
121.50000000000102,18.966653618964536,0.22553488831805601,0.023793331794925265
122.60000000000103,19.072559062865547,0.22448887406615514,0.02386849654326273
123.70000000000104,19.178999221686773,0.22635756952223374,0.023962097667440396
124.80000000000106,19.284788583891928,0.22558832013603924,0.02392997995732493
125.90000000000109,19.390180569746708,0.2276255425321655,0.024143109222951153
127.0000000000011,19.495528767346713,0.2293116997298419,0.025254116113097247
128.1000000000011,19.602086615048258,0.23011185366772446,0.024850404351417055
129.20000000000113,19.706077421232774,0.23144404141978303,0.023598521031750863
130.30000000000115,19.810945044220382,0.23058364925929087,0.025580689325865436
131.40000000000117,19.916057940293435,0.23314742771720554,0.025579625302879272
132.50000000000117,20.020852556071407,0.2340324193433857,0.02494961183038935
133.6000000000012,20.12675300907316,0.23285539320697546,0.02363367688481599
134.7000000000012,20.229229039982542,0.23525327145772046,0.02445760948356046
135.8000000000012,20.335210582224526,0.23609862959023564,0.02623980041380669
136.90000000000123,20.44063573311742,0.23587857596984008,0.02755028437543139
138.00000000000125,20.54419400260128,0.23446529922774806,0.026344918386013383
139.10000000000127,20.648715518182176,0.23722221652266995,0.024917552346698457
140.2000000000013,20.753651310550133,0.23659791590615964,0.023574798832278532
141.3000000000013,20.858821650200348,0.23629667005102073,0.022280079419878973
142.4000000000013,20.961616400329863,0.24054745755172768,0.02360560385044863
143.50000000000134,21.06630731413861,0.2383554931335129,0.023598567174444973
144.60000000000133,21.170180181532416,0.23899378851761088,0.022279860002094587
145.70000000000135,21.27435997163279,0.24005017449269384,0.022876032968546234
146.80000000000138,21.379312610872706,0.2418174750007661,0.023067684808971478
147.9000000000014,21.48391602300961,0.23939236431508026,0.02359571038957231
149.00000000000142,21.586646737142118,0.24109652842637264,0.02486930515192931
150.10000000000142,21.69077808049246,0.24300479412931353,0.023586778962860322
151.20000000000144,21.7940956572834,0.2419391196970001,0.022279594518695767
152.30000000000146,21.898293992068805,0.24197008922210084,0.020958261691269797
153.40000000000146,22.002071139608613,0.24308069170795965,0.02228047267821953
154.50000000000148,22.10562516554247,0.24395835169463043,0.021294450387988384
155.6000000000015,22.20999905088397,0.24771935393177424,0.020309863172384368
156.70000000000152,22.312844112967884,0.24731682017104373,0.01999989122274215
157.80000000000155,22.416505372752955,0.2464748784513353,0.01998010860343058
158.90000000000154,22.520683024942947,0.24877677059445802,0.019980652273669186
160.00000000000156,22.62329896969221,0.24885797938679088,0.019980025767075027
161.1000000000016,22.72739138647502,0.249403284282965,0.01900824705308679
162.20000000000158,22.830663318307863,0.24978230660042744,0.018010065982340784
163.3000000000016,22.934565714287764,0.2504917715089705,0.01929718197502428
164.40000000000163,23.038750741055196,0.2514529215737812,0.01887417567621963
165.50000000000165,23.1411488585531,0.2532850699270113,0.01756021591915502
166.60000000000167,23.24451704074158,0.2518841919519952,0.018880425909459042
167.70000000000167,23.348653811442134,0.25227729700813395,0.01974599219300721
168.8000000000017,23.4530625435555,0.2559903587175383,0.02133444004031304
169.9000000000017,23.556698588599122,0.2542501936650299,0.020861692459812176
171.0000000000017,23.66000000000017,0.2549914243425153,0.020196729366466215
172.10000000000173,23.76506433824487,0.2576615656385247,0.018880196188139742
173.20000000000175,23.86736640793596,0.2574996325610046,0.01691307920314422
174.30000000000177,23.970276678879618,0.2594115292466005,0.01693809827671977
175.4000000000018,24.07267814567289,0.2583110059646351,0.01723020031935718
176.5000000000018,24.18020234755823,0.25863325988941555,0.01723079298045871
177.6000000000018,24.282872546318966,0.26092890650342626,0.01854875125757438
178.70000000000184,24.38742903857494,0.2595257490635231,0.016427344672054645
179.80000000000183,24.49050125097948,0.26000379160338827,0.01725451844250081
180.90000000000185,24.593569815561583,0.26204546511549276,0.01788931526012938
182.00000000000188,24.69395716630369,0.2598145656389541,0.019209589383315517
183.1000000000019,24.800820069046264,0.2623951798729113,0.018284045646075775
184.20000000000192,24.903600881459813,0.2644842524271721,0.016789867067219966
185.30000000000192,25.007261479051053,0.2651255692855129,0.014774099776072802
186.40000000000194,25.110803502635886,0.2674319523559966,0.01416000001801443
187.50000000000196,25.21360631231466,0.265937481208677,0.014160000000042139
188.60000000000196,25.316932811220116,0.2661820095579368,0.014159954484124881
189.70000000000198,25.421549399713964,0.2674176094127426,0.013169331234471393
190.800000000002,25.523548146672482,0.26791996883635794,0.012839959637259923
191.90000000000202,25.627355655706783,0.2698583710959457,0.012839256558190293
193.00000000000205,25.731134849062155,0.27117620774716555,0.011519829638414691
194.10000000000204,25.835242198814257,0.2728363618264965,0.011520000000053265
195.20000000000206,25.937603902063568,0.2726922391125989,0.011519938198419233
196.3000000000021,26.04112320703949,0.2759176940009216,0.010198693029261463
197.40000000000208,26.144887373793566,0.2795117318053949,0.008895919676271014
198.5000000000021,26.247270120988173,0.2784051344032349,0.007580240821607909
199.60000000000213,26.348892980582843,0.2832359113938262,0.006557188730510255
200.70000000000215,26.454163622658236,0.283453321132781,0.008876937383749173
201.80000000000217,26.557836572933684,0.2834110404116442,0.007611818950189253
202.90000000000217,26.66131940440431,0.28800974615429653,0.006580181055662493
204.0000000000022,26.764696537668268,0.28825465187414834,0.006145703419928594
205.1000000000022,26.867180540359012,0.2912210255192335,0.006259292552502238
206.2000000000022,26.971760110516016,0.2953361468871788,0.004940220040156262
207.30000000000223,27.074745402728976,0.2985073534225344,0.0036161824072182824
208.40000000000225,27.17562996342585,0.3016061122622254,0.0009815024481234502
209.50000000000227,27.280920886006584,0.30717099141918497,0.002306445322739492
210.6000000000023,27.385283162415167,0.3113299076098097,0.0022998771383679895
211.7000000000023,27.486708981872336,0.3149059429951333,0.0008421245893437401
212.8000000000023,27.59315020084148,0.3248319826737639,-0.0003078666504583438
213.90000000000234,27.696244054702397,0.333219200484595,-0.003056573732415302
215.00000000000233,27.799338750095593,0.3422763261641868,-0.004390139752874056
216.10000000000235,27.903424120943033,0.35305961601153746,-0.005711369152590073
217.20000000000238,28.007051844270123,0.3646472457468043,-0.006462207274138265
218.3000000000024,28.10963789633655,0.3827765118672406,-0.009701463124002885
219.40000000000242,28.214844274324765,0.3996729777460992,-0.01130398957480594
220.50000000000242,28.317820318415905,0.4169972525800497,-0.013291395077290602
221.60000000000244,28.422036249075592,0.43710084566703333,-0.014598812722198318
222.70000000000246,28.525635319126657,0.4625643379520641,-0.017890025018506783
223.80000000000246,28.629186054246176,0.48406937879368284,-0.023258361155869878
224.90000000000248,28.732657100770627,0.5118475384768698,-0.02328622859218843
226.0000000000025,28.837406088245032,0.5375054530390583,-0.02622618092959783
227.10000000000252,28.941213480691058,0.5634083546354469,-0.029103019856871803
228.20000000000255,29.044738353026858,0.5880952792987206,-0.032959786763054666
229.30000000000254,29.149749287618345,0.6143015144761956,-0.03643521285241835
230.40000000000256,29.254104682512953,0.6360747089563487,-0.042358361811953404
231.5000000000026,29.357136075525112,0.655886403563297,-0.04651084297466568
232.60000000000258,29.46178684272005,0.6733014200374497,-0.05282286516874857
233.7000000000026,29.564902478786266,0.6893465416533313,-0.060531146049076945
234.80000000000263,29.6692104125036,0.6990044432315443,-0.06679339211989355
235.90000000000265,29.772938924097314,0.7105803040299061,-0.07186109616643499
237.00000000000267,29.877519513037555,0.7174020567466463,-0.07736287608253711
238.10000000000267,29.981655815003432,0.7213126543209036,-0.08349526970684407
239.2000000000027,30.08569364234799,0.7259179099904608,-0.09169016232380889
240.3000000000027,30.189810093490504,0.7280510686261401,-0.09934998253806837
241.4000000000027,30.293380246569008,0.7313076971932602,-0.10652248266441644
242.50000000000273,30.398400257352876,0.732627473889329,-0.1155970680895444
243.60000000000275,30.502103140180076,0.7351069851655728,-0.1266449383009456
244.70000000000277,30.60698894062482,0.7388469552021572,-0.136352632403538
245.8000000000028,30.710487573843043,0.7411811537079511,-0.14731628441088995
246.9000000000028,30.814826371141134,0.7437842985368128,-0.160266465435702
248.0000000000028,30.919441498749634,0.7479056851849385,-0.17030770241274862
249.10000000000284,31.02363798841976,0.7512444438015891,-0.18423200355590108
250.20000000000283,31.127922855189777,0.7550657505343795,-0.19714991803081627
251.30000000000285,31.23246244932356,0.7610139976555483,-0.21004119705102875
252.40000000000288,31.337452148794675,0.763354831737056,-0.22473723898346076
253.5000000000029,31.440763945586518,0.7695368103950103,-0.23936883954996624
254.60000000000292,31.545317317045594,0.7755563221734458,-0.25514893056596755
255.70000000000292,31.649511414679466,0.7780336021502932,-0.2703430231691928
256.8000000000029,31.753543955607327,0.7825263982524294,-0.2880361275275387
257.90000000000293,31.857939860023862,0.7834614076253706,-0.3041475654690009
259.00000000000296,31.961002408678272,0.7852764605636732,-0.32299783808622395
260.100000000003,32.06510968123021,0.7836304086125514,-0.3415659955230037
261.200000000003,32.169125556387186,0.7813061945299287,-0.3606678570748403
262.300000000003,32.27401578841516,0.7791270806868352,-0.38127845720392406
263.40000000000305,32.3782351909547,0.7712982283256211,-0.3996556844471546
264.50000000000307,32.482259457430025,0.7668179010825467,-0.4201197822278533
265.6000000000031,32.58640947460903,0.7567890246241735,-0.4386131648817351
266.7000000000031,32.690470515814354,0.7479744558578406,-0.4607675993366023
267.8000000000031,32.79465569307426,0.7354444971435558,-0.4826262530967216
268.9000000000031,32.89875446291166,0.7209189413428685,-0.5046750601610621
270.0000000000031,33.00271710869623,0.7047094515532628,-0.5224193016984882
271.10000000000315,33.106775010397534,0.6875312690698507,-0.5398057787173212
272.2000000000032,33.21207086027827,0.669154484657505,-0.5609191801634594
273.30000000000314,33.31688715177821,0.6482854510153317,-0.5813502428644841
274.40000000000316,33.42103541976149,0.6287093211891959,-0.5994944694659021
275.5000000000032,33.5243845690094,0.6045941832742708,-0.6177856802564334
276.6000000000032,33.62999894491182,0.5826879179532996,-0.6370696515942504
277.70000000000323,33.73239732543757,0.562639509174284,-0.6524607772679545
278.80000000000325,33.83706777829258,0.5410402144655975,-0.6689400503189407
279.9000000000033,33.94114528890206,0.5214688256761337,-0.6812382712275511
281.0000000000033,34.04364223422965,0.5040782310896874,-0.6933039516019459
282.1000000000033,34.15008443854777,0.48767111373315236,-0.7061373957457739
283.20000000000334,34.254024427979985,0.4719180632056928,-0.7177873701576951
284.30000000000337,34.356005642002444,0.4603700889117423,-0.7295232719943381
285.40000000000333,34.463038008366404,0.4506098792880282,-0.7399584226512519
286.50000000000335,34.568082733012446,0.44269312744537037,-0.750443591372
287.6000000000034,34.67085879414809,0.43600038740774383,-0.7591445256293836
288.7000000000034,34.775736587049806,0.431964552782341,-0.7694708572150781
289.8000000000034,34.88037664482751,0.42679235612955924,-0.7771824863255512
290.9000000000034,34.98416147258181,0.42686055221437513,-0.7858297979366329
292.0000000000034,35.08833639885938,0.4247453632808949,-0.7952396623905367
293.10000000000343,35.19323400892221,0.42641301880034177,-0.806135095579803
294.20000000000346,35.2982612090855,0.4273417818053212,-0.8135203623942178
295.3000000000035,35.40098249930263,0.4270662695067719,-0.8227593708918124
296.4000000000035,35.50693039666459,0.430494106221234,-0.8313830421807036
297.5000000000035,35.61107168550916,0.43183067151446586,-0.8376718528805362
298.60000000000355,35.7165519208909,0.4338873180969115,-0.8456332480697251
299.70000000000357,35.821702863031696,0.43813720039019555,-0.8519652301339296
300.8000000000036,35.92638588162839,0.4417675205135798,-0.8601663144868317
301.9000000000036,36.03062868615272,0.4457708119319269,-0.8640391718835585
303.0000000000036,36.136114772849716,0.4526316602521471,-0.8706524052676881
304.1000000000036,36.24074278046868,0.4558568815402356,-0.8773142602385011
305.2000000000036,36.3466459860715,0.46344497520134675,-0.884238797953639
306.30000000000365,36.45128072678129,0.46986616249654284,-0.8918658502701788
307.4000000000037,36.5560035733824,0.47531912375740826,-0.8995755772922305
308.5000000000037,36.66090465573705,0.4799496490901226,-0.9078069067993111
309.60000000000366,36.766671503084865,0.48750930708027856,-0.913607155005546
310.7000000000037,36.871158308540004,0.49384057194623426,-0.9199587433163425
311.8000000000037,36.97585559994133,0.49870043779855744,-0.9288599737964471
312.90000000000373,37.080946365254405,0.5053360931915928,-0.9356905343615214
314.00000000000375,37.18696629620747,0.5103005731523579,-0.9415527197358635
315.1000000000038,37.29124213683579,0.513561598502473,-0.9516460402508278
316.2000000000038,37.3967401623233,0.5210648215552709,-0.9612883718481386
317.3000000000038,37.50180324142282,0.5264055409471403,-0.9698539702185238
318.40000000000384,37.60665963152335,0.5311500497261289,-0.9795691927465606
319.5000000000038,37.71158109499696,0.5346778880019649,-0.9876137705529278
320.60000000000383,37.81835316321307,0.5402126259752263,-0.9960429328475673
321.70000000000385,37.92349739435506,0.5439177311586146,-1.0082337746877452
322.8000000000039,38.02804055175122,0.546710164439651,-1.0177204018040165
323.9000000000039,38.13279977676277,0.5500977042904972,-1.0271286633610504
325.0000000000039,38.238603142924376,0.5511783017727592,-1.0359013580945127
326.10000000000394,38.34403357375347,0.5519888596552756,-1.0444702503988985
327.2000000000039,38.44952600647734,0.5536891671203312,-1.0560749095371373
328.30000000000393,38.55504976466604,0.5545490163049015,-1.0683773985934684
329.40000000000396,38.65944524734499,0.5537694812315692,-1.0784704320185199
330.500000000004,38.76608029893511,0.5537595665597,-1.0901022139274397
331.600000000004,38.87008179125803,0.5528230281524037,-1.1003454976770053
332.700000000004,38.974086374548286,0.5477261007915144,-1.110954943898553
333.80000000000405,39.081079398931905,0.5438458943540144,-1.1241924897886886
334.90000000000407,39.1868868912813,0.53581479904085,-1.1378588672839554
336.0000000000041,39.29220874082455,0.5289442515433063,-1.1500078425198992
337.10000000000406,39.39849854976622,0.5204427502747668,-1.1613551258727433
338.2000000000041,39.50472788801425,0.5122618187296545,-1.1721687189685484
339.3000000000041,39.610595383665824,0.5046732911464046,-1.1854026394180002
340.4000000000041,39.71577775375624,0.4988575568258615,-1.197795158305218
341.50000000000415,39.821598643833724,0.4913466742946098,-1.2089188938274016
342.6000000000042,39.92763213666835,0.4842580752686771,-1.2220981128144301
343.7000000000042,40.030758203650976,0.4801996595377235,-1.2335149212704568
344.80000000000416,40.13776488720095,0.4710819995053265,-1.2454779514828291
345.9000000000042,40.24276556583048,0.4631662424289023,-1.26064238788052
347.0000000000042,40.35081068644235,0.45437911974695394,-1.274335927118321
348.10000000000423,40.45717080361506,0.44768631225767924,-1.2849037506485934
349.20000000000425,40.56292041304983,0.4396934112284216,-1.2967393703835546
350.3000000000043,40.666436935738275,0.430368761477935,-1.3094823703307825
351.4000000000043,40.77375572803569,0.4197887996082401,-1.3216261515337715
352.5000000000043,40.881220422807296,0.40866641667639514,-1.334324976397911
353.60000000000434,40.98639386018222,0.3984435404016559,-1.3426291410204239
354.7000000000043,41.09135953618191,0.388487890564623,-1.3552290595031344
355.80000000000433,41.198663865948475,0.37518336840163613,-1.3679658056314263
356.90000000000435,41.30383766264934,0.3629592057648507,-1.3785728505000705
358.0000000000044,41.41037996611928,0.35038534333167637,-1.3911990423708849
359.1000000000044,41.51761500910857,0.3383040978486233,-1.4011412950581885
360.2000000000044,41.62283707202574,0.3237083662357062,-1.4107363411057952
361.30000000000445,41.728945265208175,0.3132652954963874,-1.4204901903932812
362.4000000000044,41.834697696789455,0.2996414994284736,-1.4312530673723702
363.50000000000443,41.94045731353931,0.28988937912976065,-1.4389739937055412
364.60000000000446,42.046300299213044,0.2776372473611325,-1.4487671276015766
365.7000000000045,42.15300122925877,0.26732774584622293,-1.457675467861527
366.8000000000045,42.25865189930576,0.2581094782030589,-1.4660481440389792
367.9000000000045,42.3646942064112,0.24643665936031248,-1.4744644253612496
369.00000000000455,42.47081856996934,0.23895233600782145,-1.4795196133170343
370.10000000000457,42.577208972647256,0.2297795907748177,-1.4878309356254267
371.2000000000046,42.68319415164535,0.2227557315656961,-1.4973180932395058
372.30000000000456,42.78945036889481,0.21319875592091148,-1.504556348393482
373.4000000000046,42.89518294100557,0.20670592051146194,-1.511564801272283
374.5000000000046,43.00109202392591,0.1991179367343481,-1.517741964119041
375.6000000000046,43.10723052300185,0.19202304782379936,-1.5251052040204653
376.70000000000465,43.214851061098734,0.18528356843557797,-1.5322260220222863
377.8000000000047,43.32019373416216,0.17904000280173338,-1.5381879472652975
378.9000000000047,43.4260740346006,0.17317305606289213,-1.5456532809869792
380.00000000000466,43.53282629380893,0.16393556854317354,-1.5513405140024537
381.1000000000047,43.63873865312676,0.15886633385990728,-1.5592545442289985
382.2000000000047,43.744378486997576,0.15184499040278032,-1.5673529183037802
383.30000000000473,43.85047174633026,0.14688092065584324,-1.5744426572417214
384.40000000000475,43.95674414237228,0.14320421362086427,-1.5811024185606173
385.5000000000048,44.063525051934924,0.1367516358482151,-1.5880215067259322
386.6000000000048,44.169398075839254,0.1340209443136332,-1.5967834716070453
387.7000000000048,44.27698955544612,0.12852596206252365,-1.603229178260548
388.80000000000484,44.38236882111751,0.12412041205319196,-1.6101431081760937
389.9000000000048,44.48959059745071,0.12045000602232936,-1.618373610684639
391.00000000000483,44.59549891249961,0.11655582525759511,-1.6274977584611974
392.10000000000485,44.70277772461785,0.11400091298316828,-1.6342633176235672
393.2000000000049,44.8087663724901,0.11263532096427842,-1.6427736197642022
394.3000000000049,44.91444570459467,0.11191196884766313,-1.6502031737174057
395.4000000000049,45.021561035082094,0.10784706181511894,-1.6568270438634545
396.50000000000495,45.12904595396557,0.11246216023446076,-1.6669554822892665
397.6000000000049,45.235142128447656,0.11308691622629641,-1.676513160325758
398.70000000000493,45.34025687025817,0.11223010118963911,-1.6860523039009285
399.80000000000496,45.448303179919215,0.11470140209381302,-1.6915564715249207
400.900000000005,45.55404701139523,0.1170654644582671,-1.6986235568022807
402.000000000005,45.66200560004851,0.11826444030187538,-1.707395804808225
403.100000000005,45.76788051305499,0.12219003976393705,-1.7155012900254563
404.20000000000505,45.87542469119545,0.12749030394954258,-1.725421831943501
405.30000000000507,45.98248064245624,0.13239805986837216,-1.733759885221283
406.4000000000051,46.09010163840075,0.13594077296467877,-1.7452393566819908
407.50000000000506,46.19598366357301,0.1437231419435817,-1.7525443486029029
408.6000000000051,46.30393924361038,0.1484379652489764,-1.7620128294958017
409.7000000000051,46.40920476180162,0.15622430904307077,-1.7719496130862886
410.8000000000051,46.51839617156455,0.15922125039266072,-1.7784615487815167
411.90000000000515,46.62575833620708,0.16467790714307118,-1.7891822984609003
413.0000000000052,46.73031982910587,0.170288502859191,-1.7973882500819354
414.1000000000052,46.83905885510657,0.17649020336645324,-1.8078642996798422
415.20000000000516,46.94692854743701,0.1822775553999587,-1.8164022451953201
416.3000000000052,47.054640524502304,0.18878553733685793,-1.8254658491340994
417.4000000000052,47.16236420794408,0.1915788338503254,-1.8300404411570277
418.50000000000523,47.26883384708287,0.1982582283501133,-1.8386260344311434
419.60000000000525,47.3766924008015,0.20119476622331361,-1.8491809678134352
420.7000000000053,47.484443558583095,0.20330291241581702,-1.8601514443706542
421.8000000000053,47.59307527061728,0.20930439480435764,-1.8694712883101543
422.9000000000053,47.70018591697515,0.2146024828466268,-1.8780789112396876
424.00000000000534,47.808116269206636,0.21863311402109856,-1.8883721497331556
425.1000000000053,47.91574708515006,0.22164799419659698,-1.8955705287532223
426.20000000000533,48.023714348416085,0.22704252922691567,-1.9019570195652733
427.30000000000535,48.13115585436787,0.22703750000263823,-1.91037161791392
428.4000000000054,48.237933872151,0.23192073627731763,-1.9198651664558821
429.5000000000054,48.34612569060914,0.2363202378899256,-1.929974245337431
430.6000000000054,48.45428328178567,0.23605892407081575,-1.93895964423626
431.70000000000545,48.56065752972032,0.24042518401227583,-1.9461937664524163
432.8000000000054,48.66931726028778,0.2424356897208028,-1.954613127511157
433.90000000000543,48.77555704536919,0.24448741034389546,-1.9642400495786987
435.00000000000546,48.8846513677588,0.24508425736605968,-1.9722851038889888
436.1000000000055,48.992650388648485,0.244851518894774,-1.9778172368230424
437.2000000000055,49.09873638721889,0.24753360507251237,-1.9847607677478627
438.3000000000055,49.206692022441004,0.24767716767575493,-1.992514890235726
439.40000000000555,49.314566450878125,0.24853215779941923,-2.0003250205886642
440.50000000000557,49.42212158961976,0.2485306629915897,-2.010609548058367
441.6000000000056,49.52952660497612,0.2487059887104282,-2.0176558863582605
442.70000000000556,49.63715705096057,0.252755277380905,-2.0261166297976456
443.8000000000056,49.74572372173967,0.25064984211113395,-2.033198104195046
444.9000000000056,49.85357371203551,0.25327238727227147,-2.0409612484640505
446.0000000000056,49.96104601471048,0.25195389773085286,-2.0494159506390477
447.10000000000565,50.06934304916519,0.2538005651207771,-2.057279691872208
448.2000000000057,50.1779095567717,0.2534201986978358,-2.0650180733182086
449.3000000000057,50.28598695913643,0.2525408200733517,-2.070555388972013
450.40000000000566,50.394000392535496,0.25176785336890406,-2.0761298308412766
451.5000000000057,50.501677269110395,0.2534896412226733,-2.082172077875395
452.6000000000057,50.60980731315621,0.2531740786828562,-2.0922391992452023
453.70000000000573,50.717361694150746,0.25310497627673056,-2.0979042753537493
454.80000000000575,50.82568028540345,0.2505363627053145,-2.104691267753291
455.9000000000058,50.933609327545575,0.2521401577437778,-2.1111286882329523
457.0000000000058,51.0405230804497,0.25265049673281714,-2.117549315751198
458.1000000000058,51.14770833875323,0.2521437805175623,-2.124212037606215
459.20000000000584,51.2580444853542,0.2535160101922368,-2.1324915474050608
460.3000000000058,51.36590229772255,0.25441423263272994,-2.141463803216662
461.40000000000583,51.474954058935786,0.2554179883670228,-2.1493534364331452
462.50000000000585,51.583441209385796,0.25492134667214456,-2.1543353640748046
463.6000000000059,51.69056761876984,0.25615864842155855,-2.1597234615390315
464.7000000000059,51.79897712740201,0.25778992254584554,-2.1651706529046164
465.8000000000059,51.907412814247856,0.25952868487154424,-2.171929378226643
466.90000000000595,52.015071198985794,0.2586212263208634,-2.1789855561735174
468.0000000000059,52.12319366844845,0.258945072550294,-2.185313036498038
469.10000000000593,52.23108067689219,0.256885140000271,-2.1915579480956993
470.20000000000596,52.339285711377364,0.256668864377927,-2.1976766131269945
471.300000000006,52.446880956319305,0.25681813560127853,-2.205611527869953
472.400000000006,52.554933892735775,0.2565420312127305,-2.2132603389229337
473.500000000006,52.66252852856314,0.2569323250022189,-2.2196856856603437
474.60000000000605,52.771579156169445,0.25570992745604315,-2.226326024662071
475.70000000000607,52.879708462943825,0.25798657834851724,-2.232987754005642
476.8000000000061,52.986995045082466,0.2567295124290149,-2.2409369219470485
477.90000000000606,53.09533407877015,0.25464205031692877,-2.2482948239434886
479.0000000000061,53.20368646470937,0.25492647616462555,-2.253745563267759
480.1000000000061,53.31066264916974,0.25256586312534995,-2.2594959223458475
481.2000000000061,53.41891249014387,0.25163189761816934,-2.2686739068542257
482.30000000000615,53.52681115397328,0.2529740925702913,-2.2747305925538344
483.4000000000062,53.635092634513086,0.25026710088548015,-2.282041996012413
484.5000000000062,53.74324097429053,0.25037972080428494,-2.291645083789699
485.60000000000616,53.85186797144035,0.24838568598841776,-2.2985754930989577
486.7000000000062,53.96057501143842,0.2469893894316389,-2.3046878559876176
487.8000000000062,54.069477617778,0.24500432358188512,-2.314108658589951
488.90000000000623,54.17777540826307,0.245836689706605,-2.321939125560454
490.00000000000625,54.2865729151989,0.24441990040924835,-2.329294419335791
491.1000000000063,54.395623240408,0.24065069517449372,-2.337713978268563
492.2000000000063,54.50227149206963,0.24138318049238594,-2.3457280963563596
493.3000000000063,54.61233342047913,0.23974608153636318,-2.352698259289811
494.40000000000634,54.720001005457014,0.23888605749064581,-2.3605623626016032
495.5000000000063,54.82791203984613,0.23656756499272422,-2.3661042997290043
496.60000000000633,54.93766804988975,0.23699139907597228,-2.3750344670939953
497.70000000000636,55.04234912297826,0.23643385284955276,-2.3826294582795766
498.8000000000064,55.15193417326652,0.23341672998512483,-2.390081511675382
499.9000000000064,55.262064619674916,0.23231251608605524,-2.3971665325197966
501.0000000000064,55.371320957291125,0.23204453025122185,-2.4078021200532
502.10000000000645,55.47882986061788,0.23240818204392988,-2.415581040978932
503.2000000000064,55.58792973138427,0.23262843967304275,-2.4223957551122712
504.30000000000643,55.69538239697434,0.23145985026817303,-2.429302275358829
505.40000000000646,55.80480643328196,0.23178553583878586,-2.4349564061102473
506.5000000000065,55.91305087225542,0.22947524133469122,-2.4415976790532197
507.6000000000065,56.021164334516214,0.2302590335405077,-2.4515489527559584
508.7000000000065,56.13010138412952,0.22857097568399487,-2.4559873613238716
509.80000000000655,56.237216905640814,0.22756163129260398,-2.4610275353115667
510.90000000000657,56.347894327290845,0.22701923844582178,-2.4705203707543535
512.0000000000066,56.45628293232839,0.2265608061367513,-2.478221660330987
513.1000000000065,56.565417309603,0.22488117707324537,-2.483974265538198
514.2000000000066,56.673461344787164,0.22534556960800134,-2.4905192667362637
515.3000000000065,56.78143299354994,0.22184619278438336,-2.498348301156291
516.4000000000067,56.891343007267174,0.22164638554997818,-2.504721273109777
517.5000000000066,56.999580267659574,0.21991066878797047,-2.510511681045582
518.6000000000067,57.10761936266131,0.2190789098718514,-2.5149015654935147
519.7000000000066,57.21570743060463,0.21901169699100453,-2.5212606686198527
520.8000000000067,57.32601626036062,0.21848852080046754,-2.5278001588520422
521.9000000000067,57.435810243668634,0.21695431513874522,-2.5333786986989724
523.0000000000067,57.54456159885171,0.22149056346960969,-2.539353654732354
524.1000000000067,57.65258349436125,0.22115739520165023,-2.5442977362046353
525.2000000000068,57.761944621283945,0.2202790780030146,-2.551018047911124
526.3000000000068,57.87097038310226,0.21952304247169188,-2.5567711547058165
527.4000000000068,57.979556154517866,0.21976795241880792,-2.563229008521856
528.5000000000068,58.08879425368424,0.21647605815311566,-2.5676610166895824
529.6000000000068,58.19842119222325,0.21768240746127235,-2.572222351488692
530.7000000000069,58.30728185313781,0.21670064545976056,-2.5792126431035802
531.8000000000068,58.415781314344976,0.21567900572833462,-2.5855782014751156
532.9000000000069,58.52310393838936,0.21487017228813762,-2.588647758181688
534.0000000000068,58.63362467259192,0.2123245888313435,-2.596255070543752
535.100000000007,58.74258929033299,0.21499492206575546,-2.601700312301337
536.2000000000069,58.851275704005225,0.21274983130328565,-2.605470546425132
537.300000000007,58.960411511184844,0.21172426672573386,-2.609485883258405
538.4000000000069,59.0684548087022,0.2113346061524828,-2.6144085197403255
539.5000000000069,59.179009888430166,0.21165036664520065,-2.6184687459813594
540.600000000007,59.28828705296329,0.20860443808243423,-2.622976769860905
541.700000000007,59.396270015543216,0.21015327527491215,-2.628628926058955
542.800000000007,59.505569843296634,0.20814809672350476,-2.6317158277273194
543.900000000007,59.61519794387116,0.20595336032657846,-2.63516629927238
545.000000000007,59.72397052116283,0.20836429535886491,-2.640357080708683
546.1000000000071,59.83437484779747,0.20736781053368838,-2.644934716406167
547.2000000000071,59.94398316175409,0.2086002821186073,-2.649073715451838
548.300000000007,60.05185245436097,0.20639334520330663,-2.6533373839228593
549.4000000000071,60.161433309896125,0.2070892336886548,-2.656203976082434
550.500000000007,60.271108649795494,0.20809377020518266,-2.6575712709085035
551.6000000000072,60.380001928367776,0.2069542026037354,-2.6618101318321403
552.7000000000071,60.48881437241134,0.20322767170813502,-2.6678360084573396
553.8000000000072,60.598643843772784,0.20654635096395296,-2.671818527508341
554.9000000000071,60.708262131507134,0.20253664634845042,-2.6741927810014205
556.0000000000072,60.817180570543414,0.20373792813726327,-2.676410634335455
557.1000000000072,60.927453946987015,0.20235643102480788,-2.6787857851176584
558.2000000000072,61.037044096465806,0.20298760618012412,-2.682262295301053
559.3000000000072,61.14600092506669,0.20012281662817522,-2.6863802310461042
560.4000000000073,61.25464218014717,0.19930055081913073,-2.688240353949642
561.5000000000073,61.36443084437133,0.20108007507715794,-2.689794697951448
562.6000000000073,61.47375896570172,0.1997659252645517,-2.693420679911666
563.7000000000073,61.58290652791314,0.19694445854617174,-2.695864569868414
564.8000000000073,61.69191989141143,0.19817127449763566,-2.698006227935692
565.9000000000074,61.80173342481708,0.19968503929871917,-2.7032843830706077
567.0000000000074,61.91145704250977,0.19909945080527736,-2.7088885675558254
568.1000000000074,62.020110307411194,0.2016164815234829,-2.7109888704861103
569.2000000000073,62.12940377753688,0.19943249975396649,-2.7142900258994445
570.3000000000073,62.238301962714374,0.20245311054240553,-2.7169306440833756
571.4000000000074,62.34783846580896,0.20193712412699938,-2.721270702077424
572.5000000000074,62.45606397708335,0.2019520971543108,-2.7225296934326515
573.6000000000074,62.566089513903755,0.20370880132800162,-2.7265091671450676
574.7000000000074,62.67545250552721,0.20413343868767903,-2.7278506791549377
575.8000000000075,62.78488548971585,0.20270388542885828,-2.7305958206548273
576.9000000000075,62.89429822237283,0.20496090250548926,-2.7321762388299167
578.0000000000075,63.00398799224511,0.2057479714249375,-2.736226615050395
579.1000000000075,63.113232683505615,0.20612169083627702,-2.7361633661085447
580.2000000000075,63.22242597271366,0.20666501329569165,-2.7390933560115993
581.3000000000076,63.332429408864016,0.20706120587981608,-2.7431540384783992
582.4000000000076,63.442097323989906,0.20624585593486697,-2.745944191668631
583.5000000000076,63.55141698946434,0.20801845220764165,-2.7485379196137627
584.6000000000076,63.66174173497334,0.20863784653585496,-2.7498471029525455
585.7000000000077,63.77119532368182,0.2098606992810874,-2.7525989648813693
586.8000000000077,63.8802233062018,0.20898969657405272,-2.7539265481676836
587.9000000000076,63.98981828256203,0.21058229021026487,-2.757194144386967
589.0000000000076,64.0985300058794,0.2147518941036661,-2.757870924417713
590.1000000000076,64.20881309369047,0.2128060098622167,-2.7581995529603773
591.2000000000077,64.319289769337,0.21752164107635374,-2.760781760518822
592.3000000000077,64.4280022040439,0.2199597957462833,-2.760904630707301
593.4000000000077,64.53776433893238,0.2195770309171363,-2.7647853216870253
594.5000000000077,64.64767254934728,0.21901121003488686,-2.76477964589727
595.6000000000078,64.75761220615948,0.22038197548526872,-2.7660001157851823
596.7000000000078,64.86828797334458,0.21880773273133183,-2.767420279616906
597.8000000000078,64.97785132255842,0.22108294919206534,-2.768213349462841
598.9000000000078,65.08753917979433,0.22277221215095483,-2.7698691773441064
600.0000000000078,65.19799304166257,0.22310331504667824,-2.7726041972982802
601.1000000000079,65.3077472276441,0.22038164943887434,-2.7740503554813456
602.2000000000079,65.41658647792997,0.22455720006928448,-2.7761946747576465
603.3000000000079,65.52470566319239,0.22671416800323133,-2.777412391640979
604.4000000000078,65.63629612197562,0.2295392370363946,-2.778876547970494
605.5000000000078,65.74507539223754,0.22841549594042876,-2.779755385285893
606.6000000000079,65.85334314662506,0.2336924777921588,-2.778176742787144
607.7000000000079,65.96416868458317,0.2300907842609444,-2.780858308120997
608.8000000000079,66.07439686015299,0.23149525737781693,-2.7821398752386273
609.9000000000079,66.18328822960085,0.23025166789231655,-2.7808558004833426
611.000000000008,66.2924662665654,0.23234264272490227,-2.783447973645628
612.100000000008,66.40162447988155,0.23551370376141073,-2.7834646322726346
613.200000000008,66.51098750423364,0.23698265307878805,-2.786235466279136
614.300000000008,66.61980604851647,0.23856898952951464,-2.787504166004773
615.400000000008,66.73021173366138,0.24167030991985927,-2.78883006362426
616.5000000000081,66.8369405104276,0.24390287281204054,-2.790150232787023
617.6000000000081,66.94825041638417,0.24113767487142354,-2.790149926565688
618.7000000000081,67.05754299465607,0.24442380390086654,-2.7898333133881823
619.8000000000081,67.16790301759006,0.24266717361130344,-2.7904803064491577
620.9000000000082,67.27727592227441,0.2461908194625109,-2.7917838935239714
622.0000000000082,67.38736834293776,0.24679941949626197,-2.794102456722638
623.1000000000081,67.49642765832664,0.24448270796490867,-2.794104247103275
624.2000000000081,67.60725357062637,0.24759723834957412,-2.796730136933035
625.3000000000081,67.7146455833418,0.24781140080076522,-2.798108824097358
626.4000000000082,67.82487548824503,0.24741090387528286,-2.798034593590868
627.5000000000082,67.9367981724352,0.24877266917569607,-2.798006572278549
628.6000000000082,68.04635129371205,0.2518812896606932,-2.7980596008812975
629.7000000000082,68.15600428250542,0.2539253681582859,-2.8014742511880852
630.8000000000083,68.26610292486217,0.2558746822177077,-2.8020002756769067
631.9000000000083,68.37519707955809,0.25857763239185827,-2.8034305970200055
633.0000000000083,68.48431580710455,0.2565645648533389,-2.8047495741027344
634.1000000000083,68.59500788994168,0.2606996771593082,-2.804417659847976
635.2000000000083,68.70534442140061,0.26261684136123464,-2.8031112054384293
636.3000000000084,68.81608338855067,0.26514930523995084,-2.803271846810879
637.4000000000084,68.92621350730491,0.2690398026810621,-2.803078207642404
638.5000000000084,69.03669851994368,0.2679251177566063,-2.805745687775127
639.6000000000083,69.14635240145574,0.27160656302587277,-2.8057392596507698
640.7000000000083,69.25672779027526,0.272675728978951,-2.8067206541206016
641.8000000000084,69.36642611877558,0.2713986457993381,-2.808394122571402
642.9000000000084,69.4765636068353,0.27608095567579066,-2.808697037006641
644.0000000000084,69.58743937382383,0.2752429602483555,-2.8100228126302795
645.1000000000084,69.69633676276823,0.27598847477567634,-2.8109642563886523
646.2000000000085,69.80600447444544,0.2757670665837415,-2.8126299929181653
647.3000000000085,69.91656635982183,0.27429268716478794,-2.8119562363231236
648.4000000000085,70.02626344971901,0.27747572387070873,-2.8126499479691986
649.5000000000085,70.13662766179567,0.27420282125147954,-2.8126499490447276
650.6000000000085,70.24561345009138,0.277698114422233,-2.8128596642301407
651.7000000000086,70.35652071665844,0.2766864746760913,-2.814244066824025
652.8000000000086,70.46666163784346,0.27590499232124194,-2.816920402995239
653.9000000000086,70.57705886186321,0.27470157092055797,-2.818560323430578
655.0000000000086,70.68699444934856,0.2727614752928904,-2.817261020944334
656.1000000000087,70.79602724095601,0.26925962484475996,-2.8185799112869523
657.2000000000087,70.90751458669934,0.2689233080374859,-2.8178802422621585
658.3000000000086,71.01824846104589,0.26397008647913683,-2.8172686231056896
659.4000000000086,71.12743902813125,0.2647929943365044,-2.817266698425248
660.5000000000086,71.23684463197195,0.26648078536630193,-2.818558136445471
661.6000000000087,71.34818116771471,0.2663114815568593,-2.8212198979929717
662.7000000000087,71.45880460438349,0.26593095917642867,-2.8225349339825585
663.8000000000087,71.56877103266955,0.265958998235413,-2.8225401760025965
664.9000000000087,71.67900379875327,0.26081060390178007,-2.8225401817604494
666.0000000000088,71.7885245847156,0.26097302095614383,-2.822537365331285
667.1000000000088,71.90020152502946,0.264225445745354,-2.825171764100757
668.2000000000088,72.01010446800537,0.2646117587196141,-2.823859256657391
669.3000000000088,72.1201018889448,0.26476742894082317,-2.8238498158336154
670.4000000000088,72.2305677516406,0.26119483411251265,-2.8225456157254247
671.5000000000089,72.34107481733177,0.26230722111074395,-2.8215403375174013
672.6000000000089,72.45210241774538,0.2580668178681311,-2.824056928457888
673.7000000000089,72.56103117520188,0.2603429748079506,-2.8271844546438576
674.8000000000088,72.67172316014086,0.25969975616711877,-2.8278098005788017
675.9000000000088,72.78212989805569,0.2585588844826175,-2.828369488661841
677.0000000000089,72.89249853058777,0.2609809945713415,-2.8291198395946027
678.1000000000089,73.002852899985,0.26147945809509243,-2.8304405735909715
679.2000000000089,73.11324576003719,0.2594949935694397,-2.8316578190921264
680.3000000000089,73.22456901618813,0.2552794444748837,-2.831429931937249
681.400000000009,73.33493410515747,0.2543612055510459,-2.8314300637627614
682.500000000009,73.44556912501578,0.25403630365044194,-2.8320539511024188
683.600000000009,73.55627423566847,0.25157098033125447,-2.833345167268692
684.700000000009,73.66716810350411,0.251624071757086,-2.834723201685037
685.800000000009,73.77783044884377,0.24698002685454756,-2.836041393764374
686.9000000000091,73.88856272510955,0.24385483579001102,-2.836680633040041
688.0000000000091,73.99925390396089,0.2391172172038264,-2.8380066959633865
689.1000000000091,74.11066543585079,0.23767096922679876,-2.839330054475527
690.2000000000091,74.22134561691423,0.23455147147872604,-2.839330019999972
691.3000000000092,74.33185128957953,0.22828681219094205,-2.839330020441522
692.4000000000092,74.44312469677435,0.22817287103352024,-2.840530747102278
693.5000000000091,74.55360167219006,0.22624470492957835,-2.841453618815439
694.6000000000091,74.66406126054028,0.22307328155348866,-2.8419597554979896
695.7000000000091,74.77429167188728,0.22347294864293976,-2.8402756633972075
696.8000000000092,74.88592987466768,0.22178933510438875,-2.8415698471759585
697.9000000000092,74.99709057556868,0.21717709184815254,-2.8433465178694926
699.0000000000092,75.10652705201133,0.21299370445583554,-2.8419714193601404
700.1000000000092,75.2181979096152,0.2102473238158821,-2.8445992149095733
701.2000000000093,75.3295110411178,0.2040096450253836,-2.844600245846231
702.3000000000093,75.44030044797326,0.20389096669851933,-2.84459945901084
703.4000000000093,75.55183186077052,0.20018089246721987,-2.8446002185973507
704.5000000000093,75.66211231476272,0.19360637384846655,-2.845910186582336
705.6000000000093,75.77120501424503,0.188959935443636,-2.848550075129822
706.7000000000094,75.8813397310133,0.18366445778229978,-2.8472512120139752
707.8000000000094,75.99289320353287,0.17941467831003613,-2.8459227604715442
708.9000000000094,76.1039232760674,0.17547945139945914,-2.8482200678719525
710.0000000000093,76.21452756619829,0.17112795347686705,-2.84953805146924
711.1000000000093,76.32650779300027,0.16800796005880309,-2.84954006160393
712.2000000000094,76.43658222646238,0.16747848684753597,-2.8495241304399266
713.3000000000094,76.54713751679516,0.1663255964981215,-2.8507370421567377
714.4000000000094,76.65920126583109,0.15894430485704825,-2.850906922078733
715.5000000000094,76.76980292732603,0.15800187451271086,-2.8508595495718634
716.6000000000095,76.88144657799452,0.15230462876627893,-2.8502044047013455
717.7000000000095,76.99284843850431,0.14723728693087534,-2.8495449077380455
718.8000000000095,77.1033189381292,0.14224950386156363,-2.8521881144369408
719.9000000000095,77.21362181086079,0.13721142593694072,-2.853490743638334
721.0000000000095,77.32485959817627,0.13531407964963482,-2.856129697571184
722.1000000000096,77.43685164210493,0.1303153269537766,-2.8568021291821646
723.2000000000096,77.54845921666868,0.12836411888661206,-2.8574612257453116
724.3000000000096,77.66057484264675,0.11983599732975998,-2.8587597859435268
725.4000000000096,77.7716820011679,0.11404038639942779,-2.8574477730918675
726.5000000000097,77.88263651991878,0.11252875226251782,-2.860164759477663
727.6000000000097,77.99255715904818,0.10416298436347016,-2.8627202393555216
728.7000000000096,78.10744684212905,0.10120463531099803,-2.8640392755543855
729.8000000000096,78.21764268747111,0.09659891682152022,-2.8642038520144597
730.9000000000096,78.3292663397845,0.09472037827824575,-2.8653437637220747
732.0000000000097,78.44135101712496,0.08825488394259126,-2.8662322744505544
733.1000000000097,78.55155806306809,0.08846347661838341,-2.8654496969100958
734.2000000000097,78.66300602097631,0.08255247903044849,-2.863865202768307
735.3000000000097,78.77167594346102,0.08054869998717189,-2.864587395632156
736.4000000000098,78.88458887322744,0.07258907881072782,-2.8666119199733435
737.5000000000098,78.99680192018359,0.07328644625267633,-2.867879927464637
738.6000000000098,79.10908620284911,0.07268156086476504,-2.8691900399763504
739.7000000000098,79.22079523480878,0.06901682653956373,-2.870178826188881
740.8000000000098,79.33111935162569,0.0639897358375088,-2.868870095870686
741.9000000000099,79.44392746164031,0.05721728348912416,-2.8682019752632946
743.0000000000099,79.55591529541431,0.05660705329712403,-2.870840054767349
744.1000000000099,79.66676815614281,0.051984752340841205,-2.872160514578708
745.2000000000098,79.77867538198966,0.0461820762612269,-2.8721521254395057
746.3000000000098,79.89055339724091,0.03932229986221402,-2.873470082689327
746.7000000000099,79.93094114740799,0.03775771225082536,-2.8734699250486937