File: 01_Data/PU_Aerogel/STA/N2/10K_min/PU_Aerogel_STA_N2_10KData_230202_R3.csv
##Temp./Â°C,Time/min,DSC/(mW/mg),Mass loss/mg
50.0,10.92273829608936,0.058555865446068056,0.02061386546828059
51.100000000000016,11.193166599285211,0.06311966796328994,0.01591565284818941
52.20000000000003,11.422955640662751,0.06799355564797915,0.0152018411573418
53.30000000000005,11.61855611480238,0.07126090969964283,0.015345676928415042
54.40000000000006,11.793118929985223,0.07544828651035762,0.015526294227540482
55.50000000000008,11.959583647159775,0.07795728751337339,0.014691468310440658
56.600000000000094,12.118166241924044,0.08046561048739553,0.012017338895359053
57.70000000000011,12.268062908779086,0.08577153678548721,0.011794856251016395
58.800000000000125,12.415348496963151,0.08512289286178976,0.01437080215118769
59.90000000000014,12.558511251612874,0.08404457244894226,0.014001715684744287
61.000000000000156,12.696547056521535,0.08643753508473817,0.015313711844239908
62.10000000000017,12.835105293151484,0.0872552814632579,0.013036694979393193
63.20000000000019,12.969162247444705,0.08780049561479286,0.012981285054483482
64.30000000000021,13.101333613275083,0.08657016699195208,0.014843288075336858
65.40000000000022,13.233112659933441,0.08704916497676796,0.013176370042800034
66.50000000000023,13.361539633851459,0.087830666624225,0.012935450295459727
67.60000000000025,13.484684344824478,0.08748083976600962,0.013033840943136976
68.70000000000027,13.61370053897101,0.08775342281568554,0.012625546917305552
69.80000000000028,13.739219889291839,0.08708625397442304,0.012395973184407882
70.90000000000029,13.862835767881181,0.08929657760121246,0.01150314596939106
72.00000000000031,13.98693641823533,0.08721155508911127,0.012768310069860789
73.10000000000034,14.107207862016944,0.08764450388195844,0.013132298138853749
74.20000000000034,14.22655261790879,0.08556498618213948,0.012170508841760519
75.30000000000035,14.34358945134189,0.0879305200452607,0.012844002781323915
76.40000000000038,14.464936195721119,0.08803652838104448,0.01276844399933763
77.5000000000004,14.584161093938496,0.08755929804315787,0.01305882745939968
78.6000000000004,14.701951262268798,0.08740445642162853,0.014062035685735719
79.70000000000041,14.817325739117786,0.08714270379207778,0.01410511256517566
80.80000000000044,14.933236728087055,0.08551282814675831,0.013710622903464031
81.90000000000046,15.048837021298912,0.08458096046834362,0.013717243044881755
83.00000000000047,15.164007143605703,0.08245549832686416,0.015143308350570983
84.10000000000048,15.277855188589502,0.08196884742416843,0.01503312748863772
85.2000000000005,15.392621559409832,0.08010429752330483,0.014927097802769573
86.30000000000052,15.504365186114219,0.0773324629972234,0.014920944610464115
87.40000000000053,15.617491641221312,0.07697371252437124,0.014699546795505558
88.50000000000054,15.730290840659505,0.0752813411804718,0.01397764792904388
89.60000000000056,15.841045118211126,0.07687311593416402,0.014931367138604656
90.70000000000059,15.95159356201166,0.07439883922598445,0.01344292408537573
91.8000000000006,16.06144128878718,0.07513982031196953,0.013522062593999795
92.9000000000006,16.167998300603834,0.0724693466745856,0.013518811344320536
94.00000000000063,16.281739499618187,0.07351299181914195,0.013248505479577677
95.10000000000065,16.39044246391554,0.07105841754039699,0.014704476343281314
96.20000000000066,16.4989372056299,0.07151566676063426,0.014745401967221294
97.30000000000067,16.60864029750331,0.06852304026285339,0.016019784576250196
98.40000000000069,16.71632802404932,0.06831195978534788,0.014652115139120347
99.50000000000071,16.824411491937216,0.06780316888746807,0.014710030509591299
100.60000000000072,16.932702984705177,0.06757777900772122,0.014681739647619096
101.70000000000073,17.040334185436684,0.06597319458646034,0.014710111965337003
102.80000000000075,17.14646434285575,0.0653353729774413,0.016031038929531505
103.90000000000077,17.25458143933175,0.06402244531841661,0.01603029063698047
105.00000000000078,17.36169436405856,0.06480318356948578,0.015734506524138325
106.10000000000079,17.46847405181873,0.0660096023925123,0.01421015489505617
107.20000000000081,17.575352187752422,0.06538363357148946,0.014710204595612897
108.30000000000084,17.68236989008286,0.06356179039709176,0.016125854618912694
109.40000000000084,17.788419891493536,0.06257913800740389,0.014590905612975824
110.50000000000085,17.894928909147854,0.0591980807268222,0.014599820159551857
111.60000000000088,18.00205634435892,0.0587289789622818,0.01591827151690417
112.7000000000009,18.107191202495244,0.05899306049786257,0.014405101286250055
113.8000000000009,18.213567232876827,0.05847301604149657,0.014511018066153625
114.90000000000092,18.319532915731806,0.05827278780355072,0.01581028025082798
116.00000000000094,18.42509081737189,0.05896496356475267,0.014466309394829402
117.10000000000096,18.532833585975567,0.058602925444428244,0.014423705275240284
118.20000000000097,18.638772930003178,0.054413256160242396,0.014489576818538907
119.30000000000098,18.743884951680375,0.05291612006556834,0.014527409206581687
120.400000000001,18.849898994709893,0.05366216228235743,0.015789991322469277
121.50000000000102,18.955949713855826,0.053075498516920394,0.014479974776342441
122.60000000000103,19.06228981629131,0.05047408154070343,0.01414608553187513
123.70000000000104,19.16510400922878,0.0502908809137661,0.014489171794112465
124.80000000000106,19.273170728575014,0.048675190110987976,0.014443379670541212
125.90000000000109,19.37624389412767,0.04659459281767431,0.014527999642178546
127.0000000000011,19.48435279398457,0.04867092671561324,0.013170133853449784
128.1000000000011,19.5898198661078,0.04675564323368986,0.013184288035617886
129.20000000000113,19.6928721107308,0.04454814711595079,0.01448992607477706
130.30000000000115,19.79942570109338,0.04457588854349137,0.013066357369182935
131.40000000000117,19.90483368630416,0.044225172284076186,0.014533013495001246
132.50000000000117,20.010361392281236,0.044105234087704726,0.013500004430355261
133.6000000000012,20.115121510601703,0.0431934525202704,0.013506480539808852
134.7000000000012,20.220380115561415,0.04310208180290542,0.014493438489309174
135.8000000000012,20.32446074608158,0.04152563413104493,0.013169905350390199
136.90000000000123,20.42947453702216,0.041813682427591536,0.011837186786023413
138.00000000000125,20.53386465682335,0.04064027309759566,0.013175202607128345
139.10000000000127,20.6382322014028,0.039026495248334014,0.014498280735577573
140.2000000000013,20.741632851192776,0.039218382006584784,0.013169853226008943
141.3000000000013,20.84654204320607,0.03831516867811802,0.014565545640860211
142.4000000000013,20.94937206612788,0.039480045104942074,0.013173614249864407
143.50000000000134,21.05456601976634,0.03787786160190465,0.011906461276109948
144.60000000000133,21.158595414848136,0.03879377615584989,0.013173441381154394
145.70000000000135,21.263414736965327,0.03769071580666716,0.01306003456680438
146.80000000000138,21.365879323483064,0.03755230692680145,0.013354579570365122
147.9000000000014,21.46961932401833,0.03547918679779738,0.012953050340173355
149.00000000000142,21.573058259804487,0.03531382418693618,0.01296056344108587
150.10000000000142,21.677426366606696,0.03072063887014298,0.014270116370610708
151.20000000000144,21.77965348699576,0.03117187091121798,0.013909043283554912
152.30000000000146,21.88496410135437,0.030474209622791792,0.014269897964109823
153.40000000000146,21.988196615883886,0.02831857381807723,0.014269692063793915
154.50000000000148,22.09208816045157,0.0279248828340507,0.014270001295776602
155.6000000000015,22.19515997316955,0.02652753810344588,0.014352240663400018
156.70000000000152,22.29964564128798,0.025741532232255393,0.01292596927534051
157.80000000000155,22.403459036576624,0.023961734580242644,0.012566815312270219
158.90000000000154,22.505122900458936,0.021674573929895913,0.012960093450947507
160.00000000000156,22.612190845187534,0.02167543683242157,0.012960112173017624
161.1000000000016,22.714521562069034,0.02081031363081176,0.012950990284795516
162.20000000000158,22.817454715539228,0.02060801349017738,0.012929685030397042
163.3000000000016,22.921900102903084,0.020187187285922725,0.01283868398156196
164.40000000000163,23.025567294018277,0.01977304502092092,0.01284005543497413
165.50000000000165,23.129010797936875,0.01660012366858421,0.011515507171473427
166.60000000000167,23.23303823279145,0.017487463224567623,0.010860093076641597
167.70000000000167,23.336263199011945,0.016660779012857008,0.012139253492227109
168.8000000000017,23.439916396267378,0.016182189940250113,0.010878070325561318
169.9000000000017,23.54321803896309,0.014725457140931875,0.011149635866242402
171.0000000000017,23.648305505415014,0.013390031450202344,0.010869892075864751
172.10000000000173,23.75281363515415,0.012615589884748313,0.010869892060888287
173.20000000000175,23.855389924942155,0.010689844082618083,0.010964412708651228
174.30000000000177,23.958669208556138,0.01196925726741671,0.010735449155474086
175.4000000000018,24.062680059016717,0.00892950624683686,0.010749941444595734
176.5000000000018,24.165612109974955,0.010287923815524902,0.00936640578421466
177.6000000000018,24.26975236928071,0.007074932391749389,0.00944340975774649
178.70000000000184,24.373951002545258,0.008339730162441938,0.010819750404864603
179.80000000000183,24.477107559272866,0.00891631811498772,0.009437558941406632
180.90000000000185,24.579906453202767,0.007471205691424676,0.008744743064749816
182.00000000000188,24.685097687079512,0.006581971062910585,0.009109887571853381
183.1000000000019,24.78809053806348,0.00427265764777196,0.007790051726470182
184.20000000000192,24.89142244160348,0.004174464528598931,0.0064959536475233115
185.30000000000192,24.994340641568648,0.0026739073761534726,0.006469891988346799
186.40000000000194,25.095913292739866,0.002525317899818025,0.006469867209908831
187.50000000000196,25.201843003831826,0.00200957975023186,0.007101797918706243
188.60000000000196,25.305660771067693,0.0029872511472186503,0.007129476348632036
189.70000000000198,25.408025103670326,0.0010538275467422142,0.005813517859349915
190.800000000002,25.51230482547183,-0.0003905189566966172,0.005819942160457892
191.90000000000202,25.614815096829243,-0.0009031848508116447,0.0038396322814047146
193.00000000000205,25.72000000000022,-0.0007593920299857615,0.0038398919441231527
194.10000000000204,25.82312143356304,-0.0008594643429603588,0.004532711693927993
195.20000000000206,25.926826273373024,-0.002216145907536604,0.0035100144731079475
196.3000000000021,26.0300899803594,-0.0013113874328994912,0.0035099980765673777
197.40000000000208,26.133359204719316,0.0003652680651520246,0.0025186187251886594
198.5000000000021,26.23650224076804,0.0010509079771107155,0.0011999038008503327
199.60000000000213,26.339720127676628,0.002490615240252958,0.0011998867423703707
200.70000000000215,26.444008235861116,0.003436520067034987,-0.00011907189677273777
201.80000000000217,26.546877279844853,0.004878699794543806,-0.0014345896221770182
202.90000000000217,26.650410322838123,0.00645364642527102,-0.0011000989579770248
204.0000000000022,26.751445965725402,0.008734924787389242,-0.0011001087882038796
205.1000000000022,26.857477418209637,0.011647496888926634,-0.002482847100894414
206.2000000000022,26.96062299000819,0.012594562169139456,-0.0027617470999015126
207.30000000000223,27.064364059614324,0.01373811044970219,-0.004060182024383074
208.40000000000225,27.168200303143152,0.02072976733213705,-0.004063191138381939
209.50000000000227,27.271494211878267,0.024046429764475463,-0.005379946440896788
210.6000000000023,27.375568119282953,0.029257095789468557,-0.006858704944284089
211.7000000000023,27.478024244992614,0.035129711223780946,-0.008258966567490145
212.8000000000023,27.582412956333556,0.040784861406591544,-0.009330166879320423
213.90000000000234,27.68678127391341,0.04904079682748341,-0.00932105648896231
215.00000000000233,27.79072474543731,0.05738789048805093,-0.011179671204800012
216.10000000000235,27.893196016047703,0.06952511657068783,-0.01229119080969987
217.20000000000238,27.99667479162525,0.08354250015434184,-0.016260599738151527
218.3000000000024,28.101160655049643,0.09635875011189354,-0.01889486930614792
219.40000000000242,28.20453385388016,0.11239585011031283,-0.018936792311551987
220.50000000000242,28.308287029757512,0.13334712178664843,-0.021521659126202408
221.60000000000244,28.412312891620008,0.15344129488027414,-0.022807525547857033
222.70000000000246,28.516396547934335,0.17421746742337885,-0.02546927518274389
223.80000000000246,28.61964562744623,0.20087274307148106,-0.027089510380266635
224.90000000000248,28.72390510636216,0.22472616806177714,-0.029376460410735827
226.0000000000025,28.82558301152835,0.25127700111329276,-0.03380283095453818
227.10000000000252,28.931558486727603,0.27868271451284043,-0.03761985483531616
228.20000000000255,29.0344815335353,0.3046019472339923,-0.04029599305139264
229.30000000000254,29.136896486051278,0.32585380660367264,-0.046062368191884584
230.40000000000256,29.242621949471626,0.35056980003571303,-0.05041097414078921
231.5000000000026,29.348036698972734,0.36691538360651044,-0.05504458475510754
232.60000000000258,29.45073775117911,0.3831199752842165,-0.062222505987064025
233.7000000000026,29.55488180268529,0.3984132232801125,-0.06642117371443756
234.80000000000263,29.659098996066955,0.40720983491627893,-0.07201293525707086
235.90000000000265,29.763544489202356,0.4183370603712566,-0.07931490949601594
237.00000000000267,29.868235651023543,0.4258202805548632,-0.0851325892539756
238.10000000000267,29.97178272862551,0.4336161247515953,-0.09278594217736336
239.2000000000027,30.076701485817345,0.4356411840152533,-0.10026485255892004
240.3000000000027,30.180000000000256,0.4390215664928098,-0.10857993462163762
241.4000000000027,30.284010581853934,0.4433793936874487,-0.11817058796896962
242.50000000000273,30.388920743006445,0.44467188581517114,-0.12595263051744565
243.60000000000275,30.493123568980188,0.4485415198933934,-0.1360799102321666
244.70000000000277,30.59575368719697,0.45206320906033665,-0.14678515733378195
245.8000000000028,30.7008375989031,0.45490406743943657,-0.15695093167054397
246.9000000000028,30.806625346901114,0.45958814862017305,-0.1698817908528505
248.0000000000028,30.910209331915595,0.4650880951323637,-0.1818356960631804
249.10000000000284,31.012460514819757,0.46827416082863593,-0.19260428405430607
250.20000000000283,31.118793399972635,0.47381868276987704,-0.20642524128554252
251.30000000000285,31.223342761371992,0.47678415834185145,-0.21944665737480706
252.40000000000288,31.327465253418726,0.48487642056699126,-0.23429390556962515
253.5000000000029,31.433424612296143,0.4864277824393918,-0.24949138815651217
254.60000000000292,31.5363579150871,0.4909890403609127,-0.2643898708577592
255.70000000000292,31.641962662025282,0.49632163018194464,-0.2812122501780072
256.8000000000029,31.744779294247834,0.4982683055628092,-0.29765617961461066
257.90000000000293,31.849427561367186,0.5014502271421906,-0.31279577916035173
259.00000000000296,31.954692295156477,0.5022036503971032,-0.32977580681940655
260.100000000003,32.059905737887206,0.5023349443033062,-0.34756166202950656
261.200000000003,32.164061375954866,0.5015932031935055,-0.36603495448374
262.300000000003,32.267718795935096,0.49542453010454607,-0.38574284233862377
263.40000000000305,32.37066045490368,0.49219932352940354,-0.4046730101943341
264.50000000000307,32.47801832649512,0.48804471500913615,-0.42431876694968684
265.6000000000031,32.58201513602269,0.4809814683322592,-0.44312538228974985
266.7000000000031,32.68633405765081,0.4686932882036374,-0.462633834084869
267.8000000000031,32.79130066931708,0.45966538291517306,-0.48336167014397535
268.9000000000031,32.89537161504506,0.4433378288642996,-0.5045001284931439
270.0000000000031,32.99961448447734,0.43129764547349064,-0.5230564475342168
271.10000000000315,33.10340339898069,0.4130807597849259,-0.542438152278025
272.2000000000032,33.20577165414136,0.3978217318552213,-0.5600068543442451
273.30000000000314,33.31115892305817,0.3779732868709321,-0.5796547706576467
274.40000000000316,33.41638384082008,0.35538226390968763,-0.5990411086319805
275.5000000000032,33.52030175505052,0.33657538020773475,-0.616579832639458
276.6000000000032,33.62364089014058,0.3140797903935125,-0.632351798505856
277.70000000000323,33.72867213841049,0.29233580204556675,-0.6470438662990854
278.80000000000325,33.83191393622788,0.27254094719659205,-0.662403063794522
279.9000000000033,33.936373489324545,0.25618139703202186,-0.6762642588863468
281.0000000000033,34.039899826170476,0.23903381680981584,-0.6886573311491464
282.1000000000033,34.141640982313156,0.22386794805024995,-0.7003012618313869
283.20000000000334,34.2477229652152,0.2105853598426266,-0.7119797822880134
284.30000000000337,34.35231114299114,0.1981606420321857,-0.7223794610646288
285.40000000000333,34.45606239592965,0.18853161020196546,-0.7327681133653274
286.50000000000335,34.56198771105653,0.18007591589419952,-0.7428144946008954
287.6000000000034,34.66520819212335,0.17198734965663337,-0.7530611913158554
288.7000000000034,34.770785099672295,0.1688740157925242,-0.7619872464856376
289.8000000000034,34.87546746311029,0.16697635194779142,-0.7719173752674404
290.9000000000034,34.97990733990864,0.16607925864267897,-0.7801234059281437
292.0000000000034,35.08530030789067,0.16245262577431602,-0.788648896519343
293.10000000000343,35.189999097599134,0.1638076049536908,-0.7949909649551512
294.20000000000346,35.293765209085045,0.1654886655149012,-0.8031473520578865
295.3000000000035,35.398641353049044,0.17037152043318732,-0.809867204179807
296.4000000000035,35.501527934476755,0.16963560559436947,-0.8178982380725022
297.5000000000035,35.60768398036584,0.17327939567859363,-0.8261206294250028
298.60000000000355,35.71301492861051,0.17599407310894416,-0.8338185666089832
299.70000000000357,35.818366234406504,0.18045245278428784,-0.8402297149487463
300.8000000000036,35.92181946407924,0.18602181867179268,-0.847008375173969
301.9000000000036,36.02839253393114,0.1902327838891133,-0.8532958061797085
303.0000000000036,36.13269740777899,0.19521559617231687,-0.8599340481001865
304.1000000000036,36.23731730421945,0.20059312463307538,-0.8673786236795631
305.2000000000036,36.3419954616189,0.20349908934963545,-0.8747309939751617
306.30000000000365,36.44680905922404,0.21034214312890465,-0.8812395884943967
307.4000000000037,36.55259439194255,0.21346357328238003,-0.8881852746047638
308.5000000000037,36.65683914012346,0.21968597680511623,-0.895738158840254
309.60000000000366,36.759999115089066,0.22441520494063083,-0.9012099835469378
310.7000000000037,36.86742283513254,0.2314982160252591,-0.9085400893497995
311.8000000000037,36.97239896680751,0.23668395970676911,-0.9178294664387407
312.90000000000373,37.077031438818565,0.24434788654751163,-0.9241718478849053
314.00000000000375,37.181881455398475,0.25171984646486767,-0.9315280074948684
315.1000000000038,37.28668648586203,0.25710425502976164,-0.9383321006958485
316.2000000000038,37.39176393634225,0.26374446148740527,-0.9460262648802544
317.3000000000038,37.49657229568498,0.2674579978873987,-0.9561634481974552
318.40000000000384,37.602048047012026,0.2754827407523317,-0.962867599852482
319.5000000000038,37.70675172496132,0.27701782427746713,-0.9733389598319859
320.60000000000383,37.81172554072513,0.2812280202750114,-0.981349282658655
321.70000000000385,37.917441399531384,0.2834072619408197,-0.9907110671778017
322.8000000000039,38.02235470743195,0.28956721954172326,-1.0000813198196399
323.9000000000039,38.128432687160114,0.2909617535433423,-1.0097266592495862
325.0000000000039,38.23338195436511,0.2932801989871646,-1.0190911617697416
326.10000000000394,38.33877106792322,0.29410698945850366,-1.0293212038981947
327.2000000000039,38.44407035746928,0.29729373677224313,-1.0400611765191492
328.30000000000393,38.54890369470048,0.2981513870243546,-1.0504012250486303
329.40000000000396,38.654056585321584,0.2985829961187467,-1.0614850905132243
330.500000000004,38.75989861513402,0.30249639914489607,-1.0714784119099243
331.600000000004,38.86534049618936,0.3021922245383727,-1.0814074502873354
332.700000000004,38.970777783347934,0.3015827354648284,-1.0938010247485677
333.80000000000405,39.076010909097924,0.2978053658595733,-1.1055546506933434
334.90000000000407,39.182043291832386,0.29102956303003746,-1.1170244136440455
336.0000000000041,39.28784227655992,0.2817474463628684,-1.1285937656188412
337.10000000000406,39.39357829222394,0.27484715567476425,-1.1409490613539868
338.2000000000041,39.49999902952356,0.2689594585822851,-1.151739779889438
339.3000000000041,39.60478877523384,0.26214309311235373,-1.164449155556495
340.4000000000041,39.71125424076252,0.25788419876533974,-1.1751368544590526
341.50000000000415,39.81554091934525,0.2532991638982105,-1.1857074868519564
342.6000000000042,39.92330805386398,0.2495605084088396,-1.1992740583803365
343.7000000000042,40.02715009532646,0.24480280078216277,-1.2123252173147452
344.80000000000416,40.13462238974945,0.2396672491619839,-1.2246552151220618
345.9000000000042,40.24131287985066,0.234366773570197,-1.2365990892624334
347.0000000000042,40.3465216967039,0.22562594387443785,-1.2487466443020638
348.10000000000423,40.45326057765495,0.22072672237798796,-1.2617091069477202
349.20000000000425,40.55773963174074,0.212497591903958,-1.2732176583446013
350.3000000000043,40.66463611993848,0.20645810569065626,-1.2861775423654485
351.4000000000043,40.77010560847956,0.19563348140777614,-1.2963402023103403
352.5000000000043,40.87705916398732,0.18684552484762146,-1.3084117678634355
353.60000000000434,40.98259193899096,0.17836372646522072,-1.3186601671407154
354.7000000000043,41.08899525800555,0.1681242167739195,-1.3312526904654285
355.80000000000433,41.19459835060221,0.1578561992704331,-1.3405900495903547
356.90000000000435,41.30229456503103,0.14416172668678903,-1.3530288333700495
358.0000000000044,41.40820978491506,0.13437555468564794,-1.3620904346218987
359.1000000000044,41.514370295594134,0.12343077175209569,-1.3715999494236115
360.2000000000044,41.62107639245904,0.11165968644289967,-1.3826274817577153
361.30000000000445,41.72724825765243,0.09984343017726885,-1.392383543534398
362.4000000000044,41.833261971280635,0.08849675844706367,-1.4024245967903055
363.50000000000443,41.94009893457151,0.07764586381543981,-1.4101297344826
364.60000000000446,42.044943944848605,0.06923356330396008,-1.4170474579195091
365.7000000000045,42.15241585938916,0.05865093171705327,-1.4271467561543134
366.8000000000045,42.25990604734153,0.0501647213012979,-1.4349695193969385
367.9000000000045,42.36500716711898,0.038944981737275175,-1.4423548232767076
369.00000000000455,42.472303939968924,0.032544204587648284,-1.4499706649150261
370.10000000000457,42.57814017017713,0.02349706811260527,-1.458135134298379
371.2000000000046,42.68456552443064,0.013566638967503264,-1.46441546976626
372.30000000000456,42.791117644553516,0.00677498875765653,-1.4700900917167896
373.4000000000046,42.89696897946017,-0.001282424066921306,-1.4770646837589352
374.5000000000046,43.00404766135953,-0.006579630123852487,-1.4852281155099472
375.6000000000046,43.1086643864852,-0.013006396072128057,-1.4910111240216022
376.70000000000465,43.216463839876155,-0.02060165950370829,-1.4985326738213423
377.8000000000047,43.32225618060577,-0.02502814761320782,-1.5052096865388567
378.9000000000047,43.42860626644525,-0.02935471288039787,-1.5106236212733593
380.00000000000466,43.53477905701547,-0.03259598003851899,-1.517961595508023
381.1000000000047,43.641017323697426,-0.03742017959149746,-1.5250002379019012
382.2000000000047,43.74904057419565,-0.043497788700748496,-1.5316253876836234
383.30000000000473,43.85507091028666,-0.04663282994753232,-1.5385965899152625
384.40000000000475,43.961065005990356,-0.052182116416325974,-1.5463635329364007
385.5000000000048,44.06690278824238,-0.05723434490485957,-1.5519132426261897
386.6000000000048,44.173379939523954,-0.05999704380952575,-1.5589782947112898
387.7000000000048,44.279583328076576,-0.06391009791653834,-1.5652402623821358
388.80000000000484,44.3862994568764,-0.06808854658014724,-1.5732981950917888
389.9000000000048,44.491239834826864,-0.06972361470026706,-1.5809780357145247
391.00000000000483,44.59961326411008,-0.07209690849216349,-1.5885203311547955
392.10000000000485,44.70530673400277,-0.07498749761040219,-1.5943601603106052
393.2000000000049,44.812589869525446,-0.0753301698428746,-1.6026959972974306
394.3000000000049,44.919505205479666,-0.07641714903938318,-1.6094968834180343
395.4000000000049,45.02617341905202,-0.07796772330574503,-1.6180845443289695
396.50000000000495,45.13291640576442,-0.07594973081627238,-1.626167014007783
397.6000000000049,45.239999034033794,-0.07381034501704437,-1.6333599434779766
398.70000000000493,45.34740619543446,-0.07124922427544816,-1.6413710407266175
399.80000000000496,45.45353660196356,-0.0673215641995431,-1.6501510386324694
400.900000000005,45.56120137547172,-0.06405280405241753,-1.6603768046912237
402.000000000005,45.66753394779576,-0.057451589698788164,-1.6670441527204871
403.100000000005,45.77502574251394,-0.05485854467326168,-1.6755454126787872
404.20000000000505,45.88127546062937,-0.04787385274283329,-1.6844402957769486
405.30000000000507,45.98880814272429,-0.04260417857605758,-1.6933037877554904
406.4000000000051,46.09483534557579,-0.03785404433819345,-1.7001844708606337
407.50000000000506,46.20164636615838,-0.030422197985233712,-1.708590842212852
408.6000000000051,46.310381859656204,-0.023606362701261208,-1.7176056536348856
409.7000000000051,46.41740899388645,-0.01629083251262875,-1.72783301638
410.8000000000051,46.524324830499324,-0.01208895634252527,-1.7347213281378675
411.90000000000515,46.63097411045255,-0.0038110627184534396,-1.743729826882765
413.0000000000052,46.73684751490313,0.004401935072907093,-1.7523482326018636
414.1000000000052,46.84711605537228,0.010641381615138168,-1.7616517625784893
415.20000000000516,46.95331880198687,0.01660955759187943,-1.7695977903286946
416.3000000000052,47.05949256335999,0.021978185076166695,-1.777684277435971
417.4000000000052,47.167880063722784,0.029737496482217907,-1.7868330349254844
418.50000000000523,47.27448961527999,0.03400390588786917,-1.7939423905844176
419.60000000000525,47.38154904780441,0.03882495619974122,-1.8019584797521522
420.7000000000053,47.48972250543559,0.045538972685548934,-1.809228893218025
421.8000000000053,47.595960392113454,0.048043142174658715,-1.8181619996641625
422.9000000000053,47.70320783633234,0.053854135069713316,-1.8261840288179862
424.00000000000534,47.81199596753168,0.05989163915915524,-1.8342571111406585
425.1000000000053,47.91871639312315,0.0626070264174321,-1.8410094370534047
426.20000000000533,48.02720184577313,0.06974299634470846,-1.8496829159187356
427.30000000000535,48.13248636515233,0.07237345030637812,-1.8571198246947516
428.4000000000054,48.242164289781996,0.07496596559884175,-1.8662108691341426
429.5000000000054,48.34923167170589,0.07717977581199512,-1.8736258911929387
430.6000000000054,48.45797960512084,0.08034942437245529,-1.8821130814809672
431.70000000000545,48.56398190750332,0.08320795131582542,-1.890357966789436
432.8000000000054,48.672189005238224,0.08829034305607719,-1.8973683056758102
433.90000000000543,48.77858247758518,0.08989157985792318,-1.9062616246786113
435.00000000000546,48.88754553775779,0.08933722790400911,-1.9129231324803309
436.1000000000055,48.99500624025899,0.09482310663158977,-1.9209428942207714
437.2000000000055,49.10317770018263,0.09568035962763968,-1.9281629611445608
438.3000000000055,49.21048771796862,0.0987260081094444,-1.9368305114996
439.40000000000555,49.31824865213239,0.10013650254705371,-1.944512844968081
440.50000000000557,49.42609610489854,0.10528374335645917,-1.9526849901084664
441.6000000000056,49.534621671082675,0.10588178200567741,-1.9595771673656868
442.70000000000556,49.64158247002347,0.10671139079840615,-1.9668869149089918
443.8000000000056,49.74979382186918,0.11015621137051199,-1.9745069000714948
444.9000000000056,49.857751261725674,0.11051088604368764,-1.9819529254392565
446.0000000000056,49.96487870421892,0.1112155035802296,-1.9887670905449735
447.10000000000565,50.0728147413608,0.11238208658350192,-1.995806959986993
448.2000000000057,50.17945090578737,0.11349470698408862,-2.003811411203807
449.3000000000057,50.28846587991695,0.11709114396540515,-2.011254447561409
450.40000000000566,50.39536892918953,0.11776028615290436,-2.0177090156453987
451.5000000000057,50.501706719478854,0.12142350734189791,-2.0261800993393013
452.6000000000057,50.61089736406658,0.12265395910256309,-2.0341843207903008
453.70000000000573,50.7185404047009,0.1217667283861877,-2.037788644602086
454.80000000000575,50.824982513129996,0.12496889414741802,-2.0472429821953853
455.9000000000058,50.93291241017217,0.12636233040711092,-2.052780562564813
457.0000000000058,51.03990400158297,0.1261151802322789,-2.0592752529253766
458.1000000000058,51.147390964952166,0.1274158516785948,-2.06634692997742
459.20000000000584,51.25386961938693,0.1291333272460891,-2.073706933472288
460.3000000000058,51.36266665591832,0.1265763249963155,-2.078511868993185
461.40000000000583,51.47155518042829,0.1269698696649894,-2.0874749356741127
462.50000000000585,51.5790994962243,0.1277745875810461,-2.093472891848939
463.6000000000059,51.68769085459752,0.12706709756304352,-2.100686714796748
464.7000000000059,51.79537206303509,0.12747351734957735,-2.109063527327045
465.8000000000059,51.90374094037327,0.12772110795338526,-2.116128861516833
466.90000000000595,52.00858204836368,0.12792231815646377,-2.122954553389589
468.0000000000059,52.11859619895481,0.13096636398946657,-2.128651209817945
469.10000000000593,52.22765969674746,0.1284356601492634,-2.1343696739979006
470.20000000000596,52.33548038620033,0.12892792354585333,-2.1423441017044924
471.300000000006,52.4431615204935,0.12967764442823126,-2.1489748104271875
472.400000000006,52.55102571149839,0.1315765208638145,-2.1546719387287783
473.500000000006,52.6579442944426,0.1321867203356623,-2.1605083517120325
474.60000000000605,52.76712824348252,0.1323410819726208,-2.1688596790918675
475.70000000000607,52.875685023301926,0.13206468219580514,-2.174329656644639
476.8000000000061,52.98391490857858,0.13047003657769837,-2.183423122314979
477.90000000000606,53.09155615140832,0.1301305789284227,-2.1910183536381456
479.0000000000061,53.20078374332163,0.12995534638238,-2.1975908269169766
480.1000000000061,53.30743132087124,0.13054547403274788,-2.2030336432322457
481.2000000000061,53.41606055145691,0.1309809743553917,-2.2097281038702596
482.30000000000615,53.52437004547469,0.1305183266871272,-2.2180136042998884
483.4000000000062,53.632507803290125,0.1294892179562206,-2.224227960712586
484.5000000000062,53.74032660416398,0.13058686326518915,-2.2311561477185817
485.60000000000616,53.847658529220425,0.13232835549116595,-2.236610010175365
486.7000000000062,53.95680828785548,0.1311208128937846,-2.245927417349919
487.8000000000062,54.06505449213018,0.1303041397162058,-2.25133844054409
488.90000000000623,54.17357923528184,0.12805801220347982,-2.258934738229818
490.00000000000625,54.282889893389424,0.1257190819286478,-2.265521525431824
491.1000000000063,54.38912712419416,0.1235347646128593,-2.2736330127680073
492.2000000000063,54.49806994955381,0.12189264357102793,-2.2798984371826623
493.3000000000063,54.607134772909674,0.12171222730339454,-2.2881445133583873
494.40000000000634,54.71534621262876,0.11964047376659012,-2.2952878075703333
495.5000000000063,54.82410594355135,0.11975422220404534,-2.3011151197921533
496.60000000000633,54.932573076071726,0.11777799347006396,-2.307453428647576
497.70000000000636,55.04122627205571,0.11767937472302095,-2.315570955431001
498.8000000000064,55.150735691253104,0.11891048440245248,-2.320685147979435
499.9000000000064,55.25934662361802,0.1194651799835022,-2.329253090773712
501.0000000000064,55.36684776993712,0.11829636854925066,-2.3357237506921686
502.10000000000645,55.47595700060149,0.11936182268399417,-2.341014811461469
503.2000000000064,55.585316858540025,0.12032999476957676,-2.3486412370942746
504.30000000000643,55.69359801426614,0.12090903887820353,-2.3549459671782875
505.40000000000646,55.8021306449625,0.11741235276894299,-2.3630625919253814
506.5000000000065,55.91071125913759,0.11839061262118551,-2.3682103959976297
507.6000000000065,56.01929115178055,0.11799005181579249,-2.3759759625961347
508.7000000000065,56.12799290144865,0.11725883377206217,-2.3827409737365146
509.80000000000655,56.23661273744771,0.11718747971050816,-2.3884198662242353
510.90000000000657,56.345079063723894,0.11839440706103016,-2.3955948722950575
512.0000000000066,56.45421901331129,0.11650821241759408,-2.4013572730372843
513.1000000000065,56.56273722185841,0.11474489737532856,-2.407236385844328
514.2000000000066,56.67156379206612,0.114757959058032,-2.4139877576552315
515.3000000000065,56.780299386724614,0.11628862163489036,-2.4216624187818265
516.4000000000067,56.88742511188839,0.11617529135587258,-2.425655607208699
517.5000000000066,56.99663183747952,0.1162225005655555,-2.4317256360855057
518.6000000000067,57.10562890224129,0.11535153775543086,-2.4390562361312456
519.7000000000066,57.21308194121961,0.11614806338002173,-2.4447204850524127
520.8000000000067,57.3217742052304,0.1142824435130545,-2.450139700662588
521.9000000000067,57.429997902767404,0.11440030904285856,-2.4563999115277424
523.0000000000067,57.53971648096347,0.11353781178984759,-2.461856273398576
524.1000000000067,57.64764681623541,0.11280449399633527,-2.4663051504304923
525.2000000000068,57.757498184210064,0.11204786414156963,-2.472808138800149
526.3000000000068,57.86543427083564,0.10979850227068352,-2.4778399579614945
527.4000000000068,57.97455362748056,0.10950994580143261,-2.482145505713416
528.5000000000068,58.083710901756646,0.10955306451499472,-2.4881564976462847
529.6000000000068,58.19101816709443,0.10875725321405204,-2.492628839032331
530.7000000000069,58.30159535117924,0.10776733793962986,-2.498859347882335
531.8000000000068,58.410201619978444,0.10559742950557499,-2.5016423978040327
532.9000000000069,58.519599113954214,0.10845151195998762,-2.507878593801952
534.0000000000068,58.62949253459907,0.10564969881830852,-2.513918073934027
535.100000000007,58.73918811936814,0.10878879965270909,-2.51726457940109
536.2000000000069,58.848216760876085,0.11055410644133651,-2.521720705836329
537.300000000007,58.95784570547215,0.10815741499075959,-2.526287969412576
538.4000000000069,59.06676999532407,0.10883372200393651,-2.532471379664625
539.5000000000069,59.17709458490648,0.10667450550797394,-2.5359517627661945
540.600000000007,59.28407417331993,0.10668338541270385,-2.541761897583675
541.700000000007,59.393460403832215,0.10669802344198731,-2.545959545739533
542.800000000007,59.50377254913951,0.10527738552640503,-2.550154529297599
543.900000000007,59.61258456864241,0.10392478189345461,-2.5518043020048617
545.000000000007,59.721647598930005,0.10618162504400841,-2.5559773596349067
546.1000000000071,59.830287018551175,0.10618300338924092,-2.560698012995451
547.2000000000071,59.93969303369354,0.10223686707707166,-2.5650929277373637
548.300000000007,60.04934513499096,0.10175331418466027,-2.5689759292781433
549.4000000000071,60.15764613667304,0.10327800239188838,-2.5736806756200803
550.500000000007,60.26633348208464,0.10142925232042754,-2.5782287583537737
551.6000000000072,60.3758076656987,0.09973893874189044,-2.5798304911775625
552.7000000000071,60.48498576718037,0.10123908409617088,-2.5829683688760814
553.8000000000072,60.59399416812639,0.10021580930573326,-2.588595177520169
554.9000000000071,60.70196105872008,0.1020338727348328,-2.5914179368973738
556.0000000000072,60.812387962456704,0.09688316786345888,-2.595257918090459
557.1000000000072,60.92215734840958,0.09565230915613283,-2.597997915093153
558.2000000000072,61.03168780909498,0.09495818226214958,-2.603361828222629
559.3000000000072,61.14145843206372,0.08842063350102015,-2.604721373621845
560.4000000000073,61.24918283562336,0.08973442522172867,-2.6086349640366784
561.5000000000073,61.358786203406176,0.09044855599281795,-2.611392585472416
562.6000000000073,61.46816193582524,0.09201616846042776,-2.61528333342625
563.7000000000073,61.57742964320161,0.08885992298253476,-2.618117446928251
564.8000000000073,61.68594252536997,0.09002732513898556,-2.621696671720378
565.9000000000074,61.795797014116694,0.09067864763030578,-2.6244546027483175
567.0000000000074,61.904343639322086,0.09054463998799923,-2.627993433271705
568.1000000000074,62.01406717947023,0.09058629566784776,-2.6307450324106325
569.2000000000073,62.12280941388865,0.0895065795372223,-2.63306052235396
570.3000000000073,62.23212140681022,0.09000246909954325,-2.636592469880418
571.4000000000074,62.340953789483564,0.08973801380681004,-2.6397677347515933
572.5000000000074,62.450505542309074,0.08803257557310427,-2.641019076688923
573.6000000000074,62.55960328596569,0.08827114637549663,-2.6450948107999603
574.7000000000074,62.66812928506869,0.08727318684070333,-2.6463210192648496
575.8000000000075,62.778567532368605,0.08256139294860718,-2.6483016583787578
576.9000000000075,62.88737658443738,0.08580026573280566,-2.651689893283189
578.0000000000075,62.997014212771525,0.08410657162939456,-2.6529437377732483
579.1000000000075,63.106131248709,0.08725736524391632,-2.654229054213793
580.2000000000075,63.216134843493656,0.08500984517193641,-2.659504461450401
581.3000000000076,63.324882716343375,0.08531985968412328,-2.66262013961717
582.4000000000076,63.4331733501025,0.0852420582063601,-2.662600155453533
583.5000000000076,63.54427649644848,0.08402254645225699,-2.665178202396241
584.6000000000076,63.652261635006184,0.08489186213733006,-2.667128367079637
585.7000000000077,63.76189819623979,0.08482308154873579,-2.669711934997667
586.8000000000077,63.87124824480662,0.08283903603809112,-2.672335731875444
587.9000000000076,63.98197458242563,0.08700706748072554,-2.6736780790977166
589.0000000000076,64.09080907339874,0.08523601367817796,-2.675972331988065
590.1000000000076,64.20042468507526,0.08563029037373729,-2.6779875380484333
591.2000000000077,64.30978352644536,0.08180603970770692,-2.6799035792841672
592.3000000000077,64.42010479165657,0.08175856411530757,-2.6802490758108553
593.4000000000077,64.52990138298613,0.08348263617221294,-2.682879653167146
594.5000000000077,64.64020075264662,0.08415008321148529,-2.6854864423116114
595.6000000000078,64.75089825672251,0.08279950121669712,-2.6855199258089413
596.7000000000078,64.86030130985735,0.07955000287684741,-2.688157042189193
597.8000000000078,64.97120985924163,0.07978671137631879,-2.6881904840949042
598.9000000000078,65.08106810214763,0.07811612498110682,-2.690220163564306
600.0000000000078,65.19026679922412,0.07688561342689043,-2.6908004015859355
601.1000000000079,65.300336698385,0.0755863886902782,-2.692111480849417
602.2000000000079,65.41094249154263,0.07771768020999698,-2.693400313409764
603.3000000000079,65.520763170001,0.07594559490587233,-2.696058193889006
604.4000000000078,65.63069361774085,0.07845683346350704,-2.697075723044704
605.5000000000078,65.74161342296017,0.07850096356650962,-2.6975905634299577
606.6000000000079,65.85108113496545,0.07878130566463389,-2.698370142286307
607.7000000000079,65.96143115316782,0.07882420365073972,-2.6996890808775227
608.8000000000079,66.07116707866662,0.07809093752482639,-2.70106431160199
609.9000000000079,66.18145639634925,0.07579957768468625,-2.7022993048580095
611.000000000008,66.29069033392577,0.07727153395570154,-2.7027181035254686
612.100000000008,66.40000207548582,0.07906382773742988,-2.7050704936305285
613.200000000008,66.51166912616816,0.07859236917165642,-2.706483341999575
614.300000000008,66.621602038038,0.07531369511978157,-2.7064098248494695
615.400000000008,66.73183653156998,0.07584769643049881,-2.7076998457600157
616.5000000000081,66.84276343442447,0.07449107485550831,-2.7076968619795423
617.6000000000081,66.95332525048401,0.07399128161049853,-2.709174107393109
618.7000000000081,67.06308770344678,0.07210980228732128,-2.710330004264662
619.8000000000081,67.17150059371441,0.0750417353552997,-2.7116497399162354
620.9000000000082,67.28247461924296,0.07234068740562996,-2.7127725945452603
622.0000000000082,67.39205608944337,0.07377786355966141,-2.7116499973474095
623.1000000000081,67.50193178729825,0.07447308658672898,-2.712970635213508
624.2000000000081,67.61253644748604,0.07432038582424158,-2.715574481309364
625.3000000000081,67.72192295432093,0.07498307598531151,-2.717024702855537
626.4000000000082,67.83186700765509,0.07470294880216095,-2.7154886545922508
627.5000000000082,67.93966312940243,0.0737699427770478,-2.7171066132039225
628.6000000000082,68.05206524357297,0.07478396243835747,-2.718866770369658
629.7000000000082,68.16183306341726,0.07553140535897489,-2.7199108765506383
630.8000000000083,68.27121722026199,0.07670902418458243,-2.7200999458117066
631.9000000000083,68.37953067570437,0.07556732301584107,-2.7214200103552066
633.0000000000083,68.49108905754193,0.07791775362911368,-2.7220514436882057
634.1000000000083,68.59891030497903,0.07386664908175551,-2.7240219910506673
635.2000000000083,68.71195760847594,0.07700293694023588,-2.722739931246754
636.3000000000084,68.8209720299171,0.0777719507758646,-2.7240598333071624
637.4000000000084,68.92968688106318,0.07856716896354635,-2.7253629048385717
638.5000000000084,69.04046379100527,0.07839566781002945,-2.7267015223049764
639.6000000000083,69.14956629043972,0.07934591069693751,-2.728010122773437
640.7000000000083,69.25874333094889,0.08036059400021378,-2.7280199690607367
641.8000000000084,69.36856396513205,0.07800581756577234,-2.729330086184067
642.9000000000084,69.47838182350696,0.0785141131870654,-2.7306530646390383
644.0000000000084,69.58757002049107,0.07803456795905585,-2.730650153393988
645.1000000000084,69.6976499481701,0.07473233137638424,-2.731961407328193
646.2000000000085,69.8071781966527,0.07520631710707856,-2.7332839001732987
647.3000000000085,69.91757063418643,0.0726254635318954,-2.7346003023399543
648.4000000000085,70.02713369624672,0.07044421578505984,-2.7345998068106736
649.5000000000085,70.13697780245585,0.07097844821888674,-2.7345608491862547
650.6000000000085,70.246432777665,0.07155926583520689,-2.7359529400863
651.7000000000086,70.35643282951762,0.06735066943957237,-2.737213340263452
652.8000000000086,70.46680632614206,0.06732892651502977,-2.735885859532484
653.9000000000086,70.57714906660347,0.06344073108591197,-2.7372263225206264
655.0000000000086,70.68599038170531,0.0608934697867434,-2.738189793366813
656.1000000000087,70.79782994404003,0.06179502590774209,-2.7385428718846647
657.2000000000087,70.90896998682814,0.056457804103067236,-2.7385227557135146
658.3000000000086,71.0210266293158,0.051052864769486825,-2.740519320687332
659.4000000000086,71.13110897027754,0.049114338810070435,-2.739748932168018
660.5000000000086,71.23968572553197,0.04561532230498791,-2.7410700292501256
661.6000000000087,71.35256907611935,0.04473989416546037,-2.7410678629488068
662.7000000000087,71.4632924807844,0.04155296686807139,-2.7423897975046385
663.8000000000087,71.5721800248629,0.037662496807117724,-2.743846065131831
664.9000000000087,71.68465211007062,0.0378214234600788,-2.7437394314214822
666.0000000000088,71.79581154742947,0.03561181611617001,-2.742404483028907
667.1000000000088,71.9068777115299,0.028531161746900985,-2.7423913701849587
668.2000000000088,72.01835257423893,0.027263210577751357,-2.742346871649377
669.3000000000088,72.12827746050444,0.024044497708214985,-2.745066079555283
670.4000000000088,72.23829629016892,0.018484950706585207,-2.7437102999902163
671.5000000000089,72.35106443611949,0.01384743439944075,-2.744701648245226
672.6000000000089,72.46207734504418,0.012717284231313658,-2.7451285959177394
673.7000000000089,72.5726656852667,0.01135733510764858,-2.744996456171915
674.8000000000088,72.68244382785849,0.007164692404185824,-2.746360807324987
675.9000000000088,72.79446527312939,0.008768719921716378,-2.748972828230819
677.0000000000089,72.90476567151892,0.0064633292091551275,-2.747240688591217
678.1000000000089,73.01565244878189,0.003982900235923653,-2.747402935110431
679.2000000000089,73.12644016806345,-0.001599353324507613,-2.74962719293881
680.3000000000089,73.23732653344909,-0.002922711572201059,-2.749670821603175
681.400000000009,73.3486335373074,-0.003791219492267184,-2.749654083477432
682.500000000009,73.45856349083816,-0.01139262443642064,-2.749640066772013
683.600000000009,73.57000201674055,-0.012327042279815292,-2.749640068671488
684.700000000009,73.68049208902045,-0.01848431515774171,-2.7522714544454496
685.800000000009,73.79080656215226,-0.0198273315303181,-2.753650468980255
686.9000000000091,73.90139733673901,-0.02674896978185612,-2.753920390899434
688.0000000000091,74.01300109494368,-0.029928787007969887,-2.7552398081087466
689.1000000000091,74.12372832604626,-0.031140428863372455,-2.755239241579095
690.2000000000091,74.23476899484443,-0.036673697329283134,-2.755113841375614
691.3000000000092,74.34469775521242,-0.0403453477168096,-2.7564196178535765
692.4000000000092,74.45576984654011,-0.0446640111357154,-2.7577585869444796
693.5000000000091,74.56576819478651,-0.04725818641451825,-2.75633004738185
694.6000000000091,74.67614932203412,-0.052679572035192246,-2.7589699917212682
695.7000000000091,74.78720072907416,-0.05696565937674393,-2.760273718994756
696.8000000000092,74.89784648941657,-0.05919680208809164,-2.7602829622729965
697.9000000000092,75.00756679273718,-0.06854589203224873,-2.7602788215518186
699.0000000000092,75.1188961719243,-0.07453415982324943,-2.7602806188209996
700.1000000000092,75.23000244602153,-0.07882546254595788,-2.762906714611078
701.2000000000093,75.34040270200353,-0.08503239479992442,-2.7625899853613403
702.3000000000093,75.45126739870871,-0.09060439449588946,-2.7643439134186956
703.4000000000093,75.56213744929966,-0.0975889502011173,-2.764343671302284
704.5000000000093,75.67311217677768,-0.10448135529268052,-2.761529820386344
705.6000000000093,75.78376275681715,-0.11281013026607332,-2.7629203654040166
706.7000000000094,75.89477193239935,-0.11744834811523862,-2.7643382786860613
707.8000000000094,76.00494794821262,-0.1260774634338039,-2.76487439049381
708.9000000000094,76.11578848750447,-0.12740839125095094,-2.764597509561043
710.0000000000093,76.22580966842929,-0.1337131695290609,-2.7659596590130704
711.1000000000093,76.33794866302314,-0.1415141555689256,-2.7674370308276552
712.2000000000094,76.44786554241716,-0.1517510161881908,-2.7672000609473963
713.3000000000094,76.55889416042245,-0.157228655514976,-2.7685201049695016
714.4000000000094,76.67068666651265,-0.16279779862771088,-2.7685200596265633
715.5000000000094,76.78030904758235,-0.16999622705846273,-2.769840031598818
716.6000000000095,76.8916623475501,-0.17534614286421776,-2.7711598309987546
717.7000000000095,77.00264562820404,-0.1799880326591697,-2.771146391876411
718.8000000000095,77.11350695296505,-0.18629559563905848,-2.771150711892812
719.9000000000095,77.22453552300314,-0.1948229202423468,-2.7724698151257714
721.0000000000095,77.3347680836425,-0.20335780622042046,-2.773759639835073
722.1000000000096,77.44663151657909,-0.2065178198658741,-2.7751616118651623
723.2000000000096,77.55781204371479,-0.2179765130487615,-2.7751380231810647
724.3000000000096,77.66865014781821,-0.2228658381621268,-2.7757772518224635
725.4000000000096,77.78073435295555,-0.22789602381925794,-2.776420018105767
726.5000000000097,77.89269556580646,-0.2375122360319997,-2.7777381920156463
727.6000000000097,78.00436372872288,-0.2439737090618937,-2.7777414180515696
728.7000000000096,78.11582432402363,-0.25079328892674163,-2.777845805562534
729.8000000000096,78.22836774032496,-0.2590655414812744,-2.779303487732003
730.9000000000096,78.33902512984861,-0.2610429408104671,-2.7805016758308154
732.0000000000097,78.4508288273932,-0.2691626004002131,-2.7804901669009814
733.1000000000097,78.56271055990393,-0.2738482536521316,-2.779168739404203
734.2000000000097,78.67416911963053,-0.27839049749132777,-2.7833002334270827
735.3000000000097,78.78647398766849,-0.28443569612695396,-2.7802932174859087
736.4000000000098,78.89768766033616,-0.2919194846443307,-2.7827901370382957
737.5000000000098,79.00806255636105,-0.2958522761700708,-2.7841084146013677
738.6000000000098,79.11745741777922,-0.3034338793671701,-2.7842194527658224
739.7000000000098,79.230945325059,-0.3101426949714208,-2.7868395810045072
740.8000000000098,79.342912436056,-0.31432554098323573,-2.787838057538722
741.9000000000099,79.45432665052004,-0.31800046022337614,-2.7878615302557592
743.0000000000099,79.56710695095373,-0.32691314576358327,-2.789025803118701
744.1000000000099,79.67818479990046,-0.3316962882185117,-2.789159577464609
745.2000000000098,79.7910116659826,-0.33853779461230293,-2.7905616419399735
746.0000000000099,79.87020160186773,-0.34084250136399596,-2.7894899764184413