File: 01_Data/Air_Fryer/STA/N2/10K_min/Air_Fryer_STA_N2_10KData_221116_R3.csv
##Temp./Â°C,Time/min,DSC/(mW/mg),Mass loss/mg
51.0,10.51,0.018146077788080417,0.017492359897107512
51.80000000000001,10.935301271750653,0.04410144478702138,0.012085421302191257
52.60000000000002,11.163068015258075,0.08450453839755823,0.012469878159897974
53.400000000000034,11.343247015429142,0.112394871102518,0.013188676617307493
54.200000000000045,11.499154872223112,0.1345277870945809,0.012899487342246552
55.00000000000006,11.63728852175825,0.1498941115196042,0.01520571695867634
55.80000000000007,11.772768002602819,0.16785464091497837,0.013626880391553797
56.60000000000008,11.898329871827197,0.180935294152907,0.013375238147901314
57.40000000000009,12.017212350195134,0.19178228156314825,0.01268663254304947
58.2000000000001,12.131658057562024,0.20559754627575888,0.013578692355586064
59.000000000000114,12.24493399804421,0.2132600379836469,0.018159734831494134
59.800000000000125,12.355797709280317,0.22615624913703636,0.01714983084449173
60.600000000000136,12.461240336913685,0.23218911412249255,0.014672145206872322
61.40000000000015,12.564918689810968,0.23831708714568567,0.01624298463588225
62.20000000000016,12.670149731673169,0.24455057527236534,0.01641709344568998
63.00000000000017,12.771714489514038,0.2495919919392795,0.016473565124112355
63.80000000000018,12.866342529948394,0.25764322620990376,0.01594586728581593
64.6000000000002,12.969291790186405,0.26246134420364275,0.014824880992839518
65.4000000000002,13.068555193711445,0.26569813794125285,0.016840690668316505
66.20000000000022,13.165409445192063,0.26891864691154166,0.018397015001339057
67.00000000000023,13.261088380318476,0.2718967186135366,0.018050065288862882
67.80000000000024,13.355658944190212,0.27564038328539553,0.018875434731294938
68.60000000000025,13.449312270529267,0.2795554754014209,0.017541003895081175
69.40000000000026,13.543123425079555,0.28245379776975255,0.01777102418217602
70.20000000000027,13.635216091026825,0.28429794854435264,0.016259916218723802
71.00000000000028,13.728740849341701,0.2850432016476133,0.016781993328202738
71.8000000000003,13.819760268906128,0.28533330957376535,0.01624853382275049
72.6000000000003,13.909370890983913,0.28812739484281025,0.017051463191989136
73.40000000000032,13.998789802569105,0.28909826035325725,0.016275950856339705
74.20000000000033,14.085561752334112,0.29027450828480716,0.016266775771363484
75.00000000000034,14.178219371174027,0.2922649169951761,0.016255939895710725
75.80000000000035,14.268232517463556,0.29321231820455074,0.01607556630081497
76.60000000000036,14.355642034592757,0.29661894412402134,0.015225043762402635
77.40000000000038,14.442125235138272,0.29780492487880583,0.017528118583519436
78.20000000000039,14.530746931814308,0.3008001278987765,0.019449380922756276
79.0000000000004,14.61782240777714,0.2997162886139737,0.01934054418809872
79.80000000000041,14.702934755851107,0.3025460218551719,0.018008022837559423
80.60000000000042,14.786774001068022,0.3051786594113376,0.015309022432196784
81.40000000000043,14.875001290147448,0.30582687145664855,0.014138440308482991
82.20000000000044,14.960487733261493,0.3104338348106166,0.015592219781591865
83.00000000000045,15.044854063858278,0.30961394038061374,0.016019075681171557
83.80000000000047,15.130984131468205,0.3108565073116277,0.016593323030829943
84.60000000000048,15.214893377724366,0.31213924180637553,0.015278050189299286
85.40000000000049,15.299503533968764,0.31557601337001273,0.016536492278804715
86.2000000000005,15.380715994711878,0.3152410669982806,0.016540372928748326
87.00000000000051,15.464399176704454,0.31534310027239887,0.017857495867479756
87.80000000000052,15.54873367837926,0.3180198414128369,0.01682025495797035
88.60000000000053,15.630998324585649,0.31813341388041483,0.01791071099510777
89.40000000000055,15.71476485895897,0.32114929356142896,0.01790349607785746
90.20000000000056,15.796276272292836,0.32390710950694657,0.0192218229287775
91.00000000000057,15.879465389342762,0.32410190774744607,0.020368556675000704
91.80000000000058,15.961581517813302,0.32686236509622935,0.01923312756234896
92.60000000000059,16.041114228453928,0.3260466701171365,0.019229644127486623
93.4000000000006,16.122654322336174,0.32895784593677246,0.01922379954443798
94.20000000000061,16.203760143191886,0.3280688650097864,0.020848616471806025
95.00000000000063,16.28231533563949,0.32950484312662864,0.01956064953246983
95.80000000000064,16.36420372304803,0.3339421580994246,0.016814612577908505
96.60000000000065,16.44404915009178,0.33531172565242073,0.017605270168912668
97.40000000000066,16.522709524328647,0.33570028972079313,0.018089786920603146
98.20000000000067,16.60102709381364,0.3343647531127495,0.018007967203938158
99.00000000000068,16.684548541847906,0.3362948054130862,0.01974494055485465
99.8000000000007,16.764350268753283,0.3352971840405571,0.02054737971442755
100.6000000000007,16.84379511654392,0.33912464351279437,0.017880555109539564
101.40000000000072,16.922766491660703,0.3412241014465165,0.016689068227586645
102.20000000000073,17.003173175357993,0.34338776170987917,0.017898375709478387
103.00000000000074,17.080968189663512,0.3418685529652119,0.01796553011962132
103.80000000000075,17.162047670582773,0.343128097328128,0.01791394535361679
104.60000000000076,17.240363025072977,0.3452853857825464,0.016565896477057862
105.40000000000077,17.31819878756318,0.3433312525942477,0.0166017185267906
106.20000000000078,17.39735326818131,0.3440830003509593,0.016553914709895423
107.0000000000008,17.475642240285545,0.3482562536615149,0.01691974823536757
107.80000000000081,17.55559473063875,0.3455015219119816,0.017922936947295298
108.60000000000082,17.632913140550443,0.34792674910008725,0.019244672932459572
109.40000000000083,17.711768789120267,0.34589031863340836,0.020024384651769367
110.20000000000084,17.790334526092245,0.34814440201282715,0.020529989254026937
111.00000000000085,17.869700830576512,0.3492569697523934,0.020511150994451555
111.80000000000086,17.947954515953345,0.35031606628308287,0.020212568882003623
112.60000000000088,18.024772658026343,0.3518431719355519,0.021202793121333663
113.40000000000089,18.104284498244073,0.3545362282871237,0.019662008056607228
114.2000000000009,18.18255284150392,0.35440201945789795,0.0183169177532454
115.00000000000091,18.26105053099757,0.35839928353531414,0.01867013990285482
115.80000000000092,18.337774471369325,0.35578974083922965,0.01884473974894796
116.60000000000093,18.416754916672353,0.3561628174613316,0.018670010877018584
117.40000000000094,18.495120718297912,0.3579705552096185,0.019721084712263526
118.20000000000095,18.572968366683252,0.3617274504699681,0.018679738561553805
119.00000000000097,18.650423178583676,0.35895220299557984,0.01802129457622037
119.80000000000098,18.727325642957922,0.3619791741067274,0.01897459594148465
120.60000000000099,18.805580804526844,0.3631447839098122,0.018670045944905844
121.400000000001,18.88310090240193,0.36644600893558943,0.019174759053992574
122.20000000000101,18.96019785920631,0.36660657956286324,0.018985664539717284
123.00000000000102,19.039066811009114,0.3650822100973813,0.018670489353732833
123.80000000000103,19.116991800515894,0.36542501031639674,0.018659498207550307
124.60000000000105,19.194222330142015,0.36790458112512747,0.018302870149049966
125.40000000000106,19.27140862072291,0.3694717016048177,0.01767971615688957
126.20000000000107,19.348239536895242,0.37162919096878255,0.017680049544586574
127.00000000000108,19.427418603193008,0.37291322115039915,0.018228147213701362
127.80000000000109,19.50381548736097,0.37250010852531823,0.017287799291460182
128.6000000000011,19.581101874988793,0.3760875597987805,0.018668089795171205
129.4000000000011,19.658518037646388,0.37621806595101903,0.018670117011443388
130.20000000000113,19.734651859458243,0.3801395022989401,0.018788232254848936
131.00000000000114,19.811979772017185,0.3804396427556148,0.018669333961141454
131.80000000000115,19.88973082699352,0.3837393171515493,0.01801970427133881
132.60000000000116,19.963898777682907,0.3845001683971935,0.018047096460721335
133.40000000000117,20.043107034543596,0.38852299176621663,0.019309301305279192
134.20000000000118,20.119905966140053,0.3918172912086867,0.018009953443006488
135.0000000000012,20.197385872839973,0.3948219405631197,0.016860485276190218
135.8000000000012,20.273810007455133,0.3967193718365496,0.018056770545923584
136.60000000000122,20.350800733669757,0.40028756964088397,0.016693443463213775
137.40000000000123,20.427205593152838,0.40366254319487227,0.018010175178027055
138.20000000000124,20.5048024210777,0.40811657915437005,0.017984321535078784
139.00000000000125,20.58000000000011,0.4114019032566343,0.018018217774142364
139.80000000000126,20.656200611394063,0.41557197896796055,0.01801830996637932
140.60000000000127,20.73351239736826,0.4211828531410293,0.01864908183648417
141.40000000000128,20.810657793641102,0.4247998242677861,0.019329288154509072
142.2000000000013,20.886632777836528,0.4325020016934387,0.019336266956606174
143.0000000000013,20.963069666544374,0.4384709587697582,0.02032666164902075
143.80000000000132,21.03929859422321,0.4450564937914178,0.01902311356362496
144.60000000000133,21.11615342996749,0.45010490927995256,0.018967649431099076
145.40000000000134,21.192465996631373,0.4580696197333886,0.016343728539752078
146.20000000000135,21.269029585029504,0.46883949271345143,0.01504986874622638
147.00000000000136,21.345725136144175,0.47549031599715186,0.016392660023445416
147.80000000000138,21.42038356490118,0.48672940231113493,0.016503702409838006
148.6000000000014,21.498535813417845,0.49912903563402194,0.017679792363648694
149.4000000000014,21.573127461455037,0.5088105658324309,0.017680228446967483
150.2000000000014,21.65125479281086,0.5226827331050489,0.0176244165072168
151.00000000000142,21.72720390015951,0.5380157645988348,0.017680071198009628
151.80000000000143,21.80323717605414,0.5571044362590745,0.01747963100349903
152.60000000000144,21.880335732825888,0.5736249818914428,0.01635992565269273
153.40000000000146,21.956487675416366,0.5959583303719898,0.016314396012632848
154.20000000000147,22.032276740820713,0.6184835577750851,0.016542150447942383
155.00000000000148,22.110536597201726,0.6420100544685255,0.01899710217727879
155.8000000000015,22.184863563123987,0.672841422263029,0.020312395793282256
156.6000000000015,22.261297683665966,0.7036746975942634,0.018997811202865478
157.4000000000015,22.338296984503714,0.741894648010152,0.017650249132429963
158.20000000000152,22.414253907213354,0.7840610579362248,0.018337462040800112
159.00000000000153,22.490788197369348,0.8309456345129762,0.019000061768626786
159.80000000000155,22.568062382377136,0.8820170651580957,0.01899984617488215
160.60000000000156,22.644677528581155,0.9403555118754172,0.0176711187975247
161.40000000000157,22.72126125075732,1.003184540887883,0.01866870320222702
162.20000000000158,22.79806770943221,1.0714304449020269,0.018670419557789586
163.0000000000016,22.875298418669963,1.142732914332491,0.017710474270421273
163.8000000000016,22.95135185967515,1.2150866877698712,0.020396702561927604
164.60000000000161,23.027868694563914,1.2863031066766524,0.02030712182998684
165.40000000000163,23.10511817843545,1.3549871204214972,0.020308382720010343
166.20000000000164,23.182234574601804,1.4172784630311144,0.018903872033149582
167.00000000000165,23.258989324338312,1.4761265492202948,0.01899984239086283
167.80000000000166,23.33554095793713,1.5277659209084025,0.018822179540149087
168.60000000000167,23.41269353213401,1.5642081577789848,0.018981839212379725
169.40000000000168,23.489899685371377,1.5765707373982631,0.020320056762172634
170.2000000000017,23.565398617116415,1.5506798599883609,0.0203194131357467
171.0000000000017,23.642693156482355,1.4741572285646558,0.021319835993672598
171.80000000000172,23.71909974188947,1.3378541355712574,0.017198747774469503
172.60000000000173,23.793862912805583,1.1612278854009166,0.0171471502091336
173.40000000000174,23.870001025469268,0.9685343479193886,0.015809826502892754
174.20000000000175,23.944995782639495,0.8069230086146981,0.014512017964453783
175.00000000000176,24.021455656760775,0.6906894307117288,0.015810059420561018
175.80000000000177,24.0944650029458,0.617627904299314,0.016210196195897808
176.60000000000178,24.169912151078243,0.5661145389379016,0.015819720975062346
177.4000000000018,24.2464181535473,0.5332749167978481,0.017141258090537015
178.2000000000018,24.320186091579345,0.5105665888958766,0.01857478636560117
179.00000000000182,24.39618661419724,0.4960483013330207,0.021883637393035116
179.80000000000183,24.470558038424873,0.4857386404983788,0.021525351645221846
180.60000000000184,24.547613099045407,0.4780217457166209,0.020208836690946974
181.40000000000185,24.622521187173746,0.4734070071973586,0.017370790963083138
182.20000000000186,24.699061453790176,0.4694616277362646,0.016838324493157586
183.00000000000188,24.77424355270993,0.4691412271489679,0.017617139219748168
183.8000000000019,24.849901372315543,0.4672735568827592,0.016254626688885665
184.6000000000019,24.926212999688694,0.4652257500991238,0.014968811373054614
185.4000000000019,25.001416725904964,0.46623394515777566,0.013623141766061053
186.20000000000192,25.07735763380404,0.4672929655580013,0.013947289151178488
187.00000000000193,25.151131629930163,0.46430020896810803,0.016292930768570635
187.80000000000194,25.22861018934207,0.46470420977954685,0.016327205996407912
188.60000000000196,25.303678401827334,0.4644984260454192,0.016253838340531068
189.40000000000197,25.380183072452667,0.4648974057285183,0.017579892954475262
190.20000000000198,25.456761823525895,0.46255076870727546,0.017582352504674326
191.000000000002,25.531852348435983,0.46538046023542484,0.017564813201946805
191.800000000002,25.60700166067601,0.4636496385157778,0.01789225060231292
192.600000000002,25.681172206713025,0.46235098630533517,0.01789112467395615
193.40000000000202,25.758256526497743,0.46193848006983945,0.017920991384782425
194.20000000000203,25.834191449067806,0.46285413466787995,0.019220465520553454
195.00000000000205,25.910608023292724,0.4623833027111429,0.01921998586247664
195.80000000000206,25.986035553083042,0.46242509247082425,0.01818897245073181
196.60000000000207,26.060274803993146,0.4646653674447031,0.016584788421631025
197.40000000000208,26.135673976865576,0.46160867047214543,0.01658020919351877
198.2000000000021,26.210098978123227,0.4654092629582399,0.01658923481840091
199.0000000000021,26.286501375349523,0.4669003170455914,0.017909256720701094
199.80000000000211,26.362221423971096,0.4663330395935089,0.017893670268660955
200.60000000000213,26.435775049433552,0.4666366077664257,0.017590129316252145
201.40000000000214,26.515750031167794,0.4653692407517105,0.017271208873602895
202.20000000000215,26.591723667081965,0.46590213734952873,0.01691160645101064
203.00000000000216,26.666721960623164,0.4674804020860035,0.01658976923826483
203.80000000000217,26.742985630213052,0.4704901004463906,0.01658988726815913
204.60000000000218,26.815914323389094,0.4701618536551657,0.01786653742339972
205.4000000000022,26.893352924154986,0.46952384605244313,0.017991863961333898
206.2000000000022,26.969918424663565,0.47071349613817537,0.016579951381505253
207.00000000000222,27.044902818602985,0.47271261133322445,0.01788129694875007
207.80000000000223,27.120751055123215,0.4715226219430081,0.016559333335485427
208.60000000000224,27.194613007104977,0.4716908790501434,0.01526995637641626
209.40000000000225,27.273064208247337,0.47284619750458523,0.015201889148189096
210.20000000000226,27.347748930481757,0.47138691823139556,0.016589845916304746
211.00000000000227,27.424324449939828,0.47145753858767236,0.016589967248066273
211.80000000000229,27.499907740421566,0.4712835196132712,0.015287907939566914
212.6000000000023,27.57571441895602,0.4741894366890409,0.01658862054018062
213.4000000000023,27.651690782708037,0.47353817519544616,0.016585939415015183
214.20000000000232,27.724958872561583,0.47523774181747314,0.016593135226775857
215.00000000000233,27.80301588846446,0.4769160919319147,0.01657986499150521
215.80000000000234,27.878975684585217,0.4757834338121925,0.01525713979808252
216.60000000000235,27.95428680729683,0.47608330187618075,0.015259885151378327
217.40000000000236,28.029818142878813,0.47526523051650227,0.015237994355011608
218.20000000000238,28.105903398617134,0.47655048409773465,0.015589892421377094
219.0000000000024,28.180857648498847,0.47793271797062165,0.01562566170520263
219.8000000000024,28.257588436613176,0.4803007251737438,0.016893666994207912
220.6000000000024,28.33275138238447,0.4761883391653362,0.015599383676405232
221.40000000000242,28.406764231666205,0.4767766447307562,0.01592479358357224
222.20000000000243,28.485141549728993,0.4764208239382588,0.015930088642002183
223.00000000000244,28.560579969837484,0.478121510779309,0.015930089351039456
223.80000000000246,28.63462588839786,0.4777200201328241,0.015914190427022135
224.60000000000247,28.711815503204246,0.476876267016141,0.016260853422678245
225.40000000000248,28.788328652781036,0.4780723592520236,0.015930630358459652
226.2000000000025,28.86363985628382,0.47889741754400794,0.014786006404311713
227.0000000000025,28.938446880140354,0.47877985177685545,0.015597278559795313
227.8000000000025,29.015249364822505,0.4797090489144801,0.015606003584593076
228.60000000000252,29.09163185256008,0.47999576834458824,0.014280396293615105
229.40000000000254,29.167379325587522,0.47923735751075625,0.01558900803267349
230.20000000000255,29.243144108314326,0.48120893599102155,0.014882426224576584
231.00000000000256,29.31818051712176,0.48183487811380754,0.014609826007731641
231.80000000000257,29.394246250311202,0.4838629843357646,0.014237948636096398
232.60000000000258,29.47077736154966,0.4850322952952769,0.011427902896024023
233.4000000000026,29.546895714569615,0.48491127145149815,0.010103663926421369
234.2000000000026,29.621518368543033,0.48351032634598523,0.010542184870294236
235.00000000000261,29.697140810330307,0.4844551828823509,0.011097479903738439
235.80000000000263,29.77220416907153,0.4835687006432531,0.011549092422056262
236.60000000000264,29.84928377828255,0.4878854260914077,0.013703254706795676
237.40000000000265,29.92416392915225,0.4859807242997801,0.015173230239499347
238.20000000000266,30.00089162910483,0.4849221514968284,0.015143675675943769
239.00000000000267,30.074054267758445,0.4866470083074774,0.016417477417855153
239.80000000000268,30.151643718707636,0.48733249767103937,0.013859882856902317
240.6000000000027,30.226742495254072,0.4877253909603105,0.01227752300168028
241.4000000000027,30.302919001801122,0.48550750191104164,0.01196982491377696
242.20000000000272,30.3792454409432,0.4848235904504016,0.01197003661185203
243.00000000000273,30.455370425537254,0.48811698324898245,0.01306739897190301
243.80000000000274,30.531120104066773,0.4869640175908214,0.012286078947769674
244.60000000000275,30.606239933797042,0.4857545342621684,0.011970881710148262
245.40000000000276,30.682589302153847,0.4889136059796434,0.013388779902941295
246.20000000000277,30.757597011711255,0.4900316428748101,0.01462285077182024
247.00000000000279,30.834470162808984,0.4881920866568962,0.01592375897969145
247.8000000000028,30.90970754974094,0.490574997389985,0.01320679430025784
248.6000000000028,30.985123886806416,0.4901364278167185,0.010492571123823069
249.40000000000282,31.061309547527557,0.4906088623905987,0.011869777340566934
250.20000000000283,31.13687170165477,0.49089155690354924,0.011869938333822994
251.00000000000284,31.21188660068612,0.4927326599045818,0.013206799048820272
251.80000000000285,31.289169706986662,0.49125442257841373,0.013180027159441998
252.60000000000286,31.362971278830848,0.49062811894080055,0.014545982689805115
253.40000000000288,31.441293823963804,0.48983272225531627,0.015850934450064358
254.2000000000029,31.517343279312975,0.48995630209429525,0.013883614240474351
255.0000000000029,31.592646101895337,0.49245464046867526,0.011861021643499114
255.8000000000029,31.665260047907996,0.49231301705755315,0.011893670683759794
256.6000000000029,31.74394185362393,0.4927054610925037,0.01165984349520599
257.40000000000293,31.82055040554548,0.4924115627874309,0.01187880932026264
258.20000000000294,31.895741246699515,0.491783059163608,0.011867654900039604
259.00000000000296,31.97025669330054,0.48906470527494017,0.010540039179475436
259.80000000000297,32.049243985719116,0.4932124247806944,0.010539992155420563
260.600000000003,32.12347525468916,0.49393847784144795,0.010552815622370204
261.400000000003,32.199282671626776,0.4918395744760901,0.011854514659169979
262.200000000003,32.27560231270014,0.4934904385554397,0.013179320042922882
263.000000000003,32.35125426300078,0.4913228045587645,0.011830664360704901
263.800000000003,32.428243888649554,0.491940589405478,0.011956798722134288
264.60000000000304,32.50453723923713,0.4904702528663386,0.011941686683397457
265.40000000000305,32.58050001389379,0.493336712875432,0.009995787169022385
266.20000000000306,32.65661487428462,0.4921624887167555,0.010658838826173245
267.00000000000307,32.73274431180197,0.4904710080051825,0.0113220462686634
267.8000000000031,32.80831068434376,0.4931058917241419,0.010005133020443147
268.6000000000031,32.88427484758607,0.4927528737066683,0.007978976810223415
269.4000000000031,32.960249081568506,0.49485674156406223,0.00934028261743336
270.2000000000031,33.03663853713002,0.4949960249927083,0.010658327764174302
271.0000000000031,33.11260471337396,0.49527053530853954,0.010055102198628596
271.80000000000314,33.18862574029131,0.4958728579610835,0.008352720496657362
272.60000000000315,33.26543993349847,0.49587861105749803,0.009662599549999484
273.40000000000316,33.341510280021694,0.4961294174582661,0.011099750647131756
274.2000000000032,33.41761110382882,0.49698312735016364,0.011070229144407584
275.0000000000032,33.49334418616956,0.4965212861800185,0.008453406182678869
275.8000000000032,33.569237461400945,0.4981409740134051,0.008130087178511936
276.6000000000032,33.64486808338517,0.4972611934045049,0.008374245804116498
277.4000000000032,33.72171564446797,0.49876170550922405,0.010236794348236877
278.20000000000323,33.79699850261578,0.49977348945181144,0.010867482472699308
279.00000000000324,33.87321554292346,0.49841142221392387,0.009561803206334929
279.80000000000325,33.95059066762148,0.5002805164736626,0.009560179291779214
280.60000000000326,34.02610229240817,0.5002983134710433,0.009543144839523343
281.4000000000033,34.10263561985922,0.5006683510124134,0.009888419664799919
282.2000000000033,34.17853917668243,0.5020147619336137,0.00988990504759446
283.0000000000033,34.254601778208325,0.5006128383400913,0.009889905003796606
283.8000000000033,34.331023303998485,0.5022084081263773,0.009889924891959723
284.6000000000033,34.407090763489926,0.502180531983495,0.009561518065761554
285.40000000000333,34.48303078362963,0.5015349753428908,0.00956264190312428
286.20000000000334,34.55979182228182,0.5050726129914624,0.006949100372011685
287.00000000000335,34.63546988427014,0.5019913102736547,0.006930177143564364
287.80000000000337,34.71255526081392,0.5041100444500847,0.006901072078895787
288.6000000000034,34.78817374026898,0.5028060910759518,0.00824001443386635
289.4000000000034,34.86507364676283,0.5044995403991053,0.009668425101120981
290.2000000000034,34.941779962484105,0.5029128067059165,0.010556985066017432
291.0000000000034,35.0188163517964,0.5065658811657512,0.010536033070053463
291.8000000000034,35.09440492317356,0.5038548580295636,0.007153592900813521
292.60000000000343,35.17064899749632,0.5041993125117136,0.006095794701956869
293.40000000000344,35.24709719545227,0.5038543696268276,0.007370142940431812
294.20000000000346,35.3236486324302,0.5072604014778529,0.007370164271444324
295.00000000000347,35.40088290459154,0.5038511122684256,0.006678479593568376
295.8000000000035,35.476480924611636,0.5040852389668018,0.004729829570742972
296.6000000000035,35.55397061514976,0.5043971208482594,0.004696598558320275
297.4000000000035,35.630872612383506,0.5051066238929464,0.006050724363998228
298.2000000000035,35.70688121441691,0.5039421797279027,0.0047269749600404865
299.0000000000035,35.78301233686413,0.5063625225232694,0.004742744006764887
299.80000000000354,35.86091721939411,0.5042981387521752,0.0060501682985627525
300.60000000000355,35.937007588996885,0.5045771479307782,0.006050145928833572
301.40000000000356,36.01282959238622,0.5051514597738846,0.006034429802821428
302.20000000000357,36.08981940621102,0.5083351007611785,0.004741287076448941
303.0000000000036,36.16541460689611,0.5097629930287298,0.0037818180456401507
303.8000000000036,36.24154523890917,0.5106818342174885,0.003867083033025409
304.6000000000036,36.317757025474634,0.50886329645875,0.004900351345458631
305.4000000000036,36.3956772293985,0.5115158579110392,0.00342133491857588
306.2000000000036,36.46967251351374,0.5134674849776273,0.004392029161719435
307.00000000000364,36.54889310586287,0.5119694782308628,0.004729875011572737
307.80000000000365,36.6243869337193,0.5123420121347425,0.004729870406102066
308.60000000000366,36.70140797017929,0.510674089181072,0.004710072928668652
309.4000000000037,36.7777066635799,0.5104836350186923,0.005389976856513101
310.2000000000037,36.85424331013132,0.5109147040941512,0.005390025997280112
311.0000000000037,36.93112415578513,0.5110826148987428,0.005390024378507441
311.8000000000037,37.00710786532021,0.5111987522471937,0.005365199312757696
312.6000000000037,37.08318185644663,0.5131722234961922,0.005375668475092077
313.40000000000373,37.15924931538996,0.510993213728802,0.005059426390586985
314.20000000000374,37.2359025905753,0.5115264135313655,0.003761520039732069
315.00000000000375,37.31241615673222,0.512684607373991,0.003739948533454829
315.80000000000376,37.389234103528004,0.5116600668183169,0.0037399491867509127
316.6000000000038,37.468532586346896,0.5094990240738304,0.003742179017659275
317.4000000000038,37.5455775514649,0.5122637664520862,0.002752048083504377
318.2000000000038,37.62199943230347,0.5112070555879297,0.0027503092286442765
319.0000000000038,37.6991270732411,0.5123097628273284,0.0014288551765515578
319.8000000000038,37.774735536827215,0.5121504121290866,0.0014301248189578786
320.60000000000383,37.852556711889726,0.5154131694710242,0.0014301249999943977
321.40000000000384,37.930095124045735,0.5172506910151704,0.0014301250000272603
322.20000000000385,38.00619046124037,0.5125225366545471,0.001430107309301043
323.00000000000387,38.08243231295583,0.5142653022806571,0.0022882241183257435
323.8000000000039,38.159721611965075,0.5162524410187834,0.0027500380610883113
324.6000000000039,38.23682050220464,0.5150605482615418,0.003994377008476491
325.4000000000039,38.31316371804676,0.5144599062159088,0.0032462707021148063
326.2000000000039,38.39142142423285,0.5137560694351668,0.0013839016164993723
327.0000000000039,38.46751221889165,0.5158556338096497,0.0013829064620196618
327.80000000000393,38.54411974325471,0.5132598328344674,0.002749788198564751
328.60000000000394,38.621605803914,0.5152978853834286,0.0014297407700247788
329.40000000000396,38.69828434826522,0.5161899509855783,0.0006045937134100399
330.20000000000397,38.775491101480306,0.514170803144313,-0.001260029838410226
331.000000000004,38.85296943843233,0.5174980721078959,-0.0008698669545363913
331.800000000004,38.93009321532879,0.5201159071052537,-0.0011907598330367364
332.600000000004,39.00699067754349,0.5194556305542548,-0.0011653073871977782
333.400000000004,39.0841040802916,0.5198112244475601,-0.0002110349941535361
334.200000000004,39.1611447972874,0.5213088790254402,0.00011530025568706748
335.00000000000404,39.23867097318259,0.522421943755704,-0.0013603866502869266
335.80000000000405,39.315770814429456,0.5223094325992694,-0.00273098182661613
336.60000000000406,39.392220690383155,0.5216534662394681,-0.0027301945099473812
337.40000000000407,39.46973689284262,0.5236845894401571,-0.002727077741255357
338.2000000000041,39.548136031781986,0.5247595285714739,-0.0014204097949059857
339.0000000000041,39.62467054490974,0.5253057978413371,-0.0020517163380811
339.8000000000041,39.70244895593926,0.5249611769776175,-0.003389002822804521
340.6000000000041,39.77999908245757,0.5213578954182878,-0.003364683484446296
341.4000000000041,39.8566224194922,0.5215004184960933,-0.0038609161658573754
342.20000000000414,39.93393225510901,0.5253351601003755,-0.0027861085771272442
343.00000000000415,40.01103056539668,0.5260891359035418,-0.002072578120905
343.80000000000416,40.088237737406494,0.5265158075629408,-0.004050191067461739
344.6000000000042,40.16501249876739,0.5304879145038396,-0.0032283293075252573
345.4000000000042,40.242322322623,0.5267521420779913,-0.0027302008780321074
346.2000000000042,40.31850429193543,0.5286177538371162,-0.0027320957941414648
347.0000000000042,40.39532335873111,0.5331101075866944,-0.004051095504810753
347.8000000000042,40.47303216070149,0.5310486028356196,-0.002729614035343886
348.60000000000423,40.54891747733125,0.5301598638265985,-0.002717885117323071
349.40000000000424,40.62639039432099,0.5311169802758254,-0.00613697852155326
350.20000000000425,40.7037680070381,0.5324427147423488,-0.005993406055070594
351.00000000000426,40.78079597895384,0.5363768062251708,-0.0054633891981819005
351.8000000000043,40.85853985819944,0.5348236472350307,-0.00679795711339537
352.6000000000043,40.93568714021499,0.5363295364107487,-0.00801701707098701
353.4000000000043,41.01282958107723,0.5351909833373094,-0.0068001225335745374
354.2000000000043,41.0921602217127,0.5366961896925373,-0.00686182059507523
355.0000000000043,41.169344817599956,0.537171828340685,-0.008120784975363726
355.80000000000433,41.245314602701455,0.5364551870228416,-0.010817168728748605
356.60000000000434,41.32250119652044,0.538061625929967,-0.010281985227187818
357.40000000000435,41.40085434966183,0.5370412389189192,-0.009555176133523524
358.20000000000437,41.47811939739277,0.5377519833315134,-0.010860027257633575
359.0000000000044,41.55543795245183,0.5398873353318084,-0.009937785813710853
359.8000000000044,41.63316910082942,0.5399360616842446,-0.009549460564304724
360.6000000000044,41.710582298400624,0.5397940087778813,-0.009220087209079963
361.4000000000044,41.78754035389958,0.5416609544091693,-0.010417653821808592
362.2000000000044,41.864830399055776,0.5401854407168382,-0.011246636117065556
363.00000000000443,41.94215343309926,0.539866576544679,-0.010860179257766944
363.80000000000445,42.01863824668572,0.540289252615539,-0.0108601409977096
364.60000000000446,42.09774164195218,0.5425638538895394,-0.010860140999998436
365.40000000000447,42.17447937881652,0.5442172789378829,-0.010860141000000212
366.2000000000045,42.251445524422124,0.5449305067785343,-0.010860141000047285
367.0000000000045,42.33009948277771,0.5461442066880471,-0.01086014111359912
367.8000000000045,42.40674302302152,0.5436089451286584,-0.010792556880435455
368.6000000000045,42.48450431713441,0.5475494845757434,-0.011520032294156657
369.4000000000045,42.56174337158289,0.5478454009851065,-0.012845294343160063
370.20000000000454,42.63862580522834,0.5481487251828103,-0.014063043543106168
371.00000000000455,42.71523565027143,0.5503937035251598,-0.015469137960104185
371.80000000000456,42.7938472509168,0.5491471088543552,-0.015480368130679878
372.60000000000457,42.87110312380121,0.5471485492158313,-0.0167907000057248
373.4000000000046,42.948629272970095,0.5521905026273923,-0.016757004303020295
374.2000000000046,43.026164562332106,0.547657679591584,-0.01677672390340934
375.0000000000046,43.10340493111184,0.5485321704607006,-0.0141168214586882
375.8000000000046,43.180559909302815,0.5522226441024538,-0.014148714353388492
376.6000000000046,43.258527098990896,0.5502082068004608,-0.013490839765524676
377.40000000000464,43.33584987778567,0.5529693882335116,-0.014814804611679833
378.20000000000465,43.41367523887052,0.5502249809226305,-0.016966177309011954
379.00000000000466,43.491135670384814,0.550348114573534,-0.020551105980649353
379.8000000000047,43.56943884786927,0.5498693222140162,-0.021503572362209233
380.6000000000047,43.64600950868996,0.5514128727737286,-0.021391117859014486
381.4000000000047,43.72314404555184,0.5480511987019743,-0.021512796746959495
382.2000000000047,43.800928849056646,0.5516734976175122,-0.027704550799475314
383.0000000000047,43.87930356992892,0.5501475073003516,-0.029199967594746745
383.80000000000473,43.956510255497605,0.5520897927589683,-0.028123310155073966
384.60000000000474,44.035063167107545,0.5555358602658955,-0.026755988539354014
385.40000000000475,44.11191279675355,0.5556651482265478,-0.02547195502682076
386.20000000000476,44.18943608342358,0.5579561587244637,-0.026780114859893622
387.0000000000048,44.26699797245182,0.5574560427012899,-0.02810318536193801
387.8000000000048,44.344196559967706,0.5592650015861967,-0.028012932455062867
388.6000000000048,44.422795081840896,0.5593910254319637,-0.02802479296329352
389.4000000000048,44.50073861130345,0.5611210026287581,-0.02930012760508749
390.2000000000048,44.57786052906888,0.5613612245525507,-0.029300122001436613
391.00000000000483,44.65614589921341,0.5593379865482255,-0.029300205832937465
391.80000000000484,44.733834436313344,0.5623496255419604,-0.03067003077539887
392.60000000000485,44.8117090863006,0.559488425727751,-0.030536296241276517
393.40000000000487,44.88952761000743,0.5631910300604126,-0.029089657269111058
394.2000000000049,44.96718173866321,0.563383055130344,-0.029392676253735317
395.0000000000049,45.045364963806705,0.5607754571672044,-0.03504623445002508
395.8000000000049,45.12356239493418,0.5612090712685268,-0.03673399376448838
396.6000000000049,45.20269949088387,0.5633925858026192,-0.03897007575069722
397.4000000000049,45.27893537064989,0.5635269446313422,-0.040281898446093756
398.20000000000493,45.35725249048754,0.5683689075784332,-0.04217969195076421
399.00000000000495,45.434751729635835,0.5711207032469041,-0.04406766275953444
399.80000000000496,45.51230710594044,0.5724990443697744,-0.04642919476389107
400.60000000000497,45.59068941682763,0.5729255172053329,-0.04643000527097829
401.400000000005,45.66911809844021,0.5733787134854935,-0.04775934284885608
402.200000000005,45.747195467451824,0.5740286800388023,-0.048442286149854574
403.000000000005,45.824834605043286,0.5736108248048193,-0.05168362252224057
403.800000000005,45.902820487306165,0.5736015731734336,-0.058096739392971664
404.600000000005,45.980202033764805,0.5719972894080073,-0.059169958192746286
405.40000000000504,46.058161073731924,0.5709534456191965,-0.05783318101220214
406.20000000000505,46.13611030584875,0.5689700847508993,-0.05813892043039459
407.00000000000506,46.21364633362927,0.5715442296578103,-0.06080891362806007
407.80000000000507,46.291746303975174,0.5717551614813288,-0.06076232693952832
408.6000000000051,46.369531797838334,0.5715850635916899,-0.061470177082545874
409.4000000000051,46.44735928055269,0.5696506390559339,-0.0614710700836234
410.2000000000051,46.525944058245244,0.5719888730052409,-0.06540898406031737
411.0000000000051,46.60348852307406,0.5675492262148665,-0.0680994467332301
411.8000000000051,46.681612224995334,0.5696176399229486,-0.07085622287842863
412.60000000000514,46.759444801570595,0.5744777227368979,-0.07441365493297214
413.40000000000515,46.83873480322159,0.5751751789786606,-0.07570680594986712
414.20000000000516,46.91499415777916,0.5791687269653832,-0.07705993046737802
415.0000000000052,46.9943278462315,0.5785768578823437,-0.07870235274681825
415.8000000000052,47.07156786383454,0.5792240690014339,-0.08082950155691826
416.6000000000052,47.14990429692606,0.5851416113170226,-0.083209920985015
417.4000000000052,47.22854753407862,0.5882833145745372,-0.08601036978389409
418.2000000000052,47.306409697215706,0.5935395190445796,-0.09143417284031496
419.00000000000523,47.38422773054896,0.5968535406968523,-0.09144981241730488
419.80000000000524,47.46245171267178,0.6049909862866065,-0.0904579966584933
420.60000000000525,47.5403814535629,0.6092039386074908,-0.09477928622615117
421.40000000000526,47.61913573140007,0.6180772769960046,-0.10380748206084744
422.2000000000053,47.69719282249141,0.6240772305181812,-0.10800751797960073
423.0000000000053,47.77538904919428,0.634308872346454,-0.10888616668647089
423.8000000000053,47.85337353588606,0.6454454181674362,-0.1128844234248807
424.6000000000053,47.93123563961799,0.6559496094792251,-0.11925437113833359
425.4000000000053,48.00960378943816,0.6676310676028064,-0.12151722874169968
426.20000000000533,48.08731477396177,0.6801215853621624,-0.12700256233518514
427.00000000000534,48.16675606275687,0.6966897722781165,-0.13521937170668474
427.80000000000535,48.24469162156238,0.7098628946849457,-0.14022432460398937
428.60000000000537,48.32227561017948,0.7275872634522316,-0.14745262560712424
429.4000000000054,48.40160016909482,0.7451886449836986,-0.15472692784875042
430.2000000000054,48.47886359612265,0.7632240021241263,-0.1610606029494166
431.0000000000054,48.55848928183171,0.7863548790463172,-0.16873738235203373
431.8000000000054,48.63608499148818,0.8092583764092407,-0.17534018934535434
432.6000000000054,48.71469760943581,0.833924184016508,-0.18568326445437844
433.40000000000543,48.79211704182067,0.8606248948331086,-0.19814681255787514
434.20000000000545,48.870763488119465,0.8888726690359252,-0.2068396812168185
435.00000000000546,48.947987162015295,0.9159879050989619,-0.21658349761527873
435.80000000000547,49.027745571240146,0.9467442494214426,-0.22898199233061378
436.6000000000055,49.103892054309675,0.9824281196423037,-0.24346333127420827
437.4000000000055,49.184567150696616,1.0124708426025213,-0.26001343404843924
438.2000000000055,49.26249773707423,1.0525930997684219,-0.2748026518883995
439.0000000000055,49.34162948901327,1.0926045497958339,-0.29281391915238064
439.8000000000055,49.41969459723108,1.1374800366066806,-0.3101848327722463
440.60000000000554,49.49798769901886,1.179019398540106,-0.3296115644519788
441.40000000000555,49.57644908664376,1.2210492120593839,-0.35405219173931535
442.20000000000556,49.65646922582163,1.2697841258739566,-0.38126656984420393
443.00000000000557,49.73361302206547,1.3210337514384272,-0.4117023169070402
443.8000000000056,49.812061738745825,1.3728994244531674,-0.4414963016303184
444.6000000000056,49.89040718207842,1.4224226478626472,-0.46723650433501396
445.4000000000056,49.9697154718761,1.4767023144475606,-0.4963377555232755
446.2000000000056,50.04874702870557,1.526376586133154,-0.5310960134281135
447.0000000000056,50.12704403361286,1.5842127390534302,-0.5721978618752765
447.80000000000564,50.20655940104653,1.6394221069655952,-0.6138551230877187
448.60000000000565,50.285295164834096,1.6917163815041183,-0.656419002417389
449.40000000000566,50.36268411212695,1.740532682788377,-0.7000011005658786
450.2000000000057,50.443255374559676,1.8053056688481937,-0.7496201050926707
451.0000000000057,50.51876890952556,1.8542109494948815,-0.8044869730515796
451.8000000000057,50.60043935429888,1.9000197762805215,-0.863513954739175
452.6000000000057,50.67932356494919,1.9228316781149892,-0.9253461198850665
453.4000000000057,50.75916237245414,1.9688141072629843,-0.9840802646245512
454.20000000000573,50.836748912358516,2.0076103177457068,-1.046153638899852
455.00000000000574,50.915999972002325,2.0490136203793066,-1.1125828782001395
455.80000000000575,50.99491619855713,2.1030065490484064,-1.1788603815392467
456.60000000000576,51.07319374634619,2.169205683165131,-1.2553698040192387
457.4000000000058,51.15245277096659,2.213107722498909,-1.3375828237815668
458.2000000000058,51.23121599548466,2.259280189445658,-1.4251166902613304
459.0000000000058,51.310294778035406,2.2682198753452854,-1.5120864908170493
459.8000000000058,51.38893280795203,2.296456183417636,-1.6009018953159653
460.6000000000058,51.46711501227445,2.2966450602760804,-1.6961032528609774
461.40000000000583,51.546098175520584,2.306602304059134,-1.796439436114464
462.20000000000584,51.62455409212206,2.307378623286477,-1.9024871708335596
463.00000000000585,51.70390390031137,2.2954617360793277,-2.009406262029821
463.80000000000587,51.78193004170062,2.275108228274294,-2.1198278709628635
464.6000000000059,51.860194127416776,2.242359978848968,-2.2297426123457216
465.4000000000059,51.9393408245202,2.1927778192263565,-2.345667478247689
466.2000000000059,52.01772880801362,2.1300667524678385,-2.459239558563934
467.0000000000059,52.09660206555977,2.0507395730613287,-2.577846498110979
467.8000000000059,52.175339058920954,1.961806762996106,-2.6920084607601824
468.60000000000593,52.253425185629546,1.8522971778014807,-2.8069279134355503
469.40000000000595,52.332109739142375,1.7306937538677873,-2.9155970917744005
470.20000000000596,52.409607763877915,1.6036844459944375,-3.022983176930002
471.00000000000597,52.488488298168214,1.4679493245035329,-3.129318400899989
471.800000000006,52.566471768448245,1.32043017423464,-3.2339847958791275
472.600000000006,52.64460660344688,1.1701315251983757,-3.329583559068881
473.400000000006,52.72182082858359,1.0167487002646325,-3.415857584767825
474.200000000006,52.79939459674877,0.8619019216810913,-3.4949855599308775
475.000000000006,52.876668558041686,0.7120575239241058,-3.564193916719173
475.80000000000604,52.95591965714957,0.5804620664213211,-3.6333769235239313
476.60000000000605,53.03429469050616,0.46011391300122134,-3.6920651850155806
477.40000000000606,53.1125625892264,0.3553453573154279,-3.7409766321669364
478.20000000000607,53.18980422686274,0.27520585869297265,-3.7853402453112963
479.0000000000061,53.26798814715946,0.20767122668139762,-3.824658505902746
479.8000000000061,53.345316473271076,0.15380771854921482,-3.8577087908487018
480.6000000000061,53.42405547826128,0.11405818186303496,-3.886767393042777
481.4000000000061,53.50156003897392,0.0837038664006734,-3.909682728967394
482.2000000000061,53.580446618520455,0.07221268536350617,-3.93375243841352
483.00000000000614,53.658277031886946,0.060087322378702845,-3.9526091122986555
483.80000000000615,53.73767694499425,0.04559446079415724,-3.9726189158474163
484.60000000000616,53.81568031149593,0.03744508521190082,-3.986135009746355
485.4000000000062,53.893467239880906,0.034056987501956903,-3.9959778693969947
486.2000000000062,53.971734644123984,0.03211253703294059,-4.00054447362618
487.0000000000062,54.05116727265665,0.025759279086031872,-4.009585761552381
487.8000000000062,54.13084454937463,0.01670386687322095,-4.014499450987477
488.6000000000062,54.207891790696145,0.010276004693427598,-4.017513285273484
489.40000000000623,54.286470598946565,0.0054648682541228455,-4.020991640354938
490.20000000000624,54.364918180567514,0.003702153412127762,-4.023520735235621
491.00000000000625,54.44480231035811,0.0035424805781003044,-4.022159462731971
491.80000000000626,54.522916987749895,0.0008425953756019955,-4.025725024639146
492.6000000000063,54.60120993458077,-0.0003569763052571062,-4.0248584806027115
493.4000000000063,54.68051846471471,-0.004262039109786175,-4.023512567294034
494.2000000000063,54.75921809621387,-0.005711507453209919,-4.023541226229014
495.0000000000063,54.8377009151046,-0.002081467989385133,-4.022215053997326
495.8000000000063,54.91597795941551,-0.0015608840287091308,-4.0235399536440974
496.60000000000633,54.99393729893581,0.0010872680476110008,-4.022249666388471
497.40000000000634,55.07211954103883,0.0041810973253838535,-4.022247308321317
498.20000000000636,55.15148597415509,0.0011181217087211648,-4.024203372054603
499.00000000000637,55.2303967576925,-0.0026732612073338546,-4.025520163497015
499.8000000000064,55.309905813692765,-0.007551107173643545,-4.026830081492275
500.6000000000064,55.3870435405273,-0.011754326648524771,-4.028161822234207
501.4000000000064,55.467742226979325,-0.009108483657963573,-4.026866418488716
502.2000000000064,55.54574669913615,-0.013070608205015655,-4.026950211339504
503.0000000000064,55.6254344121597,-0.01118054149354547,-4.024201963038536
503.80000000000643,55.704407710623364,-0.008315375715884754,-4.025203882392563
504.60000000000645,55.78321225202942,-0.0065286214766651085,-4.025510095237675
505.40000000000646,55.8619411647039,-0.005424223678985096,-4.025596498244824
506.20000000000647,55.9409767354752,-0.006473366619524801,-4.028151571149752
507.0000000000065,56.019217402542125,-0.005714025061182015,-4.030065787361868
507.8000000000065,56.0972899494782,-0.0021449814386379495,-4.030778097145044
508.6000000000065,56.17837739570983,-0.0006825254189850027,-4.028537967841349
509.4000000000065,56.256971155562674,0.0026970673034811266,-4.026821190910872
510.2000000000065,56.33623343924367,-0.001000997963428396,-4.025480137598149
511.00000000000654,56.41290144535493,0.00017796460199348552,-4.024199952247357
511.80000000000655,56.49412586700156,-8.851129221537635e-05,-4.024201372525967
512.6000000000065,56.57172684672496,0.0034940592378070456,-4.025583727235496
513.4000000000066,56.65240671827292,0.0016606144148770818,-4.028132498439552
514.2000000000066,56.729059977425166,0.0028097828557745452,-4.026830431079212
515.0000000000066,56.8072504751627,0.001202265042531403,-4.0255110705044785
515.8000000000065,56.88730484604879,0.0016987545142188587,-4.025510372323215
516.6000000000066,56.965280219167624,0.0042437954355644125,-4.0241260495956075
517.4000000000067,57.044378763996875,0.003845559099970197,-4.026361744372886
518.2000000000066,57.12289868696443,0.00420488114459594,-4.0289876767142045
519.0000000000066,57.203029854328626,0.006434569362950504,-4.031909997714183
519.8000000000067,57.28051430633947,0.0016920033556541147,-4.029124653939693
520.6000000000067,57.36149099257529,0.0007097036197672435,-4.026838920871855
521.4000000000067,57.438881363306116,0.0005172501544979946,-4.0255108394955705
522.2000000000066,57.51893552219877,-0.0014875146645978998,-4.025520173645113
523.0000000000067,57.598235497637745,-0.004080393510888625,-4.025514929107979
523.8000000000068,57.67722319993494,-0.0008952868034733386,-4.027708106147401
524.6000000000067,57.7565787985527,-0.0036133618072044515,-4.0271856559786325
525.4000000000067,57.83554255879987,-0.004570722944780337,-4.0265042725300795
526.2000000000068,57.914170849871056,-0.0016401514501407921,-4.0271619447447184
527.0000000000068,57.99346526557237,-0.0028755795953374075,-4.026500488067417
527.8000000000068,58.07314862902909,-0.0023665302034429625,-4.026500720497438
528.6000000000067,58.1517174018625,-0.0012099876575620283,-4.0278222340243275
529.4000000000068,58.23055978712478,-0.0015718657980711148,-4.029157952228227
530.2000000000069,58.30989055879205,-0.0031301941316548842,-4.029142637906432
531.0000000000068,58.388833271057834,-0.004885538605359507,-4.027830182296002
531.8000000000068,58.468376837382664,-0.00020831799064124912,-4.027830121006458
532.6000000000068,58.54519974062442,-0.002935028900566017,-4.028851867446416
533.4000000000069,58.62493751122148,-0.0018726207348325197,-4.027819802267673
534.2000000000069,58.703949820185194,-0.0027519399279822276,-4.0278198219995165
535.0000000000068,58.78273402870997,0.0010890645470857385,-4.027819821608195
535.8000000000069,58.86341745220025,-0.0010322731633635174,-4.027859894304567
536.600000000007,58.94239719896008,0.0028235343786477962,-4.027829497275508
537.4000000000069,59.018881460523104,-0.00280485507606576,-4.026513900048847
538.2000000000069,59.100103738857584,-0.0012973395978895241,-4.025190534992802
539.0000000000069,59.17888852406561,-8.843782415024481e-05,-4.026631959903771
539.800000000007,59.258135665339644,0.000500612253031163,-4.027490041133034
540.600000000007,59.33774387481345,-0.0007991805044903488,-4.0274927657761985
541.4000000000069,59.41616009583111,0.000807283657622726,-4.027541471841723
542.200000000007,59.49605574952097,-0.0009243450728249059,-4.027958606094107
543.000000000007,59.5749953303235,0.0004033193134203028,-4.0274815040902
543.800000000007,59.65153330943555,0.0001221865334719574,-4.029911748784902
544.600000000007,59.73280205488397,0.004063664414351131,-4.031452668041256
545.400000000007,59.811926363626036,-0.001180013470312491,-4.030141785651175
546.2000000000071,59.891068475854745,0.0007212458196075855,-4.029780444845676
547.000000000007,59.97000000000069,0.0031852944904264824,-4.030851773685905