File: 01_Data/Air_Fryer/STA/N2/10K_min/Air_Fryer_STA_N2_10KData_221115_R1.csv
##Temp./Â°C,Time/min,DSC/(mW/mg),Mass loss/mg
51.0,10.643305354178235,0.015314536698000536,0.012544782002454902
52.20000000000002,11.099493341004134,0.06838457135158627,0.012979419176108564
53.400000000000034,11.374509318344472,0.10522607052354416,0.013613070236035973
54.60000000000005,11.594547938541437,0.13019274031712103,0.012451430115728357
55.80000000000007,11.794821860933588,0.15094119444998988,0.013956364905413743
57.000000000000085,11.979065951362742,0.16597936781194522,0.014074944647231469
58.2000000000001,12.153984059436926,0.18092932756807634,0.012545264453939886
59.40000000000012,12.317714023853636,0.189545980839819,0.013833732246102848
60.600000000000136,12.476843200612457,0.19861613451365856,0.014001044187151201
61.80000000000015,12.634693401371315,0.20873931850046956,0.012906860994412739
63.00000000000017,12.787473883665022,0.21299449646120938,0.013266377991081768
64.20000000000019,12.936904462133135,0.22232982358179987,0.01386524572057457
65.4000000000002,13.083113300468398,0.2271298941305111,0.01266965096508521
66.60000000000022,13.22801712327435,0.23195457851002677,0.013979661698831691
67.80000000000024,13.369093414531347,0.23779476907360908,0.01286628494795039
69.00000000000026,13.510949911831704,0.2398375544156326,0.014321706981062832
70.20000000000027,13.649597256429036,0.24252810066311903,0.014330084877567373
71.40000000000029,13.786453846487689,0.24640814563555102,0.014144654516819344
72.6000000000003,13.921611569497257,0.2454214295982109,0.015620986585360264
73.80000000000032,14.058735069787192,0.2489076296931677,0.01428164283799127
75.00000000000034,14.192465148106526,0.25092250193400245,0.014270598698182368
76.20000000000036,14.325800252093957,0.2535117020048865,0.014232398637878063
77.40000000000038,14.456342706478825,0.25278808180048795,0.015701732831886694
78.60000000000039,14.588342754368487,0.2557272368542636,0.014312703014061512
79.80000000000041,14.718193903094978,0.2566439304550059,0.013051820925279678
81.00000000000043,14.846888460932286,0.2593974956143166,0.014287741239773055
82.20000000000044,14.974779750327768,0.26156527322818135,0.014319303353811819
83.40000000000046,15.102644672396293,0.26383909931884264,0.015772352209618923
84.60000000000048,15.228781659990231,0.26477822210051694,0.016021256870655698
85.8000000000005,15.353156816406937,0.2640133920895307,0.017171567096109897
87.00000000000051,15.47886509019677,0.2670516246069774,0.01572053644629623
88.20000000000053,15.602448302988083,0.26863961624825383,0.014379359121404534
89.40000000000055,15.726963824559366,0.26930360046288504,0.014911275298822524
90.60000000000056,15.850182731493526,0.2698964336540578,0.01579815833280751
91.80000000000058,15.97204875397928,0.27442441397472017,0.015808159374872233
93.0000000000006,16.094956394525745,0.272721556685556,0.013407851399795945
94.20000000000061,16.215298243473953,0.2759955812395105,0.014856147992148294
95.40000000000063,16.33515854808723,0.2775771903817139,0.01519938827175693
96.60000000000065,16.457998855303998,0.2800886834781987,0.015506790825467576
97.80000000000067,16.57632411551391,0.28058857584358976,0.01578471214254229
99.00000000000068,16.696865760618092,0.2827604312144901,0.014489943000958405
100.2000000000007,16.81803320298195,0.2845497009774176,0.015912371035429196
101.40000000000072,16.936020054967344,0.286087303119936,0.015561308834582732
102.60000000000073,17.05457609319034,0.2872099562357694,0.017207226814527132
103.80000000000075,17.173444718697958,0.28767864016148204,0.015905995749877277
105.00000000000077,17.291231047894094,0.289350495927882,0.015940432964049123
106.20000000000078,17.41057971392054,0.291454420470899,0.017229374509978967
107.4000000000008,17.52821492312897,0.2918584681350731,0.014667601429227517
108.60000000000082,17.64323914256444,0.29576426570560777,0.01591976018844221
109.80000000000084,17.761149496027457,0.293740812210983,0.01590607469330596
111.00000000000085,17.879272505151395,0.2951751074509199,0.017246501900995526
112.20000000000087,17.999358822017882,0.29708779119453144,0.017224622420671132
113.40000000000089,18.115543790267363,0.298025956994723,0.017185966880091108
114.6000000000009,18.234697023478002,0.2986648699293255,0.017256904406057316
115.80000000000092,18.35008722373778,0.30002743042459545,0.017230292264524216
117.00000000000094,18.467078669534178,0.2999368901089029,0.0169003608236995
118.20000000000095,18.584260924095844,0.30432171058541,0.015900097185582496
119.40000000000097,18.702310698355173,0.30328626479718723,0.015585246336737413
120.60000000000099,18.81836397198168,0.30480175226026895,0.017237331638787268
121.800000000001,18.93480658920141,0.3089670447349697,0.01824717343038529
123.00000000000102,19.05055043585802,0.3087506463256303,0.015910181362232656
124.20000000000104,19.167376203069388,0.30760345917930965,0.017133539827672628
125.40000000000106,19.28429321715407,0.31228548351205865,0.0159327568163814
126.60000000000107,19.40048821406944,0.3141083150511367,0.015920032810762486
127.80000000000109,19.51619957559171,0.3159000874915866,0.01588760339376094
129.0000000000011,19.63078063435316,0.31697569320031427,0.017230089779346258
130.20000000000113,19.747800113796732,0.31869772042161204,0.015912655203903725
131.40000000000114,19.864440073888055,0.3228559192309528,0.015911733312818477
132.60000000000116,19.979059962967245,0.327295626930704,0.01788986020243044
133.80000000000118,20.093590596753543,0.3318712127196416,0.017909568739071346
135.0000000000012,20.209581265333888,0.33789884359620337,0.016581066285564106
136.2000000000012,20.324290717050225,0.3424556173367437,0.016570678551894424
137.40000000000123,20.441587424044013,0.3447178902856547,0.016570020663499108
138.60000000000124,20.555751718095614,0.3534050950727978,0.016564552273667488
139.80000000000126,20.669415847232962,0.35934131719906787,0.016280729006235006
141.00000000000128,20.781223257041425,0.36489289474596476,0.016580767206916924
142.2000000000013,20.897827808993,0.3723197835184973,0.015589800974397328
143.4000000000013,21.012917893341605,0.3831998539494673,0.01688711521064512
144.60000000000133,21.129911544903138,0.39342201715696384,0.017889841309500554
145.80000000000135,21.243907819226017,0.40711965621629637,0.01657123180259834
147.00000000000136,21.358987975959,0.4205191312304801,0.01656819683469113
148.20000000000138,21.472374212613868,0.4365020337094681,0.0165451512203596
149.4000000000014,21.587475743797807,0.4552342042675864,0.01542568728898619
150.60000000000142,21.702294160474207,0.47774217461127255,0.01658014689551557
151.80000000000143,21.816713039208828,0.5019375532037457,0.01517827680425654
153.00000000000145,21.931197103618988,0.5333433506613015,0.017954422358581468
154.20000000000147,22.045438398542537,0.5662877470886184,0.016902405892695427
155.40000000000148,22.1591966511167,0.6089734332394435,0.017875775674641048
156.6000000000015,22.27510877566995,0.6606050607614938,0.0165699970069495
157.80000000000152,22.387181200369195,0.7185654510693003,0.01656999700016204
159.00000000000153,22.50232399778324,0.7903827437829959,0.01657118949271741
160.20000000000155,22.619692616889033,0.8758345147759549,0.016580089941163223
161.40000000000157,22.733099093707263,0.9736231309408183,0.01651319396316797
162.6000000000016,22.84759082888164,1.0799560623283888,0.015249302378934182
163.8000000000016,22.965317593724787,1.1946466719849833,0.01618357231162193
165.00000000000162,23.077689360636786,1.2975705267130828,0.016901118332208753
166.20000000000164,23.193945332192595,1.405627145056302,0.018217192154926565
167.40000000000165,23.31020707296418,1.4981682969247738,0.01558119262865798
168.60000000000167,23.424919168616732,1.549747831711566,0.01592588764348779
169.8000000000017,23.541462130553956,1.5272468403226973,0.018218951052046073
171.0000000000017,23.655965660053454,1.3769815249189008,0.01820068301867117
172.20000000000172,23.76692250671754,1.097174787740898,0.018218106848434168
173.40000000000174,23.88359980208523,0.7943883062735533,0.016900121632564158
174.60000000000176,23.996622664393644,0.6063191146322835,0.01690012154800069
175.80000000000177,24.107787384261336,0.5063803140374181,0.015595381422486732
177.0000000000018,24.222079420428926,0.4552378012097279,0.016899825785521294
178.2000000000018,24.332672233232845,0.4259897173298387,0.01658420158499041
179.40000000000182,24.448291966279193,0.4143116880169081,0.016553996282010708
180.60000000000184,24.56009509887966,0.40691115793996524,0.016909904008945098
181.80000000000186,24.67300368706503,0.4036894598985144,0.015444998708947999
183.00000000000188,24.788319302702707,0.4023449231599981,0.016911224823018323
184.2000000000019,24.90166861052785,0.40095941283313175,0.016907800683917174
185.4000000000019,25.014117510795497,0.40239920222368736,0.01723005598495231
186.60000000000193,25.12800914600981,0.4008656787083338,0.017235425222224876
187.80000000000194,25.240641016729807,0.40093262625281734,0.017166047325844147
189.00000000000196,25.35427846396961,0.39832795181116765,0.016900526329280297
190.20000000000198,25.467547496706626,0.40039571063348045,0.01754881506070216
191.400000000002,25.580443925291526,0.40084929985467355,0.016249808755042672
192.600000000002,25.694343970943244,0.40393285322279393,0.015599410059581764
193.80000000000203,25.80761844602728,0.40400475739794794,0.0162508667721335
195.00000000000205,25.92030315064438,0.402823757774792,0.016580032273033396
196.20000000000206,26.034268588641208,0.40430218568110454,0.015589689714589738
197.40000000000208,26.147369459378936,0.4031740138410872,0.016899983394705664
198.6000000000021,26.26100498449263,0.4040677986632357,0.015580529778404184
199.80000000000211,26.374039596370935,0.40345553594853134,0.01690822797728231
201.00000000000213,26.487968635781932,0.4055565517437358,0.015585940898569461
202.20000000000215,26.60100709245165,0.40478652325181297,0.01558997898600456
203.40000000000217,26.714300166349652,0.40574653333470034,0.0165799824955446
204.60000000000218,26.827556174826736,0.4049366325210189,0.015608498071744137
205.8000000000022,26.941092339810154,0.4045374561773323,0.01557429999386617
207.00000000000222,27.05524889680074,0.40391269508483263,0.014929780568529338
208.20000000000223,27.16861755885639,0.405469979006209,0.014929862435853813
209.40000000000225,27.282280745276598,0.40645992201638437,0.01557998325313914
210.60000000000227,27.39511193599414,0.4065847248172192,0.0149206227858949
211.80000000000229,27.509560950573256,0.4089959447775523,0.015579938748323308
213.0000000000023,27.622318838421346,0.41086668656204484,0.01557994699993781
214.20000000000232,27.73561723393539,0.40839266662852536,0.015580179995247079
215.40000000000234,27.8497222993302,0.4089080046879071,0.015589983026907284
216.60000000000235,27.96325069563282,0.4093536554641722,0.015584241755751016
217.80000000000237,28.076568153883237,0.4091931991786567,0.016579161508317064
219.0000000000024,28.18966230746592,0.40707995282353804,0.01658012662796704
220.2000000000024,28.303736713480262,0.4076506071816672,0.015619859103649603
221.40000000000242,28.41702192667555,0.4054284893283683,0.015260108158955177
222.60000000000244,28.529895317412794,0.4081475089325881,0.015260201845152643
223.80000000000246,28.643061918789524,0.40615942967312446,0.016580195349954252
225.00000000000247,28.75686405464459,0.40621900827895896,0.015260363595611892
226.2000000000025,28.870896362464325,0.40482471714825563,0.015564697969033148
227.4000000000025,28.98448614425972,0.4055100456462987,0.01656984230333336
228.60000000000252,29.09692736779096,0.40313252903102714,0.016565735826699957
229.80000000000254,29.209486278965297,0.4040887426700599,0.015912221487905498
231.00000000000256,29.324489491061247,0.4022821027892388,0.01624005610125767
232.20000000000258,29.439508810759325,0.40171615342319256,0.01755990438525501
233.4000000000026,29.552028299070134,0.4006364131412924,0.01689974322322474
234.6000000000026,29.666121092386604,0.39925297192085607,0.0168999495486144
235.80000000000263,29.781274455916304,0.3988600253807444,0.016000364321699934
237.00000000000264,29.8942311473267,0.3980228823981287,0.016567315904503666
238.20000000000266,30.008118356360605,0.3955441010145472,0.016580249954674997
239.40000000000268,30.122219141501375,0.3943821694528542,0.015260050444742213
240.6000000000027,30.236207779992146,0.3923353220522551,0.015605877349806008
241.8000000000027,30.35028543044522,0.3945496974872423,0.016900117221968713
243.00000000000273,30.46269121745356,0.3934651162615771,0.016900495808051197
244.20000000000275,30.57731025362838,0.39387166667070495,0.015580122266858787
245.40000000000276,30.69051164231395,0.3964165803632396,0.015580116873049832
246.60000000000278,30.805319668304364,0.3931235365681939,0.014579275167554862
247.8000000000028,30.9194970486104,0.3951924972393275,0.015893226437131425
249.0000000000028,31.032574857314103,0.3939216663316485,0.015770540930573063
250.20000000000283,31.145471956550256,0.390516729979513,0.01698677703631013
251.40000000000285,31.2604454568029,0.3903931498678155,0.015579513490124874
252.60000000000286,31.373479201466765,0.3912049749940939,0.0159245051280541
253.80000000000288,31.48854704344209,0.38959278247128826,0.01591992299943712
255.0000000000029,31.600532783637867,0.3919279406491308,0.015919922982270407
256.2000000000029,31.71569351717278,0.39041555497646097,0.01589190857523004
257.40000000000293,31.829403090337212,0.38932617883974396,0.01524887431108457
258.600000000003,31.943542806768146,0.3868917664214153,0.013965926544106999
259.80000000000297,32.05775970271024,0.38793421332990174,0.012618577133975961
261.00000000000296,32.17168330453058,0.3883691317216689,0.013939991491630721
262.200000000003,32.28580390686397,0.384360207817527,0.013940385211313355
263.40000000000305,32.39924727949326,0.38674628616438206,0.014920028954001019
264.60000000000304,32.51324157555171,0.3876460150647146,0.014269228723169824
265.800000000003,32.627087933931506,0.38619705746243976,0.01394180676107748
267.00000000000307,32.74115114401793,0.386212644477037,0.015280636344845
268.2000000000031,32.85635500554807,0.38226949700673885,0.014591243432832357
269.4000000000031,32.96989474932374,0.38370056686924864,0.015580128786317538
270.6000000000031,33.08364452197341,0.3840972236291046,0.015251247370477117
271.80000000000314,33.19591400747806,0.3857110184214847,0.015250104017042965
273.0000000000032,33.31200372234395,0.385013421475502,0.014930097957723376
274.2000000000032,33.42604564469424,0.3836913574390303,0.013610169197774802
275.40000000000316,33.54114908103735,0.3826679078241974,0.013935083766663858
276.6000000000032,33.653914106060896,0.38320317654501584,0.015259691449546864
277.80000000000325,33.76893753620899,0.38366181535256594,0.014956931159283648
279.00000000000324,33.88249275371791,0.38211909848010817,0.015911959262179032
280.20000000000323,33.99655932196142,0.38147022851605195,0.013554877073887361
281.4000000000033,34.11132069974578,0.38274148065957864,0.01370985497672983
282.6000000000033,34.225585625902056,0.38158116500571054,0.014599888158745244
283.8000000000033,34.34000107831783,0.38034413121921473,0.014599888000000227
285.0000000000033,34.45490163903678,0.3813487387144472,0.014599887999972694
286.20000000000334,34.56834031892389,0.3771470969700145,0.014600095210809627
287.4000000000034,34.68331328432639,0.3810545835084069,0.013279895297982236
288.6000000000034,34.79866526047456,0.37896820801282727,0.013575098943469754
289.80000000000337,34.91295289894375,0.3796036383948343,0.01360784468393117
291.0000000000034,35.02723393295982,0.377109988991699,0.012299911571641786
292.20000000000346,35.14200301872976,0.37983941694953166,0.012299911017984222
293.40000000000344,35.25603934335452,0.3797128416966859,0.012047797178081687
294.60000000000343,35.3713562808155,0.3780922685279042,0.01097991099430029
295.8000000000035,35.48620191490014,0.38144866637216013,0.010979911002642062
297.0000000000035,35.60028869015749,0.3791121232249328,0.010793125432620343
298.2000000000035,35.71533170856131,0.3785937247688819,0.010275152921352948
299.4000000000035,35.829799547095746,0.3810605850520167,0.010649911051200611
300.60000000000355,35.94573180965013,0.38009263862410503,0.010649855529510255
301.8000000000036,36.06047053939839,0.37851489903667407,0.009329972153214072
303.0000000000036,36.17260344541268,0.3783353466029723,0.00932991094323743
304.20000000000357,36.289798852941885,0.37917021970425074,0.009973435952699283
305.4000000000036,36.40414678347237,0.3811603128157353,0.01063997810712447
306.60000000000366,36.52010359063826,0.38064556846689535,0.010641165633943572
307.80000000000365,36.634047659322825,0.37949294767244623,0.00964996734775525
309.00000000000364,36.749443793691725,0.3793533191792546,0.010970445598954548
310.2000000000037,36.86523895872576,0.378751069913604,0.010969956022420568
311.40000000000373,36.978838372662956,0.3800130722318073,0.00965001734124371
312.6000000000037,37.09356524631429,0.37550220923210775,0.009662323016222274
313.8000000000037,37.2092766177799,0.3794118206471857,0.009319978256200123
315.00000000000375,37.32464893689435,0.3775564584026214,0.009319978000000617
316.2000000000038,37.440722186434506,0.3793326151175559,0.009319977999999729
317.4000000000038,37.555392837251134,0.37889162009470156,0.009319983603317539
318.6000000000038,37.66826384235656,0.37904656986607316,0.010646250207437369
319.8000000000038,37.785742249827145,0.3814799151680621,0.00966006728291724
321.00000000000387,37.90086904282034,0.3825859696267283,0.00833744911232781
322.20000000000385,38.015003924450724,0.38159605524597484,0.008336105708771413
323.40000000000384,38.13146418297462,0.38402406085623375,0.00933004560828632
324.6000000000039,38.246247259604374,0.38341870484731255,0.009330046949428628
325.80000000000393,38.358865080687345,0.38439697900065806,0.008090502106678166
327.0000000000039,38.47734976964393,0.38406359443929483,0.007690029678941279
328.2000000000039,38.592840578228966,0.3844086691857694,0.009000627971984088
329.40000000000396,38.70795324535765,0.38541970172174006,0.007679791562280158
330.600000000004,38.82323948000309,0.38622444534653055,0.009000056670769752
331.800000000004,38.93812995868513,0.38678381406411755,0.008010166469133218
333.000000000004,39.05356415522748,0.3862047778739368,0.008008896027503987
334.200000000004,39.16912087473057,0.38708225947460373,0.006699983144010879
335.40000000000407,39.28416905051541,0.38879631899387046,0.00669998000000227
336.60000000000406,39.40018284059625,0.38858234572272776,0.006699980000000494
337.80000000000405,39.51456572939161,0.3865850188060698,0.0066999799999987175
339.0000000000041,39.62937267982872,0.38228624656953003,0.0066999799999987175
340.20000000000414,39.744899890149064,0.38483690412862465,0.0066999799999987175
341.4000000000041,39.86179655853137,0.3846637787336881,0.006699976766466165
342.6000000000041,39.97754842725284,0.385429777146577,0.005380869724561421
343.80000000000416,40.09362497474541,0.3822463291911111,0.004415287833514192
345.0000000000042,40.209623544229984,0.3831003866037743,0.004389842007594957
346.2000000000042,40.325251083531676,0.38204237257950935,0.004389842000214195
347.4000000000042,40.440187181391366,0.384083259784683,0.004389211491519163
348.60000000000423,40.55622325245436,0.3845505632993535,0.0030698205136507895
349.8000000000043,40.67240948650497,0.38454766608745594,0.0030698420049626307
351.00000000000426,40.78813348780968,0.38500713868647723,0.003144483447195867
352.20000000000425,40.90136391385747,0.38535823668644087,0.004390173880929993
353.4000000000043,41.01909389949563,0.38631581962948547,0.002414314737134937
354.60000000000434,41.13458571164862,0.38636036097628235,0.002412251196928672
355.80000000000433,41.25036282420888,0.38641139059381974,0.0010901959821350005
357.0000000000043,41.36739624285745,0.3887117436577371,0.0012828861669724745
358.20000000000437,41.48423980930335,0.3866300964738014,0.001420204295548011
359.4000000000044,41.59990481429289,0.38778431705525984,0.0007603851653152915
360.6000000000044,41.71570122540274,0.38669412258676217,-0.0002628143217275891
361.8000000000044,41.83086398702136,0.3875593556583026,-0.0005473455134064054
363.00000000000443,41.946850266204606,0.38769944246370863,-0.0005499619999040917
364.2000000000045,42.06357877056381,0.38860775978715834,-0.0005504463226166934
365.40000000000447,42.179906053564395,0.38849003625392403,0.0007592759013501649
366.60000000000446,42.29566652272875,0.39061317290185005,-0.0008717954251000748
367.8000000000045,42.41039289094167,0.39124318047170153,-0.001864485873993793
369.00000000000455,42.526782869158666,0.39060249364788935,-0.0008799632183063011
370.20000000000454,42.643708685435236,0.3910481167744556,-0.0021700897562118016
371.4000000000045,42.75970328816151,0.3874563069362831,-0.0022000510802353546
372.60000000000457,42.87570309478687,0.3886239301379225,-0.0035192284799290263
373.8000000000046,42.99199489711686,0.39109733460360396,-0.00417001696654129
375.0000000000046,43.10844142855293,0.3909096269189378,-0.004180145998327944
376.2000000000046,43.224144042175475,0.38659879232897154,-0.004180146000030582
377.40000000000464,43.34048592539007,0.38737203574122736,-0.0041801672635921605
378.6000000000047,43.45705081809185,0.38947932710856153,-0.005179154000582109
379.8000000000047,43.57345128771326,0.38932717931521454,-0.004519253483790564
381.00000000000466,43.69029755983928,0.39102101735873396,-0.005819904024281897
382.2000000000047,43.806351734954475,0.3908088418221669,-0.0058550620322330715
383.40000000000475,43.922927319276816,0.3907805779634743,-0.008440060775131819
384.60000000000474,44.03980503907937,0.39086852497785696,-0.008453646860131059
385.80000000000473,44.1560793636024,0.3913795563501871,-0.008465132271427755
387.0000000000048,44.272196175908825,0.3933844031156425,-0.00845977585091795
388.2000000000048,44.38847830193075,0.3917952071252936,-0.011005337695702888
389.4000000000048,44.50620022516302,0.3926709154207756,-0.01372501647381208
390.6000000000048,44.62337729273463,0.39263205112619937,-0.013851499168275883
391.80000000000484,44.73941449112304,0.3942150241475494,-0.016360472492491507
393.0000000000049,44.85538179256017,0.3915128600140214,-0.017665244266093172
394.2000000000049,44.97251683195936,0.3941110796443294,-0.018990325162892674
395.40000000000487,45.08931838605228,0.39380385222784053,-0.02031519591081965
396.6000000000049,45.20605732653082,0.3960358119467501,-0.024240835949268735
397.80000000000496,45.323732054498606,0.39813028300154574,-0.026796132028240383
399.00000000000495,45.4404650341917,0.39622155835809364,-0.026899863177019867
400.20000000000493,45.55673815508423,0.3997198522403355,-0.029031742074341782
401.400000000005,45.67324827603604,0.39978720245675037,-0.031501637781601755
402.600000000005,45.789897050651916,0.39924515269377236,-0.034375639961539584
403.800000000005,45.907679352174235,0.40390294663488713,-0.03674847745694576
405.000000000005,46.02449147275645,0.40162240055999654,-0.03918804855631919
406.20000000000505,46.14118178628262,0.40370198911672406,-0.03926646265586431
407.4000000000051,46.2576348989526,0.40380420138861595,-0.042966061022555735
408.6000000000051,46.374955558092964,0.40572703427078083,-0.04681860420506645
409.80000000000507,46.48944470337869,0.40844418952574135,-0.04738027434846703
411.0000000000051,46.60723053389485,0.4115955180960431,-0.04988286885092119
412.20000000000516,46.72319642389874,0.4156787540149408,-0.05519072837304728
413.40000000000515,46.8413433351401,0.4211054368414313,-0.057944425611864414
414.60000000000514,46.95797683588385,0.423107051987029,-0.06138875746129768
415.8000000000052,47.074889672718136,0.4303532182486559,-0.06464444362304134
417.00000000000523,47.19344727442926,0.43339523648558975,-0.06792122169457704
418.2000000000052,47.309791693206876,0.442903784658472,-0.07266200996292538
419.4000000000052,47.42583408450128,0.45211591618388025,-0.0771509550239049
420.60000000000525,47.543718111411565,0.45929093662308484,-0.08070927932853555
421.8000000000053,47.661665012804434,0.4719580136783371,-0.08836949313462483
423.0000000000053,47.7774085686041,0.4818130183922778,-0.09381167181170325
424.2000000000053,47.89574642854463,0.4967701040855655,-0.09886297443302094
425.4000000000053,48.01025651060005,0.5157012776580201,-0.10628222813404875
426.60000000000537,48.129023465416246,0.5361461593588479,-0.11482426289419045
427.80000000000535,48.2474045286399,0.5606830452189149,-0.12436490824623814
429.00000000000534,48.36499689349697,0.58554882923616,-0.13373915809189896
430.2000000000054,48.48165196043164,0.6148165607095238,-0.14482464179908083
431.40000000000543,48.59924056379381,0.647856073510824,-0.1555000004491851
432.6000000000054,48.717511414544724,0.6823558046199912,-0.170392391561637
433.8000000000054,48.833907335349146,0.7211601052147252,-0.18636811907367656
435.00000000000546,48.95163726741207,0.7652180635438581,-0.20462203275128088
436.2000000000055,49.06989885921087,0.8137964432432068,-0.22492727227204767
437.4000000000055,49.186616014137385,0.8624115081716679,-0.24334731182201796
438.6000000000055,49.30511149843916,0.922419689830731,-0.2687318952209905
439.8000000000055,49.42367716151841,0.9825361593952762,-0.2986203806910246
441.00000000000557,49.54143153272892,1.0460224053561626,-0.33106080605255084
442.20000000000556,49.65941095685713,1.121874447421329,-0.36626929151889254
443.40000000000555,49.777230197746306,1.1998448125887287,-0.4071622225370142
444.6000000000056,49.89549064550165,1.2853972528355162,-0.45456132820706463
445.80000000000564,50.014756016877854,1.3626032125618868,-0.5058658733077794
447.0000000000056,50.13152938608421,1.441358818220635,-0.5588369205789996
448.2000000000056,50.250093861918025,1.5185425007007347,-0.6217631564282984
449.40000000000566,50.369236112434336,1.6001921182630763,-0.6900363207801115
450.6000000000057,50.487822404563815,1.6953846782869906,-0.7624276811666766
451.8000000000057,50.60508190665341,1.7944712370915203,-0.8435125163565487
453.0000000000057,50.72239679891744,1.8650885950352896,-0.9324736637233602
454.20000000000573,50.84109196166174,1.9353705257185914,-1.029964604088395
455.4000000000058,50.959177841697475,1.9975554794302552,-1.1350977223867273
456.60000000000576,51.077463796524164,2.031504519497312,-1.2495481351057243
457.80000000000575,51.19475464582209,2.0974849971654526,-1.369987370098222
459.0000000000058,51.31299326555562,2.108855310873174,-1.502311470609535
460.20000000000584,51.431720719444925,2.1378223483589984,-1.6432473809113448
461.40000000000583,51.55019877082634,2.126700863643885,-1.7933052834934164
462.6000000000058,51.66875166916924,2.098307719409513,-1.951823466465037
463.80000000000587,51.785410448526385,2.061552650422214,-2.1158599810549714
465.0000000000059,51.90441665536907,1.9848714108009826,-2.2842279391474425
466.2000000000059,52.02168182754277,1.8833477092243545,-2.455500296620866
467.4000000000059,52.13889519560206,1.7474545278839253,-2.6255860702362113
468.60000000000593,52.25562062256085,1.5858645467614119,-2.789614658174913
469.800000000006,52.37247781129744,1.4030668092928082,-2.9487896934702746
471.00000000000597,52.48845663685472,1.2035919299090285,-3.1014885760372484
472.20000000000596,52.60536549802049,0.9849351521547492,-3.2423992051420973
473.400000000006,52.722898893908194,0.7647990793656282,-3.3703553772808275
474.60000000000605,52.83941023691971,0.5506425014669087,-3.4821258862728652
475.80000000000604,52.95332225194568,0.3639575217012687,-3.5771572083164185
477.000000000006,53.07092526999484,0.19891162422153522,-3.6606658642499417
478.20000000000607,53.18857530183389,0.07508243620213471,-3.7289812987563438
479.4000000000061,53.3042099924917,-0.016456910721490636,-3.7840813547832886
480.6000000000061,53.42293403119333,-0.0806528548145031,-3.8283019405075347
481.8000000000061,53.54000089708901,-0.122900126974794,-3.86558030879133
483.00000000000614,53.6568811770737,-0.1485420044633072,-3.895003804349064
484.2000000000062,53.77562399920972,-0.16072334852172127,-3.9184786934131997
485.4000000000062,53.893811822826756,-0.16370069888770344,-3.9350785922170592
486.60000000000616,54.00979459338345,-0.1632984728969664,-3.947473208414397
487.8000000000062,54.12738965482892,-0.16503334253245205,-3.9562478372731347
489.00000000000625,54.24759126235583,-0.16645149106074653,-3.9622809091003885
490.20000000000624,54.3664508779658,-0.16189208411569517,-3.9650614288655457
491.40000000000623,54.484019695417295,-0.15868377535143402,-3.966691659149118
492.6000000000063,54.60266250195803,-0.15814545609346276,-3.9691704412524547
493.8000000000063,54.72074174616301,-0.15867522752803073,-3.969319943999282
495.0000000000063,54.83844566373901,-0.1597020531576559,-3.9693187903495915
496.2000000000063,54.957174557276346,-0.16532456433987888,-3.9680087889219067
497.40000000000634,55.07334945299113,-0.14818201210650606,-3.968989747081498
498.6000000000064,55.192373275023535,-0.14964648858783616,-3.9691776913071024
499.8000000000064,55.31122337959039,-0.1517345597012305,-3.968989683416198
501.00000000000637,55.429378035171325,-0.154062878366305,-3.9703111037393164
502.2000000000064,55.54750804610943,-0.1541646795335121,-3.968990268921893
503.40000000000646,55.66608363977936,-0.15434053533112574,-3.969656086980576
504.60000000000645,55.78439978967189,-0.15709999982644268,-3.970290100410873
505.80000000000643,55.90240025173749,-0.15618011761591577,-3.970310035992147
507.0000000000065,56.02143078372764,-0.1577711585089689,-3.970309969995503
508.2000000000065,56.137871057851584,-0.16519353417900806,-3.968990539670556
509.4000000000065,56.2564148620769,-0.16815958367166123,-3.970310044530933
510.6000000000065,56.37359855911054,-0.1669249485559537,-3.9703100359002894
511.80000000000655,56.4941010205525,-0.16820637043090106,-3.968992079609674
513.0000000000066,56.612413322803015,-0.17225150348212356,-3.9713967475266356
514.2000000000066,56.73058051277797,-0.17034791055424253,-3.9713001280145814
515.4000000000066,56.84883625584017,-0.1678815941249412,-3.9713023573616737
516.6000000000066,56.96726401396014,-0.16919767365511892,-3.968965546023032
517.8000000000067,57.08421325305884,-0.17006145715838383,-3.9689900348838796
519.0000000000066,57.20337166251423,-0.1685393309079198,-3.9686617799758324
520.2000000000066,57.32177359155287,-0.17017184336725164,-3.9676370145188886
521.4000000000067,57.43915905438205,-0.16901839318877276,-3.9689901280405104
522.6000000000067,57.55698151356717,-0.17080193745917702,-3.9689901279999997
523.8000000000068,57.675156372522224,-0.1699388118145672,-3.9689901280140036
525.0000000000067,57.79400221200269,-0.17394141308411865,-3.969078467295147
526.2000000000068,57.913193011375405,-0.1733124118122885,-3.9676700545930714
527.4000000000068,58.029907253682616,-0.17363382170557357,-3.967020977122973
528.6000000000067,58.150097187083006,-0.17641093688659037,-3.9670200590001197
529.8000000000068,58.26941413014375,-0.1742022538955797,-3.9670200590000015
531.0000000000068,58.38742903537496,-0.17678337654288456,-3.9670200682103856
532.2000000000069,58.5064714293062,-0.17812697291021626,-3.9663604301973385
533.4000000000069,58.62584283574819,-0.17741309888041054,-3.9663600590002392
534.6000000000068,58.744236033482814,-0.17959754191129432,-3.9663613159143774
535.8000000000069,58.863363421810384,-0.17857446725441511,-3.967020097383873
537.0000000000069,58.98195654144376,-0.18054840428017777,-3.967020105000138
538.2000000000069,59.10207458098913,-0.18094861586397307,-3.967021228184921
539.4000000000069,59.22010740722837,-0.1816115065995762,-3.9676699226872816
540.600000000007,59.33990436924337,-0.18479920155922072,-3.967323139029538
541.800000000007,59.45791744045048,-0.1821190864331389,-3.9660254905205132
543.000000000007,59.576510735471395,-0.18394616933609848,-3.9673499896074085
544.200000000007,59.694712176680696,-0.1829794913697621,-3.9683401731385124
545.400000000007,59.81374664650471,-0.1846700574214199,-3.9693224081500738
546.6000000000071,59.93273047292411,-0.1837319315171852,-3.968002757344178
547.800000000007,60.050801275740476,-0.18440946452615975,-3.9669081951362197
549.000000000007,60.169097292717225,-0.1869561970799093,-3.9697322967122477
550.2000000000071,60.28831226337697,-0.18706742231646603,-3.9696425868866103
551.4000000000071,60.406458703567715,-0.18483118123179385,-3.968340148418165
552.6000000000072,60.52602825318051,-0.18691334224771228,-3.9669860612288335
553.8000000000071,60.64474109546916,-0.18790225318253376,-3.968329816576714
555.0000000000072,60.762821975212695,-0.19048730305284026,-3.968329817706242
556.2000000000072,60.882208818227134,-0.1919675360984854,-3.969621954287673
557.4000000000071,61.00117945728889,-0.1947848512141719,-3.968659908992379
558.6000000000072,61.11957112780711,-0.1975827317592223,-3.968659909
559.8000000000072,61.23808147128609,-0.19731201681682184,-3.9686599089999994
561.0000000000073,61.35708140877511,-0.19930574864839554,-3.968659909
562.2000000000073,61.47600483128053,-0.1988458099779731,-3.9686599089999994
563.4000000000073,61.593590875655366,-0.20017606318277434,-3.968659909055972
564.6000000000073,61.713106335137574,-0.19900579325661338,-3.968293680180178
565.8000000000073,61.831403579420844,-0.20035164498743577,-3.968989976375632
567.0000000000073,61.95043867399889,-0.20290957196159762,-3.968990000998293
568.2000000000073,62.06980141879875,-0.20464507939218993,-3.9689848438002118
569.4000000000074,62.18882639584204,-0.20762933110454765,-3.9683300010214193
570.6000000000074,62.30667105116009,-0.211329110522985,-3.968330000954964
571.8000000000075,62.42641374502297,-0.21205196373978985,-3.968921217976683
573.0000000000074,62.544292756157134,-0.21394313342679164,-3.968989982357013
574.2000000000074,62.66324169263222,-0.21361193995573166,-3.9689637881762057
575.4000000000075,62.7821203403947,-0.21528544815557057,-3.9689935703285695
576.6000000000074,62.901282490387274,-0.21583365767828908,-3.969650093361145
577.8000000000075,63.02047884385821,-0.21550475130013386,-3.969651224527346
579.0000000000075,63.13874143253547,-0.2209726038076664,-3.9704049662481466
580.2000000000075,63.25909560711667,-0.21969858583567453,-3.9696492320156316
581.4000000000076,63.37806909352672,-0.21704408934252267,-3.9683656431836654
582.6000000000075,63.497488916727015,-0.21976908597498668,-3.9696729034766287
583.8000000000076,63.6168999126106,-0.220349403662582,-3.969253071509195
585.0000000000076,63.73498551345822,-0.2245123535602591,-3.9695766484556883
586.2000000000075,63.855044432342844,-0.2252380638439374,-3.969650159995027
587.4000000000076,63.97441213114524,-0.22543905935573771,-3.9696501596297167
588.6000000000076,64.09098634073737,-0.2254668844373577,-3.968323373012807
589.8000000000077,64.21172718969395,-0.226859914377936,-3.969436220852056
591.0000000000077,64.330751775365,-0.22836243016590835,-3.970970266794679
592.2000000000077,64.4499989605913,-0.22584075333202847,-3.970969414689283
593.4000000000077,64.56913012540079,-0.22823404584396065,-3.97100257641418
594.6000000000078,64.68775647327182,-0.23015237618915674,-3.9703098972372604
595.8000000000077,64.80830125382934,-0.2308351799534596,-3.971652147552792
597.0000000000077,64.9246250637053,-0.23285142202792655,-3.9703047835699805
598.2000000000078,65.04549273629924,-0.24137354840322395,-3.9689898971284463
599.4000000000078,65.1644379588681,-0.24039633382467002,-3.968989896999747
600.6000000000079,65.28362749976974,-0.24061246176609385,-3.9689879103233263
601.8000000000078,65.40408019452093,-0.24378411786543147,-3.970196104499066
603.0000000000078,65.52375526834115,-0.24584874938001086,-3.971618945403836
604.2000000000079,65.64353668611336,-0.24508900484942175,-3.9688195736431613
605.4000000000078,65.76349454976494,-0.2507317100155404,-3.968923335445398
606.6000000000079,65.88431746984156,-0.24996278722925264,-3.9676819860688757
607.8000000000079,66.00395668634845,-0.2545203235551111,-3.9676480625014396
609.000000000008,66.12339305474379,-0.2551935608924449,-3.9682163574518032
610.200000000008,66.24324339289939,-0.2593559343827919,-3.968164455344519
611.4000000000079,66.36398772590408,-0.26041391383337226,-3.969320347530885
612.600000000008,66.48403351168456,-0.2631924461995915,-3.9685928206310495
613.800000000008,66.60403751764696,-0.26370420092735325,-3.968329852564916
615.000000000008,66.72427303107594,-0.26580653584697417,-3.9693331156983396
616.200000000008,66.84397013731335,-0.2679220479342034,-3.969579763855715
617.400000000008,66.9636407534495,-0.26992459273365127,-3.96995094487794
618.6000000000081,67.08165649377158,-0.269426328436223,-3.969191354554666
619.8000000000081,67.20380825149083,-0.27130975640663546,-3.9680000560005206
621.0000000000081,67.32270299399681,-0.2703696844517729,-3.9679973904677417
622.2000000000081,67.44268346003352,-0.27399939522143324,-3.9693072090843526
623.4000000000082,67.56246585965766,-0.27488878619062984,-3.9699801480957357
624.6000000000081,67.68196966154304,-0.2768562756801315,-3.968679861007564
625.8000000000081,67.80161991920998,-0.2779264676537744,-3.968658103402293
627.0000000000082,67.92174393455234,-0.27992910856356523,-3.9696498327776935
628.2000000000082,68.04107375039081,-0.27949375353440153,-3.967642112331823
629.4000000000083,68.15999795932635,-0.27728519905919646,-3.968989817227954
630.6000000000082,68.28062628162131,-0.28112342669947454,-3.9676156860206357
631.8000000000083,68.39824139449001,-0.2836160108991733,-3.968993049750047
633.0000000000083,68.51896824152249,-0.2834289038647222,-3.969319899809254
634.2000000000082,68.63893611406891,-0.282009516836266,-3.9693198348840246
635.4000000000083,68.75776692039541,-0.28878450047100024,-3.970639698929946
636.6000000000083,68.87859942412966,-0.28871983786206923,-3.969319813822218
637.8000000000084,68.99733193127075,-0.2903109853552004,-3.9691670497605145
639.0000000000084,69.11780571226028,-0.2891793833764207,-3.9689586977296933
640.2000000000083,69.2374009027313,-0.29392119237521763,-3.968990094877389
641.4000000000084,69.35632017424562,-0.2957530272925559,-3.9693197503421516
642.6000000000084,69.47632269734639,-0.2948934873659059,-3.9693210180152194
643.8000000000084,69.59663355923222,-0.30011298227834304,-3.9703098083771375
645.0000000000084,69.71607070722216,-0.30195384822905924,-3.9689898689394756
646.2000000000085,69.83535764684842,-0.30289587064426815,-3.9682670874488206
647.4000000000085,69.95610139611105,-0.3036734027094218,-3.968962786362421
648.6000000000085,70.07548740561798,-0.3031985157957685,-3.968989185282436
649.8000000000085,70.19419497086723,-0.3065579461180029,-3.9689422195574338
651.0000000000085,70.31401095691976,-0.3134437672713709,-3.9703073742136907
652.2000000000086,70.43398005969894,-0.30846308207623735,-3.9708030319342282
653.4000000000085,70.55401000284672,-0.30849694335041644,-3.9693220901098543
654.6000000000085,70.67387061517191,-0.30923340808784205,-3.9693423448972496
655.8000000000086,70.79355429098848,-0.3088067933193724,-3.970808568060225
657.0000000000086,70.91353480394744,-0.31493774717680856,-3.9719598500668534
658.2000000000087,71.03326443459972,-0.316314836835616,-3.971751864049485
659.4000000000086,71.15274144583763,-0.31913550041841077,-3.970288240619251
660.6000000000087,71.27280523568034,-0.31907268401265787,-3.970310485362881
661.8000000000087,71.39262033714526,-0.3246287948121106,-3.9712994315689625
663.0000000000086,71.50975024855288,-0.32536119148888987,-3.972282622559395
664.2000000000087,71.631490090701,-0.3265331054663867,-3.971289917792185
665.4000000000087,71.75178912444755,-0.32993629109670786,-3.9712899162881565
666.6000000000088,71.87112153640858,-0.32863170702517275,-3.9699676437369593
667.8000000000088,71.99093347123576,-0.32943354523445195,-3.9703216927697498
669.0000000000088,72.11096592134585,-0.33618362012469477,-3.9696501198514396
670.2000000000088,72.23010629329373,-0.335568661892509,-3.9686967291134554
671.4000000000088,72.34990015136515,-0.3387952139906374,-3.9699799335266643
672.6000000000088,72.46979095758579,-0.3400199929316453,-3.968669912007053
673.8000000000088,72.58971885895507,-0.3412622477258076,-3.969979963051462
675.0000000000089,72.70910603590357,-0.34296380942513593,-3.9699799629999997
676.2000000000089,72.82914282046775,-0.34448048042428026,-3.969979963009728
677.400000000009,72.94751623372912,-0.3421448595518427,-3.9704858519234807
678.6000000000089,73.07061363186746,-0.34637296949496094,-3.971311554938996
679.8000000000089,73.18979013876314,-0.34560518882105695,-3.970977401265818
681.000000000009,73.3101997085611,-0.3488975196695847,-3.968329943168689
682.2000000000089,73.42990172096778,-0.35260487446372846,-3.9696500636253553
683.400000000009,73.5503021393126,-0.35181257811720573,-3.9696508021763375
684.600000000009,73.66919404364943,-0.35124500723430435,-3.9709705618190814
685.800000000009,73.79038972157868,-0.350686418024712,-3.969649744727756
687.0000000000091,73.9091286895505,-0.3567653370162578,-3.9719599062887845
688.200000000009,74.03030365474004,-0.35793013311973754,-3.9709679707415253
689.4000000000091,74.15007955379596,-0.3606820960754894,-3.970967564491998
690.6000000000091,74.27074646050728,-0.36277979800393567,-3.9722740017708595
691.800000000009,74.39064166526883,-0.3645844482204065,-3.9735999738762033
693.0000000000091,74.51018722125364,-0.3656493192250005,-3.9735999750977085
694.2000000000091,74.62873917783347,-0.3647034663147694,-3.9732677520279607
695.4000000000092,74.75038659828455,-0.366736052547921,-3.9742601829167783
696.6000000000092,74.87048605998423,-0.3681127805488251,-3.9732710321640106
697.8000000000092,74.99026602763938,-0.3731880026228057,-3.973270042999837
699.0000000000092,75.11018935140218,-0.37472018266249035,-3.973268866991785
700.2000000000093,75.22862766104443,-0.3725870536692125,-3.9749202199348033
701.4000000000092,75.35054137276538,-0.37180069424371476,-3.975236183384899
702.6000000000092,75.47009471448011,-0.3754980101455136,-3.97459937811114
703.8000000000093,75.5898968392009,-0.37794574694019484,-3.973600158425605
705.0000000000093,75.71030412419093,-0.3774220412087991,-3.973600156366137
706.2000000000094,75.8304917646823,-0.379134905903225,-3.974920723721902
707.4000000000093,75.95191002398292,-0.37658178644131246,-3.9749074638608084
708.6000000000093,76.07085556945547,-0.38096055738406154,-3.9735981060431156
709.8000000000094,76.19170465623428,-0.3796416602220457,-3.9745898454654807
711.0000000000093,76.31126711537105,-0.3801670629231412,-3.9745898328083715
712.2000000000094,76.4314465761034,-0.38162163632834434,-3.9732721120025265
713.4000000000094,76.55246622641144,-0.38550054494973685,-3.974589906712586
714.6000000000095,76.67177851877064,-0.3852696144285197,-3.971832505671703
715.8000000000095,76.79170596637466,-0.3823096950748326,-3.9718402783411726
717.0000000000094,76.91216956107293,-0.3865887981738985,-3.9731709022770896
718.2000000000095,77.032387370857,-0.38944128227585,-3.9744801570925645
719.4000000000095,77.15258362945832,-0.3904088976067659,-3.9740288172005505
720.6000000000095,77.27340363384057,-0.3908116184284508,-3.9734901570418977
721.8000000000095,77.39365207541108,-0.3912143287009093,-3.9734901570000005
723.0000000000095,77.51392263003268,-0.3949186196915518,-3.973490161408632
724.2000000000096,77.63441545659727,-0.3931914414612706,-3.9744351981091346
725.4000000000096,77.75447469498037,-0.39370935885856767,-3.974480076768954
726.6000000000096,77.87459136896268,-0.3976933481857181,-3.9731510330367077
727.8000000000096,77.99316953069878,-0.3970884598093606,-3.9758501212178317
729.0000000000097,78.11595606047706,-0.4015637948123213,-3.9731641724424556
730.2000000000096,78.23762071548396,-0.40155899263805206,-3.9731218269518402
731.4000000000096,78.35736724548015,-0.40104855528334254,-3.9744799148288563
732.6000000000097,78.47857298635215,-0.40239093010709237,-3.9733964186755037
733.8000000000097,78.59932032049177,-0.40489695682735544,-3.974493348733354
735.0000000000098,78.72040954160603,-0.4073883536376611,-3.973159790163233
736.2000000000097,78.83918524257874,-0.4147608263111253,-3.974480705999002
737.4000000000098,78.9620736568262,-0.41657155673628593,-3.975798037835492
738.6000000000098,79.08185519648318,-0.4128279420915774,-3.975084464113541
739.8000000000097,79.20320561332565,-0.4166313081729384,-3.975850590371831
741.0000000000098,79.32322740872542,-0.4198426540686409,-3.9757901619999676
742.2000000000098,79.44418803763966,-0.4202747567448094,-3.974874326295548
743.4000000000099,79.56511798568869,-0.4234334127755146,-3.976449861388776
744.6000000000099,79.68511258578772,-0.4252939282036471,-3.9754848819523043
745.8000000000098,79.80516417344477,-0.42853241397875735,-3.9738168016035558
747.0000000000099,79.92571550750596,-0.42964765956735085,-3.9738220212824564
748.2000000000099,80.04625590424783,-0.4299030426449736,-3.9764377449196826
749.4000000000099,80.16627802407277,-0.431188289228532,-3.9764599107160157
750.6000000000099,80.28692705853398,-0.430907874540042,-3.977779394371307
751.80000000001,80.40630690766747,-0.4306894714378418,-3.9777799552109387
753.00000000001,80.5265121604007,-0.4385890014387306,-3.976460016697892
754.20000000001,80.64729947108599,-0.442172030101847,-3.9767903816984673
755.40000000001,80.7681108164077,-0.4410346533155004,-3.9767955166126683
756.60000000001,80.88788887718103,-0.4398423759738497,-3.9787603734217867
757.8000000000101,81.00863573827452,-0.4424083882173445,-3.977759042849403
759.00000000001,81.12796724924361,-0.44821148249423065,-3.977669296773332
760.20000000001,81.25038696646526,-0.45105094490328007,-3.977554842934566
761.4000000000101,81.37119767853443,-0.4469532573773756,-3.976120118225153
762.6000000000101,81.49117704286641,-0.4511704882191573,-3.9761200865014574
763.8000000000102,81.61278278461455,-0.452284616324248,-3.9781999627979237
765.0000000000101,81.73310975663601,-0.45243584748185683,-3.9768069894143103
766.2000000000102,81.85435347818502,-0.46126089666700826,-3.9768133158234993
767.4000000000102,81.97554170911292,-0.46179794453505196,-3.9780997704496603
768.6000000000101,82.09574138560748,-0.4665792253530945,-3.9771096569156774
769.8000000000102,82.2168599758239,-0.4688234709710895,-3.976789971240545
771.0000000000102,82.33746288151228,-0.47052613080462546,-3.9781099797828587
772.2000000000103,82.45921868842514,-0.47320873469549074,-3.978073399592421
773.4000000000103,82.57850781451354,-0.4707815054225555,-3.979420046177538
774.6000000000103,82.69921536366336,-0.4779453374987124,-3.9781076169455547
775.8000000000103,82.82000126842325,-0.47903389396286433,-3.9796207295969555
777.0000000000103,82.94076150417835,-0.48476867160011516,-3.978320026959046
778.2000000000103,83.06099742741733,-0.48129559997702265,-3.978320027039568
779.4000000000103,83.18262383605237,-0.48389134341558504,-3.9796418845005586
780.6000000000104,83.30180864296187,-0.4860821353102996,-3.978320298108435
781.8000000000104,83.42240505574006,-0.48571661184651543,-3.979544584862821
783.0000000000105,83.5437309103687,-0.4902249664569021,-3.9782941707147135
784.2000000000104,83.66463930758819,-0.4919654746238456,-3.978320045510713
785.4000000000104,83.78582006649354,-0.49292295781753004,-3.9796395109787337
786.6000000000105,83.90584644496639,-0.4952251824569339,-3.982273058403577
787.8000000000104,84.02711008227193,-0.49500281924820566,-3.981006260227954
789.0000000000105,84.1472917799885,-0.4999934686371366,-3.9796669465608465
790.2000000000105,84.26894137222789,-0.49656854303214193,-3.9803002433882337
791.4000000000106,84.38989897881673,-0.49839142887022764,-3.9799759144556197
792.6000000000106,84.5091500206266,-0.500319377248092,-3.9799694411340285
793.8000000000105,84.63085835045877,-0.5024583395560913,-3.980538228407189
795.0000000000106,84.75171733105103,-0.5053988987666103,-3.9799698966380475
796.2000000000106,84.87214030388121,-0.5086515038305207,-3.981278931934157
797.0000000000106,84.95283151109474,-0.511974811579392,-3.9812799689761205