File: 01_Data/Air_Fryer/STA/N2/10K_min/Air_Fryer_STA_N2_10KData_221115_R2.csv
##Temp./Â°C,Time/min,DSC/(mW/mg),Mass loss/mg
51.0,10.6,0.0006738843779363624,-0.029960598654682258
51.80000000000001,10.962584656232886,0.051981610516236954,-0.028160895766423444
52.60000000000002,11.179137035615572,0.08825074942129407,-0.027166149555979402
53.400000000000034,11.358006457449184,0.11450270054326483,-0.028180164828668808
54.200000000000045,11.513352166610316,0.13970073558898055,-0.027899799127993674
55.00000000000006,11.65393929885779,0.15813654100178187,-0.026998691671518138
55.80000000000007,11.784651800263783,0.17169479281194477,-0.027065495235586212
56.60000000000008,11.909549771053486,0.18608707944852454,-0.027767078213443597
57.40000000000009,12.027353356486726,0.19633619005400682,-0.026583834236590498
58.2000000000001,12.139211340264232,0.20927101602674725,-0.02952804801703479
59.000000000000114,12.255354008963609,0.21770430076138947,-0.02891479298651234
59.800000000000125,12.36431025635645,0.22380058494719912,-0.029215590272854364
60.600000000000136,12.471512884759868,0.23215565610318412,-0.0301961540813096
61.40000000000015,12.576219379806192,0.24166611366369017,-0.029984277787587388
62.20000000000016,12.678762771962155,0.25047934393549665,-0.028575757698157567
63.00000000000017,12.780542248274273,0.2541403413594725,-0.030051097691900175
63.80000000000018,12.881972648365148,0.2593433105780556,-0.029616171029098304
64.6000000000002,12.978884896041599,0.2649717359876571,-0.031262948530097034
65.4000000000002,13.077154050359217,0.2675436689594912,-0.03125149241584868
66.20000000000022,13.174115390622475,0.27359217095777155,-0.02982202168874437
67.00000000000023,13.270761210854507,0.277346322225241,-0.030946983194746203
67.80000000000024,13.36496217729496,0.27987791629731396,-0.0324481798926195
68.60000000000025,13.457820881052013,0.28311639013785805,-0.03235742830907018
69.40000000000026,13.553069506191656,0.2842519041181212,-0.03120598738484226
70.20000000000027,13.645916642360394,0.28854573127837324,-0.031868362197500666
71.00000000000028,13.73784185273839,0.2889846264909932,-0.031236630324301018
71.8000000000003,13.82965753854773,0.29041883376682553,-0.03260653161087568
72.6000000000003,13.91946534572054,0.29366725413584216,-0.03285864752772483
73.40000000000032,14.009695146744715,0.2960320535972998,-0.03330675559243712
74.20000000000033,14.098715814591117,0.2975380829199654,-0.0326049092894678
75.00000000000034,14.187746914571758,0.2985374409086018,-0.03259789497682686
75.80000000000035,14.277222697089673,0.30150999371628073,-0.03263666818945676
76.60000000000036,14.364542938543885,0.30203460482866606,-0.03263513594565293
77.40000000000038,14.4526802157421,0.30391455606011686,-0.033820687306468145
78.20000000000039,14.539004767371704,0.30526981244449025,-0.03260327647604022
79.0000000000004,14.626169385998534,0.3064473328998305,-0.03389951783503786
79.80000000000041,14.713738833226277,0.3106478676624096,-0.0326982255936068
80.60000000000042,14.798870668105387,0.3110354172337997,-0.035192357245342976
81.40000000000043,14.885198919455258,0.31256405475620197,-0.03524437943198322
82.20000000000044,14.96889786095019,0.3164808443155226,-0.03524505471426309
83.00000000000045,15.053690886384919,0.3182442534492732,-0.03526932785069725
83.80000000000047,15.14000000000005,0.31866538701464897,-0.034904754029867036
84.60000000000048,15.223866529999935,0.3191373120160468,-0.03372185552078477
85.40000000000049,15.306263311788156,0.3206009025049651,-0.03404227846296504
86.2000000000005,15.390850397931484,0.3247475927036725,-0.03355316628840299
87.00000000000051,15.474368255480536,0.3249927646499988,-0.03260396417345923
87.80000000000052,15.555790413577494,0.3248356565379106,-0.03262488419956977
88.60000000000053,15.639112271149296,0.3270114868403792,-0.0337579134096746
89.40000000000055,15.722377834392152,0.3270326592573495,-0.03388036247171122
90.20000000000056,15.800875634085243,0.32923842691891825,-0.03368422461855314
91.00000000000057,15.881917419397313,0.33172587837373346,-0.03387969072587538
91.80000000000058,15.966565199375845,0.3303885327778018,-0.0352397227983996
92.60000000000059,16.047071521074002,0.33459249721795126,-0.03522224713591626
93.4000000000006,16.12866712760765,0.3338932097914108,-0.035232268792393384
94.20000000000061,16.210807729835953,0.3363760978554259,-0.03451315134648514
95.00000000000063,16.290206561948846,0.3396936649667087,-0.035241586262993785
95.80000000000064,16.369433226495026,0.34146675748358013,-0.03655998490458856
96.60000000000065,16.4468791842115,0.3396175795495344,-0.03504643529685758
97.40000000000066,16.529900519641014,0.3405273761186465,-0.03512738841744323
98.20000000000067,16.61085098291119,0.34043188396664426,-0.03513386111909522
99.00000000000068,16.689791772551633,0.3425987588880822,-0.035131573171979014
99.8000000000007,16.770283212284625,0.34449162432283487,-0.0351314256481734
100.6000000000007,16.849416255851086,0.3457614112604408,-0.03401473436534541
101.40000000000072,16.929541213444356,0.3457771734353333,-0.03513183103341966
102.20000000000073,17.00868745389634,0.34776554318562836,-0.0351201466538118
103.00000000000074,17.08728546736639,0.3469146232663952,-0.03644053434286665
103.80000000000075,17.16596519598644,0.3496411950192124,-0.037081701045736715
104.60000000000076,17.245042228155032,0.3497777525070429,-0.03672602153057447
105.40000000000077,17.32406910372348,0.35170782380126486,-0.03653362148145689
106.20000000000078,17.401707629529298,0.35354501949940487,-0.0364393457370662
107.0000000000008,17.481379979698975,0.35631588501628964,-0.035102478024094275
107.80000000000081,17.560092620537286,0.35584057389393053,-0.036434665821908574
108.60000000000082,17.639369246348338,0.35476570085028203,-0.03775973107442088
109.40000000000083,17.717347753390317,0.35808622610419594,-0.03781473533544322
110.20000000000084,17.796232122144907,0.35910769785300867,-0.03647328745930434
111.00000000000085,17.873615156797296,0.35861151657635826,-0.03669286057587495
111.80000000000086,17.95288497535218,0.3602221124146824,-0.03638489835396186
112.60000000000088,18.03061529025012,0.3610971761793276,-0.03644874540655341
113.40000000000089,18.109259180559057,0.36010583504062976,-0.036424202717117105
114.2000000000009,18.186280610158306,0.36306941055669684,-0.03512611368141272
115.00000000000091,18.26610421452256,0.36361005496390975,-0.035150364636923115
115.80000000000092,18.342733951152074,0.36575331819727985,-0.03513192741993176
116.60000000000093,18.420518863343187,0.366858275875233,-0.03775237739073134
117.40000000000094,18.499540051694467,0.36856900112250346,-0.03692311753257105
118.20000000000095,18.5766912155265,0.36738037920559086,-0.03776786457011827
119.00000000000097,18.65543065454079,0.37001456543080624,-0.037778174881280435
119.80000000000098,18.733880923879177,0.3699103046586112,-0.03679878761738031
120.60000000000099,18.808751602848808,0.37031114159061085,-0.037758398777864244
121.400000000001,18.8888256053195,0.3711307518483714,-0.03778483349351536
122.20000000000101,18.965886820104892,0.3736054754015621,-0.03743114905514844
123.00000000000102,19.04435003090511,0.37229688544790873,-0.03722233744824521
123.80000000000103,19.121999677069745,0.37373148129839506,-0.03643862666436348
124.60000000000105,19.19835746440317,0.37360656784604585,-0.03775897199130007
125.40000000000106,19.276499310904814,0.38004942085765814,-0.0390899806765308
126.20000000000107,19.353901574241764,0.38188966428628635,-0.03777003793872247
127.00000000000108,19.43096929858276,0.38298634534318343,-0.03777000751047144
127.80000000000109,19.509134719245928,0.38292692937650885,-0.036886132451955156
128.6000000000011,19.58557750313405,0.3860370892572218,-0.03775754918785168
129.4000000000011,19.662327171877397,0.38949045609090394,-0.03908006975764344
130.20000000000113,19.739821989034763,0.3909892123190045,-0.04039037672202461
131.00000000000114,19.816945135315752,0.3925370529135277,-0.0399989636663749
131.80000000000115,19.894807586372213,0.3956535199075085,-0.03760171838324222
132.60000000000116,19.971354869319974,0.39790869839690657,-0.03766604308967203
133.40000000000117,20.044974829150085,0.4010000916410231,-0.03974156126071904
134.20000000000118,20.123833121031744,0.4048579862456983,-0.04028014762586185
135.0000000000012,20.202357957765205,0.4075874248583403,-0.04028076457422092
135.8000000000012,20.275799292022313,0.41142471605369013,-0.04162352042752726
136.60000000000122,20.35641251939111,0.41384815715382006,-0.040323808017403984
137.40000000000123,20.432190832794355,0.41661341006327857,-0.041610672774833546
138.20000000000124,20.509310451553958,0.4197294290080785,-0.041610035752422725
139.00000000000125,20.584873218095797,0.4252069858594052,-0.04159726273108966
139.80000000000126,20.662572102479178,0.4281175088048241,-0.04161014730951873
140.60000000000127,20.736922389454225,0.4338752316178648,-0.04255288217152042
141.40000000000128,20.81439395022895,0.4402849860274179,-0.04035943526788888
142.2000000000013,20.891201246648897,0.44395151341524985,-0.04027988755373535
143.0000000000013,20.966689692437928,0.45139478376167214,-0.04030731268100851
143.80000000000132,21.044927885968225,0.45880315603754473,-0.04093606091678215
144.60000000000133,21.12042716684845,0.46486236346777043,-0.04094012579796402
145.40000000000134,21.196829617312336,0.4756387736454168,-0.041861357884019235
146.20000000000135,21.273152189800815,0.47969939923448457,-0.04230656259344201
147.00000000000136,21.349157474256092,0.49124777610186043,-0.04161020836175933
147.80000000000138,21.426300904805537,0.501003596158986,-0.04032273718329815
148.6000000000014,21.503289069670274,0.5127728096981703,-0.04160221856745849
149.4000000000014,21.579821069039067,0.5225677854903616,-0.041280199379236215
150.2000000000014,21.653129855654516,0.5369255831908804,-0.04165417201374755
151.00000000000142,21.730621054175163,0.5529703365078263,-0.041596124973722226
151.80000000000143,21.806503279188618,0.5696917340838903,-0.041599034611098595
152.60000000000144,21.881865018371595,0.5905716242927213,-0.041588141110191046
153.40000000000146,21.957978843584904,0.6082404012684345,-0.044100576280597714
154.20000000000147,22.034967219657247,0.632363152739457,-0.044240390812056773
155.00000000000148,22.110814507504827,0.6593868169854088,-0.042920757760495754
155.8000000000015,22.187938662125383,0.6888717746559415,-0.04292003058795579
156.6000000000015,22.263977381109587,0.722940263100906,-0.042935917160215276
157.4000000000015,22.340750093013398,0.7595293131416128,-0.04325932716126246
158.20000000000152,22.41785698864952,0.8003399685207344,-0.043255457371023986
159.00000000000153,22.49402635623891,0.8494674281990102,-0.043781650072195255
159.80000000000155,22.570000000000164,0.9011316100210991,-0.042919886854089206
160.60000000000156,22.647636268238028,0.9598609091499793,-0.042156643433026275
161.40000000000157,22.724040824028393,1.023698985164403,-0.04292002197066758
162.20000000000158,22.80200001499177,1.0902009029351265,-0.042920180616242476
163.0000000000016,22.878591363959433,1.1585358684295066,-0.044247483065146476
163.8000000000016,22.952368627848738,1.2278220901069181,-0.04424268821834687
164.60000000000161,23.03141258889886,1.3057336742251333,-0.04411672730627281
165.40000000000163,23.1084579933812,1.3800210511649182,-0.04292038751961069
166.20000000000164,23.185433749669112,1.448387801143187,-0.04202078235990303
167.00000000000165,23.262356060807242,1.5100321829481784,-0.04272609310882913
167.80000000000166,23.338706657207574,1.5552762038375385,-0.04291494930878681
168.60000000000167,23.415728922102804,1.5889727494226875,-0.04423994281727861
169.40000000000168,23.493043361573235,1.5993659397956754,-0.04422636194369911
170.2000000000017,23.5690256173155,1.5718196215104587,-0.0429199327413512
171.0000000000017,23.646848020900727,1.4949103310880139,-0.04425141387593623
171.80000000000172,23.72265800499374,1.3547346848402346,-0.04358036834674461
172.60000000000173,23.799896822359337,1.1652477299487793,-0.04421187545396155
173.40000000000174,23.873050176217472,0.9720692054759887,-0.042919653382750056
174.20000000000175,23.94905055933993,0.8104048817555213,-0.04462306466803767
175.00000000000176,24.023473820862336,0.6992196645881298,-0.04487553199118555
175.80000000000177,24.09859906080195,0.6264090119725046,-0.045549976864914576
176.60000000000178,24.174599048520967,0.5743491162484947,-0.04426649163851515
177.4000000000018,24.247519113381873,0.5443820202580829,-0.044240166902033806
178.2000000000018,24.32411006110458,0.5230904172254469,-0.04598786451985948
179.00000000000182,24.399420104734695,0.508618746607233,-0.046868374492166964
179.80000000000183,24.47367517693449,0.5003042432659632,-0.048190258541123576
180.60000000000184,24.549437364278518,0.4959414322995763,-0.0468794216352979
181.40000000000185,24.624530760271917,0.49280229035311696,-0.046880115654722054
182.20000000000186,24.702188384880333,0.488984739193063,-0.04797886897185322
183.00000000000188,24.77725469151009,0.485757197983316,-0.04655405643186494
183.8000000000019,24.853489339910897,0.4854299803945592,-0.046907075929816244
184.6000000000019,24.92891777967689,0.4860853137287705,-0.04721190810942222
185.4000000000019,25.0053553899289,0.48602602580642773,-0.047200015788729566
186.20000000000192,25.08010151121341,0.4872628116849117,-0.047200014999994266
187.00000000000193,25.15648793557465,0.4853810941694075,-0.04720001500191007
187.80000000000194,25.231577228273824,0.485880268469867,-0.04720009582105522
188.60000000000196,25.307589866513847,0.4867072952573451,-0.04852291486131666
189.40000000000197,25.382570662060218,0.4887999846785904,-0.04874647769926188
190.20000000000198,25.456676820239107,0.48516446386204665,-0.04885016531908626
191.000000000002,25.533887080705483,0.4877211250349865,-0.04850478817337667
191.800000000002,25.60942406794769,0.4889718649257396,-0.04823401562047014
192.600000000002,25.685607837458793,0.4882345781622587,-0.04855183555546194
193.40000000000202,25.760781281122174,0.48915370892112486,-0.04716556337026123
194.20000000000203,25.83674950612836,0.4909116843393826,-0.04851991305620018
195.00000000000205,25.911594446713615,0.48926446664992446,-0.04851994500684054
195.80000000000206,25.987832667826225,0.49171044771843697,-0.04851999094874859
196.60000000000207,26.062491696041967,0.4931656779002805,-0.04921714281980982
197.40000000000208,26.137856546219933,0.49216325106508807,-0.04983965010404834
198.2000000000021,26.214076042462047,0.49097052268115726,-0.04971048116060661
199.0000000000021,26.28896125707072,0.49239290884361514,-0.05024399431130089
199.80000000000211,26.364382407848943,0.49236927274161824,-0.04950996339236102
200.60000000000213,26.440939112250437,0.49388091864851624,-0.04820382996400241
201.40000000000214,26.51616553454359,0.4943311838672103,-0.048190112472445534
202.20000000000215,26.59152987423966,0.49486988654885644,-0.049396528121864236
203.00000000000216,26.66659544130414,0.493564181550861,-0.048519952323929694
203.80000000000217,26.742863269333345,0.4937450972876297,-0.04853290639645813
204.60000000000218,26.818969201200897,0.4949574433936871,-0.0498298897847862
205.4000000000022,26.894115547073316,0.493690759557079,-0.05115076945709651
206.2000000000022,26.969732883639544,0.49500524097307874,-0.05115015359417896
207.00000000000222,27.0452072304665,0.49629876868098455,-0.05116360118209329
207.80000000000223,27.12096715448028,0.49397896317630474,-0.05115015391680089
208.60000000000224,27.196272536301105,0.4988587153186145,-0.04983460532119732
209.40000000000225,27.2720698023265,0.49372636006216475,-0.049840168340201885
210.20000000000226,27.34784124637783,0.4961600048773947,-0.05048487553988279
211.00000000000227,27.424373358883923,0.4954321680986943,-0.05106852748448398
211.80000000000229,27.5001963802381,0.4972308284220326,-0.05150011997759929
212.6000000000023,27.57572758989452,0.4973337923407589,-0.05280990486435666
213.4000000000023,27.65163545626879,0.49880820279183335,-0.0528101596296775
214.20000000000232,27.727173859720715,0.49682960591228664,-0.052821299540094735
215.00000000000233,27.80400509363879,0.49924717103760335,-0.05255507593643838
215.80000000000234,27.879271702966392,0.4996826085235151,-0.05279985150367272
216.60000000000235,27.955438122313318,0.4989810803575587,-0.052799860000034116
217.40000000000236,28.031109886628194,0.49846705989662465,-0.05279984942353755
218.20000000000238,28.106710242593756,0.5002044806696413,-0.053392744660255786
219.0000000000024,28.182896225735536,0.49985303976867484,-0.05411898568133111
219.8000000000024,28.25799915122757,0.5007310464780741,-0.052799606652716324
220.6000000000024,28.333030504191434,0.5000839623250606,-0.051479193094659426
221.40000000000242,28.411812388082264,0.5024228982802204,-0.05173032280851597
222.20000000000243,28.486251962712082,0.5050734700211414,-0.05280006539085136
223.00000000000244,28.56206484212767,0.5008704398673414,-0.052800069999011434
223.80000000000246,28.63645706552351,0.5033115227009493,-0.052800097692972336
224.60000000000247,28.713872658968654,0.5045187115879277,-0.05207368780976829
225.40000000000248,28.78940208830086,0.5058661480615667,-0.053459977001079295
226.2000000000025,28.865558138322864,0.5074597664681297,-0.05346662164360971
227.0000000000025,28.941466182513555,0.5064343782252725,-0.052799658074550226
227.8000000000025,29.017160784217378,0.5069232859436775,-0.05279989502363369
228.60000000000252,29.092879743757344,0.5092961213667285,-0.052799917368421045
229.40000000000254,29.169161776263834,0.5081729513496521,-0.05188718031136208
230.20000000000255,29.24376107769496,0.511075985711748,-0.05277692720128613
231.00000000000256,29.321117625662254,0.5100355391163163,-0.052799999866943725
231.80000000000257,29.3961758690786,0.509429816534342,-0.052777515236094086
232.60000000000258,29.47196541625343,0.5088220608393599,-0.05133137857032333
233.4000000000026,29.54753043548713,0.509626384778005,-0.05016993840603012
234.2000000000026,29.624062096490157,0.5111613166641321,-0.05017202882853633
235.00000000000261,29.699082199533883,0.5107904163023034,-0.051824129835672306
235.80000000000263,29.77277957707012,0.510682102203867,-0.05378825530756037
236.60000000000264,29.851255336417633,0.5098510345881246,-0.05379000636774656
237.40000000000265,29.925884566933668,0.5129419636638607,-0.0532443745244473
238.20000000000266,30.001946379968132,0.5110545111861334,-0.051978890339501316
239.00000000000267,30.078894773808162,0.5113688826036722,-0.05148992621671811
239.80000000000268,30.15383488344149,0.5118315886884278,-0.05148282987771724
240.6000000000027,30.230988150302988,0.5140120819661518,-0.05280013134346628
241.4000000000027,30.305984874016218,0.513731023777811,-0.0521364816729486
242.20000000000272,30.38181059806504,0.5134324603241599,-0.051384621784967166
243.00000000000273,30.45780742478922,0.5131095713870785,-0.05116003342916775
243.80000000000274,30.533904675305017,0.5116484329229856,-0.05113059783922136
244.60000000000275,30.609248757578385,0.5146970547432389,-0.051478404026791935
245.40000000000276,30.684817935700316,0.515327113527398,-0.05246980482639829
246.20000000000277,30.76084474328539,0.5152572039805251,-0.05246995999844106
247.00000000000279,30.83645128636744,0.5155936973178687,-0.052469959999999816
247.8000000000028,30.912726796515965,0.5131443021203584,-0.052469959999999816
248.6000000000028,30.98869193740195,0.5159837748186018,-0.05246996000000115
249.40000000000282,31.064645046555952,0.5159616442631687,-0.05246996005080806
250.20000000000283,31.139678790369295,0.516516039902162,-0.05247072282098175
251.00000000000284,31.217019049482882,0.5139583551341473,-0.05449575984658406
251.80000000000285,31.292180345451268,0.5135331031400548,-0.05445022661750887
252.60000000000286,31.36917106307732,0.5184321373682698,-0.05311911945901038
253.40000000000288,31.445262906954856,0.5164808716191326,-0.05313028450302104
254.2000000000029,31.5205300171302,0.5180089315752028,-0.05182343428333436
255.0000000000029,31.596521898463614,0.5159097890051285,-0.05246981473851253
255.8000000000029,31.67282708283479,0.5183522428854439,-0.05247005432768104
256.6000000000029,31.747995032340715,0.5177253920355858,-0.05296858854211317
257.40000000000293,31.824573503796685,0.5188178311994146,-0.053781488645560316
258.20000000000294,31.900682911081812,0.5182111283794029,-0.053790269635102916
259.00000000000296,31.976436944520707,0.5190880940756117,-0.0537900647773597
259.80000000000297,32.05214069021511,0.515696241439281,-0.05378605997093899
260.600000000003,32.12854669087563,0.5171297442547852,-0.05380636602917033
261.400000000003,32.20445459317458,0.5177144320102358,-0.05511036277020853
262.200000000003,32.28034242162783,0.5197250290985292,-0.055097765568178136
263.000000000003,32.35623641016767,0.5179692187020313,-0.056424869251943566
263.800000000003,32.43168592981567,0.5165249676540067,-0.05400240145020563
264.60000000000304,32.50807807195595,0.5202276128449667,-0.05378926695158137
265.40000000000305,32.583937422689885,0.5194236674304551,-0.05244165100470166
266.20000000000306,32.6601903280751,0.5190149476191802,-0.05313016703991291
267.00000000000307,32.73630791830242,0.5173924088632413,-0.0544383890807989
267.8000000000031,32.811441048411474,0.5185194343976751,-0.05313989236856287
268.6000000000031,32.88815413026241,0.5216018559577534,-0.053791645162748036
269.4000000000031,32.964276644057435,0.5220851165396724,-0.05511028338790336
270.2000000000031,33.03970691319154,0.5224729942580851,-0.05510734675679796
271.0000000000031,33.11595303092901,0.5213613845113583,-0.05643005219522079
271.80000000000314,33.19194536578416,0.5203386527180566,-0.05643305325528525
272.60000000000315,33.26858600547443,0.5216791024087238,-0.054580751978088315
273.40000000000316,33.34506889299892,0.521592900996799,-0.054450208583862736
274.2000000000032,33.42018558841461,0.5254373851196187,-0.054450151966457305
275.0000000000032,33.49660535761219,0.5237938537624743,-0.05375259538072896
275.8000000000032,33.57217280595175,0.5233742746596909,-0.05314133334918569
276.6000000000032,33.64815978251293,0.5241118276343354,-0.05313999494636601
277.4000000000032,33.72280758608273,0.5236600674381487,-0.053139994999996
278.20000000000323,33.79904896713553,0.5239579523659897,-0.05313999500000044
279.00000000000324,33.87544235529057,0.5231126276650989,-0.05313999499998978
279.80000000000325,33.950936717075294,0.5244936109819168,-0.05313999493823118
280.60000000000326,34.0274290910605,0.522865350644103,-0.053143257217250106
281.4000000000033,34.10303975517919,0.5228458461587596,-0.05107706811250923
282.2000000000033,34.179815064372534,0.5237028802930901,-0.049507743134431514
283.0000000000033,34.258570451741235,0.5233714615365485,-0.05085473068392954
283.8000000000033,34.331361016265475,0.5255144165338017,-0.04945934186053336
284.6000000000033,34.41020343131371,0.5243337930786784,-0.05084925306211163
285.40000000000333,34.48634719738805,0.5264817483605679,-0.05081980081401216
286.20000000000334,34.56233848136924,0.5260319604032399,-0.050819800854841723
287.00000000000335,34.63941458615886,0.5261834068766701,-0.05225260093195416
287.80000000000337,34.71470905706098,0.5264994751462233,-0.052139802866565166
288.6000000000034,34.79056412887259,0.529062680795892,-0.05214250749265714
289.4000000000034,34.86717621702668,0.529047602021611,-0.053408854227789515
290.2000000000034,34.9424690768593,0.5290585863099809,-0.050821002857624364
291.0000000000034,35.01922108306761,0.5255026807308669,-0.04989342818825282
291.8000000000034,35.0955799746365,0.5274319894938894,-0.050150367639721694
292.60000000000343,35.172026292431646,0.5298265429560112,-0.05215540655961837
293.40000000000344,35.247816520284715,0.5309946387392768,-0.05214826478355494
294.20000000000346,35.32520794936406,0.531640903173148,-0.052802544891511705
295.00000000000347,35.40157816840976,0.5312125638765661,-0.051480673853038894
295.8000000000035,35.47814053575583,0.5337219579288273,-0.05148123934418125
296.6000000000035,35.55363821541925,0.5356693544777982,-0.05213917366023546
297.4000000000035,35.63139278490831,0.5345678183646638,-0.05084350818455663
298.2000000000035,35.70665778353031,0.5384635265668315,-0.0508085007642447
299.0000000000035,35.78432726086962,0.5377751354843772,-0.05180973544897638
299.80000000000354,35.859906236746454,0.5410630454652958,-0.05180956311185225
300.60000000000355,35.937258181539754,0.5410049635342572,-0.052475057711278694
301.40000000000356,36.01290192613643,0.543791849390377,-0.05248825398859758
302.20000000000357,36.09070404683837,0.5441296717348721,-0.052149875450618666
303.0000000000036,36.16659084852621,0.5450638750036579,-0.05214988000127496
303.8000000000036,36.24045423795786,0.5446859953534335,-0.0521498825937452
304.6000000000036,36.319630087979434,0.54351133606969,-0.05272544349527264
305.4000000000036,36.39632440990803,0.5452133565981119,-0.052809878315736025
306.2000000000036,36.472861300721306,0.546480342472725,-0.05280605011850836
307.00000000000364,36.550197910122975,0.5429820659917676,-0.05410700338001506
307.80000000000365,36.62481042493666,0.5465360281136002,-0.05675958187340102
308.60000000000366,36.70205076855886,0.5461727020855772,-0.056750055731983995
309.4000000000037,36.779172499247544,0.5480739521985776,-0.0553526732564964
310.2000000000037,36.855265918634814,0.5479775232878333,-0.05542900928919137
311.0000000000037,36.93255929426726,0.545509871791083,-0.05411945223031456
311.8000000000037,37.00839759317179,0.5471097882996467,-0.05547606901847013
312.6000000000037,37.08496963457095,0.5466822797954729,-0.05543988125388033
313.40000000000373,37.161499790144525,0.549366943310086,-0.055440564044492824
314.20000000000374,37.23819195468723,0.5511941047149108,-0.057068367673169806
315.00000000000375,37.314490188332066,0.5520498953052875,-0.057080160023815996
315.80000000000376,37.39112684035052,0.5499443283781441,-0.05806486810469025
316.6000000000038,37.46835069056801,0.5528560388491848,-0.05806997935284608
317.4000000000038,37.544382537202324,0.5543050643066257,-0.05872191784338687
318.2000000000038,37.621645017831476,0.5546898428586396,-0.05870903561064633
319.0000000000038,37.69851809901612,0.554572473991798,-0.05741990383133233
319.8000000000038,37.77384099977083,0.556118337980122,-0.05741988067615855
320.60000000000383,37.851738590699235,0.5606653772142116,-0.057428781063223244
321.40000000000384,37.927014938454654,0.5620093934361877,-0.05941983178364696
322.20000000000385,38.00352664857338,0.5610804863682881,-0.060360435456284556
323.00000000000387,38.08063147504856,0.5609574145823744,-0.061660486147380844
323.8000000000039,38.156276154678714,0.5626659397433562,-0.061693668815426594
324.6000000000039,38.23535943666938,0.5651464512153773,-0.06110524604622247
325.4000000000039,38.312366992325146,0.5669140911619333,-0.062384679300745205
326.2000000000039,38.38852465081092,0.5669081106045954,-0.06235557389413371
327.0000000000039,38.46558453291243,0.5660507295798471,-0.0630115661104731
327.80000000000393,38.54104767493488,0.5692927330705069,-0.06301010380855843
328.60000000000394,38.61870880441404,0.5693997323360407,-0.06168946784449636
329.40000000000396,38.696814860941814,0.5712170257049628,-0.061628998298896676
330.20000000000397,38.772843716526616,0.5714992142909899,-0.06268007784651886
331.000000000004,38.8499083971142,0.5704706358138696,-0.061358604685816776
331.800000000004,38.92667172107502,0.5721100288217755,-0.06235044157331471
332.600000000004,39.00343047503363,0.5726262693193156,-0.06234980002203727
333.400000000004,39.08105827083638,0.5730865633206886,-0.062349792188305386
334.200000000004,39.15740917343211,0.5732957575298779,-0.06370785854633532
335.00000000000404,39.234084084321985,0.575087360308591,-0.06367010210986734
335.80000000000405,39.310720260246235,0.5763980492326053,-0.06367010000002171
336.60000000000406,39.38714066398757,0.5739792816337254,-0.06367010003854379
337.40000000000407,39.464856199116845,0.577550490914885,-0.06367110846067092
338.2000000000041,39.54135432464508,0.5780366844979152,-0.06268080460707992
339.0000000000041,39.61955900309282,0.5750988643267454,-0.06396812982799194
339.8000000000041,39.69530213286758,0.5758563254663588,-0.06401066345833506
340.6000000000041,39.77250921319133,0.5781566398538857,-0.06563704112655566
341.4000000000041,39.84921877079624,0.5808355578610214,-0.06432922550325815
342.20000000000414,39.92649072863749,0.5819136179226831,-0.06433017487121795
343.00000000000415,40.0032553866855,0.5841091185261877,-0.06433017499999405
343.80000000000416,40.08062101135656,0.5851317270271095,-0.06433017499999938
344.6000000000042,40.15777484419274,0.5843430471797448,-0.0643301749999603
345.4000000000042,40.23502319005582,0.5842932167050676,-0.0643301736196582
346.2000000000042,40.31184788608992,0.5836148263093772,-0.06430597411555761
347.0000000000042,40.38872273263726,0.586930988699303,-0.06531995077438202
347.8000000000042,40.46513428956742,0.5870283399963543,-0.06531118830003768
348.60000000000423,40.54273559792596,0.5884896526628183,-0.06631051281687217
349.40000000000424,40.61980974185115,0.5881760819159407,-0.06630991884012705
350.20000000000425,40.69700272829794,0.5920226362117789,-0.06690195348281769
351.00000000000426,40.77530514574662,0.5895215562967808,-0.06697006730772825
351.8000000000043,40.851991140265156,0.5898501262251825,-0.06697006999994182
352.6000000000043,40.92949530208954,0.5897615872665383,-0.06697007000260946
353.4000000000043,41.00635017034716,0.591157649348194,-0.06697166197688809
354.2000000000043,41.0838071073868,0.5915184677538997,-0.06894586030870364
355.0000000000043,41.160304221789595,0.5927867927725665,-0.06893981138216221
355.80000000000433,41.23781353347894,0.5946906967337312,-0.0702264496942222
356.60000000000434,41.315821748697914,0.5937046012609782,-0.07092016245703547
357.40000000000435,41.391490919534384,0.5971202122695856,-0.07092028033870967
358.20000000000437,41.46949893923481,0.5976608905951533,-0.0715793710606949
359.0000000000044,41.54718710445987,0.5995489464845197,-0.0715798849128908
359.8000000000044,41.624567958358185,0.5996873241597244,-0.07157988499999535
360.6000000000044,41.702055146404426,0.6010842760077055,-0.07157988500000023
361.4000000000044,41.77927770733113,0.6028300107514819,-0.07157988500001
362.2000000000044,41.85636706586772,0.6049793505513364,-0.07157988591253295
363.00000000000443,41.934452632101724,0.6078829282419694,-0.07160860820799053
363.80000000000445,42.01114042962153,0.609123610365239,-0.07322009191413814
364.60000000000446,42.08926275073296,0.6106613061741956,-0.07453969535317118
365.40000000000447,42.16635143626778,0.6100432642018779,-0.0745399299590721
366.2000000000045,42.24398264575945,0.6127533705870339,-0.07453992932630049
367.0000000000045,42.31974380544344,0.6150241472468065,-0.07454138255349774
367.8000000000045,42.39921626514114,0.6159598644986695,-0.07322007080899473
368.6000000000045,42.47588980718562,0.616784664254598,-0.07322003473464944
369.4000000000045,42.55371976307454,0.615305797685117,-0.07320975457020351
370.20000000000454,42.63029955201179,0.6178736734279172,-0.07453969788892545
371.00000000000455,42.708049259068595,0.6162453665787502,-0.07585206381943266
371.80000000000456,42.78546894257519,0.6176509750939507,-0.0768416129050209
372.60000000000457,42.861877074945205,0.6176406160236628,-0.07683931237158337
373.4000000000046,42.940628973925094,0.6197642090096177,-0.07716670190525887
374.2000000000046,43.018032721026294,0.6185512914423194,-0.07847689288909754
375.0000000000046,43.09654463037236,0.619285132009699,-0.07751909031730353
375.8000000000046,43.17300111220297,0.62154384527244,-0.08014362854518087
376.6000000000046,43.250444815085075,0.6207040714833663,-0.08145115621817034
377.40000000000464,43.32904257427836,0.6223822033877522,-0.08145007445846275
378.20000000000465,43.40709478425957,0.6214827589653626,-0.0821294049143404
379.00000000000466,43.48374910604432,0.6198000551319165,-0.08276996280200644
379.8000000000047,43.56202179425527,0.6202356257278928,-0.08277502256860503
380.6000000000047,43.638685434728075,0.6202250233742901,-0.08409062736942374
381.4000000000047,43.71477613388859,0.6184388094995465,-0.08639798462137316
382.2000000000047,43.79207920076986,0.6172816322243261,-0.08507690960148206
383.0000000000047,43.87215537661529,0.6174428138900057,-0.08508061273293954
383.80000000000473,43.94909960279999,0.6144780151219289,-0.08408530944894466
384.60000000000474,44.02766617842243,0.610710959779819,-0.08410084514839244
385.40000000000475,44.105247597490646,0.6090183225055263,-0.08671833180514277
386.20000000000476,44.18225784627393,0.6065069856834306,-0.08672355350597716
387.0000000000048,44.26163911605099,0.6004087631374208,-0.08802601062895254
387.8000000000048,44.33937409733359,0.5980663362628079,-0.08936021569698438
388.6000000000048,44.417286917557576,0.5939120694401885,-0.09060169959435616
389.4000000000048,44.49462326351359,0.5884395492314339,-0.09068001663762981
390.2000000000048,44.57309197543685,0.5842664629612532,-0.09067741233831228
391.00000000000483,44.650595330818355,0.5824915619008366,-0.09167436628486625
391.80000000000484,44.72967861368634,0.5800424187681359,-0.09331091683628623
392.60000000000485,44.80786471636438,0.5801368540288222,-0.09330283454883848
393.40000000000487,44.88504237755806,0.5792351514267066,-0.09462808447305004
394.2000000000049,44.96190692202521,0.5779288634812781,-0.09595038077929807
395.0000000000049,45.040571446984735,0.5835216814488502,-0.0979982158893602
395.8000000000049,45.11796675867354,0.5812272684114235,-0.09881645186896204
396.6000000000049,45.19622132944347,0.57973554210807,-0.10057167042718307
397.4000000000049,45.27400850957713,0.586673983029478,-0.10332839299840524
398.20000000000493,45.352168937376184,0.5869225968207029,-0.10562094028996905
399.00000000000495,45.429345329939444,0.5898858446710155,-0.10425747174227329
399.80000000000496,45.50772279659653,0.5911965340028583,-0.10559994802184036
400.60000000000497,45.58566725880891,0.5926525279839531,-0.10559995622333762
401.400000000005,45.66397579472693,0.5954026233913032,-0.10564039067703801
402.200000000005,45.742063537824976,0.5972355030057738,-0.1046468697758729
403.000000000005,45.81892437848342,0.5996037965523204,-0.10979080530322882
403.800000000005,45.89700886570246,0.5966239915622931,-0.11196715156227288
404.600000000005,45.97559375095323,0.5974420330677952,-0.11538907268536969
405.40000000000504,46.05279923075082,0.5958914131024894,-0.11693506648478813
406.20000000000505,46.13042412304164,0.5966813873942949,-0.11823332393975905
407.00000000000506,46.208886568021796,0.5969639912508801,-0.11957274244084992
407.80000000000507,46.28712117936568,0.5957297995315483,-0.12022598566820708
408.6000000000051,46.365194176067696,0.5912092808373886,-0.122415625985143
409.4000000000051,46.44375036589702,0.584367632005148,-0.12551082022219662
410.2000000000051,46.52151087078328,0.5848077460791398,-0.1272645717551235
411.0000000000051,46.59980899991209,0.584932670301753,-0.13106446091208346
411.8000000000051,46.67773481300162,0.5890072225908671,-0.13238802936141214
412.60000000000514,46.75604578791552,0.5906743855086549,-0.13370389037208108
413.40000000000515,46.83332790388665,0.5922461814750348,-0.13502534803468835
414.20000000000516,46.911532800764874,0.5974365132119682,-0.13681188537078848
415.0000000000052,46.98889752492949,0.6018668625367196,-0.1404836677291743
415.8000000000052,47.06712410241668,0.6052363480711946,-0.1435317794193356
416.6000000000052,47.14576085733411,0.6099439060041563,-0.1467778924656118
417.4000000000052,47.22315830114493,0.6119328304983356,-0.15016665778183658
418.2000000000052,47.301578202750036,0.6170974686313394,-0.15365151487717155
419.00000000000523,47.377723970661144,0.6200557146616857,-0.15626233013484292
419.80000000000524,47.45705601550001,0.6254653540447933,-0.1586548599450479
420.60000000000525,47.53426820428957,0.63563351948279,-0.16285032025839064
421.40000000000526,47.61278086735171,0.6431030932368337,-0.16557659029224947
422.2000000000053,47.69104472339799,0.6499286432059819,-0.16979734175086225
423.0000000000053,47.769459862748235,0.6582162760924204,-0.17622066276696113
423.8000000000053,47.845835612014405,0.6697494154273975,-0.17890075990094179
424.6000000000053,47.92520313841542,0.6794374587175617,-0.18333565817094577
425.4000000000053,48.004298256775385,0.6950208822723521,-0.18898762946392544
426.20000000000533,48.08164675921583,0.7030600532706994,-0.19338568997738648
427.00000000000534,48.160000000000565,0.7197780861025974,-0.19772110694767342
427.80000000000535,48.238728037720975,0.7351337284031324,-0.20613555533996175
428.60000000000537,48.316523063985734,0.75332729316211,-0.2139419435172205
429.4000000000054,48.395412128719826,0.7741725147319285,-0.22199636170183057
430.2000000000054,48.47273246110568,0.7913111230328475,-0.2300675794213265
431.0000000000054,48.55080382873342,0.8142185715545032,-0.2375583735543687
431.8000000000054,48.62866356422105,0.8342962928874296,-0.24526668560167098
432.6000000000054,48.707745811996006,0.8615069079707833,-0.25457668448013804
433.40000000000543,48.785575908412056,0.8894667756493575,-0.26504492012509573
434.20000000000545,48.863859198883375,0.916051181802322,-0.2754072079488532
435.00000000000546,48.94147071721016,0.9445851981922799,-0.2878364628892238
435.80000000000547,49.02049415404098,0.9750512627177343,-0.3002396658509068
436.6000000000055,49.098318459446816,1.0068655115563465,-0.3157674277835656
437.4000000000055,49.17781516005786,1.0445598036607198,-0.3330256861558998
438.2000000000055,49.25605128104312,1.082642601078784,-0.34866589275863724
439.0000000000055,49.33438811616186,1.1220494664907423,-0.36825314962995304
439.8000000000055,49.41254916989167,1.1610974757551933,-0.3879209247387716
440.60000000000554,49.4910379251124,1.2050645336190455,-0.4077664703476547
441.40000000000555,49.569154734103016,1.2508485370829838,-0.4311041950286647
442.20000000000556,49.64802750236706,1.3003069405293952,-0.4563876113546983
443.00000000000557,49.726511927097874,1.3473534000096694,-0.48197819072533665
443.8000000000056,49.8047948667024,1.406996940675586,-0.5094158585401121
444.6000000000056,49.883665774731874,1.4542696544816223,-0.5426403869259064
445.4000000000056,49.962533230368045,1.5045572090086266,-0.5778745693864229
446.2000000000056,50.03914562221894,1.5654413969170773,-0.6131424730799613
447.0000000000056,50.11874660355639,1.6190287338642384,-0.6526909267707932
447.80000000000564,50.198360360176736,1.6790422493756862,-0.694187673991038
448.60000000000565,50.2737989111788,1.7276322548915402,-0.7371584387729375
449.40000000000566,50.35609586466077,1.795251566988242,-0.7856755068470527
450.2000000000057,50.43409149569855,1.8455222082695162,-0.8359706125830635
451.0000000000057,50.513261396000225,1.88392761090619,-0.889385714315678
451.8000000000057,50.591601015585724,1.9459807786866814,-0.9435257215946287
452.6000000000057,50.670211679797276,1.9913954796868003,-1.0053403147500775
453.4000000000057,50.74910245492205,2.0458545763291327,-1.0705750872115543
454.20000000000573,50.828258546036786,2.0828888239667935,-1.1404940816097362
455.00000000000574,50.90635271149457,2.112773645091214,-1.2126364162499232
455.80000000000575,50.98601555052237,2.1540416187261133,-1.2868517772253152
456.60000000000576,51.06250934786603,2.2015085039767905,-1.361225346885
457.4000000000058,51.14366617783726,2.247407985591214,-1.4455457416473032
458.2000000000058,51.22245123426002,2.2572406497921,-1.5324346429166535
459.0000000000058,51.30153846264298,2.2732872283225634,-1.6225586238654373
459.8000000000058,51.380845091767256,2.2949771968458395,-1.7192209942984036
460.6000000000058,51.45942496158121,2.305777201118181,-1.8178156585862157
461.40000000000583,51.53867333070073,2.3133145039769083,-1.9212867902308193
462.20000000000584,51.617163043092646,2.2823671243249057,-2.026098678573422
463.00000000000585,51.69299559564007,2.2559679129062467,-2.129795130014438
463.80000000000587,51.772637489733,2.221150985049559,-2.242510524109142
464.6000000000059,51.851102485041785,2.1726560680055482,-2.3537846663603754
465.4000000000059,51.929114957461096,2.110392986147858,-2.4669906873721077
466.2000000000059,52.00950081687207,2.0302534963272016,-2.583999335119225
467.0000000000059,52.08760129235689,1.941926657934062,-2.696317947478236
467.8000000000059,52.16637544993971,1.8413257602739521,-2.8107772921819922
468.60000000000593,52.244018977322696,1.726873201626279,-2.9201615267355088
469.40000000000595,52.322948248482604,1.604528312489541,-3.028712933685507
470.20000000000596,52.399360813631354,1.4722636064891694,-3.1306693102061267
471.00000000000597,52.477353981375224,1.334932181976875,-3.2317479879557496
471.800000000006,52.554806449970506,1.1944059769632365,-3.324354212872315
472.600000000006,52.630758268089394,1.0497262966864191,-3.4130699283517596
473.400000000006,52.71000096645196,0.9040422539360711,-3.4965919943578316
474.200000000006,52.787800982151786,0.7638400823849565,-3.5730137652012504
475.000000000006,52.862962109509056,0.6326988812007294,-3.6380606996414073
475.80000000000604,52.94311333801041,0.5087171999133199,-3.7016908214694504
476.60000000000605,53.02193177745318,0.40011325304655426,-3.757868458747471
477.40000000000606,53.09899357880857,0.3062162171063567,-3.806253952581411
478.20000000000607,53.17622927163298,0.22826900560657248,-3.8485699134613087
479.0000000000061,53.25461745230118,0.16283265435339433,-3.8863570591139154
479.8000000000061,53.33313690086682,0.11332359880434684,-3.9197830130264846
480.6000000000061,53.41106387691205,0.07371904814524505,-3.9485811477075865
481.4000000000061,53.48912126579778,0.04672149140954718,-3.973768167683365
482.2000000000061,53.568067470569936,0.029352178998400202,-3.9959002554292296
483.00000000000614,53.646305566352765,0.017565934844104514,-4.0141595873318
483.80000000000615,53.72515381412273,0.008924110430982402,-4.030250338318311
484.60000000000616,53.80304470862836,0.009741525175487487,-4.0436008344799275
485.4000000000062,53.882648224707765,0.007670209971851971,-4.053287794288675
486.2000000000062,53.96109094462427,0.0074922629833710785,-4.060986146065627
487.0000000000062,54.03883193511891,0.006487374574809357,-4.06640028445634
487.8000000000062,54.1179831635589,0.0041634574059355445,-4.070999026267269
488.6000000000062,54.196418857819495,0.00654318114551633,-4.074138465915082
489.40000000000623,54.275231605986875,0.004837114070023851,-4.075385944810488
490.20000000000624,54.35378931152342,0.007471580887086882,-4.078300269880966
491.00000000000625,54.432560445832436,0.008064024202917464,-4.078329809343499
491.80000000000626,54.51041826883151,0.008420133611302116,-4.078329810003507
492.6000000000063,54.58961218352797,0.008607278262240281,-4.078329692553457
493.4000000000063,54.668137832472894,0.008200983207302615,-4.079649706308104
494.2000000000063,54.747309919066744,0.013949798868295615,-4.079805851084538
495.0000000000063,54.82511511417644,0.027761791593173324,-4.080642744819711
495.8000000000063,54.90281838320909,0.03209887642060488,-4.07898749374894
496.60000000000633,54.98120106420576,0.02839525933582493,-4.077667373085253
497.40000000000634,55.06027148434825,0.023026625146088497,-4.077669809982576
498.20000000000636,55.13980246078407,0.01409434404884069,-4.077669818913343
499.00000000000637,55.217819027887515,0.007625856566594202,-4.079110362474356
499.8000000000064,55.29770999675494,0.011482090901490105,-4.077996004330755
500.6000000000064,55.37509312334301,0.010806116210589689,-4.079015339969601
501.4000000000064,55.45413897798752,0.014226747942997997,-4.080299905101864
502.2000000000064,55.53329230796086,0.015757286905527967,-4.08027278091533
503.0000000000064,55.61294774408823,0.021721047040781927,-4.078988610644147
503.80000000000643,55.6914198679328,0.026713960196429243,-4.076354162934295
504.60000000000645,55.77043262030419,0.03365568502659266,-4.077670165698709
505.40000000000646,55.84872947914602,0.03752299798760217,-4.079035373753615
506.20000000000647,55.92802565061887,0.04227046759607089,-4.080299901526261
507.0000000000065,56.00779824773815,0.04874100473905402,-4.080300708794705
507.8000000000065,56.08720705340088,0.0542443869110919,-4.08129055163786
508.6000000000065,56.16483107187096,0.055781149923556594,-4.081254937079263
509.4000000000065,56.24556760304388,0.05994896898453461,-4.079979903892255
510.2000000000065,56.323401486799334,0.06372759691725338,-4.079962379436199
511.00000000000654,56.400826748461526,0.06088650031772663,-4.078663280768656
511.80000000000655,56.48204827862436,0.06443747795152838,-4.0812878390487795
512.6000000000065,56.560482924627856,0.06906256046423231,-4.082609961679335
513.4000000000066,56.639441536912905,0.071043287798227,-4.082610000664326
514.2000000000066,56.7183869681796,0.07198349385866115,-4.082633806216287
515.0000000000066,56.7974744058927,0.07057703034741586,-4.081249417244696
515.8000000000065,56.87595882158334,0.07206395633141482,-4.0826621485365635
516.6000000000066,56.95436833430665,0.07285942218982505,-4.081290074073507
517.4000000000067,57.03408499471544,0.07287771437425017,-4.081290125730012
518.2000000000066,57.11221568314504,0.07267783704530084,-4.080958428780121
519.0000000000066,57.19142568806566,0.07338194376878021,-4.080960083262921
519.8000000000067,57.27075763527718,0.07802548538505366,-4.080298066892061
520.6000000000067,57.349504754071226,0.07585145557535222,-4.080299850166266
521.4000000000067,57.42886650045131,0.07935373733635981,-4.080309173711742
522.2000000000066,57.50813458152212,0.0774129827216602,-4.081641696201849
523.0000000000067,57.58712257576641,0.07845237520222959,-4.081620960887514
523.8000000000068,57.666338510776704,0.08105452397575674,-4.0829419093237265
524.6000000000067,57.746215859434,0.07916953382937642,-4.081620222503985
525.4000000000067,57.823630486275995,0.08039026057635723,-4.081619655426835
526.2000000000068,57.904435036939454,0.08099509288930773,-4.082938194486985
527.0000000000068,57.983352289935446,0.08039250193427877,-4.0829401367961475
527.8000000000068,58.06138116607011,0.08325657628205346,-4.082282449919742
528.6000000000067,58.14119718340427,0.08147689766835414,-4.08359892909601
529.4000000000068,58.220527085594426,0.08292416916980999,-4.082293177202683
530.2000000000069,58.29933809192398,0.08052575656654376,-4.082907740697614
531.0000000000068,58.37856309429935,0.08000491950212801,-4.084260109710098
531.8000000000068,58.45702433232263,0.07788580841329484,-4.083800394187533
532.6000000000068,58.5364024691837,0.07364563880166436,-4.083270040143782
533.4000000000069,58.615130256104045,0.0731977008798938,-4.083270047503073
534.2000000000069,58.69469507264526,0.07076555951962171,-4.083385854713934
535.0000000000068,58.77368666272111,0.07289166127596747,-4.085176232900698
535.8000000000069,58.852746090597144,0.07333830893820559,-4.083596069135091
536.600000000007,58.93170562243598,0.07386494136264798,-4.083599964916457
537.4000000000069,59.01125546773716,0.07417102092090311,-4.083599848882054
538.2000000000069,59.08999901682894,0.06929492553212402,-4.084581880914127
539.0000000000069,59.16884345907288,0.07265102376708543,-4.084579964898317
539.800000000007,59.248499503564375,0.07119911950973562,-4.0845799650562045
540.600000000007,59.32805163088057,0.07387636119498331,-4.08458268857087
541.4000000000069,59.40515226016555,0.07497074326864034,-4.083260788361174
542.200000000007,59.48538468454838,0.07260473421776287,-4.083348265965994
543.000000000007,59.56299811537223,0.07385726968832246,-4.084579978140232
543.800000000007,59.64407055276962,0.07569158097324363,-4.085842960640887
544.600000000007,59.72251423850427,0.0779934201120025,-4.084610126348856
545.400000000007,59.80270146678252,0.07783393859278215,-4.083269903989352
546.2000000000071,59.88157956405744,0.07556491782541203,-4.081901897972607
547.000000000007,59.96052398147074,0.07652018099114394,-4.081949964907787