File: 01_Data/Polyester_Carpet_Medium_Pile/STA/N2/3K_min/Polyester_Carpet_Medium_Pile_STA_N2_3KData_220104_R1.csv
##Temp./Â°C,Time/min,DSC/(mW/mg),Mass loss/mg
50.0,10.732874512542319,0.022726545830661027,-0.009399072961281618
51.000000000000014,11.460505818141588,0.047883025721567885,-0.00817915745322928
52.00000000000003,11.923838654009232,0.055371074435598966,-0.009857859438938466
53.00000000000004,12.331736987823668,0.059797427489629795,-0.008534454805802394
54.00000000000006,12.720396642412709,0.06394365571585559,-0.008698802322208987
55.00000000000007,13.09947422872804,0.0646324396232576,-0.011183701979420757
56.000000000000085,13.465020558479484,0.06591546563725303,-0.012171787638950882
57.0000000000001,13.835873278141305,0.0663372981606859,-0.012064669415610574
58.000000000000114,14.19113541471847,0.06638255972868568,-0.011094646967976907
59.00000000000013,14.556113256076275,0.07197041018513162,-0.010849983296397081
60.00000000000014,14.906081560602185,0.07075083238502211,-0.011078947926840499
61.000000000000156,15.264828586026075,0.07240526545298842,-0.011179766608816255
62.00000000000017,15.60385871143154,0.07149730767860651,-0.009901686611403893
63.000000000000185,15.948848761873501,0.07308458981493948,-0.012499881314156802
64.0000000000002,16.2857645431479,0.07467967840911927,-0.009895987365368342
65.00000000000021,16.62617179718891,0.0725962245820142,-0.012494003768510176
66.00000000000023,16.948678146419763,0.07231861058517541,-0.012829902192214693
67.00000000000024,17.304906495766176,0.07401541442104742,-0.012500134238594196
68.00000000000026,17.645737751716542,0.06998671005918733,-0.012499964007445907
69.00000000000027,17.982288888567346,0.07048123544932683,-0.012490504240272315
70.00000000000028,18.322138133471515,0.0706722386888674,-0.012491840349062144
71.0000000000003,18.659475550813855,0.06865725168483927,-0.011850145130281042
72.00000000000031,18.992034813729912,0.06957967358208983,-0.013810854520449833
73.00000000000033,19.32606396273853,0.06943236621477278,-0.014635150267408026
74.00000000000034,19.666358509991966,0.06877312372817412,-0.013478398869931407
75.00000000000036,19.99651582099872,0.06728920702064167,-0.013634050114579743
76.00000000000037,20.339406687698904,0.06831666839393313,-0.013810319977624275
77.00000000000038,20.673597978713257,0.066344918741708,-0.013771600243978721
78.0000000000004,21.011433908847874,0.0664437222746751,-0.014235425461963658
79.00000000000041,21.343463818403393,0.06723505840189614,-0.015510092906401596
80.00000000000043,21.68193277001299,0.0672085841735176,-0.013809990979926745
81.00000000000044,22.01918524133664,0.0660029660192949,-0.01512998998371673
82.00000000000045,22.35000000000015,0.06717393679269745,-0.015130169121869042
83.00000000000047,22.686797724066437,0.07088094132919043,-0.014800594192547756
84.00000000000048,23.020902525091365,0.06852068585138493,-0.014796162727983564
85.0000000000005,23.355294958269123,0.06722655559248958,-0.015129831850199338
86.00000000000051,23.69020184349797,0.06837959356491541,-0.016387484107224015
87.00000000000053,24.028906322963202,0.07022455318373133,-0.015133229828823591
88.00000000000054,24.355651021945903,0.06868146477546355,-0.015126408239515943
89.00000000000055,24.691710338091568,0.06568624273184354,-0.01645118014951663
90.00000000000057,25.028077409640034,0.06915948297516161,-0.015129872135613898
91.00000000000058,25.360218247360514,0.06850666548709683,-0.016449862882942146
92.0000000000006,25.692167273865962,0.06772866358079022,-0.015118307145962628
93.00000000000061,26.028885318085635,0.07033708319447252,-0.01776551267745452
94.00000000000063,26.35699761096242,0.06796559906804245,-0.01776989928967776
95.00000000000064,26.690805243049745,0.06888990564603314,-0.017769884074231967
96.00000000000065,27.023219101826726,0.07012830183663221,-0.015789645373408767
97.00000000000067,27.35784139223983,0.07052125613479143,-0.0170999586566718
98.00000000000068,27.686831401122017,0.0717639717010331,-0.01677998344130449
99.0000000000007,28.02000000000032,0.07101202831957065,-0.018090135999999646
100.00000000000071,28.351660875761638,0.0733383147000648,-0.017101367158707692
101.00000000000072,28.683261355586403,0.07153787497475639,-0.017111351360483695
102.00000000000074,29.018642390125702,0.07185143407364669,-0.01798973911642454
103.00000000000075,29.351798271792855,0.070144421046341,-0.01665413864171894
104.00000000000077,29.683720489570156,0.07116308414272499,-0.017330139041087822
105.00000000000078,30.01058867616818,0.07182225881056037,-0.01731997199986335
106.0000000000008,30.341231521067797,0.0699465028688161,-0.017330407854034835
107.00000000000081,30.670506045087784,0.07139000898875503,-0.01633962397854294
108.00000000000082,31.000770411394484,0.07211977896880784,-0.01633958985938433
109.00000000000084,31.330598055358806,0.07247959725033737,-0.017650062699809954
110.00000000000085,31.66099829760515,0.0722389227374739,-0.018092467276229485
111.00000000000087,31.99311638847391,0.07517373534223037,-0.016999830000000493
112.00000000000088,32.324711410196244,0.07695387746604343,-0.017989250074922136
113.0000000000009,32.65300671091588,0.07787853270152678,-0.017240149316950504
114.00000000000091,32.982307411090126,0.07536138175507168,-0.017664745456289488
115.00000000000092,33.31282224459906,0.07681963753395482,-0.016989896000043636
116.00000000000094,33.6458216524326,0.07469578017155742,-0.018309895997020487
117.00000000000095,33.978842676995605,0.07884296002805391,-0.016339270519228233
118.00000000000097,34.306052742808475,0.07657621511730783,-0.017344393254230095
119.00000000000098,34.638746002701865,0.07853536095048297,-0.017990075614697343
120.000000000001,34.968353283399935,0.07829178779029344,-0.016669911999827924
121.00000000000101,35.29673011807926,0.07644781458097594,-0.016660143997365928
122.00000000000102,35.62483741050135,0.0783250651834021,-0.01666014399999982
123.00000000000104,35.95405796064753,0.07834937414452736,-0.017985576210869603
124.00000000000105,36.28417498954436,0.07369721055201028,-0.01666774817134309
125.00000000000107,36.61232479793165,0.07869807228840608,-0.01732992799998101
126.00000000000108,36.94201149690717,0.07842411835870045,-0.0176499338926015
127.0000000000011,37.270478856087074,0.07710289925541214,-0.01732015997151004
128.0000000000011,37.60142950151723,0.07691283724501641,-0.01632993630999069
129.00000000000114,37.92925882327683,0.07622864530351581,-0.014342111520166068
130.00000000000114,38.258493527747,0.07760312546370285,-0.017001997479525244
131.00000000000114,38.59000000000046,0.07712181637757576,-0.017000174096164056
132.00000000000117,38.9200000000004,0.07779713567847213,-0.016999835999999213
133.0000000000012,39.252110429331296,0.07703338101661217,-0.015680206750623427
134.0000000000012,39.576040774815624,0.07602225928133277,-0.016660949873183117
135.0000000000012,39.908147626085636,0.07942752027419286,-0.016908141191803505
136.00000000000122,40.23271497047233,0.08031103142702989,-0.016010134000000065
137.00000000000125,40.5600000000004,0.07986183709802774,-0.016010134000000953
138.00000000000125,40.890000000000605,0.0811106321927677,-0.014551069991592058
139.00000000000125,41.216761450189246,0.0799519936998947,-0.01568137472293918
140.00000000000128,41.54756428194459,0.07937388051307959,-0.01701180150035686
141.0000000000013,41.87289126762946,0.07816829003928294,-0.014374000586018454
142.0000000000013,42.20086920284673,0.07700592167360687,-0.01568035618455177
143.0000000000013,42.53604603053828,0.0773404021891444,-0.013607954959600654
144.00000000000134,42.864152550695636,0.07751444316771017,-0.014919926007293416
145.00000000000136,43.189614552181716,0.08122318397222417,-0.014916557048925583
146.00000000000136,43.51782193904752,0.07878397622115729,-0.014185085329805336
147.00000000000136,43.84607111276303,0.08264389547873308,-0.015239925938301813
148.0000000000014,44.17266564127163,0.08144607022312167,-0.013901490516368131
149.00000000000142,44.513713179194774,0.0801197899272923,-0.014910155467376285
150.00000000000142,44.83245315312648,0.07879693689980904,-0.014911351854720145
151.00000000000142,45.156098937706666,0.08179726120863506,-0.014579933999628203
152.00000000000145,45.487063178306016,0.07950608960830269,-0.014579933999999017
153.00000000000148,45.81255543406148,0.08348097596638604,-0.014579933627342001
154.00000000000148,46.13614666806615,0.08442402726325116,-0.015239933999999344
155.00000000000148,46.47066757832534,0.0846000455007867,-0.014909991983998783
156.0000000000015,46.74889839499339,0.08287368488839408,-0.013600058072935184
157.00000000000153,47.12804222882422,0.0870678410748762,-0.013753092905673725
158.00000000000153,47.45134309923689,0.08726322182848179,-0.013278417353271621
159.00000000000153,47.78025019594106,0.09199049524468644,-0.013269949999999753
160.00000000000156,48.10742236240545,0.09496361970201406,-0.014580627867982088
161.0000000000016,48.42886637888897,0.09499300482302286,-0.013929842074163812
162.0000000000016,48.75546734221576,0.09584618452076915,-0.015290830485437557
163.0000000000016,49.08471314521992,0.101393363017171,-0.01524407861793975
164.00000000000162,49.412230245116795,0.1022383430317419,-0.014897367919882498
165.00000000000165,49.73968445005743,0.10621833860386137,-0.014909254557207596
166.00000000000165,50.06643236558656,0.10870543384687614,-0.015544569016782361
167.00000000000165,50.39174372307974,0.10681085637466708,-0.014581023708846175
168.00000000000168,50.72480075673546,0.11089050615562279,-0.014906970300823552
169.0000000000017,51.04802295408504,0.106537300200363,-0.015580794369337347
170.0000000000017,51.37527313287129,0.1023717820726317,-0.016889850789972627
171.0000000000017,51.70290841846782,0.09804453680675884,-0.016889936611623302
172.00000000000173,52.03211265104356,0.09269254511152053,-0.014249789594205975
173.00000000000176,52.3552042012757,0.09143169142733992,-0.015570177011443587
174.00000000000176,52.67653909728256,0.08935784782081246,-0.01688549007412954
175.00000000000176,53.00963442630124,0.0872200546169678,-0.016220169475032797
176.0000000000018,53.337142274982675,0.08931702764968219,-0.01688018034960992
177.00000000000182,53.65841350604903,0.0867979169678132,-0.017042491653947778
178.00000000000182,53.99000000000101,0.08448123053404394,-0.01655018200000047
179.00000000000182,54.3139691657673,0.08493116086512797,-0.017870676319478473
180.00000000000185,54.64133921340769,0.08842177267249218,-0.017870313129519033
181.00000000000188,54.962242717327165,0.08846455502833384,-0.017230454707275467
182.00000000000188,55.295823736893965,0.0864014041102093,-0.017420074837602773
183.00000000000188,55.62600123578444,0.08750187331844361,-0.016883190546114868
184.0000000000019,55.952712424336724,0.08727860774378254,-0.016889827157850146
185.00000000000193,56.27926347419063,0.08963048649122823,-0.016229554269470814
186.00000000000193,56.60589266565931,0.08925783240082552,-0.015197214979747908
187.00000000000193,56.93318530095089,0.08956913586082815,-0.017879906691233405
188.00000000000196,57.255942369981994,0.08992412728171417,-0.016890066743881604
189.000000000002,57.58415612266162,0.08902776643617977,-0.01689143494532752
190.000000000002,57.910261729253364,0.0866573675064326,-0.015249432187876
191.000000000002,58.237221220498995,0.08684563657446992,-0.017876937115030245
192.00000000000202,58.561597234561006,0.08925229878029406,-0.01589985637063851
193.00000000000205,58.88551410689087,0.08826224268464794,-0.017870024453999545
194.00000000000205,59.211020496632315,0.08551728691985033,-0.017540197135422986
195.00000000000205,59.54057613604324,0.08787288843277397,-0.017539420040939557
196.00000000000207,59.867155461018534,0.08883190493271304,-0.01819945292026981
197.0000000000021,60.19352099500369,0.08701990616099997,-0.01754859139197107
198.0000000000021,60.51968349308564,0.08755193229803165,-0.016434199331411214
199.0000000000021,60.84564403509009,0.08895311973431597,-0.018526911970598636
200.00000000000213,61.17353542778666,0.09051384617322966,-0.017203840612916466
201.00000000000216,61.497798680394595,0.0913110641942168,-0.01689008200151454
202.00000000000216,61.824102342149516,0.0937666184091589,-0.01805492942258624
203.00000000000216,62.14917108361016,0.09149815435333747,-0.017353710869150163
204.0000000000022,62.47515160834583,0.09840691035317634,-0.017870076497035647
205.00000000000222,62.80072737763828,0.09569670519391094,-0.019198430043106285
206.00000000000222,63.125951511912405,0.09358157700855618,-0.018199966000430834
207.00000000000222,63.45194055824792,0.0957441604414701,-0.0175499659998124
208.00000000000225,63.77649067737604,0.09441229316006727,-0.018801683445786477
209.00000000000227,64.10237682510413,0.09153633355667662,-0.017549965998707062
210.00000000000227,64.42709798037613,0.0920484596372595,-0.01754996600000025
211.00000000000227,64.75458770022273,0.09364508742704747,-0.017549965890813812
212.0000000000023,65.07657236027755,0.09171159241635857,-0.018209850000001193
213.00000000000233,65.40429580927376,0.08932341556890078,-0.01689713331106324
214.00000000000233,65.72938542062606,0.0884311419424344,-0.01951870505397535
215.00000000000233,66.06035800141511,0.0879832578862787,-0.018209886188989
216.00000000000236,66.38256373373153,0.08940843562622552,-0.020500124016795684
217.0000000000024,66.70604476368052,0.08955603858780403,-0.017880030342191766
218.0000000000024,67.03338739504274,0.08994494169769834,-0.0178904425778601
219.0000000000024,67.36178733538385,0.09086446954257754,-0.019197117181945167
220.00000000000242,67.68445087190484,0.09133871699861246,-0.019443202864664055
221.00000000000244,68.01473101307087,0.09168764916099298,-0.01820985005192277
222.00000000000244,68.33774748059096,0.0907901810223975,-0.018209850000000305
223.00000000000244,68.68232681705662,0.09358899119523928,-0.018209916787132574
224.00000000000247,68.99206121072245,0.09074231865643556,-0.018200095224788715
225.0000000000025,69.31415724815,0.09335858974948702,-0.018529326310420924
226.0000000000025,69.63759168567411,0.09617361801853791,-0.018852438329040044
227.0000000000025,69.96648579598047,0.09725881119167812,-0.018859838520985495
228.00000000000253,70.29101890859351,0.09724493450528318,-0.01886118550862914
229.00000000000256,70.61170678989119,0.09502405744742978,-0.018529843511963406
230.00000000000256,70.94309497678202,0.09612256405220498,-0.01852984199599561
231.00000000000256,71.26534033586212,0.09720473828538459,-0.0191798417866047
232.0000000000026,71.59586461750922,0.09722377007988048,-0.018529907992311134
233.00000000000261,71.92227275707533,0.09454236501617841,-0.018524856062347883
234.00000000000261,72.2491984236071,0.09542613918635534,-0.020656346320124364
235.00000000000261,72.5723963436566,0.09811876804041894,-0.01885785749926283
236.00000000000264,72.8980597454286,0.10203127338428963,-0.018861232160584773
237.00000000000267,73.22607544495581,0.10319647279386407,-0.02083000771868937
238.00000000000267,73.5494024236272,0.1068119742002735,-0.019510496528937882
239.00000000000267,73.87407664240038,0.1096901035472915,-0.020830015104423616
240.0000000000027,74.20032085787551,0.11315741215363564,-0.020500065983394933
241.00000000000273,74.5222364140928,0.11740848759354863,-0.02078286162095777
242.00000000000273,74.84808684354304,0.12153515036940113,-0.02247997404682378
243.00000000000273,75.1739420666562,0.12766951378975772,-0.0214946796024007
244.00000000000276,75.50043724497502,0.13384202140242832,-0.02313934588379052
245.00000000000279,75.83189675958393,0.14861471287276296,-0.021819889198809506
246.00000000000279,76.15543581199807,0.1663103266332421,-0.022483186040931802
247.00000000000279,76.48053139526768,0.19221666302831086,-0.022480174007824427
248.0000000000028,76.81037073632073,0.23516205355618533,-0.022480173999999575
249.00000000000284,77.14033754854681,0.2744238771481897,-0.022480174000000464
250.00000000000284,77.46908241164101,0.2608014426507313,-0.02280992908634305
251.00000000000284,77.79189042621033,0.22049916442968803,-0.0241179857201832
252.00000000000287,78.1177556759295,0.18285455557249708,-0.022800120943311075
253.0000000000029,78.43909692521109,0.1602362757819145,-0.022800050019200935
254.0000000000029,78.76452444778457,0.14203625949024012,-0.024024792390045846
255.0000000000029,79.08759282570195,0.12572317786061282,-0.022800050661103022
256.00000000000296,79.41409113705684,0.11249347574389387,-0.02313868565067212
257.00000000000296,79.73732183067911,0.10678965661268155,-0.024130027410642185
258.00000000000296,80.06348775774998,0.10521029391789222,-0.023445287502928736
259.00000000000296,80.38282104410924,0.10252371626961038,-0.024449180191139952
260.00000000000296,80.70861052952375,0.09703778156682097,-0.025120083207812005
261.000000000003,81.03641148270775,0.09819414536767007,-0.02479001423916971
262.000000000003,81.3596950962096,0.09514496084679652,-0.025109798116714543
263.000000000003,81.68709717233503,0.09542489363434306,-0.02543998400000058
264.00000000000307,82.00680109759907,0.09696324100132195,-0.026751418889242817
265.00000000000307,82.3407529736193,0.0961095762827473,-0.02674680772582194
266.00000000000307,82.66839985778502,0.09660275039680216,-0.026749849287992955
267.00000000000307,82.99067388146477,0.09498807306477214,-0.02740177025488144
268.00000000000307,83.3159966961055,0.0979027325739983,-0.027410084
269.0000000000031,83.64009336619146,0.09585096932300276,-0.026099333706504968
270.0000000000031,83.98696338421972,0.09650519360167187,-0.02748237468540804
271.0000000000031,84.2943072420613,0.09301745066435459,-0.02742002585401293
272.0000000000032,84.61899568509277,0.09303849811718631,-0.027795831592809073
273.0000000000032,84.94455179403687,0.09684226867143583,-0.026723773928827743
274.0000000000032,85.27095188592398,0.09522599861453612,-0.027743065931509214
275.0000000000032,85.59910663645404,0.09211116419308368,-0.027740126006458254
276.0000000000032,85.92488655711877,0.09187034978435296,-0.027740076092884536
277.00000000000324,86.25160390695738,0.09432939385094714,-0.029050195839938286
278.00000000000324,86.58071935401183,0.0926565071149433,-0.028399572153704256
279.00000000000324,86.9108751663251,0.09357876950873585,-0.029290291046641936
280.0000000000033,87.23496610828524,0.0945579609441562,-0.030789902704460914
281.0000000000033,87.55922583251144,0.09199041719783885,-0.02972017599999832
282.0000000000033,87.8857614339311,0.09286288919892352,-0.03005007528771042
283.0000000000033,88.21167227976437,0.09315884662552176,-0.029390118455633107
284.0000000000033,88.53627599229075,0.09150350235758148,-0.02939072777618179
285.00000000000335,88.86208808602701,0.09127296722344225,-0.029390117999970045
286.00000000000335,89.18959330488173,0.0924577682352463,-0.02939168879151577
287.00000000000335,89.51635099078614,0.0909517682106337,-0.030699931915805667
288.0000000000034,89.8472563038287,0.09037459783631546,-0.03103000454702176
289.0000000000034,90.17000000000132,0.0914932260303776,-0.03216835050406042
290.0000000000034,90.49946181292643,0.09206727486759117,-0.031030101999999893
291.0000000000034,90.82511728684,0.08942087873543396,-0.031690101115196434
292.0000000000034,91.15313875251442,0.0917641139058253,-0.03168956117167765
293.00000000000347,91.47589246438736,0.09107865690902783,-0.03169985232790262
294.00000000000347,91.80096887569904,0.09279786680739818,-0.0316997525213254
295.00000000000347,92.12508497794975,0.09342585778016137,-0.03268014400000485
296.0000000000035,92.45038734134486,0.09438832231428865,-0.03301008590962118
297.0000000000035,92.77954832527602,0.09262172338158203,-0.03301007168659886
298.0000000000035,93.10762647307057,0.09159658988868391,-0.03333729651146866
299.0000000000035,93.43523894484511,0.08901410179897166,-0.03498996767324103
300.0000000000035,93.76108827842555,0.08773573930669593,-0.036543439311885084
301.0000000000036,94.0877061351429,0.08814732768229161,-0.03465954690331907
302.0000000000036,94.41194292138069,0.08967506298094705,-0.035972503196492145
303.0000000000036,94.73757469309385,0.09035045530580932,-0.03662983797990327
304.00000000000364,95.07000000000119,0.08930254639384808,-0.036299895999999165
305.00000000000364,95.39593303201411,0.08814194678939453,-0.037620155765300645
306.00000000000364,95.72416161746365,0.09035495030371661,-0.03729085548113176
307.00000000000364,96.05216993511038,0.08802477344117285,-0.03727790602633796
308.00000000000364,96.3749206782737,0.08730172140719084,-0.03881584019869733
309.0000000000037,96.70245488043886,0.08695774930354566,-0.038912959296951044
310.0000000000037,97.02567443202916,0.08799663928542947,-0.03925092767981653
311.0000000000037,97.35486591514768,0.08947618088463243,-0.03795683736732025
312.00000000000375,97.68308830486838,0.08757141828638036,-0.04057981414520384
313.00000000000375,98.00925123839718,0.08737919611645117,-0.039570859507610745
314.00000000000375,98.33500357095464,0.09008979875669033,-0.041229971996337156
315.00000000000375,98.6646628528729,0.08642731676016714,-0.04359585523681542
316.00000000000375,98.98747616512082,0.08740855953990116,-0.04222266578599143
317.0000000000038,99.32251560800803,0.0868451634419912,-0.044859920453312
318.0000000000038,99.6444054511954,0.08327367376435342,-0.044722458544887544
319.0000000000038,99.97063084844774,0.08431237018640521,-0.04588365346902323
320.00000000000387,100.29982470221893,0.08128473738026307,-0.045502654756528926
321.00000000000387,100.62596545752803,0.08316827052866364,-0.04715004973851267
322.00000000000387,100.95509265948701,0.08233001051716873,-0.04849433154376204
323.00000000000387,101.281533155339,0.08309294656555774,-0.048149873999998594
324.00000000000387,101.61000000000138,0.08292967659181347,-0.04914009799999608
325.0000000000039,101.93954053226912,0.08274150552610027,-0.05044894354925322
326.0000000000039,102.26714661844598,0.08341315378561676,-0.05210002399994895
327.0000000000039,102.58930833236383,0.08491313688169352,-0.052427432061358914
328.000000000004,102.91927794298944,0.08532293942587198,-0.05468692852995538
329.000000000004,103.24436388332104,0.08324350531747235,-0.05605083725289095
330.000000000004,103.57443006612453,0.0821676680195152,-0.05862089554022232
331.000000000004,103.90543624997973,0.0849023382024762,-0.059034996208087165
332.000000000004,104.22926120474509,0.0867174349738563,-0.05933988113045796
333.00000000000404,104.55771884823557,0.08638392226677803,-0.0629516163768642
334.00000000000404,104.88044311673042,0.08528805731683936,-0.06464272033136043
335.00000000000404,105.20866873171533,0.08894298006283392,-0.06590983539205597
336.0000000000041,105.53900808057587,0.08511153090402669,-0.06723093380124245
337.0000000000041,105.86326078554521,0.08705967819272822,-0.06987009938538424
338.0000000000041,106.19429389659226,0.08694144731315913,-0.07117998299194106
339.0000000000041,106.51787918068676,0.08779783324495108,-0.07316034028195517
340.0000000000041,106.84842557804025,0.08892362058461076,-0.07612279570244951
341.00000000000415,107.17871387955604,0.08712668585313331,-0.07877237145258853
342.00000000000415,107.50735613383243,0.08811748037745273,-0.08203984987671964
343.00000000000415,107.83463415203792,0.08563473903017801,-0.08207270556782342
344.0000000000042,108.16227283673825,0.08719683839883531,-0.08556664737484132
345.0000000000042,108.4906143600684,0.0875769604228073,-0.08925669340417475
346.0000000000042,108.820348620254,0.08617802985971035,-0.09125204585331614
347.0000000000042,109.14955844399258,0.08649428622344964,-0.0951926397121059
348.0000000000042,109.47444555933095,0.0881093822422855,-0.09914928023917513
349.00000000000426,109.79829678245063,0.08618440800877496,-0.10300294391227371
350.00000000000426,110.13220831306779,0.08625839912689462,-0.10575561861465754
351.00000000000426,110.45795674279393,0.08553092787151594,-0.11066430533169669
352.0000000000043,110.78927176226944,0.08112110310900542,-0.11394989529939448
353.0000000000043,111.11910086992542,0.08405532166007779,-0.11790739981182474
354.0000000000043,111.44392170952163,0.08157342793676275,-0.12361336890943475
355.0000000000043,111.77724729307302,0.08047267989630913,-0.12712014837229768
356.0000000000043,112.10490175714548,0.08249981528556571,-0.13238250102130733
357.0000000000044,112.43446692964038,0.08362534955168077,-0.13631043620495342
358.0000000000044,112.76260043240305,0.08276837501827611,-0.1415992225625593
359.0000000000044,113.08967312770355,0.08085984482292577,-0.1468692664123541
360.00000000000443,113.42075837619183,0.08070198737847492,-0.15285163855969408
361.00000000000443,113.7486805804367,0.08481863735209569,-0.15869987583137224
362.00000000000443,114.0753297168053,0.08605551393006262,-0.16427758582574414
363.00000000000443,114.40237665756035,0.0836512091867182,-0.16968087008276678
364.00000000000443,114.72779766549633,0.08379491487335759,-0.1765279144303662
365.0000000000045,115.05559881125915,0.08462285742386284,-0.18492480938211653
366.0000000000045,115.3833278899038,0.08591098660994714,-0.19203908254155655
367.0000000000045,115.71323881222631,0.08381770470316506,-0.19857977047420006
368.00000000000455,116.04027412894094,0.08774682727257009,-0.2058891951032984
369.00000000000455,116.36693245656672,0.0856106886254374,-0.21487587156199073
370.00000000000455,116.6991012166796,0.08690969538850879,-0.22404431014707216
371.00000000000455,117.03234106158773,0.08754661237016267,-0.23160044906730848
372.00000000000455,117.35840734169105,0.08515790659634223,-0.24139332240392575
373.0000000000046,117.69000000000301,0.0876585398861542,-0.2527100180000259
374.0000000000046,118.0241214649107,0.08490941008599955,-0.26238680267683545
375.0000000000046,118.35292558775915,0.08824531410114658,-0.2717720038386222
376.00000000000466,118.67900432834125,0.08841560839448234,-0.28150194033629816
377.00000000000466,119.0084730182559,0.08780888346074625,-0.2942594447244713
378.00000000000466,119.34000000000171,0.0913952641295789,-0.3053601780000088
379.00000000000466,119.66543694539905,0.09107457085197743,-0.31740146830215643
380.00000000000466,119.99933699752481,0.09323804797204759,-0.3300476370684402
381.0000000000047,120.32585516520943,0.09692674261298836,-0.34449083569447136
382.0000000000047,120.65658617450237,0.0971090516316691,-0.35592674678818303
383.0000000000047,120.98743152314528,0.09819194697733276,-0.3707430249058694
384.0000000000048,121.31427257118165,0.10181628216455735,-0.3861366589567954
385.0000000000048,121.63435375020606,0.10416266703731111,-0.40187603738448185
386.0000000000048,121.969711304145,0.10538865720774049,-0.4188843175435846
387.0000000000048,122.29455061518574,0.10690941714565796,-0.4339944048515929
388.0000000000048,122.6279312494293,0.1069193241740595,-0.453128986269014
389.00000000000483,122.96000000000198,0.11231583967557074,-0.4701918191190706
390.00000000000483,123.29199461200213,0.11400532947098024,-0.48938007405743766
391.00000000000483,123.62161941654591,0.11928744018887352,-0.5085691065833755
392.0000000000049,123.9497048054487,0.11814255184209721,-0.5297758966718336
393.0000000000049,124.24273155683258,0.11645765007543196,-0.5530365033785176
394.0000000000049,124.61312290477711,0.12532984177214587,-0.5742295977314424
395.0000000000049,124.94259905841572,0.12862495731822396,-0.5977612995167494
396.0000000000049,125.27123415895034,0.13249487776930063,-0.6222265595044587
397.00000000000495,125.60035698048225,0.1356977610561694,-0.647504287776131
398.00000000000495,125.92854123000166,0.13452894133682006,-0.6735036009922912
399.00000000000495,126.26099214115341,0.1345309105241967,-0.7012159933775424
400.000000000005,126.59358611046979,0.13662665029775092,-0.7292560979491789
401.000000000005,126.92183625911699,0.1383849223514179,-0.7573221462441473
402.000000000005,127.25261146730193,0.13761898567511824,-0.7867140408661699
403.000000000005,127.58309398078526,0.14220305034739522,-0.8161667661759213
404.000000000005,127.91279200583973,0.1465763284808895,-0.8468025127948238
405.00000000000506,128.240356950882,0.1461252996913925,-0.8791608370861699
406.00000000000506,128.5732184031866,0.14823349878182113,-0.9110923267546771
407.00000000000506,128.9065052575697,0.15004163589789837,-0.9459807994794458
408.0000000000051,129.24000000000154,0.15188963402067368,-0.980713502307768
409.0000000000051,129.56650054060535,0.1484987149830904,-1.0143522218552175
410.0000000000051,129.90303740229191,0.15089981158080992,-1.0508592432650024
411.0000000000051,130.2319931212593,0.1560251757235408,-1.087083734706252
412.0000000000051,130.5638337899863,0.1539911606385711,-1.1249733653923015
413.0000000000052,130.88863228462833,0.15639793466563945,-1.1621460185289894
414.0000000000052,131.21717862979906,0.15398407675528586,-1.198722010111816
415.0000000000052,131.54695497383904,0.1501733096450303,-1.2376505057454592
416.00000000000523,131.88162055382156,0.15022859410784778,-1.2745190658876728
417.00000000000523,132.21373684918237,0.1451265996097151,-1.3118424611218815
418.00000000000523,132.54321891224208,0.13910369971607994,-1.3485091867776937
419.00000000000523,132.8750438220622,0.13394174038066922,-1.383427046508829
420.00000000000523,133.2085213543444,0.13198425633079647,-1.4170738277466626
421.0000000000053,133.54044876357509,0.13163141880180848,-1.4482440056385255
422.0000000000053,133.86649303149625,0.12271825637975245,-1.475843302082033
423.0000000000053,134.19844149249514,0.11760135655349072,-1.5026141749976478
424.00000000000534,134.5280398271094,0.11293327688271862,-1.525043287489575
425.00000000000534,134.85674945584591,0.10884536784482868,-1.5458375529417752
426.00000000000534,135.19124491142122,0.09996114608812262,-1.5659144399456921
427.00000000000534,135.52614264491274,0.0910747669698454,-1.584707478549844
428.00000000000534,135.85464177313256,0.08930133760868791,-1.6008134876107074
429.0000000000054,136.18416139047773,0.07896826743802976,-1.6176790196981483
430.0000000000054,136.51389527116697,0.07510077965476819,-1.629569878409459
431.0000000000054,136.84321463558175,0.07002499917099408,-1.6441174605751327
432.00000000000546,137.17699786715923,0.06351202928854627,-1.6573457265513145
433.00000000000546,137.50872724389893,0.06498017290551483,-1.6721608596490194
434.00000000000546,137.83382728069802,0.06228451417712172,-1.6852450748598424
435.00000000000546,138.1679538332803,0.05853817853698384,-1.698237599002968
436.00000000000546,138.49832807441317,0.05474746636937766,-1.7095815234363063
437.0000000000055,138.82567259403186,0.049984829238289286,-1.7211720133632222
438.0000000000055,139.1575566238632,0.05204954458955019,-1.7346218060040743
439.0000000000055,139.48674620686967,0.04539928321822634,-1.746639220225307
440.00000000000557,139.81687954998114,0.04424623129483907,-1.7601077531468934
441.00000000000557,140.15028630055747,0.04696874471794826,-1.7717497529521524
442.00000000000557,140.48111855113038,0.042439415666394364,-1.7852286130637744
443.00000000000557,140.8082329493455,0.04288574801098094,-1.797666571021928
444.00000000000557,141.1361723632909,0.039402833767893275,-1.808862765738239
445.0000000000056,141.46575374935102,0.03801244944473814,-1.822054990051115
446.0000000000056,141.79982896711527,0.03582904774197404,-1.834282539681804
447.0000000000056,142.1334813687885,0.027944026570899838,-1.8430664645277823
448.0000000000057,142.4644457276514,0.026097977875074285,-1.8525882575907033
449.0000000000057,142.7977037004616,0.020955585970335533,-1.8623859547213253
450.0000000000057,143.12761406533812,0.01699552311424496,-1.870469465707091
451.0000000000057,143.46455274386625,0.00985693253293557,-1.877988437715961
452.0000000000057,143.79656673955273,0.0007776246366580919,-1.8863236564083272
453.00000000000574,144.12618647471885,-0.008634250701598511,-1.89232057656475
454.00000000000574,144.45962716228885,-0.01581994762639588,-1.898650101032993
455.00000000000574,144.79129529406757,-0.02078805608348344,-1.9015567448926443
456.0000000000058,145.12605456836374,-0.02618957178355269,-1.9061052399271126
457.0000000000058,145.4500000000031,-0.03440679773204597,-1.9100598180000046
458.0000000000058,145.78334546177965,-0.03688156172877427,-1.9129594615792285
459.0000000000058,146.10913071507397,-0.031661107319499615,-1.9146801925640977
460.0000000000058,146.4418902980929,-0.023594487469830616,-1.9177647867980725
461.00000000000585,146.77567047057593,-0.015493119568165958,-1.9186242915055907
462.00000000000585,147.104724603787,-0.014104984464040793,-1.9196136471772691
463.00000000000585,147.43537665236906,-0.012774227240010538,-1.9204448972100643
464.0000000000059,147.77075227302987,-0.014162842485891225,-1.923889925304616
465.0000000000059,148.09884520694203,-0.016254551804963657,-1.925242312944329
466.0000000000059,148.430000000002,-0.02522993416449082,-1.9278774899024045
467.0000000000059,148.7619141990447,-0.03123612769253037,-1.9281599879904645
468.0000000000059,149.09448333262912,-0.04182226922347365,-1.9307860652648996
469.00000000000597,149.4284554081554,-0.04686669524606024,-1.9307998914985531
470.00000000000597,149.75829693220606,-0.051252761546170034,-1.9327700136724553
471.00000000000597,150.0928245093179,-0.05437343119717197,-1.9337517225076728
472.000000000006,150.42619011610844,-0.056018386021148,-1.9334297759416685
473.000000000006,150.75767433643472,-0.054224529804649535,-1.934750171131964
474.000000000006,151.0876620269844,-0.0565181756470341,-1.9373801655744547
475.000000000006,151.40811332403098,-0.05609611912509199,-1.9383594865734386
476.000000000006,151.75303956104682,-0.059945007573397824,-1.9400102257532477
477.0000000000061,152.0854971053365,-0.05795963736924309,-1.9389925197583895
478.0000000000061,152.41704585580953,-0.0614659812097576,-1.9418012737535815
479.0000000000061,152.75488449959946,-0.0631986898135003,-1.9421890387284204
480.00000000000614,153.0829606885699,-0.06640344064176984,-1.943579130997318
481.00000000000614,153.41516161915553,-0.06384658335198867,-1.9442903490166037
482.00000000000614,153.74826463670377,-0.06376650871713524,-1.9433006495153027
483.00000000000614,154.08207894647305,-0.06498043284829896,-1.9459399500771406
484.00000000000614,154.41142980742333,-0.06862910767285951,-1.9469301693260106
485.0000000000062,154.74647147376155,-0.06808412528274788,-1.9475799100061093
486.0000000000062,155.07819258051117,-0.07068147328196411,-1.947210065730578
487.0000000000062,155.41165296792835,-0.07476572223731459,-1.9499119342687874
488.00000000000625,155.7480942809346,-0.07027860556501708,-1.9488187408535391
489.00000000000625,156.07903638693676,-0.07274614754997827,-1.95120011721811
490.00000000000625,156.41122911517695,-0.07576864313463005,-1.9512004791509199
491.00000000000625,156.7455171220082,-0.07518578776494561,-1.9525103154235395
492.00000000000625,157.07462040922545,-0.07444865132835976,-1.9528297348045918
493.0000000000063,157.4103977931857,-0.07622717469065876,-1.9538299712128957
494.0000000000063,157.746620073318,-0.07732603511053981,-1.9538302417103037
495.0000000000063,158.08030440531934,-0.07896494705919604,-1.955968698388447
496.00000000000637,158.4151897408722,-0.07654489214899507,-1.9571201779999994
497.00000000000637,158.7481460876593,-0.08003470066187163,-1.958810512822037
498.00000000000637,159.0829711907069,-0.07788284339830404,-1.960087979638136
499.00000000000637,159.41700438457661,-0.07762259056680187,-1.9600850100215088
500.00000000000637,159.7487163708584,-0.07895297457390332,-1.9614007766702706
501.0000000000064,160.07966432560772,-0.08011927583204681,-1.962710180647543
502.0000000000064,160.41436420371812,-0.07968751905618338,-1.9640300255526144
503.0000000000064,160.7450093450177,-0.08087907094773256,-1.965347924423968
504.0000000000065,161.08032171913686,-0.08147295696119106,-1.9656800073382374
505.0000000000065,161.41368435311117,-0.07728343439651136,-1.9666698319983191
506.0000000000065,161.73578096009868,-0.07591215726914885,-1.9683197558382686
507.0000000000065,162.07838583357366,-0.07710700333592535,-1.9693001560820487
508.0000000000065,162.4146423317318,-0.07649448782322144,-1.9706199246590508
509.00000000000654,162.7461178567111,-0.08041398488546231,-1.9732499511832629
510.00000000000654,163.07846975097772,-0.07248009261792715,-1.9729198742289982
511.00000000000654,163.41476713880496,-0.07175167556123041,-1.973915323484317
512.0000000000066,163.74658036156916,-0.06665740156501199,-1.9752198340994878
513.0000000000066,164.08286120974407,-0.06625949084418659,-1.9754918940340285
514.0000000000066,164.4161842510975,-0.06307860918179797,-1.9774800741621306
515.0000000000066,164.75485900797722,-0.06280394062688766,-1.9785099834766466
516.0000000000066,165.08396203043029,-0.06297078560340763,-1.9798306462624433
517.0000000000066,165.41727987638507,-0.057281660650132404,-1.9828568231962935
518.0000000000066,165.75350197096415,-0.05349707628887246,-1.9834499016340357
519.0000000000066,166.08794868324676,-0.051625623085154726,-1.986079729240985
520.0000000000067,166.42165116456658,-0.046449099733062216,-1.9860798859893354
521.0000000000067,166.7555233177136,-0.043836655439443595,-1.9873907926320244
522.0000000000067,167.08764185348693,-0.05006478254000368,-1.9900308143090997
523.0000000000067,167.42831920757192,-0.04545937233809372,-1.990483916712909
524.0000000000067,167.75767562376558,-0.04449311130011768,-1.991350018251344
525.0000000000068,168.08870375844634,-0.04436844002798923,-1.9952899724844153
526.0000000000068,168.42417289047845,-0.04940100608416753,-1.9952675990236934
527.0000000000068,168.761838713895,-0.05114848737956812,-1.999462554735463
528.0000000000068,169.09699861153564,-0.05176625976154536,-1.9994601368913205
529.0000000000068,169.42971832976235,-0.05074088169484292,-1.9993565199572567
530.0000000000068,169.76626802068637,-0.05083715507343234,-2.0033031797888885
531.0000000000068,170.094672276573,-0.05060580204576093,-2.0059302463618067
532.0000000000068,170.42637350464247,-0.0540836297644407,-2.0072495898771177
533.0000000000068,170.76318794205767,-0.054379958053870525,-2.012522713907485
534.0000000000068,171.0956582427252,-0.05728804561008627,-2.012033530833457
535.0000000000068,171.42963192262476,-0.05783441189081562,-2.0157998181882277
536.0000000000069,171.768486286925,-0.06006312363475286,-2.0187728052748666
537.0000000000069,172.10048138996987,-0.05835970864156137,-2.021074694335299
538.0000000000069,172.4381553745548,-0.05937879311927641,-2.024523158554044
539.0000000000069,172.7722661988544,-0.05923550902466446,-2.027708459038786
540.0000000000069,173.10851724039458,-0.05863999204696746,-2.0317098771107664
541.000000000007,173.4459614950889,-0.06064575756779511,-2.0330198520204448
542.000000000007,173.77798073359583,-0.061412967250205175,-2.0373065192140545
543.000000000007,174.1155855441526,-0.06024953457821558,-2.040662136543287
544.000000000007,174.4477870180119,-0.05455271059626199,-2.0445401908526937
545.000000000007,174.77965992149734,-0.05645349987581061,-2.0488200192670782
546.000000000007,175.11571880363422,-0.04795460052057021,-2.052877384775531
547.000000000007,175.44935407507518,-0.047337645088608715,-2.058506646055323
548.000000000007,175.77400057957811,-0.04725458904187019,-2.063450246920207
549.000000000007,176.12000000000262,-0.05083141356176102,-2.070000189166621
550.000000000007,176.45344987928357,-0.04770839740617927,-2.075253063133371
551.000000000007,176.79119419401272,-0.048945846460353715,-2.080839030098883
552.0000000000072,177.13437236904886,-0.04972476960266481,-2.089345574328317
553.0000000000072,177.4632126891599,-0.0503356808597738,-2.0966448786987186
554.0000000000072,177.80433088810628,-0.049717337779725757,-2.1014702051060725
555.0000000000072,178.14156648745856,-0.047806213598137304,-2.111652705071953
556.0000000000072,178.47486948359534,-0.04785645663678195,-2.11692794825293
557.0000000000073,178.80751725675034,-0.048059608904293394,-2.124952632174351
558.0000000000073,179.13628816322006,-0.051737874819876684,-2.131694412578506
559.0000000000073,179.46907178383833,-0.051721177045058186,-2.142043278088819
560.0000000000073,179.80349999243464,-0.05592133252468301,-2.1501063461794874
561.0000000000073,180.14201868897868,-0.056120023399046315,-2.1567720915249504
562.0000000000073,180.47814538219228,-0.05857696308623972,-2.1646440395623756
563.0000000000073,180.80689201369455,-0.05884968980562555,-2.17408808910816
564.0000000000073,181.14470857273662,-0.060331110020407364,-2.1809040508816406
565.0000000000073,181.47808943051632,-0.057167383128301164,-2.191137654586999
566.0000000000073,181.81692720121288,-0.060683702838955855,-2.199037406018487
567.0000000000074,182.150642382158,-0.05816097977298629,-2.2076140647854645
568.0000000000074,182.48199561709836,-0.06356850710649586,-2.2166857917138953
569.0000000000074,182.81649767283704,-0.06373989514346856,-2.2250866068356085
570.0000000000074,183.15653749225447,-0.06458891790772003,-2.2341170610630243
571.0000000000074,183.48960161835964,-0.0667748948550061,-2.242858990315077
572.0000000000074,183.82345252533804,-0.06557880666003035,-2.249685559064464
573.0000000000074,184.1596106228586,-0.06535291715415414,-2.257710967434012
574.0000000000075,184.49523388168834,-0.07276704007482482,-2.2649580542511125
575.0000000000075,184.82835670030053,-0.07636871990045713,-2.272894295105256
576.0000000000075,185.16233364918548,-0.0786264252266663,-2.2808951219230007
577.0000000000075,185.50251077829887,-0.08693228994360114,-2.2861886427999183
578.0000000000075,185.83611021319493,-0.09153116711238662,-2.2887824558085157
579.0000000000075,186.17076673740598,-0.08876034195107418,-2.2930898519476037
580.0000000000075,186.50173864694858,-0.07819701888137864,-2.2957289229859508
581.0000000000075,186.8379208903267,-0.06486625829936465,-2.2955435444056285
582.0000000000075,187.17142479702332,-0.0611891663212083,-2.298030158403886
583.0000000000076,187.52726720016415,-0.0527498053659079,-2.2993496979881085
584.0000000000076,187.84380210268256,-0.05250809114081212,-2.3000112433756397
585.0000000000076,188.1721762256497,-0.04933783447274931,-2.3000000748698
586.0000000000076,188.51525371213128,-0.05009141729839539,-2.302630054888767
587.0000000000076,188.85316520407557,-0.053954873687974025,-2.303625073054742
588.0000000000076,189.19134828080917,-0.05871651146820733,-2.306250008326094
589.0000000000076,189.52917698704442,-0.061212542503594536,-2.3120304575897452
590.0000000000077,189.86737167164443,-0.06213062777926881,-2.3061229165040906
591.0000000000077,190.20171221428578,-0.06026459716400234,-2.309096683375146
592.0000000000077,190.52910563220743,-0.06301226915044478,-2.3107594189668133
593.0000000000077,190.86246585823756,-0.06329043991869554,-2.3133958181627667
594.0000000000077,191.19610869733586,-0.06266455393285408,-2.318654632319343
595.0000000000077,191.52191599256864,-0.06790206964774015,-2.312047148980197
596.0000000000077,191.8564383335244,-0.06900345717123224,-2.3109237318715605
597.0000000000077,192.19054041747967,-0.06608515932901993,-2.3185397970268875
598.0000000000077,192.52342884849293,-0.06821737473930123,-2.3215225173991505
599.0000000000078,192.86255659564299,-0.06929456529085432,-2.324207380289601
600.0000000000078,193.19681076886053,-0.07078775934056747,-2.3251169154871025
601.0000000000078,193.53568152044784,-0.07245623721122385,-2.327208865845406
602.0000000000078,193.87627069350185,-0.07627174076358778,-2.3294999684478643
603.0000000000078,194.21374896045953,-0.07338873274936397,-2.3311733941346175
604.0000000000078,194.55489658060964,-0.07240144899227219,-2.333163208749129
605.0000000000078,194.8951522879411,-0.0702497673456125,-2.336077714666545
606.000000000008,195.2329757103687,-0.06812977640054607,-2.3374097334050754
607.000000000008,195.53032522586324,-0.06514083839760598,-2.3406942366823134
608.000000000008,195.89950152999123,-0.06727646157207812,-2.3430142800923193
609.000000000008,196.23627801404794,-0.06272778506381971,-2.3456300020307426
610.000000000008,196.5713854794336,-0.061658252059039964,-2.348267587017016
611.000000000008,196.908204566053,-0.06402309019244601,-2.350865699160627
612.000000000008,197.2446517796143,-0.05939825286656797,-2.352542938397103
613.000000000008,197.58636034285428,-0.05487432760757882,-2.3564802015666126
614.000000000008,197.92505016577337,-0.049471281928116784,-2.359097901605881
615.0000000000081,198.26343087098522,-0.04263003237013552,-2.362534017324922
616.0000000000081,198.59764258459938,-0.03801041112730097,-2.3657016971429234
617.0000000000081,198.93296430754722,-0.03320866400092548,-2.3665530561407024
618.0000000000081,199.27061669852284,-0.02795826069318097,-2.3710300899530523
619.0000000000081,199.60281373164253,-0.020656372956992408,-2.373929955590352
620.0000000000081,199.9391208827542,-0.012181873382979047,-2.3785400293437227
621.0000000000081,200.27651013449832,-0.0037894019617155106,-2.381889234278412
622.0000000000082,200.61481105599418,0.0013258477765354382,-2.385077069835808
623.0000000000082,200.94906745177747,0.008604945738928116,-2.38772260865864
624.0000000000082,201.28619783107382,0.014091360739407532,-2.3930329204677685
625.0000000000082,201.6269441223338,0.02064009765720609,-2.396961624931249
626.0000000000082,201.9628518884466,0.028362703504625886,-2.4009189239930215
627.0000000000082,202.30000000000354,0.03385764306412575,-2.4061714402992402
628.0000000000082,202.63653554839976,0.043903343183868904,-2.410832016739877
629.0000000000082,202.9719340090548,0.04800820373973158,-2.4173559666643225
630.0000000000082,203.3075725904476,0.05659904358768353,-2.421233430742922
631.0000000000083,203.65000000000424,0.06619080815640244,-2.4259298200000123
632.0000000000083,204.04370640228632,0.08327418790869423,-2.431291003079947
633.0000000000083,204.31918144026878,0.0833662748667161,-2.4352396378826655
634.0000000000083,204.6549446180777,0.0950251344345534,-2.4418301375302667
635.0000000000083,204.99228241738336,0.10143674420824245,-2.448572008022548
636.0000000000083,205.32821080826852,0.10988387908045416,-2.4542916987921384
637.0000000000083,205.66485646468172,0.11975042826486204,-2.460456066793217
638.0000000000084,206.0029817821408,0.12889190720085897,-2.4667496582859147
639.0000000000084,206.33857083778895,0.13476681846063343,-2.4724315872760374
640.0000000000084,206.6819003290478,0.14729224556597975,-2.4786701083658835
641.0000000000084,207.0204188838144,0.15226577517461748,-2.4866898485197506
642.0000000000084,207.36000000000433,0.16238291901218616,-2.493270152000005
643.0000000000084,207.69576486222408,0.17175779206916486,-2.500330430045876
644.0000000000084,208.03322119054866,0.18085981412765206,-2.5080946213322304
645.0000000000084,208.36797474205335,0.18729362099808822,-2.514686628704753
646.0000000000084,208.70742710918591,0.2001460683570011,-2.5213539454134635
647.0000000000085,209.0432936528024,0.20955686938393736,-2.5305539823850793
648.0000000000085,209.38086428047828,0.21516178862105995,-2.5390747747623252
649.0000000000085,209.71542978497823,0.22011374499502345,-2.5466437678015295