File: 01_Data/Concrete_Block/STA/N2/30K_min/Concrete_Block_STA_N2_30KData_230830_R3.csv
##Temp./Â°C,Time/min,DSC/(mW/mg),Mass loss/mg
28.0,10.277811153643906,-0.0051713588905331065,-0.015198851278045211
29.40000000000002,10.715641403981255,0.06063713865603226,-0.014832411303431492
30.80000000000004,10.880022514474042,0.10876014171660664,-0.013479755084072842
32.20000000000006,11.000575060455416,0.15078424141741054,-0.013917258330502058
33.60000000000008,11.101626933300498,0.18443646381283796,-0.013049620499979042
35.0000000000001,11.18928423760498,0.21676320068332533,-0.013690823521960382
36.40000000000012,11.270023539187383,0.24596251914696365,-0.01394399194671525
37.80000000000014,11.34391192983698,0.27167137485741555,-0.013826005170760602
39.20000000000016,11.415236808120637,0.29658405435755997,-0.014596537855394942
40.60000000000018,11.48225975409061,0.3183785351207642,-0.013794630479107006
42.0000000000002,11.546205798130098,0.3387611362178282,-0.01395355222004735
43.40000000000022,11.60865618024501,0.35987090689201207,-0.012158520018958008
44.80000000000024,11.66900610399253,0.373073660324603,-0.013119726597904169
46.20000000000026,11.728003360407978,0.3917955066325558,-0.015989727623358263
47.60000000000028,11.784789695936283,0.4070208816883527,-0.016864689929056098
49.0000000000003,11.840998743962949,0.4243749169289026,-0.016572407017533486
50.40000000000032,11.897748668505107,0.43773641886798975,-0.01678099381847087
51.80000000000034,11.95188448340958,0.4533779699135212,-0.015119319543464904
53.20000000000036,12.006311492371646,0.4632552959945102,-0.01586058675739377
54.60000000000038,12.059670915305611,0.4763816880729468,-0.01638728532554179
56.0000000000004,12.11203045081774,0.48872665485495803,-0.01624349006979564
57.40000000000042,12.16477550153953,0.502540921636202,-0.01607408570991975
58.80000000000044,12.215704289828004,0.5145990536236031,-0.017594653718362885
60.20000000000046,12.267617284752788,0.5260252945417938,-0.01869867465788122
61.60000000000048,12.318343260064859,0.5363441857691635,-0.01936233812780941
63.0000000000005,12.368363843330696,0.5477744050490208,-0.020290793042007316
64.40000000000052,12.41920472268286,0.5551473836502621,-0.02050928095724469
65.80000000000054,12.468664162163968,0.5643361640127811,-0.020420474523021426
67.20000000000056,12.517098833246337,0.5704333679943294,-0.021809275975001263
68.60000000000058,12.567879245053696,0.5776416777231943,-0.021325433850694964
70.0000000000006,12.617358010899897,0.5815403513210864,-0.020887295331727174
71.40000000000062,12.66654313746586,0.5866007757558127,-0.021066350991198135
72.80000000000064,12.715040173023095,0.5918169621396332,-0.02201519034404864
74.20000000000066,12.764306327133294,0.5948104422987451,-0.023001419491361474
75.60000000000068,12.812299589559569,0.6020894323718552,-0.02395504181962238
77.0000000000007,12.861857925139418,0.6030864815224807,-0.02504893051071022
78.40000000000072,12.910473036387467,0.6083735364987465,-0.0238323237056699
79.80000000000074,12.95847173274318,0.6119034529413919,-0.02515401561296038
81.20000000000076,13.007376184475165,0.6149436364435787,-0.026447691441567223
82.60000000000078,13.055593852247082,0.618952639353892,-0.026448610699608466
84.0000000000008,13.103613071464752,0.6239950476369335,-0.027770619624166493
85.40000000000082,13.15140076407772,0.6278812374633808,-0.02772410715223117
86.80000000000084,13.198699400695496,0.6295437627323667,-0.027771063042673738
88.20000000000086,13.246242491699885,0.6327402148039513,-0.029005684455074565
89.60000000000088,13.29410316591189,0.6375281304173205,-0.027766547452126922
91.0000000000009,13.3403517023718,0.6391656411200207,-0.027726597823176213
92.40000000000092,13.388166431640409,0.6435504389524825,-0.02748495095876624
93.80000000000094,13.435339786954689,0.646868080521638,-0.028869286079878265
95.20000000000095,13.48216723106245,0.6486979899991557,-0.030404501916090787
96.60000000000097,13.528797188627204,0.6505233684658275,-0.03170788730517238
98.000000000001,13.57606730750839,0.6530355676889021,-0.03172034675992297
99.40000000000101,13.62221236873045,0.6557742719026496,-0.03148934161264538
100.80000000000103,13.66883542594057,0.6571891879821817,-0.03172781738585595
102.20000000000105,13.715071774008837,0.6600667430365592,-0.03173451020376028
103.60000000000107,13.761707698304738,0.6597373414061695,-0.03306257438168991
105.0000000000011,13.807593407036116,0.6645094541486606,-0.03303919709385461
106.40000000000111,13.853716021949461,0.6677645183795247,-0.0321612088779597
107.80000000000113,13.899369597769052,0.6670581688841415,-0.03204925343847709
109.20000000000115,13.945328243705791,0.6693691184865397,-0.03344997321411558
110.60000000000117,13.991954702355013,0.6736422877095217,-0.03336053698256514
112.0000000000012,14.038425781204111,0.6765897107764326,-0.033059792079772166
113.40000000000121,14.084103628929707,0.6769185132585966,-0.03335148731320725
114.80000000000123,14.130065941660972,0.6776859969079667,-0.03406688033101357
116.20000000000125,14.175590077492751,0.6801416925907219,-0.03462182096393196
117.60000000000127,14.221512439001001,0.683855148710718,-0.03602621143904283
119.0000000000013,14.267110436466657,0.6868535772427969,-0.038641111023348884
120.40000000000131,14.31172259487132,0.6882087346615532,-0.03863989804532064
121.80000000000133,14.3583911462895,0.6890099890804121,-0.038639860945853144
123.20000000000135,14.40369150462049,0.6900569518129865,-0.03783760720942109
124.60000000000137,14.449137711019974,0.692074231307058,-0.03732007728927744
126.00000000000139,14.495093454119448,0.6899911768517671,-0.03731307091651104
127.40000000000141,14.540211385382744,0.690309895355221,-0.03861682669975952
128.80000000000143,14.58490217035053,0.6894153232778046,-0.038642522663665524
130.20000000000147,14.630051062699525,0.6876972939493616,-0.04124796631579386
131.60000000000147,14.675016582707817,0.6886034989844116,-0.0412698607829558
133.00000000000148,14.719448399074512,0.6859640145311621,-0.04126990806443853
134.4000000000015,14.764433959350516,0.6846416168121038,-0.04126990827731358
135.80000000000155,14.809138614801808,0.6855423527860485,-0.04127004764056519
137.20000000000155,14.853565114017615,0.6875494954844947,-0.041676994478986096
138.60000000000156,14.898016570716024,0.6854758955011742,-0.04258819631762112
140.0000000000016,14.941743437743765,0.6854175152781696,-0.04258990687146724
141.40000000000163,14.986811443532115,0.6847255164372252,-0.04259001675320473
142.80000000000163,15.030656392267169,0.6829232025960343,-0.04261322568302184
144.20000000000164,15.074443554159876,0.6839536981795573,-0.043908826996781336
145.60000000000167,15.117721936007333,0.6823152306946061,-0.04391084509874954
147.0000000000017,15.162402153031644,0.6807103460283583,-0.04519992674206019
148.4000000000017,15.20594305421819,0.6828044197249603,-0.04523167285634422
149.80000000000172,15.2500157162069,0.6835415277217046,-0.04628716170892311
151.20000000000175,15.29293751738883,0.6836599552306286,-0.04655003940863356
152.60000000000178,15.33767443142773,0.6825951943599907,-0.0465504737362048
154.0000000000018,15.38160649633683,0.6823450423885166,-0.0463418864697438
155.4000000000018,15.42536897484781,0.6829739936092667,-0.04658406143043514
156.80000000000183,15.469079397824435,0.6825635770832326,-0.04654000895519861
158.20000000000186,15.512463664818107,0.6838917421550466,-0.04791553995519582
159.60000000000187,15.555907124644737,0.6837761249379515,-0.04786030752538917
161.00000000000188,15.599326448733771,0.6845673640667385,-0.04786012596518496
162.4000000000019,15.64280740837301,0.6817569044379233,-0.04786012599797562
163.80000000000194,15.686282385749628,0.6844210850599599,-0.04786012600240941
165.20000000000195,15.729864098720112,0.6826016636997726,-0.04786012661189343
166.60000000000196,15.773357201760318,0.6840771915947848,-0.047860031458311525
168.000000000002,15.816675149365803,0.6833274754425258,-0.04773834240247954
169.40000000000202,15.859042572744807,0.686726777723227,-0.04654717011850362
170.80000000000203,15.9033357819413,0.6825482921139991,-0.04621034832643023
172.20000000000203,15.946634138149635,0.6839864501564585,-0.0462402146296883
173.60000000000207,15.989916079230758,0.6830921267149558,-0.04584140915563051
175.0000000000021,16.032980236677705,0.6830783653847899,-0.04849507266507125
176.4000000000021,16.076323722769704,0.6860825528184126,-0.048520471298716394
177.80000000000211,16.119479341420558,0.6842981002789863,-0.04860094720270958
179.20000000000215,16.16197912877528,0.6868835412945011,-0.04719486424962227
180.60000000000218,16.204760005315705,0.6858392912463379,-0.048590759171857734
182.0000000000022,16.248522664856914,0.6858500863592685,-0.04983062985209408
183.4000000000022,16.291126332415274,0.6859702377939443,-0.049829874589471856
184.80000000000223,16.334114877526687,0.6858267378101272,-0.04982986359077035
186.20000000000226,16.37703305209688,0.68363559434304,-0.049822939553634704
187.60000000000227,16.41956622149381,0.6858223315297194,-0.051142321101869115
189.00000000000227,16.462527108124448,0.6876302295029196,-0.05114989828181482
190.4000000000023,16.505240424162594,0.6880051204958461,-0.0511478683263773
191.80000000000234,16.547408519693413,0.6869264496653801,-0.04976560630772475
193.20000000000235,16.5911379130849,0.6869687458214386,-0.04983052104228314
194.60000000000235,16.633429760924262,0.6872751486077634,-0.05021125625710443
196.0000000000024,16.67612021146083,0.6874901318425866,-0.050829496504137595
197.40000000000242,16.719018436927033,0.6898469024361144,-0.05082020622982952
198.80000000000243,16.761395671160482,0.6898640275612065,-0.05088391681255455
200.20000000000243,16.804095945602853,0.6872522594392039,-0.05114920074292506
201.60000000000247,16.846622172095497,0.6900079153952303,-0.05114986412874423
203.0000000000025,16.888476232854615,0.6901986067208185,-0.05114986400730093
204.4000000000025,16.931976046024634,0.694115679119495,-0.05114989839452644
205.8000000000025,16.974559718821812,0.6926013333078204,-0.05256244095842799
207.20000000000255,17.017563431487314,0.6935645549325516,-0.05248090966512908
208.60000000000258,17.059955017149683,0.6945288221814553,-0.05404328978816597
210.0000000000026,17.10238204571846,0.698483601692478,-0.05400877640086588
211.4000000000026,17.145064578552727,0.6975852937249607,-0.05282109901864285
212.80000000000263,17.187720719919188,0.7000815198933291,-0.051317185527519626
214.20000000000266,17.230366314364705,0.7006534178405102,-0.051397560114117447
215.60000000000267,17.272568495976717,0.7039928265811779,-0.05136973403350442
217.00000000000267,17.315313563585317,0.7035629669984157,-0.052340890555950814
218.4000000000027,17.35801034716343,0.7045033956762287,-0.053996862539824164
219.80000000000274,17.400130406382875,0.704423103207221,-0.054010134688236455
221.20000000000275,17.442795559710333,0.7073658395056327,-0.054010168532227176
222.60000000000275,17.485457521545868,0.7090400108681427,-0.05400763730962055
224.00000000000279,17.527927062178186,0.7083242387738714,-0.054348066437078124
225.40000000000282,17.5700874637229,0.7115550286728435,-0.054339836868075864
226.80000000000283,17.613175103117758,0.7118924759838751,-0.05434524492815296
228.20000000000283,17.65534496753319,0.7131635961838576,-0.053660296101000426
229.60000000000286,17.697694350388236,0.7151904161841365,-0.05367959702336211
231.0000000000029,17.740287882500056,0.7160516288136856,-0.05368000341794854
232.4000000000029,17.782613936515094,0.7169173788005535,-0.05368000599425393
233.8000000000029,17.82491426160894,0.7192496492005224,-0.053680006187883045
235.20000000000294,17.867225894453323,0.7228249874720453,-0.05367993357064993
236.60000000000298,17.908787213038387,0.722491244216114,-0.053634485061466286
238.00000000000298,17.951902604641166,0.7233478912024418,-0.054989373025834176
239.400000000003,17.994110504213896,0.7258338351783999,-0.05535195813366034
240.80000000000302,18.03664104154354,0.7251912587560501,-0.05401104991687955
242.20000000000306,18.0792309555951,0.7260378104048524,-0.05401121665371722
243.60000000000306,18.121321495995726,0.725177955408425,-0.05545841835709897
245.00000000000307,18.163422722199023,0.7253627049580859,-0.05631032141294412
246.4000000000031,18.205965327057584,0.7260376195028394,-0.056310246766607897
247.80000000000314,18.248268240226842,0.7277150071958635,-0.056227700340221176
249.20000000000314,18.290636404308117,0.7252916953153274,-0.05498654547730286
250.60000000000315,18.333020579324568,0.7289372694731668,-0.05499015721690714
252.00000000000318,18.375167427534684,0.7304183027955597,-0.05499090409225893
253.40000000000322,18.41592698471927,0.7313540544648863,-0.05523071403313029
254.80000000000322,18.458875893368834,0.7302870884827496,-0.0552903518735528
256.20000000000323,18.501151406593834,0.7331018457606224,-0.056627158870968586
257.60000000000326,18.543810879074787,0.7319217366158317,-0.05664106772569877
259.0000000000033,18.58640847879899,0.7324772912699767,-0.05713821442185729
260.4000000000033,18.628525432977888,0.7336258946103766,-0.057299831696886905
261.8000000000033,18.670964184864598,0.7315998578551794,-0.05730120510626069
263.20000000000334,18.712896427156497,0.7334979663936445,-0.05633197146563518
264.6000000000034,18.755491284140973,0.7324543459725725,-0.05598057460976413
266.0000000000034,18.797716351563793,0.7329543823973359,-0.05594796672777402
267.4000000000034,18.839801725425485,0.7327894396945159,-0.05730056737304601
268.8000000000034,18.882053513033483,0.7333360838903542,-0.05850929930429416
270.20000000000346,18.924221711682552,0.7350501701792197,-0.05920093784858338
271.60000000000343,18.966349003494653,0.7355876666199056,-0.06005013233022005
273.00000000000347,19.00859990885701,0.7327816836065676,-0.060049524986582004
274.4000000000035,19.0509469551347,0.7344279488951364,-0.05924227543392391
275.80000000000354,19.092986141257207,0.7354849254071673,-0.058731035141714294
277.20000000000357,19.135415616583195,0.7351559098236025,-0.05875576399107363
278.60000000000355,19.17755769928618,0.736616633258546,-0.06005144641725613
280.0000000000036,19.219649034157626,0.7361421128166373,-0.05897377427574657
281.4000000000036,19.26207402607059,0.7355302812229283,-0.05849216063502016
282.8000000000036,19.30451176066522,0.7359999108353084,-0.05740970582780758
284.2000000000036,19.34670153410437,0.7369187454551659,-0.057432921702607054
285.60000000000366,19.389376313520074,0.7377024516814537,-0.05872958660315941
287.0000000000037,19.431461341432474,0.738135487059102,-0.058728292142770755
288.40000000000373,19.47345143041667,0.7369113919500584,-0.059854767241480644
289.8000000000037,19.51637600654808,0.7384498691880893,-0.06134833668776052
291.20000000000374,19.55854857224513,0.739151564842042,-0.06135998214324978
292.6000000000038,19.600962332853037,0.7379127406671208,-0.06135999608610376
294.00000000000375,19.643116661044722,0.738985992341932,-0.06135999548885884
295.4000000000038,19.685928493672883,0.738590365327275,-0.06135987736667037
296.8000000000038,19.728001641677942,0.7399447252462974,-0.06134640093040833
298.20000000000385,19.770648740109003,0.7401095718406385,-0.06005149693824574
299.6000000000039,19.812836181778817,0.7420467782611178,-0.060049832927731916
301.00000000000387,19.85531251565984,0.7406281258101538,-0.06004609236985914
302.4000000000039,19.897817313474455,0.7415257564842216,-0.061311031111676684
303.80000000000393,19.94018283494655,0.7420670966765014,-0.06135961169354687
305.2000000000039,19.982582769490005,0.7421118045824265,-0.060036758662026735
306.60000000000394,20.0250509142091,0.7408216829185439,-0.05905293412466772
308.000000000004,20.067989786232566,0.7414261717702111,-0.06004127926953684
309.400000000004,20.110456287071784,0.7420171042199302,-0.060048751542407075
310.80000000000405,20.152004978381083,0.7426903081641071,-0.061053093202181774
312.200000000004,20.194679560333526,0.7431498351698385,-0.06103965707793613
313.60000000000406,20.23721879838838,0.743364745847211,-0.060999373260104406
315.0000000000041,20.28008042435247,0.7425037763646396,-0.06235184498575297
316.40000000000407,20.322706469740215,0.7413504425732093,-0.06234998358681931
317.8000000000041,20.364920778329726,0.740448558725777,-0.06234097075826561
319.20000000000414,20.40734056045572,0.7410624165511415,-0.06366117697443885
320.6000000000042,20.450016959562284,0.7399985264277564,-0.06366250260221573
322.0000000000042,20.492744163100568,0.7421516074030055,-0.06497465582912243
323.4000000000042,20.535254078535893,0.7416240391123514,-0.06477958437751097
324.8000000000042,20.57783533924256,0.740235362310095,-0.06235304283726473
326.20000000000425,20.620556157710762,0.7403221286491101,-0.061712786225414984
327.60000000000423,20.66353504163834,0.7384327650606437,-0.061030743458118764
329.00000000000426,20.705971082964073,0.7383571026334071,-0.061029911333551734
330.4000000000043,20.748529338283753,0.7388095418447023,-0.06103081737334737
331.80000000000433,20.791762655199523,0.7396737953459493,-0.061710458547060476
333.20000000000437,20.834131021426906,0.7377153121003711,-0.062348963400824076
334.60000000000434,20.877046915821733,0.7383570712036998,-0.06234974819984895
336.0000000000044,20.91976598096669,0.7392603233475671,-0.062136326094405
337.4000000000044,20.962721707415234,0.7397473968273613,-0.06103078124212491
338.8000000000044,21.00530750421393,0.7415067927535987,-0.06104918046557595
340.2000000000044,21.048223104070512,0.7425139493747015,-0.06305666607834937
341.60000000000446,21.09084432981948,0.7445926181553457,-0.06377907147166839
343.0000000000045,21.134120610954902,0.7458325645088117,-0.06380663214020998
344.4000000000045,21.1770637451692,0.7461764084027706,-0.0627717395984142
345.8000000000045,21.219888381093767,0.747193107824272,-0.0614704465532987
347.20000000000454,21.262494627054632,0.7497093142003285,-0.06146990937975616
348.60000000000457,21.305242202726113,0.7503190918084988,-0.061469901987065256
350.00000000000455,21.34833506165465,0.7492627564165542,-0.061469896810901314
351.4000000000046,21.391422482082806,0.7517808110604801,-0.061471535258228904
352.8000000000046,21.434488917015177,0.7522105320241048,-0.06272866593828264
354.20000000000465,21.47767003535485,0.7534171693630805,-0.06378062710586274
355.6000000000047,21.520293792071204,0.7542667276910753,-0.06378053962641994
357.00000000000466,21.563597428841337,0.755854569362375,-0.06366782548960126
358.4000000000047,21.605871888283847,0.7569735724794708,-0.06278204077562943
359.80000000000473,21.64926532029811,0.7573868125400962,-0.06279263001089097
361.2000000000047,21.692523060488178,0.7579509459666952,-0.06411401210918344
362.60000000000474,21.735647478419438,0.7587812922015099,-0.06419068310575593
364.0000000000048,21.778833988350804,0.7600579834310017,-0.06279080503383705
365.4000000000048,21.821888547971938,0.7635116681045958,-0.06279010180764555
366.80000000000484,21.864341728760223,0.7630002413560197,-0.06346474233979338
368.2000000000048,21.90805175130585,0.7632759727345344,-0.06282907826014039
369.60000000000485,21.95118275516321,0.7645995504945946,-0.06278964042040602
371.0000000000049,21.994708086493898,0.7633264550931149,-0.06293840786593208
372.40000000000487,22.037773529878425,0.763011232536678,-0.06544650388963458
373.8000000000049,22.080864613198173,0.7623078169227335,-0.06543006384170091
375.20000000000493,22.12353739563396,0.7603431032908823,-0.06543011948392019
376.60000000000497,22.16786571242623,0.7600871801390836,-0.06543010297958407
378.000000000005,22.21087544621842,0.7605177324793986,-0.06543843969292373
379.400000000005,22.25383839736996,0.7615083791121293,-0.06674663759598376
380.800000000005,22.2974548135253,0.7600061517385105,-0.06674515650482027
382.20000000000505,22.340749431540054,0.759750293345248,-0.0654179082073525
383.600000000005,22.383974762025534,0.7598803237966274,-0.06410342411496339
385.00000000000506,22.427124176680103,0.758994860782959,-0.06410419556634972
386.4000000000051,22.470745806412406,0.7605640678719425,-0.06543577139953483
387.8000000000051,22.514261697893538,0.7597076334026535,-0.06543019239375925
389.20000000000516,22.55775199282496,0.7592967557597285,-0.06543441199888678
390.60000000000514,22.60111567189068,0.7587939628967757,-0.06410409061155553
392.0000000000052,22.644427736089778,0.7576487455338625,-0.06410977474001145
393.4000000000052,22.688225265121158,0.758364372141396,-0.064109799097253
394.8000000000052,22.731405301085587,0.7597606367396529,-0.06411593265865889
396.2000000000052,22.774647887626767,0.7589639198326839,-0.06547576839665581
397.60000000000525,22.818461575961194,0.7588158218213297,-0.06543070852405375
399.0000000000053,22.86189743081518,0.7590886445496431,-0.06671461856921024
400.4000000000053,22.905623586773395,0.760254303120001,-0.06675856696507276
401.8000000000053,22.949233456381272,0.7610992550299086,-0.06839667877072797
403.20000000000533,22.992594446718012,0.7598548080512632,-0.0690523216488983
404.60000000000537,23.03642035577833,0.7590563102950012,-0.06905019709083415
406.00000000000534,23.07995836357544,0.7605199575652061,-0.06905022708663822
407.4000000000054,23.123637601181812,0.7613403949850223,-0.06909973514447199
408.8000000000054,23.167507114786876,0.7623788918497929,-0.06773419526582414
410.20000000000545,23.21099615098593,0.7650126599054501,-0.06772975995389574
411.6000000000055,23.254762313904315,0.7662639032652211,-0.06761565476902698
413.00000000000546,23.29860857149699,0.7712386591304153,-0.06674976229152563
414.4000000000055,23.3426019184245,0.7729669706526425,-0.06674764520612442
415.8000000000055,23.386257721653678,0.7768965838866793,-0.06792780449636426
417.2000000000055,23.430218268269048,0.780420393408213,-0.06806010387316297
418.60000000000554,23.474018776441355,0.7865696664126818,-0.06805995537628906
420.00000000000557,23.517839481885893,0.7907119721277265,-0.06805995401952547
421.4000000000056,23.56193273885448,0.7960300281573037,-0.06805995313290047
422.80000000000564,23.605901094030433,0.8013975652869012,-0.06805785363737638
424.2000000000056,23.64999028483021,0.8050652707129662,-0.06840444552671565
425.60000000000565,23.693840448976815,0.8089433234246636,-0.06963994906343496
427.0000000000057,23.73763537367773,0.8094846758211167,-0.07043437913741624
428.40000000000566,23.781605534404186,0.8091444907828308,-0.07141152573441989
429.8000000000057,23.82553238070147,0.8052586305754011,-0.07134991120059908
431.20000000000573,23.86963385950776,0.7993834110654474,-0.07137122702450815
432.60000000000576,23.913543159087357,0.7929891052068717,-0.07200894606230879
434.0000000000058,23.957512807204193,0.7870403175490117,-0.0720200598305456
435.4000000000058,24.001610886468928,0.7795887989839115,-0.0733188260485953
436.8000000000058,24.045640153816265,0.7743735264393042,-0.07332043806731825
438.20000000000584,24.089817720651958,0.7676060390555567,-0.07127123851051786
439.6000000000058,24.13369741364287,0.7651947551278147,-0.07070117717751767
441.00000000000585,24.17771523307982,0.762269396267197,-0.0707001589963383
442.4000000000059,24.222034377132747,0.7591335441529624,-0.07070923788315664
443.8000000000059,24.26623527987927,0.7574637575847879,-0.07170051218328943
445.20000000000596,24.31017670146597,0.7551051278469725,-0.07168998810873317
446.60000000000593,24.354135424299884,0.756318857206008,-0.071689999953644
448.00000000000597,24.3985687433787,0.7536044985792444,-0.07169000433576933
449.400000000006,24.44286982193377,0.7532575051878748,-0.0716826381139688
450.800000000006,24.487061903484427,0.752190809682306,-0.0713996422631955
452.200000000006,24.53158877245317,0.7513996225962896,-0.0726756501480823
453.60000000000605,24.575782312061754,0.7511037013644084,-0.07131866445556678
455.0000000000061,24.619823600875986,0.7516290325712636,-0.07136264145155158
456.4000000000061,24.66458987469789,0.7501285956459212,-0.0726757869972805
457.8000000000061,24.708793486381566,0.7521836678912421,-0.07267008614913184
459.2000000000061,24.752998327570367,0.7505296590030626,-0.07267008623800253
460.60000000000616,24.797432012068608,0.7499839959468615,-0.07267175138898319
462.00000000000614,24.841549270932813,0.750625054653326,-0.0748873885194481
463.4000000000062,24.88591411252774,0.7517440924117357,-0.07529916712936569
464.8000000000062,24.93042657151747,0.7487655945285854,-0.07529999028847678
466.20000000000624,24.974891591313032,0.7493808155272796,-0.07529999001604315
467.6000000000063,25.01939654527568,0.7524646219931069,-0.0752999895794173
469.00000000000625,25.06404867346401,0.7502621129394889,-0.07529878067419249
470.4000000000063,25.10841706389774,0.7511752937856205,-0.0746935759423093
471.8000000000063,25.15287843740774,0.7505606425740952,-0.07596170308005767
473.2000000000063,25.197677863624868,0.7522676645895602,-0.07595987356637357
474.60000000000633,25.24197542496392,0.7543378017023717,-0.07593115299316233
476.00000000000637,25.286790643033473,0.7565731468513984,-0.0772736381186423
477.4000000000064,25.33125141211481,0.7580565214750228,-0.0772800145389172
478.80000000000643,25.376115822065724,0.7616899625054171,-0.07729721055606653
480.2000000000064,25.42067592241581,0.7617539337411386,-0.07594166647556255
481.60000000000645,25.4649213709952,0.7660447923696778,-0.07662354998578369
483.0000000000065,25.509673280289423,0.7714684083746228,-0.07661927914673683
484.40000000000646,25.554513045472113,0.7705547072547482,-0.07630259325942745
485.8000000000065,25.599006658659874,0.7762944719197928,-0.07696152470852935
487.2000000000065,25.64375366816856,0.7799850292339143,-0.07694456304590958
488.60000000000656,25.688551229849697,0.7820743307408601,-0.0759626325767
490.0000000000066,25.733107103377346,0.7854735843018734,-0.07599327689895219
491.40000000000657,25.778012224808542,0.7867469510378938,-0.07696228581745945
492.8000000000066,25.82270868382642,0.7889946682194013,-0.07829130202885004
494.20000000000664,25.867629791514897,0.7911260835899441,-0.07826984530428849
495.6000000000066,25.91213889097965,0.79332038438684,-0.07827907189471794
497.00000000000665,25.95731775476868,0.7943300190169748,-0.0786019300325207
498.4000000000067,26.002072484185234,0.7962597206632513,-0.0785998888880064
499.8000000000067,26.046478766418115,0.795547516209677,-0.07859987909740473
501.20000000000675,26.091370035642882,0.8011671406731954,-0.07860016184333407
502.60000000000673,26.136177876023787,0.8025525961088326,-0.07883427209090943
504.00000000000676,26.18114776574536,0.800539700322016,-0.0789176317021778
505.4000000000068,26.225940433198787,0.8025387566572075,-0.08022376793483055
506.8000000000068,26.270881562447034,0.8012578427212121,-0.07914463903748814
508.2000000000068,26.315774472803966,0.8042595182589041,-0.07893000304114306
509.60000000000684,26.360917596735884,0.8052483684888275,-0.07893634660600979
511.0000000000069,26.404729019832843,0.8077032988072678,-0.0795736416691426
512.4000000000069,26.45046760403191,0.8103862458203471,-0.0795899061641121
513.8000000000069,26.495473181979058,0.8079019778153256,-0.07959629267036394
515.2000000000069,26.540479142292362,0.8115016422096673,-0.08153418196738249
516.600000000007,26.58562338077889,0.8092413431434038,-0.08271618915397472
518.0000000000069,26.63084533813282,0.8119884179101117,-0.08288011222437541
519.4000000000069,26.675952667837095,0.8133370400099664,-0.08288006679283377
520.800000000007,26.721155316432434,0.8151208635096633,-0.08326400970448367
522.2000000000071,26.765992863012116,0.8163630882771983,-0.08354009289622866
523.6000000000071,26.811404623783133,0.8189090465224702,-0.08353974075646597
525.000000000007,26.85659572728592,0.8205959631572307,-0.08344792687276126
526.4000000000071,26.902056717229136,0.8197254473181261,-0.0835026868149491
527.8000000000071,26.9471238129394,0.8225873788310587,-0.08342488945675175
529.2000000000071,26.992508196168313,0.8216610494718002,-0.08221987499618999
530.6000000000072,27.03751627776012,0.8241383471349198,-0.08222009485268478
532.0000000000072,27.08247611529168,0.8263709852567995,-0.08221974055999048
533.4000000000071,27.127760281605113,0.8262790631837139,-0.08343819764728355
534.8000000000072,27.17281529541047,0.8267250440613528,-0.08354049628934179
536.2000000000072,27.218052607977608,0.8273629170460968,-0.0835400052095685
537.6000000000072,27.263380637631137,0.8260863515780482,-0.08353478755271881
539.0000000000073,27.308946278333845,0.8273270750869266,-0.08485889178101891
540.4000000000073,27.35431475782645,0.8313292905195956,-0.08485411043494606
541.8000000000073,27.399271612088267,0.8306209314388668,-0.08618017169176717
543.2000000000073,27.445067067390966,0.833057984238269,-0.08617820445323332
544.6000000000073,27.49032752210949,0.8350009729120752,-0.08750591495271998
546.0000000000074,27.535912335166707,0.8346823926414665,-0.08749980984852312
547.4000000000074,27.581401687592663,0.8351969193762395,-0.08749981423336095
548.8000000000075,27.62670672028664,0.8365442059629709,-0.08750072081587845
550.2000000000074,27.671410791804576,0.8369946162145308,-0.0883422828468925
551.6000000000074,27.71751127991039,0.8397669215411137,-0.08879131806683738
553.0000000000075,27.762756241112175,0.8408825072847647,-0.09033723750824096
554.4000000000075,27.80820348469927,0.8415898968381393,-0.0887864201813664
555.8000000000075,27.853695391925662,0.8407282181802582,-0.08747640277222812
557.2000000000075,27.899232744501063,0.8408597226756138,-0.08881012196230031
558.6000000000075,27.944538458073577,0.8406996191854309,-0.08880987262652207
560.0000000000075,27.99051647753975,0.8426946882590367,-0.08881594979555496
561.4000000000076,28.035891759969306,0.8438571860865421,-0.09013497783143576
562.8000000000076,28.081518727723594,0.8441299033073207,-0.0901301825759444
564.2000000000077,28.12699890169067,0.8455379540084313,-0.09012999672894617
565.6000000000076,28.173308844909123,0.8466614889853434,-0.0903312340407969
567.0000000000076,28.21891651564811,0.8483810433003438,-0.09080488837538603
568.4000000000077,28.264413802030962,0.847446446804323,-0.09168246255502277
569.8000000000077,28.310144808133096,0.846265173483593,-0.0917946221266015
571.2000000000078,28.35592109568529,0.8549084494038501,-0.09276432837127357
572.6000000000078,28.401508241112793,0.8659291150336165,-0.09413825225352479
574.0000000000077,28.446908546595182,0.8811897617482535,-0.0947361226388086
575.4000000000078,28.49283618268833,0.8689076016771817,-0.09615417896295853
576.8000000000078,28.538109570381053,0.8568684900544966,-0.09540233853046542
578.2000000000078,28.58443926764018,0.8504736128168616,-0.09605100707559044
579.6000000000079,28.6299530974255,0.8433952850613091,-0.09606022426560967
581.0000000000078,28.675713202277684,0.8349393037936618,-0.09669103466923223
582.4000000000078,28.72063740649029,0.8289367107592434,-0.09737037834205609
583.8000000000079,28.767479117268287,0.8301583967796622,-0.09788368226127941
585.2000000000079,28.813187716829507,0.8302896365350698,-0.0980367375202813
586.600000000008,28.859071426015426,0.8279397812119196,-0.09803149888592522
588.000000000008,28.904853902595633,0.8298226768339163,-0.09934822165449608
589.4000000000079,28.950589034763848,0.8294461308801369,-0.099349945861404
590.800000000008,28.996143990572214,0.8338266576104498,-0.09934425998500496
592.200000000008,29.042792118312992,0.8361355729328246,-0.10067422176586494
593.6000000000081,29.08862440648907,0.8400570485493802,-0.10147731714002095
595.0000000000081,29.134523186465707,0.8415204184019272,-0.10132053656436701
596.400000000008,29.18061131223886,0.8479718835305163,-0.10209760041685367
597.8000000000081,29.22662173690677,0.8517995571911514,-0.10263618404857278
599.2000000000081,29.272726766839245,0.853655362992763,-0.10401478032198996
600.6000000000081,29.318712336177526,0.8569452776396685,-0.1039458694925921
602.0000000000082,29.36505968264245,0.8628786304119318,-0.10527441279327254
603.4000000000082,29.410634613401,0.8648975547992006,-0.10635918250303833
604.8000000000081,29.457644412999148,0.8711637648070693,-0.10743429207783883
606.2000000000082,29.50363060235685,0.87332510419482,-0.10790597493606446
607.6000000000082,29.55000229991602,0.87845068078972,-0.10923310258879981
609.0000000000083,29.59612208908792,0.8845764244891778,-0.10920629405032978
610.4000000000083,29.64216483098125,0.8933155545399076,-0.10961655063154963
611.8000000000083,29.688412530220084,0.8968871112828627,-0.10921703648771963
613.2000000000083,29.734824569751254,0.9008694845608962,-0.11054617875330841
614.6000000000083,29.781346548784523,0.9032964042870688,-0.11058303284779925
616.0000000000084,29.82713862649631,0.9086864649788562,-0.11321748112812369
617.4000000000084,29.87389963709666,0.9098912314759511,-0.11323958459838135
618.8000000000084,29.919761121583647,0.9146022311693557,-0.11388774846425642
620.2000000000085,29.96635731021671,0.9221237661608273,-0.11448081062406112
621.6000000000084,30.012444387600908,0.9249957549341052,-0.11583481089364733
623.0000000000084,30.058940080058957,0.9306061507311347,-0.11713010424302883
624.4000000000085,30.10520009828499,0.9328340906751438,-0.1170434655537802
625.8000000000085,30.151758901705904,0.9425186648950168,-0.11846641318852935
627.2000000000085,30.198263758761293,0.9457022468862575,-0.11977693717640969
628.6000000000085,30.244294591838347,0.9514698403541157,-0.120969908037873
630.0000000000085,30.29065917691111,0.9568423732366211,-0.1225702725501212
631.4000000000086,30.336815543255234,0.9591719479952768,-0.123819255803582
632.8000000000086,30.383438603466345,0.9692495297509889,-0.12270805320580935
634.2000000000086,30.42997530010998,0.9738153415954138,-0.12539708974010688
635.6000000000087,30.476459407145484,0.9772172321073915,-0.12673740643380826
637.0000000000086,30.52278070413384,0.9840539672222581,-0.12811357045427485
638.4000000000087,30.569300173854156,0.9869064711328679,-0.1294240384839065
639.8000000000087,30.615878777976818,0.9938026049952213,-0.12941694457942488
641.2000000000087,30.662199370138946,0.9967018007696558,-0.1307464473298987
642.6000000000088,30.708270635447676,1.00295849432203,-0.1320072564103496
644.0000000000088,30.755429094678902,1.012512635447664,-0.13172949045819804
645.4000000000087,30.801829256688116,1.0237015094538684,-0.13322554202040582
646.8000000000088,30.848499536874424,1.032992315697827,-0.13467599450827228
648.2000000000088,30.894383190404618,1.0461818446644677,-0.13596009577876256
649.6000000000088,30.941508964635577,1.056711132312028,-0.13601886110392547
651.0000000000089,30.98781001412353,1.0711217089327127,-0.1369892294049504
652.4000000000088,31.034326714552105,1.0795742320974613,-0.13773603676445223
653.8000000000089,31.081079736066485,1.0956539994445897,-0.1407109912285618
655.2000000000089,31.127566973492073,1.111283283555971,-0.14234055645568677
656.6000000000089,31.174072977835156,1.1228496519994455,-0.1450269090603551
658.000000000009,31.220693580512542,1.1432936558968974,-0.14645520864891637
659.400000000009,31.267380420694455,1.1647869114493017,-0.1478217307128995
660.800000000009,31.313835677238096,1.188086767567428,-0.14954833634795062
662.200000000009,31.360640420575162,1.2092518806559325,-0.15140066952427755
663.600000000009,31.407372110496226,1.2333466268104896,-0.15335945004404739
665.0000000000091,31.454000530194314,1.2572956391941452,-0.15510669070464544
666.4000000000091,31.50088678039562,1.2849168799398345,-0.15660509071564643
667.800000000009,31.547772981936667,1.3154884341911004,-0.15956160378271456
669.2000000000091,31.594282156644645,1.3473686576067254,-0.16033566123921084
670.6000000000091,31.641003211146238,1.3760811604626855,-0.16272887263578628
672.0000000000091,31.687884813550948,1.408863466357754,-0.16746287204171484
673.4000000000092,31.734800111837004,1.4421605112805984,-0.1706144992030021
674.8000000000092,31.781749884780815,1.4829489670709748,-0.17267528624478956
676.2000000000093,31.82873097559929,1.5234662210671983,-0.17499838318492067
677.6000000000092,31.875946289798673,1.5590102825800667,-0.17694167102028047
679.0000000000092,31.922533824187592,1.60015655011179,-0.180934113225252
680.4000000000093,31.969634481806953,1.6444495799466987,-0.184591887331921
681.8000000000093,32.016702702202025,1.6836866683215725,-0.18777356244974763
683.2000000000094,32.0637684524272,1.7321211313930953,-0.19222400890073033
684.6000000000093,32.1107654800532,1.7794630111693328,-0.19658105538085913
686.0000000000093,32.15755208655943,1.8267579047507287,-0.2000372663552521
687.4000000000094,32.204884503436844,1.8773790760209166,-0.203626884799621
688.8000000000094,32.25195003145484,1.935112643177237,-0.2074133608839306
690.2000000000094,32.29907110608944,1.9880885137800621,-0.21075951848295738
691.6000000000095,32.34644784953756,2.0454664925031945,-0.21717235054147688
693.0000000000094,32.39375124824722,2.10707299673999,-0.22218552085945564
694.4000000000094,32.44112799617127,2.1707976639999496,-0.22709978545809228
695.8000000000095,32.488639573092655,2.2364454140680583,-0.23146279762674915
697.2000000000095,32.53567495943518,2.2970425597780237,-0.23582158261679576
698.6000000000096,32.58316983148749,2.3700974413552176,-0.24247133319302883
700.0000000000095,32.630575881856075,2.4356664941602006,-0.24846621236857036
701.4000000000095,32.678026672904075,2.5146629670844494,-0.2547324723708648
702.8000000000096,32.725379926612256,2.5857796175295853,-0.2628510696329731
704.2000000000096,32.77279476971714,2.6621347873807903,-0.2694903884287938
705.6000000000097,32.82053403809979,2.7418931116557106,-0.27650003107907173
707.0000000000097,32.867856304592486,2.8185808634113294,-0.2850798381045303
708.4000000000096,32.915479931692225,2.904600873708104,-0.29097187227704113
709.8000000000097,32.962998841352416,2.9919675835959283,-0.29799651117124704
711.2000000000097,33.010557003828374,3.077378844870202,-0.30617980168825865
712.6000000000097,33.05811085453398,3.1677808684132907,-0.31477886124780907
714.0000000000098,33.10617409368094,3.2638414505023525,-0.32361942264635024
715.4000000000098,33.15335884909265,3.3550900153094005,-0.3335927537460375
716.8000000000097,33.20116430331936,3.4520245518666566,-0.344419846742273
718.2000000000098,33.248764404233086,3.547431028205402,-0.3567059283431857
719.6000000000098,33.29673646803588,3.64787338169423,-0.3682305221610047
721.0000000000099,33.344365959363074,3.749838227057646,-0.3784670560013499
722.4000000000099,33.392190871074455,3.852898522528604,-0.3892485240245134
723.8000000000098,33.44009685136334,3.957816407585598,-0.39936699750587845
725.2000000000099,33.48793368516943,4.0605143556365535,-0.4106803491780089
726.6000000000099,33.535193504905806,4.169238935133888,-0.4217156633254553
728.00000000001,33.58341552352655,4.278362418598597,-0.4348133097394258
729.40000000001,33.63114874800089,4.385737472450664,-0.44738543586998647
730.80000000001,33.67881997098026,4.492600501874648,-0.4607376037296591
732.20000000001,33.72691770437265,4.6035510411485285,-0.4761470394228762
733.60000000001,33.774820297813534,4.715265768457,-0.48880977914090407
735.00000000001,33.82252648049759,4.8228824548174725,-0.5025905381311992
736.4000000000101,33.87050893236761,4.9341324261712325,-0.5183716875677815
737.8000000000101,33.91816069388338,5.042194555174674,-0.5335965998128245
739.20000000001,33.9658512342398,5.150828184872546,-0.5496974889886759
740.6000000000101,34.01379775973028,5.262068122226895,-0.5639527421957884
742.0000000000101,34.06158063223614,5.36903402588293,-0.5791716956327368
743.4000000000102,34.109136136931475,5.474429766766242,-0.5955479781245963
744.8000000000102,34.15748232156915,5.581595407684975,-0.6133458168813286
746.2000000000102,34.2050006223031,5.687804486266762,-0.6306351393691356
747.6000000000103,34.25276530963845,5.795029205184822,-0.647070622979844
749.0000000000102,34.300615227675664,5.902794476164978,-0.6645451016523332
750.4000000000103,34.3481957328886,6.009314105020702,-0.6857175403969737
751.8000000000103,34.39632155066711,6.117233151352481,-0.7051155715804636
753.2000000000103,34.44386948259805,6.224965800079922,-0.7246372324183898
754.6000000000104,34.491959770239006,6.33537905165971,-0.7438555714016304
756.0000000000103,34.540047553295274,6.446756319714302,-0.7630911253646167
757.4000000000103,34.58776059223516,6.561499882038343,-0.7850550393370788
758.8000000000104,34.63523428285647,6.674573279740103,-0.8080566513761824
760.2000000000104,34.683861878953216,6.797841474112583,-0.8314101019942126
761.6000000000104,34.732060075778605,6.92264729052707,-0.8539827487499525
763.0000000000105,34.779772494934875,7.051695155540505,-0.8768749203612645
764.4000000000104,34.82796422001147,7.18584103878707,-0.8991731071061433
765.8000000000105,34.876234300026724,7.319745458580785,-0.9236122126999464
767.2000000000105,34.92450776799066,7.4592671593958695,-0.9492415789098603
768.6000000000105,34.9727249428393,7.607457156070602,-0.9726317075861877
770.0000000000106,35.02105857150088,7.750458513039363,-0.9975741498921198
771.4000000000106,35.068747326651206,7.893678881168633,-1.0230467624732502
772.8000000000106,35.11741412678619,8.038430179583035,-1.0501720017502367
774.2000000000106,35.16579207672932,8.176755406131786,-1.0765094752684221
775.6000000000106,35.213989549966506,8.310596504266673,-1.1029641419617304
777.0000000000107,35.26205769131613,8.43499500785743,-1.1306655664540881
778.4000000000107,35.309897303267086,8.549918203365348,-1.1579598297402498
779.8000000000106,35.35790014802954,8.663006316772156,-1.1855788850085336
781.2000000000107,35.405733612426225,8.765541386663285,-1.2148340567625833
782.6000000000107,35.45329141035892,8.851513988687088,-1.241188066500674
784.0000000000107,35.501000318732984,8.91018506460627,-1.2669015399831798
785.4000000000108,35.548359830084976,8.914092175317673,-1.2944379682054787
786.8000000000108,35.594547223619685,8.814987377090487,-1.320909659144538
788.2000000000108,35.63981802407446,8.59698684597779,-1.3470339567455851
789.6000000000108,35.68392634900048,8.206113801170087,-1.370823477489345
791.0000000000108,35.726234017465146,7.609344315448536,-1.3933703899291046
792.4000000000109,35.76686879264406,6.796047793653718,-1.411988904982839
793.8000000000109,35.80574720110777,5.77234849800545,-1.427648163829386
795.200000000011,35.84377097474807,4.624231750134955,-1.442089143793896
796.6000000000109,35.88197699878629,3.5284310684483335,-1.4523168961575434
798.0000000000109,35.9218319680359,2.614319770650808,-1.4601534048268898
799.400000000011,35.96304617331485,1.9141806445532628,-1.46552337084941
800.800000000011,36.00504954030875,1.403747759840284,-1.4681887181480429
802.200000000011,36.04941461355955,1.0259125362131396,-1.471315676500716
803.600000000011,36.09427988279982,0.780976071294059,-1.472943117895964
805.000000000011,36.13970513174503,0.6164660393550657,-1.4738393525386622
806.400000000011,36.18582481153522,0.5084249953192019,-1.4741953535793564
807.8000000000111,36.23197426118608,0.438152424190692,-1.4742940106760631
809.2000000000111,36.27846060904659,0.39283003882682743,-1.4754910313529317
810.6000000000112,36.32567357971081,0.361286158071085,-1.4767760793954827
812.0000000000111,36.372516975371326,0.34762376999224587,-1.4767290517672635
813.4000000000111,36.41986083534539,0.3427827754570961,-1.4758259683679436
814.8000000000112,36.46676321737394,0.3400237991827475,-1.476439516473251
816.2000000000112,36.513583542832265,0.33936674651738596,-1.475810350877711
817.6000000000113,36.560932223073216,0.33940050068626304,-1.4758081498905797
819.0000000000113,36.608094379342944,0.33898895072300617,-1.4745349606611677
820.4000000000112,36.65526314692239,0.33194269105951535,-1.4751642191221022
821.8000000000113,36.70247149826781,0.3306381533686831,-1.4751600307089774
823.2000000000113,36.7496838330892,0.3317608867884678,-1.4751600380466026
824.6000000000113,36.79674701724141,0.33150761236457305,-1.4751601265139245
826.0000000000114,36.844073003744704,0.3288964615584775,-1.4750940073455965
827.4000000000113,36.89145482750346,0.32888059632538613,-1.4758443637237253
828.8000000000113,36.93850350747857,0.32739785130080157,-1.478640996751667
830.2000000000114,36.98599575694187,0.3278865767787562,-1.4786220045154104
831.6000000000114,37.03322099549039,0.3254137673072398,-1.4783384596657507
833.0000000000115,37.080743447261575,0.3281971202329508,-1.4772415186814611
834.4000000000115,37.12787633781827,0.3289282619740055,-1.4772398536363691
835.8000000000114,37.17535438989896,0.32844579644853167,-1.4772398548784693
837.2000000000115,37.22264116439197,0.3273260954480537,-1.477228386160374
838.6000000000115,37.27020933486814,0.3303427226504635,-1.4759331442241614
840.0000000000116,37.31737013293622,0.33231877543958854,-1.4759249590034127
841.4000000000116,37.364887594968266,0.32995110343570544,-1.4745890145271923
842.8000000000116,37.412132872044104,0.32533705160855375,-1.475967132972221
844.2000000000116,37.45964702257336,0.3270973913788684,-1.4759198340412558
845.6000000000116,37.50714233429006,0.32570802323718917,-1.4759214890194805
847.0000000000116,37.55454736409825,0.3295805258285649,-1.4745974784996823
848.4000000000117,37.602397796316616,0.3280681946044022,-1.475842322866035
849.8000000000117,37.64956210736353,0.3291461600415757,-1.4773498489604386
851.2000000000116,37.697161179317234,0.3303908666276951,-1.4762040542834054
852.6000000000117,37.744714090532426,0.3299457423071901,-1.4762168520208272
854.0000000000117,37.79219235490306,0.3336356065646,-1.4775730806985607
855.4000000000118,37.83982838066421,0.33037806584068785,-1.477558965254937
856.8000000000118,37.887103432441585,0.33115802921776116,-1.4788894129114905
858.2000000000118,37.9345816469029,0.3336304269380983,-1.4788901440920341
859.6000000000118,37.982307851842506,0.3303598412717974,-1.478890140495344
861.0000000000118,38.02961652199632,0.33309076235085255,-1.4788902662157537
862.4000000000119,38.07737008236774,0.32751656284119623,-1.480245731111717
863.8000000000119,38.125004514854496,0.3286200670247257,-1.481277987117536
865.2000000000119,38.172526618377915,0.3292475870453484,-1.481198892468902
866.600000000012,38.219952151516324,0.3335343193106619,-1.4802895322684404
868.0000000000119,38.267631108640465,0.3327693122817388,-1.4802099805175253
869.4000000000119,38.314900011026644,0.3340673698804639,-1.4801917039730994
870.800000000012,38.36247916224305,0.3319007601185804,-1.4798711056455627
872.200000000012,38.4093032604987,0.3319573442430339,-1.4785703686421625
873.600000000012,38.45738886737332,0.33676363113600427,-1.4798648599581394
875.000000000012,38.504561800011274,0.3361054662930534,-1.4798701324231431
876.400000000012,38.552257970720596,0.33563971421317595,-1.4798711103434758
877.8000000000121,38.599440470571814,0.33770293480018165,-1.481185681635361
879.2000000000121,38.64714103749637,0.3350156653986176,-1.4824968741917441
880.6000000000121,38.6943274575185,0.3380696099841749,-1.4825235527694502
882.0000000000122,38.74145154656744,0.33672551205824175,-1.4838088639821647
883.4000000000121,38.7892049703246,0.3350264230776032,-1.4838168773575866
884.8000000000122,38.83690834079243,0.3394483852111556,-1.4853140563289173
886.2000000000122,38.88391730651967,0.3482910132212693,-1.48525717899861
887.6000000000122,38.93182238804151,0.35078761915252277,-1.483888463789893
889.0000000000123,38.979203388669355,0.3573291221031121,-1.4824992947184072
890.4000000000123,39.02654461311482,0.36332330956635905,-1.4833945450461186
891.8000000000122,39.074210681509804,0.3682938862350784,-1.484024472829962
892.0000000000123,39.080791450735035,0.3690328270234371,-1.4845649316215206