File: 01_Data/Concrete_Block/STA/N2/30K_min/Concrete_Block_STA_N2_30KData_230830_R2.csv
##Temp./Â°C,Time/min,DSC/(mW/mg),Mass loss/mg
29.0,10.634809190176131,0.0005887068068753387,0.008413402118520708
30.40000000000002,10.828574169247029,0.0014290196246005762,0.008549197867864677
31.80000000000004,10.960462162000606,0.002061698336210324,0.009165351887418183
33.20000000000006,11.067084809524673,0.002664694910026827,0.01027847986352981
34.60000000000008,11.159050817203683,0.0031209964642339577,0.009169095333476207
36.0000000000001,11.242816896816972,0.0036157132048314396,0.01255368541259827
37.40000000000012,11.318907709167416,0.004051337613681035,0.009140484430929519
38.80000000000014,11.391203357826857,0.004407832348533994,0.009637157882963265
40.20000000000016,11.459415302616486,0.004766314619376318,0.009021465022271968
41.60000000000018,11.524353384358799,0.0051015968908194285,0.009123978628821305
43.0000000000002,11.587371232282136,0.005409256390834793,0.008597333727976775
44.40000000000022,11.648863490954003,0.00570889710103601,0.008300365255649922
45.80000000000024,11.707714449056894,0.005929722823631037,0.008502820671282052
47.20000000000026,11.765875795961357,0.006227328223353978,0.007926471010279101
48.60000000000028,11.82310431326242,0.006466129021763634,0.007016748183929167
50.0000000000003,11.87932561528824,0.006691398102366956,0.007044449828754296
51.40000000000032,11.933496327193307,0.006931489979912952,0.00731267810317604
52.80000000000034,11.98826384747238,0.007141414219811657,0.006344792724121362
54.20000000000036,12.041796326115518,0.007389863545936473,0.0060422562574160565
55.60000000000038,12.09479583901339,0.007570145472102351,0.006220095528249203
57.0000000000004,12.147377869830914,0.007774181146226723,0.0049439196005778285
58.40000000000042,12.199058514875302,0.007969904405271493,0.006507696505622107
59.80000000000044,12.250298394888272,0.00819298102387268,0.006284917156932579
61.20000000000046,12.301292149067464,0.008357234418331916,0.005017718614254818
62.60000000000048,12.351888871289187,0.008503434400039117,0.004630909747959322
64.0000000000005,12.402216709163815,0.00864567089138317,0.004622185769477483
65.40000000000052,12.451946655680686,0.00877695810930406,0.004818516415667773
66.80000000000054,12.502044922603284,0.00891953559953785,0.0034386140561082357
68.20000000000056,12.551863132822994,0.008984523607852648,0.003371519686055535
69.60000000000058,12.600463608820359,0.009074991777504992,0.0039017977018431793
71.0000000000006,12.650428394347855,0.009133460601833607,0.0026316495964806563
72.40000000000062,12.699103365664532,0.009234683096781621,0.0005331059032869234
73.80000000000064,12.748449583575928,0.009307993635496083,0.000362293564819538
75.20000000000066,12.796895229062073,0.009381175190220607,0.0002522791043588768
76.60000000000068,12.846265607033976,0.009471109525075395,0.0004226451528097641
78.0000000000007,12.894521744919118,0.009528323964750226,0.0012156481846261613
79.40000000000072,12.94309218918439,0.009596693622405669,0.00033341911074558084
80.80000000000074,12.991332361405755,0.009654250163262771,0.00041112948309773856
82.20000000000076,13.03971959043506,0.00970491409056397,0.0003876298177658555
83.60000000000078,13.08793069511581,0.009809035861890431,0.00031415603874052067
85.0000000000008,13.135734336578949,0.009833009800819454,-0.001012699289702823
86.40000000000082,13.183353976771633,0.00989176170331632,-0.0018615548433160711
87.80000000000084,13.231655016122087,0.009960781340986099,-0.00238800715331422
89.20000000000086,13.277981835733105,0.009991547847610863,-0.002320242959655161
90.60000000000088,13.325853631700118,0.010013049979633355,-0.00392397251189891
92.0000000000009,13.372979008897312,0.010090597367920905,-0.003949628372652114
93.40000000000092,13.420429137400854,0.010128285903514327,-0.002666191744452817
94.80000000000094,13.467450082730322,0.010154945695412658,-0.002636570010537298
96.20000000000095,13.514143542021843,0.010189912189579936,-0.004033697599908237
97.60000000000097,13.560648616430624,0.010229915033183695,-0.0036719951221186875
99.000000000001,13.607037064086425,0.010275458515574137,-0.00412304333590896
100.40000000000101,13.65390531670917,0.01030541939067754,-0.0065781884293585335
101.80000000000103,13.700439815236464,0.010327954358117095,-0.0065876062219274445
103.20000000000105,13.747227623171206,0.010353215727574187,-0.006596858832637054
104.60000000000107,13.793035130563734,0.010357837064952293,-0.007910559451204335
106.0000000000011,13.839268323426587,0.010368955461311237,-0.006575864892312211
107.40000000000111,13.885779420674256,0.010432166991574596,-0.006580640365200452
108.80000000000113,13.93176380273879,0.010447233882778432,-0.007739904652282803
110.20000000000115,13.978056837125223,0.010496134786611842,-0.007901693465811377
111.60000000000117,14.023750592375821,0.010517429678286751,-0.007908492729370664
113.0000000000012,14.069945707753314,0.010586893459863326,-0.009200256366170834
114.40000000000121,14.116099082124286,0.01054769888788046,-0.009211435834600934
115.80000000000123,14.161983512103482,0.010624802152992068,-0.009209255613683354
117.20000000000125,14.207569347194296,0.010664300788752863,-0.010500381543266712
118.60000000000127,14.252405174867649,0.010688167586442756,-0.011859478270054069
120.0000000000013,14.29894355151467,0.010723155153106598,-0.011857644605555606
121.40000000000131,14.344836336783057,0.010716663075747654,-0.011293833825561705
122.80000000000133,14.390310645357644,0.010709625181439619,-0.010868692787425971
124.20000000000135,14.435534698961055,0.01075857408427398,-0.01086901087313663
125.60000000000137,14.481257070949813,0.010745630704436704,-0.010879944514982753
127.00000000000139,14.526144220837953,0.010748925955521604,-0.013360002791955594
128.4000000000014,14.571150200969635,0.010673832544234558,-0.013515343066558216
129.80000000000143,14.615975031040076,0.010664703561311436,-0.013515204306287387
131.20000000000147,14.66071745773688,0.010670561681848219,-0.01353741191863378
132.60000000000147,14.706058700161163,0.01063113066396763,-0.014833151523077959
134.00000000000148,14.750531558705543,0.010606715081274807,-0.014835146184054793
135.4000000000015,14.795072942797312,0.010553650522421725,-0.014836214812675053
136.80000000000155,14.83938886290171,0.010555497651954605,-0.016157836201870168
138.20000000000155,14.88333173650477,0.010563683265255237,-0.016168190798282467
139.60000000000156,14.927678168904265,0.01050254575610423,-0.014842070744890634
141.0000000000016,14.972952295067564,0.01050969040802249,-0.014835118151751203
142.40000000000163,15.01662088062788,0.010527325074566172,-0.014831303528239914
143.80000000000163,15.060993614848286,0.010504668875982573,-0.015504470820673077
145.20000000000164,15.105011488333862,0.010497612543860686,-0.015806700589479306
146.60000000000167,15.148797300419552,0.010500495538352816,-0.01681154387634365
148.0000000000017,15.192792919723534,0.010526326025314732,-0.016811882552872248
149.4000000000017,15.236848128814101,0.010529620485517057,-0.017498741895650483
150.80000000000172,15.280829755311142,0.01049670549291893,-0.018316762097214223
152.20000000000175,15.324805456118174,0.010496927361148375,-0.018901091410270965
153.60000000000178,15.368535908972522,0.010540786056589995,-0.01890554115337295
155.0000000000018,15.41206856930992,0.010492182534461662,-0.01791260161130026
156.4000000000018,15.4556245449197,0.01046503550177261,-0.0179112260163663
157.80000000000183,15.499295426185627,0.010523111362922275,-0.017911311805931973
159.20000000000186,15.543329619427109,0.010503575567453498,-0.0179113035613625
160.60000000000187,15.586578809440585,0.01048482611149632,-0.017902914175834894
162.00000000000188,15.63010715969839,0.010497866680727993,-0.017584545752526992
163.4000000000019,15.673720940912023,0.01053171999220151,-0.017581302904801532
164.80000000000194,15.717400356799352,0.010471585888716833,-0.017581309743775364
166.20000000000195,15.760652617795111,0.01048644330043244,-0.017581124381479185
167.60000000000196,15.80405597768754,0.010482409354669358,-0.019109009257078924
169.000000000002,15.847658886953125,0.010460720889302237,-0.02034201678080194
170.40000000000202,15.890270017655991,0.010463395703190926,-0.019686360594732832
171.80000000000203,15.934343221772243,0.01044472125023781,-0.020249786506212786
173.20000000000203,15.977480956656802,0.010439560198104507,-0.018884836537608862
174.60000000000207,16.02068719241074,0.010435464394771079,-0.018881824095501543
176.0000000000021,16.063819527843982,0.010439403895247786,-0.02108922342972619
177.4000000000021,16.107407704847652,0.010465945938631102,-0.021529099627912274
178.80000000000211,16.15050165733003,0.010413834404610224,-0.021529521579850552
180.20000000000215,16.192689382768894,0.010408821437866218,-0.021529520010204806
181.60000000000218,16.23676475336128,0.010403326421359783,-0.021529519999518243
183.0000000000022,16.2795104980865,0.01040404709967976,-0.021529519937217856
184.4000000000022,16.322356430391338,0.01040924074134121,-0.02152954807084484
185.80000000000223,16.365109074416,0.010385990923465812,-0.021541657063352204
187.20000000000226,16.408058572943265,0.010363372136043037,-0.022874548220784163
188.60000000000227,16.450998254896465,0.01038097714715527,-0.022888166954629696
190.00000000000227,16.4935641475195,0.010376135014051864,-0.021823954994317774
191.4000000000023,16.53664379467324,0.010339407671941366,-0.020535356085076728
192.80000000000234,16.57891940616114,0.010382006054126182,-0.02054088352508643
194.20000000000235,16.62138353366162,0.010405123793331542,-0.02063394914105743
195.60000000000235,16.664457815699933,0.010414507415683175,-0.02184568302524781
197.0000000000024,16.707025743813432,0.010398316266348405,-0.021426377444527134
198.40000000000242,16.7499937325724,0.0104096659057791,-0.021266520127539934
199.80000000000243,16.79239968037391,0.010419950400525783,-0.023247885541934465
201.20000000000243,16.835027071774817,0.01039942306318739,-0.023443938006096232
202.60000000000247,16.877878618079922,0.01043511893509964,-0.024467906205359213
204.0000000000025,16.920637012820492,0.010397291589446108,-0.02316906760356119
205.4000000000025,16.962906479054833,0.010393686495660569,-0.023168372873527687
206.8000000000025,17.00559982080914,0.010429393607672163,-0.02280293282558432
208.20000000000255,17.047909628292466,0.010438165476620437,-0.021842120124517805
209.60000000000258,17.0901108963316,0.01047870014895922,-0.02184297826107695
211.0000000000026,17.13302533392767,0.010449616945940314,-0.02184296196600144
212.4000000000026,17.175234399645895,0.01044069786097059,-0.021839235186973838
213.80000000000263,17.218169716643807,0.010480138809872138,-0.023133949697751177
215.20000000000266,17.260526682878396,0.010460363786769164,-0.023169291212212784
216.60000000000267,17.303115262412554,0.01049204066070297,-0.023162229484455565
218.00000000000267,17.34520391267278,0.010482207448540622,-0.024476991189345654
219.4000000000027,17.388248080848346,0.010525175218549749,-0.024495272941095436
220.80000000000274,17.43049600028842,0.01051133256142524,-0.0244952961127467
222.20000000000275,17.47302315648859,0.010536156375093895,-0.02449529589677013
223.60000000000275,17.515073770925884,0.010543186721770483,-0.02449527226926307
225.00000000000279,17.557586879447936,0.010573199755981644,-0.024492010000841447
226.40000000000282,17.600063510073568,0.010585096839718767,-0.025143357268348154
227.80000000000283,17.642454694632583,0.01058839334011841,-0.026464329537930098
229.20000000000283,17.685056832580756,0.010631582123714324,-0.02646630814936657
230.60000000000286,17.727353193417798,0.010667990825580573,-0.026466319952021422
232.0000000000029,17.769877317981493,0.010686292527896081,-0.0264663196181516
233.4000000000029,17.811982785351773,0.01073572552689854,-0.02646618436034487
234.8000000000029,17.854351940996583,0.01072429372458801,-0.02643657695392676
236.20000000000294,17.89655388189478,0.010771981706505594,-0.02580958809031131
237.60000000000298,17.938840195512903,0.010762538781847122,-0.025797364705056225
239.00000000000298,17.981210854131163,0.010780461551220439,-0.025797124063103638
240.400000000003,18.02359967968535,0.010791453760523626,-0.02570032139206546
241.80000000000302,18.065882859746225,0.01079616423700041,-0.027041829151130514
243.20000000000306,18.10841694236311,0.010819774259973717,-0.023855592867391806
244.60000000000306,18.150329713930148,0.010751538417534807,-0.02561285368247468
246.00000000000307,18.192819357014226,0.010787887806168146,-0.02710402054051997
247.4000000000031,18.23468832739484,0.01077972702756762,-0.027123441110887825
248.80000000000314,18.277677926767545,0.010782091095576691,-0.02712574417753899
250.20000000000314,18.31966278678863,0.010777807016010452,-0.025683338767407804
251.60000000000315,18.361422070601087,0.010780709386854558,-0.026250270200961268
253.00000000000318,18.404228486160225,0.010787755317176208,-0.027132116614552615
254.40000000000322,18.446617022075642,0.010779041922614363,-0.02797118598510906
255.80000000000322,18.488704536257373,0.010761382468782131,-0.02844884465804398
257.20000000000323,18.53130289633208,0.010772969308370064,-0.028452586100456756
258.60000000000326,18.572968647153157,0.01076789308009205,-0.027148972063798738
260.0000000000033,18.615452766213416,0.010767646893099173,-0.027123599471536863
261.4000000000033,18.65705251841997,0.010764314460764871,-0.02712350379789541
262.8000000000033,18.69986059756913,0.010828611056187199,-0.027123478642408827
264.20000000000334,18.7420703960697,0.010797782135093987,-0.027145303951584765
265.6000000000034,18.78464498889362,0.010815797489903713,-0.026458468277638758
267.0000000000034,18.82636858139069,0.010821963290954577,-0.02646442171899821
268.4000000000034,18.868844162396393,0.010833757704417463,-0.027087003784259878
269.8000000000034,18.91087255568807,0.01085508728809006,-0.027788909924083782
271.20000000000346,18.95302766238655,0.010827444900365274,-0.027789659113778953
272.60000000000343,18.995299071306928,0.010865828207305899,-0.027789790361794076
274.00000000000347,19.037400058118095,0.01088010260140788,-0.027809686757052532
275.4000000000035,19.07983753754436,0.01080634431648078,-0.02909111102087536
276.80000000000354,19.12188626284777,0.010802140007755855,-0.029087546124998198
278.20000000000357,19.16410959355713,0.010824917848687337,-0.030064310142137174
279.60000000000355,19.20627635551345,0.010791373193129101,-0.030081642958009525
281.0000000000036,19.247709940350028,0.010777113095427716,-0.030081717825339638
282.4000000000036,19.29069561843624,0.010803522195055336,-0.03007986745353719
283.8000000000036,19.33274162989618,0.010779288229916507,-0.03128621149349442
285.2000000000036,19.375302787209485,0.010747823235797439,-0.03137976862589653
286.60000000000366,19.417887244408092,0.010782043527333113,-0.03043220616785902
288.0000000000037,19.459685129937295,0.010751641157837461,-0.030417869843915923
289.40000000000373,19.501494400382473,0.010740954873147007,-0.030417871813853026
290.8000000000037,19.54424099556368,0.010725481746005495,-0.030417871998935198
292.20000000000374,19.586496860234664,0.010723599595988143,-0.030417872000015223
293.6000000000038,19.62871439865742,0.01073315740814287,-0.030417872000015223
295.00000000000375,19.670793287111866,0.010739144179536007,-0.03041787199995838
296.4000000000038,19.7129363493619,0.010728485139427382,-0.030417871979153688
297.8000000000038,19.755842052129463,0.010711272835301352,-0.030417866127407933
299.20000000000385,19.79809293928657,0.010698922545874652,-0.030417261317751354
300.6000000000039,19.840832241840776,0.010714083463152597,-0.02960679471195249
302.00000000000387,19.88292060361738,0.010728814252521021,-0.02908851890018127
303.4000000000039,19.925196223985093,0.010705398882244622,-0.030396680672765797
304.80000000000393,19.9676852621342,0.010719157446258837,-0.030417832061090166
306.2000000000039,20.01032966104439,0.010719329075324947,-0.030417872104521848
307.60000000000394,20.052536036670663,0.010703018639885362,-0.030417872001038404
309.000000000004,20.09509732471522,0.010717491615397702,-0.03041787200714907
310.400000000004,20.13754255896009,0.010717716549238584,-0.030417872993808714
311.80000000000405,20.179958604018815,0.010716262894507814,-0.030417736632671222
313.200000000004,20.222224124325866,0.01073898338669938,-0.030954178706508628
314.60000000000406,20.264864303925165,0.01071147937937437,-0.0314053869133204
316.0000000000041,20.30731016684404,0.010714076939922261,-0.03140646185968876
317.40000000000407,20.349763932204567,0.010712521719702646,-0.03140646400677838
318.8000000000041,20.392184704126773,0.010684474330887265,-0.031406468701192125
320.20000000000414,20.43479262810936,0.010693252494235583,-0.03140780347050054
321.6000000000042,20.47739280245649,0.010694281676050982,-0.032011094083770786
323.0000000000042,20.520061947207147,0.01068985161680746,-0.032066681027060895
324.4000000000042,20.562739592456232,0.010671030963022205,-0.03206460190500593
325.8000000000042,20.60546296417274,0.010680244305400745,-0.03240465608843124
327.20000000000425,20.64765797337015,0.01068163559351842,-0.03237986495346945
328.60000000000423,20.690375443240505,0.010663643906927985,-0.03241302718643624
330.00000000000426,20.73325206423247,0.010626768763826804,-0.03138236646023529
331.4000000000043,20.77610648601668,0.010686991373782685,-0.03138989897527722
332.80000000000433,20.81877335360586,0.010698026167156125,-0.03138991998878282
334.20000000000437,20.861277372818225,0.010688714842031651,-0.03138993163287296
335.60000000000434,20.903422212484486,0.010673575728381825,-0.031394452646452464
337.0000000000044,20.947024594859208,0.010630642553654326,-0.03201691598906109
338.4000000000044,20.989559802380615,0.010643036597475241,-0.033808177615156865
339.8000000000044,21.032209398615855,0.010666409585447557,-0.03212507392882458
341.2000000000044,21.075159113459616,0.010649969934860901,-0.03073172986910322
342.60000000000446,21.11819557930507,0.010625867803306717,-0.03171985283793788
344.0000000000045,21.160911248777715,0.010646463936774129,-0.0330670967279616
345.4000000000045,21.203923856900786,0.01064530201982535,-0.03306125445843122
346.8000000000045,21.246298547204002,0.010648390672128008,-0.03306121693060504
348.20000000000454,21.289573474052606,0.010700734162688873,-0.03306118105638234
349.60000000000457,21.33255710623552,0.010682653503574197,-0.031378249090778354
351.00000000000455,21.37548623261915,0.010668131950288831,-0.032174157682334226
352.4000000000046,21.41853744583603,0.010698475563193425,-0.033198985479657495
353.8000000000046,21.461323574131956,0.01073678900754048,-0.035104894583639634
355.20000000000465,21.504166928340076,0.01075395714329589,-0.03519465960224011
356.6000000000047,21.547384808100777,0.01078797002446275,-0.03567801454235564
358.00000000000466,21.59028775784208,0.010779042054426955,-0.0346030291125885
359.4000000000047,21.633516933190446,0.010787008097604838,-0.03426568151954257
360.80000000000473,21.676775255783056,0.010840451704919169,-0.03357512660116413
362.2000000000047,21.719972158185218,0.010827724770042745,-0.03360967452238128
363.60000000000474,21.76263267191447,0.01087021016856908,-0.03361093888136679
365.0000000000048,21.80616325014968,0.01084608121934071,-0.034293946582039325
366.4000000000048,21.84910824230018,0.01086395449605496,-0.03491168226733521
367.80000000000484,21.892286683297428,0.01085820888592539,-0.0349116700790546
369.2000000000048,21.93524401182747,0.010878040715137479,-0.034908068289723815
370.60000000000485,21.978710093650438,0.010869514413141684,-0.03638667638881543
372.0000000000049,22.021823256557845,0.010859177909794675,-0.03895769739915522
373.40000000000487,22.06512167122079,0.010849177922573039,-0.03748802810542884
374.8000000000049,22.108587619426068,0.010845651938998946,-0.03623618966142317
376.20000000000493,22.15165507142419,0.010834177034629428,-0.03702331907382472
377.60000000000497,22.195025137854902,0.010875167150981848,-0.03722614137643632
379.000000000005,22.238323820708164,0.01087782165828244,-0.03722643172983453
380.400000000005,22.281760058681346,0.010864768212140961,-0.037226432010044164
381.800000000005,22.32486876747888,0.01086115650435776,-0.03722643487009236
383.20000000000505,22.36812375002166,0.010869856173061408,-0.03722672019196693
384.600000000005,22.41181402079981,0.010872923118341003,-0.036998463451283214
386.00000000000506,22.454646830098486,0.01086597099072185,-0.03567407916347065
387.4000000000051,22.498528225978518,0.010820195248584354,-0.037218680529406356
388.8000000000051,22.541545939988072,0.010838102980629122,-0.03736008741867636
390.20000000000516,22.585136226271565,0.010817709546737631,-0.03824453439790432
391.60000000000514,22.62885861360633,0.010796747017277576,-0.038214613436906575
393.0000000000052,22.67212089458176,0.010813261434012693,-0.03834718938270498
394.4000000000052,22.71556820412795,0.010824619603553888,-0.04086897076530249
395.8000000000052,22.75917030852007,0.010845820951881345,-0.0393068201338167
397.2000000000052,22.80275076516825,0.010841137336176105,-0.03798212570200121
398.60000000000525,22.84598852247381,0.010838832048690433,-0.036633515401348404
400.0000000000053,22.889490075629276,0.010841666399661717,-0.036674996538522464
401.4000000000053,22.933230501236306,0.010839534200609957,-0.03667506509785312
402.8000000000053,22.976496631476643,0.010844638524433434,-0.03668662924877708
404.20000000000533,23.02027249330458,0.010843040666446997,-0.037986809752368345
405.60000000000537,23.064164997327364,0.010817533891853361,-0.037380566475405885
407.00000000000534,23.107519002160114,0.010839740540358677,-0.03799109519155763
408.4000000000054,23.15115354839364,0.010839982946378373,-0.037798088402013263
409.8000000000054,23.195062165329503,0.010883653211381563,-0.037983433397812405
411.20000000000545,23.238614741848174,0.01087863419032107,-0.03799501704747854
412.6000000000055,23.2823880058788,0.010920243881599834,-0.03799502409790989
414.00000000000546,23.326011500645233,0.01093924186495827,-0.037995023609482814
415.4000000000055,23.369797250836807,0.01101667375262265,-0.0379950807513012
416.8000000000055,23.41380982769439,0.011086079940277396,-0.03808082899897158
418.2000000000055,23.457324648033776,0.011204410345298114,-0.03948630288905974
419.60000000000554,23.501502183520795,0.011343763226744817,-0.04031020269493979
421.00000000000557,23.54524362099003,0.01146962741177887,-0.04031143494646017
422.4000000000056,23.589480583718636,0.011599107918028258,-0.040301529538197656
423.80000000000564,23.633232280463844,0.011753122954102264,-0.03898584877464373
425.2000000000056,23.677028571735164,0.01185923246635544,-0.03836147503557186
426.60000000000565,23.720624048627545,0.01191683449470474,-0.03898371742644713
428.0000000000057,23.76493992969424,0.011960090282210704,-0.0389424867192929
429.40000000000566,23.808287484209668,0.011973851922796964,-0.040267592306804545
430.8000000000057,23.852979251636125,0.011941708129847876,-0.04161369605759546
432.20000000000573,23.89666968307833,0.011773423603807055,-0.04161323299572928
433.60000000000576,23.940224894273143,0.011670565969347485,-0.04161323211380363
435.0000000000058,23.98431152123936,0.011495450492254611,-0.04161333610767315
436.4000000000058,24.028449570563907,0.011336543553451992,-0.041893060573244156
437.8000000000058,24.072251666992923,0.011192977004914773,-0.04293752135893669
439.20000000000584,24.116348986163224,0.011077951418688975,-0.042921527291042594
440.6000000000058,24.160241293933318,0.011022139754093776,-0.04162150339436721
442.00000000000585,24.20411126226783,0.01092948976845295,-0.04161940011326237
443.4000000000059,24.2481986438084,0.010912503310179978,-0.041619375152549765
444.8000000000059,24.29143682176837,0.010842169095974446,-0.04160215703035419
446.20000000000596,24.335990919652758,0.010802742356840348,-0.04260747875238735
447.60000000000593,24.38022193792337,0.01079465554499482,-0.04260941449555844
449.00000000000597,24.424051209394253,0.010772262895551379,-0.042609392053776673
450.400000000006,24.468299403967713,0.010757462469111665,-0.04260939199966174
451.800000000006,24.512305617485616,0.010723075902602918,-0.042609391938242425
453.200000000006,24.556678976199926,0.01070690985065201,-0.042609397550307904
454.60000000000605,24.59993663443457,0.010666850365495247,-0.04261822262853343
456.0000000000061,24.64469316457464,0.010670502698501682,-0.042938600310606034
457.4000000000061,24.688436566285667,0.010652118813466758,-0.04294091536272049
458.8000000000061,24.733029091920876,0.010655068243213977,-0.04377668323166972
460.2000000000061,24.777011060687602,0.010604019377967674,-0.044259276109443135
461.60000000000616,24.82126893792753,0.010592813721570594,-0.04425767004099157
463.00000000000614,24.865615724549833,0.010577961834431835,-0.04313591816148232
464.4000000000062,24.90986325708989,0.010585235206718183,-0.04293948861814556
465.8000000000062,24.95399041152773,0.010542285435118886,-0.04293939196105612
467.20000000000624,24.998467577202383,0.010513268255417882,-0.042939392262638876
468.6000000000063,25.04259067394393,0.010510381234413098,-0.0429390271947625
470.00000000000625,25.086958875997595,0.010468278155858483,-0.044073638459877884
471.4000000000063,25.131479319616965,0.010526616478699227,-0.04419287038408015
472.8000000000063,25.175571721236373,0.010540427979837313,-0.04556059247008193
474.2000000000063,25.219785753454982,0.010507800190607989,-0.04476088059396943
475.60000000000633,25.264127288587815,0.010504920511013656,-0.04510371599388918
477.00000000000637,25.308562475236013,0.010541228551410698,-0.045567407662218784
478.4000000000064,25.353070150244093,0.010571875969880799,-0.045567471010400595
479.80000000000643,25.397458662254383,0.010600198993645721,-0.04535067897958811
481.2000000000064,25.441580237996252,0.010627017305164348,-0.04283490245180133
482.60000000000645,25.4860447445733,0.0105941406730042,-0.042630489942467875
484.0000000000065,25.530489076181347,0.010617034264751858,-0.04411788164085806
485.40000000000646,25.57479870377609,0.010654231785011856,-0.045469167102851316
486.8000000000065,25.618741930612106,0.010637207310890504,-0.04545596650697803
488.2000000000065,25.663839640325506,0.01064014068554504,-0.046764095610484446
489.60000000000656,25.708367740333056,0.010645347587524109,-0.04677319266235713
491.0000000000066,25.75287154006359,0.010596291748115862,-0.04677324111534631
492.40000000000657,25.797451777661827,0.01064680472886765,-0.046780753474962466
493.8000000000066,25.841687905557638,0.010618369093908574,-0.04743774861967154
495.20000000000664,25.886326295409546,0.010640954903020758,-0.04776395330628702
496.6000000000066,25.930629602861817,0.01063563900367283,-0.04765928184593804
498.00000000000665,25.974567306819573,0.010629862112294828,-0.04633747829339541
499.4000000000067,26.01988205653091,0.010640280836546157,-0.04767747954480228
500.8000000000067,26.064400210586218,0.010668064184991534,-0.04764122516996849
502.20000000000675,26.109046764240155,0.010677935102625297,-0.04763454716416504
503.60000000000673,26.15384358947542,0.010654123754102499,-0.04896806690950939
505.00000000000676,26.198663761285328,0.010687656596436994,-0.0497713171964449
506.4000000000068,26.243193426758587,0.010704057490030583,-0.05028723787191325
507.8000000000068,26.288026948237608,0.010714551696179566,-0.050290095131742873
509.2000000000068,26.333066799412965,0.010691229367483665,-0.048973835376330044
510.60000000000684,26.37701091054461,0.010674025204104145,-0.048991115887332626
512.0000000000068,26.422561454025022,0.010678987990864081,-0.050291683854453595
513.4000000000069,26.4673984938647,0.010685516685054313,-0.050293548206610694
514.8000000000069,26.51226250804111,0.010702196316047576,-0.050293541012393916
516.2000000000069,26.557253957794618,0.010711324977094474,-0.05041993887755325
517.600000000007,26.60272884660173,0.010720904483077874,-0.050953551800262176
519.0000000000069,26.647444094160356,0.010733101049779368,-0.05095354954457321
520.4000000000069,26.692630395529623,0.010721565276602485,-0.050953550607829357
521.800000000007,26.73789324500381,0.010758210969478373,-0.050941143029461955
523.2000000000071,26.783067981219297,0.010801702902256308,-0.04963825949511147
524.6000000000071,26.828336385004846,0.010787530035842647,-0.04865880578716997
526.000000000007,26.873141207021067,0.010848332132281339,-0.04689720708256573
527.4000000000071,26.91933195011209,0.010863490900801237,-0.05006032221467649
528.8000000000071,26.964619956302165,0.010918497995425892,-0.05005389268461613
530.2000000000071,27.009959074190068,0.010928470853137211,-0.05215188298825524
531.6000000000072,27.055393787885997,0.010946169304786564,-0.05269500457711729
533.0000000000072,27.10092250808973,0.010954222095827238,-0.05269295884451708
534.4000000000071,27.146627711839336,0.010954429552725142,-0.05400914693004211
535.8000000000072,27.19249496069226,0.010946402549577612,-0.05402197015865795
537.2000000000072,27.23811616447262,0.010954375153276606,-0.054021942143691604
538.6000000000072,27.283599066663076,0.010963107086277927,-0.05401400132492995
540.0000000000073,27.329265609603247,0.0110094809295652,-0.055348470960638
541.4000000000073,27.375293676210706,0.010979886472486346,-0.05534756500247795
542.8000000000073,27.42121446039294,0.0110127668657848,-0.054924223591683585
544.2000000000073,27.466756985986244,0.010991426402120802,-0.05506436961951522
545.6000000000073,27.5124038810523,0.010986464407160723,-0.05599830086435986
547.0000000000074,27.558451279352564,0.011011931766003917,-0.054668006536758185
548.4000000000074,27.604255846244257,0.01103201403627787,-0.054672939232546014
549.8000000000075,27.64985210720517,0.011095474805069842,-0.05467296061240745
551.2000000000074,27.695267221128987,0.011016364516729465,-0.05467389464234884
552.6000000000074,27.741688263430312,0.011083748330395889,-0.0562454335135385
554.0000000000075,27.787398052726562,0.011110645160452404,-0.057422484167148014
555.4000000000075,27.83348332591369,0.011128925987752166,-0.05738602362973211
556.8000000000075,27.879238818934624,0.011114322190624713,-0.05608943597792404
558.2000000000075,27.924915417172027,0.011120870375576464,-0.05739625149740846
559.6000000000075,27.97031206523716,0.011182862322721853,-0.057420259264063134
561.0000000000075,28.016383171274654,0.011210767279118251,-0.05877506227488993
562.4000000000076,28.062158521824838,0.011233076104903877,-0.0587428996205972
563.8000000000076,28.107957478632635,0.011199331227994345,-0.05865387671758526
565.2000000000077,28.15371337821528,0.011308667107084207,-0.06070468689495101
566.6000000000076,28.19956420675518,0.011308756019312296,-0.06070553621722752
568.0000000000076,28.24509275428225,0.011299459994241009,-0.06070565656258964
569.4000000000077,28.290706201822594,0.011407395686373814,-0.06118892058208303
570.8000000000077,28.336519427588893,0.011447550579195272,-0.06203081238044206
572.2000000000078,28.38221445009782,0.011675205883590169,-0.06197473153824262
573.6000000000078,28.428187644990874,0.012027224961012935,-0.06335714194509023
575.0000000000077,28.473669033086328,0.011999558074939857,-0.06472451060622575
576.4000000000078,28.519434507177717,0.011743705994932154,-0.06334020983263144
577.8000000000078,28.564966073114192,0.011571264384208062,-0.06444546509035831
579.2000000000078,28.610251623577682,0.011465837333270678,-0.06466516430432989
580.6000000000079,28.655964246702055,0.011403460185256245,-0.06595905270867775
582.0000000000078,28.701655919477968,0.011332851146520103,-0.0662496031291937
583.4000000000078,28.747347778227567,0.011282055115994234,-0.06762280182044833
584.8000000000079,28.793027046988392,0.011287628543560961,-0.06862707055609008
586.2000000000079,28.838782994459777,0.01129157608501875,-0.06860718817807765
587.600000000008,28.88384542128595,0.01135771565277686,-0.0672944462993712
589.000000000008,28.92976537134458,0.011377935125389652,-0.06599843821513218
590.4000000000079,28.975154716608323,0.011424153593870522,-0.06731508796059416
591.800000000008,29.02137804586118,0.011407774317661865,-0.06858914210303624
593.200000000008,29.06674396447004,0.011446308969788457,-0.06863721423394509
594.6000000000081,29.112317175585805,0.011444510784966997,-0.07044192371233748
596.0000000000081,29.157842544808815,0.011423045186265711,-0.0716386287074613
597.400000000008,29.203769992929576,0.011516137084065223,-0.07359196661556666
598.8000000000081,29.24967379037724,0.01154199897092788,-0.07398056605291004
600.2000000000081,29.29475365139104,0.011506528857756583,-0.07402910250223727
601.6000000000081,29.341248156421006,0.011574098530117052,-0.07267098432959074
603.0000000000082,29.386517401967208,0.011634018573912922,-0.07288259868508362
604.4000000000082,29.432491184328107,0.011654645022036902,-0.07452675220895344
605.8000000000081,29.47821980815683,0.01170140150382246,-0.07575570590915959
607.2000000000082,29.52394309227136,0.011739513769275284,-0.07852478580164757
608.6000000000082,29.569460559016512,0.011746785077355614,-0.07982435935571175
610.0000000000083,29.61543448096539,0.011767437678724405,-0.07980184975977522
611.4000000000083,29.66117644484768,0.011859488921690205,-0.08113931958757803
612.8000000000083,29.707061657666223,0.011849201162034665,-0.08105670499182338
614.2000000000083,29.75248967570312,0.0119293707037103,-0.08241186531896005
615.6000000000083,29.79875609561288,0.012003472201276325,-0.0811490585470267
617.0000000000084,29.84447222208615,0.012068650440335709,-0.08115567281177505
618.4000000000084,29.890311117941227,0.012094161996258132,-0.07987252326893213
619.8000000000084,29.936262406427502,0.012161982292019589,-0.08104540204934096
621.2000000000085,29.981750903773005,0.012206197846885416,-0.0830560381820078
622.6000000000084,30.027077822423298,0.012243958325248301,-0.08641405732177532
624.0000000000084,30.07377773542918,0.012345034205810429,-0.08643928641814114
625.4000000000085,30.119653245708758,0.01238887265320891,-0.08783199952199539
626.8000000000085,30.165891427406876,0.01241366111732178,-0.08915560506429188
628.2000000000085,30.211877693310658,0.012541389669130173,-0.09041244504777524
629.6000000000085,30.257084412130165,0.012567745305021602,-0.09170403481840594
631.0000000000085,30.303481360482333,0.012664529655403252,-0.09333345786671998
632.4000000000086,30.349838243513346,0.012764818950790622,-0.09437393067992161
633.8000000000086,30.396106085430148,0.012916012473739044,-0.09462796995899225
635.2000000000086,30.44244093666878,0.013000275970601013,-0.09603599364905335
636.6000000000087,30.48825355548886,0.013093037438320316,-0.09530792973964708
638.0000000000086,30.5346669768323,0.013173321302720638,-0.09658676725462101
639.4000000000087,30.580156332714434,0.013281177248267195,-0.09795147978377372
640.8000000000087,30.62732177421021,0.01338704366776196,-0.09911422160374173
642.2000000000087,30.673366732396914,0.013519416369487534,-0.09927702132515037
643.6000000000088,30.71959614241125,0.013602307120245235,-0.1007039262474052
645.0000000000088,30.765900171001338,0.013779726028944355,-0.10276051793374563
646.4000000000087,30.812271165380224,0.013902532460924103,-0.10416946583029585
647.8000000000088,30.858577133231393,0.014089103954639364,-0.1069815318874987
649.2000000000088,30.905034533879086,0.014331737158612889,-0.10889281294166153
650.6000000000088,30.951591940411102,0.014573139836682535,-0.10919048712324297
652.0000000000089,30.997976284680558,0.014837579193772765,-0.11197302360810113
653.4000000000088,31.044571364798657,0.015143572225444902,-0.11305469070850904
654.8000000000089,31.090841458363677,0.0154254232646052,-0.11410423676568371
656.2000000000089,31.13732787044683,0.015756812492431015,-0.11708976870582433
657.6000000000089,31.184103177146948,0.016158822728278052,-0.11867344057284868
659.000000000009,31.230746516266613,0.01655200235759166,-0.12097255217534553
660.400000000009,31.277252433176358,0.016946807598285533,-0.12194918641901609
661.800000000009,31.323722658979026,0.017446331790578768,-0.12447266461890649
663.200000000009,31.37040676280024,0.017849613468394428,-0.12470865623532745
664.600000000009,31.417450097771106,0.018395002373969592,-0.12777316870929667
666.0000000000091,31.464387895894934,0.018932368527508965,-0.13062817969944263
667.4000000000091,31.510647453469453,0.019495128004378533,-0.1344656047720605
668.800000000009,31.557588442179338,0.01999278978932354,-0.13770236440041117
670.2000000000091,31.603859154202908,0.020525032599028898,-0.13797743186810862
671.6000000000091,31.651410078423442,0.021147553653528307,-0.1414810639371069
673.0000000000091,31.698211179093285,0.021736011159454203,-0.14306296911794902
674.4000000000092,31.74514738055059,0.022457944652088956,-0.14663577080318646
675.8000000000092,31.79207143031282,0.02304496273468972,-0.14870255443770475
677.2000000000093,31.83890775957173,0.023725473897940705,-0.1521596275957222
678.6000000000092,31.88583510913995,0.024426315728607245,-0.1553947708226815
680.0000000000092,31.93267780156932,0.025187409383420897,-0.1586631792338551
681.4000000000093,31.97943023034775,0.025957575237103736,-0.161739611495193
682.8000000000093,32.026272557941176,0.02685951077593235,-0.16592449084672012
684.2000000000094,32.07306402770953,0.02766017292410365,-0.17030235032800078
685.6000000000093,32.12066812655289,0.02859220014627218,-0.17458983867791744
687.0000000000093,32.16764646678978,0.029503700153076247,-0.17980961839847964
688.4000000000094,32.214680479010596,0.03037571890941441,-0.18535234754708085
689.8000000000094,32.261968869164065,0.03142678022028702,-0.19113696807804104
691.2000000000094,32.30880538450905,0.03238215913607662,-0.19671584980488888
692.6000000000095,32.35511891217186,0.03347309413027807,-0.19937747445635523
694.0000000000094,32.403262512523675,0.03457853370175596,-0.20514162288503712
695.4000000000094,32.45002925110255,0.035714096961463625,-0.21120743895724559
696.8000000000095,32.49691092296177,0.03682869135891878,-0.21723790736209025
698.2000000000095,32.544561082240236,0.03798386232738947,-0.22279969800703725
699.6000000000096,32.591777715885854,0.03919631416998814,-0.2289021211467741
701.0000000000095,32.638929625915516,0.0404984372931754,-0.23567458072167824
702.4000000000095,32.686602024124284,0.041798643513465586,-0.2406183837254332
703.8000000000096,32.733790615991936,0.043130144470026895,-0.24816636692710858
705.2000000000096,32.781160816582485,0.04451924869363981,-0.256237960342645
706.6000000000097,32.828477988441136,0.045924340159040525,-0.2640337436597804
708.0000000000097,32.875664452543155,0.04734289975223703,-0.2730668202731579
709.4000000000096,32.923570830386595,0.0488828501089194,-0.28191303037968396
710.8000000000097,32.97107367183962,0.0504383217225579,-0.2894744925818884
712.2000000000097,33.018406281198715,0.05201917257412271,-0.29864449287157413
713.6000000000097,33.06612086842491,0.05358110474159858,-0.30792004428965924
715.0000000000098,33.11358497587762,0.05527970339672806,-0.31950504227464194
716.4000000000098,33.16090763450139,0.05698697297780125,-0.32954679935537
717.8000000000097,33.2086979955118,0.058699922997648465,-0.33913369439795815
719.2000000000098,33.256452212063195,0.06047694440326942,-0.3506514968732404
720.6000000000098,33.30399591787601,0.06220987458498109,-0.3611523068425413
722.0000000000099,33.3519196338138,0.0639441938536017,-0.3720455260605604
723.4000000000099,33.3993721630911,0.06585953799118298,-0.3832631031502558
724.8000000000098,33.446829448039935,0.06760087766430631,-0.3959918597166734
726.2000000000099,33.495457471375985,0.06953554272425681,-0.41037748559026
727.6000000000099,33.543028241151205,0.07140682388407606,-0.42343954566916864
729.00000000001,33.59020689509454,0.07321329775140505,-0.43555966949747926
730.40000000001,33.63865655009526,0.07514259297907222,-0.4507001610766679
731.80000000001,33.68667939308497,0.0770422914508033,-0.46584872774641894
733.20000000001,33.73424166964226,0.07892556309420072,-0.48097406859946545
734.60000000001,33.78249985755991,0.08075971426156126,-0.49560481332025574
736.00000000001,33.830069271091254,0.08271818813434453,-0.5105517176980925
737.4000000000101,33.87848532195404,0.08467714609411348,-0.5271425182116332
738.8000000000101,33.92643993848466,0.08652071642071693,-0.5428638775115928
740.20000000001,33.97432151629556,0.0884000468334073,-0.5601217538337551
741.6000000000101,34.02211755468638,0.09018501863353624,-0.5771135733635049
743.0000000000101,34.07023239609703,0.09195758844684597,-0.5950823542331136
744.4000000000102,34.11821310559991,0.09366697433959598,-0.6123910826429153
745.8000000000102,34.16549948431436,0.09546764020660156,-0.631436597590664
747.2000000000102,34.213900391928895,0.09716450542312763,-0.6504424178517354
748.6000000000103,34.26200163099873,0.09888321885496082,-0.6691768893405481
750.0000000000102,34.30992682194897,0.1007356948844547,-0.6889918113970452
751.4000000000103,34.35788802056408,0.10244931127135154,-0.7093612744053814
752.8000000000103,34.40567496750469,0.10424877278311911,-0.727266850507192
754.2000000000103,34.45411632624886,0.10603956121146027,-0.7457247126240532
755.6000000000104,34.502216751347284,0.10792725897141964,-0.7719783130095266
757.0000000000103,34.549807848727546,0.10982321299527126,-0.7935247944269577
758.4000000000103,34.59805081261815,0.11176354344193845,-0.8130324783345486
759.8000000000104,34.646744315256,0.1138411209045779,-0.8375306956851034
761.2000000000104,34.69459177410883,0.11594787981180305,-0.8627147560972332
762.6000000000104,34.742669374286805,0.11808949823008225,-0.8857199725397322
764.0000000000105,34.79089093493162,0.1203210722776783,-0.9086784955647147
765.4000000000104,34.839405523015,0.1225780375515201,-0.9331870976614596
766.8000000000105,34.88782046042635,0.12497880712133005,-0.9596450600591879
768.2000000000105,34.93612568457411,0.12737914146294185,-0.9840304604287553
769.6000000000105,34.98432910487387,0.12982393060360942,-1.0086767288204328
771.0000000000106,35.032849498792544,0.13229563226125957,-1.0345865559831395
772.4000000000106,35.08123665985604,0.134732952586108,-1.063928618289026
773.8000000000106,35.12945640449429,0.13710273751624863,-1.090167862734603
775.2000000000106,35.1776931485625,0.13945063491460635,-1.1142694569848288
776.6000000000106,35.22598411074854,0.14184553141835354,-1.1467213509241674
778.0000000000107,35.27465817433306,0.14411787673658902,-1.1760136300875956
779.4000000000107,35.32255910060759,0.14615491714168116,-1.2053389159202368
780.8000000000106,35.370534439075506,0.14760553367185836,-1.234609436101124
782.2000000000107,35.418171043171526,0.1481383891752893,-1.260681058139852
783.6000000000107,35.464791549939,0.14702490685916153,-1.2875956945500207
785.0000000000107,35.50998744278782,0.14332230422072673,-1.3108156453696722
786.4000000000108,35.55400254109033,0.13631875486313685,-1.33471162797224
787.8000000000108,35.59608907206577,0.1254319218869761,-1.357204906581643
789.2000000000108,35.636449329969146,0.11055074445600972,-1.3771354096409425
790.6000000000108,35.674483956475626,0.09172563562691335,-1.3932919370494403
792.0000000000108,35.71179676802993,0.07092450748670703,-1.405624951473328
793.4000000000109,35.74998060204333,0.05169537147162874,-1.4159473251688723
794.8000000000109,35.789663046360445,0.03616562194953912,-1.4233189296398905
796.200000000011,35.83102994366585,0.024660852365049155,-1.4276218821043756
797.6000000000109,35.87372317353312,0.016700632715616507,-1.4313722380069862
799.0000000000109,35.918158033990906,0.011325755587282181,-1.4325774536456777
800.400000000011,35.96300722923875,0.007841928178814257,-1.4312640250730908
801.800000000011,36.00890840074621,0.005608694570754129,-1.4325613426144912
803.200000000011,36.05475935723105,0.004138847393145292,-1.4330960912893431
804.600000000011,36.10143651859438,0.0031982211775039814,-1.4338913625659586
806.000000000011,36.147979824291404,0.0025481235671653488,-1.4352226491818385
807.400000000011,36.19502554654788,0.0022710909918577625,-1.4351163555269864
808.8000000000111,36.24219214707384,0.0020426839847714623,-1.4365136065219986
810.2000000000111,36.2891696567041,0.0018958450460830403,-1.4378397415044901
811.6000000000112,36.33641717410009,0.0018859008636599867,-1.437840013219045
813.0000000000111,36.38355746789641,0.0018211599750368665,-1.4378429016323935
814.4000000000111,36.43097832779192,0.0018347443574408782,-1.4365316230141332
815.8000000000112,36.477715477523944,0.0018318025619566275,-1.4365297253661993
817.2000000000112,36.52540030445674,0.0017968410183688936,-1.4365309061306846
818.6000000000113,36.572810932595196,0.0017820783379038849,-1.4378031629214831
820.0000000000113,36.6200831639527,0.0017723966156741981,-1.4378318255523936
821.4000000000112,36.66746830476747,0.0018086999097615165,-1.43783161283352
822.8000000000113,36.714424990235045,0.0018595297215632453,-1.438122277026764
824.2000000000113,36.761654364831635,0.0018126502884411519,-1.4378344500119056
825.6000000000113,36.80937483138354,0.0017852566976547211,-1.4378392158553197
827.0000000000114,36.85714682057623,0.0017907018453102198,-1.4391667566523267
828.4000000000113,36.90469545821968,0.0017325282083624528,-1.4391641158932202
829.8000000000113,36.95193400535414,0.0016931752890080379,-1.4391637372276023
831.2000000000114,36.99957696797689,0.0016296581632541211,-1.4378656000379806
832.6000000000114,37.046719910635176,0.0016246497873998698,-1.4378441077166713
834.0000000000115,37.093713596761944,0.0015315520794647423,-1.4378419359851478
835.4000000000115,37.141829688702074,0.0015192670836636953,-1.4371898240359542
836.8000000000114,37.1893450900193,0.0015129568025312248,-1.4365229403912565
838.2000000000115,37.23706574616621,0.0015772385642656532,-1.4365236078581347
839.6000000000115,37.28406525006763,0.0015171338597536124,-1.4379188425832012
841.0000000000116,37.33217384909494,0.001563381011201119,-1.437826121653302
842.4000000000116,37.37954063046333,0.0016223375170092043,-1.4376365047280046
843.8000000000116,37.42713833671936,0.0016191503631300223,-1.4371666271290735
845.2000000000116,37.474860333739784,0.0015489932672953476,-1.4371681050980385
846.6000000000116,37.5220501501688,0.0015763657713291981,-1.4384684912986643
848.0000000000116,37.56993178286343,0.0015494774988023992,-1.4384923512251078
849.4000000000117,37.61691875594059,0.00148089851455201,-1.438490726970599
850.8000000000117,37.66541984775963,0.0014365427002396257,-1.4391911809154294
852.2000000000116,37.712917811467534,0.0014431863091500206,-1.4395189211312527
853.6000000000117,37.76085202049898,0.0014519589972979384,-1.4401573500637141
855.0000000000117,37.80835241547041,0.0014340010286149445,-1.4402301086315674
856.4000000000118,37.85595617957625,0.0013686121127558307,-1.4388364471606678
857.8000000000118,37.90356816024907,0.001318601585983105,-1.4389655463148472
859.2000000000118,37.95116693834589,0.0013678734003521008,-1.4378403566397253
860.6000000000118,37.99910413557549,0.0013425738536935947,-1.4378305457630631
862.0000000000118,38.04686624614152,0.001312510253877252,-1.438282115992422
863.4000000000119,38.09442899386858,0.0013256831253084175,-1.4378352956015874
864.8000000000119,38.14218947078479,0.0013239437015434771,-1.4378378493360913
866.2000000000119,38.18990705998593,0.0012874991308015546,-1.4391298209857837
867.600000000012,38.23761663929218,0.0012962949563315174,-1.439138717142498
869.0000000000119,38.28519639820586,0.0012244032788720424,-1.4391388295258025
870.4000000000119,38.33320047687287,0.0012437570268612475,-1.439097884844756
871.800000000012,38.381076512364025,0.0012273014986821235,-1.4404677492626092
873.200000000012,38.42846224252385,0.0011682086869269047,-1.4404653407306967
874.600000000012,38.476453688728306,0.0011612461698758472,-1.4416803748862037
876.000000000012,38.52435951264507,0.0011098017061334023,-1.4408016621883348
877.400000000012,38.57185683332554,0.0010251915955919975,-1.4408110941515702
878.8000000000121,38.61968431388581,0.0010835836596927995,-1.4408110282859639
880.2000000000121,38.667388852189134,0.0010046524085947604,-1.4407370872081344
881.6000000000121,38.715249053436196,0.0010452059644161273,-1.4421159131530317
883.0000000000122,38.76281085331706,0.0010419765740195645,-1.441792817300751
884.4000000000121,38.81063386827899,0.001041483073353059,-1.4417182136641884
885.8000000000122,38.85841717362352,0.0012180047734833069,-1.4404625004306695
887.2000000000122,38.90622530051239,0.0014716859236941875,-1.440463123762271
888.6000000000122,38.95382568199149,0.0016613300845232867,-1.4404631205820806
890.0000000000123,39.001648423906595,0.0019087376694023744,-1.4404628894875486
891.4000000000123,39.04899740266276,0.002107503628913352,-1.4417789292430996
892.0000000000123,39.06954447544549,0.0021620614158485707,-1.441790776996271