File: 01_Data/Concrete_Block/STA/N2/30K_min/Concrete_Block_STA_N2_30KData_230829_R1.csv
##Temp./Â°C,Time/min,DSC/(mW/mg),Mass loss/mg
29.0,15.620206311863006,0.03690261869166234,-0.0033288750696560676
30.40000000000002,15.81672837039408,0.08279541098327936,-0.001803467658184843
31.80000000000004,15.951614237397774,0.11709680329163463,-0.0020464756603169043
33.20000000000006,16.060279550667655,0.1507215851035748,-0.0018949809156287856
34.60000000000008,16.15266209610513,0.1756625281876345,-0.0020210893323899803
36.0000000000001,16.235053936569024,0.20163921121817951,-0.0011452663243147754
37.40000000000012,16.313392342043556,0.22346197045004712,-0.0007818653676232579
38.80000000000014,16.38569713507536,0.24460320265283508,-0.002076041325661304
40.20000000000016,16.4537123511028,0.266959414197937,-0.002089194362828728
41.60000000000018,16.518590499419794,0.2839824782439806,-0.0023848394170160603
43.0000000000002,16.581085564188715,0.30115537983974305,-0.0026476522090757015
44.40000000000022,16.643704888624395,0.3147130329111498,-0.0015561470008531586
45.80000000000024,16.70259254823804,0.3306228217712215,-0.003217895468666132
47.20000000000026,16.761430523527437,0.3429209673694149,-0.0028469128139501088
48.60000000000028,16.818180263912517,0.356651507114369,-0.00356728390578942
50.0000000000003,16.874093983997604,0.3681401122128196,-0.0029777623482254434
51.40000000000032,16.929591375514978,0.3814885230919123,-0.0033009040286660074
52.80000000000034,16.98326361101125,0.39149754368412104,-0.005274421405930596
54.20000000000036,17.036719769035184,0.40398076401340566,-0.005764657668196893
55.60000000000038,17.08987764451039,0.4151684724379878,-0.0035180132268974873
57.0000000000004,17.142059950766676,0.42487064272817254,-0.00500889959185935
58.40000000000042,17.19424403808876,0.4375491371877791,-0.004367031131619292
59.80000000000044,17.245437195053164,0.44710671149564507,-0.006540844113068989
61.20000000000046,17.296930365226757,0.45900483582343266,-0.0060974937823252695
62.60000000000048,17.34778328083013,0.46818121722710915,-0.005554934709284254
64.0000000000005,17.39661256575587,0.4757814551977204,-0.006531947620866951
65.40000000000052,17.44794503491727,0.483743213277692,-0.007689318157063418
66.80000000000054,17.497721014165535,0.49347539295826337,-0.008140358246750079
68.20000000000056,17.546939886355243,0.497586411558091,-0.008098570648720216
69.60000000000058,17.596729608771497,0.5047441684912457,-0.007885702784178328
71.0000000000006,17.64637098062289,0.5061708825819065,-0.007797253393606152
72.40000000000062,17.69517009668985,0.5122731623759589,-0.00778680820719746
73.80000000000064,17.744305655906178,0.5130847382425826,-0.009130348383986853
75.20000000000066,17.793490083354595,0.518962797089643,-0.010417088666092145
76.60000000000068,17.84223740577337,0.520466216295938,-0.010443000684331682
78.0000000000007,17.890936336547636,0.5232324945962712,-0.01069457657903028
79.40000000000072,17.939376368635248,0.5264845930709888,-0.010450918334062642
80.80000000000074,17.987703206802735,0.5295157697143824,-0.011743888338922925
82.20000000000076,18.036399689918397,0.5333387178881215,-0.012408676089798565
83.60000000000078,18.083424544987306,0.5372344887542123,-0.011746620265857377
85.0000000000008,18.1323191907307,0.5417926148091166,-0.011782627874150187
86.40000000000082,18.18008985027761,0.5449466420169313,-0.013131006414935698
87.80000000000084,18.227533890392653,0.5463654864612926,-0.013117739228901026
89.20000000000086,18.275221191486075,0.5490394341146371,-0.013068853561003735
90.60000000000088,18.322827154298153,0.5521172720547717,-0.014366562372253977
92.0000000000009,18.37011024317279,0.5529867919367158,-0.014390431002591075
93.40000000000092,18.417175003188728,0.5577669912345993,-0.014353632565215158
94.80000000000094,18.464395154984096,0.5585293999528097,-0.015710841461885394
96.20000000000095,18.511295463356113,0.5599524423235707,-0.01700822326591167
97.60000000000097,18.557569780307123,0.5643909028660947,-0.017020207552617794
99.000000000001,18.6047486490573,0.5630824025455088,-0.017020706040374645
100.40000000000101,18.651827970883073,0.5688447380278491,-0.018374532036029123
101.80000000000103,18.697836660701753,0.5698611848637645,-0.017473659905439476
103.20000000000105,18.744455255187336,0.5707664798527257,-0.01834101862735471
104.60000000000107,18.790936613617376,0.5712910864918911,-0.018339936056945394
106.0000000000011,18.837038653615526,0.5744982082030159,-0.018340620446674283
107.40000000000111,18.883598172502587,0.5773822528054275,-0.018913237583482623
108.80000000000113,18.92998120367735,0.5749949769423365,-0.019659103274878742
110.20000000000115,18.976010529004313,0.5772412549944334,-0.019660021082029466
111.60000000000117,19.02237728538564,0.5830963684157778,-0.01966001733515288
113.0000000000012,19.068529023481503,0.5844342155553508,-0.019661750156084068
114.40000000000121,19.114463114735145,0.5840049326149037,-0.020971522326700853
115.80000000000123,19.160310208443256,0.5879268894618946,-0.02096993709097905
117.20000000000125,19.206010905723314,0.5906300852192522,-0.020996007185712706
118.60000000000127,19.252222598374857,0.592642285262893,-0.022290538540376215
120.0000000000013,19.298195337789362,0.5934769585502695,-0.023475966935404546
121.40000000000131,19.343618385805478,0.595460934132801,-0.02219798751218649
122.80000000000133,19.389658081619967,0.5959716143582519,-0.022291569732292515
124.20000000000135,19.434493061413303,0.598206055037533,-0.023260678837595083
125.60000000000137,19.48034256836896,0.5961131551758834,-0.023609910097561304
127.00000000000139,19.525422713745662,0.5968666423686528,-0.023610019942492233
128.4000000000014,19.57032986620206,0.5962110843505213,-0.023610020001064047
129.80000000000143,19.615928297882544,0.5934602373357285,-0.023610019965529805
131.20000000000147,19.660797948361232,0.5919894143417583,-0.023609972995502382
132.60000000000147,19.70558696794209,0.5943722020586087,-0.02361577849588148
134.00000000000148,19.75016205908527,0.5938280519749551,-0.024919154731604554
135.4000000000015,19.795062914651265,0.5914045078930477,-0.026248612360516344
136.80000000000155,19.839526657695085,0.5918990403349299,-0.02625018679043256
138.20000000000155,19.884142795691492,0.588279454087417,-0.02625018821480829
139.60000000000156,19.928835068253687,0.5887918887897742,-0.026209461198031025
141.0000000000016,19.973036797879825,0.5867985880683305,-0.027071253455646094
142.40000000000163,20.017437979141697,0.5861008099649645,-0.02690009675811611
143.80000000000163,20.061324529646935,0.5860186377807404,-0.026899902640367568
145.20000000000164,20.10537513707748,0.5863396715200007,-0.026899518269775324
146.60000000000167,20.14962556857682,0.5865512193506139,-0.02824386863435091
148.0000000000017,20.193779408340234,0.5845196901448695,-0.02822058745474143
149.4000000000017,20.237660906023393,0.5855305893662401,-0.028220527568962428
150.80000000000172,20.28135180303162,0.5842255066339866,-0.028073993033158384
152.20000000000175,20.324526720196136,0.5859511100615133,-0.02821808634805656
153.60000000000178,20.368982475431896,0.5847924737324377,-0.0282199022392704
155.0000000000018,20.412677865762255,0.5836769265130957,-0.028911268399025136
156.4000000000018,20.45648979588264,0.5860454491121612,-0.028610382505884324
157.80000000000183,20.499669076606196,0.5822010950112229,-0.02822068942033118
159.20000000000186,20.543755888317804,0.5827095003379269,-0.028220089618204547
160.60000000000187,20.587413744534658,0.5863582325128402,-0.02826389198935164
162.00000000000188,20.630612346036774,0.585077503096068,-0.029539771267463433
163.4000000000019,20.674217688134522,0.5835874254228852,-0.030836189331846953
164.80000000000194,20.717958549055677,0.5834179424181587,-0.03085926402856387
166.20000000000195,20.761055233090588,0.5834446919457303,-0.03004446617951606
167.60000000000196,20.804934894927452,0.582113961890173,-0.02954022266693812
169.000000000002,20.84828992586691,0.5831423015854366,-0.03201894480247658
170.40000000000202,20.891619515595295,0.5823051843246403,-0.0321902269278449
171.80000000000203,20.93495554435856,0.5834698552898328,-0.03085643741910049
173.20000000000203,20.978202510568167,0.581288729047958,-0.03100720059319606
174.60000000000207,21.02174882328195,0.5821709824851805,-0.03184992829919375
176.0000000000021,21.064513883127074,0.581465644926999,-0.031849947020083924
177.4000000000021,21.107801241302077,0.5802907561083486,-0.0320767381141982
178.80000000000211,21.1509931097757,0.5820656917890641,-0.03315867968914965
180.20000000000215,21.19396919805153,0.580510396084603,-0.03322465300375699
181.60000000000218,21.236572888726492,0.5817701585667566,-0.031147117531107327
183.0000000000022,21.279939692557672,0.5822820386116456,-0.031186590222735955
184.4000000000022,21.322475147271287,0.5800894357586063,-0.03248693036243866
185.80000000000223,21.365567528360025,0.5821337943486354,-0.03250107585858997
187.20000000000226,21.40818860957638,0.5821824990489474,-0.03307657278246179
188.60000000000227,21.450926804012926,0.5821227968685531,-0.03381921112308195
190.00000000000227,21.4934495082093,0.5870581512840336,-0.033819956864226786
191.4000000000023,21.536352011269276,0.5850517472140483,-0.03382510884058787
192.80000000000234,21.578741189348293,0.5854942592976917,-0.03250215109012844
194.20000000000235,21.62172011941693,0.5865295370748792,-0.03307826054614438
195.60000000000235,21.663962612975826,0.5875890323720623,-0.033818186623885804
197.0000000000024,21.706586767110732,0.588679081329099,-0.03381994403054778
198.40000000000242,21.74907742456006,0.5895379836135102,-0.03381917000313628
199.80000000000243,21.79147275416111,0.589987409979074,-0.0334990076350512
201.20000000000243,21.833898727213466,0.5915187200698011,-0.033496266051858736
202.60000000000247,21.876210343378908,0.5926019221825285,-0.03416223143426178
204.0000000000025,21.918567583295367,0.5929590576044189,-0.034483780592893254
205.4000000000025,21.960953791617047,0.5944331075334685,-0.03448012456129135
206.8000000000025,22.00340309952901,0.5975458889718062,-0.03447989559522391
208.20000000000255,22.045940618060325,0.5976587096217334,-0.03444732416420093
209.60000000000258,22.087819028367004,0.5974920968862633,-0.035802303349633746
211.0000000000026,22.13033118415548,0.5985082105014543,-0.03580020541163442
212.4000000000026,22.172382050938957,0.5997073473211915,-0.035807541191918535
213.80000000000263,22.214956628055823,0.598183501629368,-0.03468389855525089
215.20000000000266,22.25730736251236,0.6019355033367647,-0.0348098514832853
216.60000000000267,22.299437030652037,0.6032695045714405,-0.03481010395396611
218.00000000000267,22.341638061593336,0.6033110636372908,-0.03481010399642237
219.4000000000027,22.384185953346986,0.6044450767427726,-0.03481010156032882
220.80000000000274,22.426118452097707,0.6063953435292596,-0.034809612943763835
222.20000000000275,22.46811767566971,0.604570156371459,-0.03475557775441951
223.60000000000275,22.510965904897102,0.6074376694523793,-0.03613184080167864
225.00000000000279,22.552921832260107,0.6080545446265876,-0.03688634819575265
226.40000000000282,22.59428766976895,0.6109788401463909,-0.03744987474145889
227.80000000000283,22.63736873787627,0.6104366353612846,-0.03744987138282774
229.20000000000283,22.679434735605525,0.6110284794328238,-0.03744990350312749
230.60000000000286,22.721547648223197,0.6120684229981601,-0.03745652031378732
232.0000000000029,22.763851978332177,0.6143902321300159,-0.036132792687765036
233.4000000000029,22.806404408805324,0.6187970992530392,-0.03612962225676286
234.8000000000029,22.848096190122384,0.6174531911611997,-0.03610307535301471
236.20000000000294,22.8907124003439,0.6225220777569921,-0.03746919175055741
237.60000000000298,22.933024173274067,0.6242340501219084,-0.038761958645464833
239.00000000000298,22.975225314211034,0.624751658596815,-0.03876008439112111
240.400000000003,23.01789408591066,0.6270833245984293,-0.03875896820098346
241.80000000000302,23.060119729196252,0.6263012021521783,-0.03828957729679372
243.20000000000306,23.102316758681415,0.6266691715139799,-0.03743980521255885
244.60000000000306,23.14445943447392,0.6292188136570372,-0.037440229261751945
246.00000000000307,23.186401143960794,0.6307318262782028,-0.037467987561607075
247.4000000000031,23.228817211439207,0.6315313584423103,-0.03843010517557177
248.80000000000314,23.272304584697387,0.6326891030906165,-0.038755842892127745
250.20000000000314,23.314295105415933,0.6340384513166258,-0.040066865866233314
251.60000000000315,23.35667015692594,0.6354015189425585,-0.04007844812328676
253.00000000000318,23.39944938964332,0.6348754432005239,-0.038709048684193004
254.40000000000322,23.44184856360708,0.6377693916905888,-0.03875959898993919
255.80000000000322,23.483982763894133,0.639135711436182,-0.038761855496516784
257.20000000000323,23.526285510562627,0.64035939010104,-0.03970677724922789
258.60000000000326,23.56902043351225,0.6414822040227034,-0.04073474702154556
260.0000000000033,23.6114061811372,0.6426203054278251,-0.04074035428773426
261.4000000000033,23.65395900434178,0.6443309512177903,-0.04074008188330058
262.8000000000033,23.6963438904715,0.6435924744106254,-0.0407401271315897
264.20000000000334,23.739019421113937,0.6474002057475411,-0.0407404972624148
265.6000000000034,23.781313652432857,0.6465633868830349,-0.041431327437857046
267.0000000000034,23.82374740185529,0.6478953530176433,-0.041399815623130554
268.4000000000034,23.866076476571045,0.648574094584622,-0.04246695091758035
269.8000000000034,23.90842634133808,0.6488265099442025,-0.042714415065840505
271.20000000000346,23.95103897976218,0.6508380425803224,-0.041411605330659906
272.60000000000343,23.993677973033076,0.6511377533336947,-0.041400095833552975
274.00000000000347,24.03596868068085,0.6511583944208371,-0.04140003291666128
275.4000000000035,24.078334435715583,0.6525146109207837,-0.04140095386767184
276.80000000000354,24.12076043488297,0.6516316566714022,-0.04270120630283314
278.20000000000357,24.162430313584462,0.6530295462071838,-0.04274599905884502
279.60000000000355,24.205662431470177,0.652922158649042,-0.04370479388392434
281.0000000000036,24.247717007297773,0.653063919544299,-0.04370020560241672
282.4000000000036,24.290224022178545,0.6525823958845093,-0.04370005010954614
283.8000000000036,24.33289749108816,0.6522308523404404,-0.04358462776875083
285.2000000000036,24.375137702556135,0.6548058463675727,-0.04336460218802429
286.60000000000366,24.417609691514933,0.6543724267399104,-0.04251055432565165
288.0000000000037,24.46016625721534,0.6548735202230433,-0.04212000606710875
289.40000000000373,24.502577566871544,0.6544322126247525,-0.04205983921390244
290.8000000000037,24.544304449191113,0.6558190696404925,-0.04206016124511214
292.20000000000374,24.587459894290507,0.6549899870850864,-0.042292741337863315
293.6000000000038,24.62989432450565,0.6542944669312427,-0.043049627943750224
295.00000000000375,24.672393028831646,0.654217936169352,-0.043055126918515096
296.4000000000038,24.71487205777742,0.6567225447005881,-0.04206066635449268
297.8000000000038,24.75702594001607,0.6561808434165266,-0.04205016790861915
299.20000000000385,24.7995470674768,0.6578066073867451,-0.042050062577703606
300.6000000000039,24.842160930708815,0.6592236305653549,-0.04204986930781063
302.00000000000387,24.88464205107925,0.6599322943520901,-0.043430850973091406
303.4000000000039,24.92719044396554,0.6596241480100837,-0.0433708046490362
304.80000000000393,24.969629007441036,0.6602837699095762,-0.043421591482650346
306.2000000000039,25.01218307121829,0.6620739476270489,-0.04205252438218254
307.60000000000394,25.054858241076182,0.6636655473932161,-0.041999805477294316
309.000000000004,25.097241040294325,0.6643007835472239,-0.044692505930576054
310.400000000004,25.139817109472755,0.6657430316377481,-0.04468986518576257
311.80000000000405,25.18253138370278,0.6673980138490699,-0.04468983252885428
313.200000000004,25.224758269616515,0.6680010471461716,-0.044689693229458705
314.60000000000406,25.26741318974241,0.6688556618327297,-0.04531911025814539
316.0000000000041,25.30997682381291,0.6703998860686842,-0.04600573016968079
317.40000000000407,25.352565150271666,0.6708711028586666,-0.044695831845771306
318.8000000000041,25.395307032801032,0.670959684805633,-0.04468981848900455
320.20000000000414,25.437412437513107,0.6717175836894486,-0.0446898318947464
321.6000000000042,25.48021887123999,0.6705949827874527,-0.04468983330409637
323.0000000000042,25.522837629745947,0.6717891494612198,-0.04469078089752099
324.4000000000042,25.56534130710204,0.6716134383790023,-0.045111871816239546
325.8000000000042,25.608023403541438,0.6715358658473252,-0.045349834240310916
327.20000000000425,25.650398794778628,0.6713070801716728,-0.045350164875473276
328.60000000000423,25.693141311553017,0.670175164826968,-0.04535228637920197
330.00000000000426,25.73559591476407,0.6702003432685519,-0.04568257014350641
331.4000000000043,25.778340974978693,0.6719330225167894,-0.04568012706796942
332.80000000000433,25.820965238632464,0.6727854992876792,-0.04568011403322236
334.20000000000437,25.863078885913428,0.6731953222435261,-0.04568011399941696
335.60000000000434,25.906081038578606,0.6746842979655217,-0.04568011387280091
337.0000000000044,25.949501432320446,0.6749390341971803,-0.045680119414994724
338.4000000000044,25.99181419297647,0.6749276526644641,-0.04569043249792282
339.8000000000044,26.034537528808425,0.6751485015275032,-0.0463228684936543
341.2000000000044,26.077279438321533,0.6733395701540623,-0.046339962111884514
342.60000000000446,26.120182059121092,0.6729593233588211,-0.04633999703739944
344.0000000000045,26.16308541745494,0.6746434628072723,-0.0463391374064801
345.4000000000045,26.205507499636706,0.6741935926252677,-0.045934689655348304
346.8000000000045,26.248561932356605,0.6735546944035752,-0.04457932738155401
348.20000000000454,26.29144024082384,0.6741042735202557,-0.0462220414367045
349.60000000000457,26.334387743498283,0.673901488340374,-0.04639541528756963
351.00000000000455,26.37752094677704,0.6727393478416914,-0.047441269060942926
352.4000000000046,26.42026890108833,0.6738572663365853,-0.04744006712753368
353.8000000000046,26.462841058450582,0.6726322992547218,-0.04744006997286254
355.20000000000465,26.50627025271072,0.6771433261136088,-0.047440070038903936
356.6000000000047,26.549110643352716,0.6771551747467071,-0.04744008107597919
358.00000000000466,26.591912757464147,0.6768186561523349,-0.04744102644182302
359.4000000000047,26.635249052101454,0.6787798583628759,-0.04852134395947294
360.80000000000473,26.678403605248647,0.6792386536370517,-0.048420525632542066
362.2000000000047,26.7210572300399,0.6797992996195423,-0.048420070541242755
363.60000000000474,26.76396032437613,0.6786216975826163,-0.048420069997062054
365.0000000000048,26.806707471457443,0.6771383984423062,-0.04842006999998327
366.4000000000048,26.850150504306235,0.6773656226556012,-0.04842007000000015
367.80000000000484,26.89341661971499,0.6786245036061683,-0.04842006999998327
369.2000000000048,26.936553720887122,0.6794622582453846,-0.048420069996286674
370.60000000000485,26.97983580395454,0.678229639311391,-0.04842007032094342
372.0000000000049,27.022885016612943,0.675907551281389,-0.048420465983736616
373.40000000000487,27.06601573504721,0.6760070019331437,-0.04852239908760536
374.8000000000049,27.10938546369222,0.675529710753912,-0.04710711886657171
376.20000000000493,27.152698237994453,0.6758866469077556,-0.049801707272071116
377.60000000000497,27.195966516099546,0.6750060831942392,-0.05016944048506522
379.000000000005,27.23929242512603,0.6764114428246011,-0.05017007609421986
380.400000000005,27.282562190268866,0.6764260941282344,-0.05017007600672363
381.800000000005,27.32558846307492,0.6774220007740077,-0.05017007600389567
383.20000000000505,27.369169689368576,0.6771440767137337,-0.05017007600012802
384.600000000005,27.412539734898676,0.6765960344596335,-0.05016972708528966
386.00000000000506,27.45585407553792,0.6774319648627384,-0.05121593357536103
387.4000000000051,27.499358162155776,0.6780689913016646,-0.05148989510430413
388.8000000000051,27.542677897530357,0.677088050368422,-0.05148979632998918
390.20000000000516,27.586564299723246,0.6758323714451236,-0.05166015180952899
391.60000000000514,27.63010778688213,0.676295231133811,-0.052148817128443437
393.0000000000052,27.67276887991772,0.6783193460118443,-0.05214984364623909
394.4000000000052,27.71673811587971,0.6771457734033559,-0.05214984400953604
395.8000000000052,27.7604755034341,0.6786217769751655,-0.05214984400003253
397.2000000000052,27.803781893106347,0.677836551033232,-0.05214984400001299
398.60000000000525,27.847547564448035,0.677562131096518,-0.05214984395572442
400.0000000000053,27.890985950197376,0.6781922075918814,-0.052149831070626984
401.4000000000053,27.934724082647875,0.6769071181631532,-0.05215051806793314
402.8000000000053,27.978129263054615,0.6795142240224878,-0.05247089164621821
404.20000000000533,28.022135489297266,0.6768215953976852,-0.05247981469408414
405.60000000000537,28.06509938373812,0.6775459577461268,-0.05247980975237976
407.00000000000534,28.109264429346535,0.6763209724934073,-0.05248022133235564
408.4000000000054,28.152848996371425,0.6786228468068628,-0.05380750101747145
409.8000000000054,28.196405819568827,0.6781708835271587,-0.05379985118648145
411.20000000000545,28.24053739117145,0.6810100591291682,-0.05334730667437393
412.6000000000055,28.284117845894126,0.6818741018547102,-0.05248104429694278
414.00000000000546,28.327996526274415,0.6863418804930717,-0.053718740488511774
415.4000000000055,28.37167832088894,0.6890055589118907,-0.0538004613911629
416.8000000000055,28.415422999017,0.6916721325981084,-0.05380001193042494
418.2000000000055,28.459298396422575,0.6931989033325867,-0.05380001000717494
419.60000000000554,28.50343477962285,0.697014403166867,-0.05380006741808385
421.00000000000557,28.547121373877587,0.7038375244455879,-0.05381141003339218
422.4000000000056,28.59102521885591,0.7093107137712257,-0.055110033339574205
423.80000000000564,28.63504319991499,0.7134379095342462,-0.05512011745628209
425.2000000000056,28.678980299901053,0.7213083210013104,-0.05512017595913088
426.60000000000565,28.722838849216938,0.7269032234375238,-0.055120336133853254
428.0000000000057,28.766388425309025,0.7335918533149335,-0.05515711756019703
429.40000000000566,28.81112292224968,0.7390348152213727,-0.05479042181280791
430.8000000000057,28.85499322724602,0.7396989221340471,-0.05478983913184399
432.20000000000573,28.899139386773903,0.7385527142631224,-0.054789836035693984
433.60000000000576,28.942752402099682,0.7380975306181016,-0.054789853246177245
435.0000000000058,28.986895391837283,0.7307596738360186,-0.0547894396380717
436.4000000000058,29.030793770350115,0.7265358040360387,-0.05643507704375539
437.8000000000058,29.074968018354813,0.7223012540191578,-0.05643007954902757
439.20000000000584,29.118823589704167,0.716553257759923,-0.056430039042376645
440.6000000000058,29.16336445775605,0.7105871629045274,-0.05647107712291399
442.00000000000585,29.207056112919673,0.7068994338906932,-0.055127316323759334
443.4000000000059,29.251164600062697,0.70168637733548,-0.056236657248804445
444.8000000000059,29.295303350634672,0.7010955385513263,-0.05769969859348034
446.20000000000596,29.339480488710237,0.7001546152678513,-0.057750020468322116
447.60000000000593,29.38384761537987,0.6985122198744678,-0.05766374300804067
449.00000000000597,29.42808281120331,0.6984409285751757,-0.05907090861010955
450.400000000006,29.472414603904273,0.69477384243158,-0.05838897176755031
451.800000000006,29.51663341251475,0.6992459162019632,-0.05840972360858743
453.200000000006,29.560823823825427,0.6983699925358389,-0.058409854843362474
454.60000000000605,29.605106198824792,0.69930533941585,-0.05854857603213626
456.0000000000061,29.649633649353227,0.7003754698790409,-0.058739637770433006
457.4000000000061,29.69439015872719,0.6988681796587806,-0.05873982172304304
458.8000000000061,29.738399268489392,0.7019017452796374,-0.05873988595522528
460.2000000000061,29.782270960251218,0.6989609423842298,-0.05938222634887813
461.60000000000616,29.826370679817067,0.6996389395084243,-0.06005906059254995
463.00000000000614,29.871580861091434,0.700402878326134,-0.060061289425028086
464.4000000000062,29.91629197328859,0.6993067306419674,-0.059709040068574026
465.8000000000062,29.96076719421465,0.7001752869154918,-0.05905221459463572
467.20000000000624,30.00533849452019,0.7007754261343536,-0.05907005424877898
468.6000000000063,30.049719184892194,0.7003843894667604,-0.05907016049062097
470.00000000000625,30.094171877155873,0.702034713646733,-0.05907100444476088
471.4000000000063,30.13870277692399,0.7021451723083664,-0.05969048817505129
472.8000000000063,30.183194386740116,0.7044148961650689,-0.060389215729778734
474.2000000000063,30.227918829036184,0.704611361806417,-0.06042367286902106
475.60000000000633,30.272459755881414,0.7030409028364427,-0.0587267233602522
477.00000000000637,30.317093569071126,0.7021498362479373,-0.05958562358088493
478.4000000000064,30.361714666002353,0.7039860507225948,-0.061897947854333335
479.80000000000643,30.40622837198241,0.7030187004246611,-0.06322724524464318
481.2000000000064,30.450779703740672,0.7047562991143081,-0.062041919308115645
482.60000000000645,30.495783124930494,0.7071159838530132,-0.06308266444935562
484.0000000000065,30.540144458423622,0.7051178444848012,-0.06323975472692744
485.40000000000646,30.584958347798523,0.7080170778472357,-0.06268901166417606
486.8000000000065,30.629734177378886,0.7086074489961848,-0.06192022307787903
488.2000000000065,30.674351055728366,0.7109032611387254,-0.061920180673399994
489.60000000000656,30.719328315562127,0.7128393968427168,-0.06192017999905408
491.0000000000066,30.763505112660287,0.7156403238182442,-0.061920178732794096
492.40000000000657,30.808307500904366,0.7139156115905168,-0.061920141776698134
493.8000000000066,30.85327023479642,0.7158521374426714,-0.06213282374651952
495.20000000000664,30.89804591324297,0.7171413290187207,-0.06390562381293208
496.6000000000066,30.942843376214498,0.7171326425930172,-0.06389995672699067
498.00000000000665,30.986828429596862,0.7193831622032425,-0.06390165304472273
499.4000000000067,31.032122027412314,0.7174546468601843,-0.06498455507189949
500.8000000000067,31.0765193565239,0.7193880854504209,-0.06489048615123982
502.20000000000675,31.12181510677022,0.7203713546118902,-0.06487182399355262
503.60000000000673,31.166822885552055,0.7195336211547809,-0.06522129637771545
505.00000000000676,31.21137653123059,0.7198259994849939,-0.06522011524076543
506.4000000000068,31.25636592936907,0.7194506421091517,-0.06522186698945998
507.8000000000068,31.30136475990313,0.7234886170490853,-0.06636393547079766
509.2000000000068,31.34592607352005,0.7204020354226639,-0.06653980719036312
510.60000000000684,31.391076035413075,0.7249963206482481,-0.06653988212749162
512.0000000000068,31.435733282359813,0.7247394284045946,-0.0665398820005727
513.4000000000069,31.480601940173273,0.7256021310833145,-0.06653988199969518
514.8000000000069,31.525941325223382,0.7284570731356967,-0.0665398817867624
516.2000000000069,31.570568736581368,0.7297950213210735,-0.06653992326944547
517.600000000007,31.615393258136304,0.7295491015863855,-0.06664897105410184
519.0000000000069,31.660407347573237,0.7331526779123293,-0.0678490313038278
520.4000000000069,31.70498041553327,0.7341098917969766,-0.06785009019622557
521.800000000007,31.750399016912382,0.7381539433652945,-0.06785009800752295
523.2000000000071,31.79561944879489,0.7382110403842621,-0.06785009798679908
524.6000000000071,31.84045059641559,0.7425666948870244,-0.06785010037034223
526.000000000007,31.88544214377265,0.7430787032026988,-0.06785196078488465
527.4000000000071,31.930532408177722,0.7476099528392128,-0.06894052083741897
528.8000000000071,31.975684658127335,0.7505948994371767,-0.06916976761828941
530.2000000000071,32.0207241138146,0.7522846997183302,-0.06917017355229049
531.6000000000072,32.0660078390052,0.7557289402238805,-0.06957171911685123
533.0000000000072,32.111282011741736,0.7559609848007958,-0.07048934655227512
534.4000000000071,32.156397110550685,0.7563011928355952,-0.0699137744503866
535.8000000000072,32.20144892125252,0.7569115730596251,-0.0692666921889673
537.2000000000072,32.2467907778318,0.7604494400547004,-0.07049176183929795
538.6000000000072,32.29214626704595,0.7610903879133661,-0.07062302826476818
540.0000000000073,32.33759364814184,0.7637018337619998,-0.07180118468305974
541.4000000000073,32.38228809603281,0.7690332881361799,-0.07180007333648186
542.8000000000073,32.428130011302386,0.7715737954884585,-0.07198150430762196
544.2000000000073,32.47408805183606,0.7713529627533873,-0.07311819479461734
545.6000000000073,32.51957676696846,0.7743155200305185,-0.0731197037207032
547.0000000000074,32.56489251324115,0.7761005268529939,-0.07427563530687253
548.4000000000074,32.610550046779935,0.7772626530217064,-0.07312109494200669
549.8000000000075,32.65625471109485,0.7802194911028206,-0.07420717318174619
551.2000000000074,32.70206256049028,0.7817953587303912,-0.074440386648297
552.6000000000074,32.747125670917484,0.7876465362971428,-0.07443995124171376
554.0000000000075,32.79331336513859,0.7887438520824592,-0.07443974643523488
555.4000000000075,32.83923314849218,0.7891284955605802,-0.07444184591043124
556.8000000000075,32.884747306179825,0.7971008920686995,-0.0757636215829467
558.2000000000075,32.930868041905654,0.7989229042673431,-0.07576010549983758
559.6000000000075,32.976437931544325,0.798530651900753,-0.07575653176689334
561.0000000000075,33.02226027266088,0.8049079220063929,-0.0771178821044125
562.4000000000076,33.06824005029006,0.8106688349472001,-0.07706974618754048
563.8000000000076,33.1132459933342,0.8100507150892615,-0.07743908028835023
565.2000000000077,33.160046349652674,0.8145030896943419,-0.07839000736720658
566.6000000000076,33.20603036131698,0.8202033549113419,-0.078384486573424
568.0000000000076,33.251902873602965,0.8208260095000754,-0.07976074039100922
569.4000000000077,33.297794373881146,0.8303876711657221,-0.08236268324537166
570.8000000000077,33.343691457158286,0.8354265161504835,-0.08104251674797114
572.2000000000078,33.39003854862435,0.8502952911259849,-0.0810300545202085
573.6000000000078,33.43601498934549,0.875901032691105,-0.0810317428899534
575.0000000000077,33.48225316827703,0.8747313928434188,-0.08220894418134828
576.4000000000078,33.528013168771864,0.861875712702318,-0.08135563261339573
577.8000000000078,33.57404043439417,0.8546785347071252,-0.08267648106035219
579.2000000000078,33.619881399420024,0.8511135574024451,-0.08265772942946059
580.6000000000079,33.665687381609416,0.8468317040917339,-0.08398826665493297
582.0000000000078,33.71169257898136,0.8415034736589075,-0.0853895525417041
583.4000000000078,33.75758426990192,0.8418425493345755,-0.08530025779394323
584.8000000000079,33.80353018595113,0.8425069158000655,-0.08521389194926243
586.2000000000079,33.84936363285454,0.8452033946147508,-0.08662028210975192
587.600000000008,33.89556838643326,0.8481018656672761,-0.08723557142140148
589.000000000008,33.94103302087893,0.8495952395918088,-0.08930367692428476
590.4000000000079,33.98715010132303,0.8538296848404132,-0.08925608249965711
591.800000000008,34.03337191008192,0.8562706503110264,-0.0893395395169807
593.200000000008,34.07959280268756,0.8564173075079815,-0.08926021810696039
594.6000000000081,34.125103892025805,0.8602969933476146,-0.08984041631743445
596.0000000000081,34.17125301419689,0.8642765378893558,-0.09054612760842717
597.400000000008,34.21765147914452,0.8695642825350016,-0.0918860123885179
598.8000000000081,34.26329177095392,0.8721233075448948,-0.09189089285877294
600.2000000000081,34.309584364032816,0.8768102194569063,-0.09258517232115304
601.6000000000081,34.355324324541705,0.8808817237057147,-0.09320135059556778
603.0000000000082,34.40146498917317,0.883107813689796,-0.09454014718019099
604.4000000000082,34.44717217676762,0.8910498468283716,-0.09454331686763195
605.8000000000081,34.493580266787234,0.8952642461857329,-0.09590134519027282
607.2000000000082,34.539401195923176,0.904265444369649,-0.09584289352157604
608.6000000000082,34.58566343505986,0.9071878643889459,-0.09847127867842298
610.0000000000083,34.63151372469034,0.9161937743147757,-0.09847782882197409
611.4000000000083,34.67695743931674,0.9237711255692564,-0.09978883159610019
612.8000000000083,34.72369433416241,0.9249951172243321,-0.09925716410420504
614.2000000000083,34.769928763719484,0.9310700056039445,-0.09980387349551956
615.6000000000083,34.81594431330127,0.9378942482162753,-0.10112125067805078
617.0000000000084,34.86196455853514,0.9393363707729194,-0.10240235082227711
618.4000000000084,34.907806610905105,0.9434263135645227,-0.10371064359587567
619.8000000000084,34.953833570284004,0.949394300007604,-0.10398649369935997
621.2000000000085,35.0001374659995,0.9542140087615154,-0.10624673779908944
622.6000000000084,35.04610641782962,0.9603492874769579,-0.10517810327993526
624.0000000000084,35.09256565446577,0.9634261753398119,-0.10650822711273111
625.4000000000085,35.13834733012488,0.969846530075415,-0.10741645182706483
626.8000000000085,35.18442868486415,0.9744445168517089,-0.1078145350779467
628.2000000000085,35.23040380339961,0.9822948245229401,-0.10948157482868615
629.6000000000085,35.27663875362585,0.9866377613626119,-0.1096254012022504
631.0000000000085,35.32291976322766,0.9943576920870225,-0.11070201078453135
632.4000000000086,35.36906893486968,0.9983212973688071,-0.11209429987074104
633.8000000000086,35.41476121856221,1.0020999070846859,-0.11371360550039533
635.2000000000086,35.460848889673116,1.0122091139659124,-0.1147305679355588
636.6000000000087,35.50686077538358,1.0152430039061107,-0.11491894209747322
638.0000000000086,35.553222532726444,1.0199302898458125,-0.11764553738354122
639.4000000000087,35.59947271856876,1.0268074510200083,-0.11889602789474552
640.8000000000087,35.64550848496949,1.0320032087779643,-0.11950248153974208
642.2000000000087,35.69151986000557,1.0342839777278785,-0.1190877730119273
643.6000000000088,35.737734433623416,1.040194446416096,-0.12075872084251182
645.0000000000088,35.784089159478626,1.0498307899298045,-0.12269174564643315
646.4000000000087,35.830211082078044,1.052619471911281,-0.12492169137459497
647.8000000000088,35.87671240610995,1.0634123025066424,-0.12689041180230465
649.2000000000088,35.92301565576217,1.0702269609792927,-0.12695905778725303
650.6000000000088,35.96891014983551,1.075837214532143,-0.12833818698648436
652.0000000000089,36.01558317172629,1.0858043350397586,-0.1296779240155299
653.4000000000088,36.06165539872993,1.097439076372591,-0.13096372989687266
654.8000000000089,36.10825435534368,1.1053061292366193,-0.1326195972647115
656.2000000000089,36.15440069006776,1.1156946993133015,-0.13494560978889814
657.6000000000089,36.20079186163876,1.1308684028349254,-0.1365754011278857
659.000000000009,36.247140738700296,1.1427895923728733,-0.13825676831383138
660.400000000009,36.29360084997538,1.1610435102510643,-0.13959277088113398
661.800000000009,36.34020873584479,1.1812415785519814,-0.14104423549058653
663.200000000009,36.38651026488272,1.2021993417303247,-0.14251031049612317
664.600000000009,36.432876816606786,1.2255058338287328,-0.14514745335480983
666.0000000000091,36.479655505577,1.2499730891391456,-0.14645320551793262
667.4000000000091,36.52610863514386,1.2771944263879733,-0.14797037284309011
668.800000000009,36.57286335273035,1.3023279161910946,-0.15043515904072846
670.2000000000091,36.61933684414398,1.3339439967548845,-0.15204723221581773
671.6000000000091,36.66628043285019,1.364050775298507,-0.15465435396930705
673.0000000000091,36.71217530807687,1.3972305471768127,-0.1575619034382476
674.4000000000092,36.75991600691603,1.4307150112096332,-0.160793927631107
675.8000000000092,36.80594172583213,1.4654425934627882,-0.16331889113542397
677.2000000000093,36.853445818940386,1.50172777913648,-0.16567846825055899
678.6000000000092,36.90032363940849,1.5357431359011882,-0.16747780891993047
680.0000000000092,36.94728512942113,1.5775109127405296,-0.171403999639395
681.4000000000093,36.9941923740933,1.6167652054788473,-0.17392505906436062
682.8000000000093,37.04110594729415,1.6596567836800427,-0.177915463097436
684.2000000000094,37.087668015872715,1.7055754644551788,-0.18166613327258085
685.6000000000093,37.13526438641801,1.749079485559971,-0.18569718979835814
687.0000000000093,37.182411214879636,1.7973917303445517,-0.1891029584264432
688.4000000000094,37.22948026084492,1.8479305454684707,-0.19149268265207953
689.8000000000094,37.276946716049544,1.9015574949597722,-0.19648010242344727
691.2000000000094,37.3239542479491,1.9527379904639024,-0.20232691826140448
692.6000000000095,37.37130411381852,1.9999417521489888,-0.2065209560230139
694.0000000000094,37.41871640820003,2.059338630008849,-0.2106295368137312
695.4000000000094,37.46604053042044,2.117188239017893,-0.2167456614485248
696.8000000000095,37.51340270214532,2.178006915239512,-0.2215027162838381
698.2000000000095,37.56069875234076,2.2435675378288673,-0.22641714070339924
699.6000000000096,37.60813849491081,2.3074999866993857,-0.23288780100725015
701.0000000000095,37.655967126093074,2.3792012452334577,-0.23837860367627117
702.4000000000095,37.70306593494995,2.4506742420893994,-0.24331316102801237
703.8000000000096,37.75076593803835,2.527238727352854,-0.24992824772848854
705.2000000000096,37.79825733041311,2.5988040781148922,-0.2566076992036779
706.6000000000097,37.84587358880929,2.678352685505124,-0.26401774928923727
708.0000000000097,37.89341111619175,2.754616598899344,-0.2717625480620254
709.4000000000096,37.941198736601976,2.8326108219913837,-0.27751181785918533
710.8000000000097,37.98849703484924,2.9194130995520142,-0.2859649850921966
712.2000000000097,38.036300062121,3.003925975172596,-0.2941997269725549
713.6000000000097,38.08389158267701,3.095548807208548,-0.3024882004496119
715.0000000000098,38.13104984919523,3.1843689281738214,-0.3095566056564363
716.4000000000098,38.179306672666584,3.2832521031866473,-0.3184154716071985
717.8000000000097,38.2269779548351,3.3803374500957277,-0.3290153580692965
719.2000000000098,38.27437900070038,3.476455081484942,-0.3364665241700009
720.6000000000098,38.32234522781493,3.5782286131616226,-0.342783123358656
722.0000000000099,38.37022142346031,3.680508154387487,-0.35676633778452604
723.4000000000099,38.41824522708173,3.7895100231959624,-0.3708285336312813
724.8000000000098,38.46583982609302,3.895470561285267,-0.3813138040618633
726.2000000000099,38.51358957529404,4.008389912146795,-0.39262931184285277
727.6000000000099,38.561369112510675,4.122152276514247,-0.4028134699913051
729.00000000001,38.60944267225873,4.23220243045684,-0.4144983025065274
730.40000000001,38.65708205831218,4.349469738456131,-0.4275531044676524
731.80000000001,38.70505243721711,4.4625499608125665,-0.44058106185868207
733.20000000001,38.753114159552915,4.574104727991954,-0.45336268307477257
734.60000000001,38.80108699893547,4.695194054009737,-0.46759760044588106
736.00000000001,38.848640608438544,4.8109975333931585,-0.48150269491160724
737.4000000000101,38.896504217917865,4.927921952806142,-0.49543399946885636
738.8000000000101,38.944718522681164,5.050515491176867,-0.5102046644053315
740.20000000001,38.992247634730575,5.164813259173041,-0.52251619244513
741.6000000000101,39.03957906037614,5.283681327178802,-0.5431813592045436
743.0000000000101,39.088047923084815,5.398183487067667,-0.5589285456696564
744.4000000000102,39.136059223129905,5.517796011971055,-0.5747951436435512
745.8000000000102,39.183699937242466,5.63335246532011,-0.5914261507523371
747.2000000000102,39.23154146940017,5.7488602646220395,-0.6087719147432096
748.6000000000103,39.279540258850844,5.859421471309417,-0.6269021223803914
750.0000000000102,39.327423428233075,5.974402270912754,-0.6446989596707975
751.4000000000103,39.37535142851034,6.0812125659807865,-0.6637229898979222
752.8000000000103,39.423081289257716,6.192471829419695,-0.6815623294958146
754.2000000000103,39.470809277915485,6.294127002555808,-0.7025943742108658
755.6000000000104,39.5189300468702,6.401252270742044,-0.7222792511552636
757.0000000000103,39.56663292634115,6.507319034062312,-0.7403802182061159
758.4000000000103,39.614626186588254,6.609228756391395,-0.7602205988602377
759.8000000000104,39.66242602080102,6.711114605961956,-0.7818418809011947
761.2000000000104,39.710322765602974,6.815943294593868,-0.8039341066214987
762.6000000000104,39.7583104377244,6.924633112672118,-0.8264945097652636
764.0000000000105,39.80608028296807,7.033847120941606,-0.8488675174432858
765.4000000000104,39.854355686240396,7.143963275954222,-0.8713741612646921
766.8000000000105,39.90230354693381,7.261704475408763,-0.8936330009607198
768.2000000000105,39.950264923812874,7.3889629777450825,-0.9178442178545732
769.6000000000105,39.99853364423167,7.516791359043964,-0.9443573805882397
771.0000000000106,40.046904678915396,7.645694772452107,-0.968385476143184
772.4000000000106,40.09488335045152,7.782866058586443,-0.9920706089648883
773.8000000000106,40.14276146354991,7.915997338447797,-1.0164807680276464
775.2000000000106,40.19099022542328,8.047133601352076,-1.042758591550494
776.6000000000106,40.23917068108023,8.166680795870995,-1.0704002864158069
778.0000000000107,40.28683969032656,8.273056873358916,-1.095023351922368
779.4000000000107,40.334989949562676,8.369300808587829,-1.1198056771326148
780.8000000000106,40.38284640695673,8.447825440632018,-1.147095433416697
782.2000000000107,40.43054528219442,8.52010991892377,-1.1732563993493375
783.6000000000107,40.47861118897876,8.608058894078823,-1.19861649067049
785.0000000000107,40.52612349937023,8.709772547156387,-1.2229512166207002
786.4000000000108,40.57450906320168,8.81951991165861,-1.2491262003837589
787.8000000000108,40.6221726771717,8.89067294113366,-1.2758110073343008
789.2000000000108,40.66916965949802,8.902502011182085,-1.304019834383379
790.6000000000108,40.71528825151753,8.757462456431742,-1.3285851879681325
792.0000000000108,40.75986345618759,8.439032545839098,-1.3498354303644016
793.4000000000109,40.80306238325678,7.870251556496582,-1.3725968873796202
794.8000000000109,40.84352115457182,7.0241636757373085,-1.3922720545217961
796.200000000011,40.88106174987428,5.782072252313659,-1.408836618955001
797.6000000000109,40.91781778060303,4.388914370755052,-1.4217059201544155
799.0000000000109,40.95579190365785,3.1761142551253205,-1.432182470457089
800.400000000011,40.99507004905452,2.2518265607647585,-1.4385624295026118
801.800000000011,41.03688020605573,1.5777951720681116,-1.441587646548406
803.200000000011,41.080104375162826,1.127216039305226,-1.4440519873339102
804.600000000011,41.124605562750254,0.8312149424825162,-1.4440367433244723
806.000000000011,41.170247580212326,0.6724859155515763,-1.4455085448271654
807.400000000011,41.21627349787073,0.5903693668018015,-1.4468242647534235
808.8000000000111,41.26311948671809,0.5207656282313975,-1.4468399167976576
810.2000000000111,41.309651504745474,0.49732027119009126,-1.446839839931418
811.6000000000112,41.356665418458874,0.47558172310779545,-1.4467503939082516
813.0000000000111,41.40393976327098,0.46948402023511626,-1.4478389276703676
814.4000000000111,41.45090690527377,0.4645997196083349,-1.4468512308643682
815.8000000000112,41.49806542379144,0.46439987074659195,-1.4468500341811072
817.2000000000112,41.545069708615465,0.464964017484786,-1.446862713982469
818.6000000000113,41.5922461726916,0.4626715149000846,-1.4481451924260145
820.0000000000113,41.639435207007864,0.4611405216135147,-1.4468760587586513
821.4000000000112,41.68709233048691,0.46167399920013863,-1.4468398259073334
822.8000000000113,41.73429832608744,0.46287043689126617,-1.4468398640571318
824.2000000000113,41.7814698619024,0.4645950728234367,-1.4468398542767367
825.6000000000113,41.82809368170767,0.46175570401061017,-1.4468376494482178
827.0000000000114,41.87623436119845,0.46328189425014976,-1.4481644905039688
828.4000000000113,41.9232171373604,0.4612074618833273,-1.4481600377160015
829.8000000000113,41.97094527688979,0.46386264028107593,-1.4482536444965426
831.2000000000114,42.01763987974698,0.46409389687817826,-1.4473839048328694
832.6000000000114,42.06579699238434,0.461799722432217,-1.4481594737366552
834.0000000000115,42.11317802744714,0.46584875643059087,-1.448159996130745
835.4000000000115,42.16050619590906,0.4627889265407996,-1.448208670525311
836.8000000000114,42.20800348280953,0.46431500768253775,-1.448229754450567
838.2000000000115,42.25523599588783,0.4616893449870463,-1.4494762526365386
839.6000000000115,42.302758380078146,0.4567139596115255,-1.4494701687808895
841.0000000000116,42.35013673469907,0.458644529455555,-1.4494700584106872
842.4000000000116,42.39755356163771,0.4569656175947867,-1.4495518254386193
843.8000000000116,42.4450274797018,0.4538735662068727,-1.4481599461532344
845.2000000000116,42.49236272834649,0.45292668150578486,-1.4480915533420102
846.6000000000116,42.540155697970675,0.4570106761088446,-1.4494801298229647
848.0000000000116,42.58771691290712,0.4550233944859403,-1.4494799653197261
849.4000000000117,42.6352069225291,0.4611035156192369,-1.449474549170049
850.8000000000117,42.68249356556773,0.4591383370233415,-1.4495673211328564
852.2000000000116,42.73010574100086,0.45891887138726606,-1.4494800997478339
853.6000000000117,42.777598600531626,0.4613434613285585,-1.4494801141687792
855.0000000000117,42.82514438852556,0.45777827533870985,-1.4494795902901143
856.4000000000118,42.87266419665318,0.4595005843804394,-1.4497749626693017
857.8000000000118,42.91985501285313,0.4590834305807914,-1.4507898861998085
859.2000000000118,42.96731660935961,0.4599265458357731,-1.4507899311449712
860.6000000000118,43.01514967612154,0.4607192518720227,-1.4507901245501489
862.0000000000118,43.06280964257595,0.46311432597956004,-1.4508061819252451
863.4000000000119,43.110340706111764,0.4592240668611245,-1.4494696735686436
864.8000000000119,43.15761456959439,0.46041240798671956,-1.4508229287878622
866.2000000000119,43.20503050142554,0.462997024902432,-1.4507472541893764
867.600000000012,43.252693053039415,0.4551831495777645,-1.4518676864531876
869.0000000000119,43.30021816676881,0.45720610234463277,-1.4520824164289885
870.4000000000119,43.34739837644454,0.455401582766759,-1.4507923153465891
871.800000000012,43.39496500550798,0.45584086838805526,-1.4511110683835517
873.200000000012,43.44232741977031,0.45472156474868575,-1.4521090754931576
874.600000000012,43.48999267418797,0.4534984912687421,-1.4521020980286452
876.000000000012,43.53760428569976,0.45246705355956274,-1.453415539205817
877.400000000012,43.58482018583017,0.44966971801044653,-1.4529111574628888
878.8000000000121,43.63218323406203,0.4517692610207025,-1.452110101857449
880.2000000000121,43.67973377669572,0.44940312158606943,-1.4521100599941419
881.6000000000121,43.72683950391229,0.44871839595155993,-1.453469517426532
883.0000000000122,43.774608995102554,0.44783526826703124,-1.4534548805051033
884.4000000000121,43.82212206923051,0.4463794128069585,-1.4547486786321198
885.8000000000122,43.86957101759336,0.4422078386220276,-1.4547357802757301
887.2000000000122,43.916893117073386,0.44403121395147327,-1.4537675375334458
888.6000000000122,43.96435325272131,0.4406518484060191,-1.4534368306704386
890.0000000000123,44.01179740175381,0.43892126229447936,-1.4534455673929711
891.4000000000123,44.05903380303401,0.43637435191252827,-1.4524266300888566
892.0000000000123,44.07937619173314,0.437157793155593,-1.4534266341826139