File: 01_Data/Smoke_Explosion_Plywood/STA/N2/3K_min/Smoke_Explosion_Plywood_STA_N2_3KData_230804_R1.csv
##Temp./Â°C,Time/min,DSC/(mW/mg),Mass loss/mg
27.0,20.784366362650236,-2.3645192809933886,-0.15740721207377772
28.100000000000016,21.58857712629029,-2.339352478374464,-0.1640898530207151
29.20000000000003,22.13114804455204,-2.3308610221797763,-0.16544006848666282
30.300000000000047,22.590686396018306,-2.3291815466659513,-0.16752101438008715
31.400000000000063,23.03270059407017,-2.3271481364395337,-0.16950015202634727
32.50000000000008,23.452520319132482,-2.3268487000665483,-0.1721567213967914
33.600000000000094,23.879074517878806,-2.3276241598839067,-0.17245989874989176
34.70000000000011,24.27721709112186,-2.3259638453743934,-0.17498731428699932
35.800000000000125,24.676578262782588,-2.3263444381604894,-0.17739975254796558
36.90000000000014,25.082766566482398,-2.3267479890146436,-0.17971293583908965
38.000000000000156,25.469385269876526,-2.3280443318084587,-0.18200683429648867
39.10000000000017,25.866804305773766,-2.3283061706375707,-0.18498014530919127
40.20000000000019,26.25761916343434,-2.328549532747991,-0.1863047695862874
41.3000000000002,26.68359496318783,-2.330486697594605,-0.1909108044412049
42.40000000000022,27.00960885577343,-2.3296851628850517,-0.19289006107411755
43.500000000000234,27.383875308430408,-2.3306342089627696,-0.19551991200000085
44.60000000000025,27.751191224381206,-2.3318847897316215,-0.20025421535978172
45.700000000000266,28.13858489008136,-2.3327588496949927,-0.20111015201610405
46.80000000000028,28.52409133202538,-2.328948474259263,-0.20507000512631102
47.9000000000003,28.8931848389377,-2.3274679795382864,-0.20770988676098412
49.00000000000031,29.266610343904915,-2.3266544777062808,-0.21164992737394606
50.10000000000033,29.63250000000006,-2.3251200000000036,-0.21561007045178116
51.200000000000344,30.005981919366114,-2.3219719674330612,-0.21974423719046943
52.30000000000036,30.379716653214835,-2.3176821932311564,-0.22155764846547532
53.400000000000375,30.741164286964693,-2.3146009406764128,-0.22497773474823513
54.50000000000039,31.121983429832333,-2.31046153037124,-0.22725913400483355
55.600000000000406,31.492379303423814,-2.306725199236678,-0.23279639186542678
56.70000000000042,31.86549991703673,-2.301230601409302,-0.2339787640843336
57.80000000000044,32.23322610242976,-2.296169496119089,-0.2370142176718173
58.90000000000045,32.60106276052546,-2.2911362741207477,-0.23964732938543332
60.00000000000047,32.9695934892502,-2.285777371914028,-0.24262129147444078
61.100000000000485,33.33511105003978,-2.2798367277994784,-0.24581802245167284
62.2000000000005,33.70467877667562,-2.2726744360746634,-0.24788981137754584
63.300000000000516,34.071995334189396,-2.2663094424967687,-0.25151212726461036
64.40000000000053,34.437681187132156,-2.259315818873303,-0.2527977139690267
65.50000000000054,34.80578756758524,-2.2535772049811253,-0.2554119276234208
66.60000000000056,35.1736042121737,-2.2456658912692276,-0.25809991198874593
67.70000000000059,35.53879137659612,-2.2391148889877885,-0.261394901946026
68.8000000000006,35.905830000000165,-2.2332499999999937,-0.26236703393927474
69.9000000000006,36.27305218031217,-2.2244779875535263,-0.2640199450576035
71.00000000000063,36.63625725179779,-2.2178914660481786,-0.2653400030154054
72.10000000000065,36.99983172901217,-2.21229032437866,-0.267119067347136
73.20000000000066,37.3657187291141,-2.2055321141961666,-0.2689696052867965
74.30000000000067,37.73078896208809,-2.1985041192273806,-0.27094323992650526
75.40000000000069,38.09581817853332,-2.19374558505342,-0.27325252830420244
76.50000000000071,38.46331829061399,-2.1862525745156507,-0.2742300658166408
77.60000000000072,38.824146144304805,-2.1799253828212755,-0.274021924947768
78.70000000000073,39.19123896487723,-2.1738023832243183,-0.2758800919446407
79.80000000000075,39.55754718049347,-2.1690315605181314,-0.27720009208050067
80.90000000000077,39.920799454483124,-2.1639457697237034,-0.2791689327532736
82.00000000000078,40.29052736220865,-2.157417593241689,-0.2801598929995377
83.10000000000079,40.68677107847441,-2.1501584312151807,-0.27989787521683684
84.20000000000081,41.01917000000028,-2.1462799999999813,-0.28050009199273784
85.30000000000084,41.382486795296224,-2.1417219183910947,-0.28278474677958476
86.40000000000084,41.74583000000039,-2.1364599999999747,-0.28147329346686023
87.50000000000085,42.114536733522186,-2.1329546080700093,-0.2828000239475088
88.60000000000088,42.49915071938595,-2.1290261186203385,-0.2831298199928445
89.7000000000009,42.84206202041534,-2.123267192443007,-0.2831298199999992
90.8000000000009,43.20382715575363,-2.118803483585808,-0.2841101559999992
91.90000000000092,43.56943754056362,-2.115402209256655,-0.2841713281889455
93.00000000000094,43.918470482617224,-2.112891217745462,-0.28476995991329357
94.10000000000096,44.298194379973154,-2.1099605600600175,-0.28575988399993246
95.20000000000097,44.657419331486466,-2.1061218560678183,-0.2870798956958849
96.30000000000098,45.01250000001254,-2.1040299999993017,-0.28740015199937785
97.400000000001,45.39288785565643,-2.0994211202969155,-0.2867494724536561
98.50000000000102,45.74583802410046,-2.0959365209080407,-0.2867498439999996
99.60000000000103,46.107431268423056,-2.092164877717217,-0.2880698440000069
100.70000000000104,46.469889265548886,-2.0893235934201417,-0.28739988184225496
101.80000000000106,46.83692143517662,-2.0870615043109106,-0.28873011200000054
102.90000000000109,47.19585093480372,-2.0851315136419983,-0.28841345725547596
104.0000000000011,47.55814722495701,-2.0815276843766273,-0.28937997599979104
105.1000000000011,47.92288082606311,-2.0789953893788073,-0.28841590354079605
106.20000000000113,48.28461908762053,-2.0768226758558317,-0.28838997200176353
107.30000000000115,48.64374783534694,-2.0736169021071325,-0.28936265400063776
108.40000000000116,49.008470167495226,-2.0707792794044546,-0.28656362637961674
109.50000000000117,49.371874028599564,-2.0688510151082546,-0.2887202307482184
110.60000000000119,49.7303712595193,-2.0664257784526567,-0.2887300000001267
111.70000000000121,50.08414168842134,-2.0645415735304464,-0.2900399988322824
112.80000000000122,50.44862228402762,-2.062713329002971,-0.2887725610810947
113.90000000000123,50.81267990195438,-2.0614793282809725,-0.290040146682633
115.00000000000125,51.171013181199875,-2.0587525092987398,-0.2897101326065563
116.10000000000127,51.52744313777938,-2.058100168542362,-0.2899271915778949
117.20000000000128,51.891359781961526,-2.055955510231254,-0.2899299713598298
118.30000000000129,52.25178036072744,-2.0534960867803065,-0.28959990400001967
119.40000000000131,52.60465339035306,-2.050313668098039,-0.2899236608475322
120.50000000000134,52.97980092903573,-2.0474207117992007,-0.2886201359999996
121.60000000000134,53.3372800675223,-2.046278430131222,-0.2899400176940503
122.70000000000135,53.68863278526252,-2.0448135575928976,-0.29125013599999905
123.80000000000138,54.03803985186871,-2.0424073560036886,-0.28987568175481915
124.9000000000014,54.415728769627286,-2.039309586040022,-0.29157980000000006
126.0000000000014,54.77464653176662,-2.037992197042792,-0.291578305860821
127.10000000000142,55.13281260709966,-2.036999302985797,-0.2928832075035177
128.20000000000144,55.49645348433292,-2.0340896711753125,-0.2925718733876197
129.30000000000146,55.85673584539904,-2.034471990762016,-0.2938801375500102
130.40000000000146,56.220536271049475,-2.031995695845733,-0.29389000334883564
131.50000000000148,56.58034289927218,-2.0316441080589116,-0.2947668513857695
132.6000000000015,56.93713099182519,-2.028478622135705,-0.29312004399991665
133.70000000000152,57.29585881735909,-2.0277240014631426,-0.29411003276159464
134.80000000000155,57.65181855083217,-2.0267930639803713,-0.2938802012982138
135.90000000000154,58.01024115112632,-2.024117558915764,-0.2955298459851661
137.00000000000156,58.36873339237271,-2.021268162914802,-0.29585986400000097
138.1000000000016,58.71773287330836,-2.019275237419644,-0.29585987153723403
139.20000000000158,59.09697599477692,-2.0191924212075967,-0.29619006399999925
140.3000000000016,59.452410620830804,-2.018597281627173,-0.2962508602334828
141.40000000000163,59.807708878669935,-2.016435297506498,-0.2975098640047773
142.50000000000165,60.16699367248142,-2.014726900677394,-0.29750986399999846
143.60000000000167,60.525537357942824,-2.011642746412876,-0.2961819197679416
144.70000000000167,60.883888785677215,-2.009737820272114,-0.298716659493945
145.8000000000017,61.244087685664574,-2.0086662936835973,-0.2987209596813809
146.9000000000017,61.60376512443069,-2.0066541861444405,-0.2993696516024178
148.0000000000017,61.96205390531066,-2.0057188767080882,-0.30003004400041844
149.10000000000173,62.317307942879836,-2.0043613329973633,-0.2996693408581055
150.20000000000175,62.679443820284696,-2.001946004907674,-0.3007136640359098
151.30000000000177,63.04108503239091,-2.0004590242822062,-0.29948013243036664
152.4000000000018,63.39917401045027,-1.999329695662824,-0.30014730816419055
153.5000000000018,63.7533726466489,-1.9959775739645265,-0.3014598639999986
154.6000000000018,64.11117719069942,-1.9940302025446708,-0.30212000032025044
155.70000000000184,64.46845533652218,-1.9923717292613243,-0.3024499430773293
156.80000000000183,64.83250000000226,-1.992680000000182,-0.30135020033438975
157.90000000000185,65.18621285030511,-1.9898135129292738,-0.3021199318883201
159.00000000000188,65.54877430143455,-1.9869660657709576,-0.30310993200000036
160.1000000000019,65.90486974681023,-1.9872028767028869,-0.303109931999999
161.20000000000192,66.2597051071611,-1.9851774837472258,-0.3047320893323553
162.30000000000192,66.61778736497617,-1.9835630622055853,-0.3037699335747397
163.40000000000194,66.9765438172314,-1.982694318047481,-0.3054100736922587
164.50000000000196,67.33250000000038,-1.980089999999991,-0.30509006800052285
165.60000000000196,67.71201452828026,-1.9776379949506744,-0.305749800163464
166.70000000000198,68.04899940459359,-1.9773030490285484,-0.30705973054004554
167.800000000002,68.39655162321394,-1.9761056070870175,-0.3073786071632534
168.90000000000202,68.75842159315913,-1.9735801748363577,-0.3083760202246273
170.00000000000205,69.12106961255884,-1.9722333890631212,-0.30742551857136036
171.10000000000204,69.47368728148587,-1.9711519372294943,-0.30935983978701476
172.20000000000206,69.83298315649988,-1.9704380803808295,-0.31067936581407984
173.3000000000021,70.1928471517534,-1.968552294911067,-0.31034997600000036
174.40000000000208,70.54753684243029,-1.9687393146728718,-0.3106800441990911
175.5000000000021,70.90490792896692,-1.967501701470078,-0.31199850256841843
176.60000000000213,71.26379574737108,-1.966266248984271,-0.31265946886476614
177.70000000000215,71.61533651444533,-1.9636180331910498,-0.3146307876916796
178.80000000000217,71.97724179397873,-1.9631230520191676,-0.31534658368524626
179.90000000000217,72.3213576712938,-1.962168625935589,-0.31696967623808225
181.0000000000022,72.68495490874822,-1.960584650804633,-0.3182598200034068
182.1000000000022,73.04741330823327,-1.959893488267048,-0.32086641487561707
183.2000000000022,73.40227125620528,-1.9571441973606634,-0.3215499952880765
184.30000000000223,73.75966398201766,-1.9569633821937416,-0.32154999600000034
185.40000000000225,74.11757555960777,-1.9540599178521916,-0.3248472749722473
186.50000000000227,74.47059013701187,-1.9532193069985593,-0.32451815146452967
187.6000000000023,74.82829528689162,-1.9509312357261273,-0.3254999040284936
188.7000000000023,75.16852465843363,-1.9513266307040082,-0.3268025788554194
189.8000000000023,75.53426405907847,-1.9504965265404548,-0.3294600748514789
190.90000000000234,75.89027996219609,-1.9493412575021614,-0.33077989955737497
192.00000000000233,76.2525000000005,-1.9478200000000114,-0.3324100839999997
193.10000000000235,76.6071782256999,-1.9458352395115275,-0.33382259026845196
194.20000000000238,76.96469855677762,-1.9468017249718446,-0.3363700815774511
195.3000000000024,77.31967968015631,-1.9456431585764176,-0.33867049400525095
196.40000000000242,77.6676266204121,-1.94458554031928,-0.34179169480720706
197.50000000000242,78.03538073867716,-1.9443460728794586,-0.3440561736371208
198.60000000000244,78.39249561705789,-1.9424000434643731,-0.34437992799999906
199.70000000000246,78.73753787790835,-1.9419947761185776,-0.3470199252164168
200.80000000000246,79.09790350582793,-1.9408260242833242,-0.3487640472217217
201.90000000000248,79.46000193880833,-1.9397601876264001,-0.35202179469490735
203.0000000000025,79.81250000000065,-1.9371399999999777,-0.35525015199999954
204.10000000000252,80.16460649787997,-1.9360432045824811,-0.3565700199964117
205.20000000000255,80.51579416357805,-1.9344363532133269,-0.3594376075223713
206.30000000000254,80.87232002114044,-1.9341974794210965,-0.3621702010634378
207.40000000000256,81.23017276037343,-1.9338049109427995,-0.3661201080167866
208.5000000000026,81.58068912148923,-1.933707923481158,-0.36842965596745536
209.60000000000258,81.93978022087903,-1.9333646358920829,-0.37171988346113416
210.7000000000026,82.29581452164521,-1.93238638589426,-0.37567019503594734
211.80000000000263,82.65432339155707,-1.9320057353873041,-0.37830993201198737
212.90000000000265,83.00607894891198,-1.9304897841117312,-0.3810257560388117
214.00000000000267,83.3525000000042,-1.9287300000003482,-0.38489998000000014
215.10000000000267,83.71856626765377,-1.9280276029459893,-0.3897021271290817
216.2000000000027,84.07094415195209,-1.9269085725264252,-0.3933426135988598
217.3000000000027,84.43031867613148,-1.9265776587580068,-0.39734498249491956
218.4000000000027,84.78583324490154,-1.9254800883539518,-0.3999400116464651
219.50000000000273,85.14396689224436,-1.9240980572970863,-0.4052115711835498
220.60000000000275,85.49597185514035,-1.923710880114731,-0.4074734939114042
221.70000000000277,85.85055964710686,-1.9232016218239305,-0.4143174519370958
222.8000000000028,86.2114824530521,-1.9220864004831513,-0.41728015868674717
223.9000000000028,86.57055710220358,-1.921237584895502,-0.4225759822437616
225.0000000000028,86.92642212506757,-1.9208994889756899,-0.4278438827095643
226.10000000000284,87.27956508887412,-1.9185562964695924,-0.43122996221156296
227.20000000000283,87.63296434132985,-1.917896980778692,-0.4374647754089267
228.30000000000285,87.99022268909157,-1.9160838876209432,-0.4434068380313132
229.40000000000288,88.34496242891008,-1.91499259673233,-0.4466862268209857
230.5000000000029,88.7052602856982,-1.913794783103564,-0.45329279991362625
231.60000000000292,89.06262876210111,-1.9135635633168282,-0.4582300245355202
232.70000000000292,89.46660283821697,-1.9105835753168068,-0.4638200226957112
233.80000000000294,89.7767777837015,-1.9125399979864122,-0.470410755258754
234.90000000000296,90.13251841312757,-1.9104887714709118,-0.4750202287625074
236.00000000000296,90.48955213939345,-1.9090372055174132,-0.48260302700511115
237.10000000000298,90.84582892051469,-1.9058999266014363,-0.4872019815189059
238.200000000003,91.19837656724766,-1.9068462503450097,-0.49445806167639805
239.30000000000302,91.55678955271328,-1.9067721491131269,-0.5016339429683496
240.40000000000305,91.9070935398415,-1.9049675458475097,-0.5069782973528869
241.50000000000304,92.26682602727378,-1.9041467837736872,-0.5148657963944925
242.60000000000306,92.62213426445919,-1.9045184499151089,-0.5227883079249431
243.7000000000031,92.98248384778773,-1.903151622518697,-0.5297856601708593
244.80000000000308,93.30299365991861,-1.9026994429555641,-0.5349038199190712
245.9000000000031,93.69117674961942,-1.9012173105959524,-0.5472438266044644
247.00000000000313,94.04797902304233,-1.900781389948556,-0.5550568079860456
248.10000000000315,94.40424607493591,-1.9005987095466197,-0.5629557010923709
249.20000000000317,94.76098790821149,-1.9013179200613148,-0.5724234936546715
250.30000000000317,95.11742358695966,-1.900126329379443,-0.5818506538496893
251.4000000000032,95.46987612224623,-1.8986606313590213,-0.5904647941048107
252.5000000000032,95.82469647986002,-1.8955279226243538,-0.600489258368821
253.6000000000032,96.18122857198675,-1.8963703020556018,-0.6121431233129524
254.70000000000323,96.54100555196383,-1.8949366395444507,-0.622575468695632
255.80000000000325,96.894708214352,-1.893706801434975,-0.6348387388549881
256.9000000000033,97.24997265757752,-1.893509615354721,-0.6452962926925836
258.0000000000033,97.60433897992638,-1.8928918262027128,-0.6564859462171695
259.1000000000033,97.96170749105218,-1.891918225833659,-0.6688974393824143
260.20000000000334,98.31830537715128,-1.89113887157946,-0.6826279024402693
261.30000000000337,98.67384749378714,-1.8912605076472584,-0.6950644062664058
262.40000000000333,99.03170446860295,-1.8912085724958778,-0.7086280128786875
263.50000000000335,99.39069563902703,-1.8905590356834001,-0.7229519091344994
264.6000000000034,99.74580986623269,-1.890638857565999,-0.737189060460067
265.7000000000034,100.10007469837623,-1.8896455415405602,-0.7510142495265799
266.8000000000034,100.46206190844107,-1.89154907313318,-0.7661958197641763
267.9000000000034,100.81112607740911,-1.8908953641605644,-0.7825395201687164
269.0000000000034,101.16738441845607,-1.8889865483221742,-0.7988244014218369
270.10000000000343,101.5284671185658,-1.8885172045386007,-0.8156004801315664
271.20000000000346,101.88556731547013,-1.8883424405923597,-0.8326894265681246
272.3000000000035,102.23917462823,-1.8877899133433267,-0.8506006498699485
273.4000000000035,102.60355865666104,-1.887397832125988,-0.8692781876254974
274.5000000000035,102.95687885215041,-1.8878168948415288,-0.8883982230409311
275.60000000000355,103.31302920969385,-1.888498603437644,-0.9076911371780518
276.70000000000357,103.66695386746426,-1.8884686983437886,-0.9277456615995696
277.8000000000036,104.02583367868755,-1.8863400521000884,-0.9459983393263984
278.9000000000036,104.38561231181569,-1.8872719432723692,-0.9686300968079009
280.0000000000036,104.74054018988456,-1.8872784884485003,-0.9902923029921014
281.1000000000036,105.10430348293087,-1.8872930013301012,-1.0110665632418208
282.2000000000036,105.45860720302699,-1.8885037008873762,-1.0359471537681983
283.30000000000365,105.81125125032176,-1.8889341036524985,-1.0580141108190513
284.4000000000037,106.16951330674817,-1.8893753813863214,-1.0808155297600162
285.5000000000037,106.52883855455825,-1.886576679149649,-1.1059316821611391
286.60000000000366,106.88332528837257,-1.8886645165606726,-1.130167244512391
287.7000000000037,107.24019178064793,-1.8881169238827338,-1.1547313686395588
288.8000000000037,107.60049988507821,-1.888401702557434,-1.179967017320759
289.90000000000373,107.9572449649445,-1.8883991922424965,-1.207384098313196
291.00000000000375,108.31773917304523,-1.8900921875738943,-1.2328474872550648
292.1000000000038,108.67382732680176,-1.8880000781563402,-1.2597972036703213
293.2000000000038,109.03293007069026,-1.8855926633610522,-1.2881955759546169
294.3000000000038,109.38980995009601,-1.8859487977309661,-1.3169016358802006
295.40000000000384,109.75072383850569,-1.8841557830876037,-1.345072563165476
296.5000000000038,110.10583000000196,-1.8810399999999934,-1.3737101400001897
297.60000000000383,110.46371808215464,-1.8814813285399299,-1.4037184842149477
298.70000000000385,110.82349568873461,-1.8804340803314015,-1.4336442951499317
299.8000000000039,111.1815405787309,-1.8797107928402632,-1.4634892480233548
300.9000000000039,111.5348607542779,-1.87738292923471,-1.4946054636489743
302.0000000000039,111.89170071306228,-1.8772890612688071,-1.5245243284661423
303.10000000000394,112.24997214793153,-1.8757443096778048,-1.5560581023791689
304.2000000000039,112.60497258673374,-1.87413051707534,-1.5857941213899638
305.30000000000393,112.96621903081933,-1.8738469015235588,-1.617100811619684
306.40000000000396,113.32197403858622,-1.8715404473578978,-1.6491294964962502
307.500000000004,113.67754208735647,-1.8708467319277375,-1.6801180768760493
308.600000000004,114.03249210604487,-1.869010222704022,-1.7089892545603913
309.700000000004,114.38796051142624,-1.8691413656613023,-1.7418881450909316
310.80000000000405,114.75011047351354,-1.8663180854364079,-1.7722947038709833
311.90000000000407,115.10762344521343,-1.8646267274097321,-1.8040431407168542
313.0000000000041,115.46463722054462,-1.8612720133281782,-1.834477225315796
314.10000000000406,115.81813469355419,-1.8607980662618306,-1.8669013014023634
315.2000000000041,116.17503171332338,-1.859580028316186,-1.8979148734721862
316.3000000000041,116.56749487340582,-1.8574968908589167,-1.932414866221293
317.4000000000041,116.89690645473081,-1.8558996821101748,-1.958022791039081
318.50000000000415,117.2581768858715,-1.8536159358681243,-1.9892458351786058
319.6000000000042,117.6158386661432,-1.851832760919362,-2.0195583352624955
320.7000000000042,117.97219463771437,-1.850313358094215,-2.0501978123485562
321.80000000000416,118.3291015876746,-1.8484243702683654,-2.0796609172476277
322.9000000000042,118.69011043830609,-1.8474826368775805,-2.109801222833565
324.0000000000042,119.04731890175842,-1.8450768961292456,-2.1381422870404636
325.10000000000423,119.40474811742817,-1.8425065667706686,-2.1671237082478143
326.20000000000425,119.76433302129793,-1.8399159205503286,-2.1951643913692567
327.3000000000043,120.11917394162172,-1.838410194660069,-2.2247437636419143
328.4000000000043,120.47863690726662,-1.835547606482856,-2.25161304155438
329.5000000000043,120.84197241113405,-1.8351763487345547,-2.279779941717904
330.60000000000434,121.20451521009268,-1.8334652866232166,-2.3066461834586796
331.7000000000043,121.5573579888553,-1.8284185809205222,-2.333282944009968
332.80000000000433,121.91654789924772,-1.8257829885727643,-2.3584992286353055
333.90000000000435,122.27413493587405,-1.824278738882648,-2.3815946084388604
335.0000000000044,122.62990645721112,-1.819800310623731,-2.406726265282314
336.1000000000044,122.99152122691292,-1.8187758940567031,-2.4316321042396973
337.2000000000044,123.34480283074889,-1.8140279801225179,-2.4530765065780162
338.30000000000445,123.7052532677021,-1.8102693028540122,-2.474616432703484
339.4000000000044,124.06492542593122,-1.8078471417818307,-2.494907884330644
340.50000000000443,124.41892262022245,-1.8047737167044757,-2.5143627897200593
341.60000000000446,124.78455403990527,-1.801121764312036,-2.5332128769048636
342.7000000000045,125.14624397429016,-1.7978363342246102,-2.550600366642233
343.8000000000045,125.51114842042004,-1.7974699990997396,-2.567621204739595
344.9000000000045,125.86269080309819,-1.7963087270922353,-2.5814540383156013
346.00000000000455,126.22131815349401,-1.7935370802401545,-2.595548867141377
347.10000000000457,126.59037909841642,-1.792199261311555,-2.6088895633399227
348.2000000000046,126.94852930955865,-1.7916026226737536,-2.6205576915740876
349.30000000000456,127.30887851287623,-1.7919494911112388,-2.6314997521818673
350.4000000000046,127.6705309639246,-1.7903758830535317,-2.642695969942754
351.5000000000046,128.0293311679102,-1.7911767056500925,-2.6513546594845705
352.6000000000046,128.39074038594543,-1.7917696762451765,-2.6596766584005103
353.70000000000465,128.74582647029695,-1.7890199256603745,-2.66872011099501
354.8000000000047,129.09392844752117,-1.7903880344496983,-2.675302420665987
355.9000000000047,129.46505480414493,-1.7870575412467797,-2.684539563960812
357.00000000000466,129.82652930584274,-1.7865917147128774,-2.6884797121608894
358.1000000000047,130.1861133437314,-1.7855925033487507,-2.695052851992989
359.2000000000047,130.54582776479774,-1.791159948633314,-2.7012098920066387
360.30000000000473,130.90506495081408,-1.7950420417904314,-2.7063773427488886
361.40000000000475,131.26508397158074,-1.7986540772964457,-2.713400921646846
362.5000000000048,131.61920272974274,-1.796665685872854,-2.7173514028489487
363.6000000000048,131.98414272978786,-1.7964150860685548,-2.721300036654851
364.7000000000048,132.34508444114522,-1.7946320244856657,-2.7265694741014883
365.80000000000484,132.70612425645788,-1.7926601213803424,-2.731837160498053
366.9000000000048,133.06682143002925,-1.7918944490002393,-2.735441412296514
368.00000000000483,133.42861594434035,-1.7913649178398352,-2.7397608570067544
369.10000000000485,133.7882564319605,-1.79036059717068,-2.7450099951913747
370.2000000000049,134.1519257420932,-1.7895817952001778,-2.7499597208483526
371.3000000000049,134.51283596586467,-1.7898074648599058,-2.752920144074664
372.4000000000049,134.87533115724224,-1.789157004447446,-2.758190163246671
373.50000000000495,135.2339331962947,-1.7885769467688752,-2.762469869085044
374.6000000000049,135.59451100754214,-1.7891107104526611,-2.7661998052683714
375.70000000000493,135.9471461613457,-1.788760398858137,-2.770878724565363
376.80000000000496,136.31419186433436,-1.787608091581307,-2.7757449418903164
377.900000000005,136.67861157502432,-1.7879052815317904,-2.778387104720305
379.000000000005,137.0387505375725,-1.7875951879182916,-2.7829273236659806
380.100000000005,137.39735701153393,-1.7877631240888012,-2.7876116616398607
381.20000000000505,137.76029578351748,-1.7885577059965576,-2.7915599113728278
382.30000000000507,138.12484654225,-1.7897625630161225,-2.7980207027047497
383.4000000000051,138.48319761373634,-1.7891635116191957,-2.800460345037429
384.50000000000506,138.84535082191476,-1.788274296884858,-2.805389864997455
385.6000000000051,139.20484581489245,-1.7900639176425952,-2.808699753538976
386.7000000000051,139.56029283658057,-1.7913386814744088,-2.8125389579157254
387.8000000000051,139.92968227634995,-1.7933400097426353,-2.816164311556824
388.90000000000515,140.29223570304913,-1.7928338087090219,-2.821456804236
390.0000000000052,140.65129731408328,-1.792907704961397,-2.826028414383714
391.1000000000052,141.01403937154544,-1.7928321846078756,-2.8310255656604504
392.20000000000516,141.38005049580312,-1.7939899541631943,-2.8339419806390174
393.3000000000052,141.73820588019666,-1.7941902940829086,-2.8382200552807797
394.4000000000052,142.10330551299927,-1.793964081079097,-2.8426324809063983
395.50000000000523,142.45831143190821,-1.7954913901963963,-2.8449434081453613
396.60000000000525,142.82395395725882,-1.7958475176143072,-2.848203919686375
397.7000000000053,143.18333750230502,-1.796770920913871,-2.852060677201357
398.8000000000053,143.5510208424667,-1.796892418423031,-2.8573204203926252
399.9000000000053,143.91286696713416,-1.7991549268118112,-2.859962416258089
401.00000000000534,144.27310513191247,-1.7983955744751587,-2.864588797680131
402.1000000000053,144.6357683015942,-1.7993625586052098,-2.8665504600454
403.20000000000533,145.00219290448865,-1.8002969322504936,-2.8705000072164597
404.30000000000535,145.36091516859477,-1.8016024601566922,-2.8744675574760516
405.4000000000054,145.72583089366273,-1.8011701720686448,-2.878400104000292
406.5000000000054,146.08790163273403,-1.8038252801947159,-2.8816364693830714
407.6000000000054,146.4432260500876,-1.803706447294862,-2.884340020084821
408.70000000000545,146.80958750044508,-1.8043231549139116,-2.8869689896772472
409.8000000000054,147.1769401578646,-1.802743418461481,-2.8893154042245657
410.90000000000543,147.53634033268466,-1.8023433109752816,-2.892900116894417
412.00000000000546,147.90405837677216,-1.8014840545612594,-2.8965202658776725
413.1000000000055,148.2662799767446,-1.80317776557037,-2.9001501560002634
414.2000000000055,148.63155227158572,-1.8038907695951134,-2.9031102295418387
415.3000000000055,148.99085520439112,-1.806561043442881,-2.908947659043532
416.40000000000555,149.3607917563596,-1.8088502759064153,-2.9098190080702593
417.50000000000557,149.7207080173632,-1.8060347760604218,-2.9126599018078076
418.6000000000056,150.08140696662022,-1.8045613277427166,-2.914957912671314
419.70000000000556,150.44555127428814,-1.8060401463537987,-2.9189346934350144
420.8000000000056,150.80844938199496,-1.8068700477450677,-2.920889996197932
421.9000000000056,151.17390280670597,-1.805871712396681,-2.924850800550615
423.0000000000056,151.5355586725387,-1.8046151879728138,-2.927479995965533
424.10000000000565,151.9037392968213,-1.805531220155869,-2.9287941146184826
425.2000000000057,152.24947959357738,-1.8051931128797734,-2.931428531726953
426.3000000000057,152.6255851250816,-1.806080550009622,-2.934341932381548
427.40000000000566,152.9876873944142,-1.8065136933600472,-2.939329971567779
428.5000000000057,153.35350605306132,-1.8059146346272568,-2.9406590281488607
429.6000000000057,153.7137811575261,-1.8062351832216483,-2.941969879999111
430.70000000000573,154.08504603738197,-1.8065879098998265,-2.944609947070594
431.80000000000575,154.4430221722431,-1.8060629831908832,-2.9457787201775547
432.9000000000058,154.80824635574706,-1.8052299237815137,-2.948007343373486
434.0000000000058,155.1733999331312,-1.8034352308621526,-2.9529410007517574
435.1000000000058,155.53620580044003,-1.8035360360263706,-2.954052323287848
436.20000000000584,155.90230357263854,-1.8055339271633153,-2.954790144832668
437.3000000000058,156.26551516744698,-1.8045400750624359,-2.957780152976459
438.40000000000583,156.63107266900883,-1.805876762650918,-2.9597601559903532
439.50000000000585,156.99309582320473,-1.8054150260179516,-2.9623901940805037
440.6000000000059,157.358345223247,-1.8063680975813183,-2.96502990731436
441.7000000000059,157.72316541914304,-1.8054520161494056,-2.967659971979722
442.8000000000059,158.08583236471097,-1.8054799713263403,-2.9689798393627003
443.90000000000595,158.44934494705615,-1.8044848465606946,-2.970286675769038
445.0000000000059,158.81169737691886,-1.805301407029364,-2.971610151999425
446.10000000000593,159.1710708659853,-1.8049763217313297,-2.975556114607796
447.20000000000596,159.54420015933107,-1.8042772706825505,-2.9758900600000224
448.300000000006,159.90852792445662,-1.8031241585533861,-2.9785302018738538
449.400000000006,160.26702789604767,-1.8040725011540355,-2.9798399680001095
450.500000000006,160.63787187075312,-1.803632605848061,-2.9808299018967173
451.60000000000605,161.00201947014943,-1.8015776973537216,-2.983470098327296
452.70000000000607,161.3680844438228,-1.8006286122295685,-2.9861000168044547
453.8000000000061,161.72864470732023,-1.802329195156628,-2.9874198840301096
454.90000000000606,162.09729485780798,-1.8004429654173928,-2.988740156000026
456.0000000000061,162.46367237781132,-1.8028074612723117,-2.9913701960000005
457.1000000000061,162.8287198427655,-1.8007149452928106,-2.993239908146239
458.2000000000061,163.19788710111408,-1.8006620801666455,-2.9945500799990707
459.30000000000615,163.5615310780355,-1.8003094400656703,-2.9963032217610697
460.4000000000062,163.92844851191984,-1.798641845043925,-2.9978480429598493
461.5000000000062,164.293840129633,-1.7968995993703631,-3.0004801120748956
462.60000000000616,164.66174500942634,-1.7978700975648387,-3.0011399298028842
463.7000000000062,165.02086760310488,-1.795820933379616,-3.003567054541282
464.8000000000062,165.389875346588,-1.793483336293188,-3.006410167895877
465.90000000000623,165.75292554943593,-1.794416556288003,-3.00773004
467.00000000000625,166.12001530369997,-1.794661834099117,-3.009010553043867
468.1000000000063,166.4835329297122,-1.7941675943253992,-3.0102500783773647
469.2000000000063,166.84931366980592,-1.7938631068939337,-3.0138797794891277
470.3000000000063,167.21018564229593,-1.7936971679588014,-3.013819176063454
471.40000000000634,167.58207211187926,-1.7938597252491524,-3.0147598202983033
472.5000000000063,167.94617892137248,-1.7937062125044858,-3.0167298599999044
473.60000000000633,168.3129958269924,-1.792438722259981,-3.019369857522521
474.70000000000636,168.68102230329959,-1.7926405923557442,-3.0201887955227855
475.8000000000064,169.04063375199766,-1.7936056156816824,-3.021010172000022
476.9000000000064,169.41107799196544,-1.7921565762914933,-3.0216700324474313
478.0000000000064,169.77861825336308,-1.7905868968842993,-3.0249600845334896
479.10000000000645,170.14704826031897,-1.7896285230721993,-3.02627996766903
480.2000000000064,170.51017771961904,-1.7885045045373322,-3.027599815803468
481.30000000000643,170.8723977277356,-1.7880463463039094,-3.027650511163486
482.40000000000646,171.24546899494558,-1.7875692883942775,-3.0310045676905393
483.5000000000065,171.60966235706243,-1.7859654323380851,-3.031660152000052
484.6000000000065,171.9804103293751,-1.7865336795853017,-3.0329805595795754
485.7000000000065,172.34386879065417,-1.7851795600869609,-3.034290191992423
486.80000000000655,172.71290819812032,-1.7845150018924094,-3.0356100600005678
487.90000000000657,173.0661202145994,-1.7825826073832638,-3.036929928000003
489.0000000000066,173.4411628386718,-1.7856485542580833,-3.0402449858540983
490.10000000000656,173.80857837043547,-1.7857287276647607,-3.0388999238926218
491.2000000000066,174.17161102649263,-1.7852760873699667,-3.0412098501795923
492.3000000000066,174.541703385523,-1.7863432917981454,-3.0430799759999365
493.4000000000066,174.91293743923652,-1.785465275059598,-3.0443901354667844
494.50000000000665,175.27570210910156,-1.7838878252538939,-3.0447198898880874
495.6000000000067,175.64568383452243,-1.7856124362135277,-3.0466998840022717
496.7000000000067,176.0129329312986,-1.787830144243726,-3.0480201559999784
497.80000000000666,176.38327576392186,-1.7868044548344668,-3.0493299240004736
498.9000000000067,176.7498039865631,-1.7866537838161827,-3.049040213061481
500.0000000000067,177.1182211747924,-1.7860737569538052,-3.0519700639998493
501.10000000000673,177.47879867238612,-1.7839813069906696,-3.0529600684996234
502.20000000000675,177.84207805220296,-1.7849541600358418,-3.05459352607137
503.3000000000068,178.2130598553495,-1.7871724406950333,-3.0562392185161693
504.4000000000068,178.5767850047398,-1.7879706363466452,-3.056260176
505.5000000000068,178.9474029454866,-1.7897269313890884,-3.0592100800125746
506.60000000000684,179.31458934585177,-1.7906938958869072,-3.058230148000184
507.7000000000068,179.68109633479568,-1.7894162654232237,-3.0582657903225456
508.80000000000683,180.04954926694384,-1.7891604318126344,-3.0633880247224616
509.90000000000686,180.41688117273998,-1.7903832937621538,-3.0627569197655906
511.0000000000069,180.78669399960197,-1.788915253626522,-3.0623999096430166
512.100000000007,181.1474412110267,-1.7880012820654623,-3.0647475708472185
513.2000000000069,181.525826630217,-1.7888699822795495,-3.0656998399952102
514.300000000007,181.89101990536713,-1.7894239966539789,-3.066690044
515.4000000000069,182.2581343079116,-1.7891612394095004,-3.067999880336096
516.5000000000069,182.62525208557383,-1.7910112147833561,-3.0693200585878433
517.600000000007,182.99250625263454,-1.7924506074277144,-3.070639982451059
518.700000000007,183.36039743266087,-1.7920365293378526,-3.06965002000699
519.800000000007,183.73019495322944,-1.7898087897904444,-3.0719590066441005
520.900000000007,184.0952063746255,-1.7925833936578066,-3.0712110292341803
522.000000000007,184.46260174170487,-1.795808174360734,-3.0735998600102636
523.1000000000071,184.8311101627569,-1.7993041244417023,-3.075250131898911
524.2000000000071,185.20115342651474,-1.8006788121306716,-3.07495611496582
525.300000000007,185.56520541756996,-1.8003510894959007,-3.078200503975995
526.4000000000071,185.9367396905853,-1.7985967667997325,-3.076890187444968
527.500000000007,186.30019365458935,-1.8027385321556042,-3.0778801080000004
528.6000000000072,186.65896294187414,-1.8018146702002313,-3.0791963063157546
529.7000000000071,187.03699450291077,-1.801971220101073,-3.080950162659086
530.8000000000072,187.39427152356149,-1.8031269304833324,-3.0822699720000006
531.9000000000071,187.7736045760279,-1.8035349286075755,-3.0835898399999984
533.0000000000072,188.1391700000231,-1.8033499999991673,-3.0849101119999993
534.1000000000072,188.51250242138286,-1.804880160779124,-3.0849102952980254
535.2000000000072,188.90147329548563,-1.8025116848997527,-3.087210082652323
536.3000000000072,189.24635265412658,-1.8060172987126237,-3.0872111536237434
537.4000000000073,189.61931904921795,-1.8063408910638366,-3.0888600200759235
538.5000000000073,189.98317655214362,-1.8077562621060848,-3.089519888
539.6000000000073,190.3495434594281,-1.8079996124884277,-3.091485935055822
540.7000000000073,190.71874473360782,-1.8127175215337634,-3.0921499309899367
541.8000000000073,191.08687333004815,-1.8154208298047938,-3.0921499280007883
542.9000000000074,191.45602409141733,-1.8180180798159593,-3.0934481495608246
544.0000000000074,191.82316310253088,-1.8174292788782125,-3.0934699606664346
545.1000000000074,192.19058521400012,-1.8197808783257876,-3.096144837007677
546.2000000000073,192.56087984196202,-1.819452182481277,-3.0951199055511305
547.3000000000073,192.9314555394936,-1.8198440720691822,-3.097751140752396
548.4000000000074,193.2979881183703,-1.8213565358385013,-3.09776004379449
549.5000000000074,193.66832493606836,-1.8215557268850906,-3.0990827839382873
550.6000000000074,194.03783065507687,-1.8258457385151616,-3.1011934142859268
551.7000000000074,194.4030759528671,-1.825622159038085,-3.1008301757259145
552.8000000000075,194.77153409238457,-1.8289939649310454,-3.1014756108685395
553.9000000000075,195.1414550950807,-1.8288536507001294,-3.102479245379654
555.0000000000075,195.51250000002136,-1.830689999999796,-3.103789812
556.1000000000075,195.87465207494895,-1.831749145347479,-3.10408634436038
557.2000000000075,196.2458093767299,-1.831428521322033,-3.1057698424373625
558.3000000000076,196.61607067860322,-1.8315965191090682,-3.1054397726882823
559.4000000000076,196.98468422034145,-1.8335852166500852,-3.108051908332963
560.5000000000076,197.35465748957182,-1.835112015435722,-3.109395045447707
561.6000000000076,197.72731508650753,-1.8380351588453432,-3.1084051943141735
562.7000000000077,198.09681574716782,-1.839663127406929,-3.109059995885925
563.8000000000077,198.4663450008346,-1.841136974223686,-3.109388724231543
564.9000000000076,198.83894435242183,-1.841459796164963,-3.111022620019685
566.0000000000076,199.20843004554504,-1.8418472593231678,-3.1126937168044146
567.1000000000076,199.57849768545887,-1.8454322176928462,-3.112349836
568.2000000000077,199.94662055321734,-1.8473153685385746,-3.1116915308965494
569.3000000000077,200.31753718157626,-1.8500323752344543,-3.11366984000001
570.4000000000077,200.6853923506951,-1.849836426558399,-3.1143299759990244
571.5000000000077,201.05776671618221,-1.8503510325808636,-3.115610658231363
572.6000000000078,201.42716179037436,-1.852910973060899,-3.1156619747894454
573.7000000000078,201.79293828147448,-1.853771920838907,-3.115969852010248
574.8000000000078,202.16033143083976,-1.8546785781926973,-3.1172901520000003
575.9000000000078,202.5309401357735,-1.8591575358651489,-3.118280000389954
577.0000000000078,202.90786456683557,-1.8597551529225256,-3.1194556515704233
578.1000000000079,203.27550556619587,-1.8602170053664442,-3.1195998880000033
579.2000000000079,203.64557267691413,-1.862783829222755,-3.12058006
580.3000000000079,204.01546774230465,-1.8663783026939897,-3.12048774986993
581.4000000000078,204.38666476258632,-1.8676692419249585,-3.1222523584907744
582.5000000000078,204.75727119962633,-1.8681352646770182,-3.1215965828848993
583.6000000000079,205.12660360233377,-1.8703151380215228,-3.1222401847973753
584.7000000000079,205.49967459220684,-1.8739119109643965,-3.1235600683369196
585.8000000000079,205.86916691767348,-1.8757947046171346,-3.125089835999726
586.9000000000079,206.24058793152582,-1.877660567153164,-3.1250898360052117
588.000000000008,206.60986943998847,-1.8788519229997651,-3.1260855600645128
589.100000000008,206.979165103382,-1.8812197965701698,-3.126736043642132
590.200000000008,207.34884463869966,-1.88311443342393,-3.1260800308799843
591.300000000008,207.72372812894412,-1.8870373727442498,-3.1280496617246785
592.400000000008,208.09038584436243,-1.8874528389060785,-3.1280499647289908
593.5000000000081,208.46229017888075,-1.8930207989784635,-3.12937001596636
594.6000000000081,208.83493203169988,-1.8945523424387591,-3.1306884209939883
595.7000000000081,209.20784170399125,-1.896480482787951,-3.1293547813709273
596.8000000000081,209.58217441910887,-1.8997618302526718,-3.1303599965482776
597.9000000000082,209.95145328714915,-1.9027078494728735,-3.130438647673949
599.0000000000082,210.3242766034885,-1.9073513395560995,-3.132009955999956
600.1000000000081,210.6912667705396,-1.910521618531016,-3.133321160897249
601.2000000000081,211.06347048007055,-1.9103011462934467,-3.134639995997614
602.3000000000081,211.43363429190677,-1.9141352868531782,-3.1346399951885298
603.4000000000082,211.8005026134538,-1.9165917396218417,-3.135959863977507
604.5000000000082,212.18062135591904,-1.9212164041991797,-3.1345907962596806
605.6000000000082,212.52479514826547,-1.9201873112007037,-3.1360601047978927
606.7000000000082,212.91968052270136,-1.9256596088067777,-3.1361286074629637
607.8000000000083,213.2925038081037,-1.9284503831284525,-3.138370138450733
608.9000000000083,213.6616473286479,-1.930045608427343,-3.1387000400000913
610.0000000000083,214.03917000000342,-1.9299199999995056,-3.13870004
611.1000000000083,214.40991374500646,-1.934871308563348,-3.140349976
612.2000000000083,214.78271815291507,-1.9385410733957753,-3.140343904378249
613.3000000000084,215.15422842667695,-1.9393068079727105,-3.141000148
614.4000000000084,215.52329631465818,-1.9431055238167745,-3.141989947644459
615.5000000000084,215.8922278364961,-1.9453910482617287,-3.1433123471297435
616.6000000000083,216.2630273703329,-1.9517622240419945,-3.1433056907068426
617.7000000000083,216.6329191868913,-1.9516405179514498,-3.1439698840000005
618.8000000000084,217.00583440398725,-1.9558001376313907,-3.1440672317668414
619.9000000000084,217.38049351221449,-1.9592691493186765,-3.145304894476527
621.0000000000084,217.75250000000216,-1.9636599999996815,-3.145609924
622.1000000000084,218.1310357443466,-1.9651356659665515,-3.147040196
623.2000000000085,218.50132122733007,-1.9675009620890287,-3.147369505490582
624.3000000000085,218.87008526354253,-1.9713519127928054,-3.148692957029287
625.4000000000085,219.24056039483708,-1.9717914787496582,-3.149146258641766
626.5000000000085,219.61498147528857,-1.9754688653894128,-3.1500000688760057
627.6000000000085,219.98635308460996,-1.9776538262447847,-3.150000036
628.7000000000086,220.34811683707375,-1.9700194048984465,-3.150000034073653
629.8000000000086,220.72748643657474,-1.9105082084475609,-3.149864704088875
630.9000000000086,221.08985752829182,-1.906743051465092,-3.1500099061318556
632.0000000000086,221.45299492192296,-1.909059535288371,-3.1523100573970897
633.1000000000087,221.8301796811185,-1.9108142413541962,-3.1516582756742393
634.2000000000087,222.1999825029512,-1.9149351824713714,-3.152980048290262
635.3000000000086,222.56776099774564,-1.918695422007578,-3.1530790341108257
636.4000000000086,222.9418900634061,-1.9206561864238965,-3.152650087891439
637.5000000000086,223.31058569018708,-1.9203358711793796,-3.1555873266616814
638.6000000000087,223.6864686189428,-1.9226308441359037,-3.1539598853861435
639.7000000000087,224.05641441206882,-1.9253028710079714,-3.155280092442883
640.8000000000087,224.4294427482198,-1.9260483945528128,-3.1565999959155535
641.9000000000087,224.8075401039069,-1.929553122955787,-3.15693002
643.0000000000088,225.17461639263774,-1.9304138454835715,-3.1584443606315005
644.1000000000088,225.5471757413166,-1.933997766823393,-3.1588842761610616
645.2000000000088,225.9153335153514,-1.9354059213098516,-3.1592301365723046
646.3000000000088,226.2841236711026,-1.9399088664375705,-3.15988986
647.4000000000088,226.65434801087673,-1.9384320456854238,-3.1605499960000003
648.5000000000089,227.0229309907044,-1.9405198880119445,-3.161210132
649.6000000000089,227.3925100657196,-1.943489971246139,-3.1631899983523475
650.7000000000089,227.76020004263194,-1.9447913601137565,-3.161539932
651.8000000000088,228.13526669877487,-1.9487756674304602,-3.164170104
652.9000000000088,228.51104527106702,-1.9507177057044793,-3.1654899719999996
654.0000000000089,228.89195551123157,-1.9511444124983812,-3.1654899210904484
655.1000000000089,229.26426546524007,-1.9549436044184272,-3.1651589661993302
656.2000000000089,229.6328180508265,-1.9568869535645481,-3.1648356741716563
657.3000000000089,230.0104465318419,-1.9588220281155087,-3.167800112072526
658.400000000009,230.37916436211114,-1.9636914661714822,-3.167570416555151
659.500000000009,230.74879821642244,-1.9614205740978239,-3.168779934265658
660.600000000009,231.11917634010715,-1.9649302553077432,-3.1694401519979776
661.700000000009,231.4882750825863,-1.9682537666663074,-3.169769815999998
662.800000000009,231.85493827295397,-1.9698859080202438,-3.1697698160566006
663.9000000000091,232.23419770570146,-1.975521225821541,-3.17014830233365
665.0000000000091,232.6119028523558,-1.9790176810834108,-3.171885515873245
666.1000000000091,232.9842331329185,-1.9794126094354116,-3.171198972094155
667.2000000000091,233.35163635187124,-1.9823239446848462,-3.1715299506377264
668.3000000000092,233.72429192041088,-1.9832747720797206,-3.172840128
669.4000000000092,234.09716237901802,-1.9866889454470102,-3.1728432806873332
670.5000000000091,234.46676935582786,-1.9876324449490121,-3.172839995262631
671.6000000000091,234.84017085465874,-1.9904055647215504,-3.1741740326978904
672.7000000000091,235.21162558812972,-1.9930555247965833,-3.175795512280329
673.8000000000092,235.58009266780363,-1.9937059475617231,-3.17481986392977
674.9000000000092,235.94977652514672,-1.9997076115120307,-3.1774513375964992
676.0000000000092,236.32186287977598,-2.003152852788167,-3.177123940603243
677.1000000000092,236.69396323086858,-2.0032360159827673,-3.1782700855694754
678.2000000000093,237.06612343627773,-2.0055166963228843,-3.177468981705741
679.3000000000093,237.43665077955785,-2.0066411939790956,-3.178119908250174
680.4000000000093,237.80649384772295,-2.0069112761954653,-3.178879812201687
681.5000000000093,238.17882588828112,-2.0095268019823975,-3.182523719130656
682.6000000000093,238.54992286616377,-2.01153950601113,-3.181079807948409
683.7000000000094,238.92226150203953,-2.015332634411751,-3.1823012072095787
684.8000000000094,239.29331268363202,-2.019445521197731,-3.183059825771898
685.9000000000094,239.6585693455945,-2.017585687501276,-3.1833898879999953
687.0000000000093,240.04014215438016,-2.02135145484049,-3.184369992
688.1000000000093,240.40516795822006,-2.020703540203512,-3.1847000642706558
689.2000000000094,240.77354198052146,-2.0222437805124556,-3.185689927999977
690.3000000000094,241.14568954872715,-2.0266350404063833,-3.18699108156503
691.4000000000094,241.52377910938176,-2.0278942387469505,-3.187009214724633
692.5000000000094,241.90069564529315,-2.0293648899045444,-3.186797800719842
693.6000000000095,242.26708838379952,-2.031488695756041,-3.1887551852037954
694.7000000000095,242.64278679925178,-2.0331557457065026,-3.189969904000094
695.8000000000095,243.01281170728623,-2.0348448765268796,-3.191286845906667
696.9000000000095,243.384184311125,-2.038784188241439,-3.1907933251938907
698.0000000000095,243.76063917786408,-2.0396387783098655,-3.190959976369432
699.1000000000096,244.13379383672358,-2.0407707838697693,-3.1927190095566464
700.0000000000095,244.43779641619275,-2.045229356541901,-3.191729844