File: 01_Data/Nylon_Carpet_Low_Pile/STA/N2/10K_min/Nylon_Carpet_Low_Pile_STA_N2_10KData_220106_R3.csv
##Temp./Â°C,Time/min,DSC/(mW/mg),Mass loss/mg
50.0,10.752393019960929,0.04533391354037497,-0.0035850855313084296
51.20000000000002,11.074444944332761,0.09325793158758222,-0.001959065978222263
52.400000000000034,11.297504506435228,0.12635777056921926,-0.0022846231936339834
53.60000000000005,11.481040282243676,0.15026619219980275,-0.0002755185431855267
54.80000000000007,11.648353478928637,0.17331975091517782,-0.0025442159008690624
56.000000000000085,11.803956186178906,0.18863000595435353,-0.00262728449561056
57.2000000000001,11.952651115694794,0.2004286288488285,-0.0010437004621088875
58.40000000000012,12.09511469615543,0.21114117527420095,-0.001265383462305536
59.600000000000136,12.234489521219404,0.21991148411119132,-0.0011659230495268957
60.80000000000015,12.37174829502005,0.2259594504876748,-0.0009648436021505447
62.00000000000017,12.50698080825284,0.23314464851917938,-0.0028504318117041905
63.20000000000019,12.641169151900243,0.23968651250225464,-0.0036147225731157917
64.4000000000002,12.773431533917694,0.24629009992188616,-0.002916617654922682
65.60000000000022,12.90381419821443,0.24762044827270946,-0.0022957549767488317
66.80000000000024,13.034374701192418,0.2510812204427702,-0.001821573461646686
68.00000000000026,13.163171438127382,0.2546964591424953,-0.002737294523398326
69.20000000000027,13.291511412203075,0.25819443147517807,-0.002290197652604853
70.40000000000029,13.421814973996083,0.2616064799732549,-0.0022999400497649702
71.6000000000003,13.548962559868393,0.26663512474281215,-0.0036097945840047885
72.80000000000032,13.675726676777753,0.26962715801660275,-0.003928081664089866
74.00000000000034,13.80270184227458,0.27478443458758034,-0.003621054597743978
75.20000000000036,13.928257069193236,0.2789198321801463,-0.003610373948198742
76.40000000000038,14.054732284714078,0.28082555022456296,-0.0036032135477883642
77.60000000000039,14.178831737454399,0.28150819899682283,-0.0036094139719011764
78.80000000000041,14.30399473752248,0.28434077446995376,-0.003591796427528493
80.00000000000043,14.427505043215774,0.2874323971497005,-0.0036147263763828263
81.20000000000044,14.552263706625503,0.29042864705911114,-0.0049298748511619195
82.40000000000046,14.675178614450697,0.2932882649546747,-0.005000672165444087
83.60000000000048,14.798023082070996,0.29506793155849076,-0.007445877249755206
84.8000000000005,14.921483307853633,0.29736030353318366,-0.007482409565803927
86.00000000000051,15.041917869759763,0.30043290224815966,-0.006240087740554401
87.20000000000053,15.16305845042376,0.3022395465242242,-0.004918551852002295
88.40000000000055,15.282209361042982,0.30305878632837435,-0.004929501171009321
89.60000000000056,15.405345304267751,0.3068003720228869,-0.00493662260032135
90.80000000000058,15.526230047391083,0.3081126291079264,-0.006240199378209965
92.0000000000006,15.645109212019062,0.30924182023836644,-0.007560073690457081
93.20000000000061,15.765338185948465,0.3117188824068219,-0.006249653521604337
94.40000000000063,15.88703755496061,0.3141576777628765,-0.007559954962576221
95.60000000000065,16.00573768595039,0.31772096735680927,-0.007555370856713317
96.80000000000067,16.12511662844216,0.31927344930010965,-0.007564475797632753
98.00000000000068,16.244189241467758,0.32146972992556466,-0.007800239942121756
99.2000000000007,16.36265570523602,0.3224681140005141,-0.007575794380407785
100.40000000000072,16.48168908439792,0.3265320688173631,-0.007559563233749067
101.60000000000073,16.599903198462282,0.3251548469785158,-0.008211581467878482
102.80000000000075,16.718229933340282,0.32892107752452593,-0.008220086155732886
104.00000000000077,16.836482439883486,0.32876859141359877,-0.008219736340910444
105.20000000000078,16.95486949671801,0.3329675922153911,-0.008868998670685357
106.4000000000008,17.072485513129386,0.33216659804937826,-0.0088799636154695
107.60000000000082,17.191349847327007,0.3335249350745502,-0.010201513211749003
108.80000000000084,17.309082981626744,0.3327785184861381,-0.00888001872672195
110.00000000000085,17.42681131555442,0.3341378747226388,-0.009859589569039429
111.20000000000087,17.545362489628733,0.33435312458303,-0.008902649043262656
112.40000000000089,17.662631007246183,0.33666490977298247,-0.010190146414258194
113.6000000000009,17.781116528033166,0.3366079492109054,-0.011510587527273408
114.80000000000092,17.896843799852576,0.33804336282422826,-0.010199620851786051
116.00000000000094,18.014108216201627,0.3377807756766268,-0.010199951188498702
117.20000000000095,18.13227949389895,0.33770473905215714,-0.009338593886392133
118.40000000000097,18.24878807044988,0.33919286509372726,-0.010190117244511576
119.60000000000099,18.3660771384606,0.3384470199081628,-0.011180110681690891
120.800000000001,18.484171423617877,0.33941666951340294,-0.009869900842025103
122.00000000000102,18.600846789054042,0.33864378713174387,-0.010201254123279213
123.20000000000104,18.71830879650202,0.3428672821858917,-0.010262316969512852
124.40000000000106,18.834736024874463,0.3414964773455638,-0.011458738870213203
125.60000000000107,18.95157897098136,0.34274772076630655,-0.01184006002867477
126.80000000000109,19.06860935162112,0.34281212628835217,-0.013195171863610966
128.0000000000011,19.185838072055155,0.3418284400597967,-0.011840166661673202
129.20000000000113,19.303161232102763,0.3439379438557202,-0.013147441333175358
130.40000000000114,19.41901045299457,0.3457537789622809,-0.011839990353315955
131.60000000000116,19.536289646815657,0.3453014952995721,-0.012629000395523171
132.80000000000118,19.653268791764994,0.3457236170481841,-0.013159990002657551
134.0000000000012,19.769146528080427,0.3463643562029334,-0.011766364615565905
135.2000000000012,19.885195651714604,0.3472239576608585,-0.013160094685658486
136.40000000000123,20.002835342339857,0.34860893591086617,-0.013160094999997263
137.60000000000124,20.119254786235025,0.34984118783039786,-0.013160083382318888
138.80000000000126,20.234951029755205,0.35124153279193954,-0.013083986480344478
140.00000000000128,20.350373386842513,0.35187136069910246,-0.01315020000271172
141.2000000000013,20.467423166171002,0.35485806254514984,-0.013145020644699912
142.4000000000013,20.583576076945477,0.35532335325034814,-0.01579014315251559
143.60000000000133,20.699552227086464,0.3564843285486152,-0.015129379499478013
144.80000000000135,20.81519425284086,0.3599250180609485,-0.015785819693904912
146.00000000000136,20.930696960421656,0.3619806478435985,-0.014469835187787439
147.20000000000138,21.046588350161585,0.363555739171762,-0.014470024999662101
148.4000000000014,21.16219196769748,0.3658025686962654,-0.014470828010705539
149.60000000000142,21.27813667079056,0.3654704366996302,-0.015790022516895874
150.80000000000143,21.394283928318227,0.3717095959665543,-0.014801634770922334
152.00000000000145,21.510451049228944,0.3739520033548247,-0.015777918782844402
153.20000000000147,21.62482740315415,0.3790671159230289,-0.015790129995690627
154.40000000000148,21.740489587977077,0.3856943102409433,-0.015790130000455704
155.6000000000015,21.85576178233319,0.390790519489734,-0.01579034432482551
156.80000000000152,21.971764699850436,0.3971340103386627,-0.014967528173784217
158.00000000000153,22.087427106741824,0.40754669553466755,-0.0144700578658421
159.20000000000155,22.201956085094047,0.4133114126610832,-0.01443984982481794
160.40000000000157,22.317805044094044,0.4258218033836375,-0.015790059534100287
161.6000000000016,22.433287482600676,0.43318637261383164,-0.01579006717323761
162.8000000000016,22.54866598833836,0.44307892263600124,-0.01846041934091236
164.00000000000162,22.66315376874707,0.45176406768363264,-0.01664840068276252
165.20000000000164,22.779694320989556,0.45771477174425756,-0.017100317966862733
166.40000000000165,22.894538564741516,0.45378094104717615,-0.018407558969025573
167.60000000000167,23.009811755111297,0.4457227851252963,-0.017426106742088443
168.8000000000017,23.12457054181116,0.43361867579438546,-0.01754531654617164
170.0000000000017,23.240663706748098,0.4185039306857867,-0.01804011879747769
171.20000000000172,23.35493573767141,0.4097942975739315,-0.018090084845678867
172.40000000000174,23.47009534810367,0.39909931433618107,-0.01809008999936257
173.60000000000176,23.58417515877731,0.3933296965329909,-0.018148630168749236
174.80000000000177,23.70000000000016,0.3894139766992663,-0.017422729557946326
176.0000000000018,23.81533524008019,0.3837126158825904,-0.018424755021670514
177.2000000000018,23.930612524464212,0.38492688934852015,-0.017759914735925975
178.40000000000182,24.046119836602042,0.3837221044752698,-0.018088763263921948
179.60000000000184,24.1610889172675,0.38488475927550203,-0.018082371043992573
180.80000000000186,24.276603560350814,0.38605575528643515,-0.017758355061370246
182.00000000000188,24.390284553493146,0.38676657411657067,-0.01907421964835443
183.2000000000019,24.504494801764956,0.3892121390372315,-0.019081045570490396
184.4000000000019,24.619724635339477,0.3911003892918463,-0.019079944999973897
185.60000000000193,24.73393902818913,0.3910171872614442,-0.019079911591452614
186.80000000000194,24.847827999803158,0.39430315132493665,-0.018420360295362315
188.00000000000196,24.964269953216153,0.3947499021211034,-0.018433309427650535
189.20000000000198,25.079638913381388,0.3964547365508613,-0.019080151419743174
190.400000000002,25.194276551235273,0.39611333597689546,-0.019080174999824173
191.600000000002,25.308295206157126,0.3975189935203084,-0.019080242213930454
192.80000000000203,25.422938181772235,0.3997234884578918,-0.01874792469472375
194.00000000000205,25.538430275930647,0.4020667160006458,-0.020433377543567666
195.20000000000206,25.65160877934671,0.40317230756851374,-0.01907987521457155
196.40000000000208,25.76729321189856,0.4024449634589164,-0.019077073716787574
197.6000000000021,25.881853447178205,0.40566743818974255,-0.020398935247394334
198.80000000000211,25.99664704206524,0.405877053059975,-0.020389731964748137
200.00000000000213,26.111110953217363,0.40852765458060203,-0.020071399854414196
201.20000000000215,26.226409996049476,0.41036155090891446,-0.022042698025700247
202.40000000000217,26.33972344824379,0.4123090841911282,-0.02336854462213278
203.60000000000218,26.45516557644043,0.4166047048717725,-0.02072925063358344
204.8000000000022,26.570529898916586,0.4193641976087383,-0.020721196891353877
206.00000000000222,26.68485246076066,0.42429334312013756,-0.022040705995744148
207.20000000000223,26.79885758094153,0.42738364755452485,-0.02204245394562676
208.40000000000225,26.91506278185769,0.42995168756893565,-0.0207225296295519
209.60000000000227,27.029999052684,0.4375289682885729,-0.02334968671773119
210.80000000000229,27.143569765037732,0.4446740496347733,-0.024771689566854604
212.0000000000023,27.259520325418215,0.45346166890272127,-0.023464305463489765
213.20000000000232,27.37432699810502,0.46903169887709517,-0.02246990088076295
214.40000000000234,27.489802856304976,0.4943465944658571,-0.0237897951236139
215.60000000000235,27.603558550060548,0.5400305010885098,-0.023789800000104222
216.80000000000237,27.718152565121656,0.5973209672453603,-0.023789584767885508
218.0000000000024,27.83428315808869,0.665809367076725,-0.02378962062571599
219.2000000000024,27.94971543062241,0.7324577778040298,-0.023490803337088195
220.40000000000242,28.064164326681027,0.7852986949793703,-0.023580967121756835
221.60000000000244,28.17895881583978,0.8070023021554418,-0.023720820074481175
222.80000000000246,28.29402457105279,0.7758898144325428,-0.024450090423380644
224.00000000000247,28.410000000000235,0.7044886681618977,-0.023799274418881744
225.2000000000025,28.524192757788775,0.6297155142454838,-0.023799732898074133
226.4000000000025,28.638683306876267,0.5657699400627091,-0.025110029643797382
227.60000000000252,28.752563457516903,0.5182746792345221,-0.025439806170136414
228.80000000000254,28.86646424016199,0.48775132188301384,-0.025412037559616074
230.00000000000256,28.98055351046927,0.46567564431001285,-0.02511994936917361
231.20000000000258,29.094739621338597,0.45032691006045306,-0.02511995319838256
232.4000000000026,29.2087673263337,0.44007968253997154,-0.026428001246994626
233.6000000000026,29.323348731766853,0.43465109861037404,-0.025121837245671408
234.80000000000263,29.4385519854327,0.4314085940994494,-0.02511004501532188
236.00000000000264,29.55203124440069,0.43173394572584195,-0.026430218219261725
237.20000000000266,29.66586475177377,0.4287647732722085,-0.027856379680933685
238.40000000000268,29.780284022930473,0.4299632921661547,-0.027771977235672374
239.6000000000027,29.894881910019095,0.43032684439551755,-0.029302030415875535
240.8000000000027,30.01009183290709,0.4300040115510309,-0.030369915284405913
242.00000000000273,30.123630643570188,0.4318295262119608,-0.027599680911220226
243.20000000000275,30.24000000000029,0.4316243615622926,-0.028410020513391032
244.40000000000276,30.353094778058487,0.42938532898983983,-0.030369941673672685
245.60000000000278,30.46503040766783,0.4314857307515724,-0.03048888603933353
246.8000000000028,30.581755867942146,0.4308516293872278,-0.029387382500930315
248.0000000000028,30.69657269962276,0.4314445547766781,-0.029059608386798885
249.20000000000283,30.81156832119199,0.4330333619137939,-0.03179575553539493
250.40000000000285,30.927179388458725,0.4327611854550133,-0.0325288738947096
251.60000000000286,31.041752909191892,0.4322303490575771,-0.03279262220975365
252.80000000000288,31.155751076957735,0.43297319267085643,-0.031000490750647813
254.0000000000029,31.27000000000026,0.43540098043029823,-0.030489367284022073
255.20000000000292,31.385028414086687,0.434817041632555,-0.03113969722038057
256.40000000000293,31.499811179555675,0.43478760302889224,-0.029838957258697896
257.600000000003,31.613286606902808,0.4371198491916556,-0.031139749701357466
258.80000000000297,31.728369266220064,0.4384057340060452,-0.03280111383612461
260.00000000000296,31.843541033665172,0.43715945056289474,-0.03506573801726098
261.200000000003,31.95795413951691,0.4382077638873104,-0.03378793112507772
262.40000000000305,32.073182139091806,0.44097540715480676,-0.03376981000257473
263.60000000000304,32.18702635483531,0.4380563252696679,-0.03376980992062695
264.800000000003,32.30234344743169,0.441452319708687,-0.03455440339267746
266.00000000000307,32.41674008647285,0.4383174984034842,-0.03508981008398315
267.2000000000031,32.530630391531645,0.43795232500230963,-0.03469702198032998
268.4000000000031,32.646930830677405,0.43930121630355723,-0.035053681927313285
269.6000000000031,32.760255773856926,0.4402489978246859,-0.03619016898516936
270.80000000000314,32.875205924274056,0.4411105383974878,-0.03483371454365525
272.0000000000032,32.990706605057284,0.4404311627046661,-0.036646027125374125
273.2000000000032,33.106086206063125,0.44033092323259293,-0.03795478321699264
274.40000000000316,33.220577347261134,0.44063886372266203,-0.036959800518413743
275.6000000000032,33.33476422436204,0.4411924762483788,-0.0369598000000817
276.80000000000325,33.45134457036088,0.44073562353900714,-0.036959688156342096
278.00000000000324,33.56679154511044,0.4430717103627584,-0.03841303160314524
279.20000000000323,33.681136206472274,0.4408700874789385,-0.038390094910869976
280.4000000000033,33.796353083957015,0.44330035581620914,-0.03839009999997334
281.6000000000033,33.9111328290517,0.4442315281913784,-0.03839014578615263
282.8000000000033,34.026319734137935,0.4424838657753357,-0.04100998013403512
284.0000000000033,34.14139839244069,0.4422255377084181,-0.04166960523422869
285.20000000000334,34.256137419352896,0.4435483489970302,-0.041669870369450024
286.4000000000034,34.372155630567455,0.4446553521583795,-0.04066057165726633
287.6000000000034,34.48719751002827,0.4448979499010362,-0.040680325404697015
288.80000000000337,34.60107525379471,0.44713934521722654,-0.041339867350506765
290.0000000000034,34.71727376497961,0.44661149265543,-0.04263518906440655
291.20000000000346,34.832765183088625,0.447531851022081,-0.04266065709028943
292.40000000000344,34.947719827717144,0.44891214800393625,-0.043978619557140775
293.60000000000343,35.06377131812758,0.45370357069021094,-0.041096946162460846
294.8000000000035,35.17750811471482,0.45087969420275276,-0.040313421898088286
296.0000000000035,35.29301188047815,0.45280818940292145,-0.046172461390864505
297.2000000000035,35.408569180849256,0.4559795167670293,-0.04366898265859209
298.4000000000035,35.52390765119549,0.4555257200070453,-0.04496813412815648
299.60000000000355,35.63944915244701,0.4543134955208652,-0.044970080998608886
300.8000000000036,35.75365588903175,0.45764417018576564,-0.04627982512122131
302.0000000000036,35.86932358192002,0.4582118017593898,-0.0489103002122766
303.20000000000357,35.981328169269666,0.4596084772704862,-0.0499628731218591
304.4000000000036,36.09980339476688,0.4593058585916044,-0.04912971731929616
305.60000000000366,36.21512666139448,0.4614557993979331,-0.05049975213764135
306.80000000000365,36.330828564393656,0.4623779234955551,-0.05043213344435893
308.00000000000364,36.44584342654882,0.4658196297374422,-0.05175986650679043
309.2000000000037,36.56009198532554,0.4689251051572526,-0.05308235434945585
310.40000000000373,36.675952986510765,0.4733609958551527,-0.05439053968025176
311.6000000000037,36.79276863940643,0.4741509024933515,-0.055713443093518666
312.8000000000037,36.90840127027279,0.4747782583524794,-0.0565356224187048
314.00000000000375,37.02304848831052,0.47778015816679914,-0.05835891143309002
315.2000000000038,37.139243745819,0.4774465694055896,-0.06097357816325566
316.4000000000038,37.25384535902965,0.4786606223979812,-0.060912761051374886
317.6000000000038,37.370258980945735,0.48054077509226506,-0.06228994558201295
318.8000000000038,37.48585850206786,0.48084101480422425,-0.06360978870508482
320.00000000000387,37.60285090240447,0.4857688191153972,-0.06761031271149998
321.20000000000385,37.71809130304867,0.48892370011417524,-0.07017637512687402
322.40000000000384,37.83284995312618,0.49018487371821173,-0.07150718246220622
323.6000000000039,37.94913451883358,0.4942122216971994,-0.07413687737037522
324.80000000000393,38.06379152946255,0.4985956719788246,-0.07676570460716592
326.0000000000039,38.180354249584155,0.5032476660681412,-0.080093418629132
327.2000000000039,38.29534401837096,0.5069512860107213,-0.08201242348179827
328.40000000000396,38.41083463658977,0.5104307344723553,-0.08547606038335864
329.600000000004,38.526654437530524,0.515376779606525,-0.08941055098926087
330.800000000004,38.64302494670832,0.5194213183284848,-0.093670458938933
332.000000000004,38.75817015446962,0.5239081877716146,-0.09594694096842415
333.200000000004,38.8749484878008,0.5295929680293594,-0.10050166522191128
334.40000000000407,38.990928428130644,0.536593447107532,-0.10456047974010696
335.60000000000406,39.105995552147846,0.540782811278151,-0.11045205315159556
336.80000000000405,39.22281550026949,0.5465806395921415,-0.11450689167720896
338.0000000000041,39.338700124926056,0.5570863620979969,-0.1190019015841437
339.20000000000414,39.45421994606638,0.5624608814365555,-0.1263511501579906
340.4000000000041,39.570802273145084,0.5694242995712178,-0.13133098540717114
341.6000000000041,39.68720369866706,0.5762355130553314,-0.14008087778877254
342.80000000000416,39.802858969870066,0.5854531742801359,-0.14638270928677422
344.0000000000042,39.92028038517439,0.5945362102205755,-0.15479021053857078
345.2000000000042,40.035856991384364,0.6003554428162787,-0.16347851637594335
346.4000000000042,40.152895483494866,0.6129361952149464,-0.17265016664676924
347.60000000000423,40.26926373091476,0.6220741730147428,-0.18005910007782155
348.8000000000043,40.385576248339035,0.6353559868429376,-0.18981655887803717
350.00000000000426,40.502708301110445,0.6441960072014605,-0.19810427064533442
351.20000000000425,40.61840839103013,0.6573424316848486,-0.20850431598510122
352.4000000000043,40.735551082061974,0.668871388161287,-0.22156474513705504
353.60000000000434,40.85116329374235,0.6798184120091976,-0.23373633679656303
354.80000000000433,40.965416120827264,0.6887024738484173,-0.24545988212587266
356.0000000000043,41.08456059178829,0.7009443088812017,-0.2582002814963089
357.20000000000437,41.20068735538166,0.7106835844968444,-0.2716411798245182
358.4000000000044,41.317005130004915,0.7215631197602528,-0.2864627075624413
359.6000000000044,41.434731996404444,0.7341681701796967,-0.3010342905237806
360.8000000000044,41.55075156840919,0.7456298455636194,-0.3166635483348421
362.00000000000443,41.66822691291332,0.7549176239586712,-0.33181287147853356
363.2000000000045,41.78394860020639,0.7653471876686313,-0.34899163980821823
364.40000000000447,41.90039956016294,0.776917222745068,-0.36627546808025047
365.60000000000446,42.016613594663454,0.7849336553215636,-0.3805973528429618
366.8000000000045,42.13389968971543,0.7973793540787277,-0.4014132501386789
368.00000000000455,42.250653640984204,0.8107394746689462,-0.41900087434427835
369.20000000000454,42.36689990137693,0.8218720361562442,-0.4388338840373125
370.4000000000045,42.48257819054483,0.8315674561894606,-0.4579509305674132
371.60000000000457,42.600635411568184,0.8442824773976911,-0.4796689939667096
372.8000000000046,42.716884060293495,0.8569292054817933,-0.5004657933878449
374.0000000000046,42.833782698405116,0.8676680418556517,-0.5215797974176892
375.2000000000046,42.950688613603155,0.8809883262230818,-0.5458004375994614
376.40000000000464,43.06703528774591,0.8949605313374848,-0.5676857939156545
377.6000000000047,43.184394372754106,0.9066871446656436,-0.5909273840735478
378.8000000000047,43.300769289086034,0.9162264751265032,-0.6169516001018231
380.00000000000466,43.41892878376125,0.9316214342295159,-0.6440883268507087
381.2000000000047,43.53472013656669,0.9443429788519361,-0.6698785764810742
382.40000000000475,43.65212567808629,0.9567570351142713,-0.6981935495953815
383.60000000000474,43.769330228823264,0.9689769938343811,-0.7281296977553633
384.80000000000473,43.88646417630603,0.979835147148759,-0.7579447665829901
386.0000000000048,44.00323063730417,0.9878405240631506,-0.7881457622423644
387.2000000000048,44.11999904025912,0.9956795910403191,-0.8204497731481215
388.4000000000048,44.23760706267978,1.0052355534553497,-0.8500964793988781
389.6000000000048,44.35508328891673,1.009842700602983,-0.8822199209541952
390.80000000000484,44.47115569351238,1.0128841611064583,-0.9163910260820414
392.0000000000049,44.58944751349459,1.010589964690441,-0.9502576521788906
393.2000000000049,44.70620933946464,1.0113485066542278,-0.9859947177887238
394.40000000000487,44.82180980065859,0.9992851924343354,-1.0157587854033507
395.6000000000049,44.939438819326774,0.9880287806910362,-1.0527346742903867
396.80000000000496,45.05635202655358,0.9728058943696222,-1.08892054685329
398.00000000000495,45.17345615661436,0.9495120918227482,-1.1188521679272476
399.20000000000493,45.29075332936658,0.923090562383241,-1.1516968546305164
400.400000000005,45.40687790548292,0.8868694706221314,-1.1831068192566825
401.600000000005,45.52223657258414,0.8491512361813467,-1.2127932399564743
402.800000000005,45.64026984776931,0.8088067596871485,-1.2407802156408647
404.000000000005,45.756925010664034,0.7617923389977717,-1.2686799279316476
405.20000000000505,45.8733902531083,0.718414209001278,-1.2926292414555602
406.4000000000051,45.99054772485211,0.6760267744901451,-1.3135431544683493
407.6000000000051,46.10722222727749,0.632529832896473,-1.3337605035299522
408.80000000000507,46.22347016190854,0.5972621798426172,-1.3521973757852552
410.0000000000051,46.34000000000048,0.5700649047845292,-1.369437058035528
411.20000000000516,46.4567165239167,0.5435144952701062,-1.3840553303094971
412.40000000000515,46.57441182977531,0.5207166700385287,-1.3989789563138348
413.60000000000514,46.690999258484865,0.5044496785667607,-1.4116918886248357
414.8000000000052,46.80812282255944,0.49149377175869857,-1.4225187653848312
416.00000000000523,46.926039886020284,0.48433740464408537,-1.4330232440642043
417.2000000000052,47.04237974398084,0.47692694298319427,-1.4451211025638107
418.4000000000052,47.16030389147565,0.4731719092337823,-1.4544623732166815
419.60000000000525,47.27791439491622,0.46883070228897095,-1.4644904045241551
420.8000000000053,47.39486760283902,0.46657316043040387,-1.4751966329386677
422.0000000000053,47.5124189442634,0.4609988371797519,-1.4851193602811064
423.2000000000053,47.63019166668763,0.46263788237417236,-1.4973310511939006
424.4000000000053,47.74695885339906,0.4574247144792126,-1.5056855334446784
425.60000000000537,47.86468909368011,0.4594504411299931,-1.5135747293084476
426.80000000000535,47.9825655387405,0.4579674914236733,-1.525494362023875
428.00000000000534,48.09980503999565,0.45639989457539365,-1.533936361843244
429.2000000000054,48.21706706149147,0.4588743464281807,-1.5439112400876294
430.40000000000543,48.33475030916222,0.4565068515841282,-1.5530967950081247
431.6000000000054,48.453009471583684,0.4558386624531835,-1.5613299202306141
432.8000000000054,48.569138384748406,0.45783416417811695,-1.571096579045824
434.00000000000546,48.68792551840895,0.4557373404534153,-1.5826498516628105
435.2000000000055,48.80585265397487,0.45638062742594376,-1.5929299335417122
436.4000000000055,48.924136474034846,0.454607656080368,-1.6009792721138743
437.6000000000055,49.04149582376787,0.45469041284186074,-1.6116811883499969
438.8000000000055,49.15912824914217,0.45225696719165875,-1.6216177686656557
440.00000000000557,49.27762080682349,0.45458463676572514,-1.6330619516402956
441.20000000000556,49.394714804974534,0.4551850892450625,-1.6438439019503366
442.40000000000555,49.51359910238877,0.457295480024256,-1.6534495759500292
443.6000000000056,49.63220472443545,0.4584084982888137,-1.6643747630093677
444.80000000000564,49.74584253513482,0.4580161906888418,-1.6756945479571552
446.0000000000056,49.867506387926355,0.46033634767869114,-1.6867414928177453
447.2000000000056,49.98630881257592,0.45898074116414167,-1.6994681595473873
448.40000000000566,50.10423873155526,0.45892940387202197,-1.708625849978854
449.6000000000057,50.22198172220595,0.4623940491037285,-1.7204357228754557
450.8000000000057,50.34058331892897,0.4623498649391006,-1.7332959973903783
452.0000000000057,50.45617487278265,0.4616238277294539,-1.7439729582906196
453.20000000000573,50.575932353431035,0.46397445535558823,-1.7573672768835964
454.4000000000058,50.69484426380595,0.46399534108977447,-1.7673408866572182
455.60000000000576,50.81234480770506,0.46675698650721753,-1.781085004110218
456.80000000000575,50.93000100024559,0.4648561789061395,-1.7941300070284503
458.0000000000058,51.048988661723314,0.4658235292880547,-1.8061022124768233
459.20000000000584,51.16668898605404,0.46602778926904476,-1.8178938918820222
460.40000000000583,51.284218625747,0.4680338460576977,-1.8294513913567623
461.6000000000058,51.4027497221555,0.4665625151743227,-1.8426868524591327
462.80000000000587,51.520342953589186,0.46277955684611694,-1.8573523238000336
464.0000000000059,51.63969176400578,0.46291183356252763,-1.8684418653189088
465.2000000000059,51.75693136371532,0.46018152305607063,-1.8779466283304918
466.4000000000059,51.875526734516654,0.4555376104859702,-1.8933860002810556
467.60000000000593,51.99420892940218,0.4514966711881201,-1.9056325317483411
468.800000000006,52.112603157136824,0.4420692606274361,-1.9199528441705018
470.00000000000597,52.23124138838066,0.4333464051194703,-1.9283774917119327
471.20000000000596,52.34838671622369,0.41896116998392685,-1.9396530213381946
472.400000000006,52.467205348661416,0.4079626004180399,-1.9508620030227921
473.60000000000605,52.58513131968119,0.3893437439725491,-1.961381286771024
474.80000000000604,52.70392878689074,0.37198846792351936,-1.9700347950245418
476.000000000006,52.82229245175977,0.35125281440716694,-1.9774102877084427
477.20000000000607,52.93979472178209,0.3341191330399744,-1.9798333605521585
478.4000000000061,53.05854688156397,0.3164081071065272,-1.983979782107955
479.6000000000061,53.17593969400391,0.30516836379283474,-1.9860759620183437
480.8000000000061,53.29570758845952,0.29236737804977575,-1.9884971037707277
482.00000000000614,53.41433259349896,0.2837602671685364,-1.9913398344332722
483.2000000000062,53.53322329153144,0.27658336270676187,-1.9913276214254658
484.4000000000062,53.651646599808146,0.27654956567688616,-1.992656219627956
485.60000000000616,53.76909226572047,0.27388850118146,-1.9936501152682315
486.8000000000062,53.88900611539951,0.2746438705269487,-1.9933787939247152
488.00000000000625,54.007314799999,0.2767249765287739,-1.9927982916682527
489.20000000000624,54.12562863082098,0.289388606374839,-1.9947569641803984
490.40000000000623,54.24417115426203,0.2983239084114012,-1.9940875210530913
491.6000000000063,54.362365372188414,0.29905616888319475,-1.9952877495368462
492.8000000000063,54.47959557657063,0.303102346631166,-1.995377025223219
494.0000000000063,54.59877856383357,0.30609599171523416,-1.9965773772605298
495.2000000000063,54.71762561168326,0.30407174284159777,-1.99738351530161
496.40000000000634,54.83564552833153,0.30164527450062273,-1.9973799350001302
497.6000000000064,54.95462706299351,0.2959620429123453,-1.9973799350000014
498.8000000000064,55.07428098940692,0.2917776864057505,-1.9973799556906284
500.00000000000637,55.19167595312885,0.2865808528051986,-1.9980303525098635
501.2000000000064,55.31144462178641,0.2799194163474632,-1.9993494641568779
502.40000000000646,55.43057115912339,0.27689586528922094,-1.998029934171929
503.60000000000645,55.549080811397516,0.27280944105238736,-1.9980249372766719
504.80000000000643,55.66788513524197,0.26787389546244544,-1.9993499765598055
506.0000000000065,55.78737504953078,0.2681884145549088,-1.9990223685621182
507.2000000000065,55.906223171287564,0.26721871324498436,-1.9993496694693706
508.4000000000065,56.025015963892706,0.2627787598385174,-2.0006699218159447
509.6000000000065,56.14429663747474,0.25498589519527715,-1.9993494792936928
510.80000000000655,56.26302930645509,0.2532951677253674,-2.0006582029186872
512.0000000000066,56.38226230434491,0.24884590572113063,-1.9996834182663137
513.2000000000066,56.501808049670586,0.246096794819179,-1.9997601020302165
514.4000000000066,56.62010403026504,0.24107406450058666,-2.0000099901428854
515.6000000000066,56.740001988102144,0.23918798701774835,-2.0000099749937466
516.8000000000067,56.85929006276818,0.23289979913965508,-1.9999399897252133
518.0000000000066,56.97805732491736,0.2379257004046419,-2.0026401493985917
519.2000000000066,57.098280072171285,0.23420255257153622,-2.0027512947046255
520.4000000000067,57.217985741105444,0.23246237781560508,-2.0013201503951805
521.6000000000067,57.33654485587586,0.23128010613543593,-2.003750981148173
522.8000000000068,57.457284207873585,0.23560128156067994,-2.0039600449744137
524.0000000000067,57.57732300016681,0.2359108356100501,-2.003882944451518
525.2000000000068,57.69525568561811,0.23599347425848105,-2.004341028442051
526.4000000000068,57.81587061650551,0.24279589960404613,-2.0042901921777174
527.6000000000067,57.93386477304659,0.2466967523600857,-2.0042951910144353
528.8000000000068,58.053904712898856,0.24886794757705344,-2.003792820739937
530.0000000000068,58.174503956477515,0.24751404830635948,-2.0036301950123
531.2000000000069,58.29404258288387,0.25236782737483376,-2.0036301801496332
532.4000000000069,58.41231158812656,0.2533495885641813,-2.0049492825893274
533.6000000000068,58.53152537919725,0.2543542243749408,-2.004581924335464
534.8000000000069,58.65201243923299,0.25351395985533454,-2.0046200899956514
536.0000000000069,58.77101915449869,0.25936339118259955,-2.00462009
537.2000000000069,58.890716420828745,0.2587765759903782,-2.004620090104539
538.4000000000069,59.00968860458584,0.26496952034043897,-2.005928551503786
539.600000000007,59.1289088895062,0.26371113935575474,-2.0059298599808217
540.800000000007,59.24886578547207,0.2654156225508224,-2.005325448674585
542.000000000007,59.36887938710332,0.27004968235261817,-2.004609575043733
543.200000000007,59.48787702095522,0.27119170339975207,-2.0039379086428966
544.400000000007,59.60738044537897,0.2701396007608352,-2.0052706527783677
545.6000000000071,59.72710977068799,0.2737153789193897,-2.005930006817192
546.800000000007,59.84649533748373,0.2768446920482346,-2.0059300099999997
548.000000000007,59.96641980228573,0.2784924210245415,-2.0059300100000006
549.2000000000071,60.08695583732712,0.27500775859487847,-2.0059300100633237
550.4000000000071,60.20620702824802,0.2754260593973741,-2.006048511694046
551.6000000000072,60.32606690674214,0.2759063139147111,-2.005939905381379
552.8000000000071,60.44602874698825,0.2809362742215482,-2.0072937878901502
554.0000000000072,60.56598425947519,0.28152447627054866,-2.0082300805328153
555.2000000000072,60.68555656863372,0.28236217100223304,-2.0069204935826304
556.4000000000071,60.80516429470436,0.28451809713159104,-2.0069200585649605
557.6000000000072,60.92572604268724,0.28498580686597763,-2.0082363850064016
558.8000000000072,61.04637391404089,0.28480216654274004,-2.0092272645257863
560.0000000000073,61.165751692479674,0.28392329232517266,-2.008570416254108
561.2000000000073,61.28647211810417,0.2857137083273187,-2.008570125000033
562.4000000000073,61.40564912914275,0.2866349588559658,-2.0085701249992565
563.6000000000073,61.52576945839576,0.28807327977177866,-2.008564410535418
564.8000000000073,61.64664767989221,0.2882391030055569,-2.0092199524186367
566.0000000000073,61.766112678529915,0.28902309997199516,-2.0092142302769673
567.2000000000073,61.886728827012085,0.292818523368519,-2.009234645628766
568.4000000000074,62.00642476275709,0.29510525073610183,-2.010539918708294
569.6000000000074,62.12826331222584,0.29741968829980436,-2.011530059023978
570.8000000000075,62.24789622062209,0.29852504610585684,-2.0115299400000475
572.0000000000074,62.36839025154979,0.30097573159700697,-2.0115302406630824
573.2000000000074,62.48770617877139,0.3011157953895949,-2.0102101296845287
574.4000000000075,62.60832968223245,0.30267116191749643,-2.010206229106993
575.6000000000074,62.72779734516903,0.304198955038673,-2.010210331704472
576.8000000000075,62.84744287593023,0.3068607603305873,-2.010538326142107
578.0000000000075,62.968070100282276,0.31028231873431866,-2.013172523306582
579.2000000000075,63.088826351501254,0.3104930493399358,-2.0131696358418116
580.4000000000076,63.20865405150883,0.3108836194722484,-2.0115207932485752
581.6000000000075,63.329060506531874,0.31413832708108536,-2.012468329486113
582.8000000000076,63.44909589028756,0.31543481525299333,-2.01283892656469
584.0000000000076,63.568968373551385,0.31795658410966987,-2.012816540183527
585.2000000000075,63.688384247447246,0.3230132391889262,-2.0141599607256926
586.4000000000076,63.809090220938906,0.3246951875109816,-2.015470083350141
587.6000000000076,63.92939515286285,0.3271147713493612,-2.014159829392633
588.8000000000077,64.04923583652355,0.3282908243176894,-2.014138298553618
590.0000000000077,64.16960792050313,0.3295359912809941,-2.0153758790765646
591.2000000000077,64.28930124544556,0.3312097681149051,-2.015479975291132
592.4000000000077,64.40962305817048,0.3345031482278611,-2.0164707014215293
593.6000000000078,64.52912210849638,0.34009479785847385,-2.015150187593698
594.8000000000077,64.64990831253829,0.3413063910251968,-2.0158104719278134
596.0000000000077,64.77019217047527,0.346058386374261,-2.0158149077867993
597.2000000000078,64.89084472914487,0.3457876421795485,-2.017461813586519
598.4000000000078,65.00879688835465,0.35037112237108303,-2.0181100444424858
599.6000000000079,65.13216422155732,0.35405603069213654,-2.0180581216289535
600.8000000000078,65.2517327149496,0.3579692654719835,-2.019266290696739
602.0000000000078,65.37200795120886,0.36688269543518404,-2.0214262640556244
603.2000000000079,65.49265830390483,0.3689150659091287,-2.02060050562485
604.4000000000078,65.611650934896,0.3707870421011965,-2.020410190008957
605.6000000000079,65.73254633010367,0.378601449926242,-2.0204111062445334
606.8000000000079,65.85259575917398,0.3813593734700125,-2.0219414654737053
608.000000000008,65.97278977311232,0.387905370201048,-2.0236765483907146
609.200000000008,66.09436133908581,0.3900656770734716,-2.025024279271766
610.4000000000079,66.2140079645621,0.3984127832980402,-2.026330130620238
611.600000000008,66.33521641948596,0.4030033834891209,-2.0273185426285183
612.800000000008,66.4553199380626,0.40969763922118796,-2.027317690044751
614.000000000008,66.57668628008406,0.4097722777808368,-2.028328541045028
615.200000000008,66.69563883809778,0.41945027510359423,-2.0299500447616183
616.400000000008,66.81707389648562,0.42421301631025754,-2.0318238177513734
617.6000000000081,66.93900253084131,0.4275203159057328,-2.0329100770483737
618.8000000000081,67.05845693059237,0.43282861152556484,-2.0315722176101807
620.0000000000081,67.17882960373193,0.44218282270226394,-2.0345522000380125
621.2000000000081,67.3001104618595,0.447178190522479,-2.035895258665626
622.4000000000082,67.42139815594521,0.4549285626937154,-2.036869160418513
623.6000000000081,67.54133058732877,0.46119657121254787,-2.038234361338738
624.8000000000081,67.6627760182285,0.4687990559759896,-2.041660994531475
626.0000000000082,67.7834137468153,0.4755535114635592,-2.0446860810372964
627.2000000000082,67.903943486676,0.4883071851800873,-2.047417428627296
628.4000000000083,68.02524811554413,0.4942768555690735,-2.0488193249751245
629.6000000000082,68.1453650917617,0.5009419582077084,-2.0488236995198803
630.8000000000083,68.26682106020453,0.5112605589051731,-2.0514713514071463
632.0000000000083,68.38740867311934,0.5200809477274635,-2.0538906421995136
633.2000000000082,68.50823492800485,0.5297920990517153,-2.053918007083828
634.4000000000083,68.62999794131126,0.5365331099800308,-2.054089867598202
635.6000000000083,68.7500944258093,0.5424423238547387,-2.057628194371323
636.8000000000084,68.87213307588505,0.5528122893691851,-2.0605475118399927
638.0000000000084,68.99211674380734,0.5605148232650858,-2.062639567355476
639.2000000000083,69.11443613822088,0.571169619753864,-2.0639878167016903
640.4000000000084,69.23499214666447,0.5801897199383488,-2.0651826203632044
641.6000000000084,69.35607739245842,0.592300010839083,-2.068483794084111
642.8000000000084,69.47721530442473,0.6037961854840446,-2.072069908641173
644.0000000000084,69.59766447426962,0.6117395678599828,-2.07514891478683
645.2000000000085,69.71889235821298,0.6244878015423527,-2.0780986517091717
646.4000000000085,69.83946932016012,0.6356494079583566,-2.079820077778331
647.6000000000085,69.96135389201872,0.6482384069475222,-2.0835926803486835
648.8000000000085,70.08115533917052,0.6617342952980863,-2.0890719543134697
650.0000000000085,70.20274127872895,0.6760157017151738,-2.0923236445056235
651.2000000000086,70.32352897260358,0.6912048551870842,-2.0983996077289926
652.4000000000085,70.44445327905285,0.7069039473367513,-2.1004871260644356
653.6000000000085,70.56508011425109,0.7247819557148567,-2.103505355342347
654.8000000000086,70.68590723364997,0.7488635280308245,-2.107287584404914
656.0000000000086,70.80655718324061,0.7697803011242865,-2.1108128137259845
657.2000000000087,70.92694576299522,0.7857298944979085,-2.1154988350785233
658.4000000000086,71.0463766826918,0.8133095213191766,-2.1203940824142102
659.6000000000087,71.16858474548883,0.8386710741997376,-2.1266379806124465
660.8000000000087,71.28856897359836,0.8641068636911788,-2.130073395089471
662.0000000000086,71.40990456435539,0.8928655103339149,-2.1357974544034075
663.2000000000087,71.53051299125583,0.9222424724633533,-2.1391830408879
664.4000000000087,71.65047664042454,0.9493110206389215,-2.143051478135671
665.6000000000088,71.77238195427772,0.9822779753272208,-2.1481632058743747
666.8000000000088,71.89300665965153,1.014271486988521,-2.156194060452294
668.0000000000088,72.01321553374802,1.0489343287439092,-2.1627150833119764
669.2000000000088,72.1336263018275,1.0800103613694294,-2.1680620905622545
670.4000000000088,72.25574227140076,1.118448873047237,-2.175130933023876
671.6000000000088,72.37647173297512,1.1562266845483633,-2.1826118974886084
672.8000000000088,72.49745766235631,1.1923054268237148,-2.1903042452608066
674.0000000000089,72.61808628525448,1.2323602029248102,-2.1962254802141645
675.2000000000089,72.73942614040233,1.2691084932993848,-2.2029001528579526
676.400000000009,72.86066285747815,1.30744669616955,-2.2115452483246347
677.6000000000089,72.98106223256617,1.3485253915984907,-2.2188621628455287
678.8000000000089,73.10259682122023,1.3858266333638003,-2.225949395520961
680.000000000009,73.2223045469513,1.4249827456679203,-2.234014293111146
681.2000000000089,73.34563347058364,1.4698740602711164,-2.2431975157918647
682.400000000009,73.46605179072137,1.5080170362795915,-2.2518732265423913
683.600000000009,73.58804763700846,1.552841461753212,-2.2612877981085475
684.800000000009,73.70879466971806,1.59305200854807,-2.2702126574116095
686.0000000000091,73.82962265056766,1.6345676621375278,-2.283069436795656
687.200000000009,73.95084971463719,1.6776044025632737,-2.2917607241256555
688.4000000000091,74.06957139905249,1.7167131375328768,-2.301953137060247
689.6000000000091,74.1933283848665,1.7676825629205835,-2.314106065077295
690.800000000009,74.31487832463806,1.808838801034107,-2.3255575363195944
692.0000000000091,74.43589789228751,1.8542974274895554,-2.3369420118016855
693.2000000000091,74.55698744110467,1.8979976229456332,-2.350474587853207
694.4000000000092,74.67911937540916,1.948297655517436,-2.3616688019901018
695.6000000000092,74.79980543763524,1.9915906214831836,-2.3748953105240846
696.8000000000092,74.92130155829437,2.0367577939897004,-2.385850083751027
698.0000000000092,75.04309817323124,2.076223137125398,-2.4024326920468515
699.2000000000093,75.16515908326328,2.1197154384782353,-2.4172037315479615
700.4000000000092,75.28689833612219,2.1685502359752453,-2.431458325592751
701.6000000000092,75.40882591301721,2.2068111620809363,-2.446185568582495
702.8000000000093,75.52970258030008,2.245105132625197,-2.462903732141001
704.0000000000093,75.65137128845265,2.287820575924075,-2.4772521333013944
705.2000000000094,75.77266997334964,2.3265550085903053,-2.4931184718957877
706.4000000000093,75.8946471150608,2.3682257937731483,-2.5069813095694347
707.6000000000093,76.01593195270657,2.4042267355522657,-2.524329454371808
708.8000000000094,76.13761359100792,2.4424531585918308,-2.5429962015510537
710.0000000000093,76.25925097930109,2.47831421221111,-2.5610173117015664
711.2000000000094,76.37990029874207,2.5125219853084255,-2.5782614994606305
712.4000000000094,76.50111929190625,2.544397516422788,-2.595588262019905
713.6000000000095,76.6233911925343,2.575973592996387,-2.611170149970001
714.8000000000095,76.74419736048945,2.603181807761322,-2.629935024430539
716.0000000000094,76.86667548907985,2.6317333224660997,-2.647531330718482
717.2000000000095,76.98792012889707,2.655929308323426,-2.6658079357640823
718.4000000000095,77.10980897186822,2.670012919680495,-2.6848604275043493
719.6000000000095,77.23097446683823,2.685497586238481,-2.7058527253796036
720.8000000000095,77.35197572474746,2.689735195523162,-2.722655898022992
722.0000000000095,77.4734749018825,2.6751835536583357,-2.7411365571911177
723.2000000000096,77.59524030794685,2.6459986070443895,-2.7599042933146554
724.4000000000096,77.71648683055442,2.5866519500214755,-2.7801058632229063
725.6000000000096,77.83748977101354,2.4825107001859084,-2.79468144030553
726.8000000000096,77.95899895275835,2.305191513625452,-2.8116832792985678
728.0000000000097,78.07970057750188,1.975501666463522,-2.82712885424659
729.2000000000096,78.19970424912589,1.262696045644209,-2.840300026550696
730.4000000000096,78.32064210814406,0.48585371510912445,-2.845495835914406
731.6000000000097,78.4416548396986,0.27559464405235357,-2.846460136785298
732.8000000000097,78.56137758455358,0.2237844306842467,-2.84646012389926
734.0000000000098,78.6832998772325,0.20443695303986864,-2.847789727189973
735.2000000000097,78.80426594025911,0.2000089900966362,-2.8480435667008743
736.4000000000098,78.9262422420584,0.19662131860251053,-2.847780025016899
737.6000000000098,79.04678184174699,0.19813590062200115,-2.847777851637776
738.8000000000097,79.16850519083903,0.1982983283841273,-2.845796002775323
740.0000000000098,79.28931657569137,0.1982062769494073,-2.8471002541510977
741.2000000000098,79.41090630783043,0.1995695872997425,-2.847109972308181
742.4000000000099,79.53205896378024,0.20051668035038217,-2.8484299377151108
743.6000000000099,79.65426406708988,0.20145703795846526,-2.8484301224717896
744.8000000000098,79.77545331831783,0.20057853510170176,-2.849419876520738
746.0000000000099,79.8961290419455,0.20115773375117696,-2.848432573054689
747.2000000000099,80.01678139826772,0.20624145726034637,-2.8497490627746216
748.4000000000099,80.13806198364807,0.20562485599367086,-2.849749839999944
749.6000000000099,80.25890925307942,0.20798803909801267,-2.8497498382746063
750.80000000001,80.37989534687367,0.2091888920599052,-2.851050700033351
752.00000000001,80.5021468668087,0.20324708687058468,-2.850097545835995
753.20000000001,80.62394632682864,0.2040822962273534,-2.850409836667066
754.40000000001,80.74553882188776,0.20725107661887554,-2.850409835000011
755.60000000001,80.8678020832652,0.20634693954023753,-2.850409347175003
756.8000000000101,80.98844082309073,0.2100557499724376,-2.8507110243217784
758.00000000001,81.11188481777043,0.2081788913848337,-2.851200663093176
759.20000000001,81.23162012728801,0.20843222806550488,-2.851390199396174
760.4000000000101,81.35437422381732,0.2097068836530096,-2.851390084999929
761.6000000000101,81.47490289544061,0.21033466512397148,-2.8513895224558867
762.8000000000102,81.59866650276089,0.21463447168260652,-2.8510600858305484
764.0000000000101,81.71913078711715,0.21316863151972232,-2.8510741804344857
765.2000000000102,81.84078518257833,0.21841032134791183,-2.8510599664033984
766.4000000000102,81.9634747004262,0.21350754754580592,-2.8517254693964107
767.6000000000101,82.08526346754232,0.21186331431218042,-2.851719980000712
768.8000000000102,82.20687448160047,0.21210634787996474,-2.851720218524873
770.0000000000102,82.32799320404524,0.2116294544411419,-2.853594748152405
771.2000000000103,82.45020584944318,0.21259463163379522,-2.852374095877997
772.4000000000103,82.57190169360126,0.21136734691219283,-2.852380129994602
773.6000000000103,82.69289141813644,0.21100205227683988,-2.852380130003232
774.8000000000103,82.81438353924493,0.21553957951375047,-2.85209824823149
776.0000000000103,82.93606344042526,0.2134247463340917,-2.8523799616667285
777.2000000000103,83.0573131605743,0.21333087483813928,-2.85187494639544
778.4000000000103,83.17928961748653,0.21323888941143743,-2.853052427279227
779.6000000000104,83.30085808706633,0.2144386818108761,-2.8530328132172453
780.8000000000104,83.42209474080944,0.2109453131322554,-2.853029442825759
782.0000000000105,83.54370857653295,0.2117492846095237,-2.851720034320488
783.2000000000104,83.66565657870012,0.21606710052484512,-2.852606163426665
784.4000000000104,83.78659324938032,0.21363836531225244,-2.8527100500067717
785.6000000000105,83.90847792460856,0.21647851341829982,-2.852953272108161
786.8000000000104,84.03062926093219,0.2188979855824864,-2.8524067904041854
788.0000000000105,84.15152011956903,0.21900234627856108,-2.853752571085395
789.2000000000105,84.27339347988375,0.21923344686234092,-2.8527288040083203
790.4000000000106,84.39579498720735,0.2226962945984683,-2.853632926145187
791.6000000000106,84.5174514137619,0.2266928437191611,-2.8527102877161106
792.8000000000105,84.64000113278699,0.22615740339106605,-2.8544322145354752
794.0000000000106,84.76213251246962,0.23576749095903748,-2.855669832803538
795.2000000000106,84.88359758637763,0.23114761488078006,-2.856100360240872
796.0000000000106,84.96525040512248,0.23445997128295293,-2.8556700248832456