File: 01_Data/Nylon_Carpet_Low_Pile/STA/N2/10K_min/Nylon_Carpet_Low_Pile_STA_N2_10KData_220105_R1.csv
##Temp./Â°C,Time/min,DSC/(mW/mg),Mass loss/mg
50.0,10.751940566985862,0.043156345871693036,0.018909619333385308
51.100000000000016,11.052388548175802,0.07880050506209801,0.020212798472747373
52.20000000000003,11.262705805261593,0.10490631697944997,0.019047430040984636
53.30000000000005,11.440145920858319,0.1266496193300607,0.020480409729706217
54.40000000000006,11.598402791621021,0.14584462271398524,0.020060372795792425
55.50000000000008,11.744322412379338,0.1586339640793304,0.01978350647931304
56.600000000000094,11.886176677864096,0.1701528708520863,0.01964654569633595
57.70000000000011,12.021535400848977,0.1822358989883318,0.02089096942462465
58.800000000000125,12.152492637000167,0.18716911750261778,0.022179434354770322
59.90000000000014,12.277551519415708,0.1935306799855107,0.02076763186696695
61.000000000000156,12.40500709963445,0.19841093071964727,0.021091963042498385
62.10000000000017,12.52475350590593,0.20512291855448217,0.02242604322866182
63.20000000000019,12.653908622334752,0.2106896681419041,0.020951973924120182
64.30000000000021,12.772605166659215,0.21265577226451093,0.021172685633880306
65.40000000000022,12.89395816453306,0.21613021947722388,0.022293958378623024
66.50000000000023,13.014280266131117,0.22288724307714397,0.021285147103232482
67.60000000000025,13.133179850958564,0.2233176285066874,0.0209858909521623
68.70000000000027,13.250499717960187,0.22689579599749293,0.02184866063305435
69.80000000000028,13.36851922031019,0.2292968488378142,0.023542082314036428
70.90000000000029,13.48751648293467,0.2330628769081987,0.022139336014666
72.00000000000031,13.604632653862819,0.23592518916669758,0.02358995558054744
73.10000000000034,13.720188471648129,0.2390330243583179,0.023591731106648695
74.20000000000034,13.832759665249764,0.24024947682112535,0.022871075666862417
75.30000000000035,13.950883661603662,0.2436636971250526,0.023589167523778265
76.40000000000038,14.06718491089024,0.24654563838091204,0.023591872081507148
77.5000000000004,14.18185821023838,0.24869874040430806,0.023559771044103783
78.6000000000004,14.296817411878916,0.2509114321170484,0.02259005708347317
79.70000000000041,14.4081864755781,0.2544078045523812,0.022277145185055858
80.80000000000044,14.521061174179447,0.25492906107867974,0.02226983035849006
81.90000000000046,14.63521343800043,0.2573518029876464,0.022284583203616926
83.00000000000047,14.747249885431826,0.2601276744472587,0.020300113666987585
84.10000000000048,14.86111852193417,0.2613320775868041,0.020299021620288293
85.2000000000005,14.972629190713196,0.26449363590291264,0.019086339442715428
86.30000000000052,15.084696912434145,0.2656565842369927,0.020300010246629085
87.40000000000053,15.195871973723756,0.26824391440355144,0.02161521222989382
88.50000000000054,15.306761888181066,0.26892475893973444,0.02294011770375448
89.60000000000056,15.415634165062336,0.26972882815795207,0.02284515490138439
90.70000000000059,15.52756746697671,0.2728584580933769,0.022927664909334844
91.8000000000006,15.637219456879155,0.2745937057682887,0.0227326199933362
92.9000000000006,15.748392227243352,0.2759711418266522,0.02161716679870551
94.00000000000063,15.858196957509623,0.27716507364760445,0.0229124335010642
95.10000000000065,15.96559638194593,0.2780218255192912,0.02164814730002007
96.20000000000066,16.075290676216014,0.278524715913791,0.02227669009250377
97.30000000000067,16.18454002959381,0.2819834937203698,0.023622063230100743
98.40000000000069,16.29353106180342,0.28020517690440816,0.022280115025963276
99.50000000000071,16.402413157882606,0.28127010312969924,0.0235673970603143
100.60000000000072,16.51104847226179,0.2822235746774834,0.02096752998831697
101.70000000000073,16.619441010479452,0.2825215211214118,0.02095932599493544
102.80000000000075,16.728522647771733,0.2842091262252966,0.01963810428237256
103.90000000000077,16.835868984892603,0.2819440251463362,0.020959743628700345
105.00000000000078,16.944107314438856,0.2867101573946159,0.019837861529725664
106.10000000000079,17.052584898543095,0.28678919620803184,0.020953603449100022
107.20000000000081,17.160948026155914,0.2877494924519237,0.022269920617662642
108.30000000000084,17.26799491409052,0.2859945338910867,0.023160048643660502
109.40000000000084,17.37703907784661,0.285663512471642,0.02358068017993098
110.50000000000085,17.48349068562604,0.28694959927199765,0.02226712428658928
111.60000000000088,17.592367653566757,0.2884822650786808,0.01970817335135777
112.7000000000009,17.700108275696596,0.28850279775327303,0.019640190862353357
113.8000000000009,17.80672653347019,0.2900189541089866,0.019673382962920094
114.90000000000092,17.914232206349702,0.2907630614470509,0.018372746573954046
116.00000000000094,18.02308859654727,0.29025161536822364,0.018607457567260788
117.10000000000096,18.12930018614157,0.2924993149100011,0.01996911945879898
118.20000000000097,18.236192814259805,0.291730147950413,0.020623503434508805
119.30000000000098,18.344819860285174,0.2926554935534819,0.02029989026076162
120.400000000001,18.452812074519525,0.2947145382709117,0.021152417118999622
121.50000000000102,18.5596931108526,0.2900451386973737,0.0186650553952461
122.60000000000103,18.666880620648826,0.2937507120887398,0.01894970333115431
123.70000000000104,18.774932456575343,0.2895697411904586,0.019113316604432384
124.80000000000106,18.880547652233748,0.2950287060472851,0.019970132995311474
125.90000000000109,18.98864978476091,0.29227706014279586,0.019970132104035976
127.0000000000011,19.095694730365953,0.292997903143207,0.021295077621850567
128.1000000000011,19.20288611588082,0.2949635351565422,0.01996243221388383
129.20000000000113,19.309148101291292,0.2945483930282008,0.01780415674543523
130.30000000000115,19.415277062467684,0.2956477151932703,0.018677270936019674
131.40000000000117,19.524021696091783,0.2950485818573195,0.0187080893933258
132.50000000000117,19.630857004580267,0.29474320320198855,0.018649807894883352
133.6000000000012,19.736638859764398,0.29537968194085673,0.01997666132084941
134.7000000000012,19.842989578762367,0.29667000480315775,0.018678758917087812
135.8000000000012,19.949812722704287,0.2965032601699136,0.020095863907263478
136.90000000000123,20.055781927745706,0.2956555406800433,0.018638036658537693
138.00000000000125,20.161404703342217,0.2987981988066787,0.01734046126999811
139.10000000000127,20.268864101706317,0.29874193995194004,0.018720120912488092
140.2000000000013,20.375276684719672,0.3006786215181274,0.016679888680533494
141.3000000000013,20.481261806132352,0.3047566413632985,0.017664235348800794
142.4000000000013,20.58781959908472,0.3048057308865638,0.016233140130529122
143.50000000000134,20.693587106546598,0.3057681351919452,0.016326075111028793
144.60000000000133,20.798879580911155,0.30798561908908645,0.015326822321236833
145.70000000000135,20.90545208141527,0.3081582813760299,0.01668019096959128
146.80000000000138,21.011585640383952,0.31076179875670495,0.017005275836119438
147.9000000000014,21.117887199792015,0.31269894627875594,0.01692395635188504
149.00000000000142,21.223960900557437,0.3151073067418234,0.018312253303744086
150.10000000000142,21.329450324569276,0.31879450887517735,0.01734009530312175
151.20000000000144,21.436383586333378,0.3228899800520708,0.017339878991231572
152.30000000000146,21.54214031013078,0.3247748356111049,0.01734811029886263
153.40000000000146,21.64642699070766,0.327506146585236,0.017989894465034517
154.50000000000148,21.754104167618184,0.3333109829241051,0.0179912170647496
155.6000000000015,21.858056756686107,0.3367011129221423,0.016417300016557945
156.70000000000152,21.966134854085226,0.3424142586550488,0.016355146186280756
157.80000000000155,22.071026407651793,0.3480061745909311,0.01568994620521824
158.90000000000154,22.17387485047555,0.35472146323011106,0.0156899459999984
160.00000000000156,22.28197261295519,0.36652847654720355,0.015689946000010835
161.1000000000016,22.386585457955995,0.3748506285765032,0.01568998085625406
162.20000000000158,22.493846817509507,0.3834712661851237,0.015076439843050515
163.3000000000016,22.598932782446976,0.3912116496018365,0.014377102359639515
164.40000000000163,22.70476303288515,0.39931587193350393,0.015040411693741262
165.50000000000165,22.80873186830171,0.40013816013237474,0.015040018662946686
166.60000000000167,22.915847915943598,0.3954353750775651,0.013720049666972045
167.70000000000167,23.020942628625942,0.3874728016815166,0.013720060937252754
168.8000000000017,23.12746363020042,0.37771215084148446,0.014369864916268682
169.9000000000017,23.23345098791637,0.36484296942626604,0.01460855315934051
171.0000000000017,23.338455621965604,0.3540190563714456,0.014386082829108915
172.10000000000173,23.443859810890128,0.34661698567263743,0.013150226739491622
173.20000000000175,23.54874051815045,0.3394023789847417,0.01234444774041954
174.30000000000177,23.654535157120065,0.33362668101692716,0.014220348098739954
175.4000000000018,23.760098751627083,0.3321376692385106,0.013391040056796477
176.5000000000018,23.865544550473814,0.32944607292016337,0.013592623614591126
177.6000000000018,23.970911010599714,0.3294792116874631,0.015118577629364083
178.70000000000184,24.07701017470853,0.33025165566306625,0.015699887551479108
179.80000000000183,24.18130385424471,0.33117913957568024,0.015699887989556238
180.90000000000185,24.28693707597783,0.32918544854028575,0.015692700722342856
182.00000000000188,24.39469319140392,0.3332463355431876,0.01436360568870576
183.1000000000019,24.498184669879997,0.3330271973692198,0.013059827354908293
184.20000000000192,24.600257993450054,0.3355730480951161,0.011751412579186216
185.30000000000192,24.70784197385396,0.3368338379028206,0.011827192338638604
186.40000000000194,24.81380454327643,0.3379989828891593,0.011751610157228143
187.50000000000196,24.91829068852307,0.3400942330467891,0.0142997465482404
188.60000000000196,25.024658553549912,0.3397470473172789,0.014376602521783965
189.70000000000198,25.128780880850368,0.34079259820268726,0.014017884405440384
190.800000000002,25.234756423641358,0.34049300069258503,0.01405001868757072
191.90000000000202,25.340527548871247,0.34262218974886505,0.012731963770978183
193.00000000000205,25.444769423559155,0.34306336651563407,0.011502466577316461
194.10000000000204,25.55080496620707,0.34455371437400023,0.010100014864638851
195.20000000000206,25.6560607207444,0.34321656091740826,0.011403271532767434
196.3000000000021,25.760935635146424,0.3473586269387318,0.011410024007606268
197.40000000000208,25.867393306568033,0.3478486884888962,0.01141002399999902
198.5000000000021,25.97229579902594,0.34781091798898767,0.01141002399999902
199.60000000000213,26.078481989367425,0.3483913412907863,0.011410023999999908
200.70000000000215,26.184432171171487,0.34931702101868584,0.011410025387658784
201.80000000000217,26.28847975301932,0.3569142403297112,0.01010884488630115
202.90000000000217,26.39433872892784,0.3564863972215558,0.01010665611007866
204.0000000000022,26.50036442511625,0.35920841444798596,0.009765503899430428
205.1000000000022,26.60561629631956,0.36269933004009336,0.011640804227564416
206.2000000000022,26.710274839733472,0.3645926490782208,0.011740113983895739
207.30000000000223,26.816497082176447,0.36852905694740945,0.011745796923136709
208.40000000000225,26.921396078316,0.3702255231265512,0.010420115095217675
209.50000000000227,27.026731009990016,0.37502112264719567,0.009303076486316009
210.6000000000023,27.132173865134927,0.38140610477423653,0.009110113955674848
211.7000000000023,27.23698762284417,0.3895766544292859,0.009110114000030478
212.8000000000023,27.342508628434455,0.402025597301731,0.009110099252916726
213.90000000000234,27.44653762369868,0.4208335656224368,0.007786334604998224
215.00000000000233,27.551308667394323,0.4527835538396956,0.009164355318137751
216.10000000000235,27.656189876496818,0.4969118900782694,0.009109831966261694
217.20000000000238,27.762723269824104,0.5590542715097218,0.009460032131180185
218.3000000000024,27.867292626905147,0.621272077129722,0.009440103256374677
219.40000000000242,27.972599479780776,0.6810411320353146,0.010760247966059566
220.50000000000242,28.078165305882912,0.7292503758424209,0.010734717942233019
221.60000000000244,28.18470804595639,0.7469311420189804,0.010099849241168357
222.70000000000246,28.288657057815534,0.7252694649907627,0.010099850999996995
223.80000000000246,28.39605884146004,0.6662153459174652,0.010099851000313187
224.90000000000248,28.501329343344988,0.5917810215906627,0.010100110844393662
226.0000000000025,28.606336770355366,0.5288876473075199,0.009428296044662332
227.10000000000252,28.711750816413822,0.4797053516740766,0.008119851993352079
228.20000000000255,28.8165797755871,0.44276580464546034,0.009452888565043338
229.30000000000254,28.92041766921768,0.41562653829428975,0.00811984502136287
230.40000000000256,29.02483479209682,0.3980930176195438,0.008174508827570648
231.5000000000026,29.12781516137891,0.3867262826649449,0.0074633613854429015
232.60000000000258,29.235633381450153,0.3785694062570391,0.008888169667534918
233.7000000000026,29.33947991953667,0.37495420440205585,0.007140489559501972
234.80000000000263,29.444721239389672,0.37323787195093344,0.007139874000087865
235.90000000000265,29.549904745989796,0.3716850307292749,0.007140376238387702
237.00000000000267,29.654866148932676,0.3728934160079942,0.005819850536742166
238.10000000000267,29.76018693462505,0.3699732959843765,0.005819873992566116
239.2000000000027,29.8646958543481,0.3724870989231571,0.005667376223802201
240.3000000000027,29.97029945123804,0.3728674038437399,0.0041802109363375806
241.4000000000027,30.074649642599976,0.3734402294866147,0.0028601600702140573
242.50000000000273,30.179716971663556,0.3733844008424006,0.004170862132221842
243.60000000000275,30.283732697293594,0.3755126996873011,0.004179851063998541
244.70000000000277,30.39026213123586,0.37449608451382976,0.004179851490760278
245.8000000000028,30.49429287045809,0.3744854137313101,0.005501106520806154
246.9000000000028,30.599897777938143,0.3742197084741924,0.005499943000017993
248.0000000000028,30.70494007590748,0.3726885042159149,0.005499938151126038
249.10000000000284,30.810913581156978,0.37223905569632515,0.004182783913618593
250.20000000000283,30.91513831845217,0.3735995685685442,0.004179944868538676
251.30000000000285,31.02117152454188,0.37257102797534025,0.0028553185122612845
252.40000000000288,31.12536669185257,0.3715095294848242,0.004169457486661976
253.5000000000029,31.231783847393466,0.37149884080569495,0.004179948818101131
254.60000000000292,31.336825715739167,0.37286060609528016,0.0016869594706641067
255.70000000000292,31.44199822141947,0.37377042070287303,0.0028554666817273144
256.8000000000029,31.54666151841692,0.37655524136691854,0.003860004877449086
257.90000000000293,31.65286601815977,0.3758855561276442,0.0038499429966281085
259.00000000000296,31.757104205032306,0.3767102362045715,0.0038499429999978574
260.100000000003,31.861762326028344,0.3769744976025913,0.003849944382219306
261.200000000003,31.967617824723618,0.37833469989857926,0.0028601664995937526
262.300000000003,32.073044807067284,0.3780785847151178,0.0025299203319395502
263.40000000000305,32.17788933071575,0.37877421268215267,0.002529919999997965
264.50000000000307,32.283130967965874,0.3778708612103504,0.002529921253923817
265.6000000000031,32.388035921752994,0.3802739328059763,0.0012410651030627662
266.7000000000031,32.492980013007795,0.3792572414529267,0.0013343540024539635
267.8000000000031,32.59796353806257,0.37961281420200266,0.002538029170172429
268.9000000000031,32.704862156176134,0.3820075169342988,0.0008898732218609595
270.0000000000031,32.81069020577724,0.3842212647294281,0.0008898740020324425
271.10000000000315,32.915721640942074,0.3807573133842266,0.0008780715277598716
272.2000000000032,33.020284089786514,0.38187876992832853,0.0018694307649314013
273.30000000000314,33.1255745330857,0.38191956108391345,0.0015398533282429128
274.40000000000316,33.23131157408314,0.379965823188295,0.0015398509999977605
275.5000000000032,33.337058977403714,0.3793579747516075,0.0015398510074398075
276.6000000000032,33.44194713637503,0.38321006392876134,0.0015362969696175455
277.70000000000323,33.54682889920224,0.3831029806221756,0.00022988328915651834
278.80000000000325,33.65349288556249,0.3833443649290351,-0.001091022026816546
279.9000000000033,33.75732750283749,0.38678411171398563,-0.001093587884115621
281.0000000000033,33.86388292790128,0.3860686507931218,0.0003053904538585783
282.1000000000033,33.969506201616795,0.3879505132490989,-0.0024098451960572476
283.20000000000334,34.07371062662285,0.38680521204660634,-0.002409839999983454
284.30000000000337,34.17907603680073,0.3881325538615657,-0.0024098399999994413
285.40000000000333,34.28507268173887,0.3901006210448397,-0.0024098699897470155
286.50000000000335,34.38979637494705,0.38951630227787654,-0.0033994944830730844
287.6000000000034,34.49553019796462,0.3892413897630025,-0.004820214597850203
288.7000000000034,34.59999895698779,0.3900843531086235,-0.0035101690143717335
289.8000000000034,34.70604077214952,0.38720053133964816,-0.003511791707783374
290.9000000000034,34.81122253808024,0.39159416794374396,-0.004820172477583817
292.0000000000034,34.91667833549832,0.3877495572266121,-0.004820183900804409
293.10000000000343,35.022353979211985,0.3878802633439395,-0.00579740804025608
294.20000000000346,35.127296362020026,0.38973196111219705,-0.005809849985585203
295.3000000000035,35.23377396582955,0.3889175866811858,-0.005809849999998562
296.4000000000035,35.33900494340386,0.38849656119447046,-0.0058098509394399755
297.5000000000035,35.44503165229034,0.3908898948115205,-0.006135689095821739
298.60000000000355,35.5509534230044,0.3939929960599828,-0.006141032430231341
299.70000000000357,35.65687908816175,0.39265033095519314,-0.007775450923086957
300.8000000000036,35.76178657451495,0.3938957560469426,-0.007790706932556013
301.9000000000036,35.8693900178165,0.3956553338060405,-0.01041048675884415
303.0000000000036,35.97460561253601,0.3988513905439374,-0.009099555058086573
304.1000000000036,36.08030158648106,0.4024046252644705,-0.010404962963847186
305.2000000000036,36.1866782329438,0.40153552629250056,-0.010341092940383323
306.30000000000365,36.29318007146482,0.40593980448027184,-0.012401740628422253
307.4000000000037,36.39853103747743,0.4032430218392952,-0.01431975493993054
308.5000000000037,36.50444810085623,0.4066873460757196,-0.013699966732828806
309.60000000000366,36.610697830842504,0.4062438613511391,-0.014360058233074735
310.7000000000037,36.71598712065119,0.41200521205766355,-0.01712659979269482
311.8000000000037,36.819891835637435,0.4111898930992791,-0.017297113929916286
312.90000000000373,36.92829582847396,0.41496630926773664,-0.018309523958166096
314.00000000000375,37.035174691913234,0.41772097619512366,-0.01830972890478666
315.1000000000038,37.14063775347668,0.4209773259278308,-0.019630104877840893
316.2000000000038,37.24624133185134,0.4214120680901622,-0.02093357252348582
317.3000000000038,37.3527724503137,0.4228642379970049,-0.02357033347823112
318.40000000000384,37.457884141315446,0.4248888624410784,-0.024840000198155465
319.5000000000038,37.56459290899538,0.4255236090176545,-0.027577940685834523
320.60000000000383,37.67165257528455,0.4288008731747036,-0.028841488607564525
321.70000000000385,37.77671194291346,0.4327409765477016,-0.031499542104409084
322.8000000000039,37.882976294532995,0.43646798316324154,-0.03369805289728012
323.9000000000039,37.98830074434594,0.440019285926905,-0.03541180037947722
325.0000000000039,38.09380437743435,0.4423823258197235,-0.03690206959539122
326.10000000000394,38.20119003090883,0.44470214282346504,-0.04074844119879195
327.2000000000039,38.305806021822164,0.4470253857020396,-0.04333177349328787
328.30000000000393,38.41373999087914,0.45112019029014677,-0.04596645387290543
329.40000000000396,38.52038552332524,0.4577943716172885,-0.048684157130797434
330.500000000004,38.62568195023096,0.4605113361978851,-0.05225094680363984
331.600000000004,38.73224056585248,0.46439292863790904,-0.053969045352265876
332.700000000004,38.83793495424404,0.4708539133869082,-0.05789236968704303
333.80000000000405,38.94489280117364,0.47415733131961757,-0.06208900686940799
334.90000000000407,39.05098213142686,0.4808982166314604,-0.0665657692765409
336.0000000000041,39.157856609622655,0.4864265852286503,-0.07092974513251082
337.10000000000406,39.262881403984316,0.490893780431104,-0.07523616399415278
338.2000000000041,39.36770672913019,0.49697649594064836,-0.07962032491424242
339.3000000000041,39.47726569454838,0.5033327283875628,-0.08386503302502657
340.4000000000041,39.58377226091052,0.5084661758389707,-0.08993786243501933
341.50000000000415,39.69078093025227,0.5140817596592506,-0.09658500103406586
342.6000000000042,39.79796171066397,0.5243023294089786,-0.10118159612405364
343.7000000000042,39.903791004970735,0.5334699877671097,-0.11107728223823976
344.80000000000416,40.01144192848645,0.5414856080939883,-0.11820137528787189
345.9000000000042,40.11721925037729,0.5493095717538796,-0.12504554746056584
347.0000000000042,40.223353707878815,0.5604632102546634,-0.13304060263771023
348.10000000000423,40.33139040186735,0.5688461453138315,-0.1403266570245174
349.20000000000425,40.43801624547595,0.5794726870120719,-0.14839352481011758
350.3000000000043,40.54369392941996,0.5858010881404658,-0.15764370879532708
351.4000000000043,40.65120047017083,0.5985217528978257,-0.1674764799564481
352.5000000000043,40.75864041685328,0.6086467160553506,-0.17589910751976
353.60000000000434,40.86372572575572,0.6188624461037986,-0.1865886265230845
354.7000000000043,40.97233596202452,0.6307041159887542,-0.19728900224587687
355.80000000000433,41.077708079162406,0.6397521939279929,-0.2092026903777957
356.90000000000435,41.18394854676256,0.6504390691158429,-0.2199070207685958
358.0000000000044,41.29109872130247,0.6586802831188182,-0.23198092436927098
359.1000000000044,41.3981548040009,0.6694593420509068,-0.24571949433942386
360.2000000000044,41.50461772580118,0.6806648588481068,-0.259888350452532
361.30000000000445,41.61038755522542,0.6889108544819103,-0.2721762118359048
362.4000000000044,41.71773696541562,0.7016878772602775,-0.28555092125213477
363.50000000000443,41.82313081170384,0.7112922092799645,-0.30168083889929154
364.60000000000446,41.9318509358035,0.7225589185838908,-0.3163080679812529
365.7000000000045,42.03749489869172,0.728119661889716,-0.33299239983561524
366.8000000000045,42.14468925401257,0.7395056891726504,-0.348379580617153
367.9000000000045,42.25179662525705,0.7480962303816293,-0.3642297454904839
369.00000000000455,42.35979016645139,0.7606995208967102,-0.38142867799279934
370.10000000000457,42.465469685961395,0.7709935270265984,-0.3970139784181832
371.2000000000046,42.5729916497975,0.7820645044676455,-0.41591495145377166
372.30000000000456,42.6804629469476,0.7930017004017094,-0.4322680038716795
373.4000000000046,42.78682179729178,0.8031019376102341,-0.4517354996221341
374.5000000000046,42.892932765453,0.8144698007516151,-0.47116251191687164
375.6000000000046,43.00070750835508,0.8271046283427523,-0.49000894795898775
376.70000000000465,43.107938183717,0.8394335454396691,-0.5100218343709204
377.8000000000047,43.21457505593066,0.852926360506139,-0.5320216094772112
378.9000000000047,43.3214293557668,0.8655294748138291,-0.5520697330199624
380.00000000000466,43.428751073198185,0.8779390378279764,-0.5771494278971914
381.1000000000047,43.535075308230134,0.8898891974285927,-0.6013776231788008
382.2000000000047,43.64378852737884,0.9026893638508338,-0.6269737924383953
383.30000000000473,43.75067518616873,0.9121939566316546,-0.6526491109229315
384.40000000000475,43.85799880619029,0.9240427408371952,-0.6766164939897057
385.5000000000048,43.964795561831885,0.9364557462616241,-0.7034870872364225
386.6000000000048,44.07235174684719,0.9485037159499521,-0.732807499958533
387.7000000000048,44.180212821603995,0.958797776416099,-0.7605155360588931
388.80000000000484,44.288244569041254,0.9653707124817914,-0.7892501367437434
389.9000000000048,44.39562372242219,0.9728122904572873,-0.8184175504191158
391.00000000000483,44.50317221727134,0.9771203815068712,-0.8478361136130657
392.10000000000485,44.610534771002584,0.9783919283474176,-0.8785052077645625
393.2000000000049,44.71714720871618,0.9824020581115264,-0.909668810321012
394.3000000000049,44.82511188808245,0.9795084805094716,-0.9415175730860286
395.4000000000049,44.932308924713574,0.97452386964495,-0.9717303186222819
396.50000000000495,45.04000000000051,0.9645126036971469,-1.0043911055598245
397.6000000000049,45.14743228887144,0.9530315479959107,-1.0372895035771248
398.70000000000493,45.25544037901439,0.934900357704478,-1.0664003686449437
399.80000000000496,45.36102406955494,0.9106799238343225,-1.0971880664882248
400.900000000005,45.468526821717816,0.8808776268502375,-1.12944902743883
402.000000000005,45.576300466979546,0.8477187789676863,-1.1559776389075913
403.100000000005,45.68400557936567,0.8094409117734257,-1.1848674891322046
404.20000000000505,45.79088634963599,0.7725482196954776,-1.2099567293116889
405.30000000000507,45.898446783865126,0.724443581037797,-1.2354752339696873
406.4000000000051,46.005079655614274,0.685292173794056,-1.2569491954020524
407.50000000000506,46.112517691806694,0.6424005308128471,-1.279253505719883
408.6000000000051,46.220565777709766,0.6021262528817346,-1.2981792651633697
409.7000000000051,46.32781477951868,0.5631987751313622,-1.315580449063214
410.8000000000051,46.435173417424885,0.5333757047151214,-1.3292954392165166
411.90000000000515,46.54250804977169,0.5024288877779,-1.3438356139511272
413.0000000000052,46.65091206349002,0.4808939292545201,-1.358208619099853
414.1000000000052,46.75731588854622,0.4623384997365769,-1.3704621211851564
415.20000000000516,46.86490086266119,0.44636410605560173,-1.3850136805862188
416.3000000000052,46.97187224228313,0.4344832633404593,-1.394765307788151
417.4000000000052,47.080382665900885,0.42617519924329317,-1.405334294569911
418.50000000000523,47.18632063330768,0.4211061079512163,-1.4157954879517325
419.60000000000525,47.294767874896124,0.41232658575823333,-1.4245163793689968
420.7000000000053,47.40179797432008,0.41139668731114176,-1.4331930570304356
421.8000000000053,47.51009173734732,0.4077556064630732,-1.442610765033442
422.9000000000053,47.6178523959173,0.40291823427435614,-1.4516064423352426
424.00000000000534,47.723803008154086,0.4009895613318111,-1.4591789156537711
425.1000000000053,47.83324922286658,0.40168494345255423,-1.4701510722056934
426.20000000000533,47.94094586902287,0.39942234935752585,-1.4780437217775262
427.30000000000535,48.04654687300624,0.3963290464794571,-1.4873095413614044
428.4000000000054,48.15446243935527,0.39746421720010316,-1.4952647400971233
429.5000000000054,48.26191001944695,0.396890572968832,-1.5038435205336746
430.6000000000054,48.369998944751245,0.3973368888030312,-1.5126597555675283
431.70000000000545,48.477584756581514,0.3961550849245534,-1.5196324478089398
432.8000000000054,48.58372028087118,0.39468739942951625,-1.5292856283249057
433.90000000000543,48.69342609414514,0.3938712893738431,-1.5382610559103638
435.00000000000546,48.80042729704948,0.3969186978404716,-1.5463933142283706
436.1000000000055,48.90869459560797,0.3992611668795757,-1.5574633804499345
437.2000000000055,49.01547695007564,0.3975084854893719,-1.5662870342429809
438.3000000000055,49.12369473360052,0.39874018182619875,-1.575438684854693
439.40000000000555,49.2314769513755,0.4002020712139648,-1.5845891638194365
440.50000000000557,49.33818574620772,0.400373453769473,-1.592966078768924
441.6000000000056,49.44626783358995,0.40127316311945294,-1.6029976460414495
442.70000000000556,49.55539159816069,0.40263762855135177,-1.6129711013175383
443.8000000000056,49.66239457116139,0.401801031307093,-1.6225553329132323
444.9000000000056,49.770902588960425,0.40387437997919906,-1.6314455155969148
446.0000000000056,49.87900953832088,0.40663640295096515,-1.6420117116519144
447.10000000000565,49.98675897478596,0.4048879567748511,-1.652313646158348
448.2000000000057,50.09504336767639,0.4042847876285711,-1.661655767063313
449.3000000000057,50.20279853495139,0.4068745746714002,-1.6728263656597537
450.40000000000566,50.31150160926336,0.4071216111959194,-1.684868255607443
451.5000000000057,50.41990424090143,0.4081438920923147,-1.6923311852845742
452.6000000000057,50.5295667121927,0.40936779936245804,-1.7031419806382107
453.70000000000573,50.63688957760861,0.4084623064959122,-1.7127355127523867
454.80000000000575,50.74542145836066,0.4074422674265351,-1.7243604244044595
455.9000000000058,50.853304715997076,0.4067841972501931,-1.735554869645926
457.0000000000058,50.96287573692753,0.4071784077515008,-1.747795130780402
458.1000000000058,51.070778996264785,0.4043751086402043,-1.7575642731527417
459.20000000000584,51.17924839651612,0.4039955033726853,-1.7666441596967695
460.3000000000058,51.28761122515474,0.40587270842145484,-1.7784615761093536
461.40000000000583,51.395085806553844,0.40529150629931954,-1.790104508630566
462.50000000000585,51.50327855753291,0.4059943785575878,-1.8024097020012366
463.6000000000059,51.60999903722695,0.4025496545562287,-1.8128900357877056
464.7000000000059,51.72060343696764,0.40139951681565667,-1.823247574268752
465.8000000000059,51.82909106772202,0.3985698893779984,-1.836369725586179
466.90000000000595,51.93742056260241,0.3953439953440554,-1.8466961627273877
468.0000000000059,52.04552800972561,0.3904078096020507,-1.8570606681332587
469.10000000000593,52.15462450139849,0.3831682847956104,-1.8681105048704403
470.20000000000596,52.26340490826324,0.3757004801718714,-1.878641960414241
471.300000000006,52.37231451017682,0.3665618584409057,-1.8890705826654917
472.400000000006,52.480363060511095,0.3495308656848618,-1.8985838523182252
473.500000000006,52.58875174864068,0.3358575705071104,-1.9092734385691275
474.60000000000605,52.6979475282799,0.3177651058845693,-1.9153278887251997
475.70000000000607,52.80598558784048,0.2993945312149565,-1.9226401206168307
476.8000000000061,52.913565775785656,0.28647381104354763,-1.9275346836036684
477.90000000000606,53.02290145519861,0.2688717167674408,-1.9327037530035653
479.0000000000061,53.13146853108204,0.2529372637328975,-1.9353606832306407
480.1000000000061,53.24060356190987,0.24056300029728372,-1.9388028146712024
481.2000000000061,53.34893157893562,0.2263928647888368,-1.9410297485290706
482.30000000000615,53.457767517164896,0.22048386877338022,-1.9401197786087452
483.4000000000062,53.565833044683494,0.2188782581430938,-1.9415455392041316
484.5000000000062,53.67513652309657,0.2148034175830963,-1.9427925368197072
485.60000000000616,53.78322704951802,0.2134319442043373,-1.9427661275409696
486.7000000000062,53.89183955895843,0.21378703626270068,-1.9440523713845397
487.8000000000062,54.000745338098966,0.21745724711354042,-1.9440723077888005
488.90000000000623,54.10806522414242,0.23133229740138306,-1.9453899319529335
490.00000000000625,54.21671718012834,0.23878397711318655,-1.9452883671433994
491.1000000000063,54.325398731801,0.24044572617114235,-1.9467224240670404
492.2000000000063,54.434928159234765,0.24745844741711354,-1.9480100012350485
493.3000000000063,54.543677018468955,0.2488617412331492,-1.948347798999856
494.40000000000634,54.652450178606564,0.25358427754069834,-1.949330038747723
495.5000000000063,54.75990142705747,0.2561296085629957,-1.9493300899999983
496.60000000000633,54.869789262719024,0.25685110724838145,-1.9493300899783401
497.70000000000636,54.97764491138284,0.25737721890847254,-1.9506920231931058
498.8000000000064,55.08603689751479,0.25474140867182116,-1.950650181962252
499.9000000000064,55.195592849064646,0.24710598595576483,-1.9506673230093843
501.0000000000064,55.30486540058304,0.23960797970914305,-1.9493401827350292
502.10000000000645,55.41419239380625,0.23365854344442383,-1.9506218483594657
503.2000000000064,55.52333529619051,0.22633442097486856,-1.9519802799349906
504.30000000000643,55.63178202912831,0.2192791827683216,-1.951970919297672
505.40000000000646,55.74218742428967,0.21193433120778193,-1.9524674514941758
506.5000000000065,55.8486110281853,0.2086952429557538,-1.9510627791350696
507.6000000000065,55.959894934499566,0.20441434771186007,-1.95097994014864
508.7000000000065,56.06926404087474,0.19702271235461177,-1.9534346668048128
509.80000000000655,56.17876789917875,0.19894312281620408,-1.9535752203128323
510.90000000000657,56.28852039102539,0.18762281583794438,-1.9536094131344326
512.0000000000066,56.39781666189587,0.1833023745182818,-1.9526200464154768
513.1000000000065,56.50814178365488,0.17354054253233997,-1.9539247855008006
514.2000000000066,56.617036608825906,0.16849931492726955,-1.9552603570699825
515.3000000000065,56.72745848344603,0.1668739450399187,-1.9541670826222717
516.4000000000067,56.836065590628905,0.1616429087209409,-1.9546001678604448
517.5000000000066,56.94523672810118,0.16376176850290325,-1.9545999834917738
518.6000000000067,57.05569569355688,0.16314691283360694,-1.9532801445304573
519.7000000000066,57.16404397219491,0.16238115337121994,-1.9546006608149051
520.8000000000067,57.27383366099686,0.16347054590598076,-1.954267397918084
521.9000000000067,57.38255851545092,0.16766558553193767,-1.9564053968160078
523.0000000000067,57.49289287461609,0.1673842429381186,-1.9565797745255034
524.1000000000067,57.60144375209348,0.16926510140133344,-1.955256689197816
525.2000000000068,57.7116465983549,0.17392305397083807,-1.9565610974690806
526.3000000000068,57.821808211216485,0.17515793282685888,-1.9565696806909503
527.4000000000068,57.93009734857135,0.18015017319551918,-1.9559102421176622
528.5000000000068,58.04019808426287,0.1832437501554799,-1.9558208139679696
529.6000000000068,58.15000210656136,0.1853619366033249,-1.9572299030754254
530.7000000000069,58.259518195763114,0.19029471107478735,-1.9572299030009086
531.8000000000068,58.36873614801498,0.19277240464719858,-1.957225839486859
532.9000000000069,58.47812235444648,0.19584854322652356,-1.9595498417464952
534.0000000000068,58.58784724052891,0.19586311367146325,-1.9582199856107336
535.100000000007,58.697733296079655,0.2035277635490954,-1.9580400112048024
536.2000000000069,58.80673411119888,0.20141410126908343,-1.9592105930983439
537.300000000007,58.91641041816481,0.2040670443038457,-1.9585459502572666
538.4000000000069,59.02543479203534,0.2082276519664732,-1.957228460230219
539.5000000000069,59.13626261336953,0.2097369765692857,-1.9572299497025045
540.600000000007,59.24572694535753,0.2130375975915102,-1.9584805841118782
541.700000000007,59.354919989543056,0.21595622571792183,-1.9578984240750241
542.800000000007,59.4650492431282,0.22047235954728261,-1.958550027656552
543.900000000007,59.57434139738438,0.2187488053469342,-1.9572331120615178
545.000000000007,59.683625215811375,0.2250538389896456,-1.95985943383929
546.1000000000071,59.79366830859688,0.2251584182485049,-1.9585382358078318
547.2000000000071,59.902385446315016,0.22530493724073763,-1.9585294709130148
548.300000000007,60.01312238909778,0.2290609975060247,-1.9571836859884932
549.4000000000071,60.12353531565454,0.22838754184247445,-1.9598738814416468
550.500000000007,60.2335095477918,0.22347703493853865,-1.9609590723237793
551.6000000000072,60.34382948083807,0.22975353785580177,-1.9585376532200955
552.7000000000071,60.453858842010824,0.23083394143511338,-1.959860221900613
553.8000000000072,60.56318823484063,0.22880988182050277,-1.9585419554297552
554.9000000000071,60.673440848905145,0.22888003857935857,-1.9598602393478224
556.0000000000072,60.782943403826636,0.23194867676037356,-1.9598601999999823
557.1000000000072,60.89256595200364,0.2341243397376247,-1.9598601999934533
558.2000000000072,61.00161350654393,0.23737101402955285,-1.9598678039167545
559.3000000000072,61.11229643636093,0.2380958165179623,-1.963874137953209
560.4000000000073,61.22181768364545,0.24130733613468314,-1.9624806667478993
561.5000000000073,61.33153335979429,0.241757798583349,-1.9616470296207034
562.6000000000073,61.441806717119455,0.24453461164299006,-1.9624900427949195
563.7000000000073,61.55128352429676,0.24333564091390625,-1.9638082193473503
564.8000000000073,61.66008846674551,0.24608271781027313,-1.9638104430244328
565.9000000000074,61.770915153424674,0.2468311120810145,-1.9638101392853118
567.0000000000074,61.880314310815315,0.24859968065133153,-1.961259257397367
568.1000000000074,61.9897050557521,0.248303253234732,-1.9621700268365618
569.2000000000073,62.0995151096991,0.2505679357440149,-1.9624744892680805
570.3000000000073,62.21031610206191,0.25160212087791045,-1.962686944177884
571.4000000000074,62.32019875845039,0.25122642969782305,-1.9624902400340791
572.5000000000074,62.4306267995937,0.25558664071889203,-1.963809889271198
573.6000000000074,62.54018917689083,0.2537492617156183,-1.9638101173716271
574.7000000000074,62.6511613292576,0.25799852140236923,-1.9651296800321072
575.8000000000075,62.761309589302584,0.25718340647287596,-1.9651298079965258
576.9000000000075,62.87100786944143,0.2581481292180414,-1.9651356946574428
578.0000000000075,62.9813993216518,0.2554665864771586,-1.9648026615064182
579.1000000000075,63.09206722672294,0.2611201414569633,-1.9665105245592813
580.2000000000075,63.20118489033231,0.260973722747738,-1.9651321722892163
581.3000000000076,63.31258763212944,0.2641728285339382,-1.9664410360901474
582.4000000000076,63.420123899802206,0.2647891957433923,-1.965139940181718
583.5000000000076,63.53354636129904,0.2656021734882892,-1.966440139031696
584.6000000000076,63.64335404376972,0.26705144395826164,-1.9651296084685885
585.7000000000077,63.753713315555586,0.26790733629127006,-1.9637545817146909
586.8000000000077,63.86360046282789,0.27217890319745464,-1.965129831118872
587.9000000000076,63.97355020549222,0.2745197331106146,-1.9651299670001392
589.0000000000076,64.08373042286757,0.27721562346038997,-1.9651298289513641
590.1000000000076,64.19399868316754,0.2775855207416169,-1.9661505004121103
591.2000000000077,64.30369956238142,0.2793184309704011,-1.9667471821404598
592.3000000000077,64.41293469784996,0.28136807085316806,-1.9669903617636573
593.4000000000077,64.5242422171496,0.28531917013029173,-1.9671100898635516
594.5000000000077,64.63390878032719,0.2868565292005061,-1.9697306019367802
595.6000000000078,64.74467265573377,0.29137156382359164,-1.9697298169979605
596.7000000000078,64.8538149889038,0.29296779117992733,-1.9697336653534077
597.8000000000078,64.9651710521979,0.2964616982035648,-1.968883592177118
598.9000000000078,65.07536085318891,0.3005326564354738,-1.9707299454319367
600.0000000000078,65.18516130788002,0.3016314182192039,-1.972017189433421
601.1000000000079,65.2954335761837,0.30499488413940723,-1.9720399759136522
602.2000000000079,65.40520864631108,0.3126305985456419,-1.9723446140167042
603.3000000000079,65.51606843939841,0.31662103747950776,-1.9724717007267962
604.4000000000078,65.62659415886414,0.31957053102846955,-1.9736860898020558
605.5000000000078,65.73605809157488,0.321833592275363,-1.9750007336355346
606.6000000000079,65.84667169564545,0.32504910731993,-1.9759899121125022
607.7000000000079,65.95698819257174,0.33159766807610835,-1.9769226809857186
608.8000000000079,66.06875578737875,0.3347180039258306,-1.9766498595632025
609.9000000000079,66.17922058240957,0.3358951339595553,-1.976650009608718
611.000000000008,66.28894427471167,0.33979005270824625,-1.9779706142874938
612.100000000008,66.39989736741643,0.3400389056328823,-1.9779595889796844
613.200000000008,66.51060366369981,0.34467741960936227,-1.9788055503890467
614.300000000008,66.62147864876495,0.34942838098280893,-1.9799284516005473
615.400000000008,66.7319350572223,0.3524559534118543,-1.9799889781776314
616.5000000000081,66.84288456141489,0.3583089995674551,-1.9816514735366395
617.6000000000081,66.95265489473755,0.3597781704066292,-1.981579881462169
618.7000000000081,67.06337341243564,0.36581418126855536,-1.982339096564837
619.8000000000081,67.17405932462691,0.3730933648037009,-1.9826056154460145
620.9000000000082,67.2831351255455,0.37789256593196563,-1.9838880018649534
622.0000000000082,67.39458437211456,0.37909856307816825,-1.9854434410383512
623.1000000000081,67.50509683184264,0.3849980138771367,-1.98651967609312
624.2000000000081,67.61554440919889,0.39241055088075893,-1.9878410959470902
625.3000000000081,67.72646675476933,0.3957932854064037,-1.9878493744148775
626.4000000000082,67.83667843404338,0.40304916784639455,-1.989084843286188
627.5000000000082,67.94800656323812,0.40604445015804735,-1.9904692248380735
628.6000000000082,68.05894706135769,0.4146388909660643,-1.9930994228779517
629.7000000000082,68.17038203933132,0.41935209528410433,-1.9944211650968615
630.8000000000083,68.28097820246845,0.42186742967281377,-1.9957408460585744
631.9000000000083,68.39154804818467,0.4315611260759262,-1.995730205084978
633.0000000000083,68.5026616636271,0.436800267322645,-1.998028460182459
634.1000000000083,68.61311387280782,0.4467066348901494,-2.001050654550502
635.2000000000083,68.72447691920708,0.4542714085775146,-2.0027148712201317
636.3000000000084,68.83497584643133,0.45756684125436764,-2.0035818978086994
637.4000000000084,68.94671479787588,0.46902456004178217,-2.0049680432403942
638.5000000000084,69.05677180147293,0.4727601062021147,-2.0069304746286245
639.6000000000083,69.16702830670692,0.4832055686582588,-2.0094147531023783
640.7000000000083,69.27822596574902,0.48763031683081115,-2.010902848284821
641.8000000000084,69.38907961992695,0.49756582656086423,-2.014937933069901
642.9000000000084,69.49919963361035,0.5031039666230865,-2.0168965007700668
644.0000000000084,69.6091810802411,0.5119118189805956,-2.0189512549196715
645.1000000000084,69.72053104928142,0.5239936162368286,-2.020331163151447
646.2000000000085,69.83094428630865,0.5303504236995751,-2.0229219651713004
647.3000000000085,69.94187017199633,0.5402628961723617,-2.025570186573945
648.4000000000085,70.05240708318136,0.5490712831232973,-2.028309898954441
649.5000000000085,70.16344194120931,0.5609470626955788,-2.0298855013319352
650.6000000000085,70.27405668244154,0.5675514204974335,-2.0334637846530415
651.7000000000086,70.38417136064261,0.5816497477650053,-2.036331802584667
652.8000000000086,70.4958971702828,0.596149426344176,-2.040655227061116
653.9000000000086,70.60616009082968,0.6125177913563995,-2.0431777145757772
655.0000000000086,70.71682991252956,0.6317595043203439,-2.044743669778414
656.1000000000087,70.82742942601567,0.6533397830739063,-2.048159150026893
657.2000000000087,70.93869836351412,0.6698949785863777,-2.0500395145466914
658.3000000000086,71.0498953928259,0.6943573175084448,-2.054074609315524
659.4000000000086,71.16010605717571,0.7183136363639102,-2.0586005135338405
660.5000000000086,71.27100467853235,0.7414837521988344,-2.0612534974370784
661.6000000000087,71.38284865681892,0.7662791916496576,-2.0653843035069595
662.7000000000087,71.49279156200365,0.791928511544963,-2.0682395763333896
663.8000000000087,71.60315076093895,0.8220851445690529,-2.0742302445469636
664.9000000000087,71.71591699657314,0.8495010271590151,-2.0792274507210333
666.0000000000088,71.82537006401559,0.8779731654633096,-2.0836325959283224
667.1000000000088,71.93601920589973,0.905499050085329,-2.0866900923727494
668.2000000000088,72.04761527816416,0.9401571958994046,-2.0918817857002274
669.3000000000088,72.15803167320419,0.9708771677954824,-2.096668978824744
670.4000000000088,72.26937655062865,1.0046549282618253,-2.1016362138055573
671.5000000000089,72.38009293420092,1.0286576435823214,-2.107438794082456
672.6000000000089,72.49104024177295,1.0644630787727827,-2.113875266825988
673.7000000000089,72.60173484890889,1.0959336319506545,-2.1189199882878698
674.8000000000088,72.71207845567305,1.127253553921644,-2.1217391593060526
675.9000000000088,72.8225733892309,1.1648421262623212,-2.1276349748174157
677.0000000000089,72.93192560100475,1.2008212839214494,-2.135394135894831
678.1000000000089,73.04501512636517,1.2308893540217747,-2.140901286692455
679.2000000000089,73.15701726462434,1.2656758655080687,-2.148068424490249
680.3000000000089,73.26771352220076,1.2965806589411564,-2.154209243188351
681.400000000009,73.37928640782994,1.3272262478035106,-2.159936133574833
682.500000000009,73.49009168198108,1.35724497427216,-2.166394564236084
683.600000000009,73.60137823428022,1.3885354866187003,-2.175430195046472
684.700000000009,73.71303810822249,1.4253191726144874,-2.1827757540107413
685.800000000009,73.82437706581403,1.4579438343349043,-2.191383511112679
686.9000000000091,73.93560699457107,1.4951521060254573,-2.19874508431992
688.0000000000091,74.04656536962474,1.5329316157179274,-2.205771949602318
689.1000000000091,74.15944850727746,1.573136102407835,-2.214169280051116
690.2000000000091,74.2718160632572,1.609330226423259,-2.22421233703123
691.3000000000092,74.3828929615161,1.6502290160542934,-2.234490478315119
692.4000000000092,74.49423816214517,1.6848019448385954,-2.244024564574902
693.5000000000091,74.60616254832917,1.7246706152568474,-2.2540352936216603
694.6000000000091,74.71757346138857,1.767185118731291,-2.264366883704486
695.7000000000091,74.82678230076209,1.8019269982256312,-2.2747941622787877
696.8000000000092,74.94019632312413,1.848201927299253,-2.2846563371421906
697.9000000000092,75.05174179715766,1.8848425383207612,-2.297625946819413
699.0000000000092,75.1618636071125,1.925666441152989,-2.3076564913254454
700.1000000000092,75.27476521017763,1.9701052921818072,-2.3215805349935463
701.2000000000093,75.38527565428826,2.010523085418802,-2.334001436069615
702.3000000000093,75.49723862696285,2.0499528139999628,-2.3442437424960083
703.4000000000093,75.60797645018332,2.089583688932076,-2.3570715410095127
704.5000000000093,75.71917956757194,2.126199269313836,-2.3690899184367193
705.6000000000093,75.83087158104814,2.162184565816553,-2.383819385897254
706.7000000000094,75.94162742306256,2.200648725087432,-2.3970163616879168
707.8000000000094,76.05258715978479,2.2342939744958796,-2.4090857999080657
708.9000000000094,76.16302358806189,2.267196075991756,-2.4236865191424455
710.0000000000093,76.27451316885457,2.297384940303906,-2.4346324412956886
711.1000000000093,76.38654213599821,2.334227842240676,-2.452238999857749
712.2000000000094,76.49628460999863,2.364455305744642,-2.466560086919703
713.3000000000094,76.60750840690035,2.3956379330382696,-2.4818593926168164
714.4000000000094,76.71860389559293,2.4266404871352196,-2.494684391437999
715.5000000000094,76.8296910355192,2.455824731013596,-2.509249344536426
716.6000000000095,76.93872027851364,2.4849494333336772,-2.523860892772733
717.7000000000095,77.0538865068248,2.513769070547394,-2.5402262814682994
718.8000000000095,77.16444082368531,2.539431994622377,-2.5562498103173423
719.9000000000095,77.27681011599105,2.5662563666009817,-2.571510700988884
721.0000000000095,77.38782345715005,2.582336334851666,-2.586059363694468
722.1000000000096,77.49852267479412,2.601398139347768,-2.6053468881993322
723.2000000000096,77.61060818165582,2.616264942078364,-2.6217411674653857
724.3000000000096,77.72162484334412,2.6320539846409448,-2.636904217021355
725.4000000000096,77.83203875022595,2.6363869428764937,-2.651615291123518
726.5000000000097,77.94402848587336,2.6252069907783326,-2.6683475062352566
727.6000000000097,78.05583454114544,2.6087120545190414,-2.6841503301845737
728.7000000000096,78.1663698378891,2.576419102672765,-2.7007462301658656
729.8000000000096,78.27712625238722,2.5233403920614697,-2.7164103783643796
730.9000000000096,78.38925429118463,2.449321487123308,-2.7336882918301546
732.0000000000097,78.49991518608608,2.331512175366334,-2.750356866006241
733.1000000000097,78.61139810402312,2.1479486936992664,-2.761929222266164
734.2000000000097,78.72203594131967,1.8501908860659864,-2.77456232788452
735.3000000000097,78.833559155366,1.3134986122244885,-2.783588200105531
736.4000000000098,78.94403064866452,0.56629588236221,-2.787050004854895
737.5000000000098,79.05413142052838,0.2891739632637993,-2.7880996860455944
738.6000000000098,79.16552877873836,0.20647289455066065,-2.7894187055499913
739.7000000000098,79.27660032795102,0.18242239820350914,-2.7907351397902893
740.8000000000098,79.38849320514338,0.17343929126107804,-2.7920487574063184
741.9000000000099,79.49834067385406,0.1698965624800639,-2.7907400316832467
743.0000000000099,79.6105108793056,0.16657240850929722,-2.7907400280406383
744.1000000000099,79.72152165808086,0.16735377860968925,-2.7914340203610726
745.2000000000098,79.83295342435002,0.17386126946914127,-2.792048558214426
746.0000000000099,79.91402698092764,0.16861665529057412,-2.7920395481294635