File: 01_Data/Nylon_Carpet_Low_Pile/STA/N2/10K_min/Nylon_Carpet_Low_Pile_STA_N2_10KData_220105_R2.csv
##Temp./Â°C,Time/min,DSC/(mW/mg),Mass loss/mg
50.0,10.767506474977424,0.04037458337376132,-0.023129571310690267
51.100000000000016,11.06161157304365,0.08096961127083047,-0.02416778960901178
52.20000000000003,11.273041683716231,0.10981851924987196,-0.024887279272112206
53.30000000000005,11.448579515725195,0.1322924280229486,-0.02482656707680375
54.40000000000006,11.606431396743346,0.14721969057225803,-0.026367941604032552
55.50000000000008,11.753262439952566,0.16344317165406463,-0.025299513808231477
56.600000000000094,11.89212889444155,0.17146604996871462,-0.02565439534267444
57.70000000000011,12.025784292216779,0.1820830449128228,-0.025606414498904773
58.800000000000125,12.156994781376715,0.1899144844117815,-0.02667203226507553
59.90000000000014,12.285469982159812,0.1949744235406976,-0.027123923069634515
61.000000000000156,12.411163179583532,0.20085481033871577,-0.026511203297999497
62.10000000000017,12.535141519739827,0.20417388880865384,-0.027866080469705512
63.20000000000019,12.656804723483035,0.21028494819673005,-0.02749672295862471
64.30000000000021,12.77930525011806,0.21420148688163887,-0.028563079572272
65.40000000000022,12.898783538689795,0.2178398621809572,-0.027762811698604395
66.50000000000023,13.019200425709878,0.22044078082215024,-0.027764148159678648
67.60000000000025,13.13946711696484,0.22584983504603773,-0.027779803579452977
68.70000000000027,13.258540068614199,0.22700082548603218,-0.02779605472808777
69.80000000000028,13.376741229916894,0.22946582054432352,-0.02775814419765954
70.90000000000029,13.495126354865231,0.23299249098674957,-0.029114431893714432
72.00000000000031,13.612117925200026,0.2348470456563594,-0.029068772915207042
73.10000000000034,13.726683742293302,0.23635510915361113,-0.029074105255391558
74.20000000000034,13.843323320217566,0.24074163690224704,-0.029071166721125863
75.30000000000035,13.958437204560148,0.2435959012851987,-0.02904017707193729
76.40000000000038,14.075416321038206,0.24604245292469618,-0.0290544650692115
77.5000000000004,14.189290369719515,0.24798088386045503,-0.029080443620317364
78.6000000000004,14.302282301069132,0.2471055186264513,-0.02905672827015815
79.70000000000041,14.416887397914838,0.25348019132385646,-0.029124018645931393
80.80000000000044,14.529592898649486,0.25452220937810666,-0.029849866561851623
81.90000000000046,14.643185027149238,0.2566411607418625,-0.02920704723524059
83.00000000000047,14.756179242102107,0.25632116381863806,-0.030611797487334336
84.10000000000048,14.86646209673058,0.2594111547464841,-0.030504610706353574
85.2000000000005,14.980408281254363,0.26129387434416973,-0.029843161467364432
86.30000000000052,15.091800084162182,0.2630980081209933,-0.03050212256089946
87.40000000000053,15.202300287743828,0.2633764164093169,-0.030499538247661828
88.50000000000054,15.31502626103395,0.2642299546303438,-0.03313134561198261
89.60000000000056,15.425509508343339,0.26719773677591013,-0.032463232449005286
90.70000000000059,15.534153134258538,0.26727995632796575,-0.031125005987803878
91.8000000000006,15.64471069323833,0.2687378322955117,-0.031144343468351376
92.9000000000006,15.754868235423059,0.27141767794690896,-0.03254395942982802
94.00000000000063,15.864566552454388,0.2725220577355132,-0.033791586821373176
95.10000000000065,15.973998700637935,0.2726858860550177,-0.03444988954451356
96.20000000000066,16.083637362683678,0.27219895446781567,-0.03314056310351887
97.30000000000067,16.1930778038355,0.27582205473246885,-0.03303583029909918
98.40000000000069,16.301619135959577,0.2763045032479334,-0.03444915762660594
99.50000000000071,16.41061194636058,0.27774426090114346,-0.03448543481533317
100.60000000000072,16.518390175293963,0.2793764562781659,-0.03570958453770201
101.70000000000073,16.62788695311628,0.279426640366506,-0.03617666357323257
102.80000000000075,16.73507876546665,0.27825479572686085,-0.034450152937874456
103.90000000000077,16.84391616982229,0.2811292402191726,-0.03610279042902631
105.00000000000078,16.950744228955966,0.2819243183334403,-0.03630499290693656
106.10000000000079,17.059677882547987,0.2842852493510511,-0.03577686452912188
107.20000000000081,17.166804459859087,0.28488391259028717,-0.03838127003100311
108.30000000000084,17.274627797398697,0.2842795940392921,-0.039710517421919445
109.40000000000084,17.383180722376103,0.28243088058509,-0.03839001691958055
110.50000000000085,17.490262661267312,0.28330831281068103,-0.038390020350075105
111.60000000000088,17.59825663704082,0.28307614498829914,-0.03734547911422226
112.7000000000009,17.706204787812787,0.28270695016262276,-0.03838584685423552
113.8000000000009,17.813947763244048,0.28171255725018013,-0.03707993076539706
114.90000000000092,17.922268674651647,0.28003850619713744,-0.0383953863648574
116.00000000000094,18.02936450233714,0.281177609010962,-0.03970973537203326
117.10000000000096,18.136758741059005,0.2808454094514241,-0.041029957178102094
118.20000000000097,18.24451846543009,0.27963653765174507,-0.04094583166802579
119.30000000000098,18.352108616722028,0.2825831938824941,-0.04037968128571956
120.400000000001,18.459374171676163,0.282621898259143,-0.040060101095134026
121.50000000000102,18.566077247916677,0.2831069438915822,-0.040049979539238834
122.60000000000103,18.674788152681415,0.28163641637032844,-0.03939234051407947
123.70000000000104,18.783334446660778,0.28149230190442986,-0.03937664837634536
124.80000000000106,18.888825082418464,0.28236682518882894,-0.04070022857557509
125.90000000000109,18.996797944238228,0.28385886794526044,-0.04202020733639644
127.0000000000011,19.10326536207555,0.2823894805655849,-0.042020147987082535
128.1000000000011,19.21114283932389,0.2841550570370468,-0.042041037797180714
129.20000000000113,19.31797009502017,0.2857058865871362,-0.04333014698070947
130.30000000000115,19.42494802470079,0.28295668043440725,-0.043317332829698074
131.40000000000117,19.53019744358712,0.28560095362169724,-0.04333541030167032
132.50000000000117,19.63736353564361,0.2879350740641136,-0.04470793968928133
133.6000000000012,19.742937642401813,0.28833110089666775,-0.04597000012396801
134.7000000000012,19.85224934667655,0.2909234450887347,-0.04332692000660865
135.8000000000012,19.958003790335805,0.2912902614794147,-0.04347559438460458
136.90000000000123,20.065028689010532,0.2910555470566119,-0.04432033957398618
138.00000000000125,20.171115610895903,0.29160001990284895,-0.042889858034225625
139.10000000000127,20.276755589295753,0.29227576841903014,-0.04428259588265382
140.2000000000013,20.384577300934627,0.2932309416646034,-0.04586802838276505
141.3000000000013,20.48970333253629,0.2932477327491587,-0.0461760826372446
142.4000000000013,20.59683735622538,0.2965741589550456,-0.04551993480119032
143.50000000000134,20.702530620238,0.29747527504622395,-0.045855560343104784
144.60000000000133,20.808600689257705,0.29834365996805956,-0.04640457447724344
145.70000000000135,20.916078890333136,0.30088682775817177,-0.04702607192994401
146.80000000000138,21.021749507556336,0.30246177871053925,-0.04782913899357544
147.9000000000014,21.126320365491033,0.3057567279609089,-0.047829968472144824
149.00000000000142,21.23218641438365,0.3055266772891786,-0.046509648969796036
150.10000000000142,21.33899906718948,0.31229360894357405,-0.04650839209719271
151.20000000000144,21.443920098767133,0.3130078896486671,-0.04915026384551391
152.30000000000146,21.550094161381093,0.31634165766128675,-0.04782987850707521
153.40000000000146,21.656586000176375,0.3185545615862473,-0.047829903999391465
154.50000000000148,21.76203540262317,0.32391247811659885,-0.0478299057877587
155.6000000000015,21.867614961863367,0.3257478132744689,-0.046531569170009224
156.70000000000152,21.972776143789307,0.33148117139216837,-0.04749041124771436
157.80000000000155,22.079784099767128,0.33928160693365744,-0.04750176436807951
158.90000000000154,22.185245906611147,0.34591244894648066,-0.04849237932563888
160.00000000000156,22.289543442256665,0.3526312903074288,-0.04815728363383576
161.1000000000016,22.397037762075943,0.36099650936074,-0.04783127464484993
162.20000000000158,22.50331496457548,0.36949665356606753,-0.049150162284531174
163.3000000000016,22.607101498573467,0.3761355227043848,-0.04915018308025898
164.40000000000163,22.714028115322137,0.3828155453931903,-0.0504584803002901
165.50000000000165,22.820676731078546,0.38563958855135183,-0.051117805393477767
166.60000000000167,22.925524163823546,0.38003116857348096,-0.049800094104373915
167.70000000000167,23.031259091795377,0.37292772105483274,-0.04849762471292207
168.8000000000017,23.136537921202887,0.3616318127004361,-0.05079023668388283
169.9000000000017,23.241928179611193,0.3504947342302212,-0.04947009524917556
171.0000000000017,23.347753703527605,0.33956908871887986,-0.049469841681291093
172.10000000000173,23.45351086161194,0.33040251653835456,-0.048814701134030525
173.20000000000175,23.559412237649937,0.326697735588609,-0.04882007896922991
174.30000000000177,23.664729336883546,0.3188388964273714,-0.05014058669176613
175.4000000000018,23.768164317708415,0.3177049496434577,-0.04948003965227077
176.5000000000018,23.874226694812045,0.31490069343659666,-0.0494798559455818
177.6000000000018,23.979557981071757,0.31395212699993164,-0.05364451905047263
178.70000000000184,24.085582009678607,0.3157220119779149,-0.052276158243422355
179.80000000000183,24.18989679964075,0.3130837378279036,-0.05058014337563099
180.90000000000185,24.29482165075254,0.31543856098470674,-0.050579840566189915
182.00000000000188,24.402675890681326,0.31569863235851076,-0.051890459141745726
183.1000000000019,24.50714141961531,0.313892308663945,-0.05189634108508434
184.20000000000192,24.61147775742173,0.3162072605318998,-0.05062754221130161
185.30000000000192,24.717665953569735,0.3147027465308098,-0.05056937376163839
186.40000000000194,24.820545827927216,0.3157334928477508,-0.05189038708325677
187.50000000000196,24.92715375995471,0.3192830305519859,-0.0505804607550604
188.60000000000196,25.03268267050409,0.31915399021380797,-0.05058002076615464
189.70000000000198,25.137668290215604,0.3188510553159031,-0.051232302663458906
190.800000000002,25.2423924076278,0.3213227836845188,-0.053203034618397815
191.90000000000202,25.347838317860948,0.32085409057081327,-0.05449962754492743
193.00000000000205,25.452301131827053,0.32163271306691205,-0.05583902708182187
194.10000000000204,25.558727588824777,0.32309166169052417,-0.053208462121455025
195.20000000000206,25.663504733793793,0.3230691581048947,-0.05349119524099999
196.3000000000021,25.76832780466796,0.3261650563814379,-0.05583980051043147
197.40000000000208,25.873488162960562,0.32573897873217383,-0.05517444083523104
198.5000000000021,25.978209747238107,0.3285742545953853,-0.0547475281690879
199.60000000000213,26.0829731466382,0.3288212734936536,-0.05382457659945494
200.70000000000215,26.18874558711793,0.3308938217951608,-0.05353173348726825
201.80000000000217,26.29324808220191,0.33205021133008916,-0.05321126882017557
202.90000000000217,26.398925315325002,0.33190691100596115,-0.054496089471279596
204.0000000000022,26.502889529317915,0.3351900295270499,-0.05570940451438666
205.1000000000022,26.60743809293284,0.3382250577731097,-0.05583386560877379
206.2000000000022,26.713779541320594,0.3388740865361481,-0.05320997397510041
207.30000000000223,26.81859065844264,0.34477162844035913,-0.054523912834637756
208.40000000000225,26.923407618122855,0.344878350247216,-0.055806703550647985
209.50000000000227,27.030000000000218,0.3503726318063132,-0.05889232823472268
210.6000000000023,27.134915783523706,0.3544336679024781,-0.056167660524088614
211.7000000000023,27.23970641274302,0.3642834393939265,-0.05748715168522889
212.8000000000023,27.34585476091659,0.37636804143906044,-0.05651281539144426
213.90000000000234,27.45088617609997,0.3969906795414907,-0.05812995566499213
215.00000000000233,27.556967102028416,0.42757262943247787,-0.05818541685316969
216.10000000000235,27.661826147629924,0.4746793449180121,-0.05809058330484573
217.20000000000238,27.76649642922191,0.5337484710740353,-0.05978305497253089
218.3000000000024,27.872792146172376,0.5996804446611603,-0.05838259919820166
219.40000000000242,27.978514280237214,0.6577759964958009,-0.05977234438352319
220.50000000000242,28.08424709756311,0.7022751589596844,-0.058800282735784304
221.60000000000244,28.190614538082926,0.7176045811104177,-0.05747101459881376
222.70000000000246,28.297280790491143,0.6859023148228593,-0.05677916106857639
223.80000000000246,28.402595431522506,0.6187634273081357,-0.0561698682754046
224.90000000000248,28.507535586568036,0.5453022420754429,-0.057547915427039076
226.0000000000025,28.611276465501717,0.48255782782149736,-0.05846413149359586
227.10000000000252,28.717231150415277,0.4370928082603335,-0.05846991412765812
228.20000000000255,28.822006219663265,0.40090741449306355,-0.05879972232112518
229.30000000000254,28.926076498617817,0.37555685221728013,-0.058802022644782515
230.40000000000256,29.02981399323532,0.3586287077021332,-0.060780105540094276
231.5000000000026,29.136995080397266,0.34609331441448876,-0.06209995449434169
232.60000000000258,29.236693564755,0.3391882122950999,-0.060760712175094156
233.7000000000026,29.34538625615992,0.3324200248193626,-0.06078006528514823
234.80000000000263,29.45009804702368,0.3327251701572931,-0.059438488966910175
235.90000000000265,29.55469411426176,0.3328579089609772,-0.05946014426887869
237.00000000000267,29.660085852687907,0.32725857949132686,-0.06077935351581987
238.10000000000267,29.76504955698632,0.32752938299146506,-0.06078007998745605
239.2000000000027,29.870096475294098,0.32859866109772323,-0.06078278989791963
240.3000000000027,29.97361027729058,0.3278555473660841,-0.06218139622519869
241.4000000000027,30.080628412538893,0.3287808406019017,-0.0627511509369354
242.50000000000273,30.18489394346311,0.32792849515986916,-0.06175502585127246
243.60000000000275,30.290190404222898,0.3302706580821561,-0.06307981413427921
244.70000000000277,30.395148530814357,0.3302325845272703,-0.06307987174666829
245.8000000000028,30.501139852744284,0.32986827298945015,-0.06177110263121888
246.9000000000028,30.606410288816942,0.32965711231030614,-0.06425840810438821
248.0000000000028,30.71170327517242,0.3294678756248603,-0.06406040024123305
249.10000000000284,30.8152553917897,0.3278524138335071,-0.0653827171431911
250.20000000000283,30.920721811178637,0.3283951960855371,-0.06537996915031474
251.30000000000285,31.025940099534065,0.32525122136335577,-0.06514377779999148
252.40000000000288,31.131027419196784,0.32943311192395697,-0.06604006137783713
253.5000000000029,31.236949805220437,0.3284103427727378,-0.06604380018716816
254.60000000000292,31.342252702585306,0.3290843426810451,-0.06604008698891084
255.70000000000292,31.446646894068078,0.32806870631217794,-0.0660400870013036
256.8000000000029,31.552297228874778,0.32854879315756014,-0.06603891338653645
257.90000000000293,31.65791212718741,0.33172165290060107,-0.06636999940493116
259.00000000000296,31.76215262790108,0.3290847294142827,-0.06637000179861419
260.100000000003,31.86809205826048,0.3299655130392865,-0.06769429481615408
261.200000000003,31.972944449822833,0.3321020064796469,-0.06768999399771891
262.300000000003,32.07720738324985,0.3320162838581492,-0.06768995253103016
263.40000000000305,32.18308754477601,0.33076553690724203,-0.06867810459531354
264.50000000000307,32.28813875044777,0.33130546735812183,-0.06833646001486393
265.6000000000031,32.39274367326174,0.3284743788624411,-0.06833278756088079
266.7000000000031,32.49956069352649,0.327759803539987,-0.06593663652628834
267.8000000000031,32.60367850038347,0.3288854083887469,-0.06736008687121275
268.9000000000031,32.708524938720004,0.32935231251551755,-0.06680851419060341
270.0000000000031,32.81554863128777,0.32917540427131475,-0.06740591765326087
271.10000000000315,32.91963706673226,0.32819854998845027,-0.06998609951160573
272.2000000000032,33.02425871432532,0.33019847693365345,-0.07131018512764964
273.30000000000314,33.13028684394416,0.33009908248359093,-0.07261980646960531
274.40000000000316,33.23567992884105,0.3286349065982168,-0.07260640967384457
275.5000000000032,33.341593731460016,0.330383586033934,-0.07130947243214658
276.6000000000032,33.44611411685883,0.3292508867432423,-0.07037999334625766
277.70000000000323,33.55160969444478,0.32723700686856944,-0.07096989305567991
278.80000000000325,33.65737835821682,0.32703032547018496,-0.07229030072872833
279.9000000000033,33.762438767255716,0.3270901860392031,-0.07228990800014934
281.0000000000033,33.868344491462,0.3278564223650988,-0.07228990800000101
282.1000000000033,33.97355140799836,0.32869184064974327,-0.07228990821572312
283.20000000000334,34.079137894326294,0.3295521457888626,-0.07251116830696303
284.30000000000337,34.184603260013,0.330019440119521,-0.07392761325664798
285.40000000000333,34.29008516996287,0.3303785494819941,-0.07361087140995881
286.50000000000335,34.39591525073124,0.3326365652851673,-0.07360993301148655
287.6000000000034,34.50128228352565,0.3327805675937663,-0.07359826647040757
288.7000000000034,34.60639550014374,0.3305191988245649,-0.07524958504643298
289.8000000000034,34.711895349514094,0.33323924180445197,-0.07493131813919085
290.9000000000034,34.81771676059131,0.33237647523174507,-0.07460003334707244
292.0000000000034,34.923079663935155,0.3335715943827597,-0.07525847587207446
293.10000000000343,35.029529979701195,0.3324425099936487,-0.075261307775361
294.20000000000346,35.134626011997746,0.334643483134346,-0.0775498840997666
295.3000000000035,35.24069989394003,0.33719129378750157,-0.07755210505107923
296.4000000000035,35.34650864015725,0.33718224509623,-0.07639644578004079
297.5000000000035,35.452294369209135,0.3377005258073111,-0.07723000737340868
298.60000000000355,35.5578699221425,0.33940465241775386,-0.07853849654861689
299.70000000000357,35.663234144454734,0.33896885234208296,-0.07723008685694976
300.8000000000036,35.769317005162414,0.3389238018239223,-0.07804201426214474
301.9000000000036,35.874686893861316,0.3417296009950226,-0.07853213252820801
303.0000000000036,35.97750058733465,0.34177330989041105,-0.07986021545859234
304.1000000000036,36.08667646427857,0.3453714524986528,-0.0811800159440641
305.2000000000036,36.19212607998701,0.3475649141511106,-0.08113732028317866
306.30000000000365,36.2977805846969,0.3484374241206196,-0.08268835335696023
307.4000000000037,36.40296453384279,0.34666588838685797,-0.0841300384014474
308.5000000000037,36.50886235662671,0.3493917772401095,-0.08413041586365866
309.60000000000366,36.61417299748162,0.3529228770587649,-0.08544977644292562
310.7000000000037,36.72048401003163,0.3535323519683749,-0.08676665629913449
311.8000000000037,36.82653183113476,0.3549809737923378,-0.0894457659387391
312.90000000000373,36.93155333993659,0.35753249404158555,-0.09072002541869528
314.00000000000375,37.03846219485383,0.3593408620531786,-0.0920770895398193
315.1000000000038,37.143772955053436,0.35829247383700075,-0.09235962132696152
316.2000000000038,37.25028737191412,0.3574399990851793,-0.0942025018127004
317.3000000000038,37.356583851050935,0.35915750057652335,-0.09557507400042997
318.40000000000384,37.46169901942422,0.35837725242816665,-0.09811138614043058
319.5000000000038,37.567178223188485,0.36098851114488184,-0.09833285694802152
320.60000000000383,37.67368232507111,0.36347722674540756,-0.10036016860812147
321.70000000000385,37.77937731606796,0.3656037809507816,-0.10235033752365474
322.8000000000039,37.88612385758434,0.36356726976115117,-0.10355255081658976
323.9000000000039,37.99159407907721,0.3673446351402947,-0.10640594448104768
325.0000000000039,38.097759889514265,0.3696213241092014,-0.11072290557497988
326.10000000000394,38.20405932363899,0.3721915971402794,-0.10941053374257059
327.2000000000039,38.31057882494978,0.374974714546121,-0.11369501290423445
328.30000000000393,38.416279796197074,0.37780685319010887,-0.11718742518772718
329.40000000000396,38.52335815394924,0.3805058842094573,-0.11976339962426552
330.500000000004,38.62917334715401,0.3818755208375669,-0.12506591072675333
331.600000000004,38.73579087979611,0.38612455999456974,-0.12958553863789257
332.700000000004,38.84152701573292,0.3902210823053045,-0.13198025322695894
333.80000000000405,38.94774561853328,0.3951807006319823,-0.1361015667201686
334.90000000000407,39.055380533346316,0.4004447024620716,-0.13765818065305035
336.0000000000041,39.160919503153345,0.40325525310569105,-0.14524367721871423
337.10000000000406,39.26765574945604,0.4094996985127807,-0.15177105205960384
338.2000000000041,39.372761647119674,0.41639397153063595,-0.15361014281967966
339.3000000000041,39.48068834374714,0.4218841220263565,-0.16001047492381248
340.4000000000041,39.58369154310235,0.42811507541934934,-0.16630615957626915
341.50000000000415,39.690337369405015,0.4351607690410161,-0.1717943702830751
342.6000000000042,39.79969200762296,0.44430270561689433,-0.17780121948040462
343.7000000000042,39.90588975003808,0.451223161616077,-0.18400634705188024
344.80000000000416,40.01238509984106,0.4597822014783399,-0.1938900198955804
345.9000000000042,40.117874118310816,0.4681436625402917,-0.2006901929176106
347.0000000000042,40.22527694772392,0.47737883656367186,-0.20922185117059655
348.10000000000423,40.332322525782715,0.48319580845357524,-0.2201225927300121
349.20000000000425,40.43811981201113,0.4905193817960561,-0.2274995072286803
350.3000000000043,40.54506543867707,0.5039591838661686,-0.23733077009030001
351.4000000000043,40.65197046625979,0.512326605492932,-0.24630692774411322
352.5000000000043,40.759336534993544,0.5212422318712333,-0.2569785384770378
353.60000000000434,40.865739858252255,0.531265747795545,-0.27013153546813573
354.7000000000043,40.97264201058428,0.5415825561273928,-0.2816673231025355
355.80000000000433,41.07965231223626,0.5522767348622395,-0.2924201149981984
356.90000000000435,41.18567120035159,0.5595363472248327,-0.305779615835978
358.0000000000044,41.292969041238464,0.570357517095851,-0.3194729469564228
359.1000000000044,41.400487156592455,0.5814601244716473,-0.3326499380440846
360.2000000000044,41.506574450278634,0.5877860275152889,-0.3448479621092182
361.30000000000445,41.614836774849415,0.597253661306358,-0.3586146288126142
362.4000000000044,41.72081007993939,0.6070237404502072,-0.37161610758895236
363.50000000000443,41.826730233417265,0.6214841532482627,-0.3883999931254847
364.60000000000446,41.9331135782474,0.628651327200374,-0.40410091014146454
365.7000000000045,42.039696100124466,0.6385384945144494,-0.4213691325337501
366.8000000000045,42.14725592309975,0.6475782051687204,-0.43829876548964863
367.9000000000045,42.2530577981889,0.6594747851494508,-0.4538032832170811
369.00000000000455,42.36115391765503,0.668875629660328,-0.47332684113274803
370.10000000000457,42.467429931892255,0.6790367316908104,-0.49109021102054573
371.2000000000046,42.57377557796083,0.685674766218518,-0.5107373818473215
372.30000000000456,42.68162149475435,0.6968644924071039,-0.5293545530333015
373.4000000000046,42.78881296177111,0.7110718929219904,-0.5509167172646241
374.5000000000046,42.895657968077394,0.7205006392550435,-0.5717458580259036
375.6000000000046,43.00134265609336,0.7322008619252578,-0.5914578238477373
376.70000000000465,43.10927043304737,0.7443524440849278,-0.616006849792138
377.8000000000047,43.216202906749075,0.7552067866296779,-0.6379907566137932
378.9000000000047,43.32325612000656,0.7663600156123985,-0.6624103090558173
380.00000000000466,43.43027446271221,0.7770186670812478,-0.685836460095858
381.1000000000047,43.53755878368186,0.7883469432925504,-0.7125725521350388
382.2000000000047,43.64445858982225,0.7996956545574863,-0.7370441362471807
383.30000000000473,43.75235253008881,0.8085358074132039,-0.7656308709395039
384.40000000000475,43.859900787003475,0.8197633648227771,-0.7945159565768511
385.5000000000048,43.967036698199976,0.8279815283892172,-0.8207599333282611
386.6000000000048,44.073610269863174,0.8360250286972446,-0.8488117788993459
387.7000000000048,44.181269830897406,0.8401680378314519,-0.8788458252591873
388.80000000000484,44.28912051751276,0.843258528124189,-0.9091406249219158
389.9000000000048,44.39606471008009,0.8468535085828344,-0.9395991225485885
391.00000000000483,44.50416435171858,0.8460924212370688,-0.9708418716199065
392.10000000000485,44.611026410100195,0.8411747666102514,-1.0012381005815834
393.2000000000049,44.71926014756934,0.834203728952392,-1.0332094553592106
394.3000000000049,44.826629850867135,0.8213738877582988,-1.0653502481543922
395.4000000000049,44.934423214756855,0.8059029206497261,-1.097485549954465
396.50000000000495,45.04081535259982,0.783540358339298,-1.1260632007121862
397.6000000000049,45.14820737147039,0.7589411885058547,-1.1564921604775376
398.70000000000493,45.25501107137573,0.7292328774300753,-1.1854969074358843
399.80000000000496,45.36333600343228,0.6911170898728891,-1.2148914893311167
400.900000000005,45.47069978225173,0.656464304361819,-1.2409332058402898
402.000000000005,45.57721261071567,0.6096396319355875,-1.2653552699410278
403.100000000005,45.68477934036742,0.5652968182571038,-1.289151458786841
404.20000000000505,45.79221547198886,0.5231385045849957,-1.3112157954001251
405.30000000000507,45.89943368974945,0.478992613505269,-1.3296296017133904
406.4000000000051,46.00515062983663,0.43935700066758854,-1.3475654651381732
407.50000000000506,46.11185442863343,0.40118221338546584,-1.3627616979947468
408.6000000000051,46.21950689853736,0.37273504096167653,-1.3785557243213313
409.7000000000051,46.3268515611583,0.34484572693322224,-1.3931423379300756
410.8000000000051,46.433460967865386,0.32526757154690705,-1.4053661486923188
411.90000000000515,46.540928224906054,0.3073551765583074,-1.4145152279662443
413.0000000000052,46.64615058564197,0.2957455284585884,-1.4281043684488068
414.1000000000052,46.755124660576826,0.2843726854249167,-1.4379242812594648
415.20000000000516,46.86276650241357,0.2742657747927439,-1.4479531015320788
416.3000000000052,46.96980338816045,0.2646889577225615,-1.4567334420781686
417.4000000000052,47.07818349935807,0.2626100521168219,-1.465679729939894
418.50000000000523,47.18456942426945,0.2601480044977951,-1.4757155052334432
419.60000000000525,47.29298685253119,0.25340212187570677,-1.4836084064343185
420.7000000000053,47.40048124843987,0.2520827951365101,-1.4913640460896818
421.8000000000053,47.50788684915836,0.2468314814696303,-1.5002540803897242
422.9000000000053,47.6152402148946,0.24559655694433824,-1.5087983490713124
424.00000000000534,47.72441153560956,0.24319660080041955,-1.518702342435661
425.1000000000053,47.83184723963418,0.24140592921472265,-1.5277882414123538
426.20000000000533,47.9397549567237,0.24146140120871973,-1.5332899461322178
427.30000000000535,48.04764206509796,0.23822839253359912,-1.5425991642552543
428.4000000000054,48.155475950171606,0.23687493301156737,-1.5534567606630891
429.5000000000054,48.26450300888417,0.23684184679912418,-1.5619247567711652
430.6000000000054,48.37240589483418,0.23739590418675172,-1.5717499713533112
431.70000000000545,48.47990674238715,0.23395325564048647,-1.5797004489069852
432.8000000000054,48.5872200936307,0.23129724069723917,-1.5885814614560845
433.90000000000543,48.69504026477986,0.23265140425062092,-1.5973313769603141
435.00000000000546,48.80391236761082,0.23109200336284974,-1.6034692879882892
436.1000000000055,48.91144737273958,0.23124608200750574,-1.6127285793131292
437.2000000000055,49.01941609110589,0.23254311229024122,-1.622423163929354
438.3000000000055,49.12755948420312,0.22899507220131488,-1.6329496521631146
439.40000000000555,49.234336963842715,0.23114233264488,-1.6403315447313767
440.50000000000557,49.34404997494407,0.22660075673686453,-1.6503200194009429
441.6000000000056,49.45219088791243,0.22830103593650986,-1.6577694797458586
442.70000000000556,49.559998975007176,0.229389054144852,-1.667889851505719
443.8000000000056,49.66762513043029,0.2282519777951183,-1.677456307703956
444.9000000000056,49.77515285728152,0.2287933677242422,-1.6876230527065461
446.0000000000056,49.88446229396507,0.22767411443988717,-1.6973754037890076
447.10000000000565,49.99151808249721,0.22721075026506887,-1.7056456266234843
448.2000000000057,50.10062285775703,0.22625789719435763,-1.7159565094024094
449.3000000000057,50.208987733035826,0.22749108813587304,-1.7259418080923385
450.40000000000566,50.316768555900055,0.22641002046665382,-1.7363060503082193
451.5000000000057,50.42498839343999,0.22499860334802135,-1.7460130203904973
452.6000000000057,50.533166043794175,0.22554451825408528,-1.758292969894561
453.70000000000573,50.64072631720394,0.22348417912465468,-1.7677962947945183
454.80000000000575,50.74898740737359,0.22342318285803042,-1.778780796179881
455.9000000000058,50.85737181278113,0.22191439239669086,-1.78909209291764
457.0000000000058,50.96632514418643,0.21893000409169316,-1.8005878289138133
458.1000000000058,51.07501931043873,0.21766880198155547,-1.8115886527661043
459.20000000000584,51.18281455018761,0.21543767340043407,-1.822030245209036
460.3000000000058,51.291629091978095,0.21682007065778564,-1.832814916112147
461.40000000000583,51.40070052644557,0.2127029578943732,-1.843993865062552
462.50000000000585,51.50979755747075,0.20891532944341196,-1.8552189189191073
463.6000000000059,51.61718581611738,0.20563553811292434,-1.868157591640486
464.7000000000059,51.72584557677067,0.20352141637514787,-1.8793448359985363
465.8000000000059,51.83389731854782,0.19963058557498525,-1.8891350236864453
466.90000000000595,51.943425515195926,0.1925466313137476,-1.9007635838796961
468.0000000000059,52.05135223347805,0.1849940383842238,-1.9096094678151396
469.10000000000593,52.1604971122621,0.1800138956274695,-1.9225186026801966
470.20000000000596,52.268619387413885,0.16914860891299477,-1.9329563950697923
471.300000000006,52.37703764331333,0.15242697397693172,-1.9423900162771104
472.400000000006,52.48471104754811,0.1399900658836688,-1.9509100425950772
473.500000000006,52.59474001387372,0.12202576122913922,-1.958809461232907
474.60000000000605,52.701739320188196,0.10347314943646024,-1.9652355911456025
475.70000000000607,52.81096301156974,0.08663376049317484,-1.9672387423198603
476.8000000000061,52.919367738411175,0.06952009073687115,-1.9721072153353894
477.90000000000606,53.028194160813285,0.05241971498061837,-1.9757238734064764
479.0000000000061,53.13630799979662,0.04048204424967439,-1.9801654611826105
480.1000000000061,53.244256468791214,0.027444162669250427,-1.9823753857951432
481.2000000000061,53.35214270090138,0.0188441927259434,-1.9836725856733979
482.30000000000615,53.461970843612995,0.013517740537424494,-1.986308542581146
483.4000000000062,53.57000093379125,0.011650183760739341,-1.9863102044747805
484.5000000000062,53.67876475409989,0.0063969573168444205,-1.9871780354115558
485.60000000000616,53.78788135076531,0.010947847483297135,-1.987630172176806
486.7000000000062,53.89606815107206,0.02154115610106888,-1.9862637370816738
487.8000000000062,54.00379044161008,0.03005016724819587,-1.9872975454525608
488.90000000000623,54.111835766257975,0.03615448994160686,-1.9872998750025397
490.00000000000625,54.2211093777925,0.037703639354211504,-1.9872980469159547
491.1000000000063,54.32900066172418,0.040738422322933565,-1.9892798846180497
492.2000000000063,54.43768818058966,0.03801939788218356,-1.9892801055092382
493.3000000000063,54.54730923054827,0.03399184988545212,-1.9892696890762316
494.40000000000634,54.65636716292739,0.02534066741365848,-1.987959872374851
495.5000000000063,54.765057585562516,0.013050281799146912,-1.989276501447256
496.60000000000633,54.87438319936628,0.00957104328037639,-1.9892700461204724
497.70000000000636,54.982759073055796,0.002398876695424823,-1.9905889745109282
498.8000000000064,55.09317168284487,-0.005458513303667534,-1.9903431261031646
499.9000000000064,55.20112514115606,-0.00692053381139357,-1.9882799070786359
501.0000000000064,55.31129729849062,-0.01426771947957406,-1.989604366699653
502.10000000000645,55.42030644543759,-0.02030207486945501,-1.9895999247309208
503.2000000000064,55.53019487636355,-0.020159204589839552,-1.9889501844330224
504.30000000000643,55.638349847295714,-0.02364003893430111,-1.989860372437751
505.40000000000646,55.74740186868176,-0.0324043295507036,-1.9915044711161758
506.5000000000065,55.85522760288049,-0.035032613729087836,-1.9915801944693508
507.6000000000065,55.96617254185979,-0.04122927115786046,-1.9912418312398492
508.7000000000065,56.07567727083829,-0.04309452374404121,-1.9927567041058571
509.80000000000655,56.185441282248846,-0.048997745545321214,-1.9928900570973545
510.90000000000657,56.29115879021843,-0.056839337398859824,-1.9928806384784679
512.0000000000066,56.40334206902449,-0.05861916250502275,-1.9942100191404073
513.1000000000065,56.51306827189848,-0.06155000859542592,-1.992900880999024
514.2000000000066,56.619627808797375,-0.07051172635259129,-1.9929000820064826
515.3000000000065,56.73185225844455,-0.07036733544272677,-1.9930237833929099
516.4000000000067,56.84087062794594,-0.06941058420140167,-1.9932205130771472
517.5000000000066,56.950097416876915,-0.06977821879756496,-1.9941674648923502
518.6000000000067,57.05880138043486,-0.06691103686622579,-1.9945401792765816
519.7000000000066,57.16788396810211,-0.06018034008621165,-1.9932257751038016
520.8000000000067,57.27667377265653,-0.06066324264518774,-1.9938975478123442
521.9000000000067,57.3860849279078,-0.057863917781312724,-1.995530207056426
523.0000000000067,57.49513093853839,-0.054002969412257906,-1.9958342848296406
524.1000000000067,57.60477306315374,-0.05329696553707475,-1.9945398109009858
525.2000000000068,57.71419874919586,-0.04794261357761198,-1.994539808792723
526.3000000000068,57.82368273615408,-0.04593359385663154,-1.9959112743080718
527.4000000000068,57.93186840371843,-0.04472018671292677,-1.9971695799596367
528.5000000000068,58.04269350031574,-0.04487868463594813,-1.995871976359881
529.6000000000068,58.150565556958824,-0.04061335742778649,-1.994869809036574
530.7000000000069,58.26148073389849,-0.04050326021573525,-1.994869571748982
531.8000000000068,58.3705624948634,-0.042518794566924534,-1.9968704023935795
532.9000000000069,58.48054906715811,-0.03774169559755258,-1.9971628869522493
534.0000000000068,58.58892233611649,-0.03634569876953475,-1.995859834929803
535.100000000007,58.69844939501645,-0.03435776299252247,-1.9958598349999537
536.2000000000069,58.808414198093196,-0.037610080486782604,-1.9958599125964178
537.300000000007,58.91828534067452,-0.037116832854069304,-1.997172968174095
538.4000000000069,59.02726767040482,-0.03685460087710113,-1.9958664528832626
539.5000000000069,59.13789171944828,-0.03533644577612971,-1.9967420735515227
540.600000000007,59.24465748608837,-0.033923681537822103,-1.997167864568071
541.700000000007,59.35620763114511,-0.03807807050534984,-1.9974988306499324
542.800000000007,59.466620524517495,-0.041007774612191406,-1.9984899728058523
543.900000000007,59.57631003710991,-0.0381894075090502,-1.9977670772044935
545.000000000007,59.68802102274385,-0.040127245973578085,-1.9988199962841655
546.1000000000071,59.796028703976916,-0.03852217139898573,-1.9988231166763626
547.2000000000071,59.90565737891727,-0.03801699758655308,-1.9984898933356365
548.300000000007,60.015541953501646,-0.039455345847597245,-1.9978396640097362
549.4000000000071,60.12490912911552,-0.040839192833000526,-1.9971039943186735
550.500000000007,60.2346729921188,-0.040710330048126964,-1.9984899933875384
551.6000000000072,60.344210646726346,-0.03980030256137579,-1.9985036323948409
552.7000000000071,60.45411062675065,-0.040936852614390284,-1.9998101040633043
553.8000000000072,60.562969701079965,-0.04105662367753615,-1.9998101100000176
554.9000000000071,60.67222742418987,-0.03841689572388074,-1.99981007425517
556.0000000000072,60.78295595455659,-0.03884972101471085,-2.000787963940213
557.1000000000072,60.89284993720017,-0.04029256068512732,-2.0007149643690854
558.2000000000072,61.00218319318478,-0.038079136023167814,-1.9994801105678786
559.3000000000072,61.1114956300652,-0.035557276332154886,-1.9990833974034752
560.4000000000073,61.22092436409791,-0.04060153017308776,-1.9988199118492802
561.5000000000073,61.33095719839768,-0.042987612394474906,-1.9990176098006764
562.6000000000073,61.44019125615598,-0.041093304858062285,-2.0001399236387756
563.7000000000073,61.55029814031068,-0.04130084060995853,-2.0001398186444233
564.8000000000073,61.660092872940176,-0.04060876187400464,-1.9988199345487407
565.9000000000074,61.77077711986103,-0.039810177934522684,-1.9995670709760978
567.0000000000074,61.87920525204987,-0.040011067547950696,-2.000392909544721
568.1000000000074,61.99009782264135,-0.0383491965225663,-2.0007900240011525
569.2000000000073,62.09952113739227,-0.04152414880402544,-2.0007906430784126
570.3000000000073,62.20946064171595,-0.039246877313748985,-2.0021100493374275
571.4000000000074,62.31966447582388,-0.037434252103439425,-2.0021100489986727
572.5000000000074,62.42903827332513,-0.036253943151695056,-2.0021168408438994
573.6000000000074,62.54010364098113,-0.03904641227761052,-2.0021097404828883
574.7000000000074,62.64896464266019,-0.038405584029883366,-2.002439411388405
575.8000000000075,62.759592059096704,-0.039090733599785654,-2.0024399806610784
576.9000000000075,62.86990391015634,-0.03846545479020835,-2.0024403018998127
578.0000000000075,62.97940541042772,-0.03471716039468142,-2.001450070033156
579.1000000000075,63.08885903947948,-0.03569042696139335,-2.00144535193239
580.2000000000075,63.19826121668183,-0.03230793587337355,-2.0014463076543603
581.3000000000076,63.308260628399886,-0.03329769252698078,-2.0040802321076665
582.4000000000076,63.41852367292742,-0.029894037485783453,-2.0040901054475464
583.5000000000076,63.52908165258219,-0.027466340839282344,-2.003125115501497
584.6000000000076,63.63790162062734,-0.02832889336010025,-2.0027615727756802
585.7000000000077,63.7484449312983,-0.030068229307643524,-2.004251758917841
586.8000000000077,63.858574486536625,-0.02693564891975364,-2.0030918630909733
587.9000000000076,63.968229647700745,-0.02545077877227775,-2.005509834932086
589.0000000000076,64.07831639392813,-0.022931389367784938,-2.005517945551064
590.1000000000076,64.18970381959844,-0.024500106497610696,-2.0070937153616066
591.2000000000077,64.29912556376571,-0.02348575746517234,-2.0057297565668706
592.3000000000077,64.40861867976713,-0.023988747769531527,-2.0060596799940527
593.4000000000077,64.51872305336587,-0.019265964840385008,-2.0048665707881677
594.5000000000077,64.62915877379353,-0.01482144404501895,-2.007039354683366
595.6000000000078,64.73896984903351,-0.016303488116771847,-2.0070199381226237
596.7000000000078,64.8499990103865,-0.012679018335655545,-2.0086899839793584
597.8000000000078,64.96000107963583,-0.013984373479781986,-2.0100104924080577
598.9000000000078,65.0697036680307,-0.010037116165007687,-2.0100057026166867
600.0000000000078,65.18065281709701,-0.010635513645122163,-2.0086905289795545
601.1000000000079,65.29162277983555,-0.008698449169402434,-2.0114644497352927
602.2000000000079,65.40163156863582,-0.00548143484320418,-2.0110001897827
603.3000000000079,65.51258468507642,-0.003268806518701428,-2.009679697923442
604.4000000000078,65.62362104804201,-0.00029069516996171885,-2.0123098954423524
605.5000000000078,65.73470601090658,0.002089807042231273,-2.0125322153801948
606.6000000000079,65.84445587227815,0.003704800922162965,-2.012988343926347
607.7000000000079,65.9554585261993,0.007344405362263107,-2.014317244173786
608.8000000000079,66.06577563537766,0.012327001254890169,-2.0169920812257542
609.9000000000079,66.17570341520333,0.016029921069359965,-2.0193041114473314
611.000000000008,66.28691101905919,0.023627337949642557,-2.019833754866833
612.100000000008,66.39726554512012,0.02705585249231568,-2.0206378482277243
613.200000000008,66.50756965803387,0.029416375807152395,-2.0231735032363187
614.300000000008,66.61839182117737,0.035170666185971866,-2.0233288007814094
615.400000000008,66.72897232158309,0.0422958998089118,-2.024414109680336
616.5000000000081,66.83918875836719,0.04699772542320635,-2.0258110140637537
617.6000000000081,66.95000200799656,0.05578987389873302,-2.0271145887237645
618.7000000000081,67.06027505985163,0.05423809931674639,-2.0284282975296515
619.8000000000081,67.1710257996826,0.062319765918003034,-2.0297501804222664
620.9000000000082,67.27861726338526,0.0668412619917198,-2.0297524288393407
622.0000000000082,67.39278916948003,0.07656976614271205,-2.032487623815242
623.1000000000081,67.50338254127519,0.08256680242771619,-2.033799516137632
624.2000000000081,67.61292518748736,0.08894198834205214,-2.0338112728801043
625.3000000000081,67.7251292559349,0.09908516992092142,-2.034544238109531
626.4000000000082,67.8352937154021,0.10302931102760593,-2.0368620599303435
627.5000000000082,67.94696226175319,0.10821505206482263,-2.0397388287993707
628.6000000000082,68.05800086522979,0.11482275122222418,-2.0398392429600922
629.7000000000082,68.16799677404674,0.12295013556667844,-2.0437128990668505
630.8000000000083,68.27949314211713,0.13185751925723777,-2.0462856684023847
631.9000000000083,68.38981001383166,0.13769962073594555,-2.0489535941659236
633.0000000000083,68.50068206310301,0.14530622507085567,-2.050361690694421
634.1000000000083,68.61175896996139,0.1532414155026256,-2.0518014336010464
635.2000000000083,68.72237213322276,0.16475641275386121,-2.054820710445685
636.3000000000084,68.8335085920159,0.16960566994000525,-2.056787068565569
637.4000000000084,68.94317045219428,0.1809896745695836,-2.0597363040734296
638.5000000000084,69.05434606070688,0.18954945734083628,-2.062918406858536
639.6000000000083,69.16470610061316,0.201945492688961,-2.064245431503201
640.7000000000083,69.27510396213519,0.210828931274182,-2.0682274454743457
641.8000000000084,69.3858728256586,0.21980750028711715,-2.072174454689303
642.9000000000084,69.4971245179961,0.23152316472763612,-2.07564133430828
644.0000000000084,69.60849649087086,0.24360595546397046,-2.0775775591068975
645.1000000000084,69.71948319974088,0.25539690397348735,-2.0814781711954016
646.2000000000085,69.83020687179211,0.26792731138884607,-2.084267372055604
647.3000000000085,69.94083936867153,0.2781105545646816,-2.0869852658816357
648.4000000000085,70.05233580422359,0.29154518694130305,-2.0910548948743393
649.5000000000085,70.16315963942083,0.30488226270019814,-2.0937503832560567
650.6000000000085,70.27505236319651,0.3193804697037017,-2.098551831712955
651.7000000000086,70.38537781332958,0.3383765131078187,-2.103222071065233
652.8000000000086,70.49689177262346,0.35739142287591785,-2.106670681990548
653.9000000000086,70.60711914950838,0.37288777670806317,-2.1108454000532486
655.0000000000086,70.71805819995141,0.3919567391324996,-2.1142818178702605
656.1000000000087,70.82841164882178,0.41453740861014854,-2.1200523069752757
657.2000000000087,70.93978421763254,0.4394743660890541,-2.1237298277546373
658.3000000000086,71.04935345537777,0.46364705206694645,-2.127710965337225
659.4000000000086,71.16132663959665,0.4931031813513629,-2.130757836836814
660.5000000000086,71.2726037243868,0.5234955429956594,-2.1369922083761392
661.6000000000087,71.38343059968486,0.5483328057859136,-2.1432937581440505
662.7000000000087,71.49460553757108,0.5831577087182453,-2.149042821645148
663.8000000000087,71.60528472872201,0.6128845080732399,-2.155101206786755
664.9000000000087,71.71638196927692,0.6428108700134814,-2.159483032468466
666.0000000000088,71.82690573538217,0.6756711326766229,-2.165892149785238
667.1000000000088,71.9380774471203,0.7094528919534879,-2.172743448609917
668.2000000000088,72.04932883542874,0.7470068320130021,-2.1790072236382056
669.3000000000088,72.15918271811802,0.7840325032680602,-2.1856869945059003
670.4000000000088,72.27010283446307,0.8194941084695946,-2.1942869496236073
671.5000000000089,72.38038321951352,0.8556820305101258,-2.201426980728204
672.6000000000089,72.49102969689015,0.8956381858626721,-2.2081410673543447
673.7000000000089,72.60120047517104,0.9367192772667181,-2.2162102218418713
674.8000000000088,72.712522007185,0.9768574134653869,-2.2219797006446456
675.9000000000088,72.82285065155428,1.0178565799094967,-2.2303404528104878
677.0000000000089,72.93385012469864,1.059697578624047,-2.23729556317667
678.1000000000089,73.04509596435318,1.1053458919419603,-2.2453286717400647
679.2000000000089,73.15508449110956,1.144938568661775,-2.253942658735512
680.3000000000089,73.26637663465404,1.1878869453823,-2.2642231667273016
681.400000000009,73.37851258376152,1.2342898289259534,-2.273951388296384
682.500000000009,73.48828564191476,1.2807416014296091,-2.2819723930265976
683.600000000009,73.59945435690574,1.3242796284979441,-2.292934798385146
684.700000000009,73.7109680415097,1.3704658996350532,-2.3026369387167724
685.800000000009,73.82101283712781,1.415739418095783,-2.313162964711597
686.9000000000091,73.9331637709783,1.462814139990697,-2.323723734508073
688.0000000000091,74.0448097975239,1.5134419023891839,-2.3342073856382672
689.1000000000091,74.15581780696873,1.5588387389759488,-2.347134050202219
690.2000000000091,74.26795228064638,1.6067425655029361,-2.3597481412186254
691.3000000000092,74.37895359129443,1.6498460886707829,-2.371836501440934
692.4000000000092,74.48916546966873,1.6994805410733045,-2.383191653181108
693.5000000000091,74.60136787669309,1.7427657357564372,-2.396262811532246
694.6000000000091,74.71208492141272,1.788045646870966,-2.4077795308305157
695.7000000000091,74.82377140510997,1.831760505682087,-2.422576337211969
696.8000000000092,74.93196543137704,1.8710985484036982,-2.435929234716622
697.9000000000092,75.04703236776011,1.9146247133721732,-2.451152125913251
699.0000000000092,75.15779175649728,1.952218075554157,-2.4659401626674082
700.1000000000092,75.2694946238925,1.9917034789422294,-2.4811348293789015
701.2000000000093,75.380900084276,2.0244105141715263,-2.4978502633372273
702.3000000000093,75.49232983193083,2.0604063667273484,-2.513031766364583
703.4000000000093,75.60369180158035,2.0955860225851195,-2.52909934371469
704.5000000000093,75.71744589106913,2.1255593400754176,-2.5444773670029552
705.6000000000093,75.8281061296936,2.145402727282251,-2.561434861684526
706.7000000000094,75.9398967862511,2.1724090090982724,-2.576957556570152
707.8000000000094,76.05191036653358,2.1951266562197285,-2.5927274959941666
708.9000000000094,76.16210199838233,2.214781251946268,-2.6091353293857256
710.0000000000093,76.27417708787183,2.229681995164575,-2.6273091002957263
711.1000000000093,76.38658124478222,2.241570399236248,-2.6428416880698764
712.2000000000094,76.49812567477508,2.2432734478353824,-2.65936822319064
713.3000000000094,76.60852702242133,2.2471565542249485,-2.675962403666483
714.4000000000094,76.72115657210317,2.2315511491837805,-2.694142606859831
715.5000000000094,76.83165107612007,2.202893862227139,-2.7091759472412558
716.6000000000095,76.94268185599437,2.162022077721005,-2.7265751787755734
717.7000000000095,77.05333880003963,2.092020196187718,-2.742352051252362
718.8000000000095,77.16424685608469,1.9856176680666768,-2.758065788309511
719.9000000000095,77.27524330087576,1.823229493036531,-2.7718604432297633
721.0000000000095,77.38517988321404,1.564493736936306,-2.7880152593123233
722.1000000000096,77.49587017365177,1.1305005676281783,-2.798399222878206
723.2000000000096,77.6058335745688,0.40414717491000296,-2.8050207109720082
724.3000000000096,77.71618693521133,-0.11225133649979258,-2.807572693555709
725.4000000000096,77.82690676262195,-0.26883550782852983,-2.8095105633343778
726.5000000000097,77.93770591412644,-0.3170552689613835,-2.8107312341939514
727.6000000000097,78.04951369097863,-0.3310352977528128,-2.8108198680116177
728.7000000000096,78.15904931045023,-0.34171441206269515,-2.8108002013773294
729.8000000000096,78.27131090150039,-0.34591165005362945,-2.812172572454857
730.9000000000096,78.38011068904012,-0.34558723143816006,-2.8108298832183523
732.0000000000097,78.49358796434701,-0.3502329285641561,-2.8128337788599236
733.1000000000097,78.60532667564625,-0.348078003526487,-2.814759394332964
734.2000000000097,78.71546656625127,-0.348943145302987,-2.817510359093517
735.3000000000097,78.82721338191257,-0.3497122846184255,-2.8175103635950465
736.4000000000098,78.93881668607362,-0.3546001991396417,-2.817474371657401
737.5000000000098,79.05031242652784,-0.35563560519040927,-2.8148938055930763
738.6000000000098,79.16164734700776,-0.35447805271470334,-2.8145899269871535
739.7000000000098,79.27377915986587,-0.35670773971753666,-2.8146575142908516
740.8000000000098,79.38522003309566,-0.359250922578757,-2.814990222706
741.9000000000099,79.49727090617473,-0.3521460414504054,-2.8149919959072176
743.0000000000099,79.60802357743692,-0.3561491110530308,-2.8156810969585058
744.1000000000099,79.71947144636559,-0.35513197622148684,-2.814990136326482
745.2000000000098,79.83230097237866,-0.35502389248258037,-2.815085338883889
746.0000000000099,79.91239723292303,-0.35752184107285134,-2.816304777574842