File: 01_Data/Laminate_Flooring/STA/N2/10K_min/Laminate_Flooring_STA_N2_10KData_221205_R1.csv
##Temp./Â°C,Time/min,DSC/(mW/mg),Mass loss/mg
51.0,10.328599707737848,0.003107233857925884,-0.0007364919216392707
52.100000000000016,11.010510849796109,0.04323553222382226,0.00147752644996757
53.20000000000003,11.289224144221716,0.06276097320173069,0.0008163236958731446
54.30000000000005,11.5077835018248,0.07917488526710592,0.001028464909770932
55.40000000000006,11.69917243440108,0.09017408120143555,0.0017251468762724542
56.50000000000008,11.876898608253022,0.10258527155546981,-0.00019937984441309453
57.600000000000094,12.041277157629853,0.10922648636506072,0.002568077306983163
58.70000000000011,12.199023762299666,0.11558074136048857,0.0013756246488219048
59.800000000000125,12.348377804346883,0.12373594665471344,0.0008865675100508952
60.90000000000014,12.497827128745703,0.1264400301969928,0.0011201660016304515
62.000000000000156,12.640960895900388,0.12866886280750078,0.00161344742591929
63.10000000000017,12.781727801806156,0.13478767459955598,0.0008254539615943912
64.20000000000019,12.917482335627739,0.13788321313844953,0.0005876293253841425
65.30000000000021,13.058738856797621,0.13998789094296593,-0.0008705558392874124
66.40000000000022,13.196832901397197,0.14163253080028726,0.0003944228861225696
67.50000000000023,13.329881750737098,0.13880435227415466,0.0006481664911390794
68.60000000000025,13.460000000000033,0.13960604179957636,0.000341931042400212
69.70000000000027,13.584417693319674,0.1427666841461095,0.0011077660711569237
70.80000000000028,13.712465960831686,0.14424133972613062,0.0003274257848051576
71.90000000000029,13.842331108580877,0.14802512413096203,0.0016440889368638523
73.00000000000031,13.966597740656077,0.15109955847494483,-0.0004991194709056401
74.10000000000034,14.089781052597647,0.15551167850478875,0.00022080906491073193
75.20000000000034,14.21232314086681,0.1578231133344632,0.0013147614803781238
76.30000000000035,14.335888079701965,0.1594096260965001,0.0006016373459409863
77.40000000000038,14.45506257961576,0.16331108558021135,-0.0010902051435062177
78.5000000000004,14.57677366441383,0.16690266925639174,-0.0017766575751121394
79.6000000000004,14.694665817741535,0.16849035246944988,-0.001099549090010754
80.70000000000041,14.81364296779423,0.17225773165650038,-0.0021223213353342985
81.80000000000044,14.929772148607618,0.17470532677733597,-0.0010862070320740713
82.90000000000046,15.045102941838605,0.17705018654799498,-0.0013451634238696997
84.00000000000047,15.16417629566504,0.1791051784088067,0.00022560568776164303
85.10000000000048,15.279731845679098,0.1806656431096172,-3.31213235060801e-05
86.2000000000005,15.393665067598358,0.18036408469131082,0.00021339810525766723
87.30000000000052,15.508479100078665,0.18012384340783139,-0.001091072277738192
88.40000000000053,15.62262290263002,0.184365441648362,-0.0010878170255059771
89.50000000000054,15.734543383619496,0.18405424042976715,-0.001096379978435813
90.60000000000056,15.84820783613602,0.1866197116606918,-0.0010993456576713356
91.70000000000059,15.960487579254456,0.18452959202222674,-0.001089958246910605
92.8000000000006,16.074392287432328,0.1890112340199639,-0.0008774735797549837
93.9000000000006,16.18443321707183,0.19020192296513172,0.000287777771307951
95.00000000000063,16.29608176637006,0.19253327109990725,0.0011191383833466517
96.10000000000065,16.405082709919235,0.19332364177495753,-0.001005465739565281
97.20000000000066,16.516131082827687,0.19231797994278943,-0.0010629998193003587
98.30000000000067,16.624557426822772,0.19536557779056607,-0.0011004375142515954
99.40000000000069,16.735395094521255,0.1983181394374165,-0.0006130755748072758
100.50000000000071,16.84504084331671,0.19965091659164247,-0.0010869840862595126
101.60000000000072,16.95348410704792,0.19891907887709115,-0.0010963279176348095
102.70000000000073,17.06224053475026,0.20128566549967042,-0.0002615496442865961
103.80000000000075,17.17021332039166,0.2013780590555303,-0.0007522713043917051
104.90000000000077,17.280000000000076,0.2033172550715716,-0.0010897399534766095
106.00000000000078,17.387738578033805,0.2038433727920601,-0.0009390557424806545
107.10000000000079,17.497203655083574,0.2054311476288485,-0.0010902380569577375
108.20000000000081,17.603814595441463,0.2067491511655335,-0.002443360544766904
109.30000000000084,17.712080614484684,0.2068184018968119,-0.0012938911017270627
110.40000000000084,17.817375477190375,0.20673527938065106,0.00021903544204082692
111.50000000000085,17.9274190461537,0.20853505138145267,0.0002287683429891274
112.60000000000088,18.035248226812406,0.2079747665142747,-0.0008818242545398647
113.7000000000009,18.14290539728151,0.20715733079436638,-0.00045914850947159636
114.8000000000009,18.252731160431836,0.21028634148507175,-0.00105564976349104
115.90000000000092,18.35949517541091,0.20799836858010523,-0.0011128503849429094
117.00000000000094,18.467614658649946,0.21074176614188656,-0.000999787299942767
118.10000000000096,18.57460356806276,0.21138118673732542,-0.001175049924317051
119.20000000000097,18.681968762351858,0.21001613805446318,-0.0010898539980042088
120.30000000000098,18.78805589626012,0.21141654989001424,-0.0010988070801918326
121.400000000001,18.89659110462063,0.21174459012942104,-0.0011592332381011872
122.50000000000102,19.004349802084082,0.21458049932950773,-0.0011002310696852646
123.60000000000103,19.110704736390694,0.21333243268597246,-0.00031593301400612006
124.70000000000104,19.214525266243673,0.2146098194447178,9.692967539720598e-07
125.80000000000106,19.32331999487655,0.2161731995687437,-0.0014137297685934413
126.90000000000109,19.429922919676237,0.21578921575004473,-0.002087687203435884
128.00000000000108,19.536716078676598,0.21653287991815062,-0.0010910819895659785
129.1000000000011,19.64264456931038,0.21589883046147962,-0.001171959109635523
130.20000000000113,19.748799646175428,0.21735005083553016,-0.0024200019173461484
131.30000000000115,19.85585948614125,0.21848011634327957,-0.002408939141279376
132.40000000000117,19.961327283079342,0.22039362376031146,-0.001089904154055077
133.50000000000117,20.066295565492176,0.22069029428624953,-0.0024098497975666433
134.6000000000012,20.173884356756027,0.22079539486800137,-0.002416943749615541
135.7000000000012,20.278543250863432,0.2204088347064116,-0.002396716894726758
136.8000000000012,20.385310031464346,0.22143683745617626,-0.0024094207870275497
137.90000000000123,20.49115401699477,0.2222556239094169,-0.0024100172994385716
139.00000000000125,20.59690182305031,0.2228799634489136,-0.0037290306705175524
140.10000000000127,20.702739306874772,0.22245733557711056,-0.003730026074705073
141.2000000000013,20.807032518876163,0.22025536727221895,-0.003730234069267091
142.3000000000013,20.913342161019244,0.22398381567239523,-0.003730141516235186
143.4000000000013,21.017702511269885,0.2235930238807855,-0.0037301199999140167
144.50000000000134,21.123764359605484,0.22423395701796778,-0.003730146889783903
145.60000000000133,21.226230936367642,0.22417602752356425,-0.003720365671985526
146.70000000000135,21.33362666041608,0.2254447869377948,-0.0024100224107037604
147.80000000000138,21.43621522269847,0.22621656341333463,-0.0037308527566057847
148.9000000000014,21.544302219278755,0.22730728654453258,-0.0037300539530527033
150.00000000000142,21.648895901914585,0.22861599551082523,-0.002367245197348211
151.10000000000142,21.75189404904256,0.22981891873537996,-0.0037231742362813236
152.20000000000144,21.85793820557778,0.22941800667108636,-0.0024021643544127613
153.30000000000146,21.962174242382027,0.22955269513783405,-0.002876248718537866
154.40000000000146,22.06762740084245,0.23094508535587677,-0.0037205975302150307
155.50000000000148,22.172046631163777,0.23286189543210445,-0.004606838114134426
156.6000000000015,22.276718013285375,0.23138843979855084,-0.0050460659441853295
157.70000000000152,22.381660483722765,0.23335245767842328,-0.005049051029646812
158.80000000000155,22.4871518350817,0.23237353204888134,-0.005055991102255852
159.90000000000154,22.59090491859211,0.23362824616334787,-0.005050275157739037
161.00000000000156,22.696532537758284,0.2335720645116216,-0.005049860051344446
162.1000000000016,22.800507523217934,0.23512297132556104,-0.006442780584229091
163.20000000000158,22.90455500825782,0.23720222966139948,-0.0050349045285136285
164.3000000000016,23.006515184077745,0.23522116180845498,-0.006027473850241272
165.40000000000163,23.11334437942275,0.23722722333537916,-0.006359954455436245
166.50000000000165,23.217916010445023,0.23740322192891994,-0.006522948721577215
167.60000000000167,23.322898319376606,0.23874411777166737,-0.005649466541076897
168.70000000000167,23.42823984905395,0.23996009666145457,-0.0076887637235323325
169.8000000000017,23.532509748428062,0.2392633640352747,-0.007672616534138754
170.9000000000017,23.635545552046644,0.2403268331610876,-0.0077061819709989265
172.0000000000017,23.741586698850128,0.2396461787484626,-0.00635997056374471
173.10000000000173,23.84497404007582,0.24014030458540025,-0.0050499809512665195
174.20000000000175,23.950354593761848,0.2405403234421125,-0.006360851620236474
175.30000000000177,24.055231276757493,0.23986241940173225,-0.009109979925271183
176.4000000000018,24.159709056524292,0.24007237426883798,-0.009106122713578912
177.5000000000018,24.26374683643272,0.2395615791596536,-0.009118501273135848
178.6000000000018,24.368344230681583,0.23953382090229125,-0.009113620207944706
179.70000000000184,24.472706249470114,0.24080806106767338,-0.006700472142145308
180.80000000000183,24.576133098581888,0.24245830979634997,-0.007800251609741515
181.90000000000185,24.68194916194806,0.2430760624356404,-0.009175687305621238
183.00000000000188,24.78558969217781,0.24230653882998798,-0.0077913905027600094
184.1000000000019,24.891164980368682,0.24373754785949253,-0.009195259581892934
185.20000000000192,24.995461949838017,0.24299635057384894,-0.009105693537296844
186.30000000000192,25.098830746535185,0.24060836379136252,-0.01043039430691639
187.40000000000194,25.20474379270526,0.24354871837068237,-0.009107274197099002
188.50000000000196,25.30862027852657,0.24333403809316,-0.010428742796427137
189.60000000000196,25.413452318599408,0.2445897868362349,-0.009110111533687792
190.70000000000198,25.517621230360454,0.24680069537432192,-0.009110102103297102
191.800000000002,25.620776074851698,0.24823155749279946,-0.010424531377744906
192.90000000000202,25.726365502585168,0.24652728204725882,-0.010420100237708674
194.00000000000205,25.82904826997349,0.24712332041265905,-0.010416957176708763
195.10000000000204,25.93409871417697,0.24767057370203627,-0.010420186859499303
196.20000000000206,26.037823303127826,0.24781205236949566,-0.011638898417909438
197.3000000000021,26.142809830555706,0.24935031680210784,-0.01174019399809545
198.40000000000208,26.247440341615377,0.24890279436853968,-0.011740197134685104
199.5000000000021,26.35028174209213,0.24943431831782759,-0.01305998986434087
200.60000000000213,26.45542053992533,0.2499806097571846,-0.011739992588335468
201.70000000000215,26.558223194906056,0.25225703785985276,-0.013049821884149715
202.80000000000217,26.66329118419536,0.25147157377719187,-0.013049882003238977
203.90000000000217,26.76624443078595,0.25285113868386244,-0.01304795279223292
205.0000000000022,26.869529083126285,0.25385253683597064,-0.012729444926255162
206.1000000000022,26.97600722845753,0.25583335848322264,-0.012747945779270964
207.2000000000022,27.08063839386581,0.255956966710834,-0.013060107706597712
208.30000000000223,27.182227743669646,0.2552289307100488,-0.014376389911691767
209.40000000000225,27.287943833140844,0.256209584884149,-0.014667026553359719
210.50000000000227,27.392601864251372,0.25577602781516384,-0.015703787374550693
211.6000000000023,27.49664202421253,0.255956702950762,-0.01435548997673397
212.7000000000023,27.60085323071027,0.2560962329291333,-0.014379985509785698
213.8000000000023,27.705835287590965,0.25606784489104306,-0.014702705514337389
214.90000000000234,27.809703385937876,0.2565338917760196,-0.01733993726807359
216.00000000000233,27.91417198178525,0.25747816987397465,-0.017339767590354604
217.10000000000235,28.019490382159827,0.2567146635216674,-0.018661889122364883
218.20000000000238,28.1235156480778,0.2544972782617122,-0.018737592496139044
219.3000000000024,28.227107454858146,0.2559519010597662,-0.019953656580613988
220.40000000000242,28.33244992790856,0.2567535039425498,-0.019910308310246982
221.50000000000242,28.43644388024603,0.2569626010468441,-0.020970230280453528
222.60000000000244,28.541677070408912,0.2555660719919669,-0.020969798000892048
223.70000000000246,28.645155806880314,0.25965757187230565,-0.020969797998629858
224.80000000000246,28.749795974057147,0.25952140169909743,-0.02097644404741139
225.90000000000248,28.854400795960057,0.26031719678744514,-0.022608770106487874
227.0000000000025,28.95928408594211,0.2593703083169291,-0.023919939616941832
228.10000000000252,29.0635445117599,0.2593996777879668,-0.023919959998843332
229.20000000000255,29.167891455739618,0.2597369414478712,-0.023920384714791965
230.30000000000254,29.271725242123516,0.2601464231675361,-0.026588232502525067
231.40000000000256,29.376443937843792,0.2605516392168472,-0.02655986604781635
232.5000000000026,29.48193355960331,0.2625907037552144,-0.026559866626896245
233.60000000000258,29.585108467288343,0.26124862892179723,-0.02752549364648793
234.7000000000026,29.689745501469666,0.26260823521623755,-0.02788479666277688
235.80000000000263,29.79465088234204,0.2625957367286359,-0.029203437475946892
236.90000000000265,29.898603236381675,0.2613966709021386,-0.03150932602712597
238.00000000000267,30.003267868424697,0.2628225415442842,-0.03279437826410625
239.10000000000267,30.10764250529637,0.26319117156261196,-0.03281983980971148
240.2000000000027,30.21282850755245,0.26516027354468386,-0.03329007452554045
241.3000000000027,30.31698951339839,0.2651646066422474,-0.03455284148572879
242.4000000000027,30.421940247563388,0.2645712466655351,-0.037097636712336346
243.50000000000273,30.525766062044784,0.26579557708803403,-0.0384314023304686
244.60000000000275,30.6307168652254,0.2664216222860759,-0.041033705701964074
245.70000000000277,30.73515412004991,0.26636871974426735,-0.0415215675866607
246.8000000000028,30.83961901936515,0.2684584459715905,-0.04368816752154636
247.9000000000028,30.944967370113194,0.26674443626155275,-0.04500301355759895
249.0000000000028,31.049393283205642,0.2667474102576247,-0.047255344869860494
250.10000000000284,31.153676455998905,0.26757223355514614,-0.047639635371244715
251.20000000000283,31.25872482897725,0.2673654463382711,-0.04895973584191271
252.30000000000285,31.363172474645957,0.2659427857694959,-0.050279388602245234
253.40000000000288,31.46798564861784,0.2660900125273802,-0.05291635137072337
254.5000000000029,31.572005136898092,0.26413415665661,-0.055525506006834924
255.60000000000292,31.676865137717463,0.2632943824666165,-0.058180400210890326
256.7000000000029,31.782217203556574,0.2594369066759976,-0.05948979551896105
257.8000000000029,31.887489404430855,0.2577124321311772,-0.06079003729004784
258.90000000000293,31.991300872293003,0.25709675764148554,-0.06390511577908731
260.00000000000296,32.095752887302474,0.25449934006196917,-0.06708703888404388
261.100000000003,32.200533437349954,0.25456324035210043,-0.07015086516860247
262.200000000003,32.30570974073943,0.25715725363202546,-0.07152043062934776
263.300000000003,32.40940077241027,0.26232958299615017,-0.07410726343119522
264.40000000000305,32.51458479191779,0.2681322356256314,-0.07800007906444062
265.50000000000307,32.619351691362255,0.2757310696981452,-0.08209430257208661
266.6000000000031,32.72500884842478,0.2800529035537124,-0.08617255943079671
267.7000000000031,32.82889298292689,0.2848861632093356,-0.09043442692315562
268.8000000000031,32.93347969485621,0.2851093446558679,-0.09421751668599754
269.9000000000031,33.03820324113628,0.28809917305681243,-0.09955066943296931
271.0000000000031,33.14316713772436,0.28929812767267116,-0.1054961084960242
272.10000000000315,33.24805238385903,0.29060624628829756,-0.11079416927172625
273.2000000000032,33.35360888155007,0.293321490753665,-0.11808098427870828
274.30000000000314,33.458197572057976,0.2929357390626618,-0.12489358648126103
275.40000000000316,33.56152317573002,0.2929192310004871,-0.1316460489925544
276.5000000000032,33.66614884221802,0.29363456596885873,-0.14164287331979342
277.6000000000032,33.771194271725186,0.29278088865631136,-0.14906442881992055
278.70000000000323,33.87602268372654,0.293619342811366,-0.16034840598007527
279.80000000000325,33.98147590175552,0.2956551425043562,-0.17102065181212645
280.9000000000033,34.0855446186903,0.29849778031983276,-0.180901953111698
282.0000000000033,34.19112916049988,0.30325094885403475,-0.1925238737572248
283.1000000000033,34.29578051047309,0.30812781526188904,-0.20613115679107796
284.20000000000334,34.40086147203838,0.315874471175581,-0.22022489143675994
285.30000000000337,34.505530403076186,0.3261765713999225,-0.23468739151102724
286.40000000000333,34.612361947230205,0.3409619662254402,-0.2501014302638551
287.50000000000335,34.71699964511635,0.35605937793691705,-0.2665197271683213
288.6000000000034,34.82219575420795,0.37325954440883974,-0.2822827141319513
289.7000000000034,34.92742487056617,0.390966975665595,-0.3010397486630927
290.8000000000034,35.032867915347786,0.40529800332097476,-0.31821550200810655
291.9000000000034,35.138258185481355,0.42263349561923946,-0.338002408555814
293.0000000000034,35.2441912968517,0.43565041675561667,-0.35542934772056833
294.10000000000343,35.34955461144714,0.4442624977392531,-0.373608441477959
295.20000000000346,35.45507742796283,0.4549377723485266,-0.39212445247686256
296.3000000000035,35.56035602646049,0.46013318672972137,-0.4094231395852912
297.4000000000035,35.66564629769661,0.46114904176258986,-0.42615606331768285
298.5000000000035,35.77000000000029,0.46027871406574267,-0.4430798059999739
299.60000000000355,35.87736158507438,0.45975159239289515,-0.457652078471249
300.70000000000357,35.980480685071186,0.45050079555054073,-0.4747322628946016
301.8000000000036,36.08744574329465,0.4437090586996362,-0.4878182593177005
302.9000000000036,36.19294264995628,0.436586043528592,-0.5005899415954449
304.0000000000036,36.29801185286701,0.4265897369753134,-0.5148725953034754
305.1000000000036,36.40368355863008,0.4156459468853621,-0.5265026096150538
306.2000000000036,36.50901891234825,0.4054099206962005,-0.5368579853132482
307.30000000000365,36.61452931003365,0.39560697518359406,-0.547247995108453
308.4000000000037,36.72062315339381,0.38553376626308516,-0.5578722589263156
309.5000000000037,36.82653534946006,0.3736427958292193,-0.5659884549266989
310.60000000000366,36.93151123032643,0.3631012658414326,-0.5759506969849069
311.7000000000037,37.03763655944454,0.3527098553594679,-0.5842268111624178
312.8000000000037,37.1422085059864,0.3446949398226794,-0.5931699547007163
313.90000000000373,37.24725493003708,0.3332867204519479,-0.601014319752494
315.00000000000375,37.35432343398524,0.3253182603642439,-0.60688143022952
316.1000000000038,37.45860126115957,0.3168570595868719,-0.6138913957589232
317.2000000000038,37.56540300973513,0.3094442202257089,-0.6218203751967004
318.3000000000038,37.671117647826904,0.3023312390161077,-0.6260885166144257
319.40000000000384,37.777007411847244,0.2963412603129915,-0.6313988949583589
320.5000000000038,37.88229748197934,0.28940930278992155,-0.6365193186381122
321.60000000000383,37.98644184102372,0.28132509247522997,-0.6421673102407066
322.70000000000385,38.09453781301748,0.2738323947288753,-0.647881557326774
323.8000000000039,38.19782357488658,0.26767637608784245,-0.6520973830741639
324.9000000000039,38.30544911314857,0.2617649874021517,-0.6563795309844789
326.0000000000039,38.4102094583539,0.25496383658206095,-0.6608929436675179
327.10000000000394,38.515552506250806,0.2488930811642064,-0.6641834722503392
328.2000000000039,38.62255610106275,0.24374800664114038,-0.668160359189109
329.30000000000393,38.72868034141025,0.23951961001073552,-0.673508577090618
330.40000000000396,38.833334827929505,0.2314600464184675,-0.6755393910717928
331.500000000004,38.94000000000039,0.22548365483619182,-0.6802974460887885
332.600000000004,39.045262487690444,0.2193441368405754,-0.6838602684835817
333.700000000004,39.14990539878484,0.2148836696091715,-0.6864672616416465
334.80000000000405,39.25769613597387,0.21186905857843263,-0.6903421613317238
335.90000000000407,39.36321529184606,0.20682372437641672,-0.6933296456348188
337.0000000000041,39.468664818794814,0.20012523080876354,-0.6951455921366794
338.10000000000406,39.575249872835755,0.1984174355640227,-0.6972493196509708
339.2000000000041,39.681207806277634,0.19028441109759187,-0.6985223167915917
340.3000000000041,39.78725344456314,0.18659476596695135,-0.7018238839998028
341.4000000000041,39.89357310708028,0.18327568239360026,-0.7031953813561569
342.50000000000415,39.99961983134075,0.1815513834214969,-0.705793288583723
343.6000000000042,40.10536420410841,0.1772303463726176,-0.7071451335782268
344.7000000000042,40.21140053879209,0.1760708863416648,-0.7090644281818648
345.80000000000416,40.31519631808181,0.17255149769568467,-0.7103949159379397
346.9000000000042,40.42382210000765,0.17082420073925708,-0.7129233207345353
348.0000000000042,40.53019099018383,0.16920757396075237,-0.7143272289061366
349.10000000000423,40.636443848607954,0.16940697618091805,-0.7171071377706641
350.20000000000425,40.74316601407998,0.16671674867157094,-0.7156655864210184
351.3000000000043,40.84907072678332,0.16400538133626996,-0.7183005931293698
352.4000000000043,40.954785749152904,0.16208014478322863,-0.7187056136041949
353.5000000000043,41.06188062424792,0.1618652802221049,-0.7209687483457006
354.60000000000434,41.16782105311262,0.16033313454949216,-0.7222600890032522
355.7000000000043,41.273235774658005,0.16156040185099263,-0.7208992430678984
356.80000000000433,41.38080910080556,0.16082405551601386,-0.7235609487223482
357.90000000000435,41.48736592161694,0.16278517033462991,-0.7242299775308592
359.0000000000044,41.59328942296451,0.16047721706810758,-0.7261995678727167
360.1000000000044,41.6990093975803,0.15835056488039845,-0.7262098349286794
361.2000000000044,41.80633770415162,0.1592690947130163,-0.7269865802941671
362.30000000000445,41.91281908290437,0.15938070512569014,-0.7273189241965103
363.4000000000044,42.01932614804957,0.1593684668362887,-0.7285201635089829
364.50000000000443,42.12588746282241,0.16066914129874588,-0.7285102244224566
365.60000000000446,42.23286936222108,0.15941006551012482,-0.7311667508244923
366.7000000000045,42.33798357171707,0.1618885637353189,-0.7311446521071407
367.8000000000045,42.446525494371826,0.1603118862335643,-0.7334523931699737
368.9000000000045,42.55267851620834,0.16140689439228317,-0.7321390576391082
370.00000000000455,42.65916639236904,0.16426991029521631,-0.7308202158102932
371.10000000000457,42.766010949041906,0.1624724595072642,-0.732139156427698
372.2000000000046,42.87271080130287,0.16330771756670193,-0.7321400991724376
373.30000000000456,42.97990234563437,0.16354191507259208,-0.7334541345937184
374.4000000000046,43.08571516898224,0.1635974167963038,-0.7338994299044859
375.5000000000046,43.19247354575041,0.1625738626792358,-0.7337898510283578
376.6000000000046,43.298715069038245,0.16387552454110466,-0.7341040951047373
377.70000000000465,43.40594847746622,0.16517433741331222,-0.7341100120411497
378.8000000000047,43.51246595529848,0.1625242040929532,-0.7340782147280018
379.9000000000047,43.618986002811006,0.16159497687184665,-0.7354174465680421
381.00000000000466,43.72698492188397,0.162743060332724,-0.7380677838942034
382.1000000000047,43.83339563990383,0.16383834142074882,-0.7370792402821578
383.2000000000047,43.939801966005774,0.16438265717484002,-0.7370829027285479
384.30000000000473,44.04660368840585,0.1666172797253742,-0.7380700599659633
385.40000000000475,44.15393564447472,0.16317044321147411,-0.7380842336140359
386.5000000000048,44.26009262756807,0.16373237633128412,-0.7406997063142065
387.6000000000048,44.36738847285177,0.1641177033023673,-0.740697573127751
388.7000000000048,44.47444616740899,0.16416234918234018,-0.7410070342791766
389.80000000000484,44.58000107434589,0.16266729615165476,-0.7426798389837495
390.9000000000048,44.68819377851112,0.16245050474291223,-0.7426809061648991
392.00000000000483,44.79562693571277,0.1617776361746448,-0.744980188954103
393.10000000000485,44.901732068623616,0.16179879869961622,-0.7451196672022324
394.2000000000049,45.009481916135925,0.16224141495534927,-0.7463000521505325
395.3000000000049,45.11693718486063,0.15863743098593452,-0.7476101057582305
396.4000000000049,45.22449118717219,0.16093245050426674,-0.7478660575672986
397.50000000000495,45.330873219806776,0.16198884271624892,-0.7479500840036755
398.6000000000049,45.43862932776934,0.16168199975299324,-0.747945735891522
399.70000000000493,45.54552653255515,0.16119577062113555,-0.7512959334548124
400.80000000000496,45.652075356082,0.16197849818685273,-0.7512398195905661
401.900000000005,45.75970550845687,0.1619518609359566,-0.7515694145050458
403.000000000005,45.86673775286912,0.16091336535134237,-0.7515698926283427
404.100000000005,45.97466971589864,0.1596716546770618,-0.750256724401773
405.20000000000505,46.080475131000846,0.16046103721600657,-0.7528867801892569
406.30000000000507,46.19008806204438,0.1611439324643028,-0.7541984380139279
407.4000000000051,46.296530543007634,0.16088648171493314,-0.756541263494019
408.50000000000506,46.40293912091376,0.1617076555083249,-0.7565557673106653
409.6000000000051,46.51113488417481,0.16242310628320422,-0.7561566618133924
410.7000000000051,46.61760758834008,0.1595391407924298,-0.7571047397505137
411.8000000000051,46.725151055303286,0.16074172559944755,-0.7591478708284365
412.90000000000515,46.8319122796267,0.16288773826822378,-0.7604727783573053
414.0000000000052,46.93920429933359,0.16101714151925206,-0.7621006462209712
415.1000000000052,47.04677624290778,0.16243664554836257,-0.7634199657572149
416.20000000000516,47.153907674659145,0.16289346995920917,-0.7634281767013529
417.3000000000052,47.26218179607912,0.1637773660843731,-0.7647500199620176
418.4000000000052,47.3692893911857,0.16494907428599753,-0.7660703536633018
419.50000000000523,47.474231199424935,0.16372617703640147,-0.7673679701597966
420.60000000000525,47.584563992792326,0.16403145066614822,-0.7699710982290977
421.7000000000053,47.690908049842925,0.16538913598177585,-0.7727503478473077
422.8000000000053,47.79734226451278,0.16660197020433543,-0.7740605289669813
423.9000000000053,47.90563052538371,0.16596666352966566,-0.7750600527943821
425.00000000000534,48.01267391354724,0.1663712919409534,-0.776323590388841
426.1000000000053,48.12009623102332,0.16650389257248716,-0.7777415282557207
427.20000000000533,48.22793292757934,0.1667562404881781,-0.7797351111056785
428.30000000000535,48.334036153655205,0.16830770770733688,-0.7813167088326374
429.4000000000054,48.44207337887615,0.16727705917768793,-0.7848176349063865
430.5000000000054,48.5501920694787,0.1690786476846458,-0.7887755153859195
431.6000000000054,48.65719078471635,0.16936096916303084,-0.7899823794892344
432.70000000000545,48.7650589374041,0.16972406345619923,-0.7914893474249021
433.8000000000054,48.87203572780192,0.1707729971942737,-0.7941458664992731
434.90000000000543,48.979696246541884,0.169885759869226,-0.7981993192597976
436.00000000000546,49.086281941665725,0.17452870341066107,-0.7995162107855949
437.1000000000055,49.19348987091713,0.17487321070955275,-0.8018563239162315
438.2000000000055,49.30195244719189,0.17644626516187295,-0.8059200367323225
439.3000000000055,49.40857510363215,0.17696151990251202,-0.8085497825315584
440.40000000000555,49.51492508330851,0.17779185809995873,-0.8118915022440341
441.50000000000557,49.6226252795391,0.18172434319534708,-0.8157241034283365
442.6000000000056,49.731167492524406,0.18228187717022087,-0.8196293801286911
443.70000000000556,49.83791966341843,0.1834582842265579,-0.8241548855131646
444.8000000000056,49.9441100407637,0.18691844788331063,-0.8278009088053686
445.9000000000056,50.052638949097265,0.18843389817991119,-0.8320959096747056
447.0000000000056,50.16059758013153,0.1926228297958419,-0.8364933917594453
448.10000000000565,50.26853169408233,0.19626429163153242,-0.8414428297416121
449.2000000000057,50.37557387881637,0.19793352966920436,-0.8474540904341277
450.3000000000057,50.48325186945886,0.2012458256184213,-0.8507388976242947
451.40000000000566,50.590601479888484,0.2042575065459185,-0.8557972176013959
452.5000000000057,50.698360344145875,0.2105428094365288,-0.8611608340589938
453.6000000000057,50.80539090686796,0.2135448306001146,-0.8668404661978162
454.70000000000573,50.91227338340414,0.21911032220076943,-0.8727818078513039
455.80000000000575,51.020291405396655,0.2256641835962021,-0.8791599460252741
456.9000000000058,51.12670823846572,0.2294768956448407,-0.8837319196570101
458.0000000000058,51.23413017938471,0.23262035097076422,-0.8898730189881543
459.1000000000058,51.34336430639484,0.23868074641509057,-0.8969104669815406
460.20000000000584,51.44952398330075,0.23949596218509522,-0.9016042956230921
461.3000000000058,51.557550349238845,0.24573103397840923,-0.9075842051429328
462.40000000000583,51.66532410090123,0.24860037436882637,-0.9126732681760994
463.50000000000585,51.772661746708486,0.25223812315167127,-0.9193069176567041
464.6000000000059,51.87830786166854,0.2550838827793729,-0.92289700416298
465.7000000000059,51.98597775247949,0.25675190176696777,-0.9285733050488298
466.8000000000059,52.09541766652611,0.2592274044062269,-0.9333355620881898
467.90000000000595,52.20315797363611,0.2629551447184394,-0.9381488256515609
469.0000000000059,52.310932575626296,0.26183549349140756,-0.9443035561912172
470.10000000000593,52.41707297025631,0.26468149523925727,-0.9485044210718616
471.20000000000596,52.525733600744964,0.2664855186600459,-0.953136401712793
472.300000000006,52.63359490087671,0.26695065012156033,-0.9567157863212987
473.400000000006,52.74192191837714,0.2706986943722908,-0.9635362685512381
474.500000000006,52.84867660423521,0.27085560660883334,-0.9668638420187028
475.60000000000605,52.95696470663623,0.2709447366210979,-0.9724492419356885
476.70000000000607,53.06422725052252,0.27256803107548866,-0.9782439017051674
477.8000000000061,53.172202878214776,0.27285677350726145,-0.979677158610627
478.90000000000606,53.27968693689429,0.27124422992635017,-0.9837481990410768
480.0000000000061,53.38823794311759,0.27232532926346126,-0.9873059647669318
481.1000000000061,53.495155271395376,0.272208015641629,-0.9916635781078549
482.2000000000061,53.60325019142525,0.27252426855813644,-0.9953441671608658
483.30000000000615,53.71180220799114,0.2749195555919175,-0.9991460011398692
484.4000000000062,53.81963586843404,0.275230806555656,-1.0016254620895366
485.5000000000062,53.9281446882801,0.2779262089795611,-1.0045411940206947
486.60000000000616,54.03609209453897,0.2768941650572905,-1.0087164747878798
487.7000000000062,54.14322420531108,0.275580884838002,-1.0105377904851038
488.8000000000062,54.25162562903272,0.2771613852893554,-1.0145311054157204
489.90000000000623,54.36009049320656,0.27734227760229635,-1.0171288186340393
491.00000000000625,54.46837485140401,0.2779959982851672,-1.0184611078766461
492.1000000000063,54.57639319525449,0.27946961108936913,-1.0211464515563793
493.2000000000063,54.68411816048576,0.27734974943040797,-1.0225090310088092
494.3000000000063,54.792703385441285,0.2794522716961155,-1.0239421382364773
495.40000000000634,54.90072759466035,0.2814347729171038,-1.0264691414246148
496.5000000000063,55.00948255746454,0.2805814628345462,-1.0277807589631713
497.60000000000633,55.11730325497013,0.2829463326868808,-1.029754128776995
498.70000000000636,55.226316695638005,0.2834209599038252,-1.0325082149488218
499.8000000000064,55.33527078715139,0.2835024213796779,-1.03251134458411
500.9000000000064,55.4424557198094,0.2839221755885714,-1.0350230328931627
502.0000000000064,55.55071096956279,0.2847158942678905,-1.0371115089244385
503.10000000000645,55.65990463518219,0.28585885226010604,-1.0384298260954687
504.2000000000064,55.7654552075625,0.28387866672476725,-1.0370967458864402
505.30000000000643,55.876201159728566,0.2825718460295335,-1.041046088030419
506.40000000000646,55.98403172450078,0.28165244356603325,-1.039705969351714
507.5000000000065,56.09334183166622,0.28379004585579765,-1.0410158907308955
508.6000000000065,56.20207963929425,0.2860739872420895,-1.0433063410404153
509.7000000000065,56.30845209295043,0.2843930137888327,-1.045269693333632
510.80000000000655,56.41979672007189,0.2854005993820914,-1.0450163126269176
511.90000000000657,56.52779051966262,0.2874544932585983,-1.046660015507217
513.0000000000066,56.6359045197271,0.2878839459416669,-1.0479778217436548
514.1000000000065,56.74490677184116,0.2886294563023559,-1.0469881752640626
515.2000000000066,56.85314660897798,0.2877182582725857,-1.0483084756772292
516.3000000000065,56.96217591330829,0.2915508011191423,-1.0496345351604122
517.4000000000067,57.070098744661045,0.2941499223210894,-1.0502897851974873
518.5000000000066,57.17865333778538,0.29868080908863975,-1.0515998791698498
519.6000000000067,57.285553941323464,0.3041763041108838,-1.0522040609602525
520.7000000000066,57.39535848675732,0.30605717756679696,-1.0535641203747557
521.8000000000067,57.50313122571799,0.3063816478496058,-1.052920030412531
522.9000000000067,57.610998741174186,0.308947206843172,-1.0542416273794304
524.0000000000067,57.71969784775992,0.31016901756190085,-1.0568689308648533
525.1000000000067,57.82919811803049,0.3116351219148052,-1.0568688313279608
526.2000000000068,57.93648511730022,0.3134288650278843,-1.055880184148382
527.3000000000068,58.04573338436118,0.3162966092171291,-1.056222206900085
528.4000000000068,58.15322366228792,0.3202841523760527,-1.0573485009349932
529.5000000000068,58.26180850309867,0.3206919829889091,-1.058843460462457
530.6000000000068,58.37044056674669,0.32438277042162555,-1.0594359210712625
531.7000000000069,58.47792923599538,0.32742264626419143,-1.0603901058020617
532.8000000000068,58.58670866304825,0.3334010200338252,-1.0605025084618318
533.9000000000069,58.695002708907566,0.33431301798887547,-1.0617041353902503
535.0000000000068,58.80375644017892,0.3370903521976534,-1.0636312563137955
536.100000000007,58.912020415205056,0.33877522758980694,-1.0637096389629654
537.2000000000069,59.0217126251332,0.34061034250760236,-1.064999145436004
538.300000000007,59.129021741642845,0.34501416345571845,-1.0649998569834302
539.4000000000069,59.23811105043288,0.34639974211464253,-1.0663168693117382
540.5000000000069,59.34669387184889,0.3522450914485772,-1.067640750759204
541.600000000007,59.455126577258305,0.3562951916905891,-1.067626252528402
542.700000000007,59.56473715845914,0.3594684768948338,-1.0686310787996565
543.800000000007,59.67338383863993,0.36398577394811404,-1.0703239798744297
544.900000000007,59.781507906351166,0.3713249199459604,-1.0715871949359252
546.000000000007,59.89050832926324,0.3777501733070605,-1.0715932339041672
547.1000000000071,59.99867356946423,0.3871809666914483,-1.0734510078343296
548.2000000000071,60.107907562582206,0.3981836786315096,-1.07494424129916
549.300000000007,60.21620254957312,0.4098521989134435,-1.0741480731187463
550.4000000000071,60.32599529817044,0.4157449164400886,-1.0778830115738973
551.500000000007,60.434349751742516,0.4271886997145627,-1.0791809782860038
552.6000000000072,60.54386332849428,0.4403915459726543,-1.0818817885954646
553.7000000000071,60.65291827901395,0.4517697504417173,-1.0818433468382858
554.8000000000072,60.76264350672567,0.4640586622158911,-1.0858700005050879
555.9000000000071,60.870723600557724,0.4775643736353593,-1.087826861362926
557.0000000000072,60.9798998361825,0.48943636431075876,-1.0904715504672118
558.1000000000072,61.08938930398773,0.504342333021561,-1.090746767840364
559.2000000000072,61.19773118836409,0.5162587355873621,-1.0924300004835699
560.3000000000072,61.306037961705016,0.5283358331417966,-1.095088063441477
561.4000000000073,61.415986638643474,0.5427118953898301,-1.0991513564146933
562.5000000000073,61.52430264972445,0.5549471106296222,-1.103097853934182
563.6000000000073,61.63275647586711,0.5645042412065319,-1.104937345964427
564.7000000000073,61.742660867051406,0.5752280099883601,-1.1075934762867297
565.8000000000073,61.85035630806072,0.5846834130301883,-1.1122152344550003
566.9000000000074,61.95796113129128,0.5916779058069118,-1.1148370772439802
568.0000000000074,62.06847820670379,0.5956178838302497,-1.1188079346673367
569.1000000000074,62.17686404073345,0.5973087784945231,-1.1200542028821836
570.2000000000073,62.28632864187841,0.5943275122097412,-1.1256050390882848
571.3000000000073,62.395563481846466,0.5807183284837989,-1.128109184258745
572.4000000000074,62.50479771034325,0.5548251094180514,-1.1327169153708811
573.5000000000074,62.6136572956552,0.504330424118686,-1.1355677295639603
574.6000000000074,62.72369847777957,0.43163879880146566,-1.138289214488192
575.7000000000074,62.832122529740246,0.3658530521675696,-1.1382304058126071
576.8000000000075,62.94009434627101,0.3205469877621483,-1.1408597664250668
577.9000000000075,63.05058460059215,0.29814836229525143,-1.1421797979522297
579.0000000000075,63.1607898944114,0.27984877980398604,-1.1433064055846311
580.1000000000075,63.27036513082361,0.26968040830247036,-1.1448252057964483
581.2000000000075,63.37963036760617,0.2628441610288227,-1.1448308922908206
582.3000000000076,63.48981127459522,0.25731420460183063,-1.1448097985022274
583.4000000000076,63.59909249274502,0.2545399590100939,-1.1448098000008118
584.5000000000076,63.709574423943764,0.25135444058415773,-1.144808638498127
585.6000000000076,63.819136610313414,0.24918184832182444,-1.1437197971656494
586.7000000000077,63.92981070726918,0.2496212841809819,-1.1461284135258563
587.8000000000077,64.03889380687667,0.25366375263003493,-1.1464600827690297
588.9000000000076,64.1478656841326,0.2569185546732889,-1.147449668875662
590.0000000000076,64.258153559276,0.25945567930578456,-1.1474495001458105
591.1000000000076,64.36765532964273,0.26980629828357816,-1.1474634849208813
592.2000000000077,64.47812388028112,0.2730485361237014,-1.148759760866907
593.3000000000077,64.58751698697216,0.2758139412379708,-1.1487387127824946
594.4000000000077,64.69789551384724,0.28258331639103695,-1.1500714842812516
595.5000000000077,64.80768811783929,0.2901982147234087,-1.1507398978124277
596.6000000000078,64.91746565679118,0.2966993248716561,-1.1500816752554144
597.7000000000078,65.0273800325978,0.3017458322897283,-1.1526119482667379
598.8000000000078,65.13622617564627,0.31021657131754476,-1.1540194884071466
599.9000000000078,65.24677198036649,0.31705129897744044,-1.1554054324326466
601.0000000000078,65.35735956660785,0.3262155690730552,-1.1566695390792936
602.1000000000079,65.46633129950641,0.3339804657529731,-1.1560204357905226
603.2000000000079,65.57786863524026,0.34240524979731635,-1.1573299199059002
604.3000000000079,65.68775107564477,0.3477492537130169,-1.1591216839660308
605.4000000000078,65.7969856825448,0.3550355311334648,-1.1615225204709767
606.5000000000078,65.90692437001121,0.36118410868254147,-1.1616101886049042
607.6000000000079,66.01439657897883,0.36405557509461217,-1.1651687015376
608.7000000000079,66.12632285312068,0.37436198548028005,-1.1655434682157244
609.8000000000079,66.23609571947577,0.38021987450381634,-1.1668153127408356
610.9000000000079,66.34607802190747,0.38502473778055296,-1.1681944332942469
612.000000000008,66.455342820782,0.39158222694904427,-1.1722912895437183
613.100000000008,66.56481741393881,0.39721048891370847,-1.1710641849609393
614.200000000008,66.67446671729535,0.405976288617961,-1.1721219036547526
615.300000000008,66.78346828051572,0.4124120370951221,-1.173274486000437
616.400000000008,66.89323812212449,0.4188453834069621,-1.1757942688834166
617.5000000000081,67.00281281977847,0.42705755795316586,-1.1761050464749792
618.6000000000081,67.11228103778687,0.43467082346533265,-1.1788534627551432
619.7000000000081,67.22229517087689,0.44322079480823356,-1.1794412998792438
620.8000000000081,67.33210295118015,0.453619264069484,-1.182239959163692
621.9000000000082,67.44129181256558,0.4621784500498672,-1.1834987615709611
623.0000000000082,67.55080673748849,0.47732291869291094,-1.185440453286184
624.1000000000081,67.66053864421231,0.48850941367438544,-1.1881700587680974
625.2000000000081,67.76917241568782,0.5031256196251769,-1.1908030635398874
626.3000000000081,67.88031423595443,0.5141325214723584,-1.1931353998420544
627.4000000000082,67.9899980581292,0.5290097468366515,-1.1948698103158546
628.5000000000082,68.09990263464533,0.5463599485627726,-1.197507077476216
629.6000000000082,68.20887788902583,0.5634204777022909,-1.200157582798615
630.7000000000082,68.31889570546875,0.5797879947371719,-1.2027751239461093
631.8000000000083,68.42618854341451,0.5965385515064493,-1.2044508278788943
632.9000000000083,68.53769974712043,0.6141979632850484,-1.2081854928656415
634.0000000000083,68.6480853156958,0.6325119110047848,-1.211099559164984
635.1000000000083,68.75913085614798,0.6524411742398428,-1.2148616952261966
636.2000000000083,68.86801309556097,0.6743974402436532,-1.216976627543298
637.3000000000084,68.9779488889914,0.6933768639096793,-1.2202890806640316
638.4000000000084,69.08790157592166,0.7141308158559017,-1.2249173713746853
639.5000000000084,69.19732842858328,0.7351504956889232,-1.2288637858503133
640.6000000000083,69.30600529653745,0.7563871381930458,-1.2319911282059173
641.7000000000083,69.41639763932291,0.7813545268776185,-1.23601635998854
642.8000000000084,69.5261728089043,0.8024978326104745,-1.2416950222866503
643.9000000000084,69.63520234819067,0.8249911972918798,-1.2463371057156483
645.0000000000084,69.74503100949435,0.8494034889540765,-1.2492295039805401
646.1000000000084,69.85446326407164,0.8755603018881726,-1.254063181620586
647.2000000000085,69.96341016910753,0.9014724337020426,-1.2600334437128282
648.3000000000085,70.07256142517623,0.9241906682950849,-1.2642702689971692
649.4000000000085,70.18430144429642,0.9554869018863669,-1.268639324172229
650.5000000000085,70.29318149283044,0.9807187604432966,-1.2732905486829194
651.6000000000085,70.40340304500889,1.0104422314019026,-1.281284531894165
652.7000000000086,70.51249845678718,1.0344521586219098,-1.2856573874976092
653.8000000000086,70.62225594566232,1.0662404964332874,-1.2924719169820564
654.9000000000086,70.73166291131831,1.09642940803542,-1.2982907703005355
656.0000000000086,70.84284941543595,1.1227931596263054,-1.3049833076228863
657.1000000000087,70.95212652970189,1.1534629801459257,-1.3106834882666698
658.2000000000087,71.06156292898353,1.1876720211207372,-1.3176526576290146
659.3000000000086,71.17065605980264,1.220503118965728,-1.324149930057441
660.4000000000086,71.28183726840497,1.254334252568055,-1.3318306131253896
661.5000000000086,71.39122377792032,1.2841495512568177,-1.3401956950462064
662.6000000000087,71.5005567208518,1.3225403128082642,-1.34814829646202
663.7000000000087,71.6120251334365,1.3613781640025686,-1.357057568291523
664.8000000000087,71.72174299128646,1.395643047303523,-1.3655527057967594
665.9000000000087,71.83145245499307,1.4364492029184208,-1.372559451196461
667.0000000000088,71.9414462912143,1.4753304366581446,-1.3814765801803883
668.1000000000088,72.05248542640479,1.5198575788521624,-1.3910485050410815
669.2000000000088,72.16246455761356,1.566027800437031,-1.3995521064005154
670.3000000000088,72.27272176539876,1.6114859222158415,-1.4093869359846547
671.4000000000088,72.38296354093569,1.6611060684428824,-1.4188375279248242
672.5000000000089,72.49286130537577,1.7101300085760158,-1.4286864510954294
673.6000000000089,72.60278921233339,1.7660744482764688,-1.4403693160050293
674.7000000000089,72.71131910422449,1.8224790421007933,-1.4510805943186709
675.8000000000088,72.8238108399955,1.884397576700031,-1.4616905651207506
676.9000000000088,72.9339538674664,1.9554804608069472,-1.4730923463810512
678.0000000000089,73.04383482190012,2.022496742554329,-1.4870439873148187
679.1000000000089,73.15510331378148,2.1009884353966477,-1.4988640645246853
680.2000000000089,73.26568006320079,2.1829302308873975,-1.5125762158828415
681.3000000000089,73.37523325784836,2.2688530930785347,-1.526661110661478
682.400000000009,73.48656532638023,2.3577838522189754,-1.5383588980558534
683.500000000009,73.59734199057753,2.456602027794358,-1.553269098408165
684.600000000009,73.70711635511978,2.5496042254405533,-1.5690156636861423
685.700000000009,73.81698875476008,2.645457637121806,-1.5830364232099643
686.800000000009,73.92810889421777,2.736474586106377,-1.6000912640478289
687.9000000000091,74.03942812166085,2.8218059736121885,-1.6157790100062006
689.0000000000091,74.14989907003346,2.8946564872592333,-1.6352043159832519
690.1000000000091,74.26078056639494,2.940504099058815,-1.6517525358894103
691.2000000000091,74.37118238342144,2.964876131174384,-1.670678451526844
692.3000000000092,74.48143286683094,2.9459663411293655,-1.6894272883433255
693.4000000000092,74.59224594752209,2.9166046714923306,-1.7071737528598372
694.5000000000091,74.70227237958119,2.8879871975820914,-1.7270208427972458
695.6000000000091,74.81351055112907,2.872766567968057,-1.7461527256189338
696.7000000000091,74.92343429497939,2.860372974833867,-1.766090433282022
697.8000000000092,75.03323816834134,2.8530467512917665,-1.785156919189244
698.9000000000092,75.14428187114285,2.8365953322477564,-1.8061098165904208
700.0000000000092,75.25463531793304,2.8208980663120657,-1.8261679377379143
701.1000000000092,75.36506715561468,2.7887372336585945,-1.8451587047737803
702.2000000000093,75.47526413261743,2.7554479467404835,-1.8644381613909529
703.3000000000093,75.5849383620202,2.7015549664775467,-1.8843705211959607
704.4000000000093,75.69562690276247,2.6405470555358646,-1.9040201399467724
705.5000000000093,75.80532216669476,2.5623380186192173,-1.9230736767511556
706.6000000000093,75.91443121364681,2.4736911810227458,-1.9400431067185293
707.7000000000094,76.02614471506597,2.370647799468902,-1.9577889142839435
708.8000000000094,76.13598868119831,2.262983764958653,-1.9737577788377498
709.9000000000094,76.24550609030916,2.137938957652719,-1.989517845450445
711.0000000000093,76.35498669703563,1.9909342288247454,-2.0052649040581336
712.1000000000093,76.46436489891454,1.828140009518676,-2.0191461429002495
713.2000000000094,76.5743460346667,1.6257594574301342,-2.0323880180047924
714.3000000000094,76.6841326314104,1.364186520608246,-2.0451331991372683
715.4000000000094,76.79416218734883,1.0486475349054574,-2.054630938518539
716.5000000000094,76.90364972834843,0.7205584555835813,-2.062578244472369
717.6000000000095,77.0139225776732,0.44084873606320585,-2.0681630962211504
718.7000000000095,77.12423647166554,0.28410247590124976,-2.069483185780018
719.8000000000095,77.2340482639521,0.22011355430518795,-2.07028209555937
720.9000000000095,77.3461049766113,0.2018972135286627,-2.0715401783390774
722.0000000000095,77.45609834582305,0.19979541729337952,-2.0729186324958127
723.1000000000096,77.56622630432301,0.20058860318755675,-2.0710747803023812
724.2000000000096,77.67789281344074,0.20551515396318198,-2.0715656318295763
725.3000000000096,77.78733303984187,0.20665935428666304,-2.072920104735651
726.4000000000096,77.89745360360132,0.20863266844354325,-2.0729200449216694
727.5000000000097,78.01041597805171,0.20940371805219138,-2.0716112464083167
728.6000000000097,78.1200022057838,0.20870350753858805,-2.07161010400078
729.7000000000096,78.2310435078957,0.20748782320486242,-2.072918963378517
730.8000000000096,78.34209667460505,0.2095141757484882,-2.072917473689481
731.9000000000096,78.4529600223588,0.21117614562442083,-2.0742401784975506
733.0000000000097,78.56296871797113,0.21423205825945527,-2.0742401719999988
734.1000000000097,78.67293776258083,0.21578128642119082,-2.0742401689968233
735.2000000000097,78.78335542144433,0.21517557970316117,-2.073557692190019
736.3000000000097,78.89437185176921,0.2181197539377517,-2.0735802693308107
737.4000000000098,79.00222671405028,0.21843841447805842,-2.072918823686032
738.5000000000098,79.11498677023776,0.2187363444334642,-2.0741755673574294
739.6000000000098,79.22459815095252,0.21489840320853446,-2.0729231631670593
740.7000000000098,79.3349962445362,0.21629436748739014,-2.0729197550260783
741.8000000000098,79.44486536430624,0.2154832869372923,-2.073932865144284
742.9000000000099,79.55564935766725,0.21424132656630251,-2.0729201609528873
744.0000000000099,79.6662626565437,0.21580337425773827,-2.0729201559953547
745.1000000000099,79.77818403880948,0.21806291701484198,-2.072916653433535
746.2000000000098,79.8881148271218,0.21826579820333583,-2.0745781348721555
747.0000000000099,79.97000000000106,0.2145332382721849,-2.0745598180000004