File: 01_Data/Laminate_Flooring/STA/N2/10K_min/Laminate_Flooring_STA_N2_10KData_221205_R2.csv
##Temp./Â°C,Time/min,DSC/(mW/mg),Mass loss/mg
51.0,10.586923690809035,0.010566795902522186,0.007606939714928984
52.20000000000002,11.049864121142614,0.03789595553242031,0.004224532790233937
53.400000000000034,11.332157786220506,0.05708027070985433,0.0038946867262552587
54.60000000000005,11.558324856917261,0.0720064257308708,0.00249150451163338
55.80000000000007,11.76013698624934,0.08322824862127454,0.003741500863344349
57.000000000000085,11.940980793428178,0.09133454728872259,0.0038187790501780228
58.2000000000001,12.114462644712365,0.10030183470687182,0.0020199658477499938
59.40000000000012,12.285577460493938,0.10544994905293281,0.0039652542740373775
60.600000000000136,12.444011863981022,0.11185354004926062,0.003099390714703887
61.80000000000015,12.601302317066102,0.11452449031135692,0.002664654119109322
63.00000000000017,12.753613309068124,0.1199843409519552,0.0020546758989157254
64.20000000000019,12.90220831402826,0.12111141118011748,0.0030566011333670318
65.4000000000002,13.049591051414154,0.12882009841066444,0.002910546345773035
66.60000000000022,13.193156436585829,0.1276841008888876,0.003337881549708044
67.80000000000024,13.335867925763253,0.12834911729122656,0.003105755905090213
69.00000000000026,13.476652444318463,0.12895634701090497,0.0016594372992999595
70.20000000000027,13.616028382661039,0.1308148797425328,0.0016857295996999255
71.40000000000029,13.75277017097314,0.13599403256127807,0.0021101106527483537
72.6000000000003,13.889139419809135,0.13819149026116873,0.0016826538846173023
73.80000000000032,14.02048205108301,0.14103594926089924,0.0016282146049988455
75.00000000000034,14.15753180185819,0.14259637803945813,0.0016323594553311338
76.20000000000036,14.292231758205526,0.14777916704098248,0.0016606316208083172
77.40000000000038,14.422372004759891,0.14969378592548055,0.002949767063492814
78.60000000000039,14.553461280457364,0.15362524343581496,0.0016585767950578756
79.80000000000041,14.68317892378897,0.15521389620061266,0.0016824977179634715
81.00000000000043,14.81214447875802,0.15920310479777156,0.001117031035408722
82.20000000000044,14.93946333623957,0.16215253181215927,0.0018254806546549318
83.40000000000046,15.066009869476773,0.16300851483749335,0.0015204736158889176
84.60000000000048,15.193434618020985,0.16607133339508318,0.0015934506362640377
85.8000000000005,15.317621860161315,0.16733364397221107,0.0003301325582780734
87.00000000000051,15.444436932952792,0.16814611861893525,-4.783161928800794e-05
88.20000000000053,15.569037496018229,0.16744736097938517,0.0003502052878543438
89.40000000000055,15.691314647451337,0.16995663568233788,0.001577631634717136
90.60000000000056,15.815003550698819,0.1703248237002175,0.0003314023815184086
91.80000000000058,15.936770050316763,0.17044100798314776,0.00036874958343435793
93.0000000000006,16.05928443645739,0.1720351001958753,0.00033823251687170597
94.20000000000061,16.180929026669002,0.17647257834202512,0.000660503989776906
95.40000000000063,16.302270229967657,0.17704444009831133,0.0003303387920672307
96.60000000000065,16.424045572651764,0.18003686499645277,0.0003415047034920349
97.80000000000067,16.543101922701457,0.18052371995034577,-0.00022925709230481317
99.00000000000068,16.663034376695705,0.18275957183296265,0.00032982201203601846
100.2000000000007,16.78243047204464,0.18378805071195736,0.000343949784801012
101.40000000000072,16.901590760185847,0.1875238958981864,0.00035071395481711676
102.60000000000073,17.020725469321,0.1872934343349708,0.0003636327212630519
103.80000000000075,17.140191359380616,0.18962751110262088,-0.00019403301053610988
105.00000000000077,17.258385686718718,0.19223695428532328,0.0003327149158307563
106.20000000000078,17.37647125179752,0.1926149819597378,0.0003392009674811902
107.4000000000008,17.49486136267038,0.19433624142888828,0.00032778935830002354
108.60000000000082,17.612664054661252,0.19631139487679028,-0.0009926150144221602
109.80000000000084,17.73074070828635,0.19738632774887432,0.0003207628630503834
111.00000000000085,17.847462577577993,0.19819446302259924,0.0002455589703505012
112.20000000000087,17.965096540084314,0.19928559224499487,9.633958635291151e-06
113.40000000000089,18.08281883070057,0.1994136234529943,0.001714730762038208
114.6000000000009,18.200229587866932,0.1991049713430212,0.00034194850974333946
115.80000000000092,18.31599876382555,0.2007304811222188,0.0016669211045226007
117.00000000000094,18.432875526974332,0.2016466533599366,0.0003389568937812726
118.20000000000095,18.551643673398015,0.20270876744072952,0.00033637426525423564
119.40000000000097,18.6675834600318,0.20410915717668165,0.0013375628434992848
120.60000000000099,18.78518824367168,0.20510468208778276,0.0003265767165920863
121.800000000001,18.901639957790284,0.20547366265944567,0.000330001032027738
123.00000000000102,19.018569830520832,0.20692338881996386,-0.0009699943140843992
124.20000000000104,19.134958564195927,0.20800928806685348,-0.0013484503699876527
125.40000000000106,19.251716313505682,0.20798613214038264,0.0003907279045556322
126.60000000000107,19.367250472631497,0.2095860196280751,-0.0008963365991987438
127.80000000000109,19.484353978386245,0.20925870805018454,-0.00067168807370388
129.0000000000011,19.598647140836366,0.2124247646453128,-0.00045865261002919766
130.20000000000113,19.71590284254768,0.2126558515252811,-0.0009570069861388752
131.40000000000114,19.83034747842875,0.21269875622338674,0.0003096428284834474
132.60000000000116,19.945389175765673,0.21303664711552095,0.0003371494164357003
133.80000000000118,20.06293722436479,0.21380746440626985,-0.0006373853238379468
135.0000000000012,20.178697246062878,0.21344264231066912,0.00033087052279423546
136.2000000000012,20.29358211865893,0.2146014004141693,-0.0010031084748094443
137.40000000000123,20.409576429087743,0.215375180683804,0.0003481168267578383
138.60000000000124,20.52337642606777,0.2163117860814724,-0.00039398447253935487
139.80000000000126,20.63763618228189,0.21673098224224896,-0.0009176251064855201
141.00000000000128,20.75281058824424,0.21567771584180784,0.000340000580965949
142.2000000000013,20.86852544732876,0.21860750216472669,-0.000992576452314875
143.4000000000013,20.98324432762577,0.21756163618039537,0.00033517092922075165
144.60000000000133,21.09789214132527,0.22084045066889357,-0.0018064580810621678
145.80000000000135,21.210010339518483,0.22267724463203853,0.0003256336777583968
147.00000000000136,21.32700095768355,0.22196250304370546,-5.1123632706318034e-05
148.20000000000138,21.44226209145334,0.22272442410395243,0.0001812158014704579
149.4000000000014,21.557587939963245,0.22207834300427476,0.0002287639949019038
150.60000000000142,21.67131935310058,0.22147922589079005,0.00022989147960394973
151.80000000000143,21.78569417566695,0.22336044087533657,-0.0011917928366593777
153.00000000000145,21.90055409684958,0.22254293918685308,-0.0010899341379499994
154.20000000000147,22.013942806497194,0.2248013386031693,-0.0010884114625602237
155.40000000000148,22.129082276036534,0.22443445237769166,-0.0010933952270142377
156.6000000000015,22.241211937886813,0.2234508404745802,-0.0005046939932373817
157.80000000000152,22.357579228748683,0.2261893141054998,0.000365607581687577
159.00000000000153,22.471203355094463,0.2274578505155167,-0.0009898684801630253
160.20000000000155,22.58564699035304,0.23078810715135178,-0.0009908297778569164
161.40000000000157,22.697902755456674,0.2295899067429059,-0.0006613932314745163
162.6000000000016,22.813459751391292,0.23123127028436052,-0.0006525571136486441
163.8000000000016,22.927234399552095,0.23048989115557295,-0.0006500054756299889
165.00000000000162,23.042262746742647,0.23257060105368232,-0.0009793590833666599
166.20000000000164,23.153558918176742,0.23112945754110592,-0.0016408664927500816
167.40000000000165,23.26978567216357,0.23388748583926622,-0.0019691339208880443
168.60000000000167,23.384024332314404,0.23336611980949984,-0.0010005746657517633
169.8000000000017,23.496803620051832,0.23422193375774092,-0.0016296236713815304
171.0000000000017,23.611133021766644,0.2335657066384157,-0.0032806464766217402
172.20000000000172,23.725874521869002,0.23295380681190092,-0.000612076676365092
173.40000000000174,23.83870297726956,0.23608259216002436,-0.003289195162605729
174.60000000000176,23.950540883202287,0.2357374322310486,-0.001969993968702788
175.80000000000177,24.066796422797026,0.2365565556221898,-0.0019688754475870596
177.0000000000018,24.181215287200377,0.23621220359458195,-0.0016191935429756832
178.2000000000018,24.294653919372383,0.23595037731642843,-0.002300173985310572
179.40000000000182,24.409088525075887,0.23780761132701722,-0.0019703208289238994
180.60000000000184,24.522379584681403,0.2380125022004118,-0.001969711528839291
181.80000000000186,24.636006030962186,0.23638618434179592,-0.00196999987445734
183.00000000000188,24.750410943412337,0.23544724355933633,-0.002613854435077556
184.2000000000019,24.864265281208645,0.23693567498002088,-0.0026399532208083443
185.4000000000019,24.9780099672815,0.23685587712718714,-0.0029598628178328923
186.60000000000193,25.092848899400682,0.2383424871101366,-0.003950740486788895
187.80000000000194,25.20561210802759,0.2381742629435466,-0.0029592617169691415
189.00000000000196,25.32036354991186,0.23983115868578153,-0.0029601143111444017
190.20000000000198,25.433539239616806,0.2383255969873086,-0.003937020230174504
191.400000000002,25.54652476290092,0.23930430341604447,-0.0027268073718409447
192.600000000002,25.660360307236672,0.23874515370003868,-0.0026192848966415383
193.80000000000203,25.77483363294852,0.24041967265793918,-0.00394000323494792
195.00000000000205,25.888603502410692,0.2395764938160907,-0.003998437265974708
196.20000000000206,26.001109072401995,0.23975862774641155,-0.0039644979934116975
197.40000000000208,26.11520632564491,0.24100356919777055,-0.003950063114208646
198.6000000000021,26.228639534822214,0.24196188524881856,-0.005270012862264473
199.80000000000211,26.343532005573923,0.24147088366640612,-0.005269933882931621
201.00000000000213,26.45605745676975,0.24309649099166541,-0.003950211830953343
202.20000000000215,26.570629854039097,0.2435930952817773,-0.00468566032195028
203.40000000000217,26.684377630678718,0.24297262735729808,-0.005260082422610779
204.60000000000218,26.79800886962252,0.24339069635834876,-0.0065798874839195776
205.8000000000022,26.911488793922928,0.24427663173241188,-0.0065800000647451284
207.00000000000222,27.026493923077396,0.24487666328219948,-0.007564170176191709
208.20000000000223,27.138317259960818,0.24537802686189047,-0.006579999974751338
209.40000000000225,27.252978934832644,0.24662242914632615,-0.00657999998144998
210.60000000000227,27.367427864121325,0.24828457495372347,-0.006897700221289327
211.80000000000229,27.480494355864444,0.24798813714299783,-0.009220067031106893
213.0000000000023,27.595290100043677,0.24856821419755293,-0.007900007652810626
214.20000000000232,27.70916165608236,0.2511003208957472,-0.00818514597549358
215.40000000000234,27.822455302130376,0.24917529642396408,-0.00954001230449908
216.60000000000235,27.93724065350042,0.24829681229791678,-0.010077459659481036
217.80000000000237,28.051206858302695,0.24934842760243603,-0.010859997414804923
219.0000000000024,28.165292827861936,0.24883745326613438,-0.010860000116384771
220.2000000000024,28.27881789484386,0.2489461053816967,-0.010297902273358694
221.40000000000242,28.39304518438696,0.24753083842812607,-0.011520000755445903
222.60000000000244,28.507259583193843,0.24913141353194113,-0.011644116845235253
223.80000000000246,28.621099446695034,0.25021047222027537,-0.012156984084057854
225.00000000000247,28.7357557519059,0.2490678061469288,-0.0129311760171813
226.2000000000025,28.849734890385445,0.24927073680646739,-0.01318132765594271
227.4000000000025,28.963691313909116,0.24908721567462377,-0.013169999569687896
228.60000000000252,29.07854356795039,0.2480930929723979,-0.013726605891037469
229.80000000000254,29.191483830916436,0.24971420306825365,-0.016140059843570587
231.00000000000256,29.30721828869436,0.24998339493871702,-0.017284780449365655
232.20000000000258,29.4202988145689,0.24855555872953128,-0.017451127314357606
233.4000000000026,29.535179999567063,0.24933724364985266,-0.01844000416103375
234.6000000000026,29.64903217243377,0.2507522189684881,-0.01979053533387276
235.80000000000263,29.763038998748787,0.25226491204929846,-0.01975063192093751
237.00000000000264,29.877755074647908,0.24975865253499585,-0.021448158251816007
238.20000000000266,29.991571114200212,0.25042027339718476,-0.024009553023503827
239.40000000000268,30.106104424736962,0.25137490719676236,-0.024024682288934063
240.6000000000027,30.218657374719207,0.25353453060239506,-0.024036219986153462
241.8000000000027,30.33351382183476,0.25229409098388356,-0.02667279566607972
243.00000000000273,30.448087187971936,0.25237217552169056,-0.026670010655871934
244.20000000000275,30.562046518153256,0.2530275552361,-0.02930072268146855
245.40000000000276,30.676457733233573,0.2542853036501216,-0.02797969490674701
246.60000000000278,30.789264237711826,0.25540540341893914,-0.029711414079784948
247.8000000000028,30.902465557218736,0.25572443382211163,-0.03029353559037329
249.0000000000028,31.0172013762376,0.255135030665543,-0.03161029080056421
250.20000000000283,31.132759683129873,0.2568312997790412,-0.03326090631765943
251.40000000000285,31.245200971834816,0.2536938399364047,-0.03591437058590774
252.60000000000286,31.360433695256333,0.2536806956343578,-0.03687928780626093
253.80000000000288,31.4752808142514,0.2550073839410988,-0.039336102646250204
255.0000000000029,31.588541162658174,0.2519899314102738,-0.04227389291492667
256.2000000000029,31.701357569012934,0.25179560295100656,-0.044715989569816816
257.40000000000293,31.81552329751527,0.2491373699104369,-0.04556383723119373
258.600000000003,31.93012699044486,0.24776021951554805,-0.0477987474112358
259.80000000000297,32.04405529338263,0.2461192634018563,-0.04910820566148688
261.00000000000296,32.158030005018624,0.24391477443420206,-0.05324831212688297
262.200000000003,32.27149265677256,0.24874361083005248,-0.05547655994489098
263.40000000000305,32.386857962926776,0.2529639404776547,-0.057440259055937304
264.60000000000304,32.500643293575514,0.2589967470871266,-0.06060831170254177
265.800000000003,32.61538529689948,0.2676610195841671,-0.06632424628044031
267.00000000000307,32.72925936191209,0.27192320615011023,-0.06942681865264744
268.2000000000031,32.8418296818892,0.27379320248370187,-0.07409244404482296
269.4000000000031,32.9572844095024,0.2766665522235039,-0.07991509809839625
270.6000000000031,33.071532699421766,0.2824534199009442,-0.08678050736154219
271.80000000000314,33.18630901181471,0.28772863004818783,-0.09389883800526633
273.0000000000032,33.30073892521253,0.29176363103710745,-0.10252026069377118
274.2000000000032,33.41435866339587,0.2954739888394021,-0.11119268817589756
275.40000000000316,33.52864999147187,0.30001238418038434,-0.12146620462745927
276.6000000000032,33.64334241753775,0.30271234975695,-0.13422616149352606
277.80000000000325,33.75708581313774,0.3044361284749136,-0.1461464463801887
279.00000000000324,33.872860536204875,0.30782493817302176,-0.16006529464570818
280.20000000000323,33.986946299882774,0.31226658540771424,-0.1764016912961215
281.4000000000033,34.100610810776345,0.3170197160903245,-0.19054444113142965
282.6000000000033,34.2167419987978,0.3261892662706519,-0.2067548731278679
283.8000000000033,34.33100370455452,0.33775298784557833,-0.2233208471715038
285.0000000000033,34.44505888285267,0.3535960606552715,-0.24117908284955503
286.20000000000334,34.56047992776066,0.36978829194551055,-0.2594917737582989
287.4000000000034,34.674450836466576,0.3910225331656444,-0.2772090397179068
288.6000000000034,34.78850361603153,0.40504316694349823,-0.29686373984014924
289.80000000000337,34.90415682545432,0.41914202462727795,-0.3146399385066099
291.0000000000034,35.01895503217779,0.43299541502796685,-0.3344842601764464
292.20000000000346,35.13430063172173,0.44053015011917934,-0.35336701117970737
293.40000000000344,35.24878239326108,0.4460052005539734,-0.37360891466522883
294.60000000000343,35.3622916082001,0.4478805067933471,-0.39080508362034205
295.8000000000035,35.4781442693501,0.44793469925229695,-0.408197394484056
297.0000000000035,35.593269905050235,0.4428007661762215,-0.4242166280500599
298.2000000000035,35.707885225967,0.4380099116132227,-0.44088257202523806
299.4000000000035,35.82260879898232,0.42991600797222934,-0.4560290149978261
300.60000000000355,35.938248242907775,0.4212223770069492,-0.4706989216929278
301.8000000000036,36.052232498473536,0.4109933179588372,-0.4828225655179761
303.0000000000036,36.16755089740089,0.39912400188484637,-0.49700408048691225
304.20000000000357,36.28228146950879,0.38762789877916654,-0.507671916397455
305.4000000000036,36.39499004949736,0.3765811769336724,-0.5188729331697708
306.60000000000366,36.51173226665508,0.3634103975188906,-0.5290093019999009
307.80000000000365,36.62669016563019,0.35288940170283356,-0.5382953162090338
309.00000000000364,36.74179394803617,0.3395035894003997,-0.5480774875793366
310.2000000000037,36.85696103025494,0.3300367443645217,-0.55616156696711
311.40000000000373,36.97200098083654,0.3221004299393322,-0.5630532519018789
312.6000000000037,37.08780104507306,0.31176448958741,-0.5706754098191191
313.8000000000037,37.20168584709216,0.3047921284514408,-0.5789052057842556
315.00000000000375,37.31766423096947,0.29485307483166934,-0.5853466617546297
316.2000000000038,37.430929360009245,0.28631535146028225,-0.5901815218158619
317.4000000000038,37.544988743080125,0.2768119954685648,-0.5958774902786086
318.6000000000038,37.66150886772791,0.2695575501206895,-0.6037273061627539
319.8000000000038,37.77726898533512,0.2629480019280165,-0.6078701228471104
321.00000000000387,37.89222824223747,0.25267093242434724,-0.612343182765283
322.20000000000385,38.00668408859273,0.24612344159573418,-0.6166164455406187
323.40000000000384,38.123280901463694,0.23931459044354625,-0.6226693644045831
324.6000000000039,38.238079040051225,0.23106834594410008,-0.6265038997332937
325.80000000000393,38.352975023176796,0.22596838372748518,-0.6297738971637141
327.0000000000039,38.46896653170482,0.21766255816373392,-0.6336579274325995
328.2000000000039,38.58479122690951,0.21169123784327504,-0.6363558441299553
329.40000000000396,38.70011376224949,0.2075061459834534,-0.6403572379180664
330.600000000004,38.8122639453789,0.19886746714808978,-0.6424607333728796
331.800000000004,38.93048395269208,0.19668264554279313,-0.6457401185342349
333.000000000004,39.045392348281474,0.19135917164057448,-0.648343903827385
334.200000000004,39.16111831715328,0.18578982001683775,-0.6509953494600857
335.40000000000407,39.27602007075148,0.18213927572555166,-0.6542974634858676
336.60000000000406,39.3914936860266,0.1776941440101687,-0.6576427125510063
337.80000000000405,39.50645619589944,0.17300400997967302,-0.6588154551995653
339.0000000000041,39.622604340484514,0.17106115954912893,-0.6615536244180555
340.20000000000414,39.73791717388091,0.1677026635123875,-0.6628700913623913
341.4000000000041,39.85227868365837,0.16438387833893953,-0.6641836848172749
342.6000000000041,39.96635227918852,0.16178061717679237,-0.6655280524139853
343.80000000000416,40.0837105930191,0.15961021599646885,-0.6668229974483313
345.0000000000042,40.200045531554025,0.15581835332770855,-0.6681400497072563
346.2000000000042,40.315749266791336,0.15345017347263445,-0.6705063834331759
347.4000000000042,40.43039833590011,0.15137092089694482,-0.6704219026495517
348.60000000000423,40.54643299645864,0.14834425358432757,-0.6730692606438646
349.8000000000043,40.66267032046826,0.14848901226006894,-0.67309111298463
351.00000000000426,40.778484537657334,0.14867350360529863,-0.6751648158154548
352.20000000000425,40.89445491277358,0.1467512197271169,-0.6756627758093159
353.4000000000043,41.008152058817885,0.14626441107351196,-0.6783376907644314
354.60000000000434,41.12717334607668,0.14755482798715625,-0.6783305342632602
355.80000000000433,41.243368996695565,0.1458656793017714,-0.6783400108085149
357.0000000000043,41.35944688561639,0.1452227954911396,-0.6792126472399045
358.20000000000437,41.47563863660257,0.14634524591254405,-0.6806500002179376
359.4000000000044,41.59052969135401,0.14914879310367135,-0.680652580857446
360.6000000000044,41.70691499217832,0.14812811863672526,-0.6809700080716388
361.8000000000044,41.82372555718144,0.14878174455227478,-0.6809699991280542
363.00000000000443,41.93959452723816,0.1487417446095931,-0.6829466169362743
364.2000000000045,42.0544759117041,0.1487394304285088,-0.683643036556846
365.40000000000447,42.17148722582174,0.1491678769124255,-0.6836099936013764
366.60000000000446,42.28789419972102,0.14837418935398494,-0.6836141485728158
367.8000000000045,42.40406316317727,0.1485195079621383,-0.6849302653744531
369.00000000000455,42.521505340759795,0.14795729055550966,-0.6849422175536506
370.20000000000454,42.63586660941158,0.14740104387466002,-0.685930197977231
371.4000000000045,42.752690403855524,0.14778828982792058,-0.6869282989869614
372.60000000000457,42.86857957885089,0.14864464682904444,-0.6875599691030323
373.8000000000046,42.98470328393105,0.14839280040455738,-0.6885183337701255
375.0000000000046,43.10153122549107,0.14732767571466399,-0.6885568712597583
376.2000000000046,43.21668300162532,0.14629410509720941,-0.6898110469565819
377.40000000000464,43.33231983061566,0.148196586340957,-0.6885565075141011
378.6000000000047,43.45013153915477,0.14781157539689493,-0.6892170526197527
379.8000000000047,43.56635534685857,0.14837590023352132,-0.6898700062655991
381.00000000000466,43.68073282240792,0.14949707528307488,-0.6911899707719211
382.2000000000047,43.79921819614384,0.1480723240380637,-0.6911900002833669
383.40000000000475,43.91497881444782,0.14878750593616186,-0.6930234514657183
384.60000000000474,44.03233612725266,0.14750017786939018,-0.6938200000112964
385.80000000000473,44.149588897881756,0.1480533875392831,-0.6938200940532666
387.0000000000048,44.26615271350121,0.1473359421449284,-0.6937682403676453
388.2000000000048,44.38173785547162,0.14700492496191442,-0.6944798987161773
389.4000000000048,44.499723169046604,0.14726801167372672,-0.6958000066314165
390.6000000000048,44.616677397787605,0.1458307820629502,-0.6962882495708915
391.80000000000484,44.732332041429046,0.14714978526310252,-0.6958056892109545
393.0000000000049,44.84982742756093,0.14663143565030512,-0.697119876107839
394.2000000000049,44.96749167263608,0.14757567645311465,-0.6990898521494402
395.40000000000487,45.084084197997065,0.1488434458019371,-0.6990900003849143
396.6000000000049,45.19988945353772,0.14987424102766156,-0.7004010866149457
397.80000000000496,45.31706881892252,0.148966337943522,-0.7017399554428825
399.00000000000495,45.43377608830287,0.14950194777308734,-0.7017299999037583
400.20000000000493,45.549900671507906,0.15026006419801075,-0.7026368531735709
401.400000000005,45.66628183064733,0.14972879776221149,-0.7030512848403938
402.600000000005,45.78296427990994,0.14914840041291133,-0.7040300035462446
403.800000000005,45.900144889665626,0.14913244114355717,-0.7040171982351873
405.000000000005,46.01716298826977,0.1489003496599688,-0.7056858918672044
406.20000000000505,46.13102841071947,0.1494145724496001,-0.7056797790219629
407.4000000000051,46.250727200475865,0.14809802546999074,-0.7060014523138927
408.6000000000051,46.36737960918931,0.14867489660930833,-0.7083107875223904
409.80000000000507,46.48429472969266,0.14607448666527767,-0.7096304910224407
411.0000000000051,46.601968144134354,0.14602181180601437,-0.7109499411516236
412.20000000000516,46.71787595652465,0.14535917447099223,-0.713293578225008
413.40000000000515,46.83515356789901,0.14589774553497703,-0.71193417445033
414.60000000000514,46.95191350585494,0.1436253145366988,-0.7132869430173185
415.8000000000052,47.06923352989202,0.14530904604270012,-0.7159187045604476
417.00000000000523,47.185896582097214,0.14768265803320935,-0.71813047537779
418.2000000000052,47.303499698230375,0.1468674511065925,-0.7195585157071407
419.4000000000052,47.41992226400434,0.1441731119071128,-0.7208304303147015
420.60000000000525,47.53713039818527,0.14469422029695367,-0.7221061810547251
421.8000000000053,47.65359614775968,0.14399545112414713,-0.7234522902251737
423.0000000000053,47.770932255450155,0.14452087733081276,-0.7261017717482945
424.2000000000053,47.886140937473286,0.1440369680600757,-0.7274604694684563
425.4000000000053,48.00585546896101,0.1454534808311937,-0.7300591238618552
426.60000000000537,48.122285163998775,0.14623560119098838,-0.7314312818669282
427.80000000000535,48.23987759656772,0.14700756805149973,-0.7339936610453024
429.00000000000534,48.35656147921921,0.14569985891595777,-0.7369673404054331
430.2000000000054,48.474778721997566,0.14782517346235785,-0.7389061143310691
431.40000000000543,48.5919992767588,0.14655436940898625,-0.7395976947259362
432.6000000000054,48.708129742886264,0.1483152245214015,-0.7432039044995049
433.8000000000054,48.82548313688441,0.145121581780983,-0.7458669256397199
435.00000000000546,48.94319163592367,0.1492576633503872,-0.749825362147984
436.2000000000055,49.059901061370674,0.14824107509949425,-0.7529072253601541
437.4000000000055,49.17704624219995,0.14948996076170568,-0.7552261884289013
438.6000000000055,49.293761226044595,0.15113660201937557,-0.7593398330059653
439.8000000000055,49.41092603616652,0.15241361336192438,-0.7628873111702621
441.00000000000557,49.52890290366107,0.15599479580377762,-0.7673896450673632
442.20000000000556,49.64619121547375,0.1540981953640484,-0.7702721092670788
443.40000000000555,49.76316966483311,0.15676183301754715,-0.7744074862144767
444.6000000000056,49.88073968652277,0.1597176111432838,-0.7792231808191623
445.80000000000564,49.99729640619904,0.16401721978322747,-0.784484676010901
447.0000000000056,50.114151434197964,0.167089976616278,-0.7889439833797307
448.2000000000056,50.23111570138892,0.17225580768219745,-0.7946222767492763
449.40000000000566,50.34852023832712,0.17354637190595534,-0.7999214281420102
450.6000000000057,50.46545757742358,0.17819204612821332,-0.8046956316162035
451.8000000000057,50.582118394408596,0.1813067229947653,-0.8097466896782177
453.0000000000057,50.700320468207735,0.18310608687915297,-0.8161763278772618
454.20000000000573,50.81761889771206,0.18995425412693928,-0.821675222767456
455.4000000000058,50.93510922963513,0.1954991951143058,-0.8276024594025095
456.60000000000576,51.05183246975309,0.19671717055084126,-0.8329698615939565
457.80000000000575,51.16948693871026,0.20100542940627963,-0.8392069344265836
459.0000000000058,51.286910010183455,0.2063786957753968,-0.8455995932883522
460.20000000000584,51.403324589525965,0.21040123678610784,-0.8516296392519904
461.40000000000583,51.5204532193462,0.21467196455907678,-0.8579534753261813
462.6000000000058,51.63794153371137,0.2190227479440109,-0.8636912410324875
463.80000000000587,51.75555974055594,0.22122098412893854,-0.8699605727981505
465.0000000000059,51.872446300655994,0.22549740037849375,-0.8766442325363775
466.2000000000059,51.990021633607874,0.22493317741317237,-0.8814420688369986
467.4000000000059,52.10709852714441,0.22764164763396627,-0.8888583211788683
468.60000000000593,52.2248910567479,0.22980581916271936,-0.8933411461817862
469.800000000006,52.34232302050451,0.2327152666883539,-0.8969932273592605
471.00000000000597,52.45916853559664,0.2316348056840678,-0.9041876818311172
472.20000000000596,52.57729982792573,0.23443798222633716,-0.9083778750293963
473.400000000006,52.69366538109454,0.23370827874626182,-0.9146769685846232
474.60000000000605,52.81330535643689,0.23427157140370036,-0.9186119452653525
475.80000000000604,52.93025672073601,0.23749563052071215,-0.9232252591134591
477.000000000006,53.04864596827588,0.2367027360624256,-0.9274194647115848
478.20000000000607,53.16389494817578,0.23632997085356672,-0.9327302239260913
479.4000000000061,53.28403515585856,0.23690885284683183,-0.9369118191688433
480.6000000000061,53.40268992458194,0.2372123647558836,-0.9418618235201204
481.8000000000061,53.51869621980171,0.23734369664791571,-0.9464182496006215
483.00000000000614,53.63924275976102,0.2385701317066749,-0.9477855566691091
484.2000000000062,53.75604259251199,0.23872413965963346,-0.951270856910905
485.4000000000062,53.87458868188602,0.23932641874343996,-0.9546640134346633
486.60000000000616,53.99275731085264,0.2381660479382744,-0.9582667266354274
487.8000000000062,54.11052718325392,0.24051819071247482,-0.9609290819748435
489.00000000000625,54.22883478121638,0.24036937523921487,-0.9635626412113769
490.20000000000624,54.3457675720444,0.23878818214670916,-0.9675153921162338
491.40000000000623,54.4642633629412,0.2395680685814453,-0.9701959279570618
492.6000000000063,54.58151982725864,0.24004833755124472,-0.971792522223982
493.8000000000063,54.70063029790828,0.24081436852793808,-0.9728185724199321
495.0000000000063,54.81777642236919,0.24094047457644807,-0.9755205729751615
496.2000000000063,54.935086942181705,0.24014814661959027,-0.9780006362414753
497.40000000000634,55.05481968253527,0.23951213031699886,-0.9800933919982673
498.6000000000064,55.17316425777755,0.24328970688589524,-0.9820782612668455
499.8000000000064,55.28995490369997,0.23943199646828445,-0.9834299886053142
501.00000000000637,55.408224011344046,0.23850419368839687,-0.9847514970844595
502.2000000000064,55.527538772208686,0.2381503400311148,-0.9860696524222972
503.40000000000646,55.64438586514979,0.23890753191212905,-0.9873900688707988
504.60000000000645,55.76241343510928,0.23864679845773035,-0.9887072762683253
505.80000000000643,55.88063344935876,0.23856134297023623,-0.99002004877496
507.0000000000065,55.997909312091544,0.2382160835997807,-0.9903499725205558
508.2000000000065,56.11618288306859,0.23772350630317246,-0.9926543118084754
509.4000000000065,56.23235061872895,0.23564962550020752,-0.9933548455161594
510.6000000000065,56.35298891855568,0.23606118853820957,-0.9939699997006173
511.80000000000655,56.47031688634682,0.2360564541617649,-0.9939736552754188
513.0000000000066,56.58759288610793,0.2366287626152609,-0.9966100030798475
514.2000000000066,56.70649289722259,0.23684030080177543,-0.9958302621744148
515.4000000000066,56.82515053554062,0.23619521328373821,-0.9979199739324947
516.6000000000066,56.94186836758136,0.23619503494726496,-0.9991813164944143
517.8000000000067,57.06045481544646,0.23371404843332055,-1.0003270404881563
519.0000000000066,57.17864315291858,0.23783174283381275,-0.9992415809498643
520.2000000000066,57.29616009141219,0.23963880667124976,-1.001879881887711
521.4000000000067,57.415124160553056,0.24290496484612678,-1.0032422049439207
522.6000000000067,57.53239523785405,0.24636820038113638,-1.003185282930254
523.8000000000068,57.651044149355236,0.24979333769079837,-1.0045112075656757
525.0000000000067,57.76947768147263,0.24942257011891433,-1.0049817854294871
526.2000000000068,57.88731100018276,0.2532233867485292,-1.0045100007006686
527.4000000000068,58.00675165838879,0.2530300160350495,-1.0054859807113443
528.6000000000067,58.12507147987651,0.2561457382114825,-1.0068139851887716
529.8000000000068,58.24301569242793,0.2553965403243965,-1.0073586438766409
531.0000000000068,58.36249837825517,0.2593051623870628,-1.008129999961655
532.2000000000069,58.48122802700023,0.2615211519941431,-1.008131622687884
533.4000000000069,58.5996358439364,0.26347697451543495,-1.010766157388208
534.6000000000068,58.717467968444296,0.27084324043541075,-1.0117500629673422
535.8000000000069,58.836531686404896,0.27063781949899846,-1.0122484705753783
537.0000000000069,58.955466615536736,0.2747929614534994,-1.012080009143895
538.2000000000069,59.07438487948931,0.27969931349292654,-1.0134017142853353
539.4000000000069,59.19245217963443,0.28327166462791153,-1.0155162497566614
540.600000000007,59.31164040380063,0.288177758028059,-1.0160300007577203
541.800000000007,59.42997754423314,0.29174758126376554,-1.0173474068731823
543.000000000007,59.547959019001354,0.29646434838816105,-1.0186706718591325
544.200000000007,59.667976455433156,0.30244910727978364,-1.0178340862374458
545.400000000007,59.787346740688115,0.3087284384269402,-1.020010936707127
546.6000000000071,59.9070449456687,0.31703478432696497,-1.022989272339779
547.800000000007,60.02422596776245,0.32531943411478703,-1.0244078029874912
549.000000000007,60.143349346273276,0.33566567697185556,-1.0242637680749556
550.2000000000071,60.26231352796373,0.3459978099717086,-1.0269400171648457
551.4000000000071,60.38146851880657,0.35866275583397544,-1.028217194941642
552.6000000000072,60.500731219180466,0.3724398362802288,-1.0298643873225468
553.8000000000071,60.62017313036001,0.3852397191287915,-1.031190006456844
555.0000000000072,60.73958935007988,0.39968065995195773,-1.032505663230943
556.2000000000072,60.85700941816226,0.41234846737865166,-1.0350706121453674
557.4000000000071,60.97787255054518,0.43040735057941953,-1.0391840468015094
558.6000000000072,61.09716955373225,0.445037509045236,-1.0418182824763238
559.8000000000072,61.21637025390288,0.4606324214298498,-1.0430989208777346
561.0000000000073,61.33534135811077,0.4742770641230245,-1.0458525701168946
562.2000000000073,61.45197665710589,0.4887830007308212,-1.0495208556471343
563.4000000000073,61.57331812652522,0.5029925623654979,-1.0531853101189568
564.6000000000073,61.69185729467834,0.5163380231697559,-1.05520490821552
565.8000000000073,61.811225930955715,0.5276756072507969,-1.0589912320890766
567.0000000000073,61.93016464323528,0.5420683791409544,-1.0626953820407548
568.2000000000073,62.04960176895336,0.5502305339373341,-1.066819484600979
569.4000000000074,62.167975308406,0.5530541072635261,-1.068828158125113
570.6000000000074,62.28817331728094,0.5489950855958312,-1.0723724744833354
571.8000000000075,62.40685219054337,0.5344796299781305,-1.0776369013632539
573.0000000000074,62.52662379594205,0.5085492904220488,-1.0816893111884305
574.2000000000074,62.64591598679881,0.45879841825427986,-1.0850570246103466
575.4000000000075,62.765897900825884,0.3754152378188648,-1.0894300882500123
576.6000000000074,62.883809627716836,0.2974407956559811,-1.0906881104318549
577.8000000000075,63.00393885676731,0.2485473191127998,-1.0933207746391922
579.0000000000075,63.123721705159895,0.22009687371966374,-1.0920000373871592
580.2000000000075,63.24320983674198,0.20056706671712382,-1.0933200924188706
581.4000000000076,63.36281189529417,0.19008376160072976,-1.0946452833595584
582.6000000000075,63.48257332631718,0.1813032756877253,-1.093664797728875
583.8000000000076,63.60150773241286,0.1736768468265223,-1.09497089068513
585.0000000000076,63.721237935949,0.16524205431487143,-1.094970638883932
586.2000000000075,63.840932516447765,0.16096337991345427,-1.0972699691698504
587.4000000000076,63.960509868613485,0.16146619422549618,-1.09726796505133
588.6000000000076,64.08083217769291,0.15851412555659217,-1.0972700002937423
589.8000000000077,64.20018099962617,0.16117147583617764,-1.0985899914194115
591.0000000000077,64.3190145611445,0.16779375960256443,-1.098587549366516
592.2000000000077,64.4389021166029,0.1680763147157332,-1.0998991925381123
593.4000000000077,64.55850876283571,0.1761715597059768,-1.1012200093806963
594.6000000000078,64.67777447802861,0.18211432170330538,-1.0999072858201666
595.8000000000077,64.79715168938327,0.19150992685889623,-1.1012542223053003
597.0000000000077,64.91650737641517,0.1998583326236224,-1.102549957153132
598.2000000000078,65.03675369052021,0.2061937406803391,-1.103860742855633
599.4000000000078,65.15637687442384,0.2144552990473263,-1.105179619709956
600.6000000000079,65.27538044368177,0.22360977315897163,-1.1065000061530434
601.8000000000078,65.39369586391612,0.23110312385640505,-1.106498049002881
603.0000000000078,65.51444335014367,0.23988750607082462,-1.1083080308865942
604.2000000000079,65.63425096622682,0.24653678042617308,-1.109130888221606
605.4000000000078,65.75249349875055,0.2523476884593058,-1.110450023178942
606.6000000000079,65.873072985546,0.2593704620371437,-1.1115957834626178
607.8000000000079,65.99238623741714,0.2657965708345098,-1.114400063269343
609.000000000008,66.11167609794896,0.27158027958084485,-1.1157194185417612
610.200000000008,66.23113567401896,0.2779771240262435,-1.1167265060904628
611.4000000000079,66.3508279786315,0.2843827849523747,-1.1180198315942627
612.600000000008,66.46932596709426,0.29274857951348265,-1.1199869304312622
613.800000000008,66.58766828611104,0.29754913628886737,-1.1223742638741543
615.000000000008,66.70852749280185,0.3072348663290183,-1.1236196002468954
616.200000000008,66.82772889589646,0.3169388161430975,-1.1236223296515595
617.400000000008,66.94769794958606,0.3246483514287045,-1.126253406344305
618.6000000000081,67.06538005394967,0.33297206452467243,-1.1302115654543528
619.8000000000081,67.18682719386845,0.3387879242058428,-1.1302126100397287
621.0000000000081,67.30733010238805,0.35336038669642467,-1.1328478722663728
622.2000000000081,67.4272939246183,0.3662281782908683,-1.134161669581454
623.4000000000082,67.54721019863379,0.37842201547267024,-1.136611118099741
624.6000000000081,67.66670029972937,0.392972505565886,-1.1382116551661574
625.8000000000081,67.78567601226487,0.4044224884687842,-1.1408097230425711
627.0000000000082,67.90541701105715,0.4197076600426961,-1.143813821621456
628.2000000000082,68.02575369260822,0.4347091656499534,-1.1460025619993561
629.4000000000083,68.14631480443384,0.4517495664141172,-1.1489247684294694
630.6000000000082,68.26527866233167,0.4738002581062742,-1.1523504950488812
631.8000000000083,68.38522294447843,0.48919354369264917,-1.154374163709651
633.0000000000083,68.50623952727,0.5110983928417293,-1.1576448333953202
634.2000000000082,68.62405643403027,0.5310146433331158,-1.1606961097243618
635.4000000000083,68.74464077836569,0.5516058151217258,-1.164429981355465
636.6000000000083,68.86358051302258,0.5739111135874562,-1.1686481972288805
637.8000000000084,68.98331461671026,0.5960205476660334,-1.1711479350768483
639.0000000000084,69.10257768743371,0.622291568210032,-1.175368779098966
640.2000000000083,69.22276505059313,0.6423803463064858,-1.1795869260827931
641.4000000000084,69.34145433041836,0.6667314213473683,-1.1836908751198512
642.6000000000084,69.4617038034049,0.6919819178907625,-1.1888470806771982
643.8000000000084,69.58091660221324,0.7158581743086494,-1.1925694424604134
645.0000000000084,69.70044328981405,0.740893347877221,-1.1980333253722106
646.2000000000085,69.82072886796237,0.7661965661452872,-1.2036398917893507
647.4000000000085,69.94092507108533,0.7946118344122304,-1.2071710250936665
648.6000000000085,70.06083192590782,0.8207230195449147,-1.2140764065894891
649.8000000000085,70.18034459039471,0.848624296315707,-1.2202407765440357
651.0000000000085,70.30034947483404,0.880087904258765,-1.226352130381179
652.2000000000086,70.42024552912154,0.9090113418929547,-1.2324010681962578
653.4000000000085,70.53884614864897,0.9418564948769841,-1.2373736831106177
654.6000000000085,70.65927678003513,0.9716712082030425,-1.2443253039393274
655.8000000000086,70.7788100441894,1.0024817708511526,-1.2505464422673662
657.0000000000086,70.89851338480996,1.038102851006712,-1.2568045357715376
658.2000000000087,71.01764722334843,1.0712210752729523,-1.2647037148100964
659.4000000000086,71.13950152769804,1.1054021379265546,-1.2732371538156015
660.6000000000087,71.25826526339937,1.1409381151172377,-1.2817315463190626
661.8000000000087,71.37688386181318,1.1780019358137042,-1.2886988330703861
663.0000000000086,71.4968317826445,1.2163306038421724,-1.2963675984282386
664.2000000000087,71.61645595153416,1.253837958082316,-1.3064350559868552
665.4000000000087,71.73708973687216,1.2974727260761065,-1.3131870028539652
666.6000000000088,71.8565577039384,1.3405880502309264,-1.3232885613016236
667.8000000000088,71.9748954887755,1.3843274049723684,-1.3330299024136085
669.0000000000088,72.09664659097675,1.4340411782145437,-1.342210485874459
670.2000000000088,72.21639090167355,1.4783586734540681,-1.3516538149297634
671.4000000000088,72.33653605995586,1.5270876696820768,-1.3628057547757515
672.6000000000088,72.45689770310007,1.5789331613248188,-1.3719615427668028
673.8000000000088,72.57731171277118,1.634821547556144,-1.384186661777424
675.0000000000089,72.69770718089185,1.6926605113214892,-1.3961527999366727
676.2000000000089,72.8184011098782,1.7578085648555808,-1.4070971733122768
677.400000000009,72.93716132068073,1.829272770496044,-1.4196983096821065
678.6000000000089,73.05797984966536,1.9143958359065583,-1.4326103834636363
679.8000000000089,73.17938718746163,2.0022760072946384,-1.4467564848561176
681.000000000009,73.30092692689695,2.09868584806949,-1.4606680204132916
682.2000000000089,73.42063837432221,2.1988898451070646,-1.4757960880510437
683.400000000009,73.54114264438188,2.3042733273664764,-1.4898133148526647
684.600000000009,73.66250821863736,2.417794367517619,-1.5066208119063336
685.800000000009,73.78226798524562,2.529605629159939,-1.5223742800244997
687.0000000000091,73.9043886971413,2.645858921755869,-1.5397831119387546
688.200000000009,74.02409773012326,2.7547343757949414,-1.5550971736348624
689.4000000000091,74.14561682388174,2.843270824909133,-1.5757396635226901
690.6000000000091,74.2653875211115,2.8923821650939012,-1.5924576377253827
691.800000000009,74.38624622858438,2.902403702563405,-1.612779176480672
693.0000000000091,74.50716116585703,2.8666318645491122,-1.6340171980958593
694.2000000000091,74.62550091190906,2.829057436325397,-1.653377854568498
695.4000000000092,74.74488576432283,2.8165419895666117,-1.675382969718401
696.6000000000092,74.86714589754288,2.815229102008087,-1.6941352183636575
697.8000000000092,74.98726715033251,2.824028692097116,-1.716059178182383
699.0000000000092,75.10636040695367,2.8317605211825327,-1.7378929818354534
700.2000000000093,75.22745479636517,2.8314359031417458,-1.7595418898846842
701.4000000000092,75.3474277605973,2.821965004830492,-1.7800849183705556
702.6000000000092,75.46763706656455,2.7987095181667763,-1.8020769061588053
703.8000000000093,75.58738858436004,2.7537262467079766,-1.8236902211382646
705.0000000000093,75.70807149032679,2.680184588166859,-1.8466657360022416
706.2000000000094,75.82843622295262,2.5761526649961266,-1.8679042192580049
707.4000000000093,75.94872403493396,2.433671456807868,-1.8883527404749985
708.6000000000093,76.06729535888826,2.2688167680054434,-1.9072875617141767
709.8000000000094,76.18777960528868,2.0814600660177893,-1.9257187719319542
711.0000000000093,76.3083134782755,1.8592406882176333,-1.9422076838131925
712.2000000000094,76.42677182362125,1.6584351306834273,-1.9566301378099982
713.4000000000094,76.54733619780329,1.5211618530608524,-1.970391396609338
714.6000000000095,76.66711396420396,1.3424027947841246,-1.9868520318241956
715.8000000000095,76.78705183448227,1.0681293714430282,-1.9982244374690463
717.0000000000094,76.90625146910334,0.6923099516337035,-2.010471995808082
718.2000000000095,77.02574496108656,0.3223674212407684,-2.0165343963846727
719.4000000000095,77.14556808306776,0.1037069957877425,-2.0206050934797473
720.6000000000095,77.26570727969293,0.03122091516684844,-2.0205500082904253
721.8000000000095,77.3864070074277,0.016428571722765073,-2.0205500033737094
723.0000000000095,77.50763966099666,0.01930475395707487,-2.021613349156888
724.2000000000096,77.62805056458288,0.022870901801199606,-2.0205505193225575
725.4000000000096,77.74976799357623,0.025884213054068295,-2.0205412872312154
726.6000000000096,77.8706215211758,0.025578398398134167,-2.021870001115211
727.8000000000096,77.99011006849949,0.03005879495708383,-2.0218699999999936
729.0000000000097,78.1110369171192,0.029124293100462467,-2.021869973734822
730.2000000000096,78.23271055619936,0.030256198666192724,-2.0205170402065225
731.4000000000096,78.35201726510407,0.03032681928823658,-2.021938520651685
732.6000000000097,78.4743895035625,0.03324398809634821,-2.0208800090099834
733.8000000000097,78.59439798726665,0.033103117955775585,-2.022189514670044
735.0000000000098,78.71586915311775,0.03477102814045441,-2.023186731884071
736.2000000000097,78.8375582220804,0.034499632632228855,-2.0218600007003023
737.4000000000098,78.95803107490515,0.033619919370967505,-2.020713834324832
738.6000000000098,79.07899175410694,0.03608931358364398,-2.023040423067221
739.8000000000097,79.20023721989556,0.03660406629042001,-2.0218700040068676
741.0000000000098,79.31975618071992,0.038249587457112405,-2.023198479645991
742.2000000000098,79.44054296198196,0.03907771320571071,-2.0218678701602
743.4000000000099,79.5609374720995,0.03910911873999531,-2.023190046766651
744.6000000000099,79.68154325502258,0.03914221376645746,-2.0232017952247707
745.8000000000098,79.80197256512578,0.04142416790731274,-2.0245140911105937
747.0000000000099,79.92244880162762,0.04098784580599829,-2.023190006494358
748.2000000000099,80.04192923117374,0.040951386405761764,-2.022530586985518
749.4000000000099,80.16364149017475,0.03943250988219538,-2.023840007029966
750.6000000000099,80.28335734079756,0.043343786847238025,-2.023836646707655
751.80000000001,80.40388314657925,0.0414672223451861,-2.0251599994114406
753.00000000001,80.52371866857683,0.04423926082633453,-2.0251599936715388
754.20000000001,80.64438094236768,0.03732669514522324,-2.026484052268951
755.40000000001,80.76508855695221,0.04193138107030572,-2.024463763435566
756.60000000001,80.88628275001975,0.038562350040096255,-2.024499999994979
757.8000000000101,81.00613592054992,0.039452313136749545,-2.0245000006504625
759.00000000001,81.12682588421866,0.03959516253229062,-2.025823077278308
760.20000000001,81.24663527647382,0.041790149917244085,-2.02450102296838
761.4000000000101,81.36749770079375,0.04184038790974076,-2.024475504682737
762.6000000000101,81.48818745157776,0.040199633953991176,-2.0269334097752223
763.8000000000102,81.60939547570999,0.03820471680656945,-2.025851850189407
765.0000000000101,81.73003498730799,0.039356764308404985,-2.0244788510977125
766.2000000000102,81.85072683899101,0.03900361469640187,-2.024825456987206
767.4000000000102,81.97189156542804,0.041192044842823544,-2.026149716289561
768.6000000000101,82.09159925632947,0.04466891640082207,-2.026150104671453
769.8000000000102,82.21349629857501,0.045969378412640594,-2.0274437751892753
771.0000000000102,82.33492975309444,0.049461873001848816,-2.0274608209244316
772.2000000000103,82.45588869769583,0.05261009466187602,-2.0274635245965253
773.4000000000103,82.5768997020698,0.05144171924823282,-2.0282434205532223
774.6000000000103,82.69799619280386,0.05128153201814162,-2.0278000019212126
775.8000000000103,82.81813876198214,0.05517183631027489,-2.027800000049982
777.0000000000103,82.9390070369058,0.05508013045219562,-2.0286360841043916
778.2000000000103,83.05906641531388,0.05943965494572617,-2.0287869874766993
779.4000000000103,83.18051875903804,0.06269753714542092,-2.028775807030788
780.6000000000104,83.30045767104158,0.06506941604504704,-2.0274666146677385
781.8000000000104,83.42008438087326,0.06984509577257092,-2.0287800036865997
783.0000000000105,83.54150166698112,0.07148004527462959,-2.0297619679463437
784.2000000000104,83.66142246299836,0.07677278774604145,-2.0294507827645494
785.4000000000104,83.7810897500928,0.08175377000443614,-2.0301000003842744
786.6000000000105,83.90093590970153,0.09224796783066641,-2.030123242959376
787.8000000000104,84.02146638590938,0.10118892087041056,-2.030100011334553
789.0000000000105,84.14150116679268,0.10980690330632503,-2.0301000067311756
790.2000000000105,84.2614197113346,0.1211368467751673,-2.030429982166657
791.4000000000106,84.3821180679849,0.1377609876719222,-2.0314218750607687
792.6000000000106,84.5023200986045,0.15211577113851593,-2.0301707201585426
793.8000000000105,84.62151262938566,0.1679873701314741,-2.0294440887716076
795.0000000000106,84.74173532240134,0.19054887445944838,-2.0300901734896026
796.2000000000106,84.86210386579853,0.21249645475361797,-2.030757079165447
797.0000000000106,84.94314509413495,0.22848114666305683,-2.0327171892884923