File: 01_Data/Laminate_Flooring/STA/N2/10K_min/Laminate_Flooring_STA_N2_10KData_221206_R3.csv
##Temp./Â°C,Time/min,DSC/(mW/mg),Mass loss/mg
51.1,10.624594975385458,0.05143535620083739,0.02270193560549849
52.30000000000002,11.071596884427764,0.06336021195894936,0.012278144939283031
53.500000000000036,11.346170631456618,0.0787809847402614,0.010239941549303744
54.70000000000005,11.572231741719891,0.08893212763738867,0.009036873837059645
55.90000000000007,11.769027931329969,0.09917399834587304,0.011417935465074969
57.10000000000009,11.95014235583217,0.10332566355542694,0.008885345680275769
58.300000000000104,12.12368493967175,0.1085040701113209,0.009087949583385324
59.50000000000012,12.291828625914144,0.11566478691378723,0.009278578089418232
60.70000000000014,12.451400057474721,0.11971740217409055,0.008065162787129765
61.900000000000155,12.606848074066328,0.1220948656219929,0.008739035992864075
63.10000000000017,12.760138029066923,0.1258384103796344,0.008809972286610623
64.30000000000018,12.909850332625792,0.12945272924287798,0.008852892871206386
65.5000000000002,13.056398440738029,0.13146607453721249,0.009663838163388228
66.70000000000022,13.202003824302581,0.13210956115747607,0.008926212503305386
67.90000000000023,13.345399459679253,0.1303331864315196,0.00853004193562601
69.10000000000025,13.485214702812964,0.1318777064976373,0.009034529050992113
70.30000000000027,13.624249513818194,0.13508974724648604,0.008930600149991363
71.50000000000028,13.7628025473079,0.13843599917480565,0.008899800320696372
72.7000000000003,13.898382680435548,0.1419637482139542,0.009545617511144577
73.90000000000032,14.03407925275635,0.14478834471937807,0.008909143163227107
75.10000000000034,14.166661375087054,0.14469938337150423,0.00886626381184108
76.30000000000035,14.299077570635589,0.15145715881276356,0.009795983990318113
77.50000000000037,14.43060267751783,0.15098805442129892,0.00888346411122587
78.70000000000039,14.561248283662323,0.15341147485589723,0.009018117261620162
79.9000000000004,14.6889356455287,0.15632191671500562,0.009899485851165402
81.10000000000042,14.820091974274835,0.16024632941929484,0.008934962876265828
82.30000000000044,14.946155309159614,0.16072393532644647,0.009000232018616217
83.50000000000045,15.074614956622282,0.1618873568155912,0.01030920324272877
84.70000000000047,15.19850481116911,0.1614961704069997,0.008999286496996994
85.90000000000049,15.325246750964991,0.16424688237887985,0.009452080094649595
87.1000000000005,15.449590535492941,0.16517573099383176,0.00899274083045043
88.30000000000052,15.573233126930253,0.1666206848698384,0.010406817530071777
89.50000000000054,15.696036846358329,0.16883765553133445,0.010312940049397312
90.70000000000056,15.818944030429897,0.1709003345245681,0.009590948121847909
91.90000000000057,15.941354685258032,0.170068341149485,0.010319023686890638
93.10000000000059,16.063316137169966,0.1713800088727011,0.010010465774822563
94.30000000000061,16.183103516923712,0.1723022552613933,0.008916164589316544
95.50000000000063,16.304350941801246,0.17646709794322257,0.008972360761054787
96.70000000000064,16.425611813144727,0.17572479331720414,0.009006153561082364
97.90000000000066,16.5453691856328,0.1797370637910518,0.008926281843768535
99.10000000000068,16.664874910357,0.1789776076317704,0.007737595918831275
100.3000000000007,16.78508590966451,0.18186689314970517,0.008997991064171096
101.50000000000071,16.903289504884253,0.18155509070844023,0.00900299969419649
102.70000000000073,17.021702354272417,0.183603912619565,0.007663166714277914
103.90000000000074,17.13811237680228,0.1849477011694003,0.008975739672081318
105.10000000000076,17.258888341942953,0.18671097687910598,0.007611410003226737
106.30000000000078,17.37742007454144,0.1868395245797878,0.00900332905370238
107.5000000000008,17.494946706363905,0.18776419727001437,0.009036087545127636
108.70000000000081,17.613060836686245,0.18808676059945717,0.008891807810033292
109.90000000000083,17.731337722255976,0.1886669470519785,0.007680422325865521
111.10000000000085,17.848674707630085,0.1907033579276426,0.007680498572303129
112.30000000000086,17.962833113173563,0.19337426059655072,0.009000785808042977
113.50000000000088,18.083312642209663,0.19232356923531524,0.008990020881489258
114.7000000000009,18.20064553051487,0.19211797739002168,0.008928996826597313
115.90000000000092,18.317669775484813,0.19386857855383233,0.008956764285393604
117.10000000000093,18.434306722758013,0.19432752978398737,0.009019544015288261
118.30000000000095,18.549269118413235,0.1951951152723127,0.009000158125923363
119.50000000000097,18.669803829411403,0.19461667222505996,0.009979807349054681
120.70000000000098,18.785829609489205,0.19533839476126857,0.008981860687961252
121.900000000001,18.902356303812336,0.19661297442335746,0.009000339849611905
123.10000000000102,19.018973194213938,0.19533874443330312,0.009001286884447346
124.30000000000103,19.13709359152825,0.19639104830150766,0.010312953719086693
125.50000000000105,19.252962106871824,0.19688185660501178,0.009001001052728164
126.70000000000107,19.369472973832526,0.20034874252024182,0.010319488125993814
127.90000000000109,19.484966546556212,0.19753903322355104,0.008990298896299542
129.1000000000011,19.599999245775948,0.19806839826640976,0.008996513966446074
130.30000000000112,19.71731475733794,0.19988341429929934,0.008999810575667233
131.50000000000114,19.832854906423332,0.19868044361778903,0.008483154542318516
132.70000000000115,19.949356800989005,0.19981076962090105,0.007672191745295542
133.90000000000117,20.064336216249217,0.20087400409791878,0.009553908342161854
135.1000000000012,20.179999027334585,0.20363382047273826,0.010970116349498404
136.3000000000012,20.293992289496373,0.20317562564447844,0.009644179355692728
137.50000000000122,20.410943441884694,0.2023825137574563,0.010964609467572828
138.70000000000124,20.524880756081465,0.20443289464217052,0.009655626657467664
139.90000000000126,20.639819447944713,0.204082596251147,0.010980048098108597
141.10000000000127,20.754491467488034,0.20500914760500077,0.009672128515910927
142.3000000000013,20.869339252114738,0.2059232090002484,0.010969817250794378
143.5000000000013,20.984857698445552,0.20514946001918155,0.010976271099141677
144.70000000000132,21.09935306096029,0.2054924714801487,0.010970009897680377
145.90000000000134,21.213968965895592,0.2051808482643661,0.010968781815469342
147.10000000000136,21.327445824528397,0.20727958717053319,0.012291974541621009
148.30000000000138,21.442539077048593,0.2068668811734563,0.010978676742843696
149.5000000000014,21.557003645772028,0.20887666670779403,0.010932244231195654
150.7000000000014,21.671290963962484,0.20683237149275902,0.010964954613959854
151.90000000000143,21.78574736964999,0.20821243660931565,0.010972729986503893
153.10000000000144,21.90030520177867,0.20860880188860564,0.012291016134175159
154.30000000000146,22.014663079779258,0.21168381538328063,0.013612879383048337
155.50000000000148,22.127862516454236,0.21185392461547048,0.012175675992827095
156.7000000000015,22.241089288134127,0.21215632927825923,0.01256398270093495
157.9000000000015,22.35654466956193,0.2134193810774485,0.01228919925563332
159.10000000000153,22.46970889630004,0.21415821381723854,0.010980074441099497
160.30000000000155,22.581890739603416,0.2137330667584496,0.012290396266712023
161.50000000000156,22.696989053041236,0.21397482899796194,0.011282133053700072
162.70000000000158,22.813918717510695,0.21320550200123378,0.012290738351392605
163.9000000000016,22.92667023898767,0.21323717842606493,0.012289262018294167
165.10000000000161,23.04009748317919,0.21494468005825573,0.010970391465747298
166.30000000000163,23.155142760530563,0.21513345555925845,0.01229126783034129
167.50000000000165,23.267406000798186,0.21660908316816063,0.01228571529214939
168.70000000000167,23.382242388058906,0.21381892828562832,0.01230159150856025
169.90000000000168,23.49596905446457,0.21668096559747085,0.01359988932890488
171.1000000000017,23.60961574017006,0.21509427517690605,0.012288528372693008
172.30000000000172,23.723611041529484,0.215362478631827,0.013609819355873576
173.50000000000173,23.837912271462308,0.21669118575566615,0.013612592530836132
174.70000000000175,23.951162668033895,0.21877704397098596,0.01229468435778891
175.90000000000177,24.062862262559914,0.21725358081258506,0.01098697775560531
177.10000000000178,24.17941903541862,0.2173268679641166,0.012290089139950666
178.3000000000018,24.288537675178382,0.2166001673962582,0.012300529488067369
179.50000000000182,24.404751578934242,0.21507294500940122,0.012289960011007572
180.70000000000184,24.520737941377437,0.21760774059598842,0.01228996092522916
181.90000000000185,24.634505307053015,0.21710979347970516,0.013661605737843807
183.10000000000187,24.74810452462116,0.216835219591622,0.011630448980749719
184.3000000000019,24.862674533333564,0.21699579781452105,0.011627087769595867
185.5000000000019,24.975741731645495,0.21734515935284626,0.011625090288299056
186.70000000000192,25.089900640280685,0.21851342603148616,0.010309845149319763
187.90000000000194,25.202887308131782,0.21902207165880894,0.01162949991941531
189.10000000000196,25.31701711887366,0.21670618133312547,0.010287214399053113
190.30000000000197,25.43194940862665,0.21856255038314387,0.01031852767207031
191.500000000002,25.54464303478248,0.21822792097919663,0.011313828778002133
192.700000000002,25.658910160694965,0.217915911734625,0.011942419910837998
193.90000000000202,25.772050916273603,0.2207556346815971,0.011172038960689079
195.10000000000204,25.88569403908062,0.2199974007964438,0.011251779308275367
196.30000000000206,26.001276598877954,0.21950101616737938,0.010861985996062806
197.50000000000207,26.114229764870068,0.2222007984463249,0.011356570962582246
198.7000000000021,26.227207482123436,0.22262071066074063,0.012619970003732384
199.9000000000021,26.34176486474193,0.22255463031126987,0.01262433454676426
201.10000000000213,26.455155091142714,0.22256399560143736,0.011291046804672966
202.30000000000214,26.56870760257035,0.22426196955149968,0.009333432000061315
203.50000000000216,26.68213426408131,0.22521911065899303,0.009319907680712447
204.70000000000218,26.79505534953595,0.22551480887313025,0.010647932123112547
205.9000000000022,26.90990421755153,0.22443068812003908,0.011299907245712504
207.1000000000022,27.023254507134,0.2244845554973972,0.010639989710269582
208.30000000000223,27.137027716142427,0.225351111399959,0.010971148631558236
209.50000000000225,27.250304053657107,0.2264235585603921,0.0106500479749716
210.70000000000226,27.36356137603794,0.22613969935232747,0.01064997842158899
211.90000000000228,27.47761934455833,0.22496697204453298,0.009330128859220466
213.1000000000023,27.59209571061756,0.22778434272893233,0.009330047982047063
214.3000000000023,27.70516439537621,0.22730717120291444,0.00925141804425511
215.50000000000233,27.81933769196294,0.22856472921453275,0.008008531307747369
216.70000000000235,27.932993183330336,0.22829652264202416,0.008694613736721202
217.90000000000236,28.04498200735143,0.22838734806850425,0.009330183913331958
219.10000000000238,28.160273952348,0.22818210209938738,0.00844540330961685
220.3000000000024,28.273632674976973,0.2278864958751473,0.008403662870250628
221.50000000000242,28.38707133281253,0.22841377001560148,0.00745325963219301
222.70000000000243,28.500176438775263,0.2255782849106689,0.007679843931759578
223.90000000000245,28.615189443616558,0.2269716921378998,0.005013777296071886
225.10000000000247,28.72873265251342,0.22876033173471721,0.00534760759881614
226.30000000000248,28.83962655375305,0.22833628014973784,0.006040183958942791
227.5000000000025,28.955363971773064,0.23135045218954553,0.006040183955367873
228.70000000000252,29.06918680714534,0.230842107324855,0.005952445864608968
229.90000000000254,29.18254431670389,0.23185033050002535,0.004720169353197079
231.10000000000255,29.296377222478235,0.23159958080874077,0.0037207111928800884
232.30000000000257,29.409271607316324,0.23446601817948232,0.0033999119056105087
233.5000000000026,29.52419258878519,0.23437925244831093,0.002110372415314643
234.7000000000026,29.635953009134386,0.23404572349207498,0.0018024460634675776
235.90000000000262,29.75107632524794,0.23520809817188548,0.0017498445372678972
237.10000000000264,29.864726741065198,0.23332558836154205,0.0007883287362018265
238.30000000000265,29.978181017201166,0.2338330244091148,-0.000890058663698845
239.50000000000267,30.093198149483182,0.23257380343813683,-0.002193653902978099
240.7000000000027,30.207089868970268,0.23043500148384877,-0.002209604306051993
241.9000000000027,30.320292528859,0.2320253840157276,-0.00352012127612511
243.10000000000272,30.43463983181328,0.23239902783631616,-0.00565121114518341
244.30000000000274,30.548951826515413,0.23382593171596844,-0.0061499245331004815
245.50000000000276,30.662724245266652,0.23375059276583232,-0.008339877313988886
246.70000000000277,30.776709891702605,0.23369449250981922,-0.008786095788656745
247.9000000000028,30.89160335908877,0.2329699276542897,-0.009780073182349192
249.1000000000028,31.00563466171802,0.23189315496047447,-0.012361472678331431
250.30000000000283,31.119809853343313,0.23285249418768572,-0.013729692076163147
251.50000000000284,31.232812438368057,0.23044823767793887,-0.015026170201198674
252.70000000000286,31.347353780649897,0.23057357585536253,-0.01711455980109644
253.90000000000288,31.46129607751007,0.23232623656313578,-0.01768075934155533
255.1000000000029,31.57555430648665,0.22928549939217246,-0.02042290812353187
256.3000000000029,31.68959144733486,0.22918672521456218,-0.02193596445202406
257.50000000000296,31.804140680178104,0.2271975183743169,-0.02420582342966071
258.70000000000294,31.9185238357297,0.22487804704109582,-0.025585333525627973
259.90000000000293,32.032934424603255,0.2225254179587084,-0.02807630842360176
261.100000000003,32.147435514319874,0.22291935229834225,-0.030806220223166036
262.300000000003,32.26065934889657,0.223729842505332,-0.03348953054372927
263.500000000003,32.3757993157133,0.23004008400863785,-0.035997370411746665
264.700000000003,32.48999895834849,0.2363023373365949,-0.039420078428944016
265.90000000000305,32.604879643256595,0.2415024108081112,-0.04275126638188098
267.1000000000031,32.71948550419121,0.24533017325714868,-0.04698922215349821
268.3000000000031,32.83435547404705,0.2507436871770764,-0.05026857224892467
269.50000000000307,32.94850199716497,0.25518411081654513,-0.05705072489877816
270.7000000000031,33.06313991699684,0.2607569421166185,-0.06338114687324525
271.90000000000316,33.1778805474089,0.2633593184912908,-0.07129925183050734
273.10000000000315,33.29289172430282,0.27030673961123663,-0.08099198246617245
274.30000000000314,33.40794303851589,0.274432933227881,-0.08952260634287468
275.5000000000032,33.520978880048084,0.2793266077543298,-0.10176354989943714
276.70000000000323,33.63570121303935,0.28289885014120186,-0.11403243682346265
277.9000000000032,33.751221150946456,0.2865208388789578,-0.1260421376616212
279.1000000000032,33.864967204290814,0.2917720622557658,-0.1410210570969319
280.30000000000325,33.979908160099626,0.2971134306119654,-0.1554382585038354
281.5000000000033,34.093436797854146,0.30399040301869523,-0.17001648634283395
282.7000000000033,34.2078615374114,0.312473360947066,-0.1861781898775745
283.9000000000033,34.32236992211104,0.32666946711149836,-0.20406490607447436
285.1000000000033,34.43514158912276,0.3412556676860427,-0.2198797325177413
286.30000000000337,34.55143504135233,0.3577922288633777,-0.2390549723729456
287.50000000000335,34.66644565005846,0.37561689963245704,-0.2566935009369189
288.70000000000334,34.78042900513523,0.3919957476283625,-0.27583040070388254
289.9000000000034,34.8953645370262,0.4062181025991345,-0.2945174788490057
291.10000000000343,35.0103697097314,0.4143359233234387,-0.31308191715692946
292.3000000000034,35.12548862203427,0.42240690826506,-0.33390638615307866
293.5000000000034,35.2400871516392,0.4277808888089919,-0.3519882867851347
294.70000000000346,35.353560442404955,0.430022509005014,-0.3683386808953122
295.9000000000035,35.469076514493665,0.42716139641690676,-0.38755430077612774
297.1000000000035,35.58369065776855,0.4240589736806551,-0.4045962357897608
298.3000000000035,35.69916300308707,0.41808967792517965,-0.4199757751496924
299.5000000000035,35.81437032181032,0.40941130346086396,-0.43634630265957197
300.70000000000357,35.92884565284021,0.4006516694002536,-0.45078824570611475
301.90000000000356,36.04343560163196,0.38721564456663704,-0.4633898042899167
303.10000000000355,36.158570484189376,0.3763253502847976,-0.4757349786705918
304.3000000000036,36.27355495768478,0.36427658007247277,-0.4880489134098127
305.50000000000364,36.38841612053708,0.3520757979876542,-0.4974899713940877
306.7000000000036,36.503117342788784,0.34045535371021823,-0.5095243954396307
307.9000000000037,36.61968586708226,0.32691869954444047,-0.51783613596991
309.10000000000366,36.7338306937886,0.3161113214344753,-0.5271840640227161
310.3000000000037,36.848833438684586,0.30523884599611795,-0.5358970874744688
311.5000000000037,36.96452475709916,0.29424300832288136,-0.5423024279745148
312.70000000000374,37.07990167299308,0.28456054154235116,-0.5508835513109944
313.90000000000373,37.19393013902698,0.2757513055346966,-0.557182002173159
315.1000000000038,37.30869927456922,0.26837964866166597,-0.5616609573639018
316.30000000000376,37.4242391029555,0.25829005819613443,-0.5687596237424288
317.5000000000038,37.538921736191256,0.2504286262196781,-0.5759614730623328
318.7000000000038,37.65449139526402,0.24236536570510264,-0.579702946237894
319.90000000000384,37.76979521368771,0.23181432431193755,-0.5843885573599463
321.10000000000383,37.88551202624539,0.22710212593695417,-0.590786794634834
322.3000000000039,37.999491299309646,0.21850318383272033,-0.5959744434411443
323.50000000000387,38.11442711956071,0.21201089042325938,-0.5992445154174275
324.7000000000039,38.228904437754515,0.20344725084289106,-0.6044242900375156
325.9000000000039,38.34378882575584,0.1953014645377925,-0.6082704254049327
327.10000000000394,38.461059450638395,0.18812802611745105,-0.6106555627655403
328.30000000000393,38.57564124328035,0.18374345249920876,-0.6124697306223919
329.500000000004,38.69142493683912,0.17547503155204391,-0.6151374359660169
330.70000000000397,38.80719264763221,0.17203725522964652,-0.6205225423363996
331.900000000004,38.92317001612587,0.16430371180820214,-0.6232966646788869
333.100000000004,39.03819912392641,0.15544305238905787,-0.6258966862325623
334.30000000000405,39.151294691290396,0.15428794290597392,-0.6259437207587424
335.50000000000404,39.269382011494685,0.14998031715271254,-0.630434926919694
336.7000000000041,39.38416528431805,0.1442139187293432,-0.632476439683693
337.90000000000407,39.50146563788952,0.13770205212379494,-0.6363934500563837
339.1000000000041,39.61701199267996,0.13478140941008865,-0.6377415131804112
340.3000000000041,39.730176042771106,0.13198336899971919,-0.6390613152410896
341.50000000000415,39.84765588274914,0.12861089313534646,-0.641686206588572
342.70000000000414,39.96408763398564,0.12499257035845623,-0.6426869262351795
343.9000000000042,40.08009363354729,0.12115871175296344,-0.6440030036237943
345.1000000000042,40.194847593569776,0.1187651435880015,-0.6453100264232923
346.3000000000042,40.31059356970479,0.117423378356873,-0.6459885123645619
347.5000000000042,40.426316293920756,0.11421242982294344,-0.6473750235726774
348.70000000000425,40.542959652914014,0.11316193257809559,-0.6486098537297278
349.90000000000424,40.659066079812625,0.11187696413288084,-0.6499199365360626
351.1000000000043,40.77384065957469,0.1112275442111792,-0.6512410348292414
352.3000000000043,40.890671595820216,0.11014676168866344,-0.6518998592196392
353.5000000000043,41.00590952159905,0.10992910977726966,-0.6545122993880392
354.7000000000043,41.12225793417534,0.10900070393893546,-0.6540707473480398
355.90000000000435,41.23954350922452,0.10823763123321373,-0.6545400859853423
357.10000000000434,41.35420791797619,0.10750193555963661,-0.6559015314707453
358.3000000000044,41.47018742049402,0.11081860586460324,-0.6571601999503285
359.5000000000044,41.58645948841023,0.10961266672484327,-0.6557891033774488
360.7000000000044,41.70299254959283,0.10848504518469848,-0.6558511778440193
361.9000000000044,41.81927770358612,0.10951186768645849,-0.6571635095846426
363.10000000000446,41.93546638871559,0.10943316630517563,-0.6584822525812886
364.30000000000445,42.050402073521504,0.11075939276458868,-0.6591724482752905
365.5000000000045,42.16493824159267,0.10829939866224048,-0.6597999360976221
366.7000000000045,42.28244537769797,0.11055281779454285,-0.6597999242861872
367.9000000000045,42.399316239975064,0.11196834554670876,-0.6611203147588811
369.1000000000045,42.51605711047372,0.11182087504402771,-0.6611198040003816
370.30000000000456,42.63009555881348,0.1121458591478045,-0.6611198039999988
371.50000000000455,42.74629271521058,0.11248798929116677,-0.6611198768773159
372.7000000000046,42.86291234474109,0.11309970886263276,-0.6624302224194167
373.9000000000046,42.97884005362943,0.11338683028717678,-0.6624306199279526
375.1000000000046,43.09463593986251,0.11191209538166746,-0.6637498579695902
376.3000000000046,43.21029445629975,0.11403517221497572,-0.6637619287774483
377.50000000000466,43.32707537196295,0.1128023565751548,-0.6645072190412793
378.70000000000465,43.44229343851975,0.11265290690926588,-0.6653376066354855
379.9000000000047,43.55894479841205,0.11330306737891205,-0.6660540950080032
381.1000000000047,43.67531991583118,0.11215376331281446,-0.6650639692066846
382.30000000000473,43.79180322175157,0.10990535249945776,-0.6663898153870429
383.5000000000047,43.90888895316084,0.11112575045505846,-0.6677001443755333
384.70000000000476,44.02567410531697,0.10922458007627645,-0.6677000406090161
385.90000000000475,44.14110650643864,0.10897700585426384,-0.6707579705042521
387.1000000000048,44.25821576327999,0.10914327636820842,-0.6721006288475047
388.3000000000048,44.37467026278443,0.10754368344770793,-0.673485239358691
389.50000000000483,44.49150981682629,0.10835878027940271,-0.6714400937592337
390.7000000000048,44.60764924175404,0.10801466281665872,-0.6720984615353589
391.90000000000487,44.724540056658995,0.106776514416286,-0.6727548144009265
393.10000000000485,44.840816623428346,0.11140545302967397,-0.6723804801397049
394.3000000000049,44.95874855003765,0.10839756182055782,-0.6727734369517133
395.5000000000049,45.073441882515624,0.10894158467145221,-0.6753902839732593
396.70000000000493,45.19089837674334,0.10943235226298398,-0.6764548210093229
397.9000000000049,45.30818962536079,0.10703388866437258,-0.6754100889419354
399.10000000000497,45.42398416189519,0.10823177418999985,-0.6767101390534536
400.30000000000496,45.54083546148329,0.10613825426502554,-0.677042374726093
401.500000000005,45.6576649483661,0.10484262609182904,-0.6769898314719835
402.700000000005,45.77359703962649,0.10491084154775343,-0.6783506930264274
403.90000000000504,45.89099955882618,0.10523033928837955,-0.6796817215015882
405.100000000005,46.00703226329724,0.10260046138869128,-0.6816542524553948
406.30000000000507,46.12523843695882,0.10346613785312941,-0.6816501076188386
407.50000000000506,46.242863097130076,0.10368709489350891,-0.6829701798308556
408.7000000000051,46.35939199672632,0.10278977410170276,-0.6842901360071818
409.9000000000051,46.47561923694654,0.1005849985970636,-0.685587495039623
411.10000000000514,46.59298788125465,0.09932015659031446,-0.6866470883156239
412.3000000000051,46.7104957895424,0.10082631742899806,-0.6866316330730471
413.5000000000052,46.826879754893824,0.09767745472684841,-0.6885983836646998
414.70000000000516,46.94443177052232,0.0986737138513295,-0.6887084344980687
415.9000000000052,47.06143942102559,0.09728817340538376,-0.6902079323915347
417.1000000000052,47.17826299539844,0.09863968865860506,-0.6928449903348848
418.30000000000524,47.29468327999276,0.09797528671077527,-0.6931338111524359
419.50000000000523,47.41221664891618,0.0974593152817077,-0.6955623303420797
420.7000000000053,47.5289807686823,0.09870463576385424,-0.696800239474288
421.90000000000526,47.64497942691183,0.09750230855751552,-0.6981238955077607
423.1000000000053,47.76230343154369,0.09786849018046018,-0.6986668318573859
424.3000000000053,47.87914688261617,0.09838308137413487,-0.7008235052533891
425.50000000000534,47.996103824923914,0.09853882959862303,-0.7034989696128604
426.70000000000533,48.11375401887135,0.09879408990599181,-0.703975403330495
427.9000000000054,48.231271935747465,0.10006969842867086,-0.7061273716660663
429.10000000000537,48.34808528827305,0.09945052310184876,-0.7087495091504952
430.3000000000054,48.464255414937405,0.09858995268891396,-0.7113722510258764
431.5000000000054,48.58178516140264,0.09748553047655217,-0.7135258008240069
432.70000000000545,48.698066152783035,0.0973873990511897,-0.7167103854804919
433.90000000000543,48.81555145478311,0.09911441293662127,-0.7194030248044236
435.1000000000055,48.9335213592991,0.10068760048755099,-0.7221333711956075
436.30000000000547,49.050435082363315,0.10113013900592965,-0.7248042267374841
437.5000000000055,49.16761962204146,0.10222076014685161,-0.7287746393846422
438.7000000000055,49.28558868047058,0.10489752528311674,-0.73261990992357
439.90000000000555,49.403702150147986,0.1043038843711298,-0.735760936781872
441.10000000000554,49.51930765965129,0.10606065131021059,-0.7398848554397923
442.3000000000056,49.637885875409864,0.11107744190875113,-0.7438328246025812
443.50000000000557,49.755817757955164,0.11190836277262228,-0.7481946594588549
444.7000000000056,49.87309275920792,0.11362001558759932,-0.7523509918446338
445.9000000000056,49.990822112124285,0.11584589792898276,-0.7564996659308241
447.10000000000565,50.10887746349036,0.11961489785012497,-0.762409244348536
448.30000000000564,50.2255553221116,0.12142518786329681,-0.766652816187511
449.5000000000057,50.343357944993926,0.12395858209012744,-0.7715011458851615
450.7000000000057,50.46143425297174,0.12837149971221334,-0.7762990034429618
451.9000000000057,50.57868983172199,0.13291440503799257,-0.7816072306878494
453.1000000000057,50.696044573887136,0.13779930806605722,-0.7879816166927811
454.30000000000575,50.8129588724381,0.14207004639395737,-0.795515066578965
455.50000000000574,50.930000000000526,0.1439818812512843,-0.8003198000041896
456.7000000000058,51.04532496150061,0.15278179704632572,-0.806287217847057
457.9000000000058,51.164579184351986,0.15693474648068506,-0.8132261448154705
459.1000000000058,51.280572637128394,0.16460292026017753,-0.8182811186300532
460.3000000000058,51.39777462064773,0.16787161972395592,-0.8248812108372583
461.50000000000585,51.513961002134494,0.17171865667937858,-0.8310543019141203
462.70000000000584,51.63167319462656,0.17432835598890983,-0.837404590281821
463.9000000000059,51.74908566895208,0.17964157280917503,-0.8432317990473472
465.1000000000059,51.86721183263369,0.1804925618138588,-0.8491207272210222
466.3000000000059,51.98468932873319,0.18414935143549765,-0.8539360944499195
467.5000000000059,52.10289009079207,0.18641887647340105,-0.8588714477770711
468.70000000000596,52.219907805020405,0.18709101391719307,-0.8672873671934047
469.90000000000595,52.33750336810911,0.18880870799989202,-0.8710270847826207
471.100000000006,52.455938461738,0.19039032760228297,-0.8750127579916125
472.300000000006,52.572874434091325,0.18791314826314215,-0.8806408670833155
473.500000000006,52.69097311962397,0.19048407955610852,-0.886768743140562
474.700000000006,52.807164284822136,0.19022805653696367,-0.891103211771902
475.90000000000606,52.92670587570673,0.19262524663020475,-0.8956628238011004
477.10000000000605,53.044270295775355,0.19364509594494705,-0.9004955886324737
478.3000000000061,53.16268697103794,0.19451044415348512,-0.9036399003552402
479.5000000000061,53.27979729421973,0.19657854183576517,-0.9094409431160431
480.7000000000061,53.397640738362185,0.1960899889274863,-0.91198440498257
481.9000000000061,53.51515237140604,0.197153420201496,-0.9163447245585159
483.10000000000616,53.63271926052636,0.19577553443486773,-0.920171596078053
484.30000000000615,53.75090562233442,0.19716525966634973,-0.9230410287942403
485.5000000000062,53.869135709214554,0.1995292647978859,-0.9270274517367656
486.7000000000062,53.98680208888012,0.19699065132780014,-0.9296496301658435
487.90000000000623,54.104190423614284,0.19725676444257456,-0.932271239804586
489.1000000000062,54.2224068355574,0.1987198233265126,-0.9348771028311598
490.30000000000626,54.3403108315983,0.1983460894380557,-0.9392001728066521
491.50000000000625,54.45822581523311,0.19740631120125668,-0.940737787952143
492.7000000000063,54.5763637679808,0.19941932510888843,-0.943168160560675
493.9000000000063,54.69446698357719,0.19655487552383316,-0.9457982283208879
495.10000000000633,54.81153245352369,0.19758439235200864,-0.9470851575941799
496.3000000000063,54.93075542356544,0.19695227881280936,-0.949402311176355
497.50000000000637,55.048811548339884,0.1976879053153599,-0.9520328031664125
498.70000000000636,55.16624960491788,0.19674042065585212,-0.9530312732398256
499.9000000000064,55.28523714145555,0.19690024016016455,-0.9536875363061275
501.1000000000064,55.403257223418066,0.1982519398904622,-0.9550841345232532
502.30000000000643,55.52196730639482,0.19712383991686744,-0.9566272513421237
503.5000000000064,55.640096359341754,0.1949956794343865,-0.9589679010317309
504.70000000000647,55.757836957731755,0.1943519524096189,-0.9597885673658233
505.90000000000646,55.87576136735617,0.1947170776140374,-0.9599510571799348
507.1000000000065,55.99502571415461,0.19289895280993757,-0.9612700900833087
508.3000000000065,56.11208619021911,0.19444134097426508,-0.9625803950220422
509.50000000000654,56.23086147790034,0.1936982838277404,-0.9624155604912121
510.7000000000065,56.34893861058494,0.19373694427681182,-0.9639456772412163
511.90000000000657,56.466365618106835,0.19279484832860522,-0.9652193883452922
513.1000000000065,56.584329620103716,0.189881554748212,-0.9652201793951258
514.3000000000065,56.70276812195813,0.1947135645430808,-0.9665450490078791
515.5000000000066,56.82199197176027,0.19180009480221455,-0.9665358412507277
516.7000000000066,56.93961501258559,0.19037849323816824,-0.9678466869596849
517.9000000000067,57.05886361942977,0.19140612650040623,-0.9691698415284749
519.1000000000067,57.17735873003066,0.19380908524049067,-0.970489958280532
520.3000000000067,57.2952974788513,0.19415132259695084,-0.970550886113148
521.5000000000067,57.41409003946673,0.19427721112106683,-0.9718001366328428
522.7000000000066,57.53292975468585,0.19995666531356215,-0.9731321970677049
523.9000000000067,57.65040065642118,0.20274974385715339,-0.9738656981267213
525.1000000000067,57.769170955234806,0.20864400118334642,-0.9718098871586514
526.3000000000068,57.88697358779814,0.2088696060606111,-0.9727391995867758
527.5000000000068,58.0058636875148,0.21337446204051275,-0.9757031931405935
528.7000000000069,58.12541944295585,0.21571612305562554,-0.9770701816906384
529.9000000000068,58.2449963340138,0.21749393298490916,-0.9783207385789594
531.1000000000068,58.362748816458485,0.22061648894811764,-0.9783603280956403
532.3000000000068,58.480602625653816,0.22542801944138208,-0.9796977452657814
533.5000000000068,58.599455044670826,0.2312658897870894,-0.9823300687799499
534.7000000000069,58.71853365067264,0.2343823756481842,-0.9813536284751438
535.9000000000069,58.83709361949315,0.24107364847449864,-0.982654120311441
537.100000000007,58.95424323533548,0.24638377171114131,-0.9838929268250451
538.300000000007,59.07398424850606,0.25194001762338153,-0.9839842749416614
539.5000000000069,59.191828047115344,0.2560295720925378,-0.9852999994722582
540.700000000007,59.30990121131407,0.262838177898823,-0.9856060419935169
541.9000000000069,59.429063365969704,0.2711264883214263,-0.9869605499494467
543.100000000007,59.547080810809064,0.2771308190011701,-0.9882799664115467
544.300000000007,59.66461365223675,0.28544133242238257,-0.9896077603989335
545.500000000007,59.784702387135056,0.29319053885222146,-0.9909869670219766
546.7000000000071,59.9039963331598,0.30323805740808674,-0.9922286147097266
547.9000000000071,60.02234481059124,0.31445842256307455,-0.9945157585685758
549.1000000000071,60.141697148071955,0.32821936887112557,-0.9945354456349689
550.3000000000071,60.26133040046523,0.3411079179200984,-0.9945325713027606
551.500000000007,60.37922362092029,0.35433444520505514,-0.9981605480910609
552.7000000000071,60.497952037023744,0.36882408746779105,-0.9995081626655375
553.9000000000071,60.61685952704333,0.3848823696211029,-1.0008141371068313
555.1000000000072,60.73632656454035,0.40043627180083063,-1.003416080429333
556.3000000000072,60.85427014254848,0.4142582845804362,-1.0060270708654917
557.5000000000073,60.97361872750732,0.4282504502514272,-1.0100933521201854
558.7000000000072,61.09200331747542,0.44192159553881444,-1.0107755681687616
559.9000000000073,61.20945423659587,0.45854824619263074,-1.0162207083277628
561.1000000000072,61.3308997387907,0.473461976679265,-1.0190682591879034
562.3000000000072,61.449392253865774,0.4905961028852917,-1.021639043298233
563.5000000000073,61.56746809429725,0.5060220649955259,-1.0256630863334624
564.7000000000073,61.688623243176615,0.5176074264634695,-1.02701562486565
565.9000000000074,61.80849926269292,0.5300837913768407,-1.032505964975174
567.1000000000073,61.92755085530249,0.5410078596809991,-1.0356510546055535
568.3000000000073,62.04724047334479,0.5410587759168973,-1.0400887586228125
569.5000000000074,62.16694975348338,0.5407779665488899,-1.0435641120862762
570.7000000000074,62.28686890610204,0.5308487373019969,-1.047523406394046
571.9000000000074,62.40665299927507,0.5017990482795642,-1.050983863257997
573.1000000000074,62.52470689487562,0.4441991397133994,-1.0551242356066197
574.3000000000075,62.64472401495474,0.3566856280068904,-1.0589222672569676
575.5000000000075,62.76294478412659,0.2790463581535689,-1.059369325151311
576.7000000000074,62.88045598945528,0.23060809830702259,-1.0609809844121183
577.9000000000075,63.001249959086095,0.20145217086032907,-1.061942248212473
579.1000000000075,63.120973102341786,0.18346760666008644,-1.0619399562127239
580.3000000000076,63.239503541769366,0.17186557248727224,-1.0619401639966255
581.5000000000075,63.35817034350883,0.1627039978437112,-1.0618610218018842
582.7000000000075,63.4784004187047,0.1567083806580823,-1.0655598438410125
583.9000000000076,63.59669819683341,0.15661257976977166,-1.065924907250368
585.1000000000076,63.715849589614905,0.15624592310370367,-1.0655600721080742
586.3000000000076,63.834741705106815,0.15603061267847268,-1.0666108599926512
587.5000000000076,63.95405047490682,0.15884586777372328,-1.0665579713456586
588.7000000000077,64.07389540925709,0.16246872467261064,-1.065890613587566
589.9000000000077,64.19265568194646,0.16969223124622496,-1.0672001180071988
591.1000000000076,64.31175630010429,0.17421815752323705,-1.067226693448521
592.3000000000077,64.43150556439159,0.1779038329490505,-1.068189979570088
593.5000000000077,64.55060945922905,0.18245965380484325,-1.0695520093796884
594.7000000000078,64.67010972957281,0.1876718704120781,-1.0695098481591656
595.9000000000077,64.78961154491623,0.1973792256635508,-1.070830012592105
597.1000000000078,64.9087785505791,0.2068462007454342,-1.0721399021797682
598.3000000000078,65.03000105769013,0.21357370226645744,-1.0725138080168333
599.5000000000078,65.14862033277201,0.22152729954747874,-1.0734712725633613
600.7000000000078,65.26949398570852,0.22867018655151167,-1.0747896731635684
601.9000000000078,65.38873833489433,0.2395887497694174,-1.0760939534970824
603.1000000000079,65.50834091801357,0.24735155725829167,-1.077739722021279
604.3000000000079,65.62910634735657,0.25465866652836,-1.0796296285746196
605.5000000000078,65.7472429515745,0.2654372397300194,-1.0801777350652784
606.7000000000079,65.86675414312188,0.2727830962480815,-1.0816910794100631
607.9000000000079,65.98640869204242,0.2803489660498537,-1.0830198203761645
609.100000000008,66.10642841104315,0.2879550996363518,-1.0845657577994459
610.3000000000079,66.22606784462498,0.2953747697155058,-1.085670911617242
611.500000000008,66.3456184547978,0.300936450799681,-1.086894425628052
612.700000000008,66.4644320701681,0.3101527558529565,-1.0895043804207032
613.900000000008,66.58384063631027,0.3157388773206073,-1.092340634326165
615.100000000008,66.70478327302133,0.3247808028153584,-1.0935476767680514
616.300000000008,66.82324457054325,0.33515494853798455,-1.0937958053687118
617.5000000000081,66.94306195538454,0.3407214893683981,-1.0965239971182532
618.7000000000081,67.06233970719981,0.35197298401020466,-1.099139060555994
619.900000000008,67.18192136001447,0.3652026310763113,-1.1004687567676341
621.1000000000081,67.30042219825847,0.3766697443917926,-1.1041252460409208
622.3000000000081,67.41863487541696,0.3920083055493539,-1.104408908024178
623.5000000000082,67.53839625987631,0.4055075112580046,-1.1084556748177907
624.7000000000081,67.65815914478652,0.4204625425226043,-1.1098103987919021
625.9000000000082,67.77640489549835,0.43578796627200184,-1.1111860996054292
627.1000000000082,67.89594527190818,0.4505760250417268,-1.1148206247638934
628.3000000000083,68.01516700745783,0.46955072009363213,-1.1181931863516752
629.5000000000082,68.13486010627057,0.4841507054928764,-1.1216139552299054
630.7000000000082,68.25365314487564,0.4984114809067712,-1.1243142675036144
631.9000000000083,68.374122168555,0.5214380252967682,-1.1272830028701497
633.1000000000083,68.49308130828818,0.538657598700646,-1.1309822072986604
634.3000000000083,68.61264042751294,0.5573325711749089,-1.133682136494445
635.5000000000083,68.73214453370514,0.5783106118511986,-1.1377375272333716
636.7000000000083,68.8519035074437,0.6000766969501411,-1.1406416851009427
637.9000000000084,68.97211013536662,0.6220684309513026,-1.1456456742768704
639.1000000000083,69.09033259783885,0.6436869562581782,-1.150319141836825
640.3000000000084,69.21040505905286,0.6691103779918259,-1.1546035323273576
641.5000000000084,69.32960667770081,0.6920284304035946,-1.158777603924853
642.7000000000085,69.44906153203783,0.7210811753432589,-1.1617972663817557
643.9000000000084,69.56878663952561,0.7446450740961266,-1.1674132373993293
645.1000000000084,69.6891727411537,0.773298987303524,-1.1727763622394405
646.3000000000085,69.80842458855874,0.8029865651773096,-1.1797058824335345
647.5000000000085,69.92786537753202,0.8300435499868553,-1.1844394528515325
648.7000000000085,70.04888945798463,0.8574012391783213,-1.1897450901578668
649.9000000000085,70.16707967405893,0.8891077638752647,-1.1951773064254363
651.1000000000085,70.28469155557511,0.9201751720136624,-1.2031738825367748
652.3000000000086,70.40702875022505,0.951946906819924,-1.2082371325720018
653.5000000000085,70.5269015069586,0.9871813048640266,-1.2163145444263588
654.7000000000086,70.64794907405029,1.0193168282911285,-1.2226565790238473
655.9000000000086,70.76939077482992,1.0515297305725668,-1.2296672305526237
657.1000000000087,70.88883618016317,1.088804632563106,-1.2362883284031354
658.3000000000086,71.00880534712026,1.1207233979175955,-1.2449646578655118
659.5000000000086,71.12949598784691,1.1583637990633653,-1.252696390802285
660.7000000000087,71.25042494166215,1.1956894422766284,-1.2620131380190243
661.9000000000087,71.3683230824905,1.2288171142654851,-1.2680088193659245
663.1000000000087,71.4904904838278,1.2695681065472413,-1.2776076422834044
664.3000000000087,71.61086280625905,1.3126487555186293,-1.287635126033296
665.5000000000088,71.73138869158856,1.3548414356782004,-1.296957445719829
666.7000000000088,71.84894248766429,1.395992471009284,-1.3064680309858305
667.9000000000087,71.97078804057048,1.4409765298159165,-1.3144153972650798
669.1000000000088,72.09087742127468,1.4916096785943345,-1.325668813712496
670.3000000000088,72.21137390496305,1.5372074858718396,-1.336749557778583
671.5000000000089,72.33147821637036,1.5863485189898605,-1.3466205423804856
672.7000000000088,72.45068441395325,1.6465553053269817,-1.3584246659766492
673.9000000000088,72.57108135289158,1.7069411132194752,-1.3699787014346194
675.1000000000089,72.690202298495,1.772015054321401,-1.3802205548934041
676.3000000000089,72.81046789733227,1.843983073261318,-1.3940826240869924
677.5000000000089,72.93148091129872,1.923363939088446,-1.407114477903738
678.7000000000089,73.05211680042679,2.0096903490365396,-1.4202653586878746
679.900000000009,73.1728218422218,2.1007316668761185,-1.4347200525822852
681.100000000009,73.29188757365277,2.19316395547458,-1.449990593707641
682.3000000000089,73.41250330500195,2.29911494645288,-1.4638362384057553
683.500000000009,73.53276850017734,2.4055577110098505,-1.4801730524560215
684.700000000009,73.65296453366808,2.5185694850036295,-1.4962503098717246
685.9000000000091,73.77435600142681,2.6316478254911986,-1.5135813214525053
687.100000000009,73.89491326755662,2.740893204960954,-1.5309211297188727
688.300000000009,74.01524381403576,2.8393237897941717,-1.5496909454847914
689.5000000000091,74.13678990743554,2.913874265789501,-1.5683158025983035
690.7000000000091,74.25746529971396,2.956124552710553,-1.5877077675105302
691.9000000000091,74.37849185002122,2.947224522109585,-1.6089515707521382
693.1000000000091,74.49591556573215,2.9148925650706623,-1.6296668662369984
694.3000000000092,74.61808827451098,2.8811904122333787,-1.6505837689377034
695.5000000000092,74.73842354846168,2.8652525671286813,-1.6723824646078849
696.7000000000091,74.8585189454391,2.8546917586202643,-1.6936365432911304
697.9000000000092,74.97926337387321,2.848089070063859,-1.715000087437442
699.1000000000092,75.09959302340116,2.8358476682874496,-1.7352404464963636
700.3000000000093,75.22021247732582,2.8119512587161717,-1.7580021752823436
701.5000000000092,75.34020746078895,2.775556136979668,-1.7791933643634699
702.7000000000093,75.460637416415,2.7163633880215667,-1.8015843822411495
703.9000000000093,75.57979294434946,2.6363563874634237,-1.8224790257361954
705.1000000000093,75.69882767146223,2.5158090910074957,-1.843139160458636
706.3000000000093,75.82100458417949,2.3624694480425763,-1.8622704308344602
707.5000000000093,75.94088736599939,2.19116731863485,-1.8815096486493528
708.7000000000094,76.06041613369278,2.0044570597088422,-1.8995544578411114
709.9000000000094,76.18073062211364,1.8088147722219046,-1.9142983019229978
711.1000000000093,76.30009915859493,1.673635679317686,-1.930335233854355
712.3000000000094,76.42087984534373,1.5250790001819665,-1.9441807750875113
713.5000000000094,76.54019302212997,1.2938959487478,-1.9586588525094322
714.7000000000095,76.66020278818696,0.9352152617052445,-1.9704156159742632
715.9000000000094,76.77841475950562,0.5282437283469823,-1.9794743785244608
717.1000000000095,76.89906173776237,0.20112078575679426,-1.9838018674829967
718.3000000000095,77.01858392920445,0.05690514904356614,-1.987206425840228
719.5000000000095,77.13989921435318,0.022960605007062762,-1.9877598723397658
720.7000000000095,77.26054395823549,0.016060143339819977,-1.9883980587740897
721.9000000000095,77.38218117510391,0.01919605081626008,-1.9870796613747563
723.1000000000096,77.49966690391302,0.019731994149609078,-1.9870798559999292
724.3000000000096,77.62195985559532,0.018906065248962434,-1.98707985869948
725.5000000000095,77.74236844259242,0.02202026093649212,-1.9883921204382222
726.7000000000096,77.86389195596102,0.022905014146215597,-1.987949635455125
727.9000000000096,77.98426067085998,0.02298431699494219,-1.9890659791327399
729.1000000000097,78.10443440672073,0.024478116756530277,-1.987369177319354
730.3000000000096,78.22557328859291,0.02477058242501612,-1.9883997785657757
731.5000000000097,78.34447331017162,0.026811708667120515,-1.9883494415655387
732.7000000000097,78.46540265342968,0.026641230983655284,-1.9885929043077843
733.9000000000098,78.58494249681634,0.0267866543280722,-1.9887301667682995
735.1000000000097,78.7071565156084,0.025100530721262226,-1.9900438843753268
736.3000000000097,78.82852396400936,0.025330382126261486,-1.9887301797062191
737.5000000000098,78.94861222221896,0.02536719926966957,-1.990053722469053
738.7000000000098,79.06880360857085,0.026916748903863363,-1.9887379167688417
739.9000000000098,79.19118306990913,0.027327716938980673,-1.9900398038126301
741.1000000000098,79.31138244863308,0.02867667473318536,-1.9900398040650416
742.3000000000098,79.43178386041964,0.028179105801254156,-1.9887505982301539
743.5000000000099,79.5510008687081,0.02808785021133431,-1.988437479140437
744.7000000000098,79.67439935916988,0.029138423025888982,-1.989380125090472
745.9000000000099,79.79532624403072,0.030664550163465365,-1.9896273498908044
747.1000000000099,79.91688108345124,0.028484248587102634,-1.990049943970308
748.30000000001,80.03763273820925,0.02666947689591459,-1.9900499440011323
749.5000000000099,80.15789496785432,0.026577450455785467,-1.9900587067800237
750.7000000000099,80.27870887080041,0.023907692489938792,-1.991361870905068
751.90000000001,80.39892738113092,0.026050452727617912,-1.9900401378336605
753.10000000001,80.51968665983813,0.02455102687966887,-1.990952143800084
754.30000000001,80.64021535326347,0.023308050383894552,-1.9903699159448442
755.50000000001,80.7609450658349,0.021817299783882915,-1.9903699160000006
756.70000000001,80.88164573613089,0.020283636117980564,-1.9903699160058292
757.9000000000101,81.0022092439656,0.020504271037525973,-1.9903104203563866
759.10000000001,81.12188807299506,0.02271217188175345,-1.9900376491289524
760.3000000000101,81.24283140952562,0.02241527047264688,-1.9913598510836907
761.5000000000101,81.36176887250372,0.018424315731393304,-1.991358498256469
762.7000000000102,81.48423310912031,0.01662989012364058,-1.9926800450066762
763.9000000000101,81.60491940707519,0.014521439381520895,-1.9908924615539565
765.1000000000101,81.72583503766471,0.019915276110168495,-1.9890311743362696
766.3000000000102,81.84534529354417,0.011970202625743054,-1.9907085701901175
767.5000000000102,81.96542219509973,0.013245830387682705,-1.990264806195888
768.7000000000102,82.08510193523455,0.015438487999874323,-1.9904124524025284
769.9000000000102,82.20507460435721,0.014709023598910409,-1.9906998917507392
771.1000000000103,82.3253236840492,0.012523863917945716,-1.990673359963476
772.3000000000103,82.44577926285774,0.016448589493092747,-1.9916890791018687
773.5000000000102,82.56528707419676,0.01893556376510236,-1.9920504140003334
774.7000000000103,82.68657956680504,0.021727235292226005,-1.9910475173381426
775.9000000000103,82.80492730375163,0.023406251665003985,-1.9910298933875201
777.1000000000104,82.92716866313503,0.021404369319812516,-1.992024836595244
778.3000000000103,83.04742293826493,0.02079210553732283,-1.9921758062813186
779.5000000000103,83.1690228348783,0.02242529981912822,-1.9933399680802837
780.7000000000104,83.28901089252784,0.020556117776533572,-1.9920543418236036
781.9000000000104,83.41065639052346,0.025701784087845236,-1.9933424188989255
783.1000000000104,83.53149652525738,0.024686222602166408,-1.9942946577773428
784.3000000000104,83.6521838542961,0.02900048710355857,-1.9946504426278682
785.5000000000105,83.7725459421666,0.03545924062846911,-1.9933416302044207
786.7000000000105,83.89251694888543,0.04233857407398639,-1.9933400080002417
787.9000000000104,84.0112618474795,0.047176080361226364,-1.9933400079999997
789.1000000000105,84.13436788099843,0.056287925318384724,-1.9933399925095192
790.3000000000105,84.25527696945055,0.06274476874422372,-1.9946590110788915
791.5000000000106,84.37646792971127,0.07890393494590289,-1.9933413878364918
792.7000000000105,84.49743678656276,0.09215617703949545,-1.9946572729030931
793.9000000000106,84.61802776786605,0.10705448390397271,-1.9953100243056805
795.1000000000106,84.73705420991625,0.12841119752419652,-1.9939886117138426
796.3000000000106,84.85868381688812,0.15232418683348103,-1.9946499153254185
797.0000000000106,84.92916830213414,0.16558157441157237,-1.9946499160000415