File: 01_Data/CPVC_Pipe/STA/N2/10K_min/CPVC_Pipe_STA_N2_10KData_221024_R3.csv
##Temp./Â°C,Time/min,DSC/(mW/mg),Mass loss/mg
51.0,10.68359894502658,0.002737269129726716,-0.019128844572287917
51.80000000000001,11.010367865372032,0.024313000727735457,-0.01622624936743744
52.60000000000002,11.22271953168834,0.04338821816882743,-0.016303424645849773
53.400000000000034,11.391643016048343,0.05536031933368868,-0.016873966654076256
54.200000000000045,11.547085424945884,0.06498326248877295,-0.016081743380184754
55.00000000000006,11.686718544639477,0.0735520299008412,-0.017037777835215095
55.80000000000007,11.814654498629151,0.08147660038403282,-0.01670081321930983
56.60000000000008,11.93838275328345,0.08544820874783277,-0.016274704446685995
57.40000000000009,12.0595494719208,0.09427223086098913,-0.015843866922055305
58.2000000000001,12.173604141999842,0.09902928500644537,-0.01665751214219835
59.000000000000114,12.28466964140155,0.10293190027286037,-0.018925822929205083
59.800000000000125,12.393811965639673,0.10539119036545253,-0.017489443138138938
60.600000000000136,12.49986151214199,0.10887967193037418,-0.017399137797709407
61.40000000000015,12.605023110527775,0.11337900222049102,-0.017259551958032304
62.20000000000016,12.70792235125155,0.11363923633951245,-0.01744275761031666
63.00000000000017,12.810681929390812,0.11737290666854494,-0.017466249998488337
63.80000000000018,12.91125437880084,0.1210742964295406,-0.01689318670864992
64.6000000000002,13.009100366555119,0.12213236015980256,-0.01706845301174109
65.4000000000002,13.107627307816264,0.12493219764381469,-0.017365811490616778
66.20000000000022,13.203717623690116,0.12824917193763596,-0.018595841349188014
67.00000000000023,13.30000000000003,0.12857623102372595,-0.01906566228516393
67.80000000000024,13.395598428259449,0.12993088201558867,-0.01873093912042023
68.60000000000025,13.489390118470983,0.13230695410132975,-0.017451866203018973
69.40000000000026,13.58265268459704,0.1343547611355469,-0.018659605725900974
70.20000000000027,13.674920599982888,0.13828471689595,-0.017746264553649027
71.00000000000028,13.767388736681713,0.13860320548554728,-0.018838278985356283
71.8000000000003,13.859777718746532,0.1406669068202382,-0.018562139750263107
72.6000000000003,13.948876789884196,0.1415227532939407,-0.018787704184208387
73.40000000000032,14.040544245368029,0.14506126502597638,-0.018706399135469454
74.20000000000033,14.129732458585767,0.1484256771193342,-0.019792780875005356
75.00000000000034,14.218942957084435,0.15113236419375098,-0.018781956972978797
75.80000000000035,14.307358727917853,0.1490791561832292,-0.018765724122820515
76.60000000000036,14.396046571774116,0.15043618761834132,-0.018914267589861034
77.40000000000038,14.482973099147761,0.14994686134710888,-0.02013682802968031
78.20000000000039,14.569009522256342,0.14698017004955544,-0.018809878918747636
79.0000000000004,14.658698426625527,0.1477917259961623,-0.01876000208894446
79.80000000000041,14.743421803437094,0.1457667455398317,-0.019069666845945576
80.60000000000042,14.828846143089642,0.14489475674029317,-0.019084451815368553
81.40000000000043,14.913659529944622,0.14697903127537448,-0.02007549665040287
82.20000000000044,15.001706061015193,0.146036899293585,-0.01975219932044414
83.00000000000045,15.086278276323311,0.1439646728272126,-0.01973431353863031
83.80000000000047,15.167699731512485,0.14642178766508573,-0.020030994127308688
84.60000000000048,15.255783422917895,0.14681572261049625,-0.020101786176791592
85.40000000000049,15.338850641664282,0.1478103976702454,-0.020137506625202306
86.2000000000005,15.422679835286452,0.14875585627305088,-0.02142748490513746
87.00000000000051,15.506249879662189,0.15146370183414426,-0.021455838994394405
87.80000000000052,15.589795566647314,0.15265494440672556,-0.021522790179580475
88.60000000000053,15.672821695546615,0.15311903028164742,-0.022712090773124416
89.40000000000055,15.754692400602025,0.15328432084390164,-0.022729120713010253
90.20000000000056,15.833848698409186,0.1542099939837167,-0.021755766235811436
91.00000000000057,15.919185438528281,0.15503190331159233,-0.021411968435154805
91.80000000000058,16.00027020026893,0.15522068645312204,-0.021411428503670393
92.60000000000059,16.082704966227887,0.15724802286356432,-0.021423182572922528
93.4000000000006,16.163295216322194,0.15756727241025692,-0.021430793511078683
94.20000000000061,16.244786272499404,0.16009269342252974,-0.021410847356563067
95.00000000000063,16.3264117214592,0.16034462227600466,-0.02145423667273949
95.80000000000064,16.40513396254228,0.16047527114848237,-0.02272897724630596
96.60000000000065,16.485612455389504,0.1619679083707225,-0.021410528721542477
97.40000000000066,16.567228158497016,0.1635236262572517,-0.021376198533704205
98.20000000000067,16.646409682255136,0.1639585053101824,-0.02140858892829023
99.00000000000068,16.72524554705825,0.16360474651692503,-0.022729941133952103
99.8000000000007,16.803876145553968,0.16586301045267426,-0.023000454031670614
100.6000000000007,16.88598709975297,0.16490354453684575,-0.022722786346975
101.40000000000072,16.964072183576775,0.1674497962094028,-0.022720033999719114
102.20000000000073,17.043715650462126,0.1681488216509207,-0.021869472259576028
103.00000000000074,17.122758834785174,0.16969392395018545,-0.021413098030158118
103.80000000000075,17.204934028906543,0.17199081200274502,-0.022508016014273657
104.60000000000076,17.27959195928264,0.1725699209722753,-0.022620839781058777
105.40000000000077,17.361781674276767,0.1741352506082412,-0.022667084381606806
106.20000000000078,17.43960167627207,0.17297414702984626,-0.02273005663325467
107.0000000000008,17.518449302046665,0.17405377663798494,-0.024038972902449274
107.80000000000081,17.597154959655935,0.1755877451318637,-0.02401410758406719
108.60000000000082,17.676385696844648,0.1744092932168737,-0.024050230107006243
109.40000000000083,17.755307744639467,0.17675673814951665,-0.024046338348559182
110.20000000000084,17.833510295431253,0.17817053255991933,-0.024049933560458925
111.00000000000085,17.91260854937224,0.1800071952799963,-0.022607137302822267
111.80000000000086,17.991177497383024,0.18016317645842816,-0.023980634607650764
112.60000000000088,18.06961211576821,0.1808800677819864,-0.024040310847698976
113.40000000000089,18.148363639475654,0.17994632429683421,-0.02306035310174437
114.2000000000009,18.22633222414218,0.18359020850617758,-0.024379139829315832
115.00000000000091,18.304571989234972,0.18346403616807638,-0.025378742392518916
115.80000000000092,18.382219286396662,0.18316111571742366,-0.023694373399135493
116.60000000000093,18.461005760826083,0.18493812791816733,-0.02527825553443286
117.40000000000094,18.539712326153783,0.18586694949856053,-0.025249901960193277
118.20000000000095,18.617898011008187,0.18722641214793478,-0.023941523193730774
119.00000000000097,18.695006176778186,0.18785194374704262,-0.023929818319316176
119.80000000000098,18.774291250681905,0.19075810483817968,-0.025216323692398568
120.60000000000099,18.848183258862683,0.19134132428686113,-0.023939644310467578
121.400000000001,18.92870649264125,0.19438593412959748,-0.025259416930777157
122.20000000000101,19.007310846051272,0.19632881461151375,-0.023956129027723705
123.00000000000102,19.084117003203936,0.19814081647576487,-0.025259926576603142
123.80000000000103,19.162105263657644,0.19929656380371674,-0.023779705116838912
124.60000000000105,19.24000000000011,0.2009442018961476,-0.024259830485904743
125.40000000000106,19.31761508545377,0.2015321495075849,-0.02500002713693661
126.20000000000107,19.393886728870086,0.2037859024688532,-0.02557374760886777
127.00000000000108,19.472493376334814,0.20508555403167472,-0.02640209132280802
127.80000000000109,19.547689718955983,0.2065372855239782,-0.02729820460452359
128.6000000000011,19.62560150620475,0.2082894646342479,-0.027470319873808435
129.4000000000011,19.703239458497375,0.2101214176296401,-0.024928549299952252
130.20000000000113,19.78000000000011,0.210074994577099,-0.025617603657045684
131.00000000000114,19.857971232574716,0.21073772448972794,-0.025620883964631247
131.80000000000115,19.93387502864028,0.2109056902658899,-0.025623594956180717
132.60000000000116,20.011720645260546,0.21268451142939793,-0.027636473609861767
133.40000000000117,20.088190082849316,0.21210476732367456,-0.026899542486500394
134.20000000000118,20.16435185444616,0.21228326503162864,-0.026954813072329387
135.0000000000012,20.24306553697928,0.2133638962811898,-0.02690794980688871
135.8000000000012,20.318929654230583,0.21256927984215224,-0.026910084036040338
136.60000000000122,20.396003106270147,0.2118306628998453,-0.02552406062678081
137.40000000000123,20.47332524089804,0.21189022794562606,-0.026884664528459723
138.20000000000124,20.54980578619823,0.2134853934595603,-0.02700906196164876
139.00000000000125,20.625797609033206,0.21201214506851873,-0.026899950089106284
139.80000000000126,20.70335327108153,0.21374052953063183,-0.026892642147354984
140.60000000000127,20.77951998524919,0.21291324328823436,-0.028219855359048474
141.40000000000128,20.85569033894947,0.21280423761098766,-0.026960185887980437
142.2000000000013,20.93182912333446,0.21339839248518278,-0.02817070120152465
143.0000000000013,21.009285526083353,0.21396833654637004,-0.02821873718467227
143.80000000000132,21.086165646706352,0.2164666671392138,-0.028230492683397834
144.60000000000133,21.160614318467214,0.21597747418821145,-0.029526553384410015
145.40000000000134,21.23839417146239,0.21696235257565333,-0.028262705783781428
146.20000000000135,21.314077010409946,0.21624267554207388,-0.028235392195810505
147.00000000000136,21.39028766244041,0.21781155000855912,-0.028201614308005496
147.80000000000138,21.466750774734408,0.21782868690891355,-0.02756008571263102
148.6000000000014,21.543053088921166,0.21846105076573163,-0.02918749089854611
149.4000000000014,21.619196001399573,0.21808455375989888,-0.028219610512763005
150.2000000000014,21.695170528198307,0.21908511669030284,-0.02824040039127329
151.00000000000142,21.7720406018966,0.21953332224243471,-0.02955793819872632
151.80000000000143,21.848678311502034,0.2196981117911826,-0.029529937199521683
152.60000000000144,21.92454072170501,0.21870073643067423,-0.029530148037135717
153.40000000000146,22.000595032033704,0.21999223788057543,-0.02953145662037482
154.20000000000147,22.076650656186228,0.21929031677029198,-0.029576927641183914
155.00000000000148,22.15319879218716,0.22049165865060705,-0.029540005657427315
155.8000000000015,22.22747852898034,0.22105941816066543,-0.03082726990707574
156.6000000000015,22.3046427497526,0.2191973893179977,-0.029895986286273768
157.4000000000015,22.380905024673364,0.2213840688824913,-0.031190233956982283
158.20000000000152,22.45665122507748,0.22369301731002522,-0.031190190998300338
159.00000000000153,22.532882665371897,0.2213473743501747,-0.031190197965490718
159.80000000000155,22.60960147574098,0.22037495147683073,-0.030868618972282214
160.60000000000156,22.685288042345256,0.22133394966806386,-0.03059516229500492
161.40000000000157,22.76184201318598,0.22142872301400252,-0.03170696549244223
162.20000000000158,22.83577167583816,0.22112423681559357,-0.032169811854654284
163.0000000000016,22.91283582690314,0.22155985473433626,-0.03212745090386093
163.8000000000016,22.98879273752953,0.22170976666554432,-0.030849777928598776
164.60000000000161,23.06398759542739,0.223210426870057,-0.03219592870926924
165.40000000000163,23.140096789536578,0.2232643889847995,-0.032169903663104016
166.20000000000164,23.21631642032526,0.22304706676215158,-0.03104626325744686
167.00000000000165,23.292239472866736,0.22448950408271073,-0.03217034857092216
167.80000000000166,23.368485530891114,0.2262545902267854,-0.03349070637987506
168.60000000000167,23.444679891582204,0.22496475933931948,-0.03349017889599981
169.40000000000168,23.520810365430513,0.22845363303273014,-0.03349017546341937
170.2000000000017,23.596230466615378,0.22795705802392974,-0.03270619731379831
171.0000000000017,23.670843806318793,0.22885991682726137,-0.032500060681369014
171.80000000000172,23.749095176243724,0.22905230935601784,-0.0338192544360032
172.60000000000173,23.823857810223057,0.22849649767595492,-0.03345633448206353
173.40000000000174,23.899788542844533,0.22996812676956802,-0.033490338082505566
174.20000000000175,23.977958893927504,0.22798205263245253,-0.033481197498778315
175.00000000000176,24.051776450504406,0.22813725113842354,-0.03425642720982314
175.80000000000177,24.129199863504663,0.22876919319117905,-0.03611987328993305
176.60000000000178,24.205232042014675,0.22877722363030661,-0.03611000655487917
177.4000000000018,24.27880843426179,0.22924993976759345,-0.034800936063838606
178.2000000000018,24.35749830799815,0.22733620801370558,-0.03611939357783189
179.00000000000182,24.432510960884606,0.22837039615457433,-0.0361199735822888
179.80000000000183,24.510319845528105,0.22861394296529214,-0.03612558742778482
180.60000000000184,24.5851315769439,0.22795381945636395,-0.038759971737857946
181.40000000000185,24.66180242079502,0.22986942118818943,-0.037620722625738345
182.20000000000186,24.738057579993963,0.22734050184088894,-0.03800261064693622
183.00000000000188,24.81369761476645,0.2299855167279493,-0.03842997658206748
183.8000000000019,24.89051176605668,0.23071158729939445,-0.03842995888290979
184.6000000000019,24.965438686671764,0.23134392179932772,-0.03729253206540051
185.4000000000019,25.042901066759093,0.23230396924125518,-0.03776951530649786
186.20000000000192,25.11804973909011,0.2309618331225921,-0.039079031876759984
187.00000000000193,25.194199181447235,0.23130763480217853,-0.039080139687875715
187.80000000000194,25.268824065960995,0.23003324039537731,-0.03936382060281929
188.60000000000196,25.34456158320997,0.23041246783262692,-0.04171903500433771
189.40000000000197,25.421415635248202,0.23081836924269583,-0.040362996625432856
190.20000000000198,25.49715383770157,0.23100770238270174,-0.04039994356055221
191.000000000002,25.57368677022213,0.23183591477595222,-0.041689036011914204
191.800000000002,25.648219371701842,0.22984734421596742,-0.04040987307860089
192.600000000002,25.724231858821334,0.23262248408190678,-0.0417053066000328
193.40000000000202,25.799544823924297,0.2315106227176893,-0.04172033567718447
194.20000000000203,25.875329706608323,0.2333105936051285,-0.04270502719676195
195.00000000000205,25.95138349179284,0.2329279516472974,-0.04300030435040014
195.80000000000206,26.026357293583267,0.23321608398924987,-0.044350232350827135
196.60000000000207,26.102432468013667,0.23390201640584163,-0.04435110614752613
197.40000000000208,26.178178598198084,0.23340290340475345,-0.04335701375601175
198.2000000000021,26.25509775528413,0.23375095222480513,-0.04336931716521519
199.0000000000021,26.329907729353,0.2335012126885555,-0.044359111653792915
199.80000000000211,26.40567775295455,0.23475121736803095,-0.044356343619284644
200.60000000000213,26.481707374175034,0.2305401142385236,-0.04560114070505783
201.40000000000214,26.558330770661986,0.23248734472981314,-0.047036046050220826
202.20000000000215,26.634427471238784,0.23212175650497502,-0.046340141568233406
203.00000000000216,26.708513314343254,0.23335158611077378,-0.046340167062629334
203.80000000000217,26.78539850148268,0.23300510684349274,-0.04633504912874109
204.60000000000218,26.86060814305279,0.2338926341069093,-0.047000586543955336
205.4000000000022,26.937466968669632,0.23235810782838273,-0.04700014595309998
206.2000000000022,27.013033894342566,0.23296331821750604,-0.04773771616912548
207.00000000000222,27.087910851243986,0.23167343713003952,-0.04766026536275003
207.80000000000223,27.16412387508472,0.23331552430329583,-0.048958611156742826
208.60000000000224,27.241310634339655,0.23188901068800039,-0.04897016665667753
209.40000000000225,27.315872438189963,0.23316992030814476,-0.04897016700169221
210.20000000000226,27.39121254468258,0.2350792900501828,-0.04897021151167902
211.00000000000227,27.46798726888841,0.233034797279703,-0.05024428500487055
211.80000000000229,27.54396927504006,0.2323459116514156,-0.050310938409327655
212.6000000000023,27.62070152322551,0.23209472098285544,-0.05160061334697641
213.4000000000023,27.69610329175618,0.23235213729105875,-0.05160694220576989
214.20000000000232,27.77087834985557,0.23312882160261772,-0.05160630578444714
215.00000000000233,27.846966406143565,0.23225969056380635,-0.05391256746249162
215.80000000000234,27.923667952096388,0.2324514105352371,-0.05259280777243003
216.60000000000235,27.999467673685977,0.23273000640092345,-0.053910631844825474
217.40000000000236,28.075283184159122,0.23249233439483308,-0.05424236337987409
218.20000000000238,28.150771789399236,0.23291847601229754,-0.054208665685500534
219.0000000000024,28.227585228686007,0.23245513459716582,-0.05522354313324929
219.8000000000024,28.303316245453214,0.23302875559288272,-0.056548730109518885
220.6000000000024,28.378914892735626,0.23316026594737138,-0.05687028609945699
221.40000000000242,28.45422782402789,0.23112493936282186,-0.05719711997603749
222.20000000000243,28.531008317235592,0.23425927366490096,-0.05918340807529354
223.00000000000244,28.60614962963508,0.23179709119941416,-0.05917754573565137
223.80000000000246,28.682111067888243,0.2342833464029892,-0.05951064392152361
224.60000000000247,28.75769361925175,0.2349948945767768,-0.06050246112639801
225.40000000000248,28.83344627624553,0.23452532350470223,-0.06182013772952999
226.2000000000025,28.909348047513774,0.23441574694422695,-0.06181986594156896
227.0000000000025,28.985724543927496,0.23581743800020927,-0.06214175517413523
227.8000000000025,29.060679102536675,0.23415734310248837,-0.06253400260105657
228.60000000000252,29.13418970805666,0.2356692707694994,-0.06345996007966637
229.40000000000254,29.210505298956257,0.23678349995070502,-0.0647771247295541
230.20000000000255,29.288235837002485,0.23637534940118998,-0.06530854888477755
231.00000000000256,29.36478952680527,0.2372808254647717,-0.06741990705171208
231.80000000000257,29.440669021088215,0.23640844759376378,-0.06744448441512585
232.60000000000258,29.516049865523478,0.23554215553994562,-0.06872732037332874
233.4000000000026,29.592320173549673,0.23600024856049784,-0.07005030728249029
234.2000000000026,29.66832899001934,0.2369093671746414,-0.0709152154271031
235.00000000000261,29.74455078261034,0.23699934522883936,-0.07196060518163039
235.80000000000263,29.820500450094432,0.23678546964742375,-0.07399477599523019
236.60000000000264,29.895681073542235,0.23849396144942148,-0.075308900927606
237.40000000000265,29.971319781085132,0.2385547224514888,-0.0765708852223379
238.20000000000266,30.047793442769667,0.23835611890106534,-0.07795061247712809
239.00000000000267,30.12294491231424,0.23817626745954484,-0.07927326171141402
239.80000000000268,30.19918875778224,0.23846000381554577,-0.08059269076656594
240.6000000000027,30.27485265142577,0.23824484963064319,-0.08190024609591884
241.4000000000027,30.351219562532943,0.2385772142446409,-0.08451178599462272
242.20000000000272,30.42798282958305,0.23915959904443201,-0.08634529023000281
243.00000000000273,30.502647774421657,0.23926841029014562,-0.08855385119835013
243.80000000000274,30.579467972391054,0.23855186057748085,-0.0898172468244236
244.60000000000275,30.65559592207536,0.23789396612563207,-0.09168288758152432
245.40000000000276,30.731684334062177,0.23611204175818107,-0.09486705261426831
246.20000000000277,30.80818761162733,0.2360593727714138,-0.09635160448984559
247.00000000000279,30.883385262266337,0.2346487637123612,-0.09771879306215636
247.8000000000028,30.957075155785404,0.2348674012681517,-0.1002473048783572
248.6000000000028,31.036805204685734,0.2327136458238564,-0.101720848123243
249.40000000000282,31.11319160098042,0.2342697344982937,-0.1030901754675062
250.20000000000283,31.188999774954063,0.2323656176896357,-0.10562749687196638
251.00000000000284,31.26480210924323,0.23503607969892432,-0.10624729620176243
251.80000000000285,31.341240132762728,0.238924740198455,-0.10842983657854699
252.60000000000286,31.41663556262528,0.24121822478486865,-0.11033164261312578
253.40000000000288,31.493734016339957,0.24581059137282457,-0.11293741453178185
254.2000000000029,31.57110948337382,0.2511059054326272,-0.1142988069456008
255.0000000000029,31.645913905685482,0.2538110048073295,-0.11622141134407604
255.8000000000029,31.722830147971735,0.2565620610397984,-0.11849397087404645
256.6000000000029,31.79835144496154,0.25959581768538864,-0.12023379366573916
257.40000000000293,31.875279254865106,0.26151119239675935,-0.12048931438903088
258.20000000000294,31.951694651040555,0.2649017330910376,-0.12286639092102902
259.00000000000296,32.02789641896624,0.26597460293182423,-0.12532657831422123
259.80000000000297,32.103888722428074,0.26769347742609007,-0.12740700197896304
260.600000000003,32.18094472409451,0.27107314826062445,-0.12943895221454138
261.400000000003,32.257295010022446,0.27506146887648925,-0.1318536446499503
262.200000000003,32.33325937771254,0.2744031577809589,-0.13458538526278696
263.000000000003,32.407367091906714,0.27840941180854273,-0.13635932134881923
263.800000000003,32.484122367537175,0.2817061231464364,-0.13846803854785383
264.60000000000304,32.562085360697516,0.2864559255498399,-0.14138508610813494
265.40000000000305,32.63560708285782,0.2868224773797839,-0.1445065183008154
266.20000000000306,32.713940448855176,0.2918436651377976,-0.1472411079824223
267.00000000000307,32.79085936344242,0.2957235592076219,-0.15180776997118706
267.8000000000031,32.86622284717607,0.298368788834966,-0.1555038601562746
268.6000000000031,32.94268437073729,0.3029414131966356,-0.15881282370268357
269.4000000000031,33.0199054023125,0.30790811535633916,-0.16335155401658996
270.2000000000031,33.09512375189413,0.31128137278196827,-0.1661687703990804
271.0000000000031,33.1721116865447,0.31387838176086186,-0.16973875223132584
271.80000000000314,33.24822236326615,0.318404459483539,-0.17428047083603815
272.60000000000315,33.326771342902376,0.3238724471490842,-0.18039365145226016
273.40000000000316,33.40192171823024,0.32529809107625357,-0.18559441610192273
274.2000000000032,33.47891814745369,0.3297275841621832,-0.19029692547978838
275.0000000000032,33.55486585680024,0.33442501981227396,-0.19610349302289887
275.8000000000032,33.62974218851961,0.3375453844552913,-0.20146004566589149
276.6000000000032,33.707548638803345,0.34082161180564013,-0.20667831321788777
277.4000000000032,33.78460537842926,0.3452788839027303,-0.21435741041523748
278.20000000000323,33.86172411200485,0.3514853062956137,-0.2210560017571317
279.00000000000324,33.93721481004229,0.35465937515399576,-0.2287972442530517
279.80000000000325,34.014111546842095,0.3594551003339021,-0.23698471182318048
280.60000000000326,34.090093620277216,0.3643591100363268,-0.24515895648472208
281.4000000000033,34.16795199601941,0.3695321177478039,-0.25402859222177465
282.2000000000033,34.24399786858795,0.37347609086268824,-0.2634765840567912
283.0000000000033,34.31989791286132,0.3777049635794907,-0.27432113471355013
283.8000000000033,34.396233138806515,0.38193418797547657,-0.2850042049956345
284.6000000000033,34.4729592350405,0.38841196038625414,-0.29485864710301257
285.40000000000333,34.54909682799481,0.39324933097981035,-0.30690437374351287
286.20000000000334,34.62647321742862,0.39768435632161403,-0.3201010822854591
287.00000000000335,34.70170887992445,0.4025571333860591,-0.332290838296736
287.80000000000337,34.77952720506577,0.40668130846954686,-0.34682987858163106
288.6000000000034,34.85493771721638,0.40945079986570243,-0.3617005391592083
289.4000000000034,34.93163861163526,0.41360353536770245,-0.37514768386006736
290.2000000000034,35.00822526149841,0.4167003984071262,-0.3917481155620832
291.0000000000034,35.0831833315807,0.4212640974173914,-0.4082840021738203
291.8000000000034,35.161043108365604,0.4249617156672979,-0.4261511902001338
292.60000000000343,35.23685179713906,0.42672917443767544,-0.4440105353091308
293.40000000000344,35.31314220794404,0.4291105927175983,-0.46336529140229965
294.20000000000346,35.39105481781515,0.43116873828656,-0.48398958948048776
295.00000000000347,35.46671409325996,0.4318842538762977,-0.5060302063408537
295.8000000000035,35.5426185662537,0.4329877418417555,-0.5287923797844307
296.6000000000035,35.61848918249583,0.43487164120996974,-0.5518219194937202
297.4000000000035,35.69533733483765,0.4349915858068955,-0.5766716047379012
298.2000000000035,35.77249052725162,0.435350590932954,-0.60173101955036
299.0000000000035,35.84917613422979,0.43566104866456146,-0.6280480411512968
299.80000000000354,35.92558548205095,0.43511950332316224,-0.6549542982643652
300.60000000000355,36.00107672509983,0.4329350370597913,-0.6846579270294364
301.40000000000356,36.07779243227014,0.4304875186369994,-0.7136104566286052
302.20000000000357,36.15425722727879,0.42912811524675387,-0.7449224120889908
303.0000000000036,36.230677866076626,0.42664448600661237,-0.7774689560124783
303.8000000000036,36.30831833306892,0.4207010949380121,-0.8124954605118573
304.6000000000036,36.38453337933466,0.41572030324250286,-0.8456545842937775
305.4000000000036,36.46134702587199,0.4125322626545767,-0.882848396024674
306.2000000000036,36.53780968009147,0.4074836875476735,-0.9196849976414283
307.00000000000364,36.614283714281015,0.4020193284092911,-0.9577536994378928
307.80000000000365,36.69164675194705,0.39532005855660574,-0.9982995573391937
308.60000000000366,36.76771681110215,0.38729961907986316,-1.0382276031478161
309.4000000000037,36.84501141175641,0.3790867600811648,-1.0805576034284932
310.2000000000037,36.92154780752721,0.37257879624068,-1.1230881784049584
311.0000000000037,36.99904790089857,0.36555126034444674,-1.1663802047559653
311.8000000000037,37.07441232347162,0.3565492115012387,-1.209714576305215
312.6000000000037,37.151362824363495,0.34883949303891515,-1.2537459051145272
313.40000000000373,37.227595350857236,0.3380345682248744,-1.2988775915722335
314.20000000000374,37.30586887374878,0.32712849216925893,-1.3452377183110258
315.00000000000375,37.38120966100929,0.3175833024019175,-1.3907911801033173
315.80000000000376,37.45930393864443,0.3069161825105769,-1.4393596531698782
316.6000000000038,37.53579655483305,0.2975248287452385,-1.4890508575210628
317.4000000000038,37.61197077271167,0.2873970164985916,-1.5349285516377855
318.2000000000038,37.688843686965214,0.27485840537158146,-1.5824372909017579
319.0000000000038,37.76534119450934,0.26300536722336976,-1.6286467544650014
319.8000000000038,37.84212595875676,0.25082645050297037,-1.673491431852277
320.60000000000383,37.91816686627398,0.23793732682890006,-1.7170811812942537
321.40000000000384,37.995301549904454,0.2269251379276339,-1.760991373306569
322.20000000000385,38.071949306521944,0.21592181093471607,-1.8044703788061303
323.00000000000387,38.148810118832145,0.20565797974485028,-1.8447427777589547
323.8000000000039,38.22449772109111,0.19508931557063391,-1.8833202054976077
324.6000000000039,38.302201008145595,0.18724380169118998,-1.9204264537440108
325.4000000000039,38.37658334854225,0.17529742652662272,-1.9544861931920456
326.2000000000039,38.45440908496815,0.16711017809667095,-1.9889212880961624
327.0000000000039,38.532025816950316,0.15788694166869055,-2.019932432272933
327.80000000000393,38.609004886116,0.15069680434010335,-2.050042458789867
328.60000000000394,38.6856134203844,0.1447261879537462,-2.077835593817549
329.40000000000396,38.76265381651364,0.1358930990664493,-2.1034054707646965
330.20000000000397,38.84037408019677,0.13032074898670376,-2.127621988076844
331.000000000004,38.91643541574374,0.1253938101226202,-2.1495837563471607
331.800000000004,38.9931091025385,0.11911568337891953,-2.170839063672408
332.600000000004,39.070569120863674,0.11453396701872887,-2.1902073058034848
333.400000000004,39.14732281133014,0.11338032497622641,-2.2085968045714415
334.200000000004,39.22347335373413,0.10893253860738994,-2.2263854596660337
335.00000000000404,39.30220723460835,0.10626321392769,-2.2442196026154764
335.80000000000405,39.378234044438365,0.10203360190812327,-2.2589674126981865
336.60000000000406,39.455492356836714,0.09910260154731554,-2.2737501204040376
337.40000000000407,39.53191939692403,0.09379623319585328,-2.28741276211324
338.2000000000041,39.609090452381785,0.0895208139092658,-2.3018755542700715
339.0000000000041,39.68647709932542,0.0871848121043104,-2.313507302950956
339.8000000000041,39.76353176206686,0.08315331135333326,-2.3263486773940336
340.6000000000041,39.840390719545496,0.07896052326266789,-2.337753596985169
341.4000000000041,39.91776727631031,0.07359539062110132,-2.3473331891153375
342.20000000000414,39.994812215699774,0.07111534516259144,-2.358042785069236
343.00000000000415,40.07209046948302,0.0672768739022932,-2.368684495138233
343.80000000000416,40.14683632043321,0.06042807155070584,-2.377148267663144
344.6000000000042,40.226971213231494,0.058045112805270915,-2.3857549155666815
345.4000000000042,40.304267568372474,0.0524636403546882,-2.3952356582470724
346.2000000000042,40.381450836129474,0.05027974154003412,-2.4030574527193345
347.0000000000042,40.458790395446265,0.046003500077580806,-2.410952728279659
347.8000000000042,40.536008974865744,0.04269049643852918,-2.4185444133775933
348.60000000000423,40.61445990982402,0.03969389438276172,-2.4251151018672092
349.40000000000424,40.69195378059024,0.03598116642942917,-2.433157005184987
350.20000000000425,40.76663118494991,0.03238331393124749,-2.4385771242832153
351.00000000000426,40.84607714567488,0.02988358335174579,-2.44458629387388
351.8000000000043,40.92365681313278,0.029053028040629703,-2.45050491301639
352.6000000000043,41.00177030692632,0.02390574899235587,-2.4566315623121318
353.4000000000043,41.07981378670825,0.021952615787599883,-2.460998130811453
354.2000000000043,41.15615426154215,0.020982521884709837,-2.4659379709290468
355.0000000000043,41.23363117908773,0.0171825414365695,-2.4722203991992817
355.80000000000433,41.311806293241574,0.015737940717512444,-2.4765914448485553
356.60000000000434,41.38946970941085,0.013031420809598182,-2.4813808469704286
357.40000000000435,41.46694123819119,0.010318364357024712,-2.4860197805596784
358.20000000000437,41.54488977642875,0.01048094600161631,-2.489657150140605
359.0000000000044,41.62193166497981,0.008725442028346686,-2.4940596074690022
359.8000000000044,41.69969155606713,0.007497371069602243,-2.497428562405274
360.6000000000044,41.77625577394794,0.006990186037685975,-2.501668509892828
361.4000000000044,41.855208750636386,0.005653413378493344,-2.506696784178472
362.2000000000044,41.93247881743082,0.0046153455592917725,-2.509349249761614
363.00000000000443,42.009898652186,0.0040024804875880005,-2.5130399677778814
363.80000000000445,42.086122381224484,0.002752955006193214,-2.515260562364862
364.60000000000446,42.16449850909728,0.0031690302026374795,-2.518424527446801
365.40000000000447,42.24181029500999,0.0042724737228425624,-2.5230019572923017
366.2000000000045,42.31999900388774,0.003639317121557517,-2.524579845277767
367.0000000000045,42.39696776753812,0.0019015340091306232,-2.5269571194587286
367.8000000000045,42.47412544185941,0.0014447258832367416,-2.5298555629741886
368.6000000000045,42.55228674604781,0.0029364130263926924,-2.5326651042339448
369.4000000000045,42.62953809301203,0.0019489045359972756,-2.5361085364832734
370.20000000000454,42.70705724608264,0.0030816615350111043,-2.5375572959113395
371.00000000000455,42.78465991246788,0.002864981284137924,-2.5401796239106753
371.80000000000456,42.86239494951706,0.0017867699380629265,-2.5425959488873744
372.60000000000457,42.93980856827124,0.005489508859774395,-2.545215255293817
373.4000000000046,43.01757773239893,0.004281615279520867,-2.547291267949248
374.2000000000046,43.0955023572841,0.0038488816177248975,-2.549945657916343
375.0000000000046,43.172883516214974,0.0017483830991729121,-2.5513870881350194
375.8000000000046,43.24990761938262,0.0033861215918573606,-2.5534425191549825
376.6000000000046,43.327472874905695,0.0028513315686711227,-2.5559568594549473
377.40000000000464,43.40628621612648,0.00436516764824213,-2.5578110722143697
378.20000000000465,43.48311810483027,0.0017491229895991722,-2.5594123271765765
379.00000000000466,43.5617672374446,0.0015169486816956068,-2.5619142220678186
379.8000000000047,43.6386332634632,0.0008485774320373674,-2.5647732445298237
380.6000000000047,43.71606198317658,0.0026774136297755824,-2.56611301629275
381.4000000000047,43.79394236233011,0.0015077665286411523,-2.5684925372270113
382.2000000000047,43.87143458413732,0.00351028391319419,-2.5692808427920157
383.0000000000047,43.94901592768022,0.0024277900551009646,-2.571423562131903
383.80000000000473,44.02768315879602,0.0016152638974878952,-2.574073055590614
384.60000000000474,44.10290812855606,0.0016991637668247739,-2.575391147238843
385.40000000000475,44.18207820821628,0.0005018859117087437,-2.5781827193557003
386.20000000000476,44.2613182609199,0.000341365445459485,-2.5789176109259735
387.0000000000048,44.33866778561085,0.0021204993189393173,-2.580790095595532
387.8000000000048,44.41594908346141,6.256892055755969e-05,-2.5821366946384394
388.6000000000048,44.49376579681359,-0.00179747842642064,-2.5847562027534945
389.4000000000048,44.572136436746945,-0.003360775832298768,-2.5855609527519885
390.2000000000048,44.64869386845925,-0.0014086903052875632,-2.5873799833200373
391.00000000000483,44.72554455075849,-0.003365794383910381,-2.590287927967148
391.80000000000484,44.804435881416936,-0.0041933934122840855,-2.5919768576366193
392.60000000000485,44.88173121924295,-0.005036320801203864,-2.5919920821220885
393.40000000000487,44.95950617296399,-0.004898959007130221,-2.593299038828116
394.2000000000049,45.03652288946619,-0.006716396243800937,-2.597356522366487
395.0000000000049,45.114175045082575,-0.007279090806961319,-2.6000314555008743
395.8000000000049,45.191933694902815,-0.006632663305979558,-2.6002478468709134
396.6000000000049,45.26981938547922,-0.007769040672802818,-2.6024049077629874
397.4000000000049,45.34745102168724,-0.008196229136970268,-2.6040435556240085
398.20000000000493,45.4231764482342,-0.009012669091097436,-2.6054519978711377
399.00000000000495,45.50352481788355,-0.01111585268221249,-2.6082609418139233
399.80000000000496,45.58130749909231,-0.010988079779599036,-2.6095577332219593
400.60000000000497,45.65913447117356,-0.012133588332061573,-2.612133032195531
401.400000000005,45.7360462796277,-0.012322175953535464,-2.6133254655955653
402.200000000005,45.812841725379315,-0.01298444669832477,-2.6147995236358423
403.000000000005,45.89262505392278,-0.014391878983128215,-2.6174697009041497
403.800000000005,45.97019336531624,-0.017278890534175417,-2.6177899293223046
404.600000000005,46.0484861261204,-0.017021391388531093,-2.619089496475685
405.40000000000504,46.12688452141355,-0.017041726495444665,-2.620421072046611
406.20000000000505,46.204405242611244,-0.018531157276930776,-2.6232184456938974
407.00000000000506,46.282494341932654,-0.020725082564256314,-2.624144713461064
407.80000000000507,46.36084530289078,-0.02046477955224313,-2.625963253804914
408.6000000000051,46.43757509304956,-0.01894053657869843,-2.6272229809170935
409.4000000000051,46.51609539389739,-0.02079422182210655,-2.628547638687156
410.2000000000051,46.59444232319953,-0.02183925398920783,-2.6308399731800605
411.0000000000051,46.67205188407778,-0.022856237727428175,-2.6330577854605117
411.8000000000051,46.74963121278076,-0.02073861307968483,-2.6331502711562416
412.60000000000514,46.828575618520325,-0.02108518072710419,-2.6347025925042518
413.40000000000515,46.90628500135683,-0.02258671082090591,-2.6362146618440603
414.20000000000516,46.98506374973553,-0.023366155169261105,-2.637885356869891
415.0000000000052,47.06308897502726,-0.02376725671956037,-2.638756353593494
415.8000000000052,47.14010146260824,-0.02603434816712591,-2.640069847110964
416.6000000000052,47.217258078456425,-0.024462144794203167,-2.6412833473578483
417.4000000000052,47.29673546372858,-0.02749580923002648,-2.6438717722172185
418.2000000000052,47.37208502638312,-0.02561004611904172,-2.6463052791152197
419.00000000000523,47.45233251550033,-0.027187673718448324,-2.6476959591756564
419.80000000000524,47.53019058101155,-0.027181669041098866,-2.6489608028490137
420.60000000000525,47.60795999163105,-0.02869908732878912,-2.6502620209745427
421.40000000000526,47.686073665721366,-0.030454828901015474,-2.650501151838556
422.2000000000053,47.76352835664067,-0.0289427597882298,-2.6516001793794715
423.0000000000053,47.84201174731741,-0.031786921927797085,-2.652893358444121
423.8000000000053,47.92136860113717,-0.03324934815072411,-2.6555389346053775
424.6000000000053,47.99875803862161,-0.0340831051231264,-2.657101552477131
425.4000000000053,48.077716062921,-0.03409886514251936,-2.659488819717324
426.20000000000533,48.155661718145346,-0.03609751694542429,-2.660810122443203
427.00000000000534,48.23135614028543,-0.03725553324716979,-2.6610054105101146
427.80000000000535,48.31099659352382,-0.03634036184550449,-2.6624563970787163
428.60000000000537,48.389808930803,-0.03786806786614605,-2.6637915412106894
429.4000000000054,48.46788618175583,-0.03972167266515381,-2.6664155530087514
430.2000000000054,48.54525596690898,-0.03953311803681514,-2.667731112404309
431.0000000000054,48.624749413460734,-0.03953312861768732,-2.6703355007282408
431.8000000000054,48.70184259330948,-0.041075151056526815,-2.671751867847536
432.6000000000054,48.78163880222728,-0.040833981256129026,-2.6731479645059584
433.40000000000543,48.85747029629966,-0.04222186513838533,-2.673752040242494
434.20000000000545,48.93856365734201,-0.04347942602426691,-2.6756130888163385
435.00000000000546,49.01652856985848,-0.04466995811940444,-2.678612171013783
435.80000000000547,49.09554529740342,-0.044673048938209,-2.6792159775125377
436.6000000000055,49.173274092343,-0.0453328165958774,-2.6815330427460133
437.4000000000055,49.24950262200255,-0.046507977458112304,-2.682853305868165
438.2000000000055,49.329766186340045,-0.045789635730164036,-2.6856199780232477
439.0000000000055,49.40674912240503,-0.04567429938551715,-2.686938725554142
439.8000000000055,49.48681311559642,-0.04626739823896164,-2.688277556060338
440.60000000000554,49.5651948630745,-0.04696505664805917,-2.689597648736253
441.40000000000555,49.644023237782775,-0.046815794026585866,-2.6923745193989808
442.20000000000556,49.72212631382329,-0.04532423836248023,-2.6942990840226586
443.00000000000557,49.800843965767015,-0.046541191173393615,-2.6969649810498217
443.8000000000056,49.8786450733706,-0.04828176651580285,-2.69761960724078
444.6000000000056,49.957451554887925,-0.050400460685245396,-2.6996544255016377
445.4000000000056,50.03592065716362,-0.04880327262032236,-2.7013470364946692
446.2000000000056,50.114510300573755,-0.048474968262169904,-2.7028577194096393
447.0000000000056,50.19289476402234,-0.05015571157801535,-2.705656565618204
447.80000000000564,50.27118388756897,-0.04964712076108846,-2.7062482416418914
448.60000000000565,50.34922673492984,-0.04979140950838057,-2.708906344230143
449.40000000000566,50.42617978846369,-0.04864180878237956,-2.710178405907814
450.2000000000057,50.50725401544758,-0.04677155516693454,-2.712963275154281
451.0000000000057,50.58556014927786,-0.0468820704221834,-2.7144987617186915
451.8000000000057,50.663171624380034,-0.04708509288244245,-2.7157878132509925
452.6000000000057,50.74181743495909,-0.04426198306701312,-2.718257030619128
453.4000000000057,50.819674624251206,-0.042026488271956874,-2.722399374905134
454.20000000000573,50.897933833307015,-0.04185210740158485,-2.7236617959479066
455.00000000000574,50.97645836131753,-0.041794617528721156,-2.7249971590294346
455.80000000000575,51.05435621260691,-0.04030434580204856,-2.727884150910353
456.60000000000576,51.13435502279572,-0.038757569857563956,-2.7306357482342962
457.4000000000058,51.21216857165597,-0.03941234731062837,-2.7331288250392625
458.2000000000058,51.290833191925806,-0.035217021193590825,-2.7352590368682326
459.0000000000058,51.36881889154781,-0.03515416407299499,-2.736468391976259
459.8000000000058,51.447440847187316,-0.034148648171607454,-2.7399133662373654
460.6000000000058,51.52593352375294,-0.03148472522217238,-2.742682082688093
461.40000000000583,51.602170287720064,-0.02883465500929161,-2.7453045167242545
462.20000000000584,51.683897030338656,-0.02939090459379068,-2.7479069709080344
463.00000000000585,51.762615936006355,-0.0266477703692527,-2.7511784832869104
463.80000000000587,51.841058246684135,-0.02557111098210707,-2.752767367647259
464.6000000000059,51.91896701942321,-0.022126421776634042,-2.7555774769781767
465.4000000000059,51.99718835564487,-0.021135190453191677,-2.7599599234582053
466.2000000000059,52.076693574531575,-0.01969162059474605,-2.7597267169960737
467.0000000000059,52.15518963532589,-0.018422895816260887,-2.7632842477762782
467.8000000000059,52.2334800985268,-0.01694135209865677,-2.766557293740804
468.60000000000593,52.31251654562757,-0.01598524647542221,-2.7693532640406273
469.40000000000595,52.39073727567019,-0.013037037838719123,-2.771761050815459
470.20000000000596,52.46924922433978,-0.012153014903593662,-2.7734858378122085
471.00000000000597,52.54771332134804,-0.012950750034646186,-2.7750448851625222
471.800000000006,52.6275527077553,-0.010641821898919268,-2.778517612331581
472.600000000006,52.70483917969366,-0.009741580197947353,-2.7812565305139305
473.400000000006,52.78457969391081,-0.010340442934027472,-2.7843846978351343
474.200000000006,52.863923477864915,-0.00913845427642157,-2.7866246810978517
475.000000000006,52.942375995989266,-0.007881709258080627,-2.789661521970524
475.80000000000604,53.021654166279866,-0.008012495591389057,-2.792036894164772
476.60000000000605,53.09990447295005,-0.009026128561167468,-2.7938828205951705
477.40000000000606,53.175932686501056,-0.009394173067077904,-2.796751412175934
478.20000000000607,53.25788755667892,-0.007936503061875766,-2.798355602884068
479.0000000000061,53.33685444813629,-0.010700293500377156,-2.799802042321266
479.8000000000061,53.41519874949821,-0.009009216884982574,-2.802470160367045
480.6000000000061,53.49429454693592,-0.009719289830793065,-2.8060019114880492
481.4000000000061,53.57376569471544,-0.00889487624318308,-2.8095682394865236
482.2000000000061,53.65292660235475,-0.011418540150750611,-2.809597684133755
483.00000000000614,53.73107216599838,-0.008828836471724943,-2.8131597417636645
483.80000000000615,53.810472397830175,-0.008211115549237369,-2.815547695738501
484.60000000000616,53.88831123026633,-0.007713899383105738,-2.8167471239194124
485.4000000000062,53.96843707467919,-0.007122330664256493,-2.818354648761025
486.2000000000062,54.0443302898017,-0.008310342295908879,-2.819519834798249
487.0000000000062,54.12641886100246,-0.010126186241926183,-2.8217674167587163
487.8000000000062,54.2050372279012,-0.009410864070198088,-2.8244478539642737
488.6000000000062,54.28371607284885,-0.008502452652235037,-2.8264139847754937
489.40000000000623,54.36243709009988,-0.0072554385670972055,-2.8283220295413507
490.20000000000624,54.44193030559865,-0.009215548260730233,-2.831179996159555
491.00000000000625,54.520000000000564,-0.00818060118011188,-2.831089864282501
491.80000000000626,54.59988788213062,-0.009234874820214345,-2.832732304196547
492.6000000000063,54.67809461183238,-0.008121225926359554,-2.834060965973218
493.4000000000063,54.757797674487556,-0.0074972040205242285,-2.836140747967248
494.2000000000063,54.836788789194564,-0.009546071573161452,-2.8376845106501336
495.0000000000063,54.914905006884716,-0.008406037407637346,-2.839066166438517
495.8000000000063,54.99407570419072,-0.009324665491543871,-2.8403096397412453
496.60000000000633,55.07314798708444,-0.008015530285913619,-2.8418923690487894
497.40000000000634,55.151665355901486,-0.008794794619647162,-2.844379666078403
498.20000000000636,55.229542952082454,-0.009363292696556336,-2.8450391325853537
499.00000000000637,55.30881234117561,-0.008607490097876647,-2.846368987127195
499.8000000000064,55.38824693852297,-0.007749361205620864,-2.8476645774399865
500.6000000000064,55.46798388695713,-0.006806401145427632,-2.8491844993623627
501.4000000000064,55.546624942890645,-0.006786634697998228,-2.8519186766965934
502.2000000000064,55.62494567573876,-0.007832941620533496,-2.852482893395482
503.0000000000064,55.70386815928772,-0.007361829100641093,-2.853920284231485
503.80000000000643,55.783152950616426,-0.0060131688394042815,-2.855224789876574
504.60000000000645,55.8626033436758,-0.007445856670964646,-2.8577577747335594
505.40000000000646,55.94170392600574,-0.0070061278484196965,-2.859195248314281
506.20000000000647,56.02051682227904,-0.00932867192084752,-2.85956541385875
507.0000000000065,56.0991309632357,-0.008746437008196106,-2.8607691877048853
507.8000000000065,56.178310679519896,-0.008977884511856993,-2.8630268761604736
508.6000000000065,56.25839024225021,-0.008736703280467606,-2.8631623057218745
509.4000000000065,56.33624233986196,-0.006941927640527035,-2.8631415084436234
510.2000000000065,56.41633064671306,-0.009466721981477355,-2.8657786832017877
511.00000000000654,56.49287488866197,-0.008897991813965445,-2.8671317213665297
511.80000000000655,56.57386020731239,-0.009668334572371151,-2.867084503025001
512.6000000000065,56.65234291314137,-0.008620395547555226,-2.8684086591326117
513.4000000000066,56.73135610356591,-0.010767726756171547,-2.871020642681505
514.2000000000066,56.810973747753394,-0.010145986526948536,-2.871558920679025
515.0000000000066,56.88921064461725,-0.011194418823380015,-2.872370907047675
515.8000000000065,56.969387507734446,-0.011466795504138538,-2.873679987006613
516.6000000000066,57.04935034742614,-0.00968577654324343,-2.874998748493466
517.4000000000067,57.127475041264475,-0.007946488503525306,-2.876315906144601
518.2000000000066,57.206503945220945,-0.009242962127566368,-2.877735775948678
519.0000000000066,57.2871385742997,-0.010080699618501887,-2.8789112950766746
519.8000000000067,57.36592678187173,-0.009280229350826952,-2.880293583288375
520.6000000000067,57.444811134687015,-0.008869638723852713,-2.881590125197274
521.4000000000067,57.524038031672184,-0.011068195220841015,-2.8815915063696975
522.2000000000066,57.60288870605528,-0.008506681946595096,-2.8829103781547785
523.0000000000067,57.682086491892164,-0.008712277226147203,-2.884373312986729
523.8000000000068,57.761085316556105,-0.00879228050801828,-2.8862866879492
524.6000000000067,57.84019593627997,-0.008840797079924911,-2.885543037096144
525.4000000000067,57.91999789459066,-0.005014735366403733,-2.88685199273833
526.2000000000068,57.999292771195336,-0.006678287117916182,-2.889490020391167
527.0000000000068,58.07877354099729,-0.005832961043293117,-2.8903634562779827
527.8000000000068,58.15785180698754,-0.0075695515434800464,-2.890822783213104
528.6000000000067,58.23686032636506,-0.006066514588896732,-2.8914927072634136
529.4000000000068,58.31579990269514,-0.006679015127395771,-2.892132297285506
530.2000000000069,58.39539611316064,-0.002369577974000503,-2.8935317894265555
531.0000000000068,58.47443309656109,-0.00383286653545023,-2.8955114119831586
531.8000000000068,58.553930996983134,-0.0026855488901944558,-2.8957091683779854
532.6000000000068,58.63306304889989,-0.002648706367633036,-2.896082786182015
533.4000000000069,58.71235995751813,-0.0016703508730252503,-2.897413939898406
534.2000000000069,58.792217724747175,-0.0002215150880128247,-2.8986752807183933
535.0000000000068,58.870389707078544,0.0006914919413990583,-2.900040176368556
535.8000000000069,58.94964747157577,-1.8629033593065003e-05,-2.901349969751421
536.600000000007,59.02925840369524,-0.00012837799384346482,-2.902623043360738
537.4000000000069,59.10749851695688,0.000872580175865334,-2.9038463540642674
538.2000000000069,59.188070194429976,-0.001010289429740574,-2.9026641228497136
539.0000000000069,59.26617338850529,0.0009259231035900761,-2.9053316217879797
539.800000000007,59.346159528148625,0.0027726832098508014,-2.905270072238957
540.600000000007,59.42620312104152,0.0018948151143616254,-2.9066727482768284
541.4000000000069,59.50499483210501,0.0035919471899472644,-2.907122631158841
542.200000000007,59.58429171452384,0.0038459046596228674,-2.9092552021125972
543.000000000007,59.66121754264294,0.0033686546088366187,-2.9092593465113823
543.800000000007,59.741890716815725,0.003915487726572908,-2.911627815317464
544.600000000007,59.823069394573736,0.006992483037403963,-2.9115779296046487
545.400000000007,59.901533252294,0.00455069131946273,-2.911557868121154
546.000000000007,59.961919046035135,0.002925784309077306,-2.912869444926274