File: 01_Data/Corrugated_Cardboard/STA/N2/10K_min/Corrugated_Cardboard_STA_N2_10KData_230628_R1.csv
##Temp./Â°C,Time/min,DSC/(mW/mg),Mass loss/mg
26.0,15.47122069948266,0.05005129820521126,-0.07426009613491136
27.100000000000016,15.98169591355141,0.10327140442142757,-0.07303708496644745
28.20000000000003,16.226938896193865,0.14646650102982894,-0.07299092932323337
29.300000000000047,16.41752468043272,0.18001835378244602,-0.07177569815959117
30.400000000000063,16.587861451019833,0.20781454993914505,-0.0729172875680506
31.500000000000078,16.742733369892427,0.2289966271899122,-0.07389179416336766
32.600000000000094,16.888841991272507,0.24646839884599103,-0.07465574941501085
33.70000000000011,17.02203562841816,0.2632225467114524,-0.07414326729134846
34.800000000000125,17.162230552418947,0.2808640559814384,-0.07626673899393577
35.90000000000014,17.290104871520075,0.29347145914513595,-0.07829129876355267
37.000000000000156,17.421426475455494,0.3038948493547593,-0.07774357750360927
38.10000000000017,17.55018208352221,0.31634529461927463,-0.0776757761839395
39.20000000000019,17.67624284471981,0.32731536285304896,-0.08139546835933142
40.3000000000002,17.79937785532008,0.33849455212771984,-0.0812957937134593
41.40000000000022,17.923422677403266,0.3491706025980206,-0.08284663711064955
42.500000000000234,18.045227227692713,0.36149274283453847,-0.08249880930103526
43.60000000000025,18.167394318866517,0.3709283023181098,-0.08540235234014482
44.700000000000266,18.288007186774365,0.3819212425982208,-0.0866115913534573
45.80000000000028,18.408834948642742,0.3926033125721624,-0.08695247526198013
46.9000000000003,18.528230811516895,0.4047985748873253,-0.08825988208485391
48.00000000000031,18.648014151356744,0.41600847374852123,-0.08823584595191836
49.10000000000033,18.764921672252417,0.4263369102977135,-0.09221204424601037
50.200000000000344,18.884917037055782,0.43553340689765174,-0.09353229046292899
51.30000000000036,19.002425474863255,0.44727506208455337,-0.09616535682952154
52.400000000000375,19.119683326628163,0.4574083113177907,-0.09748012680830609
53.50000000000039,19.23437520017078,0.46784070095443475,-0.09747989858576478
54.600000000000406,19.34986950932616,0.4791508281028922,-0.10032005480251716
55.70000000000042,19.46580515164162,0.4871305294086652,-0.10430176372331434
56.80000000000044,19.5799040783434,0.4994601552102149,-0.10428999804049166
57.90000000000045,19.69545697052528,0.5066544409442957,-0.10692188900828992
59.00000000000047,19.804371721526117,0.5132486731909369,-0.10824009257167244
60.100000000000485,19.922248308182713,0.5210073147287237,-0.11094564542296492
61.2000000000005,20.034903336465753,0.5308500610631977,-0.1136963840990779
62.300000000000516,20.145564450424644,0.5387889881371173,-0.11482043918480755
63.40000000000053,20.254933037748735,0.5447626664241598,-0.11745888101819268
64.50000000000054,20.36990628115115,0.5514741580902267,-0.11878096017290307
65.60000000000056,20.48102737490058,0.5561872200260596,-0.12009941492954823
66.70000000000059,20.592266903599253,0.5616236166685857,-0.12311374148884902
67.8000000000006,20.703825414906497,0.5670738647038798,-0.12538220143155687
68.9000000000006,20.813108613779235,0.5697937742471793,-0.12942053279858534
70.00000000000063,20.92365876505695,0.5732723309707326,-0.13064015421040676
71.10000000000065,21.033971505749577,0.5766386666564771,-0.13393690341715558
72.20000000000066,21.14402383031547,0.5759653306451784,-0.135953847310895
73.30000000000067,21.25000000000006,0.5799003264186353,-0.13854088291728228
74.40000000000069,21.36292465125218,0.580270460357329,-0.14137682163606424
75.50000000000071,21.473263900763484,0.5796896895008412,-0.14359296102960606
76.60000000000072,21.580932384623647,0.5781382184538528,-0.14523532980726817
77.70000000000073,21.692602470628824,0.5784244210213929,-0.14919102099964388
78.80000000000075,21.800714342631053,0.5756672502438032,-0.15182203437446073
79.90000000000077,21.906719000082997,0.5761635624158128,-0.15352592792069863
81.00000000000078,22.019321045358147,0.5745854276653075,-0.15445996204430923
82.10000000000079,22.126364105131646,0.5712405714167785,-0.1570744649280753
83.20000000000081,22.23583834348939,0.5670217673425813,-0.1597263752121263
84.30000000000084,22.343310139712827,0.5619116807230846,-0.16105011194058516
85.40000000000084,22.45210683675583,0.5608555359629435,-0.16105002088961395
86.50000000000085,22.55917593762859,0.5568693163625065,-0.16310138015042597
87.60000000000088,22.666820522435117,0.5534055879532527,-0.16456474594451986
88.7000000000009,22.77521950738594,0.5471885371319241,-0.16762878433480832
89.8000000000009,22.881422184378415,0.5425148210008345,-0.17048992172598698
90.90000000000092,22.989661258580004,0.5400619442088744,-0.17170009742239944
92.00000000000094,23.097580554731238,0.5356946681327484,-0.1730172227478759
93.10000000000096,23.203908787535777,0.5298731342516736,-0.17432995198529078
94.20000000000097,23.311490886805306,0.5268503470852661,-0.17563136482931085
95.30000000000098,23.41676443512421,0.5204768605767465,-0.17561001793500708
96.400000000001,23.524977964054937,0.5179125081425461,-0.1769598884313437
97.50000000000102,23.630723281536977,0.5113648168973449,-0.17795612187317023
98.60000000000103,23.736580498507273,0.5082344494491862,-0.17960770297500694
99.70000000000104,23.840302071821387,0.5030410502170226,-0.18093095229583245
100.80000000000106,23.94866655032548,0.5006243615920761,-0.18215209896399998
101.90000000000109,24.05603230310148,0.49493285721859226,-0.1822280184040519
103.0000000000011,24.159902921907154,0.48937197686104106,-0.18354966679838558
104.1000000000011,24.267498398807138,0.49061028460958533,-0.18487003398984125
105.20000000000113,24.373235539313768,0.48835906423588304,-0.1843992582068168
106.30000000000115,24.478239266128554,0.4821288454879119,-0.1848969603562427
107.40000000000116,24.58529355389893,0.48159438847772706,-0.1873160905985971
108.50000000000117,24.69121759535802,0.477259008409329,-0.18619035644005688
109.60000000000119,24.797194804755126,0.47702202857110354,-0.18717026575351525
110.70000000000121,24.904098520355518,0.4756802669569318,-0.18749953020044252
111.80000000000122,25.00960743809271,0.4748943425585461,-0.18750024237682617
112.90000000000123,25.115985021209184,0.47465404569076264,-0.18882384735550506
114.00000000000125,25.222177575583082,0.4716186495822621,-0.18882023983519947
115.10000000000127,25.325640051706866,0.47004150899196995,-0.18891962474711832
116.20000000000128,25.4349270695455,0.4694118669899908,-0.18884036983800723
117.30000000000129,25.541654460559062,0.46934270987662596,-0.1901192155271092
118.40000000000131,25.647715966583213,0.4691988465166599,-0.19112990859715673
119.50000000000134,25.754326507259012,0.46640102638101943,-0.19246602148789194
120.60000000000134,25.856870186457336,0.466372478148002,-0.19112005106713248
121.70000000000135,25.96546414724132,0.466699830650425,-0.1911200480007471
122.80000000000138,26.07202790659779,0.46610090098038437,-0.19111918510688586
123.9000000000014,26.178641802435873,0.46454208809551745,-0.1911302209789234
125.0000000000014,26.284798622161027,0.46627968595767433,-0.1911301207286753
126.10000000000142,26.390930697921153,0.4671484921550759,-0.19239752128865817
127.20000000000144,26.496027325292864,0.4650576463231785,-0.19146009634878602
128.30000000000146,26.601604215600823,0.466336731498486,-0.19149268316019175
129.40000000000146,26.70741433155398,0.4675904282004669,-0.192770158493059
130.50000000000148,26.813363319126058,0.4679951665808233,-0.19409067213318654
131.6000000000015,26.91978957995427,0.46824746142443185,-0.1940901094609515
132.70000000000152,27.026112004106004,0.4681436058036812,-0.19451093309837741
133.80000000000155,27.131741475197188,0.4718988087901115,-0.19375990405846277
134.90000000000154,27.236679238263665,0.473398780148809,-0.19376345421646146
136.00000000000156,27.342144592561855,0.4742676795880665,-0.19396211007618192
137.1000000000016,27.44739593352683,0.475054781370261,-0.19277647041486734
138.20000000000158,27.553149518145656,0.47623993504482,-0.1927793002142657
139.3000000000016,27.658728440329067,0.47907289698888544,-0.1940896824633942
140.40000000000163,27.76510585106979,0.4798340228326754,-0.195410193370952
141.50000000000165,27.869014361964677,0.4812394216138468,-0.19409099331986113
142.60000000000167,27.975590887170522,0.48174373776255197,-0.19475597852196014
143.70000000000167,28.081860567309107,0.4853693395037453,-0.19474803530264495
144.8000000000017,28.18816330329595,0.4861102577783972,-0.19482065018365535
145.9000000000017,28.29233148408002,0.4898102928712722,-0.1950797073690822
147.0000000000017,28.398355386746864,0.48870627399302846,-0.19639970732193834
148.10000000000173,28.504145293898077,0.491958656061381,-0.195071803317993
149.20000000000175,28.608321058327494,0.4925271026826398,-0.19474959584767948
150.30000000000177,28.714892868432642,0.4936007929164109,-0.1970521094539368
151.4000000000018,28.81897133999417,0.49632272667738797,-0.19703142699716025
152.5000000000018,28.92403945687633,0.4986744619192688,-0.1970500641151549
153.6000000000018,29.030831982289467,0.49851193440429464,-0.1970249443414609
154.70000000000184,29.134819390676558,0.5007031077931133,-0.19606996762215978
155.80000000000183,29.238059730279673,0.5028541106637536,-0.19606995924902737
156.90000000000185,29.343550404744317,0.5057921620952921,-0.19475170472281622
158.00000000000188,29.4497342766901,0.5073700208927674,-0.1957910377835983
159.1000000000019,29.556320428282415,0.5077638473912189,-0.195395496103413
160.20000000000192,29.662324228590485,0.5107756828608746,-0.19574176882125993
161.30000000000192,29.765021829145628,0.5121492749976664,-0.1957399303684939
162.40000000000194,29.869469495849053,0.5148839556182954,-0.19705800411154506
163.50000000000196,29.97641551375998,0.5153792727961098,-0.1973797585263828
164.60000000000196,30.081209529643534,0.5164863716319478,-0.19607002524183592
165.70000000000198,30.185760386638826,0.5203673028885762,-0.19705175527113106
166.800000000002,30.29155606599697,0.522490652296445,-0.1973977841056298
167.90000000000202,30.3964617451715,0.5244427222306458,-0.19868765338001193
169.00000000000205,30.50056222687005,0.5274360906952407,-0.19836991974470042
170.10000000000204,30.607529453817584,0.5256931134642472,-0.19836985978937793
171.20000000000206,30.711220469642306,0.5287838337747247,-0.19738000962509794
172.3000000000021,30.81657100597524,0.5303923551059696,-0.1973804788257052
173.40000000000208,30.9176014268991,0.5314414084452312,-0.19869993581556322
174.5000000000021,31.02551132285658,0.535067579724285,-0.198661224704602
175.60000000000213,31.130381327262047,0.5353975591040588,-0.20001990518414825
176.70000000000215,31.235866396486884,0.5373100929365423,-0.1996881323551163
177.80000000000217,31.339206068478788,0.5389845536848653,-0.1996901430858502
178.90000000000217,31.44486892115934,0.5378405183208892,-0.20001939186294493
180.0000000000022,31.54990568029974,0.5427864146226252,-0.20100952559514518
181.1000000000022,31.654148519431256,0.540973838886282,-0.19969011111070412
182.2000000000022,31.759266832982014,0.544756285701087,-0.20098758961313212
183.30000000000223,31.864199202381858,0.5442948333796779,-0.20001731600683748
184.40000000000225,31.96929377507918,0.5471632065931027,-0.20199886204698014
185.50000000000227,32.073588909704476,0.5483437273779498,-0.20123664803204733
186.6000000000023,32.178527010192816,0.5501000255002689,-0.2019997606997581
187.7000000000023,32.28234088005459,0.5528024576604138,-0.20167019358338312
188.8000000000023,32.387671845150855,0.5555826234735207,-0.20035812451620316
189.90000000000234,32.491969030308056,0.5590192422256419,-0.20298979946454399
191.00000000000233,32.59662823137248,0.5585410532437283,-0.20429979408254084
192.10000000000235,32.70172757179414,0.5603047049339597,-0.20298944570614896
193.20000000000238,32.80568118065675,0.562239655805949,-0.20298979199872313
194.3000000000024,32.91089202495796,0.5612359456409646,-0.20299063174587317
195.40000000000242,33.01636116695902,0.5621805844670872,-0.20429842074652438
196.50000000000242,33.1214041547448,0.5657567351128092,-0.20305953484416062
197.60000000000244,33.22537617035801,0.5650043056828634,-0.20429979339785476
198.70000000000246,33.330378813815585,0.5659922537496941,-0.2042997919999996
199.80000000000246,33.43488770313229,0.5688581876373647,-0.20429979199952175
200.90000000000248,33.53940335106666,0.5711772542327522,-0.20429987630570778
202.0000000000025,33.643786774387216,0.569424640908693,-0.20555827443968866
203.10000000000252,33.74856162582935,0.5709895361433519,-0.2069397911687627
204.20000000000255,33.85276515119939,0.5719871637046506,-0.2056308575755903
205.30000000000254,33.95717627389528,0.5727421214370703,-0.20561795707445718
206.40000000000256,34.06028261726902,0.5737559241249823,-0.20694076033894948
207.5000000000026,34.166875750611126,0.5742655037328526,-0.20825022891381284
208.60000000000258,34.27104016886355,0.5746983193055749,-0.20825028738036355
209.7000000000026,34.37575954727818,0.5753035016417503,-0.20745064161903937
210.80000000000263,34.48128211474896,0.5778593478278711,-0.20859012736465665
211.90000000000265,34.58442231840261,0.5794312602039862,-0.20859012798952392
213.00000000000267,34.68925982070328,0.5809420013608639,-0.2085865743288533
214.10000000000267,34.794025752803606,0.5813010111701797,-0.21121006363429995
215.2000000000027,34.8991149026057,0.5845002664459853,-0.21121006400000564
216.3000000000027,35.00043813125451,0.5839314740999455,-0.21121006399398734
217.4000000000027,35.1074208066426,0.5843593031773375,-0.2112134517440465
218.50000000000273,35.211348790747124,0.5866597934503351,-0.21252885693158596
219.60000000000275,35.315245027127084,0.587576931390031,-0.2138463133105013
220.70000000000277,35.419388761813885,0.5895541672939635,-0.2125299200738633
221.8000000000028,35.52497235023004,0.590910839453495,-0.21282409581277228
222.9000000000028,35.62896041300897,0.5934159844381837,-0.21429186651474907
224.0000000000028,35.73339352510941,0.5910013265073701,-0.21246629903525083
225.10000000000284,35.837619402601845,0.5931873226393907,-0.21659580837118586
226.20000000000283,35.94213758429241,0.5946797058051385,-0.21736082616605046
227.30000000000285,36.04663497275813,0.5946873770837195,-0.21790148130309728
228.40000000000288,36.15175054777952,0.5961613031561517,-0.2189018975276893
229.5000000000029,36.256636188442286,0.597300213959302,-0.22025844417819407
230.60000000000292,36.36051186206047,0.5961634285609829,-0.22054958948866688
231.70000000000292,36.465487490330254,0.5987961302213263,-0.22121003049935606
232.80000000000294,36.56954819370073,0.6000292954207473,-0.22120988352166293
233.90000000000296,36.67393360149603,0.6005558051424007,-0.22252990326083033
235.00000000000296,36.777157581871144,0.6022921238681234,-0.22383949313996876
236.10000000000298,36.88383471664008,0.6040141065751592,-0.22607870797591278
237.200000000003,36.987856791368806,0.6053059740663764,-0.22615008172338502
238.30000000000302,37.092459865263066,0.60486681622549,-0.22779797159918758
239.40000000000305,37.19611065363688,0.6057851905849625,-0.22910776923779252
240.50000000000304,37.30199863155457,0.6058599691277229,-0.23180892561161848
241.60000000000306,37.40638474679969,0.6079693785782618,-0.2330606026354527
242.7000000000031,37.51188231309682,0.6069898756073717,-0.23372776551036623
243.80000000000308,37.61646587459675,0.6104477884646673,-0.23696628229698558
244.9000000000031,37.72000088048218,0.6110675056085415,-0.23900255657782488
246.00000000000313,37.82458476157249,0.610779555208129,-0.24030987975685036
247.10000000000315,37.92717690172137,0.613179195816333,-0.2415248566561088
248.20000000000317,38.03415117539248,0.611721786358339,-0.24288300039653876
249.30000000000317,38.138823693353515,0.6135051614784541,-0.2442627342645478
250.4000000000032,38.24370297437592,0.6133576766032198,-0.248220983006612
251.5000000000032,38.34734647960061,0.613803399650872,-0.24952356717233748
252.6000000000032,38.4517684579733,0.6152119058410546,-0.25223259675796506
253.70000000000323,38.55732334194869,0.616348576372456,-0.256343772100184
254.80000000000325,38.66144144135622,0.6152836442449048,-0.2589690551589854
255.90000000000327,38.76622851540908,0.6165211907912083,-0.2608914577482766
257.0000000000033,38.87198276533833,0.6167500008328843,-0.2650817694245795
258.1000000000033,38.97654051448502,0.6169496475397124,-0.26682481355133447
259.20000000000334,39.08084618739998,0.6169806598794916,-0.27056966715373143
260.30000000000337,39.186614463345485,0.6179623195386441,-0.2737894575860427
261.40000000000333,39.290837825094975,0.6190783093287966,-0.278027234155406
262.50000000000335,39.39669117816205,0.6206243667866438,-0.2820354640941174
263.6000000000034,39.50094747347055,0.6184608037794195,-0.2851104631050898
264.7000000000034,39.60502480597753,0.6207279018969867,-0.29028824596138936
265.8000000000034,39.71099976102726,0.6220797359307092,-0.29353740303617126
266.9000000000034,39.81629991702773,0.6220423813693892,-0.29902915812681385
268.0000000000034,39.920192278375175,0.6218807602848841,-0.30467654630206376
269.10000000000343,40.025587442300896,0.6240853284886985,-0.30790547433721915
270.20000000000346,40.13210953255566,0.6232572616835437,-0.31394632159119595
271.3000000000035,40.236495184597246,0.6258485140660079,-0.3193626926156661
272.4000000000035,40.34156166287679,0.6244232037181521,-0.3262334736533381
273.5000000000035,40.44661785447635,0.6267109009541691,-0.33219556858783506
274.60000000000355,40.552177448433156,0.6266524154625052,-0.33793735314163964
275.70000000000357,40.657195483822086,0.6280333777587837,-0.3434543707710125
276.8000000000036,40.76281698405227,0.6307310825814574,-0.3512729229365892
277.9000000000036,40.86798914502569,0.6295969249138759,-0.35673752934618275
279.0000000000036,40.97329262171422,0.6328579963602704,-0.36347280615690813
280.1000000000036,41.07920309601445,0.6327453640172618,-0.3715298857951259
281.2000000000036,41.18293243834561,0.6338093530958829,-0.3809258781023015
282.30000000000365,41.28834511600312,0.63735892378255,-0.3884273918790839
283.4000000000037,41.393261406939764,0.637881204125927,-0.39706356446953706
284.5000000000037,41.49889530929839,0.6386256771441479,-0.4054859096923069
285.60000000000366,41.60428557615137,0.6395908816070539,-0.4168535309926291
286.7000000000037,41.70868550181155,0.6425829359687301,-0.42431082635445705
287.8000000000037,41.81380636791787,0.6422526665646914,-0.43523336324620043
288.90000000000373,41.92075011718112,0.6440508212126748,-0.4454712671005474
290.00000000000375,42.02459658721439,0.6463259614670702,-0.45653061800070116
291.1000000000038,42.13020090440314,0.6493694540428603,-0.4689016645584241
292.2000000000038,42.23606969923989,0.6513001463872641,-0.4829647908039867
293.3000000000038,42.34144106443663,0.6551150221048727,-0.4941181650900228
294.40000000000384,42.44687577444979,0.6582959413352958,-0.5050381508399173
295.5000000000038,42.5525641597907,0.6617591518218647,-0.5175001059273798
296.60000000000383,42.65852550959164,0.6646516798914179,-0.5309230024706135
297.70000000000385,42.76415041131974,0.668693039851596,-0.544484192878401
298.8000000000039,42.87034225357065,0.6710129988069087,-0.5587308241008335
299.9000000000039,42.976294082604895,0.6750834955836479,-0.5718120300000233
301.0000000000039,43.0821980006607,0.679168078400742,-0.5869067575414899
302.10000000000394,43.18709853738383,0.6801035904397084,-0.6035582521158176
303.2000000000039,43.293934408116016,0.6841908934929706,-0.6198661497951861
304.30000000000393,43.399080401258814,0.6882503237454399,-0.6374719620819249
305.40000000000396,43.502139538996886,0.6912279902300433,-0.6529807663474081
306.500000000004,43.61043164397174,0.6954307950007168,-0.6711737954082668
307.600000000004,43.71645725025847,0.6989514504940402,-0.6900361140035365
308.700000000004,43.82184343554179,0.7001640768487962,-0.710120186019279
309.80000000000405,43.92747924402257,0.7058545735570936,-0.7268288227186819
310.90000000000407,44.034650513333204,0.708059045671322,-0.7464071476518335
312.0000000000041,44.139248620469125,0.7118713509128778,-0.7659896748259944
313.10000000000406,44.24539499282418,0.716696033625738,-0.786047103499131
314.2000000000041,44.350833478729214,0.7198462043063063,-0.8077935313239593
315.3000000000041,44.45760992255254,0.7244626979788988,-0.8312370521709544
316.4000000000041,44.56417092262687,0.7259733470171845,-0.8532788120604913
317.50000000000415,44.67000000000043,0.729578462462663,-0.875401189660737
318.6000000000042,44.77684940394485,0.7336675868784948,-0.9004539859306071
319.7000000000042,44.882829000381264,0.7379659034421684,-0.923594183055263
320.80000000000416,44.98911958711075,0.7437489005376624,-0.950811683239773
321.9000000000042,45.09472742984991,0.7462610701214722,-0.9760132651754656
323.0000000000042,45.20075178046031,0.7519787184288824,-1.001931096083596
324.10000000000423,45.30558091595871,0.7565946056775541,-1.029089188122533
325.20000000000425,45.41367664764509,0.7583419846340181,-1.0594725188579055
326.3000000000043,45.51971264375023,0.7646128140417185,-1.0860172242486588
327.4000000000043,45.627106138102945,0.7710402554625626,-1.116318276825345
328.5000000000043,45.733127439350575,0.7774483485339461,-1.1460308594489357
329.60000000000434,45.83929222886218,0.7816214411505285,-1.177467427299979
330.7000000000043,45.94644093316061,0.7873289131496091,-1.2098280386960405
331.80000000000433,46.05269497567615,0.7962967617456458,-1.2437864834521775
332.90000000000435,46.15950538038937,0.801120852542653,-1.2775870967730256
334.0000000000044,46.26551238213971,0.8102886016804278,-1.3132095593172455
335.1000000000044,46.372961336164046,0.8181197373572799,-1.3488262412819
336.2000000000044,46.47908798179569,0.8232058549532645,-1.3847481072242305
337.30000000000445,46.58586782116117,0.8313755309743027,-1.4240089592708451
338.4000000000044,46.69240769423498,0.8386393702077134,-1.462110317524032
339.50000000000443,46.799612163436,0.84915480925338,-1.5025907741823827
340.60000000000446,46.90634966818297,0.8563456542114958,-1.5438419453957017
341.7000000000045,47.01375492073288,0.8656023083276165,-1.5847500644337882
342.8000000000045,47.12017118972835,0.87424323599901,-1.628244818383103
343.9000000000045,47.22669947823296,0.8808340851421058,-1.672373577712678
345.00000000000455,47.33485344029499,0.8884928577395972,-1.7174411212445428
346.10000000000457,47.44092287996279,0.8968433530256128,-1.7616673610517553
347.2000000000046,47.54810772402982,0.9025205399950558,-1.811268654342534
348.30000000000456,47.655389261055234,0.908931613771103,-1.8556227286687994
349.4000000000046,47.76228202098351,0.9134571256127417,-1.9044618438071832
350.5000000000046,47.870203711920446,0.9161046891134751,-1.955555967878615
351.6000000000046,47.97624487968362,0.9188934592551675,-2.001617639078025
352.70000000000465,48.08275509221573,0.9190617113895931,-2.052662071501849
353.8000000000047,48.1893370664151,0.9161636003313876,-2.102807124441303
354.9000000000047,48.296603713014115,0.9105067493640457,-2.15240788388678
356.00000000000466,48.4028390879348,0.9006853530925149,-2.199544913741726
357.1000000000047,48.50970976196418,0.8940439561797897,-2.249424200179179
358.2000000000047,48.614404676538754,0.8776535052493094,-2.293989182017223
359.30000000000473,48.72091780361171,0.8629811289214913,-2.3391312663402544
360.40000000000475,48.8270042700279,0.8452675537099655,-2.383643850632401
361.5000000000048,48.933154167806265,0.8234730233908792,-2.426487265495928
362.6000000000048,49.03801210229976,0.8032400636648753,-2.463796005199502
363.7000000000048,49.14392555739958,0.7791589384823775,-2.498003577002753
364.80000000000484,49.24972381906201,0.7568907829123315,-2.5329368160946366
365.9000000000048,49.35457170834489,0.7301037706952028,-2.562568189179955
367.00000000000483,49.460282263075925,0.7062436650872772,-2.5912928746150743
368.10000000000485,49.56612887547495,0.6852350492937763,-2.616877294565476
369.2000000000049,49.67179335902614,0.662059536076411,-2.6403462081946336
370.3000000000049,49.77725979379199,0.6405461535330759,-2.6594330528717562
371.4000000000049,49.88399683564411,0.6236261480892762,-2.6773548350204166
372.50000000000495,49.988947869838334,0.6042952184212456,-2.6941211439961275
373.6000000000049,50.09396682298315,0.587375885722254,-2.7106068413752267
374.70000000000493,50.200962447636435,0.5706518189165753,-2.723479149364633
375.80000000000496,50.306838454220404,0.554182785498478,-2.736274136777633
376.900000000005,50.41313623588953,0.5398513544808636,-2.7467285949817746
378.000000000005,50.51990442778846,0.5275937334630106,-2.75531862429131
379.100000000005,50.62502575024667,0.5147943108324406,-2.761799760745867
380.20000000000505,50.73173234892185,0.5046153550911558,-2.768369225390217
381.30000000000507,50.838360970176254,0.4955932358424929,-2.7748811920376824
382.4000000000051,50.943446975015924,0.48743202364647475,-2.7819884926716214
383.50000000000506,51.05178831153846,0.4811171559363754,-2.786822118893275
384.6000000000051,51.15824965314208,0.4775204240693257,-2.790390962067022
385.7000000000051,51.26548265125813,0.473490059045911,-2.79444497074298
386.8000000000051,51.37247006224333,0.4688416651371401,-2.798684694106586
387.90000000000515,51.47945875637767,0.46647174878085174,-2.8032055710322274
389.0000000000052,51.58610384383423,0.46480908823282435,-2.8060062066208387
390.1000000000052,51.693689010254246,0.46134025343671087,-2.8092667085228915
391.20000000000516,51.801231598145506,0.46343817574983304,-2.813204918570483
392.3000000000052,51.90813500118031,0.45900888525586603,-2.8170623021158754
393.4000000000052,52.016050418217596,0.45960792311021426,-2.821233370160323
394.50000000000523,52.12343103326845,0.45732844266940886,-2.82485764324558
395.60000000000525,52.229998967281354,0.45740570519853446,-2.829110005825877
396.7000000000053,52.33772735442045,0.4546264493867228,-2.833273386865859
397.8000000000053,52.44573022633299,0.45384950486250086,-2.8347728022085703
398.9000000000053,52.55325697197051,0.4528841884755355,-2.840468122754199
400.00000000000534,52.66129650996963,0.4553770749553714,-2.8426601892536643
401.1000000000053,52.767426465581984,0.45280210864764525,-2.8472445307506966
402.20000000000533,52.874701010444674,0.4541332399465266,-2.847483779726467
403.30000000000535,52.98244612695815,0.45430797275166634,-2.850423449097533
404.4000000000054,53.087458373220784,0.4549792051807896,-2.854492852111573
405.5000000000054,53.19672733700712,0.456601535322388,-2.8582102972960284
406.6000000000054,53.30502670413436,0.45935529329509894,-2.8611718107361432
407.70000000000545,53.41270965044645,0.4603063491589796,-2.8652272899467164
408.8000000000054,53.52000102423037,0.46060777449876034,-2.868190097613188
409.90000000000543,53.6272534867934,0.46040928736189635,-2.870860746278286
411.00000000000546,53.735095025433864,0.4612117920229868,-2.8761984525228756
412.1000000000055,53.842204754105516,0.46285075715795493,-2.8782776397952436
413.2000000000055,53.951382919577426,0.46409474221190683,-2.8807575467757576
414.3000000000055,54.05849400100108,0.4626278790986713,-2.8830497219147393
415.40000000000555,54.16696307789954,0.4683673183943123,-2.8869965754963065
416.50000000000557,54.27368263898789,0.46853164074906095,-2.8896269914292887
417.6000000000056,54.38232013680725,0.4692966302917908,-2.8919103670660062
418.70000000000556,54.48999904297786,0.4710772035611533,-2.8959764151425245
419.8000000000056,54.59841185627149,0.4692737358962999,-2.8993697120781317
420.9000000000056,54.7072477717315,0.4701925041994417,-2.90140738251716
422.0000000000056,54.81562243176157,0.47261420903196183,-2.9030927369524844
423.10000000000565,54.92362697896123,0.4728609052289683,-2.9070077632358253
424.2000000000057,55.031540119577116,0.4726467591272611,-2.910950291597874
425.3000000000057,55.139492329779,0.47475029539478364,-2.9143234109002814
426.40000000000566,55.24765994102458,0.47624211222239,-2.9175945827333805
427.5000000000057,55.35640567675156,0.4772529465523234,-2.920364893013836
428.6000000000057,55.46384112843999,0.4772867102372551,-2.9217083269674773
429.70000000000573,55.572350122079655,0.48011474278938526,-2.924472613972994
430.80000000000575,55.680195529065,0.48163447944800264,-2.926930094553146
431.9000000000058,55.78890539323261,0.4818678333965877,-2.92956528095929
433.0000000000058,55.89680773132234,0.48639274075173344,-2.932182325507496
434.1000000000058,56.00478037485205,0.48632037222063884,-2.934680519072878
435.20000000000584,56.113327407827015,0.4877741288690504,-2.937711782875426
436.3000000000058,56.22165484316247,0.4891659274586526,-2.9412057814182413
437.40000000000583,56.32949777011721,0.49344429213917007,-2.9438281556211163
438.50000000000585,56.43872723904309,0.4948148025521355,-2.945153279575169
439.6000000000059,56.54639600693914,0.49546445901389824,-2.9478183053035076
440.7000000000059,56.65538356507737,0.49645964036951795,-2.9505207911288487
441.8000000000059,56.764976096597444,0.4988891572183439,-2.954712295760245
442.90000000000595,56.87237758290629,0.500311055722995,-2.9560321569500334
444.0000000000059,56.982226619021034,0.4993181206760957,-2.958756017649729
445.10000000000593,57.09029975196339,0.5046575377688056,-2.961066934242333
446.20000000000596,57.19941677976581,0.5034681345383908,-2.963692330844399
447.300000000006,57.30837849246918,0.5059627131447336,-2.964953130178391
448.400000000006,57.415963899812354,0.5081173550801097,-2.9676590160393372
449.500000000006,57.52560489403644,0.507919900931266,-2.9688689054061754
450.60000000000605,57.63495194232482,0.5091562970803916,-2.970204633983072
451.70000000000607,57.74309733700183,0.5103632857395168,-2.973066506036959
452.8000000000061,57.851428862668925,0.5136379241799903,-2.975554778363324
453.90000000000606,57.96085910030057,0.5148182367451037,-2.9780931256041243
455.0000000000061,58.069425958857806,0.5181896682126181,-2.9808376462736286
456.1000000000061,58.178438101103,0.5211880807036562,-2.9835116452977064
457.2000000000061,58.28641396847847,0.5216008154582701,-2.9847794702198716
458.30000000000615,58.3958480284304,0.5273968333096287,-2.9861445740377315
459.4000000000062,58.50547267185138,0.5298093346216401,-2.987747169507542
460.5000000000062,58.61351793362259,0.5281205057402334,-2.990252102114484
461.60000000000616,58.72208740716721,0.5329241261578682,-2.9923584135741055
462.7000000000062,58.83198514418754,0.5328948116312587,-2.9949714425292826
463.8000000000062,58.93933729395688,0.5340321256166489,-2.9959254338533654
464.90000000000623,59.04892068431608,0.537035477646248,-2.997627843697977
466.00000000000625,59.15839787572075,0.5378487720103599,-2.9989483240542265
467.1000000000063,59.26740844080199,0.5402542961143462,-3.0028983829562743
468.2000000000063,59.37453398239045,0.5418172350592688,-3.003723292580778
469.3000000000063,59.48549883314019,0.5435153771014334,-3.006841756052295
470.40000000000634,59.59531256197911,0.5436984789827136,-3.0081559423894992
471.5000000000063,59.70300838725264,0.5466859175138528,-3.0094816338615136
472.60000000000633,59.81229043952092,0.5504394731713339,-3.0118083781426463
473.70000000000636,59.921989039572814,0.5509383611979729,-3.013090051496283
474.8000000000064,60.030000964857756,0.5564013038318925,-3.015739867253772
475.9000000000064,60.13945019293325,0.5579996466428587,-3.0168382590522542
477.0000000000064,60.24877518544371,0.5601386856667369,-3.018035396050732
478.10000000000645,60.35841744447002,0.5597178459684451,-3.018041484632844
479.2000000000064,60.46709341533227,0.5607600953778062,-3.020662890440141
480.30000000000643,60.57637788598496,0.5648007709014731,-3.022029905162716
481.40000000000646,60.68507051659039,0.5722956933183624,-3.023540026817869
482.5000000000065,60.79670358814867,0.5768597469151409,-3.0259548464133434
483.6000000000065,60.905351649099835,0.5797117213740788,-3.0272687872449024
484.7000000000065,61.01388477910601,0.5852417393889091,-3.0276226232558803
485.80000000000655,61.12348372565726,0.586855427981903,-3.030237988477983
486.90000000000657,61.23357665340427,0.5903401145917697,-3.032498126322639
488.0000000000066,61.34242193433761,0.5914927010234176,-3.0331886718641963
489.10000000000656,61.451313256430964,0.5951395310865311,-3.034190069214602
490.2000000000066,61.560849267368866,0.6005357821832431,-3.0365421870188243
491.3000000000066,61.669461019334676,0.601672330933589,-3.035846719162217
492.4000000000066,61.777496057140596,0.6058509939360364,-3.038920998826762
493.50000000000665,61.8889950677843,0.6105070302802228,-3.0411106170256215
494.6000000000067,61.99816992148347,0.6134551669052423,-3.041110233367763
495.7000000000067,62.10697488329416,0.6160433524147858,-3.042427889552819
496.80000000000666,62.216574585896055,0.6169786881527702,-3.0450597052791464
497.9000000000067,62.32633233805463,0.6200729065129287,-3.0463799981272506
499.0000000000067,62.435665638143156,0.6226248452341465,-3.048816019706873
500.10000000000673,62.545015465839306,0.6269465402424882,-3.0498513052667224
501.20000000000675,62.65391023927126,0.6263466064794675,-3.048964322375423
502.3000000000068,62.76366697199138,0.6328437083679522,-3.0511243051096724
503.4000000000068,62.87357062298063,0.6344627520742365,-3.0516453138929345
504.5000000000068,62.9838604026076,0.6330288335292036,-3.0518525617920425
505.60000000000684,63.092271538344484,0.633078269445394,-3.0558982446491245
506.7000000000068,63.20133516423252,0.6339721849217599,-3.055607851407589
507.80000000000683,63.312156557223545,0.637837654413503,-3.05659262434353
508.90000000000686,63.42127859379996,0.6402477584479854,-3.058348244568549
510.0000000000069,63.53082047132865,0.6407917694030042,-3.059218195300142
511.1000000000069,63.639999048507775,0.6431372315951022,-3.059549804612307
512.2000000000069,63.749998959385394,0.6445381660784774,-3.0608597695795625
513.300000000007,63.859280492801965,0.6470099222943969,-3.0621799315382807
514.4000000000069,63.96908589713929,0.6471690891956318,-3.0644119723137857
515.5000000000069,64.07917053538611,0.6510097630849112,-3.064827013672726
516.600000000007,64.18874138267297,0.6528226636109341,-3.066098229931192
517.700000000007,64.29869074142137,0.6527483139414567,-3.0661304971089716
518.800000000007,64.40822986497434,0.6591896241616644,-3.0674805532888128
519.900000000007,64.51843853276111,0.6595424562698919,-3.0700864272206356
521.000000000007,64.62915476867889,0.6619115751641936,-3.070228022527134
522.1000000000071,64.73793937458395,0.6602321823207085,-3.071399739362527
523.2000000000071,64.8487720302301,0.6617197302135954,-3.0737103671287853
524.300000000007,64.95869796502117,0.6650502531717316,-3.073097270343873
525.4000000000071,65.06762980142548,0.664819245190458,-3.073711489879578
526.500000000007,65.17822689088224,0.6629829124867179,-3.0759318661293777
527.6000000000072,65.2886526138344,0.6640650835239447,-3.0773308103745247
528.7000000000071,65.39946061443469,0.663963547812402,-3.0770095683853986
529.8000000000072,65.50892955046383,0.6626913209113515,-3.077329398982693
530.9000000000071,65.61843228607871,0.6608570649738663,-3.0799609821340708
532.0000000000072,65.72811042034083,0.6635450899611005,-3.0799668959901645
533.1000000000072,65.83825338332625,0.6656946895168718,-3.0812843221772743
534.2000000000072,65.9476500060571,0.6641688933215989,-3.0839661036643595
535.3000000000072,66.05702301130037,0.6610412192628358,-3.0841350222298907
536.4000000000073,66.1677930421303,0.6608118608641413,-3.085532855684141
537.5000000000073,66.277119321647,0.663448866332933,-3.0842774594881215
538.6000000000073,66.38765251280448,0.6630049148979028,-3.085519736909448
539.7000000000073,66.4970189402837,0.6618048864528098,-3.0868799223723133
540.8000000000073,66.60706912549573,0.6623574830413442,-3.0872091561903705
541.9000000000074,66.71554962205309,0.6627607662948746,-3.0884590570256365
543.0000000000074,66.82648205370525,0.6642090259141451,-3.0885301328092947
544.1000000000074,66.93660380398023,0.6641682522295578,-3.0900487988124503
545.2000000000073,67.04596671682215,0.6614770624443549,-3.090831244746246
546.3000000000073,67.15683336233538,0.6613277787582936,-3.0920452908245206
547.4000000000074,67.2676158706129,0.6629238201929201,-3.0923210365994103
548.5000000000074,67.3769904535717,0.6613047011225217,-3.0934328684343795
549.6000000000074,67.48664764918051,0.660261807307403,-3.096109968286007
550.7000000000074,67.59759635342444,0.6622363901991302,-3.0974218321401232
551.8000000000075,67.70663323567715,0.6600034976169697,-3.097417280041476
552.9000000000075,67.81737445338243,0.6587086797014374,-3.098743201666385
554.0000000000075,67.92831731909853,0.6573513306493427,-3.100720719814851
555.1000000000075,68.03759135048246,0.6570334779630009,-3.1007219120039835
556.2000000000075,68.1483948448545,0.6606446382894969,-3.10203910700489
557.3000000000076,68.25890482222121,0.6589765228593633,-3.103349527746528
558.4000000000076,68.36966746214809,0.6593695900197102,-3.104658470189575
559.5000000000076,68.4800000000008,0.6580585759731626,-3.104670127999641
560.6000000000076,68.5907171349738,0.6597353744252809,-3.1059899847551278
561.7000000000077,68.70125833911158,0.6619408146965324,-3.105036048571017
562.8000000000077,68.81210851997388,0.6584962412246996,-3.105959844857164
563.9000000000076,68.92192790111127,0.6608594542060094,-3.1059976911326386
565.0000000000076,69.03249610414382,0.6615815968718253,-3.1073101381577715
566.1000000000076,69.14246651889793,0.6628260384579792,-3.109936221432372
567.2000000000077,69.25265594307486,0.6631656324266592,-3.109286001961532
568.3000000000077,69.36391163151865,0.6662557315706455,-3.1092885360903404
569.4000000000077,69.47391892562837,0.6658641034917445,-3.1119090977340447
570.5000000000077,69.58500917695149,0.6666273615260352,-3.1118179838760573
571.6000000000078,69.69512023046937,0.6681183130186811,-3.1118817896480655
572.7000000000078,69.80612417036772,0.6679902341703916,-3.113208021561066
573.8000000000078,69.9163720657626,0.6671187473683844,-3.113560292217617
574.9000000000078,70.02698661432976,0.6669504936473677,-3.1158704191743993
576.0000000000078,70.13838213179164,0.6675292900712949,-3.1168674647418038
577.1000000000079,70.24861103090757,0.6683204789697963,-3.116203356233421
578.2000000000079,70.35832049860997,0.6700083018461106,-3.1177724293494022
579.3000000000079,70.46972224819987,0.6715883777515158,-3.1188302160864256
580.4000000000078,70.58048512858356,0.6716280131789665,-3.118830139731054
581.5000000000078,70.69124605010747,0.6755462483155292,-3.1198034092441698
582.6000000000079,70.8017334657442,0.6756645036429595,-3.119820084958171
583.7000000000079,70.91192785983617,0.6822582881939993,-3.121141313956416
584.8000000000079,71.02338943350927,0.681302723325493,-3.12178991454296
585.9000000000079,71.13382219995853,0.685670074634787,-3.123118699456445
587.000000000008,71.24527068073195,0.6889160429198944,-3.1231032597401125
588.100000000008,71.35605112753095,0.6897638753390651,-3.1244351468912694
589.200000000008,71.46750672941823,0.6946108232429352,-3.1250928343961033
590.300000000008,71.57788712501561,0.6991477588510588,-3.124458140671162
591.400000000008,71.68868595680131,0.6995107629403231,-3.1246802581267614
592.5000000000081,71.8000000000008,0.7023269209657272,-3.127720240036073
593.6000000000081,71.90887686931956,0.7033506930074462,-3.127732308850444
594.7000000000081,72.0222047646234,0.7028635509690248,-3.127453241160839
595.8000000000081,72.13329171191475,0.7091248849433981,-3.1279916196612634
596.9000000000082,72.24558420167406,0.7140918488151693,-3.1290399504146786
598.0000000000082,72.3538313437364,0.7146875540271286,-3.130380170317548
599.1000000000081,72.46811980787659,0.7170039002214385,-3.1304250933927866
600.2000000000081,72.57813823798509,0.7215911616736785,-3.131004555998186
601.3000000000081,72.69021885282177,0.7225658204849931,-3.132352801509894
602.4000000000082,72.80010090214833,0.7250734482489505,-3.1323384371385803
603.5000000000082,72.91173830290589,0.7305477926044316,-3.1336626075712806
604.6000000000082,73.02287201673703,0.733125383561122,-3.133650047468712
605.7000000000082,73.13399087550546,0.7337195110992858,-3.133650089626662
606.8000000000083,73.24498913345397,0.7384442901228875,-3.135245936377002
607.9000000000083,73.3561922035914,0.7405659135646565,-3.1358794847131617
609.0000000000083,73.4670784993506,0.7460057614584225,-3.1366401011880596
610.1000000000083,73.57732424306057,0.7491369163432774,-3.1373495280410983
611.2000000000083,73.68838811372609,0.7521273442196528,-3.1371275160541288
612.3000000000084,73.80146955814399,0.7556570210892503,-3.137599888268469
613.4000000000084,73.9123351845095,0.7571018859638587,-3.138858448068385
614.5000000000084,74.02293857308081,0.7616575629882223,-3.140059472449013
615.6000000000083,74.13219141255989,0.7636046464973834,-3.140240122725337
616.7000000000083,74.24512186141921,0.7652106868741866,-3.1402519030449807
617.8000000000084,74.35664707795532,0.7680105666533644,-3.1425572055276136
618.9000000000084,74.46738843509861,0.7721939871166854,-3.1437706606899964
620.0000000000084,74.57910817690471,0.7760949731635294,-3.143860797074999
621.1000000000084,74.69070352231141,0.7816877244715695,-3.1438859934539902
622.2000000000085,74.8021519022121,0.786348614023182,-3.1438694489709307
623.3000000000085,74.91303713143817,0.7934273493317568,-3.145170011800997
624.4000000000085,75.02408695612554,0.7930506923031342,-3.1464907274780725
625.5000000000085,75.13637526143476,0.7989416557725425,-3.147490313759029
626.6000000000085,75.24766401799612,0.8036439071811896,-3.148951608628435
627.7000000000086,75.3586832827593,0.8078541090432871,-3.1484684004002323
628.8000000000086,75.47010182621716,0.814720847323154,-3.1478148572514417
629.9000000000086,75.58115949644487,0.814386064057805,-3.151226211944647
631.0000000000086,75.69252119336981,0.8201080095573721,-3.150449576132079
632.1000000000087,75.8038789675712,0.8244907218134495,-3.151769482405132
633.2000000000087,75.91549114244384,0.8259240042617515,-3.1530886843640973
634.3000000000086,76.02611252288771,0.8306742384442727,-3.155710453824672
635.4000000000086,76.13677403664222,0.8369357783134717,-3.1557110456980118
636.5000000000086,76.24892175830293,0.8398354453102258,-3.1570956779523534
637.6000000000087,76.3600022438499,0.843939121025582,-3.15572024270431
638.7000000000087,76.47174926153535,0.8447693573879881,-3.1577696158628754
639.8000000000087,76.58412362067571,0.8515676029181045,-3.1590402262382575
640.9000000000087,76.69462142030596,0.8539703542578657,-3.1609880237301446
642.0000000000088,76.80617968199918,0.8544031174709057,-3.159613340892043
643.1000000000088,76.91854492839683,0.855295869765873,-3.1630686763125286
644.2000000000088,77.02960391582977,0.8593160156259195,-3.163303380604753
645.3000000000088,77.14145977038065,0.8596219573738122,-3.1643839108242013
646.4000000000088,77.25363266969795,0.8620069619978454,-3.165605632972621
647.5000000000089,77.3649654423252,0.8636879679670166,-3.1663726205018476
648.6000000000089,77.47693088830374,0.8648562605640187,-3.1672485218751554
649.7000000000089,77.58828456555648,0.8671232069415208,-3.1685600315876092
650.8000000000088,77.69968650858348,0.8674030181474085,-3.169879789968085
651.9000000000088,77.81115567530864,0.8683017904310438,-3.1703159825696616
653.0000000000089,77.92329330603901,0.8683865950412413,-3.1725206550649414
654.1000000000089,78.0353727160136,0.866369190686927,-3.1713367022703336
655.2000000000089,78.1470399905533,0.8674957650434327,-3.172512863117861
656.3000000000089,78.2569528668582,0.8691354468586845,-3.172509685328011
657.400000000009,78.36955605839393,0.8668973095306812,-3.1738328538059832
658.500000000009,78.48197824068885,0.8682525496400356,-3.1751502733769796
659.600000000009,78.59276912227318,0.8688581287706476,-3.1757567456715607
660.700000000009,78.70410932220493,0.8670582718732917,-3.1777950352790993
661.800000000009,78.81565332845976,0.865725252449948,-3.176459494741759
662.9000000000091,78.92636274657717,0.8651707353348415,-3.177779917464081
664.0000000000091,79.03918753545959,0.8609379226401735,-3.1780432536260657
665.1000000000091,79.15146462929494,0.8632729304770201,-3.178962855242088
666.2000000000091,79.26282454950224,0.8625172999182756,-3.180093737107525
667.3000000000092,79.37487585815558,0.8660314113578726,-3.1814087666229156
668.4000000000092,79.48723651485707,0.8646806387209842,-3.180423050667894
669.5000000000091,79.59935827259402,0.8627778442230262,-3.181712242303405
670.6000000000091,79.71068628798206,0.8638019828252654,-3.180419016941307
671.7000000000091,79.82390998445246,0.8667979520885511,-3.181721924229473
672.8000000000092,79.93558929946042,0.8716772312015914,-3.1824002397483997
673.9000000000092,80.048035237702,0.8748603588744714,-3.1843800330023915
675.0000000000092,80.15979835829951,0.8727048927108035,-3.184370012570764
676.1000000000092,80.27217641971235,0.873813200357118,-3.184370529422583
677.2000000000093,80.38409143943387,0.879183206043715,-3.184037273886161
678.3000000000093,80.49618375348919,0.8843420209487475,-3.1840405431777046
679.4000000000093,80.60834836290563,0.8848844032731874,-3.1856852547292167
680.5000000000093,80.72153517328978,0.888635216383836,-3.187009369732725
681.6000000000093,80.83283095414825,0.8903083259168653,-3.186016528743912
682.7000000000094,80.94474062352889,0.8958463692108243,-3.1873400830512644
683.8000000000094,81.05600622326752,0.8977237992859817,-3.187339811585913
684.9000000000094,81.16944617875282,0.8997659929334523,-3.188645373578966
686.0000000000093,81.28095330872759,0.9061166701298428,-3.188325107220897
687.1000000000093,81.3940617279414,0.9108458955825636,-3.1883087102181253
688.2000000000094,81.50583697565835,0.9123372997853957,-3.189651654213581
689.3000000000094,81.61602110648712,0.9178945533836522,-3.188330199346911
690.4000000000094,81.72979564193511,0.9204643492108093,-3.1883302240000093
691.5000000000094,81.84221593829392,0.9247726046542414,-3.188330631724156
692.6000000000095,81.95446808489265,0.9291499879599002,-3.190660286485639
693.7000000000095,82.06595464936413,0.9345917507949831,-3.190623365061343
694.8000000000095,82.17851555853969,0.9385650753437784,-3.191940016252733
695.9000000000095,82.29120888502814,0.9445084041642735,-3.192555303841901
697.0000000000095,82.40329083902105,0.9475912939319091,-3.1919498722080784
698.1000000000096,82.51505014012572,0.9571262147436408,-3.1930150080253084
699.2000000000096,82.62747462039779,0.9623095823149768,-3.1932702224484872
700.3000000000096,82.74037282189403,0.9631195728044033,-3.19396623277101
701.4000000000096,82.85260601455617,0.9663200408117768,-3.1932587564713693
702.5000000000097,82.96438235756716,0.9732058573115694,-3.193646696991309
703.6000000000097,83.07657482739361,0.9760594979126729,-3.194531209708853
704.7000000000096,83.18812893398848,0.9790740718093618,-3.1968898967774066
705.8000000000096,83.30057019825384,0.9817663131222278,-3.1975990553844857
706.9000000000096,83.41349790167685,0.9881228654054814,-3.1968902592009516
708.0000000000097,83.52564497179279,0.9869911135245166,-3.1955697475305573
709.1000000000097,83.6361040559804,0.9967290648252054,-3.1968803667904897
710.2000000000097,83.75007656889976,1.0000562077369006,-3.1981694318332714
711.3000000000097,83.8625372518388,0.9992711916269907,-3.198784128743007
712.4000000000098,83.97513820301819,1.0018015528498503,-3.1985109138638625
713.5000000000098,84.08706791014494,1.0093356930277586,-3.198483340381255
714.6000000000098,84.19871929903718,1.0121415300972891,-3.1998451793738862
715.7000000000098,84.31182229731202,1.0152942949288466,-3.201170235108999
716.8000000000098,84.42167863117349,1.0187820620651356,-3.1998475889861737
717.9000000000099,84.53617135603609,1.0280482618970175,-3.201201751700104
719.0000000000099,84.64882935767727,1.026224251966708,-3.2021501676992576
720.1000000000099,84.76103159221866,1.0309167710278067,-3.200811573164522
721.2000000000098,84.87210598183671,1.0373183795945933,-3.202146383511497
722.3000000000098,84.9856655056183,1.041524782862254,-3.203469874104802
723.4000000000099,85.09866622761515,1.0455067927771633,-3.2034698713875454
724.5000000000099,85.21054878519934,1.0487840453147497,-3.202153123970362
725.6000000000099,85.32415793823144,1.0515981576952749,-3.2021598725526212
726.7000000000099,85.43681988159643,1.0538396715930298,-3.203444045802253
727.80000000001,85.55000096906723,1.0605066484592538,-3.2034802778818374
728.90000000001,85.66228646924658,1.0603005173471078,-3.2047901599282613
730.00000000001,85.77563187760921,1.0565013834987695,-3.204790170731477
731.10000000001,85.88837607036112,1.0623958440302839,-3.206109575254045
732.20000000001,86.00144931903762,1.063591678122365,-3.2061100168127914
733.3000000000101,86.11119565086818,1.0677127384073528,-3.2064673663769443
734.4000000000101,86.22607181310455,1.0721246190559197,-3.2074288240454734
735.5000000000101,86.33856118605347,1.0738227576270911,-3.207100031375992
736.6000000000101,86.45114444283017,1.0739127068185248,-3.2074234031454174
737.7000000000102,86.56438412552885,1.0766581348912383,-3.208788876119903
738.8000000000102,86.6773081730379,1.0846688901969648,-3.207422574662575
739.9000000000101,86.78980190029849,1.0868915599068931,-3.208742411930322
741.0000000000101,86.90187632725025,1.0881120518637681,-3.2093984617921683
742.1000000000101,87.01466653951962,1.0913648569532168,-3.2086264776839606
743.2000000000102,87.1276274629997,1.0900483476121943,-3.2099001090517185
744.3000000000102,87.24126969518575,1.0955167193003135,-3.209289876112483
745.4000000000102,87.35291015927518,1.0993706149390405,-3.2106115710980196
746.0000000000102,87.41560515302051,1.1075867720949093,-3.211926828023273