File: 01_Data/Corrugated_Cardboard/STA/N2/10K_min/Corrugated_Cardboard_STA_N2_10KData_230818_R5.csv
##Temp./Â°C,Time/min,DSC/(mW/mg),Mass loss/mg
28.0,15.61017126031175,0.05869245120604649,-0.08429454888180521
29.100000000000016,16.021329737843274,0.10656600504227409,-0.08611138489142123
30.20000000000003,16.257816403331805,0.1399159495674871,-0.08758944184515816
31.300000000000047,16.450195020274442,0.17062436202877995,-0.0889715665579689
32.40000000000006,16.61578790957695,0.1917738276556502,-0.0900907348908353
33.50000000000008,16.76798461573695,0.21162234501887944,-0.08932320680494854
34.600000000000094,16.913577670351742,0.22603266537293187,-0.09154426739250443
35.70000000000011,17.053982701125886,0.24160333137812806,-0.09215224088386131
36.800000000000125,17.188427516838825,0.25714885986601765,-0.09164041799187883
37.90000000000014,17.319692870499008,0.2688222338554802,-0.09262390051731595
39.000000000000156,17.450243550383636,0.28173379715400304,-0.09523899649790568
40.10000000000017,17.57587861995468,0.29311374704066595,-0.09562933376113136
41.20000000000019,17.70473959595659,0.30307991982642335,-0.09643390169301025
42.3000000000002,17.828804954407047,0.3160577963249771,-0.09857600891743123
43.40000000000022,17.95269988000519,0.32635048352093077,-0.10114455943869638
44.500000000000234,18.077293979569173,0.3370024092335191,-0.10001536609894801
45.60000000000025,18.19862825219638,0.34710392546049507,-0.10221255443775723
46.700000000000266,18.31804038462943,0.35821107930870855,-0.1029747982500604
47.80000000000028,18.439286726715057,0.3694527523177116,-0.10495144201565587
48.9000000000003,18.559833196458186,0.3803303908000293,-0.10529082839431725
50.00000000000031,18.67767638709546,0.39207193274202834,-0.10666144963357427
51.10000000000033,18.795559436745837,0.40045801145820903,-0.10923952464622433
52.200000000000344,18.911782781195225,0.4104623688299476,-0.11055981522897351
53.30000000000036,19.03069491306149,0.42419182406795874,-0.11198568461220981
54.400000000000375,19.147789465013975,0.4337940841112844,-0.11443852475987581
55.50000000000039,19.26352847608584,0.44585112042467934,-0.11576813401748831
56.600000000000406,19.38023826610893,0.4545420297647049,-0.1184638026257967
57.70000000000042,19.493856225817606,0.4609817423447178,-0.12110707000190413
58.80000000000044,19.60983649981701,0.47179044152816596,-0.12241026720233972
59.90000000000045,19.72215890420883,0.4811294710860714,-0.12504996467480423
61.00000000000047,19.837273414653676,0.4884486522330287,-0.1275267114163099
62.100000000000485,19.95122908938082,0.49676842983716907,-0.12904297465534453
63.2000000000005,20.06327155327074,0.5020681480697713,-0.1303472436737656
64.30000000000052,20.17378282307419,0.5102532683985952,-0.1329501279543197
65.40000000000053,20.285318758019937,0.5144046221810012,-0.13426217913238014
66.50000000000054,20.393576637141617,0.5180564056264401,-0.13689635795878496
67.60000000000056,20.50724284926337,0.5223564421496634,-0.13953223248238356
68.70000000000059,20.619802445458056,0.5262911353157844,-0.1421719239265311
69.8000000000006,20.730527958904933,0.5291640274559364,-0.14480630253496463
70.9000000000006,20.841108207777193,0.5272621926804215,-0.14743366682403902
72.00000000000063,20.951749725710187,0.5306917872481474,-0.15006474568077977
73.10000000000065,21.061815804109486,0.5310788287370309,-0.15268990609384048
74.20000000000066,21.171252989375677,0.5307447053329528,-0.15531139142566275
75.30000000000067,21.28191562435863,0.5303621698519256,-0.1566838055970523
76.40000000000069,21.390673555040028,0.5299398911675584,-0.15929372310527645
77.50000000000071,21.500058578861942,0.5233052674795655,-0.16194917406435616
78.60000000000072,21.607655898141513,0.5216912733246173,-0.16456162551074938
79.70000000000073,21.71802820282243,0.5191129431189112,-0.16588027296572116
80.80000000000075,21.82732660959872,0.5119967948117152,-0.1685256627957692
81.90000000000077,21.937362912098777,0.5063049002732711,-0.16983812520236974
83.00000000000078,22.04495148240678,0.5030658785782718,-0.17116008822556017
84.10000000000079,22.153695664122843,0.49671400850717173,-0.1737810635916417
85.20000000000081,22.25886737922266,0.49092622384815754,-0.1764201623666013
86.30000000000084,22.369484194035515,0.48550432785002484,-0.1790502212816305
87.40000000000084,22.477348166192265,0.4779217063686334,-0.17908152179748082
88.50000000000085,22.58287323212497,0.47194450716137437,-0.18039034353386052
89.60000000000088,22.69248366265371,0.46288518259997424,-0.18301586790389113
90.7000000000009,22.800352894482813,0.45644532715077446,-0.18431993657379353
91.8000000000009,22.906688550544352,0.4484557106114193,-0.18563925458752806
92.90000000000092,23.014772622768668,0.4412008158259113,-0.18827986183600887
94.00000000000094,23.122352113345137,0.43412909819953693,-0.1882749449103125
95.10000000000096,23.227142853877233,0.42724788590982254,-0.19091988980553465
96.20000000000097,23.334440688448687,0.4184363749446016,-0.19083558541544487
97.30000000000098,23.442003986324472,0.41088444767648435,-0.19223911944754724
98.400000000001,23.54749377646107,0.4048527708564853,-0.19354952338689557
99.50000000000102,23.652745680260658,0.398518508240687,-0.1926004472368521
100.60000000000103,23.76048322605792,0.3916423317322517,-0.19388014269514287
101.70000000000104,23.866546739586802,0.38486131849444893,-0.19651827208711659
102.80000000000106,23.972510429937536,0.37887063626631634,-0.1975035484139438
103.90000000000109,24.077763569060465,0.3758728978772472,-0.19782997628596988
105.0000000000011,24.184217316379847,0.3690038121995436,-0.19783015660963255
106.1000000000011,24.290840444198214,0.3637736514265748,-0.19915010884448447
107.20000000000113,24.39521744918038,0.3583671323566042,-0.1978404815916086
108.30000000000115,24.502182145429344,0.3535945882132283,-0.19928634718353688
109.40000000000116,24.60898883104231,0.34881004492650836,-0.1998088015849886
110.50000000000117,24.71463771738667,0.3456776099355987,-0.20012691905611524
111.60000000000119,24.821843596754405,0.3418373884793693,-0.2012230713336547
112.70000000000121,24.927946426408177,0.33672993121839756,-0.20276992310994446
113.80000000000122,25.033142203209252,0.3320160572706634,-0.20277549889970237
114.90000000000123,25.139389001316285,0.33017954899832835,-0.20275154628627368
116.00000000000125,25.24475903968769,0.3263260137181674,-0.2027698504721469
117.10000000000127,25.351388389764,0.32518259864501253,-0.2041038624525271
118.20000000000128,25.457978378188006,0.3210807110640681,-0.20310000923921923
119.30000000000129,25.562708971015844,0.31847007662449833,-0.20310008877045105
120.40000000000131,25.66997176027464,0.31800106365650826,-0.2044198250387428
121.50000000000134,25.77438530133714,0.31617921360311696,-0.20445458487978208
122.60000000000134,25.879079388463108,0.3145953773142407,-0.20441727795124276
123.70000000000135,25.985722149653352,0.3129102418040395,-0.20540680170443393
124.80000000000138,26.093146167154945,0.3111675305233572,-0.2054000560069209
125.9000000000014,26.197379727684748,0.30886990330313857,-0.20541372266298152
127.0000000000014,26.304275993046396,0.3104005008508306,-0.20540017376942954
128.10000000000142,26.40907519588576,0.30781538941064057,-0.2058038100420223
129.20000000000144,26.515720060398017,0.30883736615404,-0.20672017563397604
130.30000000000146,26.616660803518855,0.30757844568000636,-0.20668984946624036
131.40000000000146,26.725244514094495,0.3091481261494815,-0.20541008895592272
132.50000000000148,26.832365436730484,0.3077551808964756,-0.20541008800648086
133.6000000000015,26.9378927914169,0.3076392068302094,-0.20541438147459523
134.70000000000152,27.043389249437517,0.30894187752495417,-0.20540971804949582
135.80000000000155,27.14965191695854,0.3093565148838804,-0.2054097995660813
136.90000000000154,27.254552954866185,0.30765234539637576,-0.20681466693263628
138.00000000000156,27.358534664479873,0.30889162033682926,-0.20671977887284987
139.1000000000016,27.466072758637523,0.3086595949399762,-0.20671887984690684
140.20000000000158,27.57070012377144,0.3105474763234237,-0.2067199200001717
141.3000000000016,27.676221412605955,0.31312921816515393,-0.2067203254040444
142.40000000000163,27.78125675255229,0.31211160052993514,-0.20540010513978935
143.50000000000165,27.886752869336725,0.31309080581431137,-0.20672047943599559
144.60000000000167,27.992984760732718,0.3140943052807035,-0.20672073938343338
145.70000000000167,28.096958598877745,0.3133220593029815,-0.20705009003331387
146.8000000000017,28.202374852750953,0.31637408180564464,-0.2070472391950804
147.9000000000017,28.308821324633875,0.3147274398008437,-0.2070601175260749
149.0000000000017,28.414389460750858,0.3147269759083082,-0.20836907386641412
150.10000000000173,28.51840852796522,0.31644231210645524,-0.2083700240022126
151.20000000000175,28.624544109740118,0.3182140575592811,-0.20835797130344202
152.30000000000177,28.728623964600253,0.3180926852061108,-0.20704405610754595
153.4000000000018,28.832629681258204,0.32100238853469554,-0.2083701437490415
154.5000000000018,28.94023465644846,0.3211042327757443,-0.20762075260150548
155.6000000000018,29.044843675049272,0.3219458911352404,-0.20704985633525208
156.70000000000184,29.1492593474715,0.3220689272511199,-0.2073425571107692
157.80000000000183,29.25473214226698,0.32358236431820653,-0.2083698552814961
158.90000000000185,29.35881301479825,0.3242442716142442,-0.20837134547562375
160.00000000000188,29.46458097402741,0.3268192507915184,-0.20830102115738924
161.1000000000019,29.569613670006664,0.3270007636512131,-0.20836997786016287
162.20000000000192,29.67459065252347,0.3271254421176921,-0.20967824849934447
163.30000000000192,29.779170000000192,0.3301940514311321,-0.20967997600078858
164.40000000000194,29.885124845524714,0.33013674389141867,-0.20999592166457637
165.50000000000196,29.98985796825737,0.3330104553810478,-0.21163337614377076
166.60000000000196,30.09368549839498,0.3316286167459692,-0.21098367565138876
167.70000000000198,30.1991700000002,0.3332132271963957,-0.20968988797310795
168.800000000002,30.30408487038312,0.33311333783956476,-0.2095871576641466
169.90000000000202,30.40945162121598,0.33520580985754345,-0.21100988907171692
171.00000000000205,30.514736761558236,0.33594842449867457,-0.2096909761332557
172.10000000000204,30.618142710813707,0.33757059400164957,-0.20969105925487463
173.20000000000206,30.724353122487614,0.3381518514201878,-0.20969000800851845
174.3000000000021,30.82961739600319,0.3375545476448991,-0.20969006244880628
175.40000000000208,30.934354601626595,0.3400930201349208,-0.2110088074202192
176.5000000000021,31.038758472055704,0.3422267973057409,-0.21167014923545624
177.60000000000213,31.144828490638865,0.3411410321986157,-0.2107506647073154
178.70000000000215,31.24966393827317,0.3417992013733666,-0.21162097214253173
179.80000000000217,31.354723398111517,0.34240559483684696,-0.21162781892274074
180.90000000000217,31.459613175014212,0.3435743750844269,-0.21066972782318372
182.0000000000022,31.564412437947333,0.3454939961896799,-0.21329432138188276
183.1000000000022,31.669553854272735,0.34533729483767384,-0.21232108989329923
184.2000000000022,31.77457811513589,0.34726120571445884,-0.2124929708526504
185.30000000000223,31.87836472741712,0.3480385605010423,-0.2136409134816346
186.40000000000225,31.98449059232222,0.35009439431462086,-0.2133098665406683
187.50000000000227,32.088383017326265,0.35138310257327277,-0.21330986400000196
188.6000000000023,32.19395126698574,0.3512155888101143,-0.2133098646825502
189.7000000000023,32.29838535628291,0.35153932893829953,-0.21463825555073734
190.8000000000023,32.40357978524427,0.35239817667531526,-0.2146302631385515
191.90000000000234,32.508867634635344,0.3533578446812813,-0.2133099920647492
193.00000000000233,32.613045806692114,0.35383019870671517,-0.21344199219776083
194.10000000000235,32.718129532023596,0.35559179771495075,-0.21364005594728264
195.20000000000238,32.82340840441255,0.354519838117173,-0.21364005779349649
196.3000000000024,32.92778587804355,0.3559350232917353,-0.21464425365412065
197.40000000000242,33.0327626258951,0.3586315449429329,-0.21463005599569085
198.50000000000242,33.137312974658194,0.3601558889442533,-0.2146300560155887
199.60000000000244,33.241693756046104,0.36036492034571244,-0.2146312601853091
200.70000000000246,33.34663324524445,0.3614253658044686,-0.21562002459220864
201.80000000000246,33.45168483114724,0.3614678818005308,-0.21660004846448322
202.90000000000248,33.55614117275993,0.3614961817739655,-0.21659946772116268
204.0000000000025,33.66114637209034,0.3615522005790628,-0.21792017807673592
205.10000000000252,33.764699948908856,0.3626918451061314,-0.2165937899837158
206.20000000000255,33.86983701614077,0.3642165306910017,-0.21858190827078472
207.30000000000254,33.97435505757842,0.36330418600591674,-0.21727134060865838
208.40000000000256,34.07803993058775,0.3643679821114907,-0.21725986400490704
209.5000000000026,34.18270916650625,0.3656150744040332,-0.217259439421138
210.60000000000258,34.287457350634014,0.3645140307657473,-0.21859289509013458
211.7000000000026,34.391371014564825,0.36734355084925263,-0.219900128825532
212.80000000000263,34.49646485208756,0.3665219915803264,-0.2212191336945062
213.90000000000265,34.60099046768323,0.36823309941243587,-0.22122010146004278
215.00000000000267,34.70530121560574,0.36740524212958237,-0.22088982250278155
216.10000000000267,34.80801223232297,0.36838004392949597,-0.2208895542078153
217.2000000000027,34.915651978802245,0.3698711111705948,-0.2215530562589283
218.3000000000027,35.019260064012315,0.3675477440247943,-0.22352147565794134
219.4000000000027,35.12386529539841,0.3679828961541338,-0.22351981893371775
220.50000000000273,35.22869155372352,0.3708827601799132,-0.22483985807087503
221.60000000000275,35.33352459365085,0.36805287122442887,-0.22351346871830602
222.70000000000277,35.437957238970675,0.37183413025906686,-0.22483982284366233
223.8000000000028,35.54230335498024,0.369697777178533,-0.22743731241356446
224.9000000000028,35.647152326559365,0.3700331182432197,-0.22878348739525523
226.0000000000028,35.751718791484976,0.3725364589467486,-0.22781009775071048
227.10000000000284,35.855932585791194,0.37344665803669264,-0.22773523811238494
228.20000000000283,35.96160981863305,0.3738573023208638,-0.2297701083416066
229.30000000000285,36.06679923689557,0.37529876984842336,-0.22977011110351242
230.40000000000288,36.170891013897574,0.37275512955224843,-0.2300930650527655
231.5000000000029,36.275794079229875,0.37490648431642426,-0.2314202704714492
232.60000000000292,36.38025235954668,0.37528265133869376,-0.23273181077169802
233.70000000000292,36.48558786998265,0.3764899431942508,-0.23405509733922703
234.80000000000294,36.590181130063456,0.37358608215975164,-0.23441576085633553
235.90000000000296,36.695254638308874,0.37578576790120066,-0.23570160162990073
237.00000000000296,36.79934733419529,0.3753761745087625,-0.23702816927060955
238.10000000000298,36.90444196653433,0.37441705863705876,-0.23958619283710858
239.200000000003,37.00859181434323,0.3732491067280679,-0.24066698905370654
240.30000000000302,37.113345353497,0.3736324831483593,-0.24195673934792783
241.40000000000305,37.21917123651319,0.3721300542271355,-0.24459980873645026
242.50000000000304,37.32304729128429,0.37032786139276075,-0.24603926130719778
243.60000000000306,37.427532580564886,0.3697783951509428,-0.24848382312690553
244.7000000000031,37.53229530238574,0.37033931187185387,-0.24855239818324204
245.80000000000308,37.63734790057678,0.3708298652648261,-0.24983412080118272
246.9000000000031,37.74167537060314,0.370627733219409,-0.2538531363451466
248.00000000000313,37.845438490951445,0.37277423046867897,-0.25513070272209015
249.10000000000315,37.95081758412814,0.3691487448962225,-0.2564452457016948
250.20000000000317,38.05560850639709,0.36914942234328074,-0.25909083085045337
251.30000000000317,38.16036173973664,0.3688475413514598,-0.2617255300178063
252.4000000000032,38.26442828993714,0.36895321338657827,-0.2643676657328604
253.5000000000032,38.366826405372876,0.3688070263024077,-0.26561577572719486
254.6000000000032,38.47374833876251,0.3681523119219712,-0.26826784206456855
255.70000000000323,38.57817546042094,0.3680161603744663,-0.27101994610083535
256.80000000000325,38.683075784606224,0.36784444012758843,-0.27553772338432836
257.9000000000033,38.78782329798365,0.3654621852067892,-0.2794401876233388
259.0000000000033,38.89280761772208,0.3668776576086519,-0.2831592074829521
260.1000000000033,38.9970432245686,0.368345812115245,-0.2864343384211274
261.20000000000334,39.102284933908294,0.3681886501928564,-0.2896069941486701
262.30000000000337,39.206132266669286,0.36622947179455023,-0.2938073527452518
263.40000000000333,39.3113492661032,0.3662200886216074,-0.2980974148065636
264.50000000000335,39.41442474165436,0.3662576501376893,-0.3026590803043048
265.6000000000034,39.521859401833254,0.36896833121205397,-0.30745543554225563
266.7000000000034,39.626489008885784,0.367552613652554,-0.3125416536970085
267.8000000000034,39.73245669002897,0.3673593672070825,-0.3170640497171253
268.9000000000034,39.83769339139551,0.36794843639647135,-0.32216156883962865
270.0000000000034,39.942490254098715,0.36810270846419546,-0.32784892149488476
271.10000000000343,40.04737110684568,0.3684628727421351,-0.3333321426348905
272.20000000000346,40.15308257451995,0.36825885174077455,-0.33895591597672503
273.3000000000035,40.25888871457951,0.3670668041550198,-0.34570392737432254
274.4000000000035,40.364325281804724,0.3696191669712541,-0.3519778767943178
275.5000000000035,40.467524813447326,0.37006267522101033,-0.35695170253250064
276.60000000000355,40.57283558174022,0.3695053335555305,-0.36565022262988967
277.70000000000357,40.67954048553313,0.3702248312794991,-0.37318544420090216
278.8000000000036,40.78475761813901,0.37070377809678656,-0.3797835222537729
279.9000000000036,40.88956791060856,0.37101480503080664,-0.3888850006184641
281.0000000000036,40.99475220368067,0.3711511212425773,-0.3961419099921293
282.1000000000036,41.10047254708406,0.3706083861650413,-0.40390544087529134
283.2000000000036,41.205304857315426,0.3707267966627683,-0.4120187580435539
284.30000000000365,41.311207965557976,0.3716454293273437,-0.4239425041978637
285.4000000000037,41.416111918977435,0.3746172047986147,-0.4324460325363444
286.5000000000037,41.52084603075991,0.37577205133162606,-0.4421881953318505
287.60000000000366,41.6260381652859,0.3788707220831873,-0.45331768362831504
288.7000000000037,41.731998947734816,0.3790748718826309,-0.46316538288124054
289.8000000000037,41.83771041699829,0.37987112824612046,-0.4745450607455637
290.90000000000373,41.94244233081167,0.3821419499998635,-0.4869685973577469
292.00000000000375,42.04890077749762,0.383995522844887,-0.49804937916124636
293.1000000000038,42.15386806318386,0.38734763268957817,-0.5104405665747409
294.2000000000038,42.25927257898553,0.38881528448678493,-0.523898468050819
295.3000000000038,42.36484682252547,0.39211897735291723,-0.5372836749380197
296.40000000000384,42.47157575070544,0.39280515617403844,-0.5505164326472078
297.5000000000038,42.576978647805156,0.3956793337831035,-0.5651173214537697
298.60000000000383,42.682780939465246,0.39944487864504064,-0.5789391011736869
299.70000000000385,42.788948755452395,0.40201248720032634,-0.5954232169268638
300.8000000000039,42.89474805886347,0.40502014425276545,-0.6109540901050847
301.9000000000039,43.00026955711504,0.40694216876472233,-0.6266709388182496
303.0000000000039,43.10645057300664,0.41186713496791927,-0.643358768439199
304.10000000000394,43.21183215096568,0.41542154007520216,-0.6603300066986137
305.2000000000039,43.31785455194149,0.4170510105591223,-0.6786720515119873
306.30000000000393,43.423807326476584,0.4213467970235476,-0.6965870805755938
307.40000000000396,43.53023381502424,0.42603602056800316,-0.714748082283752
308.500000000004,43.63652144151703,0.4281807630768315,-0.7339709738388551
309.600000000004,43.74217152301084,0.43127716398265203,-0.7537370413678346
310.700000000004,43.84788505148613,0.43433621685918933,-0.7740938625086535
311.80000000000405,43.953398372367985,0.43779485545657804,-0.7947437912865034
312.90000000000407,44.059776521619554,0.4406871510862669,-0.816165785360718
314.0000000000041,44.16633226641696,0.44783095926991523,-0.8395983918709153
315.10000000000406,44.27210117168877,0.4522074852190965,-0.8616573515017838
316.2000000000041,44.378196544189244,0.4550788195948561,-0.8851735620630174
317.3000000000041,44.48461656480376,0.4596278575260859,-0.908860795663192
318.4000000000041,44.58945669074931,0.46379739247579277,-0.9316978748080378
319.50000000000415,44.696188471977585,0.46908378522805627,-0.9581409815834379
320.6000000000042,44.80197688064082,0.47538071281768657,-0.9831820721597389
321.7000000000042,44.90802141258106,0.47748774101134117,-1.0092730533547423
322.80000000000416,45.015385186675076,0.48444217155554403,-1.0389577282694162
323.9000000000042,45.12105161921723,0.4904286500940642,-1.0660750443073534
325.0000000000042,45.227398018618565,0.49583691852059,-1.094751513716092
326.10000000000423,45.333644366910036,0.499942186601926,-1.1252233691335438
327.20000000000425,45.43858386813224,0.506704823999762,-1.1544888274785037
328.3000000000043,45.54555956621574,0.5108812377555239,-1.1854427639848701
329.4000000000043,45.65130252662382,0.5199690190925805,-1.2184550441090387
330.5000000000043,45.75715819877264,0.5260864609314084,-1.2513589232737368
331.60000000000434,45.86230226652311,0.5293345621990342,-1.2848072970901483
332.7000000000043,45.969784960291,0.5386599818424953,-1.3201279157851218
333.80000000000433,46.0760521948572,0.5474730860688504,-1.3541882541753725
334.90000000000435,46.182181479598476,0.5535316577690239,-1.3927810263575395
336.0000000000044,46.28888243187812,0.5614303468473745,-1.4305870324146555
337.1000000000044,46.3958050251769,0.5713579346807813,-1.4682225129312618
338.2000000000044,46.50165529177122,0.5792865105438891,-1.507389923046155
339.30000000000445,46.60768810131729,0.5890323704807816,-1.5499663353232256
340.4000000000044,46.71539389146259,0.5987117294438695,-1.5904254546356116
341.50000000000443,46.820469643561424,0.6074231069337725,-1.635210389353388
342.60000000000446,46.92826635801561,0.6158718493504336,-1.680402937255828
343.7000000000045,47.03568539886505,0.6228981321923888,-1.7240924425244861
344.8000000000045,47.14213226028299,0.6328499637121814,-1.7703258887937436
345.9000000000045,47.24877776324047,0.6420612863226605,-1.8174973974571897
347.00000000000455,47.353628171088076,0.6480382182178741,-1.8654083089852467
348.10000000000457,47.463216046392056,0.6564434794028242,-1.9148983555505787
349.2000000000046,47.57025831434187,0.659562114896582,-1.965943817605639
350.30000000000456,47.677370107295836,0.6649468221510813,-2.0149524641572247
351.4000000000046,47.78340711340074,0.6618661671576536,-2.0653748909779033
352.5000000000046,47.89053513319675,0.662145996183509,-2.117820083372032
353.6000000000046,47.9971790507598,0.6560815332975098,-2.168569075278519
354.70000000000465,48.10356362635705,0.6506730978235575,-2.218738701343325
355.8000000000047,48.20979228736491,0.6387121375671563,-2.270496930538936
356.9000000000047,48.315652555860765,0.6249021231360712,-2.3190996085267996
358.00000000000466,48.421022676759996,0.6077076486693189,-2.366743180830322
359.1000000000047,48.52784548007899,0.5882090950838412,-2.414298882057892
360.2000000000047,48.63331200594099,0.5628007122070235,-2.4589393863505284
361.30000000000473,48.73888239618014,0.5376997159078039,-2.5010995812863097
362.40000000000475,48.843964901508784,0.5074397112921212,-2.5422345138914375
363.5000000000048,48.94881022686433,0.4766451154839939,-2.579891743958557
364.6000000000048,49.053542720740545,0.4448778181618729,-2.614626209143087
365.7000000000048,49.16055795317187,0.4099816225833395,-2.646397934511226
366.80000000000484,49.26506129047691,0.37880478954013275,-2.676586799226914
367.9000000000048,49.37138098659701,0.34592636003293875,-2.702719968370356
369.00000000000483,49.4770417109724,0.31548227695238085,-2.7260605483160574
370.10000000000485,49.58179139244514,0.28593950069959706,-2.748697295378223
371.2000000000049,49.68695207752332,0.2592819207472592,-2.767463021833479
372.3000000000049,49.79239650919395,0.23430020691497688,-2.7848817460770836
373.4000000000049,49.89758231365556,0.2117492501335403,-2.801057507813046
374.50000000000495,50.00394525455067,0.18546241488678605,-2.814034591297757
375.6000000000049,50.11047495394387,0.16407224465394576,-2.825852369756392
376.70000000000493,50.215011812426106,0.14487430004694413,-2.8370815766222455
377.80000000000496,50.32109766160052,0.12719191133587127,-2.846339656061681
378.900000000005,50.42746524049965,0.1084565927613732,-2.855231925072113
380.000000000005,50.53299109255671,0.09627985201514622,-2.8616193351612074
381.100000000005,50.640236273829444,0.08391135532008676,-2.868438938653929
382.20000000000505,50.745832883005846,0.07451266557642922,-2.873312760620635
383.30000000000507,50.851954278254134,0.06929741957159763,-2.8792132900451133
384.4000000000051,50.95876624147021,0.06386097871537233,-2.884630929698708
385.50000000000506,51.065762967430956,0.055926384438893084,-2.888463676269656
386.6000000000051,51.172742548894234,0.05383816178629197,-2.8931400448127973
387.7000000000051,51.28026050745358,0.04960651811790595,-2.897612103786858
388.8000000000051,51.38593713993175,0.04615760072701436,-2.901046281712394
389.90000000000515,51.49259492237996,0.04265295685438186,-2.904754748109478
391.0000000000052,51.599802558161926,0.039893141515160435,-2.9096338907024872
392.1000000000052,51.70651767153831,0.03720110737857274,-2.911964818908614
393.20000000000516,51.81512730972892,0.03420145602043534,-2.9158458369612203
394.3000000000052,51.92043619507592,0.030646734685040755,-2.918172744734121
395.4000000000052,52.029065055855284,0.02794626447767179,-2.9214510020350604
396.50000000000523,52.136462066413124,0.025201433112302718,-2.9261351801381847
397.60000000000525,52.243720857758184,0.02235140459927787,-2.931556985029655
398.7000000000053,52.349514133674155,0.01872646265289113,-2.9334382020233587
399.8000000000053,52.45648378511349,0.013964007332205375,-2.935851088728218
400.9000000000053,52.564235214335795,0.011733431128304161,-2.9399317912875
402.00000000000534,52.67283296106376,0.009587361519860726,-2.942857858799094
403.1000000000053,52.779796579767314,0.006558439946973138,-2.9467043170846092
404.20000000000533,52.88697886257307,0.0032117249457341845,-2.9508756925298645
405.30000000000535,52.99567586282074,0.002982926826496257,-2.9523344418387873
406.4000000000054,53.10298093898541,-0.0024220686724771845,-2.9548633125247514
407.5000000000054,53.21078766410569,-0.0024989381703157676,-2.959037024515985
408.6000000000054,53.318684484890234,-0.005933973478760901,-2.9627283177036596
409.70000000000545,53.42672589111935,-0.008899621227265841,-2.9653066062548743
410.8000000000054,53.53477070924311,-0.008598905609617402,-2.969085835894469
411.90000000000543,53.642231741802334,-0.01263178244229568,-2.9726979207909023
413.00000000000546,53.750404973100444,-0.012981647556825404,-2.974676310111673
414.1000000000055,53.85857761526219,-0.016099727607090664,-2.9778294827117726
415.2000000000055,53.96616210391421,-0.016481039803749153,-2.980289320992747
416.3000000000055,54.07388428644696,-0.01804402518312309,-2.9846822613667356
417.40000000000555,54.18216820920987,-0.020124314309445834,-2.987342017814771
418.50000000000557,54.290449696144904,-0.020006816786031667,-2.9905006202960416
419.6000000000056,54.398131520029224,-0.022608767714227485,-2.992937095612418
420.70000000000556,54.50665684333774,-0.022256154821927332,-2.9944511286474116
421.8000000000056,54.61414976182255,-0.02419782029849782,-2.998291846210237
422.9000000000056,54.723312369910374,-0.024009027789101856,-3.0008172162306064
424.0000000000056,54.831708883813754,-0.02513946147678503,-3.0045482354425666
425.10000000000565,54.93729122752356,-0.023758373565807123,-3.0063149337961184
426.2000000000057,55.04730470980734,-0.02383566289713146,-3.009910677347051
427.3000000000057,55.15620520045565,-0.022807000162977875,-3.0128874592049018
428.40000000000566,55.2645032780751,-0.02225841108034543,-3.014482648802515
429.5000000000057,55.37189413679962,-0.0204350722631661,-3.016983092940646
430.6000000000057,55.47774926866913,-0.019925445707287492,-3.0213775514221473
431.70000000000573,55.58812043702474,-0.0166329252498032,-3.024436468371978
432.80000000000575,55.695895066616636,-0.014677483565375127,-3.0261846949580815
433.9000000000058,55.80510802899064,-0.0022476915614186854,-3.0288368428666717
435.0000000000058,55.912969881720265,0.014951935804845107,-3.032286726325747
436.1000000000058,56.02112666433905,0.026697802776219692,-3.0347102121618725
437.20000000000584,56.129462384303935,0.03974242453526999,-3.0373810233484306
438.3000000000058,56.23745642446964,0.05489519008139743,-3.03999962333702
439.40000000000583,56.346020785090495,0.06332424830572325,-3.043393534835121
440.50000000000585,56.454152070381724,0.07106722804587906,-3.0451159612807865
441.6000000000059,56.56259841337295,0.08118553899007264,-3.0477052460745293
442.7000000000059,56.671332162483516,0.08392932952667254,-3.049991464668536
443.8000000000059,56.780244568420684,0.08800685170006317,-3.05262676267943
444.90000000000595,56.8878667186205,0.0888649487259332,-3.053177649151432
446.0000000000059,56.9975493580488,0.09257481696135827,-3.0553901187456107
447.10000000000593,57.10534833217283,0.09592281140242864,-3.0579456328838286
448.20000000000596,57.2141405854631,0.09809160719582866,-3.061105634014404
449.300000000006,57.32376502811698,0.1031491545221761,-3.064608769280725
450.400000000006,57.43237873693339,0.10250818815520635,-3.0645741023759703
451.500000000006,57.54054948148678,0.10373636907422568,-3.0675656756873444
452.60000000000605,57.648817142750076,0.10556167054743137,-3.0708323533014497
453.70000000000607,57.75859792792956,0.10368104426306712,-3.0724654301588603
454.8000000000061,57.86486263012739,0.1078023700898334,-3.073426778438883
455.90000000000606,57.97616605053185,0.1075303274409849,-3.0754911782806795
457.0000000000061,58.08481426888533,0.108776646170754,-3.077432724369433
458.1000000000061,58.19317808871614,0.10860545372060804,-3.080136584650319
459.2000000000061,58.30193299571297,0.11116794331478586,-3.082809404040004
460.30000000000615,58.41064671705002,0.113063864790788,-3.0845060920478953
461.4000000000062,58.51999700078801,0.11362619922278894,-3.0856790218119112
462.5000000000062,58.62880222394914,0.115924325872099,-3.086998455196709
463.60000000000616,58.73852669327178,0.11801561486560641,-3.090127115938227
464.7000000000062,58.84693663137343,0.120697981046334,-3.091171929803268
465.8000000000062,58.95553717724163,0.12061936837398357,-3.0925791178784388
466.90000000000623,59.06487060635333,0.12013331725835674,-3.095850886334645
468.00000000000625,59.173706273261786,0.1216474009855677,-3.097114571922789
469.1000000000063,59.28355234983856,0.12119712285781303,-3.098736094566381
470.2000000000063,59.392641479220465,0.12046757123877017,-3.099831720567277
471.3000000000063,59.501819472616546,0.1210368546284395,-3.102569248122961
472.40000000000634,59.61101931314548,0.11448963577418736,-3.1038056161369623
473.5000000000063,59.72073510759324,0.1143492641655981,-3.1065293662249087
474.60000000000633,59.83061640635974,0.11217260143079799,-3.108945496875685
475.70000000000636,59.93974988511736,0.1119096676968494,-3.1088652084263457
476.8000000000064,60.04802864315946,0.1078144964155725,-3.111481052496689
477.9000000000064,60.1563238998486,0.10645645580284624,-3.112802392633606
479.0000000000064,60.26633931858099,0.10475281240307344,-3.1154821487170214
480.10000000000645,60.37621645179923,0.10248721746237655,-3.115479600659524
481.2000000000064,60.48443729266151,0.10411187707273784,-3.117186911782383
482.30000000000643,60.594254101058155,0.10208826193084652,-3.1187352320145796
483.40000000000646,60.703402995770915,0.1000942466994621,-3.120069384499932
484.5000000000065,60.81254353514976,0.09995178721350895,-3.122779672622264
485.6000000000065,60.92142793513175,0.0966429579692969,-3.1236441362744807
486.7000000000065,61.031331675731614,0.0954184046775437,-3.124648757403291
487.80000000000655,61.14017629708616,0.09210967782937618,-3.127288832021656
488.90000000000657,61.24960305761068,0.08580842188540005,-3.1272900014369904
490.0000000000066,61.35861569508657,0.07639022937124795,-3.1286089741389413
491.10000000000656,61.467560913991825,0.05909969385550484,-3.1312372627424434
492.2000000000066,61.57740984540644,0.04743337291243077,-3.132609244117879
493.3000000000066,61.686277694395535,0.03042505536034268,-3.132882836163735
494.4000000000066,61.796486120052755,0.0128854988189544,-3.135563907648068
495.50000000000665,61.905306013799155,-0.0026966979389928536,-3.1342221887372608
496.6000000000067,62.01450857604469,-0.012937629353994673,-3.1355092856821476
497.7000000000067,62.12409361204456,-0.02669403959970218,-3.1375112063553456
498.80000000000666,62.2335506425044,-0.03498077669098976,-3.1401449974832802
499.9000000000067,62.34288571018575,-0.04374067592791242,-3.14013068362598
501.0000000000067,62.45322818854694,-0.04988809841426378,-3.1427374885607096
502.10000000000673,62.56246664921452,-0.05371492088845131,-3.144088557838317
503.20000000000675,62.67242341446172,-0.05511203251344199,-3.1441761246375357
504.3000000000068,62.78117836417456,-0.05938822383207665,-3.145412187332221
505.4000000000068,62.89079729346907,-0.06088747281598339,-3.1470036366095826
506.5000000000068,62.99954859750427,-0.06340897707224102,-3.1467193390048136
507.60000000000684,63.109694446571055,-0.06986082730294285,-3.149350320417577
508.7000000000068,63.21908004738415,-0.07264346177315528,-3.1493470130911634
509.80000000000683,63.327064433847326,-0.0740171381550827,-3.1519903385907817
510.90000000000686,63.43850539237068,-0.07202591518769141,-3.1533699169192158
512.0000000000068,63.54848471289094,-0.07439797572478235,-3.1546760708262678
513.100000000007,63.657123091317494,-0.0745402654864602,-3.1553981653494128
514.2000000000069,63.76682862496436,-0.07642524293615693,-3.155937087723194
515.300000000007,63.87698209718358,-0.07580564298711878,-3.1562651737584035
516.4000000000069,63.98626225862837,-0.07663845219594467,-3.1575806578432832
517.5000000000069,64.095908023167,-0.07600097478854595,-3.160224746789344
518.600000000007,64.2055060487973,-0.07741042907145812,-3.1602302451017965
519.700000000007,64.31504818691859,-0.07928573190340837,-3.162878347093968
520.800000000007,64.4250563830813,-0.0801443121260974,-3.162856209947335
521.900000000007,64.53268437964682,-0.0820050408162567,-3.1641709541654155
523.000000000007,64.64542801322489,-0.07995767392277697,-3.1641738674064284
524.1000000000071,64.75453685751236,-0.0852740403998904,-3.166830153967044
525.2000000000071,64.8650750377847,-0.08545409936627335,-3.1684166631472412
526.300000000007,64.97521372846168,-0.08567948300915251,-3.167463648624251
527.4000000000071,65.08459761950817,-0.08685520705448568,-3.16986901320913
528.500000000007,65.19533810241683,-0.08828606958733887,-3.171409033937935
529.6000000000072,65.30497419755795,-0.08765489392322912,-3.1724595638725215
530.7000000000071,65.41462576003926,-0.08435023139720599,-3.1737067852496317
531.8000000000072,65.52457158170971,-0.08720787393041429,-3.1732474037453673
532.9000000000071,65.63483186869715,-0.08840757325494897,-3.17405379081981
534.0000000000072,65.74447785017117,-0.08940574185605366,-3.1760216199517823
535.1000000000072,65.85544494042641,-0.08853468064369796,-3.176029717129977
536.2000000000072,65.9655832085899,-0.08643570427002878,-3.1772706454415074
537.3000000000072,66.07545667121981,-0.08576321145221089,-3.178686375069984
538.4000000000073,66.18582058660458,-0.08608043697159662,-3.179320970646973
539.5000000000073,66.29637158074662,-0.08391118564009692,-3.1797749480948667
540.6000000000073,66.40607182618558,-0.08296859197409678,-3.181629133031384
541.7000000000073,66.51664269105272,-0.08388016845471102,-3.1829498251375132
542.8000000000073,66.62768663054428,-0.08308015327176688,-3.1842559761246236
543.9000000000074,66.73747361657333,-0.08147031485680856,-3.18558241583471
545.0000000000074,66.84777963505485,-0.07885508413450304,-3.1868571936488825
546.1000000000074,66.9577775001386,-0.080588713204788,-3.1859202168121947
547.2000000000073,67.06916900008017,-0.08012286690910386,-3.1869097946879306
548.3000000000073,67.17936726279413,-0.08023178348515203,-3.1882256283836936
549.4000000000074,67.28907218605029,-0.079347506162593,-3.1888715115604427
550.5000000000074,67.39917000000086,-0.07796756987772957,-3.1895399589226225
551.6000000000074,67.51033024497826,-0.07604067153188754,-3.189769524466007
552.7000000000074,67.61814251579838,-0.07734590041284561,-3.191190097856602
553.8000000000075,67.72871539345641,-0.07786067325444757,-3.1921377890761002
554.9000000000075,67.8407425365816,-0.07747275965764322,-3.1925076887454775
556.0000000000075,67.95101662685765,-0.0747934476377421,-3.195138330622265
557.1000000000075,68.06094260686258,-0.0734577603739166,-3.194809985789554
558.2000000000075,68.1722048538213,-0.07556346518176982,-3.196141975511538
559.3000000000076,68.28220229022044,-0.07347242037571466,-3.1978752892728792
560.4000000000076,68.39161601718567,-0.07344536478493646,-3.198730018269057
561.5000000000076,68.50243225826046,-0.0757844818711666,-3.198766213613216
562.6000000000076,68.61340828577747,-0.07613565082601004,-3.1987571994209008
563.7000000000077,68.72400515513002,-0.07540446983603588,-3.2000799949045344
564.8000000000077,68.8333448690575,-0.07586498399299257,-3.199355382854773
565.9000000000076,68.94478014050817,-0.07821468042393631,-3.2004000534590293
567.0000000000076,69.0547183598478,-0.07780193006927827,-3.2013925807720782
568.1000000000076,69.16626317881665,-0.07864657150044696,-3.2023809282866242
569.2000000000077,69.27621868904055,-0.07713800459887743,-3.202053943906256
570.3000000000077,69.38664543590878,-0.0778983248469356,-3.203370040251478
571.4000000000077,69.4979650135548,-0.08178075732104251,-3.204689775366442
572.5000000000077,69.6083210635006,-0.0799323418672424,-3.2060103820997266
573.6000000000078,69.71927197910674,-0.0770594280954151,-3.2060100324850067
574.7000000000078,69.83028120035858,-0.07881364249648781,-3.2073299813153953
575.8000000000078,69.9412948630326,-0.07909794285327543,-3.208321175836263
576.9000000000078,70.05235012415787,-0.07945027913947622,-3.208705823014337
578.0000000000078,70.16255433636377,-0.07879952125526324,-3.209294428973442
579.1000000000079,70.27196196736895,-0.07965514333103063,-3.210622945930812
580.2000000000079,70.38383404304047,-0.08127475389309269,-3.2106798078600995
581.3000000000079,70.49378406465176,-0.083246084887999,-3.2122601969132987
582.4000000000078,70.60418275276086,-0.08349767984313261,-3.212260138357181
583.5000000000078,70.71538006700501,-0.08401592520252787,-3.2135801846254926
584.6000000000079,70.82647864830483,-0.0820064999258403,-3.213894106612316
585.7000000000079,70.93725949999283,-0.08510452993234763,-3.214094465677006
586.8000000000079,71.04927442780713,-0.08215341274138632,-3.215229842235254
587.9000000000079,71.15978108794751,-0.08429573266864532,-3.216539990293638
589.000000000008,71.27089439617501,-0.08452144074563295,-3.217534368746769
590.100000000008,71.3815144303657,-0.0858524037666275,-3.217058749332078
591.200000000008,71.49231725201824,-0.08427787443623536,-3.217859532177757
592.300000000008,71.60264462931681,-0.084781245694177,-3.2191847835405123
593.400000000008,71.71432876668209,-0.08436660737628032,-3.220820168286956
594.5000000000081,71.82462191966601,-0.08653974887393301,-3.2195245255172384
595.6000000000081,71.93529469429514,-0.08447377437421255,-3.220825076239025
596.7000000000081,72.0465017928663,-0.08512418028526914,-3.2223240309719765
597.8000000000081,72.15716260520293,-0.08610835617579204,-3.2231270357423574
598.9000000000082,72.2687749102485,-0.08670367626621744,-3.2244501413271687
600.0000000000082,72.38006043654421,-0.08514805442897,-3.223789858644836
601.1000000000081,72.49100960348864,-0.08209446202707538,-3.223788651189476
602.2000000000081,72.60098141799453,-0.08542524571261967,-3.2251099716694616
603.3000000000081,72.7120357277655,-0.08221803707101571,-3.2251237213450703
604.4000000000082,72.8222553402692,-0.08504673301462118,-3.226823479318047
605.5000000000082,72.9337644128666,-0.0862789431653539,-3.2267598399766353
606.6000000000082,73.04418595324042,-0.0869710841052842,-3.226760767051382
607.7000000000082,73.15511257617007,-0.08269012150219157,-3.2283927802632615
608.8000000000083,73.26557811021219,-0.08139462951456222,-3.229381383974798
609.9000000000083,73.37702734969695,-0.0766586747789042,-3.2307101029910577
611.0000000000083,73.48714666737513,-0.07541196266377792,-3.2320186268449773
612.1000000000083,73.5986856234818,-0.07416144555162019,-3.2316897459910976
613.2000000000083,73.70888318898407,-0.07439330708310488,-3.232998424980683
614.3000000000084,73.81886220683313,-0.0720339357135722,-3.233330369512409
615.4000000000084,73.92994854220686,-0.07112389382528583,-3.234661025330712
616.5000000000084,74.0412124655725,-0.07201755126268505,-3.2346598098190458
617.6000000000083,74.15208081651681,-0.06729792610702967,-3.2359703931060944
618.7000000000083,74.26280663889173,-0.06548644823880134,-3.2356107322003913
619.8000000000084,74.3731473833201,-0.06353780171033319,-3.2370088552656635
620.9000000000084,74.48442327122234,-0.06238354209427688,-3.2372206336056184
622.0000000000084,74.59777448486726,-0.05929814602838657,-3.2372900583227446
623.1000000000084,74.70723208240808,-0.05398084391345348,-3.23861015537755
624.2000000000085,74.82060109221794,-0.049299837029579185,-3.2399137983793547
625.3000000000085,74.93245644723777,-0.0455342435880004,-3.2412632238758206
626.4000000000085,75.04325797933468,-0.043884226784855596,-3.240915417131407
627.5000000000085,75.15580829704896,-0.04458607109273771,-3.2408829506803114
628.6000000000085,75.26588065347046,-0.04220267831901903,-3.2432427084794426
629.7000000000086,75.37975831045273,-0.04025621942093505,-3.243550198654616
630.8000000000086,75.49012304979323,-0.042032583465455575,-3.2448700048083463
631.9000000000086,75.60163596670542,-0.04045879350947357,-3.244882153364651
633.0000000000086,75.71325679956024,-0.03765482180519086,-3.2475668312418526
634.1000000000087,75.82436865032145,-0.03606859640860116,-3.2475803798846874
635.2000000000087,75.93661271260801,-0.03780826669459714,-3.2479073567580654
636.3000000000086,76.0481287374946,-0.03592556860536211,-3.248821664815029
637.4000000000086,76.15968199865259,-0.03506197442131831,-3.250155833686809
638.5000000000086,76.27221788071147,-0.03667515581152503,-3.250825690284822
639.6000000000087,76.383468966849,-0.034468786018827746,-3.2501448617626094
640.7000000000087,76.49456651610872,-0.03556130846185157,-3.251450084460797
641.8000000000087,76.60572064104332,-0.03771841892046646,-3.252769169040452
642.9000000000087,76.71646725188752,-0.035862191234939944,-3.254075429106605
644.0000000000088,76.82759783390186,-0.036349015360258585,-3.255399703631998
645.1000000000088,76.93997339406431,-0.03925992046511184,-3.2564981633768157
646.2000000000088,77.04998102844928,-0.04029966268884233,-3.256800452461624
647.3000000000088,77.16265372853425,-0.038895831668252834,-3.2588056823520795
648.4000000000088,77.27464434142188,-0.04233194970743259,-3.2589652285043047
649.5000000000089,77.38519308895408,-0.04116178624655009,-3.260682702607918
650.6000000000089,77.49798183246298,-0.042708907055728496,-3.2619767327068447
651.7000000000089,77.6111139118885,-0.045932718242201354,-3.262008536483595
652.8000000000088,77.7211913424056,-0.04704717989441365,-3.2646036414699386
653.9000000000088,77.8336657187204,-0.0504558001337152,-3.2649604022195815
655.0000000000089,77.94491360232753,-0.05598443132721753,-3.2649601214959634
656.1000000000089,78.05623471611474,-0.058236353718297496,-3.2658777288931677
657.2000000000089,78.16749191681176,-0.06203596805926037,-3.2682425236894126
658.3000000000089,78.27586435802718,-0.06652462030220962,-3.2695695366539663
659.400000000009,78.39045664789136,-0.07133428967948285,-3.269334511145652
660.500000000009,78.5011505964578,-0.07507508790031525,-3.2695338485033
661.600000000009,78.61367154004182,-0.07907778596762749,-3.271705437180991
662.700000000009,78.72499576946178,-0.08598036823552846,-3.2721453129274045
663.800000000009,78.836130406994,-0.08939993043320049,-3.272908675759907
664.9000000000091,78.94780489719258,-0.09631165077331971,-3.2741796644450285
666.0000000000091,79.05957921215376,-0.10066945515225179,-3.274195220245622
667.1000000000091,79.17049866737312,-0.10761275417172844,-3.274510031593641
668.2000000000091,79.28046138474693,-0.1102304896863715,-3.27451020008054
669.3000000000092,79.39342508529352,-0.11385783148889272,-3.275506404867425
670.4000000000092,79.50578482448027,-0.11796523686868765,-3.2758316886205145
671.5000000000091,79.61697561419749,-0.12177743794575346,-3.2765607160954557
672.6000000000091,79.72867758466651,-0.12611797994370177,-3.2754992069542026
673.7000000000091,79.84065589593057,-0.12413150549664365,-3.2774616580884985
674.8000000000092,79.95189581246684,-0.12314326472103132,-3.2774733003817036
675.9000000000092,80.0634463778522,-0.12275487782684125,-3.2771191988375725
677.0000000000092,80.1758885299093,-0.1250184395788152,-3.278643945773812
678.1000000000092,80.28742846979269,-0.12536336524691039,-3.277476653327551
679.2000000000093,80.39885089428397,-0.12162498920368603,-3.2794499010979203
680.3000000000093,80.51092060244851,-0.12305655854401598,-3.278203045448761
681.4000000000093,80.62217847574148,-0.12709033763256206,-3.2789322711136495
682.5000000000093,80.73471698547705,-0.12279620614083675,-3.280110183637474
683.6000000000093,80.84573916614504,-0.12140770593397798,-3.2801340786261104
684.7000000000094,80.95714994514148,-0.12017075190158422,-3.2807531126553986
685.8000000000094,81.06958966422884,-0.1211747383356363,-3.282080201484246
686.9000000000094,81.18081845809508,-0.11750458970011701,-3.28213339181849
688.0000000000093,81.29182675997666,-0.11940712803245068,-3.282080045929767
689.1000000000093,81.40389813799813,-0.11915892162765962,-3.282034276906903
690.2000000000094,81.5159143288358,-0.12091413727554157,-3.2833993413157496
691.3000000000094,81.62797236350626,-0.11745834284411605,-3.282647569442021
692.4000000000094,81.74095250194803,-0.11622400490164675,-3.284390150211146
693.5000000000094,81.85275991013407,-0.11071611103676027,-3.2843913228446637
694.6000000000095,81.96481461839727,-0.11230212520953686,-3.2837399386603496
695.7000000000095,82.07709446539289,-0.10999434837904976,-3.2845907283010036
696.8000000000095,82.19052167003187,-0.1118393517307481,-3.285123281574909
697.9000000000095,82.30160724463697,-0.10921833718842522,-3.2840831006981457
699.0000000000095,82.41347289930683,-0.10952986314044066,-3.285380235082903
700.1000000000096,82.52551145879475,-0.10671512495866597,-3.288007729767857
701.2000000000096,82.63690927146129,-0.10429436259185243,-3.2866989189208082
702.3000000000096,82.74873455518937,-0.10365578246508456,-3.286701343343312
703.4000000000096,82.86124675233368,-0.10000386180543419,-3.286033005153418
704.5000000000097,82.97409839812154,-0.09650680127337452,-3.287378058566609
705.6000000000097,83.08419973064926,-0.09628962746267566,-3.288009395306811
706.7000000000096,83.19737365027501,-0.09754550710096588,-3.289391655617778
707.8000000000096,83.30960271715469,-0.0967040556152634,-3.2880098958439605
708.9000000000096,83.41927708312407,-0.09023671779505626,-3.2880099333239965
710.0000000000097,83.53386390623703,-0.09118731025643001,-3.2895632394014656
711.1000000000097,83.64527924808914,-0.0890414498659724,-3.290650063764228
712.2000000000097,83.75717223729204,-0.08533950873483276,-3.290649685202743
713.3000000000097,83.86896784847558,-0.08701033517037438,-3.2919601436807557
714.4000000000098,83.98186786213617,-0.08575554576161526,-3.290640369690612
715.5000000000098,84.09358063126247,-0.084136501188814,-3.291629814602618
716.6000000000098,84.20581757077895,-0.08071412104282638,-3.2919894871040016
717.7000000000098,84.3154510327604,-0.07839237566472157,-3.2932798272933144
718.8000000000098,84.4300830741626,-0.07747723772671655,-3.291980861575545
719.9000000000099,84.54150940719214,-0.07560802223314678,-3.293965751743134
721.0000000000099,84.65391805445654,-0.07000296851422494,-3.293958219430492
722.1000000000099,84.76559977052297,-0.07122153552228605,-3.2939399943792895
723.2000000000098,84.8786182630114,-0.065552126953341,-3.294599313401833
724.3000000000098,84.99088903310653,-0.062210062694736834,-3.295915910667534
725.4000000000099,85.10343473767156,-0.060998736048358815,-3.2958780790881272
726.5000000000099,85.2150796245518,-0.05715014391146278,-3.2972208677072428
727.6000000000099,85.3270051707774,-0.05409164904308028,-3.2972396662080317
728.7000000000099,85.43886864721131,-0.05100330468968206,-3.296579806729625
729.80000000001,85.55178396587537,-0.05026063024605687,-3.297068100278353
730.90000000001,85.66378906263654,-0.04411949159511108,-3.297229599593816
732.00000000001,85.77621031768587,-0.042026052113087076,-3.298549918729986
733.10000000001,85.88826478795293,-0.034161969209858256,-3.2983199029701242
734.20000000001,86.0004971676206,-0.0336981982700193,-3.297889881865993
735.3000000000101,86.1106680743165,-0.030489915955191016,-3.299210474042024
736.4000000000101,86.22518732710274,-0.025117259153044635,-3.3005262601991228
737.5000000000101,86.33668278263502,-0.023663644925871807,-3.300519851160411
738.6000000000101,86.44927705582467,-0.020814470261536933,-3.3008496291564575
739.7000000000102,86.56163418890304,-0.01518622785709045,-3.3018405151550567
740.8000000000102,86.67363639445297,-0.009522892972190444,-3.3018687695473163
741.9000000000101,86.78566626717263,-0.006891196174245717,-3.301520841500415
743.0000000000101,86.89804112738098,-0.0026569422314324243,-3.3028398946245425
744.1000000000101,87.01011157004584,0.004787890810165951,-3.30283933230076
745.2000000000102,87.12315347939241,0.007549266674670374,-3.302463422015196
746.0000000000102,87.20486231670898,0.009916734701280294,-3.303819426556742