File: 01_Data/Corrugated_Cardboard/STA/N2/10K_min/Corrugated_Cardboard_STA_N2_10KData_230816_R3.csv
##Temp./Â°C,Time/min,DSC/(mW/mg),Mass loss/mg
28.0,15.654548080202533,0.05613884895880883,-0.10203085272489476
29.100000000000016,16.036652133263384,0.10527343000133627,-0.10400299240115318
30.20000000000003,16.266945306656943,0.14271065647020054,-0.1055325324456553
31.300000000000047,16.457948231115342,0.17353673724646912,-0.10970893998183673
32.40000000000006,16.62160062742058,0.19811199893196596,-0.10827853845274227
33.50000000000008,16.778084094328193,0.21863447265053537,-0.10976518192680862
34.600000000000094,16.922838927580916,0.23674545778825573,-0.11000389902958752
35.70000000000011,17.062176944688467,0.25342321777010923,-0.11260874796194864
36.800000000000125,17.198805012971995,0.2666532425200461,-0.11341596183213776
37.90000000000014,17.329663157346882,0.2827800414674557,-0.11373984526973846
39.000000000000156,17.45811092530568,0.2935943994788799,-0.11411359668502952
40.10000000000017,17.58659102008742,0.3074459507141065,-0.11528511822016574
41.20000000000019,17.71213044199038,0.31999637073240383,-0.11647402912276039
42.3000000000002,17.836580867340526,0.33472941304081005,-0.11779352578534397
43.40000000000022,17.96021229623333,0.34546883604035483,-0.12040801854548944
44.500000000000234,18.082723698006024,0.35636414912697845,-0.12196164410642352
45.60000000000025,18.205703304271587,0.37197378651502766,-0.12255691614016007
46.700000000000266,18.32558442333915,0.383129412998511,-0.1231737215319213
47.80000000000028,18.447650782961237,0.3985248378043935,-0.1252906558957383
48.9000000000003,18.568201479744474,0.4083268503278126,-0.1277230306512207
50.00000000000031,18.68754978804026,0.41987331439562414,-0.1306783457511913
51.10000000000033,18.8058814721138,0.43332123623029206,-0.13239915713486683
52.200000000000344,18.922168975910985,0.44324599045373003,-0.13372004344652444
53.30000000000036,19.039812678519198,0.4570531423735116,-0.13504157411657536
54.400000000000375,19.157781830319777,0.46537478375587327,-0.13765988849908695
55.50000000000039,19.274980676237213,0.47687662469630654,-0.1389801998187532
56.600000000000406,19.38917000000005,0.48472847577113365,-0.14161220967050658
57.70000000000042,19.505716928006134,0.49466971291817763,-0.14426117852041953
58.80000000000044,19.619634699611662,0.501811505574348,-0.1468875320245182
59.90000000000045,19.733108498486956,0.508477784949317,-0.14949016863849307
61.00000000000047,19.845628203282164,0.5155450350805295,-0.15183030889514448
62.100000000000485,19.95791196943396,0.5219252750334784,-0.15479426327883639
63.2000000000005,20.06870534869007,0.5268191595494762,-0.15742962103919433
64.30000000000052,20.183505937848967,0.5323934989127779,-0.16008465000000704
65.40000000000053,20.29585086932917,0.5381440840201714,-0.16147110751710558
66.50000000000054,20.406597224166823,0.5392020861808371,-0.16508582748006662
67.60000000000056,20.516976428857387,0.5403429702048803,-0.16796326452443022
68.70000000000059,20.627882301137756,0.5420665935138591,-0.16928025476939412
69.8000000000006,20.73829933403867,0.5427957112822845,-0.17084402445012126
70.9000000000006,20.848785828487475,0.5440435685690057,-0.1726233854243282
72.00000000000063,20.95873538396978,0.5437130215731056,-0.17583541792188262
73.10000000000065,21.067531222917065,0.5418183649790689,-0.178495618970262
74.20000000000066,21.17849923414017,0.5407911396470457,-0.1814696628557977
75.30000000000067,21.28775722153209,0.5385635708709735,-0.18377998727161593
76.40000000000069,21.39753139397138,0.5315345625968677,-0.18641967393462
77.50000000000071,21.504116418507525,0.5312313674223552,-0.18773199201456547
78.60000000000072,21.61360534048759,0.5258959830536065,-0.1891530106975483
79.70000000000073,21.722426583501296,0.5204571558317799,-0.19167821079740577
80.80000000000075,21.83108862070865,0.5124225434492635,-0.19431090686645236
81.90000000000077,21.940989887468675,0.507797323075329,-0.19696039496880724
83.00000000000078,22.047615556023576,0.50022216167358,-0.19881322718723693
84.10000000000079,22.156634685098574,0.49567860671388364,-0.20094766273718134
85.20000000000081,22.264630617015186,0.4865149332176224,-0.20222007390397945
86.30000000000084,22.37197025391288,0.48095313331539646,-0.2035242390231402
87.40000000000084,22.4796930484925,0.47214262819014885,-0.20623813655932066
88.50000000000085,22.58704668813174,0.4663793045617757,-0.20616993630045322
89.60000000000088,22.69485821798751,0.45882516439190413,-0.2088129651275481
90.7000000000009,22.803069996847693,0.45151481955253336,-0.20878469961802493
91.8000000000009,22.910396699553868,0.4449363294767126,-0.21112677755510978
92.90000000000092,23.016510315763224,0.4375537141629684,-0.21254909263434563
94.00000000000094,23.123114635361105,0.4276125009491685,-0.21406973997240764
95.10000000000096,23.23004327418686,0.42252166880442354,-0.21476164538715237
96.20000000000097,23.337090149228345,0.4150919564349491,-0.21604983099626907
97.30000000000098,23.442602969536246,0.4090097149450074,-0.21671505435054117
98.400000000001,23.549261900770503,0.4004326193857479,-0.2180297659721897
99.50000000000102,23.655195120607075,0.39274824913762285,-0.21802931714681728
100.60000000000103,23.763274474264318,0.38579350952903924,-0.22066051736995274
101.70000000000104,23.869073765544552,0.379793375355439,-0.2219797487883155
102.80000000000106,23.97568364019416,0.3726796511249528,-0.22197985173782975
103.90000000000109,24.08161674172265,0.3677107275621374,-0.2210128363454893
105.0000000000011,24.188197563220367,0.36204255191191725,-0.2223098466018616
106.1000000000011,24.293163023783055,0.3563976934892197,-0.22362975472141944
107.20000000000113,24.400137827498853,0.35269196349653,-0.2236298369986902
108.30000000000115,24.504834322083255,0.34907414319455277,-0.2236298105403023
109.40000000000116,24.612762693814847,0.3451920236230186,-0.22494087048286593
110.50000000000117,24.719374716862404,0.34113329537627424,-0.22559984113031817
111.60000000000119,24.82511288190901,0.33703436935794606,-0.22692368352400516
112.70000000000121,24.92964269984521,0.33191555616581714,-0.22667810208291872
113.80000000000122,25.036922323388254,0.32825361006741427,-0.22691940506012198
114.90000000000123,25.143832821296424,0.3284808793257312,-0.22823982410929045
116.00000000000125,25.24870803508093,0.3239004345243697,-0.22823982900063733
117.10000000000127,25.352958715947565,0.323037323634211,-0.22747500841042134
118.20000000000128,25.46013768680225,0.3200307067570487,-0.22823689429057126
119.30000000000129,25.566461792124702,0.3195558151581108,-0.2282298129116791
120.40000000000131,25.672765303773385,0.31856380055162603,-0.2276414105412119
121.50000000000134,25.77807997024173,0.31753587871115707,-0.228563620843782
122.60000000000134,25.884652676797316,0.3153771766950382,-0.22971413593595624
123.70000000000135,25.990181647108546,0.31349564969081745,-0.2295599630409968
124.80000000000138,26.096555509738153,0.3142251478354452,-0.22952465151476842
125.9000000000014,26.20246272993014,0.3117009855286359,-0.22955994569601046
127.0000000000014,26.30946651581843,0.30944635271933585,-0.2295599467874112
128.10000000000142,26.41452939227868,0.311280102485042,-0.22966075730821878
129.20000000000144,26.52189817571814,0.3125482414621348,-0.22954992883684433
130.30000000000146,26.627208888401235,0.3113061035072928,-0.2308744856333309
131.40000000000146,26.732767008285627,0.3108645213805312,-0.2308699439543953
132.50000000000148,26.833745209840664,0.3125859286471062,-0.22955780817863403
133.6000000000015,26.944315270915677,0.3098749934171845,-0.2308744193041936
134.70000000000152,27.047662577567895,0.30893498704357003,-0.2304925095645105
135.80000000000155,27.154916166731436,0.3122031043742246,-0.23090977698488313
136.90000000000154,27.260287414911996,0.3133512382734194,-0.22949657639578103
138.00000000000156,27.365065525811325,0.31173232364592063,-0.2308800663836812
139.1000000000016,27.47154890885699,0.31388261755813995,-0.23088006499985747
140.20000000000158,27.576999814316785,0.313331189636737,-0.2308799407204054
141.3000000000016,27.681375077585717,0.313942542676624,-0.23088046651943683
142.40000000000163,27.786680760916447,0.31476568650971193,-0.23087004898331376
143.50000000000165,27.892951176116938,0.31579611910364935,-0.23086982201672468
144.60000000000167,27.997719210852804,0.31683591853156634,-0.23218998183944617
145.70000000000167,28.10386372233772,0.3179186299824437,-0.23219343868593434
146.8000000000017,28.209346286009705,0.31974480990818765,-0.2308700309934424
147.9000000000017,28.312075782225758,0.31940927830704835,-0.23088818572538194
149.0000000000017,28.418666906112122,0.3183292278634493,-0.23120008428731698
150.10000000000173,28.523829430727893,0.32150353458418346,-0.2312000179111524
151.20000000000175,28.629344241234293,0.3202185764866117,-0.2314342031901182
152.30000000000177,28.735182079168418,0.3220543657626789,-0.2322001764307693
153.4000000000018,28.839675963558363,0.3231500227959987,-0.23350764729776863
154.5000000000018,28.944939710316646,0.3244982838888073,-0.2315715971223078
155.6000000000018,29.049539070578742,0.32352889920614625,-0.23120013977588094
156.70000000000184,29.153625769538714,0.3248030730015443,-0.23249117361158733
157.80000000000183,29.25942007270821,0.32576167519356614,-0.23120014523872268
158.90000000000185,29.364443966500048,0.3265940402061205,-0.23218877905456514
160.00000000000188,29.468897372453576,0.3279544648456618,-0.23218936283721892
161.1000000000019,29.575024439548578,0.328323305336754,-0.23252014885616967
162.20000000000192,29.6792515991065,0.33115024163508266,-0.23252157492379144
163.30000000000192,29.78388020993077,0.3341153279317184,-0.23245887975630053
164.40000000000194,29.889662955488717,0.33338905274968234,-0.2325387336649385
165.50000000000196,29.990347249090842,0.33478072805475656,-0.2335101471809069
166.60000000000196,30.096951302368566,0.3353591985465314,-0.2335144275788985
167.70000000000198,30.20293311180857,0.3351385039585406,-0.23350001001081688
168.800000000002,30.307072702442333,0.3371974778669129,-0.23350013097404299
169.90000000000202,30.41257082179288,0.3385730812276204,-0.23432930151872755
171.00000000000205,30.51917000000021,0.34037870858519015,-0.23416989801931187
172.10000000000204,30.624590515461197,0.34103955358768756,-0.23350953559302834
173.20000000000206,30.729068206740838,0.3431851302633626,-0.233509889999989
174.3000000000021,30.834772831390783,0.34438421808832187,-0.2335098834138276
175.40000000000208,30.93841482257423,0.3446089325851067,-0.23449743608505713
176.5000000000021,31.04271150122732,0.3468837753475149,-0.23449989000644322
177.60000000000213,31.14836669563408,0.3453772415762628,-0.23450013063081876
178.70000000000215,31.254069903529484,0.3469315115312821,-0.23317967516626048
179.80000000000217,31.359576356631674,0.3459180935928985,-0.23350890708370908
180.90000000000217,31.463972587565138,0.3456648978594212,-0.2361474894933293
182.0000000000022,31.56927034400121,0.3478901315818044,-0.23514959501203014
183.1000000000022,31.673640099320394,0.3488060053899682,-0.23514137562253667
184.2000000000022,31.778959579228896,0.3495350021032866,-0.23383952979997336
185.30000000000223,31.881948656966536,0.3507364264514061,-0.23514980515965656
186.40000000000225,31.987670339855327,0.3510673818694743,-0.23384001643167363
187.50000000000227,32.09226783244412,0.3518370940387323,-0.23514801413109288
188.6000000000023,32.196978115316234,0.3517796057253193,-0.23647113918424667
189.7000000000023,32.30180174012037,0.35324333605355873,-0.23580510540386568
190.8000000000023,32.406331768012016,0.3531957252656863,-0.23622642092441204
191.90000000000234,32.51065588424891,0.3543830352598769,-0.237129861788274
193.00000000000233,32.61545370601408,0.3582122964523575,-0.23712986199913688
194.10000000000235,32.72048240569279,0.35680245921818265,-0.23713004237694513
195.20000000000238,32.82517352687252,0.35864715905682854,-0.23780228679082072
196.3000000000024,32.92934761761093,0.3578731405065865,-0.23712680822992427
197.40000000000242,33.03365335333249,0.35807030030696496,-0.2384498610464858
198.50000000000242,33.138121943733985,0.359764778086173,-0.23844986200000173
199.60000000000244,33.2430134003827,0.3608134105011809,-0.23844986199999685
200.70000000000246,33.34830986004042,0.36154820079809036,-0.2384498610598298
201.80000000000246,33.45286972380457,0.36123345853140654,-0.23980264232853976
202.90000000000248,33.55682895721543,0.36184226979907463,-0.23844870125200268
204.0000000000025,33.66197245058922,0.36430040747312264,-0.23844983817662335
205.10000000000252,33.767711363555776,0.36388448769578297,-0.23976085692675086
206.20000000000255,33.87250093142478,0.3653274825223811,-0.2411863924267421
207.30000000000254,33.97765007247581,0.3657343229327952,-0.24108031825152754
208.40000000000256,34.081662356812785,0.3668193709660703,-0.24107958993416734
209.5000000000026,34.187331644938375,0.3686267295413672,-0.24207007824360316
210.60000000000258,34.29207349959757,0.37046771904641695,-0.24240279962008282
211.7000000000026,34.39665618076128,0.37129715978086697,-0.2437199803964294
212.80000000000263,34.500102189271225,0.3723655519461275,-0.24371987799994876
213.90000000000265,34.605159517440946,0.3714362490149019,-0.24371987800000117
215.00000000000267,34.70986841337049,0.3723112843992813,-0.24371987808047457
216.10000000000267,34.81415858644849,0.3731205298897482,-0.24542983592995515
217.2000000000027,34.92009358752227,0.37434042339384055,-0.24597250730251785
218.3000000000027,35.02333549246582,0.37618209606601427,-0.24640069461722192
219.4000000000027,35.12827246913541,0.3756192538352401,-0.24636163108097486
220.50000000000273,35.2328361847337,0.37533194598676833,-0.2450399312058802
221.60000000000275,35.336984006300554,0.37759402085809723,-0.24733901365261257
222.70000000000277,35.44244054188012,0.3770333595484108,-0.24769540682473057
223.8000000000028,35.546193563656225,0.377476888763252,-0.24833014588089952
224.9000000000028,35.652306868307605,0.377897624404016,-0.2488137950160514
226.0000000000028,35.75603052187925,0.37668459714658664,-0.2503101115994606
227.10000000000284,35.860430778566055,0.3781614838063556,-0.2507931649102617
228.20000000000283,35.966484354179414,0.3801474854345781,-0.2516393626439788
229.30000000000285,36.07044304161084,0.37949166806110424,-0.25294617088645976
230.40000000000288,36.17525102465325,0.3797873344319391,-0.25432973036766526
231.5000000000029,36.28100100844186,0.3806462237760593,-0.25424127196467783
232.60000000000292,36.3859650306905,0.381273103328146,-0.25553387234260105
233.70000000000292,36.49028236936213,0.38188539459214077,-0.2569106882997514
234.80000000000294,36.59620344888986,0.38136736954186023,-0.25689001239729103
235.90000000000296,36.70007958912674,0.38053349116556645,-0.25951582593395095
237.00000000000296,36.804474781586634,0.382903512508207,-0.2582241467436379
238.10000000000298,36.909696380211685,0.3825421863644385,-0.2595361456705181
239.200000000003,37.011668141309414,0.3820406496943156,-0.26228103421638904
240.30000000000302,37.118060420855905,0.3840629164718483,-0.26348847935873065
241.40000000000305,37.22198608306335,0.3848893559785609,-0.2647908826615244
242.50000000000304,37.32711520175442,0.38515827763078425,-0.2661098412247709
243.60000000000306,37.43132222625345,0.3834144905000927,-0.26742781906539603
244.7000000000031,37.536411084151965,0.3857234966612637,-0.2687836960743204
245.80000000000308,37.640920963114866,0.3838012093330341,-0.27084615606949436
246.9000000000031,37.74562125233646,0.3851967897185915,-0.27400868422684876
248.00000000000313,37.8489686966893,0.38633572986564224,-0.27435236091065196
249.10000000000315,37.954886477507905,0.3855353981786682,-0.276781909277803
250.20000000000317,38.05981890339483,0.38526531661389507,-0.2797213169997401
251.30000000000317,38.16306472076882,0.3847093457301023,-0.28139978158035905
252.4000000000032,38.268001099794624,0.38700665309945315,-0.2836712355462021
253.5000000000032,38.37324402768166,0.3865049672766543,-0.28630155238978006
254.6000000000032,38.4785806349887,0.38633703009144704,-0.2896141832614676
255.70000000000323,38.581512051153666,0.38725694755011064,-0.2921905596826635
256.80000000000325,38.68840351647839,0.3870400151988893,-0.29488693201210125
257.9000000000033,38.79254529075327,0.38986859808833096,-0.297478938120443
259.0000000000033,38.897160646647905,0.3872332567534664,-0.30173065192894777
260.1000000000033,39.00330255865811,0.39004889929512787,-0.3043620154503568
261.20000000000334,39.10672491092871,0.3901630831768699,-0.3079358138491157
262.30000000000337,39.21270297326216,0.39060914451271156,-0.31213449169036434
263.40000000000333,39.315307758044426,0.3914066882382272,-0.31591397715516223
264.50000000000335,39.421307859141365,0.38878951677547424,-0.3192220800766403
265.6000000000034,39.52714303724583,0.39077426950859917,-0.3235827238258313
266.7000000000034,39.63203629650977,0.3905737198161814,-0.32839887770956766
267.8000000000034,39.737722079180855,0.38984236356719126,-0.3323466137563589
268.9000000000034,39.8432445989915,0.3901305487814919,-0.33710067736901417
270.0000000000034,39.94706694693892,0.3902066525025256,-0.34353176844598066
271.10000000000343,40.050721775818865,0.3906823438188214,-0.3477458713204493
272.20000000000346,40.159473032357965,0.3900854195808068,-0.3538447805680751
273.3000000000035,40.26443969980543,0.3900872446555508,-0.35831209403090103
274.4000000000035,40.369345947278724,0.39155955275606247,-0.36601002390957804
275.5000000000035,40.47459381680878,0.392172329654892,-0.37227446638978856
276.60000000000355,40.579560426442406,0.39321699380920383,-0.3787807555382381
277.70000000000357,40.68522686495113,0.39192298875579556,-0.38682485671864564
278.8000000000036,40.79174147549289,0.3933459117185707,-0.3934341971620108
279.9000000000036,40.89633643791482,0.3930780208514628,-0.4019261271290131
281.0000000000036,41.00103202023393,0.39537403131140114,-0.40923436090758925
282.1000000000036,41.1078930742888,0.3947552370989895,-0.41511384621055836
283.2000000000036,41.212106045398606,0.3974166639509953,-0.42576431959338334
284.30000000000365,41.31804934893856,0.39708582356341005,-0.4341665384621791
285.4000000000037,41.422155163081555,0.3985335237045482,-0.4435473122192497
286.5000000000037,41.528759995879504,0.3996455341664289,-0.4521624475225625
287.60000000000366,41.633628290134624,0.40460022219605707,-0.46169725396482786
288.7000000000037,41.73981606421821,0.4046602663490402,-0.47279606542180463
289.8000000000037,41.84513296627017,0.4070051186754421,-0.483926662521986
290.90000000000373,41.9512444348853,0.40792600481296504,-0.49382530677977776
292.00000000000375,42.05673869162829,0.40955073431318645,-0.5054641176998143
293.1000000000038,42.160544280331415,0.41215783773360926,-0.5171324404748243
294.2000000000038,42.26747233350922,0.41302604704737556,-0.5296104001131048
295.3000000000038,42.37250583745483,0.4175892098644016,-0.5422953430315833
296.40000000000384,42.479913670399526,0.42192271088287414,-0.5556699785986785
297.5000000000038,42.58507667872937,0.4235207204660052,-0.5695424142163534
298.60000000000383,42.690035968667516,0.42547246576844966,-0.5822168312579263
299.70000000000385,42.79594324036566,0.42951560454698456,-0.5965436429440198
300.8000000000039,42.90200202332821,0.43275629461005494,-0.6108769524098343
301.9000000000039,43.00883373662321,0.4361180338020241,-0.6260424098553576
303.0000000000039,43.11323342518309,0.43620056440626676,-0.64235954973041
304.10000000000394,43.21997881497799,0.43862818789157354,-0.6590088857495342
305.2000000000039,43.324855940757324,0.44273002912176707,-0.6740577092307021
306.30000000000393,43.43090567191153,0.4452304165749753,-0.6913207605685754
307.40000000000396,43.53641907903397,0.4492991991535973,-0.709675668921518
308.500000000004,43.641456744757456,0.4540023652560875,-0.7273377333852538
309.600000000004,43.747521543579694,0.45862362454277583,-0.7465660680383603
310.700000000004,43.85397328333345,0.4615016002029695,-0.7656575553446059
311.80000000000405,43.95755140989202,0.4653249774321546,-0.7839041201094608
312.90000000000407,44.06534259207667,0.47019216690055354,-0.8060953716983983
314.0000000000041,44.17088806987414,0.4754997139506486,-0.8261268212984247
315.10000000000406,44.2747819130048,0.4779371383524821,-0.8473851385810365
316.2000000000041,44.380128134529606,0.4853504784568158,-0.8679965444564512
317.3000000000041,44.486336507865246,0.48843657657789985,-0.891204807519189
318.4000000000041,44.592340608957635,0.492666417903707,-0.9153306434193662
319.50000000000415,44.698617817780494,0.4987020084249768,-0.9406257065632788
320.6000000000042,44.804166888335644,0.5048600155639719,-0.9654106331076915
321.7000000000042,44.90848299257069,0.5083677273068448,-0.9891633853522612
322.80000000000416,45.015570296303856,0.5116413828083424,-1.0159612965149174
323.9000000000042,45.12432869044737,0.5186490534213848,-1.0431402165322456
325.0000000000042,45.230416596827425,0.52425253063618,-1.0699521679687902
326.10000000000423,45.33613111924186,0.5291082638910305,-1.0990999914602244
327.20000000000425,45.442349755746214,0.5382688280194899,-1.1283077749211206
328.3000000000043,45.548881721831464,0.5462893985852246,-1.1565854825620892
329.4000000000043,45.654259358117756,0.5512334919674076,-1.188331803936082
330.5000000000043,45.760573229014945,0.558524756458345,-1.2184747396573967
331.60000000000434,45.86715600967799,0.5657079194426519,-1.2520416429602066
332.7000000000043,45.97466425533199,0.5750759006584641,-1.2873740973068628
333.80000000000433,46.08125995901335,0.5817514406782572,-1.3223441746897984
334.90000000000435,46.187442299830934,0.594360781620156,-1.3544438125803357
336.0000000000044,46.29300045748825,0.5982602189560725,-1.3927012455774048
337.1000000000044,46.401550519100475,0.6118655673337504,-1.4291717810840225
338.2000000000044,46.506997842099544,0.6191675545726244,-1.4662510268846347
339.30000000000445,46.61391615689443,0.6294572984993172,-1.505685125296679
340.4000000000044,46.72038899475094,0.6367810847330082,-1.5464191202112207
341.50000000000443,46.827387006399306,0.647341153096255,-1.5865438861633465
342.60000000000446,46.9334516885791,0.6557003989259674,-1.6300462276929704
343.7000000000045,47.0408619403551,0.6657632596894463,-1.673995921247112
344.8000000000045,47.14863452955798,0.6765256736414776,-1.716526117200059
345.9000000000045,47.25452684325608,0.6829395893460516,-1.7607304676546396
347.00000000000455,47.362126027212724,0.6929831078398598,-1.8091504234598528
348.10000000000457,47.46864598576134,0.6989495527760845,-1.8536633056258638
349.2000000000046,47.574961160319475,0.7022210693437497,-1.9020394372029625
350.30000000000456,47.68166221768558,0.7063239087548595,-1.9510795363094835
351.4000000000046,47.78848701540625,0.7059597799336866,-1.9986618202975268
352.5000000000046,47.89521240871676,0.7065576267681117,-2.0489251786788714
353.6000000000046,48.000110322294915,0.7035908750931726,-2.0986873531953076
354.70000000000465,48.10749412007949,0.6965652270669197,-2.146367168506746
355.8000000000047,48.21331150571943,0.6880030919083211,-2.193544262847119
356.9000000000047,48.31906925476285,0.6733391575195984,-2.2426078329850556
358.00000000000466,48.42497665774338,0.6552442738337262,-2.2873610849606214
359.1000000000047,48.531833510867784,0.6345304657109444,-2.330940564376313
360.2000000000047,48.6377020238386,0.6125638668132541,-2.37720398877059
361.30000000000473,48.742666969717156,0.5830925737813906,-2.415274933865387
362.40000000000475,48.84834364778737,0.555840447341265,-2.4558727161069607
363.5000000000048,48.95373732510389,0.5252791127638526,-2.49225287046134
364.6000000000048,49.05953488901308,0.4926561286599148,-2.5246869973508828
365.7000000000048,49.16398776718664,0.4604893272741739,-2.5562540797941686
366.80000000000484,49.26917091330082,0.4273691192329804,-2.583970140109937
367.9000000000048,49.37464113592138,0.39642374519187884,-2.608340814842793
369.00000000000483,49.48007053745407,0.36807705610627484,-2.6314368622569484
370.10000000000485,49.58529077158065,0.3419823574002273,-2.6518347540412903
371.2000000000049,49.690680630183806,0.3162791816206185,-2.6698715084628017
372.3000000000049,49.7956397429903,0.29227682499298935,-2.687248406850051
373.4000000000049,49.9021788031532,0.26906130828285446,-2.700822531387135
374.50000000000495,50.00789055648176,0.24689059131212687,-2.7140597969942912
375.6000000000049,50.114098857047736,0.2254442512770355,-2.7276420538235406
376.70000000000493,50.2186732693353,0.2046530344773524,-2.7350021635055892
377.80000000000496,50.32602629930335,0.18642023158761845,-2.7419136890328684
378.900000000005,50.43159120784394,0.16917222453154335,-2.7520761814838632
380.000000000005,50.538887941123704,0.1539381488489835,-2.7603658332439123
381.100000000005,50.64440242750353,0.14214664433073054,-2.76513634474938
382.20000000000505,50.750326273972355,0.1347507278569675,-2.7710941704233
383.30000000000507,50.856337460587156,0.12731768640470809,-2.7768236303612666
384.4000000000051,50.96138729722012,0.12103874506309065,-2.780088754689113
385.50000000000506,51.07068823574221,0.11487113882255995,-2.7846886978523173
386.6000000000051,51.176884485295986,0.11165203743386243,-2.788859077355829
387.7000000000051,51.28459163172252,0.10843613926734585,-2.7916485243481626
388.8000000000051,51.390497047688825,0.10614436155641571,-2.795608163951863
389.90000000000515,51.49790908004802,0.10408071671372787,-2.79860720899056
391.0000000000052,51.603239127035515,0.10097488286930445,-2.8030745009669404
392.1000000000052,51.71220551452257,0.10097417467124536,-2.805633081461732
393.20000000000516,51.81974124156223,0.09786523710197526,-2.8084671775581693
394.3000000000052,51.92717710497075,0.09593213977348236,-2.811112328452782
395.4000000000052,52.033240787580155,0.09404365122488978,-2.816138077369616
396.50000000000523,52.14153747319666,0.09424826681977883,-2.819775165296857
397.60000000000525,52.247670096028855,0.09251379170324203,-2.8239511180605446
398.7000000000053,52.35596605969627,0.09068375362993064,-2.8273391301416178
399.8000000000053,52.46107071928447,0.0888138339202943,-2.8299946601139334
400.9000000000053,52.57085231407276,0.08704792637004843,-2.832615109494543
402.00000000000534,52.67779532146021,0.08686100810193531,-2.836123931225565
403.1000000000053,52.78592813740919,0.0846506774935959,-2.838052495478701
404.20000000000533,52.89304809151228,0.0824629198204796,-2.840797959298581
405.30000000000535,53.00178374624098,0.08121379284585739,-2.8449282646054037
406.4000000000054,53.10927306479285,0.07845995165711461,-2.8474532841171447
407.5000000000054,53.21737425089792,0.0763924068855969,-2.850189890591058
408.6000000000054,53.32502207234995,0.07513420054503073,-2.8548210170744426
409.70000000000545,53.43155500079337,0.07489683917342826,-2.8573949252450612
410.8000000000054,53.53926541163108,0.07216414059872878,-2.860448547628485
411.90000000000543,53.64695832729508,0.06991372513942062,-2.8631565187291237
413.00000000000546,53.753332398738756,0.0708472478873956,-2.8664436934288062
414.1000000000055,53.863751600797364,0.06932273878761297,-2.8694012882133624
415.2000000000055,53.97099891560167,0.06862719763892189,-2.87185951909817
416.3000000000055,54.07944999435733,0.06723998060237446,-2.8746682599315836
417.40000000000555,54.18774424576449,0.06810612841648622,-2.8773919864103283
418.50000000000557,54.29537926270739,0.0677638174473505,-2.8806380796933526
419.6000000000056,54.402524320981236,0.06677965087666271,-2.88361794635414
420.70000000000556,54.51074088711535,0.06672065253559578,-2.8866420095953496
421.8000000000056,54.61847760257322,0.06781335016180245,-2.8892461788561277
422.9000000000056,54.72593489277004,0.06479538723568068,-2.8913138648359995
424.0000000000056,54.83515762758544,0.06417542975080837,-2.8951837628474095
425.10000000000565,54.941835097353014,0.0641098366265529,-2.897832965107784
426.2000000000057,55.049655692958595,0.06479588331044572,-2.901678650696465
427.3000000000057,55.15849812423952,0.06545092517608087,-2.904323720795656
428.40000000000566,55.26551999432942,0.06771146460576338,-2.9053420817680076
429.5000000000057,55.37335868654479,0.06861699404472377,-2.9082429681855806
430.6000000000057,55.4818702866919,0.06969535261140336,-2.9121692090889333
431.70000000000573,55.590850250530416,0.07092002855785717,-2.9135498348563393
432.80000000000575,55.699864485456594,0.07316383113028857,-2.9161813009632525
433.9000000000058,55.80822842531059,0.0727466440210437,-2.918816100512202
435.0000000000058,55.917049865313324,0.07393750979240743,-2.9214757394985784
436.1000000000058,56.02523620841207,0.07614256099934236,-2.9238276548477993
437.20000000000584,56.13466372786065,0.07687690277144621,-2.9265918813621834
438.3000000000058,56.24328589861519,0.08496413905151101,-2.928900863836133
439.40000000000583,56.3510885835218,0.09598832218644182,-2.931683083155364
440.50000000000585,56.45990987743796,0.10870275531803086,-2.932866401644776
441.6000000000059,56.56906905931292,0.12301108655117832,-2.9351645336940613
442.7000000000059,56.676868221001456,0.13521050113946442,-2.9364005852745345
443.8000000000059,56.785519394578266,0.14324970375003943,-2.9404488197414684
444.90000000000595,56.892863822951604,0.15333530724880517,-2.943067418771135
446.0000000000059,57.00222100044361,0.158164591001408,-2.9443937451233158
447.10000000000593,57.109360776503586,0.165516310800356,-2.9467007610604816
448.20000000000596,57.217755932400806,0.16708650266724034,-2.948876727018166
449.300000000006,57.3263880867273,0.17023779196269484,-2.950431480466727
450.400000000006,57.43399579994846,0.1747319171358671,-2.9527047651270815
451.500000000006,57.54277528270511,0.1779938886380541,-2.9553490218976957
452.60000000000605,57.65080098380062,0.18142870247628828,-2.9569724642915203
453.70000000000607,57.75847520706054,0.1844966714509585,-2.9595822947610246
454.8000000000061,57.86751368136645,0.1881673096391855,-2.9619656849857576
455.90000000000606,57.976107662755396,0.1887682256536536,-2.9623491231085692
457.0000000000061,58.08404791221166,0.1918988546698438,-2.9646622541700465
458.1000000000061,58.191866811666046,0.19243525216564084,-2.966796733523702
459.2000000000061,58.30102896587842,0.1950853360355973,-2.968539749567376
460.30000000000615,58.40854711763031,0.1955648855732327,-2.96973243322537
461.4000000000062,58.51743237390765,0.1932626444458373,-2.9740829822611468
462.5000000000062,58.62598531401533,0.1995410475174927,-2.975457680858648
463.60000000000616,58.73359031450888,0.20070097642726348,-2.9754575838591597
464.7000000000062,58.84279647728152,0.20156330315946358,-2.978270939247275
465.8000000000062,58.9516098710914,0.20259930336042187,-2.9794129504124145
466.90000000000623,59.0605724528131,0.20366535979153477,-2.9811779309831294
468.00000000000625,59.16917000000063,0.20778497338259094,-2.984019917419398
469.1000000000063,59.2775863861159,0.20981473735117706,-2.985348104065714
470.2000000000063,59.386059321826565,0.20901329243181666,-2.9854912096795014
471.3000000000063,59.49475510296269,0.2066902884737012,-2.9879722792250343
472.40000000000634,59.60383337654058,0.20794336297050953,-2.9906253814697914
473.5000000000063,59.712664511104705,0.20751024616249802,-2.991795483818052
474.60000000000633,59.821357227486224,0.20785676028669908,-2.9932472146938967
475.70000000000636,59.92926856287924,0.20930851848536103,-2.9945586488075175
476.8000000000064,60.03855498240261,0.20870757451057997,-2.997186195527848
477.9000000000064,60.14649362450035,0.20643912853478796,-2.998509238868314
479.0000000000064,60.25523022055941,0.20561004309057185,-2.999987267133312
480.10000000000645,60.36471505414869,0.2040674256855718,-3.0011301445325165
481.2000000000064,60.47278098858265,0.20140675995885982,-3.003414463014538
482.30000000000643,60.582708124258495,0.198911446396296,-3.0051000122281506
483.40000000000646,60.691418689586,0.19795740819424412,-3.0051270670146133
484.5000000000065,60.79934679755412,0.1959760651220116,-3.0064201753637327
485.6000000000065,60.90987215604395,0.19452267220900532,-3.007733181381551
486.7000000000065,61.01811888588257,0.19284104869090146,-3.0103316138997567
487.80000000000655,61.12698941987388,0.19571268752412085,-3.010380605146464
488.90000000000657,61.23577252333149,0.19303981439368278,-3.0130606269655242
490.0000000000066,61.34564497753064,0.18817838400721376,-3.014393716382525
491.10000000000656,61.45453099571114,0.18756780526333883,-3.0156145809178696
492.2000000000066,61.56358016861123,0.18300027018029696,-3.016960261332362
493.3000000000066,61.67439359082066,0.1797233916691724,-3.0182751718519905
494.4000000000066,61.782921522824765,0.17703745657983705,-3.0196289952231847
495.50000000000665,61.89179799259755,0.17351489169279455,-3.0207638851789698
496.6000000000067,62.00053339962565,0.1694098555935435,-3.022229835528641
497.7000000000067,62.1095438510438,0.1629091134469055,-3.022228680140198
498.80000000000666,62.2184411843734,0.15930416428460792,-3.0248704991431867
499.9000000000067,62.32773463569842,0.15286907451801734,-3.027518341861393
501.0000000000067,62.43590232213894,0.14487803565687207,-3.0273752205923774
502.10000000000673,62.54655946253212,0.13852062077839933,-3.0288073342311783
503.20000000000675,62.656296353656,0.1316140676011538,-3.0306499070273487
504.3000000000068,62.76508363499579,0.12757700337673372,-3.03104790554715
505.4000000000068,62.87373876785688,0.12302517900532417,-3.0327906068860213
506.5000000000068,62.983611831085334,0.11666492308899723,-3.0327510125510373
507.60000000000684,63.09278706299888,0.11222376550544233,-3.035399971518672
508.7000000000068,63.20246190897485,0.1046904292115528,-3.034345959344389
509.80000000000683,63.31123058827641,0.10117767300102332,-3.0371863554470107
510.90000000000686,63.42094056468376,0.09703373703650875,-3.0373750865701643
512.0000000000068,63.529437929257675,0.09447566940194063,-3.040670379783707
513.100000000007,63.63728258075401,0.09254225037904396,-3.040679802428238
514.2000000000069,63.74927201110057,0.08788411346293157,-3.0419897948460757
515.300000000007,63.85692530724611,0.08856955486335139,-3.041989902497432
516.4000000000069,63.96728385557734,0.08673016014540536,-3.043300572731278
517.5000000000069,64.07864658691088,0.08125289637555522,-3.044620328247528
518.600000000007,64.18883359710533,0.08207637170832305,-3.0446196302502972
519.700000000007,64.29752646731468,0.08294800156914994,-3.0472603826172806
520.800000000007,64.40755783708862,0.0804706951944466,-3.0472488991514695
521.900000000007,64.51822068112908,0.08003578235828057,-3.049891459401584
523.000000000007,64.62734510252538,0.07873307801280804,-3.0503857050143095
524.1000000000071,64.73753329112284,0.07586144984483889,-3.0498913378650143
525.2000000000071,64.84762111545925,0.076009349640489,-3.0524094992952877
526.300000000007,64.95780689805707,0.07468485935491298,-3.0525191153367746
527.4000000000071,65.06579592863565,0.07453892397003348,-3.053834174800987
528.500000000007,65.17566112756332,0.07671832041753557,-3.0548343709600405
529.6000000000072,65.28578610010986,0.08007076859342621,-3.0547643895626675
530.7000000000071,65.39715541411091,0.07923450931776244,-3.0571814777853623
531.8000000000072,65.5060352116902,0.08083042339497115,-3.0584459459590856
532.9000000000071,65.61635414358572,0.07892158125874826,-3.0594441870682463
534.0000000000072,65.72577519872614,0.07979424607872787,-3.0606167714706354
535.1000000000072,65.83574540089008,0.0792675754756399,-3.0610800500547564
536.2000000000072,65.9447292542643,0.07976922798487751,-3.0624358955150726
537.3000000000072,66.05579102172173,0.08298833246070325,-3.062635746931831
538.4000000000073,66.16520365183663,0.08251952393366857,-3.0650178745027263
539.5000000000073,66.27303750139129,0.08346379228033163,-3.0650354530006068
540.6000000000073,66.38516678849379,0.08415755180809581,-3.0650529926964607
541.7000000000073,66.49496363559174,0.08471451707699784,-3.0664444195771607
542.8000000000073,66.60443224188035,0.08485546313404979,-3.0689345597341493
543.9000000000074,66.71481535917904,0.0844688246741031,-3.06804605861975
545.0000000000074,66.82501566605427,0.08581792439505587,-3.0690009001506353
546.1000000000074,66.93378416102709,0.08898198833159687,-3.0702252877403997
547.2000000000073,67.04357275625863,0.0896681704442448,-3.070305313144179
548.3000000000073,67.15525940333742,0.08804939840147896,-3.0730222760550285
549.4000000000074,67.26547177932702,0.09146783921064072,-3.0729493241540298
550.5000000000074,67.37500634300787,0.08992837273367393,-3.0742712192351154
551.6000000000074,67.48572429346008,0.08868912750124713,-3.07491802966629
552.7000000000074,67.59602874458135,0.087932990974106,-3.0755423163469464
553.8000000000075,67.70633396474966,0.09167170957587278,-3.0755801023290026
554.9000000000075,67.8164852756282,0.09139650138041766,-3.076895655550142
556.0000000000075,67.92765720392553,0.09264492559879933,-3.0782209878158366
557.1000000000075,68.0375466159415,0.09172089425639895,-3.0769054249636802
558.2000000000075,68.14864028802401,0.0958495121416072,-3.0795300246947503
559.3000000000076,68.26009731224786,0.09741610491091057,-3.0808499875632767
560.4000000000076,68.37104522588065,0.09772806732502048,-3.0821750870853855
561.5000000000076,68.48223919639231,0.09718858377924433,-3.081970221404128
562.6000000000076,68.59266838898952,0.09660621143806103,-3.083160098717485
563.7000000000077,68.7035085956606,0.09897923079802329,-3.084478064795317
564.8000000000077,68.81373272536925,0.1001913349801491,-3.0857899387967183
565.9000000000076,68.92449478834293,0.10130489016930211,-3.0857627502695566
567.0000000000076,69.03423676304668,0.10339120375216404,-3.085790071720373
568.1000000000076,69.14599462432027,0.10663924904601552,-3.0881021844775556
569.2000000000077,69.25690783883962,0.10853163395371812,-3.0880995659498796
570.3000000000077,69.36707272066319,0.11244096928522307,-3.0884090002297597
571.4000000000077,69.47764631842496,0.11191731161407392,-3.088646565327155
572.5000000000077,69.58824511317046,0.11481838975696146,-3.089408380481829
573.6000000000078,69.69926746408653,0.11613499061498844,-3.0907299053449475
574.7000000000078,69.80926618002624,0.11699390161636547,-3.0917087899453866
575.8000000000078,69.91998914218348,0.11685977180667817,-3.091710277095012
576.9000000000078,70.03055578288225,0.11837324949902439,-3.0930299843189473
578.0000000000078,70.14093037386912,0.11448667431163218,-3.095239043630087
579.1000000000079,70.25118523648088,0.11731651694675604,-3.094637509497245
580.2000000000079,70.36202901329737,0.1195832607325924,-3.0945743301268154
581.3000000000079,70.4730352064297,0.11533518666177556,-3.096563800576308
582.4000000000078,70.58295190693642,0.11822860386094591,-3.097856339346668
583.5000000000078,70.69378221172417,0.11850770715107939,-3.0965500209703443
584.6000000000079,70.80409760430139,0.11988130715802714,-3.096546929635606
585.7000000000079,70.91663286378984,0.1238728963165483,-3.098842635597377
586.8000000000079,71.02713436636286,0.1343992956350133,-3.1007100684529982
587.9000000000079,71.13647831604217,0.14553075900623513,-3.101407636204253
589.000000000008,71.2482166834304,0.15883269268405942,-3.100719697240351
590.100000000008,71.35868467642356,0.17110479998620143,-3.1033561777837497
591.200000000008,71.47009937758969,0.18829767883970394,-3.1033599056473227
592.300000000008,71.58097036693454,0.1939301477637868,-3.1046782571425178
593.400000000008,71.69207525620672,0.19739894554692528,-3.106191780346233
594.5000000000081,71.8021093792894,0.2026119266833203,-3.104614499786661
595.6000000000081,71.91458757278014,0.20149320679563698,-3.1037901400692673
596.7000000000081,72.0257564292246,0.20536798221609076,-3.1051972242078563
597.8000000000081,72.13551865628659,0.20731209596328526,-3.1077539100117844
598.9000000000082,72.24568121589206,0.20698787677126007,-3.1077505674518155
600.0000000000082,72.3590641097155,0.21068005230196762,-3.1078828716684543
601.1000000000081,72.4696839027378,0.20996366231345398,-3.1087395840379135
602.2000000000081,72.58161864299001,0.20920169327241878,-3.110050106989204
603.3000000000081,72.69295992440966,0.21391972085499789,-3.1110257068956897
604.4000000000082,72.80383237350435,0.21641256813387932,-3.110353736915567
605.5000000000082,72.91546877144715,0.21739618022668694,-3.1111500150574467
606.6000000000082,73.02706372037683,0.21988411650911788,-3.1122267674896453
607.7000000000082,73.13760176140647,0.2196155775586176,-3.1140179496409592
608.8000000000083,73.24685452198476,0.2228144292535873,-3.113999977428712
609.9000000000083,73.35967608602729,0.22138380788702605,-3.114659455969461
611.0000000000083,73.47211817161477,0.22428937002277005,-3.115913563239023
612.1000000000083,73.5828789778161,0.22914278626188644,-3.1153200169121185
613.2000000000083,73.69165636372936,0.2289238361061492,-3.11667429527985
614.3000000000084,73.80494101582619,0.23162395104609457,-3.117175702243731
615.4000000000084,73.91543230460222,0.2350253655155159,-3.116693805922372
616.5000000000084,74.02656560766785,0.23805796891912923,-3.1189012525723117
617.6000000000083,74.13834707911828,0.23725278729543942,-3.1174232090227
618.7000000000083,74.24721697885855,0.23831516110766104,-3.12007114232042
619.8000000000084,74.35716800217509,0.24053317150640208,-3.118730221347963
620.9000000000084,74.46957936210914,0.24439875307154668,-3.120367699309836
622.0000000000084,74.58276384761533,0.24843314438839514,-3.12168925039082
623.1000000000084,74.69474205547712,0.24972998766560983,-3.123013777943761
624.2000000000085,74.80472751267868,0.2546684574571104,-3.122746031698613
625.3000000000085,74.91634571075988,0.26106919054626776,-3.123009812978169
626.4000000000085,75.02856627281199,0.266803872043725,-3.123619587287589
627.5000000000085,75.13803282090205,0.27057762359957704,-3.1243182059265053
628.6000000000085,75.25093381335927,0.27411784416103013,-3.126965311560776
629.7000000000086,75.36281390780307,0.27930009501538144,-3.1281720961020363
630.8000000000086,75.47416739011774,0.2852503450578734,-3.126960088891501
631.9000000000086,75.586428727332,0.28649339875623814,-3.128276918439533
633.0000000000086,75.69690425661446,0.2901563928451787,-3.129589917108099
634.1000000000087,75.80906055069724,0.2906223597618962,-3.129589743902633
635.2000000000087,75.92039880123598,0.2965757757625975,-3.1313914599102284
636.3000000000086,76.03108565424928,0.29931369372038885,-3.133559930909796
637.4000000000086,76.14285785010529,0.3004595016779461,-3.132229259867239
638.5000000000086,76.25419808337712,0.3064621925791924,-3.13354180317079
639.6000000000087,76.36610181688553,0.31139509094110185,-3.1348607859790043
640.7000000000087,76.4774243847956,0.31529144638835316,-3.1361798497511315
641.8000000000087,76.58844307010159,0.31816241177106774,-3.13618595000903
642.9000000000087,76.70075280481869,0.32101369931037005,-3.1375147308609175
644.0000000000088,76.81200833370805,0.31923868609342243,-3.138114333099954
645.1000000000088,76.92279699523985,0.3204326464827474,-3.1402236631968936
646.2000000000088,77.03562749130471,0.3243254001976388,-3.1401403045065472
647.3000000000088,77.1460795122435,0.32452662599743487,-3.1414518779979836
648.4000000000088,77.25853092923906,0.3244402511886806,-3.1427700311449693
649.5000000000089,77.36994468012986,0.3224962818494177,-3.1440872884960305
650.6000000000089,77.48305904300439,0.3186109872502585,-3.144363145665449
651.7000000000089,77.5931592255791,0.3158299298191678,-3.145399789614377
652.8000000000088,77.70480832023547,0.3159945104690729,-3.145983361476108
653.9000000000088,77.81639535924256,0.31137844957210326,-3.146772989695307
655.0000000000089,77.92665101077226,0.30722601608881384,-3.1467200761188674
656.1000000000089,78.03926334664854,0.306540032809979,-3.1480399710982296
657.2000000000089,78.15015356942426,0.3041790705463654,-3.149349750578957
658.3000000000089,78.25926528347875,0.3021086048035382,-3.1500177980319157
659.400000000009,78.37173919731389,0.29509979909066963,-3.150669828676918
660.500000000009,78.48262568211773,0.2906444370147294,-3.149382464002124
661.600000000009,78.59459843128808,0.2860428245690547,-3.152270753573528
662.700000000009,78.70556449825659,0.2773592334353341,-3.153309864746057
663.800000000009,78.81684821035579,0.27093313738700053,-3.1544438316998766
664.9000000000091,78.92889887984762,0.26156873106611567,-3.153630401069741
666.0000000000091,79.04082566639408,0.2545078715877087,-3.154950124046333
667.1000000000091,79.14982094656142,0.24784255992760662,-3.1562629906784307
668.2000000000091,79.26094066095396,0.24185664738398271,-3.1562701380245266
669.3000000000092,79.37368283470433,0.23444099084911119,-3.156166384459258
670.4000000000092,79.4869366804485,0.22952143614220644,-3.1569097640968224
671.5000000000091,79.59845561100104,0.22995432052789555,-3.155401118060138
672.6000000000091,79.7104068827894,0.22843189924359208,-3.1567100034736044
673.7000000000091,79.82174230806528,0.22138848494332697,-3.1567100041545255
674.8000000000092,79.9330809378036,0.21823133552413743,-3.157670534066639
675.9000000000092,80.04320249776461,0.21419621240222053,-3.158030020134144
677.0000000000092,80.15680679332844,0.21452215150872278,-3.1580300199904285
678.1000000000092,80.26785374028387,0.20669978602142836,-3.1582605315591694
679.2000000000093,80.37975935924763,0.21316386094018647,-3.159354444543561
680.3000000000093,80.49060186073305,0.20876946354764825,-3.1603429695374583
681.4000000000093,80.60342469948473,0.2111530110056019,-3.160670917676409
682.5000000000093,80.71336748886888,0.20689825772464632,-3.1606598894989855
683.6000000000093,80.82741009337043,0.208561704920446,-3.160659897255659
684.7000000000094,80.93836612746955,0.2093200738403882,-3.161650462973604
685.8000000000094,81.05070684771319,0.20983450313998242,-3.1619793231811117
686.9000000000094,81.16333498581211,0.21014613357751766,-3.163300217536595
688.0000000000093,81.27416680287571,0.21040894985915082,-3.163299933999903
689.1000000000093,81.38600901813344,0.20965519599803017,-3.163299930249958
690.2000000000094,81.49855550978893,0.2117543019641548,-3.161992224071184
691.3000000000094,81.60977490924938,0.20736307005046029,-3.16329994371919
692.4000000000094,81.72193447724932,0.20934025924538568,-3.164264593950553
693.5000000000094,81.83352369550222,0.21128079654341292,-3.16461018668911
694.6000000000095,81.94589917812418,0.20957752977696908,-3.1646169767998664
695.7000000000095,82.05781313133109,0.2092468439340156,-3.1668396148713933
696.8000000000095,82.16866398799367,0.2150352344680817,-3.1672498315806177
697.9000000000095,82.27990124223257,0.21429545533092598,-3.1659733793296585
699.0000000000095,82.39202497705242,0.21844542910959697,-3.1673456960350572
700.1000000000096,82.5040402141707,0.2180877971776647,-3.1672598478823533
701.2000000000096,82.61749140690497,0.21952429067222523,-3.1675517588218014
702.3000000000096,82.72906219189761,0.21849265522149675,-3.168243688217219
703.4000000000096,82.84048745001316,0.22400289811107776,-3.1672506461853813
704.5000000000097,82.95297400645686,0.22228160844703826,-3.1685700982012888
705.6000000000097,83.06649189434688,0.22309037090429218,-3.169129646979761
706.7000000000096,83.17847519657742,0.22221523587178815,-3.1698904737548728
707.8000000000096,83.28959600788866,0.2209561608791044,-3.1708801342312896
708.9000000000096,83.40270301949533,0.22230732690841548,-3.1708801331806673
710.0000000000097,83.51440338293838,0.2256223540902067,-3.171232057787183
711.1000000000097,83.62653165797997,0.228450418521976,-3.1725200232526385
712.2000000000097,83.73864021011832,0.23371007188414894,-3.1721435341379203
713.3000000000097,83.85130273790104,0.24195100366124378,-3.1715300037648673
714.4000000000098,83.96365906417437,0.24652083892706744,-3.172518226876429
715.5000000000098,84.07489248802665,0.25440164700074974,-3.1725219988873716
716.6000000000098,84.18788397206505,0.26052106012487064,-3.1725194750536025
717.7000000000098,84.30089966503947,0.26606874875202946,-3.1725202534216086
718.8000000000098,84.41315246147475,0.2724730887947162,-3.1749502784649626
719.9000000000099,84.52645941386032,0.28347766648226247,-3.176469829052938
721.0000000000099,84.63742413588619,0.28552685245921094,-3.175143986276418
722.1000000000099,84.74983409895684,0.29627635444639444,-3.175149885001685
723.2000000000098,84.86209448554975,0.3010918270585097,-3.1751502555772015
724.3000000000098,84.97378777377801,0.30869973734240386,-3.175860300092537
725.4000000000099,85.08482874335908,0.3164349291239701,-3.1764381820343797
726.5000000000099,85.19843578234516,0.32177081046431266,-3.176579683007094
727.6000000000099,85.31029316390803,0.32894413075173445,-3.1777941562812604
728.7000000000099,85.42205687977324,0.33222365104231444,-3.1777908104488732
729.80000000001,85.53411506120788,0.3398940349923696,-3.179110110238029
730.90000000001,85.64667588049265,0.34664840656656093,-3.1804168402452957
732.00000000001,85.75906638647875,0.34930285313526555,-3.1804301899980656
733.10000000001,85.87121871854542,0.35243031032392813,-3.1804290287497214
734.20000000001,85.98258888970226,0.3576019975210878,-3.1790886017325324
735.3000000000101,86.0958217334509,0.36374641647795314,-3.180337212358766
736.4000000000101,86.20849842928247,0.3693381344873976,-3.1804262383243844
737.5000000000101,86.32124245846516,0.37814639424439145,-3.1817399204617014
738.6000000000101,86.43370816501898,0.38291122726594273,-3.181740131343551
739.7000000000102,86.54567277815781,0.38818661217687467,-3.1830659005918034
740.8000000000102,86.65927558930748,0.3928230730692497,-3.1817481330203363
741.9000000000101,86.77189050152933,0.3952071983151566,-3.1843801179783973
743.0000000000101,86.88420173637785,0.39872324357532696,-3.184969076901836
744.1000000000101,86.99717900965675,0.4036072943627833,-3.1858072221286955
745.2000000000102,87.10897755483643,0.41020490271228716,-3.185702489153008
746.3000000000102,87.22289105531057,0.408263091430598,-3.1856881749149824
747.0000000000102,87.29492787505987,0.4136952503801259,-3.1856899550037148