File: 01_Data/Corrugated_Cardboard/STA/N2/10K_min/Corrugated_Cardboard_STA_N2_10KData_230814_R2.csv
##Temp./Â°C,Time/min,DSC/(mW/mg),Mass loss/mg
27.0,15.8660245388807,0.09330261277779872,-0.1506340711873646
28.100000000000016,16.157020258194866,0.11559387511166186,-0.14812915477157818
29.20000000000003,16.372761597368875,0.1364460726149641,-0.14951006034555325
30.300000000000047,16.54787748955357,0.15409674449674915,-0.1485869286839443
31.400000000000063,16.716969068159642,0.1702189855137517,-0.14873130324512784
32.50000000000008,16.867759334750716,0.1861144217559514,-0.1499734364869525
33.600000000000094,17.013310082033236,0.1993527846807619,-0.1531025409885589
34.70000000000011,17.152760539528472,0.21228380638916855,-0.15149735829721367
35.800000000000125,17.288502039819278,0.22709166867742292,-0.15325327876843664
36.90000000000014,17.418325234248044,0.23709424399570223,-0.15341331596699614
38.000000000000156,17.549889745030065,0.2483702417562219,-0.15468213872077596
39.10000000000017,17.678856802955867,0.2618341070729997,-0.15602318101925317
40.20000000000019,17.806728413176053,0.27316836875168793,-0.1577443777813805
41.3000000000002,17.93212529945823,0.28307287647159995,-0.16029465360726158
42.40000000000022,18.055658634894122,0.2955611887492673,-0.15995204624040493
43.500000000000234,18.18020549601317,0.30839935294552334,-0.16127807217092682
44.60000000000025,18.302253298364167,0.3193836659527367,-0.16461281189389432
45.700000000000266,18.423153164401796,0.331255992389877,-0.165410054025235
46.80000000000028,18.544727908803377,0.34185310311209327,-0.16687978787717572
47.9000000000003,18.66498296657633,0.35319722503147455,-0.16818981392364662
49.00000000000031,18.78352491450853,0.3632752198319422,-0.1721330665182803
50.10000000000033,18.90248969587952,0.37473226952586125,-0.1734639094148709
51.200000000000344,19.0207734717157,0.38671813753582396,-0.17608955685813665
52.30000000000036,19.137879919855692,0.3953679624183153,-0.1800982816441321
53.400000000000375,19.257240935867884,0.40600876461797797,-0.18092916601212927
54.50000000000039,19.373116139031378,0.4156128445595497,-0.18404369394931397
55.600000000000406,19.4883867360074,0.42245618594424106,-0.18521577526796218
56.70000000000042,19.602845936818415,0.4321830086690559,-0.187383402320902
57.80000000000044,19.7183269464046,0.4413530290808594,-0.19190781466652096
58.90000000000045,19.831943222960597,0.4474233680795181,-0.194546425451247
60.00000000000047,19.943830445579525,0.45196717582927426,-0.19716112997813928
61.100000000000485,20.05988331252811,0.4559262891671798,-0.19848889088428567
62.2000000000005,20.171239895533933,0.46315300543174653,-0.2024430079819055
63.300000000000516,20.283636034449472,0.46645520210079017,-0.20507954777019544
64.40000000000053,20.395190672932944,0.4685485105449534,-0.2063913550410148
65.50000000000054,20.505103053068577,0.4709330327589334,-0.20902362931582186
66.60000000000056,20.61674894025953,0.4698464549397814,-0.21165620111483996
67.70000000000059,20.727825136407557,0.47182205744518324,-0.21560025899471702
68.8000000000006,20.838299666537722,0.47139827317844984,-0.21825260186589235
69.9000000000006,20.94782346954386,0.47002661758533937,-0.22088301311691172
71.00000000000063,21.059046863963268,0.46512343845508086,-0.22483911900287712
72.10000000000065,21.1675507400941,0.4641852967476132,-0.22882802359077958
73.20000000000066,21.2771787221898,0.46083882885735594,-0.23140061197578277
74.30000000000067,21.388810439396515,0.45850022031089965,-0.2327400075255146
75.40000000000069,21.49631586134313,0.45181269846546557,-0.23537935358199702
76.50000000000071,21.606162504590753,0.44661606420901867,-0.23907160647900705
77.60000000000072,21.71517782812324,0.4429051435504534,-0.2406395125295533
78.70000000000073,21.823426275425113,0.4360098924649356,-0.2419658909791056
79.80000000000075,21.931848304666982,0.4283107068913259,-0.24459564020190738
80.90000000000077,22.040398266454027,0.4230056972321721,-0.24722688605932097
82.00000000000078,22.14956832946869,0.4159809332863682,-0.2497219107983626
83.10000000000079,22.258433627761423,0.4075706379043824,-0.252027966271708
84.20000000000081,22.36742880748917,0.39776285787454757,-0.25362357899404886
85.30000000000084,22.47544951910883,0.38981466388442465,-0.2551624650485027
86.40000000000084,22.58408647466419,0.3799329737671988,-0.2577630705421634
87.50000000000085,22.689728028481035,0.3712335818566914,-0.25908988610713957
88.60000000000088,22.799605445160743,0.3628820902950314,-0.26040993425009873
89.7000000000009,22.906975422169744,0.3522260537504571,-0.2617333479868904
90.8000000000009,23.013239471353902,0.3459345344882563,-0.26434997981147257
91.90000000000092,23.120799567225895,0.3359863457185994,-0.2659104671928785
93.00000000000094,23.225522019819685,0.32970403742018695,-0.2669900000899137
94.10000000000096,23.333887499244298,0.31819320663125117,-0.26688017756698645
95.20000000000097,23.440695918640344,0.3102968346969823,-0.26963001783841634
96.30000000000098,23.54726422859105,0.30037047850270415,-0.27094309295997876
97.400000000001,23.65367027281052,0.2936331652713069,-0.27227457091263974
98.50000000000102,23.762226319899046,0.2855088709552869,-0.2722737806992295
99.60000000000103,23.86730666491941,0.27656546276698424,-0.27358000507435554
100.70000000000104,23.97312688584122,0.2698686771334313,-0.2748999999999997
101.80000000000106,24.078792950392838,0.2629250546907973,-0.27490000351925703
102.90000000000109,24.18629835511716,0.2557315110120899,-0.27538070978816753
104.0000000000011,24.292360325226458,0.2489763638328275,-0.2762203164195136
105.1000000000011,24.395511924770005,0.24411851409463003,-0.2775412009520686
106.20000000000113,24.50587218386955,0.23766365087295105,-0.27884999503918584
107.30000000000115,24.61088085832271,0.2308345904626221,-0.27884999999767723
108.40000000000116,24.716147934360926,0.22497648976822027,-0.2788483510764501
109.50000000000117,24.82210973886584,0.2185572849587485,-0.28017049364961366
110.60000000000119,24.928936166718742,0.2154910469186737,-0.28149555929222103
111.70000000000121,25.035193180247436,0.20956781676943037,-0.2814899999870373
112.80000000000122,25.14045010138235,0.2049490863471377,-0.2828100060226797
113.90000000000123,25.244982179539623,0.2022861931518931,-0.2814815072611099
115.00000000000125,25.35229798847396,0.19720020761943657,-0.28267485021659855
116.10000000000127,25.458109278099215,0.19507953686824098,-0.28214011069541023
117.20000000000128,25.563696620732696,0.1910551598233181,-0.28345979928615694
118.30000000000129,25.669023782222908,0.18963243343489378,-0.28279993099931255
119.40000000000131,25.776112874942985,0.1864845009609808,-0.28411999628324525
120.50000000000134,25.881257626599282,0.18438893536669188,-0.2841200653393443
121.60000000000134,25.986802450685694,0.1819319315348893,-0.2854402052702576
122.70000000000135,26.09287713106977,0.17920241651714863,-0.2851925559072077
123.80000000000138,26.199901647833155,0.17861540585814395,-0.2841264734123161
124.9000000000014,26.3057443992792,0.1765784859318662,-0.2847815373895397
126.0000000000014,26.41103858878976,0.17428530977352508,-0.2841213165332541
127.10000000000142,26.516926725921234,0.17175612185028322,-0.2854402825471505
128.20000000000144,26.623797946396735,0.17308646092690338,-0.28411976552961793
129.30000000000146,26.72918004330893,0.17251031843613895,-0.2841204752743338
130.40000000000146,26.835247467530657,0.1718513300397877,-0.28544001288560716
131.50000000000148,26.938279518968862,0.16826843135104075,-0.28543999999174474
132.6000000000015,27.045042085713295,0.16841494449241723,-0.285439159867785
133.70000000000152,27.15111639170794,0.17020079373581476,-0.2867543119386493
134.80000000000155,27.256361198551016,0.16748941811226237,-0.2854399982133855
135.90000000000154,27.363586883629097,0.1664591556040731,-0.28543958055817464
137.00000000000156,27.46902541064104,0.16596818205751362,-0.2867928549741552
138.1000000000016,27.57444006127691,0.1657736958396938,-0.285437441575902
139.20000000000158,27.679691276427636,0.16517548436964558,-0.2860999529651447
140.3000000000016,27.784916779428734,0.1665729611772797,-0.2851076106981276
141.40000000000163,27.889907590196167,0.16557725236301946,-0.28576999088084465
142.50000000000165,27.996534591551743,0.1661364717808047,-0.28547770457140986
143.60000000000167,28.101204573923415,0.1655983166417292,-0.28643021589808004
144.70000000000167,28.207271518324372,0.16490312851317634,-0.2854678927291845
145.8000000000017,28.31295423328418,0.16504863862127395,-0.2867277864962756
146.9000000000017,28.41790323403266,0.16519036556198508,-0.28535069115314515
148.0000000000017,28.524485545468238,0.1647407802950973,-0.28675123253393453
149.10000000000173,28.62990039791758,0.16691977144666215,-0.28757310313568674
150.20000000000175,28.734142197127493,0.16538323603532556,-0.28674297272624694
151.30000000000177,28.83911225753005,0.16579569284799223,-0.2875924021441021
152.4000000000018,28.944989063631603,0.16505875895720945,-0.2867600770318073
153.5000000000018,29.05009843405282,0.16470206629559558,-0.28675999999999746
154.6000000000018,29.156082728621527,0.16398613766245362,-0.28675999985960887
155.70000000000184,29.259613151998092,0.16439805797026974,-0.2870843425013945
156.80000000000183,29.365988991252703,0.16407400801353855,-0.28676010555935383
157.90000000000185,29.471078448519226,0.16405309413343439,-0.2867701466734198
159.00000000000188,29.576047193657633,0.16324924857470235,-0.288069989752588
160.1000000000019,29.680369847841913,0.16471703775662938,-0.2880755061623952
161.20000000000192,29.786984271959504,0.16551921616069754,-0.28807000016733486
162.30000000000192,29.89087260892675,0.16656185164677684,-0.2880135391178902
163.40000000000194,29.996385885718745,0.16690225055104846,-0.2867499847423751
164.50000000000196,30.10127789405127,0.16709572642162995,-0.2870892140665129
165.60000000000196,30.20654656367676,0.16645687181297197,-0.2884000088269243
166.70000000000198,30.310387858935254,0.16797024803219096,-0.2883998952827378
167.800000000002,30.416945283793773,0.1680850384644066,-0.287410481998577
168.90000000000202,30.51980183297225,0.16835265747822103,-0.28733458782324117
170.00000000000205,30.626980505592073,0.16895382507962542,-0.2884068410437406
171.10000000000204,30.732363399015817,0.16945083122914895,-0.2884112625932551
172.20000000000206,30.835653215381733,0.16897404728033272,-0.28840199248837317
173.3000000000021,30.940667206039283,0.1688627997497174,-0.2886307795568537
174.40000000000208,31.04619838663025,0.16736557402002816,-0.28840133714772787
175.5000000000021,31.15148294104155,0.1695066168954047,-0.29082770864306706
176.60000000000213,31.25558987603125,0.16922667340578945,-0.2897436812153611
177.70000000000215,31.36060844354911,0.1680962902860943,-0.2897200482901554
178.80000000000217,31.46523760652644,0.16882408440836194,-0.28971999999962117
179.90000000000217,31.57059625796156,0.16981680245367725,-0.2897202364372098
181.0000000000022,31.674987657890206,0.17016868666122598,-0.28997515050539624
182.1000000000022,31.779894870810804,0.17149904540461058,-0.28927127120328233
183.2000000000022,31.88391114793469,0.17299666048616302,-0.29094998642776826
184.30000000000223,31.987426705208705,0.17430960089423797,-0.2896099984136744
185.40000000000225,32.093958497935105,0.17340450084777048,-0.2896099973415245
186.50000000000227,32.199229492012726,0.17456384943794845,-0.2909327841198399
187.6000000000023,32.304177610370225,0.17387353434907338,-0.29093000014706316
188.7000000000023,32.40763631637336,0.1728922368588468,-0.2910119092201717
189.8000000000023,32.51359085796592,0.17356834140580002,-0.2912969385524917
190.90000000000234,32.6187063636709,0.1746461961713348,-0.2912497315330662
192.00000000000233,32.72306824612666,0.17282425942108937,-0.2916000402552923
193.10000000000235,32.827245808863125,0.17385507914908893,-0.2909200371256029
194.20000000000238,32.93257448164296,0.17352132806358855,-0.2922391767854231
195.3000000000024,33.03672931043575,0.171965503828454,-0.2910749002794297
196.40000000000242,33.14203382039548,0.17497548224830006,-0.2937799499854057
197.50000000000242,33.24628153415251,0.17545224901375223,-0.2937800208678407
198.60000000000244,33.35069700919232,0.17489557336634443,-0.29389098704083194
199.70000000000246,33.45711950560729,0.17481774286068585,-0.2950817103578327
200.80000000000246,33.560000000000244,0.17652863639558602,-0.2938024426110366
201.90000000000248,33.66574219353691,0.17548975090737207,-0.2937713967622013
203.0000000000025,33.770192247364825,0.17555904784831178,-0.2937800000033044
204.10000000000252,33.87547049391232,0.17662513756897535,-0.29378000006319516
205.20000000000255,33.97991010802037,0.17615748317445856,-0.2937800822568848
206.30000000000254,34.08409726782171,0.17729973228776208,-0.2947699804130166
207.40000000000256,34.18971054164591,0.17779247006270205,-0.2947702952540783
208.5000000000026,34.294335732303686,0.177414180134581,-0.2960899931114511
209.60000000000258,34.39812077238799,0.17745592000579924,-0.2960899999999853
210.7000000000026,34.5030834785455,0.17812694510571725,-0.29609001442137073
211.80000000000263,34.607887422450666,0.17974888824315194,-0.29504828677493977
212.90000000000265,34.71064611723219,0.18049254951320037,-0.29802694171748856
214.00000000000267,34.8157650626626,0.18151971321332505,-0.2987199998028469
215.10000000000267,34.920507278802376,0.1811430018239104,-0.2987200000000141
216.2000000000027,35.025874330180315,0.18101237695293015,-0.2987200007838915
217.3000000000027,35.13074837204316,0.17917151510351337,-0.3002564919665951
218.4000000000027,35.23405683299248,0.18038199137954036,-0.29894192945272646
219.50000000000273,35.33692153955086,0.18059351364129772,-0.298939984609385
220.60000000000275,35.443469020476016,0.18090933257165154,-0.3002615076961286
221.70000000000277,35.5478447129307,0.1802467754621926,-0.30157325162568904
222.8000000000028,35.65186304511791,0.18197598028387052,-0.3001757350759746
223.9000000000028,35.757547138527954,0.1811967221962858,-0.30575379931405333
225.0000000000028,35.861776502209814,0.18167561084670214,-0.3029632333667962
226.10000000000284,35.96611647961724,0.1835084684003181,-0.3048469659050741
227.20000000000283,36.070194099259716,0.182513469379751,-0.30586969398996944
228.30000000000285,36.175269311544305,0.1830699861315246,-0.3045464742073283
229.40000000000288,36.27928417525508,0.18532480352450587,-0.30543447151965086
230.5000000000029,36.3820853003635,0.18436829680219446,-0.3069697523239796
231.60000000000292,36.4889049112493,0.18541991620335319,-0.308071160716052
232.70000000000292,36.593285049242034,0.183119016626049,-0.3113115388196772
233.80000000000294,36.69846791175377,0.18619578125294556,-0.3113410415739093
234.90000000000296,36.80307545488428,0.1879488275286607,-0.311349556706777
236.00000000000296,36.90745930332602,0.18650497277219347,-0.31343061447098197
237.10000000000298,37.012565762451516,0.18711879742437065,-0.313980000087855
238.200000000003,37.11656182127666,0.18743870388377215,-0.3152694011838735
239.30000000000302,37.22088943072216,0.18827531837722677,-0.31660433827063583
240.40000000000305,37.32527468705201,0.18684770623535263,-0.3178544044223637
241.50000000000304,37.428466997505176,0.18942558816348898,-0.3189178345211814
242.60000000000306,37.53425461519115,0.19014243873503367,-0.32079804856228833
243.7000000000031,37.63882159264494,0.1913501602283929,-0.3231353188237098
244.80000000000308,37.74386514638889,0.19151331927970316,-0.32451215347630535
245.9000000000031,37.84917578954693,0.196206563443186,-0.32584982142982977
247.00000000000313,37.95305408143746,0.19573632831760412,-0.33002371163909316
248.10000000000315,38.05743902742049,0.19592049370678288,-0.3300004807278385
249.20000000000317,38.16296527812455,0.192928081162131,-0.33194677683076934
250.30000000000317,38.26730106868117,0.1945433021508558,-0.3344328912327783
251.4000000000032,38.373250420927015,0.1943168501616246,-0.33689593907005433
252.5000000000032,38.477862301693214,0.19494448702287936,-0.3394082370962317
253.6000000000032,38.583120874523246,0.19537816160506494,-0.3405504180468153
254.70000000000323,38.68654048015459,0.1957004987434503,-0.3457899899827166
255.80000000000325,38.79282872453151,0.19493216670731983,-0.3484508670221853
256.9000000000033,38.897584247242435,0.19303868309596206,-0.35114144930867175
258.0000000000033,39.000880865044174,0.18938176159289988,-0.35410785666191114
259.1000000000033,39.10496749464337,0.18516431301829694,-0.35747738976338717
260.20000000000334,39.21183165782583,0.1813448211341857,-0.36069692496157524
261.30000000000337,39.316881096512425,0.1768980199679817,-0.36337278317728616
262.40000000000333,39.421753607349004,0.16977279783579813,-0.3675008169326799
263.50000000000335,39.52683886053894,0.16562185781617655,-0.3712190491118603
264.6000000000034,39.631326233438116,0.1632095162328826,-0.37604334506410364
265.7000000000034,39.73659926318019,0.1628341933425732,-0.38021193609078985
266.8000000000034,39.84086228862299,0.16115383606483658,-0.3850291274275168
267.9000000000034,39.94681741605739,0.15996970752651363,-0.38943285077897194
269.0000000000034,40.050521730101416,0.1592246068803429,-0.39474281330709937
270.10000000000343,40.15661944531081,0.15935363087422627,-0.4001379011348969
271.20000000000346,40.26130977591687,0.16000781283841148,-0.40557937185163784
272.3000000000035,40.36473797916995,0.1606952453405417,-0.4102879780272781
273.4000000000035,40.470820420566625,0.15730258075431802,-0.41616113724252557
274.5000000000035,40.57663749090535,0.15810095943271585,-0.4216729662204708
275.60000000000355,40.680684555737976,0.15605012015523867,-0.4282784725798452
276.70000000000357,40.785908776504506,0.15773215117272987,-0.43494655776370994
277.8000000000036,40.89186592664544,0.1566659746764616,-0.44308215887958013
278.9000000000036,40.99709913189322,0.15573128134683878,-0.4499993231515824
280.0000000000036,41.100197987161636,0.15622251023988332,-0.4581242719610068
281.1000000000036,41.207405146655354,0.15617481547314904,-0.4646119359078442
282.2000000000036,41.31220820217111,0.15613459590506906,-0.47295667493956817
283.30000000000365,41.418611629163095,0.15698576304808776,-0.48232745596131554
284.4000000000037,41.52371654756606,0.1548820966232014,-0.4912730809767938
285.5000000000037,41.62810867842432,0.1582314133479712,-0.4996828509730902
286.60000000000366,41.73503892378724,0.1566136382655774,-0.5095941666749697
287.7000000000037,41.84020150223997,0.15917180054777957,-0.5196170077292575
288.8000000000037,41.9455360087806,0.1595125592257487,-0.5311229107436923
289.90000000000373,42.05136189890365,0.1608669887037557,-0.5425154625580855
291.00000000000375,42.157003020200236,0.16469242289641084,-0.5524963180888984
292.1000000000038,42.26115071941203,0.16621167759826583,-0.5646146239996575
293.2000000000038,42.36833267708933,0.16675394806092458,-0.576429900047374
294.3000000000038,42.473145500695956,0.16682958983146,-0.5886191629436444
295.40000000000384,42.57892141293555,0.1699199432481795,-0.6016949800157851
296.5000000000038,42.68410850343211,0.17190718415776374,-0.6155929939557883
297.60000000000383,42.79089440319294,0.17328328903770407,-0.6286430127676819
298.70000000000385,42.89460588476037,0.17420280135065136,-0.6415520490301563
299.8000000000039,43.00139541248758,0.17601402620492368,-0.6557600905397303
300.9000000000039,43.107012629516746,0.1798813624755331,-0.6705045740376709
302.0000000000039,43.21290529173317,0.1815722141131375,-0.6869236319453451
303.10000000000394,43.3190062503937,0.182760146473107,-0.7032866274616225
304.2000000000039,43.4246956962899,0.1858471715082728,-0.719003952412347
305.30000000000393,43.5303972460537,0.18904491258192446,-0.7353860814381394
306.40000000000396,43.635703325652656,0.1914116843313527,-0.7504893584514027
307.500000000004,43.74184934897065,0.19315106724249298,-0.7720916307447254
308.600000000004,43.84718679364315,0.1978008619252174,-0.7908389689425084
309.700000000004,43.95295360835846,0.1982433817494753,-0.8105419753583032
310.80000000000405,44.058494443901274,0.20110524026209653,-0.829787589443681
311.90000000000407,44.16519564652712,0.2046307679700663,-0.8496547857438377
313.0000000000041,44.27050416714807,0.20692835568283074,-0.8690050362267527
314.10000000000406,44.37678363288619,0.21155929671902562,-0.8907368696339968
315.2000000000041,44.4827962090094,0.21565109856397968,-0.9123715395489032
316.3000000000041,44.58814457832236,0.2184105733424364,-0.9345240387639944
317.4000000000041,44.69341482959637,0.2214870075016553,-0.9568867749419177
318.50000000000415,44.79939464386392,0.22421896618808268,-0.9808104122134131
319.6000000000042,44.905951423714974,0.226444981153074,-1.0067425892388484
320.7000000000042,45.01277434130908,0.23037393598038425,-1.029588185491113
321.80000000000416,45.11735109473946,0.2359256354225292,-1.0556913349074462
322.9000000000042,45.22293041366837,0.23872522303288712,-1.0804970727315806
324.0000000000042,45.32924404109774,0.2431120872696737,-1.1081900600075851
325.10000000000423,45.43536857657829,0.24686678578540655,-1.1365733058279028
326.20000000000425,45.54103374787773,0.2520074688334146,-1.1637283675949588
327.3000000000043,45.647793418096526,0.25728620797481994,-1.193235518854285
328.4000000000043,45.753387118172945,0.26296031664701336,-1.2243839831028773
329.5000000000043,45.86058901959276,0.26881135976917014,-1.2557505446317556
330.60000000000434,45.966687418378854,0.2760433186343023,-1.2865598075383216
331.7000000000043,46.07332175906706,0.2811792543653262,-1.3184354362158133
332.80000000000433,46.17971097603635,0.2892728421061932,-1.3519888570619978
333.90000000000435,46.28719860123994,0.29605115540311666,-1.3847685163334318
335.0000000000044,46.3925534185339,0.30285081304703465,-1.4213684960113948
336.1000000000044,46.49989052964777,0.3098942301410874,-1.4576653067658008
337.2000000000044,46.60594277035482,0.3212307266780423,-1.4941723115642613
338.30000000000445,46.71323192830477,0.32549050271899427,-1.5320776441784565
339.4000000000044,46.818085081664336,0.33498594050808794,-1.5715953886818093
340.50000000000443,46.92599224412,0.3430559742077155,-1.6110098795379493
341.60000000000446,47.033659032175706,0.35285018074782526,-1.6532053276195855
342.7000000000045,47.14050730442314,0.3593060727163724,-1.696679838178924
343.8000000000045,47.248129233029765,0.3653886619158173,-1.7379927146645104
344.9000000000045,47.35432167950385,0.37440427098845497,-1.7816417488843768
346.00000000000455,47.46167925097647,0.37866676095107743,-1.828489245286156
347.10000000000457,47.56810432581241,0.3863553930264845,-1.874394805538195
348.2000000000046,47.67458937062543,0.39144709389639765,-1.9185487986230507
349.30000000000456,47.77979661791322,0.39533809070699033,-1.9667068231849787
350.4000000000046,47.889117193016695,0.396706781148503,-2.014810992470312
351.5000000000046,47.99616262988807,0.3980211193849357,-2.063058709525629
352.6000000000046,48.10291550983282,0.39605253640077165,-2.1122647071797407
353.70000000000465,48.20848656535525,0.39172548106869165,-2.1594799376010605
354.8000000000047,48.31469717287635,0.38383823344022816,-2.208072672595926
355.9000000000047,48.42098594630103,0.3737051925366197,-2.25633941682265
357.00000000000466,48.52542290362195,0.3587000109869143,-2.3013236093981897
358.1000000000047,48.633522224440824,0.34475053457029947,-2.3477682282274808
359.2000000000047,48.73907554945945,0.32303908284996896,-2.3915630021041396
360.30000000000473,48.842468929262665,0.30224594787622583,-2.432830088158953
361.40000000000475,48.95081081064805,0.27600834454640255,-2.475983661138484
362.5000000000048,49.055749042592375,0.24778603060744375,-2.5146224258914165
363.6000000000048,49.16091408465028,0.21807831355185292,-2.5486580777156425
364.7000000000048,49.26651946897275,0.18834078699281687,-2.5817204739632644
365.80000000000484,49.37215532281097,0.15673511383274974,-2.612746228903459
366.9000000000048,49.47623051820444,0.12556674466990092,-2.639700587950216
368.00000000000483,49.58251859151055,0.09702411499917063,-2.6660257056437424
369.10000000000485,49.68724074447918,0.06799955645427902,-2.6881079028807027
370.2000000000049,49.793359089935976,0.04198144397432202,-2.7083503102768938
371.3000000000049,49.899581221324446,0.015750797693308005,-2.728362541470431
372.4000000000049,50.00413297724101,-0.009151750452621288,-2.744112718197634
373.50000000000495,50.11039610345557,-0.0323698497662408,-2.758907473893643
374.6000000000049,50.216548519594475,-0.054631099947388906,-2.772655025424914
375.70000000000493,50.323269309674224,-0.07670734187149453,-2.7840294821801743
376.80000000000496,50.42923910580245,-0.09889495253066105,-2.794107056920857
377.900000000005,50.535011880095446,-0.1152899300281296,-2.8037970655514846
379.000000000005,50.64054400835924,-0.13358104777249702,-2.8114737526861524
380.100000000005,50.74529402190496,-0.1443484937669326,-2.8192416249571313
381.20000000000505,50.85384352933637,-0.15862029451000748,-2.824058000241112
382.30000000000507,50.9603017210192,-0.16800441327643134,-2.82926054209121
383.4000000000051,51.066800652910125,-0.17408365329619802,-2.8346265035773985
384.50000000000506,51.17396282412753,-0.17988997249281669,-2.8390728205142715
385.6000000000051,51.279894582768144,-0.18361101415264658,-2.843495972039996
386.7000000000051,51.38720237699668,-0.18766822515438664,-2.847845785353559
387.8000000000051,51.49476262451039,-0.19294187135350116,-2.850608113068638
388.90000000000515,51.60145080088083,-0.19606102659886782,-2.8546181661155727
390.0000000000052,51.70968672594235,-0.19772144899234534,-2.8573319953232996
391.1000000000052,51.81646009030173,-0.20075718087291183,-2.8606748959176
392.20000000000516,51.92286808052946,-0.20401625382126287,-2.864444086652651
393.3000000000052,52.03055718761297,-0.2072703637838107,-2.868245158155368
394.4000000000052,52.13811161006169,-0.21127718616260038,-2.871120588221758
395.50000000000523,52.245059203300755,-0.2127302726831699,-2.874150543252161
396.60000000000525,52.3527164399236,-0.21614680692147403,-2.8777014320556287
397.7000000000053,52.460178077386715,-0.2210984589860936,-2.8811611340319256
398.8000000000053,52.56771638878013,-0.2243268194864707,-2.8855530481970626
399.9000000000053,52.674887911208906,-0.2272245760538667,-2.8878468064228455
401.00000000000534,52.78264663805177,-0.23058656717999093,-2.8907132460991507
402.1000000000053,52.8896050018986,-0.23523757222478103,-2.8946615583313675
403.20000000000533,52.99853052042176,-0.23886754063764437,-2.897432907030095
404.30000000000535,53.10543751061574,-0.24225628297417612,-2.900220016559736
405.4000000000054,53.21099022103733,-0.24593619363554753,-2.9035736946008592
406.5000000000054,53.32032601118926,-0.2478480274714705,-2.906176790985339
407.6000000000054,53.427856985267184,-0.24816951678604626,-2.9107303616525133
408.70000000000545,53.53584374028751,-0.25270131609590707,-2.9118940018751456
409.8000000000054,53.642832883714256,-0.2573295845675725,-2.915799976254987
410.90000000000543,53.74932911553878,-0.2577224951522987,-2.918373429721671
412.00000000000546,53.857430960788975,-0.2604494393940304,-2.922267332758654
413.1000000000055,53.96651996375368,-0.26334291900813533,-2.925060534452167
414.2000000000055,54.07438557854266,-0.26836151460281243,-2.9280273341458694
415.3000000000055,54.183632175346574,-0.2673277870544395,-2.9304389027469915
416.40000000000555,54.29072024613953,-0.26933667383134785,-2.932429290676354
417.50000000000557,54.397617999007984,-0.27080514708850223,-2.935040877032328
418.6000000000056,54.50659776702348,-0.26882871847658585,-2.9387126941821715
419.70000000000556,54.61372661542093,-0.26614796474983526,-2.9417867916115625
420.8000000000056,54.72240530850544,-0.2599830537438874,-2.9444911148982937
421.9000000000056,54.83066112950765,-0.25052017670521076,-2.94609886010385
423.0000000000056,54.93756440749443,-0.24346165888286597,-2.949689534091215
424.10000000000565,55.04616668914581,-0.23641535638823585,-2.952401813422996
425.2000000000057,55.15462552898002,-0.22944930596461077,-2.955029177481788
426.3000000000057,55.261887058787146,-0.224910070111209,-2.957688449428894
427.40000000000566,55.371988768249054,-0.22094791403566538,-2.9604133974854907
428.5000000000057,55.47951946639567,-0.21641410546984297,-2.9639070360928184
429.6000000000057,55.587531799477794,-0.21302874893898616,-2.966565719992108
430.70000000000573,55.69527298512055,-0.21190010972436135,-2.9678896919999227
431.80000000000575,55.803818575506305,-0.21062228464269106,-2.9704911504475224
432.9000000000058,55.91138679915806,-0.20565909686586337,-2.9733254089477645
434.0000000000058,56.01980046547694,-0.20381724083827368,-2.9759030884398032
435.1000000000058,56.127854721074236,-0.20118163077511508,-2.9790230527736856
436.20000000000584,56.2340976765689,-0.19903901437300942,-2.9810987332740124
437.3000000000058,56.344240232383825,-0.19318773442989956,-2.983864457800932
438.40000000000583,56.45246305876689,-0.18843523895687775,-2.985300192378852
439.50000000000585,56.56040557372786,-0.18311443084724455,-2.987792125202504
440.6000000000059,56.668822043901436,-0.17951990947096697,-2.9897519468567912
441.7000000000059,56.77488956596352,-0.1817164144149337,-2.992136470512266
442.8000000000059,56.88525020246125,-0.18062006411542408,-2.994769179927582
443.90000000000595,56.99132816096505,-0.17917811765822322,-2.996206464705784
445.0000000000059,57.10187304106554,-0.17840250929519286,-3.0001679260386838
446.10000000000593,57.21010322118064,-0.17597920054340221,-3.0003832191753763
447.20000000000596,57.319896867578834,-0.17628291277389452,-3.004218956249458
448.300000000006,57.42764274894178,-0.17490858985536883,-3.0048083489309003
449.400000000006,57.53561965545024,-0.1737765447327395,-3.0075219922278165
450.500000000006,57.6448799974555,-0.17109366711985063,-3.0101492260528175
451.60000000000605,57.753212752879456,-0.1721652158181517,-3.009081993892476
452.70000000000607,57.8621189747259,-0.16992609944187365,-3.015574144124969
453.8000000000061,57.9676711849655,-0.17005421754071404,-3.016703670497076
454.90000000000606,58.07928767128071,-0.16693186995523313,-3.018169841211353
456.0000000000061,58.18766548295647,-0.16866583275098712,-3.0209375690594014
457.1000000000061,58.29589111073606,-0.16576960043602118,-3.023540916583682
458.2000000000061,58.40549992266379,-0.1660431098420243,-3.0236562197097774
459.30000000000615,58.514880447006924,-0.1628802402448455,-3.025704264031826
460.4000000000062,58.62319971422487,-0.16237443393517936,-3.028019090266388
461.5000000000062,58.73129123019332,-0.16387030235569,-3.0291400505854114
462.60000000000616,58.83813171001894,-0.16423650992358163,-3.0309593389368814
463.7000000000062,58.949150775896,-0.16517014702434185,-3.0333529498987195
464.8000000000062,59.05765672862114,-0.16809833322282874,-3.035710699689137
465.90000000000623,59.16594219919768,-0.17030522865304798,-3.0370462878538564
467.00000000000625,59.27540550783627,-0.17141820430757182,-3.039242311722661
468.1000000000063,59.38383401799679,-0.17669055662367716,-3.04099843233799
469.2000000000063,59.49275842362669,-0.17820761222825476,-3.042295878204868
470.3000000000063,59.601356440172275,-0.1805075435830421,-3.043191123129311
471.40000000000634,59.71115641203831,-0.18140026617663985,-3.0462760271355727
472.5000000000063,59.817433604520716,-0.1843283282067989,-3.0463025332928098
473.60000000000633,59.92970911909604,-0.18767168017884783,-3.0485492970768684
474.70000000000636,60.03894247844888,-0.18676790921663722,-3.0508681908117996
475.8000000000064,60.14899164072823,-0.19164852974382263,-3.052200223337382
476.9000000000064,60.25666282707251,-0.19226070914078242,-3.0539038321424226
478.0000000000064,60.36679777760249,-0.19586336511787583,-3.056123869530631
479.10000000000645,60.475683079371265,-0.1999414192262452,-3.0574600597795865
480.2000000000064,60.58440181460564,-0.20330217110104676,-3.0581017823640555
481.30000000000643,60.693907374339005,-0.20524239317516701,-3.059440653435435
482.40000000000646,60.80378081215271,-0.20747393736513198,-3.0606021190641686
483.5000000000065,60.91331728027147,-0.20655642939009056,-3.062343392782186
484.6000000000065,61.02225059989341,-0.21312755208567546,-3.062922415982049
485.7000000000065,61.132096687724896,-0.21837095487523106,-3.064058192994983
486.80000000000655,61.24118103171383,-0.22526800296894867,-3.066679272819783
487.90000000000657,61.34927026373099,-0.23244150535612573,-3.0680088373124543
489.0000000000066,61.45899553157599,-0.24119498596903166,-3.069575976074719
490.10000000000656,61.56776738169441,-0.2547552930019128,-3.0719333558610837
491.2000000000066,61.678154404605024,-0.2721167544340308,-3.071969853372753
492.3000000000066,61.78682681008836,-0.28059023005946226,-3.073928693032501
493.4000000000066,61.89585966563613,-0.2878110831870555,-3.0759103795701
494.50000000000665,62.002590901052926,-0.29584474890049295,-3.076899236417579
495.6000000000067,62.113844715241946,-0.3002557806414168,-3.075952845197731
496.7000000000067,62.223690665900726,-0.30895492912078093,-3.0786549879310945
497.80000000000666,62.33283487960031,-0.3148804458428507,-3.0807700101460886
498.9000000000067,62.44135441262152,-0.32101291077173166,-3.081575152389549
500.0000000000067,62.55071068397292,-0.3284795952786279,-3.0820271935081514
501.10000000000673,62.660285689543315,-0.33622613279442226,-3.0840405426089132
502.20000000000675,62.76921992010686,-0.34089648013978247,-3.085359728029352
503.3000000000068,62.8788352856049,-0.34584667739981767,-3.0840535209773727
504.4000000000068,62.9879492990707,-0.3513528771808958,-3.0865166772355646
505.5000000000068,63.09680742876107,-0.3549073881931739,-3.0892827613983567
506.60000000000684,63.20675803313229,-0.3600477895063139,-3.0904702529238044
507.7000000000068,63.315625419886366,-0.366202857660751,-3.0906200889169946
508.80000000000683,63.42617553762182,-0.3717588156750993,-3.09081902615582
509.90000000000686,63.53595532626764,-0.3764748423813815,-3.0937038660204896
511.0000000000069,63.64548959503706,-0.3797791309211638,-3.095081735764967
512.100000000007,63.75550742320886,-0.38316099097369327,-3.096329298899405
513.2000000000069,63.86554503014485,-0.38847932605783875,-3.0963300660705553
514.300000000007,63.97474642156879,-0.39015461616293035,-3.0976490056702835
515.4000000000069,64.08479361271353,-0.3944956146720353,-3.098496022285551
516.5000000000069,64.19547501581134,-0.40249092517913754,-3.098959366835324
517.600000000007,64.30570916651016,-0.4049243360044865,-3.1002854301320775
518.700000000007,64.41464421585104,-0.4052479234703863,-3.101927876456561
519.800000000007,64.52641344834844,-0.41097623605057243,-3.103563566721098
520.900000000007,64.63570526000764,-0.41283351958572956,-3.104105238828038
522.000000000007,64.74553617254676,-0.41310829058712795,-3.1048870763959298
523.1000000000071,64.85538805055936,-0.41438193493821385,-3.1076061777495765
524.2000000000071,64.96474346762133,-0.4146771164391585,-3.1062138051794177
525.300000000007,65.07479710000672,-0.4178118991179345,-3.1075301225062635
526.4000000000071,65.18505335703533,-0.41652309989112957,-3.108849886033155
527.500000000007,65.29497548586414,-0.41517287998929997,-3.1088445517214307
528.6000000000072,65.40407378967033,-0.4147520446178101,-3.1101699993482175
529.7000000000071,65.51401897481011,-0.4151705044092888,-3.111422203773561
530.8000000000072,65.62465108591823,-0.41543256448454,-3.1127985823746576
531.9000000000071,65.73554230108786,-0.41705941346336406,-3.1138741983348077
533.0000000000072,65.84570657841617,-0.4192142817295921,-3.1150937540102044
534.1000000000072,65.9552875252998,-0.4188284396699633,-3.115110259756662
535.2000000000072,66.06594980177226,-0.4181633646099623,-3.1177399421621876
536.3000000000072,66.17491182739515,-0.41931691601523524,-3.1164197185793516
537.4000000000073,66.28688970189127,-0.41869910203173255,-3.1163420247543447
538.5000000000073,66.3960045755525,-0.42079335006633234,-3.1177400009264993
539.6000000000073,66.50438916236638,-0.4192608334055581,-3.118978304365104
540.7000000000073,66.61614822767719,-0.42008069830919403,-3.121369271623813
541.8000000000073,66.72726551372509,-0.41729891780440576,-3.1200448014116287
542.9000000000074,66.83654049492169,-0.4183975458626581,-3.122647253634939
544.0000000000074,66.94701435622049,-0.4184421591608978,-3.123340344275438
545.1000000000074,67.05688534303457,-0.41557247420135224,-3.1234923457485655
546.2000000000073,67.16683215582405,-0.4170853717477463,-3.1258389222551743
547.3000000000073,67.27812796893066,-0.41754710858198996,-3.1259699984552345
548.4000000000074,67.38723382202028,-0.4185197051065217,-3.1272958660575148
549.5000000000074,67.49593539497647,-0.41805185691658897,-3.128610320418187
550.6000000000074,67.60643217795003,-0.4184282022932613,-3.129969899313612
551.7000000000074,67.71848024132281,-0.41769856141566386,-3.12927008733234
552.8000000000075,67.82862654858053,-0.4168276877756447,-3.1305799633835236
553.9000000000075,67.9407176502538,-0.4186496515466731,-3.1305800006335645
555.0000000000075,68.0504119540927,-0.41696709670643317,-3.1318967923486856
556.1000000000075,68.1609294421452,-0.4164467791966928,-3.1328678759850477
557.2000000000075,68.271407116039,-0.4153545845297324,-3.134530572670643
558.3000000000076,68.3810640400324,-0.4134031221548844,-3.13321142749614
559.4000000000076,68.49275892564025,-0.41492796893128436,-3.135740674239956
560.5000000000076,68.60390416546721,-0.4169469157053096,-3.1364063184119075
561.6000000000076,68.71316159889282,-0.4163302265271802,-3.1358500791882014
562.7000000000077,68.8228795761576,-0.41694365349199347,-3.1371697627645814
563.8000000000077,68.93526457348108,-0.418780929676122,-3.1384782667103037
564.9000000000076,69.04522645566172,-0.41757083301550746,-3.138479424122086
566.0000000000076,69.15656559123778,-0.41940671227968496,-3.139799983039585
567.1000000000076,69.26615630788135,-0.42075759390543666,-3.141130398060493
568.2000000000077,69.37586958527612,-0.4173922762267148,-3.1398091913011745
569.3000000000077,69.48910490709163,-0.42176766722174364,-3.1414590017202597
570.4000000000077,69.5976093741479,-0.42231883987213936,-3.1421096656102367
571.5000000000077,69.71020959046972,-0.4225695497162518,-3.1421094407367542
572.6000000000078,69.82182726958625,-0.42139828716281635,-3.143429942074441
573.7000000000078,69.9318363156352,-0.4227679904255126,-3.143429999833299
574.8000000000078,70.04246115800383,-0.42262704603466017,-3.1448382672245385
575.9000000000078,70.15314701520519,-0.4245904806363199,-3.1447499982422435
577.0000000000078,70.26400494287154,-0.4268875030839625,-3.146069598191366
578.1000000000079,70.37517176120615,-0.4267592177467139,-3.1463209531293512
579.2000000000079,70.48595431866092,-0.4268571403323995,-3.146408413887043
580.3000000000079,70.59766418770636,-0.425512559313457,-3.1478714736004973
581.4000000000078,70.70788509808494,-0.4285686894673906,-3.1491601906339395
582.5000000000078,70.81896284144776,-0.42963962113323184,-3.15149015363824
583.6000000000079,70.93010326156357,-0.4305106909679426,-3.1513299999953563
584.7000000000079,71.04167279745116,-0.42796943780823904,-3.1513300272596796
585.8000000000079,71.14978422678583,-0.43098555432394225,-3.152650013925483
586.9000000000079,71.26317727103712,-0.4294114530101918,-3.1525944785578344
588.000000000008,71.3736917368006,-0.43078563441704043,-3.153996515980375
589.100000000008,71.48426366341967,-0.4334359801863126,-3.1526067465251693
590.200000000008,71.59455352346312,-0.4342948124896828,-3.1553257009130733
591.300000000008,71.70637169356391,-0.43651482607417313,-3.155280000209472
592.400000000008,71.81716087457929,-0.4379644115865893,-3.1544590224152356
593.5000000000081,71.9274819011905,-0.43629456189920934,-3.155444369739218
594.6000000000081,72.03901834698812,-0.43698642121620446,-3.1565999998832557
595.7000000000081,72.14930683897065,-0.43772449129381674,-3.1565998201375054
596.8000000000081,72.2608604734079,-0.43778807121461116,-3.1566109201244474
597.9000000000082,72.37257288097608,-0.44188451613021873,-3.156747434031044
599.0000000000082,72.48351806533023,-0.43776217634062475,-3.157945687452286
600.1000000000081,72.59335267238305,-0.43737561896569543,-3.159402756449042
601.2000000000081,72.70493002061555,-0.43976113159591956,-3.161530245812378
602.3000000000081,72.81578275324742,-0.43776936041057835,-3.1615500123913876
603.4000000000082,72.92668851407636,-0.4353810985316453,-3.160867553743596
604.5000000000082,73.03869259185983,-0.43739319187353876,-3.1611891769011145
605.6000000000082,73.15010865101891,-0.43863964671803,-3.16386626458723
606.7000000000082,73.26020938373432,-0.4371752156897195,-3.1635055589737373
607.8000000000083,73.37319721786496,-0.4376014190576931,-3.164717566013888
608.9000000000083,73.4837999709782,-0.4381734829108088,-3.164927693092149
610.0000000000083,73.59402006508259,-0.43846997590932224,-3.166012328934054
611.1000000000083,73.70580999695828,-0.43894021626429414,-3.1673600011039142
612.2000000000083,73.81793747155015,-0.4351646134787672,-3.1673600000127546
613.3000000000084,73.92989788857506,-0.43787605052476875,-3.1673580175989517
614.4000000000084,74.04105739189525,-0.4365003458701544,-3.1686790669772797
615.5000000000084,74.15173313486375,-0.4370824066159904,-3.1673534019971745
616.6000000000083,74.26320145659918,-0.4346048189270555,-3.1702472141045526
617.7000000000083,74.37475543996167,-0.4328440131892375,-3.170110000258618
618.8000000000084,74.48619547764721,-0.4347062381611271,-3.170109762519586
619.9000000000084,74.59634415494152,-0.4400745813910534,-3.1714484839251496
621.0000000000084,74.70663514720376,-0.44507309385009886,-3.1727372358701227
622.1000000000084,74.81713636287576,-0.4503439605907509,-3.174504828294964
623.2000000000085,74.9284273078086,-0.44987315455461285,-3.1753798993010998
624.3000000000085,75.03874424759361,-0.44642024963245697,-3.174719821441908
625.4000000000085,75.15094527129197,-0.44255376752892017,-3.17602995449204
626.5000000000085,75.26154009170315,-0.43662850180556756,-3.1760300000388613
627.6000000000085,75.37295171103449,-0.42798465360730864,-3.1765663560392996
628.7000000000086,75.48338238901428,-0.4213969226027734,-3.1776493932339944
629.8000000000086,75.59628117865165,-0.4168963594236146,-3.1785372241920613
630.9000000000086,75.70732414788687,-0.4084252458079769,-3.179344399255453
632.0000000000086,75.81732725774947,-0.40564308604451704,-3.1806394540914136
633.1000000000087,75.92929171619353,-0.40218195487468233,-3.181959885604646
634.2000000000087,76.04115085429673,-0.3980212605030822,-3.18327986363001
635.3000000000086,76.15312434915963,-0.39643449234711947,-3.1845922890374343
636.4000000000086,76.26518654168787,-0.3936270607037682,-3.184595527770743
637.5000000000086,76.37466433372903,-0.3934856302621217,-3.185454817884055
638.6000000000087,76.48743844888823,-0.39036694110004033,-3.186652579707383
639.7000000000087,76.59876705858196,-0.3882039947799083,-3.1885496797460475
640.8000000000087,76.70958794305312,-0.3845657670690985,-3.189867667749052
641.9000000000087,76.82252928226026,-0.3850882078826272,-3.1900609451493542
643.0000000000088,76.93346387710066,-0.3854462644254919,-3.191189999943818
644.1000000000088,77.04507235434441,-0.38146366056734116,-3.1912168590595194
645.2000000000088,77.15554037965607,-0.38092219766991575,-3.192513058692445
646.3000000000088,77.2682664175369,-0.3839638481803491,-3.193159965771121
647.4000000000088,77.37888327915195,-0.3859838400138105,-3.1944637935585236
648.5000000000089,77.49128835017662,-0.3886573319402562,-3.193822482420357
649.6000000000089,77.60297595686595,-0.389743031967241,-3.1978905836787
650.7000000000089,77.71414138794225,-0.391346216477251,-3.1965560725427324
651.8000000000088,77.82622558144364,-0.39704592175671816,-3.1966744081585854
652.9000000000088,77.93731297204675,-0.39549193608109157,-3.1992050142927018
654.0000000000089,78.04866828179685,-0.40361683862645803,-3.2005203594440257
655.1000000000089,78.16033327523951,-0.40916171170142146,-3.2018405789536626
656.2000000000089,78.27154605395803,-0.4131251984306994,-3.203150000097591
657.3000000000089,78.38262614498211,-0.4175514366955313,-3.2023715409243136
658.400000000009,78.49457956075632,-0.42044346968548396,-3.20348000495468
659.500000000009,78.60665786669998,-0.4263804675993128,-3.2044412457370464
660.600000000009,78.71656903012845,-0.43253934710705977,-3.204799999939871
661.700000000009,78.82939948400339,-0.43913482334039644,-3.2045750917573237
662.800000000009,78.94192890996943,-0.4435804588507979,-3.2057811569202714
663.9000000000091,79.05319360578204,-0.4495095449998654,-3.20711612395705
665.0000000000091,79.16463578721547,-0.45367512514296715,-3.208030567136727
666.1000000000091,79.27615593167732,-0.4633546715077661,-3.207762180749789
667.2000000000091,79.3880001997763,-0.47159117949767904,-3.2084296767228393
668.3000000000092,79.5003321889242,-0.47775906863074025,-3.20842337189756
669.4000000000092,79.6120392044371,-0.48441009849581573,-3.210813396917428
670.5000000000091,79.72366837601284,-0.4903690341133129,-3.2096217640792553
671.6000000000091,79.83650654272566,-0.4925591258137818,-3.2107299746736637
672.7000000000091,79.9481385887597,-0.4961231363590568,-3.212051444442799
673.8000000000092,80.05979526134325,-0.5006299318191756,-3.2120565145682685
674.9000000000092,80.17208423828345,-0.5042960153524119,-3.2133225268910275
676.0000000000092,80.28437400712141,-0.50270928144084,-3.212040707001574
677.1000000000092,80.39585119164084,-0.5078654872098822,-3.2120400001348215
678.2000000000093,80.50770067584017,-0.5128172488473963,-3.212398760544027
679.3000000000093,80.61719866230354,-0.5144594081867417,-3.2136900224201135
680.4000000000093,80.73107716282708,-0.5156875070180083,-3.2136901820132797
681.5000000000093,80.8419580655984,-0.521507558442277,-3.2150099265898024
682.6000000000093,80.95430751754323,-0.527328476857913,-3.2154147964278654
683.7000000000094,81.06321544085553,-0.5328846703583516,-3.2150267618594626
684.8000000000094,81.17737156206748,-0.535640252055338,-3.216326159565675
685.9000000000094,81.28889365674948,-0.5399118142677923,-3.217006397432579
687.0000000000093,81.4007921565618,-0.5411337881445311,-3.2182995802643948
688.1000000000093,81.51251297112023,-0.5470608345276142,-3.216982038144984
689.2000000000094,81.6242354527112,-0.5511471166253616,-3.2169800000420135
690.3000000000094,81.73724074731358,-0.5546774378652974,-3.2168985640900276
691.4000000000094,81.84671042624969,-0.5576462305905459,-3.2183000001190516
692.5000000000094,81.96010256429507,-0.5588605585900204,-3.2183004340076264
693.6000000000095,82.07058596548804,-0.5643186109582807,-3.2196200079517228
694.7000000000095,82.18367697267246,-0.5713943285838463,-3.220980628158223
695.8000000000095,82.29690249631871,-0.5748172573663339,-3.2199397650985895
696.9000000000095,82.40820361457602,-0.5793414790916709,-3.2212600996716256
698.0000000000095,82.52088255975616,-0.5816758847742332,-3.221260000000343
699.1000000000096,82.63211847240116,-0.5872138740063644,-3.221258233541588
700.2000000000096,82.7435459558867,-0.593014668779019,-3.222584190368159
701.3000000000096,82.8559753863601,-0.5988150779715944,-3.223901311803556
702.4000000000096,82.96815033968885,-0.60386639486289,-3.223577541753121
703.5000000000097,83.07798849193851,-0.6071552716212709,-3.223564256469456
704.6000000000097,83.19021776440756,-0.6116822894636942,-3.223569888215442
705.7000000000096,83.30211237976974,-0.6211876262053693,-3.2248900040224515
706.8000000000096,83.41391944080608,-0.625919410693986,-3.2262109533035335
707.9000000000096,83.5254562545123,-0.6323783444382269,-3.225868910950294
709.0000000000097,83.63805040761498,-0.636086961138687,-3.2238969493498013
710.1000000000097,83.7496923942609,-0.6404233671864312,-3.226539899621421
711.2000000000097,83.86137948562852,-0.6430239621158078,-3.2265300173934515
712.3000000000097,83.97355492624801,-0.6409497359382246,-3.22794752573271
713.4000000000098,84.08530703588367,-0.6437659404370502,-3.229170152353365
714.5000000000098,84.19804845670205,-0.644101639924727,-3.2281806360668996
715.6000000000098,84.309681228888,-0.6513448637173609,-3.2294994950807405
716.7000000000098,84.42245876859783,-0.6497887896098731,-3.230489931253298
717.8000000000098,84.53613851888962,-0.6534870818004948,-3.2291508176697405
718.9000000000099,84.64721575882433,-0.6527645222953384,-3.2291700570265234
720.0000000000099,84.75807443344925,-0.6534496047000342,-3.231480861633302
721.1000000000099,84.87239814211858,-0.6543021336234409,-3.231463814308489
722.2000000000098,84.983616407554,-0.6526963011990294,-3.230487405582426
723.3000000000098,85.09659448696397,-0.6525211277837633,-3.232811650433804
724.4000000000099,85.20871073765748,-0.652447411725201,-3.23411084160523
725.5000000000099,85.32107711752506,-0.6519454946044327,-3.2327893241575043
726.6000000000099,85.43411050040964,-0.6486549058072071,-3.234110328093571
727.7000000000099,85.5464554675851,-0.6519558940366641,-3.2350999513474794
728.80000000001,85.65758750726516,-0.6456256203198993,-3.2337990548514535
729.90000000001,85.77121501933523,-0.643365549078645,-3.235090349279849
731.00000000001,85.88359221682099,-0.6415889077293548,-3.23641592349125
732.10000000001,85.99574262971014,-0.6364662445667975,-3.2377350751441387
733.20000000001,86.10876561686207,-0.632592818296396,-3.2376798411573207
734.3000000000101,86.22074040207588,-0.6299482675438277,-3.237730004908049
735.4000000000101,86.33319072977106,-0.6214716710226589,-3.2364093172597164
736.5000000000101,86.44555879847579,-0.6214345636591696,-3.238697310136947
737.6000000000101,86.55717795096406,-0.6215574908904127,-3.240119282662919
738.7000000000102,86.6704084106574,-0.6189524448015331,-3.240039898987498
739.8000000000102,86.78251671683631,-0.6131454215729786,-3.237402053917348
740.9000000000101,86.8956038102049,-0.6110455971485154,-3.238720033814691
742.0000000000101,87.00781797293507,-0.6077712003612545,-3.238720323539855
743.1000000000101,87.12142119682976,-0.6078662317663592,-3.2400381966736043
744.2000000000102,87.23320344205814,-0.604860742096107,-3.2426373168315203
745.3000000000102,87.34583221005423,-0.6000363540831464,-3.241359718151107
746.0000000000102,87.41683711897207,-0.6002876690529069,-3.2426942397932645