File: 01_Data/EIFS_XPS/STA/N2/3K_min/EIFS_XPS_STA_N2_3KData_230905_R1.csv
##Temp./Â°C,Time/min,DSC/(mW/mg),Mass loss/mg
41.0,11.275087737617202,-0.005420879198924311,-0.00528558310317262
42.100000000000016,11.82447657331183,0.006628216519389607,-0.006693633925982656
43.20000000000003,12.311679740428422,0.011243053068874964,-0.006476680067823981
44.30000000000005,12.749048985239707,0.01269600918602265,-0.005445053545277467
45.40000000000006,13.16460705254341,0.014613863313786446,-0.005995553771926065
46.50000000000008,13.573635631811767,0.012281253909738332,-0.004919637387557962
47.600000000000094,13.974451145556221,0.013316277287178657,-0.0063008024804931395
48.70000000000011,14.374366415143268,0.014118974907327164,-0.0052692942463949954
49.800000000000125,14.760089413621698,0.014527409325608698,-0.004879550419012002
50.90000000000014,15.149360979721296,0.011857389752850889,-0.0052700001015595355
52.000000000000156,15.52917000000008,0.011526693241626695,-0.006590015963853446
53.10000000000017,15.89893094592526,0.013791085052006213,-0.006149954470080932
54.20000000000019,16.22778211492954,0.012439323220781784,-0.004832375757001017
55.3000000000002,16.665712811904456,0.014277317978185877,-0.006462431803362367
56.40000000000022,17.042769571202655,0.0150056884295946,-0.007138942462222797
57.500000000000234,17.41339116752148,0.015229652682597017,-0.005809718123967134
58.60000000000025,17.790084967957288,0.013163827448573251,-0.005489999999980011
59.700000000000266,18.152507000192223,0.01271692697752691,-0.0044926585151952025
60.80000000000028,18.526666861652085,0.013147339236790678,-0.0061499974216183695
61.9000000000003,18.89349283383168,0.015078495857177465,-0.005779538509679938
63.00000000000031,19.271270376546866,0.013889001443896376,-0.005502412883874097
64.10000000000034,19.63951856368815,0.01568949663885011,-0.005160046356833092
65.20000000000034,20.00326234526101,0.01562753382369264,-0.005127046878806496
66.30000000000035,20.372506218379936,0.015172803220327769,-0.007159189393170173
67.40000000000038,20.72983552953276,0.013670108574891149,-0.004500012918959406
68.5000000000004,21.103681945887413,0.012697272334810439,-0.00434671801829456
69.6000000000004,21.477325296411294,0.015782034853891957,-0.004728879936729324
70.70000000000041,21.847919572792197,0.014843280915606272,-0.006192409494347295
71.80000000000044,22.206153261206673,0.014542594825368127,-0.004720074079298531
72.90000000000046,22.57829582928367,0.014487908029563012,-0.005381038038363872
74.00000000000047,22.94266544038731,0.01504364780449885,-0.00603999999796212
75.10000000000048,23.30479202384136,0.013478411578683236,-0.005275171895092523
76.2000000000005,23.676328830618864,0.010897509573974506,-0.006919662147988337
77.30000000000052,24.039170000000155,0.009548996233292417,-0.006590000000009422
78.40000000000053,24.408834605926437,0.006766737367052578,-0.005236056066068695
79.50000000000054,24.771902414909835,0.0060010539886818925,-0.007908945353474639
80.60000000000056,25.13666081806445,0.007242927867411542,-0.00527003345201571
81.70000000000059,25.499466503860877,0.00754216536998209,-0.006590000608647006
82.8000000000006,25.865368454784985,0.006526333855356281,-0.007909999955313829
83.9000000000006,26.233695278718216,0.0061796756247747275,-0.007799747331147078
85.00000000000063,26.597374367638643,0.006534800840886312,-0.006149952757163568
86.10000000000065,26.967043869081646,0.006488631882748397,-0.005166483050912607
87.20000000000066,27.325461848505114,0.005707816873484095,-0.007460004136603082
88.30000000000067,27.691930222649425,0.005491696847299554,-0.007799995414376593
89.40000000000069,28.0576988967574,0.005618061235560301,-0.00746999158161854
90.50000000000071,28.42500266057462,0.007183490526899483,-0.0078048838284550115
91.60000000000072,28.790158390246198,0.0064150478145394985,-0.006479611538865004
92.70000000000073,29.15109913865172,0.009751219660287358,-0.007470000496725415
93.80000000000075,29.515063432130862,0.010956413967324607,-0.006480000124004626
94.90000000000077,29.878012904227358,0.014689469331956584,-0.006809999481554918
96.00000000000078,30.254564006163026,0.021801253189625225,-0.008128748344649495
97.10000000000079,30.595613800399292,0.027214246160411903,-0.009736812739871592
98.20000000000081,30.971061253625376,0.033967713998856564,-0.009770001236959036
99.30000000000084,31.342191257549725,0.0382294329674866,-0.00992740381785806
100.40000000000084,31.704351124362958,0.0420354209737237,-0.012117818856177909
101.50000000000085,32.06917000000029,0.04526888647461824,-0.009442234763043622
102.60000000000088,32.42661399191055,0.044490768343639076,-0.012049236910596672
103.7000000000009,32.78986503113418,0.043613262067626835,-0.013730016652691912
104.8000000000009,33.15659045601972,0.04119147914769927,-0.014053484846738407
105.90000000000092,33.51277852789832,0.034205616232293234,-0.014708244425597705
107.00000000000094,33.87545715791197,0.026484705262702413,-0.01570004187098517
108.10000000000096,34.23560932737236,0.019172687522212684,-0.015822497040026917
109.20000000000097,34.59287506793774,0.015491472766901992,-0.014835636146491638
110.30000000000098,34.954839130739124,0.015297226631686645,-0.015966541948492452
111.400000000001,35.31221947605533,0.015063508211186516,-0.017011483087472357
112.50000000000102,35.66892914046632,0.01774448942924467,-0.015734682623391283
113.60000000000103,36.03343518853489,0.013096698585301603,-0.014720010158959074
114.70000000000104,36.39332554220039,0.014236376249521232,-0.015369901050202195
115.80000000000106,36.74940009513062,0.012836295471985615,-0.016689926148553802
116.90000000000109,37.1129198699692,0.012162416725767233,-0.015370010064625461
118.0000000000011,37.486005494152685,0.011461147355358303,-0.016697091032947142
119.1000000000011,37.83217543827705,0.01206271287284455,-0.016360006919511783
120.20000000000113,38.19397540498877,0.012799319441334056,-0.0158388199467554
121.30000000000115,38.557828622750655,0.012504611887590222,-0.016040729923392227
122.40000000000116,38.9149206720744,0.012017041982269827,-0.017791079304438906
123.50000000000117,39.27623950787129,0.011120933321699056,-0.015150000323373103
124.60000000000119,39.638434771864816,0.01072829643476192,-0.013804637254906105
125.70000000000121,40.00022819983651,0.010466462442710434,-0.013509417870792628
126.80000000000122,40.35838811270692,0.01317686857538325,-0.01532594616827776
127.90000000000123,40.723247794262754,0.009622460813687894,-0.014819850479952823
129.00000000000125,41.083064863029755,0.011298838074420114,-0.01481997081632569
130.10000000000127,41.44048699614981,0.009668054584833996,-0.016260152591724086
131.2000000000013,41.794604140506635,0.00912166320567831,-0.013176963633009908
132.3000000000013,42.1584266054312,0.007830834733206338,-0.014911620281988114
133.4000000000013,42.51917422420995,0.010080661132122248,-0.015920003280835537
134.50000000000134,42.876661135900704,0.008431234354163708,-0.013264554262849781
135.60000000000133,43.23368697908855,0.008967967834142332,-0.014836376460998224
136.70000000000135,43.59317262989787,0.007989264803912377,-0.015589984629682974
137.80000000000138,43.95293013419557,0.006612951367578113,-0.014592436446748902
138.9000000000014,44.31354096505069,0.007242640210044504,-0.014270000278509443
140.00000000000142,44.666765570593725,0.0034406848801258327,-0.01625078482949549
141.10000000000142,45.02647970974321,0.0033862594551510306,-0.013940037182933018
142.20000000000144,45.379009028366745,0.0039436946389368455,-0.015258230641534531
143.30000000000146,45.74057658534903,0.0035599203915808175,-0.014045096006381819
144.40000000000146,46.099884449192245,0.0033985002389886887,-0.01504003636657858
145.50000000000148,46.45389947624631,0.002211806169598818,-0.015370547963196923
146.6000000000015,46.81464043846579,0.0031633037570499845,-0.015912942092763505
147.70000000000152,47.16755647122172,0.0022957766326479057,-0.015299170234571946
148.80000000000155,47.52580488676033,0.0030185299764484697,-0.015377461641843837
149.90000000000154,47.89054867682654,0.0014809136941418277,-0.018094893248661315
151.00000000000156,48.24626897065376,0.0009079285614568278,-0.016645841432397113
152.1000000000016,48.60967733479135,0.0015318875299774604,-0.015479967470036993
153.20000000000158,48.96285770974976,0.0030000132387246747,-0.0165781284866231
154.3000000000016,49.32254314107828,0.0018809847553147296,-0.01821999993654133
155.40000000000163,49.67264247523732,0.0013588844351248852,-0.01756000037176131
156.50000000000165,50.0304263564609,-0.0006547228324675913,-0.018337846659910895
157.60000000000167,50.39490986581608,-0.0018452318901067688,-0.01891263322330694
158.70000000000167,50.758308604645194,-0.0027898591925117344,-0.016184020241036823
159.8000000000017,51.116681658004644,0.00020744481756862498,-0.018712988368285277
160.9000000000017,51.470822144871605,0.0012151112761211724,-0.017459710886934765
162.0000000000017,51.82315263391548,0.0007224675309875916,-0.019109909347065912
163.10000000000173,52.18783745524267,0.00035992945948337685,-0.020099995072286436
164.20000000000175,52.538161027890425,0.0002865553116881969,-0.018120630233247947
165.30000000000177,52.900498135398365,-0.0013073469412905325,-0.01910982157916008
166.4000000000018,53.254514955218035,0.0013098805367508515,-0.020430026100158205
167.5000000000018,53.61653128311557,0.0011787198659074516,-0.02074999441564085
168.6000000000018,53.968860678197345,-0.0006736719477011821,-0.019535707592728713
169.70000000000184,54.32204151600715,0.0003951656562917183,-0.02075272117186433
170.80000000000183,54.6854986118128,0.0007899482130120372,-0.019547767197676258
171.90000000000185,55.039710013920676,-0.00042422492517202315,-0.020859999990833433
173.00000000000188,55.399534678875625,-0.0018836837821334385,-0.023956744480516434
174.1000000000019,55.7591668725738,-0.00039984483243848956,-0.021080084519747633
175.20000000000192,56.11634341079049,-0.0014140769852022395,-0.019989583120194165
176.30000000000192,56.476497418859765,-0.002444894919367391,-0.020969999996227173
177.40000000000194,56.82988842634547,-6.32662583992527e-05,-0.019641889503372756
178.50000000000196,57.18951976898103,0.00039312160266136154,-0.02089557847635426
179.60000000000196,57.54305918568216,-0.0016994178345681732,-0.02260346353267728
180.70000000000198,57.90128594289666,-0.0003372800806249465,-0.02374501250188965
181.800000000002,58.2467329567456,-0.0022445663879977484,-0.021476570027005426
182.90000000000202,58.61009574719813,-0.0009025852153683456,-0.02261998196377446
184.00000000000205,58.972743328117836,-0.0039687295495958175,-0.023279583049132135
185.10000000000204,59.33109877823268,-0.003367927475830701,-0.02295000179250284
186.20000000000206,59.68917000000073,-0.0012301513250958518,-0.023059926113651485
187.3000000000021,60.04327706857832,-0.003932882703931551,-0.023601700505085255
188.40000000000208,60.39395635747029,-0.004060626154267499,-0.022949997059026117
189.5000000000021,60.75886318524282,-0.004117173949456987,-0.0225927516005906
190.60000000000213,61.1109023306426,-0.004720089871196098,-0.024269999999893432
191.70000000000215,61.47105111162741,-0.0056824391945107244,-0.023379548072985035
192.80000000000217,61.82643213773574,-0.005224506799416995,-0.023939997491412512
193.90000000000217,62.188466787227966,-0.004494740033599509,-0.024920000000000275
195.0000000000022,62.54079036531071,-0.006130951883122071,-0.02492000000000205
196.1000000000022,62.88915840295028,-0.007253147224572931,-0.025260036855999424
197.2000000000022,63.257887435468504,-0.00433270522967355,-0.023542148298015597
198.30000000000223,63.60806309918327,-0.006650520360458989,-0.024269967170289508
199.40000000000225,63.962238437092466,-0.006210482787789795,-0.024270000014008364
200.50000000000227,64.31783662296525,-0.006893632899018787,-0.02623996557648134
201.6000000000023,64.67505112956297,-0.0052450999174593615,-0.026900248895708412
202.7000000000023,65.03062689525491,-0.00709506601012988,-0.026567750005645152
203.8000000000023,65.38151570654796,-0.004702387138489916,-0.02550574237796699
204.90000000000234,65.74917653161846,-0.00570327679489635,-0.025589908616900914
206.00000000000233,66.10320420142253,-0.004292703097607875,-0.025580000000000158
207.10000000000235,66.45484178242774,-0.004630844413147095,-0.02690010433520884
208.20000000000238,66.80188039049602,-0.006564528499359401,-0.026900002268336554
209.3000000000024,67.16052765929956,-0.005849075252711611,-0.028543965874113564
210.40000000000242,67.52299613527617,-0.005997156753892119,-0.02855000280878839
211.50000000000242,67.8787420257175,-0.004976595565554964,-0.026245466700646425
212.60000000000244,68.23061423299714,-0.009437920564362434,-0.027560001105546572
213.70000000000246,68.59051454967681,-0.008653424550753464,-0.028534981639906754
214.80000000000246,68.95516923600077,-0.008041824694122734,-0.0288357068436631
215.90000000000248,69.31005491024233,-0.007619635518079093,-0.02788737025207988
217.0000000000025,69.6654155541418,-0.009419817094746374,-0.027889998633006563
218.10000000000252,70.01996672611287,-0.011346626270722915,-0.030271366654589738
219.20000000000255,70.37033009975777,-0.01218300097137437,-0.028202796867201396
220.30000000000254,70.73258301959419,-0.013196720689374608,-0.029869113384322077
221.40000000000256,71.08121626887603,-0.01099819783432654,-0.030199692070822515
222.5000000000026,71.43725034335935,-0.013287414321837332,-0.02888000533939561
223.60000000000258,71.7942335194633,-0.014160666716587,-0.02888000116353684
224.7000000000026,72.14917000000177,-0.01370416833436483,-0.02953510471582943
225.80000000000263,72.50547347925531,-0.014062814488768005,-0.031178019807966084
226.90000000000265,72.86039246272853,-0.014445283865511804,-0.03050779896403455
228.00000000000267,73.21733273966103,-0.015020918138155759,-0.029870100082995066
229.10000000000267,73.56916759252417,-0.015402889076446824,-0.029539999984284915
230.2000000000027,73.93312593060358,-0.016079104826209223,-0.03106755886084489
231.3000000000027,74.27636495312694,-0.013700225383444842,-0.031180000012208886
232.4000000000027,74.64390377397946,-0.017327638831293513,-0.0311431970467968
233.50000000000273,75.00022539938485,-0.017943485317472474,-0.03085426938129876
234.60000000000275,75.35257275267873,-0.016474989399600348,-0.032182814681270155
235.70000000000277,75.71870226507377,-0.016195566018909258,-0.0324782103552721
236.8000000000028,76.07260907499341,-0.017110809897415535,-0.032500000466018975
237.9000000000028,76.42735670075278,-0.01830126405024335,-0.03084147091173106
239.0000000000028,76.78679502860818,-0.019293054145685273,-0.032830000008657656
240.10000000000284,77.14420517676056,-0.017228710682688275,-0.03316952429683262
241.20000000000283,77.50216336376155,-0.018671474563213053,-0.033159999999999634
242.30000000000285,77.85332385429854,-0.017587904162268186,-0.03174315264363381
243.40000000000288,78.21425054954835,-0.01806188427392752,-0.03151000011755167
244.5000000000029,78.56980383540754,-0.0195638861774714,-0.03347999416069891
245.60000000000292,78.92498726310345,-0.019671241568992803,-0.03463007693928377
246.70000000000292,79.28199711384464,-0.02118314366364582,-0.034139999691316536
247.80000000000294,79.63704964232613,-0.022588592863709955,-0.03191103720201216
248.90000000000296,79.98956448133598,-0.022894911161520204,-0.033149689121785286
250.00000000000296,80.34997421513907,-0.024034247926004504,-0.03280291868430396
251.10000000000298,80.70628252076945,-0.022424707242963304,-0.03380999997385237
252.200000000003,81.06492551936232,-0.020204903677588648,-0.03299946431169065
253.30000000000302,81.42054015167177,-0.02006124092053141,-0.03510887383984196
254.40000000000305,81.77447953167365,-0.023377016190660127,-0.03447000000026179
255.50000000000304,82.13259941068007,-0.02101330046777572,-0.03545999278703027
256.6000000000031,82.48426605145379,-0.021358416254725787,-0.03577224849527427
257.7000000000031,82.83848190519015,-0.023048717260120588,-0.03606829678870582
258.8000000000031,83.19674757917124,-0.023303284673929614,-0.03611985453594091
259.9000000000031,83.55603676665599,-0.023392437206782635,-0.037440000034962395
261.0000000000031,83.90839638429276,-0.023654114843745244,-0.03678253265101272
262.10000000000315,84.26855185147669,-0.024246601842941917,-0.03709903102048129
263.2000000000032,84.6204932411676,-0.02479796808009782,-0.035789999522434
264.30000000000314,84.97964128458209,-0.023492753440774283,-0.03600984696024767
265.40000000000316,85.33002402473024,-0.024398794514268962,-0.03864261698136495
266.5000000000032,85.69319972743455,-0.024091399906293276,-0.03863999188410583
267.6000000000032,86.05128064626598,-0.0241882362672583,-0.03864015005601873
268.70000000000323,86.40982156711036,-0.02369248780039146,-0.03831005597728465
269.80000000000325,86.76761899118874,-0.022358254817499645,-0.03995990046632203
270.9000000000033,87.12447590496336,-0.022730074368331854,-0.04006898858824126
272.0000000000033,87.48668963946196,-0.02498382246860764,-0.03896961548619027
273.1000000000033,87.844195954916,-0.024038099690489867,-0.03961531084593073
274.20000000000334,88.19645144291799,-0.02569799002435813,-0.04128004916983352
275.30000000000337,88.55355370609222,-0.025214153189851984,-0.040290029017715945
276.40000000000333,88.90868748201733,-0.025582884927732863,-0.03995993900176753
277.50000000000335,89.2666347460331,-0.0271963106554598,-0.04260307490988158
278.6000000000034,89.62487264624833,-0.02583943819711587,-0.04523075213060679
279.7000000000034,89.98357488544318,-0.02564802477937622,-0.04257020730354899
280.8000000000034,90.33975418803874,-0.02500114552801702,-0.0432500000000009
281.9000000000034,90.69609559715501,-0.02249874744757485,-0.04355213146821768
283.0000000000034,91.05385904830953,-0.02466983683476931,-0.04457104269616208
284.10000000000343,91.4115403618238,-0.023964137610958502,-0.046210357123980916
285.20000000000346,91.7619233305792,-0.025438344243105204,-0.04622254358218303
286.3000000000035,92.12022601826267,-0.025473707128170542,-0.046882953796823834
287.4000000000035,92.48528937524196,-0.02600497700231874,-0.04605397804920841
288.5000000000035,92.84674853120289,-0.02567787143751965,-0.0481960727976154
289.60000000000355,93.20285081888531,-0.02568650181988663,-0.049006012221946005
290.70000000000357,93.56090867914307,-0.029146069830701116,-0.04981381080704628
291.8000000000036,93.91865603370455,-0.029352529824770546,-0.049506978466942186
292.9000000000036,94.27478432815592,-0.0279839371384647,-0.05215516255556496
294.0000000000036,94.62766832279533,-0.028599638461591192,-0.05313998955464161
295.1000000000036,94.98916565048594,-0.0290015461628943,-0.051930066188302426
296.2000000000036,95.34760035637197,-0.027396723993082572,-0.051929995398247275
297.30000000000365,95.70744906882432,-0.028079387091533237,-0.05358952990604404
298.4000000000037,96.06917564624435,-0.0314385691659822,-0.05522377368298281
299.5000000000037,96.4241082369671,-0.029999514348588052,-0.055990620583289186
300.60000000000366,96.78290829001926,-0.027965443269942547,-0.055879675497405135
301.7000000000037,97.13873397243903,-0.027561503908534624,-0.05587999997276727
302.8000000000037,97.50261022786545,-0.029131263735986845,-0.05819007127659637
303.90000000000373,97.86123822785808,-0.03179882923749866,-0.05783213147485533
305.00000000000375,98.20971512868759,-0.030455237225543108,-0.06119355574547347
306.1000000000038,98.57749465202109,-0.0326885506883583,-0.06247144857795206
307.2000000000038,98.93659590608625,-0.030371123499625785,-0.0631313866584593
308.3000000000038,99.28917468437419,-0.03255333131375959,-0.06268928916921679
309.40000000000384,99.64754730745149,-0.032200194775383606,-0.0636803884919348
310.5000000000038,100.00746954008684,-0.030740373797272236,-0.06630999999994858
311.60000000000383,100.36604789391531,-0.03350572170635968,-0.06750234611004835
312.70000000000385,100.72285111330164,-0.03165725480064152,-0.06775359554466265
313.8000000000039,101.08243468290233,-0.031198755206580442,-0.06817976639798795
314.9000000000039,101.4411429296024,-0.030421677601216945,-0.06949193609711912
316.0000000000039,101.79979944920841,-0.03028055904271687,-0.07080999999980264
317.10000000000394,102.15985662388252,-0.030116763237680422,-0.07311977348138399
318.2000000000039,102.51539290080478,-0.03030851725060102,-0.07746414177217575
319.30000000000393,102.87307533468231,-0.02932424079215079,-0.07739105317828665
320.40000000000396,103.23530607817645,-0.028449813418454983,-0.07866455065131861
321.500000000004,103.59129982180369,-0.027826234427828833,-0.08082137339829165
322.600000000004,103.95483738411126,-0.02958525445953253,-0.08378055944315355
323.700000000004,104.31199264144023,-0.03129835329258657,-0.08370014886452681
324.80000000000405,104.6712683458436,-0.03207183600980801,-0.08540995757444136
325.90000000000407,105.03220381690362,-0.030878610267679907,-0.08892092996954926
327.0000000000041,105.39203012157378,-0.03066923712893943,-0.09035493546813322
328.10000000000406,105.75020888236644,-0.030018193791478298,-0.09178005678808487
329.2000000000041,106.11194169835487,-0.031540207020990696,-0.09463321728747376
330.3000000000041,106.46955741353187,-0.02847571271311722,-0.09661000234026451
331.4000000000041,106.81385262157806,-0.02835087516289203,-0.10183791409727849
332.50000000000415,107.18514881262321,-0.02807683231927416,-0.1038529412696807
333.6000000000042,107.54461526957294,-0.028051736359473445,-0.10582999885603028
334.7000000000042,107.90702775149879,-0.025815194359665172,-0.11019323713062246
335.80000000000416,108.26274792862367,-0.025905170232581654,-0.11237287745248192
336.9000000000042,108.621607038041,-0.02687072101395649,-0.11374373953425732
338.0000000000042,108.97950575305715,-0.0246518359315413,-0.11998704299914653
339.10000000000423,109.335246778528,-0.023532314641567353,-0.12126051384865111
340.20000000000425,109.70212601449204,-0.023291871174861978,-0.1259252881911168
341.3000000000043,110.06488673715079,-0.021596297295334965,-0.12987015531504298
342.4000000000043,110.42980734187456,-0.018529531741883654,-0.13448015832977767
343.5000000000043,110.79364906976193,-0.015025590689496049,-0.13977675137042844
344.60000000000434,111.15041850640743,-0.01344251283326714,-0.14548411871597855
345.7000000000043,111.51410408909666,-0.012700891787118529,-0.15105843640272898
346.80000000000433,111.86857875973965,-0.0074099992593334996,-0.15590804834326866
347.90000000000435,112.23260246034039,-0.005305855064770881,-0.16158776821725818
349.0000000000044,112.59075184027868,-0.0018097091320867786,-0.16947928457520423
350.1000000000044,112.95464781570087,0.0017618423276826167,-0.1778177647293191
351.2000000000044,113.31688136583654,0.006619858117510091,-0.1844581894506958
352.30000000000445,113.67969440894773,0.0083107949298582,-0.19351382148109142
353.4000000000044,114.04104475567368,0.016451882173479815,-0.20169146821597872
354.50000000000443,114.40354703840096,0.0217415386535611,-0.21146652451134385
355.60000000000446,114.76052627306582,0.02803693880912128,-0.22241990456917815
356.7000000000045,115.1257458149206,0.034517682179591835,-0.23356498001650872
357.8000000000045,115.48748064363265,0.04365383805408829,-0.24605994191768588
358.9000000000045,115.85261987993142,0.05278914102576082,-0.2581379352875053
360.00000000000455,116.20761287840902,0.063416958121703,-0.27234195915800274
361.10000000000457,116.57968184585431,0.07405498341553818,-0.29045372573400563
362.2000000000046,116.93824081382492,0.08395246363450215,-0.3069043718045794
363.30000000000456,117.30048134827166,0.09810052246909895,-0.3259531008454557
364.4000000000046,117.66630591231862,0.11467990992391441,-0.34852845772235774
365.5000000000046,118.0291700000013,0.1316500829083851,-0.37063113342608434
366.6000000000046,118.38179455496073,0.14609827774938333,-0.39313424533694885
367.70000000000465,118.7556330956114,0.16754513028553197,-0.4211882828600384
368.8000000000047,119.1175883085579,0.1857381663289559,-0.44881833618894973
369.9000000000047,119.48493280404797,0.20589967704438195,-0.48064891419695854
371.00000000000466,119.84463556350455,0.2335911108385318,-0.5154647560376091
372.1000000000047,120.21528980912312,0.2584201319687143,-0.5523299978792693
373.2000000000047,120.57857124937472,0.2816376133107057,-0.5948777987806837
374.30000000000473,120.94787918553979,0.31285842599284885,-0.6377424712408386
375.40000000000475,121.31386541304957,0.34475909445222785,-0.68748278151996
376.5000000000048,121.68260994112117,0.38086937696963585,-0.7367694804390181
377.6000000000048,122.04803902148655,0.4144575090872924,-0.7941912460981735
378.7000000000048,122.40743385714974,0.45353560692415185,-0.853074724794618
379.80000000000484,122.78513639986254,0.4919308446987336,-0.9227410134924217
380.9000000000048,123.15187470527938,0.5325756213539512,-0.991893761536832
382.00000000000483,123.52917000000156,0.5747660503160643,-1.0700600009589132
383.10000000000485,123.89866093037564,0.6150660449681609,-1.1561647216698505
384.2000000000049,124.26833879967526,0.6569318737207044,-1.237460908243345
385.3000000000049,124.63883403491764,0.7047700379265436,-1.3335604274506911
386.4000000000049,125.00334232250242,0.7456722492912864,-1.4325360869310737
387.50000000000495,125.37473778905193,0.790372966384417,-1.5368850835744325
388.6000000000049,125.74089630305853,0.8298236429776185,-1.6461320323349464
389.70000000000493,126.11117996313587,0.8733217085202722,-1.7621536062464496
390.80000000000496,126.47575699227714,0.8891890521851693,-1.878343214821125
391.900000000005,126.84216435755754,0.9221916224460021,-2.0001066759652417
393.000000000005,127.20979263048302,0.944236352651781,-2.128860358468274
394.100000000005,127.57527919157926,0.9505373286617846,-2.2555758038438936
395.20000000000505,127.94169710786882,0.9508751563984132,-2.3866622746416963
396.30000000000507,128.2977718976914,0.9343807493567153,-2.5121042439444983
397.4000000000051,128.65662654346804,0.9159833293385586,-2.6376489423317224
398.50000000000506,129.01917000000228,0.880840100646368,-2.761667535803852
399.6000000000051,129.36367236917206,0.8434314759951889,-2.8778924896291174
400.7000000000051,129.72863420457213,0.7883708007079264,-2.992560075826408
401.8000000000051,130.0715047872526,0.7276859078459863,-3.0992232315331294
402.90000000000515,130.43379822857617,0.6582331965800101,-3.202270238455518
404.0000000000052,130.7828406830506,0.5829258449897141,-3.293786673145194
405.1000000000052,131.1347688154553,0.5018571982915625,-3.37890285130481
406.20000000000516,131.4823972908032,0.4247080042872817,-3.452526220790197
407.3000000000052,131.83338408944405,0.34453048374540574,-3.5206112685462365
408.4000000000052,132.1829214010637,0.2654783461125483,-3.578015390029223
409.50000000000523,132.53319955055196,0.19752678258036194,-3.625543677854115
410.60000000000525,132.8745452664674,0.1336156809131679,-3.6668545400886132
411.7000000000053,133.23754710313446,0.07588452737727458,-3.7052713205391514
412.8000000000053,133.59251972904096,0.02816049776588825,-3.735467632782311
413.9000000000053,133.94757432391089,-0.017855712108993282,-3.7601134316554656
415.00000000000534,134.30031947383839,-0.05197505603015884,-3.7822750105714524
416.1000000000053,134.65228819977423,-0.07730524277937212,-3.800029904396531
417.20000000000533,135.0134097034669,-0.10132943273834805,-3.8163491151180997
418.30000000000535,135.38178696002362,-0.12184272586398537,-3.826950443599982
419.4000000000054,135.73216726163423,-0.13746359273280184,-3.8381514734334456
420.5000000000054,136.097216752291,-0.15100909607578994,-3.8473629388875072
421.6000000000054,136.45047374885144,-0.15992247997529874,-3.8543789239221593
422.70000000000545,136.82250375752972,-0.1690207995526385,-3.861060701168194
423.8000000000054,137.18739273339168,-0.17687347411339238,-3.867511597764402
424.90000000000543,137.55100774911068,-0.18293993746570059,-3.872499939709255
426.00000000000546,137.90958529431532,-0.19003354731474853,-3.8774500144177404
427.1000000000055,138.27351887435682,-0.1954707788731842,-3.8800800003123697
428.2000000000055,138.6406266733777,-0.19847384620616904,-3.8833728566684353
429.3000000000055,138.9976859291508,-0.20201802572583483,-3.8853499998455936
430.40000000000555,139.365968456327,-0.20553586578149363,-3.8890503036617097
431.50000000000557,139.7302977987388,-0.21057577228142454,-3.8901719179143424
432.6000000000056,140.09586604947444,-0.212266163447286,-3.8914900232489886
433.70000000000556,140.45171912169332,-0.21768241472288685,-3.89281
434.8000000000056,140.82467760814404,-0.2199952359882178,-3.894459393637339
435.9000000000056,141.18803407046656,-0.22203825311682612,-3.8941283697713587
437.0000000000056,141.5540484174222,-0.20000642880970565,-3.89413
438.10000000000565,141.91483187896134,-0.19848325956465462,-3.8941300000052195
439.2000000000057,142.2753369690174,-0.22424282365994075,-3.8954500032770665
440.3000000000057,142.6385919447464,-0.23869951363866426,-3.8944624644843375
441.40000000000566,143.0016699975035,-0.24590526383241107,-3.8928198201420763
442.5000000000057,143.36495797197776,-0.2458455726119364,-3.8929562632078296
443.6000000000057,143.72263975611955,-0.2493704698635668,-3.8937999940286425
444.70000000000573,144.09412290133486,-0.25324544406284155,-3.893470001213989
445.80000000000575,144.46015584501905,-0.25457051160108723,-3.892810039686942
446.9000000000058,144.82394996568675,-0.2563460854545534,-3.8938539931188036
448.0000000000058,145.1912429554634,-0.25650174535345194,-3.892785632115462
449.1000000000058,145.55825270364514,-0.25448228875859,-3.8934699999671567
450.20000000000584,145.92287155935975,-0.2546434634989747,-3.8938047690836224
451.3000000000058,146.29076128191423,-0.2560079126375854,-3.8918199966908524
452.40000000000583,146.65519831715324,-0.2586178815794997,-3.8918200009288784
453.50000000000585,147.02181442267334,-0.2590098625606281,-3.8908356170779608
454.6000000000059,147.3834246403727,-0.2608922339916331,-3.892159994013277
455.7000000000059,147.74879036676367,-0.25789034551542755,-3.8931399989201156
456.8000000000059,148.1093657935422,-0.2609982676576783,-3.891169999996972
457.90000000000595,148.48152747755992,-0.2619179450157867,-3.8908571947149473
459.0000000000059,148.8466443707274,-0.2625137282432446,-3.8908400000020773
460.10000000000593,149.20947820147222,-0.2617427395534655,-3.88955946073873
461.20000000000596,149.5798893821301,-0.2605859983683061,-3.8921580375083757
462.300000000006,149.94182530195533,-0.2614283480228079,-3.892149719547522
463.400000000006,150.31054407544084,-0.2600703467574461,-3.89148997389633
464.500000000006,150.67780564936984,-0.26413420778192265,-3.889850050687345
465.60000000000605,151.03847195369912,-0.26525733834312204,-3.8905653394420883
466.70000000000607,151.40091129076782,-0.2647274844449905,-3.889388276002114
467.8000000000061,151.77072799966092,-0.2621149326136749,-3.8898499999911227
468.90000000000606,152.13527372886398,-0.26612486240121513,-3.8899141808041984
470.0000000000061,152.501312240266,-0.2691075547974424,-3.8901778384396977
471.1000000000061,152.87285775854298,-0.26830424431693123,-3.8895199999999575
472.2000000000061,153.23813976348495,-0.2680140682707042,-3.8891783896328986
473.30000000000615,153.59567420125757,-0.26609563443161877,-3.8895167554519325
474.4000000000062,153.9691742062585,-0.2665265576856286,-3.890796934583839
475.5000000000062,154.3407084254089,-0.2662553460659207,-3.8885293754911956
476.60000000000616,154.71009791385018,-0.2656992133126479,-3.887550215295895
477.7000000000062,155.07052094943595,-0.26691975102491683,-3.8876197145893268
478.8000000000062,155.44332264681933,-0.26753526543833295,-3.8878836086684
479.90000000000623,155.8061084331432,-0.26640556029685536,-3.888872649958798
481.00000000000625,156.16917000000248,-0.26955750000003187,-3.88788
482.1000000000063,156.53391532323022,-0.2676882852758167,-3.8868800000000676
483.2000000000063,156.85673049600922,-0.2694584816114609,-3.8865221681012048
484.3000000000063,157.2630823952157,-0.2651965529842659,-3.88755
485.40000000000634,157.6321412992145,-0.2661638079342541,-3.8875500001211076
486.5000000000063,157.99832344357134,-0.26966595627240175,-3.8862299993855767
487.60000000000633,158.36662466386275,-0.27182165905212385,-3.885570090098576
488.70000000000636,158.7302257553959,-0.2734423649922779,-3.887549724044246
489.8000000000064,159.09806207714144,-0.27539821560961864,-3.884906411341529
490.9000000000064,159.4659693732855,-0.272685565085935,-3.8868899981050182
492.0000000000064,159.835987609983,-0.27560912976922425,-3.885899966367711
493.10000000000645,160.1988538014163,-0.2735341983545716,-3.8862299999997947
494.2000000000064,160.5655310103175,-0.2742872069220179,-3.8864325006980858
495.30000000000643,160.93255905379849,-0.2762126878995701,-3.884909999997864
496.40000000000646,161.29801774595055,-0.2745534757404955,-3.8849101859350212
497.5000000000065,161.67024016047512,-0.2734440232785469,-3.8842517388645597
498.6000000000065,162.03422468208797,-0.27535365784506416,-3.884125458167367
499.7000000000065,162.400395451718,-0.2777041487802199,-3.884469997495017
500.80000000000655,162.769648103353,-0.2758313810322226,-3.885129999933169
501.90000000000657,163.1342666685678,-0.28031558555328795,-3.885130000570699
503.0000000000066,163.50436443252408,-0.2804779280895393,-3.8830230033192197
504.10000000000656,163.87515297249413,-0.28005059234759844,-3.885131036408446
505.2000000000066,164.23599873275643,-0.277451547717374,-3.883812155974364
506.3000000000066,164.61070266807138,-0.28039232594190877,-3.8824900065471675
507.4000000000066,164.97739046897578,-0.28528390300643713,-3.8851293340119506
508.50000000000665,165.3389468319285,-0.28248451228717153,-3.88502
509.6000000000067,165.70651906433292,-0.2845215081148409,-3.883710866870133
510.7000000000067,166.074251710232,-0.2839902951588078,-3.8840300842007243
511.80000000000666,166.44036751380852,-0.28792701790329533,-3.8823472779184147
512.9000000000067,166.8088054348109,-0.2834597578417435,-3.8836999991822223
514.0000000000067,167.18041313205276,-0.28752976436381106,-3.8807369514329277
515.1000000000067,167.54512568695606,-0.2879962155490121,-3.8830674138271215
516.2000000000068,167.91034943186466,-0.2885223569978539,-3.88039975587303
517.3000000000068,168.27917409265004,-0.28951076625969097,-3.880790656191558
518.4000000000068,168.64783218539515,-0.2847054748107096,-3.8815508783162778
519.5000000000068,169.01421889432405,-0.2876684480802634,-3.8820501741110527
520.6000000000068,169.3836038010426,-0.2887588457353345,-3.879420762668168
521.7000000000069,169.75302412638737,-0.28823325706707803,-3.879524018412041
522.8000000000068,170.11783778574653,-0.28935297233996193,-3.8820494280060185
523.9000000000069,170.4862286637549,-0.28815841330114766,-3.8830974431254934
525.0000000000068,170.85446719307262,-0.28537911337435484,-3.8803900982649666
526.100000000007,171.2220723138979,-0.2879046751708825,-3.8804900719260242
527.2000000000069,171.58916681713472,-0.29059601770928856,-3.882050129803506
528.300000000007,171.94876875779417,-0.2927039717155231,-3.8820498128923058
529.4000000000069,172.3194199253486,-0.29369151779707847,-3.8810597679294014
530.5000000000069,172.68808493999,-0.292412146771734,-3.880729999999043
531.600000000007,173.0612548338735,-0.290402690776983,-3.881720002795895
532.700000000007,173.43355055288976,-0.28997513225688865,-3.880071037743502
533.800000000007,173.80035569938482,-0.28999633206971165,-3.8790896108699053
534.900000000007,174.17142421279115,-0.2899996639099909,-3.8801108227187773
536.000000000007,174.54094367998565,-0.28974234733158477,-3.881390985084558
537.1000000000071,174.91100202677742,-0.2908111008706822,-3.880398325059769
538.2000000000071,175.27950840413857,-0.28978744243723664,-3.88041
539.300000000007,175.64645658823784,-0.29383540462066016,-3.8808871301677357
540.4000000000071,176.0156810344805,-0.29486219404268255,-3.880410521595711
541.500000000007,176.38239286612045,-0.2945608937785269,-3.879091161875069
542.6000000000072,176.75257985838167,-0.29351865434454405,-3.8782151355666876
543.7000000000071,177.1238459999653,-0.2936213321540695,-3.8800798135469403
544.8000000000072,177.48632930229502,-0.29395592656593283,-3.878728356786173
545.9000000000071,177.85663360987508,-0.2931417312069704,-3.879750154124332
547.0000000000072,178.21917000000073,-0.2931308007563347,-3.8774399999912377
548.1000000000072,178.5952622211805,-0.2911625982592314,-3.878759998587786
549.2000000000072,178.9623600076544,-0.29037830198797376,-3.8800669413237845
550.3000000000072,179.33686778369858,-0.2889179086206233,-3.8800796356635985
551.4000000000073,179.70742501861574,-0.28976538602581403,-3.8780348256959094
552.5000000000073,180.07898223969232,-0.28576246272199857,-3.879419999999993
553.6000000000073,180.4466060250087,-0.2870749478104129,-3.8807399999977745
554.7000000000073,180.8215322418458,-0.2852117891586645,-3.8807400000087258
555.8000000000073,181.1860865246191,-0.28715380435028104,-3.8794202796618578
556.9000000000074,181.5500739603756,-0.28642014211307076,-3.8797688807038075
558.0000000000074,181.91838321145838,-0.29099347153090305,-3.8810697872728004
559.1000000000074,182.28247865728625,-0.289170782639546,-3.879093291018908
560.2000000000073,182.65613618934628,-0.29189898762620725,-3.8790903742808442
561.3000000000073,183.0234766836476,-0.29283465209304493,-3.880407068787174
562.4000000000074,183.39519456191954,-0.29141226185538915,-3.880080000000288
563.5000000000074,183.762140741954,-0.28838508466265944,-3.880080464617144
564.6000000000074,184.13231621716133,-0.2907924499002936,-3.879417305316968
565.7000000000074,184.50463431552535,-0.2900674928249294,-3.882051152646963
566.8000000000075,184.87640326835552,-0.291977811918827,-3.8810593329034924
567.9000000000075,185.24809448743835,-0.29294671309926557,-3.88106344453192
569.0000000000075,185.61917000000267,-0.29492885996130935,-3.8807299999999585
570.1000000000075,185.99743027124939,-0.2964932869242003,-3.8792989607004666
571.2000000000075,186.3629312767679,-0.29688737322254166,-3.881390006552234
572.3000000000076,186.7294850096854,-0.2947151221397153,-3.881384248612113
573.4000000000076,187.10510749633966,-0.29620710556249463,-3.8820963952702954
574.5000000000076,187.47455257798026,-0.2983828398916555,-3.8823799937572705
575.6000000000076,187.8469913935058,-0.2983014930651917,-3.8810600254175207
576.7000000000077,188.21659070310793,-0.3002747770117651,-3.8823603058148746
577.8000000000077,188.58086039951306,-0.298795913775153,-3.8823752751310048
578.9000000000076,188.95437249166378,-0.30093665554668325,-3.8827972777797464
580.0000000000076,189.32484547612177,-0.3009298358709547,-3.881719999999999
581.1000000000076,189.69755591988385,-0.2988821135135793,-3.882575074484357
582.2000000000077,190.06611295801392,-0.29843539591324486,-3.8827100041148874
583.3000000000077,190.4275921433593,-0.29698124498808065,-3.882710000021178
584.4000000000077,190.81262837831284,-0.2969117900403564,-3.8827105142728064
585.5000000000077,191.17917000000298,-0.29856698096358514,-3.8830399999999994
586.6000000000078,191.55177779834622,-0.29674703503123867,-3.8833787901195733
587.7000000000078,191.9211217776536,-0.29972385143308866,-3.883356067111707
588.8000000000078,192.29029601460007,-0.29973611678791734,-3.883125980130232
589.9000000000078,192.65952328045947,-0.2979645659498793,-3.8827191103652994
591.0000000000078,193.02871146325953,-0.29867564353018095,-3.883369999980145
592.1000000000079,193.39609328892953,-0.2956873311439123,-3.882033024037522
593.2000000000079,193.76866126589556,-0.2964595039425024,-3.881701821131863
594.3000000000079,194.13790701259984,-0.2975104347367874,-3.883260933615682
595.4000000000078,194.51352882849258,-0.3002764947453187,-3.884570167298904
596.5000000000078,194.88631120297305,-0.2995517799692613,-3.884888322323278
597.6000000000079,195.25568937212464,-0.29970221809783393,-3.8842500000032567
598.7000000000079,195.62580076732058,-0.2998458970241229,-3.88425
599.8000000000079,195.99647156151357,-0.3005478079904149,-3.88555925022365
600.9000000000079,196.37078125678676,-0.29926017491714685,-3.884249963199549
602.000000000008,196.7432047236267,-0.2986260470996891,-3.885240459578738
603.100000000008,197.1125978888607,-0.3006861742145439,-3.883883568034748
604.200000000008,197.48357849096368,-0.30369748366748484,-3.88524369398583
605.300000000008,197.85186631698275,-0.30141161647878745,-3.884910001590594
606.400000000008,198.21856645614852,-0.30319139221586733,-3.8852398481235464
607.5000000000081,198.5914856790319,-0.3034146917790834,-3.886229983797448
608.6000000000081,198.96024070766313,-0.3017473571300995,-3.884909999801798
609.7000000000081,199.33421153424615,-0.3026296087505549,-3.8842500016774224
610.8000000000081,199.69878165752596,-0.303229293836762,-3.885569800501623
611.9000000000082,200.07329181159932,-0.3043731615482881,-3.8855870402782067
613.0000000000082,200.44557626046452,-0.3099163093406623,-3.884580987340811
614.1000000000081,200.81341150403483,-0.30784605860759395,-3.8828158284883476
615.2000000000081,201.18855691843623,-0.30651876060669725,-3.884139705981086
616.3000000000081,201.55649076374795,-0.30721601839367096,-3.885130000037905
617.4000000000082,201.9303856283277,-0.30940765949089766,-3.88579
618.5000000000082,202.29782625978467,-0.30708657015787066,-3.8858940605119865
619.6000000000082,202.6662378377955,-0.30229623174837617,-3.885789999999899
620.7000000000082,203.04972789878215,-0.30742097203231733,-3.8855952729868415
621.8000000000083,203.42115794088073,-0.3041441247157688,-3.8854661800210497
622.9000000000083,203.79681503368226,-0.3046044232941405,-3.886440326162398
624.0000000000083,204.16371111096527,-0.30524292219498417,-3.8861100032411144
625.1000000000083,204.53251180303434,-0.30604926112350483,-3.8861078071598274
626.2000000000083,204.90015588221596,-0.30674594778232134,-3.887099983081237
627.3000000000084,205.27072199430663,-0.30373690732730996,-3.8874260172993753
628.4000000000084,205.64224544112233,-0.30317079533379054,-3.8871000000000033
629.5000000000084,206.00992187625363,-0.23113987767356736,-3.887986512140235
630.6000000000083,206.38478767037395,-0.22490778843991777,-3.88809019312708
631.7000000000083,206.75854250361692,-0.21503878302510282,-3.8870999999978797
632.8000000000084,207.12917401491552,-0.2152287001123856,-3.886769939505733
633.9000000000084,207.50298498678822,-0.21026170368424912,-3.885988765163535
635.0000000000084,207.87128263774466,-0.21236175204616403,-3.8853232031942375
636.1000000000084,208.24302205721077,-0.21107144113795195,-3.885129999999999
637.2000000000085,208.61454030380585,-0.21446605275864128,-3.8870965494029925
638.3000000000085,208.9884097101412,-0.21403445361646334,-3.8849030621201632
639.4000000000085,209.36109354233415,-0.21294257662673832,-3.886894003501632
640.5000000000085,209.73166182582744,-0.21481761619010964,-3.8862299999996335
641.6000000000085,210.10441112075256,-0.21301757669282395,-3.887539968413299
642.7000000000086,210.47359348156465,-0.21148489959766037,-3.887811647768973
643.8000000000086,210.83709335157172,-0.21440770915019458,-3.886780000009299
644.9000000000086,211.21072804050894,-0.2112001336283269,-3.8874165414546367
646.0000000000086,211.5903609168187,-0.21302751776060935,-3.886450000000504
647.1000000000087,211.95076719618717,-0.21449851525504826,-3.8857899999995706
648.2000000000087,212.32244460508744,-0.21365169935032347,-3.886750662605294
649.3000000000086,212.69994958420662,-0.212149221544645,-3.8854599634632683
650.4000000000086,213.07187984419386,-0.21730386785500366,-3.8867799985580036
651.5000000000086,213.44647234911335,-0.21211421139077968,-3.888089999999873
652.6000000000087,213.82113938235037,-0.2123253734175754,-3.8857901030787776
653.7000000000087,214.19277916692678,-0.21363708023306538,-3.885790007624567
654.8000000000087,214.56545337585138,-0.20848480356265986,-3.885465803586955
655.9000000000087,214.93787252826996,-0.2098423278338517,-3.886880002376524
657.0000000000088,215.30793684957337,-0.2109900651979717,-3.887209999999969
658.1000000000088,215.6784908247266,-0.21042244641060037,-3.8880231303292123
659.2000000000088,216.05060200071767,-0.2107532253758415,-3.888199887547825
660.3000000000088,216.42207135164344,-0.21330189733390803,-3.8888410502610937
661.4000000000088,216.79648114093595,-0.21309569388825134,-3.8878408735598975
662.5000000000089,217.16635342474336,-0.21112138627513355,-3.88753786392051
663.6000000000089,217.54137939839964,-0.21266987602503695,-3.886222623850274
664.7000000000089,217.91352385858474,-0.21224291008999252,-3.887208849435979
665.8000000000088,218.28732280540765,-0.21423729159594807,-3.887210199826787
666.9000000000088,218.65582354844133,-0.21489956212295613,-3.887871140513017
668.0000000000089,219.02720647663898,-0.2167630530914293,-3.888859312583424
669.1000000000089,219.39975785901933,-0.21758031717856596,-3.8872121837475526
670.2000000000089,219.77303665606283,-0.21298164362756022,-3.8898958298318678
671.3000000000089,220.14592981255112,-0.21596115016603123,-3.889736443132928
672.400000000009,220.5177845794627,-0.2128210589849453,-3.8898499999960547
673.500000000009,220.89017008415323,-0.2150590152384635,-3.8885299933347373
674.600000000009,221.26289994664455,-0.21445346469052495,-3.888529999999815
675.700000000009,221.63494816298797,-0.21263314605014916,-3.8882862941636565
676.800000000009,222.00892268423584,-0.2101028127554998,-3.8888622961407058
677.9000000000091,222.37744341853636,-0.20714707147318911,-3.8901700000221364
679.0000000000091,222.75662937975787,-0.20577634814513024,-3.890170356836444
680.1000000000091,223.13030255715714,-0.20830216778172161,-3.8914901107278346
681.2000000000091,223.50161369608406,-0.2086524078595553,-3.88885002638668
682.3000000000092,223.87208759596325,-0.2131671215559212,-3.889840000514471
683.4000000000092,224.24508096813207,-0.21286447755692262,-3.889840194174537
684.5000000000091,224.61209088578775,-0.21548016257648994,-3.8908300289457403
685.6000000000091,224.97967775987806,-0.2154939049736675,-3.88984999999816
686.7000000000091,225.35857232066894,-0.21692298469827165,-3.889850000000431
687.8000000000092,225.72772611822637,-0.2175599559114767,-3.8908400703824655
688.9000000000092,226.08577312516167,-0.30922731701572204,-3.890839999420129
690.0000000000092,226.45626635822128,-0.30952630048949814,-3.890840000000443
691.1000000000092,226.81917891338873,-0.30434325827937814,-3.8908399933079876
692.2000000000093,227.19214081197322,-0.3079744104823017,-3.8898516261191074
693.3000000000093,227.56556474644935,-0.3109232325375544,-3.890509888054192
694.4000000000093,227.93791866264772,-0.3119823763992189,-3.8905293175161515
695.5000000000093,228.31322759157135,-0.31558886007009157,-3.8910470014754286
696.6000000000093,228.69256492679074,-0.3154366461469058,-3.8905099577715245
697.7000000000094,229.06436168230658,-0.31630028673067656,-3.8921600145589297
698.8000000000094,229.43376406806283,-0.3128292558105841,-3.892328445408531
699.9000000000094,229.80417937482153,-0.3176816941042966,-3.8928200014689
700.0000000000093,229.83633663726349,-0.3168661479296344,-3.8928198530571168