File: 01_Data/Bamboo_Rug_Fabric/STA/N2/3K_min/Bamboo_Rug_Fabric_STA_N2_3KData_220125_R1.csv
##Temp./Â°C,Time/min,DSC/(mW/mg),Mass loss/mg
50.0,10.501459112510458,-0.016532464155844195,-0.026878935691995842
51.20000000000002,11.494369431226337,0.029681540847509402,-0.02285246627606874
52.400000000000034,12.02265962923477,0.03773010695874279,-0.022818808814957237
53.60000000000005,12.500000000000023,0.046829138597389464,-0.025449943455737145
54.80000000000007,12.958892481131173,0.04682160753895448,-0.02677416600704907
56.000000000000085,13.407192502791796,0.0507033087744887,-0.02284479182502297
57.2000000000001,13.845226355507508,0.05337104878981569,-0.02823991569932449
58.40000000000012,14.271285347831904,0.057215928165631036,-0.02554279138884974
59.600000000000136,14.702551820011445,0.05782026658431583,-0.027592461402651924
60.80000000000015,15.117642484864119,0.05838579421881174,-0.02948242380287658
62.00000000000017,15.537493720082534,0.05943119015479881,-0.02740304775509017
63.20000000000019,15.95313357666401,0.0605040540063958,-0.027740669034907572
64.4000000000002,16.359618542763258,0.06286545579609892,-0.030277298150353626
65.60000000000022,16.74864357037245,0.06386025738813783,-0.030057113805409763
66.80000000000024,17.167764568669647,0.06346088928045557,-0.03136985462217057
68.00000000000026,17.572043021569506,0.05876982937864039,-0.030066997115089755
69.20000000000027,17.972184589384696,0.05971908757871669,-0.033596725629085
70.40000000000029,18.376387477329008,0.05857332908434243,-0.034322527189975194
71.6000000000003,18.786528380888015,0.05877161556245958,-0.03323557396460597
72.80000000000032,19.1894906321928,0.05893133019578467,-0.032362096436877597
74.00000000000034,19.595260996292865,0.06024724136035542,-0.036304381502819894
75.20000000000036,19.99754996428313,0.058841847484278786,-0.03451445283580723
76.40000000000038,20.391449420621722,0.05876229571675551,-0.03554886609965546
77.60000000000039,20.80326172565519,0.05514904723129965,-0.037937287996314684
78.80000000000041,21.20172883525248,0.05632605712465488,-0.03630991588906607
80.00000000000043,21.60323387408254,0.053832435761967834,-0.03598078512250069
81.20000000000044,22.00526047858352,0.05542646652031746,-0.03860898608412899
82.40000000000046,22.399201981245064,0.05590448698779915,-0.0399213579762292
83.60000000000048,22.801665691776435,0.057490846999439404,-0.03861179517920377
84.8000000000005,23.202265864268966,0.05581027103785652,-0.04128799529566862
86.00000000000051,23.602945722144593,0.05388310698589316,-0.039920161814847255
87.20000000000053,24.0028144802548,0.054104715230747336,-0.04119085949595691
88.40000000000055,24.40379231263676,0.05177813531764597,-0.04224033795299986
89.60000000000056,24.80648916996461,0.05234831989035915,-0.040754278902483954
90.80000000000058,25.20703037341588,0.05467463405020445,-0.0460277885858793
92.0000000000006,25.602350805568594,0.05619630977950829,-0.040905205851116566
93.20000000000061,25.99935752139347,0.054804399341873866,-0.04322214110811773
94.40000000000063,26.4022655929268,0.052693240728131197,-0.041902013947521244
95.60000000000065,26.812458296561548,0.055773077076951894,-0.043557853355483456
96.80000000000067,27.19303946380964,0.05446641028672361,-0.04287982135577062
98.00000000000068,27.59865044654936,0.054564158205093194,-0.04502192457438925
99.2000000000007,27.99484688611715,0.05511057138055808,-0.04326211788502565
100.40000000000072,28.39018432422439,0.0577836468435845,-0.04542107385567773
101.60000000000073,28.787886864513055,0.05643826570768429,-0.04516190768157813
102.80000000000075,29.190994801166994,0.059092338946676426,-0.045749952047233755
104.00000000000077,29.58561930280053,0.057030378835849715,-0.04448513182744618
105.20000000000078,29.98642373360138,0.05609023989095707,-0.04447349618323182
106.4000000000008,30.385572808770487,0.059742752389660425,-0.04715995891369351
107.60000000000082,30.776691364289203,0.060832404619187486,-0.04456959338546307
108.80000000000084,31.17744731766101,0.06293904337754996,-0.045298749384531156
110.00000000000085,31.574079710873654,0.0625753369748081,-0.043869153022185525
111.20000000000087,31.97182979754327,0.061518197712882916,-0.04553006580060659
112.40000000000089,32.365547886669,0.06431478833835802,-0.048183274909566975
113.6000000000009,32.766670000000275,0.06577574048205215,-0.04816007120018906
114.80000000000092,33.16138650268817,0.07024515847588375,-0.046166775890445155
116.00000000000094,33.55934453211111,0.06631171906740585,-0.04512070220355291
117.20000000000095,33.955080659711655,0.06632131588541978,-0.04563314385749129
118.40000000000097,34.35074802107222,0.06657212403070978,-0.048489194281242654
119.60000000000099,34.74750226883763,0.06922919732183497,-0.04596131407105064
120.800000000001,35.146272021293456,0.06736536521359782,-0.04980010096544252
122.00000000000102,35.54201832309742,0.06873579878366742,-0.04795212920714986
123.20000000000104,35.93655816603947,0.066627967329279,-0.0501451941356601
124.40000000000106,36.333544153629774,0.06835686731175206,-0.04753314852994617
125.60000000000107,36.72982479713728,0.06782707304046554,-0.05013135963273996
126.80000000000109,37.12947956782442,0.06830506241149292,-0.048809382605232265
128.0000000000011,37.52524702428853,0.06583599824245234,-0.04947017588048519
129.20000000000113,37.91943125239796,0.06941414090599074,-0.05077954428347553
130.40000000000114,38.31626770478948,0.07079861920161701,-0.050790168027527116
131.60000000000116,38.70808463796845,0.07202894155249773,-0.04791432051939015
132.80000000000118,39.094690461350865,0.0729366193162928,-0.05060459726500932
134.0000000000012,39.495134367323274,0.07342084360627354,-0.0504941242424386
135.2000000000012,39.88417651967694,0.0753051063528627,-0.05145799202772139
136.40000000000123,40.27872916289486,0.07462862828319605,-0.05011632483783002
137.60000000000124,40.676082987423904,0.07544944011105104,-0.05437184347907209
138.80000000000126,41.07049713980838,0.0738490770947795,-0.05151210097841297
140.00000000000128,41.46600404336814,0.07688470661789948,-0.05429926830464504
141.2000000000013,41.85971087618361,0.07685960780375545,-0.05442671374177577
142.4000000000013,42.254166406460506,0.07838071138931646,-0.054105551630084125
143.60000000000133,42.64962742917406,0.0830268591491351,-0.05529004305729179
144.80000000000135,43.040338268761296,0.0826321051858272,-0.05545433137451683
146.00000000000136,43.43295983003934,0.08183456137620548,-0.05494958714992437
147.20000000000138,43.82944092953072,0.08441371809480924,-0.05668648219974104
148.4000000000014,44.21950464253131,0.08583600016398685,-0.057590055217461966
149.60000000000142,44.60938045173979,0.08413712437786547,-0.058559528874472466
150.80000000000143,45.00179808237501,0.08327906134361607,-0.05497789182030255
152.00000000000145,45.39697763466343,0.08365707104908804,-0.0582178208468096
153.20000000000147,45.79061635940531,0.08333149689034391,-0.05813053794085654
154.40000000000148,46.182480461345456,0.08696043886388927,-0.06088650364277637
155.6000000000015,46.57488848724695,0.08942466793950143,-0.059584125606235716
156.80000000000152,46.96034453542179,0.08812940849227746,-0.057816724053560975
158.00000000000153,47.35354367465963,0.08814832689603447,-0.05722188999090605
159.20000000000155,47.74038181181897,0.08827996776077329,-0.06120014513153338
160.40000000000157,48.13368448419269,0.08893588823887355,-0.06036929086715359
161.6000000000016,48.52586126453934,0.08841752124017266,-0.06385646507603138
162.8000000000016,48.921784001160695,0.08901724462898142,-0.05989029031606519
164.00000000000162,49.305114637217216,0.08952311304906602,-0.061683839380894945
165.20000000000164,49.69788327648985,0.09222544933809163,-0.06383985705566131
166.40000000000165,50.09055635519313,0.09233684034943423,-0.0664674617089438
167.60000000000167,50.48300753872716,0.09430337747577577,-0.06515978865443506
168.8000000000017,50.8734511652111,0.0964080807993789,-0.06489277240357127
170.0000000000017,51.26667000000052,0.0944252864584636,-0.06417010521894095
171.20000000000172,51.65604015366304,0.09619823317591869,-0.06679718566610449
172.40000000000174,52.0468789486877,0.0973165098124551,-0.06648145048225329
173.60000000000176,52.44011186488412,0.0973978383241022,-0.06779013647025778
174.80000000000177,52.83256468516947,0.09340236050082251,-0.06741099290393127
176.0000000000018,53.22553261717737,0.09739370063648645,-0.06767514432349486
177.2000000000018,53.610660022714875,0.09892559386448163,-0.07080237691619162
178.40000000000182,54.00534650022624,0.09900611761079958,-0.070098943298182
179.60000000000184,54.39293656971359,0.10150207473513617,-0.07375893796789112
180.80000000000186,54.7808199181345,0.10211100578578136,-0.07195797436844575
182.00000000000188,55.17340886465094,0.10191302980641248,-0.0728713492818609
183.2000000000019,55.56513825424479,0.10340881199646812,-0.07622992849258381
184.4000000000019,55.950877361821846,0.1030237265322117,-0.07491090023137481
185.60000000000193,56.34498403478054,0.10213725725116263,-0.07749967736057517
186.80000000000194,56.735876616011716,0.1036875215533114,-0.0759169575563785
188.00000000000196,57.12386976098624,0.10370683491335969,-0.07854013837574447
189.20000000000198,57.51852381064325,0.1042590035397265,-0.0824900572565066
190.400000000002,57.90777382765618,0.10855160935766728,-0.08247529526279473
191.600000000002,58.303461519880905,0.10760125378678354,-0.08371837237135438
192.80000000000203,58.69170961137107,0.11157507747395584,-0.08259860190130963
194.00000000000205,59.07336596304392,0.1132270349427234,-0.08521332475201726
195.20000000000206,59.4632229948271,0.11162342226983485,-0.08649349853027521
196.40000000000208,59.855943219943384,0.11023787347817493,-0.08679313013295964
197.6000000000021,60.238668867442925,0.11331660886776224,-0.0886347879707956
198.80000000000211,60.63427558530859,0.11146958603791907,-0.08798359603089745
200.00000000000213,61.02383984904333,0.11014419548540189,-0.09319274106967823
201.20000000000215,61.412921973476216,0.11185504768500065,-0.09239205208703671
202.40000000000217,61.80275890908996,0.11346673242279798,-0.09620565770271572
203.60000000000218,62.1886394234976,0.11553929917039357,-0.09758932548825783
204.8000000000022,62.57530591072374,0.1137036770718205,-0.09752022220287815
206.00000000000222,62.96702122904528,0.11679272403978647,-0.09959010607683982
207.20000000000223,63.36010701135883,0.11845630380815225,-0.10260163380388976
208.40000000000225,63.748632452547845,0.11791887949037727,-0.10190008325898114
209.60000000000227,64.13640911419303,0.11604358861368358,-0.10420195336581628
210.80000000000229,64.52595478976441,0.11415957534620391,-0.10702464796697919
212.0000000000023,64.92169028042376,0.11582537499893741,-0.10913996252108626
213.20000000000232,65.30821799793021,0.11733937590496213,-0.11294178335008365
214.40000000000234,65.7016200310316,0.11905059899201254,-0.11144713793981742
215.60000000000235,66.09134565973494,0.1167122821561658,-0.11374214975908092
216.80000000000237,66.4784048359321,0.1177987868149783,-0.1126583579964553
218.0000000000024,66.86830710203677,0.11731542851416493,-0.1194357622908857
219.2000000000024,67.25364174171935,0.11892683699369078,-0.12183669578344514
220.40000000000242,67.64882004750336,0.11696652893098225,-0.1231233821887141
221.60000000000244,68.03633415122171,0.12049347714555353,-0.1270246084914204
222.80000000000246,68.43172485649812,0.12034376712786049,-0.12767656571312358
224.00000000000247,68.82078998074374,0.12182667112772266,-0.12827347868258254
225.2000000000025,69.2006890107282,0.12212246903857815,-0.13374133414764344
226.4000000000025,69.60196321077211,0.12152986314420355,-0.13635131924932065
227.60000000000252,69.99231535621568,0.12502573752794105,-0.13763577376813396
228.80000000000254,70.38222630227578,0.12460583173602752,-0.14051324802678167
230.00000000000256,70.77360568648956,0.12638458530571461,-0.1441297184982444
231.20000000000258,71.16534409867249,0.13002476755718856,-0.14811242846826866
232.4000000000026,71.55445896212504,0.13105228108280387,-0.149346686757597
233.6000000000026,71.94175111158057,0.13174772242052857,-0.15383041637489292
234.80000000000263,72.32943810569112,0.13663116266318664,-0.15746213017812893
236.00000000000264,72.72002601531086,0.13899370003622158,-0.16125027064537578
237.20000000000266,73.10251754706889,0.1398996303491219,-0.16591522677023995
238.40000000000268,73.49322005585408,0.14246537546632854,-0.16946039531639112
239.6000000000027,73.88239019321932,0.14172569202435092,-0.1740581495296878
240.8000000000027,74.27152628181581,0.14563088963480408,-0.17804521332112833
242.00000000000273,74.667289723005,0.14984422304485212,-0.18261987093544185
243.20000000000275,75.058824247187,0.15347968968352282,-0.18648989421183426
244.40000000000276,75.4477423396194,0.15782494912151224,-0.19254017712199634
245.60000000000278,75.83990747072926,0.16401153464272816,-0.1970473130686652
246.8000000000028,76.23120654612202,0.1700930210285722,-0.20393958625166153
248.0000000000028,76.61838608576294,0.17878597750433656,-0.21085787314784588
249.20000000000283,77.01133504563352,0.18548781122659486,-0.21617512952730156
250.40000000000285,77.40061659879109,0.20482272971485868,-0.22244208651205977
251.60000000000286,77.79541654606818,0.21507717171028817,-0.2275905556065423
252.80000000000288,78.1843257882272,0.22494651183275152,-0.23566226147978098
254.0000000000029,78.57446251257976,0.2295604731573045,-0.24608076498342824
255.20000000000292,78.96628618996718,0.22571013225287195,-0.2536693686419196
256.40000000000293,79.35890643012672,0.21651786808788903,-0.26350522503170737
257.600000000003,79.74758460658073,0.19770129099987296,-0.26727264909080795
258.80000000000297,80.13797965405145,0.17843649900571013,-0.2782041369656856
260.00000000000296,80.52277381539268,0.16880569698396902,-0.28687963796136895
261.200000000003,80.91011911891974,0.1613742544958806,-0.29921248726714955
262.40000000000305,81.29646347588198,0.15457110097946541,-0.3060819197416347
263.60000000000304,81.68703588037116,0.15332747877105357,-0.3175381915200699
264.800000000003,82.07540296385454,0.1531452351488365,-0.32833289401604615
266.00000000000307,82.46838400769337,0.1550685961915054,-0.34086851103147087
267.2000000000031,82.86401397231708,0.1580946751652431,-0.35293809291470524
268.4000000000031,83.24808442863844,0.1571118442787326,-0.36326330152982145
269.6000000000031,83.63759818077173,0.15835454772518093,-0.37386633354994014
270.80000000000314,84.02756800331468,0.15639442673699336,-0.3885230122330001
272.0000000000032,84.41868327630038,0.15647654553311827,-0.39693009406865665
273.2000000000032,84.81768846691087,0.15567966770585906,-0.41097872893383824
274.40000000000316,85.20498574256501,0.1557041056791995,-0.4237570743163479
275.6000000000032,85.58967006344706,0.1574987868530333,-0.43740071734356123
276.80000000000325,85.98204557109624,0.15950058415343807,-0.4506222712671457
278.00000000000324,86.36940423902077,0.15973834026012926,-0.4629101586407902
279.20000000000323,86.75767126386567,0.16186670421463753,-0.4759649439469822
280.4000000000033,87.14624875014245,0.16313120880611556,-0.4909866329778221
281.6000000000033,87.53873124999514,0.16125831975825541,-0.504513342551085
282.8000000000033,87.9322757148743,0.16178841329754,-0.5219452584880138
284.0000000000033,88.31667000000178,0.16478148593572078,-0.5322132564829967
285.20000000000334,88.7191033366796,0.16540200880985556,-0.5467728383960435
286.4000000000034,89.1097874930909,0.16877472395936188,-0.5661175110214312
287.6000000000034,89.49899190481615,0.1702697742610018,-0.579981523317993
288.80000000000337,89.89234503370643,0.16894031266313966,-0.5942190287234483
290.0000000000034,90.28647256515924,0.1727100077480674,-0.6131566082690756
291.20000000000346,90.67929572714766,0.1763540982477932,-0.6281252045732675
292.40000000000344,91.0648503800069,0.17683363149152434,-0.6472279677954949
293.60000000000343,91.45087334815885,0.17924577223693125,-0.663529280620307
294.8000000000035,91.8394232336501,0.18176945602304337,-0.6790130870997184
296.0000000000035,92.23408703892896,0.18363546109063322,-0.7008771259732964
297.2000000000035,92.6207906881233,0.18794877587071168,-0.7191433876689697
298.4000000000035,93.01530344776577,0.18837756648003268,-0.7404695071890157
299.60000000000355,93.40490977269371,0.19295190663989753,-0.7596839941694822
300.8000000000036,93.79581813623014,0.19571218218117548,-0.7802809107495015
302.0000000000036,94.19101887267193,0.20029599805758525,-0.8048308219918128
303.20000000000357,94.58623690660124,0.2066510274022186,-0.828003636306196
304.4000000000036,94.97964052294785,0.21523789591356202,-0.8517431618826485
305.60000000000366,95.37388983614619,0.21897593316283437,-0.8768093241184238
306.80000000000365,95.76510456430877,0.2271054870640642,-0.9043001204036885
308.00000000000364,96.15596414900217,0.23385079687118876,-0.9336417966259805
309.2000000000037,96.54385501349581,0.2423561042180315,-0.9617015808779823
310.40000000000373,96.94000254641996,0.24913997605320826,-0.9953141374453787
311.6000000000037,97.32940198923912,0.26025001340232956,-1.0276282320133254
312.8000000000037,97.72049356768127,0.27099905887151743,-1.063538352893437
314.00000000000375,98.1108893795592,0.28580650547431874,-1.1024347937056316
315.2000000000038,98.50205468481464,0.2975473268990659,-1.1472101403670107
316.4000000000038,98.89769231891206,0.312709624484768,-1.1900348860655838
317.6000000000038,99.29317048638988,0.32682357225457936,-1.2364688959147667
318.8000000000038,99.68301178753602,0.33848828644505224,-1.2903112831672834
320.00000000000387,100.07516343803626,0.35248437267702776,-1.3492770370205367
321.20000000000385,100.46480449084027,0.36403165298842216,-1.4101437513476975
322.40000000000384,100.85807873580947,0.3662341143563651,-1.471011696129688
323.6000000000039,101.24807932054902,0.36952806071139943,-1.5432146633696364
324.80000000000393,101.63822177295624,0.35805352333988216,-1.6110203736426345
326.0000000000039,102.02962599243494,0.3452757890675269,-1.6793792255857336
327.2000000000039,102.4182621237434,0.3208885803352768,-1.7453551507058842
328.40000000000396,102.80875937949628,0.2917343738789851,-1.8084618574479885
329.600000000004,103.20065303499823,0.25629819066518006,-1.8661815488581608
330.800000000004,103.58911653458124,0.22282274951655281,-1.919452441838983
332.000000000004,103.98407084696711,0.1929018930527158,-1.9651392031331265
333.200000000004,104.3705119529393,0.1702949096084982,-2.002385745286395
334.40000000000407,104.76438142671972,0.1522963640048449,-2.039020088451367
335.60000000000406,105.15914694993161,0.1330174171227188,-2.0667301846479904
336.80000000000405,105.54703879633537,0.12714550029741625,-2.0906868071189297
338.0000000000041,105.94008843925452,0.11974750770066088,-2.115378685411764
339.20000000000414,106.33638488953572,0.11132197616695352,-2.1364313614223285
340.4000000000041,106.73015945103276,0.10561397515050734,-2.1531672582595864
341.6000000000041,107.1234789809267,0.10404636700488794,-2.1689232837279526
342.80000000000416,107.515557964965,0.1006386471734136,-2.1871596264362347
344.0000000000042,107.9039177036447,0.09920432792272049,-2.2024081973152
345.2000000000042,108.29532895517963,0.09882089898492155,-2.2159620827155244
346.4000000000042,108.69173339503787,0.09684746427504085,-2.229319902220106
347.60000000000423,109.08177747271726,0.09352288328627391,-2.245219962880115
348.8000000000043,109.47623854044299,0.09727041824592847,-2.260380382539833
350.00000000000426,109.86635662395311,0.09563743984376305,-2.27385876250898
351.20000000000425,110.25875041160619,0.0965949859522413,-2.284234430943453
352.4000000000043,110.6546114289641,0.09204660251220136,-2.298727813539239
353.60000000000434,111.04861700031155,0.09403142794567879,-2.3105725345095953
354.80000000000433,111.43884473987504,0.09548455117732643,-2.323071045497854
356.0000000000043,111.83741263579935,0.09162252994980234,-2.336672485509718
357.20000000000437,112.23561688759442,0.09227896334866367,-2.3516991930149516
358.4000000000044,112.62888022617278,0.0950235055835547,-2.366493598605807
359.6000000000044,113.02436615992352,0.09773247367835206,-2.3764554714128105
360.8000000000044,113.41597107947612,0.0961536864273648,-2.3875151280751044
362.00000000000443,113.80507227104533,0.09677747591082574,-2.4042543450506857
363.2000000000045,114.19895182077869,0.09750123536737816,-2.41345353842323
364.40000000000447,114.59659752407248,0.09625221100319761,-2.428155056441801
365.60000000000446,114.98763675723737,0.0961990343414571,-2.444421567132305
366.8000000000045,115.38608250975066,0.0962583963171045,-2.454402064383972
368.00000000000455,115.77363493505104,0.09689874262370005,-2.466991286933519
369.20000000000454,116.16788264612822,0.09542234621788126,-2.4819292462052176
370.4000000000045,116.56019082584278,0.09644021292763821,-2.4928883904029497
371.60000000000457,116.95745611670898,0.09566708918835914,-2.503482848342914
372.8000000000046,117.35198640745594,0.0961725159393158,-2.5236293218842607
374.0000000000046,117.7453954404982,0.09670160004512891,-2.536937190219838
375.2000000000046,118.13886160977873,0.09269929464664581,-2.545426840671367
376.40000000000464,118.53089651155167,0.09586946972296918,-2.56632763460234
377.6000000000047,118.92795002539833,0.0987339569799291,-2.5834609001624647
378.8000000000047,119.31914597480281,0.09908151426560631,-2.589693442442079
380.00000000000466,119.71548889692697,0.09651448739677448,-2.6017322273023153
381.2000000000047,120.11776134392223,0.09729934785953008,-2.6226514215398016
382.40000000000475,120.51329287955909,0.0970953371346525,-2.6362497893155177
383.60000000000474,120.90990606413985,0.10177311266675443,-2.654208910051053
384.80000000000473,121.30266089042844,0.10603379450597983,-2.6660811929169266
386.0000000000048,121.69346778242007,0.10639234883193724,-2.6823469344771818
387.2000000000048,122.0910829258962,0.10678930382418762,-2.7013654566754495
388.4000000000048,122.48072287456743,0.1085059742766657,-2.715019751183439
389.6000000000048,122.8760524834463,0.10707557515517069,-2.7353172947521305
390.80000000000484,123.27594342786388,0.10808929950400781,-2.7471530323215756
392.0000000000049,123.66927307923883,0.10726402730404178,-2.7617776952275657
393.2000000000049,124.06386515662577,0.10620427494454417,-2.7751519291051427
394.40000000000487,124.46000620353392,0.1102874985198112,-2.795958250750967
395.6000000000049,124.85103408275108,0.11124560245849756,-2.808497854039476
396.80000000000496,125.24108318588911,0.10998505953755264,-2.823515717617996
398.00000000000495,125.63988727794313,0.10675171821572615,-2.8366376219609384
399.20000000000493,126.03369869223448,0.1118083901532169,-2.8525181075400807
400.400000000005,126.42576168405411,0.10856957836207358,-2.864895518172478
401.600000000005,126.82437933934766,0.10707322998423913,-2.882000794578465
402.800000000005,127.21923960036426,0.10762224251978153,-2.8985999560774953
404.000000000005,127.6136722109713,0.11054618619006354,-2.9106526958795707
405.20000000000505,128.00887157923015,0.11046276218125503,-2.923966209319035
406.4000000000051,128.4100263857134,0.109228718761857,-2.9375883569162573
407.6000000000051,128.80078542209748,0.10902989372199506,-2.95264661920647
408.80000000000507,129.20306135656924,0.10889511806973043,-2.9637762595696238
410.0000000000051,129.5963604222045,0.1076116962096492,-2.976821728819038
411.20000000000516,129.9904347595422,0.10440538667335507,-2.98986616388454
412.40000000000515,130.39110649170982,0.10228951861667668,-2.999672656810926
413.60000000000514,130.78906357601622,0.10250736186759447,-3.009443707144788
414.8000000000052,131.18128584827863,0.10137199298984775,-3.0247150097900386
416.00000000000523,131.57748010030883,0.10238370221470769,-3.0371937204945745
417.2000000000052,131.97263553341196,0.10053588503338329,-3.0459302109213713
418.4000000000052,132.37482733073406,0.09748624649415355,-3.0594833467910596
419.60000000000525,132.76602055518825,0.09685868856350505,-3.0668332858980842
420.8000000000053,133.16192704880302,0.09429642055121978,-3.07961634305809
422.0000000000053,133.55477253296627,0.09483648846856872,-3.0853469955879747
423.2000000000053,133.94591906507247,0.09071540537926076,-3.0937733256983564
424.4000000000053,134.3470305486934,0.08984845497171426,-3.103206119860922
425.60000000000537,134.74103058032918,0.08807640042802466,-3.113867737537212
426.80000000000535,135.13333362942856,0.0839546355118263,-3.1216612238850145
428.00000000000534,135.5329896517942,0.08263068571393109,-3.127360261125289
429.2000000000054,135.93105010080797,0.08109995094569514,-3.1354782795034843
430.40000000000543,136.32672655262812,0.07932469579464345,-3.1422748352081245
431.6000000000054,136.72887864010033,0.08135977733130434,-3.1482237560723747
432.8000000000054,137.1180216059558,0.08030527885475046,-3.1558945926392603
434.00000000000546,137.51387555288713,0.07999049940579682,-3.1599369515708777
435.2000000000055,137.90567291152746,0.07264264820023472,-3.168812299055917
436.4000000000055,138.30041404519076,0.07071914552485466,-3.1711417878057797
437.6000000000055,138.70280649172275,0.07053778398285923,-3.1751682260779566
438.8000000000055,139.098303050937,0.07068907640235,-3.180679716893957
440.00000000000557,139.50072844034324,0.07023833416525506,-3.184302994628109
441.20000000000556,139.89492152487506,0.07144272493631176,-3.189573611277623
442.40000000000555,140.2938345387019,0.06530690543243758,-3.1943520202861566
443.6000000000056,140.69241050929062,0.0663365553449097,-3.197447920197111
444.80000000000564,141.09427451309926,0.06744734605472828,-3.2025359243467686
446.0000000000056,141.49271971534534,0.06718712779621328,-3.2044983711913155
447.2000000000056,141.88251455029663,0.06867910886333686,-3.208796515557408
448.40000000000566,142.28499212669723,0.06849978945082898,-3.209969315081735
449.6000000000057,142.68541288982854,0.06952536081755128,-3.213909653938228
450.8000000000057,143.082664292713,0.07210257540152053,-3.2137719659710484
452.0000000000057,143.48014282240368,0.07982499308906411,-3.2190765882327197
453.20000000000573,143.87457684152432,0.08786668700827735,-3.221600283100029
454.4000000000058,144.2657613087189,0.0893668569701771,-3.22433011529739
455.60000000000576,144.6630224638083,0.08671769070402836,-3.226550834983369
456.80000000000575,145.05977644737862,0.08328046199031175,-3.227423245953238
458.0000000000058,145.45672153928146,0.0769623379940269,-3.2287200816571135
459.20000000000584,145.85836364848615,0.07535774703028651,-3.233878496344819
460.40000000000583,146.25516067451255,0.07964115365626377,-3.232720956761675
461.6000000000058,146.65700143952623,0.07930586120489459,-3.2383278419568304
462.80000000000587,147.05148867521817,0.08094679205914253,-3.2394117937200964
464.0000000000059,147.45163493040423,0.08049842725738772,-3.242652787087441
465.2000000000059,147.8512394230171,0.07698187430535416,-3.2396892862805187
466.4000000000059,148.24118080056724,0.07647218330003544,-3.243626350934481
467.60000000000593,148.63783157524452,0.0737210196846814,-3.2463217985445914
468.800000000006,149.0383798641152,0.0705040329352479,-3.248364281258193
470.00000000000597,149.44316301540243,0.07202633658589488,-3.250112628450614
471.20000000000596,149.84147118813473,0.07483346200487778,-3.2515588815393106
472.400000000006,150.24077212576094,0.07366326508318075,-3.2527165013429196
473.60000000000605,150.63665977400808,0.07134149902553552,-3.2539647281901796
474.80000000000604,151.03735911606734,0.07103806412069313,-3.2566987841294504
476.000000000006,151.43189143267136,0.07129334602854945,-3.2573647983516607
477.20000000000607,151.83260921917008,0.07022120625113171,-3.258343453238358
478.4000000000061,152.230067749038,0.07434014831678623,-3.2609612313658993
479.6000000000061,152.63118181561853,0.06880865697382374,-3.259649990005124
480.8000000000061,153.02867566474012,0.07077069635236105,-3.263556143448521
482.00000000000614,153.42749508009453,0.07335998294918589,-3.2657403932650335
483.2000000000062,153.82539486543521,0.07362443223687634,-3.267451124806619
484.4000000000062,154.22124609464703,0.0726902403460008,-3.266129816231802
485.60000000000616,154.62292697949582,0.06991275706288458,-3.267118294257367
486.8000000000062,155.02351175951378,0.06732117983908151,-3.2704131020322285
488.00000000000625,155.42224753213748,0.07020130484872328,-3.2713891604819505
489.20000000000624,155.8263176115667,0.06858395937746878,-3.273371429520698
490.40000000000623,156.2255682491161,0.071142620735374,-3.274027905391743
491.6000000000063,156.62092533614577,0.06757503943557691,-3.275010345438656
492.8000000000063,157.0192073396799,0.06717229749844622,-3.27666059170434
494.0000000000063,157.41766506979693,0.06631845463655298,-3.275999850558147
495.2000000000063,157.81892499680353,0.06554780434605587,-3.2799197578963413
496.40000000000634,158.2174070625745,0.06424093816049192,-3.2799520185164286
497.6000000000064,158.61998305496627,0.06376531342181055,-3.2812593581175156
498.8000000000064,159.0236120437801,0.06451064866007547,-3.2811831607524975
500.00000000000637,159.42012729815573,0.0656593198865397,-3.2825908866121294
501.2000000000064,159.81739448666198,0.06435059839740287,-3.2854684833820293
502.40000000000646,160.2172860298368,0.06199046553007703,-3.2837890462611274
503.60000000000645,160.6175066917323,0.061406998850538685,-3.286501125272457
504.80000000000643,161.01620199350293,0.06415137073132415,-3.28838627623879
506.0000000000065,161.41576271393637,0.06467633887849084,-3.28773041738401
507.2000000000065,161.81699322825153,0.06698622600034121,-3.290042612539537
508.4000000000065,162.21068700121498,0.0634185673077885,-3.2887368942152007
509.6000000000065,162.61541896658989,0.06376442607395622,-3.2913647845649963
510.80000000000655,163.01948799558522,0.06150866678522687,-3.2929999004413775
512.0000000000066,163.4166700000021,0.05913754660809567,-3.2923320534842593
513.2000000000066,163.81977968102586,0.06042196650457715,-3.2962677693346745
514.4000000000066,164.21704117282647,0.05499912521056061,-3.2970682013149095
515.6000000000066,164.61832761539662,0.05535865658798955,-3.298021441419205
516.8000000000067,165.02119359975518,0.05217494628093594,-3.2971417293662246
518.0000000000066,165.42149384354263,0.05437138312816214,-3.2973483293813235
519.2000000000066,165.81218772070923,0.05093043572194439,-3.301297781784687
520.4000000000067,166.22011808820298,0.049916831200181366,-3.2998535622558944
521.6000000000067,166.6190703951392,0.047714699177722864,-3.301010183094289
522.8000000000068,167.02077282037644,0.05058650009615212,-3.3013792193116904
524.0000000000067,167.41862734346202,0.047965798320142805,-3.303692379498189
525.2000000000068,167.82445281516803,0.04607479637152584,-3.3048857144068697
526.4000000000068,168.2299949167935,0.04560198564889195,-3.3038574461263757
527.6000000000067,168.6311438844388,0.04465050991478192,-3.3070590024912874
528.8000000000068,169.03185557266,0.04410378992466124,-3.3075916575644726
530.0000000000068,169.4296519009316,0.04603871227600448,-3.310430613923568
531.2000000000069,169.82881400498405,0.04706202844478735,-3.307774973656936
532.4000000000069,170.226858655737,0.04229581196017995,-3.3114032298697804
533.6000000000068,170.622847346683,0.0458796265732932,-3.3104400741891573
534.8000000000069,171.02147812235762,0.044025756841215125,-3.3104398831914392
536.0000000000069,171.42195011158174,0.043485771648364646,-3.313042117273768
537.2000000000069,171.82637975472787,0.044621396230888344,-3.3145006829780312
538.4000000000069,172.22862128729753,0.04318086390637693,-3.3144427126181997
539.600000000007,172.6237507674297,0.0466081596293631,-3.314716612094632
540.800000000007,173.0255319807127,0.054446209345350105,-3.31480427953754
542.000000000007,173.4314580212715,0.060667998365953435,-3.3174504862241876
543.200000000007,173.82573545488663,0.07486729346171678,-3.318134427683697
544.400000000007,174.2369425891612,0.092086119071074,-3.3193954067622213
545.6000000000071,174.63690492558922,0.10644092912418651,-3.32206606015739
546.800000000007,175.04198651213335,0.12883535419782272,-3.322387941372016
548.000000000007,175.43971350887702,0.12408865694873394,-3.324201803566994
549.2000000000071,175.8356239314181,0.12031413960137605,-3.324982047386532
550.4000000000071,176.23739285317995,0.11739485495779978,-3.3287387209887696
551.6000000000072,176.63562678349697,0.11674584952331596,-3.330996199086973
552.8000000000071,177.03944877727758,0.11348861987584463,-3.3299584693188415
554.0000000000072,177.44462770789255,0.11477537539325738,-3.330011268668443
555.2000000000072,177.84783221265909,0.11398564593997829,-3.3355568059133134
556.4000000000071,178.2475705819517,0.11455876497742445,-3.3348950024993025
557.6000000000072,178.6442159457514,0.11080407570749057,-3.336537573810371
558.8000000000072,179.04772663016016,0.11342025756295837,-3.3379377793814005
560.0000000000073,179.44969336113462,0.10971947779321695,-3.341137802112847
561.2000000000073,179.85701553568927,0.10527986130176259,-3.3398394442459036
562.4000000000073,180.25987228168373,0.10032085474832708,-3.3414771767022247
563.6000000000073,180.66287445452264,0.09598944817088001,-3.3438191294841304
564.8000000000073,181.06944148228416,0.08859097227954649,-3.345429306931984
566.0000000000073,181.4644359006633,0.08075725284061774,-3.3434419573640817
567.2000000000073,181.866256970023,0.07648331785143386,-3.3475134955133488
568.4000000000074,182.26842447401842,0.06854562886431259,-3.3465995165454636
569.6000000000074,182.66841356651486,0.05764303313860586,-3.345551220191345
570.8000000000075,183.06803552457978,0.051862955209368844,-3.3485089502373304
572.0000000000074,183.47590753275057,0.04622962492842514,-3.348818287295714
573.2000000000074,183.88042468550728,0.045338203860827264,-3.3478430962148282
574.4000000000075,184.28332198226397,0.04936718098139192,-3.3491530296613696
575.6000000000074,184.68722968799509,0.053873758428026275,-3.3530899141056856
576.8000000000075,185.0859362951085,0.05822864595113164,-3.352125079846719
578.0000000000075,185.49031911120017,0.061532908074257264,-3.3537676185933654
579.2000000000075,185.88856805755745,0.06447749103461475,-3.351151750407384
580.4000000000076,186.2857097463073,0.07072758706969262,-3.3521350661957507
581.6000000000075,186.683006806676,0.07136148318021707,-3.3538822448087
582.8000000000076,187.09547904572852,0.0722911293859041,-3.354236799288413
584.0000000000076,187.49962645012494,0.0758829568340954,-3.357498697931394
585.2000000000075,187.90157207205618,0.07785351296214471,-3.3532200180677503
586.4000000000076,188.30642573868653,0.08022296489029779,-3.35690638519114
587.6000000000076,188.71207451067406,0.08106255847987187,-3.3556325112227747
588.8000000000077,189.1139111388588,0.08273693480974798,-3.3589412922405772
590.0000000000077,189.5139895333905,0.08436430503617087,-3.3562918410189155
591.2000000000077,189.9151142185384,0.08793309710046371,-3.358919462311756
592.4000000000077,190.3154812217435,0.08960943820546408,-3.360179136490991
593.6000000000078,190.71881351761502,0.09154466336218925,-3.360557188418741
594.8000000000077,191.12543351417534,0.09012020954821898,-3.359818608155299
596.0000000000077,191.52932967873622,0.09839406833598408,-3.36338289802541
597.2000000000078,191.9345314506457,0.09794399250837194,-3.3610980717560177
598.4000000000078,192.33489512001742,0.0978991791802366,-3.362512704087595
599.6000000000079,192.74168982859769,0.10195467620657861,-3.36356829539161
600.8000000000078,193.14565739228374,0.10370989549305354,-3.3641901038490607
602.0000000000078,193.54802758335447,0.10257377298085957,-3.362125755414137
603.2000000000079,193.94691980592827,0.10431409765040767,-3.3628679135947843
604.4000000000078,194.3440160479146,0.1088440811944742,-3.366488588630701
605.6000000000079,194.75000610008001,0.11177675537577603,-3.3651731635073157
606.8000000000079,195.15284433959044,0.11100183357714222,-3.367806165168248
608.000000000008,195.5583789427161,0.11009114396427666,-3.3648386373866264
609.200000000008,195.9623408490355,0.10993874157272432,-3.3668178299928653
610.4000000000079,196.36938170659323,0.1115316901281016,-3.368123712007759
611.600000000008,196.77295297749612,0.10811163812775815,-3.3680821527746936
612.800000000008,197.1764835405718,0.11246635118218706,-3.3702532253644653
614.000000000008,197.5699258761656,0.11865602120001251,-3.3697795790508818
615.200000000008,197.9751090386389,0.11686802802422236,-3.368785594402379
616.400000000008,198.3769618208699,0.11688807033925619,-3.3700997236224595
617.6000000000081,198.77842922865887,0.11160715344775785,-3.3689067429433726
618.8000000000081,199.1906730569983,0.11603937037854484,-3.3730795713012944
620.0000000000081,199.597564843975,0.12071044269483633,-3.371430081334454
621.2000000000081,200.0037960756165,0.11894454579580849,-3.371430132
622.4000000000082,200.4096969684378,0.11880735115305607,-3.3719401400352504
623.6000000000081,200.81332406306376,0.121925235662393,-3.371433344093398
624.8000000000081,201.2104855527466,0.12115961610702375,-3.3722476833859076
626.0000000000082,201.6090813452003,0.12475590393436731,-3.3725630677817824
627.2000000000082,202.0162979474498,0.12348810572924662,-3.371808484170134
628.4000000000083,202.4126922443599,0.1258193968156549,-3.372895258019555
629.6000000000082,202.8201512791099,0.12699392887013472,-3.3741632328983764
630.8000000000083,203.22681970596778,0.1318105214428439,-3.3781297923487035
632.0000000000083,203.6322978335736,0.1272985834048488,-3.3762080928833136
633.2000000000082,204.03827630772167,0.127109439638462,-3.3754781882933953
634.4000000000083,204.4411096844531,0.12611103652769196,-3.3748131426499377
635.6000000000083,204.8485477293994,0.12876123857887745,-3.377563981968824
636.8000000000084,205.2519780841413,0.1290825644803577,-3.3768995785406943
638.0000000000084,205.6552256366293,0.12768572795151567,-3.376900170663548
639.2000000000083,206.06206340009155,0.12864794944437297,-3.378891681097452
640.4000000000084,206.46360733050827,0.1290303751887798,-3.3782996005112897
641.6000000000084,206.864544486114,0.13033579497870218,-3.379211862183448
642.8000000000084,207.26709819344867,0.12702466554403102,-3.377908321648265
644.0000000000084,207.67382298982685,0.12983924739236175,-3.37665887003561
645.2000000000085,208.07636809058167,0.13621072983827032,-3.377240109211383
646.4000000000085,208.48332292843196,0.1333196123510355,-3.3795504704623074
647.6000000000085,208.8870368210088,0.13317287496592956,-3.3789165935970358
648.8000000000085,209.2943593587786,0.1328347487391146,-3.3795337555513085
650.0000000000085,209.7021055864821,0.13287975902999893,-3.3775606526542044
651.2000000000086,210.10700090523014,0.1332560139555241,-3.3795749360480514
652.4000000000085,210.5108569319835,0.13499146623423663,-3.380234853138897
653.6000000000085,210.91359421335454,0.13432551810658155,-3.3805195507624504
654.8000000000086,211.3163215705233,0.1380273443393948,-3.378232804515215
656.0000000000086,211.71952891492361,0.14179769436961231,-3.379926544235112
657.2000000000087,212.12140286840003,0.14174369129784792,-3.380652446014115
658.4000000000086,212.5288905494693,0.1401151622808241,-3.377206963485194
659.6000000000087,212.9345967703356,0.14324893253331616,-3.379627722394111
660.8000000000087,213.33896512335525,0.14539146484828724,-3.381189952172602
662.0000000000086,213.74077458536743,0.14511345954609023,-3.382925137329129
663.2000000000087,214.14594290537275,0.14587660783239265,-3.3815514343167745
664.4000000000087,214.54818335947937,0.14464526517618737,-3.382058175132862
665.6000000000088,214.95602686919025,0.1467786773075267,-3.3831700738384116
666.8000000000088,215.36667366887795,0.14314212286860073,-3.3802001139342615
668.0000000000088,215.76915983326933,0.14614142678194653,-3.38139815583503
669.2000000000088,216.1663257046044,0.14784494577941587,-3.381514727481309
670.4000000000088,216.5709144797974,0.14522026127005283,-3.3809308428736777
671.6000000000088,216.97092483969791,0.1497300810071288,-3.3838310483295
672.8000000000088,217.37766932155074,0.1485651301446569,-3.3817968189244705
674.0000000000089,217.7799986237583,0.15253014664625764,-3.383542121006208
675.2000000000089,218.18568713907763,0.1523815826601077,-3.3808595348290003
676.400000000009,218.59549008884633,0.1488795478119589,-3.3834766089204074
677.6000000000089,219.0034273277576,0.1502743673272806,-3.382726920791602
678.8000000000089,219.4130017150659,0.15386782677053223,-3.38216976921869
680.000000000009,219.8219330006893,0.15318569746701927,-3.3834747809069436
681.2000000000089,220.22083750513127,0.15191690773294464,-3.3831464530686652
682.400000000009,220.6192311375337,0.15299709567041186,-3.382832052428239
683.600000000009,221.02718618036064,0.1590701812280697,-3.3841500028097293
684.800000000009,221.43264806718497,0.16012482219715896,-3.3848001038131432
686.0000000000091,221.83714351897112,0.1581684457515492,-3.3821927679031916
687.200000000009,222.24160352895214,0.1586560840686484,-3.3858026124052865
688.4000000000091,222.64076427681323,0.16151490234630606,-3.384576963449325
689.6000000000091,223.04770993298436,0.15935066286365318,-3.385789857973819
690.800000000009,223.45121414569,0.15960644065394147,-3.3861551287531384
692.0000000000091,223.85882845410734,0.1572779954545267,-3.386117227452055
693.2000000000091,224.26852781303364,0.15793242055046397,-3.386744068462285
694.4000000000092,224.67160091433578,0.15777871389929654,-3.3877550946095627
695.6000000000092,225.07688705077575,0.15681100760925482,-3.3865630724107385
696.8000000000092,225.48650795741062,0.16042300314121327,-3.3880936843273317
698.0000000000092,225.89213941830388,0.156711252468257,-3.3853652191187695
699.2000000000093,226.3013884941258,0.1566887691226746,-3.386782531650721
700.4000000000092,226.70606352989776,0.1582378641741793,-3.386302859719776
701.6000000000092,227.1109754389117,0.15626123223660282,-3.3865091696351204
702.8000000000093,227.5194927445115,0.15849266315889832,-3.3854665160914688
704.0000000000093,227.92702305644568,0.16057107345979182,-3.388090156606911
705.2000000000094,228.331835924017,0.16111762222708848,-3.388429215620349
706.4000000000093,228.73949646467423,0.15840554313793076,-3.3896389976408585
707.6000000000093,229.1422461826465,0.15922549134482988,-3.386779988060381
708.8000000000094,229.5458315715441,0.16466924356851131,-3.3907364532876185
710.0000000000093,229.94708832198546,0.16621705135988374,-3.3884413312072175
711.2000000000094,230.35718498125095,0.1650616734833834,-3.3896939182715515
712.4000000000094,230.75924151054633,0.1679954736133662,-3.391512416454836
713.6000000000095,231.1673879551072,0.16544113082033807,-3.388765339438941
714.8000000000095,231.56901830272855,0.16497683083403336,-3.3900701556010118
716.0000000000094,231.9732611781867,0.16605501444808324,-3.3917194007705587
717.2000000000095,232.37724780005865,0.16293118531120498,-3.3907797247822424
718.4000000000095,232.78332202606302,0.16197401950953338,-3.3933698998720807
719.6000000000095,233.1920270533715,0.15832894512949647,-3.3899334376956043
720.8000000000095,233.5938000482632,0.15781377130349883,-3.3911643794525546
722.0000000000095,234.00000000000352,0.15644511512506898,-3.393470026707651
723.2000000000096,234.40726466180465,0.1562976505189011,-3.3921600693660823
724.4000000000096,234.8093990085528,0.15793510493110863,-3.393694655562025
725.6000000000096,235.21510675511692,0.15278140137799667,-3.393773031697185
726.8000000000096,235.62295696216802,0.1534324241187901,-3.393797556322398
728.0000000000097,236.03135924018994,0.1541852718910759,-3.3948235963861952
729.2000000000096,236.44002105863177,0.1513863938665707,-3.394790108260497
730.4000000000096,236.8469697363032,0.1513482182006245,-3.3949340050216326
731.6000000000097,237.25233757583572,0.1526882706562498,-3.3970910649155366
732.8000000000097,237.65578578823565,0.15202984307701906,-3.39448720993269
734.0000000000098,238.0592799395214,0.1509831405938662,-3.3964077262727663
735.2000000000097,238.4589735487998,0.14907897595391995,-3.396752160093931
736.4000000000098,238.86824855660805,0.15163889167235833,-3.3964226953195205
737.6000000000098,239.27247993774319,0.1477619150311642,-3.3974199609117575
738.8000000000097,239.6804203506268,0.15338063965525794,-3.3974200304549944
740.0000000000098,240.08515791459178,0.14415284806359474,-3.397387118965867
741.2000000000098,240.48971073984669,0.14688347072595676,-3.398048434347441
742.4000000000099,240.89487261398938,0.14519262787303133,-3.3993895117586304
743.6000000000099,241.29967498615585,0.1418988625589266,-3.3974191815261494
744.8000000000098,241.7100005594464,0.14542895687810797,-3.3984102021089884
746.0000000000099,242.1145743580934,0.14144596580505997,-3.3980799770479715
747.2000000000099,242.51774440419402,0.1450310446718197,-3.400710164102803
748.4000000000099,242.92317832291653,0.14184478411352464,-3.4020301064740206
749.6000000000099,243.33067114382973,0.14137826108253493,-3.400487272401431
750.80000000001,243.73399473399473,0.13567584563953572,-3.3994422451285202
752.00000000001,244.1404805206785,0.13891034655628665,-3.400304147215308
753.20000000001,244.55161643714231,0.13770020307314068,-3.3989501114393557
754.40000000001,244.96238369756907,0.13344717747361234,-3.401590106259105
755.60000000001,245.36859016063198,0.13919147776901775,-3.40063728708912
756.8000000000101,245.77816101725526,0.13052270397590982,-3.402253602965612
758.00000000001,246.18302540622517,0.13060041450281834,-3.4022428437217807
759.20000000001,246.5926686317115,0.12477409051138078,-3.4021061415214855
760.4000000000101,246.99784383802339,0.12767311737350084,-3.402996268522414
761.6000000000101,247.40688997990594,0.13137724551184138,-3.4019099456729336
762.8000000000102,247.81114069758345,0.12818014367230157,-3.4029099695495417
764.0000000000101,248.21282738837812,0.12771000126303633,-3.4029318613688693
765.2000000000102,248.61631516347688,0.1257385396013504,-3.403613844028959
766.4000000000102,249.0191630196219,0.12695335068752,-3.404938651508105
767.6000000000101,249.43101804571944,0.12472585301944661,-3.403580996311729
768.8000000000102,249.83648589135058,0.12195944333458564,-3.402920989512701
770.0000000000102,250.2474552975088,0.1234669413875018,-3.4037975344115936
771.2000000000103,250.6549422458406,0.12147518727347384,-3.4044377880839347
772.4000000000103,251.05988533710163,0.12121527582744562,-3.4063180421014154
773.6000000000103,251.46794414115456,0.116218737764755,-3.4042216201382245
774.8000000000103,251.88023471395016,0.12490075855741578,-3.4055514825865565
776.0000000000103,252.28584960619762,0.11941104932665647,-3.406520571629958
777.2000000000103,252.69283561031466,0.11792974790663546,-3.4045834794997356
778.4000000000103,253.0953251128219,0.11979516315946914,-3.406164330335761
779.6000000000104,253.49590628937594,0.12421983206645004,-3.4018302932817566
780.8000000000104,253.89968927784702,0.11794795735321251,-3.404549849412044
782.0000000000105,254.3051776567867,0.11720347411324217,-3.406520244288671
783.2000000000104,254.7153278189501,0.11811985163169436,-3.4065064561655767
784.4000000000104,255.12561967408934,0.12165571117257024,-3.4056980150947123
785.6000000000105,255.5379634404774,0.11928737515416588,-3.406906170109991
786.8000000000104,255.9467455347252,0.11847423157822323,-3.4055333066540783
788.0000000000105,256.3503997529136,0.11655610280781437,-3.407528879611489
789.2000000000105,256.7528010289087,0.11527371691421084,-3.4068512692030417
790.4000000000106,257.15594364455427,0.11269871870759363,-3.4078426172122898
791.6000000000106,257.56048193266724,0.11206795134226422,-3.408133965660678
792.8000000000105,257.96773634469963,0.10928880362215398,-3.408168800484888
794.0000000000106,258.3759976191115,0.10941632209038343,-3.409910315863118
795.2000000000106,258.7854662276969,0.10948616277760359,-3.408500431432912
796.4000000000106,259.1885493804207,0.1088940496776234,-3.411789059232608
797.6000000000106,259.59858808011995,0.10651205066070601,-3.408176640607477
798.0000000000107,259.73469757796727,0.10861779182429299,-3.410836794064233