File: 01_Data/Mineral_Wool_Insulation/STA/N2/10K_min/Mineral_Wool_Insulation_STA_N2_10KData_221108_R3.csv
##Temp./Â°C,Time/min,DSC/(mW/mg),Mass loss/mg
51.0,10.668963869803097,0.007103595857511413,-0.05770715062755327
52.100000000000016,11.075719724626326,0.05237385611528422,-0.05672881679375008
53.20000000000003,11.336703611426296,0.08007921930058237,-0.05656100259713259
54.30000000000005,11.545708604805318,0.10295936248555715,-0.0560864722352723
55.40000000000006,11.736349727939155,0.11931226368241932,-0.054475100046099456
56.50000000000008,11.906096353476519,0.13125129566471694,-0.05523160548326178
57.600000000000094,12.072035830532169,0.14410162296285822,-0.05759068545089674
58.70000000000011,12.225228714391738,0.1503526824151309,-0.05843933711230287
59.800000000000125,12.37306064748992,0.1560791231148857,-0.05873368581829075
60.90000000000014,12.520885248637875,0.16443837563720698,-0.05731805788601063
62.000000000000156,12.662375745696805,0.16895535012567553,-0.05821473143217659
63.10000000000017,12.803171033177046,0.17359672745685328,-0.059107650726049066
64.20000000000019,12.935906761558678,0.17578506473286093,-0.059264195123594376
65.30000000000021,13.07457502757265,0.18261646298292722,-0.05763960903819143
66.40000000000022,13.207220506283411,0.18645282235516802,-0.05865841943717243
67.50000000000023,13.337940902545064,0.18933377442157373,-0.0613881661241118
68.60000000000025,13.466691080033765,0.19600583126795157,-0.06170409211619754
69.70000000000027,13.59525054968826,0.1967843843671193,-0.062239380183912285
70.80000000000028,13.720592484949366,0.2022561479505809,-0.06322808803309377
71.90000000000029,13.84760222938689,0.20448401329597066,-0.06321837017558884
73.00000000000031,13.972876924594962,0.20992925417471175,-0.0645514345304532
74.10000000000034,14.0969838880835,0.21296943086121445,-0.06695070692776728
75.20000000000034,14.218201845809137,0.21517736823812905,-0.06586353868610084
76.30000000000035,14.33855665552085,0.21930256706821916,-0.06417178685156122
77.40000000000038,14.457618062980906,0.21909320444801628,-0.0642974959850604
78.5000000000004,14.579880251151637,0.2244188595729233,-0.06540366812311404
79.6000000000004,14.7002175702078,0.22931144113602642,-0.06749714009203522
80.70000000000041,14.817733755863028,0.23060233424074172,-0.06987474410557315
81.80000000000044,14.936452066164634,0.23232772629031806,-0.07012171679577417
82.90000000000046,15.053178495722554,0.23664376832520806,-0.07015666407318832
84.00000000000047,15.169432256080203,0.23885745912514889,-0.06923864430766491
85.10000000000048,15.284783159685853,0.24116599929608817,-0.07001191284414077
86.2000000000005,15.400111086919187,0.24623289961057448,-0.06991412091996585
87.30000000000052,15.514937844063338,0.24478707987227655,-0.07267001955991326
88.40000000000053,15.62789660230392,0.24800626127917136,-0.07202743495749075
89.50000000000054,15.74159082333614,0.2512743970202741,-0.0726900891352269
90.60000000000056,15.85395250964405,0.2525143701805578,-0.07148155517587318
91.70000000000059,15.96536099848114,0.253969176295872,-0.07274888546819014
92.8000000000006,16.07786657867699,0.25584642503083976,-0.0735095778484709
93.9000000000006,16.190312555925104,0.2569363394142461,-0.0730338012700158
95.00000000000063,16.30064694652804,0.2573524542558442,-0.07267069733350207
96.10000000000065,16.411812903918094,0.259169622999437,-0.07539341544126499
97.20000000000066,16.52008705140147,0.26230815864582036,-0.07532290955825971
98.30000000000067,16.631615201416544,0.2596651834843602,-0.07536553755294895
99.40000000000069,16.741582898572084,0.26335057728473055,-0.07400005317364489
100.50000000000071,16.849702057708157,0.2642361737323283,-0.07538264994370669
101.60000000000072,16.96010112885784,0.2661017200750566,-0.07664097464101083
102.70000000000073,17.068595252212027,0.266060577467761,-0.07792779690145846
103.80000000000075,17.176715370272376,0.26862758655445296,-0.07796982021758492
104.90000000000077,17.28607594663413,0.2702300357024029,-0.07938490775314433
106.00000000000078,17.391588210211644,0.27052910795198504,-0.07924086328419122
107.10000000000079,17.5027246635005,0.2713113951620858,-0.07925973805523867
108.20000000000081,17.61000000000008,0.27057380698541467,-0.07921107794799331
109.30000000000084,17.715839765056323,0.27301543424605734,-0.07925545623646846
110.40000000000084,17.827109608848914,0.2732072109334829,-0.08054933734332925
111.50000000000085,17.933017105946824,0.2736977749789389,-0.08056997581069725
112.60000000000088,18.03938484878167,0.2736496067284573,-0.08057088547484437
113.7000000000009,18.148356342616154,0.275495937395138,-0.08088261881621595
114.8000000000009,18.254494819710175,0.2746587408945139,-0.08321030006133867
115.90000000000092,18.363650477286164,0.2755493549864746,-0.08320962554245082
117.00000000000094,18.469726523537062,0.27636452660068356,-0.0844956508765673
118.10000000000096,18.577689106714992,0.2760116986818143,-0.08593837535770543
119.20000000000097,18.685661171337543,0.27724975921921846,-0.08582641206243968
120.30000000000098,18.791212970174403,0.2780334150856375,-0.08525561859108688
121.400000000001,18.899396364192867,0.2770866427659756,-0.0848630288841532
122.50000000000102,19.005820125660204,0.27722017752406936,-0.08617986103964093
123.60000000000103,19.10906725406156,0.2786783971322343,-0.08737171911313979
124.70000000000104,19.21867889235995,0.2795176231486862,-0.08848322864181846
125.80000000000106,19.325936939786384,0.2787967734426532,-0.08847995551322096
126.90000000000109,19.42984369098032,0.2800851096346876,-0.08946217025568437
128.00000000000108,19.535620134930618,0.2796401461383039,-0.08677261200963704
129.1000000000011,19.643386681469458,0.28006892831941343,-0.08755504014744409
130.20000000000113,19.751064448067755,0.280489376118657,-0.08854761490709073
131.30000000000115,19.856954998399342,0.281905223074845,-0.09064394879265913
132.40000000000117,19.963054226917563,0.28168240692448376,-0.08980113703824077
133.50000000000117,20.067360186455865,0.2822333491841913,-0.09111825721866262
134.6000000000012,20.17360327451244,0.2798203504360409,-0.09243045237957137
135.7000000000012,20.280102271864493,0.28043052294465687,-0.09374869321519697
136.8000000000012,20.385141871039842,0.2810047983632876,-0.09243009406862734
137.90000000000123,20.491842306945525,0.279164376183882,-0.09231651847264333
139.00000000000125,20.59662466825119,0.27944054023466225,-0.09440760669241666
140.10000000000127,20.701576697096066,0.2783345824927629,-0.09360921246994591
141.2000000000013,20.806834467064757,0.27942029331507434,-0.0952718350368067
142.3000000000013,20.91118684640067,0.28025266689393424,-0.09428234429190319
143.4000000000013,21.016978533100716,0.27943835831557884,-0.09395202277727854
144.50000000000134,21.121385865881486,0.2803811512203438,-0.0925838291982326
145.60000000000133,21.226610102817457,0.2803595057252021,-0.09707789084637675
146.70000000000135,21.331088896086648,0.28050681997664517,-0.09462866701352368
147.80000000000138,21.436380145648876,0.2805805799760184,-0.0959797671426279
148.9000000000014,21.540402970850284,0.2804008202146233,-0.09594710662511963
150.00000000000142,21.644489480680438,0.2801039763694746,-0.09726383495178315
151.10000000000142,21.75061886286897,0.27950240957557215,-0.09805987083544965
152.20000000000144,21.854752357244536,0.2805270891929761,-0.09729212598203274
153.30000000000146,21.95976684101718,0.2802848959122457,-0.09694211828366583
154.40000000000146,22.064269624622536,0.2799696438159317,-0.09677759341977943
155.50000000000148,22.16730236359427,0.2803480600307694,-0.09720461684661652
156.6000000000015,22.273158491493163,0.2808735349459136,-0.0990394547493012
157.70000000000152,22.377720682124902,0.2805218073007971,-0.09789196621957075
158.80000000000155,22.4796685333891,0.281727327672432,-0.10053175428602357
159.90000000000154,22.586390722224095,0.28241672183989,-0.10054948959210597
161.00000000000156,22.69074692631099,0.2828208715887145,-0.10055024564073722
162.1000000000016,22.7949366052523,0.2832604397614672,-0.1005522967260788
163.20000000000158,22.898943527340244,0.27974046433387534,-0.1002198776572758
164.3000000000016,23.004019315470064,0.28229967916590815,-0.10154025457237381
165.40000000000163,23.108476446494453,0.28195709290354554,-0.1008745590195339
166.50000000000165,23.212522153428207,0.28346231634667196,-0.10292574052441639
167.60000000000167,23.31506177284391,0.2791547555938595,-0.10132966279165734
168.70000000000167,23.421123031068294,0.2803959632536899,-0.10132991874635522
169.8000000000017,23.52523368460752,0.28040406961617237,-0.10094265410767722
170.9000000000017,23.63029781800254,0.2823764489407624,-0.10063570007154565
172.0000000000017,23.73429590312768,0.2803094037248879,-0.10116648815734619
173.10000000000173,23.83905507908601,0.2807233785834672,-0.10308715268345026
174.20000000000175,23.94269312510098,0.28139151367618054,-0.10527596713056209
175.30000000000177,24.047926418561445,0.28194273299487116,-0.10560054880286973
176.4000000000018,24.15177359297422,0.280955492764139,-0.10559910359040359
177.5000000000018,24.256036665486352,0.2783318800553287,-0.10593010232715105
178.6000000000018,24.360272892791745,0.2797320542366588,-0.10461896100602175
179.70000000000184,24.463008819264886,0.27950807483346174,-0.10462002298853967
180.80000000000183,24.571176911304665,0.28088834134238205,-0.10462002299868978
181.90000000000185,24.673899611866,0.2820445907157729,-0.10461875791417974
183.00000000000188,24.77760362732129,0.28139449694767826,-0.10395478995290741
184.1000000000019,24.881855048478563,0.28375431440397303,-0.10817940145061877
185.20000000000192,24.98559260228273,0.28241182681524524,-0.10889999953756346
186.30000000000192,25.090466880971874,0.2828243136980192,-0.10956068012075759
187.40000000000194,25.1941188808675,0.2838507089151223,-0.10823894822042934
188.50000000000196,25.298650169672303,0.2828853930101002,-0.10823983899961975
189.60000000000196,25.403040402914627,0.2825124259766305,-0.108239839002918
190.70000000000198,25.50761783733427,0.28268141672695224,-0.10823961045492814
191.800000000002,25.610829713056315,0.2825912991262325,-0.10823018428673059
192.90000000000202,25.715581422228386,0.28209951352265517,-0.10955453190180364
194.00000000000205,25.819613729076043,0.28318525566762676,-0.1095501480000296
195.10000000000204,25.92361480503983,0.28232863392923013,-0.1095335289122028
196.20000000000206,26.027289615424486,0.28223791176619584,-0.10835340085947909
197.3000000000021,26.13296968753987,0.28001023044030715,-0.10955940552105048
198.40000000000208,26.23639635509502,0.28269012688623374,-0.10856965242734251
199.5000000000021,26.34061845018297,0.2804414202273158,-0.109890218665182
200.60000000000213,26.446276788000596,0.28243339548428337,-0.11120080551390732
201.70000000000215,26.54890485083241,0.282476154702344,-0.11117471733907625
202.80000000000217,26.653347878793962,0.2822332584323045,-0.11382540728206658
203.90000000000217,26.757749541907362,0.282445395371831,-0.11252377210087428
205.0000000000022,26.86195359426413,0.2833664220726537,-0.11383912153204179
206.1000000000022,26.96626292415524,0.2838408055313204,-0.11351497524702259
207.2000000000022,27.070595322216892,0.2824135193998235,-0.11384400410611217
208.30000000000223,27.17451128743613,0.28365357628604326,-0.1138399199840876
209.40000000000225,27.279813460293944,0.28209918376935805,-0.11383982349838684
210.50000000000227,27.383285028271917,0.2838597570972703,-0.11317968628000497
211.6000000000023,27.48784429842047,0.2835230923079174,-0.11317605527093111
212.7000000000023,27.591259401530397,0.28313673122925076,-0.11383015159497045
213.8000000000023,27.696972550859684,0.28301973723086227,-0.11515000614600002
214.90000000000234,27.801519552504285,0.2846413372398238,-0.11384955211277514
216.00000000000233,27.904050751257813,0.28369044619298556,-0.11384016202434077
217.10000000000235,28.00874260632096,0.2843044678365538,-0.11384010548469803
218.20000000000238,28.11284779168547,0.28410933967151425,-0.113841351784433
219.3000000000024,28.218497756425556,0.285002343732755,-0.11384007000254526
220.40000000000242,28.321833659320756,0.2827660661474602,-0.1138386589132212
221.50000000000242,28.427055619051146,0.2830170738106601,-0.11518620985962302
222.60000000000244,28.531364603814634,0.28584850941280165,-0.11581267112892935
223.70000000000246,28.634815972515447,0.28454386704042367,-0.11624223586962135
224.80000000000246,28.738742810198925,0.28399061653894697,-0.11614125425704591
225.90000000000248,28.84360633940936,0.2832840970764298,-0.116139809958971
227.0000000000025,28.947188256476345,0.28409344397446673,-0.11644458996198725
228.10000000000252,29.053422826220604,0.2869847804637321,-0.1177892455942744
229.20000000000255,29.15660502171973,0.28428299201380614,-0.11844995181137108
230.30000000000254,29.26195471774604,0.2840318855992607,-0.1184499329303268
231.40000000000256,29.366206215221982,0.2849056233986408,-0.11778307944415767
232.5000000000026,29.471010240979787,0.2845677923468278,-0.11909987180403281
233.60000000000258,29.575502885764443,0.2838746125525851,-0.11909988599999455
234.7000000000026,29.67865988722772,0.28323914065538836,-0.11909994560314807
235.80000000000263,29.78345957655799,0.28287498891526125,-0.11977003327144375
236.90000000000265,29.88790540189193,0.28140047898959264,-0.11976859585136834
238.00000000000267,29.991764828197354,0.2829035330785078,-0.12042987073857114
239.10000000000267,30.096626581803108,0.28428600691082434,-0.12042986690368807
240.2000000000027,30.202469631389967,0.28267201316297197,-0.11978535218307051
241.3000000000027,30.306527170633938,0.28323423491088373,-0.11977030879314832
242.4000000000027,30.4115034605253,0.2826645843526782,-0.12042258850082144
243.50000000000273,30.515584348919994,0.2831077662533095,-0.12175635892821024
244.60000000000275,30.619479768987947,0.28454111060308607,-0.12043742768391175
245.70000000000277,30.72555699203229,0.2809572566098301,-0.12305859110699391
246.8000000000028,30.828916066538365,0.28265765440332585,-0.12273830798246177
247.9000000000028,30.9340351281637,0.28163905045020143,-0.12174014647004272
249.0000000000028,31.038657197428368,0.2795677070161348,-0.12174015103794167
250.10000000000284,31.14238180696553,0.2810686257633487,-0.12166808616703051
251.20000000000283,31.24764030265835,0.28007957609803436,-0.12008759837874994
252.30000000000285,31.352041946016197,0.28144858944503187,-0.12042012545824621
253.40000000000288,31.45657829123412,0.280992021425872,-0.12174038529345843
254.5000000000029,31.562227383190102,0.2810351455222629,-0.12173961610644435
255.60000000000292,31.666431062120168,0.2787009022153046,-0.12313193318541593
256.7000000000029,31.77134498161568,0.2801395278681302,-0.12470861138707923
257.8000000000029,31.876532305030704,0.28052099747494125,-0.12470005895651193
258.90000000000293,31.981072748156375,0.2786139697710605,-0.12470005899999759
260.00000000000296,32.08560116987175,0.27932971873425566,-0.12470005307842635
261.100000000003,32.1907797584324,0.27746589751702644,-0.1233832385594602
262.200000000003,32.2950995491155,0.27733908989228356,-0.12602032493343174
263.300000000003,32.40061766593821,0.2769326452992384,-0.12732315755522006
264.40000000000305,32.50486902293552,0.2764644552940773,-0.12471262463374355
265.50000000000307,32.60944984485431,0.2754687374328034,-0.12469997223942997
266.6000000000031,32.7155443378671,0.27454043165423797,-0.12338544115653827
267.7000000000031,32.820580084670276,0.2735768480786889,-0.1233899072817426
268.8000000000031,32.92396494110186,0.2739669323236023,-0.12459048152930974
269.9000000000031,33.029687645498,0.27399185170918167,-0.12439707533307098
271.0000000000031,33.133553648625494,0.2731288889474112,-0.12569950514672046
272.10000000000315,33.23898313925993,0.2731052776851284,-0.12570007841513053
273.2000000000032,33.34374502834361,0.2736530448768042,-0.12706936765835186
274.30000000000314,33.44827956008895,0.2743837577767791,-0.12569670631044083
275.40000000000316,33.55268243641308,0.27470048903492356,-0.12831992666078795
276.5000000000032,33.65586314034188,0.27446916584736836,-0.12829246817340945
277.6000000000032,33.76336135094362,0.2736523602886598,-0.126761642607625
278.70000000000323,33.8679943040053,0.2733292060128284,-0.1263410183986755
279.80000000000325,33.972542023310474,0.27415268429249057,-0.12634963015018297
280.9000000000033,34.07722637018103,0.2738875308501153,-0.12431640299826041
282.0000000000033,34.18225644160465,0.2738802423204215,-0.12638531513807694
283.1000000000033,34.28658599091303,0.2723218457644449,-0.12635018933245412
284.20000000000334,34.3908812184587,0.27324913893933106,-0.12767376461845759
285.30000000000337,34.49616786733286,0.27445535153359857,-0.12800208828209003
286.40000000000333,34.60077119496971,0.2727978455186394,-0.12799980799813904
287.50000000000335,34.70640601577614,0.2738234830764797,-0.1280018535240104
288.6000000000034,34.81089946869854,0.2735063608122521,-0.12801190381808558
289.7000000000034,34.91640809151256,0.2724633607116273,-0.12800011650264542
290.8000000000034,35.021949748170265,0.27238953360005846,-0.1267063908093542
291.9000000000034,35.12653734289181,0.2735381291288567,-0.1280000303849822
293.0000000000034,35.232142187482914,0.27409854689317814,-0.12799978487137587
294.10000000000343,35.33694521375234,0.274571567816012,-0.12932004564716149
295.20000000000346,35.443026109363906,0.27255012394771816,-0.12799924177465627
296.3000000000035,35.54757135459892,0.2728882602453578,-0.1266973679897121
297.4000000000035,35.65166131858871,0.2731125714931212,-0.12735000783217743
298.5000000000035,35.757166600987205,0.27159339973595037,-0.1299633821461983
299.60000000000355,35.86272625263175,0.2718412207554982,-0.12997007123390558
300.70000000000357,35.967369372764864,0.27114574252816787,-0.13130148533452735
301.8000000000036,36.073142139450354,0.2713253551722314,-0.13129015471455485
302.9000000000036,36.17832898557474,0.2700051280872797,-0.13003262794955894
304.0000000000036,36.28323953974633,0.27031029967857606,-0.1312904319032695
305.1000000000036,36.389517669936225,0.2701581571061897,-0.129979981115099
306.2000000000036,36.495083059970604,0.2673085656996334,-0.13093393353202432
307.30000000000365,36.600502964310586,0.26684255249960637,-0.13129088525548882
308.4000000000037,36.70584871395542,0.26640642601087394,-0.13129007100328893
309.5000000000037,36.81036617111492,0.2669254986917477,-0.13129007098984014
310.60000000000366,36.91668882789718,0.26842408881209817,-0.13130361523855427
311.7000000000037,37.0217226252507,0.2659594368802346,-0.13391302439667818
312.8000000000037,37.128069024766226,0.2659197153135105,-0.1325516591020639
313.90000000000373,37.23334179417135,0.2673311685855294,-0.13162000935908225
315.00000000000375,37.33906664747189,0.26599681746451703,-0.13026003409070075
316.1000000000038,37.44400566321806,0.2634930709364743,-0.1303000022468801
317.2000000000038,37.54980645489398,0.26428709164522324,-0.13089100316868763
318.3000000000038,37.65517357648411,0.2652485734283274,-0.1329400944360053
319.40000000000384,37.76132272036787,0.2633107486260577,-0.13294010975543147
320.5000000000038,37.86701844461648,0.26438168431712294,-0.13426340960154048
321.60000000000383,37.97170204289266,0.2638786569161835,-0.13425165156669028
322.70000000000385,38.077881239873236,0.2663867767536273,-0.13548376301799614
323.8000000000039,38.184067181219355,0.26623842780840484,-0.13557009405054554
324.9000000000039,38.28981184864883,0.26440635151445185,-0.13457987673961025
326.0000000000039,38.395423180568216,0.2644078155624736,-0.13590519010859348
327.10000000000394,38.500759184909555,0.2628656325821589,-0.1332594943359977
328.2000000000039,38.60757699717889,0.26456796680989497,-0.1345815035218263
329.30000000000393,38.71325489178981,0.26458434831858674,-0.13589999505243577
330.40000000000396,38.81910397291837,0.26578352850459536,-0.13722029505983313
331.500000000004,38.92457769657,0.2655799697107647,-0.13716796810248955
332.600000000004,39.030590884079295,0.26638030683403485,-0.1359000022096839
333.700000000004,39.13630524987634,0.2659700330297985,-0.13590000200000185
334.80000000000405,39.24000101839646,0.2644541323766564,-0.13590000200000096
335.90000000000407,39.34743559389331,0.2655314968772309,-0.1359000008331197
337.0000000000041,39.45362986848521,0.26403444811077165,-0.13522931125875104
338.10000000000406,39.557396849469015,0.2634339296324417,-0.13525001925261515
339.2000000000041,39.664893274963646,0.2628554922611189,-0.13729995795115002
340.3000000000041,39.77104257002755,0.2629425097090674,-0.13689126185329492
341.4000000000041,39.87641388796899,0.26204430519472566,-0.13556525100949646
342.50000000000415,39.98132792046903,0.26348975333573005,-0.13689002505497694
343.6000000000042,40.088452653617736,0.2650508919760262,-0.13681953265830238
344.7000000000042,40.19481303787295,0.26317553058026344,-0.1375375854184826
345.80000000000416,40.30172113131086,0.26334847126397165,-0.1375595135068557
346.9000000000042,40.40772824400082,0.2623011622082867,-0.13689624221115038
348.0000000000042,40.51322154129586,0.263580255685123,-0.13820996328176172
349.10000000000423,40.61940160835179,0.2635494367917039,-0.13820995800004
350.20000000000425,40.725813665894286,0.26441564485274943,-0.13820985886175885
351.3000000000043,40.831196490491905,0.26320002515092833,-0.13734347873865005
352.4000000000043,40.9375995675629,0.2618356172219485,-0.13821002472985944
353.5000000000043,41.04417823032186,0.2629058041483396,-0.13887533747095127
354.60000000000434,41.148632841876264,0.2635788332434215,-0.13954466293737067
355.7000000000043,41.25665912041425,0.26443525398753553,-0.13822288060414278
356.80000000000433,41.363053480656646,0.26356623355497294,-0.13821497893688672
357.90000000000435,41.469804063270466,0.2647149273996444,-0.13952003304890281
359.0000000000044,41.57526342261199,0.26669413114173296,-0.1395198733188585
360.1000000000044,41.681335005957116,0.26492970330315024,-0.13685937664819825
361.2000000000044,41.788175859461134,0.26617318440962917,-0.13733758201889135
362.30000000000445,41.89537969668935,0.26362486007108443,-0.13688638064842884
363.4000000000044,42.001569440282175,0.2659117145505911,-0.13821001234796126
364.50000000000443,42.107361825288386,0.2638076964735542,-0.13951694106939394
365.60000000000446,42.21387300090904,0.26533777156487137,-0.14216339364356134
366.7000000000045,42.32059305652629,0.26552731557685344,-0.1434801270946946
367.8000000000045,42.42725949091668,0.26713325100494606,-0.1421680302302737
368.9000000000045,42.53267938315272,0.26717500722829524,-0.140838340161066
370.00000000000455,42.63931143833279,0.2652547029648014,-0.142431181651141
371.10000000000457,42.74572974526498,0.26594873947567843,-0.14249014001519278
372.2000000000046,42.852812809546755,0.266724929096228,-0.14251201209107878
373.30000000000456,42.959727176833326,0.26599660623840743,-0.14215225143429544
374.4000000000046,43.064524806780476,0.26554675271938,-0.143788097155503
375.5000000000046,43.173413761295855,0.266007179292411,-0.14276475882690942
376.6000000000046,43.279999063058334,0.2650676584055073,-0.1424955581844043
377.70000000000465,43.386114209308886,0.2645127091421131,-0.14116953274500332
378.8000000000047,43.49246571763098,0.26525192114801016,-0.14101341296685987
379.9000000000047,43.599689842750664,0.2649080590024714,-0.14348037733520247
381.00000000000466,43.70625737578652,0.26323855430603543,-0.14350671337952248
382.1000000000047,43.81259935522149,0.26088874215559105,-0.14158416694266984
383.2000000000047,43.920098136418176,0.2603842663377402,-0.14249232325824668
384.30000000000473,44.02680484238153,0.26207471481360867,-0.14380879431838478
385.40000000000475,44.133434262381044,0.2635306836414252,-0.14611509653063726
386.5000000000048,44.240745678057245,0.26305033850289566,-0.14480012451349067
387.6000000000048,44.34657716965056,0.26186374159546066,-0.1434798355319633
388.7000000000048,44.45470529009363,0.2591462491366172,-0.14480795017620185
389.80000000000484,44.55831163576935,0.25918810796552444,-0.1461097733169745
390.9000000000048,44.66822783368459,0.2517627651556052,-0.1447985934081819
392.00000000000483,44.7752727814549,0.25855781828766516,-0.14480322810000956
393.10000000000485,44.88176460919279,0.25863170255520657,-0.14610980119100603
394.2000000000049,44.9873604505759,0.26032504290587405,-0.14610989706779343
395.3000000000049,45.095554729305306,0.26036131141055036,-0.14735220557301343
396.4000000000049,45.20323062806437,0.26151481630847395,-0.14612014663685535
397.50000000000495,45.30953684751044,0.2599508264709268,-0.14613862810476208
398.6000000000049,45.41663262204658,0.2610696452481903,-0.14610988073747055
399.70000000000493,45.524315668099504,0.25965894133332207,-0.1454597310514374
400.80000000000496,45.63069111906946,0.25930899721669687,-0.14695728063369096
401.900000000005,45.737494556124396,0.26027115007099605,-0.14709836788023
403.000000000005,45.84564929584435,0.26028267332735966,-0.14629917961974126
404.100000000005,45.95285919310328,0.26014284083779726,-0.1467698538825486
405.20000000000505,46.06009957008807,0.25603259146141133,-0.14676985399999953
406.30000000000507,46.16698845672188,0.25866198960879416,-0.14676985398336395
407.4000000000051,46.27473543016975,0.25772162360817547,-0.14679390727767316
408.50000000000506,46.37975620129527,0.2582770699910123,-0.14554194664630105
409.6000000000051,46.48974184914377,0.2571355354251049,-0.14510309969970736
410.7000000000051,46.59720874391338,0.25756056777811687,-0.14677374676860833
411.8000000000051,46.70397662813896,0.2560330366040313,-0.14676984222658884
412.90000000000515,46.812190515465126,0.2566835611124207,-0.14809037317772322
414.0000000000052,46.91922117031386,0.2573765356871991,-0.14808994600013703
415.1000000000052,47.02603613913077,0.2570427709706057,-0.14808994204559633
416.20000000000516,47.13373808026948,0.2584466410553531,-0.1490849388056601
417.3000000000052,47.24181479600847,0.26030196817391105,-0.1490805759868672
418.4000000000052,47.34909075448261,0.2579705111047645,-0.15039001558946286
419.50000000000523,47.45505218076208,0.26000383086167245,-0.14909218418211623
420.60000000000525,47.56358611767181,0.2585993143630153,-0.15039929974351507
421.7000000000053,47.67051385439495,0.2580568025065971,-0.1504000858940837
422.8000000000053,47.77906966217226,0.26085513292515977,-0.1503892768155306
423.9000000000053,47.885690073784176,0.25843118622871686,-0.14907397740425488
425.00000000000534,47.99246941898029,0.25871336944351186,-0.14910492705513922
426.1000000000053,48.09951973547715,0.25718171300729853,-0.1490798059317524
427.20000000000533,48.20737256303441,0.258454684959321,-0.14773843614810023
428.30000000000535,48.31383025518579,0.2593775101580604,-0.1477702807386332
429.4000000000054,48.42310677939991,0.259634561424137,-0.1503900513737153
430.5000000000054,48.5297020012829,0.2603467006771798,-0.15138001597872153
431.6000000000054,48.63748350692741,0.26189877706889686,-0.1517102786736575
432.70000000000545,48.74483820625096,0.2629683626301837,-0.15037711370890783
433.8000000000054,48.85262791895501,0.2602433692507977,-0.14908124068199813
434.90000000000543,48.96058566986787,0.255732234637963,-0.15007018415405327
436.00000000000546,49.06692444243344,0.25362159296513676,-0.15137103345868308
437.1000000000055,49.1746596942737,0.2525719771782762,-0.15138010500651644
438.2000000000055,49.28095730798477,0.25048890625273623,-0.1513801050000012
439.3000000000055,49.39071521818486,0.250797681744896,-0.15138010501605592
440.40000000000555,49.49772231900284,0.2496021549849498,-0.15023791852791302
441.50000000000557,49.604097039253254,0.24677060943836157,-0.1500600128125944
442.6000000000056,49.71214535049294,0.24579400599622805,-0.15006001622884613
443.70000000000556,49.820361429574646,0.24739906460678382,-0.15137954350468474
444.8000000000056,49.92825969292242,0.24411186900745,-0.15027366055771063
445.9000000000056,50.03522139935472,0.24247992584672143,-0.15270018030140875
447.0000000000056,50.14322532665921,0.2422824059307319,-0.15269882324803508
448.10000000000565,50.25107149486343,0.24049341418552347,-0.15138010936754487
449.2000000000057,50.35866842581062,0.23746585205161733,-0.1505155890329628
450.3000000000057,50.465365837506084,0.2360499088821128,-0.15040011158733435
451.40000000000566,50.57383948964896,0.23570605231361075,-0.15106542365158848
452.5000000000057,50.681922061505624,0.23536377030161124,-0.15172049227320095
453.6000000000057,50.78950338262121,0.23432630236152932,-0.15169609103865156
454.70000000000573,50.89808703558223,0.23317499269655206,-0.1520168787598415
455.80000000000575,51.00593560190463,0.23352497050766355,-0.1533598174453532
456.9000000000058,51.1140977925418,0.23139236301635874,-0.15336305840261444
458.0000000000058,51.21955623660177,0.23373727644494863,-0.15336058355698556
459.1000000000058,51.329546442267095,0.23461661101197626,-0.1520500192566976
460.20000000000584,51.437046894192335,0.23338350187458956,-0.1530298529483698
461.3000000000058,51.54522773133741,0.23442664861863155,-0.15303398520413847
462.40000000000583,51.65274238715305,0.23272527938839194,-0.1537295921373425
463.50000000000585,51.76088521560511,0.23377383859132886,-0.15302986317875478
464.6000000000059,51.86929654259444,0.23236357889827855,-0.15302986653770523
465.7000000000059,51.976518072274516,0.2351600026668067,-0.15434903420937962
466.8000000000059,52.08470637190617,0.23617662426507843,-0.15302992230572388
467.90000000000595,52.192987391722994,0.23635880387935854,-0.15310111898413625
469.0000000000059,52.30118686665215,0.23569437943732027,-0.15043199938954066
470.10000000000593,52.409398613022574,0.2335572350921587,-0.15170433301168273
471.20000000000596,52.51749173221082,0.23564045836880593,-0.15435017636967174
472.300000000006,52.62624949316494,0.23830415879014397,-0.154326101949386
473.400000000006,52.73333740757508,0.2351363045106917,-0.1543502411978599
474.500000000006,52.84151577917849,0.23748673285900537,-0.15291578491657187
475.60000000000605,52.950293850448034,0.23869016785935723,-0.1543498416667215
476.70000000000607,53.05915670620159,0.23641068362297693,-0.15533829855482928
477.8000000000061,53.16695398976243,0.23792275955039943,-0.15534004700006854
478.90000000000606,53.27498150439827,0.2370618370932654,-0.1553469775075138
480.0000000000061,53.38330251399415,0.23963150759708884,-0.15402004622883902
481.1000000000061,53.49176907003413,0.2383023979332216,-0.15402004699999994
482.2000000000061,53.599605331116365,0.23924203239521039,-0.1540200470000226
483.30000000000615,53.708359889760786,0.23885892771437833,-0.1540198933635457
484.4000000000062,53.816545160074654,0.2364210016903922,-0.15531879382651725
485.5000000000062,53.92440611478104,0.23556814661525363,-0.1543522465974818
486.60000000000616,54.033720728078315,0.23631242683015113,-0.15423590209615057
487.7000000000062,54.14135917513346,0.23783813521032637,-0.15435693345375467
488.8000000000062,54.24805890020572,0.2402628654623303,-0.15303962433844243
489.90000000000623,54.35822019160587,0.24356097362126536,-0.1562646988109715
491.00000000000625,54.46706007086284,0.2406267021129257,-0.15576980040075616
492.1000000000063,54.575012259556814,0.24196756831099345,-0.1570910736407538
493.2000000000063,54.68302998887107,0.2404419884345991,-0.15657817853808487
494.3000000000063,54.791067481401825,0.24326954615056862,-0.1557698050098688
495.40000000000634,54.89856992929856,0.2433228101585288,-0.15576980500000293
496.5000000000063,55.00672067526136,0.2439089316668531,-0.15576980452881317
497.60000000000633,55.116002470877845,0.24443086513722143,-0.15444962121170658
498.70000000000636,55.22397030757059,0.2425879982722539,-0.15576988713060258
499.8000000000064,55.33240281514384,0.24261328610246524,-0.15576989707902644
500.9000000000064,55.44019487655309,0.24625351071257817,-0.15575859781943846
502.0000000000064,55.54860650553765,0.24294820951926605,-0.1557740174622948
503.10000000000645,55.65635170820832,0.24621066512629877,-0.15708820265284995
504.2000000000064,55.764755514858976,0.24652596782515573,-0.15845833458687242
505.30000000000643,55.87348818391195,0.24583259341031652,-0.15743353417207961
506.40000000000646,55.98142960229339,0.24464821948570353,-0.15875041816231006
507.5000000000065,56.0905778861884,0.2489117469385523,-0.15840989847664977
508.6000000000065,56.19843997602818,0.2472314674506857,-0.15709001942081224
509.7000000000065,56.30740033025752,0.24814896994786967,-0.1570996366355666
510.80000000000655,56.416063062164206,0.2474793469709764,-0.15710006624509942
511.90000000000657,56.52500459229112,0.24881562883342634,-0.1584096758445277
513.0000000000066,56.634384457058445,0.24681856316011533,-0.15709691800150338
514.1000000000065,56.74203973264916,0.24773470879279882,-0.15716029741155868
515.2000000000066,56.85100995135089,0.24771799828116361,-0.1584672010616881
516.3000000000065,56.959137240987545,0.2490996261237131,-0.15841420405708506
517.4000000000067,57.06625703782441,0.24898732720748926,-0.15840948810670064
518.5000000000066,57.1732641867012,0.24974736717290974,-0.1570576009387703
519.6000000000067,57.28364204246895,0.24835114602019143,-0.1583103549510807
520.7000000000066,57.392543299700044,0.24732983928268903,-0.158277954272656
521.8000000000067,57.500737850758924,0.2485785516160977,-0.15841009461919375
522.9000000000067,57.60990077317244,0.2465636313913014,-0.15971978824503763
524.0000000000067,57.71827641150924,0.2500094896759463,-0.15973038690571428
525.1000000000067,57.82662536580029,0.24970661184202803,-0.15972981732233915
526.2000000000068,57.93606668455959,0.2514930123205812,-0.15835268637197553
527.3000000000068,58.04472466683419,0.2518341645298379,-0.15840981602769766
528.4000000000068,58.15426904578826,0.250013976221069,-0.15840972108667417
529.5000000000068,58.26173787827815,0.2516168835383007,-0.15709151118598452
530.6000000000068,58.37152548906334,0.2525066918490286,-0.15712293124177767
531.7000000000069,58.48103419630247,0.25186481188341536,-0.15915274063037277
532.8000000000068,58.58912739283169,0.25320616696144477,-0.15972990792543662
533.9000000000069,58.69936913991112,0.2521445379010215,-0.15972992732133262
535.0000000000068,58.80791581038214,0.2526413040839126,-0.1584061452396468
536.100000000007,58.91496161305311,0.2503914626087674,-0.15972992822973842
537.2000000000069,59.02444860076662,0.2508147759848762,-0.15929105196699034
538.300000000007,59.13445006328943,0.2514730444168693,-0.1577499081595204
539.4000000000069,59.24283166098595,0.24752155224252953,-0.15768017527888656
540.5000000000069,59.35177542979803,0.249806591359166,-0.1604899681998062
541.600000000007,59.460002108601444,0.250724777249037,-0.15950977797371824
542.700000000007,59.569698062984166,0.24936603374628763,-0.16065653583981465
543.800000000007,59.678447334846254,0.2496103361653489,-0.16082987439729246
544.900000000007,59.78674752027115,0.24944655945786828,-0.16016578002393533
546.000000000007,59.893630389557835,0.250059864960676,-0.161767493768477
547.1000000000071,60.00430073082898,0.24932378548231504,-0.16280005515267915
548.2000000000071,60.113992229837216,0.24842411999176403,-0.16102235280530008
549.300000000007,60.22092925572634,0.24952496281540407,-0.16081990789502587
550.4000000000071,60.33116816128158,0.251619881430846,-0.16214027059436953
551.500000000007,60.44072731843431,0.24833566161225964,-0.16180773670685866
552.6000000000072,60.54904818521659,0.24782091259173838,-0.1604504257165753
553.7000000000071,60.65800542226369,0.24979544720483504,-0.16182017107437296
554.8000000000072,60.76731013602604,0.24846195602739177,-0.16182017099969492
555.9000000000071,60.8759747748757,0.24745735151813325,-0.16182080730025028
557.0000000000072,60.98415273728234,0.24912300258122966,-0.16214456099029917
558.1000000000072,61.093544542896936,0.24971122531777312,-0.16213984156574446
559.2000000000072,61.2027505560021,0.2489401859213092,-0.16213983442005286
560.3000000000072,61.31102909877776,0.2519085241615958,-0.16310371358715026
561.4000000000073,61.42088358085988,0.24934402991611299,-0.16312983701298567
562.5000000000073,61.52757357742908,0.24831288706739355,-0.16312983699999872
563.6000000000073,61.63952387130238,0.25062072598993823,-0.16312983699828632
564.7000000000073,61.746446097739,0.2509610965104295,-0.16314604757756523
565.8000000000073,61.85772719721599,0.250929046343749,-0.16444992682987358
566.9000000000074,61.966805825700376,0.2499966105555522,-0.16445046185242163
568.0000000000074,62.077122546820654,0.24996012491655917,-0.16444979021088457
569.1000000000074,62.18593177213686,0.24881085737495523,-0.1644480328019844
570.2000000000073,62.29495522017203,0.2529694233477448,-0.16315463086252535
571.3000000000073,62.40393149901603,0.25052300209547235,-0.1644518909121624
572.4000000000074,62.513945080488185,0.25153873981003266,-0.1644835273765617
573.5000000000074,62.62337350798457,0.2519797910447701,-0.1644501129877245
574.6000000000074,62.7331923394627,0.2528003801570643,-0.16445007362923603
575.7000000000074,62.842484804665496,0.2550435464706895,-0.1657703999703637
576.8000000000075,62.9504696911297,0.25447822558630273,-0.16444995332915502
577.9000000000075,63.061277620205225,0.255267674590887,-0.16444925367607865
579.0000000000075,63.17050822937314,0.25716009037611454,-0.16444016679076023
580.1000000000075,63.28128205526916,0.25829085674387614,-0.16444017050382476
581.2000000000075,63.39050643903202,0.2574542944564348,-0.16575990966813503
582.3000000000076,63.500702543279274,0.25745110597630816,-0.16444020617719612
583.4000000000076,63.60980436305817,0.2564175786952562,-0.16444017997128002
584.5000000000076,63.71880930007565,0.2586331182220108,-0.1644920210887708
585.6000000000076,63.82894034511059,0.25691407651045195,-0.16346101131248458
586.7000000000077,63.93838417736418,0.26005986076407933,-0.16608993665772998
587.8000000000077,64.04777578943487,0.26009896536244037,-0.1674101730698867
588.9000000000076,64.15646653666832,0.26128361392485255,-0.16613030933564632
590.0000000000076,64.26539733026365,0.25990918162404414,-0.16509540478242268
591.1000000000076,64.37395886203299,0.26348917724470566,-0.16532555042867658
592.2000000000077,64.48341132948877,0.2622861939613867,-0.16623975934084223
593.3000000000077,64.5932742586745,0.2632612030561565,-0.16577003097883303
594.4000000000077,64.70108855101063,0.262708235090955,-0.16708328741695677
595.5000000000077,64.8100000000008,0.2586650693755864,-0.16840019099999148
596.6000000000078,64.91904949835859,0.259355230941125,-0.17063175435062305
597.7000000000078,65.02978729759332,0.256174486618259,-0.17005108574221106
598.8000000000078,65.13898513620649,0.25239874975100685,-0.16862002291813205
599.9000000000078,65.24908567603815,0.25122121070923337,-0.1686210660632459
601.0000000000078,65.3572474899485,0.2474807973853814,-0.16829362286322436
602.1000000000079,65.46590515312226,0.2447091214078136,-0.16729991025033364
603.2000000000079,65.57531348250082,0.24238428435790021,-0.16720306971749999
604.3000000000079,65.6862269607554,0.24152876212966523,-0.16861630287967477
605.4000000000078,65.79552564548318,0.24230354366184287,-0.17227894593719295
606.5000000000078,65.90514581078229,0.24313995400972552,-0.17224016138949594
607.6000000000079,66.01462317070646,0.24050378378044518,-0.1709193719615243
608.7000000000079,66.12388914569455,0.23736577042916396,-0.16903650903919942
609.8000000000079,66.23498192057794,0.23600102057804045,-0.16882500430617897
610.9000000000079,66.34398943664358,0.234313186705364,-0.1688401295672568
612.000000000008,66.4545895151083,0.23269908608245246,-0.16884111225928677
613.100000000008,66.5643823281887,0.233652938612177,-0.17144178610138816
614.200000000008,66.67375151241212,0.23321963583501618,-0.17015055933265533
615.300000000008,66.783725997091,0.23459942685738278,-0.17278948673522265
616.400000000008,66.89306350097827,0.23376512455632012,-0.1741091287505414
617.5000000000081,67.00365378041121,0.23232866562062704,-0.17344812948180666
618.6000000000081,67.11378819894047,0.23348369524303356,-0.17212992600119748
619.7000000000081,67.22233184178702,0.23392231489234167,-0.1721304026101116
620.8000000000081,67.33367094999721,0.23393887155867676,-0.1701575140068865
621.9000000000082,67.44278293358221,0.23358803832447167,-0.16883986009588403
623.0000000000082,67.55290352133545,0.2350787542183822,-0.17014633510254917
624.1000000000081,67.66300396067719,0.23358494741010002,-0.1704901207250593
625.2000000000081,67.77275428206691,0.23382179073580545,-0.1718305804875917
626.3000000000081,67.8813219026676,0.2323940079226904,-0.1741486656266411
627.4000000000082,67.99233993399994,0.2333357973945602,-0.1725268999178038
628.5000000000082,68.10188960198727,0.2309104752029373,-0.1714783043007868
629.6000000000082,68.21229562722245,0.23130610599483273,-0.17080999124392626
630.7000000000082,68.32235349359325,0.23269324460798183,-0.17346808012623294
631.8000000000083,68.43218772219916,0.23165228040037625,-0.17312004160501182
632.9000000000083,68.54121794340362,0.23327346561821746,-0.1744600276355448
634.0000000000083,68.6511520188002,0.23178990410644582,-0.17444233600891002
635.1000000000083,68.76120274313367,0.2315330659878766,-0.17322806139881441
636.2000000000083,68.87103201561439,0.23126160832738865,-0.17042780667248714
637.3000000000084,68.98134984802164,0.23160645656367734,-0.17301132283198406
638.4000000000084,69.08964093873195,0.23224220464985965,-0.1733108819330269
639.5000000000084,69.2004814119604,0.23072715993207119,-0.17300709597553388
640.6000000000083,69.3098992463243,0.23240921790303437,-0.171014865765847
641.7000000000083,69.41916465000665,0.23223797536790464,-0.17037022219028364
642.8000000000084,69.52937378809244,0.2347908941724862,-0.1717119227039854
643.9000000000084,69.63936067242949,0.233440565025125,-0.1720196931639193
645.0000000000084,69.74842612133634,0.23513136675173524,-0.17031082972581935
646.1000000000084,69.85888325169479,0.23501934903568744,-0.16813260283000142
647.2000000000085,69.96826089105672,0.23325153060840362,-0.1689895516112685
648.3000000000085,70.0783550141378,0.23041151983931266,-0.17169421520915717
649.4000000000085,70.18885625065676,0.23245290186626696,-0.17433008394120098
650.5000000000085,70.29846507829093,0.2330845013126773,-0.17301201565616253
651.6000000000085,70.40860066382247,0.23504135123623487,-0.1743299731367407
652.7000000000086,70.51849798808654,0.23555576075984022,-0.17433019667676097
653.8000000000086,70.62697701004704,0.2359339526029222,-0.17565016714118364
654.9000000000086,70.73636979121214,0.23234198379412743,-0.17521333904700498
656.0000000000086,70.84615832903691,0.23121031875436474,-0.17365853933893405
657.1000000000087,70.95636521137946,0.23075524022357663,-0.17367014217512944
658.2000000000087,71.06642156086987,0.22871458839258085,-0.1749902741195899
659.3000000000086,71.17619788773217,0.22828862602488492,-0.17366617061308043
660.4000000000086,71.28683870571312,0.2263026534578517,-0.17142141766282792
661.5000000000086,71.39603257120949,0.22453207279987245,-0.17103982417287256
662.6000000000087,71.50577888717399,0.22453313973958047,-0.17192425468869565
663.7000000000087,71.61621121098767,0.22542094074164182,-0.17306606239480793
664.8000000000087,71.72544489992816,0.22459148374700888,-0.1716780797458437
665.9000000000087,71.83637041759678,0.22498935633900846,-0.1736328119790964
667.0000000000088,71.94689184383441,0.22569300784140012,-0.17437480000247696
668.1000000000088,72.05632422230887,0.22868138941391933,-0.17519882431230238
669.2000000000088,72.1667142839514,0.2264723573222877,-0.1745501548604711
670.3000000000088,72.27440726262499,0.22528873668654856,-0.17466717505796403
671.4000000000088,72.3868262081997,0.22654750417562977,-0.17322457674778446
672.5000000000089,72.49768425429819,0.22650981784872048,-0.17596974110130503
673.6000000000089,72.6078215533146,0.22548542696589202,-0.17524628297571
674.7000000000089,72.71813921906934,0.2246400747159759,-0.17319928635963366
675.8000000000088,72.82709883763425,0.2297757220064621,-0.1739030422247292
676.9000000000088,72.93799046606475,0.22741394174168145,-0.17619993703156522
678.0000000000089,73.04768124877577,0.2291979500481415,-0.1762001886096365
679.1000000000089,73.15789084848767,0.23109151352272495,-0.17520982107102112
680.2000000000089,73.26837583602003,0.23181557059996974,-0.1752287680331044
681.3000000000089,73.37799211952765,0.23316472226803314,-0.17388985534771706
682.400000000009,73.48744917880076,0.23289031487918788,-0.17388982633424588
683.500000000009,73.59597672580685,0.2337682844338178,-0.17521012101609834
684.600000000009,73.7079041103891,0.2322069190520708,-0.1738899631662778
685.700000000009,73.81756621640201,0.2363616072136283,-0.17398173918284687
686.800000000009,73.92721496206332,0.23696293071193328,-0.17389155887260355
687.9000000000091,74.03862864608075,0.23903416511564252,-0.1748800157076209
689.0000000000091,74.14953530743104,0.23781379056277194,-0.1742207457721392
690.1000000000091,74.25853975384526,0.24381054449409412,-0.17421795650516403
691.2000000000091,74.36960410260932,0.2442884655038458,-0.17418698949040667
692.3000000000092,74.4800994537402,0.24713775737793786,-0.17620021851266632
693.4000000000092,74.58981383124382,0.25029998469793197,-0.1761959775367865
694.5000000000091,74.70000000000091,0.25215335631317937,-0.17619491497281503
695.6000000000091,74.80978956959864,0.25747153801618067,-0.1781701931313835
696.7000000000091,74.9186764898356,0.26089368810456315,-0.17684954611687953
697.8000000000092,75.03098989084171,0.2629982525049681,-0.1759488255640571
698.9000000000092,75.14031882298568,0.2658522304376007,-0.17553944761823592
700.0000000000092,75.2509364425399,0.2681932082939975,-0.1732295084165223
701.1000000000092,75.3620795051621,0.27504110756181,-0.1745501728406298
702.2000000000093,75.47165216358091,0.2768935688306863,-0.17215333131248345
703.3000000000093,75.5803501397731,0.28311794314686073,-0.17223699392022018
704.4000000000093,75.6932533121463,0.28903672928811963,-0.17485681794002872
705.5000000000093,75.80377523366407,0.28993793405645,-0.17718541359662998
706.6000000000093,75.91306992375593,0.29359283944359327,-0.1770817360543675
707.7000000000094,76.02154425049379,0.2964215691453198,-0.17549366414348322
708.8000000000094,76.13380662367724,0.29680944294248945,-0.17610104097289803
709.9000000000094,76.24473385248808,0.3025848874995811,-0.17487664548548576
711.0000000000093,76.35461166681199,0.302534138230273,-0.1748800094046432
712.1000000000093,76.46500858350039,0.300383796271422,-0.174879936200115
713.2000000000094,76.57570606897774,0.302855158785961,-0.17364731720084992
714.3000000000094,76.68552148621025,0.30473684877546375,-0.17487000244372375
715.4000000000094,76.79577460901115,0.30361790660569155,-0.17487000290863897
716.5000000000094,76.90602783924285,0.3024897703375289,-0.1749006336488801
717.6000000000095,77.0157582867126,0.30327911647315614,-0.17629785172375145
718.7000000000095,77.12679347274671,0.30088268272373986,-0.17753506780884143
719.8000000000095,77.23663319490504,0.30108328492310815,-0.17620486572122518
720.9000000000095,77.34774974970016,0.2981475259689751,-0.17490840182801293
722.0000000000095,77.45592875571651,0.2951713980830011,-0.17587020624089789
723.1000000000096,77.56765373037464,0.2952108880823304,-0.17587018699999346
724.2000000000096,77.67711114828529,0.2986501213068967,-0.1758701869999908
725.3000000000096,77.78828988402437,0.2951642099034281,-0.17587019896806844
726.4000000000096,77.8990433646232,0.29633467374113054,-0.1748806660664246
727.5000000000097,78.0084501423355,0.3024246141008975,-0.17553982313344196
728.6000000000097,78.11963105839074,0.3063026179564834,-0.1766799052546988
729.7000000000096,78.23063930263942,0.30891464103562766,-0.17783819346965624
730.8000000000096,78.34111453720986,0.3066610881823262,-0.1771799389585551
731.9000000000096,78.45071354456518,0.306988486323507,-0.17585981120528826
733.0000000000097,78.56236394586314,0.30778639853726486,-0.17685231352658448
734.1000000000097,78.67283863237198,0.3042839824176201,-0.17817004883992738
735.2000000000097,78.78401324047095,0.30803861731892246,-0.17817003699991707
736.3000000000097,78.89369569786652,0.3072468562245463,-0.17817017018302694
737.4000000000098,79.00501122728453,0.30995850957558774,-0.17817001001713972
738.5000000000098,79.1145109228804,0.31028105107445164,-0.1775233105978118
739.6000000000098,79.22450481949318,0.30848631076951805,-0.17686014021234797
740.7000000000098,79.33552219071343,0.3099544350253223,-0.17553895579356293
741.8000000000098,79.44457681282337,0.3094657398672132,-0.17548095227010885
742.9000000000099,79.55537962655568,0.30810626126450325,-0.17685019593512763
744.0000000000099,79.66857738783017,0.3080097017052131,-0.17685019600000107
745.1000000000099,79.77884495925899,0.30710858048921946,-0.17685019600000018
746.2000000000098,79.88943491668915,0.30477701930427337,-0.17685019600000107
747.0000000000099,79.97043465208084,0.30320127762078725,-0.17685019600000107