File: 01_Data/Mineral_Wool_Insulation/STA/N2/10K_min/Mineral_Wool_Insulation_STA_N2_10KData_221107_R1.csv
##Temp./Â°C,Time/min,DSC/(mW/mg),Mass loss/mg
51.0,10.73550843981569,0.0006367206205153408,-0.030695109910062968
52.100000000000016,11.122709865973395,0.030143985048457056,-0.0280228465904937
53.20000000000003,11.368618216403323,0.04361812716968472,-0.02958792441356284
54.30000000000005,11.57234178600993,0.05876443325068759,-0.03264752010310534
55.40000000000006,11.765577296693133,0.06743702286938547,-0.02807321124956008
56.50000000000008,11.936411292688087,0.07707243795724206,-0.027654483642843175
57.600000000000094,12.094147993656705,0.08022143486078503,-0.028856851927741012
58.70000000000011,12.253189723900043,0.08805027841295066,-0.029194166281409473
59.800000000000125,12.400359177458888,0.0912642183708594,-0.029172932585794342
60.90000000000014,12.54758650863938,0.09425826510377222,-0.02703181800194887
62.000000000000156,12.691896926363889,0.09955782366513333,-0.029442927886514703
63.10000000000017,12.830590525299616,0.10045227700124393,-0.03171696011456149
64.20000000000019,12.967095897716291,0.10676755049597264,-0.03213359310262209
65.30000000000021,13.103461946173134,0.1094806768176999,-0.031011991435723196
66.40000000000022,13.234883706814776,0.11368321557501848,-0.029237369471003305
67.50000000000023,13.366772882311285,0.11441075928210487,-0.030896508308261517
68.60000000000025,13.495617565647406,0.11899722896158416,-0.032249266308351565
69.70000000000027,13.62378924283961,0.12202998357681127,-0.03100663772989165
70.80000000000028,13.752486474724705,0.12379869684675571,-0.03241162180541757
71.90000000000029,13.876758138191423,0.12484436871204196,-0.03121854511780775
73.00000000000031,14.002120105644618,0.12783288160677198,-0.03307239978366461
74.10000000000034,14.124783648304252,0.13302203905499743,-0.03264217204177822
75.20000000000034,14.246467367067504,0.1357354973551017,-0.035060835263180934
76.30000000000035,14.368489224000957,0.13626634716887986,-0.03498075697380898
77.40000000000038,14.488217564986309,0.13751729982663918,-0.03495279328961676
78.5000000000004,14.60938627576566,0.14001184591839455,-0.03515810263452579
79.6000000000004,14.727518259933209,0.14339689964166502,-0.03524813972029062
80.70000000000041,14.846027548289825,0.14512591349441073,-0.0351429308167468
81.80000000000044,14.962503047706162,0.14643719063518001,-0.03514021481306617
82.90000000000046,15.08041964574961,0.14827985215141903,-0.03638553762541452
84.00000000000047,15.19625318359447,0.15008912907526883,-0.035140793252718794
85.10000000000048,15.312380097930362,0.15112231399461495,-0.03545372575120176
86.2000000000005,15.427028822551357,0.151211223959415,-0.03642131585181918
87.30000000000052,15.540536909851664,0.153502275004326,-0.03693683273034587
88.40000000000053,15.65439431580861,0.1535677729500815,-0.03645304664095317
89.50000000000054,15.769170000000061,0.1539174368628522,-0.037768033371941456
90.60000000000056,15.881360740184917,0.1553151767419666,-0.038181246207662944
91.70000000000059,15.993640496884288,0.1572270221864791,-0.03908994173973568
92.8000000000006,16.103446189220936,0.15752970164901214,-0.039091064468443015
93.9000000000006,16.21673729994004,0.1560388109734504,-0.0391218949219887
95.00000000000063,16.327836544139593,0.1560913856246433,-0.03908269388132357
96.10000000000065,16.437407327319804,0.15650080321181292,-0.04040157410723655
97.20000000000066,16.549651027498072,0.16046547070717188,-0.041743589117975155
98.30000000000067,16.658800987612494,0.15900984152768538,-0.04094151587621386
99.40000000000069,16.76810109282173,0.15777079108049652,-0.043045041458393385
100.50000000000071,16.877379180203697,0.16003062442805238,-0.0430446934301596
101.60000000000072,16.987138173972564,0.16034367382202497,-0.04271477768014709
102.70000000000073,17.09467651038504,0.15986755477679437,-0.04433851966408309
103.80000000000075,17.20357139468052,0.1615237103308036,-0.04302953692733169
104.90000000000077,17.308391295681943,0.16047978357707782,-0.044137598613944284
106.00000000000078,17.41979108600545,0.16280808726210405,-0.044363114446421825
107.10000000000079,17.529813076060535,0.16046693193381667,-0.044355874452532085
108.20000000000081,17.6352282146226,0.16146734745955815,-0.04435895786681332
109.30000000000084,17.745435373493997,0.16140538386746917,-0.04695536667037281
110.40000000000084,17.85099618559624,0.16196664250339743,-0.045678686784017764
111.50000000000085,17.959170000000086,0.160648024487983,-0.046259402439093655
112.60000000000088,18.066894194468823,0.15937621021824977,-0.046988413570639764
113.7000000000009,18.174289035627773,0.15971095249068523,-0.047077492028308576
114.8000000000009,18.281427067887204,0.15946044056166342,-0.04688914789826004
115.90000000000092,18.38868705750848,0.16069972683139333,-0.04829851241509253
117.00000000000094,18.496146130193573,0.15968586044479227,-0.04831005110558184
118.10000000000096,18.60409974158889,0.16051217251402372,-0.048306942107663176
119.20000000000097,18.71087851648378,0.15977855242202588,-0.049630553510700004
120.30000000000098,18.818617602036856,0.1587088690178795,-0.049343900666615426
121.400000000001,18.925181729714186,0.1584830374495565,-0.04956743223614346
122.50000000000102,19.03181894368867,0.15775938587068172,-0.04963157571228827
123.60000000000103,19.13877271973442,0.15772139875523383,-0.050949778394906
124.70000000000104,19.245291380329075,0.15714747057738943,-0.04998992502143729
125.80000000000106,19.35153571792737,0.15752926785839783,-0.04962995709068707
126.90000000000109,19.459170000000107,0.15642585781223894,-0.05094740631542205
128.00000000000108,19.565521047823765,0.15567259030690006,-0.05093939821455784
129.1000000000011,19.670703371145827,0.15714079342359888,-0.05219727818225284
130.20000000000113,19.778591164595554,0.15438519763071534,-0.05093998570599556
131.30000000000115,19.883478978625565,0.15380907616205342,-0.05130358132215829
132.40000000000117,19.990719395047037,0.15183003724855737,-0.05227530830381166
133.50000000000117,20.09616769959786,0.15112024390461154,-0.053473281900557446
134.6000000000012,20.200869059740327,0.15163078491736193,-0.05358246768511066
135.7000000000012,20.306875230247208,0.14983177987044183,-0.0542399596217793
136.8000000000012,20.412053254830756,0.15200038577478425,-0.05488272004961381
137.90000000000123,20.518775717736904,0.1495426402146781,-0.056219728405968006
139.00000000000125,20.624092342928957,0.1496561570685191,-0.05490380225184044
140.10000000000127,20.729669478636747,0.14939015083751783,-0.053583617533671024
141.2000000000013,20.83469291364279,0.14542190734666838,-0.05358015147321016
142.3000000000013,20.939940704196097,0.14608490639887162,-0.05488514726364535
143.4000000000013,21.04469846418753,0.14595926024740602,-0.05526415390112582
144.50000000000134,21.14836580502673,0.14503592864091353,-0.05495208249545769
145.60000000000133,21.253301712533965,0.1448582600816949,-0.055617794908945584
146.70000000000135,21.357947117492344,0.14452156913399383,-0.056224029058199676
147.80000000000138,21.463307751187113,0.14473747530617476,-0.056534961919912696
148.9000000000014,21.568709985449185,0.14445142881828488,-0.05654009215359679
150.00000000000142,21.672813312468595,0.1432894407314801,-0.057853180208812915
151.10000000000142,21.778251880919516,0.1429339416124208,-0.058160823249663096
152.20000000000144,21.882787694253867,0.14399134017387227,-0.05949889880962811
153.30000000000146,21.98730150790084,0.14018114723077424,-0.059848030978504774
154.40000000000146,22.091943211222947,0.14135516989520291,-0.059203891542628284
155.50000000000148,22.196645769009187,0.1409329480834851,-0.05883716696674224
156.6000000000015,22.299989454613023,0.1391680071230036,-0.0588430372363824
157.70000000000152,22.404894087400983,0.13567709638640468,-0.06023334447070994
158.80000000000155,22.510938218678923,0.13655993410218448,-0.06015621797396786
159.90000000000154,22.614513905696864,0.1354606072697241,-0.06015997199244261
161.00000000000156,22.719170000000137,0.13640752252262378,-0.060159971999756756
162.1000000000016,22.823142683782834,0.13417314368774702,-0.059731719626967994
163.20000000000158,22.92805561397224,0.1333841686436723,-0.06047908065993646
164.3000000000016,23.032385954339773,0.13396247331796918,-0.06021126985072911
165.40000000000163,23.1366381701233,0.13142166475115435,-0.06012635681930334
166.50000000000165,23.241547806180385,0.13200005251748326,-0.061270070463908866
167.60000000000167,23.34651086879636,0.1324526781690485,-0.06257202037871856
168.70000000000167,23.449480095657112,0.13035451538125586,-0.06157308746564194
169.8000000000017,23.556449662957405,0.131061073039893,-0.06260911372721623
170.9000000000017,23.661117107454913,0.13107257786435256,-0.062250010593245086
172.0000000000017,23.765310416603477,0.13149403687525152,-0.062267282196721396
173.10000000000173,23.869074295812997,0.13058737473882964,-0.062250197035438326
174.20000000000175,23.975060301681502,0.13250334170217426,-0.06357624935108142
175.30000000000177,24.078909348010836,0.13214822664963644,-0.062249828829335385
176.4000000000018,24.184063650098427,0.13084435485252977,-0.06383179430354602
177.5000000000018,24.288261789481894,0.12955110866595954,-0.06454982405233611
178.6000000000018,24.392251527708257,0.12767342335495446,-0.06360278465884406
179.70000000000184,24.497312608481934,0.12856568386396527,-0.06356591832748659
180.80000000000183,24.601609492481632,0.1282973565679919,-0.06455864970703029
181.90000000000185,24.704409342440776,0.12784769148443398,-0.06456740556341956
183.00000000000188,24.80993402821653,0.12618322483259925,-0.06456020101682203
184.1000000000019,24.913609284630297,0.12614701670609052,-0.06453863162396356
185.20000000000192,25.01867423459773,0.12829130915895115,-0.06619941003528762
186.30000000000192,25.1205703869268,0.12659523834714148,-0.06718970075098696
187.40000000000194,25.226106096851098,0.12611192450169084,-0.06587045822764015
188.50000000000196,25.330939361155057,0.12725665489937288,-0.06630786014959256
189.60000000000196,25.43488783314475,0.12778837494764106,-0.06622500861685232
190.70000000000198,25.53662165702544,0.12639568419521385,-0.06752455094485477
191.800000000002,25.64299614862696,0.12612453454126882,-0.06751999199722825
192.90000000000202,25.746511524824307,0.1251187170644409,-0.0675200093848689
194.00000000000205,25.850896948336814,0.12425709804402141,-0.06620735308049053
195.10000000000204,25.95487744696208,0.12366734591822803,-0.06744201673562689
196.20000000000206,26.059170000000194,0.12348403143109588,-0.0675198162844719
197.3000000000021,26.163184878890537,0.12493437862661039,-0.06752019387367536
198.40000000000208,26.267745854841202,0.12512308215285095,-0.0675197332721158
199.5000000000021,26.370827842568957,0.12461472028252618,-0.06883993824322499
200.60000000000213,26.475922007677884,0.12279749086385361,-0.06883995790484754
201.70000000000215,26.57694442974748,0.12230958529966074,-0.06880028524797765
202.80000000000217,26.68379588193998,0.12293088807993324,-0.07015586737455992
203.90000000000217,26.787539906933063,0.12313574423587625,-0.06884004606457683
205.0000000000022,26.89191049564655,0.12218868916418413,-0.06788937827249164
206.1000000000022,26.99575791435734,0.11951591521398774,-0.06782370570354068
207.2000000000022,27.100688439005367,0.12332116726957432,-0.06884004070693717
208.30000000000223,27.20463130820109,0.12037102619373419,-0.06982982132208093
209.40000000000225,27.30835622416483,0.12213858492488583,-0.06983590198424405
210.50000000000227,27.41233720749607,0.12166672038699011,-0.0688489960145322
211.6000000000023,27.516579963547088,0.11943638458699468,-0.07016430656765715
212.7000000000023,27.620524355781228,0.12058283200441333,-0.06883681566112632
213.8000000000023,27.72435204746903,0.12021730272166253,-0.06884012198989087
214.90000000000234,27.828310060229825,0.11980714419640892,-0.06884012199999923
216.00000000000233,27.931724349873893,0.1214951253987806,-0.06884012037027176
217.10000000000235,28.036803481886242,0.11767303994406442,-0.07015285035620611
218.20000000000238,28.141626660499817,0.11695594073629623,-0.07032116793861576
219.3000000000024,28.245693351882522,0.11575029518609858,-0.0701780962130596
220.40000000000242,28.349568319147608,0.11632690418256997,-0.07016008703237375
221.50000000000242,28.454209518553544,0.11497817217835327,-0.07146218816821426
222.60000000000244,28.558562662003787,0.11550169439232405,-0.07148008799998795
223.70000000000246,28.66332086703296,0.11390762288009326,-0.07147985323776807
224.80000000000246,28.766868559428357,0.11461386677168617,-0.07410978114714695
225.90000000000248,28.87116612080412,0.11440744017526061,-0.07396022480992315
227.0000000000025,28.974451219997125,0.11551767375171884,-0.07411008709516276
228.10000000000252,29.07998309330859,0.1133673455783295,-0.07378766970181871
229.20000000000255,29.1848695427676,0.11180700130864063,-0.07378008797400071
230.30000000000254,29.288890203690528,0.11225685915955597,-0.07377619681503944
231.40000000000256,29.391685168570124,0.11012994551189681,-0.07245299916401127
232.5000000000026,29.49850478532263,0.1102247336377653,-0.07378018643333162
233.60000000000258,29.60201946742826,0.10943837100706244,-0.07377993470487265
234.7000000000026,29.707543912235327,0.10904559326818974,-0.0751004453490296
235.80000000000263,29.810520274234364,0.10736355189472957,-0.07377604131659332
236.90000000000265,29.915739287381484,0.10582016929006133,-0.07377983600018334
238.00000000000267,30.021029807774077,0.10376007745709548,-0.0747700506082678
239.10000000000267,30.12538121128494,0.10513276245250747,-0.07582674368603382
240.2000000000027,30.229639580671485,0.10348685798901947,-0.07574959704743867
241.3000000000027,30.334606651113184,0.10344323955940726,-0.07475968703828606
242.4000000000027,30.439471158906866,0.10272297608852854,-0.07602374255712574
243.50000000000273,30.54391045766291,0.10175425596571985,-0.07596325366244905
244.60000000000275,30.647531372773056,0.1027725935739916,-0.07607990094762362
245.70000000000277,30.75178919813711,0.10285357251869598,-0.07606627312043646
246.8000000000028,30.856810763369676,0.10039483629980339,-0.07347183103280752
247.9000000000028,30.96041370668747,0.09956039827497953,-0.07475505705481744
249.0000000000028,31.06597307334316,0.09884246985148659,-0.07543312685426073
250.10000000000284,31.17071627906488,0.09733587611463812,-0.07674990783301938
251.20000000000283,31.275247777063697,0.0968718966389529,-0.07679334945781102
252.30000000000285,31.380466247669457,0.09881151905165231,-0.07674001585820545
253.40000000000288,31.482341841338847,0.09757215082981041,-0.07805800285310216
254.5000000000029,31.588879043201768,0.09722682694775964,-0.07806002099940956
255.60000000000292,31.693919594091504,0.0963238467304649,-0.07806002100000065
256.7000000000029,31.79897334327898,0.09441234844260382,-0.0780600210000002
257.8000000000029,31.90304523336271,0.09410598706594386,-0.07806002065344675
258.90000000000293,32.007775845569,0.0948429394749224,-0.07916434937061334
260.00000000000296,32.113207020639095,0.09252547083348661,-0.082231800078723
261.100000000003,32.21759196057009,0.09308667414589711,-0.08089010278629427
262.200000000003,32.322236431749985,0.09331113599749252,-0.07817017231199408
263.300000000003,32.42660417598985,0.09226664178313093,-0.07817004118024418
264.40000000000305,32.5317844367687,0.08985919713051815,-0.07751543751006551
265.50000000000307,32.63606882566954,0.08860490280008582,-0.07616639392737667
266.6000000000031,32.740666972309754,0.08924699036746353,-0.07620849717034384
267.7000000000031,32.84593009812321,0.08925778113905236,-0.0788890555321502
268.8000000000031,32.95153296143707,0.08902738971474322,-0.08013738860768171
269.9000000000031,33.05583639551374,0.08987434089242602,-0.08043467420429584
271.0000000000031,33.16031259680583,0.0882345830023657,-0.08013996589883465
272.10000000000315,33.2662716718271,0.08729660952694618,-0.08013996599863571
273.2000000000032,33.36955292843485,0.08589912478127615,-0.08014014582804974
274.30000000000314,33.47565010792548,0.08540360756485904,-0.078816631034762
275.40000000000316,33.5794555575502,0.08558139708721585,-0.07948555819494896
276.5000000000032,33.68376257316689,0.08519779676778738,-0.08015007862348611
277.6000000000032,33.78884673352158,0.08449144855121593,-0.08015011619066348
278.70000000000323,33.89336596465068,0.08311304224734911,-0.08145851954681316
279.80000000000325,33.99881040216033,0.08425766181825423,-0.0814601749370798
280.9000000000033,34.104069915840114,0.08232361354429762,-0.07994521408835586
282.0000000000033,34.2081570946712,0.0801607947791731,-0.08146734248257204
283.1000000000033,34.313900662287644,0.08319595848320577,-0.08341835195713676
284.20000000000334,34.418533312903065,0.08176386024340226,-0.08212039720597364
285.30000000000337,34.523726571686325,0.07893857879857391,-0.08071792575358305
286.40000000000333,34.62944303185624,0.08050771695777259,-0.08213041307214519
287.50000000000335,34.73454232135785,0.07942183484476867,-0.08081049573175614
288.6000000000034,34.83901564771381,0.07958745204919537,-0.0801503684976792
289.7000000000034,34.94486448401384,0.07700034134033734,-0.08213577509634495
290.8000000000034,35.05021972232281,0.07454416336184255,-0.0821309241206225
291.9000000000034,35.15496640546396,0.07694660165873035,-0.08081007914746952
293.0000000000034,35.260527406877316,0.07497145416307227,-0.08079382370199095
294.10000000000343,35.36533096584692,0.0744670675925519,-0.08147018620962587
295.20000000000346,35.47054535570905,0.07412939564815263,-0.08147032592669312
296.3000000000035,35.57587564168497,0.07188999454120676,-0.08277859877261351
297.4000000000035,35.6816263808878,0.07268786173806807,-0.08277989361126492
298.5000000000035,35.78636770381456,0.07359096673122051,-0.0834959517896765
299.60000000000355,35.891309604770726,0.07457026074295109,-0.08476010987962379
300.70000000000357,35.996218029811864,0.07253130918239681,-0.08435069820846186
301.8000000000036,36.10261725568871,0.07424751075942698,-0.08472965540522948
302.9000000000036,36.20684721025213,0.07398886101457763,-0.08344008616306198
304.0000000000036,36.31247758382714,0.07439065969478903,-0.08343976396218
305.1000000000036,36.41824636322127,0.07576083661758493,-0.08409736208943253
306.2000000000036,36.522016728561454,0.07399750077739725,-0.08456546512989016
307.30000000000365,36.627868211718194,0.07388426644187968,-0.08542006586567785
308.4000000000037,36.73262559468345,0.07287638352561127,-0.08541998426203135
309.5000000000037,36.839170000000344,0.07192697079313998,-0.08561357188672991
310.60000000000366,36.94413937217791,0.07182162479657878,-0.08571888901413915
311.7000000000037,37.0498808921778,0.07471231764069985,-0.08509173280481619
312.8000000000037,37.15555531779335,0.07378913566620893,-0.08606822834067662
313.90000000000373,37.25978258028343,0.07488911112220492,-0.08606952216017216
315.00000000000375,37.36648560346069,0.07331492815919194,-0.0864060195105174
316.1000000000038,37.4701494883928,0.07332540000108928,-0.08508013955269123
317.2000000000038,37.57700927046123,0.07346483842858398,-0.08640000254510705
318.3000000000038,37.68293819023979,0.07263166409278338,-0.08639987689189432
319.40000000000384,37.7889785319509,0.07258102689469326,-0.08774542966995691
320.5000000000038,37.894065321224836,0.07207983800983397,-0.08771987694540107
321.60000000000383,37.999777569658,0.07392288076666381,-0.08771987699997297
322.70000000000385,38.106142011264595,0.0696350065876904,-0.08771994981300324
323.8000000000039,38.21020348814528,0.07156825649085186,-0.0890394777543051
324.9000000000039,38.317061534361805,0.06735350544078827,-0.08870976423265509
326.0000000000039,38.42407448111423,0.06738131852751267,-0.0887017403912651
327.10000000000394,38.52945579994739,0.06671973864225672,-0.08771988059328795
328.2000000000039,38.63562585870631,0.06501664776508082,-0.08771977275269771
329.30000000000393,38.742113198621624,0.06408382913433752,-0.0870636347806446
330.40000000000396,38.846680746301814,0.06340259032728673,-0.08640199151803474
331.500000000004,38.95387660991539,0.06363652203753056,-0.08770830370996086
332.600000000004,39.059081879312224,0.06090832408896546,-0.08871012830534308
333.700000000004,39.164364640296384,0.05905081277016472,-0.0887109745572805
334.80000000000405,39.27072744929322,0.061708761493797226,-0.08997136306290932
335.90000000000407,39.37771918158388,0.05822262437062092,-0.08744651601372766
337.0000000000041,39.48237980903186,0.05979496103427118,-0.08735821416776224
338.10000000000406,39.58898504828376,0.05779867422558155,-0.0873901281611249
339.2000000000041,39.69450785046078,0.05891360144594149,-0.08871758420697518
340.3000000000041,39.80090593180222,0.0583582586697865,-0.08871012999937689
341.4000000000041,39.907835313504265,0.058547744775007904,-0.08871013493948521
342.50000000000415,40.01300672352737,0.0574222215413413,-0.08975829298231064
343.6000000000042,40.120436639829364,0.056997614532186824,-0.09002013301353395
344.7000000000042,40.22542028974572,0.05342140504335824,-0.09002012555492511
345.80000000000416,40.33193791667345,0.053021027054750036,-0.08903668143090915
346.9000000000042,40.43835237788715,0.05324115962866549,-0.0887575808806429
348.0000000000042,40.54487661781755,0.05281554131606919,-0.08826915055944573
349.10000000000423,40.650754331349894,0.054074160790700265,-0.09034997542018264
350.20000000000425,40.75652746776177,0.05307456646682446,-0.09034980000022719
351.3000000000043,40.8634038484941,0.05141923593703063,-0.09034980000000026
352.4000000000043,40.969789021523496,0.05333219298767511,-0.0903498000000007
353.5000000000043,41.07599521554656,0.05129646919027292,-0.09034980025579031
354.60000000000434,41.17997168422217,0.05366371707409284,-0.09067516225593408
355.7000000000043,41.28813725205229,0.05349718732126513,-0.09199968722817387
356.80000000000433,41.39471115422185,0.05320855356206594,-0.0919997999998734
357.90000000000435,41.50095735704071,0.052415044204608074,-0.09199991439511379
359.0000000000044,41.606883710702945,0.05325919605768603,-0.09101012383803875
360.1000000000044,41.71313869770066,0.05303489944918416,-0.09099543519453102
361.2000000000044,41.81977629512782,0.0515914113559634,-0.09100372141159196
362.30000000000445,41.92675945129268,0.05107885210869756,-0.09364794979676105
363.4000000000044,42.03315459379927,0.05190245057108256,-0.09396799323513783
364.50000000000443,42.139785218377384,0.05075337102179511,-0.09300090072400469
365.60000000000446,42.24680704293225,0.05165805846306459,-0.09397890457342672
366.7000000000045,42.35336647732584,0.051153869417150055,-0.09299356646698254
367.8000000000045,42.45762909791854,0.0535329078769205,-0.09140599942531002
368.9000000000045,42.567049966948105,0.05026155766210727,-0.09269884860074828
370.00000000000455,42.673635432593365,0.05127892201412054,-0.09398031907009452
371.10000000000457,42.77966184190798,0.05136248370631674,-0.09398003099996144
372.2000000000046,42.886283574527376,0.05098208186198028,-0.09398003103486818
373.30000000000456,42.99289765503682,0.05048572239517651,-0.09397816282240212
374.4000000000046,43.09936936744061,0.05247371689913183,-0.09529712636648302
375.5000000000046,43.20657991787493,0.05136363500967156,-0.0966100432574164
376.6000000000046,43.3127762220137,0.0510926114900907,-0.09660622926974094
377.70000000000465,43.418958876331345,0.05125351595642935,-0.09529981378773256
378.8000000000047,43.52622441516248,0.050998677603544595,-0.09398013001042882
379.9000000000047,43.630478702308096,0.049426013655789136,-0.09428006386313648
381.00000000000466,43.738883527783955,0.05107031489931119,-0.09464009752138791
382.1000000000047,43.84493633542444,0.04993201951853116,-0.0953003456634165
383.2000000000047,43.95236286181659,0.0470823246290602,-0.09464430168039417
384.30000000000473,44.05889495413754,0.04899275299268013,-0.09332981669350282
385.40000000000475,44.16591003829807,0.04646549337307593,-0.09596541702343675
386.5000000000048,44.272618812786334,0.04648047784895515,-0.09578520757471054
387.6000000000048,44.38004008260616,0.046823658587932804,-0.09563401618216538
388.7000000000048,44.48750212007174,0.04543227460197791,-0.09563051490600882
389.80000000000484,44.594559671190076,0.04649034295843002,-0.09628981184225038
390.9000000000048,44.70158485514717,0.046745667664172375,-0.0933912769971661
392.00000000000483,44.80841977791843,0.04725195041505187,-0.09683965226542979
393.10000000000485,44.91442811901287,0.04742791043287781,-0.09703991085826136
394.2000000000049,45.02276329381451,0.04559592769103182,-0.09749064443746791
395.3000000000049,45.12955814247835,0.04676717549642345,-0.10019263505285458
396.4000000000049,45.23645543520533,0.04631169932750184,-0.09752396901995075
397.50000000000495,45.34353102112166,0.04642649339519789,-0.09749986599097094
398.6000000000049,45.45068378915928,0.04425408264386671,-0.09749986599996197
399.70000000000493,45.55772917562431,0.04300745544029794,-0.09750001109620365
400.80000000000496,45.66568577870726,0.04296227342965464,-0.09880974733615533
401.900000000005,45.77191741353527,0.04120778007984821,-0.09880982830444074
403.000000000005,45.879170000000485,0.03954272348721716,-0.09816008282518762
404.100000000005,45.986589357999456,0.0417216219922697,-0.10072273116070729
405.20000000000505,46.093817626923645,0.041435055047961133,-0.1007799991010585
406.30000000000507,46.200453018472466,0.04205954390494504,-0.10076350124487998
407.4000000000051,46.30767589696165,0.042966263050130515,-0.10060708772810933
408.50000000000506,46.41494355227782,0.04302909025554452,-0.10077863386868158
409.6000000000051,46.5222593456742,0.04251181562953088,-0.10177098209124091
410.7000000000051,46.627258764286076,0.04164091652727908,-0.1004598571048052
411.8000000000051,46.73689784121503,0.04197764656936215,-0.10045982299996314
412.90000000000515,46.84350052434443,0.04128750198436265,-0.10045982300000045
414.0000000000052,46.951051012684836,0.04230383679594962,-0.1004598230000262
415.1000000000052,47.05845763973446,0.04347007024018107,-0.10045970601524212
416.20000000000516,47.16572853438534,0.04157911912583456,-0.0994693264278026
417.3000000000052,47.27131917442427,0.0396777281575697,-0.10079647614680631
418.4000000000052,47.38003085678487,0.03918124832713743,-0.10078201682939625
419.50000000000523,47.48808377820524,0.03840921407008274,-0.1020998215980673
420.60000000000525,47.5955644361089,0.039886689859835234,-0.10121106659492574
421.7000000000053,47.70274078778032,0.039873118382183936,-0.10077982294317467
422.8000000000053,47.81013182800573,0.03716030054474834,-0.10077248977700393
423.9000000000053,47.91639546967317,0.03647255808560229,-0.10210032620739407
425.00000000000534,48.024886048261095,0.036857755926706925,-0.10242912861068953
426.1000000000053,48.132581820760585,0.03500369694850153,-0.10242989999996466
427.20000000000533,48.23974555696754,0.03237014904286589,-0.10242996140053284
428.30000000000535,48.34771895597013,0.028874951449853525,-0.10352423281049283
429.4000000000054,48.455173815665724,0.028755883248629488,-0.10299360482413311
430.5000000000054,48.56281253268608,0.025629772283111474,-0.10242983760227808
431.6000000000054,48.67090097664679,0.02674604307773687,-0.10373491902241572
432.70000000000545,48.777803519732075,0.024504559398602743,-0.1037498034495381
433.8000000000054,48.886076698769266,0.020661784798426952,-0.10242254423440356
434.90000000000543,48.99046267261732,0.021493096877237494,-0.10487098670465755
436.00000000000546,49.10063448378269,0.02249762043231257,-0.10507017294608723
437.1000000000055,49.20728612827838,0.022106573160313225,-0.1037829196165041
438.2000000000055,49.3151624268043,0.023123987963534876,-0.10473300114412298
439.3000000000055,49.42333587131811,0.02153982626281209,-0.10478333349147029
440.40000000000555,49.53070538740032,0.02190349220955906,-0.10374987731786645
441.50000000000557,49.63877458539723,0.023602110650265296,-0.10509750878202295
442.6000000000056,49.74569715838862,0.023886592816597996,-0.1050698784031634
443.70000000000556,49.85449989765084,0.023758151781347048,-0.10615320009822948
444.8000000000056,49.95955320177582,0.02280967023117858,-0.10506000794740489
445.9000000000056,50.06908490564763,0.02273228671768679,-0.10309992901400822
447.0000000000056,50.176600710712826,0.023674507163904124,-0.10312223386049757
448.10000000000565,50.28553354099684,0.022543370077821534,-0.10471561894572723
449.2000000000057,50.392794613888306,0.019996606037594344,-0.10577097903611143
450.3000000000057,50.5013799452113,0.01943309346691985,-0.10704013892100406
451.40000000000566,50.60758524323166,0.01863178910326535,-0.10653936284367527
452.5000000000057,50.71609409456296,0.019547139500130095,-0.10703958311818518
453.6000000000057,50.822584615581626,0.01892266875137283,-0.10604960915986572
454.70000000000573,50.93320374224424,0.018038031864431703,-0.106049835000118
455.80000000000575,51.040368014116304,0.019057429763358447,-0.10604983499999987
456.9000000000058,51.14846011678857,0.019880357756493716,-0.10604983512361565
458.0000000000058,51.25691201000727,0.02067980164799721,-0.1064060808606837
459.1000000000058,51.36475526965594,0.021182621352125564,-0.10737007134019017
460.20000000000584,51.472243812288106,0.02238026624545303,-0.10735910828984796
461.3000000000058,51.580815413701295,0.023701648420752286,-0.10670998757546224
462.40000000000583,51.6875257860815,0.021725332004273068,-0.10670998917857721
463.50000000000585,51.79517110692684,0.018866615423378252,-0.1070678148636297
464.6000000000059,51.90371559232132,0.024520338332084557,-0.10704018220777334
465.7000000000059,52.01156944181996,0.02097028545361934,-0.10674963003394122
466.8000000000059,52.11956291612174,0.018914500048429206,-0.10671945959565887
467.90000000000595,52.22756733755955,0.01550133452793695,-0.10769973639524322
469.0000000000059,52.33539987542813,0.01657757887024247,-0.10769989000007296
470.10000000000593,52.44388602376625,0.01905354172269702,-0.10769988999999969
471.20000000000596,52.55181356182827,0.01798307628787832,-0.10769988999999924
472.300000000006,52.66050074711278,0.016072620627738843,-0.10769988906587802
473.400000000006,52.76857582599377,0.0163058965679046,-0.10801795696252858
474.500000000006,52.874443452571995,0.016438214549686136,-0.10934997431664417
475.60000000000605,52.98390032523276,0.01579360046065198,-0.10863134798824703
476.70000000000607,53.09171252013549,0.013677527494092234,-0.11065596751784357
477.8000000000061,53.20137647605872,0.016977536334642107,-0.10802999832683335
478.90000000000606,53.30830145469912,0.014374312293038538,-0.10804165401084553
480.0000000000061,53.41675983511051,0.016677818625296603,-0.10935020937789641
481.1000000000061,53.525352330410726,0.013586218633646174,-0.10902032213434909
482.2000000000061,53.63310315420911,0.015718935045975324,-0.10901755789553302
483.30000000000615,53.74122803010393,0.015632434064399847,-0.1103270412558155
484.4000000000062,53.84886473543044,0.016823725413991797,-0.11032984699968607
485.5000000000062,53.95754151999602,0.0168872277928509,-0.11032984708906968
486.60000000000616,54.065292179965546,0.01639003585132498,-0.1101997591061501
487.7000000000062,54.174151908130455,0.017770361857558925,-0.10903492678011917
488.8000000000062,54.28334462168186,0.01563510057965467,-0.11098999908416651
489.90000000000623,54.38892645302657,0.015441119735084718,-0.11099000099999934
491.00000000000625,54.49926068892966,0.01655216893898634,-0.11099000095510547
492.1000000000063,54.60774024678992,0.015375197239234084,-0.11025395821744777
493.2000000000063,54.7149699517691,0.014892806714123324,-0.10968000085881435
494.3000000000063,54.82376621096157,0.014246338794783653,-0.10967795267266034
495.40000000000634,54.93263178409335,0.014957513484522816,-0.11034026743023695
496.5000000000063,55.04091459542817,0.012472683258519551,-0.1116600188532697
497.60000000000633,55.14906822794576,0.014141150951927695,-0.111660056098136
498.70000000000636,55.25727011255008,0.01147585167152207,-0.11236445862310607
499.8000000000064,55.36438464165913,0.010772314483329076,-0.11264086894697423
500.9000000000064,55.47351052745576,0.007596756978829888,-0.11001338258134563
502.0000000000064,55.58243070493444,0.008737591030715336,-0.11133004713297101
503.10000000000645,55.69038668598916,0.006543056600310765,-0.11132967175369535
504.2000000000064,55.798273146751846,0.005142483638821943,-0.1119828830071321
505.30000000000643,55.90764982902632,0.006145865930391015,-0.11099983209930997
506.40000000000646,56.01669870613123,0.0041941731907418345,-0.11199075227815891
507.5000000000065,56.12507030813919,0.003988135941098592,-0.11198745942024324
508.6000000000065,56.232641734358886,-0.0014136020019299145,-0.11231979935894998
509.7000000000065,56.34197907669042,-0.0003504842209237913,-0.11231970320396822
510.80000000000655,56.45017191235135,-6.865172107239914e-05,-0.11264985845518538
511.90000000000657,56.558410829594195,-0.0009199909800148287,-0.11264987999999043
513.0000000000066,56.66735210928584,-0.0004025062350518638,-0.11264987999999843
514.1000000000065,56.775481331818796,-0.0021070036690282457,-0.1126498860137608
515.2000000000066,56.88314829799071,-0.0014099778926909834,-0.11362587675614177
516.3000000000065,56.99178789831233,-0.0034825879514997216,-0.11362994680794225
517.4000000000067,57.10156858676894,-0.0029464496840694576,-0.11263121548572785
518.5000000000066,57.211030014538935,-0.0029730574952154254,-0.11133064268139714
519.6000000000067,57.31927616436999,-0.005389498107647883,-0.11309283933993264
520.7000000000066,57.427647488340135,-0.003102988042025162,-0.11397124538995973
521.8000000000067,57.535064404383085,-0.0019401126398507218,-0.11396008986104178
522.9000000000067,57.64558560176079,-0.005502461085162308,-0.11431571092429182
524.0000000000067,57.75387398603892,-0.0036834003559143014,-0.11527999079383466
525.1000000000067,57.862417204459035,-0.007517865686320596,-0.11527999099999864
526.2000000000068,57.97188095279034,-0.006924852096634709,-0.1152799909999982
527.3000000000068,58.08096058473199,-0.007369539128253055,-0.11528002198634102
528.4000000000068,58.189070933054104,-0.007627685193352274,-0.11528019245360355
529.5000000000068,58.29927529939422,-0.008811115214453491,-0.11527989200042033
530.6000000000068,58.4074988401545,-0.009787111003297266,-0.115293893777769
531.7000000000069,58.515847569681505,-0.011235573010826783,-0.11759741541722413
532.8000000000068,58.625086905124014,-0.01028902910590887,-0.1162712622605846
533.9000000000069,58.73358833946064,-0.012368370255167682,-0.11527739681168381
535.0000000000068,58.84358882215896,-0.013339646830480917,-0.11528067755447768
536.100000000007,58.95197106313791,-0.011156438023074894,-0.11561026153762288
537.2000000000069,59.06141274819556,-0.01186110937896201,-0.11791380071054292
538.300000000007,59.16968398596423,-0.011404585309647497,-0.1166158800841588
539.4000000000069,59.2786732415429,-0.009135296931597564,-0.11692117420462234
540.5000000000069,59.387600548589575,-0.012050965576498873,-0.11889981964171792
541.600000000007,59.49670650622843,-0.013120588942755612,-0.11750585202331765
542.700000000007,59.6056151772479,-0.011065495982301832,-0.11758106977147076
543.800000000007,59.714630022080115,-0.012444177538820156,-0.11890016172328899
544.900000000007,59.82358942526465,-0.01314889550963641,-0.11889641064616407
546.000000000007,59.93237301453277,-0.014354922572524909,-0.11855754143725417
547.1000000000071,60.04100184392306,-0.013902427777006537,-0.11712019966749887
548.2000000000071,60.148981922053935,-0.014435899950970832,-0.11747030232025324
549.300000000007,60.25661038959353,-0.013794600662987822,-0.11879016352488403
550.4000000000071,60.367785520303904,-0.014943597196827418,-0.1187901680000003
551.500000000007,60.47619764898331,-0.01580379503820009,-0.11879016797121222
552.6000000000072,60.585451787077005,-0.014255613871934053,-0.11828159448310949
553.7000000000071,60.69510110470862,-0.017458993840589992,-0.11779955712019907
554.8000000000072,60.80424447877242,-0.01692940405487381,-0.12010901004003571
555.9000000000071,60.91308984432199,-0.018121067284737363,-0.11878732337194009
557.0000000000072,61.02236998890466,-0.017580821810570163,-0.1196298211473712
558.1000000000072,61.13094010542336,-0.017952714734179975,-0.11878445434140739
559.2000000000072,61.24020518651385,-0.017591244703269837,-0.12010172462176838
560.3000000000072,61.34935984412079,-0.017803254615815445,-0.12010020199810967
561.4000000000073,61.45887866123279,-0.018992446078229197,-0.12010020234372121
562.5000000000073,61.56784166768266,-0.017173592945996657,-0.12141959724445073
563.6000000000073,61.67628901582815,-0.018468462746692837,-0.12142010300060768
564.7000000000073,61.78585051333234,-0.01689072746503431,-0.12142010299808748
565.8000000000073,61.89467907082982,-0.01900445810870699,-0.12142577936452792
566.9000000000074,62.00348958530236,-0.01898527829359939,-0.1211269988968775
568.0000000000074,62.11231285589026,-0.017570798443354463,-0.1214297953344512
569.1000000000074,62.22148641296621,-0.01824308921679177,-0.12241989562298361
570.2000000000073,62.33114272622804,-0.01946234603723275,-0.12164513324353532
571.3000000000073,62.439689835001076,-0.02012616530008239,-0.12144632576406522
572.4000000000074,62.54818449706997,-0.020806471854162525,-0.12340168413293284
573.5000000000074,62.657408864358274,-0.020086880621281347,-0.12339173979105533
574.6000000000074,62.768976860631085,-0.019460217631783336,-0.12274990253729001
575.7000000000074,62.87840100149663,-0.022862518622238426,-0.12406039063884933
576.8000000000075,62.987824641596156,-0.024914213648889988,-0.12143177357521306
577.9000000000075,63.09659427413828,-0.023411337355912012,-0.12406004509154345
579.0000000000075,63.206578998184206,-0.022980336868291318,-0.12406003358305062
580.1000000000075,63.31422726672401,-0.02180384471900361,-0.12508704897032796
581.2000000000075,63.42523922022599,-0.022994017435410533,-0.12297534772698304
582.3000000000076,63.53409100261772,-0.022601950858963327,-0.12465251522602827
583.4000000000076,63.64377770121774,-0.021089222825892887,-0.1257100527842523
584.5000000000076,63.753291159843975,-0.020611544261104675,-0.12522357979232845
585.6000000000076,63.860833308917876,-0.021433427339057523,-0.12438904843570064
586.7000000000077,63.97284024012334,-0.019206459875742113,-0.12438991699993407
587.8000000000077,64.08165742614005,-0.020506757443513393,-0.1243899208909558
588.9000000000076,64.19173285875215,-0.01984066161507876,-0.12569676503859162
590.0000000000076,64.2997742945129,-0.018914538093607547,-0.12570004973155013
591.1000000000076,64.40830872748242,-0.022409963965679958,-0.1267040153247283
592.2000000000077,64.51847168092287,-0.021723750863351363,-0.1266279306578526
593.3000000000077,64.62787822627165,-0.01932025633925162,-0.1276773604225152
594.4000000000077,64.73803932790918,-0.023085622284881813,-0.12900037896162875
595.5000000000077,64.84680674357152,-0.025686286548355627,-0.1289998519988056
596.6000000000078,64.95606554020515,-0.028114706155873748,-0.1290003666073094
597.7000000000078,65.06595631541455,-0.029485898577653297,-0.12767550444543474
598.8000000000078,65.17555560100907,-0.034311469121538735,-0.12900017317000634
599.9000000000078,65.28500762241394,-0.03718817894060343,-0.12902091203317578
601.0000000000078,65.39421915544445,-0.04040512089522626,-0.12986580495314604
602.1000000000079,65.50451544204397,-0.040691805758841945,-0.12996755548157957
603.2000000000079,65.6127787660509,-0.044183214877227456,-0.13030911422162905
604.3000000000079,65.72342946409101,-0.04378982792544101,-0.12900017436409472
605.4000000000078,65.83343914916176,-0.04494815440311021,-0.13014394801064544
606.5000000000078,65.94287311845913,-0.04685570245761031,-0.12899824083258604
607.6000000000079,66.05218653872875,-0.045981243297464225,-0.1276851476739278
608.7000000000079,66.16226489085311,-0.04627258159415737,-0.1290007117738372
609.8000000000079,66.27111104305061,-0.04792852695971609,-0.1299935515579027
610.9000000000079,66.38126454262753,-0.048010202948464385,-0.12999013289249817
612.000000000008,66.49049044395171,-0.048467192758681416,-0.12966060243913358
613.100000000008,66.5985799111039,-0.05105918356850584,-0.12900021818737972
614.200000000008,66.70956790939547,-0.049857547983741236,-0.13031997876826296
615.300000000008,66.81805918303004,-0.0498708841491521,-0.1289949752282804
616.400000000008,66.92839825211324,-0.05257064476744893,-0.13097993471443248
617.5000000000081,67.03717699645802,-0.05270426917268995,-0.12967109116458042
618.6000000000081,67.14635470005976,-0.054551186876465194,-0.12966009499622544
619.7000000000081,67.25652441744197,-0.05340722520440597,-0.1296600949999993
620.8000000000081,67.36423148689865,-0.054596125218911815,-0.12966009503259546
621.9000000000082,67.47561342008255,-0.05650855388598748,-0.1295678345538045
623.0000000000082,67.58502672836332,-0.05341455801963363,-0.1309799961910132
624.1000000000081,67.69476251148764,-0.054743866285905204,-0.13098095138779708
625.2000000000081,67.80372305361236,-0.05483496730259132,-0.12964667311080946
626.3000000000081,67.91377351782884,-0.05604086326268226,-0.1309701052472616
627.4000000000082,68.02479743506584,-0.05839814992280667,-0.13229171130776418
628.5000000000082,68.13402684746382,-0.06147596650283446,-0.13229012901261195
629.6000000000082,68.24322512263298,-0.06163618739527874,-0.13226272465783584
630.7000000000082,68.35295033233828,-0.06421055906731336,-0.13195997122736935
631.8000000000083,68.46273915204858,-0.06558965233955469,-0.13195994958282187
632.9000000000083,68.5725859032607,-0.06461519645488757,-0.13295436741485078
634.0000000000083,68.68288527569084,-0.06411973658969444,-0.13201837897076363
635.1000000000083,68.79240448631964,-0.0656190859737786,-0.13162982140539103
636.2000000000083,68.9013626681403,-0.06398295125391777,-0.13195981969922954
637.3000000000084,69.01011207709091,-0.06421848205716311,-0.1326168446880538
638.4000000000084,69.12082289702911,-0.06911375495336632,-0.1336101533034455
639.5000000000084,69.23040165680996,-0.06708578358041174,-0.1336102492328357
640.6000000000083,69.34047949759596,-0.07029562455886655,-0.13295007594052866
641.7000000000083,69.44985123044138,-0.07182229291038941,-0.13295000799998213
642.8000000000084,69.55967938256833,-0.07097387884887896,-0.13295000768399534
643.9000000000084,69.67028146331036,-0.07279608468198223,-0.1342734183039367
645.0000000000084,69.78007765094839,-0.07285906095901679,-0.13429328021108233
646.1000000000084,69.89102091228493,-0.07342663749519043,-0.13219547340411353
647.2000000000085,69.99977952920953,-0.07593677821212125,-0.13294953447498603
648.3000000000085,70.11044310129601,-0.07581233294539227,-0.13294981100024117
649.4000000000085,70.22089208827518,-0.07882410501591998,-0.13294980855014238
650.5000000000085,70.33022557128676,-0.07559837012858056,-0.13331738980351293
651.6000000000085,70.4398532070758,-0.07651264487536569,-0.1336054642840767
652.7000000000086,70.55075032588145,-0.08018660623654875,-0.1339401188292535
653.8000000000086,70.66010733743866,-0.07825250090216053,-0.13394842631833326
654.9000000000086,70.77033911892138,-0.07803820810620189,-0.13526015596740848
656.0000000000086,70.88124653434632,-0.08045071457163974,-0.13449270513667555
657.1000000000087,70.99097096170036,-0.07830615705919644,-0.13338994810998273
658.2000000000087,71.10078896462896,-0.07868092103314792,-0.135040210106538
659.3000000000086,71.20985674642847,-0.07760898764002302,-0.13504002427072237
660.4000000000086,71.32043965856079,-0.07935490434695458,-0.13371794885234678
661.5000000000086,71.42926245667707,-0.07935339542841013,-0.1350399175405257
662.6000000000087,71.53948733399176,-0.0779640384331573,-0.13503990756361883
663.7000000000087,71.6495672594375,-0.0779315634154335,-0.13372019433358284
664.8000000000087,71.76020152945046,-0.07831008958824015,-0.13470914434631887
665.9000000000087,71.87036420106763,-0.07476553035548864,-0.13471732225977595
667.0000000000088,71.98026057411145,-0.07610640533946188,-0.13570722856432704
668.1000000000088,72.09007457982518,-0.07334735492796976,-0.13470003817931042
669.2000000000088,72.20012680756525,-0.0766565883431627,-0.13568782253307
670.3000000000088,72.31109656462208,-0.0749848702421368,-0.13568987800166843
671.4000000000088,72.41948824502919,-0.07696435044719835,-0.13568990877419207
672.5000000000089,72.53075917017323,-0.0765989087885465,-0.1360199374700901
673.6000000000089,72.64074409054248,-0.07619725165012799,-0.13471015263498742
674.7000000000089,72.75201680201589,-0.07617585634761265,-0.1360181608640869
675.8000000000088,72.86159313461853,-0.07780130984924301,-0.1360168540357649
676.9000000000088,72.97216817799587,-0.07918005242775371,-0.13733928352820213
678.0000000000089,73.0816747749638,-0.07858162645237678,-0.136030249850271
679.1000000000089,73.19224979078155,-0.07997738344952163,-0.1347098202884407
680.2000000000089,73.3031141805256,-0.07395248532551342,-0.134709867226674
681.3000000000089,73.4122716423737,-0.0732238470139878,-0.1373492941497121
682.400000000009,73.5233103436708,-0.07254250677889551,-0.1386629855884114
683.500000000009,73.6330178737882,-0.0711318922818413,-0.1386505131517337
684.600000000009,73.74270690267609,-0.06810909381810565,-0.13735146051200386
685.700000000009,73.85344038507264,-0.0657694395069757,-0.13778961483864682
686.800000000009,73.96353427759271,-0.06529770491173009,-0.13865922771211547
687.9000000000091,74.07346797783212,-0.060956282993962,-0.13869943548801977
689.0000000000091,74.18285225138645,-0.05984680095094995,-0.13734165450727875
690.1000000000091,74.29363972243566,-0.058057318527924215,-0.13601995195812044
691.2000000000091,74.40350490265048,-0.05296536385603476,-0.1370098063213918
692.3000000000092,74.51279003163819,-0.049931614405759654,-0.1370725749170738
693.4000000000092,74.62259646683346,-0.050974866596927376,-0.13684502421159017
694.5000000000091,74.7327982474981,-0.04681630486232338,-0.13766030309025057
695.6000000000091,74.84299017711548,-0.04406318567626684,-0.13732694237083676
696.7000000000091,74.95248535615426,-0.038956450237580445,-0.135809663172743
697.8000000000092,75.063450973268,-0.03905821553555537,-0.1371924132406459
698.9000000000092,75.17400568042174,-0.036160107179515885,-0.13981487467781273
700.0000000000092,75.28436645669991,-0.031858436016654695,-0.138590108173144
701.1000000000092,75.39377529694397,-0.028209161623432955,-0.13713013060701584
702.2000000000093,75.50435170070739,-0.02635461680426676,-0.13844037763508465
703.3000000000093,75.6148819350877,-0.02578422569030271,-0.138439999999854
704.4000000000093,75.72592553895143,-0.02018179535071357,-0.13844008971564303
705.5000000000093,75.83631153171976,-0.020384026903783867,-0.13974864246776164
706.6000000000093,75.94653191964036,-0.01888969961436074,-0.1391001266990366
707.7000000000094,76.05545245315676,-0.01626929213132572,-0.13852200594774766
708.8000000000094,76.16841626226895,-0.015258066549635144,-0.13712006999888704
709.9000000000094,76.27836250871748,-0.014182735471201163,-0.1371201330804559
711.0000000000093,76.38928504074168,-0.016122991859925273,-0.1397627905284735
712.1000000000093,76.49974961795317,-0.016993933723494323,-0.13844045458884402
713.2000000000094,76.60795432360298,-0.014652924873785292,-0.1384400339999261
714.3000000000094,76.71917096186,-0.010657865070226882,-0.13844003402399263
715.4000000000094,76.83083814341445,-0.014280828537370921,-0.1397598292358322
716.5000000000094,76.94168103138662,-0.013969083240648064,-0.139759934806444
717.6000000000095,77.05089515554758,-0.014738592872118414,-0.13894662310888384
718.7000000000095,77.1613210369336,-0.019739622800709664,-0.13877149552432488
719.8000000000095,77.27159696910783,-0.019073119220134993,-0.13580008421466294
720.9000000000095,77.38295165539606,-0.017103350712110582,-0.14032582691673978
722.0000000000095,77.49274043234308,-0.02176375599259514,-0.14131910191091235
723.1000000000096,77.60248694501034,-0.023981245533947454,-0.14031002303694162
724.2000000000096,77.71430706496143,-0.024659230774901605,-0.14031002156007277
725.3000000000096,77.82469404356614,-0.02692727499411414,-0.1416632695703548
726.4000000000096,77.93548038660678,-0.03078786522091187,-0.1413419788664978
727.5000000000097,78.04600824341661,-0.030275400901447272,-0.1399699177052982
728.6000000000097,78.15685159297523,-0.03407278530778482,-0.14030004679478525
729.7000000000096,78.26641733188468,-0.035241473510225135,-0.1406501038872916
730.8000000000096,78.37735030995425,-0.034893171976269205,-0.14194931364875485
731.9000000000096,78.48771504464615,-0.041172225772310125,-0.1419500566260119
733.0000000000097,78.59783250364828,-0.04459057608240251,-0.14074373459694423
734.1000000000097,78.70906534519756,-0.045104044240888985,-0.14195995776133596
735.2000000000097,78.81792905148163,-0.04503063430064182,-0.1419599580000006
736.3000000000097,78.92865988117961,-0.045813275729860964,-0.1419599579999975
737.4000000000098,79.03856643524566,-0.04592323360671406,-0.14195996038876846
738.5000000000098,79.14994602503172,-0.05090368994695453,-0.1406399392540063
739.6000000000098,79.25927380416586,-0.05334345953469102,-0.1419526631406285
740.7000000000098,79.37059033134516,-0.05233520974072349,-0.1432703068621688
741.8000000000098,79.48122737623339,-0.054439281475147816,-0.1419438912727906
742.9000000000099,79.59107444036582,-0.05575282573103775,-0.14195490599442984
744.0000000000099,79.70157511418022,-0.05417439969121221,-0.14293999017850822
745.1000000000099,79.8117127501409,-0.05748844979608658,-0.14293999201021057
746.0000000000099,79.90203227585613,-0.05736300712255887,-0.14293839407087905