File: 01_Data/EIFS_XPS/STA/N2/10K_min/EIFS_XPS_STA_N2_10KData_230202_R1.csv
##Temp./Â°C,Time/min,DSC/(mW/mg),Mass loss/mg
50.0,10.891978558049175,0.035038362974606274,-0.01006015644507574
51.000000000000014,11.156016545105135,0.05247144742183418,-0.011877718658666936
52.00000000000003,11.377750938815334,0.07494317338020284,-0.011446386948778198
53.00000000000004,11.560000000000027,0.08464103438686355,-0.0136924259296336
54.00000000000006,11.7252302658506,0.094948015362738,-0.013404969512678555
55.00000000000007,11.879681020154678,0.1060656806970619,-0.013362097548995422
56.000000000000085,12.028800568734209,0.1131074064509241,-0.013727097789826281
57.0000000000001,12.168938484549026,0.12052616758551493,-0.013625795715048739
58.000000000000114,12.303082946304771,0.12283557885752483,-0.014100066862633653
59.00000000000013,12.436758624615925,0.12851482161378658,-0.013826287572296536
60.00000000000014,12.566843447920366,0.1335574753430364,-0.01363309737666718
61.000000000000156,12.692103551184314,0.13530595246943156,-0.013979180659387858
62.00000000000017,12.816784770045683,0.14111413758672064,-0.015024503244871035
63.000000000000185,12.939876676813569,0.1417589546649929,-0.015487297777237785
64.0000000000002,13.06060748100435,0.14541992097375234,-0.014167319540080214
65.00000000000021,13.178884029967826,0.14773446838461868,-0.01368507544154074
66.00000000000023,13.297197251293532,0.15064369823245727,-0.012831789404984306
67.00000000000024,13.41450182477532,0.15211417393124815,-0.01442836383002355
68.00000000000026,13.529886994704995,0.15843679051896453,-0.013948702320998763
69.00000000000027,13.643555637138114,0.15860198330078168,-0.015181155367180565
70.00000000000028,13.756483404369552,0.1608024923361877,-0.015321052864424978
71.0000000000003,13.869749792069854,0.16066894941499688,-0.015355388398464953
72.00000000000031,13.981297651846342,0.16098855571227322,-0.01671124932443835
73.00000000000033,14.091400857357154,0.16082278746812073,-0.01679926661903597
74.00000000000034,14.201225859544955,0.16212612544816052,-0.01679861719205622
75.00000000000036,14.310100805331164,0.161079526109845,-0.0166707691022161
76.00000000000037,14.416972788402521,0.16147627488954286,-0.016763499816050853
77.00000000000038,14.52651311318354,0.16186430124740903,-0.015926107872904716
78.0000000000004,14.634641599101055,0.16219223879738798,-0.01801441596413067
79.00000000000041,14.742238732807046,0.1638535287045153,-0.018032422470845688
80.00000000000043,14.848234672770417,0.16481444449606752,-0.018003280664822263
81.00000000000044,14.954799450046854,0.16769693856421464,-0.017214179860435053
82.00000000000045,15.057885692507035,0.16742684426517274,-0.01897777390083899
83.00000000000047,15.163606222242288,0.1692474829665327,-0.018116658569385713
84.00000000000048,15.266621155733771,0.17320233442453548,-0.019040508521768196
85.0000000000005,15.369522199152167,0.17394315207425537,-0.019430455755474974
86.00000000000051,15.471160958770435,0.17669679748437372,-0.01942987492784365
87.00000000000053,15.575712637684099,0.17883617825012388,-0.018497260687730055
88.00000000000054,15.676696920977644,0.18063002312865473,-0.018781918044707524
89.00000000000055,15.77919136175511,0.18576863187220782,-0.01945101842724828
90.00000000000057,15.88056770716656,0.1866568969888026,-0.0191069083907065
91.00000000000058,15.981232150836805,0.18933843159897135,-0.01943721050558267
92.0000000000006,16.081695551592304,0.19287223745730986,-0.019447199232691226
93.00000000000061,16.182513668355725,0.1982905174033811,-0.020740693307294222
94.00000000000063,16.281925058161246,0.1990532983177301,-0.02010191483379753
95.00000000000064,16.381055057652034,0.20608168398885196,-0.022072668275938234
96.00000000000065,16.479519135912973,0.21137263793157957,-0.020717266469500117
97.00000000000067,16.578442356078057,0.21530971107929675,-0.02208098806855663
98.00000000000068,16.676542486933325,0.21918812384462172,-0.022061004552154984
99.0000000000007,16.77493954218099,0.22633493149077644,-0.02239131437460884
100.00000000000071,16.87292117433766,0.23690430094271553,-0.0233794003163883
101.00000000000072,16.97124891704648,0.24642409855643488,-0.023378698869020553
102.00000000000074,17.07028975868979,0.25513309526156036,-0.023378642002299443
103.00000000000075,17.16796782799426,0.26902377042946357,-0.023379813475928657
104.00000000000077,17.26658985980334,0.2809330921887725,-0.024470639827866236
105.00000000000078,17.36260673823595,0.29486449760898625,-0.026021560372608832
106.0000000000008,17.461578665887824,0.3081685942741409,-0.02470092290513648
107.00000000000081,17.557512482648644,0.32005951873060723,-0.026020097069349823
108.00000000000082,17.655714163602546,0.3300148483305102,-0.026978956813006327
109.00000000000084,17.753208818795986,0.3347829536609944,-0.027656442782001633
110.00000000000085,17.84921036369233,0.3374704728318959,-0.029145579728727
111.00000000000087,17.94785726332001,0.33622396227618667,-0.030707591637284537
112.00000000000088,18.043239784843383,0.3333347234590496,-0.028993780022585902
113.0000000000009,18.141357549110136,0.326326779120067,-0.031096276717769378
114.00000000000091,18.23872823150931,0.3193810151874613,-0.03030037073244074
115.00000000000092,18.33626201642444,0.30913965752266415,-0.0315954066475479
116.00000000000094,18.432502696914465,0.3006089438952205,-0.031620839571212755
117.00000000000095,18.529039156606085,0.29169276188772286,-0.032928550939820056
118.00000000000097,18.62578387885958,0.28605583234666265,-0.033270892573260546
119.00000000000098,18.721278704665544,0.2798858622963951,-0.03327017704350954
120.000000000001,18.816965883484674,0.2740996074726426,-0.032545565905630625
121.00000000000101,18.914737645865067,0.270064426081856,-0.03279795683269615
122.00000000000102,19.011103968357702,0.26354327821787626,-0.03561366483055206
123.00000000000104,19.107406200419117,0.26218687635515026,-0.034248013689597734
124.00000000000105,19.203426224329952,0.2601295651652946,-0.03425698667926369
125.00000000000107,19.299236577672126,0.25893967444034904,-0.03530729421283496
126.00000000000108,19.39483216097328,0.2581385657010865,-0.03259793991476023
127.0000000000011,19.4900000000001,0.2600717461787694,-0.03269751682525257
128.0000000000011,19.586888328690677,0.261066283857624,-0.03259997437591977
129.00000000000114,19.68256948272378,0.26215987934055784,-0.033919926785273447
130.00000000000114,19.77756445245814,0.2593647464119512,-0.033988460150528255
131.00000000000114,19.872418988013944,0.2592886124949576,-0.032633753929012244
132.00000000000117,19.968903886648302,0.2593819802698536,-0.03522939235625966
133.0000000000012,20.0633539071703,0.2601532086657774,-0.03637127620792224
134.0000000000012,20.160897457785595,0.2607956831309829,-0.03589889988208039
135.0000000000012,20.25510456943182,0.2615830026216648,-0.03524174588478779
136.00000000000122,20.34929217580378,0.2614268678859535,-0.03654436500700431
137.00000000000125,20.444591825595147,0.2607686699534252,-0.0352349022870424
138.00000000000125,20.539405562562457,0.26294060078646253,-0.03656043960790889
139.00000000000125,20.63379380276448,0.26389986968440504,-0.034018576114075216
140.00000000000128,20.728152669080604,0.26331751988032226,-0.035243826980954296
141.0000000000013,20.823899384115563,0.2641520985794056,-0.03655382897498338
142.0000000000013,20.918206300272974,0.2619704070580242,-0.03610347977938133
143.0000000000013,21.012723171807238,0.26472432508386656,-0.03482752228018082
144.00000000000134,21.108162788736344,0.2639804869505594,-0.03519377493170417
145.00000000000136,21.2019369887401,0.2661205132698793,-0.03667028673252748
146.00000000000136,21.296463881847554,0.26591502158480906,-0.03534943179244543
147.00000000000136,21.391408534285777,0.26596702151622953,-0.03535026992161949
148.0000000000014,21.48570550346102,0.26721200215741725,-0.03423831760170959
149.00000000000142,21.580087301644728,0.26834763047958454,-0.0353396138255091
150.00000000000142,21.674416799071164,0.26625248599707485,-0.03665990163329891
151.00000000000142,21.76799824130563,0.26798273270484296,-0.03667565846022036
152.00000000000145,21.86338497095639,0.26762935166590107,-0.0360100548386626
153.00000000000148,21.958982186036994,0.2659276664431345,-0.03601005149869163
154.00000000000148,22.051992018026695,0.2680789682925745,-0.036838903707860915
155.00000000000148,22.146626061309775,0.26761804129328415,-0.03805319386282324
156.0000000000015,22.24207889450612,0.2682638910412384,-0.03796456593111586
157.00000000000153,22.3365353849921,0.27041431175322783,-0.03789138507106049
158.00000000000153,22.430827859188362,0.2701477969626602,-0.03666073195892494
159.00000000000153,22.522922555211615,0.2710087979025201,-0.03798769598645091
160.00000000000156,22.618354227865456,0.27146436499973703,-0.0379898649578303
161.0000000000016,22.713333047833114,0.2682604020829539,-0.03799319463460815
162.0000000000016,22.80872676646037,0.26906631901750566,-0.03733014076029573
163.0000000000016,22.902176309131942,0.2696985670181773,-0.037324619150274074
164.00000000000162,22.996995208980795,0.27026657824366673,-0.03680612114603221
165.00000000000165,23.09189358320303,0.27127802117018873,-0.036674521797619875
166.00000000000165,23.186321232124392,0.2724515834618544,-0.037980075911864475
167.00000000000165,23.279467771375597,0.2731134356090293,-0.0393038480268002
168.00000000000168,23.375139295255835,0.273125575876323,-0.03927109916289773
169.0000000000017,23.46959782310355,0.27620955464720254,-0.03798016216613842
170.0000000000017,23.562677507322675,0.2750238896417955,-0.037980255784064276
171.0000000000017,23.657786410449646,0.27524232442452023,-0.03929984104970341
172.00000000000173,23.75196301023528,0.2760260984874095,-0.040754937457267104
173.00000000000176,23.846352917028035,0.2757683943217264,-0.0394200170003991
174.00000000000176,23.939534077323614,0.27309403740545835,-0.039420037759728466
175.00000000000176,24.033733438414348,0.2751603407719657,-0.039428970614855174
176.0000000000018,24.12653425711618,0.275099578150206,-0.03810023777384508
177.00000000000182,24.22236287710349,0.27663422157634837,-0.03936902509015816
178.00000000000182,24.31539335085776,0.27468273203982163,-0.0432614583480877
179.00000000000182,24.410958387439376,0.27561227246079556,-0.04193996060049976
180.00000000000185,24.505895888800378,0.27604433315880283,-0.0419426523612616
181.00000000000188,24.59706732297405,0.2772151958748582,-0.0419327988185616
182.00000000000188,24.69448735082541,0.2773235313292892,-0.041931519860598954
183.00000000000188,24.787868907232507,0.2779827019894789,-0.04293000043460449
184.0000000000019,24.882275184558594,0.27767862904719864,-0.043133645968913115
185.00000000000193,24.976186086240116,0.2770019070466065,-0.04325005619299738
186.00000000000193,25.070700411316256,0.276976514895203,-0.04259044796378664
187.00000000000193,25.16192810164144,0.2777528902074268,-0.04287979577270473
188.00000000000196,25.258446132108148,0.2787041178073938,-0.043910134567410886
189.000000000002,25.352990870311277,0.2791922901649368,-0.04407416994236435
190.000000000002,25.447131057223206,0.2776269901519119,-0.0445741398754258
191.000000000002,25.541557209301033,0.2802278788606943,-0.04384220035526987
192.00000000000202,25.63528841144837,0.27870231118371636,-0.04457679058636277
193.00000000000205,25.730000000000196,0.28229703442649856,-0.04588130848213723
194.00000000000205,25.823069778747826,0.28183839746243844,-0.044569681984436116
195.00000000000205,25.916801827055654,0.2837253466835067,-0.04651999377786886
196.00000000000207,26.011236288754436,0.2840532681264262,-0.045881555193399315
197.0000000000021,26.104833378363733,0.28376931701639624,-0.04589011610654303
198.0000000000021,26.195867185609657,0.2851695833191114,-0.04589009338515915
199.0000000000021,26.292665538605057,0.28645961837867,-0.04580424719459231
200.00000000000213,26.387598842286533,0.2869958103403327,-0.04653873759865945
201.00000000000216,26.4805528670104,0.28893483655899227,-0.04754253804204822
202.00000000000216,26.574801439605924,0.28964674399284246,-0.04615750378917216
203.00000000000216,26.66871823544177,0.29090188721594207,-0.04650422399714227
204.0000000000022,26.763146784100204,0.29281347187863666,-0.04852930586781312
205.00000000000222,26.856983262933724,0.2917778556418077,-0.04851980792601385
206.00000000000222,26.95009033532456,0.29346825113142555,-0.04818144644117872
207.00000000000222,27.04436479887707,0.2931660771334125,-0.048520376872246196
208.00000000000225,27.136801885343836,0.29669496584411786,-0.04983323570959186
209.00000000000227,27.232954911722118,0.29513664284225427,-0.04984155918694455
210.00000000000227,27.327150971740448,0.29491438890057264,-0.04980904468813829
211.00000000000227,27.420641257921595,0.2967380629994387,-0.05016999025726854
212.0000000000023,27.515278817519665,0.29546796224085536,-0.05050369946446853
213.00000000000233,27.609618957881146,0.296352349325496,-0.05182793224510984
214.00000000000233,27.70430615958015,0.2975565789916111,-0.0518190739495914
215.00000000000233,27.798427938355392,0.29706333204852636,-0.0511598321800566
216.00000000000236,27.89211449650257,0.2974836037933174,-0.05115990709550555
217.0000000000024,27.987278429418144,0.2985942556998596,-0.05114328290143888
218.0000000000024,28.07990550531501,0.2994066917283277,-0.05246990010477326
219.0000000000024,28.175093817055004,0.29952066902239805,-0.05246990700004073
220.00000000000242,28.266884618630176,0.2990806909338597,-0.05246990884017588
221.00000000000244,28.36420519202156,0.299656795868213,-0.05358591695301218
222.00000000000244,28.457277579336917,0.3007501093492132,-0.05378990765476299
223.00000000000244,28.551545860849046,0.3028761136421751,-0.05382472149571704
224.00000000000247,28.64677397127765,0.3022134838467142,-0.0531003467735669
225.0000000000025,28.740249557411893,0.30139102373841864,-0.05444948091055668
226.0000000000025,28.834546645432898,0.30066123776197107,-0.05444508597557185
227.0000000000025,28.928945719452937,0.3007303692866239,-0.05640939204048934
228.00000000000253,29.023661137307887,0.3003964268179299,-0.055109912094563285
229.00000000000256,29.118354744595436,0.29964608351456606,-0.05510996877549523
230.00000000000256,29.212980599948477,0.30038596460218925,-0.055441499014905915
231.00000000000256,29.30691178615441,0.2998178459739432,-0.05544008298712999
232.0000000000026,29.40286196076547,0.3008526375463454,-0.05544008300000769
233.00000000000261,29.496370455989247,0.3004660159052973,-0.05544008130086375
234.00000000000261,29.59053343194265,0.2994769003685235,-0.05672532200923186
235.00000000000261,29.685020687205668,0.29885271311700573,-0.058011012838035114
236.00000000000264,29.779537841265924,0.2986938552016454,-0.05806997852567708
237.00000000000267,29.875095685393685,0.30017254201207044,-0.059038524410672366
238.00000000000267,29.968385198971145,0.3020417732917733,-0.05906010212740931
239.00000000000267,30.0624576643891,0.3013571203783583,-0.05872883330219114
240.0000000000027,30.15701298787143,0.3029982695159285,-0.058069810751550044
241.00000000000273,30.25186715104604,0.30406078542433174,-0.058070541177180246
242.00000000000273,30.345926998687773,0.30560734604681933,-0.059389497463324226
243.00000000000273,30.440729989721117,0.30586565287883927,-0.0593912369586187
244.00000000000276,30.53585320787882,0.3063257667753918,-0.06203080892947721
245.00000000000279,30.631229145249584,0.3059973042325457,-0.06052173266921024
246.00000000000279,30.7245044825723,0.30751689351006606,-0.05971990554026796
247.00000000000279,30.819543715349145,0.3100576055499349,-0.05972556154831388
248.0000000000028,30.912715061599048,0.308600316538884,-0.06235938732434043
249.00000000000284,31.008133326477616,0.30933131499799615,-0.061043420922676894
250.00000000000284,31.102600776481577,0.3102589843497625,-0.0637372445998503
251.00000000000284,31.19753819611794,0.31166254250256664,-0.06137266458130419
252.00000000000287,31.29167180771461,0.3132904343372198,-0.06271845640817464
253.0000000000029,31.38611387797043,0.3111430780802944,-0.06267998450076018
254.0000000000029,31.48029418140434,0.31210480583665545,-0.06269301442843123
255.0000000000029,31.575422401708835,0.31233234244614916,-0.06407038188918168
256.00000000000296,31.669653956206783,0.31257784276983425,-0.06531987572562326
257.00000000000296,31.764829921844566,0.3130299560514494,-0.06532019479390971
258.00000000000296,31.859017711434284,0.3155383695520758,-0.0657488631619545
259.00000000000296,31.953654486260998,0.317473271537122,-0.06663504821987587
260.00000000000296,32.04927337444959,0.31445877012464973,-0.06564995673883711
261.000000000003,32.14296319200159,0.31480704017170935,-0.06564749846335971
262.000000000003,32.23838411439368,0.315192128915711,-0.06735657075798951
263.000000000003,32.33232352486835,0.31701301783610203,-0.06721381059073916
264.00000000000307,32.42818334871233,0.3175381311187505,-0.06862315039912392
265.00000000000307,32.522762492672534,0.3158364512735734,-0.0673220231448477
266.00000000000307,32.61608219200728,0.31642682412816103,-0.0686061604148378
267.00000000000307,32.71252668580824,0.3156240044802181,-0.06861992574804265
268.00000000000307,32.80768844133421,0.3164799693002872,-0.0695997921398872
269.0000000000031,32.90183925886775,0.31656525310907635,-0.06959996200004959
270.0000000000031,32.997575785899556,0.3159764003091203,-0.06959996200006913
271.0000000000031,33.09154223013859,0.3171214524270791,-0.06959994887621868
272.0000000000032,33.18568193866281,0.31678645172872805,-0.06993214153646843
273.0000000000032,33.28134646444941,0.3183117451241473,-0.07028395072939597
274.0000000000032,33.37530653065018,0.317665489144301,-0.07058034023221138
275.0000000000032,33.47095878744571,0.31752000467979374,-0.0722663111091677
276.0000000000032,33.56584061504717,0.31686935392742466,-0.07256986267231635
277.00000000000324,33.66050574795199,0.32164569884681193,-0.07256994005707718
278.00000000000324,33.755360225995474,0.32144263692127684,-0.07157974718426185
279.00000000000324,33.84970659824306,0.32088347858638777,-0.07189089716293484
280.0000000000033,33.94555839655329,0.32091264945772363,-0.0725698648699229
281.0000000000033,34.04076213759857,0.32109048081604885,-0.07256986300001422
282.0000000000033,34.13571812668108,0.32120133763398817,-0.07256986479976257
283.0000000000033,34.23018842290535,0.3217544439480403,-0.07384016952273864
284.0000000000033,34.32551567751715,0.32183397537767294,-0.07385398890282557
285.00000000000335,34.42127189969076,0.3235957936244467,-0.07354813955326778
286.00000000000335,34.515562242497076,0.3270015819250862,-0.07485802911100814
287.00000000000335,34.6108911871938,0.3284891794778018,-0.07501043090047066
288.0000000000034,34.70657194117767,0.3292301341354989,-0.07619007472558037
289.0000000000034,34.80211232477706,0.32889409597133973,-0.07616315336523716
290.0000000000034,34.896829203553025,0.3295672306012484,-0.07750998406144438
291.0000000000034,34.99201942820314,0.32851451577209745,-0.07750997400002557
292.0000000000034,35.08737295556622,0.3283207875872553,-0.07750997400634718
293.00000000000347,35.18340358783027,0.32960792669881056,-0.0775090623415573
294.00000000000347,35.27761773849319,0.33053824539824844,-0.07847833600245968
295.00000000000347,35.3728631814925,0.33148661695809134,-0.08152668421574827
296.0000000000035,35.46953648307129,0.3318751292698614,-0.08144759794062262
297.0000000000035,35.56370963902869,0.33236904075748946,-0.0801399704437844
298.0000000000035,35.660294885273814,0.33487667585867165,-0.08145005558692242
299.0000000000035,35.75557748614249,0.33646267302790733,-0.08145077642384102
300.0000000000035,35.850492362736894,0.33595889881177576,-0.08243994739669036
301.0000000000036,35.94569913241235,0.33785215499048205,-0.08417191318314377
302.0000000000036,36.03917160530524,0.33949349696303177,-0.08408990866526622
303.0000000000036,36.135947671700556,0.339520397672637,-0.08408990873837041
304.00000000000364,36.2307691921137,0.3388215245716206,-0.08475563519980245
305.00000000000364,36.327237165589914,0.34014292899242515,-0.08672975236844316
306.00000000000364,36.42327045752041,0.33999865910954746,-0.08671102791958951
307.00000000000364,36.51887415624679,0.33887931014980227,-0.08672996306723535
308.00000000000364,36.61386679809937,0.3396475889896301,-0.08747182653095997
309.0000000000037,36.70826868594849,0.3390018419910026,-0.08973114098136037
310.0000000000037,36.804877468175924,0.34029688041357753,-0.08969017442932836
311.0000000000037,36.90063938531407,0.3402348940313624,-0.08970678973058188
312.00000000000375,36.99617197155462,0.3406489217109887,-0.09152288522003715
313.00000000000375,37.09168531323675,0.3403081653562406,-0.09266008623801003
314.00000000000375,37.18824006413345,0.34235150915043105,-0.09266321716024217
315.00000000000375,37.28363365041183,0.34148647501614676,-0.09398006508488876
316.00000000000375,37.37831029450995,0.3421658810434899,-0.09332110498291302
317.0000000000038,37.47244568012981,0.3439479672919991,-0.09331677975801123
318.0000000000038,37.57019424056393,0.3464410858612031,-0.09465308244185477
319.0000000000038,37.666204100631795,0.34691580047141324,-0.09587767795502167
320.00000000000387,37.761735497384066,0.3470445379493295,-0.09798326805424784
321.00000000000387,37.8572170815324,0.347291367963703,-0.09988408478688093
322.00000000000387,37.95277619616855,0.34740758326236465,-0.09989539673292835
323.00000000000387,38.04936661882817,0.3513320283542847,-0.0998998130928026
324.00000000000387,38.14422819072756,0.349815191041738,-0.10187995996145283
325.0000000000039,38.240000000000414,0.35572074345074034,-0.10187980296828236
326.0000000000039,38.336008329159085,0.3550444907352323,-0.10385018533529422
327.0000000000039,38.43263249885393,0.35565161581036026,-0.10446164989547224
328.000000000004,38.52915761581594,0.3561082694336679,-0.10516985551760705
329.000000000004,38.625173381557495,0.357327884341308,-0.10549893201982341
330.000000000004,38.721610724894184,0.3589974297730663,-0.10686758324162993
331.000000000004,38.816149529417594,0.3621862573873889,-0.10813987722684093
332.000000000004,38.91336652265154,0.362271882317494,-0.10944725461346128
333.00000000000404,39.00854349434615,0.36457166431902416,-0.1107701905645424
334.00000000000404,39.10533108774326,0.3656818540218779,-0.11211562060042413
335.00000000000404,39.20068536969903,0.3690787110687826,-0.11141887914984938
336.0000000000041,39.29665489341494,0.3713704374006776,-0.11512213047018394
337.0000000000041,39.392920451000265,0.37360262512851833,-0.1175737502776677
338.0000000000041,39.48936643150947,0.37457173622162004,-0.11765572456943652
339.0000000000041,39.58513545189303,0.37725600523559194,-0.11894849742409663
340.0000000000041,39.68101769951445,0.3783908381290969,-0.12106460588852785
341.00000000000415,39.7771503432858,0.3800542023128833,-0.12272737415548862
342.00000000000415,39.87398923688151,0.3823836676050306,-0.12428725633656335
343.00000000000415,39.968221957684676,0.38254977415285796,-0.12592240223021411
344.0000000000042,40.06565224500894,0.3839048832918035,-0.1272377829527227
345.0000000000042,40.16175827886337,0.3853728180059357,-0.12951838608335997
346.0000000000042,40.25583258675311,0.38502110585922256,-0.13087438601087387
347.0000000000042,40.354487624168605,0.3906742170755521,-0.1335021758156154
348.0000000000042,40.45130459316584,0.39348754598432856,-0.1347946148907031
349.00000000000426,40.547387416280436,0.39566669895208906,-0.137500905210044
350.00000000000426,40.643485249886425,0.4003018033247828,-0.13883075735229244
351.00000000000426,40.73940566569731,0.4012613915603717,-0.14151057693764413
352.0000000000043,40.835925240979684,0.4072196331974191,-0.14305061085391158
353.0000000000043,40.93236600169142,0.412093610749288,-0.14577278570538654
354.0000000000043,41.02884090484118,0.416061440382829,-0.14853313152101455
355.0000000000043,41.12344566124626,0.42115424086978004,-0.15256891240885517
356.0000000000043,41.21991079906144,0.4258857645335188,-0.15380036478275683
357.0000000000044,41.31555108795521,0.4291410489007023,-0.15670809017436138
358.0000000000044,41.41289239883874,0.4343062357480286,-0.15946398668582917
359.0000000000044,41.50894726663536,0.4395876528970466,-0.1625079246393799
360.00000000000443,41.605807529918806,0.4461611124920536,-0.16635798590374495
361.00000000000443,41.70201282856429,0.451047675971412,-0.1705388364471001
362.00000000000443,41.79852309178075,0.45670328011865957,-0.1732170784733893
363.00000000000443,41.895539312523546,0.46429970268778864,-0.17777566848243742
364.00000000000443,41.99134202378009,0.47230350577210456,-0.1805352823973565
365.0000000000045,42.0901033950609,0.4797923061395934,-0.1849820440001393
366.0000000000045,42.18616828995795,0.4908707832147135,-0.1909828594430487
367.0000000000045,42.28273242864475,0.4981587337863256,-0.1967505245835648
368.00000000000455,42.37942044332179,0.510781034804097,-0.20144897436681664
369.00000000000455,42.477201502134584,0.5209370257293724,-0.20618312915544612
370.00000000000455,42.57544563801713,0.5306107250249175,-0.2125277613519745
371.00000000000455,42.672115085106554,0.5436827590320152,-0.2189610375488602
372.00000000000455,42.768995951700475,0.5570497552363294,-0.22535908897132062
373.0000000000046,42.866022108188325,0.5704325578274168,-0.23294489963861986
374.0000000000046,42.96468109562008,0.5870910556176834,-0.24151248796815494
375.0000000000046,43.060553357078554,0.6054092159183149,-0.24926188833312946
376.00000000000466,43.15852585899055,0.627730685013185,-0.257653719704241
377.00000000000466,43.25477529122246,0.6510274704027224,-0.2666508095027691
378.00000000000466,43.35245918477578,0.6755486830931903,-0.2767835049767613
379.00000000000466,43.44859023175808,0.699740179935453,-0.2879746500642977
380.00000000000466,43.54607520818345,0.7252344052980202,-0.2986392553306443
381.0000000000047,43.643499504081205,0.7561629967000985,-0.3094023826875798
382.0000000000047,43.739324025095826,0.7866329549582196,-0.32464321408572694
383.0000000000047,43.837189932455004,0.8200523503313841,-0.33696023590240154
384.0000000000048,43.933996058564404,0.8552519180732747,-0.35254747161759603
385.0000000000048,44.03077874027689,0.8927713689363531,-0.3678496090583505
386.0000000000048,44.128535383126156,0.9311565348536346,-0.38516630793413986
387.0000000000048,44.22543837904905,0.9754627194325749,-0.4031309165599448
388.0000000000048,44.32278438599033,1.0251717169974928,-0.4245964059515246
389.00000000000483,44.42052465255671,1.0753884253083783,-0.44582086009591126
390.00000000000483,44.51752652454462,1.1287572306154645,-0.468847869684887
391.00000000000483,44.61431375287192,1.1853859972331808,-0.4943800874638722
392.0000000000049,44.71149634290327,1.2417066741351488,-0.5200454680144198
393.0000000000049,44.80951923020337,1.3106290411297867,-0.5487137272887264
394.0000000000049,44.90685789850955,1.3832286649556167,-0.5781002811454785
395.0000000000049,45.00378235622642,1.4381187812277703,-0.6124797252987948
396.0000000000049,45.101494389406746,1.49703635510889,-0.6459755112647714
397.00000000000495,45.197490677282595,1.5700654039140576,-0.6823786314711966
398.00000000000495,45.296359295738206,1.651488434497816,-0.7229286127511387
399.00000000000495,45.39234795367861,1.7351595466152188,-0.7629220290879317
400.000000000005,45.49187108458439,1.8209112498714874,-0.8089450996480743
401.000000000005,45.589731230612735,1.9393677968686678,-0.8544123061790816
402.000000000005,45.68636648960448,2.032709958326905,-0.9072040932169996
403.000000000005,45.78494950406978,2.143993064500929,-0.961949248272822
404.000000000005,45.88395138271662,2.248878934844987,-1.0214945577140058
405.00000000000506,45.98182301160234,2.3551637136683685,-1.0822334083713177
406.00000000000506,46.07928437457689,2.4723035771720623,-1.1463496630739676
407.00000000000506,46.1782733645805,2.5884933841231264,-1.2165864633841235
408.0000000000051,46.27462662700001,2.7288888980694446,-1.2877498814787312
409.0000000000051,46.374480626341466,2.8754454106052076,-1.3704030480443654
410.0000000000051,46.47234358209544,2.9927737272035673,-1.4520695797347019
411.0000000000051,46.57071223611279,3.1014400534303066,-1.5420962691056985
412.0000000000051,46.66959979898761,3.2113062918780084,-1.6304620672431707
413.0000000000052,46.76751277747823,3.3385707400205704,-1.726089078560464
414.0000000000052,46.86584265279088,3.42115886066229,-1.8228320676738732
415.0000000000052,46.96462718509479,3.517129103282313,-1.9261624797207149
416.00000000000523,47.063216563711194,3.6106669152104294,-2.0303370821327116
417.00000000000523,47.161297904618685,3.657698237075559,-2.1394326945906377
418.00000000000523,47.260000000000495,3.706837098735679,-2.249240136000438
419.00000000000523,47.35903241037299,3.7537510920361368,-2.3615859769687395
420.00000000000523,47.45690964063755,3.752218565499774,-2.475916538526419
421.0000000000053,47.55567128108267,3.7159000579785855,-2.5881875482935954
422.0000000000053,47.653235693617624,3.6898799683363035,-2.7041860485805715
423.0000000000053,47.751027800602024,3.624895645495155,-2.8141892296274134
424.00000000000534,47.84893748102006,3.526183130803793,-2.9239093311352238
425.00000000000534,47.94371825703127,3.397268541216472,-3.025427748918696
426.00000000000534,48.043703848826645,3.240965462695383,-3.1303262502839413
427.00000000000534,48.14040809016518,3.066511551724962,-3.22731797586178
428.00000000000534,48.23748157970047,2.856029644852562,-3.324432337811148
429.0000000000054,48.335204955467,2.6251723381258274,-3.4126872721447805
430.0000000000054,48.43143849598527,2.3888048616311663,-3.487088076114674
431.0000000000054,48.528965726794176,2.1468479776912837,-3.562569743795839
432.00000000000546,48.6253356995092,1.8999301076258983,-3.625936152678168
433.00000000000546,48.72097662035367,1.6626314840115586,-3.6823166037871293
434.00000000000546,48.81698256663462,1.4340754332787764,-3.7320340860783765
435.00000000000546,48.91388111795783,1.2240074307884723,-3.7736013658659906
436.00000000000546,49.01009007927738,1.0362387945986118,-3.8110528849309495
437.0000000000055,49.10606018303264,0.8704887851546607,-3.840527040653545
438.0000000000055,49.20237619740488,0.7282172820604416,-3.8688003924227234
439.0000000000055,49.29904408553413,0.6014966393682293,-3.89115843088979
440.00000000000557,49.39503808590345,0.4954620125863288,-3.909763018423956
441.00000000000557,49.491546836831745,0.40920629359526206,-3.923471302515389
442.00000000000557,49.58913619027199,0.33454409583241174,-3.936993180093154
443.00000000000557,49.685013123187986,0.2706044037073013,-3.948086763565821
444.00000000000557,49.78218947184177,0.22245167933852794,-3.9581590937469913
445.0000000000056,49.88010573267259,0.17406661379934985,-3.9652255368002294
446.0000000000056,49.9771729518029,0.13685379199647213,-3.972026250389649
447.0000000000056,50.075300959646256,0.10838256621001144,-3.9771731749447587
448.0000000000057,50.17181884862123,0.08403678926870693,-3.983793143131458
449.0000000000057,50.269687294201375,0.06289182307015617,-3.9880956435093897
450.0000000000057,50.36765162524914,0.04832910185931917,-3.9912218106060258
451.0000000000057,50.46506947832322,0.03633651232857675,-3.99391027624493
452.0000000000057,50.56175197037497,0.023434163567625788,-3.9977441361950796
453.00000000000574,50.65950301107569,0.017054952221833578,-4.000616475953698
454.00000000000574,50.75703618568821,0.010342971128514178,-4.003279965240235
455.00000000000574,50.85413313664351,0.00796585525863601,-4.004778456718172
456.0000000000058,50.951584960626256,0.002042323530534698,-4.00477862528231
457.0000000000058,51.04848409003885,-0.0038077867184577174,-4.006096511696159
458.0000000000058,51.14803104770889,-0.008288307373376241,-4.009397529255695
459.0000000000058,51.24418623960365,-0.012990598273889181,-4.011491445048687
460.0000000000058,51.34247453976523,-0.016489627999655573,-4.01236822766948
461.00000000000585,51.44131975921339,-0.021942560637929653,-4.013665525867613
462.00000000000585,51.538573547161484,-0.02350364661061652,-4.014340000363366
463.00000000000585,51.636415514656505,-0.02618848154002469,-4.0157201951007915
464.0000000000059,51.73434786225895,-0.032146780722629706,-4.0150039314286925
465.0000000000059,51.83141572661434,-0.03520905054026241,-4.016288507820795
466.0000000000059,51.92968487545871,-0.037464189696676906,-4.017070886458005
467.0000000000059,52.02753450691252,-0.035631343497021614,-4.016309802114668
468.0000000000059,52.12557881785714,-0.03252338233896508,-4.016309790421456
469.00000000000597,52.22398372280968,-0.030967063933474953,-4.016642759683927
470.00000000000597,52.32098329290034,-0.03532836952900226,-4.017965283382679
471.00000000000597,52.41881470219115,-0.04414806657872758,-4.016611877788322
472.000000000006,52.51780663897559,-0.05135871420055342,-4.016639880247525
473.000000000006,52.61584999029074,-0.0570013389168927,-4.016639879743422
474.000000000006,52.714537879815445,-0.062190408319318824,-4.016493978977824
475.000000000006,52.81285540764875,-0.06346227370434823,-4.0162566351030025
476.000000000006,52.911210714004156,-0.0651636651173228,-4.015772671895682
477.0000000000061,53.00961286753084,-0.06984116715437741,-4.017959919701208
478.0000000000061,53.10787479140878,-0.07336758369791013,-4.017960996859719
479.0000000000061,53.206751491680215,-0.07774978142044307,-4.019280199760744
480.00000000000614,53.30499779087653,-0.07965727415435109,-4.018425373575444
481.00000000000614,53.40393510299611,-0.08515713118781079,-4.0179607238686
482.00000000000614,53.50207677099928,-0.08788178650087194,-4.016979711007605
483.00000000000614,53.600193642312036,-0.08997467381572777,-4.0156603718773765
484.00000000000614,53.69989573323737,-0.09211007003954405,-4.016980109899434
485.0000000000062,53.79799871000483,-0.09379474873962657,-4.016980111025236
486.0000000000062,53.89697114076355,-0.09613395235820732,-4.016993614821037
487.0000000000062,53.99610479032457,-0.09650043862714758,-4.018300024937506
488.00000000000625,54.09362068248179,-0.1023691734652517,-4.018300012872483
489.00000000000625,54.19274649068743,-0.1032538845658865,-4.017932486771381
490.00000000000625,54.29130948365728,-0.10336505389386541,-4.01797005333496
491.00000000000625,54.389701923529586,-0.1036571110164429,-4.0189501058275665
492.00000000000625,54.488539569277606,-0.10484507255844808,-4.018282948465112
493.0000000000063,54.587035283149596,-0.1054762892017933,-4.018289863932843
494.0000000000063,54.6858590034377,-0.10909028560759118,-4.017002660773987
495.0000000000063,54.78499212881143,-0.11141126172164723,-4.017309931654325
496.00000000000637,54.88326970172764,-0.1125363646214736,-4.017300387866661
497.00000000000637,54.98254133638021,-0.11493654143734984,-4.018293894350584
498.00000000000637,55.08093211872034,-0.11592282734609508,-4.0176179901793
499.00000000000637,55.18019120235119,-0.11630735871768824,-4.0186368147120675
500.00000000000637,55.27799697158076,-0.1169875656653395,-4.018949991023795
501.0000000000064,55.377309532106636,-0.11684169920509316,-4.018949990999989
502.0000000000064,55.47502185111865,-0.11900460278209167,-4.018949985129485
503.0000000000064,55.5745677717327,-0.12223913234943556,-4.017622134976564
504.0000000000065,55.67308460595835,-0.12446563523117737,-4.017629041734063
505.0000000000065,55.77245200588255,-0.12423877135303228,-4.018964029260145
506.0000000000065,55.87069796618476,-0.12504830838327655,-4.017302902832064
507.0000000000065,55.969135120787996,-0.12647782464948146,-4.017299913994628
508.0000000000065,56.068495755861704,-0.12677657406853282,-4.017299997929613
509.00000000000654,56.16624012461205,-0.1282194209642806,-4.018622449696746
510.00000000000654,56.266092918743276,-0.1301083647285438,-4.017629868599064
511.00000000000654,56.36461552391362,-0.12948258327250706,-4.017622477107064
512.0000000000066,56.464477943809996,-0.13310292208895044,-4.01729981849969
513.0000000000066,56.56342932548485,-0.1328544153047487,-4.017299815191513
514.0000000000066,56.662366176151615,-0.13521127220110832,-4.01796699195149
515.0000000000066,56.76109051141074,-0.13356940728105088,-4.019610122846854
516.0000000000066,56.860494702049564,-0.13597814714534207,-4.019637628881212
517.0000000000066,56.959508402292315,-0.13695759692678786,-4.018289735861795
518.0000000000066,57.05742499090436,-0.13900757807169303,-4.018293712017631
519.0000000000066,57.15687119243778,-0.13960430074067792,-4.016357151110805
520.0000000000067,57.25502346327952,-0.13974106372825582,-4.016969464025768
521.0000000000067,57.3543767728783,-0.14012028490709508,-4.016970122998159
522.0000000000067,57.45403360301812,-0.14141287726296242,-4.016970122999996
523.0000000000067,57.55213450422588,-0.14367286614868013,-4.016970121898545
524.0000000000067,57.649336423920104,-0.1445533033752931,-4.017898115104045
525.0000000000068,57.74935290733826,-0.1451687423004429,-4.018290024025488
526.0000000000068,57.849496894965164,-0.1468211614852729,-4.018290024002525
527.0000000000068,57.94775780276185,-0.1479624618751344,-4.018289899309572
528.0000000000068,58.047366624991994,-0.1515152997253387,-4.017640174544816
529.0000000000068,58.145780842822106,-0.1570132329525846,-4.018949878960476
530.0000000000068,58.24592591328427,-0.1541998726454329,-4.018950193779622
531.0000000000068,58.343528532977146,-0.15696052561568852,-4.017641595136534
532.0000000000068,58.44473925684564,-0.15851384036128258,-4.017940868199643
533.0000000000068,58.54408774872923,-0.16150044661179436,-4.0189876227791315
534.0000000000068,58.64218721687256,-0.16429693168515325,-4.019279261264671
535.0000000000068,58.74286031315617,-0.16697820052687984,-4.017956631535949
536.0000000000069,58.84204387446403,-0.17083424678381265,-4.0179597470869854
537.0000000000069,58.94113382945954,-0.17139816310529976,-4.018615615090012
538.0000000000069,59.04019265288366,-0.1743807791212692,-4.018549992233058
539.0000000000069,59.14041126824901,-0.174819015153042,-4.019939953540394
540.0000000000069,59.23930767233984,-0.17620502156540874,-4.018617157461395
541.000000000007,59.33816311169803,-0.17839208610432195,-4.018619981175612
542.000000000007,59.437231232161835,-0.18127588643188947,-4.018869951282441
543.000000000007,59.536548844159235,-0.18402851309887924,-4.018950076456992
544.000000000007,59.635133077815716,-0.1837563585080091,-4.019941106066758
545.000000000007,59.73420757982334,-0.18585609395051253,-4.019940056047371
546.000000000007,59.83336903229249,-0.18806488899607687,-4.021134691688176
547.000000000007,59.93236911170279,-0.18819064771411415,-4.021259958949191
548.000000000007,60.03177155512933,-0.19007803697295145,-4.0212599590035
549.000000000007,60.13009779157628,-0.19570281935961686,-4.021260053518015
550.000000000007,60.22958160192507,-0.19263132511373293,-4.020895448215052
551.000000000007,60.330846795124984,-0.19414926140676492,-4.022581862478236
552.0000000000072,60.429080240169654,-0.1968780560633861,-4.021275553990884
553.0000000000072,60.52800004637321,-0.19706425252536894,-4.019940550714293
554.0000000000072,60.62726196288291,-0.19897490879325308,-4.021262056651542
555.0000000000072,60.7262868612991,-0.1990920749329691,-4.021228722696585
556.0000000000072,60.8258826108311,-0.20066747304625543,-4.018622063341773
557.0000000000073,60.92619376770552,-0.20162070989724018,-4.019733624761783
558.0000000000073,61.026373552577645,-0.20398988209898014,-4.020929525299289
559.0000000000073,61.12459554319855,-0.20557145571288862,-4.022238932694362
560.0000000000073,61.22474347406555,-0.20382805583183022,-4.020931723482049
561.0000000000073,61.32355660279649,-0.20567255266130732,-4.020929859108243
562.0000000000073,61.42416417588233,-0.2081933443415433,-4.0219117251422185
563.0000000000073,61.52371071468277,-0.21006816166328943,-4.022239992602221
564.0000000000073,61.62235039201978,-0.20808385035298435,-4.022239993006249
565.0000000000073,61.722896543171586,-0.2076834364949532,-4.022231141191947
566.0000000000073,61.82000000000072,-0.2074545351714707,-4.02190981463626
567.0000000000074,61.92086468412731,-0.20722114487002152,-4.021909817000124
568.0000000000074,62.020824741715536,-0.2056123404019229,-4.0219098170000125
569.0000000000074,62.11989666301933,-0.2100130997848706,-4.021909816295969
570.0000000000074,62.22020414859547,-0.20589777252017555,-4.022239817226641
571.0000000000074,62.320622548358955,-0.20500295325929024,-4.023255592578945
572.0000000000074,62.42028282597057,-0.2053357291257347,-4.024550178838991
573.0000000000074,62.51968676677355,-0.20686383046285944,-4.02322991107393
574.0000000000075,62.618430591251915,-0.20736581342574806,-4.023228230975871
575.0000000000075,62.71783899458114,-0.20657138403456782,-4.023230202353058
576.0000000000075,62.81826182418086,-0.20783803389003047,-4.023660428070981
577.0000000000075,62.91846582228293,-0.20797733755780254,-4.02388986143629
578.0000000000075,63.015501119905565,-0.20810828932221231,-4.025209944819303
579.0000000000075,63.11686832116144,-0.20789094423277993,-4.024493149786703
580.0000000000075,63.21694682788285,-0.2091850596226726,-4.023890150334189
581.0000000000075,63.31609362594393,-0.20846507817286902,-4.02389010165347
582.0000000000075,63.41669366999226,-0.2074934410104824,-4.022516830034202
583.0000000000076,63.5162635578706,-0.2081001062111252,-4.023951107623349
584.0000000000076,63.615900455423564,-0.2065313782493896,-4.023889829115896
585.0000000000076,63.71605870518732,-0.20746840822665236,-4.023889829000001
586.0000000000076,63.813619271460624,-0.20770513841752705,-4.023889829
587.0000000000076,63.91489932240942,-0.2096367934947607,-4.023889829000003
588.0000000000076,64.01611513858919,-0.20509310971945677,-4.0238898308281374
589.0000000000076,64.11462926461886,-0.20731752918423632,-4.023166908523406
590.0000000000077,64.21476015201053,-0.20736190153807804,-4.024527097413184
591.0000000000077,64.3152548523208,-0.20712136202934867,-4.024548857399636
592.0000000000077,64.4152956629918,-0.21053114651736146,-4.0238902025636945
593.0000000000077,64.51476365815701,-0.20935712366222356,-4.0238902157841885
594.0000000000077,64.61399692298862,-0.20918840794385668,-4.024881596553763
595.0000000000077,64.714308894893,-0.20856051348409704,-4.023522920049158
596.0000000000077,64.81414608214473,-0.20787871541682656,-4.024213367866904
597.0000000000077,64.91460049385269,-0.20695987693346654,-4.026188262779424
598.0000000000077,65.014666664425,-0.2098638972289794,-4.024880026677162
599.0000000000078,65.11471708640657,-0.20779890265165565,-4.024880038001324
600.0000000000078,65.21531082297041,-0.20637528315776307,-4.024880872523321
601.0000000000078,65.31522291861384,-0.20611393816887308,-4.02356014409257
602.0000000000078,65.41528831044542,-0.20546768914153268,-4.02351094166056
603.0000000000078,65.51537122681466,-0.20551498206038477,-4.024873035499161
604.0000000000078,65.61631118515601,-0.20467111152207712,-4.024220186364095
605.0000000000078,65.7166095752564,-0.20470051888592738,-4.0242201915271
606.000000000008,65.81673472549762,-0.2057087806257584,-4.023757231614747
607.000000000008,65.91589615899605,-0.2019927367609212,-4.023539504649882
608.000000000008,66.01654562436106,-0.20308782054274288,-4.0248726240183625
609.000000000008,66.11788010519547,-0.20324308953128473,-4.023570660095185
610.000000000008,66.21805195037498,-0.2025065622082293,-4.024881278464312
611.000000000008,66.3178535119199,-0.20027091470223518,-4.024880352911677
612.000000000008,66.41814257788491,-0.20432016896260585,-4.024066274772474
613.000000000008,66.51798162968203,-0.20259531267322198,-4.026045917311208
614.000000000008,66.61862278546202,-0.2018159750022894,-4.025785098771596
615.0000000000081,66.71868942935849,-0.2036914962654589,-4.024880072496943
616.0000000000081,66.81920360041396,-0.20317796450267778,-4.024824073847861
617.0000000000081,66.91932886379811,-0.20244955508307805,-4.026190069587002
618.0000000000081,67.01922773721728,-0.20247529801305897,-4.02487716837433
619.0000000000081,67.1202021225893,-0.20651271005076208,-4.024880164060274
620.0000000000081,67.22000000000078,-0.2062049406841139,-4.025185414356717
621.0000000000081,67.32000000000079,-0.20608497159610364,-4.023890071954402
622.0000000000082,67.41989451951284,-0.20936112232322132,-4.025206914468065
623.0000000000082,67.519630255073,-0.20958977347448873,-4.026552831269716
624.0000000000082,67.62051002431764,-0.20824504267414362,-4.02505482144659
625.0000000000082,67.71953285615115,-0.2116794900135001,-4.024879876584332
626.0000000000082,67.82058565996259,-0.21244345254106756,-4.026206873758911
627.0000000000082,67.9213591540685,-0.21616479777240827,-4.026415193420807
628.0000000000082,68.02172446190102,-0.21326195253001226,-4.026200103084423
629.0000000000082,68.1213342528029,-0.21230208063389527,-4.0262161125683935
630.0000000000082,68.22216552906069,-0.21572060313343494,-4.027180510179842
631.0000000000083,68.32255800581495,-0.21783743827937355,-4.025864249098773
632.0000000000083,68.42280272491718,-0.21829949693419506,-4.026768623732511
633.0000000000083,68.5240204165864,-0.2208405346880896,-4.027179808559762
634.0000000000083,68.62451814321815,-0.22030508313680158,-4.027179809043738
635.0000000000083,68.72417669920453,-0.2222266733608636,-4.027207678498511
636.0000000000083,68.82511410077599,-0.21962754616441788,-4.027123798719501
637.0000000000083,68.92518151957557,-0.21819556668020476,-4.025862052942824
638.0000000000084,69.02571412747189,-0.21849641131727526,-4.026860076406921
639.0000000000084,69.12620856445206,-0.21955875563237834,-4.027183071549331
640.0000000000084,69.22763106018951,-0.22074356615941115,-4.027210004330814
641.0000000000084,69.32753336877028,-0.2209408576640239,-4.028499843691503
642.0000000000084,69.42855653326842,-0.22064048512994844,-4.028499756207182
643.0000000000084,69.52820249235916,-0.22380196380246936,-4.027841614811076
644.0000000000084,69.6285818943444,-0.22253478573187446,-4.027179408707603
645.0000000000084,69.72989552286907,-0.22288546688951916,-4.02817244685891
646.0000000000084,69.82939432726785,-0.2233603163297845,-4.028146514373942
647.0000000000085,69.92979593509668,-0.22509237299190704,-4.029818474927809