File: 01_Data/EIFS_XPS/STA/N2/10K_min/EIFS_XPS_STA_N2_10KData_230203_R3.csv
##Temp./Â°C,Time/min,DSC/(mW/mg),Mass loss/mg
50.0,10.85043523384103,0.023060163517900856,0.00301911769267571
50.80000000000001,11.096458744326092,0.04899560760832844,-0.00018869757953821065
51.60000000000002,11.28061274932506,0.06506082883471476,0.0038642494428993146
52.400000000000034,11.438466203112787,0.07920096706761881,0.0020173110614236656
53.200000000000045,11.585130176026569,0.09176982438295567,0.005492479755559998
54.00000000000006,11.714485769477434,0.10200449915163623,0.00609315378034303
54.80000000000007,11.839283434205115,0.10963895621711783,0.008169464812161298
55.60000000000008,11.959867734729189,0.1151225415175694,0.004625974763813101
56.40000000000009,12.075187264636597,0.11950042963332819,-0.006057490371812246
57.2000000000001,12.185550795821907,0.12373611156978215,-0.007653413774521223
58.000000000000114,12.296392282819143,0.12911933584363067,0.005447813040621696
58.800000000000125,12.403334597436297,0.1311578709530774,0.0027613110276965003
59.600000000000136,12.50826249470893,0.13644571351350288,0.007826992128143306
60.40000000000015,12.609431871055389,0.13722769171148252,0.009576754326266812
61.20000000000016,12.712524879514534,0.1393736655276432,0.007022264788004495
62.00000000000017,12.81069003671007,0.1440464531401222,0.001726408669636026
62.80000000000018,12.908019730138879,0.14383666509220072,0.0012660482350956848
63.60000000000019,13.00416148254462,0.14774101043515286,0.004555896190706843
64.4000000000002,13.101417231208478,0.15015025755391775,0.004677569789456992
65.20000000000022,13.197546265578511,0.14937563877944782,0.003792282917228995
66.00000000000023,13.290830000000028,0.15306920629557563,0.0009900597095047203
66.80000000000024,13.385159806665108,0.15782360638585136,0.0007087563945940012
67.60000000000025,13.479771283239376,0.15852861871022483,0.0010851137798528754
68.40000000000026,13.571335698997055,0.1605751815009282,0.004682673403530568
69.20000000000027,13.663526541451958,0.1631395770508708,0.007605632355319081
70.00000000000028,13.751935546903963,0.16511674218777017,0.005617405964812416
70.8000000000003,13.843089384143157,0.1646850845662493,0.002416849212760308
71.6000000000003,13.93371942281627,0.1686791249709867,0.001442770442005692
72.40000000000032,14.020830000000036,0.1689130006140267,0.004159892505847029
73.20000000000033,14.108982649351,0.17149153509547777,-1.1395691539739516e-05
74.00000000000034,14.196280874801952,0.17076672547247118,-0.0040227279102089675
74.80000000000035,14.283548832186613,0.1705700226831861,-0.002341666698669531
75.60000000000036,14.36893035035923,0.17160600858110597,0.0008248037046927337
76.40000000000038,14.456810597287433,0.1736721531761969,0.000899133026247334
77.20000000000039,14.541863763442915,0.170692261634376,0.004961301000874219
78.0000000000004,14.627996213920305,0.17251645763873613,0.005590173895443584
78.80000000000041,14.714179429108718,0.1736186010413372,0.006690884362433813
79.60000000000042,14.797422481041728,0.17427461358248664,0.0039148660095409404
80.40000000000043,14.882607908913654,0.17491325106473488,0.003839594540241187
81.20000000000044,14.967027351485596,0.17566845866845515,0.0027767380038166145
82.00000000000045,15.050136688251582,0.1781754376052267,0.005819967732050735
82.80000000000047,15.133752830223855,0.17945504805226342,0.0077770033177451126
83.60000000000048,15.217418115991926,0.18137283623374412,0.003274329387183972
84.40000000000049,15.29980802829305,0.18367909773313573,-0.002313764246923089
85.2000000000005,15.38112108615022,0.18582182473290088,0.0003879758606495365
86.00000000000051,15.461156915881336,0.18644408346227603,0.006347433820600212
86.80000000000052,15.545889402434296,0.186336289823807,0.009360262883657988
87.60000000000053,15.626972595184256,0.1870468015518405,0.005075026408786432
88.40000000000055,15.709095551013393,0.19059655250399477,5.999775584442091e-05
89.20000000000056,15.790428025758514,0.19211082436986526,0.0008737138099137454
90.00000000000057,15.871227847795765,0.1947408638063517,0.002327215810986605
90.80000000000058,15.951022329377421,0.19833673651801864,0.0011288469709023197
91.60000000000059,16.032012652072634,0.20277452225132953,-0.00044685131004662537
92.4000000000006,16.11137325463509,0.20802330082091314,0.0010974855965479868
93.20000000000061,16.191109731434363,0.20729427942105594,0.0024115855951194476
94.00000000000063,16.27139296045775,0.21190581729674152,0.0003370296148292873
94.80000000000064,16.351839503331906,0.214793987151637,0.0003269144412256786
95.60000000000065,16.430158128836332,0.21876903129957959,0.0016396283519557464
96.40000000000066,16.506417618097057,0.22092249626181015,0.0029599653053331565
97.20000000000067,16.588459376357427,0.2268097087850628,0.0039175974565801575
98.00000000000068,16.66840988301835,0.23197294459253248,0.0010948494555038657
98.8000000000007,16.745798269929587,0.23588903815413897,0.00029383768434776414
99.6000000000007,16.825470303168363,0.24314797005396027,0.0013223991744775176
100.40000000000072,16.90366979615714,0.2496165355778508,0.0002748063016775326
101.20000000000073,16.98167836822052,0.25682236490927557,0.0024938964715275347
102.00000000000074,17.05953719235842,0.2668124669284836,0.0017492288442682025
102.80000000000075,17.138755299077925,0.2764572186397394,-0.0009145433823376514
103.60000000000076,17.216248917659893,0.28838478740721785,-0.001732655409896644
104.40000000000077,17.294362153832164,0.300105533954633,-0.000957295602599384
105.20000000000078,17.37211828160245,0.31360171198990183,-0.0012577772855788538
106.0000000000008,17.45034802840019,0.3247289315450217,-0.003976475056706175
106.80000000000081,17.52844445605865,0.3373620342428104,-0.0027295538592224666
107.60000000000082,17.60703975168345,0.34538001251735684,0.00015189679069438355
108.40000000000083,17.684411512524388,0.3522030119022288,0.001535691239079373
109.20000000000084,17.762334783811585,0.35898320641808557,-0.0015857775733567614
110.00000000000085,17.8392110469237,0.3618463782533742,-0.005937272195890131
110.80000000000086,17.917298172149305,0.36278418767131104,-0.00869197167121838
111.60000000000088,17.9915176757352,0.3613693642018644,-0.004462107159198592
112.40000000000089,18.068569430243347,0.3551596819933496,-0.004517148023615913
113.2000000000009,18.14959242247441,0.3479333222131651,-0.007376080045856437
114.00000000000091,18.226237193243755,0.33754106189777633,-0.007330072531208209
114.80000000000092,18.305002432524333,0.3270416408929264,-0.008679191698238053
115.60000000000093,18.381124608131323,0.3137164930097406,-0.007360230312912552
116.40000000000094,18.45862281430221,0.3002245432721715,-0.007378319020323154
117.20000000000095,18.535868053754612,0.2893334983898028,-0.007364850079532914
118.00000000000097,18.612125279552185,0.28306151038250915,-0.008684794871812063
118.80000000000098,18.689809182551222,0.2781706252145011,-0.010243676763300513
119.60000000000099,18.76518668705751,0.2743942048256066,-0.012620185198769285
120.400000000001,18.84148139025165,0.2719718835764381,-0.012629284006388186
121.20000000000101,18.918958506019028,0.26921333056179797,-0.009865485475800906
122.00000000000102,18.99516208409528,0.26645486482414726,-0.008260664995908495
122.80000000000103,19.074844401861412,0.26154710250459834,-0.005634088213914534
123.60000000000105,19.15041190902376,0.2633038606703464,-0.00688659200252717
124.40000000000106,19.22827161695537,0.2597152196247422,-0.006960691699166688
125.20000000000107,19.30492694652778,0.25974332832467084,-0.006709356210195416
126.00000000000108,19.38048221343464,0.25865787295709897,-0.0050602348929373875
126.80000000000109,19.45732319283031,0.25878127208575263,-0.003787085899602083
127.6000000000011,19.534756891173974,0.2600019949836667,-0.007853106059229287
128.4000000000011,19.6106294913997,0.25949087084608835,-0.007798914683443847
129.20000000000113,19.686694922405945,0.25942815511920203,-0.009281465149764578
130.00000000000114,19.759255736931962,0.25999929153931967,-0.01186284934546622
130.80000000000115,19.838890320016876,0.2606983237917495,-0.01218605406930573
131.60000000000116,19.915125881838645,0.262256782921774,-0.010804736917647606
132.40000000000117,19.991905929209718,0.260790128932598,-0.010688279725335814
133.20000000000118,20.068936252550277,0.26073733886009676,-0.012130398581634338
134.0000000000012,20.14401693126076,0.2607448504577038,-0.012757581504606819
134.8000000000012,20.221719779288698,0.26019336012487315,-0.012367761601132177
135.60000000000122,20.29691810971891,0.2599493244721318,-0.011414214587324611
136.40000000000123,20.371549277229825,0.25918944994705495,-0.011100642707648767
137.20000000000124,20.445292446266286,0.26075182646116324,-0.013508472985912068
138.00000000000125,20.523609422878593,0.2602245111098892,-0.010870351614411522
138.80000000000126,20.59952188520109,0.26054156298895026,-0.009544320693358532
139.60000000000127,20.675840847976954,0.26042859422677955,-0.006586277191823253
140.40000000000128,20.750830935693582,0.2589917766125115,-0.006699912168708799
141.2000000000013,20.82681716224099,0.26165657374553275,-0.009877876888696235
142.0000000000013,20.90138160937447,0.2630193183141205,-0.014546382398100022
142.80000000000132,20.978753217257804,0.26397033855806273,-0.015080941344728593
143.60000000000133,21.05360197089628,0.26326375916842515,-0.012535605273496397
144.40000000000134,21.128976822429642,0.2647280987948947,-0.008263390408708826
145.20000000000135,21.204292571133507,0.26293992348971607,-0.006937723536597051
146.00000000000136,21.279455316945793,0.26446429977460906,-0.008236469313445127
146.80000000000138,21.355103148491736,0.2658961537119232,-0.011059346657858349
147.6000000000014,21.430640221322413,0.2643087700329201,-0.013511393997202248
148.4000000000014,21.50548419932359,0.2655743403345415,-0.01228697452833094
149.2000000000014,21.582225920441946,0.26746876069038605,-0.011269475195598844
150.00000000000142,21.656594433431003,0.26736897264130155,-0.010841492520023532
150.80000000000143,21.73177101925929,0.26658497522616664,-0.010590009373176112
151.60000000000144,21.80903127345823,0.26977568074086855,-0.009396095133054061
152.40000000000146,21.883072256814632,0.266954194077502,-0.012059254809036357
153.20000000000147,21.958788332927035,0.2700502544727903,-0.012079723647011598
154.00000000000148,22.03401756064864,0.27122277892022295,-0.013035083325351415
154.8000000000015,22.10882497238554,0.2707350738555141,-0.013620145264320538
155.6000000000015,22.185245004405225,0.2710102945745948,-0.012212116364267889
156.4000000000015,22.261026409010114,0.27092369629549584,-0.011012108189608405
157.20000000000152,22.334734685176418,0.2714262846244091,-0.012298801669821557
158.00000000000153,22.410162769926604,0.2709776109657346,-0.0123005917156922
158.80000000000155,22.48641783359537,0.27199507987197347,-0.013611998211335852
159.60000000000156,22.560725585791328,0.27361588775368384,-0.014939864247851986
160.40000000000157,22.6360851253457,0.27335663032497726,-0.01463574475940499
161.20000000000158,22.71203441915645,0.2722608179312015,-0.010768744026626642
162.0000000000016,22.787047412978684,0.2718097444093256,-0.00945886121255235
162.8000000000016,22.85926679276212,0.27155001438653315,-0.009439019569183582
163.60000000000161,22.938667955980883,0.27111171534408096,-0.009903239745563841
164.40000000000163,23.01242321795473,0.27422955087349166,-0.01188344939003727
165.20000000000164,23.085822370224893,0.27243782606964473,-0.012080172918486731
166.00000000000165,23.163395154546702,0.2728757863773217,-0.010774483210819419
166.80000000000166,23.23930330057787,0.2731716052065677,-0.011110836402897561
167.60000000000167,23.312781069692637,0.27405311884358263,-0.012426291059237204
168.40000000000168,23.388553967746393,0.27416007737056114,-0.013900602607239687
169.2000000000017,23.46600680306435,0.2744339580273647,-0.015160560995303385
170.0000000000017,23.540733911914174,0.2747326972851315,-0.014178183822733281
170.80000000000172,23.616139163611354,0.2734997646681273,-0.012530648520487908
171.60000000000173,23.692041326046272,0.27483445821277064,-0.010980953775606928
172.40000000000174,23.767362070170723,0.2757669942317855,-0.011026724931808563
173.20000000000175,23.842488051413827,0.2731446003604948,-0.009670142646459823
174.00000000000176,23.91977376392998,0.2753586418715137,-0.009670152821725786
174.80000000000177,23.992771891537817,0.2743276351550531,-0.009138256459114036
175.60000000000178,24.066728950819083,0.2723400490868033,-0.006247979806408566
176.4000000000018,24.144386759147608,0.2735607477200632,-0.009650680475006279
177.2000000000018,24.21951905071338,0.2748637879002038,-0.014051184967789343
178.00000000000182,24.294617184374108,0.277342356351593,-0.017693252807750248
178.80000000000183,24.370830000000183,0.27691907035789187,-0.01734866060947038
179.60000000000184,24.44619805567627,0.2771435815344595,-0.01823973576509763
180.40000000000185,24.520830889024133,0.27708915696386205,-0.017680034994890015
181.20000000000186,24.596281228792023,0.27351691112658594,-0.013201518652647959
182.00000000000188,24.67073106043285,0.2740081592068341,-0.009447100589710988
182.8000000000019,24.746730111896838,0.27522763840380937,-0.008510858285291079
183.6000000000019,24.820451724669812,0.27497078095787353,-0.012515829715952886
184.4000000000019,24.89639682456316,0.2774264326533088,-0.016556840686355656
185.20000000000192,24.971898327786548,0.2785297644542487,-0.019099744123370677
186.00000000000193,25.04676965874761,0.2775231143059761,-0.019030728698119947
186.80000000000194,25.120830000000193,0.2779782437293311,-0.018118712609954457
187.60000000000196,25.196399971763586,0.2789070051987558,-0.01937125865907996
188.40000000000197,25.27224657729881,0.27811878947588264,-0.01943720986368591
189.20000000000198,25.345511461007053,0.28054123570467604,-0.01797883591919236
190.000000000002,25.420659562823996,0.27813061932922345,-0.01800996964101298
190.800000000002,25.495892028448303,0.2795085192892135,-0.019250001009440076
191.600000000002,25.569743423183432,0.27882362439037695,-0.016617514975991732
192.40000000000202,25.645853552751316,0.27968165840683024,-0.01463591622070437
193.20000000000203,25.722532965250974,0.2789114964368937,-0.015384988146006418
194.00000000000205,25.79655331881283,0.2774575906698965,-0.015914752706441604
194.80000000000206,25.87128222627771,0.2784635752563689,-0.018580369474722414
195.60000000000207,25.947120505464266,0.2786825969204828,-0.019859322817016523
196.40000000000208,26.021843166701128,0.2802196907870978,-0.019595135491627502
197.2000000000021,26.097031121097658,0.2800992474934522,-0.01888927209131941
198.0000000000021,26.17257945720879,0.2811555562196556,-0.01841388165814406
198.80000000000211,26.246724132605294,0.2781705406264162,-0.01770672291836295
199.60000000000213,26.32303995820344,0.2799849484175926,-0.01636331103620625
200.40000000000214,26.397525542821064,0.2800181578240194,-0.01778893360718925
201.20000000000215,26.473014292816096,0.27956797510816855,-0.01646681362821134
202.00000000000216,26.547607831953833,0.27906853569568807,-0.017909680168173736
202.80000000000217,26.623290815300408,0.28299832054820273,-0.021426093021315484
203.60000000000218,26.6984750279972,0.2818845331749393,-0.022841626704192652
204.4000000000022,26.772749953181947,0.2831914635958476,-0.021524162745436115
205.2000000000022,26.849391780515322,0.28273641149776696,-0.02021000955751484
206.00000000000222,26.922691027873004,0.28549272199426184,-0.020218639253142268
206.80000000000223,26.998495308611552,0.2852011652000658,-0.021530417721960404
207.60000000000224,27.07301395283149,0.28607351098974576,-0.022828865166030443
208.40000000000225,27.148770069871844,0.2859961307777367,-0.02416117657335537
209.20000000000226,27.224246770012872,0.28542534435464273,-0.024173288117580682
210.00000000000227,27.298570818689427,0.28696482158436226,-0.020397008504301706
210.80000000000229,27.375492208441912,0.2850713396205225,-0.022278343956958935
211.6000000000023,27.44937678143315,0.28386634283804757,-0.02229008612543737
212.4000000000023,27.52481263761274,0.28572462790519765,-0.02333418801757592
213.20000000000232,27.600499115675348,0.2865426581136266,-0.022511026385775956
214.00000000000233,27.67565322673141,0.2884501654303883,-0.022501994026518535
214.80000000000234,27.75060266325157,0.28623484247867104,-0.022511851204008337
215.60000000000235,27.826190433370083,0.2891749545358829,-0.023854393354425518
216.40000000000236,27.901260270460202,0.2896892007696894,-0.0265604412477769
217.20000000000238,27.973537407916286,0.2892993685205258,-0.026563030716352465
218.0000000000024,28.051213546354013,0.2910592880800778,-0.02481523530679519
218.8000000000024,28.125375371754075,0.29071556552624916,-0.019864964852300826
219.6000000000024,28.202483714616267,0.290168327629841,-0.022901336109163672
220.40000000000242,28.278333747791752,0.29093694169069745,-0.026694891246109353
221.20000000000243,28.354251662940694,0.2934655194490769,-0.03107668475622427
222.00000000000244,28.426394944673522,0.2917834330422333,-0.029229354211743885
222.80000000000246,28.504710688268247,0.293578465322383,-0.029814663002107
223.60000000000247,28.579833882435075,0.2918964302305923,-0.029659503158569578
224.40000000000248,28.654825047915274,0.2944752677779577,-0.030199768795578397
225.2000000000025,28.73107819637055,0.29361788881296225,-0.028872175711641912
226.0000000000025,28.80627883129834,0.29305282344470457,-0.026885916143538413
226.8000000000025,28.88172495472402,0.2907521882601326,-0.024160663644507085
227.60000000000252,28.956762335321855,0.2894496709755468,-0.02558140118005614
228.40000000000254,29.0316949691012,0.2895776737606027,-0.026009657982675183
229.20000000000255,29.10745597356735,0.29048566731251224,-0.025470374309937593
230.00000000000256,29.183268183804827,0.2898612960056331,-0.026798016943385683
230.80000000000257,29.258619366447814,0.28974390184678184,-0.026663409587233566
231.60000000000258,29.33508831924626,0.28886596396547903,-0.025370467521737883
232.4000000000026,29.410263977475626,0.2874422185949942,-0.028192309434909912
233.2000000000026,29.484959741435496,0.2905261886749371,-0.03052340353714822
234.00000000000261,29.561548611224822,0.29091623304875275,-0.03538093201886161
234.80000000000263,29.63553048189522,0.2902243477083556,-0.036017814232823575
235.60000000000264,29.712028115187643,0.2930171069014697,-0.034689975422140584
236.40000000000265,29.78624587064872,0.29371600104516754,-0.034689935911313974
237.20000000000266,29.862900514026155,0.2929994882874585,-0.03468982194917336
238.00000000000267,29.937749313214635,0.29441838686205263,-0.03349960605215374
238.80000000000268,30.01313732442103,0.29219767507566907,-0.03070498188632076
239.6000000000027,30.088686162829653,0.2921534298488168,-0.03210068617372208
240.4000000000027,30.163973754363564,0.2953362532301101,-0.03207709707893258
241.20000000000272,30.23819972026905,0.29280050201669566,-0.032062707892606124
242.00000000000273,30.315009846588737,0.2930207920816972,-0.03337977580909168
242.80000000000274,30.389596252170655,0.29579154895414883,-0.033350309972085324
243.60000000000275,30.46515345269371,0.2957446579607043,-0.035734178552324636
244.40000000000276,30.54031875152716,0.29438407446610276,-0.03733013060022694
245.20000000000277,30.61531624686147,0.2954081470673063,-0.03595547725420145
246.00000000000279,30.692391267572447,0.2937506339420533,-0.03472491946908596
246.8000000000028,30.76725189219315,0.2935021415632599,-0.033377887080336954
247.6000000000028,30.841121499896364,0.29321501553151913,-0.03207010047641168
248.40000000000282,30.91741360032811,0.2951055783836237,-0.032066871460024515
249.20000000000283,30.99371249364622,0.29521023401170204,-0.03413121659965723
250.00000000000284,31.068734905510496,0.29721136901615636,-0.03600990501740098
250.80000000000285,31.14387608798037,0.2979237827198071,-0.03619317326094018
251.60000000000286,31.219415450382133,0.2974453379127786,-0.03732984952164786
252.40000000000288,31.293137046349575,0.297145781194878,-0.03600569193846326
253.2000000000029,31.3702705902112,0.2970987260045651,-0.03469445768246482
254.0000000000029,31.447268196341717,0.29772274400517834,-0.03605223387328049
254.8000000000029,31.522215157754374,0.2972399787471245,-0.03700384455074346
255.60000000000292,31.59724899313241,0.2967690648907722,-0.03862608298408032
256.40000000000293,31.673552792435213,0.2972797640188633,-0.04150543976690324
257.20000000000294,31.748844686331815,0.29778359707096136,-0.044130252177579266
258.00000000000296,31.825515029518378,0.29964013105978876,-0.04413699183233888
258.80000000000297,31.900573037040715,0.29838975363902076,-0.04280315757414055
259.600000000003,31.97520010296336,0.2984060054408779,-0.04021206367159058
260.400000000003,32.05207611552417,0.29846351834233725,-0.03602973130234721
261.200000000003,32.126753610355415,0.2980453170380938,-0.03603683113930645
262.000000000003,32.20332078033204,0.2985874765242763,-0.03664913925515423
262.800000000003,32.279551430809626,0.29704193643941745,-0.036670616533173384
263.60000000000304,32.35509106683724,0.2993618291023609,-0.03799399968396733
264.40000000000305,32.43158217288145,0.2991864654367752,-0.040659354940224546
265.20000000000306,32.50681349803089,0.29992346473346904,-0.0411804208452371
266.00000000000307,32.58275610992769,0.3019228576366214,-0.04390977122318995
266.8000000000031,32.658092532065254,0.30254764277183366,-0.044152571393314854
267.6000000000031,32.73404441377799,0.30072568141329525,-0.043923016638482526
268.4000000000031,32.80910248927471,0.3008732108789429,-0.04390662304971826
269.2000000000031,32.886641092438964,0.3026363306582488,-0.04523582216660049
270.0000000000031,32.96205504977529,0.30180551255473237,-0.04491725143897041
270.80000000000314,33.03743837769431,0.3039673447695754,-0.04644351645688882
271.60000000000315,33.11398722941837,0.3049733288081576,-0.048314169146360886
272.40000000000316,33.18707588711625,0.30494146352104473,-0.04678182179992474
273.2000000000032,33.26456640721073,0.30408958374491735,-0.04402976655696067
274.0000000000032,33.340552319532506,0.3064814310194006,-0.04544395139954016
274.8000000000032,33.417049079576216,0.30588345368262965,-0.0424830582185276
275.6000000000032,33.49267853097306,0.307430081883419,-0.04249002299237059
276.4000000000032,33.568136135761286,0.30721938373188623,-0.041580891045904345
277.20000000000323,33.64301598754307,0.30911160464218596,-0.041228699653904854
278.00000000000324,33.72008342193087,0.30922458526368535,-0.04241667920558578
278.80000000000325,33.7958113377117,0.31077751067313353,-0.045327713801631475
279.60000000000326,33.871028701367386,0.3113381056195751,-0.04512998957196901
280.4000000000033,33.945714647284575,0.31147609854921665,-0.0464591029353576
281.2000000000033,34.02313971325242,0.3125537838767429,-0.045777871770857015
282.0000000000033,34.09933630945641,0.3133992754447308,-0.048554707410302544
282.8000000000033,34.17492373611613,0.31099484362390495,-0.04973992719436415
283.6000000000033,34.25082894694871,0.31117259983820705,-0.04973986626148097
284.40000000000333,34.32725569603033,0.3102580521607724,-0.04940887057025245
285.20000000000334,34.40318127937322,0.31112925432405975,-0.04697318401041173
286.00000000000335,34.479033130989684,0.30769945475985067,-0.04467291571376952
286.80000000000337,34.55605388525389,0.309104478874178,-0.04184512282792685
287.6000000000034,34.6315238030914,0.31088359168982616,-0.039293560192389165
288.4000000000034,34.70840150172755,0.3088759539888227,-0.04338748130859171
289.2000000000034,34.78499336840855,0.3105085527491167,-0.04661777076568541
290.0000000000034,34.8605079697702,0.31061884761963554,-0.04905415455321904
290.8000000000034,34.936951194042194,0.31351387326572844,-0.05136969419511406
291.60000000000343,35.01261753022601,0.31242307000777364,-0.04903837390059884
292.40000000000344,35.08960535349762,0.3148450664144571,-0.04853148567675447
293.20000000000346,35.165425464907685,0.31347758880935733,-0.05117580142886391
294.00000000000347,35.240492354043695,0.31625112311350667,-0.05260120685048042
294.8000000000035,35.31685768419449,0.3184818112568808,-0.053943939341854374
295.6000000000035,35.393960520544944,0.3192294086450189,-0.05523414380705294
296.4000000000035,35.46782344531802,0.31919662852197217,-0.053975332886821104
297.2000000000035,35.545551724986574,0.31967152826115147,-0.051266170241810016
298.0000000000035,35.62065121103694,0.320203131238076,-0.049959946730309124
298.80000000000354,35.69779431749208,0.32024427978850706,-0.050068307892600306
299.60000000000355,35.77355156906534,0.32137202796814474,-0.05642361555560571
300.40000000000356,35.8472764766312,0.32253176155504926,-0.060352820178441124
301.20000000000357,35.926162258890095,0.3220680172775233,-0.06291502746362587
302.0000000000036,36.00254433978432,0.32265246538432135,-0.06015148573528384
302.8000000000036,36.078186489483095,0.3234097739486179,-0.05852749659817302
303.6000000000036,36.15447209328022,0.3243668419791047,-0.06004162358875753
304.4000000000036,36.23083091270685,0.32179852657804275,-0.057530022893264476
305.2000000000036,36.30622442111288,0.3225384040912587,-0.05483864978560282
306.00000000000364,36.38208427387248,0.31991442301714323,-0.058427293617430376
306.80000000000365,36.459533986365,0.323758643649248,-0.06531560447687079
307.60000000000366,36.53428390607665,0.32411996647860686,-0.06209405595962458
308.4000000000037,36.61101606307906,0.3235083255835497,-0.0593503164007565
309.2000000000037,36.68706879591126,0.3228335484308741,-0.05885762498193836
310.0000000000037,36.76360357961784,0.32263361101226473,-0.06232412221351913
310.8000000000037,36.840209791436834,0.32282392574579216,-0.06247041029384315
311.6000000000037,36.91624649716965,0.3236613483047231,-0.061148394382406046
312.40000000000373,36.99295227129076,0.3226622767745714,-0.06408089871822797
313.20000000000374,37.06886702871677,0.3274198709109748,-0.06705750509744712
314.00000000000375,37.14446361188457,0.3279860186156981,-0.07121066450076974
314.80000000000376,37.221500759620184,0.32803739870245846,-0.07277921979001745
315.6000000000038,37.297600600692746,0.32893493865419726,-0.06397923305130204
316.4000000000038,37.37387278378472,0.3274839320543045,-0.05863913179141056
317.2000000000038,37.450182574416615,0.3272949753298455,-0.06047174551438683
318.0000000000038,37.526807837980876,0.3296496019740699,-0.06414065620863196
318.8000000000038,37.60201044345,0.3283147814009252,-0.06851783019339708
319.60000000000383,37.67918631625194,0.32983582746424234,-0.06851330552978174
320.40000000000384,37.75550689116582,0.3303413035800966,-0.06983372513189545
321.20000000000385,37.83232394710743,0.3321430212044378,-0.06686340035737492
322.00000000000387,37.90832754945413,0.33236643021089696,-0.06576677041781975
322.8000000000039,37.98568892063877,0.3332254682093311,-0.07140822668364111
323.6000000000039,38.06159467291455,0.3348012574544949,-0.07482128149922396
324.4000000000039,38.13916675175536,0.33376666906777164,-0.06743111276112712
325.2000000000039,38.21560980547271,0.3352128843275246,-0.06780303913286945
326.0000000000039,38.29227473707034,0.3345896896122832,-0.07032831474513657
326.80000000000393,38.36885212751145,0.33827133215049243,-0.07419888783654827
327.60000000000394,38.445713001438314,0.34161764229057967,-0.07861298783176807
328.40000000000396,38.52178279444441,0.34141065960818107,-0.07934932149171692
329.20000000000397,38.59677545698547,0.341232781073885,-0.07997439192088995
330.000000000004,38.67522954758557,0.3439463208458676,-0.08201832898566996
330.800000000004,38.7516808433318,0.34404607563495915,-0.0820182901133717
331.600000000004,38.828192959801676,0.3450658510138733,-0.07873700199201794
332.400000000004,38.90458606821035,0.34531817281109684,-0.0759442661574381
333.200000000004,38.981848308259686,0.3465636816147773,-0.0797407927046021
334.00000000000404,39.05824672643176,0.3507526344012539,-0.0860809921371457
334.80000000000405,39.13543293974299,0.3488630415897682,-0.09204445753183021
335.60000000000406,39.21239562261864,0.3516593782662904,-0.09115809701653976
336.40000000000407,39.28860894133974,0.34969338023455976,-0.08698047017552657
337.2000000000041,39.36579260805188,0.3531314771162728,-0.08696013831086224
338.0000000000041,39.4429449542483,0.3520715558546903,-0.0869601282171768
338.8000000000041,39.519766375128306,0.35501412092898954,-0.08829794492816223
339.6000000000041,39.59452889961447,0.35321059358830453,-0.08617861043396635
340.4000000000041,39.672162947240636,0.35479642671194345,-0.08747537204649358
341.20000000000414,39.75064545410983,0.3580642144066338,-0.08940213133443331
342.00000000000415,39.82667482313715,0.35584145908150316,-0.09104412775724091
342.80000000000416,39.902875654909984,0.3599721269863505,-0.09180868927184704
343.6000000000042,39.980481492001395,0.3619476075085568,-0.09603011337121004
344.4000000000042,40.057400259378106,0.36617491265014035,-0.09733047430859276
345.2000000000042,40.13426825987728,0.36959111102595127,-0.10131971867594336
346.0000000000042,40.21003244354569,0.36966874879054223,-0.1041398156201887
346.8000000000042,40.2876565617579,0.37406492467960356,-0.10683347250109021
347.60000000000423,40.364490152009935,0.3757302388596212,-0.10680945644904138
348.40000000000424,40.44214339278683,0.3797816461889345,-0.1055462157219389
349.20000000000425,40.51825328372076,0.37747598099404966,-0.10169689683161742
350.00000000000426,40.59598449490545,0.38124582236977317,-0.10493609762241052
350.8000000000043,40.67326938164426,0.3837268491349685,-0.10900992765426176
351.6000000000043,40.75082900796236,0.3868098230910952,-0.11385977444486484
352.4000000000043,40.82818085101874,0.39093892720494694,-0.11386047793344023
353.2000000000043,40.90366549227876,0.39275258207711955,-0.11649299459267537
354.0000000000043,40.98004750906531,0.39743481465653885,-0.11913594141563744
354.80000000000433,41.058010864840774,0.3990687587423361,-0.11911972149433492
355.60000000000434,41.1350455951507,0.4022980145402633,-0.12187524517238879
356.40000000000435,41.21101924653575,0.40568609586062715,-0.12350854495688779
357.20000000000437,41.28791924345926,0.4072895933108871,-0.12351310628746903
358.0000000000044,41.366714307375126,0.41194990777297286,-0.1274643731574634
358.8000000000044,41.44167089115346,0.41596417910858213,-0.13143356631201142
359.6000000000044,41.52036681600217,0.42326262239539736,-0.1399411334484273
360.4000000000044,41.59806806926965,0.42714101177841424,-0.1437184087732044
361.2000000000044,41.67382813846616,0.4323266428310838,-0.14622683439957695
362.00000000000443,41.7511011503427,0.4371855480542709,-0.14471314502689792
362.80000000000445,41.82954011425802,0.444007726760722,-0.14644640977336687
363.60000000000446,41.90640707124458,0.44936143195094436,-0.14770761731189141
364.40000000000447,41.98317472821667,0.4541961733559286,-0.15037097015001466
365.2000000000045,42.06064336890911,0.46162791050898294,-0.15436092255073097
366.0000000000045,42.13735296595985,0.46739640144316363,-0.15730845501050927
366.8000000000045,42.21518614224741,0.47589081473059325,-0.15976125704430855
367.6000000000045,42.29301778309517,0.48451386786712486,-0.16491799404320107
368.4000000000045,42.36922983071655,0.4924930655757477,-0.16988445309784606
369.20000000000454,42.447630720496406,0.5063370273697639,-0.1762466158936178
370.00000000000455,42.524690139649245,0.5135770252900916,-0.1839377415687835
370.80000000000456,42.60257407753373,0.5265470051463015,-0.18811902050652973
371.60000000000457,42.67961796474737,0.5372945095021813,-0.19148478553559256
372.4000000000046,42.75655447709686,0.5517910317956132,-0.19634895029230304
373.2000000000046,42.83517663968731,0.5653904189037419,-0.20529653401271775
374.0000000000046,42.91227024328439,0.5769837626555492,-0.21578755775850667
374.8000000000046,42.98916196146937,0.5896614833414346,-0.21886791113063753
375.6000000000046,43.0668839315715,0.6074957349817294,-0.22576516349632758
376.40000000000464,43.14487834335935,0.6220459133277998,-0.23118249659451795
377.20000000000465,43.221122671770146,0.6429502780139232,-0.23791804945230632
378.00000000000466,43.29956895844512,0.6599116642507228,-0.24604414423624288
378.8000000000047,43.37771994843297,0.6816201261263899,-0.25532552626189764
379.6000000000047,43.45482945687813,0.7037410869124636,-0.2647929295377476
380.4000000000047,43.53217473623843,0.72477112546642,-0.27290056625574133
381.2000000000047,43.60934841162733,0.7492624666069485,-0.27906500895149877
382.0000000000047,43.68699905553439,0.7746252128039853,-0.29708761365676306
382.80000000000473,43.76561591001593,0.8012209869636537,-0.31057090694610423
383.60000000000474,43.84247997260101,0.8345533033820055,-0.3217297570334203
384.40000000000475,43.91966957376203,0.8610366323058987,-0.3313013341450204
385.20000000000476,43.99751143444113,0.8922944626318464,-0.3441483865680923
386.0000000000048,44.07499642440662,0.9231818324182519,-0.35717404816227516
386.8000000000048,44.15200435993909,0.959667538694076,-0.37206913418003085
387.6000000000048,44.23052450055326,0.9987332539754809,-0.38692582202598347
388.4000000000048,44.30766025682598,1.0397466539888633,-0.4037361874448542
389.2000000000048,44.386058238377956,1.083853787196442,-0.42097410459405804
390.00000000000483,44.46313876922457,1.1268230832283552,-0.43921203778710405
390.80000000000484,44.539070018402775,1.1707856267633163,-0.4601627171999332
391.60000000000485,44.61858514388805,1.2235474460217843,-0.48046754744492004
392.40000000000487,44.69734273571689,1.274725767090529,-0.5016110473661533
393.2000000000049,44.77427427548732,1.32708469557566,-0.5243158096718155
394.0000000000049,44.85303381215564,1.3862368458087853,-0.5483584071682186
394.8000000000049,44.93072212728728,1.4522923283989535,-0.5765661813117844
395.6000000000049,45.00906559664175,1.5139135888621085,-0.6069761340779531
396.4000000000049,45.08636786425609,1.5857678614589727,-0.6380766105071287
397.20000000000493,45.16490824861919,1.6551640780420842,-0.6676899295981515
398.00000000000495,45.24340661591012,1.733735054867501,-0.7016476323693435
398.80000000000496,45.32131494021507,1.8058430014967186,-0.7351592736123114
399.60000000000497,45.39906863448351,1.8774714319029735,-0.7712353723885692
400.400000000005,45.478239844226664,1.970064844481381,-0.8098256900279139
401.200000000005,45.55559822733875,2.056001414942353,-0.8496811342413113
402.000000000005,45.63493778527878,2.1383352478743807,-0.8933367009229412
402.800000000005,45.712848522604716,2.2245244303751783,-0.9395732705730504
403.600000000005,45.79131015603929,2.317469044104742,-0.9867014129818736
404.40000000000504,45.87033489859281,2.4121907012484742,-1.0380118085854746
405.20000000000505,45.94805029553511,2.52239881203368,-1.0893247882921546
406.00000000000506,46.026244338253676,2.6281057682897058,-1.1455290613409064
406.80000000000507,46.106079229419926,2.7154813664972073,-1.2045974260298165
407.6000000000051,46.18417527169406,2.8082767995485263,-1.2628870365468998
408.4000000000051,46.26276203789889,2.911547583618674,-1.330789633330704
409.2000000000051,46.34124935498686,3.0030542505922906,-1.3973951418854607
410.0000000000051,46.41972829715807,3.102396689577336,-1.4636251880583102
410.8000000000051,46.49770628832922,3.192341112627142,-1.5327515435804475
411.60000000000514,46.57578600107987,3.285603044129404,-1.603274414307466
412.40000000000515,46.65472935931623,3.3675150548330937,-1.676793857844796
413.20000000000516,46.73397393922517,3.4487167982722484,-1.7564720523933643
414.0000000000052,46.812724990698406,3.515805485845706,-1.8367394344568666
414.8000000000052,46.8917257285756,3.5984653049154356,-1.9196921804149913
415.6000000000052,46.97033099647793,3.6601513941116828,-2.0049615475997244
416.4000000000052,47.04920360295704,3.7242294811291385,-2.0958721118751904
417.2000000000052,47.12740096115946,3.7672294610802384,-2.1849075142419325
418.00000000000523,47.20515781963767,3.7826669785645746,-2.2741927714939987
418.80000000000524,47.283935929285676,3.8012360937624714,-2.360344842936391
419.60000000000525,47.36131964158558,3.802639785736509,-2.4495156012508117
420.40000000000526,47.440730034743936,3.78019859165423,-2.5415771185300366
421.2000000000053,47.51918242540808,3.7386672494990836,-2.6299418977994735
422.0000000000053,47.596380731570086,3.69136014602431,-2.716293225964132
422.8000000000053,47.67452307687876,3.620484945549619,-2.8019413879416986
423.6000000000053,47.752276822913565,3.5244649717781544,-2.8838220816554285
424.4000000000053,47.83072685335549,3.410532948812785,-2.9663777673497513
425.20000000000533,47.90826925739962,3.283677963612324,-3.043969420936437
426.00000000000534,47.985190545818156,3.132968523173947,-3.1193775546629845
426.80000000000535,48.063796814509175,2.9742947619321307,-3.196340929573326
427.60000000000537,48.140924367920604,2.8048186782804,-3.262821426304775
428.4000000000054,48.21816629656699,2.6236218202309494,-3.330271531998428
429.2000000000054,48.295720619244904,2.43206431020596,-3.3912951407769776
430.0000000000054,48.372668795597086,2.235047084096078,-3.444843476158744
430.8000000000054,48.449693482385044,2.036572927637266,-3.4968089230304207
431.6000000000054,48.52676457023534,1.842678185784628,-3.543689627460174
432.40000000000543,48.60328961132262,1.6511232633357675,-3.582570862609496
433.20000000000545,48.68048547698649,1.4694550890016926,-3.6188397044304854
434.00000000000546,48.75750009878491,1.2957919100333646,-3.6518626596648978
434.80000000000547,48.83451592469919,1.1359354297171154,-3.6827566607215956
435.6000000000055,48.909861500279774,0.9910995947472692,-3.7100173019714235
436.4000000000055,48.987169690212895,0.8583562028300654,-3.733918140722138
437.2000000000055,49.06485855013396,0.7361142807562887,-3.7553371958590076
438.0000000000055,49.14226726092243,0.6322521597987809,-3.7727314555584277
438.8000000000055,49.21875714591222,0.5359874974571289,-3.784453537256652
439.60000000000554,49.296095010097176,0.45646055592093515,-3.7978705045009526
440.40000000000555,49.37370768406234,0.38674946107368086,-3.8122763122560284
441.20000000000556,49.451232741236964,0.3265497376029298,-3.8251117682209443
442.00000000000557,49.52895520748445,0.2736286834582258,-3.831136521875781
442.8000000000056,49.60720308445955,0.2274109672511509,-3.8455856356192357
443.6000000000056,49.68474251944389,0.18784605718802394,-3.853188642452094
444.4000000000056,49.76281433791355,0.155610841591926,-3.8588357837976988
445.2000000000056,49.84015812035057,0.1261394795170515,-3.8627387452045348
446.0000000000056,49.917658074822455,0.10098756887542523,-3.867151804060714
446.80000000000564,49.99503118370037,0.07828071837575545,-3.8673781833265277
447.60000000000565,50.07350852678479,0.06170603850344902,-3.870342583108441
448.40000000000566,50.152080314923566,0.04754264980229783,-3.8760340190999627
449.2000000000057,50.227177497426496,0.033665623183636,-3.878441546680566
450.0000000000057,50.30772599999878,0.0240191037005813,-3.8784609212426178
450.8000000000057,50.38538232625584,0.012758911415652219,-3.8783862986632966
451.6000000000057,50.46382563132893,0.00607493647666435,-3.883626448141386
452.4000000000057,50.54120737513297,5.688385319818634e-05,-3.8890115486472148
453.20000000000573,50.61962904403694,-0.0038907080186545984,-3.89160084283695
454.00000000000574,50.698642065002005,-0.0106819186752527,-3.8906118997918955
454.80000000000575,50.77769582781087,-0.013997646662957997,-3.891978672207639
455.60000000000576,50.85485657002805,-0.01846946087305268,-3.8933839220444204
456.4000000000058,50.934266471407255,-0.022383175127313915,-3.892871234500852
457.2000000000058,51.01190444636575,-0.027512098599753954,-3.8929975337985767
458.0000000000058,51.09010975569504,-0.030515156946239907,-3.8941895160880877
458.8000000000058,51.16919908715349,-0.03278782776767292,-3.896504314436087
459.6000000000058,51.247215970217525,-0.03852804050188108,-3.896879951133867
460.40000000000583,51.32635699478837,-0.04114898370938358,-3.8968799076625595
461.20000000000584,51.40408925582297,-0.04325114824722903,-3.8981600539069623
462.00000000000585,51.482987801550834,-0.04702718107189008,-3.902054963950283
462.80000000000587,51.56184990203442,-0.05038081644423126,-3.905312293762431
463.6000000000059,51.63974516408682,-0.054500671958926605,-3.906209879507524
464.4000000000059,51.71749013994949,-0.060804702246736675,-3.906134950004897
465.2000000000059,51.798544895878614,-0.06312804620559126,-3.903750949364552
466.0000000000059,51.877166583047924,-0.06572594701247261,-3.9042701977914356
466.8000000000059,51.95559917866808,-0.0675367948760292,-3.90775761000268
467.60000000000593,52.03444131341549,-0.06751225243953174,-3.907739709691327
468.40000000000595,52.110528245635706,-0.06542795883292182,-3.903523482144208
469.20000000000596,52.191222912523976,-0.06380369380772413,-3.899264155924704
470.00000000000597,52.26903431518855,-0.0639811649766528,-3.899290448676539
470.800000000006,52.34799432698027,-0.06262457161913573,-3.900821375025771
471.600000000006,52.42606904352718,-0.06380381084870462,-3.9054586970710345
472.400000000006,52.50467612150432,-0.06524848859823054,-3.905002160030809
473.200000000006,52.583856801619525,-0.06863451741826987,-3.915038051407159
474.000000000006,52.66131589902379,-0.07055817169528941,-3.9155342418943953
474.80000000000604,52.740240150666274,-0.0769596729799055,-3.9101252718000206
475.60000000000605,52.8188725903986,-0.07978627573148436,-3.905897259460824
476.40000000000606,52.89660676964173,-0.08445949041647322,-3.9039993145731113
477.20000000000607,52.97591994563539,-0.08842235569339299,-3.898542912890075
478.0000000000061,53.05511905670978,-0.0912777910163372,-3.898959982018735
478.8000000000061,53.13228597839363,-0.09537017391889449,-3.8989601542668706
479.6000000000061,53.21063761453607,-0.09657345768622341,-3.902257463443354
480.4000000000061,53.2897154855726,-0.09486113211024969,-3.90550531280155
481.2000000000061,53.36817204961322,-0.09732096482754288,-3.9061059801590323
482.00000000000614,53.44667649411215,-0.0984056360047906,-3.9038954215728507
482.80000000000615,53.52576241125887,-0.09953217402550663,-3.903899979804699
483.60000000000616,53.60519690357064,-0.10269210632334183,-3.903901241151572
484.4000000000062,53.68449031861896,-0.10659280450348499,-3.906278466912519
485.2000000000062,53.76232173596263,-0.10915375738727368,-3.907948083124805
486.0000000000062,53.84154909379798,-0.11130860879705728,-3.9092040925347566
486.8000000000062,53.920620946784304,-0.11273115869120753,-3.909291075259514
487.6000000000062,54.00043601556067,-0.11638554472937526,-3.906666707551778
488.40000000000623,54.07919173200604,-0.11797993226842274,-3.9053236233601996
489.20000000000624,54.157916548144975,-0.11846764183213868,-3.905937421547382
490.00000000000625,54.23785182570714,-0.12153246174532378,-3.909222948606065
490.80000000000626,54.31603577026118,-0.12169535379967134,-3.906681315063626
491.6000000000063,54.39588761168109,-0.12294986455397758,-3.9058969222582927
492.4000000000063,54.47525767390885,-0.12317861311162567,-3.905990149101773
493.2000000000063,54.55189342280171,-0.12525795258634814,-3.9052478553705368
494.0000000000063,54.63318895263147,-0.1271605544679975,-3.906036335673555
494.8000000000063,54.71206850725463,-0.12835267393327404,-3.905992675995409
495.60000000000633,54.791124725254065,-0.12633873204715937,-3.9086733928481525
496.40000000000634,54.86903740028972,-0.12898664833594256,-3.9087330351943046
497.20000000000636,54.94874114077767,-0.1317688055893507,-3.905501619486735
498.00000000000637,55.027767356596726,-0.1319688250512293,-3.9047809933099065
498.8000000000064,55.10655639102063,-0.1324010614998982,-3.907459086091142
499.6000000000064,55.1856935819398,-0.13302327190570065,-3.9077499727273297
500.4000000000064,55.2640784339319,-0.13284220976862984,-3.9120518856441198
501.2000000000064,55.34244472742991,-0.13580050664981327,-3.9105979968494275
502.0000000000064,55.42236949281492,-0.13669110736935405,-3.905764398100002
502.80000000000643,55.50073312881863,-0.13746546518767316,-3.9061031906941825
503.60000000000645,55.5793941753001,-0.1383042430610329,-3.901659611845016
504.40000000000646,55.65898412915781,-0.1429144837410164,-3.895027328892764
505.20000000000647,55.73791362968441,-0.14362615820108304,-3.8960585843818634
506.0000000000065,55.81690039440183,-0.14084844755160253,-3.9014121937014523
506.8000000000065,55.89573134559394,-0.1411487941500135,-3.909827226188758
507.6000000000065,55.97448995811267,-0.14173580180551537,-3.9114794307999152
508.4000000000065,56.05420644877066,-0.1410860484529599,-3.9114618739474594
509.2000000000065,56.131723600792284,-0.14558206189552092,-3.9115340531758265
510.00000000000654,56.21323487481264,-0.145831240098122,-3.9100872913705462
510.80000000000655,56.29150442200737,-0.14691762925589,-3.9084025926316666
511.60000000000656,56.370250524053844,-0.15008438099455415,-3.907681906975943
512.4000000000066,56.44907732686783,-0.14967347383220622,-3.9082408366643953
513.2000000000066,56.527406068319834,-0.14966092499859548,-3.912374775475237
514.0000000000066,56.606556896566275,-0.14917032385876797,-3.9123599466442394
514.8000000000065,56.68558275086886,-0.15177162741082123,-3.9124827380109855
515.6000000000066,56.76483783041754,-0.15024188728656554,-3.9084084368801526
516.4000000000067,56.84432571089917,-0.15329421734846713,-3.909718583954023
517.2000000000066,56.92363362343222,-0.1541573990330556,-3.908395586375543
518.0000000000066,57.0024287342285,-0.15269185322583415,-3.907452036889649
518.8000000000067,57.08165310080375,-0.15436906555456892,-3.9070801695396096
519.6000000000067,57.16072499026109,-0.15378912628551228,-3.9084013374325646
520.4000000000067,57.23878268253366,-0.15265781819110893,-3.9083999428214007
521.2000000000066,57.318204458933906,-0.15175965240286193,-3.9083990550092467
522.0000000000067,57.39637287604969,-0.15185611303914745,-3.909717594407146
522.8000000000068,57.47627809535231,-0.15339210407764653,-3.9113583729656156
523.6000000000067,57.55517140639964,-0.15194555707482588,-3.9098515936851066
524.4000000000067,57.63500711886018,-0.15579444755370184,-3.907099697612554
525.2000000000068,57.71428731409134,-0.1547690345041406,-3.9058815128118787
526.0000000000068,57.79276390041937,-0.153217057856254,-3.9057045173228295
526.8000000000068,57.872627159552934,-0.15381453878864637,-3.9044505019606515
527.6000000000067,57.9523318714637,-0.1537303146108409,-3.90451994688403
528.4000000000068,58.031528653987344,-0.15540089988460448,-3.9096953692592975
529.2000000000069,58.111396541428824,-0.15543583159171231,-3.9117731888257343
530.0000000000068,58.189980136903806,-0.15802050580000337,-3.914894213780426
530.8000000000068,58.27003994846602,-0.15993085654545822,-3.909367275106513
531.6000000000068,58.34996416197428,-0.1603834925794796,-3.904519204243625
532.4000000000069,58.42868224433426,-0.16406799044516376,-3.9052951903174264
533.2000000000069,58.50691907372119,-0.1629735516819229,-3.9098518281044132
534.0000000000068,58.58830977177023,-0.1639137425340179,-3.906752590156088
534.8000000000069,58.66774752974166,-0.16527561428642767,-3.9067572977011693
535.600000000007,58.74697364245769,-0.16455872170348818,-3.9064338278201802
536.4000000000069,58.826809450275064,-0.165286593553289,-3.905001980384377
537.2000000000069,58.90677712337205,-0.16768956520370515,-3.906430009866725
538.0000000000069,58.986155933237605,-0.16732628937019184,-3.90643000612928
538.800000000007,59.06494639845006,-0.16982603525624831,-3.904994201271592
539.600000000007,59.144244678748485,-0.17172930801964628,-3.903569225214526
540.4000000000069,59.22376866645424,-0.1735559004687865,-3.9029206529892413
541.200000000007,59.30303047634363,-0.1751045210264085,-3.90424486025703
542.000000000007,59.38173112848495,-0.1745080752034417,-3.906198837562544
542.800000000007,59.46179537021814,-0.1778971187330145,-3.9075204219279738
543.600000000007,59.54053889002099,-0.17923504912418076,-3.9081760452186893
544.400000000007,59.61922750268061,-0.18014692405472985,-3.909615296151245
545.2000000000071,59.700063084510575,-0.1767948051459868,-3.9098432925533895
546.000000000007,59.77927542155387,-0.17757115242626187,-3.9098440320502013
546.800000000007,59.85916236590407,-0.17909467384385172,-3.9085198444449847
547.000000000007,59.87894998928064,-0.1767577014684118,-3.9085198729763233