File: 01_Data/EIFS_XPS/STA/N2/10K_min/EIFS_XPS_STA_N2_10KData_230203_R2.csv
##Temp./Â°C,Time/min,DSC/(mW/mg),Mass loss/mg
50.0,10.863688586696718,0.03539914535922084,0.012606544122503394
50.80000000000001,11.102857147038021,0.0555459906661111,0.014516316457054756
51.60000000000002,11.289343889020039,0.06992086541068931,0.012121228738013912
52.400000000000034,11.448137294518713,0.08316628937821124,0.011832626850067918
53.200000000000045,11.591951920785453,0.08947635236223062,0.022215686631360754
54.00000000000006,11.720458552929362,0.09821245843372672,0.01819073455348974
54.80000000000007,11.849496320616979,0.10245520819325948,0.011204678620286401
55.60000000000008,11.969714520809958,0.11504249291928037,0.013101509438126158
56.40000000000009,12.08454314065635,0.11921923862562922,0.018160287085636106
57.2000000000001,12.196884256381088,0.12552798497494932,0.019241962756304964
58.000000000000114,12.304297157408852,0.12622076000741256,0.016783164503382686
58.800000000000125,12.411572370668186,0.13164354291409386,0.020739754972743718
59.600000000000136,12.517238600393476,0.13412737022581123,0.019764258215269948
60.40000000000015,12.618115732149707,0.13623230756397975,0.016099109311272564
61.20000000000016,12.718415831995138,0.14077845769460962,0.013720135580126858
62.00000000000017,12.819080259864759,0.14465743737924353,0.014789712683003664
62.80000000000018,12.918533026690817,0.1498762902082622,0.013729312305019725
63.60000000000019,13.016727831871092,0.15081603104071561,0.018601809515038426
64.4000000000002,13.111678784714412,0.1535945823953675,0.011104303369513069
65.20000000000022,13.207770918231546,0.15545596773126946,0.010902908405697076
66.00000000000023,13.300532650035922,0.15887361130281152,0.016410859948797096
66.80000000000024,13.394041905401224,0.15921404202252032,0.018667185567662337
67.60000000000025,13.486910919789468,0.1619507334186865,0.021910258430677843
68.40000000000026,13.578736171657585,0.16329875313469855,0.02458406708230232
69.20000000000027,13.670378960444257,0.16669108743082828,0.019111015240850016
70.00000000000028,13.7579033998984,0.1688576245986153,0.012232200401794735
70.8000000000003,13.851702735018552,0.16958400142942387,0.010926782633339016
71.6000000000003,13.941675025008758,0.17195049765542936,0.012659066451312206
72.40000000000032,14.030679970282888,0.17124999359326543,0.015636532073560083
73.20000000000033,14.117710934259089,0.17171071268771732,0.018441696392644147
74.00000000000034,14.204390155154654,0.17329782473054656,0.01976484931561462
74.80000000000035,14.293285995454255,0.17373988305309185,0.018376409970717766
75.60000000000036,14.378527830468286,0.17399867100001898,0.015941631109837928
76.40000000000038,14.465708251102294,0.17304180948110992,0.016939151971770094
77.20000000000039,14.551818080253595,0.1738153176027153,0.019851312927964493
78.0000000000004,14.636641462071127,0.1733533198585855,0.024144229990397115
78.80000000000041,14.721857063474875,0.17495068292311444,0.023279198533832535
79.60000000000042,14.80838572717312,0.17628369704768954,0.020590073524670238
80.40000000000043,14.890848704556607,0.17512242987385718,0.01931857171491025
81.20000000000044,14.975106681800161,0.1778908375416679,0.015542001413137108
82.00000000000045,15.058634191385806,0.18128435691942957,0.011081329214143842
82.80000000000047,15.141793863344594,0.18120907862059865,0.009310309853943544
83.60000000000048,15.225186731636722,0.1851056047670221,0.013727196439843325
84.40000000000049,15.307654237223456,0.18340585620820105,0.01917919833395665
85.2000000000005,15.391861792303246,0.18756434442068315,0.022027624447110483
86.00000000000051,15.474584557176032,0.1872645259013468,0.017368720645275282
86.80000000000052,15.55535452601188,0.189205969720311,0.01865237590887947
87.60000000000053,15.636872167563372,0.19284265355200492,0.017365133333929528
88.40000000000055,15.718260561337393,0.19545013603252948,0.01849039268143393
89.20000000000056,15.798351834653243,0.19565568146845436,0.02269651300453379
90.00000000000057,15.880688444795183,0.19598029576671017,0.02404212784346882
90.80000000000058,15.95938118585866,0.19862961053784856,0.024053561452701544
91.60000000000059,16.042003282903966,0.20008378451468178,0.022295630560425828
92.4000000000006,16.121782055626287,0.205162825373698,0.019748354239001564
93.20000000000061,16.20269845657508,0.20567951787860894,0.01989798447140778
94.00000000000063,16.283657159971664,0.21221061695206456,0.019659089795489137
94.80000000000064,16.362440742604335,0.21660140230435465,0.01858892394374667
95.60000000000065,16.4411517752327,0.218920328704305,0.019209467501601907
96.40000000000066,16.52046701290892,0.22407062927368382,0.018867795535941312
97.20000000000067,16.599539829879163,0.227509248876541,0.014919804550007854
98.00000000000068,16.679377924956114,0.23373121672928243,0.015391250532949208
98.8000000000007,16.758965067765715,0.23917424325627068,0.01399461459389606
99.6000000000007,16.83430994905811,0.24611531529534425,0.011901609445020611
100.40000000000072,16.91661659758193,0.25110192257400554,0.009871550549991781
101.20000000000073,16.99419746477621,0.2597494644793983,0.011141581892193386
102.00000000000074,17.07276011127692,0.26861709031028147,0.011349885688355599
102.80000000000075,17.149583905749243,0.276784361458668,0.010204322173119174
103.60000000000076,17.2295397398222,0.28683958956347777,0.012022731276989163
104.40000000000077,17.305045379507984,0.29480650422970256,0.015576403042020459
105.20000000000078,17.382766037315513,0.30592186104964236,0.015590188609458266
106.0000000000008,17.46279464864986,0.31659260991288884,0.01427561003265776
106.80000000000081,17.540793743743347,0.3251379452113087,0.012870497865059782
107.60000000000082,17.6191178111139,0.33455990529786384,0.011515841245361536
108.40000000000083,17.695794538875575,0.3418407044979851,0.012244460939708546
109.20000000000084,17.77327658026751,0.3476965395376673,0.015267883467178223
110.00000000000085,17.851835630901256,0.3522722652020769,0.015721120439873282
110.80000000000086,17.929441972372203,0.3561738217584135,0.012295292859307416
111.60000000000088,18.008500510623392,0.3570015047752315,0.00790106725389883
112.40000000000089,18.085397368978693,0.3542524367962975,0.009098113511897488
113.2000000000009,18.162381740180795,0.3530707972578291,0.009448947017262732
114.00000000000091,18.23969208413411,0.3481906854035872,0.009430195681536802
114.80000000000092,18.316445953122678,0.3432279811622282,0.00943032143486544
115.60000000000093,18.39378758330205,0.3347956229204684,0.010705654527295216
116.40000000000094,18.472108035905713,0.3285250340824326,0.012742055874848113
117.20000000000095,18.54939618810475,0.31971148328981014,0.014048492760713849
118.00000000000097,18.626629880873963,0.3114945240989381,0.015184373373775983
118.80000000000098,18.702634105767217,0.30942519031775795,0.014045408752730637
119.60000000000099,18.780087895424934,0.3062506529270369,0.009653491134783643
120.400000000001,18.856780443831333,0.30076572955031344,0.009333738875104913
121.20000000000101,18.933255447288083,0.2970829685271513,0.010102786998165136
122.00000000000102,19.008402284112826,0.2931470981463097,0.00756830751303017
122.80000000000103,19.087826483712025,0.2889190042049604,0.007513064242733236
123.60000000000105,19.16440973091605,0.28688693548839794,0.008576434438979597
124.40000000000106,19.24154365762921,0.2854957464801461,0.008563160145746096
125.20000000000107,19.315586337437278,0.28283120458709887,0.008391567724157056
126.00000000000108,19.394999922270912,0.2820821958046974,0.008779873665951676
126.80000000000109,19.471391187010727,0.28085473036113495,0.00877913940686792
127.6000000000011,19.547767885142324,0.28008699668711945,0.007457605418229818
128.4000000000011,19.623428144869063,0.28207439768778564,0.007457272565369877
129.20000000000113,19.700191682969585,0.2797295856337614,0.007983528604079915
130.00000000000114,19.776627414965944,0.2789921138749729,0.008734573978245841
130.80000000000115,19.851947213400845,0.27984675798042025,0.0067629403590672155
131.60000000000116,19.929832199309864,0.2816417370426808,0.0063102039274651744
132.40000000000117,20.00411486524273,0.28197708875203087,0.004888845385208285
133.20000000000118,20.080948613020315,0.27989357166362416,0.004927777031700664
134.0000000000012,20.157119331998512,0.28071930149017976,0.007800359466196838
134.8000000000012,20.23345378806927,0.2804537169173359,0.005021818760409857
135.60000000000122,20.309301804781448,0.28295176262233135,0.0032929936420922346
136.40000000000123,20.385329186919872,0.2829402859643241,0.00111579724330646
137.20000000000124,20.462371114224904,0.2841646002384701,0.0015202761193977565
138.00000000000125,20.53765666612418,0.2832260486075915,0.006308337834162181
138.80000000000126,20.61451717147127,0.28399527046822703,0.005143617755829055
139.60000000000127,20.689329728482463,0.2849596972847568,0.004875418800845743
140.40000000000128,20.7662115296541,0.28408083395667527,0.0020861547287127635
141.2000000000013,20.84111415212733,0.2823312786310683,-0.0016421488041746812
142.0000000000013,20.91711072282165,0.28597283992767353,-0.001594546031409294
142.80000000000132,20.992180332359816,0.28350574383615235,0.002512543992944316
143.60000000000133,21.068790147616575,0.2849215524146178,0.005628272576433169
144.40000000000134,21.144453645581923,0.285962382617132,0.005716721934549085
145.20000000000135,21.218045065471273,0.28553589554678627,0.007947750800433084
146.00000000000136,21.29517737069072,0.28627323896707346,0.009768786780650629
146.80000000000138,21.370914645026183,0.28512055651041746,0.011090660127251795
147.6000000000014,21.446420305835804,0.285662675069838,0.011319773451685222
148.4000000000014,21.521817305476873,0.28409618953828386,0.01287540999871073
149.2000000000014,21.598355723340187,0.2868738541371787,0.015077879988855791
150.00000000000142,21.674486542807234,0.28816908388260587,0.01034204315045173
150.80000000000143,21.749641585012526,0.28741697509583264,0.007128626277346228
151.60000000000144,21.824830595552676,0.288165621006514,0.0029178116715957714
152.40000000000146,21.900105356265403,0.28932745402211824,0.002299988661171426
153.20000000000147,21.976014788592842,0.2914625191870751,0.0022802746259209528
154.00000000000148,22.05218974912635,0.2917911504341987,0.000991465917109302
154.8000000000015,22.127545675465463,0.2918113911258742,0.002299508211881296
155.6000000000015,22.202687440988758,0.2919283660990759,0.0029238137036502465
156.4000000000015,22.278017209730624,0.2941267787154771,0.0029632234923777645
157.20000000000152,22.354385719612978,0.2933035802354018,0.005006364411162423
158.00000000000153,22.429724921515184,0.292138339632225,0.0071534912786761495
158.80000000000155,22.5054027649429,0.2908303981131499,0.008480975926896228
159.60000000000156,22.58054018991425,0.2928694720667434,0.008417100768959962
160.40000000000157,22.65650038232149,0.2933987678045885,0.005797325472691739
161.20000000000158,22.73116520624239,0.29461074682899036,-0.0011778122655599077
162.0000000000016,22.807062721532994,0.29948325757470395,-0.004751596454063645
162.8000000000016,22.882483595356526,0.29969636535397925,-0.006026490132263085
163.60000000000161,22.95782000447141,0.3010679259365987,-0.0017903947430220057
164.40000000000163,23.03291930435996,0.2973066745241334,0.00566893145212255
165.20000000000164,23.108315053637927,0.29812401422130985,0.006028061722233247
166.00000000000165,23.18429044860018,0.29990116592960664,0.008702074898526035
166.80000000000166,23.258596232476776,0.2986076963242955,0.00931658766576593
167.60000000000167,23.334065260665074,0.3005447343651249,0.007653214011727805
168.40000000000168,23.4096095239392,0.30107358959031644,0.005054535801129134
169.2000000000017,23.482224751353666,0.302834137542847,0.002340545747484768
170.0000000000017,23.559122757877766,0.30515710134641805,-0.0003288701129777749
170.80000000000172,23.6341330157631,0.30509465830715154,-0.0016477365866336413
171.60000000000173,23.70931331552924,0.3043252477044287,-0.00020863309971375088
172.40000000000174,23.785069744996544,0.3049508675329386,0.0039007794929197814
173.20000000000175,23.85980734286194,0.30351665560317465,0.0041654111979951836
174.00000000000176,23.936401104005917,0.3040268268643626,0.003499934188653242
174.80000000000177,24.011757098495533,0.3050946703979097,0.0029438064115856477
175.60000000000178,24.086029564630337,0.3029981051029001,0.005962071771125288
176.4000000000018,24.160980582112447,0.3050110632732907,0.0054746740485649426
177.2000000000018,24.235593475509386,0.30567236285915306,0.002370813236104219
178.00000000000182,24.312000758327457,0.3053453874789578,0.00010997525635492167
178.80000000000183,24.387150415667634,0.30521180765233524,-8.844500085647411e-05
179.60000000000184,24.46217668030628,0.3055737264581772,-0.0009723273808814881
180.40000000000185,24.538465495519574,0.30532247340839863,0.000753167193533244
181.20000000000186,24.613878977373396,0.3068478610193698,0.003107801035107549
182.00000000000188,24.688771486546997,0.30661664999749955,-0.0010195163477577651
182.8000000000019,24.76310428047783,0.30886322823946083,-0.002216966561861433
183.6000000000019,24.836626040151295,0.3064674837027307,0.00405104383647803
184.4000000000019,24.91394375699451,0.3054057513515288,0.00253487910134087
185.20000000000192,24.99000000000018,0.3050718523194024,0.0032457342938361222
186.00000000000193,25.06563456739707,0.30628236780544227,0.0011211276616904797
186.80000000000194,25.141439697767268,0.30598785397356126,-0.0016293591162765964
187.60000000000196,25.21687257969804,0.30696495843018023,0.0006027466254554525
188.40000000000197,25.29142145405797,0.30554754403713424,0.004203615357280199
189.20000000000198,25.367213507439796,0.30580889695002983,0.003255506786826956
190.000000000002,25.442196964618812,0.3049197807847854,0.004644925374643449
190.800000000002,25.515494727056875,0.3064878393006419,0.0017591937687946313
191.600000000002,25.592793248618467,0.30552244287712466,0.003132439246794405
192.40000000000202,25.668279642297016,0.30638868973128913,0.0017855544109721677
193.20000000000203,25.74256806476535,0.30683659612572317,-0.004145851572893378
194.00000000000205,25.817951111302005,0.3077813510892166,-0.002102671690268565
194.80000000000206,25.893330441617767,0.3065261080077795,0.0020668576196953836
195.60000000000207,25.96835101718049,0.307093167171665,0.00405989983839028
196.40000000000208,26.043321880584895,0.3061712531002955,0.0026662060106286134
197.2000000000021,26.119023403572818,0.30808926411664805,-0.00023364696141126018
198.0000000000021,26.194708492901718,0.3093724063945107,-0.00189895816624297
198.80000000000211,26.269466643405394,0.3097270653634557,0.0018176256577939753
199.60000000000213,26.34492276412927,0.3126617728644989,0.001833411347933911
200.40000000000214,26.42045422169162,0.3112823090212199,0.0014900202728931333
201.20000000000215,26.49504742093269,0.31309088331640905,-0.00414412646123985
202.00000000000216,26.56868414551979,0.31352668207638534,-0.001580615049491918
202.80000000000217,26.644956605041855,0.31400714628001813,0.007035308352044467
203.60000000000218,26.721079366029947,0.3124592820492076,0.00867821782080469
204.4000000000022,26.795608802776954,0.3142146186270126,0.0025561283477992802
205.2000000000022,26.871864271989736,0.31649768901232816,-0.0028513565068521984
206.00000000000222,26.946271135988148,0.3184887710949647,-0.005894034574712492
206.80000000000223,27.02233643813619,0.31912409848110257,-0.010255272964244
207.60000000000224,27.095955763238678,0.32000831780156336,-0.011869824342364055
208.40000000000225,27.172397250187487,0.3212278791552921,-0.008770555217425091
209.20000000000226,27.247350149010362,0.32035834529075485,-0.0006084015715179802
210.00000000000227,27.323816028621348,0.3184320028202656,0.0069365836787707025
210.80000000000229,27.399401613890184,0.31840783990762217,-0.0021432180378662125
211.6000000000023,27.474133544626515,0.3192194008297349,-0.006436543356976188
212.4000000000023,27.550000905546575,0.3215415880652161,-0.0020980864043167458
213.20000000000232,27.625510646035394,0.3212984228852099,-0.0033321697750618995
214.00000000000233,27.700534289480863,0.3207836786183832,-0.004730862429827454
214.80000000000234,27.775799970373168,0.3208925043666524,-0.0015179803172715722
215.60000000000235,27.8515241022523,0.32114458925060696,-0.004090256519051039
216.40000000000236,27.927554697611644,0.32132490706569866,-0.0019650011596308303
217.20000000000238,28.00293506578311,0.3213348905310372,-0.002963925766454878
218.0000000000024,28.0778089748025,0.3214161184628595,-0.00014199212275034512
218.8000000000024,28.153810134447966,0.3232300598782805,-0.003827987890314688
219.6000000000024,28.229315674983532,0.3244390968849819,-0.011150846742248088
220.40000000000242,28.30457992476317,0.32605332228888667,-0.014854065183137699
221.20000000000243,28.379910505627738,0.3255545206701187,-0.010099476412815722
222.00000000000244,28.45594586942635,0.32383947406640257,-0.009114443529853133
222.80000000000246,28.530415776074474,0.3252692917589164,-0.009175821019825392
223.60000000000247,28.606528668663003,0.3259453307857903,-0.015375488504145274
224.40000000000248,28.683598908167514,0.3234790950342323,-0.01692998904858456
225.2000000000025,28.758647235391695,0.3246847036331424,-0.008398052791261712
226.0000000000025,28.833688175024996,0.3223366349945624,-0.001978270219407996
226.8000000000025,28.91000000000024,0.32147949254023345,-0.0009894734698336904
227.60000000000252,28.984790742621158,0.3221684468300236,-0.006060680865732415
228.40000000000254,29.060542042705254,0.3258306611504682,-0.01431982200505555
229.20000000000255,29.1360607150052,0.3244820505046365,-0.014710805872948818
230.00000000000256,29.211655933984446,0.3267989252239098,-0.011084033938943083
230.80000000000257,29.287493437208486,0.32510147256844873,-0.007021215928342706
231.60000000000258,29.3621641466241,0.3269944330047696,-0.010006778558444118
232.4000000000026,29.43835885111463,0.32838224146286793,-0.017250957186135008
233.2000000000026,29.514225008222176,0.3285769812891039,-0.018153009356982608
234.00000000000261,29.58894210516798,0.3295794131875951,-0.01322345789569157
234.80000000000263,29.665047897275194,0.3274432355518101,-0.008841732737695729
235.60000000000264,29.73999900504776,0.32825439578397747,-0.005930071632809231
236.40000000000265,29.81636743259945,0.3288848705697023,-0.009656153769013187
237.20000000000266,29.891495714331416,0.33177451297093563,-0.014717152078774554
238.00000000000267,29.96606103554502,0.33039196078206445,-0.014068624805448682
238.80000000000268,30.04288655740752,0.3315518821700569,-0.013739262162816956
239.6000000000027,30.118287581004893,0.33239698114107663,-0.012408364234866465
240.4000000000027,30.193739263360733,0.3331867456532285,-0.015796077916153006
241.20000000000272,30.26901147306925,0.33328781710102884,-0.01679071094858564
242.00000000000273,30.344929686053963,0.3350622448442754,-0.016811296015668997
242.80000000000274,30.41935391888736,0.3345510589647232,-0.017018105340105727
243.60000000000275,30.495058933224918,0.3346952551397966,-0.01801253504162892
244.40000000000276,30.571723500057868,0.3349807973551408,-0.01800929458585232
245.20000000000277,30.64642000108402,0.33553653604290407,-0.016656560501149276
246.00000000000279,30.722629801754227,0.33592332455671026,-0.015778315249585617
246.8000000000028,30.797440562708417,0.33652650469916406,-0.015163169753510175
247.6000000000028,30.874704140048955,0.33682590225398634,-0.013744157789375766
248.40000000000282,30.946804327370018,0.3390507889754214,-0.015867709494698623
249.20000000000283,31.025711401702182,0.33697678283896354,-0.014495315466366954
250.00000000000284,31.100596146355144,0.33692747329134964,-0.013590585712080827
250.80000000000285,31.176959079741184,0.3375662591078397,-0.01409650288698705
251.60000000000286,31.252630336232336,0.339369441555446,-0.017622787259064854
252.40000000000288,31.32869875791154,0.3406666475588238,-0.018140384149122113
253.2000000000029,31.40371963183929,0.34041351790123653,-0.019418527574798894
254.0000000000029,31.480373757161995,0.33994350970086423,-0.01677996820049943
254.8000000000029,31.55587777156859,0.3396941230855667,-0.015480212210608357
255.60000000000292,31.630104230544237,0.34101165946336814,-0.018426549509726442
256.40000000000293,31.70594985633021,0.341680381211244,-0.022849879380371085
257.20000000000294,31.78285009426639,0.3432134371858139,-0.026870243085796996
258.00000000000296,31.859570404911082,0.34296400987658787,-0.026899930041662135
258.80000000000297,31.93522344274247,0.34344965014686835,-0.02352169568203788
259.600000000003,32.009637806891526,0.3427540112227523,-0.01713803168556982
260.400000000003,32.086243904985004,0.3428368816039864,-0.016327498952231956
261.200000000003,32.162385175271694,0.34257313893991703,-0.0196324671522361
262.000000000003,32.23703034643299,0.34462599175663444,-0.017951873497282556
262.800000000003,32.31249440088134,0.34349668634695346,-0.016792129413838452
263.60000000000304,32.38832018654198,0.3427215514472746,-0.017378531408694275
264.40000000000305,32.464375708150726,0.3445218428161177,-0.020486406395602508
265.20000000000306,32.54020623127944,0.3431273157799718,-0.019414010105958557
266.00000000000307,32.614674916772216,0.3449312270297421,-0.018676006000410528
266.8000000000031,32.690903760055,0.3445602254389398,-0.021700809460851733
267.6000000000031,32.76656599668747,0.3456756349265905,-0.023144852276179684
268.4000000000031,32.842689486176894,0.3463555488869534,-0.024640763104947894
269.2000000000031,32.918647570983644,0.3468032013421133,-0.021747211731499405
270.0000000000031,32.99268147480799,0.3453408775568234,-0.018352760574322335
270.80000000000314,33.070387682679105,0.3459814694580321,-0.01972000081024916
271.60000000000315,33.14655824556331,0.34362245427438515,-0.019879688410298968
272.40000000000316,33.22060937778813,0.3462855359217903,-0.024334632383697485
273.2000000000032,33.29779099020167,0.3465191940933179,-0.025098042450449665
274.0000000000032,33.37443160467223,0.3462326211778155,-0.025364844272486753
274.8000000000032,33.45159405148428,0.34654871309491064,-0.02581583750155758
275.6000000000032,33.52621796568061,0.3478309137620931,-0.027337811716741545
276.4000000000032,33.602018042454375,0.34921320024979846,-0.024949719392874492
277.20000000000323,33.67912072337534,0.34778298484666814,-0.023059872447130036
278.00000000000324,33.754418180887896,0.34729008861328375,-0.023456612331606674
278.80000000000325,33.831453999507836,0.350144125780021,-0.026837497209975858
279.60000000000326,33.90671918048101,0.3513817692847411,-0.030801388426922927
280.4000000000033,33.9828787256299,0.35089866941031056,-0.030078607513183364
281.2000000000033,34.05886550811494,0.35051045147434984,-0.027450051726131797
282.0000000000033,34.13396851680096,0.3537731761453063,-0.02888276462953243
282.8000000000033,34.21094805266416,0.3521992599334725,-0.028768039625483688
283.6000000000033,34.28640961029101,0.3527249055054509,-0.028550967302300556
284.40000000000333,34.36298247403159,0.35128139896190885,-0.026066436096487067
285.20000000000334,34.43919446667704,0.35280242045952587,-0.026115419373652582
286.00000000000335,34.51510259668057,0.35271369247166384,-0.02613376373049414
286.80000000000337,34.59179289676158,0.35521077169521753,-0.027425347781819376
287.6000000000034,34.6679063586887,0.354962209359785,-0.02876621763139786
288.4000000000034,34.74373167589748,0.35759873625766136,-0.026769799052244192
289.2000000000034,34.82083459929843,0.3566859942693517,-0.02351487931581442
290.0000000000034,34.89617662390995,0.3543713602164206,-0.0236533876737286
290.8000000000034,34.97282342487282,0.35940418038641564,-0.024889948570768095
291.60000000000343,35.04803427377339,0.3586201813664087,-0.027676944800819836
292.40000000000344,35.12483407650431,0.3609624801892761,-0.03024339737943693
293.20000000000346,35.200295294704596,0.3619039933780962,-0.03320793260354282
294.00000000000347,35.27715206207639,0.36405529352657306,-0.03547453105668641
294.8000000000035,35.35222293331289,0.364428902587561,-0.03502926885704705
295.6000000000035,35.42904183140728,0.36278015656718876,-0.03404919614227264
296.4000000000035,35.50528730049741,0.3651711625147303,-0.03540131794008383
297.2000000000035,35.58201890581689,0.36491757070605324,-0.03370259680777066
298.0000000000035,35.657939910886306,0.36669895620132265,-0.03106665396764008
298.80000000000354,35.73420328959218,0.365668005236808,-0.031121524086346497
299.60000000000355,35.809809761370886,0.36597802887494646,-0.03218577828384772
300.40000000000356,35.88592668938835,0.3666467580296516,-0.031190145318228613
301.20000000000357,35.9623856959891,0.3676393685934358,-0.032004268516454104
302.0000000000036,36.037051127182096,0.36830195968432156,-0.035450108218415544
302.8000000000036,36.115008646708766,0.36851272528453954,-0.03473031483221689
303.6000000000036,36.1910848809872,0.37033368077279166,-0.03552804141268551
304.4000000000036,36.26718980771464,0.3711815365402848,-0.03822846894111365
305.2000000000036,36.34280146318634,0.3730203673061212,-0.0396392080413559
306.00000000000364,36.42028511391665,0.37187522009446394,-0.03676995082249235
306.80000000000365,36.4958775367547,0.37132833034720925,-0.035464258835317786
307.60000000000366,36.5727501759817,0.37185609893058513,-0.0354798040021973
308.4000000000037,36.648715124633455,0.3713374849694129,-0.032907519026194265
309.2000000000037,36.72599605263436,0.3723893059936308,-0.034132136373689725
310.0000000000037,36.80294220648248,0.3725747871534479,-0.036795339819558404
310.8000000000037,36.87846241089615,0.3736868142616015,-0.038416056039665136
311.6000000000037,36.95435828199905,0.37482065519223934,-0.03953002417507001
312.40000000000373,37.03180076975269,0.3736777654316871,-0.03951858374257
313.20000000000374,37.10814209665768,0.37607226371623154,-0.042159973123546024
314.00000000000375,37.18379792199837,0.37731141691591225,-0.0426762526708826
314.80000000000376,37.26101137632861,0.3746923650337089,-0.04228811691310019
315.6000000000038,37.33659525409743,0.37549041643466946,-0.041811828482023916
316.4000000000038,37.41143915885349,0.37846098782218013,-0.04222488145149628
317.2000000000038,37.49037897227745,0.3786094126045387,-0.042178870424848025
318.0000000000038,37.56795835076139,0.37605170542831823,-0.043480407750679184
318.8000000000038,37.64062089490627,0.37963473738758163,-0.04623215580905393
319.60000000000383,37.71962723222448,0.38104284170134933,-0.04820115417764814
320.40000000000384,37.7962344566839,0.38214880108997845,-0.04958990234398186
321.20000000000385,37.873003362526696,0.38408504129562127,-0.05082697193157948
322.00000000000387,37.949900278515116,0.380882058824562,-0.052754905248973305
322.8000000000039,38.026806642079514,0.3836112767876692,-0.05106331272968223
323.6000000000039,38.10315657390541,0.3835649419315233,-0.04700266952384702
324.4000000000039,38.18018370049865,0.3842560620205068,-0.04709459043354425
325.2000000000039,38.25722911196941,0.38574963963333275,-0.05025403385172034
326.0000000000039,38.33106373368519,0.38688435214996353,-0.05770478976135163
326.80000000000393,38.410930435939036,0.38961431502685895,-0.06160260221289793
327.60000000000394,38.48818505382619,0.38875866415070204,-0.0570729069933682
328.40000000000396,38.565313426717374,0.3881303455154524,-0.0534898988055974
329.20000000000397,38.64224583884495,0.3870947655780782,-0.04996181746556161
330.000000000004,38.71950979660289,0.38698120507078887,-0.049960306051471726
330.800000000004,38.796542720344824,0.3906381224201808,-0.051274167155871186
331.600000000004,38.87221498149546,0.39135448479294843,-0.05545183818603716
332.400000000004,38.94899032980487,0.39336470591393297,-0.05958843727299623
333.200000000004,39.026167442211374,0.3961485513980234,-0.05786097904059995
334.00000000000404,39.10302583687763,0.3969839337086803,-0.0564783831600999
334.80000000000405,39.18010534965465,0.3975725194632933,-0.06048502524742938
335.60000000000406,39.25469080401548,0.39978682574374297,-0.06600092859259821
336.40000000000407,39.33461064723158,0.4033482332156393,-0.07083412072844197
337.2000000000041,39.41113940282154,0.4026644516580068,-0.07082901556455745
338.0000000000041,39.48654901249476,0.40632371594062566,-0.06828937946702407
338.8000000000041,39.56357847881549,0.4058862493154264,-0.06828884087799159
339.6000000000041,39.640997735411645,0.40632161683866935,-0.06894659132125236
340.4000000000041,39.717110027062915,0.4091532898296992,-0.06894945680807263
341.20000000000414,39.794095580766644,0.4098882284985499,-0.06993955313991007
342.00000000000415,39.8712449615574,0.4124969477400211,-0.06965643294797275
342.80000000000416,39.94817942834035,0.41541758058584993,-0.07262829827197947
343.6000000000042,40.02404122048139,0.4173065263801231,-0.07521317936150718
344.4000000000042,40.10134089857302,0.4190004541952375,-0.07444513200258474
345.2000000000042,40.17824886896765,0.4201481474561594,-0.07366803977013126
346.0000000000042,40.25274573172313,0.42260884904225865,-0.074650355978366
346.8000000000042,40.330928059829205,0.4242780037304608,-0.07443235750444854
347.60000000000423,40.40735930751978,0.42730220445826783,-0.0757132883979259
348.40000000000424,40.48466995714206,0.4311033731230064,-0.07795481912152269
349.20000000000425,40.56163382449711,0.4292626101670516,-0.08400829886420347
350.00000000000426,40.63874843728436,0.4351866471794974,-0.089684827131296
350.8000000000043,40.71575006685853,0.4381188502867585,-0.09468126905829433
351.6000000000043,40.79195980326693,0.442012255177116,-0.09760038222104361
352.4000000000043,40.868845814847276,0.4461569410726525,-0.09760003405976336
353.2000000000043,40.94724300022072,0.4470801586958799,-0.09740984859059854
354.0000000000043,41.02368530173561,0.4515215366860704,-0.09627842003328801
354.80000000000433,41.10157401940267,0.4526565521441832,-0.09619918615241785
355.60000000000434,41.17842885213547,0.45616155670453956,-0.10035974199532971
356.40000000000435,41.25594592635635,0.45956461805851045,-0.10166909110667399
357.20000000000437,41.33280082544148,0.46178985915908677,-0.10656347123251253
358.0000000000044,41.41009443356409,0.46605833789961665,-0.11112028852639844
358.8000000000044,41.48620535443273,0.4714371405146569,-0.11190283053403238
359.6000000000044,41.56502809362803,0.4752451760417946,-0.1129085011283344
360.4000000000044,41.64188008060393,0.48011806123159506,-0.11239235956977645
361.2000000000044,41.71877458629497,0.4854077930272673,-0.11504986484999957
362.00000000000443,41.79586438065215,0.4929767408351847,-0.1209155964636266
362.80000000000445,41.873118616025565,0.4979865211443628,-0.12605751493486528
363.60000000000446,41.95094836655156,0.5065401875554946,-0.13044751489975237
364.40000000000447,42.02809971609474,0.5105533379542843,-0.1331095872054262
365.2000000000045,42.10541531092792,0.5187259249624983,-0.13545210611999092
366.0000000000045,42.18248698277067,0.5267733598219033,-0.1362566564145613
366.8000000000045,42.259703729508345,0.5336792348646829,-0.13611269466235898
367.6000000000045,42.33738820965385,0.5438029408378457,-0.14352462329034488
368.4000000000045,42.414183098003186,0.5536010246739815,-0.15201881357951086
369.20000000000454,42.492004091755305,0.5623101267276367,-0.15947609332014467
370.00000000000455,42.568879351574395,0.5728260125411266,-0.16555990621792382
370.80000000000456,42.646971614299666,0.5877573200444357,-0.169405413320729
371.60000000000457,42.72492039567575,0.5972997155837867,-0.17263072875628271
372.4000000000046,42.802205910390555,0.6111654833376245,-0.1778588658526612
373.2000000000046,42.87908878450881,0.6211398420710461,-0.1821465306981871
374.0000000000046,42.957634330666394,0.6359425660027012,-0.18789285307673742
374.8000000000046,43.03388041162276,0.6476385667993252,-0.1926499247167559
375.6000000000046,43.11268562463345,0.6643200602402568,-0.2033670281131985
376.40000000000464,43.18949542316432,0.6815587970267334,-0.21029533085751773
377.20000000000465,43.26579457091858,0.6978887971446437,-0.2165869934849458
378.00000000000466,43.3438803951314,0.7138957137965485,-0.22284484931971482
378.8000000000047,43.42157334619054,0.7348022948274182,-0.2288239890374575
379.6000000000047,43.498925665184274,0.7570375341517104,-0.2377802906051425
380.4000000000047,43.57694905064897,0.777285562432958,-0.247497295793774
381.2000000000047,43.65487594969312,0.7982174817313046,-0.25857301805983024
382.0000000000047,43.73280924510497,0.8230508338597955,-0.2690064415866056
382.80000000000473,43.80946684955127,0.8508851042124255,-0.28324346821130586
383.60000000000474,43.886000173600095,0.8782546830349216,-0.297326254536034
384.40000000000475,43.964847101516305,0.9115195237532514,-0.3075740387847796
385.20000000000476,44.04313522833326,0.9423939835616852,-0.3198718761862711
386.0000000000048,44.121137824110924,0.9721262667912678,-0.3333121908321166
386.8000000000048,44.19896101170429,1.0072954219422188,-0.3467040478070147
387.6000000000048,44.2758787803397,1.045938848159682,-0.3610127512650285
388.4000000000048,44.35434665606251,1.0867492976362678,-0.3827337489683349
389.2000000000048,44.43211101816198,1.1288898322669587,-0.4041394035674295
390.00000000000483,44.51179693394237,1.1736725743141054,-0.41762481071645086
390.80000000000484,44.58691680943942,1.215385641498617,-0.4356247145412411
391.60000000000485,44.66623349310146,1.2653826922520857,-0.45657450144523537
392.40000000000487,44.74396491529507,1.3208770878643703,-0.4800772539770408
393.2000000000049,44.82055433413838,1.3722950380358065,-0.4997456866479424
394.0000000000049,44.900723379780224,1.4310368891919965,-0.5281577200302148
394.8000000000049,44.979624463459004,1.4869652594652414,-0.5510121941319484
395.6000000000049,45.057163823429924,1.5505054925702357,-0.5801411144233253
396.4000000000049,45.13410496756193,1.6129790393693044,-0.6100128855356273
397.20000000000493,45.213603232023914,1.6879501549728215,-0.6405940363683396
398.00000000000495,45.29174966416697,1.745630511067478,-0.6726536466219106
398.80000000000496,45.367684821956644,1.7904617969400896,-0.6994020064187527
399.60000000000497,45.44798763208428,1.8543882464594807,-0.7308151353158365
400.400000000005,45.52682420535075,1.9421380449347616,-0.7736040672816631
401.200000000005,45.60488667084839,2.020501761828351,-0.8152491404683357
402.000000000005,45.68365656830682,2.090816483326425,-0.861397681837972
402.800000000005,45.76274549599442,2.1808054046259846,-0.905459657935805
403.600000000005,45.83990579284183,2.268953026483015,-0.9494645552351826
404.40000000000504,45.92061475458051,2.3550966773225985,-0.9991937851636084
405.20000000000505,45.99931873405554,2.4534380743848363,-1.0488896598735158
406.00000000000506,46.07808415741722,2.5576667499617827,-1.102552002293971
406.80000000000507,46.15622903230171,2.6453636704979973,-1.1614653082733755
407.6000000000051,46.235194567690314,2.7472953541586125,-1.2198395451106272
408.4000000000051,46.3151687941584,2.850432316839207,-1.2769138255268397
409.2000000000051,46.39371663267537,2.9182773445126133,-1.335210172214826
410.0000000000051,46.47156378584563,3.0012391407422587,-1.3960320833718058
410.8000000000051,46.550103378173205,3.088118670272527,-1.4660328225612962
411.60000000000514,46.62886109413558,3.185721074139462,-1.5361359999712407
412.40000000000515,46.70687968643071,3.271289591960151,-1.6073186813280405
413.20000000000516,46.78634441055034,3.3574074926051685,-1.6814334047354182
414.0000000000052,46.86431813382752,3.4247183337503464,-1.7525566761245837
414.8000000000052,46.943471193348046,3.5010087756776005,-1.834148185183134
415.6000000000052,47.02144738901478,3.58341759218563,-1.9176824902913494
416.4000000000052,47.100458623639234,3.6551720989349605,-2.0060041872133008
417.2000000000052,47.17769211168363,3.685554401225424,-2.0888739401494907
418.00000000000523,47.25843240968658,3.726535661916698,-2.1755073957662816
418.80000000000524,47.336048895378724,3.742663628646131,-2.262698149536077
419.60000000000525,47.41458915505011,3.7500839142562987,-2.3461075929108244
420.40000000000526,47.49236873941977,3.7331090441258103,-2.4377398681814366
421.2000000000053,47.57099556160745,3.705755361241275,-2.5300520205914996
422.0000000000053,47.64728116765286,3.6654233939941143,-2.6139356441509776
422.8000000000053,47.72714086321634,3.6250412739890683,-2.70243020959555
423.6000000000053,47.80410463831759,3.5505800062548167,-2.7862031970990673
424.4000000000053,47.88322861567575,3.456043066015896,-2.8746407456979455
425.20000000000533,47.96091358787643,3.3404610009672098,-2.9535178239206625
426.00000000000534,48.03857030683663,3.2110283852222974,-3.0290047899057218
426.80000000000535,48.11573797347063,3.0754551061357476,-3.101015989021497
427.60000000000537,48.19338358477951,2.910024553892834,-3.176959969070035
428.4000000000054,48.27071604628493,2.7323366003642295,-3.2526802693254933
429.2000000000054,48.34827937438052,2.5472606354267975,-3.3169772043630266
430.0000000000054,48.42557085146221,2.355578329188865,-3.3762559671638823
430.8000000000054,48.50225751421424,2.1628327615530596,-3.431227231501764
431.6000000000054,48.579115004548704,1.9680736223148574,-3.4835424795736047
432.40000000000543,48.656112901822546,1.7794099060321407,-3.5280018320683912
433.20000000000545,48.73299711953521,1.5903589883751765,-3.568271160449319
434.00000000000546,48.80961726690164,1.41522603703663,-3.600811766942742
434.80000000000547,48.887478655088486,1.245340226231408,-3.632818759633994
435.6000000000055,48.964094426950986,1.0945805921188478,-3.6653900747202273
436.4000000000055,49.041545204591635,0.9510716288804737,-3.693176164319426
437.2000000000055,49.118342962844835,0.8244163279044552,-3.7145804925329555
438.0000000000055,49.19375983448696,0.7149361471558549,-3.7315626908481736
438.8000000000055,49.272825722628525,0.6125977482068632,-3.747550036069316
439.60000000000554,49.349695943100045,0.5292123289848948,-3.7649725347530953
440.40000000000555,49.424441492635964,0.45297637627774545,-3.7765640362694493
441.20000000000556,49.50304420997402,0.38716609162761784,-3.788441303618168
442.00000000000557,49.58220847446975,0.32730294107908897,-3.7961677743714755
442.8000000000056,49.65899641663413,0.28233135579218593,-3.8052073258347385
443.6000000000056,49.73581886954683,0.23780096549151425,-3.8120480624997497
444.4000000000056,49.81266274173267,0.20171126962802233,-3.815547173815995
445.2000000000056,49.89290395139577,0.16954432490795157,-3.8221300387452173
446.0000000000056,49.97058571567844,0.1412740099709528,-3.824972381943257
446.80000000000564,50.04798030600357,0.11500689592276817,-3.82755844189783
447.60000000000565,50.125291789269255,0.09815106617006553,-3.8347258151404056
448.40000000000566,50.20456634320547,0.08219280947256982,-3.836030928059476
449.2000000000057,50.28248052123779,0.06712825567915905,-3.837518464814276
450.0000000000057,50.36045437666884,0.055521733065736115,-3.8426482643118978
450.8000000000057,50.438061052758556,0.04483933423566751,-3.8452677544044493
451.6000000000057,50.516315666854865,0.03515290679315114,-3.8453644552475508
452.4000000000057,50.59550431997793,0.027526668048704225,-3.852722251252865
453.20000000000573,50.67266110293644,0.021486229656222017,-3.8503922666070554
454.00000000000574,50.7522908167692,0.01499630961665152,-3.8602395057892167
454.80000000000575,50.83019194720124,0.00995745982230603,-3.8571402052415933
455.60000000000576,50.90894663786394,0.006427214908696466,-3.859135953862427
456.4000000000058,50.987640502336156,0.0011379737448189153,-3.866889445366069
457.2000000000058,51.065826968252445,-0.0014847051134432854,-3.8648301945871735
458.0000000000058,51.14414144616982,-0.0035241948758624464,-3.8654644869003247
458.8000000000058,51.22137259465594,-0.00761717733005518,-3.86676645703868
459.6000000000058,51.302003573682406,-0.009697770948991796,-3.8695361264826458
460.40000000000583,51.37903382910092,-0.014912636333287904,-3.865932552945916
461.20000000000584,51.45859142727326,-0.016225801718147442,-3.8619611879900364
462.00000000000585,51.53767721669496,-0.019408297826806364,-3.8674398221278716
462.80000000000587,51.615602760750974,-0.020579399800456838,-3.871937864448994
463.6000000000059,51.69460217357276,-0.024305195629769794,-3.8717641610853235
464.4000000000059,51.773897688342814,-0.02468575717740043,-3.8732634560568315
465.2000000000059,51.852752903715015,-0.029632038642478445,-3.8742527958226836
466.0000000000059,51.93049794898818,-0.03131652084103288,-3.8722854905679833
466.8000000000059,52.00865979826806,-0.03296498927739436,-3.870858541301487
467.60000000000593,52.087720522861595,-0.031011843482180834,-3.8722548781757937
468.40000000000595,52.166334044382005,-0.03144237744986354,-3.873630260277715
469.20000000000596,52.24442837826691,-0.02738007440835369,-3.8711300739699084
470.00000000000597,52.32277180960056,-0.025403192321991577,-3.866901699388646
470.800000000006,52.40133291696583,-0.026095211926247197,-3.865043862107381
471.600000000006,52.479474590339215,-0.029242495025138426,-3.8680548259459493
472.400000000006,52.55862449916264,-0.03390507166234924,-3.8708728733289703
473.200000000006,52.637814930456756,-0.03614279184677899,-3.874834549860023
474.000000000006,52.71713048950347,-0.03858233661408983,-3.8773852419955124
474.80000000000604,52.79623380548376,-0.042961407879431465,-3.8764633476719785
475.60000000000605,52.8737838800502,-0.04759785264858876,-3.8763870660503907
476.40000000000606,52.95266954300882,-0.050944069387579685,-3.8765739898394966
477.20000000000607,53.032032784877735,-0.053101603049417204,-3.8778803767099554
478.0000000000061,53.11061965651439,-0.056216293135010836,-3.8778972260149644
478.8000000000061,53.18873346577565,-0.05898791506724316,-3.8751155207407315
479.6000000000061,53.26753826381052,-0.06347824473150523,-3.8698037945721477
480.4000000000061,53.34616995142267,-0.0660472916480535,-3.866613786193225
481.2000000000061,53.42273222133727,-0.06681789378109451,-3.8657687383815276
482.00000000000614,53.503424839671496,-0.06695373415380312,-3.867564496157241
482.80000000000615,53.5815901423921,-0.07048540825350495,-3.866247377764651
483.60000000000616,53.66078922555951,-0.07282406981200863,-3.864261713244293
484.4000000000062,53.7402008927324,-0.0752586309062821,-3.8629567950369745
485.2000000000062,53.818752007127316,-0.07906125141084655,-3.8658256734363463
486.0000000000062,53.896520013003126,-0.08172081757814253,-3.8657998537243596
486.8000000000062,53.97701851482399,-0.08427843630242578,-3.8644744159636826
487.6000000000062,54.054072702435555,-0.08367385650452079,-3.870746367185058
488.40000000000623,54.1345966097613,-0.08568803515370234,-3.873818723203689
489.20000000000624,54.21356988140685,-0.08550118769724194,-3.875762453544216
490.00000000000625,54.293168940965266,-0.08780538078171002,-3.8762673485964996
490.80000000000626,54.37184743052836,-0.09014799780991944,-3.873682517619091
491.6000000000063,54.45203712771314,-0.09470338714121751,-3.870212331246589
492.4000000000063,54.52953951907741,-0.09303900692412767,-3.867638423369481
493.2000000000063,54.61059768781965,-0.0944617692436938,-3.868376963624725
494.0000000000063,54.6901915505315,-0.09474594679643313,-3.8667732599606874
494.8000000000063,54.76939140394745,-0.09581400308471455,-3.8714863200156646
495.60000000000633,54.848561574582845,-0.09647883985725758,-3.8757724479332127
496.40000000000634,54.92670435510709,-0.09780514232214599,-3.8777309051723
497.20000000000636,55.006230301978206,-0.10057158206855885,-3.873610850248572
498.00000000000637,55.08454529477083,-0.10150537850627145,-3.8698767842846924
498.8000000000064,55.16506631647906,-0.1035861100216191,-3.8663790308328507
499.6000000000064,55.24467996307828,-0.1030880917113858,-3.8688696033692564
500.4000000000064,55.32302340377338,-0.10390020096493185,-3.870199941987025
501.2000000000064,55.40253315994642,-0.10269029927274183,-3.8708215782887887
502.0000000000064,55.48072751285065,-0.10486894134206678,-3.8717159181375838
502.80000000000643,55.56020285651932,-0.10394215045582296,-3.8692965370754147
503.60000000000645,55.637655313784066,-0.10550330474908559,-3.8700613683730847
504.40000000000646,55.71751269617013,-0.10510063314604666,-3.8716297637057027
505.20000000000647,55.795813187382535,-0.10544073473271637,-3.8699778762710157
506.0000000000065,55.874441137185094,-0.10280030661132025,-3.87086008357019
506.8000000000065,55.95384163340304,-0.10318088074528906,-3.8727304737189874
507.6000000000065,56.032935903438045,-0.10319652878857316,-3.8754292225590157
508.4000000000065,56.11066648716384,-0.10211004834110851,-3.874626257535706
509.2000000000065,56.19058225804884,-0.10482755723179193,-3.871781815264745
510.00000000000654,56.26782963243564,-0.10332720911970879,-3.8694869187912246
510.80000000000655,56.34722096356109,-0.10584334212043903,-3.8730409654187015
511.60000000000656,56.426189101692856,-0.10793126607841273,-3.876966812720794
512.4000000000066,56.50564094443271,-0.1085497742005227,-3.871489174227654
513.2000000000066,56.58308449578909,-0.11094203178167003,-3.8665103864586574
514.0000000000066,56.66212601740688,-0.11138283509419869,-3.867297172468732
514.8000000000065,56.74172201390186,-0.11171428732074352,-3.868854965996142
515.6000000000066,56.81901259341189,-0.10803442067292426,-3.8751322163982027
516.4000000000067,56.898581599798916,-0.11046920726902712,-3.8806048469904306
517.2000000000066,56.977777405611505,-0.11377538073321142,-3.8717187814975156
518.0000000000066,57.0567786699272,-0.11446708767014857,-3.863967659691543
518.8000000000067,57.13541380702338,-0.11566195827217442,-3.8682319949623576
519.6000000000067,57.214684371753876,-0.1149579977888745,-3.8714373327063183
520.4000000000067,57.29424546018913,-0.11424115774808848,-3.8774541200241157
521.2000000000066,57.37328640748259,-0.11457917937182943,-3.878395191793934
522.0000000000067,57.452771359333155,-0.11511705253325297,-3.8772439221845456
522.8000000000068,57.53289327039929,-0.11889848339572122,-3.873570903130517
523.6000000000067,57.61169969952274,-0.12137996482988714,-3.872577060801364
524.4000000000067,57.6908101545966,-0.1220380922387056,-3.8716201308006357
525.2000000000068,57.76881033373752,-0.12418285749458041,-3.8722564811543907
526.0000000000068,57.85009344274846,-0.1241603867648697,-3.8742731140415154
526.8000000000068,57.929484096482774,-0.12310492529222936,-3.875181522599079
527.6000000000067,58.009399858109724,-0.1257650102350826,-3.872932189874345
528.4000000000068,58.08787982782911,-0.12478191268224179,-3.8720602684932564
529.2000000000069,58.16825755723048,-0.12666402997280996,-3.874885054965732
530.0000000000068,58.248035418480676,-0.1261195390229111,-3.8753480695270217
530.8000000000068,58.326270195481726,-0.12556040353103257,-3.8733788653811976
531.6000000000068,58.405930897967266,-0.1280149975100266,-3.8717298376146023
532.4000000000069,58.485045506786015,-0.1306678164114421,-3.8710878740046555
533.2000000000069,58.564692351380444,-0.13076819417544258,-3.8724441023398573
534.0000000000068,58.64398070118495,-0.1314206581098242,-3.873066911987023
534.8000000000069,58.72284248470676,-0.13335061037956936,-3.871693967253469
535.600000000007,58.802418733586855,-0.13481574915414732,-3.870421865631089
536.4000000000069,58.88108928146313,-0.13450475298004258,-3.8704199144458498
537.2000000000069,58.96150992381353,-0.13580764803686157,-3.8719169743450705
538.0000000000069,59.03991428693472,-0.1369176873148037,-3.8679925097327224
538.800000000007,59.119529907036515,-0.1371659590407274,-3.8679864429276005
539.600000000007,59.198450629122455,-0.1379732915123685,-3.8695195433725305
540.4000000000069,59.2788146878366,-0.13895151113955523,-3.873160993815759
541.200000000007,59.3576812333725,-0.14024621504235485,-3.8734462302269708
542.000000000007,59.437214844356404,-0.14195072844719053,-3.873122939969926
542.800000000007,59.51574994789796,-0.14279463741043852,-3.8664125135319805
543.600000000007,59.59538059731235,-0.1472358561268694,-3.8643318371665902
544.400000000007,59.67505549970905,-0.14847981820908177,-3.868428489871796
545.2000000000071,59.7543205708256,-0.14512463063869233,-3.8684412448211987
546.000000000007,59.83179541077124,-0.14950614673449855,-3.869972550459045
546.800000000007,59.912416024466964,-0.14640021194896538,-3.874086204332087
547.000000000007,59.93327903164977,-0.14734988672114785,-3.8745898934692824