File: 01_Data/EIFS_Coating/STA/N2/30K_min/EIFS_Coating_STA_N2_30KData_230914_R3.csv
##Temp./Â°C,Time/min,DSC/(mW/mg),Mass loss/mg
41.0,10.537941958868915,0.0306947774126769,0.01664041736550903
42.40000000000002,10.77192081286495,0.08709780042528603,0.017639270337999946
43.80000000000004,10.915034264252476,0.13058303364969936,0.017791760082273456
45.20000000000006,11.02401071025154,0.1672227585157231,0.016186108582080472
46.60000000000008,11.117250989496384,0.20357329414803815,0.015947777479237146
48.0000000000001,11.203081065012578,0.22981995199903027,0.014282935356359161
49.40000000000012,11.281443253244788,0.2562949186719592,0.01627040746907582
50.80000000000014,11.35340559944466,0.2798185229823107,0.015810018731118092
52.20000000000016,11.42225577831091,0.3031574284800844,0.015444469920693038
53.60000000000018,11.487429304733363,0.32616730732929344,0.016113805429359473
55.0000000000002,11.550475858058066,0.34665174854671865,0.016187107477339424
56.40000000000022,11.610698724205738,0.36127443222452005,0.017309895261671038
57.80000000000024,11.669498833128724,0.3782506358570277,0.015320124305471694
59.20000000000026,11.726809811185353,0.3976092416252883,0.015366344383125785
60.60000000000028,11.783296186168705,0.4152952596031826,0.015220733358368044
62.0000000000003,11.838077163251505,0.4310594347804645,0.015617479877248819
63.40000000000032,11.89080552961899,0.4463395617105482,0.015459032988128563
64.80000000000034,11.945386630069532,0.4623422358751097,0.014221398430933618
66.20000000000036,11.998182857379973,0.478345451550226,0.014379744298422814
67.60000000000038,12.050102920144138,0.4954166332136918,0.014745501691533214
69.0000000000004,12.101973949748803,0.509272084700957,0.01500135070542541
70.40000000000042,12.153044343813349,0.5226318840606227,0.013206406053448916
71.80000000000044,12.20352208450854,0.536775536501776,0.011802505876657321
73.20000000000046,12.254184177731897,0.5500781667251424,0.013568084295486393
74.60000000000048,12.303943734701278,0.5664331948083047,0.01240350926110878
76.0000000000005,12.35306148195333,0.579848726880779,0.012292649747049467
77.40000000000052,12.403435858405082,0.5934833531808819,0.011328958804333489
78.80000000000054,12.452463080988784,0.6077716665296775,0.010687810843537981
80.20000000000056,12.501972284251396,0.6238031799828914,0.009682243609278274
81.60000000000058,12.55048392307249,0.63743332175291,0.009507836070490328
83.0000000000006,12.598857050076191,0.6526785751752657,0.010881610550739218
84.40000000000062,12.64759228214563,0.6664360465410825,0.0100785046812506
85.80000000000064,12.695651634769254,0.6797895545108694,0.009791885362440134
87.20000000000066,12.743607613501055,0.6938971728586278,0.009557458306758804
88.60000000000068,12.791192202504188,0.7036464202372781,0.00826789529334171
90.0000000000007,12.839373920568516,0.7135246945869647,0.006919372632212095
91.40000000000072,12.886234175086617,0.7192990750124847,0.006855787074147912
92.80000000000074,12.933881192574674,0.7229030281859096,0.006927831497093528
94.20000000000076,12.980485807470888,0.7194231268701049,0.005615621848185981
95.60000000000078,13.027012128367367,0.7116171583528195,0.005609372582580541
97.0000000000008,13.073265203608692,0.7009028420850875,0.004318567611992563
98.40000000000082,13.119632704239475,0.6864760039792704,0.004289979425093904
99.80000000000084,13.166009027102962,0.6768117119578434,0.004170298689359697
101.20000000000086,13.212435699467193,0.6670350209621153,0.0042964971040371225
102.60000000000088,13.258706647704363,0.6595886480652268,0.0029619440380503903
104.0000000000009,13.304940951659955,0.6540390645307552,0.0026432058524283875
105.40000000000092,13.350956914063662,0.6481026400862652,0.0016599922430513558
106.80000000000094,13.397422753186001,0.6435247863572993,0.0029625384328282323
108.20000000000095,13.4435953398304,0.6407992293195913,0.0029603112923481945
109.60000000000097,13.48864541434522,0.641068923038564,0.0029520480341806987
111.000000000001,13.535732071094268,0.6377335704971585,0.0026787491076154524
112.40000000000101,13.582027961599952,0.6397611339608837,0.0029853705149234244
113.80000000000103,13.627930921131092,0.6397850619489238,0.004291290679804938
115.20000000000105,13.673918845360062,0.6419147034372775,0.0043704319581188145
116.60000000000107,13.719031654137614,0.643350627437938,0.0029699841454027265
118.0000000000011,13.765790064222676,0.6496851574201166,0.0029698464046488127
119.40000000000111,13.812101582793668,0.650001008562278,0.002980983238104251
120.80000000000113,13.857441496543995,0.6529890237270864,0.0016595730355906113
122.20000000000115,13.90375470802126,0.6560167234751575,0.0016498958401989228
123.60000000000117,13.948875376728054,0.6564623860478569,0.0016499143765935642
125.0000000000012,13.993499849133746,0.6573758654623982,0.0016502411473426903
126.40000000000121,14.039303306914114,0.65343604696032,0.0017076615605073897
127.80000000000123,14.085393425542511,0.6546629375628525,0.00032936599707067415
129.20000000000124,14.130487833866574,0.6573428731299876,0.0003302651646972521
130.60000000000127,14.175813545480148,0.6558240521041461,0.0013346643453937546
132.0000000000013,14.220941611743704,0.6558797289234468,0.001649859103710405
133.4000000000013,14.266113653718484,0.6538703812138705,0.0016508167649780248
134.80000000000132,14.310513943740855,0.6561325026030205,0.0024234688623927525
136.20000000000135,14.355699399353172,0.6548323199396976,0.002969161435826706
137.6000000000014,14.400092601938878,0.6558997114275991,0.0029698161784299515
139.0000000000014,14.444790709280241,0.6551458605656858,0.002970141573825913
140.4000000000014,14.48945057947573,0.6585729560235375,0.003055501077374956
141.80000000000143,14.533948317926395,0.6604529399317463,0.0016494070081218837
143.20000000000147,14.578493591424925,0.6578500687477277,0.001649813795384425
144.60000000000147,14.623059192334079,0.662031841275226,0.001649825779725056
146.00000000000148,14.66707094364275,0.6622284077874783,0.0016519656425799667
147.4000000000015,14.711459057914364,0.6644194742496451,0.0013285823084991932
148.80000000000155,14.755156751283556,0.6666141104813358,0.0013202124908779922
150.20000000000155,14.799262998481044,0.6708286408098462,0.0013293953173558748
151.60000000000156,14.843760269196343,0.6702550248256851,0.0016516092897944645
153.0000000000016,14.887282971664387,0.6742178913455911,0.0016501586552006842
154.40000000000163,14.93099650804314,0.6749970368579447,0.0016501463819231788
155.80000000000163,14.975147996547808,0.6795067549257,0.0016498592919669264
157.20000000000164,15.018984300187274,0.6796552764183064,0.0014691621632145768
158.60000000000167,15.06260674639832,0.6811900576528002,0.0023166493430819557
160.0000000000017,15.10636876034376,0.6845185711950162,0.0023133386591629446
161.4000000000017,15.150167829635635,0.6861617989203574,0.0009750945349464857
162.80000000000172,15.193402722839506,0.6902657713793914,0.0009999982811574881
164.20000000000175,15.237408525472398,0.6913665278670338,0.0012029545963700983
165.60000000000178,15.280781797380344,0.6949019254179214,0.0023089037221541986
167.0000000000018,15.32428256325656,0.6973087795534711,0.002192416388934859
168.4000000000018,15.367783566196227,0.6968482285242992,0.0016524371244335256
169.80000000000183,15.411480740337014,0.6964336916888917,0.0009990668916923795
171.20000000000186,15.45450213493875,0.6996813419664887,-6.261375631311239e-07
172.60000000000187,15.497885439493986,0.7023920666328423,1.2061622278736195e-07
174.00000000000188,15.541440958501196,0.7049906438596042,1.249952958914946e-07
175.4000000000019,15.58448301493848,0.7045903177267651,1.250000334351853e-07
176.80000000000194,15.628124051298165,0.7089783510059606,1.2500000146076218e-07
178.20000000000195,15.67149396939998,0.7105869513742149,1.2499999968440534e-07
179.60000000000196,15.714205891403175,0.7115138528792646,1.2499999968440534e-07
181.000000000002,15.757553849126053,0.7150191662325498,1.2500015866834246e-07
182.40000000000202,15.800307246939353,0.7153513796431198,1.250259442642232e-07
183.80000000000203,15.84340917805737,0.7190421046367892,1.2087156875395522e-07
185.20000000000203,15.886151602037252,0.7196411918185519,-3.3016824838583148e-06
186.60000000000207,15.928934351803838,0.7222209469883835,0.0012994130786312397
188.0000000000021,15.97189980857722,0.7241778694890872,0.0013049314618056584
189.4000000000021,16.014857760072427,0.7284395587442527,0.0026339547109905936
190.80000000000211,16.05762349898578,0.7298461450319489,0.002630176860858313
192.20000000000215,16.100334036614314,0.7314319709956276,0.002635957044202719
193.60000000000218,16.1426789499516,0.7332616879384194,0.0012395093330415108
195.0000000000022,16.185447786475727,0.7350761295000726,0.0006657676997932072
196.4000000000022,16.228122674067514,0.7349458276269737,0.0013185665284858317
197.80000000000223,16.270914272482194,0.7379132732173769,0.0019827103833289783
199.20000000000226,16.31291797753512,0.7376303277353271,0.001980146397539073
200.60000000000227,16.355904143070802,0.741345652601782,0.001980145961577584
202.00000000000227,16.398615553606504,0.7428766406723558,0.0019801458512773706
203.4000000000023,16.441124296642673,0.746488139336173,0.001980286912136364
204.80000000000234,16.483586602984918,0.7473778957018777,0.001186137575113655
206.20000000000235,16.52623655233487,0.7502225468891137,0.0006609821405119121
207.60000000000235,16.568543862444827,0.7521201828437524,0.00066359978837216
209.0000000000024,16.611104242266848,0.7515589549709623,-0.0002886728577138342
210.40000000000242,16.65370232343313,0.7514121222382878,-0.0006475394302913884
211.80000000000243,16.696279277476307,0.7542237920374332,-0.000650319676358535
213.20000000000243,16.73862708190316,0.7556098951130209,-0.0006502044283882569
214.60000000000247,16.7808117900295,0.7579868963782431,-0.0006581932677587332
216.0000000000025,16.823347491018218,0.7607822127424043,-0.0009250939398564029
217.4000000000025,16.865446126153895,0.7631650544001946,-0.0029530979140215408
218.8000000000025,16.9076728135742,0.7662342302664539,-0.0030305069590639278
220.20000000000255,16.950755447289833,0.7656712388161508,-0.0015238235137529088
221.60000000000258,16.993102713168934,0.7674811236989643,-0.00032045202102537473
223.0000000000026,17.035439282487136,0.769261006562959,0.00044819627903258663
224.4000000000026,17.077419070424547,0.7728928815505558,-0.00033010785441067725
225.80000000000263,17.11973108633623,0.7697055116425713,-0.00042827516814369915
227.20000000000266,17.162286333344028,0.7737330055313019,0.0009880983688264067
228.60000000000267,17.204358437579007,0.7760643978834327,1.4245367649934337e-05
230.00000000000267,17.246775146017576,0.775386933673012,-0.0003298347965756676
231.4000000000027,17.28914010218912,0.7779757177207162,-0.00033006180514849603
232.80000000000274,17.331222016803117,0.7790735444855361,-0.0003299496880941888
234.20000000000275,17.37359076185142,0.7815701207490291,-0.00028221264552463765
235.60000000000275,17.41571654741088,0.7819116884357202,-0.0016408136628216496
237.00000000000279,17.457990649229245,0.7826510637252134,-0.0008938749769589194
238.40000000000282,17.50030015649225,0.7844264777497785,-0.0003314495018811314
239.80000000000283,17.542734058813554,0.7846655312231234,-0.0003311710207993812
241.20000000000283,17.584873563267497,0.7851804181310693,-0.0008601253010054322
242.60000000000286,17.627037366976786,0.7849202807311562,-0.0016627983204982044
244.0000000000029,17.66943734018813,0.7860846119213662,-0.0030646229929160995
245.4000000000029,17.711642774932333,0.7866024946458849,-0.0043894342495889305
246.8000000000029,17.75374490124812,0.7865533455269174,-0.004438412432707928
248.20000000000294,17.79583580020562,0.787042564695463,-0.0030788702095287945
249.60000000000298,17.838176620687857,0.7881715892466605,-0.00306990011633701
251.00000000000298,17.880223020545976,0.7886388663959758,-0.0030699481663791772
252.400000000003,17.922629061162933,0.7898625182569512,-0.003110648033038288
253.80000000000302,17.964812166461112,0.7913988185094204,-0.0020838165662357966
255.20000000000306,18.006943601885553,0.7913998455507221,-0.0006519114843062113
256.6000000000031,18.048896649572697,0.7916039482083761,-0.0007595827559239154
258.00000000000307,18.09140100786969,0.7905348684276707,-0.0007600671146281712
259.4000000000031,18.13356648414896,0.7917240701168128,-0.0007614598552185825
260.80000000000314,18.17559159954528,0.7903855210566693,-0.0013817690153459239
262.2000000000031,18.218017045898563,0.7898339698484796,-0.0007683376343994297
263.60000000000315,18.260164029816064,0.7931547658909508,0.0002276831325502826
265.0000000000032,18.301947445112233,0.792477938072663,0.00021997069359258603
266.4000000000032,18.344803303406053,0.7925159573657341,0.00022653446274745193
267.80000000000325,18.386844765646565,0.7934483437261992,-0.0010836250715753337
269.20000000000323,18.429258113839495,0.7953970966980843,-0.0011279269370865208
270.60000000000326,18.47128097769834,0.7947344673870742,-0.0004424735906178867
272.0000000000033,18.513381707162342,0.7956012865977046,-0.00044004401955444195
273.4000000000033,18.555734381116483,0.799046154268714,-0.00044005413588976694
274.8000000000033,18.597780308348366,0.7981124829278412,-0.00044449566972382115
276.20000000000334,18.640323823627245,0.7971524423400254,0.00026198118744780174
277.6000000000034,18.682211969399706,0.8002809235846032,-0.0011460351073360187
279.0000000000034,18.72469009698535,0.8018349894259691,-0.0011001780328134814
280.4000000000034,18.766546230408846,0.8022314562762806,-0.00110590567028801
281.8000000000034,18.809050652204437,0.805929778190598,0.00020345948631472766
283.20000000000346,18.851381600924917,0.8052306056632986,-0.0012983370706551867
284.60000000000343,18.893797250724877,0.8038052269302473,-0.0025230555312090175
286.00000000000347,18.936208606044882,0.8080077161304703,-0.0035926365485332568
287.4000000000035,18.978184072022245,0.8064518229636389,-0.003846743288732135
288.80000000000354,19.020754398314956,0.8101010710455104,-0.005149819201027306
290.20000000000357,19.062731345200426,0.8109244010018711,-0.005159993135928076
291.60000000000355,19.10547654111031,0.8097735846587466,-0.005150449457984152
293.0000000000036,19.147649683551816,0.8127948769535873,-0.00379682026562822
294.4000000000036,19.18993324289876,0.8136174439893067,-0.0037903173801323575
295.8000000000036,19.232269070302756,0.8157934972374327,-0.002504126526606143
297.2000000000036,19.27472742423032,0.8143062644584951,-0.0011906132967416383
298.60000000000366,19.31727398985814,0.8132870940623196,-0.0003782420692637345
300.0000000000037,19.359609687578082,0.8153874575730348,0.0014431151953289145
301.40000000000373,19.401883145165787,0.8181488882421959,0.001429991623911775
302.8000000000037,19.444366075314935,0.8177841367058842,0.0014298473474392281
304.20000000000374,19.486505486889452,0.8208673849352381,0.002534600101624207
305.6000000000038,19.529231817244114,0.8199465180758038,0.00340584800192012
307.00000000000375,19.571697715041065,0.8218126815680862,0.0054383154939481315
308.4000000000038,19.614060180800184,0.8238513236020397,0.00560007468299073
309.8000000000038,19.656683989226057,0.8240045640548532,0.005614502653380704
311.20000000000385,19.698713372473676,0.8272972965397599,0.005478721630633565
312.6000000000039,19.741628933995315,0.8266513607701658,0.004235722728857638
314.00000000000387,19.783868134580842,0.8289404238002297,0.003282323158168232
315.4000000000039,19.82633663759434,0.8293416736005795,0.001785351646165445
316.80000000000393,19.868871370485465,0.8272177386894024,0.00013497342335622164
318.2000000000039,19.911370197052676,0.8300097656659781,-0.0006411538964830044
319.60000000000394,19.954076941771724,0.8308648748398471,-0.001862683243288643
321.000000000004,19.99658161078745,0.8321941947549977,-0.0015611132747812562
322.400000000004,20.03905043553465,0.8351899203047264,-0.0015297893434169652
323.80000000000405,20.081832812734042,0.8341145598126605,-0.001526419089486808
325.200000000004,20.124331589899825,0.8373139223937854,-0.002810216489168127
326.60000000000406,20.1669601875456,0.8389779507031467,-0.0023463430322774315
328.0000000000041,20.2098531593761,0.8398377881828465,-0.0028575574535478765
329.40000000000407,20.2521581646768,0.8420547125907847,-0.004030833610377371
330.8000000000041,20.29501126655076,0.8452046292503194,-0.0041698711213138395
332.20000000000414,20.33781358701968,0.8472458869708072,-0.004169988829521465
333.6000000000042,20.380481495694493,0.8471115058436846,-0.004169983630699647
335.0000000000042,20.422855491255365,0.8497974212084503,-0.004166774895870695
336.4000000000042,20.465653450948913,0.852048217464252,-0.005090644938036348
337.8000000000042,20.508522069238797,0.8541757115295151,-0.005150009031084757
339.20000000000425,20.551415202023012,0.8553874441329757,-0.005148933891995888
340.60000000000423,20.59417156279821,0.8562305292590077,-0.005512232386916338
342.00000000000426,20.636780423529412,0.8593881155761441,-0.005481817088983654
343.4000000000043,20.6796614976671,0.8607017411310689,-0.00459866086993177
344.80000000000433,20.72284427443606,0.8636117619950522,-0.0058272614655852095
346.20000000000437,20.76558553264572,0.8642902697289749,-0.00581172525314777
347.60000000000434,20.808568890616773,0.8635894047335757,-0.006815583623514421
349.0000000000044,20.85154038786803,0.8615837394682128,-0.00690858797621452
350.4000000000044,20.894792422637103,0.8638625122181783,-0.0077749459553979605
351.8000000000044,20.93750557763107,0.8638094434584523,-0.006803130570922633
353.2000000000044,20.980619821820483,0.8617353522208987,-0.008102551205591446
354.60000000000446,21.023597874382002,0.861356635633285,-0.00814150255761703
356.0000000000045,21.066593153979866,0.860228587503119,-0.009444858765692565
357.4000000000045,21.109799546240072,0.8599858736769127,-0.009439282776676272
358.8000000000045,21.152612908318467,0.8608974120349671,-0.010736096444494692
360.20000000000454,21.196056396467096,0.8606186620231014,-0.010892398395871972
361.60000000000457,21.239108890611817,0.8601812870845924,-0.012069963714568921
363.00000000000455,21.281928819276075,0.8619730599297554,-0.012679131828181589
364.4000000000046,21.32535488374764,0.860925107962158,-0.013365332279297704
365.8000000000046,21.36874113545954,0.8596001888299057,-0.013688575787063506
367.20000000000465,21.411244081253265,0.8601904586377835,-0.014250173544123612
368.6000000000047,21.454757778617296,0.860033719379387,-0.015029856439188194
370.00000000000466,21.49857221195425,0.8619852653124029,-0.01634796025086871
371.4000000000047,21.541886967970676,0.8614216544966928,-0.017227015369470244
372.80000000000473,21.58477436308228,0.8590808943798104,-0.01898822815071366
374.2000000000047,21.62839925424348,0.8641598561088397,-0.020055386783373486
375.60000000000474,21.671601135033068,0.8657787662220474,-0.02019117026593431
377.0000000000048,21.715430797589963,0.8669225624863299,-0.021355172776367226
378.4000000000048,21.758552233300993,0.8699091777144632,-0.02272339930746803
379.80000000000484,21.80230755787935,0.8730882370322492,-0.02402671840000803
381.2000000000048,21.845584016875826,0.8771792260582122,-0.025559785726358975
382.60000000000485,21.889293830956007,0.8812137353373344,-0.026688632037767945
384.0000000000049,21.93270315520553,0.8850322028272428,-0.029537977145587924
385.40000000000487,21.97631675930179,0.8930621403635164,-0.0310632086592717
386.8000000000049,22.01997338013626,0.8967765358746932,-0.032511011604134055
388.20000000000493,22.063672197570742,0.9043612578534759,-0.0354338640481453
389.60000000000497,22.106671387497304,0.910649148191236,-0.03772408104505143
391.000000000005,22.15061533493142,0.9212289427708806,-0.0404847103127457
392.400000000005,22.19461126434949,0.9329017734973689,-0.043069333678880994
393.800000000005,22.238600431044254,0.943547397480186,-0.047265026797461474
395.20000000000505,22.28218564065395,0.9555878348184502,-0.0511586759366347
396.600000000005,22.32611614241007,0.9684717172566099,-0.0549529454201938
398.00000000000506,22.369997848246793,0.9812613410780711,-0.05806611600864109
399.4000000000051,22.4139393303679,0.9950383719735771,-0.06258844677820274
400.8000000000051,22.457854230256057,1.0109615320302634,-0.06766827960304234
402.20000000000516,22.50168557653491,1.0238733776903999,-0.07173466409522833
403.60000000000514,22.54573016915432,1.036984663385748,-0.07799232560982716
405.0000000000052,22.589265030095284,1.0464987795157517,-0.08454115803998352
406.4000000000052,22.633266554151387,1.0585199527079543,-0.09008610332708544
407.8000000000052,22.677009261227795,1.0648274417549854,-0.09588950773150806
409.2000000000052,22.721101081919386,1.0669572192719365,-0.10221856419631337
410.60000000000525,22.765087316301873,1.069019653237053,-0.11009149782371574
412.0000000000053,22.809106469858445,1.0680587635231746,-0.11756226565000771
413.4000000000053,22.85278382059941,1.0619987055012219,-0.1254036153458249
414.8000000000053,22.896337016317926,1.0554860785456222,-0.1315116880748195
416.20000000000533,22.93946770740266,1.0409058607348947,-0.13967684766119914
417.60000000000537,22.983787302097966,1.0260758474959581,-0.1471187345539211
419.00000000000534,23.02755033669866,1.0094655673533364,-0.1537337988488252
420.4000000000054,23.071322600634005,0.9864291886051189,-0.15954546249889168
421.8000000000054,23.11499245847384,0.9639843545327215,-0.16627475164653616
423.20000000000545,23.15849174106036,0.9408944238756697,-0.17326207270241634
424.6000000000055,23.202215820670652,0.9170473782773233,-0.18002822668885976
426.00000000000546,23.24583358985852,0.8887332193873492,-0.1840095466563887
427.4000000000055,23.289602359288203,0.8601150113987566,-0.18787834409812199
428.8000000000055,23.333018614411518,0.8319306102328073,-0.1930008545667139
430.2000000000055,23.37694945151717,0.8025181575137533,-0.19581386824496594
431.60000000000554,23.42052192067406,0.7757110280564532,-0.19983137803736284
433.00000000000557,23.464482811433857,0.7571391183661017,-0.20152334267699068
434.4000000000056,23.508238803949055,0.736131953640957,-0.20350544241581092
435.80000000000564,23.552149100499292,0.7215657067932314,-0.20510031226736736
437.2000000000056,23.595955606714583,0.7102414631593603,-0.2063845202304746
438.60000000000565,23.640132550902404,0.6994774484096614,-0.20700791208701208
440.0000000000057,23.684354765826928,0.6946804662672303,-0.20783387792165087
441.40000000000566,23.72833331137,0.6879242303661037,-0.20909952908891105
442.8000000000057,23.77247728064761,0.6804340747008832,-0.20778667453867472
444.20000000000573,23.816657436241574,0.6797551538725837,-0.20911679132974337
445.60000000000576,23.861093525055185,0.6754375927480906,-0.20912706166012685
447.0000000000058,23.90523788595294,0.6728860824466008,-0.21042698335767263
448.4000000000058,23.949456121535228,0.6706230526613212,-0.21177267001336775
449.8000000000058,23.993810200226722,0.670774948402916,-0.21072811091839316
451.20000000000584,24.03824788482814,0.6670953545207422,-0.21208813071297605
452.6000000000058,24.082604446932816,0.6641941167195626,-0.21302853994016546
454.00000000000585,24.126944421425087,0.6615568257744947,-0.21340954896784492
455.4000000000059,24.171044997702634,0.6622022317852575,-0.21341000395379117
456.8000000000059,24.215691888126496,0.6595279290749569,-0.21341439461204725
458.20000000000596,24.26018419895224,0.6590885055861048,-0.21415652861252665
459.60000000000593,24.304747229074714,0.656106823682476,-0.2144271956589079
461.00000000000597,24.34923660046586,0.6563712826580403,-0.21452001187739
462.400000000006,24.393795779202108,0.6587442223886236,-0.21532666325046002
463.800000000006,24.438249313780823,0.6554212461792075,-0.2155334013502781
465.200000000006,24.48278627660131,0.6551825109638681,-0.21453034741761545
466.60000000000605,24.527565874497657,0.6565726529676214,-0.2158328340810618
468.0000000000061,24.57200963084781,0.6543381407086953,-0.21577334722922137
469.4000000000061,24.616261646076243,0.6562057017723558,-0.21714889623027966
470.8000000000061,24.6613701759206,0.6541839349271377,-0.21716088112369292
472.2000000000061,24.70603914270541,0.6561471564996267,-0.21821755664245046
473.60000000000616,24.750644161853742,0.6585309479969113,-0.21806128748978004
475.00000000000614,24.795365871531455,0.6624581012623882,-0.21910933774455943
476.4000000000062,24.840156566064945,0.6629575524018219,-0.21915443734986617
477.8000000000062,24.88478461078215,0.6643776080975671,-0.22044320641105397
479.20000000000624,24.929420810204423,0.6651200740792418,-0.22043996556458456
480.6000000000063,24.97443781866272,0.6676148631984835,-0.22051560086047317
482.00000000000625,25.019234681456673,0.6668822596855244,-0.22175986578799245
483.4000000000063,25.063771799608755,0.6694647584609479,-0.2218320778738887
484.8000000000063,25.108625422277377,0.6709354622192691,-0.2217148363831538
486.2000000000063,25.15362108211026,0.6729346904280041,-0.2224188206733233
487.60000000000633,25.198595994213928,0.6722646317301042,-0.2236925257748159
489.00000000000637,25.243582555693436,0.6727695040575739,-0.22373036669273683
490.4000000000064,25.288213473192116,0.6696837282111185,-0.22372627424082836
491.80000000000643,25.33342337660163,0.6728478288006547,-0.22507669384514806
493.2000000000064,25.378258765117018,0.6703402880021694,-0.22535333430900728
494.60000000000645,25.423093041904323,0.6698460651728934,-0.2264669862149158
496.0000000000065,25.467622271434323,0.6667865847025987,-0.22636995903421742
497.40000000000646,25.512364237291813,0.6710323539433635,-0.22637956005277582
498.8000000000065,25.55773437719039,0.6677906093278174,-0.22770381575488008
500.2000000000065,25.602437741048302,0.6648991501725271,-0.22768560835823282
501.60000000000656,25.648094779298404,0.6623261682157764,-0.2290046994793573
503.0000000000066,25.692864760051886,0.662366417198936,-0.22900728271730086
504.40000000000657,25.73782961973908,0.6625502506270815,-0.23028145408112666
505.8000000000066,25.78282718194078,0.6604912347035597,-0.23033020292729445
507.20000000000664,25.82817650346891,0.6645069428431681,-0.23033000797550818
508.6000000000066,25.873196278087345,0.6691204468249047,-0.23024724732536983
510.00000000000665,25.91832035369068,0.6792121091510017,-0.23163991675434614
511.4000000000067,25.963378136959523,0.6837412404180733,-0.23240855336121813
512.8000000000068,26.00826736314771,0.690498887309649,-0.23295971279025807
514.2000000000068,26.053297979342144,0.6929709596794501,-0.23301732666488206
515.6000000000067,26.098789370158574,0.6948855162925465,-0.23163825064857235
517.0000000000068,26.14360833522827,0.69632868955736,-0.23203717797812606
518.4000000000068,26.189202794681073,0.6994395305487635,-0.2329600228789923
519.8000000000068,26.234314944798857,0.7009937472951773,-0.23428664601936777
521.2000000000069,26.279627471133,0.7047427361339306,-0.23428018068522238
522.6000000000068,26.324779958277148,0.705172856902311,-0.23428018305319265
524.0000000000068,26.369726338161612,0.7052262883213356,-0.23428015107525946
525.4000000000069,26.415210169831226,0.7068874956221912,-0.23426757437714452
526.8000000000069,26.460465198280254,0.7037786802991747,-0.2329701945629319
528.2000000000069,26.505744785891824,0.701936359716128,-0.23297435258216082
529.600000000007,26.550910356288192,0.6986559075045964,-0.23425970370734506
531.0000000000069,26.596153824012223,0.697384362877374,-0.23427121113394334
532.4000000000069,26.641481246927942,0.6944814796131842,-0.23478564801264
533.800000000007,26.686945211530148,0.6942987966533628,-0.23459965226703794
535.2000000000071,26.732160502228567,0.6886802527446421,-0.2346006476533251
536.6000000000071,26.777124972739294,0.686398191688686,-0.23515051127580167
538.000000000007,26.82285995655533,0.6826782497604609,-0.23526033348728825
539.4000000000071,26.868164209931678,0.6820623426761463,-0.2352599643403699
540.8000000000071,26.913378180503514,0.6724108027741251,-0.23525996950061812
542.2000000000071,26.95894247442735,0.6627790429213197,-0.23526014068016732
543.6000000000072,27.004293784699954,0.6516253587936948,-0.23598604279476332
545.0000000000072,27.050054295616857,0.6397222082745961,-0.23591514917550427
546.4000000000071,27.095267424397278,0.6283149220247132,-0.23559544241060726
547.8000000000072,27.140751546227424,0.6252194889460999,-0.2366537334540384
549.2000000000072,27.186366109022114,0.6226034368998528,-0.23692807685192863
550.6000000000072,27.23165262416998,0.6208668774711433,-0.23625768729509922
552.0000000000073,27.277365668704906,0.618021200939515,-0.23649722193794664
553.4000000000073,27.323179691177803,0.6175682745395557,-0.23657855755023594
554.8000000000073,27.368674334271454,0.6154398087558918,-0.23723168367900493
556.2000000000073,27.413908632834115,0.6098139837570037,-0.23723982455106585
557.6000000000073,27.459688746170272,0.6096566549269282,-0.23861916845072706
559.0000000000074,27.505340070681385,0.6059339256567555,-0.23856344139662022
560.4000000000074,27.551315291654674,0.6035912789009426,-0.23909623141375036
561.8000000000075,27.59671777064113,0.5976044997252807,-0.23856003874260479
563.2000000000074,27.642446060762673,0.5905416901464329,-0.238536747401914
564.6000000000074,27.68837716213993,0.585945536348633,-0.23724131443449803
566.0000000000075,27.73376742233872,0.582248078550778,-0.23715867480770259
567.4000000000075,27.779540327808512,0.5828198440845813,-0.2385613340849111
568.8000000000075,27.825283060559588,0.5800359371742906,-0.2399029211034942
570.2000000000075,27.87091665598842,0.582885198795706,-0.23987983252671974
571.6000000000075,27.91648405399011,0.5931055427465721,-0.23987995439100018
573.0000000000075,27.96364003762104,0.6828949387495128,-0.2398871939208318
574.4000000000076,28.009460161501913,0.6572388386681244,-0.23855878651799323
575.8000000000076,28.0541846953369,0.6101080635828455,-0.23855995665276009
577.2000000000077,28.100115154654794,0.5782558436748058,-0.23855915013263873
578.6000000000076,28.145802576760243,0.5592503144001197,-0.23986151816679246
580.0000000000076,28.191252669686005,0.5495645278638335,-0.23987988468994415
581.4000000000077,28.23713794325283,0.5394442982861045,-0.2398798550932102
582.8000000000077,28.283077651877132,0.5362990782867973,-0.23987984269109885
584.2000000000078,28.329104601706828,0.5327657965969232,-0.23987973390025008
585.6000000000078,28.37491910333993,0.5332391983432259,-0.24119614235295117
587.0000000000077,28.42013296777503,0.5334440740577651,-0.24118997657360053
588.4000000000078,28.46677009587195,0.5342770875356799,-0.2411837244030206
589.8000000000078,28.51246016247725,0.5366001830428899,-0.2425164168224594
591.2000000000078,28.5583364225577,0.538406278182965,-0.2424991434462429
592.6000000000079,28.604580170842222,0.5363477486849962,-0.24118683127432572
594.0000000000078,28.65060167893314,0.5369851168697661,-0.24124314536480584
595.4000000000078,28.696297077576297,0.5385983135770747,-0.2425123283096271
596.8000000000079,28.74286912722644,0.5405001799775391,-0.24251019182123734
598.2000000000079,28.78897441213525,0.5404764235180178,-0.24251019699962484
599.600000000008,28.834897109517822,0.5376475199679949,-0.2425101976484747
601.000000000008,28.880876341435975,0.5409408403114009,-0.24250994406240034
602.4000000000079,28.927336816906617,0.5408740159477128,-0.24372694397014172
603.800000000008,28.973235159686695,0.5436228218517591,-0.2428526396128654
605.200000000008,29.019426985291524,0.5416019433692323,-0.24251079150638422
606.6000000000081,29.065603035931094,0.542152120968678,-0.242537863867895
608.0000000000081,29.111945038226697,0.5471551545176988,-0.2438181658244689
609.400000000008,29.158086935306628,0.5452759525521067,-0.2438198478233078
610.8000000000081,29.20405553361813,0.5504301895840876,-0.2438173979853442
612.2000000000081,29.250201159326707,0.5508517475428378,-0.24315720352002668
613.6000000000081,29.296525624841884,0.5503979922684872,-0.24381989780134283
615.0000000000082,29.343091143092447,0.5485012398563894,-0.24383015145231557
616.4000000000082,29.38904068980677,0.5507902683899603,-0.24382999086941615
617.8000000000081,29.434796203061747,0.555306979477397,-0.24443859629993314
619.2000000000082,29.48162660480789,0.5583870021507163,-0.24514854021532306
620.6000000000082,29.52804660297468,0.5590257945044166,-0.24526984654579298
622.0000000000083,29.574466027514898,0.5610664654698634,-0.2463661374642907
623.4000000000083,29.620688686910917,0.5623281753656859,-0.24777799267099176
624.8000000000083,29.666879429290738,0.5604443237002877,-0.2464551773050374
626.2000000000083,29.713281500862006,0.5683063127192102,-0.2464824575508291
627.6000000000083,29.759834417202338,0.5696076421520715,-0.24746811469348895
629.0000000000084,29.805479975411853,0.571928110856525,-0.2477790611273214
630.4000000000084,29.852660482114377,0.576068667533701,-0.2480688420236845
631.8000000000084,29.89899925941385,0.5822652458041426,-0.249099983911516
633.2000000000085,29.945405276338,0.5845904879989021,-0.24909996727002293
634.6000000000084,29.99194153604715,0.5858613290974893,-0.2491000115917501
636.0000000000084,30.03808397623392,0.5933412727979143,-0.24910677390712888
637.4000000000085,30.084584612980745,0.5958547888861752,-0.24955713239635502
638.8000000000085,30.13072869736109,0.596877916831484,-0.24908398488828354
640.2000000000085,30.17726695382543,0.6044613619130323,-0.2504047371638536
641.6000000000085,30.22378818810257,0.6056255458480354,-0.2496499928892999
643.0000000000085,30.269827389984552,0.6097844252718392,-0.24909314510848501
644.4000000000086,30.316746394913647,0.6144846089370196,-0.2504123259787727
645.8000000000086,30.363366758603544,0.6215838459102047,-0.25172497610845257
647.2000000000086,30.40936610255107,0.6270947209344413,-0.2528874626684412
648.6000000000087,30.45626036967414,0.6340357820278495,-0.25172305918806437
650.0000000000086,30.50251121051966,0.6430744459279557,-0.2530560400263484
651.4000000000087,30.549374693184756,0.6522669665409199,-0.2534700874777056
652.8000000000087,30.596190195314136,0.6645722078253549,-0.25468257774283964
654.2000000000087,30.64247723326007,0.6689000067273277,-0.2570291470227368
655.6000000000088,30.688636263255827,0.6842271514650069,-0.25699828525783763
657.0000000000088,30.73501488500682,0.692967144393352,-0.2583538594501271
658.4000000000087,30.782703560547933,0.7000613447000017,-0.25693073507530073
659.8000000000088,30.828834388453746,0.7103342396559682,-0.2583185551359026
661.2000000000088,30.87598208113843,0.7178783084757152,-0.25963533825147955
662.6000000000088,30.922336711918064,0.7258621821217918,-0.259751171154996
664.0000000000089,30.968940031374192,0.733764049809183,-0.25963342797973166
665.4000000000088,31.015721412200058,0.7491330851816066,-0.2609541310397425
666.8000000000089,31.062117391428043,0.7594942212263001,-0.2622542181636587
668.2000000000089,31.108379827906887,0.7743386645640713,-0.2635565460998963
669.6000000000089,31.155721140966765,0.7908930658871478,-0.2649399719621299
671.000000000009,31.202376743030793,0.805397691664149,-0.2665408499277655
672.400000000009,31.24920424801786,0.8192576955636905,-0.2687480724829907
673.800000000009,31.295825431691597,0.8308947070311767,-0.2684517096104311
675.200000000009,31.342670388311905,0.8521851917381689,-0.2697341080052804
676.600000000009,31.389272810837195,0.8723567182924421,-0.27106074335727026
678.0000000000091,31.43623256337243,0.8936954986420285,-0.2725079930001866
679.4000000000091,31.48278079331061,0.9195405230553167,-0.27511756919986663
680.800000000009,31.529560371354922,0.9441795209889821,-0.2770946338413047
682.2000000000091,31.57636101238608,0.9707536565109431,-0.2784067762022717
683.6000000000091,31.62323823399796,0.9943610760910304,-0.27932912333026705
685.0000000000091,31.67030202789339,1.0176700794995206,-0.28150037124301575
686.4000000000092,31.71687819977923,1.0462833718482722,-0.28417750147065135
687.8000000000092,31.76376887701485,1.069310270614765,-0.2854647582968175
689.2000000000093,31.810754682001697,1.0984607944907276,-0.28835339766999724
690.6000000000092,31.857801618475087,1.1269369101613131,-0.2905150563068126
692.0000000000092,31.904491846204035,1.1571366007906696,-0.2922001829832026
693.4000000000093,31.951491037352177,1.1907496238876811,-0.295224120960774
694.8000000000093,31.99876883161336,1.2226183459845403,-0.298251180743736
696.2000000000094,32.04526496671549,1.2549911262831661,-0.3010758949184211
697.6000000000093,32.09237266486513,1.2937591014394967,-0.3030337487481698
699.0000000000093,32.13951608311387,1.3294936982123795,-0.30654696138410387
700.4000000000094,32.18636960027901,1.371218293659803,-0.31013147033869926
701.8000000000094,32.23328439252579,1.416514114381011,-0.3124954888371767
703.2000000000094,32.280394956233906,1.4534141103192721,-0.315482679677785
704.6000000000095,32.327535824785365,1.499954294057968,-0.3197610261972019
706.0000000000094,32.37491054375293,1.5464106127260622,-0.32479246613702806
707.4000000000094,32.421675334325116,1.6010345816057303,-0.32954159472137423
708.8000000000095,32.469441847152666,1.6520997020763257,-0.3328712718551641
710.2000000000095,32.51644478060135,1.7006938406811571,-0.3373072101824577
711.6000000000096,32.56387365945666,1.7624151909631203,-0.3422004923647646
713.0000000000095,32.61141096027326,1.8136069779908701,-0.3468993451877074
714.4000000000095,32.65826379042026,1.874406323409395,-0.3514050753227478
715.8000000000096,32.7051807296112,1.932759915623543,-0.3558789462804719
717.2000000000096,32.75298612134498,1.9931117080313645,-0.36067233743611693
718.6000000000097,32.800472182647475,2.057064847618015,-0.3655387825686738
720.0000000000097,32.8472555093224,2.1262580004345795,-0.37167773911501767
721.4000000000096,32.89422105298463,2.1914514301349644,-0.37762676189985145
722.8000000000097,32.94236435890251,2.2598039747299627,-0.38417126721033723
724.2000000000097,32.98985675510323,2.3354782441261825,-0.3904679435481615
725.6000000000097,33.03807559571745,2.40952254392444,-0.3975400598484584
727.0000000000098,33.08532071917599,2.4870605181840606,-0.405739574897503
728.4000000000098,33.13299475741856,2.5662633452248635,-0.41255769155672306
729.8000000000097,33.180833571496905,2.6451236267959075,-0.4195120281100917
731.2000000000098,33.2283047736247,2.7317815376549146,-0.42776332813128537
732.6000000000098,33.2760989631013,2.8179427215743598,-0.4364720041329737
734.0000000000099,33.32409876287393,2.9065280339142916,-0.4451454415089402
735.4000000000099,33.37172579094158,2.9939371045254775,-0.452624850559054
736.8000000000098,33.418866405681996,3.0806646023036546,-0.4619254765563139
738.2000000000099,33.46754276861613,3.174012365898035,-0.4723984120221285
739.6000000000099,33.51536621785797,3.2707111954203754,-0.482254985573896
741.00000000001,33.563473449986006,3.3694560274716268,-0.4921313864104464
742.40000000001,33.611256938397155,3.4676770023087613,-0.5028228432703532
743.80000000001,33.65889716865818,3.5718899302449745,-0.5117165551299832
745.20000000001,33.70735880166096,3.675704786531783,-0.5238306368105103
746.60000000001,33.75534208897159,3.7858831904562553,-0.5354566868538018
748.00000000001,33.80318038795424,3.8949316151333266,-0.548005671871298
749.4000000000101,33.85108161314168,4.001375295468308,-0.5612941512200211
750.8000000000101,33.899102077735385,4.113635823426222,-0.574221359803953
752.20000000001,33.947415682307835,4.2236040297506605,-0.5866287301641484
753.6000000000101,33.995268627608965,4.338192839737317,-0.5990751746849212
755.0000000000101,34.0435520942846,4.455276719180765,-0.6137105280681676
756.4000000000102,34.09154815305221,4.572106233613444,-0.6284530518171465
757.8000000000102,34.13985755552436,4.694404622896297,-0.643527710380277
759.2000000000102,34.188210978550735,4.815485319870284,-0.658887348973026
760.6000000000103,34.23598507323146,4.938896147542066,-0.6745143574184111
762.0000000000102,34.284463143684235,5.065846812373569,-0.689831359359466
763.4000000000103,34.332473285283214,5.189547804047976,-0.7067780338118728
764.8000000000103,34.38106694978622,5.318604472558737,-0.7256047656011804
766.2000000000103,34.42931117835219,5.452362864079597,-0.7426104231201225
767.6000000000104,34.47731994376566,5.5826013197958355,-0.76102131400943
769.0000000000103,34.52559678243309,5.709437397433124,-0.7800748274305875
770.4000000000103,34.57419192393177,5.844218252838274,-0.7999642945297447
771.8000000000104,34.62252117019681,5.975538050973377,-0.8205661829880526
773.2000000000104,34.67061738741921,6.103962138809998,-0.8409231250360012
774.6000000000104,34.71841484975171,6.229757029410118,-0.8623461708387574
776.0000000000105,34.76678573355547,6.355741225842893,-0.8835638495509293
777.4000000000104,34.81495313793865,6.4742992151085295,-0.9046155387885069
778.8000000000105,34.86289269060767,6.583998848336603,-0.927175606578412
780.2000000000105,34.910993056676,6.682706771950683,-0.9490485427007722
781.6000000000105,34.95894002483598,6.770612532352737,-0.9716913267127145
783.0000000000106,35.007142684732926,6.84605412295348,-0.9948495498987766
784.4000000000106,35.05459484298768,6.897704679244774,-1.0175815484837547
785.8000000000106,35.10177917160795,6.931455768839826,-1.0414019405853514
787.2000000000106,35.14889515632067,6.9366252046968455,-1.0639077316274355
788.6000000000106,35.19589032202937,6.899210298168181,-1.0870594615901328
790.0000000000107,35.24210104924228,6.827530240010229,-1.1097654381421127
791.4000000000107,35.288517083255165,6.701873360449697,-1.132031045041313
792.8000000000106,35.33414953497277,6.511231256889888,-1.1549875807120795
794.2000000000107,35.37956251194472,6.253560844624076,-1.176392593033463
795.6000000000107,35.42376122366786,5.920789947554131,-1.1957306334433433
797.0000000000107,35.467249020600704,5.501913502711574,-1.2133771982866999
798.4000000000108,35.51088886025939,4.977889571429423,-1.2296085786238895
799.8000000000108,35.55313998125897,4.3720312585297085,-1.2430651599929052
801.2000000000108,35.59503508420981,3.7032064489610153,-1.2553460573414115
802.6000000000108,35.63660210732182,3.025592768480112,-1.2659693269578538
804.0000000000108,35.67883717084979,2.370863174636453,-1.2751574812785487
805.4000000000109,35.72146953601041,1.8016052802511855,-1.282039745920617
806.8000000000109,35.76461756849752,1.3373929912309424,-1.2868519051017162
808.200000000011,35.80881814230789,0.9845474675402303,-1.2900688722823501
809.6000000000109,35.85345349063275,0.7327570854739982,-1.292536681608612
811.0000000000109,35.89978476427582,0.5541734269058969,-1.2945501869102047
812.400000000011,35.94569533337456,0.4334526082093276,-1.2958631490371815
813.800000000011,35.99208432449582,0.34745216540228024,-1.2973302384258574
815.200000000011,36.038837185416604,0.3031926553997301,-1.296508916353019
816.600000000011,36.0856857108278,0.27657360184768187,-1.2971822601040555
818.000000000011,36.13302451407302,0.25819405363835696,-1.2958798055325986
819.400000000011,36.18008781294865,0.2472104746277686,-1.2972347262761414
820.8000000000111,36.227224374680574,0.2345990648526337,-1.2971905564344564
822.2000000000111,36.274495425120705,0.23257001708203656,-1.2971027620691609
823.6000000000112,36.32149758115137,0.22937292243563592,-1.2965994016004938
825.0000000000111,36.3688664160731,0.23044073862746386,-1.296535054491664
826.4000000000111,36.416237967053796,0.22769088828209608,-1.2976581359212571
827.8000000000112,36.46352446066231,0.23063444478320613,-1.2978504105386537
829.2000000000112,36.5107392898597,0.2307447175800416,-1.2978500277602927
830.6000000000113,36.55827740048933,0.22640112276645333,-1.2978506960009026
832.0000000000113,36.60544445547818,0.22616506612193565,-1.2991178675218213
833.4000000000112,36.65277589084376,0.22215165364505868,-1.2978606670795911
834.8000000000113,36.70013956422349,0.22144670578379208,-1.297859930173518
836.2000000000113,36.74710652531027,0.21875643197655414,-1.297859961055242
837.6000000000113,36.79469054800507,0.2198303224365935,-1.2978460863935393
839.0000000000114,36.842038814816036,0.21346710310046832,-1.2979549829335295
840.4000000000113,36.88916931617407,0.2120108597908721,-1.297859832574952
841.8000000000113,36.93670960124479,0.21228798896601073,-1.297859827655099
843.2000000000114,36.98380504575846,0.20590727065748787,-1.2978598269789945
844.6000000000114,37.031117740894544,0.20299597507398776,-1.29786013685567
846.0000000000115,37.07865187958237,0.2004180798456577,-1.2984723174519641
847.4000000000115,37.12641014337181,0.1980249750851121,-1.3003718706153502
848.8000000000114,37.173205619843166,0.19524200416486526,-1.3006037148035916
850.2000000000115,37.220836666290566,0.19370838380621433,-1.2992819750268119
851.6000000000115,37.26819048199858,0.18934410649802833,-1.2992561126634605
853.0000000000116,37.31569722095144,0.18748362610486421,-1.2979621358121172
854.4000000000116,37.3634711868242,0.17820013127191597,-1.2979601561047813
855.8000000000116,37.41111479659843,0.17483554117514977,-1.2979603556012056
857.2000000000116,37.45823438669848,0.18012323467208372,-1.2992973258541323
858.6000000000116,37.50574288051609,0.1692695586121487,-1.2982826918607109
860.0000000000116,37.552714226723594,0.17175988024623218,-1.2979644493715314
861.4000000000117,37.60082434716511,0.16865148956298892,-1.29929427453908
862.8000000000117,37.64815556158294,0.16669361995857174,-1.2992899665992206
864.2000000000116,37.69585630617034,0.1593663626400007,-1.2992898602430896
865.6000000000117,37.743099231198634,0.15099467218531748,-1.2993392401340373
867.0000000000117,37.790930467011606,0.15126590470660553,-1.299608775837767
868.4000000000118,37.83820371336841,0.14814614117641417,-1.2996435362201195
869.8000000000118,37.8856210118678,0.14584285967612953,-1.2992807604574628
871.2000000000118,37.9332599985639,0.15594493509058674,-1.2992800920225145
872.6000000000118,37.98099551364034,0.16364591387175784,-1.2992804525751667
874.0000000000118,38.02844403189321,0.15992513775519474,-1.2998796024906238
875.4000000000119,38.07575611280107,0.1448257697765965,-1.3005742818598365
876.8000000000119,38.1233535858421,0.14074214578992603,-1.299486567180311
878.2000000000119,38.17073738552929,0.1401506780066632,-1.3005992345883959
879.600000000012,38.21816860291088,0.14055805661250143,-1.3006034343593127
881.0000000000119,38.2658043517227,0.13614593326189592,-1.29923920722951
882.4000000000119,38.313242712666316,0.13348355163269388,-1.2992899423007742
883.800000000012,38.36057443081373,0.1272208388044189,-1.2992937590559483
885.200000000012,38.40760937075268,0.1275867135270222,-1.3006228697771274
886.600000000012,38.45572475668123,0.12961243430027242,-1.3005540878987927
888.000000000012,38.50330577178936,0.12916458439881578,-1.2993124015273438
889.400000000012,38.550811404609235,0.12957633819438263,-1.3005984509956088
890.8000000000121,38.59812599680668,0.12777057717501203,-1.3005999279600227
892.000000000012,38.63913648482302,0.1309321887916139,-1.3005999299996809