File: 01_Data/EIFS_Coating/STA/N2/30K_min/EIFS_Coating_STA_N2_30KData_230914_R2.csv
##Temp./Â°C,Time/min,DSC/(mW/mg),Mass loss/mg
41.0,10.543527548051298,0.004101652294019598,0.0060222328329926356
42.40000000000002,10.776923629000233,0.041382372477392515,0.005844397025173365
43.80000000000004,10.917899506352718,0.0682454328218296,0.0048680569487897785
45.20000000000006,11.02753177417097,0.0950081680183037,0.005160484545919886
46.60000000000008,11.124908678481487,0.11821645532216207,0.005976167902445262
48.0000000000001,11.209138268369028,0.13805958966095244,0.005421257997701545
49.40000000000012,11.286689656042329,0.15687422084211655,0.0050592012256514
50.80000000000014,11.35959196195117,0.17651246294294332,0.005528872985168576
52.20000000000016,11.427998161537813,0.18972328347813283,0.005378754074588876
53.60000000000018,11.494407547486853,0.205860515890109,0.005401560791355564
55.0000000000002,11.555766236365606,0.22079893820924656,0.004006683510066722
56.40000000000022,11.618468552290265,0.23370809395566106,0.004432464675533154
57.80000000000024,11.676788870654029,0.24766873964304015,0.004512156844382886
59.20000000000026,11.73454699932981,0.2628652863238359,0.003355336886657234
60.60000000000028,11.791032410304359,0.2724122180448527,0.0038426927214150197
62.0000000000003,11.845965370214081,0.2846199834610734,0.0034003953853884994
63.40000000000032,11.899916648591288,0.2967373251848928,0.0035363297770505397
64.80000000000034,11.95249470598658,0.30911024142709387,0.0021784231447918856
66.20000000000036,12.006572516970841,0.31890207506380164,0.0023132137739736436
67.60000000000038,12.058381230393188,0.32931707233045615,0.0015092892772452515
69.0000000000004,12.109890890550554,0.341390101527862,-0.0001359793438280299
70.40000000000042,12.160557813038817,0.3530290288661142,0.0003562540009065529
71.80000000000044,12.211292718075454,0.3612978218844869,-8.037649115566481e-05
73.20000000000046,12.262170329140488,0.36961900989906193,6.930394441262422e-05
74.60000000000048,12.312251193152782,0.38403057807735697,-0.00030882706598456267
76.0000000000005,12.361708566216725,0.393994771799269,0.0003071193021506602
77.40000000000052,12.411757331929293,0.404759108252298,0.00021050042806081137
78.80000000000054,12.46086973433463,0.41878953586117607,-0.001709662470200879
80.20000000000056,12.510036239338607,0.42773290343163006,-0.0015243661584407597
81.60000000000058,12.558616728771458,0.438556279085176,-0.001540278170592213
83.0000000000006,12.60787579571032,0.4488692328116266,-0.0015930975446387663
84.40000000000062,12.656260221218844,0.4599847742827212,-0.0029462422905979224
85.80000000000064,12.70370104569702,0.4684173150826143,-0.0032430365665216954
87.20000000000066,12.751902481665633,0.47790563612924386,-0.004276614220183994
88.60000000000068,12.799966376924402,0.48534132615040926,-0.005058520703292491
90.0000000000007,12.847898484801371,0.4891341228184969,-0.005659264095486893
91.40000000000072,12.89524641630999,0.4923207125720035,-0.006910381951015232
92.80000000000074,12.941760290110214,0.4879329811528065,-0.008307708737262054
94.20000000000076,12.989176097913104,0.4825320823945437,-0.008245930118270017
95.60000000000078,13.03563465289153,0.46927616276928874,-0.00954031338723249
97.0000000000008,13.082063514424501,0.4546961515253978,-0.009452476403194687
98.40000000000082,13.128771099531185,0.43859502431020736,-0.008226588578740923
99.80000000000084,13.1745430432707,0.42615289411103263,-0.009531261819800907
101.20000000000086,13.221531972807172,0.41111952459092826,-0.009550140229014126
102.60000000000088,13.267777386701509,0.40073624393036267,-0.00954760563335455
104.0000000000009,13.314004962577995,0.38994318264469274,-0.010843572185671224
105.40000000000092,13.359454091613348,0.384106293143168,-0.010869568018575748
106.80000000000094,13.405472177491493,0.37611752995741243,-0.012283066774358087
108.20000000000095,13.452700849879488,0.370136512075091,-0.0107751440633157
109.60000000000097,13.49946467145302,0.3649414099660947,-0.010866714087565121
111.000000000001,13.545421883047034,0.3601222636365214,-0.012216929222249817
112.40000000000101,13.591382794025456,0.3562160374339966,-0.012179469401262466
113.80000000000103,13.637578665777877,0.35471368420734756,-0.013596444329257551
115.20000000000105,13.684097296127348,0.3519750217203779,-0.013499964781974683
116.60000000000107,13.730130492591057,0.3514559673640977,-0.0134999925608974
118.0000000000011,13.775804591126636,0.3518530774910831,-0.013502931999433088
119.40000000000111,13.821760183655261,0.3516929945931815,-0.012819109965222175
120.80000000000113,13.86694621194246,0.35130947734990087,-0.011518806593876718
122.20000000000115,13.91404155743813,0.35154404502357645,-0.01152000436099021
123.60000000000117,13.959868166627736,0.34833902433882324,-0.01152257666424683
125.0000000000012,14.00552171189706,0.34980019907311166,-0.012819465368095084
126.40000000000121,14.050697793390436,0.3473996228629861,-0.01283994598802174
127.80000000000123,14.096302185888254,0.34345974312036187,-0.012839931348040512
129.20000000000124,14.141855982349636,0.33972659872921795,-0.012857637064302097
130.60000000000127,14.187145990993484,0.3376292954067303,-0.011528917841760578
132.0000000000013,14.232194163750002,0.3346402211090205,-0.012157895338930746
133.4000000000013,14.277382477972523,0.3336607174694368,-0.012403765993399762
134.80000000000132,14.322285139321796,0.3331361074478135,-0.011531288134896123
136.20000000000135,14.366953080170793,0.33124620140978783,-0.011952730076085771
137.6000000000014,14.412111109539957,0.327043829620449,-0.013474886089831717
139.0000000000014,14.457119814352884,0.32551198519002955,-0.01391576044491849
140.4000000000014,14.501202333989335,0.32368732381252074,-0.014809648489212623
141.80000000000143,14.545973745544314,0.3221664514002531,-0.01469873786326481
143.20000000000147,14.590718750315848,0.32268659328031357,-0.0125081190555969
144.60000000000147,14.634772101496422,0.3192413940231828,-0.012510061892582414
146.00000000000148,14.679299810563169,0.3190652182621623,-0.01251493485318722
147.4000000000015,14.723600547316002,0.3164898709851913,-0.013823646446478488
148.80000000000155,14.767562183165554,0.31553352929581946,-0.015146120303138222
150.20000000000155,14.811556534640534,0.3146533482510553,-0.01513999988464576
151.60000000000156,14.855675485388495,0.31531877911342576,-0.015139997287441087
153.0000000000016,14.899745906811198,0.3123981897075158,-0.015139924626587753
154.40000000000163,14.944037950512923,0.3121686882962799,-0.014646003934766227
155.80000000000163,14.987912612079896,0.31165425540885144,-0.014480194630682508
157.20000000000164,15.032157154737499,0.31221913564459325,-0.01447999941122946
158.60000000000167,15.075704757816048,0.3112432489167521,-0.014479999997229154
160.0000000000017,15.119568788295474,0.30897662933806014,-0.014479999999999826
161.4000000000017,15.163101804435255,0.3082794045300006,-0.01448000000000027
162.80000000000172,15.206857614769168,0.3076866606919674,-0.01448000000000027
164.20000000000175,15.249758846214375,0.3086970083398679,-0.01448000000000027
165.60000000000178,15.293953476721734,0.30795848936838277,-0.014480000000002491
167.0000000000018,15.33789083257193,0.30619788937156023,-0.014480000000261839
168.4000000000018,15.381501676886199,0.3070338469757732,-0.014479999866486182
169.80000000000183,15.424957818900296,0.3033656666218989,-0.014479947157195916
171.20000000000186,15.468358947499642,0.3038786914328914,-0.014474419998612653
172.60000000000187,15.51206518533043,0.30027244637804346,-0.01416260494110988
174.00000000000188,15.555241467988122,0.3023635022276799,-0.015567636173124733
175.4000000000019,15.598450703122579,0.3005489972464963,-0.01547027698652359
176.80000000000194,15.641917108099172,0.2982793029004135,-0.015472634672037966
178.20000000000195,15.685424445919722,0.29765122598514016,-0.014389482018120514
179.60000000000196,15.728048937738453,0.2976130293214935,-0.014199857582748887
181.000000000002,15.771549019584047,0.2966872469587881,-0.01414988207620338
182.40000000000202,15.814620689122183,0.2946598212130785,-0.014151224109659744
183.80000000000203,15.857779536807588,0.2946095798362437,-0.01554360463039961
185.20000000000203,15.900805418937605,0.29510290914028847,-0.015470047660545827
186.60000000000207,15.943724176660158,0.2928790416249617,-0.015471901118447207
188.0000000000021,15.986732169052166,0.29127590867719444,-0.014372772186853844
189.4000000000021,16.029509632482824,0.2908011930142524,-0.014150125702312
190.80000000000211,16.071965925079322,0.2912272971335197,-0.013326117377231217
192.20000000000215,16.11492612851944,0.2898528521132294,-0.012524705771733036
193.60000000000218,16.157895661317433,0.2891161516383069,-0.01381872988604016
195.0000000000022,16.200381167508493,0.2865412554005407,-0.013830007056102822
196.4000000000022,16.24330013674311,0.2889202346457507,-0.013830033796136565
197.80000000000223,16.286045016149526,0.2846248290942226,-0.013841588254552839
199.20000000000226,16.32881694798241,0.28485022711449715,-0.012847551821299596
200.60000000000227,16.371324622982222,0.2841440920844013,-0.012838832301554692
202.00000000000227,16.41366206231759,0.2838724091086091,-0.014156746044415414
203.4000000000023,16.456116580584627,0.28151549026291,-0.014150178751422438
204.80000000000234,16.498968826865333,0.2845294006576424,-0.014168416852174737
206.20000000000235,16.541315997973488,0.28202293477792073,-0.015469772260486625
207.60000000000235,16.584164253295327,0.28194075790866074,-0.014066426243440677
209.0000000000024,16.62688832127349,0.2820692212797328,-0.012660453934225213
210.40000000000242,16.66907268530825,0.2815784438271508,-0.012741807418662265
211.80000000000243,16.71193280492835,0.2789639221101132,-0.014049175660374669
213.20000000000243,16.754537714672647,0.2793978455555921,-0.015450007709351343
214.60000000000247,16.79657292674731,0.2797901988243542,-0.015360339905251319
216.0000000000025,16.83905514922644,0.2810135887664691,-0.015360064794474937
217.4000000000025,16.88185360624239,0.2804713609350115,-0.015865975491800022
218.8000000000025,16.923548682895326,0.27751909171665806,-0.01539235628695046
220.20000000000255,16.966607439281308,0.27778925320000764,-0.015373915442445263
221.60000000000258,17.00896494080453,0.27942533446731627,-0.016369812765419933
223.0000000000026,17.05129712246555,0.27854893222274213,-0.016359876942050544
224.4000000000026,17.093711279623697,0.2757658630708076,-0.01632128402709032
225.80000000000263,17.136375748059052,0.27785071345137907,-0.017659822837564843
227.20000000000266,17.178562314283546,0.275441271093875,-0.017670027875935634
228.60000000000267,17.221174427624806,0.27707899685964577,-0.017658292369231887
230.00000000000267,17.26320573423917,0.2764520879984966,-0.018976913787784433
231.4000000000027,17.30546417248213,0.27401417071143663,-0.018989873634609022
232.80000000000274,17.348221606330814,0.2765881930070853,-0.018980923453195242
234.20000000000275,17.390389647586478,0.27559038431051275,-0.01767534370821977
235.60000000000275,17.432803573692677,0.272862480601076,-0.01767005720321757
237.00000000000279,17.47498860471488,0.27370708279089206,-0.017664843313746292
238.40000000000282,17.5172841393619,0.27208341061011787,-0.018364031987475826
239.80000000000283,17.55969687511324,0.27355134314328877,-0.018330052949618203
241.20000000000283,17.601932792937173,0.2714771329781385,-0.01832936873924096
242.60000000000286,17.64429258733345,0.2719685319025507,-0.016917571550592925
244.0000000000029,17.686468363827377,0.27086571172048735,-0.017010734493466906
245.4000000000029,17.728931627637877,0.2705251251895223,-0.01758307475612364
246.8000000000029,17.771169295568185,0.2684471874206242,-0.018329453262677653
248.20000000000294,17.813287607153075,0.26882732535077225,-0.018329993222546914
249.60000000000298,17.85554476579041,0.26620437562588967,-0.018329469608198146
251.00000000000298,17.8978819468185,0.2677724551215245,-0.018244868882224097
252.400000000003,17.93961986010476,0.26426292296033804,-0.019649938988377524
253.80000000000302,17.982601178580957,0.2679186295246128,-0.019650001445802978
255.20000000000306,18.024890870608786,0.2652701540483252,-0.01965003323959902
256.6000000000031,18.066696208878316,0.2618747397020089,-0.019656453405498375
258.00000000000307,18.109387374581832,0.26350235412298484,-0.01832483904748461
259.4000000000031,18.151703825069344,0.26433769952393027,-0.017011631046559117
260.80000000000314,18.19354286471366,0.26334468424512325,-0.017028131148886683
262.2000000000031,18.236061959718302,0.26235491206014094,-0.018336623835543353
263.60000000000315,18.278419627279085,0.2617783923207512,-0.01833001273308099
265.0000000000032,18.320574356981403,0.2596234614249786,-0.018329975006414756
266.4000000000032,18.362882620078274,0.25779631790222757,-0.01830247961903053
267.80000000000325,18.405084384682695,0.2593338146596039,-0.019627627931015912
269.20000000000323,18.44718777490821,0.2570987053039523,-0.019639961748344703
270.60000000000326,18.489562165624786,0.25814991003537857,-0.019639995483418993
272.0000000000033,18.531869143529516,0.25673924763875877,-0.01962737697611816
273.4000000000033,18.573838731940224,0.2557812734209962,-0.020292965862973578
274.8000000000033,18.61624027543241,0.25711121477629983,-0.020160548777385046
276.20000000000334,18.658626295593727,0.25504220437152764,-0.01899699082570372
277.6000000000034,18.700962498696278,0.25698544908648513,-0.017730069906018553
279.0000000000034,18.74311428202205,0.25573712880732097,-0.018990371947638085
280.4000000000034,18.784711173012866,0.2556741860740154,-0.018990002427531127
281.8000000000034,18.827766811171898,0.25446113518919855,-0.018990087744039652
283.20000000000346,18.870178292589767,0.2546997374539085,-0.01933540825127933
284.60000000000343,18.912391595442287,0.2576182422848763,-0.020308335749849693
286.00000000000347,18.95500108818126,0.2587153190825604,-0.02030991208943167
287.4000000000035,18.996925283009833,0.2545017189212642,-0.018922526964197495
288.80000000000354,19.039444675883693,0.25887928767072466,-0.018330009496986044
290.20000000000357,19.081883844364487,0.25909509417725074,-0.018326788107558833
291.60000000000355,19.12424964361821,0.25978737747381875,-0.019623867794332117
293.0000000000036,19.166713549027413,0.2606043731956624,-0.01964991054720011
294.4000000000036,19.209319032572417,0.2608237367515185,-0.019650003093646173
295.8000000000036,19.251321187517288,0.2635356388788399,-0.019648353958372944
297.2000000000036,19.294237817245904,0.2615983435868326,-0.020877262880651948
298.60000000000366,19.33685108457628,0.2655243455680599,-0.02096989859143461
300.0000000000037,19.37921072270696,0.2632112611133505,-0.020970037571767186
301.40000000000373,19.42133168474358,0.2671980136101756,-0.020948022458104898
302.8000000000037,19.46362575626934,0.26966822348132713,-0.01997619762286229
304.20000000000374,19.50637730595068,0.2699258737546607,-0.020338087879721467
305.6000000000038,19.549144058887247,0.27050225596969457,-0.021290633302963435
307.00000000000375,19.59136067965311,0.27097362529816627,-0.021263298214912574
308.4000000000038,19.633888436688455,0.27409523023916044,-0.02228560923517664
309.8000000000038,19.67616698257658,0.2761965279155476,-0.022156706227280054
311.20000000000385,19.718944664978743,0.27699392484471724,-0.020959031041448473
312.6000000000039,19.761802743601912,0.27706638731664396,-0.020960006307904955
314.00000000000387,19.804083830029196,0.27920760828797647,-0.020959998906762145
315.4000000000039,19.846470125033733,0.2793578692903369,-0.020959713679585157
316.80000000000393,19.88911811606954,0.27969290162199095,-0.02093590221743913
318.2000000000039,19.931927269119203,0.2797991879882343,-0.022283080972441915
319.60000000000394,19.97442641820837,0.28166308736792683,-0.022279898086623895
321.000000000004,20.016993027742803,0.28149588409295057,-0.022252710380713747
322.400000000004,20.05972066096694,0.2846320452350623,-0.022339256717275546
323.80000000000405,20.102203704839212,0.2834713895322888,-0.021630840106560356
325.200000000004,20.14465544778397,0.2838905173861357,-0.021628169976888323
326.60000000000406,20.187687313446663,0.2843031437927301,-0.02027748827806919
328.0000000000041,20.230276441555386,0.2859226257475183,-0.020961448515645742
329.40000000000407,20.27290582375864,0.2870124328028463,-0.02232885421961983
330.8000000000041,20.315336749373238,0.2898030930565997,-0.02227976733983228
332.20000000000414,20.358190236288774,0.29236199983374417,-0.022206961461749497
333.6000000000042,20.401052649131284,0.29164508624090907,-0.023600271137721673
335.0000000000042,20.443645264326687,0.29253484079881736,-0.023601741196357384
336.4000000000042,20.48641540545517,0.29269372981050934,-0.024981862247685616
337.8000000000042,20.529470173149207,0.2931865323185701,-0.023618085208994444
339.20000000000425,20.572342322353435,0.29712839941358843,-0.023599526314362684
340.60000000000423,20.615094232082395,0.29910257942050594,-0.023596445826060464
342.00000000000426,20.65734667284542,0.29619777531679,-0.02480284814681255
343.4000000000043,20.700579996474474,0.298855069992173,-0.0249100835121987
344.80000000000433,20.743794480955806,0.29745986355908627,-0.024920709129361285
346.20000000000437,20.786699748598526,0.2954876755198673,-0.026264063953465477
347.60000000000434,20.829600378119096,0.2960261106309255,-0.02722000666108082
349.0000000000044,20.872398916696888,0.29569472964637855,-0.027220192881973748
350.4000000000044,20.915428810277824,0.29691056384748693,-0.02711113446868829
351.8000000000044,20.958695113242555,0.29324436923721287,-0.027301762609594604
353.2000000000044,21.001540488123958,0.2919141793551908,-0.030097166525821617
354.60000000000446,21.04427786554291,0.28914701085761574,-0.030093453030179074
356.0000000000045,21.08673080486744,0.29199712501792024,-0.030103332859464427
357.4000000000045,21.13068333386598,0.28975059022064553,-0.029603414396349503
358.8000000000045,21.173774071859555,0.28779182556335164,-0.029960492813958517
360.20000000000454,21.216930130681053,0.28507647681735415,-0.03064060743443564
361.60000000000457,21.260189102571257,0.2840511223884416,-0.03127998743385607
363.00000000000455,21.302693714990415,0.2850554827177844,-0.031280086598326484
364.4000000000046,21.346454196921318,0.2828662225874278,-0.03139943249752353
365.8000000000046,21.389570062984205,0.28381696745149554,-0.03260035561690078
367.20000000000465,21.43308353978788,0.2829953183760083,-0.03400719613696168
368.6000000000047,21.476423566270764,0.2809319470573959,-0.03402747932178807
370.00000000000466,21.51940352165006,0.2813436957760727,-0.035234247139596775
371.4000000000047,21.562254022773107,0.28287633742924034,-0.036537246468160145
372.80000000000473,21.605951245398604,0.2845769817822375,-0.03664183988290537
374.2000000000047,21.649560767196288,0.28608822537215806,-0.03756950599923936
375.60000000000474,21.6928033850098,0.28741857505387325,-0.03892470315736363
377.0000000000048,21.735948914455474,0.2900378742426276,-0.04079164655541723
378.4000000000048,21.779362512047335,0.29493082356870715,-0.04260189411570492
379.80000000000484,21.8231493701026,0.29923535923430283,-0.043912459148192085
381.2000000000048,21.866972981020535,0.300024618862984,-0.04519157749789304
382.60000000000485,21.910031256392568,0.3041964510077572,-0.04666185279673485
384.0000000000049,21.953766130927423,0.30859688461131396,-0.04913487572974873
385.40000000000487,21.997363674328117,0.3154927084747205,-0.051160167760100794
386.8000000000049,22.041259400480214,0.3215924207816405,-0.05390904067149549
388.20000000000493,22.084684049504002,0.3322198168904974,-0.0549823132663545
389.60000000000497,22.128343674392376,0.3382967522584259,-0.05783714244622118
391.000000000005,22.17216846723136,0.3470992084907479,-0.06150540981741148
392.400000000005,22.21557811713842,0.35945970094491875,-0.06466122604730451
393.800000000005,22.2595645229421,0.37121948994941506,-0.06815420958630991
395.20000000000505,22.30330667986592,0.38452168950418725,-0.07103949408553856
396.600000000005,22.347107504143096,0.3951292426147821,-0.07537195759300053
398.00000000000506,22.390942120016234,0.41405229396666454,-0.07898278755657717
399.4000000000051,22.434874808224123,0.42478605368519146,-0.08208520264033137
400.8000000000051,22.478834128003065,0.4390210365101952,-0.08792885963478225
402.20000000000516,22.522651318041916,0.4500330891974281,-0.09514791104834552
403.60000000000514,22.56646990705774,0.4650514351020179,-0.10038143904554309
405.0000000000052,22.610769923270517,0.4765063108589961,-0.10590239838338533
406.4000000000052,22.654355801312462,0.48798496797643315,-0.11333108497433964
407.8000000000052,22.698503847465062,0.4978869211516573,-0.11824492806391662
409.2000000000052,22.74231752861284,0.5030573984846387,-0.1252109035446134
410.60000000000525,22.786259287357908,0.5054713279266125,-0.1332740530461658
412.0000000000053,22.829781223455164,0.5090964466587082,-0.1414039236315281
413.4000000000053,22.873239317835928,0.504288547292603,-0.14819805761419547
414.8000000000053,22.917200393753134,0.4949770429100526,-0.15507065319947566
416.20000000000533,22.960903133628285,0.4830774952056559,-0.1628215498600718
417.60000000000537,23.00467439904332,0.46782438172475194,-0.17105134081937923
419.00000000000534,23.04856203889851,0.4507405773680593,-0.1774154853275962
420.4000000000054,23.091918712722958,0.4292622041459276,-0.18389981555347923
421.8000000000054,23.135730828823707,0.40765024499009145,-0.18861647152333738
423.20000000000545,23.179573830663273,0.3808748568978682,-0.19569302205547734
424.6000000000055,23.222861451735763,0.35567872740297196,-0.19994455174876968
426.00000000000546,23.266565789996733,0.327931162755436,-0.20685577848649173
427.4000000000055,23.310249103118018,0.2969818497341949,-0.21310470517116942
428.8000000000055,23.353980428199463,0.26824846313603073,-0.21775507336586353
430.2000000000055,23.397553716645458,0.23918563215503424,-0.22109502645255308
431.60000000000554,23.44157555736468,0.21114541841693452,-0.22472855464220842
433.00000000000557,23.485130702247005,0.18852969689439494,-0.22761743892186104
434.4000000000056,23.529250232908343,0.17115806936753886,-0.22813046593095843
435.80000000000564,23.57310078174149,0.15493092522447677,-0.2283852662589716
437.2000000000056,23.61705767018546,0.14456493538107457,-0.23042279316041459
438.60000000000565,23.66098137551313,0.13102541566956372,-0.23226550033779603
440.0000000000057,23.70487538008372,0.1247324088847113,-0.23252549339680417
441.40000000000566,23.749200502362516,0.11845713630527352,-0.23251955344665376
442.8000000000057,23.79324241625957,0.11372958467788671,-0.23277218051818682
444.20000000000573,23.837346060861893,0.10993001043818487,-0.2325535766074629
445.60000000000576,23.88180210374222,0.1094205376301344,-0.23252224497455343
447.0000000000058,23.926040424154685,0.10628645422089478,-0.23251428703504207
448.4000000000058,23.96984234609149,0.10273121986977363,-0.23384243076202127
449.8000000000058,24.014399867000503,0.10058709783932912,-0.23352146186646117
451.20000000000584,24.058781510374022,0.10184158409543204,-0.23383979554920353
452.6000000000058,24.102847265992693,0.1013984163178003,-0.23444506184273228
454.00000000000585,24.147452195108748,0.10176708253383998,-0.23514994671546807
455.4000000000059,24.191966742796446,0.10197864116334746,-0.2359710367687997
456.8000000000059,24.23614371306557,0.09736477306453403,-0.23646938338723755
458.20000000000596,24.280368721631618,0.09890939177165686,-0.23646464855145988
459.60000000000593,24.32507265900775,0.09658367016610853,-0.23778819430554332
461.00000000000597,24.369678527785933,0.09175890041263204,-0.23778876604922417
462.400000000006,24.41398456603686,0.09220973654932696,-0.2391061343819194
463.800000000006,24.458329224967667,0.09233772285230035,-0.23911002649197677
465.200000000006,24.502390434050444,0.09079486568455969,-0.24041062014493075
466.60000000000605,24.54762588291548,0.09357539715804358,-0.23941205819521016
468.0000000000061,24.592021850435604,0.09408231087501018,-0.2404182606063503
469.4000000000061,24.636880035065165,0.09386425450555769,-0.24147855871620783
470.8000000000061,24.681178720645118,0.09585147356306101,-0.2417382959519334
472.2000000000061,24.72587824265108,0.09353009720262445,-0.2430284414792383
473.60000000000616,24.770351056348634,0.09344759600919966,-0.24305000671600174
475.00000000000614,24.815087455325752,0.09477017864598442,-0.24304950378119416
476.4000000000062,24.859839006679895,0.09778332009825341,-0.24304120373407478
477.8000000000062,24.90446730126949,0.09843985501769958,-0.2443705354358654
479.20000000000624,24.94948911264967,0.10115984254821697,-0.24465914212540207
480.6000000000063,24.99395438845082,0.10347134036490019,-0.24568286824443808
482.00000000000625,25.038409386926983,0.10285818046039574,-0.2470014550114943
483.4000000000063,25.083478361201443,0.10577942616554503,-0.2470402793718316
484.8000000000063,25.12819983814698,0.10407684846736831,-0.24731098489892211
486.2000000000063,25.172834891376237,0.10609210401363806,-0.24865626594347923
487.60000000000633,25.217756886072646,0.10430350822732437,-0.24864408682040295
489.00000000000637,25.26277583012434,0.10738320947205648,-0.24997730475804225
490.4000000000064,25.307715769497154,0.10606354443619748,-0.24996998703430462
491.80000000000643,25.352512790353693,0.10576861941653748,-0.24998295508395074
493.2000000000064,25.39722638478045,0.10183195257799399,-0.25129279575507724
494.60000000000645,25.442276126616854,0.09930635633383361,-0.2512900236386799
496.0000000000065,25.487458511139263,0.09911376132215016,-0.25130136845031226
497.40000000000646,25.53157907842583,0.09662830779635734,-0.25259049895372154
498.8000000000065,25.577324615707607,0.0961902104658306,-0.2526016104499944
500.2000000000065,25.62218495704482,0.09193772528701638,-0.2537459918170235
501.60000000000656,25.667116414089456,0.08967751288171111,-0.25429131026639684
503.0000000000066,25.71247076172064,0.08610778017815057,-0.25490984020441587
504.40000000000657,25.75728587945451,0.08720725291191589,-0.2539250548605221
505.8000000000066,25.80263618623457,0.08151803900537746,-0.25525676078958126
507.20000000000664,25.847417617033216,0.08529998006538109,-0.2552500188525557
508.6000000000066,25.892606274762766,0.08266413253276994,-0.255250000305252
510.00000000000665,25.937590225906593,0.08751335311835207,-0.2552501178093731
511.4000000000067,25.98271762550184,0.09739262023613071,-0.25519937983672225
512.8000000000068,26.02786771434382,0.10263095979038883,-0.25658012699534183
514.2000000000068,26.07273308825537,0.10578735495748703,-0.2578779408671026
515.6000000000067,26.117954330654893,0.11021015488132113,-0.2578766195901925
517.0000000000068,26.162488116796236,0.1095462059147575,-0.2588807306002683
518.4000000000068,26.208590527837725,0.10640363257986929,-0.25885586315370945
519.8000000000068,26.25354986820591,0.1077912290940235,-0.2582553411839865
521.2000000000069,26.297996847435357,0.11112313877605495,-0.2588694461566581
522.6000000000068,26.34380300752231,0.11270525188369696,-0.25879279124659993
524.0000000000068,26.38967136407387,0.11125657516359455,-0.26017991754236114
525.4000000000069,26.43450677154987,0.11047731499971336,-0.26018000380731454
526.8000000000069,26.479839590027776,0.11244145610944245,-0.26018038882036
528.2000000000069,26.525018218431093,0.11176405321447713,-0.25877123806532554
529.600000000007,26.57032497804802,0.11148121531113597,-0.25885990949676163
531.0000000000069,26.61582567879047,0.10997169559446063,-0.25885304966671185
532.4000000000069,26.661299014567085,0.10828579523897386,-0.260185234780419
533.800000000007,26.706518706619452,0.10837803176656435,-0.2592801829704747
535.2000000000071,26.751457412147783,0.1026942516211844,-0.2588645602908959
536.6000000000071,26.79677156831128,0.0989350123174828,-0.25955519961178153
538.000000000007,26.84270495064382,0.10158830638572547,-0.2603727595481615
539.4000000000071,26.887984097084185,0.09329712683689351,-0.261286692984144
540.8000000000071,26.93330261169668,0.08771797095090794,-0.26040110445612186
542.2000000000071,26.978820344254252,0.0798037475884188,-0.26039818575284324
543.6000000000072,27.024102610815763,0.06804880731726692,-0.25931619026869424
545.0000000000072,27.069542678588892,0.06185468222828083,-0.25941991044038204
546.4000000000071,27.114813604297378,0.05051582893469453,-0.25967691310009977
547.8000000000072,27.160464970032145,0.04418409887901675,-0.26072885288038083
549.2000000000072,27.20612648855482,0.03803478710016084,-0.2620012045729361
550.6000000000072,27.251479120720905,0.0334447022151757,-0.26158180127240405
552.0000000000073,27.29680729568638,0.03311916968370343,-0.2607310783900303
553.4000000000073,27.342600489765683,0.03647954559799671,-0.26078612549186353
554.8000000000073,27.38819216918499,0.035086523932881364,-0.26075138137450793
556.2000000000073,27.433832209965857,0.03311010863910102,-0.2622139777735364
557.6000000000073,27.479341056526142,0.028954153988287934,-0.262164953698349
559.0000000000074,27.524960256297025,0.0310813280402219,-0.2634655906493295
560.4000000000074,27.5706634738298,0.02462224243719413,-0.26347979445580183
561.8000000000075,27.616440224063677,0.021392861123725626,-0.2628614342340363
563.2000000000074,27.661941163558005,0.018237250925445925,-0.26216008050779216
564.6000000000074,27.707660308469833,0.014087769979386211,-0.26216138729726923
566.0000000000075,27.753299375105282,0.01109558395092125,-0.26267275968117687
567.4000000000075,27.799120980741197,0.007122521956080763,-0.26358880845661314
568.8000000000075,27.84490137884896,0.011091440232724792,-0.2651114596767963
570.2000000000075,27.89058056174696,0.007849854247917731,-0.26508960462996445
571.6000000000075,27.936511584439284,0.017411545271709405,-0.2636731181558942
573.0000000000075,27.983365844042616,0.10298398432466027,-0.2623457782820453
574.4000000000076,28.02886466436856,0.08802849286944037,-0.26368733175714976
575.8000000000076,28.074198390192507,0.03800794440403976,-0.2636900160197624
577.2000000000077,28.119801448970378,0.00795093976976946,-0.263690004034697
578.6000000000076,28.165458191150563,-0.013280536050893632,-0.2656692644651155
580.0000000000076,28.211246954373202,-0.024713151443126247,-0.26566951294592656
581.4000000000077,28.257266285658993,-0.03168347199186683,-0.2651438114476501
582.8000000000077,28.30301101937332,-0.0369977719329575,-0.26518817244746673
584.2000000000078,28.34884531283991,-0.039054647418324206,-0.26566774000142734
585.6000000000078,28.394911156340456,-0.040821541177102905,-0.26704311647630474
587.0000000000077,28.440836406300875,-0.04856580467894678,-0.2670121352817483
588.4000000000078,28.48656373831905,-0.047316554304152714,-0.26632725479676056
589.8000000000078,28.532970383526653,-0.04875441023497906,-0.2663300073506374
591.2000000000078,28.578628586960455,-0.05005974349781872,-0.26633000000349716
592.6000000000079,28.624472857424625,-0.04959232386174217,-0.2663300000069646
594.0000000000078,28.670635766290598,-0.05091711669614529,-0.26633000224854353
595.4000000000078,28.71689215582374,-0.05158162276391809,-0.26632776568950733
596.8000000000079,28.762883704725304,-0.05247938855908374,-0.2662858209047756
598.2000000000079,28.809054266764697,-0.05306287748250926,-0.26630645163616995
599.600000000008,28.855040441811237,-0.05312757636000276,-0.26764362187850566
601.000000000008,28.901131209834517,-0.05431515576441481,-0.26763999914510794
602.4000000000079,28.947462538656755,-0.05712369753630431,-0.26764163695825527
603.800000000008,28.993477981350154,-0.05875594218411928,-0.2689352759216783
605.200000000008,29.03961879307084,-0.0580824780785314,-0.26895999207726273
606.6000000000081,29.085102160175325,-0.05843601212869176,-0.26895997815007533
608.0000000000081,29.13188927808591,-0.05568472828477744,-0.26896611489753397
609.400000000008,29.17798356517053,-0.054121101554406525,-0.26995635145659547
610.8000000000081,29.22452705523699,-0.057328230237054356,-0.26995053355759735
612.2000000000081,29.27046382900769,-0.0519307644475524,-0.26859728818069595
613.6000000000081,29.31616724746563,-0.05084972879069638,-0.26863971042775425
615.0000000000082,29.363040183307117,-0.05263046701032836,-0.26866200918326477
616.4000000000082,29.40905296179046,-0.048339750307605955,-0.2699325895506379
617.8000000000081,29.455632158775003,-0.051032850225311455,-0.2701830878802638
619.2000000000082,29.501754463325486,-0.04841105475744234,-0.2715660711012693
620.6000000000082,29.548292508921318,-0.05213645917425258,-0.271999271089149
622.0000000000083,29.594478566318145,-0.049825254599155766,-0.2716001331521194
623.4000000000083,29.640563910485522,-0.048520123674833826,-0.2715999967662399
624.8000000000083,29.68677541640157,-0.04756558220168494,-0.27159393320241243
626.2000000000083,29.73339959534751,-0.04858490349909883,-0.2729269328222932
627.6000000000083,29.779540152026776,-0.048593426177089505,-0.2729200029162433
629.0000000000084,29.825914312667617,-0.043846531071447536,-0.27291996994825896
630.4000000000084,29.872480837510494,-0.04236528612292423,-0.2729354620017981
631.8000000000084,29.918486613658143,-0.04116044538141517,-0.2742510872576176
633.2000000000085,29.96500447537808,-0.039190968854889485,-0.2755694869447409
634.6000000000084,30.011386405435868,-0.035198761715674154,-0.27686893236692667
636.0000000000084,30.057707574834886,-0.03192714383946038,-0.2769121226556104
637.4000000000085,30.104208465385923,-0.031134586095666883,-0.2774415974899629
638.8000000000085,30.151012613990158,-0.028037959597074114,-0.2775299176052308
640.2000000000085,30.196705793776964,-0.024596686144667812,-0.2774267298252511
641.6000000000085,30.24388766793456,-0.01918353372318271,-0.27883435299919723
643.0000000000085,30.290172908866612,-0.011126990703113293,-0.278187732016411
644.4000000000086,30.336604508741264,-0.008149832558491221,-0.27818998930556615
645.8000000000086,30.382922076356245,-0.001385637311875687,-0.2781875031520542
647.2000000000086,30.429664686310097,0.0059643190557501224,-0.2795048554853161
648.6000000000087,30.476167309781875,0.014965094942926527,-0.27983873107272794
650.0000000000086,30.522330229713102,0.02289440178685931,-0.2808575646696325
651.4000000000087,30.568920058389736,0.026326911845371948,-0.2810100085338165
652.8000000000087,30.61573700818727,0.038122853441268756,-0.2823767260367802
654.2000000000087,30.6615897361954,0.04472736499008145,-0.28334726775186647
655.6000000000088,30.70896925360507,0.05596914750651738,-0.28359926429375015
657.0000000000088,30.75524284353276,0.06134771796513028,-0.28367880490851727
658.4000000000087,30.801980247476752,0.07175798281010026,-0.28503108096666363
659.8000000000088,30.84830569890761,0.0813378261361215,-0.28491382004676646
661.2000000000088,30.894874644597664,0.09334725524392162,-0.2863099863582983
662.6000000000088,30.941679994657243,0.10026012530225303,-0.2864295233588221
664.0000000000089,30.988038904009425,0.11281658297773656,-0.2876064048695657
665.4000000000088,31.035083609769398,0.12707805939212635,-0.2877164043351783
666.8000000000089,31.081386344162595,0.13951186437860663,-0.2887113759550015
668.2000000000089,31.128027193729423,0.1534966705905172,-0.28889475354487937
669.6000000000089,31.174540050976223,0.17113712975193263,-0.29025785501643897
671.000000000009,31.22144904089849,0.18215136348075145,-0.29158364270629056
672.400000000009,31.268094002798797,0.19731053083452,-0.292126925927795
673.800000000009,31.31457309858991,0.2058155345805608,-0.29300264275647514
675.200000000009,31.36142479449952,0.2282266288476893,-0.29417400172121333
676.600000000009,31.408152269353465,0.24248999907515323,-0.29594925698404717
678.0000000000091,31.454555731089133,0.26402756881659095,-0.2980846303949387
679.4000000000091,31.501753230312918,0.285890220163346,-0.2999041683671253
680.800000000009,31.547885514801305,0.3037434502659382,-0.3003124289932053
682.2000000000091,31.594970859341302,0.3255459868067401,-0.3051333081039691
683.6000000000091,31.641157501562777,0.3455141665736525,-0.3077489818638215
685.0000000000091,31.68844780169939,0.3716431458203351,-0.31015931784125517
686.4000000000092,31.73555359039826,0.39338747525619433,-0.31182688554186866
687.8000000000092,31.78178576401721,0.4187647044577054,-0.3136106148401794
689.2000000000093,31.82887178433779,0.4438337498603777,-0.31531399018827466
690.6000000000092,31.875720720184326,0.47399164917450776,-0.3173829405470583
692.0000000000092,31.922356422527024,0.4996931395919937,-0.31944922413427346
693.4000000000093,31.96937557457074,0.5335838433547435,-0.3240465084953139
694.8000000000093,32.016140085927454,0.5658707063676163,-0.3274403746251693
696.2000000000094,32.06293765885981,0.6001189241432479,-0.33250054749914115
697.6000000000093,32.110032452271774,0.6345225487031305,-0.33360957985902173
699.0000000000093,32.15686842888317,0.6733419453077967,-0.3358954337906477
700.4000000000094,32.20395898608275,0.712900316603833,-0.3365199084363768
701.8000000000094,32.25112279284792,0.7549980987970022,-0.33982308401836914
703.2000000000094,32.29797664630234,0.7940421606727666,-0.34336893877541286
704.6000000000095,32.345132557792915,0.8371552044636297,-0.3475167887909132
706.0000000000094,32.39213966992346,0.8846093061661904,-0.35163616718901247
707.4000000000094,32.4394132326808,0.9329574493838559,-0.35474839123792856
708.8000000000095,32.486668438440574,0.9827415136580404,-0.35894191351134985
710.2000000000095,32.53390597367101,1.035658328814426,-0.36249396136374035
711.6000000000096,32.58077386029771,1.0909462680302187,-0.36411171510840434
713.0000000000095,32.628336358521146,1.145759005207581,-0.3731129618000186
714.4000000000095,32.67563625088028,1.203780504559803,-0.37870375418318325
715.8000000000096,32.72233638872016,1.265878475268924,-0.38436633010614507
717.2000000000096,32.7701986766086,1.3292172697362759,-0.38996414086709574
718.6000000000097,32.817702560724484,1.3919413841696082,-0.39557608418012524
720.0000000000097,32.864758259768465,1.4613656528399308,-0.4016507330202752
721.4000000000096,32.91257998594369,1.5324522826241411,-0.4074593431347959
722.8000000000097,32.960210878764904,1.6016593651334161,-0.41291262222520553
724.2000000000097,33.007623228674184,1.6766256737686,-0.4190159560449369
725.6000000000097,33.055404716988754,1.7549249620211316,-0.4254890072558908
727.0000000000098,33.102894822130246,1.8318289350712105,-0.4316579998055059
728.4000000000098,33.1503050623523,1.9167239656834791,-0.43554898072509474
729.8000000000097,33.19814474938564,1.999731916271958,-0.4470277052939342
731.2000000000098,33.24564421969394,2.0840844278206454,-0.45729408381835013
732.6000000000098,33.29364419720333,2.171348209929221,-0.46537585550731064
734.0000000000099,33.34140821640213,2.2595494025087817,-0.4743853911226603
735.4000000000099,33.3891052220242,2.3546409836121125,-0.4825784778761535
736.8000000000098,33.436836224018116,2.446635817751892,-0.49067771028349805
738.2000000000099,33.48464920108408,2.5405118530435367,-0.4999672602805094
739.6000000000099,33.53271970748285,2.639869731065273,-0.5111052493831325
741.00000000001,33.58020699699113,2.737285666283034,-0.5206402859441863
742.40000000001,33.628225047071076,2.8311673126895904,-0.5304923477090346
743.80000000001,33.67603812593231,2.93370448464609,-0.5413101819994113
745.20000000001,33.72413598697253,3.043338134834608,-0.5529097582253906
746.60000000001,33.77207356713296,3.1480479783781905,-0.564750013858994
748.00000000001,33.819967407343064,3.2545257942266623,-0.5766837067243924
749.4000000000101,33.8679283567565,3.363971773526093,-0.5889557507205723
750.8000000000101,33.91518124403528,3.4779888658600724,-0.6000463892575105
752.20000000001,33.96404204236285,3.588223938761948,-0.6143132921545926
753.6000000000101,34.01217513907407,3.7073185460387594,-0.6288793088937661
755.0000000000101,34.06006789619351,3.8249569379862414,-0.6421357236729794
756.4000000000102,34.108220735647706,3.94584275016829,-0.6565017458638138
757.8000000000102,34.15619854665661,4.065008444164043,-0.6716841799475453
759.2000000000102,34.204455968024725,4.185053870212627,-0.6868207956896342
760.6000000000103,34.252707437194154,4.308884094368425,-0.7041836877478191
762.0000000000102,34.300899771061914,4.435948545218036,-0.719777718903535
763.4000000000103,34.34926950209086,4.565286566693201,-0.7363600387703446
764.8000000000103,34.39697590220815,4.692648268512357,-0.7519875962802343
766.2000000000103,34.44548461449108,4.820373615671501,-0.7727074902604953
767.6000000000104,34.49378467018713,4.947828956330923,-0.7926941687639828
769.0000000000103,34.54171725973628,5.075075587809966,-0.8077013014366603
770.4000000000103,34.589999312698296,5.2022769745315465,-0.8233244030761249
771.8000000000104,34.63819444185727,5.326174087535187,-0.8436532168133968
773.2000000000104,34.68618991685513,5.440606555027392,-0.8646943277517649
774.6000000000104,34.73420749446697,5.559337172182706,-0.8863553160153623
776.0000000000105,34.78219518666032,5.664354953834808,-0.9065290165157736
777.4000000000104,34.830208832170975,5.770621529513251,-0.9268783598538946
778.8000000000105,34.878456194380476,5.8664537611865635,-0.9493166621950189
780.2000000000105,34.926283561175765,5.952457961073106,-0.969407024987603
781.6000000000105,34.97396926635841,6.026288163799023,-0.9934561938319533
783.0000000000106,35.02148285662039,6.084046110936331,-1.0137493394557096
784.4000000000106,35.06914857904875,6.129621249732269,-1.036603963008881
785.8000000000106,35.116199255580206,6.150665927103784,-1.0591021151966795
787.2000000000106,35.163654045029084,6.143718110702467,-1.0819890061159425
788.6000000000106,35.21013546090099,6.099011684552634,-1.1065372226107981
790.0000000000107,35.256811225192706,6.013362062174277,-1.1281153290466546
791.4000000000107,35.30299066360085,5.871803700377564,-1.1489736372284818
792.8000000000106,35.34859303514379,5.667390423384,-1.1697743754533398
794.2000000000107,35.39372794203325,5.39287079463144,-1.1885500331381578
795.6000000000107,35.43795919555505,5.033950659480545,-1.2077340362437603
797.0000000000107,35.481264642430645,4.578607930724246,-1.2250475359332569
798.4000000000108,35.524237981233156,4.005778359222192,-1.2400280077722412
799.8000000000108,35.56586315272365,3.3491037856188797,-1.2535594500411964
801.2000000000108,35.60726033655477,2.6183250201992587,-1.264848789764239
802.6000000000108,35.64898823993505,1.8749672234111263,-1.2745858243011385
804.0000000000108,35.690603277967384,1.1895903330095794,-1.281723792368401
805.4000000000109,35.733238116352894,0.6126070340749088,-1.2864010620114805
806.8000000000109,35.77679598539181,0.16748140613680151,-1.289370789475385
808.200000000011,35.82113441594385,-0.14642372743792054,-1.2910206446993961
809.6000000000109,35.866490215885264,-0.3602086145150385,-1.2942725082769067
811.0000000000109,35.91256577081421,-0.5000695096773464,-1.2957578516194506
812.400000000011,35.95882357660373,-0.57577042856146,-1.296602431921826
813.800000000011,36.004980538373346,-0.6227307501498869,-1.2965397316185814
815.200000000011,36.052593557735946,-0.6470404229639919,-1.2965649748941286
816.600000000011,36.099864780397745,-0.6576124984241809,-1.2952214918124456
818.000000000011,36.14678983312747,-0.6621218908708566,-1.2962753956656945
819.400000000011,36.193850325039335,-0.662839618453892,-1.296209842178551
820.8000000000111,36.24126450618876,-0.661991047107108,-1.2962137484264327
822.2000000000111,36.288636478406865,-0.6617056190083201,-1.2952253766907105
823.6000000000112,36.33570612470282,-0.6534861901145446,-1.2952201611527725
825.0000000000111,36.38324681106352,-0.646447546729418,-1.29587558777932
826.4000000000111,36.43042747843761,-0.6432563749640168,-1.2965301147945105
827.8000000000112,36.47768409463493,-0.6419516518898276,-1.2965300011078575
829.2000000000112,36.52519511703779,-0.6408232919544314,-1.2965300053099078
830.6000000000113,36.5721577360277,-0.6365581214404905,-1.2965282997834708
832.0000000000113,36.61996739496828,-0.6373703470872378,-1.2978490371192182
833.4000000000112,36.667074677088166,-0.6399906636261279,-1.2964766943908996
834.8000000000113,36.71433996672253,-0.6409683385661422,-1.296540128421924
836.2000000000113,36.761758311710906,-0.6408066098558165,-1.2965404306635318
837.6000000000113,36.8092941757,-0.6415809256486678,-1.2971527852177145
839.0000000000114,36.85640530060388,-0.640799036258517,-1.2975344584547739
840.4000000000113,36.90382439642195,-0.6395552876238408,-1.296522804382418
841.8000000000113,36.951201720393826,-0.641081120092426,-1.2965404091054746
843.2000000000114,36.998446059712954,-0.6406148917223691,-1.2978882808785452
844.6000000000114,37.04597143973612,-0.6393291117293791,-1.2978598925041185
846.0000000000115,37.09334214653963,-0.6471717782758817,-1.2978615043873716
847.4000000000115,37.14047542034865,-0.6428452531508926,-1.299163793493053
848.8000000000114,37.18764560643478,-0.6418525166855154,-1.2991540978990548
850.2000000000115,37.23548550630803,-0.6430237622539607,-1.2984920326617706
851.6000000000115,37.2830423221043,-0.647377500706499,-1.2972135139782504
853.0000000000116,37.33054128824595,-0.6532551776473894,-1.2972001715833326
854.4000000000116,37.37801285330114,-0.65820518855663,-1.2986074275707002
855.8000000000116,37.425226033478204,-0.65719861272671,-1.2978283370404964
857.2000000000116,37.472685281915986,-0.6495358628546715,-1.297131448410131
858.6000000000116,37.520382521072854,-0.6500451755124277,-1.2978501007009284
860.0000000000116,37.567900524936604,-0.6506352367103618,-1.2978482976808454
861.4000000000117,37.61535099173613,-0.6533975155967524,-1.2965597985823516
862.8000000000117,37.662755855735426,-0.6504099127048755,-1.2978636810237458
864.2000000000116,37.710268282686435,-0.658940480175378,-1.2978611796148671
865.6000000000117,37.757776905443514,-0.6655480887223924,-1.2991829751079145
867.0000000000117,37.805610523519086,-0.6633229230368807,-1.2992129718858725
868.4000000000118,37.85293842358376,-0.6614347103233982,-1.298850648924625
869.8000000000118,37.90030822836992,-0.6711604784709171,-1.298849999894744
871.2000000000118,37.948013508732025,-0.6846036208848605,-1.2988503019889377
872.6000000000118,37.99553473605524,-0.6930671541559925,-1.2985275301435881
874.0000000000118,38.042962847606574,-0.6912045230087984,-1.298859261351054
875.4000000000119,38.09055090702178,-0.6982776716916956,-1.2994708310111056
876.8000000000119,38.13782553978953,-0.7013812468022147,-1.2988404467634598
878.2000000000119,38.185231460353,-0.7084873370645117,-1.2988399987553034
879.600000000012,38.23280486419779,-0.7113180047776946,-1.2988399978126681
881.0000000000119,38.280369472291355,-0.7094758900005829,-1.29884024160945
882.4000000000119,38.32792986538336,-0.7143589504310381,-1.2985071930525853
883.800000000012,38.37572074638233,-0.7161286666849733,-1.2998177539945859
885.200000000012,38.42290321970443,-0.7184141597227431,-1.2992186707491014
886.600000000012,38.47098719603778,-0.7207392715554422,-1.3001601466542376
888.000000000012,38.51834872911181,-0.7199437848651642,-1.3001599412604445
889.400000000012,38.565825906553286,-0.7259373730922247,-1.300281794240918
890.8000000000121,38.61359745765641,-0.7264975479595766,-1.3011454692182696
892.000000000012,38.65397741519555,-0.7279511846040467,-1.301876889909157