File: 01_Data/EIFS_Coating/STA/N2/30K_min/EIFS_Coating_STA_N2_30KData_230914_R1.csv
##Temp./Â°C,Time/min,DSC/(mW/mg),Mass loss/mg
41.0,10.546326641144722,0.03078628251807647,0.03578303396617111
42.30000000000002,10.767966366540723,0.09632928583952527,0.0326869929031548
43.60000000000004,10.905440255364544,0.14614945161543957,0.032830910490308174
44.900000000000055,11.01276127471482,0.1883896710074524,0.03264271859485346
46.200000000000074,11.104900627193908,0.225011770624431,0.03298069981551288
47.50000000000009,11.186072288608734,0.25783558391836614,0.03270464771835391
48.80000000000011,11.260895393785614,0.28789206949609825,0.03370426985057273
50.10000000000013,11.330155533312377,0.31451635827843494,0.03128761722089246
51.40000000000015,11.395326695083863,0.3384961096532264,0.03251947246601761
52.700000000000166,11.458415916696811,0.3632331572345462,0.032221004377516405
54.000000000000185,11.518212095322495,0.3843293501615359,0.03235368640519409
55.3000000000002,11.576451119708826,0.4053384336726751,0.031031585354015068
56.60000000000022,11.632886693676994,0.42225690848521524,0.03131677450219916
57.90000000000024,11.687370203594583,0.4416307846503087,0.03025513416418457
59.20000000000026,11.740527946649093,0.46270545186740963,0.03028534368716551
60.50000000000028,11.7927688334305,0.47729254878557326,0.03279712886676611
61.800000000000296,11.84504969610094,0.49536087156545894,0.03248427099314677
63.100000000000314,11.895276828553442,0.5106658291475867,0.032932900484933025
64.40000000000033,11.944869463036174,0.5239954383229122,0.030944678411779503
65.70000000000036,11.99425583093685,0.5407643242255791,0.031364727518842894
67.00000000000037,12.04294389849818,0.5584272880559136,0.031570585500284576
68.30000000000038,12.091340802353082,0.5693356662432723,0.02984472742693489
69.6000000000004,12.138811059171386,0.5860615542682419,0.03083320034574699
70.90000000000043,12.186186797963439,0.6018487437854949,0.030177909609772957
72.20000000000044,12.233158619369384,0.6181230339338615,0.02957532668867513
73.50000000000045,12.280281378560561,0.6326243978182655,0.028175822406681927
74.80000000000048,12.327165412392816,0.6455506349021722,0.027792828484240584
76.1000000000005,12.37340226608047,0.6626389671376132,0.027916998446434693
77.40000000000052,12.419686788577888,0.6775039925115813,0.027333419680493964
78.70000000000053,12.465580213343035,0.6927327964576389,0.0263212173595897
80.00000000000055,12.511070838372786,0.7056484566983808,0.028509974779782343
81.30000000000058,12.55659407452453,0.7214448855530542,0.02736919566371876
82.60000000000059,12.602245848824841,0.7347809460258233,0.025934101315116198
83.9000000000006,12.647164766048816,0.749572516821572,0.026037484784795506
85.20000000000063,12.692044532639896,0.7598494614022734,0.02639889449173749
86.50000000000065,12.737377204984949,0.7767183920064367,0.026024871115205794
87.80000000000067,12.781659464727896,0.7858359730905182,0.02470318074464517
89.10000000000068,12.8266170032097,0.795593636912662,0.023299444157903526
90.4000000000007,12.870751293411146,0.8033926897753987,0.023744559598953163
91.70000000000073,12.914835857502114,0.8064773189587848,0.022698151738074213
93.00000000000074,12.958595065723816,0.8101403525382411,0.022061515490822803
94.30000000000075,13.002578558725448,0.8067575974816017,0.022014198710794464
95.60000000000078,13.04623691837474,0.7988748927394765,0.020744735756840438
96.9000000000008,13.089658556832266,0.7878943475106165,0.019915104712083576
98.20000000000081,13.132846630812603,0.7746095095136974,0.01941996553588332
99.50000000000082,13.176163270969854,0.7666433758692672,0.01810217833743577
100.80000000000085,13.218977196694217,0.7574132014785145,0.018109448548514262
102.10000000000088,13.262279725319896,0.7477667548410672,0.019121208594433448
103.40000000000089,13.305302440063505,0.7419298245615663,0.018106436253838343
104.7000000000009,13.347766452511962,0.7391808946550877,0.01810893506171496
106.00000000000092,13.392220996271789,0.7342278200099932,0.01698922384666668
107.30000000000095,13.434797216568573,0.7301961615377494,0.017255998326545008
108.60000000000096,13.478236893060911,0.7290086019627378,0.017844254945817983
109.90000000000097,13.521262390817455,0.7276282372936077,0.01646949688913768
111.200000000001,13.564337267305357,0.7249574598577226,0.01647150526864216
112.50000000000102,13.607322822705143,0.7257369565180135,0.015859973511065828
113.80000000000103,13.650747380166388,0.7269377985553116,0.015450265551102849
115.10000000000105,13.69289560407695,0.729020275153382,0.015150840081766592
116.40000000000107,13.736488930672474,0.7310424828195539,0.015377042544626018
117.7000000000011,13.779037905423738,0.7344774260353266,0.014189961655735939
119.00000000000111,13.821709319255346,0.7369550684694666,0.015468587985723037
120.30000000000112,13.86483291739392,0.7411437813033265,0.015465978999895658
121.60000000000115,13.907696609398753,0.7446027943311615,0.014453849820545983
122.90000000000117,13.94930992814789,0.7416025218669291,0.01448969567257885
124.20000000000118,13.992698242823622,0.7451462365463462,0.01554193441168561
125.5000000000012,14.034683327002474,0.7444526425705433,0.015480224511749352
126.80000000000122,14.07737333310484,0.7444500209804344,0.015489499738157608
128.10000000000124,14.119508583464869,0.7434280572240146,0.016096339069488597
129.40000000000126,14.161889635328855,0.743958133624136,0.017238020919417618
130.70000000000127,14.20382014469125,0.7439542930648069,0.0157741045277362
132.0000000000013,14.246116740210645,0.7450295891375591,0.014390443267509045
133.30000000000132,14.287432644944062,0.7441418710651504,0.014410268288909123
134.60000000000133,14.329774156991041,0.7471732591570885,0.014037630911970744
135.90000000000134,14.371338051752025,0.7471140094212587,0.01306264075882968
137.20000000000135,14.413235672510897,0.7468590942322236,0.012713082682228372
138.5000000000014,14.454856190919754,0.750788799466967,0.01405533529992864
139.8000000000014,14.496575184785131,0.7522616665265972,0.014050068316719955
141.10000000000142,14.537929683623132,0.753708820432049,0.014060406088885813
142.40000000000146,14.579194609073458,0.7575140537507115,0.013060955296045229
143.70000000000147,14.619871920478918,0.7596853847045713,0.013059454750384614
145.00000000000148,14.661090539217412,0.7593303961722051,0.014384447269621958
146.3000000000015,14.703123604442006,0.7626231550299609,0.014380220843350333
147.6000000000015,14.74409460570702,0.7634644528960941,0.014392278451501817
148.90000000000154,14.785548802810991,0.765222450752703,0.015745846912244232
150.20000000000155,14.8262159037107,0.7675844183393372,0.01569939112840446
151.50000000000156,14.867240987892536,0.7684357526820478,0.015431254390897653
152.8000000000016,14.90844502732763,0.7722245722285972,0.015373293203640337
154.10000000000161,14.9488224375397,0.7770135736063587,0.014694843487786713
155.40000000000163,14.98966188165366,0.7785463472070477,0.014709999747958502
156.70000000000164,15.030962534143832,0.7804004776102655,0.014710020587452188
158.00000000000165,15.071802010083383,0.7829255444408227,0.014710146756429676
159.3000000000017,15.112484023154078,0.7856077247302905,0.014743368240242472
160.6000000000017,15.153048411182668,0.7903622672717132,0.013600134685199272
161.9000000000017,15.193742575375635,0.7921829917692976,0.013058152569013881
163.20000000000175,15.234727134292639,0.792929429702337,0.01312049263916748
164.50000000000176,15.275009495135212,0.7929471876376524,0.014385860922992766
165.80000000000177,15.315618343475776,0.7966723498520967,0.014379934166866004
167.10000000000178,15.355950949338169,0.7988460556483804,0.014379857722447653
168.4000000000018,15.39681828416124,0.79939349426698,0.014370811396021477
169.70000000000184,15.43730826075655,0.802931016861614,0.014055640909307332
171.00000000000185,15.477660621434257,0.8040528984801967,0.014049927142266938
172.30000000000186,15.517859219242169,0.8077885815911341,0.01404887475418981
173.6000000000019,15.558355506303968,0.8065960211287191,0.01353376806037243
174.9000000000019,15.598302055081087,0.8117180249781815,0.012744183691412392
176.20000000000192,15.638981409960634,0.8128098713165653,0.01240376510315544
177.50000000000193,15.679288943246638,0.8139118819163205,0.012409997480022028
178.80000000000194,15.7194178483365,0.8168841984515032,0.012410027803000823
180.10000000000198,15.759661968484656,0.8173314596685891,0.01241094261804454
181.400000000002,15.799806107913419,0.8187388084327022,0.011748084078223364
182.700000000002,15.839755624008692,0.8192587733070665,0.011750121818594028
184.00000000000205,15.879491199478828,0.8225930166308748,0.011750175040574629
185.30000000000206,15.919938504489123,0.8228090245372055,0.011751086319743642
186.60000000000207,15.959722286952253,0.8248689503334148,0.013071242755865242
187.90000000000208,15.999466466524515,0.8277647970311987,0.012735869551279588
189.2000000000021,16.039281301455958,0.8288372684659554,0.011422833609766592
190.50000000000213,16.078968719024232,0.8316296007178786,0.011420156404751136
191.80000000000214,16.118393874739898,0.8336698577166471,0.011420149665935853
193.10000000000215,16.158486458006788,0.835631843183176,0.011422706380880499
194.4000000000022,16.198234125102708,0.835990061939672,0.010167750916556972
195.7000000000022,16.237435572599825,0.8365039310659697,0.010100463875755583
197.00000000000222,16.277473013977755,0.8393346196028999,0.01009997260164086
198.30000000000223,16.317352573971732,0.8408908630528829,0.010099970013328186
199.60000000000224,16.356965133417464,0.8447966768776066,0.010099970000099656
200.90000000000228,16.39654803145011,0.8446612837567539,0.010099970003346836
202.2000000000023,16.436026054808448,0.8467886536540127,0.010099970683886017
203.5000000000023,16.475539206323234,0.8489901531162677,0.010100099647952998
204.80000000000234,16.515005567963982,0.85022708778018,0.010123532040747119
206.10000000000235,16.5544968895616,0.8552895726205981,0.011426891303164322
207.40000000000236,16.593608992403862,0.8563318063888247,0.011420171502995569
208.70000000000238,16.63371780937416,0.8585963203910161,0.011420136213778687
210.0000000000024,16.672840581273856,0.8588912103102737,0.011420140123897582
211.30000000000243,16.712165173250742,0.8591432539266795,0.011420721814283663
212.60000000000244,16.75186777361929,0.860938441242892,0.011506672983637056
213.90000000000245,16.79145102537315,0.8617398442149323,0.012729088139844524
215.2000000000025,16.830825553561183,0.8658593420007195,0.010110643820399723
216.5000000000025,16.870060282869204,0.8661082140545514,0.010099982028215493
217.8000000000025,16.90948226867878,0.8693309516046389,0.010099969920154273
219.10000000000252,16.94906268583593,0.870528435481502,0.010099969998881964
220.40000000000254,16.98825997735982,0.8736734185872059,0.010099969993445423
221.70000000000258,17.027706896966972,0.8744418999130891,0.010099968561386508
223.0000000000026,17.067414896814554,0.876233816144441,0.010099683680024008
224.3000000000026,17.106393166837957,0.8767865164414841,0.010047147476764273
225.60000000000264,17.14598535494706,0.8786145329747139,0.011398179271902453
226.90000000000265,17.185348967207798,0.8795249554271286,0.011409892076349681
228.20000000000266,17.22444335201591,0.87909501521455,0.010524583113154407
229.50000000000267,17.263808751400127,0.8799765977303391,0.009439454907080869
230.80000000000268,17.303446333543803,0.8828222488096449,0.00802690387503091
232.10000000000272,17.342357764728845,0.8835467821761136,0.008129088206114687
233.40000000000273,17.381364827287626,0.8834143664229526,0.008089924949262084
234.70000000000275,17.421317593256298,0.8854871084735902,0.007470256452768886
236.00000000000279,17.46057938941033,0.8862571378829189,0.007479850895925733
237.3000000000028,17.499796034397882,0.8854051113232921,0.008129636377799176
238.6000000000028,17.53899518436421,0.8886129130249167,0.008129863008522697
239.90000000000282,17.57828934706507,0.8877413942690492,0.008129682216014178
241.20000000000283,17.617717583447618,0.887330234985683,0.0080909321136855
242.50000000000287,17.656661556325034,0.8908081143090403,0.008826834435037068
243.80000000000288,17.696437539078936,0.8909653500432946,0.009101459272783163
245.1000000000029,17.735219448761708,0.891565240824834,0.009109693081548187
246.40000000000293,17.77495195417296,0.8925249392990585,0.009048068009692933
247.70000000000294,17.813230424117982,0.8952499187332789,0.007783795907621016
249.00000000000296,17.853287725799735,0.8937984178243814,0.009450851195833998
250.30000000000297,17.89212773030469,0.8951946922233345,0.009439880902803566
251.60000000000298,17.931740073519745,0.8956431241009276,0.009432959394790164
252.90000000000302,17.970545383620266,0.8974348658992096,0.008007813123708463
254.20000000000303,18.00940248672688,0.8969716698782813,0.008010419870062346
255.50000000000304,18.049206337276743,0.9000180600176294,0.00735990472910375
256.8000000000031,18.08855328204323,0.901165452644282,0.007022988114466333
258.1000000000031,18.127841179322363,0.901133102092796,0.007048892311282806
259.4000000000031,18.16671615262201,0.9033852019708912,0.006688386884754038
260.7000000000031,18.206437283360163,0.9076279366519255,0.006690170219180835
262.0000000000031,18.245464971794735,0.9060363381055084,0.006706573292214468
263.30000000000314,18.284750337842862,0.906583677577953,0.007313897729249952
264.6000000000032,18.323965168431915,0.9095835642218024,0.007682335655952777
265.90000000000316,18.36310011907058,0.911941004420263,0.007679513980241914
267.20000000000323,18.40250889226911,0.9149446792888012,0.007575964714357841
268.50000000000324,18.441714537424993,0.9131585121208018,0.00504377281624846
269.80000000000325,18.480542200517938,0.9159889542898074,0.00503988461473126
271.10000000000326,18.520240645332887,0.9180746857625628,0.005039921762531208
272.4000000000033,18.55912641250804,0.918272611488922,0.005039921996092822
273.70000000000334,18.59844721677037,0.9207517020380072,0.005039921999970609
275.0000000000033,18.6376035744574,0.9177363584145506,0.005039921999999919
276.30000000000337,18.67691860097162,0.9212797467308601,0.005039921999999031
277.6000000000034,18.715840512815678,0.9237766491839926,0.005039921999999475
278.9000000000034,18.754772575042058,0.9245161843620295,0.005039922000000363
280.2000000000034,18.794485125968052,0.9268382108955775,0.005039921999998587
281.5000000000034,18.83408104783628,0.9276210440655742,0.005039921999809405
282.8000000000034,18.87308954648599,0.9299119822184503,0.005039921972139982
284.10000000000343,18.912187179142656,0.9314708230979777,0.005039918224277518
285.4000000000035,18.951801542381705,0.9352312588377976,0.005039285282554484
286.70000000000346,18.990970056241107,0.9359826160883475,0.004976657512655525
288.0000000000035,19.030427478726704,0.9362059091796472,0.003730181650783315
289.30000000000354,19.069729444291823,0.9372434872868813,0.004714541773559677
290.60000000000355,19.10837795082563,0.938034092040397,0.004720149541394658
291.90000000000356,19.148411235617342,0.9396995768949992,0.0047391898948054845
293.20000000000357,19.18725598439682,0.9401610780954145,0.0040677498807606405
294.50000000000364,19.226885043838113,0.9417425797253101,0.0033574535630354063
295.8000000000036,19.266273898877945,0.9451514403872674,0.003399676859405343
297.10000000000366,19.305569426960115,0.9478485047510319,0.0033996125699276014
298.4000000000037,19.34434143201598,0.9481878786264435,0.003318968526487165
299.7000000000037,19.38388597118127,0.9513493961150964,0.0024058121984853464
301.0000000000037,19.423855731132356,0.9532144836006966,0.002410089615306088
302.3000000000037,19.463139974647063,0.9553023365130858,0.0024101118888206763
303.6000000000037,19.502468515075453,0.9564721989621211,0.002410111999436193
304.90000000000373,19.542075755328096,0.9593181053137533,0.0024101119929009762
306.2000000000038,19.581312227287846,0.9613810775319827,0.0024101110746852505
307.5000000000038,19.62074581473942,0.9637658652968508,0.0024100234631201367
308.8000000000038,19.660214001630973,0.9645838127279407,0.002405654107203059
310.10000000000383,19.69946043199117,0.968829931479043,0.002075942865888525
311.40000000000384,19.738846450156966,0.9714765081047195,0.0007533701192650177
312.70000000000385,19.778473954356866,0.9731260197754463,-0.0005407167930449042
314.00000000000387,19.81783378650661,0.9700169842271802,-0.0005497567170826834
315.3000000000039,19.85750490647888,0.975001880730101,-0.0005497032902783694
316.6000000000039,19.896875099235746,0.9773616756613639,-0.00041826459569493935
317.90000000000396,19.93622149805788,0.9774615788933525,0.0007631271070507317
319.20000000000397,19.975768306447478,0.978311619773958,0.00021504571205754885
320.500000000004,20.01530824107289,0.9806853398882054,-0.0005501398667209223
321.800000000004,20.054700966912925,0.9832974310205824,-0.000549815165790779
323.100000000004,20.09413510905573,0.9850801645424488,-0.0005497131908671626
324.400000000004,20.133412014394963,0.9875327000255777,-0.0005303469443460607
325.700000000004,20.172881920503904,0.9918222423406512,-0.0012032807862625283
327.0000000000041,20.212680141104933,0.9935169383872452,-0.0012135692569548162
328.3000000000041,20.252531037943594,0.9951795952928051,-0.0018948201389310526
329.6000000000041,20.292208941034147,0.9961754633727293,-0.002411767922005037
330.9000000000041,20.331620442983727,0.9988312671183629,-0.0031888228530552176
332.20000000000414,20.37115364391707,1.0023474173105933,-0.0031901376487186717
333.50000000000415,20.410754413340754,1.0039968064929063,-0.0031896329882372676
334.80000000000416,20.450709134791158,1.0082377182047255,-0.003090861538730394
336.1000000000042,20.490211399278454,1.0114177346551574,-0.00286089186028482
337.4000000000042,20.530157545658145,1.0148916201087081,-0.0028623737348971723
338.70000000000425,20.56959048214572,1.0156264330388947,-0.004151838384461648
340.00000000000426,20.60938654924727,1.0187790497850415,-0.004169842217546904
341.3000000000043,20.648849949404422,1.0188312321573434,-0.004410092929659548
342.6000000000043,20.688826370731142,1.0221582251321029,-0.005491677758547642
343.9000000000043,20.728531627948755,1.0227051425212288,-0.0054901403376859115
345.2000000000043,20.768301561082858,1.0250723572661238,-0.005490128428547347
346.5000000000043,20.808052591211663,1.0268764807766104,-0.005489777190168521
347.8000000000044,20.847862822806288,1.027864003193534,-0.006648963981045863
349.1000000000044,20.88798034753084,1.0294140904765894,-0.006808779461243031
350.4000000000044,20.927702020169907,1.0309755221755266,-0.0067278375420687375
351.7000000000044,20.967612972724773,1.0285636964166696,-0.008129065178655193
353.00000000000443,21.00725745624882,1.0261600340219383,-0.00815434421805561
354.30000000000445,21.047456219505193,1.0281700718540705,-0.009443052878360891
355.60000000000446,21.086982834197197,1.0262423953080746,-0.00934676804022283
356.90000000000447,21.12703431330483,1.0260218850757576,-0.01075865326650538
358.2000000000045,21.16687995754126,1.0259540109589897,-0.010774071956638487
359.50000000000455,21.206502564121877,1.021765998804271,-0.012113939540370211
360.80000000000456,21.246604108368043,1.022988671411341,-0.01208095221838068
362.10000000000457,21.286834887689203,1.023679132282552,-0.012479379122246392
363.4000000000046,21.32631376145635,1.0217796679874882,-0.01340215070323758
364.7000000000046,21.366781410971523,1.020173602164645,-0.013780404721112749
366.0000000000046,21.406752140843142,1.0167001432839147,-0.015047462930467326
367.3000000000046,21.44658465765141,1.0188638976858586,-0.01569485986403585
368.6000000000047,21.486865140802323,1.0198530947006774,-0.016360506016091403
369.9000000000047,21.526674530372528,1.0220039367507545,-0.016359926916003076
371.2000000000047,21.56653105098443,1.0231857059718235,-0.016350986750486296
372.5000000000047,21.60695901461333,1.0199684835120515,-0.017963737813326386
373.80000000000473,21.647424724578716,1.0249909102506651,-0.019567366914177153
375.10000000000474,21.68781991424423,1.0264922076591598,-0.02164072763277991
376.40000000000475,21.727984736645737,1.025055946138911,-0.022180904591185158
377.70000000000476,21.76820527031471,1.0288271643223141,-0.022689936442596537
379.0000000000048,21.808186849761743,1.033927911232049,-0.02350135175887802
380.30000000000484,21.848630319468022,1.0347047175525013,-0.02371483134717911
381.60000000000485,21.88892381194428,1.038293731754253,-0.02559152833716416
382.90000000000487,21.929159541415217,1.0417259770545158,-0.027481229149455277
384.2000000000049,21.969697713565306,1.0446118180991215,-0.029301387010040703
385.5000000000049,22.010000000000154,1.0531393137224527,-0.030740286168132513
386.8000000000049,22.050300969095773,1.0576378950478968,-0.032325125965737556
388.1000000000049,22.090473710298635,1.064287425412342,-0.03371742322362703
389.400000000005,22.13113708272724,1.0728017973430504,-0.03695496508892271
390.700000000005,22.17164117084537,1.0793158408380008,-0.040688693342613824
392.000000000005,22.21224205675259,1.0903616009827708,-0.043374503478801785
393.300000000005,22.252620255809983,1.1004386073384154,-0.04640963882578486
394.600000000005,22.293480967043436,1.1106024373400318,-0.049518661580420176
395.90000000000504,22.333915989502433,1.1235279553406203,-0.05215747220588396
397.20000000000505,22.37423111616794,1.1360681717184038,-0.055879021737388346
398.50000000000506,22.414933408142495,1.1477100785222185,-0.06054023106253936
399.80000000000507,22.455649753818165,1.16078187109335,-0.06549579239311987
401.10000000000514,22.496471213402298,1.1722415722945707,-0.07087537310849923
402.40000000000515,22.536874847270937,1.1869452829516067,-0.07379951335958346
403.70000000000516,22.577518608850855,1.2007872050673039,-0.0784578930231743
405.0000000000052,22.617990998045602,1.2112640989235737,-0.08314906312231818
406.3000000000052,22.65863676970121,1.222567493829805,-0.08918388048285975
407.6000000000052,22.69948420057069,1.2311431569994158,-0.09563399218826607
408.9000000000052,22.74009366479771,1.2380171310264776,-0.10144830646043479
410.2000000000053,22.780589194149833,1.2428231869674469,-0.10881795372581982
411.5000000000053,22.821249381651793,1.2440902633662416,-0.11632608010058387
412.8000000000053,22.86177408933836,1.2430114686282074,-0.12351854872201473
414.1000000000053,22.90250071544045,1.2408807519854572,-0.12941963991706018
415.4000000000053,22.942907887834814,1.2325404227206356,-0.13558397713648507
416.70000000000533,22.983250176804443,1.22274926856109,-0.14341015194152762
418.00000000000534,23.02396773927335,1.2072352253534144,-0.15007238808004209
419.30000000000535,23.06439077706,1.1929572089680507,-0.15532816451600207
420.60000000000537,23.104657509143312,1.1765865930625061,-0.1618380152152601
421.90000000000543,23.144925352895676,1.158785700711701,-0.16722340266103775
423.20000000000545,23.185520160819806,1.1371751629822424,-0.17474096170394748
424.50000000000546,23.226110994735407,1.1130423526834026,-0.1805380693991645
425.80000000000547,23.266610309116242,1.0919753667957859,-0.18578752902433138
427.1000000000055,23.307197493458123,1.0672848908767276,-0.1898533441381005
428.4000000000055,23.347505289175384,1.0404840424469974,-0.1936595349190413
429.7000000000055,23.38799532954028,1.0177468110436565,-0.19751754059568016
431.00000000000557,23.428406914517847,0.9968695802624912,-0.20096557213056787
432.3000000000056,23.469116684032848,0.9746263668864277,-0.20199440217842923
433.6000000000056,23.50978085157097,0.9531555611743986,-0.20506265407012236
434.9000000000056,23.55028684602911,0.9404230538888013,-0.20660492564245247
436.2000000000056,23.591216725199676,0.9279756699936973,-0.20802608764993868
437.5000000000056,23.63212839714841,0.919366750085408,-0.20948224310469632
438.80000000000564,23.672853646144855,0.9095130131653963,-0.2108450891604945
440.10000000000565,23.713807193696514,0.9057661516812372,-0.21239764154249885
441.40000000000566,23.75458298117903,0.8993822044046837,-0.21373539437822808
442.70000000000573,23.795406692389644,0.8923571020974748,-0.21353861260497853
444.00000000000574,23.83650612227316,0.8890324573191939,-0.21495823993083407
445.30000000000575,23.877366909505092,0.8879235329116248,-0.21486536665232547
446.60000000000576,23.91843683817565,0.8848630884614395,-0.21627944803085342
447.9000000000058,23.959587362239166,0.8841577268029053,-0.21628043071025083
449.2000000000058,24.000448256582047,0.880901758601538,-0.21758365043757388
450.5000000000058,24.04144372114549,0.8809078155494059,-0.21891405561548183
451.80000000000587,24.08178451888474,0.8822460703554204,-0.21989800327862952
453.1000000000059,24.123736308896888,0.8800416448879993,-0.2202262377734132
454.4000000000059,24.164925250037417,0.8822749861181561,-0.22147874489139685
455.7000000000059,24.205679640659923,0.8847059005243846,-0.2215500310936216
457.0000000000059,24.247101925994116,0.8858557587260383,-0.22154680885521838
458.3000000000059,24.28823418776424,0.8860823893392529,-0.22280134686232733
459.60000000000593,24.329712898496947,0.8864703124001714,-0.22192530210344064
460.90000000000595,24.37086444902328,0.8903258880135865,-0.22285807878255737
462.20000000000596,24.411621739305783,0.8887721127649855,-0.2239697999201402
463.500000000006,24.45330862001857,0.8928706300385231,-0.2252281313567499
464.80000000000604,24.494469797709534,0.8930419230896238,-0.22581396555287814
466.10000000000605,24.53579244301444,0.8946115691898445,-0.2261522534680287
467.40000000000606,24.577453255403682,0.895691472161015,-0.22631372836301988
468.70000000000607,24.618354489622625,0.8969563315016593,-0.22747221315906785
470.0000000000061,24.659775402149954,0.897770069916218,-0.2274700043722846
471.3000000000061,24.70091885146244,0.9005448409990329,-0.227443705031793
472.60000000000616,24.742531839856245,0.9038098962270702,-0.22754974082461876
473.9000000000062,24.783709016137443,0.9085552338199864,-0.22750835467062824
475.2000000000062,24.825272728519177,0.9095283047521198,-0.22889822704433138
476.5000000000062,24.866702284741887,0.9110944955561749,-0.2299439237028631
477.8000000000062,24.90779898389632,0.9096420541091043,-0.23021875778295886
479.1000000000062,24.949269447395608,0.9133618854939374,-0.23018273634430342
480.40000000000623,24.9908674096339,0.9139594305738663,-0.23154010625906452
481.70000000000624,25.032365735048373,0.9157113020067364,-0.2315517558810014
483.00000000000625,25.07390358704494,0.9184901806734911,-0.23285370030507524
484.3000000000063,25.115112039279186,0.9199605470715402,-0.2339117877763015
485.60000000000633,25.156647740601095,0.9209441104831155,-0.23407271914191075
486.90000000000634,25.19825379921427,0.9188302595877673,-0.23551100642597422
488.20000000000636,25.239904864584954,0.9215843951667496,-0.2368102717143281
489.50000000000637,25.281239590342388,0.9226726354141348,-0.2368093364273225
490.8000000000064,25.32273232286696,0.9229026684730728,-0.2376913796225164
492.1000000000064,25.36442960632048,0.9270553360349774,-0.238118976679619
493.40000000000646,25.405668503790306,0.9228461389110209,-0.2381199545110535
494.70000000000647,25.447407911387245,0.9214830417050781,-0.23811394836106103
496.0000000000065,25.489135094945457,0.9191471057241787,-0.23943556413071487
497.3000000000065,25.5302935120164,0.9206560857137998,-0.23945920607683124
498.6000000000065,25.572127651074137,0.9184427733443981,-0.24071809210607276
499.9000000000065,25.613617884507676,0.9185121891141097,-0.24207895175261207
501.2000000000065,25.6554741564425,0.9163622823952624,-0.24392724784669406
502.50000000000654,25.696979945642767,0.9158740315754591,-0.24471254371642015
503.80000000000655,25.738600258660128,0.9141063665217513,-0.2433881740386048
505.1000000000066,25.78047947460035,0.9104265531851526,-0.2434069317880998
506.4000000000066,25.822117683786058,0.9111969723392422,-0.24341521196116744
507.70000000000664,25.864050879159343,0.9110987018409672,-0.2447128463281283
509.00000000000665,25.905048601868234,0.9078178627387018,-0.24471008197976873
510.30000000000666,25.94759970155695,0.9062529561537171,-0.24471007795822874
511.6000000000067,25.98837500035867,0.9056494503029542,-0.2447100779998217
512.9000000000067,26.03097595410006,0.9136704544213934,-0.24471007798094435
514.2000000000068,26.072525277341903,0.9236215426761643,-0.24471006774138093
515.5000000000068,26.114359580959217,0.9281731628504103,-0.24470663287969785
516.8000000000068,26.156148904940196,0.9337696025875406,-0.2458471964591138
518.1000000000067,26.197764507425852,0.938740412654552,-0.2460295599578659
519.4000000000068,26.239737546822457,0.939601059367373,-0.24633915220333558
520.7000000000069,26.280747857318214,0.9431759273274091,-0.24734936802800522
522.0000000000068,26.323327219809023,0.9443473701485117,-0.24734868036397417
523.3000000000068,26.36540147580578,0.9451181260345816,-0.24669146731325053
524.6000000000068,26.407023257085296,0.9436264549416553,-0.24668261850563988
525.9000000000069,26.448911687904985,0.9434782069928748,-0.24799461411046053
527.2000000000069,26.490953419115158,0.9436764418346979,-0.24800050843891386
528.5000000000069,26.532801906496367,0.9408692269340896,-0.249053198661096
529.800000000007,26.573997875555328,0.9368203514593756,-0.24899037162220106
531.100000000007,26.61641366307165,0.9334998210916173,-0.24899071906602588
532.4000000000069,26.658565823174875,0.9342370802776412,-0.24928178673080748
533.700000000007,26.700482169080214,0.9270409927323029,-0.2493200439969181
535.000000000007,26.742271039737588,0.9263013149834274,-0.2493204454270299
536.300000000007,26.78454812983762,0.9197958906052198,-0.24955115213879475
537.6000000000071,26.826478471139012,0.9140286959206491,-0.25062288157012524
538.9000000000071,26.86844610546048,0.9077563909506601,-0.2499782294484878
540.2000000000071,26.909967279835406,0.9042632885449348,-0.2499792085529191
541.500000000007,26.952409083044948,0.8976248488656989,-0.2513035208763079
542.8000000000071,26.994945239770917,0.8966117564861463,-0.25131310048187494
544.1000000000072,27.037042686779934,0.8901254290792071,-0.25264219937558297
545.4000000000071,27.07946416339781,0.8879031924639987,-0.2526101701237544
546.7000000000072,27.121737623847448,0.8856723270821324,-0.25261014571371465
548.0000000000073,27.16375311883504,0.8783821538715674,-0.25261014599825726
549.3000000000072,27.20569715556868,0.876555475512609,-0.25261014605421384
550.6000000000072,27.247929528452854,0.8757013845449817,-0.2526101548295894
551.9000000000073,27.2903921789699,0.8743251479302123,-0.25260964158791976
553.2000000000073,27.332455029613616,0.8754990830053513,-0.25390722271814603
554.5000000000073,27.374635628795225,0.8757040417944034,-0.25392975132154705
555.8000000000073,27.417124780106132,0.8690109561167721,-0.2539220263559825
557.1000000000073,27.459404892372348,0.8672847852901924,-0.25493195650272815
558.4000000000074,27.50135810072775,0.8634538972848548,-0.2549189158444962
559.7000000000073,27.54421432441302,0.862234877382058,-0.25438546828207587
561.0000000000074,27.58672021392857,0.8610098204106692,-0.25393003766859534
562.3000000000075,27.629169432623904,0.8617157433778156,-0.2539150263130314
563.6000000000074,27.671518031301805,0.861714815890599,-0.2542596037123839
564.9000000000075,27.714053371840695,0.8652780136639664,-0.25426007639270676
566.2000000000074,27.756442970182686,0.867194543263893,-0.254260083470228
567.5000000000075,27.79866269771834,0.8647228995059321,-0.25425739395110414
568.8000000000075,27.84126295599408,0.8715704706590648,-0.25394010055395144
570.1000000000075,27.88379098582517,0.8735870472436409,-0.25402885863329594
571.4000000000076,27.926262249021164,0.8805308681111947,-0.2525554820466458
572.7000000000075,27.969083442168653,0.9193492281203501,-0.25389858474787985
574.0000000000076,28.012257567247968,0.9869165331274664,-0.25524779701530775
575.3000000000076,28.054581660950934,0.9352949826848659,-0.2552494088943318
576.6000000000076,28.096473995640796,0.9026240758429301,-0.25515450142764307
577.9000000000076,28.138867426441266,0.8778544857218842,-0.25655962980609637
579.2000000000077,28.181258998334197,0.8654164791708183,-0.25656006563632827
580.5000000000076,28.22357587681297,0.8539267771466695,-0.2565600641797321
581.8000000000077,28.266091160339993,0.8468356627030769,-0.256560076080111
583.1000000000078,28.308406874386442,0.8416353994922589,-0.25654916328367694
584.4000000000077,28.35043206271184,0.8410468041064244,-0.25523328155229574
585.7000000000078,28.393813330127642,0.8389958367038928,-0.2552400426721362
587.0000000000077,28.436003596941205,0.8432806462033253,-0.25524006398616894
588.3000000000078,28.478558465991114,0.8380860288078902,-0.2552400624789559
589.6000000000078,28.52125811907106,0.838255398198848,-0.25524042203115327
590.9000000000078,28.56399271471557,0.8372873736845001,-0.25665302800088385
592.2000000000078,28.606297950420874,0.8386257724436081,-0.25721109498511696
593.5000000000078,28.649198817965082,0.837896047375123,-0.25851096293633047
594.8000000000079,28.6918304962766,0.8388833991163857,-0.2582012675859344
596.1000000000079,28.734378382185323,0.8399390750203662,-0.2572289275893347
597.4000000000079,28.776860899618278,0.8352884536241433,-0.2571240619917283
598.7000000000079,28.819733436671882,0.8365313509004917,-0.2585397646110308
600.000000000008,28.862344757099912,0.8396581513522776,-0.25853981736357934
601.3000000000079,28.904963007395825,0.8384478651679658,-0.2585398147524738
602.600000000008,28.948114180110164,0.8373480200720274,-0.258539627341011
603.900000000008,28.990801491082458,0.8375369408425057,-0.2585654069706882
605.200000000008,29.03343652267639,0.8391034427410503,-0.2598638477658626
606.5000000000081,29.075986540340143,0.8436858792488622,-0.25985974196645634
607.800000000008,29.11891829740044,0.8452427751105739,-0.2598334243397735
609.1000000000081,29.162074810543135,0.8429641587582563,-0.26117291639042106
610.400000000008,29.20453471012393,0.8423177619240627,-0.2598521796661162
611.7000000000081,29.247023530500375,0.8456127993526269,-0.25980742163174764
613.0000000000082,29.290065001210326,0.8464036132025894,-0.2611802872607414
614.3000000000081,29.33295468279165,0.8455622574616171,-0.2611801496032986
615.6000000000082,29.375490603271434,0.8486839475015564,-0.2620871532702642
616.9000000000082,29.41870035618383,0.8508049003192617,-0.2611728319427389
618.2000000000082,29.461530780602907,0.8469636649116687,-0.26117988064277364
619.5000000000082,29.504500522976286,0.8472844005336357,-0.2611865454827318
620.8000000000083,29.547328690101907,0.8468180515401161,-0.26214384809263613
622.1000000000082,29.590227347780896,0.8509126409590989,-0.26217039739475556
623.4000000000083,29.63346106584541,0.8528287570872859,-0.2635374964874484
624.7000000000083,29.675953816323187,0.8523731265986971,-0.2628333050307097
626.0000000000083,29.71874862833095,0.8516429822628832,-0.2630383468743376
627.3000000000084,29.76208879432336,0.8558381419215643,-0.26347976750489943
628.6000000000083,29.804873433424152,0.855974584490536,-0.26348079122774903
629.9000000000084,29.847804064310633,0.8620178942049421,-0.26395698178558424
631.2000000000083,29.890858235978985,0.8603895860758872,-0.26479962641184374
632.5000000000084,29.93391640546695,0.8619818519562542,-0.2648000608249741
633.8000000000084,29.977073577699947,0.8709407409919022,-0.26480004249191413
635.1000000000084,30.020102309011477,0.873517877009763,-0.2647959138861746
636.4000000000085,30.0629777374779,0.8750270997296364,-0.2638185234097761
637.7000000000085,30.106140450488,0.8790811343593676,-0.2638101468838814
639.0000000000085,30.148589697298245,0.878920855311141,-0.2638097383949658
640.3000000000085,30.1919977041996,0.8834352023938257,-0.2639561148514007
641.6000000000085,30.23513042459888,0.8888241957322598,-0.26513217432208114
642.9000000000085,30.27804113889122,0.8914884114525105,-0.26647803269274517
644.2000000000086,30.321408146191335,0.9006824355519211,-0.26644045503054015
645.5000000000086,30.364301189168486,0.9044038242397006,-0.26682241052702116
646.8000000000086,30.40759016370407,0.9103928817763042,-0.2677600488225318
648.1000000000087,30.450648395202496,0.9183288657773875,-0.26775884257793026
649.4000000000086,30.494068177949075,0.9251261691234614,-0.2690541928370611
650.7000000000087,30.536460842615444,0.9359556682959715,-0.269079901757864
652.0000000000086,30.58016740761828,0.9424840848648955,-0.2690820346143967
653.3000000000087,30.62331686021553,0.9562120872688165,-0.2689075796549063
654.6000000000088,30.666751511151652,0.9664358137245123,-0.2690739434740337
655.9000000000087,30.709546958322754,0.9726691196122264,-0.2700342196809711
657.2000000000088,30.753146590766054,0.9855319392556547,-0.27100965980870884
658.5000000000088,30.796102166267517,0.9935602034963497,-0.2726227350144206
659.8000000000088,30.839528899727185,1.0040096027218066,-0.27280911143294917
661.1000000000088,30.882904597339618,1.0211542961880606,-0.27418685706017376
662.4000000000088,30.926334837971165,1.0352682048375206,-0.27547437481563763
663.7000000000088,30.969457599792985,1.0469816913931387,-0.27675824426710793
665.0000000000089,31.012840813536712,1.0618246634908646,-0.2768861838477128
666.3000000000089,31.056276837450397,1.076942934952546,-0.2781071079577271
667.6000000000089,31.099521879365003,1.0911277525779446,-0.27940062395292076
668.900000000009,31.14292503574215,1.1068931801380306,-0.27941498115488184
670.2000000000089,31.186101695415637,1.124517536150024,-0.2807123373423428
671.500000000009,31.229325103919564,1.1432969905927823,-0.2806993880173949
672.8000000000089,31.27276028609716,1.1588948573821352,-0.2821986116079982
674.100000000009,31.316237323796884,1.1766486371182445,-0.28225906302454096
675.400000000009,31.359670841906464,1.1990508625599916,-0.2834603387948502
676.700000000009,31.402942761693204,1.221473800121274,-0.28486763385497005
678.0000000000091,31.445741981862344,1.2379739494353066,-0.28620133294112904
679.300000000009,31.48987109366663,1.2624222674675512,-0.28753322468787434
680.6000000000091,31.53310255466449,1.2896306111726468,-0.2889460515787161
681.9000000000091,31.57660842367877,1.311716029713604,-0.29120673108714223
683.2000000000091,31.62016743310787,1.3342140782187117,-0.2925907695138905
684.5000000000091,31.663480866033527,1.3595888049040739,-0.2952979857483262
685.8000000000092,31.707091373734478,1.3911243175357302,-0.2970663253193466
687.1000000000092,31.750503654547067,1.4220944708107335,-0.2985146586807095
688.4000000000092,31.794196376771566,1.449084442185867,-0.3008084931673287
689.7000000000093,31.837524531891102,1.4782802054158113,-0.3026609272833798
691.0000000000092,31.88082396940484,1.5109017626438896,-0.30518366917323947
692.3000000000093,31.924622001308087,1.5433952886154199,-0.3080769373825549
693.6000000000092,31.968149628692927,1.577935694732275,-0.31016019015187
694.9000000000093,32.01178079167966,1.618678235633684,-0.31277845806486937
696.2000000000094,32.05532860784383,1.6540027779945083,-0.31588985981540274
697.5000000000093,32.09911124870398,1.6914216257321946,-0.3195058046174246
698.8000000000094,32.143062895064126,1.7335488425629013,-0.32222778849257505
700.1000000000093,32.18641357066044,1.7745829869299075,-0.3253064814281177
701.4000000000094,32.23024003084561,1.8153776570842783,-0.3275023436353077
702.7000000000094,32.273881722101706,1.8638628780460775,-0.33043438504053224
704.0000000000094,32.317682558888556,1.9128032405897482,-0.3350047721596998
705.3000000000094,32.361330759754246,1.9565839531479763,-0.338783102681397
706.6000000000095,32.40518677051907,2.0076428425903434,-0.34246730700739336
707.9000000000095,32.448938717055086,2.0574534521738865,-0.3448702533060528
709.2000000000095,32.49285985022176,2.112667660878859,-0.3484128823353605
710.5000000000095,32.53659867628304,2.1642109876805273,-0.3526477146739255
711.8000000000095,32.580835274605576,2.219718475157752,-0.35754162523774324
713.1000000000096,32.624484071720566,2.2776944028916053,-0.36108765858505576
714.4000000000095,32.66840310245958,2.3392174759260005,-0.36591624593235483
715.7000000000096,32.71241621844713,2.397727559147244,-0.3703972658204684
717.0000000000095,32.75639089796879,2.457741990030642,-0.374417805478211
718.3000000000096,32.80031799183988,2.5211230155851503,-0.3801037150467259
719.6000000000097,32.844464651654135,2.5909484059328527,-0.3859709142372325
720.9000000000096,32.88843514054465,2.652678529116616,-0.39256154466280835
722.2000000000097,32.93226393009124,2.7243399373934727,-0.39757003875930863
723.5000000000097,32.976396091831845,2.7972318532580367,-0.4030608035493848
724.8000000000097,33.02091151497919,2.871692158027481,-0.4099282255791552
726.1000000000097,33.064896676373884,2.94510889184612,-0.41815577612967836
727.4000000000098,33.10905311363728,3.022762880986266,-0.42470594373097104
728.7000000000098,33.152920823630495,3.103590131342321,-0.42895813959506857
730.0000000000098,33.19726050304986,3.183303091913867,-0.4368214579071399
731.3000000000098,33.24186766443152,3.267628499382319,-0.44486187266753374
732.6000000000098,33.28594019825808,3.3523090641137925,-0.45094911700627494
733.9000000000099,33.330568330479814,3.439474513129818,-0.4609101753204472
735.2000000000098,33.374642128443796,3.531706741470112,-0.4686757930117871
736.5000000000099,33.41897205246074,3.62598010958436,-0.4767665893899453
737.80000000001,33.463528873856006,3.7151587677718254,-0.48605515719624215
739.1000000000099,33.50755241779413,3.8091374151762594,-0.49490462445584305
740.40000000001,33.552262484159094,3.905157101023127,-0.5041330173965011
741.7000000000099,33.596807241786124,4.010360868224047,-0.5145086070348719
743.00000000001,33.641288678843125,4.1107782571405584,-0.524799153800835
744.30000000001,33.68569615484786,4.217019055857318,-0.5345634745523564
745.60000000001,33.730137025753834,4.324482545675333,-0.5458743895927003
746.90000000001,33.774477693050464,4.425980183855064,-0.5547619673867783
748.20000000001,33.81930954153745,4.538600259674219,-0.5662636552634681
749.5000000000101,33.86349971983976,4.652954779687013,-0.5790768475084525
750.8000000000101,33.90881978180318,4.7693466805410685,-0.5917161925792098
752.1000000000101,33.95345708127136,4.884104348601195,-0.6041641035605783
753.4000000000101,33.997886825746264,5.001357499216187,-0.6163917378295247
754.7000000000102,34.04257042306414,5.120141583730219,-0.6298087326084203
756.0000000000101,34.08773811356294,5.242409929263322,-0.6416714408406219
757.3000000000102,34.13229288883185,5.358730688330874,-0.6541610559530726
758.6000000000101,34.17696533052074,5.483898664375852,-0.6686379736410744
759.9000000000102,34.2216020736553,5.607588222343015,-0.6833795312594155
761.2000000000103,34.266559803282995,5.734031673009813,-0.6986715946402429
762.5000000000102,34.311342584036474,5.855072648741109,-0.7137081253723938
763.8000000000103,34.356153795123134,5.984925271721324,-0.7275331513178718
765.1000000000103,34.400893987005645,6.108553530559838,-0.7429728788329721
766.4000000000103,34.44566949511051,6.232304377084309,-0.7599784546852546
767.7000000000103,34.49049439942699,6.349861595820483,-0.7760284207123775
769.0000000000103,34.53488674550695,6.476844814824693,-0.7949128135618824
770.3000000000104,34.579792330398185,6.598316899601131,-0.813289059831785
771.6000000000104,34.624848989832856,6.722208714149195,-0.8324464996079382
772.9000000000104,34.66982876393424,6.843447702354879,-0.8502006986315789
774.2000000000104,34.71434593691231,6.953250118744225,-0.8680848166198949
775.5000000000105,34.75913746251475,7.06340049350804,-0.8871808605741434
776.8000000000104,34.80353185927384,7.168555338869698,-0.9065104244041042
778.1000000000105,34.84805131434148,7.268568719835726,-0.9247108155246564
779.4000000000106,34.89272282177494,7.359309502640854,-0.9451035819541111
780.7000000000105,34.93685323913285,7.433258233746674,-0.9646309152254635
782.0000000000106,34.98149215028198,7.5043127795850495,-0.9842545858333942
783.3000000000105,35.025427412559765,7.553438921246698,-1.005146393516045
784.6000000000106,35.06962345084054,7.58986023482526,-1.0274848272649657
785.9000000000106,35.11392477813903,7.596932293210104,-1.048710279751909
787.2000000000106,35.15699745751569,7.573938288911972,-1.0683543473672144
788.5000000000106,35.20039901334991,7.524819998157554,-1.0889192033737864
789.8000000000106,35.243797385872675,7.4338960503889036,-1.1084258977937815
791.1000000000107,35.28639763436909,7.297407224701427,-1.1279322572558694
792.4000000000107,35.32861306471729,7.110854478090139,-1.1471343820692188
793.7000000000107,35.37044766583235,6.864505146672162,-1.1666498427843588
795.0000000000107,35.41163519417634,6.554075531419321,-1.1824559072412848
796.3000000000108,35.45255545830415,6.172223765118294,-1.1983685566451165
797.6000000000107,35.49292977269505,5.707125493090889,-1.2133741598558423
798.9000000000108,35.5322367378094,5.174433816298943,-1.2270055070143968
800.2000000000107,35.57134069586576,4.586304054222562,-1.239530432580831
801.5000000000108,35.61020840763416,3.947776498235174,-1.2497194198962438
802.8000000000109,35.64895818132265,3.3230887162920455,-1.258442532468802
804.1000000000108,35.68835495819969,2.7332045364236572,-1.2667729523451743
805.4000000000109,35.72800866545291,2.2182543472280587,-1.270317496543163
806.7000000000108,35.768141599915545,1.7992152432357902,-1.2747911551622337
808.0000000000109,35.80949489105324,1.4566385668843007,-1.276339775541186
809.3000000000109,35.850861248287664,1.204034773821487,-1.2782592706735207
810.6000000000109,35.89334126423459,1.014722429605324,-1.2809605341236088
811.900000000011,35.93607958249808,0.8809052388758346,-1.2815702281076748
813.200000000011,35.978790947915385,0.7854190772925573,-1.2827378393880995
814.500000000011,36.021911006505654,0.718983264079218,-1.2828330725726609
815.800000000011,36.06555708363426,0.6723226850695974,-1.2841362613175233
817.100000000011,36.10906036853872,0.6380144933333554,-1.284129735788412
818.400000000011,36.15268806462061,0.616176896099703,-1.2855334824012727
819.7000000000111,36.1964424058871,0.605854428816691,-1.285450078388203
821.0000000000111,36.2402030837353,0.5910847244083333,-1.2854473900188519
822.3000000000111,36.28414424231175,0.5886311736991958,-1.284152648252748
823.6000000000112,36.32790554720486,0.5864145374777727,-1.284139841374024
824.9000000000111,36.371411031850066,0.5845339912369273,-1.284139744067771
826.2000000000112,36.41569878488566,0.580544360230524,-1.284090623968082
827.5000000000111,36.45953939137734,0.5796590033811152,-1.284207482438879
828.8000000000112,36.50356861776811,0.5777726646501071,-1.2855043301391436
830.1000000000112,36.54739701319123,0.589944025750493,-1.2868790066031357
831.4000000000112,36.591329542390234,0.5929315400723478,-1.2868622615870593
832.7000000000113,36.635425213744426,0.5990167842256665,-1.2874785210571473
834.0000000000113,36.67909870911754,0.6008507571904831,-1.2862187723325151
835.3000000000113,36.72331309675145,0.6026497905159527,-1.2862200980132026
836.6000000000113,36.767199960142385,0.6064479583737663,-1.2862200900307803
837.9000000000113,36.81130228270491,0.6086161105088235,-1.2862200899999783
839.2000000000113,36.8553401943345,0.6045234926717422,-1.2862200899999845
840.5000000000114,36.89962902839913,0.6003436340141168,-1.2862200899981744
841.8000000000113,36.94301056537383,0.5976917053637159,-1.2862200912513444
843.1000000000114,36.986958408011276,0.5968564448710598,-1.2862205608473318
844.4000000000115,37.030579743092986,0.597392729286326,-1.284858319082344
845.7000000000114,37.0751159923954,0.5945854092703378,-1.28562698138964
847.0000000000115,37.11839363843403,0.5928974261375918,-1.2855663930015138
848.3000000000114,37.16300444832232,0.5947593068113702,-1.283840588866218
849.6000000000115,37.206930700574304,0.5929398511395912,-1.2827699743980978
850.9000000000115,37.251015077024384,0.5868361572183787,-1.2859925902213094
852.2000000000115,37.29504343084404,0.5955721123220236,-1.2865297808826037
853.5000000000116,37.338817160002826,0.5939137416159016,-1.286450223462415
854.8000000000116,37.383068009118816,0.5955640846664886,-1.286450094193326
856.1000000000116,37.42707836862892,0.5964689955563787,-1.2864430745675421
857.4000000000116,37.47146872655685,0.5933588338058698,-1.2872953559892872
858.7000000000116,37.5147465039993,0.595950482031245,-1.2864415669904816
860.0000000000116,37.55979960495705,0.5968875570821934,-1.2864399369744164
861.3000000000117,37.60344211946645,0.594331831462195,-1.286439599145969
862.6000000000117,37.647657184014925,0.5911441591142319,-1.287583007068228
863.9000000000117,37.69200358682934,0.599921898164645,-1.2877475228774
865.2000000000118,37.73591298203428,0.5991553250162083,-1.2864357088613358
866.5000000000117,37.78000000000041,0.5912862715526848,-1.2864401030352428
867.8000000000118,37.82425609193976,0.5903506954648512,-1.2867117356305195
869.1000000000117,37.868509551589824,0.5942706580002571,-1.2877311972007934
870.4000000000118,37.91289307757897,0.5934873547309747,-1.2877710496184807
871.7000000000118,37.95676620142374,0.5889138065501689,-1.2879517648384038
873.0000000000118,38.00096370178236,0.5887109625803374,-1.2874305634433805
874.3000000000119,38.04511241048058,0.5878867016562118,-1.2877714777456442
875.6000000000118,38.08929866534599,0.5844101987588887,-1.2880898685353954
876.9000000000119,38.13350765283631,0.5823448181781573,-1.288083859649853
878.2000000000119,38.17749009646695,0.5760891509882852,-1.287758682543409
879.5000000000119,38.221451376266714,0.5807572414860501,-1.289075778136104
880.8000000000119,38.26567981325928,0.576587058649311,-1.287782890016048
882.100000000012,38.30927184435628,0.5751409651976769,-1.2877632072358622
883.4000000000119,38.354180873742386,0.5731085362252506,-1.2854693033011269
884.700000000012,38.39837670971251,0.5729670594572198,-1.2866796083817613
886.000000000012,38.442474050521575,0.5737857485086862,-1.288174064525268
887.300000000012,38.48659919287031,0.5685736823584798,-1.288232803578882
888.6000000000121,38.5306893681262,0.5692874414934863,-1.288539418867836
889.900000000012,38.57491431903142,0.5760711522779987,-1.2885302817613056
891.2000000000121,38.61917291368072,0.5749462329265006,-1.2885301501075315
892.000000000012,38.646293880634936,0.5789439793528568,-1.2885301499897164