File: 01_Data/Cinder_Block/STA/N2/10K_min/Cinder_Block_STA_N2_10KData_230920_R2.csv
##Temp./Â°C,Time/min,DSC/(mW/mg),Mass loss/mg
41.0,10.810497362272242,0.005298381724854639,0.008430890234359278
42.40000000000002,11.165319976426382,0.03975846670244998,0.005918061695199928
43.80000000000004,11.409814135600799,0.06031605831160647,0.005076009761270761
45.20000000000006,11.615881572930407,0.07591611623437267,0.00535803942048485
46.60000000000008,11.805200354165592,0.08673551220788012,0.005421296572502232
48.0000000000001,11.980648004883038,0.09293322217520705,0.004723063181080622
49.40000000000012,12.147191873309662,0.10367834689725264,0.005043672149852796
50.80000000000014,12.310381073630483,0.1061448535944427,0.005336826056559829
52.20000000000016,12.468237230962819,0.11194231178711433,0.00449179940561617
53.60000000000018,12.624903911746484,0.11493692328763228,0.004996360466366756
55.0000000000002,12.77955903919819,0.1185141948218078,0.0042086129022278485
56.40000000000022,12.93408646260602,0.12128598081593589,0.004881447934125482
57.80000000000024,13.084633655576663,0.1217491213044326,0.0035087990379563117
59.20000000000026,13.235007577071519,0.1269678658551967,0.0034845597693609065
60.60000000000028,13.38581457840458,0.12830331866479106,0.0035579622662735844
62.0000000000003,13.533338408789913,0.1289668913668791,0.003509124307895739
63.40000000000032,13.6803525602785,0.13087239277199947,0.0027030613308625107
64.80000000000034,13.828581063708135,0.13432403896473422,0.0048319554272375775
66.20000000000036,13.974473272272983,0.13407252392213254,0.0032271680885398446
67.60000000000038,14.119670864290542,0.13703380493672657,0.003228065827717952
69.0000000000004,14.264074627938303,0.13845569931123913,0.0028867855078953397
70.40000000000042,14.408753285211702,0.1367053534434477,0.0018763953239555597
71.80000000000044,14.552330423109902,0.14217968353351806,0.002777202772004106
73.20000000000046,14.694731631810775,0.1423696641674177,0.0022370824170132586
74.60000000000048,14.836414594757901,0.1434632574968151,0.0015376092251768725
76.0000000000005,14.978895851296205,0.14562889378627242,0.0008800616955872975
77.40000000000052,15.121797816993988,0.14588260107897533,-0.00043971529278952204
78.80000000000054,15.26306769323266,0.1466698124166057,0.0008799676166755255
80.20000000000056,15.403477855725173,0.14509731269959958,0.00087973338930869
81.60000000000058,15.544532651630787,0.14780408082740992,4.1329185493488296e-05
83.0000000000006,15.682782664872507,0.14560517517323546,0.0008022670120966247
84.40000000000062,15.822198217094028,0.1483694214314244,-0.0007555720078160633
85.80000000000064,15.96071116929036,0.14897833126793691,-0.0010837965722592102
87.20000000000066,16.10005319634943,0.148153449338017,-0.0023901973490740858
88.60000000000068,16.238403521832375,0.14647978913034976,-0.0017503128507665444
90.0000000000007,16.375976448435956,0.14654079816692422,-0.00042140542041613216
91.40000000000072,16.514681679342516,0.14379104882864224,-0.0010999733645653542
92.80000000000074,16.651852529759342,0.145344531695194,-0.002420132722435575
94.20000000000076,16.788091275362945,0.14573448405330347,-0.002376701358666189
95.60000000000078,16.925264504234093,0.14325240297917663,-0.0024097734349570743
97.0000000000008,17.06263842873712,0.14594241212952563,-0.0023117511456085538
98.40000000000082,17.19854173867002,0.14393728868116096,-0.0024079262715979155
99.80000000000084,17.335301506816293,0.14582658733340592,-0.0036919632634968558
101.20000000000086,17.47264257232001,0.1461434931626735,-0.003740039618421509
102.60000000000088,17.609062311464097,0.14310314422833414,-0.0037393455416205867
104.0000000000009,17.744136117981796,0.1435314342462568,-0.004537821960317157
105.40000000000092,17.880343956213245,0.14286356079021845,-0.003710886163909688
106.80000000000094,18.016272421392074,0.14587947233575993,-0.006040033935987843
108.20000000000095,18.152175015229812,0.14372905603276043,-0.004720152009829004
109.60000000000097,18.28908151843082,0.14313998465302546,-0.0060420614203824385
111.000000000001,18.424310141667856,0.14221532650437507,-0.004719879051537923
112.40000000000101,18.55763681118852,0.14166936842440658,-0.004733498903274125
113.80000000000103,18.696020941337462,0.14158851725882937,-0.00604036973105293
115.20000000000105,18.83085814255958,0.14035523098328873,-0.006029863831622961
116.60000000000107,18.9667475988323,0.13968937809332682,-0.007340747190428765
118.0000000000011,19.098184176156227,0.1394501704744331,-0.007020082000404937
119.40000000000111,19.23806061370896,0.13819587076745932,-0.00643467083853233
120.80000000000113,19.37160755341225,0.14026040844186838,-0.007690042993556023
122.20000000000115,19.506416456109946,0.13752227422026375,-0.007690154979232311
123.60000000000117,19.641068170981672,0.13694389072190627,-0.008680007597860584
125.0000000000012,19.775630408667425,0.13555316191854838,-0.008652133598168188
126.40000000000121,19.911586031164248,0.1356552294712674,-0.0086701780006746
127.80000000000123,20.045059070115073,0.13445022312696864,-0.00868128363101306
129.20000000000124,20.1800112051679,0.1353179350928193,-0.008009256943341647
130.60000000000127,20.31423331022487,0.13338284526725896,-0.008059877086993072
132.0000000000013,20.449170000000123,0.13280832483823035,-0.00920420577610015
133.4000000000013,20.58286292450751,0.1330556202116988,-0.008999892464740533
134.80000000000132,20.71641031396192,0.13238148538283623,-0.009899473157737315
136.20000000000135,20.851899440649845,0.13013433196179336,-0.009000074729347496
137.6000000000014,20.9864122582481,0.12947137071894232,-0.010311896716641122
139.0000000000014,21.121410656925253,0.12887872332314898,-0.010309993981173715
140.4000000000014,21.25452962374314,0.12614198123535925,-0.01163397315972059
141.80000000000143,21.388726972097267,0.12537200744777088,-0.011629995021683381
143.20000000000147,21.52185425778672,0.12550578255757627,-0.010331082655321566
144.60000000000147,21.65585211325607,0.12654385633198006,-0.010980086736539718
146.00000000000148,21.78999951415017,0.12658214810313329,-0.010980078187110998
147.4000000000015,21.922568370731074,0.12561866771647323,-0.009643899835588332
148.80000000000155,22.057204466595323,0.12595200113312854,-0.010988766499735458
150.20000000000155,22.191441241520305,0.12418901928307458,-0.01229849915347403
151.60000000000156,22.324736577614104,0.12341404412262369,-0.011640192785117964
153.0000000000016,22.458491658127656,0.12534526353972986,-0.01164018600357375
154.40000000000163,22.59280678175273,0.12440611478006436,-0.010898825482178687
155.80000000000163,22.726076590637938,0.12354813935991693,-0.012343925235627662
157.20000000000164,22.860169456881117,0.12473132132136877,-0.011548214782305166
158.60000000000167,22.994224918480658,0.12021168409145133,-0.01196484588209712
160.0000000000017,23.127479848595307,0.12181060437792546,-0.011959947233041834
161.4000000000017,23.261876533530703,0.12005541274498799,-0.011319459107942187
162.80000000000172,23.39452700326663,0.11756526522237132,-0.012950035894336853
164.20000000000175,23.529068261814444,0.11893573915406042,-0.012950002999999377
165.60000000000178,23.661761934812322,0.11813142007024946,-0.012949999218016206
167.0000000000018,23.796534169650396,0.11661869303226902,-0.012299808917038746
168.4000000000018,23.928998196918723,0.11553031888734755,-0.013620033051592983
169.80000000000183,24.062664383668576,0.11598129798511181,-0.01293635760084344
171.20000000000186,24.194944923534624,0.11575778691848049,-0.01328624512580312
172.60000000000187,24.330125981946043,0.11499120918745209,-0.011960850482970908
174.00000000000188,24.46206360816429,0.11291296374320003,-0.013280140418005626
175.4000000000019,24.597249023035154,0.11341487381204152,-0.014599079685362781
176.80000000000194,24.727845512679494,0.11390239565063132,-0.013381871624626562
178.20000000000195,24.863171384157926,0.11472234573007878,-0.0142696666838793
179.60000000000196,24.994080388136098,0.11485491951669147,-0.013280463218449778
181.000000000002,25.12700592221116,0.11312256134294474,-0.014629011510268963
182.40000000000202,25.262075889280244,0.11250702463028261,-0.013274330591622974
183.80000000000203,25.39611211178476,0.11394920599564262,-0.013252127903790711
185.20000000000203,25.527628235484634,0.11074064665520811,-0.014550503094409528
186.60000000000207,25.661730572146134,0.10723651972767323,-0.01261517178662741
188.0000000000021,25.795478879839344,0.10783477636250938,-0.013913196381454718
189.4000000000021,25.926758093240284,0.10825962701918801,-0.014930004067633895
190.80000000000211,26.060660432438354,0.1065409358946332,-0.01361006132067999
192.20000000000215,26.195052725866535,0.10635355719053008,-0.014929950342195575
193.60000000000218,26.327178074614622,0.10565245264845924,-0.01459973803349257
195.0000000000022,26.460963769531627,0.10520000516991401,-0.013290044697837011
196.4000000000022,26.594181564808647,0.10218567975131698,-0.015900202458399626
197.80000000000223,26.725685914576196,0.10362805151173848,-0.015910438974471752
199.20000000000226,26.859436835814,0.10326392989008015,-0.014600040154955973
200.60000000000227,26.991854012302518,0.10417780986113412,-0.014600129206283174
202.00000000000227,27.126029755677184,0.10557011897238167,-0.01592210851642184
203.4000000000023,27.258573000231486,0.10256450874312817,-0.014938539380029425
204.80000000000234,27.391268752838933,0.10239513532073041,-0.016237166666078107
206.20000000000235,27.525067621945027,0.10117402736314607,-0.015259298167023427
207.60000000000235,27.658330601370988,0.1008984203297949,-0.016583036506965687
209.0000000000024,27.79127737837384,0.09948388796945196,-0.01783416415396566
210.40000000000242,27.924242522135174,0.10031099959004552,-0.015590148027546213
211.80000000000243,28.058070553644182,0.0988914729185848,-0.01691016080011254
213.20000000000243,28.190704997505833,0.09762052657520015,-0.016910147963110855
214.60000000000247,28.32290175742999,0.09517297322164486,-0.015617115310258
216.0000000000025,28.457078831965216,0.09730331794626612,-0.015919884780438043
217.4000000000025,28.59011216795149,0.09727241630029848,-0.01592060023245523
218.8000000000025,28.72152806466102,0.09808424666814197,-0.01689982925326694
220.20000000000255,28.85540906122356,0.09656293527556392,-0.01690761191172685
221.60000000000258,28.986764274084763,0.09876124829851185,-0.017260693605780197
223.0000000000026,29.120109030410923,0.10082762273522894,-0.016899856815758785
224.4000000000026,29.253236567881856,0.09843996638558705,-0.01656829946371685
225.80000000000263,29.387666542485125,0.10082300355458029,-0.01709897557503215
227.20000000000266,29.519740143518238,0.09985771695635992,-0.01788985700325263
228.60000000000267,29.651919052801187,0.10018548230167323,-0.017858427749711137
230.00000000000267,29.784989477010686,0.09911070664146115,-0.01727080961252847
231.4000000000027,29.91925997386733,0.09837723336610815,-0.016899962201077923
232.80000000000274,30.05247222263595,0.0998514843953302,-0.018220195014091
234.20000000000275,30.18577141240857,0.10060578565696665,-0.016901737500683467
235.60000000000275,30.318850745194208,0.10032773126673256,-0.018219964899437002
237.00000000000279,30.45274468005636,0.10147698834405472,-0.018587657548833292
238.40000000000282,30.585700385330096,0.10021894867258974,-0.01822341050491927
239.80000000000283,30.71887124336094,0.099018829526202,-0.019538807274621206
241.20000000000283,30.852213522375,0.09828056910401384,-0.019560878273914728
242.60000000000286,30.985547644540027,0.10051680667589169,-0.01887363935261943
244.0000000000029,31.117705819092958,0.09867720132379154,-0.018878186877320235
245.4000000000029,31.251625078314515,0.09849098201440487,-0.020199938399924733
246.8000000000029,31.383560239575363,0.09819857374905272,-0.020195081996068787
248.20000000000294,31.516646352161004,0.09587912169718815,-0.020846079247907046
249.60000000000298,31.64991982831036,0.0966658795673847,-0.021237769781304205
251.00000000000298,31.783874000864547,0.09821911250184812,-0.021509931841805052
252.400000000003,31.917098410531338,0.09880381892270207,-0.02031056053075364
253.80000000000302,32.04981547203684,0.09559905411920466,-0.02021152405161475
255.20000000000306,32.182895084177055,0.09759809843262257,-0.01985999641280456
256.6000000000031,32.31621211009048,0.0959469729721858,-0.021179961419398374
258.00000000000307,32.44899033587065,0.09717028177790676,-0.01986581289625411
259.4000000000031,32.58280605354755,0.09656784651794137,-0.021179991879718862
260.80000000000314,32.71587717505046,0.09705460654472553,-0.021179991999987102
262.2000000000031,32.849541053971315,0.09503893428977794,-0.02118085011880977
263.60000000000315,32.98239120355534,0.09579354386999595,-0.022499990911420298
265.0000000000032,33.11586992184432,0.09598475948336671,-0.020524461804884986
266.4000000000032,33.248525960270854,0.09498622405324242,-0.0218399917845038
267.80000000000325,33.38358420827309,0.09538356373863444,-0.022517386551485163
269.20000000000323,33.517790900303105,0.09551430680822626,-0.021190203754472225
270.60000000000326,33.65132822309163,0.09566911045838022,-0.02250036860463034
272.0000000000033,33.78562023121467,0.09398471564846012,-0.022355128326115192
273.4000000000033,33.91801868329093,0.09150882904839075,-0.0208478689314342
274.8000000000033,34.05219421245507,0.09184050132040245,-0.020534682070144417
276.20000000000334,34.18666290393188,0.0912419898780612,-0.02218905878628874
277.6000000000034,34.32027606571776,0.09011030507277673,-0.02119057166270366
279.0000000000034,34.454592545912135,0.0898718024700993,-0.022509115624302467
280.4000000000034,34.58733929332777,0.0915789059585197,-0.02251254570107486
281.8000000000034,34.72107260089977,0.09105084421732479,-0.021850028839737412
283.20000000000346,34.85468440278688,0.08988538709499783,-0.021925077538143434
284.60000000000343,34.98860050002914,0.08864257249210694,-0.0218507067299325
286.00000000000347,35.121157009542344,0.08933502558992812,-0.02185026662938183
287.4000000000035,35.25523051641005,0.08836618226661752,-0.02251042784846158
288.80000000000354,35.38877449152729,0.08960480481508415,-0.02251004799411449
290.20000000000357,35.52328349156642,0.09209166676028913,-0.021865483512778727
291.60000000000355,35.65591637110255,0.09153398080125452,-0.02207257032878207
293.0000000000036,35.79090289215532,0.0918190555596754,-0.022840075029852525
294.4000000000036,35.92499933118963,0.08950293318992752,-0.022849303448051028
295.8000000000036,36.05868971798436,0.09032981275712726,-0.023170048005594968
297.2000000000036,36.19284366307814,0.0902932694111469,-0.02317004800000122
298.60000000000366,36.32672977685952,0.09066268349701057,-0.02317004805713685
300.0000000000037,36.461021238048815,0.08803549840451752,-0.02181437247694351
301.40000000000373,36.59562895887628,0.08854487909552566,-0.023170047724708098
302.8000000000037,36.72945453960477,0.0854016017822754,-0.023170373680037937
304.20000000000374,36.864069308702284,0.08736537538615119,-0.023829993865275956
305.6000000000038,36.99880640370464,0.08702420947578449,-0.023829994592853065
307.00000000000375,37.132827583718345,0.0871631261842114,-0.022510222634656518
308.4000000000038,37.26707610717573,0.08499390755603131,-0.023829970048327542
309.8000000000038,37.401585909828555,0.08509765611335984,-0.0238299939999993
311.20000000000385,37.536009149023585,0.08580263594802218,-0.02382999401417152
312.6000000000039,37.67071611913498,0.08653032899999413,-0.02276109380001401
314.00000000000387,37.80503691766597,0.08616041059984214,-0.02350007495739259
315.4000000000039,37.93917088508566,0.08815863312180672,-0.02349486660691058
316.80000000000393,38.07434540858983,0.0825444425008337,-0.02546028893554597
318.2000000000039,38.20860272338044,0.08422278163011443,-0.023547870035006913
319.60000000000394,38.34119136963182,0.08270766957934561,-0.02481002099409846
321.000000000004,38.47721018456723,0.0829220854239987,-0.024810021000000404
322.400000000004,38.611533207058514,0.08180440019074298,-0.02481002008236821
323.80000000000405,38.74702894580941,0.08170453590550797,-0.02578497237699029
325.200000000004,38.881723014631426,0.08266700951236183,-0.025793294875710693
326.60000000000406,39.01604224366723,0.08175916939287964,-0.023074503302147775
328.0000000000041,39.151575997577936,0.0806210555573117,-0.025792184933019602
329.40000000000407,39.28557659950424,0.07754342427026462,-0.024488191464951292
330.8000000000041,39.42134815732699,0.07944711675903982,-0.023766639470359063
332.20000000000414,39.55514137942393,0.07817342817517581,-0.023809421801276986
333.6000000000042,39.68990812813126,0.08184910491968722,-0.025789936821981385
335.0000000000042,39.8255732250843,0.0782950437808767,-0.025789937999999957
336.4000000000042,39.9609983649983,0.07748108627184713,-0.025789939557000707
337.8000000000042,40.09615087793169,0.07902508169126943,-0.024810090485449354
339.20000000000425,40.23074816328869,0.07974532792894529,-0.024809937999994425
340.60000000000423,40.36563568602879,0.07784823440284305,-0.024809938000000198
342.00000000000426,40.50120050989734,0.07646338520447626,-0.02480993380417562
343.4000000000043,40.634367128149506,0.0762599421793908,-0.025139853059012562
344.80000000000433,40.77178564931596,0.07626828392854446,-0.02611992437145627
346.20000000000437,40.908355229207615,0.0784160963655296,-0.02611991099999278
347.60000000000434,41.04352778093841,0.07452830616595385,-0.02611803041960936
349.0000000000044,41.17951934935957,0.07511518391857885,-0.02512999222609036
350.4000000000044,41.31424606747354,0.07437998747944352,-0.026448450913297172
351.8000000000044,41.45002965823833,0.07380141244797778,-0.02931013616487288
353.2000000000044,41.58531926426065,0.07183576107036616,-0.029310185422988688
354.60000000000446,41.719259294725695,0.07417355980499418,-0.027990080900629266
356.0000000000045,41.85725236530107,0.07244738395097272,-0.026670131452909196
357.4000000000045,41.9921402551396,0.06982148992753157,-0.026670131999927627
358.8000000000045,42.12819403724658,0.07007465819147196,-0.026663137685771776
360.20000000000454,42.26177714751524,0.0698884850914887,-0.026570889665383124
361.60000000000457,42.39951632754977,0.06881330935236774,-0.02724599200460487
363.00000000000455,42.5345370522845,0.06801617671254112,-0.026684159496555004
364.4000000000046,42.670711138276886,0.06763834043555428,-0.025957012283774894
365.8000000000046,42.806745922613736,0.06719115213123983,-0.025687807354615178
367.20000000000465,42.94351536958154,0.0650392220787499,-0.025690105000123697
368.6000000000047,43.07639169806444,0.06504771009679122,-0.025690105044236855
370.00000000000466,43.2146751990933,0.06558798327001569,-0.027016174865018616
371.4000000000047,43.35136269459089,0.06381173247863892,-0.027003303064075723
372.80000000000473,43.487213518227115,0.0647076528010837,-0.025511546283163877
374.2000000000047,43.622959119490936,0.0627690846678759,-0.026679997220286022
375.60000000000474,43.75907055838873,0.05931030525612302,-0.026679991015959637
377.0000000000048,43.89484946114961,0.05921628622336139,-0.02602005692046827
378.4000000000048,44.031640003663824,0.05868922743971172,-0.026013878547188174
379.80000000000484,44.16744539684065,0.055293877211489484,-0.027342799876738155
381.2000000000048,44.303281756500134,0.05270003092344444,-0.026020012486155597
382.60000000000485,44.44016628152266,0.051313950850428114,-0.02668017983676574
384.0000000000049,44.57556550086709,0.05072880109852074,-0.02668063029880008
385.40000000000487,44.71310058606801,0.04839831395116456,-0.028235994988570212
386.8000000000049,44.84936019542643,0.0490815293573017,-0.02733994212768076
388.20000000000493,44.985626665982856,0.049186766439388574,-0.027339942999999423
389.60000000000497,45.12187028664931,0.044138515771709796,-0.027339942999998534
391.000000000005,45.25799604464768,0.0485435959802798,-0.027339943000088684
392.400000000005,45.395117079568614,0.04725520429308583,-0.027345979918657726
393.800000000005,45.53097841916414,0.04487663248468099,-0.027669943015017573
395.20000000000505,45.668262698328704,0.046763717050833487,-0.027669828449695455
396.600000000005,45.80540008654276,0.04381075235637111,-0.028319804731924414
398.00000000000506,45.94271822459449,0.04418642657210814,-0.028319859999998975
399.4000000000051,46.07885766896525,0.04502273627558884,-0.028319859999999863
400.8000000000051,46.21514947498876,0.0453089495282486,-0.028319859999999863
402.20000000000516,46.352311885867536,0.047070928739024076,-0.028319859999998975
403.60000000000514,46.48985485511008,0.04950021609049138,-0.02831986176318413
405.0000000000052,46.62640927161039,0.05118863845237054,-0.029640232026890256
406.4000000000052,46.764186827836575,0.05063922097263096,-0.029640108396997267
407.8000000000052,46.90133215748316,0.05080297810342116,-0.027629016322918254
409.2000000000052,47.03783885964742,0.0514270567830164,-0.029970105129070834
410.60000000000525,47.17545455105789,0.050566522806781755,-0.029245237887637554
412.0000000000053,47.3123301609932,0.04705613033399869,-0.029307352213008286
413.4000000000053,47.449373580753495,0.04877224521411483,-0.030630015935098065
414.8000000000053,47.58656341217481,0.04490584416480625,-0.02926245011556805
416.20000000000533,47.72428984482376,0.04388197774733449,-0.03070222841470338
417.60000000000537,47.86086767083238,0.04221244341105668,-0.03062361561874294
419.00000000000534,47.9983365799698,0.0398635287639002,-0.030629991013310764
420.4000000000054,48.13664898186129,0.03811760506246964,-0.029310039865374282
421.8000000000054,48.273130163401206,0.037552336159224486,-0.0293098139896375
423.20000000000545,48.41155568097143,0.034618011545961336,-0.030631431759688965
424.6000000000055,48.548688250079366,0.03365546946872189,-0.03194928866468061
426.00000000000546,48.68634742422841,0.03291891721556239,-0.030629880548836308
427.4000000000055,48.82225494315143,0.034632167256752666,-0.03062988086690721
428.8000000000055,48.96044290626237,0.03521255283162006,-0.030300311893054044
430.2000000000055,49.09740533663145,0.03514746162457505,-0.030299907999991937
431.60000000000554,49.23589016338507,0.038923962706234105,-0.030299908582445134
433.00000000000557,49.37271689653123,0.03182151768736108,-0.028989814813360493
434.4000000000056,49.51041100122124,0.033997124678491364,-0.030012915911228788
435.80000000000564,49.64763525069913,0.0325668613266461,-0.03127982499212667
437.2000000000056,49.78520141131254,0.032447824212817444,-0.03129967075906137
438.60000000000565,49.923011599042766,0.030884614762873186,-0.029963063064625484
440.0000000000057,50.06044322649249,0.029873677488582606,-0.029935506516745036
441.40000000000566,50.197756276083744,0.029319150945262606,-0.030619825419960556
442.8000000000057,50.33466000357071,0.02860760153954911,-0.03061982499951066
444.20000000000573,50.47273691945348,0.02967874534239856,-0.030582273849316444
445.60000000000576,50.610069094477886,0.030098635134806706,-0.03161038424760587
447.0000000000058,50.74801496469277,0.026615873190896755,-0.030300165549153046
448.4000000000058,50.885086573384896,0.029032639175035735,-0.031290428825279104
449.8000000000058,51.02364797522087,0.028681696719236927,-0.03162029806823963
451.20000000000584,51.16148145358396,0.028495997866839096,-0.03162011207335036
452.6000000000058,51.29990578972918,0.03033997932474941,-0.03128459477149903
454.00000000000585,51.43846998420783,0.03002226999982116,-0.032609411682398726
455.4000000000059,51.57684524197505,0.0275236844077007,-0.031286184936105244
456.8000000000059,51.71560066682838,0.02645244883923592,-0.030840615646199776
458.20000000000596,51.853875525324916,0.025385631949460752,-0.030220068599496663
459.60000000000593,51.992240450262095,0.023345387365728554,-0.031620008000496025
461.00000000000597,52.1306991189822,0.022282537967436067,-0.03162000799999776
462.400000000006,52.26743894703012,0.02229829401546879,-0.03162000799915221
463.800000000006,52.40655213251914,0.020279520330285905,-0.03151892131946399
465.200000000006,52.54559115079372,0.021660008980730616,-0.03299335795384151
466.60000000000605,52.683796313003256,0.022017246707559446,-0.03194988612679239
468.0000000000061,52.820861424105324,0.021476911789741315,-0.03194989999999942
469.4000000000061,52.95907181857754,0.02473983486128417,-0.03194989999999942
470.8000000000061,53.09759093905894,0.028578259664476358,-0.03194989336789211
472.2000000000061,53.23566192333411,0.028208096267239968,-0.032599710883116195
473.60000000000616,53.37355787415235,0.02804135039200162,-0.033259770202456185
475.00000000000614,53.51196090501742,0.030191950008916058,-0.03196017045000721
476.4000000000062,53.64926109802,0.026835680587057986,-0.03193981705559157
477.8000000000062,53.79002165913335,0.030044492081195973,-0.03293015242741548
479.20000000000624,53.92726899551963,0.03281480013763871,-0.032929983517947736
480.6000000000063,54.066438074815615,0.03323759398974491,-0.03386572945631672
482.00000000000625,54.20506136668323,0.03478495845157559,-0.03084724129847105
483.4000000000063,54.34378080671122,0.03649045093986891,-0.03315005818361172
484.8000000000063,54.4832197618716,0.034790624554538185,-0.034457161033122574
486.2000000000063,54.621812452931074,0.03706974076652636,-0.034469225023620265
487.60000000000633,54.75996382312583,0.034201259851114774,-0.03316007589078085
489.00000000000637,54.89826052851973,0.031910177975462695,-0.034151186288350566
490.4000000000064,55.03552599612794,0.028770807273019283,-0.03413989001463502
491.80000000000643,55.17486185905673,0.030780201538618268,-0.03413641912258347
493.2000000000064,55.31288341055892,0.029449702762426533,-0.03579170193226844
494.60000000000645,55.45234853331325,0.028055808419964245,-0.03579017447951216
496.0000000000065,55.590915567940634,0.027695665894892585,-0.037102830619441196
497.40000000000646,55.728791098316606,0.025799599692695185,-0.03711004597995338
498.8000000000065,55.86889714453192,0.022660629546627842,-0.03841685289014718
500.2000000000065,56.0072273082581,0.02010760259360289,-0.037109937892110256
501.60000000000656,56.146978905060934,0.01833760541490692,-0.03685314161183584
503.0000000000066,56.288094715120906,0.018039260655323908,-0.03612042444618835
504.40000000000657,56.42701067290971,0.01991989709604791,-0.03676700485677742
505.8000000000066,56.56407105213555,0.020903540555481825,-0.039198150365939544
507.20000000000664,56.705987612464924,0.021693003464108962,-0.03786998249445794
508.6000000000066,56.845845447502796,0.018744496155410406,-0.03885995135379483
510.00000000000665,56.98269429444641,0.019458427173467907,-0.04015596846442904
511.4000000000067,57.124420206342876,0.016851861176434113,-0.03885981443524322
512.8000000000068,57.26317988053255,0.01540010720151086,-0.04017962549033971
514.2000000000068,57.40281624357661,0.015541552453622653,-0.03985016027664168
515.6000000000067,57.542079955765786,0.01269337041296037,-0.04116998221403101
517.0000000000068,57.68157142749079,0.011330108365015246,-0.039850067105982934
518.4000000000068,57.82058613983976,0.013075767882320566,-0.04182300349436607
519.8000000000068,57.95886701071023,0.007537187566143633,-0.04115997124603288
521.2000000000069,58.09849004630271,0.012182520474788738,-0.04116315296340867
522.6000000000068,58.237509493721205,0.012126755454537452,-0.04052266747148625
524.0000000000068,58.37521311788024,0.006911876359367408,-0.04116944076512663
525.4000000000069,58.51594817089428,0.004461513511444082,-0.041170819299419126
526.8000000000069,58.65600452512018,0.002510586683616811,-0.04348413307882515
528.2000000000069,58.79499910721916,0.0033834414099418453,-0.04347007921067414
529.600000000007,58.93399692971078,0.005296526736214169,-0.043140105122530414
531.0000000000069,59.07339051088489,0.007712625953064212,-0.043140165845382494
532.4000000000069,59.21460141002617,0.011707287981077563,-0.044357862545651106
533.800000000007,59.354153899425725,0.011499072144450118,-0.044618589250745355
535.2000000000071,59.49237553752577,0.014843258143745874,-0.04577988418362855
536.6000000000071,59.63538813652935,0.01425369929125253,-0.04578267095745181
538.000000000007,59.77506249445149,0.014923665250136775,-0.04578014631868088
539.4000000000071,59.91532960376649,0.011913500044502534,-0.04525087058344557
540.8000000000071,60.054964966469534,0.011558358084166276,-0.04711139670335074
542.2000000000071,60.194491437547086,0.013003048695948927,-0.04772921635866112
543.6000000000072,60.33466215360734,0.013601260600818232,-0.04906909783074376
545.0000000000072,60.47382472670757,0.009993748978357253,-0.048411838138573415
546.4000000000071,60.61512422071302,0.009115685705460841,-0.04973016454786139
547.8000000000072,60.75432453754154,0.01034250851887819,-0.0500583687784073
549.2000000000072,60.89609843952519,0.008137466888433309,-0.05006008231741399
550.6000000000072,61.0360868692744,0.014345244200558493,-0.05138505223868117
552.0000000000073,61.17597230069239,0.01187439261731571,-0.05269986643917601
553.4000000000073,61.317125406788975,0.011432156378729186,-0.052369672204309214
554.8000000000073,61.45755917086036,0.013454215804996394,-0.052367504762795836
556.2000000000073,61.59530764541758,0.013782083277166013,-0.054661557221836965
557.6000000000073,61.73754494837748,0.012951432817803976,-0.05366349279107485
559.0000000000074,61.87829035032527,0.011527083942751037,-0.055005120543693664
560.4000000000074,62.019463578938925,0.012667736510787453,-0.05631997915185005
561.8000000000075,62.15977941567144,0.015379402642551554,-0.05664988132099724
563.2000000000074,62.299072262333084,0.01596557712486968,-0.05560145953603479
564.6000000000074,62.439573546303166,0.01698668189303021,-0.05698014906705451
566.0000000000075,62.57814610285407,0.016066900522365035,-0.05828975542637149
567.4000000000075,62.72058155357501,0.015629075554086658,-0.05830156331991887
568.8000000000075,62.86089817371841,0.014259053644495534,-0.060929728690926055
570.2000000000075,63.002244624317164,0.01814351002190895,-0.060929930760050155
571.6000000000075,63.14258974984539,0.018134322323625884,-0.06231720039177446
573.0000000000075,63.2831684481065,0.01740121398513983,-0.06159014274127195
574.4000000000076,63.42429251967344,0.02222034134856088,-0.06288931842790824
575.8000000000076,63.56440211426548,0.023170883460694736,-0.062258483443187185
577.2000000000077,63.70516436089384,0.02350111822235812,-0.06452205362132757
578.6000000000076,63.84684165885567,0.023757546916116645,-0.06521471085876707
580.0000000000076,63.98746788269123,0.021023576433502722,-0.06613163484679507
581.4000000000077,64.12822391251501,0.0219212338441932,-0.06883132658441626
582.8000000000077,64.26955587822646,0.019233964172910678,-0.06882995818360715
584.2000000000078,64.41040728268281,0.019100583291526085,-0.06783889043287017
585.6000000000078,64.55122081313834,0.01913205984636157,-0.06916032991892118
587.0000000000077,64.69202370385207,0.014626897325314747,-0.07014125830077145
588.4000000000078,64.83170569513295,0.011433059997790984,-0.07146004697376718
589.8000000000078,64.97370388511415,0.012870627113324318,-0.07147332949661145
591.2000000000078,65.1153530753932,0.014239046448580428,-0.07390865855209139
592.6000000000079,65.25590672637803,0.01643125427455505,-0.0747590781737113
594.0000000000078,65.3971837368648,0.011374099448794528,-0.07475995531861956
595.4000000000078,65.5386061093738,0.014066695993626865,-0.07541800340408811
596.8000000000079,65.67917099035353,0.01120138360629186,-0.07772993074321422
598.2000000000079,65.81809202195842,0.007798081432527582,-0.07670350959972572
599.600000000008,65.96108995104841,0.004602782984408638,-0.07806884944603354
601.000000000008,66.10038468995194,0.0036761802473508354,-0.08002237709640925
602.4000000000079,66.24129288279693,0.004049713670056576,-0.08036587339616963
603.800000000008,66.38467257380447,0.006156864548872765,-0.08072134292345012
605.200000000008,66.52481962781606,0.005017003504998119,-0.08309619647076705
606.6000000000081,66.66681625605386,0.00439306348046653,-0.08310314366836691
608.0000000000081,66.80771340251263,0.003572510603920165,-0.08630917791706905
609.400000000008,66.94959415443878,0.0011644632183278603,-0.08628991093893301
610.8000000000081,67.0904407761164,0.0029901420027855785,-0.08760277529996019
612.2000000000081,67.2325846408427,0.0038054827918614365,-0.08851271398278238
613.6000000000081,67.37428769421372,0.0024412160788012116,-0.08892936584380706
615.0000000000082,67.51449258599803,0.007966089712986069,-0.09022639733991777
616.4000000000082,67.65623809212134,0.00871483903384096,-0.09293583083163481
617.8000000000081,67.79760505859953,0.01786725412090373,-0.09418954835181959
619.2000000000082,67.94040563502934,0.018245179434268177,-0.09418921729121799
620.6000000000082,68.08097437137303,0.019276701863325307,-0.09551025229265031
622.0000000000083,68.22259110434713,0.02328336023664601,-0.09617818049761429
623.4000000000083,68.36387537025186,0.022193389006608832,-0.09682948785274359
624.8000000000083,68.50550497184389,0.02521319311318093,-0.09814936275571906
626.2000000000083,68.647310117046,0.02896957328138594,-0.1007838565582464
627.6000000000083,68.7883981830142,0.03781341926128068,-0.10210002756936998
629.0000000000084,68.9300703533152,0.03801356392812272,-0.10473146893925955
630.4000000000084,69.0713431590698,0.043125140819606056,-0.104725442002227
631.8000000000084,69.21283628949477,0.04922675946366084,-0.10958338991849592
633.2000000000085,69.35362764783042,0.0554164636027803,-0.10878515400210409
634.6000000000084,69.49571203647137,0.06304246899660404,-0.10971916005251625
636.0000000000084,69.63743588563118,0.07103284718243286,-0.11198117539217911
637.4000000000085,69.77947914099097,0.0793511858073499,-0.11592552712150272
638.8000000000085,69.92106219611867,0.0892603564833605,-0.11592996573916103
640.2000000000085,70.06318254327086,0.09319026105511297,-0.11891996710335828
641.6000000000085,70.20600450292781,0.09623720908065003,-0.12152985560204188
643.0000000000085,70.34801242959364,0.10613906197065415,-0.12393182372068168
644.4000000000086,70.49031323598837,0.11654007915875875,-0.12548447934824658
645.8000000000086,70.63192552059796,0.1180620964589929,-0.12811216190472363
647.2000000000086,70.77434285814832,0.12792578522113418,-0.12943707522590397
648.6000000000087,70.91542746278347,0.1338121001258341,-0.1333704634304267
650.0000000000086,71.0569649420453,0.1390318109691555,-0.1348394317482775
651.4000000000087,71.20059912531836,0.14662083486732191,-0.138945638931955
652.8000000000087,71.34175652402384,0.159167240198399,-0.14055483837708893
654.2000000000087,71.48389207290425,0.1691444372490034,-0.1445965495911823
655.6000000000088,71.6257148069021,0.17813659427375805,-0.14689501284931605
657.0000000000088,71.76764636644056,0.19102576022161344,-0.15005403282764762
658.4000000000087,71.90746304267955,0.19765269065842306,-0.15411144625314677
659.8000000000088,72.05161802275491,0.21488724324323938,-0.15791092966454867
661.2000000000088,72.19335973271947,0.22671758538876485,-0.1606748786900889
662.6000000000088,72.33662979940078,0.24133470278999924,-0.16423079867588974
664.0000000000089,72.47678240863513,0.25172685289569774,-0.16851102083817793
665.4000000000088,72.62208177681703,0.26900853596940344,-0.17277051340382465
666.8000000000089,72.76335966909693,0.28408639262863344,-0.17687882697885726
668.2000000000089,72.90643440619739,0.2985743283075766,-0.18061100644094807
669.6000000000089,73.0483565446196,0.31310921105571143,-0.18601718981144222
671.000000000009,73.19127631409187,0.3332715017018244,-0.18951946682941845
672.400000000009,73.333656291878,0.3501118927209639,-0.19383307817939954
673.800000000009,73.47641698662999,0.36920428758991397,-0.20062476561808396
675.200000000009,73.61789719655367,0.3826315110887508,-0.20561799926859248
676.600000000009,73.76146219232412,0.4056772065576921,-0.2114931496857717
678.0000000000091,73.9041038209436,0.42719349226750447,-0.21865997555804073
679.4000000000091,74.04606573786334,0.4484852566660251,-0.22487605634676333
680.800000000009,74.18884856459698,0.4762082719494134,-0.2297679946284661
682.2000000000091,74.33284480370067,0.4990890391042351,-0.23637173311037074
683.6000000000091,74.47618023989044,0.5229340270793541,-0.24372876697824886
685.0000000000091,74.61795134432442,0.5518122612651966,-0.25160188173308295
686.4000000000092,74.76036924401126,0.5788559256296977,-0.25712473462558894
687.8000000000092,74.90527610719433,0.6077433889865809,-0.2640539459002538
689.2000000000093,75.04938060673373,0.6363935177703639,-0.27348596075672305
690.6000000000092,75.19231879154104,0.6705166959366697,-0.28183136435400025
692.0000000000092,75.33586341518661,0.7001009553040154,-0.29033531100473997
693.4000000000093,75.47806652792877,0.7361023831170379,-0.29877909200088926
694.8000000000093,75.62163124287721,0.7671715419543585,-0.3088205228158083
696.2000000000094,75.76431816664787,0.8035932650965583,-0.31846706905823075
697.6000000000093,75.90835034838182,0.8417655151031522,-0.32661058132199017
699.0000000000093,76.05233247392488,0.8842225602708331,-0.33811117103822363
700.4000000000094,76.19585425075844,0.9259771737923308,-0.35003309747358546
701.8000000000094,76.33917099736672,0.965489597676243,-0.36195989127537054
703.2000000000094,76.48304133791585,1.0136257561205073,-0.37306347808414353
704.6000000000095,76.6263597991506,1.0604987468702944,-0.38491012345936904
706.0000000000094,76.77038027520334,1.1137243484535273,-0.3971261918236939
707.4000000000094,76.91412122587337,1.15969030684598,-0.41125031198210893
708.8000000000095,77.05631848227617,1.2133140886000224,-0.42455070103371195
710.2000000000095,77.20190041143749,1.2682031066701853,-0.43856562370097496
711.6000000000096,77.34548604226505,1.320282677612536,-0.45411978743101056
713.0000000000095,77.48927169711033,1.3797334057892838,-0.46922279770535047
714.4000000000095,77.63449302027877,1.4408933869688583,-0.4863992555819272
715.8000000000096,77.77868150410008,1.5014970760217268,-0.5000174456621247
717.2000000000096,77.92299664012585,1.5584630100051058,-0.5189262844969913
718.6000000000097,78.06648875377309,1.6191152972319482,-0.5357731919446738
720.0000000000097,78.21136323976116,1.6840597050821384,-0.5538310212892261
721.4000000000096,78.35548318964919,1.7483725743393332,-0.5710576585554277
722.8000000000097,78.49824260187285,1.8155219264265012,-0.5910920189209321
724.2000000000097,78.64313291239903,1.8793044229348346,-0.6114029026723844
725.6000000000097,78.78711959738632,1.947957134284521,-0.6321779298928996
727.0000000000098,78.93050508103386,2.0201741553632435,-0.6542086177761286
728.4000000000098,79.07586077205181,2.0881756294966745,-0.6757334832305251
729.8000000000097,79.2200249407485,2.15892897109129,-0.6999503116491548
731.2000000000098,79.36420510756746,2.2297360634062127,-0.7220190619149789
732.6000000000098,79.50854090963492,2.304176368947034,-0.747837215220394
734.0000000000099,79.65276270553346,2.3687605573979127,-0.7713357757101238
735.4000000000099,79.79807035034011,2.437821927951232,-0.7951979537376634
736.8000000000098,79.94234777609891,2.5008825406202098,-0.8227547464225302
738.2000000000099,80.08651893483449,2.565356755292442,-0.8477799891703128
739.6000000000099,80.23096748396316,2.6169954897550323,-0.8750016853021569
741.00000000001,80.37505163201654,2.6627595000268407,-0.9013468499959423
742.40000000001,80.51858313629731,2.704900972593888,-0.9305611533345712
743.80000000001,80.66286752255935,2.732577229369471,-0.960418416612765
745.20000000001,80.80537502490407,2.7516103348404575,-0.98745345473036
746.60000000001,80.94770211276976,2.7608618747032767,-1.0157342728527095
748.00000000001,81.09069252997556,2.746223964427261,-1.0446236992811064
749.4000000000101,81.23039663840146,2.7113138778110697,-1.071208668107897
750.8000000000101,81.37330814773546,2.6545797071400923,-1.0987727469863855
752.20000000001,81.51459509644653,2.57770505010281,-1.1272406900786858
753.6000000000101,81.65405545449305,2.4683246755525032,-1.1524474897550898
755.0000000000101,81.79440832542218,2.315661089979593,-1.1786580553490342
756.4000000000102,81.93204777044241,2.124254104034155,-1.1997724938119219
757.8000000000102,82.06655951567757,1.8844212292221076,-1.221168921896671
759.2000000000102,82.20306002449516,1.5709247366435117,-1.239745580721391
760.6000000000103,82.33436816323416,1.1821857095460464,-1.255957490716637
762.0000000000102,82.46541696553551,0.7265511727068921,-1.2682976446942331
763.4000000000103,82.5977533482185,0.27221504050240863,-1.2760135109367123
764.8000000000103,82.73176522889497,-0.05683598720014027,-1.2788709271360466
766.2000000000103,82.86947606696391,-0.24699503827027414,-1.281389644827855
767.6000000000104,83.01004159452665,-0.32157946952588645,-1.283370737644272
769.0000000000103,83.15266922007882,-0.3482413462149445,-1.2827100920759005
770.4000000000103,83.29429805226303,-0.3578761987201533,-1.2840202378477548
771.8000000000104,83.43715722585348,-0.3654601613411863,-1.2840200034689038
773.2000000000104,83.57701152476801,-0.3745247418918849,-1.2853744971636565
774.6000000000104,83.72211305607334,-0.37908285513194295,-1.2840198970029966
776.0000000000105,83.86596566486865,-0.3798338086165596,-1.2841508921696088
777.4000000000104,84.0091679219986,-0.3823684909543599,-1.284811075423569
778.8000000000105,84.15158443600441,-0.37749125797154326,-1.2853471372894365
780.2000000000105,84.29466148437153,-0.3740733465133248,-1.2853489010222705
781.6000000000105,84.4382056188815,-0.38039140682850947,-1.2852188304488523
783.0000000000106,84.58074334886633,-0.37825548081452354,-1.2853400067078113
784.4000000000106,84.7247020200427,-0.37829833566142135,-1.28632995727197
785.8000000000106,84.86766678818708,-0.3798997567398237,-1.285011227528822
787.2000000000106,85.01129307927201,-0.37916811227708536,-1.2850067965926568
788.6000000000106,85.15408037172757,-0.3867666969004242,-1.2846799256745465
790.0000000000107,85.29840807762693,-0.3855032040476343,-1.284679916102431
791.4000000000107,85.44174422937006,-0.3880948416271228,-1.285012719918452
792.8000000000106,85.58589075350835,-0.3936170215429806,-1.2867751131991532
794.2000000000107,85.72873391737716,-0.3963224951409874,-1.285999809845579
795.6000000000107,85.87290283732308,-0.3991947738067214,-1.287097983329918
797.0000000000107,86.01568487737241,-0.40341093320149035,-1.2863300392613204
798.4000000000108,86.1607496461526,-0.4042008223142015,-1.286323646565307
799.8000000000108,86.30156572930943,-0.4049517047685707,-1.287468067405698
801.2000000000108,86.44574374917784,-0.41009412335880846,-1.2863295258575045
802.6000000000108,86.58824588398319,-0.4164637249633767,-1.2876498808695005
804.0000000000108,86.7323452015126,-0.4167584106384852,-1.2876498796843294
805.4000000000109,86.87457122713978,-0.42263847279792577,-1.2883102523826224
806.8000000000109,87.01811696843725,-0.4203851501579732,-1.287650879721551
808.200000000011,87.16029697594755,-0.42439090292012827,-1.2889600892164599
809.6000000000109,87.3035543996921,-0.4243403783517605,-1.2883097617139394
811.0000000000109,87.44637479794827,-0.42725163474492334,-1.2886122246912124
812.400000000011,87.59024194920649,-0.43244234878846477,-1.288630032175559
813.800000000011,87.73334513087562,-0.43482317376459445,-1.2912579316616135
815.200000000011,87.8759031026514,-0.4335617453380345,-1.2899367304441665
816.600000000011,88.01937462943093,-0.43235301678936144,-1.2912698218283825
818.000000000011,88.16212935351875,-0.42611153799430035,-1.2912698194362675
819.400000000011,88.30425033048188,-0.4257835153634826,-1.2926288937832546
820.8000000000111,88.44852439758523,-0.42744430116881427,-1.2912800161532894
822.2000000000111,88.5920060682039,-0.43122524687290964,-1.2912704444812269
823.6000000000112,88.73528826321666,-0.42953438429447166,-1.2921021940375987
825.0000000000111,88.8788543883051,-0.43612230964723775,-1.2939783977745831
826.4000000000111,89.02328193818094,-0.4295481293624617,-1.2919299471594545
827.8000000000112,89.16663453299742,-0.4295814223497487,-1.2920806843903052
829.2000000000112,89.31010689783099,-0.42342443476310354,-1.2919298235557775
830.6000000000113,89.45396880430252,-0.4251607143092291,-1.2932389811801182
832.0000000000113,89.59898597004693,-0.4262140285639928,-1.29321380161492
833.4000000000112,89.74325097799994,-0.4238935992524211,-1.2938968394421813
834.8000000000113,89.88649629602234,-0.429209126111858,-1.2939000752525365
836.2000000000113,90.03014476387635,-0.4422671021864826,-1.292573258091005
837.6000000000113,90.17322411571301,-0.4394353366666315,-1.293900046552063
839.0000000000114,90.31607410028117,-0.4486638334769917,-1.2952227520482889
840.4000000000113,90.45982703765443,-0.45048470317508693,-1.2945698566848645
841.8000000000113,90.60373019083164,-0.45069095296316863,-1.294569655047412
843.2000000000114,90.74726943638566,-0.45090982519572353,-1.2952189073791884
844.6000000000114,90.89107186256554,-0.4508388497409572,-1.2965386762729159
846.0000000000115,91.03480433098167,-0.4532040786264,-1.2956250078626752
847.4000000000115,91.17799828607004,-0.4523657992511363,-1.2965408826731681
848.8000000000114,91.32035016499731,-0.4516461030630423,-1.2965394998811255
850.2000000000115,91.46392156716348,-0.45401930741533825,-1.2965380183633788
851.6000000000115,91.6097283924986,-0.4577882803435518,-1.2962053305910728
853.0000000000116,91.75204529940632,-0.46244171011929636,-1.2975332376778135
854.4000000000116,91.89608544896087,-0.4626530303539842,-1.2979001465302655
855.8000000000116,92.03985411275389,-0.47164432997725214,-1.2977469710479426
857.2000000000116,92.1842327147274,-0.47124387980536353,-1.2967963916282321
858.6000000000116,92.32693984938145,-0.47279004239406675,-1.2975199433485267
860.0000000000116,92.47138097678479,-0.4728633207309212,-1.2975215250097345
861.4000000000117,92.61279024815548,-0.4784798009838229,-1.2988400169856984
862.8000000000117,92.75874599186724,-0.48064407339633997,-1.298697096183763
864.2000000000116,92.90279930576395,-0.47523908660116243,-1.2985206264859035
865.6000000000117,93.04649852348946,-0.4823605104544759,-1.3008549853581028
867.0000000000117,93.19067093630011,-0.4804438482171487,-1.301460087124136
868.4000000000118,93.3345853635056,-0.4867015915924475,-1.3008256263827755
869.8000000000118,93.47708572453251,-0.4943639411262435,-1.2994209406216628
871.2000000000118,93.62104283129594,-0.49120305796451014,-1.3021332962702115
872.6000000000118,93.7644516587854,-0.49815897084643135,-1.3008199949944856
874.0000000000118,93.90774131987172,-0.5018506724006797,-1.3008199950000048
875.4000000000119,94.05239259713018,-0.5088906523453001,-1.300818508459419
876.8000000000119,94.1938033147891,-0.5113852367468952,-1.3008712617556921
878.2000000000119,94.33945209245104,-0.5194839397704896,-1.30081988703999
879.600000000012,94.48264136340264,-0.5217288196655621,-1.3021402839612843
881.0000000000119,94.62646426798449,-0.5236785181289485,-1.3008597382801756
882.4000000000119,94.77011154020995,-0.5235836863956513,-1.300830269246454
883.800000000012,94.91529233851098,-0.5321387430763087,-1.3008164365972186
885.200000000012,95.05762963071285,-0.5418292372054703,-1.30181225619252
886.600000000012,95.20163458619034,-0.5377630977585075,-1.3034649646093732
888.000000000012,95.34461302698398,-0.5491381717972463,-1.3034599032974041
889.400000000012,95.48916798335398,-0.5501193389544672,-1.302139876243321
890.8000000000121,95.63269355237013,-0.5547320935947129,-1.303790170054949
892.2000000000121,95.7750263272978,-0.554756392975241,-1.3010404460241656
893.6000000000121,95.91937800967413,-0.5654613577584211,-1.3037801920089684
894.0000000000122,95.96130789906701,-0.5634625800126551,-1.303780116953504