File: 01_Data/Cinder_Block/STA/N2/10K_min/Cinder_Block_STA_N2_10KData_230919_R1.csv
##Temp./Â°C,Time/min,DSC/(mW/mg),Mass loss/mg
41.0,10.83745026356017,0.03578215827376052,-0.006660176938717122
42.40000000000002,11.177380591778975,0.06472115993305216,-0.007236526343389116
43.80000000000004,11.419503044232181,0.08631128626797979,-0.00593745648610966
45.20000000000006,11.624716531477643,0.10416331279479829,-0.005223117391666143
46.60000000000008,11.812515560214168,0.1131997277455743,-0.006148393529045393
48.0000000000001,11.9880246861559,0.12370215593459322,-0.005972957340769192
49.40000000000012,12.15625577479607,0.13017761512844594,-0.0071639977713431335
50.80000000000014,12.315490164188319,0.13798084260290655,-0.005795028311245787
52.20000000000016,12.4760598149492,0.14155162369725827,-0.007011175462161567
53.60000000000018,12.633173567542029,0.14899522563182055,-0.005581746313639613
55.0000000000002,12.788880846693695,0.1504832749226659,-0.008550011219098153
56.40000000000022,12.94237970936631,0.15419860658227358,-0.005760650439287751
57.80000000000024,13.092887967759642,0.15693542118145354,-0.006792628091954356
59.20000000000026,13.242871117530639,0.1605847554040185,-0.005921162867011276
60.60000000000028,13.393450067076852,0.16349725676818228,-0.007348235845631379
62.0000000000003,13.541871462540927,0.16618972202394344,-0.007251218935072856
63.40000000000032,13.688938964569374,0.168665918197747,-0.007126822969232727
64.80000000000034,13.836770856273345,0.17073103353804098,-0.008558123386459116
66.20000000000036,13.982292758563515,0.17285253985078275,-0.008699139447507775
67.60000000000038,14.127161369853843,0.1772391869015868,-0.009875695148786612
69.0000000000004,14.272175071274189,0.178967566184147,-0.011228258990105822
70.40000000000042,14.416268829511308,0.17900541779813373,-0.010516522658245542
71.80000000000044,14.55861007169656,0.18154632875506693,-0.008543594791214026
73.20000000000046,14.700414484934768,0.18493055567426886,-0.010502233241758141
74.60000000000048,14.842250286821733,0.18735858829137464,-0.009819734936577618
76.0000000000005,14.984799810349589,0.1869600190029852,-0.011189895896454694
77.40000000000052,15.124306207646121,0.18832555118718797,-0.011189596665048818
78.80000000000054,15.266172847376483,0.1885036777757918,-0.011199601538244508
80.20000000000056,15.406148043995564,0.19008743957394025,-0.013149932779742635
81.60000000000058,15.544975819337628,0.19246371412317043,-0.013139162475715338
83.0000000000006,15.686108185630564,0.19303126291475659,-0.010869407649062524
84.40000000000062,15.826302468085247,0.19498777176648163,-0.012527583728866531
85.80000000000064,15.965777317447998,0.194374504141281,-0.013719920919131212
87.20000000000066,16.104064621855084,0.19497305016513677,-0.01240511970913083
88.60000000000068,16.242783669956438,0.19485681196039173,-0.014376839418074105
90.0000000000007,16.382152507399773,0.1951917638329712,-0.015683411926074697
91.40000000000072,16.520266764964642,0.19651917615162895,-0.01569027716531668
92.80000000000074,16.657233904310267,0.19500896823936964,-0.015737333961599376
94.20000000000076,16.79500414380895,0.19419563707912801,-0.016021184085539986
95.60000000000078,16.93059612429409,0.19428755926396502,-0.017365738125218577
97.0000000000008,17.06821870228589,0.19660283814837332,-0.018650185361070548
98.40000000000082,17.20537438115751,0.1982041220149302,-0.018330840951799487
99.80000000000084,17.34227467920283,0.19455158130709638,-0.018329941627738933
101.20000000000086,17.478366894134,0.1968620758747286,-0.019650171435548813
102.60000000000088,17.61491086794141,0.1952490231288917,-0.0183451708194573
104.0000000000009,17.751169330480913,0.1987147897245103,-0.019650084389373212
105.40000000000092,17.887457568225738,0.19891444015418602,-0.01866029959808113
106.80000000000094,18.02219299254072,0.1961726378676596,-0.018528774655035996
108.20000000000095,18.158206074825003,0.19622164658725527,-0.0192897955112743
109.60000000000097,18.294616310887147,0.19715577762125647,-0.019648371978738588
111.000000000001,18.430166781682274,0.19702577152777478,-0.01915318560211965
112.40000000000101,18.56419948122864,0.19615962362555184,-0.020623433756840726
113.80000000000103,18.701819503779042,0.19565797489494452,-0.02250899329680678
115.20000000000105,18.835853056635177,0.1972378171585698,-0.021315799354431064
116.60000000000107,18.970958824238547,0.1954030951900183,-0.020937622179626025
118.0000000000011,19.106188846610188,0.19634179735363788,-0.022279831024601293
119.40000000000111,19.240697933572708,0.1959118539034037,-0.02227982718867061
120.80000000000113,19.37609212310688,0.19459605830369542,-0.022318953148622533
122.20000000000115,19.510435972199787,0.1958603130269747,-0.02326869112744312
123.60000000000117,19.645247392594,0.19678141396210735,-0.02393007177709361
125.0000000000012,19.778871705695497,0.19781518932419906,-0.024195674613863183
126.40000000000121,19.915170862963805,0.19618118888385316,-0.024250182984238755
127.80000000000123,20.0508162010287,0.19693255658438513,-0.023599685040080587
129.20000000000124,20.184820542888456,0.19662448833723278,-0.023920118464321405
130.60000000000127,20.31847792923916,0.1966862009928505,-0.02655456209072593
132.0000000000013,20.453239169466272,0.19716095849344395,-0.026900028149273503
133.4000000000013,20.586890214878892,0.19662917058780072,-0.026899796999878767
134.80000000000132,20.720125431138275,0.19545346559770738,-0.026899797000000447
136.20000000000135,20.854840815490007,0.19469805018785724,-0.026899796998868908
137.6000000000014,20.987246116487228,0.19198915641938163,-0.026932871359136357
139.0000000000014,21.12337808873591,0.19331845873303766,-0.027897463156375757
140.4000000000014,21.257466819094116,0.1941314209668521,-0.0265598202320545
141.80000000000143,21.39059617372817,0.19454248737120228,-0.025578230685384007
143.20000000000147,21.52634945599604,0.1924639882515291,-0.02687392768705088
144.60000000000147,21.660087158672507,0.19437749487898937,-0.026229995006230133
146.00000000000148,21.79326807600147,0.1949014487348868,-0.026199663807875417
147.4000000000015,21.926811404184896,0.19339643136808893,-0.0275427695304451
148.80000000000155,22.060863758980258,0.19555191012250228,-0.02863787944912133
150.20000000000155,22.194528018461657,0.19504862919325627,-0.02722001761330528
151.60000000000156,22.3285694459235,0.19279905057988334,-0.02852954746358982
153.0000000000016,22.462248900463823,0.192006673140666,-0.028530131564615147
154.40000000000163,22.595267934649982,0.19116603074154748,-0.029850013114939955
155.80000000000163,22.728896525587896,0.19324454485942089,-0.0288934581110043
157.20000000000164,22.862449443485087,0.19154606769705684,-0.028539869787848282
158.60000000000167,22.995939918761962,0.19427540868883897,-0.029529619727628464
160.0000000000017,23.129832022731847,0.19252484651793833,-0.029859883634133944
161.4000000000017,23.262859432670993,0.19071164139427,-0.030606986345491194
162.80000000000172,23.39586061804907,0.19373195987636072,-0.029529999084572545
164.20000000000175,23.530588981107847,0.19384920544907014,-0.029859993073818814
165.60000000000178,23.663880795966957,0.19245505223248371,-0.03039714989268294
167.0000000000018,23.797437916782833,0.19312047248140174,-0.03084372786140399
168.4000000000018,23.93098267391678,0.1931834024050667,-0.031170080503623687
169.80000000000183,24.06406676423127,0.1932030879104376,-0.030840080598097508
171.20000000000186,24.198110003315875,0.1933567367786344,-0.030840081999984115
172.60000000000187,24.331717116673975,0.19053729219402338,-0.030840801024790032
174.00000000000188,24.46612801201667,0.19550150587901416,-0.030658716691462473
175.4000000000019,24.599452500012145,0.1931203510810675,-0.032600961213538504
176.80000000000194,24.73241716145559,0.19286071704711905,-0.03250116945974213
178.20000000000195,24.866014457134817,0.1937510677871439,-0.031509531779498445
179.60000000000196,24.99869058458294,0.19235769995698737,-0.03183244894017001
181.000000000002,25.13250386243933,0.19513318089748943,-0.03184012500183009
182.40000000000202,25.26399845954692,0.19307191324499495,-0.03179002001655373
183.80000000000203,25.398645501222028,0.1913679676002309,-0.0331777678246592
185.20000000000203,25.53123723724805,0.1927252869069236,-0.0327504519752031
186.60000000000207,25.6653927021193,0.1941657686338798,-0.032819512015361596
188.0000000000021,25.799073836618685,0.19272037336983217,-0.034140048011259694
189.4000000000021,25.931981614771523,0.19467082446372608,-0.03282062692122256
190.80000000000211,26.065622519866803,0.1937389896371402,-0.03153765015258703
192.20000000000215,26.1990776756957,0.19372864900432818,-0.030510715129459243
193.60000000000218,26.331547405636382,0.19416353440364365,-0.03315017069942705
195.0000000000022,26.463170209574855,0.1924446273152749,-0.03190866881076815
196.4000000000022,26.59765437348527,0.1942415425372599,-0.03246610230311919
197.80000000000223,26.730478991523768,0.19403677959340637,-0.031169839030876112
199.20000000000226,26.864211262813217,0.18977277785963786,-0.03246612718509745
200.60000000000227,26.99596672738282,0.19299749308650793,-0.03248983900042912
202.00000000000227,27.129270999011766,0.1908291713974133,-0.03248983899999924
203.4000000000023,27.25967866399483,0.1924313339161423,-0.032489839029838485
204.80000000000234,27.395210103506706,0.1907067582051445,-0.033204046345812976
206.20000000000235,27.52806051624295,0.19282300657276874,-0.032919333952306395
207.60000000000235,27.66123615153899,0.19341333909454095,-0.03381010888424907
209.0000000000024,27.794520228684856,0.19216543534862707,-0.03380995071232018
210.40000000000242,27.928024422718124,0.19368603725067657,-0.034470102337746944
211.80000000000243,28.059936640739235,0.18992829068841366,-0.03418300775600969
213.20000000000243,28.19247695763195,0.19295272664321117,-0.03587008574180306
214.60000000000247,28.326224339139866,0.18977493001817414,-0.03450823759650312
216.0000000000025,28.45890365656966,0.1929543277821757,-0.03380981148487994
217.4000000000025,28.59232341486499,0.19092415526969364,-0.035123999583393406
218.8000000000025,28.72423003569791,0.1904818858380315,-0.03446466919460622
220.20000000000255,28.85578617275042,0.18977699872156473,-0.034469805313032786
221.60000000000258,28.991387770770018,0.1891539901340904,-0.035787134428919565
223.0000000000026,29.124230500214534,0.18985969694218507,-0.03477436673225931
224.4000000000026,29.256673839439493,0.19144056243137397,-0.0334799032187556
225.80000000000263,29.389642118867062,0.19056823728342054,-0.034800675080441934
227.20000000000266,29.52291691218465,0.1917727588960212,-0.033479207876827566
228.60000000000267,29.656374294074773,0.19067348677683005,-0.03446954411490921
230.00000000000267,29.788524804135076,0.19131401698643402,-0.03447022895639318
231.4000000000027,29.92294221849451,0.19046296003598817,-0.03446982699998635
232.80000000000274,30.05594001576179,0.19140100381942649,-0.03446982699999879
234.20000000000275,30.18757502115166,0.1917464565164606,-0.03446982699729961
235.60000000000275,30.321625970891393,0.19031292329661342,-0.034939021521847025
237.00000000000279,30.45528337029813,0.18911048078402093,-0.0347586498290573
238.40000000000282,30.587890253957493,0.19120430852693837,-0.03611000420569077
239.80000000000283,30.720309748611367,0.18829142636021823,-0.03545217170505399
241.20000000000283,30.851517360132867,0.18822991477326512,-0.036223275671976474
242.60000000000286,30.984238996206415,0.18788233265006138,-0.0341303924473193
244.0000000000029,31.118681381165786,0.18742349240931966,-0.035117775426959597
245.4000000000029,31.252396158066738,0.1847272412647376,-0.03511984900004883
246.8000000000029,31.385175860240675,0.1871597832179146,-0.03511984899243892
248.20000000000294,31.51802612722486,0.18688617241184047,-0.03570239690883348
249.60000000000298,31.65176199703331,0.1868727408765627,-0.03611012560773297
251.00000000000298,31.784961504127796,0.18440987794904995,-0.035448454065378776
252.400000000003,31.91712842518855,0.18539896069922923,-0.035236507364777125
253.80000000000302,32.05095816472477,0.1845050202417926,-0.03545994700307542
255.20000000000306,32.183550363262185,0.18272605135872433,-0.03545994700000055
256.6000000000031,32.31749872109023,0.18297399499185918,-0.03545991769333767
258.00000000000307,32.451010172651486,0.18388216625141096,-0.036440037642731404
259.4000000000031,32.584620919549224,0.18201789328701934,-0.035561763169574157
260.80000000000314,32.7171407084444,0.18196440417184268,-0.036119870158485945
262.2000000000031,32.85044976537018,0.18200599789259164,-0.0361209370638802
263.60000000000315,32.98445127048319,0.18130751656215827,-0.034799598676201526
265.0000000000032,33.117078694350646,0.17875117179706623,-0.03611987073738199
266.4000000000032,33.25033195995511,0.18169767146896554,-0.036119870138178634
267.80000000000325,33.383718185022836,0.18125864667988356,-0.03579064052303238
269.20000000000323,33.51655560451791,0.1809093539501967,-0.03710266092742476
270.60000000000326,33.6507833960714,0.18033627806275332,-0.035789869696672305
272.0000000000033,33.78432798895992,0.18075702585501952,-0.03578987000000122
273.4000000000033,33.91766547443287,0.17963499779356762,-0.03578987000000122
274.8000000000033,34.051730870430816,0.18078344166911475,-0.03578994375056954
276.20000000000334,34.185361016315746,0.18072602492800582,-0.03841159737064004
277.6000000000034,34.31916909062514,0.18017569132829814,-0.035789883970009484
279.0000000000034,34.45365053893374,0.17887525029580664,-0.03710988627487222
280.4000000000034,34.58829772010373,0.17758266877591544,-0.03710986832299756
281.8000000000034,34.7210861150621,0.17863831732575286,-0.03775938547259816
283.20000000000346,34.854373175930604,0.17892808346792144,-0.03808986388848634
284.60000000000343,34.98821332763262,0.17934405711168866,-0.03677997203576311
286.00000000000347,35.12070777566259,0.1795588249097717,-0.036779870002966675
287.4000000000035,35.25485770403527,0.17841385173017588,-0.03545228395510769
288.80000000000354,35.387523425667,0.17702569730014805,-0.036707645161290436
290.20000000000357,35.521949196595024,0.17795440641872062,-0.0366099658957495
291.60000000000355,35.6557558761281,0.1766573917422467,-0.0361201230174899
293.0000000000036,35.78990964807877,0.17741992379966676,-0.03744822714218632
294.4000000000036,35.924629006749065,0.17609568605997827,-0.03742984899812374
295.8000000000036,36.05772116716989,0.1798107138419549,-0.03742997471770071
297.2000000000036,36.19223652599823,0.1757754196345911,-0.03871552650859211
298.60000000000366,36.32582304229153,0.17551602986947845,-0.03814240046731321
300.0000000000037,36.459265178087236,0.17830684310372202,-0.03940029448828497
301.40000000000373,36.593591862598615,0.17926793299620836,-0.03808984941128468
302.8000000000037,36.727888777634114,0.17694051343820627,-0.03810079270556166
304.20000000000374,36.86301521417311,0.1776593215786011,-0.0374389179018495
305.6000000000038,36.996451887447904,0.1751059850873975,-0.038772480322712966
307.00000000000375,37.13132723629297,0.17927656687404925,-0.0399240486353305
308.4000000000038,37.26316076802906,0.18018451368463162,-0.03874987212966108
309.8000000000038,37.399833801315864,0.17953599668082076,-0.037439653472483236
311.20000000000385,37.5334358527241,0.181110229555701,-0.03873616671739111
312.6000000000039,37.66720009356428,0.1797684761574061,-0.037359704900406854
314.00000000000387,37.80134800502228,0.18117744323522467,-0.03841889018818545
315.4000000000039,37.936867379893826,0.18016471767222408,-0.040069746605976064
316.80000000000393,38.070772410634326,0.17962927422149777,-0.04018796321506635
318.2000000000039,38.20478953563464,0.17896524356712917,-0.04005994661631096
319.60000000000394,38.33935871538714,0.17964006060260518,-0.03744008371229235
321.000000000004,38.47405098934755,0.18215001844097012,-0.03861272279257921
322.400000000004,38.60872919625096,0.1804323901035889,-0.03733709458075207
323.80000000000405,38.74229080392454,0.1801943774441368,-0.03874999429607495
325.200000000004,38.876961092484784,0.17886205867664362,-0.04005952009164204
326.60000000000406,39.01280411056702,0.17932649666953226,-0.04006000299999801
328.0000000000041,39.14526574915698,0.178402751877343,-0.04006000463001236
329.40000000000407,39.281496478072775,0.1791099619969505,-0.04105010166269807
330.8000000000041,39.416357617782644,0.17708203683621715,-0.038434534936182096
332.20000000000414,39.552322284541575,0.17941779196113528,-0.03708586313287121
333.6000000000042,39.68656075342304,0.18179093611125574,-0.040120849977181905
335.0000000000042,39.82251791954286,0.18090498511239006,-0.04170740104567461
336.4000000000042,39.95586734041806,0.18323234986587877,-0.04072027759460628
337.8000000000042,40.09304848683542,0.18339389930706185,-0.04039008226879126
339.20000000000425,40.22882100122717,0.18334266502882968,-0.040390077261516666
340.60000000000423,40.36349747964702,0.18291054069698176,-0.03973001273505972
342.00000000000426,40.4985102716713,0.18541447943181177,-0.04105023745237801
343.4000000000043,40.63441997828116,0.1851597408734651,-0.0410500919826875
344.80000000000433,40.76848802519748,0.18365679973891202,-0.04035877998707882
346.20000000000437,40.90493862946371,0.18691053434370541,-0.041682957033743584
347.60000000000434,41.04167720575553,0.18408523659004872,-0.04138344894314372
349.0000000000044,41.17684078842991,0.18308154021311762,-0.04041795717175667
350.4000000000044,41.31157741070335,0.18381752594459733,-0.04270329220450986
351.8000000000044,41.44783804063148,0.18227335909164855,-0.04138016615724638
353.2000000000044,41.58292916898686,0.18477013454939573,-0.04138005800000144
354.60000000000446,41.718405573884795,0.18446940864048056,-0.04138005799966482
356.0000000000045,41.85523588695656,0.18240470871001713,-0.04129291454031492
357.4000000000045,41.98947808007041,0.18385668021189772,-0.04269981242648235
358.8000000000045,42.124840040708904,0.1849562646286409,-0.04270099570714869
360.20000000000454,42.26027707722758,0.18600478482697236,-0.04302912058120434
361.60000000000457,42.396501470114615,0.1833294043805067,-0.043027654263729787
363.00000000000455,42.53229522550598,0.1864126081593216,-0.044399153746929265
364.4000000000046,42.667418838111274,0.18553480732098016,-0.044193555173778876
365.8000000000046,42.803804308100744,0.183537619374732,-0.04302995897923445
367.20000000000465,42.93937351462707,0.18495855377377213,-0.04435413603005944
368.6000000000047,43.07609915203293,0.18537236015914815,-0.043030652527044744
370.00000000000466,43.21194336487439,0.18413877159556713,-0.04302664274510981
371.4000000000047,43.34797001891226,0.18666056058223446,-0.044680107558216164
372.80000000000473,43.484135496436906,0.18480298854695554,-0.04501012534744131
374.2000000000047,43.62081790819365,0.18512057991072983,-0.04501011158389456
375.60000000000474,43.75577670693497,0.18612797143599957,-0.046000788325430975
377.0000000000048,43.89266622476511,0.18662395442926671,-0.04407474050402449
378.4000000000048,44.03067117549816,0.18338529385880853,-0.04401009200072803
379.80000000000484,44.16621783150165,0.18464599280057592,-0.044010131435746835
381.2000000000048,44.30248984607499,0.18470811305061363,-0.042699990349632344
382.60000000000485,44.439169079987714,0.18438986516222133,-0.04171991692719157
384.0000000000049,44.575187813023874,0.18328487263760596,-0.04303007340990117
385.40000000000487,44.71212495202346,0.18245707365327113,-0.04401977833954618
386.8000000000049,44.84835459621218,0.18699944732129525,-0.044015039027170744
388.20000000000493,44.98340887787677,0.18332184701490895,-0.04402336446378108
389.60000000000497,45.12023836186283,0.18164275698646914,-0.04504501189283161
391.000000000005,45.259070179891424,0.182038639975723,-0.04598987738699556
392.400000000005,45.39569271720722,0.1821218197587402,-0.04599003702963156
393.800000000005,45.53255177161109,0.18202963309493514,-0.04598753313702897
395.20000000000505,45.66947077570742,0.18115783782590222,-0.04600003509685724
396.600000000005,45.80563705711895,0.18001657291045214,-0.0472470116789534
398.00000000000506,45.94208664583995,0.17950919989179903,-0.04862935100928745
399.4000000000051,46.079752704932346,0.18100693807612744,-0.04863678864785648
400.8000000000051,46.21597575425789,0.180002304452884,-0.046329979485352446
402.20000000000516,46.35135199409869,0.18167195018951943,-0.04533319829733262
403.60000000000514,46.49048273480672,0.18395204696241718,-0.047970287750422
405.0000000000052,46.62765041440767,0.18299987637214543,-0.0492251626409983
406.4000000000052,46.76459248553952,0.1872922466500122,-0.04797000499185078
407.8000000000052,46.89797276312899,0.1891509280199657,-0.04797028267077508
409.2000000000052,47.03684281396935,0.1888132534436453,-0.04665000558916965
410.60000000000525,47.17155010060331,0.18998873958129847,-0.046650010024706035
412.0000000000053,47.31137104576625,0.1896284859393469,-0.049344685973773394
413.4000000000053,47.44998368326969,0.18933121419055898,-0.04927753038036453
414.8000000000053,47.5861581667929,0.18935669058991444,-0.05060220202426002
416.20000000000533,47.72364874324831,0.18640306702002252,-0.050618122358230266
417.60000000000537,47.860028135567454,0.18580078793115518,-0.049179769842268684
419.00000000000534,47.9976718081193,0.18468071065045844,-0.04787475823001852
420.4000000000054,48.13472736728562,0.18088143970469273,-0.04983980840644442
421.8000000000054,48.27116245153446,0.17955851009434065,-0.051151463219949456
423.20000000000545,48.40926380528234,0.1767600017399975,-0.04983980382215414
424.6000000000055,48.5452099594426,0.1790557529133061,-0.04956138891443018
426.00000000000546,48.68316458238679,0.17971868058797313,-0.04922783369763195
427.4000000000055,48.819359120747414,0.17698505221146332,-0.05148254272773389
428.8000000000055,48.95741204474009,0.17817963542767123,-0.050506437004433025
430.2000000000055,49.09449454425643,0.1753184554747278,-0.05180994604114986
431.60000000000554,49.23241144238791,0.17559083785261187,-0.051828342966040886
433.00000000000557,49.36997887355387,0.17965284847183538,-0.051479917998485725
434.4000000000056,49.506620290728144,0.17699771106134188,-0.05147991835064847
435.80000000000564,49.643988157041086,0.17917786897923804,-0.05280255449274929
437.2000000000056,49.78149574390115,0.18144061500319508,-0.05279981900003161
438.60000000000565,49.91876559853635,0.1837865283269169,-0.052799821120978585
440.0000000000057,50.05784292331384,0.18040521512449192,-0.05379001603985323
441.40000000000566,50.19467134078753,0.17964041539771958,-0.05224202632057384
442.8000000000057,50.33248424812608,0.18308095644316857,-0.0530443185706746
444.20000000000573,50.467089431487295,0.18148562432245763,-0.05379005000255521
445.60000000000576,50.60767651052372,0.1847667979451284,-0.053836124232406135
447.0000000000058,50.746214045200055,0.186193350806251,-0.054130165141665465
448.4000000000058,50.88496537429436,0.18341704478600507,-0.054448507641136956
449.8000000000058,51.02235784480973,0.18279768056687984,-0.055759929953106635
451.20000000000584,51.158338132731984,0.190046004852523,-0.05442455609705554
452.6000000000058,51.29739253074728,0.18869633069551162,-0.054439930020303784
454.00000000000585,51.43651597272943,0.18704305836686141,-0.055787064083087756
455.4000000000059,51.57467395691563,0.18765966497854247,-0.055759831000441906
456.8000000000059,51.71263369398691,0.18703269903149167,-0.05575981850367029
458.20000000000596,51.85053991921883,0.18928458774857337,-0.05707914050254104
459.60000000000593,51.98888018031582,0.19096647608259842,-0.05575610201877712
461.00000000000597,52.12828865048656,0.19074332661570348,-0.055770252311100776
462.400000000006,52.26611526296312,0.18894032785166148,-0.05678253148997303
463.800000000006,52.40446784338937,0.19303975945426677,-0.056727685523929594
465.200000000006,52.542347285930326,0.1950168491400559,-0.05709004000455131
466.60000000000605,52.68128162229044,0.19301468285881507,-0.05709002575239985
468.0000000000061,52.81907194673612,0.19496414996575773,-0.05840017326694724
469.4000000000061,52.95830661465838,0.19535144994047937,-0.05741939019573117
470.8000000000061,53.09500241195709,0.19739790878523022,-0.058730238383674305
472.2000000000061,53.23325537998563,0.19769560811302522,-0.05866625056409713
473.60000000000616,53.3733267979052,0.19987881598694668,-0.058679709881722
475.00000000000614,53.51164417034415,0.2027829333601534,-0.05938965935446738
476.4000000000062,53.6508852927977,0.20096246976100152,-0.058074409155276285
477.8000000000062,53.78917099622735,0.20393578190817152,-0.05873003119052278
479.20000000000624,53.927587412875,0.20595927990891139,-0.061384783665083376
480.6000000000063,54.06636362324002,0.20784754261676786,-0.06063525122717284
482.00000000000625,54.20484192541073,0.20802803020808946,-0.06069989298355338
483.4000000000063,54.34370300978885,0.20679466670512414,-0.06333956885759662
484.8000000000063,54.48232791394169,0.20688855712267396,-0.06202322620911804
486.2000000000063,54.6192719147047,0.2109549637792194,-0.06334000044989985
487.60000000000633,54.75976228013085,0.2101886589330122,-0.06271603083132504
489.00000000000637,54.89866627060542,0.21134949951688853,-0.06400461868538176
490.4000000000064,55.03717771608013,0.21463403899790778,-0.0646189785606861
491.80000000000643,55.17635048971647,0.21224370266260695,-0.06463115038529477
493.2000000000064,55.31507023309042,0.21004316328024975,-0.06488029766353165
494.60000000000645,55.45387088509416,0.21013083708594626,-0.06465017102853032
496.0000000000065,55.59318386545889,0.21253259716957862,-0.06564061607574612
497.40000000000646,55.731899438320866,0.21061937760513572,-0.06596007921198854
498.8000000000065,55.87006455121587,0.20872834566239362,-0.06597996400081563
500.2000000000065,56.010216302199666,0.20985828130817064,-0.06696997744989375
501.60000000000656,56.14740370320914,0.2128202592506121,-0.06630306420474419
503.0000000000066,56.288247748237104,0.21205106711064814,-0.0676298788165095
504.40000000000657,56.42830563881083,0.2132319377031726,-0.06860840958657732
505.8000000000066,56.56795856585551,0.20938529672671224,-0.06992353054686529
507.20000000000664,56.70626012189398,0.20825253954226253,-0.06997626222285813
508.6000000000066,56.846230506201536,0.20830244428093336,-0.0702934108430866
510.00000000000665,56.98510877088844,0.21158968424459035,-0.07087068349347758
511.4000000000067,57.12398199973044,0.2089862541931251,-0.071303091819924
512.8000000000068,57.2645663919092,0.20951760481306803,-0.06860954226519844
514.2000000000068,57.40406008201752,0.20814515654116983,-0.07066766037959438
515.6000000000067,57.54310056255923,0.20696148722626528,-0.07123994596434269
517.0000000000068,57.68287962747962,0.21317674339220494,-0.0699215142710381
518.4000000000068,57.82219516503187,0.2110852798397247,-0.07135509931167228
519.8000000000068,57.962245229329554,0.21089312687172712,-0.07365147447667963
521.2000000000069,58.10123579732486,0.20775816518007661,-0.0726701059721333
522.6000000000068,58.240560480553604,0.2118849028352705,-0.07501007741101473
524.0000000000068,58.379774577730046,0.20807048873533773,-0.07537639180848243
525.4000000000069,58.519365488360535,0.2097774166040529,-0.0733292858800847
526.8000000000069,58.65907222753266,0.212954370629582,-0.07332740077245736
528.2000000000069,58.797933579245736,0.21245437290390945,-0.07464995537558883
529.600000000007,58.938113839438394,0.2135651101452638,-0.07528066735388217
531.0000000000069,59.07851908848658,0.21354691849744745,-0.07727999134110464
532.4000000000069,59.21601764183413,0.21547443118080079,-0.07846788499312352
533.800000000007,59.358647314477714,0.21510273003971925,-0.078599889706636
535.2000000000071,59.4990682810134,0.2158741178458221,-0.07990586287447465
536.6000000000071,59.63848157546451,0.21965271055072177,-0.08022997701016488
538.000000000007,59.77917000000071,0.21681313313275274,-0.07991992005768855
539.4000000000071,59.91906729166469,0.220434031794424,-0.08123982174172184
540.8000000000071,60.05947258159603,0.21908103164447734,-0.07987486998617932
542.2000000000071,60.199169058712855,0.22181588447556,-0.08222972343275048
543.6000000000072,60.33946187135487,0.22135132862989226,-0.08320209328218864
545.0000000000072,60.48092363725274,0.22466510352853408,-0.08323808717390913
546.4000000000071,60.621088146040556,0.2218906936582019,-0.08427691999866838
547.8000000000072,60.76168703378274,0.22329777911917348,-0.08353966089015863
549.2000000000072,60.902344480626724,0.22731971973995413,-0.08452515794554039
550.6000000000072,61.04177278210774,0.22394724860235793,-0.08352402641996015
552.0000000000073,61.18159401100568,0.22638077401900647,-0.08583999286870103
553.4000000000073,61.32271568842378,0.2304098439138249,-0.08715986875013249
554.8000000000073,61.459797383030086,0.2292654789096782,-0.0871597412157441
556.2000000000073,61.602238227696695,0.2305630701737411,-0.0894687267612202
557.6000000000073,61.74218820131591,0.2328802748943808,-0.08946981075715232
559.0000000000074,61.88266076232872,0.23519066291767166,-0.09078019227876588
560.4000000000074,62.02335002143163,0.23284490427242566,-0.09078019188255748
561.8000000000075,62.16339696771291,0.2346706260339837,-0.09078568409479137
563.2000000000074,62.30321223685472,0.2344067979837119,-0.09150199892471012
564.6000000000074,62.443981960927594,0.23703555490477357,-0.09473947422596529
566.0000000000075,62.58283051055699,0.23678289513514672,-0.09506475817708537
567.4000000000075,62.724603083172596,0.2349712599065954,-0.09466189461576135
568.8000000000075,62.86468342316761,0.23324856478611355,-0.09539993004069558
570.2000000000075,63.00498587015116,0.23511901393570578,-0.09672555782182579
571.6000000000075,63.14591566621508,0.2381659495392794,-0.09680245433822376
573.0000000000075,63.28439455443055,0.2373951681370141,-0.09606093496747015
574.4000000000076,63.427820112870364,0.2441616730406313,-0.09869073074979262
575.8000000000076,63.5681909116159,0.2450809087866055,-0.1000108882718056
577.2000000000077,63.70863880028182,0.24630700659752525,-0.10066310706748638
578.6000000000076,63.84895712989294,0.2471315506610543,-0.10132998916391145
580.0000000000076,63.9892838352436,0.24256106356727725,-0.10264044693361152
581.4000000000077,64.13116859340471,0.24259418201426275,-0.10395977266316025
582.8000000000077,64.27115379883134,0.23928841712519056,-0.1052803646512106
584.2000000000078,64.41369773977488,0.24121876578721224,-0.10527613708386507
585.6000000000078,64.55347798270495,0.23876583626124215,-0.10657498057287418
587.0000000000077,64.69485507330592,0.24193177515150954,-0.10750395187896622
588.4000000000078,64.83515150911582,0.24210981526178554,-0.10922939131551423
589.8000000000078,64.97481692845179,0.23898988907903163,-0.10914967063552217
591.2000000000078,65.11659123061473,0.23553061078093407,-0.11071007146173795
592.6000000000079,65.25765075976261,0.23651954028191824,-0.11186078613279005
594.0000000000078,65.39611781311754,0.23385504120834155,-0.11186008736285569
595.4000000000078,65.5382570425714,0.23456963838477307,-0.11317414319079644
596.8000000000079,65.67829427385689,0.23001431175200016,-0.11670683058876508
598.2000000000079,65.81887590740254,0.23113031713351573,-0.11645790197618355
599.600000000008,65.95937223196601,0.2311517471170461,-0.11712992220411422
601.000000000008,66.09782265768857,0.22908525299302074,-0.11845276204346478
602.4000000000079,66.24045108842402,0.2279192612860006,-0.11878548485781426
603.800000000008,66.38065056757053,0.22881519728465105,-0.12009985897962405
605.200000000008,66.5220635203921,0.23182125213458438,-0.12140278499420232
606.6000000000081,66.66324335387029,0.23675766433428347,-0.12241036812888018
608.0000000000081,66.80307660603587,0.23536868805508981,-0.12371955474895513
609.400000000008,66.94458256416341,0.24151768405107554,-0.12503990453934044
610.8000000000081,67.08506680377342,0.24365270565668573,-0.1263565113305649
612.2000000000081,67.22644505122818,0.24669169926871914,-0.12755038907466343
613.6000000000081,67.36586892171819,0.24628118786349584,-0.1270389777096348
615.0000000000082,67.50855549815881,0.2523537127349784,-0.1283436576068282
616.4000000000082,67.64916800613244,0.2566961081046566,-0.12800110157203415
617.8000000000081,67.78994097662071,0.26270778695422625,-0.13195222125223616
619.2000000000082,67.93067475260258,0.26464711157548826,-0.13205197965339988
620.6000000000082,68.0715367796903,0.2670704543549429,-0.13459026670095398
622.0000000000083,68.21175426962832,0.2759995935952553,-0.13517079644452812
623.4000000000083,68.35291535561522,0.2761603314042782,-0.13624029236515955
624.8000000000083,68.4927073457824,0.284546731599735,-0.13917676876163254
626.2000000000083,68.63404618856761,0.2885711005127445,-0.13913138168824224
627.6000000000083,68.77551978517641,0.2921143761944651,-0.14216252708692068
629.0000000000084,68.91466136204825,0.29718425829572204,-0.14349199529090306
630.4000000000084,69.05653727828471,0.30437445160607046,-0.14480631583635262
631.8000000000084,69.19992448630757,0.31350497264092025,-0.1461199380125131
633.2000000000085,69.3404241467523,0.31977366829730003,-0.14748733244208267
634.6000000000084,69.4823198358142,0.33181792293636025,-0.150070654339316
636.0000000000084,69.6244329005542,0.34077162230778235,-0.1516153935841853
637.4000000000085,69.76643172947234,0.34639655079286213,-0.1546792856314565
638.8000000000085,69.9077802156712,0.3550695580624066,-0.15541202370479246
640.2000000000085,70.04928737333948,0.36302283346961906,-0.1579705853095832
641.6000000000085,70.19055234531339,0.37159334635285934,-0.15970008872473596
643.0000000000085,70.33282403137194,0.376531868328978,-0.16225102992805018
644.4000000000086,70.47498077642402,0.3868758610144236,-0.16751757800265032
645.8000000000086,70.61611991441636,0.3972767529594783,-0.1688443304216607
647.2000000000086,70.75896817211134,0.40593476427871433,-0.1714832179552186
648.6000000000087,70.89837020597416,0.40990281823047336,-0.17222649856402317
650.0000000000086,71.04176111695705,0.42355974699849397,-0.17478985065093022
651.4000000000087,71.18470879560802,0.4333067877099319,-0.18026562300213556
652.8000000000087,71.32612381278037,0.44145755087228067,-0.18291663563641158
654.2000000000087,71.46877522917161,0.44892686827007533,-0.18593697725412195
655.6000000000088,71.61211332874025,0.46046691436460097,-0.18833486331753369
657.0000000000088,71.7530181659324,0.47518040304025644,-0.19362137677003588
658.4000000000087,71.89508713049084,0.4845940808111677,-0.1958828145198428
659.8000000000088,72.03956421084348,0.496560781997855,-0.2004485584365976
661.2000000000088,72.18191796897996,0.5143900793841534,-0.20319890662658624
662.6000000000088,72.32395777727336,0.5271688293784433,-0.20728347937577674
664.0000000000089,72.46660775561658,0.5434810519698672,-0.2114577278293921
665.4000000000088,72.6089689268818,0.5567265207827632,-0.21570160605802302
666.8000000000089,72.75103689004652,0.5740418700904364,-0.2197607333937115
668.2000000000089,72.89401546482917,0.5874047038991463,-0.22510559724309465
669.6000000000089,73.03562246540498,0.6026448937529998,-0.23106452088904827
671.000000000009,73.17782539030556,0.6211944187596792,-0.2351041022134388
672.400000000009,73.31832848597033,0.6353048739075855,-0.24079772283414913
673.800000000009,73.46147423851473,0.6590288895479723,-0.2449613734528695
675.200000000009,73.60377244867382,0.6742569961755671,-0.2519274198898014
676.600000000009,73.74684368660714,0.7007723653562019,-0.25618537136275643
678.0000000000091,73.88886004467729,0.7255287834770618,-0.26257668970985204
679.4000000000091,74.03065320603352,0.743536921609288,-0.270216511708413
680.800000000009,74.17269461477837,0.7653801144582182,-0.2766900539449728
682.2000000000091,74.31428580583284,0.7933741029725676,-0.2819201780663154
683.6000000000091,74.45659307691365,0.8173431425509432,-0.2892674331713039
685.0000000000091,74.59926888733666,0.8454127728604874,-0.29707306664714306
686.4000000000092,74.74123540681532,0.8744708849969456,-0.3056819342426693
687.8000000000092,74.88438744562248,0.9089244374318706,-0.3121342278814061
689.2000000000093,75.0268805617404,0.9391796714640555,-0.32018300621064366
690.6000000000092,75.17076644946263,0.9757299984507064,-0.32896181607074393
692.0000000000092,75.31292081398857,1.016190160563611,-0.33651611163304285
693.4000000000093,75.45625978470846,1.0494439712630996,-0.346040771645888
694.8000000000093,75.60028627522858,1.0895564171907073,-0.35665849088816115
696.2000000000094,75.74389483134097,1.129230013985414,-0.3680182177896154
697.6000000000093,75.88683624478654,1.1690030471963135,-0.37978367619696174
699.0000000000093,76.03093632568277,1.212652683361792,-0.39049500013780314
700.4000000000094,76.17423366565512,1.2552608010546473,-0.4013519158288772
701.8000000000094,76.31870307155673,1.3022233183083536,-0.41065089372200925
703.2000000000094,76.46052227654341,1.3501122674493597,-0.4238028120835642
704.6000000000095,76.60402928951254,1.395972383505359,-0.4383259285386818
706.0000000000094,76.74718615698211,1.4436167861591862,-0.45362844717768036
707.4000000000094,76.89191852898799,1.5008910758746241,-0.46265829664271463
708.8000000000095,77.03503140470843,1.5579014748555156,-0.4748311994121934
710.2000000000095,77.17916905763161,1.6116939554072256,-0.48687055993513795
711.6000000000096,77.32340502789454,1.6681528095848415,-0.496700627065652
713.0000000000095,77.46774378990253,1.7256378892647726,-0.5199188400206358
714.4000000000095,77.61167324341643,1.7889221909949842,-0.5369979088438828
715.8000000000096,77.75626756944192,1.8443505489502796,-0.5560691855153279
717.2000000000096,77.90080708773083,1.9124461878269317,-0.5755392368336425
718.6000000000097,78.0452612209593,1.9765282045192236,-0.5931848104797108
720.0000000000097,78.19002145157016,2.0394373973752447,-0.6124318916665898
721.4000000000096,78.33356817418183,2.1086455813500957,-0.6314967725929197
722.8000000000097,78.47747438182907,2.175528242593809,-0.6530487666428728
724.2000000000097,78.62192117617712,2.243594135842741,-0.6735419251598325
725.6000000000097,78.76737317938411,2.3177627869777835,-0.6969956863690685
727.0000000000098,78.91155572432058,2.3900254800247773,-0.7192449440981665
728.4000000000098,79.05648347003002,2.460747068458112,-0.7418911851560579
729.8000000000097,79.20103879562286,2.536444667887342,-0.7657404523291835
731.2000000000098,79.34575769239609,2.6055390298903576,-0.7922605299568706
732.6000000000098,79.48986733884652,2.676771545447301,-0.8159411173658682
734.0000000000099,79.63431971136552,2.7458537291001033,-0.8419709307586554
735.4000000000099,79.77792728660329,2.8155323105812786,-0.867886949394336
736.8000000000098,79.92259116322386,2.880043314794113,-0.8979281707188376
738.2000000000099,80.067424710695,2.9389278359254236,-0.9243027098048118
739.6000000000099,80.21151461464993,2.997333302375728,-0.952246927961939
741.00000000001,80.35530773978486,3.04735259254471,-0.9821250653087064
742.40000000001,80.49937327137707,3.0872501632656513,-1.0120816257353842
743.80000000001,80.64262553722531,3.1153977933462795,-1.045028296877422
745.20000000001,80.78570070563342,3.1346175770829614,-1.0739232233141869
746.60000000001,80.92847506208044,3.1300818535766624,-1.102480948046602
748.00000000001,81.07076430536723,3.104673215778741,-1.131445822566583
749.4000000000101,81.21229109582767,3.057660932524618,-1.1603899751044806
750.8000000000101,81.35204109110224,2.974131205164424,-1.1900895449069528
752.20000000001,81.49120761952675,2.858499996458844,-1.2184282458053222
753.6000000000101,81.62978035374687,2.697378504622626,-1.242498540568794
755.0000000000101,81.76677889169171,2.480646234662015,-1.2673046180692507
756.4000000000102,81.90204601975965,2.169503046537472,-1.2897196270759004
757.8000000000102,82.03339484982233,1.7498586579971853,-1.3060577016925428
759.2000000000102,82.16144728320845,1.2070332954628165,-1.3193136514779642
760.6000000000103,82.2913912668022,0.6450080023954965,-1.3263407847072508
762.0000000000102,82.42262820415897,0.2733943469981881,-1.3305772749350524
763.4000000000103,82.56159204299684,0.10157470489642328,-1.334607494162103
764.8000000000103,82.70307966146929,0.03824811475896883,-1.3358407557320082
766.2000000000103,82.8481277777903,0.02982111583358016,-1.3358157167366977
767.6000000000104,82.99105522363064,0.026790946320182307,-1.3351799286158745
769.0000000000103,83.1334946718141,0.029322696296801176,-1.3345395078583846
770.4000000000103,83.27725912364951,0.03239856876740532,-1.3345198962734575
771.8000000000104,83.42149373650193,0.029106844001502985,-1.3358390159334763
773.2000000000104,83.56403890124841,0.03476245259469257,-1.335697548648374
774.6000000000104,83.70730496395768,0.03095669722910266,-1.3345195918477306
776.0000000000105,83.85047602435115,0.024861310407913617,-1.3371601195440226
777.4000000000104,83.99424581856636,0.028858262773987065,-1.3357698069112574
778.8000000000105,84.13720003787057,0.027033631186925255,-1.3363865591547932
780.2000000000105,84.28017505965295,0.02358210725972798,-1.33716014133278
781.6000000000105,84.42407012533896,0.023354661326352666,-1.338479135331939
783.0000000000106,84.5678357104922,0.021299706629016146,-1.3384969792310395
784.4000000000106,84.70916786219806,0.01413124895814466,-1.337150077399583
785.8000000000106,84.85348636470759,0.015953424637599856,-1.3384700391646684
787.2000000000106,84.99682941516903,0.013111815943446903,-1.3371494378052629
788.6000000000106,85.1405350311069,0.018807079262694426,-1.3371413967084993
790.0000000000107,85.28319882209719,0.020051887605299967,-1.33912870904921
791.4000000000107,85.42599105251324,0.020747055388903757,-1.3383246607065908
792.8000000000106,85.57090395596094,0.021986990131314776,-1.3384619323394755
794.2000000000107,85.71540126327525,0.020622929923910238,-1.3388817624763454
795.6000000000107,85.85852659295617,0.023047054285705748,-1.3411097335219475
797.0000000000107,86.0018935260498,0.021752326742892514,-1.3402355257573828
798.4000000000108,86.14582758259435,0.01594466532858796,-1.3397999016986968
799.8000000000108,86.28875208483801,0.01851770736987568,-1.340421785160701
801.2000000000108,86.43219366989224,0.016808201855466276,-1.3407801061237348
802.6000000000108,86.57582092964945,0.012919571625047421,-1.3407958821238575
804.0000000000108,86.71823390500413,0.009753308802013638,-1.340780104735014
805.4000000000109,86.8614537985088,0.007127341330021242,-1.3407801069998424
806.8000000000109,87.00487501676727,0.01137126420041401,-1.3407427313706775
808.200000000011,87.14715725096927,0.015946101823833825,-1.3420997545492215
809.6000000000109,87.29222057141861,0.015535396263942847,-1.3423887688860456
811.0000000000109,87.43445491686911,0.017644063334916638,-1.340120031050028
812.400000000011,87.57825585040281,0.020791844762572342,-1.34201383586102
813.800000000011,87.72203375746685,0.014179735720389886,-1.3427563490160108
815.200000000011,87.86532998442576,0.01627267044861247,-1.3427422431501679
816.600000000011,88.01077993265673,0.015463578793949218,-1.342760783331677
818.000000000011,88.15461807307102,0.014666899767328268,-1.3427615004138276
819.400000000011,88.29804731673964,0.015111476252801292,-1.3443146530505268
820.8000000000111,88.4428848166478,0.010568390120984095,-1.3441401566118931
822.2000000000111,88.5860322189454,0.003895181048208851,-1.346707714882918
823.6000000000112,88.728790020403,-0.002662058514424359,-1.3454016317215811
825.0000000000111,88.87306652377673,-0.00740132599010046,-1.3470592675148536
826.4000000000111,89.01580768351975,-0.005722700353434806,-1.3467768406994138
827.8000000000112,89.16018787462332,-0.006085725306195222,-1.3454155549249949
829.2000000000112,89.30435988640126,-0.017089735143255513,-1.346710321578231
830.6000000000113,89.44844022081301,-0.02489524421093048,-1.346709934593941
832.0000000000113,89.59177058937013,-0.026311995261721233,-1.347360643505561
833.4000000000112,89.73511001827234,-0.023174837928801928,-1.3500010193007124
834.8000000000113,89.87959610171943,-0.031446486985238664,-1.3499999647927559
836.2000000000113,90.02395105726568,-0.03256400151007499,-1.3490509221534341
837.6000000000113,90.16869950680127,-0.03535246177706952,-1.348345284843321
839.0000000000114,90.31304045019561,-0.04477999319196657,-1.3499992298264951
840.4000000000113,90.45764755295289,-0.04742373387835963,-1.3486901754903426
841.8000000000113,90.60124564579185,-0.04795439585017336,-1.349297589740409
843.2000000000114,90.74526096135624,-0.04871664122860864,-1.3506532734772003
844.6000000000114,90.88926636080471,-0.05263382044204068,-1.3506563151633624
846.0000000000115,91.03331842826807,-0.05420106441736339,-1.350655192725001
847.4000000000115,91.17697037299219,-0.058582203779911524,-1.3516713231529867
848.8000000000114,91.31997665636256,-0.06278776580106227,-1.3516500302963244
850.2000000000115,91.4633519795538,-0.0613614115675416,-1.3507050153228164
851.6000000000115,91.60642011531037,-0.06687959809477606,-1.3506598721645564
853.0000000000116,91.74968876342558,-0.06542081822432966,-1.3506581510598754
854.4000000000116,91.89136575762214,-0.076690534942363,-1.3506600997653098
855.8000000000116,92.03548653205492,-0.06955975741345766,-1.3506625362187696
857.2000000000116,92.17773202694512,-0.07576772016088906,-1.3532888735637232
858.6000000000116,92.32379728250329,-0.07637734582525679,-1.3532900502976024
860.0000000000116,92.46676507449801,-0.07260734495156829,-1.3552726850694015
861.4000000000117,92.61114184690888,-0.08045539550369929,-1.3552808748975518
862.8000000000117,92.75293533425696,-0.08308548880464439,-1.3552798485450768
864.2000000000116,92.89806312298347,-0.08719212388873698,-1.3552798864188835
865.6000000000117,93.0424793082127,-0.08694182500761771,-1.355285447744314
867.0000000000117,93.18583361216105,-0.09194868110926846,-1.3552698350444685
868.4000000000118,93.32927720545858,-0.09568244274773363,-1.3559302447300832
869.8000000000118,93.47390190424801,-0.09787837884856643,-1.3553102024265695
871.2000000000118,93.61854741721066,-0.10148563010316725,-1.3565325325617823
872.6000000000118,93.76118795797207,-0.10383401450562069,-1.3595683410806871
874.0000000000118,93.90587910658358,-0.11197766903286466,-1.356920588203304
875.4000000000119,94.0493908157646,-0.11019203369715758,-1.358230069946523
876.8000000000119,94.19393112323563,-0.11365457760161979,-1.36086681142107
878.2000000000119,94.33788330553857,-0.11761884948130286,-1.3596600749452148
879.600000000012,94.48040881492625,-0.12017695712781329,-1.359988453891142
881.0000000000119,94.62294990688869,-0.12822362867544435,-1.3593301253804335
882.4000000000119,94.76875746691424,-0.14044316946096513,-1.3603206165042026
883.800000000012,94.91099646372787,-0.14300660112475283,-1.3590100259983422
885.200000000012,95.05666858371717,-0.15107772327550784,-1.3599069749470543
886.600000000012,95.2009013676584,-0.15559163217567962,-1.3589573660661607
888.000000000012,95.34358679262985,-0.1619737243954602,-1.3616400613402653
889.400000000012,95.48837054401082,-0.16442760994895478,-1.3603200382917442
890.8000000000121,95.63216352698701,-0.1707268595161775,-1.3612620669435902
892.2000000000121,95.7764218627731,-0.17113651030815236,-1.3622999150857193
893.6000000000121,95.9211925520212,-0.1758241602496371,-1.3629549210100849
894.0000000000122,95.96171078290112,-0.1775400526327955,-1.362959836128987