File: 01_Data/Cotton_Rug/STA/N2/10K_min/Cotton_Rug_STA_N2_10KData_220112_R1.csv
##Temp./Â°C,Time/min,DSC/(mW/mg),Mass loss/mg
50.0,10.78040499342348,0.04831588772901518,-0.04500852482866158
51.20000000000002,11.090884972306046,0.08562699885437974,-0.04554095639605826
52.400000000000034,11.305761448944736,0.1126765299977327,-0.04732344044378367
53.60000000000005,11.4918178266136,0.13422405399346882,-0.0481411560871825
54.80000000000007,11.66112631395788,0.15118174404178053,-0.04989952551241039
56.000000000000085,11.812190267125285,0.16309832647189326,-0.05035315575722521
57.2000000000001,11.963203250642199,0.17469074995838907,-0.04863415351412792
58.40000000000012,12.104825743921833,0.18206068995683888,-0.048704773809173485
59.600000000000136,12.243539979936541,0.1928175859957736,-0.04985647901506818
60.80000000000015,12.382346725909283,0.19849305587602084,-0.05286117927070766
62.00000000000017,12.517146401024196,0.2019974844629734,-0.05165578431357387
63.20000000000019,12.651231777003067,0.20837530594439746,-0.050522700156409694
64.4000000000002,12.78246337176695,0.2117400503286277,-0.05156039175643112
65.60000000000022,12.913406299182853,0.21825399534221535,-0.05135719797823324
66.80000000000024,13.044077489909851,0.22052302067701657,-0.05251879190728426
68.00000000000026,13.172968296785038,0.2227855198740047,-0.05417813472558475
69.20000000000027,13.302314926940252,0.22656207279227314,-0.05420639637620717
70.40000000000029,13.431064699723846,0.22765647023236701,-0.05360793700200217
71.6000000000003,13.559012863807542,0.2285335386651084,-0.05493223632385691
72.80000000000032,13.684560993497703,0.2292934555263182,-0.05421711138966989
74.00000000000034,13.812164591360558,0.22999747984573293,-0.05558278217896451
75.20000000000036,13.937458862933504,0.23484025763230032,-0.057212433307108235
76.40000000000038,14.062298406639991,0.2354734393711463,-0.056857700054527616
77.60000000000039,14.187064214850114,0.23721410398845122,-0.05789403719960129
78.80000000000041,14.312993125486678,0.24118313052677026,-0.05772460209659824
80.00000000000043,14.437130234712935,0.24188307189403713,-0.0576958184221974
81.20000000000044,14.560443933567106,0.24247449408322147,-0.06122295501586317
82.40000000000046,14.68424774914096,0.24248237484682345,-0.06185886006710328
83.60000000000048,14.807794228026784,0.24528409007434454,-0.06183194026555183
84.8000000000005,14.930315424884542,0.24911432015086732,-0.06339738520976956
86.00000000000051,15.051839547367035,0.24762860262759662,-0.06238276567686185
87.20000000000053,15.17415092414047,0.24820013224747844,-0.06162837079283934
88.40000000000055,15.294923820456777,0.24809720953896325,-0.06039882237024141
89.60000000000056,15.414917381980063,0.24789162965719375,-0.0639436498505832
90.80000000000058,15.535712822286799,0.24960309851051443,-0.0659201859948455
92.0000000000006,15.656385552810235,0.24793989683891465,-0.06456360937985295
93.20000000000061,15.77660483260668,0.24770673223261735,-0.06721483952213791
94.40000000000063,15.896449144364995,0.24888600084051032,-0.06766890273732429
95.60000000000065,16.013479065712193,0.24656472024031617,-0.06792148149352872
96.80000000000067,16.133878384889492,0.24592301152465268,-0.07083229354225073
98.00000000000068,16.253565799152543,0.24784125129231332,-0.06788235041245771
99.2000000000007,16.372402009229468,0.24674796542105082,-0.06908972955290427
100.40000000000072,16.49147526254569,0.24801036504072832,-0.06923133139817939
101.60000000000073,16.6093245662628,0.24791984541009376,-0.06895319242335685
102.80000000000075,16.7270384083803,0.24714867956415723,-0.07108011403755743
104.00000000000077,16.844808916515127,0.2453552160317214,-0.07075733013259056
105.20000000000078,16.961905033627758,0.24478216541525805,-0.07155248295587047
106.4000000000008,17.08185378424938,0.24574767177296,-0.07182265117243336
107.60000000000082,17.19926538280953,0.24787943331648749,-0.07211443742532664
108.80000000000084,17.31747624671523,0.24592360447135592,-0.07336582922772328
110.00000000000085,17.43607825640242,0.24555956189658604,-0.0727104375404517
111.20000000000087,17.55262336188733,0.24716191395898016,-0.07407784298397857
112.40000000000089,17.670496112828058,0.24456313742026023,-0.074040153111806
113.6000000000009,17.7884189701036,0.24438786015285394,-0.07271893588989986
114.80000000000092,17.905062339446882,0.24403715770207918,-0.07402988861685511
116.00000000000094,18.022122437102773,0.24378887645341557,-0.07403084400809146
117.20000000000095,18.138275178768644,0.24611442995746752,-0.07536203901572769
118.40000000000097,18.257907360064127,0.24498896774061657,-0.07484725901334155
119.60000000000099,18.3750374099098,0.2472275226122645,-0.07397712086546226
120.800000000001,18.492166164372275,0.24703803698000482,-0.07403026067366181
122.00000000000102,18.6100000000001,0.24963841301163175,-0.07382287547737887
123.20000000000104,18.724468636984522,0.2484514808988665,-0.07643914664418938
124.40000000000106,18.843379864226247,0.2507786548299703,-0.0764420780041406
125.60000000000107,18.960000000000107,0.25432972549983657,-0.0754600398716816
126.80000000000109,19.07504125846983,0.25285976852374425,-0.07645770984780142
128.0000000000011,19.19200959338163,0.25386749498685157,-0.07515484933595307
129.20000000000113,19.308929417096678,0.2535981414511568,-0.07643989925500438
130.40000000000114,19.42477854707496,0.25547513562788887,-0.07775980725041665
131.60000000000116,19.542102959349126,0.25738142094977623,-0.0784189607105108
132.80000000000118,19.658360653120347,0.25881316816190975,-0.08151507299174643
134.0000000000012,19.774107149039885,0.257921293236675,-0.0787300943506466
135.2000000000012,19.891196534132394,0.25756476193840006,-0.07732970396779049
136.40000000000123,20.006593644091623,0.26110682357375997,-0.07732836124596787
137.60000000000124,20.12293108596641,0.261432240828109,-0.08026662676199603
138.80000000000126,20.23891569845948,0.2615660603136859,-0.08006977400701576
140.00000000000128,20.35534647044345,0.26319521832658127,-0.07874950259737412
141.2000000000013,20.471801201285718,0.2633674048250103,-0.08005694440614741
142.4000000000013,20.58651733571822,0.26720688027078676,-0.08137994119853165
143.60000000000133,20.70136382081537,0.26399375274446873,-0.08138159898466402
144.80000000000135,20.817124007417018,0.2681376237289988,-0.0813905094621421
146.00000000000136,20.932771334863887,0.268210613282389,-0.08072994615559148
147.20000000000138,21.04913666783944,0.26846213781090755,-0.08203983291218409
148.4000000000014,21.164797268611757,0.2724698180791085,-0.08300959392691665
149.60000000000142,21.281237056472804,0.2729452926780477,-0.08237010341221396
150.80000000000143,21.39519031579297,0.2758253955700297,-0.08139222837239402
152.00000000000145,21.51082867389929,0.27385640415284596,-0.08260204834077944
153.20000000000147,21.626078619005575,0.27606409688320777,-0.08139013644769477
154.40000000000148,21.740269318896097,0.2779054187590551,-0.08278695358633748
155.6000000000015,21.85665369007455,0.2756475170205625,-0.08269834499153816
156.80000000000152,21.971707476268513,0.28071504362321925,-0.0832737302157347
158.00000000000153,22.088365608258123,0.2801000866775026,-0.08306675270175257
159.20000000000155,22.201787474202305,0.28109588741925157,-0.08558945685435893
160.40000000000157,22.316517238376036,0.28070921721882636,-0.08597248532984869
161.6000000000016,22.432815897991674,0.2838382105003239,-0.08466984343834971
162.8000000000016,22.545322121366308,0.28094062748205784,-0.08598992745312861
164.00000000000162,22.662346294057855,0.2804116373438694,-0.08468163210104773
165.20000000000164,22.778925184864857,0.28137508003174855,-0.08467803512445071
166.40000000000165,22.893940134620248,0.28337905225977505,-0.08368590999063219
167.60000000000167,23.009744850515,0.28516121369137004,-0.08601947678082134
168.8000000000017,23.12473770046044,0.2857244598997164,-0.08774044241355794
170.0000000000017,23.239405966114823,0.28541683903313614,-0.08300591341896402
171.20000000000172,23.353874637840814,0.28533136649025703,-0.08400056042193205
172.40000000000174,23.46990363967837,0.2886850196225359,-0.08676197528379781
173.60000000000176,23.583876387289127,0.2906084822140733,-0.08639243812250053
174.80000000000177,23.70029273122691,0.2917105384431533,-0.08635908459298092
176.0000000000018,23.815239756668497,0.28939413691449,-0.08770033957818191
177.2000000000018,23.93059896885204,0.29267029943053663,-0.08906976009685241
178.40000000000182,24.04580577621133,0.29192032289660685,-0.0913600926750906
179.60000000000184,24.15955513523628,0.2902272937245829,-0.09005206691901035
180.80000000000186,24.275045754917432,0.29461853333606125,-0.0887400406886587
182.00000000000188,24.39056240197514,0.29172565157623187,-0.08972008473637194
183.2000000000019,24.505454666107003,0.29293202265823226,-0.08878925403122384
184.4000000000019,24.62107389662588,0.29885844330774836,-0.08841017055748246
185.60000000000193,24.73507014340637,0.29458590382269295,-0.09015275241134946
186.80000000000194,24.8517928528053,0.2936840808388319,-0.0897197690604341
188.00000000000196,24.965631407114802,0.2977110030964868,-0.0910399606719916
189.20000000000198,25.080208705280153,0.29773258412985015,-0.0910392765518453
190.400000000002,25.194522682954773,0.2960830973279975,-0.09105991524050028
191.600000000002,25.309033107554992,0.2985674303249541,-0.09036993588185327
192.80000000000203,25.42426215049317,0.296712210876055,-0.09166695549063553
194.00000000000205,25.53899814837725,0.29943128466326,-0.09170076007567429
195.20000000000206,25.653648729687166,0.29808430149663057,-0.09300993233259547
196.40000000000208,25.767741516338273,0.3000176713352474,-0.09367163840302606
197.6000000000021,25.882108345714187,0.3018414214915249,-0.09301115230131574
198.80000000000211,25.99834946918437,0.3000611614658652,-0.09300987330107224
200.00000000000213,26.111864863119848,0.3019317343831168,-0.09433012875039859
201.20000000000215,26.226724702537034,0.30166008367163066,-0.09432996800003401
202.40000000000217,26.34207072326898,0.30374236129367427,-0.0943299664251569
203.60000000000218,26.456121782214414,0.30396509622156487,-0.09564776935695685
204.8000000000022,26.57067372060309,0.30534942859799347,-0.09432983788772553
206.00000000000222,26.685151401897382,0.3083069646744946,-0.09426371635563369
207.20000000000223,26.79963147806526,0.308412865703684,-0.09432834291036984
208.40000000000225,26.915192177136653,0.30981155262232374,-0.09853285379834542
209.60000000000227,27.02879534776946,0.3104986680029389,-0.0970618889830388
210.80000000000229,27.143353997517135,0.3133442504021069,-0.09673319908394884
212.0000000000023,27.257511111765098,0.31488557171972786,-0.09761993301636229
213.20000000000232,27.372835659006686,0.3171351843401178,-0.09892946634252109
214.40000000000234,27.487104218201935,0.31927662179559324,-0.09767001487644178
215.60000000000235,27.60309211469398,0.3231324960850593,-0.0979505153472644
216.80000000000237,27.71646328491929,0.3232077786724633,-0.09827925921261604
218.0000000000024,27.831592797401907,0.3224395973093745,-0.10067549702617296
219.2000000000024,27.944334350958744,0.3242587337394227,-0.10221660750204453
220.40000000000242,28.060000855784345,0.32629426460881145,-0.10221974684922008
221.60000000000244,28.17552638754992,0.3276462704798128,-0.10199855624251608
222.80000000000246,28.290412258669612,0.32652248882396984,-0.10221981266861269
224.00000000000247,28.40485940709369,0.3251612209881353,-0.1035391088866584
225.2000000000025,28.51666825451749,0.3288542194155233,-0.10354037319678344
226.4000000000025,28.63392177683134,0.3302540306821783,-0.10446525004687057
227.60000000000252,28.748253068349477,0.3345964227701316,-0.10211984621624515
228.80000000000254,28.862484649506193,0.33610987821690413,-0.10342904654984064
230.00000000000256,28.977555423180757,0.340518733613845,-0.10342980467180718
231.20000000000258,29.09224701181478,0.3432871842886445,-0.10606690016928244
232.4000000000026,29.204866358739707,0.3397270263774308,-0.10605979381202069
233.6000000000026,29.321848158427212,0.3456260536932185,-0.10736868033694869
234.80000000000263,29.435234037281287,0.34394531924006344,-0.10723894499317499
236.00000000000264,29.549694124364994,0.34839549561633304,-0.10672412025094857
237.20000000000266,29.665074843667714,0.3516301530195248,-0.10802533226869881
238.40000000000268,29.779898424550545,0.3574562456617347,-0.10934974737813086
239.6000000000027,29.893755864954258,0.362172849002181,-0.11131505602873393
240.8000000000027,30.006683835868316,0.3694511757253918,-0.11261032065743715
242.00000000000273,30.123613767575833,0.379249241305478,-0.11331023996833878
243.20000000000275,30.2370467870896,0.39135315563696993,-0.11593400379446273
244.40000000000276,30.351519818976875,0.4044305574523182,-0.11592987819410494
245.60000000000278,30.466818035969705,0.4168528202519021,-0.11592220764942507
246.8000000000028,30.582870060996985,0.4325295836525875,-0.11627017153004715
248.0000000000028,30.695370755755352,0.4420716483921102,-0.1175808134873404
249.20000000000283,30.811562283393783,0.4541107329486872,-0.11922411688148937
250.40000000000285,30.925437079847658,0.4810803105299878,-0.12021170037470474
251.60000000000286,31.0402977970266,0.5357468793648283,-0.12284928998998934
252.80000000000288,31.155572576294418,0.6023330656966549,-0.12385264329797074
254.0000000000029,31.27029611604773,0.650910400354191,-0.1251496629543407
255.20000000000292,31.385224127388778,0.6672432933412247,-0.1291961014241787
256.40000000000293,31.50048323727141,0.642062932940183,-0.13043423179431857
257.600000000003,31.615007180136644,0.5728257832634418,-0.13172838645686236
258.80000000000297,31.726747064684115,0.496816043631216,-0.13422573221307665
260.00000000000296,31.844019862554106,0.44035454471379376,-0.13451875426689375
261.200000000003,31.95825747210936,0.4122055341039153,-0.13803790548273254
262.40000000000305,32.07262491329454,0.39633571723720207,-0.1385262674894574
263.60000000000304,32.186945880245176,0.3854332317787773,-0.14116594080137457
264.800000000003,32.300094849170335,0.3812503777587428,-0.1437888014044777
266.00000000000307,32.415150444982814,0.37899876963515056,-0.1456048556761198
267.2000000000031,32.529706686978166,0.3759516406641652,-0.14801287918426276
268.4000000000031,32.64554591856884,0.3768849775302757,-0.15052800510094766
269.6000000000031,32.75742782298022,0.37750991962441566,-0.15300996154980684
270.80000000000314,32.874728719078036,0.377716467155505,-0.15588432341774672
272.0000000000032,32.988908621912785,0.3791997521866851,-0.15960608321802017
273.2000000000032,33.10398992300983,0.3808922593349163,-0.16363051102802917
274.40000000000316,33.21750283301614,0.38076064256201964,-0.16643305048272783
275.6000000000032,33.33300812884519,0.38006611175346966,-0.17043727141951726
276.80000000000325,33.44814135962891,0.3831540324722988,-0.17295082004163165
278.00000000000324,33.562773400226234,0.382440831584429,-0.17687122792584464
279.20000000000323,33.67817827765142,0.38741123625032037,-0.18109365928977095
280.4000000000033,33.79245049467161,0.3855276487421458,-0.18542149522130558
281.6000000000033,33.90722511818098,0.38886656028017075,-0.18973555513096452
282.8000000000033,34.02136194032544,0.3874239368528116,-0.19557866001090218
284.0000000000033,34.13725485312951,0.3895175384347495,-0.1994645318601016
285.20000000000334,34.25236173888753,0.3910899032145385,-0.20444973143884493
286.4000000000034,34.367021933590294,0.39340298039291366,-0.20982161738879945
287.6000000000034,34.4821648038101,0.39477896488719155,-0.2146196165832106
288.80000000000337,34.598211787644644,0.3958599549646829,-0.222322315128463
290.0000000000034,34.712444131665016,0.3964773662185339,-0.22714019221583825
291.20000000000346,34.82676164046419,0.39736267367932643,-0.23352979827249332
292.40000000000344,34.942615314710785,0.3965379315193899,-0.2403565525543203
293.60000000000343,35.057279667229075,0.40067936938966187,-0.2477621347703014
294.8000000000035,35.17257617862832,0.4021128985880592,-0.2543880174338793
296.0000000000035,35.28740851996409,0.4007522522194602,-0.2607345724440129
297.2000000000035,35.4033325075674,0.4033970970902381,-0.27046834635876715
298.4000000000035,35.51617135678772,0.40183893048204955,-0.27838758233071026
299.60000000000355,35.63244124191226,0.3999468611562105,-0.2864807209897515
300.8000000000036,35.748039540528445,0.3994980040141965,-0.2952898602577565
302.0000000000036,35.86264363050768,0.3978997020228119,-0.30393738353648114
303.20000000000357,35.97694967412214,0.401684404468301,-0.3137329138884932
304.4000000000036,36.09343237245396,0.4030897229920635,-0.3255677525815033
305.60000000000366,36.20859103235967,0.4057135260622756,-0.3354188395626161
306.80000000000365,36.324019276761945,0.40843501152789086,-0.34674730873172077
308.00000000000364,36.439616231986115,0.41283826848446936,-0.3570927556201866
309.2000000000037,36.55560673476341,0.41812195892208837,-0.37042150660670004
310.40000000000373,36.670376290636284,0.4220990328444937,-0.3838304899482128
311.6000000000037,36.78546752258563,0.4260109984304711,-0.3965379037049037
312.8000000000037,36.900475126016765,0.43142060286392714,-0.4097367572561792
314.00000000000375,37.016815946332,0.4384918337662301,-0.42620642888583804
315.2000000000038,37.13143418399245,0.44455159976458736,-0.44008306011774767
316.4000000000038,37.24742181342429,0.44850079558918393,-0.4560076432622613
317.6000000000038,37.362802662107725,0.45129866933487284,-0.4726590872319907
318.8000000000038,37.47831392101643,0.4590965826522217,-0.48988490095620296
320.00000000000387,37.593242171798146,0.4632111931402173,-0.5077101752262316
321.20000000000385,37.70969557340424,0.46930509919728125,-0.5289706290750895
322.40000000000384,37.82585011319497,0.477522589762005,-0.547533179630681
323.6000000000039,37.94161506779388,0.48523549417607076,-0.5703106276970145
324.80000000000393,38.05611016989679,0.5004656509791535,-0.5952926093408029
326.0000000000039,38.172026861235345,0.5148875695350813,-0.6182356002106864
327.2000000000039,38.28763634958358,0.5338774010763687,-0.6439715149202754
328.40000000000396,38.40419687048549,0.5567461374638195,-0.67343292656727
329.600000000004,38.52030895461729,0.5815438225277516,-0.7018400108265119
330.800000000004,38.63626293124169,0.6088415872806454,-0.7315391202858086
332.000000000004,38.75380840788823,0.6394918816841871,-0.7639876531161041
333.200000000004,38.86902392503666,0.6694503930600161,-0.7999213078123537
334.40000000000407,38.985157303796946,0.7014285634346826,-0.8357572683285031
335.60000000000406,39.101674248563185,0.7347175538007218,-0.8740582456948633
336.80000000000405,39.21742513703922,0.7688860583602115,-0.915294534921915
338.0000000000041,39.33407699349673,0.7972384339913305,-0.9593139632153722
339.20000000000414,39.450283053112734,0.8300506835803949,-1.004081607080896
340.4000000000041,39.56685087410162,0.8586200450567631,-1.0530233313001522
341.6000000000041,39.68267027960221,0.8866487130821601,-1.1032657832526436
342.80000000000416,39.799902115362514,0.9102028911668096,-1.157025234410093
344.0000000000042,39.91558440945657,0.9321150371158773,-1.2123045571795843
345.2000000000042,40.03155439436982,0.946754095036735,-1.2713020580805803
346.4000000000042,40.147997915908775,0.9527589182541436,-1.3327497932717294
347.60000000000423,40.26442994284828,0.9518691069346112,-1.3942025571719268
348.8000000000043,40.3800009204959,0.9453667020386032,-1.457616860551044
350.00000000000426,40.49650477673632,0.9318557996970562,-1.5194871191887938
351.20000000000425,40.6118820077159,0.9193288399604194,-1.5825244497329676
352.4000000000043,40.72900362812348,0.8969356297675095,-1.6477646130276602
353.60000000000434,40.84449921165478,0.873091998298269,-1.7092675415370637
354.80000000000433,40.96090743323215,0.8419248548874426,-1.7701638791860748
356.0000000000043,41.07730027169288,0.8023678775736656,-1.830431594588315
357.20000000000437,41.19266144986738,0.7571389759375147,-1.8862007051054483
358.4000000000044,41.30847331058728,0.7013602604641124,-1.937826726529385
359.6000000000044,41.42518828984393,0.6421349513552199,-1.990396247582553
360.8000000000044,41.54104227519045,0.5784360467373237,-2.0366118502800536
362.00000000000443,41.6566756186056,0.5144757425505884,-2.0778014777905014
363.2000000000045,41.772035466924706,0.4546475723123028,-2.112936779859524
364.40000000000447,41.8883795391184,0.3947212432439731,-2.146746638731084
365.60000000000446,42.00440313375505,0.3398523240971991,-2.1755066640868375
366.8000000000045,42.119204176446715,0.29321362448355154,-2.19998664648733
368.00000000000455,42.23574046013894,0.2554944631322605,-2.220912772573459
369.20000000000454,42.349523002162194,0.22233310304835824,-2.238591927556733
370.4000000000045,42.467826951047755,0.19694883864580182,-2.253086888893126
371.60000000000457,42.58456106537349,0.17961826082092797,-2.267810501384006
372.8000000000046,42.700266234353904,0.16650155843852654,-2.281825168347981
374.0000000000046,42.81639585544073,0.1572482517140799,-2.29337659508058
375.2000000000046,42.933266623663485,0.1523376099757866,-2.3047232407929967
376.40000000000464,43.04989988957757,0.1475033995204026,-2.3181980746424067
377.6000000000047,43.16612805153152,0.14648721048439628,-2.3276654553377067
378.8000000000047,43.283118437395174,0.14367414291238423,-2.3395993715140264
380.00000000000466,43.39900345740287,0.1429166457159473,-2.34931902459114
381.2000000000047,43.51574503322691,0.14465778304702687,-2.360627113156993
382.40000000000475,43.63249859751519,0.14378171232380155,-2.3712303397759875
383.60000000000474,43.747638173111824,0.14477272167114758,-2.381170290999487
384.80000000000473,43.866437053435575,0.14467520782097654,-2.3934327351117224
386.0000000000048,43.981873494262636,0.14651097940716085,-2.403780562051015
387.2000000000048,44.09989783095749,0.14931375405545377,-2.4152681922529076
388.4000000000048,44.21383890279932,0.14556116186780532,-2.425880959146873
389.6000000000048,44.332902214634345,0.14851808898024466,-2.437548485935853
390.80000000000484,44.45061044241347,0.14830631409149164,-2.448651285390376
392.0000000000049,44.56732734708007,0.14993511556687233,-2.458965395156535
393.2000000000049,44.68488209638649,0.1480018362786658,-2.4708180464734157
394.40000000000487,44.802694310275456,0.15126706362166548,-2.4841037762698805
395.6000000000049,44.918786197331855,0.15116427624916462,-2.4955708172279785
396.80000000000496,45.03656487062649,0.14982766360742944,-2.5088174974899093
398.00000000000495,45.153441647171675,0.14950872920482855,-2.521217930030744
399.20000000000493,45.27180397443851,0.14991646461193886,-2.5345939801776507
400.400000000005,45.38833405230278,0.1502497821761289,-2.548651476798308
401.600000000005,45.50583858467289,0.15246649270378282,-2.562775877867928
402.800000000005,45.622945524282734,0.1569703204878536,-2.575538807221032
404.000000000005,45.74037926996436,0.15535907465297627,-2.589510118432366
405.20000000000505,45.857741070234454,0.1582395939184268,-2.605114830394375
406.4000000000051,45.97265697767423,0.1567724534824937,-2.618461712860005
407.6000000000051,46.09157685908803,0.15869239627753856,-2.6356230482467486
408.80000000000507,46.21029635452847,0.15910071768905082,-2.6518094635359812
410.0000000000051,46.32738833170215,0.16331558661829887,-2.6676785364662816
411.20000000000516,46.44360101270626,0.16226867063217476,-2.6849135150410985
412.40000000000515,46.55971461934224,0.16683556077832806,-2.7002219943788663
413.60000000000514,46.678471516142494,0.16796095407717226,-2.7199066186477623
414.8000000000052,46.796234088830715,0.17111953228700943,-2.737064537941907
416.00000000000523,46.913758408060005,0.17139394689670817,-2.755880290240012
417.2000000000052,47.030304463371614,0.1750430858389519,-2.7751046700758417
418.4000000000052,47.14851287416582,0.1775451231599049,-2.7952590505800363
419.60000000000525,47.266155944025286,0.1795777827286692,-2.8128993507776463
420.8000000000053,47.382502705942436,0.18357643654439693,-2.8332042730157756
422.0000000000053,47.5000948548007,0.1831734397737509,-2.8526170822720767
423.2000000000053,47.61746915064553,0.18595164259377173,-2.8734752180746472
424.4000000000053,47.7346783787154,0.18641707951145992,-2.892951030282851
425.60000000000537,47.85192262629354,0.1888531580548496,-2.914059902397687
426.80000000000535,47.97000087323198,0.18847257130456507,-2.930485185730251
428.00000000000534,48.087359366200474,0.18620430588017645,-2.9527918983275034
429.2000000000054,48.204458417734806,0.18656055311188557,-2.9705638464583197
430.40000000000543,48.32299936101697,0.18831359344898002,-2.988278453142547
431.6000000000054,48.44057043347579,0.1870405717433774,-3.0035068904283584
432.8000000000054,48.558792241354475,0.18930115012266324,-3.0217249445960768
434.00000000000546,48.67676407495835,0.1830744248286238,-3.0377799940747323
435.2000000000055,48.79365566058552,0.17975911280324885,-3.051359642614343
436.4000000000055,48.911878256719646,0.18178345710997246,-3.065398611032103
437.6000000000055,49.02880505442131,0.17888434270643416,-3.0808742078429887
438.8000000000055,49.14675308537829,0.17197338602106926,-3.0942885735058354
440.00000000000557,49.26440528209792,0.16939358774148994,-3.1054300476559487
441.20000000000556,49.38270692787681,0.16125624795257743,-3.117026026151102
442.40000000000555,49.499216625610245,0.16025071162190008,-3.129213722343697
443.6000000000056,49.617193878373946,0.1512523171602026,-3.1409465596368564
444.80000000000564,49.73450616281597,0.1454411432236461,-3.1490207075815912
446.0000000000056,49.85197070716075,0.13761559252930466,-3.1580290365093666
447.2000000000056,49.97036938854223,0.12856828807399312,-3.1672661470265524
448.40000000000566,50.08786756609262,0.12038780707724805,-3.1736189340398364
449.6000000000057,50.20528678477179,0.11414271221806072,-3.185660598793195
450.8000000000057,50.32407587645343,0.10454797918440262,-3.192406318901457
452.0000000000057,50.441421467692145,0.09474802539839866,-3.1986199098237256
453.20000000000573,50.559519033800356,0.08802776699590686,-3.20410641178868
454.4000000000058,50.67743390536303,0.08032601039818066,-3.2115355208972876
455.60000000000576,50.794285750096584,0.07434322692602924,-3.219303991775942
456.80000000000575,50.91241876836261,0.06559740226457644,-3.2221873394270406
458.0000000000058,51.03037608164009,0.0598333499288638,-3.2269598031858138
459.20000000000584,51.14805256412185,0.05042000170276295,-3.2312624515892527
460.40000000000583,51.26692742876017,0.0431048346670867,-3.235817960097512
461.6000000000058,51.383722413027066,0.03835394612421228,-3.2405059903171303
462.80000000000587,51.50256319343544,0.032355890810887744,-3.2438440856142146
464.0000000000059,51.62070077655382,0.027509990277627128,-3.2482596218086623
465.2000000000059,51.73886480383851,0.021959815383220782,-3.2508834555677106
466.4000000000059,51.85606588240616,0.016143315945892134,-3.2548857385311907
467.60000000000593,51.97551202346942,0.014650113857260672,-3.256987592396171
468.800000000006,52.09461892957651,0.012279970395720152,-3.2590194538188655
470.00000000000597,52.21076404536708,0.00461445448940867,-3.261777096979186
471.20000000000596,52.33121899102263,0.00313893992140557,-3.2644347882723412
472.400000000006,52.448491562072995,0.0017615043700209831,-3.2670223689095597
473.60000000000605,52.56713469415723,-0.003705007611997102,-3.268221888090252
474.80000000000604,52.68583367211,-0.0008986945261980628,-3.27225133891091
476.000000000006,52.80377867102439,-0.004628484766631469,-3.273650078882498
477.20000000000607,52.92239195061217,-0.004207502019830778,-3.2762222326904924
478.4000000000061,53.03990866757745,-0.005154897006057313,-3.278282251402541
479.6000000000061,53.1580394433546,-0.007130579046489838,-3.280182615682957
480.8000000000061,53.27633709109641,-0.004510888646683142,-3.281580529406772
482.00000000000614,53.39441121294871,-0.004639480896516446,-3.2841523253283493
483.2000000000062,53.5136579506499,-0.005486010238988426,-3.286765217158166
484.4000000000062,53.631365286785524,-0.0029251354185942935,-3.288143274262362
485.60000000000616,53.74938415154805,-0.007740954593647986,-3.2921944587225163
486.8000000000062,53.86705397072234,-0.0024222975173041617,-3.290801977094744
488.00000000000625,53.98568925126117,0.002077399937505997,-3.291788234133924
489.20000000000624,54.104453865085965,0.006153212193413582,-3.2932395085430444
490.40000000000623,54.22222640425198,0.010303009126754081,-3.2940897323106615
491.6000000000063,54.339999086939635,0.014300143159383882,-3.296719698535159
492.8000000000063,54.45889078065463,0.01629648463522837,-3.2980400819868825
494.0000000000063,54.57713715240046,0.018129655038071513,-3.2978413477153623
495.2000000000063,54.69554890224957,0.018887054239563716,-3.300668561649752
496.40000000000634,54.81457563668709,0.019788010767071373,-3.3005751844916893
497.6000000000064,54.932697367253915,0.02114434688903899,-3.302905537388757
498.8000000000064,55.05234027269252,0.019372323764408228,-3.305278227373984
500.00000000000637,55.17029937385406,0.02068860059206923,-3.3056067150123685
501.2000000000064,55.29029478540234,0.02497942027780342,-3.3042999619057545
502.40000000000646,55.40854715726924,0.02705382998171546,-3.304949915082764
503.60000000000645,55.52846166191944,0.0253171611220262,-3.305645091511519
504.80000000000643,55.6466529401543,0.02825437294768396,-3.3085403502519553
506.0000000000065,55.76568606169502,0.028854065403430607,-3.310540180772005
507.2000000000065,55.885603835257164,0.029159784143822254,-3.3103481785609996
508.4000000000065,56.002797490467785,0.030711583032173473,-3.3088986444573534
509.6000000000065,56.122195213846744,0.03055537938586328,-3.3101726119408754
510.80000000000655,56.24097193467255,0.030577590704283675,-3.3121800154019025
512.0000000000066,56.359315468827305,0.028353145748498343,-3.313459293254931
513.2000000000066,56.479414598861695,0.02977464501649596,-3.316130846204717
514.4000000000066,56.59845119895165,0.026385537698681127,-3.3161321283341167
515.6000000000066,56.717275838264676,0.02869804606678883,-3.316163005283781
516.8000000000067,56.83618728020787,0.027695764945149692,-3.31744986897331
518.0000000000066,56.95535777187681,0.027620371845436753,-3.3200555553804394
519.2000000000066,57.07462723503797,0.03021750704435,-3.321383554399412
520.4000000000067,57.192153593787665,0.030789798956602832,-3.322394478315937
521.6000000000067,57.31333095425949,0.03086693357214365,-3.322718897942874
522.8000000000068,57.43280982771805,0.028810034311851584,-3.322719547647134
524.0000000000067,57.55105456037167,0.030624774098186425,-3.3240376291539255
525.2000000000068,57.6711925973144,0.028545855090388872,-3.3263329089931597
526.4000000000068,57.78999796482012,0.03191463246485837,-3.3276598551298933
527.6000000000067,57.90932023495169,0.028019940650141684,-3.3263398696584083
528.8000000000068,58.02841569834726,0.026256231996631185,-3.3276499935439103
530.0000000000068,58.14776901711245,0.021984162240954896,-3.328411738853272
531.2000000000069,58.26789048993932,0.019576022827850537,-3.3296301600486498
532.4000000000069,58.38708375370038,0.011600066630237937,-3.3309362191883505
533.6000000000068,58.50739612808278,0.01160595876104864,-3.331010827108955
534.8000000000069,58.62468347069634,0.0070569681037705445,-3.3312699712198413
536.0000000000069,58.745921248309244,0.004233376500927699,-3.3332497673851256
537.2000000000069,58.86620222079569,0.0023409414458650524,-3.331925893628186
538.4000000000069,58.986338841079764,0.0005037010585008384,-3.3345404132419874
539.600000000007,59.105404429213,-0.002392749519647519,-3.334560091412603
540.800000000007,59.225141721732285,-0.002398814752680778,-3.335548780496468
542.000000000007,59.34410164356385,-0.007882381145507433,-3.337248170807885
543.200000000007,59.463532222219214,-0.006851698458688049,-3.3368700361260224
544.400000000007,59.58399662668942,-0.008444438215311267,-3.3358808474809134
545.6000000000071,59.70251658996625,-0.008409985957370414,-3.338209668698937
546.800000000007,59.82211629631208,-0.008034287136212015,-3.338187699764915
548.000000000007,59.94204941998408,-0.009368030184162435,-3.3385200784198807
549.2000000000071,60.06227838052551,-0.009239672821892086,-3.3398331007012265
550.4000000000071,60.18152909235977,-0.00980978805228827,-3.3388397519355193
551.6000000000072,60.30156208153666,-0.010052791925966864,-3.3401599791609433
552.8000000000071,60.42041167898171,-0.010501856029935697,-3.3410702075316485
554.0000000000072,60.54021119588017,-0.010422025623755271,-3.3401607286578376
555.2000000000072,60.65907449753236,-0.01174841690076922,-3.342468495640855
556.4000000000071,60.77873078884995,-0.01196289378050952,-3.3437798604723663
557.6000000000072,60.8957927494959,-0.018347469249672343,-3.343780187151588
558.8000000000072,61.01869815942213,-0.018077587217661617,-3.3437800021372936
560.0000000000073,61.13703721814268,-0.01678672833711181,-3.3464076285009137
561.2000000000073,61.25676697619849,-0.016815345105636426,-3.3449783747343056
562.4000000000073,61.37714795134343,-0.02042129158690953,-3.347612807097341
563.6000000000073,61.49730220791497,-0.019370417814143392,-3.346413625549236
564.8000000000073,61.615874367959655,-0.019546514515190405,-3.3477299733890407
566.0000000000073,61.736569491688805,-0.024983426711790546,-3.3491051739220192
567.2000000000073,61.855822601495284,-0.01980126375162905,-3.3503634742648316
568.4000000000074,61.97594932975569,-0.026056799723151336,-3.3489715692705126
569.6000000000074,62.09600541238141,-0.025791366907630953,-3.3490398733178957
570.8000000000075,62.21634544767857,-0.02704284863350903,-3.350359326468264
572.0000000000074,62.335785284679496,-0.024054036768289322,-3.3529934599464863
573.2000000000074,62.45614850483749,-0.02737637669603843,-3.351609990391574
574.4000000000075,62.57509400060539,-0.029086445036148323,-3.3517231595548216
575.6000000000074,62.69591934214615,-0.025029551758929625,-3.3539941789125454
576.8000000000075,62.81545983018188,-0.025273019647494177,-3.3556201330168975
578.0000000000075,62.934895039421924,-0.025452526438417777,-3.355622138564558
579.2000000000075,63.05541832762159,-0.025112033147871804,-3.3569540080249363
580.4000000000076,63.17537013734589,-0.023920614225832137,-3.3569420424466987
581.6000000000075,63.29562529185831,-0.021793882189647507,-3.358250109295559
582.8000000000076,63.414014009135855,-0.022005784877351386,-3.3595729308918165
584.0000000000076,63.534899752752054,-0.02017756459550646,-3.3605597490833867
585.2000000000075,63.65523767682737,-0.023123673862752714,-3.360568584246511
586.4000000000076,63.77437558929368,-0.02739966031260721,-3.3608245988219765
587.6000000000076,63.89539875118328,-0.03061580822578769,-3.3631919773084844
588.8000000000077,64.01590490594299,-0.03526466532273553,-3.3631883597538668
590.0000000000077,64.1361769018665,-0.037186479840492614,-3.364510026822421
591.2000000000077,64.25541457713037,-0.03829815717263818,-3.365034835392426
592.4000000000077,64.37568991027335,-0.03681394071931976,-3.3687695452996453
593.6000000000078,64.49477219609298,-0.03717047627836556,-3.3687122326398597
594.8000000000077,64.614640143274,-0.03650910474277924,-3.370128223517103
596.0000000000077,64.73439222564785,-0.027612653533534592,-3.371423058416827
597.2000000000078,64.85342478874693,-0.027571179806767265,-3.3714270850858226
598.4000000000078,64.97491427340314,-0.021138918122511896,-3.37147433067224
599.6000000000079,65.0956201271247,-0.018861639112937256,-3.3727369215053766
600.8000000000078,65.21520132589026,-0.01985815916762368,-3.3738279347109112
602.0000000000078,65.33562798557996,-0.020990630219772877,-3.3740499439551224
603.2000000000079,65.45558201055537,-0.02358132180324124,-3.373650689163714
604.4000000000078,65.57536307360019,-0.022775724273970344,-3.3753562877505927
605.6000000000079,65.69560607877557,-0.01788949744925228,-3.3753612675581204
606.8000000000079,65.81548765423001,-0.021387929407195028,-3.3756853666670597
608.000000000008,65.9353400595343,-0.021702035019062427,-3.378000021646927
609.200000000008,66.05627194623656,-0.020554104858021782,-3.3793141973836773
610.4000000000079,66.17582090948878,-0.02016919045522192,-3.3779475110659014
611.600000000008,66.29632586712623,-0.021390053853009405,-3.3793109305219566
612.800000000008,66.41608928250149,-0.021045292604550347,-3.3798951888240163
614.000000000008,66.5370174826331,-0.024321350830614152,-3.3799929442361925
615.200000000008,66.65805430120294,-0.026544804888420925,-3.380628763282363
616.400000000008,66.77800302136565,-0.028530462300366377,-3.379320104831314
617.6000000000081,66.89822846873285,-0.026372565956043204,-3.3806301262469662
618.8000000000081,67.01841857051784,-0.02854334539467107,-3.3806504975314247
620.0000000000081,67.13773543094776,-0.029670000360346727,-3.3819499163906324
621.2000000000081,67.25620297567089,-0.029032229150882438,-3.3812175920034875
622.4000000000082,67.37844144848543,-0.033073998348737144,-3.3819449883016923
623.6000000000081,67.49918771378498,-0.03141025413898557,-3.383253074360219
624.8000000000081,67.61938871998736,-0.03558168384428084,-3.383270234525928
626.0000000000082,67.73978843303087,-0.03283960612280801,-3.384579690820007
627.2000000000082,67.85957634250101,-0.03560626484507856,-3.384579929222978
628.4000000000083,67.98077413554653,-0.034479647406089775,-3.3848794302199092
629.6000000000082,68.10139395687027,-0.03587580773149024,-3.386001507170083
630.8000000000083,68.22128401927837,-0.036214413760070396,-3.3850130963866425
632.0000000000083,68.34195220226285,-0.03579898276672133,-3.3850912979736774
633.2000000000082,68.46221963988047,-0.0362777253435953,-3.385019756026127
634.4000000000083,68.58233039699289,-0.039730411981682145,-3.385020006453058
635.6000000000083,68.70302796230861,-0.03792645961916241,-3.3863303586993756
636.8000000000084,68.82314100900795,-0.035087639445212426,-3.3873298715610867
638.0000000000084,68.94363367102932,-0.04049929622940307,-3.3873298720000053
639.2000000000083,69.06335041830177,-0.03594742627895697,-3.3873299088694644
640.4000000000084,69.18373173417723,-0.03974346310434029,-3.387660084179214
641.6000000000084,69.30371192991063,-0.04107224916746044,-3.3876178580670686
642.8000000000084,69.42470016284796,-0.04067893861779592,-3.388635739257905
644.0000000000084,69.54519075016927,-0.045081258771469734,-3.387972255931695
645.2000000000085,69.66570445166923,-0.04390841794044875,-3.3879801039821498
646.4000000000085,69.78636534915731,-0.04317690021023135,-3.3878409445827486
647.6000000000085,69.90727033868454,-0.042806400897508645,-3.389299972026276
648.8000000000085,70.02888176100817,-0.04603484853583906,-3.389299972430682
650.0000000000085,70.15058263848871,-0.04435348777078052,-3.3906092708897875
651.2000000000086,70.27046616510191,-0.045388590833274955,-3.391608165465504
652.4000000000085,70.39179238357639,-0.04760308153328463,-3.3902800140334715
653.6000000000085,70.51249575147366,-0.05227412343297866,-3.391599973607345
654.8000000000086,70.63304183320271,-0.04826924130113586,-3.3902796041211296
656.0000000000086,70.75415881136205,-0.05137300938123235,-3.391268067759789
657.2000000000087,70.87379089928862,-0.047656610387245335,-3.3902903897635586
658.4000000000086,70.99443723229328,-0.049100667298400014,-3.3929108199347877
659.6000000000087,71.11596917490907,-0.04936672722145108,-3.391600051784242
660.8000000000087,71.2374431282693,-0.04924118908378894,-3.3928944514758475
662.0000000000086,71.35791099798098,-0.05208825535254169,-3.391519997639611
663.2000000000087,71.4770791121204,-0.05188205035131799,-3.3928578620629315
664.4000000000087,71.59968910877106,-0.056330531811200846,-3.3929215221114317
665.6000000000088,71.72132076262181,-0.05710942011862863,-3.393514156328334
666.8000000000088,71.84178232301409,-0.06075877267373597,-3.391609963402872
668.0000000000088,71.96144997678655,-0.05890652958744047,-3.392920260145087
669.2000000000088,72.08284557699659,-0.054450611048324715,-3.394271119945727
670.4000000000088,72.20344148579623,-0.060072536730083836,-3.395575121129208
671.6000000000088,72.32324241981661,-0.06204894894463919,-3.3945039036188844
672.8000000000088,72.44512807592398,-0.0598310219524012,-3.394237298376204
674.0000000000089,72.56508599940561,-0.059423698442373496,-3.394890173620876
675.2000000000089,72.68570822864376,-0.059084482134965643,-3.3955499843203887
676.400000000009,72.80613254849787,-0.06286004326773331,-3.3955495361616483
677.6000000000089,72.92640792487924,-0.06343875346375971,-3.3978503319825397
678.8000000000089,73.04828803634744,-0.0627708031993992,-3.39784984396432
680.000000000009,73.16870639083061,-0.06663152544361162,-3.3973573477146637
681.2000000000089,73.2895796709728,-0.06686665129890046,-3.3965295400626356
682.400000000009,73.4096829101532,-0.06371620453463489,-3.3969144653938903
683.600000000009,73.53082288224194,-0.06523823355905134,-3.3969336523583755
684.800000000009,73.65193783498133,-0.06428062555934866,-3.3965561869871506
686.0000000000091,73.77289234182989,-0.06582433753564243,-3.397863059137581
687.200000000009,73.89275832581404,-0.06552021272612962,-3.397859975960958
688.4000000000091,74.01463892001867,-0.06964249545576062,-3.397440424809372
689.6000000000091,74.13500278319923,-0.06836348648437607,-3.3977936436630554
690.800000000009,74.25582988626691,-0.0721165855698993,-3.3991754957053546
692.0000000000091,74.37760810906396,-0.0739228343838656,-3.3978499445652837
693.2000000000091,74.49936556590183,-0.07432752210033677,-3.3988459163362563
694.4000000000092,74.62017799155588,-0.07026716626556606,-3.3988399439654207
695.6000000000092,74.74173026392033,-0.07059540949833432,-3.3978846421611872
696.8000000000092,74.86261787177841,-0.07522776516388374,-3.3988398053027096
698.0000000000092,74.98528946838843,-0.07041372997506312,-3.4001500826455215
699.2000000000093,75.10798763225564,-0.07387524827639713,-3.4001501759999946
700.4000000000092,75.22798388615314,-0.07670237082799058,-3.4001501759999755
701.6000000000092,75.34990657264566,-0.07874093181126174,-3.4001501588547627
702.8000000000093,75.47278511757585,-0.07979668643618276,-3.400479584361428
704.0000000000093,75.59438093922579,-0.07712076175164229,-3.3994918115398267
705.2000000000094,75.71297411207269,-0.0770046516612739,-3.4008139353151825
706.4000000000093,75.83742576665573,-0.07700326634553756,-3.402107693106188
707.6000000000093,75.95970850093688,-0.079648176939487,-3.403450120757706
708.8000000000094,76.08058400308455,-0.07816512050593749,-3.4021050683156524
710.0000000000093,76.20276092291529,-0.08083374362127271,-3.3998095961422257
711.2000000000094,76.32414108734446,-0.08554753660095837,-3.400479859781508
712.4000000000094,76.4454350921976,-0.08408458521950313,-3.401910172631987
713.6000000000095,76.5669423625178,-0.0830540902350616,-3.403544845515649
714.8000000000095,76.68749215239619,-0.08411236412631484,-3.40421084177673
716.0000000000094,76.80880256120349,-0.0839185047646469,-3.402900727129207
717.2000000000095,76.92878754047285,-0.08688524858398772,-3.402897487769278
718.4000000000095,77.0493890427382,-0.08927321779717756,-3.4045482145784582
719.6000000000095,77.17000204528983,-0.08780887244023905,-3.403860364467966
720.8000000000095,77.291280140197,-0.09085508276738374,-3.4028984442477066
722.0000000000095,77.41185276284274,-0.09161719384213352,-3.404864173389592
723.2000000000096,77.53518086949977,-0.09205466331585765,-3.404815517814164
724.4000000000096,77.65504523454698,-0.09282277738030298,-3.40499983948778
725.6000000000096,77.77643396312597,-0.09558713162456312,-3.404880120084036
726.8000000000096,77.89689809483275,-0.09894815182894612,-3.4061805457535046
728.0000000000097,78.01882172721682,-0.099616143165278,-3.4075000799554656
729.2000000000096,78.14095774417116,-0.099576420069037,-3.407535892497446
730.4000000000096,78.26128649186447,-0.09924220220857038,-3.4075121118301306
731.6000000000097,78.3809721054199,-0.10325077011373529,-3.407509948000251
732.8000000000097,78.50461871811156,-0.1027728264872203,-3.4075099515670986
734.0000000000098,78.62639663209158,-0.10467341397382435,-3.4078444298435393
735.2000000000097,78.74861212029752,-0.10138533780880099,-3.4091513611974373
736.4000000000098,78.87021189056385,-0.10745129031545408,-3.409145094571515
737.6000000000098,78.99211312939872,-0.11002297395167782,-3.4078567447662587
738.8000000000097,79.11325336717965,-0.10926019100718443,-3.4091424140737794
740.0000000000098,79.23516831842443,-0.11057074098495723,-3.4099649898062
741.2000000000098,79.35794356817333,-0.11330601934858286,-3.4085082026536617
742.4000000000099,79.47749454431796,-0.11263890167473245,-3.4088226358730367
743.6000000000099,79.59948111327391,-0.11298643534613029,-3.408818402835459
744.8000000000098,79.72120055638776,-0.11296929717614912,-3.408819756229226
746.0000000000099,79.84331191326672,-0.11219192211140028,-3.4087308381728043
747.2000000000099,79.96466367036246,-0.11465397978791714,-3.408490381791759
748.4000000000099,80.0859699742035,-0.11592206646751624,-3.4098100712263903
749.6000000000099,80.20725982039902,-0.11673535938939983,-3.409811443615432
750.80000000001,80.3290171463945,-0.12002589711740774,-3.411719166881408
752.00000000001,80.45120684396895,-0.12275871969776198,-3.410800020154087
753.20000000001,80.57258146601625,-0.12254480449085015,-3.409480873171683
754.40000000001,80.6934018650406,-0.1256122301536582,-3.410800540667443
755.60000000001,80.81561934373828,-0.12651533225656308,-3.409708640882208
756.8000000000101,80.93673174401799,-0.1304817837802934,-3.4098100159691276
758.00000000001,81.05769860009656,-0.13452019701207418,-3.410960487769304
759.20000000001,81.17978570551355,-0.12646431672877667,-3.4114498742760513
760.4000000000101,81.30111258879656,-0.13231879927106838,-3.411450009037448
761.6000000000101,81.42292607289308,-0.12954741953344184,-3.4111198377420378
762.8000000000102,81.54434044006962,-0.12922631061476642,-3.4124391493195243
764.0000000000101,81.66595889069266,-0.12933945652958778,-3.4124401159999103
765.2000000000102,81.78755748846552,-0.13015499561319022,-3.4124401160004014
766.4000000000102,81.90862890195096,-0.1289413337028833,-3.412442700709789
767.6000000000101,82.02922800685427,-0.13333456335922023,-3.412118735266502
768.8000000000102,82.15082227066863,-0.12942521275099406,-3.4134297459502507
770.0000000000102,82.27183999286952,-0.13001362654932525,-3.413753222954054
771.2000000000103,82.39391540366107,-0.1317736916654031,-3.413403925257466
772.4000000000103,82.51576976141473,-0.13344007406280944,-3.4135732955300533
773.6000000000103,82.63801430358379,-0.13529010257056528,-3.4124399334900954
774.8000000000103,82.75961185191807,-0.13606848748700706,-3.4134299690056125
776.0000000000103,82.88114117957137,-0.13700450584227308,-3.414749165851628
777.2000000000103,83.00459339881078,-0.13589919324984345,-3.4147498260493476
778.4000000000103,83.12580660951782,-0.13790921448635052,-3.4133311768451993
779.6000000000104,83.2486445694108,-0.1402694422957218,-3.41599604235867
780.8000000000104,83.3698293919861,-0.1361022873967186,-3.4147500977307095
782.0000000000105,83.4913283755699,-0.13968567913304097,-3.41473807411563
783.2000000000104,83.6124154325984,-0.1402803980820213,-3.415069902618423
784.4000000000104,83.73386314874257,-0.14253159756514,-3.415088833721073
785.6000000000105,83.85528207272134,-0.14190743232711478,-3.4163901842016946
786.8000000000104,83.97763219700211,-0.1440626685997124,-3.4149891485815367
788.0000000000105,84.09855662037464,-0.14542761962728656,-3.4160601575738125
789.2000000000105,84.2210755239483,-0.14782613043402737,-3.4173802132008038
790.4000000000106,84.34210346320268,-0.14644150995399885,-3.4160843908939538
791.6000000000106,84.46446733112911,-0.1417017373609677,-3.415349597798872
792.8000000000105,84.58602677542561,-0.14246958745489646,-3.416669220477032
794.0000000000106,84.70947840588968,-0.14331919569837304,-3.417380051958059
795.2000000000106,84.83090546309555,-0.14738097738153666,-3.4173800515086876
796.0000000000106,84.91198541578446,-0.15234938295936695,-3.4188690255273007