File: 01_Data/Cotton_Rug/STA/N2/10K_min/Cotton_Rug_STA_N2_10KData_220112_R2.csv
##Temp./Â°C,Time/min,DSC/(mW/mg),Mass loss/mg
50.0,10.762945068941171,0.029441464519514793,-0.041677238649963755
51.20000000000002,11.076806957787154,0.06877060184521777,-0.04181032856299982
52.400000000000034,11.295568329968066,0.09714549863149258,-0.043187377942180305
53.60000000000005,11.48278217159048,0.1209702240494892,-0.04310201196522723
54.80000000000007,11.647376990887166,0.13996939840496536,-0.0431880046191262
56.000000000000085,11.805273804931838,0.1528963945377999,-0.04343805651735355
57.2000000000001,11.951079407867152,0.1647593822103791,-0.04425357275739472
58.40000000000012,12.095102775620305,0.1724878715724304,-0.044972109861492804
59.600000000000136,12.233546956044123,0.18128861123587758,-0.04503210847861361
60.80000000000015,12.370397620139236,0.18889189504742343,-0.044979836481625846
62.00000000000017,12.505183500000923,0.19233249591692558,-0.04646943181555674
63.20000000000019,12.639187688646498,0.19776259806646979,-0.046220430550033775
64.4000000000002,12.770102093132143,0.20092326682684603,-0.047051484693668044
65.60000000000022,12.901124266955891,0.20398047453546786,-0.04907430611997121
66.80000000000024,13.030926994252766,0.2092932137283967,-0.0477115001642181
68.00000000000026,13.161004949240885,0.21065683729642137,-0.04902624207324724
69.20000000000027,13.29050062679842,0.21566204620545404,-0.04863720730666987
70.40000000000029,13.418237178525626,0.2145715563429007,-0.047859577568856615
71.6000000000003,13.546017749040626,0.21651681584721377,-0.049029276360900376
72.80000000000032,13.67247796511396,0.2176611231272088,-0.049689708143525024
74.00000000000034,13.7988848727068,0.21972801965545524,-0.051633571122035704
75.20000000000036,13.923693393655235,0.22124192364666412,-0.050349631994484056
76.40000000000038,14.049183903054876,0.2215146236212963,-0.050340488507186976
77.60000000000039,14.176060325013488,0.22513879508557078,-0.05037165817433564
78.80000000000041,14.296139126370875,0.22712557277371226,-0.05164997747322708
80.00000000000043,14.422212735117371,0.22832413933699586,-0.05293734125337046
81.20000000000044,14.54576381758289,0.23042692848290697,-0.05297265087287695
82.40000000000046,14.66911668728898,0.22965217164745827,-0.05297020120265916
83.60000000000048,14.792810838565755,0.23315501235537,-0.0542898112529171
84.8000000000005,14.91455516899515,0.23339639373381021,-0.05546651204269715
86.00000000000051,15.033664831085279,0.23675779633520738,-0.055600505571621106
87.20000000000053,15.156071372904318,0.2376599234791748,-0.05560016652845157
88.40000000000055,15.276935711312579,0.23652895820114417,-0.05703163345480711
89.60000000000056,15.3974380247194,0.23558984410449918,-0.05691999384015478
90.80000000000058,15.51910370649534,0.23608486853050842,-0.05694343981709604
92.0000000000006,15.639415167820589,0.23672161900683664,-0.05824037041091046
93.20000000000061,15.758058863744623,0.2368575431191819,-0.056929812503553556
94.40000000000063,15.877897136940396,0.23663850845376927,-0.05824040625938842
95.60000000000065,15.993807696430439,0.23703033167485493,-0.058240023587058154
96.80000000000067,16.117292952826855,0.23716880414843466,-0.05817810941646595
98.00000000000068,16.234941384224907,0.23564786737385385,-0.05953432258552116
99.2000000000007,16.354215821154046,0.23717127046327918,-0.060801208663800566
100.40000000000072,16.473065896331587,0.23379122586410495,-0.059549752384326915
101.60000000000073,16.590976173073354,0.23821659088779046,-0.06014258404451045
102.80000000000075,16.70913608703394,0.23670800227846073,-0.06055856274702309
104.00000000000077,16.82713475770862,0.2389180201541652,-0.060869014154194545
105.20000000000078,16.944657473599445,0.23742153238990443,-0.0627102951040528
106.4000000000008,17.063307536330743,0.24177882386630645,-0.062184990939204265
107.60000000000082,17.18213925454111,0.24159325348635785,-0.06261898746523054
108.80000000000084,17.300211357046834,0.2425920345143433,-0.0619584693454005
110.00000000000085,17.417799137906425,0.24169952806529582,-0.06131005493910191
111.20000000000087,17.535842851762155,0.24200540289397565,-0.06263495747943137
112.40000000000089,17.65365003004281,0.24181194243867937,-0.063056452796447
113.6000000000009,17.769806090620804,0.2422629561117467,-0.06230001842310795
114.80000000000092,17.888930915385405,0.24596341137824174,-0.0636100907963777
116.00000000000094,18.004642241114677,0.2479631064193084,-0.06493383255646323
117.20000000000095,18.123266068505693,0.24908777572786034,-0.06393998273808466
118.40000000000097,18.24043002772376,0.24638814937402917,-0.06361891979400314
119.60000000000099,18.35840053666148,0.24838053705690005,-0.06230366582255531
120.800000000001,18.475209145602005,0.2504135029921407,-0.06360873544254941
122.00000000000102,18.592243095504738,0.25168723440820984,-0.06361078001765419
123.20000000000104,18.710098183785625,0.2503214544707076,-0.06360892955022468
124.40000000000106,18.826065876392164,0.25390404098072583,-0.06427045074088111
125.60000000000107,18.943969368122676,0.25423828356048694,-0.06295917928520467
126.80000000000109,19.0600000000001,0.2565751528798982,-0.06361993805501776
128.0000000000011,19.17832930301903,0.26014763493578935,-0.0641055787173519
129.20000000000113,19.293301462297098,0.26034785010823425,-0.06360862919196286
130.40000000000114,19.409811617856334,0.2613105632692003,-0.062290120938988114
131.60000000000116,19.52717368360335,0.2618737591569721,-0.06360783739508014
132.80000000000118,19.64302567149847,0.2631908867268164,-0.06496319984751642
134.0000000000012,19.759109472740164,0.2636646255984467,-0.06492398498117558
135.2000000000012,19.874894923190578,0.2657808464006769,-0.06360996019659515
136.40000000000123,19.991699740646563,0.26695698962273245,-0.06497777272372351
137.60000000000124,20.107365423686044,0.27041623129428816,-0.0649304059866056
138.80000000000126,20.22341513305431,0.2689632921248626,-0.06374330424709962
140.00000000000128,20.339461904380077,0.2726547377888044,-0.06493005398454255
141.2000000000013,20.45609255876485,0.2723982560941446,-0.06496076922115135
142.4000000000013,20.572941581111756,0.2737673987242732,-0.06558006695390395
143.60000000000133,20.688177426333255,0.2740956673311381,-0.06490842713306888
144.80000000000135,20.804067451104384,0.2754796041787974,-0.06559022956647143
146.00000000000136,20.918856214342533,0.27528180995229207,-0.06493002669566339
147.20000000000138,21.036075732643198,0.27753781186480786,-0.06589541546442534
148.4000000000014,21.15141670346273,0.28010876021519604,-0.06624997712414427
149.60000000000142,21.265490530650144,0.28096945475031476,-0.06564084354408362
150.80000000000143,21.381761241108904,0.28413083286505514,-0.06558275968861027
152.00000000000145,21.4978588531753,0.28499986590124443,-0.06624008067670939
153.20000000000147,21.611844236794976,0.28749771232227445,-0.06624008000000892
154.40000000000148,21.728640526564558,0.2909095573676811,-0.06623795441306513
155.6000000000015,21.84381152380831,0.28846619908511545,-0.06625005532943096
156.80000000000152,21.958615252241803,0.29244148869367376,-0.06894136361341996
158.00000000000153,22.073248925152534,0.2905595163387538,-0.0678899629369134
159.20000000000155,22.1885853481698,0.2921515434460204,-0.06753904421741463
160.40000000000157,22.304763760552085,0.29445850467797385,-0.06752519427539294
161.6000000000016,22.419702719975195,0.2953300303760899,-0.06887980379098213
162.8000000000016,22.535254016811937,0.2976992953949501,-0.0682310384781708
164.00000000000162,22.650501751396966,0.29922422504288315,-0.068880272817744
165.20000000000164,22.765830701764155,0.3005037799872338,-0.06887600742277433
166.40000000000165,22.881300987320493,0.3016977268765806,-0.06986001327831914
167.60000000000167,22.99586266296648,0.2997502521907664,-0.06986001200000169
168.8000000000017,23.10991285024265,0.30333054660684067,-0.06986001197964731
170.0000000000017,23.226760712564754,0.30448538673307046,-0.0686016610739757
171.20000000000172,23.34140247441033,0.3056752761101537,-0.07018539381934241
172.40000000000174,23.45525518167179,0.3059248728920077,-0.0701907123089276
173.60000000000176,23.57129671390976,0.3087664928027484,-0.07151009038960066
174.80000000000177,23.68550778715926,0.3090144360961555,-0.06952238196246574
176.0000000000018,23.801467433331222,0.30970348603118014,-0.07085228807719801
177.2000000000018,23.916192752101097,0.3111520434402876,-0.0708607779530559
178.40000000000182,24.0311904149027,0.3137207463204571,-0.0721707393641089
179.60000000000184,24.14718073721354,0.31477793140562493,-0.07217176021734728
180.80000000000186,24.26227187580621,0.31570983486739784,-0.07183994470063304
182.00000000000188,24.377076310332072,0.3163267307643677,-0.07183984357997986
183.2000000000019,24.491455690300537,0.3175931689749472,-0.07249997443856415
184.4000000000019,24.606580896459466,0.317020818046142,-0.0725007198837786
185.60000000000193,24.721243571823113,0.31824490088532614,-0.07268597933086118
186.80000000000194,24.835878685967817,0.32044442031904524,-0.07446883818985572
188.00000000000196,24.95065331927161,0.3213139825008814,-0.07315421651443277
189.20000000000198,25.06460987984634,0.32346342257351157,-0.07315639713407363
190.400000000002,25.18039008407404,0.32305713789540913,-0.07549449985970336
191.600000000002,25.295961454031847,0.3233776982905132,-0.07447144437962505
192.80000000000203,25.410493386097947,0.3250380565938592,-0.07447003799983243
194.00000000000205,25.52454345677744,0.3287123477877522,-0.07447414199003566
195.20000000000206,25.63833826205594,0.3318292218772999,-0.07677868106553243
196.40000000000208,25.75381354568616,0.3316732430828164,-0.07677974226682815
197.6000000000021,25.868220926916504,0.3341409878530314,-0.07578819472431597
198.80000000000211,25.982729714577665,0.3355963240061915,-0.07710003975148094
200.00000000000213,26.096675558322314,0.33795686540107206,-0.07709368668858829
201.20000000000215,26.210799689490504,0.3373663264685173,-0.07709653494405
202.40000000000217,26.326019432205925,0.33946057048964984,-0.07841999458213644
203.60000000000218,26.44113805615262,0.34047369635803026,-0.07809003303928685
204.8000000000022,26.553717759053566,0.3406458755029653,-0.07808754329126
206.00000000000222,26.669589546944447,0.3426559577220386,-0.0787501936155266
207.20000000000223,26.78529308796896,0.3434435823268297,-0.07966587358276289
208.40000000000225,26.899292736349853,0.34539577987004466,-0.08005776812470389
209.60000000000227,27.01390657814956,0.34686995787459407,-0.07868681826772939
210.80000000000229,27.129908536494238,0.34757621474830325,-0.07878195540074184
212.0000000000023,27.243303979111907,0.34939129174795236,-0.08137814798534526
213.20000000000232,27.359026851802664,0.3507197016033208,-0.08138005486158795
214.40000000000234,27.4737029948679,0.3535008814816912,-0.08138086910649855
215.60000000000235,27.587939701646583,0.35419406668384157,-0.0813898771274415
216.80000000000237,27.702604007749983,0.35655535038287955,-0.08174548805027326
218.0000000000024,27.81816353829904,0.35637336438776257,-0.08270206815041181
219.2000000000024,27.933465705272962,0.3576269773813514,-0.08399969194513668
220.40000000000242,28.045552252378634,0.36338893826575885,-0.08321946270453795
221.60000000000244,28.160740083849547,0.36190391253709897,-0.08533055288230029
222.80000000000246,28.275982825186375,0.36391120531558696,-0.08400307502591531
224.00000000000247,28.391177791497988,0.36677074850432434,-0.08665009031169424
225.2000000000025,28.50557320341389,0.36757950141547713,-0.08532980551944425
226.4000000000025,28.621276174021336,0.3673401187813779,-0.08532843862460648
227.60000000000252,28.735620150880212,0.3705560279224027,-0.08664029382558347
228.80000000000254,28.849900557716076,0.3733063498130165,-0.08730935831300668
230.00000000000256,28.963187984441987,0.3744903747837283,-0.08928624502496296
231.20000000000258,29.07897226152667,0.3775605716018149,-0.0892773404901499
232.4000000000026,29.19143017672026,0.37982733877474095,-0.09027015790783599
233.6000000000026,29.307125823922632,0.38270671443051296,-0.09061038355355011
234.80000000000263,29.4216586073039,0.3850956595797478,-0.09190980476581823
236.00000000000264,29.53670880472403,0.38875695700928287,-0.09192014105440949
237.20000000000266,29.648478141998513,0.39258631702820335,-0.09389443905937433
238.40000000000268,29.76494617884022,0.3956670952846884,-0.09330638651247636
239.6000000000027,29.87999903723803,0.4021814401177365,-0.09499014205547018
240.8000000000027,29.99526537418526,0.40694533894040086,-0.09499007524009118
242.00000000000273,30.109153471496015,0.4159324524825095,-0.0972798942984272
243.20000000000275,30.224327439294207,0.4282433236846413,-0.09720868066989485
244.40000000000276,30.339337728337856,0.44048021032399376,-0.09991353664489377
245.60000000000278,30.453738090002197,0.45629156058476805,-0.10123770227435358
246.8000000000028,30.567994105430618,0.4700254269527415,-0.102480764788345
248.0000000000028,30.683687476551004,0.48172270787468585,-0.10188413102809779
249.20000000000283,30.798403799935258,0.49264423334473423,-0.1032101833903214
250.40000000000285,30.913206114917326,0.5184235262004419,-0.10453122522320646
251.60000000000286,31.026947110322105,0.5741351385217364,-0.10845943525090807
252.80000000000288,31.14283519629362,0.6410456905546568,-0.10688521881035218
254.0000000000029,31.25756407858811,0.6851093440059886,-0.10955938989009928
255.20000000000292,31.372544599510444,0.7022146024162246,-0.11088964641402077
256.40000000000293,31.488149158373865,0.6755392681567565,-0.11373857539508636
257.600000000003,31.60412963543196,0.604951001706168,-0.11375866169202897
258.80000000000297,31.7194562194428,0.533328470538941,-0.11703108272626528
260.00000000000296,31.833428949396275,0.484258495809292,-0.1196748085062933
261.200000000003,31.947248499996114,0.45655662838521305,-0.12098203633980464
262.40000000000305,32.062337867899,0.4415311232475237,-0.1223065578167164
263.60000000000304,32.17732569695801,0.4330190014829598,-0.1254123153650104
264.800000000003,32.29235977216551,0.4283904438232106,-0.1297734215191566
266.00000000000307,32.40715121963779,0.42650933790988715,-0.13120327622742112
267.2000000000031,32.52247156523788,0.42367320243003437,-0.13095719400961858
268.4000000000031,32.63595797699413,0.42564887145988917,-0.1349546427500754
269.6000000000031,32.75080612400166,0.42451296561597407,-0.13827018914283817
270.80000000000314,32.86636763430726,0.42578595745176195,-0.14094935052119384
272.0000000000032,32.9808296472354,0.4270700561542108,-0.1437917171383627
273.2000000000032,33.095848063582274,0.4302826439016636,-0.14895363234293768
274.40000000000316,33.210290013578124,0.43206068978954504,-0.15006636888798086
275.6000000000032,33.323457959631185,0.4331094629546028,-0.15311791545071207
276.80000000000325,33.438267137113314,0.4358377960574325,-0.1575889787571758
278.00000000000324,33.55467654590742,0.4376035216442464,-0.16138437873640932
279.20000000000323,33.67010077343929,0.4403012357785024,-0.1656251522036527
280.4000000000033,33.78507882315623,0.4401567134124125,-0.16912833556551998
281.6000000000033,33.89954310818041,0.4430718885512808,-0.1731928551933306
282.8000000000033,34.01489614934739,0.4446249516034214,-0.17867407617775344
284.0000000000033,34.130624084354345,0.44494532179566504,-0.18244433189188136
285.20000000000334,34.24270601045792,0.4465812459420622,-0.18668236703208674
286.4000000000034,34.36054544564113,0.4479041475872597,-0.19178786863288133
287.6000000000034,34.47393086736241,0.45087816770247585,-0.19748283874997918
288.80000000000337,34.59064578043066,0.4508796797424899,-0.20336510288727006
290.0000000000034,34.70492336553446,0.4524305659911741,-0.2111061987251901
291.20000000000346,34.8199989463092,0.45600346074448406,-0.21729008036597008
292.40000000000344,34.934585253905134,0.4569429478864727,-0.2230244603222431
293.60000000000343,35.04910707647666,0.45889646142319274,-0.22989838952811725
294.8000000000035,35.16458993158074,0.46010868165869173,-0.23826160484641523
296.0000000000035,35.27922958054821,0.4602703846902737,-0.24324445890276758
297.2000000000035,35.39453000867234,0.4605416067516477,-0.25115664869031695
298.4000000000035,35.509721249826576,0.4588976788709746,-0.260578003334488
299.60000000000355,35.62471115939893,0.4617603154805181,-0.26795342834942604
300.8000000000036,35.74065217894944,0.46466415220333845,-0.27719834957655554
302.0000000000036,35.855411633449165,0.4611323498893354,-0.2856866750820384
303.20000000000357,35.970747153298944,0.4624698623360899,-0.2961269454823441
304.4000000000036,36.08602943081427,0.4634440740171465,-0.304662875313352
305.60000000000366,36.20138919788022,0.46696371110696316,-0.3156610690321484
306.80000000000365,36.31777728709178,0.4706241156218132,-0.326949731565231
308.00000000000364,36.43248102561813,0.4764875943845816,-0.3368880011423818
309.2000000000037,36.54698864776161,0.48146828413688847,-0.35000926410004984
310.40000000000373,36.662531379518114,0.48763080010796844,-0.3616787822496206
311.6000000000037,36.77773974524709,0.49466673283705775,-0.37391764941307937
312.8000000000037,36.8941636353701,0.4993476877363916,-0.3864626384925818
314.00000000000375,37.00907121030193,0.5051664776540199,-0.4013232204159971
315.2000000000038,37.12450593833949,0.5109304360628266,-0.41418203123668684
316.4000000000038,37.24086130438301,0.5174722259988378,-0.42978931488604744
317.6000000000038,37.35567615203612,0.5243650487863085,-0.44723980265065144
318.8000000000038,37.47078219397881,0.5273719862406689,-0.4639552555369253
320.00000000000387,37.58678145922828,0.536291479759301,-0.4808400803914217
321.20000000000385,37.70321124611734,0.5441416855370238,-0.49790889669078675
322.40000000000384,37.819799120897,0.5515681258784734,-0.5216272785975837
323.6000000000039,37.935099362067874,0.5618593832480352,-0.5422634505742288
324.80000000000393,38.05068663755562,0.5744756142009272,-0.5626319491036655
326.0000000000039,38.1671657616792,0.5914668036457296,-0.5866780264606857
327.2000000000039,38.2830163170672,0.6085136914800547,-0.6125821741894959
328.40000000000396,38.39907349463755,0.6324817026706007,-0.6365309739036507
329.600000000004,38.515589160719976,0.6585961058478274,-0.6657061356558067
330.800000000004,38.63215777971418,0.6853324397397303,-0.6952507832205082
332.000000000004,38.74798724760148,0.7144057873581641,-0.726010658563335
333.200000000004,38.86136074197664,0.7466539674133471,-0.7589513685571081
334.40000000000407,38.979789525045305,0.7790558156507652,-0.7943362874906992
335.60000000000406,39.09534949633589,0.8156774499317979,-0.8326336304615167
336.80000000000405,39.21262025324124,0.8509363427218037,-0.8712094507654395
338.0000000000041,39.32872409484823,0.8860604074895422,-0.9124389428262165
339.20000000000414,39.44542171499547,0.9211081206683829,-0.9575036793419476
340.4000000000041,39.562342421590074,0.956224274044748,-1.0057910934596537
341.6000000000041,39.67788992670431,0.9931803525064461,-1.0546377194145955
342.80000000000416,39.79567144607395,1.024678782698723,-1.1096891121911074
344.0000000000042,39.912171178291935,1.054906851552683,-1.1655547114698495
345.2000000000042,40.0276515441545,1.0847622952342304,-1.2240237861606458
346.4000000000042,40.14410895357174,1.1074832267299075,-1.2865918781873829
347.60000000000423,40.262833936775216,1.1234664452201364,-1.353334748214412
348.8000000000043,40.37812224099,1.1301380642471537,-1.417360200281732
350.00000000000426,40.495648555673576,1.12674567328342,-1.4860701750552185
351.20000000000425,40.61122362307796,1.1171584101240224,-1.5553468607002792
352.4000000000043,40.72805321589723,1.100593532922379,-1.6219812568695202
353.60000000000434,40.84413787186081,1.0813499328270533,-1.6907269612309017
354.80000000000433,40.96009292017928,1.056869017175558,-1.7560274459020375
356.0000000000043,41.07753374173679,1.021120435967772,-1.8203980345901738
357.20000000000437,41.19317870988114,0.9793318790021764,-1.8830494712496555
358.4000000000044,41.30939485454894,0.9257009542122404,-1.9458686681720376
359.6000000000044,41.42527732229674,0.8653999674587235,-2.0021735245430596
360.8000000000044,41.54108562482731,0.8015772975616091,-2.054027184784382
362.00000000000443,41.656964615843435,0.7309993889721642,-2.101660502563404
363.2000000000045,41.77285124297408,0.6634112446047543,-2.1454079870109957
364.40000000000447,41.88886967152873,0.5955338351930218,-2.1833615104934454
365.60000000000446,42.00496707923276,0.5343672518349415,-2.2171453318995775
366.8000000000045,42.11949189729711,0.47688026373144027,-2.2444857162306624
368.00000000000455,42.235224862591465,0.4285702554592007,-2.2697835340803065
369.20000000000454,42.35195175920223,0.3868973136925541,-2.290604826190932
370.4000000000045,42.46685044885865,0.3564688927852874,-2.3100567197030024
371.60000000000457,42.581435299667824,0.3334488043175692,-2.3279023454502337
372.8000000000046,42.698834285317204,0.3161116536625903,-2.340761312501712
374.0000000000046,42.81524692594943,0.30241769945319597,-2.353944443864631
375.2000000000046,42.93228251342224,0.2904318338532236,-2.3680662107729233
376.40000000000464,43.04736411612073,0.2876959963697109,-2.3798657780725145
377.6000000000047,43.16411402013881,0.28317295767570916,-2.3903511259294095
378.8000000000047,43.281001892292544,0.28154311903566287,-2.4009304770128255
380.00000000000466,43.39705865051948,0.279060024320318,-2.4147247921697543
381.2000000000047,43.513835086827456,0.27888918543329455,-2.4245762143489413
382.40000000000475,43.629797223631556,0.2808416602396042,-2.4357719640539877
383.60000000000474,43.74646909555618,0.28009472742670016,-2.446204810270065
384.80000000000473,43.863984524158425,0.2799043416821358,-2.45756555031997
386.0000000000048,43.97989493484244,0.27728482579143304,-2.469346555073124
387.2000000000048,44.097443550175576,0.2817594825320959,-2.479522194486883
388.4000000000048,44.21422545546,0.2786633957288976,-2.491517692104079
389.6000000000048,44.331865729677936,0.2810570135173328,-2.503837556684733
390.80000000000484,44.4486720028244,0.2826967153108394,-2.5153068178839812
392.0000000000049,44.56568287998418,0.28236735752725295,-2.5269351719464197
393.2000000000049,44.6817435512484,0.2814273642378764,-2.538246167156002
394.40000000000487,44.799808126544875,0.2838997430212804,-2.5524754320863945
395.6000000000049,44.917916425416024,0.2862565622182834,-2.562703842839217
396.80000000000496,45.03391219323586,0.28539583580706007,-2.5748619187442703
398.00000000000495,45.15086805511763,0.2854203386421282,-2.5874812617367446
399.20000000000493,45.268734627133625,0.2869551759277358,-2.600748807965644
400.400000000005,45.38572132154071,0.29054579319301543,-2.6154156910272843
401.600000000005,45.50310574729506,0.290794152752483,-2.6277318705410693
402.800000000005,45.62110153159448,0.2889642712029638,-2.641379851207319
404.000000000005,45.737600503672105,0.2933526268256356,-2.6578667290777527
405.20000000000505,45.85530606774726,0.29611700084382425,-2.6715278455814597
406.4000000000051,45.97327169109246,0.30021907395975544,-2.6858673164759947
407.6000000000051,46.09020129361704,0.29984714000955703,-2.701495818300914
408.80000000000507,46.20742269429597,0.3001423715481596,-2.716977018657238
410.0000000000051,46.32510807645496,0.3013209205583425,-2.7340927042420535
411.20000000000516,46.44102719468613,0.30543338112444735,-2.750302817632009
412.40000000000515,46.558801839285785,0.31071154206305307,-2.768892505131494
413.60000000000514,46.6758470134448,0.31314895998648734,-2.7873356133260527
414.8000000000052,46.791799520942874,0.3155091641215437,-2.803447553294998
416.00000000000523,46.909327526792424,0.31629689903859776,-2.8235084215786928
417.2000000000052,47.02625908072209,0.317330284232146,-2.842657166503833
418.4000000000052,47.14302197410992,0.32269868992597583,-2.862009748255699
419.60000000000525,47.26102054185778,0.3241339910310573,-2.8840754037709617
420.8000000000053,47.377981842316196,0.32576063930226684,-2.9031956361373763
422.0000000000053,47.4954619908415,0.3274330487885812,-2.923707661946618
423.2000000000053,47.611019757652045,0.33180936413122086,-2.9445024178266737
424.4000000000053,47.729291360928116,0.3294725795730977,-2.964535413252883
425.60000000000537,47.84626584022138,0.3293621582918714,-2.9854299383260283
426.80000000000535,47.96394477581478,0.3308053251905988,-3.0052449845463327
428.00000000000534,48.081715923771746,0.3311593374338834,-3.023840584890795
429.2000000000054,48.19833802817923,0.33404922483162225,-3.0437033666478412
430.40000000000543,48.316309157108684,0.33465992903565434,-3.0618172394480943
431.6000000000054,48.43377968970732,0.3324587704370306,-3.078802751969296
432.8000000000054,48.551963750107916,0.3358246872743116,-3.097124118746291
434.00000000000546,48.669439622145035,0.335564757631792,-3.112730058209467
435.2000000000055,48.78761686002753,0.3310503778658762,-3.1286350794331326
436.4000000000055,48.90485447489075,0.3298502905370085,-3.143079085543331
437.6000000000055,49.02366838562261,0.32702995718360356,-3.1555639795649686
438.8000000000055,49.14114994862502,0.32310653473973744,-3.1701543315491785
440.00000000000557,49.259899081533284,0.3160216630812805,-3.183011092990148
441.20000000000556,49.37779365175508,0.31438288292095334,-3.1933641595442164
442.40000000000555,49.496451737157706,0.3065137860202736,-3.205196879311889
443.6000000000056,49.61326195720087,0.30205576887301055,-3.2148193575410438
444.80000000000564,49.730845773730444,0.29560135599264753,-3.2258602437619266
446.0000000000056,49.848936001790236,0.29086036275323013,-3.2346212548618984
447.2000000000056,49.966760554553204,0.2832277744913421,-3.2421395160029864
448.40000000000566,50.08383860740489,0.27527028785553237,-3.2520886176642785
449.6000000000057,50.201702349775665,0.26897347599980964,-3.259620146187487
450.8000000000057,50.320181292927195,0.2605429896922849,-3.266888250561319
452.0000000000057,50.43865011762307,0.2531368457810016,-3.2728187407670117
453.20000000000573,50.55572619679837,0.24759176597333493,-3.280271704397884
454.4000000000058,50.672819908610506,0.24135912587795483,-3.2856472563497165
455.60000000000576,50.7908911935119,0.23371412756516424,-3.2926115787828216
456.80000000000575,50.9081732024108,0.22612741060333047,-3.2968607478389425
458.0000000000058,51.025867984569935,0.21917061371555502,-3.30128730293432
459.20000000000584,51.14368768785903,0.2141078822998696,-3.3067799586001314
460.40000000000583,51.26118055381285,0.2063434982923048,-3.3105456881420374
461.6000000000058,51.38038634153158,0.20345929896939713,-3.3156094587774985
462.80000000000587,51.496543197893864,0.19780648202213957,-3.3193669659303118
464.0000000000059,51.615127439285466,0.19129067168525327,-3.3237207913261706
465.2000000000059,51.73293604835534,0.186931408689335,-3.3265638473746533
466.4000000000059,51.85051146050933,0.18427833891391365,-3.3306229429946415
467.60000000000593,51.96999897441648,0.18059304563922152,-3.3322601837997516
468.800000000006,52.08780249844316,0.17849443498028372,-3.3350054775253035
470.00000000000597,52.20655030499838,0.175640081469138,-3.337791462354583
471.20000000000596,52.325158411965866,0.17572953168608063,-3.3402362928426927
472.400000000006,52.44381259839064,0.17122626083506498,-3.343233177037948
473.60000000000605,52.55980822686652,0.16917219005248463,-3.3455395676069686
474.80000000000604,52.680590601602475,0.17192250974179912,-3.3481696781285963
476.000000000006,52.79946905182582,0.17087364694202634,-3.3507685043088355
477.20000000000607,52.91746185090759,0.16974740097181917,-3.3521445850854654
478.4000000000061,53.03556510671319,0.16607912935937086,-3.35473874935293
479.6000000000061,53.15437470457776,0.16724755039789263,-3.3560702427054796
480.8000000000061,53.27270037729408,0.16793590604694286,-3.3545370657337688
482.00000000000614,53.390569470926714,0.16904018530282672,-3.356106369418239
483.2000000000062,53.50947885524973,0.17085764819381566,-3.3587424687383782
484.4000000000062,53.62820513188226,0.1720765455384291,-3.360666027704929
485.60000000000616,53.74522802319677,0.17369071307718087,-3.361979256372628
486.8000000000062,53.863662836488444,0.17818049873737163,-3.3623081416954372
488.00000000000625,53.980795712275835,0.18464016711527886,-3.364445765581442
489.20000000000624,54.09988088792686,0.18746748946650482,-3.3656932279993343
490.40000000000623,54.21730731619827,0.19140029311301754,-3.367347200033085
491.6000000000063,54.33622836078068,0.19559207250585342,-3.368463757867216
492.8000000000063,54.454747682614766,0.19658195162979153,-3.370376006386057
494.0000000000063,54.57243746399577,0.20068712685183498,-3.373175330318679
495.2000000000063,54.690492299292686,0.20289082986443208,-3.373169361288143
496.40000000000634,54.810101898029224,0.20529262018302108,-3.3744905075426925
497.6000000000064,54.92927678279773,0.20651790108768198,-3.37445618893644
498.8000000000064,55.047569407343694,0.211368499973686,-3.377119638116233
500.00000000000637,55.16589806962509,0.2116794998156164,-3.3770349701498006
501.2000000000064,55.284853425873585,0.21001105931980912,-3.3789630040835017
502.40000000000646,55.40240364132435,0.2120373793128244,-3.3797494514208464
503.60000000000645,55.52308804820502,0.2145909052644297,-3.3818630706141164
504.80000000000643,55.64084023791557,0.21214558821437746,-3.381724342690495
506.0000000000065,55.76063895786815,0.21694803126176032,-3.3823921276947497
507.2000000000065,55.88038551692504,0.21247908652540648,-3.383660634345411
508.4000000000065,55.99862792759626,0.2141594605687258,-3.386500536650691
509.6000000000065,56.117938924644015,0.21620634646134584,-3.386315545641436
510.80000000000655,56.23650246266108,0.21545190133707848,-3.3866117271420717
512.0000000000066,56.35605717605411,0.21475021889581425,-3.387646372084946
513.2000000000066,56.47598317142689,0.21302029246075238,-3.388969893877631
514.4000000000066,56.59491042147657,0.2136273637036964,-3.3902914091318803
515.6000000000066,56.714575123184744,0.21318157254876746,-3.390279690109903
516.8000000000067,56.83301155068232,0.21728759968589295,-3.3916393852751803
518.0000000000066,56.952810808637736,0.2167620439275758,-3.3916008243241733
519.2000000000066,57.07220394132563,0.2155105821385248,-3.3929216696420155
520.4000000000067,57.19092823712976,0.21616047338876043,-3.394211003296434
521.6000000000067,57.30921354365091,0.2140958379568042,-3.3965401261953634
522.8000000000068,57.429684981404044,0.2133805018604854,-3.3965304490126105
524.0000000000067,57.54855679511115,0.21213747403457694,-3.396841578693188
525.2000000000068,57.66696855812463,0.20615339856314363,-3.396744668479869
526.4000000000068,57.7871888290554,0.20444522759605765,-3.398912936392854
527.6000000000067,57.90630502131721,0.20397835744108084,-3.3994900969807
528.8000000000068,58.0257084696739,0.20338017936170028,-3.3997924552303775
530.0000000000068,58.145300808860014,0.20022796029923706,-3.402129007005273
531.2000000000069,58.263879960976986,0.19826842940395495,-3.4031019117828425
532.4000000000069,58.38453052819788,0.19773769159886767,-3.403439882969591
533.6000000000068,58.50401599965025,0.19736748827425843,-3.4031071701170004
534.8000000000069,58.62279884023108,0.19669572997253648,-3.404430018454013
536.0000000000069,58.74282494219792,0.19760535980690264,-3.405102358243197
537.2000000000069,58.86227826261068,0.1968708812144624,-3.406984586273428
538.4000000000069,58.98198689331846,0.19516743106956536,-3.407470334179809
539.600000000007,59.10186925930806,0.1937596967264077,-3.4087108386335925
540.800000000007,59.22051313933086,0.19622960685473723,-3.410019924695315
542.000000000007,59.34039692108524,0.19557759749330939,-3.4100196558883136
543.200000000007,59.46022312666219,0.19695471452446178,-3.4100296679996216
544.400000000007,59.579609079638956,0.1947806332397104,-3.412330146195095
545.6000000000071,59.69960341672869,0.19964458182272837,-3.413299170098659
546.800000000007,59.81915933907697,0.1945661842261226,-3.41265989798793
548.000000000007,59.9385220806913,0.1920647365827326,-3.413921271750466
549.2000000000071,60.05815010974128,0.19255202151529638,-3.4139804879456093
550.4000000000071,60.177591656188554,0.19066481894127718,-3.4149599801208748
551.6000000000072,60.297164960106805,0.19370096947033422,-3.4162771444663713
552.8000000000071,60.41679173194266,0.19068124251071483,-3.4172701359561684
554.0000000000072,60.53646116546431,0.19344840202434943,-3.4172701031632533
555.2000000000072,60.65576707152962,0.19646959960597232,-3.418571018779976
556.4000000000071,60.77545730825736,0.19581556447232074,-3.4192432389329666
557.6000000000072,60.89398029206256,0.19648874293590912,-3.420234421514771
558.8000000000072,61.014334779297755,0.19484885189524237,-3.420550105666167
560.0000000000073,61.13382150334681,0.19527083273630863,-3.4218958334503538
561.2000000000073,61.253289237296556,0.19457431312688034,-3.422860418851732
562.4000000000073,61.37279285504074,0.19042044251580592,-3.422987149945932
563.6000000000073,61.492432913666946,0.19419940152297632,-3.423509326159392
564.8000000000073,61.61250558011053,0.19237386826143454,-3.4241749408994853
566.0000000000073,61.731105736454964,0.19600032901468967,-3.436480838887817
567.2000000000073,61.850976402148476,0.1912668848444723,-3.4325549068987247
568.4000000000074,61.970614786557036,0.19187380709025226,-3.429945355293428
569.6000000000074,62.0911143498619,0.19348307361198724,-3.4296627124760732
570.8000000000075,62.20969707104912,0.18917263524269434,-3.426592695266087
572.0000000000074,62.32971737450154,0.19011612593735938,-3.425244943869183
573.2000000000074,62.44850583459936,0.18778006219855237,-3.4271732689679406
574.4000000000075,62.56909596847024,0.1926928893147304,-3.4272488655638593
575.6000000000074,62.68694548424984,0.1873690624680162,-3.4302944868193292
576.8000000000075,62.80819598418667,0.19203922689052433,-3.4325200649100083
578.0000000000075,62.92656210373698,0.19106808436514067,-3.433866920059551
579.2000000000075,63.046091289503124,0.1915557208916545,-3.4356096058497876
580.4000000000076,63.1661937886004,0.19391515195783826,-3.4384422933144627
581.6000000000075,63.28529820244344,0.19403475866348463,-3.439748571658622
582.8000000000076,63.40548582405062,0.19183259930107965,-3.43978749502367
584.0000000000076,63.525204183113054,0.18575166825197775,-3.4360760958351335
585.2000000000075,63.64457774501318,0.192725942835423,-3.4351080228440307
586.4000000000076,63.76540726861528,0.18357334792017832,-3.4314535131409953
587.6000000000076,63.88483944875879,0.18057127053437116,-3.432429773931431
588.8000000000077,64.0039898271177,0.1800791790947267,-3.438526707208325
590.0000000000077,64.1251007696133,0.18057794788622683,-3.4416042412066505
591.2000000000077,64.24434899114517,0.1791580851385448,-3.4439137314421817
592.4000000000077,64.36455803012032,0.18179757353305948,-3.4465472782160487
593.6000000000078,64.4842152997878,0.18355937997931648,-3.4465581074205094
594.8000000000077,64.60393724434776,0.18708150121012568,-3.447869300583199
596.0000000000077,64.72343228185608,0.18881278344933694,-3.449509760651488
597.2000000000078,64.84384854924338,0.1913256823014451,-3.4508284088048358
598.4000000000078,64.96387067088233,0.19297485202742148,-3.4521394690201097
599.6000000000079,65.08334368293325,0.1949979846169423,-3.4511601849514366
600.8000000000078,65.20245564072891,0.198982398358708,-3.451160432008656
602.0000000000078,65.32395223975364,0.19586633955967758,-3.4521501122376814
603.2000000000079,65.44382945668656,0.19457595719069976,-3.45346029420008
604.4000000000078,65.56299322382938,0.19873554341736654,-3.4527538005005285
605.6000000000079,65.68315937587698,0.19700209763772447,-3.4537901651512812
606.8000000000079,65.80348763820344,0.1965464948681397,-3.4540792914779646
608.000000000008,65.92393752738899,0.20012205757020984,-3.4554400779570624
609.200000000008,66.04431331481122,0.19462648859582732,-3.4554194737082433
610.4000000000079,66.16486483324721,0.1950639349324792,-3.456805433238878
611.600000000008,66.28547058366914,0.19599478009494886,-3.45740469154401
612.800000000008,66.40633869578627,0.192450739122213,-3.458400017789441
614.000000000008,66.5259965718467,0.1932710412673324,-3.457756148660936
615.200000000008,66.64686418000056,0.19362775075601868,-3.4590600405221648
616.400000000008,66.76646366233132,0.19264670268263195,-3.4603485468048936
617.6000000000081,66.88657786471339,0.19284896599963908,-3.4608164019308694
618.8000000000081,67.00749725600659,0.19561172914710268,-3.459776699282158
620.0000000000081,67.12777984970462,0.19647490177262283,-3.460380725738665
621.2000000000081,67.24828957307822,0.19587622626315615,-3.4609122126108334
622.4000000000082,67.36799155018754,0.19227703542502428,-3.4623440885368977
623.6000000000081,67.48917955861451,0.19657091197666365,-3.4610306653859384
624.8000000000081,67.60816273010845,0.19306859790788966,-3.4623501763181546
626.0000000000082,67.72913657571272,0.19457428764271079,-3.4626384543819366
627.2000000000082,67.849047661932,0.19234388430155747,-3.4630002014698364
628.4000000000083,67.97010296998958,0.19222597079938697,-3.4633461263625787
629.6000000000082,68.08892740590652,0.1913836987552795,-3.463010068117623
630.8000000000083,68.21120675425398,0.1923275163958833,-3.4616900835258053
632.0000000000083,68.33155039311468,0.1969698530422921,-3.46282779215843
633.2000000000082,68.45303639899839,0.1911838960233585,-3.463942441364197
634.4000000000083,68.57304727351624,0.19091997398326366,-3.4639887521152684
635.6000000000083,68.69364130643822,0.19449280648138711,-3.4653098326420997
636.8000000000084,68.81414669241101,0.1935091372804285,-3.464329369053745
638.0000000000084,68.93414257661637,0.19672415381167996,-3.465630369149319
639.2000000000083,69.05465141074681,0.1969213783707946,-3.465629973083559
640.4000000000084,69.17564385551711,0.19184656522017574,-3.466883710444843
641.6000000000084,69.29712152407292,0.19485140731962236,-3.467282251942577
642.8000000000084,69.4180674856922,0.1972165904501657,-3.466263727071344
644.0000000000084,69.53824980115688,0.19902898512615885,-3.4676093851406344
645.2000000000085,69.65882092955624,0.19740503452621283,-3.466633129024441
646.4000000000085,69.77919333468692,0.2002049625556528,-3.4666301239996717
647.6000000000085,69.90000230293856,0.20139908903495307,-3.466630137386678
648.8000000000085,70.02076433271266,0.2001319420140797,-3.4679398803594736
650.0000000000085,70.14019191775958,0.19960592246779907,-3.4676075371639787
651.2000000000086,70.26136162619939,0.1975036693268133,-3.4676063079064416
652.4000000000085,70.38189925679916,0.19406171379539972,-3.468930193913955
653.6000000000085,70.50125514979943,0.19382893813969493,-3.467615077467359
654.8000000000086,70.62458566380322,0.19852813749608766,-3.4696687174748133
656.0000000000086,70.74629523716094,0.19865685634108643,-3.469592977568433
657.2000000000087,70.86736470476065,0.19929982693376624,-3.4709029859509375
658.4000000000086,70.98754835981454,0.19747179943670767,-3.4699201743938803
659.6000000000087,71.1081269264394,0.19738560386311366,-3.471226856282282
660.8000000000087,71.23046264130342,0.19531120024639637,-3.471229845521831
662.0000000000086,71.35128064072691,0.19641913522827004,-3.4712298380000024
663.2000000000087,71.47208174905064,0.198266963372439,-3.47122983799697
664.4000000000087,71.59314790568168,0.19748304856094956,-3.471190266123732
665.6000000000088,71.71462839516252,0.20169031278356764,-3.472539999596499
666.8000000000088,71.8352977000547,0.19965597034598326,-3.4725405968379013
668.0000000000088,71.95603695938105,0.20040455075063135,-3.47303932584787
669.2000000000088,72.07545269093376,0.19755777064474467,-3.4738612300135356
670.4000000000088,72.19620321149985,0.19924918079783627,-3.472552907776599
671.6000000000088,72.31633371803626,0.19781083964074875,-3.473860303153044
672.8000000000088,72.43733509190884,0.19660088840056522,-3.4748498639662766
674.0000000000089,72.55844388490736,0.19653920959692206,-3.474199124458476
675.2000000000089,72.67886897063394,0.19751141504174297,-3.4741998955245537
676.400000000009,72.80010915032534,0.19679442001016234,-3.4751800043627625
677.6000000000089,72.92176348103297,0.19942113111028048,-3.4751799740000546
678.8000000000089,73.04222539372351,0.19750392252612947,-3.47517996799473
680.000000000009,73.16284780780664,0.19729760329827517,-3.4755103460320376
681.2000000000089,73.28357343401973,0.19920327762109902,-3.476830000885802
682.400000000009,73.40364165746328,0.1971201887406413,-3.47551263861415
683.600000000009,73.52433598542527,0.2030984316603648,-3.476831843660873
684.800000000009,73.64484868648177,0.2045112239926603,-3.4768272351501612
686.0000000000091,73.76570191454978,0.20449167677676972,-3.476820120000758
687.200000000009,73.88650205216311,0.20360810052878753,-3.4768201205997564
688.4000000000091,74.00812044357123,0.2054695786053744,-3.4781392062834864
689.6000000000091,74.1289572170176,0.20430158208310067,-3.4768250456936602
690.800000000009,74.24989896909577,0.20101307465389406,-3.4774819125165477
692.0000000000091,74.37052486053916,0.20452843211299232,-3.4775002717070915
693.2000000000091,74.49096618830514,0.20534575082740059,-3.478140193920916
694.4000000000092,74.61257473443483,0.20426629997193846,-3.4794501901016925
695.6000000000092,74.73314025166049,0.20525961828834638,-3.4794490707066617
696.8000000000092,74.8546017780528,0.2015948979331763,-3.478869477509211
698.0000000000092,74.97518056659243,0.20401459437996783,-3.479562512782062
699.2000000000093,75.09630286338925,0.20142576813040347,-3.4794598440078044
700.4000000000092,75.21717161094395,0.2005249116659933,-3.4794598429709374
701.6000000000092,75.33810258334452,0.20160223637661612,-3.4807733495272113
702.8000000000093,75.46000098902262,0.20457038266097216,-3.480780156
704.0000000000093,75.58198053539627,0.19952773283489922,-3.4807801560176452
705.2000000000094,75.7019172682289,0.19777556749017688,-3.479458205326975
706.4000000000093,75.82245353015064,0.19766320184788322,-3.4818479229154042
707.6000000000093,75.94453722174474,0.19879296613426067,-3.4817599120122438
708.8000000000094,76.06506190993215,0.19790661322086245,-3.4817599169736964
710.0000000000093,76.18615329698184,0.20104134806120522,-3.481086871044202
711.2000000000094,76.30802616438257,0.1991045963952709,-3.481324628010256
712.4000000000094,76.43054128622703,0.19578650208163273,-3.48093809612756
713.6000000000095,76.55031434363502,0.19652283476290244,-3.480469782369121
714.8000000000095,76.67238596101018,0.19627022744465772,-3.481762747255184
716.0000000000094,76.792338560759,0.19754139421143013,-3.481109962540004
717.2000000000095,76.91359294984252,0.2000766010446262,-3.482419372366417
718.4000000000095,77.03493189735558,0.19963399602611176,-3.4824201359998903
719.6000000000095,77.15652722502905,0.1996285158901323,-3.4824201359859526
720.8000000000095,77.27694705972324,0.2016423166250385,-3.4821432591423607
722.0000000000095,77.39804957429406,0.2026529635325578,-3.4834102354571006
723.2000000000096,77.52010257294921,0.2035597028494367,-3.482420360138697
724.4000000000096,77.64032680621783,0.20075228093121122,-3.482419743607436
725.6000000000096,77.76232919625478,0.2036381917526815,-3.4837399995533844
726.8000000000096,77.88391735531378,0.2032336700180879,-3.4850460608327687
728.0000000000097,78.00498161075545,0.20833362379128917,-3.4853044436380007
729.2000000000096,78.12688087708747,0.2003492096200139,-3.4865661304428555
730.4000000000096,78.24787797994857,0.19803460786495308,-3.4838414027259557
731.6000000000097,78.36938834307121,0.19540473627809907,-3.4838203091330113
732.8000000000097,78.49064553013511,0.19777495616021734,-3.485160016025028
734.0000000000098,78.61020362191385,0.19544721731715042,-3.4851600159078004
735.2000000000097,78.73272072791315,0.19630879922676847,-3.486478119028397
736.4000000000098,78.85611481899521,0.19920571911114204,-3.485185554896242
737.6000000000098,78.97796551937749,0.19527713111776812,-3.4865046926502528
738.8000000000097,79.09788811080634,0.19797122605405315,-3.487790084287061
740.0000000000098,79.21949728650664,0.19731309730863855,-3.4864800825084235
741.2000000000098,79.34154878722073,0.1978811180195792,-3.486487317693264
742.4000000000099,79.46192481051571,0.19559136775164876,-3.487462186603281
743.6000000000099,79.58512188652576,0.19694394486810363,-3.488124050862945
744.8000000000098,79.707228277677,0.19846647863837896,-3.4874699893835794
746.0000000000099,79.82793291255179,0.19602701486491925,-3.4880834638895077
747.2000000000099,79.94959686400078,0.19843009149356128,-3.4887797144306276
748.4000000000099,80.07057192428238,0.19626540774618206,-3.4891106697704823
749.6000000000099,80.19141749241018,0.19686217945712414,-3.4881220394124575
750.80000000001,80.31403499016781,0.20160641123403478,-3.4894145580011204
752.00000000001,80.4347523037184,0.20037273803832223,-3.489440135996681
753.20000000001,80.55718828433788,0.20366838855951652,-3.489440136052535
754.40000000001,80.67736168349249,0.20332822929718475,-3.4901725542394493
755.60000000001,80.79865334028591,0.20256500498275765,-3.4888797014094486
756.8000000000101,80.92019433384738,0.20330065104363504,-3.4901000280501626
758.00000000001,81.04225954979421,0.20578886872223157,-3.4894401316744554
759.20000000001,81.16441571683119,0.2062317681698298,-3.4907494367924015
760.4000000000101,81.28607363479392,0.2007244959739949,-3.4917129703861782
761.6000000000101,81.40878705462556,0.2034725663154937,-3.4907016293414634
762.8000000000102,81.52961513757636,0.2033971098773666,-3.4920701099936107
764.0000000000101,81.65258472081622,0.20748723846542694,-3.4920701099999794
765.2000000000102,81.77388322038878,0.2005085624724856,-3.4920701101693794
766.4000000000102,81.89588332360809,0.2047012566441384,-3.492118065784206
767.6000000000101,82.01711169613237,0.20034289762838942,-3.4920698660045497
768.8000000000102,82.13823346865603,0.2042066211900182,-3.492069830361399
770.0000000000102,82.25882226305802,0.20163513280048884,-3.4933798450765177
771.2000000000103,82.38028563656245,0.20370829780368105,-3.493390002917062
772.4000000000103,82.50128896987106,0.20776215509213758,-3.4923997634819086
773.6000000000103,82.62258119073039,0.20286396343544988,-3.49355935741772
774.8000000000103,82.74409621772828,0.20764633722489378,-3.493719698750083
776.0000000000103,82.86583502041331,0.20718296009099113,-3.4940497066818645
777.2000000000103,82.98682956638521,0.21110044493898705,-3.493084046090944
778.4000000000103,83.1081470414174,0.206861157989513,-3.4940501617195876
779.6000000000104,83.23000195363701,0.20755684151762965,-3.494050161999466
780.8000000000104,83.35176908703215,0.2093824557170274,-3.494704142497784
782.0000000000105,83.47211274764196,0.20779533791891458,-3.4943694310878275
783.2000000000104,83.5942988880838,0.21341430946295414,-3.49435052479458
784.4000000000104,83.71768412764409,0.21085651424565377,-3.4940399227041743
785.6000000000105,83.83885305527707,0.21015254103414094,-3.495359926072357
786.8000000000104,83.96043396576358,0.2107305108541433,-3.494039855641139
788.0000000000105,84.081950721776,0.21388080691902545,-3.4953600201858297
789.2000000000105,84.20425962201864,0.2136900765289771,-3.495359768299778
790.4000000000106,84.32586971147813,0.2147637956052746,-3.496669891198442
791.6000000000106,84.44940120662663,0.21206196997563165,-3.496317610948216
792.8000000000105,84.57071667233578,0.21202399546744788,-3.49502654080216
794.0000000000106,84.6931860814636,0.2136124125369956,-3.4950375500507986
795.2000000000106,84.81497262977412,0.20872484137627811,-3.496350077005753
796.4000000000106,84.93686298331583,0.21078800315716073,-3.4956900228024805
796.8000000000106,84.97732804698593,0.21238847162732277,-3.49569014142945