File: 01_Data/Cotton_Rug/STA/N2/10K_min/Cotton_Rug_STA_N2_10KData_220113_R3.csv
##Temp./Â°C,Time/min,DSC/(mW/mg),Mass loss/mg
50.0,10.742408069056617,0.037082992087419164,-0.009173814749579456
51.20000000000002,11.065359799751205,0.07827031331207701,-0.0066272483317932895
52.400000000000034,11.288994970575851,0.10697316024687287,-0.007907267565000708
53.60000000000005,11.47424984757776,0.12883114962995623,-0.008538834631013792
54.80000000000007,11.639955952045048,0.14865070329857477,-0.008198054081650419
56.000000000000085,11.796693335436988,0.16052875134855127,-0.008075339388367908
57.2000000000001,11.945613290106271,0.17289739295080941,-0.007261780507512583
58.40000000000012,12.088221477944256,0.18003237261776806,-0.007638909178370845
59.600000000000136,12.227659088365941,0.1893005344645906,-0.0073893134152873685
60.80000000000015,12.362941759764432,0.19819423071034792,-0.008770035680776722
62.00000000000017,12.499430247073455,0.20056906060333773,-0.008738825755826518
63.20000000000019,12.631946739414008,0.2059150895027526,-0.007830077110527967
64.4000000000002,12.762789761293353,0.21114130984262736,-0.008709335861593281
65.60000000000022,12.893768437340123,0.2172887754726468,-0.010064325274939279
66.80000000000024,13.025409366621435,0.22017019461753629,-0.00878118458490551
68.00000000000026,13.154613193829492,0.222445438678244,-0.008766596701065943
69.20000000000027,13.284768287670552,0.22411902927182203,-0.009755859145024637
70.40000000000029,13.412295775707008,0.2265331585815974,-0.010745182345083037
71.6000000000003,13.540905356747736,0.22906862913195414,-0.010026479666466415
72.80000000000032,13.667840453898839,0.22925969546842817,-0.01141387273230432
74.00000000000034,13.795298719303771,0.23040078980438705,-0.011752596402221371
75.20000000000036,13.92334311034754,0.235054357655344,-0.011285494082764913
76.40000000000038,14.047716853962122,0.23627049430531438,-0.011360212685119997
77.60000000000039,14.173567631338084,0.23615774297725045,-0.012693924768935716
78.80000000000041,14.296775441321497,0.24023739202547045,-0.012370369547848092
80.00000000000043,14.421383816092991,0.24058086984633498,-0.014030232557508349
81.20000000000044,14.541919754249166,0.2436285088320398,-0.014026347788604454
82.40000000000046,14.668497834415819,0.2459215314005132,-0.01406430295863803
83.60000000000048,14.791830807190225,0.24587132152361224,-0.014039807306019725
84.8000000000005,14.91380990576588,0.2472131168608156,-0.015349917258512313
86.00000000000051,15.03590376460731,0.24886475514181855,-0.01418776443502967
87.20000000000053,15.15715331087068,0.25168293056943786,-0.015030611549176065
88.40000000000055,15.27838798536151,0.25206920239355585,-0.01667588935744213
89.60000000000056,15.399269858977807,0.2501770732227717,-0.01667008490239219
90.80000000000058,15.518500038963818,0.25222490665362984,-0.01667005400094368
92.0000000000006,15.638401903681942,0.2532765210193736,-0.01636737636363428
93.20000000000061,15.75784546661141,0.2530445458910577,-0.016669797779911733
94.40000000000063,15.878300222038638,0.2532809919643911,-0.01666993584076959
95.60000000000065,15.997617885603212,0.25144494046861793,-0.017990155436836908
96.80000000000067,16.116657346743214,0.25148753504430943,-0.016792883785132773
98.00000000000068,16.235782219743303,0.2524632452379112,-0.018103603775238675
99.2000000000007,16.35403506222839,0.2518874834763719,-0.01941260445381765
100.40000000000072,16.472072487328038,0.24943170087825042,-0.018090069914070916
101.60000000000073,16.590086961106653,0.2519409755899467,-0.019080517615473802
102.80000000000075,16.709694448774112,0.24919919747458721,-0.018098240424713197
104.00000000000077,16.827648511867398,0.2496768026542183,-0.019420233287426925
105.20000000000078,16.94563363292657,0.2526146748342869,-0.01942031420277779
106.4000000000008,17.0633327403441,0.2516125913735814,-0.02040295610978493
107.60000000000082,17.18255847547545,0.25039058233908057,-0.02039976890527928
108.80000000000084,17.29890202417587,0.2509036241482344,-0.020399143249727913
110.00000000000085,17.41660507297205,0.25188633318167264,-0.01941956388159305
111.20000000000087,17.534632017770114,0.2531810810014561,-0.019565148919824082
112.40000000000089,17.652458239362993,0.25277135195532574,-0.02083388571205891
113.6000000000009,17.769753236427253,0.25253677929497087,-0.019410100346227033
114.80000000000092,17.887076614298554,0.25319087445676447,-0.02072979211773074
116.00000000000094,18.004786740527777,0.25321427176265965,-0.019876593741412485
117.20000000000095,18.121045227689976,0.2507679442172256,-0.020730014524227514
118.40000000000097,18.238689418499778,0.2526404116071304,-0.019409446906743177
119.60000000000099,18.35637334090537,0.2544521310167385,-0.020535642403469723
120.800000000001,18.473768209921737,0.2545065849947293,-0.020729940349728082
122.00000000000102,18.590631070379978,0.2541969779940727,-0.019946678744932278
123.20000000000104,18.707926912724083,0.25574321267529854,-0.02126703363404303
124.40000000000106,18.824704227873397,0.25716739187235443,-0.02037311798239827
125.60000000000107,18.94197279037031,0.2566387881104599,-0.021375717968910912
126.80000000000109,19.057865414263514,0.25964065344417164,-0.020937728477496087
128.0000000000011,19.175174971914537,0.26053271701792696,-0.022270047100535706
129.20000000000113,19.291659371696166,0.259296833016797,-0.021232763318552728
130.40000000000114,19.40802244416468,0.2613658431936668,-0.022334233727593578
131.60000000000116,19.52488717154847,0.2596268784856045,-0.021600021668579217
132.80000000000118,19.641146309444583,0.2620794316300147,-0.02130309137489128
134.0000000000012,19.758164843154816,0.2631250546525771,-0.022249482827126243
135.2000000000012,19.87494868101372,0.2654815787049646,-0.02357971947025561
136.40000000000123,19.991661987059693,0.2653864143702782,-0.022269670065849567
137.60000000000124,20.107743830777764,0.2683001048408089,-0.022929969289308794
138.80000000000126,20.223556211078485,0.266651740019114,-0.02255426789608883
140.00000000000128,20.33966727632062,0.26797925985514115,-0.022260426447986426
141.2000000000013,20.455301892294113,0.2681730036363076,-0.021858378284012936
142.4000000000013,20.570982997501805,0.2698377882331143,-0.02291988861156824
143.60000000000133,20.686298242423387,0.2704815039666449,-0.0240799461290937
144.80000000000135,20.801870316757544,0.27176680034472445,-0.022919871832619343
146.00000000000136,20.918175401741944,0.2741319299483699,-0.022963887220844192
147.20000000000138,21.03229870691741,0.2748522207850055,-0.02073530793451539
148.4000000000014,21.14852430896254,0.27642344841980016,-0.023360501134672695
149.60000000000142,21.26541098321388,0.2779290168641589,-0.023360114758424366
150.80000000000143,21.379936567543865,0.2773026823076901,-0.02204082240037053
152.00000000000145,21.494990934421235,0.2807460573073725,-0.022049237407067324
153.20000000000147,21.60966271283933,0.2808253317864884,-0.02335986042291971
154.40000000000148,21.725645884909476,0.28290426750562464,-0.023357603747622413
155.6000000000015,21.840415446320044,0.2828112501808734,-0.023359832657094515
156.80000000000152,21.955896058737334,0.2850982675284488,-0.023359835276572483
158.00000000000153,22.072016566733147,0.28657069278157743,-0.024673294539024226
159.20000000000155,22.187498287412012,0.2901449440612358,-0.023359412931191592
160.40000000000157,22.30228457306084,0.2887421806435438,-0.023388821440303076
161.6000000000016,22.41769328717279,0.28912278483371306,-0.024687716166225115
162.8000000000016,22.53320816496964,0.29040052156999163,-0.023363744367244976
164.00000000000162,22.648646482607266,0.2927458296571574,-0.02373842250287428
165.20000000000164,22.76183766753112,0.29345738018148526,-0.023369964008498556
166.40000000000165,22.875443587607275,0.29332274134904646,-0.023370696202114516
167.60000000000167,22.991499800305352,0.294078148170066,-0.024679964304982427
168.8000000000017,23.109267911619185,0.29563878912447783,-0.024347921090416946
170.0000000000017,23.22433351882702,0.29443045356283815,-0.024350121003675618
171.20000000000172,23.340686774635607,0.29611831267941735,-0.02407330771301286
172.40000000000174,23.455425157583555,0.29951803140544275,-0.024350121085931598
173.60000000000176,23.570298922578665,0.2999788518034704,-0.025603988623186247
174.80000000000177,23.685732806542543,0.30133321593443624,-0.02501402323409785
176.0000000000018,23.801550779333592,0.30223454753069234,-0.024880926943834147
177.2000000000018,23.916751629608488,0.30476366206029937,-0.024990539982685078
178.40000000000182,24.031331949353255,0.3056879380349339,-0.025659878886046705
179.60000000000184,24.145176108682307,0.3068028268035603,-0.025659869000002722
180.80000000000186,24.261219589384822,0.3084939320743254,-0.025659876188898423
182.00000000000188,24.375659969340433,0.30888239361549485,-0.024612610019996595
183.2000000000019,24.49056032665963,0.30823326016705777,-0.02566984221592694
184.4000000000019,24.60637839727861,0.3103645242068184,-0.025669841999977017
185.60000000000193,24.71962396122485,0.3110695921937585,-0.025669166876700622
186.80000000000194,24.835058320642464,0.3134417549636812,-0.02697962998654191
188.00000000000196,24.950393182063195,0.31083222608194305,-0.025659978635013125
189.20000000000198,25.064343296837794,0.31207794756535007,-0.025659999003720735
190.400000000002,25.17890160524179,0.3132118317717988,-0.025682510303761674
191.600000000002,25.294736399037436,0.31512335233808525,-0.026981274916474618
192.80000000000203,25.408781394444564,0.3154748126259531,-0.02764012674907157
194.00000000000205,25.52245508021222,0.3194838615940766,-0.027640369860616687
195.20000000000206,25.636871813111636,0.31702071307529794,-0.025774710057163475
196.40000000000208,25.752374890386825,0.3211854886026765,-0.0270879258684511
197.6000000000021,25.86563480424346,0.31975755236880166,-0.027315856834314367
198.80000000000211,25.980612819279756,0.3218709419214879,-0.028410023699105835
200.00000000000213,26.09547184239046,0.32105303852048517,-0.028079651198346767
201.20000000000215,26.209481739624078,0.3245401323257868,-0.029060168407951004
202.40000000000217,26.324479538566504,0.3238291683559379,-0.029059893998808484
203.60000000000218,26.439264371709164,0.32469961360783217,-0.029083898343614578
204.8000000000022,26.553328561247962,0.32534919721354016,-0.030389298016697985
206.00000000000222,26.66679439287873,0.3266480454146523,-0.03130653392623106
207.20000000000223,26.78241971642503,0.32582201165474467,-0.030379893884338927
208.40000000000225,26.898389797264738,0.3282376653517137,-0.030379894000174268
209.60000000000227,27.012146229953387,0.3309679971319497,-0.030379552089075723
210.80000000000229,27.125544396900864,0.3302968204529844,-0.03169987430992549
212.0000000000023,27.24029993181339,0.3319776419099449,-0.031699894673608675
213.20000000000232,27.356177252744857,0.33484225413746865,-0.030273892056554175
214.40000000000234,27.469994455638513,0.335434664345256,-0.0328998920618675
215.60000000000235,27.58393844629315,0.3390762435631583,-0.034222792238362665
216.80000000000237,27.6994357779291,0.3390474202074758,-0.03289982032919614
218.0000000000024,27.812959998679123,0.33963631983411613,-0.03290221676300753
219.2000000000024,27.927828723104202,0.34247618692525855,-0.03290598495573338
220.40000000000242,28.041915381242106,0.3432465743675965,-0.033507669175193655
221.60000000000244,28.156497567313505,0.344110653994516,-0.035540036685262955
222.80000000000246,28.270982590052288,0.3468383515856933,-0.03554012500001047
224.00000000000247,28.386231723763743,0.34543417359894807,-0.03554013310581894
225.2000000000025,28.499799937608188,0.3461110126370577,-0.036512162604566356
226.4000000000025,28.6158594754723,0.34676117449616195,-0.036850125039558534
227.60000000000252,28.731444496604464,0.34896923710833944,-0.03685012058011239
228.80000000000254,28.845389641794203,0.34953975584833213,-0.035868916442708176
230.00000000000256,28.960253054228478,0.35283081819831047,-0.03848928106353089
231.20000000000258,29.07398908286031,0.35351055300274953,-0.03981034723488719
232.4000000000026,29.188260344496513,0.35580127689092356,-0.039810400757901654
233.6000000000026,29.303781516544003,0.3574153748553034,-0.03881691515127983
234.80000000000263,29.41866554665196,0.36218529411597405,-0.04112999644460391
236.00000000000264,29.53284358441325,0.3636858032956468,-0.04113003765999412
237.20000000000266,29.64817717492174,0.37028851329265705,-0.04246563005409332
238.40000000000268,29.762117570781335,0.37259596087469105,-0.043769754969545716
239.6000000000027,29.87661211253046,0.37938053702104835,-0.042777246404948066
240.8000000000027,29.991816985418367,0.3885572147094075,-0.044094715046123056
242.00000000000273,30.105084091201473,0.3977976220873199,-0.046752458722438384
243.20000000000275,30.22118383156889,0.4092078672364521,-0.04672011698673195
244.40000000000276,30.33458709941297,0.42068718911792435,-0.04673859826235738
245.60000000000278,30.450583913250334,0.43557922977159214,-0.0480959878386793
246.8000000000028,30.565281172356787,0.45205187319929596,-0.050670414968900346
248.0000000000028,30.681263956417173,0.4630699878219207,-0.050747103576832764
249.20000000000283,30.795445690201543,0.47664270846263046,-0.05266337178422198
250.40000000000285,30.91033524408457,0.5021392764786551,-0.05327772741150216
251.60000000000286,31.02534231556119,0.5611060455398111,-0.054615912251750665
252.80000000000288,31.14103576706664,0.6338479038789419,-0.05592863774906309
254.0000000000029,31.256019100954777,0.6883656122527578,-0.058240121466046624
255.20000000000292,31.37188231165162,0.7014653770607364,-0.05956676035206776
256.40000000000293,31.4872411587258,0.6693210292684498,-0.06116497687375144
257.600000000003,31.601928687216922,0.5910459022941201,-0.06273578630686849
258.80000000000297,31.71601851218509,0.5162251112657823,-0.06428242703905784
260.00000000000296,31.831332504004763,0.46282279001845317,-0.06749336147310903
261.200000000003,31.94425934565143,0.4361195794589439,-0.06878160679818812
262.40000000000305,32.0593718918032,0.4174371571282309,-0.07142082713383235
263.60000000000304,32.17436545180512,0.4107069176677848,-0.0737095578080913
264.800000000003,32.288498152029796,0.40499895282698556,-0.07501913200178123
266.00000000000307,32.40227060613382,0.4038953864457055,-0.07774101446679005
267.2000000000031,32.516804563218194,0.4001971780821829,-0.07943402804902888
268.4000000000031,32.63122904713808,0.40320245160838564,-0.08279810896035755
269.6000000000031,32.7451767451132,0.40462562469353947,-0.08705702909850821
270.80000000000314,32.859786689723116,0.40425670097199706,-0.08851413136214337
272.0000000000032,32.97335728440721,0.4038121181245155,-0.09125570400896876
273.2000000000032,33.089245552456866,0.4049269801851886,-0.09508828633661048
274.40000000000316,33.20410352311416,0.4043652299883596,-0.0985093339138996
275.6000000000032,33.318659710841494,0.4091312647752926,-0.1011870899157743
276.80000000000325,33.43252304150977,0.4088900003507103,-0.10459710499045549
278.00000000000324,33.5473018630841,0.41063492842511995,-0.10969311736360954
279.20000000000323,33.662049983631874,0.40897911842220935,-0.11305132139216756
280.4000000000033,33.777280063243914,0.41155444769509053,-0.11854051390371367
281.6000000000033,33.891803288719686,0.41117818310381565,-0.12276480834259518
282.8000000000033,34.007738097440765,0.4134577186759631,-0.1271389153547111
284.0000000000033,34.12283902288493,0.41355468876616747,-0.13142958390384463
285.20000000000334,34.23770287722919,0.4148675796422369,-0.13715337089990598
286.4000000000034,34.353321500133546,0.4172972002268302,-0.14335961103870565
287.6000000000034,34.46788443167642,0.42212455532554927,-0.14782791710896825
288.80000000000337,34.58220585263906,0.42298424170747656,-0.15384752429704251
290.0000000000034,34.69823387678537,0.42750410090303614,-0.15889833387279406
291.20000000000346,34.813761832798384,0.4265963291746675,-0.16728988120176602
292.40000000000344,34.928697776661124,0.4273287586922568,-0.17374128670535827
293.60000000000343,35.0441832832698,0.4283123490562222,-0.17941942397728372
294.8000000000035,35.15897545345054,0.4309239255051196,-0.18394001675826566
296.0000000000035,35.27404793307942,0.4299486501867559,-0.1917638093832883
297.2000000000035,35.38868301767137,0.43114593138252233,-0.20111327020498226
298.4000000000035,35.504127804845915,0.4308252744831474,-0.21086567669441036
299.60000000000355,35.61868606829164,0.42966910002038167,-0.220098799886697
300.8000000000036,35.73373306199971,0.43041332486498235,-0.22935378868730494
302.0000000000036,35.849716939640544,0.42965456487906273,-0.23840508696584717
303.20000000000357,35.96519867039144,0.43071212925124885,-0.24832016375402333
304.4000000000036,36.08079557210424,0.4322457419697443,-0.25905311545089926
305.60000000000366,36.19665547615497,0.4348203184802998,-0.2690447252870354
306.80000000000365,36.31241912654723,0.43926424370639194,-0.28028423366148747
308.00000000000364,36.427988253721566,0.4431852153104009,-0.29230674508070065
309.2000000000037,36.54299121113449,0.4478494288527727,-0.30426278041633736
310.40000000000373,36.65826079546456,0.4538933371469344,-0.31831131942745694
311.6000000000037,36.773500131573,0.46011161133071854,-0.3310653840713491
312.8000000000037,36.88935294804641,0.4627131045994489,-0.3444401789359648
314.00000000000375,37.0048525329921,0.47361486179406387,-0.36088281472693895
315.2000000000038,37.121142915130925,0.47581707160690506,-0.3750797927167122
316.4000000000038,37.236287955211786,0.4805719744907362,-0.3926053885902885
317.6000000000038,37.352154036817,0.4861778775685887,-0.40925333433106426
318.8000000000038,37.46755305786498,0.49204376302017383,-0.42622239643215654
320.00000000000387,37.58223020979818,0.49969606615781076,-0.4462311479106824
321.20000000000385,37.69851501956778,0.505492835112674,-0.4654734707162924
322.40000000000384,37.81507748660379,0.5131083683992559,-0.4866570605811509
323.6000000000039,37.931083744328525,0.5240310678916765,-0.5100235241527957
324.80000000000393,38.04680064888859,0.5382920316780311,-0.5329211455187313
326.0000000000039,38.162461759171165,0.5524449387467462,-0.5591938147927618
327.2000000000039,38.2792745890228,0.574337570089391,-0.5860779959947626
328.40000000000396,38.395448123021374,0.5977421683481576,-0.6143427855356345
329.600000000004,38.51123405182707,0.6256618826932414,-0.6435094811314963
330.800000000004,38.62790500998007,0.6571389589551593,-0.6742443373338003
332.000000000004,38.74439252455157,0.689802566757288,-0.7115414230963881
333.200000000004,38.86051183593092,0.7211175959323843,-0.7453089698782711
334.40000000000407,38.97719901533612,0.7556014223019181,-0.78459198012819
335.60000000000406,39.093088574996465,0.7895942061611345,-0.8248129644328617
336.80000000000405,39.20897689349608,0.820724709783403,-0.8683076710556183
338.0000000000041,39.3257714713237,0.8553638245340187,-0.9129822480796754
339.20000000000414,39.44176925221095,0.8877751323188947,-0.9606671443799439
340.4000000000041,39.5567949966655,0.9136956563208185,-1.0107862837356811
341.6000000000041,39.67482082551116,0.9438485806338044,-1.0631086542342034
342.80000000000416,39.79124249402204,0.9657169955826146,-1.118945328772317
344.0000000000042,39.90852727513019,0.9869815549993567,-1.1798997553120278
345.2000000000042,40.02389638635595,0.9924874162481162,-1.2406148488673026
346.4000000000042,40.14053388107358,0.9971343378338708,-1.3052607573765425
347.60000000000423,40.25737297347827,0.9918354591417211,-1.3697497936858056
348.8000000000043,40.37353329868579,0.9831594755554106,-1.435191902117833
350.00000000000426,40.48936065148428,0.965198134696001,-1.5008166082894863
351.20000000000425,40.60589722034866,0.9474769913880134,-1.5658366134561992
352.4000000000043,40.72321991047152,0.9220304589623565,-1.6317888006687489
353.60000000000434,40.838772531826756,0.8880272875759656,-1.6948432872742805
354.80000000000433,40.95543845037019,0.8529908811532518,-1.7590039490261193
356.0000000000043,41.07170787338734,0.808224214134533,-1.8183352524501069
357.20000000000437,41.18736887230547,0.7569293786287905,-1.8756917459417641
358.4000000000044,41.30319290559683,0.699891447933865,-1.9289468365632247
359.6000000000044,41.42064849962774,0.6365545036756048,-1.9808753521114157
360.8000000000044,41.53481962081823,0.5732156946044304,-2.026656276892662
362.00000000000443,41.65139230884675,0.5113827346438545,-2.0657992606400404
363.2000000000045,41.76807865017127,0.45105809622688486,-2.101332916199316
364.40000000000447,41.88332715201363,0.4001370587417194,-2.1314513263451
365.60000000000446,41.99916909826761,0.34760729088660414,-2.1588396119850493
366.8000000000045,42.11572433793249,0.30942341466809675,-2.183341874044155
368.00000000000455,42.23078896459014,0.2784538327186926,-2.2030644777365014
369.20000000000454,42.34812217283881,0.2489168302749042,-2.2216092001017707
370.4000000000045,42.46353986068543,0.23048020762521032,-2.2358864897706345
371.60000000000457,42.57852634413202,0.21897285830963165,-2.2483729501207117
372.8000000000046,42.69512554913938,0.2076046056912294,-2.2635252947880913
374.0000000000046,42.811561998111806,0.20308681515141974,-2.2765609231491646
375.2000000000046,42.926662409587415,0.20084946900127099,-2.2880431843830937
376.40000000000464,43.0436931999861,0.19470950313553398,-2.2998949283192385
377.6000000000047,43.16046990970921,0.1956364145869507,-2.310785186918374
378.8000000000047,43.2763983992169,0.1938075662302643,-2.321648348303596
380.00000000000466,43.39342640485744,0.19211241292137005,-2.3324287656590172
381.2000000000047,43.51078299366997,0.19101167089895765,-2.3441641297809057
382.40000000000475,43.627082275030915,0.1906311796786891,-2.3544545836304396
383.60000000000474,43.74315157032862,0.19153351031594962,-2.366294948340975
384.80000000000473,43.860134660387445,0.19281493677094047,-2.376998841689766
386.0000000000048,43.977812354663065,0.19378425325678506,-2.39036866650367
387.2000000000048,44.094639437601884,0.19380696196735425,-2.400603792139395
388.4000000000048,44.21145318530962,0.1922635735038946,-2.4117663489799126
389.6000000000048,44.32764175853844,0.19526270060332684,-2.422923014534259
390.80000000000484,44.445601085852765,0.19790232638275823,-2.4343586573657827
392.0000000000049,44.562849086388994,0.19409024323823687,-2.446437162950233
393.2000000000049,44.679169055654974,0.19587287072549003,-2.4582720417316035
394.40000000000487,44.79652305700184,0.19542390055567443,-2.470723632646542
395.6000000000049,44.91260997025987,0.1956209050209471,-2.4834201790923194
396.80000000000496,45.02959480077135,0.1987706326425988,-2.4951825889019505
398.00000000000495,45.14651648389139,0.19857448632053798,-2.5084765844181844
399.20000000000493,45.26305592953909,0.19886744689308616,-2.5215149378391946
400.400000000005,45.3802565737654,0.1971622875483665,-2.5342996242581064
401.600000000005,45.497163200510116,0.19695013405798018,-2.5483247179405977
402.800000000005,45.61457903227047,0.20024233937194658,-2.5628865585355296
404.000000000005,45.73152553563038,0.2006490023902029,-2.576679127507547
405.20000000000505,45.84896734110001,0.19973526883755816,-2.5911987716304123
406.4000000000051,45.96650805740253,0.20298624660912828,-2.6057766066234285
407.6000000000051,46.0832245188902,0.20500420623362026,-2.621669252321395
408.80000000000507,46.20175640124156,0.2072118468464788,-2.6381323666875263
410.0000000000051,46.31710150617558,0.20986058942223262,-2.652167183260266
411.20000000000516,46.4348926086671,0.21314345012757935,-2.6710108749973713
412.40000000000515,46.55203611500626,0.21445307250702528,-2.689247951868533
413.60000000000514,46.669744061635384,0.21801577467885846,-2.7067564524327627
414.8000000000052,46.78626059636725,0.220589263686492,-2.724063685887996
416.00000000000523,46.90338923451871,0.21800606047254367,-2.745058432402954
417.2000000000052,47.02143141547254,0.22158532538058406,-2.7629219423181537
418.4000000000052,47.13857020221136,0.22337834328337403,-2.7828198377511746
419.60000000000525,47.25566892552871,0.22697796360060862,-2.8028974898255337
420.8000000000053,47.37299950431627,0.2276220259119086,-2.8237636521205234
422.0000000000053,47.49064859885353,0.23118509956871103,-2.840784025861513
423.2000000000053,47.60801766146865,0.2347330739408996,-2.8619423692916452
424.4000000000053,47.726188190702956,0.23399948681719807,-2.8832186927420533
425.60000000000537,47.84349882650265,0.23945899774768775,-2.903032476910162
426.80000000000535,47.961543285919696,0.2431858864304094,-2.9225833632950353
428.00000000000534,48.079170000000516,0.2433251177946918,-2.941780168000068
429.2000000000054,48.1956514469096,0.24492547339274617,-2.9601252588789073
430.40000000000543,48.31343421301119,0.24600204744179754,-2.9781441170253093
431.6000000000054,48.43046833777436,0.24500160709410213,-2.996147567768742
432.8000000000054,48.548887163917726,0.24574823820425795,-3.0119464474490165
434.00000000000546,48.66711901000496,0.24552287361577196,-3.0276098488121437
435.2000000000055,48.78453357807042,0.24374887042652027,-3.0433208789016493
436.4000000000055,48.90275907831552,0.2414377014153095,-3.0576518974390203
437.6000000000055,49.01988244596726,0.23620302275123717,-3.0710470559204666
438.8000000000055,49.13766754603067,0.23527838266392342,-3.083883927478639
440.00000000000557,49.25477947915417,0.2289351621254253,-3.0971507039343376
441.20000000000556,49.373572894552936,0.2229540128255867,-3.1074600535008567
442.40000000000555,49.49079421158453,0.21622309016554164,-3.119346505180925
443.6000000000056,49.608688564763106,0.2136549246054349,-3.128854168639637
444.80000000000564,49.7275993124278,0.20609711524610386,-3.1395285612603985
446.0000000000056,49.84520680086619,0.19927160793851184,-3.150351155386752
447.2000000000056,49.96275783130398,0.19218665678920244,-3.1592042772522517
448.40000000000566,50.0808636734218,0.1836213654322959,-3.1688300316644833
449.6000000000057,50.198481586920025,0.17369848531199594,-3.1780929358512604
450.8000000000057,50.31690667223238,0.16722746793512155,-3.183672965679683
452.0000000000057,50.435603476661626,0.15680733758440224,-3.1900223951204256
453.20000000000573,50.553189602138204,0.14995771107336897,-3.196936542512656
454.4000000000058,50.67084797937835,0.1408002079064219,-3.203455372213427
455.60000000000576,50.789944503512245,0.13189871034151546,-3.2093680628589984
456.80000000000575,50.90725336656706,0.12387813029889927,-3.213470109454587
458.0000000000058,51.02487566564511,0.11668449943473314,-3.2197319597357525
459.20000000000584,51.14273393816208,0.1083712719826232,-3.223928271430858
460.40000000000583,51.26110834071592,0.1033598428393886,-3.228484411991291
461.6000000000058,51.378971316446226,0.09700009748882721,-3.2339291591030648
462.80000000000587,51.497472952892934,0.09133117150696068,-3.2382470408332664
464.0000000000059,51.61494724359062,0.08618652548741323,-3.241170944659836
465.2000000000059,51.73369515856493,0.08190172579322808,-3.2446668366532263
466.4000000000059,51.852691244569435,0.07758442459244763,-3.2484659280838892
467.60000000000593,51.97044116485859,0.072985895751571,-3.250618385501486
468.800000000006,52.08873230112908,0.06961250181239997,-3.2554843782108853
470.00000000000597,52.20463335493333,0.06888027501959959,-3.2566267170473124
471.20000000000596,52.32482290815199,0.06544469881299597,-3.259521327440509
472.400000000006,52.442670526686385,0.06300502345625714,-3.2612001035630875
473.60000000000605,52.560839666191235,0.05972914960256914,-3.264609584736456
474.80000000000604,52.67951171732703,0.05981306051664337,-3.2658993307610333
476.000000000006,52.797168459701034,0.05951641412320352,-3.268540312007163
477.20000000000607,52.9155005283051,0.056828771094833974,-3.269790397082103
478.4000000000061,53.03369187728737,0.053639651980652236,-3.2738963365419758
479.6000000000061,53.15285948085918,0.05029014353091865,-3.2751969685725126
480.8000000000061,53.270956426819346,0.05126610971798684,-3.276666742364149
482.00000000000614,53.389170000000654,0.05114496578796268,-3.2778600161294307
483.2000000000062,53.50703520317546,0.04987583246904137,-3.2818049505855615
484.4000000000062,53.62566718334383,0.05134448995141716,-3.28309759727061
485.60000000000616,53.744739659639464,0.050570861722117666,-3.283061841838587
486.8000000000062,53.863597144535824,0.04820050112686736,-3.284487694960334
488.00000000000625,53.98156994617307,0.04860246751527986,-3.286905640254483
489.20000000000624,54.10001818746555,0.049021444481819665,-3.2883901256871417
490.40000000000623,54.218430275240436,0.0503190456377709,-3.2897074763771443
491.6000000000063,54.33629303632397,0.05479711706085777,-3.291021256184923
492.8000000000063,54.45584956883819,0.05854514268042477,-3.2921833085991783
494.0000000000063,54.573458794584994,0.05791487384752736,-3.2922758345003116
495.2000000000063,54.693149972307474,0.0631710593218251,-3.294652459161374
496.40000000000634,54.81208534622521,0.06306677561422547,-3.295957678706238
497.6000000000064,54.93083798318524,0.06394716741526052,-3.2972495853252815
498.8000000000064,55.04968971033719,0.06639272497410464,-3.29688488535728
500.00000000000637,55.16859637418847,0.06672350822346451,-3.2997393374285493
501.2000000000064,55.28735558653534,0.07072840931420155,-3.302759995389935
502.40000000000646,55.405756860320935,0.0697625226465396,-3.3041218324107953
503.60000000000645,55.52504854919062,0.07156813278465579,-3.303848244897531
504.80000000000643,55.6444310947782,0.07293294210504364,-3.304121257956897
506.0000000000065,55.76369127434063,0.07349663480070945,-3.3053911810869545
507.2000000000065,55.88241394032354,0.07567505915465611,-3.306751473803068
508.4000000000065,56.00118131041941,0.07613071940634641,-3.3090094239197163
509.6000000000065,56.119656139852324,0.07735914902157048,-3.310312363430658
510.80000000000655,56.23947749572871,0.07729929298345084,-3.309000054627132
512.0000000000066,56.35790168758298,0.07902097847282474,-3.3109720258335136
513.2000000000066,56.47713050283741,0.08504670993432717,-3.3109047628112416
514.4000000000066,56.59573169997537,0.08197241781643494,-3.3136096126054815
515.6000000000066,56.714888706283446,0.08332868506466273,-3.314599769501121
516.8000000000067,56.83384018464568,0.08504783291465601,-3.315244294198161
518.0000000000066,56.95218253692915,0.08136213964224204,-3.316786611250974
519.2000000000066,57.070906933173,0.08200324030148465,-3.3181925325981583
520.4000000000067,57.19059344020101,0.08277096249851956,-3.3185504554724132
521.6000000000067,57.309656359829724,0.08244765752525762,-3.319861878872362
522.8000000000068,57.427537983692915,0.08079202108972172,-3.3184320194436308
524.0000000000067,57.54780455467238,0.08005938827397507,-3.3211801124560445
525.2000000000068,57.66609838625682,0.07734850818178729,-3.3225000395577933
526.4000000000068,57.78501289617214,0.0777084886398054,-3.3224091336044506
527.6000000000067,57.904122267161405,0.07884139491343012,-3.323809848176575
528.8000000000068,58.02377819247183,0.07966740770421665,-3.3248439194717916
530.0000000000068,58.141931071125555,0.07722465606147966,-3.3247538502986753
531.2000000000069,58.26083238775561,0.07787798967313764,-3.3269026516686333
532.4000000000069,58.37967854918184,0.07416928553536573,-3.327429392618864
533.6000000000068,58.498307148969126,0.06812353304708252,-3.3286356005337794
534.8000000000069,58.617976378568244,0.06943773855952384,-3.328100179231515
536.0000000000069,58.73776174831423,0.06012330264340593,-3.3306525499727817
537.2000000000069,58.857305975959186,0.059388534818293204,-3.330738752287397
538.4000000000069,58.97617207272397,0.05898183178691263,-3.3307300879808235
539.600000000007,59.09564698632115,0.05820530541261171,-3.3314297117482488
540.800000000007,59.21560406709521,0.0566784191413483,-3.3336798681505964
542.000000000007,59.334976562081685,0.054302565254808144,-3.333679746515357
543.200000000007,59.4548668329426,0.05182258644335347,-3.3346436447156425
544.400000000007,59.573964803501596,0.050150381158704294,-3.336407875779869
545.6000000000071,59.69353447646225,0.05021827983764804,-3.3363203007640236
546.800000000007,59.813967869037626,0.049918545795461844,-3.3374493691119755
548.000000000007,59.932075777637415,0.0475776806083652,-3.3373113951527866
549.2000000000071,60.05272442813645,0.04665307136884589,-3.3377998643088214
550.4000000000071,60.17142916021592,0.04650611446147579,-3.340238590746015
551.6000000000072,60.28917226151639,0.04309600927988033,-3.3402216008167365
552.8000000000071,60.41040466057896,0.04263703811872366,-3.3416193243056607
554.0000000000072,60.52917000000063,0.038735110920941174,-3.3415900449999567
555.2000000000072,60.64907319147572,0.04091862987758166,-3.3425617983720737
556.4000000000071,60.76906123067968,0.040807484290487306,-3.3428958412451206
557.6000000000072,60.889172138556724,0.03920559719062833,-3.343230198031944
558.8000000000072,61.0081386435939,0.03676525509095041,-3.34388998730607
560.0000000000073,61.12798108530095,0.03636636348785627,-3.3442195207297964
561.2000000000073,61.24833174758484,0.037505299312577955,-3.3452099427046784
562.4000000000073,61.3673465719475,0.03530470114633566,-3.346520082408452
563.6000000000073,61.48585059507876,0.03394265528164997,-3.3461976280856343
564.8000000000073,61.605536054041,0.03506737033902718,-3.3475098412141424
566.0000000000073,61.72560367219197,0.032074665870069685,-3.3488623593449036
567.2000000000073,61.84547207362485,0.03316848969671682,-3.3488192852712793
568.4000000000074,61.965114238681466,0.0327242218183903,-3.3501329979394967
569.6000000000074,62.08481003949402,0.03550340386186268,-3.350478412402176
570.8000000000075,62.204901641072695,0.03533698274780894,-3.3504701590024393
572.0000000000074,62.32471610395554,0.03291761204311405,-3.350543220799965
573.2000000000074,62.444790497944666,0.03289212270580921,-3.3526454666198444
574.4000000000075,62.564628773668105,0.03585340558828154,-3.351895373970475
575.6000000000074,62.683993439327075,0.038616755850133355,-3.3514768638156083
576.8000000000075,62.805735565234876,0.03852991147233786,-3.3567980654158722
578.0000000000075,62.92406193300476,0.03783067220443126,-3.3554100231317596
579.2000000000075,63.04427385800838,0.03755339370074107,-3.3567281532060753
580.4000000000076,63.165346756017215,0.036289300003844005,-3.356729893895657
581.6000000000075,63.28542743472318,0.0412018528423066,-3.35901978952213
582.8000000000076,63.40591557431776,0.0367721630999196,-3.3603409736979692
584.0000000000076,63.5260447769222,0.03846089702511368,-3.3590514962310265
585.2000000000075,63.64693215733814,0.033273086010980224,-3.3603399474755205
586.4000000000076,63.76750350448074,0.0344475156475883,-3.364282175944581
587.6000000000076,63.88768775956427,0.03091982788425418,-3.364290788455863
588.8000000000077,64.00707681329392,0.024975770740049308,-3.3644101931036428
590.0000000000077,64.12878630599155,0.02190103214054262,-3.3663689382711177
591.2000000000077,64.24852860516597,0.021336954896223448,-3.3692179787296594
592.4000000000077,64.36860176704029,0.02065464681672191,-3.3692298127753446
593.6000000000078,64.48958467026793,0.020131754533460722,-3.370540440372507
594.8000000000077,64.60927231632296,0.025557344362404644,-3.3718600845506277
596.0000000000077,64.72926947183835,0.024367923062153185,-3.3718600062309756
597.2000000000078,64.84964273137311,0.028167189070743115,-3.373208272240097
598.4000000000078,64.96926206269731,0.03630745808503222,-3.37449006626781
599.6000000000079,65.08947218597436,0.039130641982476844,-3.3758099088589875
600.8000000000078,65.20895090890318,0.04072621800209708,-3.377119472583168
602.0000000000078,65.32926714624477,0.044338075950244304,-3.3771199261133837
603.2000000000079,65.44936341091893,0.0463694838094626,-3.3784390411567875
604.4000000000078,65.5696799382803,0.04724227903845679,-3.3771201836847524
605.6000000000079,65.69064960273225,0.0450789996040466,-3.3795781501868207
606.8000000000079,65.81106433232505,0.04621465906011091,-3.379762952764234
608.000000000008,65.93026122173863,0.04589848725150247,-3.379750070460172
609.200000000008,66.05025041355677,0.05027346664019294,-3.3823903939235773
610.4000000000079,66.17145075724258,0.04706590136762112,-3.3810720437773547
611.600000000008,66.2912414951307,0.0492423298323057,-3.3823901637114577
612.800000000008,66.40896787709286,0.0467740483514163,-3.38239022053014
614.000000000008,66.53195414961613,0.04855319871173558,-3.3805095256979634
615.200000000008,66.65193487526967,0.0472502704040092,-3.3837007283482023
616.400000000008,66.77247077239447,0.044338197732249895,-3.3850200347704433
617.6000000000081,66.89333080515549,0.042371463678325005,-3.3837005115097742
618.8000000000081,67.01329532879458,0.03996270761904119,-3.384674240776927
620.0000000000081,67.13379957106602,0.040028187175654484,-3.384455364280277
621.2000000000081,67.2557093033154,0.03840873057198646,-3.3886550852208357
622.4000000000082,67.37524065512096,0.0352534112213565,-3.3867698775617106
623.6000000000081,67.49525946927965,0.035164269293138206,-3.3867698490000047
624.8000000000081,67.61651133576764,0.03796892368396554,-3.386769848982445
626.0000000000082,67.73538161257366,0.034627576713121444,-3.3863251203836646
627.2000000000082,67.85662343252736,0.036801538716550786,-3.3870001327161123
628.4000000000083,67.97680812809104,0.03503571007631612,-3.388108075034523
629.6000000000082,68.09722759892698,0.03337415252474307,-3.3882629596447327
630.8000000000083,68.21713001070313,0.033167965230505914,-3.390620012566366
632.0000000000083,68.33751506547125,0.03343241433662225,-3.3906200129998485
633.2000000000082,68.45865069058051,0.032179239811714444,-3.390619554623441
634.4000000000083,68.57866790380785,0.0323596896885221,-3.3906198562322496
635.6000000000083,68.6995872928149,0.03414360864314814,-3.391953814450405
636.8000000000084,68.82071764830438,0.033411112570407075,-3.3919298972384793
638.0000000000084,68.94141916718509,0.03871611814514431,-3.391929887726896
639.2000000000083,69.06124450011666,0.03527977921305192,-3.3919323579440466
640.4000000000084,69.18282954990835,0.03321679274461942,-3.393255756455922
641.6000000000084,69.3028454275321,0.03662003444391204,-3.3932501350035893
642.8000000000084,69.42414382495794,0.034276233179253435,-3.3933206638168243
644.0000000000084,69.54433555967252,0.033910624540009815,-3.3945601255274003
645.2000000000085,69.66527477178279,0.0351516085828818,-3.3958834832725837
646.4000000000085,69.78673970238944,0.03304817705411889,-3.3945600089905534
647.6000000000085,69.90610135587778,0.034776793902434155,-3.394560005775351
648.8000000000085,70.02696216414127,0.028555601927924723,-3.3958939004027524
650.0000000000085,70.14819183694901,0.03170866182240473,-3.3968594979142033
651.2000000000086,70.26805622115997,0.029673851066396972,-3.3969159073190713
652.4000000000085,70.38885758370749,0.030473457267056636,-3.3974578380195246
653.6000000000085,70.50947428072834,0.030071027280820672,-3.3960998749999867
654.8000000000086,70.63073268309108,0.029098697685982167,-3.396099929968548
656.0000000000086,70.75066065132563,0.031327030044860704,-3.3978943201173117
657.2000000000087,70.87209342960112,0.03185133239447513,-3.3974165076801057
658.4000000000086,70.99178632495936,0.03173603652160839,-3.3985563578841016
659.6000000000087,71.11248947174974,0.028100384289414082,-3.399586126756546
660.8000000000087,71.2334883442677,0.030915169042443846,-3.398851671911819
662.0000000000086,71.3551480188062,0.029060205202313227,-3.398839800455034
663.2000000000087,71.47530179105257,0.03267404085795622,-3.398839997089939
664.4000000000087,71.59584758293057,0.032847575287426656,-3.399880411754075
665.6000000000088,71.71705910938834,0.031592956466715894,-3.4001598399082953
666.8000000000088,71.8364794278068,0.02891961530052156,-3.40015994162485
668.0000000000088,71.95784842797278,0.0291467991129295,-3.3994985022806663
669.2000000000088,72.0788477271955,0.027266365955748606,-3.401469858731425
670.4000000000088,72.1992782613463,0.028785481887702247,-3.402790811412863
671.6000000000088,72.32043147276846,0.022972033360312505,-3.4014770027592
672.8000000000088,72.4404383529875,0.026589283343809278,-3.4008757075248837
674.0000000000089,72.56192231453622,0.026298720740863146,-3.4031201845494454
675.2000000000089,72.68316415447957,0.022787291856689817,-3.4043432651861982
676.400000000009,72.80348251382469,0.022537851148879184,-3.403450028908037
677.6000000000089,72.9234337730503,0.022641793114293707,-3.403450025
678.8000000000089,73.04460494316534,0.02684693994923304,-3.4034500249939237
680.000000000009,73.16585255622671,0.021523507096796957,-3.4034113711825658
681.2000000000089,73.2862142373719,0.020030999371768443,-3.4047600517835157
682.400000000009,73.40792307568941,0.02008958151582041,-3.4047591296109454
683.600000000009,73.52876332425257,0.02245719272930158,-3.4044300520744555
684.800000000009,73.64879756478066,0.019796106138655567,-3.403765792862868
686.0000000000091,73.77097278166033,0.012856359957164276,-3.405496734862781
687.200000000009,73.89110287853467,0.010373737405231731,-3.404446933470643
688.4000000000091,74.01240258742247,0.010619497358866248,-3.405749921626293
689.6000000000091,74.13268143596409,0.01200511071458732,-3.4064153536191206
690.800000000009,74.25392570384147,0.009087499762924889,-3.407734586775829
692.0000000000091,74.37507829559404,0.0063198472663146266,-3.405102931543179
693.2000000000091,74.49351623808406,0.008421803808920325,-3.4062534341965107
694.4000000000092,74.61661074953653,0.005480123800594594,-3.408719980762405
695.6000000000092,74.73756457751266,0.005050799834926734,-3.4073969474707995
696.8000000000092,74.85863954367996,0.004579563738752457,-3.408034584038723
698.0000000000092,74.97957793416698,0.003121261018044885,-3.4082785913182336
699.2000000000093,75.1011330230444,0.004764667583674331,-3.4087102784500236
700.4000000000092,75.22155175017436,0.0026178757981503153,-3.4082841935964474
701.6000000000092,75.34277700642082,0.0001368063219264748,-3.4090398239523267
702.8000000000093,75.46314049442138,0.0010673939028631452,-3.4090398237279986
704.0000000000093,75.585994346353,-0.001360636125370851,-3.40770803101693
705.2000000000094,75.70555011824284,-0.005172465424749362,-3.4102499990361217
706.4000000000093,75.82678529175234,-0.005651742227578804,-3.410364879740575
707.6000000000093,75.94833464524064,-0.0028444621727001795,-3.409261018284307
708.8000000000094,76.06856455026387,-0.00657534434973428,-3.409920172049228
710.0000000000093,76.19063858598119,-0.01107053248958656,-3.409926493359113
711.2000000000094,76.31180565917204,-0.010877657322053258,-3.410579676078753
712.4000000000094,76.4332746348306,-0.010228789048801756,-3.4105797989999873
713.6000000000095,76.55503104790289,-0.014687851966450172,-3.4105797989998288
714.8000000000095,76.67719039435933,-0.019290765004010835,-3.4105791575365423
716.0000000000094,76.79846511773972,-0.019692153463380047,-3.4106077166055337
717.2000000000095,76.9198668375178,-0.023898948007591958,-3.4112396764578268
718.4000000000095,77.04154594817858,-0.024201526985829558,-3.4114146605588953
719.6000000000095,77.16307466704897,-0.021528139348360842,-3.411389612745676
720.8000000000095,77.28488745664289,-0.025086725409914967,-3.412276468352233
722.0000000000095,77.40603942462093,-0.028274125302715447,-3.4132097643170667
723.2000000000096,77.5270455909712,-0.026868924013387474,-3.413209952490183
724.4000000000096,77.64885103112036,-0.02930163518976303,-3.412549866414877
725.6000000000096,77.7695747224829,-0.034577740497173215,-3.412879623555906
726.8000000000096,77.88959686953834,-0.03686373963055689,-3.412544715500988
728.0000000000097,78.01214027133224,-0.03382424673575346,-3.4134790094304517
729.2000000000096,78.13347804826006,-0.03551472378134646,-3.4145281083961345
730.4000000000096,78.25527703090246,-0.038645965316240094,-3.4148501997716476
731.6000000000097,78.37700018163606,-0.0369333413107551,-3.414850140463919
732.8000000000097,78.4978628679936,-0.0394913004449533,-3.4133235686984915
734.0000000000098,78.61999173424081,-0.04030791762482444,-3.410688744200031
735.2000000000097,78.7398340404227,-0.04290554256104384,-3.417535066257608
736.4000000000098,78.86166752108414,-0.043434801582771465,-3.417489912675488
737.6000000000098,78.98311743802417,-0.04413941667581689,-3.416176638239893
738.8000000000097,79.10382030022755,-0.04257443240599956,-3.4174961592144455
740.0000000000098,79.22529128054737,-0.0442576599880915,-3.415897392144093
741.2000000000098,79.3468922662119,-0.04478885988838055,-3.4151868338817963
742.4000000000099,79.46864445073948,-0.045624860927372834,-3.4165004016539537
743.6000000000099,79.58944522770699,-0.04347965037602286,-3.4178201648000743
744.8000000000098,79.71160077054051,-0.04950939643989738,-3.4174896629839626
746.0000000000099,79.83331090151025,-0.04529484321942112,-3.416500062533431
747.2000000000099,79.95315796949461,-0.04834767248953398,-3.4178108029569323
748.4000000000099,80.0739598834338,-0.04721029354909145,-3.4178101917728867
749.6000000000099,80.1956962195762,-0.04703567572765932,-3.4191195852432217
750.80000000001,80.31633008430187,-0.04876416287601515,-3.4191320007660764
752.00000000001,80.43775212482446,-0.04545391930388032,-3.419130034838431
753.20000000001,80.55928521126037,-0.05316318360222949,-3.419130035
754.40000000001,80.68023505755554,-0.052328659256690724,-3.419130034996867
755.60000000001,80.80263854175007,-0.05420470146485057,-3.419103622355639
756.8000000000101,80.92418119505547,-0.05175513506000318,-3.4204944519676306
758.00000000001,81.04513197281138,-0.057896863016908995,-3.4204454672239497
759.20000000001,81.16729357187009,-0.062225122539276256,-3.42044155773082
760.4000000000101,81.28869717332633,-0.05569483334271785,-3.420449905039487
761.6000000000101,81.40999768788551,-0.05690273042949601,-3.4194981590644162
762.8000000000102,81.53062636609964,-0.051405574329314696,-3.420219737490614
764.0000000000101,81.6520165061372,-0.053982623566372734,-3.421770200698578
765.2000000000102,81.77296179678052,-0.058099356545827874,-3.4204500839012897
766.4000000000102,81.89677405053867,-0.05500907501857366,-3.420450156992893
767.6000000000101,82.01732991918186,-0.06454092460681027,-3.4203998717361266
768.8000000000102,82.14120670221698,-0.06632349650577885,-3.4212965957939465
770.0000000000102,82.26223203451131,-0.06599021611147027,-3.4207796584777896
771.2000000000103,82.3839289452714,-0.06605048747619113,-3.422168041662658
772.4000000000103,82.50698406085255,-0.06735638611063655,-3.420770116336449
773.6000000000103,82.62779440157398,-0.06731964209197638,-3.4220900898056694
774.8000000000103,82.74956178928258,-0.0661080533106917,-3.4220900899999998
776.0000000000103,82.87141870238958,-0.06584929070373269,-3.422090089344392
777.2000000000103,82.9926571126383,-0.07079941454442995,-3.423399890621962
778.4000000000103,83.11497547228112,-0.07103371896849131,-3.422181048421639
779.6000000000104,83.23600334784263,-0.0687405614867207,-3.422095561852314
780.8000000000104,83.35706395378338,-0.06648249590807964,-3.422104576382214
782.0000000000105,83.47937846909718,-0.0709597503738646,-3.4217399091596397
783.2000000000104,83.60112347152639,-0.07228381551622443,-3.423407795938409
784.4000000000104,83.72292333859488,-0.07257369855077034,-3.4231023148890776
785.6000000000105,83.84312988745869,-0.07528132189815251,-3.4237484187236253
786.8000000000104,83.96512692969621,-0.07418598716884484,-3.4231638908466335
788.0000000000105,84.0867936588636,-0.07284355297142575,-3.42340980122173
789.2000000000105,84.20863503211432,-0.07028397194983071,-3.4234098071073893
790.4000000000106,84.33012067477486,-0.0748903040191724,-3.424729920646309
791.6000000000106,84.45141588791624,-0.07514033370538797,-3.423420021178333
792.8000000000105,84.57286005093496,-0.07741816856203299,-3.4234200454586743
794.0000000000106,84.6954057476489,-0.07737839054423823,-3.4220989241700606
795.2000000000106,84.8159834819319,-0.07182225550219634,-3.424729508005072
796.0000000000106,84.89787136735544,-0.07250447364978907,-3.424750732307504