File: 01_Data/EPDM_Membrane/STA/N2/10K_min/EPDM_Membrane_STA_N2_10KData_220928_R2.csv
##Temp./Â°C,Time/min,DSC/(mW/mg),Mass loss/mg
51.0,10.78363012849364,0.048284039646964594,0.029752771023604296
52.100000000000016,11.146865609506523,0.08360977062894404,0.030815144875397493
53.20000000000003,11.392779062742191,0.10418134675880864,0.029406320463806424
54.30000000000005,11.602136229648417,0.1234518066147452,0.030706905465934575
55.40000000000006,11.784891239798993,0.13594120749713356,0.027825763975315887
56.50000000000008,11.959424122489253,0.14977773010600748,0.02817585113978005
57.600000000000094,12.118723962886568,0.15939082140642524,0.02938527800836077
58.70000000000011,12.272126926788522,0.16487278882465062,0.029096318358194928
59.800000000000125,12.426124022082984,0.1750537778780974,0.028765783453987837
60.90000000000014,12.572111027686757,0.1824235998324435,0.029279555833749527
62.000000000000156,12.712482244244,0.186036042955539,0.029290610708232023
63.10000000000017,12.85314428182233,0.19295173405346744,0.02921173415125189
64.20000000000019,12.98849634355547,0.19761156941550473,0.0294112779254716
65.30000000000021,13.123326862602358,0.20314715414115025,0.029331428250023883
66.40000000000022,13.25722064693029,0.20717037698720286,0.030208720786264465
67.50000000000023,13.38652734347642,0.2134901564445646,0.029547334319040885
68.60000000000025,13.516262415615312,0.21413511600946133,0.029839222323444936
69.70000000000027,13.64492337520767,0.22039201806204178,0.030764865650071194
70.80000000000028,13.772817647415305,0.22540533606000634,0.03074277717838214
71.90000000000029,13.897102598191536,0.2255964764937357,0.03355786394221916
73.00000000000031,14.020904347998504,0.23077046692362435,0.030740531781512814
74.10000000000034,14.146608422372099,0.2339787229039063,0.03296718163263268
75.20000000000034,14.267894596564524,0.23705568029461355,0.03205473186947572
76.30000000000035,14.387814375317943,0.24198770303591233,0.030658119856419752
77.40000000000038,14.511360906176401,0.24387035573835925,0.030789383738190956
78.5000000000004,14.630000000000045,0.24823430141591196,0.029418049774427857
79.6000000000004,14.750000000000044,0.2493556894099671,0.028155736497786243
80.70000000000041,14.868915276394716,0.2526616022024887,0.02943958174938377
81.80000000000044,14.985073552274093,0.25577009544781315,0.0311963668703088
82.90000000000046,15.10278161303403,0.2594995370602253,0.03063278201984332
84.00000000000047,15.218482230275237,0.2619827431374393,0.032075370368544576
85.10000000000048,15.33416407472656,0.26340644128895707,0.032152346400717846
86.2000000000005,15.448796348481306,0.2645538513411515,0.03161211391375218
87.30000000000052,15.563579190169552,0.2708440278882873,0.03348643599468826
88.40000000000053,15.676451536179991,0.2735013238288607,0.03350029965116974
89.50000000000054,15.790187724483692,0.2765536835369595,0.0321700010352588
90.60000000000056,15.902941946133573,0.2803168988075667,0.032169600360624884
91.70000000000059,16.013762783361088,0.2811759099112039,0.030901128357603724
92.8000000000006,16.127809990819337,0.2852933808078906,0.031625109561868925
93.9000000000006,16.23766999782478,0.2886610146496109,0.03217498190104262
95.00000000000063,16.346388184682787,0.2900820946172714,0.029522851573624997
96.10000000000065,16.459917720226493,0.2917331892040673,0.0321642235150561
97.20000000000066,16.57062652049079,0.2932305089808557,0.03208078219875521
98.30000000000067,16.679505125258785,0.29426798476136706,0.029785769593163813
99.40000000000069,16.786575977382288,0.2971333177499258,0.030886709220806274
100.50000000000071,16.89796444838287,0.30108467311451603,0.03215551483563939
101.60000000000072,17.007152997045335,0.30184733757443805,0.031533695858453115
102.70000000000073,17.11587479672079,0.30288307100894596,0.033208543986174455
103.80000000000075,17.22555351850199,0.3048171098468898,0.032769160750438786
104.90000000000077,17.333056500496404,0.30529510087974154,0.03081678098832441
106.00000000000078,17.440000000000087,0.3064874412456542,0.030880124645004337
107.10000000000079,17.5487739179498,0.3095519343740354,0.03086824926228271
108.20000000000081,17.65672739541384,0.3115048911411401,0.030899160374797674
109.30000000000084,17.765000730514235,0.312480257484967,0.02949353106534147
110.40000000000084,17.87305316481692,0.31481250096119906,0.029542859832889512
111.50000000000085,17.97950065387087,0.3149275684092341,0.032167857613456086
112.60000000000088,18.0875440581526,0.31720691702365567,0.03184580609342191
113.7000000000009,18.19263269070738,0.317839813575828,0.030329442824167607
114.8000000000009,18.30324784414623,0.3206151718238762,0.030738782360944406
115.90000000000092,18.410491426529887,0.3200480916471462,0.03045842635852658
117.00000000000094,18.51840689102995,0.31815660412301316,0.030750028302325205
118.10000000000096,18.624356831142478,0.3170423437267288,0.03208431875515316
119.20000000000097,18.731135685003746,0.3163977194511133,0.03195210326965814
120.30000000000098,18.838271540333096,0.31588351246091495,0.030629999999350233
121.400000000001,18.945268122551962,0.3168890580345546,0.03063187977015236
122.50000000000102,19.05160509534193,0.31926207818472585,0.03194922757774865
123.60000000000103,19.15907602140146,0.32044874115936306,0.03158735129278423
124.70000000000104,19.26628316472142,0.3213624532775399,0.030287506676339504
125.80000000000106,19.373140703978155,0.323319242188968,0.029317398707727094
126.90000000000109,19.479168783103226,0.32511662623565907,0.03190799024031765
128.00000000000108,19.585872055019877,0.3250185941268833,0.030207426308722418
129.1000000000011,19.68853654646389,0.32601364111802866,0.029310674553639338
130.20000000000113,19.7974798258809,0.3263950316497558,0.030629976405829318
131.30000000000115,19.903767511441124,0.32793519272166105,0.030637939174066986
132.40000000000117,20.008867796002384,0.3284431022642136,0.0293199989155406
133.50000000000117,20.115599494660845,0.3304342835034384,0.030639888343758415
134.6000000000012,20.22180434700975,0.33071629793739277,0.02933553427136104
135.7000000000012,20.327141549911776,0.3307716517130026,0.029309991128923407
136.8000000000012,20.432914110880006,0.33313132099334464,0.028001967369047698
137.90000000000123,20.538821795639326,0.33444411102319205,0.029328519648164075
139.00000000000125,20.645085034142863,0.3350516907826473,0.028643106783666106
140.10000000000127,20.749017562457894,0.3342830510801005,0.027339359139023856
141.2000000000013,20.85284806661517,0.3378274549296195,0.027353358446777776
142.3000000000013,20.9601958443655,0.3401482602058622,0.02834754994401667
143.4000000000013,21.065407187341744,0.3397729552023695,0.02866000000316582
144.50000000000134,21.170739591810538,0.34225253442389003,0.028659370445196508
145.60000000000133,21.275554189591183,0.3406561273932237,0.028620765095557665
146.70000000000135,21.378610880757936,0.3426261049536492,0.027538393827766683
147.80000000000138,21.482622432254555,0.34486422556527296,0.028659928107360066
148.9000000000014,21.58914513558153,0.3465823107206426,0.028648439234530088
150.00000000000142,21.693572973233668,0.3470095436025237,0.02866393136559786
151.10000000000142,21.79796028809823,0.3461059493032579,0.02464755146246489
152.20000000000144,21.903267981313352,0.3492814688526974,0.023360354830186836
153.30000000000146,22.00738857635039,0.35031538786224603,0.023389934893406128
154.40000000000146,22.113480014907463,0.3500493524883842,0.02369857370227102
155.50000000000148,22.216739548975124,0.3513374861741997,0.02452521263810503
156.6000000000015,22.320876586797485,0.3518672408219292,0.02520695510420712
157.70000000000152,22.42737961085485,0.35215256589666144,0.02514999728288636
158.80000000000155,22.532059448371466,0.3558456070451179,0.024145212599425925
159.90000000000154,22.636381868448954,0.3547536182808976,0.024148849803598438
161.00000000000156,22.737793922359494,0.35644558954081496,0.02412083158732692
162.1000000000016,22.844747694668904,0.3576726807486834,0.025470011977667184
163.20000000000158,22.94888868178697,0.3579313355217021,0.026158834789325347
164.3000000000016,23.05419844795918,0.35931142360086343,0.024149696008240795
165.40000000000163,23.155539107977653,0.3578732027602084,0.024232043561290162
166.50000000000165,23.262169961958765,0.3598321765103767,0.02348994111651237
167.60000000000167,23.366504238900685,0.36012630015069214,0.022134150188937163
168.70000000000167,23.470881406867946,0.3612735463849417,0.022069999532107865
169.8000000000017,23.575510942788167,0.3617910761017411,0.022068070777625515
170.9000000000017,23.67951308707253,0.3620340767222471,0.01942248679731229
172.0000000000017,23.784102403013446,0.3627194205161458,0.018110447762637705
173.10000000000173,23.889570384719573,0.3652385125341857,0.018122333905298937
174.20000000000175,23.993074030794013,0.36611146169522124,0.020742556134883294
175.30000000000177,24.09853329566214,0.3644910212668797,0.019431756487401586
176.4000000000018,24.20230523928563,0.3644121571408775,0.018113112433954193
177.5000000000018,24.307484651394347,0.3616769302449786,0.016777982623085386
178.6000000000018,24.411759942308475,0.3633181138942725,0.016805523096167008
179.70000000000184,24.5155682905246,0.3630523115862849,0.015480204132033215
180.80000000000183,24.619436786375235,0.36291640113792345,0.014162704003704896
181.90000000000185,24.722984262310238,0.36135610436907994,0.01449004949262278
183.00000000000188,24.828634902700404,0.36179331749163857,0.015474833963779133
184.1000000000019,24.93245819189922,0.3605278222533712,0.01393276526910281
185.20000000000192,25.037159793774393,0.3609405062512039,0.0113100405621811
186.30000000000192,25.14016917755721,0.3619785984399909,0.009998873022085242
187.40000000000194,25.245008217537446,0.3609102545583699,0.010979995777583795
188.50000000000196,25.34940855979873,0.36149276211224113,0.010981910631534753
189.60000000000196,25.45130539329296,0.3603578717964796,0.00966002920123632
190.70000000000198,25.557248900443284,0.3622569188267385,0.009662680494749054
191.800000000002,25.661630328520793,0.3637377843801244,0.0070297880348322295
192.90000000000202,25.7659302868546,0.3625485834961938,0.007359462654094706
194.00000000000205,25.86937208308427,0.36295206994778806,0.008679982467559633
195.10000000000204,25.974109604472524,0.3629892192035705,0.007404436461622588
196.20000000000206,26.07903303879506,0.363726607939284,0.004718378054882066
197.3000000000021,26.18310215774959,0.36337330551766556,0.00301215196069915
198.40000000000208,26.28738631919595,0.3647330912105987,0.00055028929014167
199.5000000000021,26.391234253578556,0.3660735701796417,-0.0007700323411889975
200.60000000000213,26.49576761052636,0.36551518114675763,-0.0007699828036682455
201.70000000000215,26.600876109638598,0.3666544991099542,-0.001990072675029708
202.80000000000217,26.704086530378234,0.3688300845179022,-0.003399986458519244
203.90000000000217,26.808341222737,0.3693665301965209,-0.00375261105892033
205.0000000000022,26.91402655098894,0.37285762647310805,-0.0034000043912740807
206.1000000000022,27.017167667344935,0.3739877551167764,-0.005847244301662169
207.2000000000022,27.120487946320065,0.3738342701204621,-0.006039999965429477
208.30000000000223,27.22605038380618,0.3773347104151372,-0.006039882957394216
209.40000000000225,27.32980512787081,0.37860992153258544,-0.008680029779408294
210.50000000000227,27.432158672488203,0.3808662588416177,-0.007538147010203389
211.6000000000023,27.536491426639436,0.3838553819604244,-0.009989903852995141
212.7000000000023,27.641711602505957,0.38617673620210513,-0.012290007970319206
213.8000000000023,27.74620142701114,0.38757336478534776,-0.013569892896057478
214.90000000000234,27.85109032588276,0.39062323180561864,-0.014961338997121487
216.00000000000233,27.954074604249424,0.39063889362777154,-0.017890532401717785
217.10000000000235,28.058534740837523,0.39438364496583606,-0.01922436208565692
218.20000000000238,28.163166519300027,0.396567529673042,-0.020498971388974496
219.3000000000024,28.26675713849465,0.39783793115972027,-0.023158972946967005
220.40000000000242,28.371464181670355,0.3975700409897988,-0.023160496017979426
221.50000000000242,28.475762462938928,0.39855796379319824,-0.024499945343151808
222.60000000000244,28.579908366043384,0.4013426692100107,-0.027119444676441784
223.70000000000246,28.683664566870373,0.4034244135981866,-0.028428255601341323
224.80000000000246,28.78860393701074,0.4021787932246261,-0.029751119686137528
225.90000000000248,28.893354877128004,0.40487929764540553,-0.032395890251730286
227.0000000000025,28.997242622951568,0.4067926150888535,-0.03413832463298272
228.10000000000252,29.101104365660824,0.4063540765231534,-0.03633175604625327
229.20000000000255,29.207077424206357,0.4075994968357665,-0.03885975005780473
230.30000000000254,29.310250300863324,0.4084279093284705,-0.03897110394384917
231.40000000000256,29.41450580821391,0.4089015985729705,-0.04028900747768871
232.5000000000026,29.519025611218233,0.40843859905142377,-0.04217891497804427
233.60000000000258,29.623363393950108,0.41181897864386274,-0.044234732451751135
234.7000000000026,29.726716462665657,0.41176253672758123,-0.04557580844257547
235.80000000000263,29.83225643553151,0.4136810653804907,-0.04755592954918164
236.90000000000265,29.93716324939941,0.4120245124863611,-0.05033546545663503
238.00000000000267,30.04155634362829,0.413346335509222,-0.052258867978775214
239.10000000000267,30.145598584821208,0.4155914589675144,-0.054851209123699896
240.2000000000027,30.25009202994923,0.4153523512081538,-0.05753000747241588
241.3000000000027,30.35237289260705,0.41709063589406287,-0.058969492321911954
242.4000000000027,30.458070013503413,0.41855995792533085,-0.06166274917583303
243.50000000000273,30.56220164859016,0.4170345418128298,-0.064070449043784
244.60000000000275,30.666707153236935,0.41966416651604904,-0.06660962298895745
245.70000000000277,30.773422303422524,0.41777938054298996,-0.06808044664103363
246.8000000000028,30.877093088244642,0.4196471567982784,-0.07069470647336118
247.9000000000028,30.978881321256345,0.41930551675201866,-0.07327929103243491
249.0000000000028,31.086047661544644,0.4179283073075187,-0.07597230691798673
250.10000000000284,31.190951652704662,0.4185759141847869,-0.07833848542042432
251.20000000000283,31.29542017733899,0.4172125662178287,-0.08000011650573668
252.30000000000285,31.39962479464202,0.41626131184795323,-0.0851801314368803
253.40000000000288,31.505767155411384,0.4159643753698922,-0.0864362804271388
254.5000000000029,31.609094741387928,0.4160511472405007,-0.0905609409542869
255.60000000000292,31.714942197303685,0.41467053782327956,-0.09198274837999199
256.7000000000029,31.81887993399195,0.4159504256065416,-0.09639146650022301
257.8000000000029,31.92201920085181,0.41448608466254355,-0.09769952856758213
258.90000000000293,32.02709102577455,0.4134647146091958,-0.09915112861970199
260.00000000000296,32.13168619528504,0.41429766649580047,-0.10319819809708841
261.100000000003,32.23451802518285,0.4132280859059551,-0.10440962225455719
262.200000000003,32.34087510990552,0.41391317168343245,-0.10717294316418391
263.300000000003,32.44540285241221,0.4132463545170735,-0.1095924569589104
264.40000000000305,32.5489822781857,0.4145530854639812,-0.1138799853153194
265.50000000000307,32.6531227227579,0.41300761188147517,-0.11692123328203374
266.6000000000031,32.759162043275325,0.4124094032061113,-0.11955050094100184
267.7000000000031,32.86393123538674,0.41190553366699667,-0.12252656782189097
268.8000000000031,32.96670892515656,0.41321906019651067,-0.12518790517919154
269.9000000000031,33.07323113008125,0.41316726113103747,-0.12835955983021696
271.0000000000031,33.17752502568751,0.4106632025051537,-0.13215953129338764
272.10000000000315,33.2821648864386,0.4119123749444525,-0.1375065336709227
273.2000000000032,33.387016011233854,0.410979803845544,-0.1408457671050023
274.30000000000314,33.491783343029596,0.4115018314101157,-0.14268192401231072
275.40000000000316,33.59736398999958,0.41243964061418537,-0.1474349624195117
276.5000000000032,33.70192652800091,0.41007597080299113,-0.15099582837071424
277.6000000000032,33.80719216848449,0.4096295018532595,-0.1550088407978003
278.70000000000323,33.91203957366972,0.40797055571250995,-0.15794784864758427
279.80000000000325,34.016629407256715,0.40873270848271154,-0.16227685890850152
280.9000000000033,34.12229709888764,0.4098290861785734,-0.16488740428647786
282.0000000000033,34.22709997717381,0.4093219459701788,-0.16619411070136092
283.1000000000033,34.33262733711692,0.4082551735539985,-0.1704009232803445
284.20000000000334,34.43864533613814,0.40544346857608754,-0.17314981948292552
285.30000000000337,34.54295698529561,0.4067434433247836,-0.17669154197566517
286.40000000000333,34.647432265469284,0.40476233325341754,-0.18111312207826913
287.50000000000335,34.75193330259643,0.4052571248883791,-0.1836692274630778
288.6000000000034,34.85643003895222,0.4036652260354297,-0.18628863690919717
289.7000000000034,34.96353174857356,0.40057793148213977,-0.19238114690031427
290.8000000000034,35.06804021365104,0.40373435305030597,-0.19701217987784503
291.9000000000034,35.17252809203878,0.4011275454780032,-0.19981145079330842
293.0000000000034,35.27735060886174,0.40091862500807174,-0.20526891817615311
294.10000000000343,35.38341927493086,0.40153192336387455,-0.2100783458177098
295.20000000000346,35.487838580895286,0.3993237729530404,-0.21418088415880687
296.3000000000035,35.59358638563232,0.3960146554444085,-0.21755027207980238
297.4000000000035,35.69813898697689,0.3990721973080499,-0.2228769843577636
298.5000000000035,35.80213976748476,0.39745857562281556,-0.22469289196035502
299.60000000000355,35.9068907169542,0.3955236746293052,-0.2267646177140068
300.70000000000357,36.01336812255775,0.3946108445890358,-0.2322873093670519
301.8000000000036,36.11960440122015,0.3937195527863854,-0.2353525585847791
302.9000000000036,36.22386726358165,0.3902836299428865,-0.2405322707910189
304.0000000000036,36.327980364016895,0.3882106529215014,-0.24632628472692586
305.1000000000036,36.43563223813652,0.3877627878758308,-0.2511987439956034
306.2000000000036,36.54093394118888,0.3852848732668875,-0.25468022654301503
307.30000000000365,36.64470724162311,0.38513129318201955,-0.2571816161113816
308.4000000000037,36.75100838793516,0.3823608336175845,-0.26172420843840394
309.5000000000037,36.85599469040962,0.3828307926554989,-0.26605587391872865
310.60000000000366,36.961347213881226,0.3819060914282907,-0.270213769106745
311.7000000000037,37.066939283647294,0.3815704437108402,-0.2766260606016404
312.8000000000037,37.171609025223006,0.3790894668801751,-0.2809503096563435
313.90000000000373,37.27839825727407,0.3783840797004146,-0.28531881743342025
315.00000000000375,37.383401676610525,0.3767250019163916,-0.28934890695534676
316.1000000000038,37.48890112417558,0.3725433391747857,-0.2946635393173431
317.2000000000038,37.592356716332084,0.372409690317331,-0.2994570914743018
318.3000000000038,37.699713725494995,0.3693657655060505,-0.30519575620718786
319.40000000000384,37.80581487026246,0.36722082724411764,-0.3098799661081424
320.5000000000038,37.91153058250492,0.3644983362511398,-0.3131557948383743
321.60000000000383,38.01701057210751,0.36142503192880276,-0.3183452847723518
322.70000000000385,38.122386371320744,0.3602883876886565,-0.32436833146846666
323.8000000000039,38.22717937061602,0.3579423872790459,-0.330313476271038
324.9000000000039,38.33306404344477,0.3560070952547793,-0.33612928625524274
326.0000000000039,38.43913059374948,0.3542347959360569,-0.3432490207588019
327.10000000000394,38.54435703381417,0.35079630082004765,-0.348839265478333
328.2000000000039,38.649632106341016,0.34815881034397433,-0.3534880138620693
329.30000000000393,38.756190073517125,0.34398096701156183,-0.3604182582592905
330.40000000000396,38.859799706323635,0.3433335059372925,-0.3664544099682647
331.500000000004,38.96736546686247,0.33861835602704293,-0.3738948749954907
332.600000000004,39.073171651107835,0.33602658864334084,-0.3803495639432217
333.700000000004,39.17903235039177,0.3330234440852266,-0.3854470552266056
334.80000000000405,39.28436136544231,0.32987901978924067,-0.3931351944947479
335.90000000000407,39.390000934637314,0.32708705516149933,-0.40092053955077356
337.0000000000041,39.49585679149437,0.32318297611411323,-0.40841328761053397
338.10000000000406,39.60167277893039,0.32022339729777366,-0.4153099468833803
339.2000000000041,39.708016714647506,0.3176369727924775,-0.4223308614642671
340.3000000000041,39.81399601152588,0.3163853872160542,-0.4299514430246072
341.4000000000041,39.91920247229865,0.3130669740399998,-0.4377595253336706
342.50000000000415,40.025989185533454,0.308409570631932,-0.4477315388302685
343.6000000000042,40.13136220782448,0.30469400654532364,-0.456082728285065
344.7000000000042,40.23788947963056,0.30337400764980926,-0.466327202588527
345.80000000000416,40.343660124059255,0.30256352706354867,-0.4757429363575376
346.9000000000042,40.449712446984314,0.29967983260324504,-0.48604044968472104
348.0000000000042,40.55516048823206,0.2961343117734,-0.49661099774618433
349.10000000000423,40.66160698754515,0.2945340433508871,-0.5073214643649266
350.20000000000425,40.765552872454165,0.29292194194633336,-0.517815018686484
351.3000000000043,40.873317284328564,0.2929226838018027,-0.5300490730018099
352.4000000000043,40.979144706649386,0.29010889532731865,-0.5431660532633176
353.5000000000043,41.08494094849734,0.28816658069501855,-0.5562565304106291
354.60000000000434,41.191697557078726,0.2888835906454812,-0.5701670664117353
355.7000000000043,41.29731559473616,0.28853928074449187,-0.5850800015985609
356.80000000000433,41.40341992903537,0.28973291687964287,-0.6001024723690618
357.90000000000435,41.50963172240398,0.2891937115581781,-0.6147247531892459
359.0000000000044,41.61606700427016,0.29131234592847,-0.6313936783976786
360.1000000000044,41.72250533005304,0.29164874275540664,-0.6479578039457294
361.2000000000044,41.829104389744764,0.29250574810329605,-0.6646539330080077
362.30000000000445,41.9346931595251,0.292846538579833,-0.6833996921120753
363.4000000000044,42.04060753844224,0.29656811665778965,-0.7038361816740677
364.50000000000443,42.14649134775233,0.29590673641015725,-0.7235826340948157
365.60000000000446,42.25259414073718,0.3001447506733732,-0.7412882706710211
366.7000000000045,42.360492536961786,0.3036263772197,-0.7614127699256352
367.8000000000045,42.46414715994648,0.306380316983742,-0.7820696838885945
368.9000000000045,42.57292873381841,0.30952421768900357,-0.8075377333765577
370.00000000000455,42.679287468656405,0.3150962707050261,-0.8306664655106912
371.10000000000457,42.78667139828765,0.31891388077077726,-0.853878877421427
372.2000000000046,42.89309064361338,0.3232394251404848,-0.8785825750882448
373.30000000000456,42.999721664468545,0.3251912991957513,-0.9021208274348891
374.4000000000046,43.10610862520656,0.33098370744889055,-0.9264474015954143
375.5000000000046,43.21211533200969,0.33289852344170884,-0.9505999059052486
376.6000000000046,43.3199990451428,0.337848368228543,-0.9774997176530285
377.70000000000465,43.42611189310237,0.34282695055753026,-1.0016700788138801
378.8000000000047,43.53200288941147,0.34588595316090304,-1.025340072325359
379.9000000000047,43.63948881123623,0.3508370342747037,-1.0539143403601372
381.00000000000466,43.7461740768059,0.35415847606317635,-1.0782984634673562
382.1000000000047,43.85281047509386,0.3595074982934724,-1.1020659336967515
383.2000000000047,43.95980138787422,0.3639355259892622,-1.128298148623978
384.30000000000473,44.065881843777696,0.3668191623554966,-1.1523435726302464
385.40000000000475,44.17291499850248,0.3721989258929122,-1.1762484675545224
386.5000000000048,44.27774018250039,0.3759847996732045,-1.2029856749278482
387.6000000000048,44.38597179963005,0.37959375327213335,-1.226306445358785
388.7000000000048,44.492279994775856,0.382135788871697,-1.2523576118005284
389.80000000000484,44.59802102980396,0.38416348399523487,-1.2747390713641145
390.9000000000048,44.70586653438526,0.3871601074685546,-1.2965776382475522
392.00000000000483,44.810503473936976,0.39104393900139617,-1.3193361523962088
393.10000000000485,44.91858857612747,0.3942021786499362,-1.3398645871754225
394.2000000000049,45.025783938831985,0.39642160063498133,-1.361697765055029
395.3000000000049,45.133355182554645,0.3988763500346135,-1.382951270441068
396.4000000000049,45.23939858267253,0.40000412885468134,-1.403800492904196
397.50000000000495,45.346712045891856,0.39928941050537076,-1.4258543172970986
398.6000000000049,45.4529075913841,0.39913510873162067,-1.4462087909819314
399.70000000000493,45.561040348172924,0.4024295552712013,-1.464513722365171
400.80000000000496,45.667652955165075,0.40190436249705946,-1.4819281021390944
401.900000000005,45.7753606891748,0.40313787201982576,-1.5007100848083912
403.000000000005,45.88329511469173,0.4042140190782281,-1.5179925490908017
404.100000000005,45.98884426093434,0.40379369952196353,-1.534993176347843
405.20000000000505,46.09693812254676,0.4052593170797165,-1.5515395057331034
406.30000000000507,46.204514645898705,0.40604439440176443,-1.5695299219957537
407.4000000000051,46.311480052213476,0.4085059703744734,-1.5877817193434098
408.50000000000506,46.417818877381464,0.4087882642606215,-1.6038855566153924
409.6000000000051,46.52605943414452,0.4096623869945119,-1.6188442480089078
410.7000000000051,46.63433422957873,0.4118048285149598,-1.6361284511526657
411.8000000000051,46.74020257755652,0.41312241403525396,-1.6522481292544429
412.90000000000515,46.84770733147612,0.41468750929026943,-1.6668695253710348
414.0000000000052,46.95556140581254,0.413705786386793,-1.683456581022582
415.1000000000052,47.06198926253201,0.4150006046248748,-1.6989317878240993
416.20000000000516,47.1692672792992,0.41502201517450327,-1.7140275084767116
417.3000000000052,47.27695507663876,0.41598820335875,-1.7286141888121334
418.4000000000052,47.38321507913858,0.41717351367021593,-1.7440673817801877
419.50000000000523,47.49088260743059,0.41715125072266035,-1.7557781938116563
420.60000000000525,47.598189703774956,0.41579824700882917,-1.7698557644909951
421.7000000000053,47.70531874844981,0.4188472424603661,-1.783341614232028
422.8000000000053,47.8129619182514,0.41684153884320574,-1.7978526905060748
423.9000000000053,47.91979013799624,0.41749522524654714,-1.8119398479212618
425.00000000000534,48.027715147374174,0.4162722222759185,-1.8251916292342227
426.1000000000053,48.134389344665095,0.4157846142066235,-1.8370767954326541
427.20000000000533,48.24176341328227,0.4131442839057081,-1.8523432076972512
428.30000000000535,48.34912960391023,0.4110402918949834,-1.8676847667683374
429.4000000000054,48.45615553246216,0.408077392389967,-1.8804022498915969
430.5000000000054,48.564226362251226,0.40915542418390255,-1.8934938616421206
431.6000000000054,48.67192263513274,0.4040306286762601,-1.9050066824775622
432.70000000000545,48.77834063448505,0.40230331230586724,-1.918792677064987
433.8000000000054,48.885974332702254,0.4003142542004838,-1.9310926692368193
434.90000000000543,48.99332960018296,0.3979361096369334,-1.9437931884643551
436.00000000000546,49.10120622386446,0.3938126285359395,-1.957318828819862
437.1000000000055,49.20818012751862,0.38877709718518466,-1.9682710582309988
438.2000000000055,49.31551014937168,0.3842784343353977,-1.9777941235791472
439.3000000000055,49.42301322606421,0.3823283406332144,-1.987631087893924
440.40000000000555,49.53120152252352,0.3778555875637448,-1.9997870960104578
441.50000000000557,49.63603901392793,0.3760243346951666,-2.009829050947025
442.6000000000056,49.74571523998656,0.3696705648963903,-2.0231357296059693
443.70000000000556,49.85381703107922,0.36849322348787666,-2.0305722185051485
444.8000000000056,49.96133521189109,0.361096698924447,-2.0386653546748392
445.9000000000056,50.06981117984704,0.35772870454504907,-2.050936929106375
447.0000000000056,50.17803162553963,0.3526906494132528,-2.0597244412500624
448.10000000000565,50.28456282560551,0.3491352265323146,-2.0670477943453167
449.2000000000057,50.39180587100232,0.3455449469818783,-2.0765152831220894
450.3000000000057,50.499799923333256,0.34037450142896275,-2.084318800039918
451.40000000000566,50.60758725194013,0.3384332641194479,-2.092869327162227
452.5000000000057,50.71487311973115,0.33326293424380415,-2.102713291441211
453.6000000000057,50.82162921383305,0.3295506024249118,-2.1096745536175803
454.70000000000573,50.93209289179926,0.325828327869135,-2.1162614327818776
455.80000000000575,51.03953854212432,0.3237770428868548,-2.1227270249330727
456.9000000000058,51.14824104288978,0.31968579064061714,-2.1305652233967267
458.0000000000058,51.253635884663645,0.31770915643784425,-2.1344809052754004
459.1000000000058,51.36229327275007,0.31429953149361123,-2.1405503672626898
460.20000000000584,51.47058452328703,0.3112725396456677,-2.1458975432008565
461.3000000000058,51.57970452279319,0.30745418707786243,-2.150531858172264
462.40000000000583,51.68475506328094,0.3031320870429716,-2.1537001363779535
463.50000000000585,51.79504734332556,0.30223997476284736,-2.156767834112865
464.6000000000059,51.90112592195784,0.29733528185210795,-2.1621806835930126
465.7000000000059,52.0097964226679,0.29640226055449487,-2.167199110680155
466.8000000000059,52.11879153798639,0.29339764294891485,-2.1724803543595046
467.90000000000595,52.226143697488325,0.29210636210968727,-2.176537559735155
469.0000000000059,52.333175763689674,0.2881971910831728,-2.181862168787516
470.10000000000593,52.441231216400936,0.28755708665456065,-2.187088453532467
471.20000000000596,52.54928322487421,0.28311175910189806,-2.1893366206080014
472.300000000006,52.65735333175069,0.2829555481479671,-2.1914268503554113
473.400000000006,52.764982484698116,0.2805106772933834,-2.1937899108682624
474.500000000006,52.872574047162544,0.2793510328813683,-2.1963685012566607
475.60000000000605,52.978981439396485,0.27873050676514965,-2.199071042442987
476.70000000000607,53.088820352046255,0.27660608286201005,-2.201609221992679
477.8000000000061,53.196280902795536,0.275310449862904,-2.20403017572868
478.90000000000606,53.303690443621704,0.2714772975338382,-2.2071287505044523
480.0000000000061,53.4139122969919,0.2723999763705336,-2.2096203105204064
481.1000000000061,53.52105208010656,0.2688676032741767,-2.2109204935257787
482.2000000000061,53.62902381830674,0.2682415600873962,-2.2135592238134225
483.30000000000615,53.736511030956024,0.26491018914801445,-2.214869953765684
484.4000000000062,53.84414602383284,0.26405483614811154,-2.216187474269184
485.5000000000062,53.95368933405661,0.26509267672788617,-2.217510329978467
486.60000000000616,54.06050085323912,0.26499563005556215,-2.220048287882573
487.7000000000062,54.16928663602456,0.26368247621901264,-2.220139997651861
488.8000000000062,54.277320145609465,0.26226806084324294,-2.220140003013321
489.90000000000623,54.383228761875124,0.2608593681111492,-2.2214364985653097
491.00000000000625,54.4924131245307,0.25811382004273153,-2.2227692625784385
492.1000000000063,54.601401473830734,0.25941101298955016,-2.222734004946753
493.2000000000063,54.7088972273471,0.2558476369442758,-2.224094662636244
494.3000000000063,54.817524324867854,0.2540351412855293,-2.22410000081637
495.40000000000634,54.92560823691874,0.2543726653140861,-2.225296861694252
496.5000000000063,55.03422561676371,0.25341789309127627,-2.2279234745426275
497.60000000000633,55.141783736552746,0.25367900937041055,-2.230748636243458
498.70000000000636,55.24961499326174,0.2554484571675302,-2.2280589440016643
499.8000000000064,55.356516096163666,0.2528904841305598,-2.229359932114563
500.9000000000064,55.46683715792436,0.24876354285294944,-2.230018253045476
502.0000000000064,55.57371334598478,0.25222328657488347,-2.2316732305036906
503.10000000000645,55.684472932458064,0.2514999249848574,-2.2324404069210884
504.2000000000064,55.792185850854125,0.26139687214856655,-2.2316659274341144
505.30000000000643,55.900770284909406,0.26509854942870614,-2.232989992926272
506.40000000000646,56.00902227105039,0.267871857270809,-2.232993376627194
507.5000000000065,56.11707766050942,0.27080241396491267,-2.2343322454949623
508.6000000000065,56.22483750892201,0.2736989643630783,-2.234619931930952
509.7000000000065,56.33142980865715,0.27113174112315575,-2.231988905516131
510.80000000000655,56.4420374021998,0.2675504207876991,-2.2334992618104317
511.90000000000657,56.550964438407306,0.2674456276831335,-2.2333099940533883
513.0000000000066,56.65851701900793,0.26627763203882016,-2.234637233826147
514.1000000000065,56.76855485784609,0.2648316524072406,-2.235949994411651
515.2000000000066,56.876712376550124,0.25891983536618646,-2.238589606938324
516.3000000000065,56.98489624482095,0.25536936831156154,-2.2385988763086884
517.4000000000067,57.09177448027783,0.25171996954235465,-2.2375999881418296
518.5000000000066,57.20279545734353,0.24663563122526433,-2.23759524252395
519.6000000000067,57.310861928835145,0.24175404455953642,-2.2376006924022604
520.7000000000066,57.420588477022555,0.23913459623747346,-2.23725390756965
521.8000000000067,57.52902144750108,0.23819035962675839,-2.238580080386625
522.9000000000067,57.63744530740176,0.23175705422752269,-2.239251677193229
524.0000000000067,57.74706677797018,0.23004094224173288,-2.241211392343113
525.1000000000067,57.85498780788355,0.22765195310769148,-2.2425404500547703
526.2000000000068,57.963469738433496,0.22573145365160607,-2.243858225986581
527.3000000000068,58.07252476386166,0.22309916189109025,-2.2413151492332912
528.4000000000068,58.180633389293035,0.22211548411761095,-2.2398999758527913
529.5000000000068,58.29065355862953,0.21885876910190327,-2.2398999996964104
530.6000000000068,58.3991849299796,0.21799647769624597,-2.2388510043847942
531.7000000000069,58.507133218399716,0.21789019199031512,-2.2385899781797898
532.8000000000068,58.617435457431235,0.2151106237717616,-2.2397093021883094
533.9000000000069,58.72699178963814,0.21229890722036315,-2.2388292302022488
535.0000000000068,58.835356204713776,0.20809154260737062,-2.240246049840309
536.100000000007,58.94432855265989,0.20837612954364249,-2.2422051166319146
537.2000000000069,59.052631989150434,0.20701581406307867,-2.2421999806014545
538.300000000007,59.16185535130609,0.2055501791339286,-2.2428180159761264
539.4000000000069,59.27031018413029,0.20188192948520944,-2.241665019022009
540.5000000000069,59.38052952334286,0.2000458849618414,-2.2436717147946146
541.600000000007,59.48889622601637,0.19826692005849644,-2.2428711092788163
542.700000000007,59.5971945193275,0.1982088739767135,-2.242870083639552
543.800000000007,59.70681585822807,0.19525504510571567,-2.2454540487915993
544.900000000007,59.81600579627263,0.19267842311502403,-2.2442175528309503
546.000000000007,59.924810883817415,0.1930443808183624,-2.2448365561608457
547.1000000000071,60.033566934221774,0.19035814682403973,-2.246989327771489
548.2000000000071,60.14408038691558,0.19105679236068673,-2.2484940831186924
549.300000000007,60.25129918717846,0.19105131982508716,-2.2510980789768134
550.4000000000071,60.36091146969768,0.1887413741757804,-2.2471514560491817
551.500000000007,60.47000000000069,0.18818869960795148,-2.2471505915222227
552.6000000000072,60.57911864980646,0.1864227869235372,-2.2464896290347385
553.7000000000071,60.688410666085744,0.1870745158227365,-2.2484775963381503
554.8000000000072,60.79813904659815,0.18601385050966224,-2.2476999618806937
555.9000000000071,60.907780956717225,0.1861437924523196,-2.2480202414587493
557.0000000000072,61.01636577221903,0.183719143557177,-2.2493398331935603
558.1000000000072,61.12584492318144,0.1867828276869381,-2.251979808288029
559.2000000000072,61.235234985077,0.18411727229236674,-2.2509900191779195
560.3000000000072,61.342069166569964,0.18360938318870978,-2.2523095500302013
561.4000000000073,61.453085522958276,0.18138893934364242,-2.2509684573043067
562.5000000000073,61.561827942230714,0.17930428515075358,-2.248380935656936
563.6000000000073,61.67159557059821,0.18034800870186918,-2.2483636438569494
564.7000000000073,61.78063197476702,0.1784801709190904,-2.2496799940097603
565.8000000000073,61.889569097474514,0.17986084365670896,-2.2510956780385247
566.9000000000074,61.9984406647546,0.17779034121493598,-2.2536250115273773
568.0000000000074,62.10752257683983,0.17589753748461778,-2.2575689392707496
569.1000000000074,62.216159817809064,0.17670446546868546,-2.2575779585282416
570.2000000000073,62.32672138711556,0.1741977962745077,-2.2562648190841457
571.3000000000073,62.435227703435736,0.17436616170121533,-2.2541711599704644
572.4000000000074,62.544048482457505,0.17112164068199154,-2.2518620347195775
573.5000000000074,62.65349068245895,0.16987862159247336,-2.2550486373660212
574.6000000000074,62.76310478121613,0.16974848398125475,-2.2576028040241325
575.7000000000074,62.872321930373346,0.1670702472566059,-2.2597096132840364
576.8000000000075,62.98201262248969,0.16627659297772612,-2.259070936635044
577.9000000000075,63.09144573830602,0.16651296241511016,-2.2576900029458526
579.0000000000075,63.2008388630008,0.16461535983125442,-2.2590092597477325
580.1000000000075,63.31000200563441,0.16420551607375233,-2.2603049614127375
581.2000000000075,63.418672919137634,0.16443292468206816,-2.2590101371370133
582.3000000000076,63.527112172151924,0.16186200638283588,-2.2590019838169324
583.4000000000076,63.63599382668032,0.1617469549902124,-2.259010006426182
584.5000000000076,63.74509711642556,0.16366888379876643,-2.2596653519899865
585.6000000000076,63.85494828379435,0.16458381281855305,-2.2629379773042695
586.7000000000077,63.96439543106162,0.16521947202947573,-2.2642697107231444
587.8000000000077,64.0731669915895,0.1692228783994676,-2.2646074683713837
588.9000000000076,64.18200019458519,0.16883193533976026,-2.2642846427985983
590.0000000000076,64.29066187748086,0.17352684873004265,-2.2628699814679383
591.1000000000076,64.40050191820312,0.17299770430010208,-2.2615302293829354
592.2000000000077,64.5099034146086,0.17654022153998683,-2.2634804060162073
593.3000000000077,64.61940418900465,0.1786507702172324,-2.26349999924077
594.4000000000077,64.72943929610781,0.18479912011223065,-2.2647314249315027
595.5000000000077,64.83811001214195,0.190112375136281,-2.2643520243033404
596.6000000000078,64.94819032963787,0.19659478712768108,-2.266799547368855
597.7000000000078,65.05722815465703,0.19955932851256952,-2.2681202949128285
598.8000000000078,65.16622648140692,0.2084107312777277,-2.268120000004192
599.9000000000078,65.27687143649383,0.20848179589575444,-2.2681112441454077
601.0000000000078,65.38744518132835,0.21514440096825926,-2.2696212543538303
602.1000000000079,65.49402893782214,0.22001642883374095,-2.270879492611977
603.2000000000079,65.60587348364835,0.22087691767058693,-2.271061640956018
604.3000000000079,65.71310567446456,0.22461429240786357,-2.272070087762753
605.4000000000078,65.82481040963077,0.22761226783898525,-2.27349376472786
606.5000000000078,65.93489800908792,0.2345406667021771,-2.2724630050800783
607.6000000000079,66.04358172695107,0.23640902420460363,-2.2750306550150707
608.7000000000079,66.15420443739492,0.24053655010660835,-2.275978394025875
609.8000000000079,66.26362775998479,0.24672386927215884,-2.276581204389659
610.9000000000079,66.37285884639165,0.24738533176740374,-2.2776698283208376
612.000000000008,66.48308124973228,0.2528311822838677,-2.2789900357894344
613.100000000008,66.59167362258988,0.2560797266981406,-2.2794778546580097
614.200000000008,66.70145067753195,0.2615231482584449,-2.2813251307731424
615.300000000008,66.81159225453652,0.26397923948319063,-2.282930289560379
616.400000000008,66.92069427636251,0.2640960707873773,-2.2833231868652555
617.5000000000081,67.03000000000083,0.2669653440406453,-2.285569539816029
618.6000000000081,67.1401028007071,0.2688175081131201,-2.2855793317332522
619.7000000000081,67.25031076854523,0.27364006361637444,-2.2869852724954383
620.8000000000081,67.35838836975667,0.2765267395908532,-2.288303291129829
621.9000000000082,67.46890797923425,0.2800797349195662,-2.289219626384941
623.0000000000082,67.57878191696014,0.2818170930394449,-2.2899699547492425
624.1000000000081,67.68875496863166,0.2877011684877615,-2.291295101538683
625.2000000000081,67.79831355712707,0.29058520948800554,-2.293794486813163
626.3000000000081,67.90856712072575,0.2936014200652829,-2.2952394248937766
627.4000000000082,68.01745881554625,0.29666498801456254,-2.296275023242016
628.5000000000082,68.12454985336488,0.3012111504622508,-2.2962194281686807
629.6000000000082,68.23761267404797,0.30464316709862876,-2.297459807794867
630.7000000000082,68.3463119511162,0.3100234564583173,-2.3001426142022243
631.8000000000083,68.45622991905798,0.3195661245335274,-2.2988833783262312
632.9000000000083,68.56614635641334,0.32190146924209684,-2.301093931157885
634.0000000000083,68.67567736851568,0.3304793741655629,-2.3029985236056483
635.1000000000083,68.78634509997278,0.3401218192148918,-2.3049387346285837
636.2000000000083,68.89548569608466,0.34212373822881265,-2.3056151267830214
637.3000000000084,69.00489133290472,0.3519874129767869,-2.308243208625537
638.4000000000084,69.11423964202102,0.35974832965328984,-2.310127944007025
639.5000000000084,69.22348507079165,0.3714578317078655,-2.3139207447839905
640.6000000000083,69.3334958444199,0.37841231651773,-2.3152477308830908
641.7000000000083,69.44296715297483,0.39240171763394865,-2.319451330314854
642.8000000000084,69.55277856303735,0.4009317292622199,-2.322791955650266
643.9000000000084,69.66136167118047,0.4081182694862178,-2.3238055471028467
645.0000000000084,69.77147401345762,0.41906719250671726,-2.3260598985095893
646.1000000000084,69.87968667148176,0.43594062966948144,-2.3276196221680743
647.2000000000085,69.99022157786449,0.44454576051913036,-2.329928670480091
648.3000000000085,70.09930490476471,0.4534675154717573,-2.331250340800514
649.4000000000085,70.20876024239209,0.4621064668510003,-2.334047808544587
650.5000000000085,70.31806392529226,0.4673471466855435,-2.3341729185617157
651.6000000000085,70.42729105891587,0.4733571082402338,-2.339476383963836
652.7000000000086,70.53704572950191,0.47721596308799524,-2.341441207256139
653.8000000000086,70.64609397094164,0.48054359206359737,-2.344003587067582
654.9000000000086,70.7566746264093,0.4803601168614743,-2.3466146608445317
656.0000000000086,70.86601284904049,0.4781801448653053,-2.349425866097305
657.1000000000087,70.97479856947979,0.47023581018124816,-2.3524049710627164
658.2000000000087,71.08507158509325,0.4669227624058835,-2.3563611999930636
659.3000000000086,71.19571904621716,0.45864164737510177,-2.3605776288920026
660.4000000000086,71.30528251980654,0.45071291211241493,-2.361861694677554
661.5000000000086,71.4129981397719,0.4433311207298649,-2.364499058461631
662.6000000000087,71.52599095084697,0.43917901365161055,-2.364935720806711
663.7000000000087,71.63409492170383,0.4458618248528512,-2.369009817570858
664.8000000000087,71.74475235499445,0.46062254919026213,-2.3740100599507543
665.9000000000087,71.85649246304285,0.4775725512332169,-2.3769540685999684
667.0000000000088,71.96607139083835,0.4953670004615396,-2.378348485511563
668.1000000000088,72.07613725597012,0.511833685413932,-2.3817759519713206
669.2000000000088,72.18560924543115,0.521651846361956,-2.383761771943773
670.3000000000088,72.29582883229226,0.5309966844081723,-2.387407099169943
671.4000000000088,72.40594571197678,0.5334806153551419,-2.38987872892102
672.5000000000089,72.51612894716125,0.528118255585587,-2.3942455949466352
673.6000000000089,72.62621583534225,0.5154023001532664,-2.3988326142291534
674.7000000000089,72.73621932219058,0.4965011540344299,-2.401398055253696
675.8000000000088,72.84588902819073,0.47334603258653435,-2.404248184878865
676.9000000000088,72.956128359043,0.4377957447838945,-2.4070016271096146
678.0000000000089,73.06392201206154,0.39916187116915564,-2.4093257145291247
679.1000000000089,73.17552090169869,0.35504813266792096,-2.41093991811082
680.2000000000089,73.28585395357142,0.31519821026469436,-2.4135920385481855
681.3000000000089,73.39574134698826,0.27496609377042946,-2.4149786998637093
682.400000000009,73.50471208488405,0.2387202207973642,-2.4161914056395313
683.500000000009,73.61547485366727,0.21103687393534465,-2.415879422383843
684.600000000009,73.72437885317007,0.1880421919557138,-2.4184947933498337
685.700000000009,73.83329616470353,0.16537867374904203,-2.4198402188344033
686.800000000009,73.94506243762652,0.1515920804201728,-2.421161574323415
687.9000000000091,74.05323953273484,0.13842995680013648,-2.4214937782981174
689.0000000000091,74.16505357956959,0.13114899023460913,-2.421176159679689
690.1000000000091,74.2742693545517,0.1287415714947161,-2.4211538166377258
691.2000000000091,74.38495300141368,0.1260576679081601,-2.4224700429325075
692.3000000000092,74.4948948970742,0.12171748322915743,-2.4237905089121714
693.4000000000092,74.60503303343337,0.12014434868541424,-2.425675484787141
694.5000000000091,74.71582370867118,0.12057828266988047,-2.4263978612953663
695.6000000000091,74.82523364251847,0.11662940389680165,-2.4251815044614045
696.7000000000091,74.9350602628617,0.11478215326335905,-2.4227438513399635
697.8000000000092,75.04637924698122,0.11431762009547541,-2.42377999743448
698.9000000000092,75.15536815836975,0.11400880439295558,-2.4250674228361953
700.0000000000092,75.26459155437695,0.11242787838794055,-2.4264310526664197
701.1000000000092,75.37577410359951,0.10874805721622638,-2.425074631663282
702.2000000000093,75.48705261573141,0.107229960580565,-2.427701661266065
703.3000000000093,75.59731386611463,0.10496999587966349,-2.426800293222022
704.4000000000093,75.70706225775774,0.10317973173646733,-2.4264249037203203
705.5000000000093,75.81773313926145,0.09970353605021687,-2.4263429874895945
706.6000000000093,75.92812524799614,0.09862470311500704,-2.4264200000349057
707.7000000000094,76.0381339705863,0.10084800266521066,-2.4263991403468097
708.8000000000094,76.14941448363116,0.09949525361934186,-2.4270799786888304
709.9000000000094,76.25929515258338,0.0992903670463604,-2.428382742588101
711.0000000000093,76.36951113092977,0.098938671857282,-2.426456502063994
712.1000000000093,76.47830294208232,0.09529019568249664,-2.429079813290902
713.2000000000094,76.5879505954893,0.09580627243996076,-2.42897498186572
714.3000000000094,76.6995971492789,0.0951152858147889,-2.430415034123679
715.4000000000094,76.81052658362628,0.08871989218669141,-2.4290513296501066
716.5000000000094,76.92080524668653,0.09227982768623144,-2.4277399966741555
717.6000000000095,77.03161232659083,0.09248770066777323,-2.4290401990868316
718.7000000000095,77.14150595228352,0.09488678342122758,-2.430369969143567
719.8000000000095,77.25304716751135,0.09158113388042344,-2.431561852971146
720.9000000000095,77.36196097815117,0.08953916061771094,-2.43303054796682
722.0000000000095,77.47252079669006,0.0925930897200008,-2.4330099934511233
723.1000000000096,77.58383521354939,0.09139053149551102,-2.43201107862017
724.2000000000096,77.69481311329868,0.090343466154156,-2.433009999993785
725.3000000000096,77.80584007452312,0.0955444306247556,-2.4330100000397503
726.4000000000096,77.91628651426659,0.09338197101401302,-2.4323205315568956
727.5000000000097,78.02525813243321,0.0916448843011547,-2.431649444282673
728.6000000000097,78.13704413026088,0.09130004973505956,-2.4344222830331157
729.7000000000096,78.24630985112744,0.09133593376703342,-2.435379473397129
730.8000000000096,78.3566006315385,0.09059929127230992,-2.436081531320627
731.9000000000096,78.4667469507872,0.08911093504934287,-2.4337857948312625
733.0000000000097,78.57688942844968,0.08737009544568453,-2.4325898437276736
734.1000000000097,78.68758831628334,0.09057148362151435,-2.4350275121989045
735.2000000000097,78.79704650388221,0.08708751062781028,-2.4364100150048724
736.3000000000097,78.90754961519157,0.08632704863924645,-2.4372138436893946
737.4000000000098,79.0173570669717,0.08643235855451858,-2.438840501292484
738.5000000000098,79.12748458831683,0.08392904479851837,-2.436426519377126
739.6000000000098,79.23820275817259,0.08139853495891958,-2.433780940265264
740.7000000000098,79.34799813577149,0.07989058230268187,-2.434439147008729
741.8000000000098,79.4581298872448,0.08383016935627707,-2.4360797407345807
742.9000000000099,79.56890877705928,0.08441173338352492,-2.4360882149871093
744.0000000000099,79.67894917358456,0.08382546976376792,-2.437395865337078
745.1000000000099,79.78877343810716,0.0891187402310536,-2.440358184748257
746.2000000000098,79.89980561694703,0.08950693604778337,-2.4403664675205103
747.0000000000099,79.98039783086409,0.08879421974296442,-2.4407326748595746