File: 01_Data/EPDM_Membrane/STA/N2/10K_min/EPDM_Membrane_STA_N2_10KData_220927_R1.csv
##Temp./Â°C,Time/min,DSC/(mW/mg),Mass loss/mg
51.0,10.753978432817938,0.024152955575060142,-0.016468933552491904
52.100000000000016,11.136770943109461,0.06824001762857734,-0.015319520088139527
53.20000000000003,11.390517305117443,0.09561004997059808,-0.01606592198855772
54.30000000000005,11.598363716768674,0.115273823008335,-0.017361388961810498
55.40000000000006,11.78366198935182,0.13147163948796492,-0.01564873130169442
56.50000000000008,11.956038083849958,0.1443598918211344,-0.013555228893127769
57.600000000000094,12.117417914371632,0.15206828475801504,-0.013425349848240842
58.70000000000011,12.274851905907019,0.1621732506241289,-0.016100764461124406
59.800000000000125,12.421332439990316,0.1658493238622496,-0.01404630521378536
60.90000000000014,12.5676955568773,0.17209480396695453,-0.015600914974622349
62.000000000000156,12.712252448038093,0.1792317854872285,-0.016873618245794475
63.10000000000017,12.85211439804049,0.185249886094756,-0.018334675861611416
64.20000000000019,12.98967356984552,0.18800303350847747,-0.017925436062846245
65.30000000000021,13.124717756597546,0.1949755768107866,-0.016751459091023158
66.40000000000022,13.25677189910414,0.1949953095894703,-0.013657205506505399
67.50000000000023,13.387659087476946,0.19934537095172078,-0.00948587626462949
68.60000000000025,13.516632264888312,0.20416090398919473,-0.006758174185992338
69.70000000000027,13.64216236769673,0.20754457892288802,-0.009699014203245149
70.80000000000028,13.771203789320147,0.21290539807656184,-0.013625239672437672
71.90000000000029,13.895778774249395,0.21834686223326516,-0.013691585999713318
73.00000000000031,14.019542442445996,0.2194874474170827,-0.014958073254136117
74.10000000000034,14.144140477023218,0.2231363518781695,-0.0162371754121704
75.20000000000034,14.266523372359359,0.2272753113252074,-0.014897409179940979
76.30000000000035,14.38734201511373,0.22838817799689426,-0.01624268784400673
77.40000000000038,14.508538777097122,0.23337657776560616,-0.01537397788781103
78.5000000000004,14.628417193578457,0.2355701226140262,-0.016777161837775445
79.6000000000004,14.748025603143212,0.23883323551389313,-0.017569677890944213
80.70000000000041,14.86604548425815,0.24065781076262893,-0.017541741558495083
81.80000000000044,14.983343758823873,0.24364188326646696,-0.018723716625323128
82.90000000000046,15.10092370275046,0.24608489028073766,-0.017680144642320705
84.00000000000047,15.216434117461825,0.24956639285334514,-0.017775213787171396
85.10000000000048,15.331312554790687,0.24973950527763034,-0.017685268777579033
86.2000000000005,15.445906892839838,0.2553302512890745,-0.018970143352177615
87.30000000000052,15.56189534083802,0.25712785131985794,-0.017698268067587897
88.40000000000053,15.676478122653501,0.2588329120597782,-0.01768281094072055
89.50000000000054,15.790930504568312,0.2621914756954403,-0.017681234749337804
90.60000000000056,15.901677499837845,0.2626827808340687,-0.01767865732439322
91.70000000000059,16.01395555137122,0.2639055125857369,-0.01784959414692544
92.8000000000006,16.1260758920756,0.26691834567379646,-0.017767180193144938
93.9000000000006,16.237135610053276,0.26866504962235693,-0.018996498139588702
95.00000000000063,16.347286842206973,0.27059982816866224,-0.017975514447662988
96.10000000000065,16.457428422561954,0.2744703095228588,-0.019349508807295024
97.20000000000066,16.565173534174097,0.2762462091902771,-0.018997265769342242
98.30000000000067,16.678087341578603,0.2775762092465379,-0.018947568309140905
99.40000000000069,16.788131494939936,0.27829729717903806,-0.01899876874554085
100.50000000000071,16.89795142341057,0.28189489389045597,-0.020305624161391478
101.60000000000072,17.00625677465029,0.2824516745537704,-0.02030997886581698
102.70000000000073,17.115192542463443,0.2839719746662043,-0.02168099575309501
103.80000000000075,17.224286879015636,0.2865002078052501,-0.02052700877857294
104.90000000000077,17.33251722608806,0.2854737247337539,-0.021620051889257752
106.00000000000078,17.44087722546596,0.2871338561604144,-0.021629667899083493
107.10000000000079,17.54785369874923,0.2885680315009769,-0.02294914192015174
108.20000000000081,17.65703087526934,0.29047075852144366,-0.021628502000923255
109.30000000000084,17.765790665834274,0.2921186517542703,-0.02160391444463361
110.40000000000084,17.874172081628018,0.2926866134573771,-0.02162037127897154
111.50000000000085,17.981287314707878,0.29276677807047247,-0.02243985889656752
112.60000000000088,18.088967888727655,0.2956122330263492,-0.022950200903625984
113.7000000000009,18.196933313154453,0.2991422605294717,-0.021960444269092605
114.8000000000009,18.304930881740052,0.29958699591314775,-0.022950374343669644
115.90000000000092,18.411437689268624,0.2999514719713109,-0.022938497130566837
117.00000000000094,18.51832637028309,0.2969129735436975,-0.02293537939593282
118.10000000000096,18.625547544535987,0.295596365286224,-0.023314437918211972
119.20000000000097,18.732720392084758,0.29624478565170986,-0.022935021279625545
120.30000000000098,18.840626461799747,0.2948182338660097,-0.024289265018179407
121.400000000001,18.946404217235205,0.2963844508762208,-0.025577918107440034
122.50000000000102,19.054501717072746,0.2975289937595129,-0.024575657351607383
123.60000000000103,19.160257796572782,0.2974892584957335,-0.024264715855311536
124.70000000000104,19.266617955852695,0.29791680115448615,-0.025582384181959128
125.80000000000106,19.374815366064535,0.29753197914085205,-0.024244295888482092
126.90000000000109,19.479974324576453,0.30011728293446815,-0.025249976910552974
128.00000000000108,19.587508239064654,0.30059360567550175,-0.026537385164584926
129.1000000000011,19.69382244391384,0.3000242390004735,-0.025251888007325363
130.20000000000113,19.798680023197917,0.3021053097916738,-0.025909948431152685
131.30000000000115,19.906060070311927,0.3025372795937601,-0.026570854193979088
132.40000000000117,20.01162270051294,0.3032730391036854,-0.02657172678267994
133.50000000000117,20.11742720966328,0.30392620578911733,-0.02736656622632072
134.6000000000012,20.223189416492026,0.30531403344871266,-0.02656936279595712
135.7000000000012,20.329080678636533,0.3068486242641204,-0.027938443080072872
136.8000000000012,20.433899159567428,0.3078030241332962,-0.02787996330598741
137.90000000000123,20.538130326798957,0.3084868083323622,-0.028010402991135663
139.00000000000125,20.64455845022991,0.30933619904573795,-0.02787376438033551
140.10000000000127,20.749863146547398,0.30902776873702276,-0.027890363139682073
141.2000000000013,20.85439164610471,0.31114612534690533,-0.02859964092688383
142.3000000000013,20.959636870893608,0.3108751770959962,-0.02788957919300472
143.4000000000013,21.0641412009149,0.3111997849369116,-0.02920843797576822
144.50000000000134,21.168398138962385,0.3146358252694552,-0.02788943125546961
145.60000000000133,21.274163594238548,0.3143678822150603,-0.028490166669801198
146.70000000000135,21.378893679440868,0.3144099136030618,-0.029529965026373617
147.80000000000138,21.482013660886984,0.31367655882301826,-0.030520451926022485
148.9000000000014,21.587984171720596,0.31535550394379497,-0.03052016000102853
150.00000000000142,21.693264062105147,0.31482777925267036,-0.03055831378059448
151.10000000000142,21.797688590602466,0.3159557538147828,-0.031842352765777626
152.20000000000144,21.902356288232482,0.3165104467223814,-0.03182985410669836
153.30000000000146,22.006361075232853,0.31793076383308505,-0.03293762234238695
154.40000000000146,22.111687595552965,0.3200533526164314,-0.03182183876210454
155.50000000000148,22.213884124165517,0.3191152861793841,-0.03226303477496861
156.6000000000015,22.320250726496845,0.32022983679318073,-0.034577860662458715
157.70000000000152,22.42536408125724,0.3199346165236394,-0.03360154542925242
158.80000000000155,22.52859805171408,0.3220439995998424,-0.03351523445911342
159.90000000000154,22.633382234988765,0.32207949231927935,-0.0358923449352071
161.00000000000156,22.738086235888737,0.3240152632023332,-0.03623018195297201
162.1000000000016,22.841239513932607,0.32304668293304484,-0.03623018214465956
163.20000000000158,22.946756164873314,0.3242641603173009,-0.03752059258150808
164.3000000000016,23.051301342330365,0.32346971335129027,-0.036999662991679116
165.40000000000163,23.155753039957983,0.3228572923308489,-0.03689010835519024
166.50000000000165,23.261078152139564,0.32534966778927366,-0.03787982669134937
167.60000000000167,23.365505797735565,0.32551291795970627,-0.03788032524827578
168.70000000000167,23.469458756960144,0.3262121660865974,-0.03920011515515087
169.8000000000017,23.57445610068367,0.3251064583882828,-0.039200125011327636
170.9000000000017,23.678985570920155,0.32494356822177406,-0.03915980456658241
172.0000000000017,23.78319634796072,0.3249118443749125,-0.042526331780893045
173.10000000000173,23.88906358662733,0.3260084249288526,-0.0411686391898054
174.20000000000175,23.993290825943784,0.3234456460683326,-0.041103736275849734
175.30000000000177,24.09762295850577,0.32404394561515737,-0.041088765773298785
176.4000000000018,24.202185500681985,0.3239453157396375,-0.03831439030184036
177.5000000000018,24.306908884882848,0.3250431359929822,-0.03963202446559899
178.6000000000018,24.411670736730155,0.32254758333263034,-0.04312267189079444
179.70000000000184,24.51612451249196,0.32303076332534986,-0.04563245957927986
180.80000000000183,24.616628939497474,0.321516713035362,-0.045560306249766924
181.90000000000185,24.724160765411224,0.3223011427189163,-0.046879666492291694
183.00000000000188,24.82898491605102,0.3235556820543285,-0.04818986924900592
184.1000000000019,24.93306566221455,0.3223990597571429,-0.048189874692097234
185.20000000000192,25.034605313285496,0.32222244476238626,-0.048733097495961
186.30000000000192,25.141812240752888,0.32276308021946754,-0.0501638796845163
187.40000000000194,25.24489088982887,0.3205949662970319,-0.051490368766447414
188.50000000000196,25.34917000000017,0.3202935326438936,-0.05017887636110441
189.60000000000196,25.45320189770565,0.3210757599179207,-0.05148954713533893
190.70000000000198,25.557578659332414,0.3215859480540203,-0.05278790892459195
191.800000000002,25.661548133589275,0.3196762600754187,-0.05192426064095912
192.90000000000202,25.765981461145465,0.32050718587356475,-0.052262433659596486
194.00000000000205,25.86927307758483,0.3197657786770858,-0.05356939008490569
195.10000000000204,25.972013553097245,0.3205554237147622,-0.05621010633612089
196.20000000000206,26.07809373628707,0.3212943468214861,-0.05621021064336196
197.3000000000021,26.182521434056977,0.32200140246673764,-0.057530123915499054
198.40000000000208,26.286638216612573,0.32197458590723377,-0.0589045521819207
199.5000000000021,26.3905960192869,0.32085051566918765,-0.05947421811879838
200.60000000000213,26.495066469738216,0.3210324121097758,-0.06106819131596852
201.70000000000215,26.599622802823777,0.32383678944128436,-0.0634886998744042
202.80000000000217,26.70259206443038,0.3228170369971009,-0.06410761649672869
203.90000000000217,26.8073444133274,0.3236217106291103,-0.06444651797412604
205.0000000000022,26.911488008391604,0.3256053470119433,-0.06707021947871894
206.1000000000022,27.01606285988738,0.32580629210526296,-0.06707000884748338
207.2000000000022,27.120022879184816,0.32755468927883646,-0.06772302873574132
208.30000000000223,27.224005433597004,0.32919631126844323,-0.06970963992924784
209.40000000000225,27.328480582868945,0.3304077328232722,-0.07232493448288935
210.50000000000227,27.432002937585427,0.3323203145786536,-0.07374264044245082
211.6000000000023,27.536564203355837,0.3345721187565631,-0.07466754431238387
212.7000000000023,27.64150279454184,0.33760763885187656,-0.07575943241807703
213.8000000000023,27.745057055857515,0.3366473699430886,-0.07630220779107333
214.90000000000234,27.849170941575235,0.3380395601411446,-0.07992937340814166
216.00000000000233,27.9542832706984,0.3395889408492513,-0.0797981617874477
217.10000000000235,28.055819653341995,0.3418065490702153,-0.08122362378448633
218.20000000000238,28.162394981078485,0.3419829420546203,-0.08255037205056404
219.3000000000024,28.266377655430798,0.3447598849668676,-0.08480881390661343
220.40000000000242,28.37056129364377,0.3452904432316949,-0.08684684950645716
221.50000000000242,28.47510547411251,0.34792073537163626,-0.08843146450535855
222.60000000000244,28.5797668654014,0.3498693587011155,-0.09079003720486911
223.70000000000246,28.683632004563396,0.3497978006637542,-0.09219421517323134
224.80000000000246,28.789170000000244,0.3530628405241294,-0.09474973474479542
225.90000000000248,28.892737659112367,0.35390359300681945,-0.09604817758222683
227.0000000000025,28.99719724528374,0.35493644706618915,-0.09738018817096972
228.10000000000252,29.101278690179353,0.3561322243419832,-0.10001956219546049
229.20000000000255,29.20547358490685,0.3570317551550946,-0.10259411149432385
230.30000000000254,29.310926733249477,0.3579935482402371,-0.10330343664750119
231.40000000000256,29.41516566238958,0.35921770338041376,-0.10528352649667871
232.5000000000026,29.519892161637543,0.35932279450314397,-0.10691460427382715
233.60000000000258,29.624307217652564,0.3604364191680026,-0.10949015154438735
234.7000000000026,29.728770385974087,0.3611904159133848,-0.1131629405767618
235.80000000000263,29.833769498744193,0.362915440306351,-0.11553578591665659
236.90000000000265,29.937924413173004,0.3635525850485529,-0.1150514391312929
238.00000000000267,30.043163573263186,0.36407187520551365,-0.11788509983789774
239.10000000000267,30.1481298308148,0.3649296515902042,-0.12121273622732431
240.2000000000027,30.251798115090637,0.36492935273532573,-0.12320255980537897
241.3000000000027,30.356462221147194,0.36586997819184025,-0.12580553006469541
242.4000000000027,30.460033970211466,0.36785717331183043,-0.12711922244160512
243.50000000000273,30.565296443623897,0.36782360507124323,-0.1305180802491579
244.60000000000275,30.66846315977589,0.3663603306547059,-0.13313840589255443
245.70000000000277,30.774112703176797,0.36711484207321715,-0.13574731584444288
246.8000000000028,30.878298764434412,0.3679518795731891,-0.13713322593555288
247.9000000000028,30.982482242427388,0.3673252732860557,-0.14070076659971376
249.0000000000028,31.08805766843814,0.36782105622322675,-0.14247785560813098
250.10000000000284,31.19159290407806,0.3674557319066404,-0.14644542575691055
251.20000000000283,31.296579485212344,0.3686834380325025,-0.1487508039793699
252.30000000000285,31.40074615265646,0.36756116201095734,-0.15171249386127927
253.40000000000288,31.503176242610433,0.3678322190772724,-0.15562840826183466
254.5000000000029,31.610440832954517,0.3692413386129745,-0.15831497699018682
255.60000000000292,31.713949886210383,0.3685663636575617,-0.15957570803468712
256.7000000000029,31.81916901451854,0.37038293560087293,-0.16357829127115142
257.8000000000029,31.922430549651803,0.3686158048022915,-0.16719352987433034
258.90000000000293,32.02742402457071,0.36665177445510033,-0.1698620942178426
260.00000000000296,32.13133837702614,0.36702764295944934,-0.17247660240222862
261.100000000003,32.23693957226358,0.3655706000139399,-0.17545432438816988
262.200000000003,32.34098921383242,0.36699944201252765,-0.17812912362790678
263.300000000003,32.44539974550996,0.36651297097180907,-0.18085286666786082
264.40000000000305,32.55057285034761,0.36621873781453224,-0.1850791002152694
265.50000000000307,32.65509696519195,0.3676936503307875,-0.18899986724969509
266.6000000000031,32.75994437967525,0.3672255728394377,-0.19102283473187542
267.7000000000031,32.86328671305077,0.3673956762431667,-0.19264941230988786
268.8000000000031,32.9700953832714,0.3665905068976278,-0.19691693766700435
269.9000000000031,33.07399706017829,0.3650805757500987,-0.2008085178606529
271.0000000000031,33.17869063714626,0.3638348448469747,-0.20453934538141683
272.10000000000315,33.28343121982449,0.3649709822062976,-0.20650256126921196
273.2000000000032,33.3891689902719,0.3646013058611607,-0.21045073189533836
274.30000000000314,33.49370222335613,0.364113233815361,-0.21438323944158633
275.40000000000316,33.597731217983515,0.36274661299885563,-0.21727445482318775
276.5000000000032,33.70229240526858,0.3624404096164199,-0.22121272045534113
277.6000000000032,33.80868241986515,0.3607789775863511,-0.2254110377445464
278.70000000000323,33.91317025319366,0.36018914277221703,-0.2284862026875807
279.80000000000325,34.017965216888555,0.3600177261921329,-0.23214890412386247
280.9000000000033,34.12336649325791,0.35882615107379356,-0.2347869054069749
282.0000000000033,34.22881929403897,0.35703834179819477,-0.23896558574033033
283.1000000000033,34.33324364072711,0.3585280658716069,-0.24265270706673103
284.20000000000334,34.43838508891799,0.3592700983086154,-0.24680068960966395
285.30000000000337,34.544132666503,0.3585721761346815,-0.2501721897214968
286.40000000000333,34.64797329991358,0.35945971396770965,-0.2540297343730167
287.50000000000335,34.752059442818194,0.35740829962220505,-0.2581422947992573
288.6000000000034,34.85858596236137,0.35725839367866496,-0.26388701450043905
289.7000000000034,34.96419454382477,0.35680213542628614,-0.26660623239171866
290.8000000000034,35.069267156323725,0.355976217350323,-0.2703976789989664
291.9000000000034,35.174443916691885,0.35405823523038416,-0.2746544202708412
293.0000000000034,35.2773843450891,0.35309473484621257,-0.2788355717678823
294.10000000000343,35.38471129853135,0.35154006817805994,-0.2834522434046387
295.20000000000346,35.4891690810079,0.3542022524523471,-0.28620028647051043
296.3000000000035,35.59311315550911,0.3520976244068523,-0.28992804295400143
297.4000000000035,35.698958401480375,0.3517828006095612,-0.2945776278173886
298.5000000000035,35.80565021065971,0.3491021646890387,-0.29879942021448036
299.60000000000355,35.90936904561719,0.34825297209999323,-0.3025577488881681
300.70000000000357,36.01469087101521,0.3476410072676172,-0.30768383775866903
301.8000000000036,36.12087462550573,0.34600811163986506,-0.31147627586142335
302.9000000000036,36.22532756080526,0.3465980625778528,-0.3185721992291053
304.0000000000036,36.330576199243275,0.3453192941326319,-0.3219189105739684
305.1000000000036,36.434838543946185,0.3442732132870768,-0.3248617932672362
306.2000000000036,36.54235723516321,0.34333132480530665,-0.3277175879538796
307.30000000000365,36.64628082950511,0.34058760835185115,-0.3334041601594566
308.4000000000037,36.75222350498783,0.34021594726139653,-0.3380837327545949
309.5000000000037,36.85679128659997,0.3374708374707518,-0.3422544109164676
310.60000000000366,36.96226895068904,0.3357850376472037,-0.34676886689714337
311.7000000000037,37.06926825521976,0.3350781584789297,-0.35153810447340295
312.8000000000037,37.17248586397104,0.33317232176790557,-0.3567511897578086
313.90000000000373,37.27857968403867,0.3314479718507576,-0.3625487899322275
315.00000000000375,37.38350029766375,0.32875411806462,-0.3672245061295758
316.1000000000038,37.48946400246584,0.3257726272037258,-0.3723709928730421
317.2000000000038,37.595232314651774,0.3255389644993712,-0.377176620335109
318.3000000000038,37.700759097505774,0.32235316087219046,-0.3828699974099923
319.40000000000384,37.806167035167306,0.32045942696440644,-0.3883250268318883
320.5000000000038,37.91238438903818,0.31942525300708463,-0.39336693811440826
321.60000000000383,38.017103339863695,0.31854278298608196,-0.39917980351687055
322.70000000000385,38.12295066182594,0.31522496595683713,-0.4037186909954591
323.8000000000039,38.22887684867072,0.31283483822065994,-0.4094597049448172
324.9000000000039,38.33391966131735,0.3090899797298269,-0.41512957326857824
326.0000000000039,38.44089042574182,0.30497045392883637,-0.4206188678085523
327.10000000000394,38.546727323969876,0.3019371511929088,-0.42615155095338464
328.2000000000039,38.65263932646257,0.29819767748928755,-0.43360715458388865
329.30000000000393,38.75871759663883,0.2961968257219,-0.4399710764347389
330.40000000000396,38.86371476369922,0.29392980698480026,-0.44361762199031407
331.500000000004,38.96981625855483,0.28929858959697735,-0.4499942334628302
332.600000000004,39.07559133932971,0.28771250345783794,-0.4579918293776326
333.700000000004,39.18176908620722,0.28575361805747895,-0.46561182878309637
334.80000000000405,39.28798579710322,0.280827923014912,-0.4727536609597651
335.90000000000407,39.393111476208226,0.280855492003951,-0.47867574755754116
337.0000000000041,39.49955705601515,0.2765463467739413,-0.4862452675044766
338.10000000000406,39.60527468953258,0.2727203858204223,-0.49387491386125326
339.2000000000041,39.71183029646196,0.271498926234642,-0.5021475198769751
340.3000000000041,39.817230750449774,0.26760802461228916,-0.5099410237008297
341.4000000000041,39.92292877781634,0.2629556730618845,-0.518246974641249
342.50000000000415,40.02883768064528,0.2596429170489456,-0.5279269012409271
343.6000000000042,40.134723421524434,0.25759228439888493,-0.5375297297355299
344.7000000000042,40.23953455484601,0.258367095541738,-0.5465399829792847
345.80000000000416,40.344986394783234,0.2557772820012364,-0.5550727138048774
346.9000000000042,40.452157039519264,0.2521750219124261,-0.5673146070048269
348.0000000000042,40.55791159687376,0.2494459181795079,-0.5773043483760394
349.10000000000423,40.664485410349975,0.24781016549472373,-0.5899229547267284
350.20000000000425,40.7706803182328,0.24815889304710143,-0.6007315564837241
351.3000000000043,40.876594537492494,0.24793594962025817,-0.613617280573084
352.4000000000043,40.98226089589707,0.2468590343340588,-0.625814370162149
353.5000000000043,41.08805728229388,0.24726268612573649,-0.6408679888053213
354.60000000000434,41.19414695155267,0.24699223506388068,-0.6537613930743014
355.7000000000043,41.3005671366963,0.24634588989107087,-0.668938473300325
356.80000000000433,41.40756390608991,0.24443911833570353,-0.6832199311350804
357.90000000000435,41.51361600406199,0.24514923751470957,-0.6984091672148383
359.0000000000044,41.61993934365813,0.24475909097162496,-0.7147145745968357
360.1000000000044,41.726739996485236,0.24523644248768312,-0.7329535329841526
361.2000000000044,41.83189250346371,0.24759666761608323,-0.7500073256276014
362.30000000000445,41.93815840877281,0.24691728210038877,-0.7680553714804161
363.4000000000044,42.044848899930855,0.2534513331763883,-0.7872172921922793
364.50000000000443,42.150629925246044,0.2545825191638853,-0.8064774931746461
365.60000000000446,42.25757424946165,0.25478648610390137,-0.8278877856603004
366.7000000000045,42.3647519087985,0.26003091670380696,-0.8502721427089326
367.8000000000045,42.47132549994416,0.2630333274815658,-0.8719420119019214
368.9000000000045,42.577155833380566,0.26671162926817515,-0.8923960891422897
370.00000000000455,42.68319207852708,0.27085614174804395,-0.9152661457212474
371.10000000000457,42.787415374511916,0.2753522339700182,-0.9396043411216941
372.2000000000046,42.89598983574297,0.2796156422565617,-0.9636151813349212
373.30000000000456,43.00184383773862,0.2833346907434344,-0.9891424405385112
374.4000000000046,43.1098510594862,0.28881111803286047,-1.013938058054805
375.5000000000046,43.21488054492538,0.2938917420379386,-1.039053361758639
376.6000000000046,43.3221062771038,0.29723055647213076,-1.0651357659831726
377.70000000000465,43.42936781282033,0.30161410705075825,-1.0880008998675508
378.8000000000047,43.53547482367683,0.3061905109390157,-1.111761776176651
379.9000000000047,43.64266113076292,0.3085220897796332,-1.1396532865479534
381.00000000000466,43.748585650270506,0.3108370783504051,-1.1635418292509776
382.1000000000047,43.85573163006314,0.3166018021917324,-1.1895597059803604
383.2000000000047,43.96174161730134,0.31988225498606027,-1.2158299718209769
384.30000000000473,44.068847197325056,0.3204566166104493,-1.2405801810370134
385.40000000000475,44.175541523459756,0.3264095167795516,-1.264179458543186
386.5000000000048,44.281572444380544,0.3273761685545448,-1.2887962287726697
387.6000000000048,44.38960685777202,0.3267121567873602,-1.3129818984953614
388.7000000000048,44.49601630399494,0.3325646355844743,-1.3367284382105988
389.80000000000484,44.602340879154575,0.33372067213659873,-1.3588414960966886
390.9000000000048,44.70980894846129,0.33691882121325306,-1.3817564694776419
392.00000000000483,44.81676729280261,0.33637829875255565,-1.4059921565188662
393.10000000000485,44.92312677509099,0.3367893807341189,-1.4279608993238124
394.2000000000049,45.030686393421604,0.3409617899433688,-1.4485751039095187
395.3000000000049,45.137155051353545,0.3389151613000731,-1.4695569937139452
396.4000000000049,45.24460557077676,0.34274189879626726,-1.4896568136392858
397.50000000000495,45.3513934262318,0.3441174569132531,-1.509398571381951
398.6000000000049,45.457942232856496,0.3450770747666815,-1.5281475109598133
399.70000000000493,45.565364741120156,0.3468740641725007,-1.5462902016367295
400.80000000000496,45.67232898891942,0.3474478951039698,-1.5682074167152766
401.900000000005,45.77834289794565,0.3494031551947316,-1.5863462057995918
403.000000000005,45.8857680761253,0.35145283785308573,-1.6032730640467703
404.100000000005,45.99098446005769,0.3524920608370129,-1.6222429910774845
405.20000000000505,46.10075111252999,0.3543200948724309,-1.6384046424891054
406.30000000000507,46.2079325003413,0.354470946810222,-1.6561846449450957
407.4000000000051,46.31551473751385,0.3542178360546862,-1.671177356243426
408.50000000000506,46.4218636888082,0.3552454069767491,-1.687563223738426
409.6000000000051,46.529381853028525,0.35392601331287105,-1.705173872872869
410.7000000000051,46.6359492436971,0.3557290299403385,-1.720033114875732
411.8000000000051,46.74278079770737,0.3570220504576175,-1.7372607143741332
412.90000000000515,46.85064613715628,0.3556099583342404,-1.751738816960386
414.0000000000052,46.95737528276862,0.35580433101028386,-1.765657926247925
415.1000000000052,47.065108900995824,0.35398829142637606,-1.7781895119873394
416.20000000000516,47.17273015816094,0.3546572339639893,-1.7949847587043197
417.3000000000052,47.278978030461325,0.353532861172615,-1.811061665486971
418.4000000000052,47.38667246481586,0.3520792545619482,-1.8255458657252093
419.50000000000523,47.494161039692585,0.3504854136026752,-1.8407792229068018
420.60000000000525,47.60007119373111,0.35387704755923965,-1.857215158752458
421.7000000000053,47.70782012247486,0.353467091276805,-1.871687295507535
422.8000000000053,47.81438628841809,0.3493503554451009,-1.885724414252043
423.9000000000053,47.92250469171407,0.35201445181054675,-1.89859302959151
425.00000000000534,48.03013985208709,0.3497336589212465,-1.911205845446791
426.1000000000053,48.136368021498924,0.3471722691350478,-1.9234401082753956
427.20000000000533,48.244732838844925,0.34615007475525783,-1.9370727370729037
428.30000000000535,48.34858489403546,0.3466594649429758,-1.950395060397101
429.4000000000054,48.458382483012485,0.339777450842242,-1.9662071606689233
430.5000000000054,48.56579844916485,0.33813593289956995,-1.9799429458187334
431.6000000000054,48.672724329434224,0.3370942052753371,-1.9928015543850819
432.70000000000545,48.78055200039386,0.3348470969550774,-2.005748686659978
433.8000000000054,48.888151280327385,0.3303685026213969,-2.0173751355294653
434.90000000000543,48.996643281420376,0.3296747970849287,-2.029033819889959
436.00000000000546,49.10360070266288,0.32416406780925977,-2.041297776493564
437.1000000000055,49.208859474151154,0.3216361593396737,-2.051489225177928
438.2000000000055,49.317391208684064,0.3175699836723318,-2.0637735836806357
439.3000000000055,49.426205647633516,0.31280658533783634,-2.075529880737941
440.40000000000555,49.53296734943513,0.308454961334895,-2.0867023633056405
441.50000000000557,49.64101430516364,0.3053394015400009,-2.098212010786737
442.6000000000056,49.74802988866272,0.3016414762291645,-2.1079565306526273
443.70000000000556,49.85525406800529,0.2963462638848294,-2.1174870790054054
444.8000000000056,49.96246080101675,0.29105904773082786,-2.1262212275014374
445.9000000000056,50.07023804684309,0.28826629583038293,-2.134207319076019
447.0000000000056,50.17757317161016,0.28689557360330875,-2.144797418682211
448.10000000000565,50.285147048273735,0.28522245178802946,-2.1551693794956037
449.2000000000057,50.392590361767034,0.2813853263548578,-2.165360869278344
450.3000000000057,50.49988242319638,0.2771479804010799,-2.1726817571851464
451.40000000000566,50.607292029250154,0.27229007811595934,-2.1793506889226926
452.5000000000057,50.71480154684422,0.26898038056718293,-2.1879430654156526
453.6000000000057,50.82312896978935,0.2650261509406009,-2.1954145040031445
454.70000000000573,50.92997735455774,0.26024599374203544,-2.20028499411532
455.80000000000575,51.03804140109784,0.25773746835546407,-2.206684304083002
456.9000000000058,51.14539241026808,0.25348230196576604,-2.2132301706814004
458.0000000000058,51.25387753400762,0.2512928851679547,-2.220582984541167
459.1000000000058,51.35880448236332,0.24631799475705118,-2.223631908153007
460.20000000000584,51.46834002648767,0.24379589868515833,-2.231371316347629
461.3000000000058,51.57649295417399,0.23821737393464504,-2.2372226751297437
462.40000000000583,51.68439966376882,0.2362639626849703,-2.242996900201544
463.50000000000585,51.790357086140084,0.23261222415780547,-2.248603976369736
464.6000000000059,51.90003009379905,0.23115135292375683,-2.2527356584389775
465.7000000000059,52.00878572784583,0.22606419490812724,-2.255696997457145
466.8000000000059,52.11562457079174,0.22382126214233472,-2.259920458093651
467.90000000000595,52.22393972539638,0.2230369666381143,-2.26414766808488
469.0000000000059,52.332168076013176,0.21863777746461066,-2.268551523016996
470.10000000000593,52.44052620339525,0.21683022007817632,-2.271537042442713
471.20000000000596,52.54676149932041,0.21323159810510423,-2.276291958932386
472.300000000006,52.65566221116193,0.21059522982208234,-2.2789893693797554
473.400000000006,52.763625378105225,0.20961963613756185,-2.2792197254573643
474.500000000006,52.87243659367229,0.20870276619823985,-2.283965044575301
475.60000000000605,52.97986923871036,0.20734825523949468,-2.2869525802911004
476.70000000000607,53.08840788031433,0.20229387951925232,-2.289960434371164
477.8000000000061,53.19647721717686,0.20134008508108303,-2.2912899314765385
478.90000000000606,53.30435549500717,0.19614162540058944,-2.292985631728332
480.0000000000061,53.411845018703204,0.19592496231793988,-2.295804267712647
481.1000000000061,53.52040129526378,0.19532444634755675,-2.2983149750046885
482.2000000000061,53.62860575540442,0.19298015578420868,-2.298592663417689
483.30000000000615,53.735037336934774,0.19152382598303253,-2.3005883175323856
484.4000000000062,53.8429692423554,0.18963070684887534,-2.301267978399916
485.5000000000062,53.95329276900712,0.1882166951102781,-2.3019251339299798
486.60000000000616,54.05926198735461,0.18788382039786183,-2.3050751671006084
487.7000000000062,54.16958012077043,0.18590421075290575,-2.30545446754941
488.8000000000062,54.27790392589007,0.1845818980086899,-2.306545557925053
489.90000000000623,54.38620240953956,0.18383332748894132,-2.307539456038901
491.00000000000625,54.493129112387926,0.18088843153553558,-2.3088846937467498
492.1000000000063,54.60189789122034,0.17944730227592814,-2.3111431208944495
493.2000000000063,54.7089676732386,0.1805946694226574,-2.310159964149414
494.3000000000063,54.81732938136098,0.17860379852766445,-2.311471825077974
495.40000000000634,54.926161547051265,0.1767005832200792,-2.31280003568415
496.5000000000063,55.034339548459734,0.1766830648810256,-2.312894869215085
497.60000000000633,55.143528070993625,0.17644970707931706,-2.31411975325225
498.70000000000636,55.25062817804946,0.17753749825999648,-2.316750093989568
499.8000000000064,55.358568848940415,0.173796970582624,-2.3167492879611027
500.9000000000064,55.466215590960694,0.17468062224736108,-2.3167507175480724
502.0000000000064,55.574937786813074,0.17412340041254343,-2.3167774919861372
503.10000000000645,55.68231425707839,0.17296534360567356,-2.3160651550343476
504.2000000000064,55.79108977227745,0.17504116401085917,-2.3167507137139447
505.30000000000643,55.89994251926881,0.17962113431302645,-2.317440790233529
506.40000000000646,56.00648738813766,0.18854784703015864,-2.3180698541090394
507.5000000000065,56.11523927984836,0.19131429098202085,-2.3180694343160604
508.6000000000065,56.2241240342118,0.19432912457615686,-2.319380055815661
509.7000000000065,56.33158342326785,0.19528608208046327,-2.319347735291851
510.80000000000655,56.44193589640073,0.19698661945997614,-2.3206984303280507
511.90000000000657,56.54906102738234,0.196556388941723,-2.322680111699755
513.0000000000066,56.657735982331104,0.1971830508750827,-2.322680107002302
514.1000000000065,56.76630629335888,0.19376898764971817,-2.322672761076033
515.2000000000066,56.87391402613436,0.19289093976241167,-2.32267994522892
516.3000000000065,56.98244276934698,0.1917238634533489,-2.3239623102139353
517.4000000000067,57.08925945934231,0.19020438938907314,-2.323990365054003
518.5000000000066,57.200259284711564,0.1863990602808897,-2.3253099066800487
519.6000000000067,57.30935848563186,0.18230836613325974,-2.3253093574563444
520.7000000000066,57.41535534852859,0.18120026419806773,-2.323999739640322
521.8000000000067,57.527686067291405,0.17716301378534682,-2.325310691711027
522.9000000000067,57.63559794816752,0.17471344896482144,-2.327948365051031
524.0000000000067,57.744527077499,0.17217257907741323,-2.326585801423322
525.1000000000067,57.852771085851444,0.16780419618568332,-2.3278976402363436
526.2000000000068,57.96164560511891,0.16296107112334723,-2.326639963480903
527.3000000000068,58.07072896362135,0.1580565779534444,-2.326639955965125
528.4000000000068,58.17799424217477,0.15692355372147604,-2.327946971977481
529.5000000000068,58.28669642149857,0.15255383160494485,-2.327950116002704
530.6000000000068,58.39769778288859,0.15041480305344468,-2.3279501031539827
531.7000000000069,58.5058044003346,0.15111984989153593,-2.3292731909932303
532.8000000000068,58.61624054846106,0.14655752380693476,-2.330260756451195
533.9000000000069,58.723693142467155,0.14606304318018237,-2.3302600940612397
535.0000000000068,58.833209289234325,0.14620220180270127,-2.328941168580572
536.100000000007,58.94258121279316,0.1446764810428287,-2.329270952225964
537.2000000000069,59.051086816024736,0.14487830020004322,-2.3305797581010856
538.300000000007,59.16035461889727,0.14649294548361497,-2.331899926921145
539.4000000000069,59.269168077012445,0.14337134451627415,-2.333880161630552
540.5000000000069,59.378350992358946,0.14264772643181312,-2.333892552875297
541.600000000007,59.486614195566595,0.1440067399719489,-2.3325875486122536
542.700000000007,59.596257173899005,0.1436748181850535,-2.3338966413324727
543.800000000007,59.704530906584345,0.14190962826430747,-2.3352680979867673
544.900000000007,59.81382193696357,0.13942355062499484,-2.3355280902116062
546.000000000007,59.92239534950365,0.13868361973122884,-2.3345459613993325
547.1000000000071,60.03142282650374,0.13747947649770664,-2.333220198643929
548.2000000000071,60.14046617278463,0.1358252501810538,-2.3332786424326715
549.300000000007,60.24907254566243,0.13532333820298292,-2.334529949849917
550.4000000000071,60.3580753954158,0.13566574525411962,-2.3355415946334386
551.500000000007,60.46490748279535,0.13531280114785088,-2.3368401218114743
552.6000000000072,60.57534259987163,0.1361054049258995,-2.336952607526552
553.7000000000071,60.68419499082376,0.1349742415252212,-2.336843004455367
554.8000000000072,60.79402233796793,0.13486067899424503,-2.3369002713162192
555.9000000000071,60.90319219744446,0.13340360885544766,-2.3381619476924502
557.0000000000072,61.0106594846471,0.13079914442878116,-2.337820496675702
558.1000000000072,61.12189042388349,0.13086026172118104,-2.338159821330092
559.2000000000072,61.23090365027476,0.13154824211295335,-2.3394725223316213
560.3000000000072,61.33986350691945,0.12901603071558998,-2.338159962301639
561.4000000000073,61.449732066361584,0.12789256132921156,-2.339460721499754
562.5000000000073,61.55897617900674,0.12629168404072721,-2.3391498031430653
563.6000000000073,61.66800524003981,0.12696403297490677,-2.3391500529246625
564.7000000000073,61.77633720067237,0.12623357717211936,-2.3394794834504475
565.8000000000073,61.88624604515681,0.12310044995755698,-2.34080367074605
566.9000000000074,61.99618910944646,0.1236368811696108,-2.339479983364546
568.0000000000074,62.1049075302072,0.1260280712361349,-2.3421183602912854
569.1000000000074,62.21444074835099,0.12524195875579747,-2.34342918305218
570.2000000000073,62.3241311627861,0.12378814245049086,-2.3421111415558107
571.3000000000073,62.43283892097036,0.1227410817225203,-2.3428450210789276
572.4000000000074,62.5425713854376,0.12459180851201235,-2.3434298371894897
573.5000000000074,62.65162870616799,0.12517826066757842,-2.34343031389946
574.6000000000074,62.76117393980621,0.12368451968410588,-2.344741859514073
575.7000000000074,62.87043710283073,0.12504514188320448,-2.343760066323932
576.8000000000075,62.97840571884153,0.12304016333930723,-2.344689181389512
577.9000000000075,63.089269039191635,0.11962114753867525,-2.3447220117584493
579.0000000000075,63.19806433258415,0.12006199716004118,-2.3459997359277422
580.1000000000075,63.30746304375296,0.12325771904416138,-2.346060047147862
581.2000000000075,63.41645277201687,0.12329414344211365,-2.347372413573839
582.3000000000076,63.52676556533387,0.12355993275394428,-2.347379869339643
583.4000000000076,63.63562443030918,0.12846974139726863,-2.348683572982336
584.5000000000076,63.74479408079111,0.130943934369684,-2.348544294256775
585.6000000000076,63.85467590762521,0.13077580639348763,-2.348699908265033
586.7000000000077,63.963708256720025,0.1313086183696811,-2.349969050642261
587.8000000000077,64.07191609851935,0.13677987819997828,-2.3499852360265914
588.9000000000076,64.1827764715503,0.13561701777895108,-2.3520077894310925
590.0000000000076,64.2921184619217,0.13773382300240788,-2.3513302299546552
591.1000000000076,64.40098359645812,0.14233512140806204,-2.351352378992621
592.2000000000077,64.51116673479864,0.1464731289866138,-2.3523200697193243
593.3000000000077,64.61897760955628,0.1518500330696393,-2.352646134594254
594.4000000000077,64.72840504943642,0.157071833502047,-2.3539703679420336
595.5000000000077,64.8366762024015,0.16096882371692717,-2.354950095303214
596.6000000000078,64.94689611664415,0.16837421590351365,-2.353972166298388
597.7000000000078,65.05660818305383,0.17080777385917767,-2.354753493255208
598.8000000000078,65.16524339554589,0.17654934972323744,-2.3556193895081767
599.9000000000078,65.27521957547172,0.1826469263352402,-2.356940192020936
601.0000000000078,65.38467799370076,0.1832023365227426,-2.3582484779993407
602.1000000000079,65.49291507682958,0.1873911065650964,-2.357919362992753
603.2000000000079,65.60386290217218,0.19099604443077367,-2.3592518759980114
604.3000000000079,65.71221200467674,0.1956913211029136,-2.359239596885216
605.4000000000078,65.82259106335157,0.19685986529958321,-2.3618833927018392
606.5000000000078,65.93152637651914,0.20216691495327255,-2.3623232165735057
607.6000000000079,66.04134686686683,0.20623338524607043,-2.361867834851753
608.7000000000079,66.15028156813652,0.21349239155287392,-2.3631901661410177
609.8000000000079,66.25999580025888,0.21600165914101216,-2.3641795377750774
610.9000000000079,66.37008382709689,0.21999545260689224,-2.3645088818226965
612.000000000008,66.47908257310218,0.2245068637367682,-2.3658134957198094
613.100000000008,66.58936981557392,0.2276789383684482,-2.368460194138337
614.200000000008,66.69746375877422,0.23222965345880858,-2.368214252572421
615.300000000008,66.80861471195419,0.2370090573617561,-2.3687459771346955
616.400000000008,66.9191679916773,0.23864035691850194,-2.3697798477221834
617.5000000000081,67.0289729061378,0.2422120888549536,-2.3710797239036845
618.6000000000081,67.13846948352206,0.24821461564956898,-2.3727458169019884
619.7000000000081,67.24772976047774,0.2537007147686285,-2.37405397566254
620.8000000000081,67.35839117474308,0.25966735051081336,-2.375367872474988
621.9000000000082,67.4676032325983,0.2662297132589281,-2.37540514198207
623.0000000000082,67.57714457370022,0.2674308910688337,-2.3766575131610086
624.1000000000081,67.68740822214292,0.2728765734787918,-2.380664689723825
625.2000000000081,67.7980871953366,0.2780361602809087,-2.380651029296561
626.3000000000081,67.90677868658567,0.2842340440363388,-2.3826216214292657
627.4000000000082,68.01641437690797,0.2899959940721204,-2.3839352220505905
628.5000000000082,68.12720257208979,0.29699488914629485,-2.383958594472997
629.6000000000082,68.23477601350687,0.3026998100439609,-2.3855541665258526
630.7000000000082,68.34595173191707,0.30842423116017664,-2.387906012006072
631.8000000000083,68.45494343583763,0.3164554404829922,-2.3891970063767287
632.9000000000083,68.56481085131225,0.3285831829611843,-2.3918862466284665
634.0000000000083,68.67476053678772,0.3337844601862123,-2.3935763116576103
635.1000000000083,68.7848132805889,0.34238627560805224,-2.3959096430004037
636.2000000000083,68.89262171881364,0.3502772235515951,-2.3958908730088275
637.3000000000084,69.00401606891032,0.3584075361288224,-2.3985384918195063
638.4000000000084,69.11271051142225,0.36796281504034195,-2.401174728310348
639.5000000000084,69.2225130764587,0.37912747147528353,-2.403485060651806
640.6000000000083,69.33218226973315,0.3886477444146204,-2.4064219165930103
641.7000000000083,69.44168130682216,0.40003529500858875,-2.4077576119509176
642.8000000000084,69.55215861637227,0.4099566314160603,-2.41053171302259
643.9000000000084,69.66130651886087,0.41452644772830166,-2.412058608364191
645.0000000000084,69.7712957588712,0.42794063296684814,-2.413385679966411
646.1000000000084,69.88084781548689,0.4335221426688621,-2.4159718365973752
647.2000000000085,69.99028349989075,0.44244873680975394,-2.418671833973023
648.3000000000085,70.10038531154049,0.45197105529831194,-2.4212632500864157
649.4000000000085,70.21062809261296,0.45449900212464334,-2.423890808922464
650.5000000000085,70.3198389860093,0.4602064300763652,-2.42691618855045
651.6000000000085,70.42896025437288,0.4653537954339828,-2.4301364380571417
652.7000000000086,70.53879676184188,0.46383829363712165,-2.433343482297035
653.8000000000086,70.64835929712703,0.4626014026342814,-2.4359719143606156
654.9000000000086,70.75866180747731,0.46078912531639593,-2.4378379175369527
656.0000000000086,70.86801375604463,0.4529005605151293,-2.441269622924454
657.1000000000087,70.97857549935458,0.44488752078733096,-2.443493372759667
658.2000000000087,71.08789231932322,0.4377824455797035,-2.4470856410050867
659.3000000000086,71.19780675780228,0.431097542567651,-2.4481619841241318
660.4000000000086,71.30698142848861,0.43011559753185424,-2.4507984876319986
661.5000000000086,71.41660491011453,0.4384974457123561,-2.4533494671441645
662.6000000000087,71.5270444124526,0.45147190842475404,-2.4564519371660705
663.7000000000087,71.63684502077423,0.4663761575207584,-2.4586148032516877
664.8000000000087,71.74740865807209,0.48371928646838425,-2.461448574313901
665.9000000000087,71.85661820145162,0.49823372045830105,-2.4649393451239767
667.0000000000088,71.96723969161927,0.5124680038079954,-2.4681685233013644
668.1000000000088,72.07707995235423,0.5189184859696891,-2.470792041148418
669.2000000000088,72.18546671516503,0.5183518004097039,-2.473988544385829
670.3000000000088,72.29712423713437,0.5125637822965124,-2.4765851870195372
671.4000000000088,72.40577323844546,0.5003275352590933,-2.4779245599787503
672.5000000000089,72.51492858500922,0.48385102582455564,-2.480817276708967
673.6000000000089,72.6244485294805,0.45630524326583083,-2.484137427441203
674.7000000000089,72.73644371990964,0.422010615354887,-2.4876087048183244
675.8000000000088,72.84613238436492,0.3882453948581325,-2.491193191245667
676.9000000000088,72.95575437186862,0.3500711812583844,-2.4938446909500778
678.0000000000089,73.06612466559942,0.31385752605643474,-2.4950059142335084
679.1000000000089,73.17588542314074,0.27984996812941704,-2.495150173017294
680.2000000000089,73.28557544612595,0.2450099087182328,-2.4978103564213736
681.3000000000089,73.39555990680752,0.21903776724304086,-2.5005711776966857
682.400000000009,73.50476187436709,0.19501482554530736,-2.500498759066444
683.500000000009,73.61522250617843,0.1758567805839395,-2.5031135978660544
684.600000000009,73.72660210554942,0.15941234264214243,-2.501849958209348
685.700000000009,73.83683585045179,0.14799437448022434,-2.502680369970816
686.800000000009,73.94705554228058,0.13971556620741055,-2.501839930288521
687.9000000000091,74.0568558970684,0.13288476212125255,-2.503200498588403
689.0000000000091,74.16725171841,0.12645851563837796,-2.5031604270673102
690.1000000000091,74.27828263824414,0.11850276878082577,-2.504479968330229
691.2000000000091,74.38774993310753,0.11830532624057233,-2.504479346795915
692.3000000000092,74.49751182750833,0.11204016621741908,-2.5031779625412818
693.4000000000092,74.60883499481442,0.11058226285697526,-2.5031609907869075
694.5000000000091,74.71848648596833,0.10697901387932018,-2.5031601370138707
695.6000000000091,74.82937175766128,0.10494046772625865,-2.503125898291686
696.7000000000091,74.93916896980915,0.10464553069540616,-2.505788307815796
697.8000000000092,75.05024850550475,0.1018216211175097,-2.5044799627061636
698.9000000000092,75.15916805650825,0.10175897555508084,-2.505469967013406
700.0000000000092,75.26988624571881,0.10125014900758655,-2.506458611608464
701.1000000000092,75.3797903497872,0.09774658082319077,-2.508129283142147
702.2000000000093,75.49081655752946,0.09566777964610895,-2.508100421856777
703.3000000000093,75.60110515234163,0.09353207919575379,-2.5071136662178675
704.4000000000093,75.71065564477968,0.09687240237206485,-2.507766602125053
705.5000000000093,75.82099446078975,0.09540616263098456,-2.508429993613304
706.6000000000093,75.93146845901134,0.09379578136331379,-2.5098368819539663
707.7000000000094,76.04263492220541,0.08736740824376188,-2.5078856355387433
708.8000000000094,76.15279604840478,0.08881811097109438,-2.5090897320728844
709.9000000000094,76.26326646246686,0.08734924700190805,-2.508429931587561
711.0000000000093,76.3717296466608,0.0872408934753266,-2.509750038177196
712.1000000000093,76.48401603166339,0.08903033555276363,-2.5105743986021007
713.2000000000094,76.59292009367279,0.08938699352733348,-2.5110601847838643
714.3000000000094,76.70378914468488,0.09089223695164772,-2.510081249699239
715.4000000000094,76.81387933911049,0.08861384421160745,-2.510171262818157
716.5000000000094,76.92188791455649,0.08774072370534014,-2.511103385297277
717.6000000000095,77.03424651695757,0.08699662494143745,-2.512375059219004
718.7000000000095,77.14455430256024,0.08801145633505869,-2.5110698493758523
719.8000000000095,77.25403219290469,0.08655692883972876,-2.5110696665255836
720.9000000000095,77.36463873657628,0.08875082102007725,-2.512390105627055
722.0000000000095,77.4751334042111,0.08831937158477077,-2.5123901852353656
723.1000000000096,77.5846544190697,0.09024656890544636,-2.5135436738184715
724.2000000000096,77.69466319405552,0.09016963286759905,-2.5123678884739773
725.3000000000096,77.80542616137461,0.09198868671900273,-2.5123801427531576
726.4000000000096,77.91596763590141,0.08928327136312886,-2.513745856531504
727.5000000000097,78.02546455750456,0.08528437351137619,-2.5150199070285337
728.6000000000097,78.1357360378116,0.08847863396943001,-2.514447438675007
729.7000000000096,78.24568796308934,0.08868786672541307,-2.514062842816342
730.8000000000096,78.3563922686451,0.08670825677062555,-2.5156067842932233
731.9000000000096,78.46721477254724,0.08823034693167275,-2.516329849946831
733.0000000000097,78.57831136449175,0.0851093974103746,-2.5150205922183053
734.1000000000097,78.68879717417262,0.08445567069474391,-2.5163400874039628
735.2000000000097,78.7993500783876,0.0870921034206037,-2.516336475497596
736.3000000000097,78.90804888407366,0.07998891740245562,-2.518319554196014
737.4000000000098,79.01963196748457,0.08056598210940746,-2.5183199090104926
738.5000000000098,79.13097999620884,0.08154029042072297,-2.5183530799907263
739.6000000000098,79.24098911810565,0.08111925378965379,-2.5184517955660284
740.7000000000098,79.35192443493862,0.07956953349419105,-2.519629827585336
741.8000000000098,79.46162561314979,0.0810957852587475,-2.5183099975216385
742.9000000000099,79.57279264689363,0.07850272847119799,-2.519629947287655
744.0000000000099,79.68313555670906,0.07635414328828083,-2.5196297982832885
745.1000000000099,79.79305611478414,0.07265274231331287,-2.5209499744696586
746.2000000000098,79.90308963797372,0.07251051732692193,-2.5209499459823888
747.0000000000099,79.9831576316528,0.07427762673704486,-2.5200066607903615