File: 01_Data/Polyester_Carpet_Medium_Pile/STA/N2/30K_min/Polyester_Carpet_Medium_Pile_STA_N2_30KData_211217_R2.csv
##Temp./Â°C,Time/min,DSC/(mW/mg),Mass loss/mg
49.0,10.517351301720788,0.04827759811680399,-0.014037917977882675
50.100000000000016,10.713242059891256,0.09360990569289085,-0.017625347211462028
51.20000000000003,10.840240378410229,0.14109790153848267,-0.015811912327571065
52.30000000000005,10.936777889423354,0.17890384432561535,-0.016826069855906844
53.40000000000006,11.020044119592049,0.2124148413667672,-0.018877711079956505
54.50000000000008,11.093381317447443,0.2430758994703004,-0.019251097719287458
55.600000000000094,11.161975181074146,0.27344654955609604,-0.018150608545172364
56.70000000000011,11.22413682936085,0.29787017595163456,-0.01723384781918158
57.800000000000125,11.283553778667105,0.3230392498821164,-0.017570920523334532
58.90000000000014,11.339117809839435,0.34597881962570887,-0.018887449773155485
60.000000000000156,11.393454960242211,0.36580003538890615,-0.018173110795895564
61.10000000000017,11.445031182785568,0.38496496730280827,-0.018019099627371915
62.20000000000019,11.495472546162835,0.40514262107387033,-0.017011454451222097
63.3000000000002,11.543773502386326,0.4222816559113304,-0.01813782767617944
64.40000000000022,11.591286486448364,0.4384239155517488,-0.01755130359379775
65.50000000000023,11.637983671655533,0.45420585139998537,-0.017769422609602348
66.60000000000025,11.683575354532868,0.4725747472090657,-0.018156104714387222
67.70000000000027,11.728213509989452,0.4880154427836297,-0.018569840765188417
68.80000000000028,11.772453536703788,0.5022982845136961,-0.017676924270641603
69.90000000000029,11.8153526260856,0.5134841007887753,-0.01839739311800548
71.00000000000031,11.858104017331748,0.528679821776132,-0.018419581777670224
72.10000000000034,11.900747110007302,0.5420737679158509,-0.01939462747837295
73.20000000000034,11.943189959255351,0.5503816941600661,-0.018599368827237228
74.30000000000035,11.984464058474536,0.5595168690487237,-0.016838533359289087
75.40000000000038,12.02567412186326,0.5628095933272017,-0.018262315512306948
76.5000000000004,12.067056733811638,0.5688666367242987,-0.016675271672813352
77.6000000000004,12.107337029557504,0.5713720869002032,-0.015970763656508957
78.70000000000041,12.147552579063674,0.5745215688699483,-0.01812730189103373
79.80000000000044,12.187726956921995,0.5754111313611805,-0.01736707178474184
80.90000000000046,12.227693001402702,0.573356054205133,-0.016030775704916067
82.00000000000047,12.267372341219641,0.5750989210457234,-0.0181276797169998
83.10000000000048,12.30671029412572,0.5776006244660983,-0.018063354444011637
84.2000000000005,12.345864007809988,0.5795500751814653,-0.01924372253372386
85.30000000000052,12.385157890433636,0.5812096069124899,-0.020381180339269278
86.40000000000053,12.423491834736632,0.5832029857569011,-0.01980534174942372
87.50000000000054,12.462138780885233,0.5847752612751171,-0.020045005965125817
88.60000000000056,12.500680039619652,0.5863097702959137,-0.020384432693155485
89.70000000000059,12.538822783952426,0.5882238072944497,-0.021021247839621005
90.8000000000006,12.576137644582452,0.5904720775395604,-0.01992101766042431
91.9000000000006,12.61528242536225,0.5932156049285783,-0.01991415198240487
93.00000000000063,12.652815420917218,0.59761629318592,-0.019891299018161224
94.10000000000065,12.690796572077836,0.5983379389523146,-0.019939875111614214
95.20000000000066,12.728649722970905,0.600168006090964,-0.019931540016068006
96.30000000000067,12.766287277195536,0.6012510495693342,-0.01996434087328547
97.40000000000069,12.803230462438542,0.6074928148459235,-0.021421365312340068
98.50000000000071,12.84096035944031,0.6091841853684989,-0.021404975788040126
99.60000000000072,12.878019702950601,0.6117828564700872,-0.022922892802035744
100.70000000000073,12.915811507339107,0.618198443804301,-0.022763945297283872
101.80000000000075,12.953046054002101,0.6217548169493824,-0.022817796541810598
102.90000000000077,12.990182586196173,0.6277416242094934,-0.021417988071075644
104.00000000000078,13.027417076716358,0.6294067296777955,-0.022845620715027604
105.10000000000079,13.064532305570232,0.6338702414792967,-0.021508300581237982
106.20000000000081,13.101445549454223,0.6384382856289598,-0.02201685658574437
107.30000000000084,13.13923616313381,0.6432292020843233,-0.021498863488352615
108.40000000000084,13.175570041828205,0.6484762633199482,-0.02151190305755213
109.50000000000085,13.212707396659573,0.6527163952888895,-0.02281328597874621
110.60000000000088,13.249650117959117,0.6574092641403956,-0.02280794013226295
111.7000000000009,13.286621186531123,0.6617822968471976,-0.023388399406837124
112.8000000000009,13.323528508000706,0.6670937253790838,-0.022816030063255166
113.90000000000092,13.359994614985785,0.6726160891086185,-0.02177028024378158
115.00000000000094,13.397350321224717,0.6751274083303583,-0.02157092149968376
116.10000000000096,13.433729497885984,0.6806289380909555,-0.022804864275337344
117.20000000000097,13.470921264685865,0.6848989619840523,-0.021449172175784792
118.30000000000098,13.50737880433191,0.6886401169671643,-0.02149993556590024
119.400000000001,13.543672272837254,0.6929350663632744,-0.021510250763634442
120.50000000000102,13.580322184030052,0.6980395770090193,-0.021499879413942935
121.60000000000103,13.616897777433199,0.7033741473817405,-0.02149960368469417
122.70000000000104,13.65348865462506,0.7070179866195194,-0.022862672630715064
123.80000000000106,13.690270922673323,0.7114523870754113,-0.022770531917069015
124.90000000000109,13.726354376528656,0.7160029805593553,-0.021506905893910577
126.0000000000011,13.762528783057398,0.7202705849417937,-0.02150000496808513
127.1000000000011,13.798879287550855,0.7248744975164836,-0.02150072727493102
128.20000000000113,13.834892529288712,0.7297811947217479,-0.02141872319546856
129.30000000000115,13.87099136273524,0.7340728026513054,-0.022536326772345294
130.40000000000117,13.907091803341315,0.7374662170168693,-0.021848144703953132
131.50000000000117,13.942998704611357,0.7405365823388881,-0.021829657484904175
132.6000000000012,13.97864420000475,0.7444136167721016,-0.021829993238109413
133.7000000000012,14.014918014323031,0.7485974105623384,-0.021831747346341857
134.8000000000012,14.050452077242461,0.7526413820251624,-0.02211795030753727
135.90000000000123,14.085949136005508,0.7557347002348261,-0.02313975763326015
137.00000000000125,14.121581763043611,0.7607309922250081,-0.02314166131870321
138.10000000000127,14.15750664860101,0.764064036077494,-0.0231614575952781
139.2000000000013,14.193110419992081,0.7689856388276644,-0.024480779913222506
140.3000000000013,14.228625023477914,0.7720302435466267,-0.024869732354492413
141.4000000000013,14.263674944129132,0.7815499103942056,-0.025121188858736154
142.50000000000134,14.299104753112456,0.7856972641147584,-0.025158983762170184
143.60000000000133,14.334899703921726,0.7916094630568655,-0.02379587906201097
144.70000000000135,14.369904983118357,0.7984754422667857,-0.023799870478989682
145.80000000000138,14.40495492361272,0.802460265869256,-0.023859715387971825
146.9000000000014,14.440504305883458,0.8079049258959689,-0.02248583311106289
148.00000000000142,14.475666794099054,0.8158879475352624,-0.022950390436404344
149.10000000000142,14.510784890883082,0.8215638825768443,-0.023803513040715707
150.20000000000144,14.545429458641815,0.8298471858362628,-0.023800114350087664
151.30000000000146,14.580864967616307,0.8373259432450453,-0.02380014664575958
152.40000000000146,14.615606108408354,0.8479211943323632,-0.02380014686231835
153.50000000000148,14.650402883128052,0.8596278645099282,-0.02380013776334744
154.6000000000015,14.685505121552845,0.8717874129856351,-0.023801690423582933
155.70000000000152,14.720373612415742,0.886431900978512,-0.023448570702393923
156.80000000000155,14.755325241998694,0.9008208318949189,-0.023784689132964942
157.90000000000154,14.79041085584519,0.9156606664876777,-0.023799759279032884
159.00000000000156,14.82489575837872,0.9326624371856791,-0.023799832605674087
160.1000000000016,14.859505559829188,0.947031751640004,-0.023799831005050898
161.20000000000158,14.894375211112104,0.9636595058822051,-0.02379983100325722
162.3000000000016,14.928875375858244,0.9806612813398291,-0.023799830971064306
163.40000000000163,14.96389027395292,0.9938095459772027,-0.023799800481799416
164.50000000000165,14.998626280037877,1.0007754407663312,-0.023800358487325646
165.60000000000167,15.033093550677897,1.0014261555172386,-0.025202502702962093
166.70000000000167,15.068127939914032,0.9943733724110125,-0.025110061248861726
167.8000000000017,15.102596559801448,0.9826824963356537,-0.025193575747902486
168.9000000000017,15.137102825648448,0.9669001869195725,-0.02576767667086699
170.0000000000017,15.170741548897377,0.9510854086120422,-0.025771510493409977
171.10000000000173,15.206195765122885,0.9378229065196715,-0.02440006952511542
172.20000000000175,15.240613910402583,0.9241235539178092,-0.02445949840383932
173.30000000000177,15.275161298578036,0.9136652017355573,-0.024461018963536585
174.4000000000018,15.30935821072554,0.9091046695442813,-0.02411581999516832
175.5000000000018,15.343742299661482,0.9019078291506681,-0.023475031417848236
176.6000000000018,15.378262687200674,0.8971920980061334,-0.02348741982235003
177.70000000000184,15.412487919126308,0.8960472619614979,-0.02484321457171257
178.80000000000183,15.44679775302319,0.8951031031614054,-0.024789262186904804
179.90000000000185,15.48119763793749,0.8932245247877504,-0.024789827649411844
181.00000000000188,15.515063300149345,0.8946930850215096,-0.024789831085909153
182.1000000000019,15.549137932988842,0.8940647345345589,-0.02478983099980514
183.20000000000192,15.583372248082782,0.8956573958027403,-0.024789831006369667
184.30000000000192,15.617341602547304,0.8980950174298492,-0.024789830681723135
185.40000000000194,15.651549258160427,0.900540270886531,-0.024789794189059133
186.50000000000196,15.685372924104287,0.9037364752911967,-0.024794152505311917
187.60000000000196,15.719076682385268,0.9053233239836741,-0.025766784532005982
188.70000000000198,15.75318260261526,0.9065209274370712,-0.025768966255955927
189.800000000002,15.787065000408276,0.9107221268836045,-0.025770183235346966
190.90000000000202,15.821132269940279,0.9155041269274303,-0.025770174093296294
192.00000000000205,15.855073313520197,0.916898956644843,-0.025770173998183044
193.10000000000204,15.888533437729382,0.922692557092244,-0.025770174000005586
194.20000000000206,15.922496500966147,0.9246057427793406,-0.025770174000000257
195.3000000000021,15.956615167247422,0.9310435481110484,-0.025770174000000257
196.40000000000208,15.990030807654417,0.9311944367937549,-0.025770173999997592
197.5000000000021,16.02391089182524,0.9325055890209312,-0.025770174000868895
198.60000000000213,16.057782788292112,0.9390627851198374,-0.025770173967274435
199.70000000000215,16.091397453723342,0.9411106010551956,-0.025770169784834263
200.80000000000217,16.125192068295288,0.9450555227750593,-0.025770657943266162
201.90000000000217,16.158901727959247,0.9493040001233014,-0.02547185677608299
203.0000000000022,16.192549445041873,0.9514371204128028,-0.024453319574117227
204.1000000000022,16.22621275558398,0.9551606114826084,-0.024459932917789917
205.2000000000022,16.260207317315277,0.9602140526768341,-0.024459855005007025
206.30000000000223,16.293638287757467,0.9623365785976251,-0.024460667248162427
207.40000000000225,16.327490474302458,0.967542611261642,-0.024425011491995274
208.50000000000227,16.36067907427521,0.9739150278934137,-0.025761600871084145
209.6000000000023,16.394334386327152,0.9763728578005603,-0.02577040721164714
210.7000000000023,16.427632655000625,0.9811083860445734,-0.025770172512266765
211.8000000000023,16.46138110812921,0.9871455192866705,-0.025770174169730264
212.90000000000234,16.49512914270388,0.9903323428816302,-0.025770151502125582
214.00000000000233,16.528615654336576,0.9950966107731564,-0.02577055174546805
215.10000000000235,16.562479955418787,1.0009136501436164,-0.025940990287807164
216.20000000000238,16.595715238083265,1.0074863924956494,-0.026757392729362728
217.3000000000024,16.629355703951557,1.0125166165182282,-0.026760090870126874
218.40000000000242,16.662631654294564,1.0201617252005746,-0.026760093371497096
219.50000000000242,16.696402063041607,1.028339896653578,-0.026760093068136204
220.60000000000244,16.729757820681872,1.0358926029447177,-0.026760093342509617
221.70000000000246,16.762400732273615,1.0457001963650923,-0.02675952418912564
222.80000000000246,16.796719102461147,1.0553135247687435,-0.026921643657782823
223.90000000000248,16.830330440046723,1.0611363262978042,-0.028080010312221404
225.0000000000025,16.86378270198602,1.0716756233763887,-0.026853486809280902
226.10000000000252,16.897010587859643,1.0830136984740997,-0.026758087848434364
227.20000000000255,16.930678319516407,1.0942047763319802,-0.026676956559172904
228.30000000000254,16.963983345285538,1.103938002198912,-0.02545138839882588
229.40000000000256,16.99723409989596,1.1178131714577526,-0.025450073027813325
230.5000000000026,17.030455157383003,1.1337022360438203,-0.025449445741282606
231.60000000000258,17.064241986327545,1.1499641360166821,-0.025575005775615
232.7000000000026,17.09760325865661,1.1659220500249037,-0.02606004926987726
233.80000000000263,17.13095525072819,1.1822643076131476,-0.026105204862815423
234.90000000000265,17.164534038615695,1.204434318678548,-0.026825653889051004
236.00000000000267,17.19787909552916,1.2300812437406126,-0.02799223782137039
237.10000000000267,17.23135478096612,1.2622240767188322,-0.028071085966208553
238.2000000000027,17.264618176537923,1.300173614570784,-0.026894507158414793
239.3000000000027,17.29804759253952,1.3463245513554079,-0.0254393354791298
240.4000000000027,17.33137998440633,1.4079481121801414,-0.025449831408098866
241.50000000000273,17.36474534137291,1.4833528981345045,-0.025449805016688032
242.60000000000275,17.398378394888077,1.5701083335437056,-0.025455763964325584
243.70000000000277,17.431750906608265,1.676658245080462,-0.026816039701093697
244.8000000000028,17.46516346410757,1.7892835937965266,-0.02677134146660043
245.9000000000028,17.49901828633541,1.9036599361711881,-0.02799179444464439
247.0000000000028,17.532372245888595,1.9901056453289891,-0.02807834234812745
248.10000000000284,17.565717358379704,2.02593483533686,-0.028079989311388776
249.20000000000283,17.599355510319885,2.0054040789441427,-0.028079957579379755
250.30000000000285,17.63285790461004,1.9271125915694807,-0.02807992795726566
251.40000000000288,17.666391721899007,1.816530185316953,-0.028083469657592453
252.5000000000029,17.699855541416653,1.7025674173192975,-0.027514795744280285
253.60000000000292,17.733206752544223,1.6011233836949086,-0.027508600452629928
254.70000000000292,17.766299995648765,1.508673400185774,-0.028083814994507517
255.80000000000294,17.799663325323174,1.432451067008056,-0.028079884184390558
256.90000000000293,17.833114895722595,1.3642965664629194,-0.028079872167194875
258.00000000000296,17.866048399007838,1.3075192801017508,-0.028080015884185627
259.100000000003,17.899412342386995,1.2616514541623505,-0.028080933992841395
260.200000000003,17.932491549545944,1.2237509714104107,-0.029375550890867963
261.300000000003,17.96559193191844,1.1916477882392285,-0.02939431762095346
262.40000000000305,17.99907927092793,1.165496385959539,-0.030217872918341104
263.50000000000307,18.032214711733516,1.1456653444755078,-0.030710606331335377
264.6000000000031,18.065723192677773,1.1294241657702013,-0.030710153772249615
265.7000000000031,18.09841639305627,1.1159490786988353,-0.03071016608668309
266.8000000000031,18.131686327145292,1.1041712032854225,-0.03071016664580606
267.9000000000031,18.16520981135066,1.0936894825098835,-0.030710070738241058
269.0000000000031,18.19837570324996,1.0879683772733622,-0.030714579841896406
270.10000000000315,18.231427238424,1.0822650364429613,-0.029993979699826312
271.2000000000032,18.264606656332134,1.0814591857024383,-0.03005144762329426
272.30000000000314,18.29782810761844,1.0761223677715965,-0.030050156935338634
273.40000000000316,18.331264898963905,1.0762111935412038,-0.030050165905470827
274.5000000000032,18.36434180914016,1.0734689988654171,-0.030050166000267442
275.6000000000032,18.397244495039175,1.0710224744318428,-0.030050166104289566
276.70000000000323,18.430804179017994,1.070123054806079,-0.03005017381209596
277.80000000000325,18.464099733691903,1.0705638953956438,-0.030048991951437287
278.9000000000033,18.49748375955257,1.0666447114221176,-0.030102015704073004
280.0000000000033,18.530385166528866,1.0699096820145413,-0.029387188362336225
281.1000000000033,18.56376058760284,1.0693122735559144,-0.029389900408588687
282.20000000000334,18.5969541286638,1.0680019532639515,-0.02939012125978424
283.30000000000337,18.630446629854696,1.0690533010781629,-0.029407993850085745
284.40000000000333,18.663688188921956,1.0699357028093304,-0.02875718527374893
285.50000000000335,18.69726573383524,1.0670762366955016,-0.028740413060182934
286.6000000000034,18.7299520396313,1.0665229618036198,-0.028768060603179713
287.7000000000034,18.763319310677222,1.0689903790272097,-0.030123438538367964
288.8000000000034,18.79697971670236,1.0713862517512307,-0.02873759156776945
289.9000000000034,18.830136433416833,1.0698531962594016,-0.03012897971705586
291.0000000000034,18.863603688150377,1.069659591363331,-0.031116136581375464
292.10000000000343,18.896741702446224,1.0716162335694013,-0.029806733336836366
293.20000000000346,18.93028395202332,1.0716607353454497,-0.029801301798613622
294.3000000000035,18.963473139106263,1.0707387830596644,-0.031157603380827403
295.4000000000035,18.996926347228555,1.072846029015688,-0.031131747621540917
296.5000000000035,19.030204044227965,1.0731599886330332,-0.02984085370650913
297.60000000000355,19.06351634076662,1.0730936318629158,-0.03048251399732882
298.70000000000357,19.09674027143276,1.0757660995287586,-0.030490076006025824
299.8000000000036,19.130451827435778,1.0766923893520486,-0.030494992174237012
300.9000000000036,19.16391253581779,1.0753424406580285,-0.03168383045917755
302.0000000000036,19.196715795544375,1.0792289209109536,-0.03246909214107996
303.1000000000036,19.230744006341517,1.079570292930598,-0.032573662062563624
304.2000000000036,19.263925884525495,1.0809135389642135,-0.03439444957511073
305.30000000000365,19.297218474073897,1.0812338968385866,-0.0354996935752232
306.4000000000037,19.33087453879446,1.0823729036917613,-0.03510725444167484
307.5000000000037,19.36398093524215,1.0831438696725424,-0.03526840364368811
308.60000000000366,19.397316019770976,1.0853772017971304,-0.03389905534936455
309.7000000000037,19.430792813950468,1.0847353812536482,-0.03524802625698342
310.8000000000037,19.464281169185327,1.0836321442439503,-0.035114775719901736
311.90000000000373,19.497728676134788,1.0866730800103686,-0.036530406658017434
313.00000000000375,19.531029466973813,1.0861453685086153,-0.03653008612493025
314.1000000000038,19.56449217422129,1.0880370031551114,-0.036527963858407286
315.2000000000038,19.597812222972948,1.0883213600555666,-0.035190819557481046
316.3000000000038,19.6313810951057,1.0896665769497138,-0.0352118612241088
317.40000000000384,19.664865166662086,1.089016095947178,-0.03521015661697868
318.5000000000038,19.698451053321502,1.090037414913637,-0.035206991218417194
319.60000000000383,19.73201418949032,1.0904096173045394,-0.0364961038967242
320.70000000000385,19.765251743309427,1.0921587970764628,-0.03652029910185162
321.8000000000039,19.798895558151266,1.0949676635651469,-0.03651993207620885
322.9000000000039,19.832206721418707,1.0920514739552227,-0.03652079540869746
324.0000000000039,19.86556656241289,1.095475443296069,-0.03649852565553058
325.10000000000394,19.899233183470233,1.094208506107038,-0.037828458953133026
326.2000000000039,19.932593748925925,1.0931579982990438,-0.038522314581201034
327.30000000000393,19.96615126379768,1.0958370621128568,-0.03915786953309075
328.40000000000396,19.999769386603557,1.097210501663364,-0.04019785058466496
329.500000000004,20.033425674803947,1.094276500888437,-0.04050198230819113
330.600000000004,20.067112734770696,1.0957640879301795,-0.04177863276886695
331.700000000004,20.10079256673382,1.093588400686766,-0.041790184415400944
332.80000000000405,20.134542138939715,1.0932412835837666,-0.041774259237345124
333.90000000000407,20.16783064452722,1.0956912896153344,-0.041782664978007755
335.0000000000041,20.201461976293167,1.096662811878315,-0.04234868015624338
336.10000000000406,20.235201062889445,1.093989333156601,-0.04303424417711632
337.2000000000041,20.26889437211107,1.0955154036271855,-0.0444285780492466
338.3000000000041,20.302498518990223,1.0936190844807747,-0.04442985230420948
339.4000000000041,20.336436396609866,1.090470502368496,-0.0444296076247217
340.50000000000415,20.3700508819964,1.090137620643122,-0.04442214935986799
341.6000000000042,20.403414939472764,1.0928068019128294,-0.045789107412608665
342.7000000000042,20.43751867787376,1.0907217673009715,-0.04572248724610173
343.80000000000416,20.47108020277617,1.0916211590222658,-0.045781030940663214
344.9000000000042,20.504838659642967,1.0902650832390566,-0.045739171346976804
346.0000000000042,20.538610849833383,1.0918722780694334,-0.045740082434737594
347.10000000000423,20.572528972961234,1.08989879883301,-0.045774969636582785
348.20000000000425,20.606314072459362,1.0898079526223774,-0.04703581028473458
349.3000000000043,20.63988325873966,1.0903812278456126,-0.047043854963364495
350.4000000000043,20.673473218451644,1.091468902291903,-0.04842534606724991
351.5000000000043,20.70653594367496,1.0872750480566105,-0.0483708220625636
352.60000000000434,20.741034664104962,1.0889892005037467,-0.04975843573703553
353.7000000000043,20.775020873573958,1.0904449261607287,-0.050231108067348096
354.80000000000433,20.808706056895208,1.0933571096374324,-0.0514028596338596
355.90000000000435,20.842553061508134,1.0953673622543036,-0.05366361005403242
357.0000000000044,20.876531667698725,1.095756691284811,-0.05463264143890312
358.1000000000044,20.910197904939665,1.097557347414941,-0.05596527345988189
359.2000000000044,20.944283331744792,1.0994996409726112,-0.05593873109339498
360.30000000000445,20.978009504317384,1.102291325529761,-0.05618257563940965
361.4000000000044,21.011904360920912,1.0984372842409984,-0.057273580356145715
362.50000000000443,21.04577016042392,1.0997670702533138,-0.058414024724348756
363.60000000000446,21.079638338215688,1.1002874919677819,-0.05894808378428351
364.7000000000045,21.113606482419467,1.1018662381098696,-0.06033580421646123
365.8000000000045,21.147585146596253,1.1001617854457713,-0.061730323346737226
366.9000000000045,21.181325609387635,1.1031859237738109,-0.06305145031233472
368.00000000000455,21.215554970081694,1.1024804620870132,-0.06481322593977357
369.10000000000457,21.249108606639396,1.1032841603421033,-0.06721969988415832
370.2000000000046,21.283193464274966,1.1058608872045153,-0.0697185015601085
371.30000000000456,21.31720398305182,1.1085796491556763,-0.07113954683172041
372.4000000000046,21.351243011490027,1.11120083070979,-0.07217227942127291
373.5000000000046,21.385181676830538,1.1107660788890956,-0.07424772262572565
374.6000000000046,21.419388379103015,1.1127400724065357,-0.07602153165244152
375.70000000000465,21.453322931221184,1.1152701174086823,-0.07773044356475589
376.8000000000047,21.48715533875361,1.118835551772016,-0.08035575796675865
377.9000000000047,21.521363735419364,1.1230632075765683,-0.08278001839173044
379.00000000000466,21.555174835967378,1.1233607272980262,-0.0845608362784529
380.1000000000047,21.588551862471878,1.1273936140820648,-0.08702907227437517
381.2000000000047,21.623410771749622,1.133970369958243,-0.08862609298568058
382.30000000000473,21.657453882088035,1.135122917961594,-0.0897796413902987
383.40000000000475,21.691723013874494,1.1405637313768822,-0.09285620347583468
384.5000000000048,21.725808755023838,1.1408115518914037,-0.09652671043708017
385.6000000000048,21.75972297547087,1.148699273482878,-0.10051816726503127
386.7000000000048,21.7939871974976,1.1521262803366996,-0.10368402498025109
387.80000000000484,21.82828106828169,1.1593199861605936,-0.10591410418531444
388.9000000000048,21.862221056441395,1.1659624106023652,-0.11029757626763281
390.00000000000483,21.89641724686297,1.1732003220163532,-0.11493645274314357
391.10000000000485,21.930468631374076,1.1817459673595203,-0.11879196515359514
392.2000000000049,21.96457385408487,1.1884287412719319,-0.12186466042976374
393.3000000000049,21.999107344055723,1.1972948777351806,-0.12557884233930583
394.4000000000049,22.033182747201785,1.206841875571055,-0.1308066280228548
395.50000000000495,22.06766614960712,1.2128651302982523,-0.1358775781390591
396.6000000000049,22.101619227068532,1.2229873106676379,-0.1408866215108331
397.70000000000493,22.135760146869767,1.2292954449780593,-0.1466031674853845
398.80000000000496,22.17001920656272,1.240068539004939,-0.15202104555688578
399.900000000005,22.204306735427075,1.2493988025288134,-0.1568492019121175
401.000000000005,22.23877107773844,1.2579894643062246,-0.16237763065205968
402.100000000005,22.272827683186605,1.2647702093171667,-0.16913954465463066
403.20000000000505,22.307146021064447,1.275632979403902,-0.17659462003400517
404.30000000000507,22.341592825101483,1.2814030269844825,-0.18219117092872406
405.4000000000051,22.37570058378585,1.2913440064184618,-0.18887138432990547
406.50000000000506,22.40985199832357,1.298062611647815,-0.19725587402322686
407.6000000000051,22.44475014765876,1.3073480321395907,-0.20341767062488048
408.7000000000051,22.478744161247466,1.316661098175884,-0.21014015468922675
409.8000000000051,22.513139524593683,1.3216532812626907,-0.21825418420588294
410.90000000000515,22.547326256931115,1.3302269440891032,-0.2279844840118046
412.0000000000052,22.58198829641367,1.3409677950679648,-0.2367399251945721
413.1000000000052,22.616430374403382,1.349799371807473,-0.24656886700341074
414.20000000000516,22.650919092677515,1.3568998497418956,-0.2582876525099418
415.3000000000052,22.68508929630041,1.366094070882891,-0.26715459217793347
416.4000000000052,22.719734430097436,1.3759143655428032,-0.27683294679797665
417.50000000000523,22.75402958378261,1.3852338142242588,-0.28720733711892743
418.60000000000525,22.78762177358321,1.3987322304060823,-0.2976465636775534
419.7000000000053,22.8230520099407,1.406936393959406,-0.3098999542738521
420.8000000000053,22.85743076031597,1.4199189169327966,-0.3228866211251078
421.9000000000053,22.89167841072925,1.4281569607831295,-0.33542218528687284
423.00000000000534,22.92637469279709,1.4407676959837246,-0.34899528784779843
424.1000000000053,22.961004684456206,1.45685804731428,-0.36343291884274587
425.20000000000533,22.99551497238063,1.4689141953819227,-0.3774140949937421
426.30000000000535,23.02923458452343,1.4847592258143494,-0.3920370297439244
427.4000000000054,23.06429752520345,1.4962956679686612,-0.4072199476574436
428.5000000000054,23.09897919678272,1.51510946567703,-0.4226617072264518
429.6000000000054,23.133377297525893,1.5325102937109991,-0.4387284048321498
430.70000000000545,23.168080736127006,1.5453383160682574,-0.4568013134999145
431.8000000000054,23.202641141263243,1.5625027433519703,-0.47402350714702157
432.90000000000543,23.237358921236385,1.579957807376336,-0.4915999050385915
434.00000000000546,23.271730990067905,1.5964089837466569,-0.5107685562691264
435.1000000000055,23.306389581632025,1.6095052691219105,-0.5314337475258792
436.2000000000055,23.34126074221289,1.6273215301030828,-0.5519423027438992
437.3000000000055,23.375602395923767,1.6418808383274426,-0.5717846364411052
438.40000000000555,23.41042689317947,1.6514958790640162,-0.59508192572823
439.50000000000557,23.44502168801392,1.6646972300294989,-0.6170142904305931
440.6000000000056,23.479744398712576,1.6752102168215144,-0.6393998082653325
441.70000000000556,23.514110959355712,1.6842422273050248,-0.6634439727659776
442.8000000000056,23.549138641224907,1.6936697364990239,-0.6892469376244925
443.9000000000056,23.583755137647575,1.7040442755353054,-0.7159751728875787
445.0000000000056,23.6182723844319,1.7144023565745976,-0.7431903167016576
446.10000000000565,23.653034274833246,1.7258853114192934,-0.7717434352511043
447.2000000000057,23.687821192769693,1.7401853552882447,-0.7999771237740836
448.3000000000057,23.72242468008923,1.7543527112281152,-0.8280059898527172
449.40000000000566,23.757301054043104,1.7656734889325674,-0.8578169887061744
450.5000000000057,23.792251384150664,1.7775525049488878,-0.888674288475225
451.6000000000057,23.827378778314284,1.791781894094659,-0.9210210014174613
452.70000000000573,23.861865311792638,1.8090624909704078,-0.9547721513250296
453.80000000000575,23.89642454261701,1.8226706801843664,-0.9892436403601068
454.9000000000058,23.930805246508946,1.8384559403740008,-1.0236024978715692
456.0000000000058,23.966116590668996,1.8474031159082653,-1.0591754628563872
457.1000000000058,24.00105588014679,1.8579646471020304,-1.093468912855478
458.20000000000584,24.03574139394353,1.8649373022441724,-1.1290990608296982
459.3000000000058,24.070659398725105,1.8676452989393126,-1.1672635378646392
460.40000000000583,24.105573035193608,1.8700551044319025,-1.2059467621696558
461.50000000000585,24.140543916728944,1.8685910858984631,-1.2445646196196285
462.6000000000059,24.175667337357318,1.8587897004141825,-1.2844333760806395
463.7000000000059,24.20956410000755,1.8482368634867237,-1.3246562332627718
464.8000000000059,24.244855808723557,1.8322086849066495,-1.3633456772105426
465.90000000000595,24.28021335519948,1.8098391361093296,-1.4000457700548798
467.0000000000059,24.31499001120509,1.7849761107097197,-1.4377931005260214
468.10000000000593,24.349946455994044,1.7574614805993718,-1.475299704130546
469.20000000000596,24.38499379203681,1.7244329611509384,-1.510654104955011
470.300000000006,24.419802798246163,1.6877090659491476,-1.5458388691047045
471.400000000006,24.45476770658645,1.6460208119523512,-1.5781534107687833
472.500000000006,24.48945577250548,1.60594130584193,-1.607349382814371
473.60000000000605,24.524695304624302,1.55524744383951,-1.6336020739732522
474.70000000000607,24.559577169748504,1.5049132949529394,-1.6563428046095292
475.8000000000061,24.59447121345365,1.4517051209675562,-1.6765204910568268
476.90000000000606,24.6294310481046,1.3964659731557874,-1.6945610331324108
478.0000000000061,24.664613006962963,1.3417404447358348,-1.712763008044655
479.1000000000061,24.69910875734826,1.2891145682245304,-1.728934294154044
480.2000000000061,24.73433931136721,1.2397039615413008,-1.7422968854114291
481.30000000000615,24.76926609728284,1.1894148742018948,-1.7565594595834
482.4000000000062,24.804210882727496,1.1506501226817147,-1.7693643749323615
483.5000000000062,24.838844182480873,1.1150421965338846,-1.7809761922296343
484.60000000000616,24.874084356404698,1.084221847558969,-1.791417663935936
485.7000000000062,24.908818071603996,1.0593717003971725,-1.8025821183404167
486.8000000000062,24.94347364181081,1.0388997130547117,-1.8124979349877508
487.90000000000623,24.978974345249746,1.02194120870312,-1.823260843477411
489.00000000000625,25.01419632395158,1.0086847283775933,-1.8338210158091965
490.1000000000063,25.04907448587797,0.9955328461178987,-1.8455368934254697
491.2000000000063,25.084260130205877,0.9867628309053169,-1.8560884083721163
492.3000000000063,25.11926710805169,0.9761526124177602,-1.866558291538119
493.40000000000634,25.154559131739664,0.9683972965993304,-1.8774931036676028
494.5000000000063,25.18920246840686,0.954847620074105,-1.8880381549122731
495.60000000000633,25.22460724471378,0.9440944554336563,-1.8989275844572688
496.70000000000636,25.259811883123156,0.9332621912312251,-1.9093421849163121
497.8000000000064,25.294644886323248,0.9157431805669631,-1.9196824529317618
498.9000000000064,25.33030772370293,0.8906493287817137,-1.929040230251243
500.0000000000064,25.36479499650959,0.8586181058977114,-1.9366664427165445
501.10000000000645,25.39964852115713,0.8104703963507729,-1.9433719773699707
502.2000000000064,25.43543260531595,0.7582592107111485,-1.949405673262052
503.30000000000643,25.47055061398073,0.7017922070531202,-1.9562109386255901
504.40000000000646,25.505732821896732,0.6452650127694304,-1.9605395147809332
505.5000000000065,25.540819262945952,0.5978223838291796,-1.9640988613098158
506.6000000000065,25.57630643087646,0.5529874669039789,-1.966169350748089
507.7000000000065,25.611497600479165,0.5179850772622803,-1.968100460250608
508.80000000000655,25.646474858913837,0.4864762070709612,-1.9713482220349725
509.90000000000657,25.681747363107338,0.4653129055185514,-1.97227931320259
511.0000000000066,25.71705282695685,0.4480530390303188,-1.974456894786524
512.1000000000065,25.75229167695177,0.4330043640267942,-1.976741285098241
513.2000000000066,25.78759532117137,0.4217762878986653,-1.978209740641001
514.3000000000065,25.822890924882188,0.4151754439422024,-1.9795754338380078
515.4000000000067,25.85808848626258,0.40744834473099023,-1.9819451522716327
516.5000000000066,25.893442043439258,0.4027028213846755,-1.9836680727277356
517.6000000000067,25.928720993814835,0.3978969322949728,-1.9835598337874019
518.7000000000066,25.964245693492607,0.3971070118833566,-1.9835708015296625
519.8000000000067,25.999473056531286,0.39424921476936947,-1.9852244745540006
520.9000000000067,26.034688756656532,0.3955189111863171,-1.9867645238163316
522.0000000000067,26.07005371975451,0.39556477180717353,-1.9883400019803399
523.1000000000067,26.105789482224854,0.3947988241908389,-1.9903328894880548
524.2000000000068,26.141132614683396,0.3916492174651227,-1.9911274852141212
525.3000000000068,26.176696413696863,0.39370966683555264,-1.9925472166492255
526.4000000000068,26.212185254066977,0.3956018925587381,-1.9911584769321795
527.5000000000068,26.247457610450954,0.396705904669324,-1.992426556004261
528.6000000000068,26.283097519981478,0.3999141050349959,-1.9936593710229922
529.7000000000069,26.3185422067464,0.40119857215515653,-1.9946888885069032
530.8000000000068,26.353661877303374,0.39984783744898844,-1.995243583146089
531.9000000000069,26.38929995294415,0.4028848097887985,-1.9965003226376665
533.0000000000068,26.42484751509598,0.4056083660956067,-1.9965763878406253
534.100000000007,26.460350996755242,0.408656062650923,-1.9979759895860372
535.2000000000069,26.49584227412301,0.4129252076949781,-1.9992231194229877
536.300000000007,26.53121533439901,0.416692424912513,-2.000379492319698
537.4000000000069,26.567199363657167,0.42356759243350206,-2.001988534035232
538.5000000000069,26.60242325009582,0.4261305318871027,-2.003675341677342
539.600000000007,26.637703942713355,0.4323229422695043,-2.0051918369368016
540.700000000007,26.673254778431023,0.43497667273495666,-2.0070213804476547
541.800000000007,26.708998284379494,0.4381810945012119,-2.008015057198013
542.900000000007,26.744304595020544,0.4417127933080789,-2.0093240414699194
544.000000000007,26.77999967833144,0.4457768619913811,-2.010068338846292
545.1000000000071,26.815551168925847,0.45191300183847183,-2.010557986393656
546.2000000000071,26.851075302740817,0.4540477665001126,-2.0119719978598303
547.300000000007,26.88654623565933,0.4549167485491923,-2.0134950417433113
548.4000000000071,26.922509488887826,0.4633022504187485,-2.014917013240793
549.500000000007,26.957856190462454,0.46286770565887947,-2.0156798989206295
550.6000000000072,26.993376534100193,0.46617495851238466,-2.0171143750249403
551.7000000000071,27.029037770851577,0.46858298740545323,-2.017772517482438
552.8000000000072,27.06470093059515,0.4701881601460405,-2.0192608355854875
553.9000000000071,27.100534743817356,0.4738227332202323,-2.0208468531810815
555.0000000000072,27.13614476409414,0.4726278320037056,-2.022087873175911
556.1000000000072,27.172060734073618,0.47606552138995695,-2.0230220180258485
557.2000000000072,27.20752024800065,0.4781308913715643,-2.02304986530764
558.3000000000072,27.243055621666063,0.47870730397917516,-2.023025963996621
559.4000000000073,27.27842758296393,0.4794265883512694,-2.0233564183170953
560.5000000000073,27.314452723544616,0.48207131610228937,-2.0245842574955066
561.6000000000073,27.35030879456819,0.48175389549684833,-2.0261203836291033
562.7000000000073,27.385970358378966,0.484088712872647,-2.0272874475499973
563.8000000000073,27.42181330648089,0.4849608465692312,-2.028750288456083
564.9000000000074,27.457503943470993,0.4835501517815779,-2.0304271954548887
566.0000000000074,27.493177242014312,0.4874590389266511,-2.0320175673908007
567.1000000000074,27.528978623282413,0.48811414942735776,-2.033249056182377
568.2000000000073,27.56494619890238,0.48853565625759576,-2.0331442590502276
569.3000000000073,27.60077102160336,0.4912530989357371,-2.0352856174241034
570.4000000000074,27.636142395189736,0.4901675710203217,-2.037700995574277
571.5000000000074,27.671877917055504,0.4934802726042,-2.0393701288210915
572.6000000000074,27.707990386913195,0.49432923953886454,-2.0409936079998974
573.7000000000074,27.743691171758414,0.49668055160578506,-2.043860318831272
574.8000000000075,27.779428752609693,0.4965847195669484,-2.0465402253397778
575.9000000000075,27.815330135749445,0.4971647599434017,-2.0495667252995267
577.0000000000075,27.851228268066706,0.500332225304706,-2.049970329068276
578.1000000000075,27.887027785646332,0.4997367504347585,-2.052336294791249
579.2000000000075,27.923083426727683,0.5014521380120638,-2.054523656976838
580.3000000000076,27.95917033148694,0.5021235805498823,-2.056503083269406
581.4000000000076,27.994992509507746,0.5027854174782209,-2.0573924505814656
582.5000000000076,28.03101799638257,0.5027589111018995,-2.059237369219
583.6000000000076,28.06696666599354,0.5067022623315793,-2.060092723821819
584.7000000000077,28.102994357256552,0.5072959361101488,-2.06246872165924
585.8000000000077,28.13894039483561,0.5094541730590876,-2.065184406156302
586.9000000000076,28.174894759072128,0.5099201896566279,-2.0666007996077003
588.0000000000076,28.211045624446196,0.5170466469349959,-2.0686166493316693
589.1000000000076,28.246785829333614,0.5201641367105261,-2.071730891058153
590.2000000000077,28.28312128611266,0.5200841286406923,-2.0742396513405312
591.3000000000077,28.31831233043736,0.5242646003515352,-2.077197715775401
592.4000000000077,28.35520460704374,0.5285365869278635,-2.0794063322950427
593.5000000000077,28.391262766966797,0.5350723898121434,-2.082326600198162
594.6000000000078,28.427408635117732,0.5368342730060918,-2.085454312661613
595.7000000000078,28.463433204648585,0.5451352061063497,-2.0877935255780202
596.8000000000078,28.499331558831965,0.5480251470726663,-2.0912859574313414
597.9000000000078,28.535663360027492,0.5497279584665682,-2.0946373766726554
599.0000000000078,28.571576179764104,0.5549558548000109,-2.0974059443346067
600.1000000000079,28.607610694795525,0.5642928581039424,-2.1010505690813455
601.2000000000079,28.643854674941526,0.5671683847120492,-2.1049280878666057
602.3000000000079,28.680010226215686,0.5750039892752075,-2.108779803356669
603.4000000000078,28.716302444816236,0.5881835738030539,-2.113034761955169
604.5000000000078,28.752123316767264,0.5926856195583947,-2.116555764477675
605.6000000000079,28.788443469198878,0.6023049312090669,-2.1190264126066243
606.7000000000079,28.824553447612164,0.6135557784355277,-2.1215569216798835
607.8000000000079,28.860617197496193,0.6202208025455138,-2.125906030969081
608.9000000000079,28.897076168632474,0.6250790067547478,-2.12998490300936
610.000000000008,28.932880145694124,0.633277846894285,-2.1346423619067147
611.100000000008,28.969445436782603,0.6319869322958613,-2.138182806878349
612.200000000008,29.00546990173057,0.6305937759928741,-2.144303706567749
613.300000000008,29.041373170805432,0.6335862645482921,-2.151395879242414
614.400000000008,29.07801115383873,0.6328388677654586,-2.158718815853035
615.5000000000081,29.113998237466095,0.6255983116781085,-2.1635980616289334
616.6000000000081,29.150221977208822,0.6257073096286854,-2.1713637286276137
617.7000000000081,29.186439171656822,0.6228310797037848,-2.178563835796708
618.8000000000081,29.22243979512815,0.6173768878756569,-2.184714353772355
619.9000000000082,29.25870546009654,0.6137294017971999,-2.1919944833158658
621.0000000000082,29.294909966229714,0.6135579979183177,-2.19807011722712
622.1000000000081,29.331185634961866,0.6117196064748758,-2.20561181837383
623.2000000000081,29.367350042098046,0.605204656484891,-2.2127072493723503
624.3000000000081,29.40359149467069,0.6057357268824433,-2.22023941929736
625.4000000000082,29.439813817662067,0.6003171901532143,-2.22727672045775
626.5000000000082,29.476156710247533,0.5945686477527783,-2.2352521450480003
627.6000000000082,29.511475757302716,0.5884339848301672,-2.2433280600930665
628.7000000000082,29.54752028645177,0.5823865997335962,-2.254857224380391
629.8000000000083,29.584542355847905,0.5752213882274007,-2.263907738764436
630.9000000000083,29.621058238232443,0.5682958140069336,-2.2720779700649523
632.0000000000083,29.657332744282883,0.5587237174974016,-2.2786587526624102
633.1000000000083,29.693455652514768,0.5490971484046492,-2.284917554822958
634.2000000000083,29.729952888590255,0.5410775556041556,-2.2905420673438255
635.3000000000084,29.76595359509178,0.5270708987303063,-2.295988536312597
636.4000000000084,29.80214375419703,0.5235468044125668,-2.2988292200358487
637.5000000000084,29.838601228789866,0.5182882475422079,-2.3032303590118355
638.6000000000083,29.874589364686575,0.5174541359357394,-2.306626048487569
639.7000000000083,29.910958683470376,0.5160671768438017,-2.309619847422827
640.8000000000084,29.947479176451544,0.5107798932091758,-2.311501748205629
641.9000000000084,29.983565216492824,0.5028460074236978,-2.3129644722100253
643.0000000000084,30.02003236324541,0.504020230920335,-2.3156090979358583
644.1000000000084,30.056302187933795,0.5027028234219517,-2.3178941683636674
645.2000000000085,30.092244709887925,0.5145613576187322,-2.3199942324100467
646.3000000000085,30.12852467646891,0.5322494019344712,-2.3224623167919316
647.4000000000085,30.16509495359106,0.5535102323953285,-2.324435850474976
648.5000000000085,30.201192206232903,0.569697118814203,-2.3265366837938073
649.6000000000085,30.237477913066556,0.5855977259715828,-2.326861739658174
650.7000000000086,30.273875205021575,0.6039900442343513,-2.3279623914989376
651.8000000000086,30.310254233868747,0.6207965445873336,-2.328718709886547
652.9000000000086,30.346531239828877,0.637466423007869,-2.3306572065793696
654.0000000000086,30.382905999671845,0.6542139489382459,-2.3321318180558013
655.1000000000087,30.419497358987844,0.6687826576568283,-2.3338091917281867
656.2000000000087,30.455722807962307,0.6834143047374566,-2.3353272931961944
657.3000000000086,30.492461136319935,0.6964901268508452,-2.3369766534940175
658.4000000000086,30.528475349678597,0.7143474421454346,-2.338402464556413
659.5000000000086,30.56474525038642,0.7263449198336138,-2.339896567666548
660.6000000000087,30.601473773897343,0.7440264125121057,-2.340375648168138
661.7000000000087,30.637942155678765,0.7608083565549455,-2.341351070140333
662.8000000000087,30.67416798165881,0.7751765398409947,-2.3433874579800453
663.9000000000087,30.710503699300784,0.7906539366845431,-2.346416241672596
665.0000000000088,30.746689975214483,0.8135930316788493,-2.3496657439110082
666.1000000000088,30.783131855330566,0.8343678054391863,-2.3528493729418436
667.2000000000088,30.819633839696543,0.8536381272592162,-2.356100942912831
668.3000000000088,30.855854768274213,0.8678216174072526,-2.3577122010075744
669.4000000000088,30.892431245518846,0.8916391950686768,-2.3591844066548573
670.5000000000089,30.928737316100886,0.909999890843801,-2.360781444232848
671.6000000000089,30.965289340307223,0.9339722555933467,-2.362254350810647
672.7000000000089,31.001648206563612,0.9601596359657423,-2.3644353612458655
673.8000000000088,31.0383176888946,0.9820034091415026,-2.3675823122530355
674.9000000000088,31.074613288093005,1.0089946294671326,-2.370709825000437
676.0000000000089,31.111074008854658,1.0400531975051863,-2.3741338546489383
677.1000000000089,31.14767534295429,1.0674893570938662,-2.377089742627237
678.2000000000089,31.183804682541496,1.0986231091538046,-2.378543538590593
679.3000000000089,31.220463629210506,1.1317154926797022,-2.380192915172696
680.400000000009,31.2570210519173,1.1614844304584921,-2.3827925999634685
681.500000000009,31.29364229131225,1.20082661559396,-2.3854193747324155
682.600000000009,31.33026680311629,1.2405006839955455,-2.389292514012042
683.700000000009,31.36662693814301,1.2793271238727595,-2.390840227639379
684.800000000009,31.402955539457018,1.323374766362428,-2.393514744051167
685.9000000000091,31.439636068304925,1.3649229580954585,-2.397050861820351
687.0000000000091,31.476254937939547,1.411242136115289,-2.399743403958068
688.1000000000091,31.512625394951083,1.4546193509292453,-2.4037233654849466
689.2000000000091,31.549237404394432,1.502796590941054,-2.4078382519049883
690.3000000000092,31.585852121612433,1.550065243512114,-2.4118249497084223
691.4000000000092,31.62238241908484,1.6030534079289023,-2.4147912399816875
692.5000000000091,31.65880539728265,1.6542018814089343,-2.4188767062490335
693.6000000000091,31.69549364933893,1.706602880254425,-2.4231342926068864
694.7000000000091,31.732003211190552,1.7604455914755408,-2.427629801815353
695.8000000000092,31.76883651172756,1.813721233870802,-2.431268144725176
696.9000000000092,31.805365096118916,1.8686320225003445,-2.4354082533693147
698.0000000000092,31.84178807883508,1.9264119006611362,-2.4400773179105686
699.1000000000092,31.87857663574487,1.9866906624570522,-2.4453944825916327
700.2000000000093,31.914392202348328,2.0413672737861766,-2.4509327405396677
701.3000000000093,31.952087724242734,2.103915684016744,-2.455695253320492
702.4000000000093,31.988437272372554,2.1573661508888864,-2.4601140450900107
703.5000000000093,32.02517136007727,2.219308277315358,-2.4664538785466767
704.6000000000093,32.06194285753099,2.2830018272654544,-2.4728292129550344
705.7000000000094,32.098361884963055,2.3440889128519102,-2.477733188338846
706.8000000000094,32.135256040081416,2.408484205460754,-2.4830607798953928
707.9000000000094,32.17182043695065,2.472884449953861,-2.489925022576898
709.0000000000093,32.20858472784047,2.537407061349782,-2.4963274852847257
710.1000000000093,32.245185578927604,2.6013012141587875,-2.502768013199045
711.2000000000094,32.28098970309561,2.6663679123215736,-2.5084918401399197
712.3000000000094,32.31864566763785,2.737077613019858,-2.5155519021823523
713.4000000000094,32.355057264823756,2.800416261960635,-2.5214314601564274
714.5000000000094,32.391823701462684,2.869119197543649,-2.530227896893707
715.6000000000095,32.42869972883274,2.9390620802899843,-2.538229863908943
716.7000000000095,32.465065134894935,3.0072116762265595,-2.546155923752341
717.8000000000095,32.50203499620795,3.0769655185847777,-2.5543656045740475
718.9000000000095,32.53847495970874,3.1438195731205854,-2.560783369701406
720.0000000000095,32.575450414324955,3.215900647885362,-2.5678252175143013
721.1000000000096,32.61190784728484,3.2900256534828487,-2.5767030306659677
722.2000000000096,32.648738614785046,3.3585349463436236,-2.5844539020232196
723.3000000000096,32.68529954608942,3.4265828127268168,-2.590012173482801
724.4000000000096,32.72208949419621,3.499859575069589,-2.598531159684037
725.5000000000097,32.75903825239032,3.570697618853217,-2.607567632793371
726.6000000000097,32.795816681544295,3.641314678912497,-2.616823310565503
727.7000000000096,32.8322483407031,3.7138193230425727,-2.6255050454615216
728.8000000000096,32.869202837788634,3.7848210417976054,-2.6346676835077045
729.9000000000096,32.90602259958063,3.8555106126276826,-2.6434595307578688
731.0000000000097,32.94272679722596,3.9254997966394685,-2.6518957472786586
732.1000000000097,32.97950879729634,3.9939542512917487,-2.661265552997758
733.2000000000097,33.01605291430202,4.0560325148639285,-2.6710995316828288
734.3000000000097,33.053007889313776,4.118011164354173,-2.6816395706867264
735.4000000000098,33.08963560645007,4.174627535111295,-2.6904913764674454
736.5000000000098,33.12619040455942,4.227529092377734,-2.699808667787574
737.6000000000098,33.16272440399034,4.272095406599668,-2.7109311171075996
738.7000000000098,33.19993968464488,4.3093779978897855,-2.722094626698743
739.8000000000098,33.236453241474315,4.336340219762517,-2.731356604409134
740.9000000000099,33.27331785415151,4.343499559535504,-2.7396894389764372
742.0000000000099,33.31003245084062,4.335497233699339,-2.7500620354093765