File: 01_Data/Polyester_Carpet_Medium_Pile/STA/N2/30K_min/Polyester_Carpet_Medium_Pile_STA_N2_30KData_220104_R3.csv
##Temp./Â°C,Time/min,DSC/(mW/mg),Mass loss/mg
49.0,10.485455148311788,0.022704064925532008,0.010902705826783432
50.100000000000016,10.700932799486033,0.08384682577136326,0.013077103184640393
51.20000000000003,10.828937499043262,0.13118553134502486,0.01072412590475924
52.30000000000005,10.9280671265677,0.17206008789165939,0.011859819107328917
53.40000000000006,11.011409477348614,0.20777080634886042,0.013245209989423579
54.50000000000008,11.08608982790095,0.23899832707299629,0.012657171863670769
55.600000000000094,11.154729530476317,0.2712319721194862,0.01247602447321583
56.70000000000011,11.217792061152057,0.29884984920274626,0.014131279520967155
57.800000000000125,11.27750452565667,0.32371109962655686,0.011418171829473245
58.90000000000014,11.334338975137413,0.3496301030737136,0.01175181470304576
60.000000000000156,11.388087656902542,0.3706784564742384,0.012362705821538533
61.10000000000017,11.4403770739276,0.3942184600026979,0.011704286752824977
62.20000000000019,11.490044711287394,0.41332528492376497,0.012263124300927686
63.3000000000002,11.539625434168746,0.43301375285885996,0.011926757368443397
64.40000000000022,11.585425745220194,0.44958541211051756,0.012622350840053365
65.50000000000023,11.633945434600184,0.46661535787944114,0.011835977148082044
66.60000000000025,11.679123207099586,0.48354984308168414,0.012818946728799574
67.70000000000027,11.724500821335077,0.5010618135633034,0.012899367857166943
68.80000000000028,11.768162293984632,0.5152535719629624,0.01310295531875294
69.90000000000029,11.812516856667928,0.5309079325461473,0.013840286293352655
71.00000000000031,11.855351793821544,0.5454555131183461,0.013966136087815606
72.10000000000034,11.898118594397758,0.5581356735872823,0.013570069209065672
73.20000000000034,11.939822512037924,0.5689833518720966,0.012844911241090884
74.30000000000035,11.981794737680074,0.5781923383723642,0.012080404725472782
75.40000000000038,12.023607338358916,0.58872846089138,0.013366796846399076
76.5000000000004,12.064073464263766,0.591040367784541,0.013185421179800372
77.6000000000004,12.104452031424842,0.5959948081671574,0.013480594391435119
78.70000000000041,12.145524126963583,0.5979566868227271,0.012067400676913032
79.80000000000044,12.18545332527373,0.6017996006188155,0.012196062737170443
80.90000000000046,12.22537438161323,0.6030392084299363,0.012000475366112262
82.00000000000047,12.265216176193597,0.6048072268817202,0.012190028565925104
83.10000000000048,12.3046738262082,0.6052118896911858,0.01221145193790285
84.2000000000005,12.343696073613286,0.6065763576964412,0.013537565249825967
85.30000000000052,12.382739129934365,0.6084525527256641,0.013387669604965069
86.40000000000053,12.42165663152437,0.6103101488239283,0.013380078555699448
87.50000000000054,12.460364190811246,0.612636829171643,0.013849104987254002
88.60000000000056,12.498916320206572,0.6144326441686057,0.013310324998947465
89.70000000000059,12.53729225916628,0.6182957327177442,0.013212972771512455
90.8000000000006,12.575574619569402,0.6211224656851371,0.013188643223909224
91.9000000000006,12.613430602894699,0.6214583600199898,0.013312610004602377
93.00000000000063,12.651587378627646,0.623994751135259,0.013274110338508116
94.10000000000065,12.689428406973922,0.627836288527949,0.013066035925640485
95.20000000000066,12.727213609208198,0.6290177788210054,0.013159723694492698
96.30000000000067,12.76484381284884,0.6318132612277035,0.012879395697502183
97.40000000000069,12.802421899584159,0.6349218092495814,0.012690644734296264
98.50000000000071,12.839729082572836,0.6375190834221689,0.012148157961408224
99.60000000000072,12.877742019474402,0.6393316123212736,0.01321006887217635
100.70000000000073,12.914682582499324,0.642682055659349,0.014275934116462885
101.80000000000075,12.95220979212294,0.6472326863785249,0.01469630354549789
102.90000000000077,12.989479245313587,0.6523945936405245,0.013269593520297995
104.00000000000078,13.026921548881933,0.6556344640193713,0.013146894563916156
105.10000000000079,13.064101178654687,0.6597150915645582,0.012282706624018758
106.20000000000081,13.101058478956995,0.6638489703095148,0.012703415249282202
107.30000000000084,13.138139575620178,0.6671367791363324,0.012209858055662437
108.40000000000084,13.17569478340674,0.6732574079743336,0.012289725829996101
109.50000000000085,13.212593857315877,0.6765832523650597,0.010993129444455185
110.60000000000088,13.24962595471465,0.681171605223845,0.011267656820479921
111.7000000000009,13.286667407757278,0.6880380752435739,0.012395588464722884
112.8000000000009,13.323315976858652,0.6921589200961289,0.012419018703694107
113.90000000000092,13.360174938319915,0.69701060980473,0.013651127881682434
115.00000000000094,13.397302667982592,0.7010071265534596,0.012398335905065672
116.10000000000096,13.433826453235078,0.7066490907610362,0.013756010336788194
117.20000000000097,13.470953806453318,0.7125552557114381,0.013655441786235123
118.30000000000098,13.507561520938207,0.7148994173044485,0.01239607662671105
119.400000000001,13.54420496890089,0.7198384639071871,0.012400134604017232
120.50000000000102,13.580975961172987,0.7242333043551417,0.012404488238144218
121.60000000000103,13.617478223794814,0.7270076818695668,0.013703103273203787
122.70000000000104,13.653603936110667,0.7344255052271516,0.012365550027566563
123.80000000000106,13.690263316593791,0.7389230488745752,0.012389707609768763
124.90000000000109,13.726573338234925,0.7437435902353351,0.012413432091870291
126.0000000000011,13.762921719031919,0.7471143621074376,0.013719119746473218
127.1000000000011,13.799015024307362,0.7494062043516803,0.013710155935685364
128.20000000000113,13.835031747806955,0.7539304478292157,0.013701112539787452
129.30000000000115,13.871514329441185,0.7566334827361141,0.01235406132103467
130.40000000000117,13.907755320330116,0.7605608252840903,0.012400084958361646
131.50000000000117,13.943705701026014,0.7644654375430362,0.012423228345012305
132.6000000000012,13.979538944131107,0.7668661192239714,0.012717763927453163
133.7000000000012,14.015211428791357,0.7718618841618987,0.01273143493076212
134.8000000000012,14.051185110097814,0.7761484815637195,0.012364539066965108
135.90000000000123,14.087398299576835,0.7815106231358055,0.012399979389082993
137.00000000000125,14.122595346788499,0.7863659045239133,0.012399993374161866
138.10000000000127,14.158137543335693,0.7905522441880051,0.012400786302562139
139.2000000000013,14.193559888377044,0.7958479738432538,0.012568841544232434
140.3000000000013,14.229308751271443,0.8013863979289945,0.013708292666198219
141.4000000000013,14.264643310694982,0.8074193512672654,0.013709924187138789
142.50000000000134,14.300437343410856,0.8112155024399048,0.01370945220458264
143.60000000000133,14.335132767153125,0.816902756494552,0.01249720941974708
144.70000000000135,14.370778057969966,0.8240428977164795,0.012391638976832375
145.80000000000138,14.406345604362283,0.8332717699298452,0.012572344114367695
146.9000000000014,14.441390200833844,0.8407061115049319,0.013051108586315863
148.00000000000142,14.476483040744275,0.8481105998063918,0.013049975170625672
149.10000000000142,14.5114532537689,0.8563198495111453,0.013049997132973168
150.20000000000144,14.546745683947078,0.8670006769831511,0.013050507337998063
151.30000000000146,14.58187507675357,0.877349092540409,0.013087969320022097
152.40000000000146,14.616984239488398,0.8911606246229274,0.013706440482174287
153.50000000000148,14.651641946808853,0.9040566841198804,0.012918282857358854
154.6000000000015,14.686673085484589,0.9206652531160369,0.0123989722516189
155.70000000000152,14.721519033010669,0.9362391097459818,0.012399965894607234
156.80000000000155,14.756539719057372,0.9543400840104864,0.012399999808430096
157.90000000000154,14.791436526323903,0.9737466437401374,0.012399962662600572
159.00000000000156,14.826030602591896,0.9951504190424492,0.012403647657480477
160.1000000000016,14.861004449706487,1.0178951996208876,0.013288605609640847
161.20000000000158,14.895808333186796,1.0395035179286314,0.012352363200991867
162.3000000000016,14.930675556267364,1.059091503052568,0.012389654275740902
163.40000000000163,14.965229427422884,1.077285428997108,0.012387813766358668
164.50000000000165,14.99983591169899,1.0922646471183988,0.01240057230736813
165.60000000000167,15.034790671189926,1.0969271301557821,0.01140164024719148
166.70000000000167,15.069276495141033,1.0900544640951664,0.011410019226834045
167.8000000000017,15.103819604607532,1.0737341883538436,0.011410000774529472
168.9000000000017,15.13869981347814,1.049496750761496,0.011409999996389253
170.0000000000017,15.173202415299253,1.025674253030692,0.011410000016797817
171.10000000000173,15.207946054853261,1.000704732507831,0.011409998853819658
172.20000000000175,15.24215873497416,0.983202293023452,0.011409885537208453
173.30000000000177,15.276734758798485,0.9665924164680482,0.011424038654949342
174.4000000000018,15.310820664351365,0.9545484199837326,0.012726956937258116
175.5000000000018,15.345586367177155,0.9453465813096996,0.011660629890668517
176.6000000000018,15.379508677037729,0.9380949707688798,0.011727154662047212
177.70000000000184,15.41392508667818,0.9328770937563187,0.01103289210224112
178.80000000000183,15.44819236317258,0.9310509798065384,0.010090981914514074
179.90000000000185,15.48213756888866,0.928793407946574,0.010100491740681505
181.00000000000188,15.5164096682744,0.9281457318264154,0.011364269668294291
182.1000000000019,15.550352458174705,0.9282328810170363,0.011399970885304533
183.20000000000192,15.584826292026907,0.9289630988200673,0.011400002812835375
184.30000000000192,15.618400666245742,0.9273841743243232,0.011399999980556963
185.40000000000194,15.652847133219948,0.9299455542400634,0.0113999995766223
186.50000000000196,15.68623791031737,0.9321439075744246,0.011400033188070147
187.60000000000196,15.72073879440292,0.933742549111979,0.011400961124788722
188.70000000000198,15.754630388754618,0.9357465680131275,0.010958202790169125
189.800000000002,15.78850378395106,0.9365661045919009,0.01041788731793325
190.90000000000202,15.822553481584917,0.9411477565989047,0.010419965444818935
192.00000000000205,15.856240207599702,0.9418290344969579,0.010420000549799191
193.10000000000204,15.890213946863172,0.9460995752561332,0.010420000028322107
194.20000000000206,15.923816494187243,0.9498102209544624,0.010419995656347325
195.3000000000021,15.957774023927024,0.9509044351003166,0.010420123641512902
196.40000000000208,15.991657787471034,0.9568166267024493,0.009842786138537285
197.5000000000021,16.025280209282293,0.9598513909192183,0.00910484796219535
198.60000000000213,16.05895110549031,0.961870924624093,0.009109992341792328
199.70000000000215,16.092881695502196,0.9646377220072415,0.009110047844330893
200.80000000000217,16.126392038864715,0.9681100315984755,0.00910599669361467
201.90000000000217,16.159969993357652,0.9718536175842265,0.009758143839560418
203.0000000000022,16.193837994247957,0.9751904643628837,0.010091388137209556
204.1000000000022,16.227219082339264,0.9790700335328196,0.010089913667234995
205.2000000000022,16.261344294342987,0.9846388504975934,0.010066200141553239
206.30000000000223,16.295141043360783,0.9872980489819667,0.008721466205164674
207.40000000000225,16.32863103010694,0.9900987295063517,0.007466479029133666
208.50000000000227,16.36216785696534,0.997110722040373,0.008879163187411443
209.6000000000023,16.396139043200165,1.0000789664108427,0.008778954892920687
210.7000000000023,16.42942478991504,1.0030679233415494,0.008779199957264616
211.8000000000023,16.463226007557672,1.0079405581129888,0.008997937492177144
212.90000000000234,16.497045892059813,1.0148986461085747,0.010084106545460436
214.00000000000233,16.53015327457596,1.0198243777364069,0.010089953295846499
215.10000000000235,16.563898863711422,1.0229017303984755,0.010090006724150946
216.20000000000238,16.597814086841748,1.0294091274697406,0.010089701885730662
217.3000000000024,16.631131728172395,1.0353785404227414,0.010075136116669547
218.40000000000242,16.664707835107464,1.041081347300373,0.010770894294068079
219.50000000000242,16.698499745912788,1.0485877508455284,0.00932782338787419
220.60000000000244,16.73194578157654,1.0561990288707492,0.007803123815215862
221.70000000000246,16.76553658833385,1.0638440395057391,0.007485194204285506
222.80000000000246,16.799101598872326,1.0731440431996644,0.007900364004211013
223.90000000000248,16.832766719044407,1.080043875057394,0.007891132422541247
225.0000000000025,16.866242985143487,1.0912799955223085,0.009903949131194523
226.10000000000252,16.899543694446383,1.0995471660742875,0.010530001717961923
227.20000000000255,16.932927267162075,1.1095189433922508,0.010529978941960394
228.30000000000254,16.966424346816765,1.121069259772615,0.010530279271198317
229.40000000000256,16.999940612237925,1.1341967616568989,0.010529516254684346
230.5000000000026,17.033232702385764,1.1461028327160558,0.009170138167815978
231.60000000000258,17.06690913777372,1.1606467876652393,0.009220656722063403
232.7000000000026,17.100340642596215,1.1766925621736293,0.009220343803349351
233.80000000000263,17.133772342192657,1.195041745325171,0.0077959074527349514
234.90000000000265,17.167446442841374,1.2139005196367005,0.007706435540125511
236.00000000000267,17.20075950883938,1.235172623407722,0.0065756827543674845
237.10000000000267,17.234108871265892,1.2599451810536595,0.006581682442821979
238.2000000000027,17.26772685153029,1.2935065823674166,0.006489620059356049
239.3000000000027,17.300828170830464,1.3359417582299646,0.007573358821147735
240.4000000000027,17.334362395470446,1.3868149657142512,0.007541325113708197
241.50000000000273,17.367981037842327,1.4491983867864935,0.007896595492625558
242.60000000000275,17.401317256974778,1.5276596315719033,0.007900286126049316
243.70000000000277,17.43462862410758,1.6197614911380873,0.00774585583998455
244.8000000000028,17.46837165654569,1.7265761679112719,0.007569035807699187
245.9000000000028,17.502021706504475,1.8393122335962186,0.007569991927779185
247.0000000000028,17.535337642979325,1.9397281131797646,0.007570000201874372
248.10000000000284,17.56877908818406,2.00834055710048,0.007570001008706306
249.20000000000283,17.602057873074248,2.0174723079896415,0.0075701323519332675
250.30000000000285,17.63613595458713,1.9661230219933525,0.0075532013705901235
251.40000000000288,17.669336528137496,1.8694030022833565,0.0066446786648430844
252.5000000000029,17.702633164541624,1.7633480313296075,0.005280658172783781
253.60000000000292,17.736304512282267,1.6581707691789012,0.005269711970997015
254.70000000000292,17.76954895217346,1.5648140181883985,0.005270002204743385
255.80000000000294,17.8026451706661,1.4879172369033238,0.005270000251091922
256.90000000000293,17.835912576653218,1.4189436246809113,0.00526995875638292
258.00000000000296,17.869303024026326,1.3596487101407264,0.00527189721981447
259.100000000003,17.90229228024671,1.3121742177433888,0.006641572532330997
260.200000000003,17.935789933507383,1.273436057214706,0.006637853239939595
261.300000000003,17.96872279315195,1.2396157371805918,0.004924769398635398
262.40000000000305,18.00215519677289,1.2111517870084472,0.0046071600639328025
263.50000000000307,18.035039723670415,1.1910196115821372,0.0038292752495934224
264.6000000000031,18.06817426449422,1.1740204530257412,0.0032966972619501433
265.7000000000031,18.101206958862434,1.1596004337127608,0.004860418528561006
266.8000000000031,18.134374278397033,1.1475368170178037,0.004869772589745303
267.9000000000031,18.167672827936823,1.138503806785165,0.003928113903803876
269.0000000000031,18.201005807314925,1.1313222004680823,0.004829294629871583
270.10000000000315,18.23410301337959,1.1264100168969182,0.005223771974401714
271.2000000000032,18.26718079925588,1.1211773887104108,0.005824489445410919
272.30000000000314,18.300591124617448,1.1171942974112348,0.005820699582762323
273.40000000000316,18.333574993193704,1.1154595074655673,0.005517471358079007
274.5000000000032,18.36665510640592,1.1135956686792232,0.004603315471996439
275.6000000000032,18.399666315957358,1.1154571256076944,0.003180519819856009
276.70000000000323,18.43304165113759,1.116780911276117,0.00317997073697196
277.80000000000325,18.466311802397822,1.114880208718484,0.0031799018294469406
278.9000000000033,18.499094416281267,1.113645759051933,0.003182380546342678
280.0000000000033,18.53274224002013,1.114891884037442,0.0024493929727080754
281.1000000000033,18.565694855995577,1.114232111110239,0.002521147899734011
282.20000000000334,18.599204972973567,1.1154848583366055,0.002521082893824911
283.30000000000337,18.632519249613228,1.1149453740148614,0.0038144523367114047
284.40000000000333,18.665899106356566,1.115662056160449,0.0038403347149253975
285.50000000000335,18.699210358006347,1.1136270297763495,0.003839822283305594
286.6000000000034,18.732457187452887,1.1155350077344863,0.0037907622372985728
287.7000000000034,18.765517851670648,1.1164585261563456,0.0031964076953512333
288.8000000000034,18.79874535007581,1.1182470910500208,0.0031899678509752505
289.9000000000034,18.83190434120625,1.1197218468131174,0.0031899994378381535
291.0000000000034,18.865309493616117,1.1182149862300972,0.0031900000124664984
292.10000000000343,18.89850129365509,1.11950195117264,0.003189999997683657
293.20000000000346,18.931680470485208,1.1231466128920193,0.0031899997889173193
294.3000000000035,18.965260121179377,1.1241866283592241,0.0031900337830466086
295.4000000000035,18.99852220907961,1.1249256441192657,0.003188838931503568
296.5000000000035,19.03205941491021,1.1262245379001623,0.0030434511694119593
297.60000000000355,19.06504858708317,1.126998443665087,0.0018720879903337817
298.70000000000357,19.09852302470133,1.1281424936137812,0.001869678487755877
299.8000000000036,19.131822406428327,1.1295139202030386,0.0019486632204568366
300.9000000000036,19.164766817302382,1.1279840556301786,0.0005385341697108359
302.0000000000036,19.198172837548505,1.132124763985079,-0.002453335838912274
303.1000000000036,19.231381233027506,1.132799088514863,-0.0007579263361359168
304.2000000000036,19.26501182541792,1.1322724540231421,-0.0009694916298403911
305.30000000000365,19.298145652114343,1.1345867189268797,0.0004395328791106934
306.4000000000037,19.331620561699715,1.1359278595157885,0.00043999542278161385
307.5000000000037,19.36513979709671,1.1351705632290716,0.00044337442412434314
308.60000000000366,19.39833605602921,1.1363223158266675,-7.309020283630119e-05
309.7000000000037,19.43184146674418,1.1338476657936505,-0.0008729610602076221
310.8000000000037,19.465329686017338,1.1388321465498117,-0.0008698928327928179
311.90000000000373,19.49875971053326,1.1371571025192764,-0.0008712002832065302
313.00000000000375,19.53216675093435,1.139355633665362,-0.0010425426107176783
314.1000000000038,19.565445106889122,1.1385466693726798,-0.002067199564822264
315.2000000000038,19.599076759888636,1.1419985104180341,-0.0018681689787163336
316.3000000000038,19.632345034202935,1.138159705037524,-0.0018675941518679906
317.40000000000384,19.66572050321863,1.1399296579475406,-0.002259731380848784
318.5000000000038,19.69929904802504,1.141565764366132,-0.00253063837560763
319.60000000000383,19.7326540622649,1.142777924587987,-0.0025300103575531807
320.70000000000385,19.76613089270132,1.1421941065218777,-0.002531375078243414
321.8000000000039,19.79940436183662,1.1442673323096975,-0.002507743971936982
322.9000000000039,19.833018965589723,1.1410113087093692,-0.00310217842155458
324.0000000000039,19.86657412458098,1.1448692287347861,-0.004173423539152399
325.10000000000394,19.89990879700226,1.1446073606581115,-0.004169840202504993
326.2000000000039,19.933613345843867,1.1451045544989453,-0.0048567294843993025
327.30000000000393,19.966953732707893,1.1455115952734385,-0.005476077071682628
328.40000000000396,20.000642962996675,1.146774117318361,-0.0042298412608015035
329.500000000004,20.034310869341958,1.146296277167851,-0.004083192256087997
330.600000000004,20.067713671097216,1.1451008893062349,-0.005448170753160397
331.700000000004,20.101223722824905,1.1472708946789423,-0.006804297546092464
332.80000000000405,20.1348247576763,1.1470809543191574,-0.007248513813022495
333.90000000000407,20.168738001432438,1.1475267957472508,-0.008109934812896569
335.0000000000041,20.202255013234037,1.1491848057797567,-0.007987364209941283
336.10000000000406,20.23554806987616,1.1470643109693455,-0.006811220257748385
337.2000000000041,20.269140872241486,1.1464155517528327,-0.00809042191386622
338.3000000000041,20.30303071516219,1.1471677396104,-0.008119701295793202
339.4000000000041,20.336712971954256,1.1457609537581388,-0.008194883396875241
340.50000000000415,20.370185001708442,1.1451497836258344,-0.010742618653364122
341.6000000000042,20.403878273030767,1.1473255249792222,-0.010746161450891023
342.7000000000042,20.437601380118505,1.146848652782664,-0.011203768208485787
343.80000000000416,20.47138326934153,1.1466433962261136,-0.012049028914962179
344.9000000000042,20.50510558682366,1.14619745691011,-0.01342347627983198
346.0000000000042,20.538840680353395,1.1418401032234007,-0.012097032028211885
347.10000000000423,20.572517713553502,1.1441991804576628,-0.012174215121089738
348.20000000000425,20.60619573863528,1.1427043413453115,-0.01337961651565367
349.3000000000043,20.639843214760766,1.1437459223692419,-0.013382690621839721
350.4000000000043,20.67357149256774,1.1467127157668942,-0.015544721216524948
351.5000000000043,20.707369221841933,1.145479610118801,-0.016006811812170785
352.60000000000434,20.741191533170593,1.1466293386549646,-0.017423223185218273
353.7000000000043,20.774798587788446,1.1431380577529882,-0.017500715636740605
354.80000000000433,20.80838551491835,1.1435625069149855,-0.018743188817007983
355.90000000000435,20.84229567429045,1.143687452046731,-0.019070082697730584
357.0000000000044,20.876494743957224,1.1444205945191088,-0.019364187538738697
358.1000000000044,20.91012267565443,1.1449490209369773,-0.020727134955624837
359.2000000000044,20.94417548710353,1.143590180039232,-0.022051243316968172
360.30000000000445,20.97805410659915,1.1443094205794084,-0.021962151785263284
361.4000000000044,21.011487995830276,1.1438324805397386,-0.02335637185575079
362.50000000000443,21.04581645946764,1.143691747611289,-0.024764740282213538
363.60000000000446,21.079818107248386,1.145788803499257,-0.026803461879802537
364.7000000000045,21.113626231080676,1.1461623988785603,-0.02739871712970743
365.8000000000045,21.14664291444235,1.145323531528018,-0.028301079188721268
366.9000000000045,21.18149679587006,1.1465518052788717,-0.02982790739248209
368.00000000000455,21.215570205302104,1.1484786396731865,-0.03133951256155809
369.10000000000457,21.249419413312438,1.1485381472377028,-0.03291428753417369
370.2000000000046,21.283009355310515,1.1524416655598924,-0.03452645642689811
371.30000000000456,21.317527374532883,1.1525822927250375,-0.03595730667529118
372.4000000000046,21.351525364724253,1.1557142337652013,-0.037551610091280274
373.5000000000046,21.385384178657286,1.1581842307315278,-0.0389013077233864
374.6000000000046,21.41934116121743,1.1604703574434398,-0.040740688047374185
375.70000000000465,21.45336459914586,1.1619291419764672,-0.04302695837617243
376.8000000000047,21.487656185607328,1.1640681483033415,-0.0450839231610809
377.9000000000047,21.521463343306685,1.1644422754848593,-0.04699594650287642
379.00000000000466,21.555632423505067,1.168019061393968,-0.049208060950691745
380.1000000000047,21.589600681837624,1.1695547957536578,-0.05217774711363088
381.2000000000047,21.623553716923368,1.1740004392124221,-0.05459460731123045
382.30000000000473,21.657865009688614,1.178388678504433,-0.05771893257457572
383.40000000000475,21.6917486443384,1.183322155089233,-0.05979322287626854
384.5000000000048,21.725898014295108,1.187106820230599,-0.06232053930793935
385.6000000000048,21.76003090585279,1.1886291795584538,-0.06438251534349515
386.7000000000048,21.79437425219581,1.1961449036120082,-0.06775655263580571
387.80000000000484,21.82804305486087,1.2008554173479793,-0.07129597619221917
388.9000000000048,21.862449779369584,1.205765622967685,-0.07500565058479047
390.00000000000483,21.896894447927977,1.2109798805630128,-0.07844316933424533
391.10000000000485,21.930886378601528,1.2166067035900359,-0.08238700980993885
392.2000000000049,21.965116624770705,1.2194496861550024,-0.08642215733578418
393.3000000000049,21.999192927578893,1.2278955491524206,-0.08998955397306885
394.4000000000049,22.03360397372687,1.2349394454220655,-0.09478773821502395
395.50000000000495,22.067964625690525,1.2390383395359599,-0.0988315499201402
396.6000000000049,22.10204163861159,1.2508357143270372,-0.1026980270682234
397.70000000000493,22.13606384756519,1.2550740531926132,-0.10810912339464007
398.80000000000496,22.170402187205426,1.2632673079082328,-0.11291943193876275
399.900000000005,22.204546320996705,1.2703217058960412,-0.11844978610305157
401.000000000005,22.239200653792903,1.2774196463224874,-0.12434210935111478
402.100000000005,22.273244874201268,1.2846319503931714,-0.12988019872679768
403.20000000000505,22.30769054719168,1.2920258891033174,-0.1358820286842577
404.30000000000507,22.341921671113074,1.2986965847874359,-0.14273974155960856
405.4000000000051,22.376261357540418,1.3076601790158215,-0.1507924717918705
406.50000000000506,22.410647637592202,1.314077299268418,-0.1570000025550531
407.6000000000051,22.444721368128036,1.3234983522764645,-0.1651064853022235
408.7000000000051,22.47909817493268,1.33248601365976,-0.1734974921750525
409.8000000000051,22.5136999355901,1.3412602354859764,-0.1812577266356774
410.90000000000515,22.54757476160028,1.3487806082097198,-0.1883918130704232
412.0000000000052,22.582644866137773,1.3572662284416217,-0.19805187732618013
413.1000000000052,22.616750193110402,1.3645913332725843,-0.20607861532716676
414.20000000000516,22.651139728644683,1.3714097291806078,-0.21427298843837672
415.3000000000052,22.685432560572306,1.382882006969386,-0.22526970347085173
416.4000000000052,22.720130807104756,1.3914124565282497,-0.23640943042173346
417.50000000000523,22.754383724289795,1.4023156273219368,-0.24591135983072254
418.60000000000525,22.788913528704466,1.414383695258974,-0.2562480604160964
419.7000000000053,22.823491118304524,1.423425411286026,-0.2671753993614141
420.8000000000053,22.85790016891292,1.4354372151326256,-0.27854682389931806
421.9000000000053,22.892561415588546,1.4480523723620105,-0.29102170582615106
423.00000000000534,22.92691862868991,1.461926544188972,-0.3041992543346135
424.1000000000053,22.961319230715034,1.4748557660607091,-0.31693472406313683
425.20000000000533,22.99612711921055,1.488467997362498,-0.33093244784277065
426.30000000000535,23.030411207849383,1.5060827939938977,-0.34427974917334225
427.4000000000054,23.064954385452854,1.5236326447858994,-0.35818524748177794
428.5000000000054,23.099839821445673,1.5397818281403381,-0.37373845108680737
429.6000000000054,23.13416125813673,1.561998428733935,-0.38893334299560367
430.70000000000545,23.169077023479257,1.5814857718896413,-0.4056667998902417
431.8000000000054,23.203814803067363,1.5999387040636948,-0.4247278511594783
432.90000000000543,23.238316492758663,1.617899056002742,-0.44247438086991675
434.00000000000546,23.272833754834863,1.6400444800611669,-0.4582791965615205
435.1000000000055,23.307408815290135,1.6564258866050001,-0.4767715765339209
436.2000000000055,23.342426679113185,1.6756548220388545,-0.4972053005610544
437.3000000000055,23.376641163746882,1.6912138846187377,-0.5181163075729698
438.40000000000555,23.4114082025561,1.7088474948940218,-0.541795213310869
439.50000000000557,23.4464059541496,1.7238980705686848,-0.5646708666489331
440.6000000000056,23.48081884862504,1.7375537193565722,-0.5869149391260269
441.70000000000556,23.51570234680528,1.7518099254160497,-0.6107595754886299
442.8000000000056,23.550700927607743,1.7652178666364031,-0.6356822820568442
443.9000000000056,23.585274116062532,1.7784508693525167,-0.6599797812819492
445.0000000000056,23.620031439816,1.7917159764912969,-0.6863336907153914
446.10000000000565,23.654767179621594,1.8087648776720264,-0.7130448961922315
447.2000000000057,23.689452774412405,1.8214304657714915,-0.7414416140522295
448.3000000000057,23.724244424699418,1.8387444845600094,-0.7713411337153468
449.40000000000566,23.759371497571127,1.8538758439748413,-0.8019935936861535
450.5000000000057,23.79392831112243,1.87068900629682,-0.8316612475621552
451.6000000000057,23.828804380359973,1.8871296535027267,-0.8609491395675541
452.70000000000573,23.86381936347214,1.9059795577939391,-0.8914254766454794
453.80000000000575,23.898691907092946,1.9217033049611523,-0.9244050596662645
454.9000000000058,23.933612067872968,1.9375305134740204,-0.9587228969706683
456.0000000000058,23.968348281892858,1.953170815701454,-0.9940791993983709
457.1000000000058,24.00333407463411,1.968682020218445,-1.030114381125868
458.20000000000584,24.03813280407376,1.9809081894235143,-1.0662249247962188
459.3000000000058,24.07290354043405,1.9873766455183146,-1.1030362471844266
460.40000000000583,24.10800475274161,1.992106794922927,-1.1394249501432947
461.50000000000585,24.142896622809147,1.9918643505848714,-1.1782680324543602
462.6000000000059,24.177532146414137,1.991197917834775,-1.2166131158618025
463.7000000000059,24.21234278596688,1.9849331793229323,-1.2554231963284326
464.8000000000059,24.247550795093694,1.9718118816966275,-1.2955550454891975
465.90000000000595,24.28241616778607,1.9551170922763241,-1.3363014051169646
467.0000000000059,24.317606777707837,1.9327358555408316,-1.374158738805352
468.10000000000593,24.352469382112528,1.9082453370265415,-1.410767516928134
469.20000000000596,24.38769422643783,1.877880693681244,-1.4468208127948903
470.300000000006,24.422299319795123,1.8468507504704605,-1.4804322994476737
471.400000000006,24.457362774430806,1.8066867663779664,-1.5143255433005338
472.500000000006,24.4920477113507,1.764285075025995,-1.545994559681262
473.60000000000605,24.52727352257684,1.722054113145958,-1.5757953428890588
474.70000000000607,24.562306664971064,1.673606703065027,-1.6023910499021379
475.8000000000061,24.597127877006557,1.6235624033693423,-1.6268745898740429
476.90000000000606,24.63208991830408,1.5669106232892895,-1.6469549801388306
478.0000000000061,24.667236670607863,1.5145254615272452,-1.6661940534554032
479.1000000000061,24.702058142375442,1.4566600903303202,-1.684283973388991
480.2000000000061,24.737213214104017,1.4062142386804002,-1.7002551909693406
481.30000000000615,24.77202333184495,1.3592727475825572,-1.7135416720345957
482.4000000000062,24.80647971828761,1.316015942736987,-1.7270965922524812
483.5000000000062,24.84206500943236,1.2764478659398353,-1.74001171217343
484.60000000000616,24.876916181488383,1.2426134005125633,-1.7517392325464831
485.7000000000062,24.911852234420532,1.214514960766763,-1.7630098317468517
486.8000000000062,24.947158962825227,1.1892223020965667,-1.775872865689641
487.90000000000623,24.981690258130193,1.1674692502890365,-1.7874407381603588
489.00000000000625,25.017055496264177,1.151692708865125,-1.798523861480287
490.1000000000063,25.051807612684446,1.1376581879169467,-1.8097544525750267
491.2000000000063,25.087022774717894,1.1274586229416903,-1.8234236069500493
492.3000000000063,25.121994996805228,1.1155660538842085,-1.8354640957909871
493.40000000000634,25.157219897792114,1.1101395614385303,-1.84734582176306
494.5000000000063,25.19236193439125,1.1061378475580579,-1.8587657323238496
495.60000000000633,25.22737017237061,1.0949276885460957,-1.8699202078050492
496.70000000000636,25.26245490662254,1.0868557388865538,-1.8832562808914615
497.8000000000064,25.297824608797846,1.072691376129708,-1.895973950282671
498.9000000000064,25.33273974614808,1.0595375789491936,-1.9077482913695216
500.0000000000064,25.36791134394248,1.0432287801707578,-1.9188540058273618
501.10000000000645,25.403490915130693,1.0238722343477173,-1.9310279469488703
502.2000000000064,25.438142979342786,0.9948824191304948,-1.9409077835047612
503.30000000000643,25.473079769026324,0.9491694187878583,-1.9500524333006455
504.40000000000646,25.508681753103666,0.8890975596858315,-1.9582013490474752
505.5000000000065,25.543857009265306,0.8248279498019349,-1.9652090870634047
506.6000000000065,25.579117871154562,0.7588757825138321,-1.9712335973443103
507.7000000000065,25.61442647042613,0.7007083620053693,-1.9752237627643932
508.80000000000655,25.64932487949554,0.6430798775673319,-1.9787721041762705
509.90000000000657,25.684869990284454,0.5967528261958321,-1.9816739365685487
511.0000000000066,25.720252620550355,0.5573299510698502,-1.984664766805361
512.1000000000065,25.7553312398135,0.5310803341088473,-1.985998037352379
513.2000000000066,25.790489891937394,0.5077798172734587,-1.987894867318373
514.3000000000065,25.826270420101807,0.4876251056293206,-1.9897577785403864
515.4000000000067,25.861404287882277,0.47725410214983466,-1.9905689965959206
516.5000000000066,25.89637115609502,0.46372353970666214,-1.9917385205206668
517.6000000000067,25.931942415539886,0.45770938279235573,-1.9932637280026873
518.7000000000066,25.96697423307854,0.450739121091547,-1.9955567181973084
519.8000000000067,26.002419313661978,0.44522661622087,-1.9973631031544934
520.9000000000067,26.03784927580992,0.43799909116826563,-1.9978152612278226
522.0000000000067,26.073123198322328,0.43823867381581927,-1.9991143230627242
523.1000000000067,26.108713108546684,0.433514831403371,-2.000404885612677
524.2000000000068,26.144244465435047,0.43335511902970847,-2.0005038432531723
525.3000000000068,26.17967963683926,0.4305398494249275,-2.00176236418797
526.4000000000068,26.21516110014101,0.4315642553196051,-2.0038757620307512
527.5000000000068,26.2507142135301,0.4304670843834637,-2.0050496859697677
528.6000000000068,26.285983090629152,0.4306559460669719,-2.0063706198280533
529.7000000000069,26.321697166946713,0.42756564626931004,-2.0071701622073386
530.8000000000068,26.357166545105926,0.4310549643687811,-2.007693350615102
531.9000000000069,26.392616477038075,0.4336365274406686,-2.0091057996434145
533.0000000000068,26.428280682686857,0.43215962495242466,-2.009027339204832
534.100000000007,26.46368180445101,0.43352922186586085,-2.0103275471326176
535.2000000000069,26.499113758327077,0.4358297128049955,-2.010900349149493
536.300000000007,26.534763760886502,0.43650551086244027,-2.012192252027306
537.4000000000069,26.57047295937691,0.4385623735604134,-2.011739059117633
538.5000000000069,26.606157097009078,0.43732504728183885,-2.0127252584726563
539.600000000007,26.641453795889607,0.43845757762584414,-2.0149610260621476
540.700000000007,26.67691110285838,0.44183727017337615,-2.0159265629904968
541.800000000007,26.712810502922352,0.4412251151777351,-2.0185555472061996
542.900000000007,26.748525749122546,0.443105431241158,-2.0198630587012913
544.000000000007,26.784009360477413,0.44469137273949677,-2.0199020803114163
545.1000000000071,26.819424801442516,0.444186468581099,-2.0208602743403428
546.2000000000071,26.855347860861045,0.44593121958349613,-2.0213125346173757
547.300000000007,26.890792102883275,0.44936179496377937,-2.0215800549671092
548.4000000000071,26.926403361535527,0.4493785378402779,-2.0226216587072336
549.500000000007,26.96216269692951,0.44905157394474715,-2.0237857806608837
550.6000000000072,26.997671678204416,0.4539891330671275,-2.0251347255829577
551.7000000000071,27.033664337156612,0.4531873403368718,-2.0265533005978273
552.8000000000072,27.069242403302034,0.4544456757355855,-2.0270469897457337
553.9000000000071,27.10448015004415,0.4576284930876513,-2.027716123209881
555.0000000000072,27.140163769693682,0.4608083825801472,-2.0291859995129995
556.1000000000072,27.176276506879606,0.4589392771213565,-2.0306584002039094
557.2000000000072,27.21195791031747,0.4609542828364366,-2.031940787705114
558.3000000000072,27.247485513450663,0.4635462985568033,-2.0331456874588145
559.4000000000073,27.283668360993925,0.46744848994488075,-2.033548561936409
560.5000000000073,27.31925626684834,0.4678380757547487,-2.035219757016291
561.6000000000073,27.35497860604796,0.4666703626965405,-2.037013309277661
562.7000000000073,27.390558093632116,0.4678487107161948,-2.038413701311521
563.8000000000073,27.42606328574741,0.4722216866634139,-2.038793522216178
564.9000000000074,27.46229903423352,0.4686803025543895,-2.0400683667848822
566.0000000000074,27.498118388497545,0.47150483181714353,-2.0416360732318193
567.1000000000074,27.53374185458656,0.47077799487544647,-2.043215072778606
568.2000000000073,27.569458138455285,0.4718817305243057,-2.044438282308452
569.3000000000073,27.605286585802812,0.4732975656309364,-2.0445070125819007
570.4000000000074,27.64146682146182,0.47481472866524355,-2.0458086635128594
571.5000000000074,27.67718186984664,0.47753088553988343,-2.047063588138991
572.6000000000074,27.71291281956714,0.48148985286606427,-2.048708706144739
573.7000000000074,27.74878510637486,0.48033111000047946,-2.050324576582488
574.8000000000075,27.784948146887203,0.48181316824509235,-2.051650777645707
575.9000000000075,27.820101231877327,0.482471995775795,-2.052779746200412
577.0000000000075,27.85668306377951,0.483051461900863,-2.054715410317328
578.1000000000075,27.89230707190974,0.4839817258361814,-2.0562507189969437
579.2000000000075,27.928447272736094,0.48588182939774915,-2.0576786747981575
580.3000000000076,27.96438844369087,0.48600580020879036,-2.0589622910982337
581.4000000000076,28.00026965419273,0.48718333183143114,-2.0604426835832346
582.5000000000076,28.03612599093856,0.4886796904761632,-2.0626018217610094
583.6000000000076,28.072475385344067,0.49242842927071173,-2.065738522238597
584.7000000000077,28.10813900013152,0.49330340272101747,-2.067182424877239
585.8000000000077,28.14447029086861,0.49479074414087254,-2.0688789359448907
586.9000000000076,28.180365295641963,0.4994115630324383,-2.0716813020868448
588.0000000000076,28.216576730070685,0.5004209505380879,-2.0739424800061235
589.1000000000076,28.252412067163974,0.5059455799048571,-2.0756608672605203
590.2000000000077,28.288393348281105,0.5073384835578976,-2.0773013914944487
591.3000000000077,28.32449151217811,0.5162137977444012,-2.0797906743338075
592.4000000000077,28.360391801377638,0.5141101139702222,-2.0816471812862614
593.5000000000077,28.39663331908775,0.5222855140619864,-2.0851458138966716
594.6000000000078,28.432768511442465,0.5296553391910575,-2.088310036391697
595.7000000000078,28.469104312096746,0.5372589174007047,-2.090681051350856
596.8000000000078,28.505242221240884,0.5450808759755903,-2.093454566506377
597.9000000000078,28.54120981309315,0.5499451989161517,-2.094948298819441
599.0000000000078,28.577515705861945,0.5582367380459199,-2.098634284381111
600.1000000000079,28.61320533629131,0.5656402958868485,-2.1005440912546227
601.2000000000079,28.649627961655106,0.5686695615720883,-2.1055236071261847
602.3000000000079,28.685537390785193,0.5735715042929197,-2.1093951125871278
603.4000000000078,28.72176280155151,0.5876732878132591,-2.1134950090731803
604.5000000000078,28.758127675437283,0.59642536994156,-2.1155729110645787
605.6000000000079,28.793933508730365,0.6063849773598435,-2.119040394909656
606.7000000000079,28.83016662728575,0.6177896100419646,-2.1222532181875633
607.8000000000079,28.866550767107544,0.6322114223181536,-2.1257273630965114
608.9000000000079,28.90267381926866,0.642468176614583,-2.129171241766683
610.000000000008,28.93853264357465,0.6540932988360115,-2.1331419869726687
611.100000000008,28.974841126121827,0.6652975249928614,-2.138135829225445
612.200000000008,29.010256655561854,0.6704577335051312,-2.142994151975045
613.300000000008,29.047377194354524,0.676703995451597,-2.148510846283097
614.400000000008,29.083485999083514,0.681412223324704,-2.1531231465580034
615.5000000000081,29.11986928177993,0.6826760077278973,-2.1589283897530325
616.6000000000081,29.156091210803254,0.6830800096257521,-2.165087887960387
617.7000000000081,29.192437301597284,0.6891753623075041,-2.170979660649808
618.8000000000081,29.22848567236213,0.690301032405872,-2.1753680167496334
619.9000000000082,29.264522488066863,0.6911346178327422,-2.1820779267035153
621.0000000000082,29.300896822909106,0.6934849951535527,-2.1877729757820332
622.1000000000081,29.33706549838308,0.692472487893236,-2.1945621674224824
623.2000000000081,29.37322948711024,0.695315330871245,-2.201175071853548
624.3000000000081,29.409090716195923,0.6976930816860287,-2.2071049003173115
625.4000000000082,29.44574396574007,0.7020004043125687,-2.2158871409272156
626.5000000000082,29.481735324822633,0.6982288529208489,-2.2221870497733156
627.6000000000082,29.51688669044153,0.7010375117245813,-2.2294213617389653
628.7000000000082,29.554200786902676,0.7011643705876605,-2.2368664896154256
629.8000000000083,29.590423852353922,0.7007053996370076,-2.243924992250375
630.9000000000083,29.626422736975222,0.7021464947003482,-2.250490935035126
632.0000000000083,29.663050996763204,0.702101676481603,-2.258086560935664
633.1000000000083,29.69911376222919,0.701160131337839,-2.265881434596621
634.2000000000083,29.73538868704033,0.7002048779112271,-2.2738555499989386
635.3000000000084,29.771696087161533,0.701012942471583,-2.279699146974375
636.4000000000084,29.807984338099388,0.6971359658188216,-2.2857523913848192
637.5000000000084,29.843928345047935,0.698179167031332,-2.2927397809818797
638.6000000000083,29.88035994282753,0.6983427600195888,-2.2986586584724695
639.7000000000083,29.91559711321205,0.7009972753706579,-2.3046171677847784
640.8000000000084,29.952662330897866,0.7084765671986135,-2.3085708463451495
641.9000000000084,29.989369391431044,0.7138279541760242,-2.3117133231814377
643.0000000000084,30.02571592833379,0.7069779388506463,-2.313671083410644
644.1000000000084,30.06182408694103,0.7021918484424612,-2.3150188425045175
645.2000000000085,30.09807280581264,0.6948884121866388,-2.316446747009578
646.3000000000085,30.13418814169831,0.7009106817327031,-2.317898153275373
647.4000000000085,30.170702903862296,0.7113290460574517,-2.3193053699948987
648.5000000000085,30.206916826532613,0.7273845090702613,-2.3199191574156783
649.6000000000085,30.24330596692483,0.7439490705193506,-2.319909868414607
650.7000000000086,30.279431892570894,0.768159045879842,-2.3212811960737825
651.8000000000086,30.315742013913383,0.783510555609698,-2.3227939107336346
652.9000000000086,30.35217349598745,0.8011562925390643,-2.3242996492189363
654.0000000000086,30.388632593858546,0.8187285292147806,-2.325682250711838
655.1000000000087,30.424992015141072,0.8366599192596849,-2.326950886574498
656.2000000000087,30.461220584366956,0.8551899470703979,-2.32838982844392
657.3000000000086,30.497628268828258,0.87057071369592,-2.329779935823942
658.4000000000086,30.53379405571232,0.8849655734779751,-2.3311880826602014
659.5000000000086,30.570529551893813,0.901329314713347,-2.332794906321615
660.6000000000087,30.606732611046112,0.9199659076786779,-2.3343515527859746
661.7000000000087,30.643114485662295,0.9360051041053641,-2.3354135155510254
662.8000000000087,30.679607750663717,0.9527196467217998,-2.3373814671755473
663.9000000000087,30.71580670560953,0.9734215743497776,-2.339237336791718
665.0000000000088,30.751789628527494,0.9877067056508411,-2.3407372670245685
666.1000000000088,30.788672673341903,1.008370013513514,-2.3425070187903336
667.2000000000088,30.825064308338078,1.029645529791674,-2.3440056361723745
668.3000000000088,30.86161473138164,1.0489414807612514,-2.3443606820103895
669.4000000000088,30.897783275239767,1.0722643222884742,-2.347005634358799
670.5000000000089,30.93341329507681,1.0943348260476182,-2.349638088413663
671.6000000000089,30.97103084761858,1.1154208013066214,-2.351555534864721
672.7000000000089,31.007281397077946,1.1360036041785664,-2.353371455971666
673.8000000000088,31.043704538620783,1.1648411480697987,-2.3557843790357507
674.9000000000088,31.080130730808612,1.188500977128209,-2.3581526454181123
676.0000000000089,31.1164267092131,1.21799874723312,-2.3605742088280044
677.1000000000089,31.152950301143978,1.2427636212530473,-2.363051524894556
678.2000000000089,31.189493616918107,1.2751429527469642,-2.365126189149579
679.3000000000089,31.22591442672978,1.3011346210241581,-2.366569073729035
680.400000000009,31.26229349007247,1.3317878189496133,-2.3691417363049907
681.500000000009,31.298968888671393,1.3679635019722913,-2.3721415840301594
682.600000000009,31.335402593347357,1.4000264274994585,-2.3743024766132583
683.700000000009,31.372034360059136,1.437051273475948,-2.3773051200680104
684.800000000009,31.40831783007189,1.4729468785926465,-2.3799068387632794
685.9000000000091,31.44467626121113,1.5165852677012315,-2.382879922578671
687.0000000000091,31.481305770293528,1.5571328698787297,-2.3861149528789802
688.1000000000091,31.5179064640411,1.5975855879564262,-2.386669386996977
689.2000000000091,31.554195684477726,1.6451270675619396,-2.3898647169545626
690.3000000000092,31.590751251574922,1.68789568697296,-2.3942825485305788
691.4000000000092,31.627410587706596,1.7368527942008232,-2.397018112875093
692.5000000000091,31.663843558263803,1.7829351751197424,-2.4018311560348162
693.6000000000091,31.70017049449207,1.8323175349919993,-2.4053507175184254
694.7000000000091,31.73664841814227,1.8858414742463356,-2.407556450346217
695.8000000000092,31.77239313364263,1.9348783235192717,-2.410591518438985
696.9000000000092,31.809873465516244,1.9903728874832396,-2.4143948880827226
698.0000000000092,31.846417872400437,2.046950875999683,-2.4194017261587213
699.1000000000092,31.883177686467683,2.1014242213612064,-2.424741653059853
700.2000000000093,31.91966616225848,2.156970158218067,-2.427664875924126
701.3000000000093,31.956107077970184,2.2111966347320364,-2.431943343886921
702.4000000000093,31.992565764967573,2.2705385975288355,-2.437049596730593
703.5000000000093,32.029231536424234,2.3299995360463766,-2.4409989393330838
704.6000000000093,32.06584799644009,2.387571917702969,-2.446555056593562
705.7000000000094,32.10234096000095,2.4509620169138624,-2.451366792446341
706.8000000000094,32.13883189507854,2.506649284172702,-2.4560456355115248
707.9000000000094,32.17563485559673,2.572857775962758,-2.4602481483160283
709.0000000000093,32.21234901140907,2.634266706911387,-2.4659201365631236
710.1000000000093,32.2485390757617,2.6958058073968836,-2.471176523487088
711.2000000000094,32.285388505115215,2.762867469324046,-2.4776782029389617
712.3000000000094,32.321888629662595,2.8250440179113667,-2.4832896502859727
713.4000000000094,32.35844592598687,2.8920114777447754,-2.4884082276698414
714.5000000000094,32.39534045768764,2.956833571908778,-2.4933651342550274
715.6000000000095,32.43191760579569,3.0241074623402393,-2.499060502356839
716.7000000000095,32.46898674634656,3.091455419551887,-2.5048161569335443
717.8000000000095,32.50514312802571,3.156636520029395,-2.5122840285041885
718.9000000000095,32.54204749542405,3.229939414370004,-2.5191854975313546
720.0000000000095,32.57858923990191,3.2998470311452923,-2.5273335718099723
721.1000000000096,32.615381529923006,3.365698092007066,-2.5334918602448204
722.2000000000096,32.652151485059676,3.441760838948845,-2.540588786600899
723.3000000000096,32.688703966195376,3.5105796082821024,-2.54698148684559
724.4000000000096,32.72571805465213,3.584029595120369,-2.5538232078346192
725.5000000000097,32.76221996165449,3.6594847643425474,-2.560874032453522
726.6000000000097,32.798873026473196,3.7317457636516735,-2.568530406898873
727.7000000000096,32.83588606838654,3.80326461385617,-2.5774073716354193
728.8000000000096,32.87231262198205,3.8752229010693426,-2.584184782139627
729.9000000000096,32.909311653980836,3.948049938929192,-2.591541171134679
731.0000000000097,32.94618915568214,4.028174728541394,-2.599254224911468
732.1000000000097,32.982591028357874,4.098910858526992,-2.608473337236154
733.2000000000097,33.019368461435775,4.171300679101664,-2.617843372158865
734.3000000000097,33.05621283376138,4.245848353542261,-2.6272833128908015
735.4000000000098,33.09275355618998,4.317947335845351,-2.6346639357717967
736.5000000000098,33.12969762496347,4.393048777191941,-2.643492077109718
737.6000000000098,33.166628585346274,4.460487468097117,-2.6524547557937197
738.7000000000098,33.203193958757176,4.5316351695569494,-2.6611464796939885
739.8000000000098,33.240201641356194,4.596127462625429,-2.6709164945131914
740.9000000000099,33.276885758051655,4.664782846176744,-2.6805004536763253
742.0000000000099,33.31333092021263,4.721229471976355,-2.690165274064219