File: 01_Data/Polyester_Carpet_Medium_Pile/STA/N2/30K_min/Polyester_Carpet_Medium_Pile_STA_N2_30KData_211217_R1.csv
##Temp./Â°C,Time/min,DSC/(mW/mg),Mass loss/mg
49.0,10.491179586310468,0.02491012712789764,0.011565364103765852
50.100000000000016,10.705403218316828,0.07662912874851058,0.013149573795574021
51.20000000000003,10.832061440767388,0.11605519750764359,0.013796340471951662
52.30000000000005,10.929920369271738,0.1502806740444137,0.01457056902997289
53.40000000000006,11.015075762440016,0.18375624397759838,0.012370407387818805
54.50000000000008,11.090321100408707,0.21183046638955771,0.0129351755950462
55.600000000000094,11.157914247543022,0.23531277419082752,0.012966726938792306
56.70000000000011,11.221353675020078,0.2641753648910489,0.013029508092549325
57.800000000000125,11.280425064280557,0.28357706123901183,0.014390226872740719
58.90000000000014,11.33685334368647,0.3051994673871354,0.013680540904172922
60.000000000000156,11.39033703787043,0.3256695965764722,0.014435720248741735
61.10000000000017,11.442934131288748,0.3447450170829371,0.014775447713833323
62.20000000000019,11.493459823753268,0.36258470149009014,0.014325125235254532
63.3000000000002,11.541984277966979,0.3791527083998189,0.015062566160092938
64.40000000000022,11.5897588846902,0.39814227402263597,0.014065993308074454
65.50000000000023,11.63626269128175,0.41122077474147295,0.015012978342833438
66.60000000000025,11.682012019463139,0.42382405646349486,0.014951045970050814
67.70000000000027,11.72712457001868,0.43650794759992373,0.016275921511531344
68.80000000000028,11.771678938936601,0.4531454677642024,0.014960370879521179
69.90000000000029,11.81476957486765,0.46543175780628365,0.014689415590757537
71.00000000000031,11.857318945885925,0.4800314110679973,0.014219817609196106
72.10000000000034,11.90000000000001,0.4915870165198047,0.013938903284239412
73.20000000000034,11.942664828412635,0.5007179981390625,0.014292322008269576
74.30000000000035,11.98400445239394,0.509330132639244,0.012850963070638599
75.40000000000038,12.025347128593838,0.5170930202562498,0.014255411012084274
76.5000000000004,12.06659183236464,0.5227268434394694,0.0138821334680852
77.6000000000004,12.106706628502275,0.5248027914620949,0.014352416117754618
78.70000000000041,12.147119197111854,0.5270032432869068,0.014434582786075012
79.80000000000044,12.187401195365196,0.5276608242792443,0.013980123820660939
80.90000000000046,12.227150712228424,0.5292634936233668,0.013892615284759824
82.00000000000047,12.266815042835765,0.5303537481277412,0.014250520394119892
83.10000000000048,12.306287368928063,0.5305811519393481,0.014713826322457102
84.2000000000005,12.34539290385195,0.5334714759540328,0.014218096876429165
85.30000000000052,12.384199189809648,0.5332606119531583,0.015432045689793839
86.40000000000053,12.423158822793475,0.5343321220209019,0.014380354911120996
87.50000000000054,12.461503691264454,0.5377080541324404,0.014901030134884863
88.60000000000056,12.500067586954774,0.5364624134389642,0.014311418407672694
89.70000000000059,12.538598496121896,0.5409179711502746,0.014387077574422147
90.8000000000006,12.576288899584698,0.5436584049853359,0.01433691535585524
91.9000000000006,12.61421140673477,0.5436155235163647,0.014484137583854029
93.00000000000063,12.652084759098235,0.5467520598206028,0.014852321062289064
94.10000000000065,12.690343523544595,0.5506365546718918,0.014916683265740804
95.20000000000066,12.727892360128223,0.5501892189812587,0.014484473754662108
96.30000000000067,12.765002234682266,0.5529320948353058,0.014466013791669674
97.40000000000069,12.803227749576218,0.5579969698706244,0.014467742223007285
98.50000000000071,12.840467723270455,0.5595013894402522,0.01450690363739815
99.60000000000072,12.87819043960043,0.5622162376366655,0.015577425727645533
100.70000000000073,12.915123291295304,0.5655253980165983,0.014476424471123295
101.80000000000075,12.952951006556964,0.5687241280938518,0.014639414346741209
102.90000000000077,12.989896006350103,0.5754960441095719,0.014414925034621717
104.00000000000078,13.027417888292486,0.5789733427806634,0.014470795450207685
105.10000000000079,13.064209414031989,0.5817238854394765,0.014885332920544947
106.20000000000081,13.101589022911485,0.5859127359427907,0.01447968083587492
107.30000000000084,13.138259915653592,0.5907749137332288,0.014525055727975467
108.40000000000084,13.1757108163494,0.5995023616900391,0.01315937517605903
109.50000000000085,13.212432151375921,0.5997036928640118,0.01313440469967464
110.60000000000088,13.249563408017087,0.6043987943271787,0.014484223536439078
111.7000000000009,13.28646241419562,0.6076781981935189,0.014480811786640402
112.8000000000009,13.323692962111581,0.6113147086588251,0.01444138002562445
113.90000000000092,13.360201470409429,0.6180907123681918,0.014469810421202212
115.00000000000094,13.39740641190312,0.621537454024454,0.014469817758415271
116.10000000000096,13.433950774227066,0.6249101590778212,0.014475931598095126
117.20000000000097,13.470946404848993,0.6317659480029194,0.013260906843932663
118.30000000000098,13.507645478793778,0.6344959568651629,0.0142948564703822
119.400000000001,13.544318907702666,0.6398885799545575,0.013714441428716917
120.50000000000102,13.581113967396576,0.6432665497480711,0.013159478433789396
121.60000000000103,13.617449503912155,0.64750504203484,0.013161633370650794
122.70000000000104,13.653576682334748,0.6535565073037467,0.013473134496162498
123.80000000000106,13.690133168476306,0.655875904714615,0.014482663921119965
124.90000000000109,13.726839920321805,0.6626360384787361,0.013865205386794255
126.0000000000011,13.763023710269845,0.6687187517878463,0.014567670541514754
127.1000000000011,13.799138775270556,0.6722649176208793,0.014482619988875456
128.20000000000113,13.835409516770925,0.6742658698872124,0.013644257275134741
129.30000000000115,13.871604699272574,0.679811669935031,0.013159596753785419
130.40000000000117,13.907538423818597,0.683641137677339,0.013159888807328102
131.50000000000117,13.94322398033999,0.6861206335040798,0.013159889022440918
132.6000000000012,13.979767517026197,0.6929809650432566,0.013159888987867685
133.7000000000012,14.015874262925532,0.6969551977146201,0.013159886833820522
134.8000000000012,14.051567745945837,0.7029922485896687,0.013159885846468544
135.90000000000123,14.087243467074831,0.7081184005316317,0.013311304221017117
137.00000000000125,14.123151225607435,0.7109920227019095,0.013119852090940576
138.10000000000127,14.15873324311996,0.7149466964660159,0.013159945893482128
139.2000000000013,14.194170648138781,0.7218958747501814,0.01315998897330184
140.3000000000013,14.22924289013388,0.727353094259621,0.013159859185277067
141.4000000000013,14.265107036201723,0.73233951520492,0.012951789977719397
142.50000000000134,14.300407736696986,0.7393007485357618,0.013163467510210136
143.60000000000133,14.335710366086381,0.7447121229031177,0.013170164448034427
144.70000000000135,14.37130654480444,0.749961881340262,0.013170063725641779
145.80000000000138,14.40685479662654,0.7583565098522443,0.013170063075437444
146.9000000000014,14.441857549976373,0.7654152549743332,0.013170075356034872
148.00000000000142,14.476712222770406,0.7700297619679968,0.013169218458432663
149.10000000000142,14.512254498938916,0.7789703476279124,0.012999952000196213
150.20000000000144,14.547301225096167,0.7863222315316338,0.012182414669085428
151.30000000000146,14.582157094788707,0.7956905565347007,0.012191018770154827
152.40000000000146,14.61735665687767,0.8073850573114236,0.013467855344460489
153.50000000000148,14.652425827106821,0.8162040852383172,0.013489785196754145
154.6000000000015,14.68747706699608,0.8293782020359333,0.013489933531274811
155.70000000000152,14.722038123207923,0.8418070109600002,0.013489932014776329
156.80000000000155,14.756851897240576,0.8571359816213497,0.013489931726364812
157.90000000000154,14.791694915640658,0.8736452803918976,0.013489912235550516
159.00000000000156,14.826681221955699,0.8881711308462351,0.013492319026774613
160.1000000000016,14.86147747236137,0.9064878036547765,0.013133167231426324
161.20000000000158,14.896597503470533,0.924298728713903,0.013160411988320853
162.3000000000016,14.931004053089344,0.9392258705308802,0.013161652705889981
163.40000000000163,14.966035510437967,0.9540266421075713,0.012597134258910181
164.50000000000165,15.000158018455199,0.9624583955903778,0.011843043802564956
165.60000000000167,15.03507828234177,0.9650648655401975,0.012172355294383763
166.70000000000167,15.069686499664513,0.9633677454343188,0.01217004927509624
167.8000000000017,15.104463757000682,0.9531724903410891,0.012169891028437352
168.9000000000017,15.13922564556766,0.9411254246360163,0.01217413701860881
170.0000000000017,15.173652296179833,0.9246947390752389,0.012536975736471945
171.10000000000173,15.207904989508911,0.9116813500652367,0.011857631912921995
172.20000000000175,15.242529061332483,0.8993518349511838,0.011850309846855644
173.30000000000177,15.27738215011104,0.8896010070145699,0.011845511036607803
174.4000000000018,15.311673101924733,0.8813244239401226,0.012562195745215998
175.5000000000018,15.345783294145056,0.8751836047459394,0.012508834568734528
176.6000000000018,15.380206065068784,0.8735913323593492,0.012510018063339956
177.70000000000184,15.414512496819265,0.869686867943659,0.01251001889035308
178.80000000000183,15.448591070396217,0.8669636128457351,0.012510026301241428
179.90000000000185,15.48302931693244,0.8670541350170036,0.012511794898562911
181.00000000000188,15.517013855360421,0.8682487649732661,0.012125476814661695
182.1000000000019,15.551137841727147,0.8688735858618719,0.01053009147063344
183.20000000000192,15.585456463071202,0.8717872289600324,0.01052991263884362
184.30000000000192,15.61962532975349,0.8734682407084141,0.010529405746119824
185.40000000000194,15.653431536588524,0.8769926393876292,0.0108997361166705
186.50000000000196,15.687346176834822,0.8809406432471448,0.010449089149578317
187.60000000000196,15.721485506566404,0.8826820839696928,0.009538720502453302
188.70000000000198,15.754842378387837,0.8850579404733427,0.009541715097216574
189.800000000002,15.78890038867859,0.8886786748849456,0.009486104316049015
190.90000000000202,15.823121609910238,0.892210029689158,0.01085864263589098
192.00000000000205,15.856948924719768,0.8967402949624785,0.01085989944018717
193.10000000000204,15.890927298995283,0.899166850631612,0.010860845295488364
194.20000000000206,15.924745168511672,0.9010212270816951,0.009564423638924513
195.3000000000021,15.95819591228833,0.905095233533036,0.009539810034838059
196.40000000000208,15.992085007016883,0.9100381354605325,0.009540061181870563
197.5000000000021,16.025893636420143,0.9126271360988872,0.009538657012740703
198.60000000000213,16.059545669559267,0.9162589384164345,0.009558151830747708
199.70000000000215,16.093254899785997,0.9185367698606449,0.008897894564257047
200.80000000000217,16.12705269579114,0.9237685199423316,0.008555784087601381
201.90000000000217,16.16080545933767,0.9302812756080965,0.00855010562383729
203.0000000000022,16.194358939349723,0.9296189547800134,0.008550709028109171
204.1000000000022,16.227900295551386,0.9347985654762003,0.009582403052975419
205.2000000000022,16.26180909563942,0.938064590929591,0.00986964242422772
206.30000000000223,16.29520024134084,0.9421650317258699,0.009870119181463188
207.40000000000225,16.328919466204894,0.9488022459969672,0.009870084664707068
208.50000000000227,16.362472850791722,0.9498521844730186,0.009870085035427856
209.6000000000023,16.39619959098104,0.9565610319227762,0.009870079338131887
210.7000000000023,16.42972471439243,0.9586016822063472,0.009870266408710915
211.8000000000023,16.4633135606836,0.9636486978828509,0.00989893439105849
212.90000000000234,16.496837817553615,0.970026314021341,0.009683959299554346
214.00000000000233,16.530611947212943,0.9735522257152325,0.009870022051312155
215.10000000000235,16.56438792422438,0.9802200912816734,0.009870136326871837
216.20000000000238,16.59779941115837,0.9864647853062374,0.009873310561004711
217.3000000000024,16.631555413793667,0.9925117226323148,0.00908037737111167
218.40000000000242,16.665172223829533,0.9986278691166679,0.008558177038968218
219.50000000000242,16.698578551515673,1.005942417844515,0.009491574916069556
220.60000000000244,16.73156331874931,1.0129719785223956,0.00954004048202739
221.70000000000246,16.765741688732653,1.022892155834446,0.009538179022795745
222.80000000000246,16.799324243021537,1.0313703926225604,0.008273754801807254
223.90000000000248,16.832434477901295,1.0409340502417836,0.00823145761219779
225.0000000000025,16.86597567906191,1.0494457728906759,0.008231715305512921
226.10000000000252,16.89972156216192,1.0588629940106762,0.008215643238557835
227.20000000000255,16.93296179140211,1.070739247123344,0.009547398717772104
228.30000000000254,16.966334256500772,1.0835089408452883,0.00889960930387046
229.40000000000256,16.999969005075997,1.09773551856423,0.008879814926264995
230.5000000000026,17.033424692561372,1.1122872917575255,0.007838089897886924
231.60000000000258,17.06689592532938,1.1280910975774994,0.007900673329523045
232.7000000000026,17.10039403499812,1.143870547596329,0.00790011362572729
233.80000000000263,17.133578539076687,1.165485107507211,0.00778782675297407
234.90000000000265,17.166920763376222,1.183923261827991,0.007568156861276432
236.00000000000267,17.200549111470483,1.2071722401852085,0.007567201541778257
237.10000000000267,17.234024607176423,1.2350703280703417,0.006477628849100636
238.2000000000027,17.267609948599954,1.269504407296369,0.006580823303772743
239.3000000000027,17.30132680054538,1.313615979975546,0.006579850906022866
240.4000000000027,17.33433828022594,1.3651551346284208,0.0065819213013544875
241.50000000000273,17.36804980696649,1.4282211597999255,0.006302906304956668
242.60000000000275,17.401514348133734,1.5063290418721769,0.006252539118026146
243.70000000000277,17.434932927172618,1.6001902766049299,0.005799808313179167
244.8000000000028,17.468541537622134,1.7046014038560902,0.00493059888038383
245.9000000000028,17.50226116253886,1.815922217792265,0.004929827381120244
247.0000000000028,17.535565370060272,1.920957671347834,0.004956041718420234
248.10000000000284,17.56905007101447,1.9968902425075366,0.006245401159917119
249.20000000000283,17.602777987837595,2.014072803478146,0.006250004204132242
250.30000000000285,17.635900477592582,1.9784312289266024,0.006250134105021399
251.40000000000288,17.66974940450056,1.8919449798883494,0.006250110230344941
252.5000000000029,17.703391879833564,1.7803488520830275,0.006231681867331584
253.60000000000292,17.736941799546322,1.669976167748822,0.004955735624864843
254.70000000000292,17.77064412015392,1.5687101731112265,0.004930088777604702
255.80000000000294,17.803535094139143,1.4832824570712795,0.004930039346889625
256.90000000000293,17.836717378249126,1.410728068290163,0.004930035239531616
258.00000000000296,17.870125795976023,1.349534079947716,0.00492993712288925
259.100000000003,17.903300078928098,1.2967461083149758,0.0049836509498395465
260.200000000003,17.93679759585914,1.2544730412453362,0.0036055901801144152
261.300000000003,17.969575592880147,1.218150426490974,0.0036069938238463273
262.40000000000305,18.00321465317245,1.188382382344645,0.002918324263672112
263.50000000000307,18.036161239601054,1.165293972601349,0.002959949569582676
264.6000000000031,18.06925497210541,1.1477489139287829,0.0029601238136591768
265.7000000000031,18.10258421646023,1.1330155673289959,0.002952672450541982
266.8000000000031,18.135744226059476,1.1208342971185996,0.004035516008029649
267.9000000000031,18.169027686002096,1.1095083592938675,0.003624073019859342
269.0000000000031,18.202047544079594,1.1033141232827672,0.00362033598215028
270.10000000000315,18.23552817187602,1.0966823931366894,0.00361789340982277
271.2000000000032,18.26864799780425,1.0915817105087193,0.0026260894544432034
272.30000000000314,18.301767687931516,1.0898044357607561,0.0013124010050109547
273.40000000000316,18.334933102183054,1.08671115525061,0.001302176065138383
274.5000000000032,18.36824520195082,1.0866070408787774,0.0026629940917750616
275.6000000000032,18.40145039547048,1.0845112142972695,0.002630498380113089
276.70000000000323,18.434603672663076,1.0860039059558482,0.002630163339919722
277.80000000000325,18.46797853664665,1.083871981051834,0.002630173077156961
278.9000000000033,18.50116149353275,1.0830419512326328,0.0026301730004880675
280.0000000000033,18.534439189752227,1.0835218940351197,0.002630173010999215
281.1000000000033,18.567808292975396,1.0837833940686388,0.0026301722546411277
282.20000000000334,18.6010407974753,1.0824106561296445,0.0026301586866934734
283.30000000000337,18.63443064141841,1.083954555825501,0.0026361448739149473
284.40000000000333,18.667605312697624,1.0848181984384162,0.0017843504442058844
285.50000000000335,18.700907886807244,1.083966747084087,0.0009782575098484791
286.6000000000034,18.73414353439279,1.084315726370009,0.0009800928277328147
287.7000000000034,18.76738543976669,1.0878774825886366,-0.0003894053806887676
288.8000000000034,18.80063179538888,1.0893992454064225,-0.0003296251117759219
289.9000000000034,18.83395207149933,1.0893372408219892,-0.000328971029152747
291.0000000000034,18.867359112759218,1.089147769686979,0.0009834860022812641
292.10000000000343,18.900673227902328,1.0914940352045701,0.0009800402814659215
293.20000000000346,18.934175176722196,1.0934014733422386,0.0009800860184512317
294.3000000000035,18.967210399622846,1.0931246410203461,0.0009800860142723522
295.4000000000035,19.000583344108772,1.094850515264481,0.0009800861647843995
296.5000000000035,19.0339259986185,1.0942573681965126,0.0009800196396079208
297.60000000000355,19.06760944424026,1.0958983659871315,0.000983824861704452
298.70000000000357,19.10072375851621,1.095295617276212,-0.0003203896412702356
299.8000000000036,19.134129796694502,1.0945827935428434,-0.0002906520826351233
300.9000000000036,19.167572043011397,1.0984244147200737,-0.0016754809497365741
302.0000000000036,19.2008304149812,1.0997871485080306,-0.001641272208408484
303.1000000000036,19.23409829104478,1.101696888686007,-0.002665074969158354
304.2000000000036,19.26750755010758,1.1021553720616515,-0.0037050690775823902
305.30000000000365,19.300824503984334,1.1014098155316985,-0.004283846410606529
306.4000000000037,19.334325863086157,1.105197201276899,-0.004279964073422793
307.5000000000037,19.367680309318583,1.107569732329797,-0.004279956337178259
308.60000000000366,19.40096381025568,1.1063590985996339,-0.004279948837289105
309.7000000000037,19.43422004926471,1.1073012280913257,-0.004280571402807354
310.8000000000037,19.46785635443017,1.1082436777775815,-0.004291575839943551
311.90000000000373,19.50119424385709,1.1102714840319259,-0.004585491996160762
313.00000000000375,19.534453229693778,1.1115952318093334,-0.004600047484449199
314.1000000000038,19.567854249346254,1.114851531179932,-0.0045998331493106726
315.2000000000038,19.60156723846581,1.1146935691945643,-0.004600356746146783
316.3000000000038,19.634966948790947,1.1154551098923273,-0.00451132402707799
317.40000000000384,19.66814167947691,1.1141311914051584,-0.005875875190754609
318.5000000000038,19.701563264257455,1.1169418953277876,-0.007252615783626126
319.60000000000383,19.735256346843787,1.1167300817511856,-0.007264541196445595
320.70000000000385,19.768644300607725,1.119490182052928,-0.005874030684843934
321.8000000000039,19.8021238049678,1.1200425516988481,-0.007060945060055612
322.9000000000039,19.83546802180249,1.1207443251678442,-0.007240539086948328
324.0000000000039,19.869118493432097,1.1195919172705198,-0.00722078192881126
325.10000000000394,19.902754480750307,1.1174554745562457,-0.008233521541218813
326.2000000000039,19.936144738899543,1.1197811571139693,-0.008229714814904199
327.30000000000393,19.969790545887058,1.1183320289199863,-0.008233645887236296
328.40000000000396,20.003219374115858,1.1176464159063444,-0.009178699229460463
329.500000000004,20.03668966752133,1.1176217653463814,-0.009440566364198766
330.600000000004,20.070338045392607,1.1188665696535476,-0.009539543444346155
331.700000000004,20.104016550815647,1.1176025294602399,-0.009730628814535347
332.80000000000405,20.137448580723444,1.1148189622661633,-0.010852738974896248
333.90000000000407,20.170955363241077,1.1129418193242409,-0.010859382527074413
335.0000000000041,20.204845703698876,1.113893969969491,-0.01081130377630135
336.10000000000406,20.238365230579667,1.1119205948440891,-0.010559708167743764
337.2000000000041,20.271897015421025,1.110467881340762,-0.010916687753900867
338.3000000000041,20.30548973261277,1.109769306341554,-0.010879277456167902
339.4000000000041,20.33886599335094,1.1053466100333487,-0.011525918026155768
340.50000000000415,20.372822577687096,1.10611899461576,-0.011480792530532025
341.6000000000042,20.40669825935839,1.107851861459705,-0.012866559284533174
342.7000000000042,20.44025741844234,1.1048622036068072,-0.012829781886785518
343.80000000000416,20.473796199190758,1.1056666359532688,-0.012746893724388642
344.9000000000042,20.507643224368227,1.1067906838244088,-0.01516167746206154
346.0000000000042,20.54035690864571,1.1048532845405066,-0.0151407513734374
347.10000000000423,20.575214886405153,1.1047736191391215,-0.016199902340114924
348.20000000000425,20.608747252776464,1.1056811149689723,-0.016450761956666504
349.3000000000043,20.642595570276956,1.1047975728571662,-0.016457157866228034
350.4000000000043,20.67648775845697,1.1039871658107236,-0.01760253487981167
351.5000000000043,20.710000000000132,1.1040317355176705,-0.017983009598415922
352.60000000000434,20.743812635675546,1.10415698154602,-0.01805671379569862
353.7000000000043,20.777672291459627,1.101938520922795,-0.01956113338692278
354.80000000000433,20.81137047549275,1.103190241884091,-0.021174327241713087
355.90000000000435,20.845192658570866,1.0996781974384262,-0.02119443568265389
357.0000000000044,20.87931023913839,1.1007490128147526,-0.02247548528436294
358.1000000000044,20.912998995404642,1.102801495941099,-0.02247562698987382
359.2000000000044,20.946696957828657,1.1027151389764351,-0.023969828992083997
360.30000000000445,20.98036839821716,1.1034939130698769,-0.02514818813596742
361.4000000000044,21.014429046591406,1.1034922319324212,-0.026174352795851785
362.50000000000443,21.048620145016475,1.101324656558068,-0.027144704922898555
363.60000000000446,21.082214773059416,1.1028772517848244,-0.028718731492983096
364.7000000000045,21.11646978133467,1.1033501140086033,-0.029992706662516078
365.8000000000045,21.150252587311225,1.1015787282818301,-0.031366104123344396
366.9000000000045,21.183988604454186,1.1011878465794036,-0.03276189546449304
368.00000000000455,21.218094368650792,1.1026204731775735,-0.03419097770129875
369.10000000000457,21.25226122839615,1.1007505363269894,-0.03508416048102925
370.2000000000046,21.286094402484302,1.1029920927778545,-0.036300039896282055
371.30000000000456,21.320063186188854,1.1019146617251767,-0.03718177037947923
372.4000000000046,21.354404135892544,1.1031674051289926,-0.03849980959709676
373.5000000000046,21.38818640983557,1.106600614622907,-0.04032679746732759
374.6000000000046,21.422164294719366,1.1087371394918246,-0.04291361819456929
375.70000000000465,21.45620341855101,1.1055337413997777,-0.045055279868589704
376.8000000000047,21.49028674508494,1.1087803695488538,-0.04729189464935413
377.9000000000047,21.524344515042074,1.1113036306359279,-0.04960285119075181
379.00000000000466,21.558224017251245,1.1139811626162481,-0.05276010584215651
380.1000000000047,21.59251336382899,1.114514574584407,-0.054838120009622404
381.2000000000047,21.626168018573622,1.1178935640859535,-0.05764880421787799
382.30000000000473,21.660342633365808,1.1175063437555097,-0.05970298275455699
383.40000000000475,21.694546913693916,1.12175018146865,-0.06286643177961837
384.5000000000048,21.72836946949434,1.126273887900845,-0.06471906991407783
385.6000000000048,21.762904574617234,1.1301705246923321,-0.06641990083208915
386.7000000000048,21.79692754672807,1.1358434998574045,-0.06959473044174347
387.80000000000484,21.831164707898743,1.1389454969656332,-0.07287019528637417
388.9000000000048,21.864726790648067,1.144358150532078,-0.07649142503768269
390.00000000000483,21.899193510585906,1.1451985676606449,-0.07899459103201556
391.10000000000485,21.933263697236438,1.1509837787247834,-0.08258598131594175
392.2000000000049,21.967579555571344,1.1573998042796807,-0.08656161203591006
393.3000000000049,22.001754663875825,1.161971889808643,-0.09010550892266389
394.4000000000049,22.035824857199373,1.1671760535877629,-0.09456406834145836
395.50000000000495,22.070148993485976,1.1722474332150308,-0.09895618180375498
396.6000000000049,22.104198551387228,1.1777366349025677,-0.10401822292990959
397.70000000000493,22.138539916995548,1.1849781556791117,-0.1099789991295439
398.80000000000496,22.172322288813405,1.1885671177798947,-0.11464149825925452
399.900000000005,22.20714077138737,1.1983419503585377,-0.12030599343919057
401.000000000005,22.24117770902253,1.2019876520033657,-0.12630717952569404
402.100000000005,22.275523308954433,1.2111098442761383,-0.13103709364827187
403.20000000000505,22.30966034731528,1.2185349062617052,-0.13735699378706512
404.30000000000507,22.344171198963693,1.224842598334429,-0.14504589007303315
405.4000000000051,22.378635517195452,1.2324304017327519,-0.15067434835381155
406.50000000000506,22.41286366113432,1.2377386520552185,-0.15738043250387657
407.6000000000051,22.447171206221636,1.247257512194676,-0.1650508969706297
408.7000000000051,22.48121034244101,1.2531153936598756,-0.17233225026827714
409.8000000000051,22.515657224654074,1.2604103063184333,-0.1809772531898104
410.90000000000515,22.550157543947268,1.267487449136421,-0.18936918770077105
412.0000000000052,22.584530811617576,1.2752337894640138,-0.1975271308518427
413.1000000000052,22.61923088351055,1.2848334457593826,-0.20634563394657546
414.20000000000516,22.653365452955832,1.2914995249900154,-0.21542022736228494
415.3000000000052,22.687719701120592,1.2970217694985686,-0.22471893054199432
416.4000000000052,22.721992870194264,1.3077979379910294,-0.23442851602118386
417.50000000000523,22.756681610191475,1.318084766042224,-0.2454762563003725
418.60000000000525,22.790931757580356,1.3273953702813426,-0.2557083200253252
419.7000000000053,22.82541463177618,1.3342628379625736,-0.26661223086380215
420.8000000000053,22.860031404266245,1.346560590122325,-0.2789388847286203
421.9000000000053,22.89443001572036,1.3596299509485277,-0.2908862924743829
423.00000000000534,22.929072401051297,1.3724421983967232,-0.3028083623401252
424.1000000000053,22.963424387140122,1.3858369393361292,-0.3164419834012615
425.20000000000533,22.998010199869768,1.3994204936213253,-0.3293920673077406
426.30000000000535,23.032563896101628,1.4111053937026465,-0.34245985643704024
427.4000000000054,23.06694669917267,1.4290932800112293,-0.35759612740903446
428.5000000000054,23.101831111807094,1.4435609896066994,-0.3727010052098616
429.6000000000054,23.13612163743693,1.4615140458231743,-0.38758746964292357
430.70000000000545,23.170823779943255,1.483289298291513,-0.4033109736747207
431.8000000000054,23.2052460961587,1.5000552404668386,-0.42077163194852885
432.90000000000543,23.239873701283503,1.5200794638603137,-0.4389019946204482
434.00000000000546,23.274781855061196,1.538195537541731,-0.45673039759987955
435.1000000000055,23.30948725190592,1.557612319180767,-0.4753733660751345
436.2000000000055,23.343563402011338,1.5734177752382708,-0.49442762297177145
437.3000000000055,23.378595637379643,1.5931998280339408,-0.5148110608458589
438.40000000000555,23.41317947817354,1.6091617524002242,-0.5359709875895238
439.50000000000557,23.447899781962906,1.6213747473856042,-0.5586566682889429
440.6000000000056,23.482562752307278,1.6324253824104982,-0.5819914575755178
441.70000000000556,23.51724466385891,1.6492480242374605,-0.6059234452102156
442.8000000000056,23.55199310132195,1.6595033998289495,-0.6290249803891914
443.9000000000056,23.586987932178832,1.6750453594671333,-0.6544457917256383
445.0000000000056,23.621552763108,1.6883391878697351,-0.6804394454105078
446.10000000000565,23.65638832521632,1.7054180982525153,-0.7067988444811601
447.2000000000057,23.690830486971,1.7169139062012224,-0.7340408209863258
448.3000000000057,23.72576844415428,1.7368420000976332,-0.7630158344362821
449.40000000000566,23.76092474240953,1.752274900783053,-0.7924810892761176
450.5000000000057,23.795303264182156,1.767576708041472,-0.8207664989904613
451.6000000000057,23.8300631307378,1.7888056235702106,-0.850137118310168
452.70000000000573,23.864795184118424,1.8041661515834746,-0.8810561864254192
453.80000000000575,23.899440213268964,1.822683379648923,-0.9125214979572003
454.9000000000058,23.93484654945986,1.840925854069416,-0.9456399432648888
456.0000000000058,23.969388787296246,1.8564434470205438,-0.9801122661073314
457.1000000000058,24.00446140008996,1.8716895410501753,-1.015753376914446
458.20000000000584,24.039510176830213,1.8864682572564462,-1.0533174266313918
459.3000000000058,24.074394794627725,1.894224449958387,-1.089534650753865
460.40000000000583,24.10894494867803,1.899701003737312,-1.1248722401918259
461.50000000000585,24.14411876742805,1.9028392102470666,-1.1611673361948172
462.6000000000059,24.17881699193604,1.899482219124136,-1.1991196457531714
463.7000000000059,24.21371625786202,1.8914599114079222,-1.237740503410211
464.8000000000059,24.248557279224013,1.8803788616402954,-1.2767622726501933
465.90000000000595,24.283927614635378,1.8668632453447762,-1.317380511227093
467.0000000000059,24.318679635251197,1.8438185656600354,-1.3560799288598222
468.10000000000593,24.353550822916596,1.81596110838792,-1.3928049682258905
469.20000000000596,24.388441910497107,1.7851856854349821,-1.4277187416527592
470.300000000006,24.423402654591104,1.7549435266673297,-1.462597172664612
471.400000000006,24.458351144482158,1.7157956529470033,-1.495749202550936
472.500000000006,24.493344315375538,1.67394635248338,-1.526068512505589
473.60000000000605,24.52828744423199,1.62611215398611,-1.555065493525687
474.70000000000607,24.563172137253275,1.5799998266230855,-1.5806303138434084
475.8000000000061,24.597933594301754,1.5274751375808067,-1.6035049845231355
476.90000000000606,24.63277461725422,1.4695530849413108,-1.6230367226396285
478.0000000000061,24.667817033657883,1.4099966677587166,-1.6398386611759963
479.1000000000061,24.70292775819487,1.3540280101488822,-1.6557645620949342
480.2000000000061,24.73791826649058,1.2971343696932265,-1.6702474783747845
481.30000000000615,24.77265426551859,1.2504445734410177,-1.6841266814211013
482.4000000000062,24.807962307616478,1.2048467774590725,-1.6974068796287467
483.5000000000062,24.842872044192223,1.1634195736936792,-1.7088591034823528
484.60000000000616,24.87782752000186,1.1287900570279663,-1.720389964671972
485.7000000000062,24.912908321472056,1.0974960668269127,-1.731158847126388
486.8000000000062,24.947823306281183,1.0697339618412227,-1.7424926090689308
487.90000000000623,24.983235288138257,1.045750924720299,-1.752517038401606
489.00000000000625,25.017919989255777,1.0293244242854367,-1.762761983996168
490.1000000000063,25.052948101350403,1.0173902814364524,-1.771690329648946
491.2000000000063,25.088077071948085,1.0053530870685952,-1.781122685897158
492.3000000000063,25.122778646798054,0.9961967491159023,-1.7913426658000384
493.40000000000634,25.15830198331026,0.9856740069313641,-1.802876665110663
494.5000000000063,25.193248756262424,0.9773065622103014,-1.8127337889704487
495.60000000000633,25.228394335424685,0.9655162179372325,-1.8228555933071622
496.70000000000636,25.263508650309916,0.9579461791329114,-1.8334721593303653
497.8000000000064,25.298741827497334,0.9437829230552257,-1.8433829175870327
498.9000000000064,25.33362573726018,0.9233595003666011,-1.8526398156184771
500.0000000000064,25.368868992233086,0.8941853267891302,-1.8615879243268036
501.10000000000645,25.403920893979826,0.8501645530420125,-1.8689249486238966
502.2000000000064,25.439235013316647,0.7976403629523432,-1.8760983141750045
503.30000000000643,25.474240418083653,0.7409623414334159,-1.8843110009417652
504.40000000000646,25.509737774354797,0.682641837049101,-1.8879992882929235
505.5000000000065,25.544539517410964,0.6296968541522183,-1.8929666586964737
506.6000000000065,25.579810372843518,0.5776661007902262,-1.8971108205219531
507.7000000000065,25.615166430504665,0.53761762122741,-1.8990688670384017
508.80000000000655,25.650155359955054,0.5036888844121608,-1.9006572018732517
509.90000000000657,25.6855684663846,0.47959118785421495,-1.9035529525050312
511.0000000000066,25.72038236635771,0.4566130742102299,-1.9059455615414693
512.1000000000065,25.75608835457783,0.4413186241577485,-1.908515700358893
513.2000000000066,25.791419693719106,0.42882612955874144,-1.910336410475542
514.3000000000065,25.826471430977346,0.41374312979675465,-1.9118028693293891
515.4000000000067,25.862121515371342,0.40789075013958986,-1.912277004657629
516.5000000000066,25.897157836438804,0.4017635214927511,-1.912283359188328
517.6000000000067,25.932548072373095,0.3953298671670642,-1.9136369720622146
518.7000000000066,25.967878041283623,0.3922545078243109,-1.914977957493528
519.8000000000067,26.00351118125265,0.3900080193467814,-1.9164092881541968
520.9000000000067,26.038730586059952,0.38671123184823,-1.9171721738903167
522.0000000000067,26.074355663587337,0.38327801318822896,-1.9200176747155844
523.1000000000067,26.10946554029334,0.38581806405443775,-1.920679215440976
524.2000000000068,26.144654375605285,0.38477429378318595,-1.921703476754772
525.3000000000068,26.180228110449526,0.3840164077901216,-1.9223828099341214
526.4000000000068,26.215968170683148,0.38269217088121454,-1.9244988744217348
527.5000000000068,26.251237331370856,0.38410222236257496,-1.9262594163967384
528.6000000000068,26.28657419122379,0.3838419126694972,-1.9263161008412535
529.7000000000069,26.322290178322977,0.38571114690172825,-1.9272996405018121
530.8000000000068,26.357447125381178,0.3849271566031218,-1.9262231615025223
531.9000000000069,26.392918091835437,0.39147558755971135,-1.927512591059196
533.0000000000068,26.428470169809508,0.3920799814956637,-1.9283598694266297
534.100000000007,26.464042799234203,0.39175777816503654,-1.9287775130408251
535.2000000000069,26.499566295089682,0.39290625382858124,-1.9312531109607185
536.300000000007,26.535010628567907,0.3944228807524275,-1.9323173537005591
537.4000000000069,26.570819816037698,0.3970558620541076,-1.93277173904505
538.5000000000069,26.606273386910388,0.3987718916041265,-1.9341430109577795
539.600000000007,26.641747555855257,0.40223233515434265,-1.9351394203557082
540.700000000007,26.67744527343503,0.40431650397761576,-1.9348302384547404
541.800000000007,26.713026214988577,0.40396239284754953,-1.9354126737404345
542.900000000007,26.74863347375388,0.40639289413550195,-1.9367483078346672
544.000000000007,26.784222398895547,0.40879022792224395,-1.936735595094928
545.1000000000071,26.819614521088248,0.41507515753259927,-1.9384657811582044
546.2000000000071,26.855157666801478,0.4167629253435736,-1.9413393840544482
547.300000000007,26.89102369210227,0.4205334099203797,-1.9433170108754048
548.4000000000071,26.9262774373838,0.4216274536976061,-1.9443118776316781
549.500000000007,26.962196990214125,0.42466870880620666,-1.9446253067757664
550.6000000000072,26.997595700473347,0.4275278712769657,-1.945985890440316
551.7000000000071,27.03339070372559,0.429471352939951,-1.9459402694325618
552.8000000000072,27.06927180853507,0.43318173593864095,-1.9462133331271403
553.9000000000071,27.104932454242526,0.4341990203968842,-1.9472890466331072
555.0000000000072,27.140580354948664,0.4368093340263983,-1.9485836745878298
556.1000000000072,27.175873080648774,0.43751766775180556,-1.94968815174995
557.2000000000072,27.211735770257544,0.43884574593311987,-1.9514056370126878
558.3000000000072,27.247461487714283,0.4434785441938547,-1.952605802372943
559.4000000000073,27.283346249307385,0.4430196955560475,-1.9541677618237716
560.5000000000073,27.319157938233882,0.44567201714003435,-1.9556158168314677
561.6000000000073,27.354751621110506,0.4461900256666538,-1.9568406469412507
562.7000000000073,27.390358322498674,0.4470682145236391,-1.9582274489321485
563.8000000000073,27.426078196367992,0.4498465491976953,-1.95920504120214
564.9000000000074,27.462033292604012,0.44712746416474625,-1.9595209951912285
566.0000000000074,27.497856887538518,0.4484495097085519,-1.9610733266288587
567.1000000000074,27.53368380429539,0.4498589893592655,-1.962699280549534
568.2000000000073,27.569389609293705,0.44934027858852676,-1.9631034697904508
569.3000000000073,27.60529701268343,0.45097386801058503,-1.964340275393036
570.4000000000074,27.64092978424172,0.4491738748807914,-1.9660915578114746
571.5000000000074,27.67676460839644,0.45512177201475934,-1.9682578015860432
572.6000000000074,27.71270144201167,0.45562170069446406,-1.9697814288219306
573.7000000000074,27.748845769449403,0.4583180943722027,-1.9712946876551762
574.8000000000075,27.78454743177977,0.4582445022624193,-1.9727543644253152
575.9000000000075,27.82050356995014,0.4614849516704349,-1.9742350069241925
577.0000000000075,27.856437598044888,0.4634701735286013,-1.9758727443942279
578.1000000000075,27.892045882975598,0.465393807772863,-1.977359860276236
579.2000000000075,27.92839484185015,0.46603132745773124,-1.9788310368230326
580.3000000000076,27.96416133132767,0.46715245544517403,-1.9791979713978827
581.4000000000076,28.000227684731513,0.4708026092419568,-1.9813922556889705
582.5000000000076,28.035879279799993,0.4759346244401166,-1.9832585818547117
583.6000000000076,28.07202588025024,0.47821631656215935,-1.9850273598682935
584.7000000000077,28.107708289358676,0.4789848709715536,-1.9866259574420129
585.8000000000077,28.143634513112755,0.48324640264111673,-1.9885273989083951
586.9000000000076,28.180063629474105,0.487557338298815,-1.9910272751713167
588.0000000000076,28.21581586351178,0.4929188022829032,-1.9931691248080192
589.1000000000076,28.252024267261948,0.49522114044109466,-1.9947045158618815
590.2000000000077,28.287648885272695,0.5027699654739006,-1.997897089220835
591.3000000000077,28.323862559135645,0.5096335444428126,-1.9996379678407394
592.4000000000077,28.359673861074807,0.5190271115753853,-2.001089132766741
593.5000000000077,28.39591190613402,0.5228729129589498,-2.0040150077209926
594.6000000000078,28.43187011442678,0.5318497817088632,-2.0065699765394083
595.7000000000078,28.468058337131918,0.5387427119052823,-2.009881965658649
596.8000000000078,28.50403932217435,0.5476071084698093,-2.0128746747811093
597.9000000000078,28.539806045163473,0.5569625036423402,-2.01557021688604
599.0000000000078,28.575978434310915,0.5620723315295084,-2.019858488436899
600.1000000000079,28.612525858439096,0.5694936005301212,-2.0228374848552395
601.2000000000079,28.64839436862378,0.5775522635103276,-2.025196713517364
602.3000000000079,28.684239075886754,0.5878409196510548,-2.0293838988968154
603.4000000000078,28.72028908510147,0.5918953511166802,-2.032956225697619
604.5000000000078,28.75631836758859,0.6021301349912971,-2.0369678027389653
605.6000000000079,28.792541550188126,0.6102823791936132,-2.039118179924614
606.7000000000079,28.828793792205747,0.6221187109108102,-2.0426442445737565
607.8000000000079,28.864951142866342,0.6365713478127679,-2.04633522241977
608.9000000000079,28.900918754165247,0.6483145268188366,-2.049241560159333
610.000000000008,28.93702981820718,0.660559223736803,-2.053417401982477
611.100000000008,28.97345393603553,0.6703875805905919,-2.056581470624417
612.200000000008,29.009536479731672,0.6793752332957417,-2.061044305584
613.300000000008,29.045499669539442,0.6808007567257892,-2.0667234102844025
614.400000000008,29.081466379359533,0.6877492586218223,-2.0717551825183076
615.5000000000081,29.11772560975501,0.6901923270340888,-2.0780238391899695
616.6000000000081,29.154111407839967,0.6954439986474705,-2.0826300936007627
617.7000000000081,29.19033579531513,0.6919124748858483,-2.0882421559469555
618.8000000000081,29.226298159987387,0.6965760565013821,-2.095251163246326
619.9000000000082,29.262374415941018,0.6963096344831614,-2.1014721505432568
621.0000000000082,29.29864826354879,0.6986711697492307,-2.1072449158438955
622.1000000000081,29.3349417103327,0.6969773305740321,-2.1134193124095093
623.2000000000081,29.371195549591707,0.7012406155407689,-2.1168308553686663
624.3000000000081,29.407230733232414,0.7037899973073354,-2.1231840412511787
625.4000000000082,29.443365344066073,0.7085910442632501,-2.133990090459231
626.5000000000082,29.47923571298201,0.7107872357788239,-2.1412320908589844
627.6000000000082,29.51587496859832,0.7087667294411597,-2.1486396876064067
628.7000000000082,29.55204061679032,0.7143899332799015,-2.155659343700803
629.8000000000083,29.588285894352545,0.7140171680476741,-2.1636409293822956
630.9000000000083,29.624273219103788,0.7150816198591783,-2.1701341465115487
632.0000000000083,29.660431589574646,0.7170587351147142,-2.1779218604051644
633.1000000000083,29.696800364904945,0.7191689410066036,-2.184366430397847
634.2000000000083,29.73306605652154,0.7196990106367229,-2.1920493530192875
635.3000000000084,29.76911456557306,0.718551527080376,-2.1995959796000726
636.4000000000084,29.80565366593774,0.7184413080284733,-2.2068703251162276
637.5000000000084,29.841834789326246,0.7134310199013174,-2.213987870015406
638.6000000000083,29.878229919660193,0.7106976737121884,-2.2195200465389258
639.7000000000083,29.91427317063223,0.7132986732509137,-2.2250318077759905
640.8000000000084,29.95091935689717,0.717699862583232,-2.2286191604450227
641.9000000000084,29.987004181708055,0.7284698186201313,-2.2339394337380205
643.0000000000084,30.023132714087286,0.7329154892490295,-2.2375324240974823
644.1000000000084,30.05959798576677,0.7292766732856091,-2.2389014186905887
645.2000000000085,30.096320544011185,0.7218018630485941,-2.2409810549448523
646.3000000000085,30.13255136873363,0.7134389458302985,-2.241846178011122
647.4000000000085,30.168737539290525,0.7117060470948537,-2.242645655943502
648.5000000000085,30.205139066959326,0.7147180108956133,-2.2436812015178553
649.6000000000085,30.24137257510026,0.724631817606094,-2.2448391011802595
650.7000000000086,30.277921704962523,0.7380827962533227,-2.2461345019443764
651.8000000000086,30.314205497186624,0.7527420159016187,-2.2473674351753314
652.9000000000086,30.350365033547877,0.7707270786324827,-2.2488246891522508
654.0000000000086,30.386738536282078,0.7924128258456036,-2.249824702969325
655.1000000000087,30.423300080551716,0.8058368983865405,-2.2511495360614266
656.2000000000087,30.45977305324037,0.823912450164273,-2.2524919702822057
657.3000000000086,30.495906618087066,0.8380752633304658,-2.2541906045212827
658.4000000000086,30.532380821258037,0.85494677130544,-2.2563123291004263
659.5000000000086,30.568597164035555,0.8709847890443911,-2.256794443475065
660.6000000000087,30.604930368951983,0.8885376842039308,-2.257898497424608
661.7000000000087,30.64151215902053,0.9035693955313153,-2.2587332874481785
662.8000000000087,30.67792936119648,0.9214271568337224,-2.260501335804069
663.9000000000087,30.714112246561616,0.9422730021894958,-2.262170299874187
665.0000000000088,30.750545531354327,0.9598144277141731,-2.2640508682168035
666.1000000000088,30.786875488068418,0.9772061569727235,-2.266030888676485
667.2000000000088,30.823114438740536,0.9982771705294553,-2.2672377334008775
668.3000000000088,30.85951200882937,1.0170656199538968,-2.26890918328942
669.4000000000088,30.89553020855655,1.0385133937690099,-2.2708502060217555
670.5000000000089,30.932336781872092,1.0599837992354075,-2.27286876608286
671.6000000000089,30.96871630668819,1.083503987446106,-2.2751150507061166
672.7000000000089,31.00488639705529,1.1084645112284264,-2.276604517063601
673.8000000000088,31.041480588537212,1.1283184071081669,-2.2780587621802155
674.9000000000088,31.077824830948984,1.1570138802228453,-2.2800386299964712
676.0000000000089,31.114406336447786,1.1799709340782223,-2.282682214704991
677.1000000000089,31.15072340884733,1.2042633302287853,-2.2842282742052373
678.2000000000089,31.18684788359555,1.2332784939087102,-2.2859694730069293
679.3000000000089,31.223325802340206,1.2608144288375311,-2.287824643755356
680.400000000009,31.26015329814695,1.2907278599890462,-2.291016875409369
681.500000000009,31.29639499670925,1.3244003878442663,-2.2936552422815866
682.600000000009,31.332608220558733,1.3540960220079215,-2.295153717198625
683.700000000009,31.3694458647073,1.3897436291825898,-2.2966893404637263
684.800000000009,31.405812432675635,1.4206641559578292,-2.2996931329684474
685.9000000000091,31.442345396533277,1.4612884664019843,-2.302067012231768
687.0000000000091,31.478616300110257,1.4962618170858852,-2.3052349826474785
688.1000000000091,31.515160011839733,1.5383694163394157,-2.3085375089125573
689.2000000000091,31.551505194395084,1.5816376831210524,-2.311194713678903
690.3000000000092,31.588087380233333,1.6220227022129405,-2.3143670967222825
691.4000000000092,31.624811678104468,1.6669409470472054,-2.316837182613122
692.5000000000091,31.660796038169792,1.7159851709707885,-2.3202269187038107
693.6000000000091,31.697613033462506,1.7637893775239957,-2.3235339463531357
694.7000000000091,31.73417084960663,1.8111355596957464,-2.327182166271588
695.8000000000092,31.77063200916366,1.8647905335710186,-2.330808408014556
696.9000000000092,31.807484802405767,1.9129066029309323,-2.3352007525550285
698.0000000000092,31.843980921168075,1.9682733498079683,-2.3396096011235623
699.1000000000092,31.880298826220944,2.0229472776077193,-2.3436985796356415
700.2000000000093,31.916873301930767,2.0724895570451762,-2.34695356195904
701.3000000000093,31.95387625399828,2.1304631549703874,-2.3502923808907785
702.4000000000093,31.990466641802843,2.185108129326725,-2.3547770223750013
703.5000000000093,32.02676892886214,2.241572788567246,-2.360417299908075
704.6000000000093,32.063426067878204,2.302484601111416,-2.3650603671606016
705.7000000000094,32.10016456380405,2.358749255867104,-2.3699070676669436
706.8000000000094,32.13669024495446,2.418200278203705,-2.3745899302174873
707.9000000000094,32.17328867806542,2.4767301750422837,-2.3782175091426545
709.0000000000093,32.20983219009786,2.5388383213486945,-2.38301775760274
710.1000000000093,32.246569423570364,2.6012897055690423,-2.3887079792883528
711.2000000000094,32.28315775708808,2.66155720461501,-2.3950335849354283
712.3000000000094,32.319933653342474,2.724660485178895,-2.399810580039306
713.4000000000094,32.35665872008067,2.788409338178713,-2.4047538409077154
714.5000000000094,32.39312580208725,2.8541370438619373,-2.4101781998838847
715.6000000000095,32.42976260773856,2.923198808262638,-2.417110922536158
716.7000000000095,32.466554367883525,2.9884813158213235,-2.4216924625457477
717.8000000000095,32.5033206022272,3.058141981424851,-2.427812721802373
718.9000000000095,32.54030321417902,3.12368861217833,-2.4336498776069306
720.0000000000095,32.57687682791802,3.1960585000918864,-2.440475004489529
721.1000000000096,32.61350113177681,3.265386407989144,-2.44687343196545
722.2000000000096,32.65023637996821,3.3343590703698816,-2.453509377683447
723.3000000000096,32.68702425815795,3.4101120222917536,-2.4598519689486227
724.4000000000096,32.724008995833145,3.480660985756949,-2.4669814618283534
725.5000000000097,32.7599653994229,3.5510359382184844,-2.473416882307048
726.6000000000097,32.797464814044,3.625143106131853,-2.4793458134523085
727.7000000000096,32.83427836749518,3.698232922773863,-2.4873129439138846
728.8000000000096,32.87087649515494,3.772129009095529,-2.495152240758774
729.9000000000096,32.90746718693705,3.8460208183020317,-2.502700810580926
731.0000000000097,32.944455547433144,3.920266249408865,-2.511169849343334
732.1000000000097,32.98127444126461,3.997305224938019,-2.5199585633692716
733.2000000000097,33.0178850876081,4.071580211871925,-2.52811800206249
734.3000000000097,33.054817218981135,4.149496115959777,-2.537806820150574
735.4000000000098,33.09188561723129,4.22453424167941,-2.5466132455817965
736.5000000000098,33.128857085128864,4.301801223490995,-2.5534432487188656
737.6000000000098,33.16544282592042,4.380011045180071,-2.5622915376610433
738.7000000000098,33.202516795369384,4.456535048702072,-2.571836120237695
739.8000000000098,33.23897731912753,4.527696538243502,-2.580309569465246
740.9000000000099,33.27596078136793,4.602232026063502,-2.5890214949925916
742.0000000000099,33.312692029115055,4.673579109292879,-2.598572304017443