File: 01_Data/Bamboo_Rug_Fabric/STA/N2/30K_min/Bamboo_Rug_Fabric_STA_N2_30KData_220126_R3.csv
##Temp./Â°C,Time/min,DSC/(mW/mg),Mass loss/mg
49.0,10.494572968527638,0.02318558185592101,-0.02459616179608526
50.20000000000002,10.715137126129965,0.09541695845915787,-0.02448221743511869
51.400000000000034,10.846670000000005,0.14960023785090193,-0.025290733763624118
52.60000000000005,10.949785174498901,0.19884001625941716,-0.024982030563028612
53.80000000000007,11.036930672950717,0.24163607266589493,-0.024679796268114007
55.000000000000085,11.11510398188509,0.2829522240085431,-0.02534978942907795
56.2000000000001,11.185689069670843,0.31772756513467454,-0.0254310083819127
57.40000000000012,11.252075621412814,0.34972109669344786,-0.0253278272165538
58.600000000000136,11.313815609119859,0.38296479344089257,-0.02466635519396032
59.80000000000015,11.372668909136516,0.40974821122124944,-0.025336607696834434
61.00000000000017,11.429284299294997,0.43840850130199677,-0.025968068229396568
62.20000000000019,11.483983427940942,0.4628313898385183,-0.025435063795204993
63.400000000000205,11.534342364576164,0.48347603471573425,-0.024511800879351675
64.60000000000022,11.588313775909063,0.5108919429979845,-0.025033525046936678
65.80000000000024,11.638905123232755,0.5347396532610492,-0.024990217944770077
67.00000000000026,11.687605896768062,0.553650420441705,-0.024338890300759086
68.20000000000027,11.736372646942824,0.5737777940905936,-0.02410244605772016
69.40000000000029,11.783019630470674,0.5926473748239777,-0.02427512563760592
70.6000000000003,11.829802207089669,0.6077211417077156,-0.0241718431730904
71.80000000000032,11.876675984712667,0.6180101257331689,-0.0245390352853061
73.00000000000034,11.921821577331194,0.62923739461782,-0.023227153380393162
74.20000000000036,11.966936628126472,0.6365244814807881,-0.02446836348659831
75.40000000000038,12.012467062076913,0.6478213297138673,-0.02475953520330787
76.60000000000039,12.055351738280764,0.6529358346038447,-0.023466899371665573
77.80000000000041,12.10018903174683,0.6608902104822026,-0.023738736899972857
79.00000000000043,12.144400028547334,0.6708245616230558,-0.024900724023313447
80.20000000000044,12.187646180202908,0.676954598004437,-0.0251475598633224
81.40000000000046,12.231059117744469,0.685411737335117,-0.02696607198213874
82.60000000000048,12.273086103435062,0.6938539481011005,-0.025538311252261803
83.8000000000005,12.31612259763251,0.7012661684782613,-0.0255486672160381
85.00000000000051,12.358703114366069,0.7091917776454768,-0.02556368748894977
86.20000000000053,12.401004986316469,0.7174293329885145,-0.026203524391363864
87.40000000000055,12.442558826386012,0.722518483739088,-0.026971894958426557
88.60000000000056,12.484461148484431,0.7325168932391654,-0.027178359550439346
89.80000000000058,12.52619267755951,0.7394504577405695,-0.02694676606947155
91.0000000000006,12.567746412524025,0.7466429706921749,-0.027888789942733805
92.20000000000061,12.608902156711318,0.7540032301651348,-0.027084444171933786
93.40000000000063,12.649687578132294,0.7620212231330985,-0.028389323258982024
94.60000000000065,12.69108262528152,0.7673379148783728,-0.028493308577989485
95.80000000000067,12.732337448832876,0.7748404968347383,-0.029843875534974362
97.00000000000068,12.77291096098892,0.7821522720579515,-0.02846160631853767
98.2000000000007,12.814042018834154,0.79330021926317,-0.02944087635501269
99.40000000000072,12.854732877195259,0.7996149601861247,-0.02984499198431889
100.60000000000073,12.894971984501117,0.8040207494606073,-0.029839922301835298
101.80000000000075,12.935656749257237,0.8114760275227834,-0.029840651533271423
103.00000000000077,12.975970314490118,0.8175186365640414,-0.02982242951594616
104.20000000000078,13.016989415062023,0.8237431174375653,-0.029831778646670415
105.4000000000008,13.057579692957644,0.8297076457854705,-0.031146025456291415
106.60000000000082,13.097643872852501,0.8363290716830792,-0.03114743274433618
107.80000000000084,13.138071044614797,0.8393839575297998,-0.03245408734728983
109.00000000000085,13.178502226841646,0.8447223763974564,-0.03246868017669424
110.20000000000087,13.219309402348063,0.8517910223678166,-0.03379635849037088
111.40000000000089,13.259149602575995,0.8557423662256914,-0.03500682141863409
112.6000000000009,13.299208886086912,0.8611822360131284,-0.0341810398926059
113.80000000000092,13.339622742691924,0.8652887913247608,-0.033779930047029616
115.00000000000094,13.379865282664191,0.8685346517411253,-0.0341628493660906
116.20000000000095,13.419796633213531,0.8724026008686986,-0.03447541870321613
117.40000000000097,13.460358171878754,0.8744688176476407,-0.03379019304991404
118.60000000000099,13.499962931589366,0.8770525942871488,-0.03379017304558074
119.800000000001,13.539430388470231,0.8823352622166296,-0.033800983228136516
121.00000000000102,13.579619634725697,0.8841421570259015,-0.03510351034006298
122.20000000000104,13.619747932836258,0.8838921361811827,-0.035761851517348564
123.40000000000106,13.659328141830647,0.889866229642228,-0.03576006697016609
124.60000000000107,13.699294476502292,0.8924619829493965,-0.03605426140562118
125.80000000000109,13.738826987573532,0.8942774595090104,-0.03708018600616558
127.00000000000111,13.77848381958802,0.8965190287671022,-0.037079982120233
128.20000000000113,13.818076787321546,0.8990876166850803,-0.03707777984260607
129.40000000000114,13.857164396104876,0.9019508697565981,-0.03842366511295969
130.60000000000116,13.89616601867499,0.9038990094364286,-0.037071127038609486
131.80000000000118,13.935939210809517,0.907398036542838,-0.03707003464051217
133.0000000000012,13.975081417576657,0.907742877264516,-0.03837658323067927
134.2000000000012,14.0138591088559,0.9103735427802717,-0.03838992065820657
135.40000000000123,14.053158821551223,0.9170425557611293,-0.038392345010257234
136.60000000000124,14.092441129640783,0.9195350067959016,-0.03706957233746788
137.80000000000126,14.131192035930503,0.9234710366503053,-0.03706977209258078
139.00000000000128,14.169906011517394,0.9266430560050913,-0.037775576579627046
140.2000000000013,14.208292757107113,0.9275671571106995,-0.0380599489206781
141.4000000000013,14.247736453479147,0.9344724183210609,-0.038059786752711044
142.60000000000133,14.285570251925432,0.9372607798799955,-0.038420787046035354
143.80000000000135,14.324791316389433,0.9419177708497661,-0.03837653275787911
145.00000000000136,14.363338006078433,0.9471546900843175,-0.03943415850980836
146.20000000000138,14.401850723708776,0.9508587464254653,-0.03834584387636841
147.4000000000014,14.440000323199678,0.9546512460140828,-0.038025138963325045
148.60000000000142,14.478184020984834,0.9595641564053405,-0.038390793793367184
149.80000000000143,14.516661343093384,0.962458031590948,-0.03974732249433588
151.00000000000145,14.554630043479793,0.9688930729234753,-0.039709816532384146
152.20000000000147,14.592938296640241,0.9717284321283135,-0.03970983297815511
153.40000000000148,14.631179124328519,0.97694006105944,-0.03970983299999009
154.6000000000015,14.668969218651322,0.9818730144291836,-0.03970983300000075
155.80000000000152,14.707437566973242,0.984381184311006,-0.03970983300000075
157.00000000000153,14.745500834690136,0.9897910262973886,-0.03970983299990216
158.20000000000155,14.783084232291063,0.9947787541770088,-0.03970983362430891
159.40000000000157,14.821172288546991,0.9993624567021215,-0.039711469550227196
160.6000000000016,14.85949398136947,1.0044234776198298,-0.04075108222894208
161.8000000000016,14.89699707410414,1.00786187604775,-0.040699940554130176
163.00000000000162,14.935187174767837,1.0168945335871953,-0.0406999259916776
164.20000000000164,14.9727224675339,1.0219880943354513,-0.040699925999992725
165.40000000000165,15.010603460674456,1.0277434109029708,-0.040699926000002495
166.60000000000167,15.048182451768499,1.03273124202033,-0.04069992599988259
167.8000000000017,15.085758503169977,1.0374334047412197,-0.040699925549550375
169.0000000000017,15.123606127516886,1.0422748610616344,-0.04069959760996378
170.20000000000172,15.161669506689526,1.0470048353098238,-0.041993719068877944
171.40000000000174,15.199234093263904,1.0527405684299036,-0.04199610476606752
172.60000000000176,15.236748874561796,1.0594175426645216,-0.042669741393859706
173.80000000000177,15.27395070289609,1.064745983901598,-0.042669262267490016
175.0000000000018,15.311870370540623,1.0671489512388743,-0.043311256948887156
176.2000000000018,15.348096549022983,1.0731676360085913,-0.044039548329306566
177.40000000000182,15.386393747922197,1.078168000194013,-0.04464015060056692
178.60000000000184,15.424145433564377,1.0819331393052913,-0.044639839996974295
179.80000000000186,15.461503985495112,1.0892599312486317,-0.04463976153656901
181.00000000000188,15.498599872380764,1.0958928472150746,-0.0449137402021198
182.2000000000019,15.535756450726678,1.098640388676678,-0.04494282864150767
183.4000000000019,15.572900441665087,1.10322688561524,-0.04529997401214381
184.60000000000193,15.609983336657434,1.1089736186413846,-0.04530005067239706
185.80000000000194,15.647077300660063,1.1152400047198534,-0.04530002592099658
187.00000000000196,15.684274231862613,1.1189161653788364,-0.045671007483585324
188.20000000000198,15.721138388523704,1.1241257967305316,-0.04727702852378357
189.400000000002,15.75831614966847,1.1275295519992938,-0.04728007335527806
190.600000000002,15.794846662118582,1.1332341265958021,-0.047280107968483254
191.80000000000203,15.83217963180648,1.1393238331084397,-0.04734963368149847
193.00000000000205,15.868774991137965,1.1447143974186895,-0.04857265805394739
194.20000000000206,15.905929582087783,1.1501912617608059,-0.04923709262190945
195.40000000000208,15.942734298759676,1.1565148699942305,-0.04989963602459735
196.6000000000021,15.979877616394848,1.159640676109392,-0.04990017602333463
197.80000000000211,16.016456736093193,1.1665099658116678,-0.04990017591453233
199.00000000000213,16.053114546380726,1.1698584553369065,-0.049900189077499935
200.20000000000215,16.09021028914084,1.1790001746742456,-0.05018773654493325
201.40000000000217,16.12663927037244,1.180617175360275,-0.051219798732815125
202.60000000000218,16.163370920312857,1.1852041552264292,-0.05148463455224439
203.8000000000022,16.200480500664263,1.1928167384451966,-0.05253993751107133
205.00000000000222,16.236881447324798,1.1974158162008468,-0.05253989157404115
206.20000000000223,16.273699785853115,1.201860563559418,-0.052558536253255905
207.40000000000225,16.310299984407553,1.2073734145555588,-0.053828308017633386
208.60000000000227,16.34709724782317,1.2115411460815841,-0.05517045891605887
209.80000000000229,16.383700277411275,1.2182829103640125,-0.05518287672177058
211.0000000000023,16.42037715101535,1.223711776026827,-0.05648126336257553
212.20000000000232,16.45710725249803,1.230871015047947,-0.0564804346320833
213.40000000000234,16.49354259978027,1.2351736266695257,-0.0574884192652898
214.60000000000235,16.529996377442814,1.2399969511928681,-0.057800160519021926
215.80000000000237,16.5669098287008,1.247934334921844,-0.05779984640588287
217.0000000000024,16.603283871051197,1.2525325037650612,-0.059172115022414484
218.2000000000024,16.639798752923657,1.2580091220923633,-0.05912010004096624
219.40000000000242,16.676445528246276,1.2640521214659095,-0.05912081539510483
220.60000000000244,16.712948355018845,1.2712824574268948,-0.060410423125004886
221.80000000000246,16.749419535220042,1.2725195846052244,-0.06042859628691133
223.00000000000247,16.785841376748934,1.2831435588737,-0.061732747564464674
224.2000000000025,16.82209931028255,1.288079706863104,-0.061753038615026234
225.4000000000025,16.85885248317397,1.2935824844666548,-0.06307655458789752
226.60000000000252,16.89524737830211,1.302079154915451,-0.06424796810137723
227.80000000000254,16.931720669690435,1.3117838153559482,-0.06565932433780386
229.00000000000256,16.968087281202134,1.318154578024029,-0.06573402942648787
230.20000000000258,17.004340594560965,1.3310622273415298,-0.06702087319007921
231.4000000000026,17.040849765193606,1.3404603818901641,-0.06701594543007738
232.6000000000026,17.07722991781177,1.3518167963803567,-0.0683258132320721
233.80000000000263,17.11372233244329,1.3650799197417771,-0.0683306603023417
235.00000000000264,17.150082064769887,1.3790545102657985,-0.06978482261501329
236.20000000000266,17.18676312431325,1.3971469579237428,-0.07108495347567834
237.40000000000268,17.222653333307083,1.4181727711452308,-0.0710646796900094
238.6000000000027,17.25885605903933,1.4401040510747025,-0.07239081143450887
239.8000000000027,17.295222885638438,1.465633109286459,-0.07391062380697866
241.00000000000273,17.331735280750276,1.4969640817463423,-0.07534703036771306
242.20000000000275,17.367839969549266,1.5326556508870721,-0.0767024797760043
243.40000000000276,17.404432435576588,1.577276570895517,-0.0774471432582513
244.60000000000278,17.44090672534709,1.6251282110792342,-0.0779983023573454
245.8000000000028,17.47739603501306,1.6816121771379473,-0.08070854825383611
247.0000000000028,17.51353861136044,1.7441604758961922,-0.08227052286717917
248.20000000000283,17.550016151594182,1.8144193183980881,-0.08371683591159762
249.40000000000285,17.586341223941055,1.8772378533249188,-0.0852216938482151
250.60000000000286,17.622728806398648,1.9176251717808834,-0.08668535573151237
251.80000000000288,17.658860622739045,1.9233166143023575,-0.08676456155013001
253.0000000000029,17.695562795406012,1.8915217211646218,-0.08848016251062507
254.20000000000292,17.73177599868529,1.8379264205569685,-0.08983614117027017
255.40000000000293,17.768083624333016,1.763800218313483,-0.09123303838466645
256.600000000003,17.80424015294028,1.6926496672734905,-0.09385122173410165
257.80000000000297,17.840284000394984,1.6245731235606795,-0.09629696269417076
259.00000000000296,17.87689775367942,1.563609175492457,-0.09761937128311393
260.200000000003,17.91278233270035,1.520549625255019,-0.09913273119246302
261.40000000000305,17.94820659271396,1.4827503774726032,-0.10256438134327173
262.60000000000304,17.98553664947295,1.4518254056214026,-0.1048162505982071
263.800000000003,18.021639543949846,1.4305366816623604,-0.1082404981864058
265.00000000000307,18.057842356629838,1.4130773655542748,-0.11132194318719879
266.2000000000031,18.09361181824419,1.4040788054114361,-0.11462453844384823
267.4000000000031,18.129899212132926,1.398036022692573,-0.11804952460806506
268.6000000000031,18.165825530340378,1.3945489285283876,-0.12160169462458459
269.80000000000314,18.202016809327617,1.3933401294606536,-0.1247271145461788
271.0000000000032,18.23803162689818,1.3911119387635564,-0.12782157508584158
272.2000000000032,18.273973557420014,1.390462556610394,-0.13076568006213352
273.40000000000316,18.31018763676512,1.3947307262260162,-0.13375515538606164
274.6000000000032,18.346492763334744,1.3989860876897386,-0.13828337283852044
275.80000000000325,18.382813308707856,1.4017048321913568,-0.1433615452812087
277.00000000000324,18.418932729479426,1.4076356019393395,-0.14792176980086902
278.20000000000323,18.455081314138475,1.4113822152123014,-0.1524900050703919
279.4000000000033,18.49111166569303,1.4177901600642429,-0.15762127187462616
280.6000000000033,18.527230003675758,1.4215561150916616,-0.16170809489452553
281.8000000000033,18.563774979175577,1.4296816837388093,-0.1664458633113477
283.0000000000033,18.60008978819528,1.4342835170599526,-0.1724537914541182
284.20000000000334,18.63624811197727,1.440633733887674,-0.17889699917831692
285.4000000000034,18.672267963544297,1.4441006367633638,-0.18421940616652321
286.6000000000034,18.70854071592487,1.4501598845701609,-0.19075360817460263
287.80000000000337,18.74478428278319,1.4550422368478015,-0.19764507146953791
289.0000000000034,18.780862166809275,1.4596624084943997,-0.20359743513622908
290.20000000000346,18.817498156056097,1.4652162766140926,-0.21036073989271875
291.40000000000344,18.853895916719974,1.4665988353047226,-0.21797659664244717
292.60000000000343,18.889866791511388,1.4696243089440029,-0.22571491082016992
293.8000000000035,18.9263990017236,1.4708592741628688,-0.23407912008641363
295.0000000000035,18.962486912655013,1.4723326769373346,-0.2433880454339441
296.2000000000035,18.998755160168706,1.4739798225500396,-0.25249168430474667
297.4000000000035,19.034881519507852,1.4774375015969554,-0.261884834734047
298.60000000000355,19.071111049975062,1.475833180272551,-0.27152040008055245
299.8000000000036,19.107687519714826,1.4751477507795427,-0.280870492995128
301.0000000000036,19.143788042083774,1.4760383946163476,-0.2919722496442838
302.20000000000357,19.180485603142532,1.4772738411805735,-0.30321507758130384
303.4000000000036,19.216367255198858,1.4751487622215804,-0.31299476077768285
304.60000000000366,19.252986754909823,1.4758836692641775,-0.3246718563209061
305.80000000000365,19.289441145195536,1.475929626513429,-0.33647260533152235
307.00000000000364,19.325369381085853,1.4744380172105376,-0.3482303862544409
308.2000000000037,19.361830858668746,1.4750836626947588,-0.36023053830911733
309.40000000000373,19.397960358301376,1.4745609566218465,-0.37094354093706405
310.6000000000037,19.43459264353396,1.4730769318302672,-0.3816489760597448
311.8000000000037,19.471037155441472,1.4757638823082435,-0.3936163093888778
313.00000000000375,19.507500327392034,1.4764863703376463,-0.40489997071237394
314.2000000000038,19.543546192083475,1.4762689134704994,-0.4166469528651948
315.4000000000038,19.57922535770554,1.4779756470556262,-0.4279549131833007
316.6000000000038,19.616393706362846,1.4803952698134153,-0.4411090278929968
317.8000000000038,19.65285307753438,1.4836648127505607,-0.4541500203035618
319.00000000000387,19.689174001914328,1.4854167387199033,-0.4668969577600275
320.20000000000385,19.725228751498776,1.4927470544114059,-0.478817768777267
321.40000000000384,19.76222866338437,1.4984296951355909,-0.4914252019682914
322.6000000000039,19.798295778375397,1.5029356372794693,-0.5049352402391194
323.80000000000393,19.834694665961308,1.5095183860535428,-0.5178581858093567
325.0000000000039,19.870744102378904,1.5158973219023137,-0.531631124985402
326.2000000000039,19.90835583629834,1.5254596342429034,-0.5462565341448844
327.40000000000396,19.94405123414423,1.535681054430552,-0.5602650860641787
328.600000000004,19.9804848547811,1.5492868899047596,-0.5747338603746392
329.800000000004,20.017402294614477,1.5611361771226258,-0.5892658926737528
331.000000000004,20.054048274415102,1.5727161997465733,-0.6037886227006335
332.200000000004,20.090744251565013,1.5870239064584837,-0.6192467405978355
333.40000000000407,20.127311454241358,1.6058977482329193,-0.6359243335485694
334.60000000000406,20.163785588901415,1.6243362389988436,-0.6522556491285192
335.80000000000405,20.200000301178545,1.6448370128495544,-0.6687602346940063
337.0000000000041,20.2368849785122,1.6671458579478906,-0.6870622933389083
338.20000000000414,20.27357715811464,1.6893799478299025,-0.7060666796993962
339.4000000000041,20.31013842102905,1.723621289735268,-0.7255414721881537
340.6000000000041,20.34688900742094,1.7483688425181965,-0.7449985205309462
341.80000000000416,20.383486830501464,1.7813917894745197,-0.7653971757080651
343.0000000000042,20.420422607813535,1.8214467055069075,-0.7864761036955183
344.2000000000042,20.45683674705947,1.859247652748818,-0.8083189632165877
345.4000000000042,20.494036303876126,1.9052060870794365,-0.8324377563401799
346.60000000000423,20.530642663172657,1.9521133433465212,-0.856213832339701
347.8000000000043,20.567404583165736,2.0029916388505407,-0.882302152595507
349.00000000000426,20.60461431109073,2.057856096199765,-0.9105477452924604
350.20000000000425,20.6411350792771,2.1172763933614993,-0.9399837172707706
351.4000000000043,20.677875418067423,2.1786481280880663,-0.9713313492318889
352.60000000000434,20.714720316015928,2.242651701795128,-1.0045707192700872
353.80000000000433,20.751949473792045,2.3082243976605237,-1.0402653152838437
355.0000000000043,20.788558049718326,2.3714989508845425,-1.0786065261898568
356.20000000000437,20.825917353529427,2.436157082751925,-1.120581595881199
357.4000000000044,20.862826441125232,2.4910384033650823,-1.1637389875426951
358.6000000000044,20.899507599534722,2.5341027247997463,-1.2087724378691864
359.8000000000044,20.936580387135553,2.5562683672381867,-1.2569984587755134
361.00000000000443,20.973728309017897,2.5620304044458706,-1.3071416166061205
362.2000000000045,21.01082269001393,2.53634640697931,-1.3610030432099096
363.40000000000447,21.047635858103643,2.4758716530823284,-1.415242365192484
364.60000000000446,21.084467456699898,2.3708427573074364,-1.4690026795862758
365.8000000000045,21.121519556974974,2.23063142184086,-1.524148232805039
367.00000000000455,21.158618070425213,2.062019768417052,-1.5769210326098348
368.20000000000454,21.19513794028248,1.885179211905525,-1.6273912859245225
369.4000000000045,21.23222710185691,1.7098671722400591,-1.6767826984989194
370.60000000000457,21.26892792821157,1.5412521988139287,-1.7212298909920531
371.8000000000046,21.30587439320511,1.3863933785233966,-1.7629176106134223
373.0000000000046,21.34244523965005,1.249866667526113,-1.7994351740950263
374.2000000000046,21.379158115630563,1.1317848237997854,-1.8323563166552312
375.40000000000464,21.415967236793314,1.0309126905900128,-1.8619097221294019
376.6000000000047,21.45257340473311,0.9498843087519104,-1.888833505304615
377.8000000000047,21.489502634331227,0.8831930771826839,-1.9116339509117655
379.00000000000466,21.52673005603213,0.8312177164512615,-1.9316010527961325
380.2000000000047,21.56318714733467,0.7904799057835574,-1.9499411186310343
381.40000000000475,21.60000030492705,0.756985147590491,-1.9671104958322978
382.60000000000474,21.636850535965372,0.728994872319908,-1.9831982952836444
383.80000000000473,21.674110887346117,0.7114535296876316,-1.9971890581450467
385.0000000000048,21.71098435556251,0.6992144563216556,-2.010789796875905
386.2000000000048,21.747942877534165,0.6894302168297439,-2.0239367188676876
387.4000000000048,21.784720155228143,0.6836603222761286,-2.0367666755214513
388.6000000000048,21.821556451158,0.6752852188881744,-2.0493445552243044
389.80000000000484,21.85868056705757,0.6708449447789193,-2.0619702623301785
391.0000000000049,21.8957790228283,0.6689183809027994,-2.0739649229906805
392.2000000000049,21.931869635334426,0.6710093111994953,-2.0857484933462733
393.40000000000487,21.969691894149705,0.6649722763272898,-2.098459426966694
394.6000000000049,22.007007291280527,0.6672032497300537,-2.1104639810617494
395.80000000000496,22.043759509313027,0.6638330539360273,-2.1225226596115747
397.00000000000495,22.081199418878157,0.6651590767321514,-2.1358050284148167
398.20000000000493,22.11830284945333,0.6630019353100551,-2.149111675791394
399.400000000005,22.155757048257957,0.6666055322796705,-2.1609100819128417
400.600000000005,22.19194126003527,0.6638565210440535,-2.173593377205373
401.800000000005,22.22991755064521,0.6640566819516258,-2.187006198495797
403.000000000005,22.266856375280273,0.6649254853439335,-2.1997047082542274
404.20000000000505,22.30455321204884,0.6633103961369622,-2.2134928239347893
405.4000000000051,22.341530427428985,0.6643109826622915,-2.2270608760187267
406.6000000000051,22.37901726334343,0.6664409139174299,-2.2397878855416895
407.80000000000507,22.416016596840514,0.6633502544428636,-2.2522535722958326
409.0000000000051,22.45357490927404,0.6627575175699676,-2.2664182428852873
410.20000000000516,22.49074177866481,0.6609796731217337,-2.279798027045145
411.40000000000515,22.528396818594388,0.6576592504146279,-2.295126682432625
412.60000000000514,22.56594676372232,0.6583316600638092,-2.3090623115238014
413.8000000000052,22.603309040431547,0.6568416770546026,-2.3233576529784643
415.00000000000523,22.640361383240993,0.6573727106812319,-2.3363403130147837
416.2000000000052,22.678012784398256,0.6541188630162318,-2.351320243525517
417.4000000000052,22.715402288813852,0.6515577838821358,-2.3665045530589426
418.60000000000525,22.753075567421135,0.652223321380349,-2.381290973839725
419.8000000000053,22.790351872791966,0.6540958722016714,-2.39643718133563
421.0000000000053,22.828058170948832,0.6484171062773618,-2.4139362750759505
422.2000000000053,22.8655155731154,0.6493408000475216,-2.4301518787947405
423.4000000000053,22.90292785194105,0.6484928843065549,-2.446550518876448
424.60000000000537,22.940347721786058,0.6474890269216249,-2.4627165859559357
425.80000000000535,22.97776007030022,0.6497346915945679,-2.4797097333761444
427.00000000000534,23.015344957606747,0.6487732159037602,-2.496471295283987
428.2000000000054,23.052965635090185,0.6483439667743043,-2.5138415230887183
429.40000000000543,23.090516494990975,0.6521960219839764,-2.530878048750078
430.6000000000054,23.12797588516079,0.6538965369567169,-2.548169473088353
431.8000000000054,23.165777679937577,0.6577447948263049,-2.5665586624112704
433.00000000000546,23.20318819523801,0.656455530773062,-2.5847670036494512
434.2000000000055,23.240849416173678,0.65801536911372,-2.603609964340058
435.4000000000055,23.278518955952283,0.6604499910560842,-2.6203561326599267
436.6000000000055,23.316380709304013,0.6592951754699896,-2.638595541962738
437.8000000000055,23.353953841555875,0.660318863683603,-2.6573439744312557
439.00000000000557,23.39161626136568,0.658379204879985,-2.6760671981548856
440.20000000000556,23.429098354750803,0.659951108046378,-2.6932824114939056
441.40000000000555,23.466978083434192,0.6625265645423364,-2.7111445053028356
442.6000000000056,23.504601547560107,0.6593123234105982,-2.7281353918210627
443.80000000000564,23.542290115946024,0.6582150360379015,-2.744575180340131
445.0000000000056,23.579751483023635,0.6592451353868471,-2.7611163439120325
446.2000000000056,23.61790514992203,0.6582251002195443,-2.777744660095651
447.40000000000566,23.65549450038967,0.6546815935229096,-2.794108160839574
448.6000000000057,23.69329750793595,0.6539474515874424,-2.8100270532828064
449.8000000000057,23.731018152632966,0.6538242200285169,-2.8244592031613713
451.0000000000057,23.768965962981397,0.653564184051135,-2.8381562530690347
452.20000000000573,23.806948043605118,0.648016137364289,-2.85203470331705
453.4000000000058,23.844658401458222,0.6459957041191302,-2.865034823297013
454.60000000000576,23.882657020743345,0.6397856227415843,-2.8790073904033697
455.80000000000575,23.920224196300023,0.6378601268449633,-2.8913966099592643
457.0000000000058,23.958300545251642,0.6294778322581296,-2.9047677004834043
458.20000000000584,23.996389999437422,0.6257489509163583,-2.9172603647808897
459.40000000000583,24.034221005558493,0.6182039090249853,-2.9290302645744513
460.6000000000058,24.07202753052019,0.6064882083110601,-2.9401659331069143
461.80000000000587,24.11010052126357,0.5990614629505273,-2.9512072195636163
463.0000000000059,24.147972393984688,0.5870826328754803,-2.9593462209479604
464.2000000000059,24.185949990934134,0.5765133229338433,-2.969658009560569
465.4000000000059,24.223414242964683,0.5580037943443075,-2.979217641991758
466.60000000000593,24.261605545782267,0.5419749886903029,-2.9877750115685133
467.800000000006,24.29974876275623,0.5255834188652091,-2.9977631675045573
469.00000000000597,24.33764239293966,0.5053087651156813,-3.007487101332591
470.20000000000596,24.37574526282066,0.4887547248725923,-3.016412771736269
471.400000000006,24.413755259874392,0.4710119320927828,-3.023229756861399
472.60000000000605,24.45148711273795,0.44945120008022843,-3.030701742418711
473.80000000000604,24.48974750858086,0.4310579342556091,-3.0375203018991153
475.000000000006,24.52792960690625,0.4140769646532696,-3.04238260104921
476.20000000000607,24.566021069571285,0.3966766626104572,-3.0495504039352253
477.4000000000061,24.603807101204513,0.3791482114971556,-3.0558231830154248
478.6000000000061,24.642001978917314,0.36443612147833115,-3.0605069365855226
479.8000000000061,24.680252231835475,0.3470481004314716,-3.065749642396069
481.00000000000614,24.718335355586277,0.3357577504288487,-3.07099764141721
482.2000000000062,24.75661417557848,0.32365350057070486,-3.0758701299694167
483.4000000000062,24.794573079258182,0.3137813457081189,-3.0804906374363803
484.60000000000616,24.832788540841996,0.30381635022231346,-3.084214399386259
485.8000000000062,24.871335632217157,0.29555741174324357,-3.087273174380151
487.00000000000625,24.909206990493164,0.2840385110039527,-3.0923797347980235
488.20000000000624,24.947610324549665,0.27867934256017146,-3.095605152518917
489.40000000000623,24.985833963447494,0.2701329923427147,-3.099370336224237
490.6000000000063,25.024051497719213,0.265669507821892,-3.099931969657299
491.8000000000063,25.062273145958972,0.26065984196400227,-3.1015202710783507
493.0000000000063,25.10052955366463,0.2558969707036174,-3.1054717498139675
494.2000000000063,25.138407401126656,0.2508114836998536,-3.1071541431730356
495.40000000000634,25.17688158136808,0.2477107501442437,-3.1104302238573736
496.6000000000064,25.215293915219128,0.24556636410661103,-3.113298663692521
497.8000000000064,25.253813381369078,0.24313456178177018,-3.116931540052717
499.00000000000637,25.29225409709805,0.23784997433452593,-3.1206657697117914
500.2000000000064,25.330547922584575,0.2333899967171753,-3.1223707302123676
501.40000000000646,25.36885402985482,0.23337182136622636,-3.124108850528595
502.60000000000645,25.40754659530939,0.23258548489293274,-3.1264075383226686
503.80000000000643,25.445924710461455,0.22818572497059586,-3.1276891346286257
505.0000000000065,25.48420753993988,0.22427243535273034,-3.129151155103419
506.2000000000065,25.52259605614521,0.22212410458422283,-3.1320530505399944
507.4000000000065,25.561297607014193,0.22300157820332278,-3.133882793509403
508.6000000000065,25.599451697930046,0.2212622643208082,-3.135470130707428
509.80000000000655,25.638236953856598,0.2186257372663527,-3.137205883211879
511.0000000000066,25.67649960468843,0.2179364228272953,-3.1410800534718044
512.2000000000066,25.715625024174322,0.21700212857804146,-3.142829213148639
513.4000000000066,25.75360829727478,0.2124984887284418,-3.1444772376380503
514.6000000000066,25.792113771990763,0.21139004064222267,-3.145875712879726
515.8000000000067,25.83053472969153,0.2104079193553876,-3.1476352319305647
517.0000000000066,25.869368202056208,0.21168984025676996,-3.1487570999411183
518.2000000000066,25.907862807531725,0.20972069491952383,-3.150073963272506
519.4000000000067,25.946508601577303,0.2065321472011723,-3.1514974406875487
520.6000000000067,25.985072513465283,0.203826248706779,-3.153871659437408
521.8000000000068,26.023500534369948,0.20281502564059473,-3.1551923472076533
523.0000000000067,26.062410092219185,0.20307545523271076,-3.156249210961384
524.2000000000068,26.10099406108626,0.20012254018806752,-3.157634736264565
525.4000000000068,26.139327104141525,0.2033749382348149,-3.1590289823289828
526.6000000000067,26.1780698217303,0.20081745497701098,-3.1606377871146103
527.8000000000068,26.21675976539168,0.20227259147657306,-3.1619357660769274
529.0000000000068,26.25541865748493,0.1978714410823723,-3.163483494707951
530.2000000000069,26.293772478917464,0.19920543330867835,-3.1670217371543465
531.4000000000069,26.332618925992797,0.19616712413967274,-3.1676283522973785
532.6000000000068,26.371171438171448,0.19595763807010091,-3.168931153237064
533.8000000000069,26.409958477147136,0.19727357834767845,-3.170149267595259
535.0000000000069,26.44862335383534,0.19493736794176186,-3.1702577772255545
536.2000000000069,26.487445563920545,0.1944937607239272,-3.171776069600287
537.4000000000069,26.525911666049836,0.19556399743748698,-3.173315246923262
538.600000000007,26.56480206082772,0.19595783128596778,-3.174646747139793
539.800000000007,26.603623643572103,0.19219665212282178,-3.175949282230676
541.000000000007,26.64158246211453,0.19193148972955032,-3.1773221272562706
542.200000000007,26.68071480385214,0.1934637165465407,-3.177280030829773
543.400000000007,26.719735301209436,0.19083477445446873,-3.177280106389053
544.6000000000071,26.75844584109171,0.1889291769290471,-3.1786409034334824
545.800000000007,26.797591992311762,0.19198894485927553,-3.178962094323128
547.000000000007,26.836411134099993,0.19324361223769704,-3.1788586194395707
548.2000000000071,26.875077235925133,0.19031300206233248,-3.1800578825095185
549.4000000000071,26.91372087721805,0.1887414260797653,-3.181913601520736
550.6000000000072,26.95245564553483,0.19040770421956532,-3.18352634503481
551.8000000000071,26.99153390027999,0.1890590097371927,-3.1848363412509735
553.0000000000072,27.03060363637813,0.1897566186485553,-3.185722638462842
554.2000000000072,27.069404041079004,0.18603998114000642,-3.188347389827085
555.4000000000071,27.10797107624142,0.1890081373837278,-3.1894412252050275
556.6000000000072,27.14679720556292,0.18880580891217513,-3.1900111220227476
557.8000000000072,27.185825532941436,0.18729602652110033,-3.190993009282363
559.0000000000073,27.22487941552724,0.18930122337070165,-3.192307630374191
560.2000000000073,27.2636870303266,0.18952795553306445,-3.1935853775391756
561.4000000000073,27.30260453758455,0.187340748022629,-3.1951514244984907
562.6000000000073,27.341405429197373,0.19111591723863786,-3.196473500577145
563.8000000000073,27.380198639970637,0.1913521021374014,-3.1972730484274767
565.0000000000073,27.419378372396103,0.19275309286247033,-3.197129892443004
566.2000000000073,27.458442421030497,0.1916863107587361,-3.197592458409581
567.4000000000074,27.49727416049891,0.19044187661901013,-3.1985881686898194
568.6000000000074,27.535801794476765,0.1942373622615774,-3.1997586448242465
569.8000000000075,27.57512904794496,0.19054019366865838,-3.201099183727607
571.0000000000074,27.614148820686328,0.1918961406261961,-3.202421681168514
572.2000000000074,27.653235172351334,0.19160668171933626,-3.203764302625466
573.4000000000075,27.692365414002925,0.19043914790165473,-3.2050317339637466
574.6000000000074,27.73137335723587,0.19115523585881333,-3.2065039541236438
575.8000000000075,27.77032453309501,0.1913218096195075,-3.205570209128315
577.0000000000075,27.80929989299112,0.19165713237186965,-3.206432978079207
578.2000000000075,27.848455016935592,0.18911061542536367,-3.207879726584644
579.4000000000076,27.887474200896587,0.18961494257141553,-3.2091926359635585
580.6000000000075,27.926607782620998,0.1913681228306101,-3.209197026525841
581.8000000000076,27.965687698746432,0.1880629457816443,-3.2105103351808286
583.0000000000076,28.004745007809085,0.1883876417427346,-3.2118577372722807
584.2000000000075,28.04419033872797,0.18636282969061502,-3.2117824825331818
585.4000000000076,28.08313850785287,0.18684789291959758,-3.213139073746144
586.6000000000076,28.122362106258063,0.18728695670367723,-3.2131069544925017
587.8000000000077,28.16163101782596,0.18581785287533692,-3.2144496767992825
589.0000000000077,28.200606604210734,0.18731059736557976,-3.215780572043851
590.2000000000077,28.239835111436733,0.18294005954296377,-3.217087169490942
591.4000000000077,28.279252500269457,0.1871162102227506,-3.2173584921911695
592.6000000000078,28.318258585370312,0.1856268606457574,-3.2184096441043204
593.8000000000077,28.357778241188818,0.18654919721456475,-3.2184151145949604
595.0000000000077,28.39685487365059,0.179927410637035,-3.219725546654816
596.2000000000078,28.43614699704305,0.18200044110093438,-3.219728527198262
597.4000000000078,28.475623803332,0.18322533989216483,-3.2210568231909047
598.6000000000079,28.51451086986975,0.1872047623573978,-3.2220192840278354
599.8000000000078,28.55414750465152,0.18693583808411351,-3.2233509276917776
601.0000000000078,28.59342836780618,0.18575140191376716,-3.224664995408207
602.2000000000079,28.632643328743004,0.18630504914519297,-3.2246600236039713
603.4000000000078,28.67199285657608,0.1901586598952809,-3.225525804583121
604.6000000000079,28.711424259182774,0.1890473053568611,-3.2258327989266062
605.8000000000079,28.750769363291816,0.1884042354709088,-3.225990470872692
607.000000000008,28.790166157633262,0.18885544488686246,-3.227386244292884
608.200000000008,28.82972005340509,0.18650358603795913,-3.228843097296765
609.4000000000079,28.86859437716495,0.18287535334441118,-3.2301508101610796
610.600000000008,28.908025580639972,0.1802218241769784,-3.231566655605687
611.800000000008,28.947642209811107,0.17845417626278826,-3.2342440002124926
613.000000000008,28.98680788141222,0.17722227300117188,-3.2355259843438677
614.200000000008,29.02638476252956,0.1779731820656767,-3.2357246110789597
615.400000000008,29.06586752040223,0.17464579188552376,-3.2366629528410438
616.6000000000081,29.105238841919423,0.17440100385117674,-3.239492744781243
617.8000000000081,29.14463813870338,0.17072562518043166,-3.2419337792826224
619.0000000000081,29.183890677094038,0.17127913663558791,-3.2409577358251815
620.2000000000081,29.22350880314089,0.16911187770944158,-3.2382159064247187
621.4000000000082,29.263200684576262,0.1645507504868955,-3.2393044396708146
622.6000000000081,29.30253371573615,0.16922650555806928,-3.2408111944555946
623.8000000000081,29.341780798682088,0.16650852540816885,-3.242115615614386
625.0000000000082,29.38145299441468,0.1649958477412099,-3.2420897546743896
626.2000000000082,29.420763608106732,0.1657227120302649,-3.2435099163507637
627.4000000000083,29.460316612783704,0.16438257730102235,-3.244839548513265
628.6000000000082,29.50012903398035,0.16546756161328346,-3.2461599593622217
629.8000000000083,29.53952584827592,0.1685272287423374,-3.247430823603178
631.0000000000083,29.578852170466615,0.16511335597370835,-3.248687018585254
632.2000000000082,29.618257222178713,0.16584145224085045,-3.2493124985401556
633.4000000000083,29.658061778290968,0.17171155724826614,-3.250846728252041
634.6000000000083,29.697414666544564,0.16836783799812127,-3.2530384534640744
635.8000000000084,29.737255709619735,0.173259327638686,-3.255548382994018
637.0000000000084,29.77641531981365,0.17529089322222147,-3.2562562027227155
638.2000000000083,29.81635253386449,0.17513799247105855,-3.2557619188125577
639.4000000000084,29.85573860196549,0.18012871097952865,-3.255335314959722
640.6000000000084,29.89516652244735,0.1815472694737159,-3.25668899670639
641.8000000000084,29.93467107153909,0.1822086769212523,-3.2567213409353823
643.0000000000084,29.974474788131253,0.18469094098339833,-3.2579998413848923
644.2000000000085,30.01394190652239,0.18791779403383102,-3.257637873651386
645.4000000000085,30.053458083225348,0.1886663798942294,-3.25767044522708
646.6000000000085,30.093198508932762,0.19659534182184601,-3.258989594198905
647.8000000000085,30.132991223864632,0.19963814746662645,-3.258990302230405
649.0000000000085,30.172307298030898,0.20259195274201192,-3.260324891827747
650.2000000000086,30.211207440791732,0.20519121794935247,-3.2603026371295485
651.4000000000085,30.250382935683117,0.20687147916135218,-3.2609665278110076
652.6000000000085,30.29115161611517,0.21124028531635775,-3.2609700934634325
653.8000000000086,30.330591962362295,0.21478006663586324,-3.2612936598116153
655.0000000000086,30.370189504392304,0.21601008291437918,-3.2632840574197504
656.2000000000087,30.40950569291857,0.22046084467395533,-3.264585321000989
657.4000000000086,30.449241701829635,0.22350086419021764,-3.265895185413759
658.6000000000087,30.488917201573354,0.22498031509352412,-3.265899946556246
659.8000000000087,30.528723394076803,0.2273785691584722,-3.2650283047159405
661.0000000000086,30.568005375257165,0.22937574155737206,-3.2645899954706232
662.2000000000087,30.60784140739412,0.22858169372279624,-3.265672405902745
663.4000000000087,30.647299263911183,0.22993425389562727,-3.2659099184757694
664.6000000000088,30.687039307030304,0.23289802988559893,-3.2658833335362663
665.8000000000088,30.726298115818278,0.2344904309374929,-3.2672226453509343
667.0000000000088,30.76619671092449,0.23546304770800086,-3.2685293841620515
668.2000000000088,30.805623210394067,0.2351198358013411,-3.268531360192231
669.4000000000088,30.84554133694226,0.23298832034269434,-3.267198741948723
670.6000000000088,30.884826275532742,0.23675580085578485,-3.268651764584871
671.8000000000088,30.924625634681107,0.2302021769873699,-3.2701965068704935
673.0000000000089,30.964314204036004,0.23369249510203183,-3.271503022484562
674.2000000000089,31.003938172719998,0.2377863804299527,-3.2715000971489365
675.400000000009,31.04353522737845,0.2395042825792042,-3.271500096000474
676.6000000000089,31.08335896913523,0.23564491561902878,-3.271500096000768
677.8000000000089,31.1230922253956,0.23714163032792523,-3.2715000968764847
679.000000000009,31.162861189751453,0.23580314698081484,-3.2714986175794563
680.2000000000089,31.202714155422733,0.23707263092412,-3.270179871854296
681.400000000009,31.242320466381805,0.23672460930857664,-3.270243895427825
682.600000000009,31.28189308162065,0.23811002352814548,-3.271499806093536
683.800000000009,31.321979912774903,0.2393890105137073,-3.271500323861911
685.0000000000091,31.36173284895205,0.2389308662301528,-3.2726120817006192
686.200000000009,31.40144198228658,0.23860585703496362,-3.2728098144612083
687.4000000000091,31.441043408318404,0.24022464761346374,-3.272831141614389
688.6000000000091,31.480680795366194,0.24477463955626888,-3.2741296882595288
689.800000000009,31.520202132272217,0.24392775361119146,-3.2741286662130897
691.0000000000091,31.559967364471966,0.24071641348793182,-3.27661215109909
692.2000000000091,31.59976373951658,0.2415114564522547,-3.276766455155254
693.4000000000092,31.639767704822088,0.23835989619354958,-3.278079259839969
694.6000000000092,31.679199123258012,0.2390431258834398,-3.2780113467088965
695.8000000000092,31.71948492476722,0.23842845572469518,-3.2780737744332673
697.0000000000092,31.759495090635447,0.23983300444126776,-3.2793902709393445
698.2000000000093,31.79898693039776,0.2346443856845677,-3.2793900990656226
699.4000000000092,31.83876043543129,0.23830295437380222,-3.2793898959249823
700.6000000000092,31.878490269412023,0.23523938968518188,-3.2806190713737418
701.8000000000093,31.91852053627616,0.23660295737445658,-3.2807097762358612
703.0000000000093,31.95875409839877,0.23949994240848493,-3.2813974728908546
704.2000000000094,31.998545604028426,0.23727807836169879,-3.28136994919789
705.4000000000093,32.03821663509297,0.23356153508882116,-3.2813698823069815
706.6000000000093,32.07811835442939,0.23423722248812373,-3.2812445247283635
707.8000000000094,32.11790781844455,0.2306651631932044,-3.280378085980256
709.0000000000093,32.15749737604304,0.2335899318329182,-3.2810363134627316
710.2000000000094,32.197876805282455,0.23484065136280208,-3.282385278024506
711.4000000000094,32.237701295222706,0.23457426546284754,-3.2823509092968637
712.6000000000095,32.27727815595051,0.23174061476911278,-3.283707481666838
713.8000000000095,32.31716777669681,0.23121025805108575,-3.2836698912295397
715.0000000000094,32.35736174786805,0.23071341709231374,-3.2836699017006303
716.2000000000095,32.397314777963,0.23147594919679104,-3.2838112217939734
717.4000000000095,32.43732434251837,0.2292075714857642,-3.2849895543916388
718.6000000000095,32.477403335452195,0.22902597836093674,-3.2849320421747086
719.8000000000095,32.517387083995,0.22804834082131986,-3.2862993238406295
721.0000000000095,32.55693075156904,0.22679189703092684,-3.286298558633867
722.2000000000096,32.597104603910246,0.22728547356026851,-3.2876338196463735
723.4000000000096,32.63714251067635,0.22422659012300938,-3.287620032819867
724.6000000000096,32.67718820414998,0.22390266542960813,-3.287620019909388
725.8000000000096,32.717192828504125,0.2229759340674251,-3.287602034043829
727.0000000000097,32.75713355926163,0.22094549598169078,-3.2889311452525263
728.2000000000096,32.797212330086765,0.2227020614911277,-3.2886003965899278
729.4000000000096,32.83725745979778,0.22335245765023082,-3.2893290388891536
730.6000000000097,32.877195086346575,0.2164321334752537,-3.289270245860739
731.8000000000097,32.917124597621495,0.2180218065888555,-3.2892662069898675
733.0000000000098,32.95737457710903,0.21473897915903883,-3.2905792640237133
734.2000000000097,32.99719245189965,0.2134570126857711,-3.2905901665721458
735.4000000000098,33.03734564082608,0.2118192004544377,-3.2902708688836313
736.6000000000098,33.07724363609198,0.20920981651243586,-3.2899435618568247
737.8000000000097,33.11754959271622,0.20555055483880658,-3.2912426194221
739.0000000000098,33.1573683929842,0.20273544580645275,-3.2912398729848196
740.2000000000098,33.197552475408315,0.20018632035634232,-3.2912194289165395
741.4000000000099,33.23750992007002,0.19609930953113386,-3.29256065052076
742.6000000000099,33.27737685166872,0.193829626908125,-3.2925598490467483
743.8000000000098,33.31744295311258,0.1907489625668215,-3.291570299164725
745.0000000000099,33.357694515544544,0.1913888081581634,-3.292899012261315
746.2000000000099,33.39751003396115,0.18875131927453825,-3.2931444763185294
747.4000000000099,33.43775996096126,0.19032822181823938,-3.294309752286197
748.6000000000099,33.47767376151623,0.1884541102552877,-3.2942568429013925
749.80000000001,33.517201584979894,0.18305171324010328,-3.2959156089102657
751.00000000001,33.557989418199284,0.18047327588231132,-3.2971345406155335
752.20000000001,33.59781558669074,0.1789826275063966,-3.298018186507816
753.40000000001,33.63796083723042,0.17455978149312035,-3.2975575594143147
754.60000000001,33.67835337516493,0.17165179972869415,-3.298696611525994
755.8000000000101,33.71875043122913,0.17159992974915284,-3.3000048239192403
757.00000000001,33.758612673140796,0.16905153281371588,-3.3000098196858634
758.20000000001,33.79895254904193,0.16732191188334644,-3.2997613007025803
759.4000000000101,33.83836697950655,0.16377678159504905,-3.2987015287891293
760.6000000000101,33.8791650624497,0.1663325760200265,-3.297376746261864
761.8000000000102,33.91963623644628,0.1662545941891147,-3.2973801173219996
763.0000000000101,33.959737742691026,0.1602137274125197,-3.2973798460843646
764.2000000000102,33.99973362152363,0.15698788574031708,-3.2987013247361188
765.4000000000102,34.04013452673112,0.1593182245225866,-3.298700142805602
766.6000000000101,34.08022295698567,0.1534728618990111,-3.2987001418080495
767.8000000000102,34.120281898327775,0.1557729805099779,-3.2986964970969566
769.0000000000102,34.160673199218934,0.15345425570643734,-3.2993330979286903
770.2000000000103,34.20104658636767,0.15295908821708037,-3.2993313398802946
771.4000000000103,34.24129357672631,0.15276611242467775,-3.299355852396478
772.6000000000103,34.281531557817026,0.1505822914065571,-3.299359870504981
773.8000000000103,34.32176967409456,0.15426600630580145,-3.299362816023432
775.0000000000103,34.36210568140322,0.14982506063910606,-3.300664382042271
776.2000000000103,34.402091998585014,0.15083404222768015,-3.3006699870077587
777.4000000000103,34.44237249765929,0.1495563756519589,-3.3007366449481474
778.6000000000104,34.48251201653136,0.14874146412479528,-3.3019896707446197
779.8000000000104,34.52274106353461,0.14622133236291557,-3.301989995438583
781.0000000000105,34.56288702752165,0.14285354008042006,-3.3019888100241186
782.2000000000104,34.60328422597999,0.14610753067214288,-3.3033286681269836
783.4000000000104,34.643485405799915,0.14656335036244306,-3.303309762970122
784.6000000000105,34.68383260255419,0.14475340330874875,-3.3044127500558176
785.8000000000104,34.723835059401054,0.1505208280963588,-3.3049372961871875
787.0000000000105,34.76432866316853,0.14285350392803808,-3.3059403314714846
788.2000000000105,34.804127628382034,0.1435502615545965,-3.3059401460577886
789.4000000000106,34.844881860764545,0.14244281950819282,-3.305940146000018
790.6000000000106,34.88521341075054,0.1422068115699271,-3.305940146
791.8000000000105,34.925373557576464,0.13606110343579303,-3.305940146
793.0000000000106,34.96532770894872,0.137455931670329,-3.305940146
793.7000000000106,34.98899378095518,0.13907977155607298,-3.305940146