File: 01_Data/Bamboo_Rug_Fabric/STA/N2/30K_min/Bamboo_Rug_Fabric_STA_N2_30KData_220126_R2.csv
##Temp./Â°C,Time/min,DSC/(mW/mg),Mass loss/mg
49.0,10.506391986111575,0.037704750735520154,0.009877280169741098
50.20000000000002,10.720727929588898,0.09951637909222266,0.009743903022223055
51.400000000000034,10.851601771866758,0.15409706079072272,0.011304752835349596
52.60000000000005,10.95369476269237,0.19955259759241462,0.011236135327817642
53.80000000000007,11.040680209593676,0.24071930111698436,0.010388639236072805
55.000000000000085,11.11877531420718,0.27881630882770814,0.009135310155223397
56.2000000000001,11.189628833553764,0.3117412827754611,0.010821107866263002
57.40000000000012,11.256185387352854,0.3441379996803729,0.013233927787711153
58.600000000000136,11.317503221437516,0.3723539368268187,0.012614861871755867
59.80000000000015,11.376656321934236,0.4008269997831652,0.01247083830771123
61.00000000000017,11.433374064039327,0.4259878577353372,0.012301501896380351
62.20000000000019,11.487819519460029,0.447573384889359,0.01108126115932162
63.400000000000205,11.540765090892325,0.47052431096903935,0.010845636432664119
64.60000000000022,11.591842947629988,0.4936956215923518,0.011197304337617453
65.80000000000024,11.641754815259457,0.5136241792155996,0.011466207554620578
67.00000000000026,11.691723979740269,0.5357584086446538,0.012503521474395818
68.20000000000027,11.739874666855663,0.5543992951721664,0.011491846165262665
69.40000000000029,11.787370760246269,0.5715150984221506,0.010752121501917955
70.6000000000003,11.834541664120065,0.5859490508076975,0.011530831692678767
71.80000000000032,11.880742236211074,0.5945230220308049,0.012015899743722969
73.00000000000034,11.926422265595198,0.6078587106047153,0.011581937185328517
74.20000000000036,11.97190987546776,0.6175819516399111,0.010939284972165453
75.40000000000038,12.016815712951685,0.6242629371771826,0.011333910173733308
76.60000000000039,12.060916459276468,0.6314838041427747,0.011631120864612932
77.80000000000041,12.105438394742368,0.6382184023995784,0.01106093801120478
79.00000000000043,12.149006504228106,0.6472119887269578,0.010524694095872977
80.20000000000044,12.192425986578312,0.6525361763431352,0.008935491509044713
81.40000000000046,12.235713682814023,0.6592580388048714,0.010471253815345083
82.60000000000048,12.27847729040582,0.6650106469205855,0.009238785186151954
83.8000000000005,12.32163971698802,0.6745310399769193,0.010572743960206132
85.00000000000051,12.363215908084904,0.6808175244686138,0.009736010694651132
86.20000000000053,12.405759934480376,0.6890814093894062,0.010456552393969698
87.40000000000055,12.447942937680374,0.6956187409762877,0.00962040006852849
88.60000000000056,12.489494045074181,0.7025593460808156,0.00881538906731727
89.80000000000058,12.531074774760743,0.7104971555630152,0.00802154687054557
91.0000000000006,12.5726679015787,0.7131506961047185,0.009316848557757051
92.20000000000061,12.6141284040926,0.721491170189292,0.00931767190891497
93.40000000000063,12.655052954774598,0.7299827459316338,0.00800285630225428
94.60000000000065,12.695745128765582,0.7342519092623886,0.009333759613750381
95.80000000000067,12.736778318703378,0.7402305747590028,0.01058217751793089
97.00000000000068,12.77758164814813,0.7476388206889251,0.009318576504480092
98.2000000000007,12.818675057148825,0.750232097757979,0.007893780490138447
99.40000000000072,12.859023927266886,0.7570483532773333,0.007904957816455838
100.60000000000073,12.899755792629092,0.7634276769971999,0.007793407876462322
101.80000000000075,12.940356834969245,0.7677074580773884,0.0066526523343410915
103.00000000000077,12.98095694800647,0.7740903709382183,0.007900371979186804
104.20000000000078,13.020950808427816,0.7790809230949137,0.007707611215543864
105.4000000000008,13.06155383540372,0.7856890387589286,0.006529179960244491
106.60000000000082,13.10234799128108,0.7922005769216462,0.006470577333476779
107.80000000000084,13.142397489943013,0.7952556076523343,0.007817619990935665
109.00000000000085,13.182728377900863,0.7990422498140648,0.006469787578950559
110.20000000000087,13.223161504589036,0.8028218365103774,0.006470012493754673
111.40000000000089,13.263691340329846,0.8069319322987373,0.006477726929458694
112.6000000000009,13.303670647483298,0.8115160185924885,0.005158746355173882
113.80000000000092,13.343662591495866,0.815179570400653,0.006482328472443566
115.00000000000094,13.38387137901828,0.8193984708509111,0.006469980206822434
116.20000000000095,13.423991721127825,0.8205428954043543,0.006107382564299879
117.40000000000097,13.464168172891142,0.8249084724421276,0.0051498374977656525
118.60000000000099,13.504175126382442,0.8247482932500884,0.0038271107497700463
119.800000000001,13.543777393870013,0.8311972159478769,0.0038299879785448354
121.00000000000102,13.583901179026263,0.8333025874366506,0.0038312341220234636
122.20000000000104,13.623973187915972,0.8366408482520822,0.00252275275850522
123.40000000000106,13.663351985021981,0.8414662180629282,0.0038723237959525925
124.60000000000107,13.703619461212579,0.843410196979764,0.00400987761805327
125.80000000000109,13.742903302707393,0.8458631933700712,0.005159763572659237
127.00000000000111,13.782677887177744,0.8492312631220479,0.005160134356816393
128.20000000000113,13.821632049948533,0.8515732567257688,0.00521771921642733
129.40000000000114,13.860995474607778,0.8556727728652561,0.0038410727822175694
130.60000000000116,13.900659477387256,0.8597235943497268,0.0038401123463662756
131.80000000000118,13.939809612297461,0.8615322380467042,0.003840112000240481
133.0000000000012,13.979106573332952,0.8669060472207357,0.0038401121758937506
134.2000000000012,14.017829336512497,0.8694838550012961,0.0038397060232506774
135.40000000000123,14.057074049106276,0.8720763126162435,0.002276473475679275
136.60000000000124,14.095790267748365,0.876432968059166,0.0036359346039724905
137.80000000000126,14.134963705636459,0.8801446911824911,0.003620086739059669
139.00000000000128,14.173362983975537,0.8843248237747798,0.0036204368996921588
140.2000000000013,14.212864815473859,0.8881730178150012,0.0023031437376945796
141.4000000000013,14.25096839081268,0.8923182704869584,0.002310128571444192
142.60000000000133,14.289709947367548,0.895789491248741,0.0023157885203706208
143.80000000000135,14.327803586248919,0.8984935193651824,0.0036151950665526122
145.00000000000136,14.3656565241623,0.9046216693391119,0.003620078154527029
146.20000000000138,14.404987738305252,0.9089770864570235,0.0036210865341361753
147.4000000000014,14.443542216643465,0.9134884096629398,0.0023092274685256875
148.60000000000142,14.481955334754813,0.9179074094738999,0.0023000629081955104
149.80000000000143,14.520140816238792,0.9232391371292601,0.0022782528195977036
151.00000000000145,14.558281971420552,0.9286951879134656,0.0029593937507659263
152.20000000000147,14.596281226540246,0.9310541601599979,0.0025508834216840803
153.40000000000148,14.634309366711038,0.936773003029481,0.0019700435715424014
154.6000000000015,14.6727941696201,0.9409404395561064,0.0019700799982591555
155.80000000000152,14.710553147860619,0.9468815657638994,0.0019700799999968766
157.00000000000153,14.748440415066357,0.9498164454451681,0.001970079999999541
158.20000000000155,14.786623121350694,0.9559149407619356,0.001970080000109231
159.40000000000157,14.82441048795035,0.9586309460143968,0.001970079681977932
160.6000000000016,14.862485948138255,0.9634461440587959,0.0019691232794007973
161.8000000000016,14.900369164934116,0.9691212723181235,0.000624487003223706
163.00000000000162,14.93820688561399,0.9764369195744674,-0.0006613140814044627
164.20000000000164,14.976230886421499,0.9804203090739474,-0.0006601850669167852
165.40000000000165,15.013889433554906,0.9850844265754067,-0.0006601840000257653
166.60000000000167,15.051430830803191,0.9919088134286675,-0.0006601843048117395
167.8000000000017,15.088923567461704,0.9982542092225513,-0.0006613078070571987
169.0000000000017,15.126710890217602,1.0041350124986819,0.00031909736974533587
170.20000000000172,15.164404119509017,1.0095469763611862,0.0003298258142407917
171.40000000000174,15.202071095515281,1.0166731600275267,0.00032981600849524284
172.60000000000176,15.23944904292394,1.0202830337057827,0.0003298159999904904
173.80000000000177,15.277490795378556,1.0270151475552791,0.0003298160659199745
175.0000000000018,15.314687577832292,1.0290692015996774,0.0003299065191435524
176.2000000000018,15.352219854726739,1.0342776860676428,3.312043184378055e-05
177.40000000000182,15.389620870599973,1.0425194324059575,-3.9027606257846514e-07
178.60000000000184,15.425956263992653,1.0447919496022287,-0.0010007646482828036
179.80000000000186,15.464135495533542,1.0499403637187807,-0.0013056910578379544
181.00000000000188,15.50137310930874,1.0558909613677947,-0.0022960021247397933
182.2000000000019,15.538887420120155,1.0604615707575098,-0.0023001533128357288
183.4000000000019,15.575729287075934,1.0658316331213287,-0.0023001520045200508
184.60000000000193,15.612778973495999,1.0679230989883457,-0.0023001523960743953
185.80000000000194,15.649741960569807,1.0730215575236222,-0.0022960475074835784
187.00000000000196,15.687025222583923,1.077871328755645,-0.003610361721005262
188.20000000000198,15.72410149083488,1.0835763354717043,-0.003620029324615359
189.400000000002,15.760918591166204,1.089058201411071,-0.003620020006571245
190.600000000002,15.797728831362516,1.0922821759107628,-0.0036200199942584277
191.80000000000203,15.83511989867745,1.0966788815782855,-0.0036200053261135068
193.00000000000205,15.87172542815694,1.101330302960441,-0.0036277387561041152
194.20000000000206,15.908433244364279,1.1061982952086695,-0.006087161860861112
195.40000000000208,15.945294099015477,1.112469893113575,-0.006259925544815914
196.6000000000021,15.981911551593647,1.1160725746399223,-0.006256115626722014
197.80000000000211,16.01901524438778,1.1199237349102789,-0.007233980111670313
199.00000000000213,16.055797029499903,1.1250963736203732,-0.006444186784943184
200.20000000000215,16.091542606036082,1.1308174876369819,-0.006249933649040251
201.40000000000217,16.129403887423518,1.1362429956496825,-0.0062165542663108475
202.60000000000218,16.166424581067396,1.1391351939828729,-0.006577158310670406
203.8000000000022,16.202867410317268,1.1451373186428084,-0.007896352183413669
205.00000000000222,16.239824886318,1.1490283447880933,-0.007900168846098232
206.20000000000223,16.275962679762042,1.1550024440316708,-0.008577840766086808
207.40000000000225,16.31287171830749,1.1577810422706871,-0.009220021057240402
208.60000000000227,16.349881663251082,1.1651812585930466,-0.00919964474985635
209.80000000000229,16.38639605168529,1.1711714145765884,-0.010530410478009955
211.0000000000023,16.423107928464297,1.177626732710484,-0.01176564094307464
212.20000000000232,16.45999058025003,1.1808897169605772,-0.011854243549264787
213.40000000000234,16.49624912492384,1.1872972122838812,-0.013155077204860977
214.60000000000235,16.53287732061264,1.1905737873962292,-0.013158914279002065
215.80000000000237,16.569487815704655,1.1956030556934578,-0.012505256032220746
217.0000000000024,16.606042198544543,1.2022090666118708,-0.013170439720815885
218.2000000000024,16.642776679284054,1.2080870323771071,-0.01447910004864239
219.40000000000242,16.679714721997907,1.2146834304723866,-0.014460620423296877
220.60000000000244,16.716031076559506,1.2199114026537783,-0.01710707594430705
221.80000000000246,16.752379377002867,1.229418345443851,-0.017104184291710567
223.00000000000247,16.789045827439033,1.231446112682466,-0.018418944739474252
224.2000000000025,16.825327639098642,1.2371925046181986,-0.018419894372843082
225.4000000000025,16.86195035182651,1.2477930118583465,-0.018431498532990087
226.60000000000252,16.898354564742725,1.2549602346159572,-0.019737510017281412
227.80000000000254,16.934866094191783,1.2610103448039993,-0.02093342518932051
229.00000000000256,16.971079973824306,1.269993705196563,-0.02265156559339676
230.20000000000258,17.007940945862543,1.2814740377027571,-0.022848336917528744
231.4000000000026,17.044044345695145,1.2898726951011859,-0.024087606630546432
232.6000000000026,17.0806615124678,1.3021053637795326,-0.024122513574827753
233.80000000000263,17.11717190885109,1.312502273938072,-0.026604792348408957
235.00000000000264,17.15366926875204,1.3298125095944182,-0.027566732236323332
236.20000000000266,17.190108447863324,1.3455045976053208,-0.028030048869639224
237.40000000000268,17.22626710892151,1.3648421541464113,-0.029389954405627083
238.6000000000027,17.262983174414583,1.386531082984464,-0.030727540613584736
239.8000000000027,17.299555617231402,1.4119232524770493,-0.03141890505748712
241.00000000000273,17.335820560866257,1.4461052624954738,-0.03226576397477343
242.20000000000275,17.37213629776744,1.4821601874167825,-0.03345428624669289
243.40000000000276,17.408589860207883,1.52465370700093,-0.03477822097007088
244.60000000000278,17.445008357167698,1.5741259539960635,-0.036077412095043115
245.8000000000028,17.48136605671924,1.6313602230703015,-0.03695560322645264
247.0000000000028,17.517730765749057,1.6967749646785835,-0.038283729898064944
248.20000000000283,17.554224215752363,1.7641108628385829,-0.03979435262309172
249.40000000000285,17.590520243142777,1.8257453652106461,-0.041301205392765716
250.60000000000286,17.62662646679641,1.8596443000625873,-0.043333228711624816
251.80000000000288,17.663664852152806,1.8590449795507171,-0.0455690094354928
253.0000000000029,17.70016752830136,1.8293540073426209,-0.04840274777085618
254.20000000000292,17.736416072984298,1.7676791445693212,-0.05011513765806619
255.40000000000293,17.77262097357096,1.6987212772346525,-0.051762658790756255
256.600000000003,17.80870470263866,1.6285892709139391,-0.05183680269109869
257.80000000000297,17.844915227140284,1.5647093391566615,-0.05328375192337198
259.00000000000296,17.881406125978042,1.5082530465816264,-0.05511024242558005
260.200000000003,17.917655900753072,1.463819551370916,-0.05743037087180225
261.40000000000305,17.953789286505724,1.4308899425674269,-0.06160628462551232
262.60000000000304,17.98974551030584,1.4038216069147507,-0.0630293176814476
263.800000000003,18.025799646118838,1.382429536217257,-0.06362955626345501
265.00000000000307,18.061843376297837,1.369944072409893,-0.06686238741569905
266.2000000000031,18.098178361411904,1.3582505488356629,-0.07022633513429577
267.4000000000031,18.13460356611752,1.3546435497925462,-0.07359163062933094
268.6000000000031,18.170675653341593,1.3509749063544607,-0.07743916463089517
269.80000000000314,18.206901197391947,1.3523187797926433,-0.08122831032467914
271.0000000000032,18.242985767193474,1.3505061147285649,-0.08379626407032736
272.2000000000032,18.27901896620405,1.352762292073093,-0.08859386980757122
273.40000000000316,18.31541645953664,1.357475583145776,-0.09264905751427976
274.6000000000032,18.351922125721988,1.3630543869062195,-0.0952341703682249
275.80000000000325,18.38794172750316,1.36729069967485,-0.10067774919546757
277.00000000000324,18.423905112053905,1.3723217715116909,-0.10550773556962323
278.20000000000323,18.4600387104022,1.3803747505855204,-0.10901275529035681
279.4000000000033,18.49644658855056,1.3859519445292348,-0.11421819901409691
280.6000000000033,18.53281405634794,1.3927321717358765,-0.12050274134067385
281.8000000000033,18.56880209667967,1.39781337360862,-0.12532713156172104
283.0000000000033,18.604990086453082,1.405955666816519,-0.13012896369626104
284.20000000000334,18.64118258242531,1.4110776223002177,-0.13615567824229835
285.4000000000034,18.67741877248247,1.4173726196493872,-0.1434261445176852
286.6000000000034,18.713782442305238,1.4246920744005807,-0.1508834511028807
287.80000000000337,18.749846335319955,1.4291541946866637,-0.1579372296281516
289.0000000000034,18.786432158717865,1.4353537665363723,-0.16448963832090913
290.20000000000346,18.8228114097527,1.4398981446965538,-0.17129087122577014
291.40000000000344,18.85863533150202,1.445405517891459,-0.17987265983227108
292.60000000000343,18.895202719857895,1.450005518321214,-0.18840906514716105
293.8000000000035,18.931531089768164,1.4535527637565384,-0.1972413990224129
295.0000000000035,18.96743735907558,1.4610131710409755,-0.20605778523858698
296.2000000000035,19.004037800740225,1.4616396162829015,-0.21466552053045174
297.4000000000035,19.040463492378155,1.465615694610333,-0.2235221114029473
298.60000000000355,19.076533479429745,1.4669353491495196,-0.23371803263323088
299.8000000000036,19.112738872404858,1.4681670090424128,-0.243448060774619
301.0000000000036,19.149118613107674,1.4687151237917802,-0.25325081519864234
302.20000000000357,19.185212626553756,1.470305262072627,-0.26339110639214924
303.4000000000036,19.221524696506737,1.4709844065862026,-0.27526719137901967
304.60000000000366,19.25807739792903,1.4718354241389688,-0.28625723879819454
305.80000000000365,19.294201710826623,1.4762573304117768,-0.29647226126815207
307.00000000000364,19.330523152921526,1.472751356611175,-0.30695577744824964
308.2000000000037,19.36693780275111,1.4748146403870424,-0.3184033105136055
309.40000000000373,19.403202567462046,1.477159404146358,-0.3299790374923188
310.6000000000037,19.439672137650163,1.4776415418209514,-0.3405275117204165
311.8000000000037,19.475700194967914,1.4775881390003067,-0.35250036049955025
313.00000000000375,19.51204499336425,1.4789391327371342,-0.36455024101100575
314.2000000000038,19.54763073148496,1.4844281409093332,-0.3766924622585055
315.4000000000038,19.584896215715183,1.4846396846668317,-0.3887019059509611
316.6000000000038,19.62125687792596,1.4905300353729083,-0.40155348111712863
317.8000000000038,19.65750109319429,1.4927816959895193,-0.41407149178184666
319.00000000000387,19.693480744539233,1.4977236827698235,-0.4267731345119712
320.20000000000385,19.73011621558455,1.5026560908645528,-0.44025077649160815
321.40000000000384,19.766292177762868,1.5079219442869527,-0.4529403213121559
322.6000000000039,19.80287963773606,1.515052531727298,-0.4662381686171382
323.80000000000393,19.839138957252107,1.5210370093731491,-0.4795380307845858
325.0000000000039,19.875738485989928,1.5296482277409198,-0.49440520761745743
326.2000000000039,19.91174920210945,1.5388567517706115,-0.5082266869704775
327.40000000000396,19.94830827585396,1.5501084713934494,-0.5212744579681976
328.600000000004,19.9847932977853,1.5599831044931867,-0.5357025226483207
329.800000000004,20.021398464562445,1.5750253851944853,-0.5508807765886945
331.000000000004,20.057904788070882,1.5917123844256487,-0.5648042081958526
332.200000000004,20.094220791210184,1.6045754175511189,-0.5791940734831926
333.40000000000407,20.13090595473892,1.6214486142068043,-0.5952700167387026
334.60000000000406,20.1672879578145,1.6423734681324111,-0.6127627503824633
335.80000000000405,20.204129229178356,1.6627035083624164,-0.6315038802515591
337.0000000000041,20.24056700695936,1.6851621686500873,-0.6482345508354381
338.20000000000414,20.276911705103235,1.7098211053544528,-0.6654783353090838
339.4000000000041,20.313719892494348,1.7402245600312054,-0.6856280962224379
340.6000000000041,20.35021320940914,1.768179042485412,-0.7046255778442356
341.80000000000416,20.386876492536313,1.8037876845034866,-0.7239630185812893
343.0000000000042,20.42351048664697,1.8393664629319493,-0.7452705093536465
344.2000000000042,20.46038015690803,1.8824413986193917,-0.7680348494502778
345.4000000000042,20.496962776819863,1.9242519898223036,-0.792164771541064
346.60000000000423,20.533796227981867,1.9730882826294571,-0.8157219969679792
347.8000000000043,20.57030873119411,2.0225131926096744,-0.841960889626038
349.00000000000426,20.60735691728569,2.0784646559354556,-0.8708832755533331
350.20000000000425,20.643506763040268,2.140072595244059,-0.8991997468888773
351.4000000000043,20.68065104636305,2.20217125811343,-0.9283405667422895
352.60000000000434,20.71764968745478,2.268652439780558,-0.9612699951516785
353.80000000000433,20.75425898408455,2.3393068972811086,-0.9971092530569701
355.0000000000043,20.79124255838806,2.406120312477527,-1.0336184531577066
356.20000000000437,20.828343609360676,2.475721541131432,-1.0716344819306034
357.4000000000044,20.865160527337295,2.5375546737419734,-1.1137808238191496
358.6000000000044,20.90201359032212,2.5926302390482054,-1.1612304949996624
359.8000000000044,20.939200110293687,2.633046308905751,-1.2107585223387747
361.00000000000443,20.975990902943145,2.6582317304013907,-1.2590572595972045
362.2000000000045,21.013214081131913,2.657059716845833,-1.3105875605731274
363.40000000000447,21.049981203882417,2.6249720093055893,-1.365419180161069
364.60000000000446,21.08727839224905,2.5527974958043926,-1.4232914533263799
365.8000000000045,21.12427141251539,2.4396042306486763,-1.4793226829267754
367.00000000000455,21.160660400725963,2.2934254727278547,-1.5302712930597524
368.20000000000454,21.197919729250945,2.122550010084238,-1.5850517808407631
369.4000000000045,21.234391878316657,1.946920670237382,-1.638180005377035
370.60000000000457,21.271286469114354,1.7735098652408507,-1.6855907041504712
371.8000000000046,21.308180953279845,1.6089595885418115,-1.7287104781166494
373.0000000000046,21.34513956678835,1.4516981127593254,-1.768623824714612
374.2000000000046,21.381865540879364,1.3184393162545958,-1.8062979197960853
375.40000000000464,21.4186247701615,1.2001977857435435,-1.8392779723389618
376.6000000000047,21.455674164998154,1.0955962177259035,-1.866250501930112
377.8000000000047,21.492219993748215,1.0105364336434923,-1.8892899859318604
379.00000000000466,21.529229825993735,0.9389802181095929,-1.9128321510310835
380.2000000000047,21.56595090564463,0.880472023892747,-1.9343698544600345
381.40000000000475,21.602721582706398,0.8358787732560259,-1.9504584934329343
382.60000000000474,21.639727739998307,0.8003171801651882,-1.966836056075178
383.80000000000473,21.676700451319597,0.7681972812706633,-1.9825881147867954
385.0000000000048,21.71349510059617,0.7456200527274668,-1.9970448830658012
386.2000000000048,21.750683127792787,0.7296658372553607,-2.010678052726776
387.4000000000048,21.787471426448906,0.7154856206281524,-2.0241453457254748
388.6000000000048,21.824414072760725,0.7062774216070995,-2.037338562566714
389.80000000000484,21.861562285823837,0.6964944733906087,-2.0509749801042467
391.0000000000049,21.898359653012072,0.6908513602050854,-2.0633363390715913
392.2000000000049,21.935859164268127,0.6881085143525862,-2.0753033661071307
393.40000000000487,21.972904519481165,0.6817929306101222,-2.0876779692486727
394.6000000000049,22.009965451841037,0.6810215595492226,-2.10005724216422
395.80000000000496,22.047270055148815,0.6772768925123362,-2.1131998636886475
397.00000000000495,22.083416427860826,0.6751175717201316,-2.1279524763666116
398.20000000000493,22.121439066954576,0.6725337861989524,-2.140703886834955
399.400000000005,22.158627303195146,0.6728562577157027,-2.152853553486152
400.600000000005,22.196235770679184,0.6717914144222392,-2.165753764504024
401.800000000005,22.23328200580946,0.6679846275017507,-2.178386039829892
403.000000000005,22.27086838715196,0.6680467623732111,-2.1908741806733785
404.20000000000505,22.30837523515937,0.665851542546152,-2.2035631862143976
405.4000000000051,22.34539182970741,0.6635233250216928,-2.2171828328300123
406.6000000000051,22.38295557614753,0.6647133974557544,-2.2303703515404063
407.80000000000507,22.420167388251233,0.6633915858511377,-2.2436138394886838
409.0000000000051,22.457477605009018,0.6595178018875882,-2.257673710148949
410.20000000000516,22.495100564681124,0.6583438460819435,-2.2715585118483097
411.40000000000515,22.53259530161632,0.6557327866182865,-2.285455962859211
412.60000000000514,22.570100131641595,0.652598566567405,-2.29946608576214
413.8000000000052,22.607325782976684,0.6531158970547357,-2.3142811768140175
415.00000000000523,22.64488944269478,0.6494030980975771,-2.3300809984795894
416.2000000000052,22.682420780169654,0.6455669308918797,-2.344448205824625
417.4000000000052,22.720087677054323,0.6464941153658004,-2.3583184757465228
418.60000000000525,22.757387055007204,0.640591817641762,-2.373377144307005
419.8000000000053,22.79498672538319,0.6411810505058253,-2.389363389775945
421.0000000000053,22.832375100108855,0.6380505645433434,-2.4053678708595707
422.2000000000053,22.870230292099702,0.639465030361853,-2.421174038005525
423.4000000000053,22.907752792486093,0.6389890100945135,-2.4364441191471258
424.60000000000537,22.94533642463637,0.6360314351608971,-2.453145527817939
425.80000000000535,22.9829434243969,0.6347691251875296,-2.4702245657918636
427.00000000000534,23.020877116919095,0.632696484500384,-2.4869643788993563
428.2000000000054,23.058051799721664,0.6345556755982482,-2.503869819332564
429.40000000000543,23.09605475536922,0.6326421807189391,-2.5214294938855364
430.6000000000054,23.133455619867604,0.6339061584537713,-2.5377463708144665
431.8000000000054,23.171091695664714,0.6363027260697012,-2.5558802554103917
433.00000000000546,23.209041597965456,0.635245346192002,-2.5745382601617024
434.2000000000055,23.246811356498544,0.6350709550927236,-2.593494035086976
435.4000000000055,23.284591590367825,0.6365096692975567,-2.611188951286303
436.6000000000055,23.322505205625742,0.6366093139008411,-2.628736903817764
437.8000000000055,23.36018892371119,0.6351981419510695,-2.64669258444
439.00000000000557,23.397791105908137,0.6395494058684312,-2.6643064271112102
440.20000000000556,23.435756882481595,0.6374251186947624,-2.682728629567439
441.40000000000555,23.473386793511708,0.637074408933576,-2.6995776626679824
442.6000000000056,23.510862403295764,0.6403748698488818,-2.71613713772142
443.80000000000564,23.548912707437207,0.6380784999084925,-2.73309342740803
445.0000000000056,23.58673136943077,0.6367811673466457,-2.7493886033614183
446.2000000000056,23.62435203517252,0.6381959630974068,-2.765098124661775
447.40000000000566,23.66253769708488,0.640495882298219,-2.780673374518741
448.6000000000057,23.700477048340392,0.6374714801036208,-2.795558915555167
449.8000000000057,23.738445821599342,0.6363404949075853,-2.8105146956787643
451.0000000000057,23.77615829894305,0.6343419566106259,-2.825893441519985
452.20000000000573,23.81396724191939,0.6327061518806267,-2.8393063440425648
453.4000000000058,23.851811071491458,0.6308047789756555,-2.8525097728176214
454.60000000000576,23.889772973306002,0.6285382286887413,-2.8652952350522503
455.80000000000575,23.927726369385226,0.6232740081874644,-2.877494546985179
457.0000000000058,23.96556733740331,0.616916339787785,-2.8897068044096494
458.20000000000584,24.003658520545656,0.611097304315561,-2.9013384217446743
459.40000000000583,24.041684964720258,0.6043167220455687,-2.9124101862516376
460.6000000000058,24.079769160267986,0.5967330659220766,-2.9227679756902303
461.80000000000587,24.117694075905398,0.5861388440987141,-2.9335198918932086
463.0000000000059,24.1558048003808,0.5751677875124559,-2.9441638691829053
464.2000000000059,24.193786710069098,0.5640788526074936,-2.9524618454426137
465.4000000000059,24.231859443049817,0.5512862095666955,-2.961039832408799
466.60000000000593,24.27004500476992,0.5339580613476893,-2.9707414199995386
467.800000000006,24.307754648546137,0.519481902586683,-2.9794872241930253
469.00000000000597,24.34564096331529,0.5032528839045354,-2.987269501311665
470.20000000000596,24.383896993449785,0.48389268504740546,-2.99553524294336
471.400000000006,24.422138802455233,0.4663514595767022,-3.0033677734703463
472.60000000000605,24.4600835023987,0.4501873064009967,-3.0097887708270914
473.80000000000604,24.498209802244244,0.4311934938023665,-3.016048931955548
475.000000000006,24.536335144111195,0.4141090172405659,-3.0234449850253275
476.20000000000607,24.57431303589679,0.3988131096855059,-3.029106776265318
477.4000000000061,24.612371186169632,0.3801870731751915,-3.0339074806997557
478.6000000000061,24.650806499562236,0.3720888221107883,-3.0394000341479597
479.8000000000061,24.688716240939776,0.3569196267730801,-3.0449625205080757
481.00000000000614,24.726770348975887,0.3422835498140573,-3.0497697844284954
482.2000000000062,24.764919324887654,0.3331185226203064,-3.054315664237925
483.4000000000062,24.802918144313857,0.323557415951619,-3.058263161766606
484.60000000000616,24.841473792862264,0.3176792333232179,-3.0613291199524646
485.8000000000062,24.879725213391016,0.3072849379770024,-3.064799567418115
487.00000000000625,24.917852254241613,0.30186444192314577,-3.068312423322886
488.20000000000624,24.956195013295932,0.29299393413124775,-3.073021697087504
489.40000000000623,24.994523852286324,0.29040793766313167,-3.076753335216219
490.6000000000063,25.032600483983042,0.288109633005432,-3.0797845188343373
491.8000000000063,25.070883075971754,0.28365372091928687,-3.082312874845712
493.0000000000063,25.109325606849897,0.27697826212473364,-3.084033993040685
494.2000000000063,25.147433539663623,0.27645553681250057,-3.0860446093562177
495.40000000000634,25.18599334052727,0.27184569514218104,-3.089216126413847
496.6000000000064,25.224032537469867,0.27302923027244197,-3.092715894115232
497.8000000000064,25.26241415488636,0.26799528832967257,-3.0951494243225186
499.00000000000637,25.30091308182998,0.2666708475550197,-3.0977789770799813
500.2000000000064,25.339138542543648,0.26368418190365217,-3.0996169375646203
501.40000000000646,25.37772261417309,0.26452990910092966,-3.102205069094312
502.60000000000645,25.416093833404044,0.26191874090757206,-3.103865045434371
503.80000000000643,25.454444334871265,0.2587378974236647,-3.1055887736003878
505.0000000000065,25.49282713030955,0.2575417073440187,-3.107445791546006
506.2000000000065,25.531554075833988,0.25580215917036897,-3.110477717438446
507.4000000000065,25.56971865856771,0.2559560840688655,-3.1130474652555233
508.6000000000065,25.60809940235373,0.25661312527298397,-3.1135754113703555
509.80000000000655,25.6467663964715,0.25448349829175565,-3.1160925249240563
511.0000000000066,25.68504385539412,0.2508000568743354,-3.1162715150076035
512.2000000000066,25.723534618086482,0.24925394143227142,-3.1176009862410163
513.4000000000066,25.76179339006292,0.25170903051340865,-3.120000361818832
514.6000000000066,25.800564660467046,0.24962542705463897,-3.1213196512992067
515.8000000000067,25.83917032669615,0.2482971299145229,-3.1229798582861186
517.0000000000066,25.877543904326227,0.2501227607575056,-3.124598157273117
518.2000000000066,25.91607788463992,0.24518091693877309,-3.1262298426234785
519.4000000000067,25.95431140977985,0.2464783157320296,-3.1272475225900265
520.6000000000067,25.993068364320816,0.24537907191094477,-3.1285624671634205
521.8000000000068,26.031615832040213,0.24504744467413597,-3.1299417187997456
523.0000000000067,26.069870466301595,0.24547162895245522,-3.130541746062134
524.2000000000068,26.108586270385903,0.24218515595619938,-3.131350700378721
525.4000000000068,26.14741577172643,0.24562458623296046,-3.1326415497591578
526.6000000000067,26.186117118668594,0.23921029157933416,-3.1352552080119214
527.8000000000068,26.224371012200088,0.2422148725207698,-3.1367067644971627
529.0000000000068,26.263059737328923,0.2419390024663608,-3.138181626385287
530.2000000000069,26.301684445017457,0.24272261010786433,-3.138448024041601
531.4000000000069,26.340380708221083,0.24088209661119864,-3.139765953459918
532.6000000000068,26.37910632928662,0.23963694187657247,-3.1397689558037003
533.8000000000069,26.417842561301143,0.23929597329026175,-3.1420525178546184
535.0000000000069,26.456274044210183,0.234401816496143,-3.1439798764311937
536.2000000000069,26.49495007698014,0.23913189010082347,-3.145271411789992
537.4000000000069,26.533897823761908,0.2390753492151103,-3.146605484752473
538.600000000007,26.572436143530382,0.23871366222665813,-3.1478771886992862
539.800000000007,26.611039589748586,0.2376686710555882,-3.1480948704858847
541.000000000007,26.649719339949268,0.23525017002268722,-3.1491830352258026
542.200000000007,26.688155953230286,0.23354831025115086,-3.151245327784187
543.400000000007,26.727069860980176,0.23356541710427425,-3.15259938718211
544.6000000000071,26.766219040436766,0.23558838730640552,-3.152598322100553
545.800000000007,26.805154630199286,0.23442002034147502,-3.1539085476681112
547.000000000007,26.84350652605617,0.23225441503162036,-3.1552419000098824
548.2000000000071,26.882108769830214,0.2339330002815625,-3.156554260552328
549.4000000000071,26.920841506735105,0.23124827169066653,-3.1564443233021553
550.6000000000072,26.959862299154445,0.23041959208665608,-3.156941607803753
551.8000000000071,26.998530688780335,0.23004036293977292,-3.1591364373772084
553.0000000000072,27.037535968515332,0.2310171600205415,-3.16060187954639
554.2000000000072,27.07637910829981,0.2281854507972656,-3.1609191289105345
555.4000000000071,27.115162150479428,0.22875105465259105,-3.1629874764219155
556.6000000000072,27.154079952556945,0.22936724485871562,-3.164302134280906
557.8000000000072,27.193066954823646,0.22984006816273528,-3.1634393690059524
559.0000000000073,27.23196165068635,0.2292783817657862,-3.1648747569070386
560.2000000000073,27.270830347219167,0.2252184400780568,-3.166161413403246
561.4000000000073,27.30979592741633,0.22691045585864167,-3.1673483674181497
562.6000000000073,27.34878516098318,0.229981468218603,-3.168824516460215
563.8000000000073,27.387983082913763,0.22825519621655155,-3.169784751643051
565.0000000000073,27.426761873982937,0.23051162163886696,-3.1702597418789864
566.2000000000073,27.465658456175625,0.23074934065507757,-3.1715670149079385
567.4000000000074,27.504763684412715,0.22964035202856992,-3.171569931751888
568.6000000000074,27.543714872059564,0.2322172089925092,-3.172738231790788
569.8000000000075,27.582490538186967,0.2333573501618742,-3.1729981847460076
571.0000000000074,27.62175461856791,0.23647531519874532,-3.1742959752124498
572.2000000000074,27.660700293380817,0.23525920030346525,-3.1756336539116123
573.4000000000075,27.699537894240713,0.2344195252185992,-3.1759689626391787
574.6000000000074,27.73886679560398,0.23628291186165407,-3.1769243545987647
575.8000000000075,27.77761736716868,0.23300646774049838,-3.1772811066449114
577.0000000000075,27.81707118500156,0.23323594364689093,-3.1786303557971256
578.2000000000075,27.85611260916385,0.23710645912705175,-3.1785809066153443
579.4000000000076,27.89515721144706,0.2374387116085348,-3.180878724282904
580.6000000000075,27.934267534734733,0.23772995201510194,-3.1826760472288758
581.8000000000076,27.973344427896418,0.23883651591020638,-3.182667875020887
583.0000000000076,28.012636500144964,0.2386851536279737,-3.1839697619029375
584.2000000000075,28.051952707812298,0.23742528466992074,-3.1839681792542436
585.4000000000076,28.090921747750183,0.239577302462473,-3.185273924924485
586.6000000000076,28.130135538977864,0.24202563478847705,-3.1856551553029457
587.8000000000077,28.16927777788476,0.24040741655729536,-3.185301583383466
589.0000000000077,28.20863176341786,0.24244952845582057,-3.185891799101452
590.2000000000077,28.247759389527907,0.23876585113676807,-3.1866104999553664
591.4000000000077,28.287297098753335,0.24102113362071287,-3.1879834191786305
592.6000000000078,28.326669799777296,0.24373597232877953,-3.1889412282811813
593.8000000000077,28.365668615951,0.24209984653483096,-3.190217391690922
595.0000000000077,28.40498856233975,0.2437226910894268,-3.1915311146944196
596.2000000000078,28.444285716844643,0.2460900607439147,-3.192874754894258
597.4000000000078,28.483619395713532,0.24687505285520595,-3.1928641597988663
598.6000000000079,28.52259298439078,0.2487033292992471,-3.1941718249919147
599.8000000000078,28.56193447423276,0.24828384670234405,-3.1954998340766085
601.0000000000078,28.601436536510594,0.2502224920216356,-3.195480081440725
602.2000000000079,28.64091140421691,0.24888678496661454,-3.1966013095112
603.4000000000078,28.680513714507995,0.2526080512661173,-3.195456465696238
604.6000000000079,28.719734645712418,0.2533828653240078,-3.1968068389332114
605.8000000000079,28.75881315778401,0.25108160559644377,-3.1981184558116262
607.000000000008,28.798337764993608,0.2512346004813948,-3.2007496806140923
608.200000000008,28.837239134543534,0.25055414648295926,-3.2009318074703303
609.4000000000079,28.876904797503578,0.24922339328377396,-3.202060881961452
610.600000000008,28.91635276329682,0.24626319776970051,-3.2034211734212823
611.800000000008,28.955887591904332,0.24514739120808215,-3.2048402002770793
613.000000000008,28.995292245605633,0.2429748214890488,-3.2061761828868853
614.200000000008,29.03441651664986,0.2449529805168893,-3.2061680188119173
615.400000000008,29.074039764687882,0.24273760375591702,-3.2074199167832704
616.6000000000081,29.11356146099324,0.24178453019615498,-3.208759248624901
617.8000000000081,29.153093036711915,0.23910097234687577,-3.2094835316003443
619.0000000000081,29.19243082460109,0.24114449293700724,-3.2100700401820763
620.2000000000081,29.231948988056132,0.238009698901267,-3.2106606958444392
621.4000000000082,29.27120600447864,0.23362886891551726,-3.2116186115999765
622.6000000000081,29.310960753137845,0.23664759057236107,-3.2121904740570075
623.8000000000081,29.350455196721445,0.23175326211098057,-3.2126990027085256
625.0000000000082,29.389830514998046,0.233163623600239,-3.21416178390323
626.2000000000082,29.429409982792556,0.23565908249887357,-3.215450296192503
627.4000000000083,29.468478921582342,0.23166417693515196,-3.2179350493094288
628.6000000000082,29.508392694895857,0.2322656341795062,-3.2180767836720015
629.8000000000083,29.547691245497425,0.2328625533009947,-3.2193879977469106
631.0000000000083,29.587384621771058,0.23809440089433775,-3.220243438974705
632.2000000000082,29.62686729187633,0.23717571513149527,-3.220769499254634
633.4000000000083,29.666160078035663,0.2420572951113953,-3.2220301053378018
634.6000000000083,29.705637334281032,0.2406279836100671,-3.2229792836331645
635.8000000000084,29.745325998829724,0.2419142853463312,-3.2220316743948207
637.0000000000084,29.78505826628455,0.24253290447222997,-3.223348193729213
638.2000000000083,29.824131697954286,0.24827931628625843,-3.225276649749561
639.4000000000084,29.86378753469436,0.25117678437402313,-3.2253189304848537
640.6000000000084,29.903282698739105,0.2508802830538619,-3.2266426572579574
641.8000000000084,29.94264331985055,0.25490974601792105,-3.2266427977400083
643.0000000000084,29.982212269684048,0.2559079090496852,-3.227953997042098
644.2000000000085,30.022153298339774,0.25933670108013596,-3.2279499894320898
645.4000000000085,30.061436645180013,0.2637879650440884,-3.2280805467666656
646.6000000000085,30.101064615116982,0.2674489638854911,-3.22992128382483
647.8000000000085,30.140612035630433,0.26779665760195104,-3.230780184518132
649.0000000000085,30.18023339067214,0.26934464687196336,-3.2313513224368466
650.2000000000086,30.219783296474446,0.2724654072356998,-3.232665329618171
651.4000000000085,30.259298065744975,0.276030162560128,-3.2316879224786996
652.6000000000085,30.298794709723467,0.27850499404190043,-3.2316896340124424
653.8000000000086,30.338387353440563,0.2808501595402302,-3.2330042179345577
655.0000000000086,30.378192725015744,0.28112275077255866,-3.2330000563249452
656.2000000000087,30.417692934908867,0.2853153137330202,-3.23385599407257
657.4000000000086,30.457363745281334,0.2868859658549885,-3.2342776982809225
658.6000000000087,30.496774580303207,0.2850377031711784,-3.235629513894361
659.8000000000087,30.536894868199873,0.2866789330241768,-3.2351938080685856
661.0000000000086,30.576436640485383,0.2895738785977304,-3.2356411263491154
662.2000000000087,30.61587913663736,0.2892128634884221,-3.2356525896608233
663.4000000000087,30.655739528388988,0.2911582474418377,-3.2368945699663083
664.6000000000088,30.69521803565107,0.28997280287788807,-3.237929683914753
665.8000000000088,30.734959549300793,0.2908784917642633,-3.239096255845636
667.0000000000088,30.774636405454224,0.2892757208643191,-3.2392499949919187
668.2000000000088,30.814291011017662,0.2879215029060169,-3.2390965942388563
669.4000000000088,30.85381546882363,0.28654328749258773,-3.23791917952286
670.6000000000088,30.893394935945718,0.28959416401672056,-3.239223769708869
671.8000000000088,30.93334275473395,0.2858302144715126,-3.2399002574745417
673.0000000000089,30.97276076153302,0.2892541650909375,-3.2402526820421205
674.2000000000089,31.01253358930003,0.28850350691093096,-3.2412199233354757
675.400000000009,31.052003282455054,0.29157630568515747,-3.2412119904252945
676.6000000000089,31.09167225989243,0.2893031364918146,-3.2425404760178687
677.8000000000089,31.1314851726926,0.2876101807299838,-3.2425406913751145
679.000000000009,31.170736703083342,0.2927406536734316,-3.242539090385286
680.2000000000089,31.210939716780576,0.29190689041355156,-3.242540884218333
681.400000000009,31.250502068202376,0.2910650043770937,-3.243877518698224
682.600000000009,31.29001570109917,0.2946671263460632,-3.245204477765638
683.800000000009,31.32985571695039,0.29414871384712926,-3.245170033263158
685.0000000000091,31.36953147729836,0.29681611932349905,-3.2451849547737908
686.200000000009,31.40897427194635,0.2942687916328919,-3.2451799562862984
687.4000000000091,31.44898052087173,0.293650001410509,-3.245423861493153
688.6000000000091,31.488777689739287,0.29932172742153407,-3.2464900711915874
689.800000000009,31.528607577114137,0.2986078852493672,-3.246489913219901
691.0000000000091,31.568193723274167,0.2912592312867508,-3.2466563731201954
692.2000000000091,31.607769838188535,0.294353899393319,-3.247810390293444
693.4000000000092,31.6477706588322,0.29651702452303796,-3.247810120090569
694.6000000000092,31.687567828640173,0.29026777307659435,-3.2478101203575
695.8000000000092,31.72727969316881,0.29324019248838695,-3.2478110416351247
697.0000000000092,31.76690378409832,0.29165634948413466,-3.247803914652299
698.2000000000093,31.806979225839065,0.28828965678535834,-3.247800110730532
699.4000000000092,31.846522589261962,0.2894606204418082,-3.247836981700944
700.6000000000092,31.886466391295347,0.28610938204013525,-3.249120079856833
701.8000000000093,31.926461291437818,0.28792658912692115,-3.2491199567574203
703.0000000000093,31.96634022530788,0.28799944823408774,-3.2491218331016056
704.2000000000094,32.0063666413551,0.2859355053731196,-3.2504416394724553
705.4000000000093,32.04573003471033,0.2882530780982351,-3.2517781218833055
706.6000000000093,32.08572764564978,0.2906407235726114,-3.2517597967039555
707.8000000000094,32.12559761935747,0.2850179471329284,-3.2520857597617012
709.0000000000093,32.16542742037059,0.2868364960382883,-3.2526893807167663
710.2000000000094,32.20536132607861,0.2799274492845938,-3.2534001161764854
711.4000000000094,32.24538900568955,0.28303841906631444,-3.254005475249147
712.6000000000095,32.2852044120533,0.27849556939440756,-3.25471996944453
713.8000000000095,32.32500282829798,0.27510355579304724,-3.2547325676724066
715.0000000000094,32.36490852937841,0.27666551143281515,-3.254390112066665
716.2000000000095,32.40472205887074,0.2727082019098086,-3.255678903777568
717.4000000000095,32.44462098881213,0.27479161004741615,-3.255700165984976
718.6000000000095,32.48446451372307,0.26988207853822344,-3.25699110607658
719.8000000000095,32.52449621586164,0.27247527447488684,-3.257020147993382
721.0000000000095,32.56459782176693,0.270807272213502,-3.257023874354779
722.2000000000096,32.604354729318665,0.2691209998644566,-3.25831516897656
723.4000000000096,32.644247211944766,0.26562616654466886,-3.257018764062312
724.6000000000096,32.68420638660619,0.2655077534814376,-3.2575462618577293
725.8000000000096,32.724394129113826,0.26427315035459653,-3.257679845080127
727.0000000000097,32.76419387947991,0.2608207978006756,-3.25790421629608
728.2000000000096,32.804275258487216,0.25535244323365225,-3.2596594849261464
729.4000000000096,32.84428196631968,0.2542761777110938,-3.259648791709061
730.6000000000097,32.884040456663115,0.2521230501035041,-3.260978398343384
731.8000000000097,32.92425184844882,0.24831032444416756,-3.2609695607925526
733.0000000000098,32.96392868210402,0.24141798741155984,-3.2597147026556392
734.2000000000097,33.004102497334834,0.23477781459779168,-3.2596409547868035
735.4000000000098,33.044198789467124,0.23037934098014468,-3.260970826935817
736.6000000000098,33.084204916716416,0.2277410221500329,-3.26224944308861
737.8000000000097,33.124377965021345,0.22519083503220516,-3.2622900800739174
739.0000000000098,33.16411682765308,0.22444221879787918,-3.262290092129056
740.2000000000098,33.20398954702856,0.21921065026802422,-3.2622904551840533
741.4000000000099,33.24455834192432,0.2180473283370361,-3.2635808318640795
742.6000000000099,33.28452790634594,0.21492457097853235,-3.2636099486828463
743.8000000000098,33.324713597440216,0.20983260361708211,-3.263607121846728
745.0000000000099,33.36479572341922,0.20851279390312083,-3.2649161095768973
746.2000000000099,33.40499738465347,0.20671013274934458,-3.264919874666446
747.4000000000099,33.44513889374461,0.20476227290062843,-3.2658668309217593
748.6000000000099,33.48539359929188,0.1964635415718421,-3.26467047418991
749.80000000001,33.52549651521425,0.19557032475786595,-3.264589963520108
751.00000000001,33.5655637564393,0.1948350052275556,-3.2649113346607948
752.20000000001,33.605400541662554,0.18961381470196992,-3.264919240264765
753.40000000001,33.6458649722474,0.18992952685223008,-3.265250079837872
754.60000000001,33.68586303064281,0.18861354346280468,-3.2662302752263948
755.8000000000101,33.72599589119953,0.18463169651090539,-3.2669107974679052
757.00000000001,33.766095162506446,0.18328126097806585,-3.2675500116646825
758.20000000001,33.806679240937626,0.18140035789770526,-3.267550027984038
759.4000000000101,33.84659322464467,0.1823340318669442,-3.2675500292288944
760.6000000000101,33.8867656788927,0.1710844192443024,-3.267553910457279
761.8000000000102,33.92699074456451,0.17291619311082984,-3.2688726112653312
763.0000000000101,33.967276027893774,0.1714569386627951,-3.268869909510874
764.2000000000102,34.00767753794522,0.1666720657574463,-3.268917943471907
765.4000000000102,34.04759365652011,0.16691502829184612,-3.268849740522284
766.6000000000101,34.08779067789411,0.16128709362473792,-3.269765783913142
767.8000000000102,34.12803132680919,0.1596195880267861,-3.2701800559899143
769.0000000000102,34.16762835511796,0.16024880061731483,-3.2701801279852516
770.2000000000103,34.20874668087212,0.1538344437113821,-3.2701801494507565
771.4000000000103,34.248558863822545,0.15430494222063107,-3.2702606369190974
772.6000000000103,34.288957243861674,0.15362610762117912,-3.2718677665466904
773.8000000000103,34.328875269918946,0.1548440820500101,-3.2718300088819263
775.0000000000103,34.36930434919174,0.15065078586811786,-3.271829996004829
776.2000000000103,34.40979090904182,0.1495452346411983,-3.27182999599999
777.4000000000103,34.449866751765,0.15118097715877266,-3.271829995968875
778.6000000000104,34.48991043730616,0.1484427088777016,-3.2718299085483427
779.8000000000104,34.53037761737379,0.1460569268081664,-3.2726045197487794
781.0000000000105,34.57026325201982,0.14358613890884264,-3.273141337749232
782.2000000000104,34.61059195845192,0.14326715636091825,-3.27181923229806
783.4000000000104,34.650820624886144,0.14320066754736782,-3.2718287850798946
784.6000000000105,34.69106386899625,0.1424944424620831,-3.273156782848613
785.8000000000104,34.73154255824999,0.1418887467097778,-3.2731509191662553
787.0000000000105,34.77161394061336,0.1426997433169559,-3.273795715664444
788.2000000000105,34.81197364737629,0.14485247257725975,-3.274393761167543
789.4000000000106,34.85232701829262,0.14193833775970655,-3.2751102069321987
790.6000000000106,34.89243464115464,0.1382523355709493,-3.2751102175015907
791.8000000000105,34.93272400429864,0.1405107615037875,-3.276430275595665
793.0000000000106,34.97308456503056,0.137628556456328,-3.2751202192455926