File: 01_Data/Bamboo_Rug_Fabric/STA/N2/30K_min/Bamboo_Rug_Fabric_STA_N2_30KData_220125_R1.csv
##Temp./Â°C,Time/min,DSC/(mW/mg),Mass loss/mg
49.0,10.54998254252611,0.0712188684918652,0.007060946383856237
50.20000000000002,10.744377938356296,0.1291147484631564,0.006030909068275747
51.400000000000034,10.868908260618909,0.173366634993685,0.004668432935089228
52.60000000000005,10.968890464037733,0.21666921684581208,0.006503536360208173
53.80000000000007,11.05504831895567,0.2559998398379496,0.005517706907807174
55.000000000000085,11.132235369884874,0.29259003707516307,0.004901048241140238
56.2000000000001,11.201930555658567,0.32540829272727023,0.0038695464081648367
57.40000000000012,11.267562908324797,0.3537303367515687,0.004250132097095793
58.600000000000136,11.32886326094325,0.37922751215228667,0.004957814456639564
59.80000000000015,11.387524545832465,0.4068961740261333,0.006069735285672007
61.00000000000017,11.444333232854943,0.43070894194972664,0.005616909571629858
62.20000000000019,11.498006275163444,0.455999574663275,0.0060026607232228635
63.400000000000205,11.55141897111536,0.478039309144469,0.006718265625503594
64.60000000000022,11.602375941617646,0.4978160888247629,0.005251846701196605
65.80000000000024,11.653491785734047,0.5174875103307658,0.004559761763907932
67.00000000000026,11.702695648118604,0.5348428639942312,0.004968614515429959
68.20000000000027,11.750887873910049,0.554639908957328,0.00477722953353954
69.40000000000029,11.798390847030303,0.5703816249764648,0.002177241396784879
70.6000000000003,11.84538818763178,0.5838299097314844,0.0021988652035438427
71.80000000000032,11.891699214302704,0.5978552176329517,0.0023734996545510256
73.00000000000034,11.937377111215731,0.6061393048378512,0.002102324491696894
74.20000000000036,11.982980511455116,0.6136794425364316,0.0026327190952017965
75.40000000000038,12.027427842267972,0.6209301642323923,0.002874888109134499
76.60000000000039,12.072132565639974,0.6295200687381194,0.003627338921480483
77.80000000000041,12.11622189437795,0.6330255497453356,0.00436039598359983
79.00000000000043,12.159774700445857,0.6426426939749853,0.003801711318031753
80.20000000000044,12.203811359291052,0.6480843320879534,0.0028401466788645635
81.40000000000046,12.246849775563806,0.6572357176105745,0.0028053647340682275
82.60000000000048,12.289547192897546,0.6650463840550891,0.0026129365196991827
83.8000000000005,12.332353730204442,0.6719236909814454,0.003093623376665633
85.00000000000051,12.37536037677843,0.6804824791251985,0.002725888906587315
86.20000000000053,12.417110875742486,0.6856684846099925,0.0027904506600435752
87.40000000000055,12.45951918035579,0.693788284846323,0.0014239321408160421
88.60000000000056,12.501235042828176,0.7014267305353502,0.001432506534779776
89.80000000000058,12.542913406331316,0.7069349363961157,0.00019328132613027904
91.0000000000006,12.584321208437705,0.7147492091881062,0.0010315338415818331
92.20000000000061,12.626076896283553,0.7209239044172089,0.0013660397367183386
93.40000000000063,12.667233697882578,0.728711337463633,0.0007150535895639187
94.60000000000065,12.708341235125099,0.7341497742623323,0.00010183046072720359
95.80000000000067,12.74973491871438,0.7410943335600515,0.001331362473106612
97.00000000000068,12.79044625050286,0.7478607277251145,0.0013202809454777586
98.2000000000007,12.831078200433335,0.7523670302407199,0.00018620719950135367
99.40000000000072,12.871444646928113,0.7594872747865261,-0.00041797201689330876
100.60000000000073,12.912501637691737,0.7669388045915206,-0.0017657337676006968
101.80000000000075,12.95248574505183,0.7719483588200282,-0.002915910055727444
103.00000000000077,12.993526542262346,0.7772296449894402,-0.0030699002917411455
104.20000000000078,13.03399148007781,0.7833282771493868,-0.0023277628382665227
105.4000000000008,13.074410430587875,0.7875237196267627,-0.0028769184564914063
106.60000000000082,13.115645115858996,0.7914266277873996,-0.003079938887483369
107.80000000000084,13.155908730974621,0.7954814822610649,-0.0030799909821395133
109.00000000000085,13.1961176503234,0.800919414101617,-0.003079992491920258
110.20000000000087,13.236540184438946,0.8044601989863551,-0.0030829147650388578
111.40000000000089,13.276979586754184,0.8081951966675879,-0.0017636627420110074
112.6000000000009,13.315789360312724,0.8111347088796973,-0.0030003022112237154
113.80000000000092,13.35749450860496,0.817068386651011,-0.0030509612892086757
115.00000000000094,13.397610844443651,0.819469280195932,-0.00438986705670974
116.20000000000095,13.437787862526763,0.8207884127181474,-0.004390599216932856
117.40000000000097,13.477351702764832,0.8229077262756765,-0.00570662089544971
118.60000000000099,13.517803552972065,0.8254952687470584,-0.0043589613471524125
119.800000000001,13.55748704442042,0.827130150813393,-0.005699916123747872
121.00000000000102,13.597797002376172,0.8291535767959168,-0.005532170264646474
122.20000000000104,13.637193190066826,0.8308200335928984,-0.004376280597900184
123.40000000000106,13.677425045818408,0.8334273341275258,-0.0056929064363564486
124.60000000000107,13.716865872416063,0.8339334693067432,-0.005699730364456368
125.80000000000109,13.756681471253712,0.837057084876505,-0.005431360275677033
127.00000000000111,13.796282222186099,0.8378814562181669,-0.004393927091745464
128.20000000000113,13.835545430505908,0.8387075399961605,-0.005705483841137671
129.40000000000114,13.874927888544779,0.8432375073052668,-0.005709849260007616
130.60000000000116,13.913846750922046,0.8442977456263553,-0.005678589652844401
131.80000000000118,13.953581818328571,0.846895486060498,-0.004389944676564728
133.0000000000012,13.992866742413794,0.8486676567900582,-0.004396368024433439
134.2000000000012,14.031797902106742,0.853347141124259,-0.006310913115576522
135.40000000000123,14.070507795336278,0.854799130716833,-0.006359918539406539
136.60000000000124,14.109833370089586,0.8574465634037821,-0.0063599289429547845
137.80000000000126,14.14843965687253,0.8624977734365187,-0.006329439917012181
139.00000000000128,14.187060178249123,0.8654237842278141,-0.0076713186640589015
140.2000000000013,14.225913634684161,0.8676651220809043,-0.00635979498518191
141.4000000000013,14.264351109404195,0.8718437002620216,-0.006360052675021599
142.60000000000133,14.302750784616661,0.8766042078167146,-0.0063600531225236345
143.80000000000135,14.340931316841433,0.8800458718639284,-0.006360268456690132
145.00000000000136,14.379703939658182,0.8838363669393579,-0.007363341604776696
146.20000000000138,14.418167493573241,0.8882498419230056,-0.007670091760044961
147.4000000000014,14.456749649401285,0.8918310534578404,-0.007675578257655413
148.60000000000142,14.494551827710525,0.898153685364403,-0.00898617845234817
149.80000000000143,14.532552081333627,0.9019315174086581,-0.009911580718060975
151.00000000000145,14.571018243162227,0.9060499175047421,-0.010299932536031342
152.20000000000147,14.608982689411926,0.9094983826612284,-0.010300954741371271
153.40000000000148,14.647362231473526,0.913592736579502,-0.008978639192290583
154.6000000000015,14.684822785315575,0.9191385288533879,-0.008992931433830176
155.80000000000152,14.723001988412179,0.9246102054589453,-0.01030624605819952
157.00000000000153,14.761079507542902,0.9326974480211563,-0.010309944087468992
158.20000000000155,14.797985271143855,0.9332203006873465,-0.010310288342026741
159.40000000000157,14.835873292839523,0.9349611734896893,-0.008958870451531098
160.6000000000016,14.874671422292446,0.9407754913296391,-0.00898992457242942
161.8000000000016,14.912758496825653,0.9446384752436814,-0.008989944996911525
163.00000000000162,14.950459758759784,0.9505230546350665,-0.008989945000004607
164.20000000000164,14.987800014727563,0.955497274772303,-0.00898994500052197
165.40000000000165,15.024429649440822,0.9598020809199281,-0.008989945317036785
166.60000000000167,15.062808627881283,0.9668500948835201,-0.00898875616824002
167.8000000000017,15.100156959760072,0.9705064828129937,-0.010328345790616034
169.0000000000017,15.138754959532964,0.9790503504404051,-0.01030994629694959
170.20000000000172,15.176387430328596,0.9840180582834321,-0.010309945115334784
171.40000000000174,15.214005710060352,0.9886894737002754,-0.010310174342328171
172.60000000000176,15.251451096520745,0.9938105262228589,-0.011293393276083474
173.80000000000177,15.288832709933468,1.0003237645599532,-0.01295474308976452
175.0000000000018,15.325609271154951,1.0052921096055467,-0.012939855945385048
176.2000000000018,15.36337704283067,1.0120338659549248,-0.012939862068692243
177.40000000000182,15.400867102691036,1.016496742878869,-0.012940077002418615
178.60000000000184,15.438503679654639,1.0220807697192535,-0.013945140027483038
179.80000000000186,15.475192551807776,1.0274377545182056,-0.013919990401749072
181.00000000000188,15.512628730292848,1.0342430970608707,-0.014846952377023825
182.2000000000019,15.54988025508101,1.037248636245983,-0.015240254883492899
183.4000000000019,15.587280155587472,1.0426652371776457,-0.01524015301599091
184.60000000000193,15.624030230741155,1.0469568181210986,-0.015240152999443257
185.80000000000194,15.661257400093128,1.0521068425036002,-0.015240152466599266
187.00000000000196,15.698298503749918,1.059095992594783,-0.015241031507921665
188.20000000000198,15.735150663151932,1.0623226487538235,-0.01660828340804743
189.400000000002,15.77182342741599,1.067800706612898,-0.016560013883230695
190.600000000002,15.809006279226805,1.072062601470639,-0.01656004496983865
191.80000000000203,15.845798444692653,1.077548401668527,-0.016560040444965285
193.00000000000205,15.882684066619206,1.0797645219054721,-0.01656967064741588
194.20000000000206,15.919457921996472,1.0860728841696905,-0.01688921373489194
195.40000000000208,15.956111293238639,1.0887905768688309,-0.01738735181214901
196.6000000000021,15.993208833815586,1.096150555461564,-0.017549155219169776
197.80000000000211,16.029701232975032,1.0994667750341511,-0.018555350372995605
199.00000000000213,16.066319432131678,1.1055789306421662,-0.018540014317149023
200.20000000000215,16.103253796260606,1.1081467384626988,-0.0185399909910835
201.40000000000217,16.139629162048564,1.1124204194279101,-0.018539990999992817
202.60000000000218,16.17644881971779,1.1134228614775914,-0.01853999102965531
203.8000000000022,16.213115489305398,1.1233372036759284,-0.01853998683145308
205.00000000000222,16.249934164800454,1.1249295333804166,-0.018481623233878253
206.20000000000223,16.28642862433406,1.13124818676623,-0.020371475677241513
207.40000000000225,16.323151401086164,1.1366461415936255,-0.0210787709368212
208.60000000000227,16.359544078822072,1.1403956596870994,-0.022159998210483867
209.80000000000229,16.39637144077008,1.1451864581785718,-0.022160117655103395
211.0000000000023,16.43294832380257,1.1521668535702179,-0.022160118280322383
212.20000000000232,16.469445908553865,1.1554072141955842,-0.022160810685791787
213.40000000000234,16.50618511471265,1.161462866965297,-0.023808630701305233
214.60000000000235,16.542419188321954,1.165390593487876,-0.023799350425126597
215.80000000000237,16.578879511194565,1.1713884139043613,-0.02242295234041025
217.0000000000024,16.615514065777766,1.178497197537854,-0.02379458310324356
218.2000000000024,16.651890489439225,1.1823032031852776,-0.023772486721103547
219.40000000000242,16.688479466369383,1.1877633265525964,-0.02509596985940199
220.60000000000244,16.725145503050094,1.1941078606986877,-0.026525510579664235
221.80000000000246,16.7612075379673,1.1982561303181125,-0.027862369492483108
223.00000000000247,16.797943899955055,1.2046225247449889,-0.029193617923878534
224.2000000000025,16.8341864538948,1.2102000323076214,-0.029991082263821855
225.4000000000025,16.870911661549325,1.219961624525114,-0.030303725651458002
226.60000000000252,16.90731292034057,1.2276600334176107,-0.03274483803596695
227.80000000000254,16.943636232721353,1.2349074383221732,-0.03266748356651439
229.00000000000256,16.98025959470397,1.244377631244559,-0.035315160947994695
230.20000000000258,17.016136406815683,1.254958711023935,-0.036616097630040034
231.4000000000026,17.052536753655225,1.2646660693176672,-0.03639475674584691
232.6000000000026,17.08899649427176,1.2780220470341472,-0.036703009622995886
233.80000000000263,17.125277458730466,1.2912880993909468,-0.03818202160901363
235.00000000000264,17.161655792605956,1.3058820867847318,-0.03949242768619765
236.20000000000266,17.198068554089165,1.3231372735748979,-0.03812016044223121
237.40000000000268,17.23443680058721,1.3450958647608127,-0.038233008271933766
238.6000000000027,17.27053470022504,1.3664077751271875,-0.039491705298605684
239.8000000000027,17.307125701566243,1.3935130307767793,-0.03949168696905536
241.00000000000273,17.343514663381224,1.4234709117875233,-0.040771221698850724
242.20000000000275,17.379783272896308,1.4609996968204855,-0.042241285232793135
243.40000000000276,17.416082722216547,1.5048273063520128,-0.04225878799274163
244.60000000000278,17.452420708014827,1.554977523325511,-0.04386261744000297
245.8000000000028,17.48792037480782,1.610575060182731,-0.04618315257095329
247.0000000000028,17.52444959697819,1.676896710782803,-0.047961638755662506
248.20000000000283,17.561876074900894,1.7462373272992622,-0.04961042544131944
249.40000000000285,17.597863427868056,1.807680396961329,-0.05127889116097162
250.60000000000286,17.63434411736749,1.840378490152033,-0.05339678566322581
251.80000000000288,17.67098367020189,1.841944789929342,-0.05474621979344807
253.0000000000029,17.707186612834338,1.8073499727438638,-0.05626687437379596
254.20000000000292,17.743516565875534,1.7489558011863071,-0.0578102254526236
255.40000000000293,17.779733505916603,1.6742076071133856,-0.05974683747164011
256.600000000003,17.815864531204728,1.6006614765205116,-0.06302821718720031
257.80000000000297,17.852265666851423,1.5366417604528468,-0.06560652325807448
259.00000000000296,17.88859976135897,1.479984729865493,-0.06690386074035759
260.200000000003,17.924728258390804,1.435283810549652,-0.06859166385119453
261.40000000000305,17.96086596688765,1.3973352149942029,-0.0722473749560697
262.60000000000304,17.996739980614166,1.3732987239011083,-0.07378288441855929
263.800000000003,18.03329889653147,1.3512256359545587,-0.0756866607026705
265.00000000000307,18.0692129206566,1.3377292199037254,-0.07928675828867915
266.2000000000031,18.104972410442,1.326150017877576,-0.08148331980955614
267.4000000000031,18.141546831594383,1.321915788314343,-0.08452086060434061
268.6000000000031,18.177800777070473,1.3182859840639156,-0.08729722318599098
269.80000000000314,18.213764692267326,1.3176946063900004,-0.0899017690213606
271.0000000000032,18.2499279505062,1.3162585173808792,-0.09247329293909878
272.2000000000032,18.286132169634136,1.3203068530352766,-0.09802977025993664
273.40000000000316,18.322119485334394,1.3226665479201982,-0.10254118513753596
274.6000000000032,18.358456241027614,1.3249396282631398,-0.10780779661369655
275.80000000000325,18.394545724533995,1.329508232956081,-0.11205755996180189
277.00000000000324,18.430945280233157,1.3336573098023279,-0.11669634771553161
278.20000000000323,18.466869775984367,1.3406212896545093,-0.12111104469938105
279.4000000000033,18.503083323343425,1.344051173882924,-0.12606433121978045
280.6000000000033,18.539445587579085,1.3497486238959018,-0.13076031383680053
281.8000000000033,18.57559127255069,1.3559017828447706,-0.1362832188980989
283.0000000000033,18.611780433658637,1.3631080990080249,-0.14136615248988083
284.20000000000334,18.64783227177278,1.3690189433899005,-0.1477521477980548
285.4000000000034,18.684213024011395,1.374264107735676,-0.15289903913322567
286.6000000000034,18.72032509813734,1.377358480714087,-0.15901532773085902
287.80000000000337,18.756738339716698,1.3820100643861175,-0.16561246821347764
289.0000000000034,18.792790351707556,1.3880530764269368,-0.17307967050077888
290.20000000000346,18.82925480609976,1.3926610532452222,-0.18027175761338476
291.40000000000344,18.865460404347253,1.3954128551906688,-0.18820003467384083
292.60000000000343,18.90184221498503,1.3966348801178836,-0.19619310701429082
293.8000000000035,18.937990183219274,1.402287607482326,-0.20458999118989363
295.0000000000035,18.97469212315996,1.4034691276529383,-0.21338613823163044
296.2000000000035,19.01036801882394,1.4052884733102347,-0.2232494568382819
297.4000000000035,19.04697961201546,1.406147023898094,-0.23414456960506103
298.60000000000355,19.083318271509892,1.4078130355079357,-0.24314502592608278
299.8000000000036,19.119462073523916,1.406039760981932,-0.2530020400296564
301.0000000000036,19.155707241339428,1.4043875248565214,-0.2629002019386739
302.20000000000357,19.192148603141895,1.4075609226296666,-0.2745832353445947
303.4000000000036,19.228418477706136,1.409042314724247,-0.2862064582740729
304.60000000000366,19.264472695021638,1.4080213309639,-0.2974466225996575
305.80000000000365,19.300945593409953,1.4091625009029498,-0.3084470724249395
307.00000000000364,19.33717207547818,1.4086578132388854,-0.32003399281052847
308.2000000000037,19.373599242385072,1.4086559640091962,-0.33221293494252624
309.40000000000373,19.410245222564512,1.4109137807020087,-0.3429241263411349
310.6000000000037,19.446183503809646,1.4114682473804843,-0.35117024618877535
311.8000000000037,19.482525174220417,1.414537215354893,-0.3630573881164483
313.00000000000375,19.51888744657716,1.415941319766553,-0.374930494171394
314.2000000000038,19.55540305295003,1.4196114996900862,-0.38594890844665963
315.4000000000038,19.591605859210652,1.4222567884198378,-0.3984514516281563
316.6000000000038,19.627854580418596,1.422906894339949,-0.41278088433554183
317.8000000000038,19.664486257361464,1.428451973575542,-0.42508458685016226
319.00000000000387,19.70122137225192,1.4302442278121315,-0.436783175453471
320.20000000000385,19.737412396236397,1.4346023840493278,-0.4483833168136844
321.40000000000384,19.77336219850815,1.4393571324142949,-0.4617917491641186
322.6000000000039,19.810206942897068,1.4478404918508465,-0.4762486112982276
323.80000000000393,19.84664031265028,1.4553825623855616,-0.48907996128610653
325.0000000000039,19.882770016011566,1.4622769437779872,-0.5030716063986556
326.2000000000039,19.91949846059099,1.4729795513847723,-0.5174093262280084
327.40000000000396,19.955870927342872,1.485737274556514,-0.5304760466927738
328.600000000004,19.992562611585768,1.4937188078435362,-0.5451707998564861
329.800000000004,20.028810135993062,1.5079984092985517,-0.5632396990398267
331.000000000004,20.065451145458038,1.520535476926336,-0.5781526800768293
332.200000000004,20.101777319360593,1.535266196727281,-0.5918692742754716
333.40000000000407,20.138708099722326,1.5550223482076881,-0.605551584078607
334.60000000000406,20.17490848697239,1.5748370820359034,-0.6251152154623667
335.80000000000405,20.211204676511162,1.598124644520655,-0.6426137254306941
337.0000000000041,20.248553668012672,1.6163028915427249,-0.660008253057395
338.20000000000414,20.285228681560547,1.6444598481207353,-0.6780585362009903
339.4000000000041,20.32149350211158,1.673087395594535,-0.6980873159166241
340.6000000000041,20.358322252489085,1.7041933484967422,-0.7197900025328168
341.80000000000416,20.39526395593262,1.742295527910992,-0.7396980517180203
343.0000000000042,20.43171011444136,1.779785332378267,-0.76093643627246
344.2000000000042,20.468399413201915,1.8208144511864448,-0.7854854390584385
345.4000000000042,20.505420284734853,1.8645549627862386,-0.808944834939366
346.60000000000423,20.541930692849682,1.9129770965570538,-0.8333172617749884
347.8000000000043,20.57884829316592,1.9635806759945629,-0.8600925437348668
349.00000000000426,20.61587684707606,2.0206908452326338,-0.8889109378446434
350.20000000000425,20.652520452531988,2.0781194500441487,-0.9200246308333031
351.4000000000043,20.689529263671883,2.142462568217466,-0.9513186568210661
352.60000000000434,20.725745146975683,2.2067019989133696,-0.9833539325407479
353.80000000000433,20.76301758977949,2.2707983782463996,-1.0208535418550397
355.0000000000043,20.799937556606768,2.335988853243763,-1.0611387842509177
356.20000000000437,20.83700563779806,2.3963895827090367,-1.103754812454118
357.4000000000044,20.873777504183824,2.446897366301194,-1.1461483779312327
358.6000000000044,20.911006885395068,2.4838736434706608,-1.1930379108132514
359.8000000000044,20.947730759595366,2.5027581891497848,-1.2434832077106588
361.00000000000443,20.984916055766575,2.499308799400123,-1.2944946690829764
362.2000000000045,21.021954474261097,2.4525861872383956,-1.3462600675021577
363.40000000000447,21.058851543492278,2.3601895289439745,-1.4003736274039214
364.60000000000446,21.095505631038357,2.218224086695937,-1.4569424347329414
365.8000000000045,21.132374743951452,2.045965356312691,-1.5131506268111434
367.00000000000455,21.169200261615643,1.8658460077236698,-1.5629178903348455
368.20000000000454,21.20610054441736,1.6912983004242346,-1.6124795696246226
369.4000000000045,21.242953333259713,1.5202905904867217,-1.6623438418219778
370.60000000000457,21.279662972880917,1.3588399535756237,-1.708711895766204
371.8000000000046,21.31645334721993,1.2089733535765075,-1.747947073217511
373.0000000000046,21.352781719682888,1.0879361095867057,-1.784125251329964
374.2000000000046,21.389705003280255,0.9836579559514149,-1.8170259187501778
375.40000000000464,21.4264314652024,0.9012618952268858,-1.8451611117691833
376.6000000000047,21.463173912895847,0.83232338974806,-1.8683338433299603
377.8000000000047,21.499780080407866,0.7815989185316348,-1.889558240220437
379.00000000000466,21.536767233019667,0.7382377974717447,-1.909338077056952
380.2000000000047,21.5733599662905,0.7065252052357232,-1.9280734786595457
381.40000000000475,21.610256882906125,0.6811198539679928,-1.9432562855073918
382.60000000000474,21.64670038150233,0.6648610562351234,-1.9571421870590844
383.80000000000473,21.6839076549506,0.6539773999492131,-1.9716943624134244
385.0000000000048,21.720872998250268,0.6454939122635575,-1.9851313963747814
386.2000000000048,21.757807828436903,0.6375420974223474,-1.997927168686763
387.4000000000048,21.794863202850927,0.6354120410462452,-2.010711728264022
388.6000000000048,21.831779211080132,0.6328945120425202,-2.022885970853302
389.80000000000484,21.868878350544616,0.6314862139149575,-2.0353135763401617
391.0000000000049,21.905719096569825,0.6311030239769042,-2.0487891705141825
392.2000000000049,21.942559820834543,0.6302314558315751,-2.059784910926422
393.40000000000487,21.97978908210245,0.631808537726692,-2.0720126509892323
394.6000000000049,22.01680445171548,0.6328477976347355,-2.0847126399583833
395.80000000000496,22.053753583767367,0.6355629983421553,-2.0975433957866425
397.00000000000495,22.091033555226762,0.6359313930936479,-2.106752089596391
398.20000000000493,22.128366323070964,0.6373401189776551,-2.1202674525874805
399.400000000005,22.165496551725536,0.640371921172912,-2.135196990194408
400.600000000005,22.202648493012187,0.638710897390337,-2.147503485266065
401.800000000005,22.23966538216456,0.6426801750585165,-2.1602658321269543
403.000000000005,22.277083610837117,0.6429826204108369,-2.1722451822004505
404.20000000000505,22.313907085951964,0.6444901387464765,-2.18362426047002
405.4000000000051,22.35148741439995,0.6461242251978034,-2.196770894000219
406.6000000000051,22.38886036050074,0.6462915002890199,-2.210312214185458
407.80000000000507,22.426051882232123,0.6449121661650659,-2.2256633781455957
409.0000000000051,22.463393518760384,0.6466818784391202,-2.23918567762162
410.20000000000516,22.501062288093777,0.6434876426998819,-2.253890830768891
411.40000000000515,22.53824686617916,0.6467204574997911,-2.268497325568613
412.60000000000514,22.575584433304197,0.64756012385887,-2.2831923537706347
413.8000000000052,22.612907364744295,0.6472612191864902,-2.298081951164669
415.00000000000523,22.65031902329586,0.6453560404012282,-2.312552664976844
416.2000000000052,22.68797347615676,0.6429923545901177,-2.3273351391641928
417.4000000000052,22.725537374741275,0.6438631205431298,-2.341548858644508
418.60000000000525,22.76269600677284,0.6390369091375805,-2.356533363698584
419.8000000000053,22.800125108994383,0.638575145764738,-2.3718016286353665
421.0000000000053,22.837725421820153,0.6380457325173186,-2.3882459401041443
422.2000000000053,22.87514425410765,0.6386153675056114,-2.4040590451515396
423.4000000000053,22.912674956584063,0.635380954069084,-2.4193267291319787
424.60000000000537,22.949279665342203,0.639609849531311,-2.436469076455701
425.80000000000535,22.987537911787467,0.6344758309925047,-2.4563151507520575
427.00000000000534,23.02555858472243,0.6392221285713131,-2.4735097579721943
428.2000000000054,23.063134274354308,0.6404462347508975,-2.49006120234717
429.40000000000543,23.10076067907072,0.6442367953430332,-2.5075880174264724
430.6000000000054,23.13843264636957,0.6487127735058236,-2.5259788862705257
431.8000000000054,23.176142710959045,0.6593053825170647,-2.5464821691730157
433.00000000000546,23.213843515470277,0.6762471073869865,-2.565771795049098
434.2000000000055,23.25136188937464,0.6926653658001183,-2.5821724656601823
435.4000000000055,23.289070956125695,0.6973894434907824,-2.6021069727010966
436.6000000000055,23.327067992010765,0.6989906951915941,-2.623005586610003
437.8000000000055,23.36452143356331,0.7005575733555336,-2.6413999878518393
439.00000000000557,23.402310391677272,0.6954172815657105,-2.6615262056147064
440.20000000000556,23.43990787506301,0.6947932970511674,-2.6801339250468112
441.40000000000555,23.477652779780517,0.6910426501955695,-2.6983009584533484
442.6000000000056,23.516020358588097,0.6846700035432602,-2.715163325038596
443.80000000000564,23.553422642740653,0.6833141026858305,-2.732321793569335
445.0000000000056,23.591104638465495,0.6783049101197562,-2.7492053937614864
446.2000000000056,23.628857972972355,0.675912731678707,-2.764729078338156
447.40000000000566,23.66663941852428,0.6741135973477976,-2.7809671310186834
448.6000000000057,23.704709819267748,0.6726718736981661,-2.796560861935734
449.8000000000057,23.74243024547515,0.6698149890957772,-2.81030159082207
451.0000000000057,23.78027667296576,0.6658817389727185,-2.8244137894129504
452.20000000000573,23.818294402955758,0.6617931733563076,-2.8383491132053087
453.4000000000058,23.856240305844857,0.6559490311912763,-2.851857343666082
454.60000000000576,23.894157866420624,0.6514221517161312,-2.8643623707261328
455.80000000000575,23.932021551916762,0.6493458185479031,-2.8762377881295578
457.0000000000058,23.97000195423341,0.6432536455958306,-2.8879910705299965
458.20000000000584,24.007606767339052,0.6376353759680944,-2.9003272004080296
459.40000000000583,24.045690867046886,0.6276089953408024,-2.911707178989742
460.6000000000058,24.083706989415045,0.6197746668604829,-2.9228485763131986
461.80000000000587,24.12167670783632,0.6119026822664577,-2.933596634619973
463.0000000000059,24.15945887177727,0.5960984169317043,-2.9439326012263463
464.2000000000059,24.197562860050134,0.5841979555015542,-2.9536307578134737
465.4000000000059,24.235753078644272,0.5672067643621466,-2.9643434057089477
466.60000000000593,24.27315851133705,0.5508754423627311,-2.975630500860768
467.800000000006,24.31163975635698,0.5369856657768095,-2.9852280348293165
469.00000000000597,24.349769243801994,0.5155388357103463,-2.9920631329578598
470.20000000000596,24.387747158750056,0.49984608296150546,-3.00007587939147
471.400000000006,24.42603816005599,0.47892727405610147,-3.008577428623551
472.60000000000605,24.463964754803932,0.4599410931157233,-3.0139893647853127
473.80000000000604,24.50202457553195,0.440933037443787,-3.020102236966586
475.000000000006,24.540356933146366,0.4213982285288278,-3.025407537371297
476.20000000000607,24.578381650101882,0.40321142534958887,-3.0312185168525554
477.4000000000061,24.616543022013733,0.38490645607185603,-3.037523055796573
478.6000000000061,24.654361109210182,0.3706284613416524,-3.0439483428004284
479.8000000000061,24.692735700548457,0.35327943090568614,-3.0499560579500176
481.00000000000614,24.730979037438228,0.34245059360216445,-3.0538417578888852
482.2000000000062,24.768978909591304,0.3317469348243871,-3.05840860093254
483.4000000000062,24.807250160086657,0.3218748899273012,-3.0634845061173324
484.60000000000616,24.84557483303403,0.31050365853781825,-3.0688407353878104
485.8000000000062,24.88372909391643,0.3006922789175115,-3.07238210945461
487.00000000000625,24.92205383680083,0.2923148360113501,-3.075952869832065
488.20000000000624,24.960218296583445,0.28538714818380684,-3.079334110629637
489.40000000000623,24.99885272894896,0.2752836765118567,-3.0821444328423464
490.6000000000063,25.036961758784557,0.27471853765156706,-3.084577064108248
491.8000000000063,25.07519703126492,0.2682434411777488,-3.087549222943335
493.0000000000063,25.113489381016063,0.26164878039204886,-3.0902026586462252
494.2000000000063,25.152156530770597,0.25756627029940815,-3.0939194361247573
495.40000000000634,25.19032386442912,0.2540078425532233,-3.0951419541934047
496.6000000000064,25.228685924112188,0.24886254746110126,-3.0975889469908933
497.8000000000064,25.26697758080943,0.2450065918934794,-3.0997633825260538
499.00000000000637,25.305593681191393,0.24278701710546002,-3.1027604416257204
500.2000000000064,25.34391593384968,0.23910569849219954,-3.1051117988669175
501.40000000000646,25.382367824149945,0.2368844888339412,-3.1073499408832674
502.60000000000645,25.421085424113713,0.2339945107670558,-3.109485273336911
503.80000000000643,25.459432271122193,0.22978527711123586,-3.1123227371014206
505.0000000000065,25.497834886384855,0.2319395450265247,-3.1157257269076792
506.2000000000065,25.53641444708238,0.22953585411760313,-3.1175665919424542
507.4000000000065,25.574882732188847,0.22735704242836463,-3.1191718236254076
508.6000000000065,25.613296875555697,0.22536251653432093,-3.1199027008735447
509.80000000000655,25.65160081908688,0.22337769821577358,-3.1225978484536054
511.0000000000066,25.690262732636718,0.22135051844427633,-3.1242070363428236
512.2000000000066,25.728726265536068,0.2209544673423518,-3.1255019481686896
513.4000000000066,25.767157088293484,0.2169157419378014,-3.1270325656382867
514.6000000000066,25.806189461688113,0.21416972890597918,-3.128682211397833
515.8000000000067,25.844652246649588,0.21338530857247529,-3.130932144260753
517.0000000000066,25.882939288932587,0.2135505227895198,-3.1323033792767196
518.2000000000066,25.92144741183338,0.2107853850589989,-3.1336579062070165
519.4000000000067,25.959905167834833,0.20990634069391478,-3.1351538395576726
520.6000000000067,25.99852851703657,0.20617003346308116,-3.1367055167218556
521.8000000000068,26.037081364966888,0.2094303911216211,-3.137802446819219
523.0000000000067,26.075907989173434,0.20580902139964552,-3.1381138114438043
524.2000000000068,26.11426583703679,0.20535918687592325,-3.1396533799910498
525.4000000000068,26.15282411073857,0.2066516125203497,-3.141048511265957
526.6000000000067,26.191448501150273,0.2025295172323427,-3.1425435095359733
527.8000000000068,26.230265823548837,0.20340393767370557,-3.143287400816234
529.0000000000068,26.268993794415596,0.20010686757173524,-3.145229190414234
530.2000000000069,26.307679829266434,0.19988175361396765,-3.1465299720421376
531.4000000000069,26.34636872690148,0.19941457399525242,-3.147402779268857
532.6000000000068,26.385149568524525,0.1990456922196675,-3.148105780740587
533.8000000000069,26.42359905489919,0.19725615102391614,-3.14938901174026
535.0000000000069,26.462289859560006,0.19434714719220803,-3.1519905669572297
536.2000000000069,26.50073335654644,0.1934930435111557,-3.1541846170283985
537.4000000000069,26.53989950650876,0.19233311447906565,-3.155551443725098
538.600000000007,26.57841784915461,0.1963918022679525,-3.1565042122060616
539.800000000007,26.617208734988616,0.1913394620910116,-3.1578644131458597
541.000000000007,26.655779181936673,0.1894115847532496,-3.159174850741048
542.200000000007,26.694700273809172,0.19010869587112778,-3.160014953730111
543.400000000007,26.733361575628344,0.189497150411311,-3.160499684563851
544.6000000000071,26.77130355469854,0.1854527663193779,-3.161920358275152
545.800000000007,26.810899803683757,0.18721640564509046,-3.163465466181016
547.000000000007,26.849838858820124,0.18813078763782642,-3.164584963831933
548.2000000000071,26.888389155827028,0.19188754174988776,-3.1649751968900968
549.4000000000071,26.927497505761053,0.1856790856832924,-3.1663413589943272
550.6000000000072,26.96597974839742,0.18687245856245638,-3.166302007171121
551.8000000000071,27.005048460854763,0.18562565778270423,-3.168939752611514
553.0000000000072,27.044150872360515,0.18482750888714716,-3.1688852160754077
554.2000000000072,27.08282540272489,0.18604321274898394,-3.170259287086027
555.4000000000071,27.12160085306004,0.1835133783430738,-3.170301631570686
556.6000000000072,27.160797601113956,0.18204202752620557,-3.1716966965160847
557.8000000000072,27.199608852005174,0.1849147262901043,-3.1730003653653838
559.0000000000073,27.23877827575099,0.18723793973772107,-3.174294344228504
560.2000000000073,27.277435242078983,0.18602037238582292,-3.1757908497794003
561.4000000000073,27.31644322700586,0.18049522513991345,-3.1770779442714696
562.6000000000073,27.3556114200502,0.18232001815226417,-3.177606202242631
563.8000000000073,27.39466841436976,0.1790704588441352,-3.177505807984094
565.0000000000073,27.43349370887767,0.18078082453911315,-3.1790506280053465
566.2000000000073,27.47231210441607,0.1785576734827672,-3.179683478888101
567.4000000000074,27.511679720948067,0.1805970487994677,-3.181010372915339
568.6000000000074,27.55053397001391,0.17444512654330513,-3.1821121385513322
569.8000000000075,27.58936611170961,0.1765603316265525,-3.1841540744869947
571.0000000000074,27.628796941995166,0.17400776108242177,-3.1856041172077463
572.2000000000074,27.667827842346128,0.17764991368887872,-3.186968851423932
573.4000000000075,27.706604976130876,0.17195831324962296,-3.186926620895142
574.6000000000074,27.74574453641274,0.1696090668702428,-3.1885073780044557
575.8000000000075,27.78526528873244,0.17140767999681694,-3.1913400510429786
577.0000000000075,27.82464869552705,0.17338593140335856,-3.1938664209846306
578.2000000000075,27.86359048339934,0.16951748488080565,-3.194636008828729
579.4000000000076,27.902976262470265,0.16671917377745982,-3.1939562206534475
580.6000000000075,27.94183763689708,0.16597142946573018,-3.1953132111042613
581.8000000000076,27.98113037150658,0.16266454722162726,-3.1960788322459392
583.0000000000076,28.020269605615706,0.16394140460931417,-3.196703592355809
584.2000000000075,28.05948080512402,0.16332123172296087,-3.198292923386302
585.4000000000076,28.098972911874007,0.15932271618137128,-3.2000648916040033
586.6000000000076,28.138278555047357,0.1564418504690437,-3.202175199173533
587.8000000000077,28.177269055136836,0.1579692119986862,-3.2022897873755864
589.0000000000077,28.216457114432245,0.15780382339463817,-3.2020467667765224
590.2000000000077,28.255720166489304,0.15591397647846517,-3.2009696544040898
591.4000000000077,28.295105598036297,0.15263224004058262,-3.2014664175261593
592.6000000000078,28.334515662369704,0.15326968258383933,-3.2010028704855564
593.8000000000077,28.373695718698013,0.1525318000089,-3.2023880962364526
595.0000000000077,28.413133541455977,0.15589039361781443,-3.203709555127225
596.2000000000078,28.45259737238744,0.15563988338973855,-3.204632461835605
597.4000000000078,28.49173267161972,0.15325388608304946,-3.2050057975363195
598.6000000000079,28.531025677855574,0.15373206649403337,-3.206341245082065
599.8000000000078,28.570334263520238,0.15321871088681238,-3.206345528473716
601.0000000000078,28.60960773746731,0.1531856764994839,-3.2076554467901595
602.2000000000079,28.649141501114414,0.15278751353814757,-3.209158406668596
603.4000000000078,28.68839002020979,0.15131301640902706,-3.210538824357875
604.6000000000079,28.728022307368022,0.15105769809522718,-3.2120329729877404
605.8000000000079,28.76726561080313,0.14990422298487238,-3.213086409043332
607.000000000008,28.806670000000267,0.14916533545252597,-3.2133601709999997
608.200000000008,28.846238712498128,0.1496210031858436,-3.214686021260145
609.4000000000079,28.885636144209354,0.14557991713012775,-3.215574557415967
610.600000000008,28.925049257221527,0.14295316727135732,-3.2159999145500056
611.800000000008,28.96454990766909,0.13998235976093865,-3.216778299050177
613.000000000008,29.004042910153554,0.13769521746936797,-3.217306414048842
614.200000000008,29.0433910245316,0.1323884090255112,-3.218623572655344
615.400000000008,29.082558634625396,0.1319330048520595,-3.2186123923490095
616.6000000000081,29.122339648522477,0.13222283670477575,-3.220029883255949
617.8000000000081,29.161422128166794,0.12620918717188978,-3.221212671396239
619.0000000000081,29.20110358691646,0.12273050330401958,-3.221269670195518
620.2000000000081,29.240241879620367,0.11935358166885934,-3.2209554818278914
621.4000000000082,29.28013290224077,0.11969053511711647,-3.221936685545492
622.6000000000081,29.319668494425734,0.1165559661023825,-3.2225673077772203
623.8000000000081,29.359334013473976,0.11404008642250951,-3.2238651724536997
625.0000000000082,29.398585022822292,0.11768138342653423,-3.2251924425973106
626.2000000000082,29.438160762736455,0.11467453469832978,-3.227843262006436
627.4000000000083,29.47756370052922,0.11072993164180023,-3.2292632964189023
628.6000000000082,29.51719334535461,0.11545671110491496,-3.2305995906182137
629.8000000000083,29.556967145069013,0.11395693277749275,-3.2328723857211954
631.0000000000083,29.59660192933099,0.11017333018669184,-3.23343014797841
632.2000000000082,29.635862614066642,0.11255809540338801,-3.2339954655772347
633.4000000000083,29.67547899146415,0.11237718574594613,-3.234913392712729
634.6000000000083,29.714993516351875,0.11382218670120214,-3.2361858590752037
635.8000000000084,29.75439903130077,0.11470779016282195,-3.2374742325249333
637.0000000000084,29.79390682704776,0.11695954002899822,-3.2389054420663554
638.2000000000083,29.83376566029774,0.12090642969699861,-3.2415525481703718
639.4000000000084,29.873062107681008,0.12118900932200183,-3.2415498792053707
640.6000000000084,29.91250843087341,0.12244165535581497,-3.2415498790085264
641.8000000000084,29.952132419730546,0.12253098832195564,-3.2415499055026604
643.0000000000084,29.991818089717455,0.12405688240346513,-3.241777469407981
644.2000000000085,30.03136723837882,0.1287049211923872,-3.2425407808398297
645.4000000000085,30.07050758255367,0.1340230272135805,-3.2438856392903452
646.6000000000085,30.11019449239855,0.1356403844910563,-3.2441462473310847
647.8000000000085,30.149756199371623,0.13381252700570068,-3.245860583641938
649.0000000000085,30.189271645886254,0.1400294634292909,-3.2457240201121524
650.2000000000086,30.22859034552828,0.14222262170725597,-3.2459539560190125
651.4000000000085,30.268158445527664,0.1468968658310188,-3.247463421230004
652.6000000000085,30.3078419613403,0.14772122423906353,-3.248847074723799
653.8000000000086,30.347478958809255,0.1496498155136261,-3.250564622459372
655.0000000000086,30.386932141076606,0.15092782590353093,-3.2505499854521074
656.2000000000087,30.426604938562683,0.15019086893323497,-3.2505528670075354
657.4000000000086,30.465980904001515,0.15513082427929104,-3.2492399429944516
658.6000000000087,30.505712869612196,0.15428508230594473,-3.247909469540006
659.8000000000087,30.545295402273155,0.15537963426905588,-3.2479097627520543
661.0000000000086,30.584956439378043,0.15788666354290504,-3.2488387508852
662.2000000000087,30.624477913406718,0.15493559005866153,-3.250549829867963
663.4000000000087,30.664055313174956,0.15982522637189556,-3.2505538068608684
664.6000000000088,30.70361750918198,0.16026198485789633,-3.2525427342142086
665.8000000000088,30.74300241773993,0.15816936751664112,-3.253180531241164
667.0000000000088,30.78251683716833,0.15951688591342683,-3.255142025068613
668.2000000000088,30.821973745665975,0.16038532820124973,-3.2554798469538846
669.4000000000088,30.86163247001288,0.15950414480128972,-3.255479130903885
670.6000000000088,30.901307124874123,0.1620631139530675,-3.2568145704606017
671.8000000000088,30.941003836204,0.15827587647751318,-3.256800440922121
673.0000000000089,30.98089854611484,0.15758019837907078,-3.2554687201758803
674.2000000000089,31.02025988269136,0.15956314923980797,-3.25548108509017
675.400000000009,31.060222144860617,0.1575021707593698,-3.254858276476559
676.6000000000089,31.099563838264885,0.15466900392286975,-3.256717438449084
677.8000000000089,31.139367219157457,0.15496817762275317,-3.256792696030317
679.000000000009,31.178869904166625,0.15735987732786638,-3.2588362146504504
680.2000000000089,31.218956420559625,0.15766095865360175,-3.2603924204205508
681.400000000009,31.258350864011838,0.1577030737033973,-3.261180019225263
682.600000000009,31.298108451272967,0.1540498161196222,-3.261179910935065
683.800000000009,31.337572969980243,0.15109310183934666,-3.261179552953162
685.0000000000091,31.37732990908273,0.15374088902770522,-3.2599394807033555
686.200000000009,31.41714139360946,0.15143524035252476,-3.2598659646956456
687.4000000000091,31.45690260024492,0.14993088574058078,-3.259926766761669
688.6000000000091,31.496555607155102,0.14724310920251238,-3.2598277020988498
689.800000000009,31.535973638182327,0.14680201382781854,-3.262504061656374
691.0000000000091,31.57598771565381,0.1462007659714586,-3.262696251619724
692.2000000000091,31.615786373736427,0.14491126587208658,-3.263807989592715
693.4000000000092,31.655514167823146,0.1410851291287818,-3.264812225546344
694.6000000000092,31.695494401930546,0.14172285914975413,-3.263824613898044
695.8000000000092,31.73522718495156,0.1379969716077296,-3.263825964511084
697.0000000000092,31.775171298081823,0.13829820686883387,-3.264149204534349
698.2000000000093,31.814856802630956,0.13766509154182227,-3.264152164105443
699.4000000000092,31.854641066755846,0.1338587538619418,-3.2657138690966905
700.6000000000092,31.89456609235965,0.13178265736673556,-3.2652979396890736
701.8000000000093,31.934519539312827,0.12768494387361473,-3.2637081957110277
703.0000000000093,31.974316358111448,0.12571135505584285,-3.2623462483488903
704.2000000000094,32.01413704596497,0.12184312980713674,-3.263698374492799
705.4000000000093,32.05387029615961,0.1226941476292156,-3.2651396390931327
706.6000000000093,32.09403307560404,0.11999579554038498,-3.2655221641776677
707.8000000000094,32.13392878492761,0.11790400878027807,-3.26644986386604
709.0000000000093,32.173873130026784,0.11465466756507947,-3.2677812808940385
710.2000000000094,32.213363740983795,0.11296887898429331,-3.269200752682328
711.4000000000094,32.25371689092424,0.11047907588479733,-3.2705092807330294
712.6000000000095,32.29349951921795,0.10824731777455199,-3.2705099359158223
713.8000000000095,32.33360332161222,0.10967115455645349,-3.2705100088670105
715.0000000000094,32.37367590181202,0.10846519987988668,-3.271835532866727
716.2000000000095,32.41373681783776,0.10364160310197867,-3.2733752850220856
717.4000000000095,32.4534977676362,0.10034429447780457,-3.273357729146875
718.6000000000095,32.4934656457584,0.09586618531478619,-3.274680037312768
719.8000000000095,32.53353276700815,0.09564109016236033,-3.274680144425779
721.0000000000095,32.57352971603791,0.09234470560162178,-3.2746810781055524
722.2000000000096,32.61332965683092,0.09221467248848692,-3.2733609475829946
723.4000000000096,32.653461113902445,0.09081939135607442,-3.2746800638635625
724.6000000000096,32.693598924494424,0.08687144079651565,-3.2743482277348503
725.8000000000096,32.73363632274953,0.08664930633328138,-3.2742788415428064
727.0000000000097,32.77357020463853,0.0800449117080464,-3.273250000279245
728.2000000000096,32.81346227641337,0.07625323837469322,-3.273261310320997
729.4000000000096,32.85336363092051,0.07668332481916362,-3.271929969300988
730.6000000000097,32.893620475312936,0.07530395667668444,-3.2719299530018837
731.8000000000097,32.93369532050532,0.0701920703813248,-3.271929960125476
733.0000000000098,32.9735521835935,0.07358787298263714,-3.2719411123978057
734.2000000000097,33.013824926227066,0.07321678138313636,-3.2732500603694996
735.4000000000098,33.05374153864446,0.06481794573087818,-3.2745862048455674
736.6000000000098,33.09426822914916,0.05783216082033782,-3.274569870122331
737.8000000000097,33.134059666531236,0.06002214739804801,-3.2758894685503415
739.0000000000098,33.17411793744467,0.0540064169701564,-3.2758831013310004
740.2000000000098,33.21437142139435,0.049213772100605624,-3.2772026296998784
741.4000000000099,33.25430860584292,0.047983311607034285,-3.2772206074195256
742.6000000000099,33.294168600216246,0.04071166382992164,-3.2785096501293083
743.8000000000098,33.33430397462182,0.038053997987753,-3.278509953335872
745.0000000000099,33.37459846056103,0.033896327008148486,-3.2796009993632245
746.2000000000099,33.41468562075227,0.027285033156201344,-3.2798301323661723
747.4000000000099,33.45506689391327,0.028420432657002337,-3.279830152940256
748.6000000000099,33.49469269423525,0.025587893081907787,-3.2798300492629764
749.80000000001,33.53485097843165,0.025283177043778693,-3.2806818946717202
751.00000000001,33.574904215780954,0.019606809073905218,-3.2811897068085876
752.20000000001,33.61474345848833,0.015281140693473194,-3.282459742064641
753.40000000001,33.65488890184584,0.012265750119769603,-3.2825612832431665
754.60000000001,33.69503074256987,0.009755240469449866,-3.285186522412205
755.8000000000101,33.73525860534744,0.007400974281752237,-3.2859698836511058
757.00000000001,33.77512344052084,0.008557855222997013,-3.2859700189577032
758.20000000001,33.81569203936594,0.0015928912663500938,-3.2859700187290994
759.4000000000101,33.85580891487266,0.002158279747703329,-3.285969271203475
760.6000000000101,33.89557470800191,0.00030106962749254507,-3.284486201915671
761.8000000000102,33.935669389723614,-0.007519403718489581,-3.2845486148643985
763.0000000000101,33.976116876756045,-0.004676114096162642,-3.2838974097906304
764.2000000000102,34.015960714856995,-0.005322920433437517,-3.283560637442738
765.4000000000102,34.05624834493776,-0.003627763974021647,-3.2842058065199153
766.6000000000101,34.09622458332575,-0.005162612655256638,-3.2866553912707075
767.8000000000102,34.13617826859931,-0.00944944921694324,-3.2879342687122115
769.0000000000102,34.17619358502222,-0.008422367139821585,-3.287729601567369
770.2000000000103,34.21661733981456,-0.013783219238027833,-3.2859617073724374
771.4000000000103,34.25629979936872,-0.013616646541792399,-3.2846830882037223
772.6000000000103,34.296314733510535,-0.012568932350117912,-3.283351330083793
773.8000000000103,34.33669831836136,-0.011964709545284613,-3.2847869311255913
775.0000000000103,34.377017605905266,-0.01739792609475721,-3.2860933508559986
776.2000000000103,34.41692967515412,-0.016223341449063344,-3.2860903135923016
777.4000000000103,34.45691134427978,-0.019877857583571412,-3.2873049242761105
778.6000000000104,34.497421801814184,-0.01942542255443458,-3.287380610247109
779.8000000000104,34.53762771529985,-0.017010786688137713,-3.2887213904566983
781.0000000000105,34.57741076571979,-0.023204833284180104,-3.2875835576608847
782.2000000000104,34.617802061625035,-0.022101647609197084,-3.2860777419466407
783.4000000000104,34.6581066976137,-0.02254282817691866,-3.286093771237536
784.6000000000105,34.69811306589945,-0.02015111306019124,-3.2875083005205736
785.8000000000104,34.73857722901215,-0.024718006694963268,-3.2888242804840173
787.0000000000105,34.778828755155814,-0.025066877556792377,-3.2888301492551113
788.2000000000105,34.819251422684474,-0.025697862072254107,-3.288830106974043
789.4000000000106,34.85955683224327,-0.029376990987136864,-3.2897701989069565
790.6000000000106,34.89943891997053,-0.02991124936856515,-3.2901381325945414
791.8000000000105,34.93986129319308,-0.03145111861992911,-3.2911298400691105
793.0000000000106,34.980268645195785,-0.033004447731842745,-3.2911299871006565