File: 01_Data/Concrete_Block/STA/N2/10K_min/Concrete_Block_STA_N2_10KData_220912_R1.csv
##Temp./Â°C,Time/min,DSC/(mW/mg),Mass loss/mg
51.0,10.89,0.03138433609600999,-0.00886494706188401
52.100000000000016,11.212853353780002,0.05835288445976894,-0.010151342161058174
53.20000000000003,11.446866000137351,0.07341035784386007,-0.010369740392399684
54.30000000000005,11.649860117822408,0.08927378095668059,-0.010294937678069438
55.40000000000006,11.829143899719966,0.09630457037679174,-0.011536132607339766
56.50000000000008,11.999690264557602,0.10437658769786906,-0.011172728247250241
57.600000000000094,12.160621413927354,0.11320711218642643,-0.009962753531926438
58.70000000000011,12.315049958853708,0.11829242744219459,-0.008790147922040248
59.800000000000125,12.463488888944424,0.12410098411558157,-0.011528164267205376
60.90000000000014,12.609257875228325,0.1272095861065461,-0.010572363246341254
62.000000000000156,12.750476613621489,0.13410451866572037,-0.011235505876782348
63.10000000000017,12.890000000000024,0.14016427593098135,-0.011614287602073503
64.20000000000019,13.025970051025629,0.14301650494857365,-0.011831797564995306
65.30000000000021,13.161631487820916,0.14594334796317066,-0.012269573502145192
66.40000000000022,13.293884494736739,0.15043456514345221,-0.011738746224652985
67.50000000000023,13.42413975298207,0.15177217837313206,-0.011621513237684233
68.60000000000025,13.553740600341168,0.15515355260075392,-0.012014936273469168
69.70000000000027,13.682795244606707,0.15903637901798373,-0.012037401909494427
70.80000000000028,13.811615870888799,0.16095861511740606,-0.012747913767227281
71.90000000000029,13.9364944223356,0.16642495165794446,-0.012825927456488806
73.00000000000031,14.058409805788866,0.16729423853379588,-0.01149700802166187
74.10000000000034,14.183032680191413,0.17310543231444886,-0.012825236418021468
75.20000000000034,14.30517307054741,0.17519484417779563,-0.012781922649442556
76.30000000000035,14.428572213696098,0.18088272353021917,-0.013255571574881664
77.40000000000038,14.547927018522044,0.1829722521635807,-0.014140479023231123
78.5000000000004,14.66678453509135,0.1855259686023042,-0.013753022942578852
79.6000000000004,14.78667753893656,0.18912847638344055,-0.014237786321336543
80.70000000000041,14.905109012074675,0.19178177808735386,-0.01425006136676732
81.80000000000044,15.02247741435665,0.19304599760556418,-0.015470147730251682
82.90000000000046,15.138914466998697,0.195807877866102,-0.01418513300919777
84.00000000000047,15.256094706836043,0.19902829449992876,-0.014522902083677458
85.10000000000048,15.370602902830763,0.2009383582174885,-0.015455861176111974
86.2000000000005,15.48531166018203,0.20066980044787341,-0.01589771229787118
87.30000000000052,15.601180035934435,0.20358249608118895,-0.016267225011444175
88.40000000000053,15.713131627159012,0.20737485939461564,-0.016820658242093778
89.50000000000054,15.827141533378738,0.20741236958757203,-0.016435763644075507
90.60000000000056,15.94144880852528,0.20758590350349249,-0.018035894468158453
91.70000000000059,16.047813136353497,0.21063182796461122,-0.015543729006281204
92.8000000000006,16.163320304522784,0.2126554006935839,-0.0194021653757801
93.9000000000006,16.27441565505692,0.214702148060695,-0.02075205312729622
95.00000000000063,16.384525200778373,0.21545548500081813,-0.01946112480944784
96.10000000000065,16.496139237388615,0.21864526955619024,-0.019420837919259526
97.20000000000066,16.607802866251376,0.21775198023355014,-0.01972058963200407
98.30000000000067,16.71652438873907,0.2195266104340159,-0.01997709713400031
99.40000000000069,16.826184980007966,0.22058139099513208,-0.02075748895315499
100.50000000000071,16.93509574855411,0.22004406093777285,-0.020740909640426075
101.60000000000072,17.043949213191844,0.22322416295379433,-0.021816671676070598
102.70000000000073,17.153645145671852,0.2219948399679592,-0.02206015796068339
103.80000000000075,17.26166156377056,0.22388837593879896,-0.02208574607517022
104.90000000000077,17.371154026348915,0.22555721975062115,-0.0233060101499607
106.00000000000078,17.479813378032844,0.22553506754868735,-0.02338015704243901
107.10000000000079,17.586188993301324,0.22903381972132708,-0.02338155618255211
108.20000000000081,17.695219659531382,0.2281421088753669,-0.024699948288627205
109.30000000000084,17.802866780654067,0.23009779332241598,-0.024697683371806
110.40000000000084,17.91000000000009,0.2302145798685582,-0.02601935320568849
111.50000000000085,18.018798386128744,0.2318211244154088,-0.024843239485419666
112.60000000000088,18.126128376095455,0.23097150665496624,-0.02470015414846216
113.7000000000009,18.2337203422252,0.2341646005928001,-0.02462083548726568
114.8000000000009,18.34140377365345,0.23219757939177155,-0.02600995498564096
115.90000000000092,18.449674979613473,0.2316586546410454,-0.026010056132053982
117.00000000000094,18.557009493761555,0.23193026312103182,-0.02633981562431309
118.10000000000096,18.664918159169755,0.2311913607795104,-0.027350674443511025
119.20000000000097,18.768776572210008,0.2310891238716365,-0.02734218133739752
120.30000000000098,18.87791605891168,0.2308475816772525,-0.028647363857451147
121.400000000001,18.984574069143203,0.23072097372013156,-0.028327681555594175
122.50000000000102,19.09021061504563,0.22763396375671074,-0.02865196139787063
123.60000000000103,19.197771534775228,0.2283503311976981,-0.029960364385416938
124.70000000000104,19.304193265725267,0.2300236696777581,-0.028650927565378126
125.80000000000106,19.41200107549502,0.22761249475371914,-0.028575488877746302
126.90000000000109,19.517616103229848,0.22807466148781286,-0.029966051143589745
128.00000000000108,19.624229925856213,0.22916362693994485,-0.029631055464563794
129.1000000000011,19.73049419781664,0.22830685892709413,-0.029874497312896153
130.20000000000113,19.83559954959957,0.22835415629269262,-0.03128004398388917
131.30000000000115,19.941379559164027,0.22808273967197978,-0.031318709095036645
132.40000000000117,20.048935934896914,0.2289532754376954,-0.03130352294288752
133.50000000000117,20.154317152821303,0.22724244642104696,-0.03161375798506416
134.6000000000012,20.25963286000132,0.2258217260272789,-0.03126574777147795
135.7000000000012,20.363166145441582,0.2279664421510278,-0.031768546586063096
136.8000000000012,20.470638081180585,0.22636939954050672,-0.030246649861576103
137.90000000000123,20.576505532302935,0.22564545783135592,-0.031128527519904914
139.00000000000125,20.682267817769954,0.22509854315318645,-0.033397139737990855
140.10000000000127,20.786974995167164,0.22702649997314062,-0.03338997844386604
141.2000000000013,20.89226249839847,0.2243356884228611,-0.03193996111735764
142.3000000000013,20.99840186066337,0.22451000214309758,-0.03227107945487884
143.4000000000013,21.103213657213356,0.22539701115750044,-0.0336441109039578
144.50000000000134,21.2078029595049,0.2266630254318549,-0.0329399133682049
145.60000000000133,21.31266460046697,0.22604081789707453,-0.032280086233862804
146.70000000000135,21.41715328600865,0.22505648449899496,-0.03359004875773497
147.80000000000138,21.52338267101139,0.2259206775096515,-0.033938934867951076
148.9000000000014,21.628058465743116,0.22582669202815642,-0.03360253583396755
150.00000000000142,21.732137928747683,0.22676895616727832,-0.035217691089214576
151.10000000000142,21.83767347165094,0.22789734008658746,-0.034589858355459135
152.20000000000144,21.941882396098453,0.2279981687134366,-0.03455334105647179
153.30000000000146,22.046240900427126,0.2270522894375323,-0.03587475471610091
154.40000000000146,22.150791693536878,0.22687136972794353,-0.03489969467071319
155.50000000000148,22.255791508535047,0.22729428470344804,-0.036220081699697815
156.6000000000015,22.360261819962215,0.227393263375529,-0.03622060467818766
157.70000000000152,22.46378571230197,0.22637406047197128,-0.036228554663761514
158.80000000000155,22.56919789709611,0.22548657021419338,-0.0355663996994684
159.90000000000154,22.67404894005424,0.22574121291737537,-0.03623571783906154
161.00000000000156,22.77926905645976,0.22575908443071735,-0.03754318750912233
162.1000000000016,22.884650104678872,0.22524934109243022,-0.03621995033872061
163.20000000000158,22.986491161655785,0.2270113531735487,-0.036219980254641015
164.3000000000016,23.09015074444349,0.22765198782583618,-0.03623461217794777
165.40000000000163,23.197479307642094,0.22726785769401991,-0.037068820261731084
166.50000000000165,23.301079413895913,0.22740447741031056,-0.03753471175169043
167.60000000000167,23.40653284488734,0.22516937026431671,-0.03753970475968149
168.70000000000167,23.51116175228386,0.22628463636654916,-0.037540081891311416
169.8000000000017,23.615597039267218,0.22636934028344102,-0.03753284711651084
170.9000000000017,23.71965761094488,0.22557689099411654,-0.038973122113378444
172.0000000000017,23.824333366623495,0.22400881356989094,-0.037649827487696186
173.10000000000173,23.929998991790832,0.22597791835014552,-0.03764526568560278
174.20000000000175,24.03468040945438,0.22635444099745172,-0.0379805585803652
175.30000000000177,24.13902525298225,0.2239616750662956,-0.0389681040925014
176.4000000000018,24.24475269873941,0.22198306165300857,-0.037617128279187284
177.5000000000018,24.349740082820038,0.22288196948826405,-0.0390617643503397
178.6000000000018,24.453686212566407,0.22351640820992652,-0.03896995931027103
179.70000000000184,24.558998444244608,0.2252406986831113,-0.039346958356507145
180.80000000000183,24.663932319827953,0.22505695288247085,-0.04029002295791351
181.90000000000185,24.768457702483452,0.22667312434940456,-0.03896909985750341
183.00000000000188,24.872874956282008,0.2269375371076371,-0.03863986967980804
184.1000000000019,24.9780285747464,0.22698174990832687,-0.03996016547444903
185.20000000000192,25.081553071200535,0.2256072659120698,-0.04127988224776313
186.30000000000192,25.18678084070695,0.22652824894903117,-0.03995958970711477
187.40000000000194,25.29134006542944,0.22636464402535894,-0.04118414428200179
188.50000000000196,25.394649945194907,0.227801631879835,-0.04028008562830454
189.60000000000196,25.49926915491479,0.22898994556280694,-0.040427899170262016
190.70000000000198,25.60426123087536,0.2272807808524444,-0.04160009692768263
191.800000000002,25.707204371482476,0.22812621309950393,-0.04129681117463235
192.90000000000202,25.813564512482802,0.22885435735058035,-0.04127998419923262
194.00000000000205,25.918019141812895,0.22795619872397027,-0.04128001958192673
195.10000000000204,26.021959569536598,0.22907779569530373,-0.039953389601950384
196.20000000000206,26.12567976147874,0.229069619491178,-0.04128015042755795
197.3000000000021,26.23029886505476,0.22910516384049884,-0.041280138153616974
198.40000000000208,26.3350475471765,0.2280661468929776,-0.04255844864623448
199.5000000000021,26.439209688234126,0.2290898237488589,-0.04126990051626045
200.60000000000213,26.54388292486348,0.22848609892201582,-0.04228795442824573
201.70000000000215,26.64759800051208,0.22885161105644874,-0.04103985447871672
202.80000000000217,26.75229313652002,0.22757821590322785,-0.04126231292877858
203.90000000000217,26.85738944057022,0.22940713687038006,-0.040170035887122424
205.0000000000022,26.961585387735123,0.22855661105889874,-0.04259892679821675
206.1000000000022,27.066259021283678,0.2299796111468247,-0.042624115236608695
207.2000000000022,27.170202425884135,0.22986227623791777,-0.042600029029871145
208.30000000000223,27.27518787110222,0.23162872913074628,-0.041245873656736265
209.40000000000225,27.379811118772828,0.23004540605377766,-0.04291540320672471
210.50000000000227,27.484256887761948,0.23052329864071414,-0.042919841068114195
211.6000000000023,27.587600165244755,0.23082172650152272,-0.04291984027629692
212.7000000000023,27.69189473435469,0.23008090616520305,-0.042859372901566495
213.8000000000023,27.797359080228105,0.2311408213710769,-0.04258999309584244
214.90000000000234,27.901709645396764,0.2281356456922205,-0.042927024945596415
216.00000000000233,28.00432948839128,0.23197911475685223,-0.042929873608952285
217.10000000000235,28.10980498104215,0.2309660160796954,-0.043916984903589196
218.20000000000238,28.213784606764577,0.23256830978488024,-0.044239606513525764
219.3000000000024,28.319805343549035,0.2340292422668533,-0.044240154969426015
220.40000000000242,28.423434915135424,0.23591799774261996,-0.04329923046820827
221.50000000000242,28.528123691125558,0.23635832318731959,-0.04424016474962933
222.60000000000244,28.63311811239856,0.23509428510092806,-0.044227932304847783
223.70000000000246,28.73658282821742,0.23720651753027505,-0.042590834924105536
224.80000000000246,28.83918615662023,0.23769494952968645,-0.0435800540688831
225.90000000000248,28.94481078087084,0.23765482506381191,-0.04354499059450756
227.0000000000025,29.050090493639043,0.23948179432911093,-0.04493520102127224
228.10000000000252,29.153990427513907,0.23611916751589046,-0.0462052251515388
229.20000000000255,29.257690615136006,0.23591136153972275,-0.045692633184128084
230.30000000000254,29.36289075444529,0.23793661487577872,-0.04539699883093817
231.40000000000256,29.466998413863465,0.23765013176332989,-0.04391145300561217
232.5000000000026,29.57121331552044,0.2375186210759091,-0.04388351848241889
233.60000000000258,29.675890401772726,0.23586198211086445,-0.043615396896973024
234.7000000000026,29.780836931849016,0.23572712702451382,-0.0449186057351838
235.80000000000263,29.884993670774183,0.23415044979618255,-0.045205620319388906
236.90000000000265,29.988460770833566,0.23428844365830154,-0.04522000509777957
238.00000000000267,30.093022777677817,0.23271791483082055,-0.04523134209314961
239.10000000000267,30.197175480182704,0.23396495799608946,-0.0462101269740991
240.2000000000027,30.2991092243227,0.2327885124164103,-0.04653259658632436
241.3000000000027,30.405350717363522,0.23615008442380592,-0.04654012700213883
242.4000000000027,30.510630294311238,0.236786114700609,-0.04654002342944885
243.50000000000273,30.613028778531948,0.23719478792278081,-0.045229919918391204
244.60000000000275,30.718903758649923,0.23619310569989432,-0.04655015170064569
245.70000000000277,30.822032536629884,0.23732167190311027,-0.04655010000001791
246.8000000000028,30.9275224205332,0.23645188121121324,-0.04655010011255367
247.9000000000028,31.03136940603059,0.23862474028701242,-0.04651044986549113
249.0000000000028,31.13652851468796,0.23470409201778458,-0.046536218123261364
250.10000000000284,31.242171600766074,0.23731626277301449,-0.04719618279783688
251.20000000000283,31.3449038581394,0.2375248898527218,-0.04719956458317487
252.30000000000285,31.44925586817461,0.23731734550818712,-0.04720013099985021
253.40000000000288,31.554958651109036,0.23712544296552146,-0.04720030252242502
254.5000000000029,31.659044832622374,0.23576054689852394,-0.04687003537622303
255.60000000000292,31.764765666920244,0.23546718503126074,-0.046870275523494875
256.7000000000029,31.868507036407042,0.2363817138127734,-0.04818961069071115
257.8000000000029,31.97274508667078,0.23584449077539849,-0.047199913572315566
258.90000000000293,32.07884196815385,0.23483145593130206,-0.04840173813257387
260.00000000000296,32.181957059325,0.23531689912356707,-0.049840135842881494
261.100000000003,32.28865191200782,0.23737982707594757,-0.04897983617710544
262.200000000003,32.39298658118449,0.23606727684602946,-0.0471997786532814
263.300000000003,32.49770256867697,0.23579366323525575,-0.04851938683720647
264.40000000000305,32.601622180689716,0.2363698031899209,-0.04713950537324241
265.50000000000307,32.70755625050721,0.23436392862647815,-0.04918016128376479
266.6000000000031,32.811987700768874,0.23604472844721325,-0.04845903628998105
267.7000000000031,32.91686686712724,0.2380697930646541,-0.04852107189668242
268.8000000000031,33.020771745757045,0.23625549053383382,-0.04719759697886605
269.9000000000031,33.125552664169064,0.23911537765650293,-0.04720109140793394
271.0000000000031,33.23190975328141,0.23743237349109342,-0.04983782853738372
272.10000000000315,33.33489841166243,0.23855009989349768,-0.04851999681942232
273.2000000000032,33.44123116914316,0.2379072386323855,-0.04852000899997222
274.30000000000314,33.54550899903693,0.23802935179023088,-0.04851994249889113
275.40000000000316,33.650584052324355,0.2379497087501452,-0.04752992490720498
276.5000000000032,33.75561013763003,0.237376246062663,-0.04752867732945809
277.6000000000032,33.86020581475308,0.23869731582796314,-0.04884980747810275
278.70000000000323,33.965405677463856,0.23906633762436277,-0.048849820000004485
279.80000000000325,34.07045603110345,0.23852485025397707,-0.048849819998960875
280.9000000000033,34.174694171470534,0.23786899302686776,-0.04884201066544236
282.0000000000033,34.2804779483539,0.23816290357159373,-0.04987703311706415
283.1000000000033,34.38541045517229,0.23835519199256533,-0.049840165984489815
284.20000000000334,34.49065964734907,0.23880547333835286,-0.04984016999573804
285.30000000000337,34.5950668041958,0.23939383218918328,-0.048521865608155856
286.40000000000333,34.700410457955904,0.2380507523683075,-0.04852590779462407
287.50000000000335,34.80551199470217,0.23855305725325374,-0.04983492195082739
288.6000000000034,34.9112901498044,0.2387672274715238,-0.04982124379707997
289.7000000000034,35.01600059013417,0.23959126175451714,-0.05015998342485606
290.8000000000034,35.12128442451628,0.24104478362390344,-0.05081784376770404
291.9000000000034,35.22568948990944,0.23886204287696883,-0.05015580300834266
293.0000000000034,35.33055164494829,0.2404675534527512,-0.050131106647511636
294.10000000000343,35.43687533692414,0.2411450617259192,-0.049509950245806955
295.20000000000346,35.541298406690345,0.24084321798373715,-0.049530356860587155
296.3000000000035,35.645523732441006,0.2389763964877791,-0.050562538648572186
297.4000000000035,35.752388298218676,0.23831046018505234,-0.05082755781418946
298.5000000000035,35.8580828690443,0.2383108942490208,-0.05016981915643193
299.60000000000355,35.96292372244551,0.2388894800650478,-0.04943081232127877
300.70000000000357,36.06868408576045,0.23866338377660662,-0.05012534692881587
301.8000000000036,36.17484143903246,0.2379917802555457,-0.052480401428093515
302.9000000000036,36.280422338231524,0.2362315822247194,-0.05116009614912986
304.0000000000036,36.38568068095873,0.23725472563125868,-0.051160107567922
305.1000000000036,36.49142526511308,0.23547068425099243,-0.05116753207569413
306.2000000000036,36.5959221734692,0.23685659241496623,-0.051169110219576375
307.30000000000365,36.70267989165327,0.23653104311263884,-0.05082998618981094
308.4000000000037,36.80763872216771,0.23623236528026534,-0.05082998101432956
309.5000000000037,36.91387154926675,0.23626852966761863,-0.05082998099999969
310.60000000000366,37.019235149834536,0.23651207546286895,-0.05082998099999969
311.7000000000037,37.1235175781135,0.235585331389413,-0.0508299809999988
312.8000000000037,37.23070073927768,0.23747219346772389,-0.05082998100000147
313.90000000000373,37.33638852925747,0.2342936262995818,-0.05082998052362342
315.00000000000375,37.44095496398,0.23591350194776253,-0.051171313066546986
316.1000000000038,37.547915068833,0.23543734870970887,-0.05180592451295496
317.2000000000038,37.65175834739423,0.23658168168002416,-0.05246983747883327
318.3000000000038,37.758612737067104,0.23758140801140432,-0.05147400142795
319.40000000000384,37.86406572630149,0.23816051015136674,-0.052800202610325364
320.5000000000038,37.970379536502676,0.23809832709547246,-0.05280020099999483
321.60000000000383,38.0747053897515,0.23875768926350452,-0.052800162939130146
322.70000000000385,38.179300649077454,0.23979106159354535,-0.052470219764044757
323.8000000000039,38.28775248865766,0.24015590752417013,-0.05247013799984135
324.9000000000039,38.39266280241211,0.24023526233821182,-0.05247013799983247
326.0000000000039,38.498769329854426,0.2396979580176489,-0.05246990299658094
327.10000000000394,38.60459542285452,0.23830861628688343,-0.05379043080568913
328.2000000000039,38.71018363272093,0.24152672305008555,-0.0537901380000374
329.30000000000393,38.817054560591636,0.23856523788780748,-0.053790270147133334
330.40000000000396,38.920913047687385,0.2388417671864705,-0.05510998818573043
331.500000000004,39.02846514843744,0.23736517083256495,-0.05379018259105983
332.600000000004,39.134090857166576,0.2372077935345418,-0.05374058027659778
333.700000000004,39.23981314037212,0.23491964412110256,-0.05445013788047515
334.80000000000405,39.345635118737334,0.23630747148125728,-0.05445013799999998
335.90000000000407,39.45175832638437,0.23217225977333214,-0.05445013797417264
337.0000000000041,39.55860776714349,0.23563237731394313,-0.054436934222642286
338.10000000000406,39.664786642049165,0.2361634073069845,-0.055110138339218295
339.2000000000041,39.770561327096885,0.23467619683937752,-0.05511013800000075
340.3000000000041,39.87760010286688,0.23397169931462639,-0.055110139591706186
341.4000000000041,39.98429564914776,0.23723227284207996,-0.05378263117041815
342.50000000000415,40.09091862351769,0.23550444340839166,-0.0550968520929116
343.6000000000042,40.19572251140754,0.23729742621651775,-0.05511168849455306
344.7000000000042,40.302449405187616,0.23788741272437242,-0.05576016344571322
345.80000000000416,40.409018852638084,0.236858290743464,-0.055760533206492546
346.9000000000042,40.515261423080226,0.23838972292978416,-0.056420161973691485
348.0000000000042,40.62114996316341,0.23921978559264154,-0.05642013799999823
349.10000000000423,40.72709943120068,0.24063859927883402,-0.056420151081393755
350.20000000000425,40.83296176650974,0.23923110678722254,-0.056090663814747366
351.3000000000043,40.93945466152693,0.2403852451180729,-0.056090184971299806
352.4000000000043,41.046478856113126,0.24050518379929675,-0.0554300052132799
353.5000000000043,41.15055171654126,0.2399442784400612,-0.0554299490458412
354.60000000000434,41.256073676776516,0.23808181163148548,-0.056037789921740355
355.7000000000043,41.365529467590456,0.23907753029446457,-0.0577401946887619
356.80000000000433,41.472439188196965,0.23790239315534742,-0.057739760340032475
357.90000000000435,41.57864444232087,0.2385410628655386,-0.057392250850294424
359.0000000000044,41.683566037041864,0.23952464046035865,-0.05641598376825385
360.1000000000044,41.789896403231836,0.23821895547562888,-0.0574102010032016
361.2000000000044,41.89650568254361,0.23846016707804427,-0.05741020100000771
362.30000000000445,42.003107487084215,0.2375424076593982,-0.05741018082011795
363.4000000000044,42.10958143128142,0.2390634877395448,-0.05873058315144686
364.50000000000443,42.215745811601415,0.23934405897215033,-0.05633956114272909
365.60000000000446,42.322788740850285,0.237498249638657,-0.05608999155845318
366.7000000000045,42.42920908274477,0.23812664672169223,-0.05669090214471151
367.8000000000045,42.53543089945212,0.23736356371399583,-0.058729299315576355
368.9000000000045,42.64207591063929,0.2365213293304516,-0.05741082938505482
370.00000000000455,42.749102246521964,0.2378555008817925,-0.058730102921981775
371.10000000000457,42.85586903011887,0.2377309377533101,-0.059796492050568695
372.2000000000046,42.96154873490936,0.23562655558892637,-0.05939020116243743
373.30000000000456,43.069076809465564,0.23642326657081453,-0.059390200999999365
374.4000000000046,43.17467860535574,0.2359781078683344,-0.05939020100000114
375.5000000000046,43.28211459870478,0.2361883757333746,-0.059390200995006914
376.6000000000046,43.38809086533801,0.2341001271468907,-0.059384229080150064
377.70000000000465,43.494464661321224,0.23660497565508726,-0.06076610483982137
378.8000000000047,43.60120112704404,0.236121500626577,-0.06070876277161208
379.9000000000047,43.706919759276886,0.23337222600653318,-0.06036915273474719
381.00000000000466,43.814124203530206,0.23600029525117444,-0.06005019977700066
382.1000000000047,43.92021849845886,0.23315611437059627,-0.060050201000001024
383.2000000000047,44.02741324421657,0.23316924958440058,-0.060050200999991254
384.30000000000473,44.133266887131484,0.2339176793094735,-0.06005021268627875
385.40000000000475,44.24091874658045,0.23331159004563481,-0.05872833486828366
386.5000000000048,44.34772465631552,0.2341989908797416,-0.058730712070950375
387.6000000000048,44.45483043198634,0.23288464558006966,-0.060050134380823295
388.7000000000048,44.559763694259374,0.2339432084848537,-0.060048771840999215
389.80000000000484,44.66810590890924,0.2330616712439256,-0.058729802325714786
390.9000000000048,44.77514113252562,0.23355086902016847,-0.06069944416631046
392.00000000000483,44.88261801162964,0.23168647069627946,-0.06069979742966769
393.10000000000485,44.98969577891326,0.2327809449451081,-0.060040116805192945
394.2000000000049,45.09629372060321,0.23331710459280147,-0.06004007499968367
395.3000000000049,45.203766144809734,0.23391621557787234,-0.060040075000191706
396.4000000000049,45.30981494958042,0.23183363068865193,-0.06003959853127494
397.50000000000495,45.41742036947263,0.2339645358470764,-0.06005527170549829
398.6000000000049,45.52263320012588,0.23275383495311436,-0.06037985481853436
399.70000000000493,45.6312290306935,0.2362594832979577,-0.06037985500000076
400.80000000000496,45.73858263781853,0.2361627794458215,-0.06037985500000431
401.900000000005,45.84417729809499,0.23790338037763892,-0.06037984703303678
403.000000000005,45.95266020795328,0.23849050060522903,-0.06070935684575307
404.100000000005,46.059482457983066,0.2403464779091957,-0.06071001276843102
405.20000000000505,46.166070831026005,0.24523368286139058,-0.05938869423027615
406.30000000000507,46.273626758163196,0.2502945127154745,-0.06070912430020137
407.4000000000051,46.37916423467612,0.2556574602910059,-0.06070991799979808
408.50000000000506,46.487407732650894,0.2614113028770683,-0.06070991800000236
409.6000000000051,46.595570227834706,0.2659211068603331,-0.060709920003260365
410.7000000000051,46.70217281980772,0.2681848590206548,-0.061356609052465316
411.8000000000051,46.809430278279315,0.2708293100774035,-0.061370169985702105
412.90000000000515,46.91665557263576,0.27056534286439177,-0.061370512059818694
414.0000000000052,47.02410951940081,0.269265806556101,-0.06268014315405956
415.1000000000052,47.13119906067446,0.2671427358235924,-0.061342244047920325
416.20000000000516,47.238631066563315,0.2616182019262993,-0.06201982970846309
417.3000000000052,47.345058707660314,0.25732484205343686,-0.06334110284371341
418.4000000000052,47.4518159402141,0.24882319526286428,-0.062680254084027
419.50000000000523,47.55982333689994,0.24433301397369822,-0.0626802018756285
420.60000000000525,47.66751671410319,0.2386666295060862,-0.061370014947440765
421.7000000000053,47.774356483724645,0.2362167669075584,-0.06268003663791166
422.8000000000053,47.88197128769587,0.23505150647189144,-0.0633399092293292
423.9000000000053,47.98863986535011,0.2328325824088301,-0.06334064112017312
425.00000000000534,48.09571593259677,0.23291541060674553,-0.06202017263492099
426.1000000000053,48.203958981493415,0.23100744157302855,-0.06330047874272982
427.20000000000533,48.31142249392339,0.23289217973271048,-0.06334019702990723
428.30000000000535,48.41893374547873,0.23257983972920082,-0.0633401969128089
429.4000000000054,48.52625086656615,0.23106276815836901,-0.06395722368967238
430.5000000000054,48.6338348997217,0.23098876076637662,-0.06437719553490506
431.6000000000054,48.74133724301008,0.2316398409720697,-0.06334016663748354
432.70000000000545,48.848565577445484,0.23147751290246316,-0.06333032711115738
433.8000000000054,48.956794025059395,0.2299803551146383,-0.06202032006126945
434.90000000000543,49.063183316065576,0.22842374493938017,-0.06399999448403548
436.00000000000546,49.17096881646254,0.2282719595493717,-0.06468525867695618
437.1000000000055,49.2793690631539,0.23010997870842748,-0.06200997142914666
438.2000000000055,49.387128297561624,0.22979305926126553,-0.06334021784398125
439.3000000000055,49.4951469348256,0.2310252106704094,-0.06334000476382506
440.40000000000555,49.6025856122893,0.23177044410967018,-0.06300264759080498
441.50000000000557,49.7103129878324,0.22933236348646474,-0.0630172103296287
442.6000000000056,49.81792702817574,0.22964855018282682,-0.06432981924305814
443.70000000000556,49.92540899300178,0.22964003196838684,-0.06433208028147241
444.8000000000056,50.032550282719434,0.22855949243580354,-0.06308447385490368
445.9000000000056,50.14030678420307,0.23107632726318622,-0.0636864296824271
447.0000000000056,50.247314731354344,0.2305437649124939,-0.06497395352935342
448.10000000000565,50.35528931868227,0.23173332743172356,-0.06569326970854661
449.2000000000057,50.46367791859925,0.23139842974672226,-0.06565000893014972
450.3000000000057,50.57123507487556,0.23274375787362583,-0.0656500090000014
451.40000000000566,50.67921521516834,0.23326176674315666,-0.06565001070622145
452.5000000000057,50.78664844498801,0.23239093090392526,-0.06465578375595715
453.6000000000057,50.89481648279742,0.2347599848912319,-0.06490185163166906
454.70000000000573,51.00166211861974,0.235078543070247,-0.0659800717626906
455.80000000000575,51.11062031666031,0.23340644059654012,-0.06598007199999945
456.9000000000058,51.21860321940677,0.2354121689723263,-0.06598007200000033
458.0000000000058,51.32683719686659,0.2372373629682859,-0.06598007200490574
459.1000000000058,51.43302027850538,0.2334566242799201,-0.06597480163765113
460.20000000000584,51.54262198305355,0.23546619474234706,-0.0672999170203834
461.3000000000058,51.65138226336864,0.2343313028689286,-0.06729991500512611
462.40000000000583,51.75961606714548,0.23437514691235298,-0.06729364071811172
463.50000000000585,51.866403476425845,0.23440295419384802,-0.06630991638094397
464.6000000000059,51.97422048912733,0.23567719995718586,-0.06762323254153113
465.7000000000059,52.08444348250631,0.234956867255593,-0.06631043026867722
466.8000000000059,52.191701407822215,0.23795476271206797,-0.06631216907192705
467.90000000000595,52.30068874786226,0.23781059597876475,-0.06761886794061311
469.0000000000059,52.409071857128886,0.23774029167542596,-0.06893994174834095
470.10000000000593,52.51612355696767,0.23759739230982085,-0.0686182806950395
471.20000000000596,52.62509615303322,0.24024326040575267,-0.06814516837202778
472.300000000006,52.732929912299255,0.23904134492317378,-0.06893994177329432
473.400000000006,52.84036717454305,0.2396640765317864,-0.06893992467365795
474.500000000006,52.94840619606557,0.2395561754960427,-0.07029427917858921
475.60000000000605,53.05712399508765,0.23926378048214422,-0.0685577194483411
476.70000000000607,53.16447826452801,0.23997852803141007,-0.06894019700949272
477.8000000000061,53.27217266406569,0.2389051119190903,-0.06894018541698799
478.90000000000606,53.38117119609083,0.23810198466886204,-0.07026219188031124
480.0000000000061,53.488776361190254,0.24135060508358663,-0.07025933917592386
481.1000000000061,53.597085597192496,0.240108582233495,-0.07058986961661073
482.2000000000061,53.70492954269381,0.2403585967708097,-0.07031579845766345
483.30000000000615,53.81357946190454,0.23907361403799773,-0.07026003697403738
484.4000000000062,53.92099196277242,0.239732562394027,-0.07026003699999972
485.5000000000062,54.029234655797254,0.24058419672728834,-0.07026003686886728
486.60000000000616,54.136304147514366,0.24127691098149126,-0.07050496566517861
487.7000000000062,54.24668370330313,0.2419638102963356,-0.07091982969316213
488.8000000000062,54.35343983416293,0.24316201403387705,-0.07077588447887084
489.90000000000623,54.46239184656136,0.24397401871575905,-0.07123875628919318
491.00000000000625,54.570835951649165,0.23959906571021983,-0.0719001282399061
492.1000000000063,54.67846935298524,0.2414290836582204,-0.07190438842822999
493.2000000000063,54.7868094786239,0.24240262625708642,-0.07193280531612523
494.3000000000063,54.895916265153204,0.24219416413946282,-0.07322627594315101
495.40000000000634,55.00397108421182,0.24245210376517243,-0.07057727309981221
496.5000000000063,55.113389502728566,0.2405186556119032,-0.0732212732735471
497.60000000000633,55.22141459526331,0.24036612641652683,-0.07321780659422927
498.70000000000636,55.32915193953308,0.2398852802287577,-0.07323870905395768
499.8000000000064,55.43719405496962,0.24191896401453827,-0.07319458308685967
500.9000000000064,55.54585099676647,0.24219002634858686,-0.07294365822380566
502.0000000000064,55.65393015284778,0.24600075477291755,-0.07420981297127405
503.10000000000645,55.7626718292873,0.24784177870708413,-0.0742098129666866
504.2000000000064,55.87061898065592,0.24729214784808345,-0.07425527097079598
505.30000000000643,55.978695790525364,0.24658157761182567,-0.07387028305482524
506.40000000000646,56.087218804313665,0.2471687264452165,-0.07464357867969618
507.5000000000065,56.195601490251526,0.24839645198302365,-0.07559191031996271
508.6000000000065,56.30338425214632,0.24696751905263808,-0.07553605252429385
509.7000000000065,56.41260845119894,0.24724559647997618,-0.07599712770289813
510.80000000000655,56.52163721269765,0.24532722031509227,-0.0755200935995779
511.90000000000657,56.6297078666331,0.24417614263344406,-0.07533064482911378
513.0000000000066,56.7372389566567,0.2480050709645767,-0.07486009196690091
514.1000000000065,56.84628329696635,0.24929988343502268,-0.07523523464514792
515.2000000000066,56.95559896887136,0.24794112284504233,-0.07749996302292672
516.3000000000065,57.06383964003504,0.24722129285834002,-0.07618410666078379
517.4000000000067,57.172270590000785,0.24993175109008386,-0.07758887986595653
518.5000000000066,57.28081710918446,0.25042126420256566,-0.07603548419256256
519.6000000000067,57.38839096193796,0.24571639532038939,-0.07815148333818644
520.7000000000066,57.49781851165195,0.24762057103395224,-0.0784572493675384
521.8000000000067,57.6047708118838,0.24636522618705073,-0.07750024125878863
522.9000000000067,57.714508380549404,0.24737316157508948,-0.07882791767963493
524.0000000000067,57.82311982839118,0.24891516953125725,-0.07882002999572979
525.1000000000067,57.93105746403946,0.24797200929486374,-0.0788200440108815
526.2000000000068,58.0404966308157,0.24885563012162557,-0.08012979236473505
527.3000000000068,58.14841123403116,0.2500509086134597,-0.07980019020167983
528.4000000000068,58.257952724291485,0.25477930946226585,-0.08112245400932938
529.5000000000068,58.366701773998535,0.25385535901967227,-0.08227701408978927
530.6000000000068,58.474125171100425,0.2559009799830774,-0.08243981446811333
531.7000000000069,58.58316153160936,0.25474720916982285,-0.0814085960792772
532.8000000000068,58.692731861730465,0.25799439831058857,-0.08145095668614744
533.9000000000069,58.80045334690304,0.2584434942752156,-0.08279944815760132
535.0000000000068,58.91019358652824,0.2600300705717331,-0.08409077746741911
536.100000000007,59.018770900833864,0.2618920720240489,-0.08278036242626019
537.2000000000069,59.127604602976405,0.26083511593268327,-0.08342782434958007
538.300000000007,59.23689970113353,0.26254570209216527,-0.08376003515830988
539.4000000000069,59.346098949444546,0.26467076356152663,-0.08442038035817134
540.5000000000069,59.45470327451419,0.26504522488105314,-0.08507854951357885
541.600000000007,59.562800860073494,0.2649692004005607,-0.08507909596148355
542.700000000007,59.67156830010398,0.26585561287208637,-0.08607000291788403
543.800000000007,59.7811430963464,0.26744824875851747,-0.08639978390631242
544.900000000007,59.889997864808095,0.26679446871111456,-0.08771989727738472
546.000000000007,59.9991831259961,0.26721921287949196,-0.08757248802883488
547.1000000000071,60.10664140261389,0.26888489095359025,-0.08640634151847326
548.2000000000071,60.21808454234044,0.26853132393092816,-0.08694399844328338
549.300000000007,60.32664611742738,0.26819057487486503,-0.08771021004331381
550.4000000000071,60.436286661497256,0.2698755246012601,-0.08770990492180974
551.500000000007,60.54268271461034,0.2729375688787354,-0.08903017779338729
552.6000000000072,60.654109068704116,0.27361153712005926,-0.08903017600201046
553.7000000000071,60.76348282933695,0.2727390385564039,-0.08902704857392063
554.8000000000072,60.87184323117372,0.27299884872358676,-0.09035005569181243
555.9000000000071,60.98074113413713,0.27293021300744325,-0.08903032565028113
557.0000000000072,61.090300825900385,0.27456505551449956,-0.08936007066076979
558.1000000000072,61.20038786231437,0.27666475901122894,-0.09067989427049472
559.2000000000072,61.30835634112213,0.27812996360587566,-0.09067986199671196
560.3000000000072,61.41880278573003,0.2780824283262793,-0.09090652835177826
561.4000000000073,61.5288435503103,0.2829368935892162,-0.09066993239576471
562.5000000000073,61.63667947583079,0.2832848297735357,-0.09132223396820205
563.6000000000073,61.74687860408613,0.28258872926927137,-0.09265013436100578
564.7000000000073,61.8551888666704,0.2839725655084445,-0.09165386883159865
565.8000000000073,61.96451890358171,0.28389665829880195,-0.0929785177634388
566.9000000000074,62.073043130718006,0.2857454036174573,-0.09428989748262051
568.0000000000074,62.1830523551537,0.2870084132428249,-0.09429001067119103
569.1000000000074,62.292252718148646,0.2874748608098891,-0.09495870057861477
570.2000000000073,62.40173336009522,0.2901203128403764,-0.0956050393928467
571.3000000000073,62.50912641519274,0.2900720925158662,-0.09529085892286826
572.4000000000074,62.61941911820492,0.3002890002716502,-0.09661010395930658
573.5000000000074,62.72680788871046,0.30425124879515814,-0.09662291743189488
574.6000000000074,62.838356477077696,0.29839737756204254,-0.09661968814840449
575.7000000000074,62.947552160018475,0.29219947094301774,-0.09690389588985449
576.8000000000075,63.05724455101471,0.29112949506891483,-0.09859014452998949
577.9000000000075,63.165609448228764,0.2902943084221913,-0.09745590919153369
579.0000000000075,63.275943439344104,0.2880575811827725,-0.09758993329902266
580.1000000000075,63.384606939395795,0.2896149950679533,-0.09890705039761638
581.2000000000075,63.49363459137502,0.29259566641906865,-0.0996454153133155
582.3000000000076,63.60367006461115,0.2932710025313712,-0.09890742029982258
583.4000000000076,63.71182187573426,0.2944308761709023,-0.10022988383080733
584.5000000000076,63.821200914067745,0.29399235646084665,-0.10253081979635237
585.6000000000076,63.93058616054773,0.2941805805874352,-0.10253459792412078
586.7000000000077,64.04087579789118,0.29359294787304413,-0.10193964306207626
587.8000000000077,64.1493614132858,0.292103639714025,-0.10253016076561616
588.9000000000076,64.25941033741611,0.2948235142340183,-0.10351923387630269
590.0000000000076,64.36835806572067,0.2955499440606547,-0.10378843177851582
591.1000000000076,64.47766693514625,0.2949673464077661,-0.10516988870297972
592.2000000000077,64.58746705109532,0.29978335246230436,-0.10647926371039418
593.3000000000077,64.69641314596656,0.298136336412928,-0.10647965772405499
594.4000000000077,64.80557363685637,0.3010591460660868,-0.10767442852208475
595.5000000000077,64.91426381938749,0.3027713574531211,-0.10780000068771933
596.6000000000078,65.02421881474811,0.30130651040045453,-0.10779974898800937
597.7000000000078,65.13406031374313,0.30630528966708015,-0.11044369439198087
598.8000000000078,65.2440317564509,0.30764720336382384,-0.11177219615243406
599.9000000000078,65.35239394987636,0.30740130008090877,-0.11042993069772855
601.0000000000078,65.4623729509377,0.3088663296900104,-0.11175007961499661
602.1000000000079,65.57130244468127,0.30902682524941744,-0.11175072385128937
603.2000000000079,65.68128881332642,0.3107309970282752,-0.11208936363325162
604.3000000000079,65.79098252569078,0.3118225041732591,-0.11340976612258791
605.4000000000078,65.90076774690982,0.31361912207618015,-0.11471992513340012
606.5000000000078,66.010541602607,0.3158629580030422,-0.1173986171605641
607.6000000000079,66.11969394843766,0.31700050117613976,-0.11603992865560375
608.7000000000079,66.2294670461466,0.317507841946897,-0.1170345678362601
609.8000000000079,66.33945613856079,0.3186736419558535,-0.11736019093645211
610.9000000000079,66.44904486361348,0.3213256006716548,-0.11997966444602781
612.000000000008,66.5580244917029,0.32336765030321357,-0.11999247445427441
613.100000000008,66.66730677161779,0.33048677938470616,-0.12131004553905367
614.200000000008,66.77677348729381,0.32964638276112523,-0.12263038436314178
615.300000000008,66.88644286412827,0.3306027373627739,-0.12294912451604967
616.400000000008,66.99511289575307,0.3329700619874174,-0.12427730405531356
617.5000000000081,67.10602715528996,0.3366457587957975,-0.12426283407666228
618.6000000000081,67.2148037527647,0.3408812658094186,-0.1255178400495387
619.7000000000081,67.32454660549084,0.3435890407100603,-0.12658340355938957
620.8000000000081,67.43420962923868,0.3494438427611778,-0.1254783928468588
621.9000000000082,67.54388798325003,0.35157592125956083,-0.12685095001516755
623.0000000000082,67.65282275167498,0.35654738232734967,-0.12915130483054904
624.1000000000081,67.763309326524,0.3595828917974667,-0.13053619167327657
625.2000000000081,67.87236975495254,0.36445741295737394,-0.1318424181568898
626.3000000000081,67.98271882140672,0.3716211204650823,-0.1318362230079071
627.4000000000082,68.0925505966867,0.37521571655688635,-0.1333578359299521
628.5000000000082,68.20201038837892,0.37752859713974224,-0.13462960549935277
629.6000000000082,68.31193588783366,0.3852525469563466,-0.13583211644857274
630.7000000000082,68.42160838572875,0.3926573595358344,-0.13711007042311607
631.8000000000083,68.53050915069322,0.40013379951926714,-0.13844553939620674
632.9000000000083,68.64127115877875,0.4068812278425555,-0.14074584736973383
634.0000000000083,68.75127626815542,0.41208395461458147,-0.1433699468727072
635.1000000000083,68.86124747228678,0.41701295225888857,-0.14469008157692453
636.2000000000083,68.97060190384231,0.42550786213053965,-0.14535190453531843
637.3000000000084,69.0806770727866,0.43380578752492027,-0.14704664381779775
638.4000000000084,69.18999791427922,0.44458788198551247,-0.1489698420631025
639.5000000000084,69.3002909391816,0.4487469698769928,-0.1515995357497042
640.6000000000083,69.41000217003199,0.45775682819492514,-0.15303011887949358
641.7000000000083,69.52092353001544,0.46354261486203396,-0.15532167643273187
642.8000000000084,69.63047962849184,0.47141403404497706,-0.1566595487533351
643.9000000000084,69.73961093021832,0.4795011284858493,-0.15930776912689737
645.0000000000084,69.84972009753562,0.4914920620488381,-0.160672673556304
646.1000000000084,69.95931852209834,0.49807705976097083,-0.1619119115276355
647.2000000000085,70.06843493477668,0.5104786836903827,-0.16590632887200796
648.3000000000085,70.17899835853746,0.5203771703603939,-0.1672222739182736
649.4000000000085,70.28836877643239,0.5299998897058076,-0.16982181350646774
650.5000000000085,70.39847703698672,0.5451974368758552,-0.172589261280637
651.6000000000085,70.50897567819392,0.5545728757729788,-0.1752207789917124
652.7000000000086,70.61906065549621,0.5672775875600217,-0.17764827293696728
653.8000000000086,70.7283154850217,0.5797538194327895,-0.1806848608139484
654.9000000000086,70.83897526042406,0.5918275766798555,-0.18355493891417796
656.0000000000086,70.9477193453003,0.6031820894180935,-0.1850203591067796
657.1000000000087,71.05709346236308,0.615483164581159,-0.18913127037842647
658.2000000000087,71.1690178669025,0.6313554439482338,-0.1958158577284359
659.3000000000086,71.27947706955143,0.6428771556930364,-0.19824462969693268
660.4000000000086,71.38957997715646,0.6565968955204857,-0.20100006674494786
661.5000000000086,71.49868023449604,0.670973891070437,-0.20318848935125633
662.6000000000087,71.60898287862784,0.6847915680791861,-0.20760490020479594
663.7000000000087,71.71942750172688,0.700636189208431,-0.21126434278724338
664.8000000000087,71.83010373644325,0.7156561802718296,-0.21681390010149704
665.9000000000087,71.93980892909622,0.7328428965706544,-0.21973843177202612
667.0000000000088,72.05021635164212,0.7496846450291043,-0.224736144032605
668.1000000000088,72.16114867643901,0.771128729363214,-0.2301046962946045
669.2000000000088,72.27070014239392,0.7851236107321532,-0.23444765567882087
670.3000000000088,72.38113836076988,0.8062040152453337,-0.2392864567131907
671.4000000000088,72.49092972012517,0.8238955851066575,-0.2428997188134434
672.5000000000089,72.60116957204542,0.8494168790005687,-0.2480078233003118
673.6000000000089,72.7105730911669,0.8692984267403981,-0.25509674255942993
674.7000000000089,72.8201092118298,0.8915134378928629,-0.2599707309187562
675.8000000000088,72.93107843869156,0.9113488046582248,-0.26523738301920474
676.9000000000088,73.04150241647515,0.9335999152387062,-0.27108785712763694
678.0000000000089,73.15169871473871,0.9591117551978826,-0.2770676832685859
679.1000000000089,73.26095927693613,0.9800412007725685,-0.28445707731865433
680.2000000000089,73.37089714721284,1.006242175867736,-0.2911537349919362
681.3000000000089,73.48010922338382,1.033480428135329,-0.2975154780356002
682.400000000009,73.59156166660384,1.0608225053147775,-0.30290972772654
683.500000000009,73.70020736804521,1.0868853979339783,-0.31124242285442394
684.600000000009,73.81113791078,1.110735319404335,-0.3171585329497324
685.700000000009,73.92038827531744,1.1369219978319751,-0.32576612602167865
686.800000000009,74.03038164867147,1.164940999243103,-0.332999544320864
687.9000000000091,74.14037299705511,1.1911865022381922,-0.3411106170202416
689.0000000000091,74.25036995973767,1.218616180548532,-0.348926376658667
690.1000000000091,74.3610899107036,1.247020019649023,-0.35749541512413296
691.2000000000091,74.46989996914195,1.274047252514262,-0.3668812727232149
692.3000000000092,74.58078984349495,1.307761155319881,-0.3759390782533165
693.4000000000092,74.69049140485316,1.3342507948559001,-0.38484533115362307
694.5000000000091,74.80099870985623,1.3636764132249177,-0.39304167680410274
695.6000000000091,74.91139566754819,1.3963387761883124,-0.404650119590221
696.7000000000091,75.02261446882763,1.4224449750553223,-0.4137769882640585
697.8000000000092,75.13197880427971,1.452067180975266,-0.42350521252553497
698.9000000000092,75.24300519694066,1.479712916704449,-0.4332962404618841
700.0000000000092,75.35138485457367,1.513460378900113,-0.4449023305831905
701.1000000000092,75.46442802223555,1.5457391857484892,-0.4563648299861862
702.2000000000093,75.5742635183594,1.580206057943449,-0.4670188381931455
703.3000000000093,75.68386706115515,1.6155101904936036,-0.47914949383729066
704.4000000000093,75.79435849302916,1.6467340785592461,-0.49185740530017563
705.5000000000093,75.90549518445964,1.6794726449901105,-0.5028197601379816
706.6000000000093,76.01532903833504,1.7127138070143175,-0.5164716183709812
707.7000000000094,76.12522153505078,1.7498063512899609,-0.5293825884939198
708.8000000000094,76.23470449872707,1.780938415753418,-0.5415657797901665
709.9000000000094,76.34504010440082,1.8140072110596737,-0.5544892689828975
711.0000000000093,76.45554884325152,1.845356679956701,-0.568397764305117
712.1000000000093,76.56490019866534,1.8796673089964324,-0.5810052045700882
713.2000000000094,76.67361622742675,1.91221553204229,-0.5957287373666791
714.3000000000094,76.78629959497931,1.9447330242294751,-0.6100340452387618
715.4000000000094,76.8953286558012,1.980216532545964,-0.624954486401061
716.5000000000094,77.007033332201,2.01830466250399,-0.6405332957847105
717.6000000000095,77.11585180535484,2.0485669907208526,-0.6547501354455121
718.7000000000095,77.22699807141046,2.0819006452122855,-0.6697282475173219
719.8000000000095,77.3376462079849,2.113687678706345,-0.6860902296148419
720.9000000000095,77.44854470141438,2.150164279542822,-0.7020244681599594
722.0000000000095,77.55859357232026,2.1825808873257175,-0.7191611156781796
723.1000000000096,77.66821427775596,2.211431278827215,-0.7349279389889394
724.2000000000096,77.77919892869198,2.23725421607354,-0.7520862028032758
725.3000000000096,77.89067744545194,2.27231490637615,-0.7682355933902003
726.4000000000096,78.00048173271345,2.299329812880785,-0.7853657867503783
727.5000000000097,78.11102246642935,2.3307186782430067,-0.8039777234639871
728.6000000000097,78.22185863829051,2.3559710374992155,-0.8215868426970196
729.7000000000096,78.33169323252693,2.3792780936230296,-0.8401998429664825
730.8000000000096,78.44191664149085,2.405734269718267,-0.8581714900608977
731.9000000000096,78.5524786501316,2.4307464997785986,-0.8768442310249416
733.0000000000097,78.66306756543543,2.4591121550351422,-0.8967637346001025
734.1000000000097,78.77310317377876,2.489429997197179,-0.915002932517095
735.2000000000097,78.88319282466433,2.517240271523588,-0.9333060259569388
736.3000000000097,78.99338119389884,2.551270874194442,-0.9536103428817606
737.4000000000098,79.10402107516258,2.579171535951818,-0.9734416531993091
738.5000000000098,79.21418831173986,2.6083002904971297,-0.9936287627543052
739.6000000000098,79.32461403937232,2.648443222860432,-1.0123036894781263
740.7000000000098,79.434800466372,2.682269869255334,-1.032539321268581
741.8000000000098,79.54522459161142,2.717259080162446,-1.0538566863344583
742.9000000000099,79.65588867673208,2.756913956760359,-1.0757498128994358
744.0000000000099,79.76585724571561,2.799587533313209,-1.0947850387659837
745.1000000000099,79.87709021736976,2.8483747896228975,-1.1164101038845824
746.0000000000099,79.96714819209933,2.893482316502854,-1.1348799777065448