File: 01_Data/Concrete_Block/STA/N2/10K_min/Concrete_Block_STA_N2_10KData_220913_R2.csv
##Temp./Â°C,Time/min,DSC/(mW/mg),Mass loss/mg
51.0,10.87921941769604,0.02193948591701611,-0.019399944727654272
52.100000000000016,11.203946758285099,0.0480799514376169,-0.018265724588134802
53.20000000000003,11.445283376285175,0.06711698320069415,-0.018547392228481563
54.30000000000005,11.642176046868514,0.08275722107275385,-0.018142984123389994
55.40000000000006,11.824934761655367,0.09407198248096549,-0.01814468361957644
56.50000000000008,11.995026362099132,0.10117030065616994,-0.019179158117592188
57.600000000000094,12.156073038131053,0.10990041915078841,-0.01903206335622265
58.70000000000011,12.30916157648089,0.11725442633702898,-0.019067190870943662
59.800000000000125,12.458506478801727,0.1222097751084621,-0.018431399088804312
60.90000000000014,12.604729718497627,0.13024365379728975,-0.020315475069067723
62.000000000000156,12.745366140047935,0.13664830780422044,-0.019664645439092965
63.10000000000017,12.884021899493206,0.1409092276703685,-0.019454822378320635
64.20000000000019,13.017193464588287,0.1452177437349682,-0.019099214134164377
65.30000000000021,13.15423755312636,0.14850877620788472,-0.02086467540563408
66.40000000000022,13.288524703802802,0.15457698475677506,-0.022047815678915228
67.50000000000023,13.42023054730865,0.1566857476932546,-0.020642502762825643
68.60000000000025,13.549368491460493,0.1605252860569908,-0.021864977636504968
69.70000000000027,13.676931126346675,0.1632833137528824,-0.021792873227982845
70.80000000000028,13.803934736357947,0.1679262101025607,-0.022630279446852697
71.90000000000029,13.928452635909377,0.1681532831244381,-0.023332294827180355
73.00000000000031,14.05266675315898,0.173853503147548,-0.022964766202122178
74.10000000000034,14.175497198249179,0.17617420525667848,-0.023466322018224517
75.20000000000034,14.298550739080978,0.181240417010041,-0.022073465660179536
76.30000000000035,14.420213505998746,0.18670677348089137,-0.022823399242983378
77.40000000000038,14.54222384850607,0.18663553766854113,-0.02345975353956664
78.5000000000004,14.660102896016856,0.19226116101512314,-0.024787297411187126
79.6000000000004,14.777963961546131,0.19379608385568192,-0.023635785024895384
80.70000000000041,14.897824802596228,0.19735735292378953,-0.023500665720839642
81.80000000000044,15.015138251283412,0.19833134400300534,-0.02481138166077468
82.90000000000046,15.132249458276213,0.20013125763374173,-0.026080695961506528
84.00000000000047,15.248263780992993,0.2027740010344662,-0.027197496830567935
85.10000000000048,15.36407045066082,0.20481290276665332,-0.027459599457821504
86.2000000000005,15.480000000000055,0.2082852735485049,-0.027450232035824307
87.30000000000052,15.591921959713906,0.208685779655304,-0.027455284219528586
88.40000000000053,15.707646787419591,0.21149527682857094,-0.02753657840777013
89.50000000000054,15.820741753834659,0.21313732414871656,-0.030119905001434244
90.60000000000056,15.93371167688871,0.21424914621048285,-0.028706472170753727
91.70000000000059,16.045284581522402,0.21768846320506974,-0.03136328797070975
92.8000000000006,16.157308339450157,0.21780076728433717,-0.03008895851762805
93.9000000000006,16.268077375354203,0.21991746519601163,-0.030135922821528993
95.00000000000063,16.380198962228782,0.22114305958577607,-0.030086309609886452
96.10000000000065,16.490751906494726,0.2219538040844169,-0.03139900136762375
97.20000000000066,16.60030419380366,0.2242877506733545,-0.03170499528554371
98.30000000000067,16.710442815254687,0.22545034122676832,-0.03235615209102871
99.40000000000069,16.82100791156507,0.2271399651965682,-0.032318061356575
100.50000000000071,16.92875564845955,0.229505332737027,-0.03271889232443437
101.60000000000072,17.038686822840734,0.23075853036587113,-0.03273040789890258
102.70000000000073,17.14803715240098,0.2326055939777565,-0.03404127351706743
103.80000000000075,17.25753778910528,0.23319039742601044,-0.034122890292944685
104.90000000000077,17.36454941903295,0.23466536073849953,-0.033430030380594555
106.00000000000078,17.470239398587374,0.23829096957205542,-0.0351996844961735
107.10000000000079,17.580109000794188,0.2363381880512576,-0.03392669272150117
108.20000000000081,17.688747143361734,0.23682970306871265,-0.03443620318837537
109.30000000000084,17.79696388636132,0.23675955310485552,-0.03535869929938862
110.40000000000084,17.90342716076025,0.23707136771300885,-0.03537320268575472
111.50000000000085,18.012737119345637,0.2383560552643944,-0.03534886748310262
112.60000000000088,18.119451909218505,0.23778932679767806,-0.03668051742487233
113.7000000000009,18.226216850348546,0.23824965862587044,-0.03789859819499597
114.8000000000009,18.334673536056847,0.23796425417010014,-0.03915871515193814
115.90000000000092,18.44246226877492,0.23792187754434924,-0.03832100828531937
117.00000000000094,18.548008034543408,0.23768958548398766,-0.03805946581829911
118.10000000000096,18.6550187956044,0.23599614509793954,-0.039048539931689774
119.20000000000097,18.762809271829635,0.23581205823408113,-0.03875282006538594
120.30000000000098,18.870795109605776,0.23408808026505723,-0.039639810731581626
121.400000000001,18.97923914668497,0.23187636561141822,-0.0406320395465527
122.50000000000102,19.08508421157318,0.23310998372528924,-0.040544740796502055
123.60000000000103,19.19262096297359,0.23243518323700307,-0.04062290852691364
124.70000000000104,19.299711608081644,0.23385484406950674,-0.04195173850092715
125.80000000000106,19.405692763716086,0.23215161144187568,-0.04195000175215968
126.90000000000109,19.51313439540529,0.2303572478552406,-0.04323404832050004
128.00000000000108,19.61919101672222,0.23220006428375972,-0.043259820276987604
129.1000000000011,19.725381284195322,0.23060103943171506,-0.04326066007525098
130.20000000000113,19.832548124613506,0.23016574446404459,-0.04194884018982892
131.30000000000115,19.93754280127979,0.23098123011038607,-0.04326912243524239
132.40000000000117,20.043177717642163,0.232356662056021,-0.04326005962982382
133.50000000000117,20.149502427150413,0.23191912675733206,-0.04325990300972071
134.6000000000012,20.254357554579226,0.23307025822634586,-0.04320338592425088
135.7000000000012,20.361136123192406,0.2322966058610757,-0.04459059996010106
136.8000000000012,20.466982696689517,0.23172775209775887,-0.04458012678261669
137.90000000000123,20.56821498664126,0.23180081499176886,-0.04598631084811089
139.00000000000125,20.678681226370518,0.23277330241608085,-0.04458971394822164
140.10000000000127,20.782426455766608,0.23262147294219526,-0.04487358586459855
141.2000000000013,20.88762388720838,0.23208773941762673,-0.046230162835021904
142.3000000000013,20.992620308170736,0.23204269294841595,-0.04615266909642024
143.4000000000013,21.097868981460028,0.23179198766270293,-0.04671942056069778
144.50000000000134,21.20362885113592,0.23126422878315156,-0.04618157808423318
145.60000000000133,21.308218879550427,0.23146815368114138,-0.04698768728637326
146.70000000000135,21.4139598477383,0.22989924122440086,-0.04623007712627025
147.80000000000138,21.5183307271105,0.23224082088422415,-0.047539881108101145
148.9000000000014,21.6209506378735,0.23069420413130237,-0.047540112809275836
150.00000000000142,21.72523693731286,0.2327742776958206,-0.04886043163465237
151.10000000000142,21.833214568360848,0.23038075320819396,-0.04852801091759451
152.20000000000144,21.938067577146036,0.23125700029072926,-0.04964755651776409
153.30000000000146,22.040425092566974,0.23012719521357738,-0.047216062478780074
154.40000000000146,22.144868353709672,0.23155916128591025,-0.04721353702962139
155.50000000000148,22.249516817365855,0.2326010706623034,-0.048529841607791724
156.6000000000015,22.351641697182753,0.23049337832999806,-0.04885420586317846
157.70000000000152,22.45876111574692,0.23168971177102538,-0.04984965096537142
158.80000000000155,22.560536999943153,0.23108605230498247,-0.049168605171302726
159.90000000000154,22.669207235384587,0.230422562849802,-0.04985002139513961
161.00000000000156,22.774352657448045,0.23018120267448128,-0.04978357719003412
162.1000000000016,22.879024784033966,0.23108369192143463,-0.04985018648770456
163.20000000000158,22.98322660789106,0.22998220343024944,-0.051159548214070316
164.3000000000016,23.087315974629966,0.2281744891399614,-0.04985015615914046
165.40000000000163,23.190738916933338,0.2286042751366949,-0.0511656537525873
166.50000000000165,23.296158841746227,0.22699054571894672,-0.04987509224248088
167.60000000000167,23.402157764809644,0.22686617734954773,-0.04981507315141842
168.70000000000167,23.505907717219085,0.22698348606518104,-0.05116980992138753
169.8000000000017,23.61168695724757,0.226636936041979,-0.05116987728433742
170.9000000000017,23.71571905398478,0.2264937948452127,-0.05114649095809698
172.0000000000017,23.820000000000164,0.2268312621349109,-0.0511599850003277
173.10000000000173,23.923905524020817,0.22552801976582615,-0.05117203100932777
174.20000000000175,24.028783119810832,0.22591259417014964,-0.052416807874196
175.30000000000177,24.13347033633696,0.22582748141219766,-0.05247975448384601
176.4000000000018,24.23888789331228,0.22735977969967647,-0.0511700638883843
177.5000000000018,24.342799734570967,0.2251560674902865,-0.05249143841631465
178.6000000000018,24.44744613743753,0.2245934642563825,-0.05248541207223223
179.70000000000184,24.550803581985047,0.22585361069599275,-0.053014579580172416
180.80000000000183,24.656259495836146,0.2267127359860625,-0.052499726847177186
181.90000000000185,24.759532906586948,0.22538662498287043,-0.05280433812856211
183.00000000000188,24.8642088794464,0.225309901217086,-0.05347018048126673
184.1000000000019,24.96896077572066,0.22439602799089148,-0.053469497170722136
185.20000000000192,25.073244023424305,0.2254542425968663,-0.05389628093373888
186.30000000000192,25.17809745929675,0.2233880094650384,-0.05379995369769208
187.40000000000194,25.28186149962666,0.22271267542370699,-0.052676252932863044
188.50000000000196,25.386732916213127,0.22203644262107736,-0.05314979991895319
189.60000000000196,25.489998930328966,0.22215919163002046,-0.0531498262995882
190.70000000000198,25.59357957534367,0.2223943561506757,-0.05381006486912776
191.800000000002,25.69923879650133,0.22322146811380478,-0.054399214075200764
192.90000000000202,25.803664548962537,0.22147724106770728,-0.05477787244104171
194.00000000000205,25.90843683735818,0.22260164290797751,-0.053469699145013205
195.10000000000204,26.0123380293194,0.22008167531857425,-0.05299846940067665
196.20000000000206,26.11702258700424,0.22091678209204613,-0.05380015770957547
197.3000000000021,26.221753866666344,0.22339990256978298,-0.05512012050279713
198.40000000000208,26.324990037388126,0.22124768230027686,-0.05381405910299142
199.5000000000021,26.430853064685724,0.22123852783332743,-0.05379998495360283
200.60000000000213,26.534869045213604,0.22136260401969426,-0.05511911046817408
201.70000000000215,26.640732787681504,0.22026598631964428,-0.0554448299150736
202.80000000000217,26.744423729316097,0.22186912367281436,-0.05512918015632229
203.90000000000217,26.848341511599823,0.22292575964711348,-0.05578246235418449
205.0000000000022,26.951277279132512,0.22378433780018803,-0.05511018989711758
206.1000000000022,27.055256928922496,0.2235804793857672,-0.05511672751041852
207.2000000000022,27.159901275105263,0.2243472457298663,-0.05644058448888778
208.30000000000223,27.266301159487995,0.2242677152357888,-0.05644005822768916
209.40000000000225,27.37091707652416,0.2244767090045402,-0.055367117314131686
210.50000000000227,27.474773739878323,0.22463992521624992,-0.05511988933716161
211.6000000000023,27.578014158261,0.22472257653226546,-0.05644250604998824
212.7000000000023,27.683106768169075,0.22482300221636609,-0.056439830620805154
213.8000000000023,27.788584297712898,0.22571728099977484,-0.056835749986641204
214.90000000000234,27.89222963480934,0.22566437393957095,-0.056430796096246016
216.00000000000233,27.99571569289158,0.2246316367978664,-0.05676002270401259
217.10000000000235,28.10151417297275,0.227082436520184,-0.056759647422094606
218.20000000000238,28.20575531610711,0.22798417364343532,-0.05755541988657331
219.3000000000024,28.310371096794,0.22879368642428577,-0.05808239005865712
220.40000000000242,28.414838752543794,0.22989569329062953,-0.059171203013510976
221.50000000000242,28.519409312916693,0.22799437177541926,-0.057759853554716134
222.60000000000244,28.624622839046424,0.22972547490142115,-0.05776165468887129
223.70000000000246,28.72772115435413,0.22942640490483462,-0.059079717933482545
224.80000000000246,28.83313051399196,0.23088062936493842,-0.05776005928939432
225.90000000000248,28.936584185241788,0.22953789340735192,-0.06039942016981836
227.0000000000025,29.042459987509407,0.2300285764820194,-0.05907002640714465
228.10000000000252,29.14714531092764,0.22812478954385396,-0.05907002799658967
229.20000000000255,29.25135246304335,0.22750752479826508,-0.059071815068708844
230.30000000000254,29.354662240855884,0.22756368463743942,-0.057874239640654856
231.40000000000256,29.46048055222816,0.22682985064213063,-0.0590697998406049
232.5000000000026,29.56545386182198,0.22771466202559348,-0.058431014532224435
233.60000000000258,29.66982190513386,0.22667809404692796,-0.059730107389260656
234.7000000000026,29.77355915711063,0.22818109729002578,-0.059730089048070756
235.80000000000263,29.877649785321776,0.2281443683443764,-0.06005959588171672
236.90000000000265,29.98301469028364,0.2265363269365881,-0.06103995173337218
238.00000000000267,30.087197171323115,0.2272632688660851,-0.05982533026801207
239.10000000000267,30.191845843757342,0.22703297210286494,-0.06038997499990151
240.2000000000027,30.29663925967479,0.22697069475170695,-0.06038997534114543
241.3000000000027,30.40143558424805,0.22881239583467133,-0.05951184001052168
242.4000000000027,30.504458188479003,0.22651777881593826,-0.059084031456711816
243.50000000000273,30.609797753664548,0.22895646551570642,-0.06038983221879635
244.60000000000275,30.71409899050219,0.2268738596734034,-0.061448044160439697
245.70000000000277,30.81950503456041,0.22798183026727126,-0.06172121642978423
246.8000000000028,30.922363740241085,0.22778487681066123,-0.06035280553253708
247.9000000000028,31.027537993705817,0.2291646753547677,-0.0630390958657494
249.0000000000028,31.13212474195192,0.22969632237578597,-0.06271505283394863
250.10000000000284,31.23674190582024,0.22982318359612397,-0.06138000250185316
251.20000000000283,31.341031234231664,0.22846688290205686,-0.06209439240859327
252.30000000000285,31.446066497513463,0.2310611441040068,-0.06269787012116801
253.40000000000288,31.549652045029955,0.2306123929744643,-0.06138017260075257
254.5000000000029,31.65539206688301,0.23103276865150368,-0.0626984697265689
255.60000000000292,31.76032720609539,0.229587405483117,-0.06302034701161219
256.7000000000029,31.864407699610464,0.22828900310813383,-0.06229209433276317
257.8000000000029,31.9698946444666,0.22858085881500523,-0.06203260849414116
258.90000000000293,32.07348861874591,0.22818218416030672,-0.06202984625049979
260.00000000000296,32.178443513990935,0.22710011107510142,-0.06276639785558613
261.100000000003,32.282520601576834,0.2269325222840427,-0.062359990061870096
262.200000000003,32.38761023362781,0.22981410732528024,-0.062359987918520154
263.300000000003,32.49239780625785,0.2287055649827604,-0.06368271186224739
264.40000000000305,32.59753935784784,0.23102509889394202,-0.06368000100349214
265.50000000000307,32.70143288779599,0.2295961261099791,-0.0636798020741236
266.6000000000031,32.80619725966845,0.23027688420842962,-0.06335017379968022
267.7000000000031,32.911139735333265,0.22834183900322347,-0.06301748723376344
268.8000000000031,33.015957121814935,0.23071043496033694,-0.0643387261777737
269.9000000000031,33.12020275126351,0.23221093330638953,-0.06433988701979754
271.0000000000031,33.22573230438746,0.2309954776508255,-0.06359077608318398
272.10000000000315,33.33028389023604,0.2309398190785958,-0.06336019097840095
273.2000000000032,33.43444305937993,0.23244227678207452,-0.06425831398847714
274.30000000000314,33.53942291589085,0.23192449127988068,-0.06334799831558202
275.40000000000316,33.64382548264444,0.23298129635382797,-0.06345246838225416
276.5000000000032,33.74923839122411,0.23199093037398183,-0.06334992690819741
277.6000000000032,33.855119466064146,0.23258233364811792,-0.06367938713370869
278.70000000000323,33.95990632316064,0.23170770181036648,-0.06466995163024958
279.80000000000325,34.062141125017796,0.2317484280152306,-0.06466996600004382
280.9000000000033,34.16860738349987,0.23267162367543281,-0.06466996600004915
282.0000000000033,34.274584558437006,0.23390319067937188,-0.06466983723364583
283.1000000000033,34.37919639601301,0.2340574894325308,-0.06335009562346805
284.20000000000334,34.48369717088012,0.23354928369315447,-0.06462970431772774
285.30000000000337,34.589321807103204,0.23250849499950849,-0.0653298522165886
286.40000000000333,34.69446625143697,0.23433057747778258,-0.06532985160000271
287.50000000000335,34.79941683360348,0.23520719719128597,-0.06663698392789241
288.6000000000034,34.905295086601676,0.23416846467167107,-0.0666498514524747
289.7000000000034,35.01016604278397,0.2337549744817305,-0.06564425467392931
290.8000000000034,35.114996408234894,0.23448543283601164,-0.06533002720794201
291.9000000000034,35.220842078928825,0.2334744800700777,-0.06571839470715846
293.0000000000034,35.32536932502592,0.23322175414682955,-0.06599002685853872
294.10000000000343,35.43020905309605,0.23640034994464376,-0.06599002700000023
295.20000000000346,35.53602499529467,0.23567384745959946,-0.06599002699999845
296.3000000000035,35.64049603168664,0.23598063293134253,-0.06599002699953305
297.4000000000035,35.74581868628244,0.2364751719232206,-0.06598783565236666
298.5000000000035,35.85188211126141,0.2359243495076962,-0.06564973787289752
299.60000000000355,35.95700828344305,0.23435982972216785,-0.06649616930076974
300.70000000000357,36.062181973006915,0.2333229892520074,-0.06663985610244527
301.8000000000036,36.1667794460785,0.23358290537598142,-0.06663985600000144
302.9000000000036,36.27220817586258,0.23530338201397027,-0.06663985600000455
304.0000000000036,36.37825326670559,0.23491841863675444,-0.06663985887575752
305.1000000000036,36.4832535546645,0.23317575332699614,-0.06697269065837075
306.2000000000036,36.58680193673853,0.2353256310484273,-0.06821088693059352
307.30000000000365,36.694059427128735,0.2337718496206515,-0.06696950666126522
308.4000000000037,36.799170393609586,0.2352866553987727,-0.0682855357574863
309.5000000000037,36.90555567525695,0.2355953006264207,-0.06828985148740907
310.60000000000366,37.01072808112201,0.23478017235482251,-0.06729831942873998
311.7000000000037,37.11547411440281,0.23717052808147915,-0.06696321957121709
312.8000000000037,37.22187995421366,0.2362554430041286,-0.0664687863910971
313.90000000000373,37.327196488582466,0.23550321289098686,-0.06698004802435431
315.00000000000375,37.43317945121512,0.23518716357939062,-0.0676722643523835
316.1000000000038,37.53856143735292,0.2367650463859547,-0.06764027720995358
317.2000000000038,37.64397997607207,0.2360950581152937,-0.06831540308051487
318.3000000000038,37.74981226236718,0.23419991824916014,-0.06895987378372048
319.40000000000384,37.855960428407684,0.23336793925876137,-0.06802431920592777
320.5000000000038,37.96061581144578,0.234314102541881,-0.06764004901760945
321.60000000000383,38.067315869432846,0.23687658882861734,-0.0672941186888063
322.70000000000385,38.172644777441505,0.2350463854339841,-0.0682866416597272
323.8000000000039,38.27809177357151,0.23542546517969365,-0.06830339144820385
324.9000000000039,38.38325862174002,0.23609806493618113,-0.06730668985120136
326.0000000000039,38.48913081808868,0.23622921745113784,-0.06730937975992157
327.10000000000394,38.59473113698678,0.23709986093061275,-0.06730948725738539
328.2000000000039,38.70096574366951,0.23642673490923127,-0.06730901326263128
329.30000000000393,38.80783493397614,0.23713803480057027,-0.06765215059846819
330.40000000000396,38.91280755588663,0.23775699202509343,-0.06896010267203323
331.500000000004,39.01895791041216,0.23797796870761984,-0.06895209167444571
332.600000000004,39.124965713388875,0.23884058971098684,-0.06763988058173842
333.700000000004,39.230094160670824,0.23706545214225,-0.06895308236595055
334.80000000000405,39.33584386727931,0.23831501244676187,-0.06894688124305581
335.90000000000407,39.443192271419704,0.2378110232489612,-0.06981498944895126
337.0000000000041,39.54823318198954,0.23820048995725368,-0.06862491269048432
338.10000000000406,39.65494215368383,0.23775605201053363,-0.0689660753668897
339.2000000000041,39.76095449909329,0.2365411299050438,-0.06828897737923478
340.3000000000041,39.86731334925943,0.23942039975963975,-0.06961005394237052
341.4000000000041,39.97366340241861,0.24023222789510076,-0.06828660927546926
342.50000000000415,40.080097560400056,0.23953501620597886,-0.06894898426337903
343.6000000000042,40.185413303155734,0.23999965089139896,-0.07000180184219884
344.7000000000042,40.29098851587696,0.24184084185534968,-0.06894605928314768
345.80000000000416,40.3991258460816,0.2428211065909633,-0.06895563054752696
346.9000000000042,40.50398553968498,0.24161864981990816,-0.07026998749056279
348.0000000000042,40.61054973400186,0.24329622574390067,-0.07026980244502523
349.10000000000423,40.71671146834577,0.24141866738467707,-0.06885807806120159
350.20000000000425,40.820338533679646,0.24013268420064757,-0.07092997065152273
351.3000000000043,40.929139102979434,0.24105196662415357,-0.06993792424453993
352.4000000000043,41.035300821041936,0.24242204787902014,-0.06994066444677127
353.5000000000043,41.13904346305696,0.24080449143322247,-0.07126008282764928
354.60000000000434,41.24852399615514,0.24098012323702533,-0.07027019727287254
355.7000000000043,41.35418165761015,0.24268686730760564,-0.07026945408657159
356.80000000000433,41.458656965322,0.24141552818528306,-0.07159012590316483
357.90000000000435,41.56665663151269,0.2417819573747016,-0.07026912624479964
359.0000000000044,41.67148296698481,0.2396470763674385,-0.07159010932958898
360.1000000000044,41.779708640500196,0.2415064542849534,-0.07060000694973656
361.2000000000044,41.885361927587184,0.2410788708557727,-0.07059993499930783
362.30000000000445,41.993630612065566,0.23918950199163316,-0.07059993499929451
363.4000000000044,42.099320986448625,0.2404338574932144,-0.070599705680912
364.50000000000443,42.20607203201983,0.2380542969663446,-0.07026986833453464
365.60000000000446,42.312423372851235,0.23967885997737426,-0.07026979491894325
366.7000000000045,42.41888881552859,0.2402863442512347,-0.0709300082273252
367.8000000000045,42.525832965296836,0.2377929957695414,-0.07092990094843987
368.9000000000045,42.63190361384296,0.24023030271441725,-0.07191916425107836
370.00000000000455,42.73879001843851,0.23903362229872252,-0.07192006899256942
371.10000000000457,42.84608919489214,0.23939970085651702,-0.07059955981429988
372.2000000000046,42.95285707021034,0.23888635502279842,-0.07191900077694813
373.30000000000456,43.05921889016536,0.23693909025406068,-0.07192004900335824
374.4000000000046,43.16610245610745,0.23872376315409852,-0.07190334171955959
375.5000000000046,43.27282418830176,0.2388658765105569,-0.07092992851428903
376.6000000000046,43.378749383442994,0.23740242908506948,-0.07157175925097548
377.70000000000465,43.48657201541446,0.23881628723046033,-0.0722570944057992
378.8000000000047,43.593548588882996,0.23776536850742036,-0.0725847243138027
379.9000000000047,43.70021087567423,0.23713467927728252,-0.07125987784983279
381.00000000000466,43.80597648681404,0.23810765567616007,-0.0712874183314196
382.1000000000047,43.913246991663016,0.23687479183493698,-0.07258010901191048
383.2000000000047,44.01980303469232,0.23896295997109673,-0.07159052417631839
384.30000000000473,44.12744288753691,0.23611679863383844,-0.07159007434609066
385.40000000000475,44.234060602243,0.23487966614434735,-0.07291032800062824
386.5000000000048,44.340000000000465,0.23525192401946604,-0.0705996664766202
387.6000000000048,44.446972851425855,0.23765570027526478,-0.07328685916110533
388.7000000000048,44.55465215245161,0.23727979894014944,-0.07324015973083675
389.80000000000484,44.66107451004705,0.2353166292279148,-0.07155355752906001
390.9000000000048,44.76881923584611,0.23578189863746868,-0.07157375279316636
392.00000000000483,44.87396325512535,0.2343651478257294,-0.07284746933609476
393.10000000000485,44.98170422205614,0.2351131944624771,-0.07357016260195337
394.2000000000049,45.089042522096975,0.23344765046844596,-0.07357342055816662
395.3000000000049,45.1964040468909,0.2344049604522248,-0.0712597924682794
396.4000000000049,45.301112198329676,0.23332748379381243,-0.07125993907901318
397.50000000000495,45.40880389111946,0.2337355696033046,-0.07390262125312308
398.6000000000049,45.516759174229094,0.23541572158094795,-0.0737731325225166
399.70000000000493,45.62148352815205,0.23647037910473967,-0.07257960432032506
400.80000000000496,45.730766671829834,0.23740682720092,-0.07173262248767909
401.900000000005,45.83816415863433,0.2400031118142451,-0.07269506967719508
403.000000000005,45.942998759908036,0.23939382032662124,-0.07258016294636072
404.100000000005,46.05195928884093,0.24558633342436129,-0.0726267935234115
405.20000000000505,46.158520569428106,0.2490413273173977,-0.07290744776527225
406.30000000000507,46.26554445563266,0.25206413471218314,-0.072912394435237
407.4000000000051,46.3730584882833,0.25624101775200236,-0.0735256310968877
408.50000000000506,46.4801991020676,0.25986316713832336,-0.07323188688043647
409.6000000000051,46.58578235433786,0.26470161555459193,-0.07291010612026128
410.7000000000051,46.69253574088298,0.2649617210537547,-0.07291213533915597
411.8000000000051,46.800910974115055,0.2639614197615118,-0.07356154899325817
412.90000000000515,46.91000099817175,0.2599793973971974,-0.07355985599999926
414.0000000000052,47.01624739248979,0.25504554001546015,-0.07355985599990333
415.1000000000052,47.12430983904001,0.24772230760230787,-0.07355976526302399
416.20000000000516,47.23133375689632,0.24447859251448908,-0.07289929752531865
417.3000000000052,47.338064474021515,0.2411469403692057,-0.07355670612136045
418.4000000000052,47.445369764645875,0.23556613863736167,-0.07456500135463529
419.50000000000523,47.55202142999572,0.23453531156788995,-0.07454997003400887
420.60000000000525,47.66018396655596,0.23003527229990886,-0.0745317516175068
421.7000000000053,47.76801813731416,0.22905009065374557,-0.0743519922883431
422.8000000000053,47.87544312112511,0.22841405327276337,-0.07455106896530372
423.9000000000053,47.98174121995454,0.2258096962767763,-0.0732303692889551
425.00000000000534,48.08918912320699,0.22689762625857782,-0.07322997018680288
426.1000000000053,48.196849431276114,0.22563332985579543,-0.07392709259135044
427.20000000000533,48.303959967727444,0.2243378240990612,-0.07471073160852493
428.30000000000535,48.41131402750212,0.22447826158483344,-0.07584509037022658
429.4000000000054,48.51875855307369,0.2250027107861221,-0.07513600174345303
430.5000000000054,48.626618389334624,0.22699537114454213,-0.0738896055723921
431.6000000000054,48.7337641675994,0.22701605736021205,-0.07520996922377243
432.70000000000545,48.841347832644786,0.22562359738296478,-0.07520990435047459
433.8000000000054,48.94678843109997,0.22781588452727614,-0.07620438039912525
434.90000000000543,49.05457682111605,0.22595791890813627,-0.07619955781376087
436.00000000000546,49.16351796093948,0.22452461703397114,-0.07520989138326772
437.1000000000055,49.271738694446704,0.22711833914447152,-0.07520990823874296
438.2000000000055,49.37892245882891,0.22607973871520026,-0.07653644300949347
439.3000000000055,49.48619487049244,0.2295333354263215,-0.07559946123738692
440.40000000000555,49.59333533892148,0.22679992244276176,-0.07587002745445126
441.50000000000557,49.701205207781626,0.2284671248917404,-0.07487584987825002
442.6000000000056,49.80556951762509,0.22810255568871404,-0.07488005001622966
443.70000000000556,49.916348755338966,0.22680017343546655,-0.07553986759313736
444.8000000000056,50.02390832565314,0.22758301279420673,-0.07554002300152618
445.9000000000056,50.13074159455468,0.22654974679952827,-0.07553930070706016
447.0000000000056,50.23946081887665,0.22810839756392148,-0.07620013975086515
448.10000000000565,50.34698105404055,0.22926903531291673,-0.07620013700477202
449.2000000000057,50.45418241355617,0.22728120726371395,-0.07619179464502635
450.3000000000057,50.56156958238081,0.22894160740861982,-0.0775093085165568
451.40000000000566,50.66819544123871,0.22817269294352957,-0.07492016844402372
452.5000000000057,50.775573845903516,0.2257310870885227,-0.07487603711322288
453.6000000000057,50.883498138446214,0.22876852482020416,-0.07618097692912018
454.70000000000573,50.99170987803191,0.22560876605236446,-0.07619056057455476
455.80000000000575,51.10018922335998,0.2240402218556507,-0.0755241306652672
456.9000000000058,51.20574321163003,0.22601018561579447,-0.07625430479623185
458.0000000000058,51.31457162024972,0.2251139770330289,-0.0758967802499293
459.1000000000058,51.421208566117706,0.22207513354129452,-0.0761898870500528
460.20000000000584,51.53103830972114,0.22343648087897378,-0.0761898813281725
461.3000000000058,51.64018446194507,0.22286211544727264,-0.07751022407160679
462.40000000000583,51.74752003240314,0.22256938742177662,-0.0775101150007762
463.50000000000585,51.85576929684061,0.22318914541005289,-0.07751011492640902
464.6000000000059,51.96353528294603,0.22442096747444087,-0.07877850674638731
465.7000000000059,52.071345202166164,0.22593221876344358,-0.07789013219605723
466.8000000000059,52.1794155326757,0.22341584497307912,-0.07751011482628734
467.90000000000595,52.286846607758285,0.22320303689803678,-0.07751011500000082
469.0000000000059,52.39520547838125,0.22733222604984957,-0.0775101150000328
470.10000000000593,52.50365793868941,0.22597656062718952,-0.07751006466780197
471.20000000000596,52.612133490078875,0.2257410319060087,-0.07883157048290013
472.300000000006,52.71968651845348,0.22651884568568267,-0.07784992090713683
473.400000000006,52.82790048088674,0.2277691402705308,-0.07783778845149358
474.500000000006,52.93508576901819,0.22636829768516628,-0.07916018850818363
475.60000000000605,53.04318891919753,0.2271194690723168,-0.07784991745981085
476.70000000000607,53.14896499676495,0.22631674454430867,-0.07785117450826196
477.8000000000061,53.260293890212736,0.22846479334137923,-0.07982016576835171
478.90000000000606,53.36849432089744,0.22871764545110282,-0.07982016799965086
480.0000000000061,53.475853717885414,0.2275923410685354,-0.0798212432222094
481.1000000000061,53.58474456399909,0.2286196197704553,-0.07799809584332174
482.2000000000061,53.69374974479827,0.23092465176601012,-0.0795073144299625
483.30000000000615,53.800557685507336,0.23087204948086185,-0.08014977253044275
484.4000000000062,53.909507936503154,0.23195414983396836,-0.08014989509121495
485.5000000000062,54.01866480376973,0.23298875011756703,-0.07785419915482938
486.60000000000616,54.126567582410814,0.23311041834609736,-0.0785217542884813
487.7000000000062,54.234100632608,0.23499641358400453,-0.07981991305872249
488.8000000000062,54.34274668214681,0.23330683273534292,-0.07982041725873756
489.90000000000623,54.45118109413051,0.23322764936774998,-0.08188218832937366
491.00000000000625,54.55901826350385,0.233156803982074,-0.08049197661700047
492.1000000000063,54.66753971866136,0.2331259636544169,-0.07982003163960005
493.2000000000063,54.77719158263229,0.2319109853476362,-0.0798201508340961
494.3000000000063,54.88427845665781,0.23384054379462038,-0.08115980375962195
495.40000000000634,54.99291804466086,0.23456383804896408,-0.08244908392025696
496.5000000000063,55.100302140878135,0.2349325859553737,-0.08179997070613876
497.60000000000633,55.20938197683539,0.2363476306303366,-0.0817999709999997
498.70000000000636,55.31627620760704,0.23525631749994563,-0.08179997101049441
499.8000000000064,55.42508158836616,0.23530007008561182,-0.08160781401845085
500.9000000000064,55.53506747029424,0.23791054931982542,-0.08126329074976812
502.0000000000064,55.64087220928366,0.236971706441763,-0.08246021955119609
503.10000000000645,55.75100378214152,0.2349510459649985,-0.08246021732371167
504.2000000000064,55.85989788176414,0.23337201396534876,-0.08113976959827252
505.30000000000643,55.968422700392246,0.2315359243599709,-0.08244975614278305
506.40000000000646,56.07818117607528,0.2346572471779548,-0.08306936077819849
507.5000000000065,56.185466895361834,0.23249585005521795,-0.08307472920995451
508.6000000000065,56.29419413823169,0.23316042956443633,-0.0831197952952043
509.7000000000065,56.403097774379205,0.2353272830948719,-0.08304410384173311
510.80000000000655,56.511369225015024,0.23633392520067903,-0.08443017729310931
511.90000000000657,56.62000096858667,0.23486140240500658,-0.0841590315695071
513.0000000000066,56.728767941160434,0.23453238139759713,-0.08376714424255338
514.1000000000065,56.83666711664323,0.23417831457302596,-0.0844387664654751
515.2000000000066,56.94553242290561,0.23535964937080786,-0.08666072209594944
516.3000000000065,57.05421534909047,0.2365633887987127,-0.08673545008319383
517.4000000000067,57.16256387700449,0.2399753111377261,-0.08575691515946993
518.5000000000066,57.270090454407224,0.2380631829521768,-0.08574982699485201
519.6000000000067,57.37883676445365,0.24034885828255872,-0.08574982691157906
520.7000000000066,57.48801462001975,0.24248783359151216,-0.08653925875574675
521.8000000000067,57.595935796546954,0.23883574587849749,-0.08841531305290751
522.9000000000067,57.70483896989684,0.2393703394395449,-0.08706589703661294
524.0000000000067,57.81349470358671,0.2395693936514025,-0.0883798050000002
525.1000000000067,57.92130100693701,0.23941420856486412,-0.08726184659817937
526.2000000000068,58.0299012519763,0.24160836606419595,-0.08773665325229718
527.3000000000068,58.138291112337946,0.2440215313569014,-0.08640975603757362
528.4000000000068,58.24643747171147,0.24291138118279115,-0.08846774720221173
529.5000000000068,58.35594701309935,0.24462245011549905,-0.08970098357296319
530.6000000000068,58.46395634066801,0.24443326745084717,-0.08970014700122775
531.7000000000069,58.57256427460588,0.24423807578658868,-0.08969757918655219
532.8000000000068,58.681111461633435,0.2429090919668792,-0.09067984324805067
533.9000000000069,58.7897847075873,0.24255326461725435,-0.09067764932010602
535.0000000000068,58.89808826731476,0.24160515465645027,-0.08969963475030118
536.100000000007,59.00777289807942,0.24289376258115436,-0.09102011491471451
537.2000000000069,59.11539272744134,0.24173945363657828,-0.09102012500000445
538.300000000007,59.22354201542047,0.2407668937447155,-0.09102013188519686
539.4000000000069,59.33305185669786,0.24080066434567626,-0.09233849413472939
540.5000000000069,59.442400902980786,0.24014341050250204,-0.09328000861120289
541.600000000007,59.550404260032316,0.24240000780868548,-0.09333596983525538
542.700000000007,59.65895342799423,0.24219166598421132,-0.09333017799512566
543.800000000007,59.768336509435045,0.2456670400422593,-0.09333017800611865
544.900000000007,59.87815072986311,0.2465852540465096,-0.0933186489837432
546.000000000007,59.98662502465079,0.24798441477006175,-0.093000271704474
547.1000000000071,60.094957015068886,0.2487209489193845,-0.09468291732876599
548.2000000000071,60.20373652854209,0.24846448605247612,-0.09465123067902503
549.300000000007,60.31313319619717,0.24915595889006437,-0.09463996980465872
550.4000000000071,60.42104200472985,0.25061072371307996,-0.09664663555495734
551.500000000007,60.52980733464871,0.2502876213789119,-0.0972897280776559
552.6000000000072,60.63640294758617,0.2530131503837644,-0.09627712102075403
553.7000000000071,60.74681215208386,0.2532894223737264,-0.09630535031429766
554.8000000000072,60.85592073746302,0.25218000651150807,-0.09727410856319896
555.9000000000071,60.96471162020441,0.25129709581242426,-0.0972699589977215
557.0000000000072,61.07323097316163,0.2507410596171278,-0.0972647879154871
558.1000000000072,61.181690261878686,0.2526118798269289,-0.09728385704352949
559.2000000000072,61.29205656436093,0.25292779395496395,-0.09860000526611978
560.3000000000072,61.400101296837356,0.2519827703566012,-0.09992829884652599
561.4000000000073,61.50893528609951,0.25129260351032623,-0.09925528351637247
562.5000000000073,61.61803570771964,0.2523763803278258,-0.09854514654753288
563.6000000000073,61.72734692212776,0.2542023172035208,-0.09497607652646778
564.7000000000073,61.83595494939097,0.2556781048726124,-0.09673861996459898
565.8000000000073,61.944900700695996,0.25304729475800447,-0.10022496545414894
566.9000000000074,62.05505711172679,0.2549475259126577,-0.10023956207778006
568.0000000000074,62.164390834580985,0.25390006480156074,-0.10123068422670611
569.1000000000074,62.27447975334973,0.2591532727358826,-0.102549971623076
570.2000000000073,62.383942388409466,0.2598593359218143,-0.10377746045544578
571.3000000000073,62.493856829581546,0.2617172370497685,-0.10484644541275578
572.4000000000074,62.60167171848468,0.26732338367804825,-0.10386173164293133
573.5000000000074,62.71049084532183,0.2743464539469924,-0.10518014275417897
574.6000000000074,62.8198966209018,0.26634468086699675,-0.10550990835608198
575.7000000000074,62.92907556320843,0.2624137754272245,-0.10684465438663615
576.8000000000075,63.03756923796068,0.25577607045775463,-0.10683007329343797
577.9000000000075,63.14801985933544,0.2563371951229841,-0.10780348028318887
579.0000000000075,63.257621564153936,0.2560600322717525,-0.10516553997131961
580.1000000000075,63.367079538841885,0.25560063524752263,-0.10341555858388185
581.2000000000075,63.477044974854856,0.2560081478529257,-0.10514901332641191
582.3000000000076,63.58799195551788,0.26056080225193456,-0.10638639513936843
583.4000000000076,63.69694455167732,0.2607201360758765,-0.11067667639233125
584.5000000000076,63.805186411057626,0.2616828850070671,-0.11463583653891707
585.6000000000076,63.91538522974646,0.26172024887551126,-0.11941527756111903
586.7000000000077,64.02370609914824,0.2616975361497168,-0.12659451386372567
587.8000000000077,64.13382648486954,0.262209000136464,-0.12263575569967111
588.9000000000076,64.24181573214801,0.2619597177978321,-0.11977424331149855
590.0000000000076,64.35268376112384,0.26234597585666497,-0.11846977242294088
591.1000000000076,64.46171614986521,0.26311076168807884,-0.11715046634218718
592.2000000000077,64.57088491086195,0.26180551501444493,-0.11587536941477872
593.3000000000077,64.68041504337198,0.2647393392005351,-0.11714120500092662
594.4000000000077,64.78950537238342,0.261385054834149,-0.11742937044378943
595.5000000000077,64.89904520953779,0.26279031233682254,-0.11847124444968182
596.6000000000078,65.00899564618143,0.26662571344776165,-0.11846994429380331
597.7000000000078,65.11889064281732,0.26601700956537666,-0.11946169712521826
598.8000000000078,65.22713728368657,0.26740299978809495,-0.11981276169939603
599.9000000000078,65.3346043384714,0.26805799644886447,-0.1201128168181933
601.0000000000078,65.44570493910328,0.26698120998183256,-0.12146843748276748
602.1000000000079,65.55594761265841,0.26812871772452873,-0.12208998596015075
603.2000000000079,65.66473662172555,0.2721698254758256,-0.12244054597533394
604.3000000000079,65.77436470385054,0.27102998424610036,-0.1224194819243487
605.4000000000078,65.88359624359606,0.2707585732159743,-0.1250264083494268
606.5000000000078,65.99277889010175,0.2722796510341152,-0.1263730067403479
607.6000000000079,66.1028322529993,0.27406927651933427,-0.1263700611107912
608.7000000000079,66.21256271296532,0.2745363153901167,-0.1263704825449432
609.8000000000079,66.32143448851869,0.27529352910125887,-0.12834011269467327
610.9000000000079,66.43146090042775,0.27471987997726716,-0.12834474452955336
612.000000000008,66.54068881893572,0.27794202387581757,-0.1296628702571887
613.100000000008,66.64728149388446,0.2816308678252512,-0.13097092624649997
614.200000000008,66.75773997641392,0.2833474008266421,-0.130772252934924
615.300000000008,66.8684548961983,0.28718930555111677,-0.13252022720733914
616.400000000008,66.978613856794,0.28556140352293585,-0.13286616185486633
617.5000000000081,67.08867520978505,0.2894616428212892,-0.13390187388825048
618.6000000000081,67.19790797079837,0.2933988514466183,-0.135196918618675
619.7000000000081,67.3043747537861,0.29610661481139733,-0.1362498047046623
620.8000000000081,67.41554500469556,0.2992777829136221,-0.13756920183991683
621.9000000000082,67.52614943008867,0.30540975901092704,-0.13755610788356876
623.0000000000082,67.6340930186052,0.3060864641989617,-0.1388918318514869
624.1000000000081,67.74479653442111,0.30960312395773343,-0.1414048800936687
625.2000000000081,67.85413828406222,0.3146913847455662,-0.14152947508072433
626.3000000000081,67.96322960229489,0.31558746387390396,-0.14283571313089372
627.4000000000082,68.0727052827846,0.32350110945289934,-0.14416101430515615
628.5000000000082,68.18224059780191,0.32645873075751897,-0.14561738642154287
629.6000000000082,68.29257726688996,0.32731125637746494,-0.14678705364046252
630.7000000000082,68.4016196058838,0.3298061299752402,-0.14811779103370082
631.8000000000083,68.51201329527461,0.3318449214323477,-0.1507552405870154
632.9000000000083,68.62144478989708,0.3348666581817674,-0.15208007666272927
634.0000000000083,68.73010179084218,0.3363462499896019,-0.15271386841268786
635.1000000000083,68.8396811811568,0.3426883991093009,-0.15534886207881193
636.2000000000083,68.94969673825814,0.34646526744959605,-0.15797927752580954
637.3000000000084,69.05950533909619,0.35201039984178745,-0.15996456630842815
638.4000000000084,69.16885659317862,0.35668155050886574,-0.1612811205999325
639.5000000000084,69.27839625854028,0.36258400620353914,-0.16392311740076648
640.6000000000083,69.38886862069744,0.36846416086340683,-0.1646392809110364
641.7000000000083,69.49854618407952,0.3745656270538067,-0.16740749009139355
642.8000000000084,69.60731463112901,0.3862434636463622,-0.16992300373136837
643.9000000000084,69.71888587183506,0.3986182726362184,-0.17176661278398075
645.0000000000084,69.82737234240273,0.40885701315142203,-0.1749871695452585
646.1000000000084,69.93806058731883,0.4227944475170421,-0.17719339031243786
647.2000000000085,70.04782779587197,0.4350046168670837,-0.17911438885795494
648.3000000000085,70.15705803473038,0.4469785158109795,-0.18278906522853333
649.4000000000085,70.26742292032704,0.46143712914288604,-0.18538929387820513
650.5000000000085,70.37692560316478,0.472015162303289,-0.18950218702646726
651.6000000000085,70.48724787590854,0.4856577641935038,-0.19103550936078095
652.7000000000086,70.5959960504675,0.5005629075992213,-0.19585220867327013
653.8000000000086,70.70688255291321,0.516471763177961,-0.20005597788288254
654.9000000000086,70.81685904440256,0.5320124996027961,-0.20349263922671978
656.0000000000086,70.92649976361795,0.547767982572824,-0.20709469948756176
657.1000000000087,71.03700221216035,0.56374135325466,-0.211292840099635
658.2000000000087,71.14757077576029,0.5822223104642739,-0.21438551814133566
659.3000000000086,71.25747054707828,0.5982103693570024,-0.21872527565421285
660.4000000000086,71.36772295725504,0.6175455296070087,-0.22307866983003866
661.5000000000086,71.47630361669313,0.6351861945896108,-0.22747901961164718
662.6000000000087,71.58654815938856,0.6558223342925132,-0.23252499639554491
663.7000000000087,71.69739896885332,0.6731486161394686,-0.237103049437843
664.8000000000087,71.80674304891745,0.6961292202157152,-0.24128785553449061
665.9000000000087,71.91653187840012,0.7144904946409166,-0.24698544257805288
667.0000000000088,72.02755457538242,0.7361313195532735,-0.25162168165632925
668.1000000000088,72.13703227438594,0.7595209464922712,-0.25661032368914416
669.2000000000088,72.24544892140325,0.7824048447800662,-0.26325640746615164
670.3000000000088,72.35553980895519,0.8036753445812562,-0.27020904162636716
671.4000000000088,72.46520203341949,0.8294025451082709,-0.2759150817518998
672.5000000000089,72.57515708545215,0.8532937772229481,-0.2809081195986858
673.6000000000089,72.68538639488057,0.877973306500148,-0.2877350825068947
674.7000000000089,72.79560263027659,0.9048893188624431,-0.29431474397899526
675.8000000000088,72.90587119351639,0.9338107220640272,-0.30143147486158783
676.9000000000088,73.01623430336763,0.9594020980243149,-0.30944276672613036
678.0000000000089,73.12680939640481,0.9868093295947322,-0.31499686361293744
679.1000000000089,73.23752840027386,1.0149637303369736,-0.3227006640100103
680.2000000000089,73.3465165587632,1.0425449670313502,-0.32976707916617576
681.3000000000089,73.45758004289777,1.0699918014313379,-0.3390993122964816
682.400000000009,73.56733814264976,1.099353253797831,-0.348165280254475
683.500000000009,73.67830401104656,1.1293662674175762,-0.35531574419107814
684.600000000009,73.78837446996842,1.16044732281271,-0.3633705392293227
685.700000000009,73.89785800575548,1.1896169061491475,-0.3727948606067759
686.800000000009,74.00658337361315,1.222658301946817,-0.3817970943637836
687.9000000000091,74.11897580641697,1.255513362281093,-0.3912545496171269
689.0000000000091,74.22908194995368,1.2889120580231586,-0.4015747110626684
690.1000000000091,74.3398940325882,1.32356161710583,-0.41106054913530166
691.2000000000091,74.45011430847792,1.3586037967421885,-0.42148027056962256
692.3000000000092,74.56022625221348,1.3885439410054936,-0.4320398857023844
693.4000000000092,74.67092975675709,1.4236547497408714,-0.442487769313757
694.5000000000091,74.78092607267925,1.4592459253226764,-0.4539354905618955
695.6000000000091,74.89020106767094,1.494421105030333,-0.4655124037830518
696.7000000000091,75.0011152004278,1.5257198038773516,-0.4768129067906397
697.8000000000092,75.11163777678324,1.5604042904946582,-0.48934534872500457
698.9000000000092,75.21908253032166,1.5930730401467272,-0.5002785023276264
700.0000000000092,75.3302738749807,1.6298945958713755,-0.5129567916292905
701.1000000000092,75.44113249316267,1.663527316478883,-0.5256510112515933
702.2000000000093,75.55100483420121,1.6980868479462488,-0.5394735101713151
703.3000000000093,75.66074182991579,1.7298254567741378,-0.5526728098728215
704.4000000000093,75.77075039059183,1.7631737573415913,-0.5659466555055856
705.5000000000093,75.88182870929909,1.7983180601005573,-0.5788541977994743
706.6000000000093,75.9918697417605,1.8292347688672548,-0.5929563572650931
707.7000000000094,76.10271996624984,1.8651210903064745,-0.6084236369132023
708.8000000000094,76.21383664171586,1.8993597258982278,-0.6215941039150117
709.9000000000094,76.32392528798177,1.9316029879869396,-0.6371142756742021
711.0000000000093,76.43418746611093,1.9619975266265468,-0.6523788910942825
712.1000000000093,76.54412215509566,1.9960236661700042,-0.6675072648722398
713.2000000000094,76.65263810472153,2.028543810454722,-0.6838477200335378
714.3000000000094,76.76288342501627,2.0639676603602157,-0.7010086193085816
715.4000000000094,76.8743994902844,2.1007470743061933,-0.7182248907896471
716.5000000000094,76.98420998791472,2.130452091044725,-0.7331907706832888
717.6000000000095,77.09433069428987,2.1645108560671833,-0.7499301729449823
718.7000000000095,77.20438698445776,2.1990975370433574,-0.7658621319394192
719.8000000000095,77.31411940100278,2.2321391431392845,-0.782620159035428
720.9000000000095,77.42488859975812,2.262759389369621,-0.8016089672754183
722.0000000000095,77.53503825054136,2.298269538732459,-0.8185510650091836
723.1000000000096,77.64464349687756,2.327162629090517,-0.837267138709243
724.2000000000096,77.75501624598472,2.358653567134634,-0.8551684331423677
725.3000000000096,77.86627806885086,2.3899733855757073,-0.8734345306364868
726.4000000000096,77.97458056254852,2.4252560362692144,-0.8922005590023581
727.5000000000097,78.08383564753504,2.457763745557841,-0.9106106558502298
728.6000000000097,78.19494935888702,2.493902817347494,-0.9309356051174875
729.7000000000096,78.30416213708487,2.522204956853475,-0.9501781862647145
730.8000000000096,78.41687386783082,2.5541372647958127,-0.9686870663932212
731.9000000000096,78.52767231506803,2.583145220138185,-0.9897898201522439
733.0000000000097,78.63833547944539,2.615732210538537,-1.0104982450846913
734.1000000000097,78.74735776415038,2.6416945998774115,-1.0309446754526275
735.2000000000097,78.85874349231402,2.6712954204421804,-1.04983323192638
736.3000000000097,78.96904307583614,2.694779463340759,-1.0713280452779395
737.4000000000098,79.07939880232642,2.723421661813142,-1.0938996083196582
738.5000000000098,79.18870627870852,2.7491702723251272,-1.1132314145601288
739.6000000000098,79.30029153199543,2.789143977489308,-1.1363372881391358
740.7000000000098,79.4096275771068,2.8407098015226415,-1.1563184235098367
741.8000000000098,79.52092240532959,2.902993080476661,-1.1782986009198724
742.9000000000099,79.63011016566003,2.9776696063779786,-1.2008383748174447
744.0000000000099,79.74291293064749,3.0606953250947564,-1.2221116161348013
745.1000000000099,79.85326479132773,3.1454158594476116,-1.246087834704844
746.0000000000099,79.94475998775623,3.207226169088611,-1.2650281505255117