File: 01_Data/Concrete_Block/STA/N2/10K_min/Concrete_Block_STA_N2_10KData_230919_R1.csv
##Temp./Â°C,Time/min,DSC/(mW/mg),Mass loss/mg
41.0,10.837249437322841,-0.006241501461783816,-0.00035963613499845337
42.40000000000002,11.181069686420049,0.01546404344897967,-0.0006733793793198828
43.80000000000004,11.423875577604031,0.031108339888782588,-0.0007302018807990862
45.20000000000006,11.629392638342608,0.04077478460411044,-0.0008156344759235878
46.60000000000008,11.81592005390466,0.05006018040558313,-0.002571760358473618
48.0000000000001,11.989638769470202,0.056539783737228344,-0.0036482810761127027
49.40000000000012,12.154831379971416,0.06244768715841653,-0.0008791870302777838
50.80000000000014,12.319212235911653,0.06366947314364291,-0.003862496337125876
52.20000000000016,12.47695143021756,0.06985295758254928,-0.0024447389981778755
53.60000000000018,12.63351088873972,0.07264315623050743,-0.0020854921566737517
55.0000000000002,12.788911040218066,0.07505005094187123,-0.00320267784484507
56.40000000000022,12.940213721288211,0.07827845236821229,-0.002428362652889149
57.80000000000024,13.092173276830948,0.08002894559120155,-0.002357615792986323
59.20000000000026,13.243119832208047,0.08251498697125781,-0.00503396376457399
60.60000000000028,13.392176879630787,0.08206852106590179,-0.004881379212063663
62.0000000000003,13.540000000000028,0.08492402193856186,-0.003730003667209658
63.40000000000032,13.688794327922949,0.08609914295409382,-0.002451426315830396
64.80000000000034,13.835688690236461,0.09075217368123178,-0.0034140357482712602
66.20000000000036,13.980107587687948,0.0883661460419618,-0.0024022147032676244
67.60000000000038,14.126535677731793,0.09087576784761064,-0.0050564841769178415
69.0000000000004,14.27010640044918,0.0945778999566973,-0.005036148840323662
70.40000000000042,14.413656902523604,0.09374646670803788,-0.005040487770635593
71.80000000000044,14.558299020593315,0.09180183838732114,-0.005039216949836778
73.20000000000046,14.698990043165825,0.09521375063958915,-0.0050781712008030055
74.60000000000048,14.841642804147353,0.09579030988586945,-0.006357137854786643
76.0000000000005,14.98413653572689,0.09865931361276492,-0.008339863399116965
77.40000000000052,15.124956411886833,0.10224780711236314,-0.007679755630263685
78.80000000000054,15.264095125189558,0.09971237384373799,-0.004111895673192478
80.20000000000056,15.404156462996616,0.10041068765075134,-0.008645944324133126
81.60000000000058,15.546408987410079,0.10111379262925801,-0.005964745029492846
83.0000000000006,15.685015041146352,0.10076828391630155,-0.007302878346422403
84.40000000000062,15.825621929719752,0.10108087673460275,-0.007349489010777255
85.80000000000064,15.964462828995227,0.0983982807444419,-0.008671215978983682
87.20000000000066,16.103129495274285,0.0978265205576494,-0.009980349814076028
88.60000000000068,16.240985866766803,0.09994463426522171,-0.011300178798893334
90.0000000000007,16.380000000000095,0.09647297569259572,-0.010508747820147768
91.40000000000072,16.51679613181222,0.09698925037097883,-0.011312592387255016
92.80000000000074,16.651203912800405,0.09518080719431543,-0.009979831945888584
94.20000000000076,16.79239337575499,0.09648884353945064,-0.008669738503462199
95.60000000000078,16.930413413372943,0.09792962786410087,-0.008971887811550339
97.0000000000008,17.066560260387558,0.09712867455037055,-0.010636181183961035
98.40000000000082,17.203870590068203,0.09548185585587077,-0.011959914718688403
99.80000000000084,17.34000000000008,0.0944947347875078,-0.01163009686996297
101.20000000000086,17.476243187781158,0.0933813903599674,-0.011282196640607367
102.60000000000088,17.61256995919499,0.09460245650544463,-0.010311430182012415
104.0000000000009,17.747756272502727,0.09569608193848356,-0.01132157124043065
105.40000000000092,17.8855597251508,0.09541191050242737,-0.011650436005147036
106.80000000000094,18.02305132200852,0.09284704409382116,-0.014259936894877256
108.20000000000095,18.156363797844456,0.09335939586546571,-0.012940948617806036
109.60000000000097,18.29168782466246,0.0920089275747229,-0.012950147360885289
111.000000000001,18.42637837505464,0.09049084184055145,-0.014005430901618432
112.40000000000101,18.562123950930804,0.08946032203106502,-0.015579952194421764
113.80000000000103,18.697789360205444,0.08829164945302703,-0.014257285668914932
115.20000000000105,18.833244079991296,0.08626897157570368,-0.01412267032131087
116.60000000000107,18.968558523391746,0.08494412262707884,-0.01492563951064696
118.0000000000011,19.10204885366424,0.08136096004033089,-0.015579833985332137
119.40000000000111,19.237141835028762,0.08306695083835147,-0.015579750323977848
120.80000000000113,19.371775775852193,0.07860449909111589,-0.015590264603130954
122.20000000000115,19.506359687073253,0.07860507233683478,-0.015980539685060968
123.60000000000117,19.64194350950571,0.07717242325863904,-0.016900057204435548
125.0000000000012,19.776337263821638,0.07459439085113373,-0.01557885684721061
126.40000000000121,19.910631060301185,0.07521956912892591,-0.01690017568025226
127.80000000000123,20.045534252926675,0.0718637279151133,-0.01690017599913496
129.20000000000124,20.180299821802507,0.07012792836242943,-0.01690927974138212
130.60000000000127,20.315175563511165,0.06954864452190668,-0.01756004001670064
132.0000000000013,20.44855281174383,0.0676424517758143,-0.017544610240371128
133.4000000000013,20.580637293287644,0.06757326495982463,-0.016897545969401406
134.80000000000132,20.71641591465938,0.06736944811993584,-0.015898239539844816
136.20000000000135,20.850717533250666,0.06900988757074322,-0.016900037078011465
137.6000000000014,20.985524139182225,0.06537770236484541,-0.018213417454117753
139.0000000000014,21.11936804965739,0.06297877402478802,-0.01821003600001614
140.4000000000014,21.254894056863773,0.06224586275974664,-0.018219556094797085
141.80000000000143,21.387760968757892,0.06142916432755485,-0.017885333361554068
143.20000000000147,21.52209978755368,0.06116193501915235,-0.01722884703897254
144.60000000000147,21.656565902958256,0.059041160998255515,-0.01758829858394151
146.00000000000148,21.790687963225952,0.06066227541922942,-0.01855013554914553
147.4000000000015,21.923756759643453,0.058926243931204825,-0.017897302538632864
148.80000000000155,22.058670884336497,0.05950400352765173,-0.0195399324440233
150.20000000000155,22.192521793096557,0.05526611563844108,-0.018375691259977955
151.60000000000156,22.325294957959088,0.05351581258059568,-0.018223010881641244
153.0000000000016,22.45961749506929,0.05212328659320309,-0.017855772208873688
154.40000000000163,22.59200615493368,0.05154517744284459,-0.017880513427268596
155.80000000000163,22.726276340726944,0.05021356610226402,-0.018539924745127223
157.20000000000164,22.860566036000677,0.04923679343682208,-0.018210074017053657
158.60000000000167,22.992989700606806,0.047370683107674116,-0.018209602212246878
160.0000000000017,23.1262118734903,0.04531056036760539,-0.018742006102912434
161.4000000000017,23.260453441921427,0.044600756692612764,-0.020849855323928246
162.80000000000172,23.39260067422836,0.04363128617293777,-0.019540324050743685
164.20000000000175,23.524852391084018,0.04242712269675297,-0.018509856819638237
165.60000000000178,23.658717191591347,0.04083007249671322,-0.020402025896084197
167.0000000000018,23.790937112556833,0.041842143978995994,-0.02052619313983417
168.4000000000018,23.9234294589784,0.040482027890357264,-0.020514578002522654
169.80000000000183,24.056588048713905,0.03915567721298063,-0.020629353710261533
171.20000000000186,24.189324088245442,0.03907860429793142,-0.01930994194720892
172.60000000000187,24.322254932669694,0.03738778042654878,-0.020629694820939903
174.00000000000188,24.45333902748749,0.036938024050051865,-0.020629824569490474
175.4000000000019,24.589191901208842,0.03578462344308164,-0.0202997390987667
176.80000000000194,24.72229508125629,0.0360594940988721,-0.02031971555092671
178.20000000000195,24.85477323461286,0.03312422492812028,-0.020957220661860454
179.60000000000196,24.987988198137213,0.030731768878800914,-0.021280276968830947
181.000000000002,25.120990588288954,0.030120115435831707,-0.021328707313264417
182.40000000000202,25.253364944670455,0.03177610495194938,-0.020529738280822052
183.80000000000203,25.386653266696484,0.03157472353451962,-0.021840753352218023
185.20000000000203,25.520000000000195,0.03138476958589398,-0.02314991145375256
186.60000000000207,25.654245726355477,0.02944907347267023,-0.021919160112267022
188.0000000000021,25.78534417638737,0.03078197026628815,-0.02249971222228364
189.4000000000021,25.92112017404014,0.029949654120200897,-0.02182923505962897
190.80000000000211,26.056312678605256,0.031357912498437335,-0.022952714552993747
192.20000000000215,26.18958982576567,0.029641412171844905,-0.021509963638341567
193.60000000000218,26.322796328068385,0.030925777795739684,-0.021567084106086654
195.0000000000022,26.45747089578009,0.029216090611713597,-0.02415034282376194
196.4000000000022,26.59139368939388,0.027124733215915242,-0.02468109831010068
197.80000000000223,26.725742174268802,0.027935776967998205,-0.022840850841931548
199.20000000000226,26.857861633328426,0.029115919921723687,-0.024151818619468024
200.60000000000227,26.99302392385546,0.027962012773988798,-0.024149569968105133
202.00000000000227,27.126013678272404,0.02808841379401894,-0.022853335902233596
203.4000000000023,27.25874539395577,0.026020239286044022,-0.022830321248821228
204.80000000000234,27.39173524694755,0.025978091041675366,-0.023492094372074668
206.20000000000235,27.526899531846233,0.024280238645765007,-0.023479827061533065
207.60000000000235,27.65850740026504,0.023887340101572452,-0.023479890845787388
209.0000000000024,27.791403565715502,0.023614273168629518,-0.02216001181424776
210.40000000000242,27.924189815282272,0.022120492761251942,-0.024454906457060943
211.80000000000243,28.055917303682744,0.02011284724555562,-0.024469880000085098
213.20000000000243,28.190000000000232,0.02153059967351223,-0.024469879999999833
214.60000000000247,28.32341224480062,0.022327895434689493,-0.024477889828481203
216.0000000000025,28.45674993965364,0.017992995546034285,-0.023505788412093054
217.4000000000025,28.58990848454568,0.02017972810820079,-0.026166952796320864
218.8000000000025,28.721688009351926,0.020785052774907387,-0.024795497190751803
220.20000000000255,28.855214283175528,0.020201007325471254,-0.024792894614407146
221.60000000000258,28.990598352598205,0.021892219081700803,-0.024798157773632035
223.0000000000026,29.122432700734432,0.019697906067052573,-0.026163418472291866
224.4000000000026,29.25582624800605,0.018791618612823413,-0.02578982865379409
225.80000000000263,29.3892607034644,0.019119699103753218,-0.024469710320043525
227.20000000000266,29.52276424064845,0.01868618820028689,-0.02578984280684793
228.60000000000267,29.656455669475072,0.017536102421416455,-0.02645002102248384
230.00000000000267,29.788755392305923,0.015984867590331797,-0.025139847315076125
231.4000000000027,29.92182294909135,0.014211021970679916,-0.025136242109269347
232.80000000000274,30.05589389363681,0.012900001559235319,-0.024809837831721637
234.20000000000275,30.187941968308273,0.013785252873429243,-0.02611991137319869
235.60000000000275,30.320703261165654,0.015006059293307894,-0.027429312785568705
237.00000000000279,30.454093915662273,0.01297487170854672,-0.02743001200007633
238.40000000000282,30.58793569367518,0.011568998387908813,-0.027430003370985112
239.80000000000283,30.721104836196012,0.009434817894223402,-0.024423105644094
241.20000000000283,30.85309262685533,0.011884250762779436,-0.02709914149491066
242.60000000000286,30.987135654830524,0.00924938983908552,-0.0257805325527789
244.0000000000029,31.119813711871483,0.009896576343932484,-0.025453589681529998
245.4000000000029,31.25333233046303,0.008361936091649813,-0.026779971060983954
246.8000000000029,31.385254048393353,0.006877721512390744,-0.02677989664357039
248.20000000000294,31.51909889778531,0.005963739418031189,-0.026779282247240133
249.60000000000298,31.65335919098204,0.004987589972422102,-0.024139839111364303
251.00000000000298,31.7861782720119,0.0025571165699189713,-0.02674503504714476
252.400000000003,31.91878786828846,0.0020964331864035124,-0.02677935285624944
253.80000000000302,32.0493214225042,0.002111153724035031,-0.02518517382601626
255.20000000000306,32.18376076540634,0.0005862205318860614,-0.02611565977187169
256.6000000000031,32.3186082342863,0.00015038579281601017,-0.024801043771115694
258.00000000000307,32.45204357937575,-0.00042571751493336585,-0.025789353224489275
259.4000000000031,32.58565422425793,0.0005111906693933133,-0.025789757023546578
260.80000000000314,32.72019937281946,-0.00020266740954122398,-0.025129971499468162
262.2000000000031,32.85411302314398,0.0003757066414808996,-0.02512924296546526
263.60000000000315,32.98766978103015,-0.0030488692653378724,-0.027989510498850123
265.0000000000032,33.12009779723084,-0.002010709192777238,-0.028320020059322992
266.4000000000032,33.25425065367293,-0.0035001096968301226,-0.02818959039279445
267.80000000000325,33.386754870547016,-0.0027747007095304532,-0.026980925755943908
269.20000000000323,33.52026713363936,-0.0047843356695729256,-0.027990653607457006
270.60000000000326,33.65409333160009,-0.005071460848297127,-0.028981134421165677
272.0000000000033,33.787062703805496,-0.00611828217439192,-0.028979951999978937
273.4000000000033,33.92149137372722,-0.004853968183397894,-0.02897995732976444
274.8000000000033,34.05465616539079,-0.004030185189336732,-0.02770043462517524
276.20000000000334,34.187502222510254,-0.008227433054940336,-0.026670084189386323
277.6000000000034,34.320912053803504,-0.007108815143602509,-0.02535061086235224
279.0000000000034,34.45556088883839,-0.009657467494199379,-0.027561173185803867
280.4000000000034,34.58689858176906,-0.006347110461760508,-0.028319811588745303
281.8000000000034,34.722238488481686,-0.006543332832829263,-0.026956991942205022
283.20000000000346,34.85636699588136,-0.009888136656664326,-0.026674131295775894
284.60000000000343,34.98981303198074,-0.007858569802233983,-0.026670152364208555
286.00000000000347,35.124504297246865,-0.00745833444959354,-0.026999768242953692
287.4000000000035,35.25842608738487,-0.0076736523368021725,-0.02835878296901928
288.80000000000354,35.39251876874548,-0.007166064534815719,-0.029640063425080854
290.20000000000357,35.525764144861554,-0.005990959072168733,-0.02831908097783309
291.60000000000355,35.65946692798921,-0.00750798942371067,-0.029348754849852554
293.0000000000036,35.793212423038824,-0.010843030387007735,-0.026669761710521378
294.4000000000036,35.927670221172434,-0.012132985108775918,-0.02798982805675365
295.8000000000036,36.06179229281442,-0.010254363587965054,-0.028019981549643802
297.2000000000036,36.19582092083523,-0.011046084765136799,-0.027329959696981376
298.60000000000366,36.329721958824514,-0.01047442467632509,-0.02834253005453835
300.0000000000037,36.46395156014749,-0.014145573190489813,-0.02863752573470979
301.40000000000373,36.597744825299316,-0.013373828137305921,-0.028305063210637194
302.8000000000037,36.732417346187624,-0.01343546597736145,-0.028319816001369347
304.20000000000374,36.8646768078639,-0.012389180806603228,-0.028319820866107293
305.6000000000038,37.00071214426611,-0.011538644270454812,-0.02939860180619025
307.00000000000375,37.13524403752341,-0.011056755917715488,-0.028320567403905095
308.4000000000038,37.27048150600301,-0.01153155895545721,-0.028650352333104756
309.8000000000038,37.40518420731048,-0.01648764466218311,-0.028641021976191006
311.20000000000385,37.539696081208334,-0.014497676412820848,-0.02831818750691273
312.6000000000039,37.674664895332214,-0.016220616544642574,-0.028320083276178742
314.00000000000387,37.80954255725397,-0.015872424381887296,-0.027000034465235245
315.4000000000039,37.943140694053916,-0.016972545206806577,-0.02837124740799446
316.80000000000393,38.07846413344589,-0.02122166481797505,-0.02765460978934975
318.2000000000039,38.21209337590515,-0.02216457117494941,-0.027783604417679797
319.60000000000394,38.347375438194554,-0.024656600763521608,-0.028290206059139678
321.000000000004,38.48227098851628,-0.02424325253861559,-0.030620124055854347
322.400000000004,38.61612692436965,-0.02186077886851745,-0.029627188856991005
323.80000000000405,38.75121620101122,-0.026428107326463834,-0.029310019946803045
325.200000000004,38.883500189218594,-0.02847210634913,-0.02931001958457813
326.60000000000406,39.02087361673108,-0.026147324489810275,-0.030299069018946412
328.0000000000041,39.15450686668268,-0.02537400657188127,-0.028590698943383508
329.40000000000407,39.289098409300976,-0.02638025873556593,-0.027989815445626398
330.8000000000041,39.42490891629848,-0.028910006605789018,-0.02734331389561362
332.20000000000414,39.5597947219357,-0.029217322166062543,-0.02865051337693103
333.6000000000042,39.69510529825833,-0.030890000671675244,-0.03126483096641941
335.0000000000042,39.8292463938323,-0.030262888116262987,-0.029850051330063465
336.4000000000042,39.965070392916175,-0.02707793691954219,-0.029850124129655597
337.8000000000042,40.098818731330084,-0.029706873949513657,-0.030508215098849156
339.20000000000425,40.23469155142733,-0.030913560325607214,-0.02985772892682892
340.60000000000423,40.369828078325725,-0.031579388136157904,-0.029850123999991318
342.00000000000426,40.50487131603895,-0.031221365181290928,-0.029850123999998424
343.4000000000043,40.64059838688429,-0.03276376836496264,-0.02985008565846403
344.80000000000433,40.775856550431456,-0.03373273055491399,-0.03049693303073653
346.20000000000437,40.909593364093276,-0.034188241715397805,-0.02863621681741524
347.60000000000434,41.04706847617345,-0.035304195240616565,-0.02667596721944321
349.0000000000044,41.1815065610864,-0.038595086408786505,-0.027415125506053073
350.4000000000044,41.31754798299268,-0.04124574859935537,-0.029300088866088814
351.8000000000044,41.45174370216119,-0.039191832026684637,-0.030936460896891838
353.2000000000044,41.58845875203405,-0.043751133148631105,-0.030930840694043837
354.60000000000446,41.723984572383,-0.043741625034907194,-0.03194012147042269
356.0000000000045,41.8598824564294,-0.04666709687902437,-0.029961846555195848
357.4000000000045,41.99518409526882,-0.04637726746023629,-0.029959893142420313
358.8000000000045,42.13189717022662,-0.0460112223121083,-0.02929986179714472
360.20000000000454,42.26706101389511,-0.04616773491846082,-0.029299855999998847
361.60000000000457,42.402561852990154,-0.047530795269603354,-0.02929985600000684
363.00000000000455,42.539156552799454,-0.04968051387345063,-0.029299689643536908
364.4000000000046,42.675022812242915,-0.051566617888553434,-0.030620127137910735
365.8000000000046,42.81075625886315,-0.05554464623056732,-0.029066196893552387
367.20000000000465,42.94732585362619,-0.05578555340733837,-0.03193943739309013
368.6000000000047,43.08236308693931,-0.05777992310710278,-0.03202919191849318
370.00000000000466,43.218238218402504,-0.05921943692408482,-0.027884337212518595
371.4000000000047,43.35519875462083,-0.06023163949640331,-0.029284603338104453
372.80000000000473,43.490091165036624,-0.060962858939148434,-0.028199048426306383
374.2000000000047,43.62652218244672,-0.06446166617662907,-0.030949956516781008
375.60000000000474,43.76280543335183,-0.0637564574257159,-0.03094999600405579
377.0000000000048,43.89906532551648,-0.06610106218760059,-0.030366418407131057
378.4000000000048,44.03557575109056,-0.0663101729247415,-0.029268433886239897
379.80000000000484,44.17082550391268,-0.06780410464861797,-0.028012789036553798
381.2000000000048,44.30772098556705,-0.06908367436430707,-0.029300058688320085
382.60000000000485,44.443644639274,-0.06958170508737416,-0.027990079497755893
384.0000000000049,44.57924824852911,-0.07088070290453041,-0.02931000649316129
385.40000000000487,44.716269637562675,-0.07290636547067719,-0.030290169901544317
386.8000000000049,44.851031216676965,-0.07616113416118142,-0.031609847345734465
388.20000000000493,44.988521695708464,-0.07461647479885425,-0.029345418790772904
389.60000000000497,45.12493926325536,-0.07879480101010006,-0.028001621430260748
391.000000000005,45.26120074783073,-0.07872142476807897,-0.02957073954377254
392.400000000005,45.39778976087869,-0.07960523741016745,-0.028979859981400402
393.800000000005,45.53543687248119,-0.0795382962857678,-0.027652704332284728
395.20000000000505,45.67122346112397,-0.07999511922499414,-0.027659860028205863
396.600000000005,45.80793059053672,-0.07779391226013188,-0.02644874858615598
398.00000000000506,45.94478165747674,-0.08341602372728207,-0.0263516381083031
399.4000000000051,46.081029669511956,-0.08291245159702654,-0.028650591264773873
400.8000000000051,46.217667190895185,-0.08096630349371603,-0.028643776765910012
402.20000000000516,46.354423165120494,-0.08071011454293076,-0.028649861128513088
403.60000000000514,46.49324089049571,-0.08031539145925404,-0.030001432714320764
405.0000000000052,46.63043152178399,-0.07676138332732818,-0.027659265489431206
406.4000000000052,46.768166614062636,-0.07368265215797987,-0.028588285152316928
407.8000000000052,46.905239637579704,-0.07147037138808754,-0.02909015623662281
409.2000000000052,47.04188495953452,-0.06968972045729749,-0.028101505277793315
410.60000000000525,47.18039892403655,-0.07034927533209157,-0.029079951768379075
412.0000000000053,47.31667753298957,-0.07061628667496489,-0.026437415079520576
413.4000000000053,47.4534396756097,-0.0704603086451785,-0.029079768988435006
414.8000000000053,47.591320466045254,-0.07202245961486087,-0.030203138079060388
416.20000000000533,47.728066817240155,-0.08115658022732619,-0.030728540619191946
417.60000000000537,47.86234039109253,-0.08339110792942073,-0.029078438127175588
419.00000000000534,48.00040974665742,-0.09014632273466727,-0.029079991998168353
420.4000000000054,48.13893790153504,-0.0909054450739335,-0.029045169878286536
421.8000000000054,48.2762251984591,-0.09234302548872453,-0.02942263875020501
423.20000000000545,48.41298496509223,-0.09338340463409112,-0.028093266544593654
424.6000000000055,48.55009728537578,-0.0982253441077281,-0.029085772361432838
426.00000000000546,48.68743099805428,-0.09753437274958188,-0.029090150764770506
427.4000000000055,48.82373525355085,-0.10284349827567252,-0.027770313105285105
428.8000000000055,48.96111771691999,-0.10102788425641118,-0.030455766144737773
430.2000000000055,49.09785058109982,-0.10170918354797309,-0.029089456361821142
431.60000000000554,49.236632965751305,-0.10323022906217627,-0.029084972884864335
433.00000000000557,49.37591818532728,-0.1039079612661189,-0.030167228429116122
434.4000000000056,49.51326101377793,-0.10458420550749303,-0.02875975031587963
435.80000000000564,49.65088427666176,-0.10499207512766362,-0.027445979892579686
437.2000000000056,49.788602454554194,-0.11035557458068124,-0.02876013187857751
438.60000000000565,49.92663007106078,-0.11120370805636193,-0.030067732480906884
440.0000000000057,50.065002637929446,-0.11277254727480956,-0.03011143736088684
441.40000000000566,50.202299932814775,-0.11179310734133896,-0.02785289217728959
442.8000000000057,50.33968740244422,-0.11614409700350325,-0.0300701064981741
444.20000000000573,50.47815363334285,-0.11603338708074151,-0.028749781078079018
445.60000000000576,50.615011627199486,-0.11537842597145742,-0.027515901482654037
447.0000000000058,50.754085907502734,-0.11912760849388615,-0.02776863422400666
448.4000000000058,50.89118889535001,-0.12121795122091616,-0.027759832045627597
449.8000000000058,51.02928331324872,-0.12265203063523544,-0.028419086362757362
451.20000000000584,51.16749292371074,-0.12141695539536013,-0.02908114513954274
452.6000000000058,51.3038172187094,-0.12546754619140144,-0.02908010400289296
454.00000000000585,51.4431112887308,-0.12278740281165468,-0.02781330502961854
455.4000000000059,51.58135538020215,-0.1245549265869097,-0.029083321344337776
456.8000000000059,51.719090897311986,-0.12687934551359836,-0.029080044476617495
458.20000000000596,51.85696992653478,-0.12828949079206087,-0.028420109431738005
459.60000000000593,51.995111098950055,-0.12875118019977427,-0.028388378945144233
461.00000000000597,52.1324903899456,-0.13129066579454918,-0.028018170067619863
462.400000000006,52.270874030950246,-0.1320830649778244,-0.02845449818429291
463.800000000006,52.41000092278202,-0.1308669714742161,-0.03105421717254142
465.200000000006,52.54787616717141,-0.13231025785674566,-0.03138708430230164
466.60000000000605,52.6865354904524,-0.13261450599809832,-0.030079840045243778
468.0000000000061,52.823604370482975,-0.13249181944918687,-0.03007984014477927
469.4000000000061,52.96310288501935,-0.13340128325128986,-0.028761970515923885
470.8000000000061,53.10261954255972,-0.136784795063565,-0.02842908292066859
472.2000000000061,53.240793119128334,-0.13709107023775946,-0.02843290801940146
473.60000000000616,53.38008820649328,-0.13837608612488883,-0.029740041154705743
475.00000000000614,53.51839372963452,-0.13816011339411838,-0.028420021702902254
476.4000000000062,53.6574076329873,-0.1384703408764829,-0.029739102063378375
477.8000000000062,53.79510737440306,-0.13774410611492516,-0.03128247756314462
479.20000000000624,53.934051100924776,-0.14133618765334277,-0.03127934114627973
480.6000000000063,54.07350434389703,-0.14037707441871605,-0.02899850496513423
482.00000000000625,54.21351121284996,-0.13936661652815774,-0.03072802154336607
483.4000000000063,54.352091280886405,-0.1397664304778048,-0.03203636142596977
484.8000000000063,54.492141734288154,-0.14039958020009435,-0.03041749351334655
486.2000000000063,54.63111691165491,-0.1444208269834799,-0.03173178366641416
487.60000000000633,54.769061164730644,-0.14563768233863383,-0.0304204771264045
489.00000000000637,54.907840763494306,-0.14470527237140307,-0.030399228060765893
490.4000000000064,55.04600853936606,-0.14384489153860258,-0.029077312380583642
491.80000000000643,55.186251725568454,-0.1466296409035941,-0.031376519359186616
493.2000000000064,55.32359520838512,-0.14513698106280226,-0.03140013554600074
494.60000000000645,55.46399186484388,-0.14692373668943004,-0.030276903390282328
496.0000000000065,55.60259202392908,-0.1476403784102105,-0.03260985497257618
497.40000000000646,55.74324562228303,-0.15031705046158828,-0.03238000816307629
498.8000000000065,55.88140609651163,-0.1482089941454816,-0.03237997946782123
500.2000000000065,56.02083122762333,-0.15211629232900847,-0.03097918420503465
501.60000000000656,56.15980381082522,-0.15350168036662848,-0.03369987244115524
503.0000000000066,56.29951202329371,-0.1558357977905851,-0.03370025203623772
504.40000000000657,56.438446576702944,-0.1583648012570722,-0.03238019603556008
505.8000000000066,56.576936303521336,-0.1597372448866532,-0.032380195999999195
507.20000000000664,56.71624388261317,-0.16012515978059927,-0.03238014906349562
508.6000000000066,56.85552402078635,-0.16466452637183737,-0.030398930171805283
510.00000000000665,56.99462145031051,-0.1642572275389904,-0.031810861183706685
511.4000000000067,57.134761672048384,-0.16802373705438534,-0.034459711370128154
512.8000000000068,57.27432217239037,-0.1678643705783247,-0.03577770145470094
514.2000000000068,57.414254343291994,-0.17284698825152423,-0.03445985474305502
515.6000000000067,57.55301052532886,-0.1723745977348674,-0.035781062747391346
517.0000000000068,57.693015650398316,-0.17189921253052032,-0.03577962124777567
518.4000000000068,57.832222394860594,-0.1773888013344307,-0.0344532876501793
519.8000000000068,57.97100082250949,-0.17650449424665582,-0.03578066854094697
521.2000000000069,58.111801601924505,-0.17443080601390126,-0.034460041822837795
522.6000000000068,58.25037644078829,-0.1748410100880744,-0.03577983240091154
524.0000000000068,58.390202053442124,-0.180464916648708,-0.03578005441334842
525.4000000000069,58.529613014812625,-0.17927504262939076,-0.03644006303359859
526.8000000000069,58.66981404540647,-0.18204435106007977,-0.037734236699838775
528.2000000000069,58.809685302392026,-0.17754237040422627,-0.03643981511043748
529.600000000007,58.94867854912816,-0.1786511451447219,-0.038745321423139245
531.0000000000069,59.08848315970757,-0.18067074895477253,-0.037430095690496934
532.4000000000069,59.22827374821038,-0.18213823250496808,-0.03875003858719328
533.800000000007,59.368668991188734,-0.1832857148347531,-0.0388361657485774
535.2000000000071,59.508215772488846,-0.1806614705309526,-0.037868099522830434
536.6000000000071,59.64582723212414,-0.18289552743938442,-0.037865408830018765
538.000000000007,59.78806907271308,-0.1844701163500435,-0.03918983989289071
539.4000000000071,59.92743456415205,-0.18422370288224,-0.04055086304199085
540.8000000000071,60.067993578693844,-0.1845035639309449,-0.04049848935375078
542.2000000000071,60.208388177586166,-0.1822232622579436,-0.042148763233358366
543.6000000000072,60.347326953123336,-0.18461807798938445,-0.04214981742069224
545.0000000000072,60.48822382391543,-0.18817671555094195,-0.04349543249612964
546.4000000000071,60.62760733216447,-0.18827903512163657,-0.04248772855438032
547.8000000000072,60.76822782892006,-0.18975966370610764,-0.04380029623248616
549.2000000000072,60.90710228856858,-0.19308203654939793,-0.04248002798947459
550.6000000000072,61.04821501427729,-0.19217075054578414,-0.042465968948630195
552.0000000000073,61.188253258732544,-0.19129259257208875,-0.04378992398765069
553.4000000000073,61.328385544254296,-0.19089720867080295,-0.043789481435843935
554.8000000000073,61.46806212459285,-0.19284968142931858,-0.045024835422755594
556.2000000000073,61.608346788882606,-0.19579986663164206,-0.04642179878420061
557.6000000000073,61.75008438961035,-0.19550288034494234,-0.04873010389732979
559.0000000000074,61.88896450434352,-0.20189624687359142,-0.04872619270199463
560.4000000000074,62.02919101802502,-0.1979281055345674,-0.04775010389592982
561.8000000000075,62.16966199601411,-0.19908664268002219,-0.04871135536633986
563.2000000000074,62.30999903021371,-0.19882505130931438,-0.04906998500676174
564.6000000000074,62.4503178171562,-0.20144152637443669,-0.04905576975971071
566.0000000000075,62.590818744338236,-0.20161559201635204,-0.04775000643390204
567.4000000000075,62.73159155252074,-0.20301834139283548,-0.04776224319177258
568.8000000000075,62.87193552137105,-0.201006914709285,-0.05051286242673081
570.2000000000075,63.01184880367226,-0.19754982397221155,-0.051665949178339776
571.6000000000075,63.15266058775517,-0.19696589008066456,-0.05580265122102146
573.0000000000075,63.29456668020573,-0.19316045298569295,-0.05442205190987304
574.4000000000076,63.433688466467025,-0.1903401678798946,-0.05707881216640365
575.8000000000076,63.574495480533926,-0.19603297417578158,-0.054440568348720575
577.2000000000077,63.71478399332666,-0.20042641675157524,-0.0553367047588198
578.6000000000076,63.854453306286466,-0.20555018824929583,-0.056429369180246436
580.0000000000076,63.996599744035755,-0.20732902550715115,-0.05905684326509508
581.4000000000077,64.13738238383607,-0.21151330141160196,-0.057720945157040404
582.8000000000077,64.27671614228107,-0.21145926024205375,-0.05906239356512444
584.2000000000078,64.41878213070954,-0.2071410198452861,-0.0577267399004322
585.6000000000078,64.55855628324905,-0.21253240532220952,-0.05928030858660849
587.0000000000077,64.69890230925553,-0.20779360195822494,-0.060380208433802984
588.4000000000078,64.84238819765517,-0.2130248453406811,-0.060933141855194606
589.8000000000078,64.98152962093265,-0.215945947138676,-0.06071023671822129
591.2000000000078,65.12397459512708,-0.21532080838406342,-0.06273862936092733
592.6000000000079,65.26417584286484,-0.2221472681423362,-0.06336370066686614
594.0000000000078,65.40552019175767,-0.2225295254601376,-0.06506203106096464
595.4000000000078,65.54637538780737,-0.22222446196446866,-0.0656326781235852
596.8000000000079,65.68660687664439,-0.22465300297253843,-0.06640223376695431
598.2000000000079,65.82734023138657,-0.23146616612106552,-0.06729838393397758
599.600000000008,65.96617055979938,-0.23105660455537724,-0.06879260601148074
601.000000000008,66.10875596880904,-0.23475265548248347,-0.06980772544338842
602.4000000000079,66.25043663012276,-0.23797412391217554,-0.06848970613468719
603.800000000008,66.39050840388691,-0.24143853740652887,-0.0698487260369065
605.200000000008,66.53202254523121,-0.23953654776470934,-0.07219242667410786
606.6000000000081,66.67254417849787,-0.23778986028948634,-0.07480736517187925
608.0000000000081,66.81401078457067,-0.24331057158037894,-0.0761801319987514
609.400000000008,66.95495429257052,-0.24086333711108754,-0.0761801320476505
610.8000000000081,67.09521763003677,-0.23994714116695182,-0.07749694440032551
612.2000000000081,67.23688502095258,-0.23778888995398906,-0.07684070098512485
613.6000000000081,67.37704153402022,-0.23917733645926598,-0.07934072494536615
615.0000000000082,67.51812988532859,-0.2398839130405408,-0.0808001172270516
616.4000000000082,67.65859670334753,-0.23204735675279498,-0.08144954524547154
617.8000000000081,67.8006070064147,-0.23048815056484928,-0.0850749336455312
619.2000000000082,67.94088788686787,-0.23009976559046708,-0.08508235719958046
620.6000000000082,68.08230800209493,-0.22630227198543684,-0.08640545525800869
622.0000000000083,68.2238558097834,-0.2242446504596347,-0.08902756912954812
623.4000000000083,68.36417567812038,-0.21916616986384074,-0.09007759616970201
624.8000000000083,68.5058037941732,-0.21393059227872468,-0.09180409284503188
626.2000000000083,68.64706689216435,-0.20629885607876108,-0.09268868381218365
627.6000000000083,68.78911788792253,-0.20036913645798426,-0.09393342387643377
629.0000000000084,68.93010624924554,-0.19365366925581018,-0.09524760091509865
630.4000000000084,69.07201842788079,-0.18826937542313837,-0.09738848464183114
631.8000000000084,69.21378850638246,-0.17956515939161255,-0.09824521202534298
633.2000000000085,69.3551298399534,-0.17344753156561543,-0.10198031920646633
634.6000000000084,69.4976251408385,-0.16350556390451265,-0.10465719722789402
636.0000000000084,69.6385568358971,-0.155234496943915,-0.10787052285717058
637.4000000000085,69.78089376250885,-0.1418548105857349,-0.10989037031242521
638.8000000000085,69.92250935248929,-0.13448588432194386,-0.11132235788997447
640.2000000000085,70.06491485278586,-0.12163946917095192,-0.11535590537144547
641.6000000000085,70.20594932967302,-0.112434670534316,-0.11794152576883876
643.0000000000085,70.3485836846471,-0.09543932003900757,-0.12056701058718344
644.4000000000086,70.49178071000176,-0.08524249641648973,-0.12330256801029549
645.8000000000086,70.63449349750329,-0.07040900535381134,-0.1274684496961367
647.2000000000086,70.77714662892959,-0.05947515276445481,-0.13288662302285337
648.6000000000087,70.91859561875556,-0.03999690577596349,-0.13546093334126486
650.0000000000086,71.06212468742052,-0.022565133034555096,-0.14051202625330417
651.4000000000087,71.20480967846865,-0.004762024303503143,-0.14490957375000368
652.8000000000087,71.34642512926476,0.011600420165547298,-0.14789446547647467
654.2000000000087,71.48778562654881,0.02863173693956167,-0.1525074468783183
655.6000000000088,71.63066410161971,0.04906504198209127,-0.15666347666487024
657.0000000000088,71.7726530045154,0.06517908984824494,-0.16272005588381422
658.4000000000087,71.91482529737834,0.07857341493681735,-0.16883053438891826
659.8000000000088,72.05702191444286,0.10109174117041864,-0.1742945292517648
661.2000000000088,72.19894431161637,0.12446244005858631,-0.18095734811090436
662.6000000000088,72.34147284327919,0.1501727405400377,-0.18979656033291636
664.0000000000089,72.48348766070677,0.17203936554810406,-0.19617350118017418
665.4000000000088,72.62593658050409,0.19929072193834507,-0.20113912546560808
666.8000000000089,72.768357212934,0.23099805704345933,-0.20661196359268574
668.2000000000089,72.90989355756443,0.259522052735798,-0.21429526386463582
669.6000000000089,73.05262163129356,0.287160403739962,-0.2209847001631835
671.000000000009,73.19542366222821,0.31675048346421253,-0.22863666746170752
672.400000000009,73.33821243109566,0.34943883709809853,-0.23919645392399858
673.800000000009,73.48000110434093,0.37829173659993387,-0.2478799697594094
675.200000000009,73.62153596539329,0.410472653032778,-0.255526323380765
676.600000000009,73.7673053824031,0.4399973244283437,-0.2650972870950734
678.0000000000091,73.90895418002626,0.47408524559718623,-0.2740833179650153
679.4000000000091,74.05358134800905,0.5099977888997245,-0.28297508294319673
680.800000000009,74.19637204572034,0.5413713812714191,-0.2950694982683215
682.2000000000091,74.33999907710177,0.5764818888710512,-0.3058499039885221
683.6000000000091,74.48408505327318,0.6173415398138666,-0.3187095109078846
685.0000000000091,74.62540083371623,0.6524608909697096,-0.3273117533690977
686.4000000000092,74.77110926246073,0.6893492237817154,-0.3409489720029675
687.8000000000092,74.91419162165913,0.7302874184192936,-0.354681674605934
689.2000000000093,75.05803071990948,0.7656086142143224,-0.3677826895116403
690.6000000000092,75.20102181744022,0.8106019907393254,-0.38005248576316886
692.0000000000092,75.34525947993383,0.8527973008319707,-0.39259843886663326
693.4000000000093,75.48841086114811,0.8963076345330223,-0.4059398101597118
694.8000000000093,75.63262857311315,0.9336247687800956,-0.4231112126026795
696.2000000000094,75.77548157009633,0.9722894067701597,-0.4407579037598013
697.6000000000093,75.9195780457515,1.0154301581310903,-0.4516037651611713
699.0000000000093,76.06340384772797,1.0548185743549472,-0.4699615152350005
700.4000000000094,76.20732000244202,1.09597731243813,-0.4859952512528096
701.8000000000094,76.35058451683813,1.1394262531618664,-0.5043237564087044
703.2000000000094,76.49386262648083,1.1820726228274943,-0.5200451290758705
704.6000000000095,76.63659147577695,1.2194716680847666,-0.538809487798964
706.0000000000094,76.7795426397811,1.263548465970564,-0.5577459400209936
707.4000000000094,76.92309871910977,1.299614020355055,-0.5768653980192244
708.8000000000095,77.0665997891941,1.3388850109606816,-0.5949126566176495
710.2000000000095,77.20990180425838,1.379820439711918,-0.6144474693811484
711.6000000000096,77.35420471134705,1.4199051542796792,-0.6358062652920631
713.0000000000095,77.4966126452496,1.4636434597674288,-0.657255388328998
714.4000000000095,77.63877652669768,1.5044666863873446,-0.676794506202465
715.8000000000096,77.78318542251141,1.5481397134839896,-0.7019598790413397
717.2000000000096,77.92703661940504,1.585861836079276,-0.7231383481002722
718.6000000000097,78.0694679182811,1.6219394371066134,-0.7439866357009217
720.0000000000097,78.21378559322362,1.661313467428363,-0.7674020364341199
721.4000000000096,78.35700907867077,1.6967285563480616,-0.7906973360858882
722.8000000000097,78.50111034614368,1.7321651606308746,-0.8142807028038526
724.2000000000097,78.64497339724268,1.76888223341818,-0.8409869434860262
725.6000000000097,78.78871153874164,1.8044911832209336,-0.8637613580856502
727.0000000000098,78.93336676694823,1.8361623710782493,-0.889112906840293
728.4000000000098,79.07667244263355,1.8688718453849207,-0.9138170704406536
729.8000000000097,79.22101727718079,1.9055174904570467,-0.9405715823109158
731.2000000000098,79.36323407167444,1.9400730291803545,-0.966417875372406
732.6000000000098,79.50753035447363,1.9801965389691798,-0.9939543130874684
734.0000000000099,79.6511590894138,2.022321240883693,-1.0224788097717417
735.4000000000099,79.7952233437166,2.0783325047593983,-1.0492936250417486
736.8000000000098,79.93936214762002,2.1441068416271003,-1.0762722347618814
738.2000000000099,80.08432357179034,2.2209190765866023,-1.1031018053544748
739.6000000000099,80.22919858959531,2.303843556352227,-1.133641172944822
741.00000000001,80.37258239364668,2.384311816665912,-1.1629535487681246
742.40000000001,80.51771866661224,2.4548705546564786,-1.194409076838403
743.80000000001,80.66021051241219,2.5013147201875423,-1.2236949710229292
745.20000000001,80.80609607494944,2.5095048022151207,-1.2560838609200555
746.60000000001,80.9477573671531,2.4628475233198324,-1.288334840904036
748.00000000001,81.08690837710952,2.3321990476436536,-1.3163521998210022
749.4000000000101,81.22391271154805,2.1062100820297642,-1.342103996151034
750.8000000000101,81.35768302973375,1.7569685677190274,-1.3666252007744064
752.20000000001,81.48799023912005,1.2383002116522221,-1.3875541273955467
753.6000000000101,81.61252865199648,0.5363506164092686,-1.3985395056171979
755.0000000000101,81.74041021614055,-0.02554148062551498,-1.407314788751345
756.4000000000102,81.87535889633828,-0.3385436246381439,-1.4110349119760772
757.8000000000102,82.01298638195092,-0.4945393280478081,-1.412997360504043
759.2000000000102,82.1524345375577,-0.5678221144745077,-1.4143299248906138
760.6000000000103,82.29426596989119,-0.6063085269107598,-1.4157508491769737
762.0000000000102,82.43630114578282,-0.6262592901863573,-1.4143404473256962
763.4000000000103,82.57966753493272,-0.6318878874638063,-1.415318735104686
764.8000000000103,82.72257909605003,-0.63709331047618,-1.416629903446594
766.2000000000103,82.86503546872275,-0.6368695233408896,-1.4166898711635514
767.6000000000104,83.00897839733867,-0.6533450087368613,-1.4166399932574478
769.0000000000103,83.15107713049143,-0.6569593417984914,-1.4156498721312243
770.4000000000103,83.29345665619215,-0.6564354411982607,-1.4155326297693365
771.8000000000104,83.43715048772034,-0.6577097252040032,-1.4130403712659416
773.2000000000104,83.5792680069409,-0.6576462653319886,-1.4157586589487723
774.6000000000104,83.7235072752821,-0.658518831620492,-1.4157352003580272
776.0000000000105,83.86678163696865,-0.662363178953274,-1.4183069349767594
777.4000000000104,84.00929944237473,-0.6561967100660269,-1.4190501740123622
778.8000000000105,84.15184600426551,-0.659599951343564,-1.4162024101148338
780.2000000000105,84.29574108146365,-0.6625311041481017,-1.4173008562299056
781.6000000000105,84.43943469115256,-0.667108679533079,-1.4194941950328608
783.0000000000106,84.58264728844317,-0.6668303648781007,-1.419474090874552
784.4000000000106,84.72524331062202,-0.6728321518348519,-1.4181822389591958
785.8000000000106,84.86951239621415,-0.6728557839485898,-1.4194901266250803
787.2000000000106,85.01186595664845,-0.6747548677899662,-1.4181801298070655
788.6000000000106,85.15503793661196,-0.6768192543605918,-1.4185338122408337
790.0000000000107,85.30010305798797,-0.6828196676085767,-1.418510330574302
791.4000000000107,85.44276744553298,-0.6822618556767694,-1.4162167477265073
792.8000000000106,85.58488281030355,-0.681869597941744,-1.4161807133907969
794.2000000000107,85.72745735308476,-0.681317790013118,-1.4175813109041626
795.6000000000107,85.87152803674998,-0.6891709039668106,-1.416640730984298
797.0000000000107,86.01496941062723,-0.6915515628062727,-1.417614908195107
798.4000000000108,86.15795010015917,-0.691965520009834,-1.416309903260303
799.8000000000108,86.30101315692197,-0.6905471467417388,-1.4163098519974548
801.2000000000108,86.44472065369483,-0.6952027745853271,-1.4177125861035775
802.6000000000108,86.5883098848142,-0.6954602653085962,-1.4167579158793027
804.0000000000108,86.73105005391982,-0.7004302075585889,-1.416192474600955
805.4000000000109,86.87468879372794,-0.7024991461312751,-1.4171918078198873
806.8000000000109,87.01759291850159,-0.7062261062438435,-1.4175079460993945
808.200000000011,87.16071422825767,-0.7082870251492137,-1.4149338145672048
809.6000000000109,87.30443494328188,-0.707782831152771,-1.4151769811433321
811.0000000000109,87.44766607033348,-0.7037400120190487,-1.416332735150812
812.400000000011,87.58936553300114,-0.6996141270473428,-1.4162596460477483
813.800000000011,87.73262937480509,-0.7030224525738391,-1.4141125075449574
815.200000000011,87.8777155267656,-0.7079237538188745,-1.4149889999292462
816.600000000011,88.02104311621267,-0.7164321197795278,-1.4156501401279984
818.000000000011,88.16436825637679,-0.7130934110060649,-1.4169596678616685
819.400000000011,88.30693304299476,-0.7246334906651279,-1.41698538659345
820.8000000000111,88.45058958367774,-0.7173366701727488,-1.4182801854505764
822.2000000000111,88.59079450834999,-0.7249907024464903,-1.4176299479478645
823.6000000000112,88.7356836148821,-0.7295077286539793,-1.4163041055637295
825.0000000000111,88.87823788920934,-0.7324045954793985,-1.4139996737474876
826.4000000000111,89.02263000750803,-0.7306254101561347,-1.4150078449378838
827.8000000000112,89.16664338932698,-0.7322110480571786,-1.4166316449028233
829.2000000000112,89.3103805173547,-0.7355431938290664,-1.4166483967478847
830.6000000000113,89.45660098076301,-0.7359785925329292,-1.4146272500290427
832.0000000000113,89.59950066912498,-0.7411265133765013,-1.4159799605677463
833.4000000000112,89.74394948437666,-0.734723487106975,-1.4139998070885178
834.8000000000113,89.88797859673826,-0.735558713869783,-1.4167470651890341
836.2000000000113,90.03166725840562,-0.7379186217657994,-1.414120082387373
837.6000000000113,90.174767263408,-0.7394488588641752,-1.4140434751867086
839.0000000000114,90.31766703348407,-0.7434252338085949,-1.4167489815309224
840.4000000000113,90.46273957831038,-0.7502384889182827,-1.416750159234871
841.8000000000113,90.60508550938644,-0.7556330872651968,-1.4182842533909636
843.2000000000114,90.74831593630154,-0.7521856724997322,-1.416835248503249
844.6000000000114,90.89051093960549,-0.756987293047394,-1.4140582393888526
846.0000000000115,91.034997982333,-0.7565961969522501,-1.4156499360991588
847.4000000000115,91.17824143391972,-0.756167632651791,-1.4169699482184996
848.8000000000114,91.3204915745387,-0.7626016602164705,-1.416982536120523
850.2000000000115,91.46415684491768,-0.7668120522055046,-1.4170780802008998
851.6000000000115,91.60676289449003,-0.7661829126221402,-1.4182785435745555
853.0000000000116,91.75128140783873,-0.7650814069454253,-1.4182798468533
854.4000000000116,91.89359418256352,-0.7724041362755045,-1.415985406179895
855.8000000000116,92.03794912961689,-0.7716480617059047,-1.417557773889821
857.2000000000116,92.18286187930698,-0.7751772314653391,-1.4148900144829866
858.6000000000116,92.32718279939141,-0.7733109199666583,-1.4171803480511675
860.0000000000116,92.4708270625293,-0.7756465722195798,-1.415871435737623
861.4000000000117,92.61546906314364,-0.782195352897189,-1.4131908425129978
862.8000000000117,92.75842732870935,-0.785381916573455,-1.415888545253401
864.2000000000116,92.90420686178787,-0.7857827220520095,-1.4161999684095599
865.6000000000117,93.04715285835097,-0.7908524187563404,-1.4157568836859586
867.0000000000117,93.19171226902806,-0.7916486023919669,-1.4157891238756366
868.4000000000118,93.3352075974018,-0.8030640359386454,-1.4144400720703874
869.8000000000118,93.47818212697528,-0.804395876886693,-1.4157598849565085
871.2000000000118,93.62225113803935,-0.8105774951510836,-1.4159629581601596
872.6000000000118,93.76561693009494,-0.8095815755055709,-1.4168294811177993
874.0000000000118,93.90825534614265,-0.8142612751689802,-1.4146599302037441
875.4000000000119,94.05241190532347,-0.8170406297677024,-1.4174785286348577
876.8000000000119,94.19585259332821,-0.8217076838189019,-1.4155744102936936
878.2000000000119,94.3389012701039,-0.8185447104245149,-1.4138966902377188
879.600000000012,94.48260269434849,-0.8304177671991919,-1.4134759786664985
881.0000000000119,94.62574203231767,-0.8349466803103542,-1.4191768634296378
882.4000000000119,94.76760581073879,-0.8317480954308363,-1.4165301016977514
883.800000000012,94.91357233334413,-0.8334888323274416,-1.4165300960001068
885.200000000012,95.05804966764788,-0.8365048108568893,-1.4165452400320007
886.600000000012,95.20146150076324,-0.8480494537618641,-1.416526424280609
888.000000000012,95.34540424036729,-0.8488313852979794,-1.416200083495096
889.400000000012,95.48946154246438,-0.8592040319093126,-1.4144742325849844
890.8000000000121,95.63327912353179,-0.8740438676838793,-1.4152458679521516
892.2000000000121,95.77801779214231,-0.8782401981911305,-1.4151000237911364
893.6000000000121,95.91980440007889,-0.8808546336233403,-1.4125716031172995
894.0000000000122,95.96080134721396,-0.8800716867884386,-1.4125700212869106