File: 01_Data/Concrete_Block/STA/N2/10K_min/Concrete_Block_STA_N2_10KData_220914_R3.csv
##Temp./Â°C,Time/min,DSC/(mW/mg),Mass loss/mg
51.0,10.830300065048432,0.037794716217053326,0.03287853858938039
52.100000000000016,11.169861813472586,0.05528911248574109,0.0314458685190413
53.20000000000003,11.41627585271011,0.071493920435995,0.03113959952753209
54.30000000000005,11.616622376269465,0.0863082342415542,0.030546929571697135
55.40000000000006,11.801028928749282,0.09369500827830413,0.03191802277939537
56.50000000000008,11.972248682966383,0.10152703671562069,0.031377945207371916
57.600000000000094,12.132794170299515,0.11075772933886685,0.029787665773246985
58.70000000000011,12.286512677060934,0.11553885105390349,0.029135261327853712
59.800000000000125,12.434475840809984,0.1212462790240898,0.03083177331917053
60.90000000000014,12.581070056356706,0.12665641914853354,0.02936096818018097
62.000000000000156,12.725194120502012,0.13187303168518416,0.030389047813232928
63.10000000000017,12.863883774703218,0.13484506335329227,0.03168918305165924
64.20000000000019,13.001587798511931,0.1372346200414558,0.03183050458726555
65.30000000000021,13.136490826789021,0.14151441076087723,0.03177968270074594
66.40000000000022,13.269419911986803,0.14712409659682502,0.03068284241230934
67.50000000000023,13.399409606755786,0.1502292919132573,0.030391782094541853
68.60000000000025,13.53045309790045,0.15277693670060555,0.028183288049594246
69.70000000000027,13.659728516082582,0.1555726689944179,0.02993222119029504
70.80000000000028,13.785720879090015,0.16231770019007463,0.0313224102832379
71.90000000000029,13.911628457147449,0.1656017391700797,0.03010578694374111
73.00000000000031,14.034425296619718,0.16670551900475195,0.030810453535436544
74.10000000000034,14.158306598408293,0.17070624016510993,0.030430335329759473
75.20000000000034,14.279585884839413,0.17294037759807024,0.02895910307604055
76.30000000000035,14.401844941063427,0.17751773991848552,0.02911624545161917
77.40000000000038,14.524419771577753,0.17933208265633915,0.029384176145869745
78.5000000000004,14.642351747503927,0.18094936217555824,0.02898557927524603
79.6000000000004,14.76112637956687,0.18479533856506924,0.029074136998305633
80.70000000000041,14.879495134885726,0.18632250180486454,0.02891021517872705
81.80000000000044,14.997344054132405,0.1868414856833851,0.028995127633374196
82.90000000000046,15.113682056648132,0.19013237311181497,0.029103504888564835
84.00000000000047,15.22988209313868,0.19023525052648282,0.028996866470969884
85.10000000000048,15.345996349787473,0.19291415559015745,0.029822025556160092
86.2000000000005,15.461260367226556,0.19649702709947325,0.03041001261368148
87.30000000000052,15.57542758875282,0.19812340458928956,0.0293734285998708
88.40000000000053,15.690283341787417,0.19931966617530283,0.029100906710333163
89.50000000000054,15.799452641356524,0.20033059209098303,0.02974216740838287
90.60000000000056,15.915134345863942,0.20220618778390853,0.029133545382119763
91.70000000000059,16.028371560773245,0.20402357518607706,0.027774357702769592
92.8000000000006,16.13931375617628,0.20571846363614665,0.030417498404765375
93.9000000000006,16.250942651973073,0.20696914551779477,0.029842526444114448
95.00000000000063,16.362025961988333,0.20866913543115062,0.02909869191731662
96.10000000000065,16.47263643459443,0.211717574857341,0.027757998305524723
97.20000000000066,16.582204463954177,0.21192888770159823,0.029105632588311003
98.30000000000067,16.690250089040923,0.21391725040770948,0.026943065483843398
99.40000000000069,16.80290661360596,0.2162151193336337,0.02773957314767639
100.50000000000071,16.91125267799233,0.21628158435249245,0.026974145335504573
101.60000000000072,17.019788522810916,0.21853755456859592,0.026471227756674764
102.70000000000073,17.12799722661085,0.21932700750422296,0.026462699232131293
103.80000000000075,17.234914137489305,0.22218193941310438,0.027785792280101695
104.90000000000077,17.346127888640208,0.22270341450318543,0.026459263983047876
106.00000000000078,17.45453685405522,0.22385642376272796,0.025140873151898724
107.10000000000079,17.562714634378054,0.22553689490767337,0.025111891954153975
108.20000000000081,17.671727092817513,0.22828170626182487,0.023821931632403093
109.30000000000084,17.780309283461083,0.22669461403738245,0.02514042213952994
110.40000000000084,17.88647565133433,0.2276275513168886,0.02545932267683515
111.50000000000085,17.99478187523809,0.2308192110930033,0.025266644801482663
112.60000000000088,18.101675682274134,0.22903428364003098,0.02382825865146021
113.7000000000009,18.209339864601294,0.22905480517189436,0.024238045587844148
114.8000000000009,18.317141900957157,0.2298145121130336,0.022505087112033806
115.90000000000092,18.420441365240478,0.22889308111907758,0.023810959790521835
117.00000000000094,18.531845216192384,0.22998157902549787,0.026572161333221267
118.10000000000096,18.63806140501912,0.229063086502433,0.023908949805963253
119.20000000000097,18.74575176855398,0.22825393735634192,0.02394105890620235
120.30000000000098,18.85316106341705,0.2281160953329321,0.025269310874734607
121.400000000001,18.959500129023468,0.2286308419850709,0.02524982887156213
122.50000000000102,19.066537492717657,0.22932650677274757,0.024133540339676074
123.60000000000103,19.173390084525664,0.2290936969471482,0.023929865604179312
124.70000000000104,19.28000000000012,0.2290984309109606,0.022619171131782245
125.80000000000106,19.386669395977005,0.2279930925068243,0.02259314145785485
126.90000000000109,19.493977242236962,0.22695464258681042,0.02342535179191163
128.00000000000108,19.599278656709348,0.2290898513054922,0.022889114926764265
129.1000000000011,19.705649201235538,0.22876512160271634,0.022620023892684138
130.20000000000113,19.81274627775664,0.22791948034949805,0.022619914998601054
131.30000000000115,19.91696076590684,0.22813351813789906,0.022619959932694833
132.40000000000117,20.023284367180597,0.22765279265308958,0.021309918626379876
133.50000000000117,20.128976748962003,0.22728689452369455,0.02130991383940728
134.6000000000012,20.235658100686084,0.22763836737573395,0.022632701841842184
135.7000000000012,20.34260481626538,0.22793208090654804,0.024744637601602726
136.8000000000012,20.446042716517926,0.22848866538430357,0.02230634793838515
137.90000000000123,20.553828851598368,0.22830112425416793,0.022620064672070228
139.00000000000125,20.658873514747857,0.22799528153612958,0.022485176039889865
140.10000000000127,20.76379997351242,0.22926345966776707,0.021419039237716042
141.2000000000013,20.868937397267153,0.22911315056838688,0.021310312389242192
142.3000000000013,20.974312998822423,0.23069315118272027,0.02195888329428808
143.4000000000013,21.078948252516923,0.23024197764096443,0.020661656811256535
144.50000000000134,21.184038671000184,0.23041958651991234,0.021299943073388228
145.60000000000133,21.28878352283539,0.2287366835803406,0.021325238254331857
146.70000000000135,21.39337998600144,0.23155551048296452,0.021286470016519843
147.80000000000138,21.49932499201222,0.2291399798132957,0.020307159175064093
148.9000000000014,21.604092281585977,0.229137598320582,0.02130014539463776
150.00000000000142,21.7085488563752,0.23178505537057525,0.021300470533911486
151.10000000000142,21.81231517684625,0.23093747955016874,0.021299020139732505
152.20000000000144,21.918935045981048,0.2305328112126811,0.019980008893122125
153.30000000000146,22.019575355382504,0.23287118119824823,0.01997991500384
154.40000000000146,22.126910947474354,0.23004582306152987,0.019979470448289405
155.50000000000148,22.231950595929607,0.23019827237498858,0.020309740894248307
156.6000000000015,22.336947679411704,0.23051383814772775,0.021302801476009492
157.70000000000152,22.44065735675125,0.23059801899744536,0.02005018328136199
158.80000000000155,22.54424859866859,0.23123248746457392,0.019989634259777844
159.90000000000154,22.64886092826611,0.22793258362323277,0.0199738637281488
161.00000000000156,22.754170412325873,0.22996591259180765,0.021312900335060725
162.1000000000016,22.860088000494475,0.22989420742149558,0.01998918273364314
163.20000000000158,22.965107032976942,0.23162416412709186,0.019978067166964486
164.3000000000016,23.06940670177545,0.23246179901218222,0.019980179974084855
165.40000000000163,23.173933083080463,0.23230307633852665,0.020065163329300972
166.50000000000165,23.279102728934777,0.2326415690066046,0.01956738637898514
167.60000000000167,23.38298744458022,0.23233045392383578,0.021165352953746108
168.70000000000167,23.488084905648638,0.23262864982800113,0.01998996795753971
169.8000000000017,23.592985755334098,0.23287830405536236,0.021262322847105608
170.9000000000017,23.69786530564294,0.2331029669110697,0.021959865273581514
172.0000000000017,23.802181287282444,0.23315345622548878,0.02197151186632329
173.10000000000173,23.906127934829115,0.23336812150491915,0.020652164075852575
174.20000000000175,24.01032758927876,0.23428631021516522,0.020639981453646428
175.30000000000177,24.115480122008893,0.23199501440402837,0.020484780643242217
176.4000000000018,24.221582777764233,0.23353570916421224,0.02070729776245095
177.5000000000018,24.322434129328816,0.23238358928993869,0.01932018563687876
178.6000000000018,24.429187875477517,0.23543466398165153,0.018009896548148774
179.70000000000184,24.533866817887155,0.2347724133763449,0.019379144468807397
180.80000000000183,24.637403333488216,0.23484197317727812,0.017995222055085414
181.90000000000185,24.743794240113136,0.23512984993136316,0.019329832838515415
183.00000000000188,24.84750072987346,0.23500656219425037,0.02012638902961683
184.1000000000019,24.952652768107928,0.234983695854507,0.019147689607477147
185.20000000000192,25.056794914833525,0.23694841867344874,0.019000054972998726
186.30000000000192,25.161542174536653,0.23633506591700348,0.019000054736001637
187.40000000000194,25.266090538188376,0.2361213471414545,0.019363780282150245
188.50000000000196,25.369804094700935,0.23696010194935507,0.01855738511482663
189.60000000000196,25.47603812434668,0.2363822105765619,0.019099719973854512
190.70000000000198,25.57931861831846,0.23810381825693722,0.019106532092260764
191.800000000002,25.68235027708119,0.23665163549016033,0.019124125897913125
192.90000000000202,25.7875600642026,0.23740800179847393,0.019090033424026487
194.00000000000205,25.89223127773866,0.23659273072869952,0.020425199892732948
195.10000000000204,25.995024427329916,0.23779679324474123,0.02173924797076765
196.20000000000206,26.099326676372883,0.23938110478842844,0.021740123302887326
197.3000000000021,26.20401042475855,0.2391674977108213,0.020431022462227055
198.40000000000208,26.30882090735176,0.23677868198437768,0.017765654537450715
199.5000000000021,26.41332932038436,0.2391504929113223,0.017789456389762925
200.60000000000213,26.517150552169376,0.23985263937851814,0.018461380075477152
201.70000000000215,26.620503259233267,0.24139021882071093,0.018066915370973824
202.80000000000217,26.725187411358494,0.23981160546879465,0.017790035518853387
203.90000000000217,26.828465206866042,0.23860672365038832,0.017786275445092592
205.0000000000022,26.93135540725448,0.23792890629037894,0.017789436748451237
206.1000000000022,27.037987967357438,0.2398340748269976,0.01647229175823295
207.2000000000022,27.14370880613798,0.23893017192408217,0.019110062208204326
208.30000000000223,27.24808394121671,0.24015373947126417,0.01715141160544409
209.40000000000225,27.352378776331594,0.24249229673473427,0.01679975010413326
210.50000000000227,27.45560409816777,0.24279980912185722,0.017779568204225882
211.6000000000023,27.561858589833932,0.243799336513931,0.016800118167114242
212.7000000000023,27.665025152733506,0.24313842107551142,0.01811420365864702
213.8000000000023,27.769906883721376,0.24357537408001517,0.017608573636671565
214.90000000000234,27.875207213777323,0.24452418812286425,0.018451460340991765
216.00000000000233,27.977074309476627,0.24283996543645542,0.017130102164755634
217.10000000000235,28.08330621286718,0.2434800736828207,0.017130104908596344
218.20000000000238,28.187690381269494,0.24495669154443767,0.017049886734226583
219.3000000000024,28.292604933018936,0.24431386978914732,0.016799514073574606
220.40000000000242,28.39689194241935,0.24323096671450506,0.018121278697289078
221.50000000000242,28.50124714023981,0.24462573835852003,0.016799872794152293
222.60000000000244,28.603200575931073,0.24535642759284199,0.016800102924931615
223.70000000000246,28.710378643005686,0.2442171343473401,0.015494195367760533
224.80000000000246,28.815114370052616,0.24455678567817973,0.016673061048011917
225.90000000000248,28.91896747060136,0.24466047074490394,0.01679999348006156
227.0000000000025,29.02174353823325,0.2419819552233996,0.016808361379172077
228.10000000000252,29.127137361688025,0.24285111738146287,0.01811989442745343
229.20000000000255,29.233199102695387,0.2413676662118634,0.017147199751659237
230.30000000000254,29.33812052228839,0.2421094249859227,0.01580986706620635
231.40000000000256,29.442241457643373,0.2427132784833399,0.016773765171969934
232.5000000000026,29.547150717585204,0.2421876974911797,0.016794102127165367
233.60000000000258,29.65173422478568,0.24357456700459384,0.01581988549254376
234.7000000000026,29.75625075485129,0.2431609798063753,0.015818683279878343
235.80000000000263,29.860399078745136,0.2452794629819196,0.015489899300572318
236.90000000000265,29.96474179000828,0.24450626393157465,0.01449934098071104
238.00000000000267,30.06981371566024,0.2434565811086028,0.015149797866103931
239.10000000000267,30.17385171055667,0.2452458974426368,0.015164934095252214
240.2000000000027,30.278265808219665,0.24402314193877,0.015810067904572733
241.3000000000027,30.382940104188084,0.24526038224465357,0.015810064219500042
242.4000000000027,30.488189642501574,0.2445656015536946,0.017065823157463633
243.50000000000273,30.592457107526435,0.24540226196247328,0.018107658871155508
244.60000000000275,30.69672701912023,0.24487044980125827,0.01679982890585041
245.70000000000277,30.801241923394233,0.2457288663413037,0.01679985683074392
246.8000000000028,30.906406745801995,0.24482972646334633,0.015819867150422162
247.9000000000028,31.010430162129587,0.24616655523051878,0.015809855144118146
249.0000000000028,31.112220027770068,0.24475893616481093,0.01679674417318555
250.10000000000284,31.219688261740302,0.2471551138579282,0.01418224617416275
251.20000000000283,31.323668523535595,0.2453920629193116,0.014169862087752172
252.30000000000285,31.42829222116371,0.24584412813869883,0.015492323266294683
253.40000000000288,31.53297840532823,0.24554295330486237,0.015490154997110928
254.5000000000029,31.637656040383586,0.24356682279460773,0.01549015500000106
255.60000000000292,31.74305916318462,0.24428374700718353,0.015490147958686862
256.7000000000029,31.847803177036656,0.24510178746755473,0.01646707644707135
257.8000000000029,31.952712610967016,0.2434336449231474,0.015161155210056343
258.90000000000293,32.05693679839906,0.2447486194284661,0.015467376945912825
260.00000000000296,32.1612968907235,0.2437782921950612,0.0154799226368878
261.100000000003,32.26651045897924,0.24450912212075632,0.014813231511521252
262.200000000003,32.37095868330544,0.24430352009421807,0.014164615710802408
263.300000000003,32.475150847239405,0.245042011822856,0.015397111696612953
264.40000000000305,32.58046315485032,0.24414120445245585,0.014159818409559044
265.50000000000307,32.684461659075254,0.244916810525158,0.015470913592505298
266.6000000000031,32.78898671742262,0.24430686637904514,0.016800241461701226
267.7000000000031,32.89206130868055,0.24358490061519306,0.015476759938020557
268.8000000000031,32.99765749975776,0.24404587329808491,0.015141767119811966
269.9000000000031,33.10298246673511,0.2442598517716565,0.01548382209952237
271.0000000000031,33.20788277382789,0.24348102214745443,0.014819879954869997
272.10000000000315,33.312372710925516,0.24586295401891106,0.013507670566437646
273.2000000000032,33.41707649080793,0.2443211589497986,0.016144013671083535
274.30000000000314,33.52134718606291,0.24530057231363195,0.01484615186548055
275.40000000000316,33.627315951220645,0.24489830366377036,0.013510110533622388
276.5000000000032,33.731502508545965,0.245773957857218,0.013510337477881329
277.6000000000032,33.836430423309544,0.2471099023250961,0.013649754236125133
278.70000000000323,33.941609446039415,0.24582738360011586,0.013179820108720541
279.80000000000325,34.04525847450904,0.24620377874932153,0.01318040472984272
280.9000000000033,34.150000910126685,0.24551943421332306,0.011859808947317418
282.0000000000033,34.25589788779244,0.2472243648673373,0.014217278093760832
283.1000000000033,34.359998989010755,0.24608951174247568,0.014635961683321597
284.20000000000334,34.46621053790045,0.24647569531119373,0.014169865960723449
285.30000000000337,34.57137285488393,0.24606033886449885,0.012850199035702836
286.40000000000333,34.675558343621084,0.24590318367578345,0.012850120015547084
287.50000000000335,34.780000000000314,0.2464072581518667,0.013180195000027872
288.6000000000034,34.88569797017949,0.24456360258505944,0.01417001436544929
289.7000000000034,34.99113186978081,0.2470080021575854,0.014163925387165932
290.8000000000034,35.09596290662658,0.24609581420864107,0.013747412001282378
291.9000000000034,35.201030005726004,0.24619400868280034,0.012824147840820643
293.0000000000034,35.30633674469502,0.2464959146507434,0.013831064785315483
294.10000000000343,35.41019297817233,0.24537593592096651,0.013830471432707547
295.20000000000346,35.51624771862447,0.24697139212413838,0.011539777121358341
296.3000000000035,35.62147015900927,0.2472928131021705,0.012106353280427307
297.4000000000035,35.726884077434825,0.248562685684324,0.012850014707433743
298.5000000000035,35.83312209441879,0.24788627160243243,0.012866403468807519
299.60000000000355,35.93726731937831,0.24832937399409802,0.012843053966729912
300.70000000000357,36.042518450516674,0.24663129027538142,0.011432104046127378
301.8000000000036,36.14789314217253,0.24563657533510433,0.01152975502025555
302.9000000000036,36.252646592981705,0.24668193850455647,0.012850202190263005
304.0000000000036,36.35880636378973,0.2475070122717239,0.012850190000000872
305.1000000000036,36.46444594364729,0.2474364053563312,0.012850143548178927
306.2000000000036,36.569271222086805,0.2497526564374913,0.012520565241876724
307.30000000000365,36.674493145002984,0.24820566340181305,0.011530215627426621
308.4000000000037,36.77916149195179,0.24950966254798804,0.01153016440085608
309.5000000000037,36.88482555588903,0.2506585425496394,0.011531838122871285
310.60000000000366,36.989999087916985,0.24807935467430475,0.010209901788787334
311.7000000000037,37.095944133250775,0.2506121386221378,0.012848641277389383
312.8000000000037,37.20213581929469,0.250619356228984,0.012976485026857887
313.90000000000373,37.30721604334453,0.25159542387969835,0.012850894067442553
315.00000000000375,37.41199854647726,0.2520845166221418,0.012850085001718803
316.1000000000038,37.51784117372038,0.25207528347162317,0.012849664569714925
317.2000000000038,37.62297440880076,0.25320480715239824,0.01351010923861029
318.3000000000038,37.729265255367025,0.2542477794636644,0.011782439504201214
319.40000000000384,37.8348838157927,0.25319599901916184,0.011859929901356203
320.5000000000038,37.93914342493686,0.2526332183102459,0.0108707836303914
321.60000000000383,38.04590219163172,0.25355938418917046,0.01219007962558738
322.70000000000385,38.15059131743514,0.2531525958366906,0.011451324584568212
323.8000000000039,38.25664386449972,0.25333602953999496,0.011992208048669184
324.9000000000039,38.36298327051038,0.25315478461550145,0.012520979966851975
326.0000000000039,38.46847176440543,0.2550259158861369,0.01256549730630141
327.10000000000394,38.57346060527234,0.25308821375531615,0.011859889681439917
328.2000000000039,38.679746553055445,0.25244152763343114,0.013180156786976482
329.30000000000393,38.785402395788594,0.25542176536158495,0.01318015244149251
330.40000000000396,38.89120168792083,0.2538759569684892,0.012520714036181602
331.500000000004,38.99776172035692,0.2557135625435698,0.012519980000896602
332.600000000004,39.10313170615553,0.25670101660040845,0.012519978140440813
333.700000000004,39.209895493398925,0.256449703100076,0.011353594364317487
334.80000000000405,39.31516553467108,0.2569693513753124,0.01020842764988572
335.90000000000407,39.42125156024176,0.2567343644772522,0.011529811407427815
337.0000000000041,39.52742673649766,0.2585643870837753,0.010203053173498233
338.10000000000406,39.63277294097541,0.25834073352355885,0.011533118274585696
339.2000000000041,39.739647097557636,0.25771211964459007,0.010999555667669192
340.3000000000041,39.84550782739617,0.2603934643643014,0.010209830393220543
341.4000000000041,39.95000105867543,0.2587716452444996,0.010209829999760167
342.50000000000415,40.057209058240026,0.25877868010640925,0.01021008106956689
343.6000000000042,40.162474049607866,0.25873221611830366,0.01218989173560292
344.7000000000042,40.268752769255535,0.25978402640909526,0.010869673301835192
345.80000000000416,40.375420686304416,0.25980739170487654,0.012189978914810773
346.9000000000042,40.480522183156864,0.26042928906559915,0.01089580756545594
348.0000000000042,40.58833528072604,0.2609736269427553,0.010869980004667212
349.10000000000423,40.69368466984395,0.25892766640818987,0.010869980176715366
350.20000000000425,40.799825456134485,0.2579184205602906,0.010722891907600562
351.3000000000043,40.90571566665456,0.25842021556110606,0.009559954246422642
352.4000000000043,41.01282731110946,0.2597534272203109,0.01087018902719894
353.5000000000043,41.118774316701995,0.25770994210564013,0.0108699800000851
354.60000000000434,41.22645566401219,0.2593283302676246,0.010869980012360614
355.7000000000043,41.330669349667055,0.25934922216971246,0.01084660736523091
356.80000000000433,41.43773883466296,0.25884612679204566,0.010219810489203063
357.90000000000435,41.54301707771564,0.26009266351159294,0.009957476629545603
359.0000000000044,41.64956607152477,0.26352553340308704,0.008580379716995878
360.1000000000044,41.756838011491716,0.26233352443602076,0.009559897147558338
361.2000000000044,41.863325127926615,0.26309349231550194,0.010871899552597597
362.30000000000445,41.96961178926837,0.26047360507467354,0.009559965906705159
363.4000000000044,42.07605256832726,0.263005092582861,0.009560678092472408
364.50000000000443,42.18237122290627,0.26386584910815486,0.009890042704394197
365.60000000000446,42.285848259042325,0.2636562871686666,0.012507911530163618
366.7000000000045,42.39537238716937,0.26233057916102487,0.012519949978100797
367.8000000000045,42.5003690241888,0.26184763667669164,0.012156736091963438
368.9000000000045,42.60730497865896,0.2615878848789386,0.009889515273654226
370.00000000000455,42.71464314325502,0.2604094518453374,0.01119837555678771
371.10000000000457,42.82055476753208,0.2612213980214244,0.009890156990482346
372.2000000000046,42.928080655776355,0.25990302525665776,0.011225681449767322
373.30000000000456,43.03459811340094,0.25699546427043635,0.011439522046053696
374.4000000000046,43.13958945129154,0.2582340223259695,0.00995403478877499
375.5000000000046,43.24783324184912,0.2575126426768807,0.009890054979183382
376.6000000000046,43.35493051206244,0.2585738515960171,0.009890055000008502
377.70000000000465,43.462091546782126,0.258674703585483,0.009890047702684868
378.8000000000047,43.56787898772671,0.25826693778448473,0.008567268169435316
379.9000000000047,43.675350240347534,0.2576957787267814,0.008569985041902761
381.00000000000466,43.78222338540582,0.25640649201558285,0.008899516610551217
382.1000000000047,43.88825088709828,0.26045204651476095,0.009891009454659816
383.2000000000047,43.993757985107734,0.25701269391573545,0.011186778190290347
384.30000000000473,44.102055546424026,0.2571247267297052,0.008570132336624958
385.40000000000475,44.20718099173856,0.2570562335333395,0.007594765253975844
386.5000000000048,44.31506262401313,0.25344916248988314,0.00759228067003459
387.6000000000048,44.42188974010662,0.2554349525688885,0.007579838477859369
388.7000000000048,44.52823509404641,0.25590162243507353,0.008900354493582618
389.80000000000484,44.635208079728685,0.2576849562950891,0.008618662620330397
390.9000000000048,44.74295195203719,0.25556231934972906,0.007909182149806071
392.00000000000483,44.84980407787486,0.2553714896187049,0.007242137451077824
393.10000000000485,44.95598654439621,0.25805388853429967,0.007909913259910972
394.2000000000049,45.06248110543056,0.25579862702368245,0.009221546909665257
395.3000000000049,45.16936697560712,0.2558016796923721,0.008239855441355637
396.4000000000049,45.276170004573125,0.254658015574202,0.007916726332392265
397.50000000000495,45.383361478600186,0.2565548662744538,0.007921121566885958
398.6000000000049,45.49053320530381,0.2583942564175236,0.008227028376587953
399.70000000000493,45.59746550814963,0.25624930101461485,0.007913994868283147
400.80000000000496,45.70521143234903,0.2590033340245286,0.007929800943823118
401.900000000005,45.81323950317817,0.2592194434773224,0.008237836615192506
403.000000000005,45.92069579281912,0.2609546421936409,0.008238194081890526
404.100000000005,46.0262849086909,0.264901087281171,0.006919088356079683
405.20000000000505,46.1347273372802,0.26828394136110156,0.005921687146835275
406.30000000000507,46.24182577597758,0.2724381496672121,0.00494721804582543
407.4000000000051,46.34947423502854,0.27817850808048905,0.006259858790722106
408.50000000000506,46.45576719365531,0.27804059577031437,0.0064703366598504175
409.6000000000051,46.5638617836607,0.2796232803483998,0.006270089489530228
410.7000000000051,46.66940187108514,0.27909260138477004,0.007237143792141687
411.8000000000051,46.77744123173017,0.2772479461378918,0.00790932658496235
412.90000000000515,46.88518365739069,0.2743474616527111,0.0052958832093947805
414.0000000000052,46.990617616617115,0.26807328129213376,0.005280014989528681
415.1000000000052,47.10018956741096,0.2628327727217598,0.005280015840829044
416.20000000000516,47.20655538554685,0.25846951468416146,0.003961363548369512
417.3000000000052,47.31357659012142,0.25773785210225564,0.003960069313182046
418.4000000000052,47.42182275506277,0.25277035399732434,0.0013323237668156906
419.50000000000523,47.52959762951179,0.25031032011839804,0.004027662798562481
420.60000000000525,47.63436656349038,0.2526099100351275,0.004364323474013609
421.7000000000053,47.74378414884017,0.24934054806437828,0.003296562726337271
422.8000000000053,47.8504826635657,0.24939952157624617,0.0046198883066868035
423.9000000000053,47.95859069890182,0.25064308837286253,0.004619865056375794
425.00000000000534,48.06374185442832,0.24952278451934176,0.0045033831459733165
426.1000000000053,48.17307740165231,0.24997770551698012,0.004644336049822506
427.20000000000533,48.280273680543885,0.24877893889441627,0.00395669331058901
428.30000000000535,48.38699819213953,0.24949970039038444,0.003961730434774324
429.4000000000054,48.49378925215982,0.24923298909781605,0.005204992073701398
430.5000000000054,48.60150940038036,0.24768671469338538,0.005279844745731843
431.6000000000054,48.70914189452546,0.2495965040815689,0.0042899562743805575
432.70000000000545,48.816648617701375,0.25079570591730455,0.004279194586826129
433.8000000000054,48.92462181243329,0.25010379011209416,0.00395988661326907
434.90000000000543,49.03216819738278,0.2502118478272911,0.0026407047286696184
436.00000000000546,49.139371479567714,0.24760227622044712,0.0030664680583551984
437.1000000000055,49.24776482729887,0.24872881297712252,0.002639872746903471
438.2000000000055,49.35562551704858,0.25223280205286114,0.003330464345202344
439.3000000000055,49.46000118326414,0.2498572027540357,0.004619997497220751
440.40000000000555,49.56963122222089,0.25049212681870137,0.0032967907483429926
441.50000000000557,49.676742694410876,0.24925525990696623,0.0036200712872656027
442.6000000000056,49.78505043967295,0.25079852473017117,0.002314314155835717
443.70000000000556,49.89307699687949,0.25180001609397124,0.0036312412012717843
444.8000000000056,50.000512276687445,0.25296905097783706,0.002310006420392696
445.9000000000056,50.10911555293359,0.2531313303267092,0.0023236873161369687
447.0000000000056,50.215442245661954,0.2541110033919246,0.0045766741763726415
448.10000000000565,50.322878641624094,0.2531824663484027,0.003300142508050996
449.2000000000057,50.43036326862365,0.2531159815150044,0.003300366453774295
450.3000000000057,50.538196475566174,0.2513292296970619,0.0019802339987284867
451.40000000000566,50.645865294406725,0.25186731416998226,0.001987594227909284
452.5000000000057,50.75354512514106,0.2540069796280124,0.0032982580011866602
453.6000000000057,50.86171816761804,0.2537395513367797,0.001921997307795742
454.70000000000573,50.96934012900138,0.2541103680765142,0.0006696507503010096
455.80000000000575,51.07748273861223,0.25546186178415076,0.001989924614949068
456.9000000000058,51.185369712447624,0.2541833854236897,0.0019899000000274114
458.0000000000058,51.29358097124091,0.25597539832085886,0.001989927206655473
459.1000000000058,51.40147784991159,0.25299571464131476,0.001331557865388966
460.20000000000584,51.50950744553574,0.25477943822187765,0.00132505750298062
461.3000000000058,51.616020530061014,0.2555427097079603,-0.000650016463319858
462.40000000000583,51.72546191529591,0.2561577471059855,0.002031561227679113
463.50000000000585,51.83239070270952,0.25721225242856893,0.0019898999748679813
464.6000000000059,51.94029052173688,0.2566695887222877,0.0019899000297227687
465.7000000000059,52.04891196061719,0.2587739746835867,0.0013503004445087896
466.8000000000059,52.156549412750635,0.2581577836967877,0.0006699777721488331
467.90000000000595,52.2641775079355,0.2593528383731741,-0.0006477848453094737
469.0000000000059,52.371695739103146,0.2604713860959565,0.000623560850643301
470.10000000000593,52.47959194682431,0.2605758585688208,0.0006545807541140647
471.20000000000596,52.588290412048565,0.26249160001597066,-0.0006601834352100155
472.300000000006,52.695280503272905,0.2655882147298056,0.0009770618101976325
473.400000000006,52.80484006549581,0.26604565905238253,0.0013202390024718014
474.500000000006,52.912829864194286,0.26410532439408435,0.0013199494446709537
475.60000000000605,53.02089837142056,0.2659359670856797,1.0728373212032238e-07
476.70000000000607,53.128857788601984,0.26760670530093367,-1.0384258670725899e-06
477.8000000000061,53.236906321865334,0.2667835531679895,-0.0009902137886044216
478.90000000000606,53.344948189344414,0.2687631960711908,-0.0009901691178200167
480.0000000000061,53.452639250520036,0.26934748842383194,0.0003300078481149882
481.1000000000061,53.561948236869235,0.2690251641037512,-0.0013962880290474544
482.2000000000061,53.66980726134991,0.26932787501405175,-0.0013100350064254584
483.30000000000615,53.775413479875304,0.2694983152317418,-0.0013100096547029594
484.4000000000062,53.88620273153094,0.2683810695652144,-0.0026318254375459205
485.5000000000062,53.99439629263688,0.2668287322993619,-0.002630558270541705
486.60000000000616,54.103700711302345,0.2670232949023598,5.197763943698419e-06
487.7000000000062,54.2115810520422,0.26745791359658266,4.9461000048545145e-05
488.8000000000062,54.31865689869641,0.26529960136746317,-0.002577963345885337
489.90000000000623,54.42544651592424,0.2661184101547542,-0.002577022165418441
491.00000000000625,54.536584693370024,0.26596146864321907,-0.0013132134540461138
492.1000000000063,54.644971508567075,0.2640039407136795,-0.0003200880859557387
493.2000000000063,54.75403202257867,0.263911064527597,-0.0004794835685686394
494.3000000000063,54.861862736746104,0.26375532917798566,-0.0016400046698672455
495.40000000000634,54.97051829322322,0.2649455538483282,-0.001643519298553997
496.5000000000063,55.076885611735875,0.26398501049327444,-0.004280602136251588
497.60000000000633,55.18725665656207,0.2645169660418572,-0.004277360531951935
498.70000000000636,55.29579072700545,0.26468628701299235,-0.005920222855559487
499.8000000000064,55.40477491071017,0.26370810078100493,-0.00565604904776329
500.9000000000064,55.51216159072111,0.26579466870627,-0.0032900585922792658
502.0000000000064,55.62153773698635,0.2648000287452374,-0.0012971623964279644
503.10000000000645,55.731259463376546,0.2662924834350592,-0.003942700737620264
504.2000000000064,55.83999900000991,0.2655099875440136,-0.003950125009253291
505.30000000000643,55.94742981044052,0.265377954045452,-0.003950162024120907
506.40000000000646,56.05619096549169,0.26650280122874603,-0.0026438907748680407
507.5000000000065,56.164672707546785,0.27025281700473597,-0.003939985777300592
508.6000000000065,56.2728567668634,0.26968886466896025,-0.0046003963986276375
509.7000000000065,56.38164274992005,0.26914227283081615,-0.006253175997573024
510.80000000000655,56.4894721937486,0.2696451385483247,-0.007570091407185231
511.90000000000657,56.59861680181089,0.27132882395763047,-0.007515179688801332
513.0000000000066,56.70666354945728,0.2718868678289962,-0.007900090223396106
514.1000000000065,56.816220059285016,0.27364886787769355,-0.008294566504162937
515.2000000000066,56.924092012264985,0.27440910440197863,-0.0072428133027209185
516.3000000000065,57.03308364894657,0.2748891835512303,-0.005965216715513755
517.4000000000067,57.142325631149525,0.27407856321976415,-0.003837482311667806
518.5000000000066,57.24981255769754,0.27199076762061664,-0.005933346679842799
519.6000000000067,57.35784276499712,0.27439772060922485,-0.007234192988784471
520.7000000000066,57.467386764652076,0.2768446824642924,-0.007240010334156111
521.8000000000067,57.57589433367572,0.2772718368023268,-0.00847448142262408
522.9000000000067,57.68341291435838,0.27738530586662213,-0.008559359249057152
524.0000000000067,57.792607566904415,0.2786354996067347,-0.009308291689360537
525.1000000000067,57.90127203723657,0.27909872690005527,-0.009219799971773135
526.2000000000068,58.01029844294009,0.2808133314066099,-0.009219798444330074
527.3000000000068,58.11838159774307,0.27949924720072544,-0.01053936227832164
528.4000000000068,58.226957353560145,0.28093600507325694,-0.010540100000554276
529.5000000000068,58.33580360328155,0.2828746952106692,-0.010540100716642797
530.6000000000068,58.4447555675907,0.28364614900961854,-0.011277511448769317
531.7000000000069,58.55252242315919,0.2831827912771739,-0.011189906391932958
532.8000000000068,58.66221656665779,0.28632300501158303,-0.011850015682479231
533.9000000000069,58.77083629562269,0.28547462124450224,-0.01184987000446025
535.0000000000068,58.87951292884301,0.2879049583473129,-0.011853930631807508
536.100000000007,58.98809451890342,0.28680878780754904,-0.013168617914284475
537.2000000000069,59.09745608940697,0.28772129032396865,-0.011703179445198053
538.300000000007,59.20620772043146,0.2888543146480005,-0.011611712961372866
539.4000000000069,59.3139374015379,0.29161944200778317,-0.010538853092739053
540.5000000000069,59.42420658956564,0.2903317205209758,-0.012802300047937365
541.600000000007,59.53173547961578,0.2946855463345558,-0.014404249180514306
542.700000000007,59.6404788265811,0.2961348098461977,-0.015810878014342222
543.800000000007,59.74867527415894,0.2987975189150073,-0.01546258472534845
544.900000000007,59.85759028924493,0.29882730716704387,-0.015799816176063075
546.000000000007,59.96659959100642,0.2958327439593059,-0.015995458660637674
547.1000000000071,60.07568207846825,0.29911733310834077,-0.01579819427329099
548.2000000000071,60.18418710568266,0.3011878181461907,-0.014492731430406636
549.300000000007,60.292747835875616,0.29820753882275686,-0.014159986643244693
550.4000000000071,60.40114494982071,0.29835331062334236,-0.015467108580645927
551.500000000007,60.509907498031986,0.2995963735121551,-0.015026036017419031
552.6000000000072,60.61917125026803,0.2994700356451159,-0.01712847719703703
553.7000000000071,60.7272395984996,0.30090922295412803,-0.01755100632974127
554.8000000000072,60.83579753560525,0.30381875534259917,-0.019011887907320002
555.9000000000071,60.94419521250029,0.30489900786113566,-0.01976006088705784
557.0000000000072,61.05365191787411,0.30511137393759047,-0.019759889999936497
558.1000000000072,61.16253094096292,0.3065114620140308,-0.019759838068910796
559.2000000000072,61.27091425437591,0.30595997874557307,-0.021074323313015064
560.3000000000072,61.37910279255431,0.30650238393798285,-0.022400084429939682
561.4000000000073,61.48836997226558,0.3087361298101152,-0.023012635939959836
562.5000000000073,61.597624018012624,0.3099100060368026,-0.023709850915460073
563.6000000000073,61.705071289373244,0.31163195168377666,-0.023705847668129998
564.7000000000073,61.81390424078448,0.3128564492851548,-0.025986064504492923
565.8000000000073,61.922343025933245,0.31162563040043295,-0.02195779929104269
566.9000000000074,62.03095930903541,0.3109286984682366,-0.022059796551462618
568.0000000000074,62.141204070102354,0.31146807175067315,-0.02337887432799235
569.1000000000074,62.2495387420341,0.31283156359017894,-0.024700632625666685
570.2000000000073,62.35833553058813,0.3151626520579401,-0.027329691501741138
571.3000000000073,62.468277481897175,0.31976150798751884,-0.026009554166090965
572.4000000000074,62.57693293441989,0.3213135295520667,-0.02744978145273791
573.5000000000074,62.68627444183782,0.3301495679091362,-0.027330911636124
574.6000000000074,62.79472375822069,0.32035658117493665,-0.02665000551394403
575.7000000000074,62.903744971159476,0.31468767278445126,-0.027989568621990202
576.8000000000075,63.013722230424165,0.3118534375054134,-0.029374565605892577
577.9000000000075,63.12237657001425,0.3104066871522737,-0.029937385672556438
579.0000000000075,63.23083818641602,0.3076776907000201,-0.028640066883476756
580.1000000000075,63.34064561193486,0.3047631452294406,-0.028639452609990457
581.2000000000075,63.447793469689486,0.3039351958040261,-0.030519366218070054
582.3000000000076,63.55733882803241,0.3047041197710265,-0.029581971430109988
583.4000000000076,63.66825453369962,0.304111536520803,-0.029472475894581684
584.5000000000076,63.77650853800498,0.304408643790825,-0.03362583613844006
585.6000000000076,63.885968569178075,0.3031619635889178,-0.033589919983794125
586.7000000000077,63.99482146599028,0.3039280276674955,-0.03358278102585288
587.8000000000077,64.10444018230815,0.30425690054212895,-0.033518051772771784
588.9000000000076,64.21338023965356,0.3033775358432982,-0.03491019475251811
590.0000000000076,64.32297997300824,0.30389293865287914,-0.03621080756294148
591.1000000000076,64.4327935870394,0.3007406236134611,-0.037562062632654936
592.2000000000077,64.54198295174723,0.3000547932036896,-0.03819791475864598
593.3000000000077,64.64935909262135,0.2990757996212753,-0.038195930070132
594.4000000000077,64.76172644880074,0.3001055559406399,-0.03753995716279501
595.5000000000077,64.87009253342585,0.30201492803718755,-0.03885564864566238
596.6000000000078,64.97929619592537,0.3011714639674694,-0.041498989297137356
597.7000000000078,65.08581599931507,0.2995859590192064,-0.04152757083134784
598.8000000000078,65.19812283774644,0.30104150686814873,-0.040496000534367305
599.9000000000078,65.30807314839974,0.302124086787886,-0.042646561216855616
601.0000000000078,65.4172972965182,0.2989443516688216,-0.0441296182549058
602.1000000000079,65.52596421375992,0.30109465563121607,-0.04471163525668942
603.2000000000079,65.63505812189167,0.30043048927529653,-0.044131081353165236
604.3000000000079,65.74525576023454,0.3008294994794732,-0.0454401378692042
605.4000000000078,65.85396168713822,0.3024423633331706,-0.04667427760356002
606.5000000000078,65.96235798168178,0.3018537878154295,-0.046762063751288885
607.6000000000079,66.07169610098013,0.30081893163174295,-0.049398863455610176
608.7000000000079,66.18130423409862,0.3047283451595446,-0.04940076307266317
609.8000000000079,66.2892541259325,0.30160872009839,-0.05071117182259277
610.9000000000079,66.39999790664298,0.3027226981442135,-0.05202996611477673
612.000000000008,66.50947682398133,0.30559734220519447,-0.050711250622345716
613.100000000008,66.6192922874487,0.3050839983370813,-0.05335622909301074
614.200000000008,66.7255314180571,0.30681497505011984,-0.05335376537789038
615.300000000008,66.8374607613203,0.3077774129709442,-0.054660158044766316
616.400000000008,66.9463835669284,0.31272629441482613,-0.05600475635290936
617.5000000000081,67.05462009158961,0.31300693898048937,-0.057296800010260274
618.6000000000081,67.16543503599434,0.31286929390802026,-0.057299677603454224
619.7000000000081,67.27584549419674,0.31877180125517385,-0.060024728470795985
620.8000000000081,67.38418893862803,0.32167252057844054,-0.06091932523980592
621.9000000000082,67.49356109676131,0.3254391681181029,-0.0609140542618265
623.0000000000082,67.60387203994122,0.3319494994567569,-0.06224013934833339
624.1000000000081,67.71175173219012,0.33477352578480535,-0.062312702186920976
625.2000000000081,67.82194544813414,0.34123936936940913,-0.06356550849974152
626.3000000000081,67.93107409463586,0.3456395098543483,-0.06622028958942572
627.4000000000082,68.03890217795781,0.34991310155642924,-0.06751093883801129
628.5000000000082,68.15123377268873,0.3575541363072263,-0.06927420900562176
629.6000000000082,68.26073397510933,0.36513914755723104,-0.07015687031973306
630.7000000000082,68.37117463804076,0.3728352395855788,-0.07274570598327479
631.8000000000083,68.48079639691147,0.3781947603374441,-0.07278005985594005
632.9000000000083,68.58960467077307,0.3859451663585478,-0.07406334576209206
634.0000000000083,68.70000000000084,0.3892243365537115,-0.0760701199994358
635.1000000000083,68.80957526265065,0.3995264362803291,-0.07738835674076006
636.2000000000083,68.91980677309911,0.4061410435147058,-0.08002995670942248
637.3000000000084,69.02669274701233,0.4131281068563417,-0.08276500322915759
638.4000000000084,69.13849291760098,0.42026581292956333,-0.08364340381632829
639.5000000000084,69.24877941098305,0.43093740998936664,-0.08607010538344362
640.6000000000083,69.3572929673225,0.44016498352318534,-0.08887580836553832
641.7000000000083,69.46626347172213,0.4468223114979058,-0.09012183031687604
642.8000000000084,69.57861387474124,0.4566588105703566,-0.09335869215036086
643.9000000000084,69.6881345481798,0.4700786537524096,-0.09466705075277426
645.0000000000084,69.79832055900904,0.4794515418995465,-0.09861542506778243
646.1000000000084,69.90680294016266,0.4929776084646715,-0.1026497815473495
647.2000000000085,70.01731398397827,0.504921895949428,-0.10392789589959328
648.3000000000085,70.12694646675267,0.5147375801350824,-0.10710761985614115
649.4000000000085,70.23742953329415,0.5262580725975169,-0.11012700467685121
650.5000000000085,70.34570549554813,0.5399795443926932,-0.11409966777899916
651.6000000000085,70.45712390681526,0.5546775827335487,-0.11683931309490347
652.7000000000086,70.56720050618554,0.5677386325399916,-0.11811259796565077
653.8000000000086,70.6773962485391,0.5825779907562296,-0.12326762112463552
654.9000000000086,70.78705456942815,0.5960371163228773,-0.12526097617144716
656.0000000000086,70.89713261686119,0.6142407876586582,-0.12942026769166093
657.1000000000087,71.00680255968831,0.6281006911793188,-0.13182026776309463
658.2000000000087,71.11640472667376,0.6424112074678968,-0.1352923212280288
659.3000000000086,71.22741465479817,0.6607969362791126,-0.14057613957461035
660.4000000000086,71.33678217031691,0.6780270407152582,-0.1466254391809354
661.5000000000086,71.44694748679358,0.6984315286602986,-0.14955219918007057
662.6000000000087,71.55768296015104,0.7107489162326069,-0.1536648941598524
663.7000000000087,71.66759135005461,0.7323236904915094,-0.15844412349306447
664.8000000000087,71.77857139601278,0.7494617547238809,-0.16549243311287132
665.9000000000087,71.8880292842798,0.7652848951261171,-0.16572031883228
667.0000000000088,71.99716894521556,0.7844486064250585,-0.17181088539930256
668.1000000000088,72.10720112296309,0.8047759417831319,-0.17751766038714845
669.2000000000088,72.21859569982726,0.8272702780211098,-0.18035870873048276
670.3000000000088,72.32818826436669,0.8487265864293894,-0.1908477976696359
671.4000000000088,72.43912194989883,0.8676790578748306,-0.19773142943730715
672.5000000000089,72.54927342102454,0.8953982445460482,-0.2039339377827467
673.6000000000089,72.66000210707148,0.9188870946060941,-0.20912616351166546
674.7000000000089,72.77059097997113,0.9370922141675186,-0.21572692195955678
675.8000000000088,72.88187855984594,0.9568427247016842,-0.2222710507513641
676.9000000000088,72.99102850653894,0.985457652862923,-0.22824926669882117
678.0000000000089,73.10205053082927,1.0079902684539308,-0.23424207638717975
679.1000000000089,73.21214507696315,1.037757539449311,-0.24447622241201383
680.2000000000089,73.32230369576688,1.0641320942170927,-0.25147018912931696
681.3000000000089,73.43287973808681,1.0904143744135553,-0.25951370881975677
682.400000000009,73.54330507187674,1.1188409722591843,-0.2664383909652708
683.500000000009,73.65357743992935,1.147667652533878,-0.2738510875869484
684.600000000009,73.76346490783263,1.1725127786180984,-0.28142885252141703
685.700000000009,73.87372554420227,1.2007072245214472,-0.29067586202195006
686.800000000009,73.98346377788774,1.229958306752591,-0.29974654086677877
687.9000000000091,74.09481301432828,1.2622744886648534,-0.31027683743125234
689.0000000000091,74.20484881436064,1.2878932984120237,-0.3194158481915341
690.1000000000091,74.31534186782326,1.320251345846162,-0.3288318220993207
691.2000000000091,74.42504207681093,1.3541350160681356,-0.339723605150863
692.3000000000092,74.53550956150265,1.3864754780082253,-0.34960066158510106
693.4000000000092,74.64554587393894,1.4203044474334117,-0.3587427483692158
694.5000000000091,74.75617986669562,1.4500740120015716,-0.3698369547578899
695.6000000000091,74.86684488983894,1.4856419848370452,-0.3826939148775441
696.7000000000091,74.97767985625958,1.51636359672281,-0.3942051838576841
697.8000000000092,75.08791518682942,1.547978172883885,-0.4055718566989843
698.9000000000092,75.19898734340487,1.5817325590169853,-0.41513114568586884
700.0000000000092,75.30879784975417,1.6098669525655904,-0.42613184172786633
701.1000000000092,75.41920161203434,1.6478800826294906,-0.4400138736393395
702.2000000000093,75.5291889035529,1.6747952783829223,-0.45376468843192264
703.3000000000093,75.64117825512956,1.7081168112143779,-0.46817119599783075
704.4000000000093,75.7518444118792,1.7420860362908825,-0.48057368825167357
705.5000000000093,75.86142186809184,1.7781239385780723,-0.49307039390451735
706.6000000000093,75.97190507141576,1.810013122036681,-0.506584148040937
707.7000000000094,76.0838649478999,1.8393076328924176,-0.5206117720451777
708.8000000000094,76.19331939254084,1.871640170956875,-0.5350671875732478
709.9000000000094,76.3029314578544,1.901412569884979,-0.5482346580494606
711.0000000000093,76.41342235427484,1.932395030239741,-0.5662722555171014
712.1000000000093,76.52350994001759,1.9663742853333672,-0.5814171323966768
713.2000000000094,76.63565575467739,1.99723083675943,-0.5954435023681541
714.3000000000094,76.74389612317007,2.0276663972840816,-0.6096720812325556
715.4000000000094,76.8555439196528,2.06086585091167,-0.6258615013045414
716.5000000000094,76.96581665850543,2.088016675207608,-0.642598481388065
717.6000000000095,77.07573568097503,2.1224553638237684,-0.6579818554043504
718.7000000000095,77.18605366747767,2.1545962591571226,-0.6747725594606622
719.8000000000095,77.29511251433927,2.1864543406935444,-0.6922142838761114
720.9000000000095,77.40563720173428,2.2186932825435077,-0.7073679902676524
722.0000000000095,77.51566869518005,2.253568420204612,-0.7252013090168794
723.1000000000096,77.62683685330305,2.2865277820369543,-0.7421402075576324
724.2000000000096,77.73770718712314,2.3215482982913898,-0.763666363716351
725.3000000000096,77.84672046878553,2.3567859997843623,-0.7805756832807047
726.4000000000096,77.95747728395612,2.3901951805594615,-0.800750508031963
727.5000000000097,78.06763788580436,2.4274711826244983,-0.81640407860194
728.6000000000097,78.17611944927366,2.459288215962001,-0.8382156315316274
729.7000000000096,78.28875542260815,2.489896931370126,-0.8567522261494784
730.8000000000096,78.398510396699,2.5187263972559406,-0.8773037956938547
731.9000000000096,78.50841520459745,2.5492777889208127,-0.897407906684542
733.0000000000097,78.61970138058099,2.5796784138172515,-0.9179001689687438
734.1000000000097,78.72866690560244,2.6097113578659235,-0.9385530065279521
735.2000000000097,78.84039723257156,2.636844595833607,-0.9581855993977695
736.3000000000097,78.9509131779565,2.6648602163272064,-0.9775552254268378
737.4000000000098,79.06149977374511,2.690192311651089,-1.0013991850408015
738.5000000000098,79.17233604151382,2.719053987573045,-1.0184296403938267
739.6000000000098,79.28231718032617,2.753791529635806,-1.041684623190736
740.7000000000098,79.39314329320197,2.7949872602555206,-1.063442018185162
741.8000000000098,79.50396895556825,2.85270368353334,-1.0825916840039516
742.9000000000099,79.61436817540125,2.9198172002077523,-1.1057891932343131
744.0000000000099,79.72424198852435,2.991533367372877,-1.1244744189900544
745.1000000000099,79.83435251353089,3.063676076931154,-1.1474739127489069
746.0000000000099,79.92529378959061,3.1191456237935555,-1.1671217757721402