File: 01_Data/Asphalt_Shingle/STA/N2/10K_min/Asphalt_Shingle_STA_N2_10KData_220916_R3.csv
##Temp./Â°C,Time/min,DSC/(mW/mg),Mass loss/mg
51.0,10.881785420955465,0.02913176494425107,0.0028289448652389915
52.100000000000016,11.205693869862298,0.05303376332226062,0.0012192219609126198
53.20000000000003,11.440501611800878,0.07175049174925996,0.0022354962183976923
54.30000000000005,11.642359582770176,0.08268444249087192,0.0003717433082681687
55.40000000000006,11.821633809841696,0.09476568585354528,0.0007214081011950313
56.50000000000008,11.992796213384665,0.0997375653778374,0.0016243267786202331
57.600000000000094,12.153537720697432,0.10823509153031075,0.0027221825795447074
58.70000000000011,12.305910200693308,0.11480178565367805,0.0007346382037920485
59.800000000000125,12.45886371829265,0.11970163060752137,0.0002840839139972573
60.90000000000014,12.603826515571422,0.12326420104795832,0.001238975591962177
62.000000000000156,12.743874325527122,0.12814369285927785,0.001291382410081976
63.10000000000017,12.88413040193552,0.1297298188823015,0.0004091277485360756
64.20000000000019,13.018972510069842,0.13377898613973582,0.000230299727365324
65.30000000000021,13.153054936666528,0.1350739945669832,0.000412947099857508
66.40000000000022,13.28468734672607,0.13904987944873803,0.0004422517160027617
67.50000000000023,13.418601810368491,0.14061413600214956,0.00013058925456332915
68.60000000000025,13.545946790906832,0.14296381019465976,0.0001046261090822398
69.70000000000027,13.674786965710437,0.1456257599059816,0.00037870347015100947
70.80000000000028,13.801615059987082,0.14774482448590698,0.00137662218577006
71.90000000000029,13.92648984182419,0.1505103549958866,-0.0008592505518283389
73.00000000000031,14.05042009068534,0.15295572076958042,7.349647334287113e-06
74.10000000000034,14.173311690448516,0.15514330388274522,3.6404624052632784e-05
75.20000000000034,14.295834607632898,0.1569160927836355,0.0012704263577942854
76.30000000000035,14.416169683543766,0.15965009502724636,-8.696030104449193e-06
77.40000000000038,14.534175094762295,0.15935328353734102,-5.345017671132268e-06
78.5000000000004,14.657485818088238,0.16011523403933925,-0.001087614448577412
79.6000000000004,14.77440304256362,0.1635870286668213,-0.0006019193659319022
80.70000000000041,14.895137580025594,0.1665935916211676,0.00036008438038370727
81.80000000000044,15.011199341716164,0.16902381039605552,-1.366203385089193e-06
82.90000000000046,15.127820577709617,0.16878086344469367,-0.001089831844546918
84.00000000000047,15.244805718428035,0.17087989543942084,5.546198454275952e-06
85.10000000000048,15.36168897677535,0.17351724079563313,-0.0013301810554660065
86.2000000000005,15.47564780485227,0.17289500450789563,-4.352720634859253e-05
87.30000000000052,15.588978877648033,0.17411560638916557,-0.0013323358829540055
88.40000000000053,15.704730934363512,0.1751581752404392,-0.00010759897568890509
89.50000000000054,15.818242186086378,0.178229049920138,-9.836304899435433e-05
90.60000000000056,15.929824677274436,0.1783578765602083,-9.988454667331226e-05
91.70000000000059,16.042105792776105,0.17929763422048928,-0.00010049442243298401
92.8000000000006,16.154380587685093,0.18120755372902586,-0.001431404997246144
93.9000000000006,16.26534605306967,0.1817399322233002,-0.0004551599938631412
95.00000000000063,16.375445819605503,0.18250821547785923,-9.45965575160912e-05
96.10000000000065,16.48732592851948,0.18590348506671228,-0.00021707232705958646
97.20000000000066,16.59748969166336,0.1876743892393824,-0.00011544270957442038
98.30000000000067,16.706404859566977,0.1878084831787583,-0.00027147789307191417
99.40000000000069,16.815710196869247,0.18787507860627106,-0.0014190140194969558
100.50000000000071,16.925416983991962,0.18798210678559313,-0.0014809033632579016
101.60000000000072,17.034352004640613,0.18951987076392585,-0.001414738956799333
102.70000000000073,17.142809954634224,0.18972202208993605,-0.0017461535475491452
103.80000000000075,17.251211566268278,0.19119904018192746,-0.00274918099287369
104.90000000000077,17.35882749230304,0.1936707321047102,-0.0014418527805366566
106.00000000000078,17.46802285040851,0.19304487035351614,-0.0015278784723391503
107.10000000000079,17.57560564240247,0.19463572869999357,-0.0014364028724127564
108.20000000000081,17.684794305921947,0.19551885441864636,-0.0014079089756857677
109.30000000000084,17.792076547022468,0.1959444790863043,-0.0014246396216561763
110.40000000000084,17.899407587590716,0.19670124270845823,-0.0014197654601968424
111.50000000000085,18.006942076149375,0.19719588320341175,-0.00045558014945923375
112.60000000000088,18.113696882096168,0.19846724121499015,-0.0014312924992978537
113.7000000000009,18.223284972809115,0.19984321417081463,-0.0020752888073114484
114.8000000000009,18.329074116895672,0.19923638436060065,-0.0010978986979308658
115.90000000000092,18.437153797634124,0.1990110519786894,-0.0010120849839005963
117.00000000000094,18.545237997612215,0.19985327965197142,-0.0014233182095066965
118.10000000000096,18.65112610413628,0.19974574068871132,-0.0026679463480761
119.20000000000097,18.75875893690773,0.2013891899559388,-0.00207998171487489
120.30000000000098,18.866120198963674,0.20268369370111894,-0.002739884679084259
121.400000000001,18.973117405095003,0.20122631382324596,-0.0014198687856539216
122.50000000000102,19.07951913226898,0.20256875004383001,-0.002454269594262648
123.60000000000103,19.18602319779217,0.20347819345792117,-0.0015510076946214646
124.70000000000104,19.292964629869445,0.20126949415625495,-0.0014401237942438527
125.80000000000106,19.39936736885629,0.2024048296797113,-0.001419761023034205
126.90000000000109,19.506114366453605,0.20359404892232746,-0.0020663989553257878
128.00000000000108,19.612572573949677,0.20352305442785945,-0.0004264993399574202
129.1000000000011,19.717821070506425,0.20565117711904113,-0.0007560568300815085
130.20000000000113,19.82388545205196,0.2052725276935775,-0.001750030360036181
131.30000000000115,19.93038070308855,0.20424987447285758,-0.0026253949421408684
132.40000000000117,20.03634631646016,0.2067047898610701,-0.0017522821217070828
133.50000000000117,20.14101137571857,0.20662084378061885,-0.0017500697713637159
134.6000000000012,20.246821793649303,0.20609851529354228,-0.002017216533054089
135.7000000000012,20.35373716982885,0.2076130261962693,-0.0028265846847266296
136.8000000000012,20.45917000000011,0.20793400879084745,-0.003064832400746731
137.90000000000123,20.564423758452453,0.20764195677197816,-0.0030691824966395664
139.00000000000125,20.670130435355752,0.20899964563087114,-0.0017502635148800572
140.10000000000127,20.775460304508574,0.20903982491276696,-0.0030688718320388553
141.2000000000013,20.881024149448805,0.21182946988966866,-0.004401577531150558
142.3000000000013,20.986245352123817,0.21164603878651633,-0.0030617066177094365
143.4000000000013,21.09062862524043,0.21183763103324627,-0.003069582063182086
144.50000000000134,21.195548246093367,0.21379755351354313,-0.003102009300828712
145.60000000000133,21.301371950373106,0.21272640572521828,-0.004386738391734646
146.70000000000135,21.405948077792814,0.2141486157768273,-0.004389553754900355
147.80000000000138,21.510256143770075,0.21230813184584862,-0.0033496494159299672
148.9000000000014,21.616202434123196,0.21378083779728996,-0.00438435482233368
150.00000000000142,21.72037408872783,0.21410491483364302,-0.0033901120728065948
151.10000000000142,21.825262789366672,0.21522230079996318,-0.004255540177427797
152.20000000000144,21.930096728162916,0.21204706925928773,-0.003723509237077316
153.30000000000146,22.03470481530253,0.21565878185565324,-0.005099284929529269
154.40000000000146,22.13955001021598,0.21528165229781826,-0.003070408293217586
155.50000000000148,22.244834014404827,0.21637421976766158,-0.004143213975391191
156.6000000000015,22.349467555518626,0.21695213764130628,-0.0036228994599141195
157.70000000000152,22.45454653002405,0.21742422325768185,-0.004380013522508275
158.80000000000155,22.559940335433655,0.21898047713516122,-0.004380015932861525
159.90000000000154,22.664037796910986,0.21782085016267516,-0.0030714707690768783
161.00000000000156,22.76898430129343,0.22007972815610644,-0.004379999289243042
162.1000000000016,22.87329393764885,0.21910127729889783,-0.003072061663417891
163.20000000000158,22.97777177386565,0.22221619572728135,-0.004444351452817408
164.3000000000016,23.08324141176164,0.22237151110959297,-0.003069740779046981
165.40000000000163,23.188640629879302,0.2215326552389959,-0.004714518719314942
166.50000000000165,23.29261698970045,0.22125306070545048,-0.006030148476486197
167.60000000000167,23.396738246835994,0.2213842349263282,-0.0047180916509406146
168.70000000000167,23.501778268181084,0.22345099838844207,-0.005321498266103841
169.8000000000017,23.604611029197866,0.22244058449027881,-0.004721377648834846
170.9000000000017,23.711845516584408,0.22447125399201318,-0.004709897436487864
172.0000000000017,23.815756154679846,0.2245567490802215,-0.006030232075151076
173.10000000000173,23.91972484837709,0.224415751539768,-0.006643315310403963
174.20000000000175,24.02595373106537,0.22429292292462455,-0.006039855701608143
175.30000000000177,24.128588824825798,0.22522315060440246,-0.006089380973458791
176.4000000000018,24.234496050243393,0.22667940206264936,-0.0060298108630516545
177.5000000000018,24.339268357883377,0.22592592342701678,-0.007349249844162298
178.6000000000018,24.443982127759075,0.2257791197659741,-0.0053684939726657
179.70000000000184,24.547860232857314,0.227193218478274,-0.006093584402503183
180.80000000000183,24.65266631989031,0.22652009778046456,-0.006031489433806048
181.90000000000185,24.757576255450562,0.2308188039540221,-0.007349821678359625
183.00000000000188,24.862765799164503,0.23004010131322095,-0.008084175956432738
184.1000000000019,24.96708798402152,0.23030518564151004,-0.007349663567679521
185.20000000000192,25.070067884709754,0.23055890533196943,-0.007349814044402159
186.30000000000192,25.175782718709282,0.22987176946052112,-0.00736912321598604
187.40000000000194,25.280108148815923,0.23246565427845378,-0.007019869515968669
188.50000000000196,25.384376313132492,0.23285971081556356,-0.006690546846771284
189.60000000000196,25.48774904495663,0.23361705117392317,-0.0073611542659568485
190.70000000000198,25.591089933348808,0.23425162863162197,-0.007349943484608268
191.800000000002,25.69768911902422,0.2349568250993157,-0.007678192348745672
192.90000000000202,25.801917584841956,0.23574188992139034,-0.00899995419763755
194.00000000000205,25.90572760213055,0.23618761370392993,-0.008989674687124083
195.10000000000204,26.00961161261976,0.23609189655687368,-0.010309952447536297
196.20000000000206,26.113796013367473,0.23686765911367635,-0.010642208317066082
197.3000000000021,26.217640938354787,0.23679505578565774,-0.010639940613328402
198.40000000000208,26.320834009338444,0.2381242011364615,-0.010316047158537955
199.5000000000021,26.425299556897887,0.23837767808858423,-0.010309937697238869
200.60000000000213,26.52946985453763,0.23827985410466046,-0.008997740725755765
201.70000000000215,26.634013112765228,0.2365834872589434,-0.010311991374432061
202.80000000000217,26.738416469183885,0.23793265932444396,-0.011629910666924204
203.90000000000217,26.842391691263344,0.2395620500256036,-0.011630167433003713
205.0000000000022,26.946267011170345,0.2398288610770325,-0.012296542788371667
206.1000000000022,27.051742405608614,0.2398814303771727,-0.01229007801640103
207.2000000000022,27.155129801366947,0.24156401548535833,-0.012290079289849487
208.30000000000223,27.25857822789925,0.2420752122262999,-0.013609768207487605
209.40000000000225,27.36307431037182,0.24110576884162926,-0.013610078032966655
210.50000000000227,27.467798286892812,0.24023397832236948,-0.013624797141740252
211.6000000000023,27.572316228059762,0.24172554832359416,-0.014293435591683057
212.7000000000023,27.67662306603058,0.24359214760315384,-0.014270069995249823
213.8000000000023,27.781152340958343,0.24116486154419914,-0.014270063268249977
214.90000000000234,27.884640412763968,0.24483251900992953,-0.012941476787562411
216.00000000000233,27.98896416393339,0.24458392047028554,-0.009230105499647312
217.10000000000235,28.094203651615338,0.2462869566940208,-0.023534580311248998
218.20000000000238,28.197023426848705,0.24536224001275186,-0.015373299043273114
219.3000000000024,28.29984550303611,0.24534481577883227,-0.015360068517255687
220.40000000000242,28.404737978568356,0.2460916909575297,-0.016356866019673788
221.50000000000242,28.509919204013567,0.24690351828857515,-0.016721472512803537
222.60000000000244,28.614276657643522,0.2483172791725482,-0.016350008361517343
223.70000000000246,28.718776798183136,0.2494749108633525,-0.017669259717558283
224.80000000000246,28.82277480318086,0.24929813933396605,-0.017990801509058407
225.90000000000248,28.926810813444373,0.2494094840906771,-0.01800037666904819
227.0000000000025,29.03206334859766,0.2491131699810455,-0.019617808131537906
228.10000000000252,29.13668316142689,0.25065477591765806,-0.018659769545282145
229.20000000000255,29.241399206004623,0.2507985129999376,-0.020310654672731854
230.30000000000254,29.344372031088504,0.2517442101110412,-0.020318059947314726
231.40000000000256,29.450387956458687,0.2528165704702654,-0.02029784417424274
232.5000000000026,29.55473284155197,0.2529493294253551,-0.02063003024850829
233.60000000000258,29.65896045904442,0.25178433993022464,-0.0219500243416908
234.7000000000026,29.764602734207386,0.2516235075207781,-0.020646317576388018
235.80000000000263,29.867327306735408,0.25025855004608966,-0.023199610781076796
236.90000000000265,29.972991642313403,0.2507284865113314,-0.02327007743475784
238.00000000000267,30.07878310650499,0.24917971417103435,-0.0245830789721162
239.10000000000267,30.181603004271366,0.25014901538371037,-0.02313369569289847
240.2000000000027,30.287331529398088,0.24978940035854524,-0.02557002579495604
241.3000000000027,30.39333182090416,0.24897010779335305,-0.025539015037566948
242.4000000000027,30.497931216290468,0.24883500701213557,-0.026564754571809956
243.50000000000273,30.60305065584265,0.25047777063019905,-0.026873556101407736
244.60000000000275,30.707972880451273,0.25053727746182697,-0.02787978882947506
245.70000000000277,30.81087727120323,0.25171335609770407,-0.029189822456267223
246.8000000000028,30.916340825943553,0.2518739755467907,-0.030179823813571982
247.9000000000028,31.021958472287064,0.25025978895249057,-0.030179933322700858
249.0000000000028,31.126773663053633,0.25283178618709756,-0.030511699688637428
250.10000000000284,31.22967946916792,0.2542759022846883,-0.03151487677167575
251.20000000000283,31.33538469771443,0.2539355959775319,-0.0328199330012251
252.30000000000285,31.439464354279608,0.25657448206995637,-0.032160788085365155
253.40000000000288,31.5453359268507,0.2552046450872978,-0.03251147447243907
254.5000000000029,31.647508198133504,0.25569266515342026,-0.035121071343501065
255.60000000000292,31.753792641794256,0.2567930363840716,-0.03511981444132051
256.7000000000029,31.859949828829937,0.2573310378926874,-0.035845367509401704
257.8000000000029,31.96318034797158,0.2570284416142864,-0.037100313425718845
258.90000000000293,32.065724736319886,0.25800595275002813,-0.03904008716671381
260.00000000000296,32.172400665880794,0.25922886537733847,-0.03973996372316435
261.100000000003,32.27699713762655,0.25757819730680553,-0.03973984581693912
262.200000000003,32.3815493121463,0.26017849077832367,-0.03992480421444666
263.300000000003,32.48571051612219,0.26142420470302197,-0.04106099993831114
264.40000000000305,32.59054249985514,0.26069128536249897,-0.04300550455054264
265.50000000000307,32.69502001762508,0.2624321096351654,-0.044340161110716814
266.6000000000031,32.79996225010471,0.26132153266876634,-0.04434011332150245
267.7000000000031,32.90533145442458,0.2609789351803815,-0.0456629599593632
268.8000000000031,33.00925777391422,0.2620433639243608,-0.04698050163687073
269.9000000000031,33.112111219323936,0.2597712194981998,-0.048299355242996
271.0000000000031,33.21811121435541,0.26172875953424457,-0.04958917931573925
272.10000000000315,33.323702597717315,0.2608631945004648,-0.05098055903970389
273.2000000000032,33.42820085999571,0.26003034961953897,-0.050930001015775606
274.30000000000314,33.53270669398424,0.26156365258075576,-0.0509298520352619
275.40000000000316,33.63758930638376,0.2612227472897526,-0.05224257917250208
276.5000000000032,33.74349142952207,0.2609724221735814,-0.05459583906790488
277.6000000000032,33.848474744007774,0.2618392300661617,-0.0558800330166882
278.70000000000323,33.95287905359243,0.2617292723700273,-0.057084632750674213
279.80000000000325,34.058346055946316,0.26266612680657797,-0.05718990192241602
280.9000000000033,34.164182498871,0.2628829897925916,-0.058824784297832
282.0000000000033,34.265524257655194,0.26438166534234686,-0.06120083230907891
283.1000000000033,34.37056280483604,0.26332600475011936,-0.06157477925520771
284.20000000000334,34.47776252175261,0.264554370088665,-0.06278014561620227
285.30000000000337,34.58241046255823,0.2648369914407127,-0.06410059710346161
286.40000000000333,34.68825482335649,0.26541555245688575,-0.0640760699354157
287.50000000000335,34.79300095010118,0.26571215003337534,-0.06673982025549297
288.6000000000034,34.89767712530671,0.26549344880125836,-0.068055912910292
289.7000000000034,35.002320124681845,0.265994890520147,-0.06937039556970248
290.8000000000034,35.107520453097756,0.2658170000589972,-0.07201121183304293
291.9000000000034,35.21218776358209,0.26709641479545176,-0.07261706482354091
293.0000000000034,35.31761484789556,0.26534730614026614,-0.07399241118564204
294.10000000000343,35.4222685129059,0.26541293328036597,-0.07530165678628586
295.20000000000346,35.52716907172703,0.2642159852813434,-0.07796886410672199
296.3000000000035,35.63266444255668,0.2644913505622616,-0.07923542453493582
297.4000000000035,35.73784815810385,0.2656857134862525,-0.07926023639588031
298.5000000000035,35.84293381924074,0.265510851596209,-0.08086843447579284
299.60000000000355,35.947521882908724,0.26347750225117383,-0.083209882279204
300.70000000000357,36.05359187408911,0.2639435470380811,-0.08454306528706512
301.8000000000036,36.15917101112583,0.26609986750541215,-0.08455525362977356
302.9000000000036,36.26456116701522,0.2650680559011621,-0.08584689849189653
304.0000000000036,36.369745402706855,0.2652192058304018,-0.0871212391216476
305.1000000000036,36.47450388452986,0.2648294076913421,-0.08979902184172017
306.2000000000036,36.57980223809638,0.26673287666407886,-0.08984234243179845
307.30000000000365,36.68297986592284,0.2673759016680186,-0.09375692043887396
308.4000000000037,36.79080687735637,0.2686529270787007,-0.09508929514445752
309.5000000000037,36.89710468957847,0.2685491476567069,-0.09736011623037655
310.60000000000366,37.000917704621955,0.2686135232520861,-0.09711972481572806
311.7000000000037,37.108239925831846,0.2681843218414127,-0.09966157030479028
312.8000000000037,37.21220909770764,0.2694482315712463,-0.10031813859940186
313.90000000000373,37.31895964471676,0.26989261871846926,-0.10328109059903978
315.00000000000375,37.42399049701329,0.2685549257330616,-0.10362230361921432
316.1000000000038,37.529741303398716,0.26861865064216917,-0.10626106260620327
317.2000000000038,37.6352582784636,0.26847484750177597,-0.1066073022077152
318.3000000000038,37.741155022767074,0.26899394701205326,-0.10941322490184335
319.40000000000384,37.845826449413,0.2689928215967755,-0.1128524133265123
320.5000000000038,37.950827015472115,0.26963335127184873,-0.11285511239516977
321.60000000000383,38.057802733248536,0.2690555381307803,-0.11424820714899031
322.70000000000385,38.16302112554659,0.2689575557603714,-0.11789868018988336
323.8000000000039,38.26917096676142,0.26957146517261543,-0.11921998726114724
324.9000000000039,38.37393434349889,0.27163753006408686,-0.12097693792843423
326.0000000000039,38.480656635397146,0.26962120248484056,-0.12228018807945196
327.10000000000394,38.585883839092695,0.2703623404535711,-0.12482266850762702
328.2000000000039,38.69103733077965,0.2710043387097577,-0.1264698705644225
329.30000000000393,38.797502560047626,0.270634813601093,-0.1277775849234417
330.40000000000396,38.90355084752127,0.27121002447281495,-0.130518948783505
331.500000000004,39.00917000000035,0.27024078774474947,-0.13256234308557335
332.600000000004,39.11488727385147,0.27165691965170113,-0.13404135218530744
333.700000000004,39.219446266592826,0.27043459254815616,-0.13536129983416867
334.80000000000405,39.32436952069856,0.27024289875674445,-0.13796578634167034
335.90000000000407,39.43303303457339,0.273845603508011,-0.14066958810202435
337.0000000000041,39.53981192051872,0.27231544709768907,-0.1419498233287757
338.10000000000406,39.6455326010367,0.27324798723498533,-0.14457221566312883
339.2000000000041,39.75237916072821,0.27288593751722545,-0.14455650328423575
340.3000000000041,39.85623211032321,0.2745150249294155,-0.14724991975663126
341.4000000000041,39.96394767768232,0.2734953550173742,-0.14971700761703532
342.50000000000415,40.07093742296242,0.2741504604356064,-0.1521511085168843
343.6000000000042,40.176826714699246,0.2733805840547122,-0.15510907714248523
344.7000000000042,40.28350868966111,0.27376144011107806,-0.15606979751355743
345.80000000000416,40.38926419418468,0.2736363124351936,-0.1591807025647407
346.9000000000042,40.494880594378884,0.2726570029437556,-0.16051978189814875
348.0000000000042,40.602371339857825,0.2720139563730827,-0.16312797120940292
349.10000000000423,40.705946480373534,0.27356326524969166,-0.16430746069619495
350.20000000000425,40.813468985727404,0.27312315261689346,-0.16706657916880285
351.3000000000043,40.91966524719338,0.27345068764574976,-0.16940412652612702
352.4000000000043,41.02656767389642,0.275585731810724,-0.17233645987470592
353.5000000000043,41.13284802418309,0.2763280141287183,-0.17330506063793782
354.60000000000434,41.238265313787466,0.27425416978742045,-0.17559177101235202
355.7000000000043,41.34472540615597,0.2718438913089609,-0.17894974777891193
356.80000000000433,41.45044062761422,0.2715697639354021,-0.1815607862431463
357.90000000000435,41.55742987409441,0.2710289209618806,-0.18281922711841592
359.0000000000044,41.66307576500373,0.2697215592184439,-0.18557303298431105
360.1000000000044,41.7687857082727,0.2675734143802827,-0.18815920286700116
361.2000000000044,41.87600684672937,0.2654135740536181,-0.1912272141453495
362.30000000000445,41.98226040811229,0.2642348455558887,-0.19241388750205424
363.4000000000044,42.088207871637856,0.2667757781540483,-0.19507797593123666
364.50000000000443,42.1938131473989,0.2619443134459164,-0.1964395939275363
365.60000000000446,42.300219696991086,0.25840359542945524,-0.19957031331899522
366.7000000000045,42.40586372885788,0.25416260811924274,-0.2017714622868345
367.8000000000045,42.51223770993765,0.25185590003330394,-0.20552862497831015
368.9000000000045,42.620007811919635,0.25059617717661453,-0.20722966737100768
370.00000000000455,42.72662079619095,0.24860181923803382,-0.2101286845886987
371.10000000000457,42.83261251556027,0.24675746807186005,-0.2130465916857185
372.2000000000046,42.939664269792374,0.24602153091679158,-0.21427837036365815
373.30000000000456,43.046390624001454,0.24574729899220704,-0.21831991492519087
374.4000000000046,43.15202433334512,0.2464552284855993,-0.22083226207573547
375.5000000000046,43.25907646320566,0.2438370116228059,-0.2223003110254802
376.6000000000046,43.36581591532385,0.24160596563052628,-0.22488041018080285
377.70000000000465,43.47243762702789,0.24265571781009432,-0.22760671604722127
378.8000000000047,43.579264388720794,0.23941453002659563,-0.23120783456068672
379.9000000000047,43.68639434995772,0.24044626950088122,-0.2329956963126838
381.00000000000466,43.79233483273323,0.2447152422945651,-0.23550340627841226
382.1000000000047,43.898948288421686,0.24066599570604885,-0.23952613218742602
383.2000000000047,44.00637443647439,0.24182090376018184,-0.2422943551998591
384.30000000000473,44.11311137459505,0.24213888325511457,-0.24488517457515613
385.40000000000475,44.218003642000795,0.24246972268254896,-0.2489936248837794
386.5000000000048,44.32663620694113,0.24206674629925284,-0.25036153055623167
387.6000000000048,44.43350125078705,0.2418307090075411,-0.2528638868123405
388.7000000000048,44.54024451649725,0.2427322549106674,-0.2572150336820034
389.80000000000484,44.64666301661943,0.2409904043344232,-0.2598657407096283
390.9000000000048,44.753436421426684,0.2407908274811209,-0.2625351075997475
392.00000000000483,44.859840296159355,0.23924483521353923,-0.26521633083984764
393.10000000000485,44.96643857267714,0.2383692788740659,-0.26829771830722215
394.2000000000049,45.073855603771214,0.23878838795609136,-0.2728084407214397
395.3000000000049,45.18091111141166,0.2379715092147111,-0.27465616404865356
396.4000000000049,45.285244395902936,0.23585279087271316,-0.27827604394442274
397.50000000000495,45.394527645222674,0.23432063767311595,-0.28258254603385646
398.6000000000049,45.50096046125121,0.23434202114152036,-0.28603704962136245
399.70000000000493,45.608366244792094,0.2357384724947612,-0.2879586721516847
400.80000000000496,45.71580795239486,0.23566812311730578,-0.29220100959627393
401.900000000005,45.822133518337495,0.23541491036930096,-0.2965618040927236
403.000000000005,45.92990265085494,0.23709062995590902,-0.29914459379494485
404.100000000005,46.03599720134284,0.23832836152507209,-0.3032561874101871
405.20000000000505,46.14286519689513,0.23791729955014762,-0.30627145698744496
406.30000000000507,46.25038773358879,0.23803401712889327,-0.30973411990005983
407.4000000000051,46.35768090391078,0.24001586985552437,-0.3139574862239556
408.50000000000506,46.464538873040134,0.2393635888238279,-0.31675531443171856
409.6000000000051,46.571648650619515,0.23994128253400326,-0.3221627921819592
410.7000000000051,46.677978024498735,0.24016713175707505,-0.3264491940538279
411.8000000000051,46.78576711791848,0.24162435872787802,-0.3294563561961428
412.90000000000515,46.89259017078076,0.2399226787661385,-0.33261547709013284
414.0000000000052,47.00076293056818,0.24071827895428655,-0.33707925727341514
415.1000000000052,47.106451244736995,0.24320934294604657,-0.3420727143829465
416.20000000000516,47.21343605047433,0.24452630431867683,-0.34513884785657556
417.3000000000052,47.32141304712998,0.2437301371084889,-0.34973339272104464
418.4000000000052,47.427682811016524,0.24600193882409138,-0.35399320944793544
419.50000000000523,47.53551198413573,0.24723779093942722,-0.3568838888427335
420.60000000000525,47.64189864136626,0.24720449567944058,-0.3608851127888606
421.7000000000053,47.748673845802045,0.24977827802614172,-0.3671122587765816
422.8000000000053,47.854780652974846,0.24884427658536212,-0.3727267923505173
423.9000000000053,47.96447478005705,0.2515780803746983,-0.37733104242968585
425.00000000000534,48.07241907630715,0.25267594774713087,-0.38154169957955775
426.1000000000053,48.17925962049523,0.2520249609594607,-0.3849004691154825
427.20000000000533,48.28705226580204,0.25564748138789417,-0.38946346071448
428.30000000000535,48.39399703464599,0.25323682246110224,-0.39419522823800524
429.4000000000054,48.50131285638243,0.2516321613656801,-0.39823183036205423
430.5000000000054,48.608954585881634,0.253702757843131,-0.40408895673334433
431.6000000000054,48.71646400042934,0.2541976795495189,-0.40889504915732733
432.70000000000545,48.82372668265417,0.25726532134277824,-0.4133476316189544
433.8000000000054,48.93132364621057,0.25676962175287954,-0.41791400633140796
434.90000000000543,49.038118269096614,0.2578589316023818,-0.42378441965958125
436.00000000000546,49.14635700238377,0.2602775972808773,-0.42883286151002986
437.1000000000055,49.25442885354373,0.26076651056187583,-0.43407776169774026
438.2000000000055,49.361958908527306,0.25928800169436717,-0.4389221776300025
439.3000000000055,49.46896976602984,0.2609151583180056,-0.4438501368099872
440.40000000000555,49.57574368671574,0.2628917039207572,-0.44982570139112354
441.50000000000557,49.68482327004952,0.2629760312780065,-0.45489824214412167
442.6000000000056,49.79238483634193,0.2610704122697646,-0.46067212934818524
443.70000000000556,49.90047495565951,0.26110838839909956,-0.46481651190664364
444.8000000000056,50.00703966600548,0.2650939462653439,-0.47106478599208135
445.9000000000056,50.11604142675808,0.26389796171061064,-0.4770142899199947
447.0000000000056,50.22224825052795,0.2657733875377499,-0.4801321631150408
448.10000000000565,50.32973904777355,0.2683920851517041,-0.4865450355186365
449.2000000000057,50.43721380189015,0.271888762185695,-0.4948548673703934
450.3000000000057,50.544426037251625,0.2733821947058144,-0.49982427580926236
451.40000000000566,50.65293301564622,0.2753470573040194,-0.5033709044832193
452.5000000000057,50.75979836683876,0.27810967102005746,-0.5077570903125843
453.6000000000057,50.86791947332237,0.2794510945722143,-0.5125758986416136
454.70000000000573,50.97601429296364,0.28175899239012847,-0.5182032151525138
455.80000000000575,51.08165896737012,0.28254994506576936,-0.5236791257153506
456.9000000000058,51.19137772443675,0.2848990683844541,-0.5307644109237075
458.0000000000058,51.2991700000006,0.28505243601443864,-0.5353008568688518
459.1000000000058,51.407739463847314,0.2839829820281078,-0.539691033732415
460.20000000000584,51.51586167436388,0.28271202334275425,-0.5439153110259025
461.3000000000058,51.62340289242311,0.28337576543992227,-0.5498153477784031
462.40000000000583,51.73083724560285,0.28399454769139365,-0.5562435137126815
463.50000000000585,51.83896755374949,0.2813719946108878,-0.5596534947983294
464.6000000000059,51.94715592987032,0.280359043901381,-0.56452100258169
465.7000000000059,52.05508916930979,0.27993149152241137,-0.5674263259591168
466.8000000000059,52.16073839755533,0.2777168316382499,-0.5707984091152101
467.90000000000595,52.2700032461376,0.28016262373329015,-0.5756015413087101
469.0000000000059,52.37824100600965,0.2768527021823851,-0.5791265518353979
470.10000000000593,52.48631882469156,0.27495741913529326,-0.5811031108228666
471.20000000000596,52.595546855214444,0.2750813743176813,-0.584998556965497
472.300000000006,52.70315050296833,0.27617866779253375,-0.5880226232613843
473.400000000006,52.810666954947,0.27341126418841655,-0.5918332777760318
474.500000000006,52.9183846444776,0.27173108076969066,-0.5944198256633944
475.60000000000605,53.0263120678345,0.26897979325318944,-0.5971529131785616
476.70000000000607,53.13442819993296,0.26573856696950227,-0.5993415168232072
477.8000000000061,53.24146593307278,0.26359029159972436,-0.6022278276022535
478.90000000000606,53.34928065747164,0.2621532393436571,-0.6040203812873832
480.0000000000061,53.45832838554818,0.25929796690347096,-0.6066568152675957
481.1000000000061,53.567489597686574,0.259225693145101,-0.6078388044457443
482.2000000000061,53.6763699853737,0.25768565758176654,-0.6093262882593757
483.30000000000615,53.784010628287405,0.2547770768629358,-0.6109293614363756
484.4000000000062,53.892036542820286,0.2531325157244225,-0.6122546173976735
485.5000000000062,53.9999719684616,0.24975771576438488,-0.6136861074355378
486.60000000000616,54.10582388424422,0.24946163754758,-0.6162969279313382
487.7000000000062,54.21549564367383,0.2497800886060214,-0.6176302298484804
488.8000000000062,54.32330779625757,0.24718330136826017,-0.6176434959140269
489.90000000000623,54.431687189585,0.24564936587318587,-0.6199870287637066
491.00000000000625,54.539914359523415,0.24447669311092945,-0.6212388570658893
492.1000000000063,54.64853241842812,0.24326090931631383,-0.6225701590394652
493.2000000000063,54.75660438874743,0.24022900067549646,-0.6238899969812763
494.3000000000063,54.86456368460745,0.23927910332183588,-0.6249666158155298
495.40000000000634,54.9733544795491,0.23794467474390535,-0.6252280302505402
496.5000000000063,55.08044374368718,0.23512800705968806,-0.6265215329750884
497.60000000000633,55.19024562954845,0.23735399708873073,-0.6265152105573084
498.70000000000636,55.29795141488675,0.23508874914233835,-0.6288247419116306
499.8000000000064,55.40611178782961,0.23765894901943774,-0.6288298774833154
500.9000000000064,55.514008419203506,0.24287348681116494,-0.6291486660647347
502.0000000000064,55.62308305921518,0.2471088158072955,-0.6298366213268909
503.10000000000645,55.730721084437604,0.2541628108408438,-0.6311308779341775
504.2000000000064,55.83948455049039,0.25544909509127334,-0.6311301520436041
505.30000000000643,55.949171097947776,0.2625239634495151,-0.6321202645804371
506.40000000000646,56.05633126274577,0.25973303033414297,-0.6324513168696901
507.5000000000065,56.16521340380447,0.26262521939230155,-0.6330786232282573
508.6000000000065,56.273918573646824,0.26546310348003743,-0.634430444323042
509.7000000000065,56.38156364473006,0.266250870689445,-0.6347618411318905
510.80000000000655,56.491005890378034,0.2651923834014338,-0.6347600254057335
511.90000000000657,56.60007368474775,0.26613659417035473,-0.6347593750324241
513.0000000000066,56.70774533161455,0.26593294377070076,-0.6361086491454002
514.1000000000065,56.81721847466141,0.2652584908365887,-0.6367400359589075
515.2000000000066,56.92562270997823,0.26577811449306243,-0.6367337372464554
516.3000000000065,57.03130696019937,0.2676990348675672,-0.6375391173171638
517.4000000000067,57.14280851656052,0.26852955970104275,-0.636842953968964
518.5000000000066,57.250378287831985,0.2668674379206284,-0.638343250385057
519.6000000000067,57.359469059512875,0.2659084179413739,-0.6403592486173553
520.7000000000066,57.46948729860263,0.2649703779871554,-0.6401217070823026
521.8000000000067,57.57816064589745,0.26662856748777786,-0.6393702546222699
522.9000000000067,57.686615178831815,0.2659481711064099,-0.6421103589221264
524.0000000000067,57.79527448476541,0.26811982685845936,-0.6408004891840937
525.1000000000067,57.90431936033349,0.26678665376668453,-0.6421324713828525
526.2000000000068,58.013009471583956,0.27058116032593493,-0.6407937171831364
527.3000000000068,58.1223483651801,0.2712169020732955,-0.6434302560338958
528.4000000000068,58.23109623593515,0.271722844146841,-0.6421097876138351
529.5000000000068,58.340287853975916,0.27231488523733904,-0.6420831035113812
530.6000000000068,58.44898555382576,0.2743086763684147,-0.6447498470337978
531.7000000000069,58.55775740579192,0.27399528359817227,-0.6460714380069139
532.8000000000068,58.66601962439856,0.27825462620765684,-0.6460705297102294
533.9000000000069,58.775433650644125,0.2816703740924644,-0.644995356397764
535.0000000000068,58.884622690402956,0.28258510738108245,-0.6451769619542205
536.100000000007,58.99353594439537,0.2828821798674319,-0.6463570476768377
537.2000000000069,59.10236968241405,0.28570606475792115,-0.6479261985950937
538.300000000007,59.21129512877017,0.28595790575088353,-0.6489565417060681
539.4000000000069,59.32037352503218,0.28821203306293564,-0.6485868083393678
540.5000000000069,59.42936994160427,0.2889465213722455,-0.6495801535800894
541.600000000007,59.538231768151455,0.2891630395153334,-0.6495800332620876
542.700000000007,59.6472857084095,0.2922598153888728,-0.6509002619524766
543.800000000007,59.7555550933351,0.29685009287834474,-0.650810458328198
544.900000000007,59.86478433277774,0.296720175886965,-0.6522094243046133
546.000000000007,59.97377673468627,0.30101722261637354,-0.6528303670980251
547.1000000000071,60.08176475868135,0.30446587316183615,-0.6528698316414956
548.2000000000071,60.19018918676655,0.30554337172407087,-0.6542703890763395
549.300000000007,60.299467203328724,0.30997408494422374,-0.6561680225822517
550.4000000000071,60.40947610970168,0.3112972539852874,-0.6558012585051722
551.500000000007,60.51861340620271,0.3173525799614647,-0.6558401930851492
552.6000000000072,60.627888441709594,0.3200344466184548,-0.6561559773506329
553.7000000000071,60.735966797196596,0.3226987364104906,-0.6581406874006879
554.8000000000072,60.84590316689879,0.33055101239746265,-0.6594241085785888
555.9000000000071,60.95446579297764,0.33214333400861695,-0.6549474000009314
557.0000000000072,61.06113480623837,0.3343414050701794,-0.6543715732583211
558.1000000000072,61.17210024521345,0.3357002173656495,-0.657359046373295
559.2000000000072,61.28113564149955,0.33734511322023975,-0.6612283277962923
560.3000000000072,61.39087838158247,0.3416716956697524,-0.6612194787378955
561.4000000000073,61.49978025128798,0.3414359093251852,-0.663530035391017
562.5000000000073,61.60886482455056,0.3406086503459351,-0.6635131943306636
563.6000000000073,61.71794565221508,0.34068602071440435,-0.6648410827786333
564.7000000000073,61.8279001361505,0.3376828488028907,-0.666480184972893
565.8000000000073,61.93667500004868,0.33446104339371396,-0.6671883866215338
566.9000000000074,62.04636784813229,0.33063251818079553,-0.6668200941957725
568.0000000000074,62.15543289241099,0.3261401999057215,-0.6678028682481205
569.1000000000074,62.264313431274005,0.32296552240990606,-0.6664767096937472
570.2000000000073,62.373664164075045,0.3172079271191599,-0.6651697817820219
571.3000000000073,62.48283866362086,0.3111578575148286,-0.6658282063418777
572.4000000000074,62.59150988270358,0.30593149413291487,-0.6671611607731207
573.5000000000074,62.699948862774626,0.3036007193522945,-0.672285105661035
574.6000000000074,62.809064862453006,0.297862996220847,-0.6766858208553077
575.7000000000074,62.91876134230094,0.2953792883213654,-0.680584212608184
576.8000000000075,63.02763974328015,0.2908408295012077,-0.6828999027466987
577.9000000000075,63.13644863158898,0.2855232995997855,-0.680110859657411
579.0000000000075,63.24612766174189,0.2828406076370721,-0.6777883385351178
580.1000000000075,63.354830736251806,0.2783682853395396,-0.6764968375848568
581.2000000000075,63.464501658387476,0.27694790252267587,-0.6761479321907826
582.3000000000076,63.57124578188818,0.27629142791466066,-0.6751612309178645
583.4000000000076,63.68297125603354,0.278856396221837,-0.6764804443850236
584.5000000000076,63.79201652931165,0.2775747041523885,-0.6764799248598705
585.6000000000076,63.901590601934345,0.27698731078500416,-0.6777960437793222
586.7000000000077,64.01104050784883,0.27507454290095434,-0.6768752260386242
587.8000000000077,64.11987783451984,0.2752085933800008,-0.6778018398995114
588.9000000000076,64.23073853185423,0.2766324041469925,-0.6784501838360866
590.0000000000076,64.33938119353016,0.2765436212353981,-0.6797770782443529
591.1000000000076,64.4490527202005,0.27901327383254915,-0.679433234410693
592.2000000000077,64.55761102889417,0.2798092549733473,-0.6787173588215998
593.3000000000077,64.66720587959024,0.280701761394617,-0.6801121031468909
594.4000000000077,64.77700188581983,0.2826343088347548,-0.6814100611902831
595.5000000000077,64.88598260735299,0.28467612174021606,-0.6827636299869053
596.6000000000078,64.99443914043702,0.28971381409091634,-0.6831299835040068
597.7000000000078,65.10481227864899,0.2932940916046711,-0.683210602403038
598.8000000000078,65.21427596894374,0.29641441641250976,-0.6837199900116362
599.9000000000078,65.32373893802175,0.2988065849859496,-0.6842738207679302
601.0000000000078,65.43250852441933,0.30568483905423094,-0.6838939343519117
602.1000000000079,65.54197993428143,0.30729130686139916,-0.6850399604305815
603.2000000000079,65.65195962033587,0.314862193643213,-0.687666425604557
604.3000000000079,65.7602193802679,0.3153992933016234,-0.6872144619477041
605.4000000000078,65.87010873571471,0.3215781876643735,-0.6877899305713742
606.5000000000078,65.97886984003273,0.32612884402802533,-0.6891106411759669
607.6000000000079,66.08814373731158,0.33135335320556136,-0.6917154555398013
608.7000000000079,66.19742633689782,0.33231260097746207,-0.6917419497928456
609.8000000000079,66.3064560947606,0.3381606734753031,-0.691751974867409
610.9000000000079,66.4165946245854,0.3437726938673136,-0.6917405584637488
612.000000000008,66.5254853711688,0.34859301497667916,-0.6943754076904067
613.100000000008,66.63422365159438,0.3529306953849648,-0.6943713704241792
614.200000000008,66.74469562883334,0.3576635554252806,-0.6956901557608042
615.300000000008,66.85357571159668,0.3660028170704257,-0.6959160480114686
616.400000000008,66.96343454907452,0.37224453597219154,-0.6983370428749618
617.5000000000081,67.07200574311038,0.3811585945334711,-0.6996087352590492
618.6000000000081,67.17886711354745,0.3905116410963395,-0.700959969519845
619.7000000000081,67.29091342308708,0.39856602749726633,-0.700903282920363
620.8000000000081,67.40034440924319,0.4049037767078978,-0.7028108288346777
621.9000000000082,67.50975564420877,0.41440647149948295,-0.7042959641461048
623.0000000000082,67.61907367648242,0.42139860598183565,-0.7072195733115789
624.1000000000081,67.72907445094825,0.42914952066918566,-0.7072101728899485
625.2000000000081,67.83796366258122,0.4392318412101742,-0.7085295206559228
626.3000000000081,67.9475794042586,0.4483983652579908,-0.7100801707097113
627.4000000000082,68.05751978795017,0.4563505371681541,-0.7121614867173478
628.5000000000082,68.16742683401236,0.4636930340350488,-0.7134157328943065
629.6000000000082,68.27631274812813,0.47225398642905403,-0.7161209279031615
630.7000000000082,68.38489830163121,0.48151099391934515,-0.7174152088370516
631.8000000000083,68.4954449658071,0.49010555794401567,-0.7181436685667606
632.9000000000083,68.60580621888549,0.5003313379731288,-0.7201734387495504
634.0000000000083,68.71550935760338,0.5081680736008567,-0.7234651972271284
635.1000000000083,68.82461926822947,0.5190644767235615,-0.725311348025897
636.2000000000083,68.93490255431293,0.5283817793611433,-0.7269807117869669
637.3000000000084,69.04545700204564,0.539695163089335,-0.7290936746523409
638.4000000000084,69.15307918684873,0.5523608097319739,-0.7314994800820971
639.5000000000084,69.26482484252782,0.5662584715148329,-0.7350953852476172
640.6000000000083,69.37501936265205,0.5791430744763757,-0.7379438519651011
641.7000000000083,69.484554541284,0.5890309254233174,-0.7409221684308207
642.8000000000084,69.59409567641326,0.5986527890968973,-0.7437198037087027
643.9000000000084,69.7039503949796,0.6093114620099851,-0.746607452877547
645.0000000000084,69.81431586317616,0.6210871935600915,-0.7492881038278183
646.1000000000084,69.92436582226556,0.6313459296202633,-0.7512193920147405
647.2000000000085,70.03389215255287,0.6435991379961894,-0.7544840404315347
648.3000000000085,70.14307133025927,0.6594039697869712,-0.7567887799784896
649.4000000000085,70.25301113708419,0.6706724186921929,-0.7595089272043527
650.5000000000085,70.36270218107653,0.6833317630760789,-0.7634336333766614
651.6000000000085,70.47393525803913,0.6971134375078858,-0.7661702580969592
652.7000000000086,70.5832104802,0.7124840803187424,-0.7703199726939185
653.8000000000086,70.69317839611486,0.7245622720144569,-0.7730333267962548
654.9000000000086,70.80321362303802,0.7397071940723864,-0.7766408355451131
656.0000000000086,70.91285716239435,0.7534883598018179,-0.7810110592782022
657.1000000000087,71.02294981966479,0.7714086013395323,-0.7847246076677052
658.2000000000087,71.1325648875358,0.78640661532265,-0.7876065803154693
659.3000000000086,71.24216764607105,0.8055348694926545,-0.7921391850723549
660.4000000000086,71.35002167721277,0.8249458701730067,-0.7964520678449496
661.5000000000086,71.46227403324954,0.8431375727638766,-0.8006812563799599
662.6000000000087,71.57214129724846,0.8581094226221927,-0.8037794864578434
663.7000000000087,71.68106415394028,0.8730214172743221,-0.8081579865648081
664.8000000000087,71.7919192282231,0.8962552139808532,-0.814373259284825
665.9000000000087,71.90097842069788,0.9145921744666036,-0.8183310191223185
667.0000000000088,72.01174654309966,0.9323793871534289,-0.822142186845285
668.1000000000088,72.12094671396723,0.9516626805152344,-0.8285818289902918
669.2000000000088,72.22866513702797,0.9705970587601935,-0.8322397419324017
670.3000000000088,72.34147958330408,0.9923606110025941,-0.8387791288404758
671.4000000000088,72.45091261529387,1.0133473025758455,-0.8446145587212284
672.5000000000089,72.5607216258674,1.0338791111712131,-0.8497138754876188
673.6000000000089,72.67098530200455,1.054101842019472,-0.855626990615757
674.7000000000089,72.78072414701471,1.0740549782470794,-0.8605859648480507
675.8000000000088,72.89026262418037,1.0955716210556588,-0.8684156570570924
676.9000000000088,73.00132216901643,1.1196526287869837,-0.8736804517127927
678.0000000000089,73.11180490028987,1.1410563405876961,-0.8761745074379332
679.1000000000089,73.2210434358958,1.1662599104574998,-0.8843499503490846
680.2000000000089,73.3319739244527,1.1892135950222007,-0.8912894762900674
681.3000000000089,73.44156647788321,1.2143743716731246,-0.8988460348484462
682.400000000009,73.55236328159131,1.2403483717571888,-0.9062003389145361
683.500000000009,73.66264595657842,1.2707336817488786,-0.9130046310449123
684.600000000009,73.77244151461555,1.2956397730649456,-0.9202679442033306
685.700000000009,73.8827422521648,1.3211942699246166,-0.9286009491551845
686.800000000009,73.99283868695368,1.3490012001647331,-0.9365142245049016
687.9000000000091,74.10311400157984,1.3793891466392103,-0.9445355936850586
689.0000000000091,74.21265748188242,1.4053458934693852,-0.9518149648761551
690.1000000000091,74.32310588879749,1.439608979152,-0.9618958522958891
691.2000000000091,74.43349706626498,1.4678817888060294,-0.9692917379003116
692.3000000000092,74.54395280972633,1.494617210937259,-0.9798382441307179
693.4000000000092,74.65340749990939,1.5267911400047918,-0.9882520273401738
694.5000000000091,74.76448621254585,1.5586415413035586,-0.9969815712024919
695.6000000000091,74.87444129363878,1.5920580894561296,-1.0053621304745692
696.7000000000091,74.98509656904797,1.6213214673755,-1.0152800532258874
697.8000000000092,75.09424248724049,1.6521452605870453,-1.0252730946391653
698.9000000000092,75.20499429742536,1.6845787246221615,-1.0353058763530276
700.0000000000092,75.31505304715868,1.7147419348871382,-1.045938269952409
701.1000000000092,75.42493713398439,1.7420191818418322,-1.0556079398673996
702.2000000000093,75.53582047423902,1.769254340986437,-1.066561306706507
703.3000000000093,75.64572728327435,1.8001932014926016,-1.0774884758558945
704.4000000000093,75.75538298593722,1.8246824989066384,-1.0865495536556358
705.5000000000093,75.86511731126872,1.8491517625064522,-1.0981997621218849
706.6000000000093,75.97530874456046,1.8757526438408552,-1.1099498755681898
707.7000000000094,76.08554294175352,1.8930401531820173,-1.1221126223900302
708.8000000000094,76.19394400616532,1.9176832696788684,-1.133571381001461
709.9000000000094,76.30612801591083,1.928101465460979,-1.1448217392173246
711.0000000000093,76.41692193170148,1.9375251073627606,-1.156505526047015
712.1000000000093,76.52718241675663,1.9342843311428024,-1.1692880399253234
713.2000000000094,76.63699289050946,1.9324553933183497,-1.180039444819084
714.3000000000094,76.74711020544464,1.922875170593969,-1.19078488709432
715.4000000000094,76.8565123747847,1.9056302485954237,-1.2014847895192236
716.5000000000094,76.96656749847695,1.8775543174471907,-1.214136818289425
717.6000000000095,77.07767449917247,1.8379306188578899,-1.2178520359092078
718.7000000000095,77.18625045959577,1.7884960263551033,-1.2361755511786479
719.8000000000095,77.29789275272441,1.714117681131742,-1.2442663327945347
720.9000000000095,77.40744329682414,1.6118282646647741,-1.2520366269566336
722.0000000000095,77.51848299819451,1.4531321815239129,-1.2617069662855247
723.1000000000096,77.62647665361817,1.203315190078817,-1.2680900351547044
724.2000000000096,77.73803744816041,0.8297694500548782,-1.2752621325271938
725.3000000000096,77.84730353192334,0.563504259276893,-1.2784538332085438
726.4000000000096,77.95718901962053,0.4308176357134559,-1.2782623840294125
727.5000000000097,78.06741690954311,0.3783065305090011,-1.2777618681240348
728.6000000000097,78.17732115414316,0.34816592690946213,-1.2779467807562668
729.7000000000096,78.28779986755976,0.33560773920166254,-1.2797347561186312
730.8000000000096,78.39804674027597,0.33123855705219396,-1.2804072390578942
731.9000000000096,78.50841652784419,0.32085635597144857,-1.281708389363911
733.0000000000097,78.61830299623071,0.32119644348419907,-1.280488418608856
734.1000000000097,78.72906787184537,0.31737777086016283,-1.2820394552712013
735.2000000000097,78.83916898226941,0.31796232522562495,-1.2820400200069324
736.3000000000097,78.94948697113148,0.31169321359671875,-1.2820252864862107
737.4000000000098,79.05970151225627,0.30578824630407775,-1.2817344960866022
738.5000000000098,79.17010535352503,0.3054619181780527,-1.2823700372756295
739.6000000000098,79.28002088153414,0.3034337692726158,-1.2833405077993234
740.7000000000098,79.38996476854267,0.30162243168936675,-1.2833604228674065
741.8000000000098,79.50076626431114,0.30175701310612146,-1.2849309211270006
742.9000000000099,79.61158398463452,0.2963739390313235,-1.286210525522001
744.0000000000099,79.72150495077221,0.29774825917741976,-1.2835707318656469
745.1000000000099,79.83129499959654,0.2891158136683586,-1.284970552907983
746.0000000000099,79.92134661058203,0.28330038661667845,-1.2862087010732872