File: 01_Data/Asphalt_Shingle/STA/N2/10K_min/Asphalt_Shingle_STA_N2_10KData_220916_R2.csv
##Temp./Â°C,Time/min,DSC/(mW/mg),Mass loss/mg
51.0,10.837866209573054,0.043921049377237065,0.021896614145812343
52.100000000000016,11.176875279542708,0.06953181977202005,0.02107294856468034
53.20000000000003,11.415604534393308,0.08825746238844001,0.019512951157235392
54.30000000000005,11.621064931930645,0.10453957496406296,0.020736612731150572
55.40000000000006,11.806285981908534,0.11604609303419466,0.021539798283618516
56.50000000000008,11.975274847657055,0.125841651197093,0.020098258979765582
57.600000000000094,12.138207771269954,0.13172704485548037,0.019501746194046987
58.70000000000011,12.292475579672217,0.14104188624271363,0.020109226401091362
59.800000000000125,12.441771667408897,0.1440394560216427,0.020108551959901355
60.90000000000014,12.587335865374463,0.15021369985410948,0.01988638687402755
62.000000000000156,12.728469767915605,0.154041663940798,0.018962146165096172
63.10000000000017,12.87052098697095,0.15838065216769626,0.01925221481314221
64.20000000000019,13.00742544068568,0.1641202726743849,0.021869756364958803
65.30000000000021,13.140328933862598,0.16687586831359202,0.020759276185659203
66.40000000000022,13.27316275439043,0.16750547002909122,0.02032705855433825
67.50000000000023,13.404359250199947,0.17112133152559372,0.020702523808830975
68.60000000000025,13.533530895608715,0.17433142973211013,0.020740597234136793
69.70000000000027,13.660714705362514,0.17718438639717937,0.020807331725515965
70.80000000000028,13.786216971760389,0.17831035080500968,0.021400678620994817
71.90000000000029,13.912727968821295,0.18330917367322286,0.021182359521199068
73.00000000000031,14.038003056231979,0.184463783300149,0.021367617014968587
74.10000000000034,14.16014228553344,0.18759349583333673,0.02096399498104784
75.20000000000034,14.285097445644201,0.18953506589226543,0.020981002031784435
76.30000000000035,14.405723721198182,0.19167772142823813,0.020533164319739505
77.40000000000038,14.526466264241343,0.19235688304887955,0.020972486438981974
78.5000000000004,14.646495695786479,0.19498487505026274,0.021447685570809227
79.6000000000004,14.765036450666,0.19719571883825693,0.021514783022166917
80.70000000000041,14.882465790518467,0.19919911311730587,0.022420123573851924
81.80000000000044,14.99970690671765,0.200371436398604,0.021592434945340244
82.90000000000046,15.117654540503613,0.20313735846429726,0.021693786540447846
84.00000000000047,15.232396962379273,0.20235092924409348,0.02269366258240524
85.10000000000048,15.347609000981087,0.20373164645414055,0.021761526952755794
86.2000000000005,15.461563026522677,0.2062371987497993,0.022850817642263266
87.30000000000052,15.577648461714361,0.2074240670208225,0.021525895763605085
88.40000000000053,15.69125328110855,0.2087279163361564,0.02150669551084139
89.50000000000054,15.804667050133448,0.209352265736666,0.022840981945778438
90.60000000000056,15.91422498263095,0.21148057612552518,0.02265211136444556
91.70000000000059,16.029684960132137,0.2114932804240488,0.022491833595362998
92.8000000000006,16.141108437335564,0.21373466527442542,0.02162063723047325
93.9000000000006,16.253358892858227,0.21387031517980537,0.02299042390777739
95.00000000000063,16.363910719621067,0.21483123489158307,0.022840237917405304
96.10000000000065,16.47527891547818,0.2181594200703778,0.0228383711372242
97.20000000000066,16.584992037342904,0.21838796959093498,0.022904142806838834
98.30000000000067,16.692222349485707,0.2184096330225258,0.02169293546781237
99.40000000000069,16.803785710561975,0.22144921436137666,0.02152060589043714
100.50000000000071,16.91182043403029,0.2224919849404734,0.020090985065984057
101.60000000000072,17.022133506325666,0.22190872103719972,0.021075896795698768
102.70000000000073,17.12978868269219,0.22312022830823608,0.0227301806953486
103.80000000000075,17.239096678864513,0.2239050920954888,0.022706894945287992
104.90000000000077,17.346898399392416,0.22536118438747255,0.022768381963288675
106.00000000000078,17.455972538730045,0.22588036144425572,0.021735204883524872
107.10000000000079,17.563717325196635,0.22555162495685477,0.021409468291680334
108.20000000000081,17.673783725317325,0.2270984228051629,0.02152020520604747
109.30000000000084,17.780549751058306,0.22619940787219406,0.02283868271495848
110.40000000000084,17.888641698608392,0.22965965492581852,0.02132438361841249
111.50000000000085,17.996592480630635,0.23020933126699172,0.021972639945093242
112.60000000000088,18.102911042327765,0.23078969128527027,0.0215193670264604
113.7000000000009,18.211452225804308,0.2301531611041332,0.02151992449182316
114.8000000000009,18.318920559625415,0.2311118066092679,0.022852061237689014
115.90000000000092,18.425836555702823,0.23095096462022768,0.022077959927714552
117.00000000000094,18.530468452127288,0.23226822131662006,0.021742396276931863
118.10000000000096,18.63981992462535,0.2336097118877093,0.022823926749857115
119.20000000000097,18.748259471481575,0.23345867855227087,0.021426022521613852
120.30000000000098,18.855680359036167,0.23369971634926923,0.021520144961245435
121.400000000001,18.963874907790782,0.23405721123251477,0.022753972061423156
122.50000000000102,19.06869712067557,0.23417839880082225,0.022188490324153598
123.60000000000103,19.17553166391845,0.23805530613971482,0.021526216179589497
124.70000000000104,19.28205671952528,0.23827199535983146,0.02283726924115559
125.80000000000106,19.38898252590428,0.237745542107348,0.021520171929069853
126.90000000000109,19.495242162694012,0.23756304848568255,0.022843446788774813
128.00000000000108,19.601977828986886,0.24102985620725792,0.021523346226532958
129.1000000000011,19.707127430089425,0.24118087609091732,0.02153022456269671
130.20000000000113,19.814068464448262,0.2433032188503247,0.022528688670274022
131.30000000000115,19.920404120726126,0.24011538105637908,0.021849881850379838
132.40000000000117,20.026811714590508,0.24111842534286798,0.020789962097603976
133.50000000000117,20.132308130131772,0.24138390827392464,0.021519964571524497
134.6000000000012,20.238845233146375,0.2421013002725858,0.021517806466024858
135.7000000000012,20.344241379512948,0.24195494185580058,0.02150848557610452
136.8000000000012,20.449734362168535,0.24453350679309127,0.021532355674835024
137.90000000000123,20.555063999768137,0.24414500731269428,0.021479949122294784
139.00000000000125,20.661487443070087,0.2453949236866867,0.021520139568619534
140.10000000000127,20.76603638184299,0.24512948062879425,0.02053248708038069
141.2000000000013,20.872861124519883,0.2450636569020771,0.020143668652170987
142.3000000000013,20.978006092180117,0.2455844204806361,0.020874513320499943
143.4000000000013,21.082038415816537,0.2483317419922526,0.020210756180423672
144.50000000000134,21.18766958877678,0.2450267787502397,0.020211429622102983
145.60000000000133,21.292700096266163,0.24803539420516896,0.021559693174523886
146.70000000000135,21.39714030870163,0.24950969166525094,0.020208524584464982
147.80000000000138,21.50290499935243,0.2487747027647238,0.021519795179227863
148.9000000000014,21.607930068149642,0.24908381698807058,0.021564169706859815
150.00000000000142,21.710469648878483,0.24992237870692102,0.02152005250205047
151.10000000000142,21.81751818042825,0.2524530153125639,0.02020980284552465
152.20000000000144,21.922148677186687,0.25340913853065594,0.021520367229932447
153.30000000000146,22.025864879815657,0.252917944121955,0.022925095839317677
154.40000000000146,22.13148764658101,0.25364314845914526,0.020797670472984642
155.50000000000148,22.232381821720168,0.2532839026234247,0.02020998031368837
156.6000000000015,22.338597635479307,0.25505594179980606,0.020211372031266883
157.70000000000152,22.444251220619186,0.25544255560559337,0.02019424492547639
158.80000000000155,22.550269641035584,0.2580209745615988,0.020202553518913646
159.90000000000154,22.654545445627136,0.2580260424978231,0.01940909345242936
161.00000000000156,22.758750058395453,0.2573921819671299,0.020200093110754658
162.1000000000016,22.862044211321997,0.257797512028898,0.021519943453855106
163.20000000000158,22.96724926110836,0.2581409992290209,0.021506364592942084
164.3000000000016,23.071288068827354,0.2603615040586864,0.020210184259526365
165.40000000000163,23.174597303890383,0.25950914368408795,0.02029864118071778
166.50000000000165,23.280800117289825,0.2618913914710129,0.020200164275925303
167.60000000000167,23.38471801896419,0.2617077635346724,0.019749661453461798
168.70000000000167,23.490000000000155,0.2642200475837013,0.019539831978462097
169.8000000000017,23.5945720213525,0.26527715176509037,0.021234145242670976
170.9000000000017,23.699245497109747,0.2645056323728291,0.02021008947027525
172.0000000000017,23.801718499677456,0.2662394212328071,0.018895301604199943
173.10000000000173,23.90779411278476,0.26646526222836064,0.02020985829412325
174.20000000000175,24.012228137770794,0.2649594219768119,0.01924121943937873
175.30000000000177,24.117243034118854,0.26602689462863904,0.018889850053522395
176.4000000000018,24.22204307695702,0.266190293163342,0.018889857890050266
177.5000000000018,24.326417135138417,0.2694698691636246,0.018217989616021057
178.6000000000018,24.43109782995261,0.2695581866074678,0.01887995962894795
179.70000000000184,24.53542713699902,0.27260704959188453,0.01882136139225654
180.80000000000183,24.64039712289684,0.27314641767807735,0.01812013615924446
181.90000000000185,24.74524930779316,0.27455901021729334,0.018144737393410715
183.00000000000188,24.848968922707535,0.27282720928718895,0.01746013598212315
184.1000000000019,24.95368687440107,0.27595026540360346,0.018860763070686737
185.20000000000192,25.058952648881498,0.27487939790235916,0.018779902027661777
186.30000000000192,25.163320135081044,0.27860904013966836,0.018781943059643424
187.40000000000194,25.267777131872695,0.2772527406250104,0.017637881974735592
188.50000000000196,25.372233284550294,0.2806698374708132,0.017396847328878806
189.60000000000196,25.475304000879632,0.28024338792080716,0.017425019536142727
190.70000000000198,25.580580780369353,0.2814899726399057,0.017460070003583184
191.800000000002,25.684341459836567,0.28146264131877163,0.017449240576849157
192.90000000000202,25.788842924550032,0.28079883778481896,0.016150129912189115
194.00000000000205,25.89331651281751,0.2818487110089638,0.017460068794970418
195.10000000000204,25.998035251361824,0.2826123975719925,0.017468001441073966
196.20000000000206,26.10105706332252,0.28335013772938955,0.017134396523855955
197.3000000000021,26.204860580813182,0.2855680566292661,0.01713106192409164
198.40000000000208,26.310580667992177,0.28813109886163324,0.01680001433597411
199.5000000000021,26.41497495357379,0.2869803574528901,0.016799972095576265
200.60000000000213,26.51929148052472,0.2872498222249281,0.01613869693581549
201.70000000000215,26.62295847462862,0.2887689166572637,0.014821503544608206
202.80000000000217,26.72666828965135,0.28981653779753136,0.015004687872840705
203.90000000000217,26.830193572112442,0.2899533947573899,0.016029285019889095
205.0000000000022,26.932748431611483,0.2923350074381186,0.014004312619614545
206.1000000000022,27.039806216513906,0.2937702151889032,0.014058934764078934
207.2000000000022,27.142880329130218,0.2928632488974532,0.015379802896857697
208.30000000000223,27.248797641610903,0.29338152878067114,0.01538526005204055
209.40000000000225,27.353181201984338,0.2955229819382701,0.01405973859798948
210.50000000000227,27.45660881677779,0.29585192754551426,0.0127393218698435
211.6000000000023,27.560277722621464,0.2956181572109394,0.01273980400007435
212.7000000000023,27.664318809695807,0.2969676101492702,0.012739804085031281
213.8000000000023,27.769421844322274,0.2977239808366515,0.01277882396840635
214.90000000000234,27.87286703098513,0.29854226805355477,0.011419803999225486
216.00000000000233,27.97905612878554,0.2978614825253828,0.011419803990015964
217.10000000000235,28.082327075903645,0.2988748588624277,0.011422696545425381
218.20000000000238,28.18625932970396,0.29880192974466124,0.010440498672171117
219.3000000000024,28.290924689051366,0.29978920351404914,0.011099876103896733
220.40000000000242,28.39626025539654,0.3012202858441818,0.010741358317508443
221.50000000000242,28.498761092316485,0.300554847025175,0.009448857510332864
222.60000000000244,28.60462756546272,0.3017311303318744,0.008798811393813999
223.70000000000246,28.708531730743047,0.30422763884281256,0.009449822720597467
224.80000000000246,28.813683216480865,0.30201006421920906,0.008344370027299597
225.90000000000248,28.918525122744054,0.3029976172601109,0.005424697084221108
227.0000000000025,29.022083809332653,0.30459042876604836,0.008129880295888903
228.10000000000252,29.127059337048188,0.30369917346153263,0.00812988955412397
229.20000000000255,29.231104552499108,0.30525027483763967,0.006815900566854438
230.30000000000254,29.336439219761637,0.30480639023351186,0.006360811734392513
231.40000000000256,29.440447997484178,0.30561088446448426,0.005833213395615822
232.5000000000026,29.545336388513302,0.3068663043958061,0.005500281550158803
233.60000000000258,29.6509006120118,0.3069415259637781,0.004180321166638912
234.7000000000026,29.75450997740991,0.3071606964730016,0.004180121975816853
235.80000000000263,29.858828299866882,0.30678151223381067,0.004046703899272863
236.90000000000265,29.964595176455735,0.30826722846038257,0.002202038246384319
238.00000000000267,30.06899637237929,0.3095388686469551,0.0015399607403026039
239.10000000000267,30.174080928726035,0.3090876393183475,0.0015399540349294583
240.2000000000027,30.278097554503166,0.3098472912286263,0.0016017514636272878
241.3000000000027,30.381292791908567,0.3094816902223957,-0.0010996721456066894
242.4000000000027,30.48807136268048,0.31021919226135375,-0.0010998220474967013
243.50000000000273,30.592993039128334,0.31121965821092656,-0.002409811999999789
244.60000000000275,30.69745446967123,0.3121859672184202,-0.002409811999925182
245.70000000000277,30.802164794220463,0.3135069655916122,-0.0024087903529927956
246.8000000000028,30.906247630765158,0.31325167753701955,-0.0026441179651151003
247.9000000000028,31.010726088532998,0.31368020288834253,-0.004709929313211347
249.0000000000028,31.11568083333615,0.3134986768879048,-0.005990313239288447
250.10000000000284,31.220788199892667,0.3148596428115259,-0.006030098001997608
251.20000000000283,31.324428757893063,0.31505602283532963,-0.006030315085171267
252.30000000000285,31.428547962618012,0.31598565493002473,-0.006414515772605434
253.40000000000288,31.53338223086373,0.316782604084204,-0.009039482389626485
254.5000000000029,31.638840423608592,0.3157952728552237,-0.008999864153910409
255.60000000000292,31.74416298535163,0.3173208967215184,-0.009421743975814856
256.7000000000029,31.848783085901157,0.317272717500271,-0.011641542215411249
257.8000000000029,31.95275968779874,0.3188584879814865,-0.011640397088779508
258.90000000000293,32.05751622191779,0.31988238217197196,-0.012946961111893529
260.00000000000296,32.16299725486484,0.3215539025642712,-0.014260142694173972
261.100000000003,32.26692803895476,0.3224649573175654,-0.014259307252604714
262.200000000003,32.37149443730361,0.3247387998631065,-0.015579933750495378
263.300000000003,32.47556436336692,0.32458769970477486,-0.015579387771820663
264.40000000000305,32.58027799302551,0.32644712702401646,-0.016900084213540723
265.50000000000307,32.68511147841375,0.3255767091768953,-0.01685095519914004
266.6000000000031,32.791283783798036,0.32644182314127423,-0.019540998103247276
267.7000000000031,32.89463662423374,0.3271280335072547,-0.02084985396113659
268.8000000000031,32.99989629536776,0.3285064133006632,-0.021174138771146378
269.9000000000031,33.10440092337992,0.3297968050796043,-0.023493045844350302
271.0000000000031,33.209311201630555,0.33029538165474204,-0.024106373936579217
272.10000000000315,33.31403308199385,0.3299635194672853,-0.025470195869141232
273.2000000000032,33.418813567729146,0.33212695161153694,-0.026772932731947918
274.30000000000314,33.5230329514175,0.331929275689299,-0.028117622005444876
275.40000000000316,33.62755555517221,0.33361469854962333,-0.029313261140438307
276.5000000000032,33.73295576208817,0.33255890694673707,-0.030729954683212046
277.6000000000032,33.83796492690112,0.33533291060260106,-0.031527888535086035
278.70000000000323,33.94309546771997,0.3358457161511621,-0.03203477455550452
279.80000000000325,34.04734269404519,0.33619911218914045,-0.034680115211481954
280.9000000000033,34.15173432631235,0.3355003201272285,-0.036004875682842385
282.0000000000033,34.25698976253052,0.3358483196753501,-0.036024696979148896
283.1000000000033,34.36232319957265,0.3377937729624002,-0.03680816810850285
284.20000000000334,34.46704562986866,0.33811123357909845,-0.037283804811768295
285.30000000000337,34.57154745825738,0.33672063162145094,-0.04030118683227135
286.40000000000333,34.67683603156854,0.3363941675778098,-0.04160537932708763
287.50000000000335,34.78208605102126,0.3396899601504655,-0.041614693557648685
288.6000000000034,34.88642170448443,0.34076992629699887,-0.04423099397806807
289.7000000000034,34.99250686014186,0.34056903519859594,-0.0465399020906645
290.8000000000034,35.097580278595224,0.3418069050020216,-0.04656644812201671
291.9000000000034,35.200453940929116,0.3402092626033322,-0.047860491900014956
293.0000000000034,35.308164216620995,0.3416842337042403,-0.049512080938559855
294.10000000000343,35.4140149012858,0.34149725855807367,-0.051668410962795175
295.20000000000346,35.51858629356157,0.34271957336814385,-0.05345945250268391
296.3000000000035,35.624197500912004,0.34035438528196904,-0.054447409659819535
297.4000000000035,35.7293264484013,0.34298354562718836,-0.05577487924830127
298.5000000000035,35.83493389279581,0.34245116062998615,-0.05708996637220176
299.60000000000355,35.93980940564881,0.3430421506523782,-0.05975303872087867
300.70000000000357,36.045401341526485,0.34406804351113207,-0.060613831005430274
301.8000000000036,36.15040171183552,0.3452251951774402,-0.0623499690567173
302.9000000000036,36.25664836235066,0.34448325213108133,-0.06366381895085649
304.0000000000036,36.36187517007815,0.3447303150757657,-0.06498532017916814
305.1000000000036,36.46548103894962,0.34427581694543974,-0.06631464390392772
306.2000000000036,36.57245697830688,0.34552996801428004,-0.06904231778313497
307.30000000000365,36.67860946234801,0.3460926724105785,-0.07125604873736169
308.4000000000037,36.78363111093685,0.3453679737344161,-0.07287105272052807
309.5000000000037,36.8898936715747,0.3469652012503226,-0.07420997324670964
310.60000000000366,36.995111238020016,0.3464561693621101,-0.07417119632077629
311.7000000000037,37.10054210868717,0.35030218388577916,-0.07688775309776297
312.8000000000037,37.20600309225459,0.350734306336027,-0.07914992261240039
313.90000000000373,37.31111948627205,0.3511155298293378,-0.08054729032372743
315.00000000000375,37.414842830519675,0.35067327530199466,-0.08179432917415896
316.1000000000038,37.52247873473961,0.35213136751165397,-0.08426250836363547
317.2000000000038,37.62728036652501,0.352636758095041,-0.08540946587282283
318.3000000000038,37.734044885957566,0.35211614355828236,-0.08637776545331288
319.40000000000384,37.839380910993654,0.3543577226910424,-0.08903052340592721
320.5000000000038,37.94437551855688,0.35402520187053066,-0.09137263051875077
321.60000000000383,38.051157940974974,0.35495979780306286,-0.09331316136417112
322.70000000000385,38.15688211672847,0.35584985144600223,-0.09594385079625845
323.8000000000039,38.26150439016917,0.35541185165327605,-0.09673234499687045
324.9000000000039,38.36816157298081,0.35720206785529385,-0.09858271276469299
326.0000000000039,38.47431489288344,0.3572120708468718,-0.1008922281975666
327.10000000000394,38.5793215539389,0.35997582203467915,-0.10314117327832006
328.2000000000039,38.6849111150044,0.35930000046219146,-0.10490036550500648
329.30000000000393,38.79141304175134,0.35943765584492604,-0.10612943951071685
330.40000000000396,38.89847650927585,0.3617963287056021,-0.10865868917550925
331.500000000004,39.0035986929842,0.3628501755043405,-0.11044228745348983
332.600000000004,39.110092220645186,0.3618991378101518,-0.11361814788906832
333.700000000004,39.215819106280364,0.3625778282445239,-0.11532242732986031
334.80000000000405,39.32162983687173,0.36200432864109444,-0.1178124170723045
335.90000000000407,39.42806151978668,0.36278390442175257,-0.12078252107809773
337.0000000000041,39.53448234695816,0.3615599303820448,-0.12231864995840525
338.10000000000406,39.6410068862472,0.3649968233607943,-0.12361182555500294
339.2000000000041,39.74530439421686,0.36730572448614907,-0.12587152823032488
340.3000000000041,39.8520517894972,0.36715802014903287,-0.12755563626421473
341.4000000000041,39.9580116319283,0.3678460277104202,-0.13118905816039383
342.50000000000415,40.06450503144968,0.3664965170376856,-0.13250287944011907
343.6000000000042,40.169998988410086,0.3684671441432308,-0.13513929876969843
344.7000000000042,40.27588981197744,0.36741414345801304,-0.13614575875543622
345.80000000000416,40.38319305937544,0.36793885004137483,-0.13873555597779053
346.9000000000042,40.488549523377706,0.3695148366390688,-0.1406211183643684
348.0000000000042,40.59407605491939,0.3693095827953605,-0.14270879854320428
349.10000000000423,40.69950512005046,0.3701085152700081,-0.14403706806426575
350.20000000000425,40.807195176828486,0.3701651852282737,-0.14840917406515697
351.3000000000043,40.9136169104762,0.3716025132312232,-0.15060414929685173
352.4000000000043,41.01914119146478,0.37101397190657326,-0.15227706394417106
353.5000000000043,41.125579526300726,0.37020352090258846,-0.15360943884329803
354.60000000000434,41.23169685409749,0.3699558462032234,-0.15753360219476065
355.7000000000043,41.33722776333788,0.3711947123316426,-0.16017311892414332
356.80000000000433,41.444432118578305,0.37163932756306406,-0.16294694463858583
357.90000000000435,41.55031850229622,0.37068687887996266,-0.16411635427272797
359.0000000000044,41.65714950179053,0.36987126599803577,-0.16690887130450438
360.1000000000044,41.76371139678235,0.37005692862765316,-0.16979676386812326
361.2000000000044,41.86821942493125,0.37038555948894103,-0.17180515746276637
362.30000000000445,41.97570102988455,0.3662276972423173,-0.17468829344153436
363.4000000000044,42.082900779019575,0.3654248175689869,-0.17608529275854012
364.50000000000443,42.18937257067377,0.366050526642532,-0.18002552497886937
365.60000000000446,42.2960288608844,0.36616482019978114,-0.18267109774605084
366.7000000000045,42.40241482087299,0.36699615097417226,-0.18410148727300824
367.8000000000045,42.50841048228265,0.3639735422372459,-0.1866485965917435
368.9000000000045,42.614775901800535,0.36251822950489965,-0.18931091379635445
370.00000000000455,42.72092889927648,0.3615880906225457,-0.1919269521990632
371.10000000000457,42.82765291091897,0.36240263791368066,-0.1945336311960899
372.2000000000046,42.933842917077904,0.3597984626337043,-0.1981225146769794
373.30000000000456,43.041889675735,0.3594084518319972,-0.2008772140447337
374.4000000000046,43.14510480545897,0.35929335225502723,-0.20278972119853078
375.5000000000046,43.25339187442327,0.362900704545728,-0.20552754939328732
376.6000000000046,43.36039594407456,0.36184190511263825,-0.2081456857266737
377.70000000000465,43.46643438727609,0.36098011765547566,-0.21078541026928566
378.8000000000047,43.572854820182144,0.36037375649923686,-0.21407127557492212
379.9000000000047,43.6797452339031,0.36061093934878996,-0.21692505419159014
381.00000000000466,43.78644841943586,0.3598987380235915,-0.2195582318206637
382.1000000000047,43.89312832430952,0.3610228023330869,-0.22344307587169077
383.2000000000047,44.00029851035928,0.3613124555987133,-0.22616414043843402
384.30000000000473,44.1070923704214,0.3598871208116924,-0.22885517069608285
385.40000000000475,44.212988485147285,0.36168742213710225,-0.2318136005656326
386.5000000000048,44.31849046407582,0.3618884167967106,-0.23469959309029864
387.6000000000048,44.4271704443779,0.36471704474003763,-0.23798896330235708
388.7000000000048,44.53386667687084,0.36593603241083905,-0.24082996346394614
389.80000000000484,44.64071471280632,0.36407938851369925,-0.24441467579894915
390.9000000000048,44.748586593495034,0.3635449478689524,-0.2484776300995435
392.00000000000483,44.85542095564462,0.3640804074545859,-0.2503463401831545
393.10000000000485,44.961542557669404,0.36412303992350925,-0.25459288261334656
394.2000000000049,45.06881811127178,0.3656279523597259,-0.25715681928492806
395.3000000000049,45.176347854888405,0.3674787082076818,-0.2620535540344795
396.4000000000049,45.283199750443465,0.3685840106649195,-0.26467957242737405
397.50000000000495,45.39017486661877,0.3680001825368493,-0.2668289748293686
398.6000000000049,45.495155157747305,0.37044920022853556,-0.2709098004050361
399.70000000000493,45.60313067616217,0.37070824538301916,-0.27362246644944843
400.80000000000496,45.710395882296446,0.37364456808670476,-0.2770024334943346
401.900000000005,45.81687214604058,0.37484712789834496,-0.2820922216804944
403.000000000005,45.9243851242272,0.375502059372267,-0.2860251699177243
404.100000000005,46.0322241019262,0.37730188697527356,-0.29047818898057853
405.20000000000505,46.13840627584365,0.37858293786705455,-0.29303169917792005
406.30000000000507,46.24473334649551,0.37834425337064914,-0.2969580098606426
407.4000000000051,46.35239942658974,0.3781114189095145,-0.3000360284154353
408.50000000000506,46.459822678726475,0.383397179822319,-0.30277110156364895
409.6000000000051,46.56470371527604,0.3820289735740011,-0.3069387725289512
410.7000000000051,46.67413242366562,0.3822493108018816,-0.3125464755322609
411.8000000000051,46.78104507769173,0.3824491045021148,-0.3161372233908093
412.90000000000515,46.887914946842166,0.38568589796839725,-0.32094109998225306
414.0000000000052,46.99422645454391,0.38630355941352534,-0.3249512003587651
415.1000000000052,47.10145821753463,0.38628579140131414,-0.32837672563331255
416.20000000000516,47.20823956663557,0.3870701499306979,-0.33289482584678387
417.3000000000052,47.31642924399208,0.38926161614312726,-0.3372904878745331
418.4000000000052,47.42426283930719,0.3918040272178023,-0.3410219545356572
419.50000000000523,47.529694741145065,0.392973362327946,-0.3431225147579271
420.60000000000525,47.63809148733789,0.395454799370738,-0.35043920117051464
421.7000000000053,47.744936578583584,0.396271293978244,-0.35550243743854626
422.8000000000053,47.8523074121583,0.3977002148688694,-0.3597923152782352
423.9000000000053,47.96010529874354,0.39967887805539404,-0.36337996686113083
425.00000000000534,48.0676938109235,0.40307448403264057,-0.3689768804488023
426.1000000000053,48.17499608533272,0.4026841433360244,-0.3729616142588661
427.20000000000533,48.28240172435698,0.4053284578433578,-0.37753136552552213
428.30000000000535,48.390000900441684,0.40749123934112774,-0.3845751458170583
429.4000000000054,48.49693718933484,0.4076198305003441,-0.3898570461098192
430.5000000000054,48.6034650431846,0.40786385795013913,-0.3948514161840069
431.6000000000054,48.71092697185755,0.4103648962673544,-0.39924462024743157
432.70000000000545,48.818308704778495,0.41302069471153957,-0.40296261483931906
433.8000000000054,48.925852980491776,0.4138544579462552,-0.41018559555688006
434.90000000000543,49.03338967573827,0.4151439559116157,-0.4143537000443356
436.00000000000546,49.13874623205622,0.4156572511878518,-0.4202194718440859
437.1000000000055,49.248687321918496,0.4188286714261238,-0.4252669965724931
438.2000000000055,49.355829386719655,0.42004050744827703,-0.4310753352455361
439.3000000000055,49.463627311084345,0.4224507553752789,-0.4371544980027595
440.40000000000555,49.57182987337274,0.42302898989025384,-0.4424128745761333
441.50000000000557,49.678889744540214,0.42336455662422057,-0.4471465123785001
442.6000000000056,49.78629914310982,0.4239779385407021,-0.4530950078510161
443.70000000000556,49.89422029113464,0.42624283597689994,-0.45939741213106844
444.8000000000056,50.00183899617124,0.4269791811321616,-0.4639121354840219
445.9000000000056,50.1100921511219,0.4283320158477948,-0.4709741285010298
447.0000000000056,50.216736879066225,0.43181812222335214,-0.47723274608816757
448.10000000000565,50.32561666206879,0.4330768365208506,-0.48202009307127947
449.2000000000057,50.43257313149822,0.4350425080672633,-0.48779865951447166
450.3000000000057,50.54068800145793,0.43822783815793886,-0.4942044591657453
451.40000000000566,50.64845904114151,0.43971606731420765,-0.4970022572657973
452.5000000000057,50.75607010746782,0.4398195889219605,-0.5032905586581791
453.6000000000057,50.86440937155152,0.44306058469954734,-0.5097629526511538
454.70000000000573,50.97210171833016,0.44235778229241374,-0.5151968978762853
455.80000000000575,51.079894693502915,0.4422363701858223,-0.5201407592909866
456.9000000000058,51.18722908300733,0.4415642645546717,-0.5262328649310168
458.0000000000058,51.29571618588798,0.4428961683772067,-0.5309978460381264
459.1000000000058,51.40176364133994,0.446032410275086,-0.5372792895451926
460.20000000000584,51.511141324421914,0.44762854680187225,-0.5415200988780065
461.3000000000058,51.61825262063977,0.4508297474845693,-0.5471368306806359
462.40000000000583,51.72565511405779,0.45011039070208436,-0.5504103438489638
463.50000000000585,51.83431668879949,0.4513589972302865,-0.5563421723790052
464.6000000000059,51.94285480451143,0.4512373300275574,-0.5597647566712944
465.7000000000059,52.05155676896771,0.4519278283278305,-0.5660305140272373
466.8000000000059,52.15880933891317,0.45144961126595806,-0.5703307216430686
467.90000000000595,52.266549420261015,0.45116178700793896,-0.5746939978422447
469.0000000000059,52.375070625833544,0.45211298071012285,-0.5784816615290977
470.10000000000593,52.48322434610276,0.4497347927587888,-0.5826315963689987
471.20000000000596,52.59105430890385,0.44815521153342575,-0.5855083968170085
472.300000000006,52.69943888155687,0.4479343633382308,-0.5883241007283915
473.400000000006,52.805451837116635,0.4478317326013077,-0.5920121321110972
474.500000000006,52.91554706718699,0.44777137159302494,-0.5951964316039309
475.60000000000605,53.0226355891949,0.4468213395395233,-0.5979787575312558
476.70000000000607,53.12999907914883,0.44501884303839745,-0.6002898425940635
477.8000000000061,53.23773159390331,0.4447112253798985,-0.6021010000973739
478.90000000000606,53.346689539163464,0.44231297243808865,-0.6044859569794294
480.0000000000061,53.45434396008803,0.441352609055204,-0.6079844532223855
481.1000000000061,53.56222198295062,0.4420668198601958,-0.6098396552793819
482.2000000000061,53.66955593634577,0.44172284402452866,-0.6104983297600839
483.30000000000615,53.77776354819441,0.439382392625391,-0.6117162081402201
484.4000000000062,53.885606910451614,0.4388994452936368,-0.6145663724619661
485.5000000000062,53.99327434132899,0.43724792208293217,-0.61726771582528
486.60000000000616,54.10180819819118,0.43731251893439227,-0.6197081410137928
487.7000000000062,54.210201169132375,0.4352972987560476,-0.6210446971351495
488.8000000000062,54.31801418895958,0.4347609794312053,-0.6210402434673599
489.90000000000623,54.42696586124989,0.43310301157609754,-0.6223582425241343
491.00000000000625,54.53494412344857,0.4333778373962677,-0.6227909190500625
492.1000000000063,54.64319359709856,0.43227423602673154,-0.6249900360197658
493.2000000000063,54.752370265396145,0.43083000887298206,-0.6263777360189522
494.3000000000063,54.86018140389943,0.43067259155138515,-0.6263154186286157
495.40000000000634,54.96807334330449,0.42935968875666763,-0.6276199329284884
496.5000000000063,55.07688708457615,0.4295477713259922,-0.628940499103678
497.60000000000633,55.185214913783355,0.4291875009070628,-0.6294285251812779
498.70000000000636,55.293518591905745,0.4293328638652676,-0.6302566499987705
499.8000000000064,55.40233415409147,0.4286748687401466,-0.631580069368662
500.9000000000064,55.509614145802956,0.429558827610238,-0.6328892368251746
502.0000000000064,55.61809705466229,0.4334337132015651,-0.6342031804799557
503.10000000000645,55.724125276911806,0.44175722799630546,-0.6342099600945148
504.2000000000064,55.8357081715891,0.44838324385258266,-0.6351218719195675
505.30000000000643,55.94351771583395,0.4485426021247787,-0.635530128187948
506.40000000000646,56.05132398809323,0.4538918537103409,-0.6355301449761086
507.5000000000065,56.160791539309564,0.4556039554104474,-0.636839484549883
508.6000000000065,56.269038939550285,0.4588871010936558,-0.6381570597308048
509.7000000000065,56.378152427917385,0.46391823353237904,-0.6391418993764151
510.80000000000655,56.48599984938855,0.4650956507048549,-0.6391501419596621
511.90000000000657,56.59533537692543,0.46537947341163666,-0.639482733414146
513.0000000000066,56.703127473666974,0.46724925280008167,-0.6394689738360873
514.1000000000065,56.81270698212139,0.4690040912598251,-0.640139912695048
515.2000000000066,56.92120726520222,0.46990459369900506,-0.6409034024163018
516.3000000000065,57.030001003188055,0.47350074107549844,-0.6419359474235153
517.4000000000067,57.13846015862388,0.4728853785086704,-0.6424398183560025
518.5000000000066,57.24742344204436,0.4754580816256121,-0.6424622884539071
519.6000000000067,57.35777006293483,0.47480516856911437,-0.64307167493696
520.7000000000066,57.46534760914704,0.47517543811721863,-0.6434306906155238
521.8000000000067,57.57399427393858,0.47637940307034166,-0.6434258394050576
522.9000000000067,57.6831061518186,0.47810571537349245,-0.6447351110002422
524.0000000000067,57.79183690480054,0.4790062338883009,-0.6447557482327513
525.1000000000067,57.89942404741998,0.4813838256364682,-0.64606070899482
526.2000000000068,58.008720253642714,0.482845996319758,-0.6457298810731191
527.3000000000068,58.11810333007924,0.4835413162583325,-0.6459194378947535
528.4000000000068,58.22661252210236,0.4834026057682934,-0.647050049807004
529.5000000000068,58.33626768557334,0.4863398504472105,-0.6474083352731981
530.6000000000068,58.445425513646036,0.4919924164698588,-0.6483691561157752
531.7000000000069,58.553667560532524,0.4926830201101481,-0.649690048388504
532.8000000000068,58.662748843939966,0.4981775669546852,-0.6496899839964128
533.9000000000069,58.77143391413049,0.5012651702096793,-0.6496933420512758
535.0000000000068,58.87970908194152,0.5034911086441127,-0.6510001028003014
536.100000000007,58.989503122017155,0.5047830755048397,-0.6509773883372327
537.2000000000069,59.097838608569425,0.5088685338892976,-0.6523360915542744
538.300000000007,59.20816401912755,0.5118485729944663,-0.652660013022802
539.4000000000069,59.31590553581726,0.5150173015102059,-0.6525828499942001
540.5000000000069,59.42515854195908,0.5171506277550277,-0.653979800033289
541.600000000007,59.533731784934695,0.5198657159077361,-0.6552953167114106
542.700000000007,59.642107061774624,0.5277328956902174,-0.6552899238811949
543.800000000007,59.75180793624773,0.5275654888525217,-0.6566087045186553
544.900000000007,59.86083797662808,0.5321393173007521,-0.6566100134144541
546.000000000007,59.96979605747343,0.5316853578373995,-0.6580399888478499
547.1000000000071,60.07878328392302,0.5357996842483682,-0.6593610006760082
548.2000000000071,60.186914623016605,0.5409179893949214,-0.6590440492207494
549.300000000007,60.29635355168417,0.5430562178274417,-0.660339862179435
550.4000000000071,60.40616207135071,0.5461648436991444,-0.6613306553081815
551.500000000007,60.51585857361382,0.551038466029074,-0.6604541325551834
552.6000000000072,60.623835983267234,0.5538347498221913,-0.6603615403826741
553.7000000000071,60.73248415432672,0.5590155617118286,-0.6625144905481974
554.8000000000072,60.8426411565129,0.5627299548938953,-0.6629679191787714
555.9000000000071,60.95178277431074,0.5675182974347014,-0.6646099958252956
557.0000000000072,61.060956701681654,0.570125120028973,-0.6650359864737849
558.1000000000072,61.16824804296358,0.5751243736832587,-0.6659398740419591
559.2000000000072,61.27936828299142,0.5760322160244595,-0.6672598048057656
560.3000000000072,61.388632421880274,0.578126655263852,-0.669244055974759
561.4000000000073,61.49721183771807,0.5806970295839253,-0.6697210129163591
562.5000000000073,61.605886244376286,0.5811562987642318,-0.669559924304612
563.6000000000073,61.716093695158264,0.5797162347414718,-0.6695120293182191
564.7000000000073,61.82445964546372,0.5771004185636454,-0.6708798676444765
565.8000000000073,61.93380745929954,0.5750904509518587,-0.6708483938335617
566.9000000000074,62.04247898927515,0.5731197228007451,-0.6721615919736097
568.0000000000074,62.151559078454746,0.5707362095959062,-0.6735492307487219
569.1000000000074,62.260997181718984,0.5657805789830763,-0.6748331008936592
570.2000000000073,62.37038967062983,0.5602486183359497,-0.6748299092122152
571.3000000000073,62.47905001694378,0.5604657783520907,-0.6757350225445142
572.4000000000074,62.58822012572893,0.5522360965023456,-0.6764800783675455
573.5000000000074,62.69804291791431,0.5490403853970253,-0.677777679358055
574.6000000000074,62.80743323720275,0.5431385095647508,-0.6778319996074207
575.7000000000074,62.91422449654638,0.5417698951228809,-0.6782276401744722
576.8000000000075,63.02414031080852,0.5396126292703918,-0.6781200984189337
577.9000000000075,63.13306127153167,0.5341559731418232,-0.6791105646767033
579.0000000000075,63.242948172079174,0.5335551996778695,-0.6791100881772634
580.1000000000075,63.35241848556223,0.5341357143532938,-0.6794763824052144
581.2000000000075,63.46181428649446,0.5313602345120875,-0.6807601143275983
582.3000000000076,63.57106399945099,0.5303530655835806,-0.680756636200798
583.4000000000076,63.6798016907652,0.5310919582645297,-0.6823936433466087
584.5000000000076,63.78927574321171,0.5325935498858088,-0.682005140459911
585.6000000000076,63.90000203716734,0.5344467552850388,-0.6833902553166009
586.7000000000077,64.00968133336754,0.5332508229167139,-0.6833900851007773
587.8000000000077,64.11930592469119,0.5385988510843253,-0.6837442246556846
588.9000000000076,64.22852555251956,0.5381481510983638,-0.683729923811073
590.0000000000076,64.33860994006639,0.5394195138682919,-0.6850502386702266
591.1000000000076,64.44891212614729,0.5426329336656983,-0.6863701676763765
592.2000000000077,64.55865810662544,0.5448819058695522,-0.6868029781332008
593.3000000000077,64.66796341781938,0.5463436809661191,-0.6870098319877451
594.4000000000077,64.77749247335467,0.5504854287681781,-0.688400051229269
595.5000000000077,64.88660191828872,0.5555191159753641,-0.6870199810572517
596.6000000000078,64.99640629730716,0.5604585010151352,-0.6883421314686364
597.7000000000078,65.10576633667965,0.5643805055742728,-0.6883401679787466
598.8000000000078,65.2132216930095,0.5669222423518964,-0.6890074032071665
599.9000000000078,65.32450889374533,0.5733715027456838,-0.690970060772282
601.0000000000078,65.4338257304073,0.5782588578519512,-0.6911392251674044
602.1000000000079,65.54289811153491,0.5840581632655015,-0.6909680365704833
603.2000000000079,65.65213172336367,0.588352501444388,-0.6916144257742034
604.3000000000079,65.76126494042119,0.5923134062971728,-0.6924220508309742
605.4000000000078,65.87124153643875,0.6013987342393609,-0.6945903965607463
606.5000000000078,65.97871248193373,0.6070703432864556,-0.694588547596843
607.6000000000079,66.08806604224782,0.6103901217658261,-0.6959062597296763
608.7000000000079,66.19758123347461,0.6166435919179859,-0.6969007407416967
609.8000000000079,66.30667713006552,0.624320832805046,-0.6970614568508031
610.9000000000079,66.41348196968804,0.6310854323347248,-0.6985356141031329
612.000000000008,66.52480105680796,0.6349399642953506,-0.6985851430473362
613.100000000008,66.63296557269331,0.6419120973849797,-0.6995433584954585
614.200000000008,66.74393296647004,0.6490131253435936,-0.7024763774530873
615.300000000008,66.85225772448706,0.6578613232796302,-0.7033440431918216
616.400000000008,66.96089849977592,0.667752275561519,-0.7051326119252215
617.5000000000081,67.06951397346843,0.6739373281703972,-0.7051157314483634
618.6000000000081,67.1786717594186,0.6808064661318461,-0.7067798592011769
619.7000000000081,67.2871659374328,0.6867269382933606,-0.7078683238314332
620.8000000000081,67.39767255917604,0.6990804127095507,-0.7093126594187837
621.9000000000082,67.50700762799636,0.7061721163864548,-0.7107015105532408
623.0000000000082,67.6162899767793,0.7149207873636403,-0.7121183768520223
624.1000000000081,67.72510999039102,0.7242174973309099,-0.7130505153613433
625.2000000000081,67.83508233604853,0.7311531316609509,-0.7143642540445287
626.3000000000081,67.94452056452783,0.7396227087340679,-0.7157029436534676
627.4000000000082,68.0542372439514,0.7484508708102258,-0.7158985910317193
628.5000000000082,68.1647743004239,0.7572581411916484,-0.7186401079579086
629.6000000000082,68.27428691179607,0.7638663169420424,-0.7214963150981446
630.7000000000082,68.38398388482855,0.7752537167034141,-0.7235789960424728
631.8000000000083,68.4946111661517,0.7825772020778685,-0.7248999714530386
632.9000000000083,68.60355792717381,0.7922609678427968,-0.7269038845387894
634.0000000000083,68.71454672337421,0.8045828188794271,-0.7300968467923785
635.1000000000083,68.82422808453876,0.8136220671082579,-0.7311555583171296
636.2000000000083,68.93345859542674,0.824597954171226,-0.7318137842836103
637.3000000000084,69.04328409657434,0.834747008672601,-0.7356336082039978
638.4000000000084,69.15251999606258,0.8458672113652583,-0.7374233410556084
639.5000000000084,69.2625265056681,0.8606287642216993,-0.7400391160679032
640.6000000000083,69.37227175839047,0.8707912059714746,-0.7413132252034811
641.7000000000083,69.48196047633205,0.8823434493540695,-0.7449508389694568
642.8000000000084,69.59173810203175,0.9152302720345342,-0.7470400297932147
643.9000000000084,69.70178572626692,0.9191176438928463,-0.7506862660153226
645.0000000000084,69.8120058031709,0.9267799536703232,-0.7533036716597254
646.1000000000084,69.9222913453321,0.9346486735414952,-0.7563520081356443
647.2000000000085,70.03231449035192,0.946558302667563,-0.7575171582184623
648.3000000000085,70.14236349231304,0.9615257892620137,-0.7594074156914474
649.4000000000085,70.25180382490538,0.9726579195913813,-0.763212228256029
650.5000000000085,70.36279738428343,0.9843140762857868,-0.7687967033087038
651.6000000000085,70.47190743382784,0.9991300700820938,-0.7702035050408429
652.7000000000086,70.58295981161069,1.0131757782834008,-0.7728103000193371
653.8000000000086,70.69311433666216,1.0292244581126653,-0.7773713177853798
654.9000000000086,70.80161638647556,1.0399801667379764,-0.7812049280065692
656.0000000000086,70.91181139680974,1.057513847126359,-0.7839605940881373
657.1000000000087,71.02146927490524,1.070900829559535,-0.7889287224176855
658.2000000000087,71.12941590795074,1.0855294124802986,-0.7912922752247633
659.3000000000086,71.24155851718574,1.1026313385747724,-0.7954931326054058
660.4000000000086,71.3508427625237,1.1195579941989482,-0.7995699105789509
661.5000000000086,71.4597127825708,1.137938623309516,-0.8043415915081749
662.6000000000087,71.57080204092327,1.1548731376232644,-0.8090952134133729
663.7000000000087,71.6810355852762,1.1726438197331281,-0.813713307976863
664.8000000000087,71.79114166080066,1.1854515814303037,-0.816892250128519
665.9000000000087,71.90060667535448,1.2012430985221045,-0.8230635640809965
667.0000000000088,72.01030415499275,1.219136753165913,-0.8273175153333443
668.1000000000088,72.12000192015016,1.236926058913173,-0.8338992464473716
669.2000000000088,72.22978171344357,1.259724250663411,-0.8381825487496308
670.3000000000088,72.33940044317254,1.2813237666368082,-0.8426755243545982
671.4000000000088,72.4494927992781,1.3016286295692878,-0.8490386650047732
672.5000000000089,72.56042354638761,1.3248192825503167,-0.8540356703132383
673.6000000000089,72.66966508142526,1.3427786072801735,-0.8600290271123425
674.7000000000089,72.77999900181511,1.3651055387717834,-0.8654102011740554
675.8000000000088,72.88905252074105,1.3876536370059487,-0.8730163043475905
676.9000000000088,72.99959144097598,1.4106971724586526,-0.8777064756440098
678.0000000000089,73.11103023833839,1.4339075677884057,-0.8850537460208057
679.1000000000089,73.2210832687176,1.4596118831563047,-0.8914275382425481
680.2000000000089,73.33130764853422,1.4828534240640001,-0.8979092000823816
681.3000000000089,73.44115456010464,1.5135147990092748,-0.9035475081997459
682.400000000009,73.55092714476918,1.5431903026302711,-0.9122295660589872
683.500000000009,73.66123338534084,1.5688408671355805,-0.9193008101223796
684.600000000009,73.77212576555976,1.5972465649020127,-0.9237383514283741
685.700000000009,73.88217480638767,1.6265225295059822,-0.9320559302450784
686.800000000009,73.99267091110922,1.6563280932486835,-0.9398375270131387
687.9000000000091,74.10212113238369,1.6862942317666434,-0.9477366870450004
689.0000000000091,74.21293925653897,1.719107026128432,-0.9574622490476594
690.1000000000091,74.32346396643943,1.7503508850845286,-0.9664775166705688
691.2000000000091,74.43359772378295,1.7798998596052473,-0.9736840069767356
692.3000000000092,74.54387005803177,1.8138539889445844,-0.9820803726746221
693.4000000000092,74.65396812010229,1.8488703391997672,-0.9915144173256323
694.5000000000091,74.76472782798972,1.881116213175858,-1.0018738333288821
695.6000000000091,74.87504663331624,1.913036703624044,-1.0100190255502643
696.7000000000091,74.98300662657745,1.9452093874040322,-1.0194037312465785
697.8000000000092,75.09485158178968,1.981035425258541,-1.0301198897729806
698.9000000000092,75.20489565890797,2.013575558063191,-1.0388704403135631
700.0000000000092,75.31508992564001,2.0474899817747394,-1.0493060966676198
701.1000000000092,75.42629988215249,2.0798205833092567,-1.060289237487169
702.2000000000093,75.53566179636934,2.111738872303448,-1.070519179602512
703.3000000000093,75.64613158094538,2.1446544365706828,-1.0815151757702703
704.4000000000093,75.75609518821662,2.171794405051,-1.0932790287612746
705.5000000000093,75.86571734742897,2.2025611495536257,-1.102670733952659
706.6000000000093,75.97648198065757,2.2424901516808697,-1.116263012893826
707.7000000000094,76.08614765996144,2.2679368971343976,-1.1265527123282428
708.8000000000094,76.1950185990306,2.289891238002874,-1.1376101936017422
709.9000000000094,76.3052394226715,2.3153298392613264,-1.1470700034038224
711.0000000000093,76.41615417229602,2.32722204067408,-1.1616234279142574
712.1000000000093,76.52618481566087,2.344629558455169,-1.1729847839319514
713.2000000000094,76.63549059519673,2.3519564357198193,-1.1841214740657557
714.3000000000094,76.7464487260175,2.355253726724799,-1.1969467173062092
715.4000000000094,76.85693258426893,2.350533591459677,-1.2089738972657895
716.5000000000094,76.96591132589845,2.3374096091810284,-1.2191126670410188
717.6000000000095,77.07716794637162,2.3163991707256812,-1.231478987197982
718.7000000000095,77.18912716485474,2.285886847273223,-1.2437182712682957
719.8000000000095,77.29863726147244,2.244913863809671,-1.2543723186168765
720.9000000000095,77.40819866472889,2.1848511087210407,-1.2644105205995189
722.0000000000095,77.52024934682782,2.110672802572539,-1.2749369766868575
723.1000000000096,77.63000210074283,2.0028462288998106,-1.2842577650270304
724.2000000000096,77.74028892300548,1.844800233402441,-1.2939263284146603
725.3000000000096,77.85048662452925,1.6248097544303066,-1.2990679441806123
726.4000000000096,77.96020363874139,1.352470318098633,-1.3068601177291121
727.5000000000097,78.07098918620947,1.0935509614794963,-1.3099290134068267
728.6000000000097,78.1810056974389,0.9258651511494489,-1.3112301244662437
729.7000000000096,78.2919152703944,0.8293292917092255,-1.3120692700281391
730.8000000000096,78.40115399190101,0.7838246254136891,-1.3139320867500972
731.9000000000096,78.51228289733889,0.7631945029043548,-1.3152038302964462
733.0000000000097,78.62072415813125,0.7503696975384105,-1.3148599652988646
734.1000000000097,78.7320215187576,0.7437889408389791,-1.3151921406142186
735.2000000000097,78.84162513631713,0.7412724407110927,-1.316498353685032
736.3000000000097,78.9517901577576,0.7348951343536321,-1.315520019779091
737.4000000000098,79.06224497989467,0.7392544960215152,-1.3168342389927674
738.5000000000098,79.1715034997759,0.7386277405179579,-1.3168398420026888
739.6000000000098,79.28238354376096,0.7396583075342461,-1.3168398418877092
740.7000000000098,79.39300899507997,0.7374158162597361,-1.3182525422434703
741.8000000000098,79.50298525215153,0.735050003148465,-1.3187912814535276
742.9000000000099,79.61265919974582,0.7329017813770965,-1.3191401783181447
744.0000000000099,79.72298701552442,0.73292418263461,-1.3192523762350805
745.1000000000099,79.8338471707746,0.7310890146272464,-1.3191498840256286
746.0000000000099,79.9230289181285,0.730861168276798,-1.3188846053717604