File: 01_Data/Asphalt_Shingle/STA/N2/10K_min/Asphalt_Shingle_STA_N2_10KData_220915_R1.csv
##Temp./Â°C,Time/min,DSC/(mW/mg),Mass loss/mg
51.0,10.867588648218723,0.06180875252653917,0.003719328020269863
52.100000000000016,11.184314838591355,0.08795068717406207,-0.0015862028873732115
53.20000000000003,11.425987800930518,0.11389429089829983,-0.002421230433865773
54.30000000000005,11.628347391837703,0.1319270115022575,-0.0006087828015841623
55.40000000000006,11.811083710357472,0.1473641879437062,-0.0030901131926786007
56.50000000000008,11.981658553139976,0.15796520017721827,-0.0018978180859763327
57.600000000000094,12.144761180262678,0.16911033873385684,-0.0011532581321116453
58.70000000000011,12.29953082874486,0.17781700552456559,-0.0012656709338667582
59.800000000000125,12.446482460171982,0.18276454255457186,-0.0018837467424948073
60.90000000000014,12.593695271474099,0.18898831533903104,-0.0003350705307898494
62.000000000000156,12.737590619514933,0.19545668022552332,-0.0028533203439984334
63.10000000000017,12.873379947588273,0.20151355118696435,-0.0009629056385307422
64.20000000000019,13.01227466007511,0.20434035083065072,-0.0019383819916862777
65.30000000000021,13.146096851685892,0.20906573661849848,-0.0021528722861710037
66.40000000000022,13.278070411849773,0.2141004340364543,-0.003369845430111873
67.50000000000023,13.40862728057748,0.21785982480236354,-0.0036550445136427356
68.60000000000025,13.538483854868483,0.22030144666024887,-0.0021720530326634346
69.70000000000027,13.666406288419555,0.22550363037593946,-0.002081777122171502
70.80000000000028,13.794564420872414,0.22694779884284988,-0.0020829673976914265
71.90000000000029,13.919490236412075,0.23200068776434346,-0.001304734417884923
73.00000000000031,14.043531691540608,0.23514022717432437,-0.003418337897330481
74.10000000000034,14.16520685586369,0.2373620005794126,-0.0035093100538716726
75.20000000000034,14.291136780852003,0.23980385376933167,-0.0011040230270999984
76.30000000000035,14.411539957547099,0.24217912741198555,-0.0007509352910757272
77.40000000000038,14.53079880349267,0.24615273716422315,-0.0024011972784538926
78.5000000000004,14.651130487253644,0.2482725751029662,-0.001970880766605454
79.6000000000004,14.770797023899233,0.2506868505068025,-0.001052587707309982
80.70000000000041,14.889162557528577,0.2524892930336684,-0.0024135451053570733
81.80000000000044,15.006676921980914,0.2541689998746579,-0.0037317407768826527
82.90000000000046,15.122303849833377,0.2582785027181589,-0.0024478934724996293
84.00000000000047,15.240090959337913,0.26075899830559046,-0.003724603397818882
85.10000000000048,15.354678405451441,0.26036806945163926,-0.0024467081572341343
86.2000000000005,15.46914946992775,0.2652460311900573,-0.001812870786202403
87.30000000000052,15.583785443637415,0.26562659966830315,-0.0024017727961833657
88.40000000000053,15.696394576500108,0.2699984181432922,-0.0037632833348721917
89.50000000000054,15.810418250691932,0.2689560258815469,-0.0010933372543471265
90.60000000000056,15.922352072452131,0.2710589946442534,-0.0024349834413852633
91.70000000000059,16.036498809147268,0.27146616547127667,-0.0014113703229972074
92.8000000000006,16.14585022085746,0.27251157841402085,-0.002720281496099375
93.9000000000006,16.25771939133278,0.2755741505960214,-0.002393064513857013
95.00000000000063,16.36717770600844,0.2771169920064478,-0.0024979321721820824
96.10000000000065,16.479900239585774,0.2803071642272752,-0.002366328677426033
97.20000000000066,16.590192926782862,0.2799872786486408,-0.002410966897550715
98.30000000000067,16.700287217583416,0.2821097486089872,-0.0024103911062223204
99.40000000000069,16.808516310651363,0.2858719662825453,-0.0024541817106404906
100.50000000000071,16.918618997931667,0.285347667712363,-0.003732916815458509
101.60000000000072,17.028155487296395,0.28553539242568693,-0.003701890452968648
102.70000000000073,17.13330104470446,0.2889846083129224,-0.002422229553283195
103.80000000000075,17.243850155404026,0.29006554755903036,-0.003731963753978107
104.90000000000077,17.35332866932132,0.29220445583667765,-0.002208925629680003
106.00000000000078,17.459543508371812,0.28999193662275435,-0.0035100277693294046
107.10000000000079,17.568936916949966,0.29288376061089205,-0.003508326425324171
108.20000000000081,17.6781663005288,0.29251758093421465,-0.0035101822630361212
109.30000000000084,17.785448686797206,0.29361363861205736,-0.003501937989256909
110.40000000000084,17.89357565458087,0.29754549338212166,-0.0035202774321634323
111.50000000000085,18.001804175249035,0.2986042611614673,-0.003509849793504216
112.60000000000088,18.108828254692728,0.2978898117939882,-0.002685393576201456
113.7000000000009,18.21689961813286,0.2982842700487276,-0.003573667637505551
114.8000000000009,18.323801916673233,0.29990191410967926,-0.004864848805545385
115.90000000000092,18.428970684036607,0.2998160497575929,-0.0035004689885713702
117.00000000000094,18.538910658440432,0.300036837088149,-0.004819929245577725
118.10000000000096,18.646064989581053,0.29967339407120375,-0.0032051093507377004
119.20000000000097,18.753051244577705,0.30418067669634175,-0.0046082800961126935
120.30000000000098,18.860394186987758,0.305072715928713,-0.004610114277162403
121.400000000001,18.967410015383688,0.3048124701754791,-0.005597464681538433
122.50000000000102,19.075053194708058,0.30604128920387064,-0.005917567443902705
123.60000000000103,19.181193705303002,0.30553401093934285,-0.005933599028805858
124.70000000000104,19.287806401336027,0.30754112315342763,-0.005931703918421682
125.80000000000106,19.393340115936862,0.30638482246131604,-0.004215015542188283
126.90000000000109,19.496402572194853,0.3065412779584993,-0.0035001330122437224
128.00000000000108,19.606487983795382,0.3087547051357995,-0.004820498203677026
129.1000000000011,19.712376961820958,0.30896096569799714,-0.004490099307189688
130.20000000000113,19.81788179078557,0.3099892446795991,-0.0031798856499465344
131.30000000000115,19.924150447558734,0.31001875259088973,-0.0020987574114412766
132.40000000000117,20.030183957176916,0.31181032469323444,-0.0031799746403118334
133.50000000000117,20.13545531910132,0.3119552878966466,-0.004062611960695683
134.6000000000012,20.2410248592819,0.3132367294097481,-0.005824188880271031
135.7000000000012,20.34843898824184,0.31367125613586977,-0.005785009909375027
136.8000000000012,20.45363600783102,0.31319451995859093,-0.006605600133563705
137.90000000000123,20.560328972479855,0.31376716181343023,-0.004820112663435516
139.00000000000125,20.665109769269584,0.3155730006094333,-0.0035064523085432953
140.10000000000127,20.770648793063973,0.3162380263163552,-0.00487432187477399
141.2000000000013,20.876790558464073,0.3171496833696046,-0.006008989703234491
142.3000000000013,20.98156552940714,0.31814322917464877,-0.006143031129820287
143.4000000000013,21.08621132138416,0.3198334837518615,-0.007459919841392271
144.50000000000134,21.192047384296814,0.31731549020692407,-0.0048202673797526074
145.60000000000133,21.297972743306783,0.3185236697507734,-0.004820250926364622
146.70000000000135,21.402140559182847,0.3185806903535435,-0.004828591782492175
147.80000000000138,21.507131875183276,0.3193391196007106,-0.0038533812749381724
148.9000000000014,21.612715839801993,0.32222797599262987,-0.0063215401918315095
150.00000000000142,21.71680174510162,0.3257565551913635,-0.006139714663473406
151.10000000000142,21.820817088818988,0.32412340867711087,-0.006730638570110692
152.20000000000144,21.926955690322487,0.3248678556268456,-0.00613995713412141
153.30000000000146,22.03153706320626,0.327298230411428,-0.006050661989846162
154.40000000000146,22.136260229102966,0.32692286986844754,-0.004857647816232991
155.50000000000148,22.24093386193208,0.32619300146178143,-0.006136001834375904
156.6000000000015,22.344074285028583,0.3271648757794213,-0.006138626948150261
157.70000000000152,22.45000000000015,0.32814391005749255,-0.004776560233488603
158.80000000000155,22.55497001551286,0.3295508930677523,-0.005479407957562188
159.90000000000154,22.65919694609217,0.3293227284474941,-0.005479989996359791
161.00000000000156,22.763898306368397,0.3306075939768671,-0.005497694415134369
162.1000000000016,22.869197646186652,0.33059871614419545,-0.004820414004169216
163.20000000000158,22.972006692223147,0.3311519159190126,-0.00483936637543092
164.3000000000016,23.077806157552192,0.331717175838423,-0.007457682237882679
165.40000000000163,23.181239232911572,0.3341802861107057,-0.006070192962803311
166.50000000000165,23.28755715370926,0.3332906705214296,-0.0038085221352046617
167.60000000000167,23.392184897512035,0.3335738675352955,-0.004817593650500385
168.70000000000167,23.495809996243864,0.33642461341399577,-0.007130323463103494
169.8000000000017,23.599732698838285,0.33772299456767496,-0.0058116873082880716
170.9000000000017,23.70430264812328,0.3368084783749201,-0.007422961473286804
172.0000000000017,23.808898830758153,0.33935283172779585,-0.00614540079559589
173.10000000000173,23.913987218882145,0.3381249981301663,-0.006877301777071132
174.20000000000175,24.01898649678111,0.33887049273985925,-0.006150059904913796
175.30000000000177,24.12367340928459,0.34034503044520714,-0.006150058270155689
176.4000000000018,24.22779846345476,0.3419859112802941,-0.007575541638107808
177.5000000000018,24.33233737126818,0.3425962610101403,-0.006469832224613725
178.6000000000018,24.435911569276616,0.34366067328530336,-0.007457357783242635
179.70000000000184,24.540830191581627,0.3444066563477529,-0.007465468322476632
180.80000000000183,24.643467311236236,0.3448094532576714,-0.006923713280333921
181.90000000000185,24.750096325745762,0.34492903724468493,-0.008780352608273034
183.00000000000188,24.854280901009737,0.3474093377942785,-0.007459878150857691
184.1000000000019,24.9591538750428,0.34517226403274226,-0.008451408759624357
185.20000000000192,25.06297162818437,0.3479613778629297,-0.007451502751418815
186.30000000000192,25.167628992174443,0.3483623769465547,-0.0074599701019204545
187.40000000000194,25.271475814272378,0.34703432142236645,-0.0073828109326115055
188.50000000000196,25.37539833904696,0.34757126187445697,-0.006799765607956587
189.60000000000196,25.480656577721774,0.3492817356586436,-0.008109754269728597
190.70000000000198,25.585044141681045,0.34765353880553684,-0.008111789595481866
191.800000000002,25.688567464366077,0.3494205774021124,-0.009432640577214713
192.90000000000202,25.792792958060303,0.35066118563426707,-0.008783897369465166
194.00000000000205,25.8947071500853,0.3494238797279674,-0.007512716522329654
195.10000000000204,26.001452777359226,0.3524724141736102,-0.010119291996073976
196.20000000000206,26.105557837907668,0.35327041319397956,-0.011429105073814227
197.3000000000021,26.209607586232945,0.3522712912440177,-0.01009988826007202
198.40000000000208,26.315290468784603,0.3551573992602314,-0.010099898817073516
199.5000000000021,26.419298141628985,0.3548188969097804,-0.01142641417403567
200.60000000000213,26.522895949771467,0.35568879639705053,-0.011416879990935769
201.70000000000215,26.62727366302417,0.3556461057309156,-0.011409831847724483
202.80000000000217,26.73214072381877,0.3571954380294,-0.012709623148743354
203.90000000000217,26.834933519159925,0.3560728708255012,-0.01001616831981611
205.0000000000022,26.94184351841602,0.36021177866759146,-0.011335475287435948
206.1000000000022,27.04491987821861,0.3594194850678323,-0.012399930070759346
207.2000000000022,27.149805665455286,0.36039983535640696,-0.012400011247837739
208.30000000000223,27.25350590853768,0.3606532835303585,-0.01372021800129275
209.40000000000225,27.35716271385228,0.36096946595381985,-0.013719932840908555
210.50000000000227,27.46102327045964,0.36180179863782735,-0.015031372827651879
211.6000000000023,27.56693392865509,0.361694793475809,-0.015095311149426749
212.7000000000023,27.670832291917442,0.3621095546608082,-0.015044583123046351
213.8000000000023,27.77417510116932,0.36517317120130544,-0.012728078595202419
214.90000000000234,27.87698673321729,0.3638681813161082,-0.015468745452023924
216.00000000000233,27.98271823787249,0.3653615480299207,-0.015832872256443586
217.10000000000235,28.088487276434773,0.3650932709740867,-0.018382488918167184
218.20000000000238,28.192563445037887,0.36672403006833965,-0.018440005087269284
219.3000000000024,28.29735234540241,0.36799210129961,-0.01844000496674525
220.40000000000242,28.401864578902696,0.36772320989827467,-0.018572144121708156
221.50000000000242,28.50688011782202,0.3683691262775014,-0.01910000475559137
222.60000000000244,28.61069446030589,0.36812064323906213,-0.01910000500000031
223.70000000000246,28.7146351823553,0.3682076641822387,-0.019100005000057152
224.80000000000246,28.818888332740194,0.36952610164200206,-0.019100025038480517
225.90000000000248,28.924256321074054,0.3691756031883596,-0.017779731584393055
227.0000000000025,29.02904905893413,0.3715898670467952,-0.018428829292330917
228.10000000000252,29.13332257832742,0.3713761337898286,-0.019748738268654975
229.20000000000255,29.23724844549036,0.37222928184607873,-0.019750110001385934
230.30000000000254,29.341457695374487,0.3701846962138645,-0.019748063948223482
231.40000000000256,29.44672453858023,0.37266885874310995,-0.0210757780661881
232.5000000000026,29.54980983872358,0.37391780050082213,-0.021070335593218026
233.60000000000258,29.654472035982973,0.3734364851451819,-0.02236326599873717
234.7000000000026,29.76000000000024,0.37468091579017315,-0.0223957233584704
235.80000000000263,29.863635170321878,0.3754169208347724,-0.02247021500765989
236.90000000000265,29.96812101559841,0.3755365760351803,-0.02371734333979525
238.00000000000267,30.07307946410816,0.377484115799414,-0.02502995532447727
239.10000000000267,30.177833023164425,0.37688528147270384,-0.025689613175253534
240.2000000000027,30.282320600157618,0.3770540632936189,-0.026319050440931413
241.3000000000027,30.386189529548403,0.3764826420321228,-0.026341240380712172
242.4000000000027,30.490725250126037,0.37776847468180896,-0.027672859214248113
243.50000000000273,30.59547539045953,0.3786712343170896,-0.027660200697110504
244.60000000000275,30.699660211690496,0.37937341317806295,-0.028747559891921348
245.70000000000277,30.802314452327895,0.38037753282178877,-0.030289979057730676
246.8000000000028,30.9092998118751,0.3808944887650372,-0.02896706989691289
247.9000000000028,31.01347966604796,0.38178774073044974,-0.030282543846261945
249.0000000000028,31.119611725040603,0.3821384101214391,-0.030289971936116267
250.10000000000284,31.222803114939975,0.382849135426204,-0.03160813558309972
251.20000000000283,31.32825177211934,0.38349786112990736,-0.031609864998739745
252.30000000000285,31.432126792701098,0.38300783485029255,-0.031609865421160954
253.40000000000288,31.53689132712544,0.38374382298346843,-0.034301385100683035
254.5000000000029,31.641848017945595,0.38410252030930925,-0.03425016454835994
255.60000000000292,31.74531367394067,0.3847594881438835,-0.035334562327963503
256.7000000000029,31.849110015106458,0.38507495161955974,-0.03692545700728633
257.8000000000029,31.95455306950756,0.3875976049452017,-0.037195800451626404
258.90000000000293,32.059252295459224,0.38695154428373546,-0.03917981590162345
260.00000000000296,32.16455922382423,0.38829080266990157,-0.03917996478850139
261.100000000003,32.26870057083188,0.38881607615101377,-0.04050008133811911
262.200000000003,32.3736501098634,0.3891713976290213,-0.04050013000128505
263.300000000003,32.47797368970472,0.38689931880906925,-0.04050102467266292
264.40000000000305,32.5851254997515,0.38712076678906715,-0.04182001481247255
265.50000000000307,32.68927474840448,0.38771584763292144,-0.04215684737982972
266.6000000000031,32.79362633708426,0.3879886506505673,-0.04478990002288974
267.7000000000031,32.89781861911476,0.389086875155468,-0.04612622131045008
268.8000000000031,33.00329870322441,0.39055031089713144,-0.046099798417007065
269.9000000000031,33.10680678701889,0.3891755275653449,-0.04741989275409164
271.0000000000031,33.212597433952205,0.3876321432679205,-0.04857877372146646
272.10000000000315,33.31799663432273,0.3891046004506781,-0.051364705715368775
273.2000000000032,33.422624172607094,0.39023418483222383,-0.05070716826257904
274.30000000000314,33.52768835969601,0.39066506728923645,-0.05202883999506902
275.40000000000316,33.63288933123901,0.39254258482423976,-0.05432386204002704
276.5000000000032,33.736911019561795,0.3925917768955557,-0.05532996676007551
277.6000000000032,33.842252487928576,0.39292237170939626,-0.05665006014123497
278.70000000000323,33.94853251267088,0.39411713036053475,-0.056653646510715916
279.80000000000325,34.051611639325344,0.3950376395190066,-0.05663621443458888
280.9000000000033,34.156868684352084,0.3946761929675937,-0.059281771928118676
282.0000000000033,34.26000000000027,0.3939198168260437,-0.061910099046468936
283.1000000000033,34.363966107367844,0.39455797871383524,-0.061917298530253184
284.20000000000334,34.47236942598225,0.39386528866376824,-0.06059716146073635
285.30000000000337,34.574969697423235,0.3955928616476483,-0.06191002543814017
286.40000000000333,34.68153259373975,0.397014594276482,-0.06456064070192591
287.50000000000335,34.78675194535308,0.3955452080935329,-0.06850516810828688
288.6000000000034,34.8913792040542,0.3985948039147128,-0.06982389530384125
289.7000000000034,34.99750366153212,0.39722462164370276,-0.06981042907997637
290.8000000000034,35.101144920113285,0.39894334728378555,-0.0697075748955549
291.9000000000034,35.20604663559064,0.39963868942511993,-0.07233431368278254
293.0000000000034,35.30953559629984,0.39963824025147443,-0.07376993148201016
294.10000000000343,35.41756525045715,0.4002391632476372,-0.07451633727937867
295.20000000000346,35.52303257314229,0.40054811947287483,-0.07509047565084437
296.3000000000035,35.62787605947521,0.3994716436191835,-0.07639328540143353
297.4000000000035,35.73306199238172,0.401041828135698,-0.07771552199342091
298.5000000000035,35.83869633010751,0.40343217300999634,-0.08033085382787952
299.60000000000355,35.944222585035256,0.402550252171478,-0.08267061683844856
300.70000000000357,36.049317994392204,0.4022976645097196,-0.08398006614154196
301.8000000000036,36.1546463572448,0.4034817439026881,-0.08530945031910164
302.9000000000036,36.25959633959449,0.402714950199729,-0.08824415534129226
304.0000000000036,36.36471431959971,0.40405439097633,-0.08831427553182403
305.1000000000036,36.47072494092009,0.4043540426268841,-0.09030193680526732
306.2000000000036,36.575531279192795,0.4049397663459712,-0.0908907797648264
307.30000000000365,36.68159446264778,0.4062953565590889,-0.09352711534840452
308.4000000000037,36.78688133280141,0.4052602136467811,-0.09485018234105214
309.5000000000037,36.892713171750195,0.40648020850465527,-0.09616374372178438
310.60000000000366,36.99726408224175,0.40611126649980156,-0.09880168550088442
311.7000000000037,37.10274175699761,0.4050386381385743,-0.10141017562985244
312.8000000000037,37.208588095347025,0.4065286954877765,-0.10276190596499735
313.90000000000373,37.313897445896465,0.4083781872999358,-0.10406987363240638
315.00000000000375,37.41960148707271,0.41012330278756015,-0.1067000240587781
316.1000000000038,37.525598187026944,0.4093635813174411,-0.10671149947218561
317.2000000000038,37.63029357538639,0.40903502814185644,-0.10802225987020186
318.3000000000038,37.73537429487743,0.408749987067615,-0.11200335966176578
319.40000000000384,37.84145452147578,0.410489921183695,-0.11331928137214975
320.5000000000038,37.94765826464086,0.41093138076896973,-0.1133009548979822
321.60000000000383,38.052835772291566,0.41148565960471395,-0.11461640241131832
322.70000000000385,38.159181744018454,0.4107067156253159,-0.11592806213442808
323.8000000000039,38.264646314985086,0.41331644902232356,-0.11988315636865288
324.9000000000039,38.370190911997916,0.4125843276648198,-0.12118988836046096
326.0000000000039,38.476198376385014,0.41207774456120405,-0.12389599597461753
327.10000000000394,38.581811712744695,0.4131608466608019,-0.12513997020024537
328.2000000000039,38.688014354472244,0.41116383381521493,-0.12638306775687713
329.30000000000393,38.79116211665418,0.4132663857820188,-0.12908816236027487
330.40000000000396,38.899420118247036,0.41456395656508627,-0.13172990558648
331.500000000004,39.005623158926014,0.41575636173687247,-0.1331662231124131
332.600000000004,39.111300658346764,0.41640045563820427,-0.13547043628887856
333.700000000004,39.217403586251095,0.4170001071998063,-0.13806754189898784
334.80000000000405,39.323100421840714,0.4176689387068062,-0.13943777959183556
335.90000000000407,39.42948704873175,0.4211873247966209,-0.1394324810564136
337.0000000000041,39.53567062308052,0.4220156765807338,-0.14336834339328375
338.10000000000406,39.64057106397659,0.4222510073625222,-0.14339207695865763
339.2000000000041,39.74552676468305,0.42265715590492214,-0.1466364501914752
340.3000000000041,39.85109280579028,0.4249672131700488,-0.15001405362198383
341.4000000000041,39.95889486318221,0.4273997364327442,-0.15127368702913957
342.50000000000415,40.06515152505083,0.4294510223884851,-0.15379888868235936
343.6000000000042,40.171107336421336,0.4312438342439152,-0.15630742025149624
344.7000000000042,40.27809035331075,0.43198364798926436,-0.15796430456561827
345.80000000000416,40.38102544495222,0.4339286829026978,-0.15929122801063667
346.9000000000042,40.488314482663974,0.43474478235699066,-0.16157950499784723
348.0000000000042,40.59627198984335,0.4363617868758375,-0.16422760688386218
349.10000000000423,40.701931245988916,0.4365498763340301,-0.16563012214467365
350.20000000000425,40.80845890790499,0.44002119245209714,-0.16686683317169315
351.3000000000043,40.91539635613736,0.44108928306945516,-0.16824064517775206
352.4000000000043,41.02164098148382,0.44442805600226665,-0.17323615994262997
353.5000000000043,41.12752834905023,0.444003620121447,-0.1760860811896081
354.60000000000434,41.23350939097679,0.4439693621151479,-0.17731567183337393
355.7000000000043,41.33991234947353,0.44518193201630185,-0.18003455782111777
356.80000000000433,41.44568325498661,0.44896871607170796,-0.18268905100248478
357.90000000000435,41.553126672246314,0.4484308872979027,-0.18457465051380506
359.0000000000044,41.65934098265722,0.4488204487511426,-0.18823131090434675
360.1000000000044,41.765185963187584,0.45003013264408553,-0.18889152713732082
361.2000000000044,41.87192619098511,0.4511722886060079,-0.19208777080257988
362.30000000000445,41.97764352245504,0.4513593503624731,-0.1916266624818097
363.4000000000044,42.08465995846877,0.4526740973292278,-0.19710264158734025
364.50000000000443,42.1906086601385,0.4512813595034548,-0.19892518256589797
365.60000000000446,42.29663770735145,0.45309864564843183,-0.20160365600996233
366.7000000000045,42.403829077932784,0.4532751701819785,-0.20405581554046925
367.8000000000045,42.51067433243683,0.45320981816824135,-0.20430176541460865
368.9000000000045,42.617495798947836,0.4534671023048633,-0.20632629320894313
370.00000000000455,42.723861628900174,0.45268332920344634,-0.2074653561590587
371.10000000000457,42.83019550924317,0.4539986573509627,-0.2138632936144882
372.2000000000046,42.93650591417827,0.45311987671800236,-0.21661278073009615
373.30000000000456,43.042528811043184,0.45506803492356884,-0.21942534935201863
374.4000000000046,43.148857404502536,0.4533320975115307,-0.2205969616678254
375.5000000000046,43.25683970572082,0.45344034756651086,-0.22199091261502657
376.6000000000046,43.36337088315386,0.45434667330655043,-0.226067951878131
377.70000000000465,43.47039150827244,0.45356160085267117,-0.22826281097477708
378.8000000000047,43.5775104331258,0.4542212005455032,-0.23046886617390028
379.9000000000047,43.682286340995596,0.4560272702240189,-0.23438282242249686
381.00000000000466,43.79091192490148,0.4561640729177744,-0.23939832953094964
382.1000000000047,43.89801183393607,0.454040780248568,-0.24035064249507299
383.2000000000047,44.003851718552134,0.45509170405909105,-0.24312900224750056
384.30000000000473,44.110678151175485,0.45555935504333045,-0.24606926886388125
385.40000000000475,44.21870405964977,0.45599617506125867,-0.2499157378279082
386.5000000000048,44.32528247873437,0.4540321897242352,-0.25135783544874934
387.6000000000048,44.43071588555023,0.45325208807005235,-0.2548027819510694
388.7000000000048,44.538012003035284,0.4542519843112478,-0.2584782893401454
389.80000000000484,44.64512912628363,0.4518800792332125,-0.25928799452539497
390.9000000000048,44.75215102543892,0.45046955426592394,-0.2631017412702854
392.00000000000483,44.85781826660121,0.4495342981628806,-0.26491120393657086
393.10000000000485,44.965581829178696,0.4492702163810005,-0.2690716142790466
394.2000000000049,45.073113898979194,0.448157071381463,-0.27086147655819337
395.3000000000049,45.18027791040351,0.44928612282857394,-0.2731402290639444
396.4000000000049,45.287526349995694,0.446757197039063,-0.2774196136700917
397.50000000000495,45.39463941858285,0.447118320609579,-0.28332712915170566
398.6000000000049,45.500540069138935,0.44688254005569705,-0.28950071521818455
399.70000000000493,45.605273833756044,0.44290561486126234,-0.2893402963481093
400.80000000000496,45.71516662385647,0.4432457725547919,-0.2927113260587073
401.900000000005,45.820577184213924,0.4403648743947257,-0.29286567612430137
403.000000000005,45.92784262479424,0.4402368248372358,-0.2971885190150636
404.100000000005,46.03563496909721,0.43999469618313114,-0.3030225023529378
405.20000000000505,46.141951978015655,0.44086291033806546,-0.3078184794436689
406.30000000000507,46.2495000592374,0.4377646458405893,-0.30978586694019583
407.4000000000051,46.354887022027995,0.4369635607014093,-0.31191827540552497
408.50000000000506,46.46376613320471,0.43645530976297364,-0.317230737389238
409.6000000000051,46.570475934428835,0.4358216160349627,-0.3221117180696651
410.7000000000051,46.677261838990106,0.4362251116153628,-0.32515902219236015
411.8000000000051,46.78518542101481,0.4348650704141138,-0.3287368915376154
412.90000000000515,46.89224130638052,0.43575048153899665,-0.3333323116575819
414.0000000000052,46.99942866513659,0.4339809032889581,-0.33759457300058493
415.1000000000052,47.104585470024084,0.4332171988367699,-0.3419753060001063
416.20000000000516,47.21318379640258,0.4318785767634832,-0.34485985998961954
417.3000000000052,47.320662543316615,0.4326655062039183,-0.3475882440029272
418.4000000000052,47.42842432070388,0.432414795546491,-0.35179947554303626
419.50000000000523,47.53522345203421,0.4335496024350093,-0.3583233811485962
420.60000000000525,47.64208222532208,0.4316964135569278,-0.3610100880003011
421.7000000000053,47.75059921786434,0.43225982633959925,-0.36606792273492417
422.8000000000053,47.85711703885395,0.43493328883326143,-0.37197927857139224
423.9000000000053,47.96551491576696,0.4338320781474795,-0.3759943672737913
425.00000000000534,48.07208859999017,0.4353692708371837,-0.3794666693409834
426.1000000000053,48.1792993721834,0.434755031069487,-0.3850411819890178
427.20000000000533,48.28682590765988,0.4379743163608798,-0.38817523096734163
428.30000000000535,48.394133426787974,0.438868460331299,-0.3947669089597392
429.4000000000054,48.50199534870329,0.43775279866112127,-0.39991687194207426
430.5000000000054,48.60920762249735,0.4420288068052236,-0.40468871584715327
431.6000000000054,48.71759378596172,0.4418024591922226,-0.4097534805017262
432.70000000000545,48.824231983444314,0.4426903071049817,-0.4168404896356961
433.8000000000054,48.931422759327916,0.44227346564956493,-0.4223459441946882
434.90000000000543,49.03823487212243,0.4438332465962843,-0.4253436759987155
436.00000000000546,49.14606010968247,0.44548431337933025,-0.4294897335483925
437.1000000000055,49.254423893785074,0.44516971887640155,-0.4336067469897791
438.2000000000055,49.361034443494475,0.4453730859313828,-0.4409841090265525
439.3000000000055,49.46895841699591,0.44575475781722407,-0.44760285937385413
440.40000000000555,49.5760735724071,0.44567041865044643,-0.4539166337917626
441.50000000000557,49.68432209936717,0.4490971793507913,-0.45961534319641295
442.6000000000056,49.7924432342392,0.45119848720344624,-0.4646793708565098
443.70000000000556,49.899330444234955,0.4521006727977728,-0.4715548281929598
444.8000000000056,50.00677757822511,0.4507822450713511,-0.4754134434217625
445.9000000000056,50.11511481732087,0.45348661022600845,-0.4810307351299383
447.0000000000056,50.22282457174195,0.45521414966574725,-0.4862584421581486
448.10000000000565,50.33020679927335,0.45778786294395635,-0.4907308261183525
449.2000000000057,50.437757509069236,0.4586246229942139,-0.4976606108149779
450.3000000000057,50.54285311078445,0.46319768455478727,-0.5036807065493125
451.40000000000566,50.653959266537335,0.4637695422568915,-0.5087102102737959
452.5000000000057,50.761057338187584,0.46409430080277103,-0.5139920236319941
453.6000000000057,50.86876341916284,0.4665592438621414,-0.5190955469787837
454.70000000000573,50.97579961646218,0.46823477723958207,-0.5235508420952537
455.80000000000575,51.08387877277145,0.4677936320487076,-0.5313106177213158
456.9000000000058,51.191530613998765,0.4694325293928101,-0.537087205821817
458.0000000000058,51.30000000000061,0.47044858978235204,-0.5401871333859645
459.1000000000058,51.40713456250623,0.4697923948972844,-0.5463299837694469
460.20000000000584,51.51573905595404,0.4690648048453705,-0.551305390643134
461.3000000000058,51.62375946446171,0.4672799201785115,-0.5569547651745053
462.40000000000583,51.73110472971895,0.47011653560089117,-0.5595503249862044
463.50000000000585,51.838654912251585,0.47077892266725885,-0.564920951675302
464.6000000000059,51.945622221101566,0.4692176996795352,-0.570184715705528
465.7000000000059,52.05531721107654,0.46803697097205765,-0.5743270068658215
466.8000000000059,52.162332102673155,0.4650352655065909,-0.5788483811458289
467.90000000000595,52.27051647112935,0.46617356226939033,-0.5807880512313353
469.0000000000059,52.37768095641183,0.46540930537997593,-0.5848223470617389
470.10000000000593,52.4859958023758,0.46546915998094107,-0.5891638854971766
471.20000000000596,52.595185008382295,0.4640392421100853,-0.5920429308557855
472.300000000006,52.70318711577278,0.463555859071765,-0.5958937199639407
473.400000000006,52.809525132368066,0.4626787473276185,-0.5997388055032435
474.500000000006,52.91873540038327,0.4600193638012081,-0.6011920247000817
475.60000000000605,53.024108603320855,0.4598277245828367,-0.6038118097625267
476.70000000000607,53.13407807000845,0.45686930598005304,-0.607852355955206
477.8000000000061,53.24220005810868,0.45432236586282615,-0.6090810095992665
478.90000000000606,53.35079862380827,0.4533748020334346,-0.611741774396962
480.0000000000061,53.458362015244596,0.452509395516297,-0.6135635632199259
481.1000000000061,53.56584874968775,0.4502166655590657,-0.6162651042831389
482.2000000000061,53.674464751521704,0.4488718644315719,-0.617203232638861
483.30000000000615,53.78273130342571,0.44507697285999814,-0.6195884730416625
484.4000000000062,53.891284947473835,0.4456941705352402,-0.619687103287736
485.5000000000062,53.99875308892851,0.4442466452865057,-0.6219200654341397
486.60000000000616,54.10752664413604,0.4411931313543084,-0.6245556400494143
487.7000000000062,54.21304692407749,0.4378889801564039,-0.625868949568388
488.8000000000062,54.32322808396803,0.43441869527502164,-0.6271821569126783
489.90000000000623,54.4320837851168,0.4349033290334158,-0.6285211829305024
491.00000000000625,54.54009761161241,0.4339567253108555,-0.6298281639995098
492.1000000000063,54.64752328707495,0.43176664115455043,-0.631450911959377
493.2000000000063,54.75635905024734,0.42987942287768643,-0.6302385994432651
494.3000000000063,54.8645762811305,0.42658150741597467,-0.6314110958340362
495.40000000000634,54.973464980870844,0.4266210876727118,-0.6340822565571531
496.5000000000063,55.081683183394425,0.4260359321708447,-0.6341098395434428
497.60000000000633,55.18929325577531,0.4225770088839431,-0.6340999759647312
498.70000000000636,55.297829527820674,0.4213469614193641,-0.636571201101571
499.8000000000064,55.40684165053821,0.4225462129134564,-0.6354195782877574
500.9000000000064,55.51414431045416,0.4213997341850987,-0.6367404214653649
502.0000000000064,55.62225799033976,0.4171705942539363,-0.6393833244062166
503.10000000000645,55.73095709983676,0.42163482481950343,-0.6406886178747948
504.2000000000064,55.83932608237978,0.4237992226374695,-0.6398522015382215
505.30000000000643,55.9484749198983,0.4306138707691878,-0.6393698406732153
506.40000000000646,56.05530367256855,0.4338427252146996,-0.640688197365793
507.5000000000065,56.163569390545305,0.43697400257828445,-0.6433293875158705
508.6000000000065,56.27168361617249,0.4386166551245536,-0.6433188791870195
509.7000000000065,56.379212077989486,0.4401920098722991,-0.6419958631956728
510.80000000000655,56.489673652359166,0.4429653706654946,-0.6446400874787099
511.90000000000657,56.59865194975966,0.4451194269589719,-0.6433161168014125
513.0000000000066,56.70691181786718,0.44497931848854144,-0.6435637719317349
514.1000000000065,56.81529019193048,0.44420054139166476,-0.6446399671506522
515.2000000000066,56.92475366801558,0.4445896688612849,-0.6466217612493086
516.3000000000065,57.03259021830966,0.44416064322325444,-0.6452685799756392
517.4000000000067,57.140763192746775,0.44237641144392204,-0.6459598984896644
518.5000000000066,57.24989281125021,0.44583782899225577,-0.6472701261302456
519.6000000000067,57.35781876721829,0.4470879082945005,-0.6472701443125866
520.7000000000066,57.46770789023758,0.4508149586612372,-0.6485895882358874
521.8000000000067,57.57614680861875,0.44741596186299737,-0.648592056357423
522.9000000000067,57.68479916929437,0.4508584240401483,-0.6499098462024784
524.0000000000067,57.79414376791867,0.4485505825278323,-0.6485999662999067
525.1000000000067,57.90298815839221,0.45068863023647154,-0.6512218221316988
526.2000000000068,58.01125453118218,0.4485132813916587,-0.6525943413323252
527.3000000000068,58.12067801423673,0.4498898336772227,-0.6525398642581854
528.4000000000068,58.23029226996677,0.4502278008392093,-0.6525899831360915
529.5000000000068,58.33901464318977,0.4498808366072249,-0.6525498199345785
530.6000000000068,58.44839894824751,0.4512182463554887,-0.6530967493550772
531.7000000000069,58.55685763641651,0.44928185621897576,-0.6537794194503714
532.8000000000068,58.66430342443756,0.44948402506700114,-0.6561601329032647
533.9000000000069,58.77467137484421,0.4504454930694217,-0.6561596671147112
535.0000000000068,58.883616064821794,0.4506133585122414,-0.6561673203417939
536.100000000007,58.993083027093334,0.4512010301798858,-0.6561048310425113
537.2000000000069,59.10199368344174,0.4496307630151274,-0.6581399404017856
538.300000000007,59.21000109104332,0.4500754896674788,-0.6581274692466224
539.4000000000069,59.31848089992771,0.44997066260043006,-0.6581501964247791
540.5000000000069,59.42881383555696,0.445657223118194,-0.6581244032035078
541.600000000007,59.53708148158644,0.44530597905238334,-0.6594601627587289
542.700000000007,59.64546424356786,0.44593769243883585,-0.6604741110272339
543.800000000007,59.755718883453525,0.4478022083265314,-0.6607894316137539
544.900000000007,59.864090359810554,0.4494996742687828,-0.6620999444758238
546.000000000007,59.9730944769962,0.4485018701933311,-0.6621005082913394
547.1000000000071,60.082407611491746,0.45272126189384454,-0.6634198793076442
548.2000000000071,60.19149134889683,0.45519494236561253,-0.6647299291336366
549.300000000007,60.2990863750411,0.4558231231076464,-0.6660687027382943
550.4000000000071,60.40897066484174,0.45730006621077557,-0.6660499100170982
551.500000000007,60.51733899516002,0.4565426169927558,-0.6659565211501448
552.6000000000072,60.62665813772988,0.4575300799359978,-0.6683593965508359
553.7000000000071,60.73596392267427,0.45729135681348787,-0.6683602580287098
554.8000000000072,60.84282652308828,0.4611377013296659,-0.669669808130561
555.9000000000071,60.95327497413333,0.4614972423094481,-0.6696280621843274
557.0000000000072,61.06209544560525,0.46500554941066385,-0.6697507557192193
558.1000000000072,61.17090545995033,0.4642460673232135,-0.6705434573498463
559.2000000000072,61.28019091122603,0.4669624341120816,-0.6706762122798531
560.3000000000072,61.389303879427956,0.4668493960803398,-0.6722963735542447
561.4000000000073,61.49902986878911,0.4661883116152834,-0.6723001436267997
562.5000000000073,61.606826435763715,0.4640742192694537,-0.6749727209649787
563.6000000000073,61.716190647823936,0.4601534495064524,-0.6768696332385198
564.7000000000073,61.824197297257115,0.4567782677716413,-0.676919922249716
565.8000000000073,61.93461740538716,0.4515263815539644,-0.6769800670962862
566.9000000000074,62.04347900094836,0.4467923672350771,-0.6782365734527209
568.0000000000074,62.15264581994346,0.4419504662028797,-0.6795499830563441
569.1000000000074,62.260191018366115,0.43372604335602405,-0.6783562778894172
570.2000000000073,62.36969688074541,0.425096865061254,-0.6795501392285521
571.3000000000073,62.47925981167678,0.4175073767214478,-0.6782403302779776
572.4000000000074,62.58800632675318,0.4091070756027406,-0.6795504067914773
573.5000000000074,62.69801093788986,0.40577941335778434,-0.6808600052991842
574.6000000000074,62.80547875773079,0.3980309396978169,-0.681200367633779
575.7000000000074,62.91660864047496,0.38996768735774456,-0.6811317361127518
576.8000000000075,63.02626049197392,0.3858447155065938,-0.6838732820252189
577.9000000000075,63.13529915354374,0.3825628855164066,-0.6839034149494543
579.0000000000075,63.243847986787515,0.37744183687116517,-0.683838648394512
580.1000000000075,63.35462874563851,0.3738994387959629,-0.6828533518353948
581.2000000000075,63.463184024939615,0.3726872001309157,-0.6858147083650357
582.3000000000076,63.572254687539676,0.37198887464291674,-0.6858099419842949
583.4000000000076,63.68322641771203,0.3711277364914408,-0.6854889857138122
584.5000000000076,63.79125295843471,0.3701555244822914,-0.6868005142591649
585.6000000000076,63.90133404835637,0.3689652351565673,-0.6854953883086279
586.7000000000077,64.01048034939089,0.36554858530634504,-0.6851496848261367
587.8000000000077,64.1197375120457,0.3703421759391954,-0.6868058478537766
588.9000000000076,64.22926211838359,0.37052384420720597,-0.6894141859045759
590.0000000000076,64.33847301486605,0.37092503755766704,-0.6894280929746301
591.1000000000076,64.44724789171195,0.3719311048579158,-0.689430647989921
592.2000000000077,64.55755464699143,0.37366624857054354,-0.6894321253529361
593.3000000000077,64.66809162798131,0.376781693559749,-0.6895583029136665
594.4000000000077,64.77750173040458,0.3771858455271344,-0.6908033927336263
595.5000000000077,64.88632490954336,0.3798673315185671,-0.6921144181355263
596.6000000000078,64.99590515160244,0.38108596498611835,-0.6909722451643501
597.7000000000078,65.10435142058287,0.3852122895018618,-0.692077425213121
598.8000000000078,65.21259572581701,0.3863480522416076,-0.6933798247366703
599.9000000000078,65.32423458603243,0.389658439222239,-0.6947009327131002
601.0000000000078,65.43258416325266,0.39183914970849965,-0.6946453246742954
602.1000000000079,65.54187668079378,0.3973169946412646,-0.6960732592324206
603.2000000000079,65.651079143159,0.399804907202298,-0.6947074706989369
604.3000000000079,65.7600009249074,0.4015977040644406,-0.6939301454619811
605.4000000000078,65.8698000807281,0.40670247641330415,-0.6945901798070024
606.5000000000078,65.97927773356274,0.4111211346332512,-0.6972301579196749
607.6000000000079,66.08765133957334,0.4153935182329529,-0.698661398664099
608.7000000000079,66.19668065364355,0.42047042129489,-0.6998692705268241
609.8000000000079,66.30710740575142,0.4254225181749638,-0.7010817832159164
610.9000000000079,66.41578658847797,0.4289072163617137,-0.7015095284206545
612.000000000008,66.52461688196972,0.43609638585526556,-0.7028299114058503
613.100000000008,66.63482730211193,0.43941868250036065,-0.7041384574459215
614.200000000008,66.74414474380094,0.4463648433931705,-0.7055652652219209
615.300000000008,66.85312407844498,0.4563806385604078,-0.7061103365450969
616.400000000008,66.96239150615104,0.4584202372844761,-0.7081086714376359
617.5000000000081,67.073496356307,0.46576168970986964,-0.7090899398753647
618.6000000000081,67.18199910625489,0.47011094233434647,-0.7103967596788463
619.7000000000081,67.29196178443578,0.4795127645613244,-0.7104803323986784
620.8000000000081,67.40094463562676,0.48890715682716535,-0.7117198503778344
621.9000000000082,67.51121996208035,0.4953303641935982,-0.7147851464297719
623.0000000000082,67.61980132773726,0.5007672045602911,-0.7156700627563746
624.1000000000081,67.72992311578717,0.5096260032338212,-0.7169899580688752
625.2000000000081,67.83979702560957,0.51972822641424,-0.7189647021123049
626.3000000000081,67.94981772415267,0.5264068077550512,-0.7212537271755797
627.4000000000082,68.05776540263368,0.536153959195039,-0.7220319980191636
628.5000000000082,68.16846642044953,0.5439772668470548,-0.7242261176864964
629.6000000000082,68.27817502283908,0.5534526289327794,-0.7231759213616655
630.7000000000082,68.38743622268062,0.556819059592076,-0.7254685123845768
631.8000000000083,68.49776526971317,0.5685500108247172,-0.7280759318890739
632.9000000000083,68.60811667694416,0.5760683099826374,-0.7293908445442381
634.0000000000083,68.71796919217107,0.5864151701281777,-0.7321022089368872
635.1000000000083,68.82711537013586,0.5945367717317387,-0.7352126504875733
636.2000000000083,68.93781010857234,0.6027018681252039,-0.737429204276137
637.3000000000084,69.04647095886085,0.6131321285060258,-0.7395619045596162
638.4000000000084,69.15717267801983,0.6243033582644988,-0.7410683493092338
639.5000000000084,69.26697085101421,0.6355194406983892,-0.7445221619102584
640.6000000000083,69.37697984680962,0.6453522671745463,-0.7472710495806489
641.7000000000083,69.48724013807612,0.6567543930271411,-0.7501245495784032
642.8000000000084,69.5969904549694,0.6683879249172083,-0.7521394438944666
643.9000000000084,69.70681932048609,0.6765411106516427,-0.7552196576047172
645.0000000000084,69.81607197313704,0.6903902400292536,-0.7561582917793279
646.1000000000084,69.92545756463893,0.6991133405413,-0.7588220478192458
647.2000000000085,70.03538665776178,0.7113122296273477,-0.7625269962883934
648.3000000000085,70.14565415766995,0.7251404650150459,-0.765755039496002
649.4000000000085,70.2551536980678,0.7393428354643208,-0.7698593368806885
650.5000000000085,70.36554414537581,0.7532086152199342,-0.7731639769233087
651.6000000000085,70.47549321551715,0.7672713096092895,-0.7777499743381222
652.7000000000086,70.58574871019829,0.7764074320704848,-0.779624495175717
653.8000000000086,70.69474269618034,0.7901235965406513,-0.7829088547341918
654.9000000000086,70.80389368720247,0.8047011527177018,-0.7862759870611211
656.0000000000086,70.91417906746643,0.8219063038076513,-0.7901570295536002
657.1000000000087,71.0238156607778,0.8383024404990327,-0.7935803423448582
658.2000000000087,71.13385125751282,0.8536703139736168,-0.7991192908200131
659.3000000000086,71.24371465801673,0.8671615543451984,-0.8022520089546288
660.4000000000086,71.35368780224104,0.8838198302333156,-0.8064829690998345
661.5000000000086,71.46265704161405,0.8987615604837067,-0.812072922707519
662.6000000000087,71.57292351587826,0.9155546751901489,-0.8166092053154141
663.7000000000087,71.68321255253304,0.9321627983930303,-0.8196733608281259
664.8000000000087,71.79283358305825,0.9443608516546586,-0.8266039719850253
665.9000000000087,71.90211132792518,0.96295775338587,-0.8296571862981752
667.0000000000088,72.01228433655955,0.9823017503190519,-0.8358622200144805
668.1000000000088,72.1226143904177,1.002232788171078,-0.8404651318216683
669.2000000000088,72.23248540427232,1.0206180614377056,-0.843860275485437
670.3000000000088,72.34222949814666,1.0405895969955032,-0.8501300540960659
671.4000000000088,72.4497836766028,1.0601160270819432,-0.8585962987613653
672.5000000000089,72.56156359267949,1.0828365217563598,-0.8641859132745195
673.6000000000089,72.67115651196276,1.106034175022614,-0.8687055119389759
674.7000000000089,72.78228797896624,1.1281535484751466,-0.8743201562191811
675.8000000000088,72.89234436944345,1.1512329453208745,-0.8807697767463272
676.9000000000088,73.00130444027059,1.1752486857231514,-0.887187971232609
678.0000000000089,73.11146265267043,1.1998157128521976,-0.8940086030092846
679.1000000000089,73.22063677853292,1.2289042170664308,-0.9006733377220217
680.2000000000089,73.33211812742199,1.2474640022276138,-0.9076146560272216
681.3000000000089,73.44148981121604,1.2737767106806568,-0.9129719319520571
682.400000000009,73.55288424833117,1.297225605071545,-0.9209190510881711
683.500000000009,73.662016451195,1.3276530107752107,-0.9298133841522378
684.600000000009,73.77219214518776,1.3529548346497249,-0.9376162545612039
685.700000000009,73.88347319595405,1.381966163738209,-0.945592162326633
686.800000000009,73.99386895946422,1.4092998040791076,-0.9541573029405526
687.9000000000091,74.10367759092871,1.438696373125645,-0.96286469193543
689.0000000000091,74.21375155101016,1.4710579101614816,-0.9697437451832047
690.1000000000091,74.32392869092601,1.4968750589335957,-0.980285932941185
691.2000000000091,74.43341191537246,1.5259496194447513,-0.9880626450342938
692.3000000000092,74.54478703618423,1.5537328936584909,-0.9970706260239237
693.4000000000092,74.65448678038163,1.579850526349681,-1.006920065427209
694.5000000000091,74.76393524174087,1.609993415831416,-1.0160355612815621
695.6000000000091,74.87580100322661,1.6415031299703828,-1.0259282830363339
696.7000000000091,74.9863292331998,1.6698578198114646,-1.034493372421207
697.8000000000092,75.09462073620216,1.700766382875483,-1.0448900195234003
698.9000000000092,75.20562000673021,1.7241271860829204,-1.0558789341856927
700.0000000000092,75.31655858128771,1.7542217606978907,-1.0668673715048036
701.1000000000092,75.42531035630594,1.774652006302214,-1.0781223896846925
702.2000000000093,75.53668061294225,1.8002629103294434,-1.0892137769309334
703.3000000000093,75.64714476670773,1.8245171956858006,-1.1008497008791358
704.4000000000093,75.75719234454309,1.84515084517255,-1.1121426680865851
705.5000000000093,75.86721190403827,1.8603937536097976,-1.123694673600327
706.6000000000093,75.97735119666112,1.875311338964409,-1.1345337243368299
707.7000000000094,76.0871908800871,1.8893100252223234,-1.1455412061353711
708.8000000000094,76.19810427978658,1.8998678464342664,-1.1535417382797797
709.9000000000094,76.30850113773374,1.9088411067289535,-1.1673672240050643
711.0000000000093,76.4193919469405,1.9086157502849113,-1.1795567591170015
712.1000000000093,76.53050576598707,1.904440660782385,-1.190999802744836
713.2000000000094,76.64037759095547,1.8941271129518178,-1.2031389299192101
714.3000000000094,76.75031000676998,1.8833362070458857,-1.214121310045012
715.4000000000094,76.8605975554004,1.8589475098514727,-1.2258964443317817
716.5000000000094,76.97098665679623,1.8254129361329257,-1.2364739501421549
717.6000000000095,77.08090646381314,1.7840953395915373,-1.2480913526719477
718.7000000000095,77.19112843340382,1.7274751295056752,-1.257033145960949
719.8000000000095,77.30073202437457,1.6545435878931358,-1.2678349827138273
720.9000000000095,77.41104301005232,1.5538759701214717,-1.2760102515991978
722.0000000000095,77.52091453597552,1.4186190074638665,-1.2856275146186005
723.1000000000096,77.63185043971777,1.2211636992130912,-1.2942208253331926
724.2000000000096,77.74063502952225,0.9836585443004868,-1.2974285151809286
725.3000000000096,77.85084678856144,0.7464393632517992,-1.3026941705864736
726.4000000000096,77.96029347005974,0.5737699686295452,-1.3047612871700793
727.5000000000097,78.06980393977004,0.4560846102552132,-1.308722218101698
728.6000000000097,78.17970302593781,0.38470027130818063,-1.3093554085392443
729.7000000000096,78.29019856192137,0.3544154106304408,-1.3100307476425908
730.8000000000096,78.39970675194583,0.334738363991428,-1.3100359212234989
731.9000000000096,78.51038908394699,0.32300009437782906,-1.3100295877649675
733.0000000000097,78.62119727165604,0.3170382795596387,-1.308725134584925
734.1000000000097,78.73107743240142,0.3113770118327557,-1.3091598284680366
735.2000000000097,78.84043708413132,0.31293116946915744,-1.3087365242359845
736.3000000000097,78.95029132016882,0.3117551644542007,-1.3113616285496397
737.4000000000098,79.06140462787762,0.31414073086954386,-1.3126773440375707
738.5000000000098,79.17142601736822,0.3155417440211268,-1.3124307528482642
739.6000000000098,79.2822008604994,0.3172363106485223,-1.3113792915418268
740.7000000000098,79.3917502058659,0.31653840679276857,-1.3127225774708622
741.8000000000098,79.50243916473543,0.31589641042948546,-1.3138860794238991
742.9000000000099,79.61293385199268,0.3169604021463992,-1.3138783795936733
744.0000000000099,79.72346619278498,0.31917425552456535,-1.3125576494019935
745.1000000000099,79.83104896260286,0.32036749027703304,-1.3125600250090206
746.0000000000099,79.92290830720404,0.32016602698075314,-1.3125552715963988