File: 01_Data/XPS_Foam_Board/STA/N2/10K_min/XPS_Foam_Board_STA_N2_10KData_221017_R1.csv
##Temp./Â°C,Time/min,DSC/(mW/mg),Mass loss/mg
51.0,10.712412555574128,0.01685137157599259,0.015866286915728445
52.100000000000016,11.104954942275137,0.05155849345407004,0.011644337349091316
53.20000000000003,11.3584002704589,0.07710832142071045,0.01406090140488736
54.30000000000005,11.571152635334444,0.09543687266237066,0.016002526914626003
55.40000000000006,11.751943142577908,0.10649811587112556,0.01535993193154983
56.50000000000008,11.932552570745178,0.12129199742850827,0.013017621155059445
57.600000000000094,12.093169223149877,0.13092777373429665,0.01429506614550391
58.70000000000011,12.24986327709297,0.1367180852155545,0.014718972722905121
59.800000000000125,12.400462327624394,0.14170633174904945,0.0156825853930167
60.90000000000014,12.546080263046978,0.14789841164867235,0.015191284240124503
62.000000000000156,12.690778872407412,0.15419132567710148,0.015220440574463368
63.10000000000017,12.828275257019673,0.16044898148477515,0.015553371470042876
64.20000000000019,12.967987531068417,0.16311523759618152,0.016220207804871656
65.30000000000021,13.103810778552626,0.1677358677157943,0.016264320969237467
66.40000000000022,13.236206127635004,0.1712795589913938,0.016163079206859443
67.50000000000023,13.36639348089609,0.1746442015095908,0.017030554255417663
68.60000000000025,13.495186486513449,0.17878830218920116,0.016159317766462067
69.70000000000027,13.625276467356677,0.18059807568935127,0.01645887488940012
70.80000000000028,13.753355048528139,0.18595605701137696,0.016581451890870902
71.90000000000029,13.876804343216335,0.18691273417078724,0.01790556672620891
73.00000000000031,14.00243895189029,0.1899955737656187,0.017648429079687666
74.10000000000034,14.122411419779953,0.19297906256938124,0.01634509112985416
75.20000000000034,14.250345558982605,0.19641369841687983,0.01768057383287669
76.30000000000035,14.37229181168049,0.19913428145537337,0.01717113321751107
77.40000000000038,14.493490765908986,0.20357806494018904,0.01763988957133389
78.5000000000004,14.61210669112799,0.20733032819879482,0.017177341781855482
79.6000000000004,14.733042156293312,0.21201812011412446,0.01882833824827923
80.70000000000041,14.850102169306208,0.21530369090236,0.017550555080287467
81.80000000000044,14.968717246863168,0.22087035136854416,0.018681473773688673
82.90000000000046,15.085121478765318,0.22429016306768446,0.017452246357755108
84.00000000000047,15.203322203220925,0.22683435947960018,0.018742283950207828
85.10000000000048,15.318028349098169,0.22511010584258928,0.017961371903551182
86.2000000000005,15.43370527046851,0.22226629851458402,0.016131283279451125
87.30000000000052,15.547476057384289,0.21630584684509868,0.016412839968661608
88.40000000000053,15.660673927687592,0.21161744438341967,0.01756165936443832
89.50000000000054,15.774459887289604,0.2090564970802118,0.018876579999749232
90.60000000000056,15.887353424745454,0.2076717664500124,0.018863733105903613
91.70000000000059,15.996348694351363,0.21037393058286458,0.018878312890240778
92.8000000000006,16.110832738646476,0.2116174646388217,0.018862441155381937
93.9000000000006,16.221602898148593,0.21584339473984404,0.017824026761549483
95.00000000000063,16.33319015264508,0.21739008153500916,0.01756013006427981
96.10000000000065,16.440813398167048,0.22357079754779585,0.016842277103934933
97.20000000000066,16.552069988478006,0.226235580338076,0.017544812469657778
98.30000000000067,16.664873552622765,0.23208021398073575,0.017880365987828384
99.40000000000069,16.770885172208406,0.23773392241237812,0.01890213084732828
100.50000000000071,16.884515408483992,0.24636552756103092,0.018855034477076593
101.60000000000072,16.99346659876605,0.25341646656593075,0.017838724961924513
102.70000000000073,17.101935084550416,0.2619008967571007,0.01887360637215174
103.80000000000075,17.211455964852288,0.27121292187438684,0.018901812819827057
104.90000000000077,17.320489304509,0.2788865003103215,0.01897983942260506
106.00000000000078,17.42981896794613,0.2842800256375311,0.01899009721622935
107.10000000000079,17.537864433746684,0.2885942165959007,0.017860510902704796
108.20000000000081,17.645817973163627,0.2913636915816513,0.017678026574999173
109.30000000000084,17.75355708859888,0.2914803445106994,0.0189800693778146
110.40000000000084,17.862507276732632,0.2902219346301387,0.019781343690627118
111.50000000000085,17.97009851791243,0.2904150782414615,0.019991100196038225
112.60000000000088,18.077993632904686,0.28782061400856196,0.018910777760896558
113.7000000000009,18.18668338570394,0.29053660895583644,0.018980011908858785
114.8000000000009,18.295165290383395,0.2895286612983121,0.019782721864030073
115.90000000000092,18.401920515995528,0.29057358341978157,0.01963886884465804
117.00000000000094,18.509596308367115,0.29214409352365034,0.019639814038982628
118.10000000000096,18.617211655780416,0.2918547137090126,0.018286743719013288
119.20000000000097,18.724361203335242,0.29210334706880037,0.018330548889715637
120.30000000000098,18.83139923202698,0.292524687389066,0.017842964622333035
121.400000000001,18.937464633199646,0.2941413871431995,0.018319855354611114
122.50000000000102,19.0449625507944,0.29475490239911284,0.017322676295478345
123.60000000000103,19.153291007972,0.29447481130975106,0.01831790663060584
124.70000000000104,19.25893393436681,0.295224185809001,0.018326359086714206
125.80000000000106,19.365940337607604,0.29787797918638026,0.01964338089684503
126.90000000000109,19.471795390671364,0.2965348491305929,0.01734036375891712
128.00000000000108,19.579233941306303,0.2999636060607216,0.015956347739492394
129.1000000000011,19.68591181004562,0.3010578255314912,0.017330886139379054
130.20000000000113,19.791348941405893,0.30001242525570126,0.017334225309325824
131.30000000000115,19.89921944998646,0.3007907965192721,0.018659758420059624
132.40000000000117,20.004154084788208,0.30225025627290925,0.017314533342752902
133.50000000000117,20.110493147638838,0.30412437980787044,0.01733947066896313
134.6000000000012,20.21613229485114,0.3041246521987796,0.01786265300271861
135.7000000000012,20.321419535763717,0.3059124636381434,0.017682923745735657
136.8000000000012,20.428018745278013,0.30553399486027066,0.017330895527942758
137.90000000000123,20.534070246163225,0.30736007002391874,0.018645410917201843
139.00000000000125,20.63881891016631,0.3074441630017105,0.017339653987350268
140.10000000000127,20.743562436220312,0.3059609250732356,0.017339905148396895
141.2000000000013,20.848389979515048,0.3079319535484094,0.01739959056529461
142.3000000000013,20.95399639980913,0.30833694108266996,0.017336001951048452
143.4000000000013,21.05873621703529,0.31057682131151887,0.016027227606662642
144.50000000000134,21.164031393468857,0.311520472925797,0.01733005976926094
145.60000000000133,21.26882420827999,0.31302310866047667,0.016019954678875514
146.70000000000135,21.37393055688994,0.31351698429746166,0.01732637520067737
147.80000000000138,21.47780443111164,0.31448730451858387,0.015999811755348148
148.9000000000014,21.582157523933397,0.31570970470495663,0.01601982022855708
150.00000000000142,21.687816021886153,0.31603785869054235,0.015046662006266587
151.10000000000142,21.792496871717887,0.31714709671915453,0.016538235013729974
152.20000000000144,21.89721794559337,0.31829647750822165,0.017342957650374302
153.30000000000146,22.00145535323524,0.3177760306513633,0.01601941402005025
154.40000000000146,22.105775341979736,0.320651643136461,0.014710069898323574
155.50000000000148,22.21044879565869,0.3202754068138737,0.01602013924594292
156.6000000000015,22.315009903486853,0.31975049337098105,0.016020180105897452
157.70000000000152,22.418158566615677,0.3208095292538802,0.016260509934098444
158.80000000000155,22.523101522857402,0.31903965161201564,0.01602008314583081
159.90000000000154,22.627745787939,0.3211176924394721,0.016019910424013517
161.00000000000156,22.73391597032173,0.320447503341851,0.016014798755513482
162.1000000000016,22.837729895503433,0.321830933600068,0.0160199840026527
163.20000000000158,22.942505693274622,0.320915557573628,0.01600587122556174
164.3000000000016,23.04461575875047,0.3196924609639976,0.014790340206975117
165.40000000000163,23.15177770715431,0.3198126103149286,0.016009810254571377
166.50000000000165,23.255835350181343,0.3221449148908865,0.015502633181461611
167.60000000000167,23.360724551781882,0.3222931814751374,0.01602001839692857
168.70000000000167,23.465263840072282,0.32206826915081177,0.01468482072291355
169.8000000000017,23.56776201412819,0.3193913058336134,0.014700161942745815
170.9000000000017,23.67366378276352,0.3202628262470205,0.015052246080564657
172.0000000000017,23.779478625822854,0.3204490653855071,0.016020065859272847
173.10000000000173,23.884144599703447,0.3191739323145396,0.016017427586042743
174.20000000000175,23.988219515805692,0.3202140560328811,0.014699715763178745
175.30000000000177,24.093125595637343,0.3212415022148236,0.013717601589653405
176.4000000000018,24.19829520297812,0.3198761536265273,0.01372055415550566
177.5000000000018,24.302042317702153,0.3215307675667556,0.014379567720080644
178.6000000000018,24.406694322979178,0.3217406768519676,0.014687749402060746
179.70000000000184,24.5120273892412,0.3200754974394786,0.014687066470397525
180.80000000000183,24.616612154094472,0.32078115152621145,0.013379957760896843
181.90000000000185,24.72045606198764,0.31947404665200696,0.014812543695918556
183.00000000000188,24.82534442551676,0.3205160021427754,0.014958272580834375
184.1000000000019,24.92808829949652,0.3205124316389131,0.014156371067954865
185.20000000000192,25.034058394545116,0.32163160931031787,0.013496301872390148
186.30000000000192,25.136802528831687,0.32167992075853546,0.013500051431057258
187.40000000000194,25.242317250682063,0.3207253827337798,0.012345513003599429
188.50000000000196,25.34664848348968,0.3222301285184017,0.012180052026678823
189.60000000000196,25.45054050522547,0.323439452655661,0.01218005197920835
190.70000000000198,25.554911305886165,0.32311369130092826,0.012095021628040215
191.800000000002,25.659510993480065,0.32311745431961136,0.012179982034934866
192.90000000000202,25.76350545418356,0.3253404407161765,0.01250987094127698
194.00000000000205,25.866909348209592,0.324222092811685,0.013170306789796804
195.10000000000204,25.973270111858493,0.32442809860249067,0.013170213142223552
196.20000000000206,26.076449917957962,0.3253385353085334,0.012171789877163164
197.3000000000021,26.180780399569116,0.3261311323012812,0.012496664350599929
198.40000000000208,26.282381884314834,0.3277619492382893,0.011318749506355807
199.5000000000021,26.388181167376555,0.328306645484979,0.011839832824745322
200.60000000000213,26.493086139662303,0.32821580602417555,0.011839044307212276
201.70000000000215,26.597912685706902,0.32980507279443594,0.010529829904935006
202.80000000000217,26.70259740195123,0.3289150717700682,0.010529833145909606
203.90000000000217,26.806315866147187,0.32917282146130855,0.009475215963400174
205.0000000000022,26.909441856994572,0.33097617290950176,0.009209164409214488
206.1000000000022,27.014480520710237,0.3308067965917274,0.009866812025781435
207.2000000000022,27.11762878802177,0.332729177202692,0.010324073354711416
208.30000000000223,27.223194572144664,0.32886420536029326,0.008887994068891736
209.40000000000225,27.326741157332606,0.3294053591756103,0.010202856722391296
210.50000000000227,27.43069605628361,0.3300704684162482,0.00854983944383303
211.6000000000023,27.53535485130582,0.33032876470794714,0.007318164324718879
212.7000000000023,27.639343411916975,0.3322778001057557,0.007900142114515951
213.8000000000023,27.743120292927063,0.3332710851997228,0.007900141000567906
214.90000000000234,27.847833855371565,0.3304024306553706,0.007900437468361332
216.00000000000233,27.951218583774477,0.3335533209674224,0.006580080290448542
217.10000000000235,28.05529777526783,0.33468184765529524,0.006580140997623829
218.20000000000238,28.15981004583134,0.3330675254437942,0.006580798637899399
219.3000000000024,28.26568014864518,0.3348887098232259,0.005271262485036843
220.40000000000242,28.36937552061078,0.332711087716143,0.00592222579986057
221.50000000000242,28.473713288937276,0.3355363843443084,0.004930072964464571
222.60000000000244,28.578094013700056,0.33638126909723254,0.004930064337487217
223.70000000000246,28.682742270269305,0.3365681180894677,0.005824548184490297
224.80000000000246,28.78742811913382,0.33815760460513694,0.005262146746948915
225.90000000000248,28.892014307230276,0.33768090586746674,0.0038103989456041987
227.0000000000025,28.99583976203248,0.33910799384680074,0.0036100640475362766
228.10000000000252,29.10037540727405,0.340266693405749,0.003610064000376667
229.20000000000255,29.204894404994253,0.34077136444337464,0.00361149555012652
230.30000000000254,29.306736238552986,0.34023279709115706,0.0022879838746643344
231.40000000000256,29.41403711452945,0.34146177774447256,0.0008978414882792052
232.5000000000026,29.518627588108515,0.3411905072210825,0.00230006384954784
233.60000000000258,29.622493039183485,0.3409898704090699,0.002372693055912478
234.7000000000026,29.727758314906108,0.3414584364720614,0.0009800638541657136
235.80000000000263,29.831135042531,0.3415298628389726,0.000980063999999281
236.90000000000265,29.93543286137028,0.34187970145300056,0.000980065759174309
238.00000000000267,30.040421707350546,0.34080764946699116,-0.0003424641291580599
239.10000000000267,30.145441038228853,0.3425525622879895,-0.0016326829881245786
240.2000000000027,30.24982626327441,0.3410436963039075,-0.0003398589038559052
241.3000000000027,30.35455493675545,0.3405563771376857,-0.0029457590955708213
242.4000000000027,30.458676848748617,0.3397400536076798,-0.0042898932467654305
243.50000000000273,30.564052724863654,0.33954808567156625,-0.004291906297618553
244.60000000000275,30.668848270352772,0.3399501599126735,-0.0029726893849320035
245.70000000000277,30.77327559611552,0.3402551318382575,-0.003517058716417054
246.8000000000028,30.878222933692665,0.33910745091522615,-0.004289969621340539
247.9000000000028,30.98276971124341,0.3418349146728657,-0.004295011983182384
249.0000000000028,31.087475176422558,0.34144114100554296,-0.00493588280158086
250.10000000000284,31.19250015378816,0.34170066605269983,-0.006589407585792628
251.20000000000283,31.297307929307674,0.34363177596498273,-0.006589870233457695
252.30000000000285,31.401099413429005,0.3430373931601872,-0.006925412245142759
253.40000000000288,31.50679321952814,0.3435218469462082,-0.008250135635027966
254.5000000000029,31.611464075076935,0.3435568518950496,-0.007586143163312187
255.60000000000292,31.71699225331404,0.34281909795019966,-0.00824002045638661
256.7000000000029,31.819379094015023,0.3411409227572496,-0.008246431078159588
257.8000000000029,31.926193549805532,0.3428820634043748,-0.010320042617779634
258.90000000000293,32.03121869952184,0.3427832675542333,-0.010982543017727053
260.00000000000296,32.13606576925422,0.34370667909198266,-0.011540080081149817
261.100000000003,32.23910262428651,0.3420623259969422,-0.012331312988354881
262.200000000003,32.34577735849978,0.3421446782652835,-0.01286007999565264
263.300000000003,32.45104713014874,0.3430994013076916,-0.012860080010593578
264.40000000000305,32.555522201465735,0.3442365378233048,-0.012890426209548167
265.50000000000307,32.659300186421795,0.34482161037689607,-0.014560239096996774
266.6000000000031,32.76517432332967,0.34610391602483925,-0.016480655723308146
267.7000000000031,32.8697392212505,0.3446148502673092,-0.017800036104050676
268.8000000000031,32.97494770169224,0.34580362147624816,-0.01779554530425731
269.9000000000031,33.07836765022317,0.3466155674202488,-0.019113531764983982
271.0000000000031,33.183729277144984,0.34696011700289225,-0.019119917468497505
272.10000000000315,33.28953867138482,0.34909061689338416,-0.020740975262737216
273.2000000000032,33.3937411893383,0.34784254539707254,-0.022070049618792886
274.30000000000314,33.49793176899419,0.34773591066948845,-0.021563929698531936
275.40000000000316,33.603690881138405,0.34829533913451455,-0.02239994965036729
276.5000000000032,33.709244259097446,0.34921097159403425,-0.02377484109868444
277.6000000000032,33.8141293524884,0.349834966761976,-0.02628881710012454
278.70000000000323,33.91827947322198,0.3503669429068056,-0.026375580629677486
279.80000000000325,34.023786604522044,0.34999092827247846,-0.02766953056547905
280.9000000000033,34.12762330943379,0.3495984742259187,-0.029307830674408564
282.0000000000033,34.23385741978157,0.35066978021295536,-0.030310187170718983
283.1000000000033,34.33793858254634,0.3511191509974867,-0.03149712448913178
284.20000000000334,34.444306069692466,0.3524938150104795,-0.031630094138208165
285.30000000000337,34.54834876321996,0.35142416060859577,-0.03162725469194072
286.40000000000333,34.654511082556276,0.3523824197894109,-0.0339628310057698
287.50000000000335,34.75907642881917,0.3548940607855034,-0.03426012785845334
288.6000000000034,34.86456875022809,0.3539596653564719,-0.03567197805211997
289.7000000000034,34.96980890103025,0.35521387154240247,-0.03821916308643303
290.8000000000034,35.07502471492004,0.3572320830915873,-0.03953589136762403
291.9000000000034,35.1822473454363,0.35662100994070545,-0.03855639246228826
293.0000000000034,35.28598937493228,0.3577110344262411,-0.03949224998166123
294.10000000000343,35.392008999920876,0.3541940234430303,-0.03985864895976121
295.20000000000346,35.496558044928975,0.35564423107099935,-0.03997253311422799
296.3000000000035,35.602328313448865,0.35554021396925745,-0.042499871092156916
297.4000000000035,35.70701389870883,0.3547606519311362,-0.042897413972038834
298.5000000000035,35.8120133877649,0.35607095393719945,-0.043821259785654654
299.60000000000355,35.918292481830896,0.3556017521856175,-0.04512488576947771
300.70000000000357,36.02313001519865,0.35682481461582416,-0.046382228932274394
301.8000000000036,36.13000130386234,0.3570045621454178,-0.04777010805247528
302.9000000000036,36.23459841900213,0.35878389850919085,-0.048760725123358384
304.0000000000036,36.34057887478127,0.3593687467209107,-0.051413012816460046
305.1000000000036,36.446839759234706,0.35935518890252865,-0.05129303991589129
306.2000000000036,36.55125030070539,0.3598474836656949,-0.05269997689653394
307.30000000000365,36.65393985111564,0.36182972541278924,-0.05401907409980389
308.4000000000037,36.76214556051721,0.36216764591721556,-0.05401994377263186
309.5000000000037,36.866476258901784,0.36440469764036526,-0.05572035474029402
310.60000000000366,36.97274350244333,0.36214390395315704,-0.05697919484745029
311.7000000000037,37.07882148891659,0.3643595190422597,-0.058300127295673576
312.8000000000037,37.18272497048127,0.36766184354944553,-0.060975842611685316
313.90000000000373,37.290000952475644,0.3669684167930218,-0.05962018683776549
315.00000000000375,37.39580372462285,0.36685704624112253,-0.06092709823814424
316.1000000000038,37.50136855998689,0.3673742444079321,-0.062122552595092806
317.2000000000038,37.606827631707766,0.36819345575336276,-0.06497615649872746
318.3000000000038,37.71335223496954,0.3701367687334477,-0.06583520280657318
319.40000000000384,37.818568168900015,0.3712056031955291,-0.06720068883446029
320.5000000000038,37.92545055082013,0.3727559184279339,-0.07023104074386621
321.60000000000383,38.03141009581933,0.37558398744198596,-0.07016042920743049
322.70000000000385,38.13675258040038,0.3754661665623958,-0.07213092596104076
323.8000000000039,38.24227315987984,0.37825693270612826,-0.07477524421336046
324.9000000000039,38.34859866641149,0.3807634980193771,-0.07476493866634515
326.0000000000039,38.454080114978716,0.38104450482670643,-0.07711172358789486
327.10000000000394,38.55981400619656,0.3845000313449508,-0.07782084345528961
328.2000000000039,38.66703734578787,0.3876360948522426,-0.07899942704742369
329.30000000000393,38.77216096623971,0.3883853811275281,-0.08299342586892111
330.40000000000396,38.87929842629078,0.3908954144776331,-0.08431767833287651
331.500000000004,38.98418805406104,0.3928775340977116,-0.08650060610844834
332.600000000004,39.089902450387505,0.39607646575376315,-0.0869598593130414
333.700000000004,39.197196941438854,0.3980257055239682,-0.08956685925794616
334.80000000000405,39.30227564570501,0.3978886388138065,-0.09362241067618182
335.90000000000407,39.4083026177456,0.4014162290945285,-0.09639993822883497
337.0000000000041,39.514367584023354,0.4039136146269191,-0.09640012506750795
338.10000000000406,39.6201846478667,0.4058589655575531,-0.09772773945142754
339.2000000000041,39.726372930885574,0.40913076114875424,-0.10170243960149872
340.3000000000041,39.83231245033746,0.41210349160952064,-0.10421853959614458
341.4000000000041,39.938004945550986,0.41511815173313904,-0.10708464123848449
342.50000000000415,40.04564028262132,0.4187327584007406,-0.10955124499908608
343.6000000000042,40.15116423361885,0.4220257045903934,-0.11346667539916977
344.7000000000042,40.25719318498721,0.4261840553380612,-0.11622332119176981
345.80000000000416,40.3640569468854,0.4287292267489282,-0.11902612779337707
346.9000000000042,40.46935017922371,0.4337264323363081,-0.1216489687330875
348.0000000000042,40.57686786749124,0.43668824640620685,-0.12430790314857054
349.10000000000423,40.68151104092138,0.44102934954267226,-0.12693463373143876
350.20000000000425,40.788991708013626,0.4448460183000444,-0.13251874882942172
351.3000000000043,40.89461415140535,0.450201368575695,-0.1369447617268662
352.4000000000043,41.000965878445314,0.4536186523529898,-0.13825555345061513
353.5000000000043,41.10685081860272,0.4596104128249199,-0.1415664793680409
354.60000000000434,41.21400077585406,0.4653524290410291,-0.14871299053389375
355.7000000000043,41.3199990528025,0.47026387828133104,-0.15293017123482233
356.80000000000433,41.42761352202588,0.4743159463539701,-0.15725032020127605
357.90000000000435,41.533663759369745,0.48234179630691476,-0.16116777726773224
359.0000000000044,41.639565805907694,0.49039055549931176,-0.16745455950482402
360.1000000000044,41.747848214788,0.4978616919885685,-0.17341554138860582
361.2000000000044,41.85346865841321,0.5066294355639169,-0.17784377315364397
362.30000000000445,41.959513734520954,0.5162210228969205,-0.18296731812035683
363.4000000000044,42.067609865248535,0.5246099135746243,-0.18933584174344498
364.50000000000443,42.1743714422783,0.5350202620681758,-0.19877874521838423
365.60000000000446,42.2798194924766,0.5468257731291318,-0.20419306607385446
366.7000000000045,42.38731298628125,0.5601372646176647,-0.2101527261465561
367.8000000000045,42.4938327254664,0.5713677131452711,-0.2199885364479397
368.9000000000045,42.60134373506079,0.5846167472106656,-0.22982877102446908
370.00000000000455,42.70788849445218,0.6026871184622297,-0.23825646885742513
371.10000000000457,42.81415435147538,0.6170678247214403,-0.2489793764884154
372.2000000000046,42.91960639560945,0.6330383417971938,-0.25849730500274903
373.30000000000456,43.02919886807745,0.6508575509619777,-0.2694156946176913
374.4000000000046,43.13559709988139,0.6711492961174719,-0.28163664838219704
375.5000000000046,43.242420507602056,0.6913842981832262,-0.29222541978754224
376.6000000000046,43.34999897127933,0.7112487913405829,-0.3065199807030057
377.70000000000465,43.45664014142829,0.7361682046113016,-0.3208838441993911
378.8000000000047,43.56088173227091,0.7605880348068137,-0.33528399947241594
379.9000000000047,43.67160052743373,0.7887726990514123,-0.34974303488044534
381.00000000000466,43.776172732297944,0.8185072770850722,-0.3686294710801379
382.1000000000047,43.88568052684616,0.8503852651102135,-0.38711376173838463
383.2000000000047,43.99206282813133,0.8877042663419289,-0.40703304266902096
384.30000000000473,44.099446554904944,0.9239770084549115,-0.42623616106201734
385.40000000000475,44.20647634435706,0.9672433483923295,-0.4500992258968832
386.5000000000048,44.31466905754657,1.00964320254749,-0.47255229667504617
387.6000000000048,44.41910280039099,1.0557062978584306,-0.49897492614997807
388.7000000000048,44.52909841470246,1.1077838409681415,-0.5275257619483678
389.80000000000484,44.63678226144047,1.1640375891199568,-0.555791939973024
390.9000000000048,44.74411165831355,1.2183002523511957,-0.5866091102111275
392.00000000000483,44.85216729835677,1.280747358009175,-0.6221816046919435
393.10000000000485,44.95999898948163,1.3453776055270017,-0.6600198050197457
394.2000000000049,45.06734515339347,1.4175955263393138,-0.6970870847414572
395.3000000000049,45.1753120397216,1.491220803138641,-0.737357096863303
396.4000000000049,45.2821256622824,1.5682423175982154,-0.7812774831839326
397.50000000000495,45.39028938086814,1.6545074451739894,-0.8282568474035754
398.6000000000049,45.49845629837637,1.7419495858147127,-0.8798799604683154
399.70000000000493,45.60561420371619,1.8378259728076904,-0.9350295644975124
400.80000000000496,45.71365905929059,1.934657453274723,-0.9931646035709392
401.900000000005,45.821907339651816,2.036479206728621,-1.0548967045187583
403.000000000005,45.930508790137466,2.141988590458668,-1.11712666690527
404.100000000005,46.03715295372497,2.2457893891895786,-1.1865750422316923
405.20000000000505,46.145924947869545,2.355213657733496,-1.2602337683067701
406.30000000000507,46.25303146025641,2.463653630677612,-1.3363099620570407
407.4000000000051,46.36197712020936,2.57373149726268,-1.4190728580837941
408.50000000000506,46.46990053288596,2.690471670581862,-1.5077916665070732
409.6000000000051,46.578726077331176,2.799444192095546,-1.5984449044019309
410.7000000000051,46.68774365015461,2.893698393843499,-1.6927804477153017
411.8000000000051,46.794695567958726,2.9867893315314613,-1.7932508082512304
412.90000000000515,46.903045155961735,3.0707728900874214,-1.8958422900662848
414.0000000000052,47.01090149160489,3.1346142406504933,-1.9992509396949987
415.1000000000052,47.12073591516056,3.1926063170713257,-2.1085340871437266
416.20000000000516,47.22607442328413,3.2331503843723315,-2.216341449627174
417.3000000000052,47.33636680471076,3.2501928865099394,-2.3312255488533156
418.4000000000052,47.44444309968851,3.252782423411141,-2.442064592772935
419.50000000000523,47.55275290846406,3.2341581158752866,-2.5570738308792516
420.60000000000525,47.659697053153266,3.1871190517798276,-2.6653942396174664
421.7000000000053,47.767852476298806,3.1205557611179104,-2.775541531448009
422.8000000000053,47.87578085097089,3.0337361051690794,-2.8852156885196183
423.9000000000053,47.983343400638006,2.918083293952752,-2.987946039482855
425.00000000000534,48.090000000000536,2.7821532536235827,-3.0856800030006184
426.1000000000053,48.19686137241023,2.6261259125595857,-3.1810932479515013
427.20000000000533,48.30394993379108,2.4528003800100677,-3.2697866228018597
428.30000000000535,48.411137543219965,2.265977544930324,-3.3511443084640185
429.4000000000054,48.517490735359154,2.073762315579948,-3.4287588765682155
430.5000000000054,48.62355513511886,1.8792728943317338,-3.496093800186439
431.6000000000054,48.72999899224028,1.6865971721317727,-3.5573035559929354
432.70000000000545,48.835819716512816,1.4998796437516595,-3.6140288216168703
433.8000000000054,48.939788283257066,1.3262951881987215,-3.660055930857191
434.90000000000543,49.048345183874325,1.1586261765802566,-3.705431308331149
436.00000000000546,49.15248914819638,1.0143262277617096,-3.743690724126207
437.1000000000055,49.25999895497149,0.8772694917284839,-3.7751457651061564
438.2000000000055,49.3674058749514,0.7608430051968,-3.8047943693152937
439.3000000000055,49.47336006591084,0.6570715771441409,-3.8290538695029586
440.40000000000555,49.580000996059894,0.5672908421243752,-3.850650105527186
441.50000000000557,49.68727295687202,0.49116179806031834,-3.8695565563299286
442.6000000000056,49.793996282571776,0.42329438528191526,-3.885539104290779
443.70000000000556,49.90139447842268,0.3701185518246253,-3.8991032053079717
444.8000000000056,50.008557202645335,0.32170687435825784,-3.9117586494492356
445.9000000000056,50.11587719851534,0.2773493413418926,-3.9207379849056294
447.0000000000056,50.222708442773374,0.2448409844469222,-3.93012279187452
448.10000000000565,50.331150560074356,0.21752197196617568,-3.9392777325357686
449.2000000000057,50.435820406603824,0.1933945147917262,-3.9459262462399183
450.3000000000057,50.5436144365308,0.16972915191209553,-3.952323745061734
451.40000000000566,50.65113518709708,0.1514208376600295,-3.958329021482569
452.5000000000057,50.75855448646762,0.13212948441170697,-3.963027301749781
453.6000000000057,50.867109113942526,0.11926989880590588,-3.9674931904153783
454.70000000000573,50.974879237237225,0.10792893388086156,-3.9717704405447796
455.80000000000575,51.08213423663527,0.09567931788368123,-3.974541343127205
456.9000000000058,51.18978717988103,0.08657845893603278,-3.977879845560606
458.0000000000058,51.29720677748344,0.07754465551247192,-3.979922884177244
459.1000000000058,51.40524606795586,0.07198031602435162,-3.9827501802125203
460.20000000000584,51.51322798091412,0.06460034429320882,-3.9851388179736644
461.3000000000058,51.62138627879645,0.0574813784353273,-3.98776788966652
462.40000000000583,51.729594019428546,0.04931965163243679,-3.990399869680708
463.50000000000585,51.83736179781391,0.037462381764259534,-3.991706307031453
464.6000000000059,51.94447236748611,0.026554499249250463,-3.9917206712817883
465.7000000000059,52.053849854664726,0.018117040046359723,-3.9917199396710155
466.8000000000059,52.1611696688847,0.01456236236784103,-3.993040180150442
467.90000000000595,52.270000922409615,0.01536146878742195,-3.992049768504126
469.0000000000059,52.376945494359944,0.014142573505077638,-3.992049829016114
470.10000000000593,52.48555978156562,0.01631127844284075,-3.993742978732695
471.20000000000596,52.59323081744569,0.017455268574811278,-3.994030297871964
472.300000000006,52.70160615492514,0.013034766942974008,-3.993693930800472
473.400000000006,52.80969175628193,0.011686704254952884,-3.993699962999157
474.500000000006,52.91848663312678,0.011113234810972927,-3.9936999885201536
475.60000000000605,53.027148239411964,0.013244776398732117,-3.992379983342095
476.70000000000607,53.13406962493835,0.012987319878359327,-3.993699840141882
477.8000000000061,53.24283253877918,0.010471813943996766,-3.993699864521778
478.90000000000606,53.35106630709674,0.009021987135082732,-3.9950713643704345
480.0000000000061,53.45897152946794,0.0030963189364094923,-3.993040142563405
481.1000000000061,53.56857185011313,0.0027327572549880053,-3.99303996252833
482.2000000000061,53.67683428322409,0.000980451436721097,-3.9940671049718435
483.30000000000615,53.78467884288658,0.000997047912365434,-3.9940301925620396
484.4000000000062,53.89316578499181,-0.001127044523812848,-3.9937326421649715
485.5000000000062,54.00156454399718,-0.001992608407084595,-3.9946923927860922
486.60000000000616,54.10990202110966,-0.0031765097511465834,-3.994689863997803
487.7000000000062,54.218797021323326,-0.001741976759603192,-3.9946900534265053
488.8000000000062,54.327340314620955,-0.0018530927665300068,-3.993369644028269
489.90000000000623,54.435983344611124,-0.003199806768642066,-3.9942861181324694
491.00000000000625,54.54550397588826,-0.0014932551175546038,-3.994349920025622
492.1000000000063,54.65383521591815,-0.004024932652474167,-3.994348375720966
493.2000000000063,54.76238581066593,-0.003523814663655145,-3.9934373816519675
494.3000000000063,54.86909037604607,-0.003777658871883194,-3.992709864513902
495.40000000000634,54.97921154563654,-0.0035749903678218287,-3.992707171931074
496.5000000000063,55.08871733648898,-0.00734837383152398,-3.994020001870141
497.60000000000633,55.196781990541005,-0.005026798589787385,-3.9940199969999943
498.70000000000636,55.30542216467597,-0.00551504264364322,-3.994019997
499.8000000000064,55.41478065329018,-0.005752055908638365,-3.9940199970000085
500.9000000000064,55.52318737507635,-0.0050938123260393375,-3.994019985161533
502.0000000000064,55.63136655621175,-0.003846592261711801,-3.9953402277692938
503.10000000000645,55.740282979364494,-0.003989505727322595,-3.995339898136309
504.2000000000064,55.84828492811248,-0.0021652096861588532,-3.996008766830129
505.30000000000643,55.95711240206164,-0.0011267724665490197,-3.9953403460811208
506.40000000000646,56.06541910041151,-0.003581107927622562,-3.994686268074706
507.5000000000065,56.17427546369203,-0.0020834249907213387,-3.994743918504029
508.6000000000065,56.283202447325685,-0.0038873830095704776,-3.997326050317872
509.7000000000065,56.39208775448654,-0.0015004724949048143,-3.996325080726843
510.80000000000655,56.49928883687657,-0.001252094211910526,-3.996329799002158
511.90000000000657,56.61037340416875,-0.0022618203749471544,-3.996329798999997
513.0000000000066,56.71890840865943,-0.0005224046541865146,-3.9963298034025407
514.1000000000065,56.827268152145166,-0.0010211070432417646,-3.997197058366603
515.2000000000066,56.93589926086304,-0.0011654022045436419,-3.9973201070909745
516.3000000000065,57.0451312176682,-0.0003761197080680567,-3.9973200976801144
517.4000000000067,57.15411670026946,0.001172857907458802,-3.9960108432834596
518.5000000000066,57.26386672436924,-0.0004051855546769456,-3.996010106999592
519.6000000000067,57.37294393689228,3.924021351031648e-05,-3.9960101070000005
520.7000000000066,57.481906693885904,-0.0021793807308615465,-3.996010107000099
521.8000000000067,57.589807685213586,-0.0045283980798225265,-3.996010124274922
522.9000000000067,57.69947076998996,-0.002459102298244198,-3.996990209290067
524.0000000000067,57.808564621065536,-0.0008739848012920826,-3.996990163061387
525.1000000000067,57.91767620363066,-0.0004350878173686734,-3.9962132365768603
526.2000000000068,58.026998831199464,-0.0005383793644785362,-3.99701429281638
527.3000000000068,58.135334463275676,-0.003961546190488718,-3.9986465741735904
528.4000000000068,58.245303916774965,-0.0016560362260307215,-3.9973203752342226
529.5000000000068,58.35430295996184,-0.0006865474360958634,-3.997320141021158
530.6000000000068,58.46319284962786,-0.0024643157469180776,-3.9972811760191647
531.7000000000069,58.572604405117374,5.942271304681945e-06,-3.9960948140627863
532.8000000000068,58.68087751335414,0.0011431081524216902,-3.995943912407593
533.9000000000069,58.78989674392511,0.0014596696369857387,-3.997320169407455
535.0000000000068,58.89881335766703,7.17798343542464e-05,-3.9953353438516794
536.100000000007,59.00716588906275,0.0006244211058101801,-3.995604014507127
537.2000000000069,59.11631586113605,0.0008234301175796821,-3.9973514880755032
538.300000000007,59.22555255881403,0.0017698852564513867,-3.9973198085656474
539.4000000000069,59.332700323227655,0.0018141597766045958,-3.996010843489948
540.5000000000069,59.441060050999646,0.0009230231634470565,-3.9973198897526254
541.600000000007,59.55198010411373,-0.0003059409940289193,-3.9963292942775643
542.700000000007,59.660747087899246,0.0001995692834596552,-3.997320085693421
543.800000000007,59.77043163078189,-0.00017876108815451097,-3.997320118996376
544.900000000007,59.87945133344703,-0.0005332524130957639,-3.997312280691468
546.000000000007,59.989224454761136,0.000695038191526387,-3.9960313153524156
547.1000000000071,60.09840806993901,0.0014945018182924708,-3.9969901957511604
548.2000000000071,60.20657985596012,0.0008200435546277252,-3.9969901960004215
549.300000000007,60.31547557086703,0.0023976229936972793,-3.9969894377219863
550.4000000000071,60.42584039723345,0.004145371772304118,-3.998299954146714
551.500000000007,60.534897377960405,0.004725205999500437,-3.99835251607495
552.6000000000072,60.64326200854923,0.003787289262904947,-3.9976499225196918
553.7000000000071,60.75242475846238,0.002622812944062969,-3.997649922000119
554.8000000000072,60.86235159837746,0.003563906639046488,-3.99764967797942
555.9000000000071,60.970790310696096,0.002542939293491031,-3.9986400977256595
557.0000000000072,61.08049043013162,0.005105439323437211,-3.9986407230573806
558.1000000000072,61.19064763207326,0.0034500963692934983,-3.9976501453421243
559.2000000000072,61.299299720168555,0.0030406724922105166,-3.997650153000009
560.3000000000072,61.40865558051399,0.004576148771649691,-3.9976501530000004
561.4000000000073,61.51742965962282,0.0026538899489700896,-3.997650153000006
562.5000000000073,61.62715591478141,0.0034466229565240925,-3.9976501410544945
563.6000000000073,61.73695588406401,0.005450131495665755,-3.9976187499590594
564.7000000000073,61.84607990921878,0.004899758782200503,-3.998975961845483
565.8000000000073,61.95601003791704,0.004005995467235346,-3.9976501284831163
566.9000000000074,62.064703798841705,0.0032027082780777816,-3.9976501310000327
568.0000000000074,62.17411682023624,0.005166573678232034,-3.99765008311989
569.1000000000074,62.283392466640294,0.0038077093848544186,-3.9986401566388494
570.2000000000073,62.39255122805266,0.0035105875450567314,-3.9989699972163444
571.3000000000073,62.50214208067118,0.006335220579616885,-3.998958870327932
572.4000000000074,62.61045321412542,0.005998409008197481,-3.9976951674800048
573.5000000000074,62.72089460939923,0.005469986827120299,-3.9976500073463845
574.6000000000074,62.82972404794757,0.006281076101748551,-3.9976500336973193
575.7000000000074,62.93932210104526,0.0036514540063410372,-3.9975755995931226
576.8000000000075,63.047222468292055,0.0037023811127796513,-3.998956201878099
577.9000000000075,63.156355446900584,0.001601333625909418,-3.996583089930432
579.0000000000075,63.266657227486405,0.0034620954122280834,-3.997532331781402
580.1000000000075,63.375972922200816,0.0025192965674180057,-3.99862998995059
581.2000000000075,63.48537078669806,0.003833288544438873,-3.997651670845825
582.3000000000076,63.593830852340524,0.00506082793092355,-3.997649826771845
583.4000000000076,63.70427344777464,0.006130138163913501,-3.9979791911582034
584.5000000000076,63.81506254102377,0.007510651808207758,-3.9979980268708735
585.6000000000076,63.92391799102236,0.007082835836840107,-3.9989700431444337
586.7000000000077,64.0339313288645,0.005839695920490495,-3.997654972014277
587.8000000000077,64.14428605883896,0.004232420460919539,-3.9986393386511376
588.9000000000076,64.25450467885878,0.005074745859869556,-3.99765006460914
590.0000000000076,64.36459086652818,0.006091252591338581,-3.9976720693539343
591.1000000000076,64.47445413288247,0.0036142850989577813,-3.9976511608253165
592.2000000000077,64.58431233744551,0.003905602246617401,-3.9986393078347557
593.3000000000077,64.69421294281223,0.0032905122887297855,-3.999860381152287
594.4000000000077,64.80463864770745,0.005435631457878509,-3.9986400126991843
595.5000000000077,64.91421075056915,0.0040156101461010785,-3.997624042203203
596.6000000000078,65.02359467607006,0.003865570084682579,-3.998868677179224
597.7000000000078,65.13297256421335,0.0038725283524034815,-3.9989699317240115
598.8000000000078,65.24186227875641,0.004108713520579177,-3.9999509407064986
599.9000000000078,65.35349386024653,0.004591423186183108,-3.9999500009973663
601.0000000000078,65.46384344639637,0.0057739061743238285,-3.999951403575453
602.1000000000079,65.5728031978261,0.0033621085603636747,-3.9986301179421866
603.2000000000079,65.68263771957453,0.0022228264751292803,-3.998282329339478
604.3000000000079,65.79316670665239,0.0008041481725173938,-3.997649942156572
605.4000000000078,65.90217757919449,0.0006216490754284987,-3.997656965014
606.5000000000078,66.01207243106273,-0.0013536396090930713,-3.9973201802662266
607.6000000000079,66.1219228750984,0.001013942409590185,-3.997650635599716
608.7000000000079,66.23109742380387,0.0024276688972545424,-3.99983372115101
609.8000000000079,66.34175436951978,-0.0005763156790422608,-3.9999499744956464
610.9000000000079,66.45144184642385,-0.0019059675395034503,-3.998652665798495
612.000000000008,66.56047884425884,0.004360052706588791,-3.9986396167088265
613.100000000008,66.67000194458548,0.002239063260621399,-3.9987349635528546
614.200000000008,66.77990237776204,0.002952835607467952,-3.9983098028315784
615.300000000008,66.89010107159459,0.0026228966614152416,-3.998309803
616.400000000008,66.99999795950441,0.0010887586542136507,-3.998309803
617.5000000000081,67.10918447713702,0.001122047654887437,-3.9983098029983655
618.6000000000081,67.21894134460518,0.002576368012689345,-3.9983139958125293
619.7000000000081,67.3284759019777,0.0009165878550381201,-3.998555645847807
620.8000000000081,67.43872737229596,9.795480667607048e-05,-3.999957615206758
621.9000000000082,67.54790396152089,-0.003127851852372965,-3.99961444826689
623.0000000000082,67.65782378781856,-0.0017792632891243665,-4.000168220294896
624.1000000000081,67.76763082058699,-0.0024388381838473805,-3.999683203556879
625.2000000000081,67.87749838892202,-0.0027312697637693617,-3.997620973178935
626.3000000000081,67.98730438391853,-0.0036495523108457384,-3.9969635296233834
627.4000000000082,68.09791180526767,-0.0023576040969703893,-3.99830912567381
628.5000000000082,68.20673201045932,-0.0022766062944863386,-3.9983099140006013
629.6000000000082,68.31629750540597,-0.0019599419121425488,-3.9983099139831064
630.7000000000082,68.42759167701185,-0.003853669405284199,-3.9983480055225877
631.8000000000083,68.53728333544541,-0.001910370875072176,-3.9973199144701996
632.9000000000083,68.64729088710546,-0.0028058297974558055,-3.9973199748129358
634.0000000000083,68.75603420913669,-0.0005295801059319594,-3.998638942801293
635.1000000000083,68.86645307632456,-0.0022953444001571066,-3.9986398150002724
636.2000000000083,68.97662306544079,0.0003026458350170458,-3.9986398943689245
637.3000000000084,69.08661225294672,-0.0006033750612153277,-3.997329610107981
638.4000000000084,69.19691513047219,-0.001477710905520624,-3.9969898966463466
639.5000000000084,69.30711156262409,-0.0032106102197303477,-3.9983108076697276
640.6000000000083,69.41784882671126,-0.0019637297145952415,-3.99732036939222
641.7000000000083,69.5275434150344,-0.00263940446376576,-3.99831006096521
642.8000000000084,69.63672998454537,-0.004419055900078184,-3.9983101230024207
643.9000000000084,69.74778603558737,-0.0036590040722898065,-3.998301507661968
645.0000000000084,69.85743732996559,-0.003887679911076747,-3.9976498340437785
646.1000000000084,69.96813929993601,-0.0037749004268899933,-3.9976490264352744
647.2000000000085,70.07798748340738,-0.00373750445126686,-3.996989847917292
648.3000000000085,70.18705465264951,-0.005479149920468607,-3.997970919108746
649.4000000000085,70.29906532561552,-0.005083923138434532,-3.9992900678977112
650.5000000000085,70.40980822287705,-0.007718337204860259,-3.9979800487332096
651.6000000000085,70.52000201242498,-0.00524869011728446,-3.997650079984027
652.7000000000086,70.62833347486148,-0.005743207356126212,-3.99765007999994
653.8000000000086,70.73969585731454,-0.005454484059006948,-3.997650103627881
654.9000000000086,70.85028770408972,-0.006710092560662018,-3.9989698678217245
656.0000000000086,70.96039236449744,-0.008020926401356876,-3.997650172105678
657.1000000000087,71.07087885187153,-0.009724738888689854,-3.997649986678394
658.2000000000087,71.18085703892149,-0.01125324463284838,-3.996655601627918
659.3000000000086,71.29147898032623,-0.011907307217587926,-3.9979797851317604
660.4000000000086,71.40210551628806,-0.010962484079677814,-3.999285313268861
661.5000000000086,71.51271444560832,-0.010945551393751973,-3.9979798798178776
662.6000000000087,71.62248619079924,-0.013197206042133036,-3.997979882000015
663.7000000000087,71.73349022308652,-0.015357948361190199,-3.9979798408924907
664.8000000000087,71.84300090335051,-0.011535023211957207,-3.9983017299993815
665.9000000000087,71.95344928271595,-0.014308991455615483,-3.998101988108539
667.0000000000088,72.06339548861284,-0.01468698123493295,-3.997970037811037
668.1000000000088,72.17473495951424,-0.015066544641482715,-3.9981477585152017
669.2000000000088,72.28406321080236,-0.01832944771197753,-3.9986654401893333
670.3000000000088,72.39534369668175,-0.016536752390163167,-3.9976498793809534
671.4000000000088,72.50616376500204,-0.01645355719363384,-3.9976487619876644
672.5000000000089,72.61625137804954,-0.017329165472864005,-3.9976279912319863
673.6000000000089,72.72709738435526,-0.018655397665431228,-3.998973024993949
674.7000000000089,72.83830573508507,-0.01975409670132855,-3.997659314485167
675.8000000000088,72.94905117699557,-0.021709922618721622,-3.9970006307626824
676.9000000000088,73.05627848676727,-0.01988255977928577,-3.996985487336771
678.0000000000089,73.16814175871869,-0.02007114418477074,-3.998310050783484
679.1000000000089,73.28000207351488,-0.019673230949385556,-3.9969901515106465
680.2000000000089,73.39010884980881,-0.019138349395997345,-3.997635885340297
681.3000000000089,73.50129127753196,-0.02029043287308485,-3.9976535496368584
682.400000000009,73.61115645425933,-0.022963630585780215,-3.9963300471712757
683.500000000009,73.7218693934083,-0.026826392090089968,-3.996330048000003
684.600000000009,73.82888280082841,-0.02642849034757866,-3.9963300444782814
685.700000000009,73.94187408923288,-0.029620044208769514,-3.995489641378946
686.800000000009,74.05201044954612,-0.028816618358604162,-3.9966699489092017
687.9000000000091,74.16270965541041,-0.028709235670807742,-3.9979523823546113
689.0000000000091,74.27320570426511,-0.030353174663684812,-3.997980081893929
690.1000000000091,74.38416282363097,-0.03152170766945417,-3.9976482016767156
691.2000000000091,74.4943418374539,-0.030624609932770386,-3.996330082078971
692.3000000000092,74.60459920029658,-0.029819927492905407,-3.997646561537426
693.4000000000092,74.7149466838529,-0.03249000736692875,-3.996330082279557
694.5000000000091,74.82430251543668,-0.03215369128390466,-3.9963300819983316
695.6000000000091,74.93484033534199,-0.030493195463796474,-3.9963350106279596
696.7000000000091,75.04517366451809,-0.03396592863512793,-3.995010082821364
697.8000000000092,75.15415583862298,-0.035282556757222694,-3.996328154803017
698.9000000000092,75.26620828505698,-0.03625099636722484,-3.9963299830013557
700.0000000000092,75.3772387770939,-0.03611029962840573,-3.9963291228223787
701.1000000000092,75.48743243020178,-0.03725106247867682,-3.995953009629729
702.2000000000093,75.59744697679798,-0.03805727433617123,-3.996339866283721
703.3000000000093,75.7082430878314,-0.03827778817294347,-3.9963398749823775
704.4000000000093,75.8188048261745,-0.040359484098436926,-3.9972681377691694
705.5000000000093,75.92867893797977,-0.040635137928848764,-3.9973306080672195
706.6000000000093,76.03887889793373,-0.04031869987521708,-3.9960150046122287
707.7000000000094,76.1505765701623,-0.04086713754463156,-3.9976509345255336
708.8000000000094,76.26125702408336,-0.042082829954277035,-3.9963300196839127
709.9000000000094,76.37207918882807,-0.04166603217966591,-3.9963300170034777
711.0000000000093,76.48305319900632,-0.04367293374067882,-3.9963205756609588
712.1000000000093,76.59349385431365,-0.04701023494107448,-3.995968391856738
713.2000000000094,76.70356847315722,-0.045131273116918336,-3.9963299177690566
714.3000000000094,76.81450900849984,-0.045649602912467,-3.9963150119858586
715.4000000000094,76.92486669169647,-0.048806466662543846,-3.996328404817024
716.5000000000094,77.03534075771027,-0.049777419354452346,-3.997648399358266
717.6000000000095,77.14700127538438,-0.05080795092096613,-3.9963289575429237
718.7000000000095,77.25704028598211,-0.051042272578733394,-3.9966592236052385
719.8000000000095,77.3678518304028,-0.054219806823699424,-3.996340130479603
720.9000000000095,77.47781399507906,-0.05906253087222191,-3.9963996358545266
722.0000000000095,77.58893892625217,-0.06023546462298601,-3.9966550720285747
723.1000000000096,77.69854102801037,-0.061235546281569686,-3.9968507518575724
724.2000000000096,77.80863510531532,-0.06276067001535124,-3.997969867094436
725.3000000000096,77.92010536588566,-0.06500028387819579,-3.997625295487885
726.4000000000096,78.02939470035827,-0.06459762373284827,-3.9979801533681396
727.5000000000097,78.1419430186333,-0.06516891614133258,-3.9979801563051387
728.6000000000097,78.25053003889474,-0.06756764997502918,-3.996660629516124
729.7000000000096,78.36073733058875,-0.06934560546016488,-3.997955271859495
730.8000000000096,78.47212903118715,-0.06926418546082047,-3.997243218756238
731.9000000000096,78.58249316900628,-0.07279961842271176,-3.9979800576193782
733.0000000000097,78.69254873694543,-0.07735671089779561,-3.9979480756895884
734.1000000000097,78.80317806333254,-0.07700544587453828,-3.996990061062579
735.2000000000097,78.91373216294755,-0.07768094136002957,-3.9969905997831385
736.3000000000097,79.0244660433082,-0.07874056044604172,-3.9982821325276614
737.4000000000098,79.13499998283687,-0.08477516971457155,-3.9979799629400037
738.5000000000098,79.24665796433024,-0.08529402400645547,-3.9979800114634787
739.6000000000098,79.3575527710423,-0.08696853997661402,-3.996669528455273
740.7000000000098,79.46810207990717,-0.09027261897677585,-3.9979801779724315
741.8000000000098,79.57626381369124,-0.09202757388660288,-3.997980095947241
742.9000000000099,79.68980433774176,-0.09459784589369147,-3.9969519930785915
744.0000000000099,79.8004868414719,-0.0954403006243777,-3.998330791856782
745.0000000000099,79.90090114677263,-0.09749826355056879,-3.99831000728867