File: 01_Data/XPS_Foam_Board/STA/N2/10K_min/XPS_Foam_Board_STA_N2_10KData_221018_R2.csv
##Temp./Â°C,Time/min,DSC/(mW/mg),Mass loss/mg
51.0,10.67,0.009852911208709791,0.0010537736321003521
51.80000000000001,11.000000000000007,0.04019168075365065,0.0023322562454737295
52.60000000000002,11.213967921041041,0.06578752829641532,0.003705141213377061
53.400000000000034,11.38614610471264,0.08151777733431653,0.004435908831851965
54.200000000000045,11.540398797880252,0.09989676194681874,0.004545475066329185
55.00000000000006,11.682977941728547,0.11289828666011292,0.0034032614219268176
55.80000000000007,11.813387346520784,0.12222291322299039,0.003518853991347104
56.60000000000008,11.937875277159447,0.1298069645560318,0.004481823419584252
57.40000000000009,12.055010155732816,0.13830232955931532,0.004186148313833016
58.2000000000001,12.172080431821493,0.1450408044645315,0.0038667141234842717
59.000000000000114,12.283480014273728,0.14859829231130894,0.0025210095273657807
59.800000000000125,12.390570261636416,0.1546103038890596,0.004217257484413928
60.600000000000136,12.499865205814759,0.16049159102570631,0.004635663143420565
61.40000000000015,12.603816261317416,0.1650323937301459,0.003584819330500366
62.20000000000016,12.706633606740152,0.16939547679619693,0.004234708840718415
63.00000000000017,12.808812354673403,0.1711533660655491,0.003383627635298314
63.80000000000018,12.908282099803836,0.1761199106217306,0.005088082043943398
64.6000000000002,13.008876895689454,0.1832743839802493,0.003630190211373119
65.4000000000002,13.106272135587377,0.18160164631530473,0.0037092824952402736
66.20000000000022,13.20328085585227,0.18748214931807383,0.0025738321049075807
67.00000000000023,13.295927658963857,0.18982000472381189,0.0036201172474550347
67.80000000000024,13.392949637970489,0.1931272474025194,0.00359262374336744
68.60000000000025,13.488399038514276,0.1944485023383311,0.006272228291960946
69.40000000000026,13.582573985412829,0.1959569553061946,0.005082353027938691
70.20000000000027,13.674265231869688,0.19963761999536134,0.004969039216478066
71.00000000000028,13.766302166388037,0.20420785692645427,0.004949790338532711
71.8000000000003,13.856681374411915,0.2063531871416362,0.0049081891224456164
72.6000000000003,13.946291908461243,0.21036376754583497,0.004935065294746188
73.40000000000032,14.040000000000033,0.21275761713264485,0.004507535097494131
74.20000000000033,14.130356235406746,0.2167245542553744,0.004947961480947782
75.00000000000034,14.216628596455744,0.21973046544057317,0.004549482098782143
75.80000000000035,14.307155104815436,0.22305484016677557,0.004900469841694566
76.60000000000036,14.395214739297458,0.22417967424728613,0.005233241988920501
77.40000000000038,14.483535502699633,0.2271379854242095,0.006304043363633216
78.20000000000039,14.569690447187277,0.2303454777171503,0.00568702695429657
79.0000000000004,14.658288157523831,0.2324844094439792,0.005786785330390121
79.80000000000041,14.7429838413605,0.2389378456025656,0.006279156975333766
80.60000000000042,14.829792007081663,0.2412448152914084,0.006261306181531534
81.40000000000043,14.914689941604879,0.2450369812741111,0.004960744245604332
82.20000000000044,14.998195600942347,0.2488109531204299,0.005385717127316614
83.00000000000045,15.085516962717756,0.24888970898992502,0.004905089637897042
83.80000000000047,15.171317435958816,0.25182170166612494,0.00369516516024726
84.60000000000048,15.252859256916114,0.2522455941142757,0.0038013477867537837
85.40000000000049,15.337310156846295,0.2521588688551226,0.003642462149408665
86.2000000000005,15.422474342423556,0.24893547859006393,0.004184294333983818
87.00000000000051,15.503829790980095,0.244621721962069,0.004962785290937077
87.80000000000052,15.587495677080197,0.24241363737488442,0.0053204534727400166
88.60000000000053,15.670112716243214,0.23870560786716388,0.006260242276277417
89.40000000000055,15.753461346348702,0.23531744267714105,0.004980018978243628
90.20000000000056,15.83452071315475,0.23475493271158887,0.00495959301837523
91.00000000000057,15.915399228058478,0.23469783548392542,0.004930505013153841
91.80000000000058,15.997730421651298,0.23496583571300045,0.004940608376420741
92.60000000000059,16.078502698812223,0.2390515332328984,0.005077767157754209
93.4000000000006,16.161170564824545,0.2411206997387274,0.0050663080560262586
94.20000000000061,16.242182433372818,0.24422605284533094,0.0036324250242438794
95.00000000000063,16.323680795583847,0.24522258113809092,0.0036601329063277177
95.80000000000064,16.401823916452386,0.25119079155840796,0.004234542416877041
96.60000000000065,16.483742248662754,0.25283943793165276,0.005006920319146513
97.40000000000066,16.563436552011783,0.25523666229526754,0.0049399800464078325
98.20000000000067,16.64397392370047,0.2597252087668529,0.004053384094468537
99.00000000000068,16.72426059906756,0.26392077162759486,0.0035390792520710868
99.8000000000007,16.804278476721507,0.2709468816050601,0.00493005664720636
100.6000000000007,16.88338717025678,0.2756662473522612,0.0035831563493506913
101.40000000000072,16.962339133570676,0.2815340302152082,0.004946762800946747
102.20000000000073,17.04292834923568,0.2872885194211072,0.003630089937729508
103.00000000000074,17.121590637902997,0.292548535961791,0.0023098805967216585
103.80000000000075,17.201764317933396,0.30119339804002987,0.0036951074284945484
104.60000000000076,17.280539668821376,0.30499299560641235,0.005273116985242243
105.40000000000077,17.358332479383428,0.30838862672550904,0.0065847260402112084
106.20000000000078,17.437667988208055,0.31714739733912656,0.004845587328325962
107.0000000000008,17.5172090341175,0.31962998414809907,0.0036066324276378126
107.80000000000081,17.595681001301745,0.31972552214027217,0.0034494743855244536
108.60000000000082,17.674549599985937,0.32256718761147174,0.0036265959706689443
109.40000000000083,17.753682577311544,0.32418896692853616,0.004982185418898055
110.20000000000084,17.832345907884395,0.32535857894568854,0.0022689299986291545
111.00000000000085,17.912483310837576,0.3268788463463903,0.003619994714067598
111.80000000000086,17.988684615511982,0.3280311263185113,0.0032060864949960965
112.60000000000088,18.067718773748627,0.3288269020728677,0.0036242003987023708
113.40000000000089,18.14662586059461,0.33095838228655394,0.002307000152237393
114.2000000000009,18.223348181603296,0.33287940061795707,0.003629205099386912
115.00000000000091,18.30169398986559,0.332461573224504,0.004950455240673612
115.80000000000092,18.381188237487873,0.3321633700716973,0.004926744634757618
116.60000000000093,18.458151266161256,0.3328444536554056,0.003550564796812594
117.40000000000094,18.537354598252467,0.3343155353128764,0.004940109160839867
118.20000000000095,18.615834680777027,0.3348720044573845,0.003957653711749831
119.00000000000097,18.693769740541946,0.3347897340087588,0.0036200511105932698
119.80000000000098,18.771256890253948,0.3343344471633066,0.003046954176434191
120.60000000000099,18.84872625719347,0.33663923339874646,0.0036288932524590756
121.400000000001,18.927867530354952,0.33892409362832454,0.0036317056339933984
122.20000000000101,19.00556178667643,0.3384178490350753,0.0023095918515836367
123.00000000000102,19.083608899413225,0.34008258298432203,0.003707906651859716
123.80000000000103,19.16058763343414,0.33848337175987264,0.0023089325170699837
124.60000000000105,19.23908274561389,0.3401499113540626,0.0036199047596001677
125.40000000000106,19.315708999473795,0.33911038533020965,0.003617968290787754
126.20000000000107,19.39311117227146,0.3408509386070493,0.0023146043434185692
127.00000000000108,19.471077164297697,0.3427925507526052,0.003620149905511738
127.80000000000109,19.54864580622329,0.3421887491672212,0.0036379554382661716
128.6000000000011,19.626413727163598,0.34497452894641667,0.0036301608562889776
129.4000000000011,19.703288521113187,0.3462118786563283,0.0036301599963484144
130.20000000000113,19.780474842224596,0.3458769763801457,0.003630094706387421
131.00000000000114,19.858288744634677,0.3464124184515942,0.002670159666018357
131.80000000000115,19.935028236047046,0.3483088626698415,0.003616648579478632
132.60000000000116,20.012756061448314,0.34748221874787644,0.003631367676656172
133.40000000000117,20.089530907283887,0.35040409271109074,0.003565427351770012
134.20000000000118,20.167247038302534,0.35033848416744795,0.003619919066227606
135.0000000000012,20.242557058839132,0.34960603587507444,0.0036177566219639523
135.8000000000012,20.32032054141488,0.35022527539179293,0.0023094711970168547
136.60000000000122,20.396471981721394,0.3495668830973626,0.002309897355606605
137.40000000000123,20.474393015946113,0.35093816274682377,0.0009840507434306645
138.20000000000124,20.547218384734535,0.3506072700177455,0.0009899205447871928
139.00000000000125,20.628450042127984,0.3534282651928038,0.0018287509423839943
139.80000000000126,20.703562669277467,0.35361741558912096,0.0013146006203794691
140.60000000000127,20.78165507083211,0.355162675721029,0.0009900898484245246
141.40000000000128,20.857703872230452,0.35490026238799377,0.0009900784296905663
142.2000000000013,20.934255773315996,0.3554328037583486,0.0010007657962001204
143.0000000000013,21.011093341060615,0.35609282565637257,0.0009980036543568716
143.80000000000132,21.08765658302125,0.35788022409817266,0.002344006764275708
144.60000000000133,21.16317356379016,0.3601242836191568,0.0024352577095267947
145.40000000000134,21.236982367833193,0.3600081967438086,0.0023098240214647348
146.20000000000135,21.314607804574273,0.3622568919808369,0.0023098294759447136
147.00000000000136,21.392099166753006,0.36344191866185127,0.002289602256049683
147.80000000000138,21.46956165025122,0.36173912295153854,0.0009898102523262509
148.6000000000014,21.544152072243865,0.36214709040489235,0.0017059245295141245
149.4000000000014,21.62152584830764,0.3647075404314555,0.0009901058582180156
150.2000000000014,21.696084150705442,0.36586043697767523,-0.00021159981420781904
151.00000000000142,21.773031893191572,0.3658743524207867,0.00029561280331202866
151.80000000000143,21.84899109584538,0.36582322144262347,0.001000168575547633
152.60000000000144,21.92230224526536,0.3654774660561204,0.0010001626374442907
153.40000000000146,22.00070834840194,0.3658539901425416,0.0010059035419485163
154.20000000000147,22.075365693342718,0.3659967108372649,0.0013835562051704997
155.00000000000148,22.1531467808355,0.36602392882748447,0.0009899783107933935
155.8000000000015,22.229714800887507,0.36742701775032804,0.0009899397628401196
156.6000000000015,22.304574934954967,0.3688585180087246,0.0002900831027776718
157.4000000000015,22.381071673055956,0.3699192135386292,0.0003848660945098281
158.20000000000152,22.45737742014,0.3705461472951024,0.001000839849688795
159.00000000000153,22.53379733344622,0.36885481225102124,-0.000316717758806373
159.80000000000155,22.608525955053285,0.37185760133990864,0.0009405366807593296
160.60000000000156,22.68480236293598,0.3712213577571226,6.365854575030028e-06
161.40000000000157,22.76088994226327,0.3724338740995914,0.0013200243203224105
162.20000000000158,22.83678735968749,0.37156215271977,0.0013198115999806248
163.0000000000016,22.91201665090029,0.3727643720243682,0.0009899535659929626
163.8000000000016,22.98907619073666,0.3729242324264852,0.0009894285422271665
164.60000000000161,23.065961224942118,0.3737479617356094,-0.00031380205208897394
165.40000000000163,23.141789344319715,0.37370631968017143,-0.00023100881792803563
166.20000000000164,23.217774483919193,0.37315032430537776,0.000324353776525399
167.00000000000165,23.29338915988189,0.37246667403373046,0.00011906750710277691
167.80000000000166,23.36928749581717,0.3740770889915588,-0.00032774961497938904
168.60000000000167,23.44487605151959,0.37548308547444365,-0.001320427552084169
169.40000000000168,23.52146563415115,0.3746720741518258,-5.768983371012837e-07
170.2000000000017,23.59670066527105,0.37569136099304784,0.001319024341659869
171.0000000000017,23.67288634515451,0.3742270996994015,0.0009374263560917306
171.80000000000172,23.748489929177612,0.37598738108960306,-0.0013109391773711287
172.60000000000173,23.825558363380917,0.3775293638433974,-0.002629338053728336
173.40000000000174,23.90181130928345,0.3769573847944634,-0.0026299469368979977
174.20000000000175,23.97731650954726,0.3777098260356988,-0.0014075966017830233
175.00000000000176,24.053700714637838,0.3780835634616504,-0.0013098316562500933
175.80000000000177,24.129508100959058,0.37939659026086564,-0.0013087474185757841
176.60000000000178,24.20485757861266,0.3800649594461263,-0.0022368832885852896
177.4000000000018,24.281564301395033,0.37856189816643776,-0.0035903247311783737
178.2000000000018,24.35721368244078,0.38081377277259953,-0.002296838022055603
179.00000000000182,24.433495456947888,0.3805162574904492,-0.0022990556069486523
179.80000000000183,24.508399471156892,0.381299528307839,-0.002298415028117784
180.60000000000184,24.58564625716684,0.3821549243799233,-0.0023100670606472917
181.40000000000185,24.6618197791802,0.3822850568040147,-0.00231010019403044
182.20000000000186,24.737641067766837,0.3838801019934873,-0.0024740665158153874
183.00000000000188,24.813160660720715,0.38267521095868606,-0.0022999011533695324
183.8000000000019,24.888601648960986,0.38590124564077927,-0.0027023691130465544
184.6000000000019,24.96474281875756,0.38582403125334336,-0.002311709226096692
185.4000000000019,25.039819274724323,0.3862908654022527,-0.002300141215469509
186.20000000000192,25.116345416996673,0.3863633759835675,-0.003668751597428521
187.00000000000193,25.19092980272959,0.3876685187365821,-0.004656401648234887
187.80000000000194,25.268921889691757,0.38668144214631833,-0.00494110994103103
188.60000000000196,25.343057906947166,0.3884928896737244,-0.004280017054679952
189.40000000000197,25.419552118005242,0.39021145168711246,-0.004285488270999505
190.20000000000198,25.494796565177516,0.3914811334915867,-0.0053504236359156465
191.000000000002,25.570541856852127,0.3939669752115581,-0.004280128310591547
191.800000000002,25.647006427117052,0.3927678634796462,-0.004279766562711895
192.600000000002,25.72293701990936,0.39430592417574156,-0.0055885396886705685
193.40000000000202,25.797253441785156,0.3928318067955863,-0.004266203106490174
194.20000000000203,25.873226533568214,0.3941427553642343,-0.0042701138345151435
195.00000000000205,25.949438031460577,0.39535629429677605,-0.0029541219282220865
195.80000000000206,26.02440590225749,0.39467015763753716,-0.002982787348576821
196.60000000000207,26.09999904433633,0.3981203737544819,-0.004269970214437091
197.40000000000208,26.176635890187143,0.39857211789070524,-0.004230095507103737
198.2000000000021,26.251937276211965,0.39750024574046383,-0.005589878380580338
199.0000000000021,26.327582865250132,0.3984277655772748,-0.005589979986045268
199.80000000000211,26.403583104042845,0.4002225331784593,-0.007012405980800995
200.60000000000213,26.47946809152008,0.4018949502545223,-0.008228946555597805
201.40000000000214,26.554840100564427,0.4012745718463741,-0.008230133769794534
202.20000000000215,26.63147929643129,0.4005205852963455,-0.008230645120710811
203.00000000000216,26.707119458177647,0.40125297768287327,-0.007700102459372804
203.80000000000217,26.78273599296541,0.40265544358772487,-0.007569949126961184
204.60000000000218,26.858579416969874,0.40070076646225866,-0.006915079276322178
205.4000000000022,26.93462690963315,0.40205001941394725,-0.006922415163785889
206.2000000000022,27.009534099413536,0.4021982216605696,-0.0076351418741418264
207.00000000000222,27.084998789388788,0.40372003418858027,-0.007569804403474656
207.80000000000223,27.162016383437802,0.40434042813018967,-0.007569810004139033
208.60000000000224,27.237054447155415,0.4056954640959189,-0.007569704596770421
209.40000000000225,27.313673610724504,0.4064234407806309,-0.006575759037824813
210.20000000000226,27.388381697338637,0.40485831625071084,-0.008232243423379249
211.00000000000227,27.46431490320001,0.40527935917021324,-0.008229982125514734
211.80000000000229,27.540285055363267,0.40634947698017565,-0.008584651804392607
212.6000000000023,27.616659946432936,0.40658550301593827,-0.009550172770070642
213.4000000000023,27.69335215382792,0.40734975728337935,-0.009575409332407858
214.20000000000232,27.770087644239602,0.4089941832474787,-0.01021102043638189
215.00000000000233,27.845559336335498,0.4094186544357666,-0.010209866966256698
215.80000000000234,27.9216542931656,0.4103844902243664,-0.010220468614775324
216.60000000000235,27.997328625166613,0.40938248743955113,-0.01120040800643407
217.40000000000236,28.07235123266511,0.4127823988081321,-0.011200262821736917
218.20000000000238,28.14832063877489,0.4116193369598742,-0.012516881989205864
219.0000000000024,28.224203998218,0.4142315592286206,-0.012519389854343643
219.8000000000024,28.300855884718345,0.41544563841275406,-0.011189312304118904
220.6000000000024,28.37729584126621,0.41495863986145304,-0.012510039893192992
221.40000000000242,28.45212235518885,0.4158127948837633,-0.012507626868059951
222.20000000000243,28.529298569801675,0.4194312841532019,-0.013796607855785403
223.00000000000244,28.60414152988083,0.4164619489374118,-0.014945514051472486
223.80000000000246,28.680087827188768,0.4184023971143806,-0.013830090684391116
224.60000000000247,28.756288258545176,0.41810222558964677,-0.013799609561187864
225.40000000000248,28.831489602566368,0.4181424688614027,-0.013829103109726404
226.2000000000025,28.90606092191581,0.4182942600935405,-0.013829929929465745
227.0000000000025,28.984252303840936,0.420604162124139,-0.014055848071947707
227.8000000000025,29.06020306666679,0.4215013956591127,-0.016137116296266907
228.60000000000252,29.136805793309343,0.42157988022788,-0.016140137733512194
229.40000000000254,29.212137311802866,0.4239225136638639,-0.014748122842038303
230.20000000000255,29.28826592022458,0.4247601345656459,-0.01484086104486293
231.00000000000256,29.364286938975667,0.4253380321285006,-0.014199086625641844
231.80000000000257,29.44079666674081,0.4264912525482174,-0.018283507342388372
232.60000000000258,29.51324550875135,0.4259107244662467,-0.0197599723930324
233.4000000000026,29.593061386676695,0.4264790539020863,-0.019763869883272722
234.2000000000026,29.66901647571254,0.42681566426084483,-0.017760373908738192
235.00000000000261,29.745309429545962,0.428944854164289,-0.016040427724177242
235.80000000000263,29.819126537454988,0.42952045915830106,-0.018000340608294252
236.60000000000264,29.896982927688722,0.42690377044901456,-0.018010526947946914
237.40000000000265,29.972927553073028,0.429840635274961,-0.019310279193941238
238.20000000000266,30.04788370410056,0.42840877119979803,-0.01931003022500466
239.00000000000267,30.12450674680655,0.4300737293829759,-0.019633119961779855
239.80000000000268,30.199734685099255,0.4279435832276981,-0.02094121168219898
240.6000000000027,30.27540291199567,0.42805262124879667,-0.019980133232619046
241.4000000000027,30.3513539969792,0.4288786192412686,-0.019980185999073807
242.20000000000272,30.42926187137852,0.428042462474406,-0.019980186400884836
243.00000000000273,30.505083102965294,0.4271233562635463,-0.02005241152717918
243.80000000000274,30.580572522320097,0.4272215679045093,-0.02260833465923051
244.60000000000275,30.657187789942295,0.4297302616932894,-0.02261000589549278
245.40000000000276,30.732026820352957,0.42724174543452437,-0.02264095255676679
246.20000000000277,30.808645687301286,0.42913070215865895,-0.02130017638748205
247.00000000000279,30.88565697356721,0.42987056512297683,-0.021300229425246897
247.8000000000028,30.960094371022144,0.42730258383773395,-0.024005146825059942
248.6000000000028,31.036024198525148,0.4276205296134512,-0.023932661412687573
249.40000000000282,31.112855109477053,0.42886850114869496,-0.02525045970413453
250.20000000000283,31.188691760305847,0.42862539015479756,-0.025250239766055227
251.00000000000284,31.26546862786782,0.42815369704164813,-0.027390473989044928
251.80000000000285,31.340922316791552,0.42726825288554215,-0.02787993883728479
252.60000000000286,31.416497186744557,0.4265038425724352,-0.02787993800678157
253.40000000000288,31.493376555456503,0.4282660897686634,-0.02787868770388391
254.2000000000029,31.571004602273227,0.42789571732172504,-0.027231153484187587
255.0000000000029,31.64522810313615,0.4296026679054424,-0.02848177227927229
255.8000000000029,31.722576163327922,0.42897366058716385,-0.02855010030652716
256.6000000000029,31.798701111948088,0.4270417899308746,-0.028511028469805133
257.40000000000293,31.87477040351464,0.4263296934963215,-0.02989999509289243
258.20000000000294,31.949712898197443,0.4268786480447744,-0.028539924608774303
259.00000000000296,32.026690928013146,0.4275486547841328,-0.028539868033335303
259.80000000000297,32.10225804213059,0.426801719839819,-0.031178372705406243
260.600000000003,32.179072283222915,0.4268498884627947,-0.031180102844870827
261.400000000003,32.25495530634703,0.42749960444937735,-0.031096133591296482
262.200000000003,32.33038725627003,0.4279561375011587,-0.03248991983352001
263.000000000003,32.407155890935755,0.42944663050871884,-0.032490089008700096
263.800000000003,32.48340545028838,0.4275323560552681,-0.033808557955743446
264.60000000000304,32.56044993108703,0.42755254074121146,-0.033810523716456764
265.40000000000305,32.636645239816204,0.42785473487474024,-0.03249123269796428
266.20000000000306,32.712470260978094,0.42891314904704747,-0.033760179916235256
267.00000000000307,32.78860153600463,0.4272563788847784,-0.035125467540643385
267.8000000000031,32.864448551569296,0.4288835435659722,-0.03644034027597298
268.6000000000031,32.9407812797246,0.4319148515218387,-0.03644993304243105
269.4000000000031,33.01759665924563,0.4319377205125435,-0.03512712006595997
270.2000000000031,33.093756959682885,0.4306922805007236,-0.03512969177831149
271.0000000000031,33.170554610992596,0.4308035958255161,-0.036448672860732945
271.80000000000314,33.24645102765416,0.4316723338014602,-0.03777009780069296
272.60000000000315,33.32278292941627,0.4314492299710157,-0.03777073519777385
273.40000000000316,33.39842829765012,0.43065291096623465,-0.04039451081587986
274.2000000000032,33.47474134604376,0.43025579012171805,-0.04167169828524919
275.0000000000032,33.55139563271699,0.43083445141381066,-0.04167315378911596
275.8000000000032,33.62728086841311,0.43350066055958936,-0.041906329844159096
276.6000000000032,33.702828479197635,0.4332037066195211,-0.044344568051740474
277.4000000000032,33.779523139036726,0.4334997348227997,-0.04562526754321583
278.20000000000323,33.85499799223083,0.436086839806812,-0.046541211680346084
279.00000000000324,33.92832992962073,0.4360804428924171,-0.04668725295424414
279.80000000000325,34.008300475788005,0.43615244608271986,-0.04665015853407084
280.60000000000326,34.08411321480364,0.4381517401300312,-0.046650156853639047
281.4000000000033,34.160736939135035,0.4385983194248726,-0.048006588095678815
282.2000000000033,34.23679271342459,0.43976457464233876,-0.048958032808195995
283.0000000000033,34.313401949821724,0.4396868203726981,-0.05027960313722524
283.8000000000033,34.389559980710395,0.4394926107376037,-0.048965376788900894
284.6000000000033,34.464791327545285,0.43868740022875563,-0.04901519346630723
285.40000000000333,34.5411818835638,0.43900371362000257,-0.051590080964325935
286.20000000000334,34.61743950258867,0.4394817603157093,-0.051534086246453725
287.00000000000335,34.69512420671721,0.44074636717861115,-0.05291001558657049
287.80000000000337,34.770808865735596,0.44013375262388005,-0.05291659391474335
288.6000000000034,34.84908143380315,0.4403145943682871,-0.05552181665188494
289.4000000000034,34.92428530651908,0.44140489010222467,-0.05620824407731728
290.2000000000034,35.00149075779762,0.4410771254088168,-0.056868586976866364
291.0000000000034,35.0772365651156,0.44208893631364027,-0.056210138826067624
291.8000000000034,35.15378373553947,0.44290302679838167,-0.05752728239902982
292.60000000000343,35.229145325684065,0.44378307755701574,-0.05881295476417847
293.40000000000344,35.306091015370484,0.44361621543041624,-0.06020533420600804
294.20000000000346,35.38317387833478,0.4437058641619675,-0.061443497557041926
295.00000000000347,35.458496036892655,0.4441162359075955,-0.06148015882725977
295.8000000000035,35.53605997420412,0.44563271296831347,-0.06147990277698456
296.6000000000035,35.61278860566309,0.4461433188120708,-0.06280220760411614
297.4000000000035,35.69031010463993,0.44514906328276693,-0.06411026444109469
298.2000000000035,35.76627601659806,0.4465377587710835,-0.06608873509784097
299.0000000000035,35.843136702494,0.44954891676186093,-0.06605649172752015
299.80000000000354,35.919230217979674,0.44881420017425705,-0.06741011154663168
300.60000000000355,35.99620050620645,0.4501858929187469,-0.0674100760049785
301.40000000000356,36.073057964381505,0.45071208809370145,-0.0674100746869124
302.20000000000357,36.14935656907131,0.449492101072731,-0.0674121884892247
303.0000000000036,36.2257767772253,0.45054105612771905,-0.06919468401918483
303.8000000000036,36.30400471519968,0.4525458734332758,-0.07061221580301691
304.6000000000036,36.37960283348198,0.452783947387556,-0.07067008554644927
305.4000000000036,36.456225755263986,0.4545447270625554,-0.07200982004165324
306.2000000000036,36.53260557442593,0.4550176850543546,-0.07200982799976163
307.00000000000364,36.60981038340081,0.4536465152042213,-0.07200982800062938
307.80000000000365,36.68668735710701,0.453798108361888,-0.07200998272019454
308.60000000000366,36.76354731060858,0.4550974091822585,-0.07296695554394717
309.4000000000037,36.839695290244315,0.45486396029849324,-0.0743218204547702
310.2000000000037,36.91635155434134,0.455049134222055,-0.07598321512711737
311.0000000000037,36.99302855675274,0.4572556801246628,-0.07727278866772602
311.8000000000037,37.06990861948563,0.456781855558906,-0.07860031816092006
312.6000000000037,37.14618733928111,0.4575372578530502,-0.07857599572239637
313.40000000000373,37.2231403907528,0.4568693231352928,-0.07960241365236209
314.20000000000374,37.29930327303983,0.4559114263480864,-0.08125102952063701
315.00000000000375,37.37642491568626,0.45884960572817973,-0.08255679544050487
315.80000000000376,37.45409419499845,0.45836596567762006,-0.08139881585079145
316.6000000000038,37.53082464258858,0.45880467780803974,-0.08523173299222409
317.4000000000038,37.60809141075698,0.45935403563785265,-0.0864960421661265
318.2000000000038,37.68248895636193,0.4593530473449462,-0.0878274863285724
319.0000000000038,37.761368996821965,0.4605924242032764,-0.08781981503168002
319.8000000000038,37.838815700753344,0.46232932949000866,-0.08778909724559991
320.60000000000383,37.91463820559438,0.4618717688605737,-0.0884346277426249
321.40000000000384,37.99218556236038,0.46396029986342313,-0.09010738486809
322.20000000000385,38.068671624662976,0.4658947166123002,-0.0901295743521855
323.00000000000387,38.14617635819509,0.46654173340681837,-0.09177335215939042
323.8000000000039,38.22238045004329,0.4679124768517559,-0.09274692261973394
324.6000000000039,38.29944318820841,0.4689227177446983,-0.09309339656767834
325.4000000000039,38.37640847857193,0.46847609051220745,-0.09438558395747121
326.2000000000039,38.45315996674054,0.4705991055647265,-0.0970699785266107
327.0000000000039,38.53019686026519,0.4714770791992101,-0.09837006887934141
327.80000000000393,38.608172555270244,0.47400996654189076,-0.09954352486701223
328.60000000000394,38.684999006575524,0.4728050203330513,-0.09879924325350542
329.40000000000396,38.7620520526946,0.4767274465646457,-0.09968005049049955
330.20000000000397,38.83913277692244,0.47557803152691847,-0.09968002080674365
331.000000000004,38.916502301293676,0.4790993322675936,-0.10091065625047335
331.800000000004,38.99348224418334,0.48097478921374726,-0.10431206336342891
332.600000000004,39.06835976919186,0.4812198255685034,-0.10626883329758519
333.400000000004,39.14752702429295,0.4855122481195616,-0.10758319077856271
334.200000000004,39.224651046966066,0.4874535014389766,-0.10882516073113369
335.00000000000404,39.3018950886324,0.4876103803818558,-0.10971475627142668
335.80000000000405,39.378576287765036,0.4918669119278492,-0.11014091692683214
336.60000000000406,39.45533777386942,0.4938562429597484,-0.11213030550137804
337.40000000000407,39.532981257085034,0.49657801536386537,-0.11445600268162881
338.2000000000041,39.60952164479542,0.4993514082852012,-0.11723292914375749
339.0000000000041,39.687781319260125,0.5010069796293322,-0.118492412874319
339.8000000000041,39.76476776754962,0.5029783363370771,-0.12117280338362946
340.6000000000041,39.84208566601592,0.5055440555865367,-0.1233511682126256
341.4000000000041,39.9185085080705,0.5079909604985368,-0.12514437644528176
342.20000000000414,39.995854876910116,0.5097143569271205,-0.1264715452334757
343.00000000000415,40.073713277595374,0.5135318778980669,-0.12797128951889736
343.80000000000416,40.15076853762942,0.5151408511445796,-0.13245562439413927
344.6000000000042,40.227248077728824,0.5200345978816273,-0.13438024719954988
345.4000000000042,40.30533184619329,0.5200108578869016,-0.13656071209010578
346.2000000000042,40.382497410026225,0.5240593143747972,-0.1394251785802143
347.0000000000042,40.459049165775355,0.5260755525827497,-0.14186921233699135
347.8000000000042,40.53736444301651,0.5280320500940497,-0.14227298263873367
348.60000000000423,40.614035111525666,0.5304261129811148,-0.1435909827041315
349.40000000000424,40.691852950071805,0.5347446848855055,-0.14556457695468739
350.20000000000425,40.769131736304494,0.5362140529067797,-0.14714267482538057
351.00000000000426,40.84683743657293,0.5401140705280305,-0.15109265849719344
351.8000000000043,40.92384262075366,0.5444682535547808,-0.15376282012234732
352.6000000000043,41.00173798220752,0.5473674901924255,-0.15710452177171375
353.4000000000043,41.07829082764447,0.550091816214906,-0.15829980393873821
354.2000000000043,41.15530187007237,0.5538905902106299,-0.1597363711655797
355.0000000000043,41.23387713665816,0.5580011923006051,-0.16536168406818064
355.80000000000433,41.310703480241315,0.5637037842669099,-0.1685707274613577
356.60000000000434,41.38873987320919,0.5695218618087726,-0.17157167446155075
357.40000000000435,41.46579067054745,0.5759976572598137,-0.17615700420117975
358.20000000000437,41.543019934733636,0.5788306552994411,-0.17876536234720497
359.0000000000044,41.62109824602846,0.5881010044118555,-0.1815105608962435
359.8000000000044,41.69891314172381,0.5916917938024147,-0.184534101634247
360.6000000000044,41.775641758077825,0.5961816110188796,-0.18897063862950425
361.4000000000044,41.852826772626045,0.6029469128753705,-0.19461129463332227
362.2000000000044,41.931238498958756,0.6095000168808967,-0.20182256024869627
363.00000000000443,42.00864026258968,0.6157233178655942,-0.2054488829488168
363.80000000000445,42.08538163600011,0.6247187415758564,-0.2090777911352073
364.60000000000446,42.16362802513604,0.6325424507145411,-0.2173649496439367
365.40000000000447,42.24033111231759,0.6407089992472836,-0.22001378225534918
366.2000000000045,42.318726528201395,0.6486670785672541,-0.22447379619961705
367.0000000000045,42.39587862556695,0.6570844527506785,-0.22991198914518574
367.8000000000045,42.47300092414801,0.6661766247589814,-0.23462559338768507
368.6000000000045,42.55009973688036,0.6782809923552127,-0.24141882187628205
369.4000000000045,42.6287742345326,0.6858568978212239,-0.2485554054861554
370.20000000000454,42.705745737172094,0.6944847508157097,-0.2549922015122945
371.00000000000455,42.7838536598594,0.7079019871551877,-0.2622977334092482
371.80000000000456,42.86186694697769,0.7211753655049897,-0.26971552736414495
372.60000000000457,42.936458511234896,0.7320372321984457,-0.27660686610753293
373.4000000000046,43.01712172004735,0.7470387252633935,-0.2844087100589565
374.2000000000046,43.094848625414244,0.758864467880057,-0.29159401070886215
375.0000000000046,43.172143124006084,0.7734206199618787,-0.3002547944861642
375.8000000000046,43.25026245966778,0.7911126979574188,-0.31050476972742347
376.6000000000046,43.326050442222986,0.8038729067260431,-0.3207542828724348
377.40000000000464,43.40568815291955,0.82419804948174,-0.32930391246594093
378.20000000000465,43.48396224432282,0.8430142481366922,-0.34062384862555195
379.00000000000466,43.56129686665388,0.8621460152707736,-0.3501191797231784
379.8000000000047,43.63903714446832,0.8814383620620143,-0.3611070774239695
380.6000000000047,43.717344864800424,0.9049898536820982,-0.3748354217471124
381.4000000000047,43.79471235305494,0.9258588260625809,-0.38782041024265457
382.2000000000047,43.87267675993406,0.9492213849337964,-0.40133375893325596
383.0000000000047,43.95077363822194,0.9749370471969576,-0.4154232575096328
383.80000000000473,44.02812951575264,1.0002660052634156,-0.426367994959846
384.60000000000474,44.10588240075247,1.0257604995872287,-0.4407906247727844
385.40000000000475,44.18391939498527,1.0575441101952419,-0.4557644639564007
386.20000000000476,44.26224501844288,1.089719168420558,-0.4717288225666523
387.0000000000048,44.3382232885644,1.1201046259703613,-0.4925275706620118
387.8000000000048,44.41694627607458,1.1565999427529452,-0.5099285016326949
388.6000000000048,44.494576134668755,1.1921436739658215,-0.5303010055303901
389.4000000000048,44.57355841506508,1.2287054962216746,-0.5534779720988006
390.2000000000048,44.651456396090936,1.2701890407095626,-0.5748554485054229
391.00000000000483,44.7291633456704,1.3125223535012784,-0.5984435233089425
391.80000000000484,44.80796412266479,1.357251876410042,-0.6226561513853168
392.60000000000485,44.88629325969858,1.4033009413166657,-0.6449120079039763
393.40000000000487,44.964766148607126,1.4538009358787323,-0.6718707188993625
394.2000000000049,45.04235352453261,1.5034903808917846,-0.7000659900986017
395.0000000000049,45.121412044215504,1.5568059088520068,-0.7288376670059815
395.8000000000049,45.19940689939903,1.6130874574839673,-0.7583794574507832
396.6000000000049,45.27732282875233,1.6697377406349871,-0.7892879676027076
397.4000000000049,45.356362090159394,1.7311427225231437,-0.8236783969197776
398.20000000000493,45.434365536881096,1.7928304128709796,-0.8597322011049822
399.00000000000495,45.513014212568905,1.856390020342238,-0.8956702920837016
399.80000000000496,45.59157222997576,1.925746802793793,-0.9348611151190283
400.60000000000497,45.67053496949403,1.9932797242498836,-0.9774029391842438
401.400000000005,45.74915122175842,2.0654515797599715,-1.0199544857797105
402.200000000005,45.827450259331236,2.136396177121072,-1.0640416951819067
403.000000000005,45.90580312623711,2.2086245886535742,-1.1110136589914403
403.800000000005,45.98416542260338,2.278456509043939,-1.1597513863364255
404.600000000005,46.062164957512834,2.361180761213464,-1.2123632425274806
405.40000000000504,46.14154455952977,2.455498223538293,-1.2639653856671118
406.20000000000505,46.219405990575424,2.5356606638144035,-1.3198015210035843
407.00000000000506,46.29878155133253,2.593214180304494,-1.3778366378650362
407.80000000000507,46.37700786294605,2.6522876156391497,-1.4349459885209113
408.6000000000051,46.455750507786625,2.7236964418879364,-1.4932554964209568
409.4000000000051,46.533973530539534,2.8059848914436545,-1.5550537291805346
410.2000000000051,46.612640966357255,2.8837271422944126,-1.6183744056456768
411.0000000000051,46.69000000000057,2.965717143019825,-1.6848432386631456
411.8000000000051,46.77000102506878,3.0341678320651613,-1.7551009932524448
412.60000000000514,46.848369693897,3.095357396122609,-1.8270301999256886
413.40000000000515,46.92714069687168,3.1523362678323057,-1.8993450754191357
414.20000000000516,47.00615305156781,3.2075583274223254,-1.9784423725944138
415.0000000000052,47.083609933965285,3.2454287767797365,-2.053892832599035
415.8000000000052,47.16235834300594,3.282005304819971,-2.1295435601416166
416.6000000000052,47.241354036538056,3.3050713710012327,-2.2099700906918955
417.4000000000052,47.31932844289431,3.3278392443244633,-2.288768550362417
418.2000000000052,47.39862588979539,3.33577316170493,-2.3713490338044703
419.00000000000523,47.4763211658815,3.327552098396805,-2.450822521752402
419.80000000000524,47.55493425678888,3.312477348181158,-2.5312739447547785
420.60000000000525,47.630113244277105,3.2808702524179862,-2.6098579853035995
421.40000000000526,47.71170916280519,3.2390567689026084,-2.695199518352828
422.2000000000053,47.78935699568186,3.1834095234017465,-2.7712908447552564
423.0000000000053,47.86735426112833,3.110722724455594,-2.8459038165448334
423.8000000000053,47.945598025056796,3.025861931850843,-2.921634084342751
424.6000000000053,48.02277579782118,2.930686987486483,-2.9959966549116084
425.4000000000053,48.100001012264364,2.8273929606346253,-3.0680011556676137
426.20000000000533,48.17896775773355,2.707246954218848,-3.1354660323789756
427.00000000000534,48.25636992546307,2.5810183352643516,-3.20008269502053
427.80000000000535,48.333689504278084,2.448099661954408,-3.2613761419204748
428.60000000000537,48.41099722149192,2.3125734415085972,-3.318924415523769
429.4000000000054,48.488484588715195,2.166834026601569,-3.3755432437597754
430.2000000000054,48.56585983088205,2.0170311709688593,-3.4293623320364155
431.0000000000054,48.641565496748534,1.870144672171575,-3.47271894624111
431.8000000000054,48.71909470460142,1.7262426484462443,-3.517911224084831
432.6000000000054,48.79682505385626,1.58792178878327,-3.556685402472084
433.40000000000543,48.873160282636306,1.4569710014414432,-3.593940499173628
434.20000000000545,48.9501975388323,1.3316083741850848,-3.6274075776256383
435.00000000000546,49.0270875712262,1.211265361977473,-3.6580121137287014
435.80000000000547,49.104843072204034,1.0981471924777733,-3.686664824000083
436.6000000000055,49.17937496594351,0.9983237912750255,-3.7120175840560146
437.4000000000055,49.2591943617974,0.9014188318304617,-3.734231355763268
438.2000000000055,49.33725808157422,0.8107604177285124,-3.7555538110543134
439.0000000000055,49.413988488761916,0.7331495530328596,-3.772497753859202
439.8000000000055,49.491808457584916,0.6630387606970072,-3.789803979118896
440.60000000000554,49.568832617596,0.6001560761319451,-3.8045114390170047
441.40000000000555,49.64669084338962,0.5391451992632219,-3.8175384127434158
442.20000000000556,49.72373551549256,0.4902306101714491,-3.830406297787338
443.00000000000557,49.80236811594741,0.44327488176081836,-3.8432303661859613
443.8000000000056,49.88106772152305,0.40053189331166006,-3.852150913761521
444.6000000000056,49.958156618279574,0.36627453267127336,-3.860687147760055
445.4000000000056,50.03594271340159,0.3330937752276859,-3.868580941332521
446.2000000000056,50.11396674314081,0.3030798212181797,-3.875349575184349
447.0000000000056,50.19261106905926,0.27840673786593556,-3.8825959800977756
447.80000000000564,50.27036308328331,0.2568307049902049,-3.88964000832457
448.60000000000565,50.3480151939318,0.23470411853258505,-3.894942788078377
449.40000000000566,50.423895209197795,0.21943868188480387,-3.9006021610869546
450.2000000000057,50.50435750459215,0.201610222540544,-3.905651064504742
451.0000000000057,50.582646478688694,0.18798227777092485,-3.9081032726504734
451.8000000000057,50.66099899891339,0.1754209893240647,-3.912941942852121
452.6000000000057,50.73891450892743,0.161223237529332,-3.9156259908055824
453.4000000000057,50.81684767158997,0.15183852095891887,-3.9197740447392153
454.20000000000573,50.89605489797337,0.14126500824963217,-3.922955462212915
455.00000000000574,50.97371737195989,0.13465533713383437,-3.92570751428786
455.80000000000575,51.052307648222076,0.12475099018500396,-3.927931149357728
456.60000000000576,51.13048106343522,0.1205411962741671,-3.930650525072671
457.4000000000058,51.208645331365254,0.11503673324320596,-3.9306808873835872
458.2000000000058,51.287260725441946,0.10810795379310245,-3.932058218552246
459.0000000000058,51.36601587499804,0.10396126746301954,-3.9342633722329388
459.8000000000058,51.44332129520958,0.09862758161451879,-3.9361241779087788
460.6000000000058,51.5232847420756,0.09315808435634954,-3.9401242329055752
461.40000000000583,51.60071135260511,0.08540497500918481,-3.9400500351580465
462.20000000000584,51.67871298079465,0.07957600460146969,-3.9408734425229546
463.00000000000585,51.75695538585509,0.0727861301807794,-3.943299230327715
463.80000000000587,51.835412953030676,0.06458571874699953,-3.943629777106322
464.6000000000059,51.913570080074514,0.05748871297644975,-3.944955988047272
465.4000000000059,51.9929930910554,0.05119883431983363,-3.9436298033631756
466.2000000000059,52.06865223660973,0.04848748666818148,-3.943629786192993
467.0000000000059,52.14933741764736,0.04501352548177645,-3.94297392456793
467.8000000000059,52.22795113844818,0.04238235177808175,-3.9442733356117192
468.60000000000593,52.30610693115751,0.047591872720936845,-3.9436301527763415
469.40000000000595,52.384619649823875,0.04684724968417375,-3.943630066003162
470.20000000000596,52.46235117768167,0.047897431847760075,-3.943630071793824
471.00000000000597,52.541381555044374,0.04887439971806179,-3.9436300390845633
471.800000000006,52.619784150954835,0.050820789810883116,-3.9436180007078283
472.600000000006,52.698325011126485,0.04991152621646766,-3.9450100781039588
473.400000000006,52.777104400623614,0.04835849407759901,-3.9454071068412997
474.200000000006,52.85536879341051,0.04700471102338771,-3.94538006618842
475.000000000006,52.9336342273119,0.04566652714241415,-3.945504076930646
475.80000000000604,53.0122514756988,0.044694381718787035,-3.945379646773665
476.60000000000605,53.09090619864406,0.043841110971582165,-3.9453798975920624
477.40000000000606,53.16926172170923,0.041107884634134784,-3.9453907096372594
478.20000000000607,53.24846829948092,0.04130206922617363,-3.946695903691584
479.0000000000061,53.326318244736406,0.039540838654714305,-3.9478172959019324
479.8000000000061,53.405223276423115,0.03592019355413667,-3.9469890675500583
480.6000000000061,53.484872638746886,0.035909132494604035,-3.9466872468859293
481.4000000000061,53.562228398360205,0.03716036481839313,-3.944117908196195
482.2000000000061,53.64235096553356,0.03535457279170606,-3.946683387891483
483.00000000000614,53.71917085984604,0.031545432722193845,-3.946695237411925
483.80000000000615,53.79901063107789,0.029020534401081433,-3.9453798433974026
484.60000000000616,53.87551111484497,0.028809409025787935,-3.946970302545583
485.4000000000062,53.95571815024291,0.02930242566965191,-3.9483622840648414
486.2000000000062,54.03473709543062,0.029209805535071076,-3.94603122491069
487.0000000000062,54.11366273480994,0.026016316343550838,-3.9457100691983604
487.8000000000062,54.193003311952175,0.02490912580806759,-3.9445172214158775
488.6000000000062,54.27169033251615,0.02600874796822883,-3.94439899559658
489.40000000000623,54.349704663803465,0.02731613345088768,-3.945710006042106
490.20000000000624,54.42952525845353,0.02602115160831786,-3.9457100060001444
491.00000000000625,54.50787090792683,0.02444810560238364,-3.9457100219273435
491.80000000000626,54.587208475169724,0.024878373502191242,-3.9445182921156934
492.6000000000063,54.66536273972841,0.02585772583087198,-3.94438984122932
493.4000000000063,54.744419161360526,0.022310976710132213,-3.944103415342523
494.2000000000063,54.82362684834965,0.022999478754076985,-3.944386077081244
495.0000000000063,54.8997769899452,0.023311674665001725,-3.946054700163624
495.8000000000063,54.98082789641658,0.022682980884064508,-3.9467001778292334
496.60000000000633,55.060675550018495,0.021693550983381715,-3.946700547077057
497.40000000000634,55.13929568392652,0.021672266087040204,-3.945379524977323
498.20000000000636,55.218224017109186,0.021334678375244942,-3.946673049561962
499.00000000000637,55.29840761310589,0.020548134268521312,-3.9495330650577567
499.8000000000064,55.37658511458059,0.020250232559835157,-3.9469849150386285
500.6000000000064,55.455781857147336,0.019981313604782225,-3.9457278831621525
501.4000000000064,55.533792528258566,0.021635926078021006,-3.9457100771549816
502.2000000000064,55.61355501106263,0.018853381025432603,-3.946981377236162
503.0000000000064,55.69333280060777,0.019512206595573456,-3.9448417866563417
503.80000000000643,55.77239157090916,0.020175714918507337,-3.9443886448069185
504.60000000000645,55.852460830717945,0.01977267569897484,-3.946103471491715
505.40000000000646,55.931431963270526,0.021049407948938725,-3.9466997794672665
506.20000000000647,56.011144908263695,0.02075720355228744,-3.946717526025442
507.0000000000065,56.090733830172354,0.019326855502426743,-3.946367819889603
507.8000000000065,56.17072220782226,0.0191919441466587,-3.94767196178894
508.6000000000065,56.24858605734564,0.01694925886265597,-3.945088976816452
509.4000000000065,56.33163046277589,0.017187482106709506,-3.9463761999044964
510.2000000000065,56.41050488226662,0.01687925547603042,-3.947680181690669
511.00000000000654,56.489281023316934,0.01866534705625056,-3.9476801559988655
511.80000000000655,56.56960646299661,0.01754826696715006,-3.9476801560142434
512.6000000000065,56.64958449274606,0.016670917229083426,-3.9476806727980156
513.4000000000066,56.727707676818746,0.01648290355442572,-3.9464716209397213
514.2000000000066,56.80777642653629,0.016076265481667795,-3.9463699429197434
515.0000000000066,56.88719224787362,0.01566326316458949,-3.946387133473793
515.8000000000065,56.966288902839224,0.01575791794466258,-3.9453799120148814
516.6000000000066,57.04659295938462,0.01522593137475109,-3.9466753539453694
517.4000000000067,57.12645587826276,0.016310134112031194,-3.948008613827045
518.2000000000066,57.2040853388982,0.014892314939583429,-3.9468197073010187
519.0000000000066,57.28506492996441,0.015509443656743616,-3.9453898892048214
519.8000000000067,57.364046473614714,0.015283720227315223,-3.9453898824243616
520.6000000000067,57.44394717525206,0.01638829928022012,-3.945426083385745
521.4000000000067,57.52159943413226,0.016509446291590124,-3.946773722680627
522.2000000000066,57.60277508319191,0.01736342340399971,-3.9460400719809985
523.0000000000067,57.6818643785042,0.015519779754251617,-3.946040097969359
523.8000000000068,57.76121461664512,0.015987185464421627,-3.9460394649338975
524.6000000000067,57.84108460647855,0.01501739498599064,-3.946700403365267
525.4000000000067,57.92031635456608,0.016111727557480415,-3.9466998876034545
526.2000000000068,57.99999902314387,0.015894315167685635,-3.945380096192597
527.0000000000068,58.07989377809257,0.015197915979376309,-3.9453800961392145
527.8000000000068,58.159276817224814,0.017315007653767978,-3.946355718140562
528.6000000000067,58.239063392707294,0.016365902702835444,-3.9463696193946722
529.4000000000068,58.318984974942886,0.019346034720507888,-3.946377394681556
530.2000000000069,58.39828218824176,0.016490436234739114,-3.946369868258014
531.0000000000068,58.479031572322825,0.01674317950044757,-3.946424805671998
531.8000000000068,58.559292962494055,0.014572500118810061,-3.9450498007378174
532.6000000000068,58.638727799769185,0.012708745853064585,-3.947043724030563
533.4000000000069,58.71898199808751,0.011803541332969736,-3.947031541131248
534.2000000000069,58.79971251452816,0.01227314792171319,-3.9476883540049803
535.0000000000068,58.87899796549989,0.011283576682521834,-3.9476900319625616
535.8000000000069,58.95870027705164,0.011517091308951843,-3.947689991681503
536.600000000007,59.03770630556119,0.010141035619820216,-3.94867124720269
537.4000000000069,59.118951452931476,0.011384948347419321,-3.9483497133385694
538.2000000000069,59.19824033729661,0.011463614983307946,-3.9460534892531625
539.0000000000069,59.27869769645593,0.010501868680498738,-3.946040016215425
539.800000000007,59.358038653683906,0.010852516441919757,-3.944717006538344
540.600000000007,59.437403510930224,0.01257646364195586,-3.9460427559907867
541.4000000000069,59.51767102463007,0.01118760569843752,-3.946040090051269
542.200000000007,59.59788871214024,0.01372626169372132,-3.946039827900358
543.000000000007,59.67716020779261,0.013169181743837577,-3.948659232502274
543.800000000007,59.75793524105893,0.014593253737105127,-3.9487922754987643
544.600000000007,59.83651897878458,0.012405992218049444,-3.950727008189545
545.400000000007,59.91680393680453,0.01434312612731592,-3.9494694762626334
546.000000000007,59.976840798350366,0.010833369802777493,-3.9494999184499973