File: 01_Data/Cotton_Sheet/STA/N2/10K_min/Cotton_Sheet_STA_N2_10KData_220719_R2.csv
##Temp./Â°C,Time/min,DSC/(mW/mg),Mass loss/mg
50.0,10.596552585631722,0.036017666311302765,0.0004227206223808011
51.000000000000014,10.961902110408895,0.0746277774932913,-0.001628368967509175
52.00000000000003,11.176543592770246,0.10301294773494152,0.0007295401353966113
53.00000000000004,11.349449863016511,0.12779482479714788,-0.0007130618599200389
54.00000000000006,11.500172704570044,0.14405093956355652,0.0003290168739740196
55.00000000000007,11.641903006164918,0.15793367367601485,0.000612815484761775
56.000000000000085,11.771932849985928,0.17153327683877295,-0.00036152161674873895
57.0000000000001,11.896984372094717,0.1827195736196252,-4.434393233498923e-05
58.000000000000114,12.016910995729639,0.19463351636590276,0.0009193509612144268
59.00000000000013,12.134308724264653,0.20345747548974336,0.0007140858017598006
60.00000000000014,12.250146391375047,0.21220308474619487,0.00039130886963878453
61.000000000000156,12.364261779968041,0.2201872551591273,-0.0006398101520748156
62.00000000000017,12.474429523884837,0.22407735909828852,-0.0005490867995368021
63.000000000000185,12.586187203482442,0.2316657565668414,-0.0006611808830347954
64.0000000000002,12.695982454035546,0.23685102094006227,-0.0006296668734693256
65.00000000000021,12.806248333360761,0.24311490951757775,-0.0006585044847957633
66.00000000000023,12.913620375959717,0.24954066696456367,-0.0006604352079326858
67.00000000000024,13.022120903482385,0.2556187405873467,0.0006554281070734191
68.00000000000026,13.129170000000025,0.2593236855111458,-0.0006637417605448448
69.00000000000027,13.236587620993731,0.2640889564887634,-0.0007818789442408658
70.00000000000028,13.345050543721774,0.26894403001418965,-0.0032906821925529073
71.0000000000003,13.445956474310446,0.27361306826812903,-0.003289864681503829
72.00000000000031,13.556689171919219,0.27631349804284233,-0.003327619306353391
73.00000000000033,13.661977597069468,0.28093814834076924,-0.004624883495526255
74.00000000000034,13.767039853125999,0.2846295951842206,-0.004608594400411725
75.00000000000036,13.870148103320561,0.28927031396865144,-0.003628301784022625
76.00000000000037,13.977040940248548,0.2940986476813331,-0.0037709938806029797
77.00000000000038,14.081093263262336,0.2957595459626289,-0.004609871654649211
78.0000000000004,14.183338255406479,0.29747739884218505,-0.005929891759813621
79.00000000000041,14.286996973791398,0.30202210868278023,-0.007229445986621563
80.00000000000043,14.388141040434299,0.30407990449196787,-0.005939635475312954
81.00000000000044,14.492963902698154,0.3066720859626787,-0.007240473908876943
82.00000000000045,14.595763219047909,0.3071504825168584,-0.009857617706822808
83.00000000000047,14.698385167444112,0.30851606281825283,-0.010276779301033656
84.00000000000048,14.799973662126321,0.308669743178402,-0.00988003445249408
85.0000000000005,14.901786313147289,0.3091966925235118,-0.01118967444314034
86.00000000000051,15.003775966264714,0.30957868385129517,-0.010966077798646445
87.00000000000053,15.103265187963563,0.3090146384447635,-0.011200304255181592
88.00000000000054,15.205510406011427,0.3094802701624736,-0.011200199967570157
89.00000000000055,15.30642486507223,0.3093316114659358,-0.011055903588291116
90.00000000000057,15.406545054105006,0.30754273159340806,-0.011199842682947825
91.00000000000058,15.506983227244094,0.30739557170220067,-0.01120029328369121
92.0000000000006,15.606736064106613,0.30799179100092267,-0.012519924792305126
93.00000000000061,15.705918391887488,0.3063368274797996,-0.012519835023757864
94.00000000000063,15.8055164502126,0.3058594552101176,-0.013866401024722919
95.00000000000064,15.90478929998415,0.3043101448154204,-0.013607155229433232
96.00000000000065,16.002544436921493,0.3042606884329244,-0.013831797402345636
97.00000000000067,16.102326007960773,0.3018889401841789,-0.01383000391568423
98.00000000000068,16.199950337412343,0.2990614373606115,-0.015056675473886116
99.0000000000007,16.300568747151868,0.2974616965441088,-0.015150005980795633
100.00000000000071,16.398202619129297,0.2965154379084993,-0.01425112441239662
101.00000000000072,16.496110116261704,0.29614945287107386,-0.014819766725493011
102.00000000000074,16.594826705324206,0.2933211529788182,-0.01514854048934744
103.00000000000075,16.693095973588626,0.29334023012755106,-0.015479998243002058
104.00000000000077,16.79008617980041,0.2894920211623524,-0.015480063353447981
105.00000000000078,16.887711654899622,0.29078390496406004,-0.016792915120124263
106.0000000000008,16.98531316078107,0.28748757654050316,-0.01647052093161161
107.00000000000081,17.084450963779773,0.2860011589713961,-0.015155420708778067
108.00000000000082,17.179296408632407,0.28473237615284763,-0.015517165745200678
109.00000000000084,17.280780048484186,0.28492533486685245,-0.015150169275576886
110.00000000000085,17.37528720151622,0.28215676494879904,-0.015150146077258064
111.00000000000087,17.474842349541834,0.2828338049366752,-0.016475289528393056
112.00000000000088,17.572936368066742,0.281919708659352,-0.01631090035571514
113.0000000000009,17.669170000000086,0.28146436444314005,-0.016459845016078667
114.00000000000091,17.76782182468027,0.28168488595327446,-0.016459845000423634
115.00000000000092,17.863923056737512,0.2811860159780779,-0.016460194275863316
116.00000000000094,17.962517183620086,0.28066524825988903,-0.016469920363714863
117.00000000000095,18.06035567430673,0.2802152042576378,-0.016096848502246353
118.00000000000097,18.156910993069406,0.2809479173703925,-0.017154490474816875
119.00000000000098,18.254455887603655,0.2811015555915831,-0.01644800137323088
120.000000000001,18.351667524678184,0.2806004956971778,-0.015149835348011287
121.00000000000101,18.4477998834517,0.28034952331389273,-0.016460165166550134
122.00000000000102,18.545965111730876,0.2836544693889107,-0.01645988044692892
123.00000000000104,18.642645585131312,0.28472127170850403,-0.016444812011113363
124.00000000000105,18.7405412106667,0.2845950355235969,-0.016397215729575088
125.00000000000107,18.837689998746544,0.2844576063174711,-0.015481095836030079
126.00000000000108,18.935633587712612,0.2868715206027128,-0.01680011228359035
127.0000000000011,19.030639635607095,0.2887128624574197,-0.016809981722753164
128.0000000000011,19.128279025076065,0.28885942516954755,-0.015882587828623507
129.00000000000114,19.22527940413855,0.28920649962018674,-0.013784319056714622
130.00000000000114,19.322641609742853,0.2895627365961312,-0.015150014122577993
131.00000000000114,19.419555145300073,0.2905963076691268,-0.01515002199232196
132.00000000000117,19.515721896660875,0.29193111835223307,-0.01580039718427173
133.0000000000012,19.61264876675484,0.29329650027216236,-0.015810013753529084
134.0000000000012,19.707490629388865,0.2957146249119673,-0.014826253541786905
135.0000000000012,19.804988344465013,0.29641405868932,-0.015140070044817655
136.00000000000122,19.9018813045064,0.2988775980060796,-0.015135074958847028
137.00000000000125,19.997545819437654,0.29869530125403565,-0.015149950006184021
138.00000000000125,20.09542408047798,0.29933763728597385,-0.015150146393042796
139.00000000000125,20.190963735292495,0.2995143484606875,-0.015145751142992658
140.00000000000128,20.287186384144675,0.30197918363242315,-0.013830055001573527
141.0000000000013,20.385524019660487,0.30105181880889376,-0.015148294218508163
142.0000000000013,20.48070962660249,0.302829996829557,-0.015150054756407627
143.0000000000013,20.576453548166096,0.3041086143684937,-0.015246200639084329
144.00000000000134,20.6716421441211,0.3044297502099109,-0.01548054212463601
145.00000000000136,20.769821256870127,0.30451128730633237,-0.015479823212428911
146.00000000000136,20.864266901165486,0.3074475500204047,-0.015147813155875767
147.00000000000136,20.961273886454943,0.3084242105233276,-0.015268609071281247
148.0000000000014,21.056793600933265,0.3100423139349663,-0.015149984807276695
149.00000000000142,21.153730585478883,0.3114983033016536,-0.016222381433252053
150.00000000000142,21.248251537236214,0.3120205903685983,-0.013760103809786095
151.00000000000142,21.34421843460932,0.313161171312036,-0.013820279745490716
152.00000000000145,21.440452968666712,0.315199815671387,-0.014830177050543014
153.00000000000148,21.53706835245407,0.31643975090676335,-0.013830532020365105
154.00000000000148,21.632206407850173,0.3173401613220165,-0.013769424243557538
155.00000000000148,21.728985389357454,0.3198191567059162,-0.015150755696580198
156.0000000000015,21.82487515360703,0.3202035161450758,-0.013830343799431155
157.00000000000153,21.920790149766376,0.31977153406825043,-0.013833146872227253
158.00000000000153,22.015754517858472,0.3198773683968379,-0.014818727896452444
159.00000000000153,22.111994744737512,0.3231629744043969,-0.013829854411424591
160.00000000000156,22.20777773279398,0.32385713418494066,-0.014134678733521255
161.0000000000016,22.302812370146782,0.3254774538093931,-0.014159542146391146
162.0000000000016,22.399775490052907,0.326671311691932,-0.014820054131353011
163.0000000000016,22.494674649331245,0.32811493160067984,-0.014839169051842127
164.00000000000162,22.590740253170956,0.32700561447927545,-0.015480581441663865
165.00000000000165,22.687263287009134,0.3291183919948192,-0.015156485221264226
166.00000000000165,22.78243074592092,0.33051431246509566,-0.015150148189333024
167.00000000000165,22.878092737888075,0.3315464481560084,-0.013841885185977176
168.00000000000168,22.9743074194837,0.329772910947301,-0.013757536143590876
169.0000000000017,23.069779475582976,0.33407334467027183,-0.013829864066738473
170.0000000000017,23.165345695860562,0.33434138839243777,-0.013747346308818464
171.0000000000017,23.261705547418632,0.3344468052294862,-0.015149929128379647
172.00000000000173,23.356049409915787,0.33731218580386146,-0.015115790108865212
173.00000000000176,23.452109658279216,0.3405411086359911,-0.013500305867907514
174.00000000000176,23.547532175501537,0.34020889194240955,-0.014156872492767647
175.00000000000176,23.644049074917262,0.3399840447577591,-0.01441894460414428
176.0000000000018,23.737043940410366,0.3407759373117314,-0.014054276776842123
177.00000000000182,23.83429177704218,0.34104754953803396,-0.01350985987277653
178.00000000000182,23.92927025328229,0.3447011276830432,-0.013509874241433018
179.00000000000182,24.024681957202112,0.3447122037898003,-0.0141746515556882
180.00000000000185,24.120030846120102,0.3462076381556318,-0.014169726148201
181.00000000000188,24.214329999703484,0.3493196581343184,-0.012851237231957136
182.00000000000188,24.311214573408126,0.3480581290111284,-0.01281921752796844
183.00000000000188,24.407872672604167,0.34888684996746777,-0.014159974835725286
184.0000000000019,24.502171129909023,0.35002956163661236,-0.01416006354169319
185.00000000000193,24.59798667719275,0.34895117151465693,-0.014820651588626
186.00000000000193,24.691874521871853,0.35099001954370757,-0.014293410598557266
187.00000000000193,24.78825110460771,0.35556949129498394,-0.013830144694420454
188.00000000000196,24.88334285491107,0.35487189725535906,-0.013830189113130942
189.000000000002,24.979170000000202,0.3563909355852366,-0.01449165675873676
190.000000000002,25.073827355259198,0.35741384433589807,-0.014490139907013422
191.000000000002,25.16945530875877,0.35806916646624176,-0.015147264287013407
192.00000000000202,25.263374450919052,0.3574861829625704,-0.01515007030527471
193.00000000000205,25.35955588857056,0.3586176200909521,-0.015150070013772776
194.00000000000205,25.456138456121227,0.3612369983064736,-0.015122044398505174
195.00000000000205,25.550624511747863,0.36095121784212225,-0.013830175287266933
196.00000000000207,25.644950435291772,0.36421097060160057,-0.013830142729474026
197.0000000000021,25.740132265447407,0.3667718944184788,-0.01546908458121532
198.0000000000021,25.83595630223459,0.3670619348523504,-0.014156378061876751
199.0000000000021,25.930675927868123,0.36858648305808084,-0.015470432572765702
200.00000000000213,26.026302161066447,0.3677152556516723,-0.015470175000146469
201.00000000000216,26.12168085548863,0.3707806851417931,-0.015470175000000808
202.00000000000216,26.217262646110775,0.37088192153908073,-0.015470175000001696
203.00000000000216,26.311631436618754,0.37104340525127155,-0.015470174995188657
204.0000000000022,26.40770385126521,0.37405441428805675,-0.015469600546137663
205.00000000000222,26.503877992045695,0.37311970530174987,-0.018083559814493277
206.00000000000222,26.597390381645223,0.37388637564348104,-0.016730731502694773
207.00000000000222,26.692846307559936,0.37446493399698677,-0.01547014403773872
208.00000000000225,26.788997466151447,0.3753119395958425,-0.016787152301982466
209.00000000000227,26.88363328415922,0.3762647406610576,-0.016719559624945646
210.00000000000227,26.978871246050737,0.3763963110809322,-0.015465980946589575
211.00000000000227,27.07414224964003,0.3781217702910182,-0.016837536048257995
212.0000000000023,27.169263079322928,0.37787653190726905,-0.018110335206063866
213.00000000000233,27.26375974828731,0.3788612509183152,-0.018110174442150573
214.00000000000233,27.36009169380109,0.38214962988965584,-0.01805013839780578
215.00000000000233,27.456131171385994,0.38160816423187727,-0.018175463283681914
216.00000000000236,27.550447865338562,0.3844284316740099,-0.01877002092999991
217.0000000000024,27.64555987189637,0.3873020319549075,-0.0184398088838007
218.0000000000024,27.7406792173373,0.38874763014316044,-0.017461392653422614
219.0000000000024,27.83350007177293,0.3900783191450143,-0.018123703352254772
220.00000000000242,27.93076837950843,0.3904314637935971,-0.019108308867609836
221.00000000000244,28.026323085222913,0.3906715299088351,-0.019088956092738307
222.00000000000244,28.121325005245595,0.39360174403570597,-0.017785858252526765
223.00000000000244,28.216383740110242,0.3944528316552714,-0.02042238318011158
224.00000000000247,28.31163648709102,0.39607412421679306,-0.019370263008104516
225.0000000000025,28.406861321057875,0.39771022494385055,-0.019154887822318223
226.0000000000025,28.501833573190154,0.3980810683499646,-0.019065508796529684
227.0000000000025,28.59705016730602,0.39831118949816663,-0.020420437840881434
228.00000000000253,28.69191171113524,0.39765058602813097,-0.01943674572912535
229.00000000000256,28.787417179326518,0.4009973807996924,-0.022023825479086767
230.00000000000256,28.88158661231201,0.4030321878487409,-0.02074983967421762
231.00000000000256,28.977327322568204,0.4028350284141017,-0.020749845218173135
232.0000000000026,29.073398118338847,0.4030379668693106,-0.022188983960067965
233.00000000000261,29.167376629502037,0.4058063850829754,-0.02337845206900191
234.00000000000261,29.26290589786814,0.40675300611796583,-0.02338926366328309
235.00000000000261,29.359069054512013,0.4073506120962642,-0.024698167424286765
236.00000000000264,29.45418367851528,0.4078973227929207,-0.023710144999999905
237.00000000000267,29.548798617948368,0.40818809579952176,-0.023710144998795535
238.00000000000267,29.64447584779458,0.4091304570229088,-0.02371014551289985
239.00000000000267,29.73907336613931,0.409354969840714,-0.02517422231264721
240.0000000000027,29.834149164333315,0.40922159350393883,-0.026421604564607293
241.00000000000273,29.929860566577098,0.4101987172406823,-0.026130039834917795
242.00000000000273,30.02481160911762,0.4127108576007956,-0.026130037401767225
243.00000000000273,30.120819764563738,0.4114450195254204,-0.027250743310207604
244.00000000000276,30.215719821569202,0.41245142142073443,-0.02744993505215465
245.00000000000279,30.310685165530995,0.41344799670424087,-0.027450793410331187
246.00000000000279,30.405784076599858,0.4155125202812124,-0.026907581794246127
247.00000000000279,30.500842864438038,0.41419792727198823,-0.028549758402335534
248.0000000000028,30.595956622932633,0.41619628674687886,-0.029528090882002367
249.00000000000284,30.690792220805445,0.4189601052204445,-0.03028521706722387
250.00000000000284,30.78751684590015,0.4169389288394958,-0.030825968792676406
251.00000000000284,30.8818029284316,0.4205719042937667,-0.03096001410693905
252.00000000000287,30.97684177824161,0.42141556940020525,-0.03096006033486809
253.0000000000029,31.07317376179785,0.42264081436800893,-0.031289251371578786
254.0000000000029,31.168522167890394,0.42170905191667735,-0.03273025009629826
255.0000000000029,31.263659831361608,0.4221396788645953,-0.03271990455884577
256.00000000000296,31.358885452475587,0.4234120049656976,-0.03403909014656481
257.00000000000296,31.453382908081814,0.423556899225939,-0.03403988233578126
258.00000000000296,31.549554428797045,0.4263176564212562,-0.03541406804432867
259.00000000000296,31.643724024062834,0.42412938857284666,-0.03538824644438421
260.00000000000296,31.740500729089106,0.42340170419092027,-0.036337620097569356
261.000000000003,31.83427640550275,0.42512462857548494,-0.036670396930514215
262.000000000003,31.93008041842926,0.4251175669277208,-0.037979799300677186
263.000000000003,32.026280378294516,0.42943154648497306,-0.03797994889057765
264.00000000000307,32.12102795100618,0.4289907633222834,-0.03970497587003319
265.00000000000307,32.21601165982766,0.42887956061224747,-0.04073218125492062
266.00000000000307,32.31178234793365,0.42946320649754055,-0.04206582065126785
267.00000000000307,32.40620578675003,0.4326512673212294,-0.042400288721387014
268.00000000000307,32.50257765396434,0.43368739580033894,-0.04203986062925136
269.0000000000031,32.59724293235437,0.43356063675565026,-0.0430318807537482
270.0000000000031,32.690466185759945,0.43408849814389044,-0.04479209560746167
271.0000000000031,32.787793799222,0.437395108860578,-0.046110182654300225
272.0000000000032,32.88391114321696,0.4369134172205432,-0.046105903575598184
273.0000000000032,32.97866163089256,0.4398141521053194,-0.04860037340380341
274.0000000000032,33.074511377203336,0.4426524737997665,-0.04874262109736005
275.0000000000032,33.169365574432156,0.44326769119236864,-0.049416143656499045
276.0000000000032,33.26471005019172,0.44525918110786356,-0.051465224418878464
277.00000000000324,33.361756539326706,0.44911894687239745,-0.052697070071543006
278.00000000000324,33.455473260470136,0.4504878995937307,-0.05439235044013202
279.00000000000324,33.55124381198949,0.4531773863328369,-0.056630630168838625
280.0000000000033,33.64824495451516,0.45580280730491174,-0.057554598309457194
281.0000000000033,33.74253811742224,0.46001801399307957,-0.060021035047884475
282.0000000000033,33.83814557281243,0.46192951452139025,-0.06153795402997764
283.0000000000033,33.93339810320793,0.4645980466350863,-0.06414655390380641
284.0000000000033,34.02935666242884,0.4680032162027654,-0.06520994766686972
285.00000000000335,34.12516291562623,0.471766941951281,-0.06754195882757097
286.00000000000335,34.22060687146601,0.4741417943279599,-0.07048443298579654
287.00000000000335,34.315175334309664,0.4793231732515997,-0.0721600678958847
288.0000000000034,34.40932375070865,0.48250933603914337,-0.07375802050662639
289.0000000000034,34.50717578127016,0.48724035141088534,-0.07743714817146685
290.0000000000034,34.6026518945808,0.4917464696263928,-0.07995660768939494
291.0000000000034,34.69648981277299,0.49705841920185406,-0.08420196104305022
292.0000000000034,34.79373687545791,0.49955686746894035,-0.08870177935864954
293.00000000000347,34.89039864022228,0.5036713660557472,-0.08937300538594828
294.00000000000347,34.986491939637595,0.5084150474604018,-0.09397229618912117
295.00000000000347,35.081770571447265,0.5117353304997908,-0.097369679371901
296.0000000000035,35.177558116890296,0.5158342717393261,-0.10379706885615514
297.0000000000035,35.27403117044619,0.5228548059962809,-0.10811899222543442
298.0000000000035,35.36986454057138,0.5261365622775133,-0.11402015666067378
299.0000000000035,35.46539282690359,0.5316965730997205,-0.11868424645908826
300.0000000000035,35.56033399743763,0.5375001988185832,-0.12426587588617721
301.0000000000036,35.65690466318744,0.5439972744584364,-0.12918109278186485
302.0000000000036,35.751807204370046,0.5475170836888641,-0.13548952736638142
303.0000000000036,35.84819240664423,0.5561770763412761,-0.1410932442324322
304.00000000000364,35.94419324837301,0.561373730066166,-0.1484240119452176
305.00000000000364,36.039889155219385,0.5722830455000172,-0.15498016303201734
306.00000000000364,36.13629552476294,0.5805657072280753,-0.16282249286135908
307.00000000000364,36.231330087572935,0.5862799299802689,-0.17049770113734475
308.00000000000364,36.32542559318591,0.5930311896567242,-0.17903131210572187
309.0000000000037,36.42284716481414,0.6011615495719651,-0.18795528324940403
310.0000000000037,36.51917000000037,0.6119770066452339,-0.19771988963838583
311.0000000000037,36.6150796197173,0.6197153914695672,-0.20739663492182148
312.00000000000375,36.71123909012036,0.6277106976018636,-0.21336755184658518
313.00000000000375,36.80562574656942,0.6379179085045887,-0.22533925746024952
314.00000000000375,36.90280727997568,0.6483425607947525,-0.23730925032792305
315.00000000000375,36.99927247919586,0.6617395715984816,-0.25144235563693673
316.00000000000375,37.093184302198765,0.6723598080992398,-0.26398896158412644
317.0000000000038,37.19088220671008,0.6843264729217851,-0.2772735346097379
318.0000000000038,37.286384402326945,0.6971914285404655,-0.2923435591355381
319.0000000000038,37.3834565579076,0.7126912040581022,-0.3074446711110723
320.00000000000387,37.47917000000036,0.7253119984461327,-0.32213015696383174
321.00000000000387,37.574832574056785,0.7383209028376256,-0.33775162014135995
322.00000000000387,37.671170814456914,0.7529679688134773,-0.35433136499652074
323.00000000000387,37.76806513223571,0.7701102526927252,-0.373929155718165
324.00000000000387,37.86393082792633,0.7864883591367735,-0.39191300296643083
325.0000000000039,37.96046505953064,0.80121720001428,-0.4115744709991498
326.0000000000039,38.05647430961399,0.8182828763336034,-0.4322459195612427
327.0000000000039,38.15341574679938,0.8371142938461976,-0.45376752146147625
328.000000000004,38.249865046877964,0.8548556690834079,-0.4773942760650254
329.000000000004,38.34561027093321,0.873486708006101,-0.5000101665330545
330.000000000004,38.44240762008544,0.8925359448316278,-0.5253917035251945
331.000000000004,38.539066070953,0.913742324320832,-0.5507563073535771
332.000000000004,38.63487571801243,0.9358691175973446,-0.5781594925413533
333.00000000000404,38.73189480463978,0.9559796555262239,-0.6067422442386516
334.00000000000404,38.828204973943585,0.9781694275770811,-0.6351315430068905
335.00000000000404,38.925842435362114,0.9996967673878643,-0.6645727582465208
336.0000000000041,39.023186788850886,1.0239058135082622,-0.6995713880009831
337.0000000000041,39.11961500501364,1.0515703154897682,-0.7326501908577843
338.0000000000041,39.21485756554001,1.0760385393738618,-0.7679820323814024
339.0000000000041,39.311959484368735,1.0997543295227183,-0.8037011718399443
340.0000000000041,39.408392559728846,1.1262833307559044,-0.8427175666451481
341.00000000000415,39.50573263058139,1.1559340600714754,-0.881198907368852
342.00000000000415,39.60212796137133,1.1822037171669415,-0.9239170231141225
343.00000000000415,39.69871576339789,1.2140514577322812,-0.9668803185945563
344.0000000000042,39.79573134852098,1.2419492516423152,-1.0101306791531344
345.0000000000042,39.893230167183475,1.2736696243774925,-1.058177240277741
346.0000000000042,39.98965583016735,1.3037270169149733,-1.1049913393110677
347.0000000000042,40.08709782656826,1.3377713634137636,-1.1574545762424013
348.0000000000042,40.18343431777234,1.3694368249501232,-1.206516552109647
349.00000000000426,40.28130222302319,1.4056096098131194,-1.263495883452431
350.00000000000426,40.37829418198144,1.4411922880845038,-1.3189589164638669
351.00000000000426,40.475450434424054,1.4773007372030467,-1.3776007849886591
352.0000000000043,40.572303893511666,1.5111149654667517,-1.4391779430442067
353.0000000000043,40.669070112105125,1.5458030838036594,-1.5000184482409171
354.0000000000043,40.76596173741073,1.5804941919926492,-1.56621784755687
355.0000000000043,40.864619751842355,1.6134438992533693,-1.6329786379328435
356.0000000000043,40.96113066607946,1.6441561131678506,-1.701868117907888
357.0000000000044,41.058754783864394,1.6726658635392653,-1.7721892728715254
358.0000000000044,41.154461535917335,1.7004157886837912,-1.8425443595231656
359.0000000000044,41.25156547284583,1.72125451532106,-1.9168701984319099
360.00000000000443,41.350581954871906,1.7406508242186074,-1.990900194013066
361.00000000000443,41.44786426190791,1.7539587669456878,-2.069509842929233
362.00000000000443,41.544720340559664,1.7612642756229577,-2.1436391094213114
363.00000000000443,41.64149031555704,1.7601387244541788,-2.219236458127262
364.00000000000443,41.7389782199501,1.75322975928941,-2.296437495991118
365.0000000000045,41.8362286143955,1.73351859506461,-2.3721706995552747
366.0000000000045,41.93313593369441,1.710475924126484,-2.4475327732343155
367.0000000000045,42.028975725877224,1.6771263728313386,-2.518505859622536
368.00000000000455,42.12657939869292,1.6372644303541992,-2.591382597875386
369.00000000000455,42.22336688123968,1.5895620006593039,-2.659329203107724
370.00000000000455,42.31906311000184,1.5373805499394448,-2.725617329333774
371.00000000000455,42.41662465679225,1.4741183965464484,-2.788657545783271
372.00000000000455,42.51172987486609,1.4082419278318263,-2.846811425883474
373.0000000000046,42.60806658793274,1.3330011910198394,-2.90554195367201
374.0000000000046,42.70479679838118,1.254658408461522,-2.957289549316108
375.0000000000046,42.801222552125076,1.1709830563873225,-3.0048788058861
376.00000000000466,42.8978975403251,1.0804357198860353,-3.0501415892828265
377.00000000000466,42.99337914913818,0.9886264371051519,-3.089944917717994
378.00000000000466,43.08963380649906,0.8988722654784274,-3.1261246678157866
379.00000000000466,43.18529822906828,0.8041618158503785,-3.154582203511808
380.00000000000466,43.28216620319284,0.7149396886181216,-3.1831933466184976
381.0000000000047,43.37774254142146,0.6302049681571251,-3.2032617474076286
382.0000000000047,43.473315831438605,0.5529556665655266,-3.2218948850789317
383.0000000000047,43.56887528402201,0.4839073208934488,-3.2358161690975984
384.0000000000048,43.66629962162063,0.42085668899480116,-3.2458209157455378
385.0000000000048,43.76198082268531,0.3726965319217297,-3.2553362909059267
386.0000000000048,43.858684563665626,0.3328440736922162,-3.2606409343223306
387.0000000000048,43.95399271035758,0.3033662688489492,-3.266965775209654
388.0000000000048,44.0501131563234,0.2846166998602427,-3.269680495897889
389.00000000000483,44.14767016347812,0.2696937013688054,-3.2722965870557315
390.00000000000483,44.243239113771374,0.26492824694750405,-3.274904507380705
391.00000000000483,44.34114155783516,0.2617436963500894,-3.2771924642339263
392.0000000000049,44.435969595763936,0.2592479544840826,-3.2790456765865654
393.0000000000049,44.53301827993439,0.25942815369219885,-3.280264449092856
394.0000000000049,44.6305464240619,0.2620178019438536,-3.2826166215268744
395.0000000000049,44.72593073610787,0.27301676619069865,-3.2852146547543235
396.0000000000049,44.823207018217964,0.2782508802544728,-3.2866395109864164
397.00000000000495,44.91974717685118,0.2805452875099298,-3.287917834724445
398.00000000000495,45.01645283081587,0.2837896056283196,-3.2869083788501383
399.00000000000495,45.11391604430458,0.2845558150093403,-3.289843769681032
400.000000000005,45.21083462947722,0.2838182764490953,-3.289768849358683
401.000000000005,45.30846970968274,0.28521346768368566,-3.2910743622714866
402.000000000005,45.40483595361329,0.2865024358306765,-3.2933907646291836
403.000000000005,45.50294970307364,0.28678466731454244,-3.294694351417207
404.000000000005,45.599072272950515,0.28866345103562535,-3.296029339077312
405.00000000000506,45.697006503564346,0.28691886571173963,-3.2973519219539
406.00000000000506,45.794205873606494,0.28692900268063076,-3.2986374089243427
407.00000000000506,45.891626692578484,0.2890826992090614,-3.2999682842409275
408.0000000000051,45.989275923574986,0.2892646725667711,-3.2999797876043053
409.0000000000051,46.0865865333874,0.28755573607621066,-3.3023908202213224
410.0000000000051,46.183243894591264,0.2905403595428776,-3.3026099025784026
411.0000000000051,46.28047393735741,0.28813186373335736,-3.303916707560644
412.0000000000051,46.378852491429626,0.2889255330179395,-3.3039299543742713
413.0000000000052,46.47545672067838,0.28952313224627574,-3.3052714166495827
414.0000000000052,46.571933696810575,0.2893255785279617,-3.306566879793576
415.0000000000052,46.671551496193906,0.2892556358280204,-3.307880094332171
416.00000000000523,46.769068572654405,0.28842202548470997,-3.309200221895873
417.00000000000523,46.866484155482325,0.2881151554684576,-3.310131417412278
418.00000000000523,46.964321173277696,0.28895057686283826,-3.3107995370419037
419.00000000000523,47.06179445886143,0.2893598691116699,-3.3122838638189425
420.00000000000523,47.158981948226675,0.2900367144648171,-3.313479957028993
421.0000000000053,47.256404777302215,0.2913422436018129,-3.312869847231766
422.0000000000053,47.35333657823031,0.2929570213673526,-3.316185599923359
423.0000000000053,47.45200690150241,0.2901945414496735,-3.314786333265673
424.00000000000534,47.546886832305574,0.29185572265716997,-3.3161541821033684
425.00000000000534,47.64685244521421,0.29171564018957064,-3.318785581223281
426.00000000000534,47.74465499887829,0.2939039237632425,-3.320070650499317
427.00000000000534,47.84279782194248,0.2916282626211829,-3.31975406524181
428.00000000000534,47.939563010125006,0.2925122997642943,-3.320069844856148
429.0000000000054,48.03760993298832,0.29537781406814434,-3.321399539746906
430.0000000000054,48.135997857536786,0.2948233030894862,-3.3237014281479826
431.0000000000054,48.23421798313613,0.29398824580089333,-3.323683591641424
432.00000000000546,48.33185745733753,0.29352621101214044,-3.323696102257118
433.00000000000546,48.42906655071015,0.29192229325579033,-3.325001546841455
434.00000000000546,48.52852861607532,0.29369851652940004,-3.3270141712065913
435.00000000000546,48.62689419640164,0.2961003589117176,-3.3279701255137244
436.00000000000546,48.72499643421937,0.29731511797651333,-3.3293802220326736
437.0000000000055,48.82247120328335,0.29689615798236646,-3.3292967557782043
438.0000000000055,48.920916878792866,0.2965979713295616,-3.3306110022086752
439.0000000000055,49.01887127172333,0.29642862459687247,-3.3332273480973114
440.00000000000557,49.116656996610985,0.2989617197149114,-3.3319211955242327
441.00000000000557,49.214953258452766,0.29882239275874606,-3.333246774104949
442.00000000000557,49.31066536165207,0.2991639325094082,-3.335228981664635
443.00000000000557,49.41092618090222,0.3003395415493594,-3.336843998238364
444.00000000000557,49.50795094730261,0.2980188379220626,-3.3372036676677475
445.0000000000056,49.60665226620829,0.3007859453376231,-3.338076063106251
446.0000000000056,49.70441480569607,0.3015091884212564,-3.3381801397450217
447.0000000000056,49.802451065860886,0.30185470263542885,-3.3381802241356184
448.0000000000057,49.89897507642734,0.3017294675865062,-3.3394992821721488
449.0000000000057,49.998185515041655,0.30392829688704215,-3.340819911995449
450.0000000000057,50.09682864207162,0.3049424335915996,-3.3421288741318387
451.0000000000057,50.19380624791279,0.3036142354496634,-3.3434633590567127
452.0000000000057,50.29158038497439,0.3044018947191023,-3.342127409065388
453.00000000000574,50.38974346602088,0.30514847744837764,-3.3447709962812158
454.00000000000574,50.48576716809717,0.3059476119324591,-3.3460946998155205
455.00000000000574,50.58547135205254,0.308710585224701,-3.345430054213932
456.0000000000058,50.68339652317091,0.30890767265745067,-3.3472468958399766
457.0000000000058,50.782879696665574,0.30948108502040284,-3.3485632194185113
458.0000000000058,50.880904402750154,0.30853810408098215,-3.348167837193735
459.0000000000058,50.9802014786089,0.3066980274609259,-3.349490429188828
460.0000000000058,51.07871873805723,0.30854625768301996,-3.3508100374619056
461.00000000000585,51.17599198605565,0.31025081068122207,-3.3521127942088684
462.00000000000585,51.27485893495957,0.31144925527152945,-3.352411863006812
463.00000000000585,51.372814640714815,0.3135131746532225,-3.3547603076564805
464.0000000000059,51.4720676546152,0.31469275768887617,-3.3547600249858247
465.0000000000059,51.57069724768973,0.3119936001165611,-3.3560874204230196
466.0000000000059,51.66869533232898,0.3152104566928167,-3.3568037438477063
467.0000000000059,51.76673841272982,0.3167788169824015,-3.3567300612024544
468.0000000000059,51.86628833417217,0.31499898593760844,-3.3580485649152076
469.00000000000597,51.96247445644355,0.3156870370506648,-3.3580499583653634
470.00000000000597,52.06221644437238,0.31642829347591916,-3.3593648545952624
471.00000000000597,52.16246096880304,0.31713461190888814,-3.360690156391609
472.000000000006,52.25947481175873,0.31610228573087035,-3.3606916204653023
473.000000000006,52.35867741887962,0.31907202400046086,-3.361999949358305
474.000000000006,52.456661921893684,0.3180168290263249,-3.363303324183615
475.000000000006,52.55511900943042,0.3188984990306024,-3.3636178756660975
476.000000000006,52.65507358410631,0.3175873219813843,-3.3640183879757837
477.0000000000061,52.75355824362345,0.3199439113947219,-3.3652200467390094
478.0000000000061,52.852094341598814,0.3216618390601289,-3.365289695085437
479.0000000000061,52.95063971652983,0.3201825041728726,-3.366609870194094
480.00000000000614,53.04964015170999,0.3199260804679784,-3.366939903381307
481.00000000000614,53.1480192246876,0.3203296765967339,-3.3678661002459096
482.00000000000614,53.24629360674772,0.3187148917621541,-3.3699275991906164
483.00000000000614,53.34488284562258,0.32041607984673354,-3.369233773563886
484.00000000000614,53.44226562381782,0.32064287145944204,-3.370560176126056
485.0000000000062,53.54201178140892,0.3201274111932648,-3.3719192965303337
486.0000000000062,53.6399949055189,0.32042944737708023,-3.3718838936678366
487.0000000000062,53.73877764818138,0.32078092291991034,-3.372540018458471
488.00000000000625,53.83818784414794,0.3210754491166419,-3.3751839741272267
489.00000000000625,53.9369001553445,0.3206945485177889,-3.3751799118167707
490.00000000000625,54.03566104305933,0.3214682853379277,-3.3764909120753126
491.00000000000625,54.135072096148306,0.3198554122363305,-3.376528659792657
492.00000000000625,54.23397854376568,0.3185895712561667,-3.376489937083111
493.0000000000063,54.33380946398523,0.3172422434501625,-3.3778136629632134
494.0000000000063,54.432036277619915,0.31753658171273935,-3.379129834902642
495.0000000000063,54.531577629505954,0.31689565695741334,-3.378144607887701
496.00000000000637,54.62958229279085,0.3165998476964207,-3.3781393678426084
497.00000000000637,54.728521371128075,0.3182892117086631,-3.3794528945765494
498.00000000000637,54.829593057660986,0.31744286435319796,-3.380439902114789
499.00000000000637,54.92841462739619,0.3150873783610625,-3.3804399052199074
500.00000000000637,55.02648440536575,0.31601086310859516,-3.3817604630029465
501.0000000000064,55.12547387520544,0.31391839710613034,-3.3819814852849195
502.0000000000064,55.224292586709005,0.3142423871905177,-3.383085204231916
503.0000000000064,55.32320687301008,0.3159907352733037,-3.3830516846053076
504.0000000000065,55.42240761282434,0.3145139833249879,-3.3843991181985045
505.0000000000065,55.52124788200095,0.313866750681165,-3.3857150227271964
506.0000000000065,55.62006611596008,0.31334838044768837,-3.3857101226854835
507.0000000000065,55.71704774151702,0.3105232665617388,-3.3870324190864927
508.0000000000065,55.818773923601185,0.3090111981382837,-3.387030059758596
509.00000000000654,55.91723963850297,0.3067317301754984,-3.3868911980590397
510.00000000000654,56.015961485446766,0.30632374525328426,-3.387368791680471
511.00000000000654,56.115224337057676,0.305513267739971,-3.3883365933137357
512.0000000000066,56.21453466367594,0.29995525698226283,-3.3885387139815437
513.0000000000066,56.31264940174962,0.2990392763553441,-3.389971350009222
514.0000000000066,56.41214641547578,0.29839611027055657,-3.390979972377754
515.0000000000066,56.5112026076575,0.2953592304998028,-3.3909403791557216
516.0000000000066,56.61072823766008,0.29387221232922034,-3.3909940001206973
517.0000000000066,56.70906423536553,0.29201039363322606,-3.3923101440216974
518.0000000000066,56.80865563595233,0.29006153433859794,-3.392310145048775
519.0000000000066,56.90711504386409,0.29000855663920044,-3.3923353437097408
520.0000000000067,57.00684944609426,0.2874004318166967,-3.3945963979667475
521.0000000000067,57.10575952604281,0.2875350261756703,-3.394610040299492
522.0000000000067,57.2038935139701,0.2850611513771508,-3.3943449519611955
523.0000000000067,57.3054918592255,0.2846898844232193,-3.394609809731678
524.0000000000067,57.403054843534946,0.28223967805903305,-3.3946098099965396
525.0000000000068,57.50260306893597,0.2845200176263887,-3.394605731356206
526.0000000000068,57.60265335602976,0.2818344021643867,-3.3958980792861704
527.0000000000068,57.7016185584126,0.28074244010794946,-3.3958964074191953
528.0000000000068,57.802561241930896,0.28263900674428055,-3.3968532892366934
529.0000000000068,57.901434639002986,0.28346593126194475,-3.3972500044784892
530.0000000000068,58.00151217138493,0.2828269908535247,-3.397777218807655
531.0000000000068,58.09974725625596,0.278866943747564,-3.3985724405737323
532.0000000000068,58.199766927220665,0.2781566706971339,-3.399880075771403
533.0000000000068,58.29834008613002,0.2776585692062441,-3.399892058000889
534.0000000000068,58.3985424378181,0.27537616891591105,-3.4011999705703237
535.0000000000068,58.497078078413665,0.2761854151043339,-3.4012543925130276
536.0000000000069,58.5958872411047,0.27632705352928116,-3.399887190244377
537.0000000000069,58.69608988120254,0.27620474752226837,-3.402423988523747
538.0000000000069,58.79530588849268,0.2770601629605916,-3.4022242746891473
539.0000000000069,58.894955675126425,0.27772134735566956,-3.4010634744213233
540.0000000000069,58.99276623139739,0.2748466085978609,-3.4024013842227845
541.000000000007,59.092977637300486,0.27490564777429216,-3.4024110609922467
542.000000000007,59.193763583817905,0.27260901117370495,-3.403719951253052
543.000000000007,59.292256517395586,0.2753937373150354,-3.4023992813386195
544.000000000007,59.39151876461302,0.27371760641985277,-3.403719976086337
545.000000000007,59.49096741924475,0.2742351041221395,-3.4037199349977563
546.000000000007,59.590627187394574,0.27219911944305564,-3.403718859570885
547.000000000007,59.689449107601476,0.27657082197865096,-3.4050399126706212
548.000000000007,59.78917000000068,0.27372544242514346,-3.405443484443338
549.000000000007,59.888074673376096,0.27562479659350214,-3.4053701301162604
550.000000000007,59.988324868967275,0.27518948060576476,-3.405635408184155
551.000000000007,60.08718850108169,0.2777859816608572,-3.408006388117795
552.0000000000072,60.188136254101124,0.27643479113513403,-3.4066799077629017
553.0000000000072,60.287781499103566,0.276821909676726,-3.4079942463531445
554.0000000000072,60.387503720900945,0.2776035656845065,-3.40832992819702
555.0000000000072,60.4860289203946,0.2764749768748352,-3.4083301241698987
556.0000000000072,60.58404344816706,0.2789511767694735,-3.409320318653682
557.0000000000073,60.68562225972751,0.28107111989487676,-3.410308533812158
558.0000000000073,60.78434059819895,0.28004067839755664,-3.410309914997304
559.0000000000073,60.884450536235235,0.2797110478356604,-3.41031057158464
560.0000000000073,60.983040261781994,0.28102172638069295,-3.411609718704372
561.0000000000073,61.08299673276893,0.28385050824994273,-3.410960163520274
562.0000000000073,61.182998879217635,0.2846263298060163,-3.412283059270777
563.0000000000073,61.28262933510521,0.2823098803641957,-3.412284960400111
564.0000000000073,61.38273283038001,0.2828850114877534,-3.4122773400541373
565.0000000000073,61.48155109081213,0.28538725967286604,-3.413600045097107
566.0000000000073,61.58091317876522,0.28422651993029063,-3.4109744822866213
567.0000000000074,61.68166128656922,0.2852589247634309,-3.4122397019729025
568.0000000000074,61.78210066318922,0.2857044298169618,-3.414588377835693
569.0000000000074,61.88209574945455,0.29014182807156486,-3.4132802340055504
570.0000000000074,61.981859222087756,0.2883977699986312,-3.4145913573369766
571.0000000000074,62.08137533932331,0.2911428423584217,-3.415900044080228
572.0000000000074,62.180769552446016,0.2903181040133563,-3.4159078911628873
573.0000000000074,62.2812950598207,0.29349186649546316,-3.4145906890755264
574.0000000000075,62.380161882231974,0.29110282244081653,-3.415250346511713
575.0000000000075,62.47971219975688,0.29359362287633006,-3.4159098931789758
576.0000000000075,62.58042997766107,0.2940644694549409,-3.415909343460668
577.0000000000075,62.68002061984305,0.2968521180510262,-3.4169009086545215
578.0000000000075,62.78007107947982,0.2996492954440545,-3.4169001427737076
579.0000000000075,62.87974327905322,0.29946787480751336,-3.4172296857750837
580.0000000000075,62.97987040951535,0.2995291354847172,-3.418550111798093
581.0000000000075,63.079170000000865,0.301890293587475,-3.4185501149999986
582.0000000000075,63.17777812922461,0.30634180343855,-3.41908464672804
583.0000000000076,63.278851772405204,0.30669627551130907,-3.418813866314659
584.0000000000076,63.37927216310986,0.3073605688070108,-3.4188690698744173
585.0000000000076,63.479259159955774,0.31222558935904254,-3.4201901847389586
586.0000000000076,63.57830291414672,0.3109087444747995,-3.420190185000007
587.0000000000076,63.67896775767335,0.3168947180444345,-3.42019018546365
588.0000000000076,63.778753574945306,0.3161376079564664,-3.4205191547817737
589.0000000000076,63.87960515669091,0.3158967819787807,-3.4205282721115458
590.0000000000077,63.979377354544454,0.31833702759534255,-3.420187859841869
591.0000000000077,64.07937201284152,0.3187872869360804,-3.4198600815078155
592.0000000000077,64.17878945489646,0.32177460711040173,-3.421180013044893
593.0000000000077,64.27876709459449,0.3248315517378201,-3.4223420636082373
594.0000000000077,64.37990722146283,0.3253556326508824,-3.422501025566987
595.0000000000077,64.4794711126345,0.32619212273771075,-3.4238120783862076
596.0000000000077,64.57897356664154,0.32957893631596635,-3.4224902072006658
597.0000000000077,64.67833706458264,0.3294988348297276,-3.4224923744162625
598.0000000000077,64.77820810239301,0.33417501702710095,-3.424381797162631
599.0000000000078,64.87732961502422,0.3352845993153758,-3.424800016498299
600.0000000000078,64.97896205835862,0.3362778865849456,-3.423812738066518
601.0000000000078,65.07801043650764,0.3359552948246801,-3.4234799761482235
602.0000000000078,65.17840182371235,0.33927185468582677,-3.424836270522863
603.0000000000078,65.27827089069794,0.34214693147571407,-3.4241414546648845
604.0000000000078,65.3782188349477,0.3444431957438532,-3.4256116117586357
605.0000000000078,65.477700401374,0.34483931233157006,-3.424151995240741
606.000000000008,65.57790293068828,0.35173766644479904,-3.4241508632288222
607.000000000008,65.67820516142298,0.3532977070921253,-3.426766387566912
608.000000000008,65.77926520662812,0.3556367170836307,-3.4271067223718727
609.000000000008,65.87848104593832,0.35688698758642123,-3.4267816591216516
610.000000000008,65.97958012017693,0.3624688482488589,-3.4261208830082817
611.000000000008,66.07821099914979,0.36189545583451754,-3.42776000604445
612.000000000008,66.17880236709954,0.36082167861916287,-3.4277601610669057
613.000000000008,66.27945356386263,0.3629259727272126,-3.427441481226551
614.000000000008,66.37838256834884,0.3636374782436876,-3.428415096283347
615.0000000000081,66.47823957677862,0.36702627794325715,-3.4271102850474007
616.0000000000081,66.57896711259276,0.3683427829843553,-3.427109980000668
617.0000000000081,66.67855338966629,0.36999516147265543,-3.4271099763704176
618.0000000000081,66.77806504697175,0.3751824959712337,-3.42744165459862
619.0000000000081,66.87874073976253,0.37737814273685866,-3.430073198360261
620.0000000000081,66.97832943797258,0.3797996062265012,-3.4303692215916755
621.0000000000081,67.0783931619859,0.3798236933055007,-3.4310490447184323
622.0000000000082,67.17887601398748,0.38127810362676134,-3.4287593354490795
623.0000000000082,67.27886613936997,0.3830644322914881,-3.430070121517745
624.0000000000082,67.3791700000008,0.3852396064482938,-3.4300701249999994
625.0000000000082,67.47973181388376,0.3882404955837846,-3.4300700733271015
626.0000000000082,67.5789732319522,0.39010835044542413,-3.431390027577348
627.0000000000082,67.6791700000009,0.39092913658483386,-3.4310685103335827
628.0000000000082,67.77990347112423,0.3937407242276045,-3.431060020057742
629.0000000000082,67.88039913705327,0.3979603112641774,-3.4310952261818506
630.0000000000082,67.98053068934362,0.39862559369427525,-3.431055578175854
631.0000000000083,68.08096173502327,0.3988956986870126,-3.4310600732141916
632.0000000000083,68.18123011407252,0.40425973711163077,-3.432380301058987
633.0000000000083,68.28127820385023,0.4049792744987445,-3.43170090876984
634.0000000000083,68.38095111985187,0.4068019558825459,-3.431714016629881
635.0000000000083,68.48141651664697,0.408695234171129,-3.432710135370172
636.0000000000083,68.58124046173663,0.4143393682381231,-3.4330328989812027
637.0000000000083,68.68208869845371,0.4122912336578497,-3.433369943883278
638.0000000000084,68.78311548018509,0.417675673270158,-3.434347973965266
639.0000000000084,68.88241194489133,0.41964788373405504,-3.4340199505867584
640.0000000000084,68.98404889159677,0.42176597403432414,-3.434027295393622
641.0000000000084,69.08490213459139,0.4265708207808154,-3.433595551256886
642.0000000000084,69.18609216717628,0.42932062969742174,-3.434020115058325
643.0000000000084,69.28511413459968,0.4299295184350521,-3.434019987564961
644.0000000000084,69.38686517855234,0.4311579746029758,-3.4336501610795938
645.0000000000084,69.48826565868487,0.4322831164674536,-3.435010179178022
646.0000000000084,69.58705752081563,0.4364315510508759,-3.435010179801385
647.0000000000085,69.6877952814878,0.44020995728260487,-3.433698507409287
648.0000000000085,69.78827379839188,0.43803889783460564,-3.435338454387699
649.0000000000085,69.889264270619,0.4395277877235492,-3.4353401807679655
650.0000000000085,69.98998108059584,0.4405260662656853,-3.4348901300323136