File: 01_Data/Cotton_Sheet/STA/N2/10K_min/Cotton_Sheet_STA_N2_10KData_220718_R1.csv
##Temp./Â°C,Time/min,DSC/(mW/mg),Mass loss/mg
50.0,10.536312624473664,0.0065355711070114175,-0.04344493031741248
51.100000000000016,10.973675568331553,0.06688349079474132,-0.04067707064822468
52.20000000000003,11.199307827262224,0.10036963826196565,-0.04114173801620735
53.30000000000005,11.385219039530787,0.1254915992869139,-0.04219284007731172
54.40000000000006,11.548228512222334,0.15027848141141575,-0.04180422633256997
55.50000000000008,11.69647393883418,0.1678460061105551,-0.04068509529125741
56.600000000000094,11.839123636080608,0.18124682989111385,-0.04145669830732057
57.70000000000011,11.974735903403745,0.1926900583728841,-0.042421604201965835
58.800000000000125,12.104328535231042,0.2054797795736958,-0.04374806970719236
59.90000000000014,12.230116249467955,0.21303457397680603,-0.04230818511016299
61.000000000000156,12.35630309575227,0.22212303222897445,-0.0436502676210595
62.10000000000017,12.479291957097804,0.22937550670972984,-0.045004711715469714
63.20000000000019,12.60220443523461,0.235046177719201,-0.043824529423684755
64.30000000000021,12.72102582009431,0.2425900362107758,-0.0464994140280397
65.40000000000022,12.843646927584397,0.24769789202685843,-0.04653550373712889
66.50000000000023,12.961150671490472,0.2575278232993963,-0.04784404366122841
67.60000000000025,13.080800684525334,0.2600608981921284,-0.04775840471452053
68.70000000000027,13.197430119818423,0.26580592629514654,-0.04907953647141339
69.80000000000028,13.316473245667531,0.26933904618991134,-0.050396376467358284
70.90000000000029,13.430000000000028,0.27451162208711755,-0.05039371848917451
72.00000000000031,13.549456987542296,0.27997558549977275,-0.05267406127072949
73.10000000000034,13.664682566201915,0.2835664586715748,-0.0529474304035924
74.20000000000034,13.782618272770396,0.28975637391877096,-0.054352688348800804
75.30000000000035,13.8971932034194,0.2941723353036747,-0.0543401840611164
76.40000000000038,14.012766900711085,0.2963067901360492,-0.054355296451498614
77.5000000000004,14.127491439637192,0.3003271929314426,-0.05566779146246903
78.6000000000004,14.241329949701553,0.3029282837332936,-0.05698949554303079
79.70000000000041,14.35495338811247,0.30783770247369124,-0.05730493862326336
80.80000000000044,14.468569244142882,0.31182532220943093,-0.05862981475685869
81.90000000000046,14.581048590706441,0.31164889655018946,-0.05996809417146931
83.00000000000047,14.69315109550909,0.31508678868218354,-0.06093468963049897
84.10000000000048,14.8049290839603,0.318916796697701,-0.05961794539703158
85.2000000000005,14.91707364971265,0.31651801611018104,-0.06093009368565783
86.30000000000052,15.02788941806482,0.31784820945876324,-0.06228479343035653
87.40000000000053,15.138840104254731,0.31857307967532067,-0.06240061517905637
88.50000000000054,15.250188752906459,0.31859786570274296,-0.06225972146242409
89.60000000000056,15.359151306624206,0.31573769917252925,-0.06325079223677665
90.70000000000059,15.46892829993566,0.31572228345915265,-0.06493528738812948
91.8000000000006,15.57919228834318,0.3135498908210418,-0.0649071612720884
92.9000000000006,15.688249573291891,0.31321635703455797,-0.06487646270588909
94.00000000000063,15.796886713540822,0.3095625101642622,-0.06488939057011756
95.10000000000065,15.906472622461578,0.31082963916809203,-0.06654294405412342
96.20000000000066,16.01499905809514,0.3092254766964134,-0.0676070191971796
97.30000000000067,16.123751760949716,0.30720529605042235,-0.06649771042396369
98.40000000000069,16.231413906136368,0.30478917792622384,-0.0678476755865347
99.50000000000071,16.340171398599715,0.3029523541459719,-0.06928748880289337
100.60000000000072,16.447210210481078,0.30101376297088933,-0.07082585198233193
101.70000000000073,16.555230142620847,0.2992420173457392,-0.0707852114904588
102.80000000000075,16.66361771338621,0.29716780033102463,-0.07305670071823744
103.90000000000077,16.77154068787497,0.29668892602684915,-0.0721307330301415
105.00000000000078,16.878921658545085,0.29413233097436886,-0.07315587549388658
106.10000000000079,16.98580570669565,0.29350341367126276,-0.07180970399652464
107.20000000000081,17.093179045596724,0.29029889127894903,-0.07312018975068746
108.30000000000084,17.2018064611769,0.2897428202427915,-0.07179325665132064
109.40000000000084,17.30903027089851,0.28950911546205726,-0.0731190651057414
110.50000000000085,17.416950903387978,0.28840430079162294,-0.07443983018301692
111.60000000000088,17.52325209077104,0.2864567816115964,-0.07443957340783491
112.7000000000009,17.632343713444264,0.2866631095213289,-0.07445883081741966
113.8000000000009,17.740000000000094,0.2851750467269625,-0.07411001200332246
114.90000000000092,17.847305488741796,0.2857715037509291,-0.07303734865793077
116.00000000000094,17.952312987150147,0.2863478547365018,-0.07349077021904549
117.10000000000096,18.06093538438389,0.285266017907541,-0.07444066402799931
118.20000000000097,18.16905383618693,0.28816182481647046,-0.07443997449477946
119.30000000000098,18.275440896763136,0.2857206953206728,-0.07378005026753875
120.400000000001,18.38251290747805,0.2897047252578958,-0.07380021978713414
121.50000000000102,18.489409017892847,0.2887764136495713,-0.07443990886806962
122.60000000000103,18.596552018772716,0.29075234109010584,-0.07444178077331198
123.70000000000104,18.703345124074072,0.29101013280490773,-0.07476640659776557
124.80000000000106,18.810824851197506,0.29044511698875375,-0.07574860646952164
125.90000000000109,18.916357106158294,0.28928022412217325,-0.07575734243908183
127.0000000000011,19.023329831899208,0.2908072338938268,-0.07576011234343794
128.1000000000011,19.130458413519918,0.29210044459677487,-0.07707938118887814
129.20000000000113,19.23766971234854,0.29443380132253694,-0.07708007599650779
130.30000000000115,19.34183513226641,0.2945726882527293,-0.07708277752341486
131.40000000000117,19.449796907087713,0.294345905295339,-0.07708000022542638
132.50000000000117,19.555203488448704,0.29589733829240483,-0.07608869776186555
133.6000000000012,19.66258740420365,0.2973263615270856,-0.07696276680684777
134.7000000000012,19.769247616940405,0.2987598736401653,-0.07740060632624735
135.8000000000012,19.873728964070505,0.29947873176439455,-0.07828100583465147
136.90000000000123,19.9813773847597,0.2984799588568151,-0.07707001830361637
138.00000000000125,20.08611268261004,0.2989551168557447,-0.07640873951587368
139.10000000000127,20.194381968589582,0.3007685582520029,-0.07770373764991056
140.2000000000013,20.298761158571832,0.3024452252691343,-0.07904816538952675
141.3000000000013,20.404991812046205,0.3022925229477411,-0.07838141947756005
142.4000000000013,20.510274517125264,0.302940332398154,-0.07806946305459395
143.50000000000134,20.616467158565698,0.3050452438602519,-0.07674983117505008
144.60000000000133,20.724070641863015,0.3067067300242279,-0.07710672244617367
145.70000000000135,20.828969383973604,0.30998102067274,-0.07606540378715154
146.80000000000138,20.934324726285965,0.30761843807767497,-0.07537150107063573
147.9000000000014,21.040089842008094,0.3093127313424825,-0.07673936760552102
149.00000000000142,21.145895083767396,0.3104667112043721,-0.0767402082420432
150.10000000000142,21.24990279152202,0.3112917806518065,-0.0777298215789175
151.20000000000144,21.356538612082645,0.3123583669050439,-0.0777300181717071
152.30000000000146,21.460079810510067,0.3146940810338209,-0.07641810571104735
153.40000000000146,21.567692037965372,0.31502879841949094,-0.07807352954645186
154.50000000000148,21.673279229899833,0.315960580879324,-0.07662921632819364
155.6000000000015,21.778325784455713,0.31808049462927,-0.0777309664565351
156.70000000000152,21.883219541501273,0.3168347358797692,-0.07804925898906712
157.80000000000155,21.98960889124321,0.319383692954441,-0.07905060250449081
158.90000000000154,22.09382252575106,0.32150022075407936,-0.07773789474182724
160.00000000000156,22.2012228034506,0.3205760357407573,-0.07633706143812136
161.1000000000016,22.306095630528386,0.3207464331430502,-0.07806043735973445
162.20000000000158,22.410414344786723,0.3216975891072831,-0.07946695985332353
163.3000000000016,22.513974591860897,0.3237885490434077,-0.07937013901621848
164.40000000000163,22.620278728954514,0.3253350437597893,-0.07806423550770925
165.50000000000165,22.726450861735692,0.3245050484906523,-0.07918246938940232
166.60000000000167,22.82999885711722,0.32648115297303804,-0.07938017218983262
167.70000000000167,22.93717680682077,0.3275053452899107,-0.07938064988536908
168.8000000000017,23.04135327644098,0.3298381663518861,-0.0779919176145234
169.9000000000017,23.147125886675447,0.3315328350092127,-0.07938037842144219
171.0000000000017,23.25250461477609,0.33344767886002746,-0.07807288141477908
172.10000000000173,23.356734808501862,0.33286343689951514,-0.07905004240272717
173.20000000000175,23.461936451821988,0.33391305118567816,-0.07805666105446152
174.30000000000177,23.56732207280198,0.3346793924452346,-0.07950214798620925
175.4000000000018,23.672099880621143,0.3379557469509169,-0.08366438338148052
176.5000000000018,23.77758452237711,0.3396164366506026,-0.08171287214514678
177.6000000000018,23.88109946223619,0.3406321977386887,-0.08037503779899735
178.70000000000184,23.987417803467356,0.33956527000597136,-0.08037036077070026
179.80000000000183,24.091880358618592,0.3411202780161581,-0.08036377780478077
180.90000000000185,24.196696101567998,0.34115411971934917,-0.08036004000101649
182.00000000000188,24.300998215083112,0.3410816031205396,-0.08036015468534652
183.1000000000019,24.40582774905514,0.34170159132005506,-0.08004167208925272
184.20000000000192,24.510833460367273,0.3451584969860293,-0.07982952787912945
185.30000000000192,24.61601977789294,0.3434161978774154,-0.0790499979102135
186.40000000000194,24.720308106964882,0.3455953330362378,-0.0797079190771468
187.50000000000196,24.825878949788443,0.34685067797255853,-0.08025445102402973
188.60000000000196,24.931412602021993,0.3496247631819138,-0.08240869480106605
189.70000000000198,25.036300205571226,0.34942310869332305,-0.08497928116298414
190.800000000002,25.141230287010348,0.35080959880516516,-0.0836064286885474
191.90000000000202,25.2451068026321,0.3517713377138103,-0.08231897037954639
193.00000000000205,25.347960271342636,0.34997468366307705,-0.08084755852116743
194.10000000000204,25.45292107918931,0.3503583668364755,-0.07685893458886506
195.20000000000206,25.560301941854238,0.3510489523027831,-0.07948293599550693
196.3000000000021,25.6644693915271,0.3511125660172385,-0.07364054293245115
197.40000000000208,25.7694525772114,0.35439569990454645,-0.073452332830656
198.5000000000021,25.87372214333344,0.3543782322686836,-0.07487320206393777
199.60000000000213,25.978927617679837,0.35508610180266686,-0.07906002910227716
200.70000000000215,26.083449080548817,0.35748318071753893,-0.08025718775729329
201.80000000000217,26.188381697593652,0.3576598123689939,-0.08157013961732318
202.90000000000217,26.292731119047424,0.3578692915065588,-0.08293792695106106
204.0000000000022,26.397261736543797,0.35896736422694797,-0.08361171808294499
205.1000000000022,26.501690861730783,0.36148980018384114,-0.0842102765490651
206.2000000000022,26.606932492917828,0.3631381946534019,-0.08421005269939164
207.30000000000223,26.712690820164802,0.3636041632302427,-0.08288706058360873
208.40000000000225,26.815551795942774,0.3628964023674021,-0.08392415584790802
209.50000000000227,26.92119242002431,0.36570565968501817,-0.08521467416904116
210.6000000000023,27.026679681936294,0.3656537838156709,-0.08388016145532795
211.7000000000023,27.129795154645155,0.3676466993360885,-0.08388015922454306
212.8000000000023,27.23554515706057,0.36854992206307996,-0.0842166995759186
213.90000000000234,27.33622345215565,0.3681128698719227,-0.08553084628712604
215.00000000000233,27.443558105392274,0.36830381231743475,-0.08585176425542462
216.10000000000235,27.549456832594256,0.36991120176512854,-0.08672844489954468
217.20000000000238,27.655121380496663,0.37086365313036873,-0.08848807648494272
218.3000000000024,27.758690731072626,0.3732872661230841,-0.08816035157870283
219.40000000000242,27.864171083552243,0.37456387977107036,-0.08815989600080254
220.50000000000242,27.968690995578985,0.3749593385442147,-0.0881598960000014
221.60000000000244,28.073257316887705,0.37618020925735884,-0.08815989599999874
222.70000000000246,28.178026973866938,0.377743146143746,-0.08815989641591493
223.80000000000246,28.282687691477964,0.3772880207278629,-0.08953843788140059
224.90000000000248,28.387616845986788,0.3782831441235112,-0.08949199044284173
226.0000000000025,28.491862626723105,0.37945535424472304,-0.09038560356460712
227.10000000000252,28.5971712363094,0.3784307385552771,-0.09178989579606878
228.20000000000255,28.700873894211654,0.37918496928072754,-0.0917899914572553
229.30000000000254,28.805495146444674,0.3807478798757526,-0.09211845425107779
230.40000000000256,28.910302574163087,0.3820398004069038,-0.09343028898488726
231.5000000000026,29.015268728651098,0.38187764888430104,-0.09342179592166389
232.60000000000258,29.11999903832516,0.3822462952164536,-0.09475002799854293
233.7000000000026,29.224374282783234,0.38268995048764315,-0.09475002800360555
234.80000000000263,29.329714065908355,0.38347094749749355,-0.0947487135702656
235.90000000000265,29.43456565701556,0.3851390773526281,-0.0960700259274696
237.00000000000267,29.539228529673796,0.3831187015313187,-0.09738185708548253
238.10000000000267,29.644415982217954,0.3839203517976977,-0.09737999599334524
239.2000000000027,29.74879295375053,0.38465062528100197,-0.09737999599999947
240.3000000000027,29.85310246575087,0.3853788984284016,-0.09737999670308506
241.4000000000027,29.958393465654595,0.38587726863507177,-0.09899583118029076
242.50000000000273,30.062330214719317,0.3861530284684641,-0.09935986507806627
243.60000000000275,30.16770507198485,0.38544706670876,-0.0993598621092362
244.70000000000277,30.273367261744717,0.3851403761561301,-0.10068932183541479
245.8000000000028,30.37644318010962,0.3863106792288054,-0.10067967624522112
246.9000000000028,30.481711094030967,0.3875945666492725,-0.10134004640344285
248.0000000000028,30.586555361566827,0.38712173000919864,-0.10196881297031579
249.10000000000284,30.690521822920296,0.3896198608104019,-0.10265839170929336
250.20000000000283,30.795128241094023,0.3878426328331705,-0.10365002365051446
251.30000000000285,30.900475305138276,0.3881535127255949,-0.10368151783025681
252.40000000000288,31.0053552509054,0.38914325938810307,-0.10495943510069461
253.5000000000029,31.11098828382801,0.38913367098620494,-0.10526205954297119
254.60000000000292,31.21513633468419,0.3921520708546511,-0.10792072537503916
255.70000000000292,31.3189520167055,0.3899289136715152,-0.10791983200038135
256.8000000000029,31.42479528219407,0.3905552743126511,-0.10791985668527282
257.90000000000293,31.529555765387883,0.3911267690237153,-0.10891007105147033
259.00000000000296,31.633595981957285,0.3917613212197246,-0.10924298283708023
260.100000000003,31.73821824180093,0.39233773237909547,-0.11056564675987612
261.200000000003,31.840113155589204,0.38919198663804405,-0.11055547977510027
262.300000000003,31.9477201603864,0.3927361144511544,-0.11154996440492804
263.40000000000305,32.05328696231397,0.39223752744123136,-0.11284271895910525
264.50000000000307,32.15698539641508,0.3916719339201513,-0.11418017047597084
265.6000000000031,32.259106645658115,0.38998074189393683,-0.11417996122458618
266.7000000000031,32.36697509077238,0.39199467706375896,-0.11449564071625318
267.8000000000031,32.471269483362256,0.39194108279878415,-0.11548984338561485
268.9000000000031,32.57636461884341,0.392965469878137,-0.11713968184316936
270.0000000000031,32.68040464047617,0.39449079797354963,-0.11845959126977679
271.10000000000315,32.78575812403529,0.3945107063600943,-0.12084291522059676
272.2000000000032,32.89181655019908,0.3946598432090335,-0.12120940630167354
273.30000000000314,32.995029426570404,0.3969896071784,-0.12121000999661913
274.40000000000316,33.10028711845727,0.3998280126245529,-0.12252111484167294
275.5000000000032,33.20600156917275,0.40173634022675825,-0.1251080831995357
276.6000000000032,33.311083652579356,0.39961996027981933,-0.12648045377594075
277.70000000000323,33.415782328500164,0.40310506988947986,-0.12779019282140602
278.80000000000325,33.521935966155745,0.4055274970446322,-0.13043594472662345
279.9000000000033,33.62654574634888,0.4074525390515981,-0.13175470059810923
281.0000000000033,33.73178741345494,0.4110903117060887,-0.13305477358459328
282.1000000000033,33.83699720667167,0.41205485504859335,-0.13571042441773162
283.20000000000334,33.941831595499984,0.417170199078355,-0.137016623809171
284.30000000000337,34.04681676471812,0.4220893689349901,-0.14075099548818493
285.40000000000333,34.151724962984915,0.4239885060188353,-0.14339522891485235
286.50000000000335,34.25807265003944,0.427406870503993,-0.1459989412428757
287.6000000000034,34.36259363689991,0.4312060074499751,-0.14877192057309596
288.7000000000034,34.46824888890569,0.4364609219783641,-0.15243704622205412
289.8000000000034,34.57332024554711,0.4384735815163994,-0.15598149159078067
290.9000000000034,34.67625709322205,0.44299158136733996,-0.158129275078581
292.0000000000034,34.78355617122141,0.4466788770809335,-0.1625035121425369
293.10000000000343,34.88884361752055,0.4500691094696555,-0.1666570853521243
294.20000000000346,34.9941027617863,0.4570188501139489,-0.17109473357077087
295.3000000000035,35.10009000615411,0.4595506574532313,-0.17598068797706512
296.4000000000035,35.20527507795798,0.4635326562082295,-0.1814166347674382
297.5000000000035,35.31085478406808,0.46789090632371083,-0.18804013812786335
298.60000000000355,35.41628540524673,0.473288946055747,-0.19091488135719548
299.70000000000357,35.521076027080866,0.4785994433934491,-0.19740493458621877
300.8000000000036,35.62655987165833,0.48354321434790826,-0.2055504384106399
301.9000000000036,35.73217075373291,0.49150541521236757,-0.2117483992769662
303.0000000000036,35.83773468126119,0.498149438531429,-0.21807311024401432
304.1000000000036,35.94276744183614,0.5068576592036882,-0.2258548090826591
305.2000000000036,36.04692595694186,0.5127553345166806,-0.23419873112273493
306.30000000000365,36.15318305438107,0.5191392884640395,-0.24015312068934058
307.4000000000037,36.2572761198923,0.5300458734012543,-0.2500567691908371
308.5000000000037,36.365047589895376,0.5397720356731429,-0.26056934190204295
309.60000000000366,36.47087113345566,0.547865356068829,-0.26896446761763615
310.7000000000037,36.57679750399091,0.560498943563187,-0.28053124770370985
311.8000000000037,36.68059813223423,0.570744569728802,-0.292082821130601
312.90000000000373,36.78790430407172,0.5794748688571367,-0.3041269478985562
314.00000000000375,36.893295943324446,0.5924041388378117,-0.31682506360521323
315.1000000000038,37.00010320983308,0.6052594790988225,-0.331230216690678
316.2000000000038,37.10591575167711,0.6179199409895427,-0.34503935841412137
317.3000000000038,37.210229407674944,0.629876415989409,-0.36024577380706235
318.40000000000384,37.317402463629364,0.6469640049606621,-0.37560277760007565
319.5000000000038,37.42173022986294,0.6600592260541037,-0.39177499471962607
320.60000000000383,37.52961888921336,0.6769714976841408,-0.41020130257624476
321.70000000000385,37.63452032362194,0.6937971123952741,-0.42828732007805437
322.8000000000039,37.73969256569084,0.709627382786351,-0.4484163616988788
323.9000000000039,37.84594185105386,0.7257073179824063,-0.46861053333135505
325.0000000000039,37.95218946243795,0.7441818083761337,-0.4899053688558044
326.10000000000394,38.05849301011039,0.762102677128644,-0.5127245822589903
327.2000000000039,38.16473330865778,0.7809101548445773,-0.5382679321896338
328.30000000000393,38.271385298650166,0.8010492059284022,-0.5628671201592295
329.40000000000396,38.37722079463206,0.8218533656954949,-0.5887889796404475
330.500000000004,38.48301135265448,0.8460941602611017,-0.6164294903372745
331.600000000004,38.58833298217043,0.863130898702309,-0.6453879599353343
332.700000000004,38.69594231758179,0.8894549630768039,-0.6777697036849961
333.80000000000405,38.801981008928195,0.9140954146459368,-0.7097322613183028
334.90000000000407,38.908314477189755,0.9397539867426123,-0.7411928751971413
336.0000000000041,39.01464244502679,0.964352049058051,-0.777490969987257
337.10000000000406,39.120203101015946,0.9918053117868102,-0.814135272496487
338.2000000000041,39.2274068391988,1.0197867132181169,-0.85275355160443
339.3000000000041,39.330509620115734,1.048167044001846,-0.8917447651927857
340.4000000000041,39.439663899997754,1.0769075216181283,-0.9335438686126007
341.50000000000415,39.54562734136234,1.1108741404833915,-0.9776970958091225
342.6000000000042,39.650463531443386,1.1415527659189908,-1.025699601640396
343.7000000000042,39.75790780089475,1.1756479868266254,-1.0727650476327102
344.80000000000416,39.865685694987135,1.2069510129218255,-1.123314619433084
345.9000000000042,39.97149991858963,1.243685773153008,-1.1774961966323074
347.0000000000042,40.07821742767453,1.2796206347246804,-1.2323058484717428
348.10000000000423,40.18555384959311,1.3190595385812331,-1.2910381884440003
349.20000000000425,40.2923446690542,1.3593957490201847,-1.352694495741464
350.3000000000043,40.398416008601835,1.3938953305144852,-1.4146272465305567
351.4000000000043,40.50439972760097,1.4342967846010743,-1.4786717052538485
352.5000000000043,40.61221519867612,1.4750980828085727,-1.55052091270651
353.60000000000434,40.7192328118195,1.5133467685081436,-1.6194906869642223
354.7000000000043,40.82390844126334,1.5504976138898048,-1.689510179053086
355.80000000000433,40.932510630439495,1.5853523780662102,-1.7696335893322517
356.90000000000435,41.03963086675604,1.6174383220377075,-1.846791889659357
358.0000000000044,41.14664825697686,1.6459215161311191,-1.926459160410595
359.1000000000044,41.253454635388316,1.6698395891831799,-2.0097492614826775
360.2000000000044,41.36010006241474,1.6883837970916205,-2.0906975991413317
361.30000000000445,41.4671646251056,1.6976161022672596,-2.174192172476765
362.4000000000044,41.5734309839878,1.7005403154216372,-2.2597443423262114
363.50000000000443,41.68026572185417,1.6940661828425136,-2.341389109876512
364.60000000000446,41.78644251693705,1.6761594865198344,-2.4252574483678484
365.7000000000045,41.89424669658888,1.6462992477776566,-2.5099229646689407
366.8000000000045,42.00049804909877,1.613175714505433,-2.5890315909650496
367.9000000000045,42.10665961852446,1.5671645306529642,-2.668184266867452
369.00000000000455,42.214110588016105,1.513251292334524,-2.7452229853401406
370.10000000000457,42.320402860384704,1.4501825527428998,-2.81769639655029
371.2000000000046,42.42601070109459,1.3848699380114404,-2.885621317222349
372.30000000000456,42.532672457485845,1.3073933010619885,-2.951312314626489
373.4000000000046,42.638838311515066,1.2203537424925333,-3.0123585930858225
374.5000000000046,42.74363401973121,1.131221616801198,-3.06742045545666
375.6000000000046,42.850294046365796,1.0322942686135024,-3.119419375433146
376.70000000000465,42.954935428345536,0.9273067860117079,-3.1648966450938434
377.8000000000047,43.06120436758512,0.8226655549019247,-3.2053879663715485
378.9000000000047,43.16692939901493,0.716698142719056,-3.24076484177011
380.00000000000466,43.272218256930344,0.614195852071219,-3.269384934559064
381.1000000000047,43.37827208035484,0.5179617337743229,-3.2942646242864795
382.2000000000047,43.483958613880574,0.43012967664030777,-3.3127726316301067
383.30000000000473,43.589255004981496,0.3530231471852494,-3.328299696459451
384.40000000000475,43.695421902969535,0.2877355333004334,-3.3385540809028407
385.5000000000048,43.801388355457846,0.23556437176182332,-3.3476110420626477
386.6000000000048,43.906007559604994,0.20000426480869443,-3.35278751296329
387.7000000000048,44.01217129565259,0.17451461727832357,-3.358261179805312
388.80000000000484,44.11843150213959,0.15814151026724493,-3.3608193661334873
389.9000000000048,44.22407975471119,0.1476845887744317,-3.3634419840073186
391.00000000000483,44.33144014326998,0.14214237947019365,-3.3661164637005117
392.10000000000485,44.43734655489083,0.14323000212134246,-3.3687673535822125
393.2000000000049,44.544029232467416,0.15250205134846068,-3.3700438605961636
394.3000000000049,44.6492006046127,0.15862102130809458,-3.370361174600827
395.4000000000049,44.755750220787505,0.16478172940913827,-3.3726360701070535
396.50000000000495,44.863165269055635,0.16684195454672063,-3.374893786802157
397.6000000000049,44.96905497257141,0.1669603170512336,-3.3766288523206884
398.70000000000493,45.076626896947346,0.1662515618615122,-3.377937398659128
399.80000000000496,45.18395031408213,0.16539472402828426,-3.3781587675554254
400.900000000005,45.29033826246691,0.16272795403716778,-3.3792510916096035
402.000000000005,45.39819058881517,0.16399274462855118,-3.380560927357059
403.100000000005,45.50470730463956,0.16448468279376194,-3.381884092607339
404.20000000000505,45.61214695536978,0.16136020472062568,-3.383450975264575
405.30000000000507,45.71807495423003,0.16017102640716546,-3.3851792557392786
406.4000000000051,45.826349054963245,0.15934317325004344,-3.3864739278206337
407.50000000000506,45.9333755545003,0.15918806723485834,-3.386833252326298
408.6000000000051,46.04118667302036,0.15979113248503696,-3.3875749933865995
409.7000000000051,46.14868955834311,0.1582839903548977,-3.3881395726211077
410.8000000000051,46.25572595473945,0.15795355125992977,-3.3904054119445446
411.90000000000515,46.36218511142686,0.1580621510571904,-3.3923025160310964
413.0000000000052,46.47066375662223,0.1586437408307833,-3.3930797702879945
414.1000000000052,46.577402961216464,0.1534451873614801,-3.393105852905494
415.20000000000516,46.685031988846596,0.15445163194267936,-3.394400096904614
416.3000000000052,46.7921396958525,0.15434881334948147,-3.394484455089571
417.4000000000052,46.89973630573677,0.15409714731051571,-3.3970299879301873
418.50000000000523,47.00688127884399,0.15306955831270103,-3.3969403775940687
419.60000000000525,47.11396013458828,0.15171695429104687,-3.3983626815956667
420.7000000000053,47.2211681464627,0.15348774516807057,-3.399670037683464
421.8000000000053,47.3290035612003,0.15357937104563157,-3.4009813992732534
422.9000000000053,47.43581029313832,0.15207432939140636,-3.4036154088756274
424.00000000000534,47.54402920353988,0.1546724545972638,-3.4039531411716943
425.1000000000053,47.65282125521083,0.1525250606114722,-3.40533162432232
426.20000000000533,47.7591970203942,0.15116946167892487,-3.406254612579075
427.30000000000535,47.86612180739366,0.15146013465611624,-3.405281756698199
428.4000000000054,47.974383173679044,0.15146133885725488,-3.40838476109887
429.5000000000054,48.0822970351017,0.14976243945747442,-3.4101737214137455
430.6000000000054,48.190564573430485,0.1499257325693653,-3.4100965988979506
431.70000000000545,48.296356763355206,0.14978998539036054,-3.4100904660799163
432.8000000000054,48.40540120975261,0.14899587555206262,-3.411818988754671
433.90000000000543,48.513241767181995,0.1493419980445151,-3.4137199391407758
435.00000000000546,48.620672137260634,0.149000651323757,-3.415019826771369
436.1000000000055,48.72872289866278,0.14881955019457171,-3.416342966486964
437.2000000000055,48.83688266361812,0.15064859416296178,-3.416533150552095
438.3000000000055,48.94418245432107,0.15129829915679893,-3.4163949927080854
439.40000000000555,49.05186718445971,0.14855917860231316,-3.418958117296863
440.50000000000557,49.160000000000565,0.1475023527960106,-3.420300011984793
441.6000000000056,49.268756947881585,0.1487056375150324,-3.421595755630496
442.70000000000556,49.37478307870595,0.1479548747114114,-3.4216200700613046
443.8000000000056,49.482987989102945,0.14787925697254245,-3.422940006061661
444.9000000000056,49.591885507301996,0.1472592660506703,-3.4229488041940304
446.0000000000056,49.69904508541684,0.1436918235842422,-3.4251587259220893
447.10000000000565,49.80639910818117,0.1437205699719537,-3.4245650981099978
448.2000000000057,49.915130863063226,0.1459924520014136,-3.4240988949037003
449.3000000000057,50.023816037725595,0.14525150950122684,-3.423902878963986
450.40000000000566,50.13198790393609,0.14268583603231166,-3.4264591942881126
451.5000000000057,50.239906113116156,0.1443980526741353,-3.4294583014159326
452.6000000000057,50.34901878059083,0.1433481746379171,-3.4306525925900706
453.70000000000573,50.45706065177593,0.14370144204658453,-3.43270510832193
454.80000000000575,50.56572293362031,0.14408769486566164,-3.432735180270437
455.9000000000058,50.67425667882004,0.14532774482275934,-3.434030524374334
457.0000000000058,50.7817836602552,0.14479554194767374,-3.434035019437284
458.1000000000058,50.890368501560694,0.14569518565982126,-3.436669223655321
459.20000000000584,50.99879809245663,0.14396282628944157,-3.43666986951314
460.3000000000058,51.10533870539612,0.14612076575544936,-3.437988190182156
461.40000000000583,51.21546866572786,0.14518174199131217,-3.436575659694631
462.50000000000585,51.32350313792945,0.14612315815207633,-3.436073858366364
463.6000000000059,51.431745035677324,0.14478956301429263,-3.4366663955197003
464.7000000000059,51.542019244722745,0.14562316030986538,-3.439558163105062
465.8000000000059,51.64569958402167,0.14657591379767176,-3.445004660230208
466.90000000000595,51.75723222065814,0.1482294016002345,-3.449212158957601
468.0000000000059,51.8655182317992,0.14899202525366512,-3.4568457144898943
469.10000000000593,51.97400178936149,0.14621016090618805,-3.4552608428083467
470.20000000000596,52.08268358456719,0.14558949244334057,-3.4514416899982345
471.300000000006,52.19069968245574,0.14615968589125872,-3.4508438700681903
472.400000000006,52.29990771285472,0.1442174238223417,-3.4507140376751955
473.500000000006,52.40664360586816,0.1425524705720448,-3.4507194750230115
474.60000000000605,52.5156834996105,0.14299571416403023,-3.4494012281548105
475.70000000000607,52.62410817101921,0.14175145957144208,-3.4507198818976166
476.8000000000061,52.73199629714801,0.14120963628988942,-3.4506813194278902
477.90000000000606,52.84010337575315,0.14298299926475377,-3.4520299106948236
479.0000000000061,52.949177781792876,0.1416433253877244,-3.451679237138287
480.1000000000061,53.05829806870846,0.14015578373220364,-3.452030179760571
481.2000000000061,53.16705207668355,0.1392122462254161,-3.453262150938859
482.30000000000615,53.27612988617742,0.13871720022904208,-3.4545782159669454
483.4000000000062,53.38384699669785,0.13870022938897952,-3.454999904652396
484.5000000000062,53.493102256485834,0.13764561946630421,-3.4563104821970496
485.60000000000616,53.60233172650081,0.13607754264722005,-3.456329706103327
486.7000000000062,53.71049974465729,0.13812687443661437,-3.4563170328243267
487.8000000000062,53.8190919638468,0.1357357079626055,-3.457644890957739
488.90000000000623,53.92823815031558,0.13551336906995712,-3.45890636505366
490.00000000000625,54.037228302598066,0.13459898317808502,-3.459915484660982
491.1000000000063,54.14574554885745,0.1330888175497624,-3.460128256204078
492.2000000000063,54.25506021533204,0.13172721528978149,-3.461579952067881
493.3000000000063,54.36311543727775,0.13007309948673626,-3.461580217305779
494.40000000000634,54.47179357047118,0.13143285595935375,-3.4629139160069227
495.5000000000063,54.58019806251019,0.1306701716236934,-3.462599657490935
496.60000000000633,54.68946651377997,0.13022338088555535,-3.4629098588112863
497.70000000000636,54.79672090665481,0.13226450173172585,-3.4629265387470474
498.8000000000064,54.90711903569162,0.1284524210286468,-3.4642197937245895
499.9000000000064,55.016324223466704,0.12750008972600774,-3.4655404207151177
501.0000000000064,55.124557688100865,0.12639738370006098,-3.4655400878206932
502.10000000000645,55.23089736473906,0.1269736356605273,-3.465594444508223
503.2000000000064,55.34282439018438,0.1251778403009843,-3.4655388395148625
504.30000000000643,55.45199472003527,0.1224870260629323,-3.4668747927594854
505.40000000000646,55.55892455072738,0.11826499781404248,-3.469491248875867
506.5000000000065,55.66971432582235,0.11934234097980617,-3.467840002662549
507.6000000000065,55.77817076095324,0.11603467315338606,-3.4686660729702026
508.7000000000065,55.88754752151699,0.11562230263411591,-3.4691601877605875
509.80000000000655,55.996444253280345,0.11224967997257468,-3.4705570656833995
510.90000000000657,56.10576523755311,0.10725020135148919,-3.469160033681884
512.0000000000066,56.21460268764885,0.10730447302600413,-3.4690865623384983
513.1000000000065,56.32107396117402,0.10671151973366061,-3.4704799163678164
514.2000000000066,56.43206700914708,0.1062142752281014,-3.4717884951422033
515.3000000000065,56.54193202967969,0.10495177352125545,-3.4724499077394295
516.4000000000067,56.65049782266268,0.10288482113895503,-3.47245015741658
517.5000000000066,56.75960166846889,0.09774860643312114,-3.4724501559597587
518.6000000000067,56.86866181277121,0.09920074871103912,-3.473322725619277
519.7000000000066,56.978414626300996,0.09771662759575439,-3.473770028235347
520.8000000000067,57.08725083501563,0.09424415457167909,-3.475087564994466
521.9000000000067,57.19661403906072,0.09137287443681094,-3.4737699863378206
523.0000000000067,57.305680064724875,0.09349311670622784,-3.4757576247107482
524.1000000000067,57.41564375915776,0.09118069259917391,-3.4762802253598526
525.2000000000068,57.525672730899544,0.09084780104711737,-3.476047606550129
526.3000000000068,57.63444441203809,0.08924138004786275,-3.4771863581552265
527.4000000000068,57.743374627620916,0.08922067348670942,-3.477731144969891
528.5000000000068,57.852039063177166,0.08795408024925813,-3.479039913480998
529.6000000000068,57.9618433248101,0.08668183229513793,-3.479039958877469
530.7000000000069,58.071468317658486,0.08373395139420581,-3.4799988484386852
531.8000000000068,58.180108066273085,0.08487668713116911,-3.4796999021807897
532.9000000000069,58.28918344891527,0.08395625873828791,-3.4810200904382578
534.0000000000068,58.399819811525724,0.08456811984260398,-3.481020091985452
535.100000000007,58.50757094960573,0.08518980759119471,-3.481081815831627
536.2000000000069,58.61693527215637,0.0814045816844487,-3.4816787487685863
537.300000000007,58.72751606740629,0.08356714627967737,-3.4816799602672144
538.4000000000069,58.83620315174986,0.08426474207962148,-3.48334767508859
539.5000000000069,58.94554774000961,0.08446562122152823,-3.4839799241753493
540.600000000007,59.05563658342889,0.08235069925000613,-3.482620078035499
541.700000000007,59.16476585738721,0.08569978245459589,-3.4839801931264525
542.800000000007,59.27420894776272,0.0818086697132081,-3.4841638585645036
543.900000000007,59.38350177811597,0.08022900955170731,-3.4852629569728815
545.000000000007,59.49268671105962,0.0789534841875151,-3.486619928962862
546.1000000000071,59.60227431729783,0.0802431455079271,-3.486619872103557
547.2000000000071,59.71176739581864,0.08001947152344155,-3.485970210772205
548.300000000007,59.8203963146787,0.08049650703335981,-3.4866096303833727
549.4000000000071,59.931461697371866,0.07694022310674234,-3.4872700361174247
550.500000000007,60.04076647158319,0.07720309654558638,-3.4879271623118853
551.6000000000072,60.15045277734137,0.07603766108822999,-3.487930171510423
552.7000000000071,60.259297702375804,0.07619170844999945,-3.4892502800549714
553.8000000000072,60.36773728630712,0.07417511869458307,-3.487929999749027
554.9000000000071,60.47803380501293,0.07189844436087947,-3.489244852418143
556.0000000000072,60.58915882949691,0.07279882400221901,-3.4892503906493957
557.1000000000072,60.698730678790525,0.07338673485677179,-3.4899098630367584
558.2000000000072,60.80823849830205,0.07365448417894818,-3.4912446473678767
559.3000000000072,60.917976850930025,0.07245235877916624,-3.4907679393973643
560.4000000000073,61.026866391063734,0.07184375116052229,-3.4905593546244105
561.5000000000073,61.13681511991434,0.07189466608866628,-3.49188016902311
562.6000000000073,61.246462943163095,0.07504570888766098,-3.4919046944980257
563.7000000000073,61.35613979040238,0.07339259865192911,-3.4931626464829986
564.8000000000073,61.46438677929758,0.07378758368860854,-3.492549996152376
565.9000000000074,61.57415848758858,0.07371246418292672,-3.4925498394679053
567.0000000000074,61.684090699062295,0.07426120704668729,-3.4928743429756315
568.1000000000074,61.79440525929087,0.07249283976695992,-3.492456123029405
569.2000000000073,61.904026145579294,0.07279951549513526,-3.493859833675713
570.3000000000073,62.01296177798267,0.06984353210225966,-3.4938647773106366
571.4000000000074,62.12298150774282,0.07211210668884789,-3.495840114680122
572.5000000000074,62.230586668866266,0.07269000106667828,-3.4958400956766935
573.6000000000074,62.34137565235123,0.07128884278089344,-3.495171045916901
574.7000000000074,62.452396101026466,0.07206143839960863,-3.4961615232513985
575.8000000000075,62.5616182230208,0.06987986878324191,-3.4961700656270653
576.9000000000075,62.67147672129253,0.07268254515925084,-3.497514248673423
578.0000000000075,62.78129195168078,0.07130677338686445,-3.495839956919264
579.1000000000075,62.891355958807665,0.0692668647007497,-3.4971599936720996
580.2000000000075,63.000861671132746,0.0677234868162728,-3.497171344906978
581.3000000000076,63.109393913187944,0.06887804928506017,-3.49681993586643
582.4000000000076,63.21786151156478,0.06976525647791822,-3.4982187058206633
583.5000000000076,63.330223003357474,0.06956391373831339,-3.498136885506183
584.6000000000076,63.43968404818042,0.06813717563222677,-3.4981401960002856
585.7000000000077,63.550196489764176,0.0701627181567048,-3.498140198538874
586.8000000000077,63.65905833267795,0.06941459102003494,-3.4994605680055484
587.9000000000076,63.76919123002128,0.06963062375325633,-3.4981409890657646
589.0000000000076,63.87958748520108,0.06733189386650991,-3.5007822701877362
590.1000000000076,63.990481593470136,0.06883369733470526,-3.4994600412790637
591.2000000000077,64.09868575055683,0.0693474119788954,-3.499459932002135
592.3000000000077,64.20959233841131,0.06817277835158762,-3.499458388737192
593.4000000000077,64.31867341064978,0.0680547776382538,-3.5007699006993525
594.5000000000077,64.42929596808675,0.07060966499812978,-3.502069128755183
595.6000000000078,64.53965340336632,0.07160927752006288,-3.502088690695216
596.7000000000078,64.64960623543645,0.07084586017840229,-3.5021128535369925
597.8000000000078,64.75956161164763,0.07041830763478771,-3.500787516916625
598.9000000000078,64.8706093279152,0.06958100335475674,-3.50210003312843
600.0000000000078,64.97991336954018,0.07186878488233592,-3.5034200766209675
601.1000000000079,65.09069993051837,0.07333116946039564,-3.502429947153345
602.2000000000079,65.200185773934,0.07121485195659873,-3.503744244963124
603.3000000000079,65.30964415891907,0.07328454248312363,-3.502749877582338
604.4000000000078,65.4209756109927,0.07105419124828083,-3.502748297425528
605.5000000000078,65.53146995634377,0.07381961119245878,-3.5040701212142364
606.6000000000079,65.64053471152492,0.07730878803656903,-3.504070132000249
607.7000000000079,65.75149421701872,0.07747062937233061,-3.5040685716238085
608.8000000000079,65.8621274220422,0.0780662039172706,-3.505683191032732
609.9000000000079,65.97217132751693,0.07624523261085647,-3.5053881264904403
611.000000000008,66.08267117352177,0.07628129526068927,-3.505388078261194
612.100000000008,66.19254509132456,0.07423922700066797,-3.505389868396171
613.200000000008,66.30315626496592,0.07861936252422178,-3.506579612899947
614.300000000008,66.41373713143383,0.07881130360986323,-3.5057201336289614
615.400000000008,66.52352363590848,0.07804254975126057,-3.5057091446144226
616.5000000000081,66.63303485737876,0.07690332395409391,-3.5070420868608165
617.6000000000081,66.74359848525418,0.07988673780882949,-3.5063715380673903
618.7000000000081,66.85153969398347,0.08275850014563386,-3.5077268933948162
619.8000000000081,66.9644136940985,0.08225908117945602,-3.507359835431065
620.9000000000082,67.07434454316494,0.08078442347141354,-3.5060817551931205
622.0000000000082,67.18494606910677,0.08566050333365813,-3.507360111451111
623.1000000000081,67.29320018121784,0.08530327671999482,-3.5083550770092216
624.2000000000081,67.40530272693181,0.08660159488479394,-3.5081001290929446
625.3000000000081,67.515639554383,0.0886119192871729,-3.508359913288586
626.4000000000082,67.62484376637693,0.08787425156599382,-3.5083710954400784
627.5000000000082,67.73525051023597,0.08809702165103239,-3.509339591561909
628.6000000000082,67.84492426575733,0.0876537629384042,-3.5106499432143763
629.7000000000082,67.95683205252186,0.08952208437397885,-3.509670178822903
630.8000000000083,68.06693849600872,0.08908477173495441,-3.509339937807271
631.9000000000083,68.17714885768054,0.08927693190365359,-3.508009149055248
633.0000000000083,68.28782942386457,0.09031425738409571,-3.5106604477831227
634.1000000000083,68.39615743333341,0.08990779240505226,-3.5106598041606
635.2000000000083,68.5068639311249,0.08842716503056522,-3.5092978815042293
636.3000000000084,68.61891235950223,0.0896805135589803,-3.5103297855295876
637.4000000000084,68.72854482458621,0.09273029745898757,-3.510669050237885
638.5000000000084,68.8382044839617,0.09237278620575158,-3.5114368004885246
639.6000000000083,68.9492389687069,0.09381575227335377,-3.5106599352119474
640.7000000000083,69.05978265058152,0.09292024055037931,-3.5113005478558303
641.8000000000084,69.17108678428706,0.09285580258964857,-3.5126764407881286
642.9000000000084,69.2814281890834,0.09693637035752427,-3.5116382217082367
644.0000000000084,69.39270275000943,0.09625076630598185,-3.512632328226199
645.1000000000084,69.50284996259465,0.09904743285410221,-3.5126050408413683
646.2000000000085,69.61414725802871,0.09977649461719224,-3.5139428103113297
647.3000000000085,69.72414620452788,0.10208927429759929,-3.512630214937732
648.4000000000085,69.8344874020445,0.10049605878338991,-3.5136220877078976
649.5000000000085,69.94538090235694,0.0983304534204184,-3.5126301583493875
650.6000000000085,70.05611924614429,0.09606004815377583,-3.51263017170666
651.7000000000086,70.16501657210911,0.09730767990024827,-3.5129623466730218
652.8000000000086,70.27694191722188,0.09672427074068168,-3.512960035999406
653.9000000000086,70.38783969176279,0.09837710497217403,-3.5129596437461763
655.0000000000086,70.49821053017021,0.09979212718162259,-3.5142799157753513
656.1000000000087,70.60911297399163,0.10192057601239765,-3.5142971909714893
657.2000000000087,70.71924136186674,0.10347476709803516,-3.5125612706899147
658.3000000000086,70.83048518828625,0.10158989933034515,-3.5133057555708636
659.4000000000086,70.93999786680914,0.10220524785892543,-3.5136200764786136
660.5000000000086,71.0520314710204,0.10107911911026607,-3.5136201353955046
661.6000000000087,71.16197887218075,0.09982368965223568,-3.514622132524704
662.7000000000087,71.27076387580645,0.10057464066251351,-3.514280184536191
663.8000000000087,71.38380378606925,0.105248087353037,-3.5142800963483007
664.9000000000087,71.49267596735181,0.10587695294010396,-3.515603239616177
666.0000000000088,71.60621560888647,0.10725335470411124,-3.515577872789228
667.1000000000088,71.7166860528236,0.10765683095971115,-3.5159303855057433
668.2000000000088,71.82694081237463,0.10581483841002479,-3.5139513532987205
669.3000000000088,71.9375927229324,0.10893566769598598,-3.5149354065650282
670.4000000000088,72.0488062603565,0.10916455566226282,-3.5148534283142134
671.5000000000089,72.15933527647753,0.11250749256063017,-3.515930135920389
672.6000000000089,72.27087728787353,0.1114283374601431,-3.5159263675028543
673.7000000000089,72.38168490049489,0.11321505298426968,-3.5185604836177005
674.8000000000088,72.49153109483804,0.11444482600137781,-3.517240072644716
675.9000000000088,72.6024308852344,0.11845552461334627,-3.5172401040000194
677.0000000000089,72.7129814414152,0.11779209281304504,-3.5172401040000008
678.1000000000089,72.8239227944318,0.12005772076074883,-3.5172401026067024
679.2000000000089,72.93486147739222,0.1216418570997716,-3.516268335132979
680.3000000000089,73.04590522429925,0.12345433134700357,-3.517569968540589
681.400000000009,73.15736710423585,0.12429881913729618,-3.5175701139814546
682.500000000009,73.26715454810069,0.124226684346533,-3.518540160136629
683.600000000009,73.37883150983649,0.12615639113749216,-3.5185533238100066
684.700000000009,73.48841785142172,0.1252802013059613,-3.5172509362601336
685.800000000009,73.59969640537668,0.12541695055402186,-3.5192013955171326
686.9000000000091,73.7105185444852,0.13064091154416796,-3.5198800715281835
688.0000000000091,73.8203219742227,0.12837275586613656,-3.518890737065081
689.1000000000091,73.93162180568235,0.13087093677453038,-3.518915989075985
690.2000000000091,74.04272759123931,0.1304756788255425,-3.518570210727122
691.3000000000092,74.15324692904628,0.13028712945822568,-3.519878580027567
692.4000000000092,74.26450460838012,0.13066672500078602,-3.518572898120153
693.5000000000091,74.37568272972227,0.1325748653410963,-3.5198803547583624
694.6000000000091,74.48643088312483,0.13434203684391754,-3.5198800836313366
695.7000000000091,74.59667422600678,0.13377827475441462,-3.519879940048882
696.8000000000092,74.70794664291996,0.13369927584927038,-3.519724448689571
697.9000000000092,74.8182232753588,0.1326614811188196,-3.5208722937038903
699.0000000000092,74.92938092158217,0.13415568970974429,-3.520869807999653
700.1000000000092,75.03991621772707,0.1329706629503435,-3.520869807996431
701.2000000000093,75.15157927871192,0.1319716735032606,-3.5208744426261935
702.3000000000093,75.26207400731683,0.13531608028323805,-3.521200313698744
703.4000000000093,75.3727358689174,0.13286542457281025,-3.520210154957897
704.5000000000093,75.48468305125493,0.13499322862097463,-3.521023969773134
705.6000000000093,75.59467994208505,0.13730692506949155,-3.522844022335829
706.7000000000094,75.7061528819107,0.13663749883458298,-3.521703159540551
707.8000000000094,75.81790320114737,0.13522182526598642,-3.520377193664035
708.9000000000094,75.92841976381065,0.13645540685397212,-3.521519907809698
710.0000000000093,76.03990113245109,0.13229498672150164,-3.521519908018428
711.1000000000093,76.15093528465145,0.13212040066510294,-3.5228644563763862
712.2000000000094,76.26193513286644,0.13400415852508524,-3.5228401720271245
713.3000000000094,76.37332149263688,0.13177988044602812,-3.5225439950619157
714.4000000000094,76.48420568995853,0.1329375347257301,-3.5219062197023545
715.5000000000094,76.59640993331311,0.13161389402879664,-3.5231365471084546
716.6000000000095,76.70702787515836,0.13176219544580414,-3.522190219626723
717.7000000000095,76.81779121652066,0.1312758818519572,-3.5213466487255416
718.8000000000095,76.93010098388822,0.1310442038286861,-3.52218990894796
719.9000000000095,77.040797947061,0.13200146030086168,-3.523149587774694
721.0000000000095,77.15189365351655,0.12871610549749068,-3.523169876025207
722.1000000000096,77.26340090706448,0.13111375616995735,-3.523152989312906
723.2000000000096,77.3748998171469,0.12756756198037145,-3.523165174872277
724.3000000000096,77.48611923868654,0.13118406282932937,-3.5234983455001347
725.4000000000096,77.59802696482998,0.12837249755871072,-3.522178341744504
726.5000000000097,77.70910906727623,0.12949129488734057,-3.522263793372298
727.6000000000097,77.81980202553518,0.12463371466452311,-3.523500022716666
728.7000000000096,77.93069002977133,0.12407583657201937,-3.5235000077651555
729.8000000000096,78.04081939009485,0.12412777666996166,-3.524152539300888
730.9000000000096,78.15286642364944,0.12510502438949933,-3.5241601400138665
732.0000000000097,78.26406217621079,0.12343390061644854,-3.5241568288423584
733.1000000000097,78.37582432726573,0.1266398486817525,-3.5234990142451066
734.2000000000097,78.48724843808584,0.12605893827714454,-3.5234998839005787
735.3000000000097,78.5977955594391,0.12538330263935815,-3.5248192969064527
736.4000000000098,78.70892253856282,0.12171432138483185,-3.5239252354067867
737.5000000000098,78.82049510755769,0.12244202554297778,-3.5235095213938123
738.6000000000098,78.93142612645012,0.11885459583728064,-3.5248201098240575
739.7000000000098,79.042736389158,0.11985823181260169,-3.524818884322344
740.8000000000098,79.15390735154011,0.11868095090281339,-3.5248201956457645
741.9000000000099,79.26421901171834,0.11817976631544314,-3.5261346678234675
743.0000000000099,79.37584828992657,0.12222087965811179,-3.5248002361696242
744.1000000000099,79.48720664747422,0.11659737075320409,-3.5248201080179884
745.2000000000098,79.59820465134159,0.11431167599506697,-3.524828144221501
746.3000000000098,79.70906024520897,0.11527341489403675,-3.52646911438232
747.4000000000099,79.82101862713488,0.11526300340362938,-3.5251498992028854
748.5000000000099,79.93253728571217,0.11651218683217501,-3.5261361300054768
749.0000000000099,79.98365501844694,0.1119668332912287,-3.526470968008753