File: 01_Data/Basswood_Panel/STA/N2/10K_min/Basswood_Panel_STA_N2_10KData_220314_R2.csv
##Temp./Â°C,Time/min,DSC/(mW/mg),Mass loss/mg
50.0,10.57,0.015897890478401733,-0.0665943857685285
51.100000000000016,10.95704875780445,0.07755060666879943,-0.06527369245575931
52.20000000000003,11.185496312021382,0.11583576822205666,-0.0641131144903544
53.30000000000005,11.368104119812674,0.14161749206222274,-0.06456455903687486
54.40000000000006,11.530971181614595,0.16544705296055529,-0.06587311155007303
55.50000000000008,11.681748836618217,0.18226172557225617,-0.06511668530123282
56.600000000000094,11.821208989475354,0.19647861931756083,-0.06714940897973243
57.70000000000011,11.956899912639344,0.20602217034716352,-0.06727130058972941
58.800000000000125,12.087320936717347,0.21745214771754506,-0.06844165824338644
59.90000000000014,12.214229395196515,0.2290774027870045,-0.06865359130697968
61.000000000000156,12.340373715924626,0.2353527625431926,-0.0683613059803041
62.10000000000017,12.463515928447139,0.24139955536821056,-0.06881457460228768
63.20000000000019,12.587532566926296,0.2487042981224723,-0.06866027698718558
64.30000000000021,12.709250453935839,0.2543868212805779,-0.06887631187403098
65.40000000000022,12.830352322758909,0.2576008564785165,-0.07020603694158112
66.50000000000023,12.946769957926287,0.26327317871983646,-0.06905392494021179
67.60000000000025,13.068451513675225,0.2701101502858948,-0.07019763675423585
68.70000000000027,13.187959624059994,0.272703787438045,-0.07264664907275087
69.80000000000028,13.304995437785841,0.27636670277068354,-0.07281462918431636
70.90000000000029,13.422903976531902,0.2805939547650531,-0.07421883633812776
72.00000000000031,13.540110946075837,0.28360199618427095,-0.07282976163418375
73.10000000000034,13.657140975851803,0.2872298702059818,-0.07483402868822386
74.20000000000034,13.774125257423979,0.2938402565357047,-0.07415673450236282
75.30000000000035,13.890095660433554,0.29712693869066215,-0.07518566049777187
76.40000000000038,14.003535408132388,0.29923653219583507,-0.07678879555820783
77.5000000000004,14.119391223274281,0.30192432993650004,-0.07678652970218991
78.6000000000004,14.234347032575617,0.30410250926003324,-0.07809880287064708
79.70000000000041,14.349439177586673,0.30686701123650145,-0.07809854981765607
80.80000000000044,14.462420209100289,0.3091348701282734,-0.07852046794203105
81.90000000000046,14.57437326873999,0.31350939975063674,-0.08063349154899324
83.00000000000047,14.684883204867447,0.3137043172991022,-0.08202936090607471
84.10000000000048,14.799784473736386,0.31614239149186585,-0.08302958832332896
85.2000000000005,14.91285038011059,0.31452234449703664,-0.08205137846089494
86.30000000000052,15.023101184071548,0.3160329380129161,-0.08336351814201359
87.40000000000053,15.135021101355841,0.3157015024135641,-0.0843272678279634
88.50000000000054,15.243956014511664,0.31831659372257576,-0.08610751801715688
89.60000000000056,15.355103043897424,0.31895454071248014,-0.08736040370485476
90.70000000000059,15.463418770752797,0.3187237687531588,-0.08731745092466037
91.8000000000006,15.575995611132164,0.3167999532605266,-0.0863301251206452
92.9000000000006,15.685587617756514,0.31577907332150584,-0.08764109189880731
94.00000000000063,15.794844621445254,0.31620651468264876,-0.09049601154408293
95.10000000000065,15.904295020503673,0.314385896828035,-0.088850832145277
96.20000000000066,16.01384087331242,0.3131400716546556,-0.0879808037165768
97.30000000000067,16.122394774580503,0.3121660204759277,-0.09048934684063026
98.40000000000069,16.231887804018246,0.3096070836474558,-0.09101592051317331
99.50000000000071,16.3392649041376,0.3102314742298281,-0.08928369523303514
100.60000000000072,16.44771254405137,0.3062605650109957,-0.09059995966662893
101.70000000000073,16.55540343880431,0.3079408228149948,-0.0905999599999987
102.80000000000075,16.663458235608303,0.31053609709992275,-0.09191994449464502
103.90000000000077,16.772179620090803,0.3065033590387364,-0.09318812598803206
105.00000000000078,16.881052784062042,0.30443050819176154,-0.09156099285139918
106.10000000000079,16.987842565582547,0.3071769879311479,-0.09291330332545744
107.20000000000081,17.09210053199923,0.30423717644988474,-0.09286679506242024
108.30000000000084,17.202803438650683,0.3052977358644303,-0.09506976489296015
109.40000000000084,17.311432167177117,0.3058982505312563,-0.09389837852024963
110.50000000000085,17.419599604732962,0.30261907008827094,-0.0952194118833507
111.60000000000088,17.527930634528836,0.3030425958396713,-0.09389998096668428
112.7000000000009,17.634909649106138,0.30256452834298386,-0.09390266113516077
113.8000000000009,17.742517736036934,0.30560426090501724,-0.09518615064283509
114.90000000000092,17.850211376366556,0.3052875590246773,-0.09636081189985735
116.00000000000094,17.9575174796266,0.30834030974398674,-0.0962834100340646
117.10000000000096,18.06545793238453,0.30769324565370976,-0.09752020364942293
118.20000000000097,18.173643341392154,0.30810657682646925,-0.09750931396464058
119.30000000000098,18.280614020699595,0.3091977126266894,-0.09849984052030081
120.400000000001,18.387639110065283,0.3087232246446596,-0.09883373970045373
121.50000000000102,18.496273753310746,0.31192532241709015,-0.09883200314054363
122.60000000000103,18.601240343886168,0.31276876203788084,-0.09846643622933904
123.70000000000104,18.708818521502053,0.3135269247709633,-0.09763430791443195
124.80000000000106,18.815806619912536,0.31294736802656076,-0.09919248175620421
125.90000000000109,18.92135334280706,0.3128811692954222,-0.09904963141978929
127.0000000000011,19.028885634357284,0.3176695710975383,-0.10032098199273554
128.1000000000011,19.13622701936971,0.31821677244189706,-0.10038282570902934
129.20000000000113,19.242743305231887,0.31935334302157026,-0.1013510733643761
130.30000000000115,19.348254945235052,0.32138196066651514,-0.10365927456649526
131.40000000000117,19.45542214937516,0.32249773877844873,-0.10241885231870285
132.50000000000117,19.563684107253106,0.3211433080234845,-0.1033322252531832
133.6000000000012,19.668162505029358,0.32220825789455343,-0.10299364064267857
134.7000000000012,19.776076033496103,0.323362439183027,-0.10430324984839956
135.8000000000012,19.88239570518964,0.32611026240694235,-0.10480426352366567
136.90000000000123,19.989121477909617,0.3273163038186303,-0.10497202658284
138.00000000000125,20.09500357654932,0.32573154580477104,-0.10496847068969473
139.10000000000127,20.20232937391981,0.32703307237250256,-0.1043620177276976
140.2000000000013,20.30877391455864,0.32958180084372896,-0.1052963561353053
141.3000000000013,20.41377676887512,0.3314764428673059,-0.10497027749631105
142.4000000000013,20.52062298533868,0.33325981110068176,-0.10497044406305722
143.50000000000134,20.62594277170946,0.33443541864039283,-0.1074247009450695
144.60000000000133,20.73147150920779,0.33658673441620196,-0.10662009609108347
145.70000000000135,20.840288540788524,0.33651054734991936,-0.10662048456019413
146.80000000000138,20.94435105730947,0.33977824006919943,-0.10782963702541437
147.9000000000014,21.050522543891173,0.34020915063268137,-0.10651004719267076
149.00000000000142,21.156723128840476,0.3419977467272217,-0.10914432520886042
150.10000000000142,21.2632658508871,0.34298791938850476,-0.1091407576502359
151.20000000000144,21.368717457317338,0.3436314242354562,-0.10979918931771326
152.30000000000146,21.473200359523968,0.3428291610051477,-0.10913969378883515
153.40000000000146,21.57916842131465,0.3463596546437849,-0.1098003991490546
154.50000000000148,21.684805662715554,0.34808027957796833,-0.11046010675145634
155.6000000000015,21.79117091141193,0.3491373876754019,-0.11138721993795153
156.70000000000152,21.89619712976702,0.35096050315888266,-0.11111349521976255
157.80000000000155,22.004261003032777,0.3510162157433512,-0.11045996629622046
158.90000000000154,22.1064014624186,0.35366500886847774,-0.11038865120869623
160.00000000000156,22.21411698133767,0.35272184089783626,-0.11176996884079271
161.1000000000016,22.31990843964876,0.35360753663494393,-0.11243449313700982
162.20000000000158,22.425326607338288,0.3558669135851377,-0.11242974858649113
163.3000000000016,22.53018499714299,0.3564640479134296,-0.11374026095066903
164.40000000000163,22.636401895919775,0.3565693571295097,-0.11505800994337534
165.50000000000165,22.74239455278969,0.35927466384855145,-0.11638008778864162
166.60000000000167,22.847694527908953,0.36275502181716107,-0.11638009600000698
167.70000000000167,22.95332073340193,0.36076371285159503,-0.1163800964448134
168.8000000000017,23.059191138603698,0.3630535719848902,-0.11510830015990825
169.9000000000017,23.16503596678694,0.3668874927955674,-0.11637544978647663
171.0000000000017,23.270184578837863,0.36610187033624286,-0.11893545296052865
172.10000000000173,23.37564730101294,0.3672403114112947,-0.11869525417942395
173.20000000000175,23.482013927993886,0.36994880855928247,-0.11768206109640289
174.30000000000177,23.58655775188082,0.37035255651741067,-0.11768523504483763
175.4000000000018,23.692791898446778,0.37088573390828006,-0.11900997224772158
176.5000000000018,23.79847343126319,0.3737163867206726,-0.11966518616772959
177.6000000000018,23.90367999130479,0.3724075580102315,-0.11962286240414066
178.70000000000184,24.00888307305425,0.375471807652739,-0.12098996807644236
179.80000000000183,24.11449636988158,0.3747074994122199,-0.12098987523382343
180.90000000000185,24.22028581475374,0.37806943035491225,-0.12205692458349304
182.00000000000188,24.32605298962313,0.3803755187254704,-0.12296213142989121
183.1000000000019,24.430449816550535,0.38216976232333083,-0.12552190136869212
184.20000000000192,24.535073715942715,0.3840623235989854,-0.12428015525366032
185.30000000000192,24.640959523043847,0.3821655993250882,-0.12558993850020217
186.40000000000194,24.74696686014524,0.38565799575375304,-0.12559247629287107
187.50000000000196,24.850368270673783,0.38670466340467163,-0.12560174563754467
188.60000000000196,24.956416345863556,0.3905510714510938,-0.1282206045195684
189.70000000000198,25.061118428511726,0.3908115384843426,-0.1295385183868123
190.800000000002,25.167658740113996,0.39235844257759633,-0.12856007450942997
191.90000000000202,25.272090774858544,0.39551697981177625,-0.129875689585782
193.00000000000205,25.37710954326476,0.3961058176089844,-0.1298700885659323
194.10000000000204,25.47988014661229,0.3987427991150906,-0.13119120992907662
195.20000000000206,25.586611944949645,0.40291201289299106,-0.13118978879800647
196.3000000000021,25.6919281014682,0.4059962783857779,-0.1325144150410913
197.40000000000208,25.79678231611451,0.408520542451206,-0.13236250811662753
198.5000000000021,25.901809316750366,0.4104155884080284,-0.13382002184943254
199.60000000000213,26.00691360474985,0.41080877004061966,-0.13512887973935195
200.70000000000215,26.112854116420316,0.41423285161411366,-0.13776768075225343
201.80000000000217,26.217610498719004,0.4137473950863393,-0.14062100412564815
202.90000000000217,26.322195862061644,0.41590451986304255,-0.13943156590562866
204.0000000000022,26.427519780179868,0.4193136408316097,-0.13940981657385398
205.1000000000022,26.53221749069088,0.4192640091204263,-0.14205620791835116
206.2000000000022,26.637326246384557,0.4199334731059733,-0.14195279738032696
207.30000000000223,26.743792131388837,0.42339730936075937,-0.1434150496776856
208.40000000000225,26.848258298771757,0.42359470981892117,-0.14599671183320373
209.50000000000227,26.95280103315864,0.4284116387026802,-0.14765912082472088
210.6000000000023,27.05858158750414,0.42979460353773724,-0.14994176022133754
211.7000000000023,27.164144518006715,0.4324254690280677,-0.15126090515899904
212.8000000000023,27.269375801031284,0.4323323488201435,-0.1539001492306613
213.90000000000234,27.37353782907816,0.43570034492381665,-0.15521632833873156
215.00000000000233,27.479705727407108,0.4364244659116611,-0.15584524866184157
216.10000000000235,27.584478925810277,0.43564018353601686,-0.1565755716779984
217.20000000000238,27.690812011316147,0.4341687615688482,-0.1591714396928947
218.3000000000024,27.795675711936084,0.43446917433502025,-0.16178984159511023
219.40000000000242,27.900913042037963,0.4379465392770443,-0.16442313660682562
220.50000000000242,28.00545653472404,0.4337089919323872,-0.16576753377531617
221.60000000000244,28.110810701728354,0.4356969038070403,-0.16744544655379734
222.70000000000246,28.21510374391725,0.4391696690379756,-0.1706273445607418
223.80000000000246,28.317825686614896,0.44118478362749003,-0.17264196686590338
224.90000000000248,28.42469631235932,0.4400345019153026,-0.17500215075046732
226.0000000000025,28.52949098916842,0.4402042528160066,-0.17726873258455544
227.10000000000252,28.63422023490661,0.44337351935849423,-0.18123515261515033
228.20000000000255,28.739898434407383,0.44193471881326696,-0.18252024083735474
229.30000000000254,28.842043864078274,0.4392879737436363,-0.18656161745124722
230.40000000000256,28.949378754625936,0.4401924712614745,-0.18909858659677736
231.5000000000026,29.05374807581727,0.44130544112548437,-0.19041880217080287
232.60000000000258,29.158413012581935,0.4391363015902412,-0.1917408966395251
233.7000000000026,29.263500017074893,0.44094996426480043,-0.19441938024009753
234.80000000000263,29.368015078051798,0.4418991695821126,-0.19800222258624522
235.90000000000265,29.473497754778702,0.4380482171207101,-0.20093756666246954
237.00000000000267,29.578072508443853,0.43825063339520837,-0.20360258620715754
238.10000000000267,29.683013869407823,0.4376998425742339,-0.2087024385414571
239.2000000000027,29.78784156034741,0.437404333873528,-0.21156591481123455
240.3000000000027,29.89271012110532,0.43799250511757,-0.21420330631764095
241.4000000000027,29.998193467270866,0.4380582953948642,-0.21548046229999507
242.50000000000273,30.10226783762815,0.4362962718783411,-0.21956799907981317
243.60000000000275,30.20636229700695,0.43627949509396047,-0.22212002077458148
244.70000000000277,30.311817812946423,0.43666390942986955,-0.2264964111069916
245.8000000000028,30.416548130069888,0.4382630979615778,-0.22974064058416488
246.9000000000028,30.52108098112443,0.4372589887337649,-0.23372063636600826
248.0000000000028,30.625951659753802,0.43756885516666744,-0.23874083603343266
249.10000000000284,30.731909941301932,0.4395134509251396,-0.24173135951861813
250.20000000000283,30.8356083007772,0.4401272871619253,-0.2454245547112941
251.30000000000285,30.94017080013726,0.4419510267961646,-0.2509016376524231
252.40000000000288,31.04493331426184,0.4442708802030905,-0.2547426656350442
253.5000000000029,31.149140256132434,0.44305140386205333,-0.25859154598810097
254.60000000000292,31.253971004819444,0.4425849736378641,-0.26265878850792923
255.70000000000292,31.35840083640335,0.4431594943341002,-0.26893643942458434
256.8000000000029,31.463432024862556,0.44310962761255257,-0.2734521788748214
257.90000000000293,31.568542439081817,0.4401881470930808,-0.27697526036290654
259.00000000000296,31.673857886873847,0.4372917679907231,-0.283385839773286
260.100000000003,31.777804425966988,0.4381632772959957,-0.2893225434834994
261.200000000003,31.883350976291432,0.4393797429072259,-0.2937434295234569
262.300000000003,31.987554384339674,0.4384722883626604,-0.2999768876755704
263.40000000000305,32.09299331391855,0.4383585969043549,-0.3070271201164725
264.50000000000307,32.19669285010586,0.4409467867706083,-0.3135527300732166
265.6000000000031,32.303096438561035,0.44118554306832736,-0.3198400443629055
266.7000000000031,32.40779251644255,0.4408447006598242,-0.3265711999597358
267.8000000000031,32.51250011071901,0.44069215372568604,-0.33439326640120726
268.9000000000031,32.61702543349981,0.4419947827418631,-0.3427295897900722
270.0000000000031,32.721652790860155,0.440474411177931,-0.3497079468682447
271.10000000000315,32.825886105333694,0.4437048942020932,-0.35831212299585014
272.2000000000032,32.93220126149787,0.4420396756181358,-0.3661976472312394
273.30000000000314,33.03680924177989,0.4432716082611219,-0.3767645850326997
274.40000000000316,33.141648211855674,0.44441329108138283,-0.38683018313416273
275.5000000000032,33.246069653371784,0.4440487135945559,-0.3971505129606938
276.6000000000032,33.350580908723416,0.4431100731073414,-0.4076680045173995
277.70000000000323,33.455920159043295,0.4405790163862316,-0.41835663898042164
278.80000000000325,33.56128074468175,0.440806644897285,-0.4300243091060221
279.9000000000033,33.66728557539796,0.4377893974987188,-0.44354502625182946
281.0000000000033,33.77110243697955,0.43817871631670813,-0.45488746850592365
282.1000000000033,33.87456789658653,0.4371867524295559,-0.4693934416725254
283.20000000000334,33.97976975377182,0.43411846872967663,-0.4823812015790243
284.30000000000337,34.086833623423544,0.4323767239115766,-0.498646586043483
285.40000000000333,34.19232444781662,0.4299435891427841,-0.5137644505777392
286.50000000000335,34.29707827496758,0.42784460587493656,-0.5284154224281066
287.6000000000034,34.40237454241246,0.4285963088188953,-0.5437722397725158
288.7000000000034,34.50889010863836,0.42552838359703626,-0.5616673121642664
289.8000000000034,34.61440043196283,0.4224318733043911,-0.5789167646239148
290.9000000000034,34.71928035528364,0.4206482254379261,-0.5947481827264816
292.0000000000034,34.82390793958948,0.4186970401157132,-0.6125702014656915
293.10000000000343,34.92904851352677,0.4163908112542325,-0.631166703326941
294.20000000000346,35.034696071939564,0.41602969216702984,-0.650318684226797
295.3000000000035,35.13939340764165,0.41371479331773736,-0.6681152679536906
296.4000000000035,35.24489315243386,0.4128483234815073,-0.6868686986794605
297.5000000000035,35.349904377055225,0.4098525712496121,-0.7084248999711802
298.60000000000355,35.45475713519413,0.41048573423066803,-0.7275686636883023
299.70000000000357,35.56096953264151,0.4096360906992953,-0.7473794219051211
300.8000000000036,35.66671387429525,0.40754428111189905,-0.7674354280612175
301.9000000000036,35.77220709858196,0.40659489643661617,-0.787343901948625
303.0000000000036,35.87853037705459,0.4072413288753212,-0.8074122617888544
304.1000000000036,35.98392523219091,0.4072861784215289,-0.8276145813997369
305.2000000000036,36.08897579230308,0.40821186261541254,-0.8500312767240747
306.30000000000365,36.19344169616979,0.40902191753623707,-0.8692730398972852
307.4000000000037,36.30008811548434,0.4132720845431953,-0.8908931792503405
308.5000000000037,36.4060459884225,0.41387855068397256,-0.9109304265518174
309.60000000000366,36.51247013364176,0.41470657915761333,-0.9336206951094104
310.7000000000037,36.617440837632785,0.4202716895795362,-0.9535549647328239
311.8000000000037,36.72297587706142,0.42322118873580067,-0.9734578212581568
312.90000000000373,36.82763372163535,0.4238585547851056,-0.9936048787776599
314.00000000000375,36.934709537541444,0.4262515907303292,-1.0155398718481732
315.1000000000038,37.040666416496066,0.4302177853343724,-1.0366489095769489
316.2000000000038,37.14652591395897,0.4306781635744505,-1.0562898066810842
317.3000000000038,37.25151538766722,0.4318899750835442,-1.0778078306880308
318.40000000000384,37.35857613978137,0.4379407401032795,-1.100772974467707
319.5000000000038,37.464711547582866,0.4412332368169248,-1.1209605925211084
320.60000000000383,37.570090852886686,0.4477323632611044,-1.1430162273981903
321.70000000000385,37.67624227730306,0.45608955581356103,-1.1639774651079202
322.8000000000039,37.78226722355819,0.4589046156097632,-1.1859137646985856
323.9000000000039,37.88724273064621,0.4631068224713633,-1.208364602917138
325.0000000000039,37.99376239449655,0.4689344170405724,-1.2320488495725703
326.10000000000394,38.10021575331302,0.4769297371217087,-1.2550919786433403
327.2000000000039,38.2063903767977,0.4818302996664847,-1.2791209746074403
328.30000000000393,38.31324061626781,0.4873306179141843,-1.3018238495332222
329.40000000000396,38.419477717129624,0.49831939612635523,-1.3273066145696077
330.500000000004,38.5258988393235,0.5035855771886195,-1.3521385262255468
331.600000000004,38.63290749857925,0.5074649492194824,-1.375302068661309
332.700000000004,38.73982249273229,0.5207485743066135,-1.401748225434499
333.80000000000405,38.84554490992401,0.5283662675757341,-1.4280337970317616
334.90000000000407,38.952181076323505,0.5367930685565354,-1.4540824915584163
336.0000000000041,39.058747213082405,0.5450649871518052,-1.4822239112269768
337.10000000000406,39.16584704696518,0.5538344105493644,-1.510741441196247
338.2000000000041,39.272449440283744,0.5670524309536369,-1.539287666687608
339.3000000000041,39.38009769544961,0.5752977881526279,-1.5686714603077392
340.4000000000041,39.485618355627736,0.5857226460898287,-1.600600392752261
341.50000000000415,39.5925815712353,0.5992085440825347,-1.6325883619363228
342.6000000000042,39.6987728634189,0.6090431684279278,-1.6628918402965809
343.7000000000042,39.805369738347565,0.6196056395553082,-1.6968981331371848
344.80000000000416,39.91074851915737,0.6337033258864772,-1.7326135190783116
345.9000000000042,40.01806692105183,0.6411438839129533,-1.7688097537439074
347.0000000000042,40.12505330945524,0.6524003963472749,-1.8046740888109456
348.10000000000423,40.23029273246625,0.6630272570386219,-1.8431614737846616
349.20000000000425,40.335877284064935,0.6767643019777585,-1.8803649090013232
350.3000000000043,40.44311901154018,0.6855440303940099,-1.92064960026249
351.4000000000043,40.54928928252918,0.6945326859630507,-1.961883343205037
352.5000000000043,40.65604372714291,0.7016797538756279,-2.00296963066738
353.60000000000434,40.76229578561831,0.7101209524090328,-2.0455478303753942
354.7000000000043,40.86896941966983,0.7158284335958905,-2.090630856885624
355.80000000000433,40.97552758900283,0.7202958058888139,-2.135172510740128
356.90000000000435,41.08157614913418,0.7206413126828679,-2.1800215633102393
358.0000000000044,41.18800023761978,0.7207683371172169,-2.2261355681606574
359.1000000000044,41.29433192138323,0.7201614953085864,-2.271382890594556
360.2000000000044,41.40072436366131,0.7125957475897089,-2.3177142197780647
361.30000000000445,41.507096310011015,0.7068144680398002,-2.365761877512387
362.4000000000044,41.61360880452787,0.695463315034707,-2.4101311002577237
363.50000000000443,41.72027475957396,0.6796460591264958,-2.4571808278381058
364.60000000000446,41.82709089873815,0.6598539416399998,-2.5002149355999412
365.7000000000045,41.9326997055093,0.6377099419412874,-2.546906541580318
366.8000000000045,42.039512288907574,0.6111504835675492,-2.590629299731671
367.9000000000045,42.146467690466594,0.5777248451309118,-2.631021788383797
369.00000000000455,42.252722560842905,0.5435510447140071,-2.6681642602298536
370.10000000000457,42.359238316647755,0.5053816980319226,-2.7055427699464873
371.2000000000046,42.46527116405296,0.4633373578001112,-2.739567087839809
372.30000000000456,42.57237107892426,0.42080320067300564,-2.7708440080974928
373.4000000000046,42.674653405833624,0.3762467188003802,-2.796670065057482
374.5000000000046,42.78457312944916,0.3307021562463677,-2.8226635775741133
375.6000000000046,42.89066623033139,0.29048947187433705,-2.844302289157582
376.70000000000465,42.9963276576718,0.24873397363876537,-2.8626562730927336
377.8000000000047,43.1022135629236,0.21261591466887203,-2.877931450975144
378.9000000000047,43.20824684973523,0.18392804137077567,-2.8904441752327403
380.00000000000466,43.31437281667822,0.15967541535414753,-2.900861583457689
381.1000000000047,43.42139385523151,0.1368898602728067,-2.9098809140356505
382.2000000000047,43.525912411966374,0.12086335966804679,-2.9176411853948765
383.30000000000473,43.63424198330986,0.10759016941284733,-2.9234720568935524
384.40000000000475,43.74138385925142,0.10140142494032706,-2.930560165156624
385.5000000000048,43.84736507446029,0.0909264702546635,-2.936642186405827
386.6000000000048,43.95531865691415,0.08659659708325285,-2.942298249033169
387.7000000000048,44.06181244068107,0.08045386604773214,-2.9460244259526114
388.80000000000484,44.16917452334279,0.07806273764526195,-2.9511651812323665
389.9000000000048,44.27618499541669,0.0725984044321889,-2.9541897772720067
391.00000000000483,44.38384053217199,0.06861864717167382,-2.958379643905592
392.10000000000485,44.49074468586141,0.0670018163949348,-2.9630235707599413
393.2000000000049,44.59831470938227,0.060840587239087085,-2.966380620190048
394.3000000000049,44.70543044728211,0.05903013865505158,-2.971467956041403
395.4000000000049,44.813087659976205,0.0554967147781118,-2.9782602617980465
396.50000000000495,44.92008700620567,0.054462702284554076,-2.98084141404349
397.6000000000049,45.02786738866124,0.04944578716293668,-2.983546535522877
398.70000000000493,45.135084279880246,0.047229330254133395,-2.9875114432386307
399.80000000000496,45.242640773835355,0.0438667893971626,-2.990763281609609
400.900000000005,45.350285208213634,0.04261780482826011,-2.993195961591588
402.000000000005,45.458595360716664,0.03881946901746536,-2.997508624800694
403.100000000005,45.566188715651855,0.03654788330933556,-3.002238448306948
404.20000000000505,45.673672861707054,0.031956380991342626,-3.0047788046062216
405.30000000000507,45.782007590536864,0.031625988512549275,-3.0089045932679044
406.4000000000051,45.890103592547206,0.028682584391740373,-3.011658923083318
407.50000000000506,45.99754465502393,0.02449213413233936,-3.015760693601374
408.6000000000051,46.10510754360503,0.024779173387941222,-3.018622282251364
409.7000000000051,46.21096488483004,0.025382339238528173,-3.0225296142649896
410.8000000000051,46.32072589394835,0.022594291352882268,-3.0251538585779865
411.90000000000515,46.428249322480944,0.022804404998615413,-3.0288662227965473
413.0000000000052,46.536810096211426,0.022723249829936842,-3.031488465023975
414.1000000000052,46.64499091449976,0.02053039927046829,-3.0348556916739087
415.20000000000516,46.75297799603032,0.02314764634255334,-3.0380077035312576
416.3000000000052,46.860428527785935,0.016531676306206333,-3.041776394445559
417.4000000000052,46.96944280710118,0.020287883792956374,-3.0456070992253954
418.50000000000523,47.076856702815284,0.02110952794944232,-3.0461428139046522
419.60000000000525,47.18480392785968,0.017864453577348616,-3.0500843506584996
420.7000000000053,47.29249798722875,0.019872279487115507,-3.0527874205706658
421.8000000000053,47.40038126194041,0.023026716054075247,-3.058282048018441
422.9000000000053,47.50853011106923,0.022797069895068023,-3.0600804855267594
424.00000000000534,47.61598696816909,0.02623979432004625,-3.0624411449310145
425.1000000000053,47.723623712787784,0.02544013083754776,-3.0665046689734927
426.20000000000533,47.83149368849672,0.026899872137139014,-3.0704432898135128
427.30000000000535,47.939409137820775,0.027441173455739154,-3.071863759441749
428.4000000000054,48.04728585918676,0.028889585750345004,-3.0755788817828615
429.5000000000054,48.155764764887095,0.030997853571421652,-3.0777584991401006
430.6000000000054,48.26347888370878,0.03238547543276754,-3.079393932912143
431.70000000000545,48.371276042164965,0.030501423423163976,-3.0835042795370122
432.8000000000054,48.47847500446102,0.033121326731541834,-3.0856683628756567
433.90000000000543,48.586612257116606,0.03652028586492123,-3.0882961237029547
435.00000000000546,48.693717966120694,0.030661769296452812,-3.091231971055633
436.1000000000055,48.80176909282524,0.037557705529536134,-3.093787083283069
437.2000000000055,48.908952754436356,0.03642253739946216,-3.0964438064481286
438.3000000000055,49.01766727944046,0.04075402982799753,-3.0984614588029964
439.40000000000555,49.12602059161199,0.04387702451318104,-3.101063285872753
440.50000000000557,49.234177676899364,0.041112212150643146,-3.103049145490118
441.6000000000056,49.34200614491788,0.04384333271907098,-3.1057432770320066
442.70000000000556,49.44959929538566,0.042825166275308024,-3.109597053275798
443.8000000000056,49.55806999031945,0.04567310462313423,-3.1114928577831122
444.9000000000056,49.66646998101924,0.04458366088681942,-3.1142445097927203
446.0000000000056,49.774190902984145,0.047267993300199596,-3.1155924089873137
447.10000000000565,49.88177419167459,0.05256097147253119,-3.11692592794866
448.2000000000057,49.98999898622781,0.050443175944761054,-3.119479909207668
449.3000000000057,50.098203680228075,0.04897497372463705,-3.1235585430957657
450.40000000000566,50.20696203248989,0.05091851256292751,-3.126209833933422
451.5000000000057,50.31490722850459,0.050345327336478785,-3.1261701577178305
452.6000000000057,50.4225763640181,0.05148838732754457,-3.1275038047480557
453.70000000000573,50.528802423291694,0.05748903912498382,-3.1301279880071244
454.80000000000575,50.63939288010738,0.05319319725927696,-3.132736302789864
455.9000000000058,50.748752145299676,0.05627589437285191,-3.134070612320091
457.0000000000058,50.85645442630425,0.05694624467426368,-3.1380281327483335
458.1000000000058,50.96482696155555,0.05739832307959597,-3.1393103409322127
459.20000000000584,51.07352767528553,0.06105730687933103,-3.141940013960488
460.3000000000058,51.182354176920725,0.06160971158909867,-3.1432800896247466
461.40000000000583,51.29009519998811,0.0623486743894468,-3.1445999542188527
462.50000000000585,51.398129087955816,0.061410881271889484,-3.1455127282254747
463.6000000000059,51.50680211926658,0.06279297599935058,-3.1472219174618674
464.7000000000059,51.615712975143474,0.0632328615341744,-3.149627503187798
465.8000000000059,51.724275054023394,0.06631342426499759,-3.152548316312095
466.90000000000595,51.83346671240596,0.06690853172461753,-3.15248166318616
468.0000000000059,51.94258438999578,0.06930667215687247,-3.1528834065236917
469.10000000000593,52.05009604750833,0.06579124005442849,-3.1544786655485746
470.20000000000596,52.159324254730215,0.07181945692235214,-3.1554203721068044
471.300000000006,52.266464245653,0.0717200523465148,-3.1567708969869606
472.400000000006,52.37576057082912,0.07060565922781203,-3.1580918471813146
473.500000000006,52.48434841015716,0.06962645746163543,-3.1596227758341673
474.60000000000605,52.5934197517586,0.07401401228741677,-3.1629743211492523
475.70000000000607,52.70201155399708,0.07395817184137099,-3.1646723134298234
476.8000000000061,52.81117743831806,0.0751344959713317,-3.164658587829759
477.90000000000606,52.92032023508699,0.07229555570354085,-3.164675166338336
479.0000000000061,53.02799196971219,0.0731563189653971,-3.1673006132380976
480.1000000000061,53.13643418917034,0.07382682803861706,-3.168605027848216
481.2000000000061,53.24608754777582,0.07553978000634498,-3.1712485219185234
482.30000000000615,53.35360937862811,0.0758525466769111,-3.1739396361766765
483.4000000000062,53.46351296172746,0.07412860480524908,-3.172428993988577
484.5000000000062,53.571561933284556,0.0728668798441775,-3.17578413936796
485.60000000000616,53.6806554162743,0.07572589071087443,-3.176729405248674
486.7000000000062,53.78898446723096,0.07234876856435912,-3.1780531087601775
487.8000000000062,53.89751459354263,0.07682949263924765,-3.1807393866351363
488.90000000000623,54.006663465387355,0.07372186302801409,-3.180819465832889
490.00000000000625,54.11452418621534,0.07585974392915062,-3.180680257002785
491.1000000000063,54.223240189033255,0.07959310858109714,-3.1820612489539757
492.2000000000063,54.33242520497574,0.07855457880155892,-3.183541028406487
493.3000000000063,54.440995020707135,0.07539629664105041,-3.1840798086106297
494.40000000000634,54.54925485397896,0.07783758150436926,-3.1886661028177876
495.5000000000063,54.65821091120367,0.07827600586086991,-3.1900098484034594
496.60000000000633,54.76631310803991,0.08560211536931062,-3.1894128459933038
497.70000000000636,54.87536308915475,0.09768952369337047,-3.1899991047933858
498.8000000000064,54.98335251632596,0.09773105253460679,-3.1930142622311717
499.9000000000064,55.09219910450423,0.10234159174267998,-3.1936106821612533
501.0000000000064,55.19968472860509,0.1019489742759343,-3.1936200239024037
502.10000000000645,55.309470003822184,0.10503322109919033,-3.1942837333144043
503.2000000000064,55.41947673717213,0.10489805184716783,-3.1939499179791664
504.30000000000643,55.527398738501034,0.10696488922310476,-3.1952749201217676
505.40000000000646,55.63642436318373,0.10792302891776073,-3.1959210030553593
506.5000000000065,55.74565562280893,0.1105865631144618,-3.196515178168939
507.6000000000065,55.85595448854585,0.111546892191011,-3.197828581931931
508.7000000000065,55.96433197277587,0.11372884811555006,-3.200540604996113
509.80000000000655,56.0730386503309,0.11862662014535197,-3.2019049376646915
510.90000000000657,56.181437244732265,0.11737372349326702,-3.201848422044839
512.0000000000066,56.290815787810196,0.11974555165893119,-3.2031603818162857
513.1000000000065,56.40000200032175,0.12267528016709783,-3.2031612418950193
514.2000000000066,56.508851577278904,0.12253046255976563,-3.2044847013588047
515.3000000000065,56.61722765482004,0.1206753801631214,-3.205824331220775
516.4000000000067,56.72574303298157,0.12548551561869525,-3.2084666053015076
517.5000000000066,56.83506278277087,0.12830449555882573,-3.209727866364508
518.6000000000067,56.94325735715334,0.12933725540996144,-3.2110788355344484
519.7000000000066,57.05220013316797,0.12937229289290786,-3.210076300747107
520.8000000000067,57.16000106024052,0.1291152833074264,-3.2127100879046537
521.9000000000067,57.27041058520634,0.12777278679882376,-3.2127100960016417
523.0000000000067,57.37897448255334,0.12850061799697943,-3.212710093735136
524.1000000000067,57.487385466951594,0.12721809533498418,-3.2140327249877743
525.2000000000068,57.59669273018679,0.12295199752546404,-3.2153498552366
526.3000000000068,57.70571994543324,0.11548795281718904,-3.2166585264434717
527.4000000000068,57.81544779854414,0.10227526727774428,-3.215997137163988
528.5000000000068,57.92531930738955,0.09487078891245315,-3.2160290156655806
529.6000000000068,58.03463557623812,0.0884617726661967,-3.2173622063496454
530.7000000000069,58.1438724501463,0.0845941889208307,-3.2186415512646716
531.8000000000068,58.25228507366828,0.08447001805975551,-3.2200271844142976
532.9000000000069,58.362434888248494,0.08615396142525267,-3.220610500768256
534.0000000000068,58.471547074579185,0.08086464676143634,-3.222598855813674
535.100000000007,58.581209765111126,0.07959711309116124,-3.222577489058062
536.2000000000069,58.69057226140757,0.07345066014979096,-3.222682710591604
537.300000000007,58.799591520772594,0.07410056473427296,-3.2225799793346592
538.4000000000069,58.90959677065072,0.0734769991993851,-3.2265374289345004
539.5000000000069,59.019498536407326,0.07190380522580875,-3.2266255061605973
540.600000000007,59.12910875789174,0.07139322916109403,-3.226529936201975
541.700000000007,59.23810564751074,0.06919698261456175,-3.2281809903348178
542.800000000007,59.3474197180948,0.06957418275995975,-3.2286874910894703
543.900000000007,59.45705197813551,0.06649502002819174,-3.2288303680109154
545.000000000007,59.56624462908949,0.0665162188620193,-3.22984785845136
546.1000000000071,59.67512417816797,0.06277847569848327,-3.2317992847534285
547.2000000000071,59.78510985983348,0.06245264545438034,-3.2319600523758636
548.300000000007,59.895031636384566,0.06019602481708308,-3.2324202053901847
549.4000000000071,60.00506860942624,0.05550232457599169,-3.23213050474544
550.500000000007,60.114203392902674,0.05226091697322488,-3.2334398952396195
551.6000000000072,60.22450421828414,0.05113565608954884,-3.2331086522347543
552.7000000000071,60.33328312707341,0.047455097589999995,-3.234091296280644
553.8000000000072,60.443241116764455,0.04267552098587757,-3.234100120073088
554.9000000000071,60.55272845070314,0.044534000716216604,-3.234762379393902
556.0000000000072,60.663055834366524,0.038982739534744404,-3.2354945112309905
557.1000000000072,60.77221031046548,0.03616290847490711,-3.2380481993710837
558.2000000000072,60.88259684256203,0.03368008206346851,-3.238049951161511
559.3000000000072,60.99150655684545,0.02926899144295636,-3.2374124718317603
560.4000000000073,61.10220905468249,0.029633350673603398,-3.2380482890816364
561.5000000000073,61.21238707675253,0.024512810993994605,-3.241243266347891
562.6000000000073,61.32228936085986,0.026449624068324074,-3.2405839516964887
563.7000000000073,61.43214565251874,0.024971402365569273,-3.2413493788810643
564.8000000000073,61.54216607361035,0.021268473809911703,-3.241016742125921
565.9000000000074,61.65203732901791,0.02110006580156254,-3.2433154464253247
567.0000000000074,61.76183136512007,0.01671319741752708,-3.2446302184112596
568.1000000000074,61.87221817570818,0.017959211142334786,-3.243309773682104
569.2000000000073,61.98299890349266,0.01402316771179557,-3.2446331329379667
570.3000000000073,62.09185363133676,0.0155837079805482,-3.2472718697410388
571.4000000000074,62.20268604115396,0.012777353581207018,-3.245923074736211
572.5000000000074,62.31152591984583,0.010921302357601692,-3.245949946953856
573.6000000000074,62.422935661764036,0.014018135473282789,-3.2459404026442975
574.7000000000074,62.53200249604335,0.012431894027157164,-3.2459401759995323
575.8000000000075,62.642117761682364,0.009722851134052135,-3.2459409844646454
576.9000000000075,62.7529554188506,0.009973292051492999,-3.2472293469138105
578.0000000000075,62.86190416578972,0.010021866103674837,-3.2485707418625562
579.1000000000075,62.97153310159026,0.008059979632896397,-3.249668706273754
580.2000000000075,63.08304518980327,0.00884052618394382,-3.2508794798088276
581.3000000000076,63.19317030660166,0.007264945446470161,-3.25185966886171
582.4000000000076,63.303349192093926,0.00882721411372589,-3.2521904952266754
583.5000000000076,63.415219680512344,0.0050844222587612675,-3.2535091614688425
584.6000000000076,63.5244361916573,0.003331825960416812,-3.2525292285151863
585.7000000000077,63.634512583400124,0.004496422907494524,-3.2538299651674727
586.8000000000077,63.74371881936208,0.005886971128304053,-3.2538398240403157
587.9000000000076,63.85482251364483,0.005567774569251949,-3.2537448572224856
589.0000000000076,63.96537967964438,0.0035522614163288058,-3.2564804399533527
590.1000000000076,64.0762588079058,0.0034277381160503495,-3.255149388153911
591.2000000000077,64.18470528750738,0.0034829875167790014,-3.2552240816400193
592.3000000000077,64.2956852268263,0.00475178717981195,-3.2564700073160573
593.4000000000077,64.40568681121493,0.00229784323179405,-3.2567804889784115
594.5000000000077,64.51636528647425,0.0007503229049200533,-3.2587803460081846
595.6000000000078,64.62603746074872,0.003352172183246238,-3.2587798720037195
596.7000000000078,64.73736408193322,0.0032722854739001273,-3.2587717559676457
597.8000000000078,64.84741586813689,0.0016878067077432668,-3.260036148493042
598.9000000000078,64.95836380045847,0.0021687087982232844,-3.2600901920256207
600.0000000000078,65.06885365424633,0.0030147048061863746,-3.2600884725012804
601.1000000000079,65.18020919528512,0.0029682924493605878,-3.261410054744344
602.2000000000079,65.2892609080988,0.005621254434149625,-3.262399508369592
603.3000000000079,65.40081501802655,-0.000957726634444267,-3.2623998543056603
604.4000000000078,65.51152414276311,0.00393282904807124,-3.263510297428846
605.5000000000078,65.62184727426705,0.003456106830284522,-3.2640369481844207
606.6000000000079,65.73255373754246,0.0053693599677215875,-3.2653598476058727
607.7000000000079,65.84404534107341,0.0052417917549523185,-3.2646999175850553
608.8000000000079,65.95412561345479,0.00481402017319521,-3.2643678742767452
609.9000000000079,66.06494326565986,0.0063700541900595375,-3.2656762833190847
611.000000000008,66.17411141339232,0.003960253162880845,-3.2656799120635194
612.100000000008,66.28409481166443,0.00568358929046342,-3.266442590786786
613.200000000008,66.39385758339432,0.008294104464453333,-3.2670141472704857
614.300000000008,66.50524529306324,0.007824535197717308,-3.2683558582526917
615.400000000008,66.61537776026094,0.010092101652179997,-3.2696300873615765
616.5000000000081,66.72454675523029,0.008626439647043016,-3.269046414649205
617.6000000000081,66.83550885886217,0.010231394707241215,-3.268981730567078
618.7000000000081,66.9448726433257,0.01449828935252806,-3.27030007798452
619.8000000000081,67.05536898665723,0.01286643961778422,-3.2696394481682365
620.9000000000082,67.16556596122393,0.013898186892055353,-3.270943130527957
622.0000000000082,67.27557627387479,0.015433019297190098,-3.2722703527484325
623.1000000000081,67.38550900476226,0.01760640204654851,-3.2696308418242284
624.2000000000081,67.49627439430775,0.019370775401671425,-3.2709505078673375
625.3000000000081,67.60595047962171,0.02313307424448796,-3.2712800323034372
626.4000000000082,67.7166371618732,0.024169118811089074,-3.2726047988389793
627.5000000000082,67.82526629683373,0.02377651347943699,-3.2738540785484176
628.6000000000082,67.93835540158604,0.025690486488046282,-3.274564476681776
629.7000000000082,68.04946720707059,0.027779821608283628,-3.2736629146880967
630.8000000000083,68.16048418753014,0.03149404783516396,-3.2746803822415114
631.9000000000083,68.26962460053846,0.030941823198018747,-3.276000090050493
633.0000000000083,68.3808565163814,0.03701488291326682,-3.276652019744512
634.1000000000083,68.49202687456084,0.03574373402298958,-3.2761778149221534
635.2000000000083,68.60253236024789,0.03327563971435521,-3.275674376635119
636.3000000000084,68.71411342665724,0.039741927534845845,-3.27437649245473
637.4000000000084,68.82472305588091,0.038727674427395664,-3.2756700868039674
638.5000000000084,68.93511105225159,0.03981474032565169,-3.275670086666492
639.6000000000083,69.0465579136236,0.03853896557579217,-3.2770165974261585
640.7000000000083,69.15690485915498,0.03584338306974888,-3.2768874529130034
641.8000000000084,69.26652811719454,0.03978254813613202,-3.277627861214133
642.9000000000084,69.37806140106592,0.0414628913333166,-3.2789598221026934
644.0000000000084,69.48859418837156,0.039044366029769684,-3.2803042390278283
645.1000000000084,69.60046992565972,0.03891439440165856,-3.2799079470374495
646.2000000000085,69.71104881488476,0.036107599620108566,-3.2802789314194554
647.3000000000085,69.82361659196366,0.03732812680095221,-3.280280145329772
648.4000000000085,69.93383275471103,0.03429213547220766,-3.279950126774396
649.5000000000085,70.04509611378037,0.03293680781816066,-3.281262477701787
650.6000000000085,70.15643160604343,0.03237239770639566,-3.2809451961997507
651.7000000000086,70.26890234139827,0.033978095822586596,-3.2796275804254154
652.8000000000086,70.37974408815724,0.03396406199414859,-3.279280130012636
653.9000000000086,70.49125809070885,0.03540806271648855,-3.2805996224333533
655.0000000000086,70.601770721698,0.03430238325434276,-3.281593714937702
656.1000000000087,70.7125607337878,0.03754554171762514,-3.2820251258147906
657.2000000000087,70.8222489351862,0.03969144556215354,-3.2812704009831535
658.3000000000086,70.9342388493097,0.03578376351185586,-3.282249928043635
659.4000000000086,71.04438786100049,0.03813998375962746,-3.2822098801496433
660.5000000000086,71.15497775629784,0.0363031867725252,-3.284550101329868
661.6000000000087,71.26530201740799,0.036750125025264424,-3.2832399920622635
662.7000000000087,71.37602073416645,0.039508841725450106,-3.2859720665879895
663.8000000000087,71.48650516100207,0.03787349153996722,-3.284530900441929
664.9000000000087,71.59658274183894,0.036125599585324464,-3.2844500479660157
666.0000000000088,71.70683368579878,0.03604479431574337,-3.2844500479998633
667.1000000000088,71.81768229281221,0.04017142240601368,-3.2844503737379496
668.2000000000088,71.92899735466617,0.04014924341961024,-3.2834571354571827
669.3000000000088,72.03881308167476,0.03909057152764395,-3.284770112478998
670.4000000000088,72.15113059112969,0.040376854666644535,-3.284434363088957
671.5000000000089,72.26218018471636,0.04213281740764763,-3.285758410339415
672.6000000000089,72.37344411424671,0.04094349343626025,-3.2870499018106347
673.7000000000089,72.48432512432582,0.042589812690976725,-3.2860900597079334
674.8000000000088,72.59515616604449,0.0394166170364727,-3.286332404127421
675.9000000000088,72.70620699856222,0.04123988272374768,-3.2873499204191674
677.0000000000089,72.81846288512001,0.04157942365010836,-3.287400040006431
678.1000000000089,72.92949566413807,0.043311070033814625,-3.2874032424725317
679.2000000000089,73.04010349143446,0.0422788920239372,-3.286750224350132
680.3000000000089,73.1509472912444,0.04067331664149054,-3.286089097163428
681.400000000009,73.26204280367688,0.04077864669492626,-3.2887338766094745
682.500000000009,73.37372479335467,0.04539989571084968,-3.2875081765661496
683.600000000009,73.48433255452653,0.04382294531861075,-3.289074238489029
684.700000000009,73.59567543044346,0.04352694120881817,-3.2893797958446784
685.800000000009,73.70722328545484,0.045234629348903654,-3.2880655903790714
686.9000000000091,73.81918157190303,0.04425657271871741,-3.289380086632298
688.0000000000091,73.93000000000089,0.0413543698227794,-3.2906999519999927
689.1000000000091,74.04101257115478,0.0449540511838864,-3.2906999520036817
690.2000000000091,74.15191690326833,0.04781936593370584,-3.2906999519996125
691.3000000000092,74.26343343927847,0.04758367475162717,-3.29070135639833
692.4000000000092,74.37378795524144,0.04640551561382633,-3.29035508223091
693.5000000000091,74.48473339736377,0.050352809605219706,-3.2898514649501887
694.6000000000091,74.59589565491714,0.05204443915771817,-3.289709951985564
695.7000000000091,74.70598345436466,0.056541422297606836,-3.289709952001335
696.8000000000092,74.81751322679723,0.05260379399092385,-3.2897076985727787
697.9000000000092,74.92791931983962,0.052582663168169175,-3.2908642710363667
699.0000000000092,75.03924375227865,0.05523947716616884,-3.290688883293857
700.1000000000092,75.15072871693454,0.052963612759695744,-3.2907049578861916
701.2000000000093,75.25960234822415,0.05292443783173506,-3.291389888360812
702.3000000000093,75.37084905822303,0.051918893048559234,-3.2919983970317306
703.4000000000093,75.48465941824638,0.052845778070764515,-3.292010010958582
704.5000000000093,75.59658418831145,0.05649127053809,-3.2933444313594
705.6000000000093,75.70748057210898,0.05732365211330981,-3.293330070506534
706.7000000000094,75.81897881225044,0.05529247781641988,-3.294221214617991
707.8000000000094,75.9306101601174,0.05721828706022314,-3.2933300961313052
708.9000000000094,76.04099254527016,0.05139753029458416,-3.2933300633077423
710.0000000000093,76.15234895888035,0.05520549966006705,-3.2946462644113232
711.1000000000093,76.26404499586273,0.05544190930943582,-3.293241563008555
712.2000000000094,76.3746498104653,0.05080921732986288,-3.2946399543155485
713.3000000000094,76.48641023171487,0.05347089991908249,-3.2936946580805193
714.4000000000094,76.59573760051234,0.05177799728149646,-3.294646157624397
715.5000000000094,76.7096180209974,0.04931454144146752,-3.295969857240835
716.6000000000095,76.82075875934144,0.05187892276524786,-3.295969855999984
717.7000000000095,76.93244565949577,0.048473302190710665,-3.2959699982521684
718.8000000000095,77.04392982435068,0.04470575885260275,-3.296937102443895
719.9000000000095,77.1552527427583,0.04679775925574603,-3.2942350421692588
721.0000000000095,77.26575689778143,0.04290789319279842,-3.2982670103405685
722.1000000000096,77.37854106393279,0.04442898280429031,-3.2960845638036522
723.2000000000096,77.48935883683227,0.045630564728912804,-3.2971398618026813
724.3000000000096,77.60102770946816,0.0463576652140294,-3.29848997162988
725.4000000000096,77.71312165569923,0.04771146759576883,-3.2998272597504785
726.5000000000097,77.82452868187599,0.04439289490196252,-3.2991400399135746
727.6000000000097,77.93596680828524,0.0442283619203363,-3.2991400400049615
728.7000000000096,78.04864279077556,0.04524328546989742,-3.299110794173477
729.8000000000096,78.15959195512028,0.044208455106893085,-3.299800593481467
730.9000000000096,78.27077318610174,0.04387399490001709,-3.2992208032682044
732.0000000000097,78.38211345522832,0.043951859451162756,-3.298489570583457
733.1000000000097,78.49395196279285,0.03771882736272536,-3.3011397527465833
734.2000000000097,78.60455842562499,0.04002309977088925,-3.3024060368672767
735.3000000000097,78.71669199767558,0.04221726269509052,-3.2997992019946
736.4000000000098,78.8282354738999,0.040028396818707845,-3.300449932263059
737.5000000000098,78.93906637877156,0.03938861161644214,-3.2978323769804367
738.6000000000098,79.05079772884166,0.036677169529318876,-3.3004474741436103
739.7000000000098,79.16351842341524,0.03836995157906231,-3.3010923219705703
740.8000000000098,79.27472720860874,0.03694861560823082,-3.302160544655482
741.9000000000099,79.3858603709067,0.03744395176720294,-3.302110087976457
743.0000000000099,79.49812753488644,0.032983028573891904,-3.3021142400175814
744.1000000000099,79.6100021194908,0.03757005653255674,-3.302120235130254
745.2000000000098,79.72137201450239,0.036359190564412947,-3.3017700282324225
746.3000000000098,79.83305989889475,0.03601049358970965,-3.30309006874086
747.0000000000099,79.90346603139402,0.03202377924579647,-3.3028994351794863