File: 01_Data/Basswood_Panel/STA/N2/10K_min/Basswood_Panel_STA_N2_10KData_220315_R3.csv
##Temp./Â°C,Time/min,DSC/(mW/mg),Mass loss/mg
50.0,10.640334912528497,0.035060997169201746,-0.03481968491404208
51.100000000000016,10.99145560733999,0.08609614893040907,-0.03664501665521325
52.20000000000003,11.210000000000008,0.11954417798320871,-0.03651801116776765
53.30000000000005,11.389854481537306,0.14344397859106706,-0.03717220917881914
54.40000000000006,11.550403409636322,0.16554538130570173,-0.03773113282770657
55.50000000000008,11.697452217398775,0.18240497519758525,-0.03756275163996836
56.600000000000094,11.836425385258803,0.19691196481224493,-0.03784915667651889
57.70000000000011,11.971131521771097,0.21125197272594243,-0.03867426712271893
58.800000000000125,12.099630960259042,0.2205916804807283,-0.03796670400509061
59.90000000000014,12.226803600785638,0.22936877894347385,-0.03825353817624677
61.000000000000156,12.352676787836376,0.23567618005441138,-0.04028049416683244
62.10000000000017,12.476746074707336,0.24277750463598613,-0.03905764554735702
63.20000000000019,12.598368604578248,0.24981592280637133,-0.03909951826587088
64.30000000000021,12.718957327647702,0.2562153620922315,-0.04169268901001999
65.40000000000022,12.838526812532972,0.25837915068830397,-0.04131269409825489
66.50000000000023,12.957392165541384,0.2665424434367851,-0.041663013772535784
67.60000000000025,13.07667492827158,0.2706648202341062,-0.04167014706470962
68.70000000000027,13.194486820454093,0.27497847537093845,-0.041677928922982055
69.80000000000028,13.310202777050916,0.27809803630037594,-0.04211764288772901
70.90000000000029,13.428087452129366,0.2844856395653938,-0.04298252280283332
72.00000000000031,13.544703666494476,0.2874751119695477,-0.04296509786571612
73.10000000000034,13.660332141933523,0.2908078320308471,-0.043102256754822044
74.20000000000034,13.776359651364976,0.29525803959923985,-0.04464041783253325
75.30000000000035,13.89281355966989,0.30067466801493686,-0.045034253415038084
76.40000000000038,14.006460799743367,0.30274603820718,-0.045654381462066684
77.5000000000004,14.121099919546268,0.30544787839257986,-0.04562027593166729
78.6000000000004,14.236061567208665,0.3080954229074856,-0.04694107550519444
79.70000000000041,14.349430055746058,0.30939582518685205,-0.04693947573084278
80.80000000000044,14.462562795114836,0.31233699806202536,-0.04693133325245569
81.90000000000046,14.576589218788474,0.3153187092933049,-0.04825007514615365
83.00000000000047,14.690561839096597,0.3188658165344681,-0.048268245719358394
84.10000000000048,14.801467157334944,0.3187870408009606,-0.04951639292985366
85.2000000000005,14.91438221951618,0.32297971615344956,-0.04955495778075525
86.30000000000052,15.02514899832999,0.3240244810609076,-0.0497635098081326
87.40000000000053,15.13683479870802,0.3273735080108305,-0.049794071807704565
88.50000000000054,15.247480694365269,0.32755637317536385,-0.05122109570609057
89.60000000000056,15.357166140415842,0.3270701198228212,-0.052173726172527246
90.70000000000059,15.46726049149093,0.32661260565080324,-0.05153973358601238
91.8000000000006,15.577401146153303,0.32614991777545266,-0.05222026882054953
92.9000000000006,15.68662294437818,0.32848932185947216,-0.053181201938703015
94.00000000000063,15.798096829584901,0.32619855628273314,-0.05352006597661063
95.10000000000065,15.90617632571408,0.32598930124682063,-0.053514460752872584
96.20000000000066,16.01591694726603,0.3247705452579005,-0.05477792940621207
97.30000000000067,16.12633427920683,0.321543899977656,-0.05546180842648418
98.40000000000069,16.234116377273136,0.32319420793516496,-0.055494682818146845
99.50000000000071,16.343533159123126,0.32397490459798656,-0.0561973827914346
100.60000000000072,16.451971170860567,0.3212416757335158,-0.05493526732613052
101.70000000000073,16.56040016369818,0.3208912285220067,-0.05614620900272982
102.80000000000075,16.668838425387293,0.32041305531893627,-0.05649416429247722
103.90000000000077,16.775844126229746,0.3208699294272789,-0.0573829301185631
105.00000000000078,16.885017187288994,0.32077071808531427,-0.05812766902659883
106.10000000000079,16.99182466772058,0.319838698096919,-0.05812965215925869
107.20000000000081,17.100878027041162,0.3230916183484872,-0.05814879584454724
108.30000000000084,17.20988519456604,0.32230147960968847,-0.05943997402467538
109.40000000000084,17.316889942448736,0.31966224898116047,-0.05940157438634275
110.50000000000085,17.424524529138612,0.3204626627323093,-0.05943991462991205
111.60000000000088,17.53210373064074,0.3234843208727829,-0.059839769061368564
112.7000000000009,17.639309494541756,0.32398454701735985,-0.05943994492189297
113.8000000000009,17.74778607368657,0.32402803012063663,-0.0607595481694827
114.90000000000092,17.854445002626065,0.32587241213326723,-0.06028338399666611
116.00000000000094,17.96239826972484,0.3272735465781178,-0.06206788799790308
117.10000000000096,18.069609573306998,0.3270932133652231,-0.06206982756878077
118.20000000000097,18.17710927062688,0.3276761762284217,-0.060752687640892145
119.30000000000098,18.283888741847015,0.32919605421398146,-0.062080111586214404
120.400000000001,18.39194823654839,0.3292636030362587,-0.06073482508873029
121.50000000000102,18.498385054184993,0.33083881270690374,-0.06207414444965309
122.60000000000103,18.604927003092957,0.33137989847551297,-0.06102390885361375
123.70000000000104,18.71227136721466,0.3329604774406608,-0.06121089008168301
124.80000000000106,18.818976453466277,0.3353293258042677,-0.06041607301306273
125.90000000000109,18.926365096526286,0.33477919339383067,-0.06194941316659541
127.0000000000011,19.03346760986152,0.33540232364848105,-0.06207703208573978
128.1000000000011,19.14035889289198,0.33528283311440055,-0.06338999709704574
129.20000000000113,19.246827002492278,0.33759758933735595,-0.06239881252717039
130.30000000000115,19.353954174867386,0.33741899432884703,-0.06174378442430761
131.40000000000117,19.45980738612584,0.34179187551257534,-0.06321687419063826
132.50000000000117,19.567728981747322,0.342137839418202,-0.06305991057106697
133.6000000000012,19.674016478647435,0.3429099709767912,-0.06305992152901574
134.7000000000012,19.78187239874311,0.3423679379254919,-0.06434556336004738
135.8000000000012,19.887432352574788,0.34596822956120415,-0.06418129941464867
136.90000000000123,19.994245427315096,0.3477177971347971,-0.06437976845660653
138.00000000000125,20.100302983243047,0.3468835622368613,-0.06437582903737127
139.10000000000127,20.207204097715955,0.3498159808664104,-0.0656995182131821
140.2000000000013,20.313628482211328,0.3530500122051269,-0.06705514009730695
141.3000000000013,20.421555071072365,0.35302790833839126,-0.06587486097773043
142.4000000000013,20.527068941445464,0.3545329161476744,-0.06733933961347072
143.50000000000134,20.633081216626273,0.35798368269724096,-0.06697717285458227
144.60000000000133,20.73931902246487,0.3584719631778873,-0.06833019587084221
145.70000000000135,20.845047798843055,0.36057436926499387,-0.06707541107689785
146.80000000000138,20.950742960168537,0.3613442459877364,-0.06702127091150212
147.9000000000014,21.056508230226438,0.35949862747467237,-0.06833009157694381
149.00000000000142,21.163170270269614,0.3632485442186162,-0.06833009332372741
150.10000000000142,21.268241048063985,0.3619932190598569,-0.06900609186385731
151.20000000000144,21.373600731396113,0.36589776031117544,-0.06921002205214455
152.30000000000146,21.48000000000015,0.36983068721421,-0.06964006815138113
153.40000000000146,21.585560443233533,0.3708508623118154,-0.06964006800001155
154.50000000000148,21.692196726264847,0.3717954807450766,-0.06964004890325359
155.6000000000015,21.79694112567028,0.37340725737655367,-0.07095964725364245
156.70000000000152,21.902291489085165,0.3750589557455929,-0.06964200575813173
157.80000000000155,22.008597846518636,0.37609549682687216,-0.07161989425424942
158.90000000000154,22.11325630472329,0.377013612604464,-0.07164267896988141
160.00000000000156,22.21924309875311,0.37597969407866805,-0.07292985581671196
161.1000000000016,22.325296631918178,0.3772528827238608,-0.07289779036198363
162.20000000000158,22.43009195577551,0.3785759017259801,-0.07289868246301312
163.3000000000016,22.536654265900065,0.37848792766251815,-0.07326013591559555
164.40000000000163,22.643055628726508,0.3787260779715694,-0.0732649913418304
165.50000000000165,22.748024938153712,0.3827679314547979,-0.07458013502032212
166.60000000000167,22.854536781071527,0.3833016911380154,-0.07458013599389135
167.70000000000167,22.96036813779972,0.3814315455822116,-0.0745852804273599
168.8000000000017,23.06624190361093,0.3846235899889239,-0.07585030632950485
169.9000000000017,23.171904525255535,0.38761857116182585,-0.07688013664521343
171.0000000000017,23.277716876507395,0.3879542426921686,-0.07714447873332819
172.10000000000173,23.382810088357,0.387624484566199,-0.07721013605946414
173.20000000000175,23.488383516568586,0.3873579943707572,-0.07721013969973312
174.30000000000177,23.593042800998017,0.3903895125850312,-0.07851842222826733
175.4000000000018,23.70000093200921,0.3924115397367693,-0.07885013627934212
176.5000000000018,23.80488301017272,0.3959376247163704,-0.07984019013167121
177.6000000000018,23.909808016009613,0.3943310686731659,-0.07984013600006623
178.70000000000184,24.01483945260685,0.3975280135274679,-0.07984010815169418
179.80000000000183,24.120270822770387,0.3988127991124232,-0.08116034030551411
180.90000000000185,24.2224220664553,0.3984754669548475,-0.08248022044982273
182.00000000000188,24.330489122160877,0.3988977851027059,-0.08308985069089303
183.1000000000019,24.436308864132346,0.4010677130165221,-0.08379052105738571
184.20000000000192,24.541591213578556,0.4030470013024944,-0.08379016100048897
185.30000000000192,24.646931073238257,0.40376001667144457,-0.08379228997311072
186.40000000000194,24.751809299138305,0.4062293427527077,-0.0851087169253848
187.50000000000196,24.856739603949652,0.4074146824062546,-0.08643183746075733
188.60000000000196,24.962031805323758,0.41215796717177483,-0.08642822071749556
189.70000000000198,25.066885687430005,0.4111323126127377,-0.08775018415269908
190.800000000002,25.17229254053095,0.41265621854583917,-0.08775018947107904
191.90000000000202,25.27634928589045,0.4150701353299838,-0.08839662436016704
193.00000000000205,25.38235731283223,0.4171207018393399,-0.09036977106171795
194.10000000000204,25.487744562940232,0.42064958405104436,-0.09036989603633883
195.20000000000206,25.592684041450866,0.42145534914469407,-0.09136613081263834
196.3000000000021,25.69806573775033,0.4242805105359372,-0.09267741589745393
197.40000000000208,25.802653146667517,0.4273860871628821,-0.0944062471883913
198.5000000000021,25.908712500398167,0.4288378656108065,-0.09429230813080602
199.60000000000213,26.01368607887428,0.4310914933395315,-0.09666749456251189
200.70000000000215,26.11910757273297,0.4324195191234189,-0.09662003901420801
201.80000000000217,26.22344032691488,0.43279412363167813,-0.09661770030965178
202.90000000000217,26.33020620638436,0.43558362818669794,-0.09827048461211163
204.0000000000022,26.434108444272585,0.43839261795650053,-0.09955708381859196
205.1000000000022,26.540718484479463,0.4422314382198733,-0.10191941694532147
206.2000000000022,26.642652267367016,0.443251790916122,-0.10187563742910433
207.30000000000223,26.749434735597724,0.44548638573139643,-0.10250581396794667
208.40000000000225,26.85571073060871,0.44936052806636617,-0.10538391974090988
209.50000000000227,26.960913533579905,0.44969015866067685,-0.10484988814422236
210.6000000000023,27.065168183517944,0.453012994955537,-0.10758048745760806
211.7000000000023,27.169064673532365,0.45503532746201736,-0.10880971467393197
212.8000000000023,27.275150859018943,0.45970010256371424,-0.11144041642886737
213.90000000000234,27.379496111042215,0.45960150318540666,-0.11275011503654353
215.00000000000233,27.483996991039803,0.4612912885890996,-0.1153791523996639
216.10000000000235,27.58807756845061,0.464145195668404,-0.116699922064194
217.20000000000238,27.693833245837407,0.46469716783659615,-0.1192526313496276
218.3000000000024,27.798226523856453,0.4655820487103338,-0.1206502484507519
219.40000000000242,27.90314810106541,0.4682021227093652,-0.12328662649562183
220.50000000000242,28.008138562309274,0.46783908849938294,-0.12512865518773664
221.60000000000244,28.11315135955785,0.46819482369885995,-0.12618106668999607
222.70000000000246,28.217685727349284,0.4662175018754886,-0.1279136436832795
223.80000000000246,28.322017597402386,0.4681245708701398,-0.1310770746799852
224.90000000000248,28.428699037313574,0.46484609352603,-0.1338124971400001
226.0000000000025,28.533048016790723,0.4639068727124724,-0.13512846609062779
227.10000000000252,28.638261912336404,0.46268556992176535,-0.1372688267895641
228.20000000000255,28.743350555717374,0.46248398073399055,-0.14104481297633287
229.30000000000254,28.84922439631834,0.4625935936341297,-0.14274986340980522
230.40000000000256,28.953390140276273,0.46142607291908627,-0.14640313034513897
231.5000000000026,29.058662021350216,0.46031858271317416,-0.1487469707273137
232.60000000000258,29.163710776603228,0.45980897600124915,-0.15100042532424007
233.7000000000026,29.269176626748163,0.4626090153178661,-0.15444869715732334
234.80000000000263,29.374092148363793,0.4604337024788557,-0.15701968115491027
235.90000000000265,29.479241731249157,0.4589029722158869,-0.1607890354407724
237.00000000000267,29.585043206659115,0.459734638918715,-0.16351002192719521
238.10000000000267,29.69029890190129,0.46175712997635554,-0.16617118102961692
239.2000000000027,29.794816967968625,0.4606153104477054,-0.16973970629285118
240.3000000000027,29.900281641852587,0.46060718636798975,-0.17285773068742216
241.4000000000027,30.005144252785698,0.46055577789043434,-0.1754755902952354
242.50000000000273,30.110000000000227,0.462124187218221,-0.1784498858248944
243.60000000000275,30.212224516837946,0.4613357206352757,-0.18232918982343183
244.70000000000277,30.319302686582432,0.46384968115341435,-0.18535743784386227
245.8000000000028,30.42511350124869,0.46169525775286857,-0.18834223872232903
246.9000000000028,30.52936185039245,0.46187196999156555,-0.19336004714751187
248.0000000000028,30.63550045909205,0.46246180541844484,-0.196851641381659
249.10000000000284,30.740286134057673,0.4637807339216365,-0.20073679711064463
250.20000000000283,30.845193976315244,0.4677862122399569,-0.20562792297767585
251.30000000000285,30.947714587976886,0.4638878723261266,-0.20873914489658896
252.40000000000288,31.054292111145443,0.47009831047713285,-0.2126899936639166
253.5000000000029,31.159914799234183,0.46771376913468365,-0.2188170587979763
254.60000000000292,31.264985298280767,0.46954353255140874,-0.22210481720967712
255.70000000000292,31.369904625476888,0.4716457455834898,-0.22768667676221144
256.8000000000029,31.47426487982023,0.471875145463355,-0.23182148212354559
257.90000000000293,31.579708627094384,0.4720675367610815,-0.23634570213356376
259.00000000000296,31.6841635678398,0.47381309334416216,-0.24115253901384914
260.100000000003,31.789364597859304,0.4760285164944765,-0.24863216063282456
261.200000000003,31.894981715664503,0.4778708780907177,-0.25232430581811016
262.300000000003,31.99849439721157,0.47764200012787467,-0.25806403056741534
263.40000000000305,32.103720743681365,0.4791281493829697,-0.2659123350137311
264.50000000000307,32.20735777590451,0.4804608199356539,-0.271551299622089
265.6000000000031,32.311975638862656,0.48155941189180823,-0.27808145153230024
266.7000000000031,32.41716460466639,0.482198024610808,-0.2858584791768237
267.8000000000031,32.522036769572004,0.4825970104631507,-0.2947487020591386
268.9000000000031,32.62639112874739,0.48368047247136886,-0.30117249811616364
270.0000000000031,32.73167039586354,0.4851092415046285,-0.31031131712538906
271.10000000000315,32.83633357582591,0.48035462191089673,-0.31859100506168403
272.2000000000032,32.94071937529228,0.48349834406418823,-0.3282091742684776
273.30000000000314,33.04621096512363,0.4828403288920788,-0.3371625880299156
274.40000000000316,33.15106187226282,0.48290375304536504,-0.3480216594618488
275.5000000000032,33.25645462309279,0.4828684655486333,-0.3579588027194536
276.6000000000032,33.36199783260614,0.48210566572220603,-0.37001724612053577
277.70000000000323,33.46707547590565,0.4828844204404777,-0.3806982149929965
278.80000000000325,33.573232935942855,0.4793758761842246,-0.3927032132375379
279.9000000000033,33.67778956737801,0.47711070405622646,-0.4037853640007758
281.0000000000033,33.783090685161895,0.477729714109678,-0.4190822466938364
282.1000000000033,33.88789437382793,0.4759407795767476,-0.43261818988000567
283.20000000000334,33.99365090221749,0.47411678291064296,-0.44536571890868704
284.30000000000337,34.09846955928674,0.4702403351981835,-0.46095052699052497
285.40000000000333,34.20366143693769,0.4712153624506731,-0.47521947787740526
286.50000000000335,34.309681093751756,0.4711050699257505,-0.49058273849676715
287.6000000000034,34.414036988663156,0.46825753743651494,-0.5067092102850084
288.7000000000034,34.520184316410635,0.4674393673706644,-0.5239964647970852
289.8000000000034,34.62505372552405,0.4618478995418787,-0.5409445076439536
290.9000000000034,34.72965177602923,0.4593834014642178,-0.5582447307778784
292.0000000000034,34.8342231210868,0.4594180812970881,-0.5768361952806806
293.10000000000343,34.94112196971324,0.4533868378616099,-0.5961898217572759
294.20000000000346,35.0452815840329,0.4544420027151258,-0.6144548720316139
295.3000000000035,35.15102531895745,0.45304541271538457,-0.6343862521746413
296.4000000000035,35.25653685658763,0.45155556533588526,-0.652644597300609
297.5000000000035,35.36237268239699,0.44701880069690303,-0.6711475626222381
298.60000000000355,35.46677907510609,0.44750926904294785,-0.6921344825120661
299.70000000000357,35.57275013209527,0.44629379831466376,-0.7130194937023107
300.8000000000036,35.67890848002831,0.4449957047835818,-0.7339648371174055
301.9000000000036,35.785032022975116,0.44413324279563027,-0.7539535030637854
303.0000000000036,35.8905838373577,0.44675237335367196,-0.7739626467869094
304.1000000000036,35.99724165487786,0.44600144977681644,-0.7952144389480194
305.2000000000036,36.10217898092967,0.450264897437054,-0.8172465328151044
306.30000000000365,36.208262474752495,0.4480001857856837,-0.8370078891236363
307.4000000000037,36.31366641386221,0.4505207020001369,-0.8576471175078213
308.5000000000037,36.41938182805558,0.45377154272868864,-0.8803020966649582
309.60000000000366,36.5245571887963,0.4560338976889951,-0.9005026212283918
310.7000000000037,36.63057677873468,0.45788886565914094,-0.9208843367484416
311.8000000000037,36.736735854055084,0.4606177581143991,-0.9417876219827539
312.90000000000373,36.841972439339784,0.4646445450476755,-0.9633214501173124
314.00000000000375,36.94738203882102,0.4702521947093797,-0.9843596410388389
315.1000000000038,37.05290446155148,0.47397952090972456,-1.0047528609451457
316.2000000000038,37.158926697184846,0.47567862082393686,-1.0255772780797119
317.3000000000038,37.26434929993389,0.48091174732192143,-1.046785293884398
318.40000000000384,37.37062816357157,0.48420117631816245,-1.0685542120089178
319.5000000000038,37.47635492284029,0.48892411562980753,-1.0904476278109647
320.60000000000383,37.58315617094093,0.4957878899839589,-1.112654431795502
321.70000000000385,37.688061479161604,0.5006402819267864,-1.1363301153701197
322.8000000000039,37.79401379563384,0.5071013702441247,-1.1576951067625467
323.9000000000039,37.90103327787585,0.5118618658391763,-1.1794645370591175
325.0000000000039,38.00642326671649,0.5199798669732871,-1.202859160887761
326.10000000000394,38.114147815797885,0.5298012911561965,-1.2271431415960303
327.2000000000039,38.21890407232801,0.5351723541540664,-1.250898298643302
328.30000000000393,38.3254281064386,0.5435334418143735,-1.2754279918638138
329.40000000000396,38.4316061791921,0.5499100476334924,-1.2986255537682498
330.500000000004,38.53801949656483,0.5598637217063692,-1.3240728772198005
331.600000000004,38.64329995538685,0.5689501104833087,-1.349022989387319
332.700000000004,38.75105942517733,0.5775049816639221,-1.374366793578432
333.80000000000405,38.85672014079631,0.5858156240255958,-1.4013941497036861
334.90000000000407,38.9638105474451,0.5942668866877678,-1.4286418298360952
336.0000000000041,39.070307308240196,0.6036659627058305,-1.455833438594334
337.10000000000406,39.17747685250919,0.6141210314224257,-1.4866314417863067
338.2000000000041,39.28357726001849,0.6236979151945625,-1.5161506993165204
339.3000000000041,39.38974772392088,0.6343388006110157,-1.5452919691180727
340.4000000000041,39.4963012855133,0.647222273513164,-1.5789540030374116
341.50000000000415,39.60310927172978,0.6561366999055825,-1.610464965532591
342.6000000000042,39.708600044534066,0.6673308221724845,-1.6419897626216415
343.7000000000042,39.81551919743809,0.6799920921429972,-1.6758160983875388
344.80000000000416,39.92280121499347,0.6915568006518207,-1.7124047941857885
345.9000000000042,40.02942580940775,0.7028965061869841,-1.748402496736484
347.0000000000042,40.13662803185892,0.7119849668202238,-1.7870262082426023
348.10000000000423,40.24314317752972,0.7237365820377417,-1.8234547769629725
349.20000000000425,40.348803655125145,0.7348314802865568,-1.8637742563235875
350.3000000000043,40.45607580498969,0.7441590010792998,-1.905116109850082
351.4000000000043,40.56271224734653,0.754461641583051,-1.9469602324640731
352.5000000000043,40.66990595325315,0.7626824481177223,-1.9892224145969086
353.60000000000434,40.77544749077214,0.770067633825062,-2.0330387632622555
354.7000000000043,40.88155979104247,0.7770366209771875,-2.076624701535942
355.80000000000433,40.988666819436915,0.7802376074697371,-2.1211863812459306
356.90000000000435,41.09456826973024,0.7819676372929746,-2.168560172035435
358.0000000000044,41.2012745961157,0.7835731113568998,-2.21555451987396
359.1000000000044,41.30849264353299,0.781480579893889,-2.262154949894448
360.2000000000044,41.415462654932284,0.7740072778224885,-2.3096657738968602
361.30000000000445,41.52214715782252,0.7656149749106458,-2.357059742942638
362.4000000000044,41.62826454203645,0.7541264279172992,-2.4032847129383206
363.50000000000443,41.73539574690603,0.7392561987601303,-2.4508047178272996
364.60000000000446,41.84280171783268,0.7195752747672296,-2.496146143906902
365.7000000000045,41.949612801617974,0.694121485468265,-2.5401685727988315
366.8000000000045,42.05514426405336,0.6667423415235312,-2.584628934487153
367.9000000000045,42.161548383651066,0.632650325495597,-2.6249457411500847
369.00000000000455,42.26768862203357,0.5997505115644035,-2.663897651543243
370.10000000000457,42.37489547656862,0.558446611198595,-2.7014750426365453
371.2000000000046,42.48066612947249,0.518552118662392,-2.733615430557871
372.30000000000456,42.5874524807806,0.4729367340453827,-2.7623980940402832
373.4000000000046,42.69212118914912,0.42584442660991284,-2.79131386103042
374.5000000000046,42.7982961048365,0.38110492349872777,-2.8166002594471413
375.6000000000046,42.90347626328234,0.3399359208336877,-2.8380442534502257
376.70000000000465,43.0122163667904,0.30112461294868376,-2.853912581289269
377.8000000000047,43.115789356408754,0.26345562405110684,-2.8698182572827737
378.9000000000047,43.22413928621957,0.23568523487531967,-2.8842629439318044
380.00000000000466,43.33108043123802,0.2105633663441575,-2.8930233528258142
381.1000000000047,43.43738443686527,0.18822904810729296,-2.9037312917073326
382.2000000000047,43.543945924450185,0.1741508872540632,-2.909306676000288
383.30000000000473,43.65106276324199,0.16191832495177205,-2.917044683572438
384.40000000000475,43.75703830032641,0.1528188666893956,-2.922861168030274
385.5000000000048,43.864229506662525,0.1461057980835842,-2.9283943349537624
386.6000000000048,43.970707218791766,0.13854425283893979,-2.9339797621948533
387.7000000000048,44.0786552688982,0.1350561351842507,-2.938594286333169
388.80000000000484,44.185225909674344,0.1306858232542134,-2.9434930380965296
389.9000000000048,44.29190191606375,0.12517994574053554,-2.9471725256768013
391.00000000000483,44.39731673867101,0.12264797242576486,-2.951616975692539
392.10000000000485,44.50590418940385,0.11798406834326125,-2.955854770388733
393.2000000000049,44.61076674725186,0.11612009467668111,-2.9605697448537844
394.3000000000049,44.720102342570165,0.11249806909521132,-2.962615185959138
395.4000000000049,44.827079987849686,0.10956814947035276,-2.9666566402592505
396.50000000000495,44.934146731491886,0.10751326876431022,-2.9714649962161728
397.6000000000049,45.0414628719808,0.10232952279400087,-2.975651400338081
398.70000000000493,45.14744238525586,0.10127224007205282,-2.9791543667291025
399.80000000000496,45.25225437620607,0.10182135071175841,-2.982382990834308
400.900000000005,45.36322171681681,0.09827485843751571,-2.986712232794125
402.000000000005,45.470000000000496,0.09721866966125214,-2.9908104484363673
403.100000000005,45.57720169811789,0.09124931002310349,-2.9934801370867508
404.20000000000505,45.685500634186006,0.09209014575939845,-2.9981668025293677
405.30000000000507,45.79237397627818,0.08985840211278623,-3.0009070511097367
406.4000000000051,45.89968369005843,0.08815408208346337,-3.003532670548001
407.50000000000506,46.007155330760234,0.08965290159087813,-3.0088720810370075
408.6000000000051,46.11475730804251,0.08943613587302307,-3.0117973048838445
409.7000000000051,46.22272166098025,0.08518347744265803,-3.0168019258063263
410.8000000000051,46.33035083676204,0.08647941263132214,-3.0176014324991263
411.90000000000515,46.4376372232313,0.08516532634669755,-3.0217002116221847
413.0000000000052,46.54570338828384,0.0854466070208198,-3.025793473978201
414.1000000000052,46.65209014736387,0.08574661703081543,-3.028714542496636
415.20000000000516,46.75939502755198,0.08650613523205736,-3.03287393364625
416.3000000000052,46.86740648721152,0.08555702723887199,-3.0354839576487924
417.4000000000052,46.97470667896482,0.08364553529934193,-3.0381536896676784
418.50000000000523,47.07870023310201,0.08487140110291264,-3.040027992500672
419.60000000000525,47.18891052989772,0.09016706701380439,-3.0440014625174463
420.7000000000053,47.29617342720995,0.08331484818950935,-3.0465801964073274
421.8000000000053,47.40408063501187,0.08355706087652304,-3.0518098366408113
422.9000000000053,47.51143555460237,0.08575885713033155,-3.053321920980071
424.00000000000534,47.61866516119399,0.08616579287314341,-3.055962263526022
425.1000000000053,47.72569936029734,0.08784697428611277,-3.0595679488498333
426.20000000000533,47.834030297574564,0.08655911374578523,-3.0633319253203686
427.30000000000535,47.94193793433955,0.09182095993375544,-3.0659068384822454
428.4000000000054,48.05034096223183,0.08923828861390953,-3.069370232026471
429.5000000000054,48.15886216302227,0.08984985762171571,-3.0713058271300806
430.6000000000054,48.267278213906565,0.09143971504391746,-3.0739510811768143
431.70000000000545,48.37508499165203,0.09179965012782737,-3.0762629857966624
432.8000000000054,48.482546915224255,0.09473762405446984,-3.078779829587469
433.90000000000543,48.5912270007396,0.09301445705470518,-3.082505812933758
435.00000000000546,48.70046249285993,0.0930861779434492,-3.0853902054794835
436.1000000000055,48.80802353201705,0.09398551838557401,-3.0872374618271197
437.2000000000055,48.91600635533096,0.09805059425539964,-3.089989848348595
438.3000000000055,49.025201029849256,0.09953275020395419,-3.0925052382412437
439.40000000000555,49.132891430652414,0.10370484732694374,-3.0967401774620678
440.50000000000557,49.241463534571146,0.10700090585441796,-3.0979738004402844
441.6000000000056,49.34809371523868,0.10515931517281635,-3.0993186777946744
442.70000000000556,49.45643469861322,0.11032971700935262,-3.102060006095825
443.8000000000056,49.56499851666173,0.11138664872501225,-3.105625568050179
444.9000000000056,49.67312235685771,0.1144883599308042,-3.1081268283578476
446.0000000000056,49.78140792869724,0.11644630428181174,-3.1103650243794236
447.10000000000565,49.88875711363435,0.11912314997061307,-3.1121837251651296
448.2000000000057,49.99761273022934,0.11900806914376594,-3.115195454575855
449.3000000000057,50.10312658634848,0.11977542269712727,-3.11788326314355
450.40000000000566,50.21227769997176,0.12194217650163724,-3.119139786890849
451.5000000000057,50.31990431271081,0.12392283788648373,-3.120790745542873
452.6000000000057,50.42601265783531,0.1264056722856557,-3.12231420244587
453.70000000000573,50.535676062306756,0.12539630691754217,-3.125057030248584
454.80000000000575,50.64409564714211,0.12703546061875964,-3.1267019045367066
455.9000000000058,50.752512859609205,0.12718693977123463,-3.1285500760768947
457.0000000000058,50.86108440393406,0.1289525331914808,-3.130976585210217
458.1000000000058,50.969059036875095,0.12971323377390725,-3.133591145017902
459.20000000000584,51.077339611961335,0.13094303211994512,-3.1362406226685215
460.3000000000058,51.18642561133662,0.1328907274581118,-3.1389109010136886
461.40000000000583,51.29511361236008,0.13290231191537683,-3.1388737838806535
462.50000000000585,51.40387316788916,0.132552551430688,-3.139536883880229
463.6000000000059,51.51297157352694,0.13644557731607643,-3.1422283318228756
464.7000000000059,51.621907623657,0.13835278127530726,-3.1448526673965156
465.8000000000059,51.73117608833102,0.13615712704656124,-3.1454580642685253
466.90000000000595,51.83980511383011,0.13873516149443255,-3.1468234131678927
468.0000000000059,51.94825211538826,0.14119008335584138,-3.1490890134498053
469.10000000000593,52.057245423248155,0.14003127790492087,-3.1517143473664975
470.20000000000596,52.16624570515803,0.1406373195311883,-3.1523652802500473
471.300000000006,52.275230441174855,0.1421158420815879,-3.1545531985074553
472.400000000006,52.38344629701562,0.1437401912037859,-3.156318993275473
473.500000000006,52.49267376260885,0.14446609813999167,-3.1570875947946
474.60000000000605,52.59940937759987,0.143729548489134,-3.1596099900426946
475.70000000000607,52.71009587914996,0.14810720058852755,-3.160930146808333
476.8000000000061,52.81858513929274,0.14568694109549207,-3.1622699583865503
477.90000000000606,52.92773045035911,0.14630695501496005,-3.162590800982872
479.0000000000061,53.03575473770059,0.14816020324547896,-3.1650774539973225
480.1000000000061,53.14513870007018,0.14925394227938804,-3.1665793938580613
481.2000000000061,53.2539029950195,0.14841651820530966,-3.1665336872580956
482.30000000000615,53.3629043565925,0.14910045613940004,-3.1691495933098928
483.4000000000062,53.471032935105676,0.14913049464270112,-3.1714599895551836
484.5000000000062,53.58045586620791,0.15054083246478156,-3.1717902013660613
485.60000000000616,53.68920287467193,0.1540373025367351,-3.1727662510283654
486.7000000000062,53.7974170880479,0.15508094568164055,-3.174253956289979
487.8000000000062,53.907373585136206,0.15227012042555832,-3.1766182093531476
488.90000000000623,54.01574870534258,0.15188882644389512,-3.176718511380638
490.00000000000625,54.12423680314668,0.1541396802225914,-3.1780404244876768
491.1000000000063,54.23286901867367,0.1618128257818059,-3.1789444720703313
492.2000000000063,54.340949531597914,0.1717656114398981,-3.1806702171522403
493.3000000000063,54.45031412829777,0.17715874278521693,-3.1826568642345965
494.40000000000634,54.55961089097468,0.1822028297244489,-3.1839635256153995
495.5000000000063,54.668000872584166,0.18462971565266517,-3.1828466097602455
496.60000000000633,54.775968803920684,0.18838464633088015,-3.1852805273292923
497.70000000000636,54.88433626277755,0.18890676206789703,-3.1865973756296313
498.8000000000064,54.99330774712243,0.19357516598172464,-3.1879082713976903
499.9000000000064,55.10135322645251,0.19641621014371524,-3.18922641032584
501.0000000000064,55.20971243825933,0.20026854856071719,-3.1905388771601917
502.10000000000645,55.318009258320814,0.19741913447686166,-3.190542280025514
503.2000000000064,55.428027665854714,0.19925739524228214,-3.1918687525419864
504.30000000000643,55.53679349368042,0.20066857015248363,-3.193292831068052
505.40000000000646,55.645241481149284,0.20271516903392428,-3.194489870583502
506.5000000000065,55.75465309306385,0.2033968637389837,-3.1954966450801803
507.6000000000065,55.863391204061585,0.20523102747770872,-3.1961154441934663
508.7000000000065,55.97246560728596,0.20650317365789972,-3.1971315169137204
509.80000000000655,56.08116663514954,0.2098488457572315,-3.198852230154508
510.90000000000657,56.190289478295185,0.21563345968854664,-3.199091158256709
512.0000000000066,56.29854811822503,0.21675828815151876,-3.199759669411331
513.1000000000065,56.40646445668238,0.21809657326359722,-3.201082227694063
514.2000000000066,56.51587941453359,0.21666880987931048,-3.203772027789272
515.3000000000065,56.62436053012515,0.21339656900946802,-3.203709323584533
516.4000000000067,56.733856723148776,0.21490925543813355,-3.2037182415392804
517.5000000000066,56.84261303768911,0.21462640681671874,-3.205029740184596
518.6000000000067,56.951269157793085,0.21264803984690828,-3.206339293893855
519.7000000000066,57.06076281719241,0.2117457583718394,-3.2086326134634344
520.8000000000067,57.17020600378662,0.2089671460957757,-3.2086372682094844
521.9000000000067,57.279049482137566,0.20277402876168926,-3.2095763537627304
523.0000000000067,57.38928615539813,0.18887775385218608,-3.2099598352719623
524.1000000000067,57.497936500321096,0.18390701161184098,-3.211198219109516
525.2000000000068,57.608232049985865,0.17273051971721343,-3.2125802917719866
526.3000000000068,57.7171929762138,0.167785540805649,-3.2138939658664825
527.4000000000068,57.827195656138684,0.16299993314517902,-3.213909985046073
528.5000000000068,57.93608204837195,0.16250810363181634,-3.2138061342393063
529.6000000000068,58.046675629222015,0.15877606854498494,-3.2152301522288593
530.7000000000069,58.15609263361219,0.158786972834856,-3.2158802518325387
531.8000000000068,58.26526270917947,0.15506014359682263,-3.2171966525494264
532.9000000000069,58.375927670575024,0.15216374417178735,-3.218509840076669
534.0000000000068,58.48365717527503,0.15332239595526964,-3.2191634404776597
535.100000000007,58.59523110414132,0.14991439504878623,-3.219829812963618
536.2000000000069,58.70301181078259,0.1518585101194403,-3.2211502916823855
537.300000000007,58.813600310201295,0.1487848102273599,-3.2220993457937617
538.4000000000069,58.92394861384751,0.14921370368018294,-3.2218856908893567
539.5000000000069,59.033011419768926,0.14466859153314604,-3.2231184930537635
540.600000000007,59.14280132149328,0.14459580989898024,-3.2257503523950852
541.700000000007,59.252223693012766,0.14184959629079297,-3.225749999006206
542.800000000007,59.36233185877354,0.13452679609614782,-3.225762381811516
543.900000000007,59.47134987656508,0.12912625814466938,-3.2270701649942177
545.000000000007,59.58020777385677,0.12477564062088997,-3.228420748528663
546.1000000000071,59.69067282140363,0.12246814429270769,-3.2270970783217767
547.2000000000071,59.79970117547362,0.12077668536030262,-3.2289275012268095
548.300000000007,59.90932644992967,0.11767121808205205,-3.230689917313509
549.4000000000071,60.019316353515364,0.11950644305326241,-3.230643734857214
550.500000000007,60.12833009365405,0.11401738427367891,-3.2306900159751675
551.6000000000072,60.23838591254916,0.11003553944720079,-3.2320398077658368
552.7000000000071,60.34775492808145,0.11330561806403827,-3.2320111576636315
553.8000000000072,60.45756055537457,0.1076920676151446,-3.2333201434873433
554.9000000000071,60.56777261221964,0.10678361510497336,-3.233963503512798
556.0000000000072,60.67744919232052,0.10088035993387423,-3.2346356466699424
557.1000000000072,60.78725772588451,0.10216350431761467,-3.2359601991336864
558.2000000000072,60.89770338728224,0.10127716287265409,-3.2359529954985846
559.3000000000072,61.0077589806219,0.0972148731485224,-3.2370920658291693
560.4000000000073,61.116883816857246,0.09431511485633526,-3.237270907913642
561.5000000000073,61.22732233145062,0.0921543839068849,-3.2395798839384318
562.6000000000073,61.33585665557836,0.0946107202917501,-3.2395799448407887
563.7000000000073,61.44580872813985,0.09385698691235189,-3.2408605151451892
564.8000000000073,61.55664067071342,0.09183380860834489,-3.2396966697362415
565.9000000000074,61.66667878815508,0.09368382279016829,-3.2408918945538767
567.0000000000074,61.77603421306024,0.09188320954195106,-3.242193079288157
568.1000000000074,61.886051365199904,0.0929518252724657,-3.242860160994275
569.2000000000073,61.99683664489221,0.09054492025845173,-3.2427670129025037
570.3000000000073,62.10710744562099,0.09012822636965723,-3.2442242737953864
571.4000000000074,62.21705864676434,0.0904268600582353,-3.244179821966415
572.5000000000074,62.32754677975824,0.08909791070266926,-3.244349620184671
573.6000000000074,62.437423962231584,0.09186478909215612,-3.247655107471508
574.7000000000074,62.547925891686276,0.08894906443711237,-3.2464799606347663
575.8000000000075,62.657818121100554,0.08908765571409283,-3.247137399014356
576.9000000000075,62.768133442271406,0.08757991098005125,-3.2487914471092956
578.0000000000075,62.878305532278176,0.08763510111581407,-3.2501354637110658
579.1000000000075,62.98833922182833,0.0900451615793324,-3.2487807890172467
580.2000000000075,63.09784911974292,0.08831514854606082,-3.2501005075063327
581.3000000000076,63.20848248667341,0.09257145010594237,-3.251420254183014
582.4000000000076,63.317924271984865,0.0912713245034702,-3.251418969199367
583.5000000000076,63.4296719837577,0.09015971643603382,-3.2540490941082476
584.6000000000076,63.53946150116899,0.09218819102647136,-3.2533893635714124
585.7000000000077,63.6487747848945,0.095929432249373,-3.254049848409972
586.8000000000077,63.75888348585355,0.09229092190987931,-3.2540500346053056
587.9000000000076,63.869997911769964,0.09377563773926978,-3.2566906712142782
589.0000000000076,63.98028118995329,0.09334814527299995,-3.2566799683061673
590.1000000000076,64.09042371334397,0.09362420850828079,-3.2566799750041446
591.2000000000077,64.20169830966516,0.09335799624927954,-3.2571666841919518
592.3000000000077,64.31059384956666,0.09587154448936197,-3.2580000005449192
593.4000000000077,64.42302810886538,0.09725864549870777,-3.2566971665156217
594.5000000000077,64.53197440558196,0.09682175586299135,-3.2569996907013077
595.6000000000078,64.64290506410609,0.10008572625430334,-3.2596488604653815
596.7000000000078,64.75422824122316,0.10009612699450965,-3.260960133450867
597.8000000000078,64.86389300414055,0.10182850628133444,-3.262261417893269
598.9000000000078,64.97410737592483,0.09965103156518884,-3.2596390349172104
600.0000000000078,65.08401948885614,0.10358379423038622,-3.260960184502277
601.1000000000079,65.19460207807165,0.10030159929381599,-3.2619481611988386
602.2000000000079,65.30560791641342,0.1043455766955137,-3.262279874381398
603.3000000000079,65.41524337803241,0.1049621781284229,-3.2623027288774473
604.4000000000078,65.5260521505853,0.11004763997034361,-3.2635899769797283
605.5000000000078,65.63618663687268,0.10913556520555512,-3.2634754280715823
606.6000000000079,65.74629426709848,0.11139184811084946,-3.264910003169735
607.7000000000079,65.85631876729964,0.11166588016045942,-3.264858682024207
608.8000000000079,65.96647925486891,0.11455626144844688,-3.2649100160490696
609.9000000000079,66.07701043357916,0.11458310683620343,-3.264926968168925
611.000000000008,66.18703654616365,0.1187846852292862,-3.265901044817572
612.100000000008,66.29659979709461,0.12171862550690382,-3.2662195196756194
613.200000000008,66.40722287184867,0.11963604099888203,-3.2675346849950495
614.300000000008,66.51593166792121,0.12395564050653252,-3.2682003277073943
615.400000000008,66.62847488017326,0.12305380200718463,-3.2683331658743455
616.5000000000081,66.73854951903752,0.12515788178820986,-3.2692027589444694
617.6000000000081,66.84989198159182,0.12577076386115082,-3.2695641435660523
618.7000000000081,66.96080352667859,0.12823560954896795,-3.269189972168047
619.8000000000081,67.07204210228578,0.13084836842839598,-3.2695180040276295
620.9000000000082,67.18195901250861,0.13253695750533412,-3.2708326644255328
622.0000000000082,67.29342987694304,0.13168903476223237,-3.2734727594241715
623.1000000000081,67.40446942196115,0.1313647771767703,-3.27247978840684
624.2000000000081,67.51499878434579,0.1354810346254458,-3.2719521545080705
625.3000000000081,67.62596275238509,0.13804759397288402,-3.272150032862096
626.4000000000082,67.73676634652696,0.13951597459280163,-3.274793348580368
627.5000000000082,67.84800181600309,0.13942757651137083,-3.274788512646434
628.6000000000082,67.9588794833834,0.14155943967396456,-3.273773116580758
629.7000000000082,68.0687604360531,0.1457114204131753,-3.2747801553358244
630.8000000000083,68.17968801620731,0.14493200199076295,-3.2747801205338147
631.9000000000083,68.28950252140004,0.14817247338896733,-3.2774248531190464
633.0000000000083,68.40138044227217,0.15046402392349267,-3.277420172861915
634.1000000000083,68.51149218245872,0.1534042896364971,-3.2781767989522423
635.2000000000083,68.61867241024869,0.15443882360176042,-3.277409883996783
636.3000000000084,68.73188649413903,0.1569573054987412,-3.277879368393708
637.4000000000084,68.84180522508389,0.15922726764747352,-3.2783076770387334
638.5000000000084,68.95185638336737,0.16131053001281592,-3.2800495180158054
639.6000000000083,69.06205579968731,0.16510332338729028,-3.2800480958788336
640.7000000000083,69.1726544974046,0.16844621799187376,-3.278730077448948
641.8000000000084,69.28330427466102,0.1676073894186232,-3.281360045103421
642.9000000000084,69.3935280744211,0.17364958156441657,-3.2813614921079575
644.0000000000084,69.50418648363366,0.17738538789927438,-3.282680311243268
645.1000000000084,69.61615989187204,0.17934009948807828,-3.281282668639916
646.2000000000085,69.72588054861419,0.18106877975032565,-3.28136005653984
647.3000000000085,69.83603586789198,0.18197727510269934,-3.2826846428794925
648.4000000000085,69.94702703358277,0.1851031647611363,-3.2826803246004697
649.5000000000085,70.05725394228722,0.18730654934598956,-3.2826035158732543
650.6000000000085,70.16934170236345,0.1889568589285613,-3.282681206689917
651.7000000000086,70.2788495777681,0.19421911578386752,-3.283736663966068
652.8000000000086,70.39140653996596,0.1930095881880669,-3.2849799040586563
653.9000000000086,70.5023930394567,0.19601561676734525,-3.285344259086706
655.0000000000086,70.61210902522339,0.19716743897024003,-3.283996307833104
656.1000000000087,70.72303571887117,0.19303918840263012,-3.285483182919094
657.2000000000087,70.83463762538257,0.1942846317026503,-3.2856399125530675
658.3000000000086,70.94429664152503,0.19630353771922326,-3.2868553701269008
659.4000000000086,71.05626946316045,0.19481240825476087,-3.2869599370228357
660.5000000000086,71.16651603700986,0.19955866662176525,-3.2869600966649744
661.6000000000087,71.27810828627895,0.19336260686237305,-3.2882762499851044
662.7000000000087,71.38937502718122,0.20005546447229805,-3.288242012791546
663.8000000000087,71.49990038064007,0.19585915710530122,-3.2876198339931793
664.9000000000087,71.61031347603554,0.20219659937540513,-3.2876199623237183
666.0000000000088,71.72146995814393,0.200128919484027,-3.2870079837730546
667.1000000000088,71.83230417032132,0.1996173351540067,-3.2872800617481936
668.2000000000088,71.94306033924245,0.20204444657759946,-3.2872800624224854
669.3000000000088,72.0541053687057,0.19960117833665536,-3.288505710086642
670.4000000000088,72.16519655664773,0.2003378524707673,-3.2885690034703012
671.5000000000089,72.27689765464373,0.20093603300521234,-3.2910507232208053
672.6000000000089,72.3885914015578,0.19935382600892182,-3.290169083173373
673.7000000000089,72.4984809465604,0.20033730468909905,-3.2912479083633164
674.8000000000088,72.60960227091523,0.199115668045879,-3.2912299423349998
675.9000000000088,72.72071205387498,0.20250492867535597,-3.291204584727865
677.0000000000089,72.83169626803613,0.20314401580971087,-3.2928797978639563
678.1000000000089,72.94232201139023,0.2037229045181439,-3.292219746041588
679.2000000000089,73.05201759497149,0.2004898165550837,-3.2912744098388194
680.3000000000089,73.16497330194706,0.20225357863406468,-3.2909100832346017
681.400000000009,73.27600639668609,0.20289814236205772,-3.2922293491280383
682.500000000009,73.38682933280803,0.20343227199071157,-3.292889624979537
683.600000000009,73.49795265442431,0.2029643123770437,-3.2915599150959354
684.700000000009,73.60901648601191,0.20278513793218855,-3.293217991077735
685.800000000009,73.72029348455851,0.2067613573577518,-3.2935405838166822
686.9000000000091,73.83155253677354,0.20662895465696285,-3.2935382181356263
688.0000000000091,73.94094991528027,0.20578027922346442,-3.293624789259308
689.1000000000091,74.05371088157918,0.20634651565305462,-3.293540176302068
690.2000000000091,74.16530518318677,0.20541605766814341,-3.2946239081500797
691.3000000000092,74.27582834631997,0.20722738441312916,-3.2948691746613274
692.4000000000092,74.38623310310929,0.2066352988313922,-3.2954766819211203
693.5000000000091,74.4963085408328,0.21073817609230727,-3.296194578276505
694.6000000000091,74.60852829004445,0.2084995609258613,-3.2961699039950476
695.7000000000091,74.7181583277778,0.21138253478244784,-3.2961699027312856
696.8000000000092,74.82958078676245,0.21484922804573214,-3.2974897811664516
697.9000000000092,74.93979338782434,0.21846353825725573,-3.2972249490734438
699.0000000000092,75.0501902874732,0.21380216150512688,-3.297150141882792
700.1000000000092,75.1610583852594,0.212033314684146,-3.29748886428956
701.2000000000093,75.27194552169378,0.21757388533790323,-3.2984439226274365
702.3000000000093,75.38442893009312,0.21531560618925316,-3.2984701470164657
703.4000000000093,75.49631224489751,0.21659797936680492,-3.2984701473542244
704.5000000000093,75.60656754188275,0.21715331255050851,-3.299634848376005
705.6000000000093,75.71779823947762,0.21737776018378008,-3.299790170181649
706.7000000000094,75.8296824279202,0.21885361978959983,-3.3011006174600848
707.8000000000094,75.94139821688752,0.21811262699528888,-3.2997898717655882
708.9000000000094,76.0526346278857,0.21689028548075018,-3.2997898475491976
710.0000000000093,76.16423146968607,0.21678335642480118,-3.3011103741537977
711.1000000000093,76.27625833079884,0.21694820274903326,-3.300445383949331
712.2000000000094,76.38756609129813,0.21456977503457653,-3.299789942947709
713.3000000000094,76.49915822447792,0.21616196731102488,-3.299789713738723
714.4000000000094,76.6107507886691,0.21373991794361924,-3.302251693936892
715.5000000000094,76.72124713325553,0.21536430524827144,-3.3024299168828968
716.6000000000095,76.83271645221944,0.21352014929153995,-3.30374323870622
717.7000000000095,76.94381508591358,0.2109193278351671,-3.302420024990653
718.8000000000095,77.05486321490848,0.21228461771336682,-3.302420041349363
719.9000000000095,77.16594602804146,0.2104982157337365,-3.3033880451981688
721.0000000000095,77.2771553569375,0.21762220893900608,-3.3023788462618575
722.1000000000096,77.38904205852458,0.2117627892855547,-3.3037379544560803
723.2000000000096,77.49887601299861,0.20618006411320988,-3.3027499372829245
724.3000000000096,77.61168521289659,0.20941147280971495,-3.3053307974513717
725.4000000000096,77.72239529204938,0.210118568731247,-3.305380130296288
726.5000000000097,77.83446545081301,0.2112323119045143,-3.3053786575923496
727.6000000000097,77.94612468027434,0.2101022109169841,-3.3040827716645063
728.7000000000096,78.0580383137138,0.21084258907026632,-3.3040701731493014
729.8000000000096,78.16890737789754,0.20752326091479412,-3.305391287003939
730.9000000000096,78.28202437992064,0.20743215864360787,-3.3053896963641556
732.0000000000097,78.39371639208895,0.20354030662328637,-3.308010198760136
733.1000000000097,78.50607841169388,0.20519439832369524,-3.3060398076231765
734.2000000000097,78.61826965541574,0.20686041286608714,-3.3060504754353257
735.3000000000097,78.73080886789464,0.20376557852988997,-3.307360114761053
736.4000000000098,78.84314107323975,0.20823430363504136,-3.3073602186819007
737.5000000000098,78.9545134875633,0.20270990435630387,-3.3090340144431423
738.6000000000098,79.06611162186024,0.20576804074006838,-3.30901013900091
739.7000000000098,79.1799000675572,0.19853060555165913,-3.3088903166510404
740.8000000000098,79.29144659943974,0.19741682017778883,-3.3076602259347982
741.9000000000099,79.4034181221488,0.19778733709160767,-3.30801082136109
743.0000000000099,79.51572068580064,0.19512842248545526,-3.308009841999149
744.1000000000099,79.62660794803917,0.1933646766333783,-3.3080107639535683
745.2000000000098,79.73934262407684,0.19633234031599045,-3.31069838304032
746.3000000000098,79.85229166358786,0.19276949095621743,-3.310623303343607
747.0000000000099,79.92236445402722,0.1937907018241174,-3.310656636375736