File: 01_Data/Basswood_Panel/STA/N2/10K_min/Basswood_Panel_STA_N2_10KData_220314_R1.csv
##Temp./Â°C,Time/min,DSC/(mW/mg),Mass loss/mg
50.0,10.538038110078384,0.049867441812678104,0.016795034950807697
51.100000000000016,10.952880685529832,0.08937121381893409,0.011621480428906317
52.20000000000003,11.185760858816648,0.1261084215070315,0.013041101422703427
53.30000000000005,11.372169040880259,0.14810272780891842,0.01151262031907141
54.40000000000006,11.531865002843846,0.16636569283848057,0.011469341828785673
55.50000000000008,11.68174117519672,0.18890934938955573,0.012166486367759077
56.600000000000094,11.82257131992079,0.2021684949510305,0.012040976985068674
57.70000000000011,11.957155037517195,0.21386273902431596,0.01046047646494408
58.800000000000125,12.087329700840035,0.22066581448271938,0.011954310956411085
59.90000000000014,12.213897597695224,0.23295859818976705,0.011362453453049426
61.000000000000156,12.339448529071419,0.2392847015270655,0.010757193436908175
62.10000000000017,12.463294646726759,0.2455476186574843,0.011877132066467233
63.20000000000019,12.587041722998359,0.25073643154083847,0.01091664945143922
64.30000000000021,12.706258570805895,0.2573215235630115,0.011108166732155311
65.40000000000022,12.826970774645428,0.26450361166355607,0.011875172378144505
66.50000000000023,12.946585412109645,0.2683528005204242,0.01063495921457669
67.60000000000025,13.06548066075039,0.2725512825603389,0.010520087548332668
68.70000000000027,13.179654959533574,0.27793479139293864,0.0105279352484704
69.80000000000028,13.302341035132363,0.28257462829033775,0.01060700027233974
70.90000000000029,13.419161615930733,0.28729522287800624,0.010522302156533492
72.00000000000031,13.536520794476289,0.2920664405559781,0.010518765624244253
73.10000000000034,13.651124955261382,0.2955614663000726,0.010520064136661844
74.20000000000034,13.767286706709395,0.2994083760196746,0.010543561617762265
75.30000000000035,13.883249159935687,0.3023993907437762,0.010561147430642848
76.40000000000038,13.997888988609589,0.30510839429036546,0.009928890244836452
77.5000000000004,14.111371288636754,0.3088178110316699,0.00920354435170001
78.6000000000004,14.22589317516614,0.3128668603883539,0.010530629081451082
79.70000000000041,14.339578387536427,0.31390894905610894,0.009210074424613524
80.80000000000044,14.452509401963612,0.31418288570562586,0.009211348927988361
81.90000000000046,14.567895469483474,0.31860310186044005,0.009034896334684461
83.00000000000047,14.679481615350255,0.3205763877442729,0.009172876931536678
84.10000000000048,14.792600859379002,0.3225607283549236,0.009202678559165456
85.2000000000005,14.903641827154033,0.32501495673887887,0.007889178139436126
86.30000000000052,15.0166752473148,0.32475595081439473,0.006708616826903935
87.40000000000053,15.123826528744985,0.3259111893575079,0.007886876055158254
88.50000000000054,15.238896067195858,0.32717257078276857,0.0065699509791175
89.60000000000056,15.349063619723951,0.32769530560525906,0.007890745709592473
90.70000000000059,15.459370570469513,0.3273680447586779,0.006580030158868766
91.8000000000006,15.56795944927796,0.32798345196304,0.005266654204591603
92.9000000000006,15.677942631365164,0.3280864501714377,0.006554430835536529
94.00000000000063,15.787609235859055,0.32605580165894327,0.005260114567457563
95.10000000000065,15.897912451146015,0.3265458723382891,0.006575193439970484
96.20000000000066,16.00497307486861,0.32427333350458915,0.007887888184508363
97.30000000000067,16.114605963132227,0.32574736746621685,0.0053123790336302434
98.40000000000069,16.22358683792206,0.3247881339926894,0.006570239885778761
99.50000000000071,16.332310068806947,0.3239919321209219,0.005581675164417987
100.60000000000072,16.440705547049614,0.32370336913057374,0.005978374595771996
101.70000000000073,16.548355206809592,0.32580317241230766,0.006222924645285843
102.80000000000075,16.65649659483633,0.32276086221803485,0.006560087159826367
103.90000000000077,16.76482100210561,0.3200129443101509,0.005255607626349246
105.00000000000078,16.873226361493845,0.3236946489473952,0.005588449757217617
106.10000000000079,16.981827843324762,0.32358935475841527,0.005589669596392177
107.20000000000081,17.08715026271831,0.3240349330541387,0.006574455133550039
108.30000000000084,17.19502948543664,0.3239888280853978,0.005259920750860125
109.40000000000084,17.30334071092583,0.323207520109507,0.005259997239492442
110.50000000000085,17.410589289487426,0.32363937810611243,0.006570920291199656
111.60000000000088,17.51822523300656,0.32443492859301015,0.005265699279209279
112.7000000000009,17.625973197196465,0.3268771352762734,0.004587749889850556
113.8000000000009,17.7340540479413,0.3259768748887785,0.005262730938666138
114.90000000000092,17.841040745454993,0.3283536589294604,0.005260090389767491
116.00000000000094,17.948427983724077,0.32885338968222755,0.00652293521998093
117.10000000000096,18.055305978703164,0.32926043964439217,0.005259827614671586
118.20000000000097,18.159535600222746,0.3308772819263659,0.005227785045085476
119.30000000000098,18.270641978189246,0.3332273578963968,0.005259916006262522
120.400000000001,18.377815643283732,0.3316879252202224,0.005259920593612577
121.50000000000102,18.483579257904346,0.3344787056472443,0.004316481274257988
122.60000000000103,18.59130431598154,0.33506071718118047,0.0036367798735899015
123.70000000000104,18.69760703962999,0.3360426213934422,0.0036100915777188547
124.80000000000106,18.80613421527258,0.3386242029516273,0.004867344351780822
125.90000000000109,18.91261843909115,0.34108020089271684,0.006254377080106011
127.0000000000011,19.018839293713935,0.3423037044028029,0.003940016477635311
128.1000000000011,19.126186129134563,0.3426261453792497,0.006251444162198361
129.20000000000113,19.232513596691202,0.34779775267630036,0.0062379709909734515
130.30000000000115,19.338452327730362,0.34641069988237094,0.006242844642145862
131.40000000000117,19.444801285764886,0.34851850764451575,0.004929839910388978
132.50000000000117,19.552285876385078,0.3514562971196554,0.005661221061720845
133.6000000000012,19.658422986513273,0.35116223764973375,0.004272265985773238
134.7000000000012,19.76545611667005,0.35141624103402647,0.0049303608532689225
135.8000000000012,19.87264858777491,0.35168990438717385,0.004936490745224731
136.90000000000123,19.978529130320776,0.3535224015020145,0.003819634880804834
138.00000000000125,20.085609122559557,0.3546187660440305,0.004919996343092592
139.10000000000127,20.190461359930428,0.3563907361322052,0.004920600756758375
140.2000000000013,20.298335967727127,0.35870741525803107,0.0035802476463882016
141.3000000000013,20.405396889209577,0.3608023767249257,0.003940019795003025
142.4000000000013,20.510626381813946,0.3621288814526994,0.00393413238654805
143.50000000000134,20.617636545630806,0.36086326745978653,0.0032666994055672305
144.60000000000133,20.723095926520728,0.3640206590900381,0.00361121517229801
145.70000000000135,20.829411089682242,0.36335346827778325,0.004930186035377204
146.80000000000138,20.93532758172802,0.3661558933362805,0.004940380765424912
147.9000000000014,21.041085980232978,0.36619483773882167,0.003620166272484404
149.00000000000142,21.14826871104008,0.3677156035421538,0.003638271716879693
150.10000000000142,21.25423113489724,0.37049081007004486,0.004929774073797688
151.20000000000144,21.358999311838268,0.3742051500784142,0.0036510434764904787
152.30000000000146,21.4667923133761,0.37572485619795337,0.0029599431941225163
153.40000000000146,21.571448130183974,0.37335413723013117,0.0033976488710756314
154.50000000000148,21.67806569628895,0.3771570660137316,0.0022898394845105585
155.6000000000015,21.782379050286966,0.37939807228740247,0.0028591147585217414
156.70000000000152,21.888507324907934,0.38158840441881464,0.001971117683171819
157.80000000000155,21.994479108958295,0.3830822770053791,0.001969931096272859
158.90000000000154,22.10092513032877,0.3861207575808108,0.0006473203934778127
160.00000000000156,22.205784574674624,0.38671821271074924,0.0010373772975160733
161.1000000000016,22.310909449505335,0.3857327826964126,0.0026168450683750066
162.20000000000158,22.41736089158074,0.38669449034102915,0.0012741737147843324
163.3000000000016,22.522446856511316,0.3888735931204159,0.001305012620489876
164.40000000000163,22.627832220915916,0.39159099800030406,0.0003199912367657376
165.50000000000165,22.732996846536352,0.39458273461342935,0.0003245844035113521
166.60000000000167,22.838236020166445,0.39497230821368845,0.0006500069914041617
167.70000000000167,22.9433685797811,0.3961366718381139,0.0006295897690664631
168.8000000000017,23.05000000000017,0.3948538425026198,-0.0009708458626702665
169.9000000000017,23.155548864875108,0.3971039728506102,0.0003223797251212801
171.0000000000017,23.259258997565784,0.3996550984451871,0.000320075000670883
172.10000000000173,23.366482382364325,0.3987597910203677,0.0003200750038825362
173.20000000000175,23.47171144128064,0.39910233449627286,0.0003238067681747836
174.30000000000177,23.577657584811675,0.40111558118281376,-0.000669930951601394
175.4000000000018,23.68267921334506,0.4025955703644136,-0.0006440461607857273
176.5000000000018,23.789793020872196,0.4047897164049181,-0.0009598280180567187
177.6000000000018,23.89474747702293,0.4052768864847392,-0.002309926319660427
178.70000000000184,24.001101184801414,0.4065824216454289,-0.0023099250001363814
179.80000000000183,24.104518080644073,0.40778495192330744,-0.0023099461640923025
180.90000000000185,24.21183479598284,0.41060186825156697,-0.0036293863042020647
182.00000000000188,24.317221047669843,0.4127626129776173,-0.004940113404211743
183.1000000000019,24.422159617675792,0.4161182058534954,-0.00494006307935102
184.20000000000192,24.52825668783856,0.4151172671428285,-0.00529372663806793
185.30000000000192,24.632444894528387,0.41881298973648473,-0.00592996868270923
186.40000000000194,24.736648935574337,0.42173295526871735,-0.005929968789392781
187.50000000000196,24.843056181211576,0.41999600914972235,-0.005946911498742935
188.60000000000196,24.948528344637616,0.42310320558870074,-0.007247061924573472
189.70000000000198,25.053622261149748,0.42358061978752626,-0.008548408577844668
190.800000000002,25.15951126406845,0.42673210020683444,-0.008586887846971258
191.90000000000202,25.26473382657514,0.43004200914461194,-0.009880595517180346
193.00000000000205,25.368518095032975,0.4309647217710603,-0.009850693656237475
194.10000000000204,25.474526227616128,0.4317502994713629,-0.009799705900570999
195.20000000000206,25.579394175006996,0.4321413167564623,-0.011518373641910884
196.3000000000021,25.684750235392396,0.4359209540935963,-0.011521540093178295
197.40000000000208,25.789371678174795,0.43621810058247784,-0.012839757233834348
198.5000000000021,25.895025490615982,0.4411712034310715,-0.013628348135740431
199.60000000000213,26.00066879099214,0.44096840039151997,-0.014160053987280818
200.70000000000215,26.105636106554037,0.44373342977874886,-0.01592792459942327
201.80000000000217,26.210775420261534,0.4469394444883583,-0.016141689358313727
202.90000000000217,26.3166189824871,0.4534192982913201,-0.017430076852314347
204.0000000000022,26.419788573261904,0.45563773475683667,-0.01942017336998214
205.1000000000022,26.525906093537337,0.4577936598154651,-0.01936086737473941
206.2000000000022,26.630748737750576,0.4613175175594132,-0.02178052018901111
207.30000000000223,26.734778627351385,0.46384021846821233,-0.02228916474742526
208.40000000000225,26.840175797642548,0.4663931586969785,-0.0233813562557752
209.50000000000227,26.945046799958902,0.46727960446853567,-0.024681938588959618
210.6000000000023,27.049602985722878,0.469536060842791,-0.025669229629885493
211.7000000000023,27.15502730229788,0.46950088344389285,-0.026965254390365345
212.8000000000023,27.25907285291045,0.47205570718423445,-0.02963221200651356
213.90000000000234,27.36464422857108,0.4746711900232819,-0.030653152275478934
215.00000000000233,27.4699011167519,0.47719271839023425,-0.03357011787874331
216.10000000000235,27.573783650111356,0.4741764882890023,-0.03356722524908795
217.20000000000238,27.68009307904262,0.47509640192000574,-0.035557360963851536
218.3000000000024,27.7831724861263,0.47388864188750024,-0.03780445430995805
219.40000000000242,27.89021922195097,0.4752545252198713,-0.04015086749441732
220.50000000000242,27.99233645953708,0.475223878764103,-0.041563834237568376
221.60000000000244,28.098949487038876,0.47441635101154356,-0.0427806248493372
222.70000000000246,28.203127515071372,0.47517892311213367,-0.0441028260696239
223.80000000000246,28.30863660563018,0.4778916135235185,-0.04805195572779564
224.90000000000248,28.41453905815321,0.47819668778484603,-0.05065301444973436
226.0000000000025,28.51942735534108,0.4782720100542921,-0.052000170023236425
227.10000000000252,28.623749082931777,0.4779000520139167,-0.054590535072264856
228.20000000000255,28.729121941567385,0.47732028272283566,-0.05785790705076188
229.30000000000254,28.83412122436961,0.47634224290155297,-0.06011950677456479
230.40000000000256,28.940390914193557,0.474725285916492,-0.06289311850134283
231.5000000000026,29.04367556332974,0.47718444602647625,-0.06509800070709248
232.60000000000258,29.14936442254895,0.47619321945166465,-0.06764476169250866
233.7000000000026,29.254487257461633,0.4763119369134907,-0.07020659202581303
234.80000000000263,29.359724070796084,0.4768774246519736,-0.07327170364402358
235.90000000000265,29.464164933224293,0.4764011284577643,-0.07592025891799148
237.00000000000267,29.568741933204535,0.4775853021887302,-0.0799683999858809
238.10000000000267,29.67411127747729,0.47636013602542093,-0.08118937909172175
239.2000000000027,29.779137073859378,0.47381116140061796,-0.08535307032842132
240.3000000000027,29.88412802136855,0.4762195080914482,-0.08797105246739712
241.4000000000027,29.989080070572456,0.47686833841382237,-0.09211006658847953
242.50000000000273,30.094533258381908,0.4784659376171264,-0.09628590057236153
243.60000000000275,30.19940246258848,0.47697333981346823,-0.0990196160987038
244.70000000000277,30.303465864725432,0.47583536328866094,-0.10200615471992025
245.8000000000028,30.408684253031257,0.47550037052811733,-0.10455945944951495
246.9000000000028,30.513760475055786,0.4738501973987706,-0.11027980738216403
248.0000000000028,30.619150881491606,0.47700504332190374,-0.11429413775067854
249.10000000000284,30.724427131405445,0.47890040056980676,-0.11695982779716152
250.20000000000283,30.82625150629923,0.47890985268753705,-0.12218219588088353
251.30000000000285,30.934084141298687,0.4784921471064631,-0.12677182596352132
252.40000000000288,31.038096348649237,0.4824072468727745,-0.13091512796400506
253.5000000000029,31.14318775310858,0.48374228732509367,-0.1338481413785133
254.60000000000292,31.247664924116577,0.4852789312831396,-0.1382543826311733
255.70000000000292,31.353012004638323,0.48584705419559193,-0.1427803814804638
256.8000000000029,31.45707264875702,0.489519404191863,-0.1480878269439212
257.90000000000293,31.56126737803709,0.48877666742071757,-0.15345208488094864
259.00000000000296,31.666634814137403,0.4923241084655271,-0.15775246997833436
260.100000000003,31.77036857639581,0.49376886033595374,-0.1639017997527481
261.200000000003,31.873577314429756,0.4958831378921766,-0.16835176123782958
262.300000000003,31.980187876833902,0.49300323508781835,-0.17573079584218254
263.40000000000305,32.085654089107,0.49199230635430286,-0.18318400155280923
264.50000000000307,32.19008715646542,0.495305442699154,-0.18867778071532282
265.6000000000031,32.2944182430648,0.49512018794977025,-0.19571405803531183
266.7000000000031,32.39896674819211,0.49678832542671525,-0.20237075730320386
267.8000000000031,32.50494085612266,0.4960061968228506,-0.2101480728355538
268.9000000000031,32.61073562377494,0.49443553691072367,-0.218088876964476
270.0000000000031,32.714781920346894,0.4956853589694941,-0.22662122385082517
271.10000000000315,32.82113925451514,0.4946632297752201,-0.2344553168275021
272.2000000000032,32.924981286583765,0.49857487846606097,-0.2433672475834685
273.30000000000314,33.0300955383218,0.49533741711995044,-0.2555786181010369
274.40000000000316,33.13514980251989,0.49483176906818604,-0.2637330913201419
275.5000000000032,33.24089552089712,0.49449119540293074,-0.2746220039228482
276.6000000000032,33.344091839519436,0.49573507170403686,-0.28472797026429175
277.70000000000323,33.45118405053084,0.49358165236064366,-0.2964054071807358
278.80000000000325,33.55626622616315,0.49198432664535324,-0.31058619218721484
279.9000000000033,33.66097770722956,0.4913083518195825,-0.32040278313581094
281.0000000000033,33.7641057651158,0.48895113466398926,-0.33407879453104794
282.1000000000033,33.871899561943025,0.4883844791454942,-0.3492014053508461
283.20000000000334,33.97721525728491,0.48894444965714234,-0.3627542800799981
284.30000000000337,34.081718430604546,0.48791605772829255,-0.3754379332450828
285.40000000000333,34.186331309169276,0.4869779365856773,-0.3919136223069932
286.50000000000335,34.292542002981506,0.48280901704798473,-0.40750843158773176
287.6000000000034,34.396690275694766,0.48386519823397284,-0.42312332276072917
288.7000000000034,34.50217316357295,0.480411418753,-0.43916229339572377
289.8000000000034,34.60737470968689,0.47973853484710566,-0.4561363494160089
290.9000000000034,34.71263031452776,0.47787689814648004,-0.4739771099611496
292.0000000000034,34.818107357143255,0.4740103868313954,-0.49184401915422393
293.10000000000343,34.92357306589425,0.4715081078631958,-0.5117965362524162
294.20000000000346,35.02874103264768,0.46895627107283383,-0.5320949852445618
295.3000000000035,35.13280996810414,0.4673060698325916,-0.5502787557911692
296.4000000000035,35.23944782116697,0.4662413629263879,-0.570895254940929
297.5000000000035,35.34459295358369,0.46700033951202014,-0.5904986789058069
298.60000000000355,35.4499989436381,0.4650382930553683,-0.6097499020866666
299.70000000000357,35.555779249842765,0.4649536409786465,-0.6311395621911116
300.8000000000036,35.66142440844312,0.46520595256558295,-0.6502805247290393
301.9000000000036,35.76664512278494,0.4655901787738823,-0.6721348411703816
303.0000000000036,35.87206319322362,0.46541281852677485,-0.6918397915226859
304.1000000000036,35.97636992288674,0.46481964026659583,-0.7121730898584651
305.2000000000036,36.08290785599975,0.46506066579496497,-0.734493303705948
306.30000000000365,36.18763984755232,0.46887415654731446,-0.7562920943813607
307.4000000000037,36.29324151545401,0.4664261665979433,-0.7769665186997399
308.5000000000037,36.39990380007121,0.46921388773138806,-0.7973155654307478
309.60000000000366,36.50519377284516,0.46963864865129357,-0.8196465859311846
310.7000000000037,36.61095186624873,0.47197635900853085,-0.840624594358311
311.8000000000037,36.71614890478563,0.4775579823280082,-0.8601112539468434
312.90000000000373,36.82229691174633,0.47672595883032404,-0.8825469573439895
314.00000000000375,36.926912758725265,0.47905690418374863,-0.9031781791683784
315.1000000000038,37.0336826565764,0.48590978000013474,-0.9268978481803218
316.2000000000038,37.138587471392206,0.4888717963836967,-0.9476763798337076
317.3000000000038,37.245036360595904,0.491929541871584,-0.9695782096867647
318.40000000000384,37.350579702005696,0.49942090476679735,-0.9905172379996201
319.5000000000038,37.45739632842957,0.504741111336724,-1.0129170132505974
320.60000000000383,37.56228819444988,0.509803904710116,-1.0347195161147278
321.70000000000385,37.668854896434055,0.5160583465817169,-1.0569901861943922
322.8000000000039,37.774968746976654,0.5230772884752233,-1.079519846542401
323.9000000000039,37.88107860455211,0.5306557218090954,-1.1016884285938602
325.0000000000039,37.98705706881269,0.5362800037653594,-1.1267451291150432
326.10000000000394,38.09178659150815,0.5470121963088647,-1.149959736687534
327.2000000000039,38.199094822429316,0.553688750475068,-1.1742650306798197
328.30000000000393,38.30470274095709,0.5593327831083076,-1.1984816396592581
329.40000000000396,38.411700098487266,0.5694368596375019,-1.2234508620021276
330.500000000004,38.51671930426738,0.5746121124620355,-1.2481178290447419
331.600000000004,38.6225331071453,0.5841193710814042,-1.2746693782829532
332.700000000004,38.73051888608243,0.5944074944127383,-1.3007843969296742
333.80000000000405,38.83560368953859,0.6015998969052523,-1.327941531419147
334.90000000000407,38.94304673273473,0.6096101798463665,-1.3549377617553828
336.0000000000041,39.049467353208044,0.6200993836030081,-1.383396614248391
337.10000000000406,39.154326003713514,0.6308668883902286,-1.412813180503207
338.2000000000041,39.26283825415661,0.6409788944196696,-1.4452732177773315
339.3000000000041,39.3688109150466,0.6538209483294662,-1.4753876186104775
340.4000000000041,39.47603708428444,0.6647142603790752,-1.5070106647377486
341.50000000000415,39.58179873271701,0.6736519839270497,-1.5389916252330957
342.6000000000042,39.68836294656744,0.6853151102998475,-1.5734031611769286
343.7000000000042,39.7949726334753,0.6963928862555566,-1.6087731258055884
344.80000000000416,39.90117272171563,0.7071558201958641,-1.6449819503454268
345.9000000000042,40.00849294164817,0.7206566267882277,-1.6813382221058943
347.0000000000042,40.11488789186381,0.7315190394864873,-1.7194857216336694
348.10000000000423,40.22091119442531,0.7431152323584673,-1.7594877206764452
349.20000000000425,40.328356248176334,0.7518184570845365,-1.7992863723185502
350.3000000000043,40.4345883718666,0.7631144406740391,-1.840581378733677
351.4000000000043,40.541783776954965,0.7680561632075766,-1.8837768445047889
352.5000000000043,40.6477178038403,0.7776234860103854,-1.925283791143809
353.60000000000434,40.75522304743594,0.7869504702455349,-1.9713532208683984
354.7000000000043,40.861911329200325,0.7906930667879091,-2.0183112687306304
355.80000000000433,40.96909379306851,0.7951471923126481,-2.0632087801458248
356.90000000000435,41.07394581032643,0.7949593230520398,-2.108331510252256
358.0000000000044,41.18072030197697,0.7953751512178701,-2.1559645148445576
359.1000000000044,41.28804081761256,0.7929007852877148,-2.204247530968958
360.2000000000044,41.395010479009855,0.7883052661353593,-2.251220490501594
361.30000000000445,41.50213362759871,0.7782596160113336,-2.300838044799164
362.4000000000044,41.60777853588759,0.7626486883557871,-2.347945221865772
363.50000000000443,41.715519332322394,0.7468372680408,-2.394481474412286
364.60000000000446,41.82205004814157,0.727286465581216,-2.4416425113867657
365.7000000000045,41.92863537486222,0.702370700631016,-2.4848538927656496
366.8000000000045,42.0359351891873,0.6721384190973718,-2.529812999151152
367.9000000000045,42.141949439835464,0.6397710677232293,-2.5716717505243833
369.00000000000455,42.24973354005234,0.601708721718626,-2.6111857807381686
370.10000000000457,42.35698548208623,0.5606047101272139,-2.6456091451163033
371.2000000000046,42.463533822400066,0.5158769942749848,-2.6807085186561874
372.30000000000456,42.57071992961252,0.47271178547857495,-2.7108266652797846
373.4000000000046,42.67759034403472,0.4275124127498229,-2.737692017052268
374.5000000000046,42.784405062391905,0.3825179458567497,-2.763010133700421
375.6000000000046,42.891329478320664,0.3401642064503043,-2.783211888583159
376.70000000000465,42.99698850159345,0.3010011270378692,-2.8008005245774994
377.8000000000047,43.1037971340019,0.2684762555420245,-2.816357648162067
378.9000000000047,43.210000945211945,0.24161046680604964,-2.8282302097601977
380.00000000000466,43.31734695621182,0.21652868247157606,-2.8376472142085296
381.1000000000047,43.42297963565016,0.20077377345158498,-2.8449541944404744
382.2000000000047,43.52798741829966,0.18700894212310157,-2.851666276964173
383.30000000000473,43.636671869093306,0.17764884136091663,-2.8581610068768213
384.40000000000475,43.74292571517966,0.16962827586069684,-2.8654672091521194
385.5000000000048,43.85000000000045,0.16152944138828063,-2.8701598740000307
386.6000000000048,43.956855059799466,0.1587151985525891,-2.8746474324299225
387.7000000000048,44.063199833950854,0.15154438039804785,-2.8794051719103937
388.80000000000484,44.17009957414137,0.15311209069483864,-2.885414352187639
389.9000000000048,44.2774911462109,0.14840410765713843,-2.888840289670976
391.00000000000483,44.383987966644966,0.14393212711473902,-2.8938089570813417
392.10000000000485,44.49118458590717,0.14308881298512097,-2.898243585498511
393.2000000000049,44.597910073498014,0.1379897957149198,-2.901088537446718
394.3000000000049,44.70437682278403,0.13309827659348522,-2.9052504302662956
395.4000000000049,44.81209761584542,0.1303960210625087,-2.9093877652093134
396.50000000000495,44.91863418410669,0.12851296896363706,-2.9131435726698105
397.6000000000049,45.025678354782634,0.12723824334899614,-2.9152126401087797
398.70000000000493,45.13344525252017,0.12326519025011792,-2.9191530242103028
399.80000000000496,45.240000969299025,0.12029866615657164,-2.9233601913129283
400.900000000005,45.347073029065236,0.1189441074482871,-2.9278980077897847
402.000000000005,45.45455768604286,0.11470568197609554,-2.9306684706473014
403.100000000005,45.56188674561843,0.11494696937153168,-2.933960491519223
404.20000000000505,45.66911953739609,0.11138818820308108,-2.9377372082995623
405.30000000000507,45.77600524822875,0.10951955384501785,-2.9406624377802677
406.4000000000051,45.883730788100124,0.10890253219006979,-2.94471192599198
407.50000000000506,45.99133908756896,0.10900705372003716,-2.9482113552210416
408.6000000000051,46.09828641059398,0.10479247058273344,-2.950893575542285
409.7000000000051,46.20603293219538,0.10524102710001154,-2.954642511029652
410.8000000000051,46.31367484257067,0.10389354253399508,-2.95850674744168
411.90000000000515,46.421986778240694,0.10410833142047476,-2.9615811688393974
413.0000000000052,46.52870441653416,0.09734095276769528,-2.965784335042793
414.1000000000052,46.636558405786154,0.10026955811436689,-2.9673403601003496
415.20000000000516,46.74414449393989,0.10176902997730136,-2.971257060565592
416.3000000000052,46.851835701967445,0.10069370603171579,-2.973935741813768
417.4000000000052,46.95863297269241,0.09838377209435667,-2.9767724854741964
418.50000000000523,47.06665317174005,0.09953674539631024,-2.980656427274008
419.60000000000525,47.17432027323248,0.09923709868110747,-2.983169690027066
420.7000000000053,47.27968456874121,0.09780009509672921,-2.9882508617003225
421.8000000000053,47.38990732636378,0.10183653292986133,-2.990159002741721
422.9000000000053,47.49818468968138,0.0986934238437468,-2.9934509881302414
424.00000000000534,47.60549530583541,0.10223203884182153,-2.997470269736268
425.1000000000053,47.71287956664764,0.10574432663249139,-2.9994374849823693
426.20000000000533,47.821609450252176,0.10398084718652817,-3.0025578923272436
427.30000000000535,47.929250414089,0.10407636913973856,-3.0056916931068685
428.4000000000054,48.03778081496159,0.10510422878749603,-3.008197221418381
429.5000000000054,48.145350034162576,0.10663774024375366,-3.010093402947242
430.6000000000054,48.253236534903536,0.11105953057539947,-3.0136128536197546
431.70000000000545,48.36117481203698,0.11112157850549703,-3.0181626116642173
432.8000000000054,48.46856623987668,0.11312011305637054,-3.019440265471272
433.90000000000543,48.576173492003996,0.11610644424568134,-3.02212942259467
435.00000000000546,48.68391031182471,0.11502832436288662,-3.023579210944991
436.1000000000055,48.791888631418246,0.1176443647239534,-3.0265002484540835
437.2000000000055,48.89912270623756,0.11896856300417508,-3.0300907940507757
438.3000000000055,49.00702544281479,0.11635299421659906,-3.0336950293644276
439.40000000000555,49.11597334368318,0.12130201013371222,-3.0363411125879205
440.50000000000557,49.223624782984125,0.12255464600810761,-3.039033013793605
441.6000000000056,49.33150891505856,0.12359484192178916,-3.0411720806500506
442.70000000000556,49.43948470711908,0.12533033657376957,-3.0430109789169566
443.8000000000056,49.54747371205079,0.12512970696746561,-3.04532342448353
444.9000000000056,49.65602620644708,0.1289216839853075,-3.0465993993054563
446.0000000000056,49.763675799147066,0.13139396580394225,-3.0492790031963324
447.10000000000565,49.872190052388355,0.1301251093808467,-3.052074050808025
448.2000000000057,49.97932893423479,0.1335033854501107,-3.053957835839907
449.3000000000057,50.087353434951055,0.1362835550394227,-3.057112165253061
450.40000000000566,50.19439455494033,0.13587056482321497,-3.0592539095363627
451.5000000000057,50.302936830778165,0.14123091769392454,-3.061903721188226
452.6000000000057,50.41099525707344,0.14158418135213563,-3.0645198620525687
453.70000000000573,50.51886686613429,0.14394014111465725,-3.065950738275296
454.80000000000575,50.626978351146136,0.14720977809289337,-3.0672715751757185
455.9000000000058,50.73551565642862,0.14909918273978323,-3.0689644851499343
457.0000000000058,50.843717104030226,0.15042536221727976,-3.0702397638861987
458.1000000000058,50.95149165559161,0.15621504843918566,-3.0738553803359387
459.20000000000584,51.05789186223399,0.1521650122006044,-3.0751888920582875
460.3000000000058,51.16925335172423,0.15532905689280552,-3.076495853439507
461.40000000000583,51.27782083110579,0.15590600358530504,-3.077799116436379
462.50000000000585,51.38644651248508,0.15520309632970752,-3.0791136499133063
463.6000000000059,51.49511519973375,0.15916982353085685,-3.0817572691584414
464.7000000000059,51.60366372281744,0.16138076384137412,-3.083068067381952
465.8000000000059,51.71155896440492,0.16161163870101208,-3.084357792978576
466.90000000000595,51.82010333458283,0.16074367233251924,-3.0860281264466876
468.0000000000059,51.929692157122034,0.16179273293040947,-3.0885999322171593
469.10000000000593,52.03813170786239,0.16574510592835012,-3.0898901561995515
470.20000000000596,52.146539791347905,0.1670035337201864,-3.0912362080683247
471.300000000006,52.25533385473514,0.16486738268541923,-3.094001802966571
472.400000000006,52.36433182164416,0.16655772385734596,-3.09428759467282
473.500000000006,52.47321137146108,0.16977702704040892,-3.095594837109465
474.60000000000605,52.58221075616504,0.16677345903956914,-3.0980678496097784
475.70000000000607,52.691335000973666,0.16617606677397312,-3.100163646330502
476.8000000000061,52.80059455992783,0.1673344701745778,-3.1015001888415483
477.90000000000606,52.908763410426054,0.16539645407304643,-3.1028096257287157
479.0000000000061,53.01743740099053,0.16714922871917282,-3.1041299126277684
480.1000000000061,53.127400701192464,0.16847039882868675,-3.105466622735176
481.2000000000061,53.23742689629005,0.17093715979590507,-3.1069428018119045
482.30000000000615,53.3453131527344,0.16920312349279382,-3.1071005836710364
483.4000000000062,53.45479571717289,0.17188834233558192,-3.1084008179181213
484.5000000000062,53.562407053018866,0.17131679591977683,-3.1097208380424655
485.60000000000616,53.671324951993036,0.17299421648019847,-3.1110457017834374
486.7000000000062,53.77999901636893,0.17339445965092581,-3.1130100864388264
487.8000000000062,53.88867249842424,0.17358216970609364,-3.113667657441586
488.90000000000623,53.99810455163081,0.17431181354036274,-3.1149798776089415
490.00000000000625,54.105809128635244,0.1752114677873602,-3.1162984807014045
491.1000000000063,54.21460847895235,0.17458852246846113,-3.1176205083470565
492.2000000000063,54.323431470402014,0.17683003279074727,-3.118930703637017
493.3000000000063,54.43196436616705,0.17420426522105986,-3.1202487225560533
494.40000000000634,54.54115869060218,0.17597400975367322,-3.12156987319453
495.5000000000063,54.6501922286112,0.17964304660177444,-3.1228797762467257
496.60000000000633,54.75894998090251,0.1788279584594306,-3.1238390957013182
497.70000000000636,54.86758471283411,0.18917696597529166,-3.1245219445080172
498.8000000000064,54.9765985491154,0.19426909080573485,-3.125754882825209
499.9000000000064,55.085503715087256,0.19917450348814691,-3.126740723615689
501.0000000000064,55.1940282576687,0.20492681601876284,-3.12867690741061
502.10000000000645,55.30193697429397,0.20714376769113096,-3.1297740851585627
503.2000000000064,55.41195471553048,0.2070935184945778,-3.1305139853564654
504.30000000000643,55.519583309766006,0.2074581612823343,-3.1311090378864526
505.40000000000646,55.62946718844336,0.21159375581045559,-3.133746555721405
506.5000000000065,55.73700449088277,0.21354640963983162,-3.1324197895565122
507.6000000000065,55.846014342619036,0.21566913470280802,-3.13472678426697
508.7000000000065,55.95459683362363,0.21719616417618304,-3.1370616023743674
509.80000000000655,56.06400273401416,0.21865152919461572,-3.13669992522677
510.90000000000657,56.172355548620025,0.21831034283206063,-3.1373509319129327
512.0000000000066,56.28068426757729,0.22153381021764285,-3.1373631416197623
513.1000000000065,56.39047546131314,0.22322888002469787,-3.1386685091332702
514.2000000000066,56.499697137962876,0.22278897720681445,-3.1406499116951503
515.3000000000065,56.60836246263484,0.22471294427251032,-3.1419739974929004
516.4000000000067,56.71639803257105,0.2265297593861484,-3.14194298422687
517.5000000000066,56.826031155506904,0.22642132445411312,-3.1419610724996
518.6000000000067,56.93511250133852,0.22645118084049765,-3.1432816791313463
519.7000000000066,57.044142376764206,0.23080644574496623,-3.1445898329408175
520.8000000000067,57.15394375246307,0.22910413298009424,-3.1459083248888486
521.9000000000067,57.263546925802856,0.23097076169257702,-3.1468995448329826
523.0000000000067,57.37321840052091,0.22910155795291032,-3.147237198180772
524.1000000000067,57.48183916280992,0.23132194731624744,-3.1495748423601766
525.2000000000068,57.591362211940144,0.23133855559689664,-3.14986023476156
526.3000000000068,57.699894842527755,0.23038452351157734,-3.151833308494684
527.4000000000068,57.810451416987775,0.23240856830084555,-3.1535080510272055
528.5000000000068,57.91927098672653,0.22932679662052347,-3.151699218202052
529.6000000000068,58.027799683216706,0.2305971668930955,-3.1528189133862616
530.7000000000069,58.13796319131741,0.22619164746684162,-3.154139739407226
531.8000000000068,58.24791161023768,0.2158176286245691,-3.1541381953667917
532.9000000000069,58.35747095193788,0.21091165850083715,-3.1561243348836823
534.0000000000068,58.4674762282338,0.20261130679080064,-3.1564401871732044
535.100000000007,58.57678846622763,0.20096569391097163,-3.1564649793995825
536.2000000000069,58.685354142256905,0.19732627567130157,-3.157805552880281
537.300000000007,58.79544366888845,0.1919897178058625,-3.1590583846509452
538.4000000000069,58.906411089640166,0.1878809730048413,-3.158989215045415
539.5000000000069,59.014429283098664,0.18793184698213083,-3.1590735803289625
540.600000000007,59.124712803032736,0.18628939661842303,-3.1604010145127734
541.700000000007,59.23394683342753,0.18219653608176944,-3.1617101360629785
542.800000000007,59.343922208190875,0.18013461690439492,-3.161746545179037
543.900000000007,59.45369155169486,0.17731532569722042,-3.163029882957579
545.000000000007,59.563349319762175,0.18062255609924205,-3.1620411720753174
546.1000000000071,59.672341071259794,0.17266236316124728,-3.1633499588508123
547.2000000000071,59.78210956289809,0.17254707235987254,-3.163349977636427
548.300000000007,59.89122841840069,0.1710977527335451,-3.1646693179876264
549.4000000000071,60.00090755119398,0.17017643378820602,-3.1657011439766336
550.500000000007,60.11000000000077,0.17011610500070262,-3.1672271419997973
551.6000000000072,60.21913870599218,0.17001208377334376,-3.16730042769965
552.7000000000071,60.32892458538076,0.1667820383207248,-3.1686213878534017
553.8000000000072,60.437963552748876,0.1646786205019739,-3.1686198979887026
554.9000000000071,60.547719795914595,0.15999595227160723,-3.1686385308931495
556.0000000000072,60.657302118262784,0.15824022016403205,-3.1699400083142164
557.1000000000072,60.7667482568401,0.1532834341730679,-3.1702830582238617
558.2000000000072,60.875558586394405,0.1505404852317852,-3.171250172291395
559.3000000000072,60.985783255372866,0.14869233668436255,-3.1739605711223673
560.4000000000073,61.09604263116576,0.14626067004687082,-3.173226846430423
561.5000000000073,61.20609193516876,0.14337555119541023,-3.17454032075042
562.6000000000073,61.316722837134016,0.14344254538201695,-3.173890899174761
563.7000000000073,61.4259203420495,0.1410779598105728,-3.17454746664293
564.8000000000073,61.536279523414585,0.13796800731608228,-3.1763339721479813
565.9000000000074,61.647016519931384,0.13582205267352587,-3.175774088829736
567.0000000000074,61.7542268148089,0.13338167301549497,-3.1761799463419704
568.1000000000074,61.86738943500534,0.1325840666216651,-3.1775018898915253
569.2000000000073,61.97745976048123,0.13343951213676197,-3.177500161746153
570.3000000000073,62.08797165086111,0.13048399790924825,-3.17880277238829
571.4000000000074,62.19736091976116,0.13525159683886012,-3.178483794924194
572.5000000000074,62.30806113727682,0.13474113158308743,-3.1788198892230453
573.6000000000074,62.41819163315172,0.12807891248859393,-3.18146893088647
574.7000000000074,62.527632593107064,0.12921384174908634,-3.1827604944580177
575.8000000000075,62.63794347240087,0.12609933290820363,-3.181450076589688
576.9000000000075,62.74823554638724,0.1289233715382303,-3.182759217410491
578.0000000000075,62.855767716658306,0.13171646599573028,-3.184058207884461
579.1000000000075,62.967548301310735,0.1300668195468878,-3.1840889853125423
580.2000000000075,63.07628335559969,0.12927716002686696,-3.1854030378180327
581.3000000000076,63.185917877816536,0.13112147134768304,-3.185456855708218
582.4000000000076,63.29670380654651,0.13040487748466112,-3.1853999390049985
583.5000000000076,63.40749094985795,0.13130076536752433,-3.1854295778233994
584.6000000000076,63.51665304155415,0.1295736977161418,-3.1856555693488913
585.7000000000077,63.626958124929466,0.13221035537960202,-3.1880301057844127
586.8000000000077,63.73587143451281,0.1333058562904058,-3.18902633406363
587.9000000000076,63.84530287670373,0.12860191367287,-3.190377786749867
589.0000000000076,63.95657254483474,0.13073920665572025,-3.1903968601062798
590.1000000000076,64.06647007651563,0.1311422089489016,-3.190673371408981
591.2000000000077,64.17774008764815,0.12996683828050748,-3.190669866975636
592.3000000000077,64.28804623049976,0.13091104855754898,-3.1918167132513426
593.4000000000077,64.39704231153947,0.13216809745102032,-3.1920077216511684
594.5000000000077,64.50784412157323,0.1325177435540541,-3.193186043085843
595.6000000000078,64.61753797944002,0.1312124671884234,-3.1919799809876475
596.7000000000078,64.72753542247281,0.13231114811367284,-3.1933020893520436
597.8000000000078,64.83788043145083,0.13524872567987245,-3.1926396011126577
598.9000000000078,64.9481537974993,0.1357809296275614,-3.1939501397069594
600.0000000000078,65.05910241870194,0.13779625540420637,-3.193950139457083
601.1000000000079,65.16932802265384,0.13813541776719596,-3.196399947301038
602.2000000000079,65.27942657590374,0.13876359731393317,-3.1952654541267314
603.3000000000079,65.38968330100047,0.13973626526252425,-3.196589800002709
604.4000000000078,65.50159716118246,0.14239563606561523,-3.197393105462603
605.5000000000078,65.61203603498387,0.14016689256315407,-3.1962514078977184
606.6000000000079,65.7213956573967,0.1397948215190138,-3.196296904467737
607.7000000000079,65.83145896283008,0.14274721596458573,-3.1979478850028062
608.8000000000079,65.94143005423987,0.14488301945720228,-3.1985340322406626
609.9000000000079,66.052746238255,0.14216875037274612,-3.199881223888263
611.000000000008,66.16373695765411,0.14843229775600864,-3.198670066723411
612.100000000008,66.27407478535966,0.14813128580975188,-3.201189804095378
613.200000000008,66.38483139026526,0.1505280925745388,-3.2008546835343155
614.300000000008,66.49538141500608,0.15302787530192952,-3.202178949591525
615.400000000008,66.60627453610941,0.15531756842190358,-3.202509780554659
616.5000000000081,66.71652049876197,0.15609637150246636,-3.2022445395840853
617.6000000000081,66.82808445683631,0.15914023765294683,-3.20349685744879
618.7000000000081,66.93805061064025,0.1617541193828762,-3.2048648532230435
619.8000000000081,67.04958435512219,0.16414782793924376,-3.203500855462525
620.9000000000082,67.1598056810099,0.1627089611739475,-3.203500089731232
622.0000000000082,67.27067944910277,0.16402475317170684,-3.204817305310331
623.1000000000081,67.38028724115708,0.16413608211891573,-3.203854617511799
624.2000000000081,67.49062622946353,0.16314064763172775,-3.2052528404069647
625.3000000000081,67.60119414418703,0.16665113057014946,-3.2057998479536165
626.4000000000082,67.71164368880524,0.16904511446445725,-3.2058002360502833
627.5000000000082,67.82166839031386,0.17216049276048961,-3.2074433509842795
628.6000000000082,67.93260974936159,0.1728239389911933,-3.2061310404073398
629.7000000000082,68.04305437041445,0.17254364445852977,-3.2061333128523857
630.8000000000083,68.15219252998338,0.17466564759426018,-3.207332662947089
631.9000000000083,68.26349011021878,0.1768936532427915,-3.2061495185734414
633.0000000000083,68.37432826370868,0.1766455428679865,-3.2081003689173926
634.1000000000083,68.4845369412086,0.17784387513139133,-3.208099593736879
635.2000000000083,68.59538405858507,0.16944939805493298,-3.2093657165289455
636.3000000000084,68.70644170414342,0.17266327105823231,-3.207562540067381
637.4000000000084,68.81684057660617,0.17314463782684864,-3.208880226375666
638.5000000000084,68.92809191627916,0.17242725457604147,-3.210190904603631
639.6000000000083,69.03938981612875,0.17267224844105034,-3.211509838489109
640.7000000000083,69.14950888454626,0.17250226279194902,-3.21150984594685
641.8000000000084,69.26129270933873,0.1686896566271523,-3.2111543427609672
642.9000000000084,69.37276537944989,0.16736696405738782,-3.2113945670116673
644.0000000000084,69.48389996390715,0.16899138166940375,-3.2121993423337405
645.1000000000084,69.5938753181059,0.16656637971669364,-3.2117421139428988
646.2000000000085,69.70411468622922,0.16772467024478543,-3.210313891754759
647.3000000000085,69.81452170248375,0.1694655908970233,-3.2116208443344734
648.4000000000085,69.92464859075905,0.1672082068453946,-3.212929942435139
649.5000000000085,70.03428667604722,0.16893212404519042,-3.213909553081493
650.6000000000085,70.14605445920172,0.17121334288273227,-3.21392000514439
651.7000000000086,70.25643499180329,0.17094416115518518,-3.214725806755644
652.8000000000086,70.36747769490353,0.17302214991752507,-3.213590084270095
653.9000000000086,70.4768208875866,0.16992551879484763,-3.2136017607611924
655.0000000000086,70.58829816298757,0.16995816392429397,-3.2152303443385946
656.1000000000087,70.69989815756865,0.17129857307035268,-3.2152296820450417
657.2000000000087,70.80893990133944,0.1678825249948177,-3.2152301622533703
658.3000000000086,70.92098878743148,0.16904242280796478,-3.2166397090029886
659.4000000000086,71.03280291638987,0.1688238962503672,-3.2152398549762213
660.5000000000086,71.14254474936372,0.1696755222260855,-3.2152398549481287
661.6000000000087,71.25332084449366,0.16826866217461234,-3.2155845983394027
662.7000000000087,71.36490101210764,0.16905393592819862,-3.2172099447865934
663.8000000000087,71.47674938777446,0.17114049795685093,-3.2172000011215416
664.9000000000087,71.58830325745866,0.17169400924238132,-3.2158999479832975
666.0000000000088,71.69866864558134,0.17524848789512082,-3.215900526854807
667.1000000000088,71.80868982637092,0.17501474034367526,-3.217209997491085
668.2000000000088,71.92061873160455,0.1717732492835251,-3.217210014310332
669.3000000000088,72.0322191257276,0.16913352611859844,-3.2185286149283905
670.4000000000088,72.14317978450312,0.17374640074948489,-3.2175391283371386
671.5000000000089,72.25497974045868,0.16839867759194194,-3.2179068328366993
672.6000000000089,72.36471712339198,0.17163293198042218,-3.219190157480993
673.7000000000089,72.47620253592801,0.17486768333943958,-3.2188666770171697
674.8000000000088,72.58885479380919,0.17381107119297678,-3.2201698788036826
675.9000000000088,72.699263610917,0.17798907045263967,-3.217272897382281
677.0000000000089,72.81076019243397,0.17865295603944786,-3.2202824679855397
678.1000000000089,72.92170916400921,0.17934719150359757,-3.218970158139924
679.2000000000089,73.031589828516,0.1777312609187911,-3.220074491508922
680.3000000000089,73.14318672769595,0.17690282230365773,-3.221269852995257
681.400000000009,73.25353535117974,0.1760061051605375,-3.221270240973099
682.500000000009,73.36518698297114,0.17791641432804273,-3.219959818057161
683.600000000009,73.47505617480066,0.17952047582231412,-3.2198929011593154
684.700000000009,73.58624060453614,0.1765701421022421,-3.221265247217338
685.800000000009,73.69767718570063,0.17829200816233493,-3.22224992328953
686.9000000000091,73.80782544361358,0.17673571043302982,-3.2222478410239885
688.0000000000091,73.91861797251767,0.17573842671206275,-3.2209497292489155
689.1000000000091,74.02990183643537,0.1797738563116893,-3.222260011904474
690.2000000000091,74.13957486603266,0.17475821981667594,-3.2235479967573504
691.3000000000092,74.25244299076334,0.17826202581618755,-3.222252130295845
692.4000000000092,74.36374717328536,0.17693075790465196,-3.2222442538632174
693.5000000000091,74.47416578413207,0.17688115588967057,-3.224559211596251
694.6000000000091,74.58618591235494,0.17825124526653435,-3.2242306372754435
695.7000000000091,74.69740788310463,0.17848648144892842,-3.22324023652589
696.8000000000092,74.80811520072947,0.1797513031906317,-3.223214672397118
697.9000000000092,74.91999794852006,0.18242894299156176,-3.223568588117999
699.0000000000092,75.03084219487273,0.1813501367582202,-3.223557560173834
700.1000000000092,75.1422934441879,0.1799655209343729,-3.2262052153820533
701.2000000000093,75.25345399441504,0.18089295858221832,-3.224892790154311
702.3000000000093,75.36497373795706,0.1800802037859932,-3.2248799292010237
703.4000000000093,75.47600444286553,0.1777009146252193,-3.2242796991286062
704.5000000000093,75.58763947730391,0.1797627387119447,-3.2239000625816123
705.6000000000093,75.6990399833173,0.17887749284092003,-3.2252108820394345
706.7000000000094,75.81010680662231,0.18127500014567421,-3.225226125815218
707.8000000000094,75.9212336224569,0.1815367906825187,-3.225225424044587
708.9000000000094,76.03330478844299,0.18082798968684144,-3.226532414311765
710.0000000000093,76.14381212090106,0.18102297198307982,-3.227200136495134
711.1000000000093,76.25640230826183,0.17681915692023797,-3.2263320223493976
712.2000000000094,76.36677222436855,0.1774128322073396,-3.2275862560202153
713.3000000000094,76.4786677887731,0.17681996006466183,-3.227532069086257
714.4000000000094,76.58989534341119,0.17638992039449475,-3.228839826356095
715.5000000000094,76.70099894246339,0.1767503465813518,-3.227290239896723
716.6000000000095,76.81256869041412,0.17686041964635368,-3.2288399179289744
717.7000000000095,76.92455439863052,0.1755248675328016,-3.229856117162132
718.8000000000095,77.0358481696656,0.17304548948158693,-3.2304800783681342
719.9000000000095,77.14863585603572,0.1750660855926116,-3.231799999575819
721.0000000000095,77.25946110786967,0.17352408873803005,-3.230476457216559
722.1000000000096,77.37093953757461,0.17226780505115347,-3.2305021060764236
723.2000000000096,77.48296714397516,0.172640816000601,-3.2316367707938696
724.3000000000096,77.59516984798813,0.1727205563877534,-3.2309204470584927
725.4000000000096,77.70584221747227,0.17198553051070076,-3.2295311512696125
726.5000000000097,77.8166398310089,0.1719414679441933,-3.2321302490491544
727.6000000000097,77.92782863363622,0.1696982226616628,-3.232130258951799
728.7000000000096,78.0383562726505,0.1679378447315818,-3.23310971441589
729.8000000000096,78.15071457017345,0.17123362577810486,-3.2335971930975096
730.9000000000096,78.2616724201649,0.16737636945256673,-3.233112243411482
732.0000000000097,78.37311856555996,0.16336469785441965,-3.234742957230028
733.1000000000097,78.484913979416,0.16766994284456316,-3.233426017507565
734.2000000000097,78.59588962132864,0.1618935387855982,-3.234216030942523
735.3000000000097,78.70685062110319,0.16259491199023435,-3.2360687716821213
736.4000000000098,78.81780533532378,0.1651283222538671,-3.2347608662699683
737.5000000000098,78.92850603128028,0.16385980098623776,-3.2347599929915445
738.6000000000098,79.04072872913487,0.15927236325598315,-3.2351521988892444
739.7000000000098,79.15117729533785,0.1629620443517079,-3.2360800850993545
740.8000000000098,79.26288241006772,0.16380232881037005,-3.23608008821279
741.9000000000099,79.37448984843483,0.16106463351460798,-3.237041996705963
743.0000000000099,79.48533826580909,0.16112119188783014,-3.2374001783813706
744.1000000000099,79.59677039156905,0.15836892007536485,-3.23675517699495
745.2000000000098,79.7091638539801,0.16413876268077998,-3.2377007069882424
746.3000000000098,79.81948859988502,0.15723668482294095,-3.23672808024056
747.4000000000099,79.93163551958465,0.15884419288099294,-3.2380488585524554
747.9000000000099,79.98222839515019,0.16082972026411757,-3.2380498911470497