File: 01_Data/Vinyl_Tile/STA/N2/30K_min/Vinyl_Tile_STA_N2_30KData_220505_R1.csv
##Temp./Â°C,Time/min,DSC/(mW/mg),Mass loss/mg
49.0,10.479391623071074,0.022608713100068956,-0.007825242679493805
50.100000000000016,10.699555382454795,0.07574341040334076,-0.007303426562543791
51.20000000000003,10.82814180594666,0.11417506128924138,-0.006528584371287671
52.30000000000005,10.927828881478142,0.15288698893177155,-0.005982817754151881
53.40000000000006,11.011299730461559,0.1831235633617031,-0.007408408122583587
54.50000000000008,11.084813608747577,0.20980874614842548,-0.00865572214615895
55.600000000000094,11.152985446606976,0.237342813949864,-0.007283721724598458
56.70000000000011,11.217139299660062,0.26121745909371985,-0.006789150977093428
57.800000000000125,11.275463499742438,0.28541100615596526,-0.007408126976821805
58.90000000000014,11.331441818005107,0.30413156086922144,-0.006894444982989079
60.000000000000156,11.385304281759112,0.32263177608261806,-0.006754411991538589
61.10000000000017,11.4369376281842,0.34142844161085506,-0.0067465212219435244
62.20000000000019,11.486346853357508,0.35649610824138245,-0.006300936973849147
63.3000000000002,11.534955299254925,0.37330825794881894,-0.006910269615449494
64.40000000000022,11.58224401137815,0.38662711000372885,-0.007075378431614432
65.50000000000023,11.628488273491373,0.40204152889253825,-0.006659136922310793
66.60000000000025,11.67380644028367,0.4121426126744499,-0.008070810807269346
67.70000000000027,11.719147327059456,0.42211165165056946,-0.007517787597490333
68.80000000000028,11.762596745754292,0.43350793143912747,-0.007531430899283542
69.90000000000029,11.805586421076578,0.44340403741911916,-0.006693985603591024
71.00000000000031,11.84778759945657,0.45376702147921744,-0.007514241021224777
72.10000000000034,11.889978984000978,0.461575551179235,-0.00839342081431571
73.20000000000034,11.93216195906775,0.4728682529734438,-0.008361759723806372
74.30000000000035,11.973206281188824,0.4787902969668806,-0.008218188286013728
75.40000000000038,12.013765179387393,0.4866617921607316,-0.0071138932975376434
76.5000000000004,12.054797701331447,0.49597627327907223,-0.00725082241990993
77.6000000000004,12.094916350450191,0.5040085848051923,-0.007938003371759983
78.70000000000041,12.134854413187902,0.510649986673422,-0.007634194774401415
79.80000000000044,12.174538701447029,0.5173132470725104,-0.007678766563181227
80.90000000000046,12.214519821173438,0.5225636148036539,-0.007295117741044521
82.00000000000047,12.253556062281735,0.530845999602816,-0.007897137921751174
83.10000000000048,12.292341792191213,0.5368363627586121,-0.00823369810925012
84.2000000000005,12.331602298455817,0.5438131888500681,-0.009096360456692487
85.30000000000052,12.37032542297506,0.5481749990293623,-0.009757425846631307
86.40000000000053,12.408519692022146,0.5538652366330203,-0.009602453968983404
87.50000000000054,12.446966221572252,0.5609610160662455,-0.008148719708875873
88.60000000000056,12.484602378742636,0.5658791650382199,-0.008112075925052586
89.70000000000059,12.522578082535553,0.5696975569277022,-0.008110885869117013
90.8000000000006,12.560775768597154,0.5758395351098244,-0.008126288897630118
91.9000000000006,12.598565688629078,0.5814030554613112,-0.0093860958093952
93.00000000000063,12.63622696616268,0.584048778986759,-0.00898309198630809
94.10000000000065,12.673282046016835,0.5884561932241529,-0.009547152371416345
95.20000000000066,12.71082535254522,0.5936084510286556,-0.009548504813617242
96.30000000000067,12.74770352701418,0.5970341431219081,-0.008556785979281223
97.40000000000069,12.784378252510638,0.5997631256097765,-0.009535449504343596
98.50000000000071,12.821641375437716,0.6056418773465444,-0.009541243216638406
99.60000000000072,12.858722258921045,0.6084865652897541,-0.008205030260928226
100.70000000000073,12.895898238019702,0.6144492535407767,-0.009575991867243339
101.80000000000075,12.932469144680573,0.6164159282351439,-0.009532521173092334
102.90000000000077,12.969709620149706,0.618527452000533,-0.008700010702932914
104.00000000000078,13.007044105671424,0.6236631170278771,-0.009539718451997636
105.10000000000079,13.043975261726493,0.6283850566069162,-0.00953175499552561
106.20000000000081,13.080651112748617,0.6316476317284504,-0.009517935142659084
107.30000000000084,13.117472781770507,0.6351457592186648,-0.009540451393860394
108.40000000000084,13.153963104049394,0.6375909052374537,-0.009946672884487029
109.50000000000085,13.1909643670697,0.6404109488317075,-0.009540277438278899
110.60000000000088,13.227657622765465,0.645944346842345,-0.00953992448675045
111.7000000000009,13.264775100898744,0.647359018460453,-0.010895816838072836
112.8000000000009,13.302122110028758,0.6523861063069412,-0.010540869626551874
113.90000000000092,13.338887332310657,0.6574387318494894,-0.010900291703100251
115.00000000000094,13.374629745133106,0.6595901259446083,-0.010859241694295196
116.10000000000096,13.411198403956096,0.6633817333553818,-0.009565860381036906
117.20000000000097,13.447833652379352,0.6659387047372515,-0.010851186233010957
118.30000000000098,13.484165828682858,0.6680625851363384,-0.010856672109728738
119.400000000001,13.521397376800326,0.6728419464772625,-0.009545990958293338
120.50000000000102,13.557603231767835,0.6769960888273774,-0.009539852979977503
121.60000000000103,13.593912603155895,0.6764756573969068,-0.009526125433322541
122.70000000000104,13.630280712763154,0.6805360915346592,-0.010860896239788254
123.80000000000106,13.666849328908704,0.6822026430222502,-0.010859843103147249
124.90000000000109,13.70261849358425,0.6859238875378565,-0.010861802399293019
126.0000000000011,13.73899769332332,0.6879923464425468,-0.012153902309626652
127.1000000000011,13.775118819739362,0.6893871344396957,-0.01190055349272523
128.20000000000113,13.811040429719377,0.6926330817685843,-0.010860396581343412
129.30000000000115,13.847032501246803,0.6956672244624579,-0.010811007246712911
130.40000000000117,13.883129846476344,0.6965720008875198,-0.011854945856501597
131.50000000000117,13.918798527310924,0.6986539849837529,-0.011850164027545684
132.6000000000012,13.954315220319389,0.7009753629529961,-0.011780956379707774
133.7000000000012,13.990275640190417,0.7053651186992849,-0.01084390826158188
134.8000000000012,14.025844849224498,0.7080962101159809,-0.012173297340705158
135.90000000000123,14.061388924106481,0.7099667021512914,-0.012170080704430042
137.00000000000125,14.0970201639253,0.7114432428501952,-0.012170082005104277
138.10000000000127,14.132709296066913,0.7144075616276797,-0.012170058355310598
139.2000000000013,14.16826624295251,0.7149707860232098,-0.01218578401011472
140.3000000000013,14.203327681279783,0.7202375271079098,-0.013491662034065932
141.4000000000013,14.238361567509099,0.7236969381018538,-0.01349007555645132
142.50000000000134,14.273661296439755,0.7252695972405774,-0.012949832920798432
143.60000000000133,14.308595277594891,0.7283793105830759,-0.01249911592263242
144.70000000000135,14.343863578715235,0.7314655921090608,-0.012157496308120574
145.80000000000138,14.379118761036613,0.7344121208234693,-0.013548499026832861
146.9000000000014,14.414323832317875,0.7374906931910339,-0.013489944264248432
148.00000000000142,14.448885546015681,0.7371873510411235,-0.013489987993080543
149.10000000000142,14.484153836959274,0.737528591509064,-0.013490846388636513
150.20000000000144,14.519005270807263,0.7436320605273105,-0.012168032087940706
151.30000000000146,14.553520050375264,0.7455081851787098,-0.012179951435467906
152.40000000000146,14.588633217240455,0.7486504512809511,-0.01217992827985137
153.50000000000148,14.623219153222689,0.748384292094349,-0.012180311343545469
154.6000000000015,14.657978902863006,0.7519271309801637,-0.013477080535968078
155.70000000000152,14.69235257834338,0.7520885337534557,-0.013489940153957214
156.80000000000155,14.727451853790269,0.756077775420049,-0.013489922926324116
157.90000000000154,14.761942925978518,0.7599389522456156,-0.013489954373831381
159.00000000000156,14.796832401482993,0.7607180110643889,-0.013494857112234193
160.1000000000016,14.831637564451041,0.7638389353902773,-0.014149531387171788
161.20000000000158,14.865783406061514,0.76516719385585,-0.014155242816454194
162.3000000000016,14.900119801548168,0.7681902299630397,-0.014803617192535867
163.40000000000163,14.93474915897905,0.7707471404564445,-0.014809928011846107
164.50000000000165,14.969192139001514,0.772520653576021,-0.014809922997577996
165.60000000000167,15.003841310401793,0.774666714082496,-0.014809922776127138
166.70000000000167,15.038173627782687,0.7796587305542572,-0.014810471990278629
167.8000000000017,15.072797058456553,0.7836955951216998,-0.015796054138701443
168.9000000000017,15.106969964934802,0.7846335293125231,-0.016131244247163057
170.0000000000017,15.141101219295425,0.7852848039326101,-0.015445330042680006
171.10000000000173,15.1755095454389,0.7889775043146025,-0.015469905439395859
172.20000000000175,15.209718604629963,0.7912314104344231,-0.015469876970048091
173.30000000000177,15.243943323862522,0.796189418655195,-0.015469877000019228
174.4000000000018,15.278069169454401,0.7966998935237438,-0.015469877000001464
175.5000000000018,15.311888564455947,0.8015252976622184,-0.015469877000465981
176.6000000000018,15.346289794700747,0.8026225279451855,-0.015469874715733578
177.70000000000184,15.380499669729033,0.8054449481995907,-0.015472824986853428
178.80000000000183,15.414592834422631,0.8077686319247537,-0.016439054252684215
179.90000000000185,15.44859597300842,0.8111346302945287,-0.017447737368895933
181.00000000000188,15.48260613040349,0.8135401149921768,-0.017439941267289427
182.1000000000019,15.516631823053919,0.817640843095489,-0.017439946004327744
183.20000000000192,15.550621545263672,0.8207644896755768,-0.017439947488401497
184.30000000000192,15.584244530789556,0.8234629428973628,-0.017430818967851813
185.40000000000194,15.61783961678379,0.8269670949756144,-0.01776948896712849
186.50000000000196,15.651547538526117,0.8283403575760768,-0.017769946707646422
187.60000000000196,15.685453446519126,0.8287728285838312,-0.017769962412108153
188.70000000000198,15.71874491728656,0.8338488977117082,-0.017756939951801165
189.800000000002,15.752753578383881,0.8343812779204094,-0.019084152922674846
190.90000000000202,15.78675352549753,0.8384784259805689,-0.019089952883143635
192.00000000000205,15.820168844143002,0.8418244130135866,-0.019089946020975468
193.10000000000204,15.853782358847463,0.8448050014134285,-0.019089922824562233
194.20000000000206,15.887548637491893,0.8441754573388207,-0.019106908651719934
195.3000000000021,15.921306102839981,0.8488979340186207,-0.018064916842935652
196.40000000000208,15.954753983452127,0.8512459944111577,-0.018425871079338574
197.5000000000021,15.988444688425655,0.8530144145410015,-0.019790229977324714
198.60000000000213,16.02202083263581,0.8564081034180011,-0.01974085437158246
199.70000000000215,16.05542699350449,0.861634965177042,-0.020952954055476702
200.80000000000217,16.088661074696944,0.8600307043771728,-0.022420110700734686
201.90000000000217,16.122407508131122,0.8641773518198548,-0.022380081290755083
203.0000000000022,16.15584835857887,0.8682194210962495,-0.022380127975128783
204.1000000000022,16.18953911632155,0.870740725312293,-0.0223801895611353
205.2000000000022,16.22292247403642,0.8704998736023156,-0.022331033879001705
206.30000000000223,16.25650768259881,0.8754115722134101,-0.023692421226535476
207.40000000000225,16.289690907634256,0.8769040205992982,-0.023690185408245856
208.50000000000227,16.323410597928614,0.878310271115057,-0.023694075958526017
209.6000000000023,16.35652852324811,0.8805179761731067,-0.02501870399258399
210.7000000000023,16.39039734309038,0.8849091244991321,-0.025012761057257915
211.8000000000023,16.423277581538205,0.8867868651138338,-0.026338521137836413
212.90000000000234,16.456948356492013,0.8890808168698405,-0.026329968727142106
214.00000000000233,16.490395096701274,0.893755384667124,-0.026329897589455253
215.10000000000235,16.523664140960015,0.8940623923073233,-0.026559124511398746
216.20000000000238,16.556878910830743,0.8997765615069375,-0.0276414039739028
217.3000000000024,16.590480227156544,0.899088215316295,-0.02888850761779782
218.40000000000242,16.623906227003392,0.9001993702658759,-0.02895222123239538
219.50000000000242,16.657416474290628,0.9047334912036065,-0.030207162166457024
220.60000000000244,16.690346474281895,0.9058262611379766,-0.031590289817499784
221.70000000000246,16.723842240296225,0.9075230291568503,-0.032096568425824756
222.80000000000246,16.757353560898835,0.9106454489638977,-0.03288835579442839
223.90000000000248,16.790194653802033,0.9112480280415858,-0.03314494458045303
225.0000000000025,16.824031071333323,0.9135046987869028,-0.03416921059650946
226.10000000000252,16.857230240814957,0.9149663006870037,-0.034230066736502085
227.20000000000255,16.890635402936592,0.9193790509878462,-0.036503778032157985
228.30000000000254,16.92357306102143,0.9197954496797552,-0.037005585210203584
229.40000000000256,16.95719689205399,0.9235596612926085,-0.037836844847927154
230.5000000000026,16.990367515428705,0.9281825983079645,-0.03917006965517267
231.60000000000258,17.023901019067157,0.9310443017205345,-0.03965968343519588
232.7000000000026,17.056750213899626,0.9337148964770149,-0.040774990213176654
233.80000000000263,17.09030321068199,0.935809548711789,-0.04206975906841803
234.90000000000265,17.12342890013675,0.9398687154333389,-0.043538515385858734
236.00000000000267,17.156793799316084,0.9417747648014669,-0.04488669018894065
237.10000000000267,17.190215951918137,0.9488885264995371,-0.04639438853456701
238.2000000000027,17.223462173254546,0.9508234881253022,-0.04799403467819596
239.3000000000027,17.256720806111193,0.9566837405992672,-0.04978283793895821
240.4000000000027,17.28975453287532,0.9606275992040312,-0.05095302766674692
241.50000000000273,17.32311183849729,0.9628196897951754,-0.05238082134998612
242.60000000000275,17.35628524604913,0.9661825949715279,-0.054025462193433516
243.70000000000277,17.389687314173848,0.9720307023951437,-0.05557218222623783
244.8000000000028,17.422625547824556,0.9741447671912666,-0.058091581121179736
245.9000000000028,17.455874482336622,0.97928679624532,-0.06124655221125508
247.0000000000028,17.4891832743951,0.9837147205311646,-0.06442270378754822
248.10000000000284,17.522513545571208,0.9885809033916845,-0.06631462708236091
249.20000000000283,17.55557267769654,0.9898029943498186,-0.06810973937678622
250.30000000000285,17.588802684293235,0.9967499538746241,-0.07129026041837827
251.40000000000288,17.622173935258903,1.0008150994204548,-0.0736035305097551
252.5000000000029,17.655171079810895,1.0019667145823878,-0.07522076518328635
253.60000000000292,17.688679839318628,1.006491765283645,-0.07817898010203317
254.70000000000292,17.72179607679254,1.009750807218208,-0.08084563093693697
255.80000000000294,17.755015665017744,1.0156921911269725,-0.08452555496997194
256.90000000000293,17.78811742495696,1.0170789545974277,-0.08650489884976098
258.00000000000296,17.821424791820032,1.0212487875279885,-0.09122042762302662
259.100000000003,17.854415724069433,1.0291604512504902,-0.09394548113632695
260.200000000003,17.88781635992609,1.0330600604855738,-0.09712975642922039
261.300000000003,17.920703536091356,1.0378117766592638,-0.10108891976257439
262.40000000000305,17.95417222472295,1.0432942668470355,-0.10471170227308013
263.50000000000307,17.987032308455433,1.0484288300733682,-0.10841858973632545
264.6000000000031,18.020467188099996,1.051914976487176,-0.11338074681150934
265.7000000000031,18.053458030537335,1.0566149641756803,-0.11714372775524717
266.8000000000031,18.086726367098336,1.0626497333588982,-0.12234671370695738
267.9000000000031,18.120100084381583,1.0638250773460274,-0.12627783592735797
269.0000000000031,18.15284546730188,1.0683999691286736,-0.130171801809285
270.10000000000315,18.18652746329738,1.0744074204051692,-0.1349720224880664
271.2000000000032,18.219662421476826,1.077679947649951,-0.1399910329175511
272.30000000000314,18.252680830878045,1.0792551194443278,-0.14465846046652375
273.40000000000316,18.285924065253756,1.0821260529907295,-0.14948455162547747
274.5000000000032,18.319066082213215,1.0851274261288566,-0.15440780068694027
275.6000000000032,18.352170781032562,1.0868760851082353,-0.16009508311073484
276.70000000000323,18.38538518125353,1.086768135962359,-0.16545281006778856
277.80000000000325,18.41830027405205,1.089392485583133,-0.1708863042282025
278.9000000000033,18.451970858066044,1.0894200339375852,-0.17586259650257707
280.0000000000033,18.4850000000001,1.0866126098871054,-0.18186016700001817
281.1000000000033,18.518179829479347,1.0891806152021288,-0.18949822104802516
282.20000000000334,18.551265500563396,1.0850014342958927,-0.19572287808960054
283.30000000000337,18.584788247790616,1.0854719132806856,-0.20144985402031557
284.40000000000333,18.617988026363406,1.082351579477021,-0.20875349698926415
285.50000000000335,18.651328440383853,1.0806316509109422,-0.2151543430856795
286.6000000000034,18.684346760918707,1.0809345033735107,-0.2219031855449125
287.7000000000034,18.71765453938672,1.0736667669523192,-0.22958442344765606
288.8000000000034,18.750823779122502,1.0680934566722025,-0.2369164069606975
289.9000000000034,18.784134990712673,1.0640965745588025,-0.2443957769260714
291.0000000000034,18.8174604450396,1.0595322595826526,-0.2540852752945413
292.10000000000343,18.850666169006907,1.055806064376713,-0.26215002574782487
293.20000000000346,18.88355125961528,1.053214265454534,-0.2717358788540998
294.3000000000035,18.91707386411568,1.0481463365640316,-0.28116819566883944
295.4000000000035,18.950076687366824,1.0496969275668775,-0.29089252742773963
296.5000000000035,18.983474048152544,1.0526105030670803,-0.30070452734029596
297.60000000000355,19.016510139629496,1.0563694581103558,-0.3122631422930402
298.70000000000357,19.049974766004386,1.067024025602698,-0.32302971233518996
299.8000000000036,19.083090799781406,1.0820339000647152,-0.3345858254068532
300.9000000000036,19.116773499577945,1.1019110503850764,-0.347654161750623
302.0000000000036,19.14961328143096,1.1270767828580994,-0.36111174669875545
303.1000000000036,19.182980881624978,1.155540713366682,-0.3750058100596503
304.2000000000036,19.21644736816966,1.1864337961153335,-0.38973825889296787
305.30000000000365,19.250000096203994,1.2195451790883658,-0.40092592861262455
306.4000000000037,19.28356302521292,1.2521670358372756,-0.4154863834763165
307.5000000000037,19.31636875633919,1.2849572544009125,-0.4284120131276121
308.60000000000366,19.350101379312083,1.313774851244852,-0.4441530566637688
309.7000000000037,19.3834158226724,1.3424203274306923,-0.4567105532060669
310.8000000000037,19.41650568520976,1.3620507302008,-0.47027146966750566
311.90000000000373,19.4500459599427,1.3779913438181717,-0.4850761033659694
313.00000000000375,19.483320873831484,1.3875475434460385,-0.49863206695119633
314.1000000000038,19.516797641529248,1.3912259707133365,-0.5100277988376258
315.2000000000038,19.550414428263604,1.3898813306326183,-0.5226776023505
316.3000000000038,19.583760322601545,1.3821973686275117,-0.533173065807619
317.40000000000384,19.61705991979986,1.3708522567482324,-0.5448640651848469
318.5000000000038,19.650785253139247,1.3566997074020255,-0.55469151493718
319.60000000000383,19.68406347912337,1.3374455884324161,-0.5641583180411645
320.70000000000385,19.717672058469724,1.3136339232538472,-0.573147929689831
321.8000000000039,19.75087220896895,1.2915278114396753,-0.583368781055206
322.9000000000039,19.784208404257217,1.2658919969504496,-0.5904433570531262
324.0000000000039,19.81765095442602,1.235765809944451,-0.5980349834117931
325.10000000000394,19.850745611938304,1.211689434571317,-0.6048357740658394
326.2000000000039,19.884274654881526,1.1898245016389648,-0.6109854511993844
327.30000000000393,19.917724462363058,1.1616937458205756,-0.6154623926692162
328.40000000000396,19.951077477306487,1.1386196982781625,-0.6214169032546066
329.500000000004,19.984787573248372,1.1172123826364029,-0.6263917774259524
330.600000000004,20.018154327016177,1.0914702754428216,-0.6314121053565316
331.700000000004,20.051669699572347,1.0737723511431332,-0.6370635985233957
332.80000000000405,20.084695204430044,1.052383152714031,-0.641518928034245
333.90000000000407,20.118451220201056,1.0358336616325974,-0.64606058552401
335.0000000000041,20.151670000000113,1.0171668906521143,-0.6501098029999972
336.10000000000406,20.185571473379426,1.0031179081839947,-0.6538294067311043
337.2000000000041,20.218585267732585,0.98698306584739,-0.6571595445801268
338.3000000000041,20.252207313890995,0.9736664586920136,-0.6603333914034524
339.4000000000041,20.28549526082942,0.9608664343751725,-0.6640134560591879
340.50000000000415,20.319222348672508,0.9474556711008282,-0.6669825508262117
341.6000000000042,20.35294423479542,0.937533997910458,-0.6702328016699428
342.7000000000042,20.38636186667187,0.9289749749516498,-0.6739898443935033
343.80000000000416,20.419995539355906,0.9168267896039034,-0.6764044137420893
344.9000000000042,20.45320329246919,0.9102976674789671,-0.6776447304582489
346.0000000000042,20.486667132146657,0.9012905704474515,-0.680444323693961
347.10000000000423,20.520428094661735,0.89331984208403,-0.6823725839380517
348.20000000000425,20.554137281637814,0.887391350242517,-0.6852742904254145
349.3000000000043,20.58773207350255,0.8808823630574181,-0.6863761819485736
350.4000000000043,20.621054653622245,0.8733584179037874,-0.6885370934125041
351.5000000000043,20.654776893654656,0.8656478500434128,-0.6902871731691484
352.60000000000434,20.68885454782425,0.8620530659642928,-0.6917589461309848
353.7000000000043,20.722256415273993,0.8535619820573177,-0.6935020673316892
354.80000000000433,20.755962562127063,0.8482058623809348,-0.6949384687985072
355.90000000000435,20.7896124178949,0.8451508706881413,-0.6964989808530238
357.0000000000044,20.823130302500537,0.8374724457359849,-0.6989490366487834
358.1000000000044,20.856956514760522,0.8339874224685941,-0.7002626305575936
359.2000000000044,20.890348705122555,0.8291621267475449,-0.7007123409703824
360.30000000000445,20.92426485454528,0.825917148095618,-0.7023255550124117
361.4000000000044,20.958173869927883,0.822705216458945,-0.7033094666767812
362.50000000000443,20.991733719052238,0.8170988320183264,-0.7046194872994662
363.60000000000446,21.02544304364751,0.8146416057365394,-0.7053347487642836
364.7000000000045,21.059444404677794,0.8111633578453493,-0.7060047215678749
365.8000000000045,21.092941240784977,0.8103973474921033,-0.7072595436831115
366.9000000000045,21.127006185357494,0.8071769135220861,-0.7081609680005361
368.00000000000455,21.160857174495888,0.8047061494157073,-0.7085681109028061
369.10000000000457,21.194136130627374,0.8012627957866286,-0.7072584165291742
370.2000000000046,21.228287444878404,0.7951246553015572,-0.7086681677877964
371.30000000000456,21.261956324000863,0.7941316452127805,-0.7102308236696837
372.4000000000046,21.29595659576724,0.7891609634428011,-0.7103683749065457
373.5000000000046,21.330054078682494,0.7814812914403546,-0.7115271830967256
374.6000000000046,21.36375941211559,0.7710153628427051,-0.7128685953126408
375.70000000000465,21.397904680216673,0.7635033673441826,-0.712849449914911
376.8000000000047,21.43167030747395,0.7501577581496889,-0.7141600033018172
377.9000000000047,21.465519308039436,0.7407677225548838,-0.7145356280699664
379.00000000000466,21.49943602725927,0.7339721371921839,-0.7154799027994843
380.1000000000047,21.533387956704214,0.7271994914928902,-0.7159753139938161
381.2000000000047,21.56718355856551,0.7256423181651815,-0.7167905297056967
382.30000000000473,21.60109965644385,0.7249007185352948,-0.7177853944531605
383.40000000000475,21.63530648581403,0.7277675854862825,-0.7180923250798648
384.5000000000048,21.669238539388957,0.7290072290858932,-0.7194260525664111
385.6000000000048,21.70325757580697,0.7309011373366883,-0.7198748697674446
386.7000000000048,21.737225502353574,0.7339626681812899,-0.7207431944201161
387.80000000000484,21.77120006322337,0.7345187663854702,-0.7220830392663986
388.9000000000048,21.80549990837351,0.7357535807795896,-0.7207630950885968
390.00000000000483,21.83932922363514,0.7376736938459046,-0.7220709031365091
391.10000000000485,21.87345366014928,0.740645459565698,-0.7227009644219793
392.2000000000049,21.907612840123793,0.7421886430932421,-0.724679961208146
393.3000000000049,21.941415900990467,0.7452476777873299,-0.7260070232071931
394.4000000000049,21.975584356063468,0.7522341942491951,-0.7271278765312776
395.50000000000495,22.00988467036431,0.7538538104734746,-0.727319897145545
396.6000000000049,22.044090494732128,0.757631063397285,-0.7266686694834892
397.70000000000493,22.078205575810593,0.7623187171452022,-0.7273309521777778
398.80000000000496,22.11243160846769,0.7677404540113565,-0.72732600528883
399.900000000005,22.146573081507263,0.7728219829400378,-0.728645468002282
401.000000000005,22.180720769780578,0.7795743860317139,-0.7287245858723614
402.100000000005,22.215001868673603,0.7862831803104723,-0.7312704282318507
403.20000000000505,22.249275919437018,0.7933930240955549,-0.7312703104856757
404.30000000000507,22.283392108172976,0.803128032584354,-0.7321113347129029
405.4000000000051,22.317985864762345,0.8119206946303481,-0.7325968392383766
406.50000000000506,22.352082381103994,0.818499204919816,-0.7325692531203742
407.6000000000051,22.386356376027035,0.8282746280445423,-0.7339265587207318
408.7000000000051,22.420633407532392,0.836873642643034,-0.735224313570912
409.8000000000051,22.455045019124853,0.8422116714232262,-0.7353340675549065
410.90000000000515,22.48889591995152,0.8488457592165652,-0.7365409548814759
412.0000000000052,22.523223925765606,0.857613862999453,-0.7367338660007166
413.1000000000052,22.557598414622433,0.8641409192828027,-0.7378506939189062
414.20000000000516,22.59213918982646,0.8692548017939822,-0.7391881593504404
415.3000000000052,22.626588826492423,0.8733560633995664,-0.7400284194808844
416.4000000000052,22.660742592477135,0.8841000837234178,-0.7410438296427633
417.50000000000523,22.695289161914495,0.8886816883098092,-0.7426503497395669
418.60000000000525,22.729841996999426,0.891431433981236,-0.7434015762982407
419.7000000000053,22.76426621516798,0.8937174577188856,-0.744759018244955
420.8000000000053,22.79872933147715,0.900945686285977,-0.7460751250065698
421.9000000000053,22.833050647076345,0.9048771103769938,-0.7460865183709546
423.00000000000534,22.867828603790425,0.914423127396134,-0.7473876914296498
424.1000000000053,22.90198704866234,0.9152555156199421,-0.7480794779908164
425.20000000000533,22.93631135226198,0.9220364631697567,-0.7488205606731002
426.30000000000535,22.971107695922832,0.9268263723098119,-0.7501096433386332
427.4000000000054,23.005597811129682,0.9332656037824881,-0.7508748328708554
428.5000000000054,23.0401791067687,0.9351437708842443,-0.7519635315260214
429.6000000000054,23.074587451281673,0.9409655880016273,-0.7554165905626498
430.70000000000545,23.109171007349243,0.9471859627326922,-0.7571285516351614
431.8000000000054,23.143702685039443,0.9501138239245459,-0.7586216607546814
432.90000000000543,23.178168165238866,0.9558053975947189,-0.7593382667946811
434.00000000000546,23.2131406857714,0.960434215653228,-0.7609767584631455
435.1000000000055,23.247465457117297,0.9629046353791726,-0.7631561936283013
436.2000000000055,23.281831954168716,0.9697106224468709,-0.7643052569685547
437.3000000000055,23.31659611793387,0.9743904112275383,-0.7652863408968842
438.40000000000555,23.351191844235633,0.9795150374454635,-0.7661454892789785
439.50000000000557,23.385869358184628,0.9848161650030629,-0.767673540604914
440.6000000000056,23.420263729771925,0.986485230988564,-0.7691136470799287
441.70000000000556,23.45490975920881,0.9936020182077834,-0.7706651719907529
442.8000000000056,23.489921549646702,0.998896984292168,-0.7727628845992087
443.9000000000056,23.524355773857252,1.006165017901842,-0.7769103310032985
445.0000000000056,23.558975146270328,1.0144801792672364,-0.7784266245244891
446.10000000000565,23.59356908110852,1.0192610111848492,-0.7800302850761862
447.2000000000057,23.628477652943644,1.02647835428521,-0.7822307637191654
448.3000000000057,23.663196255036326,1.0313129711389033,-0.7847185633529699
449.40000000000566,23.697644334365613,1.041189162210704,-0.7865600214679085
450.5000000000057,23.732620381571365,1.047494817525109,-0.7892410034602881
451.6000000000057,23.767407906752233,1.0541853985636835,-0.791970836722236
452.70000000000573,23.802031036447655,1.0639270194347428,-0.7954790455312972
453.80000000000575,23.836656408233672,1.0705832372388226,-0.7984958969218869
454.9000000000058,23.87206095690704,1.0847451978878477,-0.8009227048728609
456.0000000000058,23.90641910151605,1.089794794200645,-0.8025123039325455
457.1000000000058,23.941148775780277,1.1020803117601499,-0.8055559787778361
458.20000000000584,23.976106252784952,1.1135000295871744,-0.8091447305192316
459.3000000000058,24.01081223912737,1.1246454061576778,-0.8127489399029737
460.40000000000583,24.045867363748858,1.1339669883087171,-0.8155873749122171
461.50000000000585,24.080508067977622,1.1474178932335732,-0.8211031175226484
462.6000000000059,24.115515679122808,1.159887977945432,-0.8253481498476889
463.7000000000059,24.15040704252467,1.1727067658215629,-0.8290003456865609
464.8000000000059,24.184969779362703,1.1894583718150673,-0.8329582558414828
465.90000000000595,24.220169795794867,1.2032783519239854,-0.8365000116610988
467.0000000000059,24.25496638428042,1.216607806598906,-0.8402406750468892
468.10000000000593,24.289624323194236,1.2358018199915208,-0.8451152668589041
469.20000000000596,24.32426796988628,1.249471499872724,-0.8486814495512829
470.300000000006,24.359386036043244,1.2649694519121666,-0.8528300295600628
471.400000000006,24.394422706874074,1.2818562183703075,-0.8580490159102991
472.500000000006,24.42944600786775,1.2975862906866535,-0.8620494958385314
473.60000000000605,24.464411227553914,1.3136205525988058,-0.8665921985403906
474.70000000000607,24.4992222016493,1.327971505863189,-0.8706717910307771
475.8000000000061,24.534365846965393,1.3414130103416577,-0.8752607870950397
476.90000000000606,24.56932626665589,1.3569082223081201,-0.8801803892792108
478.0000000000061,24.604834456113046,1.373609456699,-0.8843716665565395
479.1000000000061,24.639978570696115,1.3853976744964915,-0.8888816569866305
480.2000000000061,24.674904031084385,1.3987520331093584,-0.8933888419324032
481.30000000000615,24.71004842088605,1.4145752033408954,-0.8980648867583749
482.4000000000062,24.745219107910536,1.4252181432178725,-0.901988364432238
483.5000000000062,24.78005478735922,1.4423899917303307,-0.9057205898436926
484.60000000000616,24.815317121053184,1.4513459562081739,-0.9102844172454558
485.7000000000062,24.850652349538002,1.4662389309126114,-0.9153431550075748
486.8000000000062,24.885721655702646,1.4777791583443476,-0.9186532155257554
487.90000000000623,24.920356190870514,1.4926798423397656,-0.9235304566385212
489.00000000000625,24.955585923322914,1.5072548221461524,-0.9260793779618433
490.1000000000063,24.99096468023326,1.5174507828580186,-0.9295318806716475
491.2000000000063,25.025819632550853,1.5299122860086845,-0.9331407133713268
492.3000000000063,25.061168619338446,1.546234072252256,-0.9376776852677957
493.40000000000634,25.096219520986075,1.560490882798415,-0.9422177208056817
494.5000000000063,25.131296445538325,1.5687784018581605,-0.9459643907243844
495.60000000000633,25.166482322608513,1.5862276599048832,-0.9492392518051904
496.70000000000636,25.20175309916303,1.5993712168877101,-0.9515240637689826
497.8000000000064,25.237161566136372,1.614171684726006,-0.9546009887717988
498.9000000000064,25.272324677378432,1.6297394101109957,-0.9585959372218493
500.0000000000064,25.307472106530987,1.6433053171348533,-0.9611884339491192
501.10000000000645,25.34253162419764,1.6599712446634638,-0.9643981143122851
502.2000000000064,25.378004751508556,1.676366454807273,-0.9679715806089066
503.30000000000643,25.41317851143655,1.6887738744950627,-0.9691973305986714
504.40000000000646,25.448396798286375,1.7078483148632708,-0.9719899267676255
505.5000000000065,25.48347111168529,1.7183639439417893,-0.9739216510885056
506.6000000000065,25.51894773550164,1.737369677145907,-0.9781743528196616
507.7000000000065,25.55415414002863,1.7513421863325098,-0.9798906007763821
508.80000000000655,25.589247975924774,1.765926297927996,-0.9814227420522004
509.90000000000657,25.62460433364251,1.7805567856242803,-0.9836056334290331
511.0000000000066,25.65988700851975,1.7953636306343888,-0.9864231133761026
512.1000000000065,25.69531099416768,1.8086992394892094,-0.9880806772154256
513.2000000000066,25.73064707423328,1.8242112880025796,-0.9892322989283238
514.3000000000065,25.76588179081412,1.838141521581553,-0.9908398146070496
515.4000000000067,25.801000060477236,1.8504426212100675,-0.9922937578705375
516.5000000000066,25.836417151771908,1.8667100982918914,-0.9940155430931439
517.6000000000067,25.87196461281108,1.875383688602717,-0.9945640206587947
518.7000000000066,25.90739056688529,1.8874315042842174,-0.9965695045155858
519.8000000000067,25.942398615392836,1.9037103245811764,-0.9988816344059268
520.9000000000067,25.978099636621792,1.9165919594454857,-0.9994563140672161
522.0000000000067,26.013327302590714,1.9296464446588781,-1.0007813202471714
523.1000000000067,26.04902108140975,1.943014665781865,-1.0011378246262579
524.2000000000068,26.08421014183886,1.953961461929191,-1.0010958057498716
525.3000000000068,26.11967912538717,1.966519888072745,-1.0025681584035802
526.4000000000068,26.155273946609665,1.9791732230461525,-1.0040875608320645
527.5000000000068,26.190631449094006,1.9942036618613561,-1.005235783859633
528.6000000000068,26.225382637311526,2.003774293458917,-1.006611467562176
529.7000000000069,26.261573491057785,2.020276885557006,-1.007909406327891
530.8000000000068,26.29701060614304,2.032665614583327,-1.0087689393319166
531.9000000000069,26.332372373540036,2.0498136692547932,-1.00925947282472
533.0000000000068,26.367892819284464,2.062011094052565,-1.0107522676439622
534.100000000007,26.40340017176777,2.078095782010689,-1.012788823568977
535.2000000000069,26.438685918631478,2.0939302759515863,-1.0140948455450376
536.300000000007,26.474251762380366,2.1110921248348893,-1.0147141419096268
537.4000000000069,26.50977397443169,2.1315168874318875,-1.0160305349871548
538.5000000000069,26.545290289908635,2.1485952542249596,-1.0160335603983501
539.600000000007,26.58082556224826,2.164754745934022,-1.0175087692434017
540.700000000007,26.616460026675295,2.184161376526662,-1.0191663417230883
541.800000000007,26.652399165815762,2.1968703059381256,-1.0212861347470463
542.900000000007,26.687645100096866,2.2184269513089125,-1.0232691284621223
544.000000000007,26.723132809042895,2.2314906557484706,-1.024757021022194
545.1000000000071,26.758766118248865,2.2484753438392717,-1.026243917943317
546.2000000000071,26.794250707338946,2.2636108434076583,-1.0277978975082185
547.300000000007,26.829862977147958,2.28139561879233,-1.029289851418198
548.4000000000071,26.86581845003692,2.2957682895532567,-1.030642508658084
549.500000000007,26.901124015108287,2.312440817764516,-1.0316006963966982
550.6000000000072,26.936880685060565,2.322667689342053,-1.0332835520960764
551.7000000000071,26.97230299054185,2.335427115158219,-1.035414293142893
552.8000000000072,27.008414810511642,2.345857544235849,-1.0375843367174031
553.9000000000071,27.04366975092322,2.3591908097363063,-1.039116898315184
555.0000000000072,27.079196792998008,2.3686153613001855,-1.0394022855547647
556.1000000000072,27.11523876456195,2.379893443415742,-1.0410141779416628
557.2000000000072,27.15094165245609,2.3916152420287333,-1.0429470073743596
558.3000000000072,27.186757029111167,2.4015396052075095,-1.0450117224820135
559.4000000000073,27.222276405026747,2.41414972714401,-1.0479474659979235
560.5000000000073,27.258009700905685,2.4283287595606016,-1.0496895310544643
561.6000000000073,27.293769958502356,2.44109765908236,-1.051479944980715
562.7000000000073,27.32938155679719,2.4539212426360884,-1.0539710313050974
563.8000000000073,27.36533234306642,2.467111030098728,-1.0553388812489097
564.9000000000074,27.400942219716935,2.486761276948311,-1.0562435881348358
566.0000000000074,27.436534711049998,2.5062484117990955,-1.057473629304397
567.1000000000074,27.47242242198971,2.52322220887494,-1.059057070523561
568.2000000000073,27.508459050305515,2.5520094491264373,-1.0617291704395386
569.3000000000073,27.54419157426692,2.575712233856252,-1.0636464796127987
570.4000000000074,27.580076260453833,2.6006895359372715,-1.0650893071501688
571.5000000000074,27.615728154418584,2.6236816261107827,-1.0667422819046664
572.6000000000074,27.65167066223115,2.656449505024389,-1.0692201618445512
573.7000000000074,27.687807527601223,2.6808433175316067,-1.0717165014620909
574.8000000000075,27.723168252518388,2.708673154103879,-1.0734340635624884
575.9000000000075,27.75918889121212,2.7399877510654074,-1.0754869013664416
577.0000000000075,27.795281206222683,2.7710847731756445,-1.0777321995979325
578.1000000000075,27.831069796906842,2.804688524508834,-1.0791974723222806
579.2000000000075,27.867065128627672,2.837056175477976,-1.081092242578587
580.3000000000076,27.903158294961198,2.8710959474014213,-1.0832512962305696
581.4000000000076,27.9389681777107,2.907302319473313,-1.08578233500696
582.5000000000076,27.97467564024118,2.94828104072203,-1.0869150042050335
583.6000000000076,28.010671146229942,2.9881903902858094,-1.0888265676976068
584.7000000000077,28.046773703042202,3.0344565405239057,-1.0912762790896529
585.8000000000077,28.083006065252327,3.0833472781713396,-1.0949089921745778
586.9000000000076,28.11875176954633,3.137379670289043,-1.0978505276229642
588.0000000000076,28.15488047026742,3.1917443034748,-1.1009835008194009
589.1000000000076,28.19099136931176,3.2514138106294754,-1.1030085649540888
590.2000000000077,28.226848249931297,3.315923600336512,-1.1052862571480784
591.3000000000077,28.262952972160416,3.379535355706328,-1.1079786327077379
592.4000000000077,28.299170132049795,3.4458396263486133,-1.110266616196943
593.5000000000077,28.335239060775997,3.507316916910243,-1.1128358434131953
594.6000000000078,28.371441664418736,3.563884219895863,-1.1160257022156785
595.7000000000078,28.407594739416208,3.6152905281033556,-1.1190298477041907
596.8000000000078,28.443531334803016,3.656345059121981,-1.121963218595181
597.9000000000078,28.47968134130342,3.669060215423235,-1.1255256913546399
599.0000000000078,28.515990888842207,3.639081556269031,-1.1298405997318905
600.1000000000079,28.551924709841114,3.5583587276818287,-1.1337582335066156
601.2000000000079,28.588187715962587,3.441082736933576,-1.1371043187296226
602.3000000000079,28.624063236381765,3.314392592532106,-1.140320237817507
603.4000000000078,28.659957937218625,3.1928468724006365,-1.1440572654297512
604.5000000000078,28.69599629502125,3.0881817322761718,-1.1478595485300693
605.6000000000079,28.73194583143431,2.999229420055158,-1.1507322477423698
606.7000000000079,28.76800969763303,2.917340749729529,-1.1543750168042974
607.8000000000079,28.804116294927763,2.8499182244199486,-1.1571393902740872
608.9000000000079,28.84018618413975,2.7888142455056206,-1.1591498440091206
610.000000000008,28.87615698451439,2.7399891504267226,-1.1625995284293111
611.100000000008,28.91218153808952,2.7022695810192694,-1.1644865396327941
612.200000000008,28.948061558418495,2.6794088285743967,-1.1672661502611166
613.300000000008,28.984209783871986,2.6792797479533412,-1.1703600380972619
614.400000000008,29.020127517358272,2.687364830474615,-1.171880333642204
615.5000000000081,29.05646562589748,2.6905537679239906,-1.173531372521924
616.6000000000081,29.091163717750476,2.6874528633442485,-1.1748482983430253
617.7000000000081,29.12875105551267,2.683201685324472,-1.1746909443624594
618.8000000000081,29.164966126877076,2.679402166410185,-1.1748503814635072
619.9000000000082,29.20089734214818,2.6753937812403636,-1.1762705299361809
621.0000000000082,29.237045146605567,2.675442013593943,-1.1755046055943348
622.1000000000081,29.27318976261783,2.6750893558317648,-1.1765997054824218
623.2000000000081,29.309285436169517,2.6750470985105537,-1.1766010538422398
624.3000000000081,29.34540068186053,2.677783217370597,-1.1779112352725156
625.4000000000082,29.38160697649387,2.682646174362907,-1.179003213106335
626.5000000000082,29.417520109514044,2.690758539781717,-1.1802205293649672
627.6000000000082,29.453674866304993,2.7059670691019875,-1.180361191806412
628.7000000000082,29.489782887986113,2.713998449323258,-1.181539338501592
629.8000000000083,29.526037846786977,2.725906644681012,-1.1815399669342206
630.9000000000083,29.56206801694155,2.741188459197892,-1.1822385817338223
632.0000000000083,29.598330000000264,2.7548014997729426,-1.1828499320000119
633.1000000000083,29.634287220836995,2.771328234914513,-1.1841731712453503
634.2000000000083,29.670546193975966,2.7934083577774356,-1.185496165270648
635.3000000000084,29.706749130475146,2.8120163551223323,-1.1859858288096046
636.4000000000084,29.742996767103975,2.8332155105221535,-1.1864579523114172
637.5000000000084,29.779068258510335,2.851300656699995,-1.187464902740111
638.6000000000083,29.81528833507746,2.8791519140727,-1.1888220966134204
639.7000000000083,29.85119088274495,2.9067359038332796,-1.1890603713991101
640.8000000000084,29.887562749524243,2.9357571302110914,-1.1900872945928325
641.9000000000084,29.923973609850787,2.9652249468744207,-1.1915387513699405
643.0000000000084,29.960082115517217,2.9955301450826686,-1.1930759564963411
644.1000000000084,29.996542893635915,3.0288416266764857,-1.1943242677109285
645.2000000000085,30.032408938194596,3.0633514204978485,-1.1951212733520231
646.3000000000085,30.068792629006193,3.101747216568035,-1.195980419003209
647.4000000000085,30.104999372663357,3.1367789728644047,-1.1988698840740537
648.5000000000085,30.14138264685603,3.174908054227984,-1.2006894457250956
649.6000000000085,30.177757557101152,3.219098490103969,-1.2025552457661806
650.7000000000086,30.21395778759852,3.2616448292132842,-1.2042685363584584
651.8000000000086,30.25026831393692,3.3048284360264706,-1.2067070346623652
652.9000000000086,30.286417803533276,3.3515260518262995,-1.2081719383983343
654.0000000000086,30.322940638416032,3.3993690115963595,-1.2098996529839212
655.1000000000087,30.359280218584352,3.442932675842571,-1.2123598598130032
656.2000000000087,30.395402516505495,3.4881637594255204,-1.2138308251862813
657.3000000000086,30.43186203524431,3.5298552832226644,-1.216120326490545
658.4000000000086,30.468461791524703,3.5780546895984937,-1.2185540744982957
659.5000000000086,30.50503254119291,3.6224029398689725,-1.2208056353270527
660.6000000000087,30.54110440767074,3.6682318407373806,-1.2237520532283064
661.7000000000087,30.577468031298707,3.712249382963525,-1.2268117196241906
662.8000000000087,30.613676331458446,3.7605725187571415,-1.230029694153484
663.9000000000087,30.65004750185662,3.806399964657536,-1.2328446646544475
665.0000000000088,30.68654420562673,3.8513397363548396,-1.2361363266226904
666.1000000000088,30.72293499383539,3.8995895555981184,-1.2386029108245387
667.2000000000088,30.75932044952168,3.95430705634811,-1.24237118974197
668.3000000000088,30.79543599737191,4.010206941645544,-1.24402221205185
669.4000000000088,30.83193242446893,4.062112801864471,-1.2481248405446124
670.5000000000089,30.868160655082896,4.126100549796387,-1.2514706749217717
671.6000000000089,30.90461003793479,4.194886291938441,-1.254760128392289
672.7000000000089,30.94114915185321,4.2654582891176585,-1.2580434315353548
673.8000000000088,30.977324275783957,4.339704631592724,-1.2614002965122015
674.9000000000088,31.01392979244368,4.425436153494741,-1.2658862310693046
676.0000000000089,31.05035202306832,4.517478108620496,-1.270418468792867
677.1000000000089,31.086985617603563,4.617082165337454,-1.2742806566832678
678.2000000000089,31.123414136914207,4.730580174808483,-1.277118487719271
679.3000000000089,31.159862138821108,4.849771868985844,-1.2819041414856764
680.400000000009,31.196440376039963,4.974015160730423,-1.2876719703378114
681.500000000009,31.23305475345949,5.113458390480524,-1.2936779782815906
682.600000000009,31.269305651977295,5.262599070961072,-1.297648084571692
683.700000000009,31.306076858432387,5.423537310651023,-1.3025448505822887
684.800000000009,31.34252295500224,5.586725734111102,-1.3079021449904094
685.9000000000091,31.379133030960613,5.714903117226033,-1.3144281517190177
687.0000000000091,31.416050501306515,5.724843127667544,-1.320382797786464
688.1000000000091,31.45243310833856,5.623756537329997,-1.325067673563256
689.2000000000091,31.489018375139523,5.5360163792014125,-1.3302734155677371
690.3000000000092,31.5251623726562,5.502263811230348,-1.336134835964908
691.4000000000092,31.56156799872019,5.50031651934796,-1.3432789931369191
692.5000000000091,31.598233296611358,5.529603147092697,-1.3497775819805473
693.6000000000091,31.63457304934059,5.577859932294767,-1.3562381862056392
694.7000000000091,31.67120122998672,5.637449968796648,-1.3637809372461924
695.8000000000092,31.707661398043868,5.714144469567222,-1.3714358418330992
696.9000000000092,31.74418054460593,5.787511544554787,-1.3789361215027247
698.0000000000092,31.78071537030052,5.869638131300901,-1.384486513157447
699.1000000000092,31.81712673712571,5.961737285517709,-1.3918483451719696
700.2000000000093,31.853703894230758,6.052605105217746,-1.3988764797854962
701.3000000000093,31.89049648106638,6.149575120261813,-1.4071355710582685
702.4000000000093,31.927015660713135,6.248059472672105,-1.417416356452136
703.5000000000093,31.963802153881044,6.349550269421249,-1.4265996269262686
704.6000000000093,32.00042052431952,6.448540165858034,-1.4351084668182446
705.7000000000094,32.03713696617061,6.555268723651006,-1.4438384208356894
706.8000000000094,32.07369756291225,6.660501959185067,-1.4529837206440783
707.9000000000094,32.11017735917513,6.76600919515167,-1.4620768141918354
709.0000000000093,32.1469347937532,6.87912319407441,-1.471562568410588
710.1000000000093,32.18361720584925,6.989191471295081,-1.4812659687558876
711.2000000000094,32.220322012870824,7.102057731916435,-1.4915790186715396
712.3000000000094,32.257280157156885,7.216529405826169,-1.5024553460907728
713.4000000000094,32.29395039540969,7.329874036816059,-1.5128180659760306
714.5000000000094,32.330739227968785,7.451212655119204,-1.5226435359453379
715.6000000000095,32.367501323722124,7.572765720530072,-1.5349440993425407
716.7000000000095,32.40425459751484,7.692961021321622,-1.5469670825695032
717.8000000000095,32.44076109142202,7.812742575028148,-1.5581356369592885
718.9000000000095,32.477802111039324,7.939783681016505,-1.5700062581908973
720.0000000000095,32.51462469520164,8.064409334533789,-1.5825598361252364
721.1000000000096,32.551259926156106,8.185353293929523,-1.5947923153010848
722.2000000000096,32.58832865395717,8.313626561456806,-1.6061686618619908
723.3000000000096,32.62439740659367,8.43479707347301,-1.6196298569161005
724.4000000000096,32.66128519993189,8.566548164264384,-1.6342735578051042
725.5000000000097,32.69836419519522,8.699152651630687,-1.6483735017614927
726.6000000000097,32.73474227100571,8.827454585401313,-1.6617293891291727
727.7000000000096,32.7719331126374,8.955345385834656,-1.6757927541225808
728.8000000000096,32.80910948098315,9.079782880293134,-1.6914549262915957
729.9000000000096,32.84576556816138,9.204966085010398,-1.7069879487125186
731.0000000000097,32.88273814187827,9.330565193866825,-1.722376221962259
732.1000000000097,32.91960066471021,9.452394546476043,-1.7362303912647539
733.2000000000097,32.9567745512864,9.572960950827381,-1.7524220172784988
734.3000000000097,32.993541358108736,9.68796168499948,-1.7697744999446088
735.4000000000098,33.030497873487256,9.799796876728983,-1.7860905859239038
736.5000000000098,33.067397249326554,9.904297778191912,-1.8025765260244895
737.6000000000098,33.104021917523006,9.998573206301245,-1.8190684487431765
738.7000000000098,33.14106533106389,10.082014824143219,-1.837036179243532
739.8000000000098,33.17810000307376,10.149435133726618,-1.8551202953442525
740.9000000000099,33.21510472155678,10.193979186899906,-1.8715923659489482
742.0000000000099,33.25177025723783,10.216138649789105,-1.8890557360216387
743.1000000000099,33.288823344173274,10.205775335950722,-1.9067601536211067
744.0000000000099,33.31884015532731,10.169683124235187,-1.9199773303112524