File: 01_Data/Vinyl_Tile/STA/N2/30K_min/Vinyl_Tile_STA_N2_30KData_220506_R3.csv
##Temp./Â°C,Time/min,DSC/(mW/mg),Mass loss/mg
49.0,10.407636331962507,0.004162194666708974,-0.018844379470820627
50.30000000000002,10.702787627821667,0.06315677969948497,-0.019946678077710445
51.60000000000004,10.850114429132065,0.11369222098996734,-0.018708876905543903
52.900000000000055,10.961071442786071,0.1549273770580354,-0.018198357043311297
54.200000000000074,11.05408087511121,0.1884672720485172,-0.01798707081153683
55.50000000000009,11.138302732961995,0.2199831269299446,-0.01751977143999639
56.80000000000011,11.212839323477017,0.24973955847196927,-0.016916672579324832
58.10000000000013,11.282907679662678,0.27557906526884246,-0.018730317082152226
59.40000000000015,11.34916029396342,0.300872596439933,-0.01885961958324689
60.700000000000166,11.411188778459476,0.32096736043699936,-0.017544041947277655
62.000000000000185,11.47104693457521,0.3402363680984365,-0.01763076184663781
63.3000000000002,11.528107984642855,0.36004695874106973,-0.01841682655948773
64.60000000000022,11.58446824863275,0.3773802015723546,-0.017618011535665445
65.90000000000023,11.63885119098001,0.39150836506721637,-0.017485244098362607
67.20000000000026,11.692756683100907,0.40534052682861954,-0.017890103234448063
68.50000000000028,11.744733098843831,0.4181171028439712,-0.01791152050972933
69.8000000000003,11.795676117906456,0.4280744389947618,-0.01731958073873674
71.1000000000003,11.846379272037403,0.4422531270161826,-0.01666590046616534
72.40000000000033,11.896371115958539,0.4516370576857417,-0.01582979863157874
73.70000000000036,11.944988473771875,0.4619691681762531,-0.015570629775742972
75.00000000000037,11.993637279659294,0.4706788418391137,-0.016648747186402524
76.30000000000038,12.041984506431088,0.4805514278991343,-0.0175788033251445
77.6000000000004,12.089738070845415,0.49134742592311376,-0.018910802700741414
78.90000000000043,12.13699400629894,0.49696226094190576,-0.019564136521934117
80.20000000000044,12.184132264953654,0.5055076811059298,-0.01869024176653067
81.50000000000045,12.23045741482431,0.5158336107355692,-0.019245079120005393
82.80000000000048,12.27693676778165,0.5213136347702954,-0.018915607428112935
84.1000000000005,12.322800033181078,0.5307029923376189,-0.018963787970230683
85.40000000000052,12.368864078727515,0.5351967633931398,-0.018317869592454628
86.70000000000053,12.41413285541509,0.5436736747740767,-0.0181961822700627
88.00000000000055,12.459786855140782,0.5480290142345253,-0.018312144747844705
89.30000000000058,12.504215968051327,0.5539145262005024,-0.018147958204719927
90.60000000000059,12.548752593031363,0.5613516671855922,-0.01824210860593123
91.9000000000006,12.594024153087481,0.5681253938140208,-0.018325906645666024
93.20000000000063,12.638803853848996,0.5736965835960701,-0.018314061810217552
94.50000000000065,12.682212294628242,0.5757746043013066,-0.018316020041536873
95.80000000000067,12.726202241709048,0.581571196186556,-0.01904051856587241
97.10000000000068,12.770946199849638,0.5864305077010581,-0.01964536912322945
98.4000000000007,12.814810326277135,0.5907492970968071,-0.019841108967314725
99.70000000000073,12.858714709763282,0.5939604647583603,-0.02098123832793064
101.00000000000074,12.902313994429113,0.599877006495476,-0.020389837933205257
102.30000000000075,12.946605197254339,0.6024202847274921,-0.02094111326442505
103.60000000000078,12.990090666364821,0.608735062817556,-0.01963656954344639
104.9000000000008,13.033564601979892,0.6115872179457178,-0.02094632559222287
106.20000000000081,13.077608360534418,0.6164568432714145,-0.01963355512144549
107.50000000000082,13.120836060375835,0.6182442626300734,-0.020948798323308537
108.80000000000085,13.16456802185508,0.6225314475365252,-0.020995732739469197
110.10000000000088,13.208383437499608,0.6298572319607232,-0.020949919598223232
111.40000000000089,13.251405988204484,0.6357771981065811,-0.022316178902515027
112.7000000000009,13.29460182957559,0.6383340777296825,-0.021276543196513842
114.00000000000092,13.337992627583292,0.6409921244289336,-0.021291719453370384
115.30000000000095,13.381586536333392,0.6458665044409881,-0.022258842883990937
116.60000000000096,13.424688376876798,0.6501186363846121,-0.02226009946491203
117.90000000000097,13.4680462755037,0.6528491791212951,-0.022489902400588235
119.200000000001,13.511297450710297,0.6591702555006507,-0.022259399450145878
120.50000000000102,13.55420202333641,0.6615705921954437,-0.022260186231352286
121.80000000000103,13.597110318615252,0.6642622381299557,-0.02226170113780146
123.10000000000105,13.640314340733527,0.669922736347234,-0.020952314490573443
124.40000000000107,13.683059303754163,0.6721971717393873,-0.02194162324301363
125.7000000000011,13.725909981406971,0.6776723298462672,-0.022269236715896312
127.00000000000111,13.768515079021318,0.6799812603035464,-0.023450136190433568
128.30000000000112,13.811265361632639,0.6837604960458424,-0.023583624086389143
129.60000000000116,13.853756437345002,0.6865513785563055,-0.022258865227328783
130.90000000000117,13.896040477167723,0.6893954749763789,-0.02226015229632683
132.20000000000118,13.93770615597409,0.6923883780871051,-0.022263662983174726
133.5000000000012,13.980190344620235,0.6982034198031037,-0.02257653559163053
134.8000000000012,14.022310963555798,0.7009835957013688,-0.02258991781082642
136.10000000000124,14.064394172093152,0.7036300628962964,-0.02258992024530393
137.40000000000126,14.106606441369355,0.7102330523867505,-0.022498365881630455
138.70000000000127,14.148154997942926,0.7113351654435367,-0.02225995924702051
140.0000000000013,14.190260023815673,0.7167564831683215,-0.02225873817713886
141.30000000000132,14.231707254388754,0.7189798272143677,-0.023579931055872194
142.60000000000133,14.273329680362416,0.7231751669687287,-0.024898808081380785
143.90000000000134,14.314791495183448,0.7268343289270996,-0.024803644945739833
145.20000000000135,14.356206388391977,0.729613811042469,-0.023579664848577764
146.5000000000014,14.397950003398105,0.7330118903932471,-0.023579919819165518
147.8000000000014,14.439150703992357,0.7375880136569484,-0.023605181999941216
149.10000000000142,14.480263274936066,0.7415861623259188,-0.02488958260150298
150.40000000000146,14.521528311794887,0.7425330965889361,-0.02488992089300357
151.70000000000147,14.562618023742134,0.7474905139536799,-0.024889926577495558
153.00000000000148,14.603822927244728,0.7509635034873684,-0.02489853318402968
154.3000000000015,14.644950093804395,0.7554121796142357,-0.025879816906386743
155.6000000000015,14.685786773511476,0.7591462088014883,-0.025879925094947964
156.90000000000154,14.727009512830355,0.7628509069770727,-0.025873402861748218
158.20000000000155,14.768023184307271,0.7640463015919825,-0.02457050095009894
159.50000000000156,14.808841157020641,0.7680026274749976,-0.02457019514490444
160.8000000000016,14.849539707677476,0.7746045051897354,-0.024570195126504935
162.10000000000161,14.890002243881394,0.7761205400157087,-0.02457058366349596
163.40000000000163,14.931023695014844,0.7782954981223875,-0.025813169675227066
164.70000000000164,14.971717646554183,0.7845040952449487,-0.02620988850188244
166.00000000000165,15.012566602991058,0.7869717185785842,-0.026215617207011377
167.3000000000017,15.053330000000052,0.7895491659119596,-0.027523735377110725
168.6000000000017,15.093780711861294,0.7941357380693228,-0.027519918605658944
169.9000000000017,15.134463610850418,0.799517887085908,-0.02748881283981408
171.20000000000175,15.17496926001717,0.8028169989275341,-0.02686983015949096
172.50000000000176,15.215760192707098,0.8068944457816951,-0.026917373036487113
173.80000000000177,15.255737555342307,0.8095588607196295,-0.025560479394944657
175.10000000000178,15.296399797076027,0.8165497584033871,-0.025559942172005634
176.4000000000018,15.336873879288726,0.8194760246796323,-0.025559958188255294
177.70000000000184,15.37687771089917,0.8257201789339871,-0.0258395278501391
179.00000000000185,15.416816004447844,0.8288644558714731,-0.02686989492947145
180.30000000000186,15.457328641940814,0.8326453591717989,-0.026869942447566686
181.6000000000019,15.497340069418197,0.8368431992740014,-0.026868115261448722
182.9000000000019,15.537777977366108,0.8417447194586376,-0.028189835812908015
184.20000000000192,15.577462005766135,0.8463224734285866,-0.028189941827938547
185.50000000000193,15.617384057660948,0.8454325757220282,-0.02818965027149467
186.80000000000194,15.656937067770079,0.8509102431525272,-0.028894242960170402
188.10000000000198,15.697082727404604,0.8553466890780659,-0.02883994130843437
189.400000000002,15.736966477592171,0.8585456446583346,-0.02883993378988592
190.700000000002,15.776765677892291,0.8634840828865877,-0.030506785714782048
192.00000000000205,15.816527378058064,0.8674740828311648,-0.03081998772346939
193.30000000000206,15.856384348336764,0.8704258136936175,-0.030820068848555593
194.60000000000207,15.896071801136337,0.8740816722111564,-0.030805323886328395
195.90000000000208,15.935663774089731,0.8776956484908087,-0.03214150429152163
197.2000000000021,15.975242510999605,0.8808278469372504,-0.032139928308054344
198.50000000000213,16.014936559266673,0.8850603915866307,-0.03262400421196521
199.80000000000214,16.054603235855403,0.8892313160509916,-0.03327508024806036
201.10000000000215,16.094136779957072,0.8923280418843038,-0.03211905304766738
202.4000000000022,16.133882864933373,0.8940830943861781,-0.033449554474845655
203.7000000000022,16.173645666302825,0.9008711692172046,-0.03345000989875757
205.00000000000222,16.213204893740215,0.9045368091375012,-0.03345000811670573
206.30000000000223,16.252566254553965,0.9094951821357812,-0.033436546171462744
207.60000000000224,16.291914055157406,0.9129011257585431,-0.0360797571571192
208.90000000000228,16.331522062033457,0.9162813354717454,-0.03739960686267718
210.2000000000023,16.371131171079046,0.9210969980537591,-0.03870454026321468
211.5000000000023,16.41060970712916,0.9263308021247824,-0.03942971988259458
212.80000000000234,16.449703474740208,0.9266606265692715,-0.040030038259286194
214.10000000000235,16.489399894979265,0.9324321657302418,-0.040030757758292346
215.40000000000236,16.52891038444398,0.9362595506460432,-0.041400555341338574
216.70000000000238,16.5684363432631,0.9398163026628977,-0.040019539600755216
218.0000000000024,16.607585694314686,0.9433067912864114,-0.04146268696921673
219.30000000000243,16.647038779384534,0.9477999574484666,-0.04278136491468132
220.60000000000244,16.686609753563413,0.951189521855515,-0.043763720953304386
221.90000000000245,16.725734915992454,0.9520737752886044,-0.04505493761815593
223.2000000000025,16.76549806701462,0.9549793396822035,-0.045942303583917266
224.5000000000025,16.805091684055835,0.9597857170202717,-0.04646213638289609
225.8000000000025,16.844062401798872,0.9595549204119017,-0.04781486861123074
227.10000000000252,16.8835069415168,0.9590442241417894,-0.049115808874546474
228.40000000000254,16.92295899824162,0.9609560960865311,-0.05054839317181514
229.70000000000258,16.96230100201204,0.9613467044659092,-0.051975932481330034
231.0000000000026,17.00135448354901,0.9663610883506273,-0.05340068328541392
232.3000000000026,17.040930188984532,0.966320375378336,-0.05343545940966088
233.60000000000264,17.08048425011466,0.9702721713836417,-0.055235378514591815
234.90000000000265,17.119319591214026,0.9744915136659309,-0.05826146810012034
236.20000000000266,17.158773617597728,0.9761380721146597,-0.059615764776727254
237.50000000000267,17.19827130915553,0.98209923442988,-0.06180362936541428
238.80000000000268,17.23741157590298,0.9828004934451262,-0.06343346523039184
240.10000000000272,17.276621960456698,0.9873686199193866,-0.06477359309817121
241.40000000000273,17.31607360035298,0.9953717304821048,-0.06840898234812176
242.70000000000275,17.355347645860476,0.9997554300527518,-0.07194122067743303
244.00000000000279,17.39467066276727,1.0038484407273764,-0.07350917815085634
245.3000000000028,17.43389266117506,1.0090641074223075,-0.07834721861672511
246.6000000000028,17.473005041241404,1.0122449277498442,-0.07901961190139639
247.90000000000282,17.512758817905258,1.0186359369426914,-0.08203492744492724
249.20000000000283,17.551973104226256,1.024791384768521,-0.08460377419040066
250.50000000000287,17.5908230478738,1.029715265681383,-0.08760846323863802
251.80000000000288,17.63042036939574,1.034853700888058,-0.0907965941902682
253.1000000000029,17.669810444909317,1.042240512685604,-0.09406690701515785
254.40000000000293,17.7088624688618,1.0473295873305843,-0.09720430750573783
255.70000000000294,17.747891229336126,1.050895948750719,-0.10129659189760298
257.00000000000296,17.787518106073605,1.0571147455332626,-0.10548364177800362
258.30000000000297,17.826308074398423,1.062129189092891,-0.11006711610325359
259.600000000003,17.866078510134958,1.0663894745624332,-0.11309041750671067
260.90000000000305,17.905321869438154,1.0775021913372336,-0.11644767447644311
262.200000000003,17.94432469590655,1.0830378185124567,-0.12222612848168746
263.50000000000307,17.983447329007987,1.0921542944277127,-0.1277655341722821
264.8000000000031,18.022475409203537,1.1000139997904748,-0.13215349722354963
266.1000000000031,18.061537647526162,1.1065500539968942,-0.1374383944458928
267.4000000000031,18.100951754368737,1.1130960639232501,-0.14204155834419385
268.7000000000031,18.140407782307758,1.1189635911233062,-0.14770627514828583
270.0000000000031,18.179581345780676,1.1251195922934456,-0.1541650004707149
271.30000000000314,18.21884652769169,1.1303114739241835,-0.15982178887597698
272.6000000000032,18.25793603143983,1.1358942392780755,-0.16566391945576608
273.90000000000316,18.29726937904549,1.139291101339856,-0.17214737588907614
275.20000000000323,18.33656952502726,1.1420939620543964,-0.17772455191278302
276.50000000000324,18.37568081419339,1.1458108231437094,-0.18309846980496713
277.80000000000325,18.414663446326266,1.1475099671389493,-0.19069664050850177
279.10000000000326,18.454198848314,1.1499302608757866,-0.1987010347370397
280.4000000000033,18.49371743552093,1.1522270376299502,-0.20738259911613843
281.70000000000334,18.532532817847745,1.1493313241723002,-0.2131400945002948
283.0000000000033,18.572109112700364,1.1481919098642148,-0.22161898469993835
284.30000000000337,18.611313154465737,1.1470199866065711,-0.22994094578264335
285.6000000000034,18.650565049931295,1.1432088146888097,-0.23792847541786566
286.9000000000034,18.68978607396091,1.1406188077268429,-0.24737867257370993
288.2000000000034,18.72904113933791,1.139634741823521,-0.2551674855100159
289.5000000000034,18.768472562574754,1.1350677413574175,-0.26287522895517323
290.8000000000034,18.80804081052818,1.1307982913454673,-0.27265764679987736
292.10000000000343,18.846822734299753,1.1254124121611428,-0.2829131405400154
293.4000000000035,18.886434754607563,1.1234379411571318,-0.2937802326114265
294.70000000000346,18.92545299216724,1.1228895167912467,-0.3046761452937985
296.0000000000035,18.964736445374545,1.122186018572485,-0.31622805158575806
297.30000000000354,19.004209571114266,1.1280672421207498,-0.3279100764589078
298.60000000000355,19.043346544070655,1.1361531602121628,-0.3406931235115147
299.90000000000356,19.082885482857346,1.1557502490876244,-0.35595746563925434
301.20000000000357,19.122323834602703,1.1782614640448839,-0.3705523718121011
302.50000000000364,19.161732443977158,1.2066887282541683,-0.38382281200325474
303.8000000000036,19.200960310484657,1.2482285323981577,-0.39988919975617376
305.10000000000366,19.240583045334674,1.2836379986631807,-0.4162710707117383
306.4000000000037,19.279937869638957,1.3255840485674464,-0.4326799734133684
307.7000000000037,19.319313884648814,1.361767545419023,-0.4510463156670612
309.0000000000037,19.35885299975516,1.3996273299276671,-0.4676852744685145
310.3000000000037,19.39806429528709,1.4310905792475885,-0.48352485805722356
311.6000000000037,19.437562276654308,1.456171382582006,-0.49996523878340726
312.90000000000373,19.47714184715574,1.4746571059108375,-0.515853599450339
314.2000000000038,19.516568847183162,1.4868200115687311,-0.5315611858636959
315.5000000000038,19.55612803646477,1.4870795388781757,-0.5462170108175606
316.8000000000038,19.59582637345759,1.4836405571670697,-0.5600242399932158
318.10000000000383,19.635580333551637,1.4700891626075472,-0.5727878470816794
319.40000000000384,19.674616257639308,1.4526774995148704,-0.5842003220583454
320.70000000000385,19.714292387494393,1.4295819631071938,-0.5950986942340566
322.00000000000387,19.75391003182975,1.4045765290808245,-0.6055965334044422
323.3000000000039,19.793420362622513,1.3754090620940882,-0.614479178188649
324.6000000000039,19.832836025012057,1.349473891828854,-0.6240975731111984
325.90000000000396,19.872239116158873,1.3186839535938413,-0.6323156664586467
327.20000000000397,19.91202582019341,1.288845476155366,-0.6399997037343157
328.500000000004,19.951281006588395,1.2586826468861811,-0.6472527698588992
329.800000000004,19.990731225248624,1.2353401803612074,-0.6529001292700118
331.100000000004,20.03057936723638,1.2069542633342267,-0.6590380864115208
332.400000000004,20.069907628380836,1.1838142550554633,-0.6655363254056059
333.700000000004,20.109336174635445,1.16392229438634,-0.6704128790948389
335.0000000000041,20.1488061282437,1.143332290105598,-0.6750899554621492
336.3000000000041,20.18885575335615,1.1221587759215825,-0.6790271230735803
337.6000000000041,20.22839903749998,1.1064347925968514,-0.683625917997718
338.9000000000041,20.26765039887797,1.0872172572986274,-0.6893087494721142
340.20000000000414,20.3076570170383,1.0719710017209978,-0.6939180345637364
341.50000000000415,20.34705033672255,1.0559936288658351,-0.6972867305594739
342.80000000000416,20.38679002487824,1.0449198961174826,-0.6995905927062869
344.1000000000042,20.42627225747187,1.031402074341525,-0.7021665964040897
345.4000000000042,20.46605137929418,1.0230822360279108,-0.7056106607868662
346.70000000000425,20.505723454824782,1.013562157911774,-0.7077763120761036
348.00000000000426,20.5451356189663,1.003712498841462,-0.7106906743112686
349.3000000000043,20.58507422544033,0.9980063320454299,-0.7143054118849239
350.6000000000043,20.624833469003974,0.9890719730972366,-0.7160091596531162
351.9000000000043,20.66454670522655,0.9874821082332458,-0.7180779515529174
353.2000000000043,20.704159041474913,0.9816372241965422,-0.719722727388588
354.5000000000043,20.744086834282705,0.974581902022575,-0.7222554253374343
355.8000000000044,20.783748821462886,0.970650160198421,-0.7248427084863556
357.1000000000044,20.823499885848417,0.9674092716096758,-0.7264334886446369
358.4000000000044,20.863208803106804,0.9629930087331166,-0.7286824487255368
359.7000000000044,20.903228857502345,0.9575027080281786,-0.731319784932722
361.00000000000443,20.942847463360028,0.9548969170227096,-0.7327957337356241
362.30000000000445,20.983085898875437,0.9533126341741617,-0.7342464966717683
363.60000000000446,21.022499643039758,0.9504781268771256,-0.735647110160389
364.90000000000447,21.06264943248074,0.9512650010985366,-0.7370921213914712
366.2000000000045,21.102815106598406,0.9503783540902135,-0.7381227882013017
367.50000000000455,21.142327244980383,0.9492583776754548,-0.7390761675889972
368.80000000000456,21.182310549052968,0.9510503277401072,-0.739791343521222
370.10000000000457,21.222305723459208,0.9475154309952409,-0.7411489333698329
371.4000000000046,21.2622218147347,0.9503939797107807,-0.7412995852378228
372.7000000000046,21.30233680242716,0.9520575350580744,-0.7411487045842677
374.0000000000046,21.342391568992948,0.9532739598102331,-0.7424449102064701
375.3000000000046,21.382377410110802,0.9579954252231195,-0.74263460285683
376.6000000000047,21.422631535894123,0.9551364762795345,-0.7428624594243574
377.9000000000047,21.46246028075773,0.9600974200052972,-0.7437730681154711
379.2000000000047,21.5028176958466,0.9627995287371793,-0.7440971176984386
380.5000000000047,21.54317577807823,0.9634746330640078,-0.7441096485385494
381.80000000000473,21.582866980386154,0.9644913990689885,-0.7451218338929921
383.10000000000474,21.62341181683766,0.9640985584855751,-0.7467386743051856
384.40000000000475,21.663511525061914,0.962111536351469,-0.7480623874582184
385.70000000000476,21.703668884878663,0.9603721844370288,-0.7480624398294791
387.0000000000048,21.743569443995987,0.9619102102443248,-0.749373356422292
388.30000000000484,21.784212308105012,0.9602983346585576,-0.7506231693726302
389.60000000000485,21.82442398774173,0.9589809985010408,-0.7518587787523892
390.90000000000487,21.86496660740293,0.9576551520286531,-0.7537691708393122
392.2000000000049,21.904800350756794,0.9575531717514616,-0.7548241414219108
393.5000000000049,21.94502647212517,0.9570443754211971,-0.7547848738142
394.8000000000049,21.98571382368206,0.9549817568981913,-0.7560600082065028
396.1000000000049,22.026042557492808,0.9541784043429089,-0.7554364944953242
397.400000000005,22.066575462913264,0.9516919341669439,-0.7560650126135937
398.700000000005,22.106901735181637,0.9508610489409894,-0.7560695777535171
400.000000000005,22.14704292061649,0.951666588295834,-0.7548168539550533
401.300000000005,22.18735418676846,0.9491205243694227,-0.7551575805497981
402.600000000005,22.22819787014047,0.9482157876149147,-0.7573832120460025
403.90000000000504,22.268484785837234,0.9429859548075712,-0.7601889633161449
405.20000000000505,22.309121102860605,0.9418359387026289,-0.7614098784626777
406.50000000000506,22.349367298558093,0.9400531526344746,-0.7624267215466958
407.80000000000507,22.38990894607529,0.9370717501295922,-0.7627432730188946
409.10000000000514,22.430320702262232,0.9340727634157983,-0.7640721094924317
410.40000000000515,22.47096222294788,0.9316733602351581,-0.7654286723763128
411.70000000000516,22.511425724025482,0.9288326146606192,-0.7655786526165662
413.0000000000052,22.55198280819821,0.9239365910202783,-0.7667104315558055
414.3000000000052,22.592668953289827,0.9217158151448438,-0.7681421384911538
415.6000000000052,22.633238382871767,0.9241124040141362,-0.7694514157603987
416.9000000000052,22.67400356385543,0.9195081935631522,-0.7707707857275157
418.2000000000053,22.71420295935597,0.9174791068368866,-0.7718357924313657
419.5000000000053,22.75491061968358,0.9157713778744234,-0.7716176892034681
420.8000000000053,22.795698685180625,0.9114726064143849,-0.7726355701851353
422.1000000000053,22.83673632185083,0.9121324765745966,-0.773372304775819
423.4000000000053,22.877056109247327,0.9088857046972638,-0.7746905724396855
424.70000000000533,22.917836011384072,0.9085230881815418,-0.7759756316592501
426.00000000000534,22.958702661136797,0.9052052169842106,-0.778048414034108
427.30000000000535,22.999089168946018,0.9044322250110989,-0.7789557858371823
428.60000000000537,23.04012704392382,0.9029255610557928,-0.7802983802512111
429.90000000000543,23.080749670798674,0.9023604362015685,-0.78212490346937
431.20000000000545,23.122070945910853,0.8986387943991466,-0.7836685549006477
432.50000000000546,23.16223009840349,0.8953052087831476,-0.7844360013320335
433.80000000000547,23.203086489888705,0.8956903264481783,-0.7860171424999338
435.1000000000055,23.244078126777286,0.8920413322466424,-0.7897445859248577
436.4000000000055,23.284770174609605,0.8899159555544199,-0.7913976865276555
437.7000000000055,23.32545492299365,0.8910255648894868,-0.7936994516275124
439.00000000000557,23.366824330995506,0.8913193125443368,-0.795894813941644
440.3000000000056,23.407503013636816,0.8859710240772747,-0.7978362550338076
441.6000000000056,23.44828751437225,0.8849075466472378,-0.7994978207723853
442.9000000000056,23.48920747665992,0.8835533431279781,-0.8007813583777117
444.2000000000056,23.530449756078255,0.8841896330056418,-0.8038559936543344
445.5000000000056,23.57101449420696,0.885621359200566,-0.806939814193246
446.80000000000564,23.61203514583622,0.8839429508772283,-0.8091274269268887
448.10000000000565,23.652972355660786,0.8845034895808803,-0.8119997837835462
449.40000000000566,23.694130264517717,0.8857057372830291,-0.8140672628294503
450.70000000000573,23.734926916580967,0.8876007122962981,-0.8185432595650011
452.00000000000574,23.77580437580643,0.8889799599829161,-0.8228372359795277
453.30000000000575,23.81715733493048,0.8886206204513717,-0.8263352578754652
454.60000000000576,23.858420425422487,0.8936079108640435,-0.8279923619488057
455.9000000000058,23.899252907852695,0.8976793969285424,-0.8330114508619091
457.2000000000058,23.940535661872882,0.9019307228756348,-0.837172692841039
458.5000000000058,23.981776482565135,0.9106323600547004,-0.8405412404840549
459.80000000000587,24.022581979925988,0.9160094573010287,-0.8439200894626726
461.1000000000059,24.063914231398545,0.9225300422245782,-0.8487429717722517
462.4000000000059,24.10505802708227,0.9305682515487164,-0.8531667040312843
463.7000000000059,24.146030064976898,0.9387210342381965,-0.8574340571201176
465.0000000000059,24.187321526041934,0.9486125490985999,-0.8623452964785439
466.3000000000059,24.22852118654934,0.9596340393956353,-0.8670290868820794
467.60000000000593,24.269721751486827,0.969254160656182,-0.8722158367667916
468.90000000000595,24.310994192550993,0.982176194640935,-0.8787558530939172
470.20000000000596,24.352624947146868,0.9906275878213844,-0.8834444051603536
471.500000000006,24.393297677418616,1.0021796174880242,-0.8880173312660808
472.80000000000604,24.43480406655258,1.0129013681988845,-0.8928227664647337
474.10000000000605,24.47617136005135,1.0242798317710384,-0.8982770080104316
475.40000000000606,24.517072861602497,1.0335144906508484,-0.9045783601668385
476.70000000000607,24.558593792395758,1.0460512456670863,-0.9088961825105772
478.0000000000061,24.600033331110083,1.0570902093443304,-0.915336471483366
479.3000000000061,24.641213340790078,1.06641265753808,-0.9202226412579231
480.60000000000616,24.682621266030853,1.0765330319968318,-0.9247698675092808
481.9000000000062,24.724022872577567,1.0842569697109157,-0.9315109446412788
483.2000000000062,24.765208077776194,1.0924782906493724,-0.9349899261943206
484.5000000000062,24.806767878290714,1.1020214611051316,-0.9394727034128176
485.8000000000062,24.847837033561717,1.1096059573229526,-0.945253447197894
487.1000000000062,24.889756156318114,1.1145435322609256,-0.9515674204554667
488.40000000000623,24.931083685372688,1.1218500515839471,-0.956242582951452
489.70000000000624,24.972549399273294,1.1274255935531647,-0.9603906381081719
491.00000000000625,25.014161219537772,1.1313523860661088,-0.9650455793586223
492.3000000000063,25.055616243956212,1.142171205204567,-0.9689295927364179
493.60000000000633,25.097192349632312,1.1477738237342205,-0.9737765686629807
494.90000000000634,25.138499831653068,1.147976228607639,-0.9778583276379651
496.20000000000636,25.179999691218917,1.154271479351376,-0.9823744875485008
497.50000000000637,25.22187102756243,1.1583862634525117,-0.9875082610809209
498.8000000000064,25.263260207769584,1.1631197336311483,-0.9912951268583607
500.1000000000064,25.304855715484884,1.1709230941217674,-0.9941015523548633
501.40000000000646,25.346444739348385,1.1763798031352888,-0.9963925881495577
502.70000000000647,25.38797797260388,1.1803425468314903,-0.9998596170693288
504.0000000000065,25.429214740000994,1.1895769519276236,-1.0020753873138837
505.3000000000065,25.47124456518829,1.193111656818642,-1.0053765649582074
506.6000000000065,25.51274941726716,1.2005416639314392,-1.0097284437752694
507.9000000000065,25.554659348919678,1.206292894897735,-1.0131137449508434
509.2000000000065,25.596442133011006,1.2080403734727867,-1.0139998165072703
510.50000000000654,25.637979979677162,1.2150222098341654,-1.0166642107974213
511.80000000000655,25.679463114030355,1.2188088237816503,-1.0198475765770993
513.1000000000066,25.721582537792283,1.2212453631920719,-1.0211826173989307
514.4000000000067,25.763271650723485,1.2250481010897925,-1.0227294017722302
515.7000000000066,25.804940491202508,1.2300109083539308,-1.024669034226592
517.0000000000066,25.84654081560702,1.2309076684567248,-1.0268663713404078
518.3000000000067,25.888672281998815,1.236235433187662,-1.0287787820528345
519.6000000000067,25.929997491550353,1.2406048701137342,-1.0287327260460866
520.9000000000067,25.97181382134063,1.2417745678399614,-1.0301475392867427
522.2000000000068,26.013899733708122,1.245804607205541,-1.0320807356737904
523.5000000000068,26.05570735002278,1.25185343902212,-1.0330082933956426
524.8000000000068,26.097462614778962,1.2540419314359854,-1.0338464853561167
526.1000000000067,26.139364858697586,1.2616256396079315,-1.034414559852444
527.4000000000068,26.181383164697554,1.2669678810593403,-1.0376642493100552
528.7000000000069,26.223203866136235,1.2702545376444807,-1.0388612255896281
530.0000000000068,26.265221678203368,1.2787595117913744,-1.0408650437104052
531.3000000000068,26.307128786447233,1.2883078905206589,-1.0429896847395517
532.6000000000068,26.348798367586593,1.2946103229855248,-1.0430093041651576
533.9000000000069,26.39098139965608,1.305194555507183,-1.0443257341252616
535.2000000000069,26.43304925214953,1.3159408760688966,-1.0457365572076887
536.5000000000069,26.4747374473629,1.3296574534985126,-1.0472779870230418
537.800000000007,26.51701759839904,1.3440795734194209,-1.0485772014852994
539.100000000007,26.55897610359357,1.3563494748582026,-1.0499464862068937
540.4000000000069,26.600909318778896,1.372238813005795,-1.0504322423959356
541.700000000007,26.642779883943376,1.3892382675056734,-1.0519242519150378
543.000000000007,26.684980566258783,1.4062346631203895,-1.0541233756859274
544.300000000007,26.727154131933887,1.4190014373737516,-1.055622406133566
545.6000000000071,26.76924770148004,1.4339267380708542,-1.0570206360964134
546.9000000000071,26.811211747656607,1.4513831973841926,-1.059020208766702
548.2000000000071,26.85332967419219,1.4669757684369997,-1.0618598844393263
549.500000000007,26.895310226810768,1.4802549184323823,-1.0639433459489807
550.8000000000071,26.937684704425628,1.49023506835324,-1.0665158027775186
552.1000000000072,26.97957566063443,1.4992340689065864,-1.0679022574834942
553.4000000000071,27.022071188954566,1.5082193139561015,-1.069118308742484
554.7000000000072,27.064150829801097,1.5158837406482675,-1.0705121717670227
556.0000000000073,27.106179971078102,1.5244112243932242,-1.0716740905538016
557.3000000000072,27.14844515116337,1.5355505667970446,-1.0741308328242138
558.6000000000072,27.19080654261109,1.545060144042209,-1.0769506167180407
559.9000000000073,27.232910091771675,1.5555987884506577,-1.0794747582358877
561.2000000000073,27.27512699331781,1.564858994705726,-1.0808628134359832
562.5000000000073,27.317276032314126,1.5760070214877515,-1.0829483786990468
563.8000000000073,27.359321434388505,1.5871571080775912,-1.0850245521585622
565.1000000000073,27.401537394113234,1.60137709600604,-1.0865148657572932
566.4000000000074,27.444041634877927,1.6180522175688454,-1.089529636485162
567.7000000000073,27.48626318079949,1.6351117073048795,-1.0912743081990377
569.0000000000074,27.528743422880744,1.6512235560912192,-1.0933082260857905
570.3000000000075,27.57107569942189,1.672165944535236,-1.0976328251216323
571.6000000000074,27.613265885655494,1.6987033710500543,-1.1011316305348302
572.9000000000075,27.655859997333923,1.7244093667437037,-1.1024598609459715
574.2000000000074,27.698041954856233,1.74938408778502,-1.1038408835809284
575.5000000000075,27.74058988103052,1.7791680985049738,-1.1072114822519974
576.8000000000075,27.782834914328287,1.810718812139929,-1.1095641942232923
578.1000000000075,27.82505570229526,1.844529468428388,-1.1121529960000114
579.4000000000076,27.868005616334894,1.8836888915443881,-1.1153562651722022
580.7000000000075,27.910336259174596,1.923731785238849,-1.1169539401907427
582.0000000000076,27.95248259029893,1.9685788664877957,-1.1197121610161114
583.3000000000076,27.994772861576532,2.012225802380615,-1.1218024892360723
584.6000000000076,28.037746991776825,2.0626606413398694,-1.125178660743296
585.9000000000076,28.08006587149001,2.116796537613659,-1.1293261746063723
587.2000000000077,28.122738879885205,2.1739244961334845,-1.1324595763529661
588.5000000000076,28.16542433633978,2.2348583741685366,-1.135669531794771
589.8000000000077,28.207778690529626,2.28722377709659,-1.1370759475848313
591.1000000000078,28.250350577158244,2.3481345193324477,-1.139341375752306
592.4000000000077,28.292946741074562,2.399577445265704,-1.1430220374705602
593.7000000000078,28.33567725389382,2.449244213188997,-1.1473490706155625
595.0000000000077,28.378113506963267,2.489779311676235,-1.1518908792763383
596.3000000000078,28.420872810813506,2.521090524426656,-1.1574405032561166
597.6000000000078,28.463683451105965,2.5287797879311005,-1.1613158672475028
598.9000000000078,28.505994123715055,2.484476915506658,-1.1652931068458576
600.2000000000078,28.54873758336855,2.3616718368804634,-1.16855164106269
601.5000000000078,28.59137884719071,2.194303987756144,-1.1729265545728529
602.8000000000079,28.633835824660732,2.031140272177284,-1.1767743403370088
604.1000000000079,28.676238021561648,1.8942526988816017,-1.1813661716626753
605.4000000000079,28.71881113383893,1.7802202571919443,-1.186028513802401
606.7000000000079,28.761307678345812,1.693001286729759,-1.190476987482909
608.000000000008,28.80363937919621,1.6307545080732553,-1.1944623386658488
609.3000000000079,28.84667033660013,1.599925288617076,-1.1974577523768355
610.600000000008,28.888730909317637,1.5984204745557526,-1.200330272349155
611.900000000008,28.931323583024163,1.5887689557458498,-1.2018561823940654
613.200000000008,28.974100989206523,1.5704740772518004,-1.2032476533410197
614.5000000000081,29.016544115167306,1.5547978745561244,-1.2045067279538233
615.800000000008,29.059121433775697,1.538881022268291,-1.2047819507545379
617.1000000000081,29.102030739011006,1.5310901348299741,-1.2060944323322769
618.400000000008,29.144778273263757,1.5179902169406074,-1.2069214205295822
619.7000000000081,29.187258397241926,1.5138911470404994,-1.2061097903871163
621.0000000000082,29.22996108423953,1.5136657527645832,-1.2061149865750584
622.3000000000081,29.27289340260437,1.5157307774074082,-1.2074171679184356
623.6000000000082,29.31538900098919,1.5256831318080493,-1.2100907923788302
624.9000000000082,29.358450792945845,1.5308690314565758,-1.2100504177944358
626.2000000000082,29.40085600922492,1.5473755438500232,-1.2113815988583658
627.5000000000082,29.44366756618504,1.5617176936738901,-1.2113664865430875
628.8000000000083,29.48615654808502,1.5807842547076587,-1.2135871791478263
630.1000000000082,29.529088116034604,1.601497717696096,-1.2139975231424427
631.4000000000083,29.571998677698694,1.6242769992386072,-1.2153133170977153
632.7000000000083,29.614643824395664,1.648832960315444,-1.2167524010784372
634.0000000000083,29.657468004323324,1.6767060166045482,-1.2168350476283907
635.3000000000084,29.69996440142685,1.7079015769785646,-1.218169535600433
636.6000000000083,29.742916116292314,1.7406866724680203,-1.2194838938719195
637.9000000000084,29.785978946528633,1.7779104884130512,-1.2207968055132832
639.2000000000083,29.82855818223852,1.8124304909839533,-1.2219824717239565
640.5000000000084,29.871387391913483,1.8497590679712428,-1.222609682093403
641.8000000000084,29.91439826790281,1.892591808699546,-1.2256240207119848
643.1000000000084,29.95733764879848,1.934477377538598,-1.2273727541887145
644.4000000000085,30.0004487764945,1.9815580212261652,-1.2288103636877672
645.7000000000085,30.04306441353202,2.025817249735814,-1.2307163759527393
647.0000000000085,30.08596291998434,2.076852604715398,-1.2337661056807505
648.3000000000085,30.129386379826364,2.1242644279159184,-1.2359019932150601
649.6000000000085,30.17229178764054,2.1698731422524706,-1.238819221113928
650.9000000000085,30.214653377152857,2.225822129045555,-1.2415519932304289
652.2000000000086,30.257820263489435,2.2755681691266023,-1.2447584743062379
653.5000000000086,30.300926510938186,2.3241430915297685,-1.2480148132104447
654.8000000000086,30.343400524329837,2.3723090258130135,-1.2501968395892566
656.1000000000087,30.38679961992656,2.4219403550466585,-1.253943548316331
657.4000000000086,30.42972316854372,2.4711087800008493,-1.2580818576586577
658.7000000000087,30.472565942875914,2.51907348769258,-1.2598940954465458
660.0000000000086,30.515539787144096,2.5714909486104855,-1.263503132927569
661.3000000000087,30.55856880159026,2.6220346391909257,-1.2657198018773776
662.6000000000088,30.60172954355121,2.6787588542512677,-1.2683897671559996
663.9000000000087,30.64443854474607,2.7322566237544192,-1.2714107334575724
665.2000000000088,30.68746159425297,2.7880185700141658,-1.275802935634788
666.5000000000088,30.73072909327532,2.850048899995528,-1.2799754964629058
667.8000000000088,30.773726186313308,2.913665329460728,-1.2835656575016836
669.1000000000088,30.816591469425056,2.983000701897558,-1.2892230926148187
670.4000000000088,30.85996675633361,3.0576373965790484,-1.2950539271011734
671.7000000000088,30.90313218310335,3.138633592191279,-1.2988705305133874
673.0000000000089,30.946055999288355,3.2288331615155514,-1.3058450841043872
674.3000000000089,30.989035029298133,3.326659823756122,-1.3100643446821731
675.6000000000089,31.03225069939412,3.4367429196644976,-1.3152966269388635
676.900000000009,31.075363325461336,3.5558783845084716,-1.3212782641415304
678.2000000000089,31.118417297067126,3.6919218288072453,-1.327608824792275
679.500000000009,31.162057510112756,3.839046147591411,-1.3336429776305616
680.8000000000089,31.204910947867752,4.00301457159159,-1.3400121044541682
682.100000000009,31.248171227626766,4.178276893577544,-1.3459021537521485
683.400000000009,31.291265354874263,4.372358719128123,-1.3514302027257146
684.700000000009,31.334710703659614,4.582954477330538,-1.3593898709658072
686.0000000000091,31.377929569771062,4.78498346629175,-1.3668758185528311
687.300000000009,31.421239395669886,4.885325895810977,-1.375287407346507
688.6000000000091,31.46484836739634,4.802280799618501,-1.3821746421242995
689.9000000000091,31.507913673288307,4.701078460724248,-1.3901335412080251
691.2000000000091,31.55108967103933,4.6680747473811195,-1.4002092453054913
692.5000000000091,31.59430140433368,4.6869540137824846,-1.4063775461369383
693.8000000000092,31.63787624900069,4.735333212431621,-1.4167164726219732
695.1000000000092,31.68080037351735,4.811875789274879,-1.4262013185506843
696.4000000000092,31.72411984443986,4.898241289189038,-1.4362339997223477
697.7000000000093,31.76738653937464,4.994026253210915,-1.446904904973699
699.0000000000092,31.810447838484446,5.09510482841844,-1.4565544531270804
700.3000000000093,31.85414793480316,5.208441606646397,-1.466845913900011
701.6000000000092,31.89722513570462,5.325752770598839,-1.477989232334012
702.9000000000093,31.940336742881502,5.438516830139315,-1.488201822275176
704.2000000000094,31.983686394569062,5.559620944296434,-1.4998473908521968
705.5000000000093,32.02725231187344,5.68333639783992,-1.5116388634072284
706.8000000000094,32.070567128566886,5.811041195647615,-1.524321114108771
708.1000000000093,32.11408368753498,5.9304890245974935,-1.5363313782133612
709.4000000000094,32.157378257329846,6.058837167471557,-1.5481016886648273
710.7000000000094,32.200559139351085,6.186831581859356,-1.560244716171951
712.0000000000094,32.2442818255026,6.320754949116216,-1.5741691631576957
713.3000000000094,32.28745790167137,6.4532479548168675,-1.5884601085721926
714.6000000000095,32.331007395752216,6.578491849884448,-1.6039456138439392
715.9000000000095,32.37439202916095,6.706757859412783,-1.618634786516993
717.2000000000095,32.41781517119956,6.833651948410656,-1.6339903585086288
718.5000000000095,32.46092277589397,6.959249012776029,-1.6493135677257715
719.8000000000095,32.50473145424893,7.0842495232224545,-1.6644435473844195
721.1000000000096,32.54823978331584,7.204324812718955,-1.6792178331244307
722.4000000000095,32.591462828758175,7.317545654805522,-1.695043450501731
723.7000000000096,32.63500112396405,7.429533388649162,-1.7119270214193651
725.0000000000095,32.67808900707812,7.536652331936856,-1.7287734934833159
726.3000000000096,32.722012517713814,7.650094036304802,-1.74797548858546
727.6000000000097,32.765260138703155,7.76013675216229,-1.766745466086396
728.9000000000096,32.8089445405085,7.872676303125258,-1.7855697578891236
730.2000000000097,32.852637728489455,7.984452262693455,-1.801662650461794
731.5000000000097,32.895965020706605,8.094198536603084,-1.8197660846998174
732.8000000000097,32.93937991033356,8.199833116612034,-1.8393595151072253
734.1000000000097,32.98296882843587,8.29984561787271,-1.858189937840704
735.4000000000098,33.02649744743807,8.387992733980136,-1.8768731158219611
736.7000000000098,33.07004276430278,8.46313751767308,-1.8972540381187648
738.0000000000098,33.11343181256867,8.516853742008818,-1.9180169667534468
739.3000000000098,33.15730223917681,8.544252516955272,-1.9377552386849417
740.6000000000098,33.200917863615814,8.536540987828705,-1.9578244954700605
741.9000000000099,33.24385543622165,8.488721645062823,-1.9784803571716494
743.2000000000098,33.28737376537287,8.380853010233606,-1.9973235483582386
744.5000000000099,33.33095735387063,8.187779803579856,-2.0175470906065263
745.80000000001,33.373957693442364,7.878789287476961,-2.036043514092654
747.1000000000099,33.41733765410328,7.396408470292873,-2.0545243664165276
748.40000000001,33.46074083034139,6.702595968252399,-2.0713352610362676
749.7000000000099,33.50387223636157,5.804000598621972,-2.084461487820086
751.00000000001,33.5469663141411,4.764215184561585,-2.0965940626168686
752.30000000001,33.58930086980841,3.78118162354336,-2.10543470543374
753.60000000001,33.63207767373399,2.966514825671336,-2.111570097536223
754.90000000001,33.67487052616725,2.3388778680684976,-2.1146715722477785
756.20000000001,33.71769623303695,1.9052705432424917,-2.1167805853096016
757.5000000000101,33.760326680215606,1.6114751503699327,-2.1189411892302523
758.8000000000101,33.80318196239734,1.4285400176800307,-2.1213001018232296
760.1000000000101,33.84663723235581,1.3014238481794793,-2.120450325749041
761.4000000000101,33.88922521111264,1.2226633230721493,-2.120449979192462
762.7000000000102,33.93300665298303,1.1563715731163353,-2.1204358090503
764.0000000000101,33.976254967555434,1.0993536407209983,-2.121774304629037
765.3000000000102,34.01972343640631,1.051464658138276,-2.1230893204432837
766.6000000000101,34.0632961553945,1.0203326838494724,-2.122760830695992
767.9000000000102,34.106601163070636,0.9927607631010285,-2.122809138208666
769.2000000000103,34.15019768698511,0.9683721366209853,-2.1214400840840626
770.5000000000102,34.193164800836904,0.9539231792768657,-2.120206868211265
771.8000000000103,34.237209646160196,0.9349956274104672,-2.1200699324055803
773.1000000000103,34.28089223063266,0.922605780293226,-2.121430080349201
774.4000000000103,34.32448071198364,0.9086854225288008,-2.1214299290637175
775.7000000000103,34.36808973701278,0.8950037612741153,-2.121429929000048
777.0000000000103,34.411453453998845,0.8808596590515848,-2.1214299293371117
778.3000000000104,34.45500361584077,0.8719149959262575,-2.1214279393184654
779.6000000000104,34.4986948306197,0.8621587141496307,-2.122744968948099
780.9000000000104,34.54238474649706,0.8526046361387835,-2.122751805351526
782.2000000000104,34.58609251181965,0.8436475595304784,-2.121436187008693
783.5000000000105,34.62934849257807,0.8354717810858222,-2.1214398341729055
784.8000000000104,34.67333031977813,0.8328682616002597,-2.121439723941411
786.1000000000105,34.716975616288266,0.8194281503198061,-2.122035721747471
787.4000000000106,34.760832685728644,0.8155952624653162,-2.1227454185690684
788.7000000000105,34.80427305847447,0.8077924927838425,-2.1240710878708224
790.0000000000106,34.84779847015392,0.7998368750874902,-2.1240701719118245
791.3000000000105,34.89163323487918,0.7913030584598971,-2.1240701719999957
792.6000000000106,34.93558190933607,0.7847018634750033,-2.1240701720917086
793.9000000000106,34.979164679410175,0.7734913898369695,-2.1240694674156417
795.2000000000106,35.022749162484565,0.7649375283012263,-2.122745751486907
796.5000000000106,35.06667000000036,0.7565596451789267,-2.124067165253252
797.8000000000106,35.110576989177105,0.7438210304618731,-2.125378665949759
799.1000000000107,35.154180345880306,0.7345339430104645,-2.1253798992894417
800.4000000000107,35.19764376517864,0.7253411511161976,-2.125379865875707
801.7000000000107,35.241788047970566,0.7183172897751748,-2.12412111727416
803.0000000000107,35.285797491857785,0.7090776331730324,-2.1253895597728834
804.3000000000108,35.329254351166135,0.7022292452185332,-2.1253897721820776
805.6000000000107,35.37307641537417,0.6951382308568539,-2.1248981845182793
806.9000000000108,35.41688342721296,0.6950324980148512,-2.1240525084033233
808.2000000000107,35.46058415799027,0.6889111016339704,-2.1253875206646664
809.5000000000108,35.504607050522665,0.6833939271675777,-2.1267007712311035
810.8000000000109,35.548366017552446,0.6789586259883003,-2.12669986819739
812.1000000000108,35.59182636356902,0.6731036214953219,-2.1271731091472295
813.4000000000109,35.63577802318309,0.66780653455135,-2.1279778537754144
814.7000000000108,35.679825196021994,0.6585862220379837,-2.129329830283127
816.0000000000109,35.72344414628424,0.6591314253681164,-2.1293298670771876
817.3000000000109,35.76782237486482,0.6529355481402246,-2.129329866999994
818.6000000000109,35.81173188375826,0.6532519222387683,-2.129329866999999
819.900000000011,35.85569922577396,0.648211440334096,-2.129329867
821.200000000011,35.899537121923885,0.6487590104727634,-2.129329867000238
822.500000000011,35.94345720262305,0.6471310727127417,-2.1293298649307926
823.800000000011,35.987416169882614,0.648592520624103,-2.129323161881584
825.100000000011,36.031229580040126,0.642145168096071,-2.129222056510495
826.400000000011,36.07500120036345,0.6375684105546084,-2.128832013820598
827.7000000000111,36.11904000779365,0.6382254438778141,-2.127907620573414
829.0000000000111,36.162773054483,0.6392604819833694,-2.129233424450298
830.3000000000111,36.206771217334186,0.6375376720883581,-2.129230075933637
831.6000000000112,36.25064851166331,0.6390359123222196,-2.1292259321235703
832.9000000000111,36.29475767179465,0.6359857536462328,-2.1305425331073593
834.2000000000112,36.33849179408004,0.6407800050760761,-2.130536558497499
835.5000000000111,36.3824711752807,0.63703876448276,-2.131864204471851
836.8000000000112,36.426400154605105,0.6360571946958424,-2.1331728608895926
838.1000000000112,36.470376355995626,0.6335151467549547,-2.1331937654275785
839.4000000000112,36.51408095773058,0.637505963536326,-2.131860442779285
840.7000000000113,36.558043225866996,0.63552967649612,-2.1309119110138868
842.0000000000113,36.60213986667892,0.6413386404763217,-2.1318616045889835
843.0000000000113,36.63612309137396,0.6342289300346597,-2.1312041473110015