File: 01_Data/Vinyl_Tile/STA/N2/30K_min/Vinyl_Tile_STA_N2_30KData_220506_R2.csv
##Temp./Â°C,Time/min,DSC/(mW/mg),Mass loss/mg
49.0,10.374422733789466,2.318387819366663e-05,0.019103812193115743
50.100000000000016,10.659826528525599,0.054834465318573056,0.021021709270215183
51.20000000000003,10.799036189588694,0.10064883937899427,0.021826002014887713
52.30000000000005,10.903001672860809,0.13532490654759077,0.02179012557957183
53.40000000000006,10.989369012223271,0.17025810801868946,0.021856866908041006
54.50000000000008,11.06602921861144,0.20175348642998914,0.023150450385617027
55.600000000000094,11.13584236801178,0.2287403892793427,0.023059961506316284
56.70000000000011,11.199202238766198,0.25220986381743415,0.023444316844359214
57.800000000000125,11.259622447292594,0.27942364698867017,0.022524753540233533
58.90000000000014,11.316812924644626,0.30051017146254133,0.022363614737467508
60.000000000000156,11.370329535037383,0.321656408841905,0.022974616028560213
61.10000000000017,11.423078497681482,0.3397884441756086,0.0243639592417475
62.20000000000019,11.473020371303061,0.3589072175448864,0.02365732435246848
63.3000000000002,11.522080518042975,0.3749820541318308,0.022557527596352323
64.40000000000022,11.569873778936051,0.390241676403781,0.023225607523122527
65.50000000000023,11.61641052722978,0.40526902467113257,0.02370572271138016
66.60000000000025,11.662556782917997,0.4162980331873326,0.023464557594470747
67.70000000000027,11.706973303877692,0.4279763263339585,0.02451545254632137
68.80000000000028,11.751074479745986,0.44152693909952123,0.024582499221490473
69.90000000000029,11.794456559015067,0.45043030347608426,0.024503646688694758
71.00000000000031,11.837328452658195,0.4609745052620636,0.02298925518417505
72.10000000000034,11.880038867924187,0.4695512171148612,0.024046700445890856
73.20000000000034,11.921786563883668,0.4777672034818382,0.024307414527197757
74.30000000000035,11.963335904568606,0.48725279795619736,0.024517548701136427
75.40000000000038,12.004345491567312,0.4965886245459505,0.023897066808170386
76.5000000000004,12.045679579784125,0.5029661558417198,0.024226378817645333
77.6000000000004,12.085864797452587,0.5084985335190041,0.024768813738961448
78.70000000000041,12.126776024288409,0.5177156389708922,0.023606912180307305
79.80000000000044,12.166088034282332,0.5246539994876129,0.023361773893924465
80.90000000000046,12.20606247961771,0.5318411900776902,0.024663688656027638
82.00000000000047,12.2458066419332,0.5380543893694139,0.024229375502152095
83.10000000000048,12.284894536406888,0.544341731159176,0.02324317202048043
84.2000000000005,12.323837373171852,0.5520860547433822,0.0243334753873512
85.30000000000052,12.36314440386824,0.5576401902928889,0.024910761562522588
86.40000000000053,12.401670542395324,0.5648915394585501,0.02414832969930103
87.50000000000054,12.439685458575651,0.5713021786862456,0.023339898332548792
88.60000000000056,12.478143406624582,0.5775531536040577,0.024057995808582255
89.70000000000059,12.51660315599132,0.584414599623168,0.02444116564328791
90.8000000000006,12.55443027756175,0.5882489894312701,0.023112765479230468
91.9000000000006,12.592315525504395,0.5950552992240277,0.024503812820602988
93.00000000000063,12.62966698807552,0.5988318682750378,0.023087731997682326
94.10000000000065,12.667756740975019,0.6033532976500189,0.023423529750108862
95.20000000000066,12.705318497896023,0.6087968034943505,0.02456705258210512
96.30000000000067,12.743063908185773,0.6163425661826258,0.024570325121531233
97.40000000000069,12.780225870550263,0.619485304684823,0.02396053154489053
98.50000000000071,12.818078632757084,0.6240067496349195,0.02337206316074969
99.60000000000072,12.855019922796206,0.6273279333560517,0.02375021367165786
100.70000000000073,12.892316162892316,0.6300752094540413,0.02325057849811074
101.80000000000075,12.929309483224918,0.63652121191876,0.022135398834535636
102.90000000000077,12.966141591977298,0.642610717252101,0.02324215948472652
104.00000000000078,13.003390693667736,0.6450534189946168,0.024565954746611496
105.10000000000079,13.040273333119694,0.6495900165002577,0.023266921223671133
106.20000000000081,13.077175958960206,0.6542928725442709,0.023259888373083015
107.30000000000084,13.114087262358362,0.6573251701275775,0.023262869608283943
108.40000000000084,13.150905521088655,0.6626468313674541,0.024560298102950462
109.50000000000085,13.187905025794478,0.6691692190759178,0.02538401885825259
110.60000000000088,13.224742350967828,0.670465096871733,0.024583197532278334
111.7000000000009,13.261355226023676,0.675138463510391,0.024623700647881108
112.8000000000009,13.298343643705898,0.6804875357623136,0.024560173507781613
113.90000000000092,13.335244408116296,0.6851450659199575,0.02456020881662191
115.00000000000094,13.371860705400659,0.6894862435249315,0.02357540165577987
116.10000000000096,13.408574441894991,0.694167338037589,0.023250051440806274
117.20000000000097,13.44481944988479,0.6974217799650657,0.02324853717888775
118.30000000000098,13.481298094646426,0.7037365247119967,0.0245859459281057
119.400000000001,13.51757592240022,0.7066865559190869,0.024560130942526293
120.50000000000102,13.554300368941188,0.7104933061234453,0.02325556485355129
121.60000000000103,13.590279448656325,0.7131000702763766,0.023251156818410834
122.70000000000104,13.62693095916022,0.7140961629895453,0.02457631149344497
123.80000000000106,13.662949268858334,0.7201677267732245,0.02326201074179224
124.90000000000109,13.699353306382246,0.7219980327055786,0.023259882207075755
126.0000000000011,13.735265208421314,0.7256358489640499,0.0232598870010845
127.1000000000011,13.771536216497083,0.7269690905852438,0.023259886106790972
128.20000000000113,13.807631222785911,0.7306741999894898,0.023259201904995308
129.30000000000115,13.8435733030945,0.7339066051747111,0.023568769591951977
130.40000000000117,13.879440208574563,0.7382257115889295,0.02446179201370846
131.50000000000117,13.914947194613998,0.7419066620117257,0.02323970709564005
132.6000000000012,13.950733479706983,0.7464644727972268,0.024243294778173663
133.7000000000012,13.986239126058976,0.7507872238105142,0.024240022389340865
134.8000000000012,14.022443164538613,0.7532155248377712,0.024240023025758006
135.90000000000123,14.057984366846101,0.7533965608608566,0.024240156362445475
137.00000000000125,14.093652709590726,0.7587913046725625,0.023931389646077328
138.10000000000127,14.128968127672785,0.7603114391328112,0.022920172466729838
139.2000000000013,14.16418865029271,0.7644893421415698,0.02292002233717838
140.3000000000013,14.199832341542075,0.768480404932585,0.02292012169490576
141.4000000000013,14.234947255205725,0.7718186141119674,0.023240277459097847
142.50000000000134,14.269887049008409,0.7729814515278022,0.023251088305041634
143.60000000000133,14.305167984972798,0.7785878008033517,0.02447876446711028
144.70000000000135,14.340343666495897,0.7811125719665714,0.024570117810917225
145.80000000000138,14.375793064227036,0.7851036734820014,0.02457013809767883
146.9000000000014,14.41033622737536,0.7882369356832772,0.02457013799975183
148.00000000000142,14.445500607684748,0.7913649580890942,0.024570139038615046
149.10000000000142,14.480269257565743,0.7932129893301282,0.024568914361021044
150.20000000000144,14.51543168468496,0.7989917761901184,0.024740232308396948
151.30000000000146,14.55027446074585,0.80274468393995,0.024899874917032605
152.40000000000146,14.585195901669486,0.8056156591573749,0.0249148402967716
153.50000000000148,14.619906841612178,0.8073934979533332,0.023590261531215795
154.6000000000015,14.654517471299023,0.8084407848891739,0.023590489677104642
155.70000000000152,14.689637410581923,0.8155033632548171,0.024596944665687737
156.80000000000155,14.724279283470437,0.8178098693336215,0.024576669811203544
157.90000000000154,14.759129612856873,0.819468865469496,0.024011443006842548
159.00000000000156,14.79329577042077,0.8238061107285535,0.022593584279088752
160.1000000000016,14.828248856559705,0.8243213080164089,0.022260043032980903
161.20000000000158,14.862616569168019,0.8290648924893607,0.022260130030515413
162.3000000000016,14.897062106130791,0.832594471300455,0.022266080640195973
163.40000000000163,14.932017724144304,0.8361364793666145,0.02353547317948479
164.50000000000165,14.966484193424527,0.8381684240126906,0.02225831362424735
165.60000000000167,15.000791312037347,0.8432755048212999,0.022956409967790137
166.70000000000167,15.035238973613476,0.8448601482968482,0.022919777754485615
167.8000000000017,15.06951261000019,0.8495510340590832,0.022919873126711288
168.9000000000017,15.104218937292659,0.8536393268116004,0.022919872979081823
170.0000000000017,15.138652877378497,0.8558173941497212,0.02291990992434023
171.10000000000173,15.173236240669095,0.8590890456934279,0.022882603531128254
172.20000000000175,15.207198742660735,0.8644792730510421,0.02424371505651912
173.30000000000177,15.241594091564686,0.8659826882122748,0.02423986918966481
174.4000000000018,15.275931400216432,0.8709328100795741,0.024239872991637768
175.5000000000018,15.309990681647731,0.872719002496197,0.024239881103629735
176.6000000000018,15.34388969057412,0.8777284974691663,0.024232496976721585
177.70000000000184,15.37832608914275,0.8808049023695393,0.02358387855484345
178.80000000000183,15.412575371551013,0.8860980310581265,0.023611940875583493
179.90000000000185,15.446607453672476,0.8869260923364819,0.022255964898767466
181.00000000000188,15.480625991874637,0.8914572402341341,0.02225982535925297
182.1000000000019,15.51437241086541,0.89485555682145,0.022268365210176277
183.20000000000192,15.548517393607776,0.8975892357733011,0.021598343386737717
184.30000000000192,15.58238476604081,0.902052612845541,0.02160018467871261
185.40000000000194,15.616224809396172,0.9084885798040742,0.02160018199637026
186.50000000000196,15.650180111819157,0.9119015140655654,0.02160018200000291
187.60000000000196,15.683854310828885,0.9138112241125517,0.02160018200267455
188.70000000000198,15.717807150609888,0.9162192108338222,0.021600180151568615
189.800000000002,15.751640164413033,0.919816491130749,0.02160135964762855
190.90000000000202,15.785285700787835,0.9228008197353312,0.020321756566088034
192.00000000000205,15.81886071335027,0.9266085327327604,0.020290085190320717
193.10000000000204,15.852527783174633,0.9285304010689888,0.020290115028621436
194.20000000000206,15.886175705413315,0.9332548890004343,0.020290115211343718
195.3000000000021,15.919637777125295,0.9368428237032942,0.020290003828533187
196.40000000000208,15.95345543137579,0.9391792231891175,0.02094769179168754
197.5000000000021,15.986882982570268,0.9437294242785086,0.020940118125427176
198.60000000000213,16.020566938998996,0.9472596440037062,0.020940084107527568
199.70000000000215,16.053939988664528,0.9472412643703192,0.0205664734520985
200.80000000000217,16.087664287286156,0.9518980759075171,0.019631426589425516
201.90000000000217,16.121174170050992,0.9564998544820206,0.018268677072423856
203.0000000000022,16.15478241618137,0.9614928605055652,0.018310041614489236
204.1000000000022,16.188360070054383,0.9651046567211268,0.01830997689450964
205.2000000000022,16.22189610304924,0.9673940578409661,0.018309991273443238
206.30000000000223,16.2550974036071,0.9701745886392633,0.018300122251722506
207.40000000000225,16.288882422278174,0.9735121894373711,0.01764449976623972
208.50000000000227,16.322041431959843,0.9779477497866911,0.017196090311727197
209.6000000000023,16.35565720379398,0.9818899972163571,0.016998617741464273
210.7000000000023,16.388790802431572,0.987388341983267,0.016044140935616902
211.8000000000023,16.422194184192687,0.9901516384409681,0.016016136624632082
212.90000000000234,16.455903509583653,0.994933826277241,0.014680108740200204
214.00000000000233,16.489415433003302,0.9964954554898654,0.014699840318265878
215.10000000000235,16.522781206657413,1.0015742053948888,0.01470300428044169
216.20000000000238,16.555452860493705,1.0042811782458891,0.013334115105800848
217.3000000000024,16.589243478218094,1.0088473718998232,0.013376562498311984
218.40000000000242,16.62285211052217,1.0119993393294684,0.012050674737325906
219.50000000000242,16.656131736359338,1.016081747129106,0.012070158920727714
220.60000000000244,16.689503759538272,1.0195199512729607,0.011994224838362655
221.70000000000246,16.72288985311322,1.0226322622874537,0.011727366742666945
222.80000000000246,16.756133968408687,1.0254078831836524,0.011126294625159794
223.90000000000248,16.789572974112392,1.0288380210929997,0.01042844968247536
225.0000000000025,16.82281915583023,1.036059686282357,0.00910504543427848
226.10000000000252,16.855985986572115,1.0352078473048838,0.009099819299771994
227.20000000000255,16.889218183941665,1.039489280774324,0.009087906704078996
228.30000000000254,16.92262904514654,1.041060477533248,0.007788838686871635
229.40000000000256,16.956050525707813,1.0459911594882914,0.00632447301087069
230.5000000000026,16.989333371491412,1.0496030123539268,0.005180640159005989
231.60000000000258,17.022483284060357,1.0547486281750529,0.004860567759748413
232.7000000000026,17.055963287695665,1.0564975234213938,0.0034182392145094553
233.80000000000263,17.089599391977924,1.0615919850038231,0.0009963202074843025
234.90000000000265,17.122445252444017,1.0655707107405228,-0.00017602433412822194
236.00000000000267,17.155448042182428,1.0688992543598648,-0.0008861309594569988
237.10000000000267,17.189190526447206,1.07166943881398,-0.0017211352367745292
238.2000000000027,17.222284600082418,1.0777800394524006,-0.002398256510344865
239.3000000000027,17.255373752862777,1.0807629061222883,-0.0037217199436083703
240.4000000000027,17.28856714601769,1.0870956895697546,-0.005209045795855793
241.50000000000273,17.321866650932932,1.0906357612324435,-0.00661193356049683
242.60000000000275,17.35512001002464,1.095728862298997,-0.0077031229020132486
243.70000000000277,17.38807938445234,1.1005738156291818,-0.009242538565345626
244.8000000000028,17.42148768921898,1.1036430980989542,-0.011144406609688406
245.9000000000028,17.454487144581144,1.1107627307130805,-0.01254408889940617
247.0000000000028,17.48801373448258,1.1150232618196472,-0.013956703478462895
248.10000000000284,17.520955231235874,1.1187653568621854,-0.015398172067869087
249.20000000000283,17.554312108281568,1.1253414654966938,-0.016245468550659226
250.30000000000285,17.587773815473295,1.1295915037857518,-0.01832055383111708
251.40000000000288,17.620750129129082,1.1342976774102493,-0.020607632231065764
252.5000000000029,17.6541638217657,1.1405139467194738,-0.023289434960879873
253.60000000000292,17.686700135631003,1.1430872341817435,-0.026334122911660263
254.70000000000292,17.720241964073534,1.149351092465419,-0.02865040179956857
255.80000000000294,17.75333000000009,1.153726532384112,-0.030069503739857062
256.90000000000293,17.786639552731877,1.1589199339886815,-0.03158961845934405
258.00000000000296,17.820000000000093,1.1622931407095973,-0.03422986801847472
259.100000000003,17.852915324149365,1.1680502493543432,-0.03718504346645535
260.200000000003,17.886211187597162,1.1759149979406647,-0.040762795972551835
261.300000000003,17.919253795058367,1.1802753375947015,-0.04341122469047409
262.40000000000305,17.95223959866044,1.1887439078395658,-0.04658849800222509
263.50000000000307,17.98581633261717,1.194113330363006,-0.049199460729855815
264.6000000000031,18.019025901302275,1.2020406912537378,-0.052782039051936014
265.7000000000031,18.05223907893381,1.2078183859467595,-0.05588671404540868
266.8000000000031,18.084952617778594,1.2137937953513283,-0.06011099491697047
267.9000000000031,18.11819324054674,1.2214137704053907,-0.064430409594042
269.0000000000031,18.15174136390347,1.2273719005904278,-0.06969889087627834
270.10000000000315,18.184824924652997,1.22848838337582,-0.07345285283633851
271.2000000000032,18.21784020261261,1.2345117618682657,-0.07690136766588296
272.30000000000314,18.25107777906653,1.2405958454816703,-0.08072968597444596
273.40000000000316,18.284047668331677,1.2444364262733054,-0.08542567911505072
274.5000000000032,18.317326128492304,1.2490350522668074,-0.08960019028073818
275.6000000000032,18.35065155582883,1.2520445412037016,-0.09406355925583076
276.70000000000323,18.383888254606653,1.2575781787625024,-0.0986590351463601
277.80000000000325,18.417193755262296,1.2600071966264839,-0.10450011421136995
278.9000000000033,18.450329397310952,1.2605634183615622,-0.10978313562433417
280.0000000000033,18.483528201505692,1.2615545211110353,-0.11530773708753461
281.1000000000033,18.51641942446356,1.2649369133746373,-0.12126094901739659
282.20000000000334,18.54981913036456,1.2672816506620685,-0.12653679664785944
283.30000000000337,18.582833477576735,1.267380530183003,-0.13274876199922847
284.40000000000333,18.616160913493747,1.2689890517698879,-0.13994167024108695
285.50000000000335,18.649364628751687,1.265634924127113,-0.14562242356752897
286.6000000000034,18.682684078825694,1.2669018390251334,-0.15188778408452652
287.7000000000034,18.715696333953616,1.2637656869141056,-0.1589961220405227
288.8000000000034,18.748928488058596,1.2630404331764036,-0.1668038308920856
289.9000000000034,18.782373298531986,1.259903653755061,-0.17559811908229506
291.0000000000034,18.81548531359761,1.2566603129053904,-0.1826849392448402
292.10000000000343,18.848691747419448,1.2538795578352757,-0.19215053278299532
293.20000000000346,18.881755806282957,1.251687207898659,-0.20124387135742605
294.3000000000035,18.91532148255185,1.2537154368848713,-0.21057697308894419
295.4000000000035,18.948279450822923,1.2512113918664816,-0.22084654300626738
296.5000000000035,18.981681596681895,1.248938875672548,-0.23096295294250613
297.60000000000355,19.015025627817785,1.2531143252104537,-0.24142096510773792
298.70000000000357,19.04780976780958,1.2621222470293874,-0.25351224617706825
299.8000000000036,19.081074379211437,1.2739654242425922,-0.26516171922836484
300.9000000000036,19.1144920920804,1.2930880001090261,-0.27829897590676245
302.0000000000036,19.147695981265553,1.3179238990177506,-0.2922783637723607
303.1000000000036,19.180835808483167,1.343888578608802,-0.3078521853115981
304.2000000000036,19.21432234008451,1.3807411975930228,-0.3207465371211793
305.30000000000365,19.24737217971174,1.4131258435664182,-0.33525579925369
306.4000000000037,19.280795846206804,1.4510057000811831,-0.3496662286230867
307.5000000000037,19.314287043849646,1.4875953793254282,-0.3665521971300203
308.60000000000366,19.347396155807708,1.524801106470496,-0.38338500895021754
309.7000000000037,19.380544468116415,1.5567134701594898,-0.4001300326484256
310.8000000000037,19.41408733036528,1.5861314172392647,-0.4140751998302683
311.90000000000373,19.447420623449588,1.6084189354421041,-0.42894963827403076
313.00000000000375,19.481059064444285,1.6275992077397212,-0.4424205729536923
314.1000000000038,19.514169759210255,1.6394322440133293,-0.45692776276000036
315.2000000000038,19.54768921752954,1.6464769654319047,-0.4700402452482302
316.3000000000038,19.58114266182195,1.6474121615428259,-0.484425378954894
317.40000000000384,19.614611992992206,1.6411401482624375,-0.4959795775115001
318.5000000000038,19.648016298168358,1.6313552580205566,-0.5079878242370781
319.60000000000383,19.68170875032926,1.6131106036426937,-0.5178585633687036
320.70000000000385,19.7147193299383,1.5986770747206234,-0.5283586054620808
321.8000000000039,19.747980204925888,1.5777566043542786,-0.5371345048542255
322.9000000000039,19.781903116994144,1.5509822965745597,-0.5467432521238282
324.0000000000039,19.815219182165546,1.5264032482537255,-0.5544762167870876
325.10000000000394,19.848474625841853,1.4998262751187597,-0.5622623046686641
326.2000000000039,19.882042703776463,1.4731059056790075,-0.5698486071723856
327.30000000000393,19.91541556038218,1.4466428813351482,-0.5768478787264928
328.40000000000396,19.94880414461883,1.4226090706943175,-0.5827304568634384
329.500000000004,19.98204773440846,1.396895838092508,-0.5879318837042633
330.600000000004,20.01563451842797,1.3744164795591973,-0.5931680774653545
331.700000000004,20.04915770272919,1.3501483579999414,-0.5988854368340912
332.80000000000405,20.08234736663559,1.332006192655321,-0.6038633214677822
333.90000000000407,20.115771706880484,1.307764171083279,-0.608742420311918
335.0000000000041,20.14932801412264,1.2898317333093317,-0.613657978938901
336.10000000000406,20.18251330454094,1.2696954498510484,-0.6174152165160187
337.2000000000041,20.21617388594878,1.2541914009415382,-0.6216662354247942
338.3000000000041,20.249496607029606,1.2382724692002616,-0.6256802570104432
339.4000000000041,20.283185476091628,1.223503979120907,-0.6292510358532533
340.50000000000415,20.316868541964165,1.2084555455806048,-0.6335671319495031
341.6000000000042,20.35002791055001,1.1928745561622118,-0.6369642266322031
342.7000000000042,20.38361219050602,1.1790172942496548,-0.6390167236947262
343.80000000000416,20.417131550906948,1.1680108309399588,-0.6419169180256885
344.9000000000042,20.450526284649374,1.1531499079536656,-0.6431462935030239
346.0000000000042,20.484189513990433,1.1437931035732898,-0.6451219392266725
347.10000000000423,20.518117752700178,1.132987539991654,-0.6482789101460575
348.20000000000425,20.551504604904675,1.1211831547221083,-0.650143644910822
349.3000000000043,20.585015094555686,1.1098594294854474,-0.6523863661386051
350.4000000000043,20.618732702601953,1.1018807028436806,-0.6566715914711954
351.5000000000043,20.652344144923017,1.093108603686904,-0.6582466668751037
352.60000000000434,20.685917043902986,1.082230824063842,-0.6598785797857079
353.7000000000043,20.719593013832302,1.0767417745002643,-0.6611943530892233
354.80000000000433,20.753151654306443,1.065671328116966,-0.662734643154915
355.90000000000435,20.786825893364377,1.061097236675064,-0.663240012017297
357.0000000000044,20.820650520420134,1.0560245037143439,-0.6646971417676362
358.1000000000044,20.854226465147534,1.0473809778102452,-0.6662572534939497
359.2000000000044,20.888169060248927,1.042515773774606,-0.6676883892719983
360.30000000000445,20.921884128196357,1.040155411537186,-0.6701236473439471
361.4000000000044,20.955418597077937,1.0336346632241018,-0.6717676938845396
362.50000000000443,20.989347187538687,1.0281718186077273,-0.6716775082145294
363.60000000000446,21.023020403115737,1.0256440521450336,-0.6730416332970366
364.7000000000045,21.05677022642661,1.0224430978941907,-0.6734408326059711
365.8000000000045,21.0908504000009,1.0221180878288263,-0.6734820402221784
366.9000000000045,21.124435285303573,1.0189799690856904,-0.6748468512333634
368.00000000000455,21.158298337516186,1.0173783975111537,-0.6760005312043598
369.10000000000457,21.19202180976574,1.0146626505377643,-0.676000009236422
370.2000000000046,21.22587449648922,1.0162419597486685,-0.6759724944867176
371.30000000000456,21.259937967830002,1.013780175046521,-0.6774022723761437
372.4000000000046,21.29357280157219,1.0152056039762312,-0.6797315106558957
373.5000000000046,21.327489552713537,1.015227835522213,-0.6804926011643335
374.6000000000046,21.361161477608075,1.0160385114742172,-0.6810498490691121
375.70000000000465,21.395298708005356,1.0166073625156213,-0.6821749098286918
376.8000000000047,21.42929589271608,1.015555240526501,-0.6810536233283124
377.9000000000047,21.463218375830046,1.0184840486423195,-0.6810524149066479
379.00000000000466,21.496958729098125,1.0178446952498423,-0.6823450790144401
380.1000000000047,21.53086980684895,1.0202224924906176,-0.6825186618294565
381.2000000000047,21.565080110794145,1.0232010574471155,-0.6836741206693571
382.30000000000473,21.599011515992544,1.0228791596413078,-0.6849953742750792
383.40000000000475,21.632826291081113,1.0227700012263297,-0.6849919462825307
384.5000000000048,21.666859735651144,1.0213600656966397,-0.6860223472747462
385.6000000000048,21.70115440858028,1.0217211344852877,-0.685013982023261
386.7000000000048,21.734846942247206,1.0226593702521751,-0.6863011769088354
387.80000000000484,21.769026059272857,1.0183337889366806,-0.6862922773435045
388.9000000000048,21.80324225649581,1.0176592193945893,-0.6876152526333823
390.00000000000483,21.83720257395632,1.0189184795430455,-0.6875631150574288
391.10000000000485,21.871534829164347,1.0177019205144564,-0.6889384838441317
392.2000000000049,21.90536009496352,1.01620083500806,-0.6902816210074407
393.3000000000049,21.939453388514963,1.0168508774344633,-0.6902603598869104
394.4000000000049,21.97388095959498,1.0139234679022897,-0.6915897954845782
395.50000000000495,22.007754661105476,1.0123654274521852,-0.692873890935866
396.6000000000049,22.04215318295982,1.0095135393750438,-0.6942141625325928
397.70000000000493,22.076107639568253,1.0051219280306933,-0.6930714778107925
398.80000000000496,22.11045903492146,1.0036799832540642,-0.6930276418727637
399.900000000005,22.144641207255837,1.0003015354892064,-0.6942011685410181
401.000000000005,22.178673436930723,0.9974233216550648,-0.6941872591643361
402.100000000005,22.212722960096592,0.9925844118796017,-0.6931650216476481
403.20000000000505,22.246993269579708,0.9900921228668327,-0.6941984502272116
404.30000000000507,22.280958920396245,0.9857250569987592,-0.6955134257415199
405.4000000000051,22.31532346954567,0.9831450912199416,-0.6981953483807226
406.50000000000506,22.34952833019983,0.9778860020691182,-0.6981502874310723
407.6000000000051,22.383884356219323,0.9704068364460742,-0.6988679492846499
408.7000000000051,22.418155822122582,0.9676186042093793,-0.6994699084464129
409.8000000000051,22.452560988472626,0.9618153821529892,-0.6994692994522214
410.90000000000515,22.486766221742947,0.955913149110871,-0.7007914207746846
412.0000000000052,22.520652016903934,0.9537900562157742,-0.7008292155066176
413.1000000000052,22.555203251791852,0.9470578272416202,-0.7022138168859011
414.20000000000516,22.589669730791915,0.9443486967882948,-0.7041894798889379
415.3000000000052,22.623603615535856,0.9383506168587029,-0.7067240103885437
416.4000000000052,22.65836779773614,0.9328254157151112,-0.7073702902080425
417.50000000000523,22.69289813883899,0.9331796940095707,-0.7083212743558889
418.60000000000525,22.727048157175396,0.9279141853519999,-0.7086882014199416
419.7000000000053,22.761387014533174,0.9250206409645905,-0.709994031907252
420.8000000000053,22.796002875844884,0.9188189578136036,-0.7115035850118101
421.9000000000053,22.829990518779958,0.916685757025295,-0.7113851714364734
423.00000000000534,22.86431421275974,0.9110985032478266,-0.7117497837242097
424.1000000000053,22.898809184886968,0.9085418011147453,-0.7126324223196154
425.20000000000533,22.93342401694461,0.9082734805403252,-0.7130744114863905
426.30000000000535,22.96811232833971,0.9062961402158107,-0.7145721893360655
427.4000000000054,23.00241417547676,0.9033522269917367,-0.7161887121403057
428.5000000000054,23.03686025652737,0.9035228281634708,-0.7174127370006409
429.6000000000054,23.071405500832793,0.9021698088314496,-0.7201021851781384
430.70000000000545,23.1057306355751,0.9020031501172876,-0.7214914572259854
431.8000000000054,23.140246651262864,0.9009483909676533,-0.722849773413587
432.90000000000543,23.17484808509687,0.8988558779579074,-0.7228461157231054
434.00000000000546,23.209544480696646,0.899023192196778,-0.7242261842611617
435.1000000000055,23.244138295373993,0.9006244936698392,-0.7259341765461684
436.2000000000055,23.278699620277656,0.9012910546403351,-0.7278085334545077
437.3000000000055,23.313230454530434,0.9017446879411397,-0.7291913282642071
438.40000000000555,23.347833393160368,0.9033442748748254,-0.7304555296136757
439.50000000000557,23.38211555217454,0.9036280088711531,-0.7320629171056172
440.6000000000056,23.416807706067438,0.9057481187279709,-0.7337295724967103
441.70000000000556,23.451492802589346,0.907255524753807,-0.7351997942380013
442.8000000000056,23.485804543298872,0.9113286675799877,-0.7374383818300192
443.9000000000056,23.520874505608194,0.9120797376110279,-0.7395588702059834
445.0000000000056,23.5552776519309,0.9166296279456221,-0.7411607578192445
446.10000000000565,23.59009185022745,0.9215504279401842,-0.7430083418559694
447.2000000000057,23.62490777256396,0.9227522969214885,-0.7449250844326696
448.3000000000057,23.65933491073912,0.9266419250319712,-0.7464888578842976
449.40000000000566,23.694016277386776,0.9292024016586249,-0.7495762419527514
450.5000000000057,23.72869153520787,0.9306498703438391,-0.7518138253009061
451.6000000000057,23.763622165175814,0.936958137615562,-0.7544119529298472
452.70000000000573,23.798266432108417,0.9415757498497321,-0.7581966937730424
453.80000000000575,23.83304316401619,0.9454507488148743,-0.7605341318476202
454.9000000000058,23.867829649342426,0.9516811529747556,-0.7642078640011651
456.0000000000058,23.90264492346962,0.9578278494857869,-0.7691269840449921
457.1000000000058,23.9376284139028,0.9655901834476149,-0.771486874735539
458.20000000000584,23.972193947796747,0.9715545309655367,-0.7745462538503292
459.3000000000058,24.00706947740352,0.9796881491376117,-0.7782179597295134
460.40000000000583,24.04194722594796,0.9846223492450916,-0.7826462906972078
461.50000000000585,24.0767155988403,0.9937530783159763,-0.7871345696533614
462.6000000000059,24.111733585097934,1.005511208087838,-0.7923033755462905
463.7000000000059,24.14631594955916,1.0145585973979592,-0.7965868413376977
464.8000000000059,24.18144632801244,1.0221673582266746,-0.8001581915070135
465.90000000000595,24.216009175302762,1.0315813972426973,-0.804408779725704
467.0000000000059,24.251210981163215,1.0422721709925546,-0.8089023722877351
468.10000000000593,24.286146902490746,1.0517581570047687,-0.8121859948634467
469.20000000000596,24.320884797424114,1.0654396195384876,-0.8166960816235145
470.300000000006,24.355854127367,1.0747024885273673,-0.8200642076078926
471.400000000006,24.39067288900494,1.0859729596513037,-0.8237307880750033
472.500000000006,24.42582471575788,1.0979113041905588,-0.8270768635605021
473.60000000000605,24.460577683633343,1.1101839207281756,-0.8315772711117044
474.70000000000607,24.495753752072932,1.1168887992326846,-0.8361158356130063
475.8000000000061,24.53069821406959,1.1277058223034777,-0.8404382272537654
476.90000000000606,24.565682290441426,1.141162821555903,-0.8441297072306475
478.0000000000061,24.60038313868232,1.1481325503732895,-0.8498208366489557
479.1000000000061,24.635921642131922,1.1598006951466964,-0.853891147181566
480.2000000000061,24.670650656266996,1.1671018371209914,-0.8578590906384989
481.30000000000615,24.705788702433306,1.1780585711250615,-0.8621519479874502
482.4000000000062,24.740909123311756,1.1889842644288937,-0.8648776732035115
483.5000000000062,24.775928946180773,1.1947609108889228,-0.86908628912267
484.60000000000616,24.811240711319382,1.2026909623602895,-0.8724245274651188
485.7000000000062,24.846086620314217,1.212262254614721,-0.8773752025226269
486.8000000000062,24.881632132640558,1.21797669764397,-0.8815739775283205
487.90000000000623,24.916680976190662,1.2259954259156944,-0.8856682796651407
489.00000000000625,24.95166385538131,1.2332264269140767,-0.8898938874703584
490.1000000000063,24.98670287690217,1.2388063758627066,-0.89394527848992
491.2000000000063,25.021847850782333,1.2465966907879895,-0.8988332402611228
492.3000000000063,25.05679200429391,1.2527182135434496,-0.902723040912528
493.40000000000634,25.0920929312544,1.259506509531739,-0.9056224324247095
494.5000000000063,25.127266703397684,1.2668202613462034,-0.9097529096457713
495.60000000000633,25.16222050389358,1.2730123172772525,-0.9129861823202496
496.70000000000636,25.197430060940174,1.2795988264988014,-0.916132474790027
497.8000000000064,25.232518349914947,1.28861665955074,-0.918922829543336
498.9000000000064,25.267630914446524,1.2956392433771273,-0.9228272298874791
500.0000000000064,25.30293800399057,1.301835606803706,-0.9267917114482058
501.10000000000645,25.337927332663508,1.3109083200225238,-0.9293019226029084
502.2000000000064,25.37348780948282,1.3169115236620976,-0.9315863498521129
503.30000000000643,25.408375604802217,1.326312321242413,-0.9350320485710197
504.40000000000646,25.443636647629702,1.334519833340484,-0.938125027094546
505.5000000000065,25.47861437820328,1.3438667657867094,-0.9400832433451858
506.6000000000065,25.51432334282829,1.3493401296591767,-0.9433179324460288
507.7000000000065,25.549611509378686,1.3582068046490643,-0.9477738702964236
508.80000000000655,25.584946593496074,1.3657748189898768,-0.9496315580098367
509.90000000000657,25.619877103319038,1.3734129195742306,-0.9499937735290316
511.0000000000066,25.655104310293822,1.380997047039683,-0.9516308977483554
512.1000000000065,25.690360964124626,1.388786958677272,-0.9544473114473102
513.2000000000066,25.725712321801886,1.3948854009655978,-0.9563412953074919
514.3000000000065,25.761228343739333,1.4016161555529656,-0.9578724085777055
515.4000000000067,25.796416033098602,1.4058449522469114,-0.959304023093055
516.5000000000066,25.83178359245006,1.413793554487124,-0.9623377182712263
517.6000000000067,25.86713644216972,1.4175361630722814,-0.9638154256575842
518.7000000000066,25.902470734139676,1.4225592593930152,-0.9648541277388194
519.8000000000067,25.937728040578428,1.430289135808988,-0.9668066799192312
520.9000000000067,25.973231631273972,1.4364550988783418,-0.9668904539808278
522.0000000000067,26.008430021751845,1.4406890550201663,-0.967878814342022
523.1000000000067,26.043812901723538,1.444973409712478,-0.9682147965810373
524.2000000000068,26.07948519577925,1.4509876484099746,-0.9697392967897178
525.3000000000068,26.114716356074123,1.4567725849319777,-0.971055008911256
526.4000000000068,26.150111487615735,1.4608854402658582,-0.9723267818901116
527.5000000000068,26.185389545062243,1.467336897286774,-0.9739821951129786
528.6000000000068,26.22087596801723,1.4743664060471942,-0.9753623976350245
529.7000000000069,26.256049402558343,1.4828299632971027,-0.975064744140353
530.8000000000068,26.291726398898277,1.490732577321584,-0.9760794886729021
531.9000000000069,26.327094979562677,1.50174315996273,-0.9776545537855896
533.0000000000068,26.36285904527648,1.507657657562226,-0.9799852811678775
534.100000000007,26.39817418225794,1.519176844240879,-0.9808197731294865
535.2000000000069,26.433879846669686,1.5286020566086793,-0.9813966157606173
536.300000000007,26.469120360943844,1.5362672172213696,-0.9834009227692118
537.4000000000069,26.504428542528306,1.5490017740174502,-0.9851418653878254
538.5000000000069,26.54006475094957,1.564547765426647,-0.9865493680703077
539.600000000007,26.5756175803248,1.5781508828651107,-0.9865298313653366
540.700000000007,26.611173574313785,1.591171911305195,-0.9878275341285834
541.800000000007,26.64647910913744,1.6099400463860312,-0.9891529180702969
542.900000000007,26.682057881166845,1.617804196938179,-0.990639530542174
544.000000000007,26.71782080955877,1.6339166222292854,-0.992151614797121
545.1000000000071,26.753422089915453,1.6471485077940677,-0.9941960802399681
546.2000000000071,26.78913781170719,1.6631138479908918,-0.9964720325740029
547.300000000007,26.824508523729154,1.675408646436511,-0.9979374461660506
548.4000000000071,26.860032012121387,1.6888168200691176,-0.9979790041367207
549.500000000007,26.89591888317746,1.7010215537558429,-0.9992995456928782
550.6000000000072,26.931455083452832,1.7154052658359522,-1.001375713559268
551.7000000000071,26.966863308852666,1.727273782733481,-1.0028579648050422
552.8000000000072,27.00263072655351,1.7388474070373647,-1.0039549749419194
553.9000000000071,27.038348949341422,1.7519026356153942,-1.0052776534951584
555.0000000000072,27.07387001571311,1.7596858307570498,-1.0063179432975038
556.1000000000072,27.109636734914595,1.7684777518182873,-1.0081042329413665
557.2000000000072,27.14505949623306,1.7769269086195458,-1.0108323445525076
558.3000000000072,27.18094538905796,1.7842692234171669,-1.012531917853119
559.4000000000073,27.21678943518837,1.7903566863592564,-1.0138722246235106
560.5000000000073,27.252363706425452,1.7978178271487446,-1.0164511658822732
561.6000000000073,27.288264244090914,1.8052420757435566,-1.0177023597564974
562.7000000000073,27.32391687840644,1.8118830286950414,-1.0191972526856174
563.8000000000073,27.35969633182863,1.8189617984855282,-1.0206250300148705
564.9000000000074,27.3951735065408,1.8261268054165893,-1.0233360808601022
566.0000000000074,27.430964070372937,1.8386898134557914,-1.0251342237385308
567.1000000000074,27.466670663164454,1.846232354636142,-1.0262357879427682
568.2000000000073,27.502721303375413,1.8582308111317687,-1.0285826215272347
569.3000000000073,27.538320782015564,1.8704279264111747,-1.0300629528432914
570.4000000000074,27.574166252003632,1.8851831677447843,-1.031598507294472
571.5000000000074,27.610189918290573,1.901760979884071,-1.0328959405505005
572.6000000000074,27.64594677380168,1.9158401457396865,-1.035347646685297
573.7000000000074,27.68182162847162,1.9351874859196816,-1.0374363277549379
574.8000000000075,27.717460149960573,1.9518727566809841,-1.039773747279272
575.9000000000075,27.75306956873037,1.9730949996522653,-1.039472179273035
577.0000000000075,27.78915076859459,1.9928741086454629,-1.0425576621078751
578.1000000000075,27.824695182790897,2.0164900950963336,-1.0439834779265604
579.2000000000075,27.860734909621343,2.0393698027604095,-1.0454288104169844
580.3000000000076,27.896716650194918,2.0667335804868716,-1.0486382842375677
581.4000000000076,27.93286688292312,2.0935084847962266,-1.0509953969373074
582.5000000000076,27.968543789140377,2.1236680352756823,-1.0541968640515673
583.6000000000076,28.004421024641818,2.1547027572990425,-1.0561713767110938
584.7000000000077,28.040612878248673,2.1899676277211606,-1.0577384192617862
585.8000000000077,28.07616306964049,2.2200904226980347,-1.0607673963050606
586.9000000000076,28.112121485432255,2.2555103515645025,-1.0628604998588487
588.0000000000076,28.148260182771736,2.2945348459995905,-1.064382310511713
589.1000000000076,28.184494282904957,2.338733025727717,-1.0669843549601183
590.2000000000077,28.220371616483956,2.3819725230656035,-1.0693273105440197
591.3000000000077,28.256444355297713,2.436521075600295,-1.072157497875244
592.4000000000077,28.292684536457436,2.4938774793615397,-1.074763297741173
593.5000000000077,28.328502453520475,2.5551155141516144,-1.07819524871858
594.6000000000078,28.364692871644582,2.621800497405438,-1.0800088842481363
595.7000000000078,28.40068492729951,2.6907296145635806,-1.0833011511630533
596.8000000000078,28.436832764515007,2.7626625813390655,-1.084777673569124
597.9000000000078,28.472910439941668,2.8292202104253414,-1.0876047731396068
599.0000000000078,28.509162436667207,2.8952456949042156,-1.089834832434089
600.1000000000079,28.54539096548762,2.94053735907168,-1.0929435291446992
601.2000000000079,28.581523499151647,2.954926475667868,-1.0956290550252197
602.3000000000079,28.617890526364977,2.914574836495456,-1.0994083865141429
603.4000000000078,28.65379347705843,2.809832180469596,-1.1049214374805243
604.5000000000078,28.689987101132974,2.6963051428972284,-1.106829059789895
605.6000000000079,28.725814680585643,2.5820166684337176,-1.1102763102299495
606.7000000000079,28.761991051903788,2.4671941710105467,-1.1136851877823384
607.8000000000079,28.797813557639866,2.3726872698604273,-1.1164205002942662
608.9000000000079,28.833969825488232,2.2937974607136264,-1.1186005113651407
610.000000000008,28.870051616264647,2.2201137956396577,-1.121977564178545
611.100000000008,28.906234752467604,2.1631762122859,-1.1249759212170818
612.200000000008,28.94222222416541,2.108131791929915,-1.1276939607132777
613.300000000008,28.978235464531522,2.056705881617544,-1.1316955823303783
614.400000000008,29.014367912819992,2.0142773077419274,-1.134607603541645
615.5000000000081,29.050337770525637,1.9687250923613353,-1.1371999309350662
616.6000000000081,29.08640538474428,1.929173802644803,-1.1391251483516256
617.7000000000081,29.12282981785687,1.8951218180876959,-1.1422735052867172
618.8000000000081,29.158498948837735,1.8591764800038035,-1.144605075911806
619.9000000000082,29.194896291247908,1.838744098855369,-1.1459948474846673
621.0000000000082,29.230873935842435,1.8198228245788262,-1.1475683684203037
622.1000000000081,29.26700461786345,1.8045131876383025,-1.150850019242005
623.2000000000081,29.30328103789391,1.8049044404655687,-1.1517310618557888
624.3000000000081,29.339327204705405,1.805421899783169,-1.1532577514151878
625.4000000000082,29.375641961474134,1.8161139347471038,-1.154670770905812
626.5000000000082,29.411565846574213,1.8274735358003251,-1.1559714828727667
627.6000000000082,29.447921311905052,1.8381554961291997,-1.1573153157504557
628.7000000000082,29.484180343577133,1.8449614805958967,-1.157299703457829
629.8000000000083,29.51996686279412,1.8491598809811605,-1.1576270075702007
630.9000000000083,29.556457945851314,1.8562856314916576,-1.1587403219956864
632.0000000000083,29.59268564679835,1.8594215746273075,-1.1600378020590072
633.1000000000083,29.628967394103377,1.8645794183415583,-1.1614145179990554
634.2000000000083,29.665093352447247,1.8701744956832191,-1.1603409651930554
635.3000000000084,29.701206080948957,1.8771977470410033,-1.1616792850092326
636.4000000000084,29.737430781830373,1.885385090959281,-1.1616124825161203
637.5000000000084,29.77389565087813,1.8950740613965347,-1.1626643525016434
638.6000000000083,29.809768837854776,1.9085361672903374,-1.1629200554710568
639.7000000000083,29.84618150847332,1.9219531388785152,-1.1639816660930307
640.8000000000084,29.88248537031409,1.9380580109227852,-1.1646393714434229
641.9000000000084,29.918860613546126,1.9515417683278105,-1.1646274635333764
643.0000000000084,29.954918796690567,1.9707025227188038,-1.1659610300983165
644.1000000000084,29.991323687157315,1.9898518164976269,-1.166143968374071
645.2000000000085,30.027448365476435,2.0088753093548464,-1.1673217130045295
646.3000000000085,30.063744574361476,2.0257536166298173,-1.169415713893788
647.4000000000085,30.099932316287962,2.05059082602333,-1.1712301215711527
648.5000000000085,30.136147832226943,2.0751492032862324,-1.1725146087412317
649.6000000000085,30.17260978931116,2.102992816004505,-1.172599949335082
650.7000000000086,30.208617216929415,2.1297731567991685,-1.173164204382756
651.8000000000086,30.245217360791095,2.162653378492072,-1.1754754586163583
652.9000000000086,30.28128090149066,2.1925894393559,-1.1764260191930611
654.0000000000086,30.318025023205976,2.2349726958591947,-1.1783804532246887
655.1000000000087,30.3542430025698,2.2753712783773716,-1.1800850253588075
656.2000000000087,30.390505224564134,2.3140145058634545,-1.18193956757198
657.3000000000086,30.42680396487527,2.3585265914148366,-1.1847284018611526
658.4000000000086,30.463087577735656,2.405817850507905,-1.1860616932177654
659.5000000000086,30.49959608721169,2.45461772974254,-1.1860227944724713
660.6000000000087,30.53611357025853,2.5013752550901542,-1.1875921680391484
661.7000000000087,30.57231979363628,2.5462185151087207,-1.1894031424894993
662.8000000000087,30.608818950097294,2.593339329567826,-1.1909084747033583
663.9000000000087,30.64510084986461,2.642315574364719,-1.1933193162153777
665.0000000000088,30.681363896238533,2.690345732808089,-1.195722099097047
666.1000000000088,30.71785253179479,2.735149442546293,-1.1972011222460228
667.2000000000088,30.754458625797437,2.784994641790705,-1.1997343432760172
668.3000000000088,30.7909125517164,2.833761375150458,-1.2014500383701803
669.4000000000088,30.82728212390332,2.8816692656510137,-1.2046859475757428
670.5000000000089,30.863796024460743,2.933132017996408,-1.2065676962684018
671.6000000000089,30.900164425553374,2.987318426132294,-1.2098527533581787
672.7000000000089,30.936888482445923,3.0446974149576884,-1.211992929944758
673.8000000000088,30.973261226667645,3.1086448821987553,-1.215096486123333
674.9000000000088,31.009515374387423,3.1758599122142743,-1.2186401575381156
676.0000000000089,31.04609030675485,3.2560760182650754,-1.22245460546119
677.1000000000089,31.08260481433564,3.3366110483936455,-1.2253448893894414
678.2000000000089,31.118956494560788,3.4263742262042007,-1.2281787987028983
679.3000000000089,31.155529383677976,3.5273365210707595,-1.2319737518272262
680.400000000009,31.19220730059574,3.637064636397777,-1.2366691718967209
681.500000000009,31.22846304438801,3.7537518565289862,-1.2406464480824702
682.600000000009,31.265074248737537,3.884190196395924,-1.2432519881326716
683.700000000009,31.30201112759929,4.022839520336582,-1.2468861517463665
684.800000000009,31.338357265099027,4.154499623720844,-1.2513725183412117
685.9000000000091,31.374889344304865,4.260343917116823,-1.2561440051217763
687.0000000000091,31.411418282256623,4.29448546775688,-1.2612820274634258
688.1000000000091,31.448244711160616,4.213682037576795,-1.2654270998786594
689.2000000000091,31.484781319220293,4.101084386984126,-1.2705007064118643
690.3000000000092,31.521160797131188,4.031003984143349,-1.2748913073636694
691.4000000000092,31.557521963120863,4.006272046749114,-1.2797131321277875
692.5000000000091,31.594092761654522,4.010515749474543,-1.2853267512005475
693.6000000000091,31.630483691920492,4.038439018653146,-1.2907093170266526
694.7000000000091,31.666942014702993,4.079829117606105,-1.2958552745414997
695.8000000000092,31.703354134281774,4.130528692627268,-1.3010951256723362
696.9000000000092,31.73969127595935,4.194397455140513,-1.3067290277785917
698.0000000000092,31.77620945705965,4.2625213224018195,-1.3135910521034289
699.1000000000092,31.812835498528344,4.330698790823408,-1.3209710060073139
700.2000000000093,31.84956039718957,4.4072978074071925,-1.3268747268305265
701.3000000000093,31.8858819102901,4.4863212134705455,-1.3327117551929395
702.4000000000093,31.922604996552767,4.568414624384047,-1.3393217501773105
703.5000000000093,31.95907761881099,4.652382165770357,-1.3458268879987338
704.6000000000093,31.99568407708758,4.739346667723268,-1.352593141569196
705.7000000000094,32.03220607761304,4.828898357772043,-1.3596155601237183
706.8000000000094,32.0688998658241,4.9240013683543085,-1.3677111515960587
707.9000000000094,32.10537492961115,5.016827290605295,-1.3748678816624036
709.0000000000093,32.1418580462401,5.11210251263156,-1.3818298278985024
710.1000000000093,32.17877323636734,5.208979555458898,-1.390717634997766
711.2000000000094,32.21534394608325,5.311645931649104,-1.398522046271061
712.3000000000094,32.251727160319746,5.410320751718384,-1.405676149302574
713.4000000000094,32.28875086076731,5.51186751729338,-1.4135362427641849
714.5000000000094,32.325115470925034,5.621694363989959,-1.4226018075801288
715.6000000000095,32.36185991443139,5.728301230100576,-1.4332420956805056
716.7000000000095,32.39841025673465,5.837928686766532,-1.4428620230899418
717.8000000000095,32.435285323351756,5.949818675998912,-1.4514524504468023
718.9000000000095,32.471892137784344,6.0679506043483755,-1.461212746797083
720.0000000000095,32.508548994123466,6.1854078558496655,-1.4708453537832664
721.1000000000096,32.54525904821589,6.299772870292915,-1.480916108571456
722.2000000000096,32.58195696630084,6.415622433203495,-1.4915049298699423
723.3000000000096,32.61920777613449,6.541658782095792,-1.5019212151798635
724.4000000000096,32.655699388711916,6.662185254413613,-1.5120418576001238
725.5000000000097,32.692703518241444,6.785223061415271,-1.523493736098683
726.6000000000097,32.729496261156726,6.912971478290666,-1.535282021375
727.7000000000096,32.766334012849576,7.041109339027046,-1.5466786983022955
728.8000000000096,32.802915859737006,7.164994163952723,-1.5597674531945342
729.9000000000096,32.8396348833031,7.291197771346907,-1.5709568357197505
731.0000000000097,32.876718382609724,7.428265114172661,-1.5832369148915655
732.1000000000097,32.91336374994159,7.556419870312689,-1.5962828601393033
733.2000000000097,32.950211043096644,7.690334928680228,-1.609491855905282
734.3000000000097,32.986931569633526,7.821414839987986,-1.623132195529235
735.4000000000098,33.02408443104527,7.952635344554523,-1.6379176291107802
736.5000000000098,33.06093142657277,8.08448077145755,-1.6506937862202333
737.6000000000098,33.09766605181516,8.208693445361806,-1.6648351517144104
738.7000000000098,33.13485056761178,8.338930400366436,-1.6791078972522469
739.8000000000098,33.17143529506469,8.463142719054895,-1.6942689892269867
740.9000000000099,33.20812034231242,8.589026111487172,-1.7099915503131733
742.0000000000099,33.24517205200296,8.708322645623847,-1.7264611808631125
743.1000000000099,33.28215947872764,8.822206180446102,-1.7437655831702497
744.0000000000099,33.31209624308634,8.910526373826956,-1.7574211182089954