File: 01_Data/EIFS_Coating/STA/N2/10K_min/EIFS_Coating_STA_N2_10KData_230918_R2.csv
##Temp./Â°C,Time/min,DSC/(mW/mg),Mass loss/mg
41.0,10.815963614256452,-0.019582948691121427,0.0014275102701626352
42.40000000000002,11.165645383429116,-0.0033912872194603594,0.0022559614349599855
43.80000000000004,11.412589467609154,0.0057777040874680274,0.0012955070779945288
45.20000000000006,11.617683050593378,0.015077680993336617,0.0007206822158911663
46.60000000000008,11.803378024592979,0.017685072694397785,-0.00029260951442999783
48.0000000000001,11.979686271350655,0.025340392397329214,-0.000130072470893694
49.40000000000012,12.147077690347919,0.02788256335713779,-0.0005550482272278501
50.80000000000014,12.309774005179046,0.03242854424964969,0.0001048482028869202
52.20000000000016,12.467193263063749,0.03162479403907259,-0.0010754023375829647
53.60000000000018,12.625599810247296,0.03564740330786442,-0.0025267566022986188
55.0000000000002,12.780463521102265,0.03711650565065927,-0.0025250179625855296
56.40000000000022,12.933902013844245,0.03926970796069518,-0.0024074059484515686
57.80000000000024,13.086895668664061,0.04068662121318156,-0.0024774302061647546
59.20000000000026,13.23817377075692,0.043912803893761065,-0.0036903344502512425
60.60000000000028,13.386843953506178,0.0497167593814567,-0.0012120859726287847
62.0000000000003,13.536230692592335,0.052505815803472355,-0.0020868334140748956
63.40000000000032,13.684960893945375,0.05614839488789358,-0.002507585068266316
64.80000000000034,13.833255335240432,0.058223844623011,-0.004060086577197808
66.20000000000036,13.978841453883332,0.060026576527894226,-0.0031250271948639607
67.60000000000038,14.123233817104317,0.06402674644498552,-0.00538469341239356
69.0000000000004,14.26917000000004,0.06620299913146388,-0.005369944820109218
70.40000000000042,14.411214867450724,0.06804804443603252,-0.005380444298644704
71.80000000000044,14.556323039228507,0.07352598829937862,-0.006278712389955032
73.20000000000046,14.6999323684167,0.07690083879733844,-0.005158968562509081
74.60000000000048,14.84132674711578,0.07902415691819198,-0.00920869070790964
76.0000000000005,14.983343545252703,0.08039853677109554,-0.010488823565036665
77.40000000000052,15.125902693624015,0.08116559000924783,-0.009277910247295296
78.80000000000054,15.266327925287857,0.07823246685044927,-0.010540148110143477
80.20000000000056,15.404271594251151,0.07833808446818225,-0.01040186868153059
81.60000000000058,15.546131438293498,0.07408687802336766,-0.01451560107628902
83.0000000000006,15.685893708859096,0.06596327262949364,-0.013389901655579184
84.40000000000062,15.822827333639903,0.05313696948450586,-0.014742520169967133
85.80000000000064,15.961775438808726,0.04351166251569727,-0.01437961850697178
87.20000000000066,16.10140071136648,0.03366874534891062,-0.013060209399784473
88.60000000000068,16.237998609142203,0.02533299162698266,-0.011720433677635977
90.0000000000007,16.377004902864027,0.024686326545112713,-0.014699490500125645
91.40000000000072,16.513479165806547,0.01795610770670253,-0.016020097931360944
92.80000000000074,16.649778289860055,0.016449488877568808,-0.01668344513104536
94.20000000000076,16.785786539197446,0.012812805499962998,-0.016377254973915623
95.60000000000078,16.92365675256322,0.010336695679947772,-0.01601998198884047
97.0000000000008,17.06163004683595,0.006528268640367374,-0.0160092472730895
98.40000000000082,17.19812873389112,0.0059983006915254045,-0.0160133497108208
99.80000000000084,17.335022820050114,0.00433460622145021,-0.015447564886533538
101.20000000000086,17.471258429092813,0.0037918829007965726,-0.016020196259362685
102.60000000000088,17.60731680965737,0.0020823839018397905,-0.016696249670956842
104.0000000000009,17.742884847402134,0.002307373368728216,-0.016691602190491928
105.40000000000092,17.879955781865533,0.0022171240576169815,-0.017360663914379515
106.80000000000094,18.014609673665824,0.0033583872768148115,-0.01804921585595798
108.20000000000095,18.14935565874305,0.0013650660902067013,-0.017009900368178066
109.60000000000097,18.28565359288971,0.0005277879305871647,-0.017010090059280447
111.000000000001,18.42201735744062,-0.005077765085682362,-0.018398830427312163
112.40000000000101,18.555795863991424,-0.006904185287469389,-0.017339956835452863
113.80000000000103,18.692427671220457,-0.010019938390352312,-0.01861618758286676
115.20000000000105,18.827256484250256,-0.012920988931545141,-0.01862725632176332
116.60000000000107,18.960549909326858,-0.011564770797971802,-0.02015727219451735
118.0000000000011,19.097717233397088,-0.014412207204292926,-0.019319835000063623
119.40000000000111,19.2322879691163,-0.01845798953693434,-0.01931674026450292
120.80000000000113,19.367794662984693,-0.01921354568791167,-0.019318599459231756
122.20000000000115,19.50458269434976,-0.018732730819643884,-0.01833390884028452
123.60000000000117,19.638578327347183,-0.019333947226897408,-0.01832089088779343
125.0000000000012,19.774642604034664,-0.02383936157862787,-0.019649387816297548
126.40000000000121,19.909082177034044,-0.026363486135770442,-0.018331556787121173
127.80000000000123,20.043238113719678,-0.02542160574206087,-0.01731260562240733
129.20000000000124,20.17797590676539,-0.02887233788859289,-0.018659942537892604
130.60000000000127,20.310091301379412,-0.028745003378723544,-0.01965034464538995
132.0000000000013,20.44819841238717,-0.029884776537274282,-0.019647220053615744
133.4000000000013,20.5814627022302,-0.02953499031883844,-0.017672037028363174
134.80000000000132,20.715583581675673,-0.03232193437347308,-0.01799981464486633
136.20000000000135,20.849483882516033,-0.03455715293485451,-0.01931980161662139
137.6000000000014,20.984515966960377,-0.03449128589354711,-0.018660262721479803
139.0000000000014,21.115355907416678,-0.035390197481111496,-0.020965461739276048
140.4000000000014,21.252717731568655,-0.03883634101748901,-0.01999090827320371
141.80000000000143,21.38602738520606,-0.03754796557417017,-0.020960000151181823
143.20000000000147,21.52108547708862,-0.03936693110884182,-0.020299882212813092
144.60000000000147,21.652776656526218,-0.04097034584121073,-0.019640044171655546
146.00000000000148,21.78811719544419,-0.04158436740028071,-0.019640076496803438
147.4000000000015,21.9227630011845,-0.043372265206258254,-0.02096033450387491
148.80000000000155,22.053870023366382,-0.043059564339032796,-0.01833036477700478
150.20000000000155,22.190897640292977,-0.044968478869867656,-0.01967779488916399
151.60000000000156,22.32500483160352,-0.04676851593273401,-0.01844230359770549
153.0000000000016,22.460387110400315,-0.04868071427453313,-0.01900342167299529
154.40000000000163,22.591579354841613,-0.04829380452641541,-0.018360427686969327
155.80000000000163,22.726415033877725,-0.04933438258796197,-0.018330232149392778
157.20000000000164,22.859170000000162,-0.04995591660523546,-0.01932017749909143
158.60000000000167,22.99198530783424,-0.052139323096610735,-0.01994609601049735
160.0000000000017,23.127294410330162,-0.05223055785490294,-0.020639972901445702
161.4000000000017,23.259395993999387,-0.05600211370854313,-0.02063015789774747
162.80000000000172,23.392046315402432,-0.052361683827075955,-0.02063016800000561
164.20000000000175,23.526865533817894,-0.05416675888501077,-0.020630167997614635
165.60000000000178,23.660225202872958,-0.05480293125795144,-0.021240166719344256
167.0000000000018,23.794782713158753,-0.05708601620163756,-0.02060090450676988
168.4000000000018,23.928731688504904,-0.0572330646757615,-0.021949984334275197
169.80000000000183,24.061232659136593,-0.056550059070457515,-0.02096007234138142
171.20000000000186,24.194751358674573,-0.05691630421321903,-0.021961845610177555
172.60000000000187,24.32858070076252,-0.05872632638407582,-0.02228008194857889
174.00000000000188,24.462289250471546,-0.06117610499879378,-0.02097005678748909
175.4000000000019,24.59552495769618,-0.0639336343259096,-0.019650000794914746
176.80000000000194,24.72996256165656,-0.06351523430091732,-0.02162950874250713
178.20000000000195,24.862731106234065,-0.064184103160422,-0.022280221542597012
179.60000000000196,24.995406442731635,-0.06605252496320091,-0.02095926884131938
181.000000000002,25.12966021662445,-0.06501920106401737,-0.02227993228281111
182.40000000000202,25.263004249195205,-0.06838725479749708,-0.020961501785091485
183.80000000000203,25.395141398736598,-0.06728302947299336,-0.021212899722885314
185.20000000000203,25.528577443422925,-0.0676695483335541,-0.02095983072374663
186.60000000000207,25.662413338514494,-0.06827153149038478,-0.02232848572030477
188.0000000000021,25.795157287350698,-0.07007544329465532,-0.022279631214858764
189.4000000000021,25.92798350417182,-0.07110844990885656,-0.02227982451373478
190.80000000000211,26.060427893171113,-0.07292386930592443,-0.02360175096829842
192.20000000000215,26.19439299190864,-0.06986528145951554,-0.022610154690833273
193.60000000000218,26.32907801762717,-0.07155354834541194,-0.02261015699999902
195.0000000000022,26.46072395414338,-0.07249015840913153,-0.022610157026051958
196.4000000000022,26.594372970037156,-0.07248356871408124,-0.02377876356162778
197.80000000000223,26.72705834454891,-0.07523872666501141,-0.023583939175635837
199.20000000000226,26.86007384474397,-0.07504470076639946,-0.021289327474317332
200.60000000000227,26.99311123844225,-0.073163376706332,-0.022925740156349406
202.00000000000227,27.12703242795691,-0.07524213428851922,-0.023270112899957063
203.4000000000023,27.26025227504913,-0.07815243365126445,-0.023922974126800334
204.80000000000234,27.393513930554256,-0.07927182275301292,-0.023895575194344598
206.20000000000235,27.526506757964455,-0.0780980121017325,-0.023932549966370953
207.60000000000235,27.658692194840505,-0.08073957237254592,-0.022609953285274376
209.0000000000024,27.791636944416272,-0.08157847921757067,-0.023930640887498633
210.40000000000242,27.92413002189786,-0.08459516227616715,-0.024919865798972207
211.80000000000243,28.058773347647918,-0.08373969478289567,-0.022609985775538632
213.20000000000243,28.19165615663145,-0.08457975210410096,-0.023917820599752115
214.60000000000247,28.32427385648869,-0.08719447272431369,-0.023618910015169803
216.0000000000025,28.455685881197848,-0.08801988817266815,-0.02326997543234466
217.4000000000025,28.590429689555396,-0.08835822679310579,-0.02459166138993396
218.8000000000025,28.724896244953953,-0.0899540211923755,-0.023702945247212615
220.20000000000255,28.85747533073884,-0.09024495664357834,-0.024589974112098734
221.60000000000258,28.99024307968026,-0.09346481408055163,-0.026115146619575036
223.0000000000026,29.122837263910707,-0.09254209318721718,-0.024589975099830852
224.4000000000026,29.255166478501938,-0.09451934160197606,-0.024589363275062226
225.80000000000263,29.388975924447372,-0.0942148086992749,-0.02457959487278094
227.20000000000266,29.522451996725053,-0.09473529221314836,-0.025248838143828944
228.60000000000267,29.654673238984977,-0.09760433095157195,-0.02392962916361574
230.00000000000267,29.786624837388405,-0.0991418640848789,-0.025239915297735394
231.4000000000027,29.920071025968937,-0.09773844047259006,-0.025899932757150523
232.80000000000274,30.052873784168703,-0.09958973824863482,-0.025899928999992383
234.20000000000275,30.18692403334319,-0.10217269004086016,-0.02590020252084768
235.60000000000275,30.3196848909672,-0.09959819157698302,-0.02457983722349022
237.00000000000279,30.45301676873962,-0.10165038057882292,-0.024549455598255943
238.40000000000282,30.58570440170346,-0.10281690476507421,-0.02590044505344835
239.80000000000283,30.718973489133084,-0.10316776811006467,-0.027219925663382494
241.20000000000283,30.85203473688373,-0.10514753095428353,-0.025243814934332143
242.60000000000286,30.985347235890753,-0.10369996809692617,-0.02523983608684066
244.0000000000029,31.118304627332623,-0.10510338204242675,-0.025580675855133794
245.4000000000029,31.251950994471226,-0.10523788809406298,-0.026559859943831476
246.8000000000029,31.38476797585738,-0.10739828733900203,-0.02655985999999988
248.20000000000294,31.517579115225175,-0.11075272734689845,-0.02655986000621091
249.60000000000298,31.650316926029227,-0.10900094618000589,-0.025177221078305667
251.00000000000298,31.784155149498577,-0.10941953690303596,-0.025252559755444715
252.400000000003,31.917177766469813,-0.11017907694995688,-0.02655987704684959
253.80000000000302,32.04977753047191,-0.1134255293471007,-0.024062903822407833
255.20000000000306,32.18264951741119,-0.11315969422838412,-0.02525041334314526
256.6000000000031,32.316625398358106,-0.11351471045775097,-0.02657584347437325
258.00000000000307,32.44713368177682,-0.1144836750089715,-0.025899813975599706
259.4000000000031,32.58306752176646,-0.11503119971225839,-0.025899814000101884
260.80000000000314,32.716798862403664,-0.11552553175823621,-0.025896396610844974
262.2000000000031,32.84828548711721,-0.1149151992705002,-0.02719761005678123
263.60000000000315,32.98307099354863,-0.1161246073531681,-0.028538579905854178
265.0000000000032,33.11590989743953,-0.11479095426297325,-0.027236363612790804
266.4000000000032,33.25092173545412,-0.11783817595951462,-0.02721924222838057
267.80000000000325,33.38448113828688,-0.11632969516251146,-0.02597978622223085
269.20000000000323,33.51752708901496,-0.1189724141364139,-0.02525019403140316
270.60000000000326,33.6512589771253,-0.1174192627323476,-0.027556439890981554
272.0000000000033,33.78266218756963,-0.12050792823810275,-0.027549859999769666
273.4000000000033,33.91845796355335,-0.12033771825527695,-0.027549822603899266
274.8000000000033,34.04944582939075,-0.12287973866049873,-0.027879856908812783
276.20000000000334,34.185143166064876,-0.12282179465057341,-0.02787986000000009
277.6000000000034,34.31778811703401,-0.12213045519170906,-0.027879859997209433
279.0000000000034,34.45160495335899,-0.12269422328808965,-0.02823864672879184
280.4000000000034,34.5849591503579,-0.12249729894266292,-0.028868090303526994
281.8000000000034,34.71947133869426,-0.12121394848997724,-0.02754983699007907
283.20000000000346,34.85286779556696,-0.12259024178102651,-0.027549836997915023
284.60000000000343,34.98722739778027,-0.12250080896344029,-0.027879818581698856
286.00000000000347,35.12078603928667,-0.12300781766015301,-0.0278798369990092
287.4000000000035,35.25489150546215,-0.12122285252887433,-0.027879490421531816
288.80000000000354,35.388170516074965,-0.12261897299727798,-0.02853988177940847
290.20000000000357,35.52192592878014,-0.12129236890375217,-0.028539882999874422
291.60000000000355,35.65690196222722,-0.12241302609570126,-0.028536241052822042
293.0000000000036,35.79050173769458,-0.11944616497625482,-0.029251533868783763
294.4000000000036,35.924305525749034,-0.1195576535036198,-0.030520060092258827
295.8000000000036,36.056472027561774,-0.1191141714431676,-0.030456482247764427
297.2000000000036,36.19170787168644,-0.11991054520606759,-0.03151019990934012
298.60000000000366,36.32507755918153,-0.1224270608500233,-0.02890865790363506
300.0000000000037,36.460037960069734,-0.12106708257800203,-0.029223005119086043
301.40000000000373,36.59338069569534,-0.12207650718043239,-0.029859996203699612
302.8000000000037,36.7244672759967,-0.1212577913784465,-0.02985189911160857
304.20000000000374,36.862197010266456,-0.12145608313623635,-0.031172768656521743
305.6000000000038,36.99569812153957,-0.12235354653938768,-0.03248237515624197
307.00000000000375,37.13075982758789,-0.12194661435531784,-0.032170113109164955
308.4000000000038,37.264396749651446,-0.12297160764235882,-0.03217011286634586
309.8000000000038,37.3986304303508,-0.12087140265818763,-0.030849782850578933
311.20000000000385,37.53316238684603,-0.12111679925360197,-0.030850112517590844
312.6000000000039,37.66839912868041,-0.12139509607041332,-0.03148639089952887
314.00000000000387,37.80212973747615,-0.11976962330173291,-0.03216060688858802
315.4000000000039,37.93684751644723,-0.12153338788182433,-0.03479420552764623
316.80000000000393,38.070312917455404,-0.1207137721633762,-0.03352189873702427
318.2000000000039,38.20431775387309,-0.11834731200618198,-0.03347817305816436
319.60000000000394,38.33980706473442,-0.11946837483063599,-0.034139916922980795
321.000000000004,38.47508750473921,-0.11972347626979252,-0.03413991719096021
322.400000000004,38.6092551424828,-0.11630735444047802,-0.0348000660949781
323.80000000000405,38.74421907843042,-0.11716929880626226,-0.036119859265765
325.200000000004,38.8787019397603,-0.11632770811596016,-0.036129640896268356
326.60000000000406,39.013716164514335,-0.1159491984835399,-0.03480329802151205
328.0000000000041,39.14942698646245,-0.11119347216983355,-0.03480097949646144
329.40000000000407,39.28380853769189,-0.11531747171487372,-0.03612005496122572
330.8000000000041,39.41897564562617,-0.11470979037144868,-0.03742181807985778
332.20000000000414,39.550947393622444,-0.11322510694481958,-0.0371768605926146
333.6000000000042,39.68849586361831,-0.11366177848890535,-0.03841722972230954
335.0000000000042,39.82315668610486,-0.11268997314117968,-0.03973990495818214
336.4000000000042,39.95789176509135,-0.11071238589653398,-0.03973990500097635
337.8000000000042,40.09366686339337,-0.10988504384085296,-0.039968723278763996
339.20000000000425,40.22887968825928,-0.11233418654167493,-0.040404956598482755
340.60000000000423,40.36234478194597,-0.11053610623859655,-0.04006131822975867
342.00000000000426,40.49806801896234,-0.10642361113895715,-0.04138044155324705
343.4000000000043,40.63362283696598,-0.10338914275627653,-0.042700040239340264
344.80000000000433,40.769077678038386,-0.10313027935323649,-0.042034794220329186
346.20000000000437,40.90479757927135,-0.10220029260366159,-0.043360178997107646
347.60000000000434,41.03812760452474,-0.09950480307774612,-0.04336017900000044
349.0000000000044,41.174083955084505,-0.09892631292599074,-0.04336014596953541
350.4000000000044,41.30906488478837,-0.1009774263035772,-0.045655574406890054
351.8000000000044,41.445344721294994,-0.10004755416646494,-0.04698002796799372
353.2000000000044,41.577876593422225,-0.09931370201983625,-0.048302665268685985
354.60000000000446,41.714977014142306,-0.0958785271874083,-0.0470054137267768
356.0000000000045,41.850995270575496,-0.09529932672353292,-0.0497298722904409
357.4000000000045,41.986913521176994,-0.09693569230578025,-0.051040154953657435
358.8000000000045,42.12275746340472,-0.09833789552254157,-0.051705443096031534
360.20000000000454,42.258294322614745,-0.09931057355461959,-0.051698724588225886
361.60000000000457,42.393451390585966,-0.1014576659289983,-0.0537269722503364
363.00000000000455,42.52898675626805,-0.10355601859662356,-0.05499917949015032
364.4000000000046,42.66538376746429,-0.10398057482132606,-0.05499347003225541
365.8000000000046,42.800802249731916,-0.10594229460942395,-0.056307793745574486
367.20000000000465,42.93720678476737,-0.10629987836139332,-0.060295107387703606
368.6000000000047,43.07465588432234,-0.10686702023509298,-0.06035594402666922
370.00000000000466,43.20777690894314,-0.1060655733416378,-0.0643390709190026
371.4000000000047,43.346083356410446,-0.10696848379602986,-0.06602307871235213
372.80000000000473,43.48190065234456,-0.10437308079203578,-0.06872710375845292
374.2000000000047,43.61809037411078,-0.10520454166190252,-0.0726671394930527
375.60000000000474,43.7561282201501,-0.10717156450627985,-0.0755269600356181
377.0000000000048,43.892459083897016,-0.1088626176510088,-0.07816736203105323
378.4000000000048,44.02964070746877,-0.10507243108701925,-0.08212661267864751
379.80000000000484,44.164854731112534,-0.10853701325357701,-0.08475215452490747
381.2000000000048,44.30150970815591,-0.10748100018437423,-0.08902369896621565
382.60000000000485,44.437783888857986,-0.1069915978454834,-0.09497129486109257
384.0000000000049,44.575307162814276,-0.10788742310108668,-0.09992277413923256
385.40000000000487,44.71088320139992,-0.10893960657572843,-0.10554377090857114
386.8000000000049,44.848642890400725,-0.11085457265835386,-0.11028588628479596
388.20000000000493,44.985285424734116,-0.10981403484526009,-0.12100059673909458
389.60000000000497,45.12184916542983,-0.1109979401429606,-0.12529258976626556
391.000000000005,45.259274009496174,-0.11141319900953972,-0.1328519460028792
392.400000000005,45.39502047263229,-0.11357889507108632,-0.14196707622969607
393.800000000005,45.532133815457534,-0.11677673832356295,-0.15002982282221655
395.20000000000505,45.66845006503707,-0.12210405749835629,-0.1552645998247426
396.600000000005,45.80359103504277,-0.12136624282598762,-0.16107959913846814
398.00000000000506,45.94162786124634,-0.13024712202601907,-0.17058444642615145
399.4000000000051,46.07753920650315,-0.14011086790901306,-0.17909731821882113
400.8000000000051,46.214952062333005,-0.15058043015480194,-0.18655389860343297
402.20000000000516,46.35217943122137,-0.16135978044319232,-0.1915331691142983
403.60000000000514,46.48769122781586,-0.17338820830013368,-0.1978781365738458
405.0000000000052,46.62373149005745,-0.18688390877653682,-0.20351072637159184
406.4000000000052,46.75945262060394,-0.20091354308945553,-0.20670989126498984
407.8000000000052,46.89675225656157,-0.21193739905246867,-0.21173189112037116
409.2000000000052,47.03358752469864,-0.22355814346904168,-0.21496621096304658
410.60000000000525,47.16986342953153,-0.23266030336360122,-0.21760620473993342
412.0000000000053,47.30576891463059,-0.23882809990632503,-0.22022019735735388
413.4000000000053,47.44295992619618,-0.2472077653369078,-0.22156474485462896
414.8000000000053,47.579170978867786,-0.25050440815296593,-0.2228436654834396
416.20000000000533,47.716482954234316,-0.2541410224404246,-0.22551171796348957
417.60000000000537,47.85403790252056,-0.2595142213834909,-0.2254899113899831
419.00000000000534,47.99101508157603,-0.26150353286442507,-0.22646858823179317
420.4000000000054,48.12797866034116,-0.2619331429986098,-0.2264519750292786
421.8000000000054,48.26657440731585,-0.26512188017405425,-0.22812033513428265
423.20000000000545,48.402558498690084,-0.26661625569894754,-0.2268946224080679
424.6000000000055,48.53954732861364,-0.27040652487678485,-0.22909591141121233
426.00000000000546,48.67614396174255,-0.2688996065852993,-0.23043014491912306
427.4000000000055,48.81371523116685,-0.27069275000314086,-0.23042830243278578
428.8000000000055,48.95105136463328,-0.269930773169085,-0.2317501865716345
430.2000000000055,49.08842421738046,-0.268269971911828,-0.23076039039645924
431.60000000000554,49.227104028855734,-0.2655063167736471,-0.23208468808032423
433.00000000000557,49.36448985105234,-0.26226724241732646,-0.23323081042885407
434.4000000000056,49.501332106139145,-0.260883987633143,-0.23338990803678428
435.80000000000564,49.639265905039814,-0.2653089976424088,-0.23438038683099727
437.2000000000056,49.77773308172547,-0.2651573010694044,-0.23569969689811732
438.60000000000565,49.915947426275146,-0.262641666934073,-0.2353699275790384
440.0000000000057,50.05165670439788,-0.26371883453850176,-0.23570009990863783
441.40000000000566,50.189570791627645,-0.2596388527001994,-0.2370198026099426
442.8000000000057,50.32888639655634,-0.2613221530820291,-0.23700729668166698
444.20000000000573,50.46738071687904,-0.26574653979815177,-0.2380013547766855
445.60000000000576,50.60504646841456,-0.26482804965467266,-0.23931996604236794
447.0000000000058,50.74215318278174,-0.26569399362201795,-0.23932611094158496
448.4000000000058,50.88113909355467,-0.2665398390436782,-0.23799995510209504
449.8000000000058,51.01898708010627,-0.27060424131011596,-0.238989752675566
451.20000000000584,51.157045220213654,-0.27043733425303595,-0.24060630440353137
452.6000000000058,51.293573208558186,-0.27102739995234537,-0.2406397360786694
454.00000000000585,51.43299165025315,-0.27065039655241874,-0.24063984631433222
455.4000000000059,51.57003606896331,-0.26831262353338947,-0.23965823949642306
456.8000000000059,51.7086601680559,-0.27281371120966846,-0.24229015074675653
458.20000000000596,51.84717075489889,-0.2707157847751793,-0.2436069113724595
459.60000000000593,51.98521411641609,-0.27657314116540466,-0.2436081373693737
461.00000000000597,52.12164432013682,-0.2748909060093536,-0.24393769826014378
462.400000000006,52.26185799265135,-0.2736148058313652,-0.24436998497205842
463.800000000006,52.399170930145495,-0.27932637968778495,-0.24569007695030498
465.200000000006,52.537733417076836,-0.27861574886977625,-0.24690836324161003
466.60000000000605,52.67686116726763,-0.2849348066019768,-0.24665432716162394
468.0000000000061,52.8146972228203,-0.2848223378653465,-0.24799986014724773
469.4000000000061,52.952281249199224,-0.28844824142514125,-0.24859018736448935
470.8000000000061,53.090781598788354,-0.288168743222041,-0.24769922334784056
472.2000000000061,53.229267937928086,-0.2881812379634685,-0.24798986673284285
473.60000000000616,53.36713296336901,-0.2928731884220921,-0.24883574800333053
475.00000000000614,53.504715105714105,-0.294637126066736,-0.2480659075453988
476.4000000000062,53.643984726333855,-0.29561142627181347,-0.25117787878268993
477.8000000000062,53.78220410588424,-0.2990849202297472,-0.25117992799998046
479.20000000000624,53.92209209604408,-0.30088175875028744,-0.25117992800191935
480.6000000000063,54.06048205800653,-0.3006099311943251,-0.25126460837063647
482.00000000000625,54.19894799510476,-0.3010316750118007,-0.2531323331283213
483.4000000000063,54.33917103154498,-0.3037535172413146,-0.25315011843610025
484.8000000000063,54.47702087270112,-0.30493732505255,-0.2525007854702359
486.2000000000063,54.61702042852154,-0.3056523465708405,-0.25382220732903793
487.60000000000633,54.75620313203418,-0.31021677568763817,-0.25480984646975946
489.00000000000637,54.896327621717354,-0.3096342487741812,-0.25480985212396456
490.4000000000064,55.03313275917809,-0.3116153164640745,-0.2541593739921377
491.80000000000643,55.173937238990376,-0.3160780164444048,-0.2544794788082352
493.2000000000064,55.313623367123725,-0.32173865418025605,-0.2557901088945158
494.60000000000645,55.45097036081873,-0.3282737582480513,-0.2556354687584652
496.0000000000065,55.590709213573625,-0.3350800440283104,-0.25711007262959606
497.40000000000646,55.72667459771559,-0.3470901862376947,-0.25579004760681734
498.8000000000065,55.86695566223355,-0.3512222256524937,-0.25711014315196
500.2000000000065,56.007009885371346,-0.35528894024597735,-0.2571101210000011
501.60000000000656,56.146193678506066,-0.3569891190070458,-0.25711012099991315
503.0000000000066,56.284942963164575,-0.36041913466627906,-0.25709950869745635
504.40000000000657,56.424816911459146,-0.357877439863054,-0.25710982301814234
505.8000000000066,56.564091993229134,-0.3597528283967475,-0.2571107110910402
507.20000000000664,56.70315121883158,-0.3646149272650363,-0.2584198806490887
508.6000000000066,56.84239309007352,-0.36682878840929223,-0.25841987053678483
510.00000000000665,56.981552850453944,-0.3715241680990671,-0.2584666776690794
511.4000000000067,57.120705926476944,-0.37529547256221396,-0.2584199802036107
512.8000000000068,57.26053004790195,-0.38094466685754846,-0.25914737220643413
514.2000000000068,57.39906407289708,-0.38390930371932597,-0.2597400624382935
515.6000000000067,57.537089377437255,-0.3893521937359057,-0.2587500462581569
517.0000000000068,57.67782788954081,-0.39600581360687936,-0.2576963929852085
518.4000000000068,57.817618374126184,-0.40003311197958014,-0.2590900859864087
519.8000000000068,57.95617440875803,-0.40254698311936177,-0.2590846512636653
521.2000000000069,58.09625791381651,-0.4041841882814856,-0.2604001483849889
522.6000000000068,58.234880164304194,-0.4087741614203255,-0.2600703853013835
524.0000000000068,58.374738880153565,-0.40682153419665923,-0.2600738006204555
525.4000000000069,58.513894010515905,-0.4103883920926501,-0.2611911140270413
526.8000000000069,58.65365287594511,-0.40860475845088295,-0.25940463254883994
528.2000000000069,58.79313498881377,-0.4087030953320214,-0.2595923256575001
529.600000000007,58.93146847690354,-0.4067038875993221,-0.2620954466777987
531.0000000000069,59.072571766036106,-0.4073195670435821,-0.26072998201454833
532.4000000000069,59.2130739718306,-0.4109561780277162,-0.26072841520486545
533.800000000007,59.35292719703026,-0.41153599618958525,-0.26071829503980215
535.2000000000071,59.4921881748611,-0.4117983670386902,-0.26072998476359244
536.6000000000071,59.63274283863199,-0.41336546182300626,-0.26204903689997083
538.000000000007,59.77186537353337,-0.4128448319802671,-0.26007991047866463
539.4000000000071,59.91224357536699,-0.412259058202888,-0.26105707976202686
540.8000000000071,60.05272499817224,-0.4117942597055866,-0.2610608093336504
542.2000000000071,60.193614963778785,-0.41606318000102527,-0.2610631078394734
543.6000000000072,60.33303028487613,-0.41783949929865294,-0.2623804889422616
545.0000000000072,60.47338420549833,-0.4159976490376547,-0.2610812992809337
546.4000000000071,60.61455428420384,-0.4172217793643349,-0.26170764278047853
547.8000000000072,60.75448219551826,-0.419466742766321,-0.2617201857226559
549.2000000000072,60.89362623285884,-0.4192366985674454,-0.26138468962550654
550.6000000000072,61.03408556338598,-0.4209152240870466,-0.26270987794412104
552.0000000000073,61.17480191329533,-0.4207913802675849,-0.2623775760572702
553.4000000000073,61.31483516310725,-0.42030948975716753,-0.26369996953864794
554.8000000000073,61.45558778553996,-0.4210934928304986,-0.2623878330942464
556.2000000000073,61.59639114714161,-0.4252167890250771,-0.26503399218309553
557.6000000000073,61.73564321931942,-0.42399341068142626,-0.2646921003831695
559.0000000000074,61.875969986813736,-0.4285099078140344,-0.2646766529977107
560.4000000000074,62.01615163748738,-0.42892264354650655,-0.26469274520326014
561.8000000000075,62.15703435177316,-0.43053453621124405,-0.2646400300340863
563.2000000000074,62.2963583533853,-0.432190492828175,-0.26435017502929625
564.6000000000074,62.437862162505645,-0.42946598480242026,-0.26431670264156315
566.0000000000075,62.57801534354663,-0.4315065123289712,-0.2636917034730719
567.4000000000075,62.71830173229735,-0.43514251279296334,-0.2651895026658879
568.8000000000075,62.85710527346204,-0.4316329228678315,-0.2647157665022246
570.2000000000075,63.00001027898024,-0.4309734048708591,-0.26730901937480134
571.6000000000075,63.14030452141013,-0.43049640891700536,-0.26599997287879384
573.0000000000075,63.280700021218614,-0.4112363362226179,-0.2659999119998462
574.4000000000076,63.421965173454936,-0.3841335559536192,-0.2659678663916867
575.8000000000076,63.5617864757219,-0.4287836560223206,-0.2673214222969911
577.2000000000077,63.70238076465142,-0.4418902831212179,-0.26599997855650237
578.6000000000076,63.84285318621993,-0.44391472337942495,-0.2659999686850072
580.0000000000076,63.98300985364148,-0.44635195249352955,-0.2673199838303195
581.4000000000077,64.1246463026881,-0.44664353616837693,-0.26732006794520435
582.8000000000077,64.26571365587849,-0.45012902470261884,-0.2673192181531645
584.2000000000078,64.40599029407332,-0.44940512382240194,-0.2673202759779163
585.6000000000078,64.54536426489497,-0.4488302965841562,-0.26801455130118157
587.0000000000077,64.68770943166358,-0.4517660879830281,-0.2669888701009566
588.4000000000078,64.82885465606608,-0.4497670949295438,-0.2682991885774859
589.8000000000078,64.96827737937167,-0.4482171296910067,-0.2692734560316805
591.2000000000078,65.11152526579095,-0.4521733348348811,-0.26962595312524584
592.6000000000079,65.25201437602146,-0.44953723639143606,-0.2696207418845189
594.0000000000078,65.39236011283461,-0.44933812548986296,-0.26962041184574037
595.4000000000078,65.53315758620239,-0.44862354268160054,-0.27094791063408774
596.8000000000079,65.6748754578668,-0.44981733184862716,-0.26962010333682684
598.2000000000079,65.81546903246789,-0.44897016000565015,-0.26810873876129726
599.600000000008,65.95592681798851,-0.4454907193498925,-0.27071959772306675
601.000000000008,66.09655227128243,-0.4497893764188212,-0.271050250749552
602.4000000000079,66.23853523082377,-0.45311888117218024,-0.2707167098679255
603.800000000008,66.38005243386078,-0.45056529466962636,-0.2710501183414551
605.200000000008,66.5200511876981,-0.446093172288182,-0.2713780727528592
606.6000000000081,66.66180770744786,-0.4508082890569107,-0.2713807950656677
608.0000000000081,66.8019354461626,-0.4497411355092742,-0.2746783697623427
609.400000000008,66.94442841938367,-0.4480814349950122,-0.27379996166152587
610.8000000000081,67.08541430522887,-0.4457644038063684,-0.27367426626831204
612.2000000000081,67.22663125620457,-0.4379178859027315,-0.27510990800014623
613.6000000000081,67.36835611242417,-0.43584673819341724,-0.2751097465062582
615.0000000000082,67.51056928158621,-0.4358554164261068,-0.2760834765816087
616.4000000000082,67.65065953663058,-0.44325090539136136,-0.2764300918699605
617.8000000000081,67.79239395814982,-0.4437820461317652,-0.27739975641723236
619.2000000000082,67.9327658981198,-0.4485154571212908,-0.2777529781180834
620.6000000000082,68.0742761787363,-0.4384393737650887,-0.27757736398830746
622.0000000000083,68.21598003724753,-0.4370763175032968,-0.2790616480246686
623.4000000000083,68.35711291602851,-0.43129551328377946,-0.279581895655562
624.8000000000083,68.49967402854,-0.4252730042163604,-0.2803799888834977
626.2000000000083,68.64148129913636,-0.42565141186114586,-0.2817173295828588
627.6000000000083,68.78459669071962,-0.419408223967185,-0.28301109646560985
629.0000000000084,68.92487932489256,-0.4132542391832963,-0.2829955036424714
630.4000000000084,69.06710739967856,-0.40937556882031334,-0.285137759718435
631.8000000000084,69.20966493974738,-0.4003224495168347,-0.2869625149415702
633.2000000000085,69.35127345636826,-0.3955029092339546,-0.28697615288047995
634.6000000000084,69.493611984806,-0.38883586352926014,-0.28961577880236655
636.0000000000084,69.63542269662288,-0.3843828521804906,-0.28995215858266166
637.4000000000085,69.77659923353389,-0.3799218841781049,-0.29123581069015936
638.8000000000085,69.91773091854961,-0.3758502567250446,-0.2927713239679157
640.2000000000085,70.06000360981047,-0.37287850452552695,-0.29387831436885437
641.6000000000085,70.20194096054658,-0.36509139779295086,-0.2965197559159827
643.0000000000085,70.3436592596663,-0.35012864960331,-0.2991523570973311
644.4000000000086,70.48523771711524,-0.34393530819217855,-0.2991493205752356
645.8000000000086,70.62755472137205,-0.33051559769200267,-0.3004715926188868
647.2000000000086,70.76906349515495,-0.32099561580303604,-0.3018214784218407
648.6000000000087,70.91025257029067,-0.30439120386970586,-0.30527615612697856
650.0000000000086,71.05160952129211,-0.29299441904605206,-0.3071773727672724
651.4000000000087,71.19402662320655,-0.2785319129026558,-0.3111255957934027
652.8000000000087,71.33642442186479,-0.262360885540585,-0.31246440681089505
654.2000000000087,71.47835373504995,-0.2445633865703749,-0.3164966456958864
655.6000000000088,71.62055826824503,-0.23036532353869688,-0.31847611935651843
657.0000000000088,71.76323356772109,-0.21203661691656506,-0.32064834668612674
658.4000000000087,71.90613233484702,-0.197282386740123,-0.32438801324624933
659.8000000000088,72.04805116759816,-0.18313484234646382,-0.32933956753354865
661.2000000000088,72.19165095478225,-0.16347987210552906,-0.332519584543415
662.6000000000088,72.33327638951887,-0.13856256744118278,-0.3354979614809803
664.0000000000089,72.47670940310586,-0.12484302340278575,-0.3381842187250217
665.4000000000088,72.61916806839085,-0.10912356840232507,-0.34218981749517274
666.8000000000089,72.7613636425938,-0.09073069495297226,-0.3463712553275218
668.2000000000089,72.90370332613547,-0.06977533395527091,-0.3527620461997705
669.6000000000089,73.04634350487773,-0.044401169943531826,-0.35483333500070025
671.000000000009,73.189170000001,-0.018953634448275025,-0.3597655257530268
672.400000000009,73.33167304845658,0.0027864770897085833,-0.3674058824143507
673.800000000009,73.47453022068476,0.026024259412155804,-0.3725906231270959
675.200000000009,73.61752457141836,0.04424156947961011,-0.37770478359062665
676.600000000009,73.76061113690956,0.0688503482931142,-0.38325339649911694
678.0000000000091,73.90407363927626,0.1016290397195827,-0.3902178535092524
679.4000000000091,74.04647322202109,0.12853768872508908,-0.39613868774076755
680.800000000009,74.18805449642726,0.151491474141229,-0.40333664516489254
682.2000000000091,74.33045341561336,0.18936274044848256,-0.40882527199570307
683.6000000000091,74.47509049661429,0.21509780108440912,-0.41750483495913127
685.0000000000091,74.61742308498098,0.2508663705314076,-0.42129837756417166
686.4000000000092,74.76080282220579,0.2864585265038566,-0.4333261584798471
687.8000000000092,74.90355625305871,0.32233621733363993,-0.4433782204222618
689.2000000000093,75.04635478571775,0.3582127195221685,-0.45050133231686207
690.6000000000092,75.18927182391658,0.38724647266324386,-0.45835385668538287
692.0000000000092,75.3332886090524,0.4319805986133547,-0.46827298286119623
693.4000000000093,75.47703530072961,0.4679627685777903,-0.4787206851186365
694.8000000000093,75.62008660326902,0.504339180837047,-0.48971169720763275
696.2000000000094,75.76335168621766,0.5473645767623485,-0.5009249241655964
697.6000000000093,75.90600583331089,0.5896828250530106,-0.5115196090042513
699.0000000000093,76.05087224576965,0.6365884921274687,-0.5222454424214744
700.4000000000094,76.19443330845658,0.6797716194886583,-0.5363750195807686
701.8000000000094,76.33927490235233,0.7233977520836592,-0.5476096589067976
703.2000000000094,76.48352420644545,0.772114028407592,-0.5591972940771481
704.6000000000095,76.62751982225652,0.8264439181474823,-0.5727443458558379
706.0000000000094,76.77149222617422,0.8707573102902155,-0.586820487074112
707.4000000000094,76.91499619440248,0.9249068525029207,-0.6012742702859288
708.8000000000095,77.05878739121566,0.9708765774379051,-0.6155044021935274
710.2000000000095,77.20352346027578,1.0173557032230076,-0.6314764241171527
711.6000000000096,77.34767107692954,1.0743570483244027,-0.6464582584185155
713.0000000000095,77.4914876243435,1.128545125572379,-0.6640829735880796
714.4000000000095,77.63606823263069,1.176407535055405,-0.6800901281595646
715.8000000000096,77.78016839846612,1.2275593513561094,-0.6980777790870469
717.2000000000096,77.92387098651449,1.2708699801369399,-0.7149386069146737
718.6000000000097,78.06764378675129,1.3191976026985608,-0.7320170450135852
720.0000000000097,78.21241156189035,1.361728465946464,-0.7526134849983555
721.4000000000096,78.35399376419818,1.4005374320638087,-0.7728005892140084
722.8000000000097,78.49896502512608,1.4556373386594834,-0.7931478406740098
724.2000000000097,78.6420565091483,1.5079882045691728,-0.8137627931144524
725.6000000000097,78.784509170507,1.5614535482200917,-0.8344669858490334
727.0000000000098,78.92981904191993,1.6190765731796466,-0.8554942222794653
728.4000000000098,79.07147618018317,1.6714273735456664,-0.8783801503429376
729.8000000000097,79.21752249067443,1.722885164206848,-0.8998803871994965
731.2000000000098,79.3609821629873,1.777991589266315,-0.9260299645541137
732.6000000000098,79.5047408766186,1.8240733961999474,-0.9495275808500816
734.0000000000099,79.64943004753607,1.8684317752531028,-0.97485212478849
735.4000000000099,79.79147942530984,1.8982395892686923,-0.9972535574727144
736.8000000000098,79.93657204104889,1.9237418635787074,-1.0204607552950753
738.2000000000099,80.07948019248106,1.9341137762588043,-1.0440772278721746
739.6000000000099,80.22159933783841,1.9352557559237162,-1.0732773800160271
741.00000000001,80.3644760797468,1.9222151952109567,-1.096720079868668
742.40000000001,80.50640333259224,1.8914197112519773,-1.121268402478322
743.80000000001,80.64790286764112,1.837759949538257,-1.1464042614364955
745.20000000001,80.78826391255711,1.7600678338063824,-1.171757017802502
746.60000000001,80.92838266681443,1.641440838450964,-1.1935328590116123
748.00000000001,81.06723609208649,1.4714387646556406,-1.2157256412409851
749.4000000000101,81.20244212565191,1.235413609854477,-1.2342538859375543
750.8000000000101,81.33733051990755,0.9232728293514736,-1.2507004630473646
752.20000000001,81.47126117546064,0.556322720114125,-1.2655881609550756
753.6000000000101,81.60427750230605,0.1991180281163203,-1.2736943797533327
755.0000000000101,81.73973750913434,-0.1027169734061455,-1.2822199800443128
756.4000000000102,81.87729460313506,-0.33202125452596043,-1.288342502919115
757.8000000000102,82.01484679556921,-0.48218625878426025,-1.2912945709902535
759.2000000000102,82.15649641793398,-0.5833867643500519,-1.291932150160234
760.6000000000103,82.2977643268418,-0.6505460000529366,-1.2945873114972573
762.0000000000102,82.44004181430248,-0.6859055573767654,-1.2939004552809665
763.4000000000103,82.58089006120369,-0.7096752412286689,-1.2947060779790576
764.8000000000103,82.72366266018904,-0.7218752396938419,-1.296087448786405
766.2000000000103,82.86659383665045,-0.7328923410885686,-1.2952174479982919
767.6000000000104,83.00953074696586,-0.7361232319797189,-1.2965398870262566
769.0000000000103,83.15123293780492,-0.7404488668845648,-1.2965396954708455
770.4000000000103,83.2948807837989,-0.7475887276930542,-1.297828371121461
771.8000000000104,83.43800818583499,-0.7464843204613147,-1.295549910018769
773.2000000000104,83.58063327165428,-0.7567398848002409,-1.298301429886092
774.6000000000104,83.72390349040361,-0.7602177688864964,-1.2968599814900532
776.0000000000105,83.86656871599746,-0.7689868543283838,-1.296859977000028
777.4000000000104,84.0101190193202,-0.7706183831125368,-1.296867007172882
778.8000000000105,84.15317511599697,-0.7726045541835835,-1.2965400414544939
780.2000000000105,84.29584312910636,-0.7698819266766241,-1.2965399449945307
781.6000000000105,84.4377873492605,-0.763596951997358,-1.2958801175873145
783.0000000000106,84.58056922125341,-0.7663253462851782,-1.2983399466758034
784.4000000000106,84.72321737050594,-0.7624581101183541,-1.2984866362697964
785.8000000000106,84.86553100300851,-0.764294250717545,-1.2972002430133913
787.2000000000106,85.00797050172213,-0.7682770949710229,-1.2972001839975378
788.6000000000106,85.15317107593437,-0.7771827562843459,-1.297191759347144
790.0000000000107,85.2955333171776,-0.7833455340465436,-1.2962100248429014
791.4000000000107,85.44033893990985,-0.7894703247854373,-1.2950077232213935
792.8000000000106,85.58285702280439,-0.7931048223529964,-1.2966401713913625
794.2000000000107,85.72677671696114,-0.7934831947695395,-1.2966401710003086
795.6000000000107,85.87050552503469,-0.7997717065676668,-1.2971224077278998
797.0000000000107,86.01403210489065,-0.8008872974457208,-1.297309843054407
798.4000000000108,86.15632949948571,-0.794512756617004,-1.2966498857989959
799.8000000000108,86.29985360383269,-0.7982124597557865,-1.297639930716377
801.2000000000108,86.44287544128743,-0.796986503122161,-1.2963075303775424
802.6000000000108,86.58560603398448,-0.7922201499418584,-1.2961630031255882
804.0000000000108,86.72982826222751,-0.7896051060003839,-1.2969837022432196
805.4000000000109,86.87332391232236,-0.791393740887639,-1.29433901145131
806.8000000000109,87.01751218874338,-0.791568005524738,-1.2956550692113233
808.200000000011,87.16070661028857,-0.7972410496224929,-1.296296206001962
809.6000000000109,87.30320948444492,-0.7993395131427563,-1.294321269786364
811.0000000000109,87.44713186035858,-0.7996654922331423,-1.2962940774668965
812.400000000011,87.590839045315,-0.8038139419936525,-1.2976300245713812
813.800000000011,87.73357023338734,-0.7964445289613491,-1.296368428231116
815.200000000011,87.87721173125121,-0.7992451291297673,-1.2963199513289525
816.600000000011,88.02094999393742,-0.7961707614412317,-1.2969873324166135
818.000000000011,88.16381128163891,-0.7919539489338738,-1.2976398825331321
819.400000000011,88.30686990264584,-0.7956579296400159,-1.2963198256262727
820.8000000000111,88.44990341012583,-0.7973240299447142,-1.2963198618622522
822.2000000000111,88.59350927227653,-0.7932305608737147,-1.2963199372686822
823.6000000000112,88.73552993701207,-0.7971215709368726,-1.2976398243630096
825.0000000000111,88.88020152058385,-0.8060183394481706,-1.2956714251686128
826.4000000000111,89.02286397964049,-0.8031823489908392,-1.294351030808155
827.8000000000112,89.16615987991852,-0.8043976647135551,-1.2966401130747562
829.2000000000112,89.310304430785,-0.8070380639625649,-1.297959586927973
830.6000000000113,89.45412747890713,-0.8163383723879754,-1.297958814645361
832.0000000000113,89.59687576254407,-0.8231352452985767,-1.2966400320341855
833.4000000000112,89.74099395016063,-0.828584202772584,-1.2967711104631778
834.8000000000113,89.88382476143535,-0.8284505607163137,-1.2966636438050085
836.2000000000113,90.02773515953947,-0.826718488361738,-1.296650124310771
837.6000000000113,90.17047471473677,-0.8296188325769303,-1.297969323409657
839.0000000000114,90.31320846962353,-0.8286056082237117,-1.2979698148595218
840.4000000000113,90.45738117379716,-0.8311010793464528,-1.2956581913721426
841.8000000000113,90.60065758765393,-0.8311899537546925,-1.295660161685066
843.2000000000114,90.74427191701166,-0.8290984987225274,-1.296889394924488
844.6000000000114,90.88720627129906,-0.8358998402549769,-1.2961558260226198
846.0000000000115,91.03120733928914,-0.8349695274880651,-1.2969699049981491
847.4000000000115,91.17511223072033,-0.8366889605500933,-1.296969904992617
848.8000000000114,91.31838455348029,-0.8354073371795201,-1.2982860430862964
850.2000000000115,91.46072322049964,-0.8369955204374269,-1.2974505850382578
851.6000000000115,91.60537531041977,-0.8355977340172325,-1.296282744794361
853.0000000000116,91.74823337721243,-0.8394551382328086,-1.2990599211209535
854.4000000000116,91.89181788586832,-0.8401626060520977,-1.2967619049288346
855.8000000000116,92.03529830079404,-0.8388914670002494,-1.2980780206368685
857.2000000000116,92.17864061109297,-0.8400260930089778,-1.300718426516097
858.6000000000116,92.32208196532119,-0.8470923241871082,-1.2990607265998353
860.0000000000116,92.46556771458458,-0.8512782913922168,-1.2980136435030425
861.4000000000117,92.60916770143291,-0.8533087115622322,-1.2975988523890063
862.8000000000117,92.75397018203007,-0.846600790908766,-1.2964200760035096
864.2000000000116,92.89756218735164,-0.851672362052061,-1.295161954768394
865.6000000000117,93.04079732128065,-0.853051987571424,-1.2972248493695773
867.0000000000117,93.18482586736273,-0.8573033197644848,-1.2977498589984684
868.4000000000118,93.32958210443665,-0.8554305656601284,-1.2977498565440229
869.8000000000118,93.47288796409498,-0.8606223474381336,-1.299069981035466
871.2000000000118,93.6169760235144,-0.8651938874630605,-1.297749951705479
872.6000000000118,93.76029214742621,-0.868194808465425,-1.2977500623743867
874.0000000000118,93.90508842396939,-0.8641534546999363,-1.296525511441787
875.4000000000119,94.04815756814197,-0.8621279633728463,-1.2977399979798685
876.8000000000119,94.19262946889233,-0.8576283285147184,-1.2990601114738056
878.2000000000119,94.33529100834127,-0.8542416902982004,-1.2990601100805002
879.600000000012,94.47762512847375,-0.8539853583046897,-1.2992968551678685
881.0000000000119,94.62343955187215,-0.8587156594998306,-1.2987302262680362
882.4000000000119,94.7670422168726,-0.8612573607502676,-1.2977501600536288
883.800000000012,94.91076407154256,-0.8593703245993363,-1.2980701315849439
885.200000000012,95.05408419527762,-0.8620627480626093,-1.2980702844440812
886.600000000012,95.19773163404719,-0.8595975854639404,-1.2969921398893143
888.000000000012,95.3412875785037,-0.8558753610854999,-1.2970898699996476
889.400000000012,95.48642494927122,-0.8524854628011913,-1.2970898671606874
890.8000000000121,95.62831544670661,-0.8576002753253382,-1.298155830637414
892.2000000000121,95.77169995494447,-0.8611203883788388,-1.29674993701315
893.6000000000121,95.91788069066926,-0.8627834634911462,-1.2980851114186067
894.0000000000122,95.95848901568557,-0.8647470107546975,-1.2980005383480417