File: 01_Data/EIFS_Coating/STA/N2/10K_min/EIFS_Coating_STA_N2_10KData_230915_R1.csv
##Temp./Â°C,Time/min,DSC/(mW/mg),Mass loss/mg
41.0,10.840596034465833,0.019003890049592798,0.04489456073917486
42.30000000000002,11.161487531543845,0.06357701910657676,0.04486534856383706
43.60000000000004,11.39093022722921,0.09320442183106081,0.04308535676394554
44.900000000000055,11.582352405129049,0.11202553368281354,0.04455726244273572
46.200000000000074,11.757717885190099,0.1305962633572606,0.044750318753240315
47.50000000000009,11.922346096096806,0.14459876960746598,0.04405674360282008
48.80000000000011,12.079170000000014,0.15509471609938474,0.043580729171156296
50.10000000000013,12.231245762618675,0.16552638956538424,0.04428915640739817
51.40000000000015,12.380743298130625,0.17270960163138693,0.04369431886199493
52.700000000000166,12.525822988227775,0.1810049465817143,0.044194189129350026
54.000000000000185,12.669053981237305,0.185193619964378,0.043554872484354856
55.3000000000002,12.813242059687724,0.19199283147859436,0.04370844541783203
56.60000000000022,12.955997220809952,0.20035722695663694,0.042382653135468296
57.90000000000024,13.09666983033383,0.2026887138202209,0.04355748044430774
59.20000000000026,13.235803989802392,0.20849666178387016,0.044076152775428756
60.50000000000028,13.374258176451837,0.2143342528626404,0.045024054405651714
61.800000000000296,13.513935654904556,0.22127731965002173,0.04369955702311623
63.100000000000314,13.649950571514033,0.2250300890179917,0.04370059251779468
64.40000000000033,13.783959062729348,0.23095596477515512,0.04370004347873291
65.70000000000036,13.922935960811342,0.23829616392234532,0.043350143399067065
67.00000000000037,14.056681913169692,0.24294528871103238,0.04370317746840113
68.30000000000038,14.19145132099583,0.24711467104960105,0.04433826443602351
69.6000000000004,14.327196686623244,0.25326284187514303,0.04237811142762382
70.90000000000043,14.45887978488362,0.2578557944090578,0.04370010021583637
72.20000000000044,14.590529673433117,0.26432662799691675,0.04238639181088333
73.50000000000045,14.723611293816152,0.2688538441500583,0.04111753520967376
74.80000000000048,14.857282981494954,0.2721777524522948,0.04106979003310496
76.1000000000005,14.988458335271227,0.2778999564940283,0.041062146174202674
77.40000000000052,15.11874108831506,0.2809164727298108,0.04107187853611327
78.70000000000053,15.246765859627802,0.28273586523184613,0.040071619721654184
80.00000000000055,15.380728387650754,0.2822693487471777,0.04010298439989324
81.30000000000058,15.510289813812497,0.2804083861597084,0.03843471275560528
82.60000000000059,15.639611706373833,0.2766328563521736,0.039488934821106714
83.9000000000006,15.768989715480503,0.2687913488732161,0.038430014025834236
85.20000000000063,15.897746379502815,0.26114061548822387,0.038422580907799375
86.50000000000065,16.025715844083827,0.25706106897403824,0.039801563419556985
87.80000000000067,16.15624069870298,0.25349026204666236,0.0395760121469344
89.10000000000068,16.28439434444319,0.24780261967721828,0.03847793251944953
90.4000000000007,16.411028014979408,0.24602805640446657,0.03776992934635093
91.70000000000073,16.538529763147594,0.24661028084445147,0.03774571933861237
93.00000000000074,16.66637211763291,0.24282915896620438,0.03906002586528379
94.30000000000075,16.7940078518908,0.24448212896760912,0.038595035600168526
95.60000000000078,16.92037725674941,0.24418490363687595,0.037448704183724146
96.9000000000008,17.048084649873115,0.2419212369557091,0.037766571095141366
98.20000000000081,17.174468942755787,0.24283629124847517,0.038445646321007665
99.50000000000082,17.30162398146789,0.24332765634777065,0.03852937483734964
100.80000000000085,17.428641797561653,0.24253295086504445,0.03739820201803434
102.10000000000088,17.555562512193074,0.24581170737879887,0.03875079621504307
103.40000000000089,17.681518740324904,0.24901891916980667,0.038432792241240854
104.7000000000009,17.80783307391079,0.24971070149978591,0.038427687233318686
106.00000000000092,17.93249181375214,0.250983422661873,0.03930311389041874
107.30000000000095,18.06034174399529,0.25316304060187433,0.038447181174766865
108.60000000000096,18.18748114191255,0.2537004494351103,0.036596878448178494
109.90000000000097,18.30950274218818,0.2564847425599859,0.0358032398912953
111.200000000001,18.438414938182483,0.25241941967445536,0.03777059354906509
112.50000000000102,18.56328821488591,0.25165087329671265,0.037109496325304914
113.80000000000103,18.69056702832868,0.2509698395125246,0.035784174369859034
115.10000000000105,18.815934055067473,0.2509854334965955,0.038443662144089785
116.40000000000107,18.940980747071887,0.2504614894352626,0.03710817741677985
117.7000000000011,19.067103826555275,0.25458933878260237,0.03842956304415823
119.00000000000111,19.192218183987283,0.2528785153344242,0.03842500676587246
120.30000000000112,19.318195804720638,0.25372959231625924,0.03842981641756005
121.60000000000115,19.443791457708816,0.2550357164461694,0.0384410886648614
122.90000000000117,19.569170000000128,0.25458309285896585,0.03876002083863339
124.20000000000118,19.694942606566645,0.2566966026188515,0.03838302028052043
125.5000000000012,19.82057327595828,0.2573887283147114,0.038430002460533075
126.80000000000122,19.9466558475148,0.25967798384605256,0.03974999329591711
128.10000000000124,20.069958029194538,0.25650770659984845,0.03867942164096272
129.40000000000126,20.195399632309588,0.2587063344151106,0.0391350663998824
130.70000000000127,20.32087941716331,0.26005834035334296,0.03909211086469799
132.0000000000013,20.445522150916265,0.25679829784901465,0.03777012624900111
133.30000000000132,20.571142446352056,0.2586341523338789,0.037769505261783465
134.60000000000133,20.697429186355006,0.25779948398335795,0.03867923145752128
135.90000000000134,20.821918777712426,0.2597231215488538,0.040070360127204996
137.20000000000135,20.946507732479176,0.2608626387660038,0.039087880143017006
138.5000000000014,21.07048585005786,0.2605307577112792,0.03777005742644368
139.8000000000014,21.195771649039244,0.26127029385850964,0.03908996030702783
141.10000000000142,21.31980835339742,0.2610230294511937,0.03908985405074894
142.40000000000146,21.4422490196529,0.2639878111741303,0.04041014474658944
143.70000000000147,21.569577301189884,0.2611235904904792,0.04043532419449747
145.00000000000148,21.694159781213084,0.26260275634796404,0.0388289073635506
146.3000000000015,21.817467940323684,0.26453616355564535,0.03769374249384372
147.6000000000015,21.941952144268967,0.26293158003134254,0.04007904799393103
148.90000000000154,22.065594674770296,0.2625295498708504,0.037405441669247974
150.20000000000155,22.190314136227983,0.2651610911850555,0.03876224928487915
151.50000000000156,22.31247554019292,0.26561484105767086,0.04072912853141997
152.8000000000016,22.438322390167915,0.2666803864005798,0.04072996799998041
154.10000000000161,22.56051081893642,0.267058426005119,0.04072999096957952
155.40000000000163,22.684166077534726,0.2687242600630255,0.04145900921052048
156.70000000000164,22.809264655205165,0.26812105058434965,0.04007542644951334
158.00000000000165,22.933342642120284,0.2661415564060412,0.039090031784491774
159.3000000000017,23.057027309788868,0.266398198500464,0.03808362264518994
160.6000000000017,23.180772988051395,0.26634535917402036,0.03783844945594961
161.9000000000017,23.30446542343514,0.27040491053578464,0.0390898961760624
163.20000000000175,23.428391805096606,0.27236317294345946,0.040412636152102444
164.50000000000176,23.552810909505368,0.27052439227575653,0.039129916270455034
165.80000000000177,23.676557594302576,0.2715810324671939,0.039079960139147385
167.10000000000178,23.800999562091796,0.27412627500113884,0.03974028198963264
168.4000000000018,23.92387491745553,0.2760343224082491,0.040399812660360634
169.70000000000184,24.048333545932348,0.274745411082838,0.04008063472955792
171.00000000000185,24.171985997068855,0.27413519419032495,0.04041008648984468
172.30000000000186,24.29671937690151,0.27885012964217504,0.03941982233405783
173.6000000000019,24.42090159939437,0.28076207637021877,0.039420080000048596
174.9000000000019,24.544227735217753,0.27984752463417406,0.03942008005840547
176.20000000000192,24.667718025200543,0.27890435916548495,0.03909728402508739
177.50000000000193,24.792652038097703,0.28114605705123585,0.03973685625165002
178.80000000000194,24.917190109798167,0.2801337162426012,0.03941994400211879
180.10000000000198,25.04042490976934,0.2813661722930063,0.03941994399999871
181.400000000002,25.163395189068652,0.2824709425644796,0.039419906953099826
182.700000000002,25.288489768424622,0.28157104445317804,0.039089707731940315
184.00000000000205,25.412114010635825,0.28556687698751815,0.03974475029249147
185.30000000000206,25.53776614452469,0.2833731290920847,0.03909280189200892
186.60000000000207,25.66208981221315,0.2860730566373375,0.040399871823126876
187.90000000000208,25.78428944358076,0.2859614594153781,0.040342451784220135
189.2000000000021,25.907496630478313,0.28643176057003483,0.04009287889973612
190.50000000000213,26.033064045531138,0.2869185400630576,0.04007987917101463
191.80000000000214,26.1564272615107,0.28615889897333724,0.03876090350796435
193.10000000000215,26.279963797780507,0.28813416860540064,0.038758935540519346
194.4000000000022,26.403536690429853,0.2894015373746428,0.03809655224159991
195.7000000000022,26.527171660320565,0.2919567233820035,0.04016024349436931
197.00000000000222,26.650789066296145,0.2912428458372114,0.03949952464557249
198.30000000000223,26.77552651338821,0.28991672939577406,0.03904082419188981
199.60000000000224,26.89827938954306,0.2892691468002011,0.03809683173092271
200.90000000000228,27.021828089948773,0.29026500277518874,0.0400846081190549
202.2000000000023,27.146568161546604,0.2909228829333663,0.03864307542418777
203.5000000000023,27.268589051031213,0.29149689632892395,0.03941999200979929
204.80000000000234,27.392846200328727,0.2932585111749797,0.03941999241303318
206.10000000000235,27.516436378596246,0.29334454224349815,0.04006690164597648
207.40000000000236,27.64065071164922,0.2941645011537164,0.03876006654278363
208.70000000000238,27.76381769042655,0.29588865996164326,0.04007068379898282
210.0000000000024,27.88617945860249,0.2944348733752111,0.04007018335505341
211.30000000000243,28.010658699065512,0.2973355101930124,0.0390817072935965
212.60000000000244,28.133767252588587,0.2974731810850981,0.03777061329788811
213.90000000000245,28.25667496341739,0.2958180157414634,0.03809961530624317
215.2000000000025,28.38051693652544,0.2956188170460099,0.03941985778414958
216.5000000000025,28.504003089703883,0.2975394263306941,0.03941985575441542
217.8000000000025,28.6281167343107,0.298096334931669,0.040430671399965146
219.10000000000252,28.750866097327975,0.2972591420918984,0.03942003005604455
220.40000000000254,28.874581171263983,0.29884984943959014,0.0387537642888538
221.70000000000258,28.99748823308955,0.30149826659513534,0.0374361425896943
223.0000000000026,29.121079003263887,0.30001398678427527,0.03744019835188217
224.3000000000026,29.24520990037563,0.3023015716676596,0.036122637101861255
225.60000000000264,29.36653788525254,0.3019915109420408,0.03876004952232348
226.90000000000265,29.492239047234644,0.302397188414242,0.03876004802510957
228.20000000000266,29.61602549949811,0.3036845033056754,0.039465761583310055
229.50000000000267,29.739449225559575,0.3052221104580386,0.03764793472034578
230.80000000000268,29.86322265160879,0.30449309460933693,0.03645075784109775
232.10000000000272,29.987070847507425,0.303521698022176,0.03777005475252038
233.40000000000273,30.10984721406556,0.3053055523196615,0.0377701176813412
234.70000000000275,30.23378976107523,0.30655560544151794,0.03636482530886642
236.00000000000279,30.35759502960009,0.3056664020113464,0.03642734671161518
237.3000000000028,30.480094693171672,0.30552655796562034,0.03777011467253377
238.6000000000028,30.6043134229667,0.3075689737718159,0.035641391292864366
239.90000000000282,30.727907523683577,0.30807938740260776,0.03908754821923033
241.20000000000283,30.85129956687024,0.30652915361522903,0.03777040424137601
242.50000000000287,30.97513391563704,0.30973439597300567,0.03776996437180902
243.80000000000288,31.097074838763742,0.3085992352706983,0.03644957467903254
245.1000000000029,31.221661816307,0.30830108559392966,0.03843124786402008
246.40000000000293,31.345598389328817,0.3099485098193693,0.038429257423696406
247.70000000000294,31.46963026966009,0.30773635264668453,0.03711892611956191
249.00000000000296,31.592316545692615,0.30910986127128326,0.0358000043631268
250.30000000000297,31.716953172678032,0.30912090104816436,0.03448016595186676
251.60000000000298,31.841539918477544,0.30663037216665145,0.03711893106165043
252.90000000000302,31.961401723779424,0.3104675629965512,0.03842955407375914
254.20000000000303,32.0874471392874,0.31001789966387716,0.03843004012794493
255.50000000000304,32.21072952018044,0.3089387985546943,0.037117933997180774
256.8000000000031,32.333753271942435,0.31013054271462503,0.036130018453074175
258.1000000000031,32.45975949458423,0.3102088800127696,0.03612996152671766
259.4000000000031,32.583674090063454,0.31296416494471946,0.038769392027133254
260.7000000000031,32.70636057241947,0.3119206053323791,0.03649632314420925
262.0000000000031,32.83068939496797,0.3123421280896017,0.035764260822672256
263.30000000000314,32.95460834333912,0.31368618145535354,0.0344798673660609
264.6000000000032,33.07936061243083,0.3133631351524624,0.035799978122899034
265.90000000000316,33.2027777450944,0.31448361153222537,0.0358190890006842
267.20000000000323,33.325143904545634,0.3154367752513376,0.03579001420800987
268.50000000000324,33.45011576925177,0.3152349195454871,0.03510908241258104
269.80000000000325,33.57381152852245,0.3141084867668722,0.035481875173695165
271.10000000000326,33.69838761629664,0.3131299601570301,0.035475627169359925
272.4000000000033,33.82161520375164,0.3126636169534007,0.035470104090041144
273.70000000000334,33.94679735978406,0.31285404541049533,0.03416497472359392
275.0000000000033,34.07064594928114,0.31280058890996476,0.03282464095150983
276.30000000000337,34.195381010331495,0.3136431005194531,0.033784003070016055
277.6000000000034,34.31871389029584,0.31292622192582575,0.03474451309184534
278.9000000000034,34.44062148611616,0.3158017447949131,0.0338201884158722
280.2000000000034,34.56637699900031,0.3177323525536615,0.03375746283346981
281.5000000000034,34.6920431908978,0.31889701629186673,0.03514010165155668
282.8000000000034,34.81641597578728,0.3217618583236037,0.03514013638258895
284.10000000000343,34.940766779086935,0.3198537990694643,0.033819802603473725
285.4000000000035,35.06481215800626,0.3209312447182442,0.03250013481169178
286.70000000000346,35.1889878937637,0.3192614406992986,0.03516773229477543
288.0000000000035,35.31382527429388,0.32014040397881294,0.033819798837334325
289.30000000000354,35.43862146986463,0.3229977027984017,0.032829138920104306
290.60000000000355,35.562877822100084,0.32356343152630473,0.03246491265608498
291.90000000000356,35.68603282072253,0.3254120493906496,0.03216270293665202
293.20000000000357,35.81266309978285,0.3240150655152252,0.033491030934936106
294.50000000000364,35.93740884535039,0.3270644356674459,0.0348107385750982
295.8000000000036,36.06132739443714,0.32678076889403473,0.032445831655623536
297.10000000000366,36.18642682374156,0.3256534444515784,0.033838807835938844
298.4000000000037,36.31064231901795,0.3275087713602607,0.032827193610079686
299.7000000000037,36.43559590656756,0.3272010707340518,0.032498136841257796
301.0000000000037,36.56084402839203,0.32710698438729846,0.03117998448580206
302.3000000000037,36.685817633889464,0.32654596245734613,0.031179984000000438
303.6000000000037,36.809062138111315,0.3270234721026537,0.031179984002093875
304.90000000000373,36.93575810858749,0.32975938459093723,0.031879089969561125
306.2000000000038,37.06035656581688,0.3294943480212018,0.03183771687898718
307.5000000000038,37.18535737966247,0.3309019163362408,0.03183985491170516
308.8000000000038,37.31037684759678,0.332437830661769,0.030545088827606648
310.10000000000383,37.43543170226103,0.3332570307991931,0.030841779968118654
311.40000000000384,37.56030504452303,0.33493679136503474,0.030211122573651217
312.70000000000385,37.68504778592288,0.33649603313293697,0.030189991998025967
314.00000000000387,37.80978480638954,0.33709645849055114,0.030189758170758196
315.3000000000039,37.93447824870695,0.3381337242932756,0.027888576100548512
316.6000000000039,38.05965939061852,0.3412732208159446,0.029199991793995128
317.90000000000396,38.184090647763334,0.34095709057837054,0.027889690166273517
319.20000000000397,38.30897113922012,0.34335418522295424,0.027889926655182418
320.500000000004,38.43385686144785,0.34340017837313774,0.029213168548664292
321.800000000004,38.55959343207927,0.3442290133286341,0.027900216483358165
323.100000000004,38.684282206570636,0.3468610963943195,0.027890192000204816
324.400000000004,38.80955468637728,0.35001224545084675,0.027892913253064755
325.700000000004,38.93357620534424,0.3476447659259647,0.02822604794895156
327.0000000000041,39.05859483261338,0.34693288750372364,0.026902556247270226
328.3000000000041,39.1836088905745,0.35083344819477436,0.02557987183571253
329.6000000000041,39.3081283956693,0.3524967815732336,0.0255798063923085
330.9000000000041,39.43479347951036,0.3542654155566136,0.024413227790785808
332.20000000000414,39.55900866947831,0.355182602326374,0.02491997874080809
333.50000000000415,39.68515204921003,0.3589400502580702,0.0230638057164807
334.80000000000416,39.80975218665788,0.3588588331897553,0.023308051695820176
336.1000000000042,39.93629511278197,0.36157843159393255,0.023609943992493054
337.4000000000042,40.06133427359046,0.3636718599317603,0.023609943801630173
338.70000000000425,40.18662679738484,0.36291327829415065,0.022643801821391918
340.00000000000426,40.310270498888556,0.3657267430243645,0.022290309887081694
341.3000000000043,40.435862055568414,0.36723663704871545,0.020644942239266495
342.6000000000043,40.561715264101615,0.36961280553744125,0.020691229666455424
343.9000000000043,40.68858848704971,0.3701683922908874,0.018010075557980176
345.2000000000043,40.81498219110035,0.37343934775952614,0.017640364567193867
346.5000000000043,40.94080073763699,0.3719318222367092,0.018010132816738356
347.8000000000044,41.06713582450988,0.3764164997108852,0.018010025945977226
349.1000000000044,41.19270985973597,0.37886270653921517,0.017021179617222604
350.4000000000044,41.31937747980904,0.3799392305488496,0.017331395649193837
351.7000000000044,41.444808778400905,0.37975193688255704,0.01482034943824928
353.00000000000443,41.57137331101065,0.38046997264161186,0.014823477912210503
354.30000000000445,41.69725465442328,0.38156305720889994,0.014585073353793554
355.60000000000446,41.82342862712885,0.38442740891672766,0.013190499055164118
356.90000000000447,41.94967088236125,0.38335371465902357,0.01186000727351244
358.2000000000045,42.07607289058768,0.3830121210511519,0.011859889632943599
359.50000000000455,42.20195542065206,0.38289250345958026,0.0105333125324516
360.80000000000456,42.32879509309707,0.3816292319451764,0.008241179239644847
362.10000000000457,42.453502977948425,0.38079222789133516,0.006923911451432119
363.4000000000046,42.5823125495061,0.3811238653750635,0.005600124032997478
364.7000000000046,42.7083779077432,0.3810586949974053,0.004290028048104855
366.0000000000046,42.83425729276297,0.37935009603214476,0.0029310918722145196
367.3000000000046,42.96068971740054,0.3786579858207564,0.002184306148284687
368.6000000000047,43.086133963029354,0.37818848583337084,-0.0013366142993391783
369.9000000000047,43.21418755269717,0.3785446017401646,-0.003166094441565459
371.2000000000047,43.34054727056083,0.3800682935400339,-0.004816892309956966
372.5000000000047,43.46601264339874,0.37595098356550904,-0.007155367738957974
373.80000000000473,43.59311157503425,0.3766367494689873,-0.009181642684828795
375.10000000000474,43.7205416703659,0.38105124319590056,-0.013492935585066146
376.40000000000475,43.846270989589414,0.38248409848445464,-0.016467006391151617
377.70000000000476,43.97318383745767,0.38490038487481004,-0.019768676232263083
379.0000000000048,44.100139157660955,0.387835529204136,-0.02401933393425848
380.30000000000484,44.22636230368418,0.3857773897348751,-0.029433952503760352
381.60000000000485,44.35447385380514,0.38714490537053137,-0.03233530140291441
382.90000000000487,44.48204146045256,0.38586075532192043,-0.037427407970547666
384.2000000000049,44.60878266339429,0.38690691938841626,-0.041993156298334444
385.5000000000049,44.73560312945612,0.3909164216042351,-0.04878099285769233
386.8000000000049,44.86224124365929,0.3917374202232584,-0.056095677929031584
388.1000000000049,44.989980371638055,0.3950096604593345,-0.06047558856817936
389.400000000005,45.11581349292792,0.3957036518991337,-0.06557167855749046
390.700000000005,45.24424807154711,0.39667492033373475,-0.07466086273450401
392.000000000005,45.37085386422604,0.39624722779122235,-0.08130220126206167
393.300000000005,45.49800399940792,0.39013259225850394,-0.09043980567993026
394.600000000005,45.6239712559552,0.389184410322694,-0.09517792485891441
395.90000000000504,45.75064996480274,0.3865706204356991,-0.10313656289410966
397.20000000000505,45.87870546207993,0.38173952059116467,-0.11247605644079028
398.50000000000506,46.004844066935625,0.3769414698458937,-0.11846317523426864
399.80000000000507,46.131996737263265,0.3678077402232671,-0.12438243241076785
401.10000000000514,46.25654245300122,0.3635538695506546,-0.13183657620833822
402.40000000000515,46.38526565255185,0.35167096355782435,-0.1382002471765067
403.70000000000516,46.51226718719848,0.34406232997999275,-0.1444411386214144
405.0000000000052,46.639363667252354,0.3321743486626827,-0.15074603066608905
406.3000000000052,46.7660434305962,0.3194078667526765,-0.15487279609128235
407.6000000000052,46.89261615744441,0.3117338068005202,-0.15705365886028844
408.9000000000052,47.018773274443085,0.30183645113653057,-0.16028576885022972
410.2000000000053,47.14620777886781,0.29338847839945803,-0.16286203180196024
411.5000000000053,47.27327484124702,0.28835570081283524,-0.16684878014707571
412.8000000000053,47.40028928814154,0.28137456721493925,-0.1692561596489055
414.1000000000053,47.52711606750293,0.27176246722291064,-0.1708198159873393
415.4000000000053,47.65412483080824,0.2675173094638563,-0.17306305884193351
416.70000000000533,47.78234349757958,0.26616154658620905,-0.17411035195973623
418.00000000000534,47.90866178811743,0.26212847407923623,-0.173105142664697
419.30000000000535,48.03648334398615,0.2593871186350738,-0.17554232186366647
420.60000000000537,48.16296754435016,0.25964978954877016,-0.1778111795351438
421.90000000000543,48.291146744026484,0.26064617842003335,-0.17707775362877687
423.20000000000545,48.418402404594914,0.2573385212744792,-0.17839018390644323
424.50000000000546,48.546320412560526,0.25599493486980474,-0.17838961949150667
425.80000000000547,48.67336064625562,0.25780576671714317,-0.17839251439115955
427.1000000000055,48.80120338092557,0.25967124124804575,-0.17971008271904587
428.4000000000055,48.92862223328947,0.2613375122621293,-0.18036460593784298
429.7000000000055,49.057079180937095,0.26792027622429315,-0.18086008058515501
431.00000000000557,49.184439631463675,0.26977689277440775,-0.18036049058376546
432.3000000000056,49.31239626200284,0.270214098123466,-0.18174908447988924
433.6000000000056,49.440408591347946,0.27401837012170693,-0.18168028130519653
434.9000000000056,49.56773880025306,0.2729086785538033,-0.18333011274058109
436.2000000000056,49.69645729860993,0.27607564941800056,-0.18333304373247783
437.5000000000056,49.824254212887766,0.2764683976295277,-0.18596339772524528
438.80000000000564,49.95303046556219,0.27559235983011243,-0.18591580406524422
440.10000000000565,50.08046959485516,0.27766542547591544,-0.18498002269739544
441.40000000000566,50.208518266131904,0.27476252243422716,-0.18628857509200092
442.70000000000573,50.33643456431517,0.2728140956971141,-0.1876099541020153
444.00000000000574,50.46451666079302,0.27567380564383326,-0.1872034771573814
445.30000000000575,50.5930220929797,0.2769643250168956,-0.18904916992274945
446.60000000000576,50.71839071556278,0.27455486446743316,-0.1876137795088093
447.9000000000058,50.84888541352666,0.27096481871005595,-0.18894005029595196
449.2000000000058,50.97738961335391,0.2721137622658274,-0.1902501326336079
450.5000000000058,51.105100012864895,0.27000243440204064,-0.19025014639835414
451.80000000000587,51.23387540920187,0.26840546600310144,-0.19163521855941346
453.1000000000059,51.36130423793385,0.2697821231850055,-0.1902790775847194
454.4000000000059,51.489171031519064,0.268024267385383,-0.19186776683463647
455.7000000000059,51.61886623927839,0.2696481522634473,-0.19255999495188592
457.0000000000059,51.74612998223519,0.2670441170900324,-0.19250675190816668
458.3000000000059,51.87515272705598,0.2674312447367002,-0.19387089584552664
459.60000000000593,52.0040651204994,0.2658945332400311,-0.19571271266020585
460.90000000000595,52.13155048343958,0.26405148107158705,-0.19574987117220122
462.20000000000596,52.25957159446891,0.26301529289444026,-0.19519003635687637
463.500000000006,52.388609144075375,0.26558139296057526,-0.19519142281495183
464.80000000000604,52.516860472480865,0.26377635732230487,-0.19715075496795942
466.10000000000605,52.64538650317779,0.26120035202617964,-0.19652962588159495
467.40000000000606,52.77417054304032,0.2609879432601838,-0.1984800975407186
468.70000000000607,52.9031023821925,0.26226796763786364,-0.19984000476820674
470.0000000000061,53.03194246223564,0.26035568382838803,-0.20045917200831154
471.3000000000061,53.161156032895285,0.25712898533672424,-0.19913917191397612
472.60000000000616,53.287290633419346,0.2560597034709402,-0.19925217067239087
473.9000000000062,53.418863146939806,0.25823934626681355,-0.19913895079391386
475.2000000000062,53.546852087956424,0.25645497795046057,-0.20173942385572374
476.5000000000062,53.676073509270935,0.2566346461169575,-0.2030899751958879
477.8000000000062,53.805071050126784,0.2568319439012221,-0.2034206782729262
479.1000000000062,53.9332824445995,0.2534933074271777,-0.20418864294419015
480.40000000000623,54.062831709526186,0.24914203361735865,-0.20415358685298113
481.70000000000624,54.19113776160835,0.24859997389392086,-0.2040799439988743
483.00000000000625,54.320294749174906,0.24902204472320633,-0.20407888496298776
484.3000000000063,54.449171037382435,0.24936426857685245,-0.20376009000447137
485.60000000000633,54.57634240205053,0.25271834637225443,-0.20506964483089662
486.90000000000634,54.70683878768396,0.24910717962882045,-0.20770186464973017
488.20000000000636,54.83523845328124,0.24821452182861337,-0.20643820323962725
489.50000000000637,54.96447897741506,0.24665258190924466,-0.20507107716610573
490.8000000000064,55.09438479418174,0.2460671035133366,-0.20770974903895567
492.1000000000064,55.22417836958811,0.24166870925317108,-0.20770719979233432
493.40000000000646,55.352744419797055,0.24036495635103372,-0.2077103053777294
494.70000000000647,55.48203928102611,0.23745336443433152,-0.20770988327264694
496.0000000000065,55.60957535972897,0.22934687712542856,-0.20708263127124305
497.3000000000065,55.74034124124142,0.22314206586500918,-0.20771012000342948
498.6000000000065,55.87020193512751,0.21663486668313015,-0.20770886843376646
499.9000000000065,55.99836053171998,0.21201031826217998,-0.2077002025272905
501.2000000000065,56.12809482333131,0.2110178395833,-0.207730943513877
502.50000000000654,56.25796885431164,0.2055320101938385,-0.2100104206737834
503.80000000000655,56.3842614476053,0.20272106323046812,-0.2090201816321562
505.1000000000066,56.51582459771063,0.20244687558772312,-0.20967619172894736
506.4000000000066,56.644920676306526,0.2014641065272722,-0.210338140043143
507.70000000000664,56.77228109929554,0.19714010906973245,-0.21069507944709098
509.00000000000665,56.90165413983415,0.19296663633807198,-0.20909233422933138
510.30000000000666,57.032173879647296,0.18735024646446607,-0.2089247498256075
511.6000000000067,57.160849518424094,0.18648616045448896,-0.2115420172642848
512.9000000000067,57.29039019933455,0.1827283987733732,-0.2115398399999311
514.2000000000068,57.41975514530873,0.1789320194232995,-0.21153984000516424
515.5000000000068,57.549560723464,0.17504679675797807,-0.21285353966073384
516.8000000000068,57.67917100626803,0.17290153851221457,-0.2115503155320657
518.1000000000067,57.808321806526955,0.16999799631390777,-0.21186989892261066
519.4000000000068,57.93759932369874,0.1671465754171122,-0.2131819467160394
520.7000000000069,58.067193007923024,0.16801218809280272,-0.21456207589279996
522.0000000000068,58.196943574824765,0.1691893483196023,-0.21187996229393802
523.3000000000068,58.32407685802942,0.1655936201131447,-0.21187982209343081
524.6000000000068,58.45676698503303,0.16534987762684716,-0.21122002530850903
525.9000000000069,58.58437906987771,0.16517817225474385,-0.21253663917590426
527.2000000000069,58.715216183327584,0.16575279864448844,-0.2138730576435548
528.5000000000069,58.84536080807689,0.16573737136926425,-0.21472711093005703
529.800000000007,58.97484171423286,0.16734763703070876,-0.21417995200662876
531.100000000007,59.10620439651881,0.16846628276770903,-0.2141799519999874
532.4000000000069,59.23542275199346,0.17140955614914888,-0.21418028642482678
533.700000000007,59.36530730957971,0.1718862779088295,-0.2118784958117348
535.000000000007,59.492866925312875,0.17106136223031077,-0.2131898189669439
536.300000000007,59.62551227930891,0.17037608433776708,-0.2145099427492645
537.6000000000071,59.75523782497813,0.1692242717683503,-0.21319017994487854
538.9000000000071,59.88472651911169,0.17130957591088802,-0.21451031949140242
540.2000000000071,60.01612262262837,0.1736505666520034,-0.21411004705880554
541.500000000007,60.14594526927544,0.1756788500928288,-0.21352329011493065
542.8000000000071,60.27588296898213,0.17564778128622072,-0.21319805740561382
544.1000000000072,60.405181777790624,0.1758008979518626,-0.21423169546310517
545.4000000000071,60.53646619177722,0.1759487851192123,-0.21492069133046865
546.7000000000072,60.66694690470502,0.17559461660450704,-0.21417974944566875
548.0000000000073,60.79716177323953,0.17973090995918928,-0.2161536624800311
549.3000000000072,60.92843817602002,0.17520416598283628,-0.21484002453919038
550.6000000000072,61.05806135875662,0.17274276945493994,-0.21384998893336338
551.9000000000073,61.189271513336735,0.17283364198772766,-0.21450996079198914
553.2000000000073,61.319600405339045,0.17203397351846217,-0.21451067316200767
554.5000000000073,61.4484015079523,0.17399025909679922,-0.21775002601055915
555.8000000000073,61.57851780041105,0.1716193630773557,-0.2158219330631681
557.1000000000073,61.710298623171,0.170357222006718,-0.21618831032053398
558.4000000000074,61.84017776933889,0.16925826511967568,-0.2141802429029216
559.7000000000073,61.97104231005442,0.16815895492075694,-0.21549821342736575
561.0000000000074,62.100184464583045,0.17307664928090816,-0.21549998910591306
562.3000000000075,62.23145084767289,0.16930058419761318,-0.21634999735816596
563.6000000000074,62.36216650350803,0.1694484169884518,-0.21756840647139652
564.9000000000075,62.492215081452585,0.1694924942562286,-0.21879017597234363
566.2000000000074,62.62248162708136,0.16952708261289673,-0.2187905665624208
567.5000000000075,62.753275734003964,0.1734440447594463,-0.22015872056369812
568.8000000000075,62.883456362317474,0.17692921765162173,-0.22075818110848733
570.1000000000075,63.01398584069999,0.17906090133793806,-0.2188006386190997
571.4000000000076,63.14514978015079,0.18335553802845528,-0.21878029179511405
572.7000000000075,63.27564058143554,0.19259637779219263,-0.22011017166199665
574.0000000000076,63.40706859541019,0.25552666501901733,-0.22003516900196018
575.3000000000076,63.53687292412994,0.20049139548587824,-0.22106705026297213
576.6000000000076,63.666741551691935,0.18471818890267766,-0.22241149283174355
577.9000000000076,63.79743812526675,0.17542605057884764,-0.21975451158237203
579.2000000000077,63.92790817942462,0.17333727566200485,-0.22109997420793226
580.5000000000076,64.05946621791273,0.1759195087600509,-0.2197810658375352
581.8000000000077,64.19046777733163,0.17829403598271343,-0.21846003199565134
583.1000000000078,64.3184683023726,0.1716663826650251,-0.2191244088294768
584.4000000000077,64.45034690778044,0.17450776270984392,-0.2204428984127711
585.7000000000078,64.58247540259751,0.17610821562858048,-0.22043952127771016
587.0000000000077,64.71377796051193,0.17575955281677702,-0.22036275265665894
588.3000000000078,64.84510286686313,0.17403762184231564,-0.2203113803394512
589.6000000000078,64.9750367778165,0.17456927751047457,-0.2227096857399946
590.9000000000078,65.10571793712633,0.17603745277243688,-0.22307005505608268
592.2000000000078,65.23693020968335,0.17340991159457442,-0.2243901624491369
593.5000000000078,65.36842583869172,0.1756923656268241,-0.22438997677045203
594.8000000000079,65.4988564434881,0.1822496543594725,-0.2230686198433136
596.1000000000079,65.62986281117857,0.17888034680428078,-0.2227970874159313
597.4000000000079,65.76064257096228,0.18290066212360223,-0.22077046505261455
598.7000000000079,65.88951695134932,0.1812028361762157,-0.22208993350925965
600.000000000008,66.02206269822189,0.1742257676072949,-0.2247198634638794
601.3000000000079,66.15350572385265,0.1732544372879059,-0.22473529194360697
602.600000000008,66.28547042003699,0.17291458185906894,-0.22399415488330687
603.900000000008,66.41433164297237,0.17190923699998306,-0.22471987197457377
605.200000000008,66.546266145545,0.17322856748801652,-0.22474063343448947
606.5000000000081,66.67715633192044,0.17469152216826522,-0.22603980618744224
607.800000000008,66.80794105905822,0.17660520550739145,-0.22735999349305436
609.1000000000081,66.93827563513892,0.17800621087394264,-0.22669970296450215
610.400000000008,67.06887991504068,0.17823842629626574,-0.22736012909834846
611.7000000000081,67.19907134141556,0.18377931346591847,-0.22735972272331129
613.0000000000082,67.33158438757607,0.18914577045916792,-0.22866757492861645
614.3000000000081,67.46438720059334,0.19259733127577938,-0.22899818387607906
615.6000000000082,67.59591443343007,0.19300412751762952,-0.2300401050696319
616.9000000000082,67.72613622326256,0.19876141265363856,-0.2290016553619818
618.2000000000082,67.85916889044843,0.202195533835841,-0.22899629619758244
619.5000000000082,67.98937566772075,0.207780684821965,-0.2290004564757271
620.8000000000083,68.12153116038246,0.21109001441265463,-0.23164400777048
622.1000000000082,68.25305414349029,0.21331781100932545,-0.2316398796226964
623.4000000000083,68.38423412324671,0.21561106690690135,-0.23203779930118573
624.7000000000083,68.51623947963472,0.2300267751505749,-0.23294794171102318
626.0000000000083,68.64752476019154,0.226473130984564,-0.23292317198188695
627.3000000000084,68.77906841888276,0.23445654009961103,-0.23427170815994325
628.6000000000083,68.91076149615337,0.2436346164460761,-0.23637201358392534
629.9000000000084,69.04274256949732,0.2425587682428394,-0.23560359771426365
631.2000000000083,69.1740232553331,0.24787647061646867,-0.23560051997935227
632.5000000000084,69.30298906714903,0.2546976567641064,-0.23691013445194287
633.8000000000084,69.43613958453771,0.2598679595323241,-0.2382213299592415
635.1000000000084,69.56750457106034,0.26526812133257094,-0.24005918083324929
636.4000000000085,69.69848788366869,0.2737953402939235,-0.24085994627247942
637.7000000000085,69.83004100179829,0.27765799854275475,-0.24218019185867945
639.0000000000085,69.96121049287632,0.2822200233103991,-0.24248164430460317
640.3000000000085,70.09268936177756,0.2909888265821041,-0.24375093559551875
641.6000000000085,70.22469457220565,0.3010020250640131,-0.2474365437379813
642.9000000000085,70.35563997987961,0.3109488515008838,-0.24633982786476283
644.2000000000086,70.48874498722196,0.31833101706446554,-0.2476590742611844
645.5000000000086,70.61992391749042,0.32940633460621394,-0.24898569464880493
646.8000000000086,70.75231937067927,0.34270464176134574,-0.25096006503678625
648.1000000000087,70.88368905466155,0.3560612283455078,-0.2530882087239359
649.4000000000086,71.01691942207333,0.36216924487441027,-0.25564868935359364
650.7000000000087,71.14834551387523,0.37651287111087317,-0.25705007692715576
652.0000000000086,71.27968086209388,0.38570503413775237,-0.2584301845315511
653.3000000000087,71.41297120151518,0.39662009855814295,-0.2610130695180741
654.6000000000088,71.54472915259028,0.40505128578796734,-0.26494170134230055
655.9000000000087,71.67564662948159,0.42188147039692847,-0.2676745537640657
657.2000000000088,71.80819269356138,0.43419518604498686,-0.270511824520407
658.5000000000088,71.93979241047323,0.44122026401587666,-0.2757890740672666
659.8000000000088,72.07299889616601,0.4609069022751813,-0.2769971155215232
661.1000000000088,72.20361270353175,0.47727142664096167,-0.2796696179749283
662.4000000000088,72.33749505517375,0.4894099412980015,-0.2811504694964575
663.7000000000088,72.47000893272384,0.5064071802571628,-0.2863214524501738
665.0000000000089,72.60251177987782,0.5227411309616081,-0.2894400105105541
666.3000000000089,72.73509524383252,0.546508722714135,-0.2939397361161049
667.6000000000089,72.86719931981727,0.5600775765470791,-0.29626960883641607
668.900000000009,73.00176700662327,0.5758250464887564,-0.29882812840646
670.2000000000089,73.13241422676548,0.5950663328661365,-0.3014825155675993
671.500000000009,73.26508844968134,0.6203919651084919,-0.30571339991130575
672.8000000000089,73.39754742318769,0.6393358010924657,-0.31000426600265696
674.100000000009,73.53114814425638,0.6624434136175221,-0.31548679646404887
675.400000000009,73.66073812416056,0.6812355007774173,-0.3216444743154585
676.700000000009,73.79522108687875,0.7070300610261921,-0.32734426589242327
678.0000000000091,73.92759653964708,0.7296883669340768,-0.3323007384404888
679.300000000009,74.05976476610734,0.7540379431486763,-0.3375166763909756
680.6000000000091,74.19256411533348,0.7826900109254034,-0.3440623925069044
681.9000000000091,74.32518915914707,0.8043570007153908,-0.34989246805951524
683.2000000000091,74.45802450431465,0.8366812240996002,-0.3535568972803027
684.5000000000091,74.59055775048266,0.8663470684745072,-0.3595975240257743
685.8000000000092,74.72322263204603,0.8959152154327596,-0.36702633130679985
687.1000000000092,74.8557841169687,0.9311173677013302,-0.37279500083851635
688.4000000000092,74.98806513591535,0.9626024054317384,-0.37951023765775727
689.7000000000093,75.12070396276556,0.9967885769909,-0.3882110638558909
691.0000000000092,75.25395884875167,1.0274656676887637,-0.3962795807459587
692.3000000000093,75.38661460363485,1.0604125284235253,-0.4043784209102479
693.6000000000092,75.51926841192645,1.096922991481236,-0.4134420795881635
694.9000000000093,75.65113750818128,1.130663943289849,-0.4202564421806372
696.2000000000094,75.7849895944796,1.162330706188778,-0.42998758663387227
697.5000000000093,75.91752165491579,1.1981434459288574,-0.4394808348197543
698.8000000000094,76.05041774252352,1.237257370799587,-0.448935238144478
700.1000000000093,76.18367623843703,1.2751612001652752,-0.4595030989003783
701.4000000000094,76.31557913560616,1.316740773876464,-0.47163476168923557
702.7000000000094,76.44735630190303,1.3553888036603583,-0.48263375459580526
704.0000000000094,76.57856369593648,1.394972659997907,-0.49077752571847455
705.3000000000094,76.71323968682042,1.4352844477014028,-0.5011311253142945
706.6000000000095,76.84721733581308,1.4805120200342539,-0.5157752210461957
707.9000000000095,76.97970883501324,1.5241881803689994,-0.5262415810369347
709.2000000000095,77.1126218280412,1.56718491997577,-0.5392730713489882
710.5000000000095,77.2461870385465,1.612148377689504,-0.5505635199251393
711.8000000000095,77.37976754998213,1.6589528721145328,-0.5628212709157228
713.1000000000096,77.51260622943984,1.7041389234846083,-0.5772035543349237
714.4000000000095,77.64736660393935,1.7510763266132976,-0.5933297802383852
715.7000000000096,77.78103812548689,1.7954101285634159,-0.6081717677747429
717.0000000000095,77.91462707884827,1.8391523391214846,-0.6233566328637186
718.3000000000096,78.04769010916993,1.8850361554668447,-0.6373534389059134
719.6000000000097,78.18142710835068,1.9298125900413283,-0.6525079157488451
720.9000000000096,78.3154501042519,1.9786193109501404,-0.6694252449705704
722.2000000000097,78.44872746769731,2.0263171943290574,-0.6861959629153622
723.5000000000097,78.5816708474514,2.070248017921209,-0.7030165974734222
724.8000000000097,78.71528394778134,2.113440853505117,-0.7233938725989124
726.1000000000097,78.84980706329061,2.158515751801417,-0.7429731748017483
727.4000000000098,78.98141854032795,2.204271871932204,-0.7590590440526777
728.7000000000098,79.11516075501258,2.2525369292431665,-0.7773322088993262
730.0000000000098,79.24819557527195,2.2996247381175383,-0.7954887128061965
731.3000000000098,79.38234608787421,2.3385294545410367,-0.8160488663280474
732.6000000000098,79.51721272736557,2.379399427753637,-0.8355999612031013
733.9000000000099,79.65054210977381,2.4215660398989725,-0.8591045724246236
735.2000000000098,79.7838388451201,2.460826577944319,-0.8792548880321456
736.5000000000099,79.91813109511433,2.4932063792591044,-0.899728948909595
737.80000000001,80.05134924364232,2.5213094017939444,-0.9198192850974762
739.1000000000099,80.18421609678346,2.5479196857151627,-0.9412341341032406
740.40000000001,80.3169582259265,2.5665458033208792,-0.9645444695496304
741.7000000000099,80.44916901406015,2.580875183736117,-0.9869400264068018
743.00000000001,80.58160708099629,2.58344616974489,-1.0092838678597382
744.30000000001,80.71326430177137,2.574727731356832,-1.0332476737383263
745.60000000001,80.84610196698085,2.551496651815607,-1.0541740010099332
746.90000000001,80.97757034093863,2.5158578758121446,-1.077066569383685
748.20000000001,81.10781704287287,2.461581715653976,-1.0998108674680394
749.5000000000101,81.23813189260204,2.3777441852450045,-1.120235412373117
750.8000000000101,81.36827670462198,2.2694854384019965,-1.138641184130393
752.1000000000101,81.49658823972393,2.1209330833695637,-1.1556430885899847
753.4000000000101,81.62455840631571,1.9271312803972656,-1.1727303713533765
754.7000000000102,81.75068509754837,1.6800550017557212,-1.18741041316134
756.0000000000101,81.87606900002442,1.3944772004913504,-1.1996080117099428
757.3000000000102,82.00091012252915,1.092467068851826,-1.2118957033541276
758.6000000000101,82.12731867099274,0.8221854850358823,-1.2202022520715494
759.9000000000102,82.25448453150807,0.6066724527076666,-1.2245612298073083
761.2000000000103,82.38274063599907,0.43925062679505045,-1.2275284285252974
762.5000000000102,82.51331467109858,0.32313505522112607,-1.231644637783098
763.8000000000103,82.6436338233377,0.25040150530271577,-1.231556640197807
765.1000000000103,82.7749162245775,0.2015057490685117,-1.2341928953359171
766.4000000000103,82.90704865394609,0.17599453464634562,-1.2354881049851825
767.7000000000103,83.03958966398105,0.1560987069821973,-1.2341801100290786
769.0000000000103,83.17189761450041,0.14807596796258826,-1.2354960524806264
770.3000000000104,83.30501887526914,0.14081940842123286,-1.2341818145559196
771.6000000000104,83.43631201166302,0.13494837608465637,-1.2341793027566825
772.9000000000104,83.5702277286171,0.13113654729418434,-1.2354976392814447
774.2000000000104,83.70324691190869,0.13253260113310583,-1.2368199042095638
775.5000000000105,83.83537906608908,0.131193475155436,-1.2368229108197992
776.8000000000104,83.96854204456329,0.1275083015751135,-1.2361615061313849
778.1000000000105,84.1017720604204,0.1317608516915607,-1.2362055813787896
779.4000000000106,84.23534612440271,0.13132814035946216,-1.2387900746298453
780.7000000000105,84.36874859819686,0.13432708215114086,-1.237475724509693
782.0000000000106,84.5015199572972,0.1410942489764926,-1.23627690766922
783.3000000000105,84.63432777322295,0.13662856274317825,-1.235819810860967
784.6000000000106,84.76832416345836,0.13497260344331607,-1.2371406882837306
785.9000000000106,84.90034326578065,0.13743430927820377,-1.2371408483612236
787.2000000000106,85.03287081883329,0.13669788591732157,-1.2358301474593238
788.5000000000106,85.16501254234453,0.13685756604300536,-1.2354882823679691
789.8000000000106,85.29982868808992,0.1336280441259281,-1.2358067059239897
791.1000000000107,85.43284124044688,0.13824178571426593,-1.2345100401194231
792.4000000000107,85.5650266069875,0.14399981838313147,-1.2371390880316024
793.7000000000107,85.69801069106367,0.1434097394551883,-1.2367386657258934
795.0000000000107,85.83048469761387,0.14090449766844104,-1.2372009195014084
796.3000000000108,85.96320622425007,0.14047739933199033,-1.2381449538227303
797.6000000000107,86.09656275181516,0.14437616995975144,-1.2374502437675825
798.9000000000108,86.22853564330501,0.13587388072499618,-1.2381162406877975
800.2000000000107,86.36170296449879,0.1428101681885492,-1.2371959198170077
801.5000000000108,86.4957026138152,0.14342279509311906,-1.2368098799852776
802.8000000000109,86.62874717580354,0.14818017039605103,-1.2375060472017902
804.1000000000108,86.76160099498696,0.14585730478366177,-1.2364788992906472
805.4000000000109,86.89480939620628,0.14833402619263136,-1.2351600797882898
806.7000000000108,87.02742285140823,0.14213754899774367,-1.2351600774348799
808.0000000000109,87.1616220539777,0.13869488622022486,-1.2378131966871693
809.3000000000109,87.2937147992801,0.13449212802561084,-1.2387740345716858
810.6000000000109,87.42792280798619,0.13763441179194347,-1.2374716909425256
811.900000000011,87.56120128980632,0.13745938278961933,-1.2356225537102064
813.200000000011,87.69387631413221,0.14346066018902048,-1.2351603488077525
814.500000000011,87.82802126202697,0.14308713331970546,-1.236480072968475
815.800000000011,87.96096086166945,0.14157845652713785,-1.2351700887901211
817.100000000011,88.09444684745742,0.1413207612566847,-1.2364800670897549
818.400000000011,88.22687854605378,0.14081707414613076,-1.2378140040856662
819.7000000000111,88.36019801388503,0.14234859635085284,-1.2364532751118396
821.0000000000111,88.49349488897154,0.14151108758046416,-1.2374060227363408
822.3000000000111,88.62658259783478,0.14097955069610624,-1.2364819795205046
823.6000000000112,88.75890135388426,0.1420607113063559,-1.237793936196112
824.9000000000111,88.89086996024645,0.1439078306612811,-1.2391486835995718
826.2000000000112,89.02571987124813,0.14472648262210974,-1.2378839300883113
827.5000000000111,89.15938344946743,0.1432933004088368,-1.237450561154895
828.8000000000112,89.2931720597418,0.14291100222590014,-1.2354995364350891
830.1000000000112,89.42676423329993,0.14660302137334424,-1.2351699898221278
831.4000000000112,89.55989622897953,0.15216258251065717,-1.2372104237712822
832.7000000000113,89.69336311766716,0.15595943591542705,-1.239119369547514
834.0000000000113,89.82675204392663,0.1571497011494114,-1.239119148989679
835.3000000000113,89.96082178689744,0.1570944310531428,-1.2404412238126463
836.6000000000113,90.09429678953227,0.15614291464809726,-1.2378000627777994
837.9000000000113,90.22722017554602,0.1582829481606418,-1.2361314716496197
839.2000000000113,90.36045762926616,0.1586702308279877,-1.2348300483095782
840.5000000000114,90.4929154543918,0.16455051613988658,-1.2348300483115104
841.8000000000113,90.62657298645107,0.1624304598994013,-1.2353134953716078
843.1000000000114,90.76003981658772,0.1631044915631228,-1.2358555037867234
844.4000000000115,90.89295503732538,0.16419788825486847,-1.2355000296026208
845.7000000000114,91.02619230259484,0.1597876377077605,-1.236781733199162
847.0000000000115,91.15957335183961,0.16566051506910817,-1.2355010044692936
848.3000000000114,91.29292536784428,0.16235758334832395,-1.2368106899466982
849.6000000000115,91.42553016284343,0.16692381952324098,-1.236817766020045
850.9000000000115,91.55907530855373,0.16125752857628806,-1.2384600988677956
852.2000000000115,91.69170749575126,0.170823389123965,-1.2381871027585265
853.5000000000116,91.82555988113214,0.16469243644261589,-1.237479531281755
854.8000000000116,91.95851392547644,0.16199779281223625,-1.2348707920803235
856.1000000000116,92.09235645946545,0.16066453914397405,-1.2332116389626888
857.4000000000116,92.22476536822238,0.15979393965943034,-1.2371925618383441
858.7000000000116,92.35823270247232,0.16359897254092193,-1.2371437578643687
860.0000000000116,92.49232216195787,0.15712381221874328,-1.2358200418614773
861.3000000000117,92.62595421992668,0.15982732634983376,-1.2378000007754149
862.6000000000117,92.75926894155096,0.15452358547064593,-1.238460248955361
863.9000000000117,92.892787501825,0.15798976210498816,-1.2384601343967079
865.2000000000118,93.0260946629313,0.15846315795167065,-1.2384525967636044
866.5000000000117,93.15953583733199,0.15866676240224153,-1.2374798160148885
867.8000000000118,93.29285240050378,0.15306910956218767,-1.237479816000001
869.1000000000117,93.42636551174503,0.15881633849176735,-1.2374798146837858
870.4000000000118,93.5596716135145,0.1563930228040351,-1.2371395995263645
871.7000000000118,93.69297273841043,0.160135984018142,-1.2368093860701816
873.0000000000118,93.82663835212982,0.1587500538922959,-1.2368099439027178
874.3000000000119,93.95789320105922,0.15588959699734772,-1.2374663811157558
875.6000000000118,94.09312566169069,0.15666249027777246,-1.2387899306595394
876.9000000000119,94.2268506181853,0.15847259045608508,-1.2397789083178958
878.2000000000119,94.36013607314268,0.15769171302719132,-1.238060282434669
879.5000000000119,94.49257653652977,0.16295775001067847,-1.2371383607514117
880.8000000000119,94.62703476112806,0.16426874654882795,-1.2359901594296927
882.100000000012,94.75927039571751,0.1653213311985473,-1.2358300795382595
883.4000000000119,94.89282171393975,0.16766813619831167,-1.2381578826134003
884.700000000012,95.0266864147068,0.16746305114371207,-1.2395121900311326
886.000000000012,95.1589615046799,0.16894652855467696,-1.2397810667881832
887.300000000012,95.29184904089064,0.17145824277841148,-1.2384457428094744
888.6000000000121,95.42565827716659,0.16746512250994394,-1.2397362654317088
889.900000000012,95.55885715290844,0.1703225874042662,-1.2411746904547898
891.2000000000121,95.69301689957436,0.16438489369682419,-1.237138744358707
892.500000000012,95.82652652866291,0.1648833487214585,-1.2371499839996214
893.8000000000121,95.9588651961094,0.1637562353873765,-1.2371499839999998
894.0000000000122,95.97841389368772,0.16176195463228327,-1.2371499840000002