File: 01_Data/EIFS_Coating/STA/N2/10K_min/EIFS_Coating_STA_N2_10KData_230918_R3.csv
##Temp./Â°C,Time/min,DSC/(mW/mg),Mass loss/mg
41.0,10.823453023560283,0.027232744481422877,-0.0011151632296551028
42.40000000000002,11.178916322994514,0.059479837783829925,-0.00020531965756553916
43.80000000000004,11.421037777536272,0.08043269326963642,0.0013289454356968378
45.20000000000006,11.627800652005904,0.09463074041968378,0.0005169909503131009
46.60000000000008,11.81451592989881,0.1068885955697545,0.001093059278121089
48.0000000000001,11.988221052865331,0.1180860411579241,0.0018411497239343433
49.40000000000012,12.156160008779421,0.1280603157448328,0.0017349406623301533
50.80000000000014,12.31817690254618,0.13645872017296923,0.0005017335918493515
52.20000000000016,12.476431432545438,0.14528094151205662,-0.0006605362620528688
53.60000000000018,12.633190235006527,0.14965937876451707,-0.0020575479367499483
55.0000000000002,12.789430989405458,0.15545143275510553,-0.002026123334511354
56.40000000000022,12.942613479010557,0.16313199648797005,-0.00200760459810434
57.80000000000024,13.092931666109587,0.1668484339748093,-0.002077580313122329
59.20000000000026,13.245077175328447,0.17085863180622995,-0.0007077799085823955
60.60000000000028,13.395015590576124,0.17537108621067898,-0.001984480876356276
62.0000000000003,13.543825629661214,0.18191141958849943,-0.002007045186717793
63.40000000000032,13.693068774072369,0.185094093855372,-0.0017823534377119366
64.80000000000034,13.837712044565048,0.19146151430822567,-0.0007412425772224118
66.20000000000036,13.984697782010823,0.19349488252770874,-0.0019772226305483365
67.60000000000038,14.130000000000042,0.2040894278337384,-0.004290063338605599
69.0000000000004,14.2746399634993,0.20778839931970627,-0.004792201004367946
70.40000000000042,14.418489420081345,0.21585476986610352,-0.0055208177178656115
71.80000000000044,14.562313580856149,0.21897654645313436,-0.007384598519192487
73.20000000000046,14.706058963694831,0.22639994192057866,-0.005940060451145701
74.60000000000048,14.848804690741582,0.23211111193425693,-0.00860743445495471
76.0000000000005,14.990192818153126,0.23702030031340193,-0.007250027928343172
77.40000000000052,15.13178512926575,0.23698083302923267,-0.008570001101495972
78.80000000000054,15.273280110457844,0.23792369988550788,-0.009889999999999066
80.20000000000056,15.411453992840054,0.23833544096883763,-0.011199895076351662
81.60000000000058,15.552675645216313,0.23586766716723773,-0.011184087074281646
83.0000000000006,15.6915827715724,0.23113302308063344,-0.012520068976805021
84.40000000000062,15.830934148300912,0.22107598286544072,-0.013840001679222613
85.80000000000064,15.96938266706835,0.20884714290113626,-0.014843603182218335
87.20000000000066,16.10654582859559,0.20374622736006032,-0.015186076323448372
88.60000000000068,16.24498390091633,0.19639503401707037,-0.015159999950309366
90.0000000000007,16.38195941313301,0.1930735815664637,-0.013810978012079644
91.40000000000072,16.51733509773776,0.19191672503303958,-0.016366373371355714
92.80000000000074,16.65640242243479,0.18837303773157976,-0.015159999279116487
94.20000000000076,16.794320317813625,0.185544982760111,-0.016468778205502854
95.60000000000078,16.930792825178248,0.18650351427612355,-0.017426509161898807
97.0000000000008,17.068071081704915,0.18235096434713238,-0.01779000850641843
98.40000000000082,17.203683824581713,0.18560463425974083,-0.017795274488964452
99.80000000000084,17.341314548176555,0.18651484961356468,-0.01647963724457524
101.20000000000086,17.47676158543059,0.18534042301789855,-0.016481553256137538
102.60000000000088,17.612695704914266,0.18616254245311414,-0.01758485702289958
104.0000000000009,17.748501183007303,0.1858036228608575,-0.016477756590195458
105.40000000000092,17.88513344051992,0.18693593763093186,-0.01911028129267711
106.80000000000094,18.019808944003056,0.18662355372451467,-0.019118378119452384
108.20000000000095,18.156811330823633,0.18786980273798126,-0.017818082560088655
109.60000000000097,18.289494048232864,0.18666698390363257,-0.019111945580029488
111.000000000001,18.42774682680229,0.18615104204281807,-0.020033540913885428
112.40000000000101,18.563298823543878,0.1851396883117622,-0.019111768045756428
113.80000000000103,18.698353198506005,0.18293889243177297,-0.019435756077742283
115.20000000000105,18.832532836527363,0.1819287883272449,-0.018590272070002634
116.60000000000107,18.968498412032638,0.18003091455498144,-0.01944242641245575
118.0000000000011,19.102795950710792,0.18091280145514022,-0.019428799564746413
119.40000000000111,19.238135155899045,0.18043468315964395,-0.020767480177546815
120.80000000000113,19.373840647339385,0.18105394857106738,-0.023063672753012465
122.20000000000115,19.508707178101666,0.18158617439495672,-0.021740372503837424
123.60000000000117,19.644121260886433,0.18155028194121736,-0.02042999980683513
125.0000000000012,19.778760788804195,0.18221070090357916,-0.02052766339445533
126.40000000000121,19.912202007523412,0.17957347734940643,-0.02077606743090854
127.80000000000123,20.049300592074523,0.18120915167712703,-0.02175030625942176
129.20000000000124,20.1831362149296,0.1819723072523951,-0.021800460192565208
130.60000000000127,20.316808376434032,0.1805977906896552,-0.020757879694684345
132.0000000000013,20.45201387271966,0.1819558553370313,-0.02240716375222851
133.4000000000013,20.585690564189495,0.18178716791974825,-0.022420975922887276
134.80000000000132,20.72000000000014,0.18130375165541213,-0.022414308843060837
136.20000000000135,20.852999801091585,0.17980010580143624,-0.022722282965065066
137.6000000000014,20.987787382008264,0.1821027024091122,-0.021409997222667787
139.0000000000014,21.12217445092374,0.1839093605306661,-0.021985060916079657
140.4000000000014,21.255228768898373,0.18225570895488907,-0.021420707499401725
141.80000000000143,21.390588127569835,0.18397800106382034,-0.02273735352224504
143.20000000000147,21.523785742920612,0.1805630224828947,-0.021420001301049485
144.60000000000147,21.657222125420677,0.18333566396953116,-0.022399795731528283
146.00000000000148,21.791214021026633,0.18336904359536987,-0.022725754537876508
147.4000000000015,21.92590609979294,0.1843266559322223,-0.021346594519124462
148.80000000000155,22.05868848503537,0.18241195529714993,-0.022730000001355055
150.20000000000155,22.193611323529456,0.1828728668250148,-0.022729269656361684
151.60000000000156,22.326126482959893,0.1857708949592658,-0.02141095460846243
153.0000000000016,22.46143306373779,0.18506079579119006,-0.024050310514156514
154.40000000000163,22.59423004597598,0.1833583420642757,-0.022730100046516988
155.80000000000163,22.72912367877264,0.1855526208599787,-0.023394531345279912
157.20000000000164,22.863531071448755,0.18502804167813047,-0.02284187227477652
158.60000000000167,22.99684694589337,0.18601024882228367,-0.02414351827043859
160.0000000000017,23.131191124989776,0.18666440894069192,-0.02404999999999813
161.4000000000017,23.263759459722507,0.18848074135709836,-0.024039008681912666
162.80000000000172,23.39759278100771,0.18713767091337097,-0.024049946568664105
164.20000000000175,23.531788503761895,0.18816392887894695,-0.02379498378158207
165.60000000000178,23.664567616945213,0.18766015374594436,-0.02471000001557444
167.0000000000018,23.79760566443954,0.1876372496785963,-0.02424789925547044
168.4000000000018,23.931846873628892,0.18883341020591105,-0.024709972090104504
169.80000000000183,24.065022867983007,0.1889913928067437,-0.023390709272221866
171.20000000000186,24.199369262046513,0.18810700866575392,-0.02326877205974487
172.60000000000187,24.333137120638646,0.19084858936450932,-0.02483065705688947
174.00000000000188,24.46495461938607,0.18708431905424883,-0.024710000000080168
175.4000000000019,24.59929819093192,0.18710973820332577,-0.02470999999999357
176.80000000000194,24.732776888164384,0.1874443138587223,-0.024708905001253
178.20000000000195,24.866356125250356,0.1897965924445928,-0.023583065013810245
179.60000000000196,24.999330819193943,0.19100898224377505,-0.024380755690383893
181.000000000002,25.13213355742195,0.19099931147295734,-0.023389819783178556
182.40000000000202,25.2657714115306,0.1891963131697212,-0.024753573392539696
183.80000000000203,25.39860873516933,0.18992460155452995,-0.02504000431501474
185.20000000000203,25.532296366503417,0.19050662087870385,-0.02635950558192368
186.60000000000207,25.663046600504934,0.18922227518753454,-0.026360000894404045
188.0000000000021,25.79846679055376,0.18897732627975872,-0.025039017373027495
189.4000000000021,25.93146199788171,0.19015006510500032,-0.024892686229832872
190.80000000000211,26.06403818322474,0.18729683338660563,-0.024709974243362076
192.20000000000215,26.196860805022823,0.18806702110852203,-0.02602999373000392
193.60000000000218,26.329903393147372,0.18758721532983413,-0.026030000145014665
195.0000000000022,26.462698413935172,0.18951933545411892,-0.024993655691037286
196.4000000000022,26.594402478478752,0.18816456012632665,-0.026020041261541227
197.80000000000223,26.728304401027437,0.1875775942321809,-0.0273400857940449
199.20000000000226,26.86138178834374,0.18848023338278952,-0.027326842417750186
200.60000000000227,26.994471551228425,0.18783285713907838,-0.027669897783800135
202.00000000000227,27.124831962921377,0.19077475356681828,-0.027340003994306805
203.4000000000023,27.259568397841875,0.18802103486556176,-0.02734000024885086
204.80000000000234,27.391231249503544,0.18822271660956935,-0.027015061834588572
206.20000000000235,27.524193865950508,0.191028054389206,-0.026019991658984498
207.60000000000235,27.656635601222803,0.1900533754019702,-0.02771339089602165
209.0000000000024,27.789617324422196,0.19095050620968412,-0.026349641051356176
210.40000000000242,27.92344820283671,0.19302360781830608,-0.027012258653888566
211.80000000000243,28.055242020427478,0.19177791306848313,-0.027009999999942913
213.20000000000243,28.19000000000023,0.1905842144770622,-0.027010000004656032
214.60000000000247,28.32076228284236,0.1933978426054248,-0.027701228779041465
216.0000000000025,28.454864365168667,0.1929474220551637,-0.026351431484875842
217.4000000000025,28.58749826866678,0.19216218794528794,-0.027662340020802034
218.8000000000025,28.719632027710617,0.19400826198767063,-0.027670000000039607
220.20000000000255,28.85173385820344,0.19248932973218102,-0.02905676970685711
221.60000000000258,28.98639597480228,0.19334876078662866,-0.02764824693098511
223.0000000000026,29.11909310032226,0.19305507150016865,-0.027679998572434528
224.4000000000026,29.253105458617245,0.19373512882579091,-0.028989865239509083
225.80000000000263,29.386114209131613,0.19275261441616331,-0.028986224308932496
227.20000000000266,29.51703776012699,0.19308794990700173,-0.03163412888646144
228.60000000000267,29.65187579624568,0.19287951240156587,-0.030309735501710122
230.00000000000267,29.784369406918668,0.1912195474607996,-0.030362848818180854
231.4000000000027,29.9181280985516,0.19209815977536304,-0.028989999961293034
232.80000000000274,30.05067236624914,0.19325804111821854,-0.028990000000023386
234.20000000000275,30.183279582093867,0.19168771550017083,-0.028987804401128248
235.60000000000275,30.315338094124417,0.19167362990517134,-0.03038663143929954
237.00000000000279,30.447571945856435,0.19278280761444555,-0.029006889025340765
238.40000000000282,30.58407764722594,0.19231870327134648,-0.030967669282936594
239.80000000000283,30.716623875881776,0.18974196957074452,-0.031035681388126513
241.20000000000283,30.850983586077877,0.1912876671408108,-0.031613374766573
242.60000000000286,30.98314893929425,0.19287418306324033,-0.03163017127945533
244.0000000000029,31.116557126733753,0.19094133652482648,-0.03024999201598444
245.4000000000029,31.249909210708093,0.189628183920314,-0.030969935737804377
246.8000000000029,31.383519126931834,0.19074397155062384,-0.03096999999490091
248.20000000000294,31.517452924295732,0.19010090623712772,-0.029852956647229423
249.60000000000298,31.65090586524781,0.19055607853701795,-0.030970014534270174
251.00000000000298,31.784066406587,0.19362388541219544,-0.029650193327512397
252.400000000003,31.915463804479486,0.19266536419555136,-0.03228989270190086
253.80000000000302,32.050302241899416,0.19171250512672233,-0.03130071393432532
255.20000000000306,32.18338709080819,0.18978049888161785,-0.03129999999981958
256.6000000000031,32.31643869366857,0.1894054232968998,-0.031299999999048644
258.00000000000307,32.45009940152186,0.18906187569811794,-0.03129858197539459
259.4000000000031,32.58280134990355,0.1904051059971621,-0.03262000004770904
260.80000000000314,32.71600236434235,0.18947577670748372,-0.033274890764138476
262.2000000000031,32.84734742493261,0.18938738746331518,-0.033279999990899256
263.60000000000315,32.982407032764044,0.18974674303418926,-0.033980996354054493
265.0000000000032,33.11741590318832,0.18829408804859993,-0.03392987670477332
266.4000000000032,33.25055182970224,0.1881207757490655,-0.03261999829463136
267.80000000000325,33.38305119219605,0.1897113346618846,-0.034149936269312064
269.20000000000323,33.51683085001952,0.19119402117322637,-0.03415010435319488
270.60000000000326,33.65101713949864,0.18935287397115563,-0.03382000172398403
272.0000000000033,33.78359542795521,0.1877050981323949,-0.03382000000136909
273.4000000000033,33.917349810477475,0.190171767801665,-0.03376695875877367
274.8000000000033,34.050751293436065,0.19106804841502223,-0.03512999999084876
276.20000000000334,34.18478641792338,0.18890044893101132,-0.03512999999999877
277.6000000000034,34.31891446266718,0.1857948829963807,-0.03512999999999966
279.0000000000034,34.4527612471304,0.18949396060525658,-0.03512999999999833
280.4000000000034,34.58727288524664,0.18956610100891913,-0.035129856866946696
281.8000000000034,34.72067363974366,0.18834350165426006,-0.03545999643702835
283.20000000000346,34.853531316801615,0.18534311831678685,-0.03578637253983041
284.60000000000343,34.98786412507797,0.18787122667737144,-0.03645000652892705
286.00000000000347,35.12202260921156,0.18822755326833196,-0.03382091122823283
287.4000000000035,35.255477046532796,0.18724348776642374,-0.035856497994927405
288.80000000000354,35.39009173280533,0.1880413907357248,-0.03448711018843564
290.20000000000357,35.52286049402623,0.18950354210274978,-0.03887799376281986
291.60000000000355,35.656479002141545,0.1863967550924681,-0.03920000117156697
293.0000000000036,35.790755890844785,0.18577007632848286,-0.03953008069565733
294.4000000000036,35.92500849166397,0.1853289027806797,-0.03952640070496072
295.8000000000036,36.05817765841217,0.18466994915974855,-0.036844981879227134
297.2000000000036,36.19155065948441,0.18539789174102994,-0.038210026605120184
298.60000000000366,36.32670963033344,0.18478478310084046,-0.03820999999999852
300.0000000000037,36.46009335897848,0.18631254650715556,-0.038209999975361786
301.40000000000373,36.59416845602642,0.18542337460593195,-0.04052785521471369
302.8000000000037,36.726952808120174,0.18798426660307532,-0.040519999789281336
304.20000000000374,36.86124991125134,0.1874512365524177,-0.03919784180751318
305.6000000000038,36.99553281479057,0.18999671656290862,-0.03919999989085676
307.00000000000375,37.12934901468598,0.1877862411603768,-0.040518540556029325
308.4000000000038,37.26371097321235,0.18706144440547434,-0.03986049926061064
309.8000000000038,37.398181369655546,0.18845554483755356,-0.03986005230371692
311.20000000000385,37.53154529012191,0.18817647388897152,-0.0418292349495597
312.6000000000039,37.66657921497567,0.18738564771691335,-0.040531922118468344
314.00000000000387,37.79962234821039,0.19048594865536406,-0.04037109483023649
315.4000000000039,37.934351860988784,0.19231485328247788,-0.0401859285941244
316.80000000000393,38.068488990461354,0.192703069251148,-0.04282000277652198
318.2000000000039,38.202879986307366,0.19544879777100133,-0.042440928808190836
319.60000000000394,38.33804570137542,0.19554148113575254,-0.04248999999560299
321.000000000004,38.47434663328446,0.19725068543015034,-0.04345490249212247
322.400000000004,38.60826672087424,0.20049360093353297,-0.044148561608625236
323.80000000000405,38.743355100762535,0.20149238118494028,-0.04479373678460874
325.200000000004,38.87800455651674,0.2016485207858787,-0.0461200295456079
326.60000000000406,39.01261396597622,0.20526783424103878,-0.044833144249544876
328.0000000000041,39.14770369965585,0.2047545064204852,-0.04479617819760229
329.40000000000407,39.280574244434916,0.20644543573967877,-0.04711060679204282
330.8000000000041,39.41707285177235,0.20857511504490156,-0.045790087745967156
332.20000000000414,39.552552503840815,0.21170209836992204,-0.04615558667663011
333.6000000000042,39.68699354455759,0.21210923881843535,-0.047430012183552694
335.0000000000042,39.820941138586626,0.21543065704288988,-0.047502630785346334
336.4000000000042,39.957923513875784,0.2157356131265078,-0.0487490625358622
337.8000000000042,40.092169706077634,0.21442543962956062,-0.049083248589179895
339.20000000000425,40.22707562211034,0.217853096258652,-0.049408311113272596
340.60000000000423,40.36110760883527,0.2209740096296311,-0.05072993953834404
342.00000000000426,40.497436486330436,0.22067946144428308,-0.05072999998784189
343.4000000000043,40.63242760787728,0.22261511561476888,-0.05202048250843161
344.80000000000433,40.76781827853626,0.22528520123990825,-0.05335479163162793
346.20000000000437,40.902982820702725,0.22659134191950914,-0.054678102414240204
347.60000000000434,41.037526148099836,0.2300793887206578,-0.05468000000006512
349.0000000000044,41.17339525804398,0.2282735049582012,-0.054682448966327346
350.4000000000044,41.30878789807807,0.23128706615143235,-0.05567069510451672
351.8000000000044,41.44348319731524,0.23219163649101082,-0.05600322937746416
353.2000000000044,41.579588787678304,0.23069292874236358,-0.057309999261847544
354.60000000000446,41.714964604390794,0.23300222563531392,-0.058629963577465194
356.0000000000045,41.851338337549585,0.2336570409113743,-0.059950013617137365
357.4000000000045,41.98653833557588,0.2353042758450008,-0.06126987011716967
358.8000000000045,42.12253694956132,0.23638740312464135,-0.05995117496324287
360.20000000000454,42.25821922111641,0.24485331638602004,-0.06357087549427298
361.60000000000457,42.39495305408672,0.24216164678985064,-0.0639448254869861
363.00000000000455,42.53048598351466,0.2383696446002348,-0.06653878033770777
364.4000000000046,42.66562160527572,0.24205089254250067,-0.06899446427349787
365.8000000000046,42.80224407685471,0.24126487303610422,-0.06916936947006436
367.20000000000465,42.93954062975241,0.24017733369477767,-0.07078425591219739
368.6000000000047,43.07531228023381,0.2396585886631284,-0.07307198883452459
370.00000000000466,43.21127877502635,0.23931050976454604,-0.07576488023132777
371.4000000000047,43.34798888505228,0.23802362488626616,-0.07709426579697709
372.80000000000473,43.48369030459977,0.24108693322018726,-0.07839129141740253
374.2000000000047,43.62040717547171,0.23941760009853819,-0.08103165483641117
375.60000000000474,43.75718995117224,0.2417380541096954,-0.08360757627463267
377.0000000000048,43.89374219765329,0.2421923031643609,-0.08939370379414502
378.4000000000048,44.02980108789085,0.2432955112525217,-0.09232983047892818
379.80000000000484,44.164770778254656,0.24562637274318555,-0.09711891971567344
381.2000000000048,44.30240891713272,0.24922198832985165,-0.102402068670433
382.60000000000485,44.438917246523104,0.2545726191229043,-0.10619535936890756
384.0000000000049,44.57580365178744,0.2534451079732003,-0.1132356833624728
385.40000000000487,44.71278884653825,0.25465967982615734,-0.11933964473722991
386.8000000000049,44.848843009357196,0.2582011538652198,-0.12452173486208196
388.20000000000493,44.986005497278015,0.25828377852177997,-0.13172606423157074
389.60000000000497,45.12268769064783,0.2604624681887129,-0.13978170622298514
391.000000000005,45.25926505017402,0.2582971954266928,-0.1451230830540471
392.400000000005,45.396481563951546,0.2554546991721671,-0.15213809893371977
393.800000000005,45.53238927284783,0.25505093100413934,-0.1624292227834192
395.20000000000505,45.66978807915579,0.25152425141854406,-0.1692683023267847
396.600000000005,45.8055715412838,0.24533990500229286,-0.17708841566774725
398.00000000000506,45.94309429445724,0.23754317846377826,-0.18699927339620004
399.4000000000051,46.07880738788509,0.22959264235492016,-0.19255636738420456
400.8000000000051,46.21410326402069,0.22060477616818197,-0.19925683801820515
402.20000000000516,46.3501906643186,0.21305768969784133,-0.20642186739712365
403.60000000000514,46.486977839012766,0.20256991368466792,-0.21212015957416774
405.0000000000052,46.62297413177252,0.18941306052038298,-0.218896416271817
406.4000000000052,46.75834866311891,0.1771564466357609,-0.22286469096040484
407.8000000000052,46.89539139947947,0.1680738722781545,-0.22818189421153434
409.2000000000052,47.03148717028723,0.1549210851890095,-0.2307423235602517
410.60000000000525,47.1678587635275,0.1442938678988035,-0.23473976759505977
412.0000000000053,47.30366868956656,0.134157421809719,-0.23600896583835462
413.4000000000053,47.44104054607659,0.12769193082577113,-0.23743353788726296
414.8000000000053,47.57777485165025,0.12358987891342732,-0.23735380221772662
416.20000000000533,47.71286827980282,0.12189116075347539,-0.23869486924071914
417.60000000000537,47.85206935562096,0.12068484005620417,-0.24008584040996706
419.00000000000534,47.98834947747825,0.11524580350340652,-0.24229646431852014
420.4000000000054,48.1263081404247,0.1149236744401676,-0.24460927411802968
421.8000000000054,48.26343182604417,0.11421179863977349,-0.24525752496452125
423.20000000000545,48.399689161128386,0.11482939981934015,-0.24560941985040863
424.6000000000055,48.53766868477081,0.11596258831571649,-0.24559961098694938
426.00000000000546,48.67564582434511,0.11339476337231846,-0.24690999994531948
427.4000000000055,48.810808692577375,0.12040256551769035,-0.2482302220528636
428.8000000000055,48.9493002013503,0.12171674388785503,-0.24951173286754713
430.2000000000055,49.086440540268114,0.123361037386577,-0.24894407403942376
431.60000000000554,49.22314735496854,0.1266991817765033,-0.24920786151991292
433.00000000000557,49.36156996755938,0.12955662036780424,-0.25053001266381836
434.4000000000056,49.498445367770174,0.1342958860037704,-0.2518524526966148
435.80000000000564,49.635346326649,0.13220573362668664,-0.25052693870371323
437.2000000000056,49.77415221748805,0.13256003069463707,-0.2531876687799799
438.60000000000565,49.912053152029685,0.13290160156632203,-0.2531701305595826
440.0000000000057,50.04913213687606,0.131264208509134,-0.2544937302314292
441.40000000000566,50.188023553496365,0.13367348281738822,-0.25448993391281016
442.8000000000057,50.32581225557224,0.1318197899204412,-0.25588004499249273
444.20000000000573,50.46368622227875,0.13432506451610804,-0.2557995421839512
445.60000000000576,50.60141095438303,0.13387186220535008,-0.2575687430731848
447.0000000000058,50.74020626278491,0.1333616899770924,-0.2567900206487703
448.4000000000058,50.87781430279119,0.13444032020924324,-0.25815855506635677
449.8000000000058,51.01515251622043,0.1355333404121919,-0.2604442766219379
451.20000000000584,51.152892911808124,0.13620189255115966,-0.26075000000143955
452.6000000000058,51.29051030426526,0.13718859435164665,-0.2594297124876661
454.00000000000585,51.42798952937846,0.13511297168593228,-0.260410876996338
455.4000000000059,51.56611154888607,0.13417725901069266,-0.2617259147861204
456.8000000000059,51.70462892702228,0.13968659928717542,-0.2630607455339087
458.20000000000596,51.842621447465966,0.13947441765911917,-0.26339081860090996
459.60000000000593,51.98070157108122,0.1374978706180492,-0.26407227895597973
461.00000000000597,52.11848215828152,0.13984965890807732,-0.26470005730437496
462.400000000006,52.25723265929492,0.13924102363590807,-0.2660098720053896
463.800000000006,52.39525047038043,0.13978154526492803,-0.2653298736635472
465.200000000006,52.53324790047552,0.13590767858122588,-0.2666690296355809
466.60000000000605,52.670796840384426,0.1358062240980893,-0.2689799549987293
468.0000000000061,52.80892781434707,0.13511251387814482,-0.268919289146373
469.4000000000061,52.948220474240706,0.13475873539270178,-0.2677207944530591
470.8000000000061,53.08653033834385,0.13000834376539672,-0.2681881487880977
472.2000000000061,53.22512748896824,0.12906505683760883,-0.268884746841235
473.60000000000616,53.36396228733897,0.12862556607762277,-0.27018000000309117
475.00000000000614,53.50275175550765,0.12557776437895996,-0.2701804457457766
476.4000000000062,53.640829726545434,0.12513351572947617,-0.2714999477250859
477.8000000000062,53.77903182411377,0.12303030943619886,-0.2751702547894248
479.20000000000624,53.918962569940916,0.11954659016329616,-0.27256973480445135
480.6000000000063,54.05772403621338,0.12153116790330953,-0.27188034693021024
482.00000000000625,54.196310997047036,0.12123145198548646,-0.2745845301573979
483.4000000000063,54.33452873863349,0.12376029386822096,-0.27458011896985113
484.8000000000063,54.473751034692846,0.12088955957703251,-0.27590023581968337
486.2000000000063,54.612238487930696,0.11887484804483495,-0.2759020324373571
487.60000000000633,54.74896229870933,0.11397638809948485,-0.2765499798006914
489.00000000000637,54.89027544972841,0.11670703774834168,-0.27654999999999985
490.4000000000064,55.029239497282504,0.11163617208823484,-0.2765499956132236
491.80000000000643,55.167836203568086,0.11175469034346164,-0.27688181276128043
493.2000000000064,55.30693648216002,0.10762311933297397,-0.27688025095260027
494.60000000000645,55.442313678519305,0.09493147397859114,-0.27874724720649535
496.0000000000065,55.58332877743029,0.08936179048754989,-0.278091961442958
497.40000000000646,55.72250447219695,0.08313758958274953,-0.27808999030095594
498.8000000000065,55.86058245842718,0.07489107962747399,-0.27940998156059216
500.2000000000065,55.99960304048546,0.07488399633094067,-0.27940999991473126
501.60000000000656,56.13910396721319,0.07038593178247954,-0.28038980792770873
503.0000000000066,56.27809890884156,0.07152638489516194,-0.2800020221055015
504.40000000000657,56.41743724997752,0.06635772613499014,-0.2800609400265839
505.8000000000066,56.556610858373325,0.06342596201544981,-0.2813785971027838
507.20000000000664,56.69568569041363,0.05887691491812719,-0.28072292558609524
508.6000000000066,56.834390804302245,0.05492826807834361,-0.2813804261495889
510.00000000000665,56.97383911732625,0.047521413246730315,-0.2815776546998361
511.4000000000067,57.112986977533645,0.04701007894043885,-0.2840188028955515
512.8000000000068,57.25225058558174,0.04253535594541291,-0.2827064187830586
514.2000000000068,57.39117642215847,0.0371279971869789,-0.2826994706988577
515.6000000000067,57.53116028999766,0.035449006690619234,-0.2827000001697466
517.0000000000068,57.671191050493476,0.03544559913698686,-0.28367874497176615
518.4000000000068,57.80841739645606,0.033854812257642086,-0.2839753720773128
519.8000000000068,57.94852378833071,0.03344295720839541,-0.28401000717140157
521.2000000000069,58.08858474040005,0.03342714345511677,-0.28430726676019535
522.6000000000068,58.22819079675768,0.03404925213971444,-0.28471998247049735
524.0000000000068,58.367443516012344,0.03508209366589887,-0.2850521918192772
525.4000000000069,58.50733161246041,0.03849480569831454,-0.2849437003557935
526.8000000000069,58.64706746832446,0.035533696411843785,-0.28587204516585984
528.2000000000069,58.78666585006492,0.03513043206279609,-0.2856702843149259
529.600000000007,58.927535300009716,0.03451319048841062,-0.2856695371077138
531.0000000000069,59.06719042747433,0.03431094917760302,-0.28561183180538263
532.4000000000069,59.206357777428295,0.03479082322477467,-0.2870128471589384
533.800000000007,59.34677528022364,0.03938909353059339,-0.2869937900691699
535.2000000000071,59.48574004043959,0.03750513745274464,-0.28560336844955625
536.6000000000071,59.62704912586401,0.04004094323936047,-0.2876592118799839
538.000000000007,59.76666288342011,0.039609584094228545,-0.28631999624512616
539.4000000000071,59.90642216022703,0.04295924276644092,-0.2863200002719939
540.8000000000071,60.04676861069077,0.038684288419424284,-0.2866615333983975
542.2000000000071,60.18744857036854,0.04057785968544336,-0.28797000005366513
543.6000000000072,60.32733181834707,0.03755673084380384,-0.2879942956963424
545.0000000000072,60.46795161327715,0.03959649869401849,-0.2892900037687034
546.4000000000071,60.60815113208892,0.040933259322186055,-0.2886304939998938
547.8000000000072,60.747681920177875,0.04381503941644049,-0.28896083435434683
549.2000000000072,60.88668123514059,0.044644803480154094,-0.28731078183760905
550.6000000000072,61.02864664833019,0.04458059037125861,-0.2873078880802278
552.0000000000073,61.1689014486966,0.04311414975589023,-0.2879598285534586
553.4000000000073,61.3105740149324,0.04398411030435745,-0.2892800003191134
554.8000000000073,61.449805065292324,0.04348368753624188,-0.28828973160891325
556.2000000000073,61.589213814063186,0.04182492576530006,-0.28961100810176177
557.6000000000073,61.73000195593009,0.040966545812250565,-0.28961000000000015
559.0000000000074,61.87039318338765,0.03847783455028764,-0.28960999999754344
560.4000000000074,62.009997706518156,0.03658167481234398,-0.28961432907230034
561.8000000000075,62.15048512898146,0.0353379632526265,-0.28961999999991805
563.2000000000074,62.29176293519637,0.03612076241745643,-0.2896153713130052
564.6000000000074,62.43085013838752,0.03640349838883861,-0.2909292737457312
566.0000000000075,62.57151616319524,0.03170292998440405,-0.29021121815724005
567.4000000000075,62.71146344537316,0.03329425517351581,-0.29027974963730196
568.8000000000075,62.85189891090004,0.03509769662693718,-0.2909311389423612
570.2000000000075,62.99279876807136,0.03780272352724956,-0.2922503011448172
571.6000000000075,63.13285090573257,0.040588403190461086,-0.2909292801973917
573.0000000000075,63.27423975186201,0.0589496803543903,-0.2919198655802613
574.4000000000076,63.416221197417045,0.08495226162473135,-0.2909242729586281
575.8000000000076,63.5558475639537,0.04508403939661121,-0.2919368950833827
577.2000000000077,63.69643865903269,0.027777486249868755,-0.2925672074038079
578.6000000000076,63.83716947988272,0.024342296874838576,-0.2912600630051956
580.0000000000076,63.977532087493515,0.023942967985142616,-0.2939252238959016
581.4000000000077,64.11807960823309,0.026930722736590917,-0.29608321558443196
582.8000000000077,64.25944871910303,0.02422419011319321,-0.2936666192919648
584.2000000000078,64.40039318414672,0.028797918771561237,-0.29333099812905017
585.6000000000078,64.54130974722365,0.025610891297737526,-0.2936641917435243
587.0000000000077,64.68073610967647,0.022685770513983794,-0.29369815202693994
588.4000000000078,64.82124763045782,0.02585329235800793,-0.29499000044632284
589.8000000000078,64.96039351897508,0.020743215690594896,-0.2959800821422891
591.2000000000078,65.10362475196035,0.024419993220411884,-0.29630999626008236
592.6000000000079,65.24366848924495,0.030072428270105922,-0.2962880928653031
594.0000000000078,65.38513123385576,0.030424206232043005,-0.29565780285925003
595.4000000000078,65.52594152566385,0.03276221117875333,-0.294580378209472
596.8000000000079,65.66656362142459,0.03314221419417196,-0.2969505529321159
598.2000000000079,65.80816583740838,0.03128903411399775,-0.2969699999999733
599.600000000008,65.94830133163715,0.032518331261914835,-0.29697000000148677
601.000000000008,66.08990344271116,0.03202477649129354,-0.297978266115448
602.4000000000079,66.23073191433363,0.03287341830197854,-0.2992799603846432
603.800000000008,66.37151310030336,0.033372459624222195,-0.2992900480783023
605.200000000008,66.51285469112199,0.03615632296128135,-0.2992799999995359
606.6000000000081,66.65394287618557,0.0407171516350453,-0.2978674392583365
608.0000000000081,66.79411209482642,0.03795915270263861,-0.29926999940936705
609.400000000008,66.93546398478036,0.03863927535284106,-0.29927000960493455
610.8000000000081,67.07649472910165,0.04358562223767204,-0.3005900299095763
612.2000000000081,67.21786550996914,0.04779049184260553,-0.301910251932485
613.6000000000081,67.3584053220609,0.05459998789536069,-0.30321448401607753
615.0000000000082,67.49885943910654,0.056490947028074556,-0.3032300295213992
616.4000000000082,67.64097187614938,0.06305836539345133,-0.3031636348816842
617.8000000000081,67.7839550821524,0.0736368495276769,-0.30455243007689115
619.2000000000082,67.92524068369838,0.07433860744394094,-0.3045514647781338
620.6000000000082,68.06623084131127,0.0775324243974056,-0.3058700009954034
622.0000000000083,68.20701012100828,0.07612577515284413,-0.3071902270226312
623.4000000000083,68.35030130299386,0.08056384449783849,-0.308195539966972
624.8000000000083,68.49131829765226,0.08334253974508798,-0.30751586017727206
626.2000000000083,68.63279284858292,0.0831987873442781,-0.31015183134491187
627.6000000000083,68.77462103706216,0.08863505160347951,-0.3085330920523299
629.0000000000084,68.91607257793652,0.08972790193675384,-0.31126291551386664
630.4000000000084,69.05811354867959,0.09039907380262968,-0.3138747163877773
631.8000000000084,69.19824772667252,0.09635761122746778,-0.3138797233745865
633.2000000000085,69.3401050843126,0.09840333104510268,-0.31388206604947744
634.6000000000084,69.4822968660179,0.10079519029331041,-0.31452978618035576
636.0000000000084,69.62462797082141,0.11112255866996601,-0.31795784275817685
637.4000000000085,69.76607183447823,0.11666496937865034,-0.31896691635318275
638.8000000000085,69.9079431559427,0.12426608727502675,-0.3213872803114337
640.2000000000085,70.04795578684617,0.13698170827771183,-0.321548769587511
641.6000000000085,70.19083554232726,0.1504835029241045,-0.3228816121082705
643.0000000000085,70.33381899704136,0.15301609455388054,-0.32561581665878103
644.4000000000086,70.47490689792987,0.17547406498943086,-0.32727239749953485
645.8000000000086,70.61719203078235,0.18774947427581323,-0.32924777990020004
647.2000000000086,70.75989675648688,0.20172164899279488,-0.3322210351293542
648.6000000000087,70.90030053169134,0.21469110821927728,-0.3351838135276548
650.0000000000086,71.04452201059202,0.2240910273279213,-0.33753538745706546
651.4000000000087,71.18674007896087,0.23765792319788948,-0.33879354248227855
652.8000000000087,71.32882635502683,0.24611497808334315,-0.3439500713182113
654.2000000000087,71.47104103115255,0.2559617987553462,-0.3442841254180542
655.6000000000088,71.61173879821779,0.26970540991509706,-0.34689848174199156
657.0000000000088,71.75624133519274,0.28713644114478054,-0.35181147923555134
658.4000000000087,71.89872941525638,0.30357353731171943,-0.35166055772003935
659.8000000000088,72.04171751485266,0.3240791848093467,-0.35568905878332524
661.2000000000088,72.18367604216236,0.3359499657430569,-0.35970088071000417
662.6000000000088,72.3256743579325,0.35435225269779647,-0.3663724889866775
664.0000000000089,72.4675204988026,0.372382160806944,-0.36895634006052624
665.4000000000088,72.61097036980362,0.39002785695760234,-0.37543657416765885
666.8000000000089,72.75314745599293,0.40335353283863373,-0.37725567739191757
668.2000000000089,72.89523984598648,0.4255454492878432,-0.38269627495317415
669.6000000000089,73.03829652832151,0.4487098807560683,-0.3879212725794301
671.000000000009,73.18065166749322,0.46421691700231404,-0.3928139363058136
672.400000000009,73.32370993748027,0.4895136722673783,-0.3972394845534417
673.800000000009,73.46536367402004,0.5113684514295627,-0.40283340789566413
675.200000000009,73.6082603705141,0.5330330791812286,-0.4099568470340662
676.600000000009,73.75092941192766,0.5621302882857708,-0.4150520828040758
678.0000000000091,73.89424205909177,0.5902363899003302,-0.42268343163335365
679.4000000000091,74.03615268861829,0.6187904956903401,-0.4280304109852797
680.800000000009,74.17949252091839,0.6569181201914991,-0.434836891078322
682.2000000000091,74.32170025616772,0.6928264076307704,-0.4425603927697144
683.6000000000091,74.46438730354181,0.7306032635846416,-0.4504411476438528
685.0000000000091,74.60734198413131,0.7770687272783883,-0.4551543326787937
686.4000000000092,74.74962334344656,0.8144802932342454,-0.4627166877627418
687.8000000000092,74.89326864501646,0.8523974979535529,-0.473822302964817
689.2000000000093,75.03576982876226,0.8886273615998657,-0.4832480170494997
690.6000000000092,75.17852346069742,0.9199903482026071,-0.4917612515865928
692.0000000000092,75.32186299774413,0.9606211496691492,-0.5002930374638836
693.4000000000093,75.4614718755991,0.995158448359236,-0.5102861451914302
694.8000000000093,75.60742679642956,1.0422408006115529,-0.5211880308191956
696.2000000000094,75.749787986387,1.0813944313537358,-0.5317805623462375
697.6000000000093,75.89383626076703,1.118848955715184,-0.5412565634421518
699.0000000000093,76.03701550310949,1.1584897830800043,-0.5536889965342424
700.4000000000094,76.17954417549947,1.2029211739365666,-0.5670033855376766
701.8000000000094,76.32274310626487,1.2435925812947914,-0.5804957833371449
703.2000000000094,76.46653300759023,1.2902528237926916,-0.5924832065914698
704.6000000000095,76.60949777204615,1.3413624635844836,-0.603010757551067
706.0000000000094,76.75319879335316,1.3845113254061983,-0.616955492154879
707.4000000000094,76.89655409263219,1.4364457784626514,-0.6307770127314867
708.8000000000095,77.0407232171736,1.489146268009152,-0.6485638317686706
710.2000000000095,77.1846819984965,1.5419247638260705,-0.6644380089240518
711.6000000000096,77.33010375167852,1.5923187189987758,-0.6816320307556305
713.0000000000095,77.473608342932,1.6515015780302282,-0.6972854884782191
714.4000000000095,77.61791996426514,1.7031525352694408,-0.7136331447800486
715.8000000000096,77.76439542723973,1.7572675444336954,-0.733527372914903
717.2000000000096,77.9066214284136,1.8119249152164418,-0.7478835173418079
718.6000000000097,78.05040532553403,1.8645888325146267,-0.7653140776470608
720.0000000000097,78.19512519664583,1.9188242141956915,-0.7850943985737486
721.4000000000096,78.3377059970308,1.9769678673256106,-0.8057686470164853
722.8000000000097,78.48431334055789,2.0314922880193143,-0.8249995694354726
724.2000000000097,78.62786138242475,2.0844575698702776,-0.8491013271753927
725.6000000000097,78.77256773911695,2.14549560874859,-0.8691614588668446
727.0000000000098,78.91597501574516,2.196369206715329,-0.8889527993658182
728.4000000000098,79.06115081410162,2.253175915053562,-0.911452653459984
729.8000000000097,79.204474053443,2.3010876304612222,-0.93538079576693
731.2000000000098,79.3489348756047,2.3532105353981176,-0.9581416261089943
732.6000000000098,79.49266932517097,2.401669957622266,-0.9825539569621657
734.0000000000099,79.63583982300898,2.446771659109307,-1.0052557486256242
735.4000000000099,79.77966593396563,2.483832499546657,-1.0310188025028126
736.8000000000098,79.92334242091556,2.51704164318024,-1.053166311808254
738.2000000000099,80.06672637024622,2.538410218820151,-1.0807782186688324
739.6000000000099,80.21000204639098,2.548646981312793,-1.106137782508395
741.00000000001,80.35352362507905,2.5441613993138645,-1.1306079316555544
742.40000000001,80.49587935578414,2.5215821241850436,-1.1554097990551888
743.80000000001,80.6369175473933,2.483875420188564,-1.1815717498522638
745.20000000001,80.77814750113572,2.418547918830748,-1.2076716878992557
746.60000000001,80.91834337538903,2.3216046222666282,-1.2304478571276403
748.00000000001,81.05647031324811,2.1800880129744797,-1.2511623075699019
749.4000000000101,81.1947204072513,1.9945169948507306,-1.271297762082317
750.8000000000101,81.33175934185172,1.7456991839198026,-1.2909167688589127
752.20000000001,81.46620278434206,1.4234556115504793,-1.3076711063776747
753.6000000000101,81.5981594028742,1.039515015915077,-1.3234242802304337
755.0000000000101,81.73217251864739,0.6440024367478894,-1.3275099231351009
756.4000000000102,81.86728948319629,0.3329643147776489,-1.3338353661218538
757.8000000000102,82.00371301858512,0.13536764404960655,-1.3373760272497828
759.2000000000102,82.1436982788376,0.011129390405072659,-1.3414667570577312
760.6000000000103,82.28407971632444,-0.05989989165891885,-1.342860479242332
762.0000000000102,82.426057437066,-0.10125637869055537,-1.3445554400602506
763.4000000000103,82.56892939591538,-0.1298002570033734,-1.3447568587005216
764.8000000000103,82.71192789477725,-0.14144932420169742,-1.3437167083383659
766.2000000000103,82.85379906016675,-0.15963526594135846,-1.3457400001342683
767.6000000000104,82.99574612281022,-0.15844040942656235,-1.3455575464290397
769.0000000000103,83.13976963869948,-0.16268619266935325,-1.3455653649587123
770.4000000000103,83.28244233989291,-0.16465312061736603,-1.3470491428904916
771.8000000000104,83.42486700323877,-0.17205666112587514,-1.3457299825503442
773.2000000000104,83.56723016940768,-0.17141246799492404,-1.3447400022843214
774.6000000000104,83.71103526352793,-0.17324543768902556,-1.3450941108858925
776.0000000000105,83.85458658813802,-0.17470028184460618,-1.3474176892907606
777.4000000000104,83.99734004701557,-0.17277202752737808,-1.345370147362892
778.8000000000105,84.14150277648801,-0.17414224051572624,-1.3427687774923562
780.2000000000105,84.28469755795174,-0.1800787627038516,-1.3454098664720284
781.6000000000105,84.42734735775319,-0.18287883216235978,-1.347257874038708
783.0000000000106,84.571570718319,-0.1853709337910996,-1.3469456058365683
784.4000000000106,84.71341620689319,-0.18291627623244766,-1.345620649215355
785.8000000000106,84.85731638316707,-0.1861656602632904,-1.3470288522547018
787.2000000000106,84.99961631160414,-0.18701264316086474,-1.3452898269218116
788.6000000000106,85.14294918058653,-0.19185803979704819,-1.3452881846525409
790.0000000000107,85.28583625548109,-0.19574896312681211,-1.345289948292534
791.4000000000107,85.43008208638479,-0.19442849656567263,-1.3449600043773655
792.8000000000106,85.57309302270632,-0.19615874921032184,-1.3452900339659983
794.2000000000107,85.71677348585412,-0.19250411011344348,-1.3445951100546418
795.6000000000107,85.86000216204455,-0.1927532587594727,-1.345999594648149
797.0000000000107,86.0029743213283,-0.1994419036701458,-1.3460379845843824
798.4000000000108,86.1456877322699,-0.20002005220480612,-1.3462800000007067
799.8000000000108,86.28804589595754,-0.20707736890862383,-1.344976142025378
801.2000000000108,86.4324073697722,-0.2118289729724352,-1.346281589089318
802.6000000000108,86.57469477852344,-0.21360858028478824,-1.345089371490305
804.0000000000108,86.71784632506876,-0.21549950205964907,-1.3472698856598981
805.4000000000109,86.86052021601218,-0.21794118496860015,-1.3471423576556396
806.8000000000109,87.003891503943,-0.21925908381928583,-1.3474743959421795
808.200000000011,87.147512999487,-0.2187431658686494,-1.3451900924117641
809.6000000000109,87.29000206785628,-0.22280081428590837,-1.3468308441049057
811.0000000000109,87.43315229110057,-0.22120129886568152,-1.3446281931977464
812.400000000011,87.57625657977059,-0.2263075643901311,-1.3431984738098501
813.800000000011,87.71968763953082,-0.2241103729449414,-1.344633488252314
815.200000000011,87.8633628046018,-0.2329840672978274,-1.3433184694928677
816.600000000011,88.00746453847105,-0.23173739323988696,-1.3466841461412415
818.000000000011,88.15077710969781,-0.2298151932849044,-1.3472732437746
819.400000000011,88.29478945071013,-0.23100918795796677,-1.3459500907363262
820.8000000000111,88.43795149380273,-0.23570596369359764,-1.3461948913729307
822.2000000000111,88.58099322996351,-0.23098376960643474,-1.3469400000102993
823.6000000000112,88.72415506045188,-0.23437874254334412,-1.3459649629584556
825.0000000000111,88.86787305851871,-0.23504230990053765,-1.3469399404884346
826.4000000000111,89.01146188606567,-0.2353504704776357,-1.3470393478665774
827.8000000000112,89.15411356694453,-0.23525154454387365,-1.3455105509116034
829.2000000000112,89.29860849249725,-0.2369424064263197,-1.3455099999620552
830.6000000000113,89.44228081724796,-0.24284342852752094,-1.3458395243539458
832.0000000000113,89.58532353335296,-0.23961712542291247,-1.3471605034783334
833.4000000000112,89.72923687181763,-0.24137068037436027,-1.347163216204987
834.8000000000113,89.87292978543618,-0.2398239715767998,-1.3484523953339687
836.2000000000113,90.0168589204238,-0.23502758027289117,-1.3471643135281046
837.6000000000113,90.16100230588086,-0.2436243198099306,-1.3451976662620622
839.0000000000114,90.30503218115605,-0.24728185498742805,-1.3451756665163965
840.4000000000113,90.44831904123913,-0.24577257041313683,-1.347820248031744
841.8000000000113,90.59095905091861,-0.24593675367272505,-1.3478200011748016
843.2000000000114,90.735338784672,-0.24309409618116185,-1.3464998368279666
844.6000000000114,90.8792111357174,-0.24782936626182872,-1.3491695509638202
846.0000000000115,91.02251910420027,-0.24319228997099662,-1.3464990724646206
847.4000000000115,91.16577217407843,-0.2501695625983351,-1.3465299071564871
848.8000000000114,91.3091794472374,-0.24728856316801773,-1.3491101819905862
850.2000000000115,91.45353705134215,-0.2518919373924793,-1.3504591875861176
851.6000000000115,91.59573063845728,-0.2454649139459799,-1.3484085556692484
853.0000000000116,91.74055819164286,-0.24372402800207738,-1.3450781120117266
854.4000000000116,91.88374296820629,-0.25128736835002474,-1.3443656968241147
855.8000000000116,92.02721451243892,-0.2514835206829322,-1.3486466508007031
857.2000000000116,92.17173314865676,-0.25685565079483785,-1.342549763237606
858.6000000000116,92.31532975243509,-0.26068520386197047,-1.348020857603132
860.0000000000116,92.45876004519829,-0.261345361785025,-1.3494749440750682
861.4000000000117,92.60267831406452,-0.2571922105433102,-1.3471609886178975
862.8000000000117,92.7466205365938,-0.263689527185083,-1.3493873596077735
864.2000000000116,92.88999892335909,-0.2645948002953067,-1.34904179786784
865.6000000000117,93.03391499838276,-0.2612962076100618,-1.346930171465091
867.0000000000117,93.17791035322993,-0.2607174604929603,-1.3475076969505193
868.4000000000118,93.32085170208506,-0.2603513275922107,-1.3468935425673667
869.8000000000118,93.46491851271341,-0.27024120573328103,-1.3484309874416511
871.2000000000118,93.60949632171486,-0.26865103990181094,-1.3495410321686871
872.6000000000118,93.75188789625776,-0.2757024120275533,-1.3482601524337134
874.0000000000118,93.89548184458585,-0.28263323494077097,-1.3469420423836027
875.4000000000119,94.03999800512558,-0.27723659327806427,-1.3482600000506935
876.8000000000119,94.18274264341913,-0.2809395575969438,-1.3482598291863805
878.2000000000119,94.32560887954365,-0.2822400797707525,-1.3496490246153452
879.600000000012,94.46989449385738,-0.2852469102854185,-1.3498997987750605
881.0000000000119,94.61338210757557,-0.28214284759690855,-1.3485800907921384
882.4000000000119,94.7577654865022,-0.2872701458635798,-1.348967415768311
883.800000000012,94.90070691311938,-0.2792404485072306,-1.3489200363923008
885.200000000012,95.04548424386127,-0.279678417980453,-1.3499423788880693
886.600000000012,95.18990002207963,-0.2811338932804328,-1.3512200020378748
888.000000000012,95.33376746080472,-0.28175541642075297,-1.3499100079241169
889.400000000012,95.47798998108281,-0.2769443916086787,-1.3515592983523974
890.8000000000121,95.62154525518432,-0.2754539046486242,-1.349580073460403
892.2000000000121,95.76558850467136,-0.2781556458347221,-1.3502399051289795
893.6000000000121,95.90781965392227,-0.27791027173827176,-1.35286000062933
894.0000000000122,95.9502258206034,-0.2778460808660572,-1.3528600002383304