File: 01_Data/Smoke_Explosion_Plywood/STA/N2/10K_min/Smoke_Explosion_Plywood_STA_N2_10KData_230803_R5.csv
##Temp./Â°C,Time/min,DSC/(mW/mg),Mass loss/mg
27.0,20.60812214982755,-2.4195500808073582,-0.14444367715391992
28.100000000000016,21.023190177309733,-2.3821035007208082,-0.1482665657645974
29.20000000000003,21.263560108606313,-2.366383081357515,-0.14724895939397786
30.300000000000047,21.453930486683312,-2.3560493466509693,-0.14854761836873065
31.400000000000063,21.62210668807601,-2.351695447898826,-0.14965062171445798
32.50000000000008,21.77712886270202,-2.3471202837121914,-0.1490920545105845
33.600000000000094,21.923126349931763,-2.3446450227796647,-0.1507915879030719
34.70000000000011,22.062022346314738,-2.3430441734470295,-0.1522232142833877
35.800000000000125,22.198109375222465,-2.344331501163236,-0.1534863108988791
36.90000000000014,22.331196364251717,-2.344239377747989,-0.15347574811278797
38.000000000000156,22.460301805555165,-2.3464771443215144,-0.15491054857567432
39.10000000000017,22.58941064608192,-2.3476757104082133,-0.1549173782210067
40.20000000000019,22.714250952999038,-2.349964781835093,-0.1561762358772949
41.3000000000002,22.84010603599398,-2.351677330708355,-0.157541204854307
42.40000000000022,22.960189665755557,-2.356523990752995,-0.15886133717823592
43.500000000000234,23.087844151902008,-2.3608239660242356,-0.1609972422430972
44.60000000000025,23.208575965159184,-2.364712676090585,-0.1628092867182369
45.700000000000266,23.331778810407506,-2.368444756793817,-0.1628086357853169
46.80000000000028,23.44900638836475,-2.3735034718799057,-0.16441874682216984
47.9000000000003,23.57316325230454,-2.379323664530525,-0.16543988973659696
49.00000000000031,23.69163602487676,-2.3836682826593405,-0.1667602380125488
50.10000000000033,23.812029896665617,-2.388855573608412,-0.1687999919249159
51.200000000000344,23.92958620694013,-2.39423816844689,-0.17071014914252514
52.30000000000036,24.04627719746641,-2.39843602728271,-0.17334983010334426
53.400000000000375,24.164608995020128,-2.4025807349920827,-0.17466985873340235
54.50000000000039,24.28163157934636,-2.406411137681205,-0.17729968973463306
55.600000000000406,24.397235447964036,-2.4113476962752425,-0.1785685415815692
56.70000000000042,24.514028094390902,-2.415329606372939,-0.18126005327082106
57.80000000000044,24.62729856642816,-2.4179191117275773,-0.18323005586276997
58.90000000000045,24.741950820349015,-2.4216204716725738,-0.18519993494276532
60.00000000000047,24.854834217408975,-2.423914959017337,-0.1878399695005344
61.100000000000485,24.968473115973083,-2.4245699235719416,-0.1904797189697458
62.2000000000005,25.08126493082027,-2.4257873643555294,-0.19316491663760038
63.300000000000516,25.194246644975728,-2.4274092091355843,-0.19449681836736854
64.40000000000053,25.305830000000064,-2.4271400000000023,-0.1973899290993324
65.50000000000054,25.416653679368924,-2.424801544364207,-0.19970421930956173
66.60000000000056,25.52762294470017,-2.4224716046016823,-0.20245430049842916
67.70000000000059,25.63917000000007,-2.420009999999995,-0.20628146292837313
68.8000000000006,25.74935880114494,-2.416251406737399,-0.20891987669490053
69.9000000000006,25.858818913846005,-2.4109002299446214,-0.21023988022628615
71.00000000000063,25.971038124591622,-2.4049591385468596,-0.21331556804469098
72.10000000000065,26.080480169586036,-2.3968745123087656,-0.21549994218108814
73.20000000000066,26.18898781293438,-2.389569032859628,-0.21781809798089968
74.30000000000067,26.298580840416644,-2.3796503700972704,-0.22078019387711034
75.40000000000069,26.407821837179277,-2.3705079504387783,-0.2238570772836761
76.50000000000071,26.516917843914655,-2.360560583711092,-0.22706386166989878
77.60000000000072,26.626057019208698,-2.349944360990772,-0.2270301273376032
78.70000000000073,26.736976424154793,-2.339012991842636,-0.22868491894593035
79.80000000000075,26.84398670528527,-2.3280930780569165,-0.23265131058653932
80.90000000000077,26.954430251538426,-2.3157573934805438,-0.23395016099986687
82.00000000000078,27.06033851686795,-2.3036358578087652,-0.2339501169539444
83.10000000000079,27.16980861716669,-2.2895623991170018,-0.23526574370828124
84.20000000000081,27.278196745473778,-2.2774297114491153,-0.2379059419358711
85.30000000000084,27.38730000824829,-2.262536345459594,-0.24185019785458017
86.40000000000084,27.49548577614875,-2.2493665105725427,-0.24317157802852396
87.50000000000085,27.603224115308098,-2.2343438816357737,-0.2441246884749968
88.60000000000088,27.709966604320847,-2.220025191807211,-0.2459095670511129
89.7000000000009,27.819282100064044,-2.205129809667746,-0.24679986500022677
90.8000000000009,27.92435551420255,-2.1908554443785517,-0.24680028657641184
91.90000000000092,28.0302755241293,-2.178310712746003,-0.24843754700682696
93.00000000000094,28.138755756283498,-2.1641469045071235,-0.24976081948781115
94.10000000000096,28.244339220172055,-2.1519329046724796,-0.24953982671167196
95.20000000000097,28.352126779777713,-2.1371691078674395,-0.2509306755754941
96.30000000000098,28.45702828117722,-2.1246973159508107,-0.25179500613929706
97.400000000001,28.56517413981416,-2.1113010724582435,-0.25348987677812174
98.50000000000102,28.670731539144626,-2.099646323034899,-0.2548098584645899
99.60000000000103,28.777814782177444,-2.0876865470759287,-0.25480689505999843
100.70000000000104,28.88042521549738,-2.074368020703364,-0.25611986097839434
101.80000000000106,28.989427913778176,-2.064858974731791,-0.25745689804445515
102.90000000000109,29.09590344489324,-2.05360270718743,-0.2562557789501394
104.0000000000011,29.202798388386064,-2.043676816705162,-0.25778284762833925
105.1000000000011,29.306761339922566,-2.0359376336255264,-0.257780135836827
106.20000000000113,29.41510921184017,-2.025315315894881,-0.25910011088981477
107.30000000000115,29.52093264414263,-2.016893069379272,-0.2595295668583777
108.40000000000116,29.627319208072358,-2.009101528864231,-0.25875984028326604
109.50000000000117,29.73339440538585,-2.00224013381451,-0.2600799464997774
110.60000000000119,29.83862427168161,-1.9940514013529977,-0.26009819075071405
111.70000000000121,29.94625268902919,-1.987225663866253,-0.26007060849222885
112.80000000000122,30.05211497774232,-1.9809163536439698,-0.26007981800003765
113.90000000000123,30.158717397621476,-1.974358745835964,-0.2603131535615093
115.00000000000125,30.26487718879643,-1.9688190416104443,-0.2600623215212461
116.10000000000127,30.37094642236956,-1.962695425295272,-0.26139012393176486
117.20000000000128,30.477714538594412,-1.9592162031409703,-0.2600468076609155
118.30000000000129,30.581527241497085,-1.9546393088690217,-0.26007995378860693
119.40000000000131,30.688408186328136,-1.9499752272055126,-0.26007564507692926
120.50000000000134,30.79593173160947,-1.9460331878116668,-0.2610701354737315
121.60000000000134,30.901865275099727,-1.9427664175345494,-0.2597519728508897
122.70000000000135,31.008011272419846,-1.9390438045123284,-0.26107005906713576
123.80000000000138,31.11454350957281,-1.9352183509732008,-0.26107014262914063
124.9000000000014,31.219865127275455,-1.9321292200133986,-0.2622286565265113
126.0000000000014,31.326804241662266,-1.9294119365091396,-0.26368936130803755
127.10000000000142,31.432413602619246,-1.9269429083829672,-0.2623799609936044
128.20000000000144,31.540029632615095,-1.9240331227114098,-0.2623799772567956
129.30000000000146,31.64417421588997,-1.9204844005835744,-0.2611789036738039
130.40000000000146,31.75145584234167,-1.9166934931809507,-0.2623901551521799
131.50000000000148,31.856370014546034,-1.9148908408267409,-0.26107031818682813
132.6000000000015,31.960362666848273,-1.9136291326825636,-0.2623898669397122
133.70000000000152,32.06912335889193,-1.9104789249332936,-0.26140000489082693
134.80000000000155,32.17448768801061,-1.9088151726842137,-0.2607308573253633
135.90000000000154,32.280102528134925,-1.906023603926584,-0.2612450787902034
137.00000000000156,32.38676121297231,-1.9042165626451018,-0.2613999180870117
138.1000000000016,32.493002875557366,-1.901609046952142,-0.26270956597639916
139.20000000000158,32.59551605065459,-1.9001181005997367,-0.2613898252463378
140.3000000000016,32.70359049901597,-1.8979100024483126,-0.2613898309999869
141.40000000000163,32.809617034788275,-1.8962383146778456,-0.2613370889654436
142.50000000000165,32.91498521962498,-1.8919378375193068,-0.26270983092301226
143.60000000000167,33.02099721523457,-1.892365088134083,-0.264028499956809
144.70000000000167,33.12507365212015,-1.8902946386582875,-0.26402983100303556
145.8000000000017,33.23081334298528,-1.8881919093057322,-0.26272976733005926
146.9000000000017,33.33700113378862,-1.8864549565633515,-0.2627199620011167
148.0000000000017,33.44172476819443,-1.8840609062504994,-0.26372634924759586
149.10000000000173,33.54713713965267,-1.882537493777569,-0.26403996196253576
150.20000000000175,33.653013300563295,-1.8807823418281642,-0.2633797489526457
151.30000000000177,33.7572976368941,-1.8787379049576307,-0.26435999497603646
152.4000000000018,33.86268675533126,-1.877310100326622,-0.2643599950215729
153.5000000000018,33.96835026715334,-1.8748609069858093,-0.2657154635423207
154.6000000000018,34.07424333267144,-1.87270859508632,-0.26403016532021084
155.70000000000184,34.178964347665236,-1.87206895772708,-0.2646726441005378
156.80000000000183,34.2839141417648,-1.8707964538831925,-0.2663103939164815
157.90000000000185,34.38880875053851,-1.8700364963870681,-0.264922548846362
159.00000000000188,34.49612066288762,-1.8692671649458517,-0.26498548205168815
160.1000000000019,34.60025587640797,-1.8671459587993493,-0.26633006099818024
161.20000000000192,34.70592042631102,-1.8661735294396073,-0.26633006100013423
162.30000000000192,34.80989324479955,-1.8660060830732663,-0.26495566357392697
163.40000000000194,34.91512888616733,-1.8647148744209487,-0.2650099739999665
164.50000000000196,35.02027034232841,-1.8623823136691247,-0.2650099740002556
165.60000000000196,35.12508503996134,-1.8614604612187424,-0.2660362157410803
166.70000000000198,35.23009755636241,-1.8610285072247228,-0.2664667635492939
167.800000000002,35.33570998911646,-1.8592751963627523,-0.2679613658986262
168.90000000000202,35.44097169579081,-1.8575658351486517,-0.26731982100302565
170.00000000000205,35.54671354755772,-1.8574484557234403,-0.26731980757767637
171.10000000000204,35.65024944753872,-1.8550027772740263,-0.2686397485366072
172.20000000000206,35.75609926762478,-1.8542814536183339,-0.2696298209993908
173.3000000000021,35.85998599929232,-1.85341189690471,-0.2696298210000001
174.40000000000208,35.966665500961085,-1.8509314397641377,-0.26962982100000055
175.5000000000021,36.0711386596679,-1.8513860498898753,-0.2696298212020305
176.60000000000213,36.17568552561333,-1.8497750560489912,-0.27093772306879815
177.70000000000215,36.28098515480169,-1.8468840233959098,-0.2712699410044448
178.80000000000217,36.38499693211686,-1.8468923416444178,-0.2712699409999999
179.90000000000217,36.48774658135745,-1.8463824826612516,-0.2712699410977386
181.0000000000022,36.595446254387234,-1.8443717145471727,-0.2725899414058759
182.1000000000022,36.700199614764834,-1.8433178940331574,-0.2725899418503501
183.2000000000022,36.80449303736277,-1.8411326476201737,-0.27489984050343175
184.30000000000223,36.909928804753164,-1.8411120438057218,-0.2749006021259883
185.40000000000225,37.01501226736025,-1.8389298319042262,-0.2755600793575925
186.50000000000227,37.11984705593064,-1.8380053177337372,-0.2755597073521936
187.6000000000023,37.22538672596165,-1.836017853000388,-0.2768788102602113
188.7000000000023,37.32834406574195,-1.8367944085986307,-0.2782000819736723
189.8000000000023,37.434135627843254,-1.834527208484527,-0.2782000819999899
190.90000000000234,37.53663553658683,-1.833028093696729,-0.27820602678417483
192.00000000000233,37.64445557148345,-1.8316685245424673,-0.27952002627784633
193.10000000000235,37.74802304114725,-1.8300766339940109,-0.2808299722742489
194.20000000000238,37.85265325299491,-1.8290909391759187,-0.2818199182586203
195.3000000000024,37.95805407963192,-1.8284517312129052,-0.2818199179783676
196.40000000000242,38.06057426133457,-1.8263887974706297,-0.28346377374080456
197.50000000000242,38.1673906441327,-1.8257737500124696,-0.2847536457254165
198.60000000000244,38.27211820751791,-1.8246078248324915,-0.2860899940012711
199.70000000000246,38.377213018523726,-1.8245934821985155,-0.28744164616909895
200.80000000000246,38.48200512830583,-1.8225794167513991,-0.28807031751163814
201.90000000000248,38.58591693398523,-1.8222092914912973,-0.28807004461664887
203.0000000000025,38.689850701854304,-1.821555070236704,-0.29002653492757835
204.10000000000252,38.79668643406108,-1.8200889597138858,-0.29137300042227166
205.20000000000255,38.90136147303911,-1.8189614536590082,-0.29321594769885806
206.30000000000254,39.00551263201483,-1.818727372298516,-0.29530043173565224
207.40000000000256,39.11020342443666,-1.8180904466943022,-0.29679113383338285
208.5000000000026,39.21371607663003,-1.8166113061826226,-0.29927245149410053
209.60000000000258,39.31797474151165,-1.8175323105954977,-0.3001573250365235
210.7000000000026,39.423882356223004,-1.816701713633236,-0.3005900286540135
211.80000000000263,39.52790043345848,-1.815511873747013,-0.3018637548525507
212.90000000000265,39.631454343934664,-1.8158341706424452,-0.3046507123856941
214.00000000000267,39.7373430702705,-1.8150857194751346,-0.308596884508483
215.10000000000267,39.841466381397446,-1.8155790928360531,-0.3087451376180286
216.2000000000027,39.94605676263821,-1.8144254295353461,-0.31124010090277254
217.3000000000027,40.050198181826744,-1.8132997792622199,-0.3125635789845487
218.4000000000027,40.15501258144315,-1.813028493682618,-0.3152762796682138
219.50000000000273,40.26016774935439,-1.8133191577066416,-0.3178350131982044
220.60000000000275,40.36386959751083,-1.8143915977513814,-0.32110614257559167
221.70000000000277,40.46752582690805,-1.8140614282044027,-0.32374560828959664
222.8000000000028,40.57203518215296,-1.8147819598495483,-0.32638245724540216
223.9000000000028,40.67789114539436,-1.8141035946513648,-0.3290367189102672
225.0000000000028,40.782336703999306,-1.81391000234995,-0.33242338528511395
226.10000000000284,40.886676060386115,-1.813176100701658,-0.3350481299678547
227.20000000000283,40.991612115273796,-1.8144939038923522,-0.3386990678052575
228.30000000000285,41.09571935789479,-1.8142987624664513,-0.34216091065569465
229.40000000000288,41.20030853700818,-1.8117362358720264,-0.3450825533391191
230.5000000000029,41.30533013200638,-1.8136002213940146,-0.34801329444664697
231.60000000000292,41.409034493642444,-1.812192177934188,-0.35274916937005596
232.70000000000292,41.51469038438334,-1.8118432015745938,-0.35532134027340545
233.80000000000294,41.61970963620541,-1.8102676459201512,-0.36097159433251536
234.90000000000296,41.723937037419674,-1.8113639582795698,-0.36519300841880975
236.00000000000296,41.82929412046895,-1.811137598963382,-0.368998715426911
237.10000000000298,41.93316951200803,-1.8086342621057077,-0.37295971520185
238.200000000003,42.03777186925264,-1.8085421727730149,-0.37616833628468527
239.30000000000302,42.14253594336561,-1.8063482333979926,-0.37987582414513943
240.40000000000305,42.24613840765447,-1.8058548125512586,-0.3841604539200536
241.50000000000304,42.35212061747516,-1.803734697069037,-0.3885335544093844
242.60000000000306,42.45619949766815,-1.803599762325903,-0.3931549169728128
243.7000000000031,42.560386861041096,-1.8014998826161401,-0.3973035022965399
244.80000000000308,42.66532701496426,-1.7995305270172355,-0.4024744217342997
245.9000000000031,42.77089716306656,-1.7993589351563257,-0.4075347410120491
247.00000000000313,42.873733964957985,-1.7973485605749577,-0.4125629039108447
248.10000000000315,42.979070475448424,-1.796822680806315,-0.4197914656389323
249.20000000000317,43.0842591567437,-1.794795760343593,-0.424483396138978
250.30000000000317,43.188196963033946,-1.792552164908023,-0.42871505262840115
251.4000000000032,43.29270103438222,-1.791577352153052,-0.43497671918759817
252.5000000000032,43.397723207824896,-1.7905951060236578,-0.44045398232016897
253.6000000000032,43.50092403206809,-1.7908762413815646,-0.44544082296984966
254.70000000000323,43.606946055204276,-1.7885394220684907,-0.4516127603645739
255.80000000000325,43.711006313766674,-1.7861276391507137,-0.4581146751180749
256.9000000000033,43.81621373953297,-1.7857315112273386,-0.46302289925933016
258.0000000000033,43.91798548155253,-1.7859855816242556,-0.4700170452839041
259.1000000000033,44.0251817007211,-1.7837137188492003,-0.4753297135448551
260.20000000000334,44.12996258345609,-1.7819242009887815,-0.48275611097577764
261.30000000000337,44.23358597950301,-1.7808973882738917,-0.49259215315075267
262.40000000000333,44.338251199957504,-1.77983899178545,-0.4993252614384387
263.50000000000335,44.44326409641616,-1.7790388950496667,-0.5073007000853318
264.6000000000034,44.547566769101216,-1.7773585127663016,-0.5149098077048584
265.7000000000034,44.65277133976793,-1.7763235972270959,-0.5227964933629319
266.8000000000034,44.756062611198246,-1.775186004138528,-0.5313626038373322
267.9000000000034,44.86242882720905,-1.7733698105109839,-0.5393117791421274
269.0000000000034,44.9664145750229,-1.7728622070870068,-0.5486176697532152
270.10000000000343,45.07088120041863,-1.7719424482198383,-0.5581934176817196
271.20000000000346,45.17683134817894,-1.769824275783206,-0.5662086577664684
272.3000000000035,45.281577112479965,-1.7696060204160002,-0.5761585904431739
273.4000000000035,45.38715362497982,-1.7666236017822567,-0.5863914681067728
274.5000000000035,45.49198307300472,-1.7660804217180488,-0.5958662802262951
275.60000000000355,45.596345637594354,-1.7653490171295834,-0.6066593714528592
276.70000000000357,45.702791962384865,-1.7655657186623062,-0.6174275371558529
277.8000000000036,45.80604463777647,-1.7627712226738663,-0.6305220304091232
278.9000000000036,45.912594192216474,-1.7617842899071448,-0.641821045527502
280.0000000000036,46.01751985350438,-1.7604891579497977,-0.6544418835134684
281.1000000000036,46.122342075511455,-1.7594161222578244,-0.6664083577027666
282.2000000000036,46.22851709256143,-1.7602574096734205,-0.6801040808120034
283.30000000000365,46.33377702873824,-1.7587041237227117,-0.6924400743547698
284.4000000000037,46.438567809389774,-1.7570370357629685,-0.7060172961714635
285.5000000000037,46.5447412545118,-1.75630471565103,-0.7207500389305146
286.60000000000366,46.649594127092364,-1.7556008381397876,-0.7345549875000934
287.7000000000037,46.754775914097465,-1.7540701328249046,-0.7509331697988428
288.8000000000037,46.86080256523341,-1.7545532822208794,-0.7672401888313636
289.90000000000373,46.96583098663049,-1.7525000207714272,-0.7811101323928429
291.00000000000375,47.07240158812936,-1.7537893335579382,-0.7984465433858792
292.1000000000038,47.17746000285724,-1.7528063762895467,-0.8145839672113646
293.2000000000038,47.282536507937,-1.7543567994676768,-0.8325980352415745
294.3000000000038,47.38755432877616,-1.7518861979678306,-0.8511869641323786
295.40000000000384,47.49349261034334,-1.751908691944498,-0.8697000466085076
296.5000000000038,47.5993776569253,-1.7540139844732265,-0.8874061710195331
297.60000000000383,47.70428511772638,-1.7529971458513873,-0.9054166613143071
298.70000000000385,47.809956884759984,-1.754492518795421,-0.9268511542196345
299.8000000000039,47.91507254938793,-1.754266719418346,-0.9466866230024733
300.9000000000039,48.020983595796196,-1.7544765215067715,-0.96729938336544
302.0000000000039,48.12592409344388,-1.755807991716602,-0.9890529181058878
303.10000000000394,48.23204027887846,-1.7543104586008096,-1.0096151413026604
304.2000000000039,48.337693137103464,-1.7561275252851314,-1.0317927052915619
305.30000000000393,48.44297958859071,-1.7581522648614538,-1.056044780491562
306.40000000000396,48.54811900590847,-1.7603366872591135,-1.0778576609985349
307.500000000004,48.65481844337541,-1.759296631214376,-1.102014247150938
308.600000000004,48.75723403719317,-1.757691082075539,-1.1257017025105744
309.700000000004,48.865205090533244,-1.7582958441287122,-1.1511637462776525
310.80000000000405,48.97024167132464,-1.7597826044285534,-1.1738036346879617
311.90000000000407,49.07508983219874,-1.7594100644761672,-1.198921422607182
313.0000000000041,49.182874403214896,-1.7593710998159608,-1.224825962127578
314.10000000000406,49.288592435219066,-1.7590118930828316,-1.251672599668849
315.2000000000041,49.39525627738776,-1.7576206885292334,-1.2781357100843533
316.3000000000041,49.50039829637771,-1.755617611372997,-1.3054432004559087
317.4000000000041,49.605229603868594,-1.7558892645090536,-1.331842520757562
318.50000000000415,49.71195315100933,-1.7526549570926249,-1.3605077898899038
319.6000000000042,49.81764168040239,-1.751971249699927,-1.3886942451939892
320.7000000000042,49.92285069634495,-1.7483491965129765,-1.4171222491761335
321.80000000000416,50.02905376472202,-1.7442885914202066,-1.445105512668329
322.9000000000042,50.13435182964804,-1.7434922756347402,-1.4746711408762723
324.0000000000042,50.24030260544953,-1.7391512035851793,-1.5041145066275523
325.10000000000423,50.34767519424336,-1.7366187410468312,-1.5297571644386
326.20000000000425,50.45289701701007,-1.7330439278265375,-1.5618890491131996
327.3000000000043,50.55802190930893,-1.729341275812677,-1.5931519710467947
328.4000000000043,50.66435541074368,-1.7254127561279595,-1.6222956981895336
329.5000000000043,50.76976462782765,-1.7213087065033483,-1.652046810542922
330.60000000000434,50.87651714668273,-1.7182424981916329,-1.6801354219619262
331.7000000000043,50.9808395742937,-1.7138976804346926,-1.709406683177197
332.80000000000433,51.08620796017692,-1.7098971416578792,-1.738861118185
333.90000000000435,51.19258272362137,-1.7041678657435875,-1.7700640587201009
335.0000000000044,51.29907174567971,-1.7021260005731744,-1.7984442064105308
336.1000000000044,51.40407650677752,-1.6967128406050371,-1.8279713388181675
337.2000000000044,51.50996441455303,-1.69349663038544,-1.8565761784115744
338.30000000000445,51.61568307123669,-1.6874794481838848,-1.8862116404131979
339.4000000000044,51.7225672327717,-1.6841410457832564,-1.9137076032092049
340.50000000000443,51.82774454280815,-1.6803936316804442,-1.9455350211706184
341.60000000000446,51.93372751033374,-1.6757445398392066,-1.9727901199991371
342.7000000000045,52.039866276908405,-1.669215879197015,-2.001420681442708
343.8000000000045,52.14530673597781,-1.66384167377805,-2.0303017069340825
344.9000000000045,52.25132525405634,-1.6611585676665255,-2.056487391238573
346.00000000000455,52.35802964311629,-1.656724079816075,-2.084271698921569
347.10000000000457,52.462416087458905,-1.6512663253717184,-2.11020695668327
348.2000000000046,52.569605452816084,-1.6461086017829627,-2.1385241240182804
349.30000000000456,52.67616656583415,-1.637912247778818,-2.165182212829971
350.4000000000046,52.78237559651044,-1.6316655308946915,-2.191057627174543
351.5000000000046,52.889132373291744,-1.6246906268543524,-2.216480671946925
352.6000000000046,52.995597692387946,-1.617636974030575,-2.2414983714898424
353.70000000000465,53.10013974641855,-1.6090867431089124,-2.2655874506916778
354.8000000000047,53.207666154097375,-1.5996879451874704,-2.2898721902412755
355.9000000000047,53.31333198772123,-1.592734081806768,-2.3117090657820603
357.00000000000466,53.42019071598798,-1.5849871220857688,-2.334463830604453
358.1000000000047,53.52671578596709,-1.5767442630800241,-2.3557738714150345
359.2000000000047,53.63277518655822,-1.5670203041342223,-2.3752962626934417
360.30000000000473,53.73955152549674,-1.55673728253675,-2.3947801959446315
361.40000000000475,53.84433887336911,-1.5478199923980267,-2.413103936074893
362.5000000000048,53.951947134633585,-1.5386207269060803,-2.430481590205651
363.6000000000048,54.05739717727453,-1.5307803359602958,-2.4475793222199114
364.7000000000048,54.16441131468713,-1.5239132454488782,-2.461953135177607
365.80000000000484,54.26997954677938,-1.5134413177357016,-2.4785131617394933
366.9000000000048,54.376318618203186,-1.5069326229563962,-2.4906144722887005
368.00000000000483,54.48246782266504,-1.501523333966997,-2.5013141158068395
369.10000000000485,54.58833313420162,-1.4955591090423621,-2.5142190584439392
370.2000000000049,54.69433358772661,-1.492736750758152,-2.5262248077955283
371.3000000000049,54.80073281747912,-1.487687932354634,-2.5358342333301693
372.4000000000049,54.90783822642392,-1.4850891257091774,-2.5441507121811417
373.50000000000495,55.01401879765333,-1.4832674350515964,-2.553936001009888
374.6000000000049,55.11963565506543,-1.483170045742175,-2.5603377257085276
375.70000000000493,55.227568472086716,-1.4809919177339506,-2.568015181324124
376.80000000000496,55.3328837977716,-1.482442187955111,-2.5736557666484936
377.900000000005,55.439570905077396,-1.4811130678423738,-2.5802393064557956
379.000000000005,55.54651195085986,-1.4808042488650877,-2.5868293285868402
380.100000000005,55.652118107782485,-1.480310434415748,-2.5938551951594007
381.20000000000505,55.75841162968886,-1.4794923590248779,-2.595803889044367
382.30000000000507,55.8649885453379,-1.4774299816103413,-2.6038834575803675
383.4000000000051,55.97097049139708,-1.475801989611322,-2.6087876023073013
384.50000000000506,56.076755986220626,-1.4718179325654488,-2.614431231386802
385.6000000000051,56.18486148555705,-1.467886529301079,-2.619428795486147
386.7000000000051,56.29095997360646,-1.465014064937354,-2.6241746989313506
387.8000000000051,56.397230003628906,-1.4619263252963235,-2.6275069987565574
388.90000000000515,56.505330328896,-1.459032591414677,-2.6320618022174322
390.0000000000052,56.61175151873144,-1.4550686990850439,-2.637109614988632
391.1000000000052,56.71753394309051,-1.453101026751327,-2.640897579017759
392.20000000000516,56.82446738510623,-1.4504231018565157,-2.644662114740803
393.3000000000052,56.93280257370377,-1.4481555469211025,-2.648224377626069
394.4000000000052,57.038870480486835,-1.4457075577456253,-2.6521533626060365
395.50000000000523,57.145550767327364,-1.4415232217894562,-2.6563243838436623
396.60000000000525,57.25388722235297,-1.439773297290886,-2.6600601421595838
397.7000000000053,57.361511088787594,-1.4379566193673416,-2.665222483672892
398.8000000000053,57.46810532346785,-1.4364796605205439,-2.669815860629439
399.9000000000053,57.5762762339722,-1.4352493725443418,-2.6733523563539077
401.00000000000534,57.68403741422291,-1.431560212973586,-2.6775058760188193
402.1000000000053,57.79037348684436,-1.4327214297399544,-2.6803088057817686
403.20000000000533,57.89748791833517,-1.4308496555926828,-2.685310727539525
404.30000000000535,58.005609980216356,-1.427962735121057,-2.689480673887429
405.4000000000054,58.112291852115845,-1.4291810048459892,-2.693754584407158
406.5000000000054,58.22055845922075,-1.4272232178848314,-2.698812778576454
407.6000000000054,58.3284358391979,-1.426364706393186,-2.7026197369680807
408.70000000000545,58.43573349838913,-1.427555379545795,-2.705459067603651
409.8000000000054,58.54405428114969,-1.4261271958701383,-2.708043690153904
410.90000000000543,58.65167295475269,-1.4277901253750487,-2.711914377192474
412.00000000000546,58.75591067747748,-1.427560068172657,-2.7165302425047604
413.1000000000055,58.86682698349814,-1.4301044122966424,-2.72316966184568
414.2000000000055,58.973863572902395,-1.433100054265254,-2.7244952433032648
415.3000000000055,59.08233141251337,-1.4371606798481584,-2.7275624700270815
416.40000000000555,59.189832788010946,-1.4431853801447077,-2.731501751249409
417.50000000000557,59.2969365304739,-1.452547928926936,-2.7344102185531645
418.6000000000056,59.40490658022259,-1.464328184303959,-2.739306276572377
419.70000000000556,59.51185961992451,-1.475238989249022,-2.7430969507505294
420.8000000000056,59.62077672057531,-1.4881664766290195,-2.7479020866118757
421.9000000000056,59.728736850039816,-1.4976112641353094,-2.7506664761756037
423.0000000000056,59.83595606489863,-1.5017492234032217,-2.7522681688610247
424.10000000000565,59.944249154250116,-1.5072580277806495,-2.7564812389519853
425.2000000000057,60.05201147271763,-1.5143910197250063,-2.7615570087423813
426.3000000000057,60.16050126052895,-1.521746553715146,-2.764240321000271
427.40000000000566,60.26840599881903,-1.526530052782093,-2.7669498437034825
428.5000000000057,60.376154522069655,-1.5370218572137908,-2.770178350705244
429.6000000000057,60.484682366689285,-1.5449100828226354,-2.7722720716321954
430.70000000000573,60.59310480406765,-1.5559019298315977,-2.7766494022671075
431.80000000000575,60.70107130454389,-1.56267575206491,-2.7792555701216752
432.9000000000058,60.81019211849187,-1.5685443465686257,-2.7820472991483074
434.0000000000058,60.91708192594447,-1.5724155217500444,-2.7852722850638987
435.1000000000058,61.02606892511368,-1.5759090749796256,-2.7875097371863484
436.20000000000584,61.13398004006014,-1.580358669963327,-2.7915100671532542
437.3000000000058,61.24224410762999,-1.5844294299496295,-2.794866213960498
438.40000000000583,61.349987895483366,-1.5896639019462133,-2.799393062804463
439.50000000000585,61.45944289604397,-1.5959468919509838,-2.801999808740889
440.6000000000059,61.56710276921355,-1.5988871603895265,-2.801994195576307
441.7000000000059,61.676272555941935,-1.6035949102950788,-2.8047400784583365
442.8000000000059,61.78430407960009,-1.6068327151058914,-2.8073844381897874
443.90000000000595,61.893074680567004,-1.6096325790459716,-2.8114331605228315
445.0000000000059,61.9995860209537,-1.6123124207612174,-2.8141826055057297
446.10000000000593,62.11057573816243,-1.6141259565752184,-2.8168167562686595
447.20000000000596,62.218577456016725,-1.6153579716285162,-2.8194471893912945
448.300000000006,62.32683570642527,-1.618222042369262,-2.822085995749683
449.400000000006,62.43492811915228,-1.6177437125224163,-2.8245687677955105
450.500000000006,62.544011693351706,-1.617945847563102,-2.8274000149135494
451.60000000000605,62.651958109456736,-1.6166465552137386,-2.8299939873820916
452.70000000000607,62.76148561795294,-1.6181464066933593,-2.831307747554896
453.8000000000061,62.869707005705884,-1.6193684786303026,-2.8339555198798365
454.90000000000606,62.97893856047621,-1.620466747480337,-2.8356002183749283
456.0000000000061,63.08533089261511,-1.6221311311386644,-2.8369194608597947
457.1000000000061,63.19568963914714,-1.6205415462883321,-2.839540146321049
458.2000000000061,63.30420881049243,-1.6219067030565821,-2.842087593019837
459.30000000000615,63.41280074319925,-1.621527328245309,-2.8435055465108343
460.4000000000062,63.5211736695741,-1.6194961117512836,-2.846137808908515
461.5000000000062,63.63067234759649,-1.6190628013087105,-2.848500934213744
462.60000000000616,63.73857950861336,-1.6194561641389964,-2.85119249993157
463.7000000000062,63.84667286319024,-1.6168455134789417,-2.852820321168083
464.8000000000062,63.95548730988227,-1.6164594247999668,-2.8541518634759813
465.90000000000623,64.06495488144235,-1.6164866270792144,-2.8567896856842925
467.00000000000625,64.1734468249194,-1.6142596724359273,-2.8585572215355084
468.1000000000063,64.28232201378059,-1.6129002485979789,-2.859530229574266
469.2000000000063,64.39078147941646,-1.6129129490780751,-2.862172409568317
470.3000000000063,64.49897440011088,-1.609672314691137,-2.8654600936447645
471.40000000000634,64.60822601685928,-1.6096841485153015,-2.8676929902912036
472.5000000000063,64.71691801221738,-1.6087388905498023,-2.868416786185927
473.60000000000633,64.82649312045861,-1.6076472385231007,-2.8697807145902643
474.70000000000636,64.93538076129148,-1.6052583456407985,-2.872000579941911
475.8000000000064,65.04459068051318,-1.6055370417431243,-2.873360647518939
476.9000000000064,65.15396652703126,-1.6021138617973767,-2.8760015714061566
478.0000000000064,65.2630463892261,-1.6020541341399783,-2.877305640703783
479.10000000000645,65.3725978200611,-1.5990445339262236,-2.879950463606196
480.2000000000064,65.48102281378415,-1.5967490028556026,-2.882454715472484
481.30000000000643,65.59037176554322,-1.5938110070586013,-2.8828488686393174
482.40000000000646,65.69968145801737,-1.5927457231983841,-2.88630364423732
483.5000000000065,65.80583000000078,-1.5912999999999988,-2.8878440868623594
484.6000000000065,65.91753364769417,-1.5891484437473484,-2.887798782016043
485.7000000000065,66.02556096771052,-1.5864441548816035,-2.889481739403471
486.80000000000655,66.1362069335668,-1.5841925609070728,-2.8917888640694596
487.90000000000657,66.24499951351206,-1.5796788667529622,-2.893125432388824
489.0000000000066,66.35306505448834,-1.5757808785909357,-2.893129874974747
490.10000000000656,66.46408528402208,-1.5697449651818887,-2.8959554752621255
491.2000000000066,66.5734092831204,-1.560032456233018,-2.898392854291765
492.3000000000066,66.68201674355296,-1.5502013388024445,-2.899018076030724
493.4000000000066,66.7905942991105,-1.5416877653168921,-2.9007047600602394
494.50000000000665,66.90050922699514,-1.5323633445072493,-2.9023373751037096
495.6000000000067,67.00910074657217,-1.5269629816238408,-2.904979717808377
496.7000000000067,67.1186773184171,-1.5227314827625344,-2.9062503943263622
497.80000000000666,67.22816560816744,-1.5211239455442938,-2.908226051565076
498.9000000000067,67.3379313362402,-1.5204930443380673,-2.9089408146903755
500.0000000000067,67.4464214648685,-1.5186230079144984,-2.9102394123474014
501.10000000000673,67.5555609015581,-1.5176356131308135,-2.9115698854301817
502.20000000000675,67.66572465521591,-1.5151822769393941,-2.9142088279922267
503.3000000000068,67.7751526523298,-1.5123790247080413,-2.913222503366244
504.4000000000068,67.88358376848818,-1.512446584131756,-2.9142001892629805
505.5000000000068,67.99338492951615,-1.512305546546236,-2.9168858886748463
506.60000000000684,68.10350379475366,-1.5132956753809703,-2.9181601202601337
507.7000000000068,68.21190791673114,-1.51125337407264,-2.919476510994749
508.80000000000683,68.32230596569318,-1.5110760748601617,-2.9221258188784973
509.90000000000686,68.43194096838576,-1.5104838981042759,-2.922079361005524
511.0000000000069,68.54185496084857,-1.511093972139545,-2.924751625480752
512.100000000007,68.65163009610252,-1.5082144179714632,-2.9244091640622627
513.2000000000069,68.75983907270482,-1.5067879771999928,-2.9257265084772452
514.300000000007,68.87073717505768,-1.5065710650900501,-2.928324583331362
515.4000000000069,68.98032416803838,-1.50782808847308,-2.9296801823086476
516.5000000000069,69.0891159140284,-1.506549123801293,-2.9300234978556245
517.600000000007,69.19888980978948,-1.5064404610365065,-2.933968673992747
518.700000000007,69.30819176624937,-1.5068105335029414,-2.933204609993523
519.800000000007,69.41805623509951,-1.5072541282280512,-2.9352810700742835
520.900000000007,69.52714942463618,-1.5068372688995622,-2.9365997857810853
522.000000000007,69.6367726755319,-1.5099352945244642,-2.9365901327188233
523.1000000000071,69.74659292798842,-1.5093161411336236,-2.9365894144515634
524.2000000000071,69.85528103509458,-1.5090317541343294,-2.939270834305021
525.300000000007,69.96655069882509,-1.511301066104852,-2.9405500054747797
526.4000000000071,70.07673994487402,-1.5114036584995618,-2.9418599249805295
527.500000000007,70.18735063661207,-1.5109153606574994,-2.9421854328496737
528.6000000000072,70.2969448028652,-1.5115018355314642,-2.943517861923413
529.7000000000071,70.40700717168887,-1.5142192472267588,-2.9448401324006412
530.8000000000072,70.51762118106329,-1.5155073821223437,-2.947463999687736
531.9000000000071,70.62647706312633,-1.5164186935556787,-2.947470158633152
533.0000000000072,70.7370454986085,-1.5179727283982867,-2.948789835793174
534.1000000000072,70.84733305782004,-1.5197500995762905,-2.950097558212822
535.2000000000072,70.95702245287093,-1.5226630563600339,-2.952731827350613
536.3000000000072,71.06751949160692,-1.523689589856755,-2.9527399012130244
537.4000000000073,71.17664828302942,-1.5241847841589367,-2.9540598174170745
538.5000000000073,71.2858300000008,-1.5262600000000555,-2.9556999560000694
539.6000000000073,71.39657467395148,-1.530628058707357,-2.956689920240687
540.7000000000073,71.50622837563773,-1.529998647580567,-2.9570200132089943
541.8000000000073,71.61734534511001,-1.533972206762113,-2.9570323100677194
542.9000000000074,71.72687503820512,-1.5370650210722792,-2.959661632661842
544.0000000000074,71.83588700611197,-1.5389885035705462,-2.9603064550298535
545.1000000000074,71.94661719224293,-1.5402459162119932,-2.9619628366005637
546.2000000000073,72.05752572801347,-1.543938908221939,-2.962257225974037
547.3000000000073,72.16733227889104,-1.546227992852467,-2.9622893524677867
548.4000000000074,72.27752355513744,-1.548639171551807,-2.964919600003118
549.5000000000074,72.38625578798612,-1.5515834225294656,-2.964920182999575
550.6000000000074,72.49834448890323,-1.5545199939469083,-2.9662429566536512
551.7000000000074,72.60888732960657,-1.556091849957943,-2.9662393934004543
552.8000000000075,72.71927428087773,-1.5585515860357035,-2.9682199338747752
553.9000000000075,72.82976042388826,-1.5608440886257482,-2.969507164527913
555.0000000000075,72.94005644402708,-1.5635915833728837,-2.970849975819289
556.1000000000075,73.05055078780717,-1.5659186641120066,-2.9721700949382885
557.2000000000075,73.16119518930759,-1.569705647294836,-2.9734662480456215
558.3000000000076,73.27087439237137,-1.5731722180888963,-2.972959325995233
559.4000000000076,73.38291262472966,-1.5745739454024221,-2.973481425279979
560.5000000000076,73.49377488747476,-1.5774516047249225,-2.974769542571422
561.6000000000076,73.60512631716807,-1.5806293968935403,-2.9754595469677385
562.7000000000077,73.71566529535386,-1.5842217329152315,-2.9780885595638606
563.8000000000077,73.82592779598608,-1.5865918291773466,-2.9794101800226525
564.9000000000076,73.93454197990762,-1.589093965329267,-2.97945408206553
566.0000000000076,74.04752190937101,-1.5920351955297143,-2.981191508244801
567.1000000000076,74.15731848063976,-1.5932354079025752,-2.9808857621250175
568.2000000000077,74.26809880590359,-1.5989566317983055,-2.981377522774524
569.3000000000077,74.3791710131569,-1.600270034462126,-2.9827099170000286
570.4000000000077,74.4897259188802,-1.6017844888289487,-2.984029730058807
571.5000000000077,74.60037249591181,-1.6055622458018255,-2.9853491392167246
572.6000000000078,74.71177286124534,-1.608731658975539,-2.9866765401602864
573.7000000000078,74.82254904873191,-1.6107653216447921,-2.9867038519022104
574.8000000000078,74.93360818543685,-1.6126060550530226,-2.988008481276327
575.9000000000078,75.04315359878012,-1.6151731579802509,-2.9879803573866077
577.0000000000078,75.1557870191208,-1.61561968670822,-2.989290008894126
578.1000000000079,75.26737471510319,-1.6182974422823262,-2.9899705511942396
579.2000000000079,75.37783053818549,-1.6197244606144734,-2.9899500899998825
580.3000000000079,75.48849182157029,-1.6255817804379984,-2.991179429249919
581.4000000000078,75.59850526627653,-1.6250334558632575,-2.9922612686569847
582.5000000000078,75.71111722020417,-1.630046578786516,-2.9940801663715932
583.6000000000079,75.82270406860803,-1.6317159048476824,-2.993693042646157
584.7000000000079,75.93282426078876,-1.6345148425214902,-2.9970208180845797
585.8000000000079,76.0436560507718,-1.6373680701989946,-2.9970531508340947
586.9000000000079,76.15548714266102,-1.641960216602105,-2.997629261534892
588.000000000008,76.26695463337164,-1.6452895437938593,-2.9980684770633266
589.100000000008,76.37721074980651,-1.6503173541129987,-3.000065805455031
590.200000000008,76.48789127782166,-1.6547289504297515,-2.999059884671677
591.300000000008,76.59970351290916,-1.654678311349006,-2.9991455821904522
592.400000000008,76.71047252516267,-1.6580096396665427,-3.001209226232986
593.5000000000081,76.82180959960266,-1.658694001671408,-3.0017001320037897
594.6000000000081,76.9327012547811,-1.662760250409516,-3.0018653834297817
595.7000000000081,77.04338752766624,-1.6651169258915053,-3.0023596819941494
596.8000000000081,77.15433429722526,-1.6679864086091525,-3.0031126687547456
597.9000000000082,77.26384886854456,-1.6691737972374694,-3.00435228160127
599.0000000000082,77.37478686331647,-1.6733063888342117,-3.0069705045419646
600.1000000000081,77.48563642849702,-1.6770465379904564,-3.006310129998734
601.2000000000081,77.59664557547467,-1.6802778012347477,-3.0066774729293124
602.3000000000081,77.70694124006967,-1.6844113233308258,-3.0076298319540653
603.4000000000082,77.81809951188326,-1.6881191310355959,-3.0089427555079404
604.5000000000082,77.92802557379062,-1.6918275793882456,-3.009596020809558
605.6000000000082,78.03917192351742,-1.6945200854612201,-3.009609998000208
606.7000000000082,78.1488934288353,-1.697755584182952,-3.0102837592586065
607.8000000000083,78.26045655708793,-1.6994911752461113,-3.0109200241244416
608.9000000000083,78.37141527113265,-1.704021468208536,-3.012241197146892
610.0000000000083,78.48280450423162,-1.7069847856328986,-3.011052082297475
611.1000000000083,78.59304958140038,-1.7108218483864546,-3.0149825971148654
612.2000000000083,78.70412048119813,-1.7161381269263947,-3.014979953867247
613.3000000000084,78.81443733860117,-1.7202865455759586,-3.0143199289646585
614.4000000000084,78.92632539547566,-1.7251288378707466,-3.0146891357906056
615.5000000000084,79.03674324070288,-1.7303319399117882,-3.015640231015132
616.6000000000083,79.14807722793135,-1.7353164910630772,-3.014980090584112
617.7000000000083,79.25804644232574,-1.7410359340474257,-3.015619824774034
618.8000000000084,79.37004852171782,-1.743759480220928,-3.0169596868051007
619.9000000000084,79.48110430641604,-1.7438764086159564,-3.018270080263958
621.0000000000084,79.59058904355838,-1.7442236399965623,-3.0195896869781143
622.1000000000084,79.7045078103379,-1.7428987060441383,-3.0185033794093834
623.2000000000085,79.81512407314207,-1.7406914035783498,-3.019617826863679
624.3000000000085,79.92621944466664,-1.7402619129171724,-3.020249859732398
625.4000000000085,80.03685508210098,-1.738595007841727,-3.021572737774461
626.5000000000085,80.14821250819345,-1.740372655314923,-3.0215699490282697
627.6000000000085,80.25876961492966,-1.740657428350583,-3.0228745545048556
628.7000000000086,80.36988763546842,-1.7410654093909088,-3.0235397517504685
629.8000000000086,80.48062403087494,-1.7432846781171756,-3.0258399611542948
630.9000000000086,80.59283670827242,-1.7420805357522071,-3.0258499910000274
632.0000000000086,80.70329500091526,-1.7451952248249551,-3.024770693058522
633.1000000000087,80.81404274144137,-1.74789104432455,-3.0258600783264704
634.2000000000087,80.9271838907888,-1.7507204221526782,-3.026232067496141
635.3000000000086,81.03634928373114,-1.7543082470094997,-3.029910244171939
636.4000000000086,81.14922343054118,-1.7551138899363345,-3.0285962300397427
637.5000000000086,81.26047998427556,-1.7586782457171215,-3.027941265198392
638.6000000000087,81.37183917661109,-1.7540551093800683,-3.0292588236123725
639.7000000000087,81.48343227662109,-1.757251871948225,-3.030569855855318
640.8000000000087,81.59505375856249,-1.7583988214225754,-3.030569876999997
641.9000000000087,81.70703646518403,-1.7619309357456194,-3.0305762939958183
643.0000000000088,81.81967483860413,-1.7639112228703224,-3.0322802401637365
644.1000000000088,81.93008755899609,-1.7682527057891,-3.03189005078106
645.2000000000088,82.04238011734641,-1.7727050921222511,-3.034441248397324
646.3000000000088,82.15330889141367,-1.7761192456073662,-3.0345301565015528
647.4000000000088,82.26545370921068,-1.7775077306039504,-3.033210249751892
648.5000000000089,82.37684419128414,-1.7791435714650794,-3.035840126298826
649.6000000000089,82.4888664817952,-1.7829422469193121,-3.034518962080115
650.7000000000089,82.60117874641819,-1.7869757118500817,-3.0358400895566944
651.8000000000088,82.71220790598578,-1.789460325210489,-3.0368300605653293
652.9000000000088,82.82382633913569,-1.7929936655697594,-3.0368310387080286
654.0000000000089,82.93581820862106,-1.7964167203766368,-3.035872633284613
655.1000000000089,83.04721801789552,-1.8000253867060683,-3.0371601901517504
656.2000000000089,83.15896646891936,-1.803396180856282,-3.0397857877504917
657.3000000000089,83.27064602495409,-1.8048951632757353,-3.039789831000008
658.400000000009,83.38181478659827,-1.808498251406999,-3.039789831
659.500000000009,83.49146790322686,-1.8100765527747982,-3.0397902017001748
660.600000000009,83.60583174832331,-1.812610190899081,-3.040130400708275
661.700000000009,83.71759904300889,-1.8126644571933914,-3.041450124396276
662.800000000009,83.82881109939358,-1.8141470368744064,-3.0427598133558638
663.9000000000091,83.94135764726984,-1.8183465659225244,-3.0427598191018026
665.0000000000091,84.0517372704222,-1.822340100013877,-3.0437610077100916
666.1000000000091,84.16467317290402,-1.825135647152309,-3.0458721339854704
667.2000000000091,84.27653397140013,-1.8268193724114936,-3.0448701230145963
668.3000000000092,84.38668926564517,-1.8262674077053047,-3.045070137502557
669.4000000000092,84.49960730474231,-1.8293290442161758,-3.0460605733863924
670.5000000000091,84.61193240601429,-1.828659748462531,-3.047695180727645
671.6000000000091,84.72173587130945,-1.8291330468989921,-3.0452800111614184
672.7000000000091,84.8347007797539,-1.832906339603183,-3.045280005932664
673.8000000000092,84.94707395190603,-1.835039052285396,-3.046269411589165
674.9000000000092,85.05897538177817,-1.8370529703865075,-3.047260094036957
676.0000000000092,85.17074922783021,-1.8405077372188616,-3.048580178167476
677.1000000000092,85.28146515102925,-1.8422858698866118,-3.049898977159299
678.2000000000093,85.39276011786782,-1.8426471872017942,-3.048580288630183
679.3000000000093,85.5058309966901,-1.844300011272976,-3.0498913614978904
680.4000000000093,85.61725497959843,-1.845378466964248,-3.0502195048464307
681.5000000000093,85.72931766236263,-1.8490653590069694,-3.0512098284093843
682.6000000000093,85.84043574705507,-1.8492859223795515,-3.052529872753583
683.7000000000094,85.95240864402165,-1.8497799488079496,-3.052529914999996
684.8000000000094,86.0647801380185,-1.8523063211473014,-3.052567553878761
685.9000000000094,86.17600184612658,-1.8540058083874684,-3.0525123135906407
687.0000000000093,86.28790151769525,-1.8584591944749136,-3.0521944801411545
688.1000000000093,86.39989770156724,-1.8606197886707294,-3.0525297715369133
689.2000000000094,86.51134443491469,-1.864079103114743,-3.051870024009258
690.3000000000094,86.6226683945742,-1.8650881071764527,-3.053189093467928
691.4000000000094,86.73541695700439,-1.8653823589295817,-3.054509800912438
692.5000000000094,86.84737555063957,-1.8699140415388198,-3.055826614176204
693.6000000000095,86.9590670382096,-1.8725545583157854,-3.0545099260200397
694.7000000000095,87.07066301435333,-1.876629616408,-3.054830076533978
695.8000000000095,87.18286129421041,-1.877448347376208,-3.0561498296996197
696.9000000000095,87.2937588490822,-1.8785425538640124,-3.0561506211259815
697.0000000000095,87.30387720756359,-1.8782571903463845,-3.0561462438266993