File: 01_Data/Smoke_Explosion_Plywood/STA/N2/10K_min/Smoke_Explosion_Plywood_STA_N2_10KData_230803_R6.csv
##Temp./Â°C,Time/min,DSC/(mW/mg),Mass loss/mg
27.0,20.591963975728845,-2.3392027883555073,-0.1540488749586224
28.100000000000016,21.01932142811744,-2.301336520041421,-0.15790719758078398
29.20000000000003,21.256556960921138,-2.284047485919857,-0.15724196544083124
30.300000000000047,21.450198440307332,-2.2735536419390736,-0.15952982500824398
31.400000000000063,21.61877497511404,-2.269408485761265,-0.16010669895090635
32.50000000000008,21.774834990461475,-2.2642374246907875,-0.16032517118701684
33.600000000000094,21.91908425556448,-2.2631025387092762,-0.16056534417879487
34.70000000000011,22.06083853265482,-2.2624565497607643,-0.161640231693311
35.800000000000125,22.197064222378543,-2.260731928113128,-0.16280812526158295
36.90000000000014,22.33057443234458,-2.259988035999053,-0.16422307259316637
38.000000000000156,22.460277393589216,-2.2615862605686265,-0.16586631544403518
39.10000000000017,22.587414457537466,-2.2620807036941155,-0.16588133267863858
40.20000000000019,22.713571705358508,-2.2641494795668624,-0.16551464151311546
41.3000000000002,22.839871815337204,-2.266999785479228,-0.16588447340338774
42.40000000000022,22.964242884428323,-2.268635012909048,-0.16875626458312043
43.500000000000234,23.088001989098913,-2.272191386916976,-0.17005050692233858
44.60000000000025,23.20961222818167,-2.2766204327573623,-0.16886226138126892
45.700000000000266,23.331108950656173,-2.2800808671572637,-0.1700499537874749
46.80000000000028,23.45189874790723,-2.284092372552771,-0.17268687489019863
47.9000000000003,23.572250300939476,-2.2896583184690833,-0.17532143543889633
49.00000000000031,23.69312576952486,-2.294052793317758,-0.17702518534842415
50.10000000000033,23.808720806830046,-2.2982648037077262,-0.18071483329411553
51.200000000000344,23.929221925944493,-2.3044564690019143,-0.18060189102235036
52.30000000000036,24.047475923275567,-2.307559532012441,-0.18322794767892203
53.400000000000375,24.159550625052844,-2.3141186659929405,-0.18585068849586373
54.50000000000039,24.277684958129687,-2.318016160057187,-0.18585569372328692
55.600000000000406,24.393061425264964,-2.3210067516606894,-0.1871679324160822
56.70000000000042,24.510836195216587,-2.3245996151031267,-0.1901894794820027
57.80000000000044,24.625531385472055,-2.327174640837692,-0.19306010249834404
58.90000000000045,24.739868570551906,-2.331355819824049,-0.19640266541000617
60.00000000000047,24.854147892904592,-2.3340203353399778,-0.19771086673620752
61.100000000000485,24.962834723853508,-2.334628202317688,-0.20038516895873926
62.2000000000005,25.07757665352674,-2.3356755763036854,-0.20335230345536104
63.300000000000516,25.192361781762145,-2.3372557506503777,-0.20430014591631274
64.40000000000053,25.30481992061312,-2.3362725308743375,-0.20637241819225638
65.50000000000054,25.415816097392266,-2.335242702119071,-0.20957367821363393
66.60000000000056,25.527830199279347,-2.332557951869271,-0.21456289029899
67.70000000000059,25.637864093913105,-2.3297532527530933,-0.21616134624515393
68.8000000000006,25.748300633479598,-2.3265277488627705,-0.21894647650725751
69.9000000000006,25.860095607212426,-2.321287972526335,-0.22022013001274932
71.00000000000063,25.970209978089805,-2.315606632270859,-0.22260540503415216
72.10000000000065,26.07962253203972,-2.310181308473439,-0.22546127358822865
73.20000000000066,26.190407619867074,-2.30300661911828,-0.2293475421057818
74.30000000000067,26.30172481104972,-2.294956269245396,-0.22946473449129634
75.40000000000069,26.410228753676982,-2.28661060000573,-0.2331491029927304
76.50000000000071,26.518760528020426,-2.2765807577761628,-0.23602996518070363
77.60000000000072,26.628694276453484,-2.2670849780444455,-0.23784566760573878
78.70000000000073,26.73706023501404,-2.256221597318643,-0.23993316267225673
79.80000000000075,26.84602774624911,-2.244914830541247,-0.24376976072659717
80.90000000000077,26.955520313426938,-2.23225460973341,-0.24530259459529447
82.00000000000078,27.063338418973395,-2.219189208786535,-0.24653163949443346
83.10000000000079,27.171997881660225,-2.2058561403806847,-0.24920705618686467
84.20000000000081,27.279591889806273,-2.1933658064386807,-0.2515000814032424
85.30000000000084,27.38715579033289,-2.180599024261952,-0.25410588063890405
86.40000000000084,27.494486573884476,-2.166946115480748,-0.2534798401461935
87.50000000000085,27.603710774580136,-2.1523741763547313,-0.2556800310250513
88.60000000000088,27.711108819353527,-2.13866174914328,-0.2566672514459052
89.7000000000009,27.817959036998705,-2.126870195048578,-0.2577374889301338
90.8000000000009,27.92431247438548,-2.1118740769476467,-0.25994215201186055
91.90000000000092,28.028252298120332,-2.0976734465221893,-0.2612793759300964
93.00000000000094,28.137588585371034,-2.0843575167585,-0.262599852685641
94.10000000000096,28.245495749298165,-2.0710011605518046,-0.2639106334798673
95.20000000000097,28.35198893301394,-2.0555718135969316,-0.26609381603242355
96.30000000000098,28.457857809416154,-2.0427917001088884,-0.2678751557059953
97.400000000001,28.56347489017069,-2.0300371177809473,-0.2691795302089224
98.50000000000102,28.670198155799515,-2.019020866134655,-0.27016992595018774
99.60000000000103,28.776665568855986,-2.007450040781873,-0.2701699259999999
100.70000000000104,28.882234104916513,-1.9945058206322341,-0.27016992600000034
101.80000000000106,28.988821722724456,-1.9841302509589849,-0.27016992600817025
102.90000000000109,29.094881102528316,-1.9735575890215256,-0.2708243399354968
104.0000000000011,29.200114531159016,-1.9627099363041192,-0.2728053700899786
105.1000000000011,29.307811561787847,-1.9528213890453088,-0.2739215055395201
106.20000000000113,29.413859077923757,-1.9434483232193898,-0.27391264362814827
107.30000000000115,29.5203531384266,-1.935999560616162,-0.2725798737414342
108.40000000000116,29.625972655672083,-1.927234473565934,-0.27390006392562105
109.50000000000117,29.73321601232177,-1.9196436211914585,-0.27522018077310806
110.60000000000119,29.838110607089416,-1.9127745385129007,-0.2725977975642424
111.70000000000121,29.944977350643164,-1.9061697010676582,-0.27192428678844216
112.80000000000122,30.050804990820538,-1.899463694612588,-0.272589822319274
113.90000000000123,30.15747776137144,-1.894919413861482,-0.2739104382916189
115.00000000000125,30.263433914132495,-1.889168952254936,-0.2742448292913773
116.10000000000127,30.370641273177707,-1.8839324161699296,-0.2729176665510362
117.20000000000128,30.473412153357273,-1.8788992475602107,-0.27521936106963407
118.30000000000129,30.582534160717675,-1.872620537255142,-0.2755529188676351
119.40000000000131,30.68761895032053,-1.8683077032443063,-0.27686995915055723
120.50000000000134,30.792831338379735,-1.8660819484403535,-0.2781895841247879
121.60000000000134,30.902074687219486,-1.8603408028050428,-0.2754868694153796
122.70000000000135,31.006855711071278,-1.8583893178225848,-0.27666621239652267
123.80000000000138,31.114250656924295,-1.8535411800628756,-0.2769573658664246
124.9000000000014,31.21949738359698,-1.850452652284643,-0.2743397634481237
126.0000000000014,31.32540796436581,-1.846600760899326,-0.275658773620314
127.10000000000142,31.432595308966892,-1.8437983087805134,-0.2764673918225875
128.20000000000144,31.537326766372146,-1.8409460645703777,-0.27631932722279684
129.30000000000146,31.643810531081726,-1.8384015944331757,-0.27632058731933684
130.40000000000146,31.749124732064836,-1.8360008037066096,-0.2776399178416571
131.50000000000148,31.854796995182696,-1.834487756843689,-0.2763302367782212
132.6000000000015,31.960558471365296,-1.8294799889680946,-0.2763201140000038
133.70000000000152,32.066586614487385,-1.827893982393746,-0.27632012372138837
134.80000000000155,32.17233340144112,-1.8251063351992431,-0.2763097255650062
135.90000000000154,32.27795256119302,-1.823926007928294,-0.2763098019997132
137.00000000000156,32.381988244589564,-1.8209961850588043,-0.27762986197901585
138.1000000000016,32.488927164525165,-1.819349534703184,-0.2763303237153951
139.20000000000158,32.59502847300014,-1.8171739222935308,-0.2776474926313317
140.3000000000016,32.69873957785551,-1.815480398036832,-0.2783070223701545
141.40000000000163,32.80488411934751,-1.8123445910270437,-0.27830019596548006
142.50000000000165,32.909945583926444,-1.8106302967911323,-0.2798439189642501
143.60000000000167,33.01576280184904,-1.8082816592290722,-0.2791800467575718
144.70000000000167,33.12132180015035,-1.806760748698757,-0.27786019230454917
145.8000000000017,33.227855172516016,-1.8040866777199744,-0.27786014000000003
146.9000000000017,33.33203734810443,-1.8033988033626756,-0.27786082237282184
148.0000000000017,33.438094153740685,-1.8011517158487949,-0.27917014006341834
149.10000000000173,33.54218091976436,-1.7994222559547373,-0.27917013999870566
150.20000000000175,33.64850356021079,-1.7967507609294624,-0.2777872234132919
151.30000000000177,33.75342931198192,-1.795559074731862,-0.2778505136338998
152.4000000000018,33.858556736195354,-1.7924930142803237,-0.2798297838918802
153.5000000000018,33.96352061162011,-1.7902487147679669,-0.2808190043574288
154.6000000000018,34.06911841443763,-1.7900156126969762,-0.27974151269238057
155.70000000000184,34.17276270638895,-1.7874782406681473,-0.27972002132822293
156.80000000000183,34.27650010773566,-1.7862222303389421,-0.28108174029191035
157.90000000000185,34.38253123301868,-1.7856461973853224,-0.28161662899116946
159.00000000000188,34.488921268827426,-1.7834219330745207,-0.2803784178612396
160.1000000000019,34.59322135159649,-1.78100086758592,-0.2807099999996505
161.20000000000192,34.69704393559742,-1.7794372540643408,-0.28068393337007214
162.30000000000192,34.80227149783383,-1.7777218370062549,-0.2816899220033289
163.40000000000194,34.90721558757061,-1.7776513597516534,-0.28168992200571186
164.50000000000196,35.01220170451914,-1.775152635467919,-0.2806583758678389
165.60000000000196,35.11622953001365,-1.7741154950955442,-0.2819359230660061
166.70000000000198,35.22241429509205,-1.772540489160981,-0.2807039936645408
167.800000000002,35.32485221471936,-1.7715190064212345,-0.2813699140549115
168.90000000000202,35.432425199270796,-1.7699132210516813,-0.28137008800247454
170.00000000000205,35.53655725825866,-1.769449737239329,-0.2827047219152261
171.10000000000204,35.64212639871678,-1.7668296445554992,-0.282657150556874
172.20000000000206,35.74638597087443,-1.7652662454252421,-0.2859681169509676
173.3000000000021,35.85147178763698,-1.7634277379199,-0.2859800000798298
174.40000000000208,35.95592711913862,-1.763378762028409,-0.28697018097408566
175.5000000000021,36.06065263147234,-1.7616138127105547,-0.2856497243189735
176.60000000000213,36.16308430192959,-1.76037357299772,-0.28565016160935786
177.70000000000215,36.270027286323774,-1.7587418502087377,-0.28696208141899104
178.80000000000217,36.37312110979849,-1.7549962617845205,-0.2863099159981193
179.90000000000217,36.480492278369205,-1.7545934692271987,-0.2863098878012531
181.0000000000022,36.5846882768693,-1.7533753336218576,-0.2877627395264257
182.1000000000022,36.68953796471047,-1.7518476910538052,-0.2889400769492241
183.2000000000022,36.794481094747155,-1.750661494155887,-0.2902599008836737
184.30000000000223,36.898040135641175,-1.7493560688756309,-0.28893979011382376
185.40000000000225,37.00396641853979,-1.7467367866893175,-0.29025998357273775
186.50000000000227,37.108621804104956,-1.7456432166812852,-0.29153403213843543
187.6000000000023,37.21220165653661,-1.7434635455310037,-0.2928998900145845
188.7000000000023,37.31781010266172,-1.7432220674725993,-0.2932293648114217
189.8000000000023,37.42197490599809,-1.742512620859977,-0.2945490573068885
190.90000000000234,37.52698491475278,-1.7409917470162029,-0.29554028257208476
192.00000000000233,37.63113636382299,-1.7389864992891046,-0.2955402020001143
193.10000000000235,37.73561162417084,-1.739274255318881,-0.29562372926517133
194.20000000000238,37.84081759686329,-1.7380454063102113,-0.29652020129658396
195.3000000000024,37.94480743453185,-1.73646898090906,-0.29782976802833394
196.40000000000242,38.04926175651868,-1.7351413806374143,-0.2991993680194538
197.50000000000242,38.15518313689693,-1.7331926724100908,-0.30047016733908016
198.60000000000244,38.258430905848314,-1.731259513016396,-0.3017900905751665
199.70000000000246,38.36394895106208,-1.7310295453213995,-0.3017729191828007
200.80000000000246,38.467482100445906,-1.73013413332012,-0.3034387704134982
201.90000000000248,38.57219397392382,-1.7290043752462743,-0.30575043818671555
203.0000000000025,38.676789365629844,-1.7290011798347058,-0.30706004736505044
204.10000000000252,38.78186425870441,-1.727379239870526,-0.3073900637923739
205.20000000000255,38.885699706038345,-1.7267541979151675,-0.30705988721310096
206.30000000000254,38.9886024041955,-1.7259938472895586,-0.30989810394692263
207.40000000000256,39.09424822344297,-1.724537289822606,-0.31343825378403567
208.5000000000026,39.19923922845288,-1.7247155424263805,-0.3167200071366043
209.60000000000258,39.30272173984853,-1.723239161895493,-0.31606266569628483
210.7000000000026,39.40634026764348,-1.722204104196242,-0.3173795550205858
211.80000000000263,39.512428015900255,-1.7216645230770105,-0.3186999236125554
212.90000000000265,39.61737078246727,-1.7212650293804215,-0.32001023009596086
214.00000000000267,39.722049750910024,-1.7195867004368073,-0.32001937970443306
215.10000000000267,39.82592308504506,-1.719878125751152,-0.3255845979786547
216.2000000000027,39.93060439257513,-1.7198513521318566,-0.3284056134348976
217.3000000000027,40.03456802193677,-1.7191822985233245,-0.33219477257172425
218.4000000000027,40.139901150006594,-1.7190871944374881,-0.3348315177498904
219.50000000000273,40.24536379774046,-1.7185763699953565,-0.3361499479314145
220.60000000000275,40.34970022614583,-1.7186002126997848,-0.338478098806303
221.70000000000277,40.452549193652544,-1.7183240532276127,-0.3400964860213933
222.8000000000028,40.55814036260632,-1.7173886165955103,-0.3441738744272169
223.9000000000028,40.662819890319376,-1.7166546756213759,-0.34681625580217235
225.0000000000028,40.76685451192006,-1.7167875025161323,-0.3494388325503026
226.10000000000284,40.872201880831305,-1.7170201859752834,-0.3537162796341855
227.20000000000283,40.975812452134136,-1.7163049793535818,-0.35621417716706816
228.30000000000285,41.08091143290856,-1.714667948915997,-0.36031838085786605
229.40000000000288,41.18484431479886,-1.7154496003298467,-0.3631441271891047
230.5000000000029,41.28971943114902,-1.7142547818384495,-0.36694518607835747
231.60000000000292,41.395496581198195,-1.714476567396873,-0.37100933628235966
232.70000000000292,41.499528415881116,-1.7137529523915642,-0.3738190313699681
233.80000000000294,41.60449279685627,-1.7123202483345743,-0.3764208000430198
234.90000000000296,41.708996595455964,-1.7108472631373755,-0.38178243516010824
236.00000000000296,41.81411887778198,-1.7102848561907071,-0.386326340024981
237.10000000000298,41.91958497473939,-1.7102593152624532,-0.3892837809086478
238.200000000003,42.02564481442335,-1.709090221511028,-0.3937659370253894
239.30000000000302,42.13112755922985,-1.7077324364914446,-0.39909654590305976
240.40000000000305,42.23510253253876,-1.707227998714921,-0.4013548077120639
241.50000000000304,42.34009626457308,-1.70422791625567,-0.4072897751802702
242.60000000000306,42.444328729946704,-1.7028538610888886,-0.4131113036194223
243.7000000000031,42.55095456581465,-1.7016503430189316,-0.4160421340654765
244.80000000000308,42.65624484793467,-1.7012961346431956,-0.41965005562564883
245.9000000000031,42.75982772179326,-1.6999737335255116,-0.42508007142008086
247.00000000000313,42.865070002796614,-1.6986989191017203,-0.4296635381983358
248.10000000000315,42.970893399796886,-1.6970091940769747,-0.43596683084394794
249.20000000000317,43.07631531390229,-1.695201114351178,-0.4417009322220107
250.30000000000317,43.18032754855809,-1.6944835122711326,-0.4478261002924797
251.4000000000032,43.28178007628929,-1.693012605134891,-0.45160306000951467
252.5000000000032,43.38927061471659,-1.6908477933057442,-0.4581131358592341
253.6000000000032,43.49345753964525,-1.6908886562205379,-0.46274950063901343
254.70000000000323,43.598717785313916,-1.6889494929726325,-0.46898832769023935
255.80000000000325,43.70314765573313,-1.6876794046038106,-0.4769208242164078
256.9000000000033,43.807826130905134,-1.6872882233582691,-0.48387200117983165
258.0000000000033,43.911423142314675,-1.6854339297306908,-0.4905255485404991
259.1000000000033,44.0165442499846,-1.684301593274009,-0.49493735895163793
260.20000000000334,44.12127194068361,-1.6814773049538405,-0.5036344840710854
261.30000000000337,44.22615138278242,-1.6813032355443454,-0.5108973435304258
262.40000000000333,44.33170257224794,-1.6798627025425732,-0.5175488647927566
263.50000000000335,44.43486038115526,-1.6772317628582505,-0.5247586657914001
264.6000000000034,44.53825451579933,-1.6761736996865675,-0.5353442179582855
265.7000000000034,44.64516606765545,-1.6754568832825678,-0.542838444752971
266.8000000000034,44.747759653235086,-1.6741849016646995,-0.5521161115595543
267.9000000000034,44.853964491713484,-1.6722172187080098,-0.5601878776490743
269.0000000000034,44.960096986518266,-1.671825853314908,-0.5704426928789359
270.10000000000343,45.06389579215347,-1.6708609952791642,-0.5798289232676401
271.20000000000346,45.169322209987605,-1.6697320248441925,-0.5867303958243264
272.3000000000035,45.2737714802212,-1.6664555492114548,-0.5970913278656256
273.4000000000035,45.37977271917603,-1.665737465916155,-0.610259356111714
274.5000000000035,45.485113512782,-1.6658554891630333,-0.6203808448068191
275.60000000000355,45.58973138158738,-1.6648460033354617,-0.6310101127123127
276.70000000000357,45.6947266075925,-1.6627865694733501,-0.6433084502795166
277.8000000000036,45.8000009111422,-1.6623799914286688,-0.6554099936652675
278.9000000000036,45.90413199971895,-1.6610354990603253,-0.6680637987003974
280.0000000000036,46.010065167413295,-1.6596963938619764,-0.6806278293769785
281.1000000000036,46.115959392424195,-1.6573495495666954,-0.6933057564842793
282.2000000000036,46.2211873343138,-1.6554335164384346,-0.7063140918486837
283.30000000000365,46.32606146178538,-1.6556559828407744,-0.7192870929617605
284.4000000000037,46.431232505444335,-1.6546734630471525,-0.7330686266575812
285.5000000000037,46.536498848143836,-1.6525861871609753,-0.7468091474296012
286.60000000000366,46.642179492592696,-1.6504989370005774,-0.7632588040496926
287.7000000000037,46.74826398972984,-1.6498545408445409,-0.7797606085935431
288.8000000000037,46.852839822152696,-1.6489799474133424,-0.7953397905081694
289.90000000000373,46.95797943956387,-1.647663072396654,-0.8099290743531777
291.00000000000375,47.06305886572175,-1.646047025128803,-0.8275058673636564
292.1000000000038,47.168364088783306,-1.6462694408694438,-0.8462951362262823
293.2000000000038,47.27343180308749,-1.6456381546615946,-0.8624711545343007
294.3000000000038,47.37834975889938,-1.6453499700967316,-0.8807007244059486
295.40000000000384,47.4847682567336,-1.6443467342546507,-0.9002978844535665
296.5000000000038,47.59158030592306,-1.6453247586643454,-0.9172756437597758
297.60000000000383,47.6972609852731,-1.645121083801627,-0.9379789553548052
298.70000000000385,47.80096093866886,-1.6447926069502479,-0.9594138022489327
299.8000000000039,47.906306479751564,-1.6450192632778255,-0.9789908641528111
300.9000000000039,48.013024699638805,-1.6447516397704534,-1.0017903997567634
302.0000000000039,48.11817742086662,-1.6459725705894732,-1.0226629226637476
303.10000000000394,48.224016776390584,-1.6450364629997947,-1.0425828474121248
304.2000000000039,48.32964997429565,-1.646384022626525,-1.065979652085864
305.30000000000393,48.4330205193939,-1.6458755908874885,-1.089625451060991
306.40000000000396,48.54110970497206,-1.6477847461673374,-1.1139773992344373
307.500000000004,48.64623587376586,-1.6472803926170396,-1.1373499482470981
308.600000000004,48.75275581668238,-1.6481624699922854,-1.1608362514885373
309.700000000004,48.85865254783083,-1.648145294715676,-1.1857246239515375
310.80000000000405,48.96486507524508,-1.64741552058248,-1.2138689059608456
311.90000000000407,49.070105292603266,-1.6481840304799056,-1.239623380146183
313.0000000000041,49.17553087009367,-1.647875956996301,-1.2649182333817768
314.10000000000406,49.28128517951288,-1.6471626997349489,-1.2906933709115314
315.2000000000041,49.38774606807712,-1.6443347306571083,-1.3171216445451774
316.3000000000041,49.49262464705172,-1.6441279368709136,-1.3458726682812698
317.4000000000041,49.59922301706082,-1.642160136491544,-1.3750198463989234
318.50000000000415,49.70534714790154,-1.638845062291664,-1.4025384251684816
319.6000000000042,49.80857301943179,-1.6373184013923567,-1.4317278408576066
320.7000000000042,49.91680151706615,-1.6359435179583193,-1.4590405409307996
321.80000000000416,50.02259878934241,-1.6320052698615948,-1.491517857542065
322.9000000000042,50.12723910737322,-1.6291733991942048,-1.5206494658734089
324.0000000000042,50.23219890725643,-1.6272593143710965,-1.5483695339721417
325.10000000000423,50.33895599909764,-1.6232137803102336,-1.5771070178591469
326.20000000000425,50.44516768336867,-1.6209342129230402,-1.6086531887740017
327.3000000000043,50.55101975959421,-1.6163144252237482,-1.639578956762929
328.4000000000043,50.656130584347295,-1.6115379302423234,-1.6707062223588252
329.5000000000043,50.76200513107603,-1.6075775340343386,-1.7006274830266497
330.60000000000434,50.867776957524576,-1.603233124244366,-1.7304850081160805
331.7000000000043,50.97366029887006,-1.599135508863334,-1.7624313879346927
332.80000000000433,51.07945648935672,-1.593144393992135,-1.7910659358595722
333.90000000000435,51.18572993739033,-1.5911317710942423,-1.819499134935628
335.0000000000044,51.29231748749686,-1.586672261030487,-1.8493829279261145
336.1000000000044,51.397847475052714,-1.5843910432188824,-1.8803358330933935
337.2000000000044,51.503422853404516,-1.5794791356542375,-1.9115330043294434
338.30000000000445,51.61020938448734,-1.5759481724367803,-1.9407685873557807
339.4000000000044,51.71656271179031,-1.5699925858536843,-1.9690709047446542
340.50000000000443,51.82223688313379,-1.5677808456410494,-1.997874297012963
341.60000000000446,51.92771926528039,-1.5627779686692427,-2.0274662239133256
342.7000000000045,52.032504068232086,-1.5564809414532774,-2.056056714306848
343.8000000000045,52.13924437051662,-1.5527465352879135,-2.087633121271137
344.9000000000045,52.24623752260869,-1.547680005212073,-2.116929318882801
346.00000000000455,52.353237293447776,-1.5419996638380495,-2.146014313304839
347.10000000000457,52.45870862029821,-1.537971080734797,-2.1711246024970174
348.2000000000046,52.56521337851395,-1.5315972558030069,-2.2030345364738277
349.30000000000456,52.670832165077,-1.524200424422467,-2.230079896331022
350.4000000000046,52.77724605015234,-1.5188965084098285,-2.256815004386662
351.5000000000046,52.88289819329076,-1.5110779523090982,-2.2820845232163856
352.6000000000046,52.98960677111585,-1.5041964678608946,-2.306218785427751
353.70000000000465,53.09478085815395,-1.4961774131742354,-2.3319220652577286
354.8000000000047,53.2013974281904,-1.4889369365254277,-2.355515922229638
355.9000000000047,53.307024070350614,-1.4807683633920834,-2.3778748453315552
357.00000000000466,53.41277777871502,-1.472691059260745,-2.4002905605087967
358.1000000000047,53.52018611424459,-1.4644008803792274,-2.4250428890272087
359.2000000000047,53.62629568508776,-1.4537873693465284,-2.44897175788278
360.30000000000473,53.732365957642116,-1.4461854788990827,-2.466925419120093
361.40000000000475,53.83837016036242,-1.4377990849950455,-2.48466442546996
362.5000000000048,53.94495711192618,-1.4284750483046276,-2.5035319589071623
363.6000000000048,54.05118137064454,-1.4202746824987167,-2.520295195699021
364.7000000000048,54.1577878842063,-1.4116870084845803,-2.538504660203955
365.80000000000484,54.26371336648414,-1.405464258532337,-2.555092556025709
366.9000000000048,54.36998424004501,-1.3986772806176826,-2.568787677814166
368.00000000000483,54.47641579541731,-1.3935802254879248,-2.5813227641968464
369.10000000000485,54.581847379612974,-1.3875234447054015,-2.595898482351938
370.2000000000049,54.689479898555355,-1.384652953923653,-2.6084962417216233
371.3000000000049,54.796489017940765,-1.3818303923206965,-2.619467999069111
372.4000000000049,54.90192803989332,-1.3808777980037985,-2.62775273375629
373.50000000000495,55.0082394433498,-1.378814757719741,-2.637100648561377
374.6000000000049,55.114142042761316,-1.378933365001877,-2.645481927751918
375.70000000000493,55.219908602295305,-1.3786052554378367,-2.6549959799972522
376.80000000000496,55.32705671626715,-1.3780639359027356,-2.662269290956231
377.900000000005,55.43323618637727,-1.3792323361927055,-2.670135385645758
379.000000000005,55.54091816913859,-1.3786430177415152,-2.6764738086934403
380.100000000005,55.646021150698296,-1.3789573392654462,-2.6801972536048657
381.20000000000505,55.75237541017841,-1.3757024876524624,-2.685288030292429
382.30000000000507,55.86061097640986,-1.3726665729382466,-2.6922327874636363
383.4000000000051,55.966268515767155,-1.3708135272721962,-2.6984586087089815
384.50000000000506,56.073633917431735,-1.3675480129585589,-2.701547883657952
385.6000000000051,56.179904225510846,-1.3632883679794676,-2.7072494990002305
386.7000000000051,56.28599677059295,-1.3592539073399728,-2.7127512144096153
387.8000000000051,56.39401039865071,-1.356557355772047,-2.717794041145504
388.90000000000515,56.500001004595575,-1.3522899236132468,-2.7224101713065396
390.0000000000052,56.60743413334012,-1.3486176857599133,-2.7258814000980185
391.1000000000052,56.71534063870478,-1.3459946415038622,-2.7327773980511667
392.20000000000516,56.82108926706252,-1.3438262923092867,-2.735725462048909
393.3000000000052,56.9282017371736,-1.341523266658459,-2.7404385246016774
394.4000000000052,57.03503130522434,-1.3404547582425408,-2.7442119905776705
395.50000000000523,57.14339093628345,-1.3391811425872524,-2.750033979124018
396.60000000000525,57.249129907543065,-1.3380157828907298,-2.753343813076402
397.7000000000053,57.35715154654485,-1.3359724046098902,-2.756864029352614
398.8000000000053,57.463813671030124,-1.337556167091997,-2.762445295490645
399.9000000000053,57.57128757946165,-1.338075013703277,-2.7670972609479083
401.00000000000534,57.678512131124904,-1.3371834214431364,-2.7697184738880134
402.1000000000053,57.78603893025749,-1.3383313517744566,-2.774000989138452
403.20000000000533,57.89332892622331,-1.3403299680946006,-2.777189920675325
404.30000000000535,58.00117377904975,-1.3421816064799448,-2.781126238398321
405.4000000000054,58.10793617780226,-1.3433447788936903,-2.786739008261233
406.5000000000054,58.21618541151836,-1.3440720402678872,-2.7913205848580995
407.6000000000054,58.322918444641495,-1.3458630525120834,-2.7948160179780857
408.70000000000545,58.43024281705987,-1.3485268816949674,-2.800674246860856
409.8000000000054,58.53850926291051,-1.3518688465488504,-2.805587944252104
410.90000000000543,58.64553952740712,-1.3565674764091533,-2.8071283322533374
412.00000000000546,58.753820055194744,-1.3615807372078716,-2.811221245273214
413.1000000000055,58.8612139121075,-1.3670478854963422,-2.8138921808736095
414.2000000000055,58.96867872008793,-1.3697496415215655,-2.818295305130708
415.3000000000055,59.07718990528345,-1.3708822060624533,-2.824705780151554
416.40000000000555,59.18251733665935,-1.3740532258954543,-2.8281736345275266
417.50000000000557,59.29151300066013,-1.3771209653112049,-2.830707824330628
418.6000000000056,59.39971588175182,-1.382804389156802,-2.8338051218688767
419.70000000000556,59.508022849080575,-1.3862982977284348,-2.837695357762784
420.8000000000056,59.61492979297343,-1.3921657733781996,-2.8390973261362653
421.9000000000056,59.721494979316574,-1.395637405573664,-2.8438079431043035
423.0000000000056,59.832557192593015,-1.4038044625957424,-2.8487879472542588
424.10000000000565,59.94067645320589,-1.409955944289287,-2.852445910935529
425.2000000000057,60.04840144730472,-1.4171408107926993,-2.8556779593580135
426.3000000000057,60.155733867093424,-1.423390377186364,-2.859023186909291
427.40000000000566,60.26494332885943,-1.4286090841098935,-2.863489922198826
428.5000000000057,60.37305892210611,-1.4319925438199632,-2.8661112946225495
429.6000000000057,60.481088222673506,-1.4361981661110417,-2.8685026119744355
430.70000000000573,60.58883787224185,-1.4389164732262818,-2.8724518466943403
431.80000000000575,60.69742052723635,-1.4424347577078063,-2.875443796830364
432.9000000000058,60.806844907112755,-1.4497402066941483,-2.8795312649644407
434.0000000000058,60.91405382281644,-1.4551028725445212,-2.8821277494470197
435.1000000000058,61.02211317333189,-1.4593124580723287,-2.8834610678645523
436.20000000000584,61.13151321989322,-1.4618432124993046,-2.886087100793961
437.3000000000058,61.2397857468215,-1.4619998590065124,-2.8887208543485015
438.40000000000583,61.34789220061074,-1.4672266013886797,-2.893206123120849
439.50000000000585,61.45603897149024,-1.468708199923285,-2.8959531900099207
440.6000000000059,61.564323700102754,-1.4711320705085882,-2.9001866374417418
441.7000000000059,61.67290502120101,-1.4686058067689989,-2.9027778769078245
442.8000000000059,61.780401407197424,-1.4698457401714227,-2.905641332290346
443.90000000000595,61.88859729598129,-1.4714674453323922,-2.9069501977333774
445.0000000000059,61.99713774392866,-1.4698200257707736,-2.9107301367710194
446.10000000000593,62.10618193951421,-1.4715981867509167,-2.9128722083634604
447.20000000000596,62.213971282959825,-1.4730254773943612,-2.9135445347691498
448.300000000006,62.321615187075125,-1.471667764071034,-2.916287818278592
449.400000000006,62.4289432304005,-1.4713269387661128,-2.920336732664416
450.500000000006,62.53833370141692,-1.471973920131353,-2.9223195010578467
451.60000000000605,62.64715533406174,-1.4706931431172099,-2.924979911322726
452.70000000000607,62.75485532665952,-1.4692664436842438,-2.9262576454176212
453.8000000000061,62.86353916212587,-1.4671073384533078,-2.9304603362323776
454.90000000000606,62.97136820931646,-1.4664815991497797,-2.933079156085551
456.0000000000061,63.07979145839959,-1.4645930072015971,-2.9343955098475165
457.1000000000061,63.18842370427148,-1.4633207333618015,-2.937147827603523
458.2000000000061,63.29772298866802,-1.4624172313355568,-2.93977979612931
459.30000000000615,63.403795529418744,-1.4611608399241391,-2.940645418551269
460.4000000000062,63.51457350947479,-1.4586186358158162,-2.94347529694734
461.5000000000062,63.623666770485,-1.4578180725585994,-2.946029682174765
462.60000000000616,63.73182318348858,-1.4573496223730154,-2.9478147490124456
463.7000000000062,63.84062641509482,-1.4556913896880352,-2.9491098044940753
464.8000000000062,63.950581166304985,-1.455424036703661,-2.950419250262856
465.90000000000623,64.05848430671607,-1.4548409392293669,-2.9530671381623765
467.00000000000625,64.16795816089952,-1.454218115013003,-2.9564508916030694
468.1000000000063,64.277075760361,-1.4529913105413876,-2.957890005989456
469.2000000000063,64.38647197982574,-1.4507038236047396,-2.95789000599795
470.3000000000063,64.49519177093522,-1.449487192914845,-2.9614787594876075
471.40000000000634,64.60493506144408,-1.4476410116073295,-2.9694657369382558
472.5000000000063,64.71333000000071,-1.447540000000048,-2.9667801876373776
473.60000000000633,64.8233589083043,-1.4436459246613622,-2.970555790369856
474.70000000000636,64.93162347573464,-1.4435259351889467,-2.972050068005105
475.8000000000064,65.0409967164731,-1.4434487233665778,-2.9720479979392573
476.9000000000064,65.1500459751947,-1.440564782626235,-2.9737040585066703
478.0000000000064,65.25886044283516,-1.4366930831884739,-2.9750097439416727
479.10000000000645,65.36800582529561,-1.4353822802416907,-2.9770137562934815
480.2000000000064,65.47749929179535,-1.4323981505175611,-2.978976273744922
481.30000000000643,65.5881785886468,-1.4302368155772918,-2.9815951714473194
482.40000000000646,65.69598586750227,-1.4273130510904368,-2.9821919999282245
483.5000000000065,65.806166450454,-1.4216529723672569,-2.98458063520836
484.6000000000065,65.91396944311178,-1.418698323684147,-2.985560112227224
485.7000000000065,66.02397064436049,-1.4152337661339802,-2.987144038327596
486.80000000000655,66.13269793626192,-1.4144715484360815,-2.9911480424569623
487.90000000000657,66.24106693278651,-1.4108892189026043,-2.9873478517885186
489.0000000000066,66.35106569785518,-1.4037915426449528,-2.9916106791734736
490.10000000000656,66.46010643109558,-1.3960024698120157,-2.9956617333871716
491.2000000000066,66.56940272174607,-1.3889842178144525,-2.9967486873762437
492.3000000000066,66.6778550930391,-1.3827089168739213,-2.998069864021139
493.4000000000066,66.78783667231228,-1.3781742366913432,-2.998074005943434
494.50000000000665,66.89576900043743,-1.3744067486714537,-3.0016608265350255
495.6000000000067,67.00506682176636,-1.3680932838625535,-3.0020283202170814
496.7000000000067,67.11281011971789,-1.3644492198690301,-3.0026115379338916
497.80000000000666,67.22312608370422,-1.3609021520957336,-3.0061757403308222
498.9000000000067,67.33221498381543,-1.3584258112316179,-3.0061901761505103
500.0000000000067,67.44180800584417,-1.3584263845797258,-3.006198777488409
501.10000000000673,67.5505259580803,-1.3562926898305896,-3.0078152279680097
502.20000000000675,67.66056840719621,-1.3540262913606107,-3.01096163528055
503.3000000000068,67.77006912563064,-1.3483532761432728,-3.0132198909438204
504.4000000000068,67.87644671830074,-1.3466956036848223,-3.0132632814278413
505.5000000000068,67.98846469570321,-1.3441887187163253,-3.015528198747875
506.60000000000684,68.09763483688022,-1.342815194828483,-3.0171703147765245
507.7000000000068,68.20511652337588,-1.3438534420010517,-3.0189294205296022
508.80000000000683,68.31644377083022,-1.3404921050709677,-3.01892973440476
509.90000000000686,68.4263811222576,-1.3417098386360573,-3.0215600658983517
511.0000000000069,68.53486071851177,-1.3405502427591554,-3.021560763268154
512.100000000007,68.64547679335747,-1.3438556495973157,-3.0212257174039374
513.2000000000069,68.75484696516861,-1.3418615249259687,-3.0225480663781745
514.300000000007,68.86411395023555,-1.3391368663239425,-3.0251811368074515
515.4000000000069,68.97450437694718,-1.339762238096248,-3.025500952977791
516.5000000000069,69.08452048375649,-1.3411529246618807,-3.0268488745529654
517.600000000007,69.19392986770333,-1.3407513759955165,-3.030129798447561
518.700000000007,69.30422050160395,-1.3408287762792859,-3.031769940596576
519.800000000007,69.41277837267614,-1.340232082190993,-3.032590905732561
520.900000000007,69.52367882470845,-1.340469855820304,-3.0321098448024193
522.000000000007,69.6325420982627,-1.340535099356824,-3.033394712652938
523.1000000000071,69.74255662772367,-1.3386526180996587,-3.036058559872596
524.2000000000071,69.85250303737348,-1.3384576260600014,-3.037380132657099
525.300000000007,69.96260793859074,-1.339049150151068,-3.037050130349084
526.4000000000071,70.07162185700618,-1.3382174678803131,-3.0377033353366243
527.500000000007,70.18195302069279,-1.3383161340872711,-3.040326010211178
528.6000000000072,70.2920583678001,-1.3403939738909587,-3.0416501480202314
529.7000000000071,70.4019094728827,-1.3402820062508587,-3.044286837443547
530.8000000000072,70.51156780906841,-1.3403056754084894,-3.0447321238263463
531.9000000000071,70.62246542073505,-1.3417770033629906,-3.0482400192756
533.0000000000072,70.73311559811316,-1.3427913202565827,-3.0482397588264707
534.1000000000072,70.84155211224488,-1.3437878924347568,-3.0503795195851326
535.2000000000072,70.9524858618618,-1.3446953141216993,-3.0493398626411694
536.3000000000072,71.06225433553176,-1.346245709115297,-3.049987159169506
537.4000000000073,71.17210940585373,-1.3473372442311828,-3.051307152093403
538.5000000000073,71.2819594373659,-1.3473649019304883,-3.051359456071127
539.6000000000073,71.39283960934637,-1.3494077299893,-3.053724120908539
540.7000000000073,71.50213633350884,-1.3511883296145049,-3.0552984052821417
541.8000000000073,71.612406846575,-1.3495551589165964,-3.0565866541347013
542.9000000000074,71.7221082909437,-1.3510380648991416,-3.058912196652956
544.0000000000074,71.83097637198243,-1.352962633525172,-3.0579015655682507
545.1000000000074,71.94388050338621,-1.353496381240283,-3.0579099738568694
546.2000000000073,72.05375085996766,-1.3568314088203888,-3.060200991142925
547.3000000000073,72.16343579137394,-1.3571237530485203,-3.0618500403601767
548.4000000000074,72.27402310781417,-1.3569371614423718,-3.063162769527383
549.5000000000074,72.3847373660291,-1.3584114847167483,-3.0680978444411604
550.6000000000074,72.4952176875872,-1.3626489298485935,-3.066455300743163
551.7000000000074,72.60657931267197,-1.3646278508988376,-3.0671154149513713
552.8000000000075,72.7147308258528,-1.3656232495472767,-3.068141205644853
553.9000000000075,72.82847179072783,-1.3671747267726995,-3.0689077247639034
555.0000000000075,72.93853778261274,-1.3684520079413631,-3.069869836886394
556.1000000000075,73.04838201919912,-1.369058456534093,-3.0708535142375006
557.2000000000075,73.15888028839011,-1.3711223630876992,-3.070529988969199
558.3000000000076,73.27010107913421,-1.3721938398937283,-3.0708600557555807
559.4000000000076,73.379997753394,-1.3743897371266394,-3.0727785791410627
560.5000000000076,73.49080410111524,-1.3766770629590694,-3.073161493824923
561.6000000000076,73.60251481554913,-1.378414051193609,-3.0744802018300073
562.7000000000077,73.71238381407949,-1.379164886781123,-3.077120121456422
563.8000000000077,73.82342817334923,-1.3818325665514515,-3.0784433318257207
564.9000000000076,73.93533512983967,-1.3836266507191457,-3.079948665195801
566.0000000000076,74.04541342294661,-1.3850360841480214,-3.0809600359559424
567.1000000000076,74.15625325612801,-1.3882802101710758,-3.079967686399523
568.2000000000077,74.26786403196596,-1.3905461452834162,-3.0799662543687196
569.3000000000077,74.37860782172189,-1.3922190303234492,-3.0825998669783266
570.4000000000077,74.48930113649054,-1.3925578860759977,-3.082599869782631
571.5000000000077,74.59974113660701,-1.3951153594252077,-3.0835902060021674
572.6000000000078,74.71121780382366,-1.3954179348971054,-3.085239806562784
573.7000000000078,74.8218722777715,-1.3977196636058526,-3.085239415138207
574.8000000000078,74.93300229009972,-1.4008071186786601,-3.0852298442432264
575.9000000000078,75.04430316039786,-1.4015197730346753,-3.0852432545110995
577.0000000000078,75.15456531340783,-1.4027594990150452,-3.0879925819927294
578.1000000000079,75.26622722848226,-1.4029308489364047,-3.0895787850924155
579.2000000000079,75.37731847126001,-1.4059325923252373,-3.090298038840155
580.3000000000079,75.48815577423515,-1.4084594435557578,-3.091270117014667
581.4000000000078,75.59807568966256,-1.4099520453613976,-3.0912625964616236
582.5000000000078,75.70836589468722,-1.4118893942331183,-3.091966270406851
583.6000000000079,75.8190393842224,-1.413144477115932,-3.091279968016565
584.7000000000079,75.92969169770225,-1.4133350545276127,-3.0925986998442
585.8000000000079,76.04100630151358,-1.414562377279404,-3.0925900265391153
586.9000000000079,76.15250224769086,-1.416599753069181,-3.094824156325042
588.000000000008,76.2625697495043,-1.414469464118383,-3.0939083430949896
589.100000000008,76.37411763221684,-1.4131944834081585,-3.095992090547841
590.200000000008,76.48601825234101,-1.4151152669317184,-3.0978699940241308
591.300000000008,76.5952863994342,-1.413861481273709,-3.0978701931111763
592.400000000008,76.70695026879561,-1.4160484575870078,-3.0991799158655393
593.5000000000081,76.81872016374594,-1.4168276424283708,-3.1004998676816182
594.6000000000081,76.92952434785028,-1.4189662858379966,-3.1018201300320616
595.7000000000081,77.04037834487139,-1.4202697976696699,-3.100502193483446
596.8000000000081,77.15139898752936,-1.4213405858263357,-3.100504959894591
597.9000000000082,77.26370018712694,-1.4250597159767207,-3.101821414072892
599.0000000000082,77.37343491943699,-1.4247736679422807,-3.103460196853201
600.1000000000081,77.48538631413903,-1.4291005742152028,-3.104780197010103
601.2000000000081,77.59607139815886,-1.4285492120799512,-3.103461211816594
602.3000000000081,77.70737900762616,-1.4315404264037763,-3.1034602628212307
603.4000000000082,77.81988523805514,-1.432883071378755,-3.104770961785768
604.5000000000082,77.92984643684218,-1.434090067739367,-3.1060898204298746
605.6000000000082,78.04114786737587,-1.4337251449681696,-3.1074102427240673
606.7000000000082,78.1491734188268,-1.4367857634181398,-3.1077401439847527
607.8000000000083,78.26275893965916,-1.4378642865994922,-3.107740144001183
608.9000000000083,78.37405971419902,-1.4398899177169506,-3.107446945627799
610.0000000000083,78.48532175438403,-1.4420467392813263,-3.1087345333805163
611.1000000000083,78.59429329711607,-1.444083281721277,-3.1102708671599677
612.2000000000083,78.7071573885455,-1.4473551798665394,-3.1112128088995803
613.3000000000084,78.81809501385627,-1.4489991146738845,-3.111337590210724
614.4000000000084,78.9292097496366,-1.4539336645045933,-3.113999936386998
615.5000000000084,79.03841117088288,-1.4559141055159506,-3.1126898506476897
616.6000000000083,79.15072844951176,-1.459218711975421,-3.111950092133612
617.7000000000083,79.26197005530422,-1.4584514454416864,-3.1145463930247024
618.8000000000084,79.37258704809167,-1.4632582941639336,-3.1132273066867633
619.9000000000084,79.48417004866896,-1.4650505999788137,-3.113228936511928
621.0000000000084,79.59562165988577,-1.4666212989425786,-3.117895668239645
622.1000000000084,79.70626057646285,-1.4673406233364923,-3.1178383259134357
623.2000000000085,79.81713767053586,-1.4711761730070192,-3.117839971975951
624.3000000000085,79.92786798999819,-1.4773974224494055,-3.118826644991826
625.4000000000085,80.0398923882243,-1.479543447531412,-3.117289867203514
626.5000000000085,80.15087540570586,-1.4826209428794366,-3.1186100080163097
627.6000000000085,80.26170093646606,-1.4860410916031477,-3.11861000799997
628.7000000000086,80.37087429311285,-1.4881486010697518,-3.1185103028307313
629.8000000000086,80.48355595232483,-1.4925114265202273,-3.120910254234837
630.9000000000086,80.59021670202037,-1.4972372715638125,-3.1209099967241443
632.0000000000086,80.70594073762886,-1.4997759433250557,-3.1219111790370118
633.1000000000087,80.8175320793414,-1.5033524738886017,-3.123179155243384
634.2000000000087,80.9287747914921,-1.5091419949910856,-3.124559022486798
635.3000000000086,81.04013519489824,-1.5110519321734195,-3.12519939216898
636.4000000000086,81.15098712042536,-1.5133211384553074,-3.1265099569369577
637.5000000000086,81.26235888778987,-1.5159072000094593,-3.126306765642243
638.6000000000087,81.37364894905457,-1.519142440104364,-3.127840175500451
639.7000000000087,81.48513509102003,-1.5221875246588414,-3.127380363409892
640.8000000000087,81.59569088100801,-1.5238866647468658,-3.1270761738126733
641.9000000000087,81.70843650077475,-1.5259262157911424,-3.1267300423372113
643.0000000000088,81.81907082523192,-1.5279871073724072,-3.12931046193423
644.1000000000088,81.92860347266263,-1.5300044175506073,-3.1293741281688456
645.2000000000088,82.04075611275222,-1.5333901705503792,-3.129389434448588
646.3000000000088,82.15297357669921,-1.5361414647949627,-3.129370212292621
647.4000000000088,82.26419268983446,-1.5404499107651382,-3.130374676899973
648.5000000000089,82.37562502921358,-1.543140053116468,-3.128159918037503
649.6000000000089,82.48647712180569,-1.5440235901656683,-3.130797334271578
650.7000000000089,82.59911318833117,-1.5438022368341309,-3.134865753006697
651.8000000000088,82.70984416364881,-1.5469947547633158,-3.133539800645843
652.9000000000088,82.8201289429387,-1.5478265652890795,-3.1335398092879934
654.0000000000089,82.93229932056252,-1.5522045564022293,-3.1322199016927463
655.1000000000089,83.04324291432849,-1.5546400520379173,-3.1324553006627815
656.2000000000089,83.15477968500018,-1.556885525773446,-3.1335401319975675
657.3000000000089,83.26641314871618,-1.5585462833005097,-3.1348588552250396
658.400000000009,83.37737830993055,-1.5609940405526086,-3.1361701949815117
659.500000000009,83.48912049334392,-1.5601720936797279,-3.133538090352819
660.600000000009,83.60087380399594,-1.5610115245431586,-3.134863805968914
661.700000000009,83.71354038072006,-1.5651049029955488,-3.1374999297524466
662.800000000009,83.82409114827705,-1.5669200809967696,-3.138479891467331
663.9000000000091,83.9335482563308,-1.5678131905596182,-3.138841816970123
665.0000000000091,84.0472433744401,-1.569814401702603,-3.1398000979232306
666.1000000000091,84.15859939905347,-1.5720116562218152,-3.1384899174641
667.2000000000091,84.27008369478142,-1.5744046857570573,-3.13749992729295
668.3000000000092,84.3806319218747,-1.574066188573936,-3.1392603419503344
669.4000000000092,84.4932090784226,-1.5735303322389607,-3.1430807737597313
670.5000000000091,84.6048941334797,-1.5767939771841548,-3.1416425180771212
671.6000000000091,84.71637164744433,-1.5809357039681053,-3.140460047624459
672.7000000000091,84.82743130249173,-1.580762021015127,-3.141849906589391
673.8000000000092,84.93868067082037,-1.578490801762512,-3.1446566265492857
674.9000000000092,85.05106144385913,-1.5825130767098017,-3.1419901703859194
676.0000000000092,85.16250878844664,-1.5818901416688178,-3.142158484757929
677.1000000000092,85.27258571833748,-1.5836951549948957,-3.143540032420198
678.2000000000093,85.38555829545565,-1.5863800755462754,-3.1433921921633363
679.3000000000093,85.4965274931104,-1.5889807412088897,-3.1435301471717674
680.4000000000093,85.60882480826635,-1.5894912319244008,-3.1457722684624465
681.5000000000093,85.72046305302614,-1.5919966301279584,-3.1474763157276784
682.6000000000093,85.8332298504269,-1.5939606947652238,-3.1474947102489907
683.7000000000094,85.94517245104981,-1.5961897959344242,-3.1478198957965757
684.8000000000094,86.05594825199184,-1.5982763469564847,-3.1504969162342205
685.9000000000094,86.1678686890236,-1.6019953236640128,-3.149388438719681
687.0000000000093,86.28010018508559,-1.601166986223071,-3.1491400394141964
688.1000000000093,86.3919486163332,-1.6037360898126023,-3.1478199120614
689.2000000000094,86.50369052905968,-1.6057298304063805,-3.1478199018903092
690.3000000000094,86.61650668556578,-1.6053730406175781,-3.1491250723510555
691.4000000000094,86.72689161212865,-1.6086669525308,-3.149130606089872
692.5000000000094,86.83956090322873,-1.608909872775298,-3.1501199815055823
693.6000000000095,86.95174303383472,-1.6109399088970997,-3.15013090772867
694.7000000000095,87.06388018345174,-1.6115105208292684,-3.1514398863206567
695.8000000000095,87.17584861039725,-1.611432942562363,-3.15172506613254
696.9000000000095,87.2876503096518,-1.610995045885875,-3.153071465691744
697.9000000000095,87.38944291659332,-1.6125208189046607,-3.153079954000037