File: 01_Data/Smoke_Explosion_Plywood/STA/N2/10K_min/Smoke_Explosion_Plywood_STA_N2_10KData_230803_R7.csv
##Temp./Â°C,Time/min,DSC/(mW/mg),Mass loss/mg
27.0,20.609100483359484,-2.3924325988614608,-0.16007338611726807
28.100000000000016,21.02206084555539,-2.3530793735229034,-0.16306355748187418
29.20000000000003,21.261055492075613,-2.3370685106505484,-0.1658663918918819
30.300000000000047,21.452341038596355,-2.326248090060661,-0.16455765371106024
31.400000000000063,21.6205442896897,-2.32006151000509,-0.16746395816953097
32.50000000000008,21.776073284919242,-2.3164411253838324,-0.16674708911468095
33.600000000000094,21.91713924810751,-2.315337490174242,-0.16753540717840743
34.70000000000011,22.06240768065193,-2.313602660645315,-0.16940097821972655
35.800000000000125,22.198740069339074,-2.31245162862167,-0.17068993439956381
36.90000000000014,22.32927483549504,-2.3124937654335183,-0.170439936311372
38.000000000000156,22.459221759094373,-2.3140754988835304,-0.17053525591901453
39.10000000000017,22.58681138331271,-2.316513661904027,-0.17099595652039667
40.20000000000019,22.713726899325664,-2.3175432675301026,-0.17124175562088118
41.3000000000002,22.839773280233956,-2.3198912341889506,-0.1739108392355555
42.40000000000022,22.964457649437055,-2.323773733795348,-0.17519264804686907
43.500000000000234,23.086545647548572,-2.3278209465491013,-0.17651979212144786
44.60000000000025,23.208882507916485,-2.330739286027469,-0.17915285613863619
45.700000000000266,23.32951374843509,-2.3352656199124,-0.18180010541242497
46.80000000000028,23.45083386230632,-2.3403188219693853,-0.18180045568857217
47.9000000000003,23.57124858153539,-2.344737275491761,-0.1817971293396652
49.00000000000031,23.69083131178148,-2.3493740054763057,-0.1844219872208166
50.10000000000033,23.810784869330472,-2.354299916892768,-0.1857494749234685
51.200000000000344,23.928601234385397,-2.3587786074858172,-0.1896660979323337
52.30000000000036,24.045786457389738,-2.3634882010121077,-0.19102008010475302
53.400000000000375,24.16294774987217,-2.3682230335951724,-0.19234201211886592
54.50000000000039,24.280101809966553,-2.373379653029258,-0.193659643301483
55.600000000000406,24.394941308655422,-2.377156161936581,-0.19629103460896102
56.70000000000042,24.510669058686407,-2.3816490181431194,-0.19761838985729385
57.80000000000044,24.621701713200217,-2.383719732419918,-0.20156236193620192
58.90000000000045,24.740691675358125,-2.387383673524245,-0.2041998753242753
60.00000000000047,24.854080531515187,-2.389951889297031,-0.20758104132111743
61.100000000000485,24.96701456841811,-2.3912093529166794,-0.20824974599932
62.2000000000005,25.07980021245799,-2.3913347960578424,-0.21210045063742822
63.300000000000516,25.193722449768938,-2.3914735873304394,-0.21341988770432296
64.40000000000053,25.30527507506619,-2.390551814801696,-0.21605006174907437
65.50000000000054,25.41723472890035,-2.3887013174869045,-0.21870012323784493
66.60000000000056,25.527190160640632,-2.3873714498609226,-0.2226457827920556
67.70000000000059,25.63815034583507,-2.3835395673707613,-0.2248061413036968
68.8000000000006,25.749374868615718,-2.3799265946998225,-0.22790110163941035
69.9000000000006,25.86122117091978,-2.3746952107871926,-0.23161545429874142
71.00000000000063,25.97038168734258,-2.3698864310065786,-0.23450002378024415
72.10000000000065,26.081911852667226,-2.3636012292579744,-0.2357937862354884
73.20000000000066,26.191479290328417,-2.3551324966622547,-0.2384738243510225
74.30000000000067,26.30197580917482,-2.3470678534047305,-0.23835625615965483
75.40000000000069,26.4094616271349,-2.337866667313605,-0.24136232108458167
76.50000000000071,26.520100421497983,-2.327229643032577,-0.24502978318841073
77.60000000000072,26.6297677754539,-2.315668417444831,-0.24569395676347483
78.70000000000073,26.738988448733025,-2.3066166395532166,-0.24965013159222504
79.80000000000075,26.84714796812511,-2.293981564910886,-0.25097127624940807
80.90000000000077,26.95596776248587,-2.281096489586553,-0.25360788407467627
82.00000000000078,27.064512700928645,-2.265948212075488,-0.25623030256082924
83.10000000000079,27.173534643592387,-2.253346864199225,-0.2588702643962777
84.20000000000081,27.28000000000008,-2.241740000000001,-0.26017624175209475
85.30000000000084,27.38819481713085,-2.227385242718698,-0.26151018301176654
86.40000000000084,27.4958449189048,-2.21306730289381,-0.2628197720153156
87.50000000000085,27.604099452450654,-2.1983278969162683,-0.2641267182380789
88.60000000000088,27.711992709772947,-2.184419760199759,-0.2680596861768638
89.7000000000009,27.817694457876915,-2.1710044715088266,-0.2680898919999368
90.8000000000009,27.926057259460947,-2.1554836942067706,-0.2694361387663351
91.90000000000092,28.03314202737516,-2.139735863719211,-0.26940973178839656
93.00000000000094,28.13964548048944,-2.1267611148276404,-0.27172001433745985
94.10000000000096,28.245839575495623,-2.113723239302441,-0.27303055716539015
95.20000000000097,28.352390218380766,-2.099363113230591,-0.2759737818211834
96.30000000000098,28.455400256647383,-2.0868975961337584,-0.27730564715941997
97.400000000001,28.56440313289168,-2.074268519489392,-0.2759902047185343
98.50000000000102,28.672516103562423,-2.060822099734832,-0.27499989910270806
99.60000000000103,28.778209330517385,-2.0488953175439906,-0.275649552843265
100.70000000000104,28.884423830682653,-2.035519401778509,-0.27631997812163256
101.80000000000106,28.99136868710078,-2.0248526480016786,-0.27895993778670736
102.90000000000109,29.09440463231362,-2.014593480071111,-0.2776453044696088
104.0000000000011,29.203109930365258,-2.0026598627570555,-0.2776385210654797
105.1000000000011,29.30814182835213,-1.9943662789778815,-0.2789652287276887
106.20000000000113,29.41629960214992,-1.9829451159506308,-0.2789601998331803
107.30000000000115,29.518113492003316,-1.9757220797313793,-0.27896088799354635
108.40000000000116,29.628532261363816,-1.9648704427011248,-0.2809426276077511
109.50000000000117,29.734276537015276,-1.9577429050638473,-0.2822554760263043
110.60000000000119,29.840307752470682,-1.9486271625628426,-0.2809400167622069
111.70000000000121,29.94581950453211,-1.9422034833805195,-0.28093022257007005
112.80000000000122,30.052700690450035,-1.9346028247721576,-0.28060003061091177
113.90000000000123,30.159301557050775,-1.9305123776918554,-0.28191939862230253
115.00000000000125,30.26408911883729,-1.9226229122285559,-0.28323998525751426
116.10000000000127,30.371280714253793,-1.917693351934509,-0.2819198700590686
117.20000000000128,30.47799259168404,-1.911104686394041,-0.2819212841382459
118.30000000000129,30.58381522322109,-1.9082687593748375,-0.28192246953689315
119.40000000000131,30.687201858521803,-1.9030336819290217,-0.28323970743760185
120.50000000000134,30.796275978148532,-1.8981727910568933,-0.2845499349334353
121.60000000000134,30.902323002987675,-1.8946634616458136,-0.2845499349995815
122.70000000000135,31.00794198974814,-1.8904350652463358,-0.2839005221252058
123.80000000000138,31.113716688568942,-1.8864496778807391,-0.2825798350640114
124.9000000000014,31.219045573481495,-1.8827986872366975,-0.28400983500447596
126.0000000000014,31.325796499603257,-1.8783887815556315,-0.28401360460848046
127.10000000000142,31.431520946514887,-1.8743257984908768,-0.28533136337768505
128.20000000000144,31.53828356740127,-1.8719711899087916,-0.28532981000000124
129.30000000000146,31.643447923104407,-1.8684477490519618,-0.28532980964460286
130.40000000000146,31.748658109021907,-1.8658056097546105,-0.28400982530831786
131.50000000000148,31.855432425792436,-1.8638732670697478,-0.2840101819795189
132.6000000000015,31.961396763121467,-1.8607872844989648,-0.2853143801900231
133.70000000000152,32.06635428865327,-1.8576079371274279,-0.2854431496355865
134.80000000000155,32.172127202966365,-1.854329403439014,-0.28532015550804246
135.90000000000154,32.27824445202922,-1.852512712119705,-0.2840100709161528
137.00000000000156,32.383210228427856,-1.8489803670914868,-0.28534060395721994
138.1000000000016,32.48986775330614,-1.8464676404347702,-0.2859900569986418
139.20000000000158,32.59289745776873,-1.8445996567052945,-0.28599006230822077
140.3000000000016,32.700076962029016,-1.842413658778012,-0.2846700558320068
141.40000000000163,32.80528668386496,-1.840694978166446,-0.2853300321131935
142.50000000000165,32.91159994062696,-1.8389816623313675,-0.2862877814469438
143.60000000000167,33.01713434623379,-1.8361527050772921,-0.28664003209947175
144.70000000000167,33.12129281425999,-1.8346993847066266,-0.2853205263439986
145.8000000000017,33.22885929262066,-1.8321650423049884,-0.2853200070000006
146.9000000000017,33.333330918076534,-1.8295600044038356,-0.2853200393543047
148.0000000000017,33.438444783124616,-1.8264832088182656,-0.28663761635169704
149.10000000000173,33.54388924106019,-1.824884773999536,-0.28663981823894735
150.20000000000175,33.64887517796488,-1.8234398250726798,-0.2879599993994013
151.30000000000177,33.75208713249028,-1.8218817909647194,-0.28795608091349534
152.4000000000018,33.860303855713,-1.8197703681177624,-0.2875636532387422
153.5000000000018,33.965214691982936,-1.819023482437347,-0.28795998199975026
154.6000000000018,34.071676829671986,-1.8159225310815834,-0.28914860749488636
155.70000000000184,34.17639000217767,-1.8143395132849294,-0.28927928269544667
156.80000000000183,34.282157774780195,-1.813144018235075,-0.2892699794990823
157.90000000000185,34.387072071233746,-1.8108565046257439,-0.2892699809166248
159.00000000000188,34.49120194567774,-1.810714259511998,-0.28895099799823276
160.1000000000019,34.59755388379642,-1.8079303369150617,-0.28961018600832
161.20000000000192,34.7019120786038,-1.8068218545130896,-0.28959197530658365
162.30000000000192,34.80702649807934,-1.804262912392496,-0.29091917621804697
163.40000000000194,34.91152830544442,-1.8030789589381606,-0.2909666070886545
164.50000000000196,35.017794059633225,-1.801309263528698,-0.29093018600003084
165.60000000000196,35.120594843399516,-1.8012864508435646,-0.2909301738491541
166.70000000000198,35.2268594803564,-1.798559775413173,-0.2922398837853204
167.800000000002,35.33125850664888,-1.7975177125896629,-0.29225008428253973
168.90000000000202,35.43696345055419,-1.7959995729166471,-0.2922501859999995
170.00000000000205,35.541521808469454,-1.794219130577061,-0.29225018600027175
171.10000000000204,35.645839147084615,-1.7922290978483204,-0.2931688514746109
172.20000000000206,35.75223613107788,-1.7901907284057126,-0.2935598655843097
173.3000000000021,35.85545424959848,-1.7887873249426267,-0.29486988690715243
174.40000000000208,35.96148668829979,-1.7872317302182712,-0.2944281230265564
175.5000000000021,36.06573634951389,-1.7850973550560196,-0.2948326124550573
176.60000000000213,36.17055858708894,-1.7839033651133192,-0.2948698835316965
177.70000000000215,36.275745111390094,-1.7820026897617112,-0.29449764465490524
178.80000000000217,36.38019915405929,-1.7818101590808384,-0.2962275361718998
179.90000000000217,36.484720691438994,-1.7806681309227435,-0.2975103509011827
181.0000000000022,36.590192405291305,-1.7778308135384848,-0.298829913937674
182.1000000000022,36.694426787831254,-1.776684344491814,-0.29882966487631624
183.2000000000022,36.79942514531518,-1.7750919318312033,-0.29883003881687564
184.30000000000223,36.90384622343342,-1.7744959684553485,-0.3001874129715656
185.40000000000225,37.00916251134961,-1.7736370313757355,-0.3004797829535013
186.50000000000227,37.11351971031504,-1.7710025794646393,-0.30047992425502157
187.6000000000023,37.21725857466368,-1.7698403579762836,-0.3018008062876767
188.7000000000023,37.32269748788894,-1.7687479331344966,-0.3031097722888241
189.8000000000023,37.428297878319974,-1.7666387093445914,-0.303109964498518
190.90000000000234,37.530529391944434,-1.7659498634805524,-0.3031099595854645
192.00000000000233,37.63755598493601,-1.7646337180796778,-0.3043851537817992
193.10000000000235,37.74187132441681,-1.7633706376325926,-0.3057399937330745
194.20000000000238,37.84701484676619,-1.7612857741475416,-0.3044201684687895
195.3000000000024,37.95114030955819,-1.7614894077387775,-0.3064001796319218
196.40000000000242,38.055571605334315,-1.7577390188225137,-0.30837611849775737
197.50000000000242,38.16032652043419,-1.7576233822175078,-0.3097013097791277
198.60000000000244,38.265656608380596,-1.7566453572317333,-0.3110201389947518
199.70000000000246,38.37046264864851,-1.7556264015426417,-0.31102021268203384
200.80000000000246,38.47452076614676,-1.7548711751757204,-0.31200674408830587
201.90000000000248,38.578744027605715,-1.7533722779333472,-0.31364970033146733
203.0000000000025,38.68333230364655,-1.7521903130236853,-0.31493359652162356
204.10000000000252,38.78874527968842,-1.7511919170064068,-0.31740114523499985
205.20000000000255,38.8926103376891,-1.7497053782054097,-0.31921847837695205
206.30000000000254,38.997265622009955,-1.749253806434691,-0.3187325436023909
207.40000000000256,39.103209398686175,-1.7481922885814258,-0.3199102203674169
208.5000000000026,39.206866512319046,-1.7475764358313461,-0.3213145750293167
209.60000000000258,39.311486306766184,-1.7467036913623972,-0.3238518109158197
210.7000000000026,39.41430014936414,-1.745906881662547,-0.3238613516943629
211.80000000000263,39.51909162912663,-1.7448139618409444,-0.3273943578644056
212.90000000000265,39.62617991850095,-1.74515058267512,-0.3304381147432385
214.00000000000267,39.73167421831581,-1.7438768107917182,-0.3331163097238119
215.10000000000267,39.83545058823422,-1.7446311662135785,-0.33407001057873753
216.2000000000027,39.93891244807911,-1.7432374709161622,-0.33534641470899684
217.3000000000027,40.04449540887211,-1.743406962827992,-0.3382827483154216
218.4000000000027,40.14842462585815,-1.7426547707170583,-0.34130875763126944
219.50000000000273,40.25402009160697,-1.7417835394836105,-0.3452698939374841
220.60000000000275,40.35854338941986,-1.74206547195214,-0.3465920579066939
221.70000000000277,40.462657368936014,-1.7416080826474576,-0.34808516050027816
222.8000000000028,40.56842961539418,-1.7405630294132284,-0.35074430848123805
223.9000000000028,40.67256993014127,-1.7405734695240276,-0.35471488315640043
225.0000000000028,40.777339401452444,-1.7395645931696273,-0.3560844153274072
226.10000000000284,40.882480080481066,-1.7392478049502715,-0.3599181269532452
227.20000000000283,40.98713053505263,-1.7381825208933797,-0.3633101487755255
228.30000000000285,41.092632772964045,-1.7373574860535395,-0.3677952249573697
229.40000000000288,41.19669590474656,-1.7372335705611965,-0.3714943686697598
230.5000000000029,41.30053426568284,-1.7367406410652366,-0.3742579880218182
231.60000000000292,41.405570235016384,-1.7355699923583385,-0.37687476459091407
232.70000000000292,41.51050301532553,-1.7341066487235435,-0.3809428605974392
233.80000000000294,41.61447106330361,-1.73378900068611,-0.38424809915906843
234.90000000000296,41.71683387962875,-1.733602772797442,-0.3894871241420934
236.00000000000296,41.82456806719415,-1.7324109024064864,-0.3935750457573799
237.10000000000298,41.9288503090446,-1.7314890685122108,-0.39685035719888484
238.200000000003,42.033127751383205,-1.729429356052795,-0.4005929237701227
239.30000000000302,42.13795845843075,-1.728852127652551,-0.4052748489478408
240.40000000000305,42.24298365684734,-1.7269493031061982,-0.4106867943835555
241.50000000000304,42.34646356147877,-1.7274901110346217,-0.412659406838928
242.60000000000306,42.4527288316853,-1.7262111625082854,-0.4189370272912676
243.7000000000031,42.55657768709306,-1.7238230047535155,-0.4226676660729711
244.80000000000308,42.65984620775684,-1.7232804197320024,-0.4277947214586497
245.9000000000031,42.765539548826645,-1.721476212462914,-0.4331171181028952
247.00000000000313,42.87002137767703,-1.720053324179915,-0.43766505653468846
248.10000000000315,42.97574373267754,-1.7184712752100508,-0.44417110238646496
249.20000000000317,43.079667058215655,-1.7176083239810536,-0.44792021481514466
250.30000000000317,43.18408286490885,-1.71718033276374,-0.4553489306052749
251.4000000000032,43.289617049586155,-1.7152454468799476,-0.4588473190132363
252.5000000000032,43.393827388496234,-1.7148119918044962,-0.4650299562885847
253.6000000000032,43.49835671088203,-1.7144885201637055,-0.4694033252361516
254.70000000000323,43.603187609434045,-1.7129655388490845,-0.4775737947306893
255.80000000000325,43.708946941189296,-1.7108981441424918,-0.48314813193998507
256.9000000000033,43.81251321900365,-1.7097163058097566,-0.4886785177910262
258.0000000000033,43.917752404121195,-1.7056528507743387,-0.49495040081937436
259.1000000000033,44.02199775237486,-1.7036014461916533,-0.5025439002708487
260.20000000000334,44.127999221167194,-1.7020995901237848,-0.5093069149459049
261.30000000000337,44.232139741596235,-1.7012206289388878,-0.5174723054958164
262.40000000000333,44.336767996501166,-1.6993389287234697,-0.5233554430530374
263.50000000000335,44.44171753522311,-1.6986846495386778,-0.5314933951509184
264.6000000000034,44.546865753542505,-1.6973449111751033,-0.5405809196746398
265.7000000000034,44.65081569932026,-1.6958111624345156,-0.5504380763138532
266.8000000000034,44.75559278633609,-1.69384543223966,-0.5603714363957892
267.9000000000034,44.85910869293834,-1.6914717522937652,-0.5689194736553276
269.0000000000034,44.96572907863078,-1.6898621230245237,-0.5763252100536493
270.10000000000343,45.069566736725136,-1.6900258708395681,-0.5852358978201688
271.20000000000346,45.1749158797456,-1.6880854835574886,-0.5944536166047478
272.3000000000035,45.27938097377864,-1.687340747392128,-0.6040663026310571
273.4000000000035,45.38254577093293,-1.6859240935664528,-0.6130038521907593
274.5000000000035,45.48948353690658,-1.6851735515699695,-0.6241712089542424
275.60000000000355,45.59407849314652,-1.6828108221635347,-0.6349916761654941
276.70000000000357,45.70009852966857,-1.681840838122032,-0.6469557378406625
277.8000000000036,45.80390115987337,-1.6801103568313083,-0.6565575783689832
278.9000000000036,45.9087303133987,-1.6801149203323642,-0.6689953497265702
280.0000000000036,46.014934953562175,-1.6784018447714917,-0.680639543257211
281.1000000000036,46.11910784420599,-1.6769094828430833,-0.6944880060930645
282.2000000000036,46.22514959747441,-1.6743145582186267,-0.7065818366189136
283.30000000000365,46.33009210852978,-1.6737699561003125,-0.7195832820321701
284.4000000000037,46.43520531634421,-1.6719429800481567,-0.7339438641281935
285.5000000000037,46.54017989249776,-1.6718974523296624,-0.7477437880412499
286.60000000000366,46.64491002985386,-1.66934642638619,-0.7621315854015105
287.7000000000037,46.74998017611699,-1.6686048320233438,-0.7788291989455369
288.8000000000037,46.854797962441566,-1.6667438964624202,-0.7946371164064625
289.90000000000373,46.96017711409498,-1.6652338963090856,-0.8113462793228208
291.00000000000375,47.06570174926983,-1.6650939771769127,-0.8278059441047638
292.1000000000038,47.170749425208484,-1.6645332013098946,-0.8442590785190802
293.2000000000038,47.27691288815046,-1.665376469257331,-0.8623944674528388
294.3000000000038,47.381109667503,-1.6626129355604877,-0.8805426660602538
295.40000000000384,47.4866710274133,-1.662409981729332,-0.8995602010627133
296.5000000000038,47.589620111281086,-1.6631006518381712,-0.9169560110517612
297.60000000000383,47.69706007650822,-1.6628846546721796,-0.9357089765949782
298.70000000000385,47.80171044976123,-1.6631911711137255,-0.9559239981931875
299.8000000000039,47.90870572228393,-1.6638561123600386,-0.9765638487326642
300.9000000000039,48.0127880688148,-1.664655395979467,-0.9963739384343944
302.0000000000039,48.118273845174244,-1.6629924022488658,-1.0180851042297872
303.10000000000394,48.22406223584887,-1.6620871981333527,-1.0402992234304582
304.2000000000039,48.32743181497843,-1.663157482885764,-1.061763671106743
305.30000000000393,48.4327537778679,-1.6637786198993731,-1.0831080482464346
306.40000000000396,48.53982493127506,-1.6642835673588054,-1.1074611916872148
307.500000000004,48.645738338660614,-1.662560330438277,-1.1310352141424782
308.600000000004,48.75120189345901,-1.664176705559539,-1.1536087988417716
309.700000000004,48.8563543404405,-1.6636070172964015,-1.177953307645713
310.80000000000405,48.962068239864934,-1.6630927584854895,-1.2027266795918012
311.90000000000407,49.067932922285344,-1.6615673670479336,-1.2276783067558958
313.0000000000041,49.17333000000039,-1.660490000000046,-1.2537301115557495
314.10000000000406,49.279088971790685,-1.6608595153592203,-1.2783625925433344
315.2000000000041,49.38447457002956,-1.6606143525838701,-1.305473903732199
316.3000000000041,49.48991866949009,-1.6586320720940462,-1.3339403559215546
317.4000000000041,49.59579984232237,-1.6567150336483645,-1.3626664455543915
318.50000000000415,49.701101222232204,-1.6539249154433848,-1.39062956923338
319.6000000000042,49.80727465271069,-1.6511317018236547,-1.4172377443572208
320.7000000000042,49.91325047857842,-1.650710251256345,-1.4492276238066863
321.80000000000416,50.01863983851795,-1.6483389614978745,-1.4766357472308806
322.9000000000042,50.12510148934701,-1.6440506631566005,-1.5053305446768634
324.0000000000042,50.23014990780177,-1.6416868154941096,-1.534220114474266
325.10000000000423,50.33485202804548,-1.638318411848147,-1.5613805567129675
326.20000000000425,50.44220531657595,-1.6333253312552996,-1.5928678457232737
327.3000000000043,50.54757865486736,-1.629093457616857,-1.6212757366636241
328.4000000000043,50.65413803945531,-1.6254580917543855,-1.6514032087281443
329.5000000000043,50.76030465265235,-1.6218386382008352,-1.6804256135843332
330.60000000000434,50.86533296981953,-1.6177628486575253,-1.7093463264243387
331.7000000000043,50.97024368102898,-1.6120132544441705,-1.741548089781507
332.80000000000433,51.07772677081725,-1.6093869549108495,-1.7702269039359542
333.90000000000435,51.18485575976523,-1.6066800693015595,-1.7983221802415876
335.0000000000044,51.29071054235127,-1.602167786200597,-1.8285954324450904
336.1000000000044,51.39686312329381,-1.598554158720598,-1.857752673356008
337.2000000000044,51.5026982885844,-1.593944094470496,-1.8855341523535118
338.30000000000445,51.60937698925811,-1.5868979752158527,-1.9158514203098838
339.4000000000044,51.71545805591832,-1.5839962539990915,-1.9443908217122825
340.50000000000443,51.82047006674889,-1.5804628357038968,-1.9738242004518343
341.60000000000446,51.92803259206659,-1.5754262303778164,-2.003162485921689
342.7000000000045,52.03412793727849,-1.570284252000102,-2.0312200320233584
343.8000000000045,52.14019620311914,-1.565700638826862,-2.060145286794672
344.9000000000045,52.24617717415737,-1.562591509982961,-2.088053990551672
346.00000000000455,52.35239309998445,-1.5559558824826674,-2.114501523359807
347.10000000000457,52.45968839677798,-1.5515562437670452,-2.1440870699464334
348.2000000000046,52.56516620438472,-1.5444079084189641,-2.170555240652736
349.30000000000456,52.67185591830416,-1.5393728470608585,-2.197730657557592
350.4000000000046,52.778151043492734,-1.5328760389010374,-2.2230888086149903
351.5000000000046,52.88309103389761,-1.5260569217118793,-2.250277703710239
352.6000000000046,52.98970789899356,-1.5185277634397634,-2.27422226684849
353.70000000000465,53.09593246421285,-1.5111504946129923,-2.2990841404631013
354.8000000000047,53.202799903923854,-1.503852194519666,-2.323839902842664
355.9000000000047,53.30820260499987,-1.4968441910434882,-2.345543991608685
357.00000000000466,53.4141755623538,-1.4858695510161952,-2.3676602468538577
358.1000000000047,53.520291629216025,-1.4771620793788367,-2.3901510331320326
359.2000000000047,53.62556931791974,-1.4695890030331755,-2.4116896352377113
360.30000000000473,53.73238365601664,-1.4604542947198051,-2.431566188686972
361.40000000000475,53.83775107078249,-1.451958339992958,-2.4517993270629237
362.5000000000048,53.944344007608514,-1.4428781292661785,-2.4680011836687963
363.6000000000048,54.050316938863716,-1.4349809569151442,-2.4859504650037776
364.7000000000048,54.156701197823764,-1.4267930961789064,-2.5023594361081267
365.80000000000484,54.262736034072354,-1.4187535060537715,-2.5172993778509287
366.9000000000048,54.368702224446125,-1.4135156342269655,-2.5318101622016593
368.00000000000483,54.47515280249144,-1.4077609292366386,-2.5437117027518514
369.10000000000485,54.58204847398752,-1.4036046601901635,-2.5559847925071457
370.2000000000049,54.68753030348409,-1.4016279437505363,-2.5671761719176036
371.3000000000049,54.79451714725558,-1.3987867628172026,-2.577979155231141
372.4000000000049,54.9010296012226,-1.3977374920241985,-2.5865351786480275
373.50000000000495,55.007633221692416,-1.3984636371697101,-2.5953355627124015
374.6000000000049,55.11448216613665,-1.3976151169759514,-2.603772144082028
375.70000000000493,55.221156027665025,-1.3979486929975766,-2.6114777513031875
376.80000000000496,55.32749223983025,-1.4007987189778186,-2.619986477864318
377.900000000005,55.43408640698026,-1.3995607938478278,-2.6276136227291307
379.000000000005,55.54133781485869,-1.4019600513620498,-2.6328462762728075
380.100000000005,55.64759463452771,-1.3992203409388289,-2.6393281324900526
381.20000000000505,55.755498581250336,-1.398057273660136,-2.644890701946636
382.30000000000507,55.860377897208906,-1.3947580081472821,-2.6490761694498968
383.4000000000051,55.96724389211293,-1.3903606102647676,-2.655250706738773
384.50000000000506,56.07466348511891,-1.386736050174655,-2.659790005947216
385.6000000000051,56.1801108468784,-1.3837361796968506,-2.662899197265414
386.7000000000051,56.28785694821607,-1.3801970017015024,-2.669048438261486
387.8000000000051,56.39607970203801,-1.375167793151646,-2.673557360295251
388.90000000000515,56.50314876479439,-1.3724714168016579,-2.677935210526434
390.0000000000052,56.60993447687487,-1.3690235825599975,-2.6822118807606383
391.1000000000052,56.716745679052345,-1.3647241354062818,-2.687143440778649
392.20000000000516,56.8244195863186,-1.362606183489315,-2.6910043292999726
393.3000000000052,56.93151552848568,-1.361166717469,-2.695420236068278
394.4000000000052,57.0383043088318,-1.3585923489253742,-2.699786306315183
395.50000000000523,57.145806744861986,-1.357123798724406,-2.7034395793355226
396.60000000000525,57.25376827018559,-1.355881753181086,-2.706623999191916
397.7000000000053,57.36049747230461,-1.355314720092664,-2.7115926405153963
398.8000000000053,57.46906457855744,-1.3548887068837032,-2.7166299261858136
399.9000000000053,57.57582860021129,-1.3529507709411446,-2.7204882851763896
401.00000000000534,57.683739350956685,-1.3540487174980873,-2.7228250997769456
402.1000000000053,57.79127672915228,-1.353483988013108,-2.728615041277292
403.20000000000533,57.89951940793875,-1.3535629343914304,-2.733497381133448
404.30000000000535,58.0058727543375,-1.356988419073329,-2.738035187334476
405.4000000000054,58.1137339006738,-1.3603235324684744,-2.7426106991610166
406.5000000000054,58.221494535825606,-1.3625131690814443,-2.746916511591545
407.6000000000054,58.329464016689904,-1.3662448879505817,-2.752324123748182
408.70000000000545,58.43682459321466,-1.370120242293483,-2.754883181759589
409.8000000000054,58.54415518638105,-1.3737832053988686,-2.7579696931580897
410.90000000000543,58.65208413533614,-1.3808976240070912,-2.7621476655295067
412.00000000000546,58.75814138430609,-1.3870399166881626,-2.764926216191986
413.1000000000055,58.8668785126563,-1.3907916742686104,-2.767876536775192
414.2000000000055,58.974645413178706,-1.395387289767288,-2.772527627315723
415.3000000000055,59.08169060716917,-1.3974366408368843,-2.7766227511790698
416.40000000000555,59.18982071083728,-1.4015149916731984,-2.779670720893079
417.50000000000557,59.29461786645384,-1.404313471651201,-2.78356612613439
418.6000000000056,59.4054564445442,-1.4069752956952557,-2.78849251628947
419.70000000000556,59.5128779329216,-1.411064819115794,-2.7911257441286947
420.8000000000056,59.61979856361836,-1.414515167440669,-2.7953121713305835
421.9000000000056,59.72706881817386,-1.420917967486203,-2.800899406095871
423.0000000000056,59.83540618326889,-1.4287782831653177,-2.8038463569532928
424.10000000000565,59.943749477073595,-1.4365464617742023,-2.8063908612915
425.2000000000057,60.05033541613003,-1.4440936087242653,-2.8099398142223455
426.3000000000057,60.157935595243366,-1.448452033140283,-2.8120321731821516
427.40000000000566,60.26651481483261,-1.4537998941809718,-2.814849298979528
428.5000000000057,60.374335027237834,-1.4584565365252733,-2.8195325626681536
429.6000000000057,60.482538050097865,-1.4621898289061677,-2.8238162355394536
430.70000000000573,60.590051980403636,-1.4661122000428226,-2.8265884491061852
431.80000000000575,60.69797361377628,-1.4707252828217612,-2.8279111144585727
432.9000000000058,60.80563829739884,-1.477256226863156,-2.8318417070880764
434.0000000000058,60.91401645567707,-1.4806692028079373,-2.8361677409126225
435.1000000000058,61.02244466502608,-1.4845556786259118,-2.83772716279909
436.20000000000584,61.12977584932553,-1.4846808793583954,-2.842939162172663
437.3000000000058,61.238676957101795,-1.4872778292833324,-2.8442796530634893
438.40000000000583,61.346457018654135,-1.4891642480463219,-2.845898772370849
439.50000000000585,61.45354011515697,-1.4928066880848447,-2.850086865649001
440.6000000000059,61.563529430027074,-1.4937963395234,-2.852927192112082
441.7000000000059,61.670518729283245,-1.4932865650687945,-2.855702356341401
442.8000000000059,61.78067464148081,-1.4939747804344161,-2.8574390859268823
443.90000000000595,61.88902278142467,-1.4955513817279962,-2.861336480775155
445.0000000000059,61.9974286834209,-1.4958820242616335,-2.863450335665622
446.10000000000593,62.10487310636555,-1.4983542310070104,-2.8666517888424004
447.20000000000596,62.214516894125985,-1.4978752552610795,-2.8693217180756507
448.300000000006,62.322666919320575,-1.4971643058469881,-2.8706097046846475
449.400000000006,62.43098912502381,-1.4979244423229119,-2.872704037867825
450.500000000006,62.54039353032569,-1.497370292368343,-2.875989988267732
451.60000000000605,62.648514565513175,-1.4939700128519147,-2.8774299657509745
452.70000000000607,62.7573087596115,-1.4932724169342768,-2.879748002447764
453.8000000000061,62.86587210156702,-1.4928168688494363,-2.882250481447399
454.90000000000606,62.97442747649868,-1.4907469385900876,-2.8848822275429393
456.0000000000061,63.082316668871634,-1.4902439567158192,-2.8876929020420654
457.1000000000061,63.19177151284571,-1.4909853063616654,-2.890601253780747
458.2000000000061,63.299909960489515,-1.487905617987389,-2.8919089056966722
459.30000000000615,63.406473691268346,-1.4863857149408681,-2.892877171444457
460.4000000000062,63.51740900233098,-1.484296509739637,-2.896202316238366
461.5000000000062,63.62482576770858,-1.4832078686168249,-2.8987220175389243
462.60000000000616,63.73495069517266,-1.4828262603619222,-2.901483201683826
463.7000000000062,63.84359404214336,-1.481860702238235,-2.904121545223898
464.8000000000062,63.95221572372592,-1.479672178113095,-2.905460166821748
465.90000000000623,64.06153343652979,-1.4780852550317725,-2.9081597201913807
467.00000000000625,64.17035058885284,-1.4792741163639098,-2.908157594414079
468.1000000000063,64.27980897053354,-1.476845125187234,-2.91079993115041
469.2000000000063,64.38866294509297,-1.477124398897435,-2.9134793916399007
470.3000000000063,64.49780124998273,-1.4742161673710672,-2.9149246361243533
471.40000000000634,64.60550869420625,-1.4745276432512417,-2.917500164405008
472.5000000000063,64.71649460093322,-1.472860671844874,-2.918809897858507
473.60000000000633,64.82548769755385,-1.471246826728435,-2.920366820931704
474.70000000000636,64.93487530056741,-1.468628362135877,-2.9221065705142815
475.8000000000064,65.04366283049296,-1.4680660595395805,-2.924742335265491
476.9000000000064,65.15243861127378,-1.4654388916332284,-2.9260611134990437
478.0000000000064,65.26029601734392,-1.463882350809957,-2.9280690816156216
479.10000000000645,65.36997007833305,-1.4620951320682158,-2.9295988362984975
480.2000000000064,65.47980944982275,-1.4612330400171474,-2.9319799687519907
481.30000000000643,65.5856648608609,-1.456859092738298,-2.933297308598048
482.40000000000646,65.69773601361261,-1.456142707658009,-2.933654064552212
483.5000000000065,65.80711935262137,-1.4535771523315195,-2.9352799716487965
484.6000000000065,65.91493051535572,-1.4507927495933062,-2.936579853930035
485.7000000000065,66.02483683342618,-1.4483499416453312,-2.9392714755527067
486.80000000000655,66.13333088089148,-1.4462300201919978,-2.940549870420697
487.90000000000657,66.24158608996227,-1.443374829486814,-2.942632568782261
489.0000000000066,66.35180303054605,-1.4385473034653387,-2.9448048879104087
490.10000000000656,66.46171596727375,-1.4351514401053171,-2.9479288125350696
491.2000000000066,66.57022489602896,-1.42963831859996,-2.947899462805422
492.3000000000066,66.6793777292839,-1.4227880889419338,-2.947899030957744
493.4000000000066,66.78874766987178,-1.4172815245978339,-2.949220170491454
494.50000000000665,66.89707290355753,-1.4125529890136768,-2.949550533632862
495.6000000000067,67.00686300115684,-1.4077467206771062,-2.9521876312590054
496.7000000000067,67.11675241462065,-1.4040703143560613,-2.9548237437240714
497.80000000000666,67.22548730867446,-1.3977965962514087,-2.9553394567868163
498.9000000000067,67.33479722866939,-1.3946888623722873,-2.957460084013986
500.0000000000067,67.44487996899124,-1.3923612074391118,-2.958770194184007
501.10000000000673,67.55277526301848,-1.3899653641318745,-2.9597582834046885
502.20000000000675,67.66336627715047,-1.3873315102912633,-2.961079649694903
503.3000000000068,67.7733309078247,-1.3861000252497107,-2.962389976334733
504.4000000000068,67.88356668318288,-1.3811100499896694,-2.9630424234936585
505.5000000000068,67.99333000000065,-1.379529999999935,-2.965704722544233
506.60000000000684,68.10184986420099,-1.376498442003366,-2.968331550665205
507.7000000000068,68.21152388719776,-1.3771738621824137,-2.9683092554293333
508.80000000000683,68.31857861523031,-1.3759603630788502,-2.9696417749182036
509.90000000000686,68.43042270488418,-1.3758288364980005,-2.970959872143198
511.0000000000069,68.53947540894251,-1.376885619302131,-2.9722541443740624
512.100000000007,68.64961046517881,-1.3722475247270656,-2.9742943987582953
513.2000000000069,68.75990593171929,-1.373376269027046,-2.9755580278012443
514.300000000007,68.86883363201535,-1.3737946885859325,-2.9767367704198335
515.4000000000069,68.97828053047502,-1.3741028567334752,-2.9761918633076148
516.5000000000069,69.0883110511244,-1.3749155530605794,-2.9784403057762616
517.600000000007,69.19736924721948,-1.3746911110958557,-2.9813068790827835
518.700000000007,69.30692286963395,-1.3740496899580223,-2.9814879645094265
519.800000000007,69.41638183398369,-1.3710932900681114,-2.9828053602538467
520.900000000007,69.5260775754541,-1.3715644727190635,-2.984129970774578
522.000000000007,69.63556990624762,-1.3724333234157868,-2.986168009729705
523.1000000000071,69.74633258970232,-1.373098429187735,-2.986430050908875
524.2000000000071,69.85589765439616,-1.3711374470970015,-2.987750083780897
525.300000000007,69.96569031827305,-1.370710641298535,-2.989070423915327
526.4000000000071,70.07402288048449,-1.3697827834133212,-2.9880901409368423
527.500000000007,70.18470286843174,-1.3698662671317057,-2.990705965940462
528.6000000000072,70.2950449329876,-1.3689716294945904,-2.9920170731481246
529.7000000000071,70.40495499625214,-1.3706554579828805,-2.9922527386625597
530.8000000000072,70.51343505231911,-1.3706244797925509,-2.9946703310520255
531.9000000000071,70.62524892564723,-1.3724676144500867,-2.9959943946986516
533.0000000000072,70.7349259461181,-1.3727405888536526,-2.996147521012705
534.1000000000072,70.84552938620335,-1.3745252431151085,-2.9982965533650434
535.2000000000072,70.95563139330645,-1.3768297151784847,-2.9979648107364034
536.3000000000072,71.06507569017823,-1.3780903919291312,-2.9996116010558045
537.4000000000073,71.17538506563808,-1.3791993612145297,-2.9996091848728748
538.5000000000073,71.28667000000088,-1.3803099999999435,-3.0019198095457993
539.6000000000073,71.39451100632145,-1.3795157752572789,-3.003281220828627
540.7000000000073,71.50641058003413,-1.3829175609316113,-3.003852142730567
541.8000000000073,71.6170548519697,-1.384555217021571,-3.0049898958467685
542.9000000000074,71.72717224219538,-1.3828035524241897,-3.005980926064767
544.0000000000074,71.83694523981649,-1.3838104366758832,-3.0073008879962146
545.1000000000074,71.94783137035014,-1.3877282639050286,-3.0112493004683767
546.2000000000073,72.05909914157839,-1.385038982835636,-3.00993009334205
547.3000000000073,72.16897401933423,-1.388814252412623,-3.011253220716849
548.4000000000074,72.27862568861437,-1.3915198467328196,-3.009869157832612
549.5000000000074,72.38996787040166,-1.39269241335462,-3.011234799078257
550.6000000000074,72.50000201414645,-1.3956399972304185,-3.0138798869676497
551.7000000000074,72.60918093026184,-1.3964716355188274,-3.01522601522592
552.8000000000075,72.71898113020653,-1.3979302831105804,-3.0151937618731295
553.9000000000075,72.83053806982295,-1.3969627428581852,-3.016832110707896
555.0000000000075,72.94085683683043,-1.3987731421121907,-3.0181618932410825
556.1000000000075,73.05142438564113,-1.3997002853930252,-3.018160058989594
557.2000000000075,73.16167215704174,-1.4032065629262351,-3.0194841209574266
558.3000000000076,73.27202211461326,-1.402035052846566,-3.0207901838270765
559.4000000000076,73.38158525144206,-1.403832153728771,-3.0221111175333206
560.5000000000076,73.4925319557259,-1.4055745888321312,-3.0231099347302397
561.6000000000076,73.60319406040769,-1.4077607895138944,-3.024429876022494
562.7000000000077,73.7142477075009,-1.409683580187381,-3.0244268131833105
563.8000000000077,73.8227544107884,-1.410262539162809,-3.0244203171413524
564.9000000000076,73.93464438931588,-1.4112628962731377,-3.0270618297224576
566.0000000000076,74.04364650362135,-1.4137919826234244,-3.0270600176245646
567.1000000000076,74.15485096492327,-1.4150143988123487,-3.029700037410092
568.2000000000077,74.26476716468997,-1.417710938450964,-3.031009992054227
569.3000000000077,74.37722761774344,-1.4196565564073322,-3.0323302962399667
570.4000000000077,74.48852664949467,-1.4220775462015198,-3.033007083585569
571.5000000000077,74.59907333291692,-1.4235256693625167,-3.034290941857641
572.6000000000078,74.70974596311859,-1.4245655616192503,-3.0345279432847403
573.7000000000078,74.82156137174638,-1.4284670692203856,-3.0345868452466664
574.8000000000078,74.93230689502981,-1.430178751806788,-3.0349747278444466
575.9000000000078,75.04281658701495,-1.4325831149574915,-3.0362742502894178
577.0000000000078,75.15403220247853,-1.436177277365408,-3.0362799649993217
578.1000000000079,75.26528793633005,-1.4386149876895784,-3.037611711764546
579.2000000000079,75.37520483654289,-1.44064701833802,-3.0389100978648234
580.3000000000079,75.48697435862009,-1.4411244858119505,-3.0402297955080972
581.4000000000078,75.59810031964871,-1.4424700206981265,-3.0405529251443775
582.5000000000078,75.70889739641247,-1.4442325354802772,-3.0415654328981407
583.6000000000079,75.81910644031487,-1.4454758225896465,-3.041539881569012
584.7000000000079,75.93042309920564,-1.44832749455843,-3.0428597948576592
585.8000000000079,76.04044812873751,-1.4495359662015435,-3.044179940390037
586.9000000000079,76.15194832299294,-1.4515155424845094,-3.044190127923073
588.000000000008,76.2639156528373,-1.4530012045524798,-3.0441899180010075
589.100000000008,76.37506371891037,-1.455877208637352,-3.0454818189710466
590.200000000008,76.48644169330835,-1.4548560941412372,-3.0455000179833416
591.300000000008,76.59709061996887,-1.4569068853862541,-3.046820331884891
592.400000000008,76.70961201584097,-1.4617043414211837,-3.0478177476948685
593.5000000000081,76.82020301833113,-1.463982656128223,-3.049138198230574
594.6000000000081,76.93205927744775,-1.4666836258636253,-3.0491300930000182
595.7000000000081,77.04291560424774,-1.4708797280377268,-3.049092212756176
596.8000000000081,77.15502457436531,-1.472663936607863,-3.0503150376141583
597.9000000000082,77.26574690614109,-1.4757152141919012,-3.0507698234191327
599.0000000000082,77.3761783606792,-1.4765611424408058,-3.0520898443239295
600.1000000000081,77.48934398897353,-1.481471677237716,-3.0534098640724854
601.2000000000081,77.59896471876638,-1.4822988482519874,-3.0547199437653787
602.3000000000081,77.71127915251327,-1.486374971295839,-3.054719971373059
603.4000000000082,77.821036587305,-1.4903592084270079,-3.05603996135031
604.5000000000082,77.93305261959009,-1.4918726951672479,-3.0573600324492043
605.6000000000082,78.0442404523082,-1.4965768260031747,-3.0586800467506885
606.7000000000082,78.15482793628783,-1.5015122216486774,-3.0586795756128886
607.8000000000083,78.26617315226392,-1.5068684167022794,-3.05965339804503
608.9000000000083,78.37659119337799,-1.5102884338641336,-3.058670146032315
610.0000000000083,78.48731013749486,-1.5117299109564704,-3.059349929850741
611.1000000000083,78.59829464307062,-1.5137292353618652,-3.060925752511753
612.2000000000083,78.7102243112983,-1.5157597518854673,-3.0610323951255607
613.3000000000084,78.81978519775431,-1.517833348321787,-3.0609799887266447
614.4000000000084,78.9323822579722,-1.5207777264750604,-3.062299602943673
615.5000000000084,79.04265429867998,-1.5228631769178205,-3.0636099235382384
616.6000000000083,79.15432315781669,-1.5258183066325164,-3.0649299205620437
617.7000000000083,79.2647742851289,-1.53072770670447,-3.0637734650406396
618.8000000000084,79.37691283119001,-1.534864318173519,-3.064270160027114
619.9000000000084,79.48765042677769,-1.5379508446619576,-3.064930134154329
621.0000000000084,79.59890607339453,-1.540085096811009,-3.066240054895023
622.1000000000084,79.70991078231033,-1.5413043378915767,-3.0662142919989868
623.2000000000085,79.8216963984847,-1.5459960324373399,-3.067560098998005
624.3000000000085,79.9337623859211,-1.5502021279635554,-3.068878876274393
625.4000000000085,80.04387880398174,-1.5543965375372197,-3.0702042135233403
626.5000000000085,80.15602975586685,-1.5573612494314653,-3.070199846880899
627.6000000000085,80.26697737419559,-1.5614390315371667,-3.070199852140259
628.7000000000086,80.3779392299802,-1.5647777071465327,-3.0715213714989114
629.8000000000086,80.48904956522681,-1.5686798374886775,-3.0715198948022064
630.9000000000086,80.60035730870808,-1.5741899733683382,-3.071849898991187
632.0000000000086,80.71227795788278,-1.5788324573995953,-3.0715206861006195
633.1000000000087,80.82241479386488,-1.5822562111812097,-3.0715198783098296
634.2000000000087,80.9334219831608,-1.585849540344477,-3.0715200832299754
635.3000000000086,81.04550135657179,-1.58756146252178,-3.072830018949888
636.4000000000086,81.15751025784981,-1.5917676773428089,-3.07415005252843
637.5000000000086,81.26873428760875,-1.595273981751788,-3.0754700543501565
638.6000000000087,81.38040289736554,-1.5987185242696433,-3.0754700770013836
639.7000000000087,81.4908262301876,-1.6010544993110467,-3.0767871501425477
640.8000000000087,81.6017551036963,-1.6055261083118304,-3.0755203744162087
641.9000000000087,81.71438213580161,-1.6071849794151465,-3.0767798056760367
643.0000000000088,81.82622233651847,-1.612832458335256,-3.0774400177743124
644.1000000000088,81.93819045674832,-1.61494357319841,-3.0780904993009672
645.2000000000088,82.04913072013835,-1.6187677762883506,-3.078099559685191
646.3000000000088,82.16106101390348,-1.6210713814500253,-3.0794006422203424
647.4000000000088,82.27267202513107,-1.6275752525457248,-3.0790725063225763
648.5000000000089,82.38441469694138,-1.6273252452656959,-3.0813365008682476
649.6000000000089,82.4957099658876,-1.6320937375205609,-3.0813999799815295
650.7000000000089,82.60756144034143,-1.6350699337320767,-3.080080340078335
651.8000000000088,82.7183690839871,-1.6390696307198565,-3.082391488492801
652.9000000000088,82.8307691237892,-1.6420342818831015,-3.0830496989023786
654.0000000000089,82.94178900916432,-1.6437905906644048,-3.083053466411261
655.1000000000089,83.05312202501773,-1.6462140149986557,-3.0837098395945093
656.2000000000089,83.16460320646156,-1.650758842531311,-3.083709834658535
657.3000000000089,83.27629510255453,-1.6523636823629635,-3.0853918391572357
658.400000000009,83.387600431879,-1.6557729268243966,-3.087068879236665
659.500000000009,83.49990383385851,-1.656307429085244,-3.0863401800001027
660.600000000009,83.61067307553073,-1.6606508260954216,-3.0872055967136616
661.700000000009,83.72252055369773,-1.6621867582356622,-3.0886749264903544
662.800000000009,83.83455750529158,-1.6646723914344086,-3.08864108080638
663.9000000000091,83.94333909698622,-1.6667150986220232,-3.0896195109309197
665.0000000000091,84.05616862939605,-1.6691926500964782,-3.0892999330675965
666.1000000000091,84.16801833404075,-1.6704824253088424,-3.088622860425878
667.2000000000091,84.27959110387634,-1.671136002144651,-3.0899612305527455
668.3000000000092,84.39057015745871,-1.6747437589542225,-3.0925999643131283
669.4000000000092,84.50257342493867,-1.678391997321065,-3.0919401955393693
670.5000000000091,84.61464753291912,-1.677774806930772,-3.091940065733125
671.6000000000091,84.72633488125679,-1.6822667193786307,-3.093501497845624
672.7000000000091,84.83770674262615,-1.68401547246576,-3.092920108000014
673.8000000000092,84.9498345194013,-1.6869392918078998,-3.092920107999998
674.9000000000092,85.06081928351502,-1.687349939476976,-3.092922821805455
676.0000000000092,85.17185618282888,-1.6888160499378975,-3.09390021581844
677.1000000000092,85.28265508269477,-1.6892632514108137,-3.093918607625935
678.2000000000093,85.39467109126636,-1.690822054398213,-3.095230223980524
679.3000000000093,85.50656207702184,-1.6949914022091241,-3.093260157698519
680.4000000000093,85.61888256910142,-1.6959841197392307,-3.0955598343221564
681.5000000000093,85.7290250663664,-1.7001805975899824,-3.0972133616531603
682.6000000000093,85.8413192934484,-1.699722924210683,-3.0958898540878526
683.7000000000094,85.95273142614371,-1.7036284617766344,-3.0972102695406116
684.8000000000094,86.0636399999624,-1.7053468969667545,-3.0985299379507767
685.9000000000094,86.17593308774151,-1.7045119005245883,-3.0984984997282217
687.0000000000093,86.28779718592753,-1.7072758871536846,-3.0998400359951455
688.1000000000093,86.40020870994262,-1.708394467862024,-3.0985192265365606
689.2000000000094,86.51155065028384,-1.7010463989131313,-3.0998400536945456
690.3000000000094,86.62392774174796,-1.6950141557214098,-3.099840068414278
691.4000000000094,86.73544794119589,-1.6873424877955419,-3.099507313684714
692.5000000000094,86.84676824517858,-1.6821003032320134,-3.0998401047745507
693.6000000000095,86.95862654047896,-1.6792879405073347,-3.101160104472606
694.7000000000095,87.06974547847409,-1.6723315897615374,-3.1024698125348675
695.8000000000095,87.18158983109133,-1.6717967855508207,-3.10247472076034
696.9000000000095,87.2932372793938,-1.668292721557733,-3.1037898412704097
697.0000000000095,87.30302473210192,-1.6675417360705365,-3.103790143450954