File: 01_Data/Bamboo_Rug_Bamboo/STA/N2/3K_min/Bamboo_Rug_Bamboo_STA_N2_3KData_220121_R1.csv
##Temp./Â°C,Time/min,DSC/(mW/mg),Mass loss/mg
51.0,11.349385976281676,0.0355774271037943,-0.017938562299013583
52.20000000000002,11.91628143957698,0.04866474640066587,-0.016458043284290902
53.400000000000034,12.402564213220204,0.05258806915218561,-0.016460075583497158
54.60000000000005,12.858031995174663,0.05511840855669781,-0.01844021985450528
55.80000000000007,13.298572291017216,0.05785682131915004,-0.018745569238027393
57.000000000000085,13.739796149150576,0.05865057030499621,-0.018717001837004865
58.2000000000001,14.169479635193643,0.057620097112328406,-0.018761570294461904
59.40000000000012,14.598792365990306,0.06031072127744852,-0.019747156357311724
60.600000000000136,15.01583000000004,0.06275029032619461,-0.018550010230960368
61.80000000000015,15.435474553502416,0.06695428315034846,-0.01856168629780175
63.00000000000017,15.839776992117784,0.06679885452655743,-0.018575833222594262
64.20000000000019,16.25360705528466,0.0681879737147566,-0.019767129537849648
65.4000000000002,16.6736335031486,0.06609978759028345,-0.02149376231800737
66.60000000000022,17.074122613917083,0.0691065043812441,-0.0213528445408544
67.80000000000024,17.47855704910491,0.07012154161784678,-0.021828575440831166
69.00000000000026,17.876813615440042,0.0709223961843024,-0.022070148074396112
70.20000000000027,18.276046477088823,0.0686723192370916,-0.02348073049400501
71.40000000000029,18.685116295737927,0.0677566908887135,-0.02180602815392252
72.6000000000003,19.095204124209804,0.0663850606407862,-0.023786906127179375
73.80000000000032,19.495815928765982,0.06441565711201913,-0.02512648196202516
75.00000000000034,19.902968201439016,0.06472012029019258,-0.023819198200833558
76.20000000000036,20.309996318818474,0.06282791365724205,-0.024843957461894828
77.40000000000038,20.712487753151805,0.06085277339975448,-0.02511267186058408
78.60000000000039,21.10970767037343,0.06136549330830421,-0.02580300792211876
79.80000000000041,21.508629586657722,0.05974535176157536,-0.02689986944760836
81.00000000000043,21.91399891281603,0.06106816353462863,-0.026110570703408165
82.20000000000044,22.31284580599592,0.05946559799799156,-0.028171980823780363
83.40000000000046,22.707494037649074,0.05773964953539901,-0.025777244286607992
84.60000000000048,23.110961594145035,0.05883050728569561,-0.028653280021486704
85.8000000000005,23.518957860198142,0.055150283766574715,-0.029281338067673968
87.00000000000051,23.91554778242703,0.05456178365798803,-0.028655555018018752
88.20000000000053,24.31550690809187,0.05420963825586633,-0.030050965498147342
89.40000000000055,24.720452963402337,0.05364810831864819,-0.028436338920948767
90.60000000000056,25.120280321575414,0.05222335198663042,-0.029451473871755063
91.80000000000058,25.515526366933067,0.05329004007997995,-0.02873136544895738
93.0000000000006,25.923610313510494,0.05639182062459169,-0.02867472727763154
94.20000000000061,26.308597140560657,0.05347180720729372,-0.028732329111028854
95.40000000000063,26.7096108969032,0.05190294365202397,-0.028734012725962987
96.60000000000065,27.106515839606644,0.052441868664398705,-0.03037360633814945
97.80000000000067,27.503234926626984,0.05381125604494019,-0.030390835452883902
99.00000000000068,27.901252696435762,0.05362469157201799,-0.029949768497972595
100.2000000000007,28.304583497831086,0.05168542458569725,-0.031038756660639155
101.40000000000072,28.702111808178117,0.05341199395719887,-0.03072114545773763
102.60000000000073,29.10028469805178,0.05526990248608199,-0.030720098000003304
103.80000000000075,29.500008756671352,0.05376462242103974,-0.031376461514672105
105.00000000000077,29.89358441034279,0.053335724022355535,-0.03169863079174551
106.20000000000078,30.29038400522893,0.05492425928418476,-0.031698265570678785
107.4000000000008,30.679722029577754,0.052875334301051846,-0.033349927206079766
108.60000000000082,31.07642843853763,0.05534140478259886,-0.03264297417924267
109.80000000000084,31.479901147778286,0.05437650154940399,-0.03333713024469809
111.00000000000085,31.877925738755586,0.05409623846560985,-0.033347470215333797
112.20000000000087,32.27241119791373,0.055920907168129474,-0.032028118748929746
113.40000000000089,32.670734350974776,0.058094938104465865,-0.03203961815824652
114.6000000000009,33.065083082995756,0.05629286533988409,-0.03236016193731306
115.80000000000092,33.46063675952985,0.057086879399037116,-0.0323493883536452
117.00000000000094,33.85463552354122,0.05534115624786673,-0.03433938967054928
118.20000000000095,34.25309624985265,0.057681815196913844,-0.03433819331352961
119.40000000000097,34.65138853972197,0.05830582990909461,-0.03371438344767208
120.60000000000099,35.042850575411734,0.05903896742512116,-0.03468658376564626
121.800000000001,35.43522532852644,0.061914715098804196,-0.03465513347789795
123.00000000000102,35.828658353568784,0.060684314113006455,-0.0349863464781226
124.20000000000104,36.225398095310126,0.0594190015986108,-0.034935283386927196
125.40000000000106,36.62027224531078,0.05832165069459394,-0.03467926941876076
126.60000000000107,37.01509039054006,0.05963684414697845,-0.03403438611885212
127.80000000000109,37.41080347587024,0.059366069058082616,-0.0334282902242089
129.0000000000011,37.81088221997209,0.05842709513653588,-0.03403905990947331
130.20000000000113,38.205076790603485,0.0627145128419847,-0.03599225331633793
131.40000000000114,38.59562532031709,0.05954769775572066,-0.03532341219490398
132.60000000000116,38.996838254013454,0.058710996880676936,-0.036639950027935075
133.80000000000118,39.39422330220669,0.06054145247153442,-0.03729857806418302
135.0000000000012,39.78901096356856,0.06083015320688834,-0.03729995768310124
136.2000000000012,40.1806188486524,0.06219685711450618,-0.038280050633443974
137.40000000000123,40.56382575289444,0.06292789145781763,-0.038279949630978916
138.60000000000124,40.96905822572704,0.0645930519334651,-0.0403490620505762
139.80000000000126,41.36175749594647,0.06595333161090366,-0.03831244268394496
141.00000000000128,41.7566466733333,0.06271216443192518,-0.03828634139918563
142.2000000000013,42.15044563656278,0.06472154535178598,-0.03929489166789191
143.4000000000013,42.540365339128954,0.06529257092342688,-0.03830742182157021
144.60000000000133,42.93126838067218,0.06557591551739916,-0.03998152620683815
145.80000000000135,43.31924280214693,0.06562309980744108,-0.04092009999746926
147.00000000000136,43.71241805040968,0.0674255604061218,-0.041571704217351346
148.20000000000138,44.10459598950584,0.06672125227623238,-0.04125876244343951
149.4000000000014,44.50581167296453,0.06400782737788224,-0.0422992099860342
150.60000000000142,44.89831259733883,0.06633169413754236,-0.042780139620967716
151.80000000000143,45.29060225285033,0.06790379740626185,-0.04410051734251974
153.00000000000145,45.68611433785111,0.06719858028532133,-0.04410014233698112
154.20000000000147,46.07552259210907,0.06560451484475238,-0.04575096661580469
155.40000000000148,46.47212075220817,0.06846952168749054,-0.046414952049924185
156.6000000000015,46.859988497857685,0.06822312875736214,-0.04670176485904953
157.80000000000152,47.25159065648516,0.06738617333222385,-0.04674874900517123
159.00000000000153,47.65141151306669,0.06901390724630507,-0.047498050625646826
160.20000000000155,48.04213074682508,0.07126581321331094,-0.048708439176734064
161.40000000000157,48.43449220869919,0.07431854145251049,-0.05002940383449772
162.6000000000016,48.821769448048094,0.07278111157796219,-0.05021215933324763
163.8000000000016,49.213923932910646,0.072767148582909,-0.05060917917736685
165.00000000000162,49.61328782394468,0.07169847308679611,-0.05167008313022814
166.20000000000164,50.000541753153215,0.07449330274113397,-0.053692034649625686
167.40000000000165,50.39083003736597,0.07519151434020788,-0.0536401931303403
168.60000000000167,50.78422477586759,0.07610073749736523,-0.05494990988776838
169.8000000000017,51.1709625704575,0.0740617032921056,-0.05486938207302838
171.0000000000017,51.559837719468476,0.07709074433812813,-0.05559391153659554
172.20000000000172,51.95494863547133,0.07448603467039383,-0.056929676485524716
173.40000000000174,52.34760653323523,0.07336319060776386,-0.05825313476910354
174.60000000000176,52.73675630951895,0.07585878073966656,-0.058883305851986645
175.80000000000177,53.128847142291086,0.07714988275404644,-0.06090577717352108
177.0000000000018,53.52821485409002,0.07814096117694802,-0.06188387498534187
178.2000000000018,53.90937544399253,0.08018455548267045,-0.06351012997568839
179.40000000000182,54.301546961007325,0.08275200932129767,-0.06498005917383276
180.60000000000184,54.691288158087644,0.08127389136016305,-0.06610401543961064
181.80000000000186,55.08193885167141,0.08298856742840222,-0.06734121698739726
183.00000000000188,55.47219001759837,0.0817521599116996,-0.06898117540337445
184.2000000000019,55.86426428004887,0.08396837842445515,-0.07196128007259261
185.4000000000019,56.254634741627804,0.08553111990681506,-0.0719992934021838
186.60000000000193,56.639325182226266,0.08622286281492475,-0.07425925546583567
187.80000000000194,57.02921517926727,0.08935628303115434,-0.07557002050296635
189.00000000000196,57.418115680436,0.08753836244068602,-0.07821017279055065
190.20000000000198,57.81081817820661,0.09005947700530975,-0.07918983224908605
191.400000000002,58.20054956535879,0.09058251242224968,-0.08115927263906908
192.600000000002,58.59337386389045,0.09057198235673569,-0.08256515272278042
193.80000000000203,58.983640191998994,0.09172313538004884,-0.08637106018911966
195.00000000000205,59.34858129986097,0.09139700190120631,-0.08777756489147315
196.20000000000206,59.76008744066867,0.09130699792590691,-0.09039024911347537
197.40000000000208,60.1501381213219,0.09305553514233283,-0.09174954562798066
198.6000000000021,60.540052988404746,0.09272599842729001,-0.09400986614364282
199.80000000000211,60.92745623001347,0.09073420741898769,-0.0976123489716283
201.00000000000213,61.31619120734387,0.09220039928252288,-0.10057987938388502
202.20000000000215,61.70989693825895,0.09282880507534663,-0.10322030591860898
203.40000000000217,62.1028496845946,0.09381745887405524,-0.10485380050558613
204.60000000000218,62.49517773579915,0.09408588714818905,-0.10754620975601403
205.8000000000022,62.886035666515234,0.09342094729600703,-0.11045920467656911
207.00000000000222,63.27456425004461,0.09588122792776166,-0.11084080251277362
208.20000000000223,63.66552335164912,0.09274725102753345,-0.1130943272220577
209.40000000000225,64.05400019388217,0.0972596903296255,-0.11969070770642798
210.60000000000227,64.44758146252366,0.09679003035493977,-0.12188676896501249
211.80000000000229,64.83644199823867,0.09807049268243523,-0.12463989052663349
213.0000000000023,65.22400688426946,0.09600819404184541,-0.1290213176066528
214.20000000000232,65.61419975832972,0.09501801510433755,-0.13114696140642934
215.40000000000234,66.00516349756204,0.09760690676357864,-0.13451214606536288
216.60000000000235,66.39761430703524,0.09588656067729823,-0.13841466237392552
217.80000000000237,66.78895140015982,0.09434626550276104,-0.14176438523220902
219.0000000000024,67.17553913795376,0.09024054741903875,-0.14567122397020738
220.2000000000024,67.57093949671844,0.09094868790424582,-0.149945284871424
221.40000000000242,67.958025199824,0.09414318877563455,-0.15446925495937958
222.60000000000244,68.34297450964796,0.09279264036432505,-0.1577677684227332
223.80000000000246,68.72957978329345,0.09130504545718504,-0.16179088110529305
225.00000000000247,69.12274518244192,0.08892235368826484,-0.1660522828023998
226.2000000000025,69.5151136067441,0.09211018298738877,-0.17064797669340104
227.4000000000025,69.90122168257169,0.08893734598059427,-0.17492412837950022
228.60000000000252,70.27290651753232,0.08898841516517425,-0.1802133964701551
229.80000000000254,70.67979618463056,0.09155970488267051,-0.18733314584031158
231.00000000000256,71.06685889997392,0.0910739473640903,-0.19146158260008939
232.20000000000258,71.45647945696282,0.09060914641427759,-0.19699201676952693
233.4000000000026,71.84947325091866,0.09009531550077371,-0.2026195716841448
234.6000000000026,72.23468782655296,0.08752215749050002,-0.20945366172526114
235.80000000000263,72.62379806043602,0.08719180942359539,-0.2159147470301397
237.00000000000264,73.01299636392774,0.08949710857417187,-0.22523501614492325
238.20000000000266,73.4036552160371,0.08968047682202007,-0.2330866072175466
239.40000000000268,73.79072023015742,0.08931041944619766,-0.24341888148098434
240.6000000000027,74.18388528845047,0.08906186394989873,-0.250121408230906
241.8000000000027,74.57088743457552,0.09346403978380752,-0.2599262154959119
243.00000000000273,74.95888008159649,0.09342603350478879,-0.2702960609927172
244.20000000000275,75.34850702013067,0.09172654931196955,-0.27911777100272017
245.40000000000276,75.74238842188433,0.09011997792971638,-0.28979781231795076
246.60000000000278,76.13788520047822,0.08828454358194998,-0.3020459706006755
247.8000000000028,76.52843253087259,0.0919389331701197,-0.31237581177031526
249.0000000000028,76.91641587845214,0.09570576827169003,-0.3248889721238193
250.20000000000283,77.30314390475837,0.09725973529465737,-0.33663315731334764
251.40000000000285,77.68802436880713,0.10031895754745529,-0.3484036865769493
252.60000000000286,78.07620263923947,0.09599735116371533,-0.3614709530822431
253.80000000000288,78.46177490896093,0.09701744007755359,-0.37512843354401415
255.0000000000029,78.85316315428705,0.10300217588884253,-0.3894506103866018
256.2000000000029,79.24482773471735,0.09691299321824232,-0.40604488768255065
257.40000000000293,79.63075012907379,0.09061975513496001,-0.42166288289074716
258.600000000003,80.02119320580854,0.09233730315380045,-0.4384694935961648
259.80000000000297,80.4065137209347,0.09164843934160932,-0.4550880658613443
261.00000000000296,80.79632539530428,0.09125209999566081,-0.47210734898822926
262.200000000003,81.18370739771002,0.0908379757569493,-0.4893932677510122
263.40000000000305,81.57197327689327,0.08853009630233938,-0.5074528192983205
264.60000000000304,81.95972668813907,0.08503172117158453,-0.5262424345111829
265.800000000003,82.34991962335062,0.08077300935414661,-0.5448321240038854
267.00000000000307,82.74474751680386,0.08214003372399253,-0.5656102346747058
268.2000000000031,83.13898663240002,0.08436665686510153,-0.5850489450465561
269.4000000000031,83.52656891485212,0.08382993948893641,-0.6052707353520699
270.6000000000031,83.91959342319164,0.08050984918871462,-0.6262204272384082
271.80000000000314,84.3055150830234,0.08617465452791256,-0.648970081217028
273.0000000000032,84.68732859762548,0.08540339875937092,-0.669904352982218
274.2000000000032,85.07748498694846,0.08535165669565148,-0.6928070506777071
275.40000000000316,85.46812128497038,0.08535303944233452,-0.7139398048469383
276.6000000000032,85.86142053290574,0.08534761431476451,-0.7386879788020972
277.80000000000325,86.25155028168675,0.08450779338280312,-0.7621119223492561
279.00000000000324,86.64093810458385,0.08610054955763613,-0.7860187508147534
280.20000000000323,87.02240348111926,0.08591655819545857,-0.8108223989664141
281.4000000000033,87.41012280132719,0.08900162957689828,-0.8353968604737916
282.6000000000033,87.80136660929087,0.08645950070374753,-0.8600225965769375
283.8000000000033,88.1935696481431,0.08303565986095515,-0.8854698871701583
285.0000000000033,88.58717434605272,0.08397778629051325,-0.9104272174043766
286.20000000000334,88.97798411407535,0.08389935214931193,-0.9355727841394312
287.4000000000034,89.37234418117716,0.0882242992095186,-0.9620605916081937
288.6000000000034,89.76116655790904,0.08665450840871322,-0.9859595865003872
289.80000000000337,90.15334326175805,0.08653416038078021,-1.0120115957012135
291.0000000000034,90.5472436142848,0.08472337499377983,-1.0394893491608554
292.20000000000346,90.93939761211374,0.0842482097596361,-1.0634661187873258
293.40000000000344,91.347631377295,0.08198464349724338,-1.0904383587852409
294.60000000000343,91.75089444552508,0.08276791845648834,-1.116718554252495
295.8000000000035,92.14807124015931,0.08673824239613906,-1.1453582105883129
297.0000000000035,92.5486534377873,0.08872719633030257,-1.171042508270494
298.2000000000035,92.94169269295155,0.09072733600657537,-1.197092567528316
299.4000000000035,93.32863618463688,0.09214388475450577,-1.221957780726056
300.60000000000355,93.71649656645246,0.09711442061998421,-1.2490766633767483
301.8000000000036,94.1049606094853,0.09634337789518463,-1.2731841869026832
303.0000000000036,94.49763630277089,0.09623219525379917,-1.30024426514106
304.20000000000357,94.89013776634009,0.09332303484768806,-1.3276218842459269
305.4000000000036,95.28003993635481,0.09866411743875886,-1.3545110516997108
306.60000000000366,95.6725638485269,0.09969600383945301,-1.3811814831172269
307.80000000000365,96.06238796986575,0.10007296565457713,-1.407792595887924
309.00000000000364,96.44470752201259,0.1017811040466498,-1.4341032474730833
310.2000000000037,96.84236972105418,0.1011506879089297,-1.4622738265952098
311.40000000000373,97.23841042477893,0.10651768040618403,-1.490392246484244
312.6000000000037,97.63176633321342,0.10823970547702641,-1.5191317559366206
313.8000000000037,98.01939283888714,0.11153781337468818,-1.5478904638135442
315.00000000000375,98.41446378759366,0.11414100103302563,-1.5802275589265862
316.2000000000038,98.80207910574569,0.11430175763820528,-1.610125603254247
317.4000000000038,99.19497108386054,0.11921959137093514,-1.6406808879491717
318.6000000000038,99.58513485910521,0.11999956993168895,-1.673134924869204
319.8000000000038,99.97646334062277,0.12258122382638055,-1.7065364269952177
321.00000000000387,100.36762236420515,0.12530462839182577,-1.7411788768408671
322.20000000000385,100.75959602253413,0.1275676481876052,-1.7762669809542917
323.40000000000384,101.15444824902532,0.13059250486032695,-1.814751575912191
324.6000000000039,101.54947080360039,0.13390934364839374,-1.85207313666319
325.80000000000393,101.94439214827672,0.141155603255675,-1.8930284923721903
327.0000000000039,102.32979993653643,0.14587534410627662,-1.9328658857459482
328.2000000000039,102.72680681542899,0.14874111430234122,-1.9777183618010348
329.40000000000396,103.12024464435076,0.15649358354850193,-2.022745191999105
330.600000000004,103.5157552427753,0.16051362072981412,-2.0698906963529957
331.800000000004,103.898699136698,0.16183737887925395,-2.119506354014135
333.000000000004,104.29859189156251,0.17015528300018257,-2.175017965413466
334.200000000004,104.68887672476922,0.17307005510085005,-2.228879627264173
335.40000000000407,105.07682619730133,0.1718133926619959,-2.285806918380607
336.60000000000406,105.46965695296748,0.1692732453520951,-2.3450927412016194
337.80000000000405,105.86427541601203,0.161686008018105,-2.4017683944397508
339.0000000000041,106.26079879658292,0.1498507775961057,-2.459215776190505
340.20000000000414,106.65495524835364,0.13301654677962493,-2.513733439873037
341.4000000000041,107.0320662258104,0.11491304213346437,-2.561894819748362
342.6000000000041,107.43118476254932,0.09179054740145862,-2.6042377599672184
343.80000000000416,107.82097671779914,0.06711462660009478,-2.640365061336322
345.0000000000042,108.20849433950104,0.04661274300609196,-2.6706776739557583
346.2000000000042,108.59164209782207,0.030185069447372315,-2.6944174295390324
347.4000000000042,108.9909034171201,0.01719310227252918,-2.713292587518385
348.60000000000423,109.38393142208616,0.007087675567879009,-2.731785811800081
349.8000000000043,109.77637008409127,-0.002376091091549959,-2.7443393887102046
351.00000000000426,110.17522313821944,-0.008007451097249346,-2.7529521720026002
352.20000000000425,110.56488637600421,-0.009324666014940725,-2.7629469746806077
353.4000000000043,110.95420879392121,-0.014707536264915555,-2.771504714064771
354.60000000000434,111.35169902673364,-0.014998817401845915,-2.779476411537239
355.80000000000433,111.74276403713979,-0.017536510455341547,-2.7865736123639566
357.0000000000043,112.14122424217432,-0.01707468800896711,-2.7934097220858645
358.20000000000437,112.52911467043307,-0.016662461786081467,-2.799971495696799
359.4000000000044,112.92214642030208,-0.017531649363495994,-2.8064451277546003
360.6000000000044,113.31336943312301,-0.020474104050512573,-2.812161331897612
361.8000000000044,113.70984327534441,-0.02194469842479703,-2.8172083032345716
363.00000000000443,114.10318614113348,-0.021642998612051823,-2.8220138053194366
364.2000000000045,114.49880989015561,-0.023974393546071504,-2.826491661909607
365.40000000000447,114.88912574080366,-0.021916811924795054,-2.8304317517504147
366.60000000000446,115.28093851363006,-0.022745096195789766,-2.836734417669999
367.8000000000045,115.67755586318572,-0.026448063444814124,-2.8381414394035076
369.00000000000455,116.07056231062117,-0.028321835558032,-2.844460271671261
370.20000000000454,116.4647522743058,-0.02958939550344325,-2.84796416164892
371.4000000000045,116.86190509131599,-0.030622801134467234,-2.854612879257121
372.60000000000457,117.25746587258917,-0.030705760791809533,-2.859197051393797
373.8000000000046,117.65528564202766,-0.031030871777030497,-2.8634970223531577
375.0000000000046,118.04737106345036,-0.029417588823278898,-2.8681051307907603
376.2000000000046,118.44278029855067,-0.03303835758632781,-2.872994445970364
377.40000000000464,118.83489985991555,-0.03297844113958416,-2.8749819977867297
378.6000000000047,119.22448865799943,-0.03479192467163303,-2.8801648341265764
379.8000000000047,119.6169241040995,-0.03602943511802671,-2.88258901110759
381.00000000000466,120.01091188502589,-0.03699916999838952,-2.886574336198341
382.2000000000047,120.4060715062171,-0.038695396829717024,-2.891769030058781
383.40000000000475,120.79955483801241,-0.040029565316889684,-2.8957305156147877
384.60000000000474,121.19825520513052,-0.04299688262946387,-2.8994867356086322
385.80000000000473,121.59588025277014,-0.043577337882907415,-2.9050900264788764
387.0000000000048,121.98652305111675,-0.044085458991008276,-2.9072276579749907
388.2000000000048,122.39215633310464,-0.045774823291095224,-2.912176031934597
389.4000000000048,122.78884740212455,-0.0429685935665235,-2.9176427058281824
390.6000000000048,123.18345707174855,-0.039975061435977496,-2.9197397823233544
391.80000000000484,123.5749455520071,-0.043168381453825996,-2.923777674748688
393.0000000000049,123.97182110560642,-0.043893364711499974,-2.9277935651558975
394.2000000000049,124.3661649092992,-0.04380022111439949,-2.9299497766162785
395.40000000000487,124.76405847106057,-0.04146674337923213,-2.9342783403016535
396.6000000000049,125.15261832071633,-0.044848606583089715,-2.9382644587665254
397.80000000000496,125.54723243834694,-0.04443036207803275,-2.940790179662277
399.00000000000495,125.94390227636038,-0.045744173329913124,-2.943426075676831
400.20000000000493,126.33742648417724,-0.046911293759969136,-2.9466028858102016
401.400000000005,126.73250289722989,-0.043928292490292516,-2.9500099056795808
402.600000000005,127.12565044612904,-0.04576941432261713,-2.9526395580675877
403.800000000005,127.5251254523949,-0.04333752198043805,-2.9567742021191457
405.000000000005,127.91419675985651,-0.04442710012230541,-2.960210050697369
406.20000000000505,128.31451798559567,-0.04433394994295469,-2.9621251394904853
407.4000000000051,128.71156943739422,-0.0449175080065513,-2.9641846986444333
408.6000000000051,129.10880863613897,-0.04526467607409756,-2.9681197761986486
409.80000000000507,129.50071104192537,-0.0448317024845833,-2.9694476635812013
411.0000000000051,129.89312086595893,-0.044580263089093686,-2.9733549999460425
412.20000000000516,130.29112293555366,-0.04720542318873999,-2.9773100746516956
413.40000000000515,130.6869762214538,-0.04480253498888004,-2.979512482314794
414.60000000000514,131.08454770816195,-0.045813057244890515,-2.9835857115329696
415.8000000000052,131.47965325351774,-0.04582426582064439,-2.9862100248887007
417.00000000000523,131.88021333222295,-0.04276801929195174,-2.9888529429219823
418.2000000000052,132.27199178967456,-0.04459832833180144,-2.990819612527431
419.4000000000052,132.6687902695935,-0.04340561035352816,-2.9949554371167855
420.60000000000525,133.0588574511386,-0.043490962082555894,-2.9976891420571903
421.8000000000053,133.4553144834426,-0.04977170704849671,-3.001305980037099
423.0000000000053,133.85187793987598,-0.048078516211787846,-3.003999765089926
424.2000000000053,134.24481446280532,-0.046585688496261934,-3.0069577686083244
425.4000000000053,134.6418012139897,-0.04567024941378835,-3.0081026859245004
426.60000000000537,135.03984889654288,-0.04698953756824343,-3.010648882036886
427.80000000000535,135.4382460426164,-0.04783576614066111,-3.01374818455458
429.00000000000534,135.83479186502103,-0.04736050139799908,-3.015504859255743
430.2000000000054,136.23510270050676,-0.04550485493629772,-3.0174701526519185
431.40000000000543,136.63178362148545,-0.0419156902042811,-3.020101119711362
432.6000000000054,137.02437927501936,-0.040655446525379606,-3.0216749497947526
433.8000000000054,137.42257340857012,-0.040039863535342037,-3.0246852511817623
435.00000000000546,137.81731589944792,-0.03791556917063559,-3.027090075184037
436.2000000000055,138.20793071472693,-0.035537402227166046,-3.0286599680643564
437.4000000000055,138.60346570442832,-0.033216866619499685,-3.0317493427863984
438.6000000000055,139.0037716135626,-0.03540524629888624,-3.0322957733787694
439.8000000000055,139.40061576464717,-0.03415462706245666,-3.035906128476119
441.00000000000557,139.7977599997264,-0.028345240848796596,-3.0371688491100994
442.20000000000556,140.1988552513127,-0.02493427199297009,-3.0395210815519507
443.40000000000555,140.5934788449144,-0.022387952123657934,-3.0396205864254604
444.6000000000056,140.99164418884558,-0.0244993734698465,-3.0410472482548436
445.80000000000564,141.38639074612627,-0.0245785552065919,-3.0423621036327084
447.0000000000056,141.7813004037324,-0.026200631593051638,-3.045329683122522
448.2000000000056,142.17811056521728,-0.024206836501943843,-3.0479598087702318
449.40000000000566,142.57546779393167,-0.02695167177996148,-3.0499399034474437
450.6000000000057,142.97161073817406,-0.02807988258204673,-3.052664879931836
451.8000000000057,143.3608962659483,-0.02402828432962259,-3.0520702746188486
453.0000000000057,143.76720537870904,-0.02866023736337167,-3.0555399854558813
454.20000000000573,144.16185029404943,-0.03130708602863641,-3.0578306669653026
455.4000000000058,144.5619690814005,-0.028515756329252018,-3.0590970458961126
456.60000000000576,144.95594727578987,-0.03053331752761093,-3.0601750477413505
457.80000000000575,145.3576148590361,-0.029142656468024913,-3.063088086871952
459.0000000000058,145.75817730149168,-0.032559084275023575,-3.0644697355054866
460.20000000000584,146.1572709633337,-0.035390516636478936,-3.0647019872792916
461.40000000000583,146.56037346635807,-0.04201520580304563,-3.0673810220807467
462.6000000000058,146.96010496977493,-0.04831368764729785,-3.0687002501967653
463.80000000000587,147.35889203267288,-0.05121901491118119,-3.0713300149787726
465.0000000000059,147.7539999048289,-0.05399767751962076,-3.0721522355707362
466.2000000000059,148.1553030901072,-0.05778235120215233,-3.074608629561938
467.4000000000059,148.55342881747512,-0.0580239822986329,-3.0754751415674613
468.60000000000593,148.94947902730073,-0.05910204284389897,-3.077579810254818
469.800000000006,149.34917361854113,-0.06112871083680971,-3.079890983560194
471.00000000000597,149.74917000000227,-0.06360484837323538,-3.081201021162589
472.20000000000596,150.14497245177407,-0.06491545937213072,-3.081199455256127
473.400000000006,150.54159030489194,-0.06502505202741699,-3.0825092319694076
474.60000000000605,150.93873496609783,-0.0629472635775522,-3.0838300099983558
475.80000000000604,151.34196414350492,-0.06420147235329196,-3.085150177595095
477.000000000006,151.7416243734429,-0.06927100410806947,-3.085486366681871
478.20000000000607,152.1383055712021,-0.06676206002614568,-3.0884385955585674
479.4000000000061,152.53612327791927,-0.0704813116256166,-3.0884240629563458
480.6000000000061,152.93212599390407,-0.06957990741652464,-3.091069093528531
481.8000000000061,153.32990853353635,-0.0724680216926959,-3.0923937461831974
483.00000000000614,153.7311384915989,-0.07664598158801053,-3.0937291462353715
484.2000000000062,154.13095039191475,-0.07784264446051645,-3.0959650165919523
485.4000000000062,154.52405665735193,-0.08073626814022972,-3.0956811078882227
486.60000000000616,154.9248156197457,-0.08155877280157967,-3.096997171698281
487.8000000000062,155.324777954226,-0.08168273744105484,-3.0982754358118694
489.00000000000625,155.7276480899199,-0.0858610883322535,-3.098498414591136
490.20000000000624,156.12881024067457,-0.08637216556704178,-3.1012700608279697
491.40000000000623,156.5308720183224,-0.08845820077737024,-3.102260187901239
492.6000000000063,156.9272328215825,-0.09095547536003354,-3.104215113223629
493.8000000000063,157.32293752714915,-0.09133013784548996,-3.1052200952620725
495.0000000000063,157.72057696711073,-0.09238880756619139,-3.1061862977912065
496.2000000000063,158.1265429347831,-0.09705112789114265,-3.1085100695602845
497.40000000000634,158.5276671668108,-0.09805129843912974,-3.1085105133006903
498.6000000000064,158.91268995052963,-0.10278472363941471,-3.110602366042086
499.8000000000064,159.3199506483644,-0.102279482867871,-3.1104900479276503
501.00000000000637,159.71761782319382,-0.10337923866335572,-3.1118003301641064
502.2000000000064,160.1188982323913,-0.1064324370535506,-3.1125000275719965
503.40000000000646,160.51895931195594,-0.11003238046075803,-3.1138651991830093
504.60000000000645,160.9215358504216,-0.11047920630574248,-3.1167936454261027
505.80000000000643,161.31848355160446,-0.11502284906412799,-3.116932998365211
507.0000000000065,161.71649164313973,-0.11445719120082495,-3.1166197682074133
508.2000000000065,162.11399379706262,-0.11664580401021807,-3.119045650818552
509.4000000000065,162.51092612965897,-0.1161507824791922,-3.1169755507375307
510.6000000000065,162.91053176174796,-0.11701981152121468,-3.1193766436450443
511.80000000000655,163.30986918783944,-0.11893283467624705,-3.119040761286585
513.0000000000066,163.71834105962373,-0.12333854601877872,-3.122005286846926
514.2000000000066,164.1242754630889,-0.12026841896458604,-3.1225310290196435
515.4000000000066,164.52909844794831,-0.12107352639526675,-3.124299710759316
516.6000000000066,164.92984635962065,-0.12030757463469316,-3.124294412770758
517.8000000000067,165.32342746955555,-0.12081913865938199,-3.1246399681442485
519.0000000000066,165.72215961006705,-0.12414827073118051,-3.124852312351322
520.2000000000066,166.12291113236967,-0.12275553824578056,-3.126275213322917
521.4000000000067,166.5195055986451,-0.12022160662147247,-3.1272801328007054
522.6000000000067,166.9176046490973,-0.12115254682062276,-3.1289100996620887
523.8000000000068,167.32003977735565,-0.12358989312933749,-3.1315498228984513
525.0000000000067,167.71937692835257,-0.11920338024021854,-3.134134735150128
526.2000000000068,168.1208137178058,-0.11790383840483981,-3.132828954258967
527.4000000000068,168.52346318776276,-0.12002670981417657,-3.133189917767421
528.6000000000067,168.92616694928003,-0.11842728019146526,-3.135170574437433
529.8000000000068,169.3276700362769,-0.11945617239866851,-3.1355399143880245
531.0000000000068,169.72728529531952,-0.11754346685048617,-3.1376336480466063
532.2000000000069,170.12800084923856,-0.11744811690097184,-3.1381200849599558
533.4000000000069,170.52748951162496,-0.11952679922538828,-3.138120035970498
534.6000000000068,170.92888816183003,-0.12053044605102559,-3.139023158493648
535.8000000000069,171.32594298634643,-0.11741440315785684,-3.141750481119589
537.0000000000069,171.7260987512075,-0.11659852759401013,-3.1423905271456887
538.2000000000069,172.12730979590424,-0.11939356323979938,-3.1413518671355734
539.4000000000069,172.52688604289966,-0.11746382520529264,-3.14379248772905
540.600000000007,172.93540228699675,-0.11942997123174282,-3.145149772595314
541.800000000007,173.3393566156539,-0.1191767323157672,-3.14566081232145
543.000000000007,173.74009042333972,-0.11804293864064197,-3.1462668422438806
544.200000000007,174.14135825895912,-0.1190556265477507,-3.1473429062589577
545.400000000007,174.539744614785,-0.12079969942916302,-3.1486517914842485
546.6000000000071,174.94186352983277,-0.12240706014561087,-3.1489801753189823
547.800000000007,175.338155484176,-0.12126947470199345,-3.151618763553544
549.000000000007,175.74117898490104,-0.12165975870593704,-3.150626395373518
550.2000000000071,176.1457573244148,-0.11809891559890412,-3.151289799696916
551.4000000000071,176.54641222450138,-0.12053078406441398,-3.15260995141285
552.6000000000072,176.94503169366797,-0.12089557209485807,-3.153498132589988
553.8000000000071,177.34281886925544,-0.11604669081021513,-3.1542069884039714
555.0000000000072,177.74295610390814,-0.11270214474874607,-3.1542498543170647
556.2000000000072,178.14660804764316,-0.1132450350701043,-3.1549132658965897
557.4000000000071,178.5484355045023,-0.11398326988355156,-3.1559005827525133
558.6000000000072,178.95157345548168,-0.11693990818957473,-3.1575371147539144
559.8000000000072,179.35504739410558,-0.1166606230614225,-3.158205754877802
561.0000000000073,179.7667678172513,-0.11315447749264196,-3.158874988553829
562.2000000000073,180.1683188155723,-0.1133857555113188,-3.16013694380421
563.4000000000073,180.5669219684485,-0.1118786039304333,-3.159823865653512
564.6000000000073,180.96736299303498,-0.11339665284846046,-3.15984023998477
565.8000000000073,181.3647840640125,-0.1066129125297211,-3.1634566580480805
567.0000000000073,181.7701271643685,-0.10847144686212529,-3.1634608824002797
568.2000000000073,182.16921219355638,-0.10839616138749941,-3.163777117096142
569.4000000000074,182.57334022297695,-0.10696078681210597,-3.1634599662219602
570.6000000000074,182.97570645500045,-0.10729842511549881,-3.163780128341389
571.8000000000075,183.37442304970327,-0.1040900275625114,-3.165111616150854
573.0000000000074,183.77477613285288,-0.10319306256467836,-3.165423681976503
574.2000000000074,184.17381864500754,-0.1035975729557832,-3.165447559577997
575.4000000000075,184.57590422691922,-0.10335628259188884,-3.166591788930794
576.6000000000074,184.98111916036768,-0.10549836767186205,-3.1674121029468547
577.8000000000075,185.38176334141892,-0.10079586128707119,-3.1680610922859715
579.0000000000075,185.78616565649978,-0.10078509894211463,-3.169050194852801
580.2000000000075,186.19193939625316,-0.0998301336869577,-3.170516867494092
581.4000000000076,186.59916377669003,-0.0986766615058523,-3.1703699539960852
582.6000000000075,187.00221559163617,-0.09727742456976207,-3.170370121467129
583.8000000000076,187.40100574988884,-0.09234645654515661,-3.171689836096164
585.0000000000076,187.80144146067087,-0.09281561995401166,-3.1716898762799595
586.2000000000075,188.20372292308846,-0.09438177971742512,-3.1730100060000224
587.4000000000076,188.60578431084573,-0.09450412799391039,-3.1729869261956587
588.6000000000076,189.00891323673602,-0.0937908907874776,-3.1743153759307514
589.8000000000077,189.41482231562424,-0.08771133003684639,-3.1759144926171006
591.0000000000077,189.81671943654553,-0.08888862660049801,-3.1739894659622028
592.2000000000077,190.21954298383648,-0.09033223830293324,-3.1753099347223697
593.4000000000077,190.61968380468488,-0.09067088105338206,-3.177948395124027
594.6000000000078,191.02095164313587,-0.08732895668639151,-3.1762678322560407
595.8000000000077,191.4223040995356,-0.08644120554608203,-3.176960073430873
597.0000000000077,191.829225385484,-0.08412290129213618,-3.1766298633465766
598.2000000000078,192.22882662239934,-0.08490220947532079,-3.1769594817808193
599.4000000000078,192.64496301168214,-0.08378700084765289,-3.178180947441797
600.6000000000079,193.04833662511504,-0.08612361981334682,-3.177756364477237
601.8000000000078,193.4532015858703,-0.08318224680202813,-3.1782697928268577
603.0000000000078,193.85174400026153,-0.08383090445310237,-3.1799197320662143
604.2000000000079,194.25197246099498,-0.08054568868027645,-3.181230029655411
605.4000000000078,194.64765032735585,-0.07903734405262486,-3.1819582453925275
606.6000000000079,195.04952473446065,-0.08159852112373589,-3.183910586643807
607.8000000000079,195.45414024530143,-0.08082714288301851,-3.182549961184879
609.000000000008,195.861726354445,-0.0859879499776467,-3.1840838305061636
610.200000000008,196.2694541677965,-0.0855710826453967,-3.184174018377951
611.4000000000079,196.6772058121375,-0.08537140901357376,-3.185223705371052
612.600000000008,197.08101185388273,-0.08431761467869547,-3.1827517375231063
613.800000000008,197.47985234874218,-0.08118557652222658,-3.1855128595187465
615.000000000008,197.88176267484732,-0.08340374542375995,-3.1855100535523917
616.200000000008,198.28380586766102,-0.08043714086291331,-3.188811034044889
617.400000000008,198.68920414703285,-0.0847964829969109,-3.1888356004696714
618.6000000000081,199.09280048890875,-0.08583798675447418,-3.1874201229303347
619.8000000000081,199.49519031672213,-0.08703229377801458,-3.188751172507657
621.0000000000081,199.8974653169075,-0.08372094497595306,-3.189459990760893
622.2000000000081,200.2984848503652,-0.08111101008166122,-3.189460142000999
623.4000000000082,200.70162972638758,-0.07804196547985132,-3.1884694950292807
624.6000000000081,201.10485160121894,-0.07889669832606383,-3.1900977021841594
625.8000000000081,201.51217908256632,-0.07888377703017957,-3.1884814585317307
627.0000000000082,201.91486429635114,-0.0756352696328918,-3.189793018899477
628.2000000000082,202.31909656984422,-0.07550910123877597,-3.1910996634213715
629.4000000000083,202.72445673445094,-0.07204948205500772,-3.191089136098999
630.6000000000082,203.12683936252898,-0.06729678975589615,-3.1914294115782473
631.8000000000083,203.52687290075517,-0.0692339248005488,-3.1920898761424574
633.0000000000083,203.9276452620825,-0.06896843831983457,-3.1917606483654697
634.2000000000082,204.3308134270976,-0.06705771417755924,-3.1930699932534217
635.4000000000083,204.73496958871004,-0.07188961092231894,-3.1926991518327386
636.6000000000083,205.13983868111816,-0.07330167238686991,-3.1924200359318813
637.8000000000084,205.54512022102708,-0.07586364288504421,-3.192449026018346
639.0000000000084,205.94701216582985,-0.07136907044173968,-3.193102187989008
640.2000000000083,206.35452987190942,-0.07521905721493183,-3.194059669005882
641.4000000000084,206.76005827729313,-0.07072499934315557,-3.1963834129247624
642.6000000000084,207.1607963962413,-0.07046760131230623,-3.1963631656320572
643.8000000000084,207.5705197121279,-0.07413684006308607,-3.195709287556233
645.0000000000084,207.97259490110622,-0.07229906330918989,-3.197394177742346
646.2000000000085,208.37818985544646,-0.07399598003841323,-3.1965246578752966
647.4000000000085,208.7895807930125,-0.07362258777629627,-3.1957726151557986
648.6000000000085,209.19109493748812,-0.07343820276911783,-3.1962491460013096
649.8000000000085,209.59360295345354,-0.07424158289233296,-3.1953776443618707
651.0000000000085,209.99522826071876,-0.0716665967734973,-3.1972812234935453
652.2000000000086,210.39849340688426,-0.06972920841461716,-3.197359823984917
653.4000000000085,210.80619834903686,-0.07025553830490394,-3.1973598219999997
654.6000000000085,211.210255060024,-0.07371068751908227,-3.19604146246112
655.8000000000086,211.61126895144184,-0.06762762050623561,-3.197350259544981
657.0000000000086,212.01214016507265,-0.06931914119911764,-3.197350026548814
658.2000000000087,212.4155298654613,-0.07149305640030479,-3.197176339623311
659.4000000000086,212.81930625350057,-0.06866581364343416,-3.1986701063162446
660.6000000000087,213.23213448863626,-0.06827120035701773,-3.1993301627525383
661.8000000000087,213.63544378734096,-0.0681771027740723,-3.197987201915539
663.0000000000086,214.03706675393906,-0.06446662847046691,-3.199341231496638
664.2000000000087,214.44661551893216,-0.06717530268228267,-3.1986702557211513
665.4000000000087,214.84221160379917,-0.06605554197787777,-3.200970066850076
666.6000000000088,215.25206455155035,-0.06585731611598455,-3.201300395886081
667.8000000000088,215.65195488317502,-0.06436995668416579,-3.201301575468979
669.0000000000088,216.05544732982727,-0.06829721305845726,-3.2013001599999997
670.2000000000088,216.4613863648209,-0.07025368902979212,-3.202620193001609
671.4000000000088,216.8691133737223,-0.06784221599151707,-3.2029133964751324
672.6000000000088,217.279352647439,-0.06827525292945036,-3.2022757253515666
673.8000000000088,217.67863685370864,-0.06585440711498758,-3.2022899599691357
675.0000000000089,218.08350525845847,-0.06733490912593765,-3.2036097267697237
676.2000000000089,218.48581500378566,-0.06483583071734478,-3.204261365590655
677.400000000009,218.88616238260417,-0.06613139255124423,-3.2046099289955854
678.6000000000089,219.2878679117014,-0.06504876708477147,-3.204360170132871
679.8000000000089,219.69580083446587,-0.06849138447564806,-3.20393768821822
681.000000000009,220.10426300599585,-0.06929700633588931,-3.204589935874817
682.2000000000089,220.5134940662407,-0.07179683942704762,-3.203265799683204
683.400000000009,220.91648163125933,-0.07372130050836323,-3.203297733472781
684.600000000009,221.32052065334253,-0.07261848835301765,-3.2045900924371242
685.800000000009,221.72408861146928,-0.0689979608830793,-3.2044871598159057
687.0000000000091,222.12628968039942,-0.0676181179237858,-3.2062398739656564
688.200000000009,222.53128715600147,-0.06250204474391396,-3.207226648272659
689.4000000000091,222.9365237605423,-0.06501219237543698,-3.2063726910953783
690.6000000000091,223.34261654023095,-0.06762337996820711,-3.207219980994543
691.800000000009,223.73978507165586,-0.07103367646108971,-3.2081957549989717
693.0000000000091,224.15070144189934,-0.07646209132071768,-3.208210146689681
694.2000000000091,224.55712516694425,-0.07486665195389319,-3.2098672340797116
695.4000000000092,224.9604878126272,-0.07522940698365654,-3.2099103739336927
696.6000000000092,225.368700240886,-0.07627008351487241,-3.2088917468943756
697.8000000000092,225.77536099346526,-0.07787596328029212,-3.210836105753383
699.0000000000092,226.1822215544688,-0.07918780352341659,-3.2119401574344413
700.2000000000093,226.5854737300155,-0.0846861663696048,-3.2119398200047775
701.4000000000092,226.98752904365455,-0.07841175925470578,-3.2132338008037222
702.6000000000092,227.39462196061857,-0.08306153478306055,-3.211943400869777
703.8000000000093,227.79747654993346,-0.08822199533188702,-3.212240892981911
705.0000000000093,228.20648209912025,-0.08544311040658203,-3.211732471536553
706.2000000000094,228.61332979285743,-0.0930786872275493,-3.2139911794798186
707.4000000000093,229.01447861137225,-0.09079674885772149,-3.2152114425194283
708.6000000000093,229.4190310752245,-0.09053851191138951,-3.214579550641945
709.8000000000094,229.82392770403405,-0.09411661118948045,-3.2158993691589908
711.0000000000093,230.22759145626284,-0.09143846329353855,-3.2152399558091638
712.2000000000094,230.634766306358,-0.09386285083529544,-3.2165494987917986
713.4000000000094,231.03713851988093,-0.09918156680797496,-3.2158789909832337
714.6000000000095,231.4425328694813,-0.10311793094959776,-3.2175398307883496
715.8000000000095,231.84521602403532,-0.1043420668316899,-3.217539886108473
717.0000000000094,232.25929545687387,-0.11148621799014569,-3.218536746142929
718.2000000000095,232.67302708435108,-0.11503314163986067,-3.2188499638855825
719.4000000000095,233.0781455343931,-0.11308176072360943,-3.2183151490378443
720.6000000000095,233.4805554069563,-0.11293304098130852,-3.218494385486619
721.8000000000095,233.88324600918708,-0.11282809132129024,-3.220168076096369
723.0000000000095,234.2888011952996,-0.11831728083758408,-3.219179808003503
724.2000000000096,234.69546366805434,-0.1175507339972186,-3.2211591589872244
725.4000000000096,235.10201631566866,-0.12025066930765393,-3.2188394692272095
726.6000000000096,235.51486060227978,-0.12521344551709657,-3.2188938346034046
727.8000000000096,235.91742767601758,-0.12815126165734902,-3.219839976005417
729.0000000000097,236.32310510698457,-0.1308561747421746,-3.2208397838869716
730.2000000000096,236.72667971186422,-0.12973704888595172,-3.2198400941502454
731.4000000000096,237.1299126892675,-0.13442199353290318,-3.2198401516774164
732.6000000000097,237.53440817638898,-0.13080590839695683,-3.219510101613306
733.8000000000097,237.9426065680119,-0.1363928516945605,-3.2205145620050075
735.0000000000098,238.34817820103387,-0.13648037302174676,-3.220905246387279
736.2000000000097,238.7531796203223,-0.1391073098899107,-3.223139960656063
737.4000000000098,239.15982457259827,-0.14032686684134354,-3.2231468723773187
738.6000000000098,239.56409170057802,-0.14169611182741315,-3.2231400367112255
739.8000000000097,239.9743071103115,-0.13878770941816576,-3.2254228971132033
741.0000000000098,240.37543068199375,-0.13845959611698566,-3.2244499119991628
742.2000000000098,240.78887020736184,-0.14827759567229393,-3.2247160598879625
743.4000000000099,241.2006178471496,-0.14590652032251072,-3.225094130353683
744.6000000000099,241.60295506243827,-0.15007084531923764,-3.2244491581761676
745.8000000000098,242.01155010298913,-0.15409495904290194,-3.224439490538157
747.0000000000099,242.4108782860136,-0.15581735058599788,-3.2244819819297192
748.2000000000099,242.81825460037064,-0.1554712882002125,-3.2254398377018987
749.4000000000099,243.22322626333676,-0.15805179494903965,-3.2248031794136094
750.6000000000099,243.63107288263495,-0.15982015615273948,-3.225109880244306
751.80000000001,244.03610725978086,-0.16680836815636835,-3.225770224671654
753.00000000001,244.44237189260966,-0.16910475430291494,-3.2262819630937476
754.20000000001,244.84841400524982,-0.16784509221276678,-3.226100006000754
755.40000000001,245.25359554971422,-0.17098478733242373,-3.2270800822328534
756.60000000001,245.65774709091943,-0.1785716743187018,-3.22708008200022
757.8000000000101,246.06359628939947,-0.17696685897517783,-3.227737716230688
759.00000000001,246.46892944513047,-0.1795264119569817,-3.2287292277519275
760.20000000001,246.87762526919906,-0.1831949750952948,-3.229846226708157
761.4000000000101,247.28763469034718,-0.18422192928269032,-3.23080290351172
762.6000000000101,247.69571216962999,-0.18489625947441324,-3.2303700083643423
763.8000000000102,248.1041405739987,-0.17629738236027426,-3.229740365450925
765.0000000000101,248.51050150698558,-0.1777260474562563,-3.230275985933754
766.2000000000102,248.91100546694256,-0.18023664269505013,-3.2313602372479475
767.4000000000102,249.31262403280672,-0.18512270169007827,-3.2326753347664257
768.6000000000101,249.72450834165718,-0.1861068373142183,-3.232639404489582
769.8000000000102,250.13054886812574,-0.1888603364507324,-3.2327779598751865
771.0000000000102,250.54469810092155,-0.1882856515359843,-3.233000078306029
772.2000000000103,250.94791845370762,-0.18868710695104918,-3.2333300928611717
773.4000000000103,251.3498096846125,-0.1838277363031542,-3.232138342804255
774.6000000000103,251.75971096056418,-0.187754754112345,-3.232331557384118
775.8000000000103,252.165103891642,-0.18463533413553512,-3.2330010165918113
777.0000000000103,252.5748778975363,-0.1827905161072978,-3.2330099089557343
778.2000000000103,252.98387169444283,-0.18689142111125046,-3.2330875572588273
779.4000000000103,253.38821388623282,-0.1872817984742674,-3.234319839100521
780.6000000000104,253.80142499415905,-0.184592604569231,-3.2333401767605516
781.8000000000104,254.21319793053598,-0.18613174693903778,-3.234576671284464
783.0000000000105,254.61479315499858,-0.19333645618458828,-3.234982680945164
784.2000000000104,255.01979149898173,-0.1936042441764092,-3.234979874754852
785.4000000000104,255.42335387006227,-0.19596073916301182,-3.23498463104848
786.6000000000105,255.83280720294394,-0.19688919412475947,-3.2359567429029017
787.8000000000104,256.236081384956,-0.19851952624183355,-3.234109406315015
789.0000000000105,256.6373293460327,-0.20316662862066592,-3.234970029545131
790.2000000000105,257.048991000648,-0.20545761539888274,-3.2349107854779
791.4000000000106,257.4608865867848,-0.20900116033025262,-3.233586789264987
792.6000000000106,257.87020933265853,-0.21251906862515213,-3.234650062824734
793.8000000000105,258.2799678011701,-0.2159013090047981,-3.2349684726487045
795.0000000000106,258.68732527509525,-0.2173222937818482,-3.2346435462891656
796.2000000000106,259.09384130804364,-0.2181677471751431,-3.2363651208234603
797.4000000000106,259.49421811372605,-0.21860326522681506,-3.2362999098399845
798.0000000000106,259.69852678479066,-0.22421668931200345,-3.236283776320171