File: 01_Data/Cinder_Block/STA/N2/30K_min/Cinder_Block_STA_N2_30KData_230824_R2.csv
##Temp./Â°C,Time/min,DSC/(mW/mg),Mass loss/mg
29.0,15.639808498850805,0.03444928200138264,-0.005786709723464956
30.40000000000002,15.832166106388785,0.07186766283766355,-0.006283131612261794
31.80000000000004,15.962326878043813,0.1082340644947819,-0.006407112659670755
33.20000000000006,16.068562839100483,0.13621962287387568,-0.007166382550523931
34.60000000000008,16.160637812828227,0.15957158682942185,-0.0044115707486769296
36.0000000000001,16.243268875131577,0.1810698248640401,-0.00590849338379007
37.40000000000012,16.319302680133205,0.20177941259565113,-0.007187600143875983
38.80000000000014,16.390860006401955,0.22193209593753793,-0.008097735207259316
40.20000000000016,16.45955580007413,0.2383723393515318,-0.006002539605135748
41.60000000000018,16.524469848064065,0.2576873897768177,-0.007611719235943504
43.0000000000002,16.587454095708654,0.27246376116836335,-0.0060856182970496775
44.40000000000022,16.648258163281454,0.284031448341477,-0.005763437461286713
45.80000000000024,16.708370791479844,0.2983612911703526,-0.006581334713327003
47.20000000000026,16.766535774169324,0.3108741774683792,-0.005945703279095937
48.60000000000028,16.823055907415306,0.32630800335715815,-0.006239289860507924
50.0000000000003,16.879007378007852,0.3365843272465212,-0.007194872929374263
51.40000000000032,16.934183480033163,0.3498488692923003,-0.007233646615367295
52.80000000000034,16.98790996629354,0.3605679723590114,-0.007627687672870032
54.20000000000036,17.04193333064971,0.37377306955956957,-0.008028342271989786
55.60000000000038,17.09438195159123,0.3807030885277478,-0.009016857023230074
57.0000000000004,17.146986460520598,0.39314165976779414,-0.009439687148353748
58.40000000000042,17.198770168830603,0.4050112680111633,-0.009355919528416301
59.80000000000044,17.249932098878897,0.4144080899022018,-0.010076644399520607
61.20000000000046,17.30100957637671,0.42371863694773637,-0.009535963323173302
62.60000000000048,17.35217761431544,0.43199296561177203,-0.010832164051578275
64.0000000000005,17.401942009940402,0.44040893695817673,-0.010995477757922423
65.40000000000052,17.452085547551142,0.44864608581505117,-0.011372519549269988
66.80000000000054,17.502756048546864,0.4550435549871399,-0.01254841886743785
68.20000000000056,17.552184807239218,0.46334542723158356,-0.012521518755812977
69.60000000000058,17.601660014611273,0.4683647309739598,-0.012298530120693929
71.0000000000006,17.651231339509334,0.47401560031197354,-0.012273277575860497
72.40000000000062,17.700354603232228,0.4774614393917409,-0.012732165279466745
73.80000000000064,17.74989783818781,0.4816613661139645,-0.012806696914389626
75.20000000000066,17.798224374694033,0.48654297164551097,-0.014190916200482295
76.60000000000068,17.847083585726576,0.4879608105572787,-0.01545830849045382
78.0000000000007,17.895895482191182,0.4947510786489975,-0.01682328486472784
79.40000000000072,17.94438407243139,0.4956985363601982,-0.016794516918179347
80.80000000000074,17.99272592760385,0.4974877326450138,-0.017926674882757787
82.20000000000076,18.041401205157843,0.499009770893437,-0.01819447006875219
83.60000000000078,18.089221642324542,0.5011845382921497,-0.016714421103261934
85.0000000000008,18.13660069916325,0.5040772686141125,-0.01811010785648204
86.40000000000082,18.185004867674294,0.5062011358399705,-0.018130728615001868
87.80000000000084,18.23187501370697,0.5061452797455751,-0.019420591645293417
89.20000000000086,18.28013792819427,0.5082785092759893,-0.01806317889619491
90.60000000000088,18.327709554843274,0.5074397697619946,-0.01944988130183889
92.0000000000009,18.37510195997301,0.5098297829956241,-0.02075591278363964
93.40000000000092,18.421738385281735,0.5134833249154339,-0.019954769362813707
94.80000000000094,18.46893003427949,0.5137061700638474,-0.019810515418962282
96.20000000000095,18.516228023993964,0.5137372247744074,-0.02074983588185253
97.60000000000097,18.562876186255224,0.5147012004649699,-0.021904438152377192
99.000000000001,18.60947102164952,0.5145972231821099,-0.022070492406331965
100.40000000000101,18.656177235076953,0.5170276175624183,-0.022068833519583553
101.80000000000103,18.702573667820364,0.5152534918873307,-0.023274247753780397
103.20000000000105,18.748764938853803,0.518282963471114,-0.023390343341626263
104.60000000000107,18.795001617156373,0.5182427339874083,-0.0233892733365626
106.0000000000011,18.841026079351078,0.5189166169585921,-0.024679259595388636
107.40000000000111,18.887544341085206,0.5206629952867945,-0.023724136760403525
108.80000000000113,18.93398125691664,0.5212836638340259,-0.02371002202490935
110.20000000000115,18.980464014007453,0.5207375388064936,-0.024618431671712848
111.60000000000117,19.025416633850213,0.5196263607494419,-0.025027657573931883
113.0000000000012,19.072250734243585,0.5226739060358373,-0.026336947200362726
114.40000000000121,19.117856190077585,0.5243113318391742,-0.026341944685925434
115.80000000000123,19.164545866989627,0.5239719522546101,-0.026017472502500638
117.20000000000125,19.210063465987673,0.5241270317473131,-0.026020148143053312
118.60000000000127,19.25592744836385,0.5235600116368082,-0.026020147959139983
120.0000000000013,19.301335626556746,0.5262478870827837,-0.026020105832676776
121.40000000000131,19.347086064487513,0.5277429825129765,-0.026042024125692897
122.80000000000133,19.392185546562132,0.5278431345576687,-0.027342172651603658
124.20000000000135,19.438182461959705,0.5267834074895033,-0.0273401240283091
125.60000000000137,19.483387941732648,0.5273644918580336,-0.027338506237791993
127.00000000000139,19.52841690731192,0.526052607677744,-0.028697847376823127
128.4000000000014,19.57380716477944,0.5270962609245514,-0.028650061768745072
129.80000000000143,19.618932620557327,0.5271068724432801,-0.02863646749970794
131.20000000000147,19.66430558756103,0.5286143937582811,-0.027332039883610548
132.60000000000147,19.708748847967083,0.5286924978309853,-0.028349700824791935
134.00000000000148,19.753506490965393,0.528838685827772,-0.029967662793356276
135.4000000000015,19.798412813413695,0.5299182449474338,-0.02997014628847916
136.80000000000155,19.842903949302798,0.5287971837502254,-0.02997025008993326
138.20000000000155,19.887286971743684,0.5287643472035275,-0.029919136728178586
139.60000000000156,19.93187305100616,0.5306046594736906,-0.03128926288500189
141.0000000000016,19.976205545969535,0.5310203317001954,-0.03129027967227982
142.40000000000163,20.02040884540846,0.5327803335922818,-0.03128343424156199
143.80000000000163,20.064805490666764,0.5318865647758692,-0.032608307964786754
145.20000000000164,20.10799145860755,0.5314698680330585,-0.03261011592700935
146.60000000000167,20.152803405745185,0.531529216479754,-0.03282246441461867
148.0000000000017,20.197167913816866,0.5321823148171461,-0.03392872031780936
149.4000000000017,20.241231189299274,0.5313777004071949,-0.03393172888003315
150.80000000000172,20.284643134830976,0.533179429731663,-0.032634009286304444
152.20000000000175,20.328769614911135,0.535359872356365,-0.03261017823563783
153.60000000000178,20.37242586660699,0.533774677037262,-0.03261002004435509
155.0000000000018,20.416504418310353,0.5326382955145218,-0.032560264263875816
156.4000000000018,20.460464323691586,0.5353584937105456,-0.03393194083226314
157.80000000000183,20.504155192435157,0.5329300094727307,-0.034502319841552165
159.20000000000186,20.54771540867255,0.5348911833196003,-0.03523920139905545
160.60000000000187,20.591364660398682,0.533724062591685,-0.035240013167733064
162.00000000000188,20.63477237579016,0.5350966221179742,-0.03524045552502475
163.4000000000019,20.678147363359415,0.5338634800053398,-0.03549429889282596
164.80000000000194,20.721813517402296,0.5374372555424203,-0.035807280422015086
166.20000000000195,20.765166275081874,0.5369971175717896,-0.03722039238423047
167.60000000000196,20.809010411569414,0.5372133682551412,-0.03722543326399608
169.000000000002,20.852473643278575,0.5354926098398394,-0.0359173854349093
170.40000000000202,20.89606736290547,0.5366022066302447,-0.03590013381210522
171.80000000000203,20.939504189294976,0.5355561161411754,-0.03590014782264106
173.20000000000203,20.982320703853944,0.5374751561100805,-0.03590013581338569
174.60000000000207,21.026273709364816,0.5372433266036948,-0.035895064264945375
176.0000000000021,21.069313625478337,0.5359292628584521,-0.0365676873351366
177.4000000000021,21.113107298973418,0.53691423271143,-0.03772192487366777
178.80000000000211,21.15567268376805,0.5373374404934326,-0.03883334149176054
180.20000000000215,21.19879372764849,0.535392049033099,-0.03885995066367087
181.60000000000218,21.242272726922238,0.5383493392798584,-0.038859984202304076
183.0000000000022,21.285222205116625,0.5370701173408123,-0.038859984001209824
184.4000000000022,21.328150730074256,0.5366739664647063,-0.038859984000002346
185.80000000000223,21.371182942949357,0.5370706195221329,-0.038859984000000125
187.20000000000226,21.414154691588163,0.5378896842604788,-0.038859984000000125
188.60000000000227,21.45640822133618,0.537681125906446,-0.03885998399999924
190.00000000000227,21.499881931282644,0.5377659834403301,-0.03885998399997259
191.4000000000023,21.54256074240156,0.5370991307739866,-0.03885998413178582
192.80000000000234,21.58518753182842,0.537192143371466,-0.03886003526547732
194.20000000000235,21.627933049844803,0.5374093365201938,-0.03886838500096923
195.60000000000235,21.67073467747796,0.5392687353004437,-0.03919086782878134
197.0000000000024,21.71363162818819,0.5367503732484944,-0.03918986579917938
198.40000000000242,21.756128822032352,0.5376552828629613,-0.03918995374053669
199.80000000000243,21.79771968451266,0.5390392257648,-0.03922953615049751
201.20000000000243,21.841117930912844,0.5376050546776425,-0.037878256476135075
202.60000000000247,21.883565235601292,0.5401731047753253,-0.037870121801443446
204.0000000000025,21.92599328739525,0.5401303511646314,-0.03916750234458721
205.4000000000025,21.96877395096274,0.5427205362496149,-0.039189727223794435
206.8000000000025,22.01163363844467,0.541962003367152,-0.03918985165026534
208.20000000000255,22.05399193005528,0.5437770661508835,-0.039189834498760234
209.60000000000258,22.096589365700208,0.5416384061073007,-0.039185665556798366
211.0000000000026,22.138809526198287,0.543889511994749,-0.04016682273698047
212.4000000000026,22.18142115171217,0.5420314661223343,-0.040217077545598556
213.80000000000263,22.224111189937098,0.5453326795022077,-0.04052919185584525
215.20000000000266,22.265988274407597,0.5455338985697149,-0.04116885055935571
216.60000000000267,22.309041166840856,0.5424184786331008,-0.04117011004260007
218.00000000000267,22.351550988489233,0.5439032821402968,-0.04117013444717976
219.4000000000027,22.39395899362468,0.545613124332893,-0.04117066340541342
220.80000000000274,22.436300613741153,0.5430149623622427,-0.04041547242753385
222.20000000000275,22.478644930823393,0.5446501944677807,-0.04116989036733498
223.60000000000275,22.520954738839645,0.5480442312176634,-0.041169982928279225
225.00000000000279,22.56310331756432,0.5456157325337014,-0.04116998398931804
226.40000000000282,22.60575336098295,0.5481040169288436,-0.04117001492377437
227.80000000000283,22.647754986905323,0.5506779645639178,-0.04118244457587794
229.20000000000283,22.69036842481317,0.5484923718006858,-0.042521601347514704
230.60000000000286,22.732571544484802,0.5495027065944049,-0.04249001609628378
232.0000000000029,22.775046265648516,0.5489571975673844,-0.04248329169932008
233.4000000000029,22.817228533970532,0.5489340405354937,-0.04378551378064177
234.8000000000029,22.859428238901867,0.5517074565672222,-0.043888887484516914
236.20000000000294,22.90186923515241,0.549594672194957,-0.041823260994289235
237.60000000000298,22.94402641333769,0.5520122787197872,-0.04182992444495515
239.00000000000298,22.98628096339171,0.5528236737935492,-0.04182284661458269
240.400000000003,23.028653827673097,0.5537371878424087,-0.043143180891684896
241.80000000000302,23.07094770961168,0.5537792961162384,-0.043149869059786905
243.20000000000306,23.113146658132784,0.5543946395373612,-0.04314985226734924
244.60000000000306,23.15546240618746,0.5531219641251498,-0.04314987581731433
246.00000000000307,23.197379250505207,0.5564739944338243,-0.04315353898960872
247.4000000000031,23.2398517389759,0.5560153178493213,-0.04218204382414603
248.80000000000314,23.282035517545125,0.5574884347083513,-0.042123099464772995
250.20000000000314,23.324311815292454,0.5575850171603647,-0.04347739238289661
251.60000000000315,23.366197104811985,0.5605571610718771,-0.04347984186743492
253.00000000000318,23.408686374462018,0.5597884655321823,-0.04347985198316273
254.40000000000322,23.450542097147714,0.5593760591333339,-0.04347985198169724
255.80000000000322,23.493033451232915,0.5591039471188856,-0.04347982885026802
257.20000000000323,23.53551460533329,0.5606674653906514,-0.043472558179184606
258.60000000000326,23.577650226709803,0.5619409851220262,-0.044778057260273396
260.0000000000033,23.619512119860598,0.562756027661506,-0.044789813789427146
261.4000000000033,23.661998743263013,0.5623914610436744,-0.04478981804705473
262.8000000000033,23.70350564669316,0.5622952541649844,-0.04479086683067246
264.20000000000334,23.745811222385015,0.5627786388457229,-0.04397401496854414
265.6000000000034,23.788678464447216,0.5603058047004923,-0.043800247725507724
267.0000000000034,23.830492788687703,0.5622631566393197,-0.04396043806923222
268.4000000000034,23.8731810789476,0.5619891863621933,-0.045119552305421085
269.8000000000034,23.91512645584183,0.5631388512548277,-0.0451198109299753
271.20000000000346,23.957108866792915,0.5647256446504039,-0.04511981994809622
272.60000000000343,23.999358496845694,0.5633166720443328,-0.04511981999983661
274.00000000000347,24.041616659925932,0.5652773964536291,-0.04511982000039971
275.4000000000035,24.083685995072205,0.5654094722850234,-0.04511982018933214
276.80000000000354,24.126028588267395,0.5678657962825384,-0.045119868485850034
278.20000000000357,24.16848987736423,0.5663430766729772,-0.04512598977340243
279.60000000000355,24.210773083636493,0.5686716131727634,-0.04545108902412931
281.0000000000036,24.252646842970908,0.5680873634405297,-0.045450110204763305
282.4000000000036,24.29475213596779,0.56877975395078,-0.04546601650421023
283.8000000000036,24.33761269889898,0.5704111318990748,-0.04511547681556394
285.2000000000036,24.37993875073119,0.5709621913851084,-0.045450282784092355
286.60000000000366,24.421943763130987,0.5712454107667004,-0.04544991414126143
288.0000000000037,24.464680594445568,0.5728736329074785,-0.04544995402542362
289.40000000000373,24.506761812777185,0.5722777869391068,-0.04545044765368145
290.8000000000037,24.548907902142133,0.5716590884834738,-0.04573506970879837
292.20000000000374,24.591225092307205,0.5720475796039257,-0.04610977799801308
293.6000000000038,24.633793315205114,0.5720205423928804,-0.04611008137150652
295.00000000000375,24.676013472076978,0.5726858864624893,-0.046110083988176065
296.4000000000038,24.718524953038113,0.5734792910155203,-0.046110083923214695
297.8000000000038,24.760865891643704,0.5733691897700208,-0.04611009492011675
299.20000000000385,24.803608738840474,0.5757694305776544,-0.046120888672626315
300.6000000000039,24.84555398100574,0.5760558308317338,-0.04762023360607692
302.00000000000387,24.888063041739013,0.5752998426469678,-0.04875302042056395
303.4000000000039,24.930485270067194,0.5745899414958027,-0.048749894139024974
304.80000000000393,24.973196872245797,0.5743543341448183,-0.048751190890967244
306.2000000000039,25.015562675903407,0.5754336147448011,-0.047445058362281856
307.60000000000394,25.05809254370771,0.5764289318975822,-0.04743440195686199
309.000000000004,25.100272894517108,0.5739743172414269,-0.04612503433672854
310.400000000004,25.142674652259394,0.5762702983407708,-0.04677188552298528
311.80000000000405,25.185243648992216,0.575639515674677,-0.04677223602254399
313.200000000004,25.22784836948797,0.5729963797303605,-0.04812922992974489
314.60000000000406,25.270654823750696,0.5764349517104381,-0.04808990835033988
316.0000000000041,25.312775606445737,0.5744598369224325,-0.048089951268026176
317.40000000000407,25.35553916661697,0.5753617770004527,-0.04808986808602045
318.8000000000041,25.397987758009734,0.5765904299954566,-0.04806438841724825
320.20000000000414,25.440726225879047,0.576822926245942,-0.0487478187282111
321.6000000000042,25.48348729531033,0.5749621027054885,-0.048749956419085194
323.0000000000042,25.52553920250192,0.5754696681691777,-0.048749952047318246
324.4000000000042,25.5684655076916,0.5759388911394312,-0.04874995200019949
325.8000000000042,25.611033221591946,0.575043886029928,-0.04874995200004095
327.20000000000425,25.65356678898579,0.5753434314529722,-0.048749952032842714
328.60000000000423,25.696186074153456,0.5772983001242,-0.048749960922635616
330.00000000000426,25.739116181975717,0.5768396770250466,-0.048750681143137964
331.4000000000043,25.781889592223983,0.5772953552698904,-0.05003997397664017
332.80000000000433,25.82380662932582,0.5759481409928464,-0.05004772798683099
334.20000000000437,25.867142003177864,0.5774218785879698,-0.048734601429041735
335.60000000000434,25.90987792459755,0.5764253958272026,-0.048732832169684936
337.0000000000044,25.952383667423245,0.5785299917250648,-0.05006332086015197
338.4000000000044,25.995541043741255,0.5800672020241258,-0.05005995548826725
339.8000000000044,26.03772181184086,0.5794795081978652,-0.05005992013594396
341.2000000000044,26.081003647511448,0.5786970728191938,-0.050059920009302594
342.60000000000446,26.123939648810918,0.5802825375571196,-0.050059927498071755
344.0000000000045,26.16617281220801,0.581408466647914,-0.05006208771315279
345.4000000000045,26.20943435124072,0.5800749865727979,-0.05100155709969423
346.8000000000045,26.25227820956733,0.5808553466421382,-0.051371716425133496
348.20000000000454,26.295382445050773,0.5819494016426969,-0.052045345583252356
349.60000000000457,26.338270440557565,0.5838087884449178,-0.05204020097466344
351.00000000000455,26.381030642404554,0.5821490477433372,-0.05204018305627134
352.4000000000046,26.424231120360194,0.5844644591607647,-0.05204293746470734
353.8000000000046,26.4667918769068,0.586439801182267,-0.05131835565951626
355.20000000000465,26.509906446499258,0.5853146195038603,-0.05138007085220453
356.6000000000047,26.552871912217636,0.5864941689478697,-0.0513801843345747
358.00000000000466,26.59591015331468,0.5889234112466473,-0.05138018321961324
359.4000000000047,26.639118694691373,0.5881336830286137,-0.051380116235193896
360.80000000000473,26.681508772295487,0.5900499465673725,-0.05141135643351369
362.2000000000047,26.724929719087797,0.59316172394056,-0.05038286003055292
363.60000000000474,26.768326806604406,0.5943105237364297,-0.05039017279026359
365.0000000000048,26.811440371162803,0.5915532485117125,-0.05039015948058578
366.4000000000048,26.85384571166944,0.5924569878726713,-0.050956116100300264
367.80000000000484,26.897542157855305,0.5916837211434611,-0.052686984407027015
369.2000000000048,26.940811768748045,0.5915162692309629,-0.0530258747541108
370.60000000000485,26.983712606784405,0.5933930527933559,-0.05303022096038035
372.0000000000049,27.026710428533153,0.5939630474336794,-0.05303005274717343
373.40000000000487,27.069907107101432,0.5960289045826389,-0.05303005200068078
374.8000000000049,27.11343189695847,0.5952074638156866,-0.05303005199992139
376.20000000000493,27.156438562170944,0.5950017914834167,-0.05303005197429567
377.60000000000497,27.199729349093495,0.5973915745009793,-0.053030050417882
379.000000000005,27.243072236118476,0.5992789363366968,-0.05303202126015183
380.400000000005,27.286489471267537,0.6000560033059184,-0.05193380355353927
381.800000000005,27.3289949547427,0.6020126864251413,-0.05169070086794214
383.20000000000505,27.373109699111453,0.6012938106999162,-0.0520891783741706
384.600000000005,27.416527447453205,0.6018584426716416,-0.0530280540052801
386.00000000000506,27.45965136775392,0.6019538344428998,-0.05434276243018443
387.4000000000051,27.50312053028763,0.603048220743478,-0.05330372830946528
388.8000000000051,27.546091142588875,0.6047994543983873,-0.052957944683352576
390.20000000000516,27.590246556415007,0.6054077887373714,-0.0543388437390826
391.60000000000514,27.63256201365953,0.6056781906465939,-0.05434007143340658
393.0000000000052,27.676838100942987,0.6070570185355844,-0.0543406802320785
394.4000000000052,27.72025418537336,0.60659682554437,-0.05468102734009861
395.8000000000052,27.763733546642776,0.6090249751646934,-0.05430368657184381
397.2000000000052,27.806747670706663,0.6098655045421855,-0.05434000966018715
398.60000000000525,27.85044520479342,0.6130925064959736,-0.054337391480439035
400.0000000000053,27.894130841353025,0.6131380198921328,-0.05466648264207219
401.4000000000053,27.93789720510358,0.6150909148038678,-0.05570148921691853
402.8000000000053,27.980693045304903,0.614992486549705,-0.05565987371908321
404.20000000000533,28.024810768203356,0.6149644569491519,-0.05565995143519231
405.60000000000537,28.06828758996469,0.6161143560311229,-0.05566415104298539
407.00000000000534,28.112220922059723,0.6224742586117755,-0.05631334215259498
408.4000000000054,28.155674693932497,0.6218145728247648,-0.056319892783314174
409.8000000000054,28.19945461343473,0.6219936307235712,-0.05631991998841501
411.20000000000545,28.242799572931197,0.625787643519351,-0.05631992000024866
412.6000000000055,28.28645983784506,0.6258824843286184,-0.056319920000000856
414.00000000000546,28.330425053633864,0.6289459711520211,-0.056319919999972434
415.4000000000055,28.37397543159752,0.629858393830371,-0.056319919943558894
416.8000000000055,28.417750707464567,0.6298239164787017,-0.056319907983694684
418.2000000000055,28.4613400316886,0.6330455204478325,-0.056322338229954916
419.60000000000554,28.505265162613288,0.6362240009671828,-0.056641115492779726
421.00000000000557,28.54904390333053,0.6401580065325774,-0.056650175106335965
422.4000000000056,28.593089724394137,0.6447116203600367,-0.05665018406878897
423.80000000000564,28.63689435929563,0.6454283450614036,-0.05665018400021715
425.2000000000056,28.68058795162385,0.6503309064555141,-0.056650184000042625
426.60000000000565,28.72470116928379,0.6537192469202899,-0.05665018403366018
428.0000000000057,28.768532220345072,0.6576620844696508,-0.056650188162314485
429.40000000000566,28.812409393694356,0.662425467703087,-0.05664743309829401
430.8000000000057,28.856097546436843,0.6648363838042011,-0.057353167272945704
432.20000000000573,28.90018350453593,0.6648916109385115,-0.057310167917838495
433.60000000000576,28.94423157669821,0.6660802848792586,-0.057518305515835255
435.0000000000058,28.98808403628613,0.6673699247907297,-0.05862147669009987
436.4000000000058,29.03193657515321,0.6660818345569621,-0.05862014806291782
437.8000000000058,29.075944749214717,0.6673425696732639,-0.058620151977417656
439.20000000000584,29.120030553452352,0.663613053788604,-0.05862015200000048
440.6000000000058,29.163878522342053,0.6643381401680033,-0.05862015199999959
442.00000000000585,29.207522932129073,0.6610287145354563,-0.05862015199999959
443.4000000000059,29.251899238312035,0.6620840762006274,-0.05862015200000048
444.8000000000059,29.295911009606233,0.6614904263054863,-0.05862015199999959
446.20000000000596,29.339706170394223,0.6602969234496451,-0.05862015200000048
447.60000000000593,29.383550858788283,0.6600052568365655,-0.05862015199999737
449.00000000000597,29.428263248438217,0.6623600489392033,-0.05862015199964743
450.400000000006,29.47249045171375,0.6640544941821468,-0.058620152177566
451.800000000006,29.516856549900385,0.6644761842074978,-0.05862021960269814
453.200000000006,29.560412813727908,0.666654903019426,-0.058616706564955656
454.60000000000605,29.60518093427456,0.6667332826492565,-0.059926744533036036
456.0000000000061,29.649287938470405,0.6698174922654013,-0.05994001086901468
457.4000000000061,29.69378960031422,0.6727755634130685,-0.05994011658658449
458.8000000000061,29.73771046349553,0.6730219948768309,-0.05996431868139629
460.2000000000061,29.78276915379534,0.6764374451936686,-0.06125784794753919
461.60000000000616,29.827002770403297,0.6771767964014939,-0.06125988144799166
463.00000000000614,29.87130201835855,0.6778050852586697,-0.06125988800923343
464.4000000000062,29.91582577957628,0.6815475463669254,-0.06125988800387949
465.8000000000062,29.96032530985985,0.682662687630805,-0.06125988610481592
467.20000000000624,30.004612041420653,0.6880534707012773,-0.06125919710520966
468.6000000000063,30.049454890835698,0.6922542082925318,-0.06263286077233099
470.00000000000625,30.093816213496794,0.6932666575549323,-0.06258025776709486
471.4000000000063,30.138408214384235,0.6946377401354591,-0.06257988775987133
472.8000000000063,30.182971445823764,0.6989494785842192,-0.06257993163149367
474.2000000000063,30.227152063453826,0.7037047197092083,-0.06259292545360395
475.60000000000633,30.272314064143874,0.7066051858951208,-0.06388775526499879
477.00000000000637,30.317142724975046,0.7109242907162729,-0.06390010855067496
478.4000000000064,30.361799483744203,0.7169627503953788,-0.06390060192991198
479.80000000000643,30.406031090535702,0.7186882295182629,-0.06430675494051163
481.2000000000064,30.450460015580703,0.7224899950465098,-0.06457167520876927
482.60000000000645,30.49597405559674,0.7264615951416636,-0.06520895700929641
484.0000000000065,30.540995940294007,0.7298434634232391,-0.06521012099707812
485.40000000000646,30.585553594611557,0.7334948691645377,-0.0652101198244055
486.8000000000065,30.63003207747453,0.7379810448663202,-0.06521012071824517
488.2000000000065,30.67468056327539,0.7400783042174105,-0.06523545635499728
489.60000000000656,30.71980250670972,0.7425163308300697,-0.06652996369345132
491.0000000000066,30.764278934395637,0.7466489293247267,-0.06689332960720806
492.40000000000657,30.809273408055105,0.750075176247152,-0.06685996069472555
493.8000000000066,30.854283532285127,0.7561247340274297,-0.06679688219208746
495.20000000000664,30.899181348884596,0.7593479471741691,-0.06750580467431799
496.6000000000066,30.94410580797377,0.7602466864941555,-0.06743287476432425
498.00000000000665,30.988964174719055,0.7624737973361854,-0.06751387012865706
499.4000000000067,31.033984914500355,0.76634478855863,-0.06627024919948399
500.8000000000067,31.078654700645505,0.770138334890403,-0.0672156660100951
502.20000000000675,31.123443280780172,0.7704176633690133,-0.06829711287021833
503.60000000000673,31.16741960869121,0.7730087048636536,-0.06850882923765145
505.00000000000676,31.2130032571075,0.7725160636408652,-0.0685157980227249
506.4000000000068,31.25843933146091,0.7736964921512963,-0.06883389326886835
507.8000000000068,31.303078928199685,0.7777303568479471,-0.07015677712995316
509.2000000000068,31.34780169072001,0.7766605749654252,-0.0701494039467292
510.60000000000684,31.39271797686325,0.7779446616222847,-0.07180029582615477
512.0000000000068,31.43774688266909,0.7762935706629976,-0.07245707959512293
513.4000000000069,31.482934830518076,0.7775967624733755,-0.07278066152407625
514.8000000000069,31.527642968549294,0.7764580462371634,-0.07274598637847562
516.2000000000069,31.572460979872293,0.7774967226515083,-0.07406806949031086
517.600000000007,31.617514401212564,0.7781693672023537,-0.07294949563331699
519.0000000000069,31.66246624744202,0.77921831936581,-0.07410832422171598
520.4000000000069,31.707450358653524,0.7795880036236839,-0.07411022170809067
521.800000000007,31.75259931254393,0.7751252689536293,-0.07542708668923392
523.2000000000071,31.797653285580807,0.7767338437623185,-0.07598439585722705
524.6000000000071,31.842773020128977,0.7768178848349002,-0.07540493915051627
526.000000000007,31.888038562344498,0.7792404825303595,-0.07541822338633075
527.4000000000071,31.93306589568008,0.7802714231828897,-0.07574157068882892
528.8000000000071,31.97830780970137,0.7785308447721975,-0.07710120121673336
530.2000000000071,32.02321584562131,0.7786476876470068,-0.07706843593909918
531.6000000000072,32.06837108906065,0.7817399915374524,-0.078088788360128
533.0000000000072,32.11380282308192,0.7839971493444561,-0.07808046109486977
534.4000000000071,32.15866561728778,0.7846206576452567,-0.07938113526508195
535.8000000000072,32.20395004516519,0.7888542394406654,-0.0793797580729323
537.2000000000072,32.249312326651285,0.7942265990569896,-0.08064748781547282
538.6000000000072,32.29453581902942,0.7923812784655541,-0.08069078869611124
540.0000000000073,32.3397735274106,0.7947576595008653,-0.08069341771298033
541.4000000000073,32.38494348066549,0.7999320892271227,-0.08200801570622929
542.8000000000073,32.430527151432834,0.8028976403480085,-0.08204320705910817
544.2000000000073,32.475744237729,0.8061847073634727,-0.08101320888513897
545.6000000000073,32.52096112728343,0.8083211936142812,-0.08200939279564778
547.0000000000074,32.56667653739279,0.8142571317744786,-0.08201090594053007
548.4000000000074,32.61217174035587,0.8166368278586167,-0.08285006234260894
549.8000000000075,32.65741647303742,0.8215795214641735,-0.08332966593256108
551.2000000000074,32.70286689843703,0.825515404775054,-0.08333115357037402
552.6000000000074,32.74837854971601,0.8259401291576778,-0.08416650967380424
554.0000000000075,32.79409477668469,0.8315228574712922,-0.08464081554531822
555.4000000000075,32.83948971715465,0.8378448231570661,-0.08525686806800303
556.8000000000075,32.88484263354738,0.8406041306167324,-0.08596918942333964
558.2000000000075,32.93042813333008,0.8417722474710616,-0.08694514206332027
559.6000000000075,32.97571839583155,0.8473794644414125,-0.08824877625442396
561.0000000000075,33.02145098750034,0.8496216362071807,-0.08793257522835995
562.4000000000076,33.06697512231054,0.8515710494368423,-0.08825637231165606
563.8000000000076,33.112537471788514,0.8550993773047775,-0.08941927048137943
565.2000000000077,33.1584467492669,0.8589626535128039,-0.09099071529722291
566.6000000000076,33.2041050619374,0.8633435118345529,-0.0908998026672565
568.0000000000076,33.24970783919738,0.8680376335348229,-0.09220222365214514
569.4000000000077,33.295330799859975,0.8747269132833991,-0.0922199787079876
570.8000000000077,33.341145540868354,0.8809146326087925,-0.09359051401673923
572.2000000000078,33.38683561736266,0.8845386392961425,-0.09354015455410547
573.6000000000078,33.4325154041365,0.891214887285287,-0.09353800439337423
575.0000000000077,33.47861896649628,0.8962781285783779,-0.0948064133445925
576.4000000000078,33.52413792814879,0.8999864220262866,-0.094882777845958
577.8000000000078,33.56993567830364,0.9002542288096993,-0.09617012738230768
579.2000000000078,33.61588531172618,0.903641733862244,-0.09615751961495889
580.6000000000079,33.661975572462865,0.9085745646728455,-0.09749498474914864
582.0000000000078,33.70770952143802,0.9132717773849086,-0.09766740652868178
583.4000000000078,33.75383187413538,0.9161943938108622,-0.09881823820668023
584.8000000000079,33.799709952691906,0.9199010358625908,-0.10013272448171628
586.2000000000079,33.845600386665986,0.9271358556781054,-0.1004302426701309
587.600000000008,33.89142629564095,0.9304993824877694,-0.10143936810187704
589.000000000008,33.93733649947743,0.9367714735291637,-0.10144194349053759
590.4000000000079,33.98318192513753,0.9405133724034371,-0.10143257923957094
591.800000000008,34.02932281645354,0.9464954483736002,-0.10143968008614168
593.200000000008,34.075566847586295,0.9509064229884754,-0.10195643102341023
594.6000000000081,34.1215387195219,0.9537179865212911,-0.1028209012595398
596.0000000000081,34.16734693888924,0.9597505985106636,-0.10407525428461994
597.400000000008,34.21340892491205,0.9655837372278674,-0.10539629995482569
598.8000000000081,34.25949314107214,0.970778287794805,-0.10538185468233108
600.2000000000081,34.305962967688735,0.9756761361597944,-0.10635441283419178
601.6000000000081,34.35191857843872,0.9832653764031631,-0.10672240667366095
603.0000000000082,34.39806307177027,0.9905267459360786,-0.10802993361960445
604.4000000000082,34.44428357246624,0.9917855722857464,-0.10935483637818644
605.8000000000081,34.49049296590195,0.9993595873635058,-0.11065250185482967
607.2000000000082,34.53685803526973,1.0002221072407136,-0.11195059987264289
608.6000000000082,34.58252680572378,1.0043659861773517,-0.11242251103765444
610.0000000000083,34.62908338475048,1.0126021560635052,-0.11195690931603863
611.4000000000083,34.675259131722875,1.0114619442947685,-0.11329265082651441
612.8000000000083,34.721472100497536,1.0125803328208678,-0.11339755096949888
614.2000000000083,34.767680114179996,1.0146376685622183,-0.11505075237276996
615.6000000000083,34.813705588802016,1.015407422535574,-0.11695840291991422
617.0000000000084,34.86000000000026,1.0139723904827387,-0.11824006410793686
618.4000000000084,34.906382619220054,1.016228886066309,-0.11954174382495353
619.8000000000084,34.95253261756932,1.0132672357548747,-0.12084337872230044
621.2000000000085,34.99892462477939,1.0197262160283471,-0.1221507758865159
622.6000000000084,35.04494595141955,1.0202127405511194,-0.12263570869428753
624.0000000000084,35.090942588768925,1.0227148893131992,-0.12351430844469746
625.4000000000085,35.13775964306762,1.0269346123370622,-0.12482362899460364
626.8000000000085,35.184110264670196,1.025511368754484,-0.1248410128860975
628.2000000000085,35.230355498206215,1.0288937659633868,-0.1261405936678619
629.6000000000085,35.27637102045154,1.0351628194579978,-0.12649191926024983
631.0000000000085,35.32306309321374,1.0380334169341,-0.12784213241601394
632.4000000000086,35.36912940430958,1.0389004675232765,-0.1286933106994499
633.8000000000086,35.415508523071146,1.0428117213667418,-0.1294055219118868
635.2000000000086,35.461902099834354,1.049381234666521,-0.1309446554804179
636.6000000000087,35.50800739185282,1.0530881310598346,-0.1330349604004697
638.0000000000086,35.55464058866802,1.0586191212379152,-0.13315270231368048
639.4000000000087,35.600829254317745,1.0620449348973704,-0.1344184601660996
640.8000000000087,35.6474704879817,1.0652822611893726,-0.1336686666744793
642.2000000000087,35.69413010475461,1.0767620610781594,-0.13501638132523652
643.6000000000088,35.73993324912482,1.0805653245440279,-0.13657056010084467
645.0000000000088,35.78580960514919,1.0868565725058925,-0.13793222740635303
646.4000000000087,35.833102792972525,1.0895555334241993,-0.13907844789958768
647.8000000000088,35.87957550832424,1.0978326150557343,-0.14016261465692192
649.2000000000088,35.9262709669993,1.1064278675961106,-0.14166501453208857
650.6000000000088,35.972369116011684,1.1105891008815139,-0.14271635390667647
652.0000000000089,36.01888349775808,1.114393011410522,-0.1440568239636919
653.4000000000088,36.06550115281368,1.1230460532613789,-0.1460799961245991
654.8000000000089,36.11175711983316,1.1301633804250415,-0.14625555119821154
656.2000000000089,36.15802918145083,1.1367094943427698,-0.14739663245908474
657.6000000000089,36.20439516976815,1.1439155394650482,-0.14878476667071272
659.000000000009,36.25106573078282,1.1546747084964029,-0.15008111492853526
660.400000000009,36.29740375803953,1.160253100079094,-0.15223566000776145
661.800000000009,36.34427302064922,1.165923782858886,-0.15449067417272255
663.200000000009,36.39037721534567,1.17385898694312,-0.15589712239889186
664.600000000009,36.43703695321852,1.1858071578835927,-0.15755571169425142
666.0000000000091,36.48363705523241,1.1957884174610243,-0.15760375420610462
667.4000000000091,36.53033591822082,1.20806637314928,-0.1603111174125802
668.800000000009,36.576727052629636,1.2250786646124627,-0.16182331699212638
670.2000000000091,36.623181712521614,1.2373836793307798,-0.16364884796968182
671.6000000000091,36.669736409316855,1.2521590886103053,-0.1658576373299372
673.0000000000091,36.71653261832512,1.2732299017470206,-0.1678409760632933
674.4000000000092,36.76307364140117,1.2863333302256248,-0.16917197552303342
675.8000000000092,36.80947481278999,1.3037104228349172,-0.17061419140059364
677.2000000000093,36.85563631317095,1.324995012121059,-0.17269172824983237
678.6000000000092,36.90266130575071,1.3466560688090896,-0.1740788488923397
680.0000000000092,36.949056109954455,1.3714441380037141,-0.175190276732347
681.4000000000093,36.99591880429124,1.3979558478489094,-0.1777281103240247
682.8000000000093,37.0427290650229,1.4203605251542657,-0.17970202591208917
684.2000000000094,37.08945788841347,1.4453209661780904,-0.1822905553073313
685.6000000000093,37.136049416228566,1.4744029005202839,-0.18481737056882652
687.0000000000093,37.18266748803042,1.5022014121038718,-0.18796445092753133
688.4000000000094,37.22929384267086,1.5300985853611397,-0.1908030236686682
689.8000000000094,37.27615391395403,1.5607206336618642,-0.1931550856485873
691.2000000000094,37.32280787468828,1.5874407399967292,-0.19605788187511797
692.6000000000095,37.36957394462656,1.6183163937723621,-0.199242273932136
694.0000000000094,37.41637796153411,1.6474550520992954,-0.2027725938016629
695.4000000000094,37.463126109633684,1.677557364278055,-0.20618511891502855
696.8000000000095,37.509900523832684,1.7078889300046527,-0.20946292757978524
698.2000000000095,37.55637388565389,1.7459920198903083,-0.21297123088928283
699.6000000000096,37.60322208965796,1.7791913310060792,-0.21619573014101068
701.0000000000095,37.64986552652444,1.8151756394409877,-0.21739355361274937
702.4000000000095,37.69682774266414,1.8502881946196157,-0.22195809536164557
703.8000000000096,37.743696287356805,1.8920381809469557,-0.22599345600894827
705.2000000000096,37.79056919460261,1.935026029641655,-0.22973989527573258
706.6000000000097,37.837175404003574,1.9775385125201215,-0.23444120783651812
708.0000000000097,37.88403915062372,2.0225522948885106,-0.23874283013766906
709.4000000000096,37.931298926639926,2.069354139653068,-0.2427201319323542
710.8000000000097,37.977886498257035,2.119051397303755,-0.24667135532888507
712.2000000000097,38.024892770461406,2.1697458048795277,-0.25116251654725374
713.6000000000097,38.0720281288813,2.2203421617636714,-0.2565338432530666
715.0000000000098,38.11903191711744,2.2729724109192375,-0.2615521655689097
716.4000000000098,38.16606774035046,2.334695699585629,-0.26680303931072835
717.8000000000097,38.21227331720304,2.3873243211976742,-0.27240763220917064
719.2000000000098,38.259898906679844,2.449768436253645,-0.2778418760352608
720.6000000000098,38.306902951119525,2.51151337395134,-0.28488839281839207
722.0000000000099,38.35437337124983,2.578137639214651,-0.29164203175432757
723.4000000000099,38.401448638427354,2.6475506570115743,-0.2962433688932009
724.8000000000098,38.44888897016504,2.7147593055159627,-0.3006796073663165
726.2000000000099,38.495840241100254,2.785458962467291,-0.30697923508603964
727.6000000000099,38.54327671114623,2.8668467367499906,-0.31428394065045895
729.00000000001,38.590877534119514,2.9458218246404724,-0.3231574131678978
730.40000000001,38.638188296010874,3.0280463073945967,-0.329796863703677
731.80000000001,38.68548876111264,3.118475650031296,-0.3368548058018819
733.20000000001,38.73289262329838,3.20715008673438,-0.3450103351954499
734.60000000001,38.78064313788104,3.312708453551507,-0.3530227716580563
736.00000000001,38.828142520083006,3.412267097491978,-0.3611163755280886
737.4000000000101,38.876101165408556,3.5141902214849203,-0.3724528001811027
738.8000000000101,38.92370116271242,3.6297745393610703,-0.38257158289145643
740.20000000001,38.97137525151014,3.7425167891051276,-0.3904475349175227
741.6000000000101,39.019287198581644,3.8627445006797636,-0.40044268997469734
743.0000000000101,39.0674233120631,3.9853896583522372,-0.41051383149528053
744.4000000000102,39.11529174234779,4.111016062596992,-0.42190359621706097
745.8000000000102,39.1630089477688,4.238045447415899,-0.43362608350123644
747.2000000000102,39.210761512319316,4.368281913929248,-0.4446855455474914
748.6000000000103,39.25899805090215,4.507843980191764,-0.4572678249227362
750.0000000000102,39.306908220070824,4.643276980728914,-0.4694705932232943
751.4000000000103,39.35520181399865,4.7850638048156675,-0.48267924935589246
752.8000000000103,39.40328333076549,4.93243938949686,-0.49424043611237956
754.2000000000103,39.45097576614199,5.0827108809896115,-0.5079211186193078
755.6000000000104,39.49935331896618,5.231136553487031,-0.5227534195162242
757.0000000000103,39.54803001015936,5.392658850883307,-0.5386808311757774
758.4000000000103,39.59604950109824,5.555090088711683,-0.5534754855946029
759.8000000000104,39.64452688601317,5.722728618441599,-0.5680445130577776
761.2000000000104,39.693042025281365,5.887988959235484,-0.5827493200005347
762.6000000000104,39.74146155846661,6.061281623562772,-0.5998067870084851
764.0000000000105,39.78954999528045,6.235000716414867,-0.6183458788739746
765.4000000000104,39.83750174080961,6.406850397219443,-0.6358536387672102
766.8000000000105,39.88648676612792,6.588896590230385,-0.6527803690788012
768.2000000000105,39.93522271655498,6.764043341983732,-0.6725489454323936
769.6000000000105,39.983482369465094,6.943547233010488,-0.6922211967161678
771.0000000000106,40.03187921668277,7.131674010223372,-0.7131397179523211
772.4000000000106,40.08066787285524,7.306059195971677,-0.7343790952327129
773.8000000000106,40.12904736063985,7.491407151078087,-0.7545837781029205
775.2000000000106,40.17795998244435,7.676946324408716,-0.7765353837211695
776.6000000000106,40.226198862100354,7.85530767724985,-0.8001294057596606
778.0000000000107,40.27472000319096,8.033119975327816,-0.8233294050497766
779.4000000000107,40.323570234334426,8.210393125765187,-0.8465158398686619
780.8000000000106,40.37210556930706,8.378382557194442,-0.8705054104557837
782.2000000000107,40.42024456234653,8.532889022733366,-0.8942246980573616
783.6000000000107,40.46881870179448,8.691202600635414,-0.9212961045599797
785.0000000000107,40.51707810317693,8.829256209052435,-0.9450610416541223
786.4000000000108,40.56531544298824,8.953475944446952,-0.9722599818848203
787.8000000000108,40.61338911764637,9.060924288105605,-0.9981550040354548
789.2000000000108,40.66117220691522,9.144704829091522,-1.023262783441628
790.6000000000108,40.70875747124627,9.199632758199972,-1.0511725366784503
792.0000000000108,40.756075228078856,9.213697924488555,-1.0755269870399364
793.4000000000109,40.80308939267916,9.194651118628524,-1.100470618056539
794.8000000000109,40.849634779180526,9.114347026393384,-1.1263831994524143
796.200000000011,40.89584267369843,8.9791216617394,-1.153340940956082
797.6000000000109,40.94140363497815,8.780487151383852,-1.1777600262714416
799.0000000000109,40.98616025094013,8.50494940723049,-1.201363137296485
800.400000000011,41.03071269617503,8.135707848842866,-1.2226837688467072
801.800000000011,41.07406134829033,7.637808115324842,-1.2438113381465077
803.200000000011,41.11551929485359,6.946227316983183,-1.2635103975002955
804.600000000011,41.15583270504325,6.004246375718104,-1.2796973709422121
806.000000000011,41.193731143437745,4.847164609817668,-1.2910860142489664
807.400000000011,41.23195557144617,3.585193398508114,-1.3021094705538552
808.8000000000111,41.27104463465908,2.4979932406816587,-1.3090324550941657
810.2000000000111,41.31196711393849,1.7025543998959374,-1.3122883132837901
811.6000000000112,41.35521665246024,1.1799513727200694,-1.3150539520701439
813.0000000000111,41.39968111895524,0.8750174737714566,-1.3165228578416013
814.4000000000111,41.44501293405479,0.7046345298846837,-1.3178274588984893
815.8000000000112,41.49131297946373,0.6156948057235321,-1.317840127507484
817.2000000000112,41.537968036509945,0.578191070264305,-1.318023986413146
818.6000000000113,41.584491295893066,0.5590847835917302,-1.3191580264508822
820.0000000000113,41.63229032903945,0.554888651888414,-1.319150527323214
821.4000000000112,41.678862166689875,0.5556135454463301,-1.3188271904892424
822.8000000000113,41.7268282996746,0.5496708347773206,-1.3194864157435928
824.2000000000113,41.77377681103768,0.5501568922089283,-1.3194078559336804
825.6000000000113,41.82141290236967,0.5460563854543655,-1.3192896981039048
827.0000000000114,41.868605241901264,0.5490172220837001,-1.3200753476913958
828.4000000000113,41.9155769617154,0.5476639900432356,-1.3188296712970495
829.8000000000113,41.96299895688161,0.5435318803548452,-1.31883024617935
831.2000000000114,42.01016613456373,0.5385305907418838,-1.3188286817115706
832.6000000000114,42.057711582456754,0.540175746552559,-1.320144177261401
834.0000000000115,42.104423157140516,0.5354872178414357,-1.3201500811092588
835.4000000000115,42.15267505317265,0.5381460988108039,-1.3201500639921133
836.8000000000114,42.2000328481648,0.5371374755338781,-1.3201500648003583
838.2000000000115,42.247288100372806,0.5360003886403688,-1.3201458057458786
839.6000000000115,42.29476677338987,0.543287594537518,-1.3206491967866363
841.0000000000116,42.34224103604409,0.5381920998227575,-1.3201526967397657
842.4000000000116,42.38993388266506,0.5369557047334528,-1.321466292832283
843.8000000000116,42.43769412151926,0.5345393784138858,-1.3214704334003677
845.2000000000116,42.48493239065073,0.5288897972763695,-1.3214704206966896
846.6000000000116,42.53266500989828,0.531162116790131,-1.3211963250899692
848.0000000000116,42.57922083418959,0.5296281367692557,-1.3201511696295003
849.4000000000117,42.62769183367674,0.5288343325909465,-1.3201485699595583
850.8000000000117,42.674927955955184,0.5286027606116506,-1.3208248865345404
852.2000000000116,42.72186114512767,0.5315841237928065,-1.320119980865127
853.6000000000117,42.77033565547133,0.5284799017267112,-1.321475721974065
855.0000000000117,42.818276799652146,0.5274415885654292,-1.3224491050248557
856.4000000000118,42.866215396882616,0.5265603256936024,-1.3234407619113941
857.8000000000118,42.9143066086001,0.5219984915934984,-1.3237758607387788
859.2000000000118,42.96232809232308,0.5253798103928219,-1.322443903340174
860.6000000000118,43.01036631145559,0.5268724121872477,-1.32244990569332
862.0000000000118,43.05799292260529,0.5281167622126424,-1.3226353839200633
863.4000000000119,43.10661949750441,0.5278886212606926,-1.3237688792478672
864.8000000000119,43.15471615499673,0.5272687333773839,-1.3237701835651388
866.2000000000119,43.20257471545043,0.5277990220643847,-1.3237670979729814
867.600000000012,43.25064143608178,0.5295387361532097,-1.322496473195991
869.0000000000119,43.29875810311425,0.5332588250913123,-1.323770235257999
870.4000000000119,43.346741340725025,0.5404346806537722,-1.3237701316372528
871.800000000012,43.39445027749433,0.5530219886335337,-1.3237701094739265
873.200000000012,43.44263551476397,0.5659494852711716,-1.3237860921990854
874.600000000012,43.49034254425781,0.5840728997557528,-1.3250896394794962
876.000000000012,43.53796141862854,0.6054542751766746,-1.3250830751431795
877.400000000012,43.58627300435624,0.612391642927701,-1.3264152391888615
878.8000000000121,43.63432471959491,0.6162950613024097,-1.3264134380087733
880.2000000000121,43.681900266238124,0.6185091173779282,-1.3251228878215349
881.6000000000121,43.729457624991035,0.6155988783692596,-1.3264002364968444
883.0000000000122,43.7770318058994,0.6113407658155233,-1.3274838830705118
884.4000000000121,43.82524196695445,0.6045457266031341,-1.3277205442170663
885.8000000000122,43.872847725345096,0.5959485752681531,-1.3277200372281
887.2000000000122,43.92016901605108,0.5886365606667864,-1.3271715680775635
888.6000000000122,43.968006798603106,0.5838828124407657,-1.327719731270018
890.0000000000123,44.01558490111249,0.574724267830763,-1.3277193635605609
891.4000000000123,44.063264412120745,0.5674039515271507,-1.328126911795835
892.0000000000123,44.08355538669647,0.5647903468105963,-1.3291895551764723