File: 01_Data/Cinder_Block/STA/N2/30K_min/Cinder_Block_STA_N2_30KData_230825_R3.csv
##Temp./Â°C,Time/min,DSC/(mW/mg),Mass loss/mg
28.1,15.397620630527884,-0.016333728579295048,0.014270320494635946
29.50000000000002,15.731745023161944,0.03652478711879015,0.010944481208202461
30.90000000000004,15.893684915659442,0.071179568550646,0.010334135267782152
32.30000000000006,16.009918362472472,0.10067042472834675,0.01003962319735141
33.70000000000008,16.10969474827058,0.12494410255766208,0.010855316689166727
35.1000000000001,16.197289290671613,0.15285865802719711,0.009003395911093115
36.50000000000012,16.277742843512552,0.17324718479468593,0.009526789487356968
37.90000000000014,16.35186447414159,0.19339237514665952,0.008547286570690371
39.30000000000016,16.422288986886706,0.20833408493708983,0.008550043912530558
40.70000000000018,16.488895927804034,0.22931505057899715,0.008758453056331383
42.1000000000002,16.553268179175202,0.24210982740997533,0.008247652756809831
43.50000000000022,16.61544111409903,0.25759421130913496,0.007324008261893056
44.90000000000024,16.67485172647736,0.2714255623842705,0.008206949728773782
46.30000000000026,16.734626216035096,0.282075664978237,0.006681205026739079
47.70000000000028,16.79250453242387,0.29351669796180113,0.007307315414910587
49.1000000000003,16.849041750168414,0.30641909143843526,0.006930110923042854
50.50000000000032,16.903951432362373,0.31930611381245133,0.006538222112564274
51.90000000000034,16.959179488623654,0.327472598261646,0.006309138032627448
53.30000000000036,17.011929318117033,0.34138588420392546,0.005771920208680115
54.70000000000038,17.065879720547848,0.34784844780473434,0.004629482173088562
56.1000000000004,17.119341656190358,0.35575211935999107,0.0035856661943474144
57.50000000000042,17.17137985411734,0.36851796511232204,0.003285064341713717
58.90000000000044,17.222972947785696,0.37375218112423925,0.00378503450033163
60.30000000000046,17.274180221303485,0.3836015666606385,0.0036627221102332186
61.70000000000048,17.325189014587004,0.39062223048507927,0.002319440406285622
63.1000000000005,17.375759989008284,0.4015632876575952,0.0016781990173146966
64.50000000000051,17.426162869263234,0.4060932425338821,0.0016750535836282943
65.90000000000055,17.47590521329321,0.41249319852148036,0.0019537158444649094
67.30000000000055,17.525846878466822,0.41622998552461676,0.001851042902056399
68.70000000000059,17.57512836136586,0.42357199666274803,0.0012869966658142218
70.10000000000059,17.624504718538276,0.4264028404918089,-0.001121130158920458
71.50000000000063,17.67364975843985,0.4291220906469019,-0.00252183310638765
72.90000000000063,17.722947011852995,0.43008441703084743,-0.001731568826730534
74.30000000000067,17.772200192204572,0.4312924412465351,-0.0011047003402127054
75.70000000000067,17.820673420911486,0.43292975343303397,-0.002372993329324391
77.1000000000007,17.86977706362874,0.4335247206549563,-0.002436135890418356
78.50000000000071,17.918475039009987,0.4347771525770775,-0.0037241205624418683
79.90000000000074,17.966906313094523,0.43282629127991346,-0.0035638462797660253
81.30000000000075,18.015076379291408,0.43803394111717264,-0.0051553115547005035
82.70000000000078,18.063509478965997,0.43489737715043286,-0.005101896361988878
84.10000000000079,18.111483840120897,0.436336756457519,-0.005035772950744644
85.50000000000082,18.159535889904873,0.4383816686066466,-0.005046648398400411
86.90000000000083,18.206906455693517,0.43913544119335257,-0.0050335860638792695
88.30000000000086,18.254559847426744,0.43876992719248087,-0.006500860779576456
89.70000000000087,18.30209191833991,0.4390928789198989,-0.0065803287484311745
91.1000000000009,18.34962640130601,0.4396556156204078,-0.007800041636789157
92.50000000000091,18.39661678108354,0.43994592072810745,-0.006597301810351119
93.90000000000094,18.444234931441663,0.4427741040523834,-0.007803701426743359
95.30000000000095,18.490664122231887,0.441790287628971,-0.0078001577942283795
96.70000000000098,18.537478719328398,0.44114878875318453,-0.00849461673821894
98.10000000000099,18.584492251455078,0.43960146900383057,-0.009115127307047555
99.50000000000102,18.630907324458764,0.4411471903379811,-0.011121475805451642
100.90000000000103,18.67769493020487,0.4411549093845034,-0.011090315096912384
102.30000000000106,18.724045935972093,0.4405234870962833,-0.011115137611965142
103.70000000000107,18.770482201467672,0.4409152890011885,-0.012410557556679969
105.1000000000011,18.81705000316993,0.4411513219488693,-0.012396604707347603
106.50000000000111,18.863021602751626,0.4412704868163263,-0.011113216057630382
107.90000000000114,18.909117027046136,0.4407010215999705,-0.011099932505802101
109.30000000000115,18.955543564013446,0.4416164342655393,-0.011006037131073398
110.70000000000118,19.00181882343662,0.4419190196355073,-0.012410049079939256
112.10000000000119,19.047929087185178,0.44194751332428095,-0.012409580176095503
113.50000000000122,19.09388639855976,0.43970649470726264,-0.012479995169194513
114.90000000000123,19.139603585265153,0.4421948004083778,-0.012409895363464596
116.30000000000126,19.18588536766428,0.44273507955758606,-0.012409923658856403
117.70000000000127,19.231960330508574,0.4418784466348963,-0.012417283273545188
119.1000000000013,19.277346623870876,0.44235008414389654,-0.015114416265354258
120.50000000000131,19.322837726611947,0.44384960042798866,-0.01505370604115841
121.90000000000134,19.36833074418531,0.4404184757676892,-0.01373836261414052
123.30000000000135,19.414094567305124,0.4423895705277127,-0.013729918867075419
124.70000000000138,19.45941226071318,0.43984711929963816,-0.013729824116420986
126.10000000000139,19.503978229348608,0.44145979261068297,-0.01396720046512634
127.50000000000142,19.549308964935513,0.4399643810497958,-0.016345019769201663
128.90000000000143,19.594422066014964,0.43797165821754613,-0.016370041057715667
130.30000000000146,19.638913448041233,0.4400611143077979,-0.016363640545691727
131.70000000000147,19.68467744337671,0.43901540250245585,-0.015019377032986725
133.1000000000015,19.729448448690476,0.43822393909823293,-0.01635862227768481
134.5000000000015,19.77400192062476,0.43717949331490535,-0.01635997930422395
135.90000000000154,19.818618964478787,0.4330853033445244,-0.01635995900605325
137.30000000000155,19.8632709682716,0.4348660574922683,-0.016359959042830496
138.70000000000158,19.907787366647312,0.43449633708959734,-0.016359967585164448
140.1000000000016,19.95197224849357,0.4346313114635808,-0.01635596310595755
141.50000000000162,19.995719239815706,0.43377520233021094,-0.018472302638844695
142.90000000000163,20.0402747426923,0.432368427175674,-0.018669998135670607
144.30000000000166,20.084252779731234,0.43172069458037887,-0.01866987944010079
145.70000000000167,20.12869058696597,0.43046754291871836,-0.018669878004260898
147.1000000000017,20.172407488447828,0.42871667224575155,-0.018669971304726474
148.5000000000017,20.215569161861026,0.42708849959475303,-0.01868973913111649
149.90000000000174,20.26050054766184,0.42591286271039436,-0.019666506474737666
151.30000000000175,20.30407046196164,0.4272883412245592,-0.019659959868312704
152.70000000000178,20.347909498961705,0.4250017592535734,-0.019661288329053228
154.10000000000178,20.391259464773793,0.42476101679634115,-0.019992552447749112
155.50000000000182,20.43533134932422,0.4235020687951796,-0.01998988394214951
156.90000000000182,20.47896673481072,0.42475465710182553,-0.0199899011201925
158.30000000000186,20.52258642217194,0.42603726302548584,-0.019973881617096456
159.70000000000186,20.565863812024155,0.42406467308289175,-0.020321497934032706
161.1000000000019,20.60922418135072,0.42255984468772645,-0.02030361676303727
162.5000000000019,20.652606232808775,0.42302341996521975,-0.021048334849115058
163.90000000000194,20.6963067142196,0.42221637188172295,-0.021309635596909793
165.30000000000194,20.740000000000062,0.4189042295577156,-0.021310168997053847
166.70000000000198,20.783302090227377,0.41826088048055016,-0.02131016809136277
168.10000000000198,20.826812488894234,0.41873099916642476,-0.021310198958235382
169.50000000000202,20.870062390035667,0.41761803377350526,-0.021408740285847383
170.90000000000202,20.913426840456193,0.4142687385187852,-0.021639814685672665
172.30000000000206,20.956919992121453,0.41607909467216136,-0.02164016929919832
173.70000000000206,21.000272889852642,0.4151147040400497,-0.021640169004576215
175.1000000000021,21.042954297012674,0.41248223834078684,-0.021640169000011422
176.5000000000021,21.0864704408941,0.41472425896111714,-0.02164016900000032
177.90000000000214,21.129632259491256,0.4137862828204428,-0.021640169000018084
179.30000000000214,21.172639301556053,0.41388440325275677,-0.02164016896635257
180.70000000000218,21.21556558200465,0.41285872140407953,-0.021640156354684414
182.10000000000218,21.258679230081253,0.409637414577288,-0.02163872804468081
183.50000000000222,21.301480269551416,0.40882888962984776,-0.021954072020340387
184.90000000000222,21.344465972998435,0.41029376530656403,-0.02196037449057764
186.30000000000226,21.386645707375123,0.41029040061730543,-0.022120803035840186
187.70000000000226,21.429601154855455,0.40871026256197857,-0.023243441294882317
189.1000000000023,21.4723177038886,0.4078753608254553,-0.024259061861235498
190.5000000000023,21.515365651061238,0.40801601579459795,-0.02427001591616751
191.90000000000234,21.557851203087743,0.40680629236442645,-0.024270060446279107
193.30000000000234,21.601199381081056,0.4087717895727882,-0.0242704664746225
194.70000000000238,21.643992921005246,0.4072805892939743,-0.024297127508295713
196.10000000000238,21.68624110888865,0.40684145933404187,-0.023603858396185284
197.50000000000242,21.72931059165805,0.4074865835642352,-0.022965619648977587
198.90000000000242,21.77192261169572,0.4064060631311275,-0.02296122717496063
200.30000000000246,21.814342344884032,0.40527070222983586,-0.024288232905378404
201.70000000000246,21.856425310072186,0.40695549400361486,-0.025629650330117215
203.1000000000025,21.89874955843203,0.40761848410640544,-0.025591717007651837
204.5000000000025,21.94203083498273,0.40648532290333445,-0.025807097546460156
205.90000000000254,21.98478209847966,0.40776003844367087,-0.02559005913741652
207.30000000000254,22.027514160940946,0.40637969560465936,-0.02558995079162596
208.70000000000258,22.06984719434633,0.4066350514283966,-0.025589950997354727
210.10000000000258,22.112373283964615,0.40430598739959744,-0.02558995100003081
211.50000000000261,22.155096928238915,0.4066973628512735,-0.025589950991574018
212.90000000000262,22.19737819716671,0.40421931420560775,-0.025589944054361435
214.30000000000265,22.239970348239286,0.4068376558944209,-0.025588075105484887
215.70000000000266,22.282709310596193,0.40381325898262344,-0.024251353587725344
217.1000000000027,22.324761794882743,0.4056719472648564,-0.025597129360031445
218.5000000000027,22.367598930813504,0.40517364005192924,-0.025590314456042762
219.90000000000273,22.4096653487195,0.40572575749542816,-0.024283121395551444
221.30000000000274,22.451959759433674,0.4063609065765447,-0.025581014986405304
222.70000000000277,22.494432805158162,0.40657300960789666,-0.026883418547309024
224.10000000000278,22.537118261483627,0.4080184955418964,-0.026909759635176833
225.5000000000028,22.579110954807305,0.407240481138528,-0.02690984289210796
226.90000000000282,22.6220115269144,0.4080275931675488,-0.026909843000765044
228.30000000000285,22.663747340873933,0.4075859906405246,-0.026909843000057165
229.70000000000286,22.706244227765577,0.4071196928903064,-0.026909843077792317
231.1000000000029,22.74871662110926,0.41019257109855956,-0.026909867201654336
232.5000000000029,22.790732380706782,0.4050546650043394,-0.026913882675258627
233.90000000000293,22.83316557660287,0.40792261848454653,-0.026253837299805127
235.30000000000294,22.875307249474886,0.40833355581202213,-0.02624628410456964
236.70000000000297,22.917503930118222,0.4061677895507786,-0.027457790564567652
238.10000000000298,22.960088163901272,0.4081963309307386,-0.027560216795313952
239.500000000003,23.002536208969495,0.4089697179456884,-0.027608145741836232
240.90000000000302,23.044569818407805,0.4073063230052185,-0.026906286222851072
242.30000000000305,23.08658993632371,0.40723656351719506,-0.026902949144908206
243.70000000000306,23.128790362396305,0.4077523250748534,-0.02821388045035844
245.1000000000031,23.171273478389313,0.409194365483834,-0.0282201804371649
246.5000000000031,23.21316780871067,0.40768752441283995,-0.0282201580108854
247.90000000000313,23.255601565379635,0.40774420139803413,-0.028219817482485254
249.30000000000314,23.297790677989024,0.40874093671207623,-0.028162089803048573
250.70000000000317,23.339791094484628,0.4084712729527272,-0.028880278809044313
252.10000000000318,23.38215571068046,0.4099507482190523,-0.028880099107511548
253.5000000000032,23.424529954707367,0.41204746017410165,-0.028880104964104092
254.90000000000322,23.466419341375335,0.4096746542559322,-0.02888010499985949
256.30000000000325,23.50873686726743,0.410603267159288,-0.02888010499957705
257.70000000000323,23.551277200897772,0.4105065827949396,-0.028880105118532562
259.1000000000033,23.592749542451934,0.4115441779961524,-0.02888015527104848
260.5000000000033,23.635620755990765,0.412535966381815,-0.02889959331564107
261.90000000000333,23.677572916732483,0.41216850548916917,-0.029531901163928787
263.30000000000337,23.71962373931897,0.4124099775857646,-0.02954004529637455
264.70000000000334,23.76223906214397,0.4137454900044637,-0.029540051041304416
266.1000000000034,23.80434401921376,0.4149076758791703,-0.029540022891862527
267.5000000000034,23.846546847271018,0.4147420684637131,-0.029533857523780238
268.9000000000034,23.888756376443556,0.41490426435082056,-0.030853788504939583
270.3000000000035,23.93077580527629,0.4149549435877022,-0.030859957405412697
271.70000000000346,23.97322859811207,0.4150019174327021,-0.030859942107420935
273.1000000000035,24.015267847453515,0.4155530603666605,-0.030859225573292903
274.5000000000035,24.057400015221113,0.4163827301482051,-0.03054869275833827
275.9000000000035,24.09967224111029,0.41842832520134515,-0.0298693892095665
277.30000000000354,24.14181278573073,0.41961947083340534,-0.029869996912641472
278.70000000000357,24.183905564925617,0.42039403959611654,-0.03126633893820063
280.10000000000355,24.226243217172378,0.422757984807779,-0.031180451588823654
281.50000000000364,24.26857284788725,0.42253984199745925,-0.031179944425368422
282.9000000000036,24.31113633714235,0.4233554203275405,-0.031179943002160204
284.30000000000365,24.352850026521917,0.42274557227295895,-0.031179942999988608
285.7000000000037,24.39542627107389,0.42440820542805197,-0.031179943000232857
287.10000000000366,24.437872483865938,0.42541136674320523,-0.03117994304125249
288.5000000000037,24.480157613444316,0.4271857721826198,-0.031179942158105156
289.90000000000373,24.52199381283842,0.4279665459466281,-0.031177189850802645
291.30000000000376,24.564454140563914,0.4290491004623729,-0.032418017242647146
292.70000000000374,24.607164485054344,0.42723420054565975,-0.03249975834389707
294.1000000000038,24.648988566854726,0.4291985964382906,-0.032499856422774975
295.5000000000038,24.691489841160934,0.4302886800015689,-0.032498459256827594
296.90000000000384,24.73374407223317,0.4313141683641821,-0.031867226221073075
298.3000000000038,24.776254132473184,0.43115789624566353,-0.03184992802560105
299.70000000000385,24.81874701724187,0.43156412191051097,-0.03184983529500318
301.1000000000039,24.86112217563995,0.4331678842462386,-0.03184983555146559
302.5000000000039,24.903697837029608,0.43336705225768585,-0.03185195977146371
303.9000000000039,24.946047876806634,0.4337215750131649,-0.032887494216103264
305.30000000000393,24.988168309485026,0.43476694495041524,-0.03318021924249681
306.70000000000397,25.030974051975107,0.43474793933697464,-0.03315917508655941
308.100000000004,25.073176004967234,0.4349516593221483,-0.034081572987802566
309.500000000004,25.11580249626506,0.43528861033385424,-0.03446944960765608
310.900000000004,25.158190689952047,0.4355899818546274,-0.034470148934545364
312.30000000000405,25.201028393404673,0.4374039808636645,-0.03447022742461314
313.7000000000041,25.243428762484605,0.4382687751953723,-0.033791520753241766
315.10000000000406,25.28604434771766,0.4390330668282425,-0.03316150206528201
316.5000000000041,25.328427943615733,0.4408629512664325,-0.033176657249606833
317.9000000000041,25.370834689221848,0.44285651707933976,-0.03446902485087833
319.30000000000416,25.41360663757933,0.4421387579517947,-0.03445783202217312
320.70000000000414,25.456206049077863,0.4413787106087069,-0.033153691040390676
322.1000000000042,25.498816852793716,0.44153097564441635,-0.033161980573872984
323.5000000000042,25.5415080138393,0.4409707098961919,-0.034473962544947945
324.90000000000424,25.58404889598189,0.4427692053963781,-0.034470025680493954
326.3000000000042,25.625989485024874,0.4418165403861135,-0.03447015034749734
327.70000000000425,25.66938286517643,0.4424428591260304,-0.03447015099497808
329.1000000000043,25.71215747343196,0.44345955611154075,-0.03447015095903172
330.5000000000043,25.75472868004466,0.4432287861461194,-0.03447038315309037
331.9000000000043,25.797418114576363,0.44363711092544034,-0.03347834624355617
333.30000000000433,25.840417184054413,0.44339490595753345,-0.033502085697074246
334.70000000000437,25.882884514387236,0.4443775692605247,-0.03543277470554207
336.1000000000044,25.92557069046787,0.4446799597383287,-0.03545996503630322
337.5000000000044,25.968406867692273,0.44365957097092135,-0.035466714567861324
338.9000000000044,26.011412459537553,0.44620984767284777,-0.03579169627047829
340.30000000000445,26.054396432322882,0.44610006188274565,-0.03579342790904727
341.7000000000045,26.09715630350174,0.44620638937572965,-0.034502799247650984
343.10000000000446,26.139908930503847,0.44894032678749307,-0.034473580262424974
344.5000000000045,26.182879052410872,0.4488423839859699,-0.035793190936216135
345.9000000000045,26.22556004741004,0.4477647882963569,-0.03579007286170066
347.30000000000456,26.26897975464129,0.448406968516171,-0.03578991756646399
348.70000000000454,26.311900340128336,0.4494348007304433,-0.0354874565326746
350.10000000000457,26.354894354986758,0.44982198098765724,-0.034481548129375206
351.5000000000046,26.398003603772597,0.45011843492481884,-0.03537716426335269
352.90000000000464,26.440928390643144,0.45138455563539603,-0.035789486623575506
354.3000000000046,26.483979978259725,0.45355734600491593,-0.03579004475227565
355.70000000000465,26.52718069973986,0.45286898614629484,-0.035790042829650925
357.1000000000047,26.570062368371353,0.4524388921870639,-0.03579004439182354
358.5000000000047,26.613059020269354,0.45261939892530045,-0.035816627796076084
359.9000000000047,26.655575563803513,0.4564996293589142,-0.03711579413610977
361.30000000000473,26.699547584370855,0.4541568200793745,-0.03710993765830217
362.70000000000476,26.74266962372212,0.4547826065595196,-0.03711020239057028
364.1000000000048,26.786044242844266,0.45554854807614276,-0.03720852836805921
365.5000000000048,26.828928954180654,0.45541721751786335,-0.03579031882122008
366.9000000000048,26.871903941807098,0.45521685641652754,-0.03578234458686902
368.30000000000484,26.915406135235678,0.4575334883791565,-0.03674279955183746
369.7000000000049,26.958776322769758,0.4569025171001806,-0.03582384599613775
371.10000000000485,27.002145188831967,0.4579298805259626,-0.035799972478158804
372.5000000000049,27.04548582322225,0.46090220480352717,-0.03579993484887334
373.9000000000049,27.08855587171308,0.45965991896266367,-0.03579994009322407
375.30000000000496,27.131756529053273,0.46361142256283194,-0.03580071704543286
376.70000000000493,27.175234013997752,0.463517057803577,-0.036586266841649895
378.10000000000497,27.21835467607671,0.4641939479154338,-0.037109768406621946
379.500000000005,27.26193336498131,0.4648842169317143,-0.03793290074613331
380.90000000000504,27.30500494934699,0.46510370933196366,-0.03842901929545617
382.300000000005,27.34812836357143,0.4678324894951659,-0.03842982536807327
383.70000000000505,27.39202742084083,0.46969522970584127,-0.03842982368625325
385.1000000000051,27.43513768025789,0.47194687445694,-0.03842827093412815
386.5000000000051,27.478924311552674,0.4705579704189586,-0.0370900757141972
387.9000000000051,27.522090251539645,0.47249507174508026,-0.037110044346787774
389.3000000000051,27.565496684108556,0.4747895763814597,-0.03710994527105216
390.70000000000516,27.608674492302203,0.47413125461075745,-0.0371111305445857
392.1000000000052,27.652314695342994,0.4763279823819133,-0.038408694084421935
393.5000000000052,27.695522947405884,0.4766720492904693,-0.039151820921079494
394.9000000000052,27.73921453937658,0.4812530236537119,-0.03909015850157482
396.30000000000524,27.78277487318158,0.4793572952203534,-0.039089827176880476
397.7000000000053,27.825969980514582,0.47694710941864943,-0.03908982699757857
399.10000000000525,27.869783980908878,0.4792595797204492,-0.03908982700042296
400.5000000000053,27.91297563301615,0.48016252261479364,-0.03908982548768947
401.9000000000053,27.95671452372653,0.4812769599503386,-0.03908933540136328
403.30000000000535,28.000315155862474,0.4835902462699264,-0.039108433960064026
404.70000000000533,28.043754439002992,0.48405561477432546,-0.04040056061875319
406.10000000000537,28.087512768033612,0.4855976689888023,-0.040387437021729866
407.5000000000054,28.131059627799498,0.4873185413925415,-0.039096225901250836
408.90000000000543,28.17477289029096,0.4858056584187074,-0.03909153513741703
410.3000000000054,28.2184750670908,0.48617503251943206,-0.03992342089841294
411.70000000000545,28.262221070862175,0.49163887659706795,-0.04107259228988136
413.1000000000055,28.305669683715976,0.4905638013936957,-0.041060050307364815
414.5000000000055,28.349437772868605,0.49359943758969066,-0.0410601426605548
415.9000000000055,28.393061025103883,0.49439206921159096,-0.04106014300016669
417.3000000000055,28.43713805819858,0.4969958683525088,-0.04106014299916172
418.70000000000556,28.480582896666466,0.49967391417614193,-0.041060143072741084
420.1000000000056,28.52452319438532,0.49953338929882185,-0.04106025464513596
421.50000000000557,28.568304827407875,0.5038611078892477,-0.04107683636589998
422.9000000000056,28.611988092936844,0.5078298496134556,-0.041759259073783195
424.30000000000564,28.655841271217675,0.5098470761281688,-0.041719691259207714
425.7000000000057,28.69971649498132,0.5118701239435403,-0.04171978165443546
427.10000000000565,28.743685535370425,0.517968566865453,-0.04174642472521706
428.5000000000057,28.787127751175195,0.52005720093408,-0.04304394293493008
429.9000000000057,28.831540292313406,0.5219078293409223,-0.043040040601381335
431.30000000000575,28.87538614663231,0.5248440901628413,-0.043040034980427855
432.70000000000573,28.91920447852591,0.5284613332403121,-0.043040035285021094
434.10000000000576,28.96316006564855,0.5282053821589381,-0.04303971547039698
435.5000000000058,29.007318435426356,0.5269478012418979,-0.04296036685639937
436.90000000000583,29.050848841171785,0.5254921023005601,-0.04436020407600916
438.3000000000058,29.09448452885534,0.5252755323906048,-0.04435993025416085
439.70000000000584,29.139178306050205,0.5235623560082363,-0.04435992640584363
441.1000000000059,29.183288477478936,0.5215537163004498,-0.04436064061178158
442.5000000000059,29.227382319602455,0.5202074529427758,-0.044805202433418234
443.9000000000059,29.271404071073036,0.5185291798121919,-0.0456791920248083
445.3000000000059,29.31536327275549,0.5195913673523905,-0.04567999273103762
446.70000000000596,29.35938195331147,0.5168851546354561,-0.045690760957591614
448.100000000006,29.40361481278336,0.5187625077855693,-0.04534951976000423
449.50000000000597,29.4478075243277,0.5201322212508153,-0.044812694460648395
450.900000000006,29.491924677077538,0.5197463138976278,-0.04468964308263246
452.30000000000604,29.536251031686653,0.5200781310744079,-0.04470517866681423
453.70000000000607,29.580435903688613,0.5229926236389817,-0.04599660873408018
455.10000000000605,29.624877297440005,0.5241632881156326,-0.04600409588930887
456.5000000000061,29.66920363383616,0.5252374083850717,-0.04735965368780626
457.9000000000061,29.713408761756757,0.5264074357778943,-0.04731981338172453
459.30000000000615,29.75809563303128,0.5283922894377946,-0.04731980671788749
460.7000000000061,29.80260724307163,0.5323394195963591,-0.04731962980870019
462.10000000000616,29.846871457143727,0.5356703195522416,-0.046814999957063286
463.5000000000062,29.891333638781177,0.5378953216340748,-0.047320105071087415
464.90000000000623,29.935761210308733,0.5391105827537233,-0.04731209482081944
466.3000000000062,29.98009757190132,0.5439848562723258,-0.0459947799488738
467.70000000000624,30.02517883945814,0.5465163368710559,-0.04736512648167679
469.1000000000063,30.06955546802481,0.5499276512755955,-0.04732001992612167
470.5000000000063,30.114532736139683,0.5563903268899782,-0.047320035549095696
471.9000000000063,30.159036638821377,0.5585920838453117,-0.04728241551823631
473.3000000000063,30.203687541940827,0.5600362882162575,-0.04863516812284718
474.70000000000636,30.248579512876113,0.5651082168801034,-0.04863982167746528
476.1000000000064,30.292867120920906,0.5679322588501716,-0.048776636459625156
477.50000000000637,30.338066909370994,0.5731549700094548,-0.04996128875442585
478.9000000000064,30.382542924188666,0.5758981710007791,-0.04995988785257799
480.30000000000643,30.427401604167184,0.5821123357357649,-0.049959892333867106
481.70000000000647,30.472555839559423,0.5846855479326681,-0.04995975635550032
483.10000000000645,30.51711220945107,0.5866583054970922,-0.04991164586058705
484.5000000000065,30.561916657251416,0.587688060610339,-0.05127256506595668
485.9000000000065,30.606775422029315,0.5924640832536847,-0.05126982060700502
487.30000000000655,30.65131396310222,0.5957442723671897,-0.0512698090210284
488.7000000000065,30.696468940761953,0.5979142030756042,-0.0512698160083338
490.10000000000656,30.741396227874645,0.6026824102576968,-0.05126533122541099
491.5000000000066,30.78651243458224,0.6069874543375264,-0.05257222927758898
492.9000000000066,30.831311825370552,0.6108812760894593,-0.05394508739640136
494.3000000000066,30.87644150411277,0.6109579055961671,-0.05391873126317215
495.70000000000664,30.92147789647919,0.6173233792908894,-0.052392471061524226
497.1000000000067,30.966305637879902,0.6209304182827593,-0.05299195022270853
498.5000000000067,31.01116100230239,0.6216173234165155,-0.05236538217424691
499.9000000000067,31.056629251510092,0.626365903891064,-0.05236970858672896
501.3000000000067,31.101542943024292,0.6293918278048312,-0.05242535166097273
502.70000000000675,31.146635376867113,0.6312407269658116,-0.05497688569492354
504.1000000000068,31.191434503479904,0.6351307809624075,-0.05500989133453249
505.50000000000676,31.236618137615388,0.6391748902108543,-0.055009883917233715
506.9000000000068,31.281619755202303,0.6415073264469733,-0.05500992424161755
508.30000000000683,31.326707949605336,0.6433872133765188,-0.0550342726925952
509.70000000000687,31.37172262682664,0.6420095752741664,-0.056323120795707116
511.10000000000684,31.416918955478042,0.6437733636022798,-0.05800405929648367
512.5000000000068,31.462051531130115,0.6455352737733631,-0.057970033264961085
513.9000000000069,31.507264005325965,0.645072332745839,-0.0579700922059696
515.300000000007,31.552298395374276,0.6477372215862324,-0.05796994326780247
516.7000000000069,31.597467371744575,0.6473612776882867,-0.059091163882512454
518.100000000007,31.64235143298322,0.6466653264381088,-0.059290428506263204
519.500000000007,31.687781750915665,0.6503378592049227,-0.05928407892605403
520.900000000007,31.733037463642987,0.6477839278743418,-0.060616404472694896
522.300000000007,31.77822911532488,0.6503093236576424,-0.06060846149182719
523.7000000000071,31.8232040115923,0.649827578982226,-0.059269781940149535
525.1000000000071,31.86842296264203,0.6507599203405627,-0.05903466565773474
526.500000000007,31.913870401110497,0.6496960125496046,-0.06156227465607067
527.9000000000071,31.958818340816748,0.6502426349172804,-0.062139633874069844
529.3000000000071,32.00418240774688,0.6515156325167699,-0.06216108647546559
530.7000000000071,32.0495341222455,0.6537079119251517,-0.06346044900390924
532.1000000000072,32.09448010565822,0.6571551985415996,-0.06345930680143219
533.5000000000072,32.13987041429344,0.6541476939775799,-0.06275514236513802
534.9000000000071,32.18523942478051,0.6601252359417964,-0.06379596255935338
536.3000000000072,32.23044641471029,0.6595470707640142,-0.06378996585088137
537.7000000000073,32.27580296097213,0.6626748758330498,-0.065190519714311
539.1000000000072,32.3212399559376,0.664191708305741,-0.06511003513069946
540.5000000000073,32.366203945191515,0.6699831793619282,-0.06511009414923441
541.9000000000073,32.41171831790428,0.6720902725468324,-0.0651052354926085
543.3000000000073,32.45699347426135,0.6741099486469593,-0.06646245600832312
544.7000000000073,32.50228031819887,0.6770952226245113,-0.06773824208364987
546.1000000000074,32.54801037717195,0.6809679549944156,-0.06769321419360885
547.5000000000074,32.5932525497623,0.6821701103345325,-0.06840050614128668
548.9000000000074,32.63842615123168,0.6844680239416259,-0.06839991781055144
550.3000000000075,32.68398090354687,0.6878159684875331,-0.06840004266374189
551.7000000000074,32.72930658753188,0.692632126043869,-0.06867595733739362
553.1000000000074,32.7746259208726,0.6965299596540331,-0.06973018544135634
554.5000000000075,32.82046179480816,0.7018199511196259,-0.0710367434432575
555.9000000000075,32.86580737676451,0.7050008394484475,-0.07197658124522377
557.3000000000076,32.91124152163883,0.7086355998085079,-0.07234877528948758
558.7000000000075,32.95663112116099,0.7126196364883634,-0.07365165899780646
560.1000000000075,33.00220659952522,0.7141504922278328,-0.07366994877676625
561.5000000000076,33.04741239743626,0.7193517992254164,-0.0736699260055369
562.9000000000076,33.093155838164115,0.7240211485093964,-0.07366541856294262
564.3000000000076,33.138273824796265,0.7282081130706165,-0.07497966143637713
565.7000000000077,33.18403672091391,0.7337163151659074,-0.07519386170031161
567.1000000000076,33.229400078646584,0.7362195470181392,-0.0763004847599289
568.5000000000077,33.275208971012944,0.7407640453031317,-0.0763015150298858
569.9000000000077,33.320279260946634,0.7493209248740501,-0.07704104865691175
571.3000000000077,33.366343397100636,0.7508245541373468,-0.07697409100842556
572.7000000000078,33.41183129437838,0.7571316841471605,-0.07826911586132912
574.1000000000078,33.457719197385686,0.7664858968328739,-0.07904618689883058
575.5000000000077,33.503612761113786,0.7714782831528209,-0.07959967010555768
576.9000000000078,33.54899806080554,0.7754802054586584,-0.07959979702791253
578.3000000000078,33.59499100303886,0.7778654085374043,-0.07966019877725294
579.7000000000079,33.6405671626253,0.783321902772425,-0.07959818019094733
581.1000000000079,33.68634116844152,0.7851323548992776,-0.08090592511788985
582.5000000000078,33.732216862540966,0.7890908217622641,-0.08223507386226725
583.9000000000079,33.77793972192703,0.7995992154544489,-0.08474593935683483
585.3000000000079,33.823648509801444,0.8018513982619849,-0.08518772203620761
586.7000000000079,33.86986847047586,0.8068362882606299,-0.08618008202681393
588.100000000008,33.91585255242378,0.811776817550842,-0.08673489538601453
589.500000000008,33.961770963769915,0.8178976322489114,-0.08686034222737682
590.900000000008,34.007655593323456,0.8244156043281028,-0.08740486013479698
592.300000000008,34.05355918424791,0.8309090443348708,-0.08749263333806523
593.700000000008,34.09976911288241,0.8384252453022136,-0.09009334886253262
595.1000000000081,34.145841461829974,0.8416985179547796,-0.09168450600215072
596.5000000000081,34.19184251077277,0.8493383518347697,-0.09149905718779783
597.900000000008,34.23761422569322,0.8562753001810938,-0.09119351244220208
599.3000000000081,34.28415518177173,0.8571239012079128,-0.09165412243118709
600.7000000000081,34.3303873409726,0.8641848418616126,-0.09276963518833004
602.1000000000082,34.37616189540373,0.8717570101042664,-0.09376311473303245
603.5000000000082,34.42232522611719,0.8745475846033116,-0.09493223818900542
604.9000000000082,34.468518210063785,0.8785423515466987,-0.09539931885471242
606.3000000000083,34.51459745948997,0.883136463418912,-0.09680617167443772
607.7000000000082,34.56099612906717,0.8850860529618432,-0.09713749326909804
609.1000000000082,34.60708837573595,0.8886132832713279,-0.09803153506701223
610.5000000000083,34.65332851968877,0.8907322832803806,-0.09936822638903342
611.9000000000083,34.699549276362234,0.8924744118823241,-0.10030132218955279
613.3000000000084,34.74573649077062,0.8912882199567903,-0.10230987914916767
614.7000000000083,34.79144872502594,0.892565022758239,-0.10299116514933715
616.1000000000083,34.838092066524275,0.895046160332182,-0.10352470166310557
617.5000000000084,34.88415726263479,0.8954899580544644,-0.10489783019520038
618.9000000000084,34.93033851029026,0.8961904969835229,-0.10484499556637328
620.3000000000084,34.97631940097602,0.8968434112470938,-0.10620958794040236
621.7000000000085,35.0229046547772,0.9000972385902026,-0.10767614214258225
623.1000000000084,35.06920082325448,0.9004694142795945,-0.11076170690528198
624.5000000000085,35.115352496106375,0.9034008425850557,-0.11284548211267431
625.9000000000085,35.161380025101224,0.9059983654688036,-0.11006719879583793
627.3000000000085,35.2079649899988,0.9076887686670604,-0.11044907126029324
628.7000000000086,35.25435868914268,0.9128721076469579,-0.11177122002836315
630.1000000000085,35.3004861791829,0.9166038702610002,-0.113081750755335
631.5000000000085,35.34654742402659,0.924428928438287,-0.11307602414917595
632.9000000000086,35.392834793202155,0.9296738195879866,-0.11444537093318186
634.3000000000086,35.43950114912673,0.9366427965660251,-0.11469872365183198
635.7000000000087,35.485673762225105,0.9421218552872159,-0.116974253796708
637.1000000000087,35.532030314479755,0.9444901225396686,-0.11843290626301473
638.5000000000086,35.57818318351372,0.9507399930805726,-0.12070517521430446
639.9000000000087,35.62459780145074,0.9610480202676704,-0.12123503729808016
641.3000000000087,35.67100740048715,0.9686929440206015,-0.12135471595219327
642.7000000000087,35.717284374845974,0.9740808030846728,-0.12264596319240484
644.1000000000088,35.763647180276834,0.9799010266802455,-0.12524986784437075
645.5000000000088,35.80975284123072,0.9875453402727424,-0.1265926913521187
646.9000000000088,35.856471321451686,0.9920422117688672,-0.12784190745402135
648.3000000000088,35.90290316364676,0.9942597579148257,-0.12825552181468947
649.7000000000088,35.94898607337124,1.00259138118566,-0.12955702959117854
651.1000000000089,35.99523824903264,1.0077162978592542,-0.13088162955720906
652.5000000000089,36.0419025661288,1.0116588399213005,-0.13219413362258692
653.9000000000088,36.088308706427206,1.020454105104271,-0.13357557202691428
655.3000000000089,36.13452456862874,1.0296599474228338,-0.1351464937404745
656.7000000000089,36.18091605298284,1.0400829114357653,-0.13753750221286776
658.100000000009,36.22756048427845,1.048166806252152,-0.13925669633485915
659.500000000009,36.273984259150986,1.0578476060533524,-0.14003793968316103
660.900000000009,36.3203648036494,1.068158738785996,-0.14119941545045966
662.300000000009,36.36709785100741,1.0773017486423435,-0.14256333718524594
663.700000000009,36.41361818357724,1.0884497927545096,-0.14394013245565773
665.100000000009,36.460136242736915,1.103646717328464,-0.14788543905762186
666.5000000000091,36.50646064957142,1.119849524683919,-0.14841408741825024
667.9000000000091,36.553135104442795,1.1362204614716187,-0.14808884916697762
669.3000000000092,36.599865928641705,1.1580861568195306,-0.14952962713251283
670.7000000000091,36.64674784464853,1.1755131452948586,-0.15093964284695893
672.1000000000091,36.69319520714054,1.1942945911102902,-0.1535638815648932
673.5000000000092,36.73983025104361,1.2195726894528167,-0.15545711105698246
674.9000000000092,36.78683052849559,1.2404646443053928,-0.15813120315598805
676.3000000000092,36.83346150411974,1.2617300512349887,-0.1596781562664309
677.7000000000093,36.8800649348357,1.285386796371647,-0.16138462999766556
679.1000000000092,36.92717162977571,1.3097385257251153,-0.1645634747478737
680.5000000000093,36.9737723206955,1.337668009571414,-0.16696313945968377
681.9000000000093,37.02033016947186,1.3621894102449241,-0.16896193847280028
683.3000000000093,37.06668402897906,1.3884605084041728,-0.16942941051863736
684.7000000000094,37.114422105346044,1.4172158119737401,-0.17228790229054347
686.1000000000093,37.161122262856274,1.4422809811769843,-0.17534655894635076
687.5000000000093,37.20769059689746,1.4724036996147516,-0.1786038333687867
688.9000000000094,37.25422082346155,1.5023631392842054,-0.18189305222171814
690.3000000000094,37.30154024817987,1.5330208200477105,-0.18472532579236756
691.7000000000095,37.34890934569679,1.5677885767581774,-0.1871736773121757
693.1000000000095,37.39570609936166,1.5967248957980222,-0.1908824949810981
694.5000000000094,37.442695748482265,1.6300860750363924,-0.19400848852992159
695.9000000000095,37.489763915124904,1.6603230506995488,-0.19771168834335429
697.3000000000095,37.53628876619852,1.6947655226383678,-0.20180815300818278
698.7000000000095,37.58359773168039,1.7347166855955845,-0.2063713827315934
700.1000000000096,37.63080017415142,1.7687689294729279,-0.21094331586199822
701.5000000000095,37.67749408005189,1.8067350609142738,-0.2135786080387314
702.9000000000096,37.724574527453626,1.8470630953470053,-0.21712791412054377
704.3000000000096,37.771487010832786,1.8915313025217735,-0.22117088876049218
705.7000000000096,37.81856345394688,1.9353499845691524,-0.22429316811174882
707.1000000000097,37.86559861040979,1.981025889451605,-0.2288906332319507
708.5000000000097,37.9128518077434,2.0340756457493985,-0.234084228823503
709.9000000000096,37.95979839689966,2.0813822527763652,-0.2376698005053064
711.3000000000097,38.007228950039945,2.136929468802432,-0.24248878835345566
712.7000000000097,38.054272973308,2.1897726045452464,-0.24804160476707615
714.1000000000098,38.10141904043096,2.2499198066654356,-0.25435753580615206
715.5000000000098,38.14844947807621,2.308159600899088,-0.25854650161626846
716.9000000000098,38.195629917061815,2.3688134375868266,-0.2641956228039555
718.3000000000098,38.24289327832487,2.4276930379765544,-0.27019203143153714
719.7000000000098,38.29026469579063,2.4951126654283438,-0.27614195528132646
721.1000000000098,38.337374809479606,2.56437071245125,-0.28181796345715115
722.5000000000099,38.38499107446007,2.639103600120439,-0.2915452425368539
723.9000000000099,38.43251097990118,2.7119239359352347,-0.29811676837511136
725.30000000001,38.48000033956768,2.7888707483771986,-0.30311718086562767
726.7000000000099,38.5271680543273,2.875135819079122,-0.30990303557406085
728.1000000000099,38.574859708544665,2.963481092605398,-0.31862534330846026
729.50000000001,38.622511121297535,3.0508606415877098,-0.3246615249339855
730.90000000001,38.669630979604804,3.142436653249341,-0.3327139355816242
732.30000000001,38.71803756995153,3.239860894596365,-0.3416197814799533
733.70000000001,38.765617291263844,3.3433444807743995,-0.3504054892146202
735.10000000001,38.813260263756554,3.447550930738002,-0.35988594787230443
736.5000000000101,38.86113706494684,3.547941288898003,-0.3694241386159929
737.9000000000101,38.908637515863475,3.663724082018862,-0.3799172989427735
739.3000000000101,38.95631518046258,3.7789809310536735,-0.3896277471020113
740.7000000000102,39.005136366379205,3.8993678973043755,-0.3999795628742979
742.1000000000101,39.05305731778751,4.026845796233373,-0.40926964154381906
743.5000000000101,39.101044538307,4.1506718923590915,-0.41981427127363125
744.9000000000102,39.14908678659827,4.284452295250983,-0.4324758497216332
746.3000000000102,39.19669387973698,4.4162931439642925,-0.444570987674632
747.7000000000103,39.24519082196969,4.553758573452392,-0.45797936900511393
749.1000000000103,39.29322327380709,4.691270021802405,-0.4709701686929413
750.5000000000102,39.34173163746591,4.839378949238171,-0.48371007559302326
751.9000000000103,39.39003522728654,4.989772747730231,-0.4976534784107369
753.3000000000103,39.43815208814287,5.1431378418621705,-0.5115477110303361
754.7000000000103,39.48635022192685,5.29913388659289,-0.5265019410358645
756.1000000000104,39.53454411902373,5.459507235749598,-0.5421743366590972
757.5000000000103,39.58333192786157,5.6270863445382,-0.5582491513774324
758.9000000000104,39.631592138091925,5.798179009015478,-0.5734628729525806
760.3000000000104,39.680308493873,5.965329113176095,-0.591309528913325
761.7000000000104,39.728536485178545,6.140813580588847,-0.6086418985115225
763.1000000000105,39.77716151123172,6.319173107110512,-0.6265464771720297
764.5000000000105,39.82562389476979,6.494732490929381,-0.6455851703893045
765.9000000000104,39.874302255719115,6.679242239641088,-0.6652196247308653
767.3000000000105,39.923054407357405,6.861641204237361,-0.6851481835332924
768.7000000000105,39.97170498023133,7.047650464374365,-0.7042031039881018
770.1000000000106,40.0202394970966,7.228169981688062,-0.7240173867156332
771.5000000000106,40.06827431536252,7.407006308158271,-0.744944851432082
772.9000000000106,40.11725358271233,7.59587097485001,-0.7686245083342511
774.3000000000106,40.165995866976886,7.779491525908668,-0.7911409884267684
775.7000000000106,40.21441170700337,7.957677896399946,-0.8133872701657618
777.1000000000106,40.26301238854687,8.135111747141483,-0.836678696638947
778.5000000000107,40.311623088046524,8.306012685543758,-0.8622516893463081
779.9000000000107,40.359729424052134,8.461732721421255,-0.8877790321828725
781.3000000000108,40.40817932521274,8.612861682718481,-0.912983478056991
782.7000000000107,40.456486686888965,8.751924013896891,-0.9376286389824129
784.1000000000107,40.50450008818354,8.874383454007567,-0.9629391030746706
785.5000000000108,40.55238551094594,8.979755019652416,-0.9900318059184241
786.9000000000108,40.59999931855644,9.061779794533361,-1.0177772686772455
788.3000000000108,40.64768389020067,9.112347504473934,-1.0430023253914849
789.7000000000108,40.695113531120946,9.128748108180861,-1.068661900567721
791.1000000000108,40.741947580762776,9.09770807507615,-1.0943355817074192
792.5000000000109,40.788330143000586,9.019369634700716,-1.1215777286041186
793.9000000000109,40.83439952611202,8.889032748996193,-1.1478852571301559
795.3000000000109,40.88000032364387,8.687757059335238,-1.173700293166854
796.700000000011,40.924918291259935,8.415456527680064,-1.1966765656245246
798.1000000000109,40.96914914641606,8.056837883570799,-1.2193339057198114
799.5000000000109,41.012697563244814,7.572540686022699,-1.2405030764027254
800.900000000011,41.0547955479319,6.922168868242275,-1.2587828125711131
802.300000000011,41.09495633781585,6.067489376256845,-1.2756649075213535
803.7000000000111,41.13389057494861,4.99035583288256,-1.2880663361148028
805.100000000011,41.17185470926673,3.8026463009201574,-1.298945742115802
806.500000000011,41.21058923988122,2.7162989499389965,-1.3080387383388445
807.9000000000111,41.25076820007973,1.860495611155462,-1.3136115360780098
809.3000000000111,41.29294468795839,1.2711477888105376,-1.316030470616468
810.7000000000111,41.33694391097383,0.9061487356279101,-1.31778852096225
812.1000000000112,41.38225016119691,0.7029731050488279,-1.3170797081664718
813.5000000000111,41.42824368181848,0.6036582439822508,-1.3184224174339185
814.9000000000112,41.47475477451092,0.5581267197433986,-1.3183899457405461
816.3000000000112,41.52155796332148,0.5402055020763181,-1.3183900697714526
817.7000000000112,41.56882068880661,0.5366802324873114,-1.318363850983061
819.1000000000113,41.61563884773099,0.5326910852677427,-1.3180010179660209
820.5000000000113,41.662631874846255,0.5348236035425686,-1.3183914101248262
821.9000000000112,41.70989965405246,0.535530827777086,-1.3193711864797244
823.3000000000113,41.75681697778932,0.5339156872019939,-1.3197097838338676
824.7000000000113,41.803961181985585,0.5362803358016914,-1.3197098764373538
826.1000000000114,41.85153196573496,0.5377204473700694,-1.3197031265084163
827.5000000000114,41.89846799204176,0.5382608344171467,-1.3183950412359402
828.9000000000113,41.945378051547095,0.5400865891652749,-1.31976957885644
830.3000000000114,41.9927926199804,0.5386192593192387,-1.3197173307996017
831.7000000000114,42.04013388815962,0.5364925449966205,-1.3187360870108749
833.1000000000114,42.087276406050044,0.5359152445283637,-1.3187299118661997
834.5000000000115,42.134651505764566,0.5332663722023042,-1.3189661784767543
835.9000000000115,42.18197670922545,0.5287047510157368,-1.3200392904668918
837.3000000000116,42.22904825942342,0.5260028607051821,-1.3200400524608265
838.7000000000115,42.276565002820064,0.5280635524341081,-1.3200330354191654
840.1000000000115,42.3238680840129,0.5262357579509421,-1.3196242605518274
841.5000000000116,42.37115352004332,0.5239600246278531,-1.320696713015268
842.9000000000116,42.41842159420863,0.5199712693647301,-1.3203678863560229
844.3000000000116,42.46580762114002,0.5185505784818376,-1.319697820547467
845.7000000000116,42.513444283582665,0.519051197748048,-1.3199920880282376
847.1000000000116,42.56067109956785,0.5179613703597759,-1.3210297996038718
848.5000000000117,42.608185516862854,0.5218033694005332,-1.3210298378831489
849.9000000000117,42.65566804687823,0.5239054203453201,-1.3210317024478244
851.3000000000117,42.70309658353873,0.5223636959806559,-1.322221644948233
852.7000000000118,42.7506593232439,0.5227361227054178,-1.321023359854502
854.1000000000117,42.79791774205445,0.5162782209743982,-1.321032932575105
855.5000000000117,42.84513503836191,0.5156359168792329,-1.3219608823451239
856.9000000000118,42.89274073501121,0.5134749863096926,-1.3223529022779248
858.3000000000118,42.9401016525434,0.5097316543325087,-1.3236597643112629
859.7000000000119,42.98785950696422,0.507056274400278,-1.3236710482899214
861.1000000000118,43.03529661724662,0.5049264525836012,-1.3223539579742831
862.5000000000118,43.08266975028534,0.5041328133049682,-1.3223361821432182
863.9000000000119,43.13021889007337,0.5004897932787831,-1.3210443433925567
865.3000000000119,43.17778974879886,0.4969663748543478,-1.3220193047302944
866.7000000000119,43.22527923566027,0.4939311401687392,-1.3236696202482894
868.100000000012,43.27272407811212,0.49093875560645794,-1.3222934896352676
869.5000000000119,43.32036910833248,0.48762383835541767,-1.3227116159479557
870.900000000012,43.36777728242464,0.4844134674827607,-1.3236693178250785
872.300000000012,43.415420650839785,0.4817613881654478,-1.323671875189909
873.700000000012,43.462703742474304,0.481599217597415,-1.3248263448174007
875.1000000000121,43.510418865108456,0.47661624900714916,-1.3249860853363482
876.500000000012,43.55763676297239,0.4709865083647319,-1.323652506117591
877.900000000012,43.605204124150156,0.4688973547760912,-1.3236884463106926
879.3000000000121,43.652826364420086,0.4738962315153693,-1.3250224362826062
880.7000000000121,43.70036747363675,0.47012091547338275,-1.3249872290402598
882.1000000000122,43.7477147117361,0.46209338856975213,-1.3236517254931326
883.5000000000122,43.79503024573597,0.4627940434074965,-1.3225757020546256
884.9000000000121,43.84281756050966,0.4588765019370842,-1.322357746179362
886.3000000000122,43.890343036716146,0.4520514558933755,-1.3236671902970292
887.7000000000122,43.937578631891625,0.45256207591433484,-1.3236706726469687
889.1000000000122,43.98538161145421,0.4533054821664333,-1.3247480132363556
890.5000000000123,44.032836837599454,0.45039398572837963,-1.3249809547508646
891.9000000000123,44.08027004644865,0.44023901679404276,-1.3256617896847156
892.0000000000123,44.08368491605899,0.44019200216971843,-1.325924521842201