File: 01_Data/Cinder_Block/STA/N2/30K_min/Cinder_Block_STA_N2_30KData_230823_R1.csv
##Temp./Â°C,Time/min,DSC/(mW/mg),Mass loss/mg
28.1,15.38327326636095,-0.009174488477659448,0.011145594547104842
29.50000000000002,15.731672630035225,0.05012700855868424,0.0068615823278346255
30.90000000000004,15.891755063561263,0.09125272762140302,0.007031516349493394
32.30000000000006,16.00911989874432,0.12300315248443816,0.007932496992221871
33.70000000000008,16.10910315276822,0.1510649875749268,0.005428579762583929
35.1000000000001,16.196558729239,0.1755181071139975,0.008554821220768005
36.50000000000012,16.276262361308547,0.19895419084528654,0.0057732150228231305
37.90000000000014,16.350964713652488,0.21796520972292432,0.006242862652507952
39.30000000000016,16.421123576496345,0.23623710848802792,0.006036799832850548
40.70000000000018,16.487887013492404,0.2558897108468554,0.006343007369982168
42.1000000000002,16.55269822445686,0.27075220461801397,0.00569292971443236
43.50000000000022,16.614542669448443,0.2859769011160602,0.007586683783547876
44.90000000000024,16.675070943930674,0.2985984675902218,0.0036681651011996053
46.30000000000026,16.734190010945216,0.3114434536319661,0.004555475819294941
47.70000000000028,16.791073555431616,0.3232289439510685,0.004472908670722475
49.1000000000003,16.8478975690954,0.33428812409789943,0.004705103581717829
50.50000000000032,16.903558805525638,0.34719214884000804,0.004056361879311687
51.90000000000034,16.957751983046247,0.35728539031019046,0.0037957435988076327
53.30000000000036,17.0116190436584,0.3679148916053423,0.004047163869865145
54.70000000000038,17.065074185999773,0.37986125073202404,0.0037845253203352414
56.1000000000004,17.117870451268498,0.3872189155279333,0.0037235285012755526
57.50000000000042,17.169741067191968,0.3972399967792619,0.002016603466952205
58.90000000000044,17.221635739847674,0.40563583993102625,0.0043575682042291675
60.30000000000046,17.2727955775428,0.415428556998064,0.003605861066927396
61.70000000000048,17.323564004191812,0.4266553832938116,0.0025195047109800583
63.1000000000005,17.37415924766756,0.4315774128920702,0.0021923308020053156
64.50000000000051,17.424765508945377,0.4394213730576617,0.0019550103852310485
65.90000000000055,17.474608161494917,0.44760795657565966,0.0016323123455208588
67.30000000000055,17.523920448658384,0.45360753077854277,0.00045404908993962323
68.70000000000059,17.57383368972377,0.4583510567599305,0.0004704531691857028
70.10000000000059,17.62317509812936,0.4633795828605203,-0.002678664138618281
71.50000000000063,17.67198320163622,0.46592986999474006,-0.0034164867325925385
72.90000000000063,17.72131730420687,0.47133370577043876,-0.00257619193609937
74.30000000000067,17.770312267215186,0.47275441180438205,-0.002688791214284336
75.70000000000067,17.820000000000025,0.4757758690391687,-0.0026752832058205556
77.1000000000007,17.867636530996872,0.4743135844259362,-0.004063923271362846
78.50000000000071,17.917241607406496,0.47825414088190865,-0.00403192042018663
79.90000000000074,17.965202215078083,0.4785470445303486,-0.004073593865244085
81.30000000000075,18.01400898515732,0.4783135213744202,-0.004401951971614082
82.70000000000078,18.061768325117736,0.47912520216420273,-0.005512483880285579
84.10000000000079,18.11000000000003,0.4782037987283001,-0.006806896534733653
85.50000000000082,18.158003516150682,0.4801891311174328,-0.005577195815538616
86.90000000000083,18.205647645863795,0.4800522845709977,-0.006799714778775723
88.30000000000086,18.253003959779388,0.480597632267023,-0.006812336588948753
89.70000000000087,18.30063970348219,0.4791008208269305,-0.008106004295024505
91.1000000000009,18.348033212773085,0.4814549025106749,-0.008118182465761237
92.50000000000091,18.3952113025499,0.4785579909931943,-0.00941258733836392
93.90000000000094,18.442031410910648,0.4797779192867906,-0.010433975691857
95.30000000000095,18.489072505012814,0.47607632991410676,-0.009431626662413706
96.70000000000098,18.53637802904624,0.4762436956633438,-0.010756673094372005
98.10000000000099,18.582842814269604,0.47552607246545997,-0.011479944326825198
99.50000000000102,18.629289605216275,0.47301587551038915,-0.011410696855415736
100.90000000000103,18.67606161570652,0.470458039727196,-0.012030548871377889
102.30000000000106,18.72196047069385,0.47037076380494025,-0.012729331075200356
103.70000000000107,18.768275475192567,0.46810501187643916,-0.012742905964115536
105.1000000000011,18.815386820884253,0.46853798915488254,-0.012009355549784217
106.50000000000111,18.86123567635725,0.46583131487205165,-0.013041224967500042
107.90000000000114,18.907758972443855,0.465816634357089,-0.014374648919744715
109.30000000000115,18.953744982131347,0.46140297602564173,-0.014368489800967055
110.70000000000118,18.99990246317529,0.45949328609302087,-0.015023103137715488
112.10000000000119,19.045696878602257,0.45913773525320634,-0.016351586500210402
113.50000000000122,19.091761106382165,0.4581667486804134,-0.016341150477014565
114.90000000000123,19.1381424775254,0.4570937033484599,-0.01767600906055211
116.30000000000126,19.182910890357114,0.4541751770094089,-0.017659688216278724
117.70000000000127,19.22942232364986,0.4509510404026916,-0.01636000089641243
119.1000000000013,19.275501320514362,0.4489448415549976,-0.01766390337709467
120.50000000000131,19.320557777335395,0.44955462257939804,-0.017670079544637396
121.90000000000134,19.36685450439104,0.44739420237198657,-0.017699095376833007
123.30000000000135,19.411997521834685,0.44559415098990907,-0.017999785345240937
124.70000000000138,19.45747338131617,0.4441640167115022,-0.01796913262397659
126.10000000000139,19.50283470925738,0.44171704585454796,-0.018984666667900107
127.50000000000142,19.54782525903809,0.44082161205051806,-0.01898000696648161
128.90000000000143,19.593125790231525,0.43880397413045336,-0.018980149715901895
130.30000000000146,19.638011755928808,0.4365779872205594,-0.018920674988207153
131.70000000000147,19.682587366633978,0.4342208641415478,-0.020299379746085755
133.1000000000015,19.727128487153156,0.43279446304163405,-0.02030001883910515
134.5000000000015,19.77135617985773,0.4337334547939622,-0.020300009361361226
135.90000000000154,19.816959919113728,0.4306515458901319,-0.020295633833090854
137.30000000000155,19.861275659570516,0.4292773891346229,-0.020950441691413246
138.70000000000158,19.906043979677012,0.4287555394679885,-0.02096853079392691
140.1000000000016,19.94990636948612,0.42699785168861226,-0.02228609368762413
141.50000000000162,19.99442195859566,0.425078842410925,-0.022280148269686606
142.90000000000163,20.038596446065498,0.42467497151352573,-0.02228015194465538
144.30000000000166,20.08281530480956,0.4221839749699766,-0.02228015200007416
145.70000000000167,20.126686792513052,0.420106325486252,-0.02228015203757927
147.1000000000017,20.17080755959565,0.42029001978228836,-0.022280147983107845
148.5000000000017,20.214858142164662,0.4185814221954698,-0.022275407970706596
149.90000000000174,20.2584290428261,0.41705336665515974,-0.02360659552637223
151.30000000000175,20.302355567228375,0.4159504159116852,-0.024922454507272818
152.70000000000178,20.34624334086132,0.4118762644844736,-0.02491995052934204
154.10000000000178,20.388992000580735,0.41390720489941335,-0.024920021178659546
155.50000000000182,20.43325307171496,0.4095833172079563,-0.02491970722057868
156.90000000000182,20.47755637676407,0.4095690214941586,-0.024618483119001944
158.30000000000186,20.52091779144563,0.40579986115281685,-0.022279644297567458
159.70000000000186,20.5645968600636,0.4031570446192291,-0.023279541395368142
161.1000000000019,20.60775067626095,0.4052582742449071,-0.024907392458347388
162.5000000000019,20.651677070259435,0.40153717035309067,-0.024917760612724216
163.90000000000194,20.695060010945454,0.40020963995732617,-0.02617045732598644
165.30000000000194,20.738640350520715,0.3972136974318704,-0.026239844300346427
166.70000000000198,20.781351267809924,0.3950789911419684,-0.026239888151208923
168.10000000000198,20.82556813728196,0.3941733132362142,-0.02623988800099486
169.50000000000202,20.86858380636472,0.3934271001178002,-0.026239888000074707
170.90000000000202,20.912287198667943,0.3929019408127181,-0.026239887983473764
172.30000000000206,20.955253476286174,0.3912022025878122,-0.026239876170752297
173.70000000000206,20.998850027379074,0.38988277164790336,-0.026238121826428262
175.1000000000021,21.04171284536548,0.38815667885379596,-0.02655381392693812
176.5000000000021,21.08544179159277,0.38528514946156633,-0.026561017417310318
177.90000000000214,21.127936931505563,0.38536999622498636,-0.02707255450498014
179.30000000000214,21.170933120960527,0.3838011485629355,-0.02828094278485782
180.70000000000218,21.214036368733275,0.3828965300841761,-0.02889641134198584
182.10000000000218,21.257251794175865,0.38130675543636483,-0.02886015992483415
183.50000000000222,21.30021965044228,0.381207470163546,-0.028860059969661123
184.90000000000222,21.3428369200033,0.37994375759699,-0.02886006001334973
186.30000000000226,21.385828578787663,0.37794800845233606,-0.028860064660230833
187.70000000000226,21.428781512801415,0.3786141994425994,-0.028860605622959667
189.1000000000023,21.47172628078638,0.3772295360866509,-0.029663913535551423
190.5000000000023,21.514431188948667,0.3767643553736178,-0.03017890247165589
191.90000000000234,21.557151399424022,0.3758323827438327,-0.030179940667462546
193.30000000000234,21.599907663211212,0.376711491456555,-0.030177161433492472
194.70000000000238,21.642616060873802,0.37523198363044835,-0.031152688273686557
196.10000000000238,21.685240197722674,0.3760244700250954,-0.03116986463347171
197.50000000000242,21.727738999204693,0.3742255130510032,-0.031169927927651386
198.90000000000242,21.770217190163297,0.371997119867865,-0.031169945779308428
200.30000000000246,21.81284273336858,0.37361064048988124,-0.031176350044541223
201.70000000000246,21.854623567057843,0.37289127874789185,-0.030127085055018377
203.1000000000025,21.897467899763306,0.37250017783036693,-0.0309129690511174
204.5000000000025,21.94061793170629,0.37266802613998457,-0.03150016440173786
205.90000000000254,21.983105783738473,0.3694775512537489,-0.031500199822944275
207.30000000000254,22.0257578417314,0.37111951650370845,-0.03150026031566178
208.70000000000258,22.068341295891837,0.36856840004154356,-0.03150334266042343
210.10000000000258,22.110735040253353,0.3698802772877516,-0.03280667750007016
211.50000000000261,22.153138138146314,0.3687801589456453,-0.03281917944958135
212.90000000000262,22.19552974922683,0.36927359924174175,-0.03232858479511069
214.30000000000265,22.237858558907313,0.36790896171639365,-0.03150006601479749
215.70000000000266,22.280515098779222,0.3678780772122442,-0.03150020574077317
217.1000000000027,22.323092425457386,0.36548297476429137,-0.03150157824307609
218.5000000000027,22.365339791602207,0.36589857919549335,-0.03205749829246951
219.90000000000273,22.407918890798392,0.36708336226473504,-0.03314982867662142
221.30000000000274,22.45045308308723,0.3644967484950625,-0.033150024670119294
222.70000000000277,22.492719012760073,0.3660388658645719,-0.0331500001425189
224.10000000000278,22.53520603381913,0.36315848717651344,-0.03314999987483791
225.5000000000028,22.57676286102534,0.36298326924435964,-0.03314999951931963
226.90000000000282,22.61993878319824,0.3590710351700981,-0.03315948921885514
228.30000000000285,22.66234282902554,0.3591662216512129,-0.03379178736557886
229.70000000000286,22.704683885157966,0.3572301519507184,-0.03381054577589282
231.1000000000029,22.746714098402958,0.35942053275483893,-0.03404062961801824
232.5000000000029,22.789308536361197,0.35577500609312046,-0.03413998827476927
233.90000000000293,22.83126784202617,0.3550280366522526,-0.0341403915483216
235.30000000000294,22.87386786418168,0.35571056020715774,-0.03313729509504526
236.70000000000297,22.9160561702414,0.35410345269580973,-0.03282036522075771
238.10000000000298,22.95832442513413,0.3535677843811446,-0.03282014089540297
239.500000000003,23.000433697772532,0.3523826545112801,-0.03286159150049528
240.90000000000302,23.042814184998655,0.35142388164290983,-0.03542686116611726
242.30000000000305,23.08518523402604,0.3511498839198134,-0.03544971382609052
243.70000000000306,23.1271739371872,0.3483245792531974,-0.03544983555874115
245.1000000000031,23.16928041199298,0.3489619076141882,-0.0354498359987776
246.5000000000031,23.211184598299386,0.34790342655966217,-0.03544983585315986
247.90000000000313,23.25370467761982,0.3496140430617142,-0.03544980560987465
249.30000000000314,23.29635098488795,0.3466099177165196,-0.03544934650081366
250.70000000000317,23.338222627791957,0.3460982799048697,-0.03677650883197714
252.10000000000318,23.380439252245353,0.3436577484859743,-0.0367675829355969
253.5000000000032,23.422329574381926,0.34398504173857863,-0.035396303517058136
254.90000000000322,23.464979061028455,0.3425436025316682,-0.036813769810369656
256.30000000000325,23.50709630942544,0.34273107638142514,-0.03677000414671028
257.70000000000323,23.54934768970846,0.342483718620062,-0.03659379757639414
259.1000000000033,23.591641943060896,0.34310109279593143,-0.03544712705464814
260.5000000000033,23.633451894467946,0.3411430915845435,-0.03544466578549166
261.90000000000333,23.67581755484956,0.33867514732054615,-0.03677307405471719
263.30000000000337,23.7181054366667,0.3400388153654762,-0.0375839039833501
264.70000000000334,23.760594193564508,0.33874070227550723,-0.038089925748752584
266.1000000000034,23.80271048616179,0.33833082262855735,-0.03808996837547962
267.5000000000034,23.84463079300886,0.336600158519256,-0.03808940275978667
268.9000000000034,23.88690501493661,0.3357677041590202,-0.03737881474617932
270.3000000000035,23.92919332856952,0.3349505534430772,-0.037429601980314864
271.70000000000346,23.97118883460635,0.3354429446838652,-0.037429974704596525
273.1000000000035,24.013508630726363,0.3325987004220674,-0.03743010528644852
274.5000000000035,24.05576035344598,0.33303278595062724,-0.03746397442722316
275.9000000000035,24.097931420946185,0.33283792288447295,-0.037094807866792756
277.30000000000354,24.140092275429087,0.33009247433642847,-0.03835857410816956
278.70000000000357,24.182331519112328,0.33134112108339664,-0.038419872386273646
280.10000000000355,24.2245630074212,0.33054311659086116,-0.038433669311458196
281.50000000000364,24.267111143195407,0.3300073115047245,-0.039419468699036564
282.9000000000036,24.309133319329824,0.32950411146924163,-0.039496965671751205
284.30000000000365,24.351622193950956,0.3286055816772418,-0.03809135781678297
285.7000000000037,24.39361375270657,0.3280245292040465,-0.03809010449467909
287.10000000000366,24.436187942351157,0.32691169324489977,-0.03809863002544045
288.5000000000037,24.47844832945676,0.3269872595283796,-0.039416944084732286
289.90000000000373,24.520945330685922,0.3245064559112491,-0.03941013471965693
291.30000000000376,24.563197348104033,0.32286943364446963,-0.03941010337575879
292.70000000000374,24.60525889241506,0.32401172952888446,-0.03940767216660657
294.1000000000038,24.64764605378599,0.3260788127283409,-0.03975706269948187
295.5000000000038,24.690317226201955,0.3228927093146911,-0.040417052109955165
296.90000000000384,24.73281576633163,0.32302731943410246,-0.04104558342967035
298.3000000000038,24.774817192622816,0.32079786018731443,-0.040068406040718596
299.70000000000385,24.81749973410248,0.32012274229099297,-0.040060033463605205
301.1000000000039,24.85990859127775,0.32040672850154633,-0.04005994836390414
302.5000000000039,24.90210020568602,0.31984678650778975,-0.040059948000873646
303.9000000000039,24.944460144187545,0.3179919898489051,-0.04005994799999879
305.30000000000393,24.987019616824668,0.31952078227282293,-0.04005994800000012
306.70000000000397,25.029091328801968,0.3173328420239997,-0.04005994799999657
308.100000000004,25.071940003387777,0.3156627140188363,-0.04005994800137325
309.500000000004,25.114236722242598,0.3170084699792671,-0.040059948613851315
310.900000000004,25.156605308662588,0.31468118119739535,-0.04006008907352898
312.30000000000405,25.19922183065284,0.31289531925750175,-0.04007069618812098
313.7000000000041,25.241584036017137,0.31275164687556867,-0.041378721566743604
315.10000000000406,25.28382277276621,0.3107039287374933,-0.04137980838825461
316.5000000000041,25.326720972165944,0.3116676288965464,-0.04137981597255047
317.9000000000041,25.368934843758016,0.31161337536791855,-0.041379815999955216
319.30000000000416,25.411791047700863,0.31062092056562224,-0.04137981599999785
320.70000000000414,25.45431112869109,0.3094586954815493,-0.041379815999935676
322.1000000000042,25.49676418043994,0.3070558330178036,-0.041379815985386426
323.5000000000042,25.53929482878936,0.3058667289944178,-0.04137981496825294
324.90000000000424,25.581868749161984,0.30415818451819804,-0.04138057532881145
326.3000000000042,25.624146315160218,0.30515778511314645,-0.04177300251991056
327.70000000000425,25.667000768784746,0.3050218376895041,-0.04236882980842349
329.1000000000043,25.709504978536245,0.30236263012748327,-0.042372165859456246
330.5000000000043,25.75206412746322,0.30280800261836904,-0.04369350005318129
331.9000000000043,25.79500684619159,0.3027235380567672,-0.043689933845457496
333.30000000000433,25.83755661312917,0.3021855399964836,-0.043704966060619466
334.70000000000437,25.880437029336232,0.3011258481266627,-0.042707442096825865
336.1000000000044,25.922907146673285,0.29905221584202785,-0.042700009346516854
337.5000000000044,25.965719934261177,0.29898089452669996,-0.04269758587101746
338.9000000000044,26.008418004547146,0.2989108103787891,-0.04304047937644917
340.30000000000445,26.05152790657931,0.2978036879810673,-0.04303004352182782
341.7000000000045,26.09398272567506,0.2975868870473697,-0.04302405326594716
343.10000000000446,26.136867046374217,0.297053226843691,-0.04433230496708784
344.5000000000045,26.17972675105833,0.296720731432728,-0.044944709143219796
345.9000000000045,26.222349784922624,0.2932792094064378,-0.045009935488910635
347.30000000000456,26.265442548921037,0.2930461426127464,-0.04499674434799017
348.70000000000454,26.308475038913024,0.2939855797349791,-0.04367380632578044
350.10000000000457,26.35122418737673,0.29239268605572766,-0.04369012118693805
351.5000000000046,26.394196578024932,0.2906498917278704,-0.04368321270577358
352.90000000000464,26.437052027181046,0.2918814920298537,-0.044994670850167395
354.3000000000046,26.479939142988467,0.28922605973542304,-0.045008348575070745
355.70000000000465,26.522980606194285,0.2885627087077456,-0.045696538724100844
357.1000000000047,26.565926586408253,0.28676475592799044,-0.04662686215846934
358.5000000000047,26.609315376919014,0.283398536703952,-0.04665004275272144
359.9000000000047,26.652215761938095,0.2841634737115065,-0.04665006016549267
361.30000000000473,26.69543187550966,0.2823839457980999,-0.04665006000085192
362.70000000000476,26.73825051067273,0.282933971570616,-0.04665005999670058
364.1000000000048,26.780981088428643,0.2826052740059697,-0.0466500606312632
365.5000000000048,26.824508950194556,0.28107535776397863,-0.046650648587525545
366.9000000000048,26.86778570422339,0.2817980624817532,-0.046910413569759335
368.30000000000484,26.91087716541545,0.2823653802271172,-0.048291609265048496
369.7000000000049,26.95395158757877,0.27991454217756156,-0.04829407335331748
371.10000000000485,26.99741092981088,0.27889347368435474,-0.04933400938133348
372.5000000000049,27.040339821129383,0.2807739472170817,-0.048298704842004714
373.9000000000049,27.083407789378096,0.2783742694327939,-0.048299999216408374
375.30000000000496,27.126933279679214,0.27695879241580973,-0.04829999602642987
376.70000000000493,27.170095538657797,0.27898793282303336,-0.0482999960000603
378.10000000000497,27.212987191803286,0.277233243743416,-0.048299996000000345
379.500000000005,27.25656149982074,0.2775782428113603,-0.04829999599999857
380.90000000000504,27.299844167132868,0.2773484612576232,-0.048299996000000345
382.300000000005,27.343262838487583,0.27485536377573017,-0.04829999599999901
383.70000000000505,27.38650768379878,0.2743942828738096,-0.048299996000000345
385.1000000000051,27.42993766888056,0.27427283169924904,-0.04829999600011803
386.5000000000051,27.47335290291947,0.2714237688927008,-0.04829999597552259
387.9000000000051,27.51683152012914,0.2734791351345528,-0.04829997818537635
389.3000000000051,27.560151175311596,0.271542292246259,-0.04829743916868168
390.70000000000516,27.60340256807791,0.27181201299824836,-0.0496261071848183
392.1000000000052,27.646975872648007,0.2678149486374044,-0.05002938930269529
393.5000000000052,27.69048382623229,0.2695484747013546,-0.05093958748433636
394.9000000000052,27.733930946273443,0.26807775852179266,-0.05093985877912566
396.30000000000524,27.777367794094573,0.26869952768880223,-0.05093986398615913
397.7000000000053,27.821108232096915,0.2681208969634373,-0.050939864000020485
399.10000000000525,27.864419741980505,0.26741622177389535,-0.05093986400000006
400.5000000000053,27.90823128651535,0.2662779668606883,-0.050939863999996504
401.9000000000053,27.951652662612926,0.26667402003805074,-0.050939864001093405
403.30000000000535,27.99520131888745,0.26516803479979767,-0.050939864613175345
404.70000000000533,28.038874596555488,0.26644658261378923,-0.05093993367163652
406.10000000000537,28.082390834368915,0.26424393950335584,-0.05089615393575153
407.5000000000054,28.126119266122593,0.2648833007396366,-0.05224882631057515
408.90000000000543,28.169807511516105,0.26448402900710466,-0.05226297713165007
410.3000000000054,28.21364339330393,0.2655020534219058,-0.05214678975632747
411.70000000000545,28.257294217968493,0.2652992519241332,-0.05224615391144338
413.1000000000055,28.300707765341816,0.26401402929774653,-0.05357660095414296
414.5000000000055,28.344902487960006,0.26451843102160144,-0.052275479739317454
415.9000000000055,28.388454733902634,0.2657373119171351,-0.05225009585667495
417.3000000000055,28.432539457406754,0.2694092421771786,-0.05225003854907895
418.70000000000556,28.476513781643334,0.26741740406203746,-0.05225108262653233
420.1000000000056,28.520287750087366,0.26715460143085534,-0.05293401138918297
421.50000000000557,28.563903760878905,0.27021664487842556,-0.053568919505841084
422.9000000000056,28.608033554995256,0.27251555081260087,-0.05357016874599552
424.30000000000564,28.652028367960103,0.2708598140981805,-0.053976549190912326
425.7000000000057,28.695867562773582,0.27347909131179426,-0.05454890437269899
427.10000000000565,28.74018539613063,0.27491247388812023,-0.054549903170299174
428.5000000000057,28.78384852888333,0.2783228399293461,-0.054549900690839426
429.9000000000057,28.8279890492198,0.2831573705565401,-0.05454895503412338
431.30000000000575,28.872146738441508,0.28310071563784955,-0.053797282500544163
432.70000000000573,28.916026809967793,0.28568796457867096,-0.05313245171249914
434.10000000000576,28.960226274837495,0.2851187559524132,-0.054229831522096816
435.5000000000058,29.004388715730904,0.2886761720551441,-0.05426699567361082
436.90000000000583,29.047573401900607,0.28656875471142096,-0.05586944913894154
438.3000000000058,29.091882020022037,0.28589950189102054,-0.05587017860531285
439.70000000000584,29.136470647021543,0.28700090852299376,-0.0558700782766306
441.1000000000059,29.180316600397568,0.2828979202671116,-0.055873810813142466
442.5000000000059,29.22497421925424,0.2815029186214404,-0.05702455118734484
443.9000000000059,29.269020785617023,0.2807468218816257,-0.057189926176560046
445.3000000000059,29.313016826000876,0.28061730681345876,-0.05719004374509318
446.70000000000596,29.35723938086337,0.2795674054001172,-0.05718969505432092
448.100000000006,29.401609447082468,0.27725233202473276,-0.05727410859239779
449.50000000000597,29.44495804737015,0.2764899467485097,-0.05784885498827341
450.900000000006,29.489772426645228,0.27774055059860087,-0.0578501805857492
452.30000000000604,29.533965825066435,0.2778307280574356,-0.05784625275291333
453.70000000000607,29.57859925236252,0.28200751742320257,-0.058541432567192686
455.10000000000605,29.6226305276925,0.2809518310650066,-0.057838204138644045
456.5000000000061,29.6671126758258,0.2790896907867053,-0.057839805361350916
457.9000000000061,29.7111303830618,0.28150807284989027,-0.057839812007700164
459.30000000000615,29.755687137347078,0.28587568866452145,-0.05783981237464175
460.7000000000061,29.799906052900347,0.2833834439512589,-0.057839816022778656
462.10000000000616,29.84379863323772,0.28816941772077165,-0.05857170686022206
463.5000000000062,29.888578207783485,0.28471430256009905,-0.05940884076205988
464.90000000000623,29.932622024784006,0.2893135546662629,-0.06014897676461217
466.3000000000062,29.977199887929277,0.2903388927864057,-0.06015112777955034
467.70000000000624,30.021486279601273,0.2917056155679424,-0.06093291967986625
469.1000000000063,30.06584359670742,0.2940305154587097,-0.05983161508851875
470.5000000000063,30.11048023829799,0.29658644507050663,-0.059828846559673465
471.9000000000063,30.15450231074371,0.29570806332521815,-0.06073455055525301
473.3000000000063,30.19911512630868,0.29718655227671414,-0.06081019999073245
474.70000000000636,30.24329313927329,0.3005161655686235,-0.0611771419105942
476.1000000000064,30.287912772262672,0.300440638968288,-0.061323250498989346
477.50000000000637,30.33232325516714,0.302157864143701,-0.06245818396170133
478.9000000000064,30.377142650217717,0.30100922632243754,-0.062459813678505505
480.30000000000643,30.421595181932755,0.3040269688622527,-0.06245998543096043
481.70000000000647,30.46613767146729,0.3017912962551977,-0.06263893235052542
483.10000000000645,30.51080693100333,0.3037690500487985,-0.06376699921308582
484.5000000000065,30.55501167410032,0.3026933049418775,-0.06376995411419584
485.9000000000065,30.599873970109385,0.3089314316982098,-0.0637699918924639
487.30000000000655,30.644084762396027,0.30711254688213907,-0.06377080690186254
488.7000000000065,30.689550689333633,0.30694206304609534,-0.06439271945148839
490.10000000000656,30.73440263184345,0.3114501058675375,-0.0650888323959471
491.5000000000066,30.779056796171574,0.31342918212850995,-0.06508806080198237
492.9000000000066,30.823794273238335,0.31518979224570015,-0.06646125927524871
494.3000000000066,30.86852811247662,0.31992478226962257,-0.06640986598146004
495.70000000000664,30.91355838389617,0.31977883822032993,-0.06671170903188006
497.1000000000067,30.958458182216,0.31872912895044797,-0.06773015683878558
498.5000000000067,31.00337714192241,0.3172503590021707,-0.06772997393632263
499.9000000000067,31.048317049776955,0.31877838548724846,-0.06772440371433497
501.3000000000067,31.093505993118335,0.31999470785043027,-0.06868244771593002
502.70000000000675,31.13808853472425,0.3175652923919428,-0.06899006645400974
504.1000000000068,31.183112160235186,0.319078180466634,-0.0690415279469967
505.50000000000676,31.228245407064968,0.31670514107034015,-0.06986075772695699
506.9000000000068,31.27327126983687,0.31795507608512935,-0.07035990805518466
508.30000000000683,31.31804122815713,0.31740179032274196,-0.07035963316317062
509.70000000000687,31.36347115173734,0.31610143390275985,-0.07065263479506179
511.10000000000684,31.408576933725772,0.3125402959980634,-0.07168004053786392
512.5000000000068,31.45355010804039,0.31429527714157607,-0.07171120587196
513.9000000000069,31.498866926446862,0.3103925271752282,-0.07300162457001447
515.300000000007,31.543811547575466,0.309530806354894,-0.07300016839156331
516.7000000000069,31.589026247838987,0.30794716888451346,-0.07299995760019051
518.100000000007,31.634308391283955,0.30744844197246596,-0.07337068440953542
519.500000000007,31.679078642933103,0.306596352930106,-0.07431010647273473
520.900000000007,31.724431007970956,0.3064746305566262,-0.07510377792333411
522.300000000007,31.769032559217244,0.30635232270683305,-0.07562949821474962
523.7000000000071,31.814870580921127,0.3060082359296259,-0.07562046465851102
525.1000000000071,31.86032755364235,0.3062720238827115,-0.07695168944945019
526.500000000007,31.90560943795969,0.3033229013005877,-0.07723308899260228
527.9000000000071,31.950740457833014,0.30276457002008317,-0.07728028055495262
529.3000000000071,31.99620947849798,0.30384478724517233,-0.07738370308738807
530.7000000000071,32.04161668737585,0.3049041644467033,-0.07866429098588634
532.1000000000072,32.08685764838907,0.30557139044967957,-0.07925351789275314
533.5000000000072,32.13203520161081,0.3074866253384153,-0.07925011895230805
534.9000000000071,32.177532238905194,0.31101256043105635,-0.07924641071610239
536.3000000000072,32.223154470138404,0.3078859488660175,-0.08061894468276476
537.7000000000073,32.268747333890836,0.3119765189202909,-0.08057005801109796
539.1000000000072,32.314230806451775,0.31017042578606924,-0.08057185818129309
540.5000000000073,32.35953518038964,0.3102518181180316,-0.08147070894468555
541.9000000000073,32.404888172811965,0.309072384349,-0.08123287013234082
543.3000000000073,32.45026534803154,0.31245166601789964,-0.08255097410338585
544.7000000000073,32.496018680465006,0.31374153756267764,-0.082540892844718
546.1000000000074,32.54164209813294,0.31343571109020296,-0.083980927392858
547.5000000000074,32.587011874758595,0.31381573322823353,-0.08517379066963882
548.9000000000074,32.63254565598146,0.3158321433414265,-0.08654199034739074
550.3000000000075,32.67799385040497,0.31669979947744553,-0.08515282596731977
551.7000000000074,32.72362458615929,0.32162353239632,-0.08651384193432943
553.1000000000074,32.76912200133781,0.3231292267064433,-0.08652291180534322
554.5000000000075,32.814630729956804,0.3227613936345959,-0.08747685008575656
555.9000000000075,32.86042110924742,0.3250870644704631,-0.08851574597992373
557.3000000000076,32.90595595302554,0.3277187499624674,-0.08969658023190297
558.7000000000075,32.951072444269286,0.3246227352333252,-0.09044925264273251
560.1000000000075,32.99703488117247,0.3304247805231172,-0.09163347302697344
561.5000000000076,33.04259505329882,0.332556393776933,-0.09176659914990903
562.9000000000076,33.08837940846283,0.33237014454276104,-0.09308043250331455
564.3000000000076,33.133902214666364,0.3369735455407743,-0.09308981221690349
565.7000000000077,33.178998662722634,0.33815476849968173,-0.09308483213263319
567.1000000000076,33.22498984035461,0.3409416799175935,-0.09441754973683825
568.5000000000077,33.270813707003754,0.34265316772469956,-0.09584805651366501
569.9000000000077,33.31691433707734,0.34592932090191697,-0.09803349863824451
571.3000000000077,33.36232101694621,0.34877443576162637,-0.09923445860084534
572.7000000000078,33.40765615159033,0.3510458080068851,-0.09925061833145632
574.1000000000078,33.45355842416153,0.3592950573268373,-0.1005363887694144
575.5000000000077,33.499750744218346,0.3596368458644007,-0.1005500843010192
576.9000000000078,33.54482878351901,0.3601304173392348,-0.10052498359071915
578.3000000000078,33.59099671509498,0.36051698110624986,-0.09924159077167749
579.7000000000079,33.63688857563419,0.3635010816421519,-0.0992401570177277
581.1000000000079,33.68239240775591,0.3642897505494428,-0.09921544087846534
582.5000000000078,33.728530738140286,0.3666486742533628,-0.10066597329548177
583.9000000000079,33.77420163478112,0.37127780907959196,-0.10196219186207856
585.3000000000079,33.820259786291366,0.37237894791850823,-0.10199124617431199
586.7000000000079,33.865799642520706,0.37527526096289276,-0.10330516650869459
588.100000000008,33.91174658320202,0.37764219671247834,-0.10469138202504258
589.500000000008,33.95736125051005,0.3792836007942394,-0.10582305102338374
590.900000000008,34.0033303340476,0.3839451792187568,-0.10738802480965948
592.300000000008,34.04926900215251,0.38649543632808536,-0.1087913131542333
593.700000000008,34.0949801047484,0.39183760007563206,-0.1100159808601191
595.1000000000081,34.14098528639787,0.39258826642161115,-0.1119612932656242
596.5000000000081,34.18702062343094,0.3938960959627402,-0.11287686993543034
597.900000000008,34.23306343445834,0.39795039624346495,-0.11282612350610943
599.3000000000081,34.27911379724886,0.40168961738368747,-0.11416539949391868
600.7000000000081,34.324956000555005,0.40431712605750536,-0.11586511746279404
602.1000000000082,34.371083527432184,0.4109045739953495,-0.11781507787337953
603.5000000000082,34.416341131462396,0.41296279652671386,-0.11880101795832587
604.9000000000082,34.46303972646513,0.41937027467775523,-0.11924448449149239
606.3000000000083,34.50925288653032,0.4210302180652973,-0.12042790568463957
607.7000000000082,34.555167943943886,0.42508606352847045,-0.1217558675049526
609.1000000000082,34.60128676932831,0.4292012858996518,-0.12174350810228729
610.5000000000083,34.647526164325676,0.4292618740459644,-0.12239896253228189
611.9000000000083,34.69343092814547,0.4317426995891952,-0.12361093906972798
613.3000000000084,34.74006721663222,0.4332029502529695,-0.1249308069792181
614.7000000000083,34.78568780242085,0.4338604652843314,-0.12625789571719404
616.1000000000083,34.8320501956813,0.4380665140782031,-0.1272807625410417
617.5000000000084,34.87784330258959,0.4381082529914443,-0.12771701378686684
618.9000000000084,34.92438254821069,0.43606448015696875,-0.1289399354419225
620.3000000000084,34.9697047601027,0.43766173113048445,-0.13083482243723665
621.7000000000085,35.016144061954215,0.44019584859765315,-0.1321746305173077
623.1000000000084,35.06275611805229,0.4414788590924995,-0.1326202704116004
624.5000000000085,35.109002326323754,0.4446860811343888,-0.13382760706326824
625.9000000000085,35.15470041946325,0.4429322256115349,-0.13405553468867293
627.3000000000085,35.201391475114036,0.44428675190538436,-0.13592125173651137
628.7000000000086,35.247806135637305,0.44464801227797357,-0.13669597168524739
630.1000000000085,35.29411795994511,0.4495102873386736,-0.13840785600776995
631.5000000000085,35.34033312027675,0.4513146152581774,-0.13976198638414683
632.9000000000086,35.38659473498366,0.4544522304529771,-0.1410905191119145
634.3000000000086,35.43289464162704,0.45557103429123724,-0.1424034413035713
635.7000000000087,35.47927008872988,0.45942667344969146,-0.14369900242133626
637.1000000000087,35.525464843723846,0.4631646677003458,-0.14493074639849546
638.5000000000086,35.57200494013208,0.4650517421629242,-0.14589396238705987
639.9000000000087,35.618268510461185,0.4675250155954199,-0.1476698823780218
641.3000000000087,35.66443800429159,0.46824058693468806,-0.14904454894023633
642.7000000000087,35.7107933974937,0.47262245848009554,-0.1504203416569685
644.1000000000088,35.757192883285335,0.47221203805547785,-0.15211935858270742
645.5000000000088,35.8036045055235,0.4778354123276439,-0.1552143473177301
646.9000000000088,35.85013458435974,0.4830999925253918,-0.1566480787996718
648.3000000000088,35.89631826883161,0.48293594690086683,-0.15797431289933828
649.7000000000088,35.943013706255016,0.4881317983254334,-0.15938345741599624
651.1000000000089,35.98868850502112,0.49023389100610537,-0.16051878948272247
652.5000000000089,36.03588366923606,0.4947330392097776,-0.16074607694030618
653.9000000000088,36.08217596999206,0.49973338327824945,-0.16195940696974542
655.3000000000089,36.12875783600402,0.5019048717783154,-0.16310378857223595
656.7000000000089,36.17511131350395,0.5096722387684884,-0.16517587892192465
658.100000000009,36.2215713179096,0.5127032791367296,-0.16664398423192406
659.500000000009,36.26794583523009,0.5149342986864996,-0.16926397510111846
660.900000000009,36.31444970727971,0.5188667870241833,-0.1706803033482247
662.300000000009,36.36114569859774,0.525218348097554,-0.17204272605741977
663.700000000009,36.407790178349586,0.5294962638047571,-0.1749845739132514
665.100000000009,36.454256974454374,0.535042468434695,-0.1765484174997538
666.5000000000091,36.50091677787123,0.5421085614244824,-0.17780453178459554
667.9000000000091,36.54748745050374,0.5498258356991294,-0.18041621632200844
669.3000000000092,36.59369165402758,0.556196973290088,-0.18180051165499833
670.7000000000091,36.640758210521696,0.5630398109458279,-0.1832223178177821
672.1000000000091,36.68740518398437,0.5779978715401939,-0.1846550512534737
673.5000000000092,36.73417903032744,0.5884134792234559,-0.1871468388333244
674.9000000000092,36.78061959288807,0.6033118142784899,-0.18937545990649607
676.3000000000092,36.827367928023946,0.6182745957389337,-0.1911048848993966
677.7000000000093,36.87382788420405,0.6325200475205459,-0.1925256393264103
679.1000000000092,36.920599747209565,0.6558163336407852,-0.19422707653614113
680.5000000000093,36.96745950872939,0.6753859702397913,-0.19773894663969482
681.9000000000093,37.01423426572172,0.6949953489174514,-0.20085457443147714
683.3000000000093,37.060891758455035,0.7199051842436672,-0.20440300282909352
684.7000000000094,37.10790634324855,0.7479716837967356,-0.20635948370288792
686.1000000000093,37.15466165998809,0.7696046696819485,-0.2089534758057301
687.5000000000093,37.20070993323747,0.7957615886789027,-0.21063708522465419
688.9000000000094,37.24816935927231,0.8234662039622074,-0.21313395960806103
690.3000000000094,37.295012937408266,0.8459056438743651,-0.21637058093730932
691.7000000000095,37.341837033413675,0.8769211908440591,-0.21942514500319632
693.1000000000095,37.38889527873039,0.9079229537114037,-0.22259015817817351
694.5000000000094,37.43527742345935,0.9351732241831592,-0.22675527035256593
695.9000000000095,37.482350656875745,0.9666007556504614,-0.23064984708074254
697.3000000000095,37.529291806357236,0.9990480741577625,-0.23507242512177262
698.7000000000095,37.57629009682667,1.0306052261532386,-0.23891645849700227
700.1000000000096,37.6229721782425,1.068571936902433,-0.2424388770555863
701.5000000000095,37.67006787851674,1.10178921927995,-0.24623667287402418
702.9000000000096,37.71705347533361,1.1379393039644672,-0.25138787041231314
704.3000000000096,37.76403800569986,1.1774842961130396,-0.25574233155213877
705.7000000000096,37.81093579201412,1.2189426744762388,-0.25979448428712626
707.1000000000097,37.857890579026424,1.2593772779510164,-0.2648377256717507
708.5000000000097,37.90530977915401,1.3047852490927778,-0.26891611927109516
709.9000000000096,37.952347006741185,1.3513942064560938,-0.27391790534293614
711.3000000000097,37.999792930494564,1.4036506162980529,-0.27948200747329777
712.7000000000097,38.04627910007823,1.4538866193093076,-0.2841107656561035
714.1000000000098,38.094190644647675,1.502936424550018,-0.28823829313270455
715.5000000000098,38.14128305790102,1.5643540201845738,-0.29436535412375164
716.9000000000098,38.18877458111538,1.621163819915831,-0.30125949653274287
718.3000000000098,38.235880135796265,1.6759883642845228,-0.3073077771010855
719.7000000000098,38.28336252999041,1.7457729489753253,-0.31364121607218287
721.1000000000098,38.33086310802553,1.8070303346215522,-0.3206020321724252
722.5000000000099,38.378085771940505,1.8736929599105199,-0.327600571655442
723.9000000000099,38.42633276894751,1.9491999339879904,-0.33576499090456613
725.30000000001,38.47337691394417,2.022939061790054,-0.34302734071043384
726.7000000000099,38.52106624228144,2.099902589748933,-0.35001543692996107
728.1000000000099,38.5687772338406,2.180715620181644,-0.35762579221843893
729.50000000001,38.6167072210157,2.267717097582595,-0.3667672981265757
730.90000000001,38.664263904293556,2.359098394079894,-0.37505093969667236
732.30000000001,38.712382806857136,2.451512968034744,-0.38366183911331264
733.70000000001,38.760168650790746,2.549502353246795,-0.39284347093371697
735.10000000001,38.808111421676266,2.654715333043311,-0.403365693020048
736.5000000000101,38.855930320752904,2.7576124185810977,-0.41219872071992736
737.9000000000101,38.90391111622039,2.867108131386858,-0.4209706163648921
739.3000000000101,38.95233115235855,2.9794735201989626,-0.43160178321760867
740.7000000000102,39.000207440681564,3.101827182211408,-0.44413024787329336
742.1000000000101,39.0486292717354,3.2256282199579647,-0.4565614956306532
743.5000000000101,39.09632909105829,3.3455710179958373,-0.4674355646185706
744.9000000000102,39.14486915803608,3.4761313100989115,-0.4805926736507282
746.3000000000102,39.19317834936285,3.6079141065134404,-0.49321323972188047
747.7000000000103,39.24106950525491,3.7374128263685504,-0.5064406153193421
749.1000000000103,39.28993234453983,3.8775894999370615,-0.5183547789621157
750.5000000000102,39.33841142126772,4.01803970079583,-0.5312757631557372
751.9000000000103,39.386220489468194,4.165231343521269,-0.5457948132186043
753.3000000000103,39.435018216111814,4.3171616676037505,-0.5610202211078792
754.7000000000103,39.483674792251946,4.46855108652179,-0.5769758543413337
756.1000000000104,39.532171752596184,4.629198162687311,-0.593714678573793
757.5000000000103,39.58067288069862,4.791151745155631,-0.6104750207627991
758.9000000000104,39.628772481922084,4.950916587944185,-0.625847494192231
760.3000000000104,39.677516092918886,5.122069250478701,-0.6442147898997859
761.7000000000104,39.72597823410575,5.292200514775276,-0.6625650030769132
763.1000000000105,39.77488543446725,5.467858656496615,-0.6818886188674957
764.5000000000105,39.82317132409123,5.638097346528306,-0.7006131835328446
765.9000000000104,39.87168563229568,5.818070205423253,-0.71969378839262
767.3000000000105,39.92040456113332,5.9967284941568515,-0.7412243957119191
768.7000000000105,39.96889424362246,6.174063442447516,-0.7627190201108336
770.1000000000106,40.01747367492002,6.352115444959691,-0.7836585122770199
771.5000000000106,40.06628636538596,6.52948286031845,-0.805078615193568
772.9000000000106,40.114737617442266,6.706468667691872,-0.8286404548650719
774.3000000000106,40.16333566752024,6.878202015034358,-0.8516486835787624
775.7000000000106,40.21176463753202,7.048654875735236,-0.8762642964430825
777.1000000000106,40.26028397538232,7.212144426765521,-0.9001236041151088
778.5000000000107,40.3085606293719,7.370014839669305,-0.9246796125381809
779.9000000000107,40.357268705603985,7.520136614940606,-0.9499369653302376
781.3000000000108,40.405393917104405,7.64993644493484,-0.9768362780673594
782.7000000000107,40.45343727509495,7.771952868050746,-1.0027965390195503
784.1000000000107,40.500756378642286,7.870167969378511,-1.0285665413674057
785.5000000000108,40.54917541389124,7.943490586390364,-1.0546625010641457
786.9000000000108,40.596006853824875,7.983126430207315,-1.0808701417061264
788.3000000000108,40.643968593457735,7.992480799639699,-1.1080620273058304
789.7000000000108,40.69077519953717,7.958330398277154,-1.135370872370018
791.1000000000108,40.737092885285676,7.867162056578621,-1.1609485674036777
792.5000000000109,40.78298264901873,7.697537460347809,-1.188360236686575
793.9000000000109,40.828584569274945,7.458484561836162,-1.2116209783033778
795.3000000000109,40.87239662913024,7.122667475077774,-1.2331291755758507
796.700000000011,40.916322900498855,6.666102349878733,-1.255271893044343
798.1000000000109,40.958215124569215,6.047158013059081,-1.2753270350153154
799.5000000000109,40.99829151006347,5.136978795951181,-1.291952957709844
800.900000000011,41.03590425288186,3.970564107159661,-1.3047629999954982
802.300000000011,41.07327065936716,2.6657655159495435,-1.3144316978269681
803.7000000000111,41.11149899995652,1.5154852621075174,-1.3226614466620439
805.100000000011,41.151768233070726,0.6581579740513335,-1.325206670725957
806.500000000011,41.193684106821316,0.09520222292583069,-1.3265505431407316
807.9000000000111,41.23845082097208,-0.2572457676343127,-1.3287909325600156
809.3000000000111,41.28346479464283,-0.43948474294058015,-1.3295988382664627
810.7000000000111,41.32989806167676,-0.541170862725342,-1.3309002629788145
812.1000000000112,41.37656702659369,-0.5839248244477171,-1.3309001833979197
813.5000000000111,41.423362462552944,-0.6052530715795672,-1.3309003262512804
814.9000000000112,41.47075883301944,-0.6165054009087076,-1.3308538434090713
816.3000000000112,41.51723555748991,-0.6284034309906188,-1.3312871005980735
817.7000000000112,41.56477092148368,-0.6307550214042277,-1.3309135473025822
819.1000000000113,41.61187764394763,-0.6378165414778125,-1.3322103022654055
820.5000000000113,41.65922764770089,-0.6476044241541288,-1.3318894211800196
821.9000000000112,41.70624821969567,-0.651267977602235,-1.3331892773756864
823.3000000000113,41.75363437948765,-0.6560481844006312,-1.3332001161288942
824.7000000000113,41.800943481141765,-0.6582615156370775,-1.3332000898743295
826.1000000000114,41.84820721542892,-0.6632582941395058,-1.3331942206870453
827.5000000000114,41.89526680445885,-0.6677907095029874,-1.333711885915712
828.9000000000113,41.94263741181024,-0.6693464536468636,-1.3328807314504867
830.3000000000114,41.99000034760435,-0.6729093857393222,-1.3328799019396564
831.7000000000114,42.03722959839466,-0.6737999005913322,-1.3332106539690023
833.1000000000114,42.08454896266822,-0.6760732607648148,-1.3330207223375137
834.5000000000115,42.13205697451891,-0.6742806256915379,-1.3328691963331964
835.9000000000115,42.17960860784979,-0.6735041772535215,-1.3329739197013297
837.3000000000116,42.22710859344112,-0.6762417467094726,-1.3344354848851223
838.7000000000115,42.27437863793972,-0.6723799804295842,-1.3344859987676676
840.1000000000115,42.3220482156857,-0.6722877567928593,-1.3345165099988066
841.5000000000116,42.3692189705932,-0.6585249015802752,-1.334520010262045
842.9000000000116,42.41667813987413,-0.6528080314224716,-1.334520008601023
844.3000000000116,42.46414821332765,-0.6514266461940328,-1.3345149062941828
845.7000000000116,42.51184328896953,-0.6553317529311911,-1.336726435675248
847.1000000000116,42.55908865014951,-0.6589201484399185,-1.3356156565995163
848.5000000000117,42.60648175183373,-0.6671329262315724,-1.3348237901683646
849.9000000000117,42.65363572068321,-0.6747935019450926,-1.3355104356858796
851.3000000000117,42.70142401473579,-0.685262028584924,-1.3353468319723691
852.7000000000118,42.74897344897342,-0.6915836007789609,-1.3348001967485654
854.1000000000117,42.796473423992225,-0.7002044505970311,-1.3348553044901479
855.5000000000117,42.84414229558777,-0.7057691421727108,-1.3344967421776412
856.9000000000118,42.891497148216786,-0.7139608137874249,-1.3341872221464888
858.3000000000118,42.93917634004759,-0.7194916679467476,-1.3367885834553506
859.7000000000119,42.98678439581828,-0.7252406057260437,-1.3368203930007958
861.1000000000118,43.034287028506355,-0.7275930966460942,-1.3368196409469641
862.5000000000118,43.0819643811149,-0.735134711982145,-1.3382219531913937
863.9000000000119,43.12932774377463,-0.7429928832221466,-1.3381401085117872
865.3000000000119,43.17686500615609,-0.7487992789735798,-1.3381492107282473
866.7000000000119,43.2245762512475,-0.7597468866041484,-1.3381170288680089
868.100000000012,43.27217535318924,-0.7644250621088673,-1.3381499335058136
869.5000000000119,43.31986240328628,-0.7689064281251425,-1.3381671390625955
870.900000000012,43.367235819235276,-0.7784735116153922,-1.3381401355835045
872.300000000012,43.41451573051802,-0.7853416237498876,-1.3381400916896293
873.700000000012,43.46212211742629,-0.7913735862212334,-1.3381400920150375
875.1000000000121,43.50983058830335,-0.8031003420420066,-1.3381400926352631
876.500000000012,43.557305520365,-0.8093659906639599,-1.3381355803644945
877.900000000012,43.60490036845625,-0.8170179445741246,-1.3394670908619553
879.3000000000121,43.65230289768824,-0.8251149357521557,-1.3394563875393257
880.7000000000121,43.699655194420366,-0.8350174313013488,-1.3407787453614852
882.1000000000122,43.74714598145575,-0.8435106850125549,-1.339029237572921
883.5000000000122,43.794286526261324,-0.8546046713978899,-1.338171676157156
884.9000000000121,43.84192591278234,-0.8618713445073805,-1.338194076782163
886.3000000000122,43.88957710604521,-0.8730965321807704,-1.339458623415585
887.7000000000122,43.93693705840247,-0.8793776869154697,-1.3407742179243103
889.1000000000122,43.98403811580948,-0.8864668430516134,-1.3407707469420016
890.5000000000123,44.03176182579037,-0.8971394807741684,-1.3416374844039707
891.9000000000123,44.07917796757843,-0.9068041479622992,-1.3421997784067488
892.0000000000123,44.08258852283529,-0.9078848985193995,-1.3422009523723055