File: 01_Data/Polyisocyanurate_Foam_Board/STA/N2/10K_min/Polyisocyanurate_Foam_Board_STA_N2_10KData_221019_R2.csv
##Temp./Â°C,Time/min,DSC/(mW/mg),Mass loss/mg
51.0,10.720700340566191,0.031433521668661424,0.030880356159390665
52.000000000000014,11.089103426726199,0.06499893594304362,0.033641014019727855
53.00000000000003,11.326337514545951,0.08615276605009847,0.03247791314499615
54.00000000000004,11.521930162471143,0.10367428528118627,0.029629527227880814
55.00000000000006,11.69050082411908,0.11869152046003273,0.030348679263213718
56.00000000000007,11.85967760326753,0.13234073016834969,0.03365380902161785
57.000000000000085,12.010806171054012,0.143030341721041,0.030662115755125008
58.0000000000001,12.156178043907504,0.14983922616387813,0.029563621724764566
59.000000000000114,12.295810862241698,0.15596336801698008,0.03077951231181153
60.00000000000013,12.431161631424043,0.16400391805966663,0.03158507110314801
61.00000000000014,12.563701268772277,0.16881343008998306,0.029890890366282896
62.000000000000156,12.693903619028944,0.17427893031878772,0.03156223940310987
63.00000000000017,12.819641695003632,0.17796813498804243,0.03142743662433922
64.00000000000018,12.945220944288149,0.1846842120235188,0.034684380368939394
65.0000000000002,13.068359060982079,0.18719489981268644,0.03349910917408838
66.00000000000021,13.18910316582105,0.19227242836152714,0.034468579364581586
67.00000000000023,13.30852013882401,0.19901342342535977,0.034440783973690436
68.00000000000024,13.425752332647734,0.198719179520209,0.034364285405929174
69.00000000000026,13.542654117798477,0.20337782267147575,0.03304132599520315
70.00000000000027,13.66010117784312,0.20789342644806497,0.033339591529006896
71.00000000000028,13.774740357195528,0.21148221810363954,0.03289403483803799
72.0000000000003,13.887175315038569,0.21309702475990422,0.030123484630225406
73.00000000000031,14.001767605937044,0.21713310189970403,0.03219798445989319
74.00000000000033,14.112624807137449,0.21824004681228604,0.033020865956434164
75.00000000000034,14.22670432149549,0.22178854616102406,0.034418430020961566
76.00000000000036,14.335901955331636,0.22308086723953502,0.03428017842999953
77.00000000000037,14.444474492606208,0.22464115700227338,0.03317605863764239
78.00000000000038,14.554736561735425,0.225484890846969,0.033167319733684586
79.0000000000004,14.663481830447598,0.22849932275929252,0.03333228201424632
80.00000000000041,14.769496891643133,0.22823388382421694,0.03318952286620647
81.00000000000043,14.878439525970514,0.2291076197424382,0.03256577620192047
82.00000000000044,14.985340620890453,0.23095251230833813,0.033054273363898545
83.00000000000045,15.091298599840394,0.2324068594207045,0.03456084087877809
84.00000000000047,15.196726235852537,0.23267710424234844,0.03317598869111826
85.00000000000048,15.300827221401311,0.23335751678606964,0.03254888363492192
86.0000000000005,15.407903613904047,0.23593801862330666,0.03447968076741681
87.00000000000051,15.511098874886,0.2375655229321374,0.03447921177990043
88.00000000000053,15.614145162851996,0.23627096770641698,0.03446865717814518
89.00000000000054,15.71879291351538,0.2372495457763476,0.03346321576433464
90.00000000000055,15.820255951843052,0.23932524550198475,0.034480670423836735
91.00000000000057,15.921610129313192,0.23953813820656045,0.033257224274241715
92.00000000000058,16.024016182240945,0.24100252705977832,0.035360144179973574
93.0000000000006,16.125672693197522,0.24236677249718486,0.03449185070954375
94.00000000000061,16.22725742701386,0.24334693163733334,0.03516669125128491
95.00000000000063,16.328033749026417,0.24325040905892126,0.036372522649052996
96.00000000000064,16.429901382248673,0.24515802903927653,0.035789923762007625
97.00000000000065,16.530312664477172,0.2457044623719734,0.03549908035077287
98.00000000000067,16.63028061702003,0.2474190084439163,0.034474632745356004
99.00000000000068,16.72924491648834,0.2493877285123468,0.03579687594776537
100.0000000000007,16.829319481527197,0.24798131002038715,0.03711049490441454
101.00000000000071,16.928742322633155,0.25057201828400444,0.037113729996892
102.00000000000072,17.02719479192812,0.2513422550999256,0.03541535661333839
103.00000000000074,17.1257073023251,0.24965376505453474,0.03440109237458078
104.00000000000075,17.22343105202977,0.2525156111028797,0.03576823102107962
105.00000000000077,17.32322841666054,0.2535937299358604,0.036946478502221325
106.00000000000078,17.4218620040121,0.2540575541485044,0.034462940281015264
107.0000000000008,17.51936658558442,0.25634186746523824,0.035789698524346214
108.00000000000081,17.619118945678352,0.25712998555809974,0.03716313045587061
109.00000000000082,17.716935737021235,0.25721345189411027,0.03580017347903386
110.00000000000084,17.816205901474497,0.26036309477204955,0.03573871452865962
111.00000000000085,17.912977530205414,0.26148681871927504,0.0358003306068273
112.00000000000087,18.011702432776403,0.2621120812392468,0.0373060938282439
113.00000000000088,18.107007118066406,0.2632294067212102,0.037219066435514314
114.0000000000009,18.207487343981676,0.261993617814829,0.03722081397514998
115.00000000000091,18.30407189558694,0.26218173480816676,0.037221185542435364
116.00000000000092,18.40092119333493,0.2631943222476878,0.03590996841198102
117.00000000000094,18.49891032068093,0.26507177158552353,0.03482821630738986
118.00000000000095,18.597076081304245,0.271073147880022,0.03588978601683568
119.00000000000097,18.693974056394403,0.2687381397982289,0.03466579996477481
120.00000000000098,18.792694933518725,0.2706345003731794,0.03487702955870642
121.000000000001,18.888924689325627,0.2733358927706109,0.035580075450735826
122.00000000000101,18.986877690061768,0.2734505459855743,0.034611036495571845
123.00000000000102,19.082723302391543,0.27475326746819684,0.03466890812540768
124.00000000000104,19.180773392300186,0.2748018915277083,0.034589920862022616
125.00000000000105,19.278082102122998,0.27548665695054286,0.03375619068155178
126.00000000000107,19.373607351968552,0.2741884058435292,0.03327000198594732
127.00000000000108,19.46989107082358,0.27603014690393024,0.03462191630733091
128.00000000000108,19.56625008530493,0.27759394594075726,0.03456599027227192
129.0000000000011,19.664963430529596,0.27953088110233926,0.034589836487349146
130.00000000000114,19.761590218983773,0.27930357784154936,0.03327190204826724
131.00000000000114,19.857690022392504,0.2813208513553006,0.03426080340905013
132.00000000000114,19.95371821176797,0.28324972263302817,0.034552480479022485
133.00000000000117,20.05087477468925,0.2840801543352217,0.03554638297939494
134.0000000000012,20.147368974172167,0.28258487199317317,0.03535082742560025
135.0000000000012,20.243506377568046,0.2854709224237413,0.03518594538440212
136.0000000000012,20.339902495919407,0.28595747075526334,0.03403461337311864
137.00000000000122,20.43498737294537,0.2865932456467888,0.03401300061073087
138.00000000000125,20.530675778031558,0.2895922443304202,0.034037135352178005
139.00000000000125,20.626175271342603,0.28855922252276256,0.03255920770555054
140.00000000000125,20.723225248672243,0.28950358109045526,0.031397627557606
141.00000000000128,20.818933924327386,0.29021369527323493,0.032763200416898286
142.0000000000013,20.91381736348084,0.2924088162691354,0.03283454512981265
143.0000000000013,21.010129182759144,0.2946030276442001,0.03141008287156932
144.0000000000013,21.10439171501361,0.2945316116554392,0.030089000844957248
145.00000000000134,21.200094043294204,0.29475910358067914,0.030089826283368204
146.00000000000136,21.296215025856867,0.292939322132316,0.030090013280609007
147.00000000000136,21.390969933110785,0.2952454865937759,0.030092677320889827
148.00000000000136,21.48403996527895,0.2970015915502495,0.030323709110477992
149.0000000000014,21.581364051432132,0.29621035122155936,0.03008091595530793
150.00000000000142,21.677305462353438,0.2963016002268548,0.028769768135588514
151.00000000000142,21.77217815896762,0.2968646232518867,0.028770163784676228
152.00000000000142,21.865812724147123,0.29804171447042427,0.02744857559970093
153.00000000000145,21.96148124069615,0.29920738177582895,0.02877367224530225
154.00000000000148,22.056814169543863,0.2996492322803228,0.028769819924279183
155.00000000000148,22.15083038847371,0.2997373800418497,0.028768199133205385
156.00000000000148,22.24605753157172,0.30157414550443506,0.026138766127485447
157.0000000000015,22.34176651622056,0.3027279658059655,0.027449976831494638
158.00000000000153,22.43766955547241,0.3036488451381181,0.026166752479642064
159.00000000000153,22.531488219568498,0.3053746227530776,0.024800461339301805
160.00000000000153,22.626837574234504,0.3049835222898599,0.025502557204950982
161.00000000000156,22.721361898422614,0.3063297979222541,0.024778128381627518
162.0000000000016,22.81721815836496,0.30743029016150236,0.02300840006781879
163.0000000000016,22.908950712662854,0.30777023937985304,0.021185587716129106
164.0000000000016,23.0075519270891,0.30905526921698345,0.021189006370514463
165.00000000000162,23.101906164699646,0.31411909758537504,0.018552537132378255
166.00000000000165,23.1969386321951,0.3146755341641706,0.018587405667641832
167.00000000000165,23.28834951963989,0.31486846958667647,0.01987007451010303
168.00000000000165,23.386450863249287,0.31541323040335545,0.01856871989405473
169.00000000000168,23.481088489998974,0.31953422202310644,0.015962273899919666
170.0000000000017,23.576522091564737,0.3200986234718365,0.013290126934060176
171.0000000000017,23.672016296987422,0.322774666195877,0.013290139999991624
172.0000000000017,23.76631449732748,0.3233797250375622,0.013290128878596263
173.00000000000173,23.86192649871671,0.3256357000893644,0.011964104877709936
174.00000000000176,23.9578764169749,0.3268428610358598,0.01199899371783264
175.00000000000176,24.051757943242485,0.3293050186472667,0.010645215427071086
176.00000000000176,24.147126119277207,0.3316330491202498,0.00891564805915479
177.0000000000018,24.24051714292485,0.33291430994900983,0.0059464137477034384
178.00000000000182,24.336446888757933,0.336046280388407,0.005969183883822282
179.00000000000182,24.432163351479353,0.33658070678947294,0.005270341960744496
180.00000000000182,24.526781512261767,0.3390391812465393,0.0032820436561751265
181.00000000000185,24.621224887329774,0.3419619685363261,0.0013385313454978842
182.00000000000188,24.716343364025867,0.34414467753692746,-0.0011521918985275548
183.00000000000188,24.811231813430048,0.3448044805575331,-0.003958783703005508
184.00000000000188,24.906005720386478,0.34803491571181255,-0.003946995568687939
185.0000000000019,25.001476070778228,0.3502700170255134,-0.0050463565817118194
186.00000000000193,25.095800151416086,0.35017057911130384,-0.007976573994173286
187.00000000000193,25.19019687719948,0.35394074755248894,-0.010545389260864013
188.00000000000193,25.28517181245517,0.35597631558415344,-0.014446488778696143
189.00000000000196,25.380000000000177,0.3593284467559169,-0.015809889689923473
190.000000000002,25.47468656408076,0.3605653065527237,-0.017469325738264985
191.000000000002,25.56824370881906,0.36167967275427537,-0.01974937691116363
192.000000000002,25.662975603533095,0.3646867960210265,-0.021000985158592833
193.00000000000202,25.757811001928275,0.3652612264859296,-0.023725265838590914
194.00000000000205,25.852432389315176,0.3675928940215647,-0.024226870983211413
195.00000000000205,25.94719015476411,0.37007405108044567,-0.027338864274377705
196.00000000000205,26.041929742475872,0.37102944774105484,-0.030367928005192724
197.00000000000207,26.135874715032486,0.37366874460463567,-0.03500134829590795
198.0000000000021,26.23186319880714,0.3779514225263703,-0.03918375426632981
199.0000000000021,26.32599075738133,0.377692955976268,-0.040735292638278686
200.0000000000021,26.41903673612571,0.38076916284134205,-0.044557477935183165
201.00000000000213,26.51551589238034,0.3807216219756326,-0.047496126753576284
202.00000000000216,26.609804411184747,0.3836094787085934,-0.05124556383906853
203.00000000000216,26.705024822990488,0.38567683601522623,-0.05462834800065597
204.00000000000216,26.79943568848314,0.38588750412282824,-0.058729855155135624
205.0000000000022,26.89450336355038,0.3879088476293372,-0.06000079261157776
206.00000000000222,26.989250843581633,0.3914317712948532,-0.06284176880172687
207.00000000000222,27.084015894655312,0.39404607753718446,-0.06695561843569475
208.00000000000222,27.178681873729207,0.394009082900707,-0.07137413002257098
209.00000000000225,27.273328391543636,0.3962865520107327,-0.07263932972544485
210.00000000000227,27.368065603084474,0.3977018036518493,-0.07690868237094328
211.00000000000227,27.462903828122148,0.39902517925737285,-0.08033702601004311
212.00000000000227,27.558361890585317,0.40178011441382916,-0.08575437038618716
213.0000000000023,27.652663785297467,0.4029172259639256,-0.08737829995057034
214.00000000000233,27.747297690559435,0.40178684559303746,-0.09062490656359135
215.00000000000233,27.842578183442654,0.4060592030308356,-0.097059586058581
216.00000000000233,27.936260288645144,0.40863098931554465,-0.10044487641475008
217.00000000000236,28.030949865981913,0.41078220786767694,-0.10308117630413394
218.0000000000024,28.125949552351692,0.41237913072043514,-0.1065621516170463
219.0000000000024,28.221602851760867,0.41332341228550334,-0.111132494847904
220.0000000000024,28.315698095532422,0.4147117482354127,-0.11513897527490169
221.00000000000242,28.40906897061294,0.4151979037716998,-0.1180372807466532
222.00000000000244,28.504298114746327,0.41718619205006197,-0.1236417677349384
223.00000000000244,28.59970925238352,0.41898592873070434,-0.1290798490729106
224.00000000000244,28.693809302097204,0.4202225638118317,-0.13173711577760194
225.00000000000247,28.78823624610515,0.42056109396186475,-0.13442067938983904
226.0000000000025,28.881620596982867,0.42195132701398524,-0.13879316738150127
227.0000000000025,28.97966422969842,0.42437438591938925,-0.1414864667845288
228.0000000000025,29.07345338458638,0.4250206234274378,-0.14491217980657956
229.00000000000253,29.168587440808313,0.42539335025278213,-0.14993862710033
230.00000000000256,29.264561680473502,0.42601576775766886,-0.15123113880171246
231.00000000000256,29.357689044726595,0.4263643109959601,-0.1547850407988305
232.00000000000256,29.45304788541033,0.42841538661525785,-0.1582400271045139
233.0000000000026,29.547953453458017,0.43032523729350713,-0.1610406224049039
234.00000000000261,29.642890602133967,0.4312014764179147,-0.16402829934945995
235.00000000000261,29.738429033667437,0.4312138910159479,-0.16874954279769216
236.00000000000261,29.829452793665602,0.43190524567418465,-0.17060468685849406
237.00000000000264,29.928361490431023,0.43485151725263443,-0.17492641395187114
238.00000000000267,30.023345780538257,0.4357981529385835,-0.1775139684714362
239.00000000000267,30.118457587989738,0.4384945520605833,-0.1814349108474098
240.00000000000267,30.211658127997413,0.4374375171204025,-0.1814266450531683
241.0000000000027,30.307795216448007,0.43941341894002356,-0.18432682638146725
242.00000000000273,30.403179248721788,0.44299603994696857,-0.18829566276610388
243.00000000000273,30.495738120265024,0.4435916618615439,-0.1897445252473826
244.00000000000273,30.594099379121197,0.44438711961196053,-0.19380370738728026
245.00000000000276,30.686989615041274,0.4446818293937838,-0.1963947646742148
246.00000000000279,30.784231532383554,0.4478522500134826,-0.19902609753973222
247.00000000000279,30.87940767859235,0.4487616163793521,-0.2023510742675687
248.00000000000279,30.973701635504103,0.45001514568100387,-0.20494138701860454
249.0000000000028,31.06943103954408,0.4543680365761798,-0.20721158464058176
250.00000000000284,31.162856891920637,0.4542406103840993,-0.20890934269125339
251.00000000000284,31.259349529117458,0.457671504868256,-0.2108732695857296
252.00000000000284,31.355976078621488,0.45989575544577355,-0.21372080565555862
253.00000000000287,31.45077834003499,0.4624591534204513,-0.21647652188802047
254.0000000000029,31.546157327274607,0.464867910527355,-0.22043057521772536
255.0000000000029,31.6418384544365,0.4672352330439915,-0.22338383444774568
256.0000000000029,31.73682907560749,0.47055193039474663,-0.22489174673524204
257.00000000000296,31.832639936977127,0.47641265457634807,-0.22770253242909844
258.00000000000296,31.927932911612668,0.4776944140112145,-0.23334282594042222
259.00000000000296,32.02130089209139,0.48072157381053765,-0.2342639791839587
260.00000000000296,32.1185249983132,0.4839146864377883,-0.23633626526354412
261.00000000000296,32.21387310362353,0.48825139449972593,-0.24056859488900306
262.000000000003,32.30905460389232,0.49276523718508125,-0.24352423536718115
263.000000000003,32.40413347076068,0.49737456952549425,-0.24766062919546394
264.000000000003,32.50045964351088,0.5037165010290747,-0.2501164822016202
265.00000000000307,32.59557340506801,0.5061706111165194,-0.25203973825693726
266.00000000000307,32.691183585831865,0.5121390201652519,-0.25580014167725507
267.00000000000307,32.786629718138215,0.5166628485263299,-0.2589133449883221
268.00000000000307,32.88384800438432,0.5222163714900587,-0.26264869652397005
269.00000000000307,32.977467714014864,0.5292946845716698,-0.26707279615858504
270.0000000000031,33.07325508679259,0.533967891580243,-0.27189736915314944
271.0000000000031,33.168304917783644,0.5389839010970112,-0.2756047625164486
272.0000000000031,33.26503851363134,0.5467782055152235,-0.27818101277593543
273.0000000000032,33.359829748321175,0.5557274364280399,-0.2841158602026761
274.0000000000032,33.45616663123653,0.5622690967648765,-0.2873569644175431
275.0000000000032,33.55099544303598,0.5684286874012341,-0.2932194082237918
276.0000000000032,33.64686521226993,0.5778872720229289,-0.29664501940500276
277.0000000000032,33.74150553597553,0.5867281999341961,-0.3051207946937584
278.00000000000324,33.83807070654437,0.5965343733100372,-0.31174542449327536
279.00000000000324,33.93323150221131,0.6065263960997732,-0.31640559827254044
280.00000000000324,34.02890411260764,0.614268563283545,-0.31812746556006744
281.0000000000033,34.125043154888424,0.6239947747637298,-0.32432249027372384
282.0000000000033,34.21798454332622,0.6357484773855665,-0.33084339088083103
283.0000000000033,34.31468874556844,0.6465797557560014,-0.3385290826004459
284.0000000000033,34.40947169201841,0.6574934116636879,-0.34618516727654836
285.0000000000033,34.50700009844893,0.669691522687907,-0.3517389136101672
286.00000000000335,34.59984440131546,0.6818294684445616,-0.35888359765048916
287.00000000000335,34.69802391714801,0.6948526044860737,-0.36657348829986036
288.00000000000335,34.79359086503971,0.709607796994548,-0.3776378231374169
289.0000000000034,34.889415671292845,0.7206758239131573,-0.3847346988507798
290.0000000000034,34.98459650928753,0.7356712189585588,-0.3938869955010027
291.0000000000034,35.080873604892275,0.7513492047323137,-0.4015115894403718
292.0000000000034,35.17549992868377,0.7667479704564913,-0.4104872996500015
293.0000000000034,35.27151745552353,0.7801151901323721,-0.4223277243768666
294.00000000000347,35.367390923852575,0.7942784968790342,-0.4333612280549364
295.00000000000347,35.46411437223648,0.8079796757342096,-0.4417240484557543
296.00000000000347,35.55960712849396,0.8238593038722136,-0.4540102679679503
297.0000000000035,35.65561006247282,0.8368054241458908,-0.4665059918015455
298.0000000000035,35.75164315807218,0.8534022168489956,-0.47909397588115743
299.0000000000035,35.84761522715689,0.8655349871565553,-0.49103405951310375
300.0000000000035,35.943504560328115,0.8791234272855378,-0.5052594285789289
301.0000000000035,36.03935459089986,0.8923959310561891,-0.517961723726224
302.0000000000036,36.13568109226237,0.9026941619201762,-0.532090118465903
303.0000000000036,36.2314443153778,0.9117094175769761,-0.5461112273667466
304.0000000000036,36.32740831603228,0.9236033577441276,-0.559499023516604
305.00000000000364,36.422679331680285,0.9351355908768032,-0.5751223004808752
306.00000000000364,36.519167163390875,0.9448133530610963,-0.5915256846478423
307.00000000000364,36.61555021613605,0.9509127024945287,-0.6083569224187029
308.00000000000364,36.711033185053246,0.9582472872959327,-0.6258786464426476
309.00000000000364,36.806871810099686,0.9647800755872797,-0.6418746981777614
310.0000000000037,36.90310879298516,0.9678304662682318,-0.6609003459366134
311.0000000000037,36.99901381806327,0.9715951607309632,-0.6793892394641254
312.0000000000037,37.09495967984889,0.970881720555699,-0.7004506934644747
313.00000000000375,37.19128330632866,0.9671663019684704,-0.7190227118787624
314.00000000000375,37.287058243614254,0.9578738332802553,-0.740628565728735
315.00000000000375,37.3828848991347,0.9437800854201774,-0.7636452187030653
316.00000000000375,37.47862927554267,0.9240138627000833,-0.7844627265916277
317.00000000000375,37.575437686963646,0.8964007770440863,-0.8077511664874764
318.0000000000038,37.67058048579437,0.866088361515076,-0.8336319771106737
319.0000000000038,37.767238097596824,0.8222602409873376,-0.8563874957395368
320.0000000000038,37.86257731611989,0.7791360105072651,-0.8807980162456559
321.00000000000387,37.9584358140005,0.7274499833619453,-0.9062794894138979
322.00000000000387,38.05472861970085,0.6709114334528248,-0.929114847287424
323.00000000000387,38.15019395022115,0.6095526342679775,-0.9549402455958043
324.00000000000387,38.245909714549676,0.5470910718372022,-0.9760791243835012
325.00000000000387,38.341473110249055,0.4849024782779842,-0.9998812052696389
326.0000000000039,38.43745379467018,0.4252664680783527,-1.022786096368058
327.0000000000039,38.53281153917407,0.366438071762541,-1.0476781105563115
328.0000000000039,38.628580446043514,0.3169321349860095,-1.0686966686899444
329.000000000004,38.7235967198946,0.2693561966097488,-1.0913451152803586
330.000000000004,38.8188983000872,0.22624246877783127,-1.1093714732346927
331.000000000004,38.91544459103925,0.19092761555434395,-1.1304036344635877
332.000000000004,39.00844635602785,0.16180763158675476,-1.1479803562096857
333.000000000004,39.10526663785869,0.13533386305219441,-1.165256272600113
334.00000000000404,39.20264648511503,0.11735824714548504,-1.184666987536236
335.00000000000404,39.29845499417579,0.10199049235928814,-1.2024941300622558
336.00000000000404,39.39379103137465,0.09293342910189573,-1.2175484038745217
337.0000000000041,39.49010056286927,0.08321883056515589,-1.2340867654678749
338.0000000000041,39.58539944711785,0.07763005654031918,-1.2476844251408932
339.0000000000041,39.68175729960989,0.07537409741750412,-1.2643787088687972
340.0000000000041,39.777412443963,0.07152509087036296,-1.2772254209909546
341.0000000000041,39.872610161610766,0.07252600181419855,-1.289608313898265
342.00000000000415,39.9709045578099,0.07435957879072108,-1.3019026435487668
343.00000000000415,40.066717348492865,0.07469131131030693,-1.3139578589941774
344.00000000000415,40.16283151128412,0.07652464072138798,-1.3272988961332204
345.0000000000042,40.25848084075387,0.08185397940814221,-1.3390685511187237
346.0000000000042,40.355420126004205,0.08712247753217095,-1.350561746055332
347.0000000000042,40.45139664390923,0.0891462389603428,-1.3604414328740302
348.0000000000042,40.547312555421755,0.0905174908918217,-1.3700556713167682
349.0000000000042,40.645209185699805,0.09385554468451429,-1.3794720912114102
350.00000000000426,40.741824900001326,0.09897287839852376,-1.3880898449022854
351.00000000000426,40.83774187782013,0.10449965445029696,-1.3992230097099743
352.00000000000426,40.93483659353808,0.10822990765383433,-1.4078275008215888
353.0000000000043,41.03196730161459,0.11470691374168351,-1.4178655311159738
354.0000000000043,41.12840160673566,0.11561358748244288,-1.4249643811561983
355.0000000000043,41.22546395721508,0.12066306754927036,-1.4360922738180513
356.0000000000043,41.32278731364034,0.12275254051414763,-1.4437847483953203
357.0000000000043,41.418922909734825,0.12716875703065678,-1.4518293746440074
358.0000000000044,41.516631163549405,0.1300211996494765,-1.4609900046445103
359.0000000000044,41.61329571260168,0.1323980987843945,-1.4697770796697518
360.0000000000044,41.71020753249159,0.13655558620651131,-1.4778239998364175
361.00000000000443,41.807319163388314,0.13839788973065947,-1.4812122011543107
362.00000000000443,41.904004083522324,0.14058638359108927,-1.4909777170682714
363.00000000000443,42.00147055387044,0.14491854602702875,-1.505716425414394
364.00000000000443,42.098824943591055,0.14553792663778664,-1.5116511800653623
365.00000000000443,42.19548764054492,0.14637271311849542,-1.5203465622069157
366.0000000000045,42.29281629580282,0.14780766105941645,-1.527652225044922
367.0000000000045,42.389709141535114,0.14769794239161554,-1.5348433220312865
368.0000000000045,42.48692421286604,0.14886041906620945,-1.5440987328699185
369.00000000000455,42.583748643227175,0.1477109888490526,-1.5506157748135245
370.00000000000455,42.68038404884726,0.14963563166190386,-1.5588424402896202
371.00000000000455,42.778305464513274,0.15166791367034638,-1.5665702092562235
372.00000000000455,42.875366374649964,0.15087093355252595,-1.576837035457253
373.00000000000455,42.97219753512665,0.15128295105534645,-1.5821448524700163
374.0000000000046,43.06861384515393,0.15082211235692566,-1.5913665582010643
375.0000000000046,43.16394952050436,0.15000225452685673,-1.6017797118034758
376.0000000000046,43.26328532614704,0.1514305436616275,-1.6122404751260055
377.00000000000466,43.35989840165085,0.14949287080421864,-1.618406198860892
378.00000000000466,43.45653080815018,0.1501930254947692,-1.6271058041114266
379.00000000000466,43.5536261595179,0.14967817431579966,-1.634537137868632
380.00000000000466,43.64907645138568,0.14863942045541823,-1.6403974069877658
381.00000000000466,43.748487454626556,0.1497126493598092,-1.6492281686435248
382.0000000000047,43.844350968614705,0.1467121062762768,-1.6578912591355848
383.0000000000047,43.942363667888195,0.14804639263630842,-1.666942039914812
384.0000000000047,44.03989749196196,0.14585489517545125,-1.6754975295769872
385.0000000000048,44.13606408256482,0.14377931408163186,-1.6826519058924698
386.0000000000048,44.23175509785568,0.144237892553028,-1.6897226778986711
387.0000000000048,44.33113599118728,0.14637751413449235,-1.6976831758174833
388.0000000000048,44.428478545054546,0.14531598715523497,-1.7068976620053329
389.0000000000048,44.52476820148884,0.14544530152518276,-1.7133388788423112
390.00000000000483,44.62250913424543,0.14721843819499902,-1.7213542880126647
391.00000000000483,44.7190970360779,0.14792436114385898,-1.7304282532217368
392.00000000000483,44.81673261453788,0.1511972028933823,-1.7382639279750633
393.0000000000049,44.91442288082184,0.14928678349478397,-1.7451526210315862
394.0000000000049,45.01153426366985,0.15204675885401675,-1.7534966149152673
395.0000000000049,45.10937586033983,0.15497266499134404,-1.7615116164038889
396.0000000000049,45.207449358784864,0.1559769978417292,-1.7710246568363184
397.0000000000049,45.30347993116747,0.16005802932211294,-1.7790724881344304
398.00000000000495,45.397765805649456,0.15935178463543176,-1.7866014829815473
399.00000000000495,45.499204005295326,0.16186670915292178,-1.7939545930596448
400.00000000000495,45.59591481390092,0.16253161497130414,-1.8016769403391972
401.000000000005,45.69383284965758,0.1657511094571023,-1.8090073960169546
402.000000000005,45.79118046030205,0.16745674229160734,-1.8148364581626844
403.000000000005,45.88932530790277,0.16989723552388342,-1.8226572479509855
404.000000000005,45.98602388502198,0.16943329662854928,-1.8323456621402179
405.000000000005,46.082736274169314,0.17062174558189325,-1.8388402118180132
406.00000000000506,46.181567005073056,0.1707254600489222,-1.8462848029000751
407.00000000000506,46.27808922985247,0.17258735076944093,-1.8540104654458824
408.00000000000506,46.375688435312874,0.17293579115847268,-1.861548586891523
409.0000000000051,46.472568882272,0.17465019467649595,-1.8691604799342123
410.0000000000051,46.570286446780415,0.17565132782920706,-1.8749876611520144
411.0000000000051,46.66888398945917,0.1747581016276119,-1.8809475693691518
412.0000000000051,46.76562251591877,0.1760441089080364,-1.889682518832482
413.0000000000051,46.86284069867295,0.1767912867569631,-1.8950303853984116
414.0000000000052,46.96076065720516,0.177357098590731,-1.9035380991470499
415.0000000000052,47.05769513191832,0.1784811456442244,-1.9159564768468549
416.0000000000052,47.1555686961617,0.17911342387823392,-1.921461687339555
417.00000000000523,47.25295645127544,0.18080706941136715,-1.927546807518374
418.00000000000523,47.34924902134989,0.18089760343420863,-1.9332443440703364
419.00000000000523,47.44879848321802,0.18040658428050732,-1.941184196725465
420.00000000000523,47.545491547973356,0.183734427678085,-1.9493861176504614
421.00000000000523,47.64404896229733,0.18030723807320498,-1.9547087364550468
422.0000000000053,47.74084340927934,0.18420434672595598,-1.9612230701598286
423.0000000000053,47.838102266644306,0.18311811167634073,-1.9684110558473895
424.0000000000053,47.93642487492222,0.1857241473759561,-1.9754722649837593
425.00000000000534,48.03471008658433,0.18525955543171135,-1.9812320605648739
426.00000000000534,48.132902191268364,0.18533695643488513,-1.986835206513951
427.00000000000534,48.22954137658376,0.1851956709112803,-1.9935248014615166
428.00000000000534,48.32776420587814,0.1851744293337222,-2.001357074638628
429.00000000000534,48.42577453605337,0.18642567346866745,-2.0096088471791957
430.0000000000054,48.52429872894061,0.1880852112514802,-2.0183326418721426
431.0000000000054,48.62153282215688,0.1892680162588674,-2.025112475143179
432.0000000000054,48.719162675622236,0.19021549389500114,-2.030933273151985
433.00000000000546,48.8181962041297,0.19341395584861965,-2.0353690954143273
434.00000000000546,48.91665738837205,0.19304679565407484,-2.04179249823929
435.00000000000546,49.01179163093572,0.1931743761791534,-2.047909646097536
436.00000000000546,49.11246310508246,0.1955983999507233,-2.052619513054154
437.00000000000546,49.209801734859425,0.19613277070400387,-2.058534042822675
438.0000000000055,49.30789931067752,0.19917637145352862,-2.0636607898934516
439.0000000000055,49.4066442877981,0.19930532902013276,-2.070424211365488
440.0000000000055,49.50389650840772,0.19789945737388476,-2.076357527485067
441.00000000000557,49.599885115727375,0.200643991042327,-2.0824560900459614
442.00000000000557,49.699136433498005,0.20194632202468432,-2.088386032529623
443.00000000000557,49.795418959067376,0.20416847252345205,-2.094984930495641
444.00000000000557,49.896410601750176,0.20471668892164863,-2.101905278928284
445.00000000000557,49.994443525864845,0.2070820982025699,-2.1100875221233166
446.0000000000056,50.09273004366112,0.20708812752616973,-2.115061898198017
447.0000000000056,50.18981195564714,0.20803666698247747,-2.1214395726686774
448.0000000000056,50.287471293917605,0.20825406047153106,-2.127965749607113
449.0000000000057,50.386015381186134,0.20868991989698277,-2.1341120250658108
450.0000000000057,50.484662024935794,0.2108970751849037,-2.1410705454229224
451.0000000000057,50.58182092661626,0.21196370522921126,-2.1471825727118596
452.0000000000057,50.681314718630006,0.21185263947319194,-2.15520550562127
453.0000000000057,50.77829222095857,0.21200991073801345,-2.1611155246154494
454.00000000000574,50.876902242775984,0.2138288448632895,-2.1652907523593647
455.00000000000574,50.973533033819756,0.2141471664334268,-2.173385418236582
456.00000000000574,51.07265412367312,0.2130668108705544,-2.1811665674688654
457.0000000000058,51.17123423251668,0.21230365401995255,-2.187427285367213
458.0000000000058,51.26914805070264,0.2143204293897174,-2.195249460109877
459.0000000000058,51.367997137895074,0.21462994337524605,-2.2038148602706378
460.0000000000058,51.46592183678581,0.21323671541491473,-2.2106386866873415
461.0000000000058,51.56445655824213,0.21238096108909893,-2.21554338831327
462.00000000000585,51.662826352279865,0.21213798483891955,-2.2199863008999063
463.00000000000585,51.76086623293418,0.21409028183523116,-2.2259465017793163
464.00000000000585,51.85917444483732,0.21310412876117696,-2.233689378321625
465.0000000000059,51.95745200507088,0.2110478623373483,-2.240102530188058
466.0000000000059,52.05537381634166,0.2107870217715021,-2.2479328396661953
467.0000000000059,52.154168648929186,0.212988094436884,-2.2544560596404524
468.0000000000059,52.251854665407556,0.2127114454403074,-2.2614595651831726
469.0000000000059,52.351528995572366,0.21303933070928632,-2.2698109497957875
470.00000000000597,52.448844378171785,0.2138091119600078,-2.27679154111271
471.00000000000597,52.54723576470678,0.21144294311197653,-2.2826590563389857
472.00000000000597,52.64563020240629,0.21165865708937504,-2.290806380204109
473.000000000006,52.74443037063658,0.20961101998338855,-2.2963312052150258
474.000000000006,52.84171137737026,0.20939997767237395,-2.30485024698783
475.000000000006,52.94020554220689,0.20902570983831908,-2.3091936254401055
476.000000000006,53.03870040605941,0.20587442314630738,-2.315042473531464
477.000000000006,53.1365211295845,0.20566950701235787,-2.322056862000279
478.0000000000061,53.23556148933404,0.20653133692728048,-2.3281518241619796
479.0000000000061,53.333887362449815,0.2034095618586207,-2.334121098533908
480.0000000000061,53.431886790438305,0.2024278114828854,-2.342197954322799
481.00000000000614,53.530284715643525,0.20229853323075092,-2.347731782000446
482.00000000000614,53.6290569121262,0.2011777859851686,-2.354094473205416
483.00000000000614,53.72712925039261,0.20119415896711496,-2.3612950676793947
484.00000000000614,53.82547855419449,0.20021083995913896,-2.3681017628503542
485.00000000000614,53.9237570378386,0.1998475934380009,-2.373890432262785
486.0000000000062,54.02231574977531,0.1981114447442497,-2.379375417435383
487.0000000000062,54.12093706739518,0.19837055449186602,-2.3826307869954118
488.0000000000062,54.22027641366043,0.1967080981290485,-2.390196219572973
489.00000000000625,54.318530841433244,0.1990054475629407,-2.395786667399083
490.00000000000625,54.41706545935232,0.1966131839524361,-2.4013842239704575
491.00000000000625,54.515786571737,0.19543777006110008,-2.4053442555439934
492.00000000000625,54.61436736164766,0.19549293704301246,-2.4099639762048506
493.00000000000625,54.71360637370503,0.1935772051878542,-2.4151044546799407
494.0000000000063,54.81229714944284,0.19306871907825346,-2.4187520281277544
495.0000000000063,54.91129017371189,0.1933362175632553,-2.4255647566722174
496.0000000000063,55.01107243627292,0.19419312083950452,-2.4323275512810616
497.00000000000637,55.10849851125787,0.19237274428222711,-2.4356810775919495
498.00000000000637,55.20758328567729,0.19096076997297434,-2.4384411532372496
499.00000000000637,55.30689517835621,0.18907480567742607,-2.4452906601533977
500.00000000000637,55.40543025053177,0.19007632250574713,-2.451069743161538
501.00000000000637,55.50354659875905,0.18873431005669106,-2.455921152743183
502.0000000000064,55.604251721892915,0.18990846809235534,-2.4586193714052973
503.0000000000064,55.7021985702817,0.18869146639095097,-2.4628951712347416
504.0000000000064,55.801474598642315,0.1891395884508132,-2.4678871825051134
505.0000000000065,55.90081570677545,0.18984702858525998,-2.470826356831505
506.0000000000065,56.000105241279755,0.1899919544057082,-2.475609435749336
507.0000000000065,56.098403126288005,0.18980406044599996,-2.479066321313398
508.0000000000065,56.197047374545726,0.18775720909738464,-2.4802359521545547
509.0000000000065,56.29609599916196,0.18794547782258242,-2.483696490209685
510.00000000000654,56.3954228896046,0.18685836351606638,-2.4855333430972055
511.00000000000654,56.494964122950556,0.18874947862739244,-2.4892993220060813
512.0000000000066,56.59366474628892,0.18858444881819653,-2.4967602558737507
513.0000000000066,56.69320582147777,0.18935021007402025,-2.5026674147642636
514.0000000000066,56.791853347441744,0.1901031717275391,-2.506408268741505
515.0000000000066,56.89193076557022,0.1898228784916069,-2.5081671667137453
516.0000000000066,56.99011749729523,0.18784182431625346,-2.510008835170325
517.0000000000066,57.08937072767076,0.18645201748937917,-2.5089378026134646
518.0000000000066,57.18826863643825,0.1877740771151573,-2.5138113670999065
519.0000000000066,57.287518246823815,0.18600993829111362,-2.517987093904352
520.0000000000066,57.38696670228095,0.1860627784811465,-2.5261659247893045
521.0000000000067,57.486168713170784,0.18661316283409418,-2.530133247480816
522.0000000000067,57.58595108067903,0.18815911581382838,-2.5312811159950477
523.0000000000067,57.684269395530656,0.18544587440935795,-2.536421904314814
524.0000000000067,57.78394026948337,0.1854152957453481,-2.541796736145528
525.0000000000067,57.883754592926906,0.18377307505891716,-2.544288314593621
526.0000000000068,57.982136388426945,0.1826475303706585,-2.5434459854688827
527.0000000000068,58.081532918481564,0.18133701771268879,-2.544220662898464
528.0000000000068,58.18061115546596,0.1806326931911531,-2.5486723248013594
529.0000000000068,58.28029034964241,0.18160742060710722,-2.5527778488505763
530.0000000000068,58.37862663108537,0.18174417513154206,-2.5542279467415034
531.0000000000068,58.47862902254991,0.1806554607750575,-2.557471007186618
532.0000000000068,58.576260326190436,0.1794600596130082,-2.561615442910184
533.0000000000068,58.67612950939567,0.17841071277178533,-2.5630274970221034
534.0000000000068,58.775248859686286,0.17874242801233203,-2.5660406808007656
535.0000000000068,58.874702759062366,0.17789288429743588,-2.569832859605677
536.0000000000068,58.97413402018177,0.17822551759874827,-2.5717712843374665
537.0000000000069,59.073756060088485,0.1767405222779838,-2.5763963378546775
538.0000000000069,59.17185363816792,0.1758240082538023,-2.578909073187556
539.0000000000069,59.27071064429197,0.17634746395216327,-2.5822740494949614
540.0000000000069,59.37050478941419,0.17626775748087298,-2.585321166838942
541.0000000000069,59.469413557504794,0.17566369097914547,-2.587534499210247
542.000000000007,59.568045532765304,0.1758518031187275,-2.5917118442166114
543.000000000007,59.66751894424984,0.17510528646990037,-2.5953833200335055
544.000000000007,59.7662989249405,0.17652704877103909,-2.598176147633817
545.000000000007,59.86548712073102,0.17345740975982737,-2.6009289330988032
546.000000000007,59.96501694472639,0.17404580929554442,-2.603655368780551
547.000000000007,60.063746661463945,0.17276020524087615,-2.6063891876955947
548.000000000007,60.16171026936975,0.17283798751901702,-2.60766089855362
549.000000000007,60.26218454868348,0.17185114272070579,-2.6111653655040445
550.000000000007,60.362022926513696,0.1700691223338282,-2.6147707283487827
551.000000000007,60.46042443651293,0.1706549117510548,-2.617543801485562
552.000000000007,60.560293197003865,0.16989113857426885,-2.6205193823120627
553.0000000000072,60.659504020221846,0.16807598011547514,-2.623878020094904
554.0000000000072,60.759012830760966,0.16755578774462193,-2.628725816286395
555.0000000000072,60.857644493250994,0.16519413365227176,-2.6299036900430073
556.0000000000072,60.95713318955984,0.16585054706216062,-2.634180893386902
557.0000000000072,61.056570161351445,0.1640504408208815,-2.638392995863312
558.0000000000073,61.155188470763164,0.16448472527743713,-2.640226966325025
559.0000000000073,61.254840691741876,0.1609450728225444,-2.6429088318907468
560.0000000000073,61.35408576551445,0.16302567382885025,-2.646687012616531
561.0000000000073,61.45235375185119,0.16229623612206207,-2.6491469372653715
562.0000000000073,61.55106889445134,0.15952375614211795,-2.650369015268661
563.0000000000073,61.6508313851338,0.15781322845679735,-2.653129165886466
564.0000000000073,61.75205082823808,0.15662044311028783,-2.6559148292930472
565.0000000000073,61.852049699277735,0.15567250717839343,-2.6587237272312825
566.0000000000073,61.95091745323237,0.15427668414255707,-2.6602580497593005
567.0000000000073,62.050384475032835,0.15633558553945465,-2.664418281755123
568.0000000000074,62.14926631851349,0.15245268954813168,-2.667134650092142
569.0000000000074,62.24972424606992,0.15197454937688504,-2.672194095224653
570.0000000000074,62.34799692578867,0.1525073508153364,-2.6743272927372796
571.0000000000074,62.44890367156661,0.15310480766440843,-2.6764256085082145
572.0000000000074,62.54874810122014,0.1514036136834312,-2.676522719174681
573.0000000000074,62.64823400916285,0.14891425543560416,-2.679190157547312
574.0000000000074,62.74813405618495,0.15033730691805225,-2.683214307648055
575.0000000000075,62.84647375913714,0.1470707362875472,-2.685716225601136
576.0000000000075,62.94687942924671,0.14893402391298138,-2.687762794463837
577.0000000000075,63.04630147969967,0.1484468249130334,-2.69055610829406
578.0000000000075,63.145235029178224,0.1467253868571094,-2.6958013682255233
579.0000000000075,63.24528714802513,0.14679547254916098,-2.697556728341328
580.0000000000075,63.342164610769636,0.14812798972088353,-2.6990942266983224
581.0000000000075,63.44431036550604,0.1457827415784972,-2.70192971680914
582.0000000000075,63.54389372630253,0.1470151328535254,-2.7055211435397206
583.0000000000075,63.64258779748196,0.14722438278196165,-2.7074000220307886
584.0000000000076,63.742049730078286,0.14786517746726036,-2.708676039792949
585.0000000000076,63.8405130308635,0.14767883478506116,-2.7113388393300966
586.0000000000076,63.94058644890395,0.1491952738607369,-2.714260255761093
587.0000000000076,64.03980829218362,0.14958686449974262,-2.7155860617057055
588.0000000000076,64.13918632497719,0.15140502218627738,-2.7195391731937386
589.0000000000076,64.23816861815922,0.15075945883878827,-2.7208684357391038
590.0000000000076,64.3360682466636,0.1507282476408489,-2.7220948654418144
591.0000000000077,64.43729068685158,0.15225457205340243,-2.7249087777994694
592.0000000000077,64.5368001101106,0.15347498842363594,-2.728858798150511
593.0000000000077,64.6358527895022,0.15314643862626925,-2.7302090155302907
594.0000000000077,64.73560697186099,0.15307584922789225,-2.7329375684891484
595.0000000000077,64.83477645275993,0.15318778828496968,-2.734277572422321
596.0000000000077,64.9352210657622,0.1526245102675512,-2.7344894888709392
597.0000000000077,65.03497228942139,0.1540375790719987,-2.736847017076591
598.0000000000077,65.13449620750684,0.15098009534797,-2.7381988923780467
599.0000000000077,65.23468617140784,0.15335401453915518,-2.739546746546594
600.0000000000078,65.33549500409048,0.15379447284525435,-2.741817877332164
601.0000000000078,65.43472327408566,0.15539296766244984,-2.7424567402477735
602.0000000000078,65.53369922095371,0.15479608724265412,-2.743920285814455
603.0000000000078,65.63430937646521,0.15654877633716857,-2.7452305761949862
604.0000000000078,65.73332104574474,0.15643137163595178,-2.7479967216782413
605.0000000000078,65.8330139305735,0.15762030764201918,-2.7505018054795025
606.0000000000078,65.93407405881767,0.1555882229293959,-2.751998398608783
607.000000000008,66.03402831809606,0.15696969621658943,-2.7532578122251343
608.000000000008,66.13348080581974,0.15721121368854557,-2.754483464731746
609.000000000008,66.23306842922004,0.15759788203783945,-2.7543640478034366
610.000000000008,66.33288890039528,0.15888494102438183,-2.757152149629857
611.000000000008,66.4337615869522,0.15766450075265473,-2.759709922080189
612.000000000008,66.53299774904072,0.158944828473949,-2.761074841390985
613.000000000008,66.63260140885113,0.15626119186870666,-2.7632417421375477
614.000000000008,66.732201840765,0.1614442466969299,-2.763700612649642
615.000000000008,66.83233965902976,0.1607487321971472,-2.7662180214184833
616.0000000000081,66.93087101848278,0.16057972201323617,-2.76507628518687
617.0000000000081,67.03044921555909,0.16162474537199303,-2.7698318626426057
618.0000000000081,67.13079417705846,0.16214566886580767,-2.7698100044727703
619.0000000000081,67.23000000000083,0.1576778216569431,-2.769383272920303
620.0000000000081,67.3300000000008,0.1599049018117908,-2.768500477597449
621.0000000000081,67.4289529353964,0.1616884282591549,-2.7697632374367327
622.0000000000081,67.5280979818888,0.16058251937235313,-2.7703615161207233
623.0000000000082,67.62733748513003,0.16160648137567912,-2.7723467939921056
624.0000000000082,67.72766656999343,0.162167250479058,-2.7740698489406954
625.0000000000082,67.82781900844947,0.16451886681164554,-2.775310371076329
626.0000000000082,67.92587880708474,0.16547377895237542,-2.7740000256767217
627.0000000000082,68.02716244069846,0.16520180327961287,-2.77666693404698
628.0000000000082,68.12626622590476,0.1660471775361868,-2.7779904267679227
629.0000000000082,68.22588399333775,0.1670146751600595,-2.776558271729195
630.0000000000082,68.3252604877169,0.1661732833849003,-2.777919148506018
631.0000000000082,68.42442906758816,0.1682629486213212,-2.7793829218959805
632.0000000000083,68.5249922324374,0.16721488653614422,-2.7767036161165586
633.0000000000083,68.62454954563354,0.1675849107130463,-2.779372387023657
634.0000000000083,68.7236783955293,0.16639334869348618,-2.7805816231649856
635.0000000000083,68.82418006795909,0.16796199270581788,-2.7818987505966
636.0000000000083,68.92355273502483,0.16608363382918553,-2.7838805527734904
637.0000000000083,69.02254504576261,0.16645972621487767,-2.784526639735684
638.0000000000083,69.12283374150694,0.16740007093572412,-2.7866174678707454
639.0000000000084,69.22204527294735,0.16692082039128772,-2.7865093748746896
640.0000000000084,69.32205885805986,0.16866819392494928,-2.7865292561831994
641.0000000000084,69.42041532287939,0.1680647115706572,-2.787724220644857
642.0000000000084,69.52083019335446,0.16721425288787153,-2.78683966680851
643.0000000000084,69.61960126403254,0.16940410243077564,-2.7868431531187667
644.0000000000084,69.72000000000085,0.1712352077222834,-2.790757127098412
645.0000000000084,69.8187013724548,0.1695755387806876,-2.7921096027883103
646.0000000000084,69.91972314140037,0.17078050791415106,-2.791100471122988