File: 01_Data/Polyisocyanurate_Foam_Board/STA/N2/10K_min/Polyisocyanurate_Foam_Board_STA_N2_10KData_221019_R3.csv
##Temp./Â°C,Time/min,DSC/(mW/mg),Mass loss/mg
51.0,10.739446955446205,0.03169563130679909,0.0028438368648755485
52.000000000000014,11.091149471360245,0.05554019153001044,0.0002770253033839154
53.00000000000003,11.325654149928505,0.06962485893950765,0.0016329576259757062
54.00000000000004,11.522927262292558,0.08763682355055313,0.0010965853948787796
55.00000000000006,11.69644291545221,0.09866069490801088,0.0011404539984276596
56.00000000000007,11.859682455070523,0.10534876853312092,2.6041879978677684e-05
57.000000000000085,12.01086828300657,0.11355522532653306,0.003365233420778324
58.0000000000001,12.155979576084597,0.1208643851433473,0.0019725943565065407
59.000000000000114,12.293660676216867,0.1254033177913032,0.003676601007907898
60.00000000000013,12.429362647737628,0.13101728003566682,0.0015184175838314218
61.00000000000014,12.562476321076907,0.13223125614244524,0.0008080317627294775
62.000000000000156,12.690902262019373,0.1354518415409509,0.0012313199443934053
63.00000000000017,12.818666664236652,0.14080466630602984,0.0015889185970427988
64.00000000000018,12.941518944106047,0.1413695832886992,0.0020116108411718514
65.0000000000002,13.066631942086302,0.14558565011310498,0.0010690360742922067
66.00000000000021,13.187646357209093,0.1470482505914683,0.0005860055530417796
67.00000000000023,13.307851691535308,0.14970673116962452,0.0011045171466932402
68.00000000000024,13.426524181445314,0.15414131882592685,0.0013902097277540548
69.00000000000026,13.541371636500715,0.15642040076870534,0.0006582825180281304
70.00000000000027,13.65856160941597,0.16074100015321457,-0.00018479001372906367
71.00000000000028,13.774107383007127,0.15801602740882936,0.0018399422079049543
72.0000000000003,13.887547708387611,0.16394534145409279,1.3246916892306615e-05
73.00000000000031,14.000320693747447,0.1661222562432958,0.0018000887973226298
74.00000000000033,14.11294091550425,0.1676620270826481,0.0012126882439229547
75.00000000000034,14.224956145052884,0.16725408116734308,0.0006826206249694877
76.00000000000036,14.333727692866438,0.17050317963903328,0.00021137231505008458
77.00000000000037,14.444591159941956,0.17173606323484392,0.0001776577183667527
78.00000000000038,14.553172441572457,0.17186225301694846,0.00021520430253652023
79.0000000000004,14.66204147437168,0.17420239652795855,0.00028681574209876715
80.00000000000041,14.770696869055953,0.17364344511983687,0.0013918853028629385
81.00000000000043,14.878835463897785,0.17325738986360528,-0.0011063988429018679
82.00000000000044,14.985533520794725,0.17366906155500272,-0.0012061737325854693
83.00000000000045,15.09187438818487,0.17604941750660796,-0.0011113754305487333
84.00000000000047,15.196651303979484,0.17628112901569293,-0.0010445142414408082
85.00000000000048,15.30292779608221,0.1747544340727214,0.00032220695724216597
86.0000000000005,15.406845584416237,0.17569631938036534,0.0005876897703211981
87.00000000000051,15.51164756262641,0.17595151246590335,0.001534968324816255
88.00000000000053,15.613854630980699,0.17553371427612896,0.0015164350419825112
89.00000000000054,15.717621925131198,0.17630805916336112,0.00021227599211748327
90.00000000000055,15.820467437602261,0.1763249216625823,-0.0011084977694428844
91.00000000000057,15.922568519167948,0.17743479070464552,0.00019907981230815608
92.00000000000058,16.0256942756416,0.1782115040637986,0.00020945993650567374
93.0000000000006,16.125954788259875,0.1781966088833692,-8.72893788628204e-05
94.00000000000061,16.228009335505778,0.17742081914222696,-0.0012206253614763796
95.00000000000063,16.327762841304548,0.17967177895364828,-0.0012183485382921688
96.00000000000064,16.430267854316504,0.1794120347249808,-0.0011826336235616353
97.00000000000065,16.530942299613894,0.17878985238447376,0.00010204138752722969
98.00000000000067,16.629297931125855,0.18168506130010198,0.0001191587812972017
99.00000000000068,16.729165084041952,0.17918102319790286,7.955633732059653e-05
100.0000000000007,16.828051456145126,0.18312293608545704,0.00010990392024279316
101.00000000000071,16.929046477911456,0.18213457141924072,9.278466110629324e-05
102.00000000000072,17.027975242749832,0.18326309295564136,-0.0012654357716552767
103.00000000000074,17.126003111823582,0.18320041988443225,0.00010052619476308422
104.00000000000075,17.225345064166433,0.18482169473620402,-0.001782505722019323
105.00000000000077,17.324259267985514,0.18634070289387528,-0.001783479306245006
106.00000000000078,17.42205709515113,0.1870119139834039,-0.0011774032191080863
107.0000000000008,17.520136261268807,0.18729921938835115,-0.00021921834546212438
108.00000000000081,17.618906000888206,0.18831640703560504,6.977629006055253e-05
109.00000000000082,17.717011280249707,0.18954958067692373,-0.0005633163093543558
110.00000000000084,17.814940147807587,0.19053219307575897,-0.002502600466743665
111.00000000000085,17.91232661761288,0.19400526349675973,-0.001210156691630715
112.00000000000087,18.01172574625313,0.1946324314767428,-0.0025063480142595296
113.00000000000088,18.109166334088936,0.19550955330846131,-0.0012762948303777222
114.0000000000009,18.20690403389229,0.1966925048635505,-0.0012290363170599505
115.00000000000091,18.304641996027357,0.1964329432730656,-0.0026390754335032796
116.00000000000092,18.40280766093909,0.1988211596659536,-0.0011227616061564305
117.00000000000094,18.500822960899555,0.20097409865780624,-0.002605138784251615
118.00000000000095,18.5981699210121,0.1995514443266726,-0.0025308829041295056
119.00000000000097,18.694984448461984,0.19973420930320585,-0.0051921366117930745
120.00000000000098,18.79280490298741,0.19908600655353825,-0.0051711230678446185
121.000000000001,18.88733808512546,0.2024430751802706,-0.0025087716871059484
122.00000000000101,18.987346357218005,0.20239910782358284,-0.0012205839965959697
123.00000000000102,19.084769816953557,0.20267545314227675,-0.002682285624411307
124.00000000000104,19.182031149225967,0.20503682919353472,-0.0026401860613400885
125.00000000000105,19.277586688514866,0.2069940553981685,-0.0026378122332824105
126.00000000000107,19.375026178696043,0.2073303243955782,-0.002641596753848674
127.00000000000108,19.47223466966425,0.20753171376690716,-0.0020170874992819776
128.00000000000108,19.568752484468362,0.21011842638135325,-0.0020300657795404575
129.0000000000011,19.665482858023594,0.20964028465323803,-0.0019958391937660025
130.00000000000114,19.762403609952667,0.2108209931309033,-0.003210446783207921
131.00000000000114,19.858253098200613,0.2126783540585775,-0.0034599074937275986
132.00000000000114,19.95472924816159,0.21268668794547974,-0.00363138789617512
133.00000000000117,20.05135935442295,0.21401906021794148,-0.0036299654538742843
134.0000000000012,20.1467446221799,0.2161121671371763,-0.0042843298671169094
135.0000000000012,20.243208449986007,0.2163481109881511,-0.005943897866452552
136.0000000000012,20.33973427066948,0.2176205215266036,-0.005956773434559359
137.00000000000122,20.434675589827915,0.2167689283401507,-0.005956948870949219
138.00000000000125,20.531424121402058,0.21718149260732644,-0.00726238162200854
139.00000000000125,20.626596002553466,0.21684806094399234,-0.008689032271266939
140.00000000000125,20.72195747943377,0.21592348597206334,-0.007258647889862857
141.00000000000128,20.817607771249524,0.21806064546108073,-0.005946863264756352
142.0000000000013,20.914860125087454,0.21530259028037202,-0.00726576218660302
143.0000000000013,21.006580427915747,0.21706561766523247,-0.005939979742123569
144.0000000000013,21.105466117458526,0.21644856866196205,-0.007248017779254212
145.00000000000134,21.198752348969375,0.21537788523739176,-0.005930556562226741
146.00000000000136,21.29542301276915,0.21670535334094498,-0.005930148028977733
147.00000000000136,21.39009240542549,0.2187769694644165,-0.00592190152740546
148.00000000000136,21.48555689923483,0.22053954047652002,-0.007468439324392229
149.0000000000014,21.58120460318612,0.21787778258758306,-0.0061642424868164625
150.00000000000142,21.67331123730535,0.21798397583271012,-0.00813001419825543
151.00000000000142,21.771568433294874,0.2200909955572089,-0.010150129297968213
152.00000000000142,21.86603354138999,0.22224527807600847,-0.012728061432937032
153.00000000000145,21.960842045110173,0.22185059055489698,-0.012739911918858482
154.00000000000148,22.0563030625976,0.22208598132300594,-0.012755894817423119
155.00000000000148,22.151051140169155,0.22328034944940978,-0.014019687816421822
156.00000000000148,22.246460099288463,0.22424978452270294,-0.011789817777669853
157.0000000000015,22.342137210532634,0.2252442698010536,-0.012747814082703535
158.00000000000153,22.436301198925797,0.224103420082844,-0.012750193811570831
159.00000000000153,22.530807017635667,0.2243868263720994,-0.014059575410376723
160.00000000000153,22.62701676520192,0.22848391155640768,-0.014014590334888055
161.00000000000156,22.721568970776996,0.2277624587137117,-0.014719775318200234
162.0000000000016,22.817164002652863,0.2272215194247027,-0.015380328511318098
163.0000000000016,22.912324984760335,0.23049917833696565,-0.015380033646526847
164.0000000000016,23.006568380142415,0.23188225108312033,-0.016730523163525746
165.00000000000162,23.099727260625688,0.23219343225020617,-0.018010160379734685
166.00000000000165,23.196100419298997,0.23720961710139477,-0.01799991429900949
167.00000000000165,23.291315755015805,0.2382336545402861,-0.020645148011443126
168.00000000000165,23.386002546822702,0.2399130625280066,-0.021962582378658002
169.00000000000168,23.480584504231217,0.24055579634299873,-0.02327991430517251
170.0000000000017,23.57555744762789,0.24411071396110495,-0.023279872931000867
171.0000000000017,23.671404577213096,0.24499979134866678,-0.024599472378812326
172.0000000000017,23.766248849354678,0.24563689873042027,-0.02460531942388089
173.00000000000173,23.859147401936912,0.24956075701444158,-0.023777065055844204
174.00000000000176,23.95583702188865,0.24961819397239682,-0.024124381983947174
175.00000000000176,24.050535538976902,0.25215896917952674,-0.02755952735541989
176.00000000000176,24.14561455173314,0.25473488150953905,-0.03019848247216883
177.0000000000018,24.241268874527268,0.2580985531125879,-0.03289672079502193
178.00000000000182,24.335696999261977,0.2590631974354831,-0.03415496429880527
179.00000000000182,24.4295085664486,0.2606362883710106,-0.03414996415335425
180.00000000000182,24.52560822824772,0.2601545863849968,-0.03511907555907223
181.00000000000185,24.619908329219136,0.26374700940219886,-0.03633310952611524
182.00000000000188,24.714490313248522,0.2668980621987128,-0.0405662042199646
183.00000000000188,24.809905307364403,0.2689913105527664,-0.0405700926235637
184.00000000000188,24.905097641032242,0.27034140042896837,-0.04269001141773332
185.0000000000019,24.999156241266263,0.2734121225930178,-0.045788898013800594
186.00000000000193,25.094690624458394,0.27511699847697957,-0.047109427813681215
187.00000000000193,25.188616485773387,0.2754836463513796,-0.04671345431453844
188.00000000000193,25.283201731296906,0.2790021241230195,-0.04846360511564374
189.00000000000196,25.378668899751627,0.28061235905538506,-0.054443237595720895
190.000000000002,25.473526687064332,0.2822837303005979,-0.057867256995634886
191.000000000002,25.568079252359574,0.2851529291069304,-0.0592155639195
192.000000000002,25.66280830697259,0.2896845354899223,-0.05918108937121591
193.00000000000202,25.755663401264723,0.2891733048344332,-0.06173079391295211
194.00000000000205,25.852191135179055,0.29028903183859034,-0.06487174107722815
195.00000000000205,25.946448489632928,0.29291185546480897,-0.06619864421826849
196.00000000000205,26.040572010643032,0.29304599824361305,-0.07026424980534607
197.00000000000207,26.135334721647755,0.2960782603104832,-0.0730280805000505
198.0000000000021,26.230663677533407,0.2994744309141272,-0.07866245122172533
199.0000000000021,26.324941778481623,0.3008927856876264,-0.07733851559697813
200.0000000000021,26.418913748667276,0.30263598884829046,-0.0799351027934283
201.00000000000213,26.513716203156353,0.3043010081420586,-0.0814281985133567
202.00000000000216,26.607716567779505,0.3065468762592473,-0.08516946475723985
203.00000000000216,26.70147449823081,0.3086949202835074,-0.09075041960497199
204.00000000000216,26.79806742744045,0.31055710368020795,-0.09473554507037196
205.0000000000022,26.89025298105369,0.3125519280687715,-0.09771273291566374
206.00000000000222,26.986262466291716,0.3137740383906112,-0.10328809156641716
207.00000000000222,27.081511616231197,0.3158703091373996,-0.10642072801973734
208.00000000000222,27.17404194233337,0.3167397025023467,-0.11018202880165351
209.00000000000225,27.27069285981956,0.3182931683704589,-0.11419573946425654
210.00000000000227,27.36607647357634,0.32138078309395035,-0.11569569512295264
211.00000000000227,27.45914266099964,0.3218699695746458,-0.11841430425847177
212.00000000000227,27.554673329755094,0.32337049053696204,-0.12216927113750975
213.0000000000023,27.649393099347044,0.3247716973533936,-0.12484521946081806
214.00000000000233,27.743307331694684,0.326633263727423,-0.13124711868583994
215.00000000000233,27.840191449393078,0.32763291098880437,-0.1310060117365679
216.00000000000233,27.934240855542086,0.3272452793833731,-0.1339589386220177
217.00000000000236,28.02862620615686,0.3291049309561359,-0.14030508898651162
218.0000000000024,28.123462202709767,0.3321442952040145,-0.14432410904071613
219.0000000000024,28.217853225518624,0.33380712015126796,-0.15273309979785976
220.0000000000024,28.313276092017663,0.3342183642564425,-0.1525460153526197
221.00000000000242,28.407176106137932,0.3362063159689248,-0.15545366448261078
222.00000000000244,28.50348590231041,0.33906703847389286,-0.15965792659243494
223.00000000000244,28.597979535413188,0.3370422194920269,-0.16117427395643436
224.00000000000244,28.69278258769194,0.3415646068440503,-0.1651908529899666
225.00000000000247,28.786550188228905,0.3429783057572664,-0.16773156430110037
226.0000000000025,28.881056777956598,0.34264754900259675,-0.17219083018966996
227.0000000000025,28.975627695195694,0.344599110649828,-0.17601263190943373
228.0000000000025,29.071595712518903,0.34550735776341734,-0.17873450685731251
229.00000000000253,29.166133202801408,0.34836567993943246,-0.1829675168330862
230.00000000000256,29.25926947266763,0.3484862521734848,-0.1842178666029861
231.00000000000256,29.35516114185767,0.34878447467591883,-0.1894090872083729
232.00000000000256,29.450000000000298,0.35282142615602613,-0.19255706808593276
233.0000000000026,29.543328260066165,0.35226275603049256,-0.1967023896810529
234.00000000000261,29.63870943382211,0.3557035707637775,-0.19926208084287733
235.00000000000261,29.73199878648125,0.354855600079471,-0.2019703375886195
236.00000000000261,29.8288880022345,0.3560252554143025,-0.20520166685362362
237.00000000000264,29.923719546962488,0.35680956223385596,-0.20880049028690895
238.00000000000267,30.018681667454832,0.3605014398191115,-0.21135473598284937
239.00000000000267,30.113938123205493,0.35841492328722435,-0.21364871193783097
240.00000000000267,30.20960800677633,0.3598374162310134,-0.21497258856705592
241.0000000000027,30.304522066613444,0.35901004382811874,-0.2175174413906431
242.00000000000273,30.398959292504877,0.3613454568872135,-0.22036461548474096
243.00000000000273,30.494966430496188,0.3632731394199424,-0.22357065457562442
244.00000000000273,30.58929128234486,0.3671905618107543,-0.2262783633574923
245.00000000000276,30.684557155962555,0.36874050567315736,-0.22632402781075633
246.00000000000279,30.78010321160982,0.3710638149259674,-0.23022564288192227
247.00000000000279,30.875142833111646,0.37108525039356804,-0.2343598743079105
248.00000000000279,30.970470730038826,0.3736470166870848,-0.23701609874029472
249.0000000000028,31.065245023094175,0.37596316612359026,-0.23966709342161963
250.00000000000284,31.161072399474154,0.37880851599619825,-0.24241236199636607
251.00000000000284,31.25417607909874,0.38079101832163176,-0.24372061564126568
252.00000000000284,31.350957714271328,0.38539332706562185,-0.24578424705008173
253.00000000000287,31.445713036444346,0.3892585445591771,-0.25055732921180773
254.0000000000029,31.541105365105302,0.39155563884305644,-0.2518925672639005
255.0000000000029,31.637684904689657,0.3947029785069203,-0.2544735483699494
256.0000000000029,31.731641942074113,0.39899321598954945,-0.2572930761062806
257.00000000000296,31.826379627803757,0.4017002038670067,-0.2559331322900955
258.00000000000296,31.922554679559052,0.40634099944850716,-0.26071959997087735
259.00000000000296,32.017823705603405,0.4099328925800985,-0.2649329827968683
260.00000000000296,32.11301881022607,0.4144666833708275,-0.2676908828040081
261.00000000000296,32.20797232193325,0.41945446519259116,-0.27152399692478246
262.000000000003,32.30297074440195,0.4233094094763949,-0.27543958681624137
263.000000000003,32.39813515240024,0.4275634672684924,-0.27695249107192677
264.000000000003,32.49378551876758,0.434459583127163,-0.2797528332077217
265.00000000000307,32.58971919819976,0.4396771819438841,-0.28249043955069375
266.00000000000307,32.68548686667852,0.4461590413618918,-0.28510083099950556
267.00000000000307,32.77991311671459,0.45016760965820113,-0.29235038811544634
268.00000000000307,32.87681178208733,0.4571388118703715,-0.2955314610076121
269.00000000000307,32.971757908070956,0.46274663231005897,-0.29681521990732174
270.0000000000031,33.06680372944469,0.47071212936224804,-0.3025622013402023
271.0000000000031,33.162550427569414,0.4764920696655697,-0.30838501553394604
272.0000000000031,33.257497800627675,0.4830634324935313,-0.31051270030955314
273.0000000000032,33.354119706076325,0.4919097663608578,-0.3151082693633045
274.0000000000032,33.44962088474001,0.5002201556752703,-0.31990795944159034
275.0000000000032,33.54524156381813,0.506516990409596,-0.32307287304541177
276.0000000000032,33.6406493758803,0.5182099230778822,-0.3299230524124912
277.0000000000032,33.73522777244521,0.5252057210556824,-0.3345587612355114
278.00000000000324,33.830842498142495,0.5364481834889524,-0.3393085794438857
279.00000000000324,33.927744510254044,0.5455137818278367,-0.34546601405401756
280.00000000000324,34.022752465419785,0.5552357498150579,-0.3512256934724811
281.0000000000033,34.11832845881813,0.5672725580873663,-0.358526939314888
282.0000000000033,34.21504910956517,0.5791290110930325,-0.36335568736491464
283.0000000000033,34.31074637080715,0.5900271038311063,-0.3696145549899814
284.0000000000033,34.40557354716078,0.603530295374902,-0.3752675200223363
285.0000000000033,34.501563909315976,0.6159975673615287,-0.3809205901745951
286.00000000000335,34.59690869399959,0.6290062758826358,-0.3877606596197052
287.00000000000335,34.693155022994254,0.6429731606772352,-0.39619583489340426
288.00000000000335,34.7884101040873,0.6614948137115525,-0.406261710806298
289.0000000000034,34.88422314085047,0.6753731504309972,-0.41657198119705674
290.0000000000034,34.97871799860729,0.6878867382005789,-0.42644966690054
291.0000000000034,35.07549661210883,0.7043357936671546,-0.43445572468738014
292.0000000000034,35.17175664675819,0.7200537162012136,-0.44213778699257755
293.0000000000034,35.26728916903799,0.7357178909437321,-0.4520335987262927
294.00000000000347,35.36352691922705,0.7516793549801342,-0.46529852349072787
295.00000000000347,35.45886581933924,0.7662831309493021,-0.47689497615742127
296.00000000000347,35.55437178084521,0.7807337773468723,-0.48664011756564207
297.0000000000035,35.65048324133442,0.7930551497511164,-0.4954290646829156
298.0000000000035,35.744059222589044,0.8068981744858473,-0.5088705331625762
299.0000000000035,35.84228827495742,0.8231342632525831,-0.5229098335912608
300.0000000000035,35.93778474405002,0.8341210775735814,-0.534908008013665
301.0000000000035,36.034559131132724,0.843198499724576,-0.5495510627666533
302.0000000000036,36.13000000000034,0.8564136789426585,-0.5644001980000768
303.0000000000036,36.22615217600475,0.8669686554289717,-0.5796024901299157
304.0000000000036,36.32207588682801,0.8779664626980659,-0.5954764928661085
305.00000000000364,36.417672894489016,0.8854449761621919,-0.6082577389374473
306.00000000000364,36.51374314602586,0.8936835066386415,-0.6237034124221625
307.00000000000364,36.610764279373015,0.9015096269078764,-0.640393769015771
308.00000000000364,36.70610944041191,0.906978126975968,-0.6553716108228516
309.00000000000364,36.80117603455412,0.9095600421751178,-0.6723677176035765
310.0000000000037,36.89805680603564,0.912107475060862,-0.6904672110229568
311.0000000000037,36.992945067480576,0.9113453886390509,-0.7080083313240548
312.0000000000037,37.091198482089894,0.9077185778510719,-0.7278147977716123
313.00000000000375,37.18641461524063,0.9030214536602684,-0.7490376846086146
314.00000000000375,37.28272943949536,0.8915785136370418,-0.7698234763617386
315.00000000000375,37.37695603854433,0.8744008675580281,-0.7903697538581005
316.00000000000375,37.472883563019245,0.8476038278705016,-0.8134394877661295
317.00000000000375,37.56953604931451,0.8183562968500611,-0.8354628691819133
318.0000000000038,37.66574514523435,0.7829738138814436,-0.8584553488351587
319.0000000000038,37.759436277474194,0.7399644579842667,-0.8799926504867579
320.0000000000038,37.85721927021497,0.6921177806660772,-0.9042608720890879
321.00000000000387,37.95294231886819,0.6383682247224809,-0.9272218597088173
322.00000000000387,38.04971319606573,0.5817682808544401,-0.9524097023644984
323.00000000000387,38.142634217407895,0.5221640438616011,-0.9735805287985295
324.00000000000387,38.24058235834828,0.460553667060835,-0.9974118360193094
325.00000000000387,38.336821623756336,0.40483828765041613,-1.018519908745179
326.0000000000039,38.43336120466312,0.34671705997275704,-1.0399543094646475
327.0000000000039,38.52871868681596,0.2945173965424507,-1.0617098193289278
328.0000000000039,38.62431090503977,0.24740667681431877,-1.0830958714452166
329.000000000004,38.719801660121654,0.2059204241149158,-1.102283081237017
330.000000000004,38.81567835226625,0.16814092797042768,-1.1217982890323164
331.000000000004,38.910889853239645,0.13597386358776253,-1.1393091566958495
332.000000000004,39.00785678848756,0.11209301308455005,-1.1578095920562088
333.000000000004,39.1027661962182,0.08867907333870345,-1.1749649945583522
334.00000000000404,39.19746477039806,0.07316223234575187,-1.193149230313205
335.00000000000404,39.2955483807809,0.058491589966997326,-1.2089672742514055
336.00000000000404,39.39190820712487,0.05206827933066677,-1.22385873340041
337.0000000000041,39.48755657208779,0.04523314426640851,-1.2388112211310438
338.0000000000041,39.58344587279485,0.040072217422255973,-1.251299231110842
339.0000000000041,39.680559288809846,0.03627650598640009,-1.2627781332156696
340.0000000000041,39.77605109490602,0.034588833177390865,-1.2767792274176655
341.0000000000041,39.868206858436736,0.03515751687910046,-1.289387274304668
342.00000000000415,39.967831636684274,0.037623003037287495,-1.3037335189158843
343.00000000000415,40.06322042160941,0.03973526702939034,-1.3171334370555305
344.00000000000415,40.16165906678786,0.04316229477855721,-1.3274702660034516
345.0000000000042,40.258227434537886,0.045374632516384295,-1.3371020704976844
346.0000000000042,40.355033278232824,0.048959818559873136,-1.347752482581837
347.0000000000042,40.451188764883824,0.05268885666439199,-1.3581603355598642
348.0000000000042,40.547685566843995,0.05652094701469146,-1.3669988194786638
349.0000000000042,40.644122860273086,0.06203928814690712,-1.3764735465856526
350.00000000000426,40.740600527617616,0.06340947445806472,-1.3850941584175716
351.00000000000426,40.8376994312214,0.07005182776368657,-1.3943121904632347
352.00000000000426,40.93438845976083,0.07439214439413061,-1.404662284525263
353.0000000000043,41.031397889097704,0.07886042952987543,-1.413461842332973
354.0000000000043,41.12857606257945,0.08466569157576942,-1.4219026885518518
355.0000000000043,41.224632694157194,0.0883932042701725,-1.4303648453601734
356.0000000000043,41.3204157070595,0.08909851377768346,-1.4369958926258968
357.0000000000043,41.4189126320377,0.09230703513753463,-1.4471258876812003
358.0000000000044,41.51493814592857,0.09738508507894422,-1.4575442679401083
359.0000000000044,41.612068075353974,0.10136925423945486,-1.4660269373825714
360.0000000000044,41.70866959110033,0.10430921097383206,-1.4730646652422403
361.00000000000443,41.80476779802313,0.10566997663030309,-1.481386193605239
362.00000000000443,41.90273489292295,0.10881208116261665,-1.4896459995791544
363.00000000000443,41.99952399568835,0.11163695238829491,-1.4982843326829869
364.00000000000443,42.09629040044833,0.11188848017395431,-1.506431640519486
365.00000000000443,42.19094147783096,0.11457289623866879,-1.5143380443625305
366.0000000000045,42.28958026392197,0.11676927241509177,-1.5227655817559476
367.0000000000045,42.38695393745184,0.11707716966692716,-1.5318830424999126
368.0000000000045,42.483320637650486,0.11954507937609599,-1.5397616211417375
369.00000000000455,42.58029828811089,0.12221492157885872,-1.5467751014148323
370.00000000000455,42.67728864191876,0.12387029203772038,-1.5547209977986602
371.00000000000455,42.774367510437806,0.12535498238763543,-1.5627978166427754
372.00000000000455,42.872231679821354,0.1260406998220166,-1.5715380059401625
373.00000000000455,42.969591810789495,0.12544710173783175,-1.57865966126161
374.0000000000046,43.06690340768782,0.12428888493531765,-1.5855252520616672
375.0000000000046,43.163029564190204,0.12581115654060748,-1.5948725408297992
376.0000000000046,43.260584698417695,0.12543202859904024,-1.6018000179159784
377.00000000000466,43.357528587882605,0.12439550853418102,-1.610509983079802
378.00000000000466,43.45447255443219,0.12631695719299568,-1.6179021614290603
379.00000000000466,43.551414543903014,0.1261848567492891,-1.6245530733954179
380.00000000000466,43.64912923242074,0.1250649406578162,-1.6317337695294039
381.00000000000466,43.745492938668825,0.12493209833407032,-1.6411667499130842
382.0000000000047,43.84311368865986,0.1245057558177704,-1.648785675848973
383.0000000000047,43.94107192995666,0.12330309220688457,-1.6570804713607794
384.0000000000047,44.037537266498305,0.12665886867823295,-1.665437536152941
385.0000000000048,44.13292727651873,0.12392678769053278,-1.6759728315812055
386.0000000000048,44.23062316409476,0.12564230131327564,-1.682313220213394
387.0000000000048,44.329179308722345,0.12652888329565976,-1.690642496603803
388.0000000000048,44.42606192116869,0.12571228823832076,-1.6985392394466992
389.0000000000048,44.52320655106103,0.12847798882983646,-1.7062076191184152
390.00000000000483,44.6207164680568,0.12656601772857073,-1.7123889785544568
391.00000000000483,44.71781281654924,0.12742230604108867,-1.718735820319771
392.00000000000483,44.814767572907805,0.13092383501938654,-1.726986002437544
393.0000000000049,44.91242643432659,0.1316804645231645,-1.7348777633333272
394.0000000000049,45.009820577967446,0.13234938517206968,-1.7432568102312405
395.0000000000049,45.10707866552943,0.13474048495885144,-1.7521123088533859
396.0000000000049,45.20412374750555,0.13638916820226438,-1.7583491286897868
397.0000000000049,45.30079882285335,0.137497057603779,-1.76507805301366
398.00000000000495,45.39833281616672,0.14201605843666854,-1.7747410903904561
399.00000000000495,45.49618495834524,0.14324297752835374,-1.7814320865132136
400.00000000000495,45.593535579413285,0.14734303266791204,-1.79052004939206
401.000000000005,45.69171660127737,0.14796741091685128,-1.7984996289071753
402.000000000005,45.78908344920217,0.15019725731561634,-1.8055750828801371
403.000000000005,45.886778025596726,0.15246442178689162,-1.8124126587103455
404.000000000005,45.98356762792723,0.15260641870157537,-1.8195065860898798
405.000000000005,46.08147223134126,0.152992173771126,-1.8269156219483769
406.00000000000506,46.179127855337036,0.15585615925693452,-1.8338289466917796
407.00000000000506,46.27582466106323,0.15524181427468586,-1.8384888555633374
408.00000000000506,46.373593345701295,0.1549280299005204,-1.8471141115651593
409.0000000000051,46.47176590676441,0.1569560551953026,-1.8540014595414918
410.0000000000051,46.56883626315337,0.15915977625314115,-1.8628946004650455
411.0000000000051,46.666461662222005,0.16019985327478148,-1.8701301526497662
412.0000000000051,46.764346276501435,0.16061408875864824,-1.8779817467588868
413.0000000000051,46.861342223460895,0.16047871769484034,-1.8840701392237582
414.0000000000052,46.95918889715892,0.16340559903282298,-1.8888882675843446
415.0000000000052,47.056926669813066,0.16322367055768422,-1.8962534287838042
416.0000000000052,47.15242245852427,0.16496367101368886,-1.9008498165738894
417.00000000000523,47.25204135750154,0.16626297636107074,-1.9098291230021722
418.00000000000523,47.3497347197627,0.16865335730193892,-1.9181301875183143
419.00000000000523,47.446658267340005,0.1682086888911668,-1.9233336588771386
420.00000000000523,47.54469761412276,0.16663341238247753,-1.930452979566561
421.00000000000523,47.64117334078346,0.16841559388161015,-1.9356037575299507
422.0000000000053,47.73980687416467,0.16762245368539913,-1.9442570759153197
423.0000000000053,47.8377548318804,0.16894168007056132,-1.9523657088723847
424.0000000000053,47.934961524570156,0.17027957327044585,-1.9594261025670496
425.00000000000534,48.033440696580016,0.17096567188767725,-1.9655781839293915
426.00000000000534,48.12845818394655,0.1735394301971706,-1.9733443637856012
427.00000000000534,48.22851179303811,0.17301380721344745,-1.9790449108839847
428.00000000000534,48.32613399772808,0.1754532768701217,-1.9858891109033303
429.00000000000534,48.42451669307733,0.17825001201200313,-1.9927035209326225
430.0000000000054,48.522310360539834,0.17755152487666648,-1.998013523308769
431.0000000000054,48.620000000000516,0.17863004007950306,-2.001900081197378
432.0000000000054,48.71636051034333,0.1803717880278304,-2.0091733455710985
433.00000000000546,48.81693145802105,0.18069809785116542,-2.0147381678223937
434.00000000000546,48.913574680949715,0.18298875961411082,-2.0201289442142523
435.00000000000546,49.01124638373229,0.18559523211735704,-2.0280900227103746
436.00000000000546,49.10989906873586,0.1870968926186568,-2.0312925974816487
437.00000000000546,49.20801610384597,0.1891115172239073,-2.038556957290063
438.0000000000055,49.30578987964514,0.19101516570425048,-2.0430407910230963
439.0000000000055,49.40372850561098,0.19051190246583563,-2.048609311923686
440.0000000000055,49.50115271616828,0.19401489481163217,-2.0554999467047717
441.00000000000557,49.598946538825935,0.19639696356654832,-2.0620784695976755
442.00000000000557,49.69682001573934,0.1977502794606023,-2.068430751597056
443.00000000000557,49.794845307902186,0.19882940942466543,-2.0786766736137925
444.00000000000557,49.89272683703927,0.20025849206085947,-2.083852149392432
445.00000000000557,49.99106923182415,0.20220939842131336,-2.0858656213882805
446.0000000000056,50.08930731947075,0.20372058553972808,-2.093303584090341
447.0000000000056,50.18600379862494,0.2050313301067888,-2.1012263535888027
448.0000000000056,50.28490566119048,0.20709694621837416,-2.1081943903608322
449.0000000000057,50.38286365854946,0.20791008214815163,-2.114669861702254
450.0000000000057,50.48114284845031,0.20845425023631226,-2.1198251534768806
451.0000000000057,50.57875683649167,0.21065163126892886,-2.125316498531191
452.0000000000057,50.676798867463056,0.20983889338937448,-2.1312253154981846
453.0000000000057,50.77530435114875,0.20727166905998679,-2.1375747124925706
454.00000000000574,50.873365086435776,0.21092868652684293,-2.142292206464841
455.00000000000574,50.97090727441129,0.21082263535292436,-2.1529591543329953
456.00000000000574,51.070191913356666,0.21189838723075502,-2.158580698017389
457.0000000000058,51.16809258983673,0.20962554245642379,-2.1607617829499075
458.0000000000058,51.266108510257524,0.2104423925894948,-2.1658976585710064
459.0000000000058,51.36441798316943,0.21119381211003194,-2.176473149358637
460.0000000000058,51.46247880213158,0.20936442850930256,-2.1820306519501353
461.0000000000058,51.56090722641647,0.20997675266862745,-2.1897268049189305
462.00000000000585,51.65951251670151,0.2097085299186069,-2.1973826408324166
463.00000000000585,51.7579164848421,0.21044340249046042,-2.2040110669616686
464.00000000000585,51.85635912124899,0.2125827742858881,-2.211726963474355
465.0000000000059,51.954578867393806,0.20898506906096856,-2.21781424665143
466.0000000000059,52.052614874458996,0.20978266803165702,-2.2245825930593375
467.0000000000059,52.15157640152296,0.21151423222869595,-2.2300515318071614
468.0000000000059,52.249016933839854,0.21231146151475683,-2.236679461134746
469.0000000000059,52.347657085968706,0.211632457945015,-2.242801588049888
470.00000000000597,52.44559967653907,0.21078758248263935,-2.250753978294645
471.00000000000597,52.54398278259723,0.21104574495654968,-2.256729090675704
472.00000000000597,52.64256018484956,0.2096078148498142,-2.2628568310674044
473.000000000006,52.74169423025166,0.20953970940896507,-2.267849441147514
474.000000000006,52.83917788614645,0.20946427155268263,-2.2756582936692977
475.000000000006,52.9373684262421,0.20921838152666908,-2.28584176197539
476.000000000006,53.03573806374239,0.20706391767436078,-2.291016012834197
477.000000000006,53.134109928519614,0.20739969333699124,-2.2938518947109547
478.0000000000061,53.232660842916964,0.2072514392622186,-2.2999219420060486
479.0000000000061,53.3301898674682,0.20374676132762234,-2.3065588357526545
480.0000000000061,53.42897814491482,0.20534654451753642,-2.313828566900522
481.00000000000614,53.527322489845375,0.20469633400045018,-2.3200204967020728
482.00000000000614,53.625789470094304,0.20382475648929577,-2.326060860313742
483.00000000000614,53.72393831600344,0.19996020664213773,-2.3321537217512898
484.00000000000614,53.82197399120977,0.20007353706728542,-2.336677899285477
485.00000000000614,53.92100196105765,0.20114428667359313,-2.3441544735133526
486.0000000000062,54.018494929073114,0.20190247229495448,-2.3501804276568263
487.0000000000062,54.11768388677068,0.20191482497940977,-2.355647336749519
488.0000000000062,54.216183458655955,0.20003240759587507,-2.361953116675807
489.00000000000625,54.31458621498362,0.20080471207188794,-2.3680588445020536
490.00000000000625,54.411130683465544,0.20050811104059435,-2.3703439138238074
491.00000000000625,54.51141113854806,0.19882743895801888,-2.37282809394886
492.00000000000625,54.6099036594843,0.19854377765631698,-2.379528662076532
493.00000000000625,54.70950895821751,0.19936296513258647,-2.3863368801472165
494.0000000000063,54.80769319575338,0.1983838919255923,-2.3926688191816456
495.0000000000063,54.90731125738783,0.19723963171864795,-2.3983374363257584
496.0000000000063,55.005064484527885,0.19826276535036644,-2.4032235590921758
497.00000000000637,55.10457295577266,0.19625074401475925,-2.4068927181989377
498.00000000000637,55.20387571977955,0.19596433907119726,-2.4093976498003684
499.00000000000637,55.30203255260545,0.19769972041831088,-2.4126232825073854
500.00000000000637,55.40059279052961,0.19742737806361255,-2.4185158983311865
501.00000000000637,55.4994236819479,0.19684906866142893,-2.4227005609161356
502.0000000000064,55.59806401829311,0.19613331273627355,-2.427590709281504
503.0000000000064,55.69783909299374,0.19587523159871753,-2.432219759192937
504.0000000000064,55.79626499085847,0.19664024547675016,-2.4368044912190707
505.0000000000065,55.89564251729255,0.19628872449373483,-2.4385844439859845
506.0000000000065,55.994596408406096,0.19703633951871147,-2.4426538650697465
507.0000000000065,56.09091011212881,0.19750082750894923,-2.4462304149958363
508.0000000000065,56.19113333127378,0.19831877943220885,-2.450560495947063
509.0000000000065,56.290516927875075,0.19501840656131544,-2.454012760284033
510.00000000000654,56.38886736600553,0.19544987709789394,-2.4597570476758346
511.00000000000654,56.48873764793261,0.19200503850451942,-2.4619939482553184
512.0000000000066,56.58708979834434,0.1935933089563468,-2.4657915605044947
513.0000000000066,56.68676734831135,0.1947189170212138,-2.468752221877299
514.0000000000066,56.78538148756259,0.1943801669227865,-2.47287284742282
515.0000000000066,56.88435843584276,0.19237786759735306,-2.4766196129494378
516.0000000000066,56.98300536300049,0.19198438789498312,-2.478015384677831
517.0000000000066,57.08237492277319,0.19305019536968987,-2.481468248877837
518.0000000000066,57.18227073853255,0.18942660964662902,-2.4829833896163462
519.0000000000066,57.281095711260434,0.19142129830590493,-2.4856097246081728
520.0000000000066,57.37937677600345,0.1909206198132541,-2.489100281848357
521.0000000000067,57.478505509770834,0.19100422151602123,-2.4933030330768355
522.0000000000067,57.57724844542121,0.19069537608888876,-2.4973501797030844
523.0000000000067,57.67585344847944,0.1886311226549039,-2.501046013661622
524.0000000000067,57.776016081282236,0.18700995755534464,-2.5029728806016927
525.0000000000067,57.874541996831105,0.187300143981245,-2.504268948100007
526.0000000000068,57.97460415723288,0.18514750405947364,-2.510591081147612
527.0000000000068,58.0734642839502,0.18377640051018546,-2.5123815420000053
528.0000000000068,58.17196593064249,0.18473758466569004,-2.515332026251249
529.0000000000068,58.27199314848527,0.18172422113699077,-2.5170783412533893
530.0000000000068,58.37053205407955,0.18139390626355878,-2.5198912819550947
531.0000000000068,58.46990273622025,0.18161916789039248,-2.5236914673230944
532.0000000000068,58.570195951177865,0.18233138340357874,-2.526768982727329
533.0000000000068,58.66857317378957,0.18175114282757932,-2.5304415452109836
534.0000000000068,58.767293571226276,0.18135035436778524,-2.5319220370646613
535.0000000000068,58.86551756999049,0.17895182908822888,-2.5350055240257383
536.0000000000068,58.966497430750564,0.18007326085457742,-2.5363500557265213
537.0000000000069,59.06501502939634,0.1781789091252904,-2.540957975242256
538.0000000000069,59.16444575284119,0.1767298293096852,-2.545138699031133
539.0000000000069,59.263647263161445,0.1767347069813343,-2.5478672906304682
540.0000000000069,59.36170592129375,0.17642697473285118,-2.5491402752743455
541.0000000000069,59.461171494824406,0.17401664527745223,-2.5526849012059074
542.000000000007,59.560693879400944,0.17269322818504224,-2.5560705745670522
543.000000000007,59.65961018548019,0.17553073489056337,-2.559589273428921
544.000000000007,59.75921664604808,0.17499794588913872,-2.56150251168848
545.000000000007,59.85835119070352,0.1721415898124648,-2.5650004420016232
546.000000000007,59.956858933501394,0.17209761650192917,-2.566843133041354
547.000000000007,60.05653504825009,0.1720152399877724,-2.569932265551355
548.000000000007,60.155882056042174,0.16888652103785948,-2.5739964614529907
549.000000000007,60.25435224148499,0.16951872781388164,-2.577841750426336
550.000000000007,60.35447262289496,0.16879015542608972,-2.5795796691183988
551.000000000007,60.453284925031134,0.16651328009652275,-2.5831276180889606
552.000000000007,60.55226154741646,0.1636915815272942,-2.5854352831792315
553.0000000000072,60.65121206948439,0.163258410095066,-2.587700735620669
554.0000000000072,60.75183582736348,0.1618793345760201,-2.5909750371598808
555.0000000000072,60.850675004017894,0.16122799466390328,-2.593483453061513
556.0000000000072,60.94851356629765,0.16130061487415243,-2.5966096683891893
557.0000000000072,61.04949582664265,0.1596909206004892,-2.60065795949843
558.0000000000073,61.14815818577528,0.15608387454070588,-2.6019395005015564
559.0000000000073,61.248016637879346,0.15361278213639246,-2.6073225297552045
560.0000000000073,61.346834555459246,0.15122672723036618,-2.608883846185572
561.0000000000073,61.44755006482632,0.15066607952538652,-2.6121891950742926
562.0000000000073,61.54587934227827,0.14919867548141752,-2.6158194099847054
563.0000000000073,61.644960272433735,0.14555929948957128,-2.618468416401411
564.0000000000073,61.74376959564141,0.14544734170600496,-2.6224693559359817
565.0000000000073,61.84403603994006,0.14364260929787112,-2.6254293120407324
566.0000000000073,61.94305845096254,0.14101469462651905,-2.626912143289836
567.0000000000073,62.04262892045588,0.14018288364235187,-2.6297051576644543
568.0000000000074,62.14131666384988,0.1387983614013148,-2.634721799109715
569.0000000000074,62.24010442351582,0.13967321399211566,-2.636060015471858
570.0000000000074,62.339414274177464,0.13905745575250447,-2.6373624465808403
571.0000000000074,62.4399126043647,0.13600100616323013,-2.6388532868548977
572.0000000000074,62.539064640559424,0.13715864542182007,-2.640142555686026
573.0000000000074,62.63780392048831,0.13788833236549122,-2.6445838597665903
574.0000000000074,62.73494439371556,0.1354456001779992,-2.647669144085259
575.0000000000075,62.83685922449145,0.13562183952462042,-2.6481999792185453
576.0000000000075,62.93644680084986,0.131418166608109,-2.6511273883679647
577.0000000000075,63.03583636626121,0.133031403313675,-2.657497697020117
578.0000000000075,63.135488385976636,0.1289641040975548,-2.657681610983332
579.0000000000075,63.23428220691829,0.13090686728799025,-2.65935010524088
580.0000000000075,63.33366219976816,0.12847349621442566,-2.662126770969904
581.0000000000075,63.4333893880784,0.12427429541282564,-2.6666627437955777
582.0000000000075,63.532950045247645,0.12527007014127506,-2.6698945045518028
583.0000000000075,63.632223985858715,0.12536314999328474,-2.6726158206707766
584.0000000000076,63.73230020362741,0.12359567792008569,-2.674988625507072
585.0000000000076,63.83093013492945,0.11981171228129028,-2.6742241004558363
586.0000000000076,63.93000000000069,0.1209809335252785,-2.676520185613493
587.0000000000076,64.0300000000007,0.11957402770285866,-2.6779612151104937
588.0000000000076,64.1302069811798,0.11815722341947357,-2.680156815877816
589.0000000000076,64.22990163688861,0.11607596119109048,-2.68211353046824
590.0000000000076,64.32942685699777,0.11727406866995999,-2.684751336127831
591.0000000000077,64.42878027387816,0.11723150910245814,-2.6875018625592793
592.0000000000077,64.52881117499697,0.11405640562459096,-2.68784485368831
593.0000000000077,64.62808977796516,0.11253617679812122,-2.691726918497541
594.0000000000077,64.72739420170613,0.11202448299206055,-2.6945192575901578
595.0000000000077,64.82754718997016,0.11443436128434636,-2.6961695697327936
596.0000000000077,64.92687542323623,0.11308542372778632,-2.697553494298213
597.0000000000077,65.0256233912558,0.10965163590561489,-2.6974195098704543
598.0000000000077,65.12513097455607,0.10905379094816925,-2.7001478935486194
599.0000000000077,65.22452456593494,0.10683764192095357,-2.701678992645188
600.0000000000078,65.32316806003399,0.10701804632041406,-2.704070463565861
601.0000000000078,65.4228560214277,0.10565354363945326,-2.7054195414212527
602.0000000000078,65.5219939238622,0.10554429970925094,-2.706021166827888
603.0000000000078,65.62249748539725,0.10490428582327121,-2.707591314239585
604.0000000000078,65.7213146895144,0.10438172191918935,-2.7083653406916173
605.0000000000078,65.82173321151767,0.10312170130313561,-2.71189585417761
606.0000000000078,65.9206788177708,0.10164554775861476,-2.7136804937299175
607.000000000008,66.02030849623385,0.09738422488771711,-2.7133018301008
608.000000000008,66.11958997741343,0.09578845951222911,-2.714620150471065
609.000000000008,66.21936327532168,0.09558436197862497,-2.7173576267798185
610.000000000008,66.3199024281587,0.09331015641686738,-2.7176822611487825
611.000000000008,66.41912697160632,0.09002650386206651,-2.721299818382779
612.000000000008,66.51819903039333,0.08851514242403222,-2.7199969276877827
613.000000000008,66.6179221156811,0.08643752951371023,-2.719973260625184
614.000000000008,66.7175829491379,0.08713922357737358,-2.7236022706293683
615.000000000008,66.81717703873136,0.08342550791718378,-2.7239479208875634
616.0000000000081,66.9157451324513,0.08130779316702136,-2.726129524504609
617.0000000000081,67.01608786315431,0.08145141116956997,-2.7274591810515036
618.0000000000081,67.11578941003049,0.07804552295764614,-2.7290351033210265
619.0000000000081,67.21697036081298,0.07769361217720172,-2.728769311143515
620.0000000000081,67.3152506050133,0.07636192436753714,-2.730907059352721
621.0000000000081,67.41569687452352,0.07565180539968491,-2.732044678374154
622.0000000000081,67.51575590105568,0.07607135513017393,-2.731966467125892
623.0000000000082,67.61533659936254,0.0743378870130938,-2.7333898412952866
624.0000000000082,67.71422299868883,0.07342916049063697,-2.7346991592260395
625.0000000000082,67.81506596879719,0.07345605593236079,-2.734677077924977
626.0000000000082,67.91446396314007,0.07250575702566106,-2.736014816257091
627.0000000000082,68.01454932915016,0.07531055681304183,-2.7386433134837453
628.0000000000082,68.11474806959487,0.0727951326255949,-2.7399036874044116
629.0000000000082,68.21487565147252,0.07214419330457017,-2.7386338786040803
630.0000000000082,68.31364895590997,0.07216012328433635,-2.7412991393657555
631.0000000000082,68.41245517212856,0.07119859354243316,-2.7426000850806913
632.0000000000083,68.51468706802738,0.06923903723153663,-2.7414970666844605
633.0000000000083,68.61279631779408,0.0669137962379841,-2.7411799448198932
634.0000000000083,68.71351660039197,0.0681596181353177,-2.7425009144797885
635.0000000000083,68.81343241955867,0.06634889491695484,-2.743820698892858
636.0000000000083,68.91333378784378,0.06416920533538131,-2.7451403765330626
637.0000000000083,69.01319539615076,0.06263312281365646,-2.7451351664586277
638.0000000000083,69.11215331249849,0.061086919132326056,-2.74717730118082
639.0000000000084,69.21252372192309,0.060521282055235326,-2.7464500235303975
640.0000000000084,69.3106692767584,0.05964041460618921,-2.7474406950366244
641.0000000000084,69.41076352546708,0.058682583125244187,-2.748759015233414
642.0000000000084,69.51046829226527,0.05804285312371035,-2.749118837453554
643.0000000000084,69.60958876211473,0.05642030619935712,-2.7490952514490132
644.0000000000084,69.70626385845588,0.05304974677278318,-2.7504018901808616
645.0000000000084,69.80733907011093,0.04856104048408344,-2.751685234550432
646.0000000000084,69.90826981913744,0.04761956382145063,-2.75006982309111