File: 01_Data/Polyisocyanurate_Foam_Board/STA/N2/10K_min/Polyisocyanurate_Foam_Board_STA_N2_10KData_221018_R1.csv
##Temp./Â°C,Time/min,DSC/(mW/mg),Mass loss/mg
51.0,10.701895228330441,0.022208160506582697,0.016853836651715248
52.100000000000016,11.1043038275499,0.05765840738576844,0.014793122329376907
53.20000000000003,11.357349497866512,0.08096406900391018,0.01926397991790285
54.30000000000005,11.568495872453147,0.09873587397765715,0.015853523142395076
55.40000000000006,11.752640444845136,0.111557736186364,0.017598343596744392
56.50000000000008,11.924115198820285,0.12569788740230203,0.015710635674778928
57.600000000000094,12.089076795610806,0.1345902158481329,0.01533566880677828
58.70000000000011,12.245333735932354,0.14242596951500652,0.016313796555260218
59.800000000000125,12.396042048508617,0.14772027527953013,0.017368899411213334
60.90000000000014,12.541643033426338,0.15455848013606355,0.017377909975609285
62.000000000000156,12.684483004112614,0.16069377307429344,0.016540267997168456
63.10000000000017,12.824235555004279,0.16645321614909436,0.01576692585487649
64.20000000000019,12.960293798055817,0.17171780842393214,0.017170846703394638
65.30000000000021,13.096150814586291,0.17497590953877107,0.017326838544051704
66.40000000000022,13.230108665959513,0.1778329472043898,0.0169108684277548
67.50000000000023,13.360310850361767,0.18344746380726118,0.01691019899178059
68.60000000000025,13.491409438052191,0.18743958361306245,0.015393436680998462
69.70000000000027,13.620289560049521,0.1886306526305508,0.016919245008972794
70.80000000000028,13.745521309958509,0.19327612788278836,0.017042760141843694
71.90000000000029,13.872436030467105,0.1979301040857233,0.016878048956033176
73.00000000000031,13.997080754766912,0.19895123681108173,0.016741713204332598
74.10000000000034,14.120119596828099,0.19985352847009596,0.016909924504814988
75.20000000000034,14.24378015925864,0.20396594907392207,0.018116569485568057
76.30000000000035,14.366284453153819,0.20640935177448405,0.015522294370158285
77.40000000000038,14.485893490310856,0.2083500774735667,0.018238440744558382
78.5000000000004,14.605478570030945,0.20962371894520582,0.01791472180949505
79.6000000000004,14.724692183501576,0.21143320133734478,0.017140454319473974
80.70000000000041,14.842960584732865,0.21373574983012,0.01692207942194468
81.80000000000044,14.96102971849502,0.21302423848544239,0.018237617192468747
82.90000000000046,15.077578714803812,0.2168663053451766,0.017249145281990508
84.00000000000047,15.194030452267793,0.21396985306065297,0.018426565773302706
85.10000000000048,15.307496239445813,0.21516985596082971,0.018198497503345124
86.2000000000005,15.423549532900678,0.2150175026422393,0.01648423694836687
87.30000000000052,15.539503194544208,0.2164739628986858,0.01823670769989505
88.40000000000053,15.653229345179389,0.21763578984219567,0.01817901124154009
89.50000000000054,15.767353068154382,0.21839231211367238,0.017938685447600022
90.60000000000056,15.880000000000049,0.21953336594259543,0.013183396956387483
91.70000000000059,15.992297529251418,0.2221845230199213,0.015498776873981157
92.8000000000006,16.104575705083708,0.22265783645286563,0.018212601910964743
93.9000000000006,16.217221573234095,0.22391252812227125,0.018119833024795362
95.00000000000063,16.32771241697823,0.22336976766830052,0.019547615833481302
96.10000000000065,16.43773316252103,0.22184675719757063,0.021624085369498225
97.20000000000066,16.548079824623823,0.22426384142582645,0.0225921237832738
98.30000000000067,16.65931180934863,0.2264464007657846,0.02130293482525847
99.40000000000069,16.767509103833177,0.22641954996192926,0.020984835974109828
100.50000000000071,16.877474954566072,0.23013990967027342,0.018767183367358165
101.60000000000072,16.98658854648563,0.23016213788969853,0.017759458769088354
102.70000000000073,17.09634168889011,0.23196074491701668,0.020430041251783493
103.80000000000075,17.203986941715584,0.23312489115870827,0.01857740282211484
104.90000000000077,17.312567441814345,0.23323073043748332,0.018155865995308496
106.00000000000078,17.42126651138086,0.23416743695078357,0.01944002121031918
107.10000000000079,17.529829931506676,0.23568055211103323,0.020617846210827295
108.20000000000081,17.636724469542347,0.23583630351431917,0.0190873925100572
109.30000000000084,17.74715087449543,0.2377863552281232,0.01811958895077037
110.40000000000084,17.855738483855454,0.23909159818413872,0.016226329298739905
111.50000000000085,17.963307688188515,0.24139513034654236,0.019652446229786236
112.60000000000088,18.07162802267793,0.24319113226530775,0.021031437671137354
113.7000000000009,18.177461600715628,0.2449164861397023,0.018839776522736607
114.8000000000009,18.285520083464036,0.24588928685458544,0.018263386288530192
115.90000000000092,18.392461331099266,0.24821828688068448,0.019653899462579894
117.00000000000094,18.500709131842616,0.24944182182586805,0.018339935725989243
118.10000000000096,18.607156554339443,0.25058226779690196,0.02007777625178786
119.20000000000097,18.715177664702995,0.2515013342179677,0.019276154155890346
120.30000000000098,18.821228827999896,0.2531411992113839,0.020310039846384242
121.400000000001,18.92935175043381,0.25488405564518724,0.02158863717100079
122.50000000000102,19.034894664608707,0.2551727023832374,0.020321232288764257
123.60000000000103,19.14309791394708,0.256865607746513,0.020262761466855572
124.70000000000104,19.249476081029965,0.25730060825706846,0.01897951306047574
125.80000000000106,19.35574832942915,0.25799120531425535,0.019944632911599314
126.90000000000109,19.462802618070395,0.25901363111742604,0.01900000519076528
128.00000000000108,19.568823354004792,0.26097654853945706,0.018494051455011373
129.1000000000011,19.67620289239503,0.2645272762346633,0.01893749908139064
130.20000000000113,19.782120475240852,0.2641922511890782,0.01767990339414638
131.30000000000115,19.887493656892353,0.26428815957018437,0.017679251549257202
132.40000000000117,19.99398645556387,0.2647158189214023,0.017487993274977853
133.50000000000117,20.10090710306397,0.2658065763201718,0.016370157291396126
134.6000000000012,20.2060658827068,0.2652820054714693,0.014890721696525944
135.7000000000012,20.31331303692979,0.2684501060123705,0.017223542721971796
136.8000000000012,20.41843941043662,0.2677071543706879,0.01724011885888377
137.90000000000123,20.523766429138167,0.2688115514188394,0.01817030176804213
139.00000000000125,20.629900762704935,0.27022274665282087,0.01719446311038375
140.10000000000127,20.73424485218017,0.2726894442879826,0.018180808720165587
141.2000000000013,20.83952000409539,0.2710276467980528,0.017009754206898542
142.3000000000013,20.944388938884558,0.2734750638783078,0.015700174004116718
143.4000000000013,21.050791428693163,0.2738555889401352,0.016687065913534305
144.50000000000134,21.156426046334836,0.2759499711424027,0.01635863621077327
145.60000000000133,21.259743169707185,0.27709619198290103,0.015709976657140245
146.70000000000135,21.365667487572804,0.27663844102763524,0.01439034658926186
147.80000000000138,21.470748090054887,0.27637122034606176,0.014721695158499415
148.9000000000014,21.572013588699264,0.2748901762156267,0.016040433882921867
150.00000000000142,21.680409630333568,0.2755966791966026,0.014720003642636037
151.10000000000142,21.783332681672782,0.2774067299547679,0.015582788396461211
152.20000000000144,21.888566213743935,0.2759582530149971,0.013400008869314028
153.30000000000146,21.99296914746532,0.27709628676667675,0.013399954999910868
154.40000000000146,22.097666903877375,0.27880742855729956,0.013399956909765365
155.50000000000148,22.202734001133646,0.2788932698459772,0.012095596220920157
156.6000000000015,22.307501333559483,0.27917766410002365,0.012119490374269404
157.70000000000152,22.411734900881985,0.2805911478368388,0.013391706815370163
158.80000000000155,22.514212411690742,0.28060955609372407,0.010153769230989873
159.90000000000154,22.621191454750907,0.2833151458186991,0.013294106280528517
161.00000000000156,22.725080009266428,0.2835272490905839,0.013280449410457251
162.1000000000016,22.8297903676327,0.286248677512997,0.010659619400541942
163.20000000000158,22.93111407134843,0.2876593102052395,0.009340935009459095
164.3000000000016,23.03818109966253,0.2890255157751127,0.00803030827990181
165.40000000000163,23.142906712706203,0.291710862574475,0.00538808967227844
166.50000000000165,23.2467780895772,0.2913278861825609,0.005394274321889547
167.60000000000167,23.35177830821248,0.2958418252859235,0.004423882100894616
168.70000000000167,23.455956569432182,0.2971661358729578,0.0030801692760986654
169.8000000000017,23.561587652160693,0.2998613379993049,0.003079531997819629
170.9000000000017,23.665603518087025,0.3013541328487932,-3.109313880766962e-05
172.0000000000017,23.769305960991627,0.3049493984628985,-0.0012001259909775186
173.10000000000173,23.874673288990607,0.30475525587440766,-0.0011976027777427234
174.20000000000175,23.977706532949917,0.3088085532706307,-0.0025098635915759004
175.30000000000177,24.082285619801837,0.31122538067709515,-0.00349871318629269
176.4000000000018,24.187134240026126,0.3135844465965504,-0.005150920815279569
177.5000000000018,24.29191920186919,0.31547444689250104,-0.006479477779906873
178.6000000000018,24.396419990318254,0.31887208915719467,-0.009470639941442371
179.70000000000184,24.500821455684857,0.32172717568473963,-0.012141713462074932
180.80000000000183,24.605491301114736,0.32373271261456993,-0.012731167590136039
181.90000000000185,24.71009331931416,0.3265570621554289,-0.014050293764505284
183.00000000000188,24.813996580769416,0.3299044684235698,-0.017744949015535916
184.1000000000019,24.917888082537484,0.3298026684668851,-0.020833573767776947
185.20000000000192,25.02205590317929,0.33204587010090936,-0.022288718305071953
186.30000000000192,25.127062849305474,0.3351141663511745,-0.025325447698645753
187.40000000000194,25.230388245835172,0.3380376743990144,-0.02755005273907507
188.50000000000196,25.335811476458787,0.34265364923149333,-0.03019006703148097
189.60000000000196,25.437792212019886,0.34611896264021647,-0.03198926213416975
190.70000000000198,25.543986207539945,0.34648329135994643,-0.0336406760291581
191.800000000002,25.648352716512772,0.3495285060536755,-0.03818626198835329
192.90000000000202,25.751650179035888,0.34977755856026344,-0.038695535203734366
194.00000000000205,25.85624195857391,0.35453207461661324,-0.04040348390344928
195.10000000000204,25.960191930456656,0.3563405733240306,-0.04314975466757165
196.20000000000206,26.063686711361086,0.35789934941199225,-0.04666790752968453
197.3000000000021,26.169153464627886,0.36189505457291593,-0.04989310354956
198.40000000000208,26.27257307272098,0.3649575721759512,-0.05185306457774885
199.5000000000021,26.377915445362103,0.3689434303939385,-0.05522775797923929
200.60000000000213,26.482209930196003,0.37317130918011887,-0.0595623591262906
201.70000000000215,26.585541910921318,0.37302824286040653,-0.06526134392267746
202.80000000000217,26.69019426203924,0.37524803750832947,-0.06761317496036234
203.90000000000217,26.795120675626436,0.37941237516703175,-0.07164331689486492
205.0000000000022,26.8996095302345,0.37850575596200103,-0.07672966579401441
206.1000000000022,27.003136211608677,0.38138456069742704,-0.0756635491510429
207.2000000000022,27.10573877103433,0.38196248523592635,-0.07811564436611196
208.30000000000223,27.209712287042418,0.3847026576671436,-0.08209911109903789
209.40000000000225,27.31473181514909,0.3880676078271097,-0.08637492316505035
210.50000000000227,27.4192037498928,0.3884723700130677,-0.09078100458101401
211.6000000000023,27.52397278421446,0.3890796676790379,-0.09341320169487988
212.7000000000023,27.62850911770889,0.39211753980603614,-0.09702881357192705
213.8000000000023,27.731842460089958,0.39239799984010304,-0.10240375289244419
214.90000000000234,27.836762868495505,0.39578631422451394,-0.10734748460641752
216.00000000000233,27.941073780057298,0.39825569183958226,-0.11064536036055861
217.10000000000235,28.045782013923116,0.40023894954681927,-0.11558225335961314
218.20000000000238,28.150284337577638,0.4021256398464919,-0.12000139282055367
219.3000000000024,28.25396009510473,0.4032682863697266,-0.12337461740988775
220.40000000000242,28.35842091106621,0.4045242888254324,-0.12618452987344186
221.50000000000242,28.462801602034446,0.40540793734422736,-0.13043934141068414
222.60000000000244,28.56759834856648,0.40899211356338444,-0.13451154118903075
223.70000000000246,28.670148966442945,0.40971385526038573,-0.13392566487804913
224.80000000000246,28.77611097207464,0.4116197737701561,-0.13796902690627988
225.90000000000248,28.880112568631034,0.41254751058021755,-0.14468509810017238
227.0000000000025,28.98387041542399,0.41806635829923616,-0.15007003498402893
228.10000000000252,29.08918365880497,0.4208521093665556,-0.15278390470991576
229.20000000000255,29.19403258537705,0.4218546688579119,-0.15844427217367274
230.30000000000254,29.29875689351573,0.4236262308401019,-0.16261516899829953
231.40000000000256,29.402785751532456,0.42453846739015605,-0.16532564750382495
232.5000000000026,29.50729954903637,0.4259476474107548,-0.1682385670105071
233.60000000000258,29.61097655010753,0.4265147006469234,-0.171001827390882
234.7000000000026,29.716640940863673,0.42833867774700374,-0.17489127148553552
235.80000000000263,29.821197465520957,0.4310349417977051,-0.1790822042444562
236.90000000000265,29.9245581887925,0.43329990294658355,-0.18222819036429216
238.00000000000267,30.030000000000236,0.4354385778268988,-0.18442982500000138
239.10000000000267,30.134387418771215,0.43693408310794163,-0.18726427785205368
240.2000000000027,30.23841615715031,0.43931672083132434,-0.19138391128778665
241.3000000000027,30.343027320303968,0.4432385029459008,-0.19572026082694682
242.4000000000027,30.448341711355468,0.4440029578658409,-0.19706611089646664
243.50000000000273,30.55154929993474,0.44681931155173493,-0.20017499433898944
244.60000000000275,30.65783753100341,0.4484411800111552,-0.20346789421851508
245.70000000000277,30.761731831416622,0.4524018488201941,-0.20410691707111406
246.8000000000028,30.86668995810734,0.45471806310215074,-0.2090206042054925
247.9000000000028,30.97123341124211,0.4558610719479597,-0.21165136236218407
249.0000000000028,31.07564128980997,0.4575254175660289,-0.21352762745046228
250.10000000000284,31.180733310670675,0.4589354096489711,-0.21665972132256117
251.20000000000283,31.286094718910945,0.4636745339005286,-0.2210069258028513
252.30000000000285,31.39106238066106,0.46689271158684065,-0.22233644165713118
253.40000000000288,31.49526283255985,0.4692740440904115,-0.22676453071803682
254.5000000000029,31.600193571723636,0.4722765545383091,-0.22879633318363446
255.60000000000292,31.70471881090967,0.47803631587848133,-0.23145129234826234
256.7000000000029,31.80999902098251,0.48015199046639057,-0.23448990628382216
257.8000000000029,31.914041818404396,0.485031839889704,-0.23844281400787892
258.90000000000293,32.019712019160664,0.48677015814037294,-0.24249046465015756
260.00000000000296,32.12452294474971,0.4939248612878139,-0.24518381551632773
261.100000000003,32.22850661570175,0.4951149090233128,-0.248296705784532
262.200000000003,32.33354730215614,0.5022241952051019,-0.2505639873749983
263.300000000003,32.43884368585967,0.5056416866168549,-0.25588291882274383
264.40000000000305,32.54392044203653,0.512362114589746,-0.2585397357422665
265.50000000000307,32.647967498112656,0.5169813108801733,-0.2597554595113145
266.6000000000031,32.753715386865295,0.522796217281455,-0.2625868498984838
267.7000000000031,32.858538898677736,0.5287487263877525,-0.26851937663005065
268.8000000000031,32.96415206517906,0.5342770572807387,-0.27270203101550194
269.9000000000031,33.069018774270155,0.5422644860828109,-0.2783603056273187
271.0000000000031,33.17345461004743,0.5499947060013158,-0.2836650885025671
272.10000000000315,33.280101499018336,0.5550837088515609,-0.28500076064780533
273.2000000000032,33.384441558441985,0.5639854991759046,-0.2898330981008388
274.30000000000314,33.4893544658393,0.5724961200776206,-0.3005253563247843
275.40000000000316,33.594393880798044,0.5837610863808559,-0.3055022641324934
276.5000000000032,33.69854772595755,0.5939902732208963,-0.30937211186923586
277.6000000000032,33.80433664986587,0.6036981922879512,-0.3118121323835972
278.70000000000323,33.90908342807748,0.6129277267253002,-0.31641646461835915
279.80000000000325,34.01469957953809,0.6216622859217406,-0.32324827156060687
280.9000000000033,34.12066248602265,0.6360748164402308,-0.3300406244193357
282.0000000000033,34.22451188871643,0.6489640505231365,-0.33656592442678823
283.1000000000033,34.32865368517337,0.660018998283934,-0.34326472786571927
284.20000000000334,34.43512945165947,0.6717317234042091,-0.35009811013381986
285.30000000000337,34.540777745747576,0.6891570060113598,-0.3565362161051673
286.40000000000333,34.64606217354513,0.7003781088707337,-0.36509979485574684
287.50000000000335,34.75156755994814,0.7159074849128332,-0.3741096601511762
288.6000000000034,34.856466737517835,0.7322435608592918,-0.38351502478358057
289.7000000000034,34.96322589554081,0.7470489116759214,-0.3928937983081431
290.8000000000034,35.06689000355297,0.7666554581305037,-0.4018953805206009
291.9000000000034,35.17229202980286,0.7814577029001782,-0.4116893262410781
293.0000000000034,35.27818031585328,0.7952825955244316,-0.41772495531355025
294.10000000000343,35.38406371259934,0.8127701259578224,-0.43017879421186933
295.20000000000346,35.48949638750301,0.8331155699211936,-0.442819460949587
296.3000000000035,35.59463477561086,0.849733003657097,-0.4550401510307003
297.4000000000035,35.697756046608234,0.8665248249081984,-0.4693137852990059
298.5000000000035,35.80553206749782,0.8825617040912936,-0.48241477255350995
299.60000000000355,35.91051582194937,0.9009966370466054,-0.49928600335501816
300.70000000000357,36.01655075618171,0.9149663046573844,-0.5145827272388388
301.8000000000036,36.12240002061618,0.9296023870913711,-0.5294177544728793
302.9000000000036,36.22883875660974,0.944651863894126,-0.5414846878138824
304.0000000000036,36.33367428876683,0.9599448496899059,-0.555036520742243
305.1000000000036,36.43674589180341,0.969753758289965,-0.5723693851284977
306.2000000000036,36.54561259065932,0.9819383644095283,-0.5898610037522385
307.30000000000365,36.65109318312099,0.989546089052708,-0.6067199739526181
308.4000000000037,36.7569797482848,0.9981594274720818,-0.6225785748553645
309.5000000000037,36.86281258459525,1.0045583267107838,-0.6430322031624423
310.60000000000366,36.96782129790497,1.0075747145147762,-0.6632240053371965
311.7000000000037,37.07368342841397,1.0098929995013166,-0.6839940304771099
312.8000000000037,37.180000915381655,1.0083198336311816,-0.7055702725110629
313.90000000000373,37.28502994396961,1.005031764761768,-0.726288808144337
315.00000000000375,37.38883030198588,0.9927743037873745,-0.7491747522909291
316.1000000000038,37.49774194082015,0.9734909405939937,-0.774487131403343
317.2000000000038,37.60280881806641,0.9471478955364395,-0.799789013139371
318.3000000000038,37.70777992609665,0.9143351182297079,-0.8273628308258432
319.40000000000384,37.81324264729345,0.8728396726717539,-0.8514093742247582
320.5000000000038,37.920196879027834,0.819759876613371,-0.8782902877686287
321.60000000000383,38.025088148210685,0.7629403458279945,-0.9019262043414682
322.70000000000385,38.129999114428834,0.6987894811002958,-0.9300675117232342
323.8000000000039,38.234998019295105,0.6315372215448496,-0.9551608110713019
324.9000000000039,38.3407043209109,0.5609659473988686,-0.9834933225968987
326.0000000000039,38.44586548630956,0.4937083824345837,-1.0087427200446188
327.10000000000394,38.55165798263142,0.4259388759821161,-1.0354471846287323
328.2000000000039,38.656574403957535,0.36484066771662893,-1.0580123215076576
329.30000000000393,38.76110091986394,0.3122878749610828,-1.0811016850177322
330.40000000000396,38.86666965281141,0.2656366352158045,-1.1030124064229598
331.500000000004,38.97303532745978,0.22690752559695526,-1.1262808535788897
332.600000000004,39.07760556319652,0.19342831093100205,-1.145809210435548
333.700000000004,39.183202571227525,0.16751980605526828,-1.167368302251878
334.80000000000405,39.28929873488984,0.14512850582868975,-1.1863103743354682
335.90000000000407,39.394878591593915,0.13255552095660994,-1.2027874007573005
337.0000000000041,39.49855016595753,0.12097335753167249,-1.2185421978900322
338.10000000000406,39.60527064434407,0.11632182970187344,-1.2363567088735303
339.2000000000041,39.709770813172014,0.110516604479595,-1.2530517964576973
340.3000000000041,39.81638560158543,0.10741201914366971,-1.269475293670057
341.4000000000041,39.924403057342644,0.10613077240899238,-1.2847516066460694
342.50000000000415,40.02979851089445,0.10753571448305066,-1.297488744294108
343.6000000000042,40.134566377556546,0.10953559868623497,-1.3110125595824136
344.7000000000042,40.2414454183702,0.11364852030230854,-1.3221957607319457
345.80000000000416,40.348768423877864,0.11492562778247473,-1.3326726371718514
346.9000000000042,40.45445357899842,0.12149822787812037,-1.3442988636337079
348.0000000000042,40.56047686871522,0.12431698661441537,-1.3521228069818751
349.10000000000423,40.665963140543944,0.12901291518566615,-1.3663704838710569
350.20000000000425,40.77311374344061,0.1328651512793093,-1.3761461295200461
351.3000000000043,40.879216857804096,0.1382124182880905,-1.3882330822341626
352.4000000000043,40.98483954894963,0.14387568468256473,-1.4000408267196
353.5000000000043,41.091790644257095,0.1480381305780044,-1.4082528654003408
354.60000000000434,41.1973620093563,0.15264174034689915,-1.416948854822008
355.7000000000043,41.30454250292417,0.157784255784081,-1.4290457340055611
356.80000000000433,41.41090336975162,0.16210340916792315,-1.4381317933794415
357.90000000000435,41.51764084680917,0.16739989567148372,-1.446036708581564
359.0000000000044,41.624452798398885,0.17191153165667478,-1.455720583018337
360.1000000000044,41.730336679256084,0.17581505943670134,-1.4660714655403577
361.2000000000044,41.836583537633466,0.17924782012930562,-1.475529596748303
362.30000000000445,41.9439460649163,0.18335799340301595,-1.4858312987356737
363.4000000000044,42.05019348101802,0.1852704790410114,-1.500630768423791
364.50000000000443,42.15737150685042,0.1886259872662276,-1.5023536859119835
365.60000000000446,42.2640697964267,0.19091482177475178,-1.5116104629056584
366.7000000000045,42.37056143360735,0.1929625872997704,-1.5229609344880641
367.8000000000045,42.47775889371217,0.19445921101732988,-1.5379494502703395
368.9000000000045,42.58428796869453,0.19615317928332,-1.545090664857811
370.00000000000455,42.687164537791446,0.19757334814353655,-1.5492743831438371
371.10000000000457,42.79714258795819,0.19842208387015492,-1.558581893338661
372.2000000000046,42.90392219908761,0.1999797519010133,-1.5667285194930622
373.30000000000456,43.0114152575267,0.20117615778368347,-1.5769529370810003
374.4000000000046,43.118143416411186,0.20104739804849303,-1.586539681954282
375.5000000000046,43.2241226105015,0.20214954698193527,-1.593806309581188
376.6000000000046,43.331498362161014,0.20177934967865657,-1.6052016372166134
377.70000000000465,43.437888961749636,0.1984873997578092,-1.6122360965978881
378.8000000000047,43.54500258868194,0.20023035101495013,-1.621323770449703
379.9000000000047,43.652380784063794,0.19919521777053856,-1.6306704850792881
381.00000000000466,43.75861818752239,0.20026649138361657,-1.6391800475068825
382.1000000000047,43.865384665002075,0.19900190378348492,-1.6455931822769796
383.2000000000047,43.97229683529592,0.19899730945915545,-1.658574333989029
384.30000000000473,44.08018737498333,0.19915887004720934,-1.6670701258039657
385.40000000000475,44.186154495267616,0.2010318329615559,-1.676849211754166
386.5000000000048,44.29145433688829,0.20128011218906505,-1.683314399397692
387.6000000000048,44.40027195544512,0.20256560606901897,-1.6911222759626088
388.7000000000048,44.50746985980288,0.2030017874412492,-1.6988148533464331
389.80000000000484,44.614122121025005,0.20597711384165002,-1.7109556468820752
390.9000000000048,44.72139110586543,0.2075704381834107,-1.721889808947612
392.00000000000483,44.82898039890172,0.211668539971183,-1.7290622683996864
393.10000000000485,44.93594885513377,0.2145386131031629,-1.7339298070524394
394.2000000000049,45.04249569321953,0.2139246492877866,-1.7449966576214502
395.3000000000049,45.150578725139,0.21672269231489827,-1.7556141615548375
396.4000000000049,45.25751661945918,0.22156483202203392,-1.7642874572458198
397.50000000000495,45.36482959049419,0.22250960840312017,-1.7700657853464907
398.6000000000049,45.471799635575195,0.22457584066479103,-1.7790127966444627
399.70000000000493,45.57891240874454,0.22576872268210618,-1.786138821591127
400.80000000000496,45.68707656912256,0.22943083816039944,-1.7952876939581865
401.900000000005,45.793100266935944,0.23145062696674296,-1.8020860222158244
403.000000000005,45.90117366691582,0.23207019968754455,-1.8116187459511228
404.100000000005,46.00819802581873,0.23525069534849524,-1.8222787997863672
405.20000000000505,46.115310057715455,0.2382232997608456,-1.8296723996623134
406.30000000000507,46.223243252364924,0.23872642131321875,-1.8354782595496104
407.4000000000051,46.33058926982418,0.2393242951492171,-1.8436182029713049
408.50000000000506,46.43896404496103,0.24044965270259633,-1.8525218137273027
409.6000000000051,46.54535072213614,0.24157851391425877,-1.8602550104465
410.7000000000051,46.65195065324806,0.24258105619347115,-1.868309975858499
411.8000000000051,46.75979383789287,0.24427699256160107,-1.8755234180265532
412.90000000000515,46.86725851329556,0.24458385407810823,-1.8840518533137653
414.0000000000052,46.97314976293624,0.24605017060292816,-1.893185947427099
415.1000000000052,47.078915323161965,0.2479912982716203,-1.9012968961018926
416.20000000000516,47.189897865890394,0.2490674851502026,-1.909767352197402
417.3000000000052,47.29724396906186,0.25159923137776435,-1.9179269123147713
418.4000000000052,47.40440579893251,0.2508842369757437,-1.9235748509807205
419.50000000000523,47.51305983558137,0.25372717425877417,-1.9307187789861655
420.60000000000525,47.61959495589269,0.25448659553666075,-1.9395990724443122
421.7000000000053,47.72684441132333,0.25470351319238665,-1.9477617423482387
422.8000000000053,47.835140659503686,0.25525507968150685,-1.9562365391210843
423.9000000000053,47.942919470235,0.25842409366823116,-1.9644452555920258
425.00000000000534,48.050499061981334,0.259353022710262,-1.9715312243640888
426.1000000000053,48.15844578161104,0.25914609089974394,-1.979262872411879
427.20000000000533,48.26559835199878,0.2621154247531641,-1.9868988369747376
428.30000000000535,48.37416285896608,0.2651104974505855,-1.9963205649365432
429.4000000000054,48.48148581961491,0.2660737047449774,-2.0033634145338186
430.5000000000054,48.58862188655049,0.2687831676820586,-2.009307602754073
431.6000000000054,48.69399571159559,0.26718443718130336,-2.019262773472534
432.70000000000545,48.80452962565295,0.2707583461681382,-2.0248844161837116
433.8000000000054,48.91238476453645,0.27214426458677216,-2.03253049117184
434.90000000000543,49.01786710559092,0.2755831272911824,-2.039035057196917
436.00000000000546,49.127351581038006,0.27544543106887737,-2.0456952825122467
437.1000000000055,49.235351405863454,0.27735127314823427,-2.054186225357137
438.2000000000055,49.34406977639401,0.28153471147119513,-2.0600184012221225
439.3000000000055,49.45106911207928,0.28405130806619117,-2.0667760471092134
440.40000000000555,49.559644362163525,0.28806410749555705,-2.0738956161725715
441.50000000000557,49.666697434105856,0.2885039356590973,-2.080674886768197
442.6000000000056,49.773586378726506,0.2899973498477507,-2.087329694057408
443.70000000000556,49.88250636698229,0.2918480884688095,-2.09627370854922
444.8000000000056,49.99062821586556,0.2935868331548676,-2.1032003545538362
445.9000000000056,50.098575328704484,0.2947374700394635,-2.108504300740313
447.0000000000056,50.2063644107538,0.29750571354291644,-2.116366086407342
448.10000000000565,50.31430251145606,0.2977328481748886,-2.1246801128276416
449.2000000000057,50.422153569513945,0.2975428883730466,-2.1323387991205855
450.3000000000057,50.52961348313153,0.30035562520125564,-2.139863475874825
451.40000000000566,50.638765549733385,0.30020224831509057,-2.146972705697666
452.5000000000057,50.74633004646962,0.3004667325336743,-2.154611162359575
453.6000000000057,50.85486335568723,0.2982282976290209,-2.162491245959675
454.70000000000573,50.96331566995662,0.30128692304521504,-2.170825421118299
455.80000000000575,51.070816310141225,0.30202693276197995,-2.1777982144018777
456.9000000000058,51.17840459583877,0.2999140884402011,-2.1847284182255646
458.0000000000058,51.286508838258364,0.2994337291347522,-2.1920022283953533
459.1000000000058,51.394565074804895,0.30234137735652006,-2.2001776238156956
460.20000000000584,51.50254835833907,0.3014760533355253,-2.2084605940701567
461.3000000000058,51.610763829198625,0.29914753504278396,-2.2159018921168765
462.40000000000583,51.718341777400255,0.3005350631819856,-2.2231656969673548
463.50000000000585,51.82537899471821,0.29833492889949287,-2.230565801397303
464.6000000000059,51.934515751962984,0.296910919614215,-2.2392863364719178
465.7000000000059,52.04192537222894,0.29945304447693355,-2.246870704308476
466.8000000000059,52.15063231561378,0.29889184481330483,-2.253435657736956
467.90000000000595,52.25912103115029,0.29550608430693226,-2.261910404985872
469.0000000000059,52.36606835325094,0.2956013825920413,-2.2697514746644267
470.10000000000593,52.47385948092893,0.2942612929500675,-2.2760892770117187
471.20000000000596,52.58170378028094,0.2934511082162226,-2.283206770641371
472.300000000006,52.69009840076841,0.2935799028997439,-2.2916099105624967
473.400000000006,52.79820166964159,0.29318283406043993,-2.299117323816613
474.500000000006,52.90657257365149,0.29079658043103107,-2.306604644433188
475.60000000000605,53.015136693014625,0.29083861203687844,-2.3147880376389924
476.70000000000607,53.1223211479435,0.28750137960809946,-2.3218630242946725
477.8000000000061,53.230694084795765,0.284925151444077,-2.3281959212280023
478.90000000000606,53.33911434210269,0.28423283155173007,-2.3347984200630454
480.0000000000061,53.447020805596274,0.2833558110407293,-2.34198741192876
481.1000000000061,53.555847271189094,0.28492498249257797,-2.347770470314444
482.2000000000061,53.66470484147731,0.2824972572125249,-2.3552695396242953
483.30000000000615,53.77296614026348,0.2844433984070796,-2.363139344034492
484.4000000000062,53.881661045267265,0.28384064824235555,-2.3694351278553007
485.5000000000062,53.99024397310536,0.2825646758078784,-2.376916848005887
486.60000000000616,54.09908791690005,0.2821324995605015,-2.3831950836139013
487.7000000000062,54.20665677011524,0.28147993109252173,-2.387672805508407
488.8000000000062,54.315350059595836,0.2828326319846813,-2.394315063297692
489.90000000000623,54.4238882124637,0.280770651723106,-2.3992594719641724
491.00000000000625,54.5316639381763,0.2815809204986647,-2.404404053325697
492.1000000000063,54.64215102401823,0.2806107347519309,-2.4119361181252374
493.2000000000063,54.74989822727563,0.27909135034939736,-2.416200876266306
494.3000000000063,54.85783110214727,0.28083726525833064,-2.4219047389761608
495.40000000000634,54.966737111635574,0.28174011925883913,-2.424974094429287
496.5000000000063,55.07481989002572,0.28042302709280337,-2.430642764183503
497.60000000000633,55.184180255272814,0.28084255970457356,-2.439126914351008
498.70000000000636,55.29220748076786,0.28318675078751915,-2.4448128593080414
499.8000000000064,55.400942436212155,0.2824832537101046,-2.447582980631311
500.9000000000064,55.508862070176356,0.2800749698006202,-2.4524661835018664
502.0000000000064,55.617371317834944,0.2803651527561202,-2.4572250235586024
503.10000000000645,55.725834241625975,0.28063750058568726,-2.463218804661987
504.2000000000064,55.83554173540146,0.28194452596165964,-2.465864241449718
505.30000000000643,55.94325055914887,0.2812736045823406,-2.4703307212123655
506.40000000000646,56.05205710749383,0.280726410593227,-2.474839481588609
507.5000000000065,56.16000000000068,0.28420399539989977,-2.483172347390668
508.6000000000065,56.268950063522865,0.28478877563604726,-2.4850991322339366
509.7000000000065,56.37669294856534,0.28568046999533686,-2.4875287443733067
510.80000000000655,56.485116730929576,0.2853890790023878,-2.493170871497349
511.90000000000657,56.59477155821263,0.2855985419339002,-2.493744015949571
513.0000000000066,56.70243318506871,0.28398851784727264,-2.497532819764133
514.1000000000065,56.81089771285038,0.2841230978794776,-2.5052921675281565
515.2000000000066,56.92105601311018,0.2852765279499079,-2.504201069957261
516.3000000000065,57.029590908046586,0.285630517948048,-2.5075093923641987
517.4000000000067,57.13882467204227,0.2859283106500845,-2.511291061256289
518.5000000000066,57.245433152857544,0.28715462460407815,-2.5156499273334103
519.6000000000067,57.35610866085288,0.2874645488006476,-2.520697109836511
520.7000000000066,57.464795645483925,0.2880542905397179,-2.5199750716323646
521.8000000000067,57.573509125406126,0.284083697403117,-2.5229853520783303
522.9000000000067,57.6824351169598,0.2867117723426983,-2.5282742554963322
524.0000000000067,57.791438127507874,0.28659966906479734,-2.532643735206068
525.1000000000067,57.90048297744581,0.2859280326356929,-2.534931519017411
526.2000000000068,58.00932784584454,0.286645996389508,-2.539272689273382
527.3000000000068,58.11883693311761,0.2886659237512295,-2.542920650144028
528.4000000000068,58.22786632603906,0.28787088326754073,-2.545379777801655
529.5000000000068,58.3365774630467,0.2895456388217049,-2.549874696741192
530.6000000000068,58.44594728040278,0.2885854912525143,-2.5538785271685542
531.7000000000069,58.55377256173546,0.28719916380795973,-2.557894327470584
532.8000000000068,58.6630048821646,0.28637041019430876,-2.5610635616975097
533.9000000000069,58.77215143252446,0.2867856049254436,-2.5635134243577897
535.0000000000068,58.87860990373295,0.28775174523717834,-2.5655018165075294
536.100000000007,58.989464472340515,0.2848764614833394,-2.5690854251102917
537.2000000000069,59.09821353909769,0.2834839664780149,-2.5729147400586356
538.300000000007,59.20812607911169,0.2854295062354952,-2.5765323299533076
539.4000000000069,59.31675990643299,0.28602040693091146,-2.5783305044359155
540.5000000000069,59.426003744397384,0.2861147677446311,-2.5823800213854318
541.600000000007,59.53482232862351,0.28895792107238794,-2.5838490137696692
542.700000000007,59.64400370493655,0.290456778738879,-2.587448572294279
543.800000000007,59.75325399437855,0.2886153645361047,-2.594786007823056
544.900000000007,59.861430800833055,0.2884209889672943,-2.597865220022746
546.000000000007,59.97110427734424,0.2894053258917355,-2.600182167460038
547.1000000000071,60.080632191317676,0.28863311888339926,-2.603713323558067
548.2000000000071,60.18933025386127,0.28484804444549094,-2.607626232485247
549.300000000007,60.300001038143776,0.287358654395114,-2.6105199968659627
550.4000000000071,60.40812346482596,0.2850643377000058,-2.612392174367627
551.500000000007,60.51758664026442,0.2860373827667268,-2.6150230635714147
552.6000000000072,60.626747176841405,0.2851185811875325,-2.6186759864451403
553.7000000000071,60.735737454310154,0.2848517399453761,-2.620074214932643
554.8000000000072,60.84506427815849,0.2839877278709736,-2.6231591744711054
555.9000000000071,60.95420425878432,0.28401190392059683,-2.632234093809862
557.0000000000072,61.063214079320666,0.2830594187235681,-2.628967413267783
558.1000000000072,61.17212342966116,0.28374731370969763,-2.632487254899434
559.2000000000072,61.28172418602555,0.28244685454565155,-2.635521609844263
560.3000000000072,61.389475292950436,0.28285443942834876,-2.639607750522919
561.4000000000073,61.49694732769883,0.28296426414767084,-2.6409905995539606
562.5000000000073,61.60978795161763,0.28273083199101523,-2.6464135592915827
563.6000000000073,61.7186290712487,0.2820024603913468,-2.6490170238294652
564.7000000000073,61.8281371231262,0.281329785097528,-2.653320765606664
565.8000000000073,61.9374967226658,0.28174967661621186,-2.655278217676312
566.9000000000074,62.04658664299029,0.27871292941912307,-2.657305197177073
568.0000000000074,62.156203193621025,0.2772624480912886,-2.6599107212042647
569.1000000000074,62.26582467075357,0.2801833570244792,-2.661478374676247
570.2000000000073,62.375207328723256,0.27862272125225496,-2.6671216320949647
571.3000000000073,62.484885971443774,0.2774089018651257,-2.6684697624189084
572.4000000000074,62.59481656405325,0.2788999044460538,-2.672580020930704
573.5000000000074,62.703935121010126,0.27861040339841053,-2.6755284820075658
574.6000000000074,62.81279233949987,0.27765962225514595,-2.6780592800429672
575.7000000000074,62.922097382755446,0.2779101607808007,-2.6794809346149466
576.8000000000075,63.03189351411886,0.2791341629496251,-2.68221223569306
577.9000000000075,63.141820950605656,0.27761019870653547,-2.6863079669268535
579.0000000000075,63.251641297466314,0.27831786137205583,-2.686613676232394
580.1000000000075,63.361156267012994,0.2784322685454219,-2.690521315639907
581.2000000000075,63.47067001101346,0.27963197264119494,-2.69522598335742
582.3000000000076,63.5803169131367,0.28296372488462374,-2.696005343748223
583.4000000000076,63.69109254063304,0.2803780295793935,-2.6988211018109727
584.5000000000076,63.798448299794636,0.28129776008792434,-2.70154010960274
585.6000000000076,63.90843614088352,0.281546260715537,-2.7052691382983265
586.7000000000077,64.0189486066059,0.28448281716258034,-2.7080489517675073
587.8000000000077,64.12789812534959,0.2836950867725426,-2.7107579619646893
588.9000000000076,64.2377035131451,0.2842985560792765,-2.712054814537149
590.0000000000076,64.34766117390839,0.28361395868280626,-2.7135790875259738
591.1000000000076,64.45805068928625,0.2846089838839682,-2.7148105012205406
592.2000000000077,64.56668324300027,0.2854703592247914,-2.7174759249481015
593.3000000000077,64.67672850768255,0.28448573974443125,-2.7200541056229675
594.4000000000077,64.78635090607457,0.2862850083278215,-2.7221453915563214
595.5000000000077,64.89434968056783,0.28526319568652325,-2.725648178684108
596.6000000000078,65.00568069482374,0.2855950807740229,-2.72808828399549
597.7000000000078,65.11596687123082,0.2875218003332024,-2.7279530317493608
598.8000000000078,65.22499055056483,0.2862871296663032,-2.7294132337318184
599.9000000000078,65.3348521219825,0.2890976141845555,-2.732065783649695
601.0000000000078,65.44451675570394,0.28828830099785485,-2.7334613583706373
602.1000000000079,65.55428908811555,0.2896229274610098,-2.7371019394030327
603.2000000000079,65.66418462135313,0.2865088880850233,-2.738329463953511
604.3000000000079,65.77219484366182,0.29010092471528104,-2.739641297771702
605.4000000000078,65.88245670527776,0.2885117637643164,-2.7409506164459336
606.5000000000078,65.99316375141197,0.28685862863932243,-2.7422919083289607
607.6000000000079,66.10199276836272,0.28809192666177663,-2.744903596495357
608.7000000000079,66.21232694097135,0.287876374642031,-2.7463888748448024
609.8000000000079,66.32121888288532,0.29001527310655595,-2.7489639804014114
610.9000000000079,66.43104299265548,0.286648047226645,-2.749056094531255
612.000000000008,66.54132576002239,0.2842413174559144,-2.748836328598165
613.100000000008,66.65187984969003,0.28586844067659667,-2.7501381740117843
614.200000000008,66.76128131647458,0.2833612355000505,-2.752242267715226
615.300000000008,66.86865946302554,0.28061967971060675,-2.7533436561784215
616.400000000008,66.97916240732866,0.280991880110917,-2.7554324943133714
617.5000000000081,67.08944097131834,0.2803233763301066,-2.7554397167143114
618.6000000000081,67.19989724486355,0.27680061581726983,-2.757741461730287
619.7000000000081,67.30944001828317,0.2802358563238818,-2.7580806435293614
620.8000000000081,67.41885355535767,0.28026486363681946,-2.760633550860726
621.9000000000082,67.52842324653017,0.27937368529822526,-2.7619748299669524
623.0000000000082,67.63859577120103,0.28159884104739946,-2.7607110061696662
624.1000000000081,67.74906798285821,0.2840898322304948,-2.762021610447186
625.2000000000081,67.8585335568921,0.28207532343740765,-2.7633394705275522
626.3000000000081,67.96808814481992,0.2822256670771135,-2.7633399070428406
627.4000000000082,68.07786345018965,0.28156370564301536,-2.7646559580702896
628.5000000000082,68.18809958303396,0.2840040811079523,-2.7659450582175547
629.6000000000082,68.29827082769583,0.28499290174538416,-2.767290807562536
630.7000000000082,68.40611280437282,0.28576624216070035,-2.7672825831555605
631.8000000000083,68.5167238794994,0.2861388283149601,-2.7686098713720795
632.9000000000083,68.62567647295872,0.2867328577176148,-2.7699679811305185
634.0000000000083,68.73632482687889,0.288052032529688,-2.770419860308216
635.1000000000083,68.8468004246498,0.2895246915248392,-2.7705898117959045
636.2000000000083,68.95582870972075,0.29253626311235736,-2.771567970750522
637.3000000000084,69.06646163096597,0.2928641713001522,-2.7725703298759345
638.4000000000084,69.17673065534815,0.29131675556723935,-2.7808595558739855
639.5000000000084,69.28606159190821,0.2949648569511158,-2.7779536664261615
640.6000000000083,69.39612647257057,0.2959356534795908,-2.7772886478758823
641.7000000000083,69.50610619172656,0.2944761200390519,-2.773988769055735
642.8000000000084,69.61657559341747,0.29611284025648266,-2.773991696361035
643.9000000000084,69.72596627509306,0.2939989943522054,-2.7767243025094297
645.0000000000084,69.83662074104284,0.2940035819202156,-2.779259830401371
646.1000000000084,69.94652872270188,0.29127779912620494,-2.7805747507644796
647.2000000000085,70.056448100802,0.2913476293449001,-2.781899007436058
648.3000000000085,70.16636297366182,0.28664786977273393,-2.7809099354913256
649.4000000000085,70.2762519059954,0.2869773707280753,-2.7821993973829313
650.5000000000085,70.38582689053982,0.28697766731574526,-2.7831969989341516
651.6000000000085,70.49579715257187,0.28417284932609405,-2.7832031268658306
652.7000000000086,70.60612224800435,0.2822825374868452,-2.7845337603206373
653.8000000000086,70.71474716075745,0.2816249941693186,-2.784178450940494
654.9000000000086,70.82683686131975,0.28217551768329663,-2.7845300574749308
656.0000000000086,70.9366560797652,0.27957532911622013,-2.787169847364345
657.1000000000087,71.046122904573,0.2807067963025709,-2.788467396193446
658.2000000000087,71.15644717287705,0.2797067237054135,-2.7884825196376593
659.3000000000086,71.26706214424713,0.27880331657461327,-2.7871835171384225
660.4000000000086,71.37640732391891,0.2776751204869897,-2.7871715170000626
661.5000000000086,71.4866532156169,0.2755825251996633,-2.788492628193482
662.6000000000087,71.59743902427385,0.2759208339693123,-2.7884535346023114
663.7000000000087,71.70701108457273,0.27438924939935555,-2.788474164399407
664.8000000000087,71.81584843329287,0.27468410836927665,-2.7899124306989798
665.9000000000087,71.92821018201427,0.2739980211242967,-2.79111992475214
667.0000000000088,72.03827943783004,0.2722596999228922,-2.79112066460109
668.1000000000088,72.14735593309655,0.2713980864240907,-2.791123371884173
669.2000000000088,72.25889758605251,0.267625953074769,-2.792431029144572
670.3000000000088,72.37000099998254,0.26760521852983654,-2.792209278833382
671.4000000000088,72.4794209380419,0.2661166902371154,-2.7924372591692297
672.5000000000089,72.58981034654943,0.26584599323609326,-2.793101162578381
673.6000000000089,72.70049775876242,0.26390885224278776,-2.794419686126708
674.7000000000089,72.81063549326251,0.2603454700722101,-2.795729690686114
675.8000000000088,72.92163031707678,0.2612337348649925,-2.7957298477822734
676.9000000000088,73.03119515003286,0.25645941106551684,-2.7970521375722965
678.0000000000089,73.14085576192151,0.25718488793398503,-2.797095359998133
679.1000000000089,73.2523695010575,0.2539108389645113,-2.798370105124471
680.2000000000089,73.3616837386669,0.2551045708058737,-2.7996818322692953
681.3000000000089,73.47296484725975,0.25267840847761214,-2.798310222442296
682.400000000009,73.58334267832969,0.2526916497765771,-2.798614639076797
683.500000000009,73.69095720998378,0.24943392674649226,-2.799019953899122
684.600000000009,73.80292370024532,0.24660125768491933,-2.799627542446214
685.700000000009,73.91327107273135,0.247914853981266,-2.8016398539370284
686.800000000009,74.02359968529593,0.24724506309889924,-2.8016502292546295
687.9000000000091,74.13204310706386,0.2458593147708807,-2.80163134025473
689.0000000000091,74.24412407451892,0.24263232877628244,-2.7979220377951535
690.1000000000091,74.35467167889809,0.24034203507911311,-2.8015741465113786
691.2000000000091,74.46386378994504,0.2382012696965332,-2.803419799511681
692.3000000000092,74.57430118837406,0.23762980916178994,-2.8047299600803717
693.4000000000092,74.6840160755407,0.2348840168001215,-2.804781547628574
694.5000000000091,74.79544993907314,0.23517352742262132,-2.8060566555950945
695.6000000000091,74.90477328678189,0.2327083397826984,-2.8063815759478503
696.7000000000091,75.01558400241593,0.22840341423055083,-2.8082483450701643
697.8000000000092,75.12642413785743,0.23194278529422674,-2.8095567391351857
698.9000000000092,75.23585306166068,0.2290207027385351,-2.811309048238713
700.0000000000092,75.34661922149981,0.22881804460363148,-2.8113514726153204
701.1000000000092,75.45746826744481,0.22527066729302425,-2.8113733121151645
702.2000000000093,75.56823444283948,0.2244451061474994,-2.811320049541886
703.3000000000093,75.67784337684417,0.2215359576015653,-2.8116395291628606
704.4000000000093,75.78886122061611,0.22032010274199088,-2.8139423931060934
705.5000000000093,75.8986951289656,0.21881323065352548,-2.8139507507234365
706.6000000000093,76.00820760011966,0.21855919357180964,-2.8139510949868907
707.7000000000094,76.11940062918659,0.2159611311509661,-2.8152804137216525
708.8000000000094,76.23009485433512,0.21088915157018784,-2.814716505127364
709.9000000000094,76.34019496307523,0.20814112932649137,-2.8162611931778523
711.0000000000093,76.4502863153028,0.20764257292326133,-2.818254322901912
712.1000000000093,76.56041216967155,0.20918612940456255,-2.817899868822426
713.2000000000094,76.67020996365665,0.20652638911523818,-2.81791074489883
714.3000000000094,76.78065881600627,0.2020330027395481,-2.817910130371417
715.4000000000094,76.89162385296466,0.2008501376833023,-2.822307860454607
716.5000000000094,77.00226349366389,0.1982394369052083,-2.826822763269405
717.6000000000095,77.11249340288016,0.19458802198071318,-2.8162154470318406
718.7000000000095,77.22329471455487,0.1947521303156552,-2.8192930246352796
719.8000000000095,77.33334443731486,0.19516279817495852,-2.8245496969104034
720.9000000000095,77.44107153720866,0.19367348384387068,-2.8226586241346063
722.0000000000095,77.55440873631488,0.19082113599839756,-2.8229501796110124
723.1000000000096,77.66509305743932,0.187959881212723,-2.8243290398889207
724.2000000000096,77.77551603168473,0.18922583184614006,-2.824270006949169
725.3000000000096,77.8856243136776,0.1860565071294017,-2.825588078373327
726.4000000000096,77.99645743067418,0.18494922605129033,-2.8249797763187847
727.5000000000097,78.10699878689475,0.18523327592366373,-2.8272288543409294
728.6000000000097,78.21647560971321,0.18172841720597982,-2.8296969734636797
729.7000000000096,78.32768908392778,0.18127983863863484,-2.82855040333276
730.8000000000096,78.43727337475708,0.18246240334493147,-2.8295483883756316
731.9000000000096,78.54835927753729,0.18105484443810638,-2.831193549478228
733.0000000000097,78.65834543721813,0.18051929046051934,-2.833161490987132
734.1000000000097,78.76980237954956,0.18399929259893094,-2.8331602909155422
735.2000000000097,78.88072455742277,0.1776433056284561,-2.833160285603762
736.3000000000097,78.99095218771433,0.1773320781753704,-2.8331764756057827
737.4000000000098,79.1019518164433,0.17418362361735235,-2.833003427659336
738.5000000000098,79.21328297109785,0.17023530620592275,-2.833510988991459
739.6000000000098,79.32427100411594,0.16956946793865846,-2.8361301506526626
740.7000000000098,79.43503544574949,0.16750168907787644,-2.8358758233974313
741.8000000000098,79.54573359120506,0.166149580022378,-2.836128134553971
742.9000000000099,79.6562471518193,0.16899638001877554,-2.8375258529652774
744.0000000000099,79.76827907248662,0.16491289107162033,-2.8382748027305427
745.1000000000099,79.87882247128938,0.1680794768015007,-2.838765718523316
746.0000000000099,79.96980140474409,0.16746556534635237,-2.840080005932927