File: 01_Data/Nylon_Carpet_Low_Pile/STA/N2/3K_min/Nylon_Carpet_Low_Pile_STA_N2_3KData_220106_R1.csv
##Temp./Â°C,Time/min,DSC/(mW/mg),Mass loss/mg
50.0,10.725672894260155,0.006887257720536666,-0.012483836815369465
51.20000000000002,11.539415630624246,0.036135032721311466,-0.012065554056052363
52.400000000000034,12.08009518641937,0.04951633843210501,-0.012922742036822754
53.60000000000005,12.557023321238237,0.05468409709458033,-0.011628470444160932
54.80000000000007,13.018025753778593,0.059026868055434,-0.01285687615062514
56.000000000000085,13.464561135508621,0.06192647338028323,-0.013167212585047494
57.2000000000001,13.89892321659394,0.0636408009706746,-0.012180457545754919
58.40000000000012,14.339524174026318,0.06592194550342423,-0.012699924199330859
59.600000000000136,14.766282169368296,0.06798033384096014,-0.011851539369157393
60.80000000000015,15.185104917064015,0.0687590209974368,-0.014149486751085405
62.00000000000017,15.59570861168775,0.07158318139436515,-0.014463125277610622
63.20000000000019,15.99490046061968,0.07244780622904201,-0.01314813431727302
64.4000000000002,16.422841134119043,0.0730402532669675,-0.013482490408088132
65.60000000000022,16.832605689002616,0.07247422588180552,-0.012499840986094135
66.80000000000024,17.240285090426703,0.07203315486458917,-0.013165800553641915
68.00000000000026,17.645905602865493,0.07489585334849969,-0.01341576563013458
69.20000000000027,18.04969720333671,0.07339781046065375,-0.014150686686958736
70.40000000000029,18.45415707102118,0.07690755374391722,-0.014152650003222966
71.6000000000003,18.863049277298593,0.07542099103107913,-0.014149722323167246
72.80000000000032,19.267259882848812,0.07638174076232118,-0.011772528104169844
74.00000000000034,19.67094087667695,0.074383523976568,-0.01488777452903367
75.20000000000036,20.08222608333392,0.07642797177436789,-0.014049909466375077
76.40000000000038,20.484793062819197,0.07723210186431362,-0.012746452027439403
77.60000000000039,20.879709267422584,0.07636778107633624,-0.013716244779014453
78.80000000000041,21.28982363115401,0.07894158094839399,-0.01502012877620551
80.00000000000043,21.68868381795641,0.07952519113392698,-0.01478743753918188
81.20000000000044,22.093515101366123,0.07815116815538892,-0.01535761751608522
82.40000000000046,22.490749679974876,0.07885874871159637,-0.015019763760260929
83.60000000000048,22.89486463718409,0.07836888672538511,-0.017660070011336515
84.8000000000005,23.297990820382342,0.07935846924117584,-0.018517055604458932
86.00000000000051,23.698669531153307,0.08305241875798297,-0.018058242678407055
87.20000000000053,24.10224799742074,0.08029349742904002,-0.018969862073061172
88.40000000000055,24.511770833114785,0.08055184274889227,-0.019303493002738925
89.60000000000056,24.914624184034466,0.07905348002402024,-0.01864999040968751
90.80000000000058,25.29621043875456,0.08092366971607112,-0.02024334253643989
92.0000000000006,25.71267317132399,0.08173536531273629,-0.01864224793795799
93.20000000000061,26.104903792701773,0.08090917152917365,-0.01854852068069146
94.40000000000063,26.502400851990455,0.08357999937164373,-0.01798955206344477
95.60000000000065,26.89963579036407,0.08098159996453225,-0.01917513110576685
96.80000000000067,27.301610657878584,0.07959928155862472,-0.018317878967295975
98.00000000000068,27.69843499815624,0.07899198930145857,-0.017324776690228916
99.2000000000007,28.098979035105252,0.07880859140295304,-0.018970484959015543
100.40000000000072,28.496653224913505,0.07787845717431596,-0.01997010453432324
101.60000000000073,28.90154749068627,0.07859684022263425,-0.019931988664825262
102.80000000000075,29.29604958767719,0.0797666987032456,-0.01869632403427257
104.00000000000077,29.692658019863615,0.07962919915651445,-0.019885773852711175
105.20000000000078,30.089986780157453,0.08153096286962591,-0.02183514368570183
106.4000000000008,30.487363285015267,0.08308454100684826,-0.020687236255913177
107.60000000000082,30.885962651330647,0.07975793734567604,-0.02069942918033263
108.80000000000084,31.28442551327727,0.07983465830850212,-0.021329035464717983
110.00000000000085,31.66913880998141,0.0825130518596987,-0.02270334506814642
111.20000000000087,32.075574383261184,0.08169913384184724,-0.021059068446143137
112.40000000000089,32.47171585943553,0.08165671431568877,-0.021594373538630585
113.6000000000009,32.86555323811214,0.08119785248618883,-0.023483393237056838
114.80000000000092,33.26333961565294,0.08076631169020132,-0.023595240899212833
116.00000000000094,33.661135132088404,0.08442830443993843,-0.02259885065799594
117.20000000000095,34.052327872312645,0.08298113717489675,-0.02348221618445212
118.40000000000097,34.45210277789928,0.08357806514346222,-0.025595317181940302
119.60000000000099,34.84433075930409,0.08379362209366747,-0.02816955894186357
120.800000000001,35.24918346115701,0.08180708614340049,-0.02588326425104892
122.00000000000102,35.64012786926602,0.07884068919715026,-0.02757269522158534
123.20000000000104,36.04294086635392,0.07815953161236111,-0.025842977653439902
124.40000000000106,36.43615110200857,0.08041764094299086,-0.027210149073481738
125.60000000000107,36.82820326881015,0.08284225985077187,-0.02721159186256461
126.80000000000109,37.22251805768178,0.08157084737629006,-0.029964398682478688
128.0000000000011,37.61757065042654,0.08280709064576552,-0.02730499398519637
129.20000000000113,38.0101273927959,0.08629963918417227,-0.028301370361956124
130.40000000000114,38.40799173068191,0.08522681719036584,-0.028299880081077866
131.60000000000116,38.79725137724191,0.0849703605032347,-0.027651391502015343
132.80000000000118,39.191939727130865,0.08329484748434679,-0.028300108957034276
134.0000000000012,39.590747774956554,0.08487384253831032,-0.027974916068997935
135.2000000000012,39.98407623638796,0.08686584368126571,-0.027306985800922057
136.40000000000123,40.37812021563022,0.08375098562177652,-0.027334790047246926
137.60000000000124,40.77061948649048,0.08688603684698537,-0.027309418217590142
138.80000000000126,41.164767133047384,0.08653628457037976,-0.02664246951274407
140.00000000000128,41.56182362951482,0.08691227061807716,-0.027649891665106452
141.2000000000013,41.95961297357989,0.08689444680977454,-0.025673167192748814
142.4000000000013,42.35378328167827,0.0886937564174427,-0.02861975150179763
143.60000000000133,42.74454829308042,0.08723240810528582,-0.02796580679179783
144.80000000000135,43.133628849890094,0.08816851585878682,-0.025649916456848665
146.00000000000136,43.52946586297883,0.08895098936971807,-0.028966865496133032
147.20000000000138,43.92061402453337,0.08881330117261749,-0.030278805796894126
148.4000000000014,44.31570732648371,0.08840174658390099,-0.029897749074939917
149.60000000000142,44.71106092231071,0.08995541239771937,-0.02961863071341231
150.80000000000143,45.104576979436374,0.09178271151778988,-0.02895223986489448
152.00000000000145,45.50305198902535,0.09020228735305896,-0.030178152911663148
153.20000000000147,45.89296640046978,0.09276313215424326,-0.030270106432093158
154.40000000000148,46.28565907105858,0.0960185078354498,-0.030272050577926812
155.6000000000015,46.6766819565662,0.09782613439367338,-0.030736180859092244
156.80000000000152,47.066670000000464,0.10352812140162931,-0.02995002659478896
158.00000000000153,47.4575827532886,0.10407077404996556,-0.031919285874943526
159.20000000000155,47.84866164073875,0.10620584164526714,-0.03060997698405643
160.40000000000157,48.24137783369087,0.10699449100798458,-0.03356969203335414
161.6000000000016,48.63447599062522,0.11135638075487542,-0.03357000000056498
162.8000000000016,49.02561356376724,0.11366706887377337,-0.032250237158494954
164.00000000000162,49.420085627873114,0.11728435725499725,-0.033563851090311125
165.20000000000164,49.81171795589481,0.12089789080323199,-0.03425866760248564
166.40000000000165,50.203314955234354,0.1235123482816256,-0.034350598500982876
167.60000000000167,50.595064576288095,0.12331751698174964,-0.03288749343548325
168.8000000000017,50.983235519097704,0.11990048389393398,-0.03160020901938321
170.0000000000017,51.379590439972105,0.11383320228820065,-0.032381402936297654
171.20000000000172,51.77493982754628,0.1068279465937404,-0.03127011466596041
172.40000000000174,52.1618425816234,0.10320845537675766,-0.03227050666380826
173.60000000000176,52.55341082842073,0.09849086035854204,-0.031247093548317117
174.80000000000177,52.94905906915776,0.09684277946653574,-0.032250276598214
176.0000000000018,53.33395073575923,0.09395395910502524,-0.03158985702606376
177.2000000000018,53.72556515064435,0.09455094555753918,-0.03266067771705394
178.40000000000182,54.11949874832752,0.09425676902852359,-0.03126571766552999
179.60000000000184,54.510299301300044,0.0969895309286703,-0.032879762861656836
180.80000000000186,54.89589074544386,0.09795244301745232,-0.03245143324611277
182.00000000000188,55.28657735433853,0.09573548138646426,-0.03143280614935495
183.2000000000019,55.67632220423136,0.09515132005222698,-0.03262974401914409
184.4000000000019,56.069612342257045,0.09474095079964406,-0.03421981221392745
185.60000000000193,56.458982171200226,0.0957672748550416,-0.03686668688666028
186.80000000000194,56.848571448937065,0.09622591043290057,-0.03686011000000455
188.00000000000196,57.2394126479249,0.09918278700644317,-0.035815111044284365
189.20000000000198,57.62665982466422,0.10073057650417755,-0.03684126298407708
190.400000000002,58.017002246311385,0.10025752200716626,-0.03752011982447723
191.600000000002,58.41136840780896,0.10186588804322716,-0.03619948509972737
192.80000000000203,58.79659706111436,0.09878364141345075,-0.037508419383388336
194.00000000000205,59.192643585311,0.09925117345076284,-0.03644567300279267
195.20000000000206,59.5823260997511,0.10223722659060347,-0.03619454937648037
196.40000000000208,59.96906271434787,0.102607084547507,-0.036200587869105405
197.6000000000021,60.364093501987924,0.10276473816804743,-0.035869997917576946
198.80000000000211,60.75490060343162,0.10411513191029265,-0.034570625341411976
200.00000000000213,61.147644949085816,0.10576168452615209,-0.03310365920967939
201.20000000000215,61.53916622892454,0.10244445960821041,-0.03521013652422056
202.40000000000217,61.936912625692955,0.1003777154321156,-0.03631010892113373
203.60000000000218,62.32368702138227,0.10265224729032502,-0.036094670745285384
204.8000000000022,62.714920992764945,0.10613842564747966,-0.04527706402050846
206.00000000000222,63.10284451817253,0.10520685900166471,-0.03586091821927262
207.20000000000223,63.48366381484805,0.10731503706807305,-0.03825288084638423
208.40000000000225,63.87070535882739,0.10807807166010902,-0.033335558920613906
209.60000000000227,64.25575661164149,0.10801849388774842,-0.032426262091004965
210.80000000000229,64.63674880045544,0.1141233844576775,-0.0400164830484675
212.0000000000023,65.0200251463408,0.11267320822437182,-0.040479731433205934
213.20000000000232,65.40811999310107,0.11448514554335598,-0.04255867230343657
214.40000000000234,65.79773252700848,0.11911480364003751,-0.04342133296931028
215.60000000000235,66.18770735261954,0.12592417156653635,-0.04235725571106652
216.80000000000237,66.58077891085469,0.1398138085750349,-0.04587500818571044
218.0000000000024,66.97176409428984,0.16893039918463149,-0.044386855711960216
219.2000000000024,67.36640062199086,0.20186108781596954,-0.04289247168623511
220.40000000000242,67.75411795492879,0.22319215925503275,-0.047279580384539166
221.60000000000244,68.15673775785102,0.22852525065171853,-0.04346219351240155
222.80000000000246,68.54333606064017,0.22626856836404027,-0.04597011984201327
224.00000000000247,68.93850320933988,0.21661043540522743,-0.04492742329309429
225.2000000000025,69.32895432682912,0.19339237027786318,-0.046073399097148915
226.4000000000025,69.72115002116449,0.1613741849852998,-0.045800316783100925
227.60000000000252,70.11075202336107,0.13702255068696892,-0.04618588016623093
228.80000000000254,70.50139816178458,0.12322453489023213,-0.04617994977675188
230.00000000000256,70.88956476006818,0.11360709058942037,-0.047159953089455975
231.20000000000258,71.27814417521778,0.11224485193815542,-0.04717610694958285
232.4000000000026,71.66606467202568,0.1066275004912291,-0.0474849574818883
233.6000000000026,72.05564386661656,0.10643370745669042,-0.046567421032945866
234.80000000000263,72.44521800169656,0.1037539896873548,-0.04824654045065824
236.00000000000264,72.83819825795105,0.10234079061621565,-0.048567352723997814
237.20000000000266,73.22414210447273,0.10170976708959056,-0.04947017892119554
238.40000000000268,73.6220196976621,0.0995525609419187,-0.05209481700995777
239.6000000000027,74.01700298927531,0.1027770884372125,-0.05244813151120287
240.8000000000027,74.40629019736492,0.10393820656014296,-0.05309021094470401
242.00000000000273,74.79614074382555,0.10134987420869729,-0.05243002034618227
243.20000000000275,75.18163930519016,0.10272598080920581,-0.05244004153190307
244.40000000000276,75.56816824821095,0.10252705234446599,-0.05242041589790425
245.60000000000278,75.96141125312795,0.10259698111082219,-0.0528643804360196
246.8000000000028,76.35259607065345,0.10506069273030683,-0.05281453931572644
248.0000000000028,76.7343342210939,0.10539127009824326,-0.05242991647834527
249.20000000000283,77.13119384442822,0.10173890315667225,-0.05243109274484059
250.40000000000285,77.52321811721764,0.10050254747753987,-0.052799971650472344
251.60000000000286,77.90960269885225,0.10251207134694926,-0.05308997580932173
252.80000000000288,78.30000000000095,0.1006189207552175,-0.05340974057881143
254.0000000000029,78.68557156836444,0.10106019244772796,-0.054409184771790464
255.20000000000292,79.07850349707321,0.10250225886145309,-0.052763253045982506
256.40000000000293,79.47013062839225,0.103885209710291,-0.05341967748086773
257.600000000003,79.85742603341187,0.10156929298172618,-0.054251531891809535
258.80000000000297,80.24670616801377,0.10138922487832044,-0.05342019724171099
260.00000000000296,80.63514098875946,0.10182346499316874,-0.05404209184196285
261.200000000003,81.02331346494596,0.10458142720036095,-0.05639153122994944
262.40000000000305,81.4113330591018,0.10261000203651852,-0.056388231326200966
263.60000000000304,81.80509310461711,0.10289957009277542,-0.05770416967116976
264.800000000003,82.1948410457572,0.10309111851778521,-0.058689211913317774
266.00000000000307,82.58374035554736,0.10146617746716524,-0.057699603812394695
267.2000000000031,82.97897526809179,0.10251114642841595,-0.058661643197896574
268.4000000000031,83.37102354881178,0.10324449004935096,-0.05835289324029702
269.6000000000031,83.75841504526738,0.10550257850394174,-0.05900991502419117
270.80000000000314,84.15428773960348,0.10431459541567334,-0.0590099142201872
272.0000000000032,84.54140135466439,0.10543823829952281,-0.058022760800245266
273.2000000000032,84.93207974350604,0.10551808666014144,-0.05938789408161904
274.40000000000316,85.31963684275422,0.10675623995174478,-0.05704016140682411
275.6000000000032,85.71034736643873,0.10441157915419962,-0.058359882591670686
276.80000000000325,86.10186773972097,0.1069163707402622,-0.06098537471127674
278.00000000000324,86.4899365981035,0.10662681271238923,-0.06229910363748958
279.20000000000323,86.87920481692984,0.10645628954919105,-0.06230920273789042
280.4000000000033,87.27245722734942,0.11168244532857229,-0.06296109788001791
281.6000000000033,87.66157529581545,0.1077249683242003,-0.06494000543345724
282.8000000000033,88.05427270253156,0.1068364949292197,-0.06693586786067529
284.0000000000033,88.44216535570663,0.10792103030007565,-0.06887992225955264
285.20000000000334,88.83574398925877,0.10674198759506352,-0.07052619201361665
286.4000000000034,89.21995830700078,0.1105819161881839,-0.07183662479919173
287.6000000000034,89.60872923654243,0.11056380273664737,-0.07346816793905298
288.80000000000337,90.00124634123091,0.110383418370612,-0.0738198649484949
290.0000000000034,90.38974035110097,0.112697102482056,-0.07382092824363173
291.20000000000346,90.78047780330323,0.11369887379196479,-0.074479940369927
292.40000000000344,91.17034827682711,0.11335932305489951,-0.07645983669029954
293.60000000000343,91.55919836460313,0.11668922874791542,-0.07746810018250594
294.8000000000035,91.95403729013347,0.11453401218958902,-0.07940068957728119
296.0000000000035,92.34506003430626,0.11709649898187921,-0.08302371043373657
297.2000000000035,92.73929375746864,0.11867564788496032,-0.08533753024271995
298.4000000000035,93.13262923224104,0.11763636567691055,-0.08830030202203076
299.60000000000355,93.52557810658224,0.1201929497297275,-0.0902791736330748
300.8000000000036,93.91737945032256,0.12314587884764215,-0.09257978648857845
302.0000000000036,94.31055365133486,0.12016764455138722,-0.09553014752005007
303.20000000000357,94.70455062914714,0.12025123242289938,-0.09948674687228642
304.4000000000036,95.10103192207869,0.1190068265293744,-0.10243978137373544
305.60000000000366,95.4901960953636,0.12290021210623153,-0.10642265321051969
306.80000000000365,95.88163294226571,0.12607910688703572,-0.11163302676914144
308.00000000000364,96.27304031602792,0.12600354449787984,-0.11679952012822037
309.2000000000037,96.66742935415128,0.12566344367556184,-0.12251861903067596
310.40000000000373,97.05945973665872,0.12849959681882,-0.1278065972155833
311.6000000000037,97.45091958551279,0.13015142531139196,-0.13357304120421798
312.8000000000037,97.84429441136304,0.1316407649849154,-0.1395384928482546
314.00000000000375,98.23392890337593,0.13617833061319798,-0.1432800228856963
315.2000000000038,98.62731115243254,0.14013633173597112,-0.1487608411927117
316.4000000000038,99.01447437122235,0.14115278755636984,-0.1567093663504986
317.6000000000038,99.40997811570595,0.14582744882194862,-0.16440880993001228
318.8000000000038,99.80238663297662,0.15210310602873117,-0.17391330604478172
320.00000000000387,100.19868535819063,0.15363575627431653,-0.183262127483522
321.20000000000385,100.59321808601486,0.15825561651791512,-0.19484073983639183
322.40000000000384,100.98293530626216,0.1618395508439439,-0.205671999822171
323.6000000000039,101.36957343477185,0.1684605727897694,-0.21737091882911663
324.80000000000393,101.76115600427438,0.17032051114730246,-0.2291934755328855
326.0000000000039,102.15078515016626,0.17794345153820698,-0.24080399407659359
327.2000000000039,102.54636859172763,0.178615239808247,-0.2538298187873207
328.40000000000396,102.94067608259589,0.18446491829142853,-0.26778150824278724
329.600000000004,103.33479384274627,0.1910360673893583,-0.282073124329413
330.800000000004,103.72575864011331,0.19453456286606396,-0.2980251037451467
332.000000000004,104.12238990484197,0.19755465089995072,-0.31591402309494665
333.200000000004,104.51308491088798,0.20044204163173535,-0.33290507377508227
334.40000000000407,104.90639727334647,0.20647612165700918,-0.35076588264938824
335.60000000000406,105.29820098613362,0.20860046711315605,-0.36769461914648227
336.80000000000405,105.69274982001431,0.20948793841770044,-0.38693668162435557
338.0000000000041,106.08503820815446,0.21405811001795555,-0.4063227247141121
339.20000000000414,106.48000668608125,0.21869600138118592,-0.42733135636742103
340.4000000000041,106.87030158984896,0.22505672403857443,-0.447550498891502
341.6000000000041,107.2643654597638,0.22678757950559303,-0.4700225377490539
342.80000000000416,107.65599695127769,0.23206649649589128,-0.4932371086029015
344.0000000000042,108.0487329918873,0.23552542776436608,-0.5123811946436367
345.2000000000042,108.44501034046105,0.2350866954881908,-0.538409352591267
346.4000000000042,108.84138067920198,0.24056965442778544,-0.562892207172828
347.60000000000423,109.23368711234957,0.24115003039891705,-0.5867783199100649
348.8000000000043,109.62836038970445,0.245842102026613,-0.61397397015303
350.00000000000426,110.02252057026055,0.24680195624479162,-0.6419006454231595
351.20000000000425,110.41451364931481,0.252489567786027,-0.6686419749483368
352.4000000000043,110.81222829504937,0.2541032830759472,-0.6983209949304521
353.60000000000434,111.2084712833768,0.26037500525084845,-0.7277793874952789
354.80000000000433,111.60000325001518,0.261004892043702,-0.7559600733924974
356.0000000000043,111.99227279084441,0.2651379606932633,-0.7857730718301252
357.20000000000437,112.38474327806006,0.2648225739254445,-0.8156992497548905
358.4000000000044,112.77756727254052,0.26663123459990024,-0.8461863066628763
359.6000000000044,113.16778638797736,0.2661771525489201,-0.8769853175420961
360.8000000000044,113.56300751563198,0.26436991953078853,-0.9105587420019301
362.00000000000443,113.95494320827619,0.263450541502948,-0.9415729004368405
363.2000000000045,114.34706528261108,0.2656898695130192,-0.975056163016363
364.40000000000447,114.74205211216433,0.26109652081172197,-1.008528704490526
365.60000000000446,115.13756438905975,0.25685832788659463,-1.0409841284509311
366.8000000000045,115.529812549079,0.2560804702344404,-1.075102648471217
368.00000000000455,115.92192928814183,0.2510931576393139,-1.106414554205572
369.20000000000454,116.31435355448455,0.23934850210861336,-1.1356598609840818
370.4000000000045,116.71206708464857,0.23157581581454773,-1.1669963509723362
371.60000000000457,117.10891862631763,0.22185819193513434,-1.1950038427399492
372.8000000000046,117.50322622238198,0.21156053184271567,-1.2227220411141428
374.0000000000046,117.89722220803853,0.194806886414039,-1.2496815737613458
375.2000000000046,118.29114220702274,0.18231770994670346,-1.2740575569755976
376.40000000000464,118.6887934130162,0.16915828889969542,-1.2945665756130884
377.6000000000047,119.07594136656526,0.1557223857516958,-1.3143163234411444
378.8000000000047,119.47254057158628,0.1446467210065502,-1.3333235354853454
380.00000000000466,119.86667000000187,0.13159953864347285,-1.3482707815863417
381.2000000000047,120.25717656678783,0.11958260527642423,-1.3637080021832433
382.40000000000475,120.65282812557885,0.11326544929579944,-1.3753246038093296
383.60000000000474,121.04523877007466,0.10375369626778562,-1.386766192344603
384.80000000000473,121.44027583116245,0.103527045414821,-1.3972955022919176
386.0000000000048,121.83551584876926,0.09785620530980785,-1.4082311219717862
387.2000000000048,122.22987447951965,0.0939034619485961,-1.417643748988735
388.4000000000048,122.62175824446554,0.09386234980172606,-1.4273863446529904
389.6000000000048,123.01994418610879,0.09499843210145753,-1.4377935951278342
390.80000000000484,123.41007500778446,0.09497427695511328,-1.447121891466384
392.0000000000049,123.8065953563633,0.09297809680507843,-1.4567575338734864
393.2000000000049,124.20030354517706,0.09547075446239868,-1.465531799400844
394.40000000000487,124.5960746275805,0.09287915108299993,-1.4736730863930014
395.6000000000049,124.99510588776789,0.0924758757999006,-1.4828256151100767
396.80000000000496,125.39124128696845,0.0909427783987448,-1.4928168486693476
398.00000000000495,125.78791686395182,0.09064841064186044,-1.500965494370519
399.20000000000493,126.18415720236405,0.08855011142793016,-1.51159028765731
400.400000000005,126.5820693217493,0.09281047756777788,-1.5191886472326082
401.600000000005,126.97859100937751,0.09349555695048004,-1.5265429502189907
402.800000000005,127.3682179489245,0.09538593240470569,-1.5351428730944354
404.000000000005,127.76520743237486,0.09475873683815939,-1.544055626095819
405.20000000000505,128.15937939399038,0.09156819206573774,-1.5542717919960678
406.4000000000051,128.5542605179882,0.09275110836629599,-1.5624961294988893
407.6000000000051,128.95193100971952,0.08950139077650066,-1.5718761572627873
408.80000000000507,129.34793272849694,0.08946639919251664,-1.5810986315464142
410.0000000000051,129.74369044766215,0.08907481746632417,-1.5913453596760125
411.20000000000516,130.14229313087856,0.09198208894408663,-1.6014202578419536
412.40000000000515,130.5366031455188,0.09077132825170137,-1.6091508057125434
413.60000000000514,130.9357807322098,0.09183917096391558,-1.6210973233218153
414.8000000000052,131.33144447526607,0.09206613093844315,-1.6303323849117488
416.00000000000523,131.7308455203199,0.09118984784144679,-1.6396052840663953
417.2000000000052,132.1283658521294,0.08839043854903045,-1.649521975770556
418.4000000000052,132.52763786365753,0.09277397570557747,-1.6600699424722443
419.60000000000525,132.9265977999986,0.09113245859075089,-1.670135100561546
420.8000000000053,133.3242102098187,0.09235786497381565,-1.680307395863963
422.0000000000053,133.71825163944158,0.09320439190948263,-1.6913687373917923
423.2000000000053,134.11498960758556,0.09318319770201797,-1.7010613284087137
424.4000000000053,134.50902657942137,0.09310039830843769,-1.712628230187561
425.60000000000537,134.90450129972297,0.09585247180537101,-1.723846877587797
426.80000000000535,135.3000033415736,0.09767709315570652,-1.7358998559780066
428.00000000000534,135.69855646531826,0.09412786957702565,-1.7481858884022636
429.2000000000054,136.09591422236727,0.09709568067259605,-1.761271119201631
430.40000000000543,136.49210968894835,0.09486186143367697,-1.7732334237101508
431.6000000000054,136.89087084404383,0.09544528158825649,-1.7850800154289237
432.8000000000054,137.2924825159512,0.09801151392253782,-1.7979949008190257
434.00000000000546,137.6909301374942,0.09998135815716927,-1.8116374688834296
435.2000000000055,138.08255780115746,0.10052903913822497,-1.8242529374950585
436.4000000000055,138.47628788123814,0.10083341605476712,-1.8378421365575885
437.6000000000055,138.87081135973636,0.09879143167837895,-1.8506274963178755
438.8000000000055,139.26865693134164,0.0963901131694152,-1.8654821318687347
440.00000000000557,139.66842755082735,0.09780708043622605,-1.8776920693673094
441.20000000000556,140.06450490536116,0.09815690130245519,-1.8934999808860815
442.40000000000555,140.4651911961441,0.09620865121601818,-1.9094709649726687
443.6000000000056,140.86252652761164,0.09635176619220209,-1.9243124434334353
444.80000000000564,141.25892185607677,0.09621602496624221,-1.9388144273311867
446.0000000000056,141.65676276667585,0.09264099958202465,-1.9530229001412578
447.2000000000056,142.05796981435086,0.08935630039537262,-1.968383693340026
448.40000000000566,142.45852069013088,0.08286928927791448,-1.980017590767444
449.6000000000057,142.8490452284849,0.07799408540479325,-1.9930599764857164
450.8000000000057,143.24693767596617,0.07272982221745045,-2.00236759872879
452.0000000000057,143.6455044440954,0.06456797829029587,-2.011620622447139
453.20000000000573,144.04149454238663,0.054478791281383665,-2.0182241182864007
454.4000000000058,144.44281278155202,0.05019069802309262,-2.0231696762533695
455.60000000000576,144.83756935509146,0.04199113961213674,-2.0250989991306185
456.80000000000575,145.2374666613645,0.04071612859100138,-2.0271037823432145
458.0000000000058,145.6375232617266,0.0397785912947064,-2.0297308631482656
459.20000000000584,146.035059530309,0.040636098612284344,-2.0300702209524473
460.40000000000583,146.43333342090682,0.04612255350202177,-2.031719889569673
461.6000000000058,146.83079610646053,0.05448132803332262,-2.0313922384585763
462.80000000000587,147.22678887967695,0.05675784121063121,-2.029773492744347
464.0000000000059,147.62406982938003,0.0574305759253238,-2.0323698548232616
465.2000000000059,148.0239701245243,0.05909201418441162,-2.0330253791435005
466.4000000000059,148.41967095629167,0.05356963469379383,-2.0353493978555277
467.60000000000593,148.82292841873567,0.05180737060442969,-2.0357104123995033
468.800000000006,149.22145226821362,0.044797067103235555,-2.036313971706709
470.00000000000597,149.62019924740036,0.041003473483525954,-2.0377436727777254
471.20000000000596,150.02415573163873,0.03366564664854138,-2.0390057757754634
472.400000000006,150.4187588234188,0.026796394787893585,-2.039289880638287
473.60000000000605,150.81357276777203,0.025084209491496867,-2.039289853172852
474.80000000000604,151.20842199653015,0.018854864847024477,-2.0406074496293902
476.000000000006,151.6085671065827,0.017360850532691596,-2.041593020364947
477.20000000000607,152.01298940916007,0.013621114756104058,-2.0403487248112055
478.4000000000061,152.41378050207743,0.0064934354954214735,-2.0405979808621515
479.6000000000061,152.81570647025836,0.0029664789327611962,-2.0414480222490825
480.8000000000061,153.21873707260133,-0.0006267729350474815,-2.042254170291995
482.00000000000614,153.61771183019516,-0.005331671177717656,-2.042250154999999
483.2000000000062,154.0170462987885,-0.008143122217273646,-2.0425797552306446
484.4000000000062,154.41432044544615,-0.005974275242121019,-2.044878587807311
485.60000000000616,154.81475706349218,-0.0023376010321332075,-2.0442361696725384
486.8000000000062,155.21667356170775,-0.00046260276583331983,-2.0452098756784123
488.00000000000625,155.61292438510537,-0.0008277211018495323,-2.0445498949396574
489.20000000000624,156.01597744029186,-0.0008112888845978605,-2.044879969999079
490.40000000000623,156.4148115331858,0.002385421599421844,-2.0448779874183916
491.6000000000063,156.81129744382767,0.002357048907797865,-2.045941967228017
492.8000000000063,157.21147342589023,0.005167858862023367,-2.0460142539029618
494.0000000000063,157.60927601692185,0.007987626524294023,-2.0465277138531413
495.2000000000063,158.01267404596277,0.012546464295598414,-2.04586740321702
496.40000000000634,158.41044832495234,0.01198110915050854,-2.0470474831918675
497.6000000000064,158.809867080282,0.012226791688239425,-2.0468385762948156
498.8000000000064,159.20833892087504,0.015665743522266073,-2.0464388241012346
500.00000000000637,159.61295894082372,0.01562234435495019,-2.0472001165853375
501.2000000000064,160.01029194031594,0.01689884478289444,-2.047427911673582
502.40000000000646,160.40810873127327,0.0165155230010422,-2.047509515039445
503.60000000000645,160.79843787685334,0.0192601646284431,-2.047513664031278
504.80000000000643,161.2103514387654,0.018464785885622392,-2.0478499120149203
506.0000000000065,161.61129029622768,0.016026123761051336,-2.047850875787742
507.2000000000065,162.01339012297115,0.019908625109185507,-2.044151593591606
508.4000000000065,162.41098132320454,0.021050621064302555,-2.050183362707483
509.6000000000065,162.81399241735565,0.02223369081864518,-2.049441633204056
510.80000000000655,163.21240047475519,0.024659988337819072,-2.0474620427630987
512.0000000000066,163.61417773288827,0.020758154169566445,-2.050858987080681
513.2000000000066,164.01851114453893,0.020558367757113394,-2.050755212614437
514.4000000000066,164.4119797047723,0.024386626178317328,-2.0521097492186224
515.6000000000066,164.81088957039614,0.02292961534191107,-2.0491592335063133
516.8000000000067,165.2131874309391,0.023578657082691246,-2.051455204540688
518.0000000000066,165.61130570763842,0.023835106290113095,-2.0517519617240705
519.2000000000066,166.01487428466984,0.02539882896498591,-2.0521198949999993
520.4000000000067,166.41435244203467,0.02497979241486792,-2.050773574997665
521.6000000000067,166.81993563119732,0.025784850630828138,-2.054434492139567
522.8000000000068,167.22587677718573,0.029944681415342678,-2.0531101950000004
524.0000000000067,167.6262912198607,0.027576360857481386,-2.0531101947932826
525.2000000000068,168.0288961602169,0.03107890135146585,-2.053128285095922
526.4000000000068,168.42937766598678,0.03088184171610109,-2.052406750346387
527.6000000000067,168.83242670283153,0.0293365654745118,-2.051789528103459
528.8000000000068,169.22793583842224,0.03439565511051268,-2.052450049668856
530.0000000000068,169.62851635170975,0.033499655384882754,-2.0519404902908245
531.2000000000069,170.0283264713328,0.03208585161491995,-2.0535612072820895
532.4000000000069,170.42993310946648,0.033258256993815793,-2.054750189828484
533.6000000000068,170.83175317249473,0.03319949914553966,-2.0558237826770025
534.8000000000069,171.23485369477817,0.03320739230705749,-2.0564407764102506
536.0000000000069,171.63777814935187,0.034259905842117355,-2.0565101473510143
537.2000000000069,172.0380795822187,0.035080542740773324,-2.057819646279869
538.4000000000069,172.43781245932166,0.035690848720375534,-2.0572220648643147
539.600000000007,172.843946022079,0.03726872374413792,-2.055850827299718
540.800000000007,173.2415065719292,0.03793265685891667,-2.0561665944523666
542.000000000007,173.6438476454556,0.03578281689444718,-2.0572305063846006
543.200000000007,174.04664048645068,0.0398239621273726,-2.0577593443768425
544.400000000007,174.44860541066475,0.03938006157697449,-2.0592107197609626
545.6000000000071,174.84666969727067,0.041619986216922866,-2.059140155000008
546.800000000007,175.24824652899068,0.03784225262448171,-2.0591400542033815
548.000000000007,175.65100695633575,0.039820218012158515,-2.0611200954506823
549.2000000000071,176.05478610234863,0.03932957758021993,-2.061120604354064
550.4000000000071,176.45850284370113,0.04021848005194739,-2.061109511201092
551.6000000000072,176.8602249005049,0.04223842677271161,-2.06077956272311
552.8000000000071,177.2613208702231,0.04237984013069829,-2.0621506576206015
554.0000000000072,177.66127769993585,0.03950822780950913,-2.062100057674198
555.2000000000072,178.0663165280412,0.040756897287143934,-2.0621035083240584
556.4000000000071,178.4686888948852,0.046884061950182354,-2.063191964635494
557.6000000000072,178.8686544043843,0.044781536655901344,-2.0634510283903666
558.8000000000072,179.2681153293042,0.04956929942226174,-2.0624301949999886
560.0000000000073,179.6740694270339,0.0485551497733232,-2.062430349591497
561.2000000000073,180.07663406378623,0.04695547272204981,-2.0636573728769196
562.4000000000073,180.47598385066382,0.04706421169661612,-2.064730178977164
563.6000000000073,180.88226899088798,0.04761925484958063,-2.065039102123044
564.8000000000073,181.28511619336004,0.04677473597700066,-2.063348568303379
566.0000000000073,181.6870485482265,0.05261151354147764,-2.0653903669174225
567.2000000000073,182.0853109379499,0.05214057670594552,-2.0660625348320867
568.4000000000074,182.48824165924086,0.05560265071158199,-2.066049481768606
569.6000000000074,182.89369580140286,0.05985330736390104,-2.0667914432579653
570.8000000000075,183.29922361853622,0.06118939830213854,-2.0667100049296563
572.0000000000074,183.70182236351755,0.061875863365157935,-2.067697471355272
573.2000000000074,184.105710529441,0.0632159933055697,-2.067930207015668
574.4000000000075,184.50136331634508,0.06236513914748787,-2.069020458548901
575.6000000000074,184.9066104806762,0.06647704023611023,-2.0709807956368067
576.8000000000075,185.3044056415125,0.06327205261940994,-2.0703259745872478
578.0000000000075,185.70747307927485,0.0640939509617171,-2.0716501947779973
579.2000000000075,186.11469154673134,0.06750016946617288,-2.072936077369469
580.4000000000076,186.51439720734328,0.0677652112200674,-2.0722624945445416
581.6000000000075,186.9200406513558,0.06787045122237467,-2.0742747046426544
582.8000000000076,187.32210674528412,0.07413611675635823,-2.07600399978572
584.0000000000076,187.7257081735221,0.0727697548194135,-2.0763275163419315
585.2000000000075,188.12765193044405,0.07722797477458931,-2.0772391526732585
586.4000000000076,188.52868092952676,0.07725253941892074,-2.078554483812044
587.6000000000076,188.93229391919328,0.08028572182131155,-2.0812736106870386
588.8000000000077,189.33909981912836,0.08257292273823447,-2.078550503887649
590.0000000000077,189.73945589958535,0.08504081827603915,-2.080221997599949
591.2000000000077,190.1426027031649,0.08447582607119275,-2.081515129679027
592.4000000000077,190.5496339157723,0.08763600050906462,-2.082825594461405
593.6000000000078,190.95160281050443,0.08992747235305043,-2.083822734966245
594.8000000000077,191.35603004353516,0.09480853036282255,-2.086111323118801
596.0000000000077,191.75950408020032,0.092473488667275,-2.0890876740334816
597.2000000000078,192.16524235840984,0.0939108311217336,-2.0917035260441232
598.4000000000078,192.57356136275388,0.10078311355662295,-2.0930301898378847
599.6000000000079,192.9734367525252,0.10190532390950013,-2.0943110252739903
600.8000000000078,193.37612162072207,0.1042433612700866,-2.097971213908523
602.0000000000078,193.77979498308983,0.10610555156997425,-2.0970208301352256
603.2000000000079,194.18372826824537,0.10481190579418975,-2.0983129708494883
604.4000000000078,194.58899280145675,0.10790587217332837,-2.1022645698949534
605.6000000000079,194.99168551898197,0.1112676329612079,-2.103402830598477
606.8000000000079,195.39698647312665,0.11664427744171713,-2.104856465212947
608.000000000008,195.79781036710497,0.11486751101734571,-2.1070868627082757
609.200000000008,196.2034334110753,0.1214198913532637,-2.1088122880282247
610.4000000000079,196.60935505707968,0.12455164929290041,-2.112821659281641
611.600000000008,197.01251270285704,0.12695239682191173,-2.116049445753972
612.800000000008,197.4132558922053,0.13226280404278445,-2.1199343900744134
614.000000000008,197.81696604602013,0.13519079751690244,-2.1229705591727557
615.200000000008,198.21630469834062,0.13951812960229482,-2.126930594591161
616.400000000008,198.6230233201667,0.14585962016399645,-2.1292023249368928
617.6000000000081,199.02222753458656,0.14756054510008432,-2.132018335507456
618.8000000000081,199.4247725772047,0.15142275580184328,-2.1347799837194676
620.0000000000081,199.8233494114465,0.15831901013601046,-2.1384393864933307
621.2000000000081,200.23257220672815,0.15809757418155124,-2.141059529461869
622.4000000000082,200.63461541511418,0.16268247155994608,-2.142696075355552
623.6000000000081,201.03793790044693,0.16581814145798135,-2.147667894085324
624.8000000000081,201.44235219797304,0.16972598306806574,-2.1513529390103514
626.0000000000082,201.8491826629761,0.17409786700323082,-2.155312390338353
627.2000000000082,202.25833635687235,0.1778257204404856,-2.1598089964458937
628.4000000000083,202.66163727581636,0.1810728091264857,-2.1621570811954083
629.6000000000082,203.06631945169028,0.18951534627308952,-2.167276008338693
630.8000000000083,203.468129376324,0.1968798300244997,-2.17278213159603
632.0000000000083,203.8687545917384,0.2026084843050856,-2.179425585540276
633.2000000000082,204.27193279190982,0.20941385580536886,-2.184622062701469
634.4000000000083,204.6772008819754,0.21363381055029507,-2.1908646194237797
635.6000000000083,205.08238958223725,0.2205038290609509,-2.1961337339353766
636.8000000000084,205.48820219326737,0.2280284410965483,-2.2020513299849624
638.0000000000084,205.8904708573516,0.23209761929080752,-2.2080087708601086
639.2000000000083,206.29780685397597,0.24030256610354073,-2.2144248698967197
640.4000000000084,206.70714261109026,0.24470885537332432,-2.22035285570903
641.6000000000084,207.10813045915157,0.25636111873196854,-2.228964602375579
642.8000000000084,207.5105502273336,0.26329517885344167,-2.2359785281072653
644.0000000000084,207.91085311079328,0.2716790738915096,-2.2432310908344304
645.2000000000085,208.31432661040134,0.2809862686295834,-2.2506775760419804
646.4000000000085,208.71973843128228,0.2899632964640624,-2.2574416617924005
647.6000000000085,209.12151117274036,0.3032565119230801,-2.2668965087480215
648.8000000000085,209.52754313050218,0.3113929918289371,-2.2734163496162547
650.0000000000085,209.9357242904615,0.3186545071779774,-2.2828756028712047
651.2000000000086,210.34405668646298,0.33012337470088027,-2.2917856392429106
652.4000000000085,210.74867642717155,0.3441618880928152,-2.30208487576672
653.6000000000085,211.15675450826205,0.3519644057667386,-2.3112979813319257
654.8000000000086,211.55946413502028,0.36194721896553017,-2.322951491718434
656.0000000000086,211.96609163983146,0.3780594543996958,-2.3338651030278292
657.2000000000087,212.3686221328339,0.39366515942194535,-2.345411791339129
658.4000000000086,212.77066911257918,0.41016628860834614,-2.357431677246006
659.6000000000087,213.1769935644001,0.4238201842690892,-2.3704153587667225
660.8000000000087,213.58155844622638,0.44455729715889536,-2.3817178247175663
662.0000000000086,213.98841629664162,0.4596976241709665,-2.3946072432908814
663.2000000000087,214.39238739287197,0.4723387451605894,-2.4046492442250154
664.4000000000087,214.80074190870388,0.4912668121427335,-2.4186071108533245
665.6000000000088,215.19795757201814,0.5063355291457627,-2.4306149125528
666.8000000000088,215.60837102334943,0.5228198225652372,-2.4448719812973287
668.0000000000088,216.01263886353732,0.5370175577997585,-2.4594635208695683
669.2000000000088,216.41584237737814,0.5545152482990718,-2.473766141539576
670.4000000000088,216.8271189561707,0.571554449129376,-2.489206419219796
671.6000000000088,217.22939423348993,0.5862122161565384,-2.5061600843984424
672.8000000000088,217.63800344681428,0.6035102491527213,-2.5220178310992214
674.0000000000089,218.0393891360492,0.6160911057013949,-2.5399771875441353
675.2000000000089,218.44458631389432,0.6307233755417636,-2.55437141226178
676.400000000009,218.85077191902153,0.6421677481065666,-2.5724115248680466
677.6000000000089,219.2578916158927,0.6509693009514916,-2.588117063361821
678.8000000000089,219.66028190467466,0.6638678175786075,-2.606987966907455
680.000000000009,220.06304467718533,0.6787878618188172,-2.6237912052989483
681.2000000000089,220.46872584722635,0.6844608482947405,-2.6417823323697673
682.400000000009,220.87425890536775,0.6964508362499382,-2.6607783731515733
683.600000000009,221.28171768063783,0.6990858657801711,-2.6789690206360355
684.800000000009,221.68514610364062,0.7090870948364509,-2.6979287424329197
686.0000000000091,222.09144730661757,0.7163910704624592,-2.7162598195789274
687.200000000009,222.49788919852904,0.7213418602630277,-2.735322633238871
688.4000000000091,222.90262909229793,0.7218691312153023,-2.7538083656389007
689.6000000000091,223.30512780029508,0.7236916766466417,-2.7709182344556513
690.800000000009,223.7093077160626,0.714551817910239,-2.7905229443722033
692.0000000000091,224.1196292114675,0.7066618837217105,-2.8099588500117383
693.2000000000091,224.52655468843903,0.6904059164304379,-2.829819560491326
694.4000000000092,224.92933936277953,0.6623242705028758,-2.849376304185868
695.6000000000092,225.33730417023332,0.609915261243485,-2.8645473765565836
696.8000000000092,225.73996608656793,0.5313389285492378,-2.882114225411944
698.0000000000092,226.14589971811753,0.37324658554177415,-2.8939428575290664
699.2000000000093,226.55165501678533,0.12372375210640008,-2.9007897778649285
700.4000000000092,226.96385972799635,0.022437433544638452,-2.903009974051507
701.6000000000092,227.36783292094685,0.010725676459993005,-2.9032899250092887
702.8000000000093,227.77598594890986,0.004888638702071013,-2.9036224382613685
704.0000000000093,228.17064682744154,0.00736055788083112,-2.904600666283417
705.2000000000094,228.58584818294833,0.006885102757572259,-2.9046000999999997
706.4000000000093,228.99114052180468,0.0031687482180500215,-2.904600099844601
707.6000000000093,229.4036741049096,0.0004625886095934728,-2.9052598317354237
708.8000000000094,229.8103964637663,0.003824054006752009,-2.9039399503640215
710.0000000000093,230.21303255630153,0.0007985565262955685,-2.9035901538308115
711.2000000000094,230.61752561162146,-0.0027364863656900162,-2.9038927420070055
712.4000000000094,231.01852187760073,-0.0016412707805308901,-2.902619949975698
713.6000000000095,231.4231366607027,-0.003660964342934392,-2.901316893277654
714.8000000000095,231.82530180569108,-0.004980273961284087,-2.9010004703477925
716.0000000000094,232.23685248388784,-0.004624866905881042,-2.9013064601040233
717.2000000000095,232.6478384733073,-0.005476492504072894,-2.902882498180226
718.4000000000095,233.05396057537186,-0.0068582534958550045,-2.9029603297634825
719.6000000000095,233.46437977267476,-0.005852002637752873,-2.9046018492218195
720.8000000000095,233.86965567477668,-0.007186659936282425,-2.902540369526206
722.0000000000095,234.27152476915091,-0.007012016362154316,-2.9039489027653063
723.2000000000096,234.67980251350994,-0.0066789681811363355,-2.9048431535578576
724.4000000000096,235.0836920103117,-0.002425101609949243,-2.9075721874090976
725.6000000000096,235.48721080095626,-0.0036584978276115176,-2.9064158291690996
726.8000000000096,235.89071442686054,-0.00288318818487876,-2.909534431745878
728.0000000000097,236.30465480621268,0.003763006621774423,-2.91018649686923
729.2000000000096,236.7084383524019,-0.00046653545185271206,-2.910348508577057
730.4000000000096,237.11448897537733,0.000591651779089597,-2.910850026340724
731.6000000000097,237.52360442108233,-0.008185517500135298,-2.912587762269048
732.8000000000097,237.9271896802723,-0.007582470588039403,-2.9112896758924887
734.0000000000098,238.33755506937123,-0.003971379186068935,-2.9084098831795453
735.2000000000097,238.7433603817199,-0.008350425846207488,-2.9095263991318365
736.4000000000098,239.15366357138245,-0.012864931835363524,-2.9086004306250706
737.6000000000098,239.5562445568175,-0.007750531180383602,-2.907556481869368
738.8000000000097,239.9606112051562,-0.005823376998174146,-2.9078897258998824
740.0000000000098,240.36404739955128,-0.006216411771454711,-2.909200024863643
741.2000000000098,240.76666590679366,-0.004225545537930975,-2.9072622092520235
742.4000000000099,241.17427530229907,-0.0011311111485190484,-2.9085523295385225
743.6000000000099,241.58574661054618,-0.006992140573879313,-2.910530232371765
744.8000000000098,241.98990460007425,-0.001971511356861466,-2.909963763582371
746.0000000000099,242.39639986859834,-0.0018962981035297588,-2.9121691190725625
747.2000000000099,242.80273862924528,-0.003376064756630326,-2.9111869109051898
748.4000000000099,243.20190730731497,-0.00694757131897239,-2.9099589571172695
749.6000000000099,243.6033913971712,-0.009000218622415845,-2.9105534600304503
750.80000000001,244.01515358099024,-0.008864478969543788,-2.909215284992716
752.00000000001,244.42589381307639,-0.014974867348846344,-2.9079192376951393
753.20000000001,244.83258375033873,-0.015693177955385496,-2.9091378334749702
754.40000000001,245.2394170741338,-0.01338575261765218,-2.908283008878568
755.60000000001,245.64463148252975,-0.012764275476978115,-2.9085987420679147
756.8000000000101,246.0452635736163,-0.01151104236697642,-2.9088799228275
758.00000000001,246.45031921843213,-0.01596423396654445,-2.9102110915800847
759.20000000001,246.85606497559243,-0.01144753904865281,-2.9111808057291277
760.4000000000101,247.25240349109447,-0.01601946908298224,-2.911185197167173
761.6000000000101,247.6771556228624,-0.012773898150684193,-2.912500128835438
762.8000000000102,248.08175572160852,-0.011997726659008556,-2.9128196165512645
764.0000000000101,248.49083554438064,-0.010286075831983377,-2.913273852952717
765.2000000000102,248.8980677661616,-0.005432098680795638,-2.913820249608336
766.4000000000102,249.3032808451263,-0.010519611843291088,-2.9150042892454238
767.6000000000101,249.7053692316776,-0.004191040846173166,-2.9161185445964604
768.8000000000102,250.1079823883755,-0.004735219162891768,-2.915868342319106
770.0000000000102,250.51667000000376,-0.005413142109254032,-2.916439859303156
771.2000000000103,250.9240696275907,-0.004207447626118688,-2.915460743752053
772.4000000000103,251.3348418867393,-0.004612398768565784,-2.9158038865577227
773.6000000000103,251.73849152003996,-0.002678086985816508,-2.9157738141172684
774.8000000000103,252.14756159609018,-0.0035874340231991653,-2.9170998051198476
776.0000000000103,252.55470734242724,0.000991231847089491,-2.9184201057823316
777.2000000000103,252.95973257849204,-0.00021569904748397484,-2.918419922617163
778.4000000000103,253.3677134140595,0.0042816477364295835,-2.916439823256946
779.6000000000104,253.77061560628684,0.0015794841133787152,-2.9161108647272203
780.8000000000104,254.1790467596487,-0.003872173866357631,-2.917153311802603
782.0000000000105,254.59177471404104,-0.009689752035907606,-2.9162147118800705
783.2000000000104,254.99236374526285,-0.006986431037387497,-2.913810006177938
784.4000000000104,255.39874378165598,-0.007189069345696186,-2.9138098399980192
785.6000000000105,255.80636600745632,-0.005108208880981291,-2.9125024164095783
786.8000000000104,256.21563110419106,-0.011859080869412342,-2.9143955272311226
788.0000000000105,256.624793295162,-0.008828022095317856,-2.9164494482228003
789.2000000000105,257.02922681542947,-0.005812001105672593,-2.9153167847875894
790.4000000000106,257.4388960812956,0.00023942398657306185,-2.91810146248016
791.6000000000106,257.84362507798187,-0.00628580884959451,-2.9193749862752387
792.8000000000105,258.24676348173426,-0.0019910838005841036,-2.9197347833640714
794.0000000000106,258.65426716705383,0.002950068660070748,-2.921677334249287
795.2000000000106,259.0624713522859,0.0015027020754074805,-2.9221257977455863
796.4000000000106,259.4642806551257,0.0011518552495970447,-2.9200610024631546
797.0000000000106,259.66773825760527,0.004658985219724077,-2.9210496342023524