File: 01_Data/Rug_Pad/STA/N2/10K_min/Rug_Pad_STA_N2_10KData_221025_R2.csv
##Temp./Â°C,Time/min,DSC/(mW/mg),Mass loss/mg
51.0,10.711687815240884,0.0126219008863937,-0.031276075784473445
52.100000000000016,11.10521785683782,0.05228398333156137,-0.030672335438952203
53.20000000000003,11.361124862219414,0.07556737915313394,-0.0283373588206155
54.30000000000005,11.571271792705646,0.09877569495556182,-0.029575270040399282
55.40000000000006,11.756821035266478,0.10849200170452167,-0.02912755691764435
56.50000000000008,11.929503881102042,0.12188602789703107,-0.028869840273202385
57.600000000000094,12.092866702126843,0.1300934629477113,-0.02901726425832063
58.70000000000011,12.248572894071508,0.13734057363330465,-0.029999673645319636
59.800000000000125,12.400350059198473,0.1466028534922308,-0.029309224194505656
60.90000000000014,12.545235271830485,0.1509540984092319,-0.0304237234186977
62.000000000000156,12.688320963005156,0.1542039778148454,-0.03018454853107988
63.10000000000017,12.827639632171632,0.1579212617423873,-0.030393490311654503
64.20000000000019,12.964577735134828,0.16405570841793127,-0.03063163017187298
65.30000000000021,13.097642269083272,0.16733694492128914,-0.030447868427966096
66.40000000000022,13.233561187648545,0.16976755134526944,-0.030924672267454767
67.50000000000023,13.365486340296497,0.17315329537696988,-0.031698694564067154
68.60000000000025,13.494725778605485,0.1778189525374383,-0.032044041825241454
69.70000000000027,13.622138724492281,0.17968647189905584,-0.03183603266397661
70.80000000000028,13.750128895471175,0.18350132395131413,-0.033053793417047395
71.90000000000029,13.87591572896095,0.18796346575630918,-0.03302997080683312
73.00000000000031,14.001119442486617,0.19060649677554342,-0.033676800671558205
74.10000000000034,14.123173840502131,0.19282342876001235,-0.034448283478322406
75.20000000000034,14.242486978887163,0.19699124382307387,-0.03474983617347682
76.30000000000035,14.367968683595901,0.19854725366796022,-0.03436042895233049
77.40000000000038,14.4879124393634,0.2010691007720926,-0.035727740141262565
78.5000000000004,14.608423679979573,0.20226334246057576,-0.03567907561183992
79.6000000000004,14.728798762239332,0.20296825733424462,-0.03567522843539894
80.70000000000041,14.843503198968584,0.20510589084406095,-0.035640628025116694
81.80000000000044,14.963899766547446,0.2066463827330064,-0.035734804860675595
82.90000000000046,15.081487819599545,0.2089344062550591,-0.03567896159513406
84.00000000000047,15.198027630192376,0.2100999593865287,-0.03563872664346057
85.10000000000048,15.314356389661857,0.2114494805842002,-0.03573419362509789
86.2000000000005,15.428359968400358,0.21291900632048577,-0.03735531139442072
87.30000000000052,15.543118464134263,0.21244483297986239,-0.037088934307266896
88.40000000000053,15.657439090237116,0.21472775415464662,-0.03710601188857332
89.50000000000054,15.770019386028702,0.21563159098045426,-0.037100117633896534
90.60000000000056,15.880954594867147,0.21760951099563308,-0.037094694265007444
91.70000000000059,15.995631178579426,0.21660731798287503,-0.03849895805382442
92.8000000000006,16.10461892504504,0.21838683878490928,-0.04135211293381991
93.9000000000006,16.21835349175526,0.22014355360599258,-0.039738470082375965
95.00000000000063,16.32991887339415,0.22017021382453494,-0.0384209492877452
96.10000000000065,16.441853084707002,0.22098978426396854,-0.03985159732088306
97.20000000000066,16.551282682205052,0.21968500793259504,-0.039844527422961296
98.30000000000067,16.661928131760863,0.22104219939413694,-0.03984524753831309
99.40000000000069,16.772456134615584,0.22319044009798672,-0.039845049694795964
100.50000000000071,16.87955418298039,0.22288535884393257,-0.040472455709975375
101.60000000000072,16.990895812888603,0.2230169795068091,-0.040666579973524186
102.70000000000073,17.09748106389288,0.22136316239468423,-0.04143680927996307
103.80000000000075,17.207699879879662,0.22391638470480102,-0.04104398904406237
104.90000000000077,17.317008896474487,0.22709180271910978,-0.04016704403779503
106.00000000000078,17.424431580978293,0.22650525119369525,-0.04051548489938961
107.10000000000079,17.533333267048516,0.2241033151977705,-0.04135292238446864
108.20000000000081,17.64165733457718,0.22580663603530204,-0.04143074437399896
109.30000000000084,17.75092360698528,0.22791721181461055,-0.042709875325624314
110.40000000000084,17.857963003869266,0.22594393480999386,-0.04133671786582971
111.50000000000085,17.965631730939524,0.22808337774553844,-0.04173938480080697
112.60000000000088,18.074034593002267,0.22898508004320672,-0.042834233271626054
113.7000000000009,18.182413546074464,0.22849762261646678,-0.04271805620714009
114.8000000000009,18.289951305914077,0.22978707835063117,-0.04272369726403191
115.90000000000092,18.396632791368823,0.23010243020272736,-0.04270884712728629
117.00000000000094,18.504247313999176,0.23025815478847278,-0.042693871017381646
118.10000000000096,18.611562056739764,0.23015576636743706,-0.043024955441858026
119.20000000000097,18.718893892976958,0.22946387849933192,-0.04393998156867873
120.30000000000098,18.825405456149834,0.23154879399484452,-0.04270966985003666
121.400000000001,18.93309612210824,0.23038868996533424,-0.04406538182046971
122.50000000000102,19.040668899438888,0.23134702818289343,-0.04364996609470362
123.60000000000103,19.146914185110518,0.2288805119715689,-0.044003599206774435
124.70000000000104,19.25425721004519,0.22893851635779772,-0.044461041410037705
125.80000000000106,19.36040437185813,0.22922781896376532,-0.04534062874531797
126.90000000000109,19.467367808512726,0.23039976192734413,-0.045338980184714384
128.00000000000108,19.573292655892207,0.23024130671068088,-0.04534005670730945
129.1000000000011,19.67848786847189,0.23120516429068128,-0.045339271511227075
130.20000000000113,19.786660531654128,0.23468373773775042,-0.04534222034312885
131.30000000000115,19.890504412515785,0.23434477374278084,-0.0466600894314233
132.40000000000117,19.997405589533148,0.2356527378752873,-0.04581976781680641
133.50000000000117,20.102211492196762,0.2338763472238009,-0.045330056066116065
134.6000000000012,20.2074741132326,0.23597280852333102,-0.04599213794445145
135.7000000000012,20.313569462591616,0.23539711169591138,-0.04777971262571867
136.8000000000012,20.419276697911382,0.23749921893494175,-0.04731999966058842
137.90000000000123,20.524585885306095,0.2376075194264694,-0.047460079191412596
139.00000000000125,20.629915804211233,0.23795317698102303,-0.04731974517117843
140.10000000000127,20.73567220699504,0.23851852852516797,-0.04738363822545599
141.2000000000013,20.840955655238247,0.23865169546371168,-0.045988688756517515
142.3000000000013,20.94645873107901,0.2389827575675122,-0.048300308736440645
143.4000000000013,21.050968974240366,0.23883687259569197,-0.0486324309692594
144.50000000000134,21.156469709560554,0.24002047220896616,-0.04862997676478775
145.60000000000133,21.260325308526788,0.23827242418340444,-0.04927461707344971
146.70000000000135,21.366565315574952,0.2421358645826135,-0.04864974592481808
147.80000000000138,21.4709258808081,0.2399113270757991,-0.04863228082006188
148.9000000000014,21.574635942324896,0.23814656792225186,-0.0486300265790236
150.00000000000142,21.680387491877422,0.23787738749610499,-0.049941828897885454
151.10000000000142,21.783455749412727,0.23904311772657738,-0.0489227689488092
152.20000000000144,21.89013659001198,0.23736663476804043,-0.0499500982979324
153.30000000000146,21.995182285742164,0.23824380389319832,-0.05126772874811314
154.40000000000146,22.09963005033926,0.23720162870537276,-0.05124729037010933
155.50000000000148,22.202293066904115,0.23555909973575762,-0.05158636563655028
156.6000000000015,22.309443630688108,0.23749522768499376,-0.05125999984779339
157.70000000000152,22.41395381305807,0.23656656342916593,-0.051260948300581255
158.80000000000155,22.518014255334627,0.23785798701228977,-0.05127321171297439
159.90000000000154,22.622673752255576,0.2378579781048109,-0.0525925262624205
161.00000000000156,22.728117390679785,0.2395182516378329,-0.05334790936780198
162.1000000000016,22.830545660005832,0.23924574514507624,-0.052589826896131786
163.20000000000158,22.9368113092304,0.23993281671662992,-0.05128641023410552
164.3000000000016,23.040779204717904,0.23866791114965924,-0.052981114593466216
165.40000000000163,23.153076238510707,0.239749791981259,-0.0532391039907405
166.50000000000165,23.25983135540535,0.24006477206779264,-0.05324939769814474
167.60000000000167,23.365600548303597,0.23981096061762164,-0.053240000132623866
168.70000000000167,23.469924517257713,0.2384946357909158,-0.05466129264110009
169.8000000000017,23.575703269161224,0.239373248592203,-0.053244570868191676
170.9000000000017,23.678683679079192,0.2406760372011193,-0.05456999097520665
172.0000000000017,23.783633459211,0.23905081191176414,-0.05457017673021802
173.10000000000173,23.887874647384187,0.2394699769129055,-0.055874559114504674
174.20000000000175,23.991558643008858,0.2377851101245425,-0.05554999930094784
175.30000000000177,24.096940242584417,0.239964167621475,-0.055547222234866744
176.4000000000018,24.201873181891298,0.24085948118784806,-0.056210186906913595
177.5000000000018,24.306379450224114,0.24063727772128962,-0.05752984440828435
178.6000000000018,24.411448218354842,0.2388396548284345,-0.057529999830561174
179.70000000000184,24.515163783975304,0.2394788628310065,-0.05773794513993513
180.80000000000183,24.620516955860946,0.2398343344418753,-0.05885000065606594
181.90000000000185,24.724924616897788,0.23885669923035135,-0.05994021985106457
183.00000000000188,24.829071885017505,0.24080018712075912,-0.0601599973846052
184.1000000000019,24.93304983429225,0.24008415598460253,-0.060500885617568834
185.20000000000192,25.03837486315886,0.24074437999392362,-0.060489820158804886
186.30000000000192,25.142853428229692,0.24119484265997893,-0.059682520274479955
187.40000000000194,25.246229536026206,0.24116123229769104,-0.06114705564890199
188.50000000000196,25.34992010086717,0.24320646147311642,-0.06114999999679416
189.60000000000196,25.45496522661382,0.24329800945833335,-0.06114999904202989
190.70000000000198,25.559079333602742,0.24428431908403847,-0.06150613506989
191.800000000002,25.66183144811924,0.24473527145499685,-0.06311996046848245
192.90000000000202,25.76683095437205,0.24431001449158396,-0.06312006326372588
194.00000000000205,25.871034370321293,0.24490665527548283,-0.06444060446963062
195.10000000000204,25.974724665845375,0.24577442346417433,-0.06548497084901816
196.20000000000206,26.07969244547219,0.2444396031748487,-0.06543000006899069
197.3000000000021,26.181405122726062,0.24369519442831067,-0.0654299999733996
198.40000000000208,26.287827037591175,0.2457043801516201,-0.06539419544322511
199.5000000000021,26.392559943806763,0.24567580472917094,-0.06707951672419776
200.60000000000213,26.49621466238776,0.24697284283533372,-0.06708127862202451
201.70000000000215,26.600257163376664,0.24706357851757088,-0.06839481107180134
202.80000000000217,26.705125627108977,0.24822128671948196,-0.06904999571263071
203.90000000000217,26.80889534517628,0.2489748778630424,-0.07036641373204544
205.0000000000022,26.911371756422366,0.24952498219662578,-0.07168498296720038
206.1000000000022,27.018048743787027,0.25179231500560273,-0.0710315395175618
207.2000000000022,27.12264205749605,0.25065456860064445,-0.07235002491236209
208.30000000000223,27.22661277220526,0.2504520801963102,-0.07365941252293418
209.40000000000225,27.331011095098233,0.24949651648477905,-0.07366200755533203
210.50000000000227,27.435450633920507,0.24898950363569178,-0.07497999328209115
211.6000000000023,27.54041627159595,0.25042991698546335,-0.07541949976735474
212.7000000000023,27.644607055839547,0.25166034732021586,-0.0762999976439458
213.8000000000023,27.74804255973127,0.2549728178546906,-0.07756597257882847
214.90000000000234,27.85391150130002,0.252877427034362,-0.07991913500045245
216.00000000000233,27.958607628047154,0.25520458983047234,-0.07991999913921477
217.10000000000235,28.062595681877273,0.25710049063148793,-0.08124665819406074
218.20000000000238,28.167844232784258,0.257339459249462,-0.08157065847563905
219.3000000000024,28.271553456382566,0.25647073362858364,-0.08256007147224187
220.40000000000242,28.37651429890459,0.25973558101043936,-0.08256008397000514
221.50000000000242,28.481322758734603,0.26093156694528197,-0.08303133976931365
222.60000000000244,28.584814725745094,0.2600830214012848,-0.08414336241328657
223.70000000000246,28.68836682442339,0.26274461425064616,-0.08685157686603118
224.80000000000246,28.79414480065559,0.26361848374520946,-0.08684826676136304
225.90000000000248,28.898680734507057,0.26544708967856506,-0.0881598179702272
227.0000000000025,29.00294697545438,0.26782999458260714,-0.08945812625705729
228.10000000000252,29.10778473456448,0.2706396972900933,-0.09078999187782699
229.20000000000255,29.21234523674347,0.2718189026116531,-0.09313664212747197
230.30000000000254,29.316448674163475,0.2709871199296741,-0.09341953746890708
231.40000000000256,29.420698789552045,0.2736957797218985,-0.09445152052358408
232.5000000000026,29.525355147184715,0.27655741090784636,-0.09606072777124819
233.60000000000258,29.629980162860488,0.2782316365969636,-0.09738078217152957
234.7000000000026,29.73503779621034,0.2821157043135529,-0.09870609010962417
235.80000000000263,29.838988983182468,0.2839292651863985,-0.1000098777222802
236.90000000000265,29.944177837878037,0.2833771190003282,-0.1026498268042495
238.00000000000267,30.04780768162171,0.2846000660270603,-0.1031550750908532
239.10000000000267,30.153737733493273,0.2867737177109847,-0.10536952332627258
240.2000000000027,30.257991990236928,0.2879878572160068,-0.10593079759343027
241.3000000000027,30.362833723038655,0.2881567742138461,-0.1072253597971784
242.4000000000027,30.467118633569807,0.2862347904228527,-0.10988959844572532
243.50000000000273,30.571758023709435,0.2887092679646486,-0.11129132376766249
244.60000000000275,30.676562619812938,0.2904168561859141,-0.11252081566321337
245.70000000000277,30.78067361337129,0.295519194093662,-0.115147297611502
246.8000000000028,30.885817116010365,0.2979371397023564,-0.11647661503591822
247.9000000000028,30.98926720415166,0.3014042153410856,-0.11781278475820267
249.0000000000028,31.095064227285025,0.3070035050788666,-0.12047698914155802
250.10000000000284,31.1995095650875,0.3162892258565984,-0.121751580695582
251.20000000000283,31.303410917356416,0.3301957084938603,-0.1227327565555636
252.30000000000285,31.40786586623634,0.3464935927281163,-0.12492201762329369
253.40000000000288,31.51290895936763,0.3580486418903404,-0.12657897133487594
254.5000000000029,31.618456536436163,0.36160895246135644,-0.12933176360622012
255.60000000000292,31.722625964735688,0.3454253975172248,-0.13064004220821257
256.7000000000029,31.827554741208505,0.33373917161516603,-0.13404009647367676
257.8000000000029,31.932759250995336,0.32078657742732963,-0.13599081314801298
258.90000000000293,32.03832800606698,0.3091832924697174,-0.1373405544819426
260.00000000000296,32.142080534745396,0.3018379788559705,-0.13877989308173166
261.100000000003,32.247973812355696,0.2943179395437048,-0.14229511742832734
262.200000000003,32.35168946828402,0.2874428440056859,-0.14524007898181868
263.300000000003,32.45631684333578,0.28530809663644513,-0.1472691619409714
264.40000000000305,32.559080994227,0.28404561801643613,-0.14919072957202317
265.50000000000307,32.66622152545832,0.2811087903898791,-0.15163963662155
266.6000000000031,32.770802778787846,0.2799157319591676,-0.15423968742888494
267.7000000000031,32.87596423866867,0.280341161345808,-0.1572964052684691
268.8000000000031,32.98134059482865,0.28065653229644777,-0.1599728766591646
269.9000000000031,33.085040963411636,0.2802643860610029,-0.16255047411378065
271.0000000000031,33.18973029504571,0.2782483001470559,-0.1659267674266962
272.10000000000315,33.294716125347854,0.28096786802164014,-0.16786999134369562
273.2000000000032,33.39925874184147,0.2813732368221376,-0.17181212054958195
274.30000000000314,33.50377779530004,0.2807534051177206,-0.17537649994840754
275.40000000000316,33.60898838534008,0.2822561250705402,-0.17729362979706798
276.5000000000032,33.71435243055156,0.28142452217938546,-0.18123952785182906
277.6000000000032,33.818604545935194,0.27892506893955843,-0.1838467290162673
278.70000000000323,33.92274697294663,0.2778770015229629,-0.1867415604917726
279.80000000000325,34.02888402889023,0.27628577805462146,-0.18999286856173603
280.9000000000033,34.133106690129964,0.27793676836348724,-0.19358186739561534
282.0000000000033,34.23817890554585,0.2763531045078172,-0.19743322900829963
283.1000000000033,34.34382265973539,0.27439332300759967,-0.2016417835831099
284.20000000000334,34.446675778071345,0.2738142591483576,-0.2032339997508199
285.30000000000337,34.55301066107923,0.2719333401860481,-0.20847303172813092
286.40000000000333,34.658687200908794,0.2726646424872809,-0.20989809697360018
287.50000000000335,34.763779992405304,0.2711843030193469,-0.21368464311570845
288.6000000000034,34.86804581687639,0.2701050768644398,-0.216598649923208
289.7000000000034,34.97368671854452,0.2669830182339094,-0.21981623130929684
290.8000000000034,35.079738604282575,0.267381702543288,-0.22412840167767767
291.9000000000034,35.1835352731066,0.267061358654299,-0.22779183521443525
293.0000000000034,35.29003410603916,0.2649501983841841,-0.23043235662097805
294.10000000000343,35.39473346628042,0.2642653101069733,-0.2329975609956576
295.20000000000346,35.49961665474058,0.2616293185745274,-0.23604663201906906
296.3000000000035,35.60561750090139,0.2609568171484418,-0.23855943971609195
297.4000000000035,35.70956480170294,0.2581324878820102,-0.2440630316943717
298.5000000000035,35.81514740952509,0.25623508353187213,-0.24669392310612448
299.60000000000355,35.92090477824398,0.25437142678046487,-0.24960362530828917
300.70000000000357,36.02531100125861,0.2528246812760932,-0.2522248579401487
301.8000000000036,36.13167793219792,0.2517312457749417,-0.2548785338220827
302.9000000000036,36.235972729253874,0.2494668168843177,-0.2575149496373146
304.0000000000036,36.34149946544248,0.247504947108178,-0.2612808101640205
305.1000000000036,36.44768746668966,0.24522139835513912,-0.26511896548821134
306.2000000000036,36.55314772370494,0.24320842806320148,-0.2677802396511222
307.30000000000365,36.65926999735499,0.2404522031787087,-0.27040032295763705
308.4000000000037,36.764360806256015,0.23939577045987825,-0.2743370238021101
309.5000000000037,36.86993970489398,0.23618473707498183,-0.2751734894103546
310.60000000000366,36.97652697687546,0.23586400913604577,-0.2798650268138436
311.7000000000037,37.0819884402078,0.2348006488995099,-0.28244576875814875
312.8000000000037,37.18709172296819,0.23144927156897704,-0.2861978411356949
313.90000000000373,37.29291548630303,0.23131951146049623,-0.28752919667110266
315.00000000000375,37.398034313973014,0.22846930010789657,-0.2928188107970384
316.1000000000038,37.50426896506517,0.22867472542968376,-0.2942008810003518
317.2000000000038,37.609569295401315,0.2265535902954956,-0.2970629519559749
318.3000000000038,37.71482163179027,0.2253039763833541,-0.30083600572861524
319.40000000000384,37.82105138657157,0.22389869006228363,-0.30232281128840466
320.5000000000038,37.926679164713185,0.22015253244373106,-0.30491367856381313
321.60000000000383,38.03337733384719,0.2198466690430309,-0.30846327197783774
322.70000000000385,38.13784926551949,0.21906963223630277,-0.3117772632044451
323.8000000000039,38.24372133303457,0.21478400226433464,-0.3157118328631441
324.9000000000039,38.350284191343746,0.21446171614265164,-0.3196661926536515
326.0000000000039,38.45432752937734,0.20984943528573502,-0.3213433570870232
327.10000000000394,38.56105823848527,0.20739811866992292,-0.32503036579565414
328.2000000000039,38.66717326025529,0.20603761186915331,-0.32800767533575126
329.30000000000393,38.77359699214369,0.2015309069050431,-0.33277129672641026
330.40000000000396,38.87917090221116,0.1994780373037276,-0.3358299983622892
331.500000000004,38.985652077738024,0.19550958912755506,-0.3403046499528153
332.600000000004,39.09120729710523,0.19386311667694772,-0.34293889433177016
333.700000000004,39.19653720413784,0.19015180398846737,-0.3473877808360073
334.80000000000405,39.30197168406543,0.18835029557310395,-0.3512718948781717
335.90000000000407,39.40897909483521,0.18548107046518986,-0.3560338538036225
337.0000000000041,39.51441637460622,0.18334789902909548,-0.3611051227165989
338.10000000000406,39.61974698377627,0.18075822696915966,-0.3657438736218688
339.2000000000041,39.72608522506628,0.17862014524264164,-0.37001156518526246
340.3000000000041,39.83184482580416,0.1773182704049876,-0.37533431686492236
341.4000000000041,39.938120162988675,0.17346803276883266,-0.3808569702948432
342.50000000000415,40.04478445046609,0.16853546037584533,-0.38671641779805643
343.6000000000042,40.14988863322534,0.1677687154693961,-0.3922888850657218
344.7000000000042,40.25677777819719,0.16485429264233836,-0.39910140066527866
345.80000000000416,40.361713375577985,0.1614060002885993,-0.40707444488264155
346.9000000000042,40.468804857137584,0.15859757581296346,-0.41450449464379835
348.0000000000042,40.574218934228675,0.15785293960131747,-0.4213106450949602
349.10000000000423,40.68098000838126,0.15547755305625405,-0.4289416138342905
350.20000000000425,40.78681578315667,0.1553150315939943,-0.4373662602256472
351.3000000000043,40.893245853536,0.1542038821008983,-0.4487610811326195
352.4000000000043,40.99955126669405,0.15375156370497473,-0.4578236534085196
353.5000000000043,41.10552732729513,0.15233997714175396,-0.4680439964603762
354.60000000000434,41.21213607215068,0.15020782965419616,-0.47886201789603744
355.7000000000043,41.31906786530301,0.15254879723361225,-0.49114553768703395
356.80000000000433,41.42562630934677,0.15121365405080733,-0.5022090035170899
357.90000000000435,41.53099137414367,0.15247535722988753,-0.5147095095896397
359.0000000000044,41.6378018812905,0.15371616200009613,-0.5289773984510249
360.1000000000044,41.744356803883925,0.15421336991794343,-0.5430979709821466
361.2000000000044,41.85109023254327,0.1560672130759368,-0.5571327054527417
362.30000000000445,41.95779597716051,0.15801879763796473,-0.5731160006913631
363.4000000000044,42.064000725783394,0.15792725319495,-0.5911729161503585
364.50000000000443,42.170061032883645,0.16088419532011733,-0.6073776338339956
365.60000000000446,42.27692677170923,0.162052297209978,-0.6229360314303172
366.7000000000045,42.38374158178817,0.1650033332161297,-0.6422834281823486
367.8000000000045,42.48982605726524,0.16951784092330852,-0.660606334874613
368.9000000000045,42.594923093248,0.17225420776547307,-0.680804994297584
370.00000000000455,42.703176757830725,0.17661640329067307,-0.7010815989370838
371.10000000000457,42.81007056076916,0.18092213608096047,-0.7229388975870799
372.2000000000046,42.916231394857846,0.1831673526478756,-0.745240025632798
373.30000000000456,43.0240639859433,0.18418224187431909,-0.7668848245942606
374.4000000000046,43.12990476684015,0.1873820581210559,-0.7892281414741786
375.5000000000046,43.236306478779255,0.19407185260241727,-0.8115400740884038
376.6000000000046,43.34271617796109,0.19558260810216044,-0.8347478455235366
377.70000000000465,43.44970720616505,0.19668296995586965,-0.8589459565639883
378.8000000000047,43.55555548755661,0.19879158663764118,-0.8814235750905413
379.9000000000047,43.66271656485455,0.2026822091096268,-0.9040723909706201
381.00000000000466,43.76825558718356,0.20323852776566326,-0.9265737638926668
382.1000000000047,43.87553100568944,0.204969038381156,-0.9493288990212418
383.2000000000047,43.98173952481266,0.2052104047447258,-0.9723387176243667
384.30000000000473,44.08907243091809,0.20706514137084986,-0.9934072023568197
385.40000000000475,44.197173190864014,0.20673971517281148,-1.0158686961063834
386.5000000000048,44.30299971485899,0.2059027655640404,-1.035394766108443
387.6000000000048,44.409334210289174,0.20705230737180613,-1.0557136186528888
388.7000000000048,44.51617116838047,0.20756762483938795,-1.0760487978818563
389.80000000000484,44.62392845407736,0.20884365805644023,-1.0949309131376244
390.9000000000048,44.73056069832664,0.20704962616020067,-1.114569947351649
392.00000000000483,44.838305872087474,0.20531526793023203,-1.1339713767991033
393.10000000000485,44.94524999960627,0.20323072548811422,-1.152421768374999
394.2000000000049,45.051582933725534,0.20481905134466494,-1.1689635904234592
395.3000000000049,45.157612081222396,0.20145630913671236,-1.1836951543546985
396.4000000000049,45.26719224658107,0.1999150666661087,-1.201994264725922
397.50000000000495,45.374514089953564,0.19827181944121464,-1.2165773111759441
398.6000000000049,45.48128072186668,0.19914750834875117,-1.2331330906801048
399.70000000000493,45.58869282730899,0.19641863348514849,-1.2469503872625372
400.80000000000496,45.69549265992091,0.19566645638307684,-1.2615243091552863
401.900000000005,45.800617509074705,0.19664815937782776,-1.2756646893799748
403.000000000005,45.90986835673712,0.1951181011612121,-1.2913960127514734
404.100000000005,46.01679568099012,0.1944751406666141,-1.304468473616467
405.20000000000505,46.12374837703813,0.19409646057421492,-1.317690431282144
406.30000000000507,46.23043373645482,0.19292112773876452,-1.3314414488489144
407.4000000000051,46.33887993312916,0.19169879345471197,-1.3439234211756745
408.50000000000506,46.44641203582383,0.19105648585613877,-1.357331742641029
409.6000000000051,46.553629320451265,0.18921193363309102,-1.370109548691457
410.7000000000051,46.66036184041283,0.19015702684241476,-1.3817387754586496
411.8000000000051,46.76778563164322,0.1883212954200702,-1.3951573912335884
412.90000000000515,46.874672049809924,0.1850832579607209,-1.4074912208195136
414.0000000000052,46.9826946990426,0.18599261162329117,-1.4196641439666564
415.1000000000052,47.08963684099636,0.18385910383055865,-1.4321701339082171
416.20000000000516,47.19629818807045,0.18344868360889283,-1.4439545597160772
417.3000000000052,47.304687404300815,0.1832593864756742,-1.4546246353405259
418.4000000000052,47.41101077094569,0.18284823602907485,-1.4654599022684822
419.50000000000523,47.5186703908112,0.18091418215944505,-1.477523137455501
420.60000000000525,47.6251983938199,0.18212630460979717,-1.4897160404039766
421.7000000000053,47.73211549059234,0.18247033411045116,-1.4998364377923799
422.8000000000053,47.84057487599185,0.17982921619940473,-1.5096315636869617
423.9000000000053,47.94748287301448,0.17860934804320977,-1.5197763754465106
425.00000000000534,48.054973994240214,0.17725345454490726,-1.5304112805830887
426.1000000000053,48.1625165618783,0.17828063460257237,-1.539577110248234
427.20000000000533,48.270196804472135,0.1772053136575149,-1.549064812860962
428.30000000000535,48.3777991558014,0.17652462148677922,-1.5592714660516838
429.4000000000054,48.484926997363274,0.17725718586348777,-1.5684550215838007
430.5000000000054,48.5931272654085,0.17757310820878008,-1.5779676610027908
431.6000000000054,48.70085613954608,0.1752212060730967,-1.5879089811256772
432.70000000000545,48.808348268409304,0.1748201941377051,-1.5945356475377634
433.8000000000054,48.91637859699811,0.174537252360354,-1.6045644757865283
434.90000000000543,49.02349722106719,0.175917760899729,-1.6133666598218097
436.00000000000546,49.130923883823904,0.1760964581510881,-1.6204565782949354
437.1000000000055,49.239390878490056,0.1734024882110562,-1.6274329541618329
438.2000000000055,49.34668427244311,0.1722946392954987,-1.6364781465400728
439.3000000000055,49.454572133550684,0.17073009997734823,-1.6436543843021765
440.40000000000555,49.56195431170617,0.17165521179835574,-1.6510344509853976
441.50000000000557,49.66964239447317,0.1682768068616124,-1.6606261960189066
442.6000000000056,49.777829267840524,0.16877117066165936,-1.6668326397807913
443.70000000000556,49.88568681241411,0.16725116829739695,-1.6738849781100185
444.8000000000056,49.99444885912037,0.16625558498592852,-1.6811999870086893
445.9000000000056,50.09971105635634,0.1663664325490945,-1.6886965309570128
447.0000000000056,50.21007734084108,0.1668102494040622,-1.6953915003632294
448.10000000000565,50.318097230585614,0.16514109131532512,-1.7017611341557939
449.2000000000057,50.42312042524736,0.1628568569960253,-1.7089937233056771
450.3000000000057,50.531353014001006,0.16187265927097644,-1.713696390137935
451.40000000000566,50.64143036010065,0.16458390391196032,-1.7197287078972514
452.5000000000057,50.74926558987226,0.16283864744596266,-1.7262298924017636
453.6000000000057,50.85694230422054,0.16400749254570895,-1.7319495654151345
454.70000000000573,50.965420868651464,0.16185649045729295,-1.7366724988415463
455.80000000000575,51.07241420545262,0.16523500561392135,-1.7413753332391537
456.9000000000058,51.180576863876084,0.1630591425852459,-1.7472123990467199
458.0000000000058,51.288078348175596,0.16298559785851735,-1.751284989303716
459.1000000000058,51.396089449311056,0.16496144859436568,-1.7542781013392617
460.20000000000584,51.50440905176754,0.16503952139825312,-1.7570172933920642
461.3000000000058,51.612858919631904,0.16526659668488247,-1.7624601366812747
462.40000000000583,51.718974624996605,0.1607584047268218,-1.765189288956158
463.50000000000585,51.828388054300454,0.16013023366316548,-1.768168518459218
464.6000000000059,51.936109664262794,0.16143733181681547,-1.7707106813277749
465.7000000000059,52.043505905569404,0.15723269921891764,-1.7749700600944296
466.8000000000059,52.152528312337445,0.15641471886568653,-1.7776090203346966
467.90000000000595,52.258363509578224,0.15449655562298548,-1.77888169591375
469.0000000000059,52.366831350731886,0.15178169974890937,-1.780228827094966
470.10000000000593,52.47768856276667,0.15191160036209778,-1.783718751426059
471.20000000000596,52.585171333518396,0.1484340847810955,-1.7861170416758365
472.300000000006,52.694198439952146,0.14620438182987838,-1.7868765255654924
473.400000000006,52.802609487378525,0.14221495583170846,-1.790791965849357
474.500000000006,52.91123630821096,0.14137199546402895,-1.7909146413755104
475.60000000000605,53.018631193472686,0.13958382380959355,-1.7934232563612085
476.70000000000607,53.12762421452849,0.13685781143195924,-1.7958104605685872
477.8000000000061,53.23541770948802,0.1358057217235768,-1.796492030318272
478.90000000000606,53.34442980157109,0.13274213062229417,-1.79747008563894
480.0000000000061,53.45255500619516,0.13081972880566506,-1.7987191797082667
481.1000000000061,53.55907718205093,0.12867025751606237,-1.8001064135307274
482.2000000000061,53.66952195164143,0.12975095385042473,-1.8014300186342522
483.30000000000615,53.77791355408525,0.12557223169639647,-1.8027175139556602
484.4000000000062,53.885183542925105,0.12297966509528369,-1.8065959019117153
485.5000000000062,53.994449338451545,0.12107633792337125,-1.8054895614174278
486.60000000000616,54.1028004451295,0.11890280928112679,-1.8058255880311673
487.7000000000062,54.21010526834691,0.11550950443207136,-1.8087799951034973
488.8000000000062,54.319256356760384,0.11809997344829065,-1.807460092586906
489.90000000000623,54.42827358137759,0.11439660628363402,-1.8087365310042598
491.00000000000625,54.53576761117509,0.11414942227017649,-1.8102211310400276
492.1000000000063,54.6449081615777,0.11360110273390212,-1.8114096587026736
493.2000000000063,54.75320180772219,0.11245505415157048,-1.812742137116261
494.3000000000063,54.861470994028785,0.11322731476246328,-1.8140481782275182
495.40000000000634,54.97090610185089,0.11266975686157876,-1.815370014084556
496.5000000000063,55.076584843945426,0.11107559296107145,-1.8153659847966677
497.60000000000633,55.187353169033976,0.10934931709754953,-1.816604841158969
498.70000000000636,55.29525892239859,0.10728213033591893,-1.8179999989376547
499.8000000000064,55.40425835914227,0.10753758842921068,-1.8173547540670452
500.9000000000064,55.51242124704184,0.10765476565547233,-1.8186705022599887
502.0000000000064,55.61963955193584,0.10769788794867824,-1.8199899426028683
503.10000000000645,55.728765484586276,0.10656243433840307,-1.8212999992273944
504.2000000000064,55.83728279517229,0.10533295285514022,-1.8212997786747867
505.30000000000643,55.945993536603744,0.10490013110636459,-1.8226199924637645
506.40000000000646,56.05408929748247,0.10545538536785731,-1.8228906913854344
507.5000000000065,56.162727042977934,0.10297581158913421,-1.8245753208507134
508.6000000000065,56.26958887606978,0.10311121632654263,-1.824587232234006
509.7000000000065,56.380245051954674,0.09943321523113424,-1.8268995500592227
510.80000000000655,56.489079542077256,0.10081807455564595,-1.8269098085100617
511.90000000000657,56.59828565459263,0.10032330257661348,-1.828215983771794
513.0000000000066,56.70664152522256,0.09775520188519576,-1.8296348710716934
514.1000000000065,56.816206613889634,0.09753717553617808,-1.830862556742976
515.2000000000066,56.92516822721619,0.09716741223586639,-1.8308580824693883
516.3000000000065,57.034599258175284,0.09538953544622802,-1.833433740452521
517.4000000000067,57.14276421883201,0.09466064946262365,-1.832170760836922
518.5000000000066,57.25170099473212,0.09416922561170499,-1.8348097489418134
519.6000000000067,57.35948648940818,0.09373092547884054,-1.8348139651907238
520.7000000000066,57.469272298630415,0.09465452794761708,-1.8361202847475822
521.8000000000067,57.578461334741995,0.09277493286744254,-1.8388557294056538
522.9000000000067,57.687414434411906,0.09148767229182853,-1.8377265581135531
524.0000000000067,57.79363270973455,0.09062446930189016,-1.8396312176359282
525.1000000000067,57.90578292503606,0.0898068050220781,-1.8399913928630949
526.2000000000068,58.014185533195175,0.08966666885458918,-1.8413882579958027
527.3000000000068,58.12209965719022,0.08838049373070578,-1.841420812917887
528.4000000000068,58.23143903041511,0.08885632447704789,-1.8433634332581468
529.5000000000068,58.340485200709765,0.08699345198705166,-1.8449929534509981
530.6000000000068,58.4460937195305,0.08943493167937988,-1.8463345937453663
531.7000000000069,58.55773791702928,0.088726629557901,-1.846323400021622
532.8000000000068,58.665429916832196,0.0866175220677618,-1.8480567617859602
533.9000000000069,58.77459969695406,0.08808743186934459,-1.8496201255374745
535.0000000000068,58.88388120659545,0.08836364140907038,-1.8496444488992267
536.100000000007,58.9925909082368,0.09000547630044292,-1.8509754195668897
537.2000000000069,59.10071357708566,0.08785176892437435,-1.853235390600541
538.300000000007,59.21027684885135,0.0900388547658989,-1.8545644800013394
539.4000000000069,59.32031641389659,0.0869913598807347,-1.8572049085440945
540.5000000000069,59.428894420162855,0.08889104155007654,-1.8571999951860763
541.600000000007,59.538284175926506,0.08926856552549778,-1.859783503334051
542.700000000007,59.6483163043103,0.08705391270114704,-1.862438054022011
543.800000000007,59.75509183312214,0.08751386283508733,-1.8624661114074565
544.900000000007,59.86635965032209,0.08971671967321154,-1.8639878610935572
546.000000000007,59.97524272493032,0.08874734126044898,-1.8665999379183744
547.1000000000071,60.08479010883409,0.08923290583983584,-1.8692947275757712
548.2000000000071,60.193946324478816,0.09192858635841972,-1.870584539644073
549.300000000007,60.304029924102814,0.09281467213019495,-1.8718583503435404
550.4000000000071,60.412687385457204,0.09287001315996557,-1.8745111366293328
551.500000000007,60.52188892824688,0.09287870848846658,-1.8758269114365924
552.6000000000072,60.63193679072275,0.09292045531111814,-1.8785126546290982
553.7000000000071,60.74073538725146,0.0921616055323709,-1.8811471758711615
554.8000000000072,60.85064923121325,0.09078137927220192,-1.8837665920829005
555.9000000000071,60.95966092270376,0.09163655693797434,-1.886403449573824
557.0000000000072,61.069170000000696,0.09119031773412423,-1.889027336071977
558.1000000000072,61.178766010624734,0.09274393645834134,-1.8903234751588651
559.2000000000072,61.28835749235575,0.09261858761023051,-1.8929855380614846
560.3000000000072,61.39707015110684,0.0953290932951461,-1.895634365449581
561.4000000000073,61.50595239580599,0.09468673611917122,-1.8985012335899039
562.5000000000073,61.615343370101336,0.09490102083340235,-1.9022374306942988
563.6000000000073,61.72525840345431,0.09422297989425998,-1.9042482979484152
564.7000000000073,61.83433568963431,0.09532323026789258,-1.9081778935272946
565.8000000000073,61.94313362393579,0.09572321242624021,-1.9103759373834692
566.9000000000074,62.05098879817477,0.09614593668187232,-1.9129763214695323
568.0000000000074,62.161933004493434,0.09497884457422417,-1.9172519368587047
569.1000000000074,62.27099278623396,0.09487164499271894,-1.9210883345545038
570.2000000000073,62.38101762673876,0.09403410965472081,-1.923025163854954
571.3000000000073,62.48989503228797,0.09600535403646626,-1.9251930770455132
572.4000000000074,62.599270710607314,0.09439031365658856,-1.929335627720301
573.5000000000074,62.70947666421641,0.09665257196701077,-1.933385006083712
574.6000000000074,62.81758858851602,0.09284369589606695,-1.935920276743508
575.7000000000074,62.928790805818,0.09208319417968175,-1.9386596732119759
576.8000000000075,63.0368362403751,0.0922727543754569,-1.9413181144700955
577.9000000000075,63.14600371235157,0.09147279364314032,-1.9451918012460676
579.0000000000075,63.25539335772432,0.0885489424437827,-1.9480252328703553
580.1000000000075,63.36584192855806,0.09102975813417213,-1.9489172878062315
581.2000000000075,63.47563017387582,0.09204820667142588,-1.9520553379530994
582.3000000000076,63.58592337364876,0.09196996667889729,-1.9543235953407416
583.4000000000076,63.69532711971373,0.09289075754372361,-1.9560097978538646
584.5000000000076,63.804215601695155,0.09557695641265773,-1.9583082570938748
585.6000000000076,63.913942135805804,0.10272779489408704,-1.9584184660648534
586.7000000000077,64.02307341617951,0.1099450508508035,-1.960912920704263
587.8000000000077,64.13227758168647,0.11944055968275585,-1.9609033971754393
588.9000000000076,64.24256712732989,0.11937812364603878,-1.9622496966260714
590.0000000000076,64.3508139304262,0.12298618699334388,-1.9623261969152574
591.1000000000076,64.4602793644835,0.12203324587849976,-1.9635684900392274
592.2000000000077,64.57044428469104,0.12099054947248933,-1.9635831326595317
593.3000000000077,64.6804379350992,0.12080558598422503,-1.9662131571377182
594.4000000000077,64.78897777525391,0.12068949720545358,-1.9662199956525876
595.5000000000077,64.89946515989396,0.12209859258883107,-1.9662148031551396
596.6000000000078,65.00897563999118,0.11765944546934154,-1.9675300078152635
597.7000000000078,65.11897072428589,0.11198592292869713,-1.9688579603175236
598.8000000000078,65.22813822361834,0.1127139380115903,-1.9678715561504956
599.9000000000078,65.33835718033365,0.10953552355488852,-1.9691813461358691
601.0000000000078,65.44906724097665,0.11212578448804458,-1.9714895372082792
602.1000000000079,65.55845262176365,0.10892981348463451,-1.9728268753285754
603.2000000000079,65.6682228944137,0.11039926069387734,-1.9733066881819328
604.3000000000079,65.77788305539251,0.11459268296656655,-1.9729981968215067
605.4000000000078,65.88825846751472,0.11693811063319459,-1.9727642717307767
606.5000000000078,65.99751741089423,0.12049224607038161,-1.9741269416729246
607.6000000000079,66.10785259349409,0.12205973154822636,-1.9767515641036786
608.7000000000079,66.21648884242589,0.12733259997164206,-1.9767479147106615
609.8000000000079,66.32677498897704,0.13144480971619438,-1.979384000680942
610.9000000000079,66.43711589978015,0.13839697432367867,-1.979441962954727
612.000000000008,66.54672781589012,0.14306346711019494,-1.9806999532490552
613.100000000008,66.65665145117181,0.15015604948253813,-1.9833583894455207
614.200000000008,66.76668894132416,0.15875165390015522,-1.9815569003404754
615.300000000008,66.87443074209337,0.1658599448125857,-1.9823410816189186
616.400000000008,66.98514691516411,0.17246959960431238,-1.9849871929591614
617.5000000000081,67.0951761891482,0.17938736641784156,-1.986288093189538
618.6000000000081,67.20517925606644,0.18958428796220073,-1.987621006715325
619.7000000000081,67.31483205080283,0.1958330491038729,-1.9900333952638363
620.8000000000081,67.42374605981223,0.20279843321998972,-1.991666879227123
621.9000000000082,67.53415084248483,0.21048358373169507,-1.9925608763258849
623.0000000000082,67.64302077429075,0.22316379704048964,-1.9941865241451775
624.1000000000081,67.75373376886903,0.23294031493034917,-1.995517179073015
625.2000000000081,67.8633895538838,0.2474018271341678,-1.9968813107303482
626.3000000000081,67.97229890220076,0.2572304766515987,-1.9995943307210902
627.4000000000082,68.08162605997362,0.2648639137056051,-1.9995057554482458
628.5000000000082,68.19121885858483,0.28069183930073527,-2.002111254146985
629.6000000000082,68.30115420808592,0.2896002232206712,-2.0061217704901564
630.7000000000082,68.41082658919088,0.3008556270453533,-2.006172999494033
631.8000000000083,68.52058867942111,0.31253006878881745,-2.0089050936376527
632.9000000000083,68.6299247279046,0.3246443061956186,-2.013000063026804
634.0000000000083,68.73877815587869,0.3414960637721053,-2.015598402753916
635.1000000000083,68.84853376429649,0.3537175074806096,-2.017206445537106
636.2000000000083,68.95927059494232,0.3698544137889498,-2.018253740170973
637.3000000000084,69.06887018264274,0.3806274823394648,-2.023738916446888
638.4000000000084,69.17846640891658,0.3948434524523241,-2.0251359948276058
639.5000000000084,69.28761280506016,0.4095166324285139,-2.027720784971362
640.6000000000083,69.39795413077171,0.42477201161121203,-2.031954363521715
641.7000000000083,69.50806427823264,0.43740900598496457,-2.035855337664596
642.8000000000084,69.6179429226199,0.4546591779766298,-2.0389128807660573
643.9000000000084,69.72775446314353,0.46860197189445735,-2.041654577809565
645.0000000000084,69.83789314478138,0.4858817971069069,-2.0446934911623305
646.1000000000084,69.94743547877678,0.5041039036087391,-2.0490907785723564
647.2000000000085,70.05543754356117,0.5187490996029205,-2.0532897414565343
648.3000000000085,70.16763379257739,0.535270228989908,-2.0560786938228723
649.4000000000085,70.2770375708563,0.5514095388366577,-2.0618833720967977
650.5000000000085,70.3871846518927,0.5677799206676613,-2.064720758637542
651.6000000000085,70.4965538460286,0.5873859029921229,-2.0681820648174103
652.7000000000086,70.6085540461666,0.6049663824928878,-2.073179940451002
653.8000000000086,70.71878302121748,0.6219686964821352,-2.078207568896797
654.9000000000086,70.82756925133322,0.6387222372181033,-2.0825621809496373
656.0000000000086,70.93793909759725,0.6565323822850349,-2.087105682171693
657.1000000000087,71.04842617147304,0.6736104828234173,-2.091697737950222
658.2000000000087,71.15927364867834,0.6909017917286283,-2.0973003266846746
659.3000000000086,71.26948369214786,0.7107521639070025,-2.1034642145234965
660.4000000000086,71.37959898291746,0.7245701600026663,-2.108619589820938
661.5000000000086,71.48956624564767,0.7425623375929812,-2.1146650235885307
662.6000000000087,71.59956885229187,0.7617320403311608,-2.118362948463468
663.7000000000087,71.71034271940648,0.7787765928994272,-2.1255098655098426
664.8000000000087,71.81955926347682,0.7980666476605858,-2.1329112561614627
665.9000000000087,71.92938234318909,0.8106795270962515,-2.136053897279427
667.0000000000088,72.03946008931594,0.830958801537496,-2.143980176902545
668.1000000000088,72.14962043251717,0.8481646060835555,-2.149603324350838
669.2000000000088,72.25991357407166,0.8642030148587923,-2.156863522697229
670.3000000000088,72.36977674652786,0.8801306675569518,-2.163005195215951
671.4000000000088,72.4801701833553,0.89035066088213,-2.169585807972254
672.5000000000089,72.58995296910926,0.9013945106914962,-2.1756673913434943
673.6000000000089,72.70035010363678,0.9125277995941754,-2.1836346966748104
674.7000000000089,72.81039109179038,0.9204102808768897,-2.190046902465052
675.8000000000088,72.92035541044008,0.9271053611085822,-2.1980401655153803
676.9000000000088,73.0301650366019,0.9310740966269033,-2.203911132814891
678.0000000000089,73.13982362338406,0.9301269283301434,-2.2102877038169852
679.1000000000089,73.24860199618224,0.9259605967348369,-2.2187001251279925
680.2000000000089,73.36076729416985,0.9219848877341883,-2.2230543810430543
681.3000000000089,73.47059054039967,0.9124488483279989,-2.2296481480011012
682.400000000009,73.58128169542015,0.8989568429315857,-2.2380108287579628
683.500000000009,73.69138330179369,0.8866391831490776,-2.244234349260936
684.600000000009,73.80150740155717,0.8794518150917066,-2.2497190713314144
685.700000000009,73.91218500511549,0.885477384708188,-2.2565122641520805
686.800000000009,74.02182778291468,0.9080198104469881,-2.2618058447881957
687.9000000000091,74.13198156937565,0.9450202123922011,-2.2691185681633708
689.0000000000091,74.24161486574147,0.9879068558183155,-2.2762470818383296
690.1000000000091,74.35213082166631,1.0432756398238094,-2.282848440458422
691.2000000000091,74.46296847841555,1.090872535060639,-2.2906246616298986
692.3000000000092,74.57211777985322,1.1399683458859704,-2.2971072195458815
693.4000000000092,74.68281641774995,1.1900759417551199,-2.3056025523433235
694.5000000000091,74.79322446011314,1.2389179514063826,-2.316073639041801
695.6000000000091,74.90352343773773,1.287964014896008,-2.3245292960442607
696.7000000000091,75.0135459455883,1.3313766374976703,-2.333828898386162
697.8000000000092,75.1238578305533,1.3789759265992112,-2.3436432507098623
698.9000000000092,75.23429727849864,1.4184168798224916,-2.3521904838592778
700.0000000000092,75.3447595066341,1.46695160558268,-2.362877076301279
701.1000000000092,75.45460704988156,1.5110699943435535,-2.373648240378265
702.2000000000093,75.56568959487855,1.5559707777029583,-2.3844747298904636
703.3000000000093,75.67649150007628,1.5923863354761267,-2.3960582773310337
704.4000000000093,75.78642819961895,1.6345430036529196,-2.40745744327429
705.5000000000093,75.89472614803438,1.670167465619782,-2.4177247084720572
706.6000000000093,76.00671772689482,1.7108626486870055,-2.4290111521401796
707.7000000000094,76.11784910873766,1.7527500978726047,-2.4422999251735407
708.8000000000094,76.22793295662967,1.7856271779145982,-2.4525890674409383
709.9000000000094,76.33936803392035,1.819750970423279,-2.4663984271572996
711.0000000000093,76.44917000000095,1.846341360473699,-2.480167786511024
712.1000000000093,76.56222183075849,1.8735434599293246,-2.4925031462688296
713.2000000000094,76.66938922524855,1.9042875631438518,-2.5056039286893665
714.3000000000094,76.78196752426024,1.9255914064417363,-2.519378273659956
715.4000000000094,76.89259545895165,1.9493577296297138,-2.5328940109901104
716.5000000000094,77.00339092068407,1.9744250265656844,-2.546433047049173
717.6000000000095,77.11290908605211,1.9965706708405144,-2.561305056389641
718.7000000000095,77.22413138548538,2.015930930789052,-2.5737006196615773
719.8000000000095,77.33469308203415,2.0356016032175055,-2.5883199169572
720.9000000000095,77.4451407263381,2.0537631373958587,-2.601343479738823
722.0000000000095,77.55582744745097,2.0687684131899227,-2.615715106872213
723.1000000000096,77.6659235087806,2.0854574225132207,-2.6295250322085826
724.2000000000096,77.77652511080315,2.0974205210964154,-2.6451082382723814
725.3000000000096,77.88642428672132,2.0972765679634082,-2.6592638261680692
726.4000000000096,77.99649804100177,2.0870749218403484,-2.674348334580152
727.5000000000097,78.10657187017269,2.068131766930619,-2.6897223740199356
728.6000000000097,78.21732935017376,2.040850601419805,-2.702554558033381
729.7000000000096,78.32694959947857,1.9950211758670584,-2.715484725873851
730.8000000000096,78.43684542447525,1.931566767847983,-2.729645202773612
731.9000000000096,78.54702339635732,1.8292085233897655,-2.742643884188862
733.0000000000097,78.65815395769894,1.6726730299836858,-2.755296805437683
734.1000000000097,78.76738405141799,1.40428107774457,-2.765065807928914
735.2000000000097,78.87734908390591,0.8325380505629245,-2.7733387247946335
736.3000000000097,78.98600102151413,0.3192836168630827,-2.7776693982453367
737.4000000000098,79.09645994781091,0.12682484880549474,-2.779160007541945
738.5000000000098,79.20622400814759,0.05529535634245908,-2.7791486478806893
739.6000000000098,79.31629861790113,0.02554364132908432,-2.7804701488356613
740.7000000000098,79.42770086494906,0.012227195714112682,-2.780470342141581
741.8000000000098,79.53839298455419,0.006097998709529151,-2.779049620134848
742.9000000000099,79.64809099615007,-0.0001163912795069666,-2.7819000821832476
744.0000000000099,79.75936470157119,-0.005962503030112587,-2.7812506073632584
745.1000000000099,79.86998978911562,-0.008924610574053693,-2.7805899081922645
746.0000000000099,79.9601477560871,-0.0073485144036826155,-2.781583082821121