File: 01_Data/Rug_Pad/STA/N2/10K_min/Rug_Pad_STA_N2_10KData_221025_R3.csv
##Temp./Â°C,Time/min,DSC/(mW/mg),Mass loss/mg
51.0,10.707199887509569,0.014505835316208193,-0.01602628116119753
52.100000000000016,11.108489617138899,0.05732244482441651,-0.013201877202257073
53.20000000000003,11.361855437676677,0.08310314764431648,-0.013556435467716454
54.30000000000005,11.572383215306337,0.10473662754143587,-0.013311296440353004
55.40000000000006,11.758887290404738,0.12102389906183819,-0.014428175101047103
56.50000000000008,11.930731882403395,0.13510463962111507,-0.013340490320887355
57.600000000000094,12.092574939360228,0.14557736095899698,-0.01322518289919472
58.70000000000011,12.249869648899056,0.15141210001935135,-0.013505379250570826
59.800000000000125,12.40095785763795,0.15947486896674845,-0.013416108884825917
60.90000000000014,12.545695866566026,0.1644758481360613,-0.01268369733808239
62.000000000000156,12.68815432690021,0.16742098156984353,-0.013278142999197051
63.10000000000017,12.827242557235566,0.17468471084876858,-0.014517591224874948
64.20000000000019,12.965620932546175,0.17946512786174784,-0.01518660173574915
65.30000000000021,13.102860666404649,0.1849257115844809,-0.01403657358544308
66.40000000000022,13.232444816485865,0.18779974003423017,-0.01467497517434957
67.50000000000023,13.365398945631012,0.19333421925934702,-0.01503233530362369
68.60000000000025,13.493914717323243,0.19587442712185243,-0.015378418831331508
69.70000000000027,13.624353322863126,0.19781316051850517,-0.01580814935582442
70.80000000000028,13.752585434444864,0.2039170765438001,-0.015591181452192515
71.90000000000029,13.87701756816816,0.20858818101640852,-0.015544895072681975
73.00000000000031,14.001010659849564,0.21012675782189616,-0.015601021434203055
74.10000000000034,14.124701376699587,0.2153261368605257,-0.015591469321656781
75.20000000000034,14.247645015446675,0.21546191911460544,-0.01589343349680572
76.30000000000035,14.370774565928654,0.21909988115450485,-0.01650511764703655
77.40000000000038,14.490348481846137,0.221707955997262,-0.016935436336540377
78.5000000000004,14.611296108933256,0.2239635436177072,-0.018151505928344136
79.6000000000004,14.728995078913812,0.22524747210489826,-0.01750668016839274
80.70000000000041,14.848783500075836,0.2270264204654715,-0.018322648750110915
81.80000000000044,14.96638759461837,0.228961010042245,-0.018005965518738343
82.90000000000046,15.082571513645648,0.2310362243987364,-0.016917099316827944
84.00000000000047,15.200107858772304,0.23185468541779175,-0.018335649106035135
85.10000000000048,15.315144115325806,0.23249803698941807,-0.018316959809780542
86.2000000000005,15.43095290549243,0.233087218293077,-0.017024158798417233
87.30000000000052,15.544101865634833,0.23430482651239404,-0.018372354602265162
88.40000000000053,15.658573562038798,0.2367585891342544,-0.01833306686997993
89.50000000000054,15.769416215772189,0.23832585731187772,-0.01834090607681471
90.60000000000056,15.884639195727065,0.2390879810123837,-0.01965155096083393
91.70000000000059,15.9985319622923,0.24053560689237985,-0.01844979600148733
92.8000000000006,16.10989745096459,0.23992311893705642,-0.019652902377698567
93.9000000000006,16.21969707902299,0.24305308493932198,-0.0196520347704352
95.00000000000063,16.3324981954855,0.24335038089553707,-0.0209797786517516
96.10000000000065,16.44281791681916,0.24311305274356632,-0.019658709384968276
97.20000000000066,16.552760416128137,0.24304083801023513,-0.01964537753036666
98.30000000000067,16.663692650963423,0.24492717922622786,-0.019329814240435006
99.40000000000069,16.77253793846221,0.2468191678060575,-0.01964472480725732
100.50000000000071,16.878819006625108,0.2469508192615617,-0.01967991180098405
101.60000000000072,16.99202687938941,0.2474675233195882,-0.01959940374248248
102.70000000000073,17.100098333412987,0.24893873149322465,-0.019660853696092495
103.80000000000075,17.20978614227861,0.248886081599062,-0.020955413573096493
104.90000000000077,17.31864522840939,0.249759227269994,-0.020966544932366382
106.00000000000078,17.42655768865511,0.24957772308789217,-0.020982590813527047
107.10000000000079,17.533188732897955,0.25021963055185503,-0.020988179842990284
108.20000000000081,17.64294682460294,0.25065857241715683,-0.022290070893975056
109.30000000000084,17.75130782645263,0.2545362271769507,-0.022272314203499732
110.40000000000084,17.85646448761261,0.25280652730982567,-0.020967667472663543
111.50000000000085,17.967698751582052,0.2551531881847664,-0.021113641187533005
112.60000000000088,18.07586270862487,0.25321880471097735,-0.022290570933047427
113.7000000000009,18.183268449769603,0.25521725079013124,-0.021644704108206625
114.8000000000009,18.2900000000001,0.2571834468404698,-0.023603333339592858
115.90000000000092,18.39807468241024,0.2579616356378822,-0.022693341420558788
117.00000000000094,18.506373562224148,0.25688265073495964,-0.02229826489331721
118.10000000000096,18.613454897217633,0.2592064211716255,-0.022290149160380857
119.20000000000097,18.72061101650866,0.2572098020453446,-0.020976398919061445
120.30000000000098,18.827080362422148,0.257425169125699,-0.022288366723979713
121.400000000001,18.93435174171832,0.25887448869614893,-0.02360989291833704
122.50000000000102,19.040426443625577,0.2598417496801463,-0.022290098478416454
123.60000000000103,19.149097223443018,0.26124268645471316,-0.02225480989227613
124.70000000000104,19.255753724564034,0.2611535059730966,-0.02230012224689837
125.80000000000106,19.3609407874796,0.2603646858074874,-0.023598615503292564
126.90000000000109,19.466761799701874,0.2622381022338234,-0.02360991587041994
128.00000000000108,19.57273660289004,0.26399504127692697,-0.02222166690086702
129.1000000000011,19.67685192931757,0.2658975773063068,-0.022218961811885762
130.20000000000113,19.785341362501583,0.2665335965628842,-0.024526190668469283
131.30000000000115,19.892738851713595,0.26717675774167615,-0.023609928987451845
132.40000000000117,19.99923750937625,0.2677252907096107,-0.023372379723128667
133.50000000000117,20.104932455389935,0.26889658133893557,-0.024293667696545285
134.6000000000012,20.209804436063603,0.2686024130625231,-0.02492865630513208
135.7000000000012,20.31639857118901,0.27133728142897107,-0.023606761504630036
136.8000000000012,20.42112468579649,0.2736753656196369,-0.023587527199576463
137.90000000000123,20.527144527026454,0.27231271702168314,-0.02362878173444294
139.00000000000125,20.632179461636056,0.2731262085869114,-0.02492978071809482
140.10000000000127,20.737132715586448,0.27286620179541954,-0.024920770321639196
141.2000000000013,20.842847950027064,0.2752713180580886,-0.02558420167790665
142.3000000000013,20.948416427003835,0.2743075292162195,-0.025584710915257602
143.4000000000013,21.054167583657105,0.27450698926916006,-0.02626346369200938
144.50000000000134,21.15910234098302,0.27654920393161175,-0.02624976465378559
145.60000000000133,21.263235936213416,0.2767359761808167,-0.025923701838513225
146.70000000000135,21.368950107302563,0.2760549249452131,-0.02595268501637893
147.80000000000138,21.473435283003823,0.2767621924599656,-0.0263716590978893
148.9000000000014,21.577648036721964,0.27500178392528984,-0.02722227199187266
150.00000000000142,21.68351119690845,0.27742040606463036,-0.02761369162237859
151.10000000000142,21.788582297788277,0.27789612991119417,-0.027560535215471305
152.20000000000144,21.89258729869243,0.2761126055034392,-0.027566726939725505
153.30000000000146,21.996568114897954,0.2789232349179255,-0.02887764397224757
154.40000000000146,22.101240623380207,0.278011376657595,-0.02755340947126328
155.50000000000148,22.207498452022058,0.27936987722116524,-0.027889925285427886
156.6000000000015,22.311641563820597,0.28000629349191386,-0.028727727079032483
157.70000000000152,22.416274945889274,0.28035733535298846,-0.029209945688196903
158.80000000000155,22.52056571918245,0.28221819524299807,-0.029688411269070514
159.90000000000154,22.624744177626923,0.2814964385987857,-0.029210167845226565
161.00000000000156,22.729739618618655,0.28312532138797963,-0.029210169388824703
162.1000000000016,22.834110363845273,0.28350654589754753,-0.029841590598223
163.20000000000158,22.939238142222802,0.2842276151060017,-0.030505033205680654
164.3000000000016,23.043614195129102,0.2825146390626255,-0.029199328773828803
165.40000000000163,23.146304520992306,0.2815747113541225,-0.030520912549950374
166.50000000000165,23.252739494038565,0.27978682846901104,-0.030530124393150615
167.60000000000167,23.356055888046416,0.2804902981604952,-0.03053001999980154
168.70000000000167,23.460648020684285,0.282994519015082,-0.0305300200003229
169.8000000000017,23.565541194787983,0.2798295776494272,-0.030530468739469185
170.9000000000017,23.670449638113308,0.2802019636953833,-0.03091041879617773
172.0000000000017,23.77467684490539,0.2804187333228886,-0.03216987030988783
173.10000000000173,23.878671015647857,0.28181622139980633,-0.03348747717505507
174.20000000000175,23.98266848242837,0.28239882985983555,-0.033150352366675406
175.30000000000177,24.086935263635745,0.28204887451047234,-0.032170076400736214
176.4000000000018,24.192419723183324,0.2810321788820518,-0.03215702862581438
177.5000000000018,24.29705833186434,0.2822266034173069,-0.033160338218961805
178.6000000000018,24.4008768679377,0.2820157209429798,-0.03448043876813589
179.70000000000184,24.50543248130093,0.28389454793370406,-0.0341500340853349
180.80000000000183,24.609543693055816,0.2823875344496789,-0.03284381253004742
181.90000000000185,24.71315340760908,0.2860170057999851,-0.03530745735411589
183.00000000000188,24.815009769928636,0.28590741484036886,-0.035460065867205515
184.1000000000019,24.92259487167907,0.2857373756097906,-0.03414071973236865
185.20000000000192,25.026155533329096,0.28539077131374924,-0.03545981962957612
186.30000000000192,25.131078961293884,0.2866103262770089,-0.035459655092506814
187.40000000000194,25.235069869580112,0.28752055325427384,-0.03678011913885104
188.50000000000196,25.339472024499727,0.28852152500330785,-0.037745582491774954
189.60000000000196,25.44303176967838,0.2907860003843643,-0.03776039424301825
190.70000000000198,25.547868455641762,0.2897750888285716,-0.03809989177345319
191.800000000002,25.65219121405214,0.292810461751506,-0.03941153014921106
192.90000000000202,25.757648523360764,0.289877613885732,-0.03940967076274671
194.00000000000205,25.86046100461342,0.29310698006369273,-0.04006995364972532
195.10000000000204,25.965702865733782,0.2933779348838747,-0.0404912951396037
196.20000000000206,26.07026665788189,0.29384161924790486,-0.040079548740815873
197.3000000000021,26.174330880001797,0.29317480256633693,-0.04138999451139913
198.40000000000208,26.27891464169199,0.2939419202098522,-0.04202578749918562
199.5000000000021,26.38063283291008,0.2945785870820204,-0.04204982980598526
200.60000000000213,26.486655001732608,0.29515014644731574,-0.04218289975682055
201.70000000000215,26.59188988486417,0.29624107008411243,-0.0443490951835015
202.80000000000217,26.695692687516672,0.2963853718346916,-0.04469003065028865
203.90000000000217,26.79990189765826,0.29726080751000605,-0.0446839670684307
205.0000000000022,26.903480396074777,0.29818518589266974,-0.0460000296092149
206.1000000000022,27.008278098771942,0.30037469027010044,-0.045949778541947595
207.2000000000022,27.112840499512824,0.3008205683325312,-0.04699018029769064
208.30000000000223,27.216858541892655,0.3029363007978017,-0.04754752438954135
209.40000000000225,27.320614976933964,0.30403203156804204,-0.04831018512312557
210.50000000000227,27.425158016342642,0.30546455277494194,-0.04937285326884666
211.6000000000023,27.530093034994728,0.30659327882187537,-0.05029377451731687
212.7000000000023,27.633805865629714,0.3075923186241403,-0.050619683258638304
213.8000000000023,27.735490087589863,0.30806082042004423,-0.052600204667115236
214.90000000000234,27.842982174602685,0.309189901820474,-0.05260002000175934
216.00000000000233,27.94732649310314,0.30903150026966314,-0.0526017541039554
217.10000000000235,28.051375833533747,0.3103872974143386,-0.05390995872218696
218.20000000000238,28.15601489571432,0.31194442754631363,-0.05522377027183456
219.3000000000024,28.259736448045803,0.311981304244753,-0.056208731844254345
220.40000000000242,28.364593262805876,0.3126018965213093,-0.057096314285175254
221.50000000000242,28.46778836038883,0.31344739575403635,-0.057860081317628875
222.60000000000244,28.57256220947442,0.3137572763256535,-0.05883200739100225
223.70000000000246,28.677028105476598,0.3148833513977577,-0.059882718235960475
224.80000000000246,28.782303290984704,0.3179000607392548,-0.0618201084697283
225.90000000000248,28.886548768721045,0.3188465954808593,-0.0631292627852682
227.0000000000025,28.99141669299501,0.3211717636164079,-0.06313010153033538
228.10000000000252,29.095172872564753,0.32200660564572975,-0.06573968774424177
229.20000000000255,29.199274800547606,0.32534283977370954,-0.06708009901307221
230.30000000000254,29.30465852550865,0.32734827191215726,-0.06710006340744634
231.40000000000256,29.409387702417632,0.3297977034423091,-0.06840554870596538
232.5000000000026,29.513608350750363,0.33128165157944617,-0.07070025286513193
233.60000000000258,29.6180693221764,0.3338406982787969,-0.07122874005594682
234.7000000000026,29.722882940861357,0.335106351394502,-0.07249032930850863
235.80000000000263,29.827394649425948,0.33690706748606924,-0.074986932740436
236.90000000000265,29.931736210007177,0.3364207788372866,-0.07629828956363127
238.00000000000267,30.03592333148494,0.33891467838665634,-0.07890708729547402
239.10000000000267,30.140749171362433,0.340084412621843,-0.07894085293154163
240.2000000000027,30.24516672420451,0.34096236327257157,-0.0793555312685239
241.3000000000027,30.350648814225835,0.3416999882689013,-0.08191024288523696
242.4000000000027,30.454489311853493,0.34298961240650194,-0.08553223724031511
243.50000000000273,30.558682703657706,0.3453968451756386,-0.08584975571139797
244.60000000000275,30.661451352055487,0.3489398224354006,-0.08718162245646344
245.70000000000277,30.76897602844993,0.35134126361882123,-0.08848726445869914
246.8000000000028,30.87387440128515,0.35558268844059426,-0.08979720480659381
247.9000000000028,30.977867401755304,0.36234254733407895,-0.09381109748625605
249.0000000000028,31.08268742050875,0.3700853674220075,-0.09370012156549734
250.10000000000284,31.186903999164812,0.38270778130953,-0.0951081767476305
251.20000000000283,31.292114894361227,0.40663159787727937,-0.097696183420239
252.30000000000285,31.396589320576965,0.430008241224281,-0.10027397054606535
253.40000000000288,31.501221675158554,0.44867418017953264,-0.10167940685545762
254.5000000000029,31.606730864294146,0.45622018460322306,-0.10429047661266555
255.60000000000292,31.71138331244343,0.4426331877008135,-0.10560611673909737
256.7000000000029,31.816820512003858,0.4217724193110606,-0.10693736273057208
257.8000000000029,31.920875241731093,0.39903368972029,-0.10956862540557699
258.90000000000293,32.025085254894165,0.3836483425386559,-0.11083519996624913
260.00000000000296,32.13017851337712,0.36853289966178265,-0.11291059729763608
261.100000000003,32.23505288607128,0.3590064508577954,-0.11619822092948917
262.200000000003,32.33954263608966,0.3513495439926345,-0.11890112638873962
263.300000000003,32.4446157897451,0.3465863055351728,-0.12027492372466408
264.40000000000305,32.5489021500536,0.3448534300258221,-0.12284289350885391
265.50000000000307,32.65105857268399,0.34203589208023066,-0.12425546797031783
266.6000000000031,32.75702078073684,0.34004578881614067,-0.12809796652355931
267.7000000000031,32.86282001270037,0.33987577517031015,-0.13062037375464008
268.8000000000031,32.96757438412395,0.33944913568008117,-0.13202594611368657
269.9000000000031,33.072041032304156,0.339988058573834,-0.1358782058676553
271.0000000000031,33.177045995039286,0.33831988587264444,-0.1376633808101495
272.10000000000315,33.28104652473454,0.3381664072013512,-0.14032060515691303
273.2000000000032,33.38747020169202,0.33704765809653836,-0.14419127125584286
274.30000000000314,33.491263876895715,0.3365358991715453,-0.14707613612281234
275.40000000000316,33.59648429388103,0.3365881859036724,-0.15075553397428498
276.5000000000032,33.701229814030775,0.3340867543190186,-0.15456535562909357
277.6000000000032,33.80624135265376,0.3356194414206427,-0.15569929649239134
278.70000000000323,33.91120979258611,0.3352466773593589,-0.15978452090408712
279.80000000000325,34.01663318165495,0.33502780889179046,-0.162370497789476
280.9000000000033,34.121247250138204,0.3339203238910494,-0.16630887694163876
282.0000000000033,34.227098375745555,0.3338549661811707,-0.16948504451934365
283.1000000000033,34.33218370632519,0.33135723619716784,-0.17262454175974185
284.20000000000334,34.436272462062384,0.33252065948357284,-0.1761188475177864
285.30000000000337,34.54293506289056,0.3320645884058738,-0.17888614925159851
286.40000000000333,34.646985317174654,0.33058183605546376,-0.18235801512512895
287.50000000000335,34.75329353466735,0.3319308839211495,-0.18556960364205732
288.6000000000034,34.85812759890801,0.3284525554863215,-0.18949239848584565
289.7000000000034,34.963059814275255,0.32887588591740136,-0.19223913349227173
290.8000000000034,35.06849924843678,0.32707483779147567,-0.19486421858761815
291.9000000000034,35.171261356554396,0.32571563306679385,-0.19952804840007943
293.0000000000034,35.279814360806995,0.32464556628206476,-0.2032147150190844
294.10000000000343,35.38477122832543,0.3228606318497541,-0.20584649197864024
295.20000000000346,35.48960789567511,0.3219894727883716,-0.20899954232176388
296.3000000000035,35.59492714297344,0.3213093252994828,-0.2123370013579211
297.4000000000035,35.69969625166094,0.3205533458758401,-0.21625569922288834
298.5000000000035,35.8059353993375,0.32005089722503965,-0.21850340422226067
299.60000000000355,35.912332978620945,0.3190604829335062,-0.22202661376603894
300.70000000000357,36.01662941361502,0.31724456833547526,-0.22464231164432436
301.8000000000036,36.12207210614319,0.3171392937739005,-0.2264757457920097
302.9000000000036,36.22632530578736,0.31695797238798457,-0.2299211909130232
304.0000000000036,36.332616218284905,0.3142796793568031,-0.2329753995157784
305.1000000000036,36.43798983879677,0.3140418751926754,-0.23608635910551934
306.2000000000036,36.54341381602144,0.31220769832253725,-0.23934178856875654
307.30000000000365,36.648372693650636,0.31035197081242694,-0.2413115676951949
308.4000000000037,36.754471049716635,0.30853327890435384,-0.24489194657954938
309.5000000000037,36.85990482658278,0.3083616372549338,-0.24767186580943656
310.60000000000366,36.9651418547819,0.30599951450154766,-0.2503150074999829
311.7000000000037,37.0710983753775,0.30476929668908836,-0.2529482910416738
312.8000000000037,37.17649378746563,0.3019716381187434,-0.25560052684116075
313.90000000000373,37.28103188592644,0.30131362506161585,-0.25854567858277866
315.00000000000375,37.38764505761159,0.29945016890311893,-0.26184507864332307
316.1000000000038,37.49203174119413,0.2990211355142927,-0.2646266294359241
317.2000000000038,37.59874706269022,0.29439778152454316,-0.26734135100421375
318.3000000000038,37.704613817487356,0.2946425357148789,-0.2699860205067499
319.40000000000384,37.80990916820997,0.2915980478684485,-0.2726002245840671
320.5000000000038,37.91585340009132,0.2899561690810271,-0.2755620431584678
321.60000000000383,38.02222464005449,0.2861909559500522,-0.27796897130534814
322.70000000000385,38.1271660212384,0.28714794356806933,-0.28184460715822457
323.8000000000039,38.234532492781746,0.2833012072767038,-0.28632683884503374
324.9000000000039,38.340000923560645,0.27918335000052913,-0.288850195906341
326.0000000000039,38.44540996713115,0.2781700663570213,-0.2913904543262502
327.10000000000394,38.54991862835863,0.27640278600683443,-0.2950928352899047
328.2000000000039,38.656900883798976,0.2738619476892412,-0.2973776957705456
329.30000000000393,38.763475472819906,0.27127151041795877,-0.30076833853900453
330.40000000000396,38.86908355425437,0.2699673662233669,-0.3051115723409028
331.500000000004,38.97281209100233,0.27005339381099897,-0.3095101387700563
332.600000000004,39.081124277502134,0.2659575405772346,-0.3131186584326122
333.700000000004,39.185000940744,0.26356497447984206,-0.3162766901797398
334.80000000000405,39.29292125262289,0.2617371316793836,-0.3205764624941345
335.90000000000407,39.39854729576126,0.25891384932926476,-0.32550996750096806
337.0000000000041,39.504452190274826,0.25750902622235433,-0.33025933711725086
338.10000000000406,39.61028987938495,0.2561657206468031,-0.33333800804492153
339.2000000000041,39.71632609061173,0.254411523957321,-0.3402200896086742
340.3000000000041,39.82233819950891,0.25285430706097795,-0.343813341705443
341.4000000000041,39.92623330519144,0.2504621774747807,-0.3490318767089122
342.50000000000415,40.03387816367933,0.2471036412744273,-0.3553717397116998
343.6000000000042,40.13839220925474,0.24691966048474934,-0.3603854160130564
344.7000000000042,40.246249106343,0.2453600704256111,-0.3664235817726391
345.80000000000416,40.35226917834076,0.2434769413792896,-0.3741486465888646
346.9000000000042,40.45905961350731,0.24054869856002703,-0.38125064884486015
348.0000000000042,40.56432778941748,0.2390249817905754,-0.38822650622626
349.10000000000423,40.670812515183485,0.23979451338375785,-0.3958520621581796
350.20000000000425,40.777245907985844,0.2356279913695466,-0.40598043012991525
351.3000000000043,40.88285423459733,0.23560931068933544,-0.4134456974973859
352.4000000000043,40.987971433150555,0.23763262109473204,-0.4229629284917902
353.5000000000043,41.09563644862727,0.2340527157031908,-0.43343632049558556
354.60000000000434,41.20187225161419,0.23518192647893854,-0.44460346591239475
355.7000000000043,41.307610186521806,0.23590271587096706,-0.4554472153737179
356.80000000000433,41.41473370897734,0.23434988119619987,-0.4665466777121705
357.90000000000435,41.521293382827814,0.23458654669346202,-0.4790454137494997
359.0000000000044,41.62655312569571,0.2344495539398505,-0.4932561557427788
360.1000000000044,41.73412893329272,0.2368611821058066,-0.5057424383651457
361.2000000000044,41.840104830757305,0.23890780674012158,-0.5200612811710608
362.30000000000445,41.94449005487906,0.2382597044014022,-0.5338855645834935
363.4000000000044,42.05388455683789,0.24091304195151053,-0.5506482746802703
364.50000000000443,42.16056320045511,0.2422729602401521,-0.5679845346214862
365.60000000000446,42.26707873839857,0.24313340285015395,-0.5850766174947077
366.7000000000045,42.371042243935165,0.24536625640999649,-0.6023161302984246
367.8000000000045,42.47971424775015,0.2476372237693228,-0.6202392283847646
368.9000000000045,42.586960724618216,0.25128988476362274,-0.6404698075948589
370.00000000000455,42.69325239194566,0.2533473039333404,-0.6603542108570508
371.10000000000457,42.8003959256013,0.25668087941909756,-0.6806363144477157
372.2000000000046,42.90596401020432,0.2608623618803358,-0.7013621099448817
373.30000000000456,43.012790259547565,0.2630011721692426,-0.7224816333532793
374.4000000000046,43.11930359654802,0.26541164852016624,-0.7440654820935291
375.5000000000046,43.22630874678465,0.2676771270407629,-0.7667005039757231
376.6000000000046,43.33240584097177,0.270274645538832,-0.7886787569040776
377.70000000000465,43.4382479355347,0.2720016496404936,-0.8104086179997099
378.8000000000047,43.5454322166936,0.27499053067474444,-0.8314117174173434
379.9000000000047,43.65161726687215,0.27678350973729193,-0.85443237449027
381.00000000000466,43.75821833381389,0.27673690152311525,-0.8776185782083363
382.1000000000047,43.86523343828582,0.27765413629395086,-0.8992352807535906
383.2000000000047,43.97184013991718,0.279259804327442,-0.9208441837310355
384.30000000000473,44.077990046997634,0.28046599963908503,-0.9411284730170468
385.40000000000475,44.185068534334505,0.28032434542352785,-0.9635001050269243
386.5000000000048,44.29289760428886,0.28092224301825,-0.9834077424463703
387.6000000000048,44.399065869323344,0.2781316153958553,-1.0045010754604542
388.7000000000048,44.505653865261806,0.2766368383455965,-1.0236480647237705
389.80000000000484,44.6124568398281,0.2759411306273143,-1.0432284545830033
390.9000000000048,44.719915980937266,0.2749037477573927,-1.061038422194709
392.00000000000483,44.826590324862856,0.27371321694043615,-1.079302705166254
393.10000000000485,44.93281518043282,0.27141876220578026,-1.0977376592025228
394.2000000000049,45.039662452871255,0.2715395240940953,-1.114254043748403
395.3000000000049,45.1483992038366,0.2696639102193811,-1.1325431647339577
396.4000000000049,45.25519344792984,0.26849266750674017,-1.1498050890513243
397.50000000000495,45.36217330099054,0.2666014939394311,-1.1655580930562839
398.6000000000049,45.46892437709339,0.2652041419335165,-1.1820724397523152
399.70000000000493,45.575999819962774,0.2637174217932105,-1.1972617639414675
400.80000000000496,45.68357741908125,0.26358769703268187,-1.2119692041669845
401.900000000005,45.7909663236551,0.262706068297351,-1.2284544765886642
403.000000000005,45.89768973633099,0.26145845121910266,-1.2443362546315644
404.100000000005,46.00508217060436,0.2617403942059858,-1.2589128060698966
405.20000000000505,46.11270251834081,0.2605342375283619,-1.272702106709342
406.30000000000507,46.219552503502044,0.25979325373409745,-1.2884577063002354
407.4000000000051,46.32636543756996,0.25885025294921193,-1.3018672533832918
408.50000000000506,46.43352332152778,0.2591591828086499,-1.3173885759161852
409.6000000000051,46.540686031708475,0.25951160024781994,-1.3320223029243627
410.7000000000051,46.64779540245451,0.2586508741181113,-1.345998212772182
411.8000000000051,46.7566143741289,0.25710059049239103,-1.3601594021573225
412.90000000000515,46.86205387600729,0.2596872072284859,-1.3755099676133433
414.0000000000052,46.97044613780104,0.2587056881747136,-1.390473648329297
415.1000000000052,47.077659905243856,0.2573387142122034,-1.4032277862035296
416.20000000000516,47.18591274307288,0.25564032153407673,-1.4194595501690923
417.3000000000052,47.29220851250082,0.25670964675448593,-1.4316322854450725
418.4000000000052,47.40143818573117,0.25568811690731463,-1.446564001860903
419.50000000000523,47.508035979532536,0.2567281126991136,-1.4607608223711352
420.60000000000525,47.61560930250358,0.25491919495616566,-1.4737382418962492
421.7000000000053,47.72282168350929,0.2540981006588233,-1.4883722639178227
422.8000000000053,47.83134374309466,0.25464273289588385,-1.500995144915596
423.9000000000053,47.93777320331496,0.25194446223199474,-1.513460139503176
425.00000000000534,48.04548608212582,0.25020842606970073,-1.5264302369764322
426.1000000000053,48.152637408157645,0.24877180477159966,-1.5381385084832475
427.20000000000533,48.26009654884794,0.24678109010865668,-1.5492831862794576
428.30000000000535,48.367631289718204,0.246189160520387,-1.5610760719983494
429.4000000000054,48.47537839300808,0.24384225359199294,-1.5703782225495053
430.5000000000054,48.58298977635053,0.24148835982594893,-1.58130599410923
431.6000000000054,48.69059977846141,0.24069851236614706,-1.591917492689121
432.70000000000545,48.79748278329425,0.2369361834870859,-1.601511506315076
433.8000000000054,48.905542101593824,0.23558057593368548,-1.6113442582762914
434.90000000000543,49.01289261282264,0.23382767293606213,-1.620185596490174
436.00000000000546,49.12031206967214,0.23209542130907956,-1.6260212473668316
437.1000000000055,49.22828842270668,0.23321046849065316,-1.6375618870058704
438.2000000000055,49.33556324699536,0.23492888066161036,-1.6454188049783518
439.3000000000055,49.44249506628985,0.2329896590154509,-1.6523582026967762
440.40000000000555,49.54980079418873,0.23343265662136667,-1.6613580601574554
441.50000000000557,49.65800683859828,0.23396010694910635,-1.6695767863465827
442.6000000000056,49.76559020355514,0.23576386611566835,-1.6759714354001298
443.70000000000556,49.87329965213367,0.23471157753376815,-1.6833819417508273
444.8000000000056,49.98009408273429,0.2346753715278941,-1.6908651768585332
445.9000000000056,50.08880782910414,0.23217955192660625,-1.6983465448536168
447.0000000000056,50.19626478660363,0.23124647734893394,-1.7053236033080266
448.10000000000565,50.303799308345866,0.23162744016144066,-1.711343361030436
449.2000000000057,50.411998899081894,0.23001973093238448,-1.7180738935493212
450.3000000000057,50.5188587708309,0.2296328080255608,-1.7232621910349923
451.40000000000566,50.62821842544587,0.22985163467261432,-1.728112966417894
452.5000000000057,50.734585721000684,0.22837142652638792,-1.7345386614406069
453.6000000000057,50.8425400056755,0.22770732385494769,-1.7391636267675836
454.70000000000573,50.95054513035498,0.23053541022212062,-1.7440275651701223
455.80000000000575,51.05876865781357,0.23018541198116743,-1.7489631618812287
456.9000000000058,51.16718297359453,0.23085960345463047,-1.7531055962995516
458.0000000000058,51.274707409418625,0.23103757682033058,-1.7577924025084086
459.1000000000058,51.38368552340679,0.23317737417813278,-1.761991636475151
460.20000000000584,51.49084116027414,0.23301159052085368,-1.7670525147937184
461.3000000000058,51.598720917524155,0.2310933775163267,-1.7703756948884366
462.40000000000583,51.70728351086666,0.2306788094880504,-1.7742615198740852
463.50000000000585,51.81278219187858,0.23047890559486656,-1.7758564241238326
464.6000000000059,51.92246599651131,0.22952769109757845,-1.7797601178645386
465.7000000000059,52.03092127082731,0.2258964477144345,-1.7825228426833108
466.8000000000059,52.13963186201221,0.22598592510297247,-1.7851882756813815
467.90000000000595,52.24616573359215,0.2247094478248928,-1.7871788742512686
469.0000000000059,52.35494705325957,0.22383106581567913,-1.7897192144581036
470.10000000000593,52.464260523768694,0.21961130855943634,-1.7911424329941772
471.20000000000596,52.57124614451712,0.2175715967843983,-1.7937355752687738
472.300000000006,52.68108537986544,0.21559804849074157,-1.7951840660261924
473.400000000006,52.78804355155751,0.2119794175424041,-1.7970433459601085
474.500000000006,52.89647777932949,0.21126833072549478,-1.7987217109726248
475.60000000000605,53.00560368689147,0.2080144729852163,-1.8009963018536195
476.70000000000607,53.11368153643835,0.206223999508303,-1.8022151647032758
477.8000000000061,53.22207881825671,0.20470212152314993,-1.8049508382465689
478.90000000000606,53.330583299429996,0.20112154430844076,-1.8056268041893468
480.0000000000061,53.43889109727732,0.200126140697512,-1.8069153266233853
481.1000000000061,53.54806663375229,0.19974143159207303,-1.8090365974904157
482.2000000000061,53.6562184648422,0.19981884279783713,-1.810850711609619
483.30000000000615,53.76430512012821,0.19722417716229568,-1.8121901559001765
484.4000000000062,53.8724356237002,0.19432906135534073,-1.8133349607974085
485.5000000000062,53.9807014269674,0.19295204673636115,-1.814831164575442
486.60000000000616,54.089278617779094,0.18930806959923993,-1.8148308178565413
487.7000000000062,54.19707966299672,0.18808413723604153,-1.8181831128925765
488.8000000000062,54.305665419527145,0.18624072482332563,-1.8193971301350738
489.90000000000623,54.41257036729361,0.18584097083476497,-1.8197786728418746
491.00000000000625,54.52258928898627,0.1849022815257165,-1.821007390711948
492.1000000000063,54.62980426915598,0.18241189993542117,-1.820739754778002
493.2000000000063,54.7380492030546,0.18135645931591493,-1.8220627539563572
494.3000000000063,54.84649551145505,0.18232345858443258,-1.824788449386685
495.40000000000634,54.95420373143399,0.18321867482005796,-1.8260268918582567
496.5000000000063,55.062661507992,0.18231487792448725,-1.8260375780892413
497.60000000000633,55.17050917926355,0.18127267055314916,-1.8273406039918099
498.70000000000636,55.27940311771145,0.17947522720723597,-1.8273471470238585
499.8000000000064,55.38698915652023,0.18029856650050938,-1.8293296520474382
500.9000000000064,55.49566379707964,0.17825800609959472,-1.8300114253079514
502.0000000000064,55.60419780834065,0.17979747704590654,-1.8299744182118793
503.10000000000645,55.71358080878733,0.17977075878146861,-1.8319600038851673
504.2000000000064,55.821618160796376,0.17647623106731325,-1.8329534289686764
505.30000000000643,55.92968050161057,0.17890481298173508,-1.8345990017528049
506.40000000000646,56.038376952068916,0.17596614181159204,-1.8346008412607038
507.5000000000065,56.1474525741665,0.17490876941806818,-1.835911927292198
508.6000000000065,56.25649341631882,0.17581445991835518,-1.8364411328841097
509.7000000000065,56.364829629579845,0.17491861193923858,-1.8385487137150611
510.80000000000655,56.473762767840064,0.17258940410469567,-1.837135541415353
511.90000000000657,56.582886947256306,0.17250428917952368,-1.8396718716789806
513.0000000000066,56.692057606710286,0.17060868128573778,-1.8421679933490793
514.1000000000065,56.80020792240577,0.16900992434853834,-1.8421788242757189
515.2000000000066,56.90905831632128,0.16697689257688964,-1.8421668293320077
516.3000000000065,57.01698633580304,0.16638005997732333,-1.843481382505073
517.4000000000067,57.126040476771735,0.16677504415965605,-1.8447993435508727
518.5000000000066,57.23495239693278,0.16540257723119603,-1.8459554241662173
519.6000000000067,57.34266520870572,0.1648597906771837,-1.8461212060286782
520.7000000000066,57.45215757415061,0.1631013823280003,-1.8487835776812984
521.8000000000067,57.56142569914817,0.16304384407551717,-1.8487500644411101
522.9000000000067,57.669574929559516,0.16122210339766305,-1.8510253788620923
524.0000000000067,57.779038764172675,0.15940681968866005,-1.8513868493946273
525.1000000000067,57.88710834607007,0.15986875134187117,-1.8513902207067598
526.2000000000068,57.996479853815444,0.15901768707217606,-1.8540469276616989
527.3000000000068,58.10498988202624,0.1584221475552489,-1.854689097436188
528.4000000000068,58.21319218899803,0.15821310333355926,-1.8574019932371715
529.5000000000068,58.32313114189521,0.15738115157908916,-1.8574198971421274
530.6000000000068,58.43174032267858,0.15605119951530033,-1.8587457394912206
531.7000000000069,58.541302014259976,0.15691726884776527,-1.8601396095056364
532.8000000000068,58.650291624018124,0.15587488077966843,-1.8626969215296727
533.9000000000069,58.759221748436325,0.15714422751548107,-1.8626983717878591
535.0000000000068,58.867276704784516,0.15561377717457583,-1.8639998927241108
536.100000000007,58.97683996397315,0.15539196023098664,-1.86654522901949
537.2000000000069,59.086091003059416,0.15534236137638985,-1.8675434629486674
538.300000000007,59.194365859001714,0.15433403734708004,-1.8697308236782728
539.4000000000069,59.30390481228682,0.1542024547887177,-1.8696122066000727
540.5000000000069,59.41182295774191,0.15449783911936532,-1.8722230361223295
541.600000000007,59.521136740193384,0.1548217646265234,-1.8745504921480571
542.700000000007,59.63136711624551,0.15418172325239013,-1.8771975599037418
543.800000000007,59.73787117787731,0.15571907940696056,-1.8778390362277424
544.900000000007,59.84856165227035,0.15440418536855213,-1.8791556436922416
546.000000000007,59.95815247321635,0.15467886535237968,-1.8827813701526308
547.1000000000071,60.06699416642013,0.15452186456693118,-1.884128480893295
548.2000000000071,60.17622855777705,0.15282035517165568,-1.8853978746071762
549.300000000007,60.28642416035322,0.15319456159975003,-1.887840012577826
550.4000000000071,60.395179121904675,0.155171753900753,-1.8903374467976732
551.500000000007,60.50444267848391,0.15295003218500725,-1.8930991269858786
552.6000000000072,60.614319560911625,0.15292238895063098,-1.895747167122619
553.7000000000071,60.72392706543807,0.15309153105744133,-1.8983791481546604
554.8000000000072,60.83285297036344,0.15366762953073576,-1.9002576940273732
555.9000000000071,60.94141772281693,0.15385435872369466,-1.9026620545232298
557.0000000000072,61.051015899043676,0.15198517347324372,-1.9068511618239046
558.1000000000072,61.158569649115066,0.1547103542670027,-1.9083102318426226
559.2000000000072,61.2685033271262,0.15253087120441833,-1.9124173408526084
560.3000000000072,61.379902767033265,0.1550712021374512,-1.915491879123599
561.4000000000073,61.48870349581671,0.1558903060736394,-1.9187956153827983
562.5000000000073,61.59891550513408,0.1558896440055527,-1.9221572985849154
563.6000000000073,61.707451899132565,0.15661682942787022,-1.9249101364003858
564.7000000000073,61.81633162969413,0.15857829186674782,-1.9290000148379782
565.8000000000073,61.926318908720084,0.15949361186412664,-1.9321627283870675
566.9000000000074,62.03461952051258,0.15904944242004276,-1.9347940027965187
568.0000000000074,62.144273253482964,0.15915676449697064,-1.939508292777881
569.1000000000074,62.25280659702642,0.15822330143462238,-1.9436849753860233
570.2000000000073,62.36231878925846,0.16212783768928204,-1.9478103678875214
571.3000000000073,62.472230657557056,0.15842402649656528,-1.9501426653366196
572.4000000000074,62.58148039150932,0.1610159418354112,-1.9543628302941385
573.5000000000074,62.690091855856906,0.1622813136361449,-1.9581074153619666
574.6000000000074,62.79859786626421,0.15646391910926358,-1.9620464123463952
575.7000000000074,62.90947637194264,0.1552024598283267,-1.9671782148961836
576.8000000000075,63.0190480874999,0.1557068202638549,-1.9693060093573407
577.9000000000075,63.12948708550766,0.15535716728409935,-1.9736497897956622
579.0000000000075,63.237843018793875,0.1542893555621739,-1.9762467434233866
580.1000000000075,63.348560148736205,0.15231658998422248,-1.9817565544069407
581.2000000000075,63.45819666342094,0.15062447618785274,-1.985209606848208
582.3000000000076,63.5680069616912,0.1484218592175566,-1.9878888386786224
583.4000000000076,63.67753174835152,0.14710323228925343,-1.9911249318256408
584.5000000000076,63.788421690705995,0.14788122887921792,-1.994951297610815
585.6000000000076,63.8971295057194,0.146320056651721,-1.9989918039179186
586.7000000000077,64.00620388744859,0.14506552637606307,-2.001646145657056
587.8000000000077,64.11692308148531,0.14542451339921375,-2.0028468088326816
588.9000000000076,64.22566356919303,0.14705517088681447,-2.0057034644691685
590.0000000000076,64.33552941747107,0.14908023731798917,-2.0074948937528254
591.1000000000076,64.4440683124278,0.1546354572062747,-2.0095865252567218
592.2000000000077,64.55394240371373,0.15932459176617872,-2.009598012012859
593.3000000000077,64.66320850542817,0.16878429944083553,-2.0109040792884585
594.4000000000077,64.77256810102045,0.1728079357675953,-2.0123479107758304
595.5000000000077,64.88189399650646,0.16934522962371767,-2.01367881869976
596.6000000000078,64.98907129607224,0.16820405779642814,-2.0148632161737545
597.7000000000078,65.09989925110182,0.16906806437484279,-2.0161261485740543
598.8000000000078,65.20980432424486,0.17350569071094768,-2.0181235418696843
599.9000000000078,65.3195934763012,0.17464066252783456,-2.017506364429037
601.0000000000078,65.4292502901934,0.17611513335529577,-2.0190805024481397
602.1000000000079,65.53811930424799,0.17657202753766274,-2.0201298497702087
603.2000000000079,65.64845573172218,0.17993330556353365,-2.020131514251063
604.3000000000079,65.75726615889569,0.18382290762101108,-2.0214327788043285
605.4000000000078,65.86685125785634,0.18887907825818365,-2.022760007332372
606.5000000000078,65.9750566806334,0.19099021317161452,-2.0240784026656766
607.6000000000079,66.0869680381246,0.19170593483225187,-2.025069787420184
608.7000000000079,66.19640132897345,0.19644601173366072,-2.0253012440661537
609.8000000000079,66.30683987014534,0.19924185631568114,-2.025390282930842
610.9000000000079,66.41461113644026,0.205792971732248,-2.0263807737282478
612.000000000008,66.52528964289628,0.21035796261798415,-2.027700803960536
613.100000000008,66.63464393966424,0.214999785770105,-2.0303389899908275
614.200000000008,66.74447628424424,0.2208416633997996,-2.0289360197327166
615.300000000008,66.8539673094326,0.22912096482362238,-2.031706149222218
616.400000000008,66.96378975183788,0.23671789432872797,-2.032970089027824
617.5000000000081,67.07426188983386,0.2447718787385424,-2.0335319023474403
618.6000000000081,67.1837581864093,0.25329881054085684,-2.036309018046767
619.7000000000081,67.29275036314925,0.2607878652471215,-2.0359071467438814
620.8000000000081,67.40334666336422,0.26815610072294555,-2.038455436204135
621.9000000000082,67.51334231540244,0.2781184558179315,-2.0399462945247517
623.0000000000082,67.62326983882161,0.2889760301747093,-2.0408080308029555
624.1000000000081,67.73259707419466,0.2992346670500066,-2.043490578881923
625.2000000000081,67.84199083757304,0.3077115660553279,-2.044766823129904
626.3000000000081,67.95249744823336,0.3166829740464674,-2.047554079914124
627.4000000000082,68.06274501990237,0.3268205226714527,-2.0474594358369327
628.5000000000082,68.17210011357324,0.3388498283987554,-2.050077946291394
629.6000000000082,68.28073884790587,0.34916129421446745,-2.051452119451851
630.7000000000082,68.39176417181115,0.3579501942000635,-2.0541809278101364
631.8000000000083,68.50101095973747,0.3693883109254453,-2.0554467496923348
632.9000000000083,68.61080576310358,0.3807177117606978,-2.0593077964299917
634.0000000000083,68.72129146453341,0.3937361789661742,-2.061952872227288
635.1000000000083,68.83065656466447,0.4081538612148089,-2.064257694482362
636.2000000000083,68.94120873631421,0.4192691153536379,-2.0668912082139697
637.3000000000084,69.05021241551356,0.43102955617014793,-2.06864876787885
638.4000000000084,69.15999781469571,0.4469567150207342,-2.072600185684321
639.5000000000084,69.268316959924,0.45968670637022696,-2.075236537032551
640.6000000000083,69.37981017854385,0.4739552041300919,-2.077303640195958
641.7000000000083,69.4903952341978,0.4861231686185491,-2.0822608342280615
642.8000000000084,69.59906878464574,0.49826298336648644,-2.0845856049680815
643.9000000000084,69.70954171571742,0.5136098830889344,-2.0881938628326613
645.0000000000084,69.82010551857024,0.527635295171557,-2.0923671550035716
646.1000000000084,69.9297984722786,0.5433478870722551,-2.093770970615769
647.2000000000085,70.03970016785885,0.5545668262794212,-2.099157813560445
648.3000000000085,70.15066970281178,0.5682041794672303,-2.1035603278452717
649.4000000000085,70.260679875799,0.5845068787041223,-2.10623602443272
650.5000000000085,70.37024818321359,0.6010924112010746,-2.1119207478862503
651.6000000000085,70.48063491536362,0.6180683646776355,-2.115111104755041
652.7000000000086,70.5913268133646,0.6306307470339185,-2.1198413379543073
653.8000000000086,70.70210085979134,0.6460446626017986,-2.124261083842934
654.9000000000086,70.81298742551115,0.6624806814110522,-2.1285307672825486
656.0000000000086,70.92187038710898,0.6781851956190803,-2.133781338563832
657.1000000000087,71.03356716585228,0.6938813596834754,-2.138613078664189
658.2000000000087,71.14385484655126,0.7104087215067034,-2.142925015466786
659.3000000000086,71.25518036620187,0.7265966760017821,-2.1493670482014866
660.4000000000086,71.3648079320363,0.7394940165488202,-2.1551443599002136
661.5000000000086,71.4757592814923,0.75957247361502,-2.160302295080012
662.6000000000087,71.58577527481201,0.7731180629093843,-2.1650623525289436
663.7000000000087,71.69713956608801,0.7895520296452831,-2.172779871724121
664.8000000000087,71.80788594539273,0.8039168647468521,-2.177282734416391
665.9000000000087,71.91783205981176,0.8193939348168122,-2.183279246429472
667.0000000000088,72.02635392743959,0.8357357322925985,-2.18956300170546
668.1000000000088,72.13782432442963,0.8498753811965286,-2.194810318054463
669.2000000000088,72.24746709358365,0.8643696004368787,-2.2015261109995587
670.3000000000088,72.35663813517348,0.8780528204346794,-2.2080451899930296
671.4000000000088,72.46666030463905,0.888663475274984,-2.2143795582933237
672.5000000000089,72.57662140164229,0.8991767491127642,-2.2214953832127122
673.6000000000089,72.68564684420882,0.9099323192526697,-2.2281174328277604
674.7000000000089,72.79654074893398,0.9239835613175473,-2.234397578657685
675.8000000000088,72.90584335819571,0.9272434492897633,-2.2399953538257296
676.9000000000088,73.01555557298227,0.9318637305444502,-2.247000711987087
678.0000000000089,73.12519605947558,0.939646020353806,-2.254438737757531
679.1000000000089,73.23629500810277,0.9417223566364437,-2.261568326956767
680.2000000000089,73.3470828495851,0.940019031864471,-2.267644021037457
681.3000000000089,73.4567365368492,0.9383084038160976,-2.2741734282051693
682.400000000009,73.5671438096511,0.9348400771039234,-2.2809009210042435
683.500000000009,73.67764123159692,0.9331099345277984,-2.2869565621960586
684.600000000009,73.78692853702441,0.9330804275224575,-2.293829291655176
685.700000000009,73.89780788087464,0.9365742177616831,-2.3011506815727234
686.800000000009,74.00839819286337,0.9468031684540232,-2.3080571744883525
687.9000000000091,74.11868876846529,0.967860159501793,-2.3153477078311173
689.0000000000091,74.22903462390886,1.0020111369925502,-2.3220439191024953
690.1000000000091,74.33936572864273,1.0394267839099367,-2.327485885325488
691.2000000000091,74.4499055571548,1.0817128507780212,-2.3343243625070373
692.3000000000092,74.5593289635206,1.1259417904347733,-2.3430711696426547
693.4000000000092,74.670304360905,1.173166361471567,-2.3503817287416364
694.5000000000091,74.77970325399919,1.2219907137716737,-2.358580893344598
695.6000000000091,74.89010258394269,1.2646307842923994,-2.3669404118917967
696.7000000000091,75.0006892249291,1.306674831122924,-2.3763084534408416
697.8000000000092,75.11018803765968,1.3516730043038656,-2.3853784692242783
698.9000000000092,75.22073507221575,1.3955084711656034,-2.3944479251636306
700.0000000000092,75.33109604577287,1.438386229287336,-2.4048263572224036
701.1000000000092,75.44149187503278,1.483425796002138,-2.415065414451138
702.2000000000093,75.55215596999241,1.5250742412756488,-2.42584360404373
703.3000000000093,75.66302779810468,1.5703138799609209,-2.4362716296553026
704.4000000000093,75.77283842575737,1.6102338609740832,-2.446392992201997
705.5000000000093,75.88380130421625,1.6545076234497207,-2.458693224163926
706.6000000000093,75.99402253008047,1.6960573528465452,-2.4687542184362337
707.7000000000094,76.10432894000992,1.7369811422852097,-2.4824954922731113
708.8000000000094,76.21475729102777,1.779905155170368,-2.4929572793023542
709.9000000000094,76.32470615251644,1.8225351131339946,-2.5043431037351302
711.0000000000093,76.43550318224133,1.8604890580850149,-2.5177640971504243
712.1000000000093,76.54686826228608,1.9032911472131604,-2.5323522288107165
713.2000000000094,76.65736272572462,1.938845810780617,-2.5444287310724825
714.3000000000094,76.76782307567403,1.9794653110469889,-2.5580927988739894
715.4000000000094,76.87871072052842,2.012965503802297,-2.5717935643313687
716.5000000000094,76.98887767303752,2.0449314724644956,-2.5854012174413836
717.6000000000095,77.10011353121885,2.078529562274256,-2.5985825577200177
718.7000000000095,77.21158075228584,2.1076267408487936,-2.615198914214504
719.8000000000095,77.32188641720818,2.134904525512404,-2.629019627868859
720.9000000000095,77.43331689760703,2.160116054317385,-2.643703530370481
722.0000000000095,77.54308975336801,2.1834659922702606,-2.6580498779813695
723.1000000000096,77.65435327746354,2.202339619752557,-2.6734158621875226
724.2000000000096,77.76291073050598,2.217784671440402,-2.6879218045601405
725.3000000000096,77.87579673910956,2.2204951239110606,-2.703326362638074
726.4000000000096,77.98600906375215,2.2172346908962806,-2.7170573342639432
727.5000000000097,78.09571281756587,2.2058094219787527,-2.733483284494489
728.6000000000097,78.20724465703864,2.178180007373741,-2.748567998445632
729.7000000000096,78.31749419471288,2.1346593469685815,-2.762551618411598
730.8000000000096,78.42741293058766,2.068299082565109,-2.776717390135577
731.9000000000096,78.53649337800049,1.9752433685108486,-2.7896238342023487
733.0000000000097,78.64793963802904,1.8352832194574953,-2.8030782040087794
734.1000000000097,78.75824064968799,1.6156443764209412,-2.816080797727724
735.2000000000097,78.8670748315516,1.1889111428640602,-2.8238494022511067
736.3000000000097,78.97646333629413,0.5735539725287575,-2.8307206241821175
737.4000000000098,79.08504087307332,0.29322377535521627,-2.831021651140192
738.5000000000098,79.19438022825317,0.17645018520313996,-2.832080042838796
739.6000000000098,79.30568336688519,0.12398237473314022,-2.8360993052916283
740.7000000000098,79.41559558174669,0.10426546037091217,-2.8426472277131793
741.8000000000098,79.52586339945005,0.08461375404944468,-2.841281135273262
742.9000000000099,79.63487381042674,0.07798107409402491,-2.838560227013638
744.0000000000099,79.74672022012702,0.07363210112006274,-2.8385638413002496
745.1000000000099,79.85720801658088,0.0698263431135463,-2.8365444713935046
746.0000000000099,79.94757297503156,0.07339385339531737,-2.836580100199616