File: 01_Data/Plastic_Laminate_Countertop_Laminate/STA/N2/10K_min/Plastic_Laminate_Countertop_Laminate_STA_N2_10KData_221005_R2.csv
##Temp./Â°C,Time/min,DSC/(mW/mg),Mass loss/mg
51.0,10.66,0.02205756737785869,-0.006599361707461782
52.000000000000014,11.057233630182575,0.06752000945939018,-0.006732534052554584
53.00000000000003,11.30355941569471,0.09611616371642073,-0.004742289161113966
54.00000000000004,11.506398673725233,0.1221229908189645,-0.0049377890871316055
55.00000000000006,11.68439185980315,0.13895780392977608,-0.0044730226360742975
56.00000000000007,11.847117671205066,0.1540149207639132,-0.005034357909119436
57.000000000000085,11.99812095111433,0.16472739061339747,-0.0038188379103596404
58.0000000000001,12.143875689782377,0.1747561056718112,-0.00379777967630357
59.000000000000114,12.283852048035515,0.18393149778535212,-0.005343805282498337
60.00000000000013,12.420847233978836,0.1953215423181771,-0.0049048915395095705
61.00000000000014,12.552175950553721,0.20133138140657292,-0.005625531540758288
62.000000000000156,12.680402857188213,0.2071864842328459,-0.005728991176297882
63.00000000000017,12.808751166460647,0.21417234478096026,-0.006139074174285497
64.00000000000018,12.934229274866311,0.2200426536673432,-0.006156241098818072
65.0000000000002,13.057048020137707,0.22700784905908122,-0.004897840312608537
66.00000000000021,13.179473262581089,0.23158164047484164,-0.005601241113471822
67.00000000000023,13.299647545968721,0.23753392895135006,-0.0057206097276152335
68.00000000000024,13.418682160379253,0.24373224565721574,-0.004885880359502437
69.00000000000026,13.535698021008335,0.25001063495164044,-0.006264867149282871
70.00000000000027,13.65320505728622,0.2560326479232762,-0.007475339752748056
71.00000000000028,13.770339812892598,0.26267139110294113,-0.007440124584486618
72.0000000000003,13.884634995785417,0.2671232019392652,-0.009537447508148666
73.00000000000031,13.998490858278641,0.27298446801778886,-0.00874033617009129
74.00000000000033,14.109568167081338,0.27750511137115974,-0.008781544744781655
75.00000000000034,14.222744088237896,0.28215884833469806,-0.008805489563204816
76.00000000000036,14.334281172459345,0.28698228086676947,-0.00871965108398065
77.00000000000037,14.443114527246657,0.291408854879208,-0.008797916201537248
78.00000000000038,14.552890689140543,0.29370293124298696,-0.010063267821410093
79.0000000000004,14.661388252924159,0.2992023704137253,-0.010107120011735304
80.00000000000041,14.769351147912603,0.30237947794255216,-0.01138411209360779
81.00000000000043,14.877411069117347,0.3047462562859282,-0.01278591906714066
82.00000000000044,14.985345222769437,0.3084414030359588,-0.011667466019058104
83.00000000000045,15.09184535086919,0.31338633182314024,-0.012739463356960634
84.00000000000047,15.198040700763638,0.31648770344507215,-0.013912354379952419
85.00000000000048,15.302506162949719,0.31732769584566434,-0.01658900203590452
86.0000000000005,15.407001047182746,0.3197675479363574,-0.014857317290006833
87.00000000000051,15.51199754754342,0.3223855556239992,-0.011879328097973207
88.00000000000053,15.615639500512492,0.3253701895418687,-0.014734731141859747
89.00000000000054,15.71819367436646,0.3272861184761767,-0.01468805051245159
90.00000000000055,15.821218597418206,0.32818501471768124,-0.013268395962133361
91.00000000000057,15.924508143759786,0.3289935480460703,-0.014600410250285911
92.00000000000058,16.025027002099392,0.330495836304074,-0.016807059019997794
93.0000000000006,16.128381175963934,0.33011449449697117,-0.01724082286048212
94.00000000000061,16.23064369315345,0.33069079977962734,-0.0168756645704633
95.00000000000063,16.330568448435493,0.3323785204058106,-0.01743951530460297
96.00000000000064,16.431162844380125,0.33088878039004666,-0.01724062002855664
97.00000000000065,16.532241219839523,0.33119728088592126,-0.01854924980533923
98.00000000000067,16.63234701787776,0.3331448094644711,-0.01854961151752299
99.00000000000068,16.732633126401126,0.33184876211316994,-0.019869755105858644
100.0000000000007,16.832345699060568,0.3315364615518531,-0.01862264360242971
101.00000000000071,16.932147430644253,0.33102864117068964,-0.017239879041498263
102.00000000000072,17.03150514027867,0.3298667568275975,-0.018458903706705776
103.00000000000074,17.130814965789863,0.3325657530560251,-0.019833753833485623
104.00000000000075,17.226272501905594,0.3300145707211086,-0.0211900885041425
105.00000000000077,17.327656963464516,0.331638568878446,-0.022499488416461766
106.00000000000078,17.425469546090486,0.33280122391653677,-0.022151089686494707
107.0000000000008,17.52507314383716,0.3311294715683596,-0.02086563770490013
108.00000000000081,17.623454076740753,0.3302371417677148,-0.01811009080184789
109.00000000000082,17.721553016435244,0.32893181258473725,-0.01943012179860304
110.00000000000084,17.820483216194027,0.32787191708337093,-0.020750134521198227
111.00000000000085,17.91659823569149,0.32755291839289435,-0.02075023987467528
112.00000000000087,18.017921926802806,0.32868225480745505,-0.022324928257792642
113.00000000000088,18.11533235050389,0.3297160066639112,-0.02371061516534745
114.0000000000009,18.211735882802817,0.33036814031342887,-0.0250318990092131
115.00000000000091,18.309902471705467,0.3292690416944535,-0.023719903349631366
116.00000000000092,18.40854167415518,0.32946746980359365,-0.02372297782899846
117.00000000000094,18.50497267110356,0.3306492720528701,-0.025040215516638042
118.00000000000095,18.601999034887946,0.3288349640338132,-0.025029945661363406
119.00000000000097,18.699254455256813,0.3299342039035079,-0.024038453551752603
120.00000000000098,18.796895344310318,0.32979789430798134,-0.025224125658011687
121.000000000001,18.894221456566587,0.32940621060355435,-0.0253601814970148
122.00000000000101,18.991462825110894,0.328395427060279,-0.02634608515786674
123.00000000000102,19.089203462873098,0.32753153811917113,-0.02634843452282709
124.00000000000104,19.186696892892527,0.3284855139837426,-0.025294345100738802
125.00000000000105,19.28244687330195,0.32862479136992107,-0.025192566714232534
126.00000000000107,19.379801660204,0.32939307220730996,-0.02503112495905757
127.00000000000108,19.47650705627374,0.32855072792939066,-0.02534891599905187
128.00000000000108,19.57407206122002,0.33133903564047895,-0.026680188321465792
129.0000000000011,19.67214134968362,0.3321070949701038,-0.026725314570557934
130.00000000000114,19.767671694970982,0.33313744581874194,-0.02635804927356844
131.00000000000114,19.864019798146302,0.3346758849629399,-0.026680091749706314
132.00000000000114,19.959617442430677,0.3333991165522677,-0.027999069926386788
133.00000000000117,20.057047591394543,0.3353626845939942,-0.028650175773609732
134.0000000000012,20.15304581393316,0.3358343703625779,-0.028706857350670134
135.0000000000012,20.249906633321864,0.3360205181952026,-0.0293180790669183
136.0000000000012,20.345846250024785,0.3369803537422732,-0.028659859177977864
137.00000000000122,20.443096665739205,0.3384186249886828,-0.028659648945482452
138.00000000000125,20.53822880480077,0.3384608298785353,-0.0289897641223833
139.00000000000125,20.63574627512279,0.3410705145736246,-0.029057816972418493
140.00000000000125,20.730103339097205,0.34206733700174274,-0.027937711374325325
141.00000000000128,20.82580428371913,0.3425837730687602,-0.0293704801799608
142.0000000000013,20.922081909998845,0.3445811297130965,-0.030629908500058534
143.0000000000013,21.016108362721425,0.3451274809868117,-0.032094759281234175
144.0000000000013,21.113811562336345,0.34516316262080504,-0.03063008234736664
145.00000000000134,21.207785930511065,0.3481249180700131,-0.030630003999782218
146.00000000000136,21.304004522713445,0.35027527987855545,-0.030630006872031323
147.00000000000136,21.400745345750664,0.3523291683772264,-0.03193948582787698
148.00000000000136,21.495469720009307,0.35459345818842036,-0.03193660682213739
149.0000000000014,21.59202744128925,0.3556712270803476,-0.031940097996531414
150.00000000000142,21.687295829772566,0.3576845976494678,-0.03193910563182456
151.00000000000142,21.78327754442756,0.36004216974815073,-0.030625253547634124
152.00000000000142,21.87893092596202,0.3601425215511318,-0.03293247812350142
153.00000000000145,21.973689919874865,0.36193530923937534,-0.03424858750773119
154.00000000000148,22.06839745863899,0.3634535126855073,-0.034256206336488404
155.00000000000148,22.163494066570358,0.36547982441634885,-0.034910031114486095
156.00000000000148,22.260092526430565,0.3655710065599006,-0.03559808544678411
157.0000000000015,22.356386665730405,0.3681320038450472,-0.035570047207844624
158.00000000000153,22.451252907511655,0.3694107415928846,-0.036879280120957425
159.00000000000153,22.545600742472956,0.3719339792507633,-0.036196917577099086
160.00000000000153,22.642712153904924,0.3756342627704241,-0.03686601343277385
161.00000000000156,22.737453165736163,0.3749199393599451,-0.036827800261065136
162.0000000000016,22.832238573616202,0.3762401363089884,-0.0387437923006404
163.0000000000016,22.928117384951015,0.37899203285816624,-0.03853001372989873
164.0000000000016,23.022634952362385,0.37893281593722894,-0.0385380061357079
165.00000000000162,23.117918335615546,0.3827814232331749,-0.03935426965480637
166.00000000000165,23.210944294114103,0.38275527789010205,-0.04019016071398607
167.00000000000165,23.307992249941666,0.385139552868497,-0.0415000290335632
168.00000000000165,23.40389328892107,0.3868101780394797,-0.041477222252249035
169.00000000000168,23.498926897117627,0.3864731706608118,-0.04149995611578472
170.0000000000017,23.59464989078707,0.3871944092358774,-0.04149903093547014
171.0000000000017,23.688986224739093,0.3909858257235259,-0.0441297123644917
172.0000000000017,23.78338718965336,0.391534755420168,-0.044140016885654276
173.00000000000173,23.878796279748364,0.39261271018129384,-0.04413999556256698
174.00000000000176,23.975148027028137,0.3956851053572623,-0.045451604274048485
175.00000000000176,24.070089715414326,0.39541977084884733,-0.04676998179618863
176.00000000000176,24.165970401322227,0.39538328771279674,-0.04677009799999521
177.0000000000018,24.260092554065203,0.39645066215722174,-0.04677010014025029
178.00000000000182,24.356847910405868,0.39625884022895635,-0.04808897107897181
179.00000000000182,24.450296713876117,0.39967431042444385,-0.050718067182776494
180.00000000000182,24.545644548232115,0.3977197698192445,-0.04940144061056184
181.00000000000185,24.64123132560513,0.39864492540502017,-0.04940000426039326
182.00000000000188,24.735930161681075,0.39910168720185246,-0.05082971826794758
183.00000000000188,24.831247703630044,0.40077947124102464,-0.05203983605647444
184.00000000000188,24.926737539206776,0.40067315468211584,-0.05342226008861317
185.0000000000019,25.018964563437134,0.40225881552422377,-0.053371478422199914
186.00000000000193,25.116670868514873,0.3998864641362344,-0.05467984002858994
187.00000000000193,25.211228769718417,0.4016157318414196,-0.05470166275568111
188.00000000000193,25.30616664678445,0.40110562517063825,-0.05730006350933525
189.00000000000196,25.401444155126878,0.40166301242247643,-0.05730014436994946
190.000000000002,25.49539905114458,0.40490610383105574,-0.05861938444956838
191.000000000002,25.58925807443703,0.4024920126861538,-0.05993986667818341
192.000000000002,25.686007115158745,0.40264440447603017,-0.05994177891512731
193.00000000000202,25.780929174227268,0.40156705301770207,-0.06126020234959251
194.00000000000205,25.875885879467702,0.40300527582750817,-0.06126024199686064
195.00000000000205,25.969904133271385,0.40193408744448467,-0.06257375944427412
196.00000000000205,26.065143075315785,0.40095107743622954,-0.06290013336192679
197.00000000000207,26.159792624746988,0.39873237731387223,-0.06289944852529272
198.0000000000021,26.255354634348603,0.3991201306837151,-0.06448848231891136
199.0000000000021,26.350515023057856,0.39972966932361836,-0.06685987129655091
200.0000000000021,26.446214481624526,0.401454702749112,-0.06687141172516897
201.00000000000213,26.540616363426786,0.4005094403470999,-0.07082612743117744
202.00000000000216,26.63479676678844,0.39750934177602554,-0.07075091159098257
203.00000000000216,26.730000000000203,0.39804494228533815,-0.07211983197035199
204.00000000000216,26.82601031225884,0.39779431605912796,-0.07278267286359519
205.0000000000022,26.920960075809177,0.3958225664634248,-0.0748041631541847
206.00000000000222,27.016386629853876,0.39620424392724846,-0.07608024683618808
207.00000000000222,27.109129040947828,0.3951441698410847,-0.07742084177567676
208.00000000000222,27.204155797314908,0.39524444966409267,-0.07839010129415191
209.00000000000225,27.29899210501217,0.3932795324135251,-0.07969977833527819
210.00000000000227,27.39532297039098,0.39276953723698466,-0.08002547377275038
211.00000000000227,27.488776487643484,0.3910704609648992,-0.08268501047422427
212.00000000000227,27.581388011351574,0.38905606918044566,-0.08399020292539428
213.0000000000023,27.67869351383027,0.38874660972526376,-0.08266127379768484
214.00000000000233,27.77387474720699,0.38504668153409694,-0.08530410823966905
215.00000000000233,27.868595210105937,0.3830425742442831,-0.08662106350779863
216.00000000000233,27.96302408082563,0.38113813172804345,-0.08909187138837682
217.00000000000236,28.05840940061504,0.37952353197129235,-0.0879049933096292
218.0000000000024,28.15393266803941,0.37791474916947665,-0.09054585248797675
219.0000000000024,28.24745853977714,0.37554219444885995,-0.09189003834568021
220.0000000000024,28.342177076522557,0.37443515829903323,-0.09371658645712388
221.00000000000242,28.436627426551723,0.3725358882053252,-0.0972151530009504
222.00000000000244,28.53260649087385,0.3675258435209828,-0.09774562674307452
223.00000000000244,28.626824759918428,0.36557718587538934,-0.10084168892146206
224.00000000000244,28.7224152897883,0.36446395750134625,-0.1023964381682716
225.00000000000247,28.81710781659436,0.36201605297087314,-0.10375195074427923
226.0000000000025,28.910104461585757,0.360535027143659,-0.10506040074749734
227.0000000000025,29.00686758464681,0.3560315368816803,-0.10627611239687651
228.0000000000025,29.101915737641665,0.3549684000686752,-0.10913748332815487
229.00000000000253,29.196802132536305,0.35288935752534356,-0.11176293344941612
230.00000000000256,29.2921322746151,0.3503320746692039,-0.1143874188009244
231.00000000000256,29.386951736062038,0.34695647167818405,-0.11449330114603784
232.00000000000256,29.482972092135174,0.34479458264073753,-0.11794813784049074
233.0000000000026,29.577478969297047,0.34166930852440824,-0.12086068583127618
234.00000000000261,29.671864514848586,0.3409392547396656,-0.12213507105760257
235.00000000000261,29.767788011460688,0.3371488201102071,-0.12494823748436312
236.00000000000261,29.86325679026211,0.3345364384920001,-0.12641230693025785
237.00000000000264,29.957865980522936,0.33146625587861045,-0.12947119707122123
238.00000000000267,30.053972240256112,0.3297711683649053,-0.1315283333500319
239.00000000000267,30.14778318816212,0.32828045978819415,-0.1339730802916148
240.00000000000267,30.245270228083644,0.32511039461018915,-0.13692725834634567
241.0000000000027,30.339382469140663,0.32325878034170624,-0.1396580661368083
242.00000000000273,30.435297938411612,0.3211622056183384,-0.142178290652768
243.00000000000273,30.5300983429362,0.31938992068478994,-0.14491926197938998
244.00000000000273,30.625482014503095,0.31593997656073586,-0.14748188324617928
245.00000000000276,30.719313356839166,0.3144446469208975,-0.1488797920771252
246.00000000000279,30.81588407327,0.311211187277897,-0.15406196308326914
247.00000000000279,30.910862867977777,0.3084589578522011,-0.15732265299646198
248.00000000000279,31.006791355287643,0.3073098870595231,-0.1592884880543628
249.0000000000028,31.101781922660766,0.3066533293711437,-0.16250984279276093
250.00000000000284,31.197394808445004,0.3061378948847829,-0.16524527728256722
251.00000000000284,31.293169630379804,0.30166991419729466,-0.16994610467017468
252.00000000000284,31.387622278983105,0.2985807769615165,-0.17272913704275528
253.00000000000287,31.483328590106183,0.297366631009635,-0.17572584096216692
254.0000000000029,31.578284625963416,0.2971244015247796,-0.18148203449061473
255.0000000000029,31.672534311779916,0.29436802836676385,-0.18621070263786965
256.0000000000029,31.76878595026099,0.2936966455876521,-0.18847163731114547
257.00000000000296,31.863977785404792,0.2909922960511301,-0.19171990804217298
258.00000000000296,31.960186164814765,0.2897295334550659,-0.19694970886490148
259.00000000000296,32.054280499204054,0.2884973118068237,-0.20298419475944218
260.00000000000296,32.15020346250555,0.28796056829516237,-0.2060603003217074
261.00000000000296,32.245379797338536,0.2855673951920376,-0.20997448908493865
262.000000000003,32.34136683152594,0.285463176608431,-0.2157354048004998
263.000000000003,32.43297380161614,0.282246839035021,-0.21848936355737258
264.000000000003,32.53040093465362,0.2821805319728442,-0.22257295947754052
265.00000000000307,32.62611265934987,0.28203856844965214,-0.22796554888006604
266.00000000000307,32.72075925110378,0.27900617779500214,-0.23254664721325735
267.00000000000307,32.8179954708266,0.2783178918638371,-0.2390326598506345
268.00000000000307,32.91221207594309,0.27799483497965666,-0.24608808378284852
269.00000000000307,33.00716915227285,0.27896642217456225,-0.2525581295252386
270.0000000000031,33.103563465631154,0.27695637605171547,-0.256322229796083
271.0000000000031,33.19798609915329,0.27743690615997124,-0.2629720220389844
272.0000000000031,33.293321005118095,0.2744771925186249,-0.2676588191624858
273.0000000000032,33.388270998394404,0.276197060180154,-0.2739686624719404
274.0000000000032,33.48486701927381,0.2757525337211744,-0.28082309937986105
275.0000000000032,33.580387578069356,0.27656644406412023,-0.28777744589768206
276.0000000000032,33.67607348389842,0.27595783141070507,-0.29322098606032787
277.0000000000032,33.77094680395515,0.27646015386935247,-0.29942942181021914
278.00000000000324,33.86663787938466,0.27599636721646476,-0.3066138593720056
279.00000000000324,33.96280841700706,0.2767301855725567,-0.31350598752985226
280.00000000000324,34.05806451207256,0.27627966396683085,-0.3235370854919406
281.0000000000033,34.15307898183118,0.27405128228311015,-0.3318916218091825
282.0000000000033,34.24907087060921,0.2737180165301673,-0.33790407758076757
283.0000000000033,34.34522951815842,0.27572182784575294,-0.34616659715859477
284.0000000000033,34.44062308625997,0.2764719945080399,-0.35418606620453374
285.0000000000033,34.535606409856406,0.27443419925472623,-0.3620838380348017
286.00000000000335,34.632780513423256,0.27546489142982533,-0.37228944272612496
287.00000000000335,34.72705578026382,0.2743418891636359,-0.38169763569343607
288.00000000000335,34.82327209012996,0.2743024224902555,-0.3922745531383103
289.0000000000034,34.916320548651235,0.27585398205673173,-0.40282248176343316
290.0000000000034,35.01328743472544,0.2774510243104765,-0.41239857836437954
291.0000000000034,35.10851253329049,0.27578617930748667,-0.4209424114979563
292.0000000000034,35.204978626463195,0.2746036657774422,-0.4305328283821419
293.0000000000034,35.300647392797316,0.27537072480418084,-0.4387766875183443
294.00000000000347,35.395347672085514,0.2814346658388961,-0.45013638939190326
295.00000000000347,35.49278187258666,0.3044567125391173,-0.46105795574392827
296.00000000000347,35.58801444041024,0.3178023571816899,-0.47329439079918245
297.0000000000035,35.684334401019306,0.3226889332276182,-0.4862443028649466
298.0000000000035,35.7805968271807,0.3266808795336435,-0.4973607028185585
299.0000000000035,35.87570509923224,0.3258828362782005,-0.5081837214053233
300.0000000000035,35.97000000000029,0.32601770620979453,-0.5209190000106663
301.0000000000035,36.068036265627974,0.3268277474107317,-0.5355869549662096
302.0000000000036,36.16371314991856,0.3256090616899692,-0.548723670004982
303.0000000000036,36.25947397985895,0.3272432742095352,-0.5625313737039574
304.0000000000036,36.355200322550935,0.3246097533777028,-0.5774387556513103
305.00000000000364,36.451433069747964,0.3260883435279055,-0.5924471338936792
306.00000000000364,36.5475956270101,0.3274553906560724,-0.6069732037040225
307.00000000000364,36.6430783455567,0.3236808675632488,-0.6228530635798171
308.00000000000364,36.740000000000364,0.32395363908945307,-0.6391582634895854
309.00000000000364,36.83542870969181,0.3222295640538871,-0.6520943353265989
310.0000000000037,36.93168336759838,0.3219534175338789,-0.6676183490780319
311.0000000000037,37.02788042673503,0.31983450770605876,-0.685338791438368
312.0000000000037,37.12481271843642,0.3179920107472483,-0.7041356722913314
313.00000000000375,37.21972740933379,0.31781202147942667,-0.7220045816706775
314.00000000000375,37.31730037192814,0.318075770733562,-0.7403910290533133
315.00000000000375,37.41326798523094,0.31833104128260203,-0.7587717646655667
316.00000000000375,37.51011102175729,0.3164248651911538,-0.7776185362739714
317.00000000000375,37.60608105361662,0.3181175769764115,-0.7984099839804966
318.0000000000038,37.7021263056605,0.3154260467211143,-0.8191016918234473
319.0000000000038,37.79892193315802,0.31520793711762385,-0.840240469319613
320.0000000000038,37.89117524368816,0.3144470213758627,-0.8610387041384344
321.00000000000387,37.98951769312285,0.3148528905948732,-0.8831598270795284
322.00000000000387,38.08615419260702,0.31374180994853945,-0.9057734091068066
323.00000000000387,38.183540898554696,0.3138843089639364,-0.9274860302795345
324.00000000000387,38.279361952925115,0.3102446060684665,-0.9523043824393258
325.00000000000387,38.376077965116245,0.3123838449490831,-0.9753272593331572
326.0000000000039,38.4694441069616,0.31093633587117414,-0.9992947083557078
327.0000000000039,38.56804480993534,0.3115925781801232,-1.0261413515005167
328.0000000000039,38.66458767959996,0.31043986879248675,-1.0514408121419354
329.000000000004,38.76165426147299,0.31015880850046584,-1.079572254835766
330.000000000004,38.856889062509204,0.306656385808848,-1.1039689538280237
331.000000000004,38.95522420889721,0.3075374721344355,-1.133313473363844
332.000000000004,39.051760587245035,0.30504785271239365,-1.1611353261404393
333.000000000004,39.14812300703194,0.30235222305799386,-1.188810793087396
334.00000000000404,39.24515775422154,0.30140990027871617,-1.2206136934548129
335.00000000000404,39.34191119225366,0.2975427258236254,-1.247601960208283
336.00000000000404,39.439068699347004,0.2952540115131674,-1.2757816775078106
337.0000000000041,39.53411925536272,0.29154846438538323,-1.3073547444401763
338.0000000000041,39.631995840942366,0.2877430761009006,-1.3381381096947997
339.0000000000041,39.72731826680935,0.2829503502056926,-1.3710713150769815
340.0000000000041,39.825332679496206,0.2785291404822598,-1.4022671806096438
341.0000000000041,39.920000000000435,0.2717270672087883,-1.4357416268268324
342.00000000000415,40.01740135101023,0.26705511440910457,-1.464774492360068
343.00000000000415,40.11402677163791,0.2646165374887676,-1.4975206942722181
344.00000000000415,40.21083257520667,0.25901481457647835,-1.5294996403484142
345.0000000000042,40.307093013713164,0.2515911590689574,-1.5590002868461412
346.0000000000042,40.40360466699835,0.24482863069845656,-1.5890251960267463
347.0000000000042,40.50000000000039,0.24023134000817292,-1.6173405780625831
348.0000000000042,40.5969105044087,0.23314398278209686,-1.645646437738427
349.0000000000042,40.69345854109411,0.22902983000994948,-1.6712041479605806
350.00000000000426,40.790671110172006,0.22581613199678452,-1.6991018457604774
351.00000000000426,40.88529101022905,0.22228267156399406,-1.7231030184955607
352.00000000000426,40.9834081594744,0.2197556314816006,-1.7457583288620468
353.0000000000043,41.08020774940185,0.217242101165104,-1.7682092522160513
354.0000000000043,41.17804703389324,0.216673213874435,-1.7881163856941753
355.0000000000043,41.275336485084615,0.2145696409479766,-1.805836817511735
356.0000000000043,41.37248921106893,0.21302892027278275,-1.821178565530667
357.0000000000043,41.46937395874655,0.21438239375535345,-1.8355740959212583
358.0000000000044,41.56637008713967,0.2122272732705454,-1.8506949588398696
359.0000000000044,41.66310516825708,0.2141526555839835,-1.862662746352223
360.0000000000044,41.75978159179177,0.213352782109685,-1.8754016242250002
361.00000000000443,41.8579810632594,0.21515700632892115,-1.8874504720427456
362.00000000000443,41.95514005937026,0.2135653465792926,-1.8971200536005846
363.00000000000443,42.051321573927474,0.21482487410968493,-1.9056171761556175
364.00000000000443,42.148247212783566,0.21589436539893242,-1.9125690001072542
365.00000000000443,42.246697188831305,0.21655566469305054,-1.9207167681723765
366.0000000000045,42.343266566675176,0.2217834569161375,-1.9279714654905655
367.0000000000045,42.441049371245235,0.22137728644709642,-1.9350782625676186
368.0000000000045,42.536417842656576,0.2239312824425586,-1.942203017716876
369.00000000000455,42.636119286258584,0.2253875755674261,-1.948036389184447
370.00000000000455,42.73318893410926,0.22482308049947064,-1.954163341664545
371.00000000000455,42.83000000000043,0.22602531662185077,-1.96050977987182
372.00000000000455,42.92752011068047,0.2251736639031865,-1.9659357622210072
373.00000000000455,43.02433274671879,0.2250415325109842,-1.9712709632271856
374.0000000000046,43.118887361202425,0.22536490549691296,-1.9779520731033755
375.0000000000046,43.219093568171466,0.22496378741745848,-1.9833421355574976
376.0000000000046,43.31658973164085,0.22660531349009583,-1.987921538269061
377.00000000000466,43.41353503146541,0.22707797940464192,-1.993500777272165
378.00000000000466,43.51132662049531,0.228502082105574,-1.9978484465580633
379.00000000000466,43.60808517219938,0.22712506417741635,-2.001472342572195
380.00000000000466,43.70462929304101,0.22924572788975728,-2.00534628156805
381.00000000000466,43.80299252337947,0.2305926394161204,-2.0100555465700185
382.0000000000047,43.8998031598976,0.22995214079610254,-2.012761577274655
383.0000000000047,43.99722499766063,0.23145532097451849,-2.018018993649521
384.0000000000047,44.094614478730726,0.2309583131440771,-2.0219405291179804
385.0000000000048,44.191282375976705,0.23256603979242724,-2.027029590300056
386.0000000000048,44.289048538198266,0.23408946611527676,-2.032035536383607
387.0000000000048,44.38645169077217,0.23248434680979746,-2.0361076525626984
388.0000000000048,44.48104812457973,0.2340503596472539,-2.039619101176655
389.0000000000048,44.580702082026676,0.2329786220822716,-2.0446167050927504
390.00000000000483,44.67802176693661,0.2338849696133387,-2.0478347551613387
391.00000000000483,44.77618534233012,0.2332360483133712,-2.0508266348077715
392.00000000000483,44.872304053936915,0.2329838291560404,-2.0516442906567374
393.0000000000049,44.96956534470502,0.2350212862080072,-2.0553644937229505
394.0000000000049,45.06788204656736,0.23436438373892296,-2.059783013874208
395.0000000000049,45.16571557261688,0.23419228839340095,-2.0645825024567253
396.0000000000049,45.262908711630516,0.23682325637390048,-2.068719779012413
397.0000000000049,45.36078803011043,0.23503573525420884,-2.0746915446458027
398.00000000000495,45.45473019090717,0.23465079054450458,-2.0751514887807034
399.00000000000495,45.55575119175933,0.23919395710572244,-2.0784136296543805
400.00000000000495,45.654574541937386,0.2371088492699074,-2.0820548520974462
401.000000000005,45.75155390558879,0.23919995237530955,-2.0876144109402097
402.000000000005,45.849049002262504,0.24198566354328155,-2.092197971379135
403.000000000005,45.94712445137986,0.24189231487529242,-2.0974124459909653
404.000000000005,46.04553213474742,0.24488714034386488,-2.10118348778456
405.000000000005,46.14228279685853,0.24587707363534683,-2.1027273455298303
406.00000000000506,46.24126763115998,0.246831303378622,-2.1066197302419623
407.00000000000506,46.3384410350525,0.2468706104820216,-2.111326623039055
408.00000000000506,46.435931370471046,0.24889899737897683,-2.1152177353029034
409.0000000000051,46.53375187945039,0.2496462712340127,-2.1172275858970497
410.0000000000051,46.63168025110072,0.2495077087150986,-2.12401692016364
411.0000000000051,46.72990717200276,0.2535246472638026,-2.1275921084615947
412.0000000000051,46.826059284418484,0.2544257567104029,-2.1305971556424237
413.0000000000051,46.92422813860308,0.2559983484933651,-2.13399832659987
414.0000000000052,47.023204318163856,0.25611461033764477,-2.1398679851080247
415.0000000000052,47.120714348895326,0.2571463010285345,-2.1445378066275915
416.0000000000052,47.219206804392456,0.25857001413678876,-2.148944558837983
417.00000000000523,47.31687476623563,0.2586484723135287,-2.1518666580813197
418.00000000000523,47.413141610035105,0.2592426968778976,-2.1577876822818043
419.00000000000523,47.5125171104345,0.25989342957476724,-2.1609932498558573
420.00000000000523,47.60915889760007,0.2594898209330593,-2.164553276676566
421.00000000000523,47.7061468005393,0.25837923638893456,-2.1704044696545752
422.0000000000053,47.8047195241954,0.26154488464471254,-2.1732328276723747
423.0000000000053,47.90335296857698,0.2654382213028703,-2.177749423432071
424.0000000000053,48.00098954473613,0.2635281165779214,-2.1817241181906586
425.00000000000534,48.09864286239286,0.265065225645307,-2.1858395296601576
426.00000000000534,48.197050675817586,0.26745674904698824,-2.1901819949477455
427.00000000000534,48.29459790886365,0.2648461711298722,-2.192961215268022
428.00000000000534,48.39220331666804,0.26507898474456815,-2.1991471072135402
429.00000000000534,48.49035820034448,0.2666856740025538,-2.203480834699948
430.0000000000054,48.58783369163592,0.2660729510690869,-2.2091039589457866
431.0000000000054,48.68666606374528,0.26610584876556587,-2.2133832026406015
432.0000000000054,48.78420951765458,0.26747839606390666,-2.216539255060317
433.00000000000546,48.882416306014434,0.26583220294294896,-2.2222931949758906
434.00000000000546,48.980634108247266,0.2666240959836208,-2.2254424812483147
435.00000000000546,49.07882037324652,0.26547011199861725,-2.2285689743856296
436.00000000000546,49.176263013398575,0.26607720006563607,-2.2345657368681646
437.00000000000546,49.27382156351005,0.2674255312247654,-2.239145300801268
438.0000000000055,49.37275762633445,0.26643045503882684,-2.242147184962062
439.0000000000055,49.47090361408964,0.2674952606683445,-2.247585892205877
440.0000000000055,49.56814791775222,0.2681616709029472,-2.251725349033649
441.00000000000557,49.66671659685721,0.2654789379526832,-2.2553650085666836
442.00000000000557,49.76569567350476,0.2654082721025228,-2.258856849529234
443.00000000000557,49.863380074988065,0.2647021650340251,-2.2642191489426935
444.00000000000557,49.961338202769895,0.2647143312605892,-2.2683340259911473
445.00000000000557,50.05960110778027,0.26403151205580727,-2.2719560473852405
446.0000000000056,50.157378104190435,0.2629656993946955,-2.2755460074579843
447.0000000000056,50.25592434315517,0.26480813259894076,-2.280675694073518
448.0000000000056,50.35482947635416,0.2636564511643783,-2.2847998668812455
449.0000000000057,50.4525425095362,0.2635208412387085,-2.289073370654066
450.0000000000057,50.55164777199605,0.26201590645842787,-2.2932128361973314
451.0000000000057,50.649530475315416,0.26128123153936356,-2.296012427537325
452.0000000000057,50.748473477733825,0.2588713033939547,-2.2978488746632664
453.0000000000057,50.84684786252235,0.2618726364578498,-2.3040578484893026
454.00000000000574,50.9459461090491,0.26231261250543353,-2.3079686468912977
455.00000000000574,51.04426723409216,0.2636132265746129,-2.3141528032647094
456.00000000000574,51.14257420921557,0.26327699647536273,-2.3156231822594875
457.0000000000058,51.240977784048894,0.26419313425241986,-2.3199210868256603
458.0000000000058,51.339094604330064,0.2617017387259466,-2.323477215872387
459.0000000000058,51.437738769554684,0.2640739824328816,-2.326003033999556
460.0000000000058,51.53620030333561,0.2627330537873302,-2.329845674314913
461.0000000000058,51.633606795015666,0.26074441366361634,-2.3342797018532915
462.00000000000585,51.7332046930452,0.26194744995897545,-2.3384304891978775
463.00000000000585,51.83231547538801,0.26252242321071106,-2.34152923240499
464.00000000000585,51.930101976829036,0.26255855614621304,-2.3448084458647642
465.0000000000059,52.02884389965313,0.2627221605401458,-2.3471619232208396
466.0000000000059,52.12685510762105,0.26184335112679924,-2.3503759867787277
467.0000000000059,52.226334304203604,0.2632676068413272,-2.354521932054958
468.0000000000059,52.32474795962299,0.2648153077344106,-2.358305054657794
469.0000000000059,52.423561448781555,0.26564958077125433,-2.360894317963661
470.00000000000597,52.521931557331804,0.2652190042974256,-2.365034002931345
471.00000000000597,52.61950775373636,0.26520449794832357,-2.367676482216698
472.00000000000597,52.71847823900506,0.26657589236852075,-2.3714349622452633
473.000000000006,52.8163361242742,0.26769139414792253,-2.3754463161602635
474.000000000006,52.91509857054481,0.2679662494708708,-2.3782749420002745
475.000000000006,53.01383503401793,0.2715098182963619,-2.380886312625322
476.000000000006,53.11254792607046,0.2716511425128747,-2.384858458509776
477.000000000006,53.21100517023646,0.2696262107050724,-2.3862548016381435
478.0000000000061,53.309702486398365,0.26883619271188597,-2.390228327824522
479.0000000000061,53.40833575012973,0.26849914548567855,-2.394054500246411
480.0000000000061,53.506846906951665,0.2665994587702083,-2.3982230651871133
481.00000000000614,53.60621016261924,0.26982648883325916,-2.400066548736614
482.00000000000614,53.70412567393084,0.2721629115620414,-2.4019409108716685
483.00000000000614,53.80306968823835,0.27117243324134543,-2.4055182709936447
484.00000000000614,53.899221744963526,0.27067381392998113,-2.4099139474705384
485.00000000000614,54.00009442479124,0.269708815013358,-2.4142547563603616
486.0000000000062,54.09961422999945,0.2696338786803771,-2.4162172196758283
487.0000000000062,54.19807604419702,0.2694074551150841,-2.417602564851948
488.0000000000062,54.294943671455954,0.2677782013518054,-2.4201342784878297
489.00000000000625,54.39522337633243,0.2685597364857159,-2.423320487306891
490.00000000000625,54.49391876555632,0.2710532387783013,-2.4260567236191926
491.00000000000625,54.59269070910781,0.2705466024772819,-2.428752702689344
492.00000000000625,54.69067240025974,0.267923555130469,-2.433602272457948
493.00000000000625,54.78989154823071,0.26916390188052747,-2.4371809060678937
494.0000000000063,54.887321415289605,0.27012040863061754,-2.440210492147531
495.0000000000063,54.98687345455494,0.27150439538183657,-2.441581202835157
496.0000000000063,55.08606011627431,0.26831318448180297,-2.442912141887626
497.00000000000637,55.185574238134954,0.27149614776592723,-2.4468946573762302
498.00000000000637,55.284243962559415,0.26977527126010076,-2.451007235092761
499.00000000000637,55.3833433274147,0.2687152677586688,-2.453806490144172
500.00000000000637,55.48200448704347,0.268806954680502,-2.4563986794833506
501.00000000000637,55.580855579167654,0.26689341610762674,-2.4579087806976267
502.0000000000064,55.680000000000646,0.26554477084567335,-2.460570341718653
503.0000000000064,55.7792820982302,0.26501505049877994,-2.4620198454106834
504.0000000000064,55.87818211409343,0.2639245132633845,-2.4680207080202075
505.0000000000065,55.97737926587973,0.2619160473559639,-2.468059531003621
506.0000000000065,56.07617724838838,0.2639286032665542,-2.471404413527922
507.0000000000065,56.17523151730693,0.26545277551487306,-2.4736660337287804
508.0000000000065,56.2739258101589,0.26562396283341505,-2.475134089711173
509.0000000000065,56.37298771488513,0.2617379645414294,-2.4792706881093234
510.00000000000654,56.472079321672105,0.26194991433958636,-2.48139752683791
511.00000000000654,56.57123927940206,0.2621669382535228,-2.483951762591471
512.0000000000066,56.66843608901667,0.26286642042657554,-2.486802391367173
513.0000000000066,56.769494550274004,0.2628136067354848,-2.4894485129261676
514.0000000000066,56.86849002086632,0.2614767575398261,-2.4914571440135402
515.0000000000066,56.96764992366112,0.2620908402885074,-2.4935641820743255
516.0000000000066,57.066514556913916,0.2626086412453874,-2.4943659555430138
517.0000000000066,57.16580607052017,0.26454025669803943,-2.498001270893165
518.0000000000066,57.26482152748394,0.26238716010101465,-2.500249878881223
519.0000000000066,57.36404893850916,0.26250135155713045,-2.502577699283111
520.0000000000066,57.463636134874974,0.2612325311125947,-2.5040344448192697
521.0000000000067,57.56262355658344,0.26096005256886573,-2.5044999182475944
522.0000000000067,57.661686501132166,0.2612042778949786,-2.5085024218619507
523.0000000000067,57.75949055490062,0.2618153272480668,-2.5110775647204973
524.0000000000067,57.86063324606545,0.2595306168954929,-2.5130962162446107
525.0000000000067,57.959603098259095,0.2595178558370112,-2.5150172755922284
526.0000000000068,58.056542111273004,0.25848983045247176,-2.517651953928011
527.0000000000068,58.15832548910768,0.2588464784165029,-2.5188460529038466
528.0000000000068,58.256688434252894,0.25746447032264713,-2.519740736589045
529.0000000000068,58.35671463775654,0.260057005702115,-2.521658778850801
530.0000000000068,58.4563553602362,0.25897461679186595,-2.5255083042327113
531.0000000000068,58.5553465031351,0.2598583882905961,-2.5271154106508247
532.0000000000068,58.65470154261485,0.2607158446791368,-2.529728555947778
533.0000000000068,58.7536967018193,0.25959200257819315,-2.53123126057865
534.0000000000068,58.85361338223548,0.25942587172324705,-2.5340785591953767
535.0000000000068,58.95260777148607,0.2605259889894518,-2.536426597485728
536.0000000000068,59.051980357560765,0.26104467606604936,-2.5385838406923193
537.0000000000069,59.152117452943905,0.2604044523704288,-2.540573171711727
538.0000000000069,59.250000000000675,0.2605242871837395,-2.5425762176553186
539.0000000000069,59.35093209892127,0.2615998277004036,-2.543576170664968
540.0000000000069,59.450408973180565,0.2609636606839688,-2.545896483650459
541.0000000000069,59.548969690350695,0.26007195920279497,-2.547190611600823
542.000000000007,59.64865653308738,0.25749660820185455,-2.5498576091046754
543.000000000007,59.74722445384351,0.2563191967987877,-2.552962392576002
544.000000000007,59.84741732595088,0.2568462414724936,-2.555115588376087
545.000000000007,59.94715071220159,0.256542554225835,-2.5562492760800835
546.000000000007,60.04471823911136,0.256760330123739,-2.5563717392908645
547.000000000007,60.14629638756867,0.25300596665695707,-2.5577449331405484
548.000000000007,60.244887825008846,0.2540327426618516,-2.5603476423574625
549.000000000007,60.345754236473,0.2545531552163518,-2.56308516278222
550.000000000007,60.444397895149685,0.25619718055817287,-2.5654090188500405
551.000000000007,60.54404317201335,0.25364531600770984,-2.566772860466076
552.000000000007,60.644175754905596,0.2536773339414554,-2.566729387580418
553.0000000000072,60.74374749563943,0.2526624242737379,-2.5679774873636223
554.0000000000072,60.843365978063034,0.25075139076760117,-2.5720952687365832
555.0000000000072,60.94383554591946,0.2500555869307854,-2.5733739211119637
556.0000000000072,61.04332782929671,0.2505416822042853,-2.5746696146658437
557.0000000000072,61.14228235742075,0.24759169430219452,-2.577276107242283
558.0000000000073,61.2413900976477,0.24967520147731326,-2.5785671405148927
559.0000000000073,61.34072245442879,0.25073111202934273,-2.5799001162111566
560.0000000000073,61.44109994909374,0.24910453635086272,-2.5804334298169866
561.0000000000073,61.54061244049507,0.24929023610178824,-2.5815400712193997
562.0000000000073,61.63938161588446,0.24552146807940317,-2.5841779559819607
563.0000000000073,61.738794071081564,0.24634740333225913,-2.5868315328110274
564.0000000000073,61.83479000008364,0.24509382724825113,-2.5880944602386178
565.0000000000073,61.93647406732604,0.24314667306817184,-2.5907640795657505
566.0000000000073,62.03375905436542,0.24373778646238817,-2.5930498487013063
567.0000000000073,62.13593496569373,0.24608892397510979,-2.593347598297597
568.0000000000074,62.23455114836096,0.24345308179128128,-2.59232751348592
569.0000000000074,62.334170800126806,0.24163399160596905,-2.595701624088467
570.0000000000074,62.43288648267715,0.24164623249434092,-2.596234571037762
571.0000000000074,62.532638414108135,0.23795477655270583,-2.597350372911485
572.0000000000074,62.632001414076385,0.2372536469299341,-2.5986589959013315
573.0000000000074,62.732366524469946,0.23596988520422352,-2.601311462958967
574.0000000000074,62.83126750579532,0.23500024514619647,-2.6025872614931833
575.0000000000075,62.93128748056173,0.23458151219041884,-2.6040180021237527
576.0000000000075,63.03009478006453,0.23227821810040097,-2.6052812532695495
577.0000000000075,63.130000000000756,0.2320732707239846,-2.60623321656433
578.0000000000075,63.230103306953154,0.23140499917980328,-2.6052611350360375
579.0000000000075,63.328684252242965,0.23011545042969328,-2.6092311280809866
580.0000000000075,63.42882716838368,0.22982727901441968,-2.6105538400932895
581.0000000000075,63.52819860124077,0.23132716161957215,-2.612666260181765
582.0000000000075,63.627641090492695,0.2306125340537681,-2.6144123414558798
583.0000000000075,63.72610757539109,0.23127825784347122,-2.6167167299895047
584.0000000000076,63.82666438293844,0.23011586116474048,-2.6178187237205464
585.0000000000076,63.92635058884392,0.23129347275452944,-2.6180753919497652
586.0000000000076,64.02647039079677,0.2323266199609163,-2.6197626936937732
587.0000000000076,64.12567170045047,0.2324245333069377,-2.6210110637016983
588.0000000000076,64.22487857256472,0.23201745882058317,-2.6210787575188177
589.0000000000076,64.32483490285348,0.2309446492269966,-2.621066490316601
590.0000000000076,64.42474446043262,0.22959925797882771,-2.6223727634193432
591.0000000000077,64.52502029355362,0.22942975123373432,-2.6250943273141134
592.0000000000077,64.62415323959675,0.2281563306554608,-2.626551270547962
593.0000000000077,64.72362379729894,0.22991106867925137,-2.629038905124358
594.0000000000077,64.82374324073278,0.2282254012965179,-2.631617941088365
595.0000000000077,64.92338049798346,0.2259403491898135,-2.6317324732231167
596.0000000000077,65.02312615151827,0.22865890684625967,-2.632930298024127
597.0000000000077,65.12298089951159,0.2286178512994902,-2.632941492297775
598.0000000000077,65.22302846345505,0.23031156650394077,-2.63292598449465
599.0000000000077,65.32132177366763,0.23207994804653675,-2.634243289255789
600.0000000000078,65.42152625263887,0.22988457349166283,-2.635669558013843
601.0000000000078,65.52179190115416,0.22985282956215403,-2.6376951359659175
602.0000000000078,65.62165810670336,0.22907014270672665,-2.638260328238226
603.0000000000078,65.7206799147505,0.2281562485259182,-2.64082943926275
604.0000000000078,65.82051860421304,0.22580621362237133,-2.6408446870662408
605.0000000000078,65.91951248019696,0.22557231843508763,-2.6434587771307223
606.0000000000078,66.01990829618012,0.2281943226666086,-2.6447376662556805
607.000000000008,66.11990302388776,0.22794068659706704,-2.6441196919023047
608.000000000008,66.21919775665053,0.2258192440698637,-2.644788149701914
609.000000000008,66.31989045777945,0.2264055842501621,-2.6461094157877687
610.000000000008,66.41970973970528,0.22662732806020053,-2.646746323034362
611.000000000008,66.51952076040959,0.22871151141130502,-2.648740071140824
612.000000000008,66.61775670565108,0.22500396704687145,-2.6513528300342695
613.000000000008,66.71860254371134,0.22536174880836368,-2.65271379021522
614.000000000008,66.81794702280072,0.22592916650230427,-2.6532790560486266
615.000000000008,66.91796288427966,0.22531205991826647,-2.6559719650680336
616.0000000000081,67.01796530744714,0.22514616574846058,-2.6546831648820364
617.0000000000081,67.11901043384125,0.22697316823492797,-2.6559883032572977
618.0000000000081,67.21900738953839,0.22518638482779404,-2.657312440940159
619.0000000000081,67.3191896985064,0.22377278172413403,-2.657295394305171
620.0000000000081,67.41906800811549,0.22634473143403497,-2.65885901788808
621.0000000000081,67.51850698521243,0.2280683661791394,-2.660590742526499
622.0000000000081,67.61789064335295,0.22780091028323202,-2.66169528548007
623.0000000000082,67.71802173142852,0.22940668469537093,-2.66325193008924
624.0000000000082,67.81794828944055,0.2305401763081392,-2.6658694076012197
625.0000000000082,67.91770585175885,0.22866119003022983,-2.6646736063964815
626.0000000000082,68.01818419668092,0.228642986280976,-2.66586014273506
627.0000000000082,68.11825302336183,0.22929535524126143,-2.6671809401419617
628.0000000000082,68.21812005434862,0.22977483708229615,-2.6684620919222217
629.0000000000082,68.31630128187435,0.23159121475710454,-2.6710172989637915
630.0000000000082,68.41779099335258,0.2328916226619416,-2.6738108793489737
631.0000000000082,68.51749415150897,0.2312529911836596,-2.672452089409263
632.0000000000083,68.61779702772098,0.23465754355701537,-2.675096302788096
633.0000000000083,68.71694411079137,0.23494724187103955,-2.676295505052025
634.0000000000083,68.81709860464579,0.2336055314396117,-2.676400038789076
635.0000000000083,68.91812280407669,0.23552845796036143,-2.6777193180826195
636.0000000000083,69.01779877434917,0.23504222554817647,-2.677716957381456
637.0000000000083,69.11902420742284,0.23288605311468008,-2.6803685482111423
638.0000000000083,69.2187150184053,0.23028939376734736,-2.6819974248870757
639.0000000000084,69.31789456088474,0.2270900923101413,-2.6831159163780685
640.0000000000084,69.41902133806653,0.22489894858308762,-2.6833707721370232
641.0000000000084,69.5185287991849,0.2217255728986338,-2.684739736543664
642.0000000000084,69.61825737088425,0.21777333618524627,-2.686055050936666
643.0000000000084,69.71839403557323,0.2154190436121099,-2.687389369050928
644.0000000000084,69.8184696651587,0.21173507126512994,-2.6887034961247
645.0000000000084,69.91836647758461,0.2056898618736963,-2.6884464204993446