File: 01_Data/Plastic_Laminate_Countertop_Laminate/STA/N2/10K_min/Plastic_Laminate_Countertop_Laminate_STA_N2_10KData_220930_R1.csv
##Temp./Â°C,Time/min,DSC/(mW/mg),Mass loss/mg
51.0,10.739496911467656,0.027210318595687566,-0.0020140361511886695
52.100000000000016,11.119897698882426,0.06775358151632838,-0.001988670969861328
53.20000000000003,11.373381879706894,0.09445319788013751,-0.0020044086744297474
54.30000000000005,11.584906922139103,0.11519653447129441,-0.0033468763508093247
55.40000000000006,11.770811715005854,0.13290049948725668,-0.0016454569996215973
56.50000000000008,11.942626248028803,0.14398880209981013,-0.000734867906404979
57.600000000000094,12.1044389124607,0.15633718958754428,-0.0011951072927263162
58.70000000000011,12.25878495424662,0.1661584543606902,-0.001689138273042179
59.800000000000125,12.410208517193686,0.1757866688213514,-0.002495019027654699
60.90000000000014,12.556739487317905,0.18196405469906796,-0.0018338081498843195
62.000000000000156,12.698235259053428,0.18843574849023859,-0.002235391013917898
63.10000000000017,12.836959802045138,0.1968055245766156,-0.0022602067132715398
64.20000000000019,12.974808448748547,0.20524540442343286,-0.0019589102100465716
65.30000000000021,13.108808884395291,0.21137263961413422,-0.002446014674446939
66.40000000000022,13.242635904426049,0.21726414313065923,-0.0023821655079330206
67.50000000000023,13.373081573522867,0.22210888140748852,-0.0023290353119578278
68.60000000000025,13.50291722329954,0.2293232426622831,-0.0035853911658225712
69.70000000000027,13.629970143412761,0.233975172421808,-0.0033238158337343116
70.80000000000028,13.755154496371027,0.2387931016531164,-0.003406582115647261
71.90000000000029,13.881172201170108,0.24415332465155237,-0.004967669700512989
73.00000000000031,14.006023218787092,0.24841273424771138,-0.00491539923248796
74.10000000000034,14.130433659973455,0.25332459133836105,-0.006336315015907701
75.20000000000034,14.252704719970739,0.2578356064662086,-0.006372578214098201
76.30000000000035,14.375747107080457,0.2618038749779419,-0.005061760174445151
77.40000000000038,14.496391233797723,0.26554755204772773,-0.006406813358017516
78.5000000000004,14.615304672985017,0.2703839128213039,-0.006418970306440563
79.6000000000004,14.735413136912179,0.27562316048751934,-0.0076912660578329906
80.70000000000041,14.853562713136546,0.27845474382265156,-0.007962221154482751
81.80000000000044,14.971667616650114,0.28203639263240776,-0.009642656398061167
82.90000000000046,15.087968808689121,0.28487278756855605,-0.009007818013457847
84.00000000000047,15.202727114280266,0.28640668846355843,-0.010901768726112149
85.10000000000048,15.32124141190811,0.29019582852118964,-0.011678294331247674
86.2000000000005,15.434430450590284,0.29193646888315505,-0.011647166580297963
87.30000000000052,15.550098757924523,0.2957631960495226,-0.011651577926975243
88.40000000000053,15.663743715924923,0.2959104733267842,-0.011647881679150096
89.50000000000054,15.776812356186475,0.2976191159127536,-0.012961484559578906
90.60000000000056,15.889682018539188,0.2982681463165665,-0.012960047766320315
91.70000000000059,16.000578739376174,0.2994422693734803,-0.0129615540888679
92.8000000000006,16.114534607747792,0.2998267920455061,-0.01427975445176033
93.9000000000006,16.224764078065846,0.3016107156490764,-0.0156221603310005
95.00000000000063,16.336219991845034,0.3017313523891082,-0.016266975766754843
96.10000000000065,16.445780344004234,0.3020912093653553,-0.016916997488815255
97.20000000000066,16.55623860765165,0.30424069303703993,-0.017071889319330236
98.30000000000067,16.665907356058298,0.30244898903655715,-0.016938209178683383
99.40000000000069,16.775234927578968,0.3019029746349975,-0.018229804743687072
100.50000000000071,16.884876610820427,0.3033346336762197,-0.01859508915565522
101.60000000000072,16.994616445060654,0.3040405723443842,-0.01820733726817192
102.70000000000073,17.10275131734231,0.3034515251157678,-0.01822821708660749
103.80000000000075,17.21146432704696,0.30120865497837,-0.01922906323793816
104.90000000000077,17.321211282737288,0.30060391440440715,-0.019551822984320122
106.00000000000078,17.428176940656776,0.29930791093377984,-0.019567063363433057
107.10000000000079,17.53580191814055,0.29860385997869887,-0.019474317803811925
108.20000000000081,17.644258559675283,0.3003581433598861,-0.02053987944751201
109.30000000000084,17.750866933813032,0.2992170481796509,-0.020849749249562954
110.40000000000084,17.85957500205418,0.29830140851256715,-0.02087190072704015
111.50000000000085,17.968617894708398,0.2988247215832708,-0.021858474541178285
112.60000000000088,18.074844889856887,0.2990095352292377,-0.019500630870467273
113.7000000000009,18.18293514399893,0.29777784349621395,-0.02217975616092227
114.8000000000009,18.290038537811817,0.29704684440054174,-0.02151613187944834
115.90000000000092,18.397888330808314,0.2983212474674881,-0.022192471574881356
117.00000000000094,18.504465680927332,0.29672094724351494,-0.022161386157453666
118.10000000000096,18.612744348695717,0.2958801021528875,-0.02352976710770438
119.20000000000097,18.719268774462606,0.2959363171126428,-0.023499976990765337
120.30000000000098,18.825272761161465,0.2954106129273769,-0.023500047917442313
121.400000000001,18.932276612726906,0.29558013071108746,-0.02339922816611706
122.50000000000102,19.039353096441587,0.29435785436571504,-0.02487263390243344
123.60000000000103,19.145631334289046,0.29478389006967953,-0.02480997221173542
124.70000000000104,19.252899622924417,0.2960371312319896,-0.024495369878325235
125.80000000000106,19.359835004501438,0.29712093637534,-0.024789794664224374
126.90000000000109,19.464538687245337,0.2970533570377313,-0.024819708628954995
128.00000000000108,19.570629588516088,0.297358000723317,-0.02250578965218475
129.1000000000011,19.676995782969925,0.29747824850830173,-0.02400272037181761
130.20000000000113,19.782166639285588,0.29791328392449956,-0.02526028402088354
131.30000000000115,19.89001566440784,0.29929410901201736,-0.026570029757726044
132.40000000000117,19.995510538014102,0.29938026913703286,-0.026553478326750035
133.50000000000117,20.100995232247357,0.3020902899923258,-0.026900157193751273
134.6000000000012,20.20693862108729,0.3018470787826809,-0.02657008979973563
135.7000000000012,20.312311246399112,0.30374495425376746,-0.026570289206305997
136.8000000000012,20.41891290415192,0.30288909464256375,-0.026574341618855968
137.90000000000123,20.524664661268496,0.30617434706349655,-0.027897018929329498
139.00000000000125,20.630246242586555,0.3081205779745675,-0.027912512866553385
140.10000000000127,20.731596506725406,0.3070743185836222,-0.02758431988619936
141.2000000000013,20.840560851457266,0.30969190142323855,-0.028850191045571183
142.3000000000013,20.94671818238707,0.3112416276394536,-0.029216929742867048
143.4000000000013,21.051702404701754,0.31190466526250105,-0.02821999422131727
144.50000000000134,21.156582729615746,0.31220430691661527,-0.0295397851956003
145.60000000000133,21.26139676769095,0.314781736872472,-0.02952819893155878
146.70000000000135,21.36733473455539,0.3162943279445892,-0.03052991143458783
147.80000000000138,21.473019343154096,0.3168043425074166,-0.02924428800651402
148.9000000000014,21.575169875750518,0.3192749082156481,-0.030520166355706646
150.00000000000142,21.680145019442005,0.3216269121726073,-0.030542260477936622
151.10000000000142,21.78400057683448,0.32355533405092696,-0.03184017042920395
152.20000000000144,21.889670592589255,0.32620698627279776,-0.030529182461316307
153.30000000000146,21.99514247094549,0.32715316313484644,-0.03186505518113014
154.40000000000146,22.09959575664024,0.33070985402259,-0.03435238609340274
155.50000000000148,22.203734543727318,0.3349806247706444,-0.033160277889092704
156.6000000000015,22.308133798746958,0.33442713172730065,-0.03480148884892298
157.70000000000152,22.41250845122517,0.3367695920529117,-0.035462610058064836
158.80000000000155,22.516927959910632,0.33752430496496577,-0.03545968979053438
159.90000000000154,22.6215528380234,0.3385267930889826,-0.036571467988742334
161.00000000000156,22.726298232736074,0.34140087476843617,-0.035469711001117954
162.1000000000016,22.831523416663675,0.3432105498402095,-0.036788542752423936
163.20000000000158,22.93492736214186,0.34403059188407004,-0.03678995089024051
164.3000000000016,23.040469751814886,0.34306366536581867,-0.038084640428476035
165.40000000000163,23.144410895870877,0.34576803453240534,-0.038436190033393824
166.50000000000165,23.249603171009383,0.3468995655584627,-0.03975014203651428
167.60000000000167,23.353066175534373,0.34749857951000207,-0.03974782311326219
168.70000000000167,23.45811066640995,0.3491885099485377,-0.0423792088527839
169.8000000000017,23.563265236003588,0.3503351730435179,-0.041385425113849905
170.9000000000017,23.66832021475123,0.35349864527333985,-0.04163889217911354
172.0000000000017,23.76889947725012,0.34983170041416956,-0.042710150109865896
173.10000000000173,23.876266014086593,0.3510580558514338,-0.04271015244601006
174.20000000000175,23.981154771523226,0.35202779248557214,-0.04367734444449045
175.30000000000177,24.086009520601618,0.35254206806064337,-0.045003801421080514
176.4000000000018,24.190527734603283,0.3541683337378344,-0.04402745270804287
177.5000000000018,24.29400091725663,0.352668555749551,-0.04669638225281636
178.6000000000018,24.399481745992805,0.3541561387230925,-0.04773706359734797
179.70000000000184,24.50374327061625,0.3547588006368931,-0.047979910022723615
180.80000000000183,24.608984571657768,0.35678202472870274,-0.04797990997961721
181.90000000000185,24.712543150663738,0.3561670503337654,-0.04827552404195812
183.00000000000188,24.818405926923823,0.3580038293117888,-0.050517077103143126
184.1000000000019,24.920605056872454,0.35799580171076195,-0.05062006096691496
185.20000000000192,25.02657131836838,0.3566894554952928,-0.05186353624624607
186.30000000000192,25.130807636853334,0.35824938422092345,-0.05325954901626728
187.40000000000194,25.23459936364823,0.35740166173991716,-0.05455802614419136
188.50000000000196,25.339263140580123,0.35679895315913923,-0.05587983144479036
189.60000000000196,25.442398473199745,0.3577015686722069,-0.05588923755058195
190.70000000000198,25.547469985631245,0.357732597623422,-0.05719998625639189
191.800000000002,25.65084859635776,0.3589586917226872,-0.057118068637770136
192.90000000000202,25.756197994900813,0.35969863573020905,-0.05851997979567036
194.00000000000205,25.86084171271832,0.35898615297603825,-0.05893942796471485
195.10000000000204,25.964070340120948,0.35892554082201866,-0.06116014131210701
196.20000000000206,26.068206246997953,0.3565542861377668,-0.06248212201860959
197.3000000000021,26.173453379775005,0.3567615586984564,-0.06376245385513313
198.40000000000208,26.2767083365918,0.3570967219631572,-0.06414455744515202
199.5000000000021,26.380657649826514,0.3557730696167503,-0.06520934128997835
200.60000000000213,26.485181721801663,0.3580546959164087,-0.06533338589960946
201.70000000000215,26.58888301285884,0.3554776215332732,-0.0667599909957759
202.80000000000217,26.69298003077854,0.3550576848405235,-0.06809160249916335
203.90000000000217,26.79844023706793,0.3558226287975188,-0.0693900853575431
205.0000000000022,26.901936563225853,0.35654861484042344,-0.07168549796121226
206.1000000000022,27.005601584293025,0.3543784433922742,-0.07298054636454276
207.2000000000022,27.109359320600383,0.35345163469787333,-0.07323269465682936
208.30000000000223,27.213724261906748,0.35239614843097056,-0.07598733194660046
209.40000000000225,27.318342061710844,0.35229074126189514,-0.07729678239889148
210.50000000000227,27.422460774579214,0.35134223436495365,-0.07731830955957442
211.6000000000023,27.526481133566165,0.3495207594337935,-0.07906013316186433
212.7000000000023,27.63001925637484,0.3500243222929992,-0.08123998027703516
213.8000000000023,27.734612094989274,0.3478719691390371,-0.08253146525155053
214.90000000000234,27.837296931710444,0.34345536541875066,-0.0838798497533797
216.00000000000233,27.94346306668107,0.3424853922759636,-0.08640289176162375
217.10000000000235,28.048147250225128,0.3403407305085403,-0.08782974223492879
218.20000000000238,28.1526364722248,0.3388164707336901,-0.08916597703906382
219.3000000000024,28.256636105121636,0.33552082806846945,-0.09046978230298075
220.40000000000242,28.35794156706216,0.33426659052174423,-0.09178945971371277
221.50000000000242,28.46494754058319,0.3321701325998157,-0.09310020165324628
222.60000000000244,28.570162855701618,0.33130150563430993,-0.09574786426584847
223.70000000000246,28.673241171645007,0.3277023851498417,-0.09716512653982123
224.80000000000246,28.778985779857923,0.3247790222729826,-0.09848023246656412
225.90000000000248,28.883318972852845,0.3240857162366636,-0.09975672113133127
227.0000000000025,28.987896028928798,0.3229416842080425,-0.1024396403159411
228.10000000000252,29.091934734070435,0.3206207617061976,-0.10411263441605945
229.20000000000255,29.19625795244634,0.3192697133060808,-0.10739753175071609
230.30000000000254,29.300910683215918,0.3167629515682131,-0.10735793015012352
231.40000000000256,29.406206838480927,0.3152117253072041,-0.11168494361266124
232.5000000000026,29.508883846929642,0.3121632037664742,-0.11427693432794728
233.60000000000258,29.61471281645821,0.3101674501508041,-0.11627137033712875
234.7000000000026,29.718566663242267,0.3070876606520087,-0.11758383924667859
235.80000000000263,29.823378049606568,0.3036275290634952,-0.12021866086922994
236.90000000000265,29.924182734871383,0.3022984555513029,-0.1232604671144597
238.00000000000267,30.032150713243045,0.3007718356517872,-0.12480148885420084
239.10000000000267,30.13711944217437,0.2983692205784593,-0.12737881195571044
240.2000000000027,30.240779459613282,0.2958138071907387,-0.12876049643391596
241.3000000000027,30.34523811290823,0.295039317583476,-0.13290534278342703
242.4000000000027,30.450998725985972,0.29158352609254606,-0.13615092210480162
243.50000000000273,30.555412812434668,0.2888124154268813,-0.13894511519482577
244.60000000000275,30.65907502817128,0.28634119553146903,-0.14293942353037803
245.70000000000277,30.76359553145056,0.28375465716752857,-0.1442626815730801
246.8000000000028,30.868318528513655,0.28294691145979206,-0.14820695747754087
247.9000000000028,30.972606910866073,0.2808166583252109,-0.15111144371014396
249.0000000000028,31.07633978934849,0.2782195682154647,-0.15530723224677212
250.10000000000284,31.182572783031066,0.2759418333006624,-0.15829036107446193
251.20000000000283,31.28691068372161,0.27605799644601053,-0.16203027459130404
252.30000000000285,31.390620392506616,0.2747632565856579,-0.16596724643084837
253.40000000000288,31.493480913527634,0.2725871637781167,-0.16995797344008468
254.5000000000029,31.600284197491746,0.27178101312487496,-0.17345469505918887
255.60000000000292,31.705217849117155,0.2677839088938739,-0.17611979817027068
256.7000000000029,31.809877476433066,0.26731429416371577,-0.18134617702520117
257.8000000000029,31.913092714050094,0.26548237183113776,-0.18600478095662876
258.90000000000293,32.01734793672959,0.26435343111474413,-0.19057677501156833
260.00000000000296,32.12129754129146,0.2636394909341765,-0.1936160968535101
261.100000000003,32.226634298048374,0.2641555877152694,-0.19911284290232834
262.200000000003,32.33158220972863,0.26228138675284035,-0.20233263025285764
263.300000000003,32.43617480113467,0.26114707261594283,-0.20856537923442753
264.40000000000305,32.5405318127144,0.2600972084447827,-0.21273183688363329
265.50000000000307,32.64531526528847,0.26029904953310945,-0.2175585961303761
266.6000000000031,32.750367313986494,0.2605487378948002,-0.22452457022632277
267.7000000000031,32.855245942212164,0.25837101561457704,-0.23069375442699247
268.8000000000031,32.95897866708671,0.25718716150011367,-0.233820748907847
269.9000000000031,33.063166567858836,0.2577493729453129,-0.24144399292547192
271.0000000000031,33.16767505244137,0.25609317496361045,-0.24794161132217019
272.10000000000315,33.2727838291344,0.25680154446914993,-0.25366145296645426
273.2000000000032,33.37626184481912,0.2561977451302174,-0.26191710614097863
274.30000000000314,33.4825240477102,0.25273535731406616,-0.2669122328178992
275.40000000000316,33.58740156522346,0.25277028977791643,-0.27407996847895966
276.5000000000032,33.69181998180494,0.2528341842707225,-0.2808658383807523
277.6000000000032,33.79734830190496,0.2513211839590604,-0.28742854062682843
278.70000000000323,33.90196780307632,0.250069457810743,-0.2948659655380488
279.80000000000325,34.006309055473984,0.24913028771000745,-0.3028828722244503
280.9000000000033,34.11152687059121,0.249197733684887,-0.3091771708805471
282.0000000000033,34.216702613201605,0.24872254696016294,-0.3172661443630709
283.1000000000033,34.32181969359144,0.24949730454440444,-0.3273558867615618
284.20000000000334,34.42652102217582,0.24991823112544787,-0.3344499313072409
285.30000000000337,34.53135842133104,0.25018826669427113,-0.3443909384835093
286.40000000000333,34.63604210188012,0.24914082312871888,-0.3515041173352147
287.50000000000335,34.74188571110748,0.24887566284794443,-0.36205437472043744
288.6000000000034,34.84645958108345,0.2482679913830877,-0.37134660556268306
289.7000000000034,34.95207059356562,0.24587819010066397,-0.38133357466624096
290.8000000000034,35.05762624153692,0.24573900228832196,-0.3924271971516693
291.9000000000034,35.16244707154107,0.2472934498283499,-0.40319600544837186
293.0000000000034,35.26743236015904,0.24624409750570503,-0.4135274961763806
294.10000000000343,35.37260862713365,0.24643252323410936,-0.4240528019688794
295.20000000000346,35.47768840484696,0.24607143495740025,-0.43596229008888665
296.3000000000035,35.58154347564367,0.24716207610503343,-0.44717141618718026
297.4000000000035,35.688147352945236,0.2469581424559108,-0.46128047326980814
298.5000000000035,35.79338958891513,0.24506342582287488,-0.47302103732356926
299.60000000000355,35.898520070927134,0.24326747073276045,-0.4848582381411295
300.70000000000357,36.00269222371484,0.244275709100499,-0.49876654707440915
301.8000000000036,36.10857479508432,0.2422656419369824,-0.5119961556264063
302.9000000000036,36.213897508174234,0.2427267778896517,-0.5279704453783949
304.0000000000036,36.3195202238056,0.23752478712097658,-0.542045469309532
305.1000000000036,36.423516028916715,0.23833006929315714,-0.5571140279028208
306.2000000000036,36.52968924130271,0.2371855131788418,-0.5732704638341404
307.30000000000365,36.63360225236649,0.2355455748644824,-0.5878951287670473
308.4000000000037,36.739491114380314,0.23691730534371158,-0.6032048833700769
309.5000000000037,36.845976318281174,0.23251950187626758,-0.6205750567643742
310.60000000000366,36.95128085802613,0.23046501249561496,-0.6364465294594437
311.7000000000037,37.05633767337989,0.22940498544197385,-0.6560590037366261
312.8000000000037,37.16119041800875,0.22553718357911373,-0.6747418117721384
313.90000000000373,37.26705141988029,0.22650371033047367,-0.6933349021184649
315.00000000000375,37.372117970406535,0.22350697149038268,-0.7137623167926099
316.1000000000038,37.47753520512619,0.22450426780228622,-0.7334809257976485
317.2000000000038,37.5828374466131,0.22109647561298718,-0.7534026201023734
318.3000000000038,37.68873200681546,0.2193783666856315,-0.7731598189282214
319.40000000000384,37.79356569126912,0.21724925020738023,-0.7959259884739973
320.5000000000038,37.89935814268562,0.21732554820171712,-0.8193696724221686
321.60000000000383,38.003962273018374,0.2147574792229328,-0.840822778590661
322.70000000000385,38.1093482741312,0.21430729225156792,-0.8657959713295074
323.8000000000039,38.21506434315743,0.21172273263864894,-0.8915633796583089
324.9000000000039,38.32028026514681,0.21077189795735196,-0.9149749799238935
326.0000000000039,38.4261949736564,0.21096724704654607,-0.94130163890576
327.10000000000394,38.53191004796893,0.20938185116694358,-0.9661240302309286
328.2000000000039,38.637916981237545,0.2084682429724456,-0.994492408978211
329.30000000000393,38.74276280309754,0.20567462800317565,-1.0225143057831447
330.40000000000396,38.846038273188285,0.20380464535187776,-1.047711170195734
331.500000000004,38.95367088281803,0.201858452888874,-1.0766673346458489
332.600000000004,39.059371568171784,0.20096058094315933,-1.1089910153075238
333.700000000004,39.165521875685016,0.19939520052473797,-1.1383616411650008
334.80000000000405,39.27126178583197,0.19740604563124936,-1.1694557507181487
335.90000000000407,39.37615727057754,0.19316410479025087,-1.2006677595662323
337.0000000000041,39.48195145935223,0.18942789513481112,-1.232301474157726
338.10000000000406,39.58759766075566,0.18316726764558577,-1.2643414786469074
339.2000000000041,39.6936104060383,0.17904184728059502,-1.2975545578528949
340.3000000000041,39.79907400341949,0.17465627042844484,-1.3303366985034581
341.4000000000041,39.9053725493556,0.16834075905082974,-1.3642721595339409
342.50000000000415,40.01008103270207,0.1618340899256575,-1.3947022000649616
343.6000000000042,40.11596068263045,0.15662846233269623,-1.4289585101754092
344.7000000000042,40.222659728635136,0.14860615690622525,-1.4615567604197022
345.80000000000416,40.327307391220295,0.1416178580395825,-1.4931938445370592
346.9000000000042,40.434636110167446,0.13468143327080645,-1.5250463551136337
348.0000000000042,40.54076317773154,0.12851957968813993,-1.5547720072848072
349.10000000000423,40.64710649916893,0.12412401622416219,-1.5816902638676678
350.20000000000425,40.753029745578374,0.12324500862881266,-1.6103662134919507
351.3000000000043,40.85829631081028,0.11903574534221101,-1.635867949325187
352.4000000000043,40.96505663597442,0.11808701714168945,-1.6601058764585703
353.5000000000043,41.070437088374675,0.11775887769484222,-1.6806844261412084
354.60000000000434,41.17716790438264,0.11689375899484011,-1.7010409298652505
355.7000000000043,41.28307461658799,0.11929719674991263,-1.71920877432476
356.80000000000433,41.38906749133517,0.11966715101118186,-1.7355363466874172
357.90000000000435,41.495802918437946,0.12074393492111024,-1.750253068452829
359.0000000000044,41.601886921580565,0.12069812451479328,-1.765021482270662
360.1000000000044,41.708336395717005,0.12004190326615366,-1.777085631137933
361.2000000000044,41.814895017081774,0.12566364250193918,-1.788095691665117
362.30000000000445,41.92075237119861,0.125453593828732,-1.7981924786523273
363.4000000000044,42.026677844097776,0.12694503749340652,-1.8074980561858927
364.50000000000443,42.13521837899795,0.12936063752625343,-1.815362253779345
365.60000000000446,42.24154753247611,0.13226809207729234,-1.8246373051316582
366.7000000000045,42.34754641988326,0.13662187466600773,-1.8311786870493334
367.8000000000045,42.45366549761212,0.13745480693090228,-1.8389916044230143
368.9000000000045,42.560664652634784,0.14056728425092468,-1.844558305600441
370.00000000000455,42.66737320405273,0.1408662621391073,-1.8527510127037465
371.10000000000457,42.773151556079235,0.14086502336266493,-1.8598531291257525
372.2000000000046,42.8795684564316,0.13839627799389226,-1.865121008395343
373.30000000000456,42.98695588817377,0.13903953196470703,-1.8694075950003652
374.4000000000046,43.09349204902024,0.13868310649292898,-1.8754686427125828
375.5000000000046,43.2000594920431,0.13639290346509242,-1.8827334254636656
376.6000000000046,43.3062251042447,0.1360476991317503,-1.8862236970015256
377.70000000000465,43.41364354961749,0.13875766024982894,-1.8913154441464575
378.8000000000047,43.52052250664091,0.1360874675319575,-1.8968459171318885
379.9000000000047,43.62707889125023,0.1366047079385983,-1.900682264977815
381.00000000000466,43.73300621392489,0.13988069642004564,-1.9054084419312824
382.1000000000047,43.84026548460669,0.13941083263660764,-1.9088558343642132
383.2000000000047,43.9464358155103,0.13875383144208286,-1.9142249411351693
384.30000000000473,44.05332428742314,0.13896070416292533,-1.9172386774056496
385.40000000000475,44.160491107180185,0.14320965713300549,-1.919905055541411
386.5000000000048,44.266536733314545,0.14264826723921326,-1.9258923358727107
387.6000000000048,44.37386864121601,0.14366782465776223,-1.93059295600968
388.7000000000048,44.4807965221447,0.1436452810594207,-1.9347099274671682
389.80000000000484,44.587839951867046,0.14561625814183288,-1.9389117677542882
390.9000000000048,44.69327376165107,0.14612127900958427,-1.9420438022688156
392.00000000000483,44.80153552021771,0.14559226426286642,-1.946645380057597
393.10000000000485,44.90827971879429,0.14445742642483633,-1.9493994854154633
394.2000000000049,45.01455554527621,0.14778257706885178,-1.952616774689762
395.3000000000049,45.121359297943556,0.14943058115690372,-1.9583083548461402
396.4000000000049,45.228662818487535,0.15069638944845665,-1.9626812209158468
397.50000000000495,45.33543998353278,0.1534735958074943,-1.966562158945965
398.6000000000049,45.44267348019173,0.15045122643687903,-1.9709412545375824
399.70000000000493,45.54826704874017,0.15211410618789106,-1.9751411106756556
400.80000000000496,45.656179371982,0.1534061641186898,-1.9786172104150113
401.900000000005,45.76479169482027,0.15335312657552802,-1.9818926144371622
403.000000000005,45.87141684126083,0.15607986471561058,-1.9855593013990454
404.100000000005,45.97804406371082,0.1555698080216561,-1.9901694049378895
405.20000000000505,46.08539629218246,0.15698108657622295,-1.9940136425938895
406.30000000000507,46.192280463350116,0.15523678707882949,-1.9998000604424244
407.4000000000051,46.29927126213344,0.15802467984872498,-2.0021292970686235
408.50000000000506,46.40578082092683,0.15910355217177563,-2.0073303844822097
409.6000000000051,46.512672140014814,0.15914797340166875,-2.012150169286488
410.7000000000051,46.619372573495085,0.16130306743074635,-2.01617659627256
411.8000000000051,46.72667763338195,0.16295339026112804,-2.021721757749399
412.90000000000515,46.833442581521794,0.16191034597565057,-2.0262594131677814
414.0000000000052,46.939863068604026,0.16552529095250573,-2.03045449188843
415.1000000000052,47.04851043483224,0.16675097019056678,-2.034364217214155
416.20000000000516,47.1549574093563,0.16644291972498138,-2.039082046515895
417.3000000000052,47.261496767683084,0.1711686269006289,-2.04238960088081
418.4000000000052,47.36819538105808,0.16903312198110332,-2.046996881832969
419.50000000000523,47.47397521808184,0.17041214292862694,-2.052630382487515
420.60000000000525,47.584254261645576,0.1716424165530515,-2.0571163247081232
421.7000000000053,47.69096966710646,0.17241763605649385,-2.061515193908506
422.8000000000053,47.798195373061276,0.17326038915017433,-2.0649491969456664
423.9000000000053,47.90532702909261,0.17416536833446217,-2.0696038958942307
425.00000000000534,48.01302642390512,0.17331839109941594,-2.074318338594815
426.1000000000053,48.11966727576067,0.17335186683322695,-2.0793509709698093
427.20000000000533,48.22678187833345,0.17595107845917313,-2.0855647811246265
428.30000000000535,48.333706530076846,0.1729014614626319,-2.0892950264826258
429.4000000000054,48.44076677648636,0.17430517488728425,-2.0937160933080587
430.5000000000054,48.54852471041372,0.17444355164560166,-2.099776311936347
431.6000000000054,48.65566417202676,0.1732601786738041,-2.1037370404302362
432.70000000000545,48.76321359225311,0.17490848270162346,-2.107069333784776
433.8000000000054,48.87166616404207,0.17385412420465496,-2.1134762497235338
434.90000000000543,48.978897669893904,0.17320793155337955,-2.1178297078084563
436.00000000000546,49.08520720203704,0.1716330830782466,-2.1220721455013614
437.1000000000055,49.19341047904731,0.17456376973406967,-2.1257224689037333
438.2000000000055,49.30081907480198,0.17357425256990455,-2.1306792648679305
439.3000000000055,49.40775230880581,0.1731880213044354,-2.1348832654558607
440.40000000000555,49.51585676305772,0.17332399807896365,-2.1388596484560765
441.50000000000557,49.62304616624749,0.17437367247391794,-2.145635217200737
442.6000000000056,49.730364880032774,0.17187026138505768,-2.148794528685572
443.70000000000556,49.83843820891123,0.17182361207796543,-2.1528300912861464
444.8000000000056,49.94583758595718,0.16923764091196108,-2.1572014304280387
445.9000000000056,50.054022397285564,0.17064210545986364,-2.161647726798126
447.0000000000056,50.16104936608935,0.16971918611724346,-2.1658071692220906
448.10000000000565,50.26860678761034,0.16801524267612766,-2.170685236651884
449.2000000000057,50.37709876125467,0.1695738775371644,-2.175815336550833
450.3000000000057,50.48420653271695,0.16689623194730951,-2.178820427436836
451.40000000000566,50.5922464055609,0.16769174065150372,-2.1840611469512567
452.5000000000057,50.700762963657525,0.1672019865307563,-2.186779632007297
453.6000000000057,50.80849585087192,0.16791701602169284,-2.1916583609980345
454.70000000000573,50.9164478988422,0.16676162355903346,-2.195275519415702
455.80000000000575,51.02144785768664,0.16690123297956033,-2.1994643957199456
456.9000000000058,51.132481683020984,0.1650144779868628,-2.2040871719594755
458.0000000000058,51.24050241918435,0.1668821882471943,-2.2088139240925826
459.1000000000058,51.348729922880096,0.1658691311611043,-2.2115897369758706
460.20000000000584,51.456079495513876,0.16566525877793287,-2.214576462160541
461.3000000000058,51.56390006382185,0.16786677083740698,-2.2192450901799163
462.40000000000583,51.6696130329492,0.16684728883314737,-2.2223971703576453
463.50000000000585,51.77851359171071,0.1672595463353872,-2.2277439710632536
464.6000000000059,51.886445326737245,0.1666921734258779,-2.230911576529578
465.7000000000059,51.99410754271354,0.16562993661653752,-2.2345223624906088
466.8000000000059,52.102369915518544,0.16713529064411659,-2.2368620536346184
467.90000000000595,52.208417705793394,0.1662101652633441,-2.2414365890871544
469.0000000000059,52.3175198111552,0.16533029591278864,-2.245544349071414
470.10000000000593,52.426314712088434,0.16665384700177327,-2.248945948703658
471.20000000000596,52.533362248493454,0.1651167056820358,-2.2524707094343825
472.300000000006,52.63896614674201,0.1654590412143706,-2.255158338176244
473.400000000006,52.74862215815294,0.1629554226222633,-2.259452404263513
474.500000000006,52.85679299765986,0.16582177874536996,-2.2626353482866204
475.60000000000605,52.965023609410586,0.1644680343239025,-2.26682999487858
476.70000000000607,53.07332809398507,0.16231271919890305,-2.2704623312371033
477.8000000000061,53.180399018090775,0.15971741497980635,-2.273942244472087
478.90000000000606,53.289170973091245,0.15736651373840832,-2.276250123299356
480.0000000000061,53.397393898816155,0.15862170250504293,-2.281665868081288
481.1000000000061,53.50554724863489,0.15829700788625384,-2.28477248998192
482.2000000000061,53.61338574799359,0.15925638243139273,-2.286652556026096
483.30000000000615,53.72201776121642,0.15877802723675605,-2.2894245899108636
484.4000000000062,53.830245716354156,0.15839964633380904,-2.292049975127734
485.5000000000062,53.9386618490308,0.15603124298405013,-2.2961841850630575
486.60000000000616,54.04761843065819,0.15762892922294047,-2.29944372799169
487.7000000000062,54.15468446745771,0.15443142885715577,-2.303898280358376
488.8000000000062,54.26294487114187,0.1536595415073449,-2.306895603241049
489.90000000000623,54.372083122750034,0.15400787118034226,-2.310332945640699
491.00000000000625,54.480093818932886,0.15155383036218595,-2.3128240778061837
492.1000000000063,54.58647674077197,0.15078461428394185,-2.3154514633089245
493.2000000000063,54.69566974708935,0.1527360308685461,-2.318072419140437
494.3000000000063,54.80450200758224,0.15121290495375783,-2.3219667306625054
495.40000000000634,54.91314138394126,0.1489759195804281,-2.3237812563270657
496.5000000000063,55.021507511967386,0.15137776612985004,-2.3273435426976197
497.60000000000633,55.12842386102581,0.1500235772841902,-2.327773816565041
498.70000000000636,55.23767030763016,0.15003666013603134,-2.3315812619151255
499.8000000000064,55.34645313935598,0.1494289776939307,-2.333335120550978
500.9000000000064,55.45380901614531,0.14982826629005414,-2.3372184602449853
502.0000000000064,55.56283666078833,0.1476878302725136,-2.3391469656201105
503.10000000000645,55.67110752465557,0.14652761496925704,-2.3427856121704584
504.2000000000064,55.77784240617989,0.14568148128179564,-2.3468815323923073
505.30000000000643,55.88723108523649,0.14462014845446208,-2.346950629012815
506.40000000000646,55.9953112320501,0.1454149449787695,-2.3498322584608493
507.5000000000065,56.10437064979738,0.1446689568847232,-2.35396049299897
508.6000000000065,56.212390300996,0.14425815412162818,-2.3549291206699015
509.7000000000065,56.320867997257785,0.14259938100453468,-2.3580425080093144
510.80000000000655,56.42865942316185,0.14452706169345914,-2.3606842389420772
511.90000000000657,56.536180821217876,0.14173879333479178,-2.364707947613347
513.0000000000066,56.64513361083113,0.1404286072337086,-2.366474476182411
514.1000000000065,56.753398272290156,0.14274264638333933,-2.367818803158973
515.2000000000066,56.86327766611786,0.14066527205095708,-2.3716288873219153
516.3000000000065,56.970801898115774,0.1405125691741591,-2.3754242237047096
517.4000000000067,57.07991964874466,0.139768643340905,-2.376103457571726
518.5000000000066,57.18907022301072,0.13858653169885743,-2.377705720228608
519.6000000000067,57.296903040581675,0.137057098313487,-2.3804146490391935
520.7000000000066,57.40531750908704,0.13788085049684656,-2.3829647505508444
521.8000000000067,57.51439145031702,0.13693577510576166,-2.385918030707699
522.9000000000067,57.62249878905853,0.13616402715584702,-2.3885597284355056
524.0000000000067,57.73205291076871,0.13473046598579308,-2.391177713300745
525.1000000000067,57.841061309069865,0.13696714891785994,-2.392015341130469
526.2000000000068,57.950184147917916,0.13371111283774173,-2.3938238160125453
527.3000000000068,58.05879336654895,0.13509737365782032,-2.3967939326860703
528.4000000000068,58.16713684229863,0.13004452007975187,-2.399381057003372
529.5000000000068,58.27616279796826,0.1309664103850945,-2.4030479098719244
530.6000000000068,58.38540057263203,0.13177221809391765,-2.4047135093644507
531.7000000000069,58.493956637321475,0.1305993413468312,-2.4069992344668516
532.8000000000068,58.60273955101715,0.13145660937689285,-2.4079485862790544
533.9000000000069,58.710982947595916,0.13303943726786177,-2.4109780383641546
535.0000000000068,58.82087779039786,0.1329577924270231,-2.413395589740472
536.100000000007,58.92917198113408,0.1324599183601849,-2.4132502945575602
537.2000000000069,59.035724238988216,0.1321148119354979,-2.4162256507705164
538.300000000007,59.14669766700219,0.13290188467528302,-2.4176688217442353
539.4000000000069,59.2550901869673,0.13304235810589515,-2.420483047512327
540.5000000000069,59.363994109009326,0.13398349681317095,-2.4217111009344157
541.600000000007,59.4731104313987,0.1343557539897497,-2.424949153946613
542.700000000007,59.58244207948324,0.13358231668245768,-2.428437907526815
543.800000000007,59.69085984558231,0.13519317216824572,-2.4285209401099737
544.900000000007,59.80013568567594,0.1340041296264904,-2.4311449119281416
546.000000000007,59.90917000000065,0.13432695024376468,-2.4337770242442787
547.1000000000071,60.01637553239577,0.13103849957979796,-2.437615441490315
548.2000000000071,60.12568766534856,0.13115064334903692,-2.43776810347119
549.300000000007,60.234479598832436,0.13256700260519427,-2.439053845293871
550.4000000000071,60.34444954148461,0.1296693967940264,-2.4404425642735172
551.500000000007,60.4532717724187,0.12848501788306238,-2.4421067449808365
552.6000000000072,60.5625216119338,0.12890442738294816,-2.443340296357696
553.7000000000071,60.671994758488445,0.12547428542368794,-2.4459949680649227
554.8000000000072,60.78155628501394,0.1250455767696087,-2.4500281034012987
555.9000000000071,60.8880403975726,0.12262094808457552,-2.450040253120738
557.0000000000072,60.99961508689906,0.12123122771825556,-2.452692887105012
558.1000000000072,61.10897424480844,0.12141380401763602,-2.453000361148189
559.2000000000072,61.21817323076384,0.12026206912183485,-2.455599579875161
560.3000000000072,61.32711559126763,0.11981909416168429,-2.4569687422820268
561.4000000000073,61.43637563013344,0.11847614003981405,-2.458270697913153
562.5000000000073,61.545169392533424,0.11677921247756756,-2.4608644877796735
563.6000000000073,61.65454558356474,0.11823437102297712,-2.4627162027672362
564.7000000000073,61.76425026686104,0.11712100256367902,-2.463313846416966
565.8000000000073,61.87375009807894,0.11892405689423485,-2.464928148278414
566.9000000000074,61.982182301367736,0.11558204311727388,-2.4665416474718462
568.0000000000074,62.09232633993109,0.11238836400848529,-2.4656187243791923
569.1000000000074,62.20083690311882,0.11452640375657946,-2.4682599598209634
570.2000000000073,62.309891437731594,0.1143549913748112,-2.46957962141836
571.3000000000073,62.41838930168942,0.11233692491174069,-2.472228854109444
572.4000000000074,62.52808874050816,0.11199465285590032,-2.4748452386433666
573.5000000000074,62.637120201439025,0.10984025157441601,-2.474840103309064
574.6000000000074,62.74666122787322,0.10844699479007053,-2.4774796189797863
575.7000000000074,62.855823896325845,0.10556666666602332,-2.477619551708268
576.8000000000075,62.965154831337834,0.10808843258632878,-2.478782779706406
577.9000000000075,63.07374117641026,0.10607617100433148,-2.4801101915506414
579.0000000000075,63.18198880084747,0.10656306025514861,-2.4816625163570967
580.1000000000075,63.28927110896917,0.10673980038020281,-2.485489846884919
581.2000000000075,63.39797597295623,0.10789649108246163,-2.485489901707095
582.3000000000076,63.510394177001714,0.10734368645958503,-2.488415441681532
583.4000000000076,63.61907192247492,0.10781899255031624,-2.4897998140212505
584.5000000000076,63.72766113224378,0.10425284406783297,-2.489964799562227
585.6000000000076,63.837232772791054,0.10508129906383673,-2.4910992968985997
586.7000000000077,63.94664265492667,0.10456945219712227,-2.493730043122178
587.8000000000077,64.0572164757968,0.10414730745989098,-2.4943316337899217
588.9000000000076,64.16567970536391,0.10513691686085047,-2.495050068042311
590.0000000000076,64.27440819567379,0.10368135397225664,-2.495041932839545
591.1000000000076,64.38387401463866,0.10169246628570605,-2.4976950637414466
592.2000000000077,64.49315372552569,0.10525542778264896,-2.4990018244791017
593.3000000000077,64.60333300174564,0.10348962917520066,-2.500238288463759
594.4000000000077,64.71232048686547,0.10408260358835969,-2.501628180103721
595.5000000000077,64.82273639198452,0.1024016615945007,-2.5029495294677
596.6000000000078,64.93161903636769,0.10617963661214974,-2.5042763580995198
597.7000000000078,65.04073484864357,0.10527963395291556,-2.5055900407220846
598.8000000000078,65.15104947355594,0.10353679718640879,-2.505587897478763
599.9000000000078,65.26055164941361,0.10644387488183465,-2.5086906032113028
601.0000000000078,65.36980760931549,0.10478054545752641,-2.5098687440005536
602.1000000000079,65.47960091984268,0.10565090368979829,-2.510849903491366
603.2000000000079,65.5884493410187,0.10551233266190413,-2.51216936681317
604.3000000000079,65.69936275136237,0.10490355144722013,-2.5121704305079087
605.4000000000078,65.80808685565049,0.10727275167764067,-2.5146202282861494
606.5000000000078,65.91762861424333,0.10412672368493853,-2.5149100493139467
607.6000000000079,66.02723347000996,0.10308103974951005,-2.514888010676504
608.7000000000079,66.13757076253779,0.1022358527173764,-2.517219068187106
609.8000000000079,66.2459852154129,0.10223796676541419,-2.5187842841088863
610.9000000000079,66.35568292622598,0.1020835147684152,-2.5201989770825564
612.000000000008,66.46464129470623,0.10375751564207625,-2.521450242229986
613.100000000008,66.57452428960836,0.1031437147277457,-2.522901690313902
614.200000000008,66.68434609564447,0.10314165525081342,-2.5241403987795
615.300000000008,66.79350172350011,0.10540131825994753,-2.525459375380706
616.400000000008,66.9030883590298,0.10340635680431581,-2.5267798089722175
617.5000000000081,67.01204854071929,0.10381080501362144,-2.5266884045117384
618.6000000000081,67.12193518157468,0.10286351637761454,-2.529194158974164
619.7000000000081,67.23264189625246,0.1051835909348941,-2.5303654056224953
620.8000000000081,67.34045441169823,0.10277520439845106,-2.5317228703001597
621.9000000000082,67.45048575496448,0.10454671737817472,-2.532039461158429
623.0000000000082,67.56049253493836,0.10454218551601185,-2.5331041958665983
624.1000000000081,67.66988673054999,0.10414510798013776,-2.5344537528239783
625.2000000000081,67.78022537516391,0.10452939857805377,-2.5357801207426407
626.3000000000081,67.8898090938862,0.10280538337245515,-2.536483482312544
627.4000000000082,67.99916796397136,0.1033746736861218,-2.539070034041483
628.5000000000082,68.10844236131301,0.10154275392013545,-2.5405926778891557
629.6000000000082,68.2179327809809,0.09959364134930787,-2.540390208930932
630.7000000000082,68.32574756568742,0.10319517131582906,-2.5417082272726326
631.8000000000083,68.4372985950398,0.10198724607482873,-2.542849140356681
632.9000000000083,68.54733559480914,0.09875246374871383,-2.5443445000925364
634.0000000000083,68.65748616499552,0.09584111005478446,-2.546968003602954
635.1000000000083,68.76639481393407,0.09369404081007515,-2.5460710091548413
636.2000000000083,68.87669012585674,0.0913330958575786,-2.548397456883403
637.3000000000084,68.98572201019235,0.08993260752580567,-2.549710186794809
638.4000000000084,69.09543478709475,0.08626951612947192,-2.5510198646525297
639.5000000000084,69.20633857312616,0.08651360250840961,-2.551256391626385
640.6000000000083,69.3148836654729,0.08103781651407982,-2.552359875121424
641.7000000000083,69.42480262673352,0.0782197978479941,-2.551040901055508
642.8000000000084,69.53494548569284,0.07756697201952595,-2.5523497517334173
643.9000000000084,69.64388714566265,0.07059166075115009,-2.5550122841617737
645.0000000000084,69.75420473941067,0.06489438912369205,-2.556257450126231
646.1000000000084,69.86318466930435,0.0641102923692175,-2.558922534161052
647.2000000000085,69.97273975608795,0.059280563232897265,-2.5589317515635934
648.3000000000085,70.08245335322965,0.05900791976532327,-2.5589401353810883
649.4000000000085,70.1916348469796,0.05630239183399882,-2.5602436976311473
650.5000000000085,70.30152455837174,0.056267152847748414,-2.5602582132810325
651.6000000000085,70.41114962261634,0.050098424866769686,-2.5628899444792386
652.7000000000086,70.52094117336651,0.04922288794389995,-2.563369818113618
653.8000000000086,70.62991741486739,0.04568717244250725,-2.562890319008965
654.9000000000086,70.74078862529984,0.04520703700964851,-2.5655356536623692
656.0000000000086,70.85085225355373,0.04234068339520608,-2.565005644149772
657.1000000000087,70.96106817111391,0.042173977344214686,-2.564207664167433
658.2000000000087,71.07138623094258,0.038525365378924925,-2.5656782288727995
659.3000000000086,71.17917103490204,0.03875439256161095,-2.567830028914878
660.4000000000086,71.29114877089287,0.03565343097927598,-2.5681241889652036
661.5000000000086,71.40136279285811,0.038617962699868336,-2.5694801201828756
662.6000000000087,71.51076585866397,0.03332537359427962,-2.5694801188755125
663.7000000000087,71.62141052625951,0.0316916485316216,-2.5707871323200897
664.8000000000087,71.73154114085841,0.031914353519671534,-2.5722171985694517
665.9000000000087,71.8418523027459,0.028016348228482146,-2.572118240067809
667.0000000000088,71.95274567902035,0.024169216913494884,-2.5731086453787193
668.1000000000088,72.06306592450068,0.026918525506770596,-2.5732236431942113
669.2000000000088,72.17291772743405,0.0225709490443306,-2.574749660727902
670.3000000000088,72.2835777528777,0.022016820865005615,-2.5760702391710932
671.4000000000088,72.39299785933376,0.02046517991695429,-2.5747528300634803
672.5000000000089,72.50329131467556,0.0207276819282039,-2.576072483064319
673.6000000000089,72.61354596774977,0.017627870423102154,-2.577380111367958
674.7000000000089,72.72322282485065,0.017482024593890755,-2.5773930348819394
675.8000000000088,72.8339742382437,0.014584082364724305,-2.578699648037902
676.9000000000088,72.94366395437747,0.014412474143978116,-2.5804309689866263
678.0000000000089,73.05438066932517,0.013468712044479303,-2.5827399406754945
679.1000000000089,73.1646169922459,0.011280485729984913,-2.5826501720161352
680.2000000000089,73.27403007435845,0.008862176850659875,-2.5839738831075163
681.3000000000089,73.3838432336928,0.006942325512648728,-2.5849598134333656
682.400000000009,73.49497429404876,0.002472069706855373,-2.5835536097740572
683.500000000009,73.60453925947564,0.004305487407696762,-2.5849605701650615
684.600000000009,73.71429249651527,0.0038792295447745984,-2.584962886798911
685.700000000009,73.82547904238695,0.000347260495331736,-2.586269868571616
686.800000000009,73.93515612559317,-0.003792187635028199,-2.587580115274766
687.9000000000091,74.04553781018139,-0.00292824328026442,-2.5866015007564087
689.0000000000091,74.15614372228089,0.0005530701875582356,-2.586741306217661
690.1000000000091,74.26552969631803,-0.0004105167786483954,-2.58792016782032
691.2000000000091,74.3762899534909,-0.00010293937166638845,-2.5892454769306505
692.3000000000092,74.48619456068056,-0.0008468229624523649,-2.5915263123093526
693.4000000000092,74.59676600145664,-0.003942440069241437,-2.5928588855087265
694.5000000000091,74.70653005008305,-0.008423890698917358,-2.59286174909259
695.6000000000091,74.81607557651994,-0.006332085925275233,-2.591549685713116
696.7000000000091,74.92631629300848,-0.011364521775544423,-2.591886747718536
697.8000000000092,75.03648312767206,-0.00781517500393214,-2.591880059997594
698.9000000000092,75.14676203210038,-0.015275217068763891,-2.5918800482547213
700.0000000000092,75.2568717828692,-0.01362789473075443,-2.5937059061504644
701.1000000000092,75.36655901920355,-0.016507774650660723,-2.595079521256377
702.2000000000093,75.47784272019004,-0.01857300832210068,-2.593189414263439
703.3000000000093,75.58763799937651,-0.021518846158991578,-2.596228265519133
704.4000000000093,75.6978000486302,-0.023101349283889017,-2.5979098510155856
705.5000000000093,75.80763220222032,-0.024784179955278762,-2.5978359685911796
706.6000000000093,75.91758793488353,-0.023678764206558678,-2.5979098770759457
707.7000000000094,76.0281611066703,-0.026373912872379335,-2.596589903556402
708.8000000000094,76.13844210002169,-0.026103033739773907,-2.600743644298006
709.9000000000094,76.24936932621178,-0.029250281521478072,-2.602090010585971
711.0000000000093,76.35960726860223,-0.027249818026361727,-2.600766469115592
712.1000000000093,76.46989192753938,-0.029328245472642678,-2.599444336031251
713.2000000000094,76.58081881706069,-0.029379932091967598,-2.601419874013196
714.3000000000094,76.69058776122256,-0.03358754247336104,-2.602450882905722
715.4000000000094,76.80091068400803,-0.031057422131629597,-2.601434747638115
716.5000000000094,76.9121621633934,-0.03339826394250883,-2.6041713447893367
717.6000000000095,77.02164383904338,-0.031011899892555594,-2.605384118193829
718.7000000000095,77.13183888045926,-0.031207288613343598,-2.6040923303191748
719.8000000000095,77.24298739015491,-0.03180013504473944,-2.60533361856268
720.9000000000095,77.352985370347,-0.0374672454644151,-2.60540233663403
722.0000000000095,77.46433943248796,-0.040309664671180745,-2.605359837221729
723.1000000000096,77.57471073006018,-0.04243728106464517,-2.6066858491185485
724.2000000000096,77.68515559285662,-0.04152884683711794,-2.607275250153058
725.3000000000096,77.79486564728715,-0.04259977680491367,-2.6079591982423773
726.4000000000096,77.90531868332958,-0.043782361455925234,-2.609345264053238
727.5000000000097,78.01580610527631,-0.0434519416039198,-2.6080101680319867
728.6000000000097,78.12735894357644,-0.044452642458381875,-2.608011817424524
729.7000000000096,78.23676286677258,-0.04871772767481358,-2.6115701909738043
730.8000000000096,78.34833263308138,-0.04984838929825608,-2.609225412990301
731.9000000000096,78.45799650856524,-0.05121202124789964,-2.609193170241699
733.0000000000097,78.5676263673351,-0.04534080989473044,-2.611682963583399
734.1000000000097,78.67926824995148,-0.04799473272723748,-2.610541805964243
735.2000000000097,78.78888268916282,-0.05058799344090226,-2.611850111319087
736.3000000000097,78.89917103357185,-0.05415693725240961,-2.6118598321510946
737.4000000000098,79.00916777258237,-0.05697823012291364,-2.6118598500000307
738.5000000000098,79.12003791952847,-0.054375275822878655,-2.6132221426840276
739.6000000000098,79.23021013276764,-0.05196809857921586,-2.6118687592064944
740.7000000000098,79.34105602266263,-0.05460504528940785,-2.614489924392516
741.8000000000098,79.45027431708255,-0.05345142633388722,-2.6144894896626623
742.9000000000099,79.56178621969526,-0.049226231176924096,-2.6144887597442272
744.0000000000099,79.67227091559215,-0.04784648351893567,-2.617139689532901
745.1000000000099,79.78274225821268,-0.04776484599612818,-2.6171300256363326
746.2000000000098,79.89343137331028,-0.049724660382885644,-2.6157618803447003
747.0000000000099,79.97351518111853,-0.04831164481615419,-2.61680010418553