File: 01_Data/PU_Aerogel/STA/N2/30K_min/PU_Aerogel_STA_N2_30KData_240108_R3.csv
##Temp./Â°C,Time/min,DSC/(mW/mg),Mass loss/mg
52.0,10.641409194251342,0.10379958384354993,-0.004417700474713904
53.100000000000016,10.80112876968275,0.1769581596807912,-0.004839604742937098
54.20000000000003,10.914248482772603,0.23531635000354623,-0.0059168741972071
55.30000000000005,11.007970511217929,0.28532937385335355,-0.006534496650699495
56.40000000000006,11.088525070618829,0.3298645950313568,-0.005073687806135929
57.50000000000008,11.1606918809707,0.3723063075895734,-0.00475410512065455
58.600000000000094,11.226346553369156,0.4121141344385095,-0.0070015318605278765
59.70000000000011,11.28985328131605,0.4448743125640777,-0.004946744785928381
60.800000000000125,11.348547052247124,0.4785927137845889,-0.007658520363825083
61.90000000000014,11.404711186996645,0.5068790970065336,-0.007917085327552975
63.000000000000156,11.458243632361356,0.5376422899651305,-0.008000147151498105
64.10000000000016,11.508974668400002,0.5617863837886188,-0.008095271218363287
65.20000000000019,11.559875235355545,0.5869757296071796,-0.007435328585282619
66.30000000000021,11.607846853650912,0.6106397606418483,-0.007267995968227581
67.40000000000022,11.656039168690887,0.6325814148128599,-0.007764649255254774
68.50000000000023,11.702477914686396,0.6514767922959452,-0.00816429304972921
69.60000000000025,11.74746341371063,0.6754951758563978,-0.006895102480826587
70.70000000000027,11.79189242452981,0.6918602212987961,-0.007210991076637363
71.80000000000028,11.836484366179363,0.7114752086980514,-0.006784311434974377
72.90000000000029,11.879507032977509,0.7284659504546689,-0.0074969551742416485
74.00000000000031,11.922116557713379,0.745954513591575,-0.009394543936825706
75.10000000000034,11.964572370313208,0.7607574548658231,-0.008046336355785222
76.20000000000034,12.006363771015383,0.7744509493447493,-0.008183311722342879
77.30000000000035,12.04807820891711,0.7859890936892118,-0.007512926370929485
78.40000000000038,12.08823978459515,0.8026599236458591,-0.008476458619139038
79.5000000000004,12.130107830932728,0.8179227087870278,-0.0076293997537870695
80.6000000000004,12.17051861253815,0.8281310791372831,-0.008614580801244998
81.70000000000041,12.210162336802291,0.8404455496773242,-0.007898766510497701
82.80000000000044,12.250300352126894,0.8505513235417492,-0.008460779925832718
83.90000000000046,12.289346255155076,0.8616573887849364,-0.009067713137152822
85.00000000000047,12.328994322374287,0.8721585601235631,-0.010059620740386688
86.10000000000048,12.368103836724455,0.8812386478533938,-0.01033038609697412
87.2000000000005,12.406711064624933,0.8899422810108395,-0.010270678987298165
88.30000000000052,12.445035655374816,0.8973898107542331,-0.008831637535915426
89.40000000000053,12.48364771125666,0.9049427902212366,-0.009219617568616556
90.50000000000054,12.521200942132158,0.9131231735702103,-0.00919850241671849
91.60000000000056,12.559417820385757,0.9166201789999289,-0.01052669808401241
92.70000000000059,12.597394776221734,0.9245722708780304,-0.010571712200849959
93.8000000000006,12.635288690741541,0.9293672323095574,-0.009453189146663377
94.9000000000006,12.67292441237323,0.9345580931268294,-0.01053461098163977
96.00000000000063,12.710641307397385,0.9398300605102594,-0.009171052508323285
97.10000000000065,12.747806942406665,0.9446363438045806,-0.010555921094474563
98.20000000000066,12.78501023947395,0.9463431484867315,-0.010647806484636924
99.30000000000067,12.822310580212172,0.9523695746567924,-0.009868723549658398
100.40000000000069,12.859463159249316,0.9542797763574498,-0.010541361431191998
101.50000000000071,12.89643561165266,0.960100837412071,-0.010470484482312248
102.60000000000072,12.933499489672013,0.962434435044234,-0.010650083728767079
103.70000000000073,12.970726854452177,0.9634850486587787,-0.010958905857374468
104.80000000000075,13.007090809681372,0.9675649180668384,-0.01062333284040129
105.90000000000077,13.04418492154998,0.9722109704255366,-0.010617657553293025
107.00000000000078,13.081022092370265,0.9723458403821172,-0.010972755403214407
108.10000000000079,13.117317745780692,0.9757616356135714,-0.01098579291325441
109.20000000000081,13.154542092681012,0.9789812134985207,-0.011979596867687459
110.30000000000084,13.191142608470015,0.9818309044668618,-0.011814857943175383
111.40000000000084,13.228008129297573,0.9844759483802439,-0.010660275781221529
112.50000000000085,13.26472428728211,0.9895458607470882,-0.010620227581836339
113.60000000000088,13.301379884862362,0.9925827233910882,-0.010649410099952572
114.7000000000009,13.337919404749183,0.9970553358819911,-0.010804536375037088
115.8000000000009,13.374463675817063,0.9997872681960644,-0.01196591825002935
116.90000000000092,13.411071344088109,1.0035186706922774,-0.011950453781829573
118.00000000000094,13.447637700051212,1.0051693193208011,-0.011729072308947597
119.10000000000096,13.483911276389764,1.0103347580475606,-0.011957704803805314
120.20000000000097,13.520320494744833,1.014892676226314,-0.011975434847071309
121.30000000000098,13.556781763582862,1.017374240632327,-0.01065009533735184
122.400000000001,13.593378113462908,1.0234128063916061,-0.01064063614285704
123.50000000000102,13.6296136279827,1.0266793775764664,-0.010644200337637688
124.60000000000103,13.666146418809236,1.028903023744869,-0.010341152347461247
125.70000000000104,13.70212102815629,1.033590183496965,-0.010639601063475279
126.80000000000106,13.738185906365395,1.0365269948439546,-0.01200073688433223
127.90000000000109,13.774493040394455,1.0397944666868373,-0.01197033728353114
129.00000000000108,13.810715363667496,1.0450914089400916,-0.011969966599251869
130.1000000000011,13.845493995762872,1.0479718721503128,-0.011911801330557914
131.20000000000113,13.882127228782121,1.053074258057948,-0.013274419722695718
132.30000000000115,13.918335234132616,1.0583063363748177,-0.013272965492404865
133.40000000000117,13.953829887352931,1.0594968270586314,-0.01191463716175889
134.50000000000117,13.989460376220736,1.0623662159237102,-0.012209628869758404
135.6000000000012,14.02549048227729,1.0660549756503195,-0.013282662268837342
136.7000000000012,14.060893960883863,1.070172793485701,-0.014037534047809608
137.8000000000012,14.096837620430712,1.0739663030100504,-0.014270429914375882
138.90000000000123,14.131981035849925,1.0806215561088024,-0.014263968159027307
140.00000000000125,14.167887600575579,1.0825489071559282,-0.012791884312692403
141.10000000000127,14.203273159064965,1.0884816298990443,-0.011344373534463603
142.2000000000013,14.238544280693544,1.0909920908392674,-0.010103394380969188
143.3000000000013,14.273592713904964,1.0923876082023591,-0.010100066206379044
144.4000000000013,14.309362678780143,1.0983254914523175,-0.0100999824564032
145.50000000000134,14.344289496395248,1.1020542213647566,-0.010116164870890731
146.60000000000133,14.379331218015858,1.1056375379383714,-0.011529526698915049
147.70000000000135,14.41458347096639,1.1111742974552978,-0.012847775975838971
148.80000000000138,14.44994130632865,1.1139638391201074,-0.01403604846785722
149.9000000000014,14.48514106423694,1.119669672730142,-0.01415267750922089
151.00000000000142,14.51980357722788,1.1205758277638447,-0.015509290176730861
152.10000000000142,14.554908534233439,1.1264113161534102,-0.015490131450910827
153.20000000000144,14.589609686526732,1.1299167446056226,-0.01580762314999573
154.30000000000146,14.624783052156351,1.134051560005028,-0.015810119839351433
155.40000000000146,14.659686155923925,1.1392147697278623,-0.01580996320775263
156.50000000000148,14.694544855381206,1.1424110193496375,-0.01581017539334706
157.6000000000015,14.729263242714781,1.1453294418836941,-0.015798165151564625
158.70000000000152,14.763996414282493,1.1486761867032516,-0.014959839742659131
159.80000000000155,14.798819532904698,1.1543738244054311,-0.015150675376701894
160.90000000000154,14.833503293384641,1.1566911885234754,-0.015150022187531142
162.00000000000156,14.867308652183175,1.1653850434189592,-0.015150008068054444
163.1000000000016,14.902520954604723,1.1687133576995272,-0.01515003984421659
164.20000000000158,14.937496796049613,1.1718036969032883,-0.015148114732999485
165.3000000000016,14.972310132627406,1.1751703916559615,-0.015514582085397688
166.40000000000163,15.007006582188897,1.1788044444953032,-0.015479901599521284
167.50000000000165,15.040673900692115,1.1850068232711362,-0.01570664143350209
168.60000000000167,15.0759167899705,1.187054661346142,-0.017195083317200766
169.70000000000167,15.110766556726679,1.1904526167922866,-0.018112796680388676
170.8000000000017,15.145288479731535,1.192192078994164,-0.018110017145292368
171.9000000000017,15.179703832897522,1.1983306461459147,-0.018111652079955576
173.0000000000017,15.214143315355733,1.2024070438093568,-0.01829060304325747
174.10000000000173,15.248433173313272,1.2046859019358793,-0.019418927434332378
175.20000000000175,15.283018502610705,1.2074080712008697,-0.019430795552766167
176.30000000000177,15.317405730814075,1.2126901623743809,-0.02066959695143078
177.4000000000018,15.351871683896789,1.2150078947859442,-0.02073454532489638
178.5000000000018,15.386165626733401,1.2205411598642004,-0.01944435134213851
179.6000000000018,15.420475481386937,1.2233799954358513,-0.0194301371074177
180.70000000000184,15.454794273142827,1.2285591618081977,-0.019432327127778315
181.80000000000183,15.488699909236539,1.2317805878830543,-0.01904344365753108
182.90000000000185,15.522959174453582,1.2354145708036486,-0.018289157071900597
184.00000000000188,15.556842460892339,1.2399359615667298,-0.019418117507980615
185.1000000000019,15.591077374205563,1.244432045649706,-0.020785402959376587
186.20000000000192,15.625166646795597,1.2472495936212713,-0.022156012368795608
187.30000000000192,15.658981820027824,1.2507761194067177,-0.02265951017638379
188.40000000000194,15.693228522336586,1.2544013470824933,-0.02272974624871882
189.50000000000196,15.72710062485352,1.2592982682577425,-0.0227299810122501
190.60000000000196,15.761179534400156,1.2646469381568362,-0.02273002442929517
191.70000000000198,15.794911176006977,1.266858206819713,-0.022739100136605295
192.800000000002,15.82904814725021,1.2712530627020342,-0.023432128085972614
193.90000000000202,15.86255901661831,1.2774307295291791,-0.02338912290601769
195.00000000000205,15.896728248146033,1.2803082325234538,-0.0245837149590713
196.10000000000204,15.930452560155496,1.2846916505348354,-0.02469289354048554
197.20000000000206,15.96408194643688,1.2911575300898428,-0.025747259861499394
198.3000000000021,15.997905123183427,1.2959293556901237,-0.026010979083655794
199.40000000000208,16.031841677759598,1.29960562240501,-0.02601000791838981
200.5000000000021,16.06556718105373,1.3044211740335072,-0.026023994135452977
201.60000000000213,16.0994438884939,1.310178352994344,-0.027337581439581093
202.70000000000215,16.13285022388026,1.316380761774695,-0.02750117302326549
203.80000000000217,16.166109598334376,1.3212225601772012,-0.028628792900031286
204.90000000000217,16.200561822285568,1.329162111313532,-0.029062911270806957
206.0000000000022,16.23454323902223,1.3351286848155985,-0.030856162917727303
207.1000000000022,16.268130773988,1.3427507665548473,-0.03128121924506244
208.2000000000022,16.301189408334018,1.3490599695153813,-0.031286027862701626
209.30000000000223,16.335628948327475,1.3581547922206594,-0.03243405828454238
210.40000000000225,16.36935848132681,1.3668921670051835,-0.03119875635116598
211.50000000000227,16.40239823309727,1.3766314186458368,-0.03177208665815412
212.6000000000023,16.43694542682429,1.3863240568198525,-0.031152853608372943
213.7000000000023,16.470589556835126,1.3967804587187826,-0.03128201232986072
214.8000000000023,16.504428767905807,1.4100185365567732,-0.031356658700623985
215.90000000000234,16.538382578938993,1.423889110716655,-0.03262371506946593
217.00000000000233,16.57193322358182,1.440121067569524,-0.03521860324524928
218.10000000000235,16.60580246380327,1.4580450067149746,-0.035142780048583955
219.20000000000238,16.639835974726754,1.4783453375410645,-0.03655981276728859
220.3000000000024,16.673189735744366,1.4987556696585842,-0.037311717982949855
221.40000000000242,16.707347762462827,1.5211141738798928,-0.037880770089973925
222.50000000000242,16.741144622405837,1.5482582925398698,-0.03935015894313931
223.60000000000244,16.77503831797931,1.5778974016694152,-0.040709957580638
224.70000000000246,16.809291681674438,1.610876798273714,-0.042272162013858416
225.80000000000246,16.843120573301327,1.6472650249832375,-0.04369722773687812
226.90000000000248,16.877171653616486,1.6853505254767915,-0.04598464164132654
228.0000000000025,16.911486866219896,1.7298555515017142,-0.047659849396199494
229.10000000000252,16.945419924871214,1.77826443607748,-0.048251205789264784
230.20000000000255,16.979941851621547,1.829888752088432,-0.05076365195384369
231.30000000000254,17.0141481305041,1.8851122579091328,-0.05272053649351127
232.40000000000256,17.048305899822843,1.9442524408988575,-0.05522334071480817
233.5000000000026,17.082618301345732,2.0067789248300243,-0.057688847504319796
234.60000000000258,17.116929820509387,2.0678349574026,-0.06055907966338836
235.7000000000026,17.151445235937043,2.132024591032354,-0.06358798719522119
236.80000000000263,17.185545993864967,2.1908320976994315,-0.06646928277277242
237.90000000000265,17.22009922615887,2.2554660578002528,-0.06901835385827271
239.00000000000267,17.254216684920024,2.3127672127710506,-0.073984242193192
240.10000000000267,17.28870348677545,2.368451062139733,-0.07797223788212948
241.2000000000027,17.322789081633438,2.4196540320238484,-0.08197481367700288
242.3000000000027,17.35696087732778,2.4651414626202044,-0.08534513827624313
243.4000000000027,17.39027425372586,2.5052610689618664,-0.09006063100083717
244.50000000000273,17.4240316068663,2.5406895897391704,-0.09472568688879024
245.60000000000275,17.458734800580444,2.5729946387081473,-0.09713727845674525
246.70000000000277,17.492795422135607,2.5975365385967684,-0.10283259850882409
247.8000000000028,17.52639315827389,2.6153881324499557,-0.10780579414185354
248.9000000000028,17.55957601706542,2.6322303377770324,-0.11317915799501543
250.0000000000028,17.593528913383018,2.6464622153923076,-0.11981642494193512
251.10000000000284,17.627039283125836,2.6542716797977595,-0.12547346283047967
252.20000000000283,17.660695837938896,2.661351588541713,-0.13145500405276467
253.30000000000285,17.694248153846356,2.6657951036745975,-0.13810182467219434
254.40000000000288,17.727826642319048,2.667270016140967,-0.14417055807457357
255.5000000000029,17.761249187232927,2.6704321801743665,-0.15124071959824503
256.6000000000029,17.794639839442798,2.673615961716087,-0.15957641967183633
257.7000000000029,17.827840750325933,2.677864484659144,-0.1674634640295074
258.8000000000029,17.86159357413694,2.679648759413266,-0.17626327142690945
259.90000000000293,17.894881656536334,2.6865975681853986,-0.1859978948847445
261.00000000000296,17.928197323339333,2.6909547052301885,-0.195496204744265
262.100000000003,17.961692408765074,2.6985432844859973,-0.20638248124925296
263.200000000003,17.995008272249184,2.704471215704527,-0.21682436337552158
264.300000000003,18.028712545846467,2.714096378932517,-0.22653900482010414
265.40000000000305,18.061247693942168,2.7257955102490294,-0.2369644600551637
266.50000000000307,18.095321969963717,2.7363308178478123,-0.24952060428939316
267.6000000000031,18.128787477179632,2.745589261278191,-0.2613905225024564
268.7000000000031,18.16237145856678,2.752937008253173,-0.27491057627834836
269.8000000000031,18.195928853010578,2.7632081179025945,-0.28871099257465227
270.9000000000031,18.229352990353348,2.770124520811105,-0.3004494540682652
272.0000000000031,18.262447843569777,2.778298929741809,-0.3140565683180334
273.10000000000315,18.2962021009347,2.7856160413188817,-0.32820829199708346
274.2000000000032,18.329476442349613,2.790684600607704,-0.34436991003269046
275.30000000000314,18.363192082663815,2.79341813203338,-0.3604469680821327
276.40000000000316,18.396357197084722,2.7948684889263347,-0.37513779177210216
277.5000000000032,18.429538723713463,2.7917411029497656,-0.3914943024591597
278.6000000000032,18.462886958303592,2.7884931120307335,-0.4073385447258038
279.70000000000323,18.496223235329786,2.782478197132639,-0.42607455889091783
280.80000000000325,18.52938452587178,2.7733717405738347,-0.4443847249719073
281.9000000000033,18.56250977149699,2.7611885705401256,-0.4635368154343693
283.0000000000033,18.59575813195369,2.7475589336176798,-0.4815239803222435
284.1000000000033,18.628205278319033,2.7304225383466068,-0.4993925918004014
285.20000000000334,18.662035541295793,2.7104860642304764,-0.5194387579213213
286.30000000000337,18.695083492600308,2.6874770896519578,-0.5386420129602545
287.40000000000333,18.728010595723237,2.6608235546930525,-0.5581272583746935
288.50000000000335,18.760762040325755,2.6295432438784605,-0.5789856176168815
289.6000000000034,18.793879807220364,2.5944782233793195,-0.600352446816387
290.7000000000034,18.826602867177744,2.559139782461801,-0.6201092054938502
291.8000000000034,18.859584269209837,2.521932067818463,-0.640528115975501
292.9000000000034,18.89211843828651,2.478999854889518,-0.6617336502769433
294.0000000000034,18.92470146655793,2.43710143054651,-0.6826655548305629
295.10000000000343,18.95714685302601,2.3930449920303123,-0.7025267587661559
296.20000000000346,18.990493897195638,2.3454670767761123,-0.7224067435030608
297.3000000000035,19.023320413565166,2.2989989901205656,-0.7424398060697417
298.4000000000035,19.055707314400042,2.2517849771324356,-0.7625078040486928
299.5000000000035,19.088608224785798,2.203025864872363,-0.7822353453642221
300.60000000000355,19.12111055697254,2.159118663068802,-0.8014322292762635
301.70000000000357,19.15380441324813,2.1173801871340387,-0.8196364777403442
302.8000000000036,19.18684385257162,2.0755259961783312,-0.8358292796456674
303.9000000000036,19.219770245042103,2.0377728558905286,-0.8535399654583813
305.0000000000036,19.25286787020773,2.0040193182315624,-0.8690460147379295
306.1000000000036,19.28553789929167,1.9750539250716481,-0.8850452128404291
307.2000000000036,19.318611449985053,1.9474602738573936,-0.900684185054637
308.30000000000365,19.35134940066722,1.9277466092248199,-0.9152259065512101
309.4000000000037,19.384775084208542,1.9082709769884765,-0.9284066919209919
310.5000000000037,19.418077262171092,1.8953915555369545,-0.9420461899374786
311.60000000000366,19.451288172356787,1.8864326083364467,-0.9553735129103105
312.7000000000037,19.484531087882267,1.8802347206775614,-0.9686493450518019
313.8000000000037,19.51780967251853,1.880398311845846,-0.980751018410599
314.90000000000373,19.551175533450486,1.880189883284682,-0.9906157076459277
316.00000000000375,19.58480250720379,1.8841478702917114,-1.0022209702488887
317.1000000000038,19.61841577350516,1.8886527077839266,-1.0130187602538663
318.2000000000038,19.651741272749415,1.8978815454623676,-1.0231720007859395
319.3000000000038,19.685303577045346,1.908045116517018,-1.0338965244481697
320.40000000000384,19.71843742893859,1.9184102935127871,-1.04322271833655
321.5000000000038,19.752908932391026,1.9301714133448065,-1.0542263953799824
322.60000000000383,19.786250851653136,1.9429772498360474,-1.0647081457669785
323.70000000000385,19.81962954305817,1.9569641449054496,-1.0729431361085382
324.8000000000039,19.853753742209186,1.9707125164835966,-1.081564692015717
325.9000000000039,19.88725523461589,1.9788980323346246,-1.0910070878713465
327.0000000000039,19.920988592976805,1.9945547637993752,-1.1025165527531788
328.10000000000394,19.954666070777737,2.004978855590965,-1.11181551782273
329.2000000000039,19.988449077688692,2.0145951177173314,-1.1218540802382981
330.30000000000393,20.02219689846628,2.0268031967021756,-1.1321325832986684
331.40000000000396,20.055938028523343,2.0370609856804314,-1.1416852677252964
332.500000000004,20.08968812947999,2.043499726445108,-1.150885981836554
333.600000000004,20.123510900260257,2.0503026055255837,-1.1600704332494698
334.700000000004,20.157044315917297,2.0551337761362287,-1.1715654829194055
335.80000000000405,20.190760814430696,2.0570378507928324,-1.1816801284732024
336.90000000000407,20.224353737273123,2.059877775545698,-1.1903174482899868
338.0000000000041,20.258137012101002,2.05997678977683,-1.1998615730308786
339.10000000000406,20.2910621907032,2.0555115346724167,-1.2096240324171186
340.2000000000041,20.325620139378454,2.0497266730301114,-1.2192122908752907
341.3000000000041,20.359107857294024,2.0412435308086194,-1.2295543120756545
342.4000000000041,20.391926255240953,2.031918913405327,-1.2402203488949195
343.50000000000415,20.425613699309686,2.0213002751994313,-1.2501729992902884
344.6000000000042,20.45935189411204,2.0082132312581935,-1.2596017941335371
345.7000000000042,20.493288617572308,1.9921195018223246,-1.2693119350646564
346.80000000000416,20.526515833901747,1.9793382228877017,-1.2794297106343624
347.9000000000042,20.560325938607015,1.9564665658062395,-1.2901439969799458
349.0000000000042,20.594180293740077,1.9307242662591872,-1.2993415237745913
350.10000000000423,20.627603996022366,1.9029745358332424,-1.3096140455790484
351.20000000000425,20.661214276340477,1.8721500796938209,-1.3195841870299372
352.3000000000043,20.694242279640598,1.8412311747058574,-1.3293716764293957
353.4000000000043,20.727791553402113,1.8088643157130775,-1.3390835100776428
354.5000000000043,20.761314691855997,1.7757369213682548,-1.3489914837340962
355.60000000000434,20.79472156937856,1.7450609479824906,-1.3588833627971235
356.7000000000043,20.827864508773626,1.7149716814049005,-1.36818062031197
357.80000000000433,20.86141083674395,1.6864850224159,-1.3771533268057539
358.90000000000435,20.894920594424104,1.6579716313259456,-1.3867882965586769
360.0000000000044,20.928376539072097,1.6324673172929987,-1.3965409203870536
361.1000000000044,20.962044882574453,1.6071927177148067,-1.405397065600329
362.2000000000044,20.995591675962817,1.5818509434531822,-1.4151017025564432
363.30000000000445,21.029485661462843,1.5595639120627354,-1.4253947160974287
364.4000000000044,21.06306768586809,1.5340595009441544,-1.4337907763222222
365.50000000000443,21.096459947936655,1.5105557305755617,-1.442839457366028
366.60000000000446,21.129859051948987,1.4884330501498049,-1.452738149629679
367.7000000000045,21.163425467735046,1.4656251609235529,-1.462357945523424
368.8000000000045,21.19764399187173,1.4438430610499244,-1.4716484450012697
369.9000000000045,21.231062251613963,1.4213971152617093,-1.4808085565050377
371.00000000000455,21.264646213415435,1.3948764341711073,-1.4898189102430979
372.10000000000457,21.298119277974653,1.3719153561101056,-1.498956274387944
373.2000000000046,21.33175204228944,1.3484128264308453,-1.5077049892121162
374.30000000000456,21.365613415806397,1.3226976070463508,-1.5169476640818882
375.4000000000046,21.399262735859107,1.2975542229576522,-1.5272119043369283
376.5000000000046,21.433064150704205,1.2741783209373345,-1.5365536441506817
377.6000000000046,21.46656780567514,1.2478988734336982,-1.5448845671500213
378.70000000000465,21.500379458953784,1.2226745894576405,-1.5530196667862373
379.8000000000047,21.534179857324528,1.197149346915864,-1.560861059753464
380.9000000000047,21.56785672273135,1.171023877700615,-1.5695759911777332
382.00000000000466,21.60141964779454,1.1441447501100275,-1.577696633243311
383.1000000000047,21.634932052971664,1.1220401587552506,-1.586151153424869
384.2000000000047,21.668225527721617,1.0971647480635172,-1.5919828321353529
385.30000000000473,21.702954425165583,1.0729430992579856,-1.5997852533574486
386.40000000000475,21.73678699320925,1.047786580427997,-1.6078232059413518
387.5000000000048,21.77054581944385,1.0259498071027509,-1.6164158963864756
388.6000000000048,21.80440857162361,1.004009531479587,-1.623510206633922
389.7000000000048,21.838112427485626,0.9812585287009191,-1.6306633810028943
390.80000000000484,21.872163210407674,0.9604769525482679,-1.6379213307132794
391.9000000000048,21.906034723447743,0.9426483675237726,-1.6454037500090588
393.00000000000483,21.9397284513335,0.9180651223970522,-1.6529992641218576
394.10000000000485,21.973482073530068,0.9003419648955027,-1.6608241038562133
395.2000000000049,22.007558618086673,0.8804290033618358,-1.6669023704897015
396.3000000000049,22.041676350098747,0.8612304386888969,-1.6743987009095829
397.4000000000049,22.07570046373172,0.8452732862801984,-1.6801619928439568
398.50000000000495,22.109902459078754,0.8274714506254064,-1.6868716930823413
399.6000000000049,22.143434723842628,0.8107002101752875,-1.6936601387466945
400.70000000000493,22.17748415873399,0.7938776230112747,-1.7004856158350576
401.80000000000496,22.21176141270847,0.7801217399009733,-1.7073301140071417
402.900000000005,22.245844259830374,0.7651423750156039,-1.714287822700677
404.000000000005,22.279870654586112,0.7517847638986337,-1.7188254752518666
405.100000000005,22.31405246674546,0.7417863226075246,-1.725471717501108
406.20000000000505,22.34827496263416,0.7286207064955631,-1.731820724101861
407.30000000000507,22.382302326678055,0.7191735653249152,-1.7389995994207763
408.4000000000051,22.416315539462534,0.7091062797658707,-1.7466946656243634
409.50000000000506,22.450367368887537,0.6974713917737521,-1.7535963816057554
410.6000000000051,22.484917067910107,0.6891505803835178,-1.760868645748086
411.7000000000051,22.518821248456284,0.6844518327557589,-1.7683116122622335
412.8000000000051,22.5533456969926,0.6810593071692677,-1.775698277688949
413.90000000000515,22.587745947746665,0.67649475346478,-1.7834096827920827
415.0000000000052,22.62195117890206,0.6736521468835435,-1.7900516173537238
416.1000000000052,22.65665741355646,0.6741837856559754,-1.7978277489962045
417.20000000000516,22.690854035937473,0.6770314688291847,-1.8047958201313201
418.3000000000052,22.72522927344134,0.6840039475186264,-1.8108706713859721
419.4000000000052,22.75981088205808,0.6878288886340136,-1.8189064813756213
420.50000000000523,22.794383865546664,0.6955533786903518,-1.8257433861175905
421.60000000000525,22.829104669637623,0.7037528690094883,-1.8331433545371167
422.7000000000053,22.863704382807594,0.7131303988214406,-1.841233179994184
423.8000000000053,22.89830206119153,0.7248633909717797,-1.8492931930968637
424.9000000000053,22.932785750913812,0.7378137936890946,-1.8569489278032094
426.00000000000534,22.9676263383317,0.7505219728319685,-1.8649089893349284
427.1000000000053,23.002309534282723,0.765455051813944,-1.8715027989109978
428.20000000000533,23.03696708666617,0.778251614213936,-1.8787776335825432
429.30000000000535,23.071795344363927,0.792808234899363,-1.887366735789167
430.4000000000054,23.10598729215882,0.8095387881240821,-1.8938655548591465
431.5000000000054,23.140558988983294,0.8251592597634249,-1.9017079462766309
432.6000000000054,23.17615407016215,0.8397326398159664,-1.9095688087521512
433.70000000000545,23.211055295990768,0.8567922627636941,-1.9167924579599434
434.8000000000054,23.24578600352749,0.8716285839904694,-1.9246748700847038
435.90000000000543,23.280512942645533,0.8864466291733166,-1.9324822842469658
437.00000000000546,23.315398888848872,0.9003583019545189,-1.9386665278297173
438.1000000000055,23.350220671408607,0.9128651428023264,-1.9461830385308279
439.2000000000055,23.385148832089914,0.924713377983378,-1.9537402843596747
440.3000000000055,23.41982978830628,0.9385586502727541,-1.9606217189272344
441.40000000000555,23.454749205702377,0.9486448245346097,-1.9679848979784058
442.50000000000557,23.489537748013188,0.9609383523290742,-1.975960095773146
443.6000000000056,23.524498869136398,0.969663646696467,-1.9827461010036087
444.70000000000556,23.55945470448651,0.9810488913167891,-1.9907825494856723
445.8000000000056,23.594213969419073,0.9859929496031361,-1.9985052807444608
446.9000000000056,23.629331358995007,0.9954774253980725,-2.0064370539978515
448.0000000000056,23.66388994033509,1.0017625399498655,-2.0147238544332255
449.10000000000565,23.699073346096373,1.0058346926935313,-2.0221862959238344
450.2000000000057,23.734240761745333,1.0149693312221697,-2.0295542225788914
451.3000000000057,23.768862061620553,1.0199065973479469,-2.037343587918675
452.40000000000566,23.80362225908209,1.0231084514708995,-2.045577342271835
453.5000000000057,23.838661916137337,1.0310668645804528,-2.053596637522057
454.6000000000057,23.873593240127217,1.0335221428478087,-2.060877890230321
455.70000000000573,23.90859806924134,1.040423103786447,-2.0690572409743284
456.80000000000575,23.943408997836826,1.0452182113633557,-2.07585816631324
457.9000000000058,23.97867878016459,1.0470253101187668,-2.081695297286645
459.0000000000058,24.01355486100606,1.049787710764251,-2.089431320299422
460.1000000000058,24.048186572660605,1.0536043562465685,-2.096427647642501
461.20000000000584,24.083336420853776,1.0568193212085697,-2.104970070245512
462.3000000000058,24.118155442814352,1.0589940750216458,-2.1126746525851146
463.40000000000583,24.152969378072324,1.0599045201141206,-2.1208942208226373
464.50000000000585,24.188242933656554,1.0611454135213647,-2.12888954853881
465.6000000000059,24.22327917445071,1.0639413142311291,-2.135966337479844
466.7000000000059,24.257623350854573,1.0651172508518594,-2.1426527298343796
467.8000000000059,24.29332023046377,1.0656762217678473,-2.150290824914253
468.90000000000595,24.32854966630181,1.0661214783161441,-2.157788696810208
470.0000000000059,24.36330809419488,1.066348274087431,-2.165023581010956
471.10000000000593,24.398193195809842,1.0683974966172938,-2.172718536112235
472.20000000000596,24.433363679948638,1.0691833311602459,-2.179153194513022
473.300000000006,24.46851152994272,1.06686208320171,-2.186601344083206
474.400000000006,24.503402801742887,1.067813140796508,-2.1943397099084008
475.500000000006,24.538670595385653,1.0672431540976592,-2.2015738983219597
476.60000000000605,24.573109409734396,1.068064605551432,-2.2084839071331652
477.70000000000607,24.60842755262416,1.0675398090924404,-2.2148625504325437
478.8000000000061,24.64352872192408,1.0663345973606675,-2.2221677299110594
479.90000000000606,24.678643123639784,1.0654502642695582,-2.228396027411755
481.0000000000061,24.713693338456032,1.065630082888693,-2.235543011962991
482.1000000000061,24.74865497521868,1.0648692534753992,-2.242224032587801
483.2000000000061,24.783399272962036,1.063618912735269,-2.2485641958343097
484.30000000000615,24.819072639725277,1.0617195597128102,-2.2557039828520478
485.4000000000062,24.854027692513185,1.0608493237501286,-2.2638520093330152
486.5000000000062,24.889265367092275,1.0592812747803841,-2.270773368441203
487.60000000000616,24.924266005988212,1.0591434162181508,-2.2779393161059382
488.7000000000062,24.95963699381255,1.0570850045537992,-2.284876971817006
489.8000000000062,24.99456183360181,1.057174835710244,-2.291577560606815
490.90000000000623,25.029706857330957,1.0557505076152225,-2.297607138687725
492.00000000000625,25.064765758861665,1.0536203280399554,-2.3033577669169523
493.1000000000063,25.099938423542287,1.0515672707967116,-2.311412112271549
494.2000000000063,25.135148958895815,1.0506648563044367,-2.317186796845748
495.3000000000063,25.17041625749609,1.0501451953621217,-2.323757555427768
496.40000000000634,25.205255343587982,1.0474490455408123,-2.332498973026626
497.5000000000063,25.240614597343523,1.0453482501285272,-2.3381796889948228
498.60000000000633,25.27568360828348,1.0452846654121446,-2.345820339029701
499.70000000000636,25.310592841974298,1.0432663235636983,-2.3517598817215557
500.8000000000064,25.346202323850545,1.0392783879305365,-2.3587783769542994
501.9000000000064,25.381394838803196,1.039923645915879,-2.3650945229178
503.0000000000064,25.41661253120197,1.0378651073910115,-2.372355284820461
504.10000000000645,25.451947412011933,1.0363771829876858,-2.3794521028286937
505.2000000000064,25.487389815392785,1.0348137249780356,-2.385816600817514
506.30000000000643,25.522487219475092,1.0310107908670085,-2.3933487173697685
507.40000000000646,25.55687337786364,1.028311853623117,-2.3994279257414846
508.5000000000065,25.593006012180275,1.0277953310095571,-2.407937213675592
509.6000000000065,25.628315163110752,1.0252130300739226,-2.4154174443320136
510.7000000000065,25.663573615947474,1.022220320657693,-2.42188249894456
511.80000000000655,25.699070066055302,1.0180611195498281,-2.4298071854313905
512.9000000000066,25.7340655937788,1.018303722408526,-2.4356074464055464
514.0000000000066,25.769555113118415,1.0148339289817507,-2.441331820135942
515.1000000000065,25.804666959520347,1.0136372261044388,-2.4485860686116476
516.2000000000066,25.840065175467885,1.0078343041380402,-2.456058370385851
517.3000000000065,25.87565415998417,1.0073247550708042,-2.464856815226467
518.4000000000067,25.911007680541818,1.004629010760592,-2.471729270504016
519.5000000000066,25.945979209734727,1.001789100855325,-2.479132855497361
520.6000000000067,25.981517717535155,0.9995365792645865,-2.4864289352813467
521.7000000000066,26.01677687815216,0.9965344952085278,-2.493788435767221
522.8000000000067,26.052488463921932,0.9953633032540625,-2.5017666560015286
523.9000000000067,26.08771839724375,0.994111542703012,-2.5085381712133286
525.0000000000067,26.123012474555996,0.9915909202462276,-2.5162081185815017
526.1000000000067,26.158609786364373,0.9890758584893022,-2.5231969017692943
527.2000000000068,26.193794188280318,0.9882236590293408,-2.530808878564729
528.3000000000068,26.229298147683373,0.9872048553520123,-2.5375507855947506
529.4000000000068,26.26524964353107,0.9846463084554247,-2.5441583573162188
530.5000000000068,26.300060950976388,0.9836985418702824,-2.5522074291897585
531.6000000000068,26.335916733768993,0.9790268599398553,-2.558960682789306
532.7000000000069,26.37153222121561,0.9783890642812731,-2.5657828441467245
533.8000000000068,26.406958273165767,0.9770242086730343,-2.572386869623209
534.9000000000069,26.442278325708354,0.9751599757868522,-2.578465830339053
536.0000000000068,26.4780140233182,0.973458130580245,-2.584878977212158
537.100000000007,26.51343504097944,0.9734297543040559,-2.5911280906294394
538.2000000000069,26.549301801897602,0.9717103035474333,-2.5982656429803166
539.300000000007,26.58451457226716,0.9719598525594915,-2.6040555384694106
540.4000000000069,26.619965075330324,0.9689937665609714,-2.6109241762231887
541.5000000000069,26.6555277138722,0.9693913256978645,-2.6172083013399097
542.600000000007,26.691421202361365,0.9683047044229245,-2.6236688267372705
543.700000000007,26.72710654071423,0.9655989246173633,-2.629526437220199
544.800000000007,26.76275008168889,0.9647103201883075,-2.6353720611254063
545.900000000007,26.79804891532658,0.9657487620739076,-2.6415010176207563
547.000000000007,26.833848138976887,0.9629256574943525,-2.6471227738337118
548.1000000000071,26.869201610940866,0.9657800030962015,-2.652805027072229
549.2000000000071,26.904964239186274,0.9662714863085385,-2.658199428299006
550.300000000007,26.940898469441255,0.9639815336762083,-2.664512714915007
551.4000000000071,26.976335425997007,0.9659359715873738,-2.6697415516971965
552.500000000007,27.012260206232508,0.9665269233154127,-2.673782649898091
553.6000000000072,27.047223452600402,0.9655062979746769,-2.679875060997663
554.7000000000071,27.083740708354682,0.9647688098812632,-2.6847488081240325
555.8000000000072,27.11950279026455,0.9631004834161567,-2.689412327550358
556.9000000000071,27.154919449756658,0.9650346337225498,-2.6948752375900287
558.0000000000072,27.19094825025779,0.9645378647492453,-2.699570987720739
559.1000000000072,27.226813808294917,0.9651138919669414,-2.7046141277094815
560.2000000000072,27.262232236845936,0.9643018749266687,-2.7082521725609245
561.3000000000072,27.29821567715038,0.9637257782211882,-2.7133270541888868
562.4000000000073,27.33362894781498,0.9614606626251554,-2.717538253288432
563.5000000000073,27.369359283163732,0.9622077240353644,-2.722105675868421
564.6000000000073,27.405654691698714,0.9622860497531779,-2.7261784103785285
565.7000000000073,27.44164459803446,0.9605984863016727,-2.730282795502068
566.8000000000073,27.476980797026727,0.9596529703315269,-2.7344122737231595
567.9000000000074,27.51259126751176,0.9550466221209463,-2.73875997280587
569.0000000000074,27.54871045485747,0.9571709735470202,-2.7426694800781846
570.1000000000074,27.584455739616892,0.9534650052245729,-2.7466184202403765
571.2000000000073,27.620350206541033,0.9534569102108496,-2.7519688473911312
572.3000000000073,27.65591852385299,0.952830215975217,-2.7545073331214165
573.4000000000074,27.691990844007734,0.9510041985843913,-2.7590843130092164
574.5000000000074,27.7279981729158,0.9502582999025821,-2.763364388159452
575.6000000000074,27.76312817628748,0.9489659815144937,-2.7669166872088065
576.7000000000074,27.79963265236379,0.9475638598478874,-2.770742824012086
577.8000000000075,27.835321696316385,0.9464109598220443,-2.774457113752863
578.9000000000075,27.871292442229777,0.946232810070067,-2.7772851938620304
580.0000000000075,27.906732629529138,0.9458069825415112,-2.779436344011602
581.1000000000075,27.942990022561066,0.9437956633931736,-2.78308783161046
582.2000000000075,27.97884289579204,0.9415311359387256,-2.7859381485028045
583.3000000000076,28.014891777605634,0.9404757530074651,-2.7891060181184866
584.4000000000076,28.050999993266842,0.9413882884439687,-2.792291876975315
585.5000000000076,28.08677086513068,0.940663743021722,-2.796039100279245
586.6000000000076,28.12304607040495,0.9409152893527291,-2.798905645420417
587.7000000000077,28.158706365968907,0.9427516633356943,-2.801958511671521
588.8000000000077,28.19500128749635,0.9425720131091575,-2.805267478924973
589.9000000000076,28.23107859866817,0.9383938153405714,-2.807734503450738
591.0000000000076,28.266905307639597,0.9411241494495576,-2.8109632724037388
592.1000000000076,28.302761897492605,0.9428165442585905,-2.8137657631423036
593.2000000000077,28.338908688358785,0.940236351991828,-2.8164883685813784
594.3000000000077,28.374805250157433,0.9424471237251015,-2.8189426461749294
595.4000000000077,28.41081423113335,0.9438873596322616,-2.822041449639038
596.5000000000077,28.447126916446027,0.9462252107069218,-2.8251502232309766
597.6000000000078,28.48285223206432,0.9454301106899318,-2.827274960399269
598.7000000000078,28.51904020013479,0.9483689962528923,-2.8304258955593005
599.8000000000078,28.555118062580704,0.9474668865525896,-2.832266331908521
600.9000000000078,28.591640899813534,0.9492039027737742,-2.835158207500431
602.0000000000078,28.627847461903446,0.948535775957442,-2.837194174716035
603.1000000000079,28.663667916319977,0.9506202136360807,-2.838921889268414
604.2000000000079,28.7000542753869,0.9531206669161707,-2.8410617601096546
605.3000000000079,28.73602637714082,0.9541360002034307,-2.8436503446900625
606.4000000000078,28.77239763367149,0.9567062807506491,-2.844786171086599
607.5000000000078,28.808128495243153,0.9591801742196207,-2.847446581381246
608.6000000000079,28.844576230282186,0.9608693656200721,-2.849595262064917
609.7000000000079,28.880681336780704,0.9597681866558336,-2.851395180100897
610.8000000000079,28.91692438952565,0.9628668751514186,-2.8524217472931217
611.9000000000079,28.95328275288792,0.9640293128198947,-2.8541447474560426
613.000000000008,28.98966398473796,0.9651425502372958,-2.8571461329752337
614.100000000008,29.025714326017496,0.9690836531137704,-2.858482193556542
615.200000000008,29.06216872489856,0.9690563307061268,-2.8597565944643195
616.300000000008,29.098230634356824,0.9706532744047625,-2.8613028386143196
617.400000000008,29.134303051912706,0.9729620018835191,-2.8620044189981977
618.5000000000081,29.17086328329001,0.9745288679384122,-2.8641985655987705
619.6000000000081,29.206626612751528,0.9771077226531039,-2.8662863219420354
620.7000000000081,29.243334680022638,0.9757761182685495,-2.8680039361508687
621.8000000000081,29.27959658217095,0.9782239003286803,-2.869403808034262
622.9000000000082,29.31593840309828,0.9804204693612657,-2.8708340007721773
624.0000000000082,29.352147933444268,0.9839054884235345,-2.872258137643483
625.1000000000081,29.38805413884833,0.9870186518146465,-2.8733281856314803
626.2000000000081,29.42437049718379,0.986991896626609,-2.87564783353917
627.3000000000081,29.46129974353725,0.9915094989014356,-2.8775236045970773
628.4000000000082,29.49739792362523,0.993055174861388,-2.87901628015168
629.5000000000082,29.533813016514507,0.9947562677390506,-2.8802975333397702
630.6000000000082,29.57057585237374,1.0022720150751943,-2.8821010018136795
631.7000000000082,29.606664943839807,1.0016492200568246,-2.8825601316775114
632.8000000000083,29.643302842890535,1.0079990298665535,-2.882780033304297
633.9000000000083,29.679373158337558,1.0164598023143934,-2.883891323909682
635.0000000000083,29.715811206242464,1.0201006346732542,-2.8851921356561347
636.1000000000083,29.751943742244332,1.0235094160306666,-2.8867199176237945
637.2000000000083,29.788529280992904,1.029504977313471,-2.8880950375997703
638.3000000000084,29.82499905453355,1.0306931421023116,-2.8877091799110683
639.4000000000084,29.86136584210846,1.033846268117833,-2.8888123687176077
640.5000000000084,29.89774876118627,1.039603987831407,-2.8901641050956286
641.6000000000083,29.934206610398494,1.0422389814343465,-2.8901430327966224
642.7000000000083,29.970516324307418,1.0493814801703758,-2.8913702020692504
643.8000000000084,30.006930198356958,1.0568643407229765,-2.892922755918552
644.9000000000084,30.043315199027457,1.0613072683322031,-2.893475527594825
646.0000000000084,30.079878703346473,1.0639355207900634,-2.8944317562919135
647.1000000000084,30.116114505735037,1.0678515743611778,-2.895613448461648
648.2000000000085,30.15249269301883,1.0688894772887036,-2.8957447852761393
649.3000000000085,30.189170337055316,1.0787626268502346,-2.8970700476577034
650.4000000000085,30.22534777889769,1.0775585391338804,-2.8976633842957225
651.5000000000085,30.2616980026931,1.0832540642749167,-2.898393852339294
652.6000000000085,30.298503558170786,1.088770744523062,-2.8996963413165826
653.7000000000086,30.33475164339127,1.09302643182676,-2.899700719227372
654.8000000000086,30.371155869506172,1.0957894054609079,-2.8997820608869564
655.9000000000086,30.407621653236113,1.0989098784516464,-2.9010135728975897
657.0000000000086,30.444202768151733,1.10410308182772,-2.9021349632507567
658.1000000000087,30.480675467108174,1.1096224197907127,-2.9029102261307207
659.2000000000087,30.51704185832101,1.1167089172097375,-2.9037853882700553
660.3000000000086,30.55359298014097,1.120241252753846,-2.9050820444826986
661.4000000000086,30.589954399298897,1.1287460823542208,-2.9043977091668456
662.5000000000086,30.62678165161321,1.1336065195886684,-2.904890077678057
663.6000000000087,30.663004742912804,1.1436716666913775,-2.905712065160319
664.7000000000087,30.699337633521733,1.1494814817221835,-2.9070689238855367
665.8000000000087,30.736082556291798,1.155749046916355,-2.9082363083579246
666.9000000000087,30.772748700489625,1.1639380522302893,-2.9083794916260333
668.0000000000088,30.809036173929012,1.1712291064053288,-2.908376196306973
669.1000000000088,30.84531054596766,1.1786646709066964,-2.9097166240314793
670.2000000000088,30.882064590278024,1.183228769258303,-2.9095611323076516
671.3000000000088,30.91850692217261,1.1940473442659938,-2.909704734148591
672.4000000000088,30.9550363937955,1.2009663725155404,-2.9110531464648757
673.5000000000089,30.99153617462153,1.2088174083307666,-2.9110085060470148
674.6000000000089,31.028157630548712,1.212643602180034,-2.911586532427857
675.7000000000089,31.064700117031542,1.2181590873756059,-2.912282394159896
676.8000000000088,31.100930899690926,1.2245706610509668,-2.9133427822512417
677.9000000000088,31.13750364800062,1.2313474928821941,-2.9129855095105963
679.0000000000089,31.17338103255524,1.237049892229168,-2.914283304155115
680.1000000000089,31.21055339075687,1.242956139491365,-2.9147654195801445
681.2000000000089,31.24689097881993,1.2496548193348134,-2.9155749691575306
682.3000000000089,31.28349564285499,1.2524012727746587,-2.916927883374074
683.400000000009,31.319601937306274,1.2545833367379733,-2.918281657651571
684.500000000009,31.356450910446082,1.2580367622634232,-2.918210405684343
685.600000000009,31.392851207777525,1.2654519150550554,-2.919565613380274
686.700000000009,31.429376188422097,1.267947664782178,-2.919576920853009
687.800000000009,31.46592899308791,1.270746817075048,-2.9208950338769766
688.9000000000091,31.502240546228595,1.2714869054220204,-2.920884977875162
690.0000000000091,31.538742768878414,1.2777104929148915,-2.922217113461108
691.1000000000091,31.57457884158244,1.2776752511550837,-2.9222243339857394
692.2000000000091,31.61176002613029,1.2814217067408789,-2.923578235032248
693.3000000000092,31.648011150991984,1.2845203610752867,-2.923530861542366
694.4000000000092,31.684677548427278,1.287538075677212,-2.9249373212686836
695.5000000000091,31.721392633446264,1.2918154672583306,-2.924856282383608
696.6000000000091,31.757720381387117,1.2953344205919661,-2.9261052283612417
697.7000000000091,31.794253768099896,1.296717665909501,-2.9264244896669074
698.8000000000092,31.831093912295835,1.2987147182035739,-2.9274841925904616
699.9000000000092,31.867401081159397,1.3022508313029801,-2.926763974134893
701.0000000000092,31.903810554485005,1.3060472544800474,-2.927850699848034
702.1000000000092,31.9401753577997,1.3077262385372919,-2.928139555540497
703.2000000000093,31.976844775444356,1.3089296900068477,-2.928316192922359
704.3000000000093,32.01321123866438,1.3147622190253077,-2.9294850458103596
705.4000000000093,32.05029959173863,1.3164254040628636,-2.9308964718423076
706.5000000000093,32.086937481050306,1.3192304996149227,-2.932183899774345
707.6000000000093,32.12321301530266,1.3203361445704096,-2.93224478200508
708.7000000000094,32.15978852484768,1.321992857284965,-2.933479284293117
709.8000000000094,32.19638069011408,1.326879201461483,-2.936141760626887
710.9000000000094,32.23305551077873,1.3278325554045614,-2.9349798769730437
712.0000000000093,32.26954628546311,1.3308867124447348,-2.9347293233730056
713.1000000000093,32.30604109570357,1.3291475214272233,-2.934952641640467
714.2000000000094,32.34249712505412,1.3329959820702357,-2.934742837869463
715.3000000000094,32.37920249196673,1.333501757277876,-2.9361500833075604
716.4000000000094,32.41602881521902,1.335336040021304,-2.9368214590988257
717.5000000000094,32.45235928103206,1.3362220803548905,-2.9374993375575205
718.6000000000095,32.48913613307254,1.3376396705355011,-2.9400950654868
719.7000000000095,32.525786215508845,1.3359960935160835,-2.9400976441045827
720.8000000000095,32.562222169516104,1.3330043716368467,-2.9399540689641386
721.9000000000095,32.59890370466738,1.3344837836541343,-2.940432846022511
723.0000000000095,32.635479622935115,1.3324027541485182,-2.940572236021948
724.1000000000096,32.67216595851992,1.3275924143018045,-2.9414248668150336
725.2000000000096,32.70897096347846,1.33000373292846,-2.94141940314407
726.3000000000096,32.745687003094204,1.328878575480973,-2.9427485581822426
727.4000000000096,32.78234998926383,1.3251793920444448,-2.943673831742431
728.5000000000097,32.81870901545047,1.3207336628168824,-2.9450449216297643
729.6000000000097,32.855462140996565,1.3230351806922163,-2.9456310484678982
730.7000000000096,32.89209213647632,1.3221631692577946,-2.944984773888827
731.8000000000096,32.928625141865524,1.3208077866342185,-2.9459837403296207
732.9000000000096,32.965495703649374,1.3187408332768271,-2.9449552044516323
734.0000000000097,33.002152221347636,1.3192957387963506,-2.9463537401253626
735.1000000000097,33.0387758337328,1.3159185423173099,-2.946997175494805
736.2000000000097,33.075823366843586,1.3157905626694353,-2.9476838717991125
737.3000000000097,33.112355670538236,1.3130915011130382,-2.947824438628609
738.4000000000098,33.14916933586543,1.3101233941563213,-2.948934187431905
739.5000000000098,33.18609786344731,1.3027736441089577,-2.948861156527892
740.6000000000098,33.22241869007006,1.3007214655887087,-2.9490287417729126
741.7000000000098,33.25913682957288,1.2981020783814383,-2.950320434455775
742.8000000000098,33.295952180968314,1.295830341363739,-2.950833740397245
743.0000000000098,33.302667390215,1.295468547955204,-2.9506520945354158