File: 01_Data/PU_Aerogel/STA/N2/30K_min/PU_Aerogel_STA_N2_30KData_231213_R1.csv
##Temp./Â°C,Time/min,DSC/(mW/mg),Mass loss/mg
51.0,10.438664234080697,0.002433866135286955,0.003181148244862264
52.100000000000016,10.697449064797103,0.0752428872707882,0.0016733012965968186
53.20000000000003,10.834362388728492,0.13321287008566296,0.0022899646715064392
54.30000000000005,10.937492250914074,0.18099458207448693,0.001404016478371517
55.40000000000006,11.02491995733034,0.22171444638740123,0.0016061699550000696
56.50000000000008,11.102004565229556,0.2631935093261806,0.0010027683974369594
57.600000000000094,11.170467663248102,0.29458483516513656,0.001593308611743005
58.70000000000011,11.235631111882194,0.32741598033801256,0.0024529926376484212
59.800000000000125,11.294553109460029,0.3538804117597656,0.001742178169650721
60.90000000000014,11.353066325950493,0.3829296870620227,0.0013813255326642349
62.000000000000156,11.407126450075685,0.4098211107422116,0.0015952688996385689
63.10000000000017,11.459928395486076,0.43325997145628525,0.0006242573553514319
64.20000000000019,11.511101111351566,0.4547065251335878,0.0008676458414980104
65.30000000000021,11.559421720546963,0.47627381469785357,-3.4530452552417046e-05
66.40000000000022,11.6071861546802,0.4962851799849821,0.0005026874518208047
67.50000000000023,11.654323148792688,0.5138040179566137,0.0012164634685234432
68.60000000000025,11.699045785992237,0.5349357394538263,0.0007891161050643802
69.70000000000027,11.744055216683922,0.5483319938999323,5.5200662949950186e-05
70.80000000000028,11.788075199363032,0.5604801336534089,0.00042647037623755324
71.90000000000029,11.831931731284405,0.5784075745562423,-0.000332915199145134
73.00000000000031,11.87468363143379,0.5931680410892732,0.0005227713916253762
74.10000000000034,11.916704414792783,0.605745013161205,0.0007371273952605506
75.20000000000034,11.958700381290214,0.6201829877107801,-0.0010079736072050594
76.30000000000035,12.000187918688281,0.6331950087983484,0.0006062611557853259
77.40000000000038,12.040996847490467,0.6431665303960474,0.00021568273840255614
78.5000000000004,12.081355715387884,0.6527097680678895,-0.000720183590023904
79.6000000000004,12.121596366546493,0.6645730017691214,0.0005456289053586971
80.70000000000041,12.161733898450189,0.6742140000192973,0.0005050929814265359
81.80000000000044,12.201877387458445,0.6807297370467618,-0.00012167225009607208
82.90000000000046,12.24107008431112,0.6891847229653592,-0.0015846326969208846
84.00000000000047,12.2801373233489,0.6946518522925929,-0.0010109338371151466
85.10000000000048,12.319239711246832,0.7013491172090334,0.0003326362839617403
86.2000000000005,12.35753080213554,0.708142219441535,-0.0004189156892837609
87.30000000000052,12.396173545311012,0.714230010690748,-0.00027426298173383046
88.40000000000053,12.434600152489509,0.7194238956000034,0.0001764607834964238
89.50000000000054,12.472712687578749,0.723796936742535,0.0004750603394292341
90.60000000000056,12.510446355585714,0.727380935900688,0.00024708967534525783
91.70000000000059,12.548482327409737,0.7317045121720605,-0.0011620658420334884
92.8000000000006,12.585720582386323,0.7327987123481843,-0.0012113312566897072
93.9000000000006,12.623774640891334,0.7396513374609655,-0.001298784274678333
95.00000000000063,12.66057289326352,0.742726623295102,-0.0007456490164501339
96.10000000000065,12.698314863976648,0.7437007745580111,-0.001180060595524779
97.20000000000066,12.735256616659122,0.7472864846754506,6.598618251008048e-05
98.30000000000067,12.772635715666752,0.7483665647100046,-0.0012146453831158865
99.40000000000069,12.809786559173915,0.7523137035998442,-0.0011325218775954937
100.50000000000071,12.846487895546053,0.7536767660584969,-0.0012429929961732533
101.60000000000072,12.883426405109251,0.7547098270497645,-0.0013481261981045378
102.70000000000073,12.91987028350932,0.7587748541909627,-0.0012243904048743204
103.80000000000075,12.957099974812689,0.7581603765076339,-0.0012259027419094792
104.90000000000077,12.993273572485782,0.7603790058537604,-0.0012817543902046147
106.00000000000078,13.030312676591816,0.7629816003483295,-0.001221744846567674
107.10000000000079,13.067032505704118,0.7672906033563771,-0.0012900439963012822
108.20000000000081,13.103728550069562,0.7659635056726374,-0.00252592652944017
109.30000000000084,13.139440259625161,0.7702610171167288,-0.002509894742166896
110.40000000000084,13.176531713591771,0.7702838551327469,-0.00121718192318232
111.50000000000085,13.213617208044228,0.7720225844048707,-0.001210055667502985
112.60000000000088,13.249798153783386,0.7754001098305939,-0.001211547815640479
113.7000000000009,13.286405144292198,0.7737811236863615,-0.0026148291517769096
114.8000000000009,13.323010155322626,0.7786096049367869,-0.0017659937072607157
115.90000000000092,13.359270241864497,0.7795653124959143,-0.0007255756223818466
117.00000000000094,13.396123451318237,0.7817779298466381,-0.0010819266728270271
118.10000000000096,13.432052462833086,0.7850337514072027,-0.0010999471830688279
119.20000000000097,13.468525887091232,0.7877689357486443,-0.0010999770493502758
120.30000000000098,13.504800588441315,0.7912470872591377,-0.0020070707681627553
121.400000000001,13.541281375179851,0.7915687013849826,-0.0010992287502658016
122.50000000000102,13.577820116010445,0.7953062075503308,-0.0010999949541190546
123.60000000000103,13.613870197639674,0.7976013527877759,-0.001099915065942536
124.70000000000104,13.650044984654963,0.8034649066260039,-0.0010970641971623785
125.80000000000106,13.685602129009037,0.8020722836858271,-0.00040180857204985543
126.90000000000109,13.721718612950315,0.8048874353632205,-1.3804295666108857e-05
128.00000000000108,13.757999528653873,0.8075292271866796,-0.0009263386160824894
129.1000000000011,13.793610903258639,0.8114771016903144,-0.0010990797213303871
130.20000000000113,13.829829538780537,0.8116705365677103,-0.0011000080932888068
131.30000000000115,13.86549765316842,0.8159455215593322,-0.0011001028393549106
132.40000000000117,13.901262384837494,0.8167930824249725,-0.0010989125298768165
133.50000000000117,13.936893043204371,0.8198531214356579,-0.0023611744179663496
134.6000000000012,13.972655730756411,0.8218794794325002,-0.0021304785406308646
135.7000000000012,14.00831275961454,0.8245098064600144,-0.00110041035648889
136.8000000000012,14.04365225758102,0.8263011067948273,-0.0011000133235441467
137.90000000000123,14.079404962305542,0.8275840059832811,-0.0011000001710992358
139.00000000000125,14.114993257039222,0.8339063352070123,-0.0010978578493627822
140.10000000000127,14.149871616702743,0.8345881977921653,-0.0012639975652546376
141.2000000000013,14.185715954182033,0.8367710857119808,-0.0011083520913266476
142.3000000000013,14.221120679686726,0.8378468367747968,-0.0011077305149638228
143.4000000000013,14.256313927976596,0.841538465639251,-0.0024251797002676767
144.50000000000134,14.291475211078145,0.8423889664003721,-0.0024199994464364494
145.60000000000133,14.326539872724881,0.8457606820700487,-0.0024199992374693835
146.70000000000135,14.36211490545716,0.8490614485021458,-0.002419970007780936
147.80000000000138,14.397041359088947,0.8509943721099484,-0.002422174686803835
148.9000000000014,14.432102420210095,0.8525097918345054,-0.0038387383144584675
150.00000000000142,14.467485828476727,0.8526580250680866,-0.0037379975870663884
151.10000000000142,14.501759525375496,0.8595208759515857,-0.00352429037675428
152.20000000000144,14.53687478942203,0.8576294532731651,-0.0024206224575542556
153.30000000000146,14.571952559902043,0.8634089414787293,-0.002420006848565137
154.40000000000146,14.60666235979189,0.864308635423713,-0.002420006249498563
155.50000000000148,14.641450084431987,0.8672281209394798,-0.0024199871167844833
156.6000000000015,14.6762110125646,0.8678868809766873,-0.002358308821852173
157.70000000000152,14.71094038923166,0.8730207898305957,-0.003048240588302331
158.80000000000155,14.746200066573751,0.8737201775968835,-0.0037351070886146864
159.90000000000154,14.780627165255455,0.8749001395022031,-0.003728678420986231
161.00000000000156,14.815265765203357,0.8794794411037362,-0.004079992045404879
162.1000000000016,14.849982337534268,0.8803171260675504,-0.0050514612086098865
163.20000000000158,14.884755731043095,0.8827671423098906,-0.005049946290179186
164.3000000000016,14.91929594513668,0.8840404680184101,-0.005049999974999775
165.40000000000163,14.954012107993716,0.8871068641617914,-0.0050500000270883305
166.50000000000165,14.988496895111552,0.8885514199103165,-0.0050499974279447635
167.60000000000167,15.022980721298307,0.890758656949536,-0.005049851136100347
168.70000000000167,15.057494324195908,0.8908954221898138,-0.005075253372736288
169.8000000000017,15.09198537736886,0.8961350695760194,-0.006374004412297296
170.9000000000017,15.126595130951246,0.896570157438212,-0.006369800697880734
172.0000000000017,15.161166145352915,0.8996650828838879,-0.006369992457195384
173.10000000000173,15.195517707197496,0.9034037885813555,-0.006371003287531263
174.20000000000175,15.229858016051752,0.9046433195713746,-0.006394389773408005
175.30000000000177,15.263924000271086,0.905816494118248,-0.007677537608174134
176.4000000000018,15.298437447026517,0.9090257156618213,-0.007690053696366217
177.5000000000018,15.332769249050918,0.9095818261133573,-0.007691004309587246
178.6000000000018,15.366960771380516,0.9135744899765232,-0.007351687708030408
179.70000000000184,15.40133237874976,0.9157567498306078,-0.006700266235211583
180.80000000000183,15.435471185154459,0.9165295472778983,-0.006714034760161969
181.90000000000185,15.469855105716144,0.9202797019311033,-0.00802918623886617
183.00000000000188,15.503745410471748,0.9248395266318004,-0.008024809481086415
184.1000000000019,15.538061334867603,0.9253103006328456,-0.00930827826283842
185.20000000000192,15.571992241251708,0.9294575131002378,-0.009326190623474506
186.30000000000192,15.605159602396672,0.9324477813813312,-0.010722342780594474
187.40000000000194,15.639138613870982,0.9363651914136617,-0.010649991166858719
188.50000000000196,15.67373985175135,0.9376056261041366,-0.01064999134756306
189.60000000000196,15.707787396128424,0.9415040794076218,-0.010650000039299723
190.70000000000198,15.741811533938195,0.9418918692533065,-0.010649998816048445
191.800000000002,15.775551013901582,0.9466441204653642,-0.010650124566267571
192.90000000000202,15.809292879934299,0.950780767960418,-0.010650476090250827
194.00000000000205,15.84267311070552,0.9556671371428178,-0.011840913972636535
195.10000000000204,15.87721197462402,0.9568023064938687,-0.01197138023104527
196.20000000000206,15.910657083597151,0.9633042006777477,-0.012048475721142538
197.3000000000021,15.944509777858508,0.9654901767838902,-0.012653086740011421
198.40000000000208,15.978427004440551,0.9695716616513218,-0.013299016483588666
199.5000000000021,16.01238696108934,0.9729028742029608,-0.013290251001609743
200.60000000000213,16.046020835058474,0.9796653980009942,-0.0133104680846019
201.70000000000215,16.079464538103647,0.9852428302308459,-0.015272055098027426
202.80000000000217,16.113339562657103,0.9884977060315481,-0.015590686348723182
203.90000000000217,16.146935980944157,0.9934365288956168,-0.01560210709286558
205.0000000000022,16.180761859900695,0.9971505784745877,-0.016948650946899235
206.1000000000022,16.214310595069538,1.0014007082446983,-0.016909045343637796
207.2000000000022,16.248084170046077,1.0093879952554572,-0.016910076820731312
208.30000000000223,16.281884760470795,1.0164839077687566,-0.016924128316626597
209.40000000000225,16.315434790394086,1.023833325992511,-0.018192841545954686
210.50000000000227,16.349230235190525,1.033434640791766,-0.018228029196610596
211.6000000000023,16.382628265809103,1.0416007792669209,-0.01951819977873015
212.7000000000023,16.416772079674708,1.0506951517283223,-0.019799372377228508
213.8000000000023,16.45035356481573,1.0637805683573045,-0.021303077272709636
214.90000000000234,16.484104455907165,1.0750599589701177,-0.022009954708645196
216.00000000000233,16.517208897526714,1.088190924260482,-0.021295347933310005
217.10000000000235,16.551703734126516,1.1022799498464715,-0.021491823676185184
218.20000000000238,16.585373639043816,1.1205479383577686,-0.02260827025708867
219.3000000000024,16.618874415972265,1.1391452359766132,-0.02394379315423789
220.40000000000242,16.652850988569234,1.1593965482631772,-0.02390344843197001
221.50000000000242,16.686490190381022,1.1816389927008264,-0.02528080553301404
222.60000000000244,16.72009420346171,1.206972333244972,-0.025315111609723218
223.70000000000246,16.754165479214873,1.23803632144368,-0.026625356019405633
224.80000000000246,16.78750198307496,1.266924827896061,-0.029116919666803298
225.90000000000248,16.822277994452257,1.3043660548998217,-0.030888887560694744
227.0000000000025,16.85628424876117,1.344573261952631,-0.033150169986819744
228.10000000000252,16.890381754509814,1.3848842805211923,-0.03554380079500685
229.20000000000255,16.923734618174752,1.4327523576124865,-0.0368978068951753
230.30000000000254,16.958616552042663,1.4856473354332185,-0.03853499214711409
231.40000000000256,16.99196892139519,1.5389296994426975,-0.04017040879638101
232.5000000000026,17.02642831943736,1.5970752035661773,-0.04244967330908844
233.60000000000258,17.06128815937202,1.6602670715299952,-0.04542265464332429
234.7000000000026,17.095564042992734,1.718446403038377,-0.048030535464061774
235.80000000000263,17.130293796500002,1.7816482183224236,-0.051169771424661725
236.90000000000265,17.164153861360216,1.8413395253175429,-0.054282099563136565
238.00000000000267,17.19837432312091,1.9004994720304993,-0.057550422756277975
239.10000000000267,17.232831755918035,1.9565496680108705,-0.0600539167743559
240.2000000000027,17.266753598733757,2.0090861200039805,-0.0629659813107386
241.3000000000027,17.30077986063584,2.0562608375598357,-0.06642377545233602
242.4000000000027,17.33514154624407,2.102605726206023,-0.07118606383052484
243.50000000000273,17.369137963447606,2.1386686537599915,-0.0742165918849409
244.60000000000275,17.40287405549992,2.173549983457909,-0.07890598704479723
245.70000000000277,17.436628719142572,2.197998308731568,-0.08342269093293053
246.8000000000028,17.470550370448844,2.220072700649709,-0.09048467812137684
247.9000000000028,17.504060136471242,2.238111516874035,-0.09495239196817984
249.0000000000028,17.53772510875451,2.2519589861418745,-0.09983983568785515
250.10000000000284,17.571580193141973,2.2623035814146077,-0.1068491333773105
251.20000000000283,17.604949162907765,2.2670537067217134,-0.11329481187672297
252.30000000000285,17.63806071666068,2.2731064995080352,-0.11933301379980055
253.40000000000288,17.671335456064135,2.275578745096255,-0.1258100542720877
254.5000000000029,17.705211108242693,2.2767486755618926,-0.13397265145667925
255.60000000000292,17.738502348048137,2.2807834772485513,-0.14241231268084853
256.7000000000029,17.771784965175605,2.283090415497863,-0.15027377257163232
257.8000000000029,17.805332704590043,2.286679223261213,-0.158338823374657
258.90000000000293,17.838209444662787,2.2907808110551136,-0.16718900770567702
260.00000000000296,17.871764419725604,2.293730003241377,-0.17591083132083174
261.100000000003,17.9044224262236,2.299292894578682,-0.18499109291970095
262.200000000003,17.93848118361175,2.3039834823362413,-0.1953976409340754
263.300000000003,17.971844639486825,2.3122079688031922,-0.2062498303701905
264.40000000000305,18.00570894573791,2.3223529620571237,-0.21677517738536478
265.50000000000307,18.039349591430252,2.3312569048513265,-0.22831219329175445
266.6000000000031,18.072711256173516,2.3387612659250925,-0.24031277022958442
267.7000000000031,18.10563417383745,2.346363332358884,-0.2529872480491422
268.8000000000031,18.13942044618179,2.3558561934098856,-0.2661099800051936
269.9000000000031,18.1730313851304,2.362769063938823,-0.2798994148849032
271.0000000000031,18.20634403441247,2.3684801958546635,-0.2929617666645692
272.10000000000315,18.23976541399963,2.377978413665609,-0.3066627260669943
273.2000000000032,18.273193736237857,2.38008942288775,-0.3199760552597417
274.30000000000314,18.30647675813109,2.3822484770970016,-0.33573196185871534
275.40000000000316,18.33979531106909,2.384575429919975,-0.3514494525440024
276.5000000000032,18.372957872337587,2.3825146021563492,-0.36911861512169875
277.6000000000032,18.406922768044886,2.3784503684955456,-0.3860083696277328
278.70000000000323,18.439998471018335,2.3720977192720043,-0.4034537811013883
279.80000000000325,18.47316286790003,2.365007109705541,-0.4209186158866163
280.9000000000033,18.50657887849391,2.3524859450154776,-0.43935715912066886
282.0000000000033,18.539408210365675,2.3395451584858815,-0.4579330471683756
283.1000000000033,18.57268159477871,2.321760246983401,-0.47639686389168157
284.20000000000334,18.605576787480405,2.3040309328601474,-0.49487163065346307
285.30000000000337,18.638528484830957,2.27977581111415,-0.5134040479420983
286.40000000000333,18.671687598571854,2.2517069268423517,-0.5336493040889825
287.50000000000335,18.70498683619717,2.222052715023581,-0.5553383682301356
288.6000000000034,18.73792059204229,2.18974446514237,-0.5764231437446456
289.7000000000034,18.77089807889385,2.1551029272681386,-0.5958720159483879
290.8000000000034,18.803589940407914,2.1154988303266062,-0.6161889156683387
291.9000000000034,18.836268773962274,2.076043890259795,-0.637511726880958
293.0000000000034,18.869375210688553,2.0307271004138108,-0.6586653531094817
294.10000000000343,18.901657391368044,1.987905116417091,-0.6784413372424094
295.20000000000346,18.934052196324835,1.9403202014312304,-0.698632222149469
296.3000000000035,18.967192274108168,1.8924541509112667,-0.7191480003260087
297.4000000000035,18.999765266934823,1.8434844272496214,-0.7393249903136581
298.5000000000035,19.031887856155016,1.7977962560571796,-0.7585149630222179
299.60000000000355,19.065585009969837,1.7477615637533055,-0.7785532329329543
300.70000000000357,19.09793236608562,1.705124931214577,-0.7978173513322444
301.8000000000036,19.130213761152465,1.6607531251977439,-0.8147240287196662
302.9000000000036,19.163216456261747,1.6196945467951496,-0.831713191801962
304.0000000000036,19.195967736812126,1.5841168656070073,-0.848375656581783
305.1000000000036,19.229503582944865,1.5513462338716308,-0.8650112447456815
306.2000000000036,19.262285905309785,1.5227936092093275,-0.8809537494609652
307.30000000000365,19.29550176094989,1.4980802166950473,-0.8954261253223423
308.4000000000037,19.3288622421589,1.477249680677495,-0.9096187936313842
309.5000000000037,19.36178564117208,1.46372556267555,-0.923800060111374
310.60000000000366,19.395092713719116,1.4522559957584333,-0.9371404306593338
311.7000000000037,19.42824702168701,1.4439053389336758,-0.9495366735126156
312.8000000000037,19.461628074129063,1.4402926470119843,-0.9612884950149199
313.90000000000373,19.495225068702595,1.4375015833281737,-0.9729931206865614
315.00000000000375,19.528404332365255,1.4424445702517288,-0.9839105283489196
316.1000000000038,19.562275905160188,1.4479209612485509,-0.9950371239950195
317.2000000000038,19.595636043881306,1.4550391474918203,-1.0068308269681792
318.3000000000038,19.629109904292388,1.4661231792711173,-1.0166998565142342
319.40000000000384,19.662834977453727,1.4753973522420678,-1.027542540367854
320.5000000000038,19.696370563181944,1.4869946629366193,-1.0374036171152046
321.60000000000383,19.729965402517177,1.4993107836184416,-1.0462049909672202
322.70000000000385,19.763576255183015,1.510914817321892,-1.056183294736468
323.8000000000039,19.79685884508764,1.52533865770892,-1.0651506190152613
324.9000000000039,19.830834723411826,1.5383838431195103,-1.0748442694555362
326.0000000000039,19.864893770037632,1.5491338983758738,-1.0843356673189537
327.10000000000394,19.89828365026513,1.5646144491869045,-1.0936200363044324
328.2000000000039,19.932220766989083,1.5750407827121953,-1.1035098036252875
329.30000000000393,19.965727324215468,1.5845740025205852,-1.1122727655527918
330.40000000000396,19.99958831640235,1.592212805509318,-1.1212031506117666
331.500000000004,20.033351343844245,1.6011017333641744,-1.1289478173969334
332.600000000004,20.067193506854576,1.6068361229073618,-1.1394275643689626
333.700000000004,20.10091661382669,1.6132426283006767,-1.1494932130247144
334.80000000000405,20.13455933978464,1.6175780294883366,-1.1593358020338314
335.90000000000407,20.16811391592843,1.6166157032960609,-1.1684346416251032
337.0000000000041,20.202181625101737,1.6204056886899463,-1.1782159703503106
338.10000000000406,20.235822972438843,1.6159088095115621,-1.1885093015318318
339.2000000000041,20.269468742021925,1.6095709036380048,-1.1984743848138062
340.3000000000041,20.303414160795025,1.6032798894471543,-1.2090765481806156
341.4000000000041,20.3367203077949,1.5971369563062996,-1.2195018451511541
342.50000000000415,20.370504034183814,1.582974878981685,-1.2291846539434372
343.6000000000042,20.404025159028784,1.5699254712668196,-1.2392431467997032
344.7000000000042,20.437643913286696,1.5562024728585384,-1.2490297726800534
345.80000000000416,20.4713805427106,1.5420440073297201,-1.2586159124885046
346.9000000000042,20.504739690912658,1.5240480045464522,-1.2692939585003566
348.0000000000042,20.538288161496645,1.4999151688770145,-1.2785134738505701
349.10000000000423,20.571624619483604,1.4731884943035602,-1.2875705534518063
350.20000000000425,20.605467329533525,1.4420568115533976,-1.2976211429730315
351.3000000000043,20.63832149627165,1.412723198297701,-1.3070618430487952
352.4000000000043,20.672070786317146,1.3806735065319542,-1.3163728674923019
353.5000000000043,20.70563619905825,1.3489572662569829,-1.3263689557480154
354.60000000000434,20.73901966244113,1.3146234468822833,-1.3362428267975233
355.7000000000043,20.772497781383787,1.2837194791630169,-1.3467706204103718
356.80000000000433,20.806233701110674,1.2541742987336402,-1.3556268990516687
357.90000000000435,20.83947567151328,1.2241092352535399,-1.3647001425159058
359.0000000000044,20.873144707109322,1.197517540689747,-1.3746737710187338
360.1000000000044,20.90676609534556,1.1682070490458036,-1.3845297332557154
361.2000000000044,20.94010145277495,1.1460053951040756,-1.395526105151824
362.30000000000445,20.974030506835035,1.1191633432704522,-1.404964753696417
363.4000000000044,21.007431505586922,1.098280148808457,-1.4132917503309863
364.50000000000443,21.041340070098205,1.072674686330479,-1.4217892878676714
365.60000000000446,21.07508126654426,1.049698472436687,-1.430698496901695
366.7000000000045,21.108643092139456,1.0246862810689688,-1.4409921465483175
367.8000000000045,21.142434311191945,1.0039605758227288,-1.451883700256599
368.9000000000045,21.176267173682312,0.9801004189715723,-1.4612177854006063
370.00000000000455,21.209848031400664,0.9565604192455611,-1.4697883956243172
371.10000000000457,21.243340206024588,0.9335874718994364,-1.4784655477955333
372.2000000000046,21.27730555742422,0.907149017891323,-1.4884330896733364
373.30000000000456,21.311106855321622,0.883273475261997,-1.4978434044088198
374.4000000000046,21.344778195636717,0.8568408518408452,-1.5064048415875324
375.5000000000046,21.378860192633805,0.8298122787467107,-1.5155995897608703
376.6000000000046,21.412121566138836,0.8072538360848786,-1.5235808639722
377.70000000000465,21.446254781834728,0.782041185624101,-1.5325830686585142
378.8000000000047,21.479754019867276,0.753079053661905,-1.541150892740926
379.9000000000047,21.51388023629924,0.7300304198857814,-1.5498007468766333
381.00000000000466,21.547440044587603,0.7028112097255698,-1.5582628336365203
382.1000000000047,21.581522189193926,0.6764601834662882,-1.5672293211397288
383.2000000000047,21.615475097747105,0.6519097084590284,-1.574692865281512
384.30000000000473,21.648863196182496,0.6287962419796157,-1.5820120539514173
385.40000000000475,21.68294017809074,0.6039233035232384,-1.5899690750718505
386.5000000000048,21.717091631220796,0.5819062314755655,-1.5967818445101685
387.6000000000048,21.750952106238234,0.5584298194894163,-1.6046601216838612
388.7000000000048,21.784796930763147,0.5382317551260504,-1.6124702235697526
389.80000000000484,21.81877057233085,0.5184017486139445,-1.618655385546003
390.9000000000048,21.85283473127064,0.49620298800131424,-1.6264646990132823
392.00000000000483,21.8869088244714,0.4759797041508549,-1.633570539594456
393.10000000000485,21.921016705239655,0.45757872036903563,-1.6395008848991988
394.2000000000049,21.954938061830475,0.44135546039048523,-1.6461040782998952
395.3000000000049,21.988982366869294,0.42377962821673876,-1.6528860789640731
396.4000000000049,22.023150768423783,0.4076663520499004,-1.6591788516587456
397.50000000000495,22.057253023864217,0.3884553961361596,-1.6655080895240109
398.6000000000049,22.091544545424657,0.3715333556637155,-1.6713426102971671
399.70000000000493,22.125026339170507,0.35615191403745095,-1.6785699692473464
400.80000000000496,22.159486054390975,0.3436568796120341,-1.6855514530378648
401.900000000005,22.193434848159885,0.3277473264282507,-1.6911059789369745
403.000000000005,22.227754766708266,0.3124738462706169,-1.6988699791092303
404.100000000005,22.261921197816267,0.2996499991358338,-1.7055584780198365
405.20000000000505,22.2963664916621,0.2840594713605287,-1.7115911766287
406.30000000000507,22.330311936856145,0.2762418988989674,-1.7185595100962523
407.4000000000051,22.364751195375323,0.2652095571119174,-1.7251765758608895
408.50000000000506,22.3993934078967,0.25287863532741495,-1.732226136278289
409.6000000000051,22.43350412414134,0.24268516030061404,-1.7394474860592193
410.7000000000051,22.467273961736115,0.23616433684668822,-1.7463983291498826
411.8000000000051,22.50237653531827,0.22971081698754692,-1.75338418088679
412.90000000000515,22.537002904882012,0.22416996323895078,-1.7608558230586087
414.0000000000052,22.57183066640363,0.2223667830698035,-1.768647656424625
415.1000000000052,22.606459819911446,0.2211329813246145,-1.7763732957638156
416.20000000000516,22.640871528714516,0.21923465196932812,-1.782939034846557
417.3000000000052,22.675412066349942,0.22127793150666647,-1.79031898387088
418.4000000000052,22.7100810498131,0.2249727540317239,-1.7967328170258794
419.50000000000523,22.74489300498394,0.2267188424368604,-1.8040719586242675
420.60000000000525,22.779426635230582,0.23256608690397174,-1.8121341133440638
421.7000000000053,22.81423559906644,0.2428384302303248,-1.8199964937530129
422.8000000000053,22.848888737635676,0.25232473984497145,-1.8275035901909091
423.9000000000053,22.884256211882704,0.26306278911360914,-1.8345271071451
425.00000000000534,22.919014395752235,0.27026842145686475,-1.8422451834334832
426.1000000000053,22.95341314754221,0.2868889486691952,-1.8496007012944085
427.20000000000533,22.988756343199704,0.2998712871836543,-1.8575746497294205
428.30000000000535,23.02351769110528,0.3115372060017548,-1.865339394747905
429.4000000000054,23.058275836766665,0.3231101812877388,-1.8721383638569153
430.5000000000054,23.09312780097762,0.33782939903775,-1.8801092108174728
431.6000000000054,23.12837544436973,0.3509204438252856,-1.8881203317915172
432.70000000000545,23.163282709205703,0.36483627491794274,-1.8955144774740762
433.8000000000054,23.197940573858684,0.38209323564080994,-1.903884091339528
434.90000000000543,23.23322375908046,0.39355557120487655,-1.9105236782912653
436.00000000000546,23.268253926965475,0.40380116075621786,-1.9178910121738775
437.1000000000055,23.303211723777338,0.4183201906150892,-1.9259200440982487
438.2000000000055,23.33828846504686,0.42976343711552395,-1.9332118158951648
439.3000000000055,23.373012610955488,0.43906866130169775,-1.9406666031778665
440.40000000000555,23.40818768165237,0.4489535488708172,-1.9480445115726548
441.50000000000557,23.443212107994352,0.45992673399681666,-1.9561928508757385
442.6000000000056,23.478369561799987,0.4687154142823564,-1.9651075217673588
443.70000000000556,23.51343352538013,0.475545180472323,-1.9727776156237185
444.8000000000056,23.548439701885634,0.4853792630591621,-1.9784759626589543
445.9000000000056,23.5833500937387,0.4917084411875918,-1.9859352472234044
447.0000000000056,23.618336030757334,0.4962352862185885,-1.9931047583906105
448.10000000000565,23.653437818381825,0.503856258073557,-2.000982431366932
449.2000000000057,23.68869150982817,0.5075286281141387,-2.0084040258002913
450.3000000000057,23.723790211466007,0.513280314284146,-2.0160867524016775
451.40000000000566,23.758849143483694,0.5171815187850501,-2.0241299105736332
452.5000000000057,23.793602581647818,0.5198902500141329,-2.0314473859608784
453.6000000000057,23.82889309426253,0.5243361760534733,-2.0390747411813583
454.70000000000573,23.863935297242758,0.5283487709708075,-2.044920774681647
455.80000000000575,23.898911225314905,0.530153593110394,-2.0524507974657276
456.9000000000058,23.933883300389063,0.5313944619393521,-2.059916849562037
458.0000000000058,23.96891441102281,0.5337098104756832,-2.0677492696721176
459.1000000000058,24.004425225187735,0.5375721355188895,-2.0760908669654645
460.20000000000584,24.039611260629474,0.5342969706143915,-2.0832263533415354
461.3000000000058,24.07439196800973,0.5377640601052569,-2.0906209200239303
462.40000000000583,24.10958275793294,0.538573625283872,-2.100026001079078
463.50000000000585,24.144741923640613,0.5379154120289367,-2.1063362576545064
464.6000000000059,24.179547881049956,0.5376353981989588,-2.114570373228805
465.7000000000059,24.214884962233658,0.5390807876164839,-2.1222587696132624
466.8000000000059,24.25024160537042,0.5412116285562878,-2.1285588111624945
467.90000000000595,24.28534323085031,0.5401660889573769,-2.1366195673183688
469.0000000000059,24.320525508526504,0.5414431145876643,-2.143496097003492
470.10000000000593,24.355480638507256,0.5419889402928625,-2.1514057983053947
471.20000000000596,24.390817312389977,0.5389924070449273,-2.1592455650945204
472.300000000006,24.4261064003738,0.5401311328548654,-2.165451908056025
473.400000000006,24.461173335291456,0.5383042699312719,-2.1732041122749797
474.500000000006,24.496418936041547,0.5368907996514389,-2.1796358267797813
475.60000000000605,24.530667277466677,0.5353929557276853,-2.186794907965565
476.70000000000607,24.56659792773481,0.5399778286615472,-2.193694672720083
477.8000000000061,24.601842029715637,0.5370831718203646,-2.2003323547324563
478.90000000000606,24.636706578304867,0.5328168834973015,-2.206973536445831
480.0000000000061,24.672168688357043,0.532342150060693,-2.2138297163252862
481.1000000000061,24.707329350133254,0.533504100072904,-2.2214075280531476
482.2000000000061,24.742644191433257,0.5308889864151087,-2.227614183595823
483.30000000000615,24.777563300665733,0.5288836008435404,-2.2341727257417316
484.4000000000062,24.812873463522603,0.526983962151113,-2.240798633219975
485.5000000000062,24.848600864795756,0.524711392528331,-2.247505969412907
486.60000000000616,24.883790286031726,0.5250073985369532,-2.2534893474188076
487.7000000000062,24.918758719915623,0.5203067131308667,-2.260480280433184
488.8000000000062,24.954167476182793,0.5214223938178181,-2.266308488560484
489.90000000000623,24.989137334308197,0.5182841335351659,-2.273171856083037
491.00000000000625,25.024230976447647,0.515213499720796,-2.280229190093837
492.1000000000063,25.059745909597314,0.5140870103250436,-2.2865618492098747
493.2000000000063,25.09511173929897,0.5127556973995946,-2.295488514055058
494.3000000000063,25.13015547736717,0.5095648017566319,-2.301410223967525
495.40000000000634,25.165660170671845,0.5069680042114053,-2.3088650860148205
496.5000000000063,25.200790979832902,0.5041505780944313,-2.3151353081218424
497.60000000000633,25.236335006209487,0.5018071346629568,-2.3212069121537984
498.70000000000636,25.270952133142984,0.49777654314278064,-2.3273179810956934
499.8000000000064,25.306395989777048,0.4973835027655924,-2.333812887058003
500.9000000000064,25.341905063545404,0.49384230558787456,-2.340597392446744
502.0000000000064,25.376877813205745,0.4908154464865563,-2.3487251601892334
503.10000000000645,25.412039119642216,0.48960262517256725,-2.3557020511275977
504.2000000000064,25.44761808695941,0.48508109526265497,-2.3631778832485355
505.30000000000643,25.48299635597338,0.4837712326779745,-2.36966009046363
506.40000000000646,25.518155185939097,0.4795148181638603,-2.3759813168588684
507.5000000000065,25.553884593496097,0.47435557598018907,-2.384081909537917
508.6000000000065,25.589106417262006,0.47126895553022496,-2.39062564681562
509.7000000000065,25.624314308390147,0.46995257320012807,-2.3979663938269704
510.80000000000655,25.659878848145052,0.46495871694596147,-2.404553042185482
511.90000000000657,25.695071785892836,0.463723640514609,-2.411283033008324
513.0000000000066,25.730247242636228,0.4594264158269672,-2.4178327089833793
514.1000000000065,25.766094958358774,0.4574334788170229,-2.4245664485112446
515.2000000000066,25.801520704464487,0.45218640400296517,-2.4330375912146116
516.3000000000065,25.83630166703248,0.4528345921953567,-2.4386811794898247
517.4000000000067,25.87177476813793,0.44874001839916433,-2.445875607997972
518.5000000000066,25.9078819899597,0.44313670417016016,-2.452857507169771
519.6000000000067,25.943327499090195,0.44290019952409776,-2.4600537658819235
520.7000000000066,25.97863268142577,0.4383916057172417,-2.4677385592806953
521.8000000000067,26.01478151301281,0.43824134616728816,-2.474815974957542
522.9000000000067,26.05013688886596,0.438297947954552,-2.4822786855912327
524.0000000000067,26.085790480042828,0.43115709491175946,-2.488412774444385
525.1000000000067,26.12125818017088,0.4318784603128101,-2.4956839056156213
526.2000000000068,26.156802849973577,0.42809378725910174,-2.5034652653586384
527.3000000000068,26.1923661025549,0.4284993847667772,-2.5097758392724905
528.4000000000068,26.22788088454621,0.42478179123777315,-2.5169950578832765
529.5000000000068,26.263224943120054,0.42417704359522956,-2.5240885289083543
530.6000000000068,26.299010228099277,0.4212265877417737,-2.531579181264795
531.7000000000069,26.334519795806134,0.4163238465323059,-2.537682867108362
532.8000000000068,26.370126731003126,0.4157713242890274,-2.5445888488831283
533.9000000000069,26.405801857818606,0.413626474417196,-2.551875724881855
535.0000000000068,26.441227611565754,0.4130415248507704,-2.557817869958247
536.100000000007,26.477037989073928,0.4086883004951223,-2.564858260162913
537.2000000000069,26.5125607904028,0.4068214585366048,-2.570366110450947
538.300000000007,26.548258112787583,0.4029917930086885,-2.5778419973063484
539.4000000000069,26.583792210524948,0.4044810850142534,-2.5836940533497925
540.5000000000069,26.619740019952395,0.40148250686832865,-2.5897960934723465
541.600000000007,26.655213863711175,0.39957072610737365,-2.59584779302375
542.700000000007,26.6905246592634,0.3984266596530843,-2.6010880359655157
543.800000000007,26.72695227947631,0.3973934100647665,-2.607845054998471
544.900000000007,26.762352761411403,0.39385700078098806,-2.6132791297523306
546.000000000007,26.798165965636574,0.3901245900740654,-2.6193641783997945
547.1000000000071,26.83418299251725,0.3941489130537691,-2.624741424920108
548.2000000000071,26.86983354639826,0.39147806725287193,-2.6308875350713863
549.300000000007,26.9056191939977,0.3908555804018523,-2.636721415214553
550.4000000000071,26.94133664738637,0.38849728873931266,-2.6411239431884175
551.500000000007,26.97725351149672,0.38724198358665685,-2.6462957931230227
552.6000000000072,27.012787744652538,0.3838098276369517,-2.6518038587191826
553.7000000000071,27.048635272633568,0.3833819469260642,-2.6573374072977547
554.8000000000072,27.084464705041825,0.3829692151235661,-2.6627301244039754
555.9000000000071,27.120544913305928,0.38167739412918056,-2.6680695280407845
557.0000000000072,27.156235193163866,0.3780165795715309,-2.6733719184554166
558.1000000000072,27.192177515855004,0.3776088250905304,-2.6777576921545245
559.2000000000072,27.228036267746823,0.37296109918252374,-2.6819113189730652
560.3000000000072,27.263513596038415,0.37222670494752785,-2.686013610003343
561.4000000000073,27.299642892199113,0.3705029726238305,-2.6900012833285545
562.5000000000073,27.335658279837485,0.3680496384893367,-2.69297936205244
563.6000000000073,27.371455450190993,0.36543480520637517,-2.6974694021454413
564.7000000000073,27.407332233965,0.363933113505867,-2.702723082517195
565.8000000000073,27.443190437085715,0.36184416170004563,-2.7074714302456653
566.9000000000074,27.479267018713724,0.35785291965139954,-2.7106021110125273
568.0000000000074,27.515162778153552,0.35683864862660775,-2.713518531368023
569.1000000000074,27.550969088518258,0.3497841912077033,-2.7171527662967607
570.2000000000073,27.586813052319027,0.34728438368652625,-2.7216331604473964
571.3000000000073,27.622817948509624,0.34759153970603496,-2.726378312545732
572.4000000000074,27.658866191118047,0.34269832195630934,-2.730824120936373
573.5000000000074,27.69446877520376,0.34226834565874853,-2.734805087400349
574.6000000000074,27.73073570512995,0.338311248639652,-2.7381946411200535
575.7000000000074,27.766527533653207,0.3361792018473826,-2.7403773535294347
576.8000000000075,27.801840411454283,0.33202592782550155,-2.743930173165407
577.9000000000075,27.838470094702704,0.3314427889516105,-2.747562053372837
579.0000000000075,27.874543049039367,0.33284486284476933,-2.751338259782952
580.1000000000075,27.91079574603771,0.32777549980523313,-2.7548744787602963
581.2000000000075,27.946842201513576,0.32600568601180435,-2.7580365543566723
582.3000000000076,27.982553475807048,0.3253480092008034,-2.761318773552908
583.4000000000076,28.018844991977986,0.3212274632065011,-2.7653751550801933
584.5000000000076,28.05473898836255,0.3181159202589725,-2.767632574803691
585.6000000000076,28.090717026738805,0.3156884106097886,-2.7713762837363483
586.7000000000077,28.126893278856063,0.31329147770920285,-2.7749250300146215
587.8000000000077,28.163002773784584,0.30998180368230477,-2.7775835246266167
588.9000000000076,28.19849650742747,0.3096694441066239,-2.77925337945678
590.0000000000076,28.235045871340354,0.3075649433083365,-2.7815201365043665
591.1000000000076,28.2710895604656,0.3050239725531161,-2.783186240249183
592.2000000000077,28.307199679516554,0.30462904178897854,-2.786539620587198
593.3000000000077,28.343583719233813,0.3045116317181755,-2.7897990270229767
594.4000000000077,28.37982708827423,0.3028517948485001,-2.7930606908532662
595.5000000000077,28.41573188756773,0.30085435780097014,-2.7957356942803044
596.6000000000078,28.45182997398676,0.29939071244296556,-2.798444858476543
597.7000000000078,28.487338088250908,0.2999186370570086,-2.8006766130710545
598.8000000000078,28.524061947963062,0.29883994814392234,-2.802345298057964
599.9000000000078,28.560167185176443,0.2981878091627921,-2.804350629622922
601.0000000000078,28.596870638993977,0.29800010512486597,-2.806341379246199
602.1000000000079,28.63278117868334,0.2985841694067546,-2.8089378309871114
603.2000000000079,28.668870872866833,0.2989396125936554,-2.811197069094057
604.3000000000079,28.705100861934625,0.2993002920846295,-2.8145545687969573
605.4000000000078,28.741361719124235,0.2989449384985756,-2.8161361215952696
606.5000000000078,28.77744905858359,0.2990543099933325,-2.8178990167025053
607.6000000000079,28.81386640803764,0.3006629501828373,-2.8193823745310613
608.7000000000079,28.850131147635555,0.29725517383994937,-2.8208761981223276
609.8000000000079,28.88625590855253,0.29969888989161664,-2.823234284842737
610.9000000000079,28.922365405259168,0.29962148775403463,-2.8254589869588633
612.000000000008,28.9584949381128,0.2974090511161147,-2.828753037677103
613.100000000008,28.99472988283001,0.30149949238356966,-2.8302809657877024
614.200000000008,29.03060261602682,0.30234638584548135,-2.831764627470517
615.300000000008,29.06727356313389,0.30388581443455065,-2.8334433022573693
616.400000000008,29.103743372863256,0.3052548356462681,-2.834786199361976
617.5000000000081,29.140104633262037,0.3056846564509148,-2.8361438723982406
618.6000000000081,29.17590307076273,0.30589877647962416,-2.8380280175346337
619.7000000000081,29.212152917455303,0.3095229278198468,-2.8389256929271394
620.8000000000081,29.24873920487483,0.3097719183124481,-2.8400646889321344
621.9000000000082,29.285093308656275,0.30952689918860377,-2.841769419379153
623.0000000000082,29.32131319714448,0.31235163631623064,-2.8433116591678855
624.1000000000081,29.357753902967247,0.3169618082804033,-2.8444358446508735
625.2000000000081,29.39390027862253,0.31882935715893446,-2.8466190582586606
626.3000000000081,29.430034526761865,0.32037756952224705,-2.8480925766371263
627.4000000000082,29.46654284427885,0.3216873730897061,-2.849657063855328
628.5000000000082,29.50239837760181,0.3238092232955896,-2.849848814045024
629.6000000000082,29.539036698078327,0.327436321217341,-2.8505197065496595
630.7000000000082,29.57562563974971,0.3322863081515113,-2.8521603690776907
631.8000000000083,29.611611396493842,0.3328166922279516,-2.85355737208056
632.9000000000083,29.648012674153176,0.33829371753969295,-2.855016724698355
634.0000000000083,29.684388145511186,0.33765630002861946,-2.8564319520532004
635.1000000000083,29.720774145187878,0.33888789507118533,-2.85683374065773
636.2000000000083,29.75710410503453,0.3427888809029176,-2.8576952135935265
637.3000000000084,29.79354232234847,0.34294893249459624,-2.859100711395857
638.4000000000084,29.829702536775095,0.34439447074564944,-2.8604243402345726
639.5000000000084,29.866293357349846,0.3475453783453262,-2.8605733295286875
640.6000000000083,29.902701857140652,0.3493586879479553,-2.860412045135306
641.7000000000083,29.93896723270208,0.35026852809707787,-2.861053372292802
642.8000000000084,29.975167720910434,0.35666055679469233,-2.8623129721027474
643.9000000000084,30.011688850663656,0.3574887988735689,-2.863159427105831
645.0000000000084,30.048329789797425,0.36287173779807036,-2.864364831843954
646.1000000000084,30.084725891885043,0.36228218624355923,-2.865622843464099
647.2000000000085,30.120995290686324,0.3652005136570382,-2.8665036946501155
648.3000000000085,30.15728971560502,0.36962697222075724,-2.8679239343423535
649.4000000000085,30.19386598092955,0.36823799992726625,-2.868345506040707
650.5000000000085,30.23019019336799,0.37368736340974706,-2.869738933718506
651.6000000000085,30.266803556291215,0.3786726427825733,-2.869737047119812
652.7000000000086,30.30329427505131,0.37706095465128975,-2.87077359046899
653.8000000000086,30.339664658498958,0.37929676402504775,-2.872516076653354
654.9000000000086,30.375873969662354,0.3833474276290203,-2.8724391666163873
656.0000000000086,30.412433217906344,0.38795633502039073,-2.8738134618483
657.1000000000087,30.44884394827284,0.38938760241031756,-2.875118769295079
658.2000000000087,30.485530005642463,0.39146241637918067,-2.8751480417843798
659.3000000000086,30.52167091425677,0.3932698840105977,-2.876089089417389
660.4000000000086,30.55812298211421,0.3960735386152927,-2.8765021219198963
661.5000000000086,30.594907012182425,0.39607126294816153,-2.8754470978379065
662.6000000000087,30.631389760430263,0.39804592127906346,-2.876421176198452
663.7000000000087,30.667490322953224,0.4016521046115016,-2.8777726348018273
664.8000000000087,30.70411494347473,0.40341854099945706,-2.879003129371608
665.9000000000087,30.740643143462115,0.40660534369383594,-2.8790772776484848
667.0000000000088,30.77720237294038,0.4108000087506809,-2.8803789021479145
668.1000000000088,30.813571781370847,0.4131115702770305,-2.8804403234732945
669.2000000000088,30.850214257887473,0.41367648104020227,-2.881713407594468
670.3000000000088,30.886455616822232,0.4185037401288365,-2.881723405855682
671.4000000000088,30.92314779919219,0.42207272287313025,-2.883081262275477
672.5000000000089,30.95977498555321,0.42182882756155626,-2.8830502739961403
673.6000000000089,30.996065863377392,0.4264512597629584,-2.884331265243722
674.7000000000089,31.032372083652678,0.4304992284634348,-2.8849898033462855
675.8000000000088,31.069135214182786,0.43221433786515795,-2.884356239299361
676.9000000000088,31.105564171823804,0.43300151739519,-2.884962356454144
678.0000000000089,31.142364436332304,0.431610469061106,-2.885666484008343
679.1000000000089,31.17883624325038,0.4319244650756824,-2.8869654476811304
680.2000000000089,31.214931520813625,0.4309423030822257,-2.8875265533325027
681.3000000000089,31.250958110518336,0.43466247994542995,-2.8882991164910923
682.400000000009,31.288095500281948,0.43735976715324165,-2.888860592871196
683.500000000009,31.324699909616356,0.4350244849749909,-2.8896095334070253
684.600000000009,31.361120594628073,0.43473516221754416,-2.890434309952269
685.700000000009,31.39746360522045,0.43912188108253525,-2.8909318730804827
686.800000000009,31.43418481321135,0.44326716492703744,-2.891194145575977
687.9000000000091,31.470751788445668,0.44638917188371363,-2.8922527997138716
689.0000000000091,31.50724314126262,0.447185186891879,-2.8922427460243103
690.1000000000091,31.543843746150625,0.44989210712426475,-2.893561410830376
691.2000000000091,31.580343554447374,0.4481750427023059,-2.895118467268629
692.3000000000092,31.616169129439744,0.44973768923332336,-2.8944527519098524
693.4000000000092,31.652835005969752,0.45241182187239404,-2.8940803448937267
694.5000000000091,31.689103575283657,0.4533537819483935,-2.893780450502458
695.6000000000091,31.726406960625834,0.4521744736607518,-2.8949803297030625
696.7000000000091,31.762890345347824,0.4553227379966105,-2.8952829544768433
697.8000000000092,31.799735834605944,0.45893499247627156,-2.896411088996289
698.9000000000092,31.836186098352965,0.45684273010573784,-2.896411727105643
700.0000000000092,31.872620385217537,0.4608073893897413,-2.8966991984039936
701.1000000000092,31.909170655896997,0.4596068550164607,-2.8977297694521846
702.2000000000093,31.946082126563482,0.45963711407792784,-2.8979048587954095
703.3000000000093,31.98281781227513,0.4568299135499636,-2.8977590860564013
704.4000000000093,32.019472506341366,0.45961955337564997,-2.897737763748249
705.5000000000093,32.056050697750706,0.4606433574144535,-2.899100993984238
706.6000000000093,32.09262987854343,0.4621525120415866,-2.9004821494267503
707.7000000000094,32.12916965960668,0.4642506789992087,-2.9017299423353293
708.8000000000094,32.165375422357656,0.4642045244960771,-2.9016703617188058
709.9000000000094,32.20261616149054,0.4645644310713053,-2.9029816551743894
711.0000000000093,32.23952910720936,0.4725394518765633,-2.9041207735541192
712.1000000000093,32.275860771176426,0.4667237510330613,-2.9030092412172848
713.2000000000094,32.312759649336975,0.47081485880302076,-2.9029743227898557
714.3000000000094,32.34936335844059,0.4667541311627059,-2.904328425876218
715.4000000000094,32.38582672260586,0.46249031326618795,-2.9049796607593033
716.5000000000094,32.42275757259496,0.4619766464001387,-2.9043347501151917
717.6000000000095,32.45967211847735,0.459766547305124,-2.9056419257565205
718.7000000000095,32.496297376880364,0.4593796623682662,-2.905635203631892
719.8000000000095,32.532951523213086,0.4554194410957453,-2.9073657829810076
720.9000000000095,32.56937094986524,0.45286116497397577,-2.9074118304085363
722.0000000000095,32.60686448573026,0.4513533756262844,-2.9087192076730926
723.1000000000096,32.64334890088114,0.44908168512702584,-2.9087196173272205
724.2000000000096,32.68001275356842,0.44597525451340436,-2.9091178769787955
725.3000000000096,32.71692994297317,0.44499012456419473,-2.908749215384171
726.4000000000096,32.753517342140796,0.4452180122845175,-2.91005524542832
727.5000000000097,32.79014746151549,0.44251000484222613,-2.911530601125144
728.6000000000097,32.827213748045345,0.4368528708187389,-2.9121793587929043
729.7000000000096,32.86365024070291,0.4329550363874568,-2.913004235679516
730.8000000000096,32.900838905943964,0.4311634884145277,-2.9142877234510847
731.9000000000096,32.93738541857814,0.42642770127862084,-2.915296826177123
733.0000000000097,32.97441333712247,0.42147358618063624,-2.915788720264333
734.1000000000097,33.01099919649983,0.42064730787247084,-2.9166202090315525
735.2000000000097,33.047652578029414,0.41856633763273043,-2.916562199262734
736.3000000000097,33.08444360846832,0.4149870552754944,-2.9169504539239943
737.4000000000098,33.121434040648126,0.4112215769887122,-2.9177945315625413
738.5000000000098,33.157940653345584,0.4074395740584982,-2.9182282948935656
739.6000000000098,33.19522807652589,0.4017364664412333,-2.9195694893578854
740.7000000000098,33.23191200362155,0.39896694673613187,-2.9195759671663772
741.8000000000098,33.26876930492556,0.39718764017540487,-2.9209070164533237
742.9000000000099,33.30545566260236,0.3869435412221627,-2.9222921910078417
743.0000000000098,33.30882840020372,0.38641199714871455,-2.922225431735852