File: 01_Data/PU_Aerogel/STA/N2/3K_min/PU_Aerogel_STA_N2_3KData_231215_R1.csv
##Temp./Â°C,Time/min,DSC/(mW/mg),Mass loss/mg
50.0,10.01917,0.021804675578176447,-0.0037280869518179216
51.100000000000016,11.420248580363598,0.01167950994027489,-0.0030552429012882243
52.20000000000003,11.917557152796121,0.005180147300454685,-0.00462080806084586
53.30000000000005,12.378231037317171,0.0036071463014542005,-0.0029672314192961124
54.40000000000006,12.791286689536864,0.004233994413864739,-0.0051977862109913175
55.50000000000008,13.195515280142592,0.0038471900907706136,-0.0035865583716230276
56.600000000000094,13.597966496052784,0.0008484696996586827,-0.004949243571333639
57.70000000000011,13.982229658159511,0.005400461351837915,-0.004924175429964706
58.800000000000125,14.370631023618131,0.004973800792530181,-0.0035439979795963694
59.90000000000014,14.754023083183965,0.00477910354043809,-0.0030801747347304342
61.000000000000156,15.127362215892738,0.006054529936327935,-0.004828949746729094
62.10000000000017,15.50085508771271,0.004090387441574084,-0.004060424528625539
63.20000000000019,15.871897014353545,0.003236755000004088,-0.005720334476611022
64.30000000000021,16.243541777891362,0.0067576694544908555,-0.006679979647274514
65.40000000000022,16.61844179716392,0.006598059312886928,-0.008327296744253587
66.50000000000023,16.987317299608936,0.00981757760025559,-0.005819372437640524
67.60000000000025,17.353553006542803,0.009922909728970364,-0.005058877250191607
68.70000000000027,17.7169226548563,0.01280031011451932,-0.005049287673755565
69.80000000000028,18.076227414124105,0.012302438420122463,-0.007302002714506983
70.90000000000029,18.45422410438349,0.011496712135468101,-0.006043164631239328
72.00000000000031,18.81836815781918,0.01348233711910174,-0.007634995063741101
73.10000000000034,19.164694639628042,0.013253663042444686,-0.006478845197809946
74.20000000000034,19.55425825707598,0.014546767812484873,-0.0087798860107835
75.30000000000035,19.913462442673517,0.013888989220366188,-0.00812310167235708
76.40000000000038,20.27874828210962,0.01766194929236997,-0.008345872143238786
77.5000000000004,20.636828926057593,0.017526189102261114,-0.009669952850301478
78.6000000000004,21.002820621316452,0.01733782679018203,-0.009332362940674521
79.70000000000041,21.36834621382746,0.018281710242164184,-0.008350060158401895
80.80000000000044,21.70037194272706,0.019347115210626153,-0.007376886985468012
81.90000000000046,22.090167211420518,0.021024046579733113,-0.009339988023360668
83.00000000000047,22.453373432495663,0.01870021640588071,-0.010249837510508009
84.10000000000048,22.8161763995728,0.021879409990585685,-0.008993133431300038
85.2000000000005,23.179170000000333,0.0226391344133261,-0.011559871241540343
86.30000000000052,23.54782619539408,0.023142290959043077,-0.010319883285332843
87.40000000000053,23.912896561524256,0.027225400718530857,-0.011639453076227824
88.50000000000054,24.26961011953288,0.028028326752358446,-0.010330158530204692
89.60000000000056,24.631947284106065,0.028218612771476526,-0.009999911835167019
90.70000000000059,24.993166785097376,0.02982309810934236,-0.011312708493104395
91.8000000000006,25.34589443402194,0.030103880252356774,-0.013242561903422434
92.9000000000006,25.714295037928817,0.030441336842604194,-0.012375255005895092
94.00000000000063,26.075069532412712,0.030390986060796266,-0.010666879238093507
95.10000000000065,26.434976746032138,0.031415910757275345,-0.01116644826870683
96.20000000000066,26.791297864776258,0.03176359553296271,-0.011508352948445655
97.30000000000067,27.15618027069145,0.034110117279767316,-0.011247313346328447
98.40000000000069,27.512579507769008,0.035992305326775664,-0.011310099014473884
99.50000000000071,27.878342886947305,0.03507132277114122,-0.012644878435334128
100.60000000000072,28.233905438333014,0.036867488749440014,-0.011304759222349858
101.70000000000073,28.607388378620094,0.03606129805842562,-0.011079327543899176
102.80000000000075,28.958039248744484,0.038490262442141265,-0.011443650094301816
103.90000000000077,29.31841750789869,0.03908643391147315,-0.013070062337211752
105.00000000000078,29.674213603972728,0.03734986255109396,-0.012379637174981362
106.10000000000079,30.038146591289262,0.03916154894996149,-0.015071044752027696
107.20000000000081,30.397906922792828,0.03940300962457988,-0.012715714173268111
108.30000000000084,30.759914087051474,0.03998739065823598,-0.012419138377709693
109.40000000000084,31.117536690790004,0.04180645755833323,-0.012480204213770385
110.50000000000085,31.47727760855887,0.04413758483106811,-0.013730100065239448
111.60000000000088,31.835208770950345,0.047384853778275726,-0.01373433851446837
112.7000000000009,32.19238686554105,0.04739886674145577,-0.013364198138665628
113.8000000000009,32.5605062770374,0.04924438041036172,-0.014719755422039071
114.90000000000092,32.918006734410454,0.04775971603930973,-0.013554749686007561
116.00000000000094,33.27382902258585,0.05090419118171763,-0.014716090678700056
117.10000000000096,33.634927436580256,0.054134188386952165,-0.01406441347671361
118.20000000000097,34.0017575901541,0.05306863241367088,-0.015704455420097574
119.30000000000098,34.34845691217805,0.05197744324333309,-0.015710048279021116
120.400000000001,34.7064795688495,0.05375345963542255,-0.016477884801758158
121.50000000000102,35.068337645946194,0.05401501997254643,-0.016470198006171444
122.60000000000103,35.42449153751461,0.054679870849913215,-0.015206724189277487
123.70000000000104,35.786152153724586,0.05636158924695778,-0.01581235399305747
124.80000000000106,36.14212858765356,0.05599297425239147,-0.01703408828675279
125.90000000000109,36.50505033881392,0.05629860481615312,-0.0164049567181328
127.0000000000011,36.84606202175697,0.05698467252020256,-0.01679569496307831
128.1000000000011,37.21774905966388,0.05603489557212482,-0.016733594096793425
129.20000000000113,37.575274895509665,0.058315080049564205,-0.017016556599205757
130.30000000000115,37.93393153298133,0.05945540176861197,-0.016960148439752132
131.40000000000117,38.28946749527165,0.062391666546380176,-0.01728651318892105
132.50000000000117,38.64985851150184,0.06214116699159966,-0.019406666615363832
133.6000000000012,39.005297682862334,0.06448226226859388,-0.018549283540932215
134.7000000000012,39.360403874875466,0.06607689729514377,-0.020546886503215234
135.8000000000012,39.71917000000037,0.06684834301655762,-0.019219990166310374
136.90000000000123,40.077682412920325,0.06599437069532943,-0.020539457880374368
138.00000000000125,40.43821857181586,0.0652485079810412,-0.021405886716168165
139.10000000000127,40.79680404361109,0.06826966853018535,-0.02008974881134895
140.2000000000013,41.154790552347826,0.0688395450940531,-0.020089869521221715
141.3000000000013,41.513615964893994,0.06902599937690912,-0.021595929101711597
142.4000000000013,41.875129508105296,0.07094088527997178,-0.02450514446014962
143.50000000000134,42.23127376381422,0.07097505840459473,-0.022729937660128652
144.60000000000133,42.58541903721591,0.07251416909224728,-0.02305980972364763
145.70000000000135,42.94027799079937,0.07646310654237665,-0.02571480415385663
146.80000000000138,43.3013212870156,0.07585617984703674,-0.024692864733531827
147.9000000000014,43.659395999792515,0.0776076413427047,-0.025371604987341367
149.00000000000142,44.01312597094499,0.07910435359893953,-0.025359811319140668
150.10000000000142,44.36987319492638,0.07997868523724216,-0.024370082885638578
151.20000000000144,44.72470174385998,0.08153841164003595,-0.02668071794275484
152.30000000000146,45.08285683478678,0.08033212472134199,-0.026350086000380024
153.40000000000146,45.43704848182872,0.08113066742397912,-0.026350084926017203
154.50000000000148,45.793898706741714,0.08172259894739042,-0.026390828397346855
155.6000000000015,46.13842927798062,0.08295646393186118,-0.029716862878359063
156.70000000000152,46.49854047615781,0.08579991822881627,-0.027941315563341007
157.80000000000155,46.857928482923995,0.08870414635419799,-0.029545231979071662
158.90000000000154,47.215378764949264,0.08991886475660182,-0.02865008572260752
160.00000000000156,47.56801957922248,0.08956413607426628,-0.03131259286426902
161.1000000000016,47.92150368362977,0.09032599174226474,-0.03205494181637292
162.20000000000158,48.284551788106334,0.09097071496014664,-0.03161985191831507
163.3000000000016,48.63578484535509,0.09312841976562325,-0.030991888616205276
164.40000000000163,48.989172151486194,0.09158714811531432,-0.03162003212824871
165.50000000000165,49.34658355479866,0.09346957843094117,-0.032940069334436384
166.60000000000167,49.70435667540163,0.09700901257318773,-0.034259768744213215
167.70000000000167,50.060431323282955,0.09755750498979765,-0.03501853303137192
168.8000000000017,50.41917000000057,0.09740367058817911,-0.035349851328836834
169.9000000000017,50.7698772294563,0.0975282522479679,-0.0350765208990893
171.0000000000017,51.12695351717462,0.1002696854723899,-0.035350093066314425
172.10000000000173,51.4830496432195,0.09817902712348081,-0.035019992956838664
173.20000000000175,51.82938344966513,0.10376888648765026,-0.03633980999999942
174.30000000000177,52.1934340809919,0.10275327467875939,-0.037937880494862686
175.4000000000018,52.550936011504795,0.10383554987893406,-0.03831990606700586
176.5000000000018,52.90276772114095,0.10409476123634942,-0.0383198569197849
177.6000000000018,53.25986599741648,0.10589854811699628,-0.03963989401924284
178.70000000000184,53.62253662745194,0.10641753023946166,-0.04029997853258305
179.80000000000183,53.970185494509614,0.10931376350016353,-0.041290062000014505
180.90000000000185,54.3138361400822,0.11040894328964468,-0.04128967933351513
182.00000000000188,54.6772525434282,0.11113133634599293,-0.042521723506442566
183.1000000000019,55.032938434818405,0.10958140323963872,-0.0431568318162463
184.20000000000192,55.38532742719741,0.11039311459866252,-0.042820256403513834
185.30000000000192,55.742688661328444,0.11230678360502777,-0.044138507043529174
186.40000000000194,56.101037579374236,0.11248678941790091,-0.04676942625205571
187.50000000000196,56.45556914539496,0.1128194567775036,-0.04544990426713014
188.60000000000196,56.808101988630916,0.11235032835071701,-0.046769903987765815
189.70000000000198,57.16330154049716,0.11325358868638524,-0.04809008573216644
190.800000000002,57.51721464680484,0.11245367515431948,-0.049762620375259026
191.90000000000202,57.873270849747776,0.11010453687017341,-0.05105987187142258
193.00000000000205,58.23061720819127,0.11186478582862436,-0.05205003896100413
194.10000000000204,58.585401452597964,0.10939800325393745,-0.05270003939399537
195.20000000000206,58.937784446059865,0.10847895721957412,-0.05665005648446364
196.3000000000021,59.294988519541825,0.1109519384254134,-0.05533956467751766
197.40000000000208,59.64980285748803,0.10602799315214195,-0.05731009208038218
198.5000000000021,60.00803819516132,0.10600779634921231,-0.05895970567689224
199.60000000000213,60.364069924044344,0.1040469781457698,-0.059286018476284674
200.70000000000215,60.71171684397454,0.10087458385414139,-0.06324015129520033
201.80000000000217,61.07442574695143,0.10129644787537484,-0.0655400354618525
202.90000000000217,61.42845691447162,0.09936191068540134,-0.06685717274736014
204.0000000000022,61.78140378547764,0.09562085235403495,-0.07115004127730673
205.1000000000022,62.128077462849994,0.09387687884775042,-0.07245982824383868
206.2000000000022,62.48952218176646,0.08769087086221417,-0.07443554416072917
207.30000000000223,62.84371309753929,0.08652724851652605,-0.07837544384883488
208.40000000000225,63.196499232175505,0.08050321735948929,-0.08216305496226006
209.50000000000227,63.5541818773007,0.07624000696488298,-0.08495396007682654
210.6000000000023,63.91211061665547,0.07015617134695362,-0.08903409027824516
211.7000000000023,64.26892190846391,0.06440890136171373,-0.09219565172601119
212.8000000000023,64.62687086746368,0.05655290858797546,-0.09781184741101612
213.90000000000234,64.98418586689908,0.05127826467044061,-0.10438900606597024
215.00000000000233,65.33833879452793,0.042885226928719655,-0.10704528861278018
216.10000000000235,65.69764818044615,0.03375485247542853,-0.11429988420628989
217.20000000000238,66.05454830410167,0.02532093249646339,-0.12230679537060851
218.3000000000024,66.41115609203632,0.02019835273130166,-0.1288955188137031
219.40000000000242,66.76428933711772,0.013228930144622009,-0.13677123819519688
220.50000000000242,67.12518512169673,0.005759610766071344,-0.146108914175894
221.60000000000244,67.4803609382258,-0.0015387991147464142,-0.15538398545867205
222.70000000000246,67.83748684040032,-0.0025525592573409916,-0.16753330208367379
223.80000000000246,68.19696600230498,-0.0060172399574560664,-0.17438368306009977
224.90000000000248,68.55203009100505,-0.003882437223800661,-0.189175271608637
226.0000000000025,68.91117691063283,-0.005694589563048691,-0.19929415560697672
227.10000000000252,69.25734426283864,-0.006288751709192297,-0.21265847054630704
228.20000000000255,69.61609102045371,-0.006821977667650803,-0.22593543897277124
229.30000000000254,69.96781620726057,-0.0038607125631986428,-0.24223182992162196
230.40000000000256,70.32215064018449,-0.005015520396409734,-0.25522047109544044
231.5000000000026,70.67622790436818,-0.006406520045082242,-0.27274673357271384
232.60000000000258,71.030817593929,-0.0037204505060439708,-0.2905589218771407
233.7000000000026,71.38464752991602,-0.003582440294682243,-0.30855560621418165
234.80000000000263,71.74000780465292,-0.004178467269392971,-0.32591659941443396
235.90000000000265,72.10167978118876,-0.00421982194903503,-0.3444415683815434
237.00000000000267,72.45830581293279,-0.001503253455239939,-0.3681392557347083
238.10000000000267,72.81423744659611,0.0010739281332612372,-0.39030704418929174
239.2000000000027,73.16622488201408,0.000968488165757897,-0.41159476223976466
240.3000000000027,73.51829109871979,0.005164102643238522,-0.4355313091902895
241.4000000000027,73.87379573504974,0.005380418941628884,-0.45907978152684814
242.50000000000273,74.23083432693709,0.008781107358299067,-0.4825842289873945
243.60000000000275,74.5871001562949,0.016377690812507062,-0.5084840791307332
244.70000000000277,74.94078442263104,0.020253423960202133,-0.5323213650384884
245.8000000000028,75.29259685919581,0.024476983676031683,-0.555075111977561
246.9000000000028,75.64728546384835,0.03155307284364128,-0.5782432205203727
248.0000000000028,76.00377363407726,0.03510667193791206,-0.5996173735433925
249.10000000000284,76.35947334743987,0.04473936934916711,-0.6231454827024461
250.20000000000283,76.71249022901712,0.053050333011657846,-0.6433496464595034
251.30000000000285,77.06632999437193,0.06082922989903672,-0.6635861483341845
252.40000000000288,77.42356316411671,0.07058227657702032,-0.6834239163084721
253.5000000000029,77.77171004033751,0.07945621291889138,-0.6996968074030518
254.60000000000292,78.12841944425433,0.09365365172320939,-0.7162485272647388
255.70000000000292,78.4837685403074,0.09998880588548986,-0.7320429833396309
256.8000000000029,78.84047070841277,0.1094864398018176,-0.7452745315554044
257.90000000000293,79.19289771617677,0.11383616710746991,-0.7591001177856564
259.00000000000296,79.54688255964547,0.12399541547867332,-0.7682189366278043
260.100000000003,79.90279411921392,0.1320752414403934,-0.7810150673862304
261.200000000003,80.25691873176675,0.13670243178810004,-0.7931166797362774
262.300000000003,80.60688786327039,0.14116139141406459,-0.802051897060716
263.40000000000305,80.95917375920813,0.1501503349188278,-0.8141747079261736
264.50000000000307,81.31488654445815,0.1546183122677076,-0.8210844889754139
265.6000000000031,81.6675234290255,0.1571617745310352,-0.8307403701618479
266.7000000000031,82.02451536100203,0.16608337887792168,-0.8412730043918888
267.8000000000031,82.38147567098295,0.16853798024065236,-0.8501928933923235
268.9000000000031,82.73807143147464,0.17113244053707755,-0.8568705401424364
270.0000000000031,83.09077529616191,0.1747117386407524,-0.8653586771605677
271.10000000000315,83.45178766786302,0.17640940069976296,-0.8756356484076604
272.2000000000032,83.80571637952643,0.17568176285275738,-0.8791562323472433
273.30000000000314,84.1618322127846,0.17670646522740796,-0.890850060632177
274.40000000000316,84.51853417258553,0.18009768607386523,-0.8962605787942461
275.5000000000032,84.87410018841955,0.1815986542136887,-0.9014172935651965
276.6000000000032,85.23022454014641,0.18394212768498086,-0.9103930991875715
277.70000000000323,85.58734599286566,0.181986800309474,-0.9181275862767255
278.80000000000325,85.94089579435366,0.18030526871292296,-0.9242440167891024
279.9000000000033,86.30433163624673,0.18040107957750884,-0.9326756624593235
281.0000000000033,86.64746875023049,0.18323439335251668,-0.9382113541289967
282.1000000000033,87.00632708152686,0.1837113493276452,-0.9452348690816939
283.20000000000334,87.36101484862189,0.1863289997267541,-0.9523710643787848
284.30000000000337,87.72033685753709,0.1847751019461883,-0.9576507785429174
285.40000000000333,88.07268190889222,0.1846090013010222,-0.9630325931085189
286.50000000000335,88.42620114298249,0.1861614429778049,-0.9709189277215127
287.6000000000034,88.78273893010132,0.1857096802825362,-0.9775701252045783
288.7000000000034,89.13312590094355,0.18639298174993235,-0.9862989257967536
289.8000000000034,89.48119941018274,0.18346636028512386,-0.9917271473146632
290.9000000000034,89.84572567612219,0.183399320912635,-0.9983837360143593
292.0000000000034,90.2062119574589,0.18572522462516128,-1.0046005761332801
293.10000000000343,90.56366604905963,0.18776470410905488,-1.0114369848483622
294.20000000000346,90.92944381958391,0.18415639112615279,-1.0181498509479034
295.3000000000035,91.27423233465696,0.18337531952080366,-1.0240746449267495
296.4000000000035,91.63527200169526,0.18354292372798597,-1.0343872490081063
297.5000000000035,91.99137191944966,0.18425795666957878,-1.0407655212143632
298.60000000000355,92.34355522556268,0.18414149485747267,-1.0465535849895176
299.70000000000357,92.70445441327985,0.18217364883010023,-1.0574423972757567
300.8000000000036,93.05917242595909,0.17959599254289071,-1.0653501062281516
301.9000000000036,93.41382922924363,0.17844560899285788,-1.0720428097089036
303.0000000000036,93.77607647097362,0.1789585170872019,-1.0797826564434176
304.1000000000036,94.13650586304325,0.17723358104538867,-1.0893530523780615
305.2000000000036,94.49290387523224,0.17451243029546282,-1.0999712935432875
306.30000000000365,94.85208662039355,0.1778660411548687,-1.1095573854887055
307.4000000000037,95.20676444388832,0.17589180319393538,-1.116824629227764
308.5000000000037,95.57032666660804,0.17329304893131714,-1.129128826244742
309.60000000000366,95.92871914643982,0.1744569049795366,-1.139395364218728
310.7000000000037,96.28562211581159,0.17010173610647827,-1.1516639548365224
311.8000000000037,96.6428849134018,0.16975490719058728,-1.1618538662435656
312.90000000000373,96.99693107973377,0.16933586399777067,-1.1745355464362608
314.00000000000375,97.35371900578468,0.17030499206259742,-1.1866352031719467
315.1000000000038,97.71193989046424,0.1689227102627564,-1.2005231649094155
316.2000000000038,98.06680182663486,0.16459730429303598,-1.2137338449763178
317.3000000000038,98.42703417675581,0.1655110333343437,-1.2298048167170705
318.40000000000384,98.77913773834793,0.16689914800728567,-1.2431689220053688
319.5000000000038,99.13911734018112,0.16721588772074525,-1.2605637832774121
320.60000000000383,99.49997843133028,0.17089189109630665,-1.277254922413864
321.70000000000385,99.85916658375663,0.17351193810968013,-1.2921599328919173
322.8000000000039,100.22022247644963,0.17678032460878157,-1.309151362718321
323.9000000000039,100.5782352788717,0.17928839319406475,-1.326656154648381
325.0000000000039,100.92917000000156,0.18291212659540057,-1.3446299681265241
326.10000000000394,101.28635975631286,0.18603577299767227,-1.3631763463600879
327.2000000000039,101.64916513050633,0.1908012553475802,-1.3800899741025416
328.30000000000393,102.00657065050692,0.19687553590737772,-1.3971418619041254
329.40000000000396,102.36218939633628,0.20086404253922963,-1.4122389131348485
330.500000000004,102.71977862772206,0.20752728835936662,-1.4308293664606255
331.600000000004,103.07758393043456,0.2132312501308835,-1.4474398732924936
332.700000000004,103.43557489095811,0.22229257699274152,-1.4621520949056315
333.80000000000405,103.79226458530984,0.2329593148019513,-1.4772645805584168
334.90000000000407,104.15249067704771,0.2380609073350426,-1.4907347163388827
336.0000000000041,104.50774262703456,0.24465774653289207,-1.5049996547991191
337.10000000000406,104.86651245696603,0.25188631458813515,-1.5188388180413614
338.2000000000041,105.22530543194453,0.26106538253044187,-1.5290435309508865
339.3000000000041,105.58496892521708,0.26921981209702994,-1.54021644137143
340.4000000000041,105.93949237528895,0.27529688478055725,-1.5519094329287948
341.50000000000415,106.29602482031126,0.28050742247605887,-1.5613544348273485
342.6000000000042,106.66114668122032,0.2850728150310817,-1.5702882234568398
343.7000000000042,107.01665597443706,0.293361077559944,-1.5799207650501437
344.80000000000416,107.3747434528206,0.300164911280846,-1.5897032162196498
345.9000000000042,107.732380453541,0.30403037414460243,-1.597462031025311
347.0000000000042,108.09087703464368,0.3096457607671552,-1.6050634122610443
348.10000000000423,108.4505253447687,0.3131140175484637,-1.61359005768281
349.20000000000425,108.80916711079468,0.31522480575989564,-1.6188699981492412
350.3000000000043,109.16758355454505,0.31990301702632995,-1.6268166073719281
351.4000000000043,109.52526327886991,0.3253232897913447,-1.633368766977843
352.5000000000043,109.88431074289035,0.32923195422546203,-1.6399533852997896
353.60000000000434,110.24836711958001,0.33564472330484096,-1.6480761768128027
354.7000000000043,110.60776239158571,0.33711380994958384,-1.6547650536513427
355.80000000000433,110.96667329338071,0.3417334840361075,-1.6610362074716156
356.90000000000435,111.32326984555407,0.34208061059118644,-1.6689514759391102
358.0000000000044,111.6825466278645,0.3474955214741977,-1.675859803573804
359.1000000000044,112.04042714328193,0.3506121030147036,-1.6836118635218922
360.2000000000044,112.40086354803708,0.3564219250667586,-1.68947023354351
361.30000000000445,112.75672909961015,0.3571810532949895,-1.697349313288833
362.4000000000044,113.11776207002106,0.36057247802700476,-1.7066193209350162
363.50000000000443,113.47234120964862,0.3646590761751538,-1.7135335808510344
364.60000000000446,113.83812811322369,0.3677938166171708,-1.7187685934122623
365.7000000000045,114.1987637218336,0.3710080543174241,-1.7287088141766627
366.8000000000045,114.55102742016395,0.3714051696379024,-1.7372755592297904
367.9000000000045,114.91807930752793,0.37608833772692485,-1.7439292986334243
369.00000000000455,115.27946197103748,0.37935377067292464,-1.75360822103569
370.10000000000457,115.64483400483407,0.38121463572858083,-1.7638795700438656
371.2000000000046,116.00605314884861,0.3845298826276764,-1.772827575987904
372.30000000000456,116.36722288602496,0.38685472467653725,-1.779586153266207
373.4000000000046,116.72714987142562,0.38898587710817933,-1.790059182495153
374.5000000000046,117.09221688302077,0.3876239315963079,-1.7972997940639979
375.6000000000046,117.45076400302592,0.3917234211412064,-1.8057562244069372
376.70000000000465,117.81571833432577,0.39375609334851047,-1.8155063607186839
377.8000000000047,118.17364389597977,0.3937712125693449,-1.8252569444685216
378.9000000000047,118.5375099588,0.3959783535583077,-1.8334752039988405
380.00000000000466,118.8904360451785,0.39729685547013416,-1.8428414196796137
381.1000000000047,119.24990044828337,0.39712949542992537,-1.852382037881012
382.2000000000047,119.61344503856587,0.39655289956227646,-1.8621997717348733
383.30000000000473,119.97204484144977,0.3971102515842455,-1.8712869359327469
384.40000000000475,120.33696211967637,0.39635097191852564,-1.8812064981217698
385.5000000000048,120.7002596266151,0.39790631563171264,-1.8904774365701646
386.6000000000048,121.06199511155646,0.39727786741080173,-1.9000735569440246
387.7000000000048,121.4225492133444,0.39595841377823815,-1.9103792831664896
388.80000000000484,121.79632751776488,0.39755958421592097,-1.9187024510450978
389.9000000000048,122.1537681070721,0.3979111980640564,-1.9277544752831206
391.00000000000483,122.5162872763278,0.40223925590945675,-1.93673988413701
392.10000000000485,122.87374065147311,0.4023117037766206,-1.94544738209586
393.2000000000049,123.24099963554005,0.4023946237331,-1.9551734844016666
394.3000000000049,123.60646661606069,0.4028593312160711,-1.964485949861746
395.4000000000049,123.96952193027316,0.40286956111199945,-1.9722906210087254
396.50000000000495,124.34003993307681,0.4002496217217304,-1.9826013019762945
397.6000000000049,124.70493585372078,0.4002156359117295,-1.9921568441701605
398.70000000000493,125.07409104532871,0.40256709699300597,-1.9992660576857109
399.80000000000496,125.43517869877512,0.4017276968404009,-2.0068027618612203
400.900000000005,125.79755344407577,0.4031547510003195,-2.015623601368051
402.000000000005,126.1588288806162,0.4016104243625849,-2.0236235712201807
403.100000000005,126.50916870125643,0.40321992521590366,-2.03109159060971
404.20000000000505,126.87980129449376,0.4049276549266849,-2.0404686070374884
405.30000000000507,127.24744617306746,0.408067168668778,-2.0496486407987584
406.4000000000051,127.61145496197261,0.4067682076286965,-2.0563550785449634
407.50000000000506,127.97718923621579,0.4054600078602375,-2.06425692017307
408.6000000000051,128.3413548821361,0.4076826913834941,-2.0708058592500196
409.7000000000051,128.70916664837435,0.40507721298365307,-2.079849938608916
410.8000000000051,129.07291061341644,0.409089259615218,-2.0874357426343426
411.90000000000515,129.43292026316033,0.40866151711568777,-2.0928168918510117
413.0000000000052,129.79139731774669,0.4079164954338965,-2.102253176061735
414.1000000000052,130.15922301260002,0.41050852606078436,-2.1100253621618914
415.20000000000516,130.51794693643512,0.4104130361877232,-2.118523763872603
416.3000000000052,130.8818566578849,0.4163335765765508,-2.1284732061149723
417.4000000000052,131.2437364625082,0.4145651391519187,-2.1322609134964767
418.50000000000523,131.60590972943388,0.41218353221577786,-2.137544001729024
419.60000000000525,131.96682053612378,0.41476348614511394,-2.145604602597646
420.7000000000053,132.33256233393783,0.41559615085429913,-2.1524429415668456
421.8000000000053,132.6960331488522,0.41555135049148073,-2.1602421663849705
422.9000000000053,133.06264460448426,0.4135469185874425,-2.1668167379746253
424.00000000000534,133.42926191341738,0.4140671789147634,-2.1756065851017583
425.1000000000053,133.79456766463417,0.41432913380193837,-2.1805065601014126
426.20000000000533,134.16010574032862,0.4164191179177734,-2.1884302258620214
427.30000000000535,134.52223545801195,0.42018814933747173,-2.1934291403448674
428.4000000000054,134.885287333924,0.4202388361673812,-2.2000713888093326
429.5000000000054,135.24848957331875,0.42349799715697034,-2.2082980826380463
430.6000000000054,135.61144085736512,0.4260903889097396,-2.213585961748584
431.70000000000545,135.9758393528716,0.429104823159006,-2.2201518086279615
432.8000000000054,136.3338310302872,0.43106749304991543,-2.2267366819610253
433.90000000000543,136.70531925538094,0.42924910803643734,-2.2346497581166327
435.00000000000546,137.07031992402077,0.4308504892242222,-2.2399123250154527
436.1000000000055,137.43356671458034,0.43075923627330015,-2.246093694737988
437.2000000000055,137.80243217205435,0.43355880822827286,-2.254187297867172
438.3000000000055,138.1659385041126,0.43674587891025674,-2.258317651312271
439.40000000000555,138.53217541367465,0.4371197820218937,-2.2682710482438733
440.50000000000557,138.9004360683288,0.43763797169139385,-2.2739418587038878
441.6000000000056,139.26581106596484,0.43883792430722335,-2.277850650037758
442.70000000000556,139.63241024235367,0.4403122091323781,-2.2857948631203877
443.8000000000056,139.99547731081998,0.4433628409139194,-2.2896573165492797
444.9000000000056,140.36641667565965,0.4439547426946784,-2.297155483394646
446.0000000000056,140.73119445019879,0.44392075872664427,-2.3058217477097185
447.10000000000565,141.09604233617418,0.44545173879362676,-2.310232838926094
448.2000000000057,141.4631057803739,0.44701066522916366,-2.31491326019267
449.3000000000057,141.83445760526607,0.44694519654685183,-2.3194186838259494
450.40000000000566,142.20136238773102,0.4505950227827853,-2.331113307032475
451.5000000000057,142.56801629946398,0.4507401199441097,-2.3377229472077
452.6000000000057,142.92391494605818,0.4539705835466077,-2.341569137365673
453.70000000000573,143.30028813361307,0.45687985530480635,-2.3485815474055602
454.80000000000575,143.6663713052003,0.46016260774133855,-2.355747999155253
455.9000000000058,144.03216751020761,0.46385474225215306,-2.360885995647199
457.0000000000058,144.39516539600473,0.4638197248421394,-2.3660165866847964
458.1000000000058,144.76212701726382,0.46362213070745306,-2.3724910105863457
459.20000000000584,145.12916758049846,0.46621601619156605,-2.379120051125917
460.3000000000058,145.4544767722027,0.46488766150100425,-2.38070183979441
461.40000000000583,145.8641738941906,0.4697070728211412,-2.393280531048563
462.50000000000585,146.22510750405377,0.47237688884647655,-2.39923852747312
463.6000000000059,146.59099553854827,0.4727788018642898,-2.405800093227736
464.7000000000059,146.95683179489424,0.4743550125987783,-2.411059206402147
465.8000000000059,147.32383949848477,0.4747138004261273,-2.4179661878695846
466.90000000000595,147.69407954502776,0.47675101401102293,-2.423082607308117
468.0000000000059,148.05963998309352,0.47825780303357224,-2.4308280426996838
469.10000000000593,148.42674792528973,0.48187948422111715,-2.4363938826262164
470.20000000000596,148.7928335559201,0.48339548959118805,-2.441366058584351
471.300000000006,149.15301053814045,0.48782959092785094,-2.4451710489383096
472.400000000006,149.5238366235789,0.4897789794950511,-2.4532300879858893
473.500000000006,149.88876489460637,0.4904243143132443,-2.4598031396824225
474.60000000000605,150.2576670886883,0.48893361831745397,-2.4649646731420294
475.70000000000607,150.62583343759522,0.489422619626942,-2.4719143383141424
476.8000000000061,150.99214907767018,0.4909313683759118,-2.4747511599672984
477.90000000000606,151.35845227391462,0.49208051354691995,-2.4837731169361827
479.0000000000061,151.72356588798326,0.4934810247532746,-2.490320097737827
480.1000000000061,152.08415938029273,0.49456805691705075,-2.4929540215468626
481.2000000000061,152.45247131900433,0.4987426899756009,-2.50086710175224
482.30000000000615,152.82381992722853,0.4984142933604525,-2.506137492791967
483.4000000000062,153.18585625576546,0.49784944643408613,-2.5107467634145255
484.5000000000062,153.558576470945,0.49907040926213964,-2.517457284886105
485.60000000000616,153.92288545655765,0.4994456409583663,-2.5240798427088453
486.7000000000062,154.29090073575802,0.5015261754784646,-2.528970635514333
487.8000000000062,154.66078895374525,0.5024700526435286,-2.53423363546085
488.90000000000623,155.02421131277433,0.5041735630153295,-2.5403872022544336
490.00000000000625,155.38873475147042,0.5069127246744682,-2.546063360540776
491.1000000000063,155.7599304835246,0.5076122337087472,-2.5487661154828256
492.2000000000063,156.1267866962664,0.5089884245821359,-2.5563294212898673
493.3000000000063,156.49375164446903,0.5105112005122994,-2.5616893950914474
494.40000000000634,156.86064243724365,0.5100096991280121,-2.5669597834919005
495.5000000000063,157.2256164590103,0.5136784449599188,-2.570872624367201
496.60000000000633,157.59377009254948,0.5130530777562909,-2.5775054519252603
497.70000000000636,157.96110614798263,0.5142006815350193,-2.581446034745361
498.8000000000064,158.32951221002125,0.5146794279055782,-2.5867300728748157
499.9000000000064,158.700223463095,0.5175910092661853,-2.5919906718410104
501.0000000000064,159.06402176633335,0.5200520856111266,-2.5959499909848622
502.10000000000645,159.43330917704031,0.526597881335511,-2.6015623246994624
503.2000000000064,159.8003266918389,0.5257767517873337,-2.6054987518936366
504.30000000000643,160.16982169078796,0.5263680563490789,-2.6125146696162287
505.40000000000646,160.54078312479595,0.5311767352328209,-2.6135509057450594
506.5000000000065,160.9053615708268,0.5323526135346812,-2.6217287513298135
507.6000000000065,161.27184389787084,0.5330806301569688,-2.626751132516277
508.7000000000065,161.64003408414234,0.5336950503028468,-2.628335041047916
509.80000000000655,162.00674336303584,0.5355372950565478,-2.633438757077859
510.90000000000657,162.37684879178914,0.538053344910074,-2.638887688405039
512.0000000000066,162.7467781702047,0.5380851351046823,-2.642814049550894
513.1000000000065,163.1180251519514,0.5426011742917851,-2.6467455334644194
514.2000000000066,163.48058723248715,0.5444058062040988,-2.6507335410276234
515.3000000000065,163.8513052874187,0.5467784156868198,-2.6559901136036115
516.4000000000067,164.22172437087215,0.5464928138465273,-2.6626154706385607
517.5000000000066,164.5885873018526,0.5472045671577561,-2.66540313234972
518.6000000000067,164.95719435881273,0.5516218339147723,-2.6693901944951968
519.7000000000066,165.32468652174072,0.552915765235078,-2.674767985879953
520.8000000000067,165.69086129835364,0.5581883630915123,-2.67872014167473
521.9000000000067,166.05882222432354,0.5603789340182967,-2.682668211212323
523.0000000000067,166.42308934932274,0.5597332684502254,-2.686621066921353
524.1000000000067,166.75046425049413,0.5648250713049634,-2.690579858918975
525.2000000000068,167.15658246488422,0.5605446423727114,-2.694853340167385
526.3000000000068,167.52765071111668,0.5645898416770352,-2.698160872288979
527.4000000000068,167.89886982571795,0.5664378232280258,-2.7027318609290374
528.5000000000068,168.26993401176733,0.5696591132630922,-2.708688832381069
529.6000000000068,168.63818851378025,0.5698288281881501,-2.711320677282156
530.7000000000069,169.00212646092425,0.5704456239918925,-2.716829600326772
531.8000000000068,169.3740451321591,0.5720791578464508,-2.7167104819409706
532.9000000000069,169.74486163803417,0.5760651540357933,-2.7244300764084026
534.0000000000068,170.11271651582825,0.5781247410260766,-2.7272400070591916
535.100000000007,170.47531638855648,0.5792966881125627,-2.7288227115429255
536.2000000000069,170.84816318168555,0.5813678536376519,-2.7302623030743893
537.300000000007,171.2171989691817,0.5848696588122377,-2.7382201258517433
538.4000000000069,171.58782816347932,0.584445622306849,-2.7421698973287025
539.5000000000069,171.9604196480156,0.5876678058653746,-2.7438305982244544
540.600000000007,172.33372124791552,0.5912086543464254,-2.7476169392742724
541.700000000007,172.70654443429316,0.5909176142874584,-2.753157412676564
542.800000000007,173.0721851267298,0.5928866406151543,-2.7553450992096504
543.900000000007,173.4425875958639,0.597752526054665,-2.7571547535676966
545.000000000007,173.81319196871516,0.6005664884535304,-2.762487760398427
546.1000000000071,174.1758968927593,0.6030356649526005,-2.7657694365229193
547.2000000000071,174.5484848602189,0.6056919887732501,-2.768408322278937
548.300000000007,174.9159316833301,0.605017619423017,-2.7724697981407975
549.4000000000071,175.29048417061048,0.6064630850384549,-2.775769780917737
550.500000000007,175.65579918022434,0.6108375162739652,-2.778414732139363
551.6000000000072,176.02060484406329,0.6094222972589556,-2.7810399463367057
552.7000000000071,176.39542892102253,0.6083027246010968,-2.783205678963114
553.8000000000072,176.76682279879742,0.6094956199682298,-2.7860236631619646
554.9000000000071,177.1385002964898,0.6119634400626903,-2.7907085772912894
556.0000000000072,177.5100828190576,0.6125292662418629,-2.792197181842816
557.1000000000072,177.88858960605677,0.6159705593597777,-2.795313127362893
558.2000000000072,178.24954208070483,0.6195904020437908,-2.796658732513989
559.3000000000072,178.6166667005059,0.6198197006057362,-2.798171645700328
560.4000000000073,178.98916311011087,0.6204576254741969,-2.8037598990807338
561.5000000000073,179.35277575678333,0.6234746005156788,-2.804430087149878
562.6000000000073,179.72253862009305,0.6235229224477126,-2.805735614186097
563.7000000000073,180.09516310695244,0.6248631222325718,-2.8083799161958396
564.8000000000073,180.46511540398296,0.6246905539724308,-2.811010195978082
565.9000000000074,180.8384899833803,0.6269513567598866,-2.813271329651611
567.0000000000074,181.20774341792497,0.628327703414786,-2.8149598459999945
568.1000000000074,181.57907862584779,0.6302897080520087,-2.8186579764653876
569.2000000000073,181.9520379255099,0.6350451196342195,-2.819392996088522
570.3000000000073,182.3211595482185,0.6348470900248253,-2.8215498259612763
571.4000000000074,182.69097010251645,0.6387710476295314,-2.8217084355144104
572.5000000000074,183.0604923527314,0.6410504233316987,-2.8242550781739757
573.6000000000074,183.42788368783883,0.6423727660568082,-2.825830050299389
574.7000000000074,183.79397436156898,0.6437112856125473,-2.826681573562925
575.8000000000075,184.16456411811512,0.6469076729688494,-2.830445029016777
576.9000000000075,184.53812877808906,0.6500268018379343,-2.8308798699937583
578.0000000000075,184.90979692749232,0.6488113136124405,-2.832200177937482
579.1000000000075,185.27593557756273,0.6495782698290238,-2.8327852847281365
580.2000000000075,185.65139121717706,0.6499618514476055,-2.8330418528566215
581.3000000000076,186.02334140181517,0.6501097526671835,-2.8361500957053996
582.4000000000076,186.3963931395423,0.64863493185638,-2.837232706188294
583.5000000000076,186.770976941713,0.6507288839575185,-2.837349882003185
584.6000000000076,187.13559210526023,0.6492311893735239,-2.8386725853114525
585.7000000000077,187.50941545189883,0.6475755389301892,-2.8399910709519554
586.8000000000077,187.879735203056,0.6471643684751178,-2.8419699587655485
587.9000000000076,188.24916494132592,0.6455070636889326,-2.841630244233447
589.0000000000076,188.61628531487764,0.6475315686194036,-2.844599960000006
590.1000000000076,188.98649928288432,0.6495275655677561,-2.8452601616009163
591.2000000000077,189.35759217759966,0.651428669421861,-2.8462142595155036
592.3000000000077,189.72209862557443,0.6520884927735793,-2.8467077631400928
593.4000000000077,190.1041695139306,0.6511367396844072,-2.8482330689758677
594.5000000000077,190.4738572015058,0.6495370217373235,-2.848229980591479
595.6000000000078,190.84353599039486,0.6542366612967692,-2.849548946851578
596.7000000000078,191.21539456360213,0.6509192148644845,-2.85251038311959
597.8000000000078,191.5820832744963,0.6462477341968274,-2.852526187569433
598.9000000000078,191.95152739495703,0.6463921464268567,-2.8518803812397895
600.0000000000078,192.32659471750466,0.6486331837042789,-2.8548100820025946
601.1000000000079,192.69801531693744,0.6462311089372805,-2.8561298575628067
602.2000000000079,193.06756820648104,0.6457396886763935,-2.8548198480292397
603.3000000000079,193.4303099308337,0.6425632136053137,-2.857439969774509
604.4000000000078,193.80447556084016,0.638276171047687,-2.8564601077421314
605.5000000000078,194.17589394942678,0.6360319512000603,-2.854480520574242
606.6000000000079,194.54848576876213,0.6323176937401263,-2.858439379612497
607.7000000000079,194.91058185452889,0.6292015575863494,-2.8597558041933517
608.8000000000079,195.29344544607181,0.628455368810733,-2.8610701805005165
609.9000000000079,195.6645347311434,0.6244709584121249,-2.861069954573475
611.000000000008,196.03588968145664,0.6250960923526248,-2.8628253553658136
612.100000000008,196.4058142701829,0.6221480959933559,-2.862390092587276
613.200000000008,196.77445911827348,0.6234354111579676,-2.8630497850431937
614.300000000008,197.14754407240372,0.6189956300267141,-2.8660099112818553
615.400000000008,197.51590749563064,0.6184673627704411,-2.8650211811826085
616.5000000000081,197.8887353432976,0.6171906918834191,-2.867330181065462
617.6000000000081,198.26383027915733,0.6126001943196477,-2.8669998698707273
618.7000000000081,198.63596295561766,0.6154327163770605,-2.866999699534416
619.8000000000081,199.0071397584399,0.6135950048806604,-2.866669879462031
620.9000000000082,199.3765028989542,0.6151806424757813,-2.8701821239637964
622.0000000000082,199.74645972474133,0.6140495596106277,-2.872802043396055
623.1000000000081,200.11772691395427,0.6151629220057733,-2.870179989870251
624.2000000000081,200.4862665056141,0.6143837314104155,-2.8705096488236643
625.3000000000081,200.8559992623643,0.6131750105295222,-2.874139982589707
626.4000000000082,201.2291594395378,0.6125127051480899,-2.871500199441246
627.5000000000082,201.60250292700624,0.6111493490811359,-2.8714999160010812
628.6000000000082,201.97306409986317,0.6085135292770081,-2.8734701047510596
629.7000000000082,202.346186335607,0.6106980134198419,-2.8724467231054773
630.8000000000083,202.71412201154834,0.6060801951752757,-2.8761072652898254
631.9000000000083,203.09327852924682,0.6068475025215112,-2.8770452569930876
633.0000000000083,203.46166574479145,0.6138377952237346,-2.8771856532338758
634.1000000000083,203.8359575141608,0.6112314484018124,-2.8793998853996494
635.2000000000083,204.20875937772382,0.6128608758191556,-2.878089667717859
636.3000000000084,204.57949315272975,0.6154639616514999,-2.8794100279994725
637.4000000000084,204.95201611578395,0.6140896080154752,-2.8817098339885208
638.5000000000084,205.3266071415228,0.6116790265540164,-2.882355383404719
639.6000000000083,205.70250094165243,0.6128911790952494,-2.8813799193238583
640.7000000000083,206.08110708353803,0.6102106488749122,-2.883647112549234
641.8000000000084,206.4546567210354,0.6090203643592893,-2.884349803994921
642.9000000000084,206.8291627456352,0.6126292121464094,-2.8856294367170525
644.0000000000084,207.1985514381237,0.614453811768312,-2.8861060102348866
645.1000000000084,207.5788560674132,0.6164657864031184,-2.8857701381576097
646.2000000000085,207.94984279331254,0.6202841367060914,-2.8870902474967854
647.3000000000085,208.32087570726318,0.6207869143558906,-2.8870898979999895
648.4000000000085,208.6960643486732,0.6151836188924178,-2.8870847164818016
649.5000000000085,209.0734703250245,0.6197771872858553,-2.887711292596169
650.6000000000085,209.4474419932277,0.623015082113535,-2.887089385572464
651.7000000000086,209.82121299718844,0.6181020357213587,-2.888069862615593
652.8000000000086,210.19917421668583,0.6157891694907429,-2.8897199079859512
653.9000000000086,210.57160702394245,0.6221290910795567,-2.893306470059444
655.0000000000086,210.94435950057695,0.6249025432426916,-2.8926798649340917
656.1000000000087,211.31483383287585,0.6243214432527096,-2.8930203252438105
657.2000000000087,211.69358266141887,0.6252014687903735,-2.8936799374197855
658.3000000000086,212.0643262707266,0.626654581017323,-2.8958999119998343
659.4000000000086,212.44338699827085,0.6264190059570522,-2.894554091580476
660.5000000000086,212.81835778718235,0.6264412111471187,-2.898484573130678
661.6000000000087,213.19544945565914,0.6293584716800389,-2.8968598966629795
662.7000000000087,213.57077118987553,0.6298681485279849,-2.8974193614758033
663.8000000000087,213.94122280111563,0.6327835356850036,-2.8977374810624568
664.9000000000087,214.3125027619935,0.6309515524636349,-2.8991598679297583
666.0000000000088,214.6875172888585,0.6325746680814754,-2.8993558892997306
667.1000000000088,215.06435790284613,0.6329382853212855,-2.899170185162964
668.2000000000088,215.44131457351946,0.6348536774233087,-2.901532851258434
669.3000000000088,215.81882612711902,0.6340532336157672,-2.903117234068481
670.4000000000088,216.19012469972648,0.6368602903619545,-2.904429847918282
671.5000000000089,216.56366556311642,0.6350936410138033,-2.902022084687524
672.6000000000089,216.940624710034,0.6382963285962218,-2.9046600182062674
673.7000000000089,217.3126100628333,0.6395276487132311,-2.9059801839999997
674.8000000000088,217.69207850763584,0.6420795187389643,-2.9072900784202815
675.9000000000088,218.0727063997044,0.6432893861010975,-2.907812091559351
677.0000000000089,218.44836959041612,0.6490965419958334,-2.906630026073209
678.1000000000089,218.82053589890268,0.6543284759906891,-2.9089393133850168
679.2000000000089,219.1938125925088,0.659904090033326,-2.9102498826910397
680.3000000000089,219.56666215075217,0.6592295988672225,-2.9109100354081803
681.400000000009,219.94417500881008,0.65455009795091,-2.910921054739914
682.500000000009,220.32127510361815,0.6523988208878653,-2.9109098480488043
683.600000000009,220.69617216580187,0.6553223291690518,-2.9119302425354583
684.700000000009,221.0732334120625,0.661587441496833,-2.9143204827609726
685.800000000009,221.45477931112634,0.660667539820244,-2.9133224779050506
686.9000000000091,221.83237728799665,0.6611976963025963,-2.9143081180199215
688.0000000000091,222.21032782896128,0.6644574758091679,-2.9169510438047856
689.1000000000091,222.58833648864157,0.6667761549924704,-2.9169503671893438
690.2000000000091,222.96711536682116,0.6689127444123886,-2.9182814891057056
691.3000000000092,223.34423041103662,0.669397243525913,-2.9195755064771536
692.4000000000092,223.71617258952838,0.678585102096003,-2.92045984000005
693.5000000000091,224.0964865439691,0.6781173002633478,-2.920787901804575
694.6000000000091,224.47037580961452,0.6786048368861874,-2.9204703591255563
695.7000000000091,224.85077171545265,0.683349882201733,-2.9231000733193997
696.8000000000092,225.22674736641548,0.6852350864188155,-2.925386146815698
697.9000000000092,225.60044437166684,0.6861711995118553,-2.9250489269894793
699.0000000000092,225.9716652849516,0.6866075476108731,-2.923760059997579
700.1000000000092,226.3606813407461,0.687605576737585,-2.9263949273699295
701.2000000000093,226.73203759651025,0.6892445955271904,-2.928346112078935
702.3000000000093,227.11210152256572,0.6912992412391867,-2.9281542201428827
703.4000000000093,227.49135352430937,0.6913355760045139,-2.926847691364708
704.5000000000093,227.8695099855762,0.6948452858907821,-2.9284799543505393
705.6000000000093,228.24957971492884,0.6985868154592667,-2.9289430344583645
706.7000000000094,228.6283169286064,0.7074276154025261,-2.9295798362443017
707.8000000000094,228.99885179908935,0.7079901332130685,-2.932209802163678
708.9000000000094,229.377560788383,0.7147295425251015,-2.93220890518924
710.0000000000093,229.75311675109194,0.7206913524352376,-2.9330762198384166
711.1000000000093,230.12714889668644,0.7258665623457528,-2.9344098407290486
712.2000000000094,230.51062048394692,0.724772631196372,-2.9350632773173264
713.3000000000094,230.89045061634175,0.7270575255189144,-2.935060108000214
714.4000000000094,231.27504721407715,0.7303732689805316,-2.9376979722933863
715.5000000000094,231.65729597183378,0.7269481710866021,-2.937815278925156
716.6000000000095,232.0352815955308,0.7332369433481187,-2.9391300840001326
717.7000000000095,232.41477978222989,0.7376506151222155,-2.9404185559666263
718.8000000000095,232.7925683384208,0.7424385762693386,-2.9394619936819413
719.9000000000095,233.16798232100348,0.7409270976802822,-2.9420900097735716
721.0000000000095,233.54347968326007,0.7445451967716366,-2.9395216603144414
722.1000000000096,233.9158519552302,0.7447242931189157,-2.941755181986407
723.2000000000096,234.2947635268883,0.7504130796761421,-2.9430698940000077
724.3000000000096,234.6755506036378,0.7551229187144666,-2.9458275989226634
725.4000000000096,235.05361573288118,0.7544212515570206,-2.944251444137842
726.5000000000097,235.43505575687885,0.756255044175522,-2.9453563074538023
727.6000000000097,235.8130429156957,0.7599473638967464,-2.946702785875898
728.7000000000096,236.1898840354038,0.7641320176837401,-2.9470295506074526
729.8000000000096,236.56457939929004,0.766319456673235,-2.9483432286394784
730.9000000000096,236.94644968872996,0.7727419157346782,-2.947917775180258
732.0000000000097,237.32406244116868,0.7778761307458155,-2.9482823437857197
733.1000000000097,237.70257449031126,0.7796396077011916,-2.9513207010153963
734.2000000000097,238.0753166944732,0.789022595489469,-2.9506737947584494
735.3000000000097,238.45087621126518,0.791793871841662,-2.952629971672718
736.4000000000098,238.82318343236423,0.7977866520152241,-2.953978768085779
737.5000000000098,239.20653546141565,0.8069092556363173,-2.9505408367354553
738.6000000000098,239.58499480444192,0.8043705672939097,-2.953297375693382
739.7000000000098,239.96190613927936,0.811985519715922,-2.95577653447512
740.8000000000098,240.34050475644614,0.8194996881281214,-2.957196602710455
741.9000000000099,240.71479677872543,0.8223891627921958,-2.955810152057181
743.0000000000099,241.09109433695446,0.8257315951340238,-2.9584756074573093
744.1000000000099,241.4670635274682,0.8285883985924596,-2.9591058419180127
745.2000000000098,241.8488293225697,0.8310919911658909,-2.958396954778072
746.3000000000098,242.22551642461397,0.8345708146442818,-2.9590090227209567
747.4000000000099,242.60115526912276,0.8426031441047002,-2.958450368076621
748.5000000000099,242.97917000000325,0.8456300130867422,-2.9584498940002684
749.0000000000099,243.1469610518043,0.8508564784233483,-2.9610774794656223