File: 01_Data/Basswood_Panel/STA/N2/30K_min/Basswood_Panel_STA_N2_30KData_220315_R3.csv
##Temp./Â°C,Time/min,DSC/(mW/mg),Mass loss/mg
49.0,10.416614480911603,0.008966435366648096,-0.06527111472616287
50.20000000000002,10.68380419334778,0.07610204968416245,-0.06330509034974696
51.400000000000034,10.823794444634594,0.13222209227033066,-0.06308360258088808
52.60000000000005,10.929698231149594,0.17818798906442468,-0.06307950335821211
53.80000000000007,11.018256486972525,0.2185116349653422,-0.06368568804339425
55.000000000000085,11.09762251079284,0.25669499051755235,-0.06129858464510907
56.2000000000001,11.16934919938623,0.2907976739355869,-0.06281489915664995
57.40000000000012,11.236013055581019,0.3231233095310176,-0.0633284318778431
58.600000000000136,11.29832581528552,0.3509180576464134,-0.062307071029888306
59.80000000000015,11.357465646010123,0.3784055474702288,-0.06317396772812511
61.00000000000017,11.414157771209918,0.4026357431895552,-0.06342205552965208
62.20000000000019,11.469213995354238,0.42759292906244223,-0.062345532441599794
63.400000000000205,11.522661250840452,0.4496981107034821,-0.06397733582302667
64.60000000000022,11.574204616699351,0.47243779394455676,-0.0638029852132771
65.80000000000024,11.62431947336071,0.49169799711664053,-0.06370335019334128
67.00000000000026,11.673549841013827,0.5095314565081064,-0.06377688471351028
68.20000000000027,11.722169891028043,0.5325759424672394,-0.06464942734679546
69.40000000000029,11.770358295083724,0.5480470159312185,-0.06478096744172746
70.6000000000003,11.816783951344373,0.5647069428339411,-0.06548517907286033
71.80000000000032,11.863728758991959,0.581837919488116,-0.06659120078214453
73.00000000000034,11.909323502751427,0.5984995617002795,-0.06547127903225558
74.20000000000036,11.954389260231553,0.6143927118435839,-0.0656874038234001
75.40000000000038,11.999618625443125,0.6295392013522855,-0.06572788506129523
76.60000000000039,12.043850506096378,0.6427295031089844,-0.06621789198398886
77.80000000000041,12.087983648882762,0.6591252003995822,-0.06719226359817476
79.00000000000043,12.131652473682673,0.6721517884388318,-0.06831502375314535
80.20000000000044,12.175207381465773,0.6865594451706585,-0.06897408947668726
81.40000000000046,12.218613548111136,0.6988573196667911,-0.06843583443909385
82.60000000000048,12.261933172711688,0.7127144815935395,-0.0675239656189115
83.8000000000005,12.304776956452951,0.7234279266607135,-0.06754896788101927
85.00000000000051,12.346470688340153,0.7370760717507383,-0.07005915258429596
86.20000000000053,12.389064390753209,0.7476647812193423,-0.07006873081270326
87.40000000000055,12.431572092327178,0.7611557826690311,-0.07099135268346979
88.60000000000056,12.47321189878193,0.7714220468076809,-0.0713709774406932
89.80000000000058,12.514565514741163,0.7811277690265161,-0.07244409157888354
91.0000000000006,12.556161058666966,0.7914987003232038,-0.07141597283318157
92.20000000000061,12.597825047766092,0.8014504358668992,-0.07270619793054811
93.40000000000063,12.639031072815836,0.8094546373259832,-0.07289044862558214
94.60000000000065,12.6802517550653,0.8197056632474314,-0.07409474023334672
95.80000000000067,12.721204022149221,0.8264043620464417,-0.07410160811118516
97.00000000000068,12.76213717475358,0.8363880860174262,-0.07432140101260742
98.2000000000007,12.803173170046227,0.8394951032774155,-0.0755746408913387
99.40000000000072,12.844016486523698,0.845441173222047,-0.07691178001504184
100.60000000000073,12.884155535901325,0.851894482007161,-0.07682537546731849
101.80000000000075,12.924856847343436,0.8576569633546642,-0.07689476896294645
103.00000000000077,12.96540262601834,0.8593459628684208,-0.0771458519207795
104.20000000000078,13.006529332130583,0.8621127866726247,-0.07819994951647047
105.4000000000008,13.046182678417436,0.863765859764877,-0.07855295403861629
106.60000000000082,13.086905536572793,0.8658375809940706,-0.07951968232818007
107.80000000000084,13.127170984772032,0.8651235011442305,-0.08080255078371179
109.00000000000085,13.167403515640629,0.8674910002751325,-0.08018654168905925
110.20000000000087,13.207635506534745,0.867394382644319,-0.08018026959227553
111.40000000000089,13.247966904468694,0.8697359794434633,-0.08023707604642416
112.6000000000009,13.288132286863805,0.8649646246508902,-0.08150450724054759
113.80000000000092,13.328014438153726,0.865154536777156,-0.08131691719670897
115.00000000000094,13.368375148250733,0.8623249831954491,-0.0821419453343406
116.20000000000095,13.408696883409185,0.8614074563072198,-0.08345902797291549
117.40000000000097,13.448382624223335,0.8598636087071647,-0.08346826214091285
118.60000000000099,13.488413701849801,0.8571666323697813,-0.08367251122580965
119.800000000001,13.528361860601537,0.8557708013196399,-0.08346889319967721
121.00000000000102,13.567912788582232,0.8536034292761946,-0.08346998714381515
122.20000000000104,13.607718036373182,0.8536675659272059,-0.08346914403485695
123.40000000000106,13.647603525587643,0.8512464655514251,-0.08478525291011385
124.60000000000107,13.687678262289309,0.8516550972197185,-0.08479000000000259
125.80000000000109,13.726851625228862,0.8504112677565885,-0.08609853210373775
127.00000000000111,13.766173211930461,0.8505501483087143,-0.08610005483351024
128.20000000000113,13.805912093435506,0.8502291676173988,-0.08612107486147025
129.40000000000114,13.844992821738083,0.8488047864605082,-0.08707616517382455
130.60000000000116,13.884095112714169,0.8509649702015739,-0.0870874148451839
131.80000000000118,13.923246967522038,0.8498283524256603,-0.08568983627285265
133.0000000000012,13.962841652579517,0.8530821493693175,-0.08577807506323465
134.2000000000012,14.001736448455253,0.8545474859192881,-0.08627012889395091
135.40000000000123,14.040749318212441,0.8591318702173126,-0.08709092701970444
136.60000000000124,14.079570564075846,0.8606612715268471,-0.08709056143264116
137.80000000000126,14.118470396529153,0.864366274631096,-0.08715047727958547
139.00000000000128,14.157691663643853,0.8657004953575568,-0.08839977781661901
140.2000000000013,14.195662257383695,0.8700022269135528,-0.08840000684837346
141.4000000000013,14.233657962254291,0.8754251547789562,-0.08852549120097031
142.60000000000133,14.273278191061639,0.8783513506407126,-0.0897264571937395
143.80000000000135,14.311812621598158,0.8810967253751052,-0.08971995830459356
145.00000000000136,14.35037017192444,0.8864176819050331,-0.08971992316680799
146.20000000000138,14.388460326707818,0.8890723354032797,-0.08971992299952314
147.4000000000014,14.426685957628663,0.8939302521889245,-0.08971992343459068
148.60000000000142,14.465096618441086,0.8984885823647998,-0.08972003737429723
149.80000000000143,14.5030436483658,0.9043387410356376,-0.08974264932216247
151.00000000000145,14.541828483175138,0.9099583847932263,-0.09104779567652788
152.20000000000147,14.580136155831703,0.9139082294008045,-0.09103995271119736
153.40000000000148,14.618051139192485,0.9202822849286516,-0.09103992392867255
154.6000000000015,14.656259365125168,0.9237560647499244,-0.09104110714989044
155.80000000000152,14.694043155747034,0.9285802434617549,-0.0914073288190087
157.00000000000153,14.732128256767647,0.9328193284229156,-0.09241845980164376
158.20000000000155,14.769795269827206,0.9377857048320937,-0.09235013998481323
159.40000000000157,14.807627019387027,0.9451557197106276,-0.09235033838041673
160.6000000000016,14.845632904189602,0.9475532575650774,-0.09254589372310296
161.8000000000016,14.883710998225819,0.9522865516886713,-0.09333320833584269
163.00000000000162,14.921349574779072,0.9553785116506509,-0.09334178275938054
164.20000000000164,14.95932443998594,0.9630381941159237,-0.09467772351714077
165.40000000000165,14.997129151110899,0.9675310451482203,-0.09532117119370076
166.60000000000167,15.03510980553306,0.9709544036269335,-0.09531991447244303
167.8000000000017,15.072387402677832,0.9735809026543638,-0.09531990346622798
169.0000000000017,15.109795710691193,0.9790749653516817,-0.09531998192138236
170.20000000000172,15.147603820851911,0.9866794813325579,-0.0952947556765702
171.40000000000174,15.185103349077496,0.9876767888769771,-0.09567647127334711
172.60000000000176,15.222950742154582,0.9946438638139856,-0.09660342390308507
173.80000000000177,15.2602947482222,0.9980657449452001,-0.096639981191188
175.0000000000018,15.297679445324908,1.0016981210021385,-0.09794556822269573
176.2000000000018,15.335412911541452,1.006061732348534,-0.09795000084702288
177.40000000000182,15.37295237974035,1.0114419447817953,-0.09797636014790179
178.60000000000184,15.410096729276585,1.0156224056139243,-0.09927332081929263
179.80000000000186,15.447166844702172,1.0186975769300441,-0.09926987732224646
181.00000000000188,15.484381090256832,1.02226215486746,-0.09927002826609899
182.2000000000019,15.521808622404704,1.0261483677032135,-0.09928191875332981
183.4000000000019,15.55902055077333,1.0309481483145717,-0.10190940365131906
184.60000000000193,15.59577043794526,1.0360177214919024,-0.10190025107353806
185.80000000000194,15.632909351285976,1.0397509605668653,-0.10192100244225788
187.00000000000196,15.669683460812616,1.0423559012244694,-0.10124193860170072
188.20000000000198,15.70707323904773,1.0454829089222906,-0.10124005053387064
189.400000000002,15.744151626011217,1.050578096783299,-0.10124177584148386
190.600000000002,15.781048855643222,1.0543938897881104,-0.10099452499243222
191.80000000000203,15.818072507739306,1.0577722141807957,-0.10120452235627697
193.00000000000205,15.854920216650397,1.0622381777978536,-0.1039618134781981
194.20000000000206,15.891927945545032,1.0673913479674515,-0.103884723940606
195.40000000000208,15.928619784853204,1.0701924537325542,-0.10518727448448484
196.6000000000021,15.965252354593826,1.0725807846297242,-0.10519040792109946
197.80000000000211,16.001860770861374,1.0765026362147458,-0.10586696057882339
199.00000000000213,16.03886699977214,1.082308382756744,-0.10781663299831923
200.20000000000215,16.075859408355413,1.0858239963504905,-0.1092391116343272
201.40000000000217,16.112246479935536,1.0871676281879457,-0.10925114085983267
202.60000000000218,16.149289738700826,1.0925094549053367,-0.1105768579985873
203.8000000000022,16.185837706196008,1.0970399824668648,-0.11095305845290593
205.00000000000222,16.22273782553244,1.1023177736446277,-0.11204795779426746
206.20000000000223,16.259231175539647,1.1038141577970602,-0.11320010705627626
207.40000000000225,16.295928868304586,1.110795645952746,-0.1132271297184575
208.60000000000227,16.33287627302336,1.1157687790186077,-0.11468643564216707
209.80000000000229,16.36917000000007,1.1210885422407857,-0.11581999705621193
211.0000000000023,16.40580749749931,1.1262486687267708,-0.11698785523268729
212.20000000000232,16.44254439980884,1.1315049927062062,-0.11715803429269789
213.40000000000234,16.47888092281224,1.1351492129625185,-0.11845958401943735
214.60000000000235,16.51582855000952,1.1431901860128373,-0.11909422597253316
215.80000000000237,16.552145062923408,1.1457907143788648,-0.1200169113475078
217.0000000000024,16.58874090294661,1.1544916888601473,-0.12119868231873321
218.2000000000024,16.625331374196083,1.1590114487671384,-0.12255473429910912
219.40000000000242,16.661711963939034,1.1647745815516657,-0.1239438219798834
220.60000000000244,16.698548369184504,1.1704994314920918,-0.1253519499768072
221.80000000000246,16.73505146810465,1.1769437422840414,-0.12688128430710366
223.00000000000247,16.771481025109026,1.1829104086554632,-0.1283006279657326
224.2000000000025,16.807957493361034,1.1874580960943317,-0.12920911124094792
225.4000000000025,16.844538499163406,1.1947124297698766,-0.12989880865659575
226.60000000000252,16.88097440438479,1.197240303635559,-0.1320285313517675
227.80000000000254,16.91694196996312,1.20342758058025,-0.1341107140430089
229.00000000000256,16.9538877213259,1.2086757077191563,-0.13556755281096144
230.20000000000258,16.989742815009105,1.214983027449173,-0.1382449502400247
231.4000000000026,17.026196114061925,1.2167302904310855,-0.13958697543406995
232.6000000000026,17.06210178249389,1.2220373457532412,-0.14107221344092435
233.80000000000263,17.09943877555539,1.226151385843626,-0.1429472253133035
235.00000000000264,17.13567276156648,1.2310793960326407,-0.14550490548817363
236.20000000000266,17.17108999337551,1.2348901250197493,-0.14743106274336704
237.40000000000268,17.208191007427068,1.2400050651758547,-0.1492944178540525
238.6000000000027,17.244387632616103,1.240309754487376,-0.1518057102810637
239.8000000000027,17.28095829793771,1.244954748010034,-0.15394292201164772
241.00000000000273,17.317165314991406,1.2447027025935524,-0.15729601483256594
242.20000000000275,17.353734830888655,1.2496945654336302,-0.15901688376108636
243.40000000000276,17.38950602479515,1.2513980987530862,-0.16057718916364472
244.60000000000278,17.426168119138836,1.2536432628594218,-0.16271894353370397
245.8000000000028,17.462535073846247,1.253891836294859,-0.16614247148847516
247.0000000000028,17.49877413480867,1.2568307766338807,-0.16821884064967918
248.20000000000283,17.53529840095058,1.2578123003846973,-0.17125385565844553
249.40000000000285,17.57156706979248,1.2590927047040525,-0.17342663937371228
250.60000000000286,17.607851674111213,1.2594864901840386,-0.17671250983420128
251.80000000000288,17.644165948405735,1.2584003725105797,-0.18050626501476152
253.0000000000029,17.6792620495539,1.258345726275917,-0.18515505789011133
254.20000000000292,17.716367276229985,1.2576293752447156,-0.18902527553713622
255.40000000000293,17.752564212253773,1.2561228007546856,-0.19150070820610843
256.600000000003,17.788869555502725,1.2553863144289186,-0.1948813025457281
257.80000000000297,17.825456353344357,1.2534962586468144,-0.19854110386558332
259.00000000000296,17.861662367886282,1.2546640490934515,-0.20188906652411598
260.200000000003,17.897450340111728,1.2529677613966568,-0.20539383021945934
261.40000000000305,17.933979645880402,1.2497690406225062,-0.20869006971903037
262.60000000000304,17.970227878347288,1.2515201484596459,-0.2123321811571266
263.800000000003,18.00636557090053,1.2543852459954845,-0.215702567677015
265.00000000000307,18.042728713621607,1.2529408209235884,-0.21892799106527905
266.2000000000031,18.07883832533052,1.2523220833962498,-0.2223082248311159
267.4000000000031,18.11515008697921,1.2511879287640117,-0.2265162165334833
268.6000000000031,18.1514789863648,1.2533542439042573,-0.23130768506498667
269.80000000000314,18.187427263265125,1.2538203434465227,-0.23551392882724453
271.0000000000032,18.223771995661313,1.2540338197734688,-0.2400690671475436
272.2000000000032,18.259882047422085,1.2541541136900285,-0.244825476962808
273.40000000000316,18.295927832916448,1.253742754453521,-0.2494251723982508
274.6000000000032,18.332427681352595,1.2591377622217312,-0.25408170339458946
275.80000000000325,18.368606047658265,1.2570148890393091,-0.2601042665410169
277.00000000000324,18.404891291083107,1.2601672858237136,-0.26429090704195835
278.20000000000323,18.441151388197632,1.257839739496776,-0.27012298124986156
279.4000000000033,18.477132067767954,1.2575514349000667,-0.2758625105881123
280.6000000000033,18.513455976102314,1.2580105536666704,-0.2835352810373446
281.8000000000033,18.549895845708477,1.2581583980421633,-0.28933024145467856
283.0000000000033,18.585500042920483,1.259084433337823,-0.2950706829288934
284.20000000000334,18.62247074780674,1.2540779386958807,-0.30190573695065037
285.4000000000034,18.65871177851593,1.2559739940553527,-0.3099681673817507
286.6000000000034,18.694880915293204,1.2542788048065205,-0.3195587774275319
287.80000000000337,18.731168502326067,1.2503112437128727,-0.32655156033633315
289.0000000000034,18.767510367931994,1.249810461056678,-0.33399440046838347
290.20000000000346,18.803994666012127,1.2460650785535683,-0.3420670325505335
291.40000000000344,18.84029874039335,1.2419460714603794,-0.3515438122002661
292.60000000000343,18.876598660994773,1.2390131359521324,-0.3628953179686438
293.8000000000035,18.912615210986143,1.2329702376829954,-0.37304344424305924
295.0000000000035,18.94905209448083,1.2290051980171743,-0.38474602489304255
296.2000000000035,18.985377171480394,1.2257170098693002,-0.39703890563180044
297.4000000000035,19.021775220989454,1.216058916153763,-0.4089000224465411
298.60000000000355,19.05784769068176,1.2072828583607442,-0.42180126394247086
299.8000000000036,19.09419416981067,1.198374752965419,-0.43335149050524535
301.0000000000036,19.130949345962044,1.1888240411404656,-0.44670135535185906
302.20000000000357,19.16664381838767,1.1789356551694115,-0.46070967781351646
303.4000000000036,19.203106083182643,1.1700286336448045,-0.47586332637619533
304.60000000000366,19.239505429921834,1.15872959843207,-0.4909893202413502
305.80000000000365,19.275792572986795,1.1496678944698495,-0.5070996140237987
307.00000000000364,19.312017205714348,1.1379991316172917,-0.5249095442777776
308.2000000000037,19.34844056304978,1.1262646825769573,-0.5436349808911638
309.40000000000373,19.384638796687568,1.1145825995644711,-0.5618805500065465
310.6000000000037,19.421062697003286,1.103963435260796,-0.5804884235647467
311.8000000000037,19.45739427182537,1.091451612469646,-0.5991072310610313
313.00000000000375,19.4937151803873,1.0807084740905966,-0.6187081935977843
314.2000000000038,19.53033278621692,1.071938064445771,-0.6389128879664074
315.4000000000038,19.566614928634262,1.0601699742188138,-0.6593903957877547
316.6000000000038,19.60298473422732,1.0539117571352532,-0.6806978473993084
317.8000000000038,19.638935924954424,1.0458709307921885,-0.701960384551461
319.00000000000387,19.675502214246073,1.0386648533408525,-0.7241981535739828
320.20000000000385,19.711965510621457,1.031860320138853,-0.7468680193258246
321.40000000000384,19.748668168729058,1.0272699560758718,-0.7695301534091183
322.6000000000039,19.78479020259874,1.0221429815363365,-0.7926913529602939
323.80000000000393,19.821569460766685,1.0190594341338892,-0.8160873596773426
325.0000000000039,19.857774431964877,1.0171207261546347,-0.8386192469232538
326.2000000000039,19.894313244534562,1.0160222836880297,-0.8608253626669922
327.40000000000396,19.930752185460815,1.0181917841631762,-0.8828318914653157
328.600000000004,19.966890422908683,1.0218511770294532,-0.9049232895717925
329.800000000004,20.0036325390283,1.0260058824481644,-0.9277974628230643
331.000000000004,20.040030929124306,1.0303099183283317,-0.9523662230461918
332.200000000004,20.07633812403745,1.0397548911054997,-0.9751270214375709
333.40000000000407,20.113093569699284,1.0470101443505742,-0.9980962981308541
334.60000000000406,20.149715869406403,1.0528339558486344,-1.0215774712340018
335.80000000000405,20.186514480325997,1.0629539402007098,-1.0455537339197454
337.0000000000041,20.222919514458987,1.073058887146451,-1.0689298232999631
338.20000000000414,20.259416678190405,1.0836260706862184,-1.0921946447925595
339.4000000000041,20.29627389474982,1.0949980643561321,-1.1164869012015255
340.6000000000041,20.332814151119116,1.1091071915263002,-1.1405982128869372
341.80000000000416,20.369385117307484,1.1250085683733206,-1.163823079439405
343.0000000000042,20.40621919728666,1.1387494679064356,-1.1873867572657009
344.2000000000042,20.442950658059004,1.153606103896074,-1.2116342269413098
345.4000000000042,20.479700624305373,1.1718120190397263,-1.2366349926638067
346.60000000000423,20.516255710222428,1.1858568986444031,-1.261372278055953
347.8000000000043,20.553200356918286,1.2065639519156321,-1.2856265748737092
349.00000000000426,20.58958578455418,1.2245225090778695,-1.3115535723613365
350.20000000000425,20.62657019383492,1.2432520475958604,-1.339135688438632
351.4000000000043,20.663558418156658,1.263131178803899,-1.365087081416433
352.60000000000434,20.700345751941228,1.2830082908870837,-1.3920054775761335
353.80000000000433,20.737226451097758,1.3039185064107284,-1.4205788944583002
355.0000000000043,20.774162122413617,1.3248312433657887,-1.4492732754486037
356.20000000000437,20.81080625363943,1.3469814713523696,-1.4772231299973275
357.4000000000044,20.847635756953032,1.369957624268003,-1.5065545037988834
358.6000000000044,20.884625099726964,1.3968108765594536,-1.5366949476263896
359.8000000000044,20.921506986760036,1.418628962002098,-1.5681581557718989
361.00000000000443,20.95879920067451,1.4451804319542527,-1.5997806302545245
362.2000000000045,20.995617397756423,1.4711277841582164,-1.6326581325952096
363.40000000000447,21.032557364899223,1.497389496788329,-1.6666647626044289
364.60000000000446,21.069107051976786,1.522461990034749,-1.7017316147343409
365.8000000000045,21.106568132478305,1.552383759422482,-1.7380523106218333
367.00000000000455,21.143498163264695,1.5807657166504505,-1.7760830209456442
368.20000000000454,21.180645234213227,1.6078534954651282,-1.8158051202643195
369.4000000000045,21.21768949305552,1.6351658747385946,-1.8555791103987054
370.60000000000457,21.25495634708616,1.6626261304057885,-1.8960730261590442
371.8000000000046,21.291984975712076,1.6871138534218233,-1.9369122231872367
373.0000000000046,21.32917000000015,1.7124550871613193,-1.979280048401932
374.2000000000046,21.366338359652318,1.7303823673125978,-2.02342501663483
375.40000000000464,21.403371298033196,1.748784634495252,-2.070462074354011
376.6000000000047,21.440393230719568,1.7656212787891221,-2.1161251658997795
377.8000000000047,21.477534614865426,1.7746433691972512,-2.1626654269453605
379.00000000000466,21.514715954730242,1.7795814239191197,-2.209662192923923
380.2000000000047,21.551875072912697,1.7788776681514666,-2.257350488215631
381.40000000000475,21.589231306518673,1.7734225190610493,-2.306433097803924
382.60000000000474,21.62640404837602,1.760032708023297,-2.357622889192344
383.80000000000473,21.663705376659617,1.7361566123739927,-2.4091344283076657
385.0000000000048,21.700620842957438,1.70650520090008,-2.4587560179396366
386.2000000000048,21.73814513406498,1.6654623324177267,-2.507953459468346
387.4000000000048,21.774636805312543,1.612901514639987,-2.5549682357311587
388.6000000000048,21.812202516889418,1.556256480498078,-2.5997420264399542
389.80000000000484,21.848578642332935,1.4882784900170376,-2.643364419484149
391.0000000000049,21.88662121731295,1.405512736129194,-2.6875556068012667
392.2000000000049,21.92369102158219,1.3156121752730687,-2.7287322138293906
393.40000000000487,21.960554120596136,1.2169734883130638,-2.7674308045190097
394.6000000000049,21.997914530372846,1.113170420831993,-2.8043564844781677
395.80000000000496,22.03519332662683,1.0017330583498916,-2.838542478401079
397.00000000000495,22.072003584123927,0.893734264353192,-2.867727275700509
398.20000000000493,22.10907621530436,0.7824303325523287,-2.895479581152852
399.400000000005,22.14648028748163,0.6781746211274207,-2.918621586113048
400.600000000005,22.183365029316047,0.5794396295430433,-2.9389531980388
401.800000000005,22.220583638180855,0.4921715003126459,-2.955950270135877
403.000000000005,22.257766772087443,0.4097161611421827,-2.97040596300741
404.20000000000505,22.29485257800866,0.34812522787414557,-2.9822437675494538
405.4000000000051,22.331889573669507,0.29511976197874557,-2.991774675593716
406.6000000000051,22.36916969860551,0.246637705601908,-3.001009753607439
407.80000000000507,22.406303744877984,0.21094676312356953,-3.0083538527984874
409.0000000000051,22.443659400659616,0.1775177267502328,-3.012987768741837
410.20000000000516,22.480945609329467,0.15508316070511152,-3.020393331609502
411.40000000000515,22.518004295457533,0.13188835044303704,-3.0250707922176954
412.60000000000514,22.555327227228872,0.11279225040184548,-3.0308909744366073
413.8000000000052,22.592565961915255,0.09831570652526289,-3.0352762331177843
415.00000000000523,22.63010867891385,0.08266801453272987,-3.0388708039915935
416.2000000000052,22.667144145813975,0.06928596324274316,-3.0433210635260703
417.4000000000052,22.70462297524081,0.05641184648065822,-3.0494117150729907
418.60000000000525,22.742124619912683,0.04287916908303835,-3.0527077106276397
419.8000000000053,22.77913821131361,0.034512818601985185,-3.0561527007064884
421.0000000000053,22.816770156552835,0.024625571065372,-3.059371896654988
422.2000000000053,22.854268974303658,0.01313538966105865,-3.063286332249324
423.4000000000053,22.89160395682493,0.006692479335120627,-3.067746348992606
424.60000000000537,22.92895342424718,0.0009555812589199242,-3.0712490273841326
425.80000000000535,22.96636189090172,-0.00849790390530325,-3.076964065137311
427.00000000000534,23.003800567259617,-0.012449095404671207,-3.0814775688247495
428.2000000000054,23.04120252203745,-0.01972896753434039,-3.084595660059403
429.40000000000543,23.079074956861273,-0.02595401620658655,-3.088200837481643
430.6000000000054,23.11639533445911,-0.032057531667162076,-3.0914101639931717
431.8000000000054,23.154050862800645,-0.03720000638766208,-3.0947085744585205
433.00000000000546,23.191655359400194,-0.043039510406632786,-3.0988247729372067
434.2000000000055,23.22913965393902,-0.046195202023246784,-3.1022484961572028
435.4000000000055,23.266738768897767,-0.047692632133947255,-3.1058761859465305
436.6000000000055,23.30408682392226,-0.051848908386685766,-3.109017780434116
437.8000000000055,23.3421142714634,-0.052625834573252206,-3.1126317846986424
439.00000000000557,23.37979907217795,-0.056751450477094734,-3.1159653132685103
440.20000000000556,23.417618806392262,-0.05816911026293092,-3.120961227698501
441.40000000000555,23.45504489322123,-0.060482365897532864,-3.125055096182937
442.6000000000056,23.492903838374968,-0.05921526370839536,-3.12860584708762
443.80000000000564,23.530553726842165,-0.05777586082082675,-3.1313806108993347
445.0000000000056,23.568582526745086,-0.059988284750505994,-3.134996620314413
446.2000000000056,23.60616802398529,-0.057718558808926845,-3.1377007666929106
447.40000000000566,23.6438575915015,-0.05773333825615001,-3.1405778946415164
448.6000000000057,23.681697546882017,-0.05628138279916017,-3.1426770078675355
449.8000000000057,23.719360937300102,-0.055556917954974194,-3.1467105137818407
451.0000000000057,23.75774293891835,-0.05184696048024251,-3.1507930645608595
452.20000000000573,23.795432102777504,-0.05090887785350873,-3.1532200207786696
453.4000000000058,23.833352130351322,-0.04609607558469597,-3.1565011922318673
454.60000000000576,23.871172493841996,-0.043631813485140336,-3.1598362035096086
455.80000000000575,23.909042237537594,-0.040058252545964734,-3.161251210495663
457.0000000000058,23.94696095835883,-0.03681792265836181,-3.1647198541755355
458.20000000000584,23.984937129766376,-0.03447516024492914,-3.168439252499922
459.40000000000583,24.022954939078414,-0.02971060521252178,-3.1710536116377543
460.6000000000058,24.06086509947755,-0.02409087092988682,-3.174908687051203
461.80000000000587,24.098848342659437,-0.01987951442088498,-3.176605152131595
463.0000000000059,24.136825611427934,-0.014859102593514972,-3.179369727006526
464.2000000000059,24.174922519153885,-0.009823512188498862,-3.1821648709272994
465.4000000000059,24.21293145518564,-0.003932176858596037,-3.1835046144351855
466.60000000000593,24.250959558968617,4.274862969766424e-05,-3.18553539375167
467.800000000006,24.289264366939914,0.0036274275512939713,-3.187156089211994
469.00000000000597,24.326969938085117,0.009459795741228572,-3.1913256287115757
470.20000000000596,24.365428254937836,0.012737645923552865,-3.195227233556552
471.400000000006,24.403128595752378,0.02055353092122747,-3.196533189416377
472.60000000000605,24.44145371134961,0.023269126856711342,-3.1984576656114663
473.80000000000604,24.479556831333397,0.03155656586122091,-3.2005791110261628
475.000000000006,24.51758493484611,0.03421913512657482,-3.2034860796807747
476.20000000000607,24.555965357205736,0.040088268076919675,-3.2050315979922024
477.4000000000061,24.59415330520231,0.04406982874717014,-3.206802854192347
478.6000000000061,24.632092709787155,0.04991487577727072,-3.2092266857906
479.8000000000061,24.670645444287764,0.05496071287973847,-3.2113930802500126
481.00000000000614,24.70825858021119,0.05800207069568142,-3.2138155895624445
482.2000000000062,24.747074706394876,0.06365313969928854,-3.2163047300909158
483.4000000000062,24.78516202498131,0.06707659358574491,-3.2177293598337693
484.60000000000616,24.823303332524187,0.06983813849145237,-3.2191807210098435
485.8000000000062,24.861755220468797,0.07356634834603226,-3.220805362764956
487.00000000000625,24.89992791992656,0.07598751620795352,-3.222253419221772
488.20000000000624,24.93817060037717,0.07732083738226891,-3.2240111608122777
489.40000000000623,24.976766864503418,0.0825210106395653,-3.2269449779878663
490.6000000000063,25.015273003858347,0.08513719665778252,-3.228983390555081
491.8000000000063,25.053478754305985,0.08697928521715936,-3.2303461602845016
493.0000000000063,25.091725902204068,0.09064683223695313,-3.232598367364916
494.2000000000063,25.130317757359627,0.09367327677424164,-3.233926564808394
495.40000000000634,25.168633979338782,0.0949545637036815,-3.23540465618876
496.6000000000064,25.206687777051563,0.0968344143495532,-3.237073151403669
497.8000000000064,25.245435394795916,0.09731355994212021,-3.239447233289543
499.00000000000637,25.284068548473854,0.10354808001623139,-3.240828588791048
500.2000000000064,25.322398306948692,0.10430615996190462,-3.24234207214141
501.40000000000646,25.360869056097822,0.10789661542997098,-3.2441261832752244
502.60000000000645,25.39926643728791,0.10758133543439952,-3.2447221667114894
503.80000000000643,25.437668652090856,0.11208785409068422,-3.245720481731564
505.0000000000065,25.476260002282554,0.11277540219183968,-3.247207113382001
506.2000000000065,25.51477656115076,0.11484078563474753,-3.2486576776320573
507.4000000000065,25.553309938341197,0.11667430593296113,-3.2499714675750537
508.6000000000065,25.591884524029602,0.12025053413360243,-3.2515120517070084
509.80000000000655,25.63039628375326,0.11908056960617586,-3.2529199962670083
511.0000000000066,25.668943031566506,0.11992729611255437,-3.2547961657959807
512.2000000000066,25.70796581525786,0.12323479405828985,-3.2553861579304035
513.4000000000066,25.74646495527683,0.12273673509095784,-3.257010429172178
514.6000000000066,25.784781408124942,0.12434551404141514,-3.2579079806340414
515.8000000000067,25.82335960724472,0.12636401553435528,-3.2593859348695093
517.0000000000066,25.861689888483856,0.12822070388872198,-3.2607156661942804
518.2000000000066,25.9005736633555,0.1309185967648534,-3.2621352695836974
519.4000000000067,25.939358087940676,0.13010038681573666,-3.2639474459444546
520.6000000000067,25.977796173725554,0.134369867662687,-3.2652324973583946
521.8000000000068,26.016427115953064,0.12969744650815374,-3.2665460372266235
523.0000000000067,26.054713319031855,0.1293287821770308,-3.266857890163176
524.2000000000068,26.093775824495474,0.13203204739217345,-3.2688893193969375
525.4000000000068,26.132533642952623,0.13154542567971528,-3.270756520799409
526.6000000000067,26.171195640756444,0.13288917329491556,-3.270950150298963
527.8000000000068,26.209678171357805,0.13324860454101284,-3.272402653734978
529.0000000000068,26.24849587936563,0.13175695597029424,-3.273902847475231
530.2000000000069,26.287029379247276,0.13213622028204153,-3.2743919030459194
531.4000000000069,26.325586342848407,0.13235900818584834,-3.2752526174051493
532.6000000000068,26.364315942232015,0.1326396113723074,-3.2769047945722267
533.8000000000069,26.402871295636942,0.13183623358491503,-3.2768764615420247
535.0000000000069,26.44186899870698,0.13264642640478908,-3.279086901524955
536.2000000000069,26.4807004273257,0.13326539016586292,-3.2802712447130498
537.4000000000069,26.51942077798861,0.12992720381112943,-3.280497048832973
538.600000000007,26.558212593345125,0.12863007626294376,-3.280487450444416
539.800000000007,26.597223679038734,0.13349942280775995,-3.281821770877094
541.000000000007,26.635629686653502,0.1379280398435081,-3.2833500143523104
542.200000000007,26.674618231070706,0.1447559822996216,-3.284746286525672
543.400000000007,26.713129206139126,0.14933823862439932,-3.2863132846851304
544.6000000000071,26.752128459780764,0.15469091779770117,-3.2868124631872364
545.800000000007,26.79079111610326,0.15935833213825856,-3.2874923855645264
547.000000000007,26.829465848773523,0.1636216646325357,-3.2888289224297207
548.2000000000071,26.868301088362017,0.16788363921932503,-3.2901325864315414
549.4000000000071,26.907340188119083,0.17066943008832736,-3.291447362973787
550.6000000000072,26.94612801390101,0.17207516242003917,-3.2925262625884972
551.8000000000071,26.98494542110538,0.17577660415896745,-3.2927577079013735
553.0000000000072,27.02374018096709,0.17444948978462627,-3.2948730139120057
554.2000000000072,27.062622123718533,0.1773526880781897,-3.295043678217385
555.4000000000071,27.10160136910423,0.1815958515740721,-3.2963869855917194
556.6000000000072,27.140808812591487,0.18276191584574253,-3.2968784594522775
557.8000000000072,27.17968643058059,0.18423094900936077,-3.2977010333159322
559.0000000000073,27.21825682777343,0.1835958631701493,-3.2990308539226643
560.2000000000073,27.25729124994747,0.18563517357831327,-3.300214338257415
561.4000000000073,27.296316331977312,0.18772765370762712,-3.3003734095161996
562.6000000000073,27.335212294279486,0.19498704021244873,-3.301665730766506
563.8000000000073,27.374304920001563,0.19356140445003844,-3.301654663119699
565.0000000000073,27.413354638795482,0.19531326250277092,-3.3029644582220916
566.2000000000073,27.45250395156912,0.19539888926635074,-3.304468162109223
567.4000000000074,27.490986845833167,0.19488689297929152,-3.304390328393877
568.6000000000074,27.5305360796501,0.19597432557967376,-3.304493015841728
569.8000000000075,27.56923293409332,0.19888936861963424,-3.3057199948317777
571.0000000000074,27.608648261148847,0.19642644716682645,-3.3063368881269533
572.2000000000074,27.647538756405382,0.19732281401689278,-3.307050274415616
573.4000000000075,27.686589228502854,0.1954276213049706,-3.3083548622121874
574.6000000000074,27.725748154068356,0.1950340415415608,-3.3089945158150402
575.8000000000075,27.765018195362668,0.19537554319082662,-3.309666953293707
577.0000000000075,27.804131159919475,0.19364656532062363,-3.310710525447173
578.2000000000075,27.843195713269985,0.18951773662025628,-3.3113379181040585
579.4000000000076,27.88234517488679,0.1851376879656399,-3.312232763713066
580.6000000000075,27.92187674480243,0.17690869174176194,-3.3135355746609534
581.8000000000076,27.960879102819423,0.17530364642708252,-3.3157273975383723
583.0000000000076,28.00003630702238,0.1666654834016421,-3.316259080762089
584.2000000000075,28.03923419579355,0.1642942548479942,-3.315275556011167
585.4000000000076,28.0784943829629,0.15242543932033437,-3.316579736868213
586.6000000000076,28.117813210594715,0.15251251659285736,-3.316804335628043
587.8000000000077,28.15701356152589,0.14333668755206386,-3.3180040927284917
589.0000000000077,28.196467919161563,0.14560058143042354,-3.318437314334435
590.2000000000077,28.23580729373515,0.13711542079386208,-3.3193492971713656
591.4000000000077,28.275125662932304,0.1343733104590361,-3.3206442891857426
592.6000000000078,28.314372031103083,0.1307232506732383,-3.320707536006254
593.8000000000077,28.353912968847332,0.12936316550223004,-3.3219500882283763
595.0000000000077,28.393282141691394,0.12661094859607824,-3.3231848277350036
596.2000000000078,28.43247801769037,0.11821954488730868,-3.3232707394305505
597.4000000000078,28.47196485679846,0.11589499680775583,-3.3233899944253116
598.6000000000079,28.51131655118903,0.11436549773792892,-3.3246519512549026
599.8000000000078,28.550674059719544,0.10850491721831457,-3.3268973239913975
601.0000000000078,28.59001419411376,0.1061548486626751,-3.326874824519466
602.2000000000079,28.62943241640305,0.10125279791022845,-3.3282098289225632
603.4000000000078,28.668881428266126,0.10182927323709134,-3.328212509239988
604.6000000000079,28.7081420771964,0.09746043801224524,-3.329529005572631
605.8000000000079,28.747967812740296,0.0929403260584949,-3.329534384545325
607.000000000008,28.787628676430863,0.08827781843289584,-3.3308422598546628
608.200000000008,28.82676735925623,0.08387199021697711,-3.3309958683850605
609.4000000000079,28.86626045298711,0.0784380406510381,-3.3322656202381307
610.600000000008,28.905984321175385,0.07590418825676748,-3.3326586834190493
611.800000000008,28.94546743024135,0.0687410295494586,-3.3335874172377653
613.000000000008,28.98505820474797,0.06453247308670473,-3.332973832834157
614.200000000008,29.02424443317455,0.06010680541631275,-3.3342460070765187
615.400000000008,29.064490521180794,0.05783594833227035,-3.334325222840072
616.6000000000081,29.103694799524426,0.05306883827798026,-3.3355562707747453
617.8000000000081,29.143122785098022,0.04937830520558739,-3.335569749676969
619.0000000000081,29.182762527593564,0.04212740847071195,-3.3368783501001724
620.2000000000081,29.22227826120941,0.037975917174426055,-3.3368923513698405
621.4000000000082,29.262069082128303,0.03406874226612966,-3.338193825420343
622.6000000000081,29.301871432132923,0.029809491534273036,-3.3389936124688466
623.8000000000081,29.341077133382598,0.02647745442241556,-3.3388180165439416
625.0000000000082,29.38046117437452,0.022673980620466994,-3.3401517354956423
626.2000000000082,29.420571348904733,0.015428040341781468,-3.3401598346272157
627.4000000000083,29.460055445058302,0.01652658146870456,-3.34015153120533
628.6000000000082,29.499305656066458,0.010476632779738981,-3.341469107606351
629.8000000000083,29.538969890596334,0.008536304929489091,-3.3414692973635662
631.0000000000083,29.578649534849376,0.006118777937172526,-3.342787958510667
632.2000000000082,29.618218475560035,0.0006353460670069921,-3.342802077559722
633.4000000000083,29.658080166816326,-0.0008141655204068066,-3.3441116431534503
634.6000000000083,29.697384902641026,-0.006343619656470345,-3.3441087527012305
635.8000000000084,29.737019284879025,-0.007727290979007373,-3.344709143574108
637.0000000000084,29.776735808303464,-0.010766746320384435,-3.344753674787634
638.2000000000083,29.816269069162633,-0.016259459071826576,-3.3460586644958377
639.4000000000084,29.855433653429643,-0.02002416747290936,-3.34607166615954
640.6000000000084,29.89580164911631,-0.021041672616989526,-3.34737152638935
641.8000000000084,29.93546417932261,-0.025633043741055905,-3.3473925975555456
643.0000000000084,29.97518744074683,-0.027178094585388557,-3.3486728595572486
644.2000000000085,30.01458826624029,-0.031473380199264156,-3.34871160443873
645.4000000000085,30.05440008587576,-0.03290831529028604,-3.3501203304452805
646.6000000000085,30.094189738215206,-0.038279000416449493,-3.350026995117016
647.8000000000085,30.133614287040345,-0.038846962747719926,-3.3510379582437024
649.0000000000085,30.17330837216727,-0.04459364495277196,-3.3513386251502526
650.2000000000086,30.212602621235302,-0.043663735211459054,-3.3512980057262016
651.4000000000085,30.25258559479217,-0.049528857919192815,-3.3524312529420723
652.6000000000085,30.29252707728559,-0.05314033989744238,-3.352668393031293
653.8000000000086,30.332024380537288,-0.05790353345691068,-3.3540282720956744
655.0000000000086,30.3715187067429,-0.06077419560474029,-3.3539802843166897
656.2000000000087,30.41145454739032,-0.06007437958185302,-3.353959602948648
657.4000000000086,30.450938241000372,-0.06667181223118068,-3.3552954772869503
658.6000000000087,30.491067622962248,-0.062158435594603434,-3.3566512312812464
659.8000000000087,30.53035159313685,-0.07219992397177921,-3.355261626422979
661.0000000000086,30.570277761127645,-0.07110068379228363,-3.3552882434905915
662.2000000000087,30.610157206014634,-0.07287506055055504,-3.356358662543677
663.4000000000087,30.649532346439543,-0.07804670768877098,-3.3566098046273187
664.6000000000088,30.689270188164798,-0.0806908591859612,-3.3566097396635155
665.8000000000088,30.729007594479157,-0.08557485677504761,-3.356297538488577
667.0000000000088,30.768808246345106,-0.08362401226056093,-3.3576341776777054
668.2000000000088,30.80856953292267,-0.0884449507909233,-3.356628904252549
669.4000000000088,30.84866190461442,-0.0917831577125301,-3.3579303875833304
670.6000000000088,30.88780775356574,-0.09652495574574482,-3.3579304732995823
671.8000000000088,30.927956204941648,-0.09478782468178437,-3.358484622640039
673.0000000000089,30.967461101778184,-0.09672505774571638,-3.359938046198675
674.2000000000089,31.007126323494326,-0.09985753827921995,-3.359921182169746
675.400000000009,31.04701995284377,-0.10395091417281765,-3.3612433555274857
676.6000000000089,31.08664697512691,-0.10335697530168897,-3.361219546764312
677.8000000000089,31.126556441012962,-0.10877783369825167,-3.361129806075098
679.000000000009,31.16615352063107,-0.11279459330797614,-3.363236633269689
680.2000000000089,31.20573738246866,-0.11418527199437278,-3.3630845077026477
681.400000000009,31.24556861067396,-0.11490746353295744,-3.363908351766364
682.600000000009,31.285761398692678,-0.11897493143472104,-3.363200568383174
683.800000000009,31.325386609319203,-0.11575689219655017,-3.363545397274847
685.0000000000091,31.365302069917348,-0.11552939105158622,-3.364513788584169
686.200000000009,31.405114881892075,-0.11894814501289641,-3.3648395935168027
687.4000000000091,31.444783225708555,-0.11696747084747772,-3.3658316665589005
688.6000000000091,31.48443560023944,-0.12153834350237291,-3.36532339228612
689.800000000009,31.524377463046964,-0.12451171260913307,-3.3644629202806744
691.0000000000091,31.564287406258483,-0.1270975971354633,-3.365817230496086
692.2000000000091,31.60393844919627,-0.13002800279238835,-3.365831201989348
693.4000000000092,31.64380534921418,-0.1301439587079094,-3.367040434257273
694.6000000000092,31.68352703584637,-0.1320619597230306,-3.368458778000548
695.8000000000092,31.723497677418607,-0.12866019405998497,-3.368457232439834
697.0000000000092,31.76328113831096,-0.13463280485513884,-3.3694555628957366
698.2000000000093,31.803174999157655,-0.1340886536443069,-3.3688062575106184
699.4000000000092,31.84331369614693,-0.1368409628984164,-3.368461126974381
700.6000000000092,31.882916256604325,-0.13751583405410228,-3.3684815054475017
701.8000000000093,31.923006434785687,-0.13868973959032171,-3.3708424907683168
703.0000000000093,31.962662051612632,-0.14231559438865293,-3.370746147953128
704.2000000000094,32.00240917540162,-0.14329540938106833,-3.369753623201679
705.4000000000093,32.04261480050606,-0.14283325306041972,-3.369770117110889
706.6000000000093,32.08263149885235,-0.14607184704151432,-3.369771284125274
707.8000000000094,32.122482308208824,-0.14870415258548286,-3.371180893553386
709.0000000000093,32.162265766490464,-0.15398683644886813,-3.3710905764657184
710.2000000000094,32.202234991391784,-0.15518774422807402,-3.371089915742089
711.4000000000094,32.24199237384841,-0.1557179057949396,-3.371056803884037
712.6000000000095,32.28209652019265,-0.1610674646329695,-3.3723982442515603
713.8000000000095,32.321824574601806,-0.16298299487171342,-3.3724098121218615
715.0000000000094,32.36232029152865,-0.1637209292004962,-3.37237667072025
716.2000000000095,32.402393326886546,-0.16546235581305657,-3.3737065984242998
717.4000000000095,32.44249044708942,-0.17043598183922049,-3.3737200581861333
718.6000000000095,32.482544243710514,-0.17665656269878793,-3.3737197435399953
719.8000000000095,32.522463530124995,-0.1741957529309084,-3.373650855544839
721.0000000000095,32.5625611851616,-0.17484238995653367,-3.3743892370253668
722.2000000000096,32.60290586639337,-0.1811761228530404,-3.3737094210482432
723.4000000000096,32.64317772675651,-0.17753868082402846,-3.373724157808847
724.6000000000096,32.683263012766005,-0.18155936520461147,-3.374968073110429
725.8000000000096,32.72335183259789,-0.18226399979322538,-3.3751235658170327
727.0000000000097,32.76331255411269,-0.18533621559652724,-3.376359475025421
728.2000000000096,32.803757649343495,-0.18951300403883797,-3.377397046632202
729.4000000000096,32.84370340488149,-0.18783967684429026,-3.376369252271975
730.6000000000097,32.883904491968856,-0.19164649274717416,-3.3763601081112644
731.8000000000097,32.924154915918606,-0.19381235871369418,-3.3763600661274245
733.0000000000098,32.964463850924304,-0.19431509094504484,-3.3763600332125767
734.2000000000097,33.00438831684107,-0.19611480250639746,-3.376353606558804
735.4000000000098,33.04437578271164,-0.19614052123947312,-3.3776162945806925
736.6000000000098,33.08446308622715,-0.1984766292762381,-3.3776716059253826
737.8000000000097,33.12482535492823,-0.20240167037681944,-3.3772042969064926
739.0000000000098,33.16507501850597,-0.20606552757897711,-3.378000485369827
740.2000000000098,33.2052000734897,-0.20589426320678994,-3.3779997395239443
741.4000000000099,33.245570216472345,-0.209965726944628,-3.3779055019936117
742.6000000000099,33.28546843862628,-0.2129393368784065,-3.3790253473965586
743.8000000000098,33.325971806286056,-0.21376408042539286,-3.378990314589919
745.0000000000099,33.36607641208376,-0.2197691435084086,-3.379126165993453
746.2000000000099,33.406234561834374,-0.2202146053870524,-3.3803134678851836
747.4000000000099,33.446342632411785,-0.2214668584568229,-3.3802197164045173
748.6000000000099,33.486047687021156,-0.22430065448293712,-3.381620515984416
749.80000000001,33.527085840957234,-0.2273493990656248,-3.380936881039487
751.00000000001,33.567172412164325,-0.22711948303176888,-3.3806319073919604
752.20000000001,33.60766114935231,-0.2312058571244151,-3.3811626260638556
753.40000000001,33.6478289165477,-0.23534600716409848,-3.3819508269436773
754.60000000001,33.68806509737016,-0.23856721273535264,-3.3819499395693704
755.8000000000101,33.72810331419974,-0.24439816081885857,-3.3819499112212026
757.00000000001,33.76838674462092,-0.24465900142938013,-3.3819460862992825
758.20000000001,33.80910131268621,-0.24546877947479073,-3.383269552569187
759.4000000000101,33.84934081531486,-0.2461927936379329,-3.383269171657625
760.6000000000101,33.889439696721105,-0.2503017307043547,-3.384368989566159
761.8000000000102,33.929993491184284,-0.2532386928972259,-3.384249718897731
763.0000000000101,33.9701061643216,-0.2552763280700745,-3.3838471036796927
764.2000000000102,34.0104881230897,-0.2568584173469368,-3.384025662637992
765.4000000000102,34.05091839704269,-0.2600385195607564,-3.384259754075646
766.6000000000101,34.09116660685705,-0.2589885328369821,-3.3842598740210645
767.8000000000102,34.13190120837308,-0.26144895178035776,-3.384260853151761
769.0000000000102,34.171966787842806,-0.26652737135105076,-3.384475352045412
770.2000000000103,34.212265522668446,-0.26441408460455795,-3.38557023586153
771.4000000000103,34.25255143159396,-0.27111047960461176,-3.3855066891034378
772.6000000000103,34.29311335643254,-0.2745359973407999,-3.3868877587532618
773.8000000000103,34.33299490772119,-0.2759057402341063,-3.3863057937420185
775.0000000000103,34.37347373862263,-0.2774359004329914,-3.3855696689742456
776.2000000000103,34.413821905090025,-0.2807297754591782,-3.3855929732714585
777.4000000000103,34.45448536001164,-0.28273314201296795,-3.386896864895231
778.6000000000104,34.49478252626897,-0.2807052468412148,-3.3868899733370634
779.8000000000104,34.535395529107205,-0.286905335437627,-3.386915724159024
781.0000000000105,34.575649565550634,-0.2864064463666356,-3.3882057377802806
782.2000000000104,34.61588203079323,-0.2897588094487844,-3.388199964896484
783.4000000000104,34.65618851068939,-0.28993490365150754,-3.388197004617179
784.6000000000105,34.696417234541634,-0.28802861926441503,-3.387877268165213
785.8000000000104,34.736899502400775,-0.29334095425688256,-3.387870090147965
787.0000000000105,34.7770694882913,-0.29004412781808453,-3.3878901066471183
788.2000000000105,34.81781010904075,-0.2935530434238647,-3.38919213447062
789.4000000000106,34.858244339497496,-0.2949108110308867,-3.3891663449109686
790.6000000000106,34.89856857434602,-0.30127356662028193,-3.390489213150409
791.8000000000105,34.93893822892174,-0.3005140918501299,-3.3895486991229147
793.0000000000106,34.979406991786696,-0.2978273882071196,-3.3895202901455153