File: 01_Data/Basswood_Panel/STA/N2/30K_min/Basswood_Panel_STA_N2_30KData_220315_R2.csv
##Temp./Â°C,Time/min,DSC/(mW/mg),Mass loss/mg
49.0,10.466931008958634,0.04594669113022287,-0.02209743532010755
50.20000000000002,10.70530766623087,0.11049144122333698,-0.021537765002089593
51.400000000000034,10.838606014621803,0.1636162207515418,-0.0217457912179273
52.60000000000005,10.943693660364824,0.21115869156565847,-0.0221147442350218
53.80000000000007,11.031510099980752,0.25217691369167183,-0.021652946390948724
55.000000000000085,11.109265265487934,0.29044414476611813,-0.020887952039083668
56.2000000000001,11.180340726931844,0.32469018223750984,-0.023646550435763913
57.40000000000012,11.246498206772845,0.35833659468684786,-0.022905586571384084
58.600000000000136,11.308886387653121,0.38780277088828274,-0.02124725637186753
59.80000000000015,11.367939334659868,0.41562846454457403,-0.023445901653644796
61.00000000000017,11.423780423212884,0.44112123742025344,-0.022163348751770062
62.20000000000019,11.478377378255123,0.4673031593338261,-0.02328206079820294
63.400000000000205,11.531327645615036,0.4893985208134923,-0.02385485422303457
64.60000000000022,11.582967253568041,0.5137795978069112,-0.02299518361019537
65.80000000000024,11.633360730983352,0.5354524384304866,-0.022950480225781167
67.00000000000026,11.682290437459491,0.5562777001973627,-0.023498041131143843
68.20000000000027,11.730276726554875,0.574366606407968,-0.023687706767836936
69.40000000000029,11.777940833085637,0.5935239810817019,-0.023651170439296543
70.6000000000003,11.825414792569665,0.6135279797462119,-0.02388471239203316
71.80000000000032,11.871591863620758,0.6271752092325278,-0.0248134396877151
73.00000000000034,11.916947411736686,0.6452575756111587,-0.024861005675900216
74.20000000000036,11.962323709639149,0.6597423538370557,-0.025676212723984015
75.40000000000038,12.006595844312287,0.6762181935965063,-0.024797901142113776
76.60000000000039,12.05131001293027,0.6907830002096969,-0.024095467645779856
77.80000000000041,12.095638385116864,0.707184285601663,-0.02474716070441474
79.00000000000043,12.139507830869826,0.7213082751556477,-0.024713764304943098
80.20000000000044,12.183205111439982,0.7366704867856599,-0.025929364502745855
81.40000000000046,12.226194726348378,0.746291288081692,-0.026052911119684996
82.60000000000048,12.268790511711387,0.7605095934575161,-0.026081877596136227
83.8000000000005,12.31137512178151,0.7739447795477425,-0.026645998190945708
85.00000000000051,12.354240665785065,0.7840868791081341,-0.02701450782261894
86.20000000000053,12.395918685372056,0.7957591901334629,-0.02787100591819458
87.40000000000055,12.438874865543486,0.8071547107688191,-0.02785948143925454
88.60000000000056,12.480415896585333,0.817791557605207,-0.0291910410284002
89.80000000000058,12.52061000555477,0.8293427094208161,-0.029153790990092077
91.0000000000006,12.562901799009593,0.8409452768250761,-0.029362834715977115
92.20000000000061,12.604170856594463,0.8487005176772335,-0.030447475527073387
93.40000000000063,12.645602377124723,0.8559816705518862,-0.03218578650189219
94.60000000000065,12.6868717661846,0.8667620854314223,-0.031363644851122974
95.80000000000067,12.727564968985963,0.8735314437005213,-0.03239157797772085
97.00000000000068,12.769082411027789,0.8778026501345584,-0.033451661537376776
98.2000000000007,12.808334169679126,0.8831436600689762,-0.032193420793109606
99.40000000000072,12.8500331513888,0.8896132201213971,-0.033489732983211784
100.60000000000073,12.890727773254998,0.8942113037859057,-0.03256010343482929
101.80000000000075,12.931464824828808,0.8973946965566533,-0.03344940523573614
103.00000000000077,12.972371755872649,0.8987991074625443,-0.033683391042321986
104.20000000000078,13.01190482179678,0.9036143675419457,-0.034769993551644784
105.4000000000008,13.052564771171012,0.9056611876116395,-0.03547805861839315
106.60000000000082,13.093158531491964,0.9068082380426521,-0.03607982127661957
107.80000000000084,13.133511937697016,0.9067774857519195,-0.03647749142851264
109.00000000000085,13.173634206187241,0.9056661744108284,-0.03608587620621595
110.20000000000087,13.214631231513222,0.9056878776610586,-0.03737472628184069
111.40000000000089,13.254481703272612,0.902377958515897,-0.037425197473865524
112.6000000000009,13.294631655563554,0.902149200487168,-0.03872536019746242
113.80000000000092,13.334711055314854,0.9020600680119433,-0.038199222652717246
115.00000000000094,13.37477893782355,0.8997899219798017,-0.03812820616685286
116.20000000000095,13.41496928579528,0.9004697793756102,-0.03938650304530178
117.40000000000097,13.454951503816474,0.8965550402306894,-0.039376438352085597
118.60000000000099,13.494988532070428,0.8958336090623275,-0.040428890213277224
119.800000000001,13.534916802324009,0.8957339654529838,-0.040003615773897216
121.00000000000102,13.574771685627958,0.8954503268814261,-0.0400290150249103
122.20000000000104,13.614372403592093,0.8942711609164585,-0.039799577465124525
123.40000000000106,13.654666059839998,0.8945671203698533,-0.03870647975271213
124.60000000000107,13.69385168051236,0.8925710211273625,-0.03870725669498487
125.80000000000109,13.733500698628925,0.8941730410414714,-0.03955678827367226
127.00000000000111,13.77253964505174,0.8978768233212567,-0.040030370659122294
128.20000000000113,13.812395701533903,0.8953786006352099,-0.041426190643579996
129.40000000000114,13.852169039825334,0.8982641038782904,-0.040875462498127124
130.60000000000116,13.891226758041599,0.9002677822192081,-0.040370671292987215
131.80000000000118,13.930524333451435,0.9021919351601257,-0.04036997480693039
133.0000000000012,13.969428804037458,0.9039440309444948,-0.04062245392170638
134.2000000000012,14.008365212319491,0.9054958066805643,-0.041351692594198575
135.40000000000123,14.047154908960447,0.9085058685829639,-0.04135002155921308
136.60000000000124,14.08619392743921,0.910471559958783,-0.041350018103411657
137.80000000000126,14.124883062274476,0.9137047449106319,-0.041351703710627685
139.00000000000128,14.163778688150519,0.9174199335874802,-0.04276173816941098
140.2000000000013,14.202527723688235,0.9190018839069078,-0.042670297430605686
141.4000000000013,14.241045692304455,0.9230828856844906,-0.0426647840903831
142.60000000000133,14.279598093180743,0.9265911754469379,-0.04167631713623221
143.80000000000135,14.318184632794662,0.9308476762919496,-0.04300657108203554
145.00000000000136,14.356618304931345,0.9347630273994769,-0.04299007434333735
146.20000000000138,14.394878439862907,0.9387883129398795,-0.04298861689511302
147.4000000000014,14.433077458024224,0.9415497763786383,-0.04277928702196121
148.60000000000142,14.47175973865026,0.9481118660709578,-0.04234081616840735
149.80000000000143,14.509362214071814,0.9512425426907216,-0.042339939185013
151.00000000000145,14.547692310786323,0.9578326865762123,-0.042341409037060185
152.20000000000147,14.586303530411614,0.9606384908820303,-0.04372496897630329
153.40000000000148,14.62407296600142,0.9643747185421604,-0.04365040567263634
154.6000000000015,14.662224187236834,0.9716367400147372,-0.043649941328670394
155.80000000000152,14.700634068654695,0.976765794920571,-0.04364993900572811
157.00000000000153,14.738307956798128,0.9762170706232571,-0.04364993656726934
158.20000000000155,14.776098470608833,0.9845160951336704,-0.043649269739270746
159.40000000000157,14.81411614388146,0.9874606680690012,-0.044422947172411575
160.6000000000016,14.8521234570211,0.9898745570584309,-0.044947045530655316
161.8000000000016,14.890348066080621,0.9968340669531963,-0.04627936054458415
163.00000000000162,14.92812925282302,1.0012938303257948,-0.046280144389903466
164.20000000000164,14.965713330758337,1.0048842361976649,-0.04629823062749949
165.40000000000165,15.00356107105909,1.0108146021642797,-0.04683241118529535
166.60000000000167,15.041449799672096,1.0137299976629794,-0.046620362416284866
167.8000000000017,15.078820783995909,1.0192506180038237,-0.04661807356311298
169.0000000000017,15.116309639876006,1.0210061678314708,-0.04771246496807802
170.20000000000172,15.154382307017219,1.029125534149284,-0.047928893546844265
171.40000000000174,15.191558420870482,1.029467108558207,-0.04792995040108394
172.60000000000176,15.228986746423429,1.0358065696512448,-0.04793682895597762
173.80000000000177,15.266846453894678,1.0406521596035267,-0.04927193984389966
175.0000000000018,15.303980274319686,1.0454702775983877,-0.049581879289327446
176.2000000000018,15.341625532824056,1.0486782076500432,-0.05056049032938059
177.40000000000182,15.378966605952646,1.0533900153034492,-0.05056079172318517
178.60000000000184,15.416468292279252,1.0587740324518626,-0.05100669529137836
179.80000000000186,15.45335184310339,1.0646841719110984,-0.05191035164802926
181.00000000000188,15.490687658411778,1.0668824314479688,-0.05322121680887504
182.2000000000019,15.527901686169248,1.0733092762980294,-0.0532031318451911
183.4000000000019,15.565279466117211,1.0783778056522206,-0.052147759414973294
184.60000000000193,15.602384244470082,1.0824335713519466,-0.05188099964829407
185.80000000000194,15.639601040414071,1.086014875654143,-0.05188018269946415
187.00000000000196,15.676384363743212,1.0902389770165364,-0.05187646138475355
188.20000000000198,15.713091506389064,1.0949090706919224,-0.05279320427907397
189.400000000002,15.750376335461137,1.096115237294336,-0.05350942755350818
190.600000000002,15.787023320699793,1.1047041610776716,-0.0546469957408644
191.80000000000203,15.824036706732686,1.1080217190230992,-0.05582324356689261
193.00000000000205,15.861280238191437,1.1142832427970766,-0.055173967043827155
194.20000000000206,15.897663899209133,1.114759653105489,-0.05517156379766286
195.40000000000208,15.934691553848463,1.1200408970811946,-0.05658803920518496
196.6000000000021,15.971496095932057,1.1252973002927702,-0.056489369512645826
197.80000000000211,16.008198227550956,1.1287463888803455,-0.05701974047625713
199.00000000000213,16.04496075983746,1.131463016611093,-0.0587982061296044
200.20000000000215,16.081635521837956,1.1371724430525876,-0.058790178124308756
201.40000000000217,16.11833839579205,1.1410104031602042,-0.05878533351894877
202.60000000000218,16.15482232636344,1.1461038936781622,-0.060036293286873654
203.8000000000022,16.191605402412105,1.1532534221153794,-0.06017168667698147
205.00000000000222,16.228330969386313,1.154267296192573,-0.06142525203640403
206.20000000000223,16.265312629502553,1.1582718618832883,-0.0614293234169363
207.40000000000225,16.301827225476142,1.1658141207729347,-0.06193435696307015
208.60000000000227,16.338325421097483,1.1677470450980585,-0.0626753433915006
209.80000000000229,16.374694998771325,1.175609975348198,-0.0640653128266031
211.0000000000023,16.411414266016315,1.1792067900603913,-0.06437498862715874
212.20000000000232,16.44826799278812,1.187763208891334,-0.06489637749296717
213.40000000000234,16.484942081134314,1.1890137499073616,-0.06593487368501316
214.60000000000235,16.521297249392628,1.197046349379196,-0.06723631172430222
215.80000000000237,16.557886337519953,1.1999271735003032,-0.06845965079209382
217.0000000000024,16.594097883505476,1.2067453877309422,-0.06857089935924199
218.2000000000024,16.630982077974085,1.2122756447077099,-0.07008652557382833
219.40000000000242,16.66735071701045,1.2163144540931952,-0.07149142390356378
220.60000000000244,16.703669748602586,1.2218677899963346,-0.07289398726336227
221.80000000000246,16.740120524205196,1.2270393692984074,-0.0735996056909256
223.00000000000247,16.77657646335708,1.2358576596809714,-0.07514724074639378
224.2000000000025,16.813400504877663,1.2401688428276485,-0.07658621611151739
225.4000000000025,16.849875666350506,1.2467051680287637,-0.07797641116112164
226.60000000000252,16.886084656385016,1.251743726287608,-0.07982643815135138
227.80000000000254,16.922597419439025,1.2549777626564933,-0.08125993057614256
229.00000000000256,16.95891953916627,1.2619772164237237,-0.08238182024324647
230.20000000000258,16.995594919886273,1.264408922511483,-0.08372034421944585
231.4000000000026,17.03184668481768,1.2692189776356912,-0.08482744275337017
232.6000000000026,17.068440176087126,1.2730581512978487,-0.08745148216878817
233.80000000000263,17.10452672332693,1.2800757187952079,-0.08889668528076689
235.00000000000264,17.140937333104876,1.2821936964361615,-0.09028650868229882
236.20000000000266,17.17752299158683,1.285851953380981,-0.09194744191753301
237.40000000000268,17.213735462580026,1.2904113008331524,-0.09423527535546228
238.6000000000027,17.25009069667631,1.2924751190393502,-0.09790441482309076
239.8000000000027,17.286423402755922,1.2962496118048503,-0.10035969629129271
241.00000000000273,17.322723555711644,1.2974454936012716,-0.10250509229763827
242.20000000000275,17.35916804161185,1.3003709175926952,-0.10472854853614688
243.40000000000276,17.39547187773256,1.3044858067397982,-0.10730780566993792
244.60000000000278,17.431900689314084,1.3061873197377187,-0.10974981301095754
245.8000000000028,17.468194528603334,1.3054508832300125,-0.11235041533907664
247.0000000000028,17.504356237072777,1.3080340378028454,-0.11441828911743102
248.20000000000283,17.540803818131867,1.3078555488055932,-0.11698787195454985
249.40000000000285,17.577090169176213,1.3083759866845264,-0.12043751849240358
250.60000000000286,17.613589626187117,1.306424364172671,-0.12327680617777181
251.80000000000288,17.64984816331456,1.3072186218549307,-0.12741307029765814
253.0000000000029,17.68590768722652,1.3056020639322583,-0.1308984894161469
254.20000000000292,17.721815090060254,1.303947967371272,-0.13465367268193607
255.40000000000293,17.758550262366445,1.3039666746729153,-0.13706535575618073
256.600000000003,17.794554998518443,1.3027151123389036,-0.1383843698964915
257.80000000000297,17.831047189228546,1.303350610147736,-0.14185940807602382
259.00000000000296,17.86694587212181,1.3008259207620134,-0.14588265645447107
260.200000000003,17.903683748072847,1.2996963719366423,-0.14892473525447425
261.40000000000305,17.939674828977825,1.3029106336128844,-0.15292170295732532
262.60000000000304,17.9758686163264,1.3012567400973514,-0.15696522615033848
263.800000000003,18.01176669353351,1.3014988770038756,-0.16130176571471644
265.00000000000307,18.048125401683418,1.303195935989685,-0.16518165478985347
266.2000000000031,18.08438005582606,1.3031650040910234,-0.16848977806036913
267.4000000000031,18.120763738892226,1.3052847202191438,-0.17087025914271514
268.6000000000031,18.156784830209816,1.3049620194430185,-0.17523955350777998
269.80000000000314,18.193213400481486,1.3095776683736542,-0.17911681803649948
271.0000000000032,18.22973584745169,1.311028098878274,-0.1834683221902531
272.2000000000032,18.265526915096036,1.3107965788636098,-0.18756930717990894
273.40000000000316,18.301549222871742,1.310513177826858,-0.1921124173547013
274.6000000000032,18.337924963313537,1.310852160402853,-0.1972942571890539
275.80000000000325,18.374041975034636,1.312964428237865,-0.202123119555758
277.00000000000324,18.41030709230653,1.3165431883730083,-0.2076861869796076
278.20000000000323,18.44651294846222,1.3175282288733372,-0.21319180468382726
279.4000000000033,18.482581523134105,1.316622463789167,-0.2192861670850763
280.6000000000033,18.519176630594195,1.3173455949851425,-0.22583464812212073
281.8000000000033,18.555016492712817,1.3190451783365011,-0.23275434625853064
283.0000000000033,18.591362534791166,1.3196400982632124,-0.24010534020513585
284.20000000000334,18.6276465962131,1.3185667539565404,-0.2466655353171503
285.4000000000034,18.664006531681064,1.319027231222206,-0.25406015630344614
286.6000000000034,18.699999695061617,1.3179886793022844,-0.2612699959195779
287.80000000000337,18.73654794688387,1.316248950897477,-0.2693267862668298
289.0000000000034,18.772844983151252,1.3136401716351693,-0.2777555992862428
290.20000000000346,18.80877054402339,1.310765241264418,-0.28669831156609593
291.40000000000344,18.845343920169853,1.309339861448202,-0.2963727344092115
292.60000000000343,18.88128922089763,1.3054462294037334,-0.3058995672057052
293.8000000000035,18.91786741028426,1.3011475311818377,-0.3158513318594447
295.0000000000035,18.95400220921915,1.2963380565160374,-0.32678532555238693
296.2000000000035,18.99025172944439,1.2927006296322086,-0.3380121897961099
297.4000000000035,19.026487363801458,1.2854666681260716,-0.3492883795043147
298.60000000000355,19.062829804819593,1.2779915504175927,-0.3621946012816424
299.8000000000036,19.099079892314332,1.2708652775919282,-0.3754045198151119
301.0000000000036,19.135244900539906,1.260598130718281,-0.38930278314079914
302.20000000000357,19.17164642421036,1.2511440432957788,-0.4048698531029218
303.4000000000036,19.20796651743024,1.244058276680222,-0.41994100047354443
304.60000000000366,19.244345200098127,1.2323070439222445,-0.43546586170147084
305.80000000000365,19.28079592340485,1.2240877211205434,-0.4516383032863862
307.00000000000364,19.316873318709174,1.2149279063954426,-0.4671388750761216
308.2000000000037,19.353308572805833,1.2054081313955896,-0.48525496182971706
309.40000000000373,19.389723166775713,1.1946966354787194,-0.5030971866785867
310.6000000000037,19.426010859990953,1.18271997843537,-0.5214020819749869
311.8000000000037,19.462398079644835,1.1732724401570382,-0.540871022695419
313.00000000000375,19.498309947953118,1.1640971712601789,-0.5610435553288999
314.2000000000038,19.535072144709062,1.1517727555296826,-0.5807942511078052
315.4000000000038,19.571435286368718,1.1428749387100061,-0.6016569919630141
316.6000000000038,19.607767370566716,1.1360422370590666,-0.622876482205529
317.8000000000038,19.644213295151587,1.1284179062155903,-0.6436096961802176
319.00000000000387,19.680187224047852,1.123534139148712,-0.6645038705336743
320.20000000000385,19.71681809974634,1.1156418834835091,-0.6856807938962977
321.40000000000384,19.75287796218533,1.1116291997543535,-0.7068195110082054
322.6000000000039,19.789543368031264,1.106782126539966,-0.730627120552203
323.80000000000393,19.826137429879353,1.105031970292275,-0.7544906949246499
325.0000000000039,19.862491031777243,1.1057083231940628,-0.7766388826406767
326.2000000000039,19.898725744393563,1.1087272669252046,-0.7989797874775402
327.40000000000396,19.93527260685972,1.1077275407509337,-0.8220082345075403
328.600000000004,19.972049873145526,1.1106208607371888,-0.8453292580512692
329.800000000004,20.008205303739413,1.1188019638700286,-0.8673052761649913
331.000000000004,20.04505711150649,1.1204371822399775,-0.8897692360999816
332.200000000004,20.08124698159419,1.127892587544594,-0.9116264505137455
333.40000000000407,20.118045544649878,1.1344149897379245,-0.933605420284235
334.60000000000406,20.15451791416823,1.1458639417362468,-0.9566924180468996
335.80000000000405,20.19094301867065,1.1556610743027003,-0.9800615520805387
337.0000000000041,20.227502933471477,1.16585589124483,-1.0025974654583747
338.20000000000414,20.26415697238914,1.1780317606749486,-1.025048075858615
339.4000000000041,20.300656628073142,1.190351158535136,-1.0488373013673193
340.6000000000041,20.337552127342185,1.2047592797356914,-1.0730278535210473
341.80000000000416,20.37426796541574,1.2180978330789904,-1.0981896748606985
343.0000000000042,20.41021223038248,1.2337309252591204,-1.1215690875644877
344.2000000000042,20.447512620095903,1.2523093675881152,-1.1465848036831883
345.4000000000042,20.484141162404192,1.2663427260540945,-1.1702913598092417
346.60000000000423,20.521005971756356,1.286508647568248,-1.1939634926302167
347.8000000000043,20.55748632401433,1.303911028740814,-1.2178425115816869
349.00000000000426,20.59441539895839,1.3211761709637129,-1.2428585124990885
350.20000000000425,20.631108438148125,1.3429088162647527,-1.269851568821446
351.4000000000043,20.66767957124272,1.364705575745589,-1.2954156577418336
352.60000000000434,20.704658535533124,1.3856725564393901,-1.322547114938538
353.80000000000433,20.74150724385221,1.4034473976302018,-1.3497552212291293
355.0000000000043,20.778143378382374,1.4254432248288067,-1.3778439579953483
356.20000000000437,20.81516763801789,1.4494663444364622,-1.407241325047889
357.4000000000044,20.85182957895042,1.472960973019935,-1.437388089788998
358.6000000000044,20.88878793035732,1.4972731124088565,-1.4672915230991896
359.8000000000044,20.92611636219907,1.5215429758494832,-1.498585907690126
361.00000000000443,20.96245199057775,1.5450615006642545,-1.5280467756947291
362.2000000000045,20.99984622169257,1.5730577178118548,-1.560335684454273
363.40000000000447,21.036738248438972,1.600146756885551,-1.5944890259197386
364.60000000000446,21.072779076058296,1.6271576168234214,-1.628357112163819
365.8000000000045,21.110615472719918,1.654262621020885,-1.664750563759024
367.00000000000455,21.14770487141725,1.6823417942152272,-1.7017554747629977
368.20000000000454,21.184325042517802,1.7113720678451159,-1.739808560513222
369.4000000000045,21.22135399279245,1.7373771021091038,-1.7786887822358612
370.60000000000457,21.258775685391797,1.7640805662173773,-1.819909491377623
371.8000000000046,21.295617642215262,1.7877827653863547,-1.8638025174911483
373.0000000000046,21.332540949946612,1.8126218033415467,-1.9063284534709108
374.2000000000046,21.369936622595063,1.8344669214213616,-1.9505820970843852
375.40000000000464,21.40689290803417,1.848962988291879,-1.9944417744632559
376.6000000000047,21.44395011682448,1.8657746268904953,-2.039034504276803
377.8000000000047,21.481052869116652,1.8744046930812244,-2.0854000958162002
379.00000000000466,21.51811338710627,1.8804658676391044,-2.1319243028176604
380.2000000000047,21.55503910515903,1.8793979496685247,-2.1793668155227723
381.40000000000475,21.592263944735375,1.8707306998369646,-2.2275908312317307
382.60000000000474,21.62927082707549,1.8541655934407089,-2.27678424688158
383.80000000000473,21.666428786882793,1.8331838628030346,-2.3266716063258723
385.0000000000048,21.70379779514815,1.798678181114047,-2.3757489051162017
386.2000000000048,21.740824261671772,1.7622577781475643,-2.423747972544796
387.4000000000048,21.77782408597426,1.709918269810697,-2.470104269123984
388.6000000000048,21.81492860546553,1.6471743587816228,-2.516453514035932
389.80000000000484,21.85242255540866,1.5745791580523054,-2.561161397324411
391.0000000000049,21.88938537705946,1.4959462978300575,-2.6039889728932657
392.2000000000049,21.92651604570595,1.4035811015065602,-2.6443673179406098
393.40000000000487,21.963460363120994,1.3021880312620921,-2.6828956801001858
394.6000000000049,22.00013439437398,1.1976212079558768,-2.7167419576680865
395.80000000000496,22.037618475390065,1.0839489741894541,-2.74889479852736
397.00000000000495,22.075076367749272,0.973015590064624,-2.7787660519197566
398.20000000000493,22.112027559976628,0.8599778547848946,-2.804803900547717
399.400000000005,22.14933447341565,0.749752768041033,-2.827021683508537
400.600000000005,22.18617009811159,0.6516508671362351,-2.8462023120648325
401.800000000005,22.223655722816027,0.5595139259779736,-2.862403488401912
403.000000000005,22.260783105523686,0.4811214653983553,-2.876087204887431
404.20000000000505,22.29771516311738,0.4127831437073035,-2.887891539943511
405.4000000000051,22.334880533932026,0.357321505076144,-2.8977627891268005
406.6000000000051,22.371730970464423,0.3136036277646541,-2.9064819505704778
407.80000000000507,22.409370750299757,0.2769492821165138,-2.911944634279751
409.0000000000051,22.446340032050408,0.24227254373684382,-2.9184872051514934
410.20000000000516,22.483451567827338,0.21708472024574665,-2.924652774578233
411.40000000000515,22.520724344145652,0.19325036616084224,-2.9289104593623576
412.60000000000514,22.558022953903738,0.17285369665265637,-2.9345036851928654
413.8000000000052,22.59550555405861,0.15471488456053928,-2.938232652493946
415.00000000000523,22.63264521087155,0.14080730284043907,-2.9430256567152298
416.2000000000052,22.67003128713849,0.1255444586786021,-2.947814887044692
417.4000000000052,22.707477629243296,0.11164687810976526,-2.951367136300358
418.60000000000525,22.744854580884898,0.10101259098825488,-2.955358247290385
419.8000000000053,22.78243702333648,0.09123266926215057,-2.960415383964909
421.0000000000053,22.819664596754173,0.07998603393594128,-2.9644436559658582
422.2000000000053,22.857303815802968,0.07005092406413138,-2.968350263469749
423.4000000000053,22.89493421153396,0.06211966400437374,-2.9714635069658315
424.60000000000537,22.93209221455832,0.050991807662736255,-2.9750107537408446
425.80000000000535,22.969655696128346,0.04636681250961838,-2.9788136192850105
427.00000000000534,23.00733546433213,0.04019342888281385,-2.982307432686631
428.2000000000054,23.044658819112534,0.03135890502713101,-2.9857122069100255
429.40000000000543,23.08248113669379,0.02668910243176481,-2.9900009318666365
430.6000000000054,23.11975575815606,0.02185249035645298,-2.9937512048396275
431.8000000000054,23.15770464390276,0.016149406979942382,-2.9972534421161248
433.00000000000546,23.195084155647443,0.010506298644859191,-3.0009495085020603
434.2000000000055,23.232914862235504,0.007514897849507651,-3.003382903371521
435.4000000000055,23.270647956034157,0.0025350085844482173,-3.006556157213981
436.6000000000055,23.308102603209313,0.000878993528840244,-3.0108968751857184
437.8000000000055,23.345822639836694,-0.004475447736997928,-3.014557696924194
439.00000000000557,23.38356992271262,-0.0038029959131520297,-3.0175399750614513
440.20000000000556,23.421217080422494,-0.0046924285183733705,-3.020980145000765
441.40000000000555,23.45909661748331,-0.008386760364026857,-3.0245034473195633
442.6000000000056,23.49687973020538,-0.0061398780598136415,-3.027498432057513
443.80000000000564,23.5347844503774,-0.010033255953942,-3.030242625440838
445.0000000000056,23.57240277269862,-0.008751442143404287,-3.0349196071155653
446.2000000000056,23.609937153261143,-0.007717221519080386,-3.038186554079954
447.40000000000566,23.647323862874792,-0.006135058727654297,-3.0410315472625475
448.6000000000057,23.685603300842793,-0.0016143557939334308,-3.0432914904496378
449.8000000000057,23.723915172452884,-0.001027519156171497,-3.045371641428548
451.0000000000057,23.761431731042162,0.0014662212567539967,-3.0489284301276784
452.20000000000573,23.799056630107444,0.0022274639624455528,-3.052763183492024
453.4000000000058,23.83709140107046,0.004686072562360533,-3.0553789800352775
454.60000000000576,23.874805901834364,0.008358519844613888,-3.0577862081346554
455.80000000000575,23.912183002249275,0.012659174488370617,-3.059753784451842
457.0000000000058,23.95039703524873,0.016149680027897073,-3.0632206490000544
458.20000000000584,23.98882018027109,0.019569252174423735,-3.0657057830560634
459.40000000000583,24.026958122484167,0.02465411455041422,-3.0677304394782814
460.6000000000058,24.065007332816123,0.027359913703679073,-3.070776351738539
461.80000000000587,24.102816025810476,0.033436186064598195,-3.073118730811213
463.0000000000059,24.141024542430827,0.03753992914108384,-3.0747479720718998
464.2000000000059,24.178677114722223,0.04298747610925968,-3.078358074797914
465.4000000000059,24.217099459714397,0.04828770060784837,-3.0811791729448625
466.60000000000593,24.254842274472935,0.04979475798468003,-3.084574842855216
467.800000000006,24.2930309351083,0.05744219664139627,-3.0863165497605385
469.00000000000597,24.331434945456138,0.06301879053503345,-3.0885673631301893
470.20000000000596,24.369421871523233,0.06466807436617561,-3.090820977387274
471.400000000006,24.407601085601012,0.06966631359326936,-3.092819221267733
472.60000000000605,24.44580103359954,0.07325935210942647,-3.095173876141879
473.80000000000604,24.48378380805115,0.07914089974454197,-3.0969840384100618
475.000000000006,24.522475245027206,0.08597092830280695,-3.0984980470851604
476.20000000000607,24.560376050352726,0.08658731831323196,-3.1014191593098417
477.4000000000061,24.598886361335477,0.08859938871410944,-3.1033727473778647
478.6000000000061,24.636907559819946,0.09287946065687303,-3.1047673456555254
479.8000000000061,24.675262612724996,0.09831409011982628,-3.1068964013890197
481.00000000000614,24.713523707830877,0.10248521096202912,-3.108603884440679
482.2000000000062,24.75178494900271,0.1093001912332896,-3.1105034454552563
483.4000000000062,24.790197881837347,0.10828138630671158,-3.1122471099391857
484.60000000000616,24.82805251748718,0.11427376470014572,-3.1147440830724147
485.8000000000062,24.866567365756666,0.1141619504705933,-3.1168733506665327
487.00000000000625,24.905214075416957,0.11978605387389152,-3.119039508473671
488.20000000000624,24.943307654446624,0.12235123766183098,-3.1214814327159592
489.40000000000623,24.981450845692724,0.12716809848792132,-3.122760007478969
490.6000000000063,25.019999675044062,0.1298118493516338,-3.1242997564600623
491.8000000000063,25.058176464379255,0.13202938390043784,-3.12565061481014
493.0000000000063,25.096321051085827,0.13583604362517332,-3.1267157582062532
494.2000000000063,25.134817724142177,0.1375472962252955,-3.128206886811347
495.40000000000634,25.173314546534154,0.14029509953156838,-3.129566295371281
496.6000000000064,25.211609878086943,0.14284111249790876,-3.132261654488448
497.8000000000064,25.25006527779396,0.14712645123245482,-3.1338397819499093
499.00000000000637,25.288571928029512,0.14629604101598082,-3.1346835682878944
500.2000000000064,25.32663337635691,0.14832105159068987,-3.1353606368281493
501.40000000000646,25.365182764641613,0.14776589504100612,-3.1367135747792227
502.60000000000645,25.403627921316545,0.14954118825485319,-3.139157315553122
503.80000000000643,25.441731378203635,0.14976878003425598,-3.1407772325380363
505.0000000000065,25.4808581725708,0.15285383407931308,-3.141814617985383
506.2000000000065,25.519427910800097,0.15269540378539093,-3.143449625825475
507.4000000000065,25.55780583779343,0.1533227165741129,-3.1446403868643014
508.6000000000065,25.596049004647874,0.15346568925085813,-3.1447095377858214
509.80000000000655,25.63457402934448,0.15762871986801397,-3.1460710672018397
511.0000000000066,25.672890708858144,0.15431349986577358,-3.1466201677698145
512.2000000000066,25.711410025521786,0.1556493636172489,-3.1475150747501495
513.4000000000066,25.749839350065642,0.15938095528035978,-3.1490923451252706
514.6000000000066,25.788527953747703,0.1608050621480428,-3.1519237867463206
515.8000000000067,25.827182227878318,0.1599918387948227,-3.153235102319049
517.0000000000066,25.865564239055637,0.16037742814822487,-3.15471083879301
518.2000000000066,25.904433977258208,0.16261225370880217,-3.1561181535724936
519.4000000000067,25.9426395516726,0.1632499494473807,-3.1574339011646595
520.6000000000067,25.98139663202012,0.16079529764399614,-3.1587715678951334
521.8000000000068,26.0200646911114,0.16588603721627826,-3.1587388543916597
523.0000000000067,26.058569424561107,0.16414197153491883,-3.1600466033895698
524.2000000000068,26.097311428774603,0.16593884201626663,-3.161341619356599
525.4000000000068,26.13580874232583,0.1669578997111003,-3.1628368873315784
526.6000000000067,26.174578417130135,0.16689332575253268,-3.164314076443074
527.8000000000068,26.213142646388683,0.16691012813802875,-3.1642288941541588
529.0000000000068,26.25204062158013,0.16876556915833052,-3.1655234074086778
530.2000000000069,26.29052337400432,0.16548848203637023,-3.16723864912045
531.4000000000069,26.329577554890495,0.16855625018715092,-3.1685729929762303
532.6000000000068,26.36803182754667,0.1653415619242471,-3.168896866246917
533.8000000000069,26.406696208154607,0.16869346205937785,-3.170243914440587
535.0000000000069,26.445500257257624,0.16812101860817963,-3.1715615211458603
536.2000000000069,26.484205898604824,0.16574931302121243,-3.1729368491353758
537.4000000000069,26.52323567032124,0.16722799374327257,-3.173158129799274
538.600000000007,26.56160946783678,0.16629748596145544,-3.174264582758518
539.800000000007,26.6008249974167,0.1689044546063454,-3.175659697656945
541.000000000007,26.63984089375824,0.1761467291193919,-3.176949875845424
542.200000000007,26.67803577776909,0.18334594588502506,-3.178295556459005
543.400000000007,26.717187028915223,0.1917215821503786,-3.1782536517511577
544.6000000000071,26.755950960069942,0.19610199288916386,-3.1795611171373523
545.800000000007,26.79457890331944,0.19899355202101154,-3.181007619418657
547.000000000007,26.833283125708526,0.2027046568781039,-3.181169491847946
548.2000000000071,26.872232763321847,0.20688151005423627,-3.1822078477576987
549.4000000000071,26.910945470502064,0.21346471158709956,-3.18351769483703
550.6000000000072,26.949583932722103,0.21506383588150269,-3.1835284504925574
551.8000000000071,26.988693500767663,0.21659350925237741,-3.1848443046827395
553.0000000000072,27.02750606112125,0.2205676581811289,-3.1855893245585074
554.2000000000072,27.06583004003552,0.22200153439194503,-3.1861614242201655
555.4000000000071,27.105363581116883,0.22470124826656557,-3.1864516356264776
556.6000000000072,27.144277255369712,0.22688479505038384,-3.187441859710895
557.8000000000072,27.183325137598413,0.225287019049206,-3.1887843117648837
559.0000000000073,27.22254306553017,0.23222260988297205,-3.1902981517534266
560.2000000000073,27.261375979751243,0.23177245216631182,-3.192248851307016
561.4000000000073,27.30013314205724,0.23690369528936062,-3.192204129285553
562.6000000000073,27.33922756958613,0.23892752998937872,-3.193505359044256
563.8000000000073,27.377916421048997,0.24216905783606246,-3.194817080066528
565.0000000000073,27.417019674994588,0.2441227210515493,-3.1948320304160616
566.2000000000073,27.45608574459606,0.2466748894895039,-3.196217933251706
567.4000000000074,27.49527577285162,0.2516973296511842,-3.1961078590335
568.6000000000074,27.53414559998817,0.2513010971833858,-3.1974568704271933
569.8000000000075,27.573178247539225,0.2503493623937463,-3.198827735377156
571.0000000000074,27.61229615353931,0.2526580433507015,-3.1987956458704145
572.2000000000074,27.651539014167547,0.2508640796111532,-3.200093109377865
573.4000000000075,27.69034978866533,0.2519261115544831,-3.201021006242977
574.6000000000074,27.729590903639963,0.25151328844708454,-3.2000895975180987
575.8000000000075,27.76867924300464,0.24859349235789452,-3.201431360328959
577.0000000000075,27.807810144816024,0.25047407625666307,-3.2013101799118164
578.2000000000075,27.84697941041275,0.249789089171917,-3.203699297183423
579.4000000000076,27.88611793744011,0.2450757505414629,-3.2043012222827763
580.6000000000075,27.925388121463502,0.24291196340837717,-3.205030345394779
581.8000000000076,27.964351538566305,0.2348770192413001,-3.2049818074365692
583.0000000000076,28.003603158614524,0.23128833119847814,-3.2063247697923156
584.2000000000075,28.043234465108796,0.22662071942282336,-3.2072596256263752
585.4000000000076,28.08230646012472,0.22588220428850847,-3.2076350141518426
586.6000000000076,28.12128148271205,0.21665849558686956,-3.208972378500377
587.8000000000077,28.160568808496947,0.21484257584565647,-3.208996813388244
589.0000000000077,28.199771174039938,0.2091274453091838,-3.208972482297648
590.2000000000077,28.238996641082714,0.20798970763029168,-3.2105215767366317
591.4000000000077,28.278652573555945,0.2027413154057771,-3.212478405461478
592.6000000000078,28.31793252765931,0.20207928413125242,-3.212931171662581
593.8000000000077,28.35714784963914,0.19965794193654895,-3.213347985878655
595.0000000000077,28.3963690402986,0.19422302097682942,-3.21424435834123
596.2000000000078,28.435740982738455,0.19434306923985067,-3.2156468915775713
597.4000000000078,28.475011402668727,0.19240938059512236,-3.215531022777593
598.6000000000079,28.514276564344325,0.18875082248380703,-3.215517251457116
599.8000000000078,28.55406323947779,0.18708692740563748,-3.2155561801083703
601.0000000000078,28.593197867045284,0.1863804781164946,-3.217489509679935
602.2000000000079,28.632803731764998,0.1811519939929631,-3.217530877247116
603.4000000000078,28.67203804269884,0.17825304058343483,-3.217680752904932
604.6000000000079,28.711190533070592,0.17575750328993855,-3.2188505550882947
605.8000000000079,28.751006217063022,0.17132200841205547,-3.2188540317356633
607.000000000008,28.790269080969495,0.1729851042479138,-3.2201605957642228
608.200000000008,28.829319384524474,0.17187099053032062,-3.2210907554444406
609.4000000000079,28.8689474668288,0.16333267120494188,-3.2214811707636084
610.600000000008,28.908499666556764,0.16608430354013626,-3.2228256576525984
611.800000000008,28.947951787084353,0.1621279163997209,-3.222801804246397
613.000000000008,28.987136426050427,0.15785052858321813,-3.224165961065064
614.200000000008,29.026609548604167,0.1568092428092851,-3.2241253132455245
615.400000000008,29.066030093437643,0.15267705628354333,-3.2254656622781446
616.6000000000081,29.105557820348167,0.15023128761160387,-3.225444719016732
617.8000000000081,29.144948255349803,0.1461906111903819,-3.226785703795785
619.0000000000081,29.18445691096623,0.14537109634811274,-3.226740061162918
620.2000000000081,29.223978401725898,0.14094110271738325,-3.2267353286568836
621.4000000000082,29.263248198410395,0.14044749667377676,-3.228143623440217
622.6000000000081,29.302853420211964,0.13894510008714178,-3.23032688595612
623.8000000000081,29.34263673938053,0.1366840443749251,-3.230344074731642
625.0000000000082,29.3821191976573,0.13202770937219444,-3.228634751060806
626.2000000000082,29.42102662159164,0.13065190236950497,-3.229907755095003
627.4000000000083,29.460525762792034,0.12700088852836067,-3.2299196424888197
628.6000000000082,29.500710968901377,0.12853001028892663,-3.2305163581001426
629.8000000000083,29.54026496314702,0.12588505873774158,-3.2299265932166628
631.0000000000083,29.57946274923658,0.12400449028340232,-3.231524764512322
632.2000000000082,29.619203171118162,0.12215051931106924,-3.2325608749304444
633.4000000000083,29.65909833003486,0.11930858453946946,-3.2325599088963903
634.6000000000083,29.6983118554168,0.11445892020968662,-3.232756674930952
635.8000000000084,29.73803141115956,0.11129158782047877,-3.2338738186406433
637.0000000000084,29.777397321111106,0.10997042572403837,-3.2346581845801516
638.2000000000083,29.817060867974934,0.10984834179067637,-3.234428301376486
639.4000000000084,29.856472928378178,0.10554223389146222,-3.2358393170673727
640.6000000000084,29.896209418330226,0.10495371126570241,-3.2358400899167834
641.8000000000084,29.93589139359322,0.10111333284672819,-3.235839828294644
643.0000000000084,29.97562922129412,0.10098386872699927,-3.2357879057521064
644.2000000000085,30.01497848867503,0.09858670916711287,-3.2371472082155623
645.4000000000085,30.05483813920204,0.09572120283935837,-3.2371731567156927
646.6000000000085,30.09454283581067,0.09226301674497694,-3.238543703005416
647.8000000000085,30.13418172542956,0.08996999008577755,-3.239851351336174
649.0000000000085,30.173947195999908,0.09049672469831527,-3.2398486086935856
650.2000000000086,30.21356456831738,0.0870291943016055,-3.239900371636014
651.4000000000085,30.253158890614284,0.08576711996069109,-3.239786288314894
652.6000000000085,30.292673539277203,0.08530622852649472,-3.2412323420808677
653.8000000000086,30.33228204107904,0.08080669529548823,-3.2424342213763695
655.0000000000086,30.372446752657435,0.0804544727448282,-3.243839398137002
656.2000000000087,30.41211875309996,0.07827185007730386,-3.242682763295537
657.4000000000086,30.45180425460186,0.07904378824003766,-3.2440590648425323
658.6000000000087,30.49143594731738,0.07789250170616913,-3.244078989852186
659.8000000000087,30.531141946093467,0.07319904217549977,-3.243728202271255
661.0000000000086,30.571228373403365,0.07312767694119571,-3.2450517794027767
662.2000000000087,30.610780835371774,0.06979256536564438,-3.2450598685620764
663.4000000000087,30.65039639590806,0.07073208105325945,-3.245060833832732
664.6000000000088,30.690032757174407,0.07031239361549058,-3.2463708963844353
665.8000000000088,30.73003329314627,0.06791972408936364,-3.246639985895114
667.0000000000088,30.769676210382237,0.06571976101335864,-3.2478008031984635
668.2000000000088,30.809601614093776,0.06512207801258563,-3.2477933144090523
669.4000000000088,30.84915772284556,0.06063963310453735,-3.246465504630579
670.6000000000088,30.889151510436594,0.06351969638980237,-3.2478376269468603
671.8000000000088,30.928777187671702,0.05520739593079438,-3.2464962612794146
673.0000000000089,30.96866087874157,0.058869911907356354,-3.247835150053218
674.2000000000089,31.008129730481528,0.05561796090152615,-3.2478103060510044
675.400000000009,31.048016280368817,0.053141771232198654,-3.247807342362109
676.6000000000089,31.087893675812985,0.04890890007070814,-3.2490316827305032
677.8000000000089,31.127675231172542,0.04967414996994135,-3.249119313373895
679.000000000009,31.167524878821485,0.04796548863199712,-3.249119137714618
680.2000000000089,31.206867643875093,0.04984849069969233,-3.250178794321285
681.400000000009,31.24654560282325,0.046053892918153316,-3.2515081302713464
682.600000000009,31.286395529763034,0.044198213772967065,-3.251420338125947
683.800000000009,31.32637961578848,0.0411613282361758,-3.2514235390116024
685.0000000000091,31.36608713347167,0.04044197535077121,-3.2524592396692853
686.200000000009,31.405889377159365,0.03799012047538319,-3.252458084470728
687.4000000000091,31.445417482068375,0.03602533881186387,-3.25111072907186
688.6000000000091,31.485378969211858,0.03501972196054037,-3.251460492683159
689.800000000009,31.525435272941788,0.03557492982474697,-3.251714917647199
691.0000000000091,31.565075695233354,0.03005213032921228,-3.25274366205904
692.2000000000091,31.60487796684557,0.03272089530549094,-3.2527395969017077
693.4000000000092,31.644675957658183,0.02972282577250951,-3.252654045150641
694.6000000000092,31.684351759041522,0.02876581114387955,-3.2540548283837527
695.8000000000092,31.724331059806374,0.028829013111790758,-3.255064963412457
697.0000000000092,31.764358493258083,0.026154541202182635,-3.2553743373686697
698.2000000000093,31.804340309623267,0.023693416578672633,-3.2540764282304666
699.4000000000092,31.843989653283007,0.02324423405112741,-3.2540507969442376
700.6000000000092,31.883937649177675,0.018700679280016175,-3.2542447410876267
701.8000000000093,31.92379797908628,0.017302393985334508,-3.255060146816027
703.0000000000093,31.964026966289236,0.017219968059366764,-3.256369765065953
704.2000000000094,32.0038114996115,0.013929740227422549,-3.256359957180095
705.4000000000093,32.043814536922504,0.014194706196609896,-3.2563600071993895
706.6000000000093,32.08350165955341,0.01398951633664991,-3.256378692437754
707.8000000000094,32.123650327283535,0.008871356508562744,-3.257686362557931
709.0000000000093,32.1635945531362,0.00856769728178719,-3.2576809924166423
710.2000000000094,32.203531619003606,0.008035575346619694,-3.2590878352129633
711.4000000000094,32.24369779098066,0.003553825905238117,-3.258990583925021
712.6000000000095,32.28378856399646,0.002411180757545761,-3.2589917320720443
713.8000000000095,32.3234985389096,0.00025512411080130803,-3.2604045656397007
715.0000000000094,32.363752241422475,0.003881582916034798,-3.260328194059425
716.2000000000095,32.403615379884755,-0.00029248689252447946,-3.2590013216615437
717.4000000000095,32.44363950728619,-4.469432649578664e-05,-3.258990214919485
718.6000000000095,32.483838139550244,-0.002867879716666355,-3.258989817310817
719.8000000000095,32.5237005052648,-0.0037346137689207026,-3.2597073387668543
721.0000000000095,32.563740760297904,-0.004857583345104555,-3.260308117074678
722.2000000000096,32.60400020471998,-0.0036996178734405305,-3.2603308723015925
723.4000000000096,32.643243486090995,-0.01145707735698176,-3.2616234757948486
724.6000000000096,32.684212861240795,-0.014079440448313996,-3.26161993365424
725.8000000000096,32.72389754421758,-0.014115901350794768,-3.261619900594712
727.0000000000097,32.76407625364227,-0.019138178845826026,-3.261616871016313
728.2000000000096,32.804084387880536,-0.021000949408940706,-3.261297453513038
729.4000000000096,32.843954457527666,-0.02334149723387835,-3.261289713068529
730.6000000000097,32.884218694152196,-0.02184085055774876,-3.261240056318034
731.8000000000097,32.92425468878866,-0.024729577786139156,-3.2622755611001333
733.0000000000098,32.964071535610636,-0.025229513362938327,-3.2622800928654954
734.2000000000097,33.004387106208405,-0.02847562167101625,-3.262302294892646
735.4000000000098,33.044917838868805,-0.02909601904541148,-3.2635948201053413
736.6000000000098,33.08487048946633,-0.031095966591963453,-3.2635901055704237
737.8000000000097,33.12479317990076,-0.032247352533350426,-3.2635911552847743
739.0000000000098,33.16539985168935,-0.03674735300623855,-3.2650024955608394
740.2000000000098,33.20530629362624,-0.0393212263562428,-3.2649106282493565
741.4000000000099,33.24551565298968,-0.03779786409268748,-3.2649097385043007
742.6000000000099,33.285893180328,-0.04262733076418268,-3.2648276649993977
743.8000000000098,33.32591464242286,-0.047466183722111754,-3.266170265548258
745.0000000000099,33.36582883222144,-0.045035273497960215,-3.2654779917826278
746.2000000000099,33.406114920734446,-0.0479593957636566,-3.2668883099082784
747.4000000000099,33.44622809804079,-0.04993125243985741,-3.2668899067053334
748.6000000000099,33.48634856333825,-0.05374609874659653,-3.2668880635702315
749.80000000001,33.526625251908804,-0.05591554653879616,-3.2674736243261613
751.00000000001,33.56703835030653,-0.05696076350181789,-3.2680299256930896
752.20000000001,33.6070862933572,-0.060239109292301585,-3.268209161200807
753.40000000001,33.64719176425099,-0.061739096690772044,-3.2681998636760543
754.60000000001,33.68720952934221,-0.06551541447316689,-3.266841664578412
755.8000000000101,33.727548926761266,-0.0677405074278199,-3.2668895287498048
757.00000000001,33.76774990278118,-0.07234173015054379,-3.266845697001665
758.20000000001,33.80758633598293,-0.07014018563472524,-3.2682033336809075
759.4000000000101,33.848224998648746,-0.07421470316248824,-3.268210090595109
760.6000000000101,33.88823951444133,-0.07401006383561803,-3.2682112207526783
761.8000000000102,33.92859761651345,-0.0758912959609721,-3.269544738066774
763.0000000000101,33.968699604244016,-0.078429371342978,-3.2695203299333695
764.2000000000102,34.00890343163631,-0.07784398842099538,-3.269526586869472
765.4000000000102,34.049058933730805,-0.07774738683542015,-3.2707628934706943
766.6000000000101,34.08858067953062,-0.07840360524077683,-3.269514594254539
767.8000000000102,34.129625791104566,-0.08418500237570692,-3.269613193030098
769.0000000000102,34.16947099617964,-0.08479756725323817,-3.272153355660807
770.2000000000103,34.209830791432445,-0.08852110758341825,-3.272149981928785
771.4000000000103,34.25013270004581,-0.08998161730316134,-3.2721548403827767
772.6000000000103,34.29034328572053,-0.0886110746943225,-3.2714490623385326
773.8000000000103,34.33056672689778,-0.09302030982602938,-3.272197228166492
775.0000000000103,34.37110354152056,-0.09324170490383832,-3.272809491220372
776.2000000000103,34.411315022773465,-0.09611986141983264,-3.272810024162095
777.4000000000103,34.45162358257415,-0.09689389292694184,-3.27281059606989
778.6000000000104,34.491734260380355,-0.10352937142727381,-3.2729392989765485
779.8000000000104,34.53201682648522,-0.10308370237777131,-3.27348648394743
781.0000000000105,34.57255986975877,-0.10531168307192562,-3.2734698250913694
782.2000000000104,34.61303654000438,-0.10588780911499418,-3.2721473019360108
783.4000000000104,34.65301388789975,-0.10747367547371844,-3.2734462971296727
784.6000000000105,34.69357942130089,-0.11070929494782789,-3.2734654224129525
785.8000000000104,34.73390680195604,-0.11200865936017923,-3.2747632399523097
787.0000000000105,34.77410019548576,-0.11272219840641329,-3.2747897419433407
788.2000000000105,34.81468109349263,-0.11347929398228906,-3.274789874164795
789.4000000000106,34.854776515515276,-0.11701258123199931,-3.2747898425224835
790.6000000000106,34.89545797892786,-0.11632416296657588,-3.2747831839855945
791.8000000000105,34.93552146401179,-0.12106993717985803,-3.2760628810430306
793.0000000000106,34.975902551225765,-0.12026275365380767,-3.2762122057477283