File: 01_Data/Basswood_Panel/STA/N2/30K_min/Basswood_Panel_STA_N2_30KData_220315_R1.csv
##Temp./Â°C,Time/min,DSC/(mW/mg),Mass loss/mg
49.0,10.404067774085359,0.031130527117216866,-0.0044182783333655
50.20000000000002,10.677318121046298,0.10000701688644509,-0.006111290213445031
51.400000000000034,10.819078644287263,0.15650989437269136,-0.007011134978434974
52.60000000000005,10.925745371409583,0.20688741138992206,-0.007869229698385105
53.80000000000007,11.016087127087474,0.2517517777820185,-0.007141263890015459
55.000000000000085,11.095579506386647,0.29307289278626253,-0.006316501242482175
56.2000000000001,11.167076759293137,0.33082992240512077,-0.0075817807272802185
57.40000000000012,11.234388367068778,0.36420569815158577,-0.006385515182980583
58.600000000000136,11.296999067819746,0.39695009387961133,-0.005988021277702593
59.80000000000015,11.356834129121202,0.42790198248318123,-0.006459233316503443
61.00000000000017,11.413616199596085,0.4546683497479128,-0.0067425141018890855
62.20000000000019,11.46963797239229,0.48240265438220054,-0.009164780331800237
63.400000000000205,11.522000740093633,0.5079040656786172,-0.007067173494321288
64.60000000000022,11.573686111473023,0.530926063378595,-0.006375056036517002
65.80000000000024,11.62425550345403,0.554440082971507,-0.006708660498610186
67.00000000000026,11.674059093299045,0.5757603881617993,-0.008035005814739371
68.20000000000027,11.721955726256178,0.5956235150383543,-0.007852058341846657
69.40000000000029,11.769831552288016,0.6176239708111565,-0.008161722338577704
70.6000000000003,11.816981452924491,0.634899742687308,-0.008021552102300156
71.80000000000032,11.863032494574421,0.6519428980089563,-0.009031638570127676
73.00000000000034,11.908880128369205,0.670433910874892,-0.008384222306553113
74.20000000000036,11.954448600654807,0.6897334569600282,-0.008099918574445475
75.40000000000038,11.999320798473954,0.7065666559883697,-0.008791603614313637
76.60000000000039,12.043487390249023,0.7210371821868742,-0.00960582865102566
77.80000000000041,12.087843766684205,0.737866036609466,-0.008136504824371116
79.00000000000043,12.131788130975606,0.7524246807406787,-0.0071942509290297
80.20000000000044,12.174916642940044,0.7699642749671312,-0.010602729564383573
81.40000000000046,12.218211259726488,0.7806779981600983,-0.011261914539568707
82.60000000000048,12.261707708759197,0.7963958803881344,-0.011911135261008177
83.8000000000005,12.30393826634047,0.8095553990620035,-0.01016532837159545
85.00000000000051,12.346681117133905,0.8245421801160323,-0.011199688557717913
86.20000000000053,12.388599233462282,0.8382005784864615,-0.011156005970160088
87.40000000000055,12.431036811068573,0.8498141418310893,-0.010345923211252384
88.60000000000056,12.472413848897455,0.8616411780742332,-0.011543865440749812
89.80000000000058,12.514076777680218,0.871585274122951,-0.01208279744118368
91.0000000000006,12.554786921825903,0.8826309367776137,-0.012586890321983901
92.20000000000061,12.596989987175032,0.8919828934991516,-0.013275875358987221
93.40000000000063,12.637303452225474,0.9014692886683846,-0.013403118182349516
94.60000000000065,12.678862108031348,0.910159536631456,-0.014485019006711397
95.80000000000067,12.719948926323031,0.9193072409822678,-0.01461164809834603
97.00000000000068,12.761104807708143,0.9261859775147157,-0.015086902313671047
98.2000000000007,12.802086721498986,0.9328254899956658,-0.0145705408611283
99.40000000000072,12.842359595318408,0.9400517937430557,-0.01592234125570169
100.60000000000073,12.882969554262514,0.9445901953474771,-0.01483447339187105
101.80000000000075,12.923554859658092,0.9503803698970467,-0.016237229209731474
103.00000000000077,12.963595212578253,0.9566197702746663,-0.017070437378859715
104.20000000000078,13.004114258404298,0.9591017701884861,-0.01721638565332473
105.4000000000008,13.044908838078676,0.9602113948505133,-0.018464308170344168
106.60000000000082,13.085118301799023,0.9635445385772019,-0.01797384313234751
107.80000000000084,13.125201990295468,0.962796426635797,-0.01721484322494682
109.00000000000085,13.165239911017252,0.9646002819582893,-0.018523727708999793
110.20000000000087,13.205523014749888,0.965617927550537,-0.018530645692426795
111.40000000000089,13.245773191219897,0.9672230347989507,-0.019433809190440243
112.6000000000009,13.285937399352846,0.9681180550958033,-0.0198499208215015
113.80000000000092,13.326236548482969,0.966278855017727,-0.019849626912329832
115.00000000000094,13.365955880047256,0.9666333035654618,-0.021127202950798285
116.20000000000095,13.406039937044806,0.9638049234030496,-0.02115327968878411
117.40000000000097,13.445845222677812,0.9636298409031014,-0.021473513508832198
118.60000000000099,13.485882468213493,0.9625225702053293,-0.02148992411202677
119.800000000001,13.525684509594774,0.9660117336817517,-0.021490095628338146
121.00000000000102,13.565447860067431,0.9644217124607503,-0.0214900981762991
122.20000000000104,13.605029567581033,0.9653772983369542,-0.02149015043589042
123.40000000000106,13.6447459442339,0.9658497516933374,-0.02150576513562541
124.60000000000107,13.684414927845435,0.967766415491798,-0.02263557299304164
125.80000000000109,13.723477869427294,0.9671733743255382,-0.022480785989489327
127.00000000000111,13.763274417723112,0.969038164039465,-0.022479720052231755
128.20000000000113,13.802491104254768,0.9719476881533213,-0.02241157562444851
129.40000000000114,13.841329639153573,0.9735301233992486,-0.02378897880794817
130.60000000000116,13.880716019667403,0.9746234616820025,-0.023799948543977045
131.80000000000118,13.919685283363059,0.9775458170857245,-0.023795969584676335
133.0000000000012,13.959234238269154,0.9808392348222865,-0.024766730844437923
134.2000000000012,13.99767085012699,0.9823838589422371,-0.023797854414609354
135.40000000000123,14.037191547803639,0.9865108448849267,-0.023793475578728795
136.60000000000124,14.075786805891081,0.9904621766181294,-0.02501856584888973
137.80000000000126,14.114815657495472,0.9956046402615362,-0.025121048735123885
139.00000000000128,14.153554901088661,0.9981894759919219,-0.02476711378922758
140.2000000000013,14.191618877487391,1.0012666094416238,-0.02478985431010905
141.4000000000013,14.230451116594262,1.008226028976961,-0.024789888558023776
142.60000000000133,14.269264686870953,1.0114082574264898,-0.024789888003033944
143.80000000000135,14.307733685105159,1.015187028121255,-0.024789886703698194
145.00000000000136,14.345816375744029,1.0215836205780218,-0.024789664917642895
146.20000000000138,14.384271310168112,1.0258380203068087,-0.024756226220145727
147.4000000000014,14.421905372952045,1.0309619069093905,-0.026103355362142366
148.60000000000142,14.461138652913796,1.0386075832537742,-0.026109888008327253
149.80000000000143,14.498848747961292,1.043369789271148,-0.026106041545897796
151.00000000000145,14.537112157890975,1.0498586772322602,-0.027400264073725644
152.20000000000147,14.575095403018896,1.053175531913997,-0.027420614026984147
153.40000000000148,14.613173115649065,1.0577000957603488,-0.027594287660633654
154.6000000000015,14.651225230376792,1.0637282502749381,-0.02741914677530577
155.80000000000152,14.689201785673731,1.0710457732924248,-0.027419121164379945
157.00000000000153,14.727302951187028,1.0761948410421076,-0.026115074032516006
158.20000000000155,14.765068882274374,1.0805480388022581,-0.026109953687009302
159.40000000000157,14.802868000983377,1.0870399332970013,-0.02611075774156113
160.6000000000016,14.840608576109705,1.0922761976082853,-0.02745171712085348
161.8000000000016,14.87844246501691,1.0990904851100776,-0.0274193404655243
163.00000000000162,14.916259939667956,1.1058143718197875,-0.02742000489410401
164.20000000000164,14.95406847585527,1.109222174839915,-0.027482997271517817
165.40000000000165,14.991998602690964,1.117705254712577,-0.028736923055978636
166.60000000000167,15.02958618628504,1.1223568747266353,-0.028730051823257163
167.8000000000017,15.067339614445432,1.127827300901091,-0.028751814656410524
169.0000000000017,15.10514985847511,1.1306655469791003,-0.030049656743409425
170.20000000000172,15.142862707136352,1.137341235559744,-0.031015214639331212
171.40000000000174,15.180354695791216,1.1427595124662262,-0.03133450719254194
172.60000000000176,15.217723226310182,1.1475648570759218,-0.03070841239667077
173.80000000000177,15.255262152484132,1.154068729846688,-0.03070958808128399
175.0000000000018,15.292884707138146,1.1589474397694937,-0.03067317665151137
176.2000000000018,15.330290243221766,1.1658951375144833,-0.03202293419252289
177.40000000000182,15.367320773102215,1.168534216929697,-0.032030186739090194
178.60000000000184,15.404652503606288,1.1735041408788447,-0.03203009518565825
179.80000000000186,15.44210589245926,1.177344975651601,-0.03203009423298209
181.00000000000188,15.479326262345683,1.1804127425230453,-0.03203009536465107
182.2000000000019,15.516611272566358,1.1867039578880019,-0.032026565281893404
183.4000000000019,15.554003288397887,1.1900648605096147,-0.033055596043008784
184.60000000000193,15.5910219627591,1.1924966295076174,-0.034665208712872264
185.80000000000194,15.627987062987676,1.197869700762177,-0.03466773056553407
187.00000000000196,15.664761013772818,1.2022019328625972,-0.036024022350383156
188.20000000000198,15.701828037551696,1.2056783592205744,-0.03598035569700109
189.400000000002,15.738927345243328,1.2149095077317686,-0.035979538670396494
190.600000000002,15.776113484981899,1.2172655824494134,-0.037160145506660136
191.80000000000203,15.812464968638814,1.2223351924000414,-0.03729894491472496
193.00000000000205,15.849627748919296,1.227696399632297,-0.03730006910529848
194.20000000000206,15.886732651820319,1.233356980256096,-0.038418345946973353
195.40000000000208,15.92350167388919,1.239215764319181,-0.03860818656203069
196.6000000000021,15.96060539576446,1.242640517376144,-0.038608556599404764
197.80000000000211,15.997133947484848,1.2481127610479474,-0.039970465389741694
199.00000000000213,16.033971193068073,1.2522619144646967,-0.03988538354789428
200.20000000000215,16.070474337733813,1.2554633757012346,-0.04123235404489067
201.40000000000217,16.10743969538846,1.2584310275091846,-0.04124012681866107
202.60000000000218,16.14404034738718,1.2656323413847792,-0.041243264710963956
203.8000000000022,16.18043163878369,1.2705781933465572,-0.042699447321083106
205.00000000000222,16.217430144423474,1.2745931052430552,-0.04386825380194059
206.20000000000223,16.253945668021277,1.2799647755637542,-0.04541520575971614
207.40000000000225,16.290509089333455,1.2831348197982855,-0.046061836204571716
208.60000000000227,16.327507924910954,1.2890898126884571,-0.04661330765720528
209.80000000000229,16.36385588464118,1.2950829120486658,-0.04628877602561943
211.0000000000023,16.400376536684036,1.2997957378757867,-0.04758171588739746
212.20000000000232,16.43728377649332,1.3056949151073296,-0.048933065035968504
213.40000000000234,16.473660832841137,1.3144211305486775,-0.05041326957569581
214.60000000000235,16.510261866192984,1.3176761203136969,-0.051685604898346504
215.80000000000237,16.546728505623143,1.3250676948637699,-0.05240711788607655
217.0000000000024,16.583587831057937,1.330963606738729,-0.052981611971174125
218.2000000000024,16.619961291353768,1.3378752211940186,-0.054313590109810406
219.40000000000242,16.656603410140434,1.3451045836319269,-0.0555832253579327
220.60000000000244,16.69339165634154,1.353059638554786,-0.05723868051916181
221.80000000000246,16.72979529280626,1.3575610228139685,-0.05818066919139575
223.00000000000247,16.766226891614195,1.364318056012677,-0.05886938126748209
224.2000000000025,16.80265483940789,1.3719778405342944,-0.06060058458838746
225.4000000000025,16.838925615520793,1.3788820213968478,-0.06194991746161538
226.60000000000252,16.875604015597414,1.38247769468167,-0.06299563105737072
227.80000000000254,16.912244655632552,1.3896145389395205,-0.06420765810767914
229.00000000000256,16.948364789163058,1.394227482405396,-0.0663893060233951
230.20000000000258,16.984795845297864,1.3992342472592105,-0.06837443278721089
231.4000000000026,17.021308154363904,1.4054503132153782,-0.069954877339232
232.6000000000026,17.056879817629543,1.4110074426118904,-0.07146794155817648
233.80000000000263,17.094189538403256,1.4152532439698104,-0.07288405217812688
235.00000000000264,17.130582414527677,1.4230301329707644,-0.07440478085881486
236.20000000000266,17.16682083446252,1.4251155689279595,-0.07742771749115906
237.40000000000268,17.203047613332696,1.4275126726438492,-0.0796829249634694
238.6000000000027,17.23949740704918,1.4334712902722262,-0.08239200239613353
239.8000000000027,17.27550137108574,1.4366449922441342,-0.08470987721514245
241.00000000000273,17.31227858145844,1.441213521147167,-0.087412790423397
242.20000000000275,17.34874743819137,1.4436968285897915,-0.09049168577324096
243.40000000000276,17.384525441617807,1.445382434598717,-0.09266664827393845
244.60000000000278,17.421007196372514,1.4481292034357827,-0.0948726572875418
245.8000000000028,17.457201604624927,1.449949233294245,-0.09610065272313939
247.0000000000028,17.4935131646699,1.453452938024025,-0.09891566447369415
248.20000000000283,17.530067932294113,1.4528477688185424,-0.10163583558623124
249.40000000000285,17.565192528155865,1.4539682596571304,-0.10614608959776639
250.60000000000286,17.601808831409684,1.4561996021876789,-0.10867547607161354
251.80000000000288,17.63882762869934,1.4554498266633145,-0.11133231339105043
253.0000000000029,17.674775304300972,1.4554852753484666,-0.11385656153915935
254.20000000000292,17.711134320112922,1.4548015326857189,-0.11767238885328624
255.40000000000293,17.74722857215425,1.4560878223848426,-0.120420098782414
256.600000000003,17.783391333514146,1.4550199816535923,-0.12396293916313583
257.80000000000297,17.8193820342204,1.4538011390424788,-0.12813193833617742
259.00000000000296,17.854794066158526,1.452326496493007,-0.13033810589130423
260.200000000003,17.891822885902606,1.45382581125003,-0.13310798992629547
261.40000000000305,17.928317636977436,1.4567915877409008,-0.13612335881287185
262.60000000000304,17.964348321497873,1.455662385728924,-0.14061930949373735
263.800000000003,18.00063145481184,1.4566119052588289,-0.14486245942651355
265.00000000000307,18.03682728111569,1.4525176049680217,-0.14841371617686416
266.2000000000031,18.07292223457171,1.4530849746972034,-0.15290389471012533
267.4000000000031,18.109140842756876,1.4563213894540215,-0.1560774829942866
268.6000000000031,18.14535460466557,1.4553761110338295,-0.159972500962402
269.80000000000314,18.18139187947482,1.4560671950705117,-0.16575638006346427
271.0000000000032,18.217769791609808,1.4591230400464361,-0.1693335016619617
272.2000000000032,18.254024688849963,1.4604176703396,-0.17404909727129558
273.40000000000316,18.290100607452562,1.4623591825193079,-0.17830123297673728
274.6000000000032,18.3261701043796,1.4625970379806126,-0.18237413539119407
275.80000000000325,18.362413128765148,1.466047455870621,-0.18748699760771093
277.00000000000324,18.398708868123858,1.4685674598731027,-0.19307783160551706
278.20000000000323,18.43481201455335,1.4687048315629472,-0.197523729425654
279.4000000000033,18.471126476276133,1.4689575676173914,-0.2032760305672916
280.6000000000033,18.507206375110343,1.4697652280886728,-0.20928231557171095
281.8000000000033,18.543377799514708,1.471122125435286,-0.21594145029046308
283.0000000000033,18.579675393571772,1.472508491643138,-0.2224135926360713
284.20000000000334,18.61585710185344,1.4720710432744988,-0.23031671537828569
285.4000000000034,18.652076833309934,1.4718188415780113,-0.2380859425726567
286.6000000000034,18.688536415641963,1.471755896665424,-0.24509666066098346
287.80000000000337,18.724818704524388,1.4722147894222113,-0.2535839848933512
289.0000000000034,18.760925385228393,1.4696217831221756,-0.2615921829875605
290.20000000000346,18.797284491034247,1.4691377065533968,-0.2716076154334024
291.40000000000344,18.833223167542368,1.4652980091719305,-0.2813186377475043
292.60000000000343,18.869474924706086,1.46307279300971,-0.2904075003677238
293.8000000000035,18.905764835656175,1.4590637731911162,-0.29964190328314855
295.0000000000035,18.942065421165168,1.4551063017589352,-0.311558257712945
296.2000000000035,18.978306117846877,1.44700318248524,-0.3230241868688144
297.4000000000035,19.014524626014573,1.4409451763681667,-0.33476268041252855
298.60000000000355,19.050943029253876,1.433164912391616,-0.3460598352271802
299.8000000000036,19.087193318507673,1.4259976673006922,-0.35912923965248655
301.0000000000036,19.123387982286655,1.4184550729807175,-0.37328733077507437
302.20000000000357,19.15975627621123,1.4102246524479167,-0.3873788042199364
303.4000000000036,19.196094312221806,1.401318952363871,-0.40234497713436124
304.60000000000366,19.23237878060023,1.391938468854322,-0.41906247819382925
305.80000000000365,19.268573460275388,1.3821334521751993,-0.43496336235858024
307.00000000000364,19.304687479352232,1.3746505433559855,-0.45126074044194775
308.2000000000037,19.341144250210593,1.3620020324244038,-0.4685120582736628
309.40000000000373,19.377365022410267,1.3527265064220149,-0.486156779157739
310.6000000000037,19.413617184310787,1.341428908178679,-0.5047090320228058
311.8000000000037,19.449817320005504,1.328828744798916,-0.5232053314118632
313.00000000000375,19.48609141234271,1.321360497812313,-0.5424886920494152
314.2000000000038,19.522219620063687,1.3112547131284822,-0.5620666667925276
315.4000000000038,19.558595925386253,1.3001127373749373,-0.582838812511473
316.6000000000038,19.594995421365674,1.2945042272728535,-0.604274072273288
317.8000000000038,19.6315274063877,1.28743759930653,-0.6269962846361485
319.00000000000387,19.66745614515286,1.2812502070198413,-0.6483629397915553
320.20000000000385,19.70423232946398,1.2732534275533336,-0.6692332512839378
321.40000000000384,19.740359125667858,1.2693502683646458,-0.690747191694975
322.6000000000039,19.776821067812843,1.2634208677296155,-0.7131665833447105
323.80000000000393,19.813460466970895,1.260725214377138,-0.735801618584325
325.0000000000039,19.849697477442234,1.260040572143352,-0.7585819905086426
326.2000000000039,19.886077485671105,1.2614118299393329,-0.7802665369151391
327.40000000000396,19.922863009086402,1.261931886752791,-0.8031002545469934
328.600000000004,19.95889422618726,1.263527162184086,-0.8261208278137944
329.800000000004,19.995732022381954,1.2667901134015906,-0.8500416173486784
331.000000000004,20.032219154547988,1.2683208251815794,-0.8747879204701103
332.200000000004,20.068571984863322,1.2768383969232513,-0.8971763645969961
333.40000000000407,20.105219510021243,1.2834976947321868,-0.9196452389557312
334.60000000000406,20.1419362899123,1.2921591620129227,-0.9412308076307538
335.80000000000405,20.17833993942319,1.2991464808362887,-0.9637562865452298
337.0000000000041,20.214654819554752,1.309707965621105,-0.9874717679516061
338.20000000000414,20.251575763229283,1.3224244896042774,-1.0104292877547514
339.4000000000041,20.288246011903777,1.3343002853195371,-1.0336714239151288
340.6000000000041,20.32502246935067,1.346211392497654,-1.0574595519741607
341.80000000000416,20.36182044423721,1.3604931220009204,-1.081512238897231
343.0000000000042,20.398359134750184,1.3768783930236401,-1.1036538023826679
344.2000000000042,20.434929272346256,1.3917211359231256,-1.1283634684668455
345.4000000000042,20.471580698406523,1.4066117428620513,-1.1532942908890789
346.60000000000423,20.508569968419827,1.4215793695785564,-1.1780348134227787
347.8000000000043,20.545272981423008,1.4395080319009772,-1.2023882977248217
349.00000000000426,20.58200658793432,1.460753562286193,-1.2271510347245371
350.20000000000425,20.618826489176257,1.4810157066648608,-1.2535695971562393
351.4000000000043,20.655578678546384,1.497988966619975,-1.280182264341581
352.60000000000434,20.692413696477967,1.5202452159583764,-1.306045283395704
353.80000000000433,20.729327509739704,1.5424849611478364,-1.3330264073515972
355.0000000000043,20.766136510349057,1.5649897491187306,-1.3615306435232357
356.20000000000437,20.80290001677014,1.5873251848256245,-1.3904104906427786
357.4000000000044,20.83988544917775,1.6115522854353501,-1.4198115721785247
358.6000000000044,20.876767590713946,1.6343583357966918,-1.4503405685860349
359.8000000000044,20.91389842855661,1.660628181253377,-1.4821468614775593
361.00000000000443,20.95050808651213,1.6855787281607744,-1.5145765921027472
362.2000000000045,20.987798408800643,1.7142325564548437,-1.5473793133856701
363.40000000000447,21.024492589670764,1.7406541002496416,-1.5807055582122058
364.60000000000446,21.061494887221897,1.7671436238174332,-1.6147678953432512
365.8000000000045,21.09853443533577,1.796589064669131,-1.6496131700889922
367.00000000000455,21.13553872031676,1.8249827647790207,-1.6860230875649722
368.20000000000454,21.172743316940736,1.8531007369567727,-1.723799251874171
369.4000000000045,21.209654206352564,1.8775748155766976,-1.762728945230831
370.60000000000457,21.246441967366298,1.9063731609968904,-1.803248466084053
371.8000000000046,21.283799180310993,1.9313753145585517,-1.8456953018365159
373.0000000000046,21.320676545602968,1.9560067162958374,-1.8886345619927742
374.2000000000046,21.357819727822893,1.9777858469825185,-1.9336401579980356
375.40000000000464,21.394922005827755,1.9972778860028568,-1.9791367787172356
376.6000000000047,21.4313787863786,2.0125756795724836,-2.024456025884845
377.8000000000047,21.468706848835264,2.0220782112105224,-2.071686769958603
379.00000000000466,21.50555811749221,2.0281890132795164,-2.118474193629776
380.2000000000047,21.54314467320076,2.0300632625934125,-2.1667723705848747
381.40000000000475,21.58040969162401,2.0219174426567914,-2.2150984383160335
382.60000000000474,21.617349414426048,2.010116491588868,-2.262710401668805
383.80000000000473,21.65458566622767,1.990211644885301,-2.3113814147874123
385.0000000000048,21.69168857031013,1.9570379948548686,-2.3598587563772186
386.2000000000048,21.728801228393305,1.9207579350351207,-2.4081260996996727
387.4000000000048,21.76615544625468,1.8677677152042804,-2.4558454552370623
388.6000000000048,21.803065929944857,1.8102442370194578,-2.502388666135823
389.80000000000484,21.8404142331743,1.7374053271576837,-2.5474012096332785
391.0000000000049,21.87749549345108,1.6581186704826598,-2.592847841014859
392.2000000000049,21.914231715297586,1.5654626179896305,-2.63393621985744
393.40000000000487,21.951679736913146,1.4646786852361375,-2.6719314059086434
394.6000000000049,21.988771818343913,1.3596957752740273,-2.7072175306636126
395.80000000000496,22.02596193977326,1.248794239594047,-2.740842582622812
397.00000000000495,22.06314337420174,1.1329883280877768,-2.769991773530406
398.20000000000493,22.100094448675183,1.0236911054851037,-2.7949746653283087
399.400000000005,22.137465031511475,0.915136878730743,-2.818128411282751
400.600000000005,22.17426055092374,0.8145033040635088,-2.837536949274555
401.800000000005,22.21135372610656,0.7222483443193841,-2.8540621325340734
403.000000000005,22.248352873819965,0.6432174734896587,-2.8687343502956333
404.20000000000505,22.285690030294376,0.569047622626816,-2.8788820442646914
405.4000000000051,22.322842989280588,0.5169192752829439,-2.888599819686017
406.6000000000051,22.35970713681198,0.4666496669625808,-2.8978123568276333
407.80000000000507,22.397302123764398,0.42730764946544286,-2.9066385623962505
409.0000000000051,22.43423226971701,0.3946838785756861,-2.913011818037537
410.20000000000516,22.47188043363878,0.3708682797218179,-2.9180872332702235
411.40000000000515,22.50858172447738,0.3488273281130896,-2.922964527658098
412.60000000000514,22.546377502326667,0.32834929026667337,-2.9284463265785803
413.8000000000052,22.583605801927295,0.3127032292966263,-2.933046722703213
415.00000000000523,22.62107213235366,0.2963937590915955,-2.9379433520236145
416.2000000000052,22.658355909179335,0.2835962756080237,-2.9419158404298433
417.4000000000052,22.695801398533995,0.2731670120384295,-2.9460770777265717
418.60000000000525,22.73326903549155,0.26188174223896477,-2.950058094383597
419.8000000000053,22.770553338805836,0.2513729064082375,-2.953466921772158
421.0000000000053,22.808157216108853,0.24164410391492952,-2.9570181875659394
422.2000000000053,22.84548917702656,0.23407693231658566,-2.961084526265095
423.4000000000053,22.883091393931878,0.2255776987049194,-2.965734364124459
424.60000000000537,22.920695305380175,0.21550243568701233,-2.968285350083232
425.80000000000535,22.958316178439908,0.2115831494355651,-2.971467268957641
427.00000000000534,22.995446788200773,0.20552198897673324,-2.976589599248788
428.2000000000054,23.03296211886561,0.19955574641239182,-2.9802771872833707
429.40000000000543,23.070632672955334,0.1915662787852801,-2.983110378469298
430.6000000000054,23.108329514025726,0.18699551588849017,-2.988218688887925
431.8000000000054,23.146188567296623,0.18101331910260643,-2.992220549430087
433.00000000000546,23.183653876935413,0.17949434141059517,-2.9939755902359586
434.2000000000055,23.22112845978788,0.1747691059045573,-2.9958781144862505
435.4000000000055,23.25917032126923,0.17054625377037236,-2.9992960603070933
436.6000000000055,23.296503785649065,0.1697996338041483,-3.0043636507879006
437.8000000000055,23.334268590177896,0.16725261944186043,-3.0087758242507334
439.00000000000557,23.371629858398713,0.16261097717546025,-3.012117553451717
440.20000000000556,23.409603376298456,0.16538024241198723,-3.0147679905992297
441.40000000000555,23.447318607083076,0.16530574944416276,-3.0179491905884492
442.6000000000056,23.484898176704768,0.16506322070658364,-3.02193223647707
443.80000000000564,23.522768160249026,0.16271092483873972,-3.025042544581111
445.0000000000056,23.560387299862704,0.16390739118894526,-3.027775442616363
446.2000000000056,23.598055870246565,0.164250669174965,-3.03090698495739
447.40000000000566,23.63612744212477,0.1661867370128416,-3.0335205018341607
448.6000000000057,23.67395995775096,0.16677298913851812,-3.036831912338625
449.8000000000057,23.71179680426749,0.17051829187656775,-3.0400433450910542
451.0000000000057,23.749546161142973,0.17118047837028394,-3.044221238611601
452.20000000000573,23.78765639532823,0.1769567499725424,-3.0479077318374195
453.4000000000058,23.82536986635221,0.17784168888648777,-3.0494865917245426
454.60000000000576,23.863319891175383,0.18189647546185328,-3.051756570425094
455.80000000000575,23.901466602689055,0.18213612610983998,-3.0553117935341882
457.0000000000058,23.939296185484345,0.1859116922138866,-3.058821157735807
458.20000000000584,23.977118962402336,0.1923852062605773,-3.060502747848388
459.40000000000583,24.01507818033839,0.19816834061799282,-3.0639892661873724
460.6000000000058,24.05333137275203,0.20056842177301903,-3.065133461264579
461.80000000000587,24.091402907551352,0.2064151144015396,-3.0675999618743166
463.0000000000059,24.129297174859552,0.21084187833689372,-3.070341343606873
464.2000000000059,24.167152556783407,0.21641966812884528,-3.073434526636548
465.4000000000059,24.205218118055697,0.22250758473677612,-3.07580902183219
466.60000000000593,24.243261846132906,0.2250926581946886,-3.07818927834704
467.800000000006,24.281504011629078,0.2337274063540602,-3.080381003442901
469.00000000000597,24.319805984339354,0.23746319960922424,-3.0823460025256537
470.20000000000596,24.357894299552797,0.24100664451286358,-3.085184282116542
471.400000000006,24.395995632887136,0.24709318000774938,-3.0870381476905155
472.60000000000605,24.434256789429273,0.2507483849703205,-3.089811858929759
473.80000000000604,24.47233862704732,0.25730876091637844,-3.091763916887042
475.000000000006,24.51042251070957,0.26013035340455515,-3.0931195211717166
476.20000000000607,24.54876752583791,0.2707558855242922,-3.094319361189184
477.4000000000061,24.587174861630913,0.27328851216411154,-3.096842798923265
478.6000000000061,24.625387395616823,0.2799805343561461,-3.0987991288456573
479.8000000000061,24.663500366853384,0.2811775927798801,-3.1010689127201347
481.00000000000614,24.701807723858206,0.28455122499531393,-3.1041593879434117
482.2000000000062,24.740273320565045,0.28950335200123534,-3.10590261936931
483.4000000000062,24.7784909587289,0.2937258364091786,-3.107392272861917
484.60000000000616,24.817015505970144,0.29755972413658927,-3.109103358963332
485.8000000000062,24.855158811429256,0.3017168114857731,-3.1115894180025534
487.00000000000625,24.893650780037706,0.30195624107703756,-3.113497042491222
488.20000000000624,24.931867403992396,0.3061233613169094,-3.1143464609641
489.40000000000623,24.970207578733763,0.3094611394331501,-3.1164372929130333
490.6000000000063,25.008813576080662,0.3105211668201231,-3.1176972924528066
491.8000000000063,25.047074897051548,0.3145225678750452,-3.119368668205924
493.0000000000063,25.08568314683461,0.31781930525736857,-3.121452578667757
494.2000000000063,25.123916160639578,0.3178658215524006,-3.123576540802172
495.40000000000634,25.162515397968573,0.3199863576322719,-3.125376357805048
496.6000000000064,25.20121768777516,0.3237309049519248,-3.126354603132684
497.8000000000064,25.239742502771495,0.32398361305475465,-3.128485648227657
499.00000000000637,25.277869446302237,0.32612730390607236,-3.1297264342351547
500.2000000000064,25.316754009029914,0.33039950399310536,-3.132064384280814
501.40000000000646,25.35502579167029,0.33089523838156754,-3.1335185344303538
502.60000000000645,25.393277676096172,0.3318384804375403,-3.1347274261356306
503.80000000000643,25.431717853409125,0.3348050570762864,-3.1361346474288414
505.0000000000065,25.470452285149143,0.3349043917992618,-3.137800103262606
506.2000000000065,25.508636679393984,0.33755646264049566,-3.139224482318049
507.4000000000065,25.547520522815223,0.33651818221129326,-3.1406560009000177
508.6000000000065,25.58601725725912,0.3365968704336939,-3.142000592013444
509.80000000000655,25.624669159090633,0.33720878558621914,-3.1434901469985013
511.0000000000066,25.66313666707688,0.3419082718992623,-3.1448577995114446
512.2000000000066,25.701866079834243,0.34155399163974054,-3.1447823414611835
513.4000000000066,25.740312505889246,0.3440588169347696,-3.1461033820269177
514.6000000000066,25.778882006849877,0.3457580615278857,-3.1475529877341755
515.8000000000067,25.81744762534108,0.3450164728434404,-3.149076625955152
517.0000000000066,25.856198359999706,0.3466360121176786,-3.150385571841868
518.2000000000066,25.89473105495083,0.3453214568894034,-3.1509259152042493
519.4000000000067,25.93340849066143,0.3496693137543312,-3.151678278789678
520.6000000000067,25.97211975975084,0.347186336249814,-3.1530150856288213
521.8000000000068,26.010855035454792,0.34704903954317223,-3.1545447810556624
523.0000000000067,26.049300111621008,0.35058836682261085,-3.155888012478677
524.2000000000068,26.087962447087126,0.3498304955974725,-3.15744662865545
525.4000000000068,26.126915595949214,0.34728906381353397,-3.1581881197336408
526.6000000000067,26.165383899483516,0.35150209690801715,-3.1587298964882367
527.8000000000068,26.204258534280466,0.35236056940341576,-3.1607325514725666
529.0000000000068,26.242798529561757,0.35045336046281195,-3.1620836128692686
530.2000000000069,26.28164563144029,0.354099117868794,-3.163562086850094
531.4000000000069,26.319971772519487,0.35208452466015805,-3.1648074849386276
532.6000000000068,26.358792827439324,0.350041575329469,-3.164748762679741
533.8000000000069,26.397570483680564,0.35100634790393714,-3.1660511202895187
535.0000000000069,26.43671663193872,0.3528734376147875,-3.167392565078087
536.2000000000069,26.47530194775163,0.35244153258215705,-3.1683780004192705
537.4000000000069,26.51404259826302,0.35248420568933203,-3.1687697352127424
538.600000000007,26.552862485705706,0.3562215785283198,-3.170176175917647
539.800000000007,26.5913885865145,0.355673945439684,-3.1714643939695026
541.000000000007,26.630488950171678,0.35676000653937856,-3.172231955293264
542.200000000007,26.669370074163783,0.3556603906641307,-3.172776901489846
543.400000000007,26.707957496942875,0.3600210892249236,-3.1741159526453946
544.6000000000071,26.746992326610695,0.35831799217859794,-3.1755312862726064
545.800000000007,26.785576711006907,0.35776888003270435,-3.176907085390977
547.000000000007,26.824547570596998,0.35940325078578406,-3.1771311841618197
548.2000000000071,26.863152159568706,0.3665522456172343,-3.178153469192849
549.4000000000071,26.90193965214896,0.3734755591842245,-3.1781467635548575
550.6000000000072,26.94049017788065,0.381691302963721,-3.1794538436746955
551.8000000000071,26.979787971826113,0.38385880278946716,-3.180181396380856
553.0000000000072,27.018500619703904,0.3869954476723003,-3.180791793878944
554.2000000000072,27.057166288621048,0.38864629106398185,-3.182863698841409
555.4000000000071,27.09630731486676,0.39095695980570677,-3.1840771857231287
556.6000000000072,27.13514047817749,0.39251555953634054,-3.185351870698489
557.8000000000072,27.1738402741792,0.3945350764635913,-3.1854133754592198
559.0000000000073,27.212902032229824,0.39841922076939795,-3.1867128892806433
560.2000000000073,27.251884124993904,0.4028130593014887,-3.1878774792721627
561.4000000000073,27.290682587317935,0.40320293959482645,-3.1881380450916907
562.6000000000073,27.3301394218716,0.4056774656410129,-3.1893425380092424
563.8000000000073,27.369104404035667,0.4092151553468437,-3.190658081397729
565.0000000000073,27.40857294239641,0.40830072851746047,-3.19065861863109
566.2000000000073,27.44703509441862,0.40978512614384344,-3.1919587672876455
567.4000000000074,27.486058361976916,0.41436447090122064,-3.192663123510754
568.6000000000074,27.52504684268373,0.4158213915192426,-3.1939482621662805
569.8000000000075,27.564162707339715,0.41845731977597933,-3.1942060404244836
571.0000000000074,27.603077529251166,0.41717804862445984,-3.1946254427458403
572.2000000000074,27.642486141196976,0.42059451246089874,-3.195599884790936
573.4000000000075,27.6812653383129,0.4218047466500643,-3.1969526929500436
574.6000000000074,27.720724912688475,0.42501013430998835,-3.196968607853081
575.8000000000075,27.759302322779984,0.42462676611098904,-3.1982293840444616
577.0000000000075,27.798493438911184,0.4250826049286338,-3.1995466949635363
578.2000000000075,27.837670876023232,0.42294131366371257,-3.2003912537521044
579.4000000000076,27.87688954204827,0.4211892806621096,-3.2008605113404642
580.6000000000075,27.916163408871697,0.42048733996104337,-3.2009941139419458
581.8000000000076,27.955177097400966,0.4223841372868673,-3.202187412310376
583.0000000000076,27.994637248965688,0.4183074405257572,-3.2035764451359903
584.2000000000075,28.033611443812458,0.4201071107622778,-3.203493378650037
585.4000000000076,28.072886825229332,0.4199338259052128,-3.204273522151875
586.6000000000076,28.11195937523935,0.41606247734188795,-3.2055897289470687
587.8000000000077,28.151310715199514,0.4130127667915968,-3.2068540660655005
589.0000000000077,28.190594901312345,0.40966935835082996,-3.208208978707436
590.2000000000077,28.22998842154525,0.4078182233272607,-3.208259940311673
591.4000000000077,28.26936876000962,0.40312429673588346,-3.2085510404521074
592.6000000000078,28.308402062686895,0.397261335869765,-3.2088676548878485
593.8000000000077,28.34788773313163,0.3939275470461858,-3.2101734957858157
595.0000000000077,28.38717278136004,0.3917063092387185,-3.2101038255994547
596.2000000000078,28.426533824101522,0.3847183238218199,-3.2114990676828064
597.4000000000078,28.46588060199982,0.38322300117547203,-3.211524540507339
598.6000000000079,28.505354658279085,0.37987391863079445,-3.2129607190695513
599.8000000000078,28.54461626021211,0.37761008812323205,-3.2142869955630484
601.0000000000078,28.58385509813342,0.3766219485163065,-3.214240155809396
602.2000000000079,28.623229702543675,0.37127740521044905,-3.214192773466026
603.4000000000078,28.66240808591294,0.3674326512772814,-3.2155573830513093
604.6000000000079,28.701761056773755,0.36727841758015844,-3.216912063340937
605.8000000000079,28.74144013850189,0.3620596715587008,-3.216964619520039
607.000000000008,28.780640497888417,0.35735999759229964,-3.2181923361478626
608.200000000008,28.820259890636034,0.35752155906400107,-3.218195223625749
609.4000000000079,28.85982123625891,0.35663255971725616,-3.21951313612737
610.600000000008,28.898898958716735,0.3576463057773722,-3.2195139719554864
611.800000000008,28.938177538248326,0.3546778603905423,-3.2208210993067947
613.000000000008,28.977965127705836,0.3491178864835869,-3.220834883881545
614.200000000008,29.01717034704021,0.3518389193604634,-3.2221426889889724
615.400000000008,29.056485953385135,0.34942072603090923,-3.2221420984890625
616.6000000000081,29.096117628363693,0.35039978157328355,-3.2235176210401053
617.8000000000081,29.13555791928589,0.3466726384764538,-3.2234603383909195
619.0000000000081,29.175117994802854,0.3466859560045097,-3.223455177425284
620.2000000000081,29.21439543951576,0.34511748258159125,-3.2247599776911224
621.4000000000082,29.253698076104268,0.34329546420071,-3.2261422779130955
622.6000000000081,29.293288645030916,0.3426601260973867,-3.225400241628635
623.8000000000081,29.333014833822546,0.34320631514822164,-3.2254259170504334
625.0000000000082,29.372229024452892,0.3390692211140436,-3.226712469360773
626.2000000000082,29.411609263475444,0.34037291762370003,-3.228140193938007
627.4000000000083,29.45095718607991,0.3371854292230436,-3.227984493275726
628.6000000000082,29.490609897835345,0.33544978881936993,-3.228722471595147
629.8000000000083,29.530324269154825,0.3334021051272391,-3.2298007480238384
631.0000000000083,29.56952237747936,0.33074112970488345,-3.230040167141762
632.2000000000082,29.60913800140266,0.33361538315912376,-3.230040052173144
633.4000000000083,29.648259794715795,0.3303907506768906,-3.2313456990255265
634.6000000000083,29.68770738962362,0.32868471488780626,-3.2313126192129076
635.8000000000084,29.727506216673483,0.33240251444411784,-3.2326701527163775
637.0000000000084,29.76702160017206,0.32656642946528014,-3.2313747381498663
638.2000000000083,29.806533101540712,0.32725896190969883,-3.2327107946301084
639.4000000000084,29.845993628396652,0.325106196170164,-3.233493189959485
640.6000000000084,29.8858275097823,0.32568394242188026,-3.235361918271907
641.8000000000084,29.925289195715425,0.3229533759094225,-3.2353014386822796
643.0000000000084,29.964855864211607,0.32230801525670016,-3.235609751904292
644.2000000000085,30.004457523398234,0.32164698352943644,-3.2366249317411504
645.4000000000085,30.04428107662638,0.32072307988920024,-3.2356666787271706
646.6000000000085,30.083965541645153,0.3193614783335761,-3.2370082935350553
647.8000000000085,30.123608049954466,0.3189449174848398,-3.237936059168164
649.0000000000085,30.163301125963763,0.31754068795623813,-3.237852564115423
650.2000000000086,30.202982715931547,0.315102525701898,-3.2392479780033305
651.4000000000085,30.24266614070617,0.3145692580478858,-3.2392502402675474
652.6000000000085,30.282208180991695,0.3136438593157118,-3.2392645885963427
653.8000000000086,30.32183401633525,0.3105802866174474,-3.240568422194933
655.0000000000086,30.361926110292348,0.31158080912571773,-3.2405596547244233
656.2000000000087,30.40147185525092,0.3100299385184442,-3.2411135435328697
657.4000000000086,30.441071588981277,0.30652556668923037,-3.2418787204598134
658.6000000000087,30.480930751305443,0.3080546822641601,-3.24188083071133
659.8000000000087,30.520464250871534,0.3055110077271266,-3.24324610432239
661.0000000000086,30.55990461434245,0.3068641596033286,-3.2431900728379226
662.2000000000087,30.600021051712382,0.3041360306984886,-3.2431898930521386
663.4000000000087,30.63933106817029,0.3035529937371315,-3.2431896382278227
664.6000000000088,30.67889897777726,0.3040399523834212,-3.2430437037022366
665.8000000000088,30.719334554589384,0.30258697249727007,-3.243516275693365
667.0000000000088,30.75876961354485,0.30459685602272524,-3.2435201148173527
668.2000000000088,30.798346128390918,0.3007178330357936,-3.24352569629798
669.4000000000088,30.837816680347274,0.3050271348861555,-3.2448527626419454
670.6000000000088,30.87799860429049,0.3012278207602377,-3.2448409491556793
671.8000000000088,30.917364217693283,0.3004138977340247,-3.2456505204766675
673.0000000000089,30.957525407205377,0.29972874081401923,-3.24615035616679
674.2000000000089,30.997003275504657,0.2996447346369058,-3.2461578052081363
675.400000000009,31.037002062797253,0.2986220329403584,-3.2464268225385116
676.6000000000089,31.076690427404127,0.29746739129820643,-3.2474674289196175
677.8000000000089,31.11651622166298,0.2936011689885656,-3.247463001328744
679.000000000009,31.156183417038278,0.29305703494301993,-3.2487744960513543
680.2000000000089,31.196021249790867,0.29528215871838404,-3.2487898079910504
681.400000000009,31.23543815801271,0.2929826602888672,-3.2487321311363724
682.600000000009,31.27544717415541,0.29134799248906096,-3.25009009064821
683.800000000009,31.315084852624924,0.2912642820714253,-3.2500998466869837
685.0000000000091,31.355046991697435,0.2918322667099835,-3.2500999005130145
686.200000000009,31.394681822947163,0.29145563044414,-3.250099864075257
687.4000000000091,31.434255779634793,0.28781779586775724,-3.250092875911715
688.6000000000091,31.474098845918185,0.2906124463548392,-3.251394943802327
689.800000000009,31.513895223014664,0.29008240186373535,-3.251373059382411
691.0000000000091,31.55361696960183,0.28552224466540443,-3.2527179428670943
692.2000000000091,31.593268820441494,0.2858747743610124,-3.2523945342658185
693.4000000000092,31.633386172047558,0.2850001467728698,-3.252421583678972
694.6000000000092,31.673346590250997,0.283855168717728,-3.2537902287700513
695.8000000000092,31.7132335025255,0.28241819184486805,-3.2527166658187707
697.0000000000092,31.752928130048986,0.2803717637252987,-3.2524115696251914
698.2000000000093,31.792819942576287,0.2772021342369184,-3.252726387948016
699.4000000000092,31.83263611733086,0.27758265544826144,-3.255054494157781
700.6000000000092,31.872575049642318,0.27762463367114365,-3.2550479418042007
701.8000000000093,31.912428051934725,0.2804016189893237,-3.2537296528147444
703.0000000000093,31.95206598091704,0.27910428252096997,-3.2537271355676225
704.2000000000094,31.991702780383378,0.2800102495603163,-3.2531351625057336
705.4000000000093,32.031950280476686,0.27901182437153027,-3.2537143400572273
706.6000000000093,32.071569388841596,0.27752065474895016,-3.2537402399012247
707.8000000000094,32.11171745452821,0.27325561674170684,-3.2550439453766593
709.0000000000093,32.15131124144418,0.2714842061934144,-3.255799277625492
710.2000000000094,32.191339625999575,0.2713413513912655,-3.257349169115578
711.4000000000094,32.231121995126195,0.27132177794923473,-3.257375354499681
712.6000000000095,32.2709300320881,0.2701242396778132,-3.2563605408510767
713.8000000000095,32.310780689739346,0.266953202291063,-3.256402162257406
715.0000000000094,32.3505849452562,0.26571318992867,-3.2566898988127164
716.2000000000095,32.39015317013003,0.26192277985441415,-3.2572959259811745
717.4000000000095,32.43055732619472,0.2603251661276027,-3.2590920234663017
718.6000000000095,32.47026688595975,0.26377201670543826,-3.2593198039164686
719.8000000000095,32.510349983505925,0.26029488538090684,-3.2593177272760707
721.0000000000095,32.55012595802187,0.25971071958412617,-3.2606533290016593
722.2000000000096,32.590005155251475,0.25606978245862955,-3.25997348911252
723.4000000000096,32.63019941062578,0.2539913642321996,-3.259305431415908
724.6000000000096,32.670218506004396,0.2551316599256763,-3.2606287114391863
725.8000000000096,32.709843759171534,0.25278789415654623,-3.260629869152412
727.0000000000097,32.750293009772285,0.251073285389368,-3.2606326395824836
728.2000000000096,32.78991725068042,0.2459399424499713,-3.2613560882710866
729.4000000000096,32.83007167311204,0.24209783952249841,-3.2606399122750975
730.6000000000097,32.869942621611465,0.2445626611755496,-3.2606436183219554
731.8000000000097,32.910181558678474,0.24126142234182213,-3.2619554357628164
733.0000000000098,32.95015756630312,0.23987899749120034,-3.262290183363364
734.2000000000097,32.99016819610679,0.23554631468460796,-3.262590967001999
735.4000000000098,33.03015046184331,0.23602646765327062,-3.262196365884151
736.6000000000098,33.07003360159598,0.23511152976172722,-3.262276160528393
737.8000000000097,33.11011639382136,0.23380391784905763,-3.263346814901014
739.0000000000098,33.15015692699933,0.23106209233443842,-3.2649670458183113
740.2000000000098,33.19014836111432,0.2286612970124331,-3.2649201935203305
741.4000000000099,33.230371087817005,0.2250341471408932,-3.2649199825861324
742.6000000000099,33.27039288632084,0.22415653268037383,-3.264925997788399
743.8000000000098,33.310593004476985,0.22042435139711314,-3.266234575894978
745.0000000000099,33.34981647363145,0.21523675399522713,-3.2662301179638358
746.2000000000099,33.39081256786815,0.21905133169138935,-3.2662301200233754
747.4000000000099,33.43070361903125,0.21371051383461115,-3.266228546899417
748.6000000000099,33.470546714790316,0.2158042081152094,-3.2655672340873143
749.80000000001,33.51100672797354,0.21356304572145612,-3.26524028629312
751.00000000001,33.55104573932579,0.21090703812266653,-3.265251825324884
752.20000000001,33.5912586688021,0.2071844846622013,-3.266565628347254
753.40000000001,33.63158842945654,0.20618433650532175,-3.26656085072329
754.60000000001,33.67154907119,0.20692971147296513,-3.267959222109099
755.8000000000101,33.71111912056522,0.20078521389638215,-3.26788048235663
757.00000000001,33.75183800192097,0.20000197356177152,-3.267876699388756
758.20000000001,33.792107515215505,0.19802833765386252,-3.2691668812617607
759.4000000000101,33.83255285944425,0.19626681406974766,-3.2691903329210974
760.6000000000101,33.87276072019572,0.18973555611482285,-3.268833951955501
761.8000000000102,33.912803145892674,0.19263393582386934,-3.269567127240504
763.0000000000101,33.95335865816772,0.19015464904006585,-3.2701782427938273
764.2000000000102,33.99354292645587,0.1859704296494904,-3.2701780013276798
765.4000000000102,34.03372678839819,0.1868215922346641,-3.27022616567869
766.6000000000101,34.07422913111098,0.1867341705068477,-3.270179833082385
767.8000000000102,34.1144987687734,0.18164382040562854,-3.2700759157074692
769.0000000000102,34.1546762933654,0.18510444771501433,-3.268818843126758
770.2000000000103,34.19506631597901,0.18334955463616387,-3.2710479883274486
771.4000000000103,34.23528214794236,0.1782029421164717,-3.2714889870774417
772.6000000000103,34.27573573971569,0.17627452191456916,-3.2714653265292757
773.8000000000103,34.31601537654805,0.17636685583179945,-3.271232053721309
775.0000000000103,34.35647955365689,0.17274058865704456,-3.2723383476935477
776.2000000000103,34.39670156564181,0.1687398672736662,-3.2724796494544544
777.4000000000103,34.43701578406401,0.17076902727478194,-3.272480988313372
778.6000000000104,34.47739309343256,0.1679032253720436,-3.27382393030002
779.8000000000104,34.517704914624254,0.1659072718275505,-3.2720238097381693
781.0000000000105,34.558341375051135,0.16605199225975475,-3.269584667620693
782.2000000000104,34.59874162149538,0.16465990459136037,-3.2726658241433237
783.4000000000104,34.63896192631556,0.16552975929433256,-3.27401893015733
784.6000000000105,34.6795486670475,0.1630293576940871,-3.274019965806831
785.8000000000104,34.719999790497944,0.15798217041757612,-3.2740199571103155
787.0000000000105,34.76014335789989,0.16173828649503497,-3.27401995985284
788.2000000000105,34.80071401899424,0.16024292336939272,-3.2740204825715375
789.4000000000106,34.84109516379122,0.1588441023880729,-3.274117478060761
790.6000000000106,34.88153372435789,0.16194649391112348,-3.273586787502121
791.8000000000105,34.92226857586182,0.1562382286246402,-3.2743482456416024
793.0000000000106,34.962678694646755,0.1575904240300927,-3.2743501748150345
793.8000000000106,34.989779195321546,0.16155423130376256,-3.2743501851469765