File: 01_Data/Coaxial_Cable/STA/N2/10K_min/Coaxial_Cable_STA_N2_10KData_220715_R2.csv
##Temp./Â°C,Time/min,DSC/(mW/mg),Mass loss/mg
50.0,10.646547426505162,0.01915110066237191,0.03982835651113836
51.000000000000014,10.975784558698814,0.060446875168014724,0.04007848754725796
52.00000000000003,11.183683968502368,0.0878369655528215,0.04008160615731171
53.00000000000004,11.356677135284599,0.1116259368438568,0.0406150870247064
54.00000000000006,11.506553235379675,0.1288019311896189,0.042042692036371676
55.00000000000007,11.644875829793397,0.1465786453197504,0.041988162582608624
56.000000000000085,11.77664817336431,0.16074983841969104,0.04199029065982973
57.0000000000001,11.89943935370828,0.17180448316957242,0.041807920576646396
58.000000000000114,12.021226556046281,0.1833687355014939,0.04326949371195177
59.00000000000013,12.138576710464633,0.18627343242451322,0.043014650753481654
60.00000000000014,12.254457028447733,0.1946480278320839,0.043140307808998024
61.000000000000156,12.366232048890831,0.19897060575375947,0.04317531028933086
62.00000000000017,12.478683643099217,0.20325917320649567,0.04326110746856937
63.000000000000185,12.587637641414299,0.20625655106659413,0.04464880466987253
64.0000000000002,12.698242760952066,0.2092888020733772,0.04335931527633363
65.00000000000021,12.808785778164896,0.2127999703547232,0.04277708119730583
66.00000000000023,12.915588037121383,0.21360899948632572,0.043364027036118635
67.00000000000024,13.02415707287108,0.21408017517212374,0.04457224341904542
68.00000000000026,13.130857696399234,0.21349974482824297,0.04458065657593302
69.00000000000027,13.239767194077007,0.21839741367813392,0.04457002050397474
70.00000000000028,13.345335981575728,0.21851911710735172,0.04455519903370675
71.0000000000003,13.451952864441576,0.21996553954652476,0.044573144302428425
72.00000000000031,13.557897466371013,0.22059283681148956,0.04457030885102142
73.00000000000033,13.66040312347314,0.22193803688414937,0.044656942755200824
74.00000000000034,13.768882908448678,0.2232091965014943,0.044840783453885535
75.00000000000036,13.873989023553841,0.22424198241454874,0.04589524589113125
76.00000000000037,13.97841170838772,0.2273407490118119,0.0470717691168554
77.00000000000038,14.081915190072328,0.22816839615971096,0.04459338081678066
78.0000000000004,14.18658334002421,0.23050108414105064,0.04455178028778395
79.00000000000041,14.290608049648059,0.23127167855352682,0.04478969646647801
80.00000000000043,14.392768728881936,0.2333978816060026,0.046267450518775455
81.00000000000044,14.497349872468419,0.23504247992093152,0.0452284687644493
82.00000000000045,14.598834563607266,0.23693074753848065,0.04589821690275908
83.00000000000047,14.699955056162725,0.24076606061902173,0.046286411788683424
84.00000000000048,14.802622754734877,0.2403342153959721,0.04589073394165499
85.0000000000005,14.903767447935259,0.24348531487895042,0.04588552251171407
86.00000000000051,15.00440996473766,0.24598006270079176,0.04720033974095639
87.00000000000053,15.105246418686084,0.24801157780918992,0.047270390520871786
88.00000000000054,15.20583638692085,0.2513457727382058,0.04725295150797404
89.00000000000055,15.307173248543323,0.2521446688108472,0.04721057667375206
90.00000000000057,15.405116200339164,0.2546063109693255,0.047210236272830386
91.00000000000058,15.505697056184216,0.25687943630341403,0.048531731928047606
92.0000000000006,15.602003913070691,0.25819551356237846,0.04851983537870996
93.00000000000061,15.703885114980752,0.2587871310854738,0.04856516775166497
94.00000000000063,15.803634027948426,0.26117962744753964,0.04852205641228835
95.00000000000064,15.899819075790608,0.2650188935743749,0.047870128531167566
96.00000000000065,16.001510779019945,0.2684146055033618,0.04851810884249286
97.00000000000067,16.101584732535297,0.26985945726941873,0.04720665914747357
98.00000000000068,16.200010061431787,0.27348039582451755,0.04851893909795901
99.0000000000007,16.299485497861856,0.27643030590410345,0.049233596404118174
100.00000000000071,16.396765455048715,0.2768529385999592,0.04708727511710986
101.00000000000072,16.49536226058033,0.2807180587712379,0.048519753652820796
102.00000000000074,16.5934988868777,0.2797657195141575,0.04952101639218842
103.00000000000075,16.692393008977064,0.2826018689122419,0.0498093400628159
104.00000000000077,16.79010196079825,0.28635993811856086,0.0498399878777116
105.00000000000078,16.888202711929374,0.2867042614553159,0.05011945475311297
106.0000000000008,16.98705766848846,0.28731943006874316,0.04891230263199553
107.00000000000081,17.084118698774937,0.2900688332410485,0.04819998812211157
108.00000000000082,17.18221137701021,0.29127332460013733,0.04829029482865721
109.00000000000084,17.27968522705085,0.2950720585736004,0.049840119008115025
110.00000000000085,17.377666834820914,0.29828169076488265,0.049837052707847995
111.00000000000087,17.47587473534356,0.30212371043174324,0.048555273997621384
112.00000000000088,17.574057256680994,0.3037322471997439,0.04983974244298839
113.0000000000009,17.671014959605447,0.3045797230190742,0.0508298770424922
114.00000000000091,17.768886796311456,0.30971920679389986,0.05116980037472452
115.00000000000092,17.86570441883255,0.31048164454037697,0.04852362623781126
116.00000000000094,17.962598577596903,0.3170841073765768,0.0503648850132139
117.00000000000095,18.060339684224108,0.32256269251113745,0.05083973915300444
118.00000000000097,18.157630444102193,0.3252817293579999,0.05079011461645422
119.00000000000098,18.2546616567001,0.3323212432600561,0.05191455408898449
120.000000000001,18.352614048573443,0.3426075670916543,0.051166437033835166
121.00000000000101,18.450256872905655,0.3543212781308762,0.05083010217417616
122.00000000000102,18.547378748293383,0.36905580490443757,0.05215681360694013
123.00000000000104,18.642843298828865,0.395323079318599,0.052150508255579986
124.00000000000105,18.742506896412962,0.4318270506999059,0.0521501880846964
125.00000000000107,18.840477138296066,0.4869032079583483,0.05216691743917412
126.00000000000108,18.93775509226822,0.5601396689280479,0.05215163528554889
127.0000000000011,19.03512464506203,0.6441441526738552,0.05215015600745687
128.0000000000011,19.132758874643383,0.7145510279727312,0.0521501618618494
129.00000000000114,19.230370271488397,0.7116086571089539,0.05221471565321689
130.00000000000114,19.32524627832153,0.5639589740162324,0.05214934680485772
131.00000000000114,19.425448704154046,0.43125833074931297,0.04950672888251706
132.00000000000117,19.52121529730168,0.3616783617497028,0.05214832640349787
133.0000000000012,19.617548648806643,0.31930567365013274,0.05214989197876019
134.0000000000012,19.714294752374098,0.2978591971077056,0.052149618235988626
135.0000000000012,19.809547438857066,0.28682437963626894,0.05217531802481368
136.00000000000122,19.905682869227554,0.27717013008725166,0.05084066682707267
137.00000000000125,20.002082134337094,0.27219856862300784,0.05351054197317051
138.00000000000125,20.09771962259142,0.2704321645096913,0.05207480071330206
139.00000000000125,20.195018401503063,0.26845361394261746,0.052146230899688284
140.00000000000128,20.290307398628865,0.26766491228272427,0.05182014043392513
141.0000000000013,20.38726243757175,0.26921014200040594,0.05182012399969427
142.0000000000013,20.483139816411498,0.2689157138047382,0.0518201264621414
143.0000000000013,20.57898504978592,0.2685253050213008,0.05215104143879046
144.00000000000134,20.67590912582768,0.27013982568920025,0.05082214947568975
145.00000000000136,20.771002015403855,0.26687109246419227,0.05214985563575514
146.00000000000136,20.86678999929887,0.2695235033848373,0.0521498601616619
147.00000000000136,20.962757178009515,0.27146061704179136,0.052173328706889954
148.0000000000014,21.05858791670366,0.27354184015196925,0.05213985943290922
149.00000000000142,21.153700899258347,0.27176108866376525,0.052139828068420435
150.00000000000142,21.251064653165965,0.2733405244034597,0.05213934602844983
151.00000000000142,21.34757559182004,0.27506563472221657,0.05247977962169781
152.00000000000145,21.443560263857208,0.27506766122025206,0.05215533591352006
153.00000000000148,21.538487599416072,0.2766245676864474,0.051115218251864825
154.00000000000148,21.634213677531623,0.27861895696979877,0.05347021809303776
155.00000000000148,21.730570822894464,0.2791497111114013,0.05215033218278364
156.0000000000015,21.826013139341416,0.28177323955294564,0.052192682038291416
157.00000000000153,21.92183356346151,0.2818943604720794,0.052784069820924095
158.00000000000153,22.01708498297419,0.28212070985560855,0.05296489132076765
159.00000000000153,22.11304161086721,0.2830109375441835,0.05216125951753536
160.00000000000156,22.208780233646696,0.28426776992942315,0.05280995880392325
161.0000000000016,22.30385760774053,0.2839115085816938,0.05214829062545778
162.0000000000016,22.39952561827568,0.28284490250012606,0.05181689710111126
163.0000000000016,22.49620543460898,0.28188223488917763,0.05148995671432477
164.00000000000162,22.592437470838206,0.2807136045739752,0.05212077125152881
165.00000000000165,22.687551217999566,0.2801578145640041,0.05344995449716183
166.00000000000165,22.783073394828197,0.2802823752756076,0.05215002950416103
167.00000000000165,22.879075654522435,0.27739150178464844,0.05215005983216425
168.00000000000168,22.974720104965577,0.27927970003590064,0.0534561256909889
169.0000000000017,23.069543750712935,0.2790062606697723,0.05346414799311372
170.0000000000017,23.166026146349633,0.2807896178880641,0.051162013524609584
171.0000000000017,23.260622734262,0.2802422515075409,0.05116070520391425
172.00000000000173,23.355366704078097,0.2818235962013531,0.05222185145407909
173.00000000000176,23.451706745793746,0.2815860558494908,0.05215349172152006
174.00000000000176,23.54848065088284,0.2827007384828484,0.05216089205100349
175.00000000000176,23.643959001688774,0.28315164059791764,0.0508549605814661
176.0000000000018,23.739541330315248,0.28242165739371805,0.05215019981662827
177.00000000000182,23.83582906191402,0.28314828583776186,0.052156551460238454
178.00000000000182,23.929627346858183,0.28343311670456506,0.04951825366594509
179.00000000000182,24.025233252452914,0.2828460640240861,0.05084291309486222
180.00000000000185,24.12075867549227,0.2857382469457045,0.05083997055534262
181.00000000000188,24.21647749384605,0.2865183633931008,0.05215035244905142
182.00000000000188,24.312135531175635,0.28611858865270556,0.050191759573142924
183.00000000000188,24.407075808731637,0.28622811184286523,0.04984886710388281
184.0000000000019,24.503042455340523,0.2873921079134307,0.049850608959183695
185.00000000000193,24.598498713512207,0.28765165406461657,0.04984000011489531
186.00000000000193,24.693427757535982,0.28668280065511886,0.049834499329749704
187.00000000000193,24.788552911609344,0.28824911839796075,0.050829990045258455
188.00000000000196,24.884209580584137,0.2881378591551169,0.049506337390272215
189.000000000002,24.978793616524328,0.2889079337247775,0.049510310482919095
190.000000000002,25.074069077841866,0.2888002671016948,0.04818848697508127
191.000000000002,25.16986989899238,0.2908546512472109,0.04819333223166833
192.00000000000202,25.264947017468202,0.2901300060843873,0.04951089494836669
193.00000000000205,25.35872169449003,0.2918490085173475,0.04851999567414911
194.00000000000205,25.45388154734281,0.29213792791958093,0.048543255387273554
195.00000000000205,25.549170000000196,0.2913438706036696,0.04786993672579953
196.00000000000207,25.64408158853785,0.28915219851643137,0.0465495810278842
197.0000000000021,25.73877773685495,0.29161249804283074,0.04654983959144765
198.0000000000021,25.83391929160415,0.29219163236540846,0.04562102479764096
199.0000000000021,25.930324592608088,0.2931241063475477,0.045560160254225046
200.00000000000213,26.026020715568414,0.29304289936737316,0.04556017118400302
201.00000000000216,26.116969760350727,0.29333194853610445,0.04490399111671195
202.00000000000216,26.215572147899557,0.2927207219093365,0.04455204216839537
203.00000000000216,26.31139480714645,0.2943751223942819,0.044580059961793594
204.0000000000022,26.403016804312823,0.29542110063910554,0.044574258716922444
205.00000000000222,26.500566963657715,0.2983798314026982,0.04193629902681728
206.00000000000222,26.596625360283998,0.29650488205569614,0.04193992805800395
207.00000000000222,26.691164780887522,0.2975358559012709,0.0419721480413795
208.00000000000225,26.78578821285293,0.2980159085871575,0.04161037110843768
209.00000000000227,26.880801943688308,0.30148719803443835,0.04029016631462756
210.00000000000227,26.97655871955924,0.300234847584748,0.040290059660832434
211.00000000000227,27.071698110384286,0.30248687335047886,0.04005297725509571
212.0000000000023,27.167212450745424,0.30384498081114536,0.03798013294734437
213.00000000000233,27.261698498089963,0.3044393476523445,0.036655006340156504
214.00000000000233,27.35766739385721,0.30562570653120213,0.036009447922198845
215.00000000000233,27.452637854543266,0.30975591337646535,0.03466451917550506
216.00000000000236,27.547888137107154,0.3113048692062664,0.03239333141946332
217.0000000000024,27.643327575819114,0.3129449455688119,0.03200756514140091
218.0000000000024,27.73945147732715,0.3169132902998578,0.03074172487579041
219.0000000000024,27.83344834847601,0.31864273151918693,0.02902986401157648
220.00000000000242,27.92973716376484,0.321395296082561,0.027778008049462066
221.00000000000244,28.024631313784948,0.32494534022696053,0.027684167056726938
222.00000000000244,28.120222995545962,0.3293411611395738,0.026383401508198734
223.00000000000244,28.214314152476824,0.3312307379093805,0.023508344137344483
224.00000000000247,28.310020154256495,0.3350880470470544,0.023514235368014003
225.0000000000025,28.405484150273583,0.33929788455444326,0.021185738547514266
226.0000000000025,28.500837812248882,0.34451305005910604,0.01888634211338358
227.0000000000025,28.59620920369145,0.34549241244523,0.01757032498381106
228.00000000000253,28.691817927786143,0.3495706338509452,0.015619209419750923
229.00000000000256,28.786914060863882,0.3535422460958827,0.012957884517522444
230.00000000000256,28.882960802529983,0.35518916877912154,0.01162790051580842
231.00000000000256,28.978875822041378,0.3588551059373065,0.008998505587662908
232.0000000000026,29.07364707695165,0.3619672354889297,0.006305643293714969
233.00000000000261,29.168813870707545,0.36292694953755206,0.0031239395285527216
234.00000000000261,29.263747730530397,0.3658285608104735,0.0011055229664944655
235.00000000000261,29.359660086502483,0.37093131594882844,-0.0008367602629206772
236.00000000000264,29.455180683540554,0.372337742682523,-0.0033635653768357976
237.00000000000267,29.550038788569736,0.3741473318680092,-0.007682404411961219
238.00000000000267,29.643934048521388,0.37645150608347105,-0.010365692686341799
239.00000000000267,29.740470697183255,0.3752600370072249,-0.013071633492703683
240.0000000000027,29.836681672259704,0.3793068825267,-0.016454956702564694
241.00000000000273,29.93181405187754,0.3808640634072986,-0.020290526078947213
242.00000000000273,30.027445254083347,0.3794203186835059,-0.02301508549281328
243.00000000000273,30.12203100288166,0.38276631862285015,-0.02990917817185723
244.00000000000276,30.21786654942291,0.3812314891804256,-0.03189992625741267
245.00000000000279,30.31247544135784,0.3837889119537207,-0.03627797745712735
246.00000000000279,30.40690387861454,0.3816784975870762,-0.04093888756963038
247.00000000000279,30.503705262822947,0.38250024556526613,-0.04622806932698742
248.0000000000028,30.598578687607237,0.3821309395960578,-0.051215969139069006
249.00000000000284,30.6930962469501,0.3822995046184977,-0.0552428004641623
250.00000000000284,30.788287999451285,0.38038889413263266,-0.05986534579266545
251.00000000000284,30.885043651194223,0.38133873805584445,-0.06589362329699
252.00000000000287,30.978593360441653,0.38126030628163843,-0.07092340712130696
253.0000000000029,31.07436052612098,0.3804734047524513,-0.07649185282171
254.0000000000029,31.170103185333755,0.3816481806266494,-0.0824847333442178
255.0000000000029,31.2642541139537,0.38057597738247884,-0.08828049466490384
256.00000000000296,31.360205040195055,0.3841417274596502,-0.09599991774982009
257.00000000000296,31.454964001750604,0.38668293153868977,-0.10181391443624488
258.00000000000296,31.551387202367618,0.3888282170280428,-0.10944021221500932
259.00000000000296,31.645212080417696,0.39250235031615405,-0.11589875584419218
260.00000000000296,31.74118085379214,0.3954913530203292,-0.12247350274367363
261.000000000003,31.83532802285152,0.40031262232663856,-0.12992386936772826
262.000000000003,31.931482127445555,0.4060395025807765,-0.13829973929271278
263.000000000003,32.02449079541438,0.4075422238003093,-0.1475428100038978
264.00000000000307,32.12160558452288,0.4144831155944432,-0.1552971445110134
265.00000000000307,32.21841740226042,0.4195303985252029,-0.1622261717161262
266.00000000000307,32.31323821989141,0.42358032686514924,-0.17260987752596835
267.00000000000307,32.40886841160632,0.42788261134792116,-0.18199013766025507
268.00000000000307,32.50340500477693,0.4348384307951288,-0.1919915216509338
269.0000000000031,32.59927687285687,0.43703614090426035,-0.20212256300818598
270.0000000000031,32.69499826845643,0.44052528621983567,-0.2111290581956342
271.0000000000031,32.791064807972944,0.44324919866854134,-0.22267525778993402
272.0000000000032,32.88497840521437,0.4468944225738748,-0.23183811813425326
273.0000000000032,32.980264065249706,0.4503308709533666,-0.24422973675281012
274.0000000000032,33.075843063545655,0.45618589054088154,-0.2538963101627032
275.0000000000032,33.171760651682234,0.4589169595411531,-0.26638992636139047
276.0000000000032,33.2669019387202,0.45961638558800944,-0.27853271350456366
277.00000000000324,33.36254333569731,0.46203844971869956,-0.2897698197026184
278.00000000000324,33.45917000000031,0.4630932795684941,-0.30365992799967945
279.00000000000324,33.553624022663364,0.46494369920875783,-0.3158405380428091
280.0000000000033,33.65036874822702,0.46809226374034185,-0.3288090729721489
281.0000000000033,33.74490441548571,0.4683322345708702,-0.3420222156479702
282.0000000000033,33.84176907419944,0.466943661922944,-0.35743875385406065
283.0000000000033,33.936246191606635,0.46634787086699603,-0.3705941457514945
284.0000000000033,34.032813648530635,0.465921584108387,-0.3865012401687622
285.00000000000335,34.12671328380082,0.4635508647312411,-0.3996464565268716
286.00000000000335,34.22211477116459,0.4613247124308141,-0.41513436536434023
287.00000000000335,34.318451536248354,0.4566041531524598,-0.43081236988758276
288.0000000000034,34.41346216034666,0.4510945817255877,-0.44903307578346485
289.0000000000034,34.509506427206006,0.4452131421988477,-0.4668746166504967
290.0000000000034,34.60514698337392,0.4382414803223895,-0.4852139284654404
291.0000000000034,34.700305495466296,0.43318816917507863,-0.5051926402374423
292.0000000000034,34.795670892186536,0.42989105931480065,-0.52691293750605
293.00000000000347,34.89127703160423,0.42569583968684876,-0.5458676887371414
294.00000000000347,34.98710328862475,0.42058793050740007,-0.5725061961805387
295.00000000000347,35.08189340438663,0.41122023403911634,-0.5950372616479749
296.0000000000035,35.178171984113334,0.39885214619998494,-0.6174668142812414
297.0000000000035,35.27374533189069,0.3857622719198299,-0.6400433097999767
298.0000000000035,35.368320707032446,0.3717214472425065,-0.6638531036083228
299.0000000000035,35.46459535918494,0.36165933937154265,-0.6871765574538662
300.0000000000035,35.55997120172073,0.35836202587705623,-0.7109468350967973
301.0000000000036,35.655448723385426,0.36149681867107364,-0.7339616485652494
302.0000000000036,35.750856019344255,0.3731481522149477,-0.7576965560891735
303.0000000000036,35.847264563205826,0.3894263889039524,-0.781211945423864
304.00000000000364,35.94235313755178,0.40576442890011355,-0.8043071784892262
305.00000000000364,36.037922981449675,0.4158338753024008,-0.8263875733624264
306.00000000000364,36.13361173471684,0.43095298910286717,-0.8495270348315955
307.00000000000364,36.230996315518695,0.44439044498071795,-0.8725150354837896
308.00000000000364,36.32594671242658,0.4521163819223362,-0.8955056107350665
309.0000000000037,36.42181255328403,0.45875430378074444,-0.9202422189524491
310.0000000000037,36.518074965778965,0.4634276360449596,-0.942655295401531
311.0000000000037,36.61465243943009,0.4650005864896396,-0.9677714566366125
312.00000000000375,36.70970171787383,0.4641057189216495,-0.9913646606872226
313.00000000000375,36.807101176063085,0.46179967168152747,-1.0172830154037964
314.00000000000375,36.901691909962814,0.45842254092533274,-1.0415919381997627
315.00000000000375,36.9982011880886,0.45242196413951896,-1.0651273797328753
316.00000000000375,37.09410009624676,0.44426262477518197,-1.0884382338826555
317.0000000000038,37.19021843247897,0.4328801127583357,-1.1124404328696538
318.0000000000038,37.28564553736976,0.42306727524404003,-1.1346723458324752
319.0000000000038,37.38222199624167,0.41315637110848136,-1.1577949295950885
320.00000000000387,37.477752771080176,0.3980986345873935,-1.1773636698525172
321.00000000000387,37.57402943284807,0.3851211566193925,-1.1995214258550164
322.00000000000387,37.669622805241296,0.37496758506668726,-1.219467236667319
323.00000000000387,37.76567194033006,0.3615584002248795,-1.238615811244923
324.00000000000387,37.86092906385891,0.3494286362907121,-1.2574667502301105
325.0000000000039,37.95673229015509,0.3375775273526535,-1.2725665796857313
326.0000000000039,38.05301368810931,0.32763015940352713,-1.289899737823828
327.0000000000039,38.149257413047,0.320542430730678,-1.305343367203918
328.000000000004,38.245335866419126,0.30853317686804554,-1.3174601117851958
329.000000000004,38.3408513824729,0.2974831734503731,-1.3318737183178428
330.000000000004,38.43611723408223,0.2878503996061289,-1.3422815337366227
331.000000000004,38.53283232836554,0.279063333169865,-1.3542872302975195
332.000000000004,38.62936347273348,0.2677918316582621,-1.363298866672498
333.00000000000404,38.72585709485054,0.2568219015193065,-1.3720854297288319
334.00000000000404,38.820620332305836,0.2479582065982947,-1.3810597799621078
335.00000000000404,38.91597514856361,0.2394831225516379,-1.3886320765860507
336.0000000000041,39.0124804966056,0.23088798467982175,-1.3946319795563444
337.0000000000041,39.107495206251315,0.2227045865293681,-1.4021222671266709
338.0000000000041,39.204653202972935,0.21530953729631647,-1.4073147722292818
339.0000000000041,39.3012807096423,0.20629296759901244,-1.4135558297284154
340.0000000000041,39.39707652553498,0.2001697768071211,-1.4179306813186687
341.00000000000415,39.49340191862665,0.1950230504337342,-1.422548110329712
342.00000000000415,39.58927166929769,0.1888539295611243,-1.4275105099794398
343.00000000000415,39.6865598926659,0.18180456802194384,-1.430132611709372
344.0000000000042,39.78259300291622,0.1769347055873104,-1.4348033280147474
345.0000000000042,39.879266668640945,0.1717454447355638,-1.4347678593775903
346.0000000000042,39.9744687222844,0.16687149903754883,-1.4397134198521302
347.0000000000042,40.072116778797074,0.1633311412403069,-1.4429851960970108
348.0000000000042,40.16844671103878,0.1586389804038142,-1.4455891414730302
349.00000000000426,40.26451260241205,0.1555135039432528,-1.4483043043845183
350.00000000000426,40.36047815879132,0.14983058461930304,-1.4509194756283748
351.00000000000426,40.45723910910132,0.14689075805002189,-1.4525372820116793
352.0000000000043,40.55419820771587,0.14180723894584557,-1.4551520897799204
353.0000000000043,40.65018087853185,0.13798318623977873,-1.4572325110820912
354.0000000000043,40.74633355820982,0.13503804991260515,-1.4576128085793294
355.0000000000043,40.84385923959212,0.13381344276767526,-1.4601217397183244
356.0000000000043,40.94005343456328,0.13077157834343572,-1.461604947944814
357.0000000000044,41.03706492465413,0.12929652559191868,-1.4641967591522804
358.0000000000044,41.13259002245574,0.12601511428872547,-1.4641697694832994
359.0000000000044,41.22970203198521,0.12445127090849906,-1.4652049356834418
360.00000000000443,41.325065715425374,0.12286303300504331,-1.4668140923429922
361.00000000000443,41.4234550281661,0.12192854094541283,-1.4687768967674808
362.00000000000443,41.51945179174054,0.12059309418420744,-1.468790124510746
363.00000000000443,41.61616329671568,0.1197815154929141,-1.4700837384119212
364.00000000000443,41.7131394742968,0.12032283087611995,-1.4714202884330283
365.0000000000045,41.809371033799,0.12252290481104133,-1.4714226966711537
366.0000000000045,41.9061594933947,0.11990593590944454,-1.4714243798587994
367.0000000000045,42.003154518185255,0.1201661383221358,-1.4739472095595403
368.00000000000455,42.099890496028316,0.11813803337502982,-1.4727360366772833
369.00000000000455,42.19697684335184,0.11890324614384595,-1.4741549120886237
370.00000000000455,42.294433913704964,0.1197266517619266,-1.4753700272499795
371.00000000000455,42.39009816441043,0.11865299177879557,-1.4766889809643713
372.00000000000455,42.487275251667,0.11954958171464952,-1.4766872844986532
373.0000000000046,42.58425051898416,0.11746438073248577,-1.4770434457167538
374.0000000000046,42.68212766984288,0.1170039807597072,-1.4780087759059062
375.0000000000046,42.77891170075873,0.11727440205335155,-1.4786601570740334
376.00000000000466,42.87500424253285,0.11791184047256353,-1.479982974146247
377.00000000000466,42.97233172330501,0.1175707924472702,-1.4799800191026908
378.00000000000466,43.067966287614674,0.11787780298856221,-1.4813104494571547
379.00000000000466,43.16690799316193,0.11895144424289467,-1.4812998960900159
380.00000000000466,43.26445284251228,0.11780436398241667,-1.4813256691812828
381.0000000000047,43.36118635218697,0.11840742051537234,-1.4826201636461191
382.0000000000047,43.45855079927777,0.1150432239339167,-1.4826201603324312
383.0000000000047,43.55553564289428,0.1153603470567523,-1.4839086648847082
384.0000000000048,43.65234012698573,0.11527846226899596,-1.4839301279699622
385.0000000000048,43.74899033586779,0.11708505219586202,-1.4839293710115125
386.0000000000048,43.846214942787334,0.11657586384115914,-1.485249992914563
387.0000000000048,43.94408175315754,0.11591328331672829,-1.4858861488356885
388.0000000000048,44.0406131462199,0.1154728734153016,-1.4868889946573507
389.00000000000483,44.1371544782672,0.1154883143467384,-1.488545715507597
390.00000000000483,44.23403058456615,0.11534272603713375,-1.487373915878623
391.00000000000483,44.331530858068156,0.11452994519226872,-1.4877981134090312
392.0000000000049,44.42866106046176,0.11474623949995866,-1.4898599707442584
393.0000000000049,44.5259924679017,0.11185262953185698,-1.4898775788258676
394.0000000000049,44.62317018121057,0.11297505712596828,-1.4911795419505998
395.0000000000049,44.72059588037562,0.11136641921657939,-1.490270771431792
396.0000000000049,44.818387982424,0.11101600380952714,-1.491189806497803
397.00000000000495,44.91543233281863,0.11063063046927885,-1.4925090123147813
398.00000000000495,45.01239148722475,0.10960064493024266,-1.4934395997348369
399.00000000000495,45.109567319332214,0.1094681166551725,-1.4938200530931414
400.000000000005,45.20722923114652,0.10621420347758484,-1.4961645698753574
401.000000000005,45.30532177892962,0.1049500819317726,-1.4974181491313474
402.000000000005,45.40315554685668,0.10293594596143218,-1.497438265981606
403.000000000005,45.500079328860025,0.10150594054058604,-1.4974544100760685
404.000000000005,45.596817453781,0.10285367932515119,-1.5000635994228233
405.00000000000506,45.695033092444,0.10160000377921419,-1.5000699998959677
406.00000000000506,45.79234263372272,0.09885598658454336,-1.5001022443440677
407.00000000000506,45.88977715333334,0.0999044053906617,-1.5017320489202737
408.0000000000051,45.98754794492521,0.09902933564415736,-1.5040318256193985
409.0000000000051,46.08561625828672,0.09859196747086407,-1.5053377338790352
410.0000000000051,46.182466367173696,0.09664393655295914,-1.5053047347155162
411.0000000000051,46.27964043941972,0.09607317935945214,-1.506651646499499
412.0000000000051,46.37556506245733,0.09549926337425002,-1.5094030218912189
413.0000000000052,46.47496657543175,0.09442019885135733,-1.510717225839381
414.0000000000052,46.57280170470202,0.0940266997581802,-1.5104188870446502
415.0000000000052,46.67008420071814,0.0927045956188561,-1.512383141019816
416.00000000000523,46.766975900959245,0.09425950689807702,-1.5150432895013206
417.00000000000523,46.86492204973544,0.09453823565320915,-1.5163129640387583
418.00000000000523,46.9631236062432,0.09401586950282592,-1.5177054102436611
419.00000000000523,47.05961005417443,0.09431877527219207,-1.5176644419414025
420.00000000000523,47.157581660513515,0.09367315669068968,-1.521426127769471
421.0000000000053,47.255151671715055,0.0901019184125707,-1.52334993143106
422.0000000000053,47.35281799476771,0.08772454577545405,-1.5246552505173305
423.0000000000053,47.45133318378488,0.08888997918116903,-1.5268316647308282
424.00000000000534,47.54887618254481,0.0891016361643584,-1.5289567260215589
425.00000000000534,47.64624876945752,0.08888490988832931,-1.531602140414801
426.00000000000534,47.74271259432909,0.08887603175308881,-1.5342290309166011
427.00000000000534,47.84154923821506,0.08921751727741567,-1.535552858062725
428.00000000000534,47.93985102944674,0.08893988547979986,-1.538960144734081
429.0000000000054,48.03776596698346,0.08770945327629306,-1.5417705547346552
430.0000000000054,48.135761605918006,0.08705127587239281,-1.5431397606178852
431.0000000000054,48.2331313296988,0.08830479743633157,-1.547556613510749
432.00000000000546,48.3304934752098,0.08902619918516125,-1.5521699742058095
433.00000000000546,48.427711506763,0.08977427241902561,-1.5544301155269564
434.00000000000546,48.52717044006276,0.09108929968898336,-1.557656248799577
435.00000000000546,48.62304251382406,0.09167166646767794,-1.5619081219776474
436.00000000000546,48.723633610812385,0.09337924675081527,-1.5673857332619816
437.0000000000055,48.820895889263596,0.09623442851265829,-1.5717184528464152
438.0000000000055,48.91979541467751,0.09812800742356284,-1.5752661879628111
439.0000000000055,49.01643071100415,0.1018331580883941,-1.5785131352156205
440.00000000000557,49.11576994315375,0.10446827788441646,-1.5843755992341575
441.00000000000557,49.21212909823686,0.10959609960640193,-1.5893896232086706
442.00000000000557,49.311315966964834,0.11268241760950493,-1.5951631704839335
443.00000000000557,49.40917000000049,0.11688900802703105,-1.6008601840000014
444.00000000000557,49.50836989979386,0.1225589708504297,-1.606698265160388
445.0000000000056,49.60638574886691,0.1265765984035393,-1.6131125844914345
446.0000000000056,49.7034439569335,0.13034479007669492,-1.6197474338604447
447.0000000000056,49.802831883577234,0.1376761252657846,-1.6264002277838672
448.0000000000057,49.90055153410847,0.14286718121064512,-1.6337323599686004
449.0000000000057,49.99809394191724,0.14872126269049685,-1.6397103268383488
450.0000000000057,50.09615559705211,0.15645924871036415,-1.647603328228851
451.0000000000057,50.19400679006821,0.16371162334869552,-1.6558008996348095
452.0000000000057,50.29249204028262,0.16637191817422756,-1.6643710864063124
453.00000000000574,50.39091524766282,0.17439249373101376,-1.6729683389495484
454.00000000000574,50.48927198470459,0.18202134592371677,-1.6819499918357814
455.00000000000574,50.587336954087576,0.1858976090854915,-1.6904568309619221
456.0000000000058,50.685479889725904,0.1932650818523743,-1.699313247982278
457.0000000000058,50.78367543217141,0.20173465019057263,-1.7087007489231771
458.0000000000058,50.882045757955495,0.20823559242314055,-1.7207105364738688
459.0000000000058,50.98028842737064,0.215221312865499,-1.729738672444646
460.0000000000058,51.07839451436345,0.22262827523472337,-1.7414851988698032
461.00000000000585,51.17706014592367,0.22799296923350704,-1.7542574484898736
462.00000000000585,51.2763944100085,0.23335949610844775,-1.7668584908833802
463.00000000000585,51.375220095235505,0.24207825922245824,-1.7776632288317709
464.0000000000059,51.47364462808365,0.24825101916798986,-1.7898574047666975
465.0000000000059,51.57052482016112,0.2581623844062456,-1.8036559599371356
466.0000000000059,51.669808722266815,0.26558238444303117,-1.817968009861636
467.0000000000059,51.76861716508667,0.2726804153311403,-1.8323196866522888
468.0000000000059,51.86738966251329,0.28007523337747664,-1.847088433153341
469.00000000000597,51.96621661715917,0.288372434332155,-1.863597726753592
470.00000000000597,52.064616222058,0.29487336362159206,-1.8788851822137946
471.00000000000597,52.16309464597384,0.3033789072291497,-1.8964643993329373
472.000000000006,52.26136188395974,0.3085031585479476,-1.9145382254626369
473.000000000006,52.35989227348865,0.3189045813118383,-1.93267845318891
474.000000000006,52.45864153279289,0.32449285385893445,-1.9527824216612566
475.000000000006,52.557138882222944,0.33144659945193183,-1.9741308059802185
476.000000000006,52.656181054936184,0.3383626711701552,-1.9940273353714058
477.0000000000061,52.754090244769024,0.3445924362299586,-2.0152742935825234
478.0000000000061,52.85375828510248,0.3501621736723826,-2.038153218796305
479.0000000000061,52.95118986951685,0.35257877741102295,-2.0611039158044155
480.00000000000614,53.05044495036762,0.35642303656395263,-2.0856281993706762
481.00000000000614,53.14877543783631,0.35750654539520416,-2.1101766430907656
482.00000000000614,53.24827653160271,0.3588924459639163,-2.135454542399482
483.00000000000614,53.346358053906876,0.36035968014586905,-2.16093508264047
484.00000000000614,53.44487937852528,0.35798508329808765,-2.1865359188384326
485.0000000000062,53.543734138817925,0.357126530475815,-2.2136757946015724
486.0000000000062,53.64197487257082,0.35209838268278637,-2.2392181585119926
487.0000000000062,53.74234171925106,0.3450961577092091,-2.2670953100819653
488.00000000000625,53.84055666178202,0.3365893826504203,-2.293948893207741
489.00000000000625,53.93802970141411,0.3258197910977449,-2.3194654376641752
490.00000000000625,54.037588379631146,0.31422907061047756,-2.344116146542009
491.00000000000625,54.136447472778784,0.30004157817032057,-2.369469222988587
492.00000000000625,54.23588369990816,0.28350427265735195,-2.393394782586374
493.0000000000063,54.334302368456676,0.2688964436709156,-2.41718107285719
494.0000000000063,54.43383434080857,0.2521408196251654,-2.439824321622279
495.0000000000063,54.532665019372345,0.2369950417546679,-2.460229495416076
496.00000000000637,54.63126194869513,0.21778838517671578,-2.480260395429858
497.00000000000637,54.727124527543864,0.19800580617500416,-2.4976149192093056
498.00000000000637,54.82875335515646,0.1739434202741741,-2.5138587132121364
499.00000000000637,54.927511999433435,0.15063977940852874,-2.5274785121382726
500.00000000000637,55.02584122155858,0.12540360222174476,-2.5391981799681824
501.0000000000064,55.124014500785016,0.10362532481655326,-2.550239429562891
502.0000000000064,55.22323039167328,0.08205081032086314,-2.5597244852129597
503.0000000000064,55.321181703707744,0.06503663544397292,-2.5659148756934167
504.0000000000065,55.41978469347893,0.048325651155646285,-2.5734201598915343
505.0000000000065,55.51927434458175,0.033623135756184475,-2.57745437852127
506.0000000000065,55.617199490365216,0.026727733870478484,-2.5809737422315386
507.0000000000065,55.717329735895724,0.01600183377677717,-2.5834945853682885
508.0000000000065,55.81714060346763,0.01237831533189928,-2.5858392395814094
509.00000000000654,55.91476848554737,0.007709740680799227,-2.5884479442220822
510.00000000000654,56.01403028219993,0.007218639092091193,-2.5897968930020783
511.00000000000654,56.11420523154897,0.0051982065096497325,-2.591109025755328
512.0000000000066,56.21230683929577,0.0037687253636853376,-2.5937206959346435
513.0000000000066,56.31139053395896,0.0020271227385765763,-2.594502328813197
514.0000000000066,56.409743706992394,0.003162647700940774,-2.596395504692461
515.0000000000066,56.508312738696105,0.0029719664393033102,-2.5963667330850955
516.0000000000066,56.60806519150081,0.0008380094883479149,-2.599009504451834
517.0000000000066,56.70760622104745,-0.0003652266131555157,-2.597658944073899
518.0000000000066,56.805851106680464,0.004574474395036152,-2.5990014837073336
519.0000000000066,56.90528409470174,0.00785038139991491,-2.602370387290101
520.0000000000067,57.004437878868394,0.011929643773678045,-2.6029557546499538
521.0000000000067,57.10297667208959,0.012057291308955026,-2.602959886196051
522.0000000000067,57.20204483151383,0.012202427798103162,-2.604279697401167
523.0000000000067,57.30105829631001,0.012917948204412374,-2.6029748541973694
524.0000000000067,57.40057420344255,0.01400250161158667,-2.605597484938938
525.0000000000068,57.49984859295576,0.01349177751870445,-2.6079046445415286
526.0000000000068,57.598159109790885,0.014655860917188741,-2.608927257170807
527.0000000000068,57.69739865009052,0.016006882980293152,-2.60922015847653
528.0000000000068,57.79661596347529,0.015303853259415176,-2.6105238799697688
529.0000000000068,57.89561089361804,0.015985577244237367,-2.6105241262033414
530.0000000000068,57.994309233317395,0.01828825159834581,-2.611851676102061
531.0000000000068,58.09404553314731,0.018079549344387588,-2.6118081995464273
532.0000000000068,58.1940164626718,0.01856455914639933,-2.613100514934543
533.0000000000068,58.293437035867505,0.017686366042044974,-2.614510368131631
534.0000000000068,58.392850147948835,0.019382437125308988,-2.61568175438086
535.0000000000068,58.492088492344784,0.018811715784473118,-2.6158630020975204
536.0000000000069,58.591125008774824,0.015910836630621567,-2.616461241808847
537.0000000000069,58.6920116287455,0.01566879960095785,-2.6172418216961195
538.0000000000069,58.790287205935314,0.01693601809457075,-2.6181272678959475
539.0000000000069,58.89035367329013,0.01597139936332835,-2.6184437455561786
540.0000000000069,58.989584912921316,0.01684003817289348,-2.6191166558717693
541.000000000007,59.08997006690972,0.0166799473298318,-2.6204201356430694
542.000000000007,59.18969648261588,0.01909436261320875,-2.621417302432774
543.000000000007,59.28808744531557,0.01567371731465149,-2.622056799372698
544.000000000007,59.38786187616579,0.016727054939860694,-2.6240301695492123
545.000000000007,59.48731113070237,0.015727496670964472,-2.6242329528990584
546.000000000007,59.58607765602726,0.015217029260505333,-2.6251296577536922
547.000000000007,59.6856148225934,0.014402244693083821,-2.625342335865839
548.000000000007,59.78556666637707,0.01569741896618146,-2.6266785568261453
549.000000000007,59.88553951290335,0.01656629383760333,-2.6265939546380506
550.000000000007,59.98614691486998,0.015690006405567086,-2.6279902818734495
551.000000000007,60.08382686278029,0.014416534538641806,-2.6293104249866412
552.0000000000072,60.18432835452248,0.01823662339178933,-2.629976313157578
553.0000000000072,60.2841035470994,0.019765272199900513,-2.6312892071318146
554.0000000000072,60.38388947679247,0.02230367439595765,-2.632241409846099
555.0000000000072,60.48219291224286,0.02265966272791531,-2.632591701204215
556.0000000000072,60.58153229200048,0.026308334076070278,-2.6339177599403163
557.0000000000073,60.68193180030301,0.028734219435624736,-2.636564566358797
558.0000000000073,60.780643823390804,0.034148385197256576,-2.6378702240641054
559.0000000000073,60.881597055516366,0.04296868124913933,-2.6392453632340946
560.0000000000073,60.98003899268438,0.048186365513537555,-2.6405035362048763
561.0000000000073,61.07993754872603,0.055758259975005164,-2.6411731927282807
562.0000000000073,61.18064409211987,0.060341329348315986,-2.6432639349659346
563.0000000000073,61.279480932111525,0.06659922193868753,-2.6444853638438346
564.0000000000073,61.3802380784993,0.07584409034582412,-2.646421759714128
565.0000000000073,61.47897040702499,0.0809755133127868,-2.647019925316898
566.0000000000073,61.57917000000064,0.08744269204187557,-2.6487401398790515
567.0000000000074,61.67833652101735,0.08856019744593904,-2.6525527511448574
568.0000000000074,61.77823954713272,0.09371590166052687,-2.6531511019049203
569.0000000000074,61.878093400178045,0.09364278929310813,-2.654554475666271
570.0000000000074,61.97785834343551,0.09190059968506065,-2.655976692703494
571.0000000000074,62.077464507965225,0.08658961575714727,-2.6594014111177238
572.0000000000074,62.17753643512329,0.07894079368936407,-2.6620346263104726
573.0000000000074,62.27727659359787,0.06603897029096903,-2.662346614447152
574.0000000000075,62.37700811719476,0.05074815821453316,-2.6636699539247606
575.0000000000075,62.47638985862478,0.03317599213020325,-2.664983213681444
576.0000000000075,62.57628211466956,0.01197998497127939,-2.667621377875376
577.0000000000075,62.67610157614781,-0.008100910874097894,-2.6686021434617095
578.0000000000075,62.77613391790417,-0.022633612740961206,-2.6686315651210073
579.0000000000075,62.87505250324129,-0.03806697373044521,-2.6708082659397165
580.0000000000075,62.97589203663762,-0.05249321911549554,-2.6725650538412347
581.0000000000075,63.07425966023563,-0.06182207282924568,-2.6725722426589407
582.0000000000075,63.17462357329263,-0.06574135302232556,-2.6738800809204273
583.0000000000076,63.27482219975651,-0.07300826385844886,-2.6738800610968205
584.0000000000076,63.37396906891983,-0.07983202656865579,-2.6751626143202323
585.0000000000076,63.47410415428124,-0.0867069866334744,-2.6765048183593056
586.0000000000076,63.57325099347891,-0.08945197851652248,-2.6761711697234274
587.0000000000076,63.674146456751366,-0.0934604203368434,-2.676851808617621
588.0000000000076,63.77235674758236,-0.09642770936183062,-2.6768501703751504
589.0000000000076,63.87365761461281,-0.10050059544038897,-2.678177683598659
590.0000000000077,63.974787825615444,-0.10267183860588075,-2.678168837735314
591.0000000000077,64.0748577242775,-0.10293943128518676,-2.6791499813655992
592.0000000000077,64.17468901718465,-0.10566226530886294,-2.6785259145874254
593.0000000000077,64.27447155459642,-0.10788459283830742,-2.6784852094940836
594.0000000000077,64.37463142313733,-0.10954896168986875,-2.6802381013323693
595.0000000000077,64.47430448426122,-0.11119225983389411,-2.680470135616424
596.0000000000077,64.57464274499495,-0.1083095339674108,-2.6804701342817037
597.0000000000077,64.67479376491667,-0.10459164945154342,-2.681583341783963
598.0000000000077,64.77466297869013,-0.1017567590843877,-2.681790008281121
599.0000000000078,64.87473472326161,-0.09909883163087785,-2.683143413234251
600.0000000000078,64.97371471526128,-0.09241821130716299,-2.683099315230364
601.0000000000078,65.0743083385674,-0.08966063275516312,-2.681780378486125
602.0000000000078,65.17480832016255,-0.08933272797899738,-2.6824548606585883
603.0000000000078,65.27474581844277,-0.07932281384952605,-2.6837620232459884
604.0000000000078,65.3755548030121,-0.07745747764911687,-2.6850801202518464
605.0000000000078,65.47607556985017,-0.07726480937973573,-2.6850736159755657
606.000000000008,65.57366762976444,-0.06771101557059123,-2.686386979856299
607.000000000008,65.67531671504673,-0.06279876697838271,-2.685259390151991
608.000000000008,65.77541287064524,-0.05891591323939854,-2.6863889987050626
609.000000000008,65.87543114884862,-0.05418851144957032,-2.687709705241346
610.000000000008,65.97486218797779,-0.05098896701317163,-2.687709389775085
611.000000000008,66.075487314276,-0.04608012047921345,-2.688474886713937
612.000000000008,66.17589190493788,-0.04032733440579073,-2.689052015295676
613.000000000008,66.27531382944883,-0.03803117718143323,-2.690345967587347
614.000000000008,66.37669833542239,-0.034508108796820924,-2.6916701889771484
615.0000000000081,66.47645977274325,-0.029297250022900845,-2.692651092197398
616.0000000000081,66.57672725946867,-0.027282905765625143,-2.693953468243122
617.0000000000081,66.67676592988289,-0.026134493089469135,-2.6952002147536605
618.0000000000081,66.7769727506462,-0.0236178789710495,-2.695590471207538
619.0000000000081,66.87740744522375,-0.02125539026180301,-2.6972836327193046
620.0000000000081,66.97786551544587,-0.017990551489054596,-2.6985811545683207
621.0000000000081,67.07798693926001,-0.014243516029255832,-2.698555628659628
622.0000000000082,67.17783069916415,-0.012949400930387989,-2.699890093568487
623.0000000000082,67.27765728522338,-0.009018650475857037,-2.6999671732310415
624.0000000000082,67.37820263032245,-0.0024327648847191075,-2.7002625813092895
625.0000000000082,67.47855434665803,-6.874070392248743e-05,-2.7039431748034812
626.0000000000082,67.57866743135446,0.005548157792878539,-2.7033792339378944
627.0000000000082,67.67991135912301,0.007804339001664773,-2.7040705706653956
628.0000000000082,67.77998143189402,0.013563387663161675,-2.7040858738621747
629.0000000000082,67.87995818621552,0.02432069260201486,-2.7081548656661156
630.0000000000082,67.97883016770666,0.03031869636408213,-2.7083515803995484
631.0000000000083,68.0820509676073,0.03763057320798591,-2.7096867366340187
632.0000000000083,68.18159594536387,0.04451086905861301,-2.7115822948119783
633.0000000000083,68.2827628532896,0.05409421028962014,-2.7123030476334176
634.0000000000083,68.3828476432629,0.06393748819939471,-2.713573584761466
635.0000000000083,68.48312853084909,0.06747569047258717,-2.716249156658417
636.0000000000083,68.58322890741329,0.07870457686717602,-2.7175775733490246
637.0000000000083,68.68406133432872,0.0873337445110044,-2.7185641709317077
638.0000000000084,68.7850600580841,0.09753985017105682,-2.7197887379897017
639.0000000000084,68.88369470237804,0.10551665492441353,-2.7225695525389435
640.0000000000084,68.98460729228911,0.11295462617039453,-2.72429493049658
641.0000000000084,69.08497160873037,0.11926717314976065,-2.725158227992512
642.0000000000084,69.18466608690211,0.1325491391966508,-2.7291007391379685
643.0000000000084,69.28624328814573,0.14172819476745735,-2.729041951657881
644.0000000000084,69.3860536678418,0.14933054896370812,-2.7330518929234717
645.0000000000084,69.48702020196548,0.15927560308177668,-2.733515095441276
646.0000000000084,69.58733523194645,0.16728850853707466,-2.7373487979669715
647.0000000000085,69.68685843349277,0.17598332124764626,-2.7391286915116133
648.0000000000085,69.78792191198332,0.1835985241938669,-2.741236933028407
649.0000000000085,69.88897146029059,0.19042735985007642,-2.743920585088679
650.0000000000085,69.9893651167358,0.1968217246188021,-2.745166774727586