File: 01_Data/Coaxial_Cable/STA/N2/10K_min/Coaxial_Cable_STA_N2_10KData_220715_R3.csv
##Temp./Â°C,Time/min,DSC/(mW/mg),Mass loss/mg
50.0,10.65917,0.030782731476791447,0.0025799387984450917
51.000000000000014,10.986500080978782,0.07337624599450909,0.0038494087602103377
52.00000000000003,11.194958957649396,0.10488448076621926,0.0033130602480930804
53.00000000000004,11.368246607952232,0.1321132480596412,0.0036887618026879565
54.00000000000006,11.5171999561126,0.15054251677634833,0.004065460097121942
55.00000000000007,11.656763932704239,0.16595808995117745,0.004411360318004931
56.000000000000085,11.78421555682291,0.18067968030486758,0.0033369162156668963
57.0000000000001,11.906759785862016,0.19360790090399682,0.003507063748688921
58.000000000000114,12.029825562840454,0.20482864489978891,0.002109607237921196
59.00000000000013,12.146023092724455,0.21248910343187677,0.00418758523582774
60.00000000000014,12.26296135185002,0.21912101483575475,0.003516027791121701
61.000000000000156,12.37511855622269,0.22459921139094652,0.002236672760443703
62.00000000000017,12.487396004363985,0.22810030279366256,0.0023902726174629407
63.000000000000185,12.597018454571216,0.2311902409898854,0.002914018419382103
64.0000000000002,12.707319402079074,0.23708663318425072,0.0035547241204740843
65.00000000000021,12.817824020742924,0.23934113304300575,0.0030799372076000253
66.00000000000023,12.926039954795444,0.2410264015164001,0.002239183874288564
67.00000000000024,13.033610148658527,0.2433568115754139,0.0036215918365600785
68.00000000000026,13.141070612852989,0.24622688985661867,0.0036824371667805167
69.00000000000027,13.248416068613588,0.24658068247785092,0.0023014825326157506
70.00000000000028,13.3546258468775,0.24821835154400362,0.00243988832406572
71.0000000000003,13.463035614229403,0.2491923348984636,0.0029941105534208035
72.00000000000031,13.567513973803432,0.25262935538569387,0.002187253903257691
73.00000000000033,13.67343032244101,0.2546716497505609,0.0023525495337812785
74.00000000000034,13.779273684923528,0.2554035207753593,0.002621466521548932
75.00000000000036,13.883395910170941,0.25520849053787753,0.0028938725018390343
76.00000000000037,13.988472967494596,0.25975500017176967,0.0022443521306723113
77.00000000000038,14.092635814418522,0.26189644086718766,0.002344823123218376
78.0000000000004,14.195428627336407,0.26258581846556117,0.0036259884933631525
79.00000000000041,14.300261950967744,0.26545544672694865,0.0009919643583771176
80.00000000000043,14.402778801477224,0.26616644876218887,0.0014241639133043549
81.00000000000044,14.505055716288693,0.26826929822675294,0.00454767875802542
82.00000000000045,14.607275674153998,0.27218986010808943,0.003197875499959757
83.00000000000047,14.709432649277417,0.2738713663512722,0.003191337811429662
84.00000000000048,14.811899450245884,0.2758555309443329,0.0031875485172010443
85.0000000000005,14.91463262892373,0.27822157620525967,0.0018484236586111535
86.00000000000051,15.013549167904856,0.2778896270565039,0.0011999631304266956
87.00000000000053,15.116648819865823,0.2822582752623335,0.0011989974166484174
88.00000000000054,15.214871203199591,0.28277389894392724,0.0018494420004833145
89.00000000000055,15.316361572507796,0.28541520345704496,0.0018704513965630554
90.00000000000057,15.417352628164329,0.28701445917212265,0.001863629388588528
91.00000000000058,15.514732044876409,0.29047074138987505,0.000457555455552594
92.0000000000006,15.616627838044902,0.2930894049278303,0.002312046751657526
93.00000000000061,15.715516170037633,0.29533573044691575,0.0018933545472039626
94.00000000000063,15.815659301408136,0.2975633104761356,0.0018598571700154665
95.00000000000064,15.913408065491698,0.3020546911646148,0.001856471234073176
96.00000000000065,16.01432105969495,0.3027156305784019,0.002325083753117241
97.00000000000067,16.113403807040267,0.3049260421945761,0.0031796583403700396
98.00000000000068,16.210631932938785,0.30916101709424026,0.0031799619902104226
99.0000000000007,16.3112239790303,0.31131148786464924,0.0034482717445118993
100.00000000000071,16.40894612956145,0.3145686719582811,0.003178443194512326
101.00000000000072,16.507419408633467,0.3170964282813352,0.0018601385965295592
102.00000000000074,16.604573710667072,0.31910928086599977,0.002846464355256373
103.00000000000075,16.703571686173714,0.3206525495575856,0.002008204676601011
104.00000000000077,16.80103221999459,0.3241120462479813,0.0018545720120091147
105.00000000000078,16.899939944241012,0.3255482591772445,0.0018598300179908378
106.0000000000008,16.996792239116346,0.326877086983686,0.0017870151863519368
107.00000000000081,17.096463491999987,0.329364860373062,0.002112028989349035
108.00000000000082,17.19302473365498,0.3323225351833987,0.0018260592396517339
109.00000000000084,17.291626647324513,0.33401793179616623,0.0018698223366984124
110.00000000000085,17.38955035414706,0.3362220599608603,0.0012416479323622553
111.00000000000087,17.487070979342878,0.340975452434649,0.0023441498151779427
112.00000000000088,17.584106486257422,0.34163461205464507,0.003178952788226219
113.0000000000009,17.68258552946259,0.34574131543244213,0.001995141620122709
114.00000000000091,17.780718480502067,0.350242977345231,0.002423203600629087
115.00000000000092,17.87766832803835,0.3528461060248558,0.0025180747374875523
116.00000000000094,17.975036018912554,0.35802100489322874,0.0024962365505558637
117.00000000000095,18.071434283931353,0.36245421351747775,0.0021867595639815107
118.00000000000097,18.16981208646676,0.3663592461076739,0.0019894826681916555
119.00000000000098,18.26456988028117,0.371104270435764,0.0018702962650207766
120.000000000001,18.363744369123275,0.38060276089523903,0.0018599079199264068
121.00000000000101,18.461470457512362,0.39137062384119403,0.0018724947592110297
122.00000000000102,18.559065292011894,0.40768511788448736,0.0031833963697778245
123.00000000000104,18.65680049877208,0.4304229746705326,0.0021917810078306843
124.00000000000105,18.753930930422946,0.46522654612877445,0.003176819637066508
125.00000000000107,18.85121435160139,0.5128790600368678,0.0018699305731111338
126.00000000000108,18.947020533830607,0.5770029386614598,0.001867846773285109
127.0000000000011,19.046583322573248,0.6506441578774741,0.0017961036722038415
128.0000000000011,19.143633871985557,0.7040971697492044,0.0018701790493595993
129.00000000000114,19.240892539292762,0.6874858215539756,0.0019506371677096013
130.00000000000114,19.338885172241113,0.5547181380837463,0.0015174431962501345
131.00000000000114,19.435092574122653,0.45336034089274224,0.0019121929562402329
132.00000000000117,19.532020034232737,0.39679669652338323,0.00017635943206073534
133.0000000000012,19.628770978445893,0.3634025996483723,0.0015306233916945189
134.0000000000012,19.724745950629465,0.3462931272916958,0.0015302342029714922
135.0000000000012,19.82148132459932,0.3371078814673407,0.002012378271882831
136.00000000000122,19.917423780703434,0.3307059861832693,0.0015399745841193635
137.00000000000125,20.012366684104123,0.32830721260552487,0.0011512599330556483
138.00000000000125,20.110062375784477,0.328515749844725,0.0015301469375845755
139.00000000000125,20.20353452856639,0.3277223621709797,0.0028483542747599344
140.00000000000128,20.301560840088513,0.32624089228529285,0.0025551623145840807
141.0000000000013,20.397990125585387,0.3265404110993668,0.0015299661827512523
142.0000000000013,20.494638876801105,0.32695635075149576,0.002523352747931362
143.0000000000013,20.59074746897444,0.32769240148260725,0.002857574331158297
144.00000000000134,20.683664802985476,0.32739943075446376,0.001414362821427595
145.00000000000136,20.78222351861607,0.32830773532856905,0.00219031961129712
146.00000000000136,20.878780528794074,0.3295378392936025,0.0008790561981459888
147.00000000000136,20.97595083863034,0.3292014588622344,0.0015402607987438088
148.0000000000014,21.07162650706395,0.33005170035701037,0.0005462619157059478
149.00000000000142,21.167664940314907,0.33140912145513357,0.0018599866845523394
150.00000000000142,21.263634457494817,0.33285716482173167,0.001530051594579973
151.00000000000142,21.359770859212876,0.33285250400460387,0.0015301779626302192
152.00000000000145,21.455046528274877,0.3338550217997446,0.001188272748900765
153.00000000000148,21.549363149681643,0.3360866788131981,0.0015344795140093126
154.00000000000148,21.648030345895503,0.33728117079476305,0.001787454456685822
155.00000000000148,21.742638906722373,0.3387872088700785,0.0012784028117271973
156.0000000000015,21.840138887069568,0.34080725086256614,0.0013154120940912506
157.00000000000153,21.93506979347596,0.34013211738674554,0.001319809996050303
158.00000000000153,22.031771241270196,0.3421595090148831,0.0012895423599132982
159.00000000000153,22.127274284548857,0.3427942339107798,0.001320860924074907
160.00000000000156,22.223261562579342,0.3434996579927603,0.0013200379248390348
161.0000000000016,22.31851991374436,0.34359862549194387,0.001320038000063306
162.0000000000016,22.41442507659408,0.34443304163310406,0.001320046222083704
163.0000000000016,22.508268467329277,0.3441258409260387,0.0013007043393535866
164.00000000000162,22.605634417176336,0.3429572749307319,0.0013193780385600817
165.00000000000165,22.700440304530822,0.3419090171994942,-9.896897695149676e-06
166.00000000000165,22.797186539705613,0.3421466742499969,0.0012477887964097434
167.00000000000165,22.891787994158392,0.34463530342737747,-2.692113438840238e-07
168.00000000000168,22.987746690882982,0.34458691860687996,0.001308831208264749
169.0000000000017,23.083682913729216,0.3454958529498582,0.0025698462917125298
170.0000000000017,23.178457989680698,0.3440262098619823,0.0013198515799572874
171.0000000000017,23.275304859574863,0.34634816926877854,-1.5899999894486427e-07
172.00000000000173,23.369457569041604,0.3487665559515849,0.0010066596041893305
173.00000000000176,23.46581495775564,0.3482334082190641,0.000990026571252578
174.00000000000176,23.56189753818087,0.3491619785394098,-0.00033082750673774086
175.00000000000176,23.65664351925223,0.35089210589705566,0.00033002205675281004
176.0000000000018,23.752245967333685,0.3495705951048267,0.0003329169580936764
177.00000000000182,23.848688300321875,0.3502240851123327,-0.0006598724954205437
178.00000000000182,23.943594499725638,0.3518059412254203,-0.0009899865809472885
179.00000000000182,24.03759497938011,0.35150833282066984,-0.0010314030987270684
180.00000000000185,24.136195012324453,0.35476185188489295,-0.0023306088686769755
181.00000000000188,24.231073918507136,0.35274062483423396,-0.0016500562047712108
182.00000000000188,24.325950249911454,0.353711685732612,-0.0006692683949545142
183.00000000000188,24.42190051661051,0.3533614827012126,-0.0006699786549075881
184.0000000000019,24.51659219162028,0.3550043805877634,-0.0019802155350729933
185.00000000000193,24.612281653302045,0.35568050296863596,-0.001979802596172142
186.00000000000193,24.7085212691439,0.35845944184450584,-0.0016498855679936142
187.00000000000193,24.80362086987774,0.3587849907752233,-0.0016502692941147146
188.00000000000196,24.89925666582456,0.3588253661126769,-0.002970693942306646
189.000000000002,24.994508924759074,0.35997910625226914,-0.002970181021842322
190.000000000002,25.0903276219592,0.3620165926299037,-0.0029871365975022712
191.000000000002,25.18422493327804,0.3620586620686621,-0.003960179597665814
192.00000000000202,25.280129892117476,0.3637283546006047,-0.003957755278770847
193.00000000000205,25.37544586586664,0.36461180335110077,-0.004290201805194904
194.00000000000205,25.471304034498903,0.36463884706036964,-0.0029711845328694864
195.00000000000205,25.56655572827773,0.3650077975727244,-0.0042900722462499985
196.00000000000207,25.660533683547314,0.3668576261136065,-0.004715922867422506
197.0000000000021,25.75739577903243,0.36932906586404957,-0.004950181225552797
198.0000000000021,25.852772588127014,0.36783345638640363,-0.004950180021921824
199.0000000000021,25.94847461443311,0.3681793879049239,-0.005538594034169009
200.00000000000213,26.04380074611008,0.36875960953405074,-0.0049912335852724254
201.00000000000216,26.138204084504977,0.3697092488922282,-0.007523861272339616
202.00000000000216,26.234121012283055,0.3704164907412115,-0.008230249063091222
203.00000000000216,26.327815777837067,0.37338065809001875,-0.0069206913714063845
204.0000000000022,26.42352733383647,0.37360124737473366,-0.0084285652216467
205.00000000000222,26.519077528958356,0.3772372737233982,-0.00840079713935804
206.00000000000222,26.613105523929907,0.3775638663495112,-0.009439964771302378
207.00000000000222,26.708575205945177,0.3772695197072876,-0.009439860040016512
208.00000000000225,26.803848754784813,0.3787428587037295,-0.009769717008555112
209.00000000000227,26.89946012891939,0.3806414823388638,-0.009786724882367537
210.00000000000227,26.994153697590466,0.38297324460378374,-0.012410066589561453
211.00000000000227,27.08886595208275,0.38160104209571677,-0.012411787190483636
212.0000000000023,27.18386225242723,0.3854645683894301,-0.013824796087480884
213.00000000000233,27.279516343111915,0.38666638304243856,-0.015040508869730296
214.00000000000233,27.37470348218128,0.38937351060221703,-0.01635898449304296
215.00000000000233,27.468977560582328,0.39268781964558713,-0.01537920618692823
216.00000000000236,27.564369198562,0.39272719041276444,-0.01669233318655383
217.0000000000024,27.66025407618801,0.39552847771380784,-0.017999340291917854
218.0000000000024,27.75540175198265,0.397962223032451,-0.01802429726570587
219.0000000000024,27.849264412026606,0.40077871150195127,-0.020750200220739146
220.00000000000242,27.94473391725462,0.4042916135814667,-0.021473808585684928
221.00000000000244,28.040875994567987,0.40658934983727724,-0.023386448346182753
222.00000000000244,28.134485461073776,0.411151776458686,-0.023391970914096838
223.00000000000244,28.230127017778102,0.4134305961934253,-0.024731974474245355
224.00000000000247,28.32529976328502,0.4172893131551056,-0.026019135059377696
225.0000000000025,28.420611742685995,0.41996969722815003,-0.027339872238600904
226.0000000000025,28.516089389225474,0.4258120103123839,-0.02868223310363227
227.0000000000025,28.611094335131238,0.42846265942037437,-0.030959992989089802
228.00000000000253,28.70631344178642,0.4317991541662197,-0.03227422578928696
229.00000000000256,28.802172662759826,0.4350166959637008,-0.035363297487397194
230.00000000000256,28.89703549515069,0.43787768948835293,-0.036512516137487516
231.00000000000256,28.99101178449206,0.4414991614002405,-0.037837985267596075
232.0000000000026,29.0860867791889,0.4429815983475876,-0.04152789101685128
233.00000000000261,29.18269647297125,0.44643314258966016,-0.043514405345499885
234.00000000000261,29.27723042763293,0.44939269671204135,-0.04545007678324753
235.00000000000261,29.371985263088174,0.4508412944268954,-0.046897921528083586
236.00000000000264,29.468260039976066,0.4563979099422482,-0.04941917021318343
237.00000000000267,29.56327934152106,0.4593104740160248,-0.052173102768426016
238.00000000000267,29.658102515778378,0.46287410149187685,-0.055232486159642935
239.00000000000267,29.753264147702808,0.46510387007438514,-0.05654987320427729
240.0000000000027,29.848232832576137,0.46652175545547014,-0.06171433129364701
241.00000000000273,29.942939235070074,0.46768276846186824,-0.06409074507904489
242.00000000000273,30.03882000549243,0.4691504799325221,-0.06957497493990683
243.00000000000273,30.13331318791583,0.47176937537313535,-0.07240231395803942
244.00000000000276,30.22833866035939,0.4725541255357755,-0.07510650244749417
245.00000000000279,30.323734436755405,0.47425463351978375,-0.07825638905393895
246.00000000000279,30.420269883051247,0.4741611953707556,-0.08176835296781304
247.00000000000279,30.51468572580299,0.4728063862095068,-0.08777885207654768
248.0000000000028,30.608797649426172,0.4722496412715501,-0.09108175856364831
249.00000000000284,30.70400667731005,0.4719742044676911,-0.09501033381935242
250.00000000000284,30.799743963264536,0.4718210618941683,-0.09959065445851989
251.00000000000284,30.895240811813878,0.4711614021827248,-0.10417243184848468
252.00000000000287,30.99079183211272,0.4711403473621584,-0.10877260615164674
253.0000000000029,31.085234418215332,0.46942924705053124,-0.11394468471783936
254.0000000000029,31.18124853121664,0.4665567547327785,-0.11769152161349483
255.0000000000029,31.275789178460784,0.4694399237316762,-0.12566541780312157
256.00000000000296,31.37172043384481,0.4697747516182288,-0.13127844962556434
257.00000000000296,31.466803530057046,0.4707639251729053,-0.13726712591672774
258.00000000000296,31.56038894699693,0.47283351401832685,-0.14364869085120846
259.00000000000296,31.65669646064206,0.4750784136672789,-0.14875194023185
260.00000000000296,31.75099799709017,0.47715200408178515,-0.15721060075677418
261.000000000003,31.846433488602067,0.48394965864038053,-0.16289375136732076
262.000000000003,31.941801357579248,0.4890542008738457,-0.1702989215962667
263.000000000003,32.03750267000543,0.4948576530663591,-0.17823976734643043
264.00000000000307,32.13244057568101,0.5027835460532271,-0.18514676885883574
265.00000000000307,32.225609538416606,0.5091863091289928,-0.19397830494879909
266.00000000000307,32.32288130543222,0.5166947248375132,-0.20226712023514493
267.00000000000307,32.418629982803665,0.52267893748261,-0.2115373721962297
268.00000000000307,32.51349993641728,0.5294426412320216,-0.21927046019662866
269.0000000000031,32.6091700000003,0.5365237648970465,-0.2288999130000251
270.0000000000031,32.70354190852872,0.5420985612444518,-0.23767756148684205
271.0000000000031,32.79999341699057,0.5464070312110875,-0.24818845663250944
272.0000000000032,32.895876097672996,0.5523834778230439,-0.25999194604031794
273.0000000000032,32.99016151810187,0.5585839571349052,-0.26899087194156834
274.0000000000032,33.087103651659895,0.5620659202210496,-0.2799438857003551
275.0000000000032,33.18169963509697,0.5689303237610704,-0.29100370701527156
276.0000000000032,33.27609306161085,0.5732345280865175,-0.30115606358398583
277.00000000000324,33.371465385931145,0.5780597961809943,-0.314228823494894
278.00000000000324,33.46864187985525,0.5823537501942484,-0.3277234939380711
279.00000000000324,33.56334411277174,0.5851329877995157,-0.338641187558685
280.0000000000033,33.658887120670855,0.585794885186363,-0.35326733886139783
281.0000000000033,33.75151539432518,0.5871382906945686,-0.36488089425414705
282.0000000000033,33.84906775001809,0.5902818190380502,-0.37928761447042714
283.0000000000033,33.94463044321252,0.5913385545985286,-0.3948624408678234
284.0000000000033,34.04071501540359,0.5894953453329136,-0.41150625750409464
285.00000000000335,34.13542905776151,0.587044215798721,-0.4263185426664755
286.00000000000335,34.23145489069507,0.5861069656845623,-0.4422868978659831
287.00000000000335,34.326856570085944,0.583378402701044,-0.4590807130757484
288.0000000000034,34.420260616224816,0.5778575827694802,-0.47926720826160407
289.0000000000034,34.51805064517329,0.5748668127654886,-0.4997703794766082
290.0000000000034,34.61375939030408,0.5680252922791247,-0.5178448758795247
291.0000000000034,34.70907614512321,0.5630273794316178,-0.5404422399867439
292.0000000000034,34.804156656383476,0.5575769577940409,-0.5642102909065394
293.00000000000347,34.900118800907805,0.5543815634128622,-0.5909412090779087
294.00000000000347,34.995202381448976,0.5543371435039549,-0.6195600092004847
295.00000000000347,35.090681834593894,0.5530414450141653,-0.6481059465332537
296.0000000000035,35.186175436641236,0.546897743904482,-0.6785976566749605
297.0000000000035,35.28129759159349,0.5387993675560663,-0.7080575990125193
298.0000000000035,35.3778825200104,0.5319733630256757,-0.7408690756539005
299.0000000000035,35.47318798837706,0.5265889896468976,-0.7711762280034686
300.0000000000035,35.56954178732256,0.5247790480858094,-0.8016257675061254
301.0000000000036,35.664107828111945,0.5345456919097368,-0.8315977675252726
302.0000000000036,35.759806277227504,0.5434452800893006,-0.8626665503972584
303.0000000000036,35.855560577674495,0.5549331824427716,-0.8905424231154222
304.00000000000364,35.95181595113346,0.5671505641285921,-0.9198861204074502
305.00000000000364,36.046607321277584,0.5788784267822237,-0.9509889472120086
306.00000000000364,36.14230283371867,0.5906826248938478,-0.9807026167629016
307.00000000000364,36.23926515703766,0.6017087429777062,-1.0124518888806002
308.00000000000364,36.33482075037357,0.6123521833795488,-1.0416006222899905
309.0000000000037,36.43106945020243,0.6217152512386414,-1.0732807512029576
310.0000000000037,36.526828899200325,0.6253952580158078,-1.102999533647564
311.0000000000037,36.622897880632685,0.628931780101661,-1.133250127980657
312.00000000000375,36.71917000000038,0.631194825177896,-1.164139955726045
313.00000000000375,36.814544083375566,0.6248285371326817,-1.1956952892136794
314.00000000000375,36.91083241118719,0.618611638438569,-1.2259196468837907
315.00000000000375,37.00754652136584,0.6071138828800392,-1.2556849414681968
316.00000000000375,37.101666304880794,0.5976726628821072,-1.2829998993390062
317.0000000000038,37.1991700000004,0.5838785232790653,-1.31325340805465
318.0000000000038,37.29489405909834,0.5718671382016305,-1.340473501790341
319.0000000000038,37.39118554115989,0.5538788576334057,-1.3665799950766342
320.00000000000387,37.48661167232281,0.5376031983970049,-1.392509219917068
321.00000000000387,37.583727191835806,0.5241376392739561,-1.4162452945510018
322.00000000000387,37.679017990056906,0.505574275299861,-1.4394389256598132
323.00000000000387,37.775055230241335,0.4886954562043975,-1.4602086109749464
324.00000000000387,37.871264941311765,0.4709546095743442,-1.4800537587010676
325.0000000000039,37.967754499307354,0.4573493553814931,-1.499813797879877
326.0000000000039,38.06436301111316,0.44250723741362863,-1.5182706982613365
327.0000000000039,38.1605144752813,0.42785456660593,-1.5345264172255564
328.000000000004,38.25528257988939,0.41709381607010165,-1.5499109878399233
329.000000000004,38.352637600938294,0.40282483333317326,-1.563724323216615
330.000000000004,38.44977295856118,0.39004649857552226,-1.5754387985868568
331.000000000004,38.544995379850526,0.3795567603256747,-1.585680228507686
332.000000000004,38.64177275767149,0.3686817179592808,-1.5981873942012212
333.00000000000404,38.73845192838458,0.3583187408223772,-1.607929962516335
334.00000000000404,38.83420211122645,0.34568481253920197,-1.6174082135752377
335.00000000000404,38.93048109584866,0.33661906042057704,-1.6252479496058414
336.0000000000041,39.025362489759516,0.32518844404448927,-1.633776414572012
337.0000000000041,39.12372862651022,0.3159498735329486,-1.6413948299680272
338.0000000000041,39.21986856457832,0.309497863427555,-1.6492256098529081
339.0000000000041,39.31496503652563,0.3018779719449143,-1.6543375445394788
340.0000000000041,39.41079801101511,0.29183705193029436,-1.658229245753875
341.00000000000415,39.50839334106427,0.28484228130715145,-1.6646583438495943
342.00000000000415,39.60433512100961,0.2771741328852825,-1.6688925375928525
343.00000000000415,39.700173807291584,0.2694511839270333,-1.6733311900063406
344.0000000000042,39.79618134989903,0.2614180560149571,-1.6769569570355891
345.0000000000042,39.89169834010316,0.25647801978048684,-1.680519175158731
346.0000000000042,39.98657099810284,0.25210294846053405,-1.683743819401287
347.0000000000042,40.084763984963274,0.2490136473573823,-1.6877344656912499
348.0000000000042,40.18119011106745,0.24219446529838018,-1.6913035466021231
349.00000000000426,40.2767437773296,0.23946454869652406,-1.6941767756902193
350.00000000000426,40.37288039689029,0.2330784870648353,-1.6954526032409651
351.00000000000426,40.47031898891893,0.22950628635261433,-1.698782837776681
352.0000000000043,40.56417426300563,0.22651438523845635,-1.7004000567354192
353.0000000000043,40.66263241096283,0.2220372125274705,-1.702621973060623
354.0000000000043,40.75980906933104,0.21807659442951222,-1.7040596816770135
355.0000000000043,40.85569459937085,0.21578128205601693,-1.7054047122473115
356.0000000000043,40.95256195008943,0.21425925057196898,-1.7080743800485232
357.0000000000044,41.04971533780903,0.21290183206907004,-1.7093297300190557
358.0000000000044,41.145415325175286,0.20959056887200977,-1.7107765335483247
359.0000000000044,41.24244303639877,0.20890518088852317,-1.7122225955684693
360.00000000000443,41.339453734697415,0.2078454233999441,-1.7150397921836364
361.00000000000443,41.43550851829479,0.20629158818981347,-1.7150077552888296
362.00000000000443,41.53324013521347,0.20501699833755938,-1.71636064226978
363.00000000000443,41.629696196676306,0.20572862458095947,-1.717671428931939
364.00000000000443,41.727188029276604,0.205613386805457,-1.7189899068789276
365.0000000000045,41.82387064981885,0.20511801058495943,-1.7190002974449223
366.0000000000045,41.91984379445935,0.2067575726919219,-1.7203101430694274
367.0000000000045,42.01723909504198,0.20616148301789017,-1.7216442623699417
368.00000000000455,42.115528439778146,0.2062398980083966,-1.7216299380174105
369.00000000000455,42.2119992084124,0.20700152079145567,-1.7229382438061935
370.00000000000455,42.30881204052048,0.20881636821091798,-1.7229410485084182
371.00000000000455,42.404841537461664,0.20853897203022825,-1.7242599690631004
372.00000000000455,42.50217445693946,0.2073396066781335,-1.7244098698885915
373.0000000000046,42.598906210369506,0.20818363514780258,-1.725487071031306
374.0000000000046,42.69612015249032,0.20847947206557277,-1.7245907422969564
375.0000000000046,42.79344840898401,0.20810360704440656,-1.72657004954395
376.00000000000466,42.88861803762659,0.21053540007426585,-1.7272224509226088
377.00000000000466,42.98642211399538,0.20920032317438364,-1.7279360771857037
378.00000000000466,43.083254298659234,0.21138491284162053,-1.7298372206810555
379.00000000000466,43.18032158976063,0.21252324716049503,-1.7298599729732613
380.00000000000466,43.27643661074521,0.210894983516896,-1.729859950477766
381.0000000000047,43.37270854382521,0.2111559226840064,-1.7311690638770152
382.0000000000047,43.46979169731321,0.21138738863196366,-1.7311801761161516
383.0000000000047,43.567344952866904,0.21146724160112035,-1.732501609493522
384.0000000000048,43.66468664435852,0.21298802604293582,-1.7324995651746202
385.0000000000048,43.76084153357376,0.21130662492871732,-1.7338100183673562
386.0000000000048,43.85830351789108,0.21357574726776762,-1.735129706990251
387.0000000000048,43.95617345977445,0.2120659927097267,-1.7341271708789323
388.0000000000048,44.052978424125826,0.20926428997841712,-1.7341401066871538
389.00000000000483,44.15025608529958,0.21095784184442273,-1.7354554023494781
390.00000000000483,44.24711552476787,0.20904900981275382,-1.7360877292371408
391.00000000000483,44.34424877071328,0.2074873629557552,-1.7379076848229174
392.0000000000049,44.44230815256353,0.20931379732851568,-1.73838150112365
393.0000000000049,44.53906890723961,0.208099855027908,-1.7384201206982204
394.0000000000049,44.636684295880016,0.20880729804929993,-1.7399144835211895
395.0000000000049,44.73308428329556,0.2077103553051829,-1.741059805329475
396.0000000000049,44.83083083039322,0.20799521026482665,-1.741059801728737
397.00000000000495,44.92766486444079,0.20695876347709763,-1.7424045101370238
398.00000000000495,45.02525146060238,0.20585875625904554,-1.7414521651410544
399.00000000000495,45.12164505022124,0.20531448532233826,-1.743694165655271
400.000000000005,45.219671439389764,0.20768090113035825,-1.7450101569561252
401.000000000005,45.31771111547326,0.20588682092788707,-1.746357154613539
402.000000000005,45.41542197116756,0.20381987345529456,-1.7463275255443738
403.000000000005,45.511855057651225,0.20362908741451713,-1.7476622696697928
404.000000000005,45.61055635718599,0.20362318026405124,-1.7476391362979005
405.00000000000506,45.70768379306181,0.20366611470831142,-1.750202853813391
406.00000000000506,45.804579068025355,0.2020657667913543,-1.750355017648717
407.00000000000506,45.903036574183794,0.20292763669540614,-1.7515957591278286
408.0000000000051,46.000075833427665,0.19842399237738761,-1.7542150849490428
409.0000000000051,46.09675140255486,0.2005547373170733,-1.7542298131962557
410.0000000000051,46.1949710158307,0.20020987229430565,-1.755545162109661
411.0000000000051,46.2936525902032,0.1989271995882756,-1.75681795470937
412.0000000000051,46.391428342487416,0.19826186718285305,-1.7584816030025494
413.0000000000052,46.48823182494372,0.19563178571986156,-1.7604070519457022
414.0000000000052,46.585755443070184,0.19575963718319583,-1.7621425326489333
415.0000000000052,46.68433434222782,0.19504732914814388,-1.7634450614623778
416.00000000000523,46.78033277133881,0.19411118658384474,-1.7634556001891908
417.00000000000523,46.87834560909356,0.1924112232478708,-1.7674050471422404
418.00000000000523,46.976620903226944,0.19348265785980973,-1.7674277557795603
419.00000000000523,47.07294272833559,0.19331322567672976,-1.7700562691113704
420.00000000000523,47.170229274776965,0.1928308134014982,-1.7714225193466482
421.0000000000053,47.26842254275368,0.19128552393333154,-1.775409651976665
422.0000000000053,47.36742555847331,0.19025963822673797,-1.7765866771780914
423.0000000000053,47.46565204103876,0.18963028937007292,-1.7786986641532931
424.00000000000534,47.56300039099443,0.18994917171934317,-1.7814662085950648
425.00000000000534,47.66017166627955,0.18958196233838115,-1.7834034449526524
426.00000000000534,47.757423276721866,0.18961028405305264,-1.7858049813354375
427.00000000000534,47.856147918264355,0.18845167527637147,-1.789605429717073
428.00000000000534,47.95435078014275,0.1917646246696073,-1.7915410936023832
429.0000000000054,48.05268607306885,0.1904224862047344,-1.7942298188512642
430.0000000000054,48.14973834177062,0.19242772120361207,-1.7963209014541146
431.0000000000054,48.2483254275752,0.19168368908697775,-1.8006720278907937
432.00000000000546,48.34617622278864,0.19353311404978496,-1.8036434153812682
433.00000000000546,48.44383747868436,0.19338221714223947,-1.8079766579732102
434.00000000000546,48.54204297637578,0.19504766012092783,-1.8125203831939265
435.00000000000546,48.63878430043462,0.19823848917889303,-1.815565871865525
436.00000000000546,48.73714674185732,0.2000024565867497,-1.8212272557017988
437.0000000000055,48.834153823522755,0.2003451735167745,-1.8260579869412408
438.0000000000055,48.932918551102404,0.2036217636075826,-1.8308910793023814
439.0000000000055,49.030552376222495,0.20628394528690236,-1.8353218057632583
440.00000000000557,49.127966345314,0.2097178951518964,-1.8406431475974965
441.00000000000557,49.22628874607063,0.21430327820703432,-1.8459572074752506
442.00000000000557,49.32495627520166,0.21716831534248188,-1.851568427347984
443.00000000000557,49.421631785365,0.22224304307564946,-1.8569284516819011
444.00000000000557,49.51982768228516,0.22670044960752542,-1.8633607367618494
445.0000000000056,49.61636320753718,0.23412435232544393,-1.8701780414595364
446.0000000000056,49.714500024213244,0.23725582698655406,-1.8757540779406923
447.0000000000056,49.81399404184585,0.24246798800746314,-1.883416473083745
448.0000000000057,49.912977702794365,0.2484221148659194,-1.8912293608299313
449.0000000000057,50.00812795774385,0.25431265344920895,-1.898332002411892
450.0000000000057,50.108655013230845,0.2608873834835401,-1.9057665078615802
451.0000000000057,50.20687156030581,0.26700798061158565,-1.9133309860681957
452.0000000000057,50.30470136275111,0.27405978388287,-1.9230796393408691
453.00000000000574,50.40425244125601,0.27914512873950725,-1.9316815821381366
454.00000000000574,50.50120782508087,0.2877208347023469,-1.9384995091313835
455.00000000000574,50.59970276163067,0.2949450692660609,-1.950114856597987
456.0000000000058,50.697601863415436,0.30317630752430963,-1.9589291194559468
457.0000000000058,50.796792785117404,0.30713400381893624,-1.967450011884663
458.0000000000058,50.89235335056649,0.3151165580926547,-1.9771535287155908
459.0000000000058,50.99279369734,0.32267175333263454,-1.988174396398192
460.0000000000058,51.09201346752092,0.33220166000223883,-1.9995125799394242
461.00000000000585,51.189264333603774,0.33685098721957096,-2.008609535360122
462.00000000000585,51.287469964420865,0.3454698311323969,-2.0198407037684887
463.00000000000585,51.38606137810018,0.3512155710666612,-2.0327687849642326
464.0000000000059,51.48311434070724,0.35801245873976684,-2.0445495612834472
465.0000000000059,51.58253125634216,0.36347166862428687,-2.0567899597576447
466.0000000000059,51.68167773716486,0.37143738168765134,-2.0700061785081427
467.0000000000059,51.78009264316247,0.3755311607193737,-2.0831835153835105
468.0000000000059,51.87955808266219,0.3842339641236042,-2.0971290523458146
469.00000000000597,51.976935132476854,0.39123781710651573,-2.111632834935474
470.00000000000597,52.074922021848806,0.39562539855909445,-2.125746758885791
471.00000000000597,52.17366700123979,0.4026804303322636,-2.1423799910254777
472.000000000006,52.2720931495216,0.408744100550128,-2.1577757762721417
473.000000000006,52.370787651268245,0.41563733978832634,-2.1742866140105015
474.000000000006,52.46808737021428,0.42022123424114316,-2.1917049161920277
475.000000000006,52.56897315603733,0.4275907089213989,-2.2096749918866574
476.000000000006,52.666554326474326,0.43279826741388405,-2.227165217162084
477.0000000000061,52.765632377797644,0.4409303901244745,-2.2455651355963324
478.0000000000061,52.86452984922646,0.44391805560789904,-2.2656380091850084
479.0000000000061,52.96392803068741,0.4469169922859637,-2.2858879613587
480.00000000000614,53.06273842336243,0.4514541327854953,-2.3073650671762302
481.00000000000614,53.16141489309535,0.4538461853342485,-2.3286106167837692
482.00000000000614,53.26023248598729,0.45412980917054574,-2.3517657610292493
483.00000000000614,53.35945652958298,0.45737908544222194,-2.3745697601753175
484.00000000000614,53.457701546104765,0.454522846043803,-2.3952722253509418
485.0000000000062,53.55596540215396,0.45523642194285496,-2.4185791702254793
486.0000000000062,53.65543316718805,0.45358903518565524,-2.4430708774188865
487.0000000000062,53.75381807518448,0.44552749021892696,-2.465724175203212
488.00000000000625,53.8526884459368,0.44124837780717635,-2.4870738031195643
489.00000000000625,53.95150714507662,0.432807652428189,-2.5104757804640943
490.00000000000625,54.049774491333245,0.42438602565535877,-2.532587965336745
491.00000000000625,54.148615059372766,0.4143327980534076,-2.5547839368588257
492.00000000000625,54.24743087339261,0.4043303684542215,-2.5768945431458965
493.0000000000063,54.34572750771409,0.39760170680763635,-2.5972394138790613
494.0000000000063,54.44504860438248,0.3862971929060789,-2.6165763357737903
495.0000000000063,54.54379377105132,0.37256994242182384,-2.6344563541538832
496.00000000000637,54.64149307361077,0.35467388613948303,-2.6522333018341584
497.00000000000637,54.74117495088044,0.33154264750649465,-2.6694928749716103
498.00000000000637,54.83880734566377,0.3107188678219669,-2.6844815693005804
499.00000000000637,54.938680797348994,0.29030662677193253,-2.6988238666173476
500.00000000000637,55.0366451932651,0.26904758149272295,-2.7106851771333784
501.0000000000064,55.1359601560572,0.24659174911986828,-2.7194972190496034
502.0000000000064,55.234299229806666,0.22695961970693387,-2.7280836270954056
503.0000000000064,55.33356833600238,0.21029441755377243,-2.735761487842556
504.0000000000065,55.43183881801404,0.19378165002311099,-2.742687675942503
505.0000000000065,55.53136660340852,0.17972873196620134,-2.7475239485605636
506.0000000000065,55.62701484231758,0.1683434420416977,-2.7503225934767688
507.0000000000065,55.729485533135225,0.16138481544391395,-2.75446366359754
508.0000000000065,55.827879342186634,0.15672031412835505,-2.757337354246041
509.00000000000654,55.927937739432004,0.15182824152520055,-2.761071664574782
510.00000000000654,56.02619711619344,0.14792216391836063,-2.762494937574188
511.00000000000654,56.125934068228815,0.14796426317163294,-2.763799437451189
512.0000000000066,56.22492767702842,0.14422994596702626,-2.7639047920595003
513.0000000000066,56.32421783110832,0.14221543679217166,-2.7662763591416635
514.0000000000066,56.423818847225476,0.13997420787833287,-2.7687467886224786
515.0000000000066,56.522015787199365,0.13849368002186524,-2.7699951687549373
516.0000000000066,56.62070777403738,0.13850513454537217,-2.770024282042697
517.0000000000066,56.719262468651955,0.13627021720691457,-2.7713681618896135
518.0000000000066,56.819075764325724,0.1366176237047782,-2.7740000809068937
519.0000000000066,56.917904421574605,0.13887819850066255,-2.7742505207429176
520.0000000000067,57.01706521134697,0.13953235492020158,-2.77659091740518
521.0000000000067,57.11694344363209,0.1427188475585792,-2.7780726716835575
522.0000000000067,57.214804802355935,0.14586786428716725,-2.7793591540036227
523.0000000000067,57.315194758192376,0.14633060317203844,-2.780704458894017
524.0000000000067,57.413073412602955,0.1470908775286069,-2.78167412197198
525.0000000000068,57.512996480457026,0.14924043971287965,-2.7820198759354007
526.0000000000068,57.61144239899609,0.1469297350493286,-2.7806654038165965
527.0000000000068,57.710045956970056,0.1505988179526182,-2.783963570070536
528.0000000000068,57.8114326402984,0.1516157320982584,-2.7855438216601134
529.0000000000068,57.90885633098955,0.14831862736976587,-2.786864363294152
530.0000000000068,58.00855260794375,0.1518971348882265,-2.786859888046192
531.0000000000068,58.10796137999763,0.15145416104442633,-2.7881699443669
532.0000000000068,58.208113020382626,0.15024735972846495,-2.7881481519587847
533.0000000000068,58.30659932053324,0.14937932946373672,-2.790851986154827
534.0000000000068,58.405792999471785,0.15034740536237978,-2.790813181638025
535.0000000000068,58.50527929021649,0.1537639027382544,-2.792138965366832
536.0000000000069,58.60464175254299,0.1524765224346083,-2.7921336816677664
537.0000000000069,58.703087920268466,0.15297265926624448,-2.7934400556038805
538.0000000000069,58.80270448120531,0.1549522729959104,-2.7947314254402524
539.0000000000069,58.902124215613654,0.15344748033740702,-2.794760251972213
540.0000000000069,59.001966645539525,0.15546967296477604,-2.7967437587748907
541.000000000007,59.10090930995918,0.15043807224975997,-2.79805032433696
542.000000000007,59.20051439697047,0.15095299103307522,-2.7993690856781024
543.000000000007,59.301277621595865,0.1517572276330674,-2.7993688254672415
544.000000000007,59.39970146911236,0.15038848436928415,-2.80068982995328
545.000000000007,59.499264886677445,0.1458464796390216,-2.8019999686706716
546.000000000007,59.598969339348855,0.1452196963108121,-2.803323167901996
547.000000000007,59.69789388098779,0.14598760727785526,-2.802870735894699
548.000000000007,59.7976241529028,0.14308505155368992,-2.8033201823681333
549.000000000007,59.89763875307269,0.14165972591743548,-2.80464004270611
550.000000000007,59.995874367024626,0.1395323176829395,-2.8059553563195485
551.000000000007,60.09611032581843,0.13892171637558562,-2.8058544036978805
552.0000000000072,60.19571850674115,0.13544032424961608,-2.8070380839473215
553.0000000000072,60.29456065390568,0.13961199313982012,-2.80826873378372
554.0000000000072,60.39474330429069,0.14053585058704218,-2.8096640459004227
555.0000000000072,60.491694038544466,0.1408755173203775,-2.8095911922922308
556.0000000000072,60.59166505528411,0.14174463922834182,-2.8098996378425616
557.0000000000073,60.693230696588714,0.1428994495920693,-2.8116609931899217
558.0000000000073,60.79232778908258,0.15009612847867068,-2.813682735586987
559.0000000000073,60.89265174804003,0.1535545136147161,-2.8148499489227596
560.0000000000073,60.99154474116853,0.16175524188383492,-2.816141927327709
561.0000000000073,61.091535139982284,0.16979541424724753,-2.8161721545479423
562.0000000000073,61.19166516637091,0.1773649212939658,-2.818354512703229
563.0000000000073,61.29231045891415,0.1895532410205324,-2.8200351687106266
564.0000000000073,61.3916663753314,0.1975932136317653,-2.822771855313494
565.0000000000073,61.49188964982065,0.2078758623261784,-2.8227111981980775
566.0000000000073,61.59323655421811,0.22218910472743036,-2.825464168458651
567.0000000000074,61.693192111255726,0.23077752463614667,-2.82673655915743
568.0000000000074,61.79063366985591,0.24247805530482047,-2.828241776236495
569.0000000000074,61.893146243287816,0.2553886835684649,-2.829778716924654
570.0000000000074,61.99293429489017,0.2654915270173783,-2.8311544745423642
571.0000000000074,62.09358473680064,0.2733334504702169,-2.834952759195554
572.0000000000074,62.19317736857039,0.2830257941421201,-2.83635658134331
573.0000000000074,62.29310893898702,0.2904659526166012,-2.83802806870081
574.0000000000075,62.393473886823266,0.29622020652752024,-2.8415741304194952
575.0000000000075,62.493324221198726,0.29762221294426705,-2.8432440596146527
576.0000000000075,62.59376982075731,0.29747704228305927,-2.845600327645121
577.0000000000075,62.693416221467736,0.29261306664983633,-2.848154023622298
578.0000000000075,62.79178248416436,0.27665365760411664,-2.8501390155014503
579.0000000000075,62.89105876820542,0.25576172073163533,-2.8521878293673852
580.0000000000075,62.992038729152,0.22644085901997452,-2.8535306658162973
581.0000000000075,63.089822191595495,0.1973591228867838,-2.85653343630859
582.0000000000075,63.1909760809437,0.17212697247646222,-2.8561104347111277
583.0000000000076,63.289941220492636,0.15474285423867973,-2.858759694459196
584.0000000000076,63.388220271856376,0.1374733829616103,-2.8600809742002546
585.0000000000076,63.48967004831595,0.1263581386620084,-2.860080670337438
586.0000000000076,63.58698330907884,0.11554774667459076,-2.8613999476656646
587.0000000000076,63.68937225055953,0.109091282318026,-2.862722309692752
588.0000000000076,63.788232466500325,0.10530661487413501,-2.8627099923266375
589.0000000000076,63.888561527045624,0.10062616419883827,-2.8636436271182966
590.0000000000077,63.98811784308096,0.09873890007766085,-2.864028858501152
591.0000000000077,64.08752632468544,0.09699777870412202,-2.8627033001841258
592.0000000000077,64.18771461857837,0.09431594760779696,-2.86403022436002
593.0000000000077,64.28777815383037,0.09467714101881972,-2.865349972572553
594.0000000000077,64.38787709265087,0.09309374405642677,-2.8653499194018153
595.0000000000077,64.48860578694755,0.09265887134346311,-2.866660286129963
596.0000000000077,64.58790952257579,0.09363255344332304,-2.866667523857701
597.0000000000077,64.68738951008754,0.09222781844147028,-2.86665303230004
598.0000000000077,64.78897060059373,0.09710731201835628,-2.8679760892817665
599.0000000000078,64.88906216188862,0.09546391238646705,-2.867490891011773
600.0000000000078,64.98845528737095,0.09631399873758426,-2.867980663922357
601.0000000000078,65.08992906075004,0.09745854163618556,-2.8679551747143224
602.0000000000078,65.18926364412536,0.09958536913477499,-2.8699598017056975
603.0000000000078,65.29016887745189,0.10335920767876697,-2.8699599009714896
604.0000000000078,65.39034519044235,0.107428266968964,-2.8704017229626686
605.0000000000078,65.4894561120135,0.11047762575273316,-2.871270053904776
606.000000000008,65.58968303213727,0.11329629225812708,-2.871288541342382
607.000000000008,65.69026128349094,0.11956924003893143,-2.871272376621319
608.000000000008,65.79020593798151,0.12263058767871983,-2.871269878979414
609.000000000008,65.89028155387473,0.1329933852607619,-2.8717051208082873
610.000000000008,65.99008223335755,0.1346339141211731,-2.873272153503545
611.000000000008,66.08986191808647,0.14474884511209665,-2.874569932325385
612.000000000008,66.18917000000084,0.14712597066523248,-2.875880085000024
613.000000000008,66.28982872265141,0.15366575995845647,-2.875880081886365
614.000000000008,66.38926656374178,0.16211519340041577,-2.8772378839489834
615.0000000000081,66.48869119392474,0.16718786392170337,-2.876836015599108
616.0000000000081,66.5885364794704,0.17193636356731729,-2.877503747575351
617.0000000000081,66.68802190104303,0.18127366756430713,-2.878529815197914
618.0000000000081,66.78818652856646,0.187601071470602,-2.8798399402131682
619.0000000000081,66.88797979171414,0.19365647528615115,-2.880114282916387
620.0000000000081,66.98762950675777,0.19642302253260596,-2.880771000074502
621.0000000000081,67.08498431887413,0.20308008955637505,-2.8821496156896553
622.0000000000082,67.18746708146087,0.20755735547616377,-2.882771044626629
623.0000000000082,67.28758306770632,0.2093248329211485,-2.8841196992112073
624.0000000000082,67.38704352572823,0.2144873737632193,-2.8854399942154982
625.0000000000082,67.486944912215,0.2170759979376356,-2.8867632714216165
626.0000000000082,67.58816342654666,0.22701970251763143,-2.8880699517279806
627.0000000000082,67.68782722834797,0.23455896344992516,-2.8897158262946134
628.0000000000082,67.78868211002288,0.23805430381307408,-2.8910394082951063
629.0000000000082,67.88999413385623,0.23953413965280843,-2.8910397794777687
630.0000000000082,67.98967797646561,0.2489113720177049,-2.892349648869323
631.0000000000083,68.09140680480841,0.2572641072033233,-2.8936763297940433
632.0000000000083,68.19017040102067,0.258860394301102,-2.895039879810187
633.0000000000083,68.29153863899782,0.2672119446593434,-2.8963057297858557
634.0000000000083,68.39191488672218,0.27494698381740895,-2.8976420129421054
635.0000000000083,68.49219712437855,0.286464551089636,-2.9002170369698943
636.0000000000083,68.59262679650891,0.29242916707678784,-2.9002400351253717
637.0000000000083,68.69396407169708,0.30301796876633913,-2.9015703815987983
638.0000000000084,68.79377328556657,0.31155893699450077,-2.904081200990399
639.0000000000084,68.89526226564881,0.3226093526963953,-2.905396529137377
640.0000000000084,68.99484680072885,0.3331529099409891,-2.906790872232555
641.0000000000084,69.09573127913156,0.34439834478549286,-2.909520376285461
642.0000000000084,69.19654832479574,0.35261296193208924,-2.9107263029109776
643.0000000000084,69.29721838838407,0.3666771730732703,-2.911286351075615
644.0000000000084,69.39738529842663,0.3784433231850167,-2.914748562032774
645.0000000000084,69.4973642034182,0.38792744428422044,-2.9174208147599563
646.0000000000084,69.59837480713256,0.3977546062613298,-2.917981961520491
647.0000000000085,69.69836864158272,0.40893595866486165,-2.9200249593456533
648.0000000000085,69.79917000000087,0.4195456467860478,-2.924959808268972
649.0000000000085,69.90001302255406,0.42824312440808393,-2.92495757431325