File: 01_Data/Coaxial_Cable/STA/N2/10K_min/Coaxial_Cable_STA_N2_10KData_220714_R1.csv
##Temp./Â°C,Time/min,DSC/(mW/mg),Mass loss/mg
50.0,10.642617875932155,0.02086148963142964,0.026164460643562926
51.000000000000014,10.977568528447147,0.07033972004220002,0.02910626160298513
52.00000000000003,11.188670594616275,0.10200041384433067,0.02870901276497939
53.00000000000004,11.359997889494142,0.1326255775672447,0.029059364964165724
54.00000000000006,11.507147759211037,0.15465203797872973,0.029523272600192385
55.00000000000007,11.649015047553913,0.1746690280495642,0.029959954220799112
56.000000000000085,11.78027726848494,0.18961706851223892,0.029565881398831984
57.0000000000001,11.904606403336413,0.20284862946844662,0.029513037219929927
58.000000000000114,12.025026618043343,0.2128054920297029,0.029605315843586943
59.00000000000013,12.143110967627866,0.22248362720399895,0.030444912203240193
60.00000000000014,12.25860073687665,0.22968139035472546,0.03054598565278699
61.000000000000156,12.371762444179527,0.2360340443673521,0.03042409917867328
62.00000000000017,12.478918931303497,0.2395209554651072,0.029443506667926833
63.000000000000185,12.593952653625669,0.24603319939333934,0.030392375736924215
64.0000000000002,12.7052160778193,0.24703240050197528,0.030405230813215667
65.00000000000021,12.81338092551364,0.2497201055607965,0.03139354255525273
66.00000000000023,12.922516587321807,0.25186090157229724,0.030787426704950605
67.00000000000024,13.031168696370182,0.25510427578251926,0.031706429024561444
68.00000000000026,13.136670270226594,0.2551937459564362,0.030433301007355418
69.00000000000027,13.244959704354855,0.2580936167101181,0.031706620223279636
70.00000000000028,13.350790316358323,0.2599682831402075,0.032822053893615255
71.0000000000003,13.457466550839706,0.26238250442184874,0.03172567558659445
72.00000000000031,13.562120011979955,0.2644036229726825,0.03167503486106149
73.00000000000033,13.668619867708797,0.2670383031773115,0.03133971196592267
74.00000000000034,13.77285754256968,0.2680806476017973,0.031730092004629284
75.00000000000036,13.878138498792293,0.2697998507166479,0.031743520304595485
76.00000000000037,13.982980621341392,0.27148844647914694,0.03172020345952564
77.00000000000038,14.087356404854196,0.2733151979720361,0.033033487564200215
78.0000000000004,14.191188161521872,0.2758032476562272,0.03303914016206022
79.00000000000041,14.294194168583815,0.27947242296749986,0.03402912193108776
80.00000000000043,14.398690220252504,0.28077337984385375,0.03305390362438576
81.00000000000044,14.496769527822467,0.2836312699093122,0.03304068520048009
82.00000000000045,14.601949388054798,0.28683752884046876,0.03304739327397321
83.00000000000047,14.705162495417456,0.288822909259425,0.03436272136410512
84.00000000000048,14.806227273463184,0.29134759538186683,0.03435637784599699
85.0000000000005,14.90842287655831,0.2942088173947146,0.03305571945786845
86.00000000000051,15.009170000000053,0.296071117686896,0.03305000232403543
87.00000000000053,15.110976154039644,0.29980553802914145,0.034039506218291216
88.00000000000054,15.211545415335603,0.301159062241811,0.03304032248003175
89.00000000000055,15.311413013890103,0.30415631520102626,0.034428565240719244
90.00000000000057,15.412649192553927,0.3075521388276212,0.03567855083652738
91.00000000000058,15.510981563112221,0.30912658671497373,0.034363159908837204
92.0000000000006,15.610872602874903,0.3141679467011602,0.034701474963499734
93.00000000000061,15.71147409144335,0.3166260093718771,0.03301369699014067
94.00000000000063,15.812183238833969,0.32143839822846165,0.03436004498873668
95.00000000000064,15.91014375869043,0.32416881240027273,0.035713946881944736
96.00000000000065,16.008627453478194,0.32890656816882835,0.03498750623640312
97.00000000000067,16.10851533972282,0.3316073507721752,0.03634023888751958
98.00000000000068,16.20678583266932,0.33553518027325946,0.036987068971762405
99.0000000000007,16.304470553143833,0.33967113694741036,0.03568016750169445
100.00000000000071,16.403826658026215,0.3438678009154301,0.03428519237982819
101.00000000000072,16.501517909580247,0.34583624171780036,0.03428638054383537
102.00000000000074,16.598396730511407,0.3503571576232539,0.034359925939797975
103.00000000000075,16.697619272218386,0.3522614060551411,0.03435992599998805
104.00000000000077,16.79583222430145,0.3550036386214289,0.034359902501995165
105.00000000000078,16.893697611229662,0.3594719021359417,0.03439454544391296
106.0000000000008,16.992366779031265,0.3607996985429358,0.035678814221154376
107.00000000000081,17.09010775492066,0.36379602273631917,0.034359903841157724
108.00000000000082,17.18837629078947,0.36698602192878693,0.03433868992461342
109.00000000000084,17.285926292257372,0.37182895563747176,0.0356800500536405
110.00000000000085,17.383062003460832,0.3750134042510145,0.03644102550454953
111.00000000000087,17.48319192255059,0.38097686844321554,0.035337611675662295
112.00000000000088,17.5763902437258,0.3840319606330911,0.034359480988904956
113.0000000000009,17.677692283080077,0.3889347806756006,0.035207961532956134
114.00000000000091,17.77208100138664,0.3933751055658602,0.035680794474793665
115.00000000000092,17.873697429630568,0.4003646591925142,0.03804063803342039
116.00000000000094,17.96973868957134,0.40614271442427796,0.03791441704302745
117.00000000000095,18.068011262104488,0.4134213438769949,0.03665331031003394
118.00000000000097,18.16472831549571,0.4239155106056869,0.03666018595166687
119.00000000000098,18.26311479126625,0.43351414641618047,0.0366601855337807
120.000000000001,18.360302399776934,0.44485041721557816,0.03658399418127534
121.00000000000101,18.457980830066745,0.46249701024522494,0.03666109556307351
122.00000000000102,18.555353936299795,0.4889395556124495,0.03764981576251447
123.00000000000104,18.652855773041484,0.5246091110691935,0.037649939325420156
124.00000000000105,18.751505089700117,0.5772766270581422,0.03634046553274928
125.00000000000107,18.84738998352137,0.6488139592610176,0.036989244654226816
126.00000000000108,18.945474261952555,0.7484993412177139,0.03830852757816139
127.0000000000011,19.044378262627273,0.8716865505928136,0.03766203724512884
128.0000000000011,19.141850916050505,0.9968826814501381,0.03640385833368587
129.00000000000114,19.240288121711746,1.0763647763228328,0.03698964919014269
130.00000000000114,19.33839713473307,0.9667782333175251,0.03831271611388676
131.00000000000114,19.43552285026787,0.7008027582630609,0.03691644315300824
132.00000000000117,19.53191726698841,0.5408346908743691,0.03830908133864952
133.0000000000012,19.62778291445482,0.44872469453780217,0.037650015656493174
134.0000000000012,19.724549789783158,0.3981691798765109,0.03765106702183463
135.0000000000012,19.82000641963235,0.3675871040707216,0.03902024545426919
136.00000000000122,19.915253946184837,0.35009487762447167,0.037660024321461094
137.00000000000125,20.01136506284651,0.34234096965233884,0.03634051935126603
138.00000000000125,20.10661883330373,0.3359834877105049,0.03869529925422199
139.00000000000125,20.20393519973956,0.33348459918231554,0.0389799399735864
140.00000000000128,20.29647556214165,0.3301056375245407,0.037659946544991385
141.0000000000013,20.39593039365939,0.3312130672607061,0.03762137729992254
142.0000000000013,20.491340971258193,0.33162270870637944,0.037979978900302136
143.0000000000013,20.587693706308386,0.3311988788666368,0.03864044147931889
144.00000000000134,20.68393834578584,0.33288215969014157,0.03863993000294741
145.00000000000136,20.77945779524626,0.3331015587260786,0.03863992999999866
146.00000000000136,20.875101045960278,0.33634550977614885,0.038639929722445565
147.00000000000136,20.970025010114153,0.3354944947102969,0.0385783602735037
148.0000000000014,21.064692830651,0.3384725115515269,0.03751004570835459
149.00000000000142,21.16045304885472,0.33794131663699056,0.03896063099123914
150.00000000000142,21.258083780465277,0.3393060585278548,0.03765991286550996
151.00000000000142,21.353153039458768,0.3413026209593433,0.0376599412535672
152.00000000000145,21.44888090256148,0.34377387817549976,0.036342580486963705
153.00000000000148,21.54529688668893,0.3411438487709294,0.03895427926272532
154.00000000000148,21.641006532004237,0.3431612311170176,0.038970075943647764
155.00000000000148,21.735895436258367,0.3449813081862434,0.0389700759696856
156.0000000000015,21.831415725447474,0.3469670569714782,0.03894715240632873
157.00000000000153,21.926378891548644,0.3483337632859205,0.038953964389245144
158.00000000000153,22.02358956861094,0.35095065663317104,0.03905137813431292
159.00000000000153,22.118696169946492,0.3530727273499752,0.0376499817895839
160.00000000000156,22.21370379828656,0.3529742120341429,0.037649951374220336
161.0000000000016,22.309737654260328,0.3534229014917568,0.03897006640974965
162.0000000000016,22.405302801672402,0.351749169700735,0.03890258883615072
163.0000000000016,22.50130384112647,0.3496605177094704,0.04012126467402588
164.00000000000162,22.594584821983542,0.34730135382761007,0.037682641084711754
165.00000000000165,22.69318734216491,0.34472166995706943,0.03895319477102799
166.00000000000165,22.78753029891792,0.34404214280915935,0.03766018205384114
167.00000000000165,22.88371598683662,0.3425616877868838,0.037660236504996725
168.00000000000168,22.979732917349693,0.3418322112232084,0.03766837347373464
169.0000000000017,23.07504422976006,0.34314153023909866,0.03634773650282508
170.0000000000017,23.16806319831366,0.3450317994654689,0.03767947962902607
171.0000000000017,23.266548132610385,0.343766910719821,0.03897085805834788
172.00000000000173,23.361428391936496,0.34528417498159847,0.038639451737819464
173.00000000000176,23.45785267799871,0.34496762527377955,0.037669742649582005
174.00000000000176,23.552140750800987,0.34572838126151983,0.037650094530114586
175.00000000000176,23.64858666672422,0.3470186821832477,0.03797979121861417
176.0000000000018,23.74447244560781,0.34785100751136966,0.03797985990214503
177.00000000000182,23.84043314032415,0.34926940494293024,0.039305169550157615
178.00000000000182,23.93620316529683,0.3500983696452602,0.03895591778297991
179.00000000000182,24.0310075311284,0.34931597432652084,0.03897013002018035
180.00000000000185,24.126601345875592,0.35017638107710025,0.037651749343089236
181.00000000000188,24.222950698414365,0.35254567842010887,0.038952075171446054
182.00000000000188,24.318971069363425,0.3535084657868801,0.038004805210313464
183.00000000000188,24.413607134585288,0.35387976056404813,0.038856590449142026
184.0000000000019,24.507991387856354,0.35444642487251954,0.038970080207554325
185.00000000000193,24.603590298896773,0.35523781808836397,0.038195983880574325
186.00000000000193,24.6993728193723,0.3551724033038549,0.03762208811500578
187.00000000000193,24.793811393550175,0.3572290954276143,0.03634017615713159
188.00000000000196,24.887323498979452,0.3565367919640464,0.036264571429934556
189.000000000002,24.98486386999815,0.3579204394950094,0.03633929679822412
190.000000000002,25.080825645929483,0.3576987195438175,0.036340079994499064
191.000000000002,25.175237355560025,0.3596008300348582,0.03634008001405409
192.00000000000202,25.271498301188803,0.36082629302329805,0.03632907027519483
193.00000000000205,25.366287240917043,0.3626580568310146,0.03502006796816648
194.00000000000205,25.46204564439414,0.3607914950172183,0.03502008000005841
195.00000000000205,25.55670419909528,0.36241827165510354,0.03502007999999979
196.00000000000207,25.651913182405742,0.3631854234904941,0.03502007999999979
197.0000000000021,25.746929320138157,0.36430458170086344,0.03502008000000156
198.0000000000021,25.841790258901188,0.3651443636939934,0.03502007982146882
199.0000000000021,25.936572852674498,0.3635538477316387,0.034782948510202694
200.00000000000213,26.03299622109275,0.36605082905333475,0.03238191245976285
201.00000000000216,26.12710936640606,0.3675081902813639,0.03370002346491141
202.00000000000216,26.22296191795022,0.36692126998143165,0.033700080007228905
203.00000000000216,26.318866437501793,0.36914864880585896,0.03376172896302165
204.0000000000022,26.41334727763512,0.371087403243042,0.033050079948976574
205.00000000000222,26.507481801431762,0.3685736088279041,0.03286026536718545
206.00000000000222,26.602892726589385,0.3718975267688268,0.03107211970250212
207.00000000000222,26.698880235802086,0.37239660293917354,0.032403446682049086
208.00000000000225,26.79365441733204,0.37396980929442925,0.03107017480229146
209.00000000000227,26.887378426071084,0.37443838701449206,0.031070160472387975
210.00000000000227,26.983792065454082,0.37745173530493964,0.029749293389392584
211.00000000000227,27.079071175144726,0.3783649610190376,0.027512243559429272
212.0000000000023,27.174328248303514,0.3774757260009267,0.027107073006800597
213.00000000000233,27.267663460307062,0.37895890119573494,0.02710995600805699
214.00000000000233,27.363608391181053,0.38105165968063015,0.02710995772877478
215.00000000000233,27.459918158382777,0.3830042900254344,0.02641193727454283
216.00000000000236,27.554836988077735,0.38484114945301334,0.026129871754909217
217.0000000000024,27.649834488838582,0.38809061168198733,0.026134501171811486
218.0000000000024,27.74459763492525,0.3901676698905596,0.024480468716093995
219.0000000000024,27.840598688275538,0.39220969355715424,0.023159988116428387
220.00000000000242,27.93578376429596,0.39553947132363887,0.021800022748331038
221.00000000000244,28.030704438988415,0.39884000562662536,0.02183998199777104
222.00000000000244,28.12571690481857,0.40253505760723285,0.0208175801304753
223.00000000000244,28.219970465757243,0.40517055286314135,0.01979815140858321
224.00000000000247,28.31599901684125,0.40849032480899794,0.018191042378749245
225.0000000000025,28.410787930716594,0.41121878784713845,0.015461298610163432
226.0000000000025,28.505823708121888,0.4176074490158637,0.016543637579388815
227.0000000000025,28.60060195225801,0.4191593683800232,0.013941677723526169
228.00000000000253,28.695621333364578,0.42068065434550783,0.012620430196989219
229.00000000000256,28.791732107284496,0.4260574095335308,0.01129232057266183
230.00000000000256,28.886020842853107,0.42584811102015274,0.009349334278789811
231.00000000000256,28.981721842198734,0.43120294923174274,0.007511450467275971
232.0000000000026,29.076347020722103,0.4341381956611872,0.006936952863174639
233.00000000000261,29.17124181987787,0.4374878284478356,0.006023722747918292
234.00000000000261,29.266761521649368,0.43960389808398376,0.002993498454440413
235.00000000000261,29.36151450510285,0.4416827391791058,0.0011047744154746297
236.00000000000264,29.457511993406683,0.44304585404668567,-0.0015756935932023097
237.00000000000267,29.55269940106934,0.44504220714349507,-0.002850654495923699
238.00000000000267,29.647061456841424,0.4477774626384804,-0.004189719336300968
239.00000000000267,29.742814122863734,0.45014001448085683,-0.006947117701892935
240.0000000000027,29.8386042282242,0.449632195321929,-0.010162621887820578
241.00000000000273,29.933756511515178,0.4515324408679551,-0.011261610966068147
242.00000000000273,30.028058431904217,0.45230854473414733,-0.016582946298763446
243.00000000000273,30.124336850854654,0.45342952713427764,-0.01794729461878486
244.00000000000276,30.219170000000258,0.45297407058729483,-0.02162981669023889
245.00000000000279,30.31480078996057,0.4529047648480686,-0.024227005742388563
246.00000000000279,30.40863511976125,0.4526093434661988,-0.026897203949080684
247.00000000000279,30.50344016241392,0.4520477631213141,-0.029862217852386408
248.0000000000028,30.59957940541453,0.4533232864825958,-0.03341317146244549
249.00000000000284,30.691862956434775,0.45353143580466493,-0.038157814422245195
250.00000000000284,30.78993370457657,0.45167737897707283,-0.041344062056207775
251.00000000000284,30.884981152069003,0.4507484304268546,-0.04522991659967168
252.00000000000287,30.979967281902404,0.4490905347782262,-0.04871328544375331
253.0000000000029,31.075633687624673,0.4512854097874568,-0.05527646089198868
254.0000000000029,31.170958732658317,0.45227789109953764,-0.058532241105147875
255.0000000000029,31.26667952377695,0.45460796285445954,-0.062115966620246876
256.00000000000296,31.361053653868495,0.45646062730169756,-0.06679182946122042
257.00000000000296,31.455696030260096,0.4579108619590441,-0.07102083457527675
258.00000000000296,31.552448260224743,0.461227824004978,-0.07686148443586571
259.00000000000296,31.6467077767654,0.46345137162365435,-0.08295170880354075
260.00000000000296,31.741128875380824,0.4652811283112611,-0.08762044787979839
261.000000000003,31.83568849101008,0.4706534474867213,-0.09275596105154182
262.000000000003,31.93104562841129,0.4745295288316251,-0.09841869210117116
263.000000000003,32.02719622058301,0.47996437826395527,-0.10269822925752914
264.00000000000307,32.12136780332067,0.4825711165226591,-0.11032627899676406
265.00000000000307,32.217220310184146,0.48725090313489744,-0.11778081079269098
266.00000000000307,32.31201625778468,0.4917675320309761,-0.12254325190683613
267.00000000000307,32.408154000936094,0.49432547316890624,-0.12955482390680562
268.00000000000307,32.50331684647145,0.5004931466840133,-0.13776538965897211
269.0000000000031,32.59856589312487,0.5027061161828331,-0.1446329998268494
270.0000000000031,32.69408174015034,0.5080321518587485,-0.15369182614191024
271.0000000000031,32.78863126103155,0.5114606592765403,-0.16146807682791264
272.0000000000032,32.88470093573334,0.5145966390095238,-0.16943994969176357
273.0000000000032,32.98088939069458,0.5184669539818975,-0.17791726057296575
274.0000000000032,33.074179787136906,0.5221542359455774,-0.18620143720951177
275.0000000000032,33.1681399757253,0.5233506976824118,-0.19487452370802627
276.0000000000032,33.264775495794424,0.5275014206822656,-0.20540553331385647
277.00000000000324,33.36134406312722,0.528486977453363,-0.21545935018726148
278.00000000000324,33.45628533427406,0.5304946521080944,-0.2248010611711848
279.00000000000324,33.551134242879655,0.5350550520400148,-0.23461646889625287
280.0000000000033,33.646986380763295,0.5358709039223027,-0.24528979069023116
281.0000000000033,33.742203742888336,0.5354389481231463,-0.25808029407570965
282.0000000000033,33.83764008925031,0.5364349359778615,-0.2691254800593659
283.0000000000033,33.93286757677117,0.5348464828970306,-0.280255467291445
284.0000000000033,34.02861157212558,0.5345451213861945,-0.2921840662210391
285.00000000000335,34.12171649625571,0.532287967534758,-0.3039823057364903
286.00000000000335,34.21771070832818,0.5308673432274914,-0.3165960911978547
287.00000000000335,34.31547961067885,0.5270530781376732,-0.3313913080819919
288.0000000000034,34.41126282158895,0.5271434927341281,-0.345334960737548
289.0000000000034,34.50671848148757,0.5233320067967338,-0.3600471249318318
290.0000000000034,34.6021444637105,0.517178114664498,-0.3758976537223262
291.0000000000034,34.69792698849561,0.5142662890610731,-0.3939378064407282
292.0000000000034,34.79337327506687,0.51138297221066,-0.4116482575432836
293.00000000000347,34.88917000000032,0.511790975132121,-0.4300298100000717
294.00000000000347,34.98483511597122,0.5094027952326277,-0.4498415054348075
295.00000000000347,35.08123326814586,0.5069328979782144,-0.47058896862425703
296.0000000000035,35.17659925472236,0.4997541667031944,-0.49063988326556895
297.0000000000035,35.27209595487333,0.4913347661599683,-0.5109459781938179
298.0000000000035,35.367991114139755,0.48212517812288574,-0.5326808954867355
299.0000000000035,35.46313629656888,0.47212916150248696,-0.5556934470045123
300.0000000000035,35.55917000000035,0.4632167948001303,-0.5772461477507767
301.0000000000036,35.654569460711606,0.45939986148135403,-0.5988983962006058
302.0000000000036,35.75107679370826,0.4627723133579882,-0.6238323623480215
303.0000000000036,35.847698982946476,0.4686748679555688,-0.6464447470563415
304.00000000000364,35.943106832811466,0.4796543919401778,-0.6664150939004929
305.00000000000364,36.03813866330557,0.493606837962252,-0.6893109052268653
306.00000000000364,36.1338651464887,0.5059730351476751,-0.7113932568245689
307.00000000000364,36.230034497749756,0.5190462425276283,-0.7347838478334081
308.00000000000364,36.3265128007875,0.5314555682802238,-0.7599010562345301
309.0000000000037,36.4217209109781,0.5401350292123275,-0.7823804281108857
310.0000000000037,36.51886223881209,0.5505561448022671,-0.8070582031101958
311.0000000000037,36.61430435989455,0.5578416636972687,-0.8300583430516406
312.00000000000375,36.71063017929105,0.5631586452181883,-0.8541429100706583
313.00000000000375,36.80552051050348,0.570195497314928,-0.8797618621198464
314.00000000000375,36.90201246903539,0.5716905431340079,-0.9023302048394806
315.00000000000375,36.99799723186242,0.5718017862720742,-0.9261523275138703
316.00000000000375,37.09371253875698,0.57238641763497,-0.9502622977187869
317.0000000000038,37.189476843325984,0.5701591480630832,-0.9741931304787683
318.0000000000038,37.28649262667149,0.5631912445342437,-0.9978238156325108
319.0000000000038,37.38247608759883,0.5591753133021011,-1.0192812918871272
320.00000000000387,37.47739759674996,0.5517636805549447,-1.0438659584113363
321.00000000000387,37.57405011750546,0.5460483116061847,-1.0654172271000757
322.00000000000387,37.67094358809524,0.5368545771452506,-1.0853619884319916
323.00000000000387,37.7660256415837,0.5280746501299782,-1.1039089866625034
324.00000000000387,37.86329235891675,0.5160564680727538,-1.1238572288630593
325.0000000000039,37.9582211737043,0.5068864230346857,-1.1418577678525708
326.0000000000039,38.055011134215654,0.4935511622039973,-1.1606290391511047
327.0000000000039,38.15156190595429,0.4822564051123853,-1.1761678917618061
328.000000000004,38.24741165087867,0.47055065362805526,-1.192442279788569
329.000000000004,38.343207898102634,0.4596279648332233,-1.206906652169463
330.000000000004,38.43854800769598,0.44856073504678334,-1.2210255037867683
331.000000000004,38.53563446657432,0.4361322687110288,-1.233427051266704
332.000000000004,38.63050651971399,0.42583969420002665,-1.2460632139728771
333.00000000000404,38.72639673805226,0.41623027156578385,-1.2562753233224835
334.00000000000404,38.823756182550376,0.40720519985492093,-1.2671009792326027
335.00000000000404,38.91917000000042,0.39536699974840706,-1.276569948000049
336.0000000000041,39.015801436836426,0.3857774394982753,-1.2863346663149358
337.0000000000041,39.112533112893715,0.3737488269377168,-1.2946113426115775
338.0000000000041,39.20906925299374,0.3660418681017144,-1.3030224678335052
339.0000000000041,39.304847103887134,0.3585054613999215,-1.30998649775621
340.0000000000041,39.40181403360414,0.3473012402986307,-1.3157652832320101
341.00000000000415,39.49749235019713,0.3431526201092434,-1.3246150720572736
342.00000000000415,39.592965821733344,0.3325648733558305,-1.330233732894059
343.00000000000415,39.68945189044017,0.3281512724352451,-1.3353146297754876
344.0000000000042,39.78571567238393,0.31825964668783757,-1.3414077461215879
345.0000000000042,39.882627807719885,0.3130201118421534,-1.3450349691569587
346.0000000000042,39.97837371442649,0.30265030557132894,-1.349220933726512
347.0000000000042,40.07406734794383,0.2984006446111195,-1.3548976620496322
348.0000000000042,40.17133509013728,0.2924934608544383,-1.3583261763283447
349.00000000000426,40.267586774708555,0.28668115853721626,-1.3627990567890294
350.00000000000426,40.36349040545101,0.28284836602816804,-1.3673173578637923
351.00000000000426,40.45994978304536,0.2756692241443671,-1.3707053443631345
352.0000000000043,40.556686769665454,0.27281324880764407,-1.3737608303023277
353.0000000000043,40.65093590949314,0.26775861882685625,-1.3764002373482929
354.0000000000043,40.74769492161995,0.2632328936326841,-1.3791139725264516
355.0000000000043,40.8458220440827,0.25913654417279575,-1.3804520245077185
356.0000000000043,40.94172413835488,0.25539291039810813,-1.381737152268777
357.0000000000044,41.03945428198181,0.25399356436742254,-1.384491268649335
358.0000000000044,41.135395177573464,0.24906932913088414,-1.3871578135384621
359.0000000000044,41.23311620028683,0.24603399527626563,-1.3894605829562043
360.00000000000443,41.328711561505074,0.24428621463720956,-1.3916705454897325
361.00000000000443,41.42480411452943,0.2454402248765299,-1.3938264029590917
362.00000000000443,41.52154454219719,0.24236430856578967,-1.3951355311501765
363.00000000000443,41.61882741921266,0.24068863857887696,-1.3957591181566724
364.00000000000443,41.7157442973996,0.2381264819080851,-1.3977690014870632
365.0000000000045,41.81236716016701,0.2378336051424979,-1.3978113216378394
366.0000000000045,41.90996225198709,0.2384685412367537,-1.4003998808606553
367.0000000000045,42.00629124206684,0.23777234292834404,-1.401777826557589
368.00000000000455,42.10314185913616,0.23811773387826796,-1.4007625732177242
369.00000000000455,42.200982997345754,0.23870708987749634,-1.4020501648004902
370.00000000000455,42.297751864848706,0.23889586571765264,-1.4033720602962538
371.00000000000455,42.394570125028785,0.23703794213798213,-1.403369566419459
372.00000000000455,42.491107691027636,0.2395729244784356,-1.4059884975532282
373.0000000000046,42.58888231089637,0.23949542613594,-1.4073103016065542
374.0000000000046,42.6852695220941,0.24008240669725478,-1.408635207944537
375.0000000000046,42.781960977330414,0.24057301803839404,-1.4086300446310673
376.00000000000466,42.87992821078284,0.24018490291826627,-1.4099395835876098
377.00000000000466,42.976917969345905,0.23984888252303965,-1.4099730101661567
378.00000000000466,43.073315987833496,0.23908932325630244,-1.4118844954217593
379.00000000000466,43.170239502159504,0.24115692128870558,-1.411601610594483
380.00000000000466,43.26798375868651,0.24299363282654218,-1.412919754154959
381.0000000000047,43.3637515928727,0.24068528001502487,-1.4129199259100402
382.0000000000047,43.461347112051044,0.24138757144164846,-1.4128980081111484
383.0000000000047,43.5555739511504,0.24200092939715406,-1.414209463612738
384.0000000000048,43.65497854563628,0.24029571780598646,-1.4152199109007153
385.0000000000048,43.752627726605176,0.23854864590974967,-1.4151993290626925
386.0000000000048,43.849535621165465,0.23811664194461524,-1.4165421446090343
387.0000000000048,43.946337404488176,0.2373019884120381,-1.416560396497423
388.0000000000048,44.043297386970664,0.23751918100731317,-1.4178598104666018
389.00000000000483,44.14061432925947,0.23559526189300778,-1.4166580810004699
390.00000000000483,44.23840902232512,0.23526185109064351,-1.419235717803356
391.00000000000483,44.33578335448148,0.23544413109449513,-1.4204927600484534
392.0000000000049,44.43342956208903,0.2338286514280648,-1.4195281189131066
393.0000000000049,44.530012131460765,0.23393354998188381,-1.4208964395727333
394.0000000000049,44.62643850253568,0.23076113514716456,-1.422470065992338
395.0000000000049,44.72467463561925,0.2324138379637799,-1.4224702336773531
396.0000000000049,44.8216611693702,0.23184717045525932,-1.4237804263689897
397.00000000000495,44.91917000000046,0.2297194290406107,-1.4231199054891244
398.00000000000495,45.01712554847225,0.22903764733137066,-1.4255990982594549
399.00000000000495,45.11375640447758,0.22917666686142724,-1.4257592064860742
400.000000000005,45.210966816838095,0.2289752690958285,-1.4270796184142558
401.000000000005,45.30907836277002,0.22705147995310238,-1.4277293915424356
402.000000000005,45.40584891711598,0.2267036602555535,-1.4291019858238405
403.000000000005,45.504199886513064,0.2251835237632131,-1.4316681871865145
404.000000000005,45.600589090357715,0.22245141839317695,-1.4316898770032238
405.00000000000506,45.698683124964795,0.2230658265586209,-1.4316868385209665
406.00000000000506,45.79619427838378,0.2187879403624634,-1.4343478884019834
407.00000000000506,45.89465003318029,0.2178724162908821,-1.4348779768484734
408.0000000000051,45.99214906231326,0.2172589225085435,-1.435973741470014
409.0000000000051,46.089784096930096,0.21612020282245248,-1.4372897021254145
410.0000000000051,46.187777968226634,0.2159394245504448,-1.4386009722377806
411.0000000000051,46.28519898761387,0.2169005887966447,-1.439959156742887
412.0000000000051,46.382677536116425,0.2171211820099444,-1.4412389561862633
413.0000000000052,46.481159248610254,0.2156074516135113,-1.4439243092374525
414.0000000000052,46.57791675328358,0.21572819456538334,-1.4451869881541084
415.0000000000052,46.67565392558415,0.21361927348828857,-1.4464083957082972
416.00000000000523,46.77373053298722,0.21466734557419415,-1.4478213955082233
417.00000000000523,46.871823671009935,0.21266401021118453,-1.4492549247391522
418.00000000000523,46.969374938322986,0.21438246575832043,-1.4517782460922684
419.00000000000523,47.067862361579984,0.21315632507515048,-1.4543407029113444
420.00000000000523,47.16548620797205,0.21154450936969044,-1.4551903120916245
421.0000000000053,47.26305976043168,0.2114008137465634,-1.457905159822905
422.0000000000053,47.36124645979388,0.21195728475883496,-1.4604439932711348
423.0000000000053,47.45827814490103,0.21345729398318747,-1.4618221869544903
424.00000000000534,47.5565210127286,0.2140273843205971,-1.4644886399982648
425.00000000000534,47.65357705736326,0.21573797615451185,-1.4671688936922638
426.00000000000534,47.75125433780561,0.21535010130736837,-1.47120769824841
427.00000000000534,47.84886378583308,0.21447539748888994,-1.472283510100307
428.00000000000534,47.947395216908426,0.21824032728585535,-1.475488821327858
429.0000000000054,48.044059014259794,0.21903721768587575,-1.4792060650809695
430.0000000000054,48.141820339995164,0.22287786289902595,-1.480884921217755
431.0000000000054,48.23856080929252,0.2247698490614966,-1.4850210047055978
432.00000000000546,48.33869271681393,0.2292811869812818,-1.4890943616472767
433.00000000000546,48.43531181475098,0.23005735199054866,-1.4939094024575073
434.00000000000546,48.534419761006546,0.23482095941157188,-1.5004606857756824
435.00000000000546,48.63133601671076,0.23739396492907472,-1.5017310288153238
436.00000000000546,48.72977127368886,0.24014241308780973,-1.5045771035766324
437.0000000000055,48.82707406533527,0.24420891723348012,-1.5101058588705363
438.0000000000055,48.926203363747426,0.24672654779487485,-1.5151204972049568
439.0000000000055,49.02432852043177,0.25047562943366275,-1.518902690824306
440.00000000000557,49.1221237163812,0.2569716603117618,-1.523596789812049
441.00000000000557,49.21956894444937,0.2599185773525212,-1.5278529341460705
442.00000000000557,49.318224086485486,0.26541226669135176,-1.5342588171933724
443.00000000000557,49.41547084518918,0.26987935984808886,-1.540965786600395
444.00000000000557,49.51370543498806,0.2789398533261843,-1.5462216272938036
445.0000000000056,49.61320458509408,0.28280019536210393,-1.555067190138582
446.0000000000056,49.71134026775856,0.29092235134776534,-1.563751747051155
447.0000000000056,49.808268029826735,0.29749863174235885,-1.5717733952139414
448.0000000000057,49.9070364894563,0.3036892720264237,-1.5784836373908324
449.0000000000057,50.00586709540296,0.3124137963105915,-1.5798922787492744
450.0000000000057,50.10365417381146,0.31907725603870746,-1.5864973080977869
451.0000000000057,50.2025177144464,0.32738898836579566,-1.5949381971885934
452.0000000000057,50.30081871178666,0.33396546495214274,-1.6002942247881133
453.00000000000574,50.39864338307186,0.3452684179520402,-1.6061958911354641
454.00000000000574,50.497523929565176,0.35455013034199245,-1.6206968784367652
455.00000000000574,50.594965998213475,0.36462819537563373,-1.6338827907274474
456.0000000000058,50.69315820176152,0.37420638467321143,-1.6464384680544026
457.0000000000058,50.79142993929217,0.382612811148511,-1.6591875461997962
458.0000000000058,50.889271143465734,0.3929294073475742,-1.6718974895850858
459.0000000000058,50.988465438467415,0.40416928603583785,-1.6833525163086125
460.0000000000058,51.08713694182896,0.41385358820188367,-1.6957712526129067
461.00000000000585,51.18505137204027,0.4237506696730456,-1.7097836178209391
462.00000000000585,51.283098705471595,0.4335472542808322,-1.7257380846732784
463.00000000000585,51.38145587409133,0.4471120651572859,-1.7390944253185774
464.0000000000059,51.47974313764014,0.4606902298008014,-1.7557781723368868
465.0000000000059,51.57854785143052,0.46981947522504186,-1.7731021367199458
466.0000000000059,51.67655660100958,0.4833056372397036,-1.788959100913797
467.0000000000059,51.77535814546574,0.494135330727751,-1.8080850119394518
468.0000000000059,51.87387480049962,0.5093817866697353,-1.8287540464827154
469.00000000000597,51.97238157158271,0.5221212398242998,-1.8496492271430274
470.00000000000597,52.07175311923823,0.536457268799462,-1.8715280910836527
471.00000000000597,52.169780061310306,0.5513495423407682,-1.8946897242297993
472.000000000006,52.26841948142943,0.5631416833821972,-1.920161047313846
473.000000000006,52.36700262135484,0.5783601266818599,-1.94445483530775
474.000000000006,52.466006656101975,0.5930078896276886,-1.9728923381925814
475.000000000006,52.563386004332955,0.6044087128021627,-1.999707413218177
476.000000000006,52.66229558692391,0.6185571873609479,-2.030746404178735
477.0000000000061,52.761011766287965,0.633055587423968,-2.0618277699218357
478.0000000000061,52.86032272529356,0.6454632398120566,-2.095876977802096
479.0000000000061,52.958978792256076,0.6560964633833822,-2.1287540930290754
480.00000000000614,53.056710987729595,0.6651419447410211,-2.1645709864474423
481.00000000000614,53.15601030911968,0.6775002008310977,-2.202260252304691
482.00000000000614,53.25370852392653,0.6836823532868486,-2.239526231504653
483.00000000000614,53.35266290966257,0.686205790804508,-2.2793771386776487
484.00000000000614,53.45240447776281,0.6933177839436305,-2.3191492951068033
485.0000000000062,53.54917000000058,0.6918702770126,-2.3614490043899874
486.0000000000062,53.64898279579573,0.6878530304766225,-2.4032991378087094
487.0000000000062,53.74721772419214,0.6829612659910274,-2.4455390777551775
488.00000000000625,53.846848156315296,0.671424443472418,-2.4881565194700634
489.00000000000625,53.945879741892355,0.6573770979513596,-2.5317753884667975
490.00000000000625,54.04439874221794,0.6381916597522133,-2.5722794355380754
491.00000000000625,54.14210304835887,0.6187451802909965,-2.614188861113159
492.00000000000625,54.24156374468744,0.5932646484805587,-2.653659949121339
493.0000000000063,54.34000296054204,0.5596022231263647,-2.691173605094679
494.0000000000063,54.4380563920545,0.5288160243653987,-2.72815544710281
495.0000000000063,54.53701085763032,0.4953583052884295,-2.7630549960118413
496.00000000000637,54.63497822600394,0.46090770733601505,-2.7964439364206646
497.00000000000637,54.7334693147601,0.42732696055595143,-2.8262601057009515
498.00000000000637,54.83269948437386,0.392482128134715,-2.857214869370181
499.00000000000637,54.930937975938335,0.3554034088276723,-2.880327059249333
500.00000000000637,55.03025762124446,0.31756856206022255,-2.902421494893262
501.0000000000064,55.12827687003711,0.27672462104930495,-2.9202118719076138
502.0000000000064,55.22697689368188,0.24150566135018664,-2.9372125249608345
503.0000000000064,55.32453661558436,0.20952911322163484,-2.950224244974589
504.0000000000065,55.424527605452234,0.1789368779171586,-2.96158726921127
505.0000000000065,55.5228198839142,0.15758622091007998,-2.9700810221951484
506.0000000000065,55.62209688576258,0.13541426899986578,-2.9766937313339272
507.0000000000065,55.7200422818008,0.12103513820620918,-2.9802207453095395
508.0000000000065,55.819367856108826,0.11319067841743918,-2.985701512085145
509.00000000000654,55.91792981216874,0.10653329870697703,-2.9873151003755622
510.00000000000654,56.01690298771008,0.09997851313758926,-2.9904609872017147
511.00000000000654,56.11529632376593,0.09774443574636649,-2.9927935763294875
512.0000000000066,56.21360043519683,0.09788894498589631,-2.994539502206286
513.0000000000066,56.312042467012425,0.09614679006472654,-2.9957734222710313
514.0000000000066,56.41040296960657,0.0996715285763266,-2.9970894312619825
515.0000000000066,56.510779836599944,0.10191596669234435,-2.999514776135036
516.0000000000066,56.60837031193662,0.10752303718756323,-2.999724506091294
517.0000000000066,56.70740330114064,0.11070532567519997,-3.0009654934656864
518.0000000000066,56.806063283465924,0.11601445107394501,-3.0010196424425657
519.0000000000066,56.905468097720046,0.11726991616309068,-3.004995053024918
520.0000000000067,57.00381628528521,0.12122083399779479,-3.0049895038025376
521.0000000000067,57.101205537515135,0.12497368038314549,-3.006318587478362
522.0000000000067,57.203182590776464,0.1338201338563593,-3.0063101576184694
523.0000000000067,57.30135893688061,0.1408332947233397,-3.007630830880829
524.0000000000067,57.39936380943607,0.14462348475786216,-3.0089515580088877
525.0000000000068,57.49907079589706,0.14876358662648873,-3.01125068995351
526.0000000000068,57.598529182927315,0.1519100254433284,-3.0112537038112
527.0000000000068,57.697734528296316,0.1542302657850827,-3.012892261313712
528.0000000000068,57.79599288929761,0.15750606469411121,-3.0142101073815395
529.0000000000068,57.89494587863855,0.15923592347046134,-3.014520031856512
530.0000000000068,57.994714595661485,0.15996029882450297,-3.015858283619919
531.0000000000068,58.09428375978169,0.16168336662681249,-3.016522546364354
532.0000000000068,58.19327130062106,0.16559943591530352,-3.016615761073442
533.0000000000068,58.293474514218644,0.16780267931094633,-3.0186557601098385
534.0000000000068,58.39237323039178,0.1680720186525388,-3.0181893511237767
535.0000000000068,58.49181054177541,0.16962161380604707,-3.018502039538528
536.0000000000069,58.591672123381336,0.17427547934916748,-3.0199187620469363
537.0000000000069,58.69157920047732,0.16886748761226972,-3.0211275329364495
538.0000000000069,58.79007421825009,0.17377478389307544,-3.021129956760869
539.0000000000069,58.88948293591477,0.1707775614602343,-3.02244987263959
540.0000000000069,58.99017196159908,0.16903144318642532,-3.0237697468991875
541.000000000007,59.089656079766584,0.16513770651611703,-3.0250902007784863
542.000000000007,59.18845387209591,0.16144398964424972,-3.02637582914002
543.000000000007,59.2883859362092,0.15835385025229654,-3.0260700359953896
544.000000000007,59.387319358312446,0.15390348388857955,-3.0265691157556045
545.000000000007,59.487568115005246,0.15218523897616593,-3.0260697697251633
546.000000000007,59.586912909396304,0.14818638421240415,-3.027390047556889
547.000000000007,59.68604164531399,0.1454476089515619,-3.0287102948626847
548.000000000007,59.78522186007591,0.14527902968071144,-3.0300199304335176
549.000000000007,59.88540493811193,0.14400755902792156,-3.0313353346139897
550.000000000007,59.98485804153298,0.1431316713999397,-3.032682081868878
551.000000000007,60.08479533850882,0.14487785512219392,-3.0326620809873996
552.0000000000072,60.183760813051926,0.14760962600405927,-3.0326795702227134
553.0000000000072,60.28327942875813,0.15010643825815118,-3.0343342591078803
554.0000000000072,60.38385160554861,0.1521141445934361,-3.0352909146749774
555.0000000000072,60.48316580401672,0.15742701420069855,-3.0366101962746654
556.0000000000072,60.58175822221126,0.15942667455884652,-3.036835084838102
557.0000000000073,60.68197885785732,0.16771656282697178,-3.037927599950856
558.0000000000073,60.783545438181804,0.17138342441629684,-3.0391743094977874
559.0000000000073,60.88216062910385,0.17628960733033738,-3.0406398683275193
560.0000000000073,60.98245016052418,0.1843922805564516,-3.042865460055835
561.0000000000073,61.08185103864882,0.1906793268754663,-3.043985475957217
562.0000000000073,61.181759024825915,0.20065107079194638,-3.0441437603499755
563.0000000000073,61.281384165812476,0.2110315335200021,-3.0467939054072897
564.0000000000073,61.3786992003959,0.2210321183573812,-3.0481400274277046
565.0000000000073,61.48085247261444,0.23133717246892155,-3.04941840731511
566.0000000000073,61.58085896948612,0.24418554354123537,-3.049503956029632
567.0000000000074,61.68125805422125,0.2551582094903597,-3.052069401340197
568.0000000000074,61.780641716334436,0.26960631152424497,-3.0551821586838925
569.0000000000074,61.87730241857591,0.2757437797819511,-3.057366012759251
570.0000000000074,61.97970179196452,0.2875486617383619,-3.0577416835698172
571.0000000000074,62.080686531205885,0.2955310220611893,-3.0599739823074805
572.0000000000074,62.180632905727464,0.30275679643706443,-3.0613147888298204
573.0000000000074,62.27979077046245,0.3071313861584525,-3.063939405679967
574.0000000000075,62.37958533785161,0.3057868572592596,-3.065261763352379
575.0000000000075,62.47855547410356,0.3049967997948038,-3.0678913881755943
576.0000000000075,62.57896750054924,0.29491635499244795,-3.0692093288984816
577.0000000000075,62.67833016903483,0.2773910561237056,-3.071797706754342
578.0000000000075,62.77817802921064,0.25762154454755926,-3.07316062804387
579.0000000000075,62.87724787258942,0.2350501367795167,-3.074669370483558
580.0000000000075,62.977022239730324,0.21802847118147933,-3.0765710283385292
581.0000000000075,63.077169885680455,0.20675282522912147,-3.0773095743058905
582.0000000000075,63.176088440636555,0.19960121359442043,-3.0784223445023384
583.0000000000076,63.27611810059303,0.194214582196361,-3.0797534831156046
584.0000000000076,63.37446732200999,0.19072612716539722,-3.080415813330635
585.0000000000076,63.47558961843563,0.18818660198744902,-3.080521368444754
586.0000000000076,63.57519893424217,0.1868289671009136,-3.0811728421662083
587.0000000000076,63.675227946446824,0.1881755100293368,-3.0810769224703836
588.0000000000076,63.77468556275119,0.18833581684966655,-3.082390183458425
589.0000000000076,63.87388917157154,0.18905505197514927,-3.0823916242487597
590.0000000000077,63.97418012635992,0.18945691479386792,-3.0837101305186945
591.0000000000077,64.07349442711636,0.19121268497858784,-3.083709980926546
592.0000000000077,64.17404894202052,0.19376746531973196,-3.0843694321680397
593.0000000000077,64.2742576053602,0.1936758566975081,-3.085031737679883
594.0000000000077,64.37371981052425,0.19502229832400544,-3.086334627931301
595.0000000000077,64.47410214302136,0.19733096898656233,-3.086792025560089
596.0000000000077,64.57438744015899,0.19667033158341335,-3.086345063796765
597.0000000000077,64.67521460111543,0.20269062280728897,-3.0860006807164506
598.0000000000077,64.77568428526344,0.20631442053428506,-3.087328165069761
599.0000000000078,64.8756280680405,0.20608968103796643,-3.0880070994354147
600.0000000000078,64.97443679358074,0.20766049657098845,-3.0886501278878975
601.0000000000078,65.07506007291553,0.2141141628235898,-3.0885000976113286
602.0000000000078,65.1753147815531,0.21610498029883485,-3.0896423474233443
603.0000000000078,65.27529619678067,0.22189012197894287,-3.0896548272527085
604.0000000000078,65.3758246776485,0.22581491781455032,-3.089601414814188
605.0000000000078,65.4756589117636,0.230556310793857,-3.0916118222184372
606.000000000008,65.57585273589112,0.23692295430922122,-3.0915594806691162
607.000000000008,65.67571399023079,0.24363010389028372,-3.0929260022728102
608.000000000008,65.77470538906067,0.2493811545874362,-3.0942515783096463
609.000000000008,65.87531556233961,0.2544426949934343,-3.093590045010874
610.000000000008,65.9757398352892,0.2640025880574178,-3.096218889653263
611.000000000008,66.07624625072685,0.2680042640074488,-3.096219462843005
612.000000000008,66.17700328968068,0.273346108728005,-3.0965499421751983
613.000000000008,66.27647654568574,0.27866085746114094,-3.097868863868109
614.000000000008,66.37682392156638,0.28567131643190596,-3.09787104537752
615.0000000000081,66.47800573642893,0.2888957054450908,-3.0997394529606277
616.0000000000081,66.57804138727532,0.2968138309430529,-3.100499958945783
617.0000000000081,66.67818795556434,0.29942322171774793,-3.1018155240734986
618.0000000000081,66.77786037966486,0.3045536376382636,-3.1028138775114917
619.0000000000081,66.87888660764357,0.30983227412794506,-3.102799352955704
620.0000000000081,66.97864606115562,0.311977481186015,-3.1034599050194154
621.0000000000081,67.0790742927131,0.3172774420669988,-3.1034176278746006
622.0000000000082,67.17937592844244,0.3209862827870138,-3.105499943393374
623.0000000000082,67.27917000000082,0.3273799551152089,-3.106760060067005
624.0000000000082,67.37956312163999,0.32749838696719363,-3.1080737075968097
625.0000000000082,67.4799288359187,0.33394435010437146,-3.109791242177109
626.0000000000082,67.58007009986719,0.33850495591555324,-3.1093898174485357
627.0000000000082,67.67975179318675,0.3433897293789555,-3.1107102223222087
628.0000000000082,67.78090460723246,0.34749185714472686,-3.1120297629340645
629.0000000000082,67.8818234598919,0.35365861060451803,-3.1133394648656596
630.0000000000082,67.98043110134438,0.35984366170473797,-3.1133536747389425
631.0000000000083,68.07897514862506,0.3657502769070245,-3.1133495847387866
632.0000000000083,68.1811686458017,0.37391763677855555,-3.1161248845489915
633.0000000000083,68.28111161551324,0.3783514909901005,-3.1173176951150983
634.0000000000083,68.38227879369079,0.3885827028610985,-3.118488547925386
635.0000000000083,68.4824594601092,0.39696024687028697,-3.121420138585198
636.0000000000083,68.58300102348984,0.4056114139214489,-3.122610654006941
637.0000000000083,68.68385487601417,0.41398742227782664,-3.122679499179144
638.0000000000084,68.78335012902369,0.4245174181584284,-3.123997888986175
639.0000000000084,68.88334998258135,0.4335356901732136,-3.1247492225477154
640.0000000000084,68.98430991536928,0.44386959406701265,-3.1284818864820316
641.0000000000084,69.08436465648217,0.4563712633156434,-3.1298314814426433
642.0000000000084,69.18487397844373,0.46422908500914195,-3.1311482982265284
643.0000000000084,69.28482844934928,0.4737967217422258,-3.131856664924589
644.0000000000084,69.3853536990775,0.48464098656791316,-3.1331734965269686
645.0000000000084,69.48590096460103,0.492741674034329,-3.1364206678697557
646.0000000000084,69.58593059696764,0.5061448706016264,-3.1378298540695595
647.0000000000085,69.68661087787983,0.5173769659407914,-3.140469114855456
648.0000000000085,69.78744993852625,0.5296534037867263,-3.1431103494204917
649.0000000000085,69.88738877155458,0.5378508736583745,-3.145664802572034
650.0000000000085,69.9882302306427,0.5437916191078583,-3.147079655263239