File: 01_Data/Bamboo_Rug_Fabric/STA/N2/10K_min/Bamboo_Rug_Fabric_STA_N2_10KData_220125_R3.csv
##Temp./Â°C,Time/min,DSC/(mW/mg),Mass loss/mg
50.0,10.76947674165057,0.06480427221041618,-0.0072003895219001635
51.20000000000002,11.082610925913963,0.10096118580609614,-0.008012645870222102
52.400000000000034,11.302359538058782,0.12946216903845387,-0.007687460762468845
53.60000000000005,11.487011319079489,0.14981292697085724,-0.007828765902022639
54.80000000000007,11.654757488616278,0.16819060640383987,-0.00825970270904719
56.000000000000085,11.809430066221754,0.18063282459859775,-0.008076388009827795
57.2000000000001,11.956933612120752,0.1921858244451793,-0.007942349484902245
58.40000000000012,12.098627681959846,0.2009613112821158,-0.007692420824226609
59.600000000000136,12.232880223886452,0.21094976391252862,-0.008457568920652747
60.80000000000015,12.375036835604,0.21919379523782578,-0.008436828805080232
62.00000000000017,12.509271329454958,0.22369548669786632,-0.00906565259402825
63.20000000000019,12.641971978114961,0.22953583635220154,-0.008243000496874764
64.4000000000002,12.773985468945193,0.23534034266958015,-0.007899759751403224
65.60000000000022,12.905621136380367,0.23729139511102781,-0.006797090414031537
66.80000000000024,13.035491251950631,0.24270945221195828,-0.009434471514927267
68.00000000000026,13.164042471338051,0.24369018861261627,-0.01080075578062445
69.20000000000027,13.29368512486556,0.24796483187035906,-0.009429649328457579
70.40000000000029,13.422488090787551,0.24811820440840782,-0.010057656540693571
71.6000000000003,13.550268533224342,0.24699722658412598,-0.0120701412545694
72.80000000000032,13.677871645068617,0.2510867724491152,-0.010210493675154808
74.00000000000034,13.805003809176295,0.2500362085191369,-0.010770330678130158
75.20000000000036,13.930335706153016,0.252464690649545,-0.00922069836482109
76.40000000000038,14.056516258354076,0.25501859391088166,-0.011851269392583852
77.60000000000039,14.181555034460908,0.25653599639764213,-0.013160298075698407
78.80000000000041,14.306244065374727,0.25556263541965735,-0.013252580978294404
80.00000000000043,14.430184896990458,0.25926015917031925,-0.012950094293275427
81.20000000000044,14.553718491213246,0.25992197497671626,-0.013611160282064105
82.40000000000046,14.677192848827984,0.2609635842789536,-0.014918892632740821
83.60000000000048,14.800920098780932,0.2614066098286169,-0.014920698633108742
84.8000000000005,14.922694626521897,0.2620730207099792,-0.014920564882321408
86.00000000000051,15.044608188446766,0.26104088113407586,-0.014970460886019055
87.20000000000053,15.16597396376421,0.26380082369642405,-0.016369556529711282
88.40000000000055,15.287823159080439,0.26298372321176977,-0.020308980275473232
89.60000000000056,15.408789053579579,0.2648225728459422,-0.019871415639399537
90.80000000000058,15.528714008066117,0.2609802651368545,-0.018549702191453576
92.0000000000006,15.648478354708717,0.26196472717308544,-0.01723144151565492
93.20000000000061,15.768084497566893,0.2617676477092922,-0.017227866535077574
94.40000000000063,15.88743235702572,0.2609652720275121,-0.017219537462725754
95.60000000000065,16.006364187065934,0.26090110670085576,-0.015568597599698641
96.80000000000067,16.12519925180124,0.25997696110489615,-0.017902048233457535
98.00000000000068,16.24565349681525,0.26142558849758485,-0.01680369214207289
99.2000000000007,16.36270939442547,0.25909191167431206,-0.018111924162110604
100.40000000000072,16.481599935686255,0.25895143223881417,-0.01645566297836787
101.60000000000073,16.601102795963502,0.25917576884226,-0.01779118833098714
102.80000000000075,16.71834378375128,0.2596346399695588,-0.01777024216452272
104.00000000000077,16.83744878119633,0.26005387372539535,-0.01851915701871043
105.20000000000078,16.954582319232127,0.25926604948523446,-0.01876240974284027
106.4000000000008,17.070979195965684,0.2629553854901421,-0.01908981690686673
107.60000000000082,17.18603439612436,0.26021207208267805,-0.019090283447654954
108.80000000000084,17.307359667829616,0.26120654275015054,-0.01776848374374751
110.00000000000085,17.42497922931382,0.2637020707441796,-0.019120828893647968
111.20000000000087,17.541596416867005,0.264699763896643,-0.019077311190296875
112.40000000000089,17.658990268596323,0.2658534690136066,-0.018769888944841995
113.6000000000009,17.775594332496787,0.26751455044364225,-0.01840120811513568
114.80000000000092,17.8934062279856,0.26680719046685664,-0.01777755806263137
116.00000000000094,18.010814302280533,0.26864425413573756,-0.019090051557569154
117.20000000000095,18.12787437917037,0.26941593095423605,-0.017889508085708883
118.40000000000097,18.24439334161783,0.27050504367256784,-0.019089823672969963
119.60000000000099,18.361114636005198,0.2723495082318993,-0.019089829310935613
120.800000000001,18.47782198138713,0.27219567224780544,-0.016962657644187473
122.00000000000102,18.59385418777747,0.2718455264821076,-0.017892542214801743
123.20000000000104,18.708388592019766,0.2728591190605575,-0.01870337799212418
124.40000000000106,18.825842757428987,0.2759436353507926,-0.017643285336949255
125.60000000000107,18.946236117387848,0.27541635473876136,-0.018377198718867227
126.80000000000109,19.061636721461774,0.2770844152585862,-0.017550019289238605
128.0000000000011,19.179065065779135,0.277811751131946,-0.01755021111700472
129.20000000000113,19.295683707575066,0.27864103006191604,-0.017004711447045295
130.40000000000114,19.412174850007393,0.2809730736277575,-0.0175546764145027
131.60000000000116,19.527881033098723,0.2790762473369881,-0.01624026707124937
132.80000000000118,19.645000168348147,0.2807053697549591,-0.016570080360692074
134.0000000000012,19.76079331177931,0.28208336980426674,-0.017549529127141028
135.2000000000012,19.877560001015613,0.283683748647133,-0.017559754696475416
136.40000000000123,19.993935601592828,0.2832174636568411,-0.017559448299325098
137.60000000000124,20.109168878202386,0.28418808656559646,-0.01887988964437337
138.80000000000126,20.227222157318135,0.2863628885047854,-0.018888796916741057
140.00000000000128,20.34235124306783,0.28562112962518055,-0.020187961028716117
141.2000000000013,20.458255738559405,0.28765333951952166,-0.020216716310126337
142.4000000000013,20.573818262450203,0.2883931523841888,-0.020520120225685723
143.60000000000133,20.68955841434279,0.2893843291743208,-0.021511983864328066
144.80000000000135,20.80665597817625,0.291954065038208,-0.02075132270844282
146.00000000000136,20.921834444756467,0.29192029573221395,-0.020520066529985392
147.20000000000138,21.038086908781576,0.29301936671285145,-0.02182992560155661
148.4000000000014,21.152320616809114,0.2971122874148442,-0.021829892000140738
149.60000000000142,21.267991936077514,0.29806187250331057,-0.021831028863094737
150.80000000000143,21.383212480473265,0.29996951942545647,-0.02314988783826255
152.00000000000145,21.499431184326554,0.3028048045733206,-0.023149891999998395
153.20000000000147,21.615271086581313,0.30354793829508,-0.023149892000000172
154.40000000000148,21.72973641739111,0.30564034649824295,-0.0231499017659198
155.6000000000015,21.84650338421338,0.30784307711117,-0.02446289724764572
156.80000000000152,21.961326062475646,0.3093603295607928,-0.024129834254014604
158.00000000000153,22.076546301806957,0.3130007476597144,-0.02412983500256427
159.20000000000155,22.19102918123379,0.3116347287559552,-0.025079589017986237
160.40000000000157,22.30726552377323,0.31481369611862964,-0.024153730754076896
161.6000000000016,22.4210366631274,0.3163965632480596,-0.025127233469106613
162.8000000000016,22.5368895608654,0.3166726932789951,-0.025460074305228453
164.00000000000162,22.651780285247003,0.3170719648099921,-0.026770726844695503
165.20000000000164,22.767526381754053,0.32078352983794445,-0.026770085013357203
166.40000000000165,22.881846926981048,0.32264118905280775,-0.02674659741520813
167.60000000000167,22.99711552021837,0.32330128085282633,-0.029052764052673652
168.8000000000017,23.113377497981656,0.32699004664676395,-0.029410485492953775
170.0000000000017,23.228261425179067,0.32553052079719674,-0.02842005700651562
171.20000000000172,23.343773496391577,0.32583665383960386,-0.029732239074183653
172.40000000000174,23.45943461401023,0.32885988588768256,-0.030413385945302185
173.60000000000176,23.573852030164996,0.33126464344184214,-0.029588803903211947
174.80000000000177,23.688986204030154,0.33266667279033135,-0.029734918715760728
176.0000000000018,23.803388645387262,0.33382765126744224,-0.03105008448053992
177.2000000000018,23.915697973523393,0.3352368816461764,-0.0323691433907749
178.40000000000182,24.034017511989386,0.33768808641471915,-0.031049915094512937
179.60000000000184,24.14833475069377,0.3346797466199883,-0.031050264996248522
180.80000000000186,24.263299576709557,0.33531270288117315,-0.03369062334897954
182.00000000000188,24.378291280042124,0.33835848045455985,-0.03236785125888897
183.2000000000019,24.493784001029354,0.33905198537282466,-0.0333500283418422
184.4000000000019,24.60907991731141,0.3409845541202081,-0.033350028000000975
185.60000000000193,24.723433993364424,0.34252509578764206,-0.03335002800009068
186.80000000000194,24.838050562882565,0.3442733376503345,-0.03334991846951629
188.00000000000196,24.952544369566418,0.3441987576656933,-0.03367818391279487
189.20000000000198,25.068345834661326,0.3433757415033234,-0.035000416032133774
190.400000000002,25.18298596601059,0.34439742705802945,-0.03531851973870026
191.600000000002,25.297648290959927,0.34888075052599543,-0.035999735580699355
192.80000000000203,25.412173786020944,0.34878683948469463,-0.03598018099613798
194.00000000000205,25.527586428328757,0.35203680942925597,-0.03598018134652703
195.20000000000206,25.641075533531144,0.35445646205033754,-0.036956676356945994
196.40000000000208,25.756790464423904,0.35640752045281016,-0.03828994516291573
197.6000000000021,25.870022128716826,0.3578510392112597,-0.039600101638666896
198.80000000000211,25.98380293838307,0.3555596760908964,-0.03961547328991699
200.00000000000213,26.0981134764766,0.3602431971483217,-0.04091988712425243
201.20000000000215,26.21290492264888,0.36151583919922814,-0.04091768991236666
202.40000000000217,26.326909728652968,0.361563418462602,-0.04297300833053708
203.60000000000218,26.440929198740644,0.36447624636387643,-0.04289005992406025
204.8000000000022,26.5552839484934,0.36531034123682216,-0.044678461103404565
206.00000000000222,26.668981160074367,0.36753176765078477,-0.04618625397270559
207.20000000000223,26.783540300510566,0.3678863966011512,-0.04619123852494589
208.40000000000225,26.898050040911276,0.36966266320874586,-0.04619903978010509
209.60000000000227,27.010445814236437,0.369338682872702,-0.0488340532501792
210.80000000000229,27.12476961123238,0.3730880638700919,-0.05012888354371814
212.0000000000023,27.239079999321774,0.37610586423279846,-0.050129843905104554
213.20000000000232,27.352177558137335,0.37439981814879014,-0.051448905297724945
214.40000000000234,27.467337057136405,0.37836139379829214,-0.05281638660849053
215.60000000000235,27.581421374157863,0.37982777944127,-0.05401859305199297
216.80000000000237,27.695137163395977,0.37956747016711023,-0.05634033278232575
218.0000000000024,27.810093428838286,0.38050594342746713,-0.056710046532610914
219.2000000000024,27.92414183952405,0.38491655233460237,-0.05803070378600017
220.40000000000242,28.03695358167966,0.38561731158321316,-0.05901181121783683
221.60000000000244,28.152003729893167,0.3876402101093619,-0.05963809213186044
222.80000000000246,28.266355357040574,0.3899121636520427,-0.0609898527135484
224.00000000000247,28.379444775460176,0.3905131049253659,-0.06264541069826102
225.2000000000025,28.494415515691244,0.3935991612176699,-0.06460873349053253
226.4000000000025,28.60880998275387,0.3942138204111209,-0.06592266414561543
227.60000000000252,28.72235606725626,0.3981619798373931,-0.06829422699942755
228.80000000000254,28.83570105641843,0.40292702563575516,-0.06733763182350261
230.00000000000256,28.950328672382614,0.40394868117646704,-0.07113205966150193
231.20000000000258,29.065216143311282,0.40240771189983215,-0.0728596377878521
232.4000000000026,29.17829410661041,0.4055852468534556,-0.07513641124918502
233.6000000000026,29.293067471623786,0.41013897087970336,-0.07643477103283702
234.80000000000263,29.407762286284257,0.4122616565911073,-0.07777736056374307
236.00000000000264,29.521361860470638,0.41713993807675825,-0.07909022667309262
237.20000000000266,29.63670928771539,0.42388162438678645,-0.08171919627120339
238.40000000000268,29.75091337076812,0.4278600168154902,-0.08302632337585791
239.6000000000027,29.864243081552043,0.4388919154872945,-0.08488293493424948
240.8000000000027,29.979440999040975,0.4512303679244889,-0.08697724709416477
242.00000000000273,30.093507198656695,0.46099227551913224,-0.08983920743733798
243.20000000000275,30.208441890538374,0.47276701525336134,-0.09222465974910765
244.40000000000276,30.323125136875106,0.49252773893569524,-0.09384514722384019
245.60000000000278,30.437907349402515,0.5124689862399577,-0.09630974790994884
246.8000000000028,30.551808997878975,0.5344369135446366,-0.10029774400313718
248.0000000000028,30.668186606760127,0.5642751040321782,-0.10295592381332908
249.20000000000283,30.781194639738764,0.6004152714813619,-0.10777123828860002
250.40000000000285,30.896046611665557,0.6370523827333963,-0.1110163887111506
251.60000000000286,31.011430560074295,0.6624475427094626,-0.11374999291919963
252.80000000000288,31.126729242488384,0.6636282212111854,-0.11771307441871315
254.0000000000029,31.241232448957046,0.638287231197337,-0.12055287552117111
255.20000000000292,31.35593419456373,0.5933921628424329,-0.12406857625995871
256.40000000000293,31.46917100940585,0.5480918110675637,-0.12745905910415845
257.600000000003,31.583846604576934,0.5034374090270503,-0.1328776289041853
258.80000000000297,31.69720471170098,0.473472503404598,-0.1372744781223072
260.00000000000296,31.81157599365395,0.4533601963508351,-0.14343068084288957
261.200000000003,31.925291483084724,0.4403953666724907,-0.14836948547555995
262.40000000000305,32.03960394869669,0.43687772025161525,-0.15326313341106967
263.60000000000304,32.152831872485336,0.4360756749378786,-0.1592187651977226
264.800000000003,32.268978015092614,0.4330937804427763,-0.16386328789385196
266.00000000000307,32.38226775455266,0.4346645895351566,-0.16959424628554087
267.2000000000031,32.495544802605984,0.43522866463549437,-0.17756180110219777
268.4000000000031,32.61073410445397,0.43729981684930863,-0.18339041777937037
269.6000000000031,32.72654569325313,0.4399488263312405,-0.19175669179651322
270.80000000000314,32.840916066465674,0.44065003251690515,-0.1989607426810185
272.0000000000032,32.955484884819896,0.4449740872569225,-0.20688829104238904
273.2000000000032,33.071151158925126,0.4452805350490952,-0.21605345230470396
274.40000000000316,33.18560035088575,0.44525500436665855,-0.2233374737433209
275.6000000000032,33.30108144351791,0.44802064894317944,-0.23262372558454203
276.80000000000325,33.41576757044274,0.44793008183537747,-0.24110083365558266
278.00000000000324,33.5302726991398,0.4529707257413403,-0.2511360564534555
279.20000000000323,33.64563562329476,0.4551027490902082,-0.2597450709813831
280.4000000000033,33.759981422713,0.4534823242330687,-0.2728519457156553
281.6000000000033,33.87655846707635,0.45462525750491484,-0.2829089623035963
282.8000000000033,33.989396908785466,0.45711299213022627,-0.29201957007210755
284.0000000000033,34.1052243986282,0.45810293636072197,-0.3026689747655418
285.20000000000334,34.22154431953323,0.45866687054958544,-0.31396169151062603
286.4000000000034,34.33653884832917,0.45659187208047497,-0.3264654017479036
287.6000000000034,34.45200130766007,0.45845326853965945,-0.3366508836825961
288.80000000000337,34.567007153125736,0.4585048175499829,-0.3503145693394396
290.0000000000034,34.681767560048534,0.45914296450517855,-0.36111414591360225
291.20000000000346,34.7971255199469,0.45925736557914276,-0.372543562483719
292.40000000000344,34.91218262092048,0.4601947589051041,-0.38397883502326735
293.60000000000343,35.02637807175303,0.4633262996387274,-0.3973786030125668
294.8000000000035,35.14221053808087,0.462845338454165,-0.4101094833570098
296.0000000000035,35.25656093593598,0.4654900890718555,-0.421590874913397
297.2000000000035,35.371075627226084,0.46783522544984535,-0.4366540104112926
298.4000000000035,35.48683935679405,0.4700607835847511,-0.44859212597854725
299.60000000000355,35.60118427445332,0.47148311428511647,-0.4621789918082908
300.8000000000036,35.71671176150957,0.47413726753321495,-0.4754982707229587
302.0000000000036,35.831688607967315,0.4774301883961216,-0.48944400057546344
303.20000000000357,35.94598918949041,0.4793902525761685,-0.5032980646157115
304.4000000000036,36.060533055840175,0.4841352411042956,-0.517197811401199
305.60000000000366,36.17648509694132,0.4846249837947737,-0.5310193256822484
306.80000000000365,36.29165424664628,0.48972387902419395,-0.5449703792274194
308.00000000000364,36.406720102668594,0.49675520392129735,-0.5620928962404279
309.2000000000037,36.52230128072065,0.5021732782213478,-0.5773116301832477
310.40000000000373,36.637105072205834,0.5069279372567402,-0.592285687232645
311.6000000000037,36.75204696144647,0.5148687491468421,-0.6090515395109786
312.8000000000037,36.86752778755983,0.5187000008665027,-0.6269098934546529
314.00000000000375,36.98270002549522,0.5248902771560144,-0.641340975005857
315.2000000000038,37.09853868642701,0.5315098570134865,-0.6606666461843393
316.4000000000038,37.214147622626015,0.5426370542193899,-0.6796055823802121
317.6000000000038,37.32985063198603,0.5529095853048434,-0.6983015905840868
318.8000000000038,37.44463025174522,0.5640539203169278,-0.7184792776930546
320.00000000000387,37.56081990633704,0.5743801741191871,-0.7381266854260087
321.20000000000385,37.675087666930885,0.5913781492491317,-0.7606887341914685
322.40000000000384,37.79146305265244,0.6041205728233161,-0.783640500253878
323.6000000000039,37.905801572812436,0.6201797396152248,-0.8064727099093059
324.80000000000393,38.02128436922995,0.6368942169430315,-0.8298322358156955
326.0000000000039,38.13813844295118,0.6548979106214222,-0.8575129581961702
327.2000000000039,38.25437259342093,0.6757519872439561,-0.8855974106779092
328.40000000000396,38.36895943812162,0.6976689443741435,-0.9152861706938764
329.600000000004,38.485692495465536,0.7229172322755248,-0.9472347879001988
330.800000000004,38.60084619579302,0.7475368362196757,-0.9796161364821963
332.000000000004,38.71738878411965,0.7785484046863559,-1.014132355210072
333.200000000004,38.83256801454883,0.8108232225588079,-1.0507128037522189
334.40000000000407,38.94821594551433,0.843305350826929,-1.0925221546656485
335.60000000000406,39.0654091923732,0.8748180889764369,-1.1352785401353693
336.80000000000405,39.182467726599484,0.9079875303498606,-1.1829271623160356
338.0000000000041,39.29814071488471,0.9366597165558652,-1.2332910731028868
339.20000000000414,39.41427095239322,0.9582604336762665,-1.2875239762728707
340.4000000000041,39.5309972528638,0.9761476336253758,-1.3423937390010172
341.6000000000041,39.646650129985176,0.9782869480180915,-1.4027909538150705
342.80000000000416,39.76361053064874,0.967602941755346,-1.4656366622627406
344.0000000000042,39.88093643866677,0.9376256139048778,-1.528652511977688
345.2000000000042,39.99559784549574,0.8894653763069366,-1.589763512985137
346.4000000000042,40.11063599877772,0.8267204508780859,-1.6490499673083536
347.60000000000423,40.228181250626605,0.7490447147808297,-1.7078430415739025
348.8000000000043,40.34319628252577,0.6710833726172784,-1.762779959362732
350.00000000000426,40.45763477987156,0.5971141147408284,-1.8091046559366295
351.20000000000425,40.573623938015146,0.5307714395323437,-1.85403527280249
352.4000000000043,40.6890686740916,0.4714349891703595,-1.8928308465130939
353.60000000000434,40.80515819282711,0.4227909274898852,-1.9268908497025081
354.80000000000433,40.92026895999785,0.37979787787290725,-1.9558389631499216
356.0000000000043,41.03577281257979,0.3432167623986318,-1.9825410618957666
357.20000000000437,41.15111730709115,0.316345430808697,-2.0053943502775424
358.4000000000044,41.26716051929455,0.29214097083752943,-2.0254880514494262
359.6000000000044,41.383025683936935,0.27698660597363034,-2.045196220136696
360.8000000000044,41.497854117099315,0.2651755620291409,-2.059466286922177
362.00000000000443,41.61451940132613,0.2537558400217962,-2.077229721178249
363.2000000000045,41.73107409442888,0.24703932494518277,-2.092322796966269
364.40000000000447,41.845775244332835,0.24247250338291837,-2.106610722940643
365.60000000000446,41.96318525867823,0.24060512964055164,-2.1214819949999777
366.8000000000045,42.078904396728745,0.23665768833188178,-2.135338698546536
368.00000000000455,42.1948288176337,0.23554437393935268,-2.1473900858999464
369.20000000000454,42.309813357205975,0.23172681084073016,-2.1614258974699343
370.4000000000045,42.42653180040748,0.23221244091040683,-2.174829504924893
371.60000000000457,42.542095700483095,0.23019495922990535,-2.1865768066355917
372.8000000000046,42.65834325328836,0.2293258359684705,-2.1993661109519937
374.0000000000046,42.77383185829195,0.22739645237339168,-2.2132960485465194
375.2000000000046,42.891069217733154,0.22625576751210674,-2.225668178446349
376.40000000000464,43.00756696327943,0.22471846786000316,-2.238372037254458
377.6000000000047,43.123874517341,0.22405992446532969,-2.251688864538691
378.8000000000047,43.239528571164676,0.22126047691520812,-2.263870023336332
380.00000000000466,43.357432691473434,0.2215060282099724,-2.277647480567463
381.2000000000047,43.4740836987113,0.21811791013458048,-2.2901911844188154
382.40000000000475,43.59113164213663,0.21639451822118572,-2.304168595563984
383.60000000000474,43.70821178472052,0.2156301858545534,-2.318123910396835
384.80000000000473,43.825258068631854,0.21537519251119153,-2.329726113334498
386.0000000000048,43.94203492991725,0.21262307072270314,-2.3434405697069107
387.2000000000048,44.05981467169562,0.2113898803509927,-2.3579842161246787
388.4000000000048,44.1766306678209,0.20821997765705508,-2.3699445791742564
389.6000000000048,44.2932290161948,0.20767827149241846,-2.3842848337862823
390.80000000000484,44.41052419081708,0.20720181117353242,-2.3973503660430984
392.0000000000049,44.52697588179792,0.20506895555404198,-2.410827631464274
393.2000000000049,44.645008503924394,0.2036228276464651,-2.4266056189524825
394.40000000000487,44.76175546745828,0.20425653907674268,-2.4395842747113026
395.6000000000049,44.87849671054176,0.20594820427499289,-2.4538425358325084
396.80000000000496,44.995669471615216,0.20447235034047545,-2.4686052734017103
398.00000000000495,45.11125297102573,0.20563385419915647,-2.482095378005491
399.20000000000493,45.2273939261269,0.20108400023997564,-2.497418234838307
400.400000000005,45.34576052625978,0.20392316458819382,-2.515041745288088
401.600000000005,45.46206035176844,0.20556159274520203,-2.5287310552853626
402.800000000005,45.57872410724654,0.20376658225702926,-2.54533653803946
404.000000000005,45.69609580598322,0.20230963219326675,-2.561832057179752
405.20000000000505,45.81316576264382,0.20325465446290125,-2.5783514825280416
406.4000000000051,45.92989889021192,0.20436420835558472,-2.594441520890047
407.6000000000051,46.047148837959305,0.20204322308783507,-2.6104018266091367
408.80000000000507,46.164540752318786,0.20045451877362314,-2.6267704383760493
410.0000000000051,46.2795195568926,0.20236083990720066,-2.64270575540479
411.20000000000516,46.398668166906106,0.20281685340964073,-2.660491018576871
412.40000000000515,46.51638985713002,0.20378547184654316,-2.6766026481952796
413.60000000000514,46.63414937497075,0.20547005138262636,-2.6923026460934576
414.8000000000052,46.75094008801301,0.20573731139995505,-2.7086560065891723
416.00000000000523,46.86716170988224,0.20673618137077499,-2.726826298520491
417.2000000000052,46.98594995752339,0.20439457366013541,-2.743020769336782
418.4000000000052,47.10331930730802,0.2065040061916263,-2.7591773135918305
419.60000000000525,47.22085542717199,0.2080198675332689,-2.775941351343413
420.8000000000053,47.33805573652953,0.2075118719281574,-2.7908711767701737
422.0000000000053,47.45456994978163,0.20990413115063594,-2.80623669949534
423.2000000000053,47.57160310050186,0.20745750688715242,-2.8209163558381687
424.4000000000053,47.68997935655958,0.2081384715228985,-2.8373900036616027
425.60000000000537,47.807851065840715,0.20650164273803928,-2.8511792629415718
426.80000000000535,47.92536599700465,0.20729475816672632,-2.8657029290855345
428.00000000000534,48.042761642172906,0.2045759721601862,-2.877479535778331
429.2000000000054,48.16052933359052,0.20367524806907578,-2.892313153356513
430.40000000000543,48.28022322243048,0.20278079573033375,-2.9069000818374096
431.6000000000054,48.39776149964629,0.20196237810223183,-2.9197215288917886
432.8000000000054,48.51482778100646,0.1995994718840709,-2.931195726024549
434.00000000000546,48.63362109173281,0.19634508160637515,-2.9448892687030153
435.2000000000055,48.750951634912916,0.19275442785178465,-2.95741449141863
436.4000000000055,48.86897374748905,0.19182541910042383,-2.966118825653057
437.6000000000055,48.98645011646768,0.18970355146830603,-2.9794305679570856
438.8000000000055,49.10485078665678,0.18611482640062593,-2.9915867272475545
440.00000000000557,49.222154278688166,0.17961830903204135,-3.001517360136919
441.20000000000556,49.339996174023256,0.1763149810589062,-3.011396949239787
442.40000000000555,49.457978957699325,0.16936612391482708,-3.0202733271409774
443.6000000000056,49.57440467697106,0.16270016054786518,-3.025380618049842
444.80000000000564,49.69271967616717,0.15726540526382032,-3.039799855315223
446.0000000000056,49.810137075145406,0.15485498069102965,-3.04812299907346
447.2000000000056,49.92775422443063,0.14594986082674244,-3.055505506889772
448.40000000000566,50.04634372145718,0.13916652450986244,-3.063306827667942
449.6000000000057,50.163823638771476,0.12984349680481394,-3.070605158209239
450.8000000000057,50.28066277255162,0.1236673314580104,-3.077774758960466
452.0000000000057,50.39862714817376,0.11642042248347229,-3.0838245927752927
453.20000000000573,50.51598493940407,0.11156608290708986,-3.0892486059064264
454.4000000000058,50.6344284958129,0.10840358200039762,-3.096750724185343
455.60000000000576,50.750540275304445,0.10201735347871999,-3.101852553608353
456.80000000000575,50.86834664355762,0.0971327718547525,-3.1084134707014255
458.0000000000058,50.98690730592467,0.09254659473471805,-3.11338919612995
459.20000000000584,51.104859334445315,0.08820133213579007,-3.117731753850542
460.40000000000583,51.22351829590428,0.08513956556271762,-3.1235957093980153
461.6000000000058,51.3401608261736,0.08110754107506035,-3.1282674417136365
462.80000000000587,51.45907026819602,0.08021538767291869,-3.131878112804065
464.0000000000059,51.57706477362035,0.07909200931712579,-3.1361680614749847
465.2000000000059,51.69592693799669,0.07645436731826472,-3.1398348347984997
466.4000000000059,51.81465212288058,0.07144463585060723,-3.144522722626904
467.60000000000593,51.93333756253443,0.07074877496413334,-3.1477717122911626
468.800000000006,52.05137352013842,0.07059309029718419,-3.1523426495556985
470.00000000000597,52.17032195140854,0.06840280596315573,-3.1551201336795316
471.20000000000596,52.28874509601906,0.06447613608287683,-3.1564521212029026
472.400000000006,52.4073210027819,0.061542154217215095,-3.1606463270047422
473.60000000000605,52.524975992848425,0.062456765643199796,-3.1619427107988116
474.80000000000604,52.64381417188276,0.06143613454918351,-3.1660555355395417
476.000000000006,52.761520652770365,0.05907044819445384,-3.168601401610328
477.20000000000607,52.88119190280971,0.057748824450406966,-3.1712518794538527
478.4000000000061,52.99907385677184,0.0561512110094321,-3.1725698412279923
479.6000000000061,53.1173644157043,0.05780554343416333,-3.1751984436624587
480.8000000000061,53.23478041396167,0.055279713036352485,-3.1779510682120105
482.00000000000614,53.353978186531606,0.053834564722784806,-3.179123038000211
483.2000000000062,53.472647402253195,0.05210091487058366,-3.18152103588304
484.4000000000062,53.5912577009018,0.056307453129282536,-3.182963071064212
485.60000000000616,53.70967598624421,0.054924523176501316,-3.185510173885742
486.8000000000062,53.82716060115076,0.05331772660283496,-3.1863097482625684
488.00000000000625,53.946401732953575,0.05286506201961383,-3.1882434746994197
489.20000000000624,54.065563891564615,0.054214961546752094,-3.189569783368351
490.40000000000623,54.18467018418914,0.054827215384964045,-3.1908937688973817
491.6000000000063,54.30272715904629,0.057011279651623115,-3.193438853727652
492.8000000000063,54.421236068592926,0.05662101014755705,-3.1948309997669804
494.0000000000063,54.539854201138084,0.05827968639984449,-3.1962480111340077
495.2000000000063,54.65844553584367,0.061840471270829145,-3.197773227295963
496.40000000000634,54.776723206590596,0.06214056544628954,-3.198707713923492
497.6000000000064,54.89504372215625,0.061782989906333574,-3.201408516030651
498.8000000000064,55.01436181826653,0.06454606881229719,-3.2027309316490005
500.00000000000637,55.131989911796325,0.06354124414370077,-3.2040754655077013
501.2000000000064,55.250100245347824,0.0643693495010178,-3.2053602021518586
502.40000000000646,55.36827298813324,0.06653946680622247,-3.2066810888917967
503.60000000000645,55.48776993387502,0.06382376443264759,-3.2103163699539485
504.80000000000643,55.604956047397735,0.06505301601958347,-3.2116948104616876
506.0000000000065,55.725783598695834,0.06500582645241071,-3.2129764543563457
507.2000000000065,55.84367453220651,0.06382758433140234,-3.2142501062322193
508.4000000000065,55.96260372254733,0.062223910522278825,-3.215574293120612
509.6000000000065,56.08030147739122,0.05976290105381454,-3.215890148683986
510.80000000000655,56.19973179355108,0.05933399852717447,-3.2172016783794275
512.0000000000066,56.31822674012112,0.06043157340909888,-3.218519785637603
513.2000000000066,56.43768035133472,0.061339152385836204,-3.2209183310861507
514.4000000000066,56.55591375463848,0.05718197297131822,-3.2224799190679843
515.6000000000066,56.673780941397816,0.057684565655093833,-3.225087432197097
516.8000000000067,56.79307442213479,0.05657811229628262,-3.2236842193855093
518.0000000000066,56.911622456043325,0.05523837232684714,-3.225140673355873
519.2000000000066,57.030967169473755,0.053274476571205764,-3.227376458932111
520.4000000000067,57.14967282754845,0.053334282215415696,-3.229431134992354
521.6000000000067,57.268256111173635,0.05431480571096159,-3.2313710192821006
522.8000000000068,57.38705136993966,0.05184083757719804,-3.231358433628925
524.0000000000067,57.5045884256803,0.05187878086399067,-3.231899722711545
525.2000000000068,57.623689551120826,0.05302820664752317,-3.233908353596453
526.4000000000068,57.74260544068007,0.048933130284980475,-3.2353197056631933
527.6000000000067,57.86112014654754,0.05120402528561052,-3.2379123073677336
528.8000000000068,57.97978240304544,0.04801921762302508,-3.237940324727724
530.0000000000068,58.098880975113914,0.048719490610071636,-3.2392591321960746
531.2000000000069,58.217248864059904,0.04579153064371688,-3.239251867339863
532.4000000000069,58.33664948113568,0.048072428524285504,-3.2406809717991276
533.6000000000068,58.45507361436224,0.04587808845960706,-3.243199656606809
534.8000000000069,58.575602363972436,0.04539481490548358,-3.2444858869861157
536.0000000000069,58.694999320850656,0.04747083567611243,-3.2437647379410492
537.2000000000069,58.81427661277725,0.04290383752564131,-3.244557703711931
538.4000000000069,58.93350839767144,0.04527848269028989,-3.2458400872763082
539.600000000007,59.051977585199985,0.042822585333612384,-3.247279157016915
540.800000000007,59.17157440208358,0.04295098631971028,-3.2484701052022076
542.000000000007,59.29080938389065,0.046614805512387614,-3.2497801207301062
543.200000000007,59.409482980744315,0.04438516711694307,-3.2507793347481506
544.400000000007,59.52966806950603,0.04421083757044486,-3.2521366997058143
545.6000000000071,59.64820495540971,0.04351887106525054,-3.2536686642251573
546.800000000007,59.76750861934896,0.04725949240767913,-3.2524433207484975
548.000000000007,59.8877752455374,0.04559565522726894,-3.253744468857578
549.2000000000071,60.00732275270868,0.04044507910129658,-3.2563602898597157
550.4000000000071,60.12720864285271,0.04094307121602736,-3.2563219169839113
551.6000000000072,60.24623781458089,0.04122017351977514,-3.2575949950465612
552.8000000000071,60.366080975751764,0.040795696874806664,-3.259000082970212
554.0000000000072,60.48598284764064,0.0426282332339073,-3.2590000806842294
555.2000000000072,60.60538190397331,0.04397250774119088,-3.2603189372340515
556.4000000000071,60.7256473659142,0.04241691576158657,-3.2616396777402956
557.6000000000072,60.84540135502095,0.04149268246728732,-3.2616284011016123
558.8000000000072,60.96586384237849,0.04361118927570595,-3.262952396527345
560.0000000000073,61.08505066830728,0.041091416558225013,-3.263503972808423
561.2000000000073,61.20500806864194,0.042875569836558935,-3.2642598644026943
562.4000000000073,61.32467908696018,0.04158413905057967,-3.265622541923987
563.6000000000073,61.44474570229168,0.04337274914290323,-3.2669001389660854
564.8000000000073,61.564465665082636,0.040945470930021766,-3.266899914888503
566.0000000000073,61.684884046623274,0.04270678814233442,-3.2674447926459615
567.2000000000073,61.80546031102944,0.04259394255197746,-3.266790849078631
568.4000000000074,61.92416375229681,0.04388078437728582,-3.268930775442857
569.6000000000074,62.04380988451525,0.04288502154072671,-3.2695517571766133
570.8000000000075,62.163350325416936,0.04658917977439425,-3.270839873241163
572.0000000000074,62.2832113420018,0.04464293087023208,-3.271212957088305
573.2000000000074,62.40304879238482,0.04880270548279686,-3.271821032624184
574.4000000000075,62.523775550102776,0.04370065645580945,-3.273478339594965
575.6000000000074,62.642465349764805,0.040223688094509824,-3.2747923641495382
576.8000000000075,62.763846974956586,0.03659204721666587,-3.2774669857336023
578.0000000000075,62.88421590939191,0.03462733571952148,-3.27743090315253
579.2000000000075,63.0034285442979,0.0321090381967325,-3.2800611703003897
580.4000000000076,63.12420572084801,0.025939549862743827,-3.28005899909035
581.6000000000075,63.244751753052526,0.02270832803202738,-3.2814630420406035
582.8000000000076,63.36463669491173,0.021433472421566457,-3.2826859659155083
584.0000000000076,63.484321335794846,0.019259490243019983,-3.285317863997649
585.2000000000075,63.604735793070176,0.01800654819907721,-3.2865925207961584
586.4000000000076,63.725015353947555,0.017592584264266575,-3.2867169830698213
587.6000000000076,63.84527795869537,0.018440918999849676,-3.288622560426088
588.8000000000077,63.9645907858275,0.01641694233636304,-3.2912267869068
590.0000000000077,64.08540798251258,0.016317350617797155,-3.290599135830175
591.2000000000077,64.20578723268669,0.021445358442008233,-3.2918944338064144
592.4000000000077,64.32606696304559,0.021047423359564,-3.2932280132161957
593.6000000000078,64.44560629472319,0.021898289354126632,-3.292593790451524
594.8000000000077,64.56582446575862,0.021993003965137037,-3.2942579276909054
596.0000000000077,64.68537989202983,0.0276539251728134,-3.295845823132935
597.2000000000078,64.80606400440614,0.026145455296861186,-3.2973605730341218
598.4000000000078,64.92688492570481,0.02811363192914551,-3.298809105342848
599.6000000000079,65.04642374900153,0.026825728782251312,-3.2992684479133976
600.8000000000078,65.16630372413793,0.030243599230934004,-3.2999750124429994
602.0000000000078,65.28650365909907,0.03514651639030819,-3.300791121980531
603.2000000000079,65.40712554705647,0.037658168168656525,-3.302113298126815
604.4000000000078,65.52721254646374,0.03895241869041466,-3.3021100365660616
605.6000000000079,65.64596269340423,0.042214413674068973,-3.303163600258414
606.8000000000079,65.76675527405598,0.04206783577124851,-3.303735866582219
608.000000000008,65.88711465077026,0.04782603606666247,-3.3060612622075602
609.200000000008,66.00690004865052,0.04996044264391042,-3.3060596003278393
610.4000000000079,66.12657872939434,0.05607154178875473,-3.3060601118903277
611.600000000008,66.247233706007,0.05651272915800454,-3.3063900963647557
612.800000000008,66.36715371462783,0.058126078344387766,-3.3086845509835348
614.000000000008,66.48748399945897,0.061732336247729114,-3.3086894241398603
615.200000000008,66.60807709268339,0.06245203710136571,-3.3100081302972186
616.400000000008,66.72808766966526,0.06376827790128825,-3.3099976999134864
617.6000000000081,66.84937650361627,0.06323519066147032,-3.3126395348477318
618.8000000000081,66.96956216715482,0.060579942876313186,-3.312634620298774
620.0000000000081,67.09032454738573,0.0656191152025336,-3.3126399866585747
621.2000000000081,67.21030881400642,0.06244808867178708,-3.3126398519967517
622.4000000000082,67.3308973794378,0.06416396522903667,-3.3126257697812407
623.6000000000081,67.45147310352012,0.06031549414977744,-3.313951148457174
624.8000000000081,67.57182744786603,0.062073465595249955,-3.3139499859638883
626.0000000000082,67.6928316378501,0.06180200010896297,-3.315269664279622
627.2000000000082,67.81280148001521,0.06038228640984311,-3.3165900320361437
628.4000000000083,67.93351672528284,0.06236863568769979,-3.3178998358314846
629.6000000000082,68.0543351161279,0.0623293299421408,-3.317899808000022
630.8000000000083,68.17438542007429,0.06187073809644028,-3.317899943295178
632.0000000000083,68.2949796077608,0.06402939632789661,-3.319220031669694
633.2000000000082,68.41598664357299,0.06243832823897422,-3.3192200346343697
634.4000000000083,68.53710150731541,0.06001589978666866,-3.3205261809768927
635.6000000000083,68.65702780312948,0.05896074274854857,-3.3205300655575547
636.8000000000084,68.77617843493714,0.06294856704937835,-3.321827369983062
638.0000000000084,68.89819374178086,0.062423732548494204,-3.3228450747482086
639.2000000000083,69.01850405421939,0.06055062369965514,-3.323172336061632
640.4000000000084,69.13926888379213,0.05719951301499626,-3.322497622313981
641.6000000000084,69.26063297558964,0.056810169404844846,-3.322183596953064
642.8000000000084,69.38128369507564,0.059349906313037604,-3.3230120616918417
644.0000000000084,69.50165028048,0.05541905361428867,-3.32481936265109
645.2000000000085,69.62184181364847,0.05682020677605348,-3.324489943174141
646.4000000000085,69.74332546164725,0.05816698194026171,-3.3231700012751686
647.6000000000085,69.86473810090231,0.05645415673296683,-3.3258369862545165
648.8000000000085,69.98498530495623,0.05407470229159994,-3.325798371182878
650.0000000000085,70.10581643261568,0.053892794818180434,-3.326048973957083
651.2000000000086,70.22868270014685,0.05770519584778655,-3.3288794724105504
652.4000000000085,70.3487590883755,0.05473241945471208,-3.3268902264736075
653.6000000000085,70.47007999623166,0.05866105565198243,-3.3268955724384623
654.8000000000086,70.5913273553988,0.0570635358158198,-3.3282100453349646
656.0000000000086,70.71275293279456,0.054287462613123116,-3.3268951302778422
657.2000000000087,70.83362426888932,0.05502936827514526,-3.329397011070716
658.4000000000086,70.95426836330002,0.052590683262006,-3.3282101909991244
659.6000000000087,71.07573590016574,0.05606591791577942,-3.3282103598219877
660.8000000000087,71.19694590337807,0.05640702435273681,-3.330179955961061
662.0000000000086,71.31866558945454,0.05635738921255684,-3.3315003391663587
663.2000000000087,71.43907949422857,0.0556906783880875,-3.3301941859809134
664.4000000000087,71.55838873263113,0.056634416758443384,-3.3315178171792375
665.6000000000088,71.68018224476356,0.05800712328156554,-3.3315100079658517
666.8000000000088,71.80207840407573,0.05605532675573688,-3.330849756706837
668.0000000000088,71.92262119079179,0.05732545410526724,-3.332159074916743
669.2000000000088,72.04288631209904,0.05874015022806556,-3.3316739905791346
670.4000000000088,72.16284854833492,0.059040504380527103,-3.332578201033088
671.6000000000088,72.28274318540342,0.05890850681676407,-3.3339810201435682
672.8000000000088,72.404856698498,0.05805375291156034,-3.3353399444997223
674.0000000000089,72.52469438523953,0.05964871676790873,-3.3353401515251475
675.2000000000089,72.64595905099998,0.058004099399359355,-3.3340200787461254
676.400000000009,72.76670335694345,0.059536519483454065,-3.3346798906078163
677.6000000000089,72.88699143808508,0.05562715250938299,-3.3353479998639344
678.8000000000089,73.00652566647251,0.05740459214183802,-3.337219147363042
680.000000000009,73.12758437732873,0.05762849291909311,-3.335997421405174
681.2000000000089,73.24781101916349,0.05949891163901855,-3.3373160756852123
682.400000000009,73.36839060369275,0.057576854100233055,-3.337324761862499
683.600000000009,73.4887538835859,0.057250813596709804,-3.337309909002944
684.800000000009,73.61025013220139,0.05923517234778086,-3.3372961326330364
686.0000000000091,73.7307462381515,0.055330563279035516,-3.337338036769469
687.200000000009,73.85258040212517,0.05576775225674968,-3.339642100807369
688.4000000000091,73.97313359428898,0.05835737991389234,-3.339949964858879
689.6000000000091,74.09479672069776,0.05403739212236869,-3.341260531202827
690.800000000009,74.2156076581725,0.055072115099285,-3.3412603115798536
692.0000000000091,74.33649701207528,0.05680892497666723,-3.339936420249253
693.2000000000091,74.45769846303557,0.05423712677772752,-3.3406115256049373
694.4000000000092,74.5789798172986,0.05879079464440817,-3.3409360855031087
695.6000000000092,74.70091524423984,0.05802487792424604,-3.3433537703658387
696.8000000000092,74.82155799703764,0.05655909658457925,-3.343569803997831
698.0000000000092,74.94158655755479,0.054604283257481345,-3.34363131713036
699.2000000000093,75.0633726519541,0.05727170931804859,-3.3442618735301664
700.4000000000092,75.18397110408999,0.05184899888886463,-3.3442300339709154
701.6000000000092,75.30625149820126,0.0524424333532183,-3.343568001193007
702.8000000000093,75.42670196107471,0.049160873821781026,-3.344230331219464
704.0000000000093,75.54826220171749,0.049047609651351465,-3.3442301328831507
705.2000000000094,75.66907396221868,0.04451034558143441,-3.3462002653384877
706.4000000000093,75.79005746201251,0.04495996878444064,-3.346200009631775
707.6000000000093,75.91082120376065,0.038627639737683905,-3.345216883111618
708.8000000000094,76.03270823906121,0.03731443131151968,-3.3452027153943056
710.0000000000093,76.15461617607622,0.03648129485254614,-3.3465309081259633
711.2000000000094,76.27485697792908,0.0336359313055099,-3.3478400052656445
712.4000000000094,76.39662713594511,0.03281985194960346,-3.3461829656584574
713.6000000000095,76.51836677627625,0.0328628464450893,-3.3475099764893157
714.8000000000095,76.63886241677196,0.030799262739842792,-3.3475099895524276
716.0000000000094,76.76061841175826,0.02916700311407494,-3.3481506969998263
717.2000000000095,76.88098313867536,0.025229093629572485,-3.348154380039176
718.4000000000095,77.00200581548984,0.027250307221910797,-3.3494900405699313
719.6000000000095,77.1241953353314,0.025740389116596152,-3.3494900407457457
720.8000000000095,77.24565910398722,0.026262532408672712,-3.348862337388743
722.0000000000095,77.36677619775269,0.02406086307471833,-3.348765674234137
723.2000000000096,77.48577632479088,0.021668661515806376,-3.349490068916593
724.4000000000096,77.61020260137087,0.01869931228931332,-3.3511997867525603
725.6000000000096,77.7316796341109,0.01931461141706059,-3.3501502175843134
726.8000000000096,77.85176620227087,0.019233427196926556,-3.351504921347711
728.0000000000097,77.97320495951229,0.01690369675356962,-3.3514698611501728
729.2000000000096,78.09428757250453,0.018181762478189478,-3.351213119839424
730.4000000000096,78.21552856959015,0.018455772852925323,-3.3520858642343785
731.6000000000097,78.33825447706087,0.01822749631266718,-3.3541065362122295
732.8000000000097,78.45947438732289,0.013467754874464388,-3.3512506144142424
734.0000000000098,78.58040085380716,0.01357964886982388,-3.354092646069993
735.2000000000097,78.70222352720513,0.014413065059827979,-3.3554098654849733
736.4000000000098,78.82328057465651,0.015879762759098526,-3.354101613224847
737.6000000000098,78.94572489113477,0.007970612347294681,-3.354082998924474
738.8000000000097,79.06747733464731,0.005637625258995138,-3.3540899749996242
740.0000000000098,79.18917000000093,0.004991576054254487,-3.354089975
741.2000000000098,79.30812471608681,0.004030859900490347,-3.3540899618570204
742.4000000000099,79.4299347084133,0.004874509475856215,-3.3554098246133166
743.6000000000099,79.55456107626706,0.003823178425662155,-3.3567308168852312
744.8000000000098,79.6761537057058,0.002079343534344469,-3.3570594472346427
746.0000000000099,79.7978261472806,0.00020643796256814007,-3.3583258099563906
747.2000000000099,79.91947004764525,0.0010113388019576952,-3.3561453044406693
748.4000000000099,80.04120390007375,0.0014068277379271077,-3.3563801622496667
749.6000000000099,80.16281717496044,-0.00020292161879753579,-3.357696971307806
750.80000000001,80.28471787043861,-0.0011808594024089736,-3.3600198724686954
752.00000000001,80.4055382692821,-0.002655393221753455,-3.3594278066964667
753.20000000001,80.5268269062952,-0.002391856311563245,-3.357402636955917
754.40000000001,80.64837063700642,-0.0042801726735395285,-3.360018289129109
755.60000000001,80.76937662169098,-0.0064010892049206625,-3.3586999341783508
756.8000000000101,80.89056616932065,-0.0007523093917523038,-3.3586998066064337
758.00000000001,81.01215214543483,-0.00510137627319307,-3.360020019259539
759.20000000001,81.13309278106355,-0.006072534358235293,-3.3600200979999877
760.4000000000101,81.25465606460106,-0.009248592078341611,-3.3600200766725123
761.6000000000101,81.37656557506673,-0.008577496370683946,-3.36067996286377
762.8000000000102,81.49789685039777,-0.01227820739663632,-3.3600211363588333
764.0000000000101,81.61906399708938,-0.008058450406788431,-3.360029922999588
765.2000000000102,81.74056473519335,-0.01108956371658465,-3.3600299230000004
766.4000000000102,81.86322249751792,-0.00936610564620155,-3.360029923001368
767.6000000000101,81.98484812762649,-0.01075742901079435,-3.3600424069177315
768.8000000000102,82.10606740933079,-0.007808369795876846,-3.3613400772177098
770.0000000000102,82.22917000000103,-0.005495907578598747,-3.362659900999985
771.2000000000103,82.35051171178225,-0.009283312674737587,-3.362659900997862
772.4000000000103,82.47220412951198,-0.007999618322181767,-3.362659854088071
773.6000000000103,82.59359651798015,-0.00587526111584058,-3.3639702463961245
774.8000000000103,82.7152292278838,-0.008166730419255419,-3.3626501165906197
776.0000000000103,82.83611853463881,-0.010909320857325877,-3.363971945913086
777.2000000000103,82.95849414801076,-0.010613156003587587,-3.363309877315554
778.4000000000103,83.0809331235311,-0.01247251026194185,-3.3633098789362768
779.6000000000104,83.20238161269125,-0.009625047169683931,-3.364488352777239
780.8000000000104,83.32444248358938,-0.00823279570370472,-3.364630107015321
782.0000000000105,83.44565362294169,-0.013608372794787993,-3.3659214552567063
783.2000000000104,83.56738185883655,-0.009757645738718512,-3.365039179036014
784.4000000000104,83.68877004678771,-0.011046538307053044,-3.3642902082405977
785.6000000000105,83.81150847276444,-0.012888126199970706,-3.3669276186615997
786.8000000000104,83.9333653297566,-0.014285695752895844,-3.3669301729129684
788.0000000000105,84.05632829911144,-0.009459980120293032,-3.3679167783571686
789.2000000000105,84.17848118596149,-0.016378810441177283,-3.3679083724024697
790.4000000000106,84.30050224552444,-0.012744915185468386,-3.3682398919870615
791.6000000000106,84.42252308284938,-0.01255249546223558,-3.368226279239984
792.8000000000105,84.54573651938956,-0.020218532905701192,-3.3685801211666737
794.0000000000106,84.66717822366228,-0.015174742633262461,-3.368581473356371
795.2000000000106,84.78927962591247,-0.017115164181133125,-3.3698999449556917
796.4000000000106,84.91161980945387,-0.01412654318426787,-3.3697797356189114
797.0000000000106,84.97285367598006,-0.013161824234639852,-3.369569984872662