File: 01_Data/Bamboo_Rug_Fabric/STA/N2/10K_min/Bamboo_Rug_Fabric_STA_N2_10KData_220124_R2.csv
##Temp./Â°C,Time/min,DSC/(mW/mg),Mass loss/mg
50.0,10.810220783315465,0.039707814802123154,0.006175192481714831
51.20000000000002,11.109425029836624,0.08175395396624685,0.006717079210178056
52.400000000000034,11.323553152618624,0.10994964472363056,0.00727023859776299
53.60000000000005,11.508181587376457,0.13092007308432763,0.006637839748388608
54.80000000000007,11.673999444951313,0.14813415547189712,0.005604594189308365
56.000000000000085,11.82528880171198,0.1637205128938214,0.005879660494032102
57.2000000000001,11.97413490409366,0.17533361432548988,0.006656175339241344
58.40000000000012,12.117705431439315,0.1854942302649346,0.004928692595146167
59.600000000000136,12.25620443578655,0.19335042785949608,0.006425556522427378
60.80000000000015,12.39203950133807,0.2008211047404923,0.005067289093413585
62.00000000000017,12.525966335863455,0.20727264276574797,0.005799978731018562
63.20000000000019,12.658752528553663,0.21487997310322737,0.006278411594424327
64.4000000000002,12.790579889351173,0.22044413492773068,0.0063660592738266075
65.60000000000022,12.91977818153996,0.22396922258667612,0.007574643303170703
66.80000000000024,13.050927801704736,0.2283231636566716,0.0061163955423078065
68.00000000000026,13.179761268257725,0.23146123390331108,0.0038797179129446135
69.20000000000027,13.307443709268277,0.2317696397452227,0.003641630054661782
70.40000000000029,13.435221524101943,0.23238183909948595,0.0038581083895428137
71.6000000000003,13.558481170156837,0.23367414052755364,0.005040936990180711
72.80000000000032,13.689892370063106,0.23646395387548225,0.003707882819541375
74.00000000000034,13.815433985583603,0.23807982408825545,0.003717423108354545
75.20000000000036,13.941153882745692,0.23890815722358116,0.003736057658320746
76.40000000000038,14.06739543736638,0.24098223322584655,0.0050402756431866536
77.60000000000039,14.190837088492135,0.2433026066599751,0.0037238735878233342
78.80000000000041,14.316162459166083,0.2468437303179365,0.0037127529386742353
80.00000000000043,14.441096888691373,0.24568696876992907,0.0037299716110537062
81.20000000000044,14.564829651271536,0.24695232690590585,0.0024104508538451697
82.40000000000046,14.686793420763543,0.2488855849358388,0.002503302935104479
83.60000000000048,14.810180423675236,0.25077686544921246,0.002421359713981275
84.8000000000005,14.93223055361527,0.25069412019914816,0.0010770783970013298
86.00000000000051,15.054501812522695,0.2512391213135579,0.0024008305354064063
87.20000000000053,15.174250692973441,0.2483654366971198,0.0005608354515187486
88.40000000000055,15.295175721249045,0.25144943411418896,0.0009298382404443473
89.60000000000056,15.414549121359952,0.2520192018774193,0.0011010013507322114
90.80000000000058,15.53716002184689,0.25206878986836323,-0.00022045111096602454
92.0000000000006,15.655984499181097,0.25000689547844684,0.000530712195747185
93.20000000000061,15.775541710360136,0.25096659514732345,0.0017298006444583791
94.40000000000063,15.894436294558796,0.25140683914704387,0.0004290471049586131
95.60000000000065,16.012884084410924,0.2524382741847704,-0.0008927159448770539
96.80000000000067,16.131308592448843,0.2512791936459339,-0.000220359285934002
98.00000000000068,16.250106057911758,0.25441643806454106,-0.002203220471392875
99.2000000000007,16.368535643064064,0.25684999438720857,-0.002196898495724575
100.40000000000072,16.48457686849164,0.25477547304395426,-0.00218999470114678
101.60000000000073,16.602209912669647,0.2551849231221448,-0.0008799113738815478
102.80000000000075,16.720087328439934,0.25657474702144223,-0.002191734766604725
104.00000000000077,16.837988005146435,0.25352242575117107,-0.002090324600093396
105.20000000000078,16.955109134766747,0.2550349094458087,-0.0025406054505570097
106.4000000000008,17.07048144783,0.2549225922791411,-0.0038341499971625836
107.60000000000082,17.191937314421246,0.2544615092496897,-0.0038180278841117854
108.80000000000084,17.30882616417187,0.2586218736111001,-0.0038759873341112083
110.00000000000085,17.426852106007583,0.25763497505773536,-0.003839005766734793
111.20000000000087,17.54542167589675,0.2578407123093659,-0.00517090487558125
112.40000000000089,17.66094112865659,0.2574217534388157,-0.005122591227054052
113.6000000000009,17.778749905417094,0.2583412172659544,-0.004830130669279953
114.80000000000092,17.896570236954517,0.2580392707437086,-0.004833139681534426
116.00000000000094,18.01461014925963,0.25833973441373104,-0.0038647287879234327
117.20000000000095,18.130251473734216,0.2614046774233589,-0.005152361071144362
118.40000000000097,18.247832156900138,0.2648748794889337,-0.00515994731642877
119.60000000000099,18.364371813089104,0.26245887562944353,-0.005160076887323228
120.800000000001,18.481851332480698,0.26615638205176173,-0.005348783955829717
122.00000000000102,18.599442792654276,0.2653636539315909,-0.005158183154033935
123.20000000000104,18.715643206543024,0.26346476610843694,-0.005538171194980457
124.40000000000106,18.83178278566059,0.26652661254077736,-0.005159823720931378
125.60000000000107,18.948233448765407,0.2681591742733406,-0.005651140420612322
126.80000000000109,19.065371339268072,0.2686159502057373,-0.005160026406839435
128.0000000000011,19.181256676773433,0.2693698702488019,-0.006470029007238587
129.20000000000113,19.29855069844544,0.27121735570484873,-0.007790037954648277
130.40000000000114,19.41570130592369,0.2714094452770952,-0.006488892682299685
131.60000000000116,19.53273837737642,0.27341528829055706,-0.006480083956136973
132.80000000000118,19.643676219072912,0.275551594059283,-0.007469286022086408
134.0000000000012,19.763566492121402,0.27497119347324817,-0.006149968249489213
135.2000000000012,19.879898014002674,0.277213105159902,-0.006149894954802448
136.40000000000123,19.996579940173664,0.27841171468543846,-0.00640918166221649
137.60000000000124,20.111536158305157,0.2831420360216147,-0.006471931818078147
138.80000000000126,20.22727159296857,0.28402929709228075,-0.007795063072968844
140.00000000000128,20.341660649234427,0.28576053099728693,-0.007139837572438523
141.2000000000013,20.459278599562822,0.286329777900519,-0.00845049883245963
142.4000000000013,20.5739286100951,0.2874303069492951,-0.008434003717366245
143.60000000000133,20.689062383700307,0.2887048677656503,-0.007829206284062806
144.80000000000135,20.80507050370014,0.287555592566787,-0.007789516938385255
146.00000000000136,20.920994299748845,0.29273376365217524,-0.008097477842903267
147.20000000000138,21.034983743720673,0.29143631627782535,-0.009125349776597957
148.4000000000014,21.151459355296684,0.2926650801345311,-0.009110057258595816
149.60000000000142,21.26631021857938,0.2972114289033259,-0.008449426071407196
150.80000000000143,21.381482488097152,0.2979525913200799,-0.008216159881769158
152.00000000000145,21.497465408037513,0.29877303761017376,-0.009100150076437608
153.20000000000147,21.61138323413842,0.2997169065682607,-0.009100150007495422
154.40000000000148,21.726881515286838,0.3005430419926645,-0.009147532558475113
155.6000000000015,21.842810582370173,0.3045508172519686,-0.010452048059369723
156.80000000000152,21.957284783064708,0.3062929788446661,-0.009870108561024438
158.00000000000153,22.072367485107247,0.3065497966181487,-0.009739453405138043
159.20000000000155,22.186201595032223,0.30909350809979,-0.010043361042534116
160.40000000000157,22.302200302077345,0.3081981247062207,-0.010429530587392932
161.6000000000016,22.41685629620043,0.31077003466407294,-0.011740201234925252
162.8000000000016,22.53238081930612,0.31247274824868526,-0.011740200090553543
164.00000000000162,22.647046048747505,0.3144326001902287,-0.011034501251796947
165.20000000000164,22.76294527998454,0.31345372410883504,-0.01140985190329502
166.40000000000165,22.874801247041436,0.31543339651836444,-0.011503531996803318
167.60000000000167,22.992801973512137,0.3175905676873562,-0.01304499767641687
168.8000000000017,23.108033947474542,0.3195142995085266,-0.013021889688006993
170.0000000000017,23.22422410938677,0.3196244968857255,-0.014373135286781746
171.20000000000172,23.337960209894682,0.3213447502507899,-0.013049998591888823
172.40000000000174,23.45358332288343,0.324756471016384,-0.013708489619703279
173.60000000000176,23.568959854224055,0.32478357647841427,-0.015030171829899075
174.80000000000177,23.68358142933467,0.326755568761805,-0.015030101477401026
176.0000000000018,23.796915494877286,0.3272493181379446,-0.015067843757798016
177.2000000000018,23.914779782832504,0.3303030173854284,-0.01634528700817217
178.40000000000182,24.02887691894574,0.33177282455546914,-0.014443943322958397
179.60000000000184,24.14418525395364,0.32979246235162607,-0.015359923835384315
180.80000000000186,24.260000000000176,0.3300377390066189,-0.017992383318925498
182.00000000000188,24.37507607382058,0.33219846919189605,-0.017986972178519522
183.2000000000019,24.489604252601875,0.3350828398690224,-0.01798419110891203
184.4000000000019,24.60523438245364,0.334573120708496,-0.019360777796120665
185.60000000000193,24.719721495213562,0.33701134569042174,-0.017990150116443893
186.80000000000194,24.83445887727743,0.33901662417380213,-0.019172205537763
188.00000000000196,24.948182274537118,0.3416545890452771,-0.020630505123910403
189.20000000000198,25.063639553036225,0.34312185150497354,-0.02193259601165387
190.400000000002,25.177686609560652,0.34591156471981044,-0.0219499400040446
191.600000000002,25.291957637548055,0.3459914300543331,-0.021949939999998946
192.80000000000203,25.405937647891246,0.34872617136824613,-0.02194993999999273
194.00000000000205,25.520589020749647,0.351398761361958,-0.021950006691001
195.20000000000206,25.63495836521643,0.3526402603940576,-0.02374946509732556
196.40000000000208,25.748540829770043,0.3533961976588133,-0.0245698785564592
197.6000000000021,25.8638804764527,0.35684197259286454,-0.024569888242440996
198.80000000000211,25.97832494826142,0.3571084837862161,-0.026205908773795805
200.00000000000213,26.09172545517368,0.35739608007317736,-0.02751766162343028
201.20000000000215,26.206717080298134,0.35918616340513276,-0.027514649019968473
202.40000000000217,26.32067757283609,0.36256968778042253,-0.027539398806137427
203.60000000000218,26.434721131933205,0.3600368218831017,-0.028520226056489406
204.8000000000022,26.547372057770158,0.36045243541488114,-0.029225072582693024
206.00000000000222,26.663468882108635,0.36209155770778917,-0.031142980371258844
207.20000000000223,26.77808383875709,0.36413542929381765,-0.0308173693610021
208.40000000000225,26.892410728425762,0.3623817622466269,-0.0331310214313989
209.60000000000227,27.007794956884272,0.36371222786945107,-0.03376524471266773
210.80000000000229,27.12196395399627,0.3616923892863815,-0.03328702272932649
212.0000000000023,27.2372178019221,0.3638864809356216,-0.035756022999903436
213.20000000000232,27.352259803306097,0.366245177624764,-0.037738167196989636
214.40000000000234,27.466382932961988,0.36632299989605316,-0.03773798704971476
215.60000000000235,27.581671243150275,0.36811503256030537,-0.0410348277700745
216.80000000000237,27.696874255618177,0.3703946933768714,-0.041364692720586405
218.0000000000024,27.810195680303533,0.3687870460737711,-0.041360673378847856
219.2000000000024,27.92559090829511,0.37210113216461554,-0.04276273741190462
220.40000000000242,28.04030934447959,0.37680257786931504,-0.0449701705505019
221.60000000000244,28.15209594146513,0.3772111175614285,-0.04503462246557266
222.80000000000246,28.269212322723366,0.3790274114269014,-0.04787888643376359
224.00000000000247,28.383050167197666,0.38260498811753874,-0.04920829154893802
225.2000000000025,28.497323705585845,0.3859010967839348,-0.05188991305587898
226.4000000000025,28.61258370437275,0.38800491106406126,-0.05057206037524242
227.60000000000252,28.726729336916755,0.3944701946259954,-0.0531997629401566
228.80000000000254,28.842057299728516,0.39255010164634163,-0.05451712714485346
230.00000000000256,28.956782899318586,0.3955464301142976,-0.05682987913218085
231.20000000000258,29.070077821669027,0.39741363009086295,-0.05814047041885306
232.4000000000026,29.185180053449912,0.39903350365126816,-0.05979160279128237
233.6000000000026,29.299330050596396,0.40187955035935974,-0.061099884741744326
234.80000000000263,29.413975346255853,0.405753265797573,-0.06241591638534594
236.00000000000264,29.52854351241238,0.41011523813792355,-0.06635989867435832
237.20000000000266,29.642611003087477,0.415532499844356,-0.06765945803205575
238.40000000000268,29.756893348180892,0.42514404601341965,-0.07103792536038345
239.6000000000027,29.872659460187535,0.43097391252929607,-0.07098302770929887
240.8000000000027,29.98668167676598,0.4412869265950464,-0.07425324395632327
242.00000000000273,30.100190886748234,0.45145820782290885,-0.0768998457625738
243.20000000000275,30.21567381853901,0.4648130653567417,-0.07937172141072857
244.40000000000276,30.330000871066062,0.4830545787076571,-0.08356528228685
245.60000000000278,30.44539404787211,0.5035148001728125,-0.0845580272200257
246.8000000000028,30.559150667561287,0.526369815005828,-0.08755398709655449
248.0000000000028,30.674009752955143,0.557045076024451,-0.09017650187344994
249.20000000000283,30.789696069226625,0.5929840963238057,-0.09410860790548448
250.40000000000285,30.904537770018948,0.6314140655379973,-0.09666227383869508
251.60000000000286,31.019424921300338,0.6523575039403875,-0.10172349199824815
252.80000000000288,31.13428575351485,0.6547196372178941,-0.10479238261312629
254.0000000000029,31.24980540626895,0.6297266953138223,-0.10891719423314594
255.20000000000292,31.36441072346725,0.5853689729927621,-0.11267685703225272
256.40000000000293,31.47855836141496,0.5390986396832976,-0.1169408977926274
257.600000000003,31.59303250179035,0.49556552768608964,-0.12001889049849712
258.80000000000297,31.707136229467583,0.4624207017363873,-0.12456909977172037
260.00000000000296,31.820574427024997,0.4442476958852438,-0.1299804892414702
261.200000000003,31.934692605632293,0.43116353945258923,-0.13416786842155393
262.40000000000305,32.04863415954059,0.4263101249265364,-0.13928586657059228
263.60000000000304,32.16250478316393,0.4228347552417077,-0.1448907012783991
264.800000000003,32.27782504631352,0.42232223575668876,-0.15123426513674332
266.00000000000307,32.39163760087029,0.4239104988695787,-0.15720809782287626
267.2000000000031,32.50383159045675,0.4252985894304995,-0.1639482653695179
268.4000000000031,32.62009974015382,0.42905620302835934,-0.1716644530120517
269.6000000000031,32.73404504940961,0.43101974780002533,-0.17857738648983945
270.80000000000314,32.848544189058074,0.42997500028735763,-0.18661080888068104
272.0000000000032,32.963449451766174,0.43070714638111973,-0.19523929784367722
273.2000000000032,33.07924903619955,0.43528431696031833,-0.20307057430754005
274.40000000000316,33.19400966456884,0.4342268061045488,-0.21190303798418686
275.6000000000032,33.30678608320731,0.43605155692894026,-0.22202056554448246
276.80000000000325,33.42061089755286,0.43661853469317147,-0.23136740745911544
278.00000000000324,33.538563438895,0.4388837817464645,-0.24156897565171498
279.20000000000323,33.652612012584854,0.44153187631681995,-0.25141275193677615
280.4000000000033,33.76822433000915,0.44193732662845014,-0.26129056866462763
281.6000000000033,33.88160697586767,0.4430974570420455,-0.27182900647733277
282.8000000000033,33.99676853511807,0.44179899467027106,-0.28307512676373836
284.0000000000033,34.11219280074197,0.4435591361305057,-0.2936446053171844
285.20000000000334,34.22672672828293,0.44391391820601733,-0.3042681356487904
286.4000000000034,34.3419596496523,0.4433589578870936,-0.31526393239637684
287.6000000000034,34.45694115495644,0.4421576866166622,-0.3270002877264666
288.80000000000337,34.57106976287574,0.44528437185710495,-0.33816707589999373
290.0000000000034,34.686209210597156,0.44499510368510403,-0.35168229426646125
291.20000000000346,34.80176012555528,0.4432509393587692,-0.36503884498491024
292.40000000000344,34.915668331607485,0.4445293689799017,-0.3753863857356343
293.60000000000343,35.030767573239245,0.4426110899895358,-0.387969519102211
294.8000000000035,35.14568646581439,0.44544451137057506,-0.40038704181212426
296.0000000000035,35.260750086243036,0.4455982213144638,-0.4150458420202785
297.2000000000035,35.37529811532564,0.44844263958184716,-0.4280539122920328
298.4000000000035,35.490803506719004,0.4481431360732566,-0.43894909252758785
299.60000000000355,35.60535640514232,0.45103858419509185,-0.45288694088983084
300.8000000000036,35.71965109349861,0.4559614635016508,-0.46777929500579907
302.0000000000036,35.83521053910045,0.45574521898974796,-0.482587395190051
303.20000000000357,35.94853440078084,0.4602303182196985,-0.49577618518511724
304.4000000000036,36.06490474972148,0.4660113828715482,-0.5103637057475052
305.60000000000366,36.17990738870268,0.46685684230770547,-0.5249463892737385
306.80000000000365,36.29538154341499,0.4713532817550453,-0.5408939979512288
308.00000000000364,36.408948980551884,0.47634473031551766,-0.5549396428437983
309.2000000000037,36.52377410947151,0.4815957820764902,-0.5722642188176792
310.40000000000373,36.63933455031006,0.4879159497849683,-0.5899235274510661
311.6000000000037,36.75527178473348,0.49459771402726005,-0.6062125343369233
312.8000000000037,36.87081273339555,0.5007735966605773,-0.623755023202285
314.00000000000375,36.98540755156972,0.5075330022559331,-0.6413717059227144
315.2000000000038,37.10111619486887,0.5153795246204055,-0.6593311295384376
316.4000000000038,37.217309516639844,0.524872379845488,-0.6797596821854222
317.6000000000038,37.33281130449211,0.5349003619342254,-0.6962870949265878
318.8000000000038,37.44855340109657,0.5464475618303022,-0.7191995037588872
320.00000000000387,37.564063709054786,0.5597981612198012,-0.7410856686422655
321.20000000000385,37.679695800149155,0.5715400075282062,-0.7634562165360625
322.40000000000384,37.7953916030018,0.5855464277923506,-0.7854016394041357
323.6000000000039,37.91094256905177,0.602192215096969,-0.8113107273963074
324.80000000000393,38.02647927619413,0.6182015665737094,-0.8375381787422747
326.0000000000039,38.14205606075733,0.6360673586432559,-0.8649015412618053
327.2000000000039,38.25882722041157,0.6604107730014996,-0.893475240496644
328.40000000000396,38.374481322202456,0.6806060414274603,-0.923283791369955
329.600000000004,38.490093666439165,0.7065354569756751,-0.9555745139199434
330.800000000004,38.60532696562119,0.7336491101881722,-0.9918768900009063
332.000000000004,38.7224977029015,0.7614113601417645,-1.0296441771408413
333.200000000004,38.836774300856554,0.7902529585167458,-1.06823691511714
334.40000000000407,38.95369816684132,0.8184306050383587,-1.1115551234572973
335.60000000000406,39.070094947107336,0.8476848790386237,-1.1582112397812367
336.80000000000405,39.18531087726108,0.8719153406133807,-1.2075797723066022
338.0000000000041,39.30135307555472,0.894938439591952,-1.2604335006980807
339.20000000000414,39.417231510565756,0.9066858262979886,-1.3168874587756565
340.4000000000041,39.53290524041921,0.9070777799895601,-1.3742112125658896
341.6000000000041,39.649814234221566,0.8953191187323416,-1.4356872554116675
342.80000000000416,39.76471626656628,0.8656531876233611,-1.4969808606319295
344.0000000000042,39.88051498493416,0.811207965175638,-1.560777550328162
345.2000000000042,39.99659343349953,0.7380525514816374,-1.6211432814063875
346.4000000000042,40.11135274934108,0.65483224713447,-1.6797348547509978
347.60000000000423,40.227790818876684,0.5730949858555372,-1.7335660989965485
348.8000000000043,40.343531146178776,0.4999038811023226,-1.7825631665404287
350.00000000000426,40.45784846748642,0.4405770514769993,-1.8263363232583636
351.20000000000425,40.57342024613865,0.3884009197426698,-1.8659308529404774
352.4000000000043,40.688819897971996,0.34716744740786387,-1.899700803109643
353.60000000000434,40.80439078622393,0.31429921675291417,-1.9293312879877722
354.80000000000433,40.920480767970325,0.286721241471786,-1.9559456913768072
356.0000000000043,41.0374864737803,0.26401545441027097,-1.9786426658512353
357.20000000000437,41.15319318682204,0.24740562536027846,-1.9998054710469217
358.4000000000044,41.26963016646525,0.23377841293972396,-2.0181024267610024
359.6000000000044,41.38727813458891,0.22289255247289713,-2.0356093050045843
360.8000000000044,41.503813263264924,0.21522800525321417,-2.051323712281898
362.00000000000443,41.62188171594197,0.21019598180070265,-2.0681684655537014
363.2000000000045,41.739243337960005,0.2076514879066674,-2.0809702641407015
364.40000000000447,41.85632300193419,0.203140752963752,-2.0944840136538114
365.60000000000446,41.97284629315836,0.20140231939054176,-2.1068089777190395
366.8000000000045,42.09076127242361,0.20004158925669296,-2.120959625515657
368.00000000000455,42.20782614704116,0.2004571085832734,-2.1348765561967316
369.20000000000454,42.326455377500324,0.20113616040448892,-2.14983102399352
370.4000000000045,42.44286624646343,0.2003476279459987,-2.1600205175192575
371.60000000000457,42.56057312678744,0.19910217386621912,-2.1740600255593505
372.8000000000046,42.67811973738191,0.1983400123375256,-2.1859467399126244
374.0000000000046,42.79419291812855,0.19985425757767278,-2.199145618815251
375.2000000000046,42.911746495678514,0.20034564241757044,-2.2123353481709787
376.40000000000464,43.02786119562581,0.1991107813400645,-2.224006880633585
377.6000000000047,43.1447924016295,0.19751305620608256,-2.2379665125672434
378.8000000000047,43.26118903552054,0.200284536867063,-2.252351316123007
380.00000000000466,43.37795619728855,0.19919330228405513,-2.2631872089963263
381.2000000000047,43.49381860522696,0.19746780136727032,-2.2793989886748665
382.40000000000475,43.61096102501198,0.1988784589534479,-2.2927341833667287
383.60000000000474,43.72801244648129,0.19566449765917182,-2.3042660252913993
384.80000000000473,43.84513360304943,0.19661015300005058,-2.3167594644411835
386.0000000000048,43.96239648765056,0.19493247501020483,-2.329930917071227
387.2000000000048,44.079536349497495,0.195543591219073,-2.34259623920014
388.4000000000048,44.19516520438948,0.1917983485062681,-2.3580025461543492
389.6000000000048,44.31194027715595,0.19170090426835812,-2.3721099455403514
390.80000000000484,44.429455268724595,0.1867421857229758,-2.386685052960213
392.0000000000049,44.546113741386904,0.18893554699838866,-2.4001278885808617
393.2000000000049,44.66306309530056,0.1900726354666345,-2.4150859738120616
394.40000000000487,44.77960245792919,0.19060866488821987,-2.429483028616213
395.6000000000049,44.89695403561603,0.18495620420843573,-2.4428624082399084
396.80000000000496,45.013287648758514,0.18599578240768821,-2.4587753152989915
398.00000000000495,45.130364291976115,0.18663865179287442,-2.4729165514545093
399.20000000000493,45.24708751400325,0.18471427411955382,-2.4883380195012954
400.400000000005,45.36499252453913,0.18412922055998798,-2.5048596724714596
401.600000000005,45.481568756955234,0.18529322469229365,-2.519752276643425
402.800000000005,45.599455778075324,0.18568502773181733,-2.536898718964802
404.000000000005,45.71595638418182,0.18736274054445945,-2.5527110190443363
405.20000000000505,45.833565470072934,0.18631235784165973,-2.5703121025309414
406.4000000000051,45.949466601245675,0.18588776943903756,-2.584580357099957
407.6000000000051,46.06844530969925,0.18880770157815774,-2.603864978048703
408.80000000000507,46.18534380393504,0.19250958593895945,-2.6210516636960173
410.0000000000051,46.30292726591233,0.19336169493432576,-2.6383149544140645
411.20000000000516,46.41841524876697,0.19097358134790515,-2.655060163119194
412.40000000000515,46.537086334053996,0.19289498686177758,-2.6718976135916845
413.60000000000514,46.65464194042313,0.19277978887288721,-2.6900820393303917
414.8000000000052,46.772161241354716,0.19192915500850888,-2.7075917634613056
416.00000000000523,46.88919785547251,0.19540101799712228,-2.7260183611789794
417.2000000000052,47.00747651395695,0.19308704066115628,-2.7433066861978688
418.4000000000052,47.12522527431866,0.19439833193677641,-2.7608115197607894
419.60000000000525,47.24186080325515,0.19354965749108355,-2.7768301495306655
420.8000000000053,47.35878181727704,0.19321655244999847,-2.79422759563771
422.0000000000053,47.47685065424675,0.19588164314100315,-2.8100663145298537
423.2000000000053,47.59362485635503,0.19702320946401336,-2.8261567499205533
424.4000000000053,47.71184873915427,0.1963816566705125,-2.841669634110029
425.60000000000537,47.82946448264811,0.19478917039111993,-2.856626013534911
426.80000000000535,47.94359061457706,0.19516770859261384,-2.8713375181838954
428.00000000000534,48.065023917185044,0.19909595646639705,-2.886662402266773
429.2000000000054,48.182936664334385,0.19551040211043175,-2.901604914561304
430.40000000000543,48.29973316243805,0.19426231700898983,-2.914991859689818
431.6000000000054,48.417515496843826,0.1912851798270891,-2.9299831140057444
432.8000000000054,48.534836334572724,0.1886909874241054,-2.94175699663319
434.00000000000546,48.65140155210166,0.188968993713861,-2.954643254930458
435.2000000000055,48.77019434994694,0.1851336184848179,-2.9679147959380847
436.4000000000055,48.886710662952986,0.18375076159269005,-2.978811443259197
437.6000000000055,49.0034572867422,0.18261754410451048,-2.991971292801813
438.8000000000055,49.121059809425,0.1786717391542318,-3.002346823552516
440.00000000000557,49.23812636252848,0.17244229287245016,-3.013562386070426
441.20000000000556,49.35527636329982,0.16742544279263644,-3.0215526134302615
442.40000000000555,49.47232001704185,0.16203034905518487,-3.034325182074072
443.6000000000056,49.590287273040154,0.15784880664364032,-3.0462222416843883
444.80000000000564,49.70796308382649,0.14834167004668408,-3.0542684550051855
446.0000000000056,49.82506998774721,0.14308470325622824,-3.0655445505631027
447.2000000000056,49.94312139092929,0.1358583851548794,-3.0729393186569993
448.40000000000566,50.061350578349725,0.12963370539005203,-3.082360034595796
449.6000000000057,50.17917367325584,0.12393057570748722,-3.0902951217266823
450.8000000000057,50.297453246433854,0.11170699721340754,-3.0985808825100456
452.0000000000057,50.41317029226989,0.10861103330368471,-3.1046803491579196
453.20000000000573,50.53244495891568,0.10276820917492241,-3.1111587543586823
454.4000000000058,50.650001020433265,0.09334878613749925,-3.1192465661051454
455.60000000000576,50.76636520705045,0.08885062805875549,-3.1244384132284635
456.80000000000575,50.884565506457015,0.08490026913262266,-3.1301294830442297
458.0000000000058,51.002836190223434,0.0792014889574228,-3.1357137651866784
459.20000000000584,51.12086382319656,0.07358874144284444,-3.140252712098097
460.40000000000583,51.239253235156085,0.0686783675769298,-3.1451793133634007
461.6000000000058,51.35625104504288,0.06617660741289944,-3.150756555380845
462.80000000000587,51.47446701408228,0.06537597436588055,-3.154964903522842
464.0000000000059,51.59260329241255,0.06213327995997675,-3.159497163416413
465.2000000000059,51.71131842434965,0.05938734294467318,-3.1637691250790856
466.4000000000059,51.83000095503227,0.05616924668850476,-3.167839877226072
467.60000000000593,51.94753655197967,0.055879852394187524,-3.171603932445386
468.800000000006,52.06585866455502,0.05335800785933459,-3.1730079233903163
470.00000000000597,52.183968112862374,0.04842199223765209,-3.1776902896387336
471.20000000000596,52.303108470386654,0.04933099187181689,-3.1802192228949533
472.400000000006,52.42173916082178,0.04401596807544095,-3.1828789979187384
473.60000000000605,52.53980651457343,0.043008286568810394,-3.1855117573626055
474.80000000000604,52.659794706812505,0.04346169175738934,-3.1883601961679977
476.000000000006,52.77737866738252,0.04075158427741632,-3.1909760321499743
477.20000000000607,52.89618332898447,0.04176769596523844,-3.193764739770418
478.4000000000061,53.01455581079125,0.04071825116749306,-3.1964002462419123
479.6000000000061,53.13356031499845,0.03863376111976602,-3.1990874672505827
480.8000000000061,53.25191290084534,0.04064279217146216,-3.2017378623474984
482.00000000000614,53.370210047483425,0.038247997311882664,-3.204047180895072
483.2000000000062,53.48652287818733,0.0405516750613405,-3.2053707038089705
484.4000000000062,53.60426107710918,0.039437086105380104,-3.2076783474405755
485.60000000000616,53.72569674773221,0.040067819594610476,-3.210581001419755
486.8000000000062,53.84381282667454,0.046288518103659304,-3.211953873604303
488.00000000000625,53.96222077537245,0.04511375820080099,-3.2135751249932625
489.20000000000624,54.08021054033038,0.04303430746992365,-3.2135882826144493
490.40000000000623,54.19989419080877,0.04963763669220178,-3.2169017927630104
491.6000000000063,54.318592688830854,0.04765881936964855,-3.2185017786109613
492.8000000000063,54.43664588531991,0.05082557850681246,-3.2212167636027984
494.0000000000063,54.55528008007135,0.05128961855007974,-3.222470144703424
495.2000000000063,54.67306525145796,0.05123297907272739,-3.223800063699927
496.40000000000634,54.791340318219476,0.0541664921620727,-3.2264265559310283
497.6000000000064,54.91057731806493,0.05588971586053204,-3.2277550848159233
498.8000000000064,55.02876268990275,0.05728245831765444,-3.229621778199771
500.00000000000637,55.147722451310464,0.05390926161459775,-3.230652798804609
501.2000000000064,55.265016440015195,0.056468098875163464,-3.2330893110565277
502.40000000000646,55.38515615722753,0.055626479255557415,-3.2358190485604013
503.60000000000645,55.50355520069324,0.05417655296015378,-3.234383520118321
504.80000000000643,55.62230891123582,0.054857830007218666,-3.238087841319369
506.0000000000065,55.74166451882994,0.055321042633971196,-3.239470348156401
507.2000000000065,55.860601611691905,0.05700207819751546,-3.2412249487350517
508.4000000000065,55.97905415804722,0.054588333452002424,-3.243446453938672
509.6000000000065,56.09766865377508,0.0533255770761506,-3.243875079432141
510.80000000000655,56.216090491229686,0.054348834511001254,-3.245163688918609
512.0000000000066,56.33448827141167,0.05132742563115422,-3.2465001781098213
513.2000000000066,56.452897528745105,0.051469720180551626,-3.247808409119483
514.4000000000066,56.57152891582001,0.05120432484400239,-3.2491302890013034
515.6000000000066,56.68843800838771,0.05117211078396633,-3.2504500939786625
516.8000000000067,56.80931650096974,0.05191458101101187,-3.25175863689787
518.0000000000066,56.927855492887055,0.047352213685965316,-3.253867544763718
519.2000000000066,57.04679018880672,0.048138329547314895,-3.2539757827574056
520.4000000000067,57.16536823193451,0.04501002355699735,-3.255049380423381
521.6000000000067,57.283756458066826,0.046340000312125484,-3.2564261136556807
522.8000000000068,57.40309258108026,0.04519320262071069,-3.2577229414385105
524.0000000000067,57.52209284481848,0.042824507897632924,-3.258999949534709
525.2000000000068,57.639899640531326,0.04547744026065159,-3.2603203167118617
526.4000000000068,57.7592718194133,0.04538901798519723,-3.2616352214779267
527.6000000000067,57.87873015493927,0.04176479714958525,-3.262964045279831
528.8000000000068,57.9966962240884,0.039949522052787234,-3.265579938394829
530.0000000000068,58.11674976416065,0.03941948472977497,-3.2669317931534376
531.2000000000069,58.23583996184129,0.03679149862147291,-3.2675314865256193
532.4000000000069,58.35552669667932,0.037449500315702045,-3.266311987415543
533.6000000000068,58.47426694068498,0.037179441188218254,-3.2688697125473007
534.8000000000069,58.593652137155935,0.03533590281252519,-3.2713958069384557
536.0000000000069,58.71335651248034,0.03555644014900072,-3.2715094382637626
537.2000000000069,58.832664184337666,0.036093239570483826,-3.2728150440520274
538.4000000000069,58.95268889950337,0.03755036622828112,-3.272865657745534
539.600000000007,59.0718836005022,0.03722827447273258,-3.2754485904450377
540.800000000007,59.190625306201234,0.034033708518127814,-3.2754540994449313
542.000000000007,59.30980590469394,0.03387532895559575,-3.2776994688531906
543.200000000007,59.42894914843202,0.03265246260867427,-3.2780795166241696
544.400000000007,59.54835198583351,0.0315594897401118,-3.2794144998916295
545.6000000000071,59.667826652069024,0.03251997586358524,-3.2800600945173137
546.800000000007,59.78731447650177,0.031845618064812675,-3.2799595655932627
548.000000000007,59.906800367433036,0.031999365564533755,-3.2839059926799106
549.2000000000071,60.02689036171616,0.03314315464652129,-3.282672509954753
550.4000000000071,60.14659152938784,0.03516103293365902,-3.284040145046297
551.6000000000072,60.266835138237326,0.030937786759685615,-3.286638487163697
552.8000000000071,60.38539381659423,0.032122826790862535,-3.2866360136115444
554.0000000000072,60.50515347990576,0.03147874661031702,-3.287960898590251
555.2000000000072,60.62453935101537,0.032888658480250244,-3.289270018630029
556.4000000000071,60.7434241216874,0.0320835737152011,-3.2899365999654053
557.6000000000072,60.86380075489327,0.032040949847319866,-3.291250012681167
558.8000000000072,60.98340794965292,0.0309532433651174,-3.292559918158841
560.0000000000073,61.103302762685814,0.03122133317883724,-3.2927159922148013
561.2000000000073,61.22274199656161,0.02915358315883454,-3.2952692815671716
562.4000000000073,61.34319793877922,0.030848747871512705,-3.2947381180957294
563.6000000000073,61.46227083014404,0.0321400484288068,-3.2972109076068943
564.8000000000073,61.58284769435112,0.029271972659309475,-3.2974995895975017
566.0000000000073,61.7018201818368,0.03351039411712586,-3.2971646543518474
567.2000000000073,61.82306487672956,0.03135760404610133,-3.297762174525989
568.4000000000074,61.94302165353118,0.03407146320445276,-3.2985915720631125
569.6000000000074,62.06295866029368,0.03240415435844757,-3.3009894061174903
570.8000000000075,62.183244389969595,0.03307182991553126,-3.3022099560799134
572.0000000000074,62.30279217130013,0.033121394917971836,-3.3033628090067877
573.2000000000074,62.423006266860426,0.030158755950449145,-3.3035313272079003
574.4000000000075,62.54242367113651,0.034706215297442666,-3.303530053994842
575.6000000000074,62.664315046584555,0.031306141089045836,-3.3055020447988657
576.8000000000075,62.78406644063689,0.030796574864317416,-3.3068258408486657
578.0000000000075,62.904773228241524,0.02824541542817538,-3.307172652822678
579.2000000000075,63.024108487980634,0.024923973645981534,-3.3081374248993747
580.4000000000076,63.1444129094995,0.022229339116854985,-3.3094600321552106
581.6000000000075,63.26330396839996,0.01944546317147522,-3.310757082486443
582.8000000000076,63.38399489710714,0.01844842751275233,-3.312094908887598
584.0000000000076,63.5032352343479,0.014614944251027051,-3.313445956002052
585.2000000000075,63.62187875922205,0.015438271179130658,-3.3144216267180053
586.4000000000076,63.741831891500794,0.008051472393727055,-3.3149009837811616
587.6000000000076,63.862768115915955,0.007002130335660661,-3.3157000898115143
588.8000000000077,63.98169326692395,0.0066032398868209885,-3.317020746761746
590.0000000000077,64.10273590245518,0.004329741113429875,-3.3196290051906625
591.2000000000077,64.2217122900284,0.005648422579013657,-3.32097103827048
592.4000000000077,64.34182976915343,0.0019966748501732967,-3.3213046779226176
593.6000000000078,64.46245449141263,0.0025617575593673836,-3.322290147705068
594.8000000000077,64.58147465949152,-0.0015057795288379028,-3.3232691616210595
596.0000000000077,64.70280413359528,-0.0017314911894109608,-3.324922109099114
597.2000000000078,64.8212006958449,0.00033646266933495816,-3.326237200610991
598.4000000000078,64.942437448044,-0.0030410961449032214,-3.326235512565998
599.6000000000079,65.06267119181238,-0.0034500403204341668,-3.3288712012879134
600.8000000000078,65.18278483758391,-0.001484798265819376,-3.327821837344057
602.0000000000078,65.30346249011757,0.0015031049275037178,-3.3288321020282488
603.2000000000079,65.42417203094143,0.00044466354408279063,-3.330562331205856
604.4000000000078,65.54412175974637,0.003211320145201202,-3.331830094102593
605.6000000000079,65.66527007640454,0.0031238609578545518,-3.333140024519468
606.8000000000079,65.78491129916696,0.009693385098120455,-3.3344565501990346
608.000000000008,65.90505700303032,0.0072084079867883455,-3.3358182437863695
609.200000000008,66.02532501161225,0.010052039083981223,-3.3357726201099944
610.4000000000079,66.14583958224877,0.014925011389767429,-3.336234876252847
611.600000000008,66.2659180230725,0.01909521089426014,-3.337430126632465
612.800000000008,66.38478475707313,0.019379294661149293,-3.3371005316117452
614.000000000008,66.50521155229065,0.022019170500859664,-3.3384099982954165
615.200000000008,66.62481859885392,0.026730088603652558,-3.339733750423526
616.400000000008,66.7439941288889,0.027946921223083176,-3.339932795585825
617.6000000000081,66.86381380826846,0.0323311451129944,-3.3397302511607285
618.8000000000081,66.9848042909149,0.03015558849208788,-3.3413670422850217
620.0000000000081,67.10527296630465,0.032391815375545585,-3.3428544892200884
621.2000000000081,67.22547903030546,0.03474949766477886,-3.3423598100518923
622.4000000000082,67.34584994094035,0.03420347280997471,-3.341416536832761
623.6000000000081,67.4666021052792,0.03137357964622045,-3.3433954428394026
624.8000000000081,67.58754814015342,0.03707746339344409,-3.3446594717798313
626.0000000000082,67.70733974541629,0.03617317119151764,-3.345980154722155
627.2000000000082,67.82714815416544,0.029070147999695983,-3.3459801600001073
628.4000000000083,67.94782434851669,0.037172846599186515,-3.345982176902286
629.6000000000082,68.06874935354102,0.032903197663775474,-3.3459796853323516
630.8000000000083,68.18970764721689,0.0310648662051749,-3.3472988897993763
632.0000000000083,68.30949702024594,0.029588480226942604,-3.3472973819295175
633.2000000000082,68.43044306010977,0.030068602633497088,-3.347630063655942
634.4000000000083,68.55096519548852,0.027509117388528015,-3.347723953011676
635.6000000000083,68.67205243202572,0.0299692128832183,-3.349160775653556
636.8000000000084,68.79179278803028,0.029416723281130874,-3.349752559732779
638.0000000000084,68.91280822561707,0.027797174152469406,-3.351580779396678
639.2000000000083,69.03293650771207,0.03153546902903237,-3.351240148984817
640.4000000000084,69.15294755010815,0.02898893550107462,-3.3512404935449123
641.6000000000084,69.27291415607733,0.031324551103443676,-3.3517022686683986
642.8000000000084,69.39366698813521,0.030017548717736542,-3.3528899901069553
644.0000000000084,69.5144313126814,0.03224742750811593,-3.3528862635074623
645.2000000000085,69.63531534271975,0.03205778366143197,-3.3528338518729486
646.4000000000085,69.75558009687822,0.031081081556975976,-3.3545422166594765
647.6000000000085,69.87671078733702,0.03243090399411552,-3.354530140000316
648.8000000000085,69.99768994577956,0.0324028033396091,-3.3545290261890313
650.0000000000085,70.11794152309142,0.033073825731265494,-3.354529839727753
651.2000000000086,70.23821686042822,0.03374412012703121,-3.354859666780059
652.4000000000085,70.3593621671662,0.032493858661321706,-3.355860136260101
653.6000000000085,70.47968666530582,0.030573936277804137,-3.355860129999993
654.8000000000086,70.60143346703737,0.03314446557371831,-3.3558604386109083
656.0000000000086,70.72077495558952,0.030405748527284615,-3.357170085776235
657.2000000000087,70.84292609669363,0.029348736697788924,-3.3584968267846196
658.4000000000086,70.96328462970632,0.027554575318907037,-3.3591401934866862
659.6000000000087,71.08281834153418,0.0316762197377638,-3.3591396794873853
660.8000000000087,71.20455843610041,0.02884825966048221,-3.359141451030059
662.0000000000086,71.32536396249397,0.028392738013617524,-3.3591605009518593
663.2000000000087,71.44538980250942,0.0309658187977071,-3.361120269077085
664.4000000000087,71.56530255947143,0.03497976745055409,-3.361116985795756
665.6000000000088,71.68616802294267,0.02956149547329301,-3.3611199171952744
666.8000000000088,71.8063877548621,0.034495367337934235,-3.3611209931504336
668.0000000000088,71.9265312028013,0.03184353951380481,-3.3624354234933844
669.2000000000088,72.04755168861608,0.03329693584965687,-3.3617701913216163
670.4000000000088,72.16691422303826,0.028942022320521232,-3.361770168436202
671.6000000000088,72.28739781241214,0.03258513614780312,-3.363089157024386
672.8000000000088,72.40739137670215,0.032021888857574066,-3.3630899600106585
674.0000000000089,72.52823974991517,0.03154648003591354,-3.3633449804445155
675.2000000000089,72.6492006526578,0.03245787682512424,-3.3643999104414686
676.400000000009,72.76915759870916,0.03160928675671415,-3.3636808373274154
677.6000000000089,72.8900929432541,0.03272999533048937,-3.3650653220238147
678.8000000000089,73.01021062129168,0.032479427023030194,-3.3644101088449148
680.000000000009,73.13148098596342,0.030442158119560414,-3.363750702385963
681.2000000000089,73.25239075603045,0.032281368181169556,-3.3650699695191726
682.400000000009,73.37226821555592,0.02986755802786467,-3.366499428723805
683.600000000009,73.49378959032583,0.034277544396008164,-3.3657381783157763
684.800000000009,73.61481600130452,0.031810811338252254,-3.3670678935996436
686.0000000000091,73.73591468486725,0.03433815535819207,-3.3680048033206877
687.200000000009,73.85708606413496,0.03205738134603919,-3.367055176274523
688.4000000000091,73.97927980993495,0.02862012441765982,-3.36836096694495
689.6000000000091,74.09960750902978,0.029420823730250012,-3.3670494177238823
690.800000000009,74.22103713498943,0.02879481985035981,-3.3696695782745394
692.0000000000091,74.34271878814792,0.03292801413233959,-3.3696662136942273
693.2000000000091,74.46429270874806,0.028537315362725302,-3.3683507995762207
694.4000000000092,74.58520491597413,0.027010790839582244,-3.3682849229539764
695.6000000000092,74.70702106992647,0.024228922634860428,-3.370610696643125
696.8000000000092,74.82795705892309,0.02693768218138004,-3.371970039839455
698.0000000000092,74.94915117989183,0.02456209884359417,-3.3719703729044452
699.2000000000093,75.06999887170326,0.02628186265970589,-3.3706620524986524
700.4000000000092,75.1926382052577,0.026370992755526235,-3.3732903654390487
701.6000000000092,75.31237423371617,0.026288383385944414,-3.3732898296280918
702.8000000000093,75.432616463984,0.024411013639145995,-3.3739448085127233
704.0000000000093,75.55266173062535,0.02518950100872841,-3.372923258433184
705.2000000000094,75.67399466956788,0.02191507529986958,-3.375263298250652
706.4000000000093,75.79482813632657,0.021592336650889,-3.374855233236441
707.6000000000093,75.91540245134402,0.02578284048857582,-3.373632623248714
708.8000000000094,76.03617124916188,0.026379314433847334,-3.374956917981046
710.0000000000093,76.15713047044038,0.019440820778461765,-3.376129153634267
711.2000000000094,76.2772623819696,0.017896819874936076,-3.3749409161505257
712.4000000000094,76.39780038847263,0.019230886691014026,-3.374939874173403
713.6000000000095,76.52051743884697,0.015087980723381245,-3.3772405280746023
714.8000000000095,76.6414058456803,0.014890952099545052,-3.37723981999999
716.0000000000094,76.76251934632636,0.008158713647503424,-3.3772346548365277
717.2000000000095,76.88098375274575,0.008894991922804518,-3.375919819744645
718.4000000000095,77.00642308855275,0.007804772047347752,-3.3759330406209536
719.6000000000095,77.12704666267484,0.005355394849532846,-3.376931390823776
720.8000000000095,77.24938408827035,0.00840893796240727,-3.3779012212480404
722.0000000000095,77.37116957110392,0.0001738848986296837,-3.3792100961282032
723.2000000000096,77.49321499299246,0.0005448767516282871,-3.379183861661403
724.4000000000096,77.61540060513117,0.0027362103259955806,-3.377904454207658
725.6000000000096,77.73842774724135,0.006971511572392064,-3.3779001732868927
726.8000000000096,77.85853411158755,0.005020010769555494,-3.37922295129602
728.0000000000097,77.98077506243096,0.006574627204894989,-3.3808718244619316
729.2000000000096,78.10325279494289,0.0010368894924941419,-3.379880846328772
730.4000000000096,78.22481331313277,-0.0016866171289937615,-3.380529904105507
731.6000000000097,78.34620204127084,-0.005358356053203561,-3.3805299499839796
732.8000000000097,78.46671351382862,-0.00243634988423147,-3.3792099408378746
734.0000000000098,78.5867397118974,-0.005101472852921951,-3.3804997732193747
735.2000000000097,78.71047767738487,-0.007517673641494582,-3.380531763388323
736.4000000000098,78.83298456161256,-0.006560300467742808,-3.3805450758403737
737.6000000000098,78.95462491643379,-0.009057889690033516,-3.381849900301487
738.8000000000097,79.0755652726362,-0.009987306830171017,-3.3818499448568677
740.0000000000098,79.1959524074413,-0.006508194376711796,-3.3818398901158373
741.2000000000098,79.31766496835479,-0.0072094063111203255,-3.3831603425730488
742.4000000000099,79.4390408710411,-0.007329573693021674,-3.382169915277842
743.6000000000099,79.56084655345428,-0.005837266136308639,-3.382183065547464
744.8000000000098,79.6817542690401,-0.00860620463321915,-3.382168932778375
746.0000000000099,79.80313627860849,-0.004506276122091091,-3.3835582758275433
747.2000000000099,79.92505795134377,-0.007275166640946074,-3.3821800655923884
748.4000000000099,80.04552040621049,-0.009922397539490646,-3.384146950871405
749.6000000000099,80.16864828739737,-0.009038064245064925,-3.3828107479532585
750.80000000001,80.29000101803207,-0.00852964215230223,-3.384148740753468
752.00000000001,80.41166879652522,-0.009470952265101973,-3.3854257966602126
753.20000000001,80.53444881182301,-0.012431322028172875,-3.3843776184055736
754.40000000001,80.65595251700819,-0.012228008981665095,-3.385767440453484
755.60000000001,80.77685226384602,-0.018591354501731105,-3.3864717553696493
756.8000000000101,80.89847175326051,-0.014805176412812981,-3.385140039840298
758.00000000001,81.02068007550228,-0.007405323508381523,-3.3858321346291858
759.20000000001,81.14181585204197,-0.014326435687720185,-3.38611993473134
760.4000000000101,81.26248714936281,-0.01684661746215621,-3.3877714019293506
761.6000000000101,81.38363308403575,-0.019382167505100023,-3.386659016326574
762.8000000000102,81.50585274417557,-0.0199331458732821,-3.386450374153691
764.0000000000101,81.62637103214244,-0.019540948381424617,-3.387807304702295
765.2000000000102,81.74881835242297,-0.014108649369753534,-3.3877601217364397
766.4000000000102,81.87050130627117,-0.02109228232712601,-3.3890870563676456
767.6000000000101,81.99246434885613,-0.01986940484508004,-3.3888481111098394
768.8000000000102,82.1139604032956,-0.02169548039062552,-3.3890799299860683
770.0000000000102,82.23576975502709,-0.02001231354062427,-3.3890787704328798
771.2000000000103,82.35756317213176,-0.020070256806141273,-3.389945321179763
772.4000000000103,82.48050798820671,-0.020820225015483862,-3.390400204780592
773.6000000000103,82.60202450846312,-0.019679693544320198,-3.3897450112968386
774.8000000000103,82.72409408655594,-0.02105026725513448,-3.391061830503082
776.0000000000103,82.84663312957933,-0.01906593815754709,-3.390352317961554
777.2000000000103,82.96869038918352,-0.02613888741621828,-3.391727676297377
778.4000000000103,83.09050680187597,-0.026451287876279483,-3.3894548496581987
779.6000000000104,83.21231446141039,-0.028865088599663302,-3.3903997335209057
780.8000000000104,83.33413524681528,-0.027056748781800977,-3.3917200091130506
782.0000000000105,83.45542602800595,-0.025740843806423497,-3.3917200699999928
783.2000000000104,83.57593478744607,-0.030042669251375997,-3.3917200699922367
784.4000000000104,83.6984585508764,-0.030911303946780322,-3.3916838034342884
785.6000000000105,83.82028710568467,-0.0289435768064199,-3.3930300188609674
786.8000000000104,83.94232260226921,-0.03002359501718299,-3.391347336389108
788.0000000000105,84.06352508657976,-0.03467356685271494,-3.3936374951843464
789.2000000000105,84.18425402532282,-0.039281421171305286,-3.3920403985784517
790.4000000000106,84.30656544612047,-0.04059269489843165,-3.393039811308506
791.6000000000106,84.42850097627873,-0.036811448868639296,-3.39171971158203
792.8000000000105,84.54981405260091,-0.036869643215483805,-3.394375684272668
794.0000000000106,84.67298910787721,-0.03909577900620098,-3.3917461053344162
795.2000000000106,84.79478256545953,-0.037102260502240636,-3.3941607219958723
796.4000000000106,84.91753068886908,-0.039289566990764246,-3.39302297437043
797.0000000000106,84.97570536351525,-0.03848411236689264,-3.394348094152969