File: 01_Data/Bamboo_Rug_Fabric/STA/N2/10K_min/Bamboo_Rug_Fabric_STA_N2_10KData_220124_R1.csv
##Temp./Â°C,Time/min,DSC/(mW/mg),Mass loss/mg
50.0,10.79719091241804,0.06623382288358559,-0.01344355446831269
51.20000000000002,11.096046916896752,0.10545517179769814,-0.013703847306374861
52.400000000000034,11.312964503125068,0.13371349756427853,-0.014648115030548858
53.60000000000005,11.49732800798898,0.155212576570408,-0.014776284558820407
54.80000000000007,11.66163213667738,0.17197615437998648,-0.015948845372688147
56.000000000000085,11.8173357699103,0.1831719729010166,-0.015627994230969833
57.2000000000001,11.966985176708624,0.19612155778817164,-0.016530495114239763
58.40000000000012,12.107670797148183,0.2054994627347514,-0.015248068962118388
59.600000000000136,12.246463251225876,0.21598099658764303,-0.014889959546033005
60.80000000000015,12.384917652765303,0.22082673553727117,-0.01584979930137198
62.00000000000017,12.518527365459695,0.22785669018436205,-0.016354873354095467
63.20000000000019,12.651608894541516,0.23378962954025762,-0.017542491749209077
64.4000000000002,12.783471399883094,0.23951700245431196,-0.016240445355683697
65.60000000000022,12.914225562682581,0.2453847006915959,-0.017556980512917875
66.80000000000024,13.045851604651373,0.24949340450541935,-0.018858655487173692
68.00000000000026,13.17520579265897,0.2525400052710427,-0.01974318505868311
69.20000000000027,13.30408789371413,0.25273837635058266,-0.018190478642766017
70.40000000000029,13.43236850176909,0.25255376614517683,-0.020268847836001136
71.6000000000003,13.553695937135382,0.25421060110802174,-0.018972995997653008
72.80000000000032,13.688830789953213,0.2551556629047036,-0.0202901848531436
74.00000000000034,13.814948288758616,0.2572432231635016,-0.01993308725717302
75.20000000000036,13.939535596056984,0.25738711714375284,-0.01979700643399962
76.40000000000038,14.06618904773837,0.26185092316306124,-0.018980842380865504
77.60000000000039,14.191015041087159,0.26162063671303576,-0.02147168475228156
78.80000000000041,14.316006025658508,0.2658254942802521,-0.02291883118700433
80.00000000000043,14.441724913195824,0.2660675544958168,-0.021590715130127336
81.20000000000044,14.564019327548076,0.2678560573941202,-0.021604608968917027
82.40000000000046,14.68828948788018,0.2705716485794406,-0.02424566232329628
83.60000000000048,14.810088316515545,0.2728792825617485,-0.02291763225089749
84.8000000000005,14.932951178759604,0.27341027853068456,-0.022917978662827743
86.00000000000051,15.053190439935923,0.2736580003819726,-0.024386908745297475
87.20000000000053,15.174423245299757,0.2722432565057387,-0.024240026359183986
88.40000000000055,15.296301906261377,0.27379752517134853,-0.026964037031945054
89.60000000000056,15.41680081875966,0.275851068939505,-0.02554985749084082
90.80000000000058,15.535933601734191,0.2735911470118041,-0.02554083936182483
92.0000000000006,15.655169883282388,0.274969821613392,-0.026263605592185435
93.20000000000061,15.775413562681633,0.2754422626276703,-0.026850668731122518
94.40000000000063,15.89499451934906,0.2756008151593476,-0.0268693465339771
95.60000000000065,16.013914540819954,0.27598217182319373,-0.02689940743950814
96.80000000000067,16.131791833265787,0.27868032733286485,-0.02739109741186585
98.00000000000068,16.250249492415378,0.2781455418077033,-0.025327657215187926
99.2000000000007,16.36962197585384,0.277758854436778,-0.027969975078339537
100.40000000000072,16.486750608756847,0.27692272742724233,-0.027964221335200712
101.60000000000073,16.604341200217977,0.2766361291926938,-0.02799097001313111
102.80000000000075,16.723432197699573,0.2779988192768889,-0.02761252217521637
104.00000000000077,16.841167185013802,0.2755158629867735,-0.02659785875270604
105.20000000000078,16.95871007187986,0.2793908429109822,-0.02795900146879937
106.4000000000008,17.075330552392543,0.27769057136044145,-0.02796003200043451
107.60000000000082,17.194404630688297,0.27954521196495585,-0.0279642850312527
108.80000000000084,17.31159512149822,0.2812678743733069,-0.027969984996936148
110.00000000000085,17.428980234263637,0.281587240279939,-0.029289840925388333
111.20000000000087,17.545764473705677,0.2829099081493985,-0.028949832463908365
112.40000000000089,17.66220672700954,0.28111151967422304,-0.027989429665810306
113.6000000000009,17.781794251793954,0.2834751899390754,-0.029280255161451052
114.80000000000092,17.89887028341205,0.28297568782790217,-0.029308555903958755
116.00000000000094,18.016867771022486,0.28448114518911016,-0.029246191894824136
117.20000000000095,18.134634988229084,0.28736220178397487,-0.029279987253302053
118.40000000000097,18.25185177988058,0.28844738072349163,-0.028950945167995457
119.60000000000099,18.368639241009465,0.28979226811872993,-0.030270155984011282
120.800000000001,18.485567221240498,0.2923025787510559,-0.029292437938086557
122.00000000000102,18.602622825275585,0.29269775895202904,-0.029281694498852318
123.20000000000104,18.717708301182558,0.2955236409415216,-0.030601898651715587
124.40000000000106,18.835475583734997,0.296056421456616,-0.030602701882309624
125.60000000000107,18.952186984773615,0.29844698529928104,-0.030600089342086356
126.80000000000109,19.06826671150107,0.30101250778088096,-0.03191132783477446
128.0000000000011,19.18672004388191,0.29896883238636784,-0.030599869745682184
129.20000000000113,19.30215344781851,0.30006063963711355,-0.03194348567893801
130.40000000000114,19.419626617803576,0.30083292685218743,-0.029431742488278623
131.60000000000116,19.535466793162435,0.3030216390707721,-0.031479777323801805
132.80000000000118,19.651930513708347,0.3039533168042276,-0.03181003547805705
134.0000000000012,19.76730258681874,0.3055616759567321,-0.032790055481591196
135.2000000000012,19.8843110351411,0.3083279307063768,-0.03178959088275857
136.40000000000123,20.000950688650406,0.30861698578057034,-0.031927751112375446
137.60000000000124,20.115908382060915,0.30964060780431846,-0.031755186097418786
138.80000000000126,20.232292524037078,0.31234209981295624,-0.03311358152716348
140.00000000000128,20.34751629534955,0.3143029873346135,-0.033245606305739805
141.2000000000013,20.46420013304189,0.3134368552406318,-0.03317751431753546
142.4000000000013,20.578033839000042,0.314601326197013,-0.03378011580551288
143.60000000000133,20.693622122243394,0.3190356494970227,-0.0344125076262225
144.80000000000135,20.809762872470678,0.3213927596015506,-0.034439984009856595
146.00000000000136,20.92500076235284,0.31991266253643397,-0.03452220563578123
147.20000000000138,21.039800492825425,0.3203138400713389,-0.03411820741596561
148.4000000000014,21.15550060593541,0.32349139745389094,-0.03411064378327211
149.60000000000142,21.270472016172793,0.3283410303278627,-0.03576480042415575
150.80000000000143,21.38601585011378,0.32765860674479547,-0.035024082031243964
152.00000000000145,21.501190227306505,0.330142620163788,-0.03576001570024179
153.20000000000147,21.617273801519065,0.3308737238199609,-0.03576001599308487
154.40000000000148,21.73271195374957,0.33354483488201614,-0.03434288107972794
155.6000000000015,21.848271380664787,0.3364458854022303,-0.03575776206522452
156.80000000000152,21.96319106755482,0.33475124490553604,-0.03485231067216077
158.00000000000153,22.079170000000147,0.3385988135217669,-0.03575013598494703
159.20000000000155,22.19318633971573,0.3388693317231617,-0.03687127644198451
160.40000000000157,22.307490652894504,0.3425791142773384,-0.035774147440084114
161.6000000000016,22.424544103886536,0.3430655912439371,-0.03773019355774743
162.8000000000016,22.540016179100643,0.3444837041058777,-0.0377301919958164
164.00000000000162,22.653262299982632,0.34625611939940903,-0.03794939137402942
165.20000000000164,22.769077408014724,0.3461409789177993,-0.03774289790263197
166.40000000000165,22.885071501955764,0.3475367819738035,-0.03904988372161622
167.60000000000167,23.00002610288512,0.3494124621659199,-0.039395747863747665
168.8000000000017,23.114976378428143,0.3515387414679709,-0.03970990396702234
170.0000000000017,23.230193731503377,0.35470868404390965,-0.03970987621284561
171.20000000000172,23.344649447288173,0.3538171047978339,-0.04035990399910183
172.40000000000174,23.458694517101925,0.35549022325132784,-0.040281574780372864
173.60000000000176,23.573632930752474,0.358664064920539,-0.04036009754889758
174.80000000000177,23.68870905803187,0.3592209901014524,-0.04037018336235754
176.0000000000018,23.803661658219628,0.3594977126182566,-0.04037734344794064
177.2000000000018,23.91844429209913,0.36174422334689077,-0.042990027146940335
178.40000000000182,24.033540277807877,0.36379735552103826,-0.04299002399999985
179.60000000000184,24.148184393761667,0.3627133440712743,-0.04299002400083829
180.80000000000186,24.26303107140574,0.36451646572083485,-0.04300059792947053
182.00000000000188,24.378730642380507,0.36660649445304627,-0.044308865642101125
183.2000000000019,24.492920578404362,0.367895601870991,-0.04431001137755697
184.4000000000019,24.60826490258353,0.36790256589288034,-0.04562999655355249
185.60000000000193,24.723164255056417,0.3700384066789505,-0.044525856143172504
186.80000000000194,24.838100866806577,0.3729800598317602,-0.044970006207847746
188.00000000000196,24.952831902858534,0.3754943548941737,-0.04570006559073381
189.20000000000198,25.06730582963845,0.3780056199875862,-0.04760080938495559
190.400000000002,25.18243301289972,0.37774159269388197,-0.04628011756809247
191.600000000002,25.29621415253138,0.3778514829163132,-0.047600184696374725
192.80000000000203,25.411324887039935,0.380996092326338,-0.04759768999650582
194.00000000000205,25.525624844886725,0.38413627965783015,-0.04825989852483836
195.20000000000206,25.639819103311122,0.3846586324732485,-0.048259904001796805
196.40000000000208,25.753549823931387,0.3845054395839851,-0.04823107248795111
197.6000000000021,25.868786489204222,0.38938727484804647,-0.050290242746851455
198.80000000000211,25.982834018264896,0.39015558459056154,-0.05023994913200713
200.00000000000213,26.09655637776948,0.3914621615205525,-0.05090025869933967
201.20000000000215,26.211525954346072,0.3944312936820953,-0.05089008338492729
202.40000000000217,26.324825783590153,0.3948228249868172,-0.053189802558807564
203.60000000000218,26.439074782710204,0.3969694597312255,-0.05318980000000195
204.8000000000022,26.553656361517834,0.39963940966167133,-0.05318980001282192
206.00000000000222,26.667986188891565,0.401866029507562,-0.053186108636781526
207.20000000000223,26.78183171847848,0.4019171708483268,-0.05615837521659284
208.40000000000225,26.89668958237981,0.4030781465185207,-0.05640638831950007
209.60000000000227,27.010541362906903,0.4038776169164213,-0.05735489981465847
210.80000000000229,27.126246663242032,0.40754958619267334,-0.058054680994071184
212.0000000000023,27.240328204828927,0.4079585043817615,-0.060027637084805185
213.20000000000232,27.354278005814326,0.4075615093876794,-0.06000000853188592
214.40000000000234,27.470316238925843,0.4086749009241247,-0.061390766077483505
215.60000000000235,27.584149186541755,0.4118050130266043,-0.06394398905861642
216.80000000000237,27.699268263622855,0.41318928693542084,-0.06526022265714904
218.0000000000024,27.813473507882573,0.41476281824085415,-0.06513184617421341
219.2000000000024,27.929373739662918,0.4154223395115896,-0.06527010271545297
220.40000000000242,28.04338710180757,0.41913019711890076,-0.06759771992603802
221.60000000000244,28.158438546396873,0.42026855708683863,-0.06888006061701368
222.80000000000246,28.272715996416796,0.42462643782068954,-0.07018215884595946
224.00000000000247,28.388033877431386,0.42525975525359316,-0.07185296301128652
225.2000000000025,28.50280808627565,0.4288737060117314,-0.07413786349252316
226.4000000000025,28.61752229973974,0.42936332014406586,-0.07579189753322524
227.60000000000252,28.732394572118338,0.43214717743230535,-0.07604690108739387
228.80000000000254,28.847176890759606,0.4342242712407268,-0.0776661734264259
230.00000000000256,28.963192464430083,0.43786447876666723,-0.07977269956359034
231.20000000000258,29.07692192356254,0.44089636036945046,-0.08106346404516174
232.4000000000026,29.191723206863156,0.44502185051287674,-0.08364257891592386
233.6000000000026,29.307310567290717,0.44863749555587545,-0.08566151475631134
234.80000000000263,29.422382774820253,0.4522920883271837,-0.08697940473309318
236.00000000000264,29.536392594356574,0.458370620313456,-0.08959880818689214
237.20000000000266,29.651722400961347,0.46232098775906144,-0.08961701806144795
238.40000000000268,29.76546886082088,0.4669919257475137,-0.09227282005127346
239.6000000000027,29.881380408002357,0.47555868066384194,-0.09487823269047357
240.8000000000027,29.995604575851562,0.48309012476039703,-0.09614099295228318
242.00000000000273,30.10995999787938,0.49599131597071855,-0.09883008589095876
243.20000000000275,30.225625507925656,0.5088714283680551,-0.10127922706806869
244.40000000000276,30.34017550572465,0.5252436059539021,-0.10412854099247637
245.60000000000278,30.455572032139898,0.5464392849924472,-0.10682559858901852
246.8000000000028,30.569865589366135,0.5711872445731374,-0.1093519909163776
248.0000000000028,30.686095318874166,0.5974439663091508,-0.11264349133782492
249.20000000000283,30.799926138542705,0.6380008332640854,-0.11462196137347336
250.40000000000285,30.914827562272436,0.6740518094688873,-0.11854374503323095
251.60000000000286,31.03043481010472,0.6980001758277303,-0.12263362408791689
252.80000000000288,31.144424195808803,0.6978992548812161,-0.12722593426823625
254.0000000000029,31.260580734670206,0.6725356068340632,-0.13024940867270196
255.20000000000292,31.374468208118746,0.6306508081957296,-0.13410436668289671
256.40000000000293,31.48897007002688,0.5816513097768916,-0.13826673868055295
257.600000000003,31.603818666544267,0.5413311239927282,-0.14383135243197254
258.80000000000297,31.71765690180186,0.5090983704145033,-0.14712155383105952
260.00000000000296,31.831897624720515,0.49101900855018243,-0.15260051263490215
261.200000000003,31.947216506686416,0.47854929434307314,-0.1570173916902191
262.40000000000305,32.06081138477248,0.4729168233008364,-0.16322108411346914
263.60000000000304,32.174800856544046,0.47196765187275663,-0.16889884314699888
264.800000000003,32.289269519952185,0.4704882119010911,-0.17396122600290465
266.00000000000307,32.404192205836644,0.4732058628110141,-0.18069631865173985
267.2000000000031,32.518524785116234,0.47839274203671306,-0.1882788133348403
268.4000000000031,32.63151193398042,0.4804940595690637,-0.19433032180606258
269.6000000000031,32.74687540809669,0.48112079084958664,-0.20238051731085083
270.80000000000314,32.861723901841366,0.48174168745607443,-0.20930516886209638
272.0000000000032,32.97546529376132,0.48517511690525045,-0.21752908540943716
273.2000000000032,33.090525607493504,0.4878927172652841,-0.2265689198086136
274.40000000000316,33.204741692240134,0.4881991753385011,-0.23502984070077915
275.6000000000032,33.32081612751772,0.4880813794899583,-0.24542524060488313
276.80000000000325,33.43489765218994,0.4892864592744166,-0.25378758490012165
278.00000000000324,33.54809542465983,0.490954935398946,-0.26367043566146897
279.20000000000323,33.66507185358727,0.4927176013987683,-0.2744838618393226
280.4000000000033,33.77938178680786,0.4949252996656679,-0.2821272221034472
281.6000000000033,33.89567703284326,0.4968584965809779,-0.2949401484045713
282.8000000000033,34.01101078597888,0.4964516106144939,-0.30520556404438226
284.0000000000033,34.12568587705654,0.49920428252334204,-0.3141691949949905
285.20000000000334,34.2409702343954,0.4997574093027918,-0.32677008053877366
286.4000000000034,34.357010624653206,0.5029359186455956,-0.3390407148723966
287.6000000000034,34.47065844646402,0.5038392014584224,-0.34799169233319605
288.80000000000337,34.584443224244225,0.501752816292171,-0.3618166735517052
290.0000000000034,34.69890447464023,0.5025341659084382,-0.374448669654341
291.20000000000346,34.81404434124921,0.5051029047190108,-0.38532937238192844
292.40000000000344,34.92897095015951,0.5053166694159077,-0.39802723161357667
293.60000000000343,35.043769835932395,0.5067669392406668,-0.4109389482175212
294.8000000000035,35.159271041749804,0.5073261681368102,-0.4236210468304593
296.0000000000035,35.272487011310645,0.5096350055830415,-0.434653881715394
297.2000000000035,35.38780037950869,0.511537642647443,-0.4478895955992095
298.4000000000035,35.50258212853767,0.5154450105135293,-0.46079324955167955
299.60000000000355,35.61673539026762,0.5162188720463641,-0.4764365369992394
300.8000000000036,35.73161316359956,0.5191854908180463,-0.4889766399803528
302.0000000000036,35.84765378329173,0.5184955619335203,-0.5016194006886798
303.20000000000357,35.96152640875494,0.5224420542775494,-0.5174880991745088
304.4000000000036,36.0779029887166,0.5243560200563102,-0.5306493006430886
305.60000000000366,36.19258444589443,0.5298037790727244,-0.5444831517279152
306.80000000000365,36.30580832624082,0.534308398245419,-0.5596737528562303
308.00000000000364,36.42331171992387,0.5365737671375407,-0.5759869395111852
309.2000000000037,36.5387021035999,0.5442377386517934,-0.5914605882479256
310.40000000000373,36.65303230510358,0.5483511541835406,-0.6091747505140912
311.6000000000037,36.76927459194213,0.555274563317187,-0.6242288571799746
312.8000000000037,36.88447374040918,0.5625611683945123,-0.6401010679655736
314.00000000000375,36.99981014016057,0.5693176839472707,-0.6574619289451995
315.2000000000038,37.11520739513996,0.5774658782185368,-0.6767191477109615
316.4000000000038,37.22917095914029,0.5888367663275336,-0.696280190395842
317.6000000000038,37.34429736423922,0.5972907634727933,-0.7141470382424688
318.8000000000038,37.45757864004846,0.6066117664972225,-0.7336589346345113
320.00000000000387,37.575657081041946,0.619830797720857,-0.7568263669679847
321.20000000000385,37.6918914917334,0.6300765786845071,-0.7778365746096707
322.40000000000384,37.80666504926907,0.6449483552982548,-0.8016880001957181
323.6000000000039,37.921688315546845,0.6607825883404042,-0.8245387395383847
324.80000000000393,38.03775199882966,0.6786139935677824,-0.8511927703663167
326.0000000000039,38.15289487863737,0.69568565600544,-0.8764791260511093
327.2000000000039,38.26716252269799,0.7158401536495795,-0.9036428212928387
328.40000000000396,38.383278797472606,0.7381341368589878,-0.9340377846788388
329.600000000004,38.5000139887115,0.7660020741046477,-0.9660092795184068
330.800000000004,38.615445318025984,0.7925681042735551,-1.0000881847314593
332.000000000004,38.7295544837758,0.8214670310194763,-1.0358667591536963
333.200000000004,38.846479058321144,0.8550714403119315,-1.0745197593300375
334.40000000000407,38.963292775801065,0.8857005892576837,-1.117066447118372
335.60000000000406,39.07889199962607,0.9153942773808273,-1.1608999069738033
336.80000000000405,39.19403915733033,0.9438386587799957,-1.2080379290757373
338.0000000000041,39.31066829851164,0.9771344646298803,-1.2626082764990363
339.20000000000414,39.42646509637919,0.9967322342016723,-1.3153504615121676
340.4000000000041,39.542620003889056,1.0069685646731643,-1.3722858806074094
341.6000000000041,39.65850976798458,1.0054019225531556,-1.4292514713480866
342.80000000000416,39.775252947523896,0.9865075891675816,-1.4922246276177673
344.0000000000042,39.89118805191092,0.9532242488236813,-1.55607050262308
345.2000000000042,40.00662298887986,0.8964571779420151,-1.6179808375262343
346.4000000000042,40.122626969494256,0.8263418894012637,-1.677651268126338
347.60000000000423,40.23774793864548,0.7496710687182622,-1.7355890791711341
348.8000000000043,40.35411930172345,0.6713174259424816,-1.7875524062047505
350.00000000000426,40.46852156763199,0.6027416818190686,-1.83479848544181
351.20000000000425,40.58462436616657,0.5377881411580441,-1.8767701841701991
352.4000000000043,40.698668676187076,0.48649910639924876,-1.91199482582559
353.60000000000434,40.81527994687361,0.44164354952401796,-1.9442864106587368
354.80000000000433,40.930020764596456,0.40314067772724893,-1.9732299278596241
356.0000000000043,41.04588462509463,0.3738982756242014,-1.9980046680397314
357.20000000000437,41.16210182826722,0.34747268335547743,-2.0204362383208894
358.4000000000044,41.277769552435885,0.3321169945915514,-2.040954269160907
359.6000000000044,41.3935781102098,0.31585748134102004,-2.056741680711863
360.8000000000044,41.510097146528196,0.3058246489539815,-2.0753641850441045
362.00000000000443,41.62409505399207,0.3002288254837662,-2.09067886158953
363.2000000000045,41.74242082704365,0.29648033170868293,-2.1036354662116676
364.40000000000447,41.85809735345773,0.2911543271425451,-2.1181688690651956
365.60000000000446,41.974816900159546,0.2879124033380517,-2.1322664552871604
366.8000000000045,42.089633873751126,0.28729712794580575,-2.145747051341158
368.00000000000455,42.20669056947326,0.2826015329721109,-2.159916605680089
369.20000000000454,42.32261162163341,0.28202164732737095,-2.1721867749622703
370.4000000000045,42.43877088311345,0.2814106322744841,-2.1863079308936393
371.60000000000457,42.55491134503812,0.282216738512844,-2.199205941437478
372.8000000000046,42.67174971819115,0.2767383395780502,-2.2123858514833623
374.0000000000046,42.78832857115319,0.27724341921598655,-2.2244659221724095
375.2000000000046,42.90502303389435,0.2772948663513224,-2.2382730842711536
376.40000000000464,43.02061548381457,0.2770800746874966,-2.2495211871510796
377.6000000000047,43.13857146196469,0.27493355786262985,-2.263967162582305
378.8000000000047,43.254564343970976,0.27539267404022755,-2.276715543038192
380.00000000000466,43.3715552265555,0.2723060259849474,-2.2903306587843892
381.2000000000047,43.48718349419535,0.2690410050790666,-2.302864554042323
382.40000000000475,43.60332689544524,0.2691151785590796,-2.3152427769110506
383.60000000000474,43.72139982206877,0.2680381453915401,-2.3305216158945647
384.80000000000473,43.83770366927644,0.26703844894570444,-2.3416410033343182
386.0000000000048,43.95441582480914,0.26810261155308746,-2.3564386532905575
387.2000000000048,44.07111862043849,0.2658568774562852,-2.369884765455727
388.4000000000048,44.18772363532576,0.2659178452360493,-2.383811251624911
389.6000000000048,44.30437290006307,0.2662733119932641,-2.3965107556049094
390.80000000000484,44.42093099743177,0.2659163314089604,-2.411466657105861
392.0000000000049,44.538159526386146,0.2644840592439307,-2.4246096524045364
393.2000000000049,44.65495591244912,0.2627933034438437,-2.4393399120825485
394.40000000000487,44.77238386432979,0.26416856227874586,-2.4536045299058373
395.6000000000049,44.887620325699466,0.26220422741221,-2.467517642307011
396.80000000000496,45.0048816663985,0.2619396641074995,-2.4821596057046422
398.00000000000495,45.12249070732712,0.2629615418826107,-2.497693828713413
399.20000000000493,45.23908071515323,0.26429887298441623,-2.5123446546680555
400.400000000005,45.35565590540986,0.26320384369264715,-2.527083040575035
401.600000000005,45.47208170812955,0.26231731832718924,-2.5426214430414475
402.800000000005,45.58976357533093,0.26386743557100983,-2.5600882873032242
404.000000000005,45.70736410600446,0.2637504356712708,-2.574809655365687
405.20000000000505,45.823940610726865,0.26423332094323826,-2.5900319627930477
406.4000000000051,45.942128819896254,0.2647305664455795,-2.607165264150524
407.6000000000051,46.059529438748186,0.2682011756759286,-2.6247256622326
408.80000000000507,46.17651934173714,0.26759523651559963,-2.6413563602633556
410.0000000000051,46.29336946185071,0.26752085675484666,-2.6580126093198198
411.20000000000516,46.41080172333424,0.2681898049123354,-2.673926952161208
412.40000000000515,46.52805575364821,0.2714206885539917,-2.69279720428244
413.60000000000514,46.645371297995105,0.27332222299162634,-2.7093473060855846
414.8000000000052,46.76295164941653,0.27100230473839093,-2.7271625883509776
416.00000000000523,46.88045470113671,0.2720145932233666,-2.739838038177987
417.2000000000052,46.997379404040515,0.27297239514320576,-2.7607327473900076
418.4000000000052,47.11615936572771,0.2731732106746646,-2.777686953346712
419.60000000000525,47.23284178681201,0.27192977973485327,-2.7920194685249458
420.8000000000053,47.350258227835376,0.2749229153431329,-2.8086685019306485
422.0000000000053,47.4676830245064,0.2735457594027564,-2.8225514710831936
423.2000000000053,47.5850654938985,0.27600063984811185,-2.8387345617475557
424.4000000000053,47.70239006149513,0.273829752820161,-2.8539892723485636
425.60000000000537,47.81973840715606,0.2753552841290824,-2.8681400308523752
426.80000000000535,47.93836204824518,0.27468382818988857,-2.8845709175213994
428.00000000000534,48.05559107213116,0.27275371467209686,-2.8974294941033545
429.2000000000054,48.173390424563145,0.27437189975830084,-2.9109611140314677
430.40000000000543,48.290839661155076,0.27370801704858655,-2.924719590025992
431.6000000000054,48.40869071698678,0.2698547311043177,-2.936903256971292
432.8000000000054,48.52613350562572,0.2692030046080631,-2.9497984201505596
434.00000000000546,48.643580034080635,0.26534547296860694,-2.962868414946148
435.2000000000055,48.760552386260784,0.26266584183356145,-2.974404517099857
436.4000000000055,48.877829824408956,0.2608186069917708,-2.988153159066375
437.6000000000055,48.996523969561586,0.25636906341781757,-2.996591791955211
438.8000000000055,49.112659683113925,0.25291593529917133,-3.009010704081766
440.00000000000557,49.23154132881722,0.24997193350890867,-3.0191211057212817
441.20000000000556,49.347747132872854,0.24226311170994347,-3.0304789337854428
442.40000000000555,49.46546441609718,0.23602527574587778,-3.04117961524691
443.6000000000056,49.58312868054175,0.23131169775614624,-3.0504585456064612
444.80000000000564,49.699896548162,0.22305526555488442,-3.0589234450243303
446.0000000000056,49.81808772006107,0.22012032036188967,-3.0675282123163203
447.2000000000056,49.93528496602612,0.2093514405310984,-3.0763311359097125
448.40000000000566,50.05401684788532,0.2035141190364897,-3.085631520084371
449.6000000000057,50.17121291446773,0.1968843389487805,-3.0942664716877815
450.8000000000057,50.288963774250895,0.19072224334091908,-3.0993758090560624
452.0000000000057,50.40613415489483,0.1865713972804937,-3.1057307241007175
453.20000000000573,50.52456688208639,0.1781653494239167,-3.112102479089214
454.4000000000058,50.64260960283823,0.17114160959771235,-3.1200210491937694
455.60000000000576,50.760893932231724,0.16641087762223383,-3.12474200445707
456.80000000000575,50.8790796210967,0.1577039500014319,-3.130544620527151
458.0000000000058,50.996561674983546,0.15654250090498611,-3.1364934235955397
459.20000000000584,51.11414684453799,0.1528765762744435,-3.1414210305589365
460.40000000000583,51.232511562786044,0.15045761086366316,-3.1468441708320163
461.6000000000058,51.35089534229581,0.1477086620136734,-3.1504690708769254
462.80000000000587,51.46953146935273,0.14311250576544776,-3.154250207979538
464.0000000000059,51.58651090323233,0.14196469956325874,-3.1587508079809337
465.2000000000059,51.704828920364704,0.13952716558659495,-3.1621073179607695
466.4000000000059,51.82335250559726,0.13675964646980365,-3.166305557556444
467.60000000000593,51.942218621341475,0.13412913791185865,-3.170201302342787
468.800000000006,52.060351173459395,0.1335571003151661,-3.173871028813129
470.00000000000597,52.17871064602487,0.13243566984271393,-3.1765086297155936
471.20000000000596,52.29696379242207,0.13102571286312892,-3.1791722920722427
472.400000000006,52.416371148922956,0.13211580708151205,-3.181884512707091
473.60000000000605,52.53307189114764,0.12960216913697664,-3.1860886558578945
474.80000000000604,52.65166922938894,0.12874092943455073,-3.1881419010708996
476.000000000006,52.77069923706121,0.1306776469451698,-3.189672671792035
477.20000000000607,52.88744183652219,0.12817443643222037,-3.192957216307091
478.4000000000061,53.00632702357365,0.13169570881982562,-3.195585453415478
479.6000000000061,53.12371019718701,0.1280105176094245,-3.19771805744328
480.8000000000061,53.241095980655814,0.12883684240005822,-3.198260796519459
482.00000000000614,53.35996669723218,0.12729384262932109,-3.2022052633431235
483.2000000000062,53.47780679933402,0.1309851754649496,-3.2033805567741735
484.4000000000062,53.59552095131253,0.13035896367019162,-3.206478196255649
485.60000000000616,53.71227765349105,0.13446903075160022,-3.20908495549323
486.8000000000062,53.83210950963624,0.13270628769729664,-3.2096146963518173
488.00000000000625,53.950974174626324,0.13640059304622143,-3.210441539988472
489.20000000000624,54.06869155845534,0.1405302418311246,-3.211719996125588
490.40000000000623,54.18717801782676,0.14097360763097277,-3.2142998700262475
491.6000000000063,54.30566637121287,0.14395009557174454,-3.215675824445272
492.8000000000063,54.42390418588706,0.14558434472350268,-3.218386857263641
494.0000000000063,54.542498989157515,0.14912016067879352,-3.2199215804275156
495.2000000000063,54.661821268015586,0.14856357982805324,-3.221049760928166
496.40000000000634,54.78075175429749,0.14661812556506426,-3.22359389809548
497.6000000000064,54.89994506106449,0.15092944875463854,-3.2248687129512437
498.8000000000064,55.01828850218668,0.1509968571565179,-3.2264541410558976
500.00000000000637,55.13736132816018,0.15023091220983864,-3.2268499871968204
501.2000000000064,55.25616765632196,0.14805316781376832,-3.2293778826942106
502.40000000000646,55.375478493106016,0.14989915209421534,-3.230141226269563
503.60000000000645,55.49442744576519,0.14701827700387105,-3.230800949684396
504.80000000000643,55.611554467257726,0.14756711320283955,-3.232100261754916
506.0000000000065,55.731681262067966,0.14819314181798948,-3.233538928934168
507.2000000000065,55.85024397792326,0.15081854378156911,-3.2371306474405643
508.4000000000065,55.969474757215146,0.1445833169404549,-3.2383970774492576
509.6000000000065,56.08888773026672,0.14723845499532573,-3.2401202053951605
510.80000000000655,56.20694736936518,0.147373028242197,-3.241440361118251
512.0000000000066,56.325800119996074,0.14816064489962744,-3.24276325119101
513.2000000000066,56.445498909463545,0.14752538490522804,-3.2440643844293264
514.4000000000066,56.563812513194556,0.14723561759389237,-3.245840941979738
515.6000000000066,56.684325365517424,0.1446351720363691,-3.2467097733935737
516.8000000000067,56.802198841030936,0.14505741280502105,-3.2480332431993193
518.0000000000066,56.92133504658292,0.14438406522025804,-3.2493038200815647
519.2000000000066,57.04082839164621,0.141300036714881,-3.2501260008977706
520.4000000000067,57.15984300711002,0.1443085071904464,-3.252992335342843
521.6000000000067,57.279580795562374,0.14391106677593235,-3.2542703752007576
522.8000000000068,57.397780105078496,0.14428866040888322,-3.25445194129668
524.0000000000067,57.51689733538149,0.14359061983804355,-3.254300565611842
525.2000000000068,57.63713858488373,0.14361291243391228,-3.2578854834129407
526.4000000000068,57.757157225050946,0.14465955570321187,-3.2578891825315464
527.6000000000067,57.87615589294791,0.14035507972713712,-3.257912561440797
528.8000000000068,57.99650872966616,0.14422402082819452,-3.260559148972284
530.0000000000068,58.11590265370107,0.14585375558960167,-3.2609256150076655
531.2000000000069,58.235779688928126,0.1473280399724658,-3.2618498623346506
532.4000000000069,58.35518334534579,0.14802410427467028,-3.2644686092263813
533.6000000000068,58.47547931117614,0.1466867539909411,-3.2651311844025135
534.8000000000069,58.594757774584636,0.14427802473023876,-3.265812936096167
536.0000000000069,58.71417232703762,0.14516257134775468,-3.267110046564405
537.2000000000069,58.83367655665131,0.1471006267550249,-3.267109814668614
538.4000000000069,58.95297130268746,0.14470736280657093,-3.268352070440172
539.600000000007,59.073626710560625,0.14907430126024068,-3.2695143347518867
540.800000000007,59.19312461051885,0.14668641339703492,-3.2710312259718455
542.000000000007,59.31250772887863,0.15097578201235295,-3.271057552571586
543.200000000007,59.43266624230271,0.15014751504238322,-3.2723698287079843
544.400000000007,59.551694008371825,0.14425367194621308,-3.274714567314116
545.6000000000071,59.67137697465606,0.14029140058717127,-3.2746889386238127
546.800000000007,59.79024857134306,0.1427920517420691,-3.274750057954155
548.000000000007,59.90936422951758,0.14341745057084154,-3.275990499933469
549.2000000000071,60.02826207060461,0.14718595824166736,-3.277309983097113
550.4000000000071,60.14808644521159,0.14546394177372446,-3.278610597742831
551.6000000000072,60.26831509227095,0.1451861994620547,-3.2782813793039858
552.8000000000071,60.3864066052993,0.148477915331381,-3.278619970365154
554.0000000000072,60.50543241674806,0.14617911264856265,-3.280912514187934
555.2000000000072,60.62469247451563,0.14746933146997943,-3.2802693119192394
556.4000000000071,60.74392557119997,0.15157014096658572,-3.2800000553315813
557.6000000000072,60.86310673169028,0.14988812344509683,-3.281859322105679
558.8000000000072,60.982744026618214,0.15204241339665703,-3.28389324421802
560.0000000000073,61.101315231764524,0.15507664799153975,-3.283890088001969
561.2000000000073,61.22129151840744,0.15465693950080794,-3.283901342198189
562.4000000000073,61.340749792760505,0.1592534182688098,-3.2851997901281447
563.6000000000073,61.46051386684252,0.15719562509191132,-3.28652005903246
564.8000000000073,61.579566586107696,0.1606570993789178,-3.2878308853692775
566.0000000000073,61.69917000000071,0.15842003511173208,-3.2884898800000455
567.2000000000073,61.819448786963484,0.1583440398794409,-3.289150072466238
568.4000000000074,61.93823943962325,0.15705508816231029,-3.29046989550082
569.6000000000074,62.0576847688388,0.15898271856301416,-3.2908010089638737
570.8000000000075,62.17783778294785,0.15800923092019037,-3.2921160593923466
572.0000000000074,62.29781143651802,0.1631159673648901,-3.29442016375726
573.2000000000074,62.417772332531065,0.16157546312750226,-3.2947508893332946
574.4000000000075,62.538300353368115,0.16230423323988474,-3.2984411111234495
575.6000000000074,62.659065216978604,0.15733435273567875,-3.2958626590119513
576.8000000000075,62.77917100079617,0.1564844518125761,-3.2945301729297083
578.0000000000075,62.9001167740673,0.15497709403795135,-3.2981503461797725
579.2000000000075,63.02058246356599,0.15110229833811162,-3.2981472146604673
580.4000000000076,63.14084431418327,0.14981843747159018,-3.298480419855534
581.6000000000075,63.26016083191985,0.14652974387290985,-3.2998028075106958
582.8000000000076,63.380919492319805,0.14740927080069466,-3.3011204117208606
584.0000000000076,63.500542645189995,0.14514292334078682,-3.303739884798116
585.2000000000075,63.62136115633623,0.14296869602026308,-3.305051153694864
586.4000000000076,63.74221529389194,0.14302264396268483,-3.3050607730920953
587.6000000000076,63.86188205337578,0.14350389346506842,-3.3077817108952035
588.8000000000077,63.98213625674384,0.14239743512395808,-3.3090091191719986
590.0000000000077,64.10133340619213,0.14252481687038787,-3.3103198720354206
591.2000000000077,64.22312256671482,0.14275869375782024,-3.3116400143977094
592.4000000000077,64.34245115716429,0.1401065225064244,-3.3129502480335935
593.6000000000078,64.46157281786147,0.14492051557251817,-3.3142704431950767
594.8000000000077,64.58192819550649,0.1422296704772119,-3.314470706638555
596.0000000000077,64.7023593969923,0.1436706584991263,-3.3169067754364665
597.2000000000078,64.82279133020286,0.14920379410339857,-3.3182185247686684
598.4000000000078,64.94154123920264,0.1491660973788096,-3.3177689768204894
599.6000000000079,65.06130796418707,0.1527868912644763,-3.319576105438292
600.8000000000078,65.1790460457317,0.152479472182792,-3.320860087979902
602.0000000000078,65.30168079790856,0.15874372566842299,-3.3208600880187467
603.2000000000079,65.4219760693541,0.15828871769389674,-3.322144840647921
604.4000000000078,65.54237206525505,0.1582313008930638,-3.323494485279935
605.6000000000079,65.66286407700997,0.16249640789067055,-3.3234985713838476
606.8000000000079,65.78181698664109,0.16976868526019762,-3.3244801814671705
608.000000000008,65.90252907923579,0.17159799797778952,-3.323029748780177
609.200000000008,66.02259312587485,0.17651976849114726,-3.3244864457207033
610.4000000000079,66.14258172955262,0.17677887117510704,-3.327109612458017
611.600000000008,66.2631477807331,0.18005884381392856,-3.3260791768754716
612.800000000008,66.38365473728312,0.18389118366440638,-3.3271101898870055
614.000000000008,66.50373352622887,0.18456038102600014,-3.3290950889722493
615.200000000008,66.62313234849364,0.18585316519416595,-3.329091066140593
616.400000000008,66.74364320322115,0.1880568824130049,-3.3304001615276557
617.6000000000081,66.86498381284439,0.18884006725334235,-3.3304149545840174
618.8000000000081,66.98475344839596,0.1884396803690731,-3.3307183298628438
620.0000000000081,67.10475629350978,0.19031445098111544,-3.332039368810306
621.2000000000081,67.22520625439984,0.18739190787131244,-3.333348003482229
622.4000000000082,67.34554720448273,0.18704779379805658,-3.3333597383326166
623.6000000000081,67.46634171019129,0.18772213705736984,-3.3343400818578317
624.8000000000081,67.58731861864266,0.1875571176398716,-3.334340210846797
626.0000000000082,67.70742835058543,0.1884922085597165,-3.3356599912768425
627.2000000000082,67.82826170721546,0.18934523400657466,-3.3356599761566956
628.4000000000083,67.94810758171133,0.19042879854747463,-3.3369895415465844
629.6000000000082,68.06835413913718,0.19222953047258629,-3.3356716063506653
630.8000000000083,68.18854228633833,0.1891306365184806,-3.3356687921402832
632.0000000000083,68.30896556226261,0.18913925905598927,-3.3370208724445733
633.2000000000082,68.42926786863454,0.19033328971747276,-3.336979919937912
634.4000000000083,68.54987316772339,0.18936551765508258,-3.338283549112224
635.6000000000083,68.6704353977231,0.19228552383908948,-3.3382998240321315
636.8000000000084,68.79118225514861,0.19380292617935568,-3.338299824542773
638.0000000000084,68.91150595362222,0.19241680827164287,-3.339615333282145
639.2000000000083,69.03241621551427,0.19247529377931527,-3.3379545828192856
640.4000000000084,69.15384799904969,0.1916023980443884,-3.340030570043015
641.6000000000084,69.27319707821596,0.19364766277595846,-3.3418237217146025
642.8000000000084,69.39474483445247,0.19514810864094234,-3.3397963795885444
644.0000000000084,69.51511121812419,0.19810418077147607,-3.3397347553179157
645.2000000000085,69.63529577184363,0.19948881538651375,-3.340465163853495
646.4000000000085,69.75628768812227,0.20234720012809415,-3.3410884266687773
647.6000000000085,69.87691144764312,0.20565249190474422,-3.3424393497016514
648.8000000000085,69.99713525991443,0.20336320238197358,-3.3424599598506335
650.0000000000085,70.11707548238597,0.20481160231620188,-3.342459959966882
651.2000000000086,70.23845060302844,0.20531641201872852,-3.343766549319155
652.4000000000085,70.35877312844875,0.20567578573096257,-3.343488163783782
653.6000000000085,70.47946121793775,0.2035015158893474,-3.345090603691056
654.8000000000086,70.59869833604779,0.20337038834669863,-3.3437805816599333
656.0000000000086,70.71999225926318,0.20684110348655826,-3.3450306237465943
657.2000000000087,70.83968999664118,0.20694853175900318,-3.3450998079895986
658.4000000000086,70.95978626371048,0.20671803557992563,-3.3450998080005077
659.6000000000087,71.08177583741355,0.20693788912734967,-3.3451029751267183
660.8000000000087,71.20129094676453,0.20626569984102638,-3.343942240336369
662.0000000000086,71.32207500078661,0.20838533917067537,-3.346409839258703
663.2000000000087,71.43929487676648,0.2107054506346624,-3.3450898557502553
664.4000000000087,71.56216860225223,0.20846261077204709,-3.346410221005397
665.6000000000088,71.68338822771051,0.21367916852207403,-3.3490915708799704
666.8000000000088,71.80323708866773,0.21470280556154586,-3.349040152006686
668.0000000000088,71.92417816585377,0.2151213873446174,-3.3490401519999997
669.2000000000088,72.04475445358631,0.21625290954686105,-3.349040152000616
670.4000000000088,72.16540483454149,0.212192728585906,-3.349043700751986
671.6000000000088,72.28588156360905,0.21681196272222558,-3.3490453690406814
672.8000000000088,72.40727048240714,0.21290257313416694,-3.350350229717009
674.0000000000089,72.5282679951955,0.21649535956652644,-3.3509627040579053
675.2000000000089,72.64966783800037,0.20928380720674378,-3.3520001057149686
676.400000000009,72.7699872072179,0.21022859621069734,-3.350364387785892
677.6000000000089,72.89065762377237,0.2095980561232642,-3.3503597156010017
678.8000000000089,73.01274755993401,0.21338269948904598,-3.351680131660074
680.000000000009,73.1336093892098,0.21195758317065394,-3.3516780400767696
681.2000000000089,73.25491416413607,0.21270175479033226,-3.3533767768245166
682.400000000009,73.37608164390149,0.21176092935889446,-3.3537692707961204
683.600000000009,73.49680328217676,0.2125975934715203,-3.3546401046396146
684.800000000009,73.61748051862838,0.2139461233981086,-3.35332028584425
686.0000000000091,73.73906840774254,0.21389414633071713,-3.3543123980893634
687.200000000009,73.8593684472139,0.21191913083757008,-3.3549699202427976
688.4000000000091,73.98029913719003,0.21446970416683442,-3.3552996188960003
689.6000000000091,74.10028101249524,0.21495482759897544,-3.3566096092705093
690.800000000009,74.22215576844756,0.21546440640623388,-3.3556479378512316
692.0000000000091,74.34380412601337,0.21583171924856126,-3.3552898114753775
693.2000000000091,74.46494808330739,0.22094040144459393,-3.356662511322047
694.4000000000092,74.5862217099159,0.22020124246202433,-3.3566099802583276
695.6000000000092,74.70645695442657,0.21960609374580597,-3.3566099599613106
696.8000000000092,74.82818016317087,0.21969399024707248,-3.356074503997193
698.0000000000092,74.94965513471058,0.2144601494890077,-3.3562255976229984
699.2000000000093,75.06987818349228,0.22024601901631846,-3.358276725917132
700.4000000000092,75.19126169856168,0.2189783003973842,-3.3569500018725082
701.6000000000092,75.31309607359195,0.22392990177517946,-3.35460834804757
702.8000000000093,75.4340305394842,0.2224865274273491,-3.3559599112041902
704.0000000000093,75.5552892821204,0.22158148259743538,-3.3559075712597104
705.2000000000094,75.67622131057048,0.21987244580377063,-3.3572716004791427
706.4000000000093,75.7964683195357,0.2184779740366105,-3.3585896278027567
707.6000000000093,75.91839584476887,0.21621578819815235,-3.3598894318999704
708.8000000000094,76.03960086200985,0.2177551053438287,-3.3595699680482674
710.0000000000093,76.16025777240414,0.21480601031723068,-3.3582061179686247
711.2000000000094,76.2804965548742,0.2194648248608575,-3.3590358856643805
712.4000000000094,76.4010737265161,0.21783251173413398,-3.3592817180982273
713.6000000000095,76.52291064692633,0.22064109344734062,-3.3612206467901107
714.8000000000095,76.6440044012256,0.2173642472133821,-3.3612212292136774
716.0000000000094,76.76561418693834,0.21761747798675612,-3.361879858280469
717.2000000000095,76.88656836605927,0.21673632865918724,-3.3631897824940293
718.4000000000095,77.00958177751995,0.21599866099349985,-3.3631668432334365
719.6000000000095,77.13107564908952,0.21355943473202088,-3.36194450072158
720.8000000000095,77.25271364130369,0.21581369310087428,-3.3656968106691
722.0000000000095,77.3744261632563,0.21295049259500232,-3.3631015533148108
723.2000000000096,77.49641076204254,0.21571232955529074,-3.364510424278427
724.4000000000096,77.61765695105301,0.21504618454181168,-3.364509983776453
725.6000000000096,77.73966449865387,0.2155507078254293,-3.3641887883230446
726.8000000000096,77.86081496690717,0.21028306902166927,-3.3635806624467404
728.0000000000097,77.98239934565282,0.2140970204644852,-3.3638307387808086
729.2000000000096,78.10522251299602,0.21350912933419042,-3.3641783774710974
730.4000000000096,78.2267683027766,0.2182059489106487,-3.3641798918348256
731.6000000000097,78.34793776256171,0.21433408632228979,-3.365500267307145
732.8000000000097,78.46926880530484,0.2158977465068841,-3.365500168000056
734.0000000000098,78.59054814917434,0.21647013208397525,-3.3655071176717946
735.2000000000097,78.71273106342188,0.21752172159111716,-3.3658202565257365
736.4000000000098,78.83409005843782,0.21840653891630946,-3.3658226100829602
737.6000000000098,78.95574836656735,0.220075392849314,-3.3669536311429153
738.8000000000097,79.0789632941725,0.21934860868542794,-3.3681301329007396
740.0000000000098,79.19898540091287,0.21856006638096748,-3.368459806957672
741.2000000000098,79.3209872754472,0.2174939066705477,-3.3671972453387733
742.4000000000099,79.44189677963588,0.2183782638317866,-3.367139799914143
743.6000000000099,79.56323202096688,0.2194079683498933,-3.367864680605231
744.8000000000098,79.68520407176716,0.22359947311679806,-3.3698625358013357
746.0000000000099,79.80619124132829,0.22331530967134383,-3.3698208597621875
747.2000000000099,79.92820416181634,0.2241424094771025,-3.367258101386308
748.4000000000099,80.0491679422001,0.22647840393074392,-3.3701107525505694
749.6000000000099,80.17083103368647,0.22269550245577618,-3.370065448114863
750.80000000001,80.2931973772383,0.2240034684463139,-3.3686796844695257
752.00000000001,80.41524668224173,0.2230885829664493,-3.370351278670231
753.20000000001,80.53659550701666,0.22328423502273687,-3.3713100597125365
754.40000000001,80.65750537665947,0.22469908425045437,-3.3699999902737257
755.60000000001,80.77971769497451,0.22364488349404255,-3.3693493984046308
756.8000000000101,80.90228002690748,0.22746886798009958,-3.3695847648361594
758.00000000001,81.02329315915523,0.23016754718807464,-3.371749650536549
759.20000000001,81.14517923961543,0.23372561253518453,-3.3717498479997174
760.4000000000101,81.2652633192164,0.23118157272856643,-3.3717479617603363
761.6000000000101,81.38678408816722,0.23055142133036566,-3.3701404856502393
762.8000000000102,81.50823306163002,0.23120356473592119,-3.370220939302794
764.0000000000101,81.63046834893692,0.23227575482531093,-3.3741335348552015
765.2000000000102,81.75099142380004,0.23080310052253128,-3.371419334744826
766.4000000000102,81.87248729135302,0.23381643773391492,-3.3714200239730276
767.6000000000101,81.99395218514725,0.22978315965776996,-3.3707379944231075
768.8000000000102,82.11625292141625,0.22873961609940707,-3.3720798277652184
770.0000000000102,82.23708825038693,0.23279972035078877,-3.3721016995049506
771.2000000000103,82.35979648918916,0.23615972267299457,-3.37208213358155
772.4000000000103,82.48133810552116,0.2308966958048848,-3.3709365202018104
773.6000000000103,82.60275158565832,0.23799177630399448,-3.3734001912208393
774.8000000000103,82.72386472416174,0.23762552014784966,-3.3746959039874667
776.0000000000103,82.84536152056863,0.23701318795394277,-3.3747098537359292
777.2000000000103,82.96708836328804,0.23669354913299978,-3.3743798631342434
778.4000000000103,83.08895515155473,0.23728789706579523,-3.374379871999999
779.6000000000104,83.21165180110539,0.23496324209484154,-3.374380018805778
780.8000000000104,83.33317119034399,0.23411919416579785,-3.3750399435777814
782.0000000000105,83.45507946949826,0.23404669897385766,-3.3750436209307493
783.2000000000104,83.57666015073112,0.23662281143103137,-3.374222662196657
784.4000000000104,83.69857502530355,0.23939700414182097,-3.376310398956568
785.6000000000105,83.82182384924164,0.24136646340792556,-3.3760502634627416
786.8000000000104,83.94259349329093,0.2437302782748456,-3.3755900775067076
788.0000000000105,84.06537120532987,0.24395056241644042,-3.376570075584749
789.2000000000105,84.18737091695839,0.2436550518267473,-3.3765701316424104
790.4000000000106,84.3088797903863,0.24712579563567338,-3.3752600696729878
791.6000000000106,84.42992250210983,0.23962190620278,-3.376581098272205
792.8000000000105,84.55305010311413,0.24486079150853746,-3.376580024000429
794.0000000000106,84.67484680730122,0.24619919899033293,-3.376580023807241
795.2000000000106,84.7966150833568,0.24379479474913168,-3.376345024546077
796.4000000000106,84.91754693636467,0.2451291635212658,-3.3781744249084067
797.0000000000106,84.97936953015592,0.24477677592011737,-3.377191445068327