File: 01_Data/Cotton_Rug/STA/N2/3K_min/Cotton_Rug_STA_N2_3KData_220114_R1.csv
##Temp./Â°C,Time/min,DSC/(mW/mg),Mass loss/mg
50.0,10.6,-0.016923793641500984,-0.03433421982781848
51.20000000000002,11.503289484643622,0.026811910259023075,-0.03414551428892665
52.400000000000034,12.041977166946786,0.039462829129225274,-0.03563183548649018
53.60000000000005,12.525537862141203,0.04343326538207393,-0.03682606777243436
54.80000000000007,12.980842720616849,0.04801482842160909,-0.03698317739170598
56.000000000000085,13.4234672645776,0.05085414288209422,-0.034506896783362606
57.2000000000001,13.859606308600476,0.053100666213583225,-0.03718480413838687
58.40000000000012,14.292891414167448,0.05639498079740579,-0.03572571724841467
59.600000000000136,14.71143514409139,0.056405232925081705,-0.03854822626323262
60.80000000000015,15.136603352100064,0.05844126271092187,-0.03594979658411823
62.00000000000017,15.54547376928869,0.05731489399510359,-0.03912709799475067
63.20000000000019,15.964479219089966,0.06057050207468451,-0.04195031026890117
64.4000000000002,16.378368144414676,0.060408664659579725,-0.04247827615179922
65.60000000000022,16.785107655788288,0.06039109452205138,-0.043155568297426505
66.80000000000024,17.193462996848886,0.06080275560357118,-0.0440027867767796
68.00000000000026,17.59452370765546,0.06157262124258578,-0.048338240131769794
69.20000000000027,18.001616310740438,0.06012966713010914,-0.04728313762391245
70.40000000000029,18.42706587430635,0.058955007052493014,-0.04365726372305723
71.6000000000003,18.80414324983839,0.05874301802426729,-0.05002239101037631
72.80000000000032,19.207550580528025,0.059457962422799104,-0.04946822424375341
74.00000000000034,19.610109705797928,0.05711775954846732,-0.04538863498309631
75.20000000000036,20.013003864315642,0.0592314466245788,-0.04739092924971189
76.40000000000038,20.41903886538157,0.05843119029405519,-0.050783583114410114
77.60000000000039,20.817937567639568,0.05797765063805249,-0.052435673628807855
78.80000000000041,21.211332078364727,0.0575798379868846,-0.053456570250862256
80.00000000000043,21.618908957678066,0.058552530942958314,-0.05036114765451494
81.20000000000044,22.022233926267198,0.05768859765372325,-0.049492029751682765
82.40000000000046,22.423098258461653,0.05650794241637258,-0.05229891625063399
83.60000000000048,22.827043684509658,0.05708040015527338,-0.05150207356875569
84.8000000000005,23.22622521105233,0.05523241677767743,-0.05371996717116634
86.00000000000051,23.62513263607294,0.05712231049453642,-0.053119751318766006
87.20000000000053,24.023413338882,0.05419677786772725,-0.05434370322653326
88.40000000000055,24.42473562894014,0.05471996380280597,-0.05464264878955749
89.60000000000056,24.827002697772,0.06580902136049793,-0.054007186417284636
90.80000000000058,25.226255172314,0.0528677002036505,-0.0598933386940006
92.0000000000006,25.627240689818308,0.052330810168569,-0.05669744490131645
93.20000000000061,26.028124139246376,0.05404435097004534,-0.05611761300539264
94.40000000000063,26.408863167004363,0.05331635432746784,-0.05737367496552892
95.60000000000065,26.821669625574607,0.053796327949426015,-0.05901385138118975
96.80000000000067,27.21910643639547,0.05560764084174008,-0.05879591371200199
98.00000000000068,27.615311652990773,0.05269490484991801,-0.05472319766814415
99.2000000000007,28.01055162267198,0.05145021511772452,-0.06085661089169392
100.40000000000072,28.412210723808045,0.05452378608147024,-0.05818083917191075
101.60000000000073,28.80556374597917,0.05291483710222278,-0.059584600151572076
102.80000000000075,29.204547618264463,0.05421695177651076,-0.060942792791737865
104.00000000000077,29.602572593991866,0.05465777152994755,-0.061214654987605144
105.20000000000078,29.99972144598934,0.05223083347574242,-0.061853025161940245
106.4000000000008,30.392799327289648,0.0513679276175657,-0.06416482960805858
107.60000000000082,30.797694915811313,0.05287711230541958,-0.059429790081439116
108.80000000000084,31.19307850385099,0.05060754594182537,-0.06352072387828134
110.00000000000085,31.587656914124825,0.054898515473090215,-0.06346062275557518
111.20000000000087,31.98483237444838,0.053627785918344606,-0.06327851787033456
112.40000000000089,32.38398704268336,0.0533289375449999,-0.06329031716811695
113.6000000000009,32.77913315561093,0.05522619221191294,-0.06732388300711278
114.80000000000092,33.17715570211687,0.05531925821482908,-0.06703986460125666
116.00000000000094,33.57387504491353,0.05293456955025155,-0.06280892790249215
117.20000000000095,33.97104893940597,0.054154038925882,-0.0664810473111439
118.40000000000097,34.36868603558079,0.05628132536782571,-0.06411185200451719
119.60000000000099,34.76351801051053,0.059068221571097035,-0.06560093223145635
120.800000000001,35.159659559438616,0.05935317784717231,-0.06828200961218656
122.00000000000102,35.55355567317948,0.05899274610622307,-0.06490865607397822
123.20000000000104,35.94744182794453,0.05803955475307676,-0.06908296353111698
124.40000000000106,36.34159412449925,0.05833591151043116,-0.06770420587466042
125.60000000000107,36.73528746007448,0.056251711984842134,-0.06767987498331784
126.80000000000109,37.1315260117545,0.05733474844571529,-0.06909815539831232
128.0000000000011,37.52578882162338,0.05738806564486665,-0.06756983033149488
129.20000000000113,37.92159125489845,0.0585409843683824,-0.07031354607907847
130.40000000000114,38.314007913999326,0.05857448984071678,-0.06820767706250042
131.60000000000116,38.70883042565702,0.059765883874329684,-0.06752721648536841
132.80000000000118,39.10553193301981,0.058321408757194826,-0.07021000621519757
134.0000000000012,39.50086492812997,0.05787479995107092,-0.0713930647822627
135.2000000000012,39.89933142832661,0.06074938464199875,-0.0692206907754187
136.40000000000123,40.29152345572159,0.05989963305792678,-0.07215889628375027
137.60000000000124,40.68484889583423,0.05911026560247623,-0.0708011548387093
138.80000000000126,41.07889683202035,0.05683032172333902,-0.07178007941498432
140.00000000000128,41.4745812014261,0.05722782764034451,-0.06921098154517402
141.2000000000013,41.86698379711552,0.05742376639702573,-0.07312283486998705
142.4000000000013,42.26292874614621,0.05911287405103316,-0.07322874632142806
143.60000000000133,42.65793242104384,0.05904521835245691,-0.0689899099379847
144.80000000000135,43.05085352327808,0.05804880803643564,-0.07203778079205758
146.00000000000136,43.44692172781648,0.05718259151718985,-0.07494596732558811
147.20000000000138,43.844333909584655,0.05765268591295181,-0.07267869065011201
148.4000000000014,44.23333350967056,0.058640752587350686,-0.07407091505387609
149.60000000000142,44.62503769954819,0.06053200307706985,-0.07142546845060949
150.80000000000143,45.0155383997087,0.06031358548330701,-0.0731251530445336
152.00000000000145,45.402174847530915,0.06041699269628287,-0.0740499471000895
153.20000000000147,45.80300242147432,0.059294515590369135,-0.07057260752583971
154.40000000000148,46.184215446143,0.05821414199976982,-0.07697190710316093
155.6000000000015,46.58896391121329,0.06149171244866758,-0.07993934483504894
156.80000000000152,46.979902802212166,0.0626395643329164,-0.07638532181205271
158.00000000000153,47.37034195805345,0.059583216056530164,-0.07572402631964348
159.20000000000155,47.76230616965519,0.05975766215454836,-0.07657007452893971
160.40000000000157,48.154764601389445,0.06111637600578618,-0.07623199073855957
161.6000000000016,48.54805447100562,0.0592585424286321,-0.07383570706252307
162.8000000000016,48.9403250562906,0.060298504516790585,-0.07700700738788147
164.00000000000162,49.33723260451024,0.06084281400733843,-0.07559926820456297
165.20000000000164,49.72903723593728,0.06250864534584355,-0.07589587680643906
166.40000000000165,50.1137335166587,0.06212045839563296,-0.07736226709255156
167.60000000000167,50.50278626711392,0.06181087539086866,-0.07886945267757195
168.8000000000017,50.89640845522378,0.06310253135170302,-0.08066810064086916
170.0000000000017,51.286333086588,0.06097583286029051,-0.07630287786142453
171.20000000000172,51.67505838757138,0.06188230798485983,-0.08056352243106879
172.40000000000174,52.070177855965305,0.06117534534995539,-0.08040991928009689
173.60000000000176,52.46708943714839,0.06247616658409755,-0.07826782139562294
174.80000000000177,52.84801292995594,0.06427123838273635,-0.08106144418626382
176.0000000000018,53.24408906268551,0.06692256182498096,-0.08203115826899054
177.2000000000018,53.63994704642856,0.06686105236296447,-0.08243007423584459
178.40000000000182,54.02743435188238,0.06606296844433762,-0.08106992680366787
179.60000000000184,54.41927211312791,0.06386498634599214,-0.08104955143123949
180.80000000000186,54.809250423102114,0.0654487925063813,-0.08172128038708237
182.00000000000188,55.20168454820767,0.06640412033862492,-0.0842502760864905
183.2000000000019,55.59522936365893,0.06499659513756184,-0.08508812232823804
184.4000000000019,55.98427552765841,0.06604699495170213,-0.08403074847926639
185.60000000000193,56.37497162985712,0.06561156183993633,-0.0833686357045682
186.80000000000194,56.76799328965648,0.06586270072130218,-0.08436025582224893
188.00000000000196,57.158197062719665,0.06476637621716075,-0.08369742283058113
189.20000000000198,57.55182070586,0.06683662059175349,-0.08625715851632165
190.400000000002,57.940125907930565,0.0680504559098764,-0.0851003786500204
191.600000000002,58.332098956057315,0.06825333863678323,-0.08614510323814528
192.80000000000203,58.723753458459164,0.07101524487990513,-0.08797036888616372
194.00000000000205,59.10802550938229,0.06918186692515754,-0.08677642193891888
195.20000000000206,59.500849941497655,0.06884518535328077,-0.090440418718845
196.40000000000208,59.89157796166792,0.0681988298569901,-0.08519071525472466
197.6000000000021,60.2840860031123,0.06756486548255247,-0.08800798190387837
198.80000000000211,60.67346488069542,0.06801787755316563,-0.09094717727253121
200.00000000000213,61.06327344357915,0.06895814137308931,-0.09007562111832002
201.20000000000215,61.45678641605292,0.06733587511947947,-0.09138149014426089
202.40000000000217,61.844834743538776,0.07227421972227427,-0.09123727312859442
203.60000000000218,62.23437822245798,0.0708318282437696,-0.08994554703593227
204.8000000000022,62.61961215710431,0.07086725410286182,-0.08975976028162425
206.00000000000222,63.01299540063656,0.07119590344133325,-0.0915265769147493
207.20000000000223,63.40254043653163,0.07133907873141482,-0.0945733438737939
208.40000000000225,63.79124085727942,0.07272636300308016,-0.09323987881264628
209.60000000000227,64.18083382442985,0.0727336068607326,-0.09579116149726152
210.80000000000229,64.57413798742307,0.07211925767190602,-0.09306106431311578
212.0000000000023,64.96861780126932,0.07326097231459655,-0.09817505214727795
213.20000000000232,65.3542939088373,0.07602031862569364,-0.09815897859497102
214.40000000000234,65.74501997000554,0.07225613451187007,-0.09687492347386861
215.60000000000235,66.13864680432113,0.07302982086264098,-0.10081006762573441
216.80000000000237,66.52613734103369,0.0752740039415889,-0.09724456653261582
218.0000000000024,66.91591751827552,0.07655645613428452,-0.09719018919432942
219.2000000000024,67.30432470105532,0.07671613427973822,-0.1024599120207208
220.40000000000242,67.69362874329134,0.07505386186513124,-0.09926111076571464
221.60000000000244,68.08696879650631,0.07510253070749012,-0.09948630017130844
222.80000000000246,68.47686629488194,0.07505853941316548,-0.10267563442002592
224.00000000000247,68.8642257483024,0.07564058528746648,-0.10078829117197818
225.2000000000025,69.2550005256954,0.07873410926436597,-0.10717799676643747
226.4000000000025,69.64586447226591,0.0763912420228764,-0.10673101383657269
227.60000000000252,70.0314871804506,0.07559948053161764,-0.10574203704739693
228.80000000000254,70.42518965557713,0.07939354056844339,-0.11075562849052911
230.00000000000256,70.81633564707313,0.07790678948542779,-0.10707829670554636
231.20000000000258,71.20268513162091,0.07812320689774088,-0.11302542037220498
232.4000000000026,71.5906157792975,0.07892662968466035,-0.10989509525921637
233.6000000000026,71.98134581639087,0.07961340247259119,-0.11643961709822204
234.80000000000263,72.37674762383578,0.07829982092023285,-0.11443234605862873
236.00000000000264,72.76635977363682,0.08168966780459275,-0.11952153842216884
237.20000000000266,73.15178895819754,0.08088945711922402,-0.1190195625366064
238.40000000000268,73.5439532864576,0.08293456856526066,-0.1215743239418372
239.6000000000027,73.93332663102612,0.08390940875064046,-0.12428019968530668
240.8000000000027,74.32267279193194,0.08734056215192812,-0.1242679696981912
242.00000000000273,74.71443985446217,0.08554649120848273,-0.12655762884144117
243.20000000000275,75.10561224751439,0.09103240676706106,-0.129884063867431
244.40000000000276,75.49638336521492,0.09272231485978427,-0.12906728183471428
245.60000000000278,75.88861164583189,0.09902977254506504,-0.1332222684213722
246.8000000000028,76.28057342229643,0.1013255738686748,-0.1350429320172828
248.0000000000028,76.67088950154641,0.10888731448729946,-0.1370002349276085
249.20000000000283,77.057292377726,0.11221302048487486,-0.14049021868605616
250.40000000000285,77.44913238776452,0.1119459768781175,-0.14124509149948983
251.60000000000286,77.8430901822596,0.11718939329092193,-0.14778892374632235
252.80000000000288,78.23036088210233,0.12645020031962462,-0.14846925002652478
254.0000000000029,78.61771001161068,0.1503903659011991,-0.14875984072095472
255.20000000000292,79.01527322137389,0.1993941191144163,-0.1548953625719358
256.40000000000293,79.39849866387262,0.2278497861284657,-0.15849477866254835
257.600000000003,79.7861148371874,0.20782259715756357,-0.160251650861293
258.80000000000297,80.18008144641601,0.1467414474132839,-0.162795509868225
260.00000000000296,80.57047019323707,0.11433257515240977,-0.16933206115652544
261.200000000003,80.96420109540696,0.10200735784443057,-0.17199756258430643
262.40000000000305,81.35594525263906,0.09790928584593286,-0.17644139911024403
263.60000000000304,81.74525704332437,0.09282929326768544,-0.17990290763830874
264.800000000003,82.13541553363046,0.09397163949273249,-0.1838010674597501
266.00000000000307,82.52297815355091,0.09395508578786163,-0.18758993533845914
267.2000000000031,82.9108592156044,0.09627917954606713,-0.19474789290807104
268.4000000000031,83.30230903974639,0.0961874422298446,-0.20062110402983757
269.6000000000031,83.69547575542802,0.09238589432989097,-0.20427787279563736
270.80000000000314,84.08584254709503,0.09596878822475374,-0.20905728093994647
272.0000000000032,84.47472601964188,0.09356457596608561,-0.21710986127672127
273.2000000000032,84.86737544669784,0.09366566373691149,-0.2143318233208933
274.40000000000316,85.2543684102333,0.09217444072927397,-0.2300011437578875
275.6000000000032,85.6477765889911,0.0914913622075712,-0.23235286937512312
276.80000000000325,86.0360148889438,0.09155853509853976,-0.24023136951342794
278.00000000000324,86.42516974997089,0.08996436387174056,-0.24807159590589656
279.20000000000323,86.81539489778831,0.08948582247704481,-0.25536909362439486
280.4000000000033,87.20715143542105,0.08985552833337684,-0.26543731925668457
281.6000000000033,87.58956814967132,0.0860898882263108,-0.26973007129024484
282.8000000000033,87.98665536471162,0.086454166912635,-0.28211487179246264
284.0000000000033,88.37796055396818,0.0877192785282089,-0.28817504970565855
285.20000000000334,88.76982390633712,0.08845568031193868,-0.2975514763403386
286.4000000000034,89.15713477111854,0.08794558697266718,-0.3143099626875987
287.6000000000034,89.54999667746861,0.08704460285353766,-0.32093629052515205
288.80000000000337,89.9438407397079,0.09039812041112011,-0.33333309526677724
290.0000000000034,90.33262830899733,0.08993670601800041,-0.3437696497891398
291.20000000000346,90.72251148622317,0.08746206200494545,-0.3515134906712767
292.40000000000344,91.11601833628045,0.0873753469385494,-0.3651711235720545
293.60000000000343,91.50973424816952,0.08662034300833828,-0.3785785840439089
294.8000000000035,91.90000371824449,0.08728710944402837,-0.39239452686809084
296.0000000000035,92.29182359624005,0.08726309422507705,-0.40402279871500113
297.2000000000035,92.68154314602386,0.0942562388575417,-0.42176494591536073
298.4000000000035,93.07191890140594,0.09534028736794846,-0.4370975754877091
299.60000000000355,93.46387924998373,0.10104431921139084,-0.4563300896318374
300.8000000000036,93.85733527056068,0.10564571272094476,-0.475614242844006
302.0000000000036,94.252107103222,0.1123016915704945,-0.48638315531905496
303.20000000000357,94.64118676195402,0.12285110479260167,-0.5121590856862186
304.4000000000036,95.03361922709682,0.1364044485050563,-0.5371583787685168
305.60000000000366,95.42372506233517,0.1454431103998631,-0.5539774138943403
306.80000000000365,95.81389965174832,0.15149585285961834,-0.5763071736593104
308.00000000000364,96.20408697907779,0.1604091177338774,-0.6009690348830579
309.2000000000037,96.59999683219286,0.17023293205866297,-0.6283125984686722
310.40000000000373,96.98981811321345,0.17788201135720252,-0.654023731028949
311.6000000000037,97.38332655144012,0.18277448378537497,-0.6867496367248687
312.8000000000037,97.77847727970432,0.1886450886778125,-0.715998186688239
314.00000000000375,98.17345330960815,0.19799508888269987,-0.7509079071971563
315.2000000000038,98.56434964182668,0.20908057374921896,-0.7853119310465533
316.4000000000038,98.94787661335131,0.2172784714233174,-0.8196826366115042
317.6000000000038,99.344149751597,0.22408771900069785,-0.8593495637734767
318.8000000000038,99.73937172206632,0.23982887579110213,-0.9038591679573456
320.00000000000387,100.12995222157055,0.24671099977130187,-0.9459686207426152
321.20000000000385,100.52258550863188,0.25839567086343196,-0.9906031847732235
322.40000000000384,100.9124087152281,0.27337782280755085,-1.0472951098338892
323.6000000000039,101.30841552388083,0.2849789944395595,-1.1009319488535518
324.80000000000393,101.69810402551911,0.2969243742177922,-1.1544796623726041
326.0000000000039,102.09210676565135,0.31240883054898627,-1.2151514439110125
327.2000000000039,102.4871144615858,0.3235712840998254,-1.2842250691756307
328.40000000000396,102.88176156311881,0.3357636626033415,-1.355914227504969
329.600000000004,103.27858420166102,0.34237513138420755,-1.4277143176834932
330.800000000004,103.66836960207749,0.3447685594680054,-1.504332674952182
332.000000000004,104.05926935127765,0.3429339947199161,-1.5813429549117615
333.200000000004,104.45382454991436,0.33437804312687325,-1.6575295500438139
334.40000000000407,104.84723809113585,0.32855613949046064,-1.7350960130942354
335.60000000000406,105.23534543231692,0.31344034375594776,-1.8080473042437326
336.80000000000405,105.62349222351537,0.3008225737059451,-1.8811328846090603
338.0000000000041,106.01312192327434,0.27822538315680545,-1.9507596055684893
339.20000000000414,106.39964788262617,0.256063221407105,-2.0178451846813195
340.4000000000041,106.79618832721056,0.22724119294053885,-2.077927814941702
341.6000000000041,107.18993655537093,0.1988693655621791,-2.1326485022028567
342.80000000000416,107.58161420043348,0.17226797294114712,-2.1860917270130074
344.0000000000042,107.97341918963332,0.14333853919481185,-2.228805976702773
345.2000000000042,108.36931502090624,0.11960857628730237,-2.2672388059678523
346.4000000000042,108.75550532885823,0.09952783716881211,-2.299249846798463
347.60000000000423,109.14344105329354,0.08076626261875676,-2.3265805263396757
348.8000000000043,109.53880520447268,0.06379273842742775,-2.350955043828594
350.00000000000426,109.92886703356807,0.04895422816225534,-2.371730271376321
351.20000000000425,110.32633118092107,0.0431420174910938,-2.390137241592476
352.4000000000043,110.71345278256274,0.03689578892445209,-2.405384689124026
353.60000000000434,111.11303392775301,0.03238889619037033,-2.4197073534292275
354.80000000000433,111.50238721012356,0.029304648550001176,-2.4369137152578024
356.0000000000043,111.89682051913762,0.02444357665640267,-2.44421964283801
357.20000000000437,112.29014265104657,0.024002699868552548,-2.4610007250992547
358.4000000000044,112.6822230917391,0.02209432197584145,-2.471179680535971
359.6000000000044,113.07843685901437,0.019091906973389798,-2.4812979028670448
360.8000000000044,113.47102872069172,0.02011724336235152,-2.4945399068321956
362.00000000000443,113.86384831619671,0.016918851318686822,-2.505871310754438
363.2000000000045,114.25953222698486,0.01690812141537208,-2.5163536554089614
364.40000000000447,114.65181876769714,0.017824574486485868,-2.5294526154176045
365.60000000000446,115.03523483474665,0.019146138709023812,-2.539809811454009
366.8000000000045,115.43497598011398,0.01992974029973686,-2.5520885923225634
368.00000000000455,115.83239416991917,0.018425103168255953,-2.5626418105910185
369.20000000000454,116.22705543195649,0.017565108588004266,-2.574773688133556
370.4000000000045,116.61738324205636,0.017712369966328252,-2.5853591986025455
371.60000000000457,117.01470865730164,0.015846026635681357,-2.600183864380496
372.8000000000046,117.4101144989957,0.01790434148695016,-2.6110676606310337
374.0000000000046,117.80308423310758,0.019340198704072834,-2.622568786425199
375.2000000000046,118.19816393736961,0.018271232315591038,-2.6374944033029397
376.40000000000464,118.59157232493337,0.018020044566225725,-2.650371949809342
377.6000000000047,118.98918710810207,0.01720522542317402,-2.6607339370605496
378.8000000000047,119.38222055145765,0.017748916543170838,-2.6755464591054126
380.00000000000466,119.78001366651634,0.01486866783331927,-2.6898237000377243
381.2000000000047,120.17397328271095,0.018686407396066244,-2.706004763546134
382.40000000000475,120.5657439590563,0.016497352013186375,-2.721228724966603
383.60000000000474,120.96178542197381,0.01770780289175211,-2.7364294180544824
384.80000000000473,121.3531088391963,0.019159170461026193,-2.7532943755494337
386.0000000000048,121.745679966254,0.019499541118119364,-2.7626206570250034
387.2000000000048,122.14002297529365,0.019684930547993085,-2.7821156428840887
388.4000000000048,122.53433890848018,0.0213498417978085,-2.8023947527179924
389.6000000000048,122.92720164871895,0.023323590659833,-2.8209103065871313
390.80000000000484,123.32667707684136,0.022697457259524365,-2.8391382788308075
392.0000000000049,123.72384126066721,0.02550231551704507,-2.858131594090404
393.2000000000049,124.12496135748201,0.02418073540403591,-2.8766631080357445
394.40000000000487,124.51636562470098,0.024358580701488886,-2.8993110791634473
395.6000000000049,124.91382943700137,0.029403734487085678,-2.9218102909359542
396.80000000000496,125.3082350062622,0.02897836261829756,-2.940494385488808
398.00000000000495,125.700000000002,0.02871210174759363,-2.9614038683081274
399.20000000000493,126.09790504432863,0.02774870812363303,-2.9864888169876864
400.400000000005,126.4915473383394,0.027377356888403342,-3.006855756134647
401.600000000005,126.89049359218147,0.02731354619621515,-3.0285042463395597
402.800000000005,127.2908212889902,0.02927248797384388,-3.0540350426286693
404.000000000005,127.68446803241922,0.024916973635061207,-3.075933286941293
405.20000000000505,128.08042507405565,0.03041376816369369,-3.1008433032268017
406.4000000000051,128.4755215505912,0.028945284669300478,-3.1132230624527706
407.6000000000051,128.86958704190423,0.031346315271104375,-3.138370167380483
408.80000000000507,129.26266592305055,0.027936015057397734,-3.1595266864641673
410.0000000000051,129.65380803546904,0.02804134644119366,-3.173989465093178
411.20000000000516,130.05190369790097,0.0250555164307798,-3.1937911606558265
412.40000000000515,130.4463302641282,0.022476278933415278,-3.2115493129114507
413.60000000000514,130.84672498237316,0.024325737704879447,-3.2323926542459205
414.8000000000052,131.24065725820043,0.019840455196423135,-3.2431323402598498
416.00000000000523,131.63747950288456,0.018618744231093665,-3.258491647421386
417.2000000000052,132.03079276131328,0.01810779489286435,-3.2711244654736786
418.4000000000052,132.42571099248806,0.017566599066748123,-3.2864406241399955
419.60000000000525,132.82160278220456,0.014576861467143487,-3.296897153681308
420.8000000000053,133.21667287305834,0.009317742853338584,-3.3067010715451137
422.0000000000053,133.60951131124784,0.006694719418173317,-3.3188772527243517
423.2000000000053,134.00815350444992,0.005475461432538187,-3.334990885337574
424.4000000000053,134.40505881088478,0.0004798334743117971,-3.3394848396500625
425.60000000000537,134.80368585205247,-0.0015198117137870948,-3.3511523772099174
426.80000000000535,135.19967002447504,-0.009410799096841449,-3.3593079199263194
428.00000000000534,135.59835468361536,-0.01333925839751901,-3.3641273488057397
429.2000000000054,136.00024831144685,-0.011174421092593034,-3.377472017268397
430.40000000000543,136.39376006885075,-0.016116881429708407,-3.3790021593051884
431.6000000000054,136.78543435403157,-0.014744051599282298,-3.3888914847941765
432.8000000000054,137.1794008487448,-0.01911056833827507,-3.394470452073468
434.00000000000546,137.57752321595237,-0.017205725679330847,-3.4017856195458025
435.2000000000055,137.96805511960713,-0.024183210907855024,-3.4070169887484694
436.4000000000055,138.36509468444757,-0.021635121952078423,-3.4138531266131533
437.6000000000055,138.76268067056395,-0.029938923762230646,-3.4175819530321223
438.8000000000055,139.16084991527802,-0.03067063106089346,-3.4225864096694134
440.00000000000557,139.55822127622548,-0.03389826640394453,-3.4254610782697954
441.20000000000556,139.95277167395878,-0.03337340302095032,-3.4307907321227136
442.40000000000555,140.35611220435973,-0.0356733112758999,-3.4347263302280577
443.6000000000056,140.75386147087076,-0.041353362631215224,-3.434060262096246
444.80000000000564,141.15273906605177,-0.03786537003319787,-3.444376367542916
446.0000000000056,141.54860134478295,-0.04016035197682105,-3.4430469631175384
447.2000000000056,141.94596018183964,-0.03882408764911924,-3.4480031160209874
448.40000000000566,142.34268979159992,-0.03276968175573031,-3.4507303538670135
449.6000000000057,142.73957587867233,-0.029914016467136262,-3.4519297735851273
450.8000000000057,143.1355340252845,-0.027306639105981412,-3.456868865392969
452.0000000000057,143.5354328085753,-0.025019394171296172,-3.460370479979579
453.20000000000573,143.93261864679533,-0.018348837381259808,-3.459070017336788
454.4000000000058,144.32913528525395,-0.014370983237269264,-3.464229013286408
455.60000000000576,144.7243398820433,-0.009631846039274083,-3.4646343147799197
456.80000000000575,145.12229783886065,-0.012629253239888893,-3.4694624516149766
458.0000000000058,145.51954110980728,-0.013013813831429022,-3.469251637590641
459.20000000000584,145.91776605402032,-0.013746971714004907,-3.471131641919082
460.40000000000583,146.31416869361428,-0.017644882413007545,-3.4756743680267403
461.6000000000058,146.7150782835921,-0.016935931299474016,-3.4746020869378773
462.80000000000587,147.11300631854996,-0.01988886649600735,-3.4746426889795394
464.0000000000059,147.50966430510132,-0.028535893397749423,-3.480005203432614
465.2000000000059,147.9067245714327,-0.033522750536863655,-3.4762841148580375
466.4000000000059,148.29962629720083,-0.035086649643400025,-3.4850598649984494
467.60000000000593,148.7088713674383,-0.03989427566116044,-3.4845195638082664
468.800000000006,149.09856789627187,-0.04252350958075024,-3.480665383512727
470.00000000000597,149.50693112527406,-0.041807028831573945,-3.4871509829760887
471.20000000000596,149.90276603997074,-0.04262826418172472,-3.486819843002957
472.400000000006,150.29562792534534,-0.04757052215460489,-3.487479646392889
473.60000000000605,150.69396021813532,-0.04754051925071878,-3.487129610407183
474.80000000000604,151.09251887636614,-0.04838503748208273,-3.4890092999480613
476.000000000006,151.49199760463446,-0.05007931202420862,-3.488013530472431
477.20000000000607,151.88629165491494,-0.05311739271252652,-3.494694242380249
478.4000000000061,152.2881797502003,-0.051041580904758244,-3.4927178217038146
479.6000000000061,152.69104196179657,-0.053761314364119905,-3.494073343376175
480.8000000000061,153.09051179666832,-0.05590379297747594,-3.4955290284369527
482.00000000000614,153.49276052135434,-0.058073413220326386,-3.499458146521456
483.2000000000062,153.89250405284696,-0.060343551532072714,-3.500927021687177
484.4000000000062,154.28960001726244,-0.058072101670745224,-3.5029769124494528
485.60000000000616,154.69023767814053,-0.06026842631695373,-3.5011885914941616
486.8000000000062,155.08905908812972,-0.05891956761943962,-3.5049758838215785
488.00000000000625,155.48623789908305,-0.058572114823473354,-3.504695488368741
489.20000000000624,155.8846475829967,-0.06202241126546104,-3.503244844359906
490.40000000000623,156.28688648969816,-0.06254970072429178,-3.5039379709818697
491.6000000000063,156.6895145647355,-0.06364100030164549,-3.508860050733607
492.8000000000063,157.08648563348032,-0.06487484482622347,-3.508414977460864
494.0000000000063,157.48513364390695,-0.06803164620237473,-3.5088681223003073
495.2000000000063,157.88589827295195,-0.06659354082970603,-3.5098493800139616
496.40000000000634,158.2877417928358,-0.06933575461952923,-3.512154653879379
497.6000000000064,158.68912498240553,-0.06725076444898415,-3.5148304229058542
498.8000000000064,159.08826321606773,-0.06927925466193341,-3.5144593763226286
500.00000000000637,159.48776960846672,-0.0684208367175636,-3.5160930558133505
501.2000000000064,159.88476726445077,-0.07254794172946077,-3.51566900737591
502.40000000000646,160.2844476733597,-0.07274561572838928,-3.517806081083779
503.60000000000645,160.68687965114654,-0.07693011704221758,-3.520594317707181
504.80000000000643,161.08814067749356,-0.0807136080537238,-3.519097978559454
506.0000000000065,161.48772241990872,-0.07849725136470026,-3.5213758915775317
507.2000000000065,161.8866447355017,-0.08025972418139399,-3.52399966330935
508.4000000000065,162.28571799951544,-0.08466973991918214,-3.5210041543584927
509.6000000000065,162.68124243866498,-0.08616230207655695,-3.525310133426772
510.80000000000655,163.08433375963796,-0.08440135233573354,-3.5262521287431374
512.0000000000066,163.48507251202776,-0.08537662952416497,-3.5224645520528384
513.2000000000066,163.88701297290808,-0.09047454777442171,-3.529474777499984
514.4000000000066,164.28891487455647,-0.08674488110110556,-3.530261540635954
515.6000000000066,164.68415524042274,-0.0902260222964047,-3.530295419197797
516.8000000000067,165.087600929492,-0.09495302852349158,-3.5316872758641793
518.0000000000066,165.48681947113653,-0.0971518053656838,-3.532782486647524
519.2000000000066,165.88864919344465,-0.10110161178085303,-3.530859762581897
520.4000000000067,166.2938243618752,-0.09613769466498062,-3.5312833124602827
521.6000000000067,166.68997993663254,-0.10148682370230672,-3.530633234941872
522.8000000000068,167.094579472894,-0.10074283525705346,-3.533825592572823
524.0000000000067,167.4941479782875,-0.09661012586390316,-3.5368273297487964
525.2000000000068,167.89564741822923,-0.10130470552343357,-3.535526862172362
526.4000000000068,168.29626814039418,-0.09886735964178534,-3.5395361553155658
527.6000000000067,168.6960129350267,-0.09786489157425637,-3.5382683246178814
528.8000000000068,169.0909871828204,-0.09487288028318647,-3.538258859587853
530.0000000000068,169.4925656839392,-0.09486660201043806,-3.5382626761495004
531.2000000000069,169.8951704893092,-0.09864488413222916,-3.5431884300331653
532.4000000000069,170.2975906004016,-0.09951499017604909,-3.540960923950265
533.6000000000068,170.69831272648497,-0.10188712960975932,-3.539425249427075
534.8000000000069,171.1024001709174,-0.09996393316283031,-3.5427760229378844
536.0000000000069,171.50359642247975,-0.09923951482441373,-3.5447170769652536
537.2000000000069,171.90175375629195,-0.10139651814632633,-3.542133273583416
538.4000000000069,172.303440614754,-0.10339921552331938,-3.545170015807917
539.600000000007,172.70587128134997,-0.10107213388112807,-3.5478167391066244
540.800000000007,173.09960907198064,-0.1031577545611046,-3.5451698410667856
542.000000000007,173.49927981541393,-0.1027749459352244,-3.54649289560685
543.200000000007,173.9019956500957,-0.10164313629803534,-3.5491388897582956
544.400000000007,174.29354946837782,-0.1018879095306493,-3.5467845353270064
545.6000000000071,174.70164301481276,-0.09620822714278199,-3.5514075099111313
546.800000000007,175.10836097146273,-0.09412242240004953,-3.551078519073347
548.000000000007,175.5045086095012,-0.08723684112762209,-3.5509699520865787
549.2000000000071,175.9041846685952,-0.0801872325038977,-3.5520538365186973
550.4000000000071,176.3061853125919,-0.07705998844619966,-3.551969957798975
551.6000000000072,176.7098620527873,-0.06369612733421948,-3.556263744943273
552.8000000000071,177.10563327396295,-0.048438178149915356,-3.5549884919677175
554.0000000000072,177.50694022804623,-0.03758889803375309,-3.55882721988098
555.2000000000072,177.90778405616913,-0.03263695487373408,-3.559531386863819
556.4000000000071,178.31005745712494,-0.03539520761094417,-3.560424063801392
557.6000000000072,178.7133380628512,-0.03612999903176972,-3.5621895449607317
558.8000000000072,179.116997425204,-0.03780339925932219,-3.564480232058395
560.0000000000073,179.517020193146,-0.04399598079190681,-3.5670062617105147
561.2000000000073,179.91586250143655,-0.0486212530256388,-3.567384688352726
562.4000000000073,180.3199528873734,-0.055838424643060325,-3.56809976457496
563.6000000000073,180.71908785218994,-0.06310830431178305,-3.5688528469385354
564.8000000000073,181.1210821167429,-0.06445317557640384,-3.5688081991024285
566.0000000000073,181.53096146302133,-0.07288624360719498,-3.5737694943294516
567.2000000000073,181.93502118039453,-0.08783911657311338,-3.568564181947211
568.4000000000074,182.33638013356708,-0.09483581113527295,-3.5704008391115467
569.6000000000074,182.74002656335816,-0.09913371998497067,-3.572345198560992
570.8000000000075,183.14515574617582,-0.10292233738432166,-3.5750315628669123
572.0000000000074,183.54731571888962,-0.10069979414290897,-3.5788400167290835
573.2000000000074,183.9429770685516,-0.10540735741296137,-3.5711782635272273
574.4000000000075,184.34359415079524,-0.10300559325135805,-3.5785099885901483
575.6000000000074,184.75000699778158,-0.09981621456517087,-3.577554696306369
576.8000000000075,185.1554450820378,-0.09799848502177722,-3.5766624797743125
578.0000000000075,185.5573308338856,-0.09982220060943436,-3.5773014258740212
579.2000000000075,185.95879342173086,-0.09624358299660263,-3.580389913601225
580.4000000000076,186.36095783399222,-0.0943510681087788,-3.58034489040224
581.6000000000075,186.76391673826888,-0.09219208912127175,-3.5803800926044773
582.8000000000076,187.16442682958714,-0.09248731533979071,-3.580334188316806
584.0000000000076,187.56167755987036,-0.09379613324115232,-3.5830221348895304
585.2000000000075,187.96666668962166,-0.09050814413934061,-3.5834298967076363
586.4000000000076,188.37102214896865,-0.08871143228727729,-3.5849887484634095
587.6000000000076,188.77298752117184,-0.08836884522663924,-3.5825116880056047
588.8000000000077,189.172935717815,-0.08663159068872817,-3.585427319234254
590.0000000000077,189.5764090084561,-0.08701981546351345,-3.5838782680029193
591.2000000000077,189.97812714871185,-0.08220718690828455,-3.5881271477259093
592.4000000000077,190.37684055732115,-0.08319181679135845,-3.584668265666811
593.6000000000078,190.7790229140388,-0.08117257363424157,-3.584649483314254
594.8000000000077,191.18592730414505,-0.08538799873124148,-3.5873995684648943
596.0000000000077,191.59623203538428,-0.08280623583017344,-3.588428189208634
597.2000000000078,192.00280303207953,-0.08027538969263603,-3.5907043948084567
598.4000000000078,192.4038680150261,-0.0816861310803979,-3.5867639264266353
599.6000000000079,192.8093822887195,-0.07954938749003282,-3.589296825258144
600.8000000000078,193.21308100082442,-0.08150547767128602,-3.5878891194158635
602.0000000000078,193.61198448162355,-0.07593242062020666,-3.591915408887636
603.2000000000079,194.01603395437334,-0.08126847884934518,-3.592526884995735
604.4000000000078,194.41284818538062,-0.07684862667061498,-3.5932475929264385
605.6000000000079,194.81629877889722,-0.07666130976763819,-3.59199981176355
606.8000000000079,195.22174937685676,-0.07614836828444571,-3.5921900214590123
608.000000000008,195.62288388530354,-0.07435388588956571,-3.591296517351884
609.200000000008,196.02694134696299,-0.07475254097918471,-3.593751081106662
610.4000000000079,196.43608352024057,-0.07349525604791463,-3.5952848587497312
611.600000000008,196.8365355148704,-0.07471600435261871,-3.5923523948827305
612.800000000008,197.2375370700851,-0.07619080317388904,-3.5970583544625545
614.000000000008,197.6409591262575,-0.07517547767856325,-3.593014256000505
615.200000000008,198.04544469051675,-0.0766836736566815,-3.5927905612295876
616.400000000008,198.44999314867025,-0.07672422694562209,-3.5973782528467346
617.6000000000081,198.85757672149856,-0.07925712854133315,-3.5970980675020905
618.8000000000081,199.26263150137535,-0.07788825720846015,-3.59573598428388
620.0000000000081,199.66518075630987,-0.07839487964898595,-3.5996822526663417
621.2000000000081,200.0680619745835,-0.07571693718859596,-3.59803988060075
622.4000000000082,200.47332380305747,-0.07839579922020079,-3.5995600177724913
623.6000000000081,200.86438566428723,-0.07075716513764763,-3.60101006019719
624.8000000000081,201.27912486515967,-0.0758138400629822,-3.597416830195376
626.0000000000082,201.68553567329516,-0.07483687541154482,-3.602818213204334
627.2000000000082,202.09223010391096,-0.07549481970444938,-3.600129925001425
628.4000000000083,202.493210142162,-0.07420452013754919,-3.600259458456183
629.6000000000082,202.90035325189413,-0.07806948952569981,-3.601550215917624
630.8000000000083,203.30354254943353,-0.07775505055152565,-3.6015538859766867
632.0000000000083,203.7063557036428,-0.07739183690012941,-3.6021945957189194
633.2000000000082,204.10957549760144,-0.07746354636483577,-3.600238692450084
634.4000000000083,204.50924822665692,-0.07942865307116165,-3.6028572659973954
635.6000000000083,204.91559006718563,-0.07654595511085216,-3.6011890153091457
636.8000000000084,205.3217833404691,-0.0783632430452893,-3.603102900225951
638.0000000000084,205.72146935215298,-0.0745979145228911,-3.602758178967532
639.2000000000083,206.1265995507663,-0.07509280875353475,-3.605060199605008
640.4000000000084,206.5297177108985,-0.07630954098189469,-3.6037502020118275
641.6000000000084,206.93719701850026,-0.07791830537483968,-3.607682253275099
642.8000000000084,207.34012198429105,-0.07918164081199719,-3.6029522236480624
644.0000000000084,207.7427392831728,-0.07781813467576992,-3.607085757827499
645.2000000000085,208.1418083871152,-0.07728557320584584,-3.6045814538513667
646.4000000000085,208.5482834289984,-0.08391290728809175,-3.6036268189424043
647.6000000000085,208.95316039294897,-0.08178203936661388,-3.6106619972461296
648.8000000000085,209.36043411614344,-0.08071762230485025,-3.607041238777613
650.0000000000085,209.7669978892749,-0.08335288862190038,-3.608789982281041
651.2000000000086,210.1694894674945,-0.08490196527488614,-3.6060710678074894
652.4000000000085,210.56868237614358,-0.0874849020827726,-3.608066008783402
653.6000000000085,210.97393435978282,-0.08399368352187642,-3.6092109962471755
654.8000000000086,211.38020199628613,-0.08480350520894775,-3.610539971593326
656.0000000000086,211.7851881452564,-0.08612816995600792,-3.6089055893123163
657.2000000000087,212.19012707757255,-0.08070608570529347,-3.6132884160414585
658.4000000000086,212.5920127243337,-0.08707049157205393,-3.6129857452949503
659.6000000000087,213.00033682167276,-0.0808445090997949,-3.613793341734019
660.8000000000087,213.40065614050437,-0.08483617283899392,-3.6102124277766188
662.0000000000086,213.8050000981245,-0.08593162008644328,-3.6128151849842
663.2000000000087,214.2076409424028,-0.08800621352550175,-3.612157495847609
664.4000000000087,214.60662902375867,-0.08999543248467323,-3.6140825447912013
665.6000000000088,215.01318434311312,-0.08961861174979524,-3.614997861562075
666.8000000000088,215.4225738652709,-0.09044005366081342,-3.6138933332454615
668.0000000000088,215.82881490619064,-0.0889883129829756,-3.615511211059201
669.2000000000088,216.23262540848026,-0.08981983291511475,-3.6137701194986844
670.4000000000088,216.63332268485524,-0.08706214717344118,-3.6197544247726716
671.6000000000088,217.04278001156285,-0.09527264852337325,-3.613424689009257
672.8000000000088,217.44735780590707,-0.0939161320234152,-3.6170028155358978
674.0000000000089,217.8524836176938,-0.09602302323106415,-3.6172797756663075
675.2000000000089,218.2565752936636,-0.09582543647412733,-3.61563957411751
676.400000000009,218.65453234997355,-0.09820419974891403,-3.621619279990649
677.6000000000089,219.06156147534566,-0.09700978673990801,-3.6200642324296695
678.8000000000089,219.4655280338182,-0.10229168915900488,-3.6153749631572842
680.000000000009,219.8718784987428,-0.10464546068077896,-3.6191230808505215
681.2000000000089,220.27977424856746,-0.10778537093334872,-3.6189322304124496
682.400000000009,220.68518566764416,-0.11222835044421542,-3.6162168016534375
683.600000000009,221.0822578009482,-0.10962342805925629,-3.621239971722912
684.800000000009,221.49082881732815,-0.10718751342694266,-3.6192491989518065
686.0000000000091,221.8960605470364,-0.11004472785323771,-3.6212984261347634
687.200000000009,222.2987786889861,-0.10950825584962831,-3.6240039810437077
688.4000000000091,222.69852571549166,-0.1069863433719116,-3.6201419455641144
689.6000000000091,223.10698624075974,-0.1067869487717612,-3.6214253265482683
690.800000000009,223.51152871124384,-0.10886960918380684,-3.6227948021960032
692.0000000000091,223.91453472115558,-0.10967321511635064,-3.6221433281983364
693.2000000000091,224.31984721929368,-0.11406671762257892,-3.621309276656186
694.4000000000092,224.7257238586068,-0.11484000951934559,-3.624051043338834
695.6000000000092,225.1333372549807,-0.11501907010268497,-3.6239619417011175
696.8000000000092,225.53735471763554,-0.11635767453124979,-3.6214161300676677
698.0000000000092,225.94004306252637,-0.11924918085716985,-3.6228305824015745
699.2000000000093,226.3435346162899,-0.11737786924310956,-3.624140300655859
700.4000000000092,226.75107086267008,-0.11869074688144421,-3.626449960907119
701.6000000000092,227.15372047997846,-0.11978026209332882,-3.625128684792135
702.8000000000093,227.55670455625574,-0.11977589747801476,-3.6277777693723636
704.0000000000093,227.96558528065242,-0.1219633756080154,-3.6255694471042315
705.2000000000094,228.37430057097004,-0.12731696173110763,-3.625240157221502
706.4000000000093,228.7793760451823,-0.1311133040992014,-3.628263347508005
707.6000000000093,229.18294965732656,-0.13034681137483983,-3.62458114135228
708.8000000000094,229.5862069154623,-0.13072216847105822,-3.627581542605034
710.0000000000093,229.99410242419543,-0.13666803429265095,-3.6255438135187275
711.2000000000094,230.39910312180507,-0.1358221881920041,-3.6254696175280063
712.4000000000094,230.80184954949962,-0.13555042509197257,-3.6288400997868386
713.6000000000095,231.20984062614485,-0.14115680000946362,-3.6305396299803943
714.8000000000095,231.61498861028775,-0.14105291630711947,-3.6273054064267485
716.0000000000094,232.01571598077635,-0.1427737366275521,-3.632534286074919
717.2000000000095,232.41924895040648,-0.1425459058951073,-3.631494715857996
718.4000000000095,232.82613099886447,-0.14783774503057723,-3.630497345427906
719.6000000000095,233.23631867772414,-0.14916145726174768,-3.6301789638211233
720.8000000000095,233.64279069194984,-0.1498888090003534,-3.630171719889704
722.0000000000095,234.0435586657159,-0.15334898282379128,-3.631496904308685
723.2000000000096,234.45221534263118,-0.15204477562209529,-3.6328098369119926
724.4000000000096,234.85779039490114,-0.15515431368754884,-3.6298716252996694
725.6000000000096,235.26238354152528,-0.1604812533321982,-3.6328803163503336
726.8000000000096,235.66888217973488,-0.1604856178699252,-3.632407890042329
728.0000000000097,236.0750170818094,-0.15959748134528073,-3.6308331683371415
729.2000000000096,236.48231442356405,-0.1559557717437663,-3.633459915430517
730.4000000000096,236.8927063597225,-0.1611313559094818,-3.6318261297965515
731.6000000000097,237.29709006572264,-0.16268826789947877,-3.633003366135857
732.8000000000097,237.70511217082625,-0.17109048451172648,-3.633982721225215
734.0000000000098,238.10685253079197,-0.16531289712042319,-3.6346836450356017
735.2000000000097,238.515344656033,-0.16797365860028513,-3.635660618033027
736.4000000000098,238.9211260575598,-0.17500373607053543,-3.631281533043542
737.6000000000098,239.3235278371749,-0.17847064976803018,-3.6375872883862783
738.8000000000097,239.73076031174202,-0.18321835809491138,-3.629326164919152
740.0000000000098,240.1366986109008,-0.1801104283156585,-3.635205867130968
741.2000000000098,240.53871558291223,-0.18143893478579454,-3.632658293388795
742.4000000000099,240.9459225597688,-0.1768731252070599,-3.6367260190551036
743.6000000000099,241.35154360200167,-0.1843557940285434,-3.6355531689735043
744.8000000000098,241.75688018794054,-0.18353365114870712,-3.6381760951423057
746.0000000000099,242.16483921436995,-0.18652795952537327,-3.635426472587799
747.2000000000099,242.5683391163291,-0.18175622358967725,-3.6370829277307157
748.4000000000099,242.97474497352562,-0.18708060597850595,-3.6377423835060663
749.6000000000099,243.3806138594928,-0.19014763683873803,-3.6396993422106494
750.80000000001,243.7930482379466,-0.190314071916603,-3.634389763139156
752.00000000001,244.20354802664465,-0.19350989234208194,-3.6367086747625503
753.20000000001,244.60475235941576,-0.1912107555153344,-3.6392778964172354
754.40000000001,245.00432127450367,-0.18935132733748095,-3.6414895649014576
755.60000000001,245.4118236154141,-0.18298610516922031,-3.6362811025036517
756.8000000000101,245.81596453833484,-0.18828783706895202,-3.6374237408277184
758.00000000001,246.21952050120063,-0.1865265775066718,-3.640432094667154
759.20000000001,246.62931664010543,-0.1845662419443983,-3.640665900181536
760.4000000000101,247.03385799602785,-0.18746775903354407,-3.6405614472719687
761.6000000000101,247.43939220239156,-0.18945409764957155,-3.638289875532633
762.8000000000102,247.84784946879066,-0.19079238137746057,-3.6422597885196804
764.0000000000101,248.2541083275965,-0.19077938459119936,-3.639538348018395
765.2000000000102,248.66018870662313,-0.19128845217821944,-3.6371036683194338
766.4000000000102,249.06822203585992,-0.195976239654283,-3.6447205629300545
767.6000000000101,249.47593998226117,-0.1985659684277188,-3.6392179309675527
768.8000000000102,249.8802402582363,-0.1967667479654216,-3.6433399767295174
770.0000000000102,250.28563686893892,-0.19253240070511612,-3.6431990036121036
771.2000000000103,250.69151105884185,-0.20056948703322663,-3.6414329652065414
772.4000000000103,251.09891320307906,-0.19718422761561638,-3.6403139741200827
773.6000000000103,251.50546451177712,-0.19640437623696716,-3.6416991444380202
774.8000000000103,251.91110815275098,-0.1974523865810014,-3.6420259092752207
776.0000000000103,252.32403767958016,-0.19712613439910354,-3.641091046258935
777.2000000000103,252.725265153452,-0.1985060616349641,-3.6426186003476424
778.4000000000103,253.13047461724358,-0.195642765127102,-3.6412319786646257
779.6000000000104,253.54171775975772,-0.19938188412567692,-3.642391992064161
780.8000000000104,253.94372580507587,-0.19738805997956654,-3.6419166651227695
782.0000000000105,254.35372859553593,-0.19932500558011323,-3.6437935439603018
783.2000000000104,254.76257030032355,-0.20120549498174944,-3.646615460789845
784.4000000000104,255.17196800336458,-0.19918573893584646,-3.6463456567777293
785.6000000000105,255.5789504627504,-0.20604823295825359,-3.6426737696498543
786.8000000000104,255.98597644054072,-0.20654036320481817,-3.6427027246778287
788.0000000000105,256.39095119173913,-0.20814512411462482,-3.6453197007248286
789.2000000000105,256.797464470358,-0.2055212895945686,-3.6453148192513765
790.4000000000106,257.20479547135864,-0.20129059370049918,-3.64510137317605
791.6000000000106,257.60857648660993,-0.20415850600789875,-3.6451345173094207
792.8000000000105,258.0175420539388,-0.20234632098047767,-3.6437683881411864
794.0000000000106,258.4240244933133,-0.2015705543201789,-3.6466858223970027
795.2000000000106,258.8305717691282,-0.20387987289687892,-3.6449080488630585
796.4000000000106,259.23768617608937,-0.20288800184574685,-3.6474840476046926
797.6000000000106,259.6500065369426,-0.20537353316771423,-3.647849923987039
798.0000000000107,259.7861131827485,-0.2036387136355473,-3.648949829228452