File: 01_Data/Polyester_Carpet_High_Pile/STA/N2/30K_min/Polyester_Carpet_High_Pile_STA_N2_30KData_230926_R3.csv
##Temp./Â°C,Time/min,DSC/(mW/mg),Mass loss/mg
51.0,10.599310281080315,0.026723945114166536,0.024694438389337492
52.20000000000002,10.783038639549883,0.07246821460101494,0.025426126797025717
53.400000000000034,10.907901636693213,0.10776411137281805,0.026477599827350318
54.60000000000005,11.006643203638074,0.13875879179818007,0.027347253239518032
55.80000000000007,11.090581055094322,0.16729081777224586,0.02534265585190898
57.000000000000085,11.169115149111803,0.19621996409055065,0.024959721807357838
58.2000000000001,11.240549355715912,0.21855237507601388,0.02600522979407316
59.40000000000012,11.305666271120492,0.24179431745391478,0.025475684886053784
60.600000000000136,11.367265604058797,0.26222393300729907,0.027621328903745024
61.80000000000015,11.426322742602448,0.2837571509161634,0.02588929108054039
63.00000000000017,11.482249127288476,0.3002204389994554,0.027666659298392737
64.20000000000019,11.537766259981268,0.31682797346788827,0.026459492249764516
65.4000000000002,11.58973562880785,0.3331905586702062,0.025269075143650177
66.60000000000022,11.641459761409857,0.3461574904690199,0.024322943674751407
67.80000000000024,11.692055124092937,0.36151409551304337,0.025611617151350075
69.00000000000026,11.740517029886364,0.3728721479256334,0.026495949844052014
70.20000000000027,11.788993758308322,0.3868410932358719,0.026261974011724476
71.40000000000029,11.83673781470256,0.3996480318615361,0.026164777547855067
72.6000000000003,11.883771013148317,0.41240891147172576,0.025917626341205313
73.80000000000032,11.929961081136172,0.42168335379305555,0.026642366962351005
75.00000000000034,11.97512137104243,0.4340194430562343,0.026056378410411973
76.20000000000036,12.02014625714434,0.44304181130764353,0.026166321399942127
77.40000000000038,12.064810824186653,0.4508950758848309,0.026316089826221578
78.60000000000039,12.108981368294103,0.45988979237433014,0.02627015880448713
79.80000000000041,12.15243366994881,0.4671897735022754,0.028110570939199775
81.00000000000043,12.196350762173633,0.4705465190939955,0.028600054622072157
82.20000000000044,12.238965584492776,0.4706808926218491,0.026724467425552234
83.40000000000046,12.281306416389457,0.47189497532480273,0.02651529898850402
84.60000000000048,12.323537461297299,0.4669597388234137,0.02650619019573952
85.8000000000005,12.365788840077512,0.465319825890131,0.026436283960291185
87.00000000000051,12.407835874058284,0.4647057350280763,0.02646907387771691
88.20000000000053,12.449231587736296,0.4643923100529628,0.026043177488662472
89.40000000000055,12.490517210769113,0.46058402152331324,0.026388652670582324
90.60000000000056,12.532047523973105,0.46115120288351963,0.026322534871160208
91.80000000000058,12.572980163395437,0.46031821990961697,0.026420050098979964
93.0000000000006,12.614409202448355,0.46077617796728476,0.02733668156479041
94.20000000000061,12.654522482707327,0.46127619957558386,0.026346633522589258
95.40000000000063,12.695237404784626,0.4577667911149641,0.026367267146850004
96.60000000000065,12.735876404470336,0.45999240295500265,0.026408603034499656
97.80000000000067,12.776219661568147,0.46096340918786294,0.02671449272420645
99.00000000000068,12.816535294976724,0.46039144314337865,0.026352723255929078
100.2000000000007,12.856825015222956,0.4622479535877697,0.02603104906794229
101.40000000000072,12.897098870431304,0.4621802688447434,0.026345954868666865
102.60000000000073,12.937234487597614,0.46539269055925314,0.02633461395440495
103.80000000000075,12.977618639970098,0.46813407729022427,0.026228289381950987
105.00000000000077,13.017163488165082,0.46885440372007725,0.026341226622680125
106.20000000000078,13.057431806994336,0.470638868414464,0.026003693730249466
107.4000000000008,13.09758852819849,0.4715232248007717,0.026342769518350906
108.60000000000082,13.137406456625804,0.4753724781899231,0.025023369376643068
109.80000000000084,13.17737391825745,0.47419769660611655,0.026235851350901562
111.00000000000085,13.21687650576164,0.4779929610940863,0.026349604308119723
112.20000000000087,13.256983103579795,0.48152762270233906,0.026350286931446476
113.40000000000089,13.296933965205595,0.48336966503052436,0.025948984002713615
114.6000000000009,13.336685997274207,0.4863249783744332,0.025024299571775543
115.80000000000092,13.376599571367347,0.48816887561514366,0.026302153971097475
117.00000000000094,13.416036067568719,0.48947507184793126,0.025717052735050316
118.20000000000095,13.45587933194269,0.4938943775179936,0.025576543206671687
119.40000000000097,13.495230984632377,0.49613694785211027,0.026344417037978296
120.60000000000099,13.535288063909135,0.49931266823489007,0.025039733049896817
121.800000000001,13.5742839286889,0.5008740821956534,0.025030236735923417
123.00000000000102,13.613661849558932,0.5001345200351484,0.025030762362951542
124.20000000000104,13.65269880285446,0.5031581080022116,0.025139142662437663
125.40000000000106,13.691908562887981,0.5076243208462952,0.02539239819677075
126.60000000000107,13.731740717692526,0.5096411414754651,0.02536025691619237
127.80000000000109,13.770384717538672,0.513396637781915,0.025360091719739408
129.0000000000011,13.810188006987996,0.5176024235873669,0.02536014991809754
130.20000000000113,13.849074064695635,0.5184213224445025,0.025314271565430424
131.40000000000114,13.888365214388248,0.5209095311462282,0.026679233205905817
132.60000000000116,13.926180401230484,0.5243100449294893,0.0266748306798279
133.80000000000118,13.965766870063419,0.5264981509167459,0.02634942877018087
135.0000000000012,14.003741216986173,0.529693488133052,0.026363609516534936
136.2000000000012,14.043183676842398,0.5317841540662178,0.02537343748938614
137.40000000000123,14.081909505143539,0.5347570978343392,0.026748058247694217
138.60000000000124,14.12016365805231,0.5409462289255613,0.026670169511240793
139.80000000000126,14.1593208168193,0.5429136941333583,0.02667012387737344
141.00000000000128,14.197848838655176,0.5446773160292231,0.026670125069057526
142.2000000000013,14.235985532896448,0.5509051332107004,0.026670100362852445
143.4000000000013,14.274541287492358,0.5555479953701281,0.02666094311880407
144.60000000000133,14.31268806475698,0.5614440224708095,0.026348912682344405
145.80000000000135,14.350523157104007,0.5682237085772355,0.026340075508271887
147.00000000000136,14.389262410584715,0.5740819519968445,0.026330509874872732
148.20000000000138,14.427230191216086,0.577826391580645,0.0250205636913714
149.4000000000014,14.465373193868981,0.5878832569092227,0.02502016399264395
150.60000000000142,14.503703677995885,0.5959289908304186,0.025020143296754505
151.80000000000143,14.541598599659244,0.6087119286488667,0.025022856552721073
153.00000000000145,14.579967062689697,0.6190194029973355,0.024218227495316214
154.20000000000147,14.61823894117144,0.6339430816825307,0.023709905827285382
155.40000000000148,14.656564501082311,0.6493151232407213,0.02371011327735406
156.6000000000015,14.69426736015307,0.6663973034637967,0.023709700798064226
157.80000000000152,14.732432201571488,0.6836969875204306,0.023663581644827403
159.00000000000153,14.77070070837771,0.7013188656236049,0.025029288737596467
160.20000000000155,14.808616335423935,0.7239645315195784,0.02498786260821273
161.40000000000157,14.846838432159322,0.7423230642109371,0.026338479400060066
162.6000000000016,14.884776640601034,0.7607765346053359,0.026339926484232556
163.8000000000016,14.922613191665638,0.7728444270801642,0.02633130790881566
165.00000000000162,14.960128589279345,0.7725814624595571,0.025033381404849564
166.20000000000164,14.997443347140408,0.7650494055687045,0.026351750151230924
167.40000000000165,15.03488098389737,0.7513634711257822,0.02634921529214651
168.60000000000167,15.071317614924915,0.7331826291883976,0.026320237381672662
169.8000000000017,15.109572739753864,0.71344597040114,0.02406770471782327
171.0000000000017,15.146706087691294,0.6976910324646692,0.02370239129741858
172.20000000000172,15.183936456404886,0.6812407537380265,0.024935621936114316
173.40000000000174,15.221508185769785,0.6680286153048293,0.025029860657816982
174.60000000000176,15.258448773978255,0.6600868630430929,0.025029927574444777
175.80000000000177,15.29500298398338,0.6526225230069275,0.025029927010094433
177.0000000000018,15.332022125014813,0.6482908181818163,0.0250299269918397
178.2000000000018,15.369476604302514,0.6444444417347168,0.02502992659500336
179.40000000000182,15.406942298160228,0.6414369217134204,0.02503003654901459
180.60000000000184,15.444335259808968,0.637266660554933,0.025057437663366322
181.80000000000186,15.480742602446336,0.6375019100803079,0.02599302805805781
183.00000000000188,15.518301674856788,0.6364291609636374,0.026020003854365648
184.2000000000019,15.554995729007173,0.638351364720601,0.026019801575307255
185.4000000000019,15.592208942736445,0.6391697921616643,0.026008949312221752
186.60000000000193,15.62914199183127,0.641329923984046,0.024704398699741503
187.80000000000194,15.665958408927091,0.6431993062568497,0.02470013697302509
189.00000000000196,15.702450629453025,0.6427926615316414,0.024700026618040383
190.20000000000198,15.739554705611255,0.645588933470717,0.024700025999000452
191.400000000002,15.776546762325674,0.6504986561000967,0.024700025882447463
192.600000000002,15.813154163750626,0.6506148287057039,0.024700009854549343
193.80000000000203,15.849819683319854,0.6504835378949643,0.02469985683924758
195.00000000000205,15.887045915560629,0.6554042189532516,0.025154340505540773
196.20000000000206,15.923385608959759,0.6572888677357452,0.024721653087460993
197.40000000000208,15.959719345713637,0.6574442629732474,0.023375754608435884
198.6000000000021,15.996943826126401,0.6622025858661418,0.023379725115040273
199.80000000000211,16.033174403227648,0.6664042069711403,0.023380023423844598
201.00000000000213,16.06975629735914,0.6670831435490632,0.023380026001926346
202.20000000000215,16.106628161869892,0.6713858284685429,0.023380026000186405
203.40000000000217,16.14314642517503,0.671214356734774,0.023380026003198218
204.60000000000218,16.179814070356965,0.674809687057025,0.023380026187179936
205.8000000000022,16.216536394691463,0.6790232006101257,0.02337999931111856
207.00000000000222,16.252970454849105,0.680364482105026,0.02337381436635777
208.20000000000223,16.289550185989754,0.6840190341412367,0.024475268664197358
209.40000000000225,16.32596987142239,0.6859290328689092,0.02470025985240376
210.60000000000227,16.362903179081375,0.6877215911079816,0.024700246672511028
211.80000000000229,16.399097485851268,0.6917839960701487,0.024708065964642145
213.0000000000023,16.435730096546756,0.6945170960559768,0.023352525962287984
214.20000000000232,16.47227971620476,0.7001435211011727,0.023379740804453597
215.40000000000234,16.509144385282234,0.702252564889283,0.02338002582984977
216.60000000000235,16.545156601507518,0.7062105652525266,0.02338002601914191
217.80000000000237,16.581403762382102,0.7110077799142211,0.023380026000137555
219.0000000000024,16.61806909262848,0.7149931241517445,0.023380025999999
220.2000000000024,16.654637238761417,0.71969612472735,0.023380025999999887
221.40000000000242,16.690914529260453,0.7250586574761002,0.023380025999999887
222.60000000000244,16.727668804115837,0.7309225280306346,0.023380025999999
223.80000000000246,16.763864262838254,0.7376787753801305,0.023380025999917287
225.00000000000247,16.800246656234318,0.7437182862570855,0.023380025999177434
226.2000000000025,16.83667049524876,0.7496702836517949,0.023380027054524355
227.4000000000025,16.87334894517071,0.7578667754025319,0.023380162576954966
228.60000000000252,16.909544445005906,0.7649533965566613,0.023377370106704376
229.80000000000254,16.945946640985394,0.7712104861767832,0.022852959624611202
231.00000000000256,16.98253851830673,0.7832799372997262,0.02272072682541726
232.20000000000258,17.01885339098023,0.7929108904841331,0.02271004806634469
233.4000000000026,17.055563638683147,0.8036066241011501,0.022068961325077296
234.6000000000026,17.09199312897961,0.8168113765092425,0.02335483275533523
235.80000000000263,17.12825031381863,0.8327566900252177,0.023380106850304117
237.00000000000264,17.16492021789118,0.8474443213953592,0.022358163894066863
238.20000000000266,17.201443470027787,0.8672870535249986,0.021399910164758396
239.40000000000268,17.238070960894444,0.890438456823196,0.02140135058512005
240.6000000000027,17.274704575753756,0.9198974702172961,0.020888049554223187
241.8000000000027,17.31140217614015,0.9551002647856242,0.02075030741381223
243.00000000000273,17.3484365429661,1.0031047146426566,0.02074335202673705
244.20000000000275,17.385507459048334,1.0629898513205924,0.02191980123469328
245.40000000000276,17.42283637552176,1.1344202995249462,0.022070091964386584
246.60000000000278,17.46018964202959,1.215596112783003,0.02207001446191814
247.8000000000028,17.497379543970652,1.2933072726716712,0.02207110754015762
249.0000000000028,17.534157686761894,1.3534132487402388,0.021565543852034352
250.20000000000283,17.571487853255054,1.3817171755504836,0.020274318245292022
251.40000000000285,17.607604265981,1.37762539990308,0.0194270395439764
252.60000000000286,17.643554818794925,1.3411296203759464,0.019429538986488026
253.80000000000288,17.67889812903845,1.2870659242999767,0.019365556261262462
255.0000000000029,17.714515105908163,1.223236228388704,0.020726580576991616
256.2000000000029,17.749359375432885,1.1594363954888234,0.021379905557546763
257.40000000000293,17.78529858785281,1.096914004775678,0.021408583567851913
258.600000000003,17.820312266353397,1.0434724990307522,0.021409836428442297
259.80000000000297,17.856014879587384,0.9963936790310801,0.021410106864972356
261.00000000000296,17.89157616502268,0.9534471828262159,0.021425074620295526
262.200000000003,17.927352143868056,0.919229010656102,0.02006344438088359
263.40000000000305,17.963162226508523,0.8928130006585585,0.020086659947903485
264.60000000000304,17.998953386957137,0.8705774080291567,0.020711481955599353
265.800000000003,18.034637182425463,0.8529278642437509,0.01951067359270109
267.00000000000307,18.070631322475787,0.8397641657773176,0.0194300891082424
268.2000000000031,18.105984332233938,0.8255267049863633,0.019430031858981067
269.4000000000031,18.142532004045655,0.8194339624162489,0.019429883228825773
270.6000000000031,18.178560094400904,0.8164204925712404,0.01944047293943818
271.80000000000314,18.214628245861487,0.8111264745407203,0.018456505879594687
273.0000000000032,18.25056608384312,0.8068046715914325,0.018439831547128804
274.2000000000032,18.28661890323599,0.8054018543684286,0.01843980356846142
275.40000000000316,18.322988264195146,0.8045370159849069,0.018439765388228224
276.6000000000032,18.35889767726603,0.8031847947901255,0.018440612090450337
277.80000000000325,18.395024746200207,0.804960113484426,0.01830730535541214
279.00000000000324,18.43141586246447,0.8029695050819142,0.018755120020607308
280.20000000000323,18.466838346712134,0.8022719677015223,0.017467636959792365
281.4000000000033,18.50384293905786,0.8040536253868881,0.017448345660297626
282.6000000000033,18.539969680571676,0.8059521399736463,0.01722220817745601
283.8000000000033,18.576120725727286,0.8082399106650334,0.016140346513880743
285.0000000000033,18.61273167596122,0.812169872677279,0.01613281472436867
286.20000000000334,18.648286399272653,0.8120372757531874,0.015350774176293491
287.4000000000034,18.68504757894573,0.8133691956913057,0.016134200268626664
288.6000000000034,18.721268646300107,0.8163626142119679,0.01612863607326176
289.80000000000337,18.757611173542294,0.8186682477560997,0.016095216230848308
291.0000000000034,18.793742154700297,0.8212586757893824,0.01482134333757923
292.20000000000346,18.82997006465539,0.8214284915685499,0.014820117774029917
293.40000000000344,18.86620442388802,0.8231275752457987,0.01382841908271093
294.60000000000343,18.902648273785427,0.8254437459091868,0.013501808960731942
295.8000000000035,18.939095743914393,0.8293262837514742,0.013503752378210443
297.0000000000035,18.97531725447785,0.831931005311888,0.012202265002157375
298.2000000000035,19.011695349658062,0.8347518651107488,0.012179750714510718
299.4000000000035,19.04801061525238,0.838704917836585,0.012169200667495161
300.60000000000355,19.084444597697708,0.8410176267116223,0.013519987642415465
301.8000000000036,19.12067887653763,0.8465379096136869,0.012782947403850109
303.0000000000036,19.157056285066048,0.8468611556957537,0.012178002187204662
304.20000000000357,19.19334680903048,0.848084195720983,0.012180147017717857
305.4000000000036,19.22990974176041,0.8540948215956375,0.0121801683441225
306.60000000000366,19.265922235479888,0.8556317988197196,0.012189122521565565
307.80000000000365,19.30250324901269,0.8575378346153386,0.01088158023444219
309.00000000000364,19.338768602703457,0.8630537474616392,0.010850827729753654
310.2000000000037,19.37503450875255,0.8624656685026237,0.009552401443869485
311.40000000000373,19.411676039944844,0.8696511589406419,0.008231624850950858
312.6000000000037,19.447583753525688,0.8746323614925451,0.0082298901021991
313.8000000000037,19.484199283872364,0.8793798879904186,0.008395968777966445
315.00000000000375,19.520671397027126,0.8869873724514444,0.009545276874050046
316.2000000000038,19.55730532751886,0.893558778415192,0.008345992631714871
317.4000000000038,19.593814123320808,0.9003150249440662,0.008230873620830081
318.6000000000038,19.63051219100694,0.9089788274114772,0.008230137826207518
319.8000000000038,19.66667092527606,0.9107681969307843,0.007847969746369365
321.00000000000387,19.703086421182597,0.9198335219175846,0.006908555009872863
322.20000000000385,19.73975018089609,0.9312114276000605,0.006270843602191434
323.40000000000384,19.77598886535591,0.9383116203375309,0.0055942524806251726
324.6000000000039,19.812838037373957,0.9455739951219599,0.004406669909689853
325.80000000000393,19.84957622226488,0.9530185167264994,0.005383515452175303
327.0000000000039,19.8861649543069,0.9606567860807008,0.004208788100619643
328.2000000000039,19.922470456304264,0.9647453565105033,0.004276672165426376
329.40000000000396,19.95918993444384,0.9700109368858586,0.0029490135307206344
330.600000000004,19.99554924343814,0.9760951931356041,0.0016465323067906823
331.800000000004,20.03240218525749,0.97921933392078,0.0007808692833934927
333.000000000004,20.06936936569107,0.9856210846823421,-0.00028552385330282704
334.200000000004,20.10586963060352,0.9921077386485548,-0.0017189813674800547
335.40000000000407,20.14246272569528,0.9953888340088418,-0.003214115816927432
336.60000000000406,20.179059918237858,0.9992865282225549,-0.003935632619115559
337.80000000000405,20.215870564609805,1.0036770713383731,-0.005322300767867105
339.0000000000041,20.25257328596548,1.005458399823262,-0.008016122819252125
340.20000000000414,20.289421262842847,1.0101104895446529,-0.010368009508309406
341.4000000000041,20.326358312378513,1.0142608004993092,-0.012382152215411502
342.6000000000041,20.363021825861967,1.0149292858443326,-0.013966132688318034
343.80000000000416,20.400060019445366,1.0143547007655052,-0.016156687501427847
345.0000000000042,20.43651651386318,1.0139759953279222,-0.01712459225664542
346.2000000000042,20.473316149902608,1.0162568477030596,-0.019232480715634992
347.4000000000042,20.51009234224563,1.0145461187159972,-0.020323742662815114
348.60000000000423,20.547156078336165,1.0177227420382402,-0.023399768790405062
349.8000000000043,20.583766797562404,1.0182573177994243,-0.02751754335592871
351.00000000000426,20.620610743832515,1.0163824806786415,-0.030179078674430926
352.20000000000425,20.6574006445908,1.0143592650247775,-0.03411375388566462
353.4000000000043,20.69405190817463,1.0107962145637184,-0.03782031328537805
354.60000000000434,20.731028539694968,1.0090780543498818,-0.041257098545135484
355.80000000000433,20.76798179177783,1.0028530850282045,-0.04464984184105525
357.0000000000043,20.804410088783644,0.999075115384784,-0.047919747414700176
358.20000000000437,20.84138645067422,0.9911160431282633,-0.05190966946995257
359.4000000000044,20.878350937324978,0.9879614181729836,-0.05709953161412695
360.6000000000044,20.914938351657707,0.9836255626363521,-0.06230165220657291
361.8000000000044,20.951996489384392,0.9771659537016891,-0.06744907985257154
363.00000000000443,20.98892758750568,0.9742977318351136,-0.07216697041022657
364.2000000000045,21.025787155281826,0.9671278315443995,-0.07808616692387016
365.40000000000447,21.06185491072614,0.9618556945656462,-0.08360649805265963
366.60000000000446,21.098802126237935,0.9578939538895507,-0.08955982846846977
367.8000000000045,21.136543080013748,0.9543842091903669,-0.09426776289457361
369.00000000000455,21.173532019528054,0.9593588617477983,-0.10086032776051779
370.20000000000454,21.210546863002048,0.9550467463058735,-0.10649863263438242
371.4000000000045,21.247559040369055,0.9543396543068818,-0.11245753068477748
372.60000000000457,21.2846499285998,0.9547189589404318,-0.11731524338592347
373.8000000000046,21.321811480072537,0.9588109444862288,-0.12457773704112851
375.0000000000046,21.35875636808484,0.9592775358939369,-0.13040684309396067
376.2000000000046,21.39575226139031,0.9636440359960381,-0.13736878259862717
377.40000000000464,21.432916375902657,0.9638448445980299,-0.14371873862910478
378.6000000000047,21.470212144957046,0.9684688024899588,-0.15100101150893064
379.8000000000047,21.5071578936722,0.9696969763683428,-0.15662144547097911
381.00000000000466,21.54413115411378,0.9706005968876564,-0.16338285120651896
382.2000000000047,21.581505551945938,0.9777806030260073,-0.17006647382253215
383.40000000000475,21.61875274511778,0.9811957757619278,-0.17686276322029792
384.60000000000474,21.65600069684522,0.9818580069869407,-0.18190342446679608
385.80000000000473,21.693044092511656,0.9880737492506044,-0.1886807312481884
387.0000000000048,21.730221683248327,0.9900430523613651,-0.19611290157352546
388.2000000000048,21.76758642601372,0.9934524622271961,-0.20327378737790402
389.4000000000048,21.805079883022078,0.9981499341861875,-0.2093304647183234
390.6000000000048,21.84208822466919,0.9976432446896768,-0.21619606378639267
391.80000000000484,21.87966243857441,1.0021353398754729,-0.22272061613633953
393.0000000000049,21.916999756780637,1.0055580418645076,-0.2306334960906642
394.2000000000049,21.954057329611743,1.0080910110150958,-0.2373283509481965
395.40000000000487,21.99136774625456,1.0094784822344156,-0.24348463926996455
396.6000000000049,22.02833942121002,1.0121512338464158,-0.2510915786426775
397.80000000000496,22.066001547599253,1.0119991702085882,-0.25916643823461083
399.00000000000495,22.103206145584824,1.0123926067723286,-0.2666296687670542
400.20000000000493,22.14084210153695,1.0117622729080926,-0.27410159607383733
401.400000000005,22.178050725435853,1.0113486763898831,-0.28071408068990156
402.600000000005,22.21552748341255,1.0101190350180203,-0.2868920355057316
403.800000000005,22.252782845067063,1.0098668705583012,-0.29377969203436427
405.000000000005,22.29021797236852,1.0081820872643692,-0.30251896325925465
406.20000000000505,22.327056618939732,1.006670206604673,-0.31120904022050944
407.4000000000051,22.365086756037872,1.0078224906732318,-0.31978488166546803
408.6000000000051,22.402398261886304,1.007515189771331,-0.3289238319805756
409.80000000000507,22.439843240713913,1.0051628884401822,-0.337758245197024
411.0000000000051,22.477126149555527,1.0029397567475624,-0.34684288478812775
412.20000000000516,22.514597302697563,1.001207591666564,-0.3559060471227138
413.40000000000515,22.552097648042274,0.9976591123979817,-0.3648657681860845
414.60000000000514,22.58971354101719,0.9965880609728851,-0.37406633300772096
415.8000000000052,22.62737701026208,0.9955775871074312,-0.3839442849340937
417.00000000000523,22.66479822518877,0.9949044962529251,-0.39338687286002116
418.2000000000052,22.702385985670965,0.9925339462595748,-0.40385452822367274
419.4000000000052,22.739670702646233,0.9895427665948943,-0.4126666424484453
420.60000000000525,22.777465591406088,0.9845840755177243,-0.4223567251338043
421.8000000000053,22.814948915775574,0.9883770089773275,-0.43359476523786844
423.0000000000053,22.852736783504078,0.984250869448626,-0.4448305728390394
424.2000000000053,22.89003100746372,0.9829469654400338,-0.45670922122001656
425.4000000000053,22.927496051330095,0.9848084413341652,-0.4682607080000758
426.60000000000537,22.965402043742174,0.9832787542249618,-0.4800306755695476
427.80000000000535,23.002388907797425,0.9852250561831369,-0.49075096657221007
429.00000000000534,23.040805971345094,0.9877202930214326,-0.5036985668507086
430.2000000000054,23.078358038565874,0.9913851892061872,-0.5168659622298142
431.40000000000543,23.115968833356117,0.9972382229884335,-0.5307606495800936
432.6000000000054,23.15371155647497,1.0020699140438771,-0.5451067839003843
433.8000000000054,23.19105744226947,1.0123112547368587,-0.560964453497161
435.00000000000546,23.229586402372895,1.0194198417539624,-0.5764212601025873
436.2000000000055,23.26729640177238,1.0343613713306432,-0.5918860298209658
437.4000000000055,23.30498047653758,1.047519539993583,-0.6079498568618122
438.6000000000055,23.3430022691308,1.060593182319796,-0.6257655203679517
439.8000000000055,23.38094202466871,1.0756961447037066,-0.6433925357504306
441.00000000000557,23.41863022988489,1.094063398614844,-0.663000485375894
442.20000000000556,23.456643819826738,1.1109857773772167,-0.6825099583877159
443.40000000000555,23.494627915753398,1.1249251926305728,-0.7033839198667686
444.6000000000056,23.532720726235823,1.1405290943118582,-0.7231775545338124
445.80000000000564,23.570714290628104,1.1532366088245753,-0.7445318569400108
447.0000000000056,23.608697813229945,1.1667271353426947,-0.7667899262710494
448.2000000000056,23.646365101954174,1.1789390190107234,-0.79023357642901
449.40000000000566,23.684817416476836,1.1901046984484815,-0.8131592149577589
450.6000000000057,23.722883348177657,1.2008280210896283,-0.8376508237760296
451.8000000000057,23.760665002391427,1.2119252871466313,-0.8626751440000691
453.0000000000057,23.7988395748082,1.2235870997722202,-0.889072692785327
454.20000000000573,23.83672994265532,1.2324194135504858,-0.914929592615374
455.4000000000058,23.874547233626604,1.2417065126202478,-0.942170142877516
456.60000000000576,23.912602545673344,1.2497858396919352,-0.970645512968515
457.80000000000575,23.9509181115218,1.2565158398671148,-0.9998252064679232
459.0000000000058,23.989073373205862,1.2645086614117778,-1.0288479133835575
460.20000000000584,24.026676099179063,1.2650755718625266,-1.0565902779806788
461.40000000000583,24.06474930675133,1.2691853814646605,-1.0864453883452905
462.6000000000058,24.10261390029585,1.2648277085541402,-1.115698968046709
463.80000000000587,24.140681735498667,1.2617976781034832,-1.1444729211670839
465.0000000000059,24.177793605427343,1.2535924641068092,-1.1725735784379405
466.2000000000059,24.21647120710076,1.2413557229619863,-1.2016638401288438
467.4000000000059,24.254230407556946,1.2233220177445288,-1.2284807894243994
468.60000000000593,24.291776235953556,1.2021030822500007,-1.253364454311519
469.800000000006,24.329899159849692,1.1771597714539608,-1.2764984466063671
471.00000000000597,24.367247715241465,1.1461011516577941,-1.2967105145161542
472.20000000000596,24.404862426872356,1.1137306687138915,-1.316194607390916
473.400000000006,24.442449211598998,1.0748291325575368,-1.3322778674050326
474.60000000000605,24.480188276442025,1.0368081358275667,-1.3468012289232898
475.80000000000604,24.517461912069137,0.9990905876611034,-1.3613557611380385
477.000000000006,24.55495298967909,0.9615656771847403,-1.373792148528762
478.20000000000607,24.59281163011165,0.9260407622541528,-1.3862297297819692
479.4000000000061,24.63059643888208,0.896164314717418,-1.3973758970849257
480.6000000000061,24.667662054223815,0.8738932709120731,-1.407779722514352
481.8000000000061,24.706456464970604,0.8507395957812018,-1.4181952939639517
483.00000000000614,24.744228403246353,0.8324430229387365,-1.4280342466307863
484.2000000000062,24.782293199096838,0.8184731977898962,-1.4387311930731643
485.4000000000062,24.820329109390563,0.806970297912021,-1.4491000954629207
486.60000000000616,24.858544207357745,0.8047489192662058,-1.458979486297519
487.8000000000062,24.896667666778722,0.7980538163012953,-1.4678375513153443
489.00000000000625,24.934645508482475,0.7968897614486821,-1.479242583093693
490.20000000000624,24.97305434507768,0.7969355503207887,-1.4896119551633653
491.40000000000623,25.011060191895506,0.7969450618895033,-1.5013181559660564
492.6000000000063,25.049331054771088,0.798379185122611,-1.513274326172731
493.8000000000063,25.08751544161462,0.7955639812287898,-1.5254878417649342
495.0000000000063,25.125772168895498,0.7953258198294277,-1.537997069421913
496.2000000000063,25.16383257778068,0.7888305141318459,-1.55039669382148
497.40000000000634,25.202286624859592,0.7804130318042672,-1.5625681603070198
498.6000000000064,25.24029363341036,0.7670345983379714,-1.575177627849278
499.8000000000064,25.278333852007105,0.7433797414573957,-1.5877115920680938
501.00000000000637,25.31650698335873,0.712686250043775,-1.5998526006107974
502.2000000000064,25.354089628015338,0.6757969799857921,-1.6098945915790996
503.40000000000646,25.392203661617327,0.6357627930808221,-1.6198798120721465
504.60000000000645,25.430096152912622,0.5933466564069318,-1.629428978958309
505.80000000000643,25.46791020121943,0.543974920103623,-1.6370024669569645
507.0000000000065,25.505585475420503,0.49656053939579303,-1.6415505326789432
508.2000000000065,25.543081773788707,0.4495097642578241,-1.645568161852672
509.4000000000065,25.581115179908753,0.4067006694070512,-1.6487395107730034
510.6000000000065,25.619076469424378,0.37069489634297703,-1.6519649439940167
511.80000000000655,25.65752471087459,0.34658260849417233,-1.6534892044960303
513.0000000000066,25.695660293158276,0.3248454167692443,-1.6573622703553514
514.2000000000066,25.733530149940385,0.3124583971264585,-1.657833967603013
515.4000000000066,25.77221024326424,0.3018889971169594,-1.659009139547654
516.6000000000066,25.81061564089182,0.2998881159800244,-1.6608084210646732
517.8000000000067,25.848835739793778,0.2923064559350712,-1.6611567977725055
519.0000000000066,25.887332517788323,0.2937521584453686,-1.6625372566337502
520.2000000000066,25.92583129863201,0.29278143553893354,-1.6640449475498964
521.4000000000067,25.963999094396875,0.29265718952922004,-1.6654056091044698
522.6000000000067,26.002829121411768,0.2900179828424807,-1.6660314284237185
523.8000000000068,26.041624950294484,0.28753885249859135,-1.6667218105736223
525.0000000000067,26.080128867785017,0.29431533984933966,-1.6680577495985252
526.2000000000068,26.118866690490535,0.2959435073699437,-1.669402817504554
527.4000000000068,26.157510561600095,0.2960617780544861,-1.6707678300808206
528.6000000000067,26.195875024847762,0.29955946407304657,-1.67221924733145
529.8000000000068,26.234745516745015,0.30304450795368765,-1.6736408915514267
531.0000000000068,26.273718449318324,0.3029725637347802,-1.6735615370071546
532.2000000000069,26.312180015011347,0.3033888697817222,-1.6749160520285784
533.4000000000069,26.350760783570088,0.30586493069686926,-1.6763001940770526
534.6000000000068,26.38970827120211,0.3058049172814614,-1.677608928209382
535.8000000000069,26.427690077163756,0.31074667888250107,-1.677517343754083
537.0000000000069,26.46756489076421,0.3091458151439592,-1.6788436261317936
538.2000000000069,26.506173362165637,0.315287122603245,-1.6802310992934468
539.4000000000069,26.54494601062589,0.316443459731095,-1.6815382448155036
540.600000000007,26.58408109447085,0.31581084195327214,-1.6819087083730961
541.800000000007,26.62299882299596,0.3189621008847905,-1.6849426110897623
543.000000000007,26.662120742182317,0.32224937666178977,-1.6857012280130124
544.200000000007,26.70060088177724,0.3257547575501718,-1.6869206671611963
545.400000000007,26.739310588486045,0.32602744942127204,-1.6873177680494886
546.6000000000071,26.778457726977685,0.3279534464381333,-1.6882782092541775
547.800000000007,26.817733213589584,0.32831540927126057,-1.6897243111792242
549.000000000007,26.856793165402614,0.331781384591171,-1.690852631387668
550.2000000000071,26.89596202611003,0.3307452454238513,-1.6915642688271246
551.4000000000071,26.934829392864792,0.33447823907762886,-1.692357704383761
552.6000000000072,26.974076523128392,0.33389458101604097,-1.6949652490358957
553.8000000000071,27.01334605029056,0.3351342644068138,-1.6969555996916852
555.0000000000072,27.052097497818067,0.3332647196103178,-1.698419619849905
556.2000000000072,27.090984027392118,0.33253526245613396,-1.6998173753975028
557.4000000000071,27.13038689284417,0.3368231951752092,-1.700805024637281
558.6000000000072,27.16953781547915,0.33375355487424074,-1.702439121182366
559.8000000000072,27.208147191103947,0.3335896911994698,-1.7027200525615838
561.0000000000073,27.247779754698612,0.3341409644755249,-1.7028695886385545
562.2000000000073,27.286987931272375,0.334660181833611,-1.7042251519701215
563.4000000000073,27.325995771208923,0.3369147534359067,-1.705344116242034
564.6000000000073,27.36524397816114,0.33468706627976297,-1.706743580788813
565.8000000000073,27.403987714952223,0.3363839703528464,-1.7081293640728266
567.0000000000073,27.443866565970897,0.3344501791993615,-1.7099406109120787
568.2000000000073,27.482866073927998,0.337314176570058,-1.7114372105252578
569.4000000000074,27.52201571356078,0.33902475621509387,-1.7124815185066633
570.6000000000074,27.5613533752371,0.3377995855328424,-1.7138354104067628
571.8000000000075,27.600262461046096,0.34141110753828907,-1.7151515158721349
573.0000000000074,27.639836130831004,0.34496884690549057,-1.7164660730418007
574.2000000000074,27.679560897986747,0.34652796991970924,-1.7180034057874223
575.4000000000075,27.71868242498081,0.3493809172069322,-1.719317633630408
576.6000000000074,27.758270570311716,0.3488299496799654,-1.720673051520865
577.8000000000075,27.797505037302113,0.352026952736503,-1.7224079039515883
579.0000000000075,27.836669006957393,0.35411022670117887,-1.7251786708876593
580.2000000000075,27.876166822622068,0.3560707835539203,-1.7270938645874838
581.4000000000076,27.91566990399713,0.3621013249701359,-1.7299100380447219
582.6000000000075,27.955348283361683,0.3633995145056268,-1.7317556614605198
583.8000000000076,27.994548166464597,0.36475526000506786,-1.7334558790297994
585.0000000000076,28.033717672607466,0.3719246562372789,-1.7364500739623496
586.2000000000075,28.073577374174697,0.3763712346003505,-1.7363365204816237
587.4000000000076,28.113086586707503,0.37593100041462635,-1.735462297821615
588.6000000000076,28.152337661422507,0.38220844748693117,-1.7408002534666966
589.8000000000077,28.191974790760753,0.3877733337989544,-1.7443467871980314
591.0000000000077,28.231346755077297,0.392255633165282,-1.7474621633720302
592.2000000000077,28.27093634416457,0.3974494472419743,-1.7508989999528617
593.4000000000077,28.310795470696046,0.4061771476953664,-1.7525983173901518
594.6000000000078,28.349967447248876,0.41385212805993676,-1.7546659925596417
595.8000000000077,28.389738396723175,0.42109679986695614,-1.757845881808322
597.0000000000077,28.428716194701366,0.43086627951973955,-1.7606695972875865
598.2000000000078,28.469267503348206,0.44563405317230464,-1.762876840117864
599.4000000000078,28.508798937531267,0.45973838319769134,-1.7664141837044869
600.6000000000079,28.548250886236048,0.4742642169543829,-1.7696163769565443
601.8000000000078,28.58823773931489,0.49327467406320746,-1.7721484124009264
603.0000000000078,28.627782418010483,0.5097307359882932,-1.7767287850193285
604.2000000000079,28.66786852021824,0.5298347771508551,-1.7801715107822353
605.4000000000078,28.707409690569673,0.5495339885986295,-1.7850063636542464
606.6000000000079,28.7470834083014,0.5653890283928658,-1.7899432212374107
607.8000000000079,28.786591977983484,0.5755745519207356,-1.7966645097264902
609.000000000008,28.82658987759377,0.5862604802317686,-1.8021441951960289
610.200000000008,28.866255725240528,0.5927881240356458,-1.8077726623813537
611.4000000000079,28.906144454867317,0.6016408670344409,-1.8138234809693885
612.600000000008,28.94539989995169,0.6062246583836628,-1.8210353748696688
613.800000000008,28.985384466374967,0.6116113923574835,-1.8241059998332978
615.000000000008,29.02498914006818,0.6128828582228987,-1.8297374665164736
616.200000000008,29.06470953421255,0.6174684704686175,-1.844416869093434
617.400000000008,29.104578336677548,0.6256859751479698,-1.8545761286700024
618.6000000000081,29.14407132305757,0.6250949588060504,-1.8624966795474966
619.8000000000081,29.183700338146334,0.6293750579614714,-1.8695381850677055
621.0000000000081,29.22329216486657,0.6284499159096486,-1.8774956490370394
622.2000000000081,29.263134605835727,0.6308993254312067,-1.886003682208779
623.4000000000082,29.30252387737579,0.6321224513330523,-1.894647455302172
624.6000000000081,29.34239975959744,0.6357168146346199,-1.9037785284683948
625.8000000000081,29.382111367429257,0.634957171119978,-1.9130210001599037
627.0000000000082,29.42181251609261,0.6369699998554317,-1.9221697755714873
628.2000000000082,29.461290340624256,0.6388470550449319,-1.9322807143601217
629.4000000000083,29.50105843290303,0.6417653073851382,-1.9422481829916984
630.6000000000082,29.540454657253008,0.6416850014880533,-1.9541813870088602
631.8000000000083,29.580234658756886,0.6443395065357986,-1.9637515701567563
633.0000000000083,29.61989919560284,0.6421677292458006,-1.972455849146996
634.2000000000082,29.659601428711753,0.6422672860955774,-1.9819327159016638
635.4000000000083,29.699331261138493,0.6457505935369499,-1.9915301562983831
636.6000000000083,29.73879796213739,0.6457214705046315,-1.9993583988575687
637.8000000000084,29.778538143183358,0.6480980090516766,-2.0062091410309097
639.0000000000084,29.81815609907277,0.6557975168209675,-2.012414216880156
640.2000000000083,29.857903971048394,0.6655688273346303,-2.014895742119965
641.4000000000084,29.897666567184913,0.6649655410712241,-2.01822811949506
642.6000000000084,29.937201000825603,0.6634487317329809,-2.0199343020793954
643.8000000000084,29.977125048805142,0.6563018885745759,-2.0230235288646057
645.0000000000084,30.016874030657235,0.6470061091418062,-2.024800710939327
646.2000000000085,30.05614372929039,0.6351943985884869,-2.027018420071838
647.4000000000085,30.096072516684192,0.6306779100783388,-2.0285440342764005
648.6000000000085,30.13579083036735,0.6310228003978207,-2.030493147008485
649.8000000000085,30.175470293279318,0.6351316257306066,-2.0315294737352216
651.0000000000085,30.215418625999824,0.6415497621604507,-2.0327234075802187
652.2000000000086,30.255079766311326,0.6577458757848968,-2.033661675140687
653.4000000000085,30.295049354570594,0.6774327013923673,-2.03445265466687
654.6000000000085,30.33481032052545,0.698248515629813,-2.0359508774432244
655.8000000000086,30.374740235263726,0.7169989786195603,-2.0374609452078176
657.0000000000086,30.41469756282134,0.7417327569527836,-2.0344440529613608
658.2000000000087,30.454873399836057,0.7594826074723504,-2.0388010834127197
659.4000000000086,30.49480505814641,0.7893081048205368,-2.047379735286941
660.6000000000087,30.534655380976023,0.8118521490566861,-2.0604686654650215
661.8000000000087,30.574561105084655,0.8365413407371258,-2.0369300624762565
663.0000000000086,30.614632373211847,0.8550091464134912,-2.0424919754776223
664.2000000000087,30.65488315894352,0.8862266935373857,-2.051984599446902
665.4000000000087,30.695110050480633,0.9096010812288682,-2.054244547702321
666.6000000000088,30.735046848099667,0.9361620235150594,-2.0554180291383752
667.8000000000088,30.774959700935586,0.9676492752974262,-2.05728605725512
669.0000000000088,30.814955981815913,0.9947411582366106,-2.0597703375542586
670.2000000000088,30.85430905255309,1.0244639167669962,-2.0613745430821973
671.4000000000088,30.89542107366293,1.0548078803676757,-2.064204733451456
672.6000000000088,30.9354111461728,1.086514871553033,-2.0666310209851635
673.8000000000088,30.975568262772086,1.1267734819743473,-2.069528081967561
675.0000000000089,31.01586244704848,1.1648047116873443,-2.0724503552619824
676.2000000000089,31.055992827462106,1.2041426801754371,-2.0743656998414193
677.400000000009,31.096436390629815,1.2499855922114245,-2.0764004931441464
678.6000000000089,31.13631299912372,1.2974382271123193,-2.079417106116024
679.8000000000089,31.176991725627616,1.3410818418307549,-2.0823279587100454
681.000000000009,31.217243443116008,1.3876079918248196,-2.0840272742585
682.2000000000089,31.257691081803127,1.4424647791377458,-2.0873373655797662
683.400000000009,31.298051777084858,1.4933091517252208,-2.091230565223086
684.600000000009,31.33823308485757,1.5442936253874235,-2.0943719042541957
685.800000000009,31.378940858557893,1.5971418162671112,-2.098752739309191
687.0000000000091,31.41902443170826,1.6547638090362908,-2.1031243142456884
688.200000000009,31.459897730662558,1.7074667399298062,-2.1075954977541103
689.4000000000091,31.5002365322525,1.7681019677223773,-2.110066769956557
690.6000000000091,31.54063154595015,1.8271513733814568,-2.115881431812417
691.800000000009,31.58097575317425,1.8861991451498115,-2.1198217991649626
693.0000000000091,31.621948941958053,1.9445968319609979,-2.1251499718972147
694.2000000000091,31.66246135223492,2.007026068670017,-2.1302061381564323
695.4000000000092,31.702980173321134,2.0695655391519403,-2.1367875123180795
696.6000000000092,31.74340909452682,2.1324389345403443,-2.1421487662823604
697.8000000000092,31.784238574940566,2.1999806464702454,-2.1463063409206597
699.0000000000092,31.824632928263735,2.265935676938457,-2.1517489377074672
700.2000000000093,31.865321750198863,2.3277488564047903,-2.1573446139543115
701.4000000000092,31.905813793932808,2.393679772803198,-2.163798295316511
702.6000000000092,31.94681380167134,2.4633831877779553,-2.170788869089907
703.8000000000093,31.98758139662916,2.5291988853410206,-2.1761363916106493
705.0000000000093,32.028122039056136,2.5944035364656033,-2.1828445477251766
706.2000000000094,32.068890681705305,2.6618982049856883,-2.1898427565180905
707.4000000000093,32.10933325178392,2.73573336911124,-2.196305740104858
708.6000000000093,32.150396627594105,2.805219514931928,-2.203078447011234
709.8000000000094,32.19087743798717,2.872480837089772,-2.2095930805639465
711.0000000000093,32.232061612599125,2.9497102606958086,-2.216944377902231
712.2000000000094,32.27271145175461,3.0170796097287766,-2.2247115352605067
713.4000000000094,32.313250218607116,3.089106385844625,-2.2320160315038513
714.6000000000095,32.35420233582712,3.1615719309740244,-2.2392289172150885
715.8000000000095,32.39505627294864,3.2316235200793866,-2.248272644401906
717.0000000000094,32.43575231460136,3.3038612216784897,-2.256287065096261
718.2000000000095,32.47653615302417,3.3741648516162632,-2.2652058090804066
719.4000000000095,32.51728560226645,3.4509789916778155,-2.273576286173754
720.6000000000095,32.55804177719955,3.515671238331056,-2.284188664308374
721.8000000000095,32.598890603185865,3.590491918867816,-2.293670881297475
723.0000000000095,32.63989837896723,3.6616951475892687,-2.3008888083084
724.2000000000096,32.68086739749651,3.7348518788975453,-2.3117214419606738
725.4000000000096,32.721469709765294,3.8105827102843066,-2.3225185792963456
726.6000000000096,32.762049377878206,3.88774517453884,-2.3332027800670168
727.8000000000096,32.80343053635096,3.971467197264485,-2.3426851373084956
729.0000000000097,32.84446866143812,4.053548306842054,-2.3501859301981547
730.2000000000096,32.885317048693516,4.143014796789647,-2.3613992361864744
731.4000000000096,32.92657729839803,4.234027427576384,-2.3715810063966902
732.6000000000097,32.9676780321602,4.330037544854272,-2.3818162282786153
733.8000000000097,33.00863223883458,4.426502775301843,-2.3927875459022925
735.0000000000098,33.049519283161445,4.533469466106361,-2.40413012035263
736.2000000000097,33.0911246393778,4.639121228517521,-2.4155756366627705
737.4000000000098,33.13242117162909,4.7462404273918315,-2.428117801195569
738.6000000000098,33.17323764999388,4.858139523512656,-2.4386690597677907
739.8000000000097,33.21483317454506,4.966871158460753,-2.4500104526017115
741.0000000000098,33.255868583415044,5.077437503093468,-2.463264472146058
742.2000000000098,33.29700543886064,5.175960975125516,-2.476170369638668
743.4000000000099,33.33844301805241,5.2723115134705925,-2.489473866385336
744.6000000000099,33.379304780332006,5.355494908275465,-2.5033077755269453
745.8000000000098,33.41972225840684,5.43054124203808,-2.5144879915947618
747.0000000000099,33.4611757675586,5.495590583031986,-2.52792620914579
748.2000000000099,33.501975435000716,5.543634603019225,-2.5419639874437
749.4000000000099,33.54275034679854,5.577855708188396,-2.5569651201080528
750.6000000000099,33.58311875967679,5.586169075668629,-2.570407055947518
751.80000000001,33.623334781685784,5.575849721461209,-2.5840744193982297
753.00000000001,33.66337893606527,5.5446039970880605,-2.597609874363325
754.20000000001,33.703359626916146,5.482666385762645,-2.610737310386491
755.40000000001,33.742750777280435,5.38627675463307,-2.623627452525267
756.60000000001,33.78153750761308,5.239416059961768,-2.6358915078019542
757.8000000000101,33.82066059727702,5.026552784416133,-2.649565589796892
759.00000000001,33.85819409831169,4.752509007912314,-2.6613226765888705
760.20000000001,33.89566033258347,4.3861659079049335,-2.6709735973933744
761.4000000000101,33.93160107082506,3.886171587096301,-2.680131038043889
762.6000000000101,33.965987275644046,3.138018250023065,-2.689395478839746
763.8000000000102,33.99921601821944,2.2443040089773807,-2.6968187334242013
765.0000000000101,34.03316428768193,1.470753703781123,-2.7026314838639447
766.2000000000102,34.06894416962749,0.8968632864339634,-2.705736930218171
767.4000000000102,34.10547322960183,0.5018287957962166,-2.705954302091894
768.6000000000101,34.14354891930806,0.23172365284105867,-2.705747476335728
769.8000000000102,34.182189068426666,0.055581788946786226,-2.707248020187729
771.0000000000102,34.221378552405405,-0.06405689682717997,-2.708472519472443
772.2000000000103,34.260809438610735,-0.14653058493496363,-2.7084700032972027
773.4000000000103,34.3004475315187,-0.20214090165745913,-2.708463240888176
774.6000000000103,34.34036326877051,-0.24046761754796298,-2.709771485604173
775.8000000000103,34.37952293231862,-0.26867031492755533,-2.7084628795609236
777.0000000000103,34.42046360529445,-0.2857078090473526,-2.7084482286503837
778.2000000000103,34.46057323731769,-0.2985244543993819,-2.7071552781957404
779.4000000000103,34.500903904137985,-0.31305496626571405,-2.70847272432998
780.6000000000104,34.54115918555127,-0.3219492864212168,-2.7084756244072263
781.8000000000104,34.581600839663615,-0.3284070249227735,-2.7097950961975634
783.0000000000105,34.621980430954245,-0.328692635355712,-2.709789665683774
784.2000000000104,34.66176832328457,-0.33183726518740486,-2.709716622322608
785.4000000000104,34.701918229193105,-0.340430505423194,-2.707919514832485
786.6000000000105,34.74234134589585,-0.3429430619759253,-2.7105046338634313
787.8000000000104,34.78327910554894,-0.3460885798607123,-2.7133368279015553
789.0000000000105,34.823766898894796,-0.3498452094337081,-2.714741390408717
790.2000000000105,34.863929474358024,-0.3563575138753976,-2.713459490715014
791.4000000000106,34.904243472089945,-0.3548280464971756,-2.714737023685993
792.6000000000106,34.944787933283486,-0.35719345925905155,-2.7147301008177234
793.8000000000105,34.985223019147035,-0.3575159429035586,-2.714730068212651
794.0000000000106,34.9919590525213,-0.35818662979822635,-2.714730067888284