File: 01_Data/Polyester_Carpet_High_Pile/STA/N2/30K_min/Polyester_Carpet_High_Pile_STA_N2_30KData_230925_R2.csv
##Temp./Â°C,Time/min,DSC/(mW/mg),Mass loss/mg
51.0,10.613178851674089,0.06311733469480707,-0.001846379719048219
52.20000000000002,10.791010303000855,0.13385547341434556,-0.000793569445536324
53.400000000000034,10.913146113167883,0.1887113923712569,-8.328606451790677e-05
54.60000000000005,11.012422581064335,0.23661322609962454,-8.56234168624681e-05
55.80000000000007,11.096874188598623,0.2803936976463093,-0.0005239843837552272
57.000000000000085,11.172691079564176,0.31826767476807416,-0.00024211441203814132
58.2000000000001,11.243371447059017,0.3560064893869248,0.004416802548452559
59.40000000000012,11.30885388680791,0.39061967492880734,0.0003336327074241474
60.600000000000136,11.370685156749541,0.4222559243488673,-0.003133931363948239
61.80000000000015,11.429487371725022,0.4503252561920017,-0.002429586465367173
63.00000000000017,11.485516069597901,0.4766103734068854,-0.0015528444721533141
64.20000000000019,11.539713100214497,0.5049409752679523,-0.0008646846445219403
65.4000000000002,11.5924334101423,0.5293445633024458,-0.0019958088513063466
66.60000000000022,11.643374543709458,0.5509063020253899,0.003507856756868044
67.80000000000024,11.694426076133443,0.5750033515582558,-0.0010883198106359515
69.00000000000026,11.743034353078407,0.5956703430669819,-0.0035544264190252584
70.20000000000027,11.790980122639217,0.6162458839567899,-0.0020221290266353442
71.40000000000029,11.83836989641709,0.635567471269654,-0.0011735913243486884
72.6000000000003,11.884992749499315,0.6555435774526537,-0.0025583125289121433
73.80000000000032,11.93142340617993,0.6730800672372661,-0.003285545713730631
75.00000000000034,11.97638108470474,0.6911175257370763,-0.003927510390556055
76.20000000000036,12.022004994807265,0.7057164780255678,-0.0032133935141738235
77.40000000000038,12.06659050788827,0.7213280558957826,-0.003427149755287573
78.60000000000039,12.111063256949969,0.7387920758532585,-0.002920515223456377
79.80000000000041,12.154437137757574,0.7499231368187145,-0.0037725212212187387
81.00000000000043,12.196909313727911,0.7598513050940492,-0.006130676468388163
82.20000000000044,12.239856175616694,0.7683121494054657,-0.004292526209309866
83.40000000000046,12.282538111105161,0.7704603199314086,-0.0017359974671009581
84.60000000000048,12.325895231332495,0.7745030430308946,-0.001333373402485627
85.8000000000005,12.367186190228907,0.7788127668232183,-0.0019218499631374897
87.00000000000051,12.410034585594419,0.7814721440597381,-0.004296184934995839
88.20000000000053,12.45098035182227,0.7865914357390156,-0.004637606026243635
89.40000000000055,12.492211351076842,0.7897784161164756,-0.0027763474520901
90.60000000000056,12.53399942947679,0.7934485527796142,-0.0011170799144393229
91.80000000000058,12.575089503149336,0.7995846360783385,-0.002657769994809378
93.0000000000006,12.615856491236858,0.8038247681081889,-0.002697749638758573
94.20000000000061,12.656379346352715,0.8096248742076868,-0.0027622960882505154
95.40000000000063,12.696849806051471,0.8133748153229814,-0.00282360825990402
96.60000000000065,12.737629316183682,0.8181774887215147,-0.003909069997652281
97.80000000000067,12.777812823787634,0.8212294756401395,-0.0027551812121604513
99.00000000000068,12.818305905457194,0.8280091762722595,-0.004119149297373781
100.2000000000007,12.858259363203484,0.8353351823678764,-0.0027512069675625916
101.40000000000072,12.898650242382699,0.8400572803637903,-0.0017965745850871961
102.60000000000073,12.938715145066443,0.8468928076933862,-0.0027258301613111158
103.80000000000075,12.978345965728824,0.8545770400061402,-0.0013767126998311952
105.00000000000077,13.018904054764967,0.8596412106275352,-0.0024223530581415353
106.20000000000078,13.058628476496523,0.8650546043548816,-0.0013724692421717144
107.4000000000008,13.098704814601577,0.870379191929232,-0.0027387345068690117
108.60000000000082,13.138075146028685,0.8794762070170872,-0.0027510096373362103
109.80000000000084,13.178345542723076,0.884154364786701,-0.004154107973994847
111.00000000000085,13.21825337311967,0.8897319031030588,-0.003489350443026673
112.20000000000087,13.257831481426319,0.895480498715329,-0.0030223052256661553
113.40000000000089,13.297839287294446,0.9012677648144629,-0.004075536290145898
114.6000000000009,13.336987959126201,0.9095999041719032,-0.0028351353367677135
115.80000000000092,13.37722797635637,0.9160100806698289,-0.002750820275347454
117.00000000000094,13.416787237621222,0.9222811495636162,-0.003984767581461934
118.20000000000095,13.45619763434731,0.9298119830186516,-0.00273627087934436
119.40000000000097,13.496236408986789,0.9375469473913632,-0.00274054729075468
120.60000000000099,13.535187303930467,0.9395951943413282,-0.002956618444643677
121.800000000001,13.574932666579002,0.9462279680730612,-0.004696408387634854
123.00000000000102,13.61435947101318,0.956049008560718,-0.00471981280273015
124.20000000000104,13.653515920155195,0.9587673330266806,-0.004722579694702134
125.40000000000106,13.693116399179956,0.9666093065657639,-0.0050334068954951405
126.60000000000107,13.732188387194435,0.9712592982024021,-0.005380821994294127
127.80000000000109,13.771539296335268,0.98159033144113,-0.0053801783517637425
129.0000000000011,13.810533454889475,0.9864279639778917,-0.004441006015165172
130.20000000000113,13.849266300805024,0.9924986553638304,-0.004718516472779211
131.40000000000114,13.888411147369956,0.9983168544565052,-0.003413253796348492
132.60000000000116,13.927583895227583,1.0057670105889784,-0.003409892997149111
133.80000000000118,13.966172359636337,1.0134708660457332,-0.003409827274718058
135.0000000000012,14.005206784683605,1.019537632407518,-0.0034092314775882038
136.2000000000012,14.043721887945585,1.0268516237522407,-0.0044166741385889274
137.40000000000123,14.082471536365011,1.0319258419619177,-0.004400035902139887
138.60000000000124,14.120508607961352,1.0402029663900705,-0.004399855452266621
139.80000000000126,14.159006534054667,1.0484415339449429,-0.004399854004614401
141.00000000000128,14.198052187971522,1.057301214337794,-0.004399853514534868
142.2000000000013,14.236918539397339,1.0640892803849806,-0.004399828157195973
143.4000000000013,14.275219480752845,1.0740248001706885,-0.004402418330304858
144.60000000000133,14.31390729377327,1.0818407185413992,-0.004300819291994884
145.80000000000135,14.351688391197975,1.0923308019165634,-0.0034099748222566895
147.00000000000136,14.390468887911897,1.1024194957929683,-0.0034575361018660544
148.20000000000138,14.428144613727737,1.112846809753231,-0.004725207557367828
149.4000000000014,14.466324181811625,1.1257004498850638,-0.004720080703912721
150.60000000000142,14.504812812599578,1.1406381623453141,-0.004720083419802901
151.80000000000143,14.542640423505702,1.1533073242762697,-0.004719636675138528
153.00000000000145,14.58124096143274,1.1679659590551732,-0.005420814559446097
154.20000000000147,14.619138792985009,1.1891138006863304,-0.006039020523124883
155.40000000000148,14.657396339300236,1.2095489045343328,-0.006040099539321719
156.6000000000015,14.695246258196404,1.230174757116513,-0.006043227738342871
157.80000000000152,14.733560080288632,1.253047774479985,-0.005764135586510566
159.00000000000153,14.771413390866732,1.2759150581125542,-0.004713288076963806
160.20000000000155,14.809721278004963,1.3006217846263075,-0.0047198510414614425
161.40000000000157,14.84776591002838,1.321342787797158,-0.004719862221822968
162.6000000000016,14.88527934985982,1.339313322403623,-0.004719862003055297
163.8000000000016,14.923310870229196,1.3521433926465394,-0.004719862000025721
165.00000000000162,14.960582561385701,1.354355284216812,-0.0047198620001140945
166.20000000000164,14.998184238078013,1.346021479141526,-0.004719861901022249
167.40000000000165,15.035218324095224,1.3319884371755757,-0.004719843638538723
168.60000000000167,15.07268545434261,1.3151188749652922,-0.004718306896162705
169.8000000000017,15.10990434135209,1.3000416366885974,-0.005379861999918578
171.0000000000017,15.14702442335674,1.2870472126153225,-0.00604207085772579
172.20000000000172,15.184512940166236,1.2746413055343324,-0.006039887433331614
173.40000000000174,15.221665090797405,1.2666551565923054,-0.006040500164861573
174.60000000000176,15.258764665114384,1.2628443301185799,-0.006024180332373064
175.80000000000177,15.295874783010076,1.2568519270216643,-0.0067033850029787345
177.0000000000018,15.333064837549422,1.2572386215537306,-0.006700170061201494
178.2000000000018,15.370423148608134,1.2556765063262745,-0.006700107093095209
179.40000000000182,15.407232326356112,1.2565028860989371,-0.006706129034957264
180.60000000000184,15.444676919778015,1.2580467409541758,-0.005403001205911195
181.80000000000186,15.481175130687552,1.2609425744302383,-0.005380260959501282
183.00000000000188,15.517824034888998,1.2630617304097214,-0.005380143621518396
184.2000000000019,15.555200221687102,1.2661302460471306,-0.005380142136869992
185.4000000000019,15.591947549752811,1.2716269032288632,-0.0053799259603684035
186.60000000000193,15.629139699526723,1.274314531571279,-0.005380469614533645
187.80000000000194,15.66595310518132,1.2795060773258382,-0.006029482890486548
189.00000000000196,15.702737522250382,1.2817277520298598,-0.0060400512670772954
190.20000000000198,15.739711820762464,1.285723084293594,-0.006040143842368728
191.400000000002,15.776481300712016,1.2891534955382735,-0.006040144005302839
192.600000000002,15.81323888785968,1.292688111510861,-0.006040144000045267
193.80000000000203,15.849757345055451,1.2951723135453013,-0.006040144000001302
195.00000000000205,15.886730866473034,1.296183918101845,-0.006040144000000414
196.20000000000206,15.923241471444944,1.3014150213232234,-0.006040143999929359
197.40000000000208,15.959911756845234,1.3061219244633404,-0.006040143997760428
198.6000000000021,15.996789678292332,1.310072567285013,-0.006040144800554703
199.80000000000211,16.033293910909624,1.313574074577577,-0.006040287877801642
201.00000000000213,16.06976436147075,1.316867685484781,-0.006043576682754459
202.20000000000215,16.10665473687606,1.3204129350858465,-0.005714527516465839
203.40000000000217,16.143101751002817,1.3220052924804853,-0.005709851162958746
204.60000000000218,16.1797971432624,1.3285362227559805,-0.005709804077641767
205.8000000000022,16.216060758790473,1.3340772038621407,-0.00570980399865606
207.00000000000222,16.25288312008827,1.336998618677593,-0.005709804254768525
208.20000000000223,16.28926149310187,1.3424421445351296,-0.005709804991380185
209.40000000000225,16.326112032127725,1.3478285658964215,-0.005706343211832721
210.60000000000227,16.362451346505466,1.3520691976940709,-0.006639407674288389
211.80000000000229,16.399075820744066,1.3566379439393337,-0.007030025802726048
213.0000000000023,16.435663432673586,1.3618855433731711,-0.007029984127261191
214.20000000000232,16.472560569511046,1.3672993344991338,-0.007029970103244576
215.40000000000234,16.50904564936922,1.3729503904766462,-0.00702996998646066
216.60000000000235,16.54548368137592,1.378937606213458,-0.007029933895613016
217.80000000000237,16.58183224839151,1.3848712738524838,-0.007026049796447165
219.0000000000024,16.618326949608115,1.3920910124727905,-0.008365136841959941
220.2000000000024,16.654673204386185,1.3988482990971807,-0.008433572747417184
221.40000000000242,16.69088361787512,1.4059408623345995,-0.00703240938830918
222.60000000000244,16.72782413018618,1.4151345277984049,-0.007029647794571492
223.80000000000246,16.764159321382227,1.4227421627115935,-0.006939419162419913
225.00000000000247,16.800000059547546,1.4321170346654009,-0.008349679677530641
226.2000000000025,16.8368582850674,1.4418652695148717,-0.008350144942469662
227.4000000000025,16.873864440715092,1.452877785243546,-0.008350136117933893
228.60000000000252,16.910054697785927,1.4616665396718969,-0.00835013479785962
229.80000000000254,16.946562605281038,1.4721441369656794,-0.008349830901529298
231.00000000000256,16.983065243387937,1.485169551251209,-0.008336681935322332
232.20000000000258,17.019840102723816,1.4968297984087204,-0.00737102549856905
233.4000000000026,17.05592000665047,1.5104877774709773,-0.007360220805845419
234.6000000000026,17.092895471641633,1.5269596867291488,-0.007360136474371171
235.80000000000263,17.129293336114316,1.5468486064179463,-0.007360138510624115
237.00000000000264,17.165693424953083,1.5663986306514122,-0.007352862688383421
238.20000000000266,17.20235646860816,1.5902084105762344,-0.008643902265098813
239.40000000000268,17.239107066674876,1.6206085291683423,-0.008669958928518184
240.6000000000027,17.27575916923533,1.6574007781306805,-0.008669670827440079
241.8000000000027,17.312782456522665,1.6998985312997026,-0.008629037996880307
243.00000000000273,17.35002513958932,1.7576653387196686,-0.009984571598388836
244.20000000000275,17.387305816998527,1.8302323103231901,-0.009990209199450373
245.40000000000276,17.424648885055504,1.9125810934030474,-0.009990121132691154
246.60000000000278,17.462387966912207,2.003719713803752,-0.00999011842354891
247.8000000000028,17.499535709322423,2.0847017411710635,-0.00999024357846423
249.0000000000028,17.536456757950006,2.1403513030275114,-0.01002129490586734
250.20000000000283,17.573154954049507,2.154526444098663,-0.00965897775118929
251.40000000000285,17.609139804072946,2.1329047441471447,-0.009660181955190694
252.60000000000286,17.644797292670855,2.08079719619239,-0.0096650959027893
253.80000000000288,17.680107845342594,2.0162351906898306,-0.008344790516571887
255.0000000000029,17.715331011573554,1.9504360281629056,-0.009629978015655016
256.2000000000029,17.750762355427334,1.8822025666727529,-0.00966978423036835
257.40000000000293,17.786203928317253,1.821247165634392,-0.009669968160843201
258.600000000003,17.82145038697701,1.7688518990754871,-0.009710994030384779
259.80000000000297,17.857467165262324,1.723007924120987,-0.011092073713488748
261.00000000000296,17.8926333468579,1.6834653040329213,-0.01108887096676403
262.200000000003,17.92881049933728,1.6523308680938673,-0.010946303382988631
263.40000000000305,17.964404532313935,1.6245933992696815,-0.009781538665925904
264.60000000000304,18.000129161465228,1.605136707993143,-0.009779953398170615
265.800000000003,18.036197574196414,1.5895639007090765,-0.009779396759099779
267.00000000000307,18.072157859991254,1.576198160325262,-0.009718050028305836
268.2000000000031,18.108134646299924,1.56539392253609,-0.011100967074522572
269.4000000000031,18.14404173399651,1.5595633806440499,-0.011074118275097078
270.6000000000031,18.180165947399317,1.5542794405116263,-0.00955262572568838
271.80000000000314,18.21629965391804,1.5490005089126604,-0.009559317270495526
273.0000000000032,18.252379083048663,1.54477043325727,-0.011078200733623866
274.2000000000032,18.28823976894648,1.5454110979810198,-0.012620011683665666
275.40000000000316,18.32479664760169,1.5431685518811986,-0.013930502544012846
276.6000000000032,18.360822650563215,1.5428865026916236,-0.013950040450557921
277.80000000000325,18.39692672466094,1.5429322176701132,-0.013950099959878948
279.00000000000324,18.433114869166424,1.5409819724298104,-0.013944458002042914
280.20000000000323,18.469294210336976,1.5411921068400487,-0.015268180122582464
281.4000000000033,18.505618322306034,1.5437988584879176,-0.015270231672956491
282.6000000000033,18.54149254546904,1.5413561399313942,-0.015269901847746237
283.8000000000033,18.57808773777275,1.5427921461130933,-0.015269759180243092
285.0000000000033,18.614052786519323,1.5454781499051526,-0.015258200378994502
286.20000000000334,18.650416854773,1.5421157876138798,-0.01424759595603664
287.4000000000034,18.68679523776498,1.5457553389248928,-0.014269654086269679
288.6000000000034,18.72288721478301,1.5473852306697682,-0.013955688955630485
289.80000000000337,18.758302751053634,1.5469124561648926,-0.01394977956582899
291.0000000000034,18.79484073294187,1.5477147414555774,-0.013943601676618123
292.20000000000346,18.831008712886742,1.5478381917300625,-0.015065206645222595
293.40000000000344,18.86716145898165,1.5497087303525041,-0.015260335039089412
294.60000000000343,18.903830148950004,1.5496812816259802,-0.015262518670060565
295.8000000000035,18.94055101088455,1.5515050501968866,-0.01664810238731862
297.0000000000035,18.976363532518356,1.5534172232113472,-0.016578909258745167
298.2000000000035,19.012961549226517,1.5550131576954511,-0.016579852226387803
299.4000000000035,19.04941966563154,1.5558916746236071,-0.016579660956188125
300.60000000000355,19.085360922691272,1.5575400685250564,-0.017976497949832027
301.8000000000036,19.12205250846828,1.5581155897738008,-0.01790052061032421
303.0000000000036,19.158395955736584,1.5578387050112936,-0.017900037352271525
304.20000000000357,19.19470580129863,1.558022717958445,-0.01789460083327299
305.4000000000036,19.230995833348036,1.5586029704933817,-0.01920006753049508
306.60000000000366,19.26652713836471,1.5610297839883263,-0.019220080376844084
307.80000000000365,19.303454492917144,1.5639922278503484,-0.019219589856406483
309.00000000000364,19.33904502267801,1.5654823534865718,-0.01922081218279237
310.2000000000037,19.375783534033562,1.5670303621892112,-0.02056389350124954
311.40000000000373,19.412865951074792,1.5719237849214167,-0.020529923507927705
312.6000000000037,19.4489903932199,1.570890203466409,-0.020533002806728984
313.8000000000037,19.485364999560215,1.573711570338771,-0.02097254803064752
315.00000000000375,19.521613321330296,1.577061363840575,-0.02053122335362101
316.2000000000038,19.557426836244336,1.5794418278953701,-0.020525288132904773
317.4000000000038,19.594129277054968,1.580167613832253,-0.021824402642494523
318.6000000000038,19.630705084118194,1.5840437039284336,-0.02366891684800221
319.8000000000038,19.667435909828967,1.5850083965350859,-0.02416090707975327
321.00000000000387,19.703802042872628,1.5885585843488619,-0.024156812283322004
322.20000000000385,19.740254151222814,1.5937374170853063,-0.024900109653353653
323.40000000000384,19.776482891509787,1.5958026766742281,-0.0254718149262807
324.6000000000039,19.813541742160666,1.5996442170280813,-0.02546506747857835
325.80000000000393,19.849739221010452,1.60094289430652,-0.026785565672510003
327.0000000000039,19.88647561686419,1.602548504295957,-0.025450165826357285
328.2000000000039,19.922788885307295,1.604628896957024,-0.026841207941797673
329.40000000000396,19.959201198553984,1.6043243719320248,-0.026789957450714663
330.600000000004,19.9957803441674,1.6048071236378945,-0.027949657936565675
331.800000000004,20.03254342115308,1.6060270305278672,-0.029329153963161048
333.000000000004,20.069200614522057,1.6079814476340746,-0.0308515572336594
334.200000000004,20.10600723091891,1.6097820538435765,-0.031153165153285922
335.40000000000407,20.142787444674234,1.6120105850682047,-0.03376467446545517
336.60000000000406,20.17950421050284,1.6121507109533395,-0.035041482682224956
337.80000000000405,20.216133926189105,1.6123348380142886,-0.03700569698070133
339.0000000000041,20.25281808787285,1.6155193506571495,-0.03757855784179975
340.20000000000414,20.289532803647926,1.6159285688609284,-0.03976157300915828
341.4000000000041,20.326372644659145,1.6172632210078794,-0.04091104473171736
342.6000000000041,20.362808142550236,1.619989560624054,-0.04255135554367451
343.80000000000416,20.399562765928923,1.6176253214853102,-0.04424268686057431
345.0000000000042,20.436736330889588,1.6214801133010373,-0.04659187196879744
346.2000000000042,20.473273283428533,1.6197385747263708,-0.04924225006057359
347.4000000000042,20.510128798598238,1.6211438294796798,-0.050281944260079925
348.60000000000423,20.547086327866182,1.619103330071451,-0.053218453306661306
349.8000000000043,20.58377427120037,1.6155298398283577,-0.056572884576960636
351.00000000000426,20.620385291891758,1.613529851295868,-0.05889935291509296
352.20000000000425,20.65744887168947,1.6113234670561247,-0.06222461767094112
353.4000000000043,20.694005693637113,1.6088122558571993,-0.06503248553818208
354.60000000000434,20.731157903236305,1.6056379961960034,-0.06893166534419226
355.80000000000433,20.767713893047052,1.6021248671028172,-0.07323559931945534
357.0000000000043,20.80473472474814,1.5964289451011227,-0.07830333400729605
358.20000000000437,20.84140546200807,1.591221700084807,-0.08281737769449915
359.4000000000044,20.878409537840174,1.5850963771973203,-0.08786578576491788
360.6000000000044,20.91510208640111,1.5792643009324063,-0.09219951104560842
361.8000000000044,20.95206875357415,1.5762558055060802,-0.09692014735074705
363.00000000000443,20.989234432201926,1.5711806161924908,-0.10166746120493686
364.2000000000045,21.025855245997228,1.5659727248946345,-0.10638778931086756
365.40000000000447,21.062616333811988,1.5587875020467266,-0.11205253501002543
366.60000000000446,21.098816469650615,1.556548236320919,-0.11718585971145501
367.8000000000045,21.13693653606247,1.5538291865913756,-0.1237953601777062
369.00000000000455,21.173701394539847,1.550513183925299,-0.12963567168307133
370.20000000000454,21.21064848247001,1.5496760469240822,-0.13557074575965267
371.4000000000045,21.247438726693712,1.5504751626187534,-0.14045806188913978
372.60000000000457,21.28485523952819,1.548086088450619,-0.14597701901016302
373.8000000000046,21.321607610177004,1.5492657676219468,-0.15210262066037084
375.0000000000046,21.358803726481185,1.5486329891656425,-0.15829834670066179
376.2000000000046,21.395694744389168,1.550392805657562,-0.162745972919494
377.40000000000464,21.433023389910964,1.5538905959290759,-0.16924209913632682
378.6000000000047,21.46988766656944,1.557685688871423,-0.17609624441078475
379.8000000000047,21.50739746328756,1.5587874835459261,-0.1842701384787495
381.00000000000466,21.544208056835256,1.5603755750679422,-0.1894131132596253
382.2000000000047,21.581379299131427,1.5624967603339337,-0.19666599725040168
383.40000000000475,21.61877186184676,1.5643935368502255,-0.20251732876917394
384.60000000000474,21.655909610007676,1.5682905140023402,-0.20947542786948148
385.80000000000473,21.693151162817614,1.5720365224843025,-0.2150086826430666
387.0000000000048,21.730594514032408,1.5761299040778523,-0.22162141610339203
388.2000000000048,21.76770702415442,1.5763489278476117,-0.22786270565110156
389.4000000000048,21.804587764812414,1.578052593663921,-0.2353108210837278
390.6000000000048,21.84150707383738,1.5816595590604896,-0.24122502217757136
391.80000000000484,21.87923479478551,1.5820661540954395,-0.24790462055815876
393.0000000000049,21.91651425943325,1.5844554197568745,-0.25471991315249953
394.2000000000049,21.95400815040261,1.584540008360007,-0.2623499233991886
395.40000000000487,21.991143608281465,1.5862815932953442,-0.2696991462170786
396.6000000000049,22.028365658544526,1.589102788826244,-0.2783457604528512
397.80000000000496,22.065648360698745,1.5852634476626812,-0.28542917767719134
399.00000000000495,22.103067196149077,1.586177189198711,-0.29219566794882024
400.20000000000493,22.14062643496058,1.5842652662022592,-0.2989719769307837
401.400000000005,22.17779043620383,1.5841599865941987,-0.3058389345113439
402.600000000005,22.21536340061087,1.584283812201083,-0.313769421959861
403.800000000005,22.252386161639997,1.5802447468751153,-0.32070058235124765
405.000000000005,22.289822628990844,1.5771530076822389,-0.32857740254599
406.20000000000505,22.327248445266186,1.5769138123569915,-0.33684296418430604
407.4000000000051,22.36475814269514,1.5768147096668814,-0.34652885516664345
408.6000000000051,22.402009634960304,1.5768209427237472,-0.35464665792338934
409.80000000000507,22.439353800285332,1.5706824710535068,-0.3632315536164543
411.0000000000051,22.477155876358186,1.5703088944863421,-0.37029280232552386
412.20000000000516,22.514306570735382,1.5672188563771932,-0.3787778328098743
413.40000000000515,22.552059444286655,1.5664598755049899,-0.38839252110648825
414.60000000000514,22.589232699298407,1.5621685242444177,-0.39732208007140546
415.8000000000052,22.626969910968874,1.5623384964311144,-0.40641848208679576
417.00000000000523,22.664343226957925,1.557392715182082,-0.41635267838114
418.2000000000052,22.702082352522396,1.555566778259577,-0.42685809732775226
419.4000000000052,22.739617181281993,1.553660157737464,-0.43550652895389375
420.60000000000525,22.776356729254317,1.5522875620866785,-0.44578475923364014
421.8000000000053,22.814646771279804,1.5507844668019315,-0.4586102470760496
423.0000000000053,22.851520753287733,1.547850537725644,-0.46907020787906717
424.2000000000053,22.889813537976394,1.5454458639735962,-0.4805334356778408
425.4000000000053,22.92732482181716,1.5475368956169417,-0.4917647668128997
426.60000000000537,22.965012075912703,1.5445672840544733,-0.5033760850104874
427.80000000000535,23.00251258928236,1.5460861090317535,-0.515137062337689
429.00000000000534,23.04035454601433,1.5514355355698335,-0.5268373055444155
430.2000000000054,23.07788895675032,1.5528186258083447,-0.5406728051885614
431.40000000000543,23.115821928807236,1.557407446079066,-0.554011815277867
432.6000000000054,23.153415066891856,1.5661483375891962,-0.5680653902512729
433.8000000000054,23.191299048697843,1.573723813044764,-0.5849711136570024
435.00000000000546,23.229394527309648,1.5837694250355534,-0.5999350995075501
436.2000000000055,23.267110862438795,1.5956333225622357,-0.6160693789614178
437.4000000000055,23.30476756011479,1.6091341137515338,-0.6313949426212653
438.6000000000055,23.34304195459967,1.6248235524475256,-0.6484519718574822
439.8000000000055,23.38114912390605,1.6413431239384488,-0.6668681828277987
441.00000000000557,23.41913792811515,1.664039661790011,-0.6849242284824806
442.20000000000556,23.457153909862036,1.6823555421908796,-0.70430339131565
443.40000000000555,23.49445510877197,1.6994493241190378,-0.7238244427717784
444.6000000000056,23.53293089458073,1.7131075825133417,-0.7448859312161238
445.80000000000564,23.570981264936993,1.726476985617578,-0.7654395469709536
447.0000000000056,23.609106201595885,1.7392383467098098,-0.788608803626857
448.2000000000056,23.64736987973428,1.7505538164218923,-0.8113351057789155
449.40000000000566,23.68534206348331,1.7626000422705133,-0.8333600263048462
450.6000000000057,23.723367917388366,1.7721795645974008,-0.8575510939479942
451.8000000000057,23.761105768079435,1.7827902086436545,-0.8821599013385284
453.0000000000057,23.799135871397244,1.7872457622294993,-0.9077768242994102
454.20000000000573,23.83752900521248,1.7978601686495521,-0.9347906155771075
455.4000000000058,23.87585193789802,1.80340581433848,-0.9620830094486377
456.60000000000576,23.913803352214845,1.8107057131499804,-0.9904056094370088
457.80000000000575,23.95226059549409,1.8147656362006197,-1.0202352112210114
459.0000000000058,23.99003298266144,1.8182723212761038,-1.0501873288912709
460.20000000000584,24.028624942175774,1.818251002920197,-1.0794754687427406
461.40000000000583,24.066433973627472,1.817992874480767,-1.1080452553921085
462.6000000000058,24.104517719615114,1.8151028699808138,-1.1361238042742436
463.80000000000587,24.142668085778723,1.8071988161599486,-1.1653273975811222
465.0000000000059,24.179910691514443,1.7955318523745292,-1.1924184698909701
466.2000000000059,24.217597713867708,1.7800818354558996,-1.218862582948797
467.4000000000059,24.25570749912558,1.7573375569622711,-1.2453266511284005
468.60000000000593,24.294218414503888,1.7377988216283304,-1.2699721994562485
469.800000000006,24.331994526180562,1.708794876521711,-1.2906823033656787
471.00000000000597,24.369818549678943,1.6736708449655446,-1.3093477594394622
472.20000000000596,24.407497265550088,1.6386820107160975,-1.3276880825641912
473.400000000006,24.44562475877036,1.599762965743688,-1.3440698387210608
474.60000000000605,24.483149891194053,1.5572216896316249,-1.3586224797617268
475.80000000000604,24.520902712899186,1.5175710795790978,-1.3726803375489842
477.000000000006,24.558594205388275,1.4776854897593836,-1.3850394184703112
478.20000000000607,24.596362615300325,1.4424667215426485,-1.3974499586165043
479.4000000000061,24.634351596368116,1.4123167049014815,-1.4093576839594886
480.6000000000061,24.672143736977578,1.3857097204993651,-1.4199391734532112
481.8000000000061,24.709886506920874,1.3645085650848192,-1.4297394740341418
483.00000000000614,24.74802456028993,1.3428629062793997,-1.4391398427017226
484.2000000000062,24.785598343800693,1.3313767720795728,-1.4484680522226316
485.4000000000062,24.824344769142506,1.3225781399640109,-1.4578755290671217
486.60000000000616,24.862520189425634,1.3158269344657183,-1.4690038835972206
487.8000000000062,24.900635359155398,1.3105323513551494,-1.4795988613007207
489.00000000000625,24.93892069985077,1.3054014579335127,-1.4894798161174307
490.20000000000624,24.97719968454534,1.3024432382489015,-1.4988188966018852
491.40000000000623,25.015488421835926,1.3013259103744583,-1.5109739398556843
492.6000000000063,25.053689129298824,1.3004881620338296,-1.522188592180549
493.8000000000063,25.09171165815829,1.295448750864672,-1.533128678301729
495.0000000000063,25.130124296252667,1.290157850902719,-1.5448100758076757
496.2000000000063,25.168426085469605,1.2811433014725346,-1.5566931139066802
497.40000000000634,25.206896276654845,1.2685399115289306,-1.5675382672343758
498.6000000000064,25.24474799865658,1.249934736983263,-1.5801574344089802
499.8000000000064,25.28267679902352,1.221430682886285,-1.5920080148007192
501.00000000000637,25.32112422579961,1.190314428057519,-1.6017791410052986
502.2000000000064,25.35901196734919,1.1575711868204763,-1.6116889361957227
503.40000000000646,25.39703654541197,1.1153616424565203,-1.6210142634184153
504.60000000000645,25.43500832709363,1.070669655769955,-1.6286638970673843
505.80000000000643,25.4726899442233,1.0227953183673062,-1.6354402015780245
507.0000000000065,25.51051768186463,0.9754515729666956,-1.640606694368012
508.2000000000065,25.54859189005017,0.9309026885382097,-1.6442942430358496
509.4000000000065,25.5862876861084,0.8941031611056361,-1.647691162390811
510.6000000000065,25.62473742365684,0.8661812209300376,-1.6512116654118651
511.80000000000655,25.66262509740916,0.8426226211022996,-1.6520174765777145
513.0000000000066,25.701206223116937,0.825824148978792,-1.6539406291992877
514.2000000000066,25.739201702239097,0.8200013608558245,-1.655309706961885
515.4000000000066,25.777974690919503,0.808755219784863,-1.6566515600971345
516.6000000000066,25.81650297475903,0.8050426358634817,-1.6582333852777458
517.8000000000067,25.85488790068809,0.8042520995525808,-1.6584883270385031
519.0000000000066,25.893348413534483,0.8020741158133656,-1.6595144933624035
520.2000000000066,25.93217824714136,0.8023231649619853,-1.660808616204136
521.4000000000067,25.970454255914483,0.8012127175870927,-1.6607747480117605
522.6000000000067,26.00929657121462,0.8014524363081704,-1.6621177637927582
523.8000000000068,26.04791261460791,0.8007834372218124,-1.6635695498786838
525.0000000000067,26.08638564226978,0.8023131188372814,-1.6650800646429342
526.2000000000068,26.125001686109,0.8031147603727208,-1.6663712913629842
527.4000000000068,26.163784314628984,0.8058501962990271,-1.6676938594720063
528.6000000000067,26.202467541271837,0.8085627931826005,-1.667714218610318
529.8000000000068,26.240696579501464,0.8082559494375865,-1.6685860924291678
531.0000000000068,26.279938361171457,0.8122655476599598,-1.6696819057032228
532.2000000000069,26.31878131417541,0.8168237815442441,-1.6711021422922467
533.4000000000069,26.357278642619562,0.8199334639367616,-1.6726366742790684
534.6000000000068,26.3963819780194,0.8233166903970025,-1.673852480037353
535.8000000000069,26.434980186208666,0.8254492132164446,-1.675080885836374
537.0000000000069,26.47392573630017,0.8315448570371855,-1.676349011603941
538.2000000000069,26.51286132198622,0.8308034317231596,-1.6786335724257797
539.4000000000069,26.551574504804428,0.8370099657900114,-1.6785019999400355
540.600000000007,26.590648271722905,0.8391675660859468,-1.6792326818285819
541.800000000007,26.62936493565294,0.8422931987886487,-1.6802456504247596
543.000000000007,26.66777673086629,0.8416752585230703,-1.6815126169224888
544.200000000007,26.70716271928581,0.8438176759976032,-1.6833646074414776
545.400000000007,26.74626361189787,0.8482456581567251,-1.6848758276467728
546.6000000000071,26.785301212013234,0.8481821443344543,-1.6864482380905224
547.800000000007,26.824069627907015,0.8512939460540796,-1.687687623263511
549.000000000007,26.86321480832307,0.8515656569703387,-1.6881367901442874
550.2000000000071,26.90239323491141,0.85072499715232,-1.6929914353297986
551.4000000000071,26.94126946010496,0.848727851475134,-1.6957515560514023
552.6000000000072,26.98031789188098,0.8531579529590783,-1.692842482771284
553.8000000000071,27.019201195691718,0.8550759879108187,-1.6908170182520155
555.0000000000072,27.058159405880538,0.8525308700687529,-1.6918343194825973
556.2000000000072,27.097487603003703,0.8557851966486281,-1.6931931035751662
557.4000000000071,27.136762331494534,0.8562283377474819,-1.6958229218448064
558.6000000000072,27.175955686499503,0.8554109951065331,-1.6973511515699888
559.8000000000072,27.215013577471318,0.8563361163338327,-1.6986033761869725
561.0000000000073,27.25442702361579,0.8556561701232168,-1.699991780100203
562.2000000000073,27.29342146867912,0.8565841604214668,-1.701292758362896
563.4000000000073,27.33204421363339,0.8570543516934033,-1.7022146919894108
564.6000000000073,27.371650943512467,0.8562321849734367,-1.7044075966320018
565.8000000000073,27.410758002093235,0.859162507632232,-1.705812438507175
567.0000000000073,27.450090040203772,0.8615913540590668,-1.7084567840805986
568.2000000000073,27.489558351225725,0.8617679300604203,-1.7097588111204036
569.4000000000074,27.52845438865119,0.8636822733459786,-1.7110774965444477
570.6000000000074,27.568005757514403,0.8632420097162904,-1.7126452054017571
571.8000000000075,27.60712314148324,0.8636858553548471,-1.7138579050362024
573.0000000000074,27.646362583693513,0.8642544176861607,-1.7146279747108575
574.2000000000074,27.685574841459736,0.8679213039138394,-1.7165203393190462
575.4000000000075,27.72487839414099,0.8706351567373698,-1.7185604444314118
576.6000000000074,27.76450511449931,0.8703505536117903,-1.7199493552836627
577.8000000000075,27.803513001323783,0.8727589912825531,-1.7212502160936793
579.0000000000075,27.842601749370836,0.8752201002994215,-1.721530960819457
580.2000000000075,27.88197952235573,0.8759588525762173,-1.7240094622210433
581.4000000000076,27.92162797355266,0.8829102990162698,-1.726177807185167
582.6000000000075,27.960751306523424,0.8851944621560204,-1.7276587257422213
583.8000000000076,27.99976122977794,0.8894858173326115,-1.7295972528274786
585.0000000000076,28.039365941154205,0.8924451679092363,-1.7325055874154263
586.2000000000075,28.079072081377895,0.8986195439962341,-1.7340249531215153
587.4000000000076,28.118240344405642,0.8995536961141384,-1.7365657482577261
588.6000000000076,28.157581339279112,0.9046981033733,-1.7388690724863216
589.8000000000077,28.197212923424818,0.9114912474249496,-1.7403939480856279
591.0000000000077,28.23677506076122,0.9147200924270261,-1.741747934484514
592.2000000000077,28.27629599152532,0.922013394245189,-1.7450014443343718
593.4000000000077,28.31558794549243,0.9259662300551262,-1.7478583458120758
594.6000000000078,28.355150442521936,0.9334709978158646,-1.750577210464379
595.8000000000077,28.394477633402648,0.9429689602146684,-1.7538902990392113
597.0000000000077,28.43414260436111,0.9518193097161797,-1.7569473160346951
598.2000000000078,28.474036898578486,0.9596135619970753,-1.7597393915450792
599.4000000000078,28.513013515546323,0.9731018536899771,-1.7629584600860846
600.6000000000079,28.55295386319823,0.9898819427477356,-1.7667984082293726
601.8000000000078,28.59279033482599,1.0061533264466114,-1.7712318945880816
603.0000000000078,28.632271520012445,1.0258158671394453,-1.7752115350354072
604.2000000000079,28.67187575902743,1.0460452209194826,-1.7803942608424737
605.4000000000078,28.711673852866227,1.062627084110245,-1.7849819123561943
606.6000000000079,28.751495921810996,1.0770885359900129,-1.7890989596864926
607.8000000000079,28.791310301143152,1.0895870583380283,-1.794631888038822
609.000000000008,28.831034043180043,1.1024582073348625,-1.7998368142524481
610.200000000008,28.870700906612157,1.109576736847936,-1.80420006269163
611.4000000000079,28.91022453574318,1.11906422515601,-1.811467192009903
612.600000000008,28.949945914690066,1.121302545063145,-1.8186003176071113
613.800000000008,28.989563866790803,1.1253814174185508,-1.8248732677811033
615.000000000008,29.029069918582206,1.1285603508446733,-1.833485739535429
616.200000000008,29.06860389557972,1.1308054651505488,-1.8394147280888893
617.400000000008,29.10830713169756,1.1345586968378532,-1.8468667905308407
618.6000000000081,29.148170218212414,1.1399727938489226,-1.8541245401986886
619.8000000000081,29.187597861528957,1.140907873135665,-1.862247270597872
621.0000000000081,29.227277110075587,1.1442508943617744,-1.8716535511335173
622.2000000000081,29.26682311204833,1.143906503265305,-1.8802973427625482
623.4000000000082,29.30662380087894,1.1415568293235487,-1.8895330965156618
624.6000000000081,29.346155022936294,1.1430300411686574,-1.898926099704982
625.8000000000081,29.385811809222265,1.1429339386963144,-1.9076577374194934
627.0000000000082,29.42541628699107,1.1429831507786976,-1.9171088044293456
628.2000000000082,29.46511270019901,1.145624452303649,-1.9266584620562206
629.4000000000083,29.50477308593589,1.1509464139965297,-1.936112624279184
630.6000000000082,29.544902119455763,1.1503582113086948,-1.9462099474308032
631.8000000000083,29.584280543557966,1.1540204321732566,-1.9554249133591242
633.0000000000083,29.623973424695016,1.1540810042825351,-1.965306567071344
634.2000000000082,29.663663489693587,1.1581750628425307,-1.9747150015588764
635.4000000000083,29.703232922585478,1.1570832822729775,-1.9848075156998575
636.6000000000083,29.743275606572485,1.1579458122233244,-1.9934646094927415
637.8000000000084,29.7824117932958,1.159741827018048,-2.0009316442198175
639.0000000000084,29.822611163619776,1.1687877871723409,-2.0070296439755135
640.2000000000083,29.862718681317865,1.1728519081056652,-2.0113865491489515
641.4000000000084,29.902403814547366,1.1781908999987425,-2.0151919197496446
642.6000000000084,29.94247773687696,1.1733887458413303,-2.0174243078174854
643.8000000000084,29.98173087341241,1.1716240555134458,-2.018953443982171
645.0000000000084,30.021628819159428,1.1646252074377648,-2.021176703186291
646.2000000000085,30.061465118274075,1.158870399186689,-2.023235560518164
647.4000000000085,30.101124117436484,1.1494515926579347,-2.024554806929584
648.6000000000085,30.141210685687174,1.1489480404847918,-2.026270371691212
649.8000000000085,30.18084745540881,1.1530962556879782,-2.0263822036517913
651.0000000000085,30.22076370971738,1.1600037617872134,-2.0277286138530295
652.2000000000086,30.26043557243968,1.1717989269331974,-2.029048463548997
653.4000000000085,30.300524870311346,1.187030698691326,-2.02979290009314
654.6000000000085,30.339863437686382,1.2032384846558695,-2.0315026342664972
655.8000000000086,30.380603057248678,1.2258461139701318,-2.0334455902053294
657.0000000000086,30.420632631883745,1.2456432316902752,-2.034881860982031
658.2000000000087,30.46034982336489,1.2669814754376427,-2.0367278566212415
659.4000000000086,30.50055728720351,1.2995816489473002,-2.0385748803013533
660.6000000000087,30.54040568047285,1.3166322103840395,-2.0406115496030433
661.8000000000087,30.58074802813864,1.3445105261377917,-2.0421281082676046
663.0000000000086,30.621006196030812,1.3700051287695603,-2.043609160342723
664.2000000000087,30.66122821327269,1.3960417015615783,-2.0439120291465893
665.4000000000087,30.701237072936596,1.4214893487658027,-2.047339007707572
666.6000000000088,30.74122319396329,1.4492984240396456,-2.048877501909976
667.8000000000088,30.78164229687408,1.4780480614674967,-2.0510700211474564
669.0000000000088,30.821359089627528,1.5064847502640337,-2.0538315274409498
670.2000000000088,30.86178507861935,1.536030951968975,-2.055277582138697
671.4000000000088,30.902153797216528,1.5672532151255947,-2.0581620320142346
672.6000000000088,30.942327104897302,1.5997984188041403,-2.060071952955898
673.8000000000088,30.9826484598964,1.6371552209859572,-2.0631183882608135
675.0000000000089,31.02296985943926,1.6708271170901765,-2.065607881710151
676.2000000000089,31.063057245598156,1.7134986993492916,-2.0686159994376636
677.400000000009,31.103345309199852,1.7555766511076112,-2.0706443659449922
678.6000000000089,31.143697187579836,1.7998536644598448,-2.0734905215495063
679.8000000000089,31.183868879623226,1.8458836806828243,-2.077058202258071
681.000000000009,31.22441694917575,1.8922339956051062,-2.0792429641061947
682.2000000000089,31.264742113275066,1.9415741878954826,-2.082487048094938
683.400000000009,31.305223258017183,1.9936358187400303,-2.0853107301271177
684.600000000009,31.34584867597273,2.044262671201925,-2.089794364765345
685.800000000009,31.386387583962183,2.0995869705101633,-2.0937751863993666
687.0000000000091,31.42668592151928,2.155681626418197,-2.097520962729313
688.200000000009,31.466990507689278,2.2106939485326698,-2.1025494456391165
689.4000000000091,31.50767978334272,2.2721902753527816,-2.1066467457172124
690.6000000000091,31.548204026696354,2.332587473853186,-2.1101748103373295
691.800000000009,31.58836780018673,2.3913652853616676,-2.11518400306134
693.0000000000091,31.629137228067304,2.455811846106239,-2.120355801345159
694.2000000000091,31.670056167355195,2.5166018040349356,-2.12431663761702
695.4000000000092,31.710592901090486,2.5821299478043596,-2.129913942464053
696.6000000000092,31.7511124684541,2.6493537752188443,-2.134600575949827
697.8000000000092,31.791683600575404,2.7155824474009984,-2.139106571038927
699.0000000000092,31.832463339883336,2.78924557151774,-2.144600988060925
700.2000000000093,31.873176133409572,2.8597891011134164,-2.1505649200590264
701.4000000000092,31.913527040158414,2.9303032726892857,-2.1561061776502313
702.6000000000092,31.9543075836868,2.997532607597395,-2.162126791604406
703.8000000000093,31.994918720731025,3.074595143540521,-2.1668764493629213
705.0000000000093,32.03580236222887,3.1460619254822495,-2.17174886621663
706.2000000000094,32.07587912688791,3.2202796606237234,-2.1795571228989687
707.4000000000093,32.11704494395545,3.2938834454402843,-2.1867602498241565
708.6000000000093,32.15776945135545,3.3637682231026087,-2.193914109880395
709.8000000000094,32.19855782099347,3.4407367141377176,-2.201143373888118
711.0000000000093,32.23972103277103,3.5194771581224247,-2.2081987506191885
712.2000000000094,32.27954220290876,3.5901680685054824,-2.2162648815217962
713.4000000000094,32.321158415604245,3.663060647560232,-2.2244495443004473
714.6000000000095,32.362001085340296,3.740538258305246,-2.231277390008369
715.8000000000095,32.40265797745726,3.816801808644379,-2.2383961321979378
717.0000000000094,32.44333902149834,3.8954820342228924,-2.246838849604401
718.2000000000095,32.48409811629956,3.9690814389297904,-2.253136086380735
719.4000000000095,32.52487714749085,4.0463775771382,-2.262864415319127
720.6000000000095,32.565831537571846,4.12427785593386,-2.2727480410399448
721.8000000000095,32.60654952304253,4.20198425113457,-2.2821479003135776
723.0000000000095,32.647272227331854,4.271067148791694,-2.2858423702449504
724.2000000000096,32.68833593613675,4.348594583664639,-2.2942426619926763
725.4000000000096,32.729067852686526,4.428070241429909,-2.312551118938612
726.6000000000096,32.76975603779799,4.505537979412499,-2.3228281752531257
727.8000000000096,32.810915752001506,4.585343286908521,-2.3317375468396326
729.0000000000097,32.85174756557383,4.67229014365724,-2.3409181922333695
730.2000000000096,32.89251130252394,4.761292541701377,-2.3509255470057973
731.4000000000096,32.93376430478499,4.854491738225892,-2.36198944024735
732.6000000000097,32.97478687163683,4.953004352324044,-2.3721562279461033
733.8000000000097,33.015234016374045,5.055732441620732,-2.3812246062754596
735.0000000000098,33.05697514819736,5.166228056401234,-2.392009768764137
736.2000000000097,33.09837834910203,5.277982396588904,-2.401798608034556
737.4000000000098,33.13943997733212,5.3976569318305545,-2.4129983017283605
738.6000000000098,33.180525561029604,5.514282679601174,-2.4252065409268413
739.8000000000097,33.22201465945181,5.641174226192115,-2.437233291821747
741.0000000000098,33.26344923519676,5.752016422608893,-2.450696386930211
742.2000000000098,33.304287417725526,5.869959584525225,-2.462022595647222
743.4000000000099,33.345609436320444,5.9763474483181565,-2.473780686606102
744.6000000000099,33.386637333816076,6.076799164973136,-2.487999182327867
745.8000000000098,33.42713891448587,6.163632835848252,-2.501016425360072
747.0000000000099,33.46824866772093,6.240841287629661,-2.5133155963476455
748.2000000000099,33.5094133428999,6.302983575022869,-2.526742393769646
749.4000000000099,33.549845874901465,6.34561849928135,-2.5406233482597247
750.6000000000099,33.5906303583146,6.3715275985753,-2.554490765840791
751.80000000001,33.630639271741735,6.3684702562455,-2.5683322037533496
753.00000000001,33.67089091734291,6.339915568165088,-2.58169834211749
754.20000000001,33.710652637124326,6.289540654360503,-2.595205057215364
755.40000000001,33.75029571758891,6.204218947355505,-2.6081520212064677
756.60000000001,33.78948555370468,6.073420397243312,-2.619414113396725
757.8000000000101,33.82829183772416,5.894794341310819,-2.6322135648398346
759.00000000001,33.86668920483551,5.632183578174822,-2.6440889786503083
760.20000000001,33.9041873131045,5.295885435156952,-2.655082204025621
761.4000000000101,33.94079066826805,4.845538238997895,-2.665457968468931
762.6000000000101,33.97532654133505,4.147270741788228,-2.674920997468149
763.8000000000102,34.00880928826636,3.2746724061291586,-2.682050453308344
765.0000000000101,34.042771387303,2.43095916384014,-2.687104750931922
766.2000000000102,34.07798719772942,1.8089482338857312,-2.6884952638137083
767.4000000000102,34.114651793764665,1.3720286122029226,-2.6908098292679714
768.6000000000101,34.152207209784365,1.0860214385000904,-2.6917506927713135
769.8000000000102,34.19012567881403,0.8950397300445876,-2.69287111147524
771.0000000000102,34.2298538216688,0.7681165204278777,-2.693213548855367
772.2000000000103,34.26926955967729,0.6881007973004003,-2.6945330848181586
773.4000000000103,34.309105388893954,0.6351973109417088,-2.6945298412774488
774.6000000000103,34.348470430212245,0.5949991047412977,-2.6958374909166265
775.8000000000103,34.38900301861298,0.5718802611657348,-2.695839934007502
777.0000000000103,34.4292384714398,0.54879535366681,-2.6958398934476726
778.2000000000103,34.469374107731184,0.532689541548127,-2.696516795641231
779.4000000000103,34.50877534200325,0.5233224947892907,-2.6971603346667945
780.6000000000104,34.54972201151571,0.5123715506638038,-2.6971602818703646
781.8000000000104,34.589789793903925,0.5076679170309863,-2.6985097116953187
783.0000000000105,34.63023144280853,0.5029932872976348,-2.697913660343348
784.2000000000104,34.67021442778916,0.5008316347014503,-2.6985035995283426
785.4000000000104,34.710881573860014,0.5002250359232452,-2.698480214125672
786.6000000000105,34.75164191481299,0.4960460700706091,-2.698479906740119
787.8000000000104,34.79189549790194,0.5005550275363388,-2.6984525726375694
789.0000000000105,34.832342478126115,0.49980790641626727,-2.6997782610035097
790.2000000000105,34.87300545744522,0.49807222444806243,-2.7001164483708386
791.4000000000106,34.91363876376643,0.4973850215022242,-2.701109926265432
792.6000000000106,34.95405820579804,0.49869581633782323,-2.7009764747126237
793.0000000000106,34.96737855373908,0.5004779281545679,-2.699946164205361