File: 01_Data/Polyester_Carpet_High_Pile/STA/N2/30K_min/Polyester_Carpet_High_Pile_STA_N2_30KData_230925_R1.csv
##Temp./Â°C,Time/min,DSC/(mW/mg),Mass loss/mg
51.0,10.613816451936428,0.023153532806614585,0.0037199416570192767
52.20000000000002,10.790138814732119,0.07511686424525044,0.0006487147842006991
53.400000000000034,10.91258418289322,0.11449990538316968,0.0006114997679809164
54.60000000000005,11.011098907473704,0.1470373397590221,0.001222510425997747
55.80000000000007,11.096708192689082,0.17996417929765074,0.0023581461145978366
57.000000000000085,11.172514186618766,0.2092370795227505,0.0010809801066118396
58.2000000000001,11.242626889364843,0.23507912213649074,-1.1756402935603205e-06
59.40000000000012,11.308082173324046,0.2589460554125702,0.001409722454881468
60.600000000000136,11.369283483684056,0.28126072204707175,0.0005839357841503912
61.80000000000015,11.427895403992247,0.29984099839049505,0.0014496790255549286
63.00000000000017,11.484219162422656,0.32023709051175175,0.002789447728395622
64.20000000000019,11.538445558118056,0.33645780228931477,0.0021115535915114947
65.4000000000002,11.589419785382635,0.35253472278014697,0.0003810414188274436
66.60000000000022,11.64129321729092,0.36797305244836087,0.0002492077596469855
67.80000000000024,11.692012665524834,0.3827620605681399,0.0007331705977042802
69.00000000000026,11.740963388149602,0.3970461011240416,-0.0005779004030985746
70.20000000000027,11.78951904110253,0.4072104339756153,-0.0010533853898593293
71.40000000000029,11.836401290780664,0.4201535878316951,7.670933389292145e-05
72.6000000000003,11.882813115997454,0.42949646157734755,0.0004440750848528907
73.80000000000032,11.92919570373001,0.4417605632979609,0.0016507534431111637
75.00000000000034,11.974479570349393,0.45208186727690425,0.0007390265692990283
76.20000000000036,12.019574041115728,0.46273247687884567,0.00042709267315732546
77.40000000000038,12.063551913851851,0.4687278223151321,-0.0008824668976483707
78.60000000000039,12.107722763248262,0.4778278430238061,-0.0009227445557460356
79.80000000000041,12.1515872173379,0.48034399022803154,0.000406194895189671
81.00000000000043,12.194184416700077,0.4851050575720739,0.00041735595284553284
82.20000000000044,12.237477100706856,0.4846850634398503,0.0006123043141599283
83.40000000000046,12.279778894773639,0.48170504346163345,0.000675372470725577
84.60000000000048,12.322173852977052,0.48224908869468996,0.00010334276965640043
85.8000000000005,12.364429018775136,0.4812611778175393,0.0005660544594503492
87.00000000000051,12.406132983176171,0.4792456121816451,0.0004517419463825334
88.20000000000053,12.448077371702986,0.4806310124576405,0.0007381398897461366
89.40000000000055,12.489194862673633,0.4811890340334395,-0.00018772745937489788
90.60000000000056,12.530367593948265,0.48009550748908847,-0.0007785034022029791
91.80000000000058,12.571263625496146,0.4781000746459252,-0.0007066931187145187
93.0000000000006,12.612157548375235,0.4790461082509858,0.0002597378351651969
94.20000000000061,12.653047263830961,0.4764148362452414,0.00039836687720296027
95.40000000000063,12.694007147418347,0.4781129537210711,-0.0007048423942057624
96.60000000000065,12.733999210802889,0.47672482014554607,-0.0006390001522662558
97.80000000000067,12.773725973011192,0.47841367714487637,-0.002005231317355083
99.00000000000068,12.815179492261809,0.48083667537034214,-0.0016660439006406236
100.2000000000007,12.854898089156398,0.48202913560781857,-0.0010457002610086974
101.40000000000072,12.89500340122381,0.4832492674998736,-0.0013152708220607323
102.60000000000073,12.935646608053487,0.4839021370346952,-0.0011677499514926026
103.80000000000075,12.97556235774868,0.4861756989860959,-0.0007813283718425268
105.00000000000077,13.015192130942708,0.48971517160713374,-0.002106221477497172
106.20000000000078,13.055607120714665,0.4892295329873948,-0.002270192486542477
107.4000000000008,13.095417039215702,0.490769848993002,-0.003400564998350397
108.60000000000082,13.135224246317561,0.4959149237489221,-0.0020439136660348467
109.80000000000084,13.17502210285155,0.4975348061309033,-0.0020583392561981384
111.00000000000085,13.214974791275319,0.499637407072263,-0.00207048642309271
112.20000000000087,13.25492005741383,0.5048053858026543,-0.0020898780503841863
113.40000000000089,13.294720324713232,0.5049676155717017,-0.00207729200105522
114.6000000000009,13.334340208840091,0.5075208597701095,-0.0007155987423033139
115.80000000000092,13.374286705682497,0.5101747367302653,-0.0007832412608763661
117.00000000000094,13.413788846951649,0.5130794102476554,-0.0021370512790577223
118.20000000000095,13.453208506974153,0.5149730367685557,-0.002091544377635479
119.40000000000097,13.493061141769966,0.520652018267052,-0.0023585701700543638
120.60000000000099,13.532863294419254,0.5232454206707393,-0.0033531036303706685
121.800000000001,13.572074022372032,0.5244582513431117,-0.0027485699422697962
123.00000000000102,13.611687014234953,0.5269271348644272,-0.0027513195804305113
124.20000000000104,13.650863448768636,0.5282981086374114,-0.0026033774296880807
125.40000000000106,13.690331494902187,0.5309518239959767,-0.003408960856924992
126.60000000000107,13.729297984820523,0.5356742025288231,-0.003410893272112858
127.80000000000109,13.76890223342565,0.5353401834388157,-0.002782608584135815
129.0000000000011,13.807947378733074,0.5414955947216086,-0.0030908703430734263
130.20000000000113,13.84687594679208,0.5418736250833173,-0.0030907695544133418
131.40000000000114,13.886234696817812,0.5464198409162567,-0.00329545850990165
132.60000000000116,13.924770143001009,0.5482995405862017,-0.003409563146210992
133.80000000000118,13.963812043755874,0.5532998740240485,-0.0034101380558206884
135.0000000000012,14.002823393305261,0.5545650620152444,-0.003410345012584415
136.2000000000012,14.041328616739769,0.5596311624294129,-0.0034277946476848342
137.40000000000123,14.080195601450491,0.5618635681799308,-0.0030662615386409797
138.60000000000124,14.119034426881388,0.5656326482793173,-0.004072320295295917
139.80000000000126,14.157409151284375,0.569076187948516,-0.0040725221281947555
141.00000000000128,14.195811861376288,0.5736685130978392,-0.0037128197014206776
142.2000000000013,14.234567580111701,0.5775004742546984,-0.0037397451668796933
143.4000000000013,14.27299319131619,0.5840719077280744,-0.003739935038158393
144.60000000000133,14.310856611684903,0.5880331884068144,-0.0037399359798415688
145.80000000000135,14.348648483019833,0.5948090117868134,-0.0037399395845314487
147.00000000000136,14.388040466835125,0.6021553980175535,-0.003740819095710002
148.20000000000138,14.425981834380552,0.6093351645474028,-0.0041123171920052215
149.4000000000014,14.4634975399452,0.6156327326834669,-0.004731329891167313
150.60000000000142,14.50255858106135,0.6252667964370504,-0.004729374390074703
151.80000000000143,14.540801050888948,0.6362783087691982,-0.005507411966817699
153.00000000000145,14.57881692624934,0.6472074386378233,-0.004733012958384464
154.20000000000147,14.61695611180213,0.6618680876441636,-0.004729915988538558
155.40000000000148,14.655448895538413,0.6805404332519922,-0.004729868331040166
156.6000000000015,14.693478703640741,0.6959186657349621,-0.00472986800175601
157.80000000000152,14.731612428338677,0.7159929235718782,-0.0047298680000054105
159.00000000000153,14.770031849321043,0.7315912915668144,-0.004729867999992088
160.20000000000155,14.80764926459727,0.7536889334602249,-0.004729868028976014
161.40000000000157,14.8457946576819,0.7718941259291124,-0.004729874327832562
162.6000000000016,14.88390018429111,0.7839403106928716,-0.0047308034578659175
163.8000000000016,14.921768600707141,0.7862212418816928,-0.004281126063667706
165.00000000000162,14.95917351796615,0.7839867111817853,-0.004031505231422372
166.20000000000164,14.99639803238295,0.7725681107714486,-0.005060314014010636
167.40000000000165,15.033598929487717,0.7561107373759247,-0.005060065276210501
168.60000000000167,15.071066974838237,0.7317871450824677,-0.00505993523886783
169.8000000000017,15.108499032495509,0.7101068055389653,-0.005041927183769168
171.0000000000017,15.145534849890659,0.6949498309107792,-0.003703327880480778
172.20000000000172,15.182437149718908,0.6798729114862235,-0.004072461398915372
173.40000000000174,15.2195283278349,0.6673204713393325,-0.004087751189874034
174.60000000000176,15.256819324661745,0.6593140299487777,-0.0050734699495533775
175.80000000000177,15.294066139254262,0.652980175209989,-0.005060176590916399
177.0000000000018,15.331444738011845,0.6454447664447917,-0.00506133293709965
178.2000000000018,15.368595790746042,0.6428783531364485,-0.005986118195610679
179.40000000000182,15.405258601954843,0.6400546564981038,-0.005788546830293839
180.60000000000184,15.442536470891,0.6409812277660178,-0.0045047729263894
181.80000000000186,15.479543147378674,0.6368593365408759,-0.004510358458842845
183.00000000000188,15.516638616403457,0.6352199220734969,-0.005154722545501755
184.2000000000019,15.553647926170836,0.636216908945638,-0.00583068093567185
185.4000000000019,15.590093925396399,0.6375007946603739,-0.005830160134118856
186.60000000000193,15.627429763858702,0.6362222041034802,-0.005830160101357507
187.80000000000194,15.6642631307327,0.6375351879560504,-0.005830182516618265
189.00000000000196,15.701237576259343,0.6377023049977361,-0.0058312932440323095
190.20000000000198,15.73840825284107,0.637773280966311,-0.005255758051298187
191.400000000002,15.774203306473265,0.6411131338700364,-0.005171355891885554
192.600000000002,15.81151197742321,0.6399386598308175,-0.005170028106229907
193.80000000000203,15.848157885888817,0.6440641245293689,-0.005170102169325119
195.00000000000205,15.884789647676246,0.6461158735510887,-0.00518692843593449
196.20000000000206,15.921652641780913,0.6472626033102955,-0.005816674745961592
197.40000000000208,15.958429375154147,0.6470765742085135,-0.005830268256145743
198.6000000000021,15.995117888261545,0.6511228453458336,-0.005830161560848701
199.80000000000211,16.03178382955946,0.6515357175956832,-0.005830182506801229
201.00000000000213,16.06856292965597,0.6546376845284023,-0.005836822233955097
202.20000000000215,16.104975333758492,0.6556013604528828,-0.0046988955682953915
203.40000000000217,16.141404566342498,0.6597900872716538,-0.004508514023403798
204.60000000000218,16.17810583533204,0.6575951853834845,-0.005015143337469219
205.8000000000022,16.21465797867127,0.6609709065686973,-0.006462692805510706
207.00000000000222,16.25147959551387,0.6638672274447974,-0.007459121727199758
208.20000000000223,16.287650910313758,0.6665331261442962,-0.0074701384410529315
209.40000000000225,16.32437410464539,0.6681235922460806,-0.0074692751524843
210.60000000000227,16.36077298031676,0.6718948201460169,-0.0077458999070865175
211.80000000000229,16.39742353802026,0.6733419090095868,-0.0077993402110836385
213.0000000000023,16.434146086995035,0.6747575155936587,-0.007799994127033472
214.20000000000232,16.47030826680555,0.6815843688920682,-0.007799996034306922
215.40000000000234,16.506896731664913,0.6827246520169077,-0.00779999600039627
216.60000000000235,16.54346117699498,0.6827468226500188,-0.0077999960000010304
217.80000000000237,16.580119601877925,0.6889195822391236,-0.007799996007201493
219.0000000000024,16.616342964324513,0.6951539524546899,-0.00779999696946021
220.2000000000024,16.653133599002505,0.6981093396838399,-0.00779997030782642
221.40000000000242,16.689485831819802,0.7030009468532776,-0.007783841984558393
222.60000000000244,16.72601126216161,0.706703932779522,-0.0067888938955071865
223.80000000000246,16.762036562565257,0.7162082747470553,-0.00717039982342893
225.00000000000247,16.798622037446048,0.720628283492114,-0.0071398923323853225
226.2000000000025,16.835380443449356,0.7246400832245696,-0.007141293000876736
227.4000000000025,16.871651870625346,0.7325563771768314,-0.007228499420834034
228.60000000000252,16.90819457153051,0.7403265635829415,-0.008048055325007297
229.80000000000254,16.944545468207178,0.7465059363548285,-0.009762045785026707
231.00000000000256,16.981327617599035,0.7585765195205593,-0.00977970687928309
232.20000000000258,17.017476119522623,0.7713749900541275,-0.009763825482163924
233.4000000000026,17.05426762364764,0.7819374383712456,-0.008464198904635012
234.6000000000026,17.090603142610366,0.7936897405297285,-0.00845447250653919
235.80000000000263,17.1271975702577,0.8097965432189604,-0.009805912464657673
237.00000000000264,17.16353781369812,0.8266704605500961,-0.010327121991708488
238.20000000000266,17.200212847319914,0.8495470140033438,-0.011103288478638618
239.40000000000268,17.236989271516798,0.8761393242230253,-0.01109981201102439
240.6000000000027,17.273666300962937,0.9084886171690338,-0.011099799779888286
241.8000000000027,17.310624519875198,0.953188845399353,-0.011099799892878792
243.00000000000273,17.34756356877682,1.0108452551394793,-0.011099843536934273
244.20000000000275,17.385099673442816,1.0784497395988293,-0.011108901541423855
245.40000000000276,17.421831209532144,1.158286090497596,-0.011426729375263456
246.60000000000278,17.460187680235773,1.2507352458034227,-0.010495047000189217
247.8000000000028,17.497260911005675,1.3248563600798473,-0.010957908186517429
249.0000000000028,17.534314009608554,1.3708729274767668,-0.011098847066802087
250.20000000000283,17.570902530453754,1.37236898896799,-0.011100069170671745
251.40000000000285,17.606675900533105,1.3456201771863339,-0.011100072082611767
252.60000000000286,17.641724197356332,1.2891183364346634,-0.011100071942470535
253.80000000000288,17.67736173776931,1.2228318419355495,-0.01110008063755874
255.0000000000029,17.712703155867455,1.1516791483299345,-0.011101044084658618
256.2000000000029,17.74805604112369,1.0864247995580558,-0.0122661409574647
257.40000000000293,17.783470460504674,1.0220099975421866,-0.012408032575133454
258.600000000003,17.81888744379675,0.971594650594396,-0.012409847314607703
259.80000000000297,17.85420394082857,0.9252661860132283,-0.01240984021599889
261.00000000000296,17.889853985417556,0.8858402262578808,-0.01240983977464083
262.200000000003,17.92550623989474,0.8527250408749734,-0.012409356810779926
263.40000000000305,17.96145133876197,0.823386997526734,-0.01238265589812837
264.60000000000304,17.997356009893018,0.8024863612328952,-0.013733778618671089
265.800000000003,18.033253617978943,0.7862219404604519,-0.013730134077897027
267.00000000000307,18.069145020593467,0.773028849612524,-0.013730532691681674
268.2000000000031,18.105029514536547,0.7633707934580094,-0.013994559887976266
269.4000000000031,18.140791598617863,0.754624393378954,-0.01505160974697084
270.6000000000031,18.17681062160456,0.7468407431521059,-0.015049931960713359
271.80000000000314,18.213107200034454,0.7422824076032316,-0.015049979629320198
273.0000000000032,18.249198076519022,0.7387068199652382,-0.015049979998252638
274.2000000000032,18.285339872885334,0.7342195514855201,-0.015049978786905172
275.40000000000316,18.321048306097367,0.7323939880846762,-0.015049930425929503
276.6000000000032,18.357175025168665,0.7318170553199621,-0.01506292849700408
277.80000000000325,18.393787951840007,0.7303297854163526,-0.016430077765404505
279.00000000000324,18.42943090395879,0.7289100249393424,-0.016366191455840173
280.20000000000323,18.46585969123817,0.7261297821493649,-0.017529327900737357
281.4000000000033,18.501907529674778,0.7262387967949104,-0.01867287942130158
282.6000000000033,18.537981822123225,0.7256794983775023,-0.0186714645814261
283.8000000000033,18.57431048144128,0.7245645203919444,-0.020083296634504144
285.0000000000033,18.61054147995386,0.7250839598849221,-0.019989549697305264
286.20000000000334,18.646821221742638,0.7251389723282489,-0.020458930789674312
287.4000000000034,18.683071659570547,0.7236676161041762,-0.020648744834685928
288.6000000000034,18.71895049070835,0.7260112436622562,-0.020647300170520744
289.80000000000337,18.75523009289168,0.72484707110344,-0.021373110108675597
291.0000000000034,18.79143139766215,0.7249721012932726,-0.02131017371839139
292.20000000000346,18.827620022461822,0.7249924362995599,-0.021537901938423865
293.40000000000344,18.86384942684386,0.7260028627215162,-0.02164030536852568
294.60000000000343,18.900061273643498,0.7291066189917494,-0.021641965168246458
295.8000000000035,18.936468140049442,0.7266892310804114,-0.02287618428788374
297.0000000000035,18.972487710371663,0.7266013468679784,-0.023615108278172592
298.2000000000035,19.00894542358905,0.729502340147233,-0.024849154025929465
299.4000000000035,19.045249247572293,0.7288716629147594,-0.024918362924231552
300.60000000000355,19.081374395200534,0.7265676920916266,-0.024914261015502426
301.8000000000036,19.11749326686352,0.7279261015287679,-0.024446813240172283
303.0000000000036,19.153798834247834,0.7285521488281892,-0.024931705150546435
304.20000000000357,19.190281155611626,0.7277991919864186,-0.02493006737009651
305.4000000000036,19.226464120173922,0.7267356496180809,-0.02493277413978312
306.60000000000366,19.26214815767745,0.7292765852926787,-0.02631654983660514
307.80000000000365,19.299312797499933,0.7291166793371925,-0.026249755486947635
309.00000000000364,19.335885329061227,0.7321090593612811,-0.02603342061811098
310.2000000000037,19.371790532802862,0.7343158384840682,-0.0264215400992871
311.40000000000373,19.40808937893831,0.7350521019239287,-0.027232757761813886
312.6000000000037,19.444676118588568,0.7360815667300915,-0.02723027290539548
313.8000000000037,19.480988389441016,0.7375190640064537,-0.02723746847906927
315.00000000000375,19.517359717596758,0.7424503130787203,-0.02918487820908844
316.2000000000038,19.55370009016718,0.7443268145197173,-0.029650998426939523
317.4000000000038,19.589877032928264,0.7469172760714611,-0.028769680701942413
318.6000000000038,19.626477712276028,0.7505773761765462,-0.029790487332869375
319.8000000000038,19.662925948800332,0.7550120890380816,-0.03022032070789127
321.00000000000387,19.699788433679938,0.757574126107756,-0.031408829583669196
322.20000000000385,19.73591772410103,0.761509938958714,-0.03267401293104211
323.40000000000384,19.772462538934146,0.7669103880362398,-0.032720137869097776
324.6000000000039,19.80892280335775,0.7697074065047479,-0.0327283066180426
325.80000000000393,19.8453795183643,0.7753681999917754,-0.03279495322570991
327.0000000000039,19.881945039111766,0.7789750330506665,-0.032729527870285935
328.2000000000039,19.918722688299486,0.7785129898185201,-0.03405042057800678
329.40000000000396,19.95530388912075,0.7812694081961149,-0.035605576023122865
330.600000000004,19.991723767253077,0.784631628175567,-0.036910209082045675
331.800000000004,20.028222520589313,0.7911025486881846,-0.0380611865339775
333.000000000004,20.06471089054116,0.789692126695615,-0.03930964281711358
334.200000000004,20.101887554331004,0.796984442742765,-0.04019531626211936
335.40000000000407,20.1382385042553,0.7982347284538014,-0.04144102491824553
336.60000000000406,20.174965502388712,0.798522590803721,-0.04194970964652622
337.80000000000405,20.21121333379587,0.8051331620654782,-0.04371270182917897
339.0000000000041,20.247875097001135,0.8069036359547698,-0.04572331264101015
340.20000000000414,20.284572367615223,0.8100955718051511,-0.04750180718084218
341.4000000000041,20.321959788278452,0.8138751189887232,-0.0490891611193649
342.6000000000041,20.35821720324117,0.8169927602101855,-0.05139356638528847
343.80000000000416,20.39472729415546,0.817459917510837,-0.05360523683721796
345.0000000000042,20.43199036377045,0.8215398584098312,-0.05541917398657992
346.2000000000042,20.468791504315323,0.8203735474720648,-0.058710753458514287
347.4000000000042,20.50594056894186,0.8244236867612389,-0.06173372398705235
348.60000000000423,20.54265932222979,0.8266875369645061,-0.06457185484793504
349.8000000000043,20.579081621098524,0.8243936271884895,-0.06748448377818894
351.00000000000426,20.61595868883258,0.8247122944051077,-0.07064148848896101
352.20000000000425,20.65310286410716,0.8248127335717974,-0.07390665897729543
353.4000000000043,20.689875454926568,0.8199215099140948,-0.0773880804870104
354.60000000000434,20.72667564668384,0.8154869431828965,-0.08144395272654359
355.80000000000433,20.763430080562756,0.8144944794066588,-0.0853518363584187
357.0000000000043,20.80006144791032,0.8086689608801865,-0.08981696898758385
358.20000000000437,20.83699708576016,0.803403843404897,-0.0938217715254317
359.4000000000044,20.873837355122557,0.7981675578554479,-0.09761296487801951
360.6000000000044,20.91067744263066,0.791690461217351,-0.1028495541775647
361.8000000000044,20.94739504275747,0.7869961913212205,-0.10842081056529418
363.00000000000443,20.984033187670075,0.7818903034223588,-0.11370179924123258
364.2000000000045,21.02120076402511,0.7774423414145235,-0.11880439670777188
365.40000000000447,21.05782677996318,0.7720778786172202,-0.1243391033955441
366.60000000000446,21.09497295699839,0.7689704678510121,-0.12976886304193913
367.8000000000045,21.131871484528695,0.7655804133683659,-0.13630348951895277
369.00000000000455,21.169099447390952,0.7641998881172885,-0.1416850518052053
370.20000000000454,21.205896275607376,0.7615944973604044,-0.1482535533854783
371.4000000000045,21.242999038645337,0.761010010105085,-0.15402973419643162
372.60000000000457,21.27985039094152,0.7611568924144303,-0.15971454751219794
373.8000000000046,21.31697906783182,0.7639477181061598,-0.1654696883939022
375.0000000000046,21.354244087698433,0.7686522859722035,-0.17308827447699437
376.2000000000046,21.391385909455046,0.7683560338874016,-0.17957039901844363
377.40000000000464,21.428577606584227,0.7699258283713357,-0.18688612098397428
378.6000000000047,21.465347899068597,0.7732894475692694,-0.19270497207028203
379.8000000000047,21.502667346302765,0.7776842795529305,-0.1992380177795905
381.00000000000466,21.539782672176713,0.7783074825644023,-0.20505880860929127
382.2000000000047,21.577073275875087,0.7801959250941048,-0.21160978508323103
383.40000000000475,21.614515420748962,0.7861952427471472,-0.21916452705475953
384.60000000000474,21.651753845707333,0.7909789773288983,-0.22642497140586615
385.80000000000473,21.68878594914455,0.7927183511964655,-0.23313505887411834
387.0000000000048,21.725893445655256,0.7927890758460276,-0.24015546011527045
388.2000000000048,21.762669396634074,0.7977875359715423,-0.2458363575051492
389.4000000000048,21.800778288318064,0.7990007831844165,-0.253130389674197
390.6000000000048,21.837896820537704,0.7980404785258544,-0.259869232779828
391.80000000000484,21.874954724322286,0.8016475385975308,-0.26730531582958106
393.0000000000049,21.911979424321686,0.8034477280948166,-0.27361170706048155
394.2000000000049,21.94937651652587,0.8035819824743033,-0.28045415160978493
395.40000000000487,21.98683839507773,0.8063518127754303,-0.2880173377195554
396.6000000000049,22.024310156651882,0.8047725212003966,-0.2951117337992364
397.80000000000496,22.061361964153967,0.8080504731484871,-0.301668234291129
399.00000000000495,22.09888140717578,0.805505628407396,-0.30930996503924524
400.20000000000493,22.13639379136958,0.807222993808278,-0.31683302520911605
401.400000000005,22.17282440232054,0.8016274022061588,-0.3233883220749205
402.600000000005,22.210980220209,0.8025936561914131,-0.33117808083309086
403.800000000005,22.248190026051894,0.8002724760927508,-0.3392604065961953
405.000000000005,22.28580087737928,0.7989636641880354,-0.34839326159127815
406.20000000000505,22.323092566192347,0.7957336148154748,-0.35663014620575906
407.4000000000051,22.36028310362236,0.7945455477018868,-0.36504208925185866
408.6000000000051,22.39767603310346,0.7898576725259128,-0.37302635915956683
409.80000000000507,22.435217662772896,0.7915821850065881,-0.3825026947016492
411.0000000000051,22.472523083395473,0.7859663532123536,-0.39117846299316117
412.20000000000516,22.510031130749823,0.7839836770599218,-0.39973898168379396
413.40000000000515,22.54749806801825,0.7806536036566517,-0.4089852586656053
414.60000000000514,22.584885533410215,0.7778251936111198,-0.41981799777584783
415.8000000000052,22.62194159421523,0.7748344021492019,-0.4288721337315571
417.00000000000523,22.65975412970889,0.7717184606936762,-0.4388554696954472
418.2000000000052,22.697280863738104,0.7664188699086502,-0.4497386149220475
419.4000000000052,22.734846704158354,0.7652036103765543,-0.4592403869810955
420.60000000000525,22.77231793147874,0.7644659510802329,-0.4695775479823898
421.8000000000053,22.809783435498165,0.7588764195381483,-0.47976864808461883
423.0000000000053,22.84756970321181,0.7584961174384302,-0.49040935806664754
424.2000000000053,22.88506130296948,0.7573236961440779,-0.5018979525290002
425.4000000000053,22.922797585535573,0.7542153766878031,-0.5143232674010534
426.60000000000537,22.960376386020112,0.7550511154430354,-0.5273268161104481
427.80000000000535,22.998141166053315,0.7579466261940255,-0.5414156585820593
429.00000000000534,23.03524199638911,0.7579385433729849,-0.5533165735148096
430.2000000000054,23.073374936698542,0.7610532358585602,-0.5665669592258462
431.40000000000543,23.11110269384233,0.7644698009027775,-0.5804945833393838
432.6000000000054,23.149017139475518,0.7744453711779125,-0.5952354770939543
433.8000000000054,23.186870601298253,0.7805408050016176,-0.6104431948454501
435.00000000000546,23.224504073432836,0.7926952021426347,-0.6254948870348112
436.2000000000055,23.2625122656633,0.8040562768429246,-0.6428765731176829
437.4000000000055,23.300466762259113,0.8136851875353739,-0.6609022756012686
438.6000000000055,23.33817036641707,0.8287846562543028,-0.6783109448709457
439.8000000000055,23.376556057956034,0.8476541228463026,-0.6962658320205097
441.00000000000557,23.414598866026285,0.863062939619035,-0.716277374228663
442.20000000000556,23.45237676637091,0.8783398621805099,-0.73587192809658
443.40000000000555,23.49060888991448,0.8976540388951569,-0.7563621370201781
444.6000000000056,23.528687674729905,0.9080494774317365,-0.7772156498516383
445.80000000000564,23.566642750829498,0.9220817965074182,-0.799061974615376
447.0000000000056,23.604465065872134,0.9363185672020515,-0.8217461125726215
448.2000000000056,23.642866686021495,0.947783513041907,-0.8446969207179995
449.40000000000566,23.6810526450321,0.9591410463680097,-0.8708364524317505
450.6000000000057,23.719381071153393,0.9707148439998153,-0.8960774836044809
451.8000000000057,23.75715967184616,0.9809794922799054,-0.920462992725569
453.0000000000057,23.795308501454674,0.9919912400093329,-0.9468688320478611
454.20000000000573,23.83351280883825,0.9998669790242847,-0.9732246633576622
455.4000000000058,23.871582472712827,1.0069076435343165,-0.9998644111665236
456.60000000000576,23.909317392433387,1.0154336714175494,-1.027408851589866
457.80000000000575,23.947851765543373,1.022336332615502,-1.0566267532350686
459.0000000000058,23.986107725652513,1.0273014803147507,-1.0863744202398697
460.20000000000584,24.023972539843022,1.0294756978839597,-1.115770354311088
461.40000000000583,24.062412056638884,1.0268124770976588,-1.1458945917679637
462.6000000000058,24.10031504522508,1.0243514549811135,-1.1744809455686234
463.80000000000587,24.138618296243486,1.0174939738460997,-1.203551646116841
465.0000000000059,24.176482114247257,1.0057593142462864,-1.2309282986615253
466.2000000000059,24.21430075724294,0.9858002165457479,-1.2579172594368728
467.4000000000059,24.252183994427234,0.9691375236697032,-1.2843965974999074
468.60000000000593,24.290157496461703,0.9417653810268459,-1.3091421745082483
469.800000000006,24.328135494383037,0.9148621725375962,-1.3308612053161797
471.00000000000597,24.365825869689445,0.8812752316602892,-1.3511721070093063
472.20000000000596,24.40378506566661,0.8474241955535973,-1.369053646473065
473.400000000006,24.44136275835925,0.8069500452182542,-1.385058178515742
474.60000000000605,24.479254014504285,0.7652283896687301,-1.4003439169331169
475.80000000000604,24.51673994600828,0.7301472966824306,-1.4134412970270072
477.000000000006,24.555005123740308,0.6912823673100703,-1.4264392711367204
478.20000000000607,24.592969464741476,0.6598674665034064,-1.4372988974310195
479.4000000000061,24.630736280661786,0.6323851279351422,-1.4492023010536856
480.6000000000061,24.66879724949552,0.6077661684965033,-1.4600902570374608
481.8000000000061,24.706922928868483,0.5897092378453085,-1.469476618323835
483.00000000000614,24.74521584828159,0.574833239397468,-1.4791542618257183
484.2000000000062,24.782933486625094,0.5632610022150488,-1.4900702665923138
485.4000000000062,24.821375098580894,0.5545132762729299,-1.5002727419150972
486.60000000000616,24.85968277034248,0.5513670366536026,-1.5097703729640628
487.8000000000062,24.897915178646468,0.5440547583694754,-1.5204745432067241
489.00000000000625,24.936600104306773,0.543940641699343,-1.53185677094155
490.20000000000624,24.97444681038206,0.5435670650963289,-1.542422507396823
491.40000000000623,25.013003402289673,0.5417497369284103,-1.5533562247232946
492.6000000000063,25.051697962456807,0.544376568636398,-1.56537585958666
493.8000000000063,25.08984565585081,0.5415520559419862,-1.5763425643007682
495.0000000000063,25.128070667238234,0.5346692853522135,-1.5883720151524918
496.2000000000063,25.166431406424735,0.5273793737505373,-1.6006070430909132
497.40000000000634,25.205134783353735,0.5085247955254831,-1.6127340035278124
498.6000000000064,25.243319573408947,0.4877259932206691,-1.6252182179435506
499.8000000000064,25.281573436535815,0.46086882653508865,-1.6371302221294668
501.00000000000637,25.318835378789473,0.43145666489048307,-1.6475433077520982
502.2000000000064,25.357310061712262,0.3947005862120462,-1.6567146016414616
503.40000000000646,25.39513325978068,0.3522337642274985,-1.666845088858333
504.60000000000645,25.43356846488792,0.30653639681392064,-1.6749172630962743
505.80000000000643,25.471401490985592,0.258572001168767,-1.6805384272972974
507.0000000000065,25.509451858403207,0.21466704810796,-1.6865535714442164
508.2000000000065,25.54754690575539,0.17467547890652035,-1.6885439170646763
509.4000000000065,25.585341315452837,0.14165880870987313,-1.691484680959297
510.6000000000065,25.62396203583542,0.11310342124263528,-1.6929636774108028
511.80000000000655,25.66217175802713,0.09385178192758825,-1.6944912789627669
513.0000000000066,25.7005965518524,0.0792234385574776,-1.6959707832005884
514.2000000000066,25.73935947503012,0.06740641999688313,-1.697477236574421
515.4000000000066,25.777586028966805,0.06246319443378667,-1.6987153767459802
516.6000000000066,25.81609235083331,0.06036753198059985,-1.700146197443242
517.8000000000067,25.854678325464562,0.058019813207075166,-1.6997822314240785
519.0000000000066,25.893574229475632,0.05505266285469079,-1.7018620285758743
520.2000000000066,25.93234296596835,0.05294922948290426,-1.7048559008205721
521.4000000000067,25.970791523206202,0.05174801518430128,-1.7050670562711092
522.6000000000067,26.009611481862827,0.05225140313928667,-1.7063732214075724
523.8000000000068,26.048446027592796,0.05028184412441106,-1.7079294905089446
525.0000000000067,26.087046865403394,0.052047518920940394,-1.7091007317584985
526.2000000000068,26.126013832613232,0.0553297828738708,-1.7092255281512982
527.4000000000068,26.16466825432185,0.054939765127969276,-1.7102582627469256
528.6000000000067,26.203237129271248,0.0605575906479634,-1.710824071002909
529.8000000000068,26.24247865546687,0.061531778188066544,-1.713159033386824
531.0000000000068,26.281292097245746,0.06422791050867782,-1.7144826659638208
532.2000000000069,26.319871240396782,0.06392404025737342,-1.71580136727024
533.4000000000069,26.358688530259784,0.06807301211741945,-1.716698111889571
534.6000000000068,26.397636225040237,0.07082750278638639,-1.7164303547167274
535.8000000000069,26.4366515869529,0.07277947528439488,-1.7171867934040113
537.0000000000069,26.475434933751284,0.07467276432410697,-1.7187682090974512
538.2000000000069,26.51450402428824,0.07643153104602662,-1.7200223671535566
539.4000000000069,26.553344903239815,0.07967096527533524,-1.7207979121015229
540.600000000007,26.592452606542103,0.08169223797129177,-1.7223976141358532
541.800000000007,26.631466387463995,0.08169579784395176,-1.7241786035638338
543.000000000007,26.670463288306014,0.08318185288294944,-1.7259379393382317
544.200000000007,26.70918902594876,0.0835427376668354,-1.7273581521729038
545.400000000007,26.74823125856413,0.08728353246674725,-1.7286894472182222
546.6000000000071,26.78703740784173,0.08861837957292162,-1.72867369511511
547.800000000007,26.826148426769457,0.08798606768709327,-1.730039840506227
549.000000000007,26.865230238632027,0.08783098818719082,-1.7314513422251823
550.2000000000071,26.904073789752378,0.08978367257081954,-1.7327255177985674
551.4000000000071,26.94306797257401,0.09097046932016217,-1.7327701016914285
552.6000000000072,26.982290355767002,0.08867477991102823,-1.7332397796616101
553.8000000000071,27.02124366380554,0.08854288249223785,-1.7366628397124866
555.0000000000072,27.060299413512066,0.08934677362492582,-1.7384414760973237
556.2000000000072,27.099247326876196,0.08704139008791512,-1.7397428563911235
557.4000000000071,27.138436237364814,0.08685787986076043,-1.7412494270584085
558.6000000000072,27.17768765424499,0.08471239504961048,-1.7412248680653715
559.8000000000072,27.21683045311436,0.0859143329124048,-1.742889829782618
561.0000000000073,27.255604449693262,0.08294374354128131,-1.7437051969016952
562.2000000000073,27.294519933574826,0.0821546327431556,-1.7453549860322664
563.4000000000073,27.33348896645238,0.08629067646640276,-1.7468833984553234
564.6000000000073,27.372789810790408,0.08602499801464436,-1.7483995045244547
565.8000000000073,27.41203525654587,0.08298987007091552,-1.7499481676312238
567.0000000000073,27.450967323656467,0.08212822429763444,-1.7519862983308792
568.2000000000073,27.49029443375492,0.08656176300613405,-1.753472549445842
569.4000000000074,27.52936991166371,0.08580856034828788,-1.7547991956027138
570.6000000000074,27.568405445671615,0.0870831773519124,-1.7561869149938558
571.8000000000075,27.607325329617804,0.09275353017504506,-1.757579163252891
573.0000000000074,27.646771644035546,0.09430604247599916,-1.7585768346761643
574.2000000000074,27.686074531027057,0.09314989439857602,-1.7591792842636127
575.4000000000075,27.72509889866062,0.09582525542961007,-1.7614633832135347
576.6000000000074,27.764396357321058,0.0977898063498871,-1.7633276193478324
577.8000000000075,27.803680713907887,0.10347552348117894,-1.7644649880225116
579.0000000000075,27.84282955796613,0.10279513325555556,-1.7658596653406167
580.2000000000075,27.882015503785468,0.1067808984522679,-1.7674225476285543
581.4000000000076,27.92162254475989,0.10670127711524346,-1.7699213835147507
582.6000000000075,27.960785022705377,0.11414366809431564,-1.7725784422847517
583.8000000000076,28.00009898914732,0.11404074976635337,-1.774116264102633
585.0000000000076,28.039174926438722,0.11850689015189197,-1.775995089771219
586.2000000000075,28.078914171214592,0.12236342565310354,-1.7786791564744537
587.4000000000076,28.118339467305102,0.12589810242289456,-1.7808375686910112
588.6000000000076,28.15743748374105,0.12953012635744998,-1.7836192191946547
589.8000000000077,28.196327197088845,0.13349973882461152,-1.784743627478698
591.0000000000077,28.236329485977198,0.13813004754755265,-1.788329230389297
592.2000000000077,28.27571412529674,0.1418343704401649,-1.7909631003409214
593.4000000000077,28.315177622565447,0.1523161638404742,-1.793558315743386
594.6000000000078,28.35448952280262,0.1600877643996671,-1.7956948229190686
595.8000000000077,28.393843654244975,0.16920390786875572,-1.7990068168775757
597.0000000000077,28.433464290058545,0.18304690279933244,-1.802111179827814
598.2000000000078,28.473183262807648,0.19537337535409405,-1.8057519056130378
599.4000000000078,28.512476082247577,0.20908254290233208,-1.8089979094953534
600.6000000000079,28.55198341765717,0.229360870752076,-1.8115825734413664
601.8000000000078,28.591621777488218,0.24800606923315738,-1.8153122146770575
603.0000000000078,28.63105741998047,0.26154533224450793,-1.8199674407187776
604.2000000000079,28.670779909611436,0.2777817343007398,-1.8254553799338633
605.4000000000078,28.710609426023304,0.29765145185673303,-1.8305349551718648
606.6000000000079,28.749933123231923,0.3124760199965968,-1.8362340756987838
607.8000000000079,28.78905397394913,0.32258568942342924,-1.8420077082348723
609.000000000008,28.829154927130677,0.3303534413128272,-1.8474030266633696
610.200000000008,28.86880082492371,0.336956089695159,-1.8546094647736315
611.4000000000079,28.908236309038447,0.34455513498823853,-1.860842335785275
612.600000000008,28.947468655269123,0.34784542472526425,-1.8676633963249412
613.800000000008,28.987582510926842,0.3541852482454009,-1.875082925680983
615.000000000008,29.027087487816285,0.35319984513381275,-1.8821222130788668
616.200000000008,29.066613719516674,0.35922087331687313,-1.8895364691477963
617.400000000008,29.105886889237304,0.3590225429584597,-1.8971757547761552
618.6000000000081,29.145590856323004,0.36034451041464255,-1.9063744559083982
619.8000000000081,29.185270485870813,0.3618574649738564,-1.9144164866158313
621.0000000000081,29.224416961933464,0.3611446109010874,-1.9240795119970238
622.2000000000081,29.264104989163084,0.3592037199108271,-1.9337530231052038
623.4000000000082,29.304180203415875,0.3584914343688048,-1.9431971678310704
624.6000000000081,29.343851916010266,0.3606631908224023,-1.9526774862547365
625.8000000000081,29.383343385521776,0.358878879583433,-1.962754044644234
627.0000000000082,29.422783854758084,0.35990027072993946,-1.9733429108520788
628.2000000000082,29.462592890091802,0.35786313713388185,-1.9830152145457807
629.4000000000083,29.50202813926105,0.3560625681463201,-1.9946271508310516
630.6000000000082,29.541879519961242,0.35690143035283395,-2.004713942476246
631.8000000000083,29.58148398948832,0.35799221197242437,-2.013130289785238
633.0000000000083,29.621152046482447,0.35880055587895887,-2.0227228531030144
634.2000000000082,29.660926490200065,0.3570800736977233,-2.032494756985269
635.4000000000083,29.700604263823493,0.35656278625445537,-2.040381685840259
636.6000000000083,29.740201693402575,0.3594079569762103,-2.049032419685032
637.8000000000084,29.779933493492635,0.3601421111086567,-2.055157982694724
639.0000000000084,29.819796122299877,0.3621440738977926,-2.058978337406702
640.2000000000083,29.85925723694908,0.36257291402005754,-2.0627742324814915
641.4000000000084,29.89889630951225,0.36239778107745635,-2.0662955020514
642.6000000000084,29.938754367918754,0.3542084996784596,-2.0679135249921194
643.8000000000084,29.978391177523264,0.34261344036155483,-2.0692102925154643
645.0000000000084,30.01783406044704,0.3313448651997033,-2.0707396652294596
646.2000000000085,30.05771836639729,0.324407547396123,-2.072428022743485
647.4000000000085,30.09735875826101,0.31924393874160195,-2.0733235566085257
648.6000000000085,30.13720056500928,0.32516277264654936,-2.0746122687385173
649.8000000000085,30.176998306571416,0.3340738023010732,-2.075926895662982
651.0000000000085,30.21710659880953,0.34747335756685516,-2.076287591273589
652.2000000000086,30.256718001694164,0.3684348267753108,-2.0773881618150254
653.4000000000085,30.29666868123935,0.37938643448709275,-2.0792281103872563
654.6000000000085,30.336616660472316,0.40022093046781526,-2.0809270111667475
655.8000000000086,30.37621203334627,0.4243582196150537,-2.082916288144243
657.0000000000086,30.41637344676044,0.4396997167565926,-2.0844154335555944
658.2000000000087,30.456308920109855,0.46711131321976174,-2.08582337773815
659.4000000000086,30.496470143862997,0.4960370359575894,-2.0873115007383225
660.6000000000087,30.536287613827056,0.5188287040978856,-2.089687226396313
661.8000000000087,30.5764605831249,0.5421748219821025,-2.0918913910828176
663.0000000000086,30.61645156929358,0.5680150883595174,-2.0934137163490436
664.2000000000087,30.656657545656575,0.5934998481847258,-2.095619832567659
665.4000000000087,30.696467393398393,0.6212164208713302,-2.098345416551139
666.6000000000088,30.736365850134195,0.6497044021672496,-2.099993179641086
667.8000000000088,30.776717495855433,0.6822650093178808,-2.1027623676236633
669.0000000000088,30.81673802549499,0.7105148933696668,-2.1048016236770466
670.2000000000088,30.856956197121516,0.7442741713619061,-2.1075619976559263
671.4000000000088,30.897477883578233,0.7779957875265964,-2.110007334793438
672.6000000000088,30.937647532883346,0.8146523473430192,-2.112878197589304
673.8000000000088,30.977657503189057,0.8508362984868385,-2.1150610819074798
675.0000000000089,31.01810511166873,0.8908900430424469,-2.117029435684087
676.2000000000089,31.058335690837367,0.9304911124929174,-2.120354387644622
677.400000000009,31.098559221551888,0.9764932740579264,-2.1234111257067605
678.6000000000089,31.138961648187294,1.0176269761595582,-2.1269657106394053
679.8000000000089,31.179043952289224,1.0682567241168126,-2.130478634457084
681.000000000009,31.21980461193951,1.1155326146957403,-2.134507130699119
682.2000000000089,31.25996575299026,1.1714877066113674,-2.1370464269013927
683.400000000009,31.30038303645285,1.2215409036501534,-2.140044600695795
684.600000000009,31.340831335647266,1.2758687095139836,-2.1443022988393987
685.800000000009,31.381046704467707,1.3381123156859571,-2.1491331667350675
687.0000000000091,31.421516501804692,1.3971792955360556,-2.1531884324518265
688.200000000009,31.46206908839568,1.453624612700154,-2.1590335488625145
689.4000000000091,31.502114456631823,1.5182224684208732,-2.1636103845171872
690.6000000000091,31.54329336588481,1.5762987922375387,-2.1667738610177834
691.800000000009,31.58374815010257,1.6393408964886595,-2.1705745813376938
693.0000000000091,31.624260100811004,1.7026811530401589,-2.1761004096407195
694.2000000000091,31.664811771466905,1.7693422546901683,-2.181104006484162
695.4000000000092,31.705488364016187,1.8359359765893635,-2.1866602134243154
696.6000000000092,31.746094234530215,1.9040629424477473,-2.1912743246486968
697.8000000000092,31.78651833718194,1.9700248747374427,-2.196963041440943
699.0000000000092,31.827534992032234,2.042323436945347,-2.2027592076280835
700.2000000000093,31.868124226573197,2.109993034358853,-2.2088206186689225
701.4000000000092,31.908725671451197,2.178878373467136,-2.2148690001646383
702.6000000000092,31.94942871717635,2.248692889485197,-2.223108281604567
703.8000000000093,31.99027364472296,2.323110181488225,-2.229761434718114
705.0000000000093,32.03073866599879,2.39425740179644,-2.2362681949792282
706.2000000000094,32.07141778282243,2.4652310720354675,-2.24403814847529
707.4000000000093,32.11214169678285,2.5389119027318916,-2.249443850839258
708.6000000000093,32.153206693610244,2.6113523714135853,-2.2568011936439665
709.8000000000094,32.193831735380826,2.688130343817579,-2.2645915448277094
711.0000000000093,32.2347753885667,2.7590988524634996,-2.272809636448141
712.2000000000094,32.275207235677065,2.8346624790704755,-2.2804139744853327
713.4000000000094,32.31535794938079,2.9058603666320444,-2.288437252385276
714.6000000000095,32.356712776465315,2.982913118409485,-2.297143505664293
715.8000000000095,32.39733805510997,3.056824254261761,-2.306537846424491
717.0000000000094,32.43832874474138,3.1348995168362452,-2.314992769195971
718.2000000000095,32.47911123992874,3.206797679615768,-2.323890902760784
719.4000000000095,32.51976497991126,3.2776710081313913,-2.333540778221356
720.6000000000095,32.56072190872241,3.357484225052278,-2.3425298624260167
721.8000000000095,32.60141778064261,3.4346261488322947,-2.350474146023224
723.0000000000095,32.64255679325694,3.513084071076583,-2.360857028472682
724.2000000000096,32.68345888362571,3.593446806271408,-2.3711354504987243
725.4000000000096,32.72408323030231,3.6762759950441115,-2.3810345549960688
726.6000000000096,32.765100473538695,3.761175286802592,-2.391841112050612
727.8000000000096,32.80571868075163,3.8495282573840326,-2.402087210794533
729.0000000000097,32.84737927486161,3.9476265727515845,-2.4122242081447904
730.2000000000096,32.88853390162596,4.048798838200831,-2.4236948853827847
731.4000000000096,32.92996616830591,4.153299669358647,-2.4342211001200793
732.6000000000097,32.971077074684125,4.260175942452295,-2.4457340862139105
733.8000000000097,33.012115743404806,4.371451287998762,-2.4560707028552025
735.0000000000098,33.05355585275007,4.488281816983896,-2.4679099976646253
736.2000000000097,33.094759189511656,4.602155397135351,-2.4804183082873257
737.4000000000098,33.13599830023795,4.717205182328163,-2.4927389097059525
738.6000000000098,33.17717094471218,4.82675180485465,-2.505962865146421
739.8000000000097,33.21815167029592,4.934619559063615,-2.5186418079510577
741.0000000000098,33.259262754944835,5.032398751114447,-2.5314028020131296
742.2000000000098,33.30044175119973,5.127817942243257,-2.5442341392979837
743.4000000000099,33.34133179320558,5.2083874456386,-2.557228391222269
744.6000000000099,33.3823943206379,5.276737344772606,-2.571006969953826
745.8000000000098,33.42325211034488,5.326281423063117,-2.5849664195535755
747.0000000000099,33.46407233724523,5.355720799721838,-2.598285287295501
748.2000000000099,33.50349420380373,5.365709378397368,-2.611736739043967
749.4000000000099,33.544258603353086,5.350836348363858,-2.6254530393611804
750.6000000000099,33.58371147565691,5.31440925630745,-2.63872335221017
751.80000000001,33.62443083085426,5.2471468380039346,-2.6524178212211087
753.00000000001,33.663832670055896,5.1356855259808105,-2.6652991551506715
754.20000000001,33.702709137575724,4.983542115086317,-2.676885265451876
755.40000000001,33.74149567051965,4.776306370228448,-2.6894216714057873
756.60000000001,33.779689533999715,4.493405751841346,-2.701343041632324
757.8000000000101,33.81694024400946,4.132761313187169,-2.7124331092820393
759.00000000001,33.85285467869382,3.6353941271911183,-2.7221916309762264
760.20000000001,33.88761475134934,2.8931294826691225,-2.7303845967247273
761.4000000000101,33.920722581686576,2.0265264393318545,-2.73673600436351
762.6000000000101,33.95462038012714,1.2583360926772222,-2.741994935186398
763.8000000000102,33.990392590021166,0.6957856368191533,-2.74276993660747
765.0000000000101,34.02756542769301,0.308437770267195,-2.745232332347713
766.2000000000102,34.06527213669512,0.05433861652299399,-2.7467303362166215
767.4000000000102,34.104173899853684,-0.11946833628912601,-2.746789237854059
768.6000000000101,34.143313803210305,-0.23177757812958388,-2.7474510308094766
769.8000000000102,34.182699833887014,-0.3092981605369518,-2.7482199976869057
771.0000000000102,34.22241173478467,-0.36033382732619756,-2.749419632901148
772.2000000000103,34.26253087846579,-0.4015406934186192,-2.74979641721718
773.4000000000103,34.302341631868025,-0.4258097222993875,-2.7491569927193487
774.6000000000103,34.34250858591446,-0.4478976845001823,-2.749420442812586
775.8000000000103,34.38258216254683,-0.4657776961710687,-2.74961694367751
777.0000000000103,34.42249965410882,-0.477918628915575,-2.750692257055329
778.2000000000103,34.46280043039634,-0.485906292623314,-2.752048206796916
779.4000000000103,34.50319631750227,-0.500005406433341,-2.7520502782711818
780.6000000000104,34.54336062073483,-0.503525807013907,-2.7520685690165596
781.8000000000104,34.583438373266496,-0.5074577861323326,-2.7533744342608744
783.0000000000105,34.624117528031185,-0.5129929148258099,-2.753364034985898
784.2000000000104,34.664065699921665,-0.5160003973417784,-2.754303884001148
785.4000000000104,34.70446247821131,-0.5165466710220261,-2.754059916442897
786.6000000000105,34.74415719018153,-0.5194956426399471,-2.7540270987407136
787.8000000000104,34.78483414168,-0.5274571176234408,-2.7550801259030164
789.0000000000105,34.82560749483357,-0.5267432606187537,-2.7553489265365716
790.2000000000105,34.86584339086942,-0.5280329437670392,-2.755349986487105
791.4000000000106,34.906599001348646,-0.5294404086593749,-2.7553904726620146
792.6000000000106,34.94739752543614,-0.5295420330964451,-2.756001810771279
793.8000000000105,34.98770402270436,-0.5321524072462906,-2.755999942065927
794.0000000000106,34.9942305079034,-0.5308396535050932,-2.755999872843199