File: 01_Data/Corrugated_Cardboard/STA/N2/3K_min/Corrugated_Cardboard_STA_N2_3KData_230921_R1.csv
##Temp./Â°C,Time/min,DSC/(mW/mg),Mass loss/mg
28.0,15.704136158263083,0.03193549979995858,-0.036230119699045105
29.200000000000017,16.612036264950593,0.07299793072601712,-0.039455838505459084
30.400000000000034,17.166817217949998,0.0880160372336456,-0.04095065485173022
31.60000000000005,17.673564452252997,0.0954431657785757,-0.04295306914943087
32.80000000000007,18.149692224562358,0.10263749471313455,-0.04423085775496238
34.000000000000085,18.613960124198503,0.10870838971335317,-0.0436163480377294
35.2000000000001,19.050290064700025,0.11908114431440397,-0.04524665956498897
36.40000000000012,19.4933336067844,0.124602554858257,-0.04590055034291396
37.600000000000136,19.924461209571085,0.13010069688804737,-0.04757978627530557
38.80000000000015,20.35019397365029,0.13607321310671816,-0.04786764544692135
40.00000000000017,20.77798387437482,0.13898607723872125,-0.0492002114393566
41.20000000000019,21.194894379139733,0.14348935289078302,-0.05119701946891775
42.400000000000205,21.609787395094763,0.14863199958217654,-0.05314047402015332
43.60000000000022,22.019316582132262,0.15315619433299688,-0.055769905483113114
44.80000000000024,22.426913585336234,0.15775776067116576,-0.0557716396422725
46.000000000000256,22.830887401015094,0.161261613636404,-0.05808016069237043
47.20000000000027,23.24817008016738,0.16494843540597293,-0.06005013240868262
48.40000000000029,23.6560934149033,0.16859035141138,-0.06302010527531943
49.60000000000031,24.062202527575465,0.16949494692638378,-0.06393062042310982
50.800000000000324,24.45842369097289,0.17273431012477314,-0.06729997431813883
52.00000000000034,24.876169266692624,0.17565061335359688,-0.0699661302401422
53.20000000000036,25.275093909479963,0.17616097246070428,-0.0715798607376179
54.400000000000375,25.68348676662501,0.1793185225768652,-0.07288536690906877
55.60000000000039,26.089149243650624,0.1797199164230623,-0.07563974585869637
56.80000000000041,26.487343414926695,0.18179018964973048,-0.07718013903076804
58.000000000000426,26.89452109544044,0.18216793786598373,-0.07981583836291328
59.20000000000044,27.293239542105383,0.1815557069437106,-0.08019918523078795
60.40000000000046,27.693188666019573,0.18173438116903995,-0.08383085261302714
61.60000000000048,28.097898677147246,0.1817898454620659,-0.08639999769931972
62.800000000000495,28.50181453391521,0.18194525398158934,-0.08772256776888954
64.00000000000051,28.90034807477399,0.18044745084167335,-0.09003012793769694
65.20000000000053,29.2867645598063,0.17729839874937703,-0.09233016662966831
66.40000000000055,29.697653156341097,0.17662832973769227,-0.09422775256811278
67.60000000000056,30.099938064109406,0.17422897355004485,-0.09731879697030177
68.80000000000058,30.487877056398606,0.17326302781688296,-0.09858971568819852
70.0000000000006,30.90160462571133,0.17084191148498507,-0.10043371483474495
71.20000000000061,31.29016693829329,0.16769099729884118,-0.1032000724136295
72.40000000000063,31.697404805824217,0.16483249157508384,-0.10320439646999091
73.60000000000065,32.09062421726732,0.16013006998681734,-0.10616953899398363
74.80000000000067,32.49031594349691,0.15698616006264166,-0.10715470838409935
76.00000000000068,32.881859461887764,0.15537874436226407,-0.10878911064205532
77.2000000000007,33.282849822086156,0.15323295977143392,-0.10990991322762955
78.40000000000072,33.67891018288649,0.15266343411491068,-0.11208998824134664
79.60000000000073,34.07746907224409,0.15013628560744685,-0.11241991700007326
80.80000000000075,34.47426427805301,0.14902981393705472,-0.11372991695613566
82.00000000000077,34.87434715906171,0.14564728689829876,-0.11549490559727893
83.20000000000078,35.28226010913243,0.14240124781479446,-0.11746983599999616
84.4000000000008,35.67851030022821,0.13700113993059615,-0.11747434298304604
85.60000000000082,36.07487016564082,0.136280373801414,-0.1179915316472564
86.80000000000084,36.473178073287094,0.13284599362891747,-0.11823933328876324
88.00000000000085,36.85782363662644,0.13123482157143673,-0.11955006375850719
89.20000000000087,37.25744863763227,0.1302289463996158,-0.12025347629247918
90.40000000000089,37.65176540833749,0.1296741011174869,-0.12121009700415275
91.6000000000009,38.05307155011839,0.12540881513726365,-0.1203853546588487
92.80000000000092,38.431719279863145,0.1260427271343567,-0.12219051765516697
94.00000000000094,38.84127224495133,0.126083240947803,-0.12218983299994113
95.20000000000095,39.234632972086374,0.12202678002785161,-0.1214468071370507
96.40000000000097,39.62876794139604,0.11912060653911283,-0.12151306646650095
97.60000000000099,40.01401496034996,0.11714832336771153,-0.12284996593406117
98.800000000001,40.41667322094043,0.1171902098517621,-0.12332311387313899
100.00000000000102,40.80315751313772,0.11898961152957632,-0.12384033788958737
101.20000000000104,41.207402512409836,0.11809718828328908,-0.1238401049955753
102.40000000000106,41.604956928580435,0.11499892957298519,-0.12516010500000174
103.60000000000107,41.99874870557604,0.11670194623277119,-0.12515654503015572
104.80000000000109,42.39746114883343,0.11642007760797579,-0.12614747603004428
106.00000000000111,42.78958075165754,0.11754535615950923,-0.12447800530163455
107.20000000000113,43.18476426729163,0.11813371042426235,-0.12646992200882545
108.40000000000114,43.57569511741039,0.11673573991321895,-0.12548002763930022
109.60000000000116,43.97585849041622,0.11891409891777371,-0.12672157066366063
110.80000000000118,44.364435980391505,0.11655891864064527,-0.12746017523023578
112.0000000000012,44.75551368027543,0.11428072024282754,-0.12746001621789338
113.20000000000121,45.14917000000054,0.11458652880165232,-0.12779011299999965
114.40000000000123,45.545571728423404,0.11572815940321712,-0.1277782879875713
115.60000000000124,45.93318768209171,0.11827708899296319,-0.1284494808552945
116.80000000000126,46.32279377491167,0.1189170440802525,-0.128230605085502
118.00000000000128,46.721497615235776,0.1147096430057628,-0.12789997281796506
119.2000000000013,47.114782000084055,0.11793959362963635,-0.12823109065916372
120.40000000000131,47.50999836490644,0.11507259337222386,-0.12692019169131497
121.60000000000133,47.91099175055918,0.11507647464533033,-0.12889025237184315
122.80000000000135,48.30316987195509,0.1176308398082786,-0.12863408181195002
124.00000000000136,48.697557256373955,0.12014461553074796,-0.12885432472209057
125.20000000000138,49.08867645219557,0.11752136023986859,-0.1288901722740623
126.4000000000014,49.48087350360787,0.11999685153817108,-0.12921985699649507
127.60000000000142,49.875376824001165,0.12042006278652106,-0.1311889941508606
128.80000000000143,50.26629115668065,0.12060228074034818,-0.12986991100004053
130.00000000000145,50.656798957573955,0.12115506345537863,-0.1295303569260864
131.20000000000147,51.051102446528404,0.12199499531727076,-0.12855004196745767
132.40000000000148,51.442310555765694,0.12173586868854214,-0.12928258581307484
133.6000000000015,51.83654680190495,0.12080423230359072,-0.12789959343552848
134.80000000000152,52.225998609264835,0.12347137513997675,-0.12977268466224157
136.00000000000153,52.614972081450915,0.12216991659765508,-0.1295506552095711
137.20000000000155,53.00702956307297,0.12355970834427099,-0.1309317801303269
138.40000000000157,53.39981978758292,0.12621096722445202,-0.12987135905994363
139.6000000000016,53.79135018197554,0.12511971194146376,-0.1295498110000124
140.8000000000016,54.184240941004674,0.12150930683330508,-0.12954981099999063
142.00000000000162,54.56857303933185,0.1278638623228181,-0.1295498639967403
143.20000000000164,54.96361511934733,0.12420429317332271,-0.12982232522658066
144.40000000000165,55.34364705476358,0.12353879166897519,-0.13020011952425348
145.60000000000167,55.73335504103619,0.12710833088221118,-0.1315230714017166
146.8000000000017,56.13975685551349,0.1295595245256469,-0.13152034310807492
148.0000000000017,56.52572700242137,0.12975731598041484,-0.13086727090382722
149.20000000000172,56.92547495036727,0.1311739072743574,-0.1309099559193232
150.40000000000174,57.314647817240726,0.13099172025260808,-0.13087011000018078
151.60000000000176,57.70235939222989,0.13199262602501927,-0.13087010999822413
152.80000000000177,58.097972019483414,0.13171863725106547,-0.13155692963709065
154.0000000000018,58.48786812366109,0.13358203899782284,-0.13119812283204846
155.2000000000018,58.8772534769467,0.1341931925332247,-0.1325101639999997
156.40000000000182,59.26777412675969,0.13406890832667928,-0.13185164370148383
157.60000000000184,59.65346249540179,0.13412849763337942,-0.13286633669237524
158.80000000000186,60.04239970132096,0.1352107036519592,-0.1332725965646291
160.00000000000188,60.432469205035,0.13483837726440306,-0.13295155540432813
161.2000000000019,60.81990432431284,0.13506006446986873,-0.13360981878170008
162.4000000000019,61.16068816981606,0.1348720648522308,-0.132614434987949
163.60000000000193,61.6003655330766,0.14096048633751446,-0.13360989981469062
164.80000000000194,61.9899014719992,0.13818036959424784,-0.13328018295984645
166.00000000000196,62.37871536903154,0.14027939527837896,-0.13327992699999847
167.20000000000198,62.765960162075714,0.13974409790464204,-0.1339399270627588
168.400000000002,63.15436234273856,0.14191941598210267,-0.1339391651580648
169.600000000002,63.54157721749889,0.14185034062735102,-0.1336099539999993
170.80000000000203,63.93014417559943,0.1420457705589766,-0.13491980784064772
172.00000000000205,64.31836054373399,0.14441248262569673,-0.1342570232230873
173.20000000000206,64.70873838416829,0.1436422951128833,-0.13458576602134764
174.40000000000208,65.09866537618356,0.14538856617139784,-0.13491995409918545
175.6000000000021,65.48779612296968,0.14662987073634115,-0.13493307473214955
176.80000000000211,65.88137741459003,0.14826640939009694,-0.13458691268530876
178.00000000000213,66.26917000000088,0.14594971943133128,-0.13590995399957073
179.20000000000215,66.65916862846441,0.14930173508638145,-0.1355799547178469
180.40000000000217,67.04869760171164,0.1466292992251459,-0.13689808092393996
181.60000000000218,67.44737030175074,0.14685375768048337,-0.13656986197098364
182.8000000000022,67.83360195797216,0.14846238003101098,-0.13523305227477556
184.00000000000222,68.22570186497632,0.15231565659403046,-0.13656994186249616
185.20000000000223,68.60869134940248,0.14929168756376066,-0.13623928897671833
186.40000000000225,68.99712069754658,0.1502323142426003,-0.13821990616482793
187.60000000000227,69.38293488824661,0.14962400777085305,-0.13821992752467605
188.80000000000229,69.77098849891286,0.15162303100538943,-0.13689986599378434
190.0000000000023,70.15943084914743,0.15170405079464389,-0.13821985540251713
191.20000000000232,70.54990354863338,0.15054443533828632,-0.13821998036972216
192.40000000000234,70.93782513947517,0.15311790541949644,-0.13756137986093542
193.60000000000235,71.32448492919552,0.15328378379859076,-0.13855177379524797
194.80000000000237,71.71786901283477,0.15176596225619265,-0.13822702255754615
196.0000000000024,72.10237104176105,0.15476875298463377,-0.13953981907453983
197.2000000000024,72.49114745130532,0.15460951315355742,-0.1408606633066345
198.40000000000242,72.87853933608089,0.15580238721439832,-0.1385498342325926
199.60000000000244,73.26680087478184,0.1546274158373746,-0.1408617742381124
200.80000000000246,73.65071141343786,0.15650211655012547,-0.14086007058790795
202.00000000000247,74.04147572977679,0.15628051409848465,-0.1405294450815564
203.2000000000025,74.42666974725634,0.15520281256963986,-0.14218503203811084
204.4000000000025,74.82100635450692,0.1530515520301392,-0.14348994599873022
205.60000000000252,75.20944261129375,0.15298414113978853,-0.14348994599948295
206.80000000000254,75.60135225222557,0.15401556757941726,-0.14480983800001646
208.00000000000256,75.98917000000098,0.15278428054119275,-0.1441498920962534
209.20000000000258,76.38061618783887,0.15711952426810005,-0.14683779401679953
210.4000000000026,76.76820887691066,0.15586747279667534,-0.1443640349217774
211.6000000000026,77.15020432763066,0.15857816252926105,-0.1467903953073697
212.80000000000263,77.54640508328515,0.15754868702070768,-0.14745868354061908
214.00000000000264,77.9344285972908,0.15582361298516645,-0.1467718086614882
215.20000000000266,78.31917000000084,0.15730656546001986,-0.14875991098765606
216.40000000000268,78.70433756078984,0.1558543205899452,-0.15007892769040865
217.6000000000027,79.09548207133534,0.15478960648659412,-0.15044462360624022
218.8000000000027,79.48369089496335,0.15921209263635738,-0.15139002099263132
220.00000000000273,79.87210746977388,0.15905886575867711,-0.15369992179392966
221.20000000000275,80.26427267105969,0.1593684463098961,-0.15435982183173724
222.40000000000276,80.65272164550306,0.15765983069736,-0.15503719072075395
223.60000000000278,81.04068369274296,0.15799121863641452,-0.15633003134708456
224.8000000000028,81.429458750227,0.1571838788612967,-0.15897024058294384
226.0000000000028,81.81711887727849,0.15828881266256745,-0.16095010735560988
227.20000000000283,82.20666480856788,0.15625990516374033,-0.16490352308334844
228.40000000000285,82.59224889872866,0.15700224037937138,-0.1655604010089209
229.60000000000286,82.98011949265998,0.1550234806993429,-0.16589012805296788
230.80000000000288,83.36645961225881,0.15578167257475473,-0.1678192626620265
232.0000000000029,83.7531775792189,0.15585352079109316,-0.17149016914001525
233.20000000000292,84.14125179345254,0.1565088980406788,-0.17312945617291842
234.40000000000293,84.52836593791217,0.1541475286294125,-0.17576981632507316
235.60000000000295,84.91270319485548,0.15672052532983471,-0.1796981259358592
236.80000000000297,85.30515918889446,0.15653292928250218,-0.18133888499369322
238.00000000000298,85.69202616254215,0.15513751594762226,-0.18533932306134693
239.200000000003,86.08343924488568,0.1543560225915519,-0.18663011694086862
240.40000000000302,86.47090889269441,0.15459593948980754,-0.191549253729967
241.60000000000304,86.86410680316168,0.1522274368049128,-0.19583804988947673
242.80000000000305,87.25092340864533,0.1542676451878393,-0.1983741380737114
244.00000000000307,87.64434912614858,0.1560063448585316,-0.20201117300289484
245.2000000000031,88.0287610844677,0.15448030158541348,-0.20529944281240686
246.4000000000031,88.41484381262978,0.15511343193165805,-0.21056981692924426
247.60000000000312,88.80237969354489,0.15509607907988965,-0.21645283894648948
248.80000000000314,89.1856732878027,0.15301827102638965,-0.2211042240835286
250.00000000000315,89.57754635148375,0.15190225576827765,-0.22730703986402467
251.20000000000317,89.9657023967371,0.1523400294075874,-0.23103980067625018
252.4000000000032,90.35734335362761,0.15241832202414907,-0.23614997502360247
253.6000000000032,90.7453181541057,0.14957039680809547,-0.24232829880469442
254.80000000000322,91.12805231375646,0.15310201139187174,-0.2494295361418608
256.00000000000324,91.52407497848749,0.1528999383094678,-0.25601098372129805
257.20000000000323,91.91081798944614,0.1512533143688719,-0.2622678790218873
258.4000000000033,92.30283960140395,0.15268127394982,-0.2715168634332237
259.6000000000033,92.6921570505688,0.1524964796507926,-0.27828789979835244
260.8000000000033,93.07790536212369,0.15599883571105133,-0.28577436472583795
262.0000000000033,93.46518401928216,0.15314836491118822,-0.2961408987580505
263.20000000000334,93.85084076541176,0.15554064152811953,-0.3041394979186003
264.4000000000034,94.24242237171029,0.15395589147374356,-0.3139018269497189
265.6000000000034,94.62129264148263,0.15483251646690133,-0.3209309705872738
266.80000000000337,95.0827929212454,0.15126222040120396,-0.3323673007354202
268.0000000000034,95.41149287990058,0.1566091498968385,-0.3444026247278704
269.20000000000346,95.797265948305,0.15610708622312885,-0.35595513666419
270.40000000000344,96.18261826787901,0.15681294843167848,-0.36779014269950583
271.60000000000343,96.57609682654989,0.159021757869368,-0.3786384708216377
272.8000000000035,96.9640192232861,0.16080587409188318,-0.39207214526560286
274.0000000000035,97.34974407295292,0.16135723254365542,-0.40468772299720746
275.2000000000035,97.72188740790745,0.1613807448521245,-0.4148472591109962
276.4000000000035,98.13722651164254,0.16182744993347797,-0.43119433763501913
277.60000000000355,98.52910371780719,0.1604073512338262,-0.44705624159851
278.8000000000036,98.91773859512072,0.16354827241768533,-0.46368884526022347
280.0000000000036,99.3069974482896,0.16432285621406728,-0.48008799759330456
281.20000000000357,99.69401893384406,0.16761288536099062,-0.49609419683576306
282.4000000000036,100.08694913184458,0.1646075750413456,-0.5143115810670071
283.60000000000366,100.47399299917745,0.16703579065702456,-0.531598445453858
284.80000000000365,100.86753772376822,0.17386081190061664,-0.5511443417864168
286.00000000000364,101.259170000001,0.17228267205783654,-0.5703298175828859
287.2000000000037,101.65096040565601,0.1720811017829218,-0.5898337536056117
288.40000000000373,102.04204854051044,0.17356277940838094,-0.6103208573289725
289.6000000000037,102.42881400846998,0.17541658273418426,-0.6293574938983406
290.8000000000037,102.81843652809196,0.17488678360076748,-0.6525698358075953
292.00000000000375,103.20770261229188,0.17570150628917314,-0.6748017461189915
293.2000000000038,103.59382071028459,0.1804909731336901,-0.6979637325965413
294.4000000000038,103.98759522917017,0.18006443884702916,-0.722294319603495
295.6000000000038,104.383418310624,0.18224751164823672,-0.748442728604386
296.8000000000038,104.77589839844018,0.18489241373500476,-0.7730062359966698
298.00000000000387,105.16878144447023,0.18259842667125592,-0.8007424644475352
299.20000000000385,105.55971303085487,0.18800112265601054,-0.8283184589162844
300.40000000000384,105.95143480680613,0.18986488066252405,-0.8550127433897714
301.6000000000039,106.34302409378101,0.1909640120671119,-0.8849725240779018
302.80000000000393,106.72982448727137,0.193845973288717,-0.9135014877433445
304.0000000000039,107.12347857460847,0.195708349615483,-0.9490966006322292
305.2000000000039,107.51582981447879,0.1962893933360328,-0.9789500394683048
306.40000000000396,107.90723282486611,0.2007375230897861,-1.0127107153390091
307.600000000004,108.29205614721982,0.19963604233301413,-1.0477927980784192
308.800000000004,108.68665562531937,0.2032472972246182,-1.0760692303770054
310.000000000004,109.07698325420806,0.20769760218028366,-1.115382709542636
311.200000000004,109.46567971789122,0.20881428365514676,-1.1569410594567344
312.40000000000407,109.86015223879747,0.21264538017732493,-1.1945351289674915
313.60000000000406,110.25351344328567,0.2150360371378799,-1.2356903613355419
314.80000000000405,110.64381173187611,0.21712343420002966,-1.2774374622240683
316.0000000000041,111.03102473017258,0.22246891658763568,-1.3190818991107434
317.20000000000414,111.42197872775901,0.22488124430625356,-1.3623696085803658
318.4000000000041,111.80962913693416,0.2308802847664606,-1.408771746926286
319.6000000000041,112.20021682724912,0.23286345750704252,-1.4550445909633005
320.80000000000416,112.59620288004308,0.23704280151727408,-1.5039369106567784
322.0000000000042,112.99181168995541,0.2407989598190421,-1.5535796822101129
323.2000000000042,113.38550080548839,0.23872886663515636,-1.604667425854219
324.4000000000042,113.77403815975264,0.24228013189720343,-1.6563634877633189
325.60000000000423,114.16373624826926,0.24444891667077884,-1.7079358882641058
326.8000000000043,114.55927990860602,0.24533586836204813,-1.7630299814715853
328.00000000000426,114.9488131911188,0.2468843005283401,-1.8188518694010973
329.20000000000425,115.34028974301816,0.2472584090038379,-1.8750054751544063
330.4000000000043,115.73200220022935,0.24776010486885536,-1.9309913311424904
331.60000000000434,116.12238498816498,0.24622552793955244,-1.9877611343889319
332.80000000000433,116.50764149728987,0.24250606314962297,-2.0442459813258447
334.0000000000043,116.90068802551367,0.23822037659215756,-2.100678957025598
335.20000000000437,117.28940686687112,0.23219080050870655,-2.1552857807636085
336.4000000000044,117.68321289287384,0.22717052537210147,-2.209950749759125
337.6000000000044,118.06914397103752,0.21677533436992968,-2.26044766436348
338.8000000000044,118.46817888275336,0.2066745701483561,-2.3118889067486377
340.00000000000443,118.85866021180911,0.19485209732026298,-2.3588647210400264
341.2000000000045,119.25001207895339,0.17968776931405062,-2.4045427285559517
342.40000000000447,119.63812275399135,0.1706992702109762,-2.442531350581526
343.60000000000446,120.02607681108658,0.15700749299364203,-2.4789829608658795
344.8000000000045,120.41575570282026,0.14663429795205518,-2.513024288011683
346.00000000000455,120.8102272364251,0.13634230228618271,-2.5424546849470717
347.20000000000454,121.20515340617007,0.12609458163498655,-2.5687135580773752
348.4000000000045,121.59675057282494,0.1167252445936291,-2.5952554882520213
349.60000000000457,121.98972191105003,0.10630266646967179,-2.615521616576292
350.8000000000046,122.38524163359341,0.09781568341530944,-2.634467264695674
352.0000000000046,122.77572268928013,0.08879945393997346,-2.651290817325357
353.2000000000046,123.16570138436131,0.08146184550572855,-2.6661153841049297
354.40000000000464,123.5560724551166,0.07164997222120562,-2.6785229998640467
355.6000000000047,123.95046287186463,0.06836163684814567,-2.6905696176659157
356.8000000000047,124.33953054563803,0.06260874034773112,-2.6986076857962384
358.00000000000466,124.7291700000012,0.056808555777891456,-2.709344833368914
359.2000000000047,125.12402872550258,0.04979190909115738,-2.7150875792182
360.40000000000475,125.51354710664489,0.04707579047463373,-2.722590537431672
361.60000000000474,125.9073141029938,0.04369908862795935,-2.728012519561812
362.80000000000473,126.30312419916818,0.045019755686678486,-2.736364643195902
364.0000000000048,126.70196711898679,0.042227990286500816,-2.741194193249081
365.2000000000048,127.09229321849362,0.040361925000772736,-2.7437986446235207
366.4000000000048,127.48957997410685,0.039203107711852425,-2.750409968635913
367.6000000000048,127.87941110926074,0.03704521779093772,-2.7540317500524
368.80000000000484,128.27164809959186,0.035143669002419387,-2.758056039346764
370.0000000000049,128.666774701399,0.033976515870232316,-2.7619320095629654
371.2000000000049,129.05851066249136,0.033425501286008075,-2.7665500572593595
372.40000000000487,129.44800620312813,0.030619033341151347,-2.770446289116168
373.6000000000049,129.83947757278762,0.031421167813610484,-2.7754537874484084
374.80000000000496,130.2317269535835,0.03034618036658454,-2.780612680547184
376.00000000000495,130.6265794658063,0.02677373581976461,-2.784660087759188
377.20000000000493,131.02161644231927,0.028461715624356287,-2.7897030277314174
378.400000000005,131.41840071231547,0.02738218375852952,-2.7928494615452357
379.600000000005,131.8144835587964,0.027444609860336477,-2.79781895757142
380.800000000005,132.2080253035696,0.025926974948130788,-2.800482948041368
382.000000000005,132.61255657660266,0.025651713033633783,-2.804643984301128
383.20000000000505,132.99305833861973,0.02259526039358306,-2.810015340575042
384.4000000000051,133.3833770744336,0.02187709915660152,-2.8148158788006654
385.6000000000051,133.78479699525823,0.022177934446288905,-2.8175833516078983
386.80000000000507,134.17949370007224,0.020794354815611982,-2.8241798010423382
388.0000000000051,134.57188515994744,0.02024322658497013,-2.8255158091529697
389.20000000000516,134.96316129596536,0.019613418757835177,-2.829770497398412
390.40000000000515,135.3574776831293,0.021403100763995653,-2.8327888512540884
391.60000000000514,135.7530656862656,0.02222150388739319,-2.835320813950466
392.8000000000052,136.14413275241344,0.01776481146944242,-2.8393299375925887
394.00000000000523,136.54167097796113,0.022477286904696747,-2.843486327593178
395.2000000000052,136.93323876691227,0.019512527494812026,-2.8482199641473613
396.4000000000052,137.33837730344,0.020925277914884965,-2.852170013575276
397.60000000000525,137.7333245052341,0.017160075913916994,-2.855769273947118
398.8000000000053,138.13036044551885,0.01734834012290465,-2.8574365559456925
400.0000000000053,138.52474399243832,0.016693778326680064,-2.8620466286536503
401.2000000000053,138.9170424622682,0.014878920415823949,-2.8640298709784036
402.4000000000053,139.31309302352952,0.017704486457379875,-2.8666781559318473
403.60000000000537,139.70490708866313,0.01798736927108946,-2.8700950453603618
404.80000000000535,140.0989867447832,0.018370711514888338,-2.874239911924543
406.00000000000534,140.49624327362105,0.020784347452473373,-2.876877971228048
407.2000000000054,140.88786909737266,0.019525277058169976,-2.8818113835666406
408.40000000000543,141.2814317145739,0.017749406730592554,-2.884775892271663
409.6000000000054,141.68064405494917,0.020854342445515872,-2.8861533012526346
410.8000000000054,142.07525667746,0.02254313283767173,-2.888813434977525
412.00000000000546,142.4703359965348,0.02263525451478987,-2.893789477430694
413.2000000000055,142.8634749538563,0.022760546867342413,-2.896295252592723
414.4000000000055,143.26418055226202,0.0227289792190275,-2.899930605233627
415.6000000000055,143.6584526943369,0.02249733916960217,-2.903875863825101
416.8000000000055,144.0620486151771,0.025427161478656313,-2.90649478837068
418.00000000000557,144.4570951274557,0.02704335854755957,-2.9078296213558534
419.20000000000556,144.85321753149867,0.026259011517550057,-2.9117920091216245
420.40000000000555,145.25049386198717,0.024224044202887374,-2.9157391286343572
421.6000000000056,145.64030774738774,0.024726632842793084,-2.9170498103265805
422.80000000000564,146.01991758220944,0.031007973271616862,-2.9196899008116874
424.0000000000056,146.43917000000164,0.03186813978172509,-2.922230592145563
425.2000000000056,146.83549463628023,0.03276883400273922,-2.9249599910001196
426.40000000000566,147.2273738371507,0.03238642050406959,-2.9275901820044474
427.6000000000057,147.62371237250275,0.03382717833131865,-2.930229983040492
428.8000000000057,148.02196976152584,0.032868230247718344,-2.933850145519422
430.0000000000057,148.41387683484027,0.03675348568459835,-2.934838563725542
431.20000000000573,148.81021343320202,0.037377153823613174,-2.9364798772856595
432.4000000000058,149.2038892629324,0.04175122558706468,-2.9388159869446957
433.60000000000576,149.6043324733951,0.04287974694543939,-2.93912528872713
434.80000000000575,150.0025892951334,0.04692672434071277,-2.9420899612722398
436.0000000000058,150.40177978480278,0.05175338886423875,-2.944729932255445
437.20000000000584,150.801335061383,0.051846485031028955,-2.9464399295727217
438.40000000000583,151.2015002759651,0.052604427886224325,-2.9479837967840963
439.6000000000058,151.59506726520496,0.054902634152400154,-2.9506498653751647
440.80000000000587,151.98709368571338,0.05773991207835083,-2.952960051845839
442.0000000000059,152.38271631678063,0.061170746771913365,-2.9546099453857493
443.2000000000059,152.78402681054212,0.0597078277741101,-2.9585601326244433
444.4000000000059,153.17788254640783,0.06251026831717654,-2.9598799288715574
445.60000000000593,153.58063764113493,0.06271592574466878,-2.9605298506492135
446.800000000006,153.9788176688685,0.06165406263577422,-2.9618179321351223
448.00000000000597,154.38009811634453,0.06313862411549476,-2.9638228836361304
449.20000000000596,154.77916653096327,0.06352720965574354,-2.964479899838655
450.400000000006,155.17804876083335,0.06608161665852119,-2.9671200810082095
451.60000000000605,155.57706957198081,0.06732536074137174,-2.969750140664093
452.80000000000604,155.97291691132685,0.06842347722968611,-2.9713977381653507
454.000000000006,156.37372177210702,0.06694641077932895,-2.9749906526250802
455.20000000000607,156.7758653242902,0.06810336280831253,-2.974366586727845
456.4000000000061,157.16939951395895,0.06567620847027422,-2.978320118193712
457.6000000000061,157.5676018628199,0.06625333491070018,-2.9783652891459007
458.8000000000061,157.96480997665196,0.06510602924107456,-2.9796331759420935
460.00000000000614,158.36206035891348,0.06653522729282368,-2.981270069112905
461.2000000000062,158.7591668230141,0.06460956440563459,-2.9826000029999964
462.4000000000062,159.16019755577867,0.06508172027667802,-2.9829871583427585
463.60000000000616,159.55567385011346,0.06353699831204374,-2.9861102552694594
464.8000000000062,159.95313160087898,0.06683939540476747,-2.987669910692892
466.00000000000625,160.35150623908635,0.061965447530214934,-2.9895087020717312
467.20000000000624,160.75280716991784,0.05816152767449356,-2.9928104180321062
468.40000000000623,161.149598709162,0.055998731237046684,-2.9924829746797013
469.6000000000063,161.55404549807628,0.054240926774444365,-2.9937903764642
470.8000000000063,161.9529439799713,0.04983608052227906,-2.9931315156991576
472.0000000000063,162.35759366314005,0.05580444392917894,-2.994460102180524
473.2000000000063,162.7580841620516,0.05097894225180166,-2.9984008755102196
474.40000000000634,163.15549870402785,0.048154735538423754,-2.999389815011793
475.6000000000064,163.55631314297094,0.04629672283775044,-2.999391294388183
476.8000000000064,163.9529892808608,0.04362105873189215,-3.0010491329458064
478.00000000000637,164.35326693826414,0.040758448911049516,-3.0036558141223586
479.2000000000064,164.75159587071371,0.04216455310369405,-3.0037828973027887
480.40000000000646,165.15034755631478,0.04133509018388226,-3.006319969212792
481.60000000000645,165.55136565234884,0.04260362864908096,-3.006309844569749
482.80000000000643,165.9550625090942,0.03787928378643368,-3.0089496553246278
484.0000000000065,166.349808864753,0.035368794501251966,-3.0079597004220364
485.2000000000065,166.75359314109238,0.029473971665692655,-3.0087397617531098
486.4000000000065,167.152934697371,0.0324954441184655,-3.0120195632216173
487.6000000000065,167.54782565830405,0.02756953191898326,-3.0119102048615205
488.80000000000655,167.949596083916,0.025752431412631616,-3.0143301507701667
490.0000000000066,168.352651969671,0.025488920767145373,-3.014978521638801
491.2000000000066,168.7566104028677,0.02520117078009454,-3.0169598909909774
492.40000000000657,169.16189760632966,0.02171731410438804,-3.0180774744872467
493.6000000000066,169.55826301509794,0.019450394266412374,-3.0182799162596887
494.80000000000666,169.95183820553075,0.013160544892364179,-3.020260028655839
496.00000000000665,170.3600272068137,0.010665966621035139,-3.0214380848683167
497.20000000000664,170.75916689541987,0.00956098725982013,-3.0202131216117873
498.4000000000067,171.1631991777634,0.010078854494782075,-3.0213496322450113
499.60000000000673,171.56397047318612,0.007801048958536505,-3.0239897426340576
500.8000000000067,171.9666357264783,0.006860450661986928,-3.0239702484799933
502.0000000000067,172.3682296279259,0.005988467352367355,-3.0266200508746777
503.20000000000675,172.77309201795478,0.00571070841411192,-3.0266198749999997
504.4000000000068,173.17159969835478,0.008524694935506894,-3.0269501659997466
505.6000000000068,173.56674377767263,0.004702282024736437,-3.026291132909359
506.8000000000068,173.96826224093613,0.0053931763504233565,-3.0317172012332656
508.0000000000068,174.36779545164111,0.004572513721555094,-3.0321098404975744
509.20000000000687,174.76770913212195,0.006669708687594866,-3.032110131000432
510.40000000000686,175.1664253891938,0.003188726660330765,-3.034410075000438
511.60000000000684,175.57238213666596,0.005631198645580149,-3.0350598384958007
512.8000000000069,175.97058579447912,0.005087948157640909,-3.0340808691926364
514.0000000000069,176.37553016276766,0.006277092574868082,-3.038039635427325
515.2000000000069,176.7779949715496,0.005808726978760781,-3.0393606229367296
516.4000000000069,177.17674946941813,0.007559196439089977,-3.0390301234072075
517.600000000007,177.5765173665702,0.008693978180108086,-3.0406827916041097
518.800000000007,177.98136236117415,0.009795896622140976,-3.0406393130333966
520.000000000007,178.38695050992976,0.009881169479320384,-3.0422142345748875
521.200000000007,178.78850706241352,0.010686893216676374,-3.042210127154477
522.400000000007,179.18960619974953,0.01111545843023487,-3.042151704549002
523.6000000000071,179.5950926666018,0.012126628278870122,-3.044080409550273
524.800000000007,179.99349679909767,0.008252639861500377,-3.0447398638803804
526.000000000007,180.39243740927674,0.010712845052051723,-3.047810781248519
527.2000000000071,180.7966004038711,0.01090272016430438,-3.0478121502178253
528.4000000000071,181.19467334358274,0.011042689705596853,-3.0491200222326507
529.6000000000072,181.60099678753852,0.013434565941509824,-3.047479955393573
530.8000000000071,182.00520958161925,0.015329533212532276,-3.0491740277022874
532.0000000000072,182.41039923748707,0.017368402889518464,-3.0514767642848097
533.2000000000072,182.8082819414275,0.013235621683006737,-3.0500433140657686
534.4000000000071,183.2080803927046,0.014709328793223175,-3.0549400137020015
535.6000000000072,183.60701273912284,0.020603150769882728,-3.053083208531868
536.8000000000072,184.00938971402658,0.019662193630338276,-3.054949693173457
538.0000000000073,184.41422005056654,0.022164465302778602,-3.055653877553235
539.2000000000073,184.8104286503623,0.02055705130336305,-3.0568826584211486
540.4000000000073,185.21010036985587,0.02408386576196353,-3.056589813915238
541.6000000000073,185.61811678674144,0.024401749284584717,-3.0565895820598064
542.8000000000073,186.02393733061965,0.023458446612853123,-3.059021926520865
544.0000000000073,186.4269485187941,0.02565946182323886,-3.0602194197168204
545.2000000000073,186.82972208646268,0.025678196316110125,-3.0589007645018036
546.4000000000074,187.2308495546566,0.024796869597559557,-3.0595543165918824
547.6000000000074,187.6314982757355,0.022506797456019356,-3.063510054000049
548.8000000000075,188.02953394343209,0.024479947885786668,-3.061090028717042
550.0000000000074,188.43341979867375,0.027801055330173963,-3.063540388321477
551.2000000000074,188.8374246696777,0.02956779813104138,-3.0623000654282695
552.4000000000075,189.24147624928597,0.029170370979477056,-3.0637951810564967
553.6000000000074,189.6323470188663,0.035704080920655024,-3.0650393512845744
554.8000000000075,190.04215632859103,0.03277426860296151,-3.0663584110013042
556.0000000000075,190.44659662543734,0.02866598159015732,-3.06405992349446
557.2000000000075,190.85521571527525,0.03353566449472378,-3.0664104147581863
558.4000000000076,191.26073943734292,0.03314007341187475,-3.068890115508449
559.6000000000075,191.66420930749888,0.032117524666521735,-3.068657837976056
560.8000000000076,192.06954063127372,0.0317943730035557,-3.068999991737539
562.0000000000076,192.4722045895524,0.033870907428086294,-3.0686699824350976
563.2000000000075,192.87490653711254,0.03321855207535629,-3.07130945090912
564.4000000000076,193.27446935615035,0.031124804131746675,-3.0726198491822956
565.6000000000076,193.6814336508776,0.033631067590613295,-3.0716260122916887
566.8000000000077,194.08340711721905,0.031326388363436486,-3.0726282457294127
568.0000000000077,194.48546221221977,0.040097752150416,-3.072836100990382
569.2000000000077,194.8929120121837,0.038512118577584964,-3.0728400589798004
570.4000000000077,195.29419453833748,0.042355998250206195,-3.075471719147283
571.6000000000078,195.69680960975802,0.04554081638082197,-3.074474685880329
572.8000000000077,196.0991736978776,0.04494605492179016,-3.0754584771770626
574.0000000000077,196.5002133805927,0.04492431453848722,-3.074871226396982
575.2000000000078,196.9096470377679,0.04384235993249597,-3.076407106891556
576.4000000000078,197.31880492748223,0.04645496217703826,-3.078110045392174
577.6000000000079,197.7221241768301,0.04448081685167793,-3.078154580913898
578.8000000000078,198.1284909515261,0.042543297900302424,-3.0794295267695038
580.0000000000078,198.525935527789,0.04096601141547129,-3.0794294710132686
581.2000000000079,198.92789293924116,0.04551386596876261,-3.0781098384946866
582.4000000000078,199.32873109911102,0.04703960442483979,-3.078758819713136
583.6000000000079,199.72968593889885,0.046786308194606274,-3.0815602711540713
584.8000000000079,200.13737174999534,0.04786177839468442,-3.0830581969308417
586.000000000008,200.54153955135203,0.04836977801576037,-3.083049906000001
587.200000000008,200.94647769463103,0.045148553655071755,-3.082383485162958
588.4000000000079,201.35215980781442,0.049176096806085035,-3.0833815727684533
589.600000000008,201.75607315821034,0.051818934149980844,-3.084030140783984
590.800000000008,202.09463508293237,0.037006415412286664,-3.085019815174738
592.000000000008,202.56633725411209,0.053926023994551375,-3.08699988693769
593.200000000008,202.96884004284504,0.05577191639056389,-3.0874400211943174
594.400000000008,203.37448658320832,0.06181341719502598,-3.087119560843657
595.6000000000081,203.7821208356121,0.059551125300966845,-3.089075814637621
596.8000000000081,204.19120018532087,0.06174958366744443,-3.092187581095157
598.0000000000081,204.59819143385081,0.06335114196256475,-3.092067831412467
599.2000000000081,205.00847011872688,0.06653078922875277,-3.0959006328781458
600.4000000000082,205.41370912842015,0.06904569178704145,-3.093140443337912
601.6000000000081,205.81795222761764,0.06798698130927194,-3.093800152247775
602.8000000000081,206.22877742323234,0.0687078619702115,-3.0947900707536107
604.0000000000082,206.63110302511603,0.06870135319882742,-3.0957799899283702
605.2000000000082,207.03201037583216,0.06519534237482949,-3.0978789874414634
606.4000000000083,207.4354571800557,0.0714312096181362,-3.098097379669542
607.6000000000082,207.84060387635188,0.06664325622581435,-3.1000695702611045
608.8000000000083,208.24342438426336,0.06482674296132585,-3.1019414549774056
610.0000000000083,208.64558249142945,0.06663353725137622,-3.1026928524115487
611.2000000000082,209.0508798027866,0.06747397651849907,-3.103912053119415
612.4000000000083,209.45737173443916,0.06623936982866052,-3.1042525413022783
613.6000000000083,209.86959065748957,0.06643995338539055,-3.1042400817625655
614.8000000000084,210.2754884260469,0.06456103173655947,-3.10688090270253
616.0000000000084,210.68318169386322,0.06649799205065454,-3.104803157148374
617.2000000000083,211.0840652618998,0.06570680568377352,-3.107860030466221
618.4000000000084,211.49026461380495,0.06573282512097789,-3.107219090903837
619.6000000000084,211.89138502212583,0.05994442923070542,-3.110830059565814
620.8000000000084,212.29526830735628,0.06187721599063334,-3.1094095474447614
622.0000000000084,212.70168493743992,0.060774634999101185,-3.1102898137637647
623.2000000000085,213.10502289813186,0.05728948695896685,-3.112275868489047
624.4000000000085,213.5117464832865,0.05879275275929707,-3.1104900926047443
625.6000000000085,213.91415212620385,0.05401952382507291,-3.1127755285184753
626.8000000000085,214.32049178290876,0.05614641337411852,-3.1144499146540614
628.0000000000085,214.7239437986169,0.058440264133767794,-3.1134998721132607
629.2000000000086,215.1300640561197,0.06002016116113795,-3.115431696303919
630.4000000000085,215.53247899388498,0.056953026265138984,-3.115333530263898
631.6000000000085,215.9333185872069,0.06112212897835212,-3.1159794795972338
632.8000000000086,216.33568396715498,0.06165730079683751,-3.11641395600702
634.0000000000086,216.74167272459943,0.06497758351849425,-3.1164198515756976
635.2000000000087,217.15969359008434,0.07028226830962447,-3.116749977001248
636.4000000000086,217.56471962551748,0.06721723776831023,-3.116765497711028
637.6000000000087,217.97015464631716,0.06456303055162715,-3.1169810486341296
638.8000000000087,218.37312553550757,0.06438804565038003,-3.1178508981237787
640.0000000000086,218.7744279358712,0.08471157174094257,-3.1178478986049654
641.2000000000087,219.1851273744614,0.1346661613756197,-3.1185207843274965
642.4000000000087,219.59212964340657,0.13724602564370159,-3.1188395739700594
643.6000000000088,219.9991783224867,0.13801638784050585,-3.1175202037787075
644.8000000000088,220.40138050588956,0.14426809306593924,-3.122153836882735
646.0000000000088,220.80807103199328,0.1437090348395973,-3.122775382258764
647.2000000000088,221.2122051280722,0.14098333158104648,-3.1219199689971684
648.4000000000088,221.62072214651965,0.14684680289496344,-3.1219223268824114
649.6000000000088,222.03050688853693,0.14295312250326653,-3.1235590595130525
650.8000000000088,222.46325533809653,0.14847728956282813,-3.1213594965279596
652.0000000000089,222.84700237397968,0.14745587267566584,-3.1240010417257498
653.2000000000089,223.2516632751738,0.15147748061915323,-3.124329394627556
654.400000000009,223.65005323082624,0.13604163210389686,-3.1233401373315264
655.6000000000089,224.050776894052,0.12627941526808462,-3.125320014942993
656.8000000000089,224.4495472533722,0.1089390139646218,-3.124149550391364
658.000000000009,224.85843477860632,0.10289663847909525,-3.1239765269391815
659.2000000000089,225.2644299896989,0.10510453226536276,-3.125319956930266
660.400000000009,225.671012327825,0.10409092655244878,-3.1272895355192705
661.600000000009,226.08000205772,0.10498895534542463,-3.1259546757881536
662.800000000009,226.48917375452936,0.10998460027454504,-3.1249798312839956
664.0000000000091,226.89696326881696,0.10988013673681829,-3.1262706023678595
665.200000000009,227.30031227167467,0.11226505754101357,-3.1272900667727246
666.4000000000091,227.70611325333607,0.1096370816327692,-3.1276328500284434
667.6000000000091,228.11019285939992,0.11395290904388178,-3.12729007980643
668.800000000009,228.5186759718482,0.11794608760011505,-3.12860995299995
670.0000000000091,228.92729554897767,0.1188092634109279,-3.127950080996499
671.2000000000091,229.33423373692042,0.12399846104783441,-3.1276200180852864
672.4000000000092,229.7436483917132,0.12669370303621763,-3.128929872205764
673.6000000000092,230.14848044360383,0.13729345685782546,-3.1292691540018893
674.8000000000092,230.55405230685977,0.14026428950187064,-3.129600110173265
676.0000000000092,230.9587717661072,0.14775020017396345,-3.1295900968624375
677.2000000000093,231.36465660119987,0.1504791445603777,-3.130590626773647
678.4000000000092,231.77757843856693,0.15124540450138513,-3.1306994885606594
679.6000000000092,232.19173759622055,0.1615126693944755,-3.1310299450000674
680.8000000000093,232.59917465900293,0.16908959548959057,-3.132104229143134
682.0000000000093,233.00635025997187,0.1710688627693573,-3.1324576102964006
683.2000000000094,233.40654878365356,0.17719549959888914,-3.1304693018451126
684.4000000000093,233.813199385937,0.1765427797012249,-3.132780715977799
685.6000000000093,234.21769037867523,0.18440425113663483,-3.1331101796994965
686.8000000000094,234.62434913742507,0.1965973265856289,-3.1334877894148976
688.0000000000093,235.0330175871586,0.20089181906045983,-3.1333300720000006
689.2000000000094,235.44724587571687,0.20948279303779582,-3.133330071049885
690.4000000000094,235.8546024555282,0.20858318987085234,-3.132669945147309
691.6000000000095,236.25987855861587,0.20563144429207858,-3.1363592536249265
692.8000000000095,236.66763808920058,0.20765181584572368,-3.135299956977021
694.0000000000094,237.07134887052234,0.2117485753177113,-3.13629019828487
695.2000000000095,237.4783013443455,0.21456032188021856,-3.136620191189277
696.4000000000095,237.88873824066667,0.21591202968240353,-3.138600045322244
697.6000000000095,238.29260551797654,0.21542772385153297,-3.138597175744501
698.8000000000095,238.68412909047734,0.221380585695798,-3.137846288654759
700.0000000000095,239.11249656648388,0.2269906740193397,-3.138469222127528
701.2000000000096,239.52425357914916,0.23048542581580955,-3.13826981479826
702.4000000000096,239.92880969503634,0.2337017651283797,-3.1392607312799816
703.6000000000096,240.33772797793927,0.23323680708137884,-3.139178761374542
704.8000000000096,240.7409885982495,0.2402987836507302,-3.1405801367367414
706.0000000000097,241.14164478190006,0.24132733905736758,-3.14025015918029
707.2000000000096,241.554382442945,0.24200594112674434,-3.1415700392635637
708.4000000000096,241.963468223542,0.24767997866166924,-3.1418927022819316
709.6000000000097,242.37481089123827,0.24491822172521172,-3.14189850522648
710.8000000000097,242.78287536830524,0.23951858511429114,-3.1415693745976725
712.0000000000098,243.1851587386779,0.24221017387608912,-3.141889676078571
713.2000000000097,243.59959023802207,0.23980029673876135,-3.141558294987036
714.4000000000098,244.00308345533628,0.23890936468547563,-3.1429925454344616
715.6000000000098,244.41083278934406,0.24521990775037805,-3.144568774296731
716.8000000000097,244.81647617952927,0.23820913868144222,-3.1445299464718315
718.0000000000098,245.22686131435634,0.23917990798229738,-3.144530213358789
719.2000000000098,245.62817784047698,0.23777969382935327,-3.1455097077425243
720.4000000000099,246.03578346271843,0.23789082490224,-3.14583978033001
721.6000000000099,246.44703103380883,0.2365811886218232,-3.146829884100475
722.8000000000098,246.8567055657302,0.23617011636586005,-3.1468298013902527
724.0000000000099,247.262412398472,0.23606553007225406,-3.14815007933218
725.2000000000099,247.67142906193897,0.23674801760125153,-3.1472681703665955
726.4000000000099,248.07310138709474,0.23922508069330517,-3.148438224966994
727.6000000000099,248.49157070471244,0.24608203149416807,-3.1479217534332813
728.80000000001,248.90045539970907,0.24815199400541088,-3.1479241229992527
730.00000000001,249.31180033207917,0.24904261113459247,-3.149569927443318
731.20000000001,249.71803045405954,0.24942452542515658,-3.1505598042666048
732.40000000001,250.13026788018504,0.2474743594778004,-3.1492427694636054
733.60000000001,250.53728519328547,0.24759152556362762,-3.151220726085292
734.8000000000101,250.94453101261138,0.2504927005761446,-3.151220167
736.00000000001,251.35094527070942,0.25275809403801563,-3.152792666960958
737.20000000001,251.7577364355207,0.25442306356385824,-3.1538599780231573
738.4000000000101,252.15942736413444,0.2564419701876135,-3.152549978
739.6000000000101,252.57200363571778,0.25810165010940356,-3.152858815455448
740.8000000000102,252.97454514108114,0.2605001823433848,-3.154190162522333
742.0000000000101,253.3864996080548,0.26337021053144616,-3.155180155543955
743.2000000000102,253.79618884770358,0.2661261721902157,-3.1568841217696906
744.4000000000102,254.20170079683476,0.2682676830874198,-3.1558398890450614
745.6000000000101,254.61047474591604,0.27270570498922053,-3.1559227200464304
746.8000000000102,255.02600856841266,0.27623855944390874,-3.1578099423451262
748.0000000000102,255.43233190350185,0.28115569239004046,-3.157809940352895
749.0000000000102,255.77131165268528,0.28499496824228654,-3.1574796930094227