File: 01_Data/Cardboard/STA/N2/10K_min/Cardboard_STA_N2_10KData_230818_R4.csv
##Temp./Â°C,Time/min,DSC/(mW/mg),Mass loss/mg
28.0,15.656334533153142,0.03612031753046807,-0.08497170239173801
29.100000000000016,16.034156979346175,0.08559012790699816,-0.09020157517477223
30.20000000000003,16.265928665028888,0.11817578167636,-0.09309573701034202
31.300000000000047,16.449588934663566,0.1406368417641306,-0.09250378883465604
32.40000000000006,16.622045444015555,0.15963151730471958,-0.09452628894313353
33.50000000000008,16.775434890151097,0.1755561798011871,-0.09497650268078894
34.600000000000094,16.919593264711818,0.18915589993734816,-0.09692593825631901
35.70000000000011,17.05892615450151,0.20184307706934357,-0.09985714581212912
36.800000000000125,17.193936363120272,0.21674533579957478,-0.0990729096297609
37.90000000000014,17.32642468983044,0.2292184373648749,-0.10032679934814093
39.000000000000156,17.455089018695435,0.2406815544618781,-0.10108606175292012
40.10000000000017,17.58243953868896,0.25307180671796914,-0.10070088685524148
41.20000000000019,17.70451924988688,0.2620819150285836,-0.10061737319987252
42.3000000000002,17.8329889853669,0.27246710269208085,-0.10189873336526167
43.40000000000022,17.95250490344868,0.28431639913499884,-0.10327236664716688
44.500000000000234,18.079790045153906,0.2936816914079512,-0.10461995007897817
45.60000000000025,18.20110138063518,0.30388125782231357,-0.10586442540197138
46.700000000000266,18.321837639657574,0.31289607959708055,-0.10586625256815152
47.80000000000028,18.44300107648844,0.3237201978155766,-0.1084756779455267
48.9000000000003,18.564140032751038,0.33356814274359126,-0.11109411797650415
50.00000000000031,18.68159838686323,0.3446415315235176,-0.11374059301270956
51.10000000000033,18.801134296071687,0.356687430439363,-0.11447978864307284
52.200000000000344,18.918919099585835,0.36492071162499307,-0.11638027000937745
53.30000000000036,19.036714004664873,0.3758980989006615,-0.11771455944378495
54.400000000000375,19.152279727759264,0.38651609487171457,-0.11833818370516447
55.50000000000039,19.2679484434172,0.3957524662238596,-0.1209661543840066
56.600000000000406,19.384992224803856,0.40511617874234584,-0.1222711071459619
57.70000000000042,19.50026864193775,0.4144066788392142,-0.12284762669206639
58.80000000000044,19.614260648601515,0.4221450975878942,-0.1262259743996319
59.90000000000045,19.728111437176693,0.432241195324917,-0.12758449742403588
61.00000000000047,19.841677810510664,0.4383334845706166,-0.13138448109012169
62.100000000000485,19.95370984551149,0.44452759938755904,-0.13251043257128536
63.2000000000005,20.06659099728884,0.45050422984482874,-0.13382803005417943
64.30000000000052,20.179434637575937,0.4540267142746446,-0.13677768090571485
65.40000000000053,20.29225538413191,0.4619537718779765,-0.13812433917940847
66.50000000000054,20.40353766684582,0.46435916276371647,-0.14350353349969414
67.60000000000056,20.515217215391058,0.46628575805896255,-0.14350279744254246
68.70000000000059,20.625342630855016,0.47067336380779556,-0.14480937950297745
69.8000000000006,20.735933790959493,0.4711010991530653,-0.14743796434510115
70.9000000000006,20.845797195416033,0.47296907185040515,-0.15011279895082996
72.00000000000063,20.957381843013117,0.4717225712073596,-0.15271975619367018
73.10000000000065,21.06725313824371,0.47192752297064167,-0.15657964775194033
74.20000000000066,21.175799259663187,0.46955569168698763,-0.15666026765731855
75.30000000000067,21.28583906432569,0.46588839157939854,-0.15929993158501832
76.40000000000069,21.395992009408197,0.46306144848111286,-0.1619442869690868
77.50000000000071,21.503357139651886,0.4610599340432009,-0.1645801661834252
78.60000000000072,21.61244019254068,0.45746574951706065,-0.1657753444584995
79.70000000000073,21.722231224802666,0.4511916729044978,-0.16986990119056067
80.80000000000075,21.830433782639485,0.4482748678181352,-0.16983441101187635
81.90000000000077,21.938894856654624,0.44100335178130146,-0.1724921963737116
83.00000000000078,22.048428799941366,0.43425057646359977,-0.17510886274355286
84.10000000000079,22.15608846070334,0.42752920268386485,-0.1764442508141788
85.20000000000081,22.264132989977366,0.4224729957405762,-0.17901123170594024
86.30000000000084,22.372469450969668,0.4164720950306964,-0.1803838294739708
87.40000000000084,22.47959169538269,0.40544873849036267,-0.1803801268723908
88.50000000000085,22.586990802297837,0.4011076768837498,-0.18300988890871128
89.60000000000088,22.693677025105817,0.39302427712691723,-0.18532001393910935
90.7000000000009,22.802379683831766,0.3837742123878345,-0.1863105154932283
91.8000000000009,22.909816823631107,0.377459531706813,-0.18667316342898488
92.90000000000092,23.016266103606018,0.3718526855028528,-0.1879479838758682
94.00000000000094,23.12348398643499,0.364585615975356,-0.18959897066310338
95.10000000000096,23.230132816295185,0.3550871969853715,-0.1909198699547643
96.20000000000097,23.33694814354579,0.3491948594116747,-0.1927923251268071
97.30000000000098,23.443488387696807,0.34231696855196025,-0.19487049750545138
98.400000000001,23.54782158541234,0.334397565287855,-0.19585869747897888
99.50000000000102,23.656995075133043,0.32579944397445204,-0.19460523498906301
100.60000000000103,23.763400071838795,0.31887912932207807,-0.19585017209232758
101.70000000000104,23.868746901949134,0.3136165015702952,-0.19716992525965793
102.80000000000106,23.972797292370483,0.31003435822828607,-0.1957826682599184
103.90000000000109,24.08132007603636,0.30257852157258625,-0.19904326913000103
105.0000000000011,24.188755772132247,0.2976537714746643,-0.1987101509872118
106.1000000000011,24.29475761207403,0.28978601853857633,-0.20036800733143023
107.20000000000113,24.4008824816844,0.28443457903145486,-0.20281935021386133
108.30000000000115,24.507862023209032,0.2796835589756337,-0.20239133392573194
109.40000000000116,24.613382333949474,0.2753702519884833,-0.20199032803128336
110.50000000000117,24.720023272445623,0.2687877299477779,-0.20285518197979346
111.60000000000119,24.824861163360467,0.2658572662683336,-0.202769620221114
112.70000000000121,24.931531485017167,0.2618441785650687,-0.20283228000818543
113.80000000000122,25.036844322301434,0.2585297694759061,-0.20277996000153964
114.90000000000123,25.14337357517522,0.2534468065344817,-0.20277710664387438
116.00000000000125,25.249622418308658,0.2522180149512425,-0.20486108553663884
117.10000000000127,25.354728725999358,0.2487017467364987,-0.20222797112176938
118.20000000000128,25.46128705859889,0.2461290724322076,-0.20279759679509235
119.30000000000129,25.56674360827159,0.24554090430164432,-0.20354027958424492
120.40000000000131,25.672085087713175,0.24171619459186422,-0.20221954520335306
121.50000000000134,25.77868577705406,0.2393689994358672,-0.2022207685317059
122.60000000000134,25.885131338421054,0.2364926343455438,-0.20490623597419555
123.70000000000135,25.990283426963593,0.23534155672173473,-0.20486183142256253
124.80000000000138,26.09656122253295,0.23380202250764626,-0.2048566805692369
125.9000000000014,26.19950001073384,0.23122785085345177,-0.2048601671656085
127.0000000000014,26.3081648816474,0.230629183170038,-0.2035731702834318
128.10000000000142,26.41502373487549,0.23077827288706443,-0.20617010843003847
129.20000000000144,26.520439740407564,0.2274744878858459,-0.20616920764357838
130.30000000000146,26.6258709317695,0.22647683751722014,-0.2074697226228941
131.40000000000146,26.731119288589287,0.22706018564290642,-0.20486137441942853
132.50000000000148,26.837242525983577,0.22673416791729228,-0.20481445203454696
133.6000000000015,26.943262392751006,0.22923745031407416,-0.20484519258202338
134.70000000000152,27.047928086969918,0.22638448190470473,-0.20387012162003115
135.80000000000155,27.153755470378094,0.22519918255661864,-0.20519375936022177
136.90000000000154,27.25987913610858,0.2245718681932971,-0.20519011199983161
138.00000000000156,27.36586058024949,0.22653879491658468,-0.20519179870018434
139.1000000000016,27.470802814339116,0.22529333019699993,-0.20350848446478098
140.20000000000158,27.576351243986522,0.2275014472715633,-0.2048563406210544
141.3000000000016,27.681813360179063,0.22636424807726252,-0.20573356805704535
142.40000000000163,27.78630038416685,0.22694650182024634,-0.20715997841928013
143.50000000000165,27.892691300691897,0.22534999288451218,-0.20715962683276246
144.60000000000167,27.995420293930163,0.22615217527267495,-0.20716179077272834
145.70000000000167,28.102331508292274,0.22606723921294036,-0.2082694084140888
146.8000000000017,28.207338607500066,0.22772720226508936,-0.20716994807172728
147.9000000000017,28.312620650022648,0.2268986205793675,-0.20847849930614926
149.0000000000017,28.418052655357744,0.22835993929850562,-0.2084881555232374
150.10000000000173,28.523078338701634,0.2273191352180539,-0.2084899366173225
151.20000000000175,28.62693022329341,0.22744763436427617,-0.2078491743294406
152.30000000000177,28.733243063822925,0.22972873518070225,-0.20717004044525789
153.4000000000018,28.83843098623719,0.23003485485384667,-0.2071604721092002
154.5000000000018,28.943403057172834,0.229285619388373,-0.20683019258797186
155.6000000000018,29.047159290102925,0.22996634558379658,-0.20582739538557515
156.70000000000184,29.152609802188675,0.23081597999246473,-0.20715989826605963
157.80000000000183,29.257954889551407,0.23071622253184976,-0.20716055585987236
158.90000000000185,29.362584804745456,0.22985935732685703,-0.20847997137803764
160.00000000000188,29.46753790428112,0.22941971570647035,-0.20715691242367074
161.1000000000019,29.57208495363885,0.23086610884723746,-0.2068221757501414
162.20000000000192,29.677771609281393,0.2292279499672405,-0.20944165762929812
163.30000000000192,29.78237303009326,0.2330864600698983,-0.2084962759337463
164.40000000000194,29.887699182738693,0.23500742533026742,-0.2095518976773736
165.50000000000196,29.993180044888174,0.2357897918128009,-0.20686824068810905
166.60000000000196,30.09823629239652,0.23601858602696013,-0.2068400691909793
167.70000000000198,30.20235032602463,0.23764851208832694,-0.20815963858673525
168.800000000002,30.30773144198918,0.2368444557257623,-0.20814624976606266
169.90000000000202,30.4129212284449,0.23951820261637535,-0.20946898812491455
171.00000000000205,30.518524245902377,0.23903239417974453,-0.20814993946668015
172.10000000000204,30.623785677658592,0.23859762293619435,-0.20946981743567106
173.20000000000206,30.728520956840597,0.23978643330120386,-0.21152592059849162
174.3000000000021,30.83183825273524,0.2394763247331999,-0.21298412970964398
175.40000000000208,30.93944564531327,0.24176752839647508,-0.21278547726557484
176.5000000000021,31.043503278058605,0.243025891258144,-0.2120658859345248
177.60000000000213,31.14875339409455,0.2419275285224216,-0.21009144356304432
178.70000000000215,31.2531986412653,0.24447361691979608,-0.21078408604547327
179.80000000000217,31.359027700380643,0.2439546314512795,-0.21176261526213347
180.90000000000217,31.46314046512878,0.24246705917678701,-0.2117700146263024
182.0000000000022,31.569322440118288,0.24388500202470031,-0.21046557048620107
183.1000000000022,31.67430744598783,0.2431470292212996,-0.2117709724715584
184.2000000000022,31.77758058561456,0.24487137286850014,-0.2117798480093933
185.30000000000223,31.88259634150109,0.24537395053700428,-0.21177984799556748
186.40000000000225,31.987099718863327,0.24646077671838773,-0.21228537207888465
187.50000000000227,32.091669105238395,0.24633474404418276,-0.2117748271099642
188.6000000000023,32.19699347976798,0.24671725995728044,-0.211782635331502
189.7000000000023,32.300245250056484,0.24656033755023987,-0.21112011997472901
190.8000000000023,32.40585732849909,0.24867440752947623,-0.21044907528519508
191.90000000000234,32.510744476844586,0.2501761085138776,-0.21045996133350275
193.00000000000233,32.61437676773499,0.24950520140782295,-0.21178273395862357
194.10000000000235,32.718957989123545,0.24866127632806445,-0.2124310836379273
195.20000000000238,32.82335161369556,0.24987781619074734,-0.21376011428655683
196.3000000000024,32.92852333479773,0.24888223632185502,-0.21375912752281812
197.40000000000242,33.03258392719308,0.25185828442070024,-0.21273968557999723
198.50000000000242,33.13833000000025,0.2531631822057805,-0.21445678966694448
199.60000000000244,33.242558337231266,0.25174269677758376,-0.21316916037959732
200.70000000000246,33.347178068860956,0.2517690563284911,-0.21308914298255566
201.80000000000246,33.451479622180436,0.2521740056358788,-0.21341966442754945
202.90000000000248,33.55635238986684,0.25375861481672635,-0.21575029438131388
204.0000000000025,33.66033338146248,0.2556401181195327,-0.21572984796469274
205.10000000000252,33.76522764629791,0.2538207819759748,-0.21573073324005554
206.20000000000255,33.86841104789164,0.25570286113966256,-0.2160629416009323
207.30000000000254,33.9737100705564,0.2557610264230785,-0.21598114233907806
208.40000000000256,34.079968379869946,0.25754098763966105,-0.21705018427798484
209.5000000000026,34.18365170290711,0.2565102829543051,-0.21705018873022341
210.60000000000258,34.28944110201264,0.2571581627748689,-0.21779222482402671
211.7000000000026,34.394138807102486,0.25643690064708013,-0.21899992598243623
212.80000000000263,34.49910623941569,0.25838799086763076,-0.22110368182665052
213.90000000000265,34.60360437964546,0.25798623325795056,-0.22103421030291237
215.00000000000267,34.708134709545504,0.2598577402562907,-0.21996213603821957
216.10000000000267,34.8133078702931,0.259640728874559,-0.2204190432427926
217.2000000000027,34.91814226239852,0.25984844070679713,-0.2223756272374735
218.3000000000027,35.022432316378286,0.2592770690447086,-0.2236264350004462
219.4000000000027,35.12715244445897,0.2589063472044799,-0.2223308548842695
220.50000000000273,35.23209264163039,0.2596450508175001,-0.22374528778696057
221.60000000000275,35.336631204633214,0.2592264285286241,-0.22408467162515233
222.70000000000277,35.44185115505307,0.2585482415325391,-0.22297006922058982
223.8000000000028,35.54523048437981,0.25705204651665303,-0.2255137811395298
224.9000000000028,35.65069799455365,0.2584726149996732,-0.22822359431863015
226.0000000000028,35.75577849651016,0.25729109218184143,-0.227462351236146
227.10000000000284,35.85900789085868,0.2579844779070952,-0.22824006784891004
228.20000000000283,35.96544631885018,0.2591953952830115,-0.22824008124234263
229.30000000000285,36.07008753558011,0.2612884436259819,-0.22955930100466748
230.40000000000288,36.17519388643656,0.26057103971727535,-0.22956067609649056
231.5000000000029,36.28075783438234,0.25935908327405577,-0.23122280338878642
232.60000000000292,36.38507764707429,0.2608350934526922,-0.23250594350244747
233.70000000000292,36.49093270265899,0.25969418121974375,-0.23383997454716487
234.80000000000294,36.594888934437954,0.2600244021059932,-0.23385364502028416
235.90000000000296,36.700182105519865,0.2602019194537515,-0.2359726689165238
237.00000000000296,36.80582562044833,0.26120855720826475,-0.2378647600082484
238.10000000000298,36.910628608122074,0.26205100106068735,-0.23910864290873812
239.200000000003,37.01338018113226,0.2606352898020583,-0.2391099519973956
240.30000000000302,37.11724043664894,0.2599483934839839,-0.23910996299183562
241.40000000000305,37.22434557674273,0.2615157902129479,-0.24220444059227786
242.50000000000304,37.32968037922856,0.2593816705715579,-0.2463606570994239
243.60000000000306,37.433232148411335,0.2605275057057479,-0.24741756307578333
244.7000000000031,37.537782775489504,0.2600715918077834,-0.24900772403189064
245.80000000000308,37.64396439136812,0.2603598286553013,-0.2516782578780532
246.9000000000031,37.74787779296436,0.25992258338601837,-0.25294412070879524
248.00000000000313,37.853040366361164,0.25968908815402747,-0.2542869406551378
249.10000000000315,37.957262297619465,0.259101532899352,-0.2552503902240524
250.20000000000317,38.0636972785298,0.2595033899190877,-0.25712574520495135
251.30000000000317,38.1680418239165,0.257966876728984,-0.2606028380298735
252.4000000000032,38.272123933666876,0.25722295737616374,-0.2626458382250889
253.5000000000032,38.37800171006935,0.2566378581816835,-0.2662629486885426
254.6000000000032,38.48260471813112,0.2573074868666496,-0.26954027383455603
255.70000000000323,38.58625163309377,0.25767328185476135,-0.27042775848518064
256.80000000000325,38.6921026802484,0.2566129680240745,-0.272799632720381
257.9000000000033,38.795620198232356,0.25536716297530293,-0.2764455497990035
259.0000000000033,38.90051816863773,0.2559424364413314,-0.2801408324403529
260.1000000000033,39.003668422826046,0.25707629259349374,-0.280878541958435
261.20000000000334,39.10990492271159,0.2565325544788739,-0.28610483273993736
262.30000000000337,39.2155594324626,0.2558188838628266,-0.28998395362870033
263.40000000000333,39.32045571869864,0.25700225259604403,-0.294122285029907
264.50000000000335,39.42475119868981,0.2559067609575716,-0.2991368482920178
265.6000000000034,39.52932542074089,0.25598022882776417,-0.3050837081941782
266.7000000000034,39.634989252202416,0.2554971819579479,-0.30978123391712753
267.8000000000034,39.74050232090009,0.25708844285030485,-0.31574828501265495
268.9000000000034,39.84476069499978,0.2607337086643178,-0.320896403654515
270.0000000000034,39.95074481196788,0.2563468434220195,-0.32524773124397655
271.10000000000343,40.0555753429727,0.2582592722110948,-0.3317404521915064
272.20000000000346,40.160513155243,0.2573852216209802,-0.3365773915487873
273.3000000000035,40.26638771588774,0.25704081196256023,-0.34298153834374423
274.4000000000035,40.37124142603664,0.2591470477382902,-0.34990018583205806
275.5000000000035,40.47582606748973,0.2593941544977296,-0.356206430777366
276.60000000000355,40.58147849026438,0.259018593806815,-0.36299544752965085
277.70000000000357,40.686908745436504,0.25795843196006074,-0.37050545962603776
278.8000000000036,40.79285603967141,0.2616405490720226,-0.3780572611277786
279.9000000000036,40.8968671307702,0.26015161121955166,-0.3842830214529269
281.0000000000036,41.00253176469488,0.2611793979061978,-0.39384231761587296
282.1000000000036,41.1091986573506,0.2612748665034086,-0.40309714417150877
283.2000000000036,41.21342722676799,0.26368324057605297,-0.4121868534634938
284.30000000000365,41.31992906298656,0.26421495105179704,-0.42092795383363013
285.4000000000037,41.424226957536895,0.2643309256663948,-0.42938530405333575
286.5000000000037,41.5290385897395,0.2674999295629088,-0.4376640870978359
287.60000000000366,41.63570437859541,0.26920580106587955,-0.44771062240706394
288.7000000000037,41.74197884626824,0.27053312833558074,-0.4585716000862914
289.8000000000037,41.84646683337987,0.270978128736888,-0.47122031615502813
290.90000000000373,41.95246103834606,0.27307163477934715,-0.48186174436103
292.00000000000375,42.055952998903635,0.2755229574457809,-0.49442007767309715
293.1000000000038,42.162179968481354,0.279562871125288,-0.5062838225683679
294.2000000000038,42.26862761246036,0.2801993511105929,-0.5192051200993091
295.3000000000038,42.373089552592184,0.28361909659264173,-0.5322979107086612
296.40000000000384,42.478673824754715,0.28622567325121717,-0.547319016764205
297.5000000000038,42.58453156723382,0.2876410668843836,-0.5603357130567592
298.60000000000383,42.689385211968634,0.29156939082216216,-0.573058562920929
299.70000000000385,42.79476482132926,0.29461557949987394,-0.5894844301092239
300.8000000000039,42.90103017438094,0.2977103488597066,-0.6059999054619718
301.9000000000039,43.007343970906405,0.3019654340537181,-0.6206171815231345
303.0000000000039,43.11281700674153,0.30366951091824834,-0.6356970292384196
304.10000000000394,43.21851263378833,0.30763684634273014,-0.652374590439754
305.2000000000039,43.32346871296062,0.31236238253104887,-0.6701016424518502
306.30000000000393,43.43080028929846,0.3159732276790561,-0.6888563964453542
307.40000000000396,43.537054289173874,0.3187059259618561,-0.7084669715584315
308.500000000004,43.64247447536549,0.32305325654659667,-0.7272978723981645
309.600000000004,43.7484276967685,0.32668299931578604,-0.746549887127832
310.700000000004,43.85453068313089,0.3313316262351482,-0.7657238997795659
311.80000000000405,43.960893511087505,0.33528193211550317,-0.7860213854131599
312.90000000000407,44.06722635379174,0.339886872598526,-0.8078817828160347
314.0000000000041,44.1734206306034,0.34441230004210244,-0.8294156072340217
315.10000000000406,44.28023448921263,0.3484289418095883,-0.8529680303462661
316.2000000000041,44.38632140430644,0.3536946597808508,-0.8720944971613815
317.3000000000041,44.491865080545146,0.3574526933659674,-0.8987720361609446
318.4000000000041,44.59860256565797,0.36206357582482074,-0.92234660127628
319.50000000000415,44.70506893605489,0.3643869370997328,-0.9478949922025661
320.6000000000042,44.81138351315433,0.3694088065846548,-0.9739540915804366
321.7000000000042,44.91655729634348,0.371771930335864,-1.0005951438258935
322.80000000000416,45.023925847562424,0.37876616620788406,-1.025379595520898
323.9000000000042,45.12919310155769,0.3830174127011423,-1.0540762132534152
325.0000000000042,45.23531133495548,0.39122983999411365,-1.081872961727433
326.10000000000423,45.342252732667426,0.39764294867724037,-1.1118675895265517
327.20000000000425,45.447379808135835,0.4035878889156401,-1.138565746894531
328.3000000000043,45.554338683261435,0.4093947851869306,-1.1702944766720091
329.4000000000043,45.66065720357954,0.415637792878754,-1.2022471943375685
330.5000000000043,45.76704481969222,0.42425815651153953,-1.2336111314274412
331.60000000000434,45.873127318707425,0.43310760647818114,-1.2658051100234187
332.7000000000043,45.978429444469164,0.4388803094726328,-1.301767930719254
333.80000000000433,46.08662876327002,0.44814466173048073,-1.3361060086429255
334.90000000000435,46.1938816645383,0.4566685232890255,-1.3728376450120399
336.0000000000044,46.30174522331164,0.4647591879593056,-1.4120063630304722
337.1000000000044,46.4067612805085,0.47472937687170713,-1.4493878040838042
338.2000000000044,46.51277033121037,0.48387425672959417,-1.4882625281801238
339.30000000000445,46.62090838274681,0.49154690069458673,-1.528874312595946
340.4000000000044,46.72654032557667,0.5008804307073094,-1.5699592538273515
341.50000000000443,46.834267118059934,0.5119056660226813,-1.6107254498780619
342.60000000000446,46.94089304993151,0.5206246287164569,-1.6536135463614867
343.7000000000045,47.04744350908702,0.5314476481920771,-1.696903871287939
344.8000000000045,47.154331467181144,0.5398327571854398,-1.741251449889584
345.9000000000045,47.26155249235851,0.54766467543787,-1.7881790211977995
347.00000000000455,47.36795407010429,0.5538334159849805,-1.835057740090308
348.10000000000457,47.475099104938536,0.5609990571934584,-1.8829736036088094
349.2000000000046,47.58218583520499,0.5645996463552505,-1.9309639971439525
350.30000000000456,47.68867294958727,0.5658439407573055,-1.9802199301154109
351.4000000000046,47.795034500483105,0.5665530898545341,-2.0311633236549906
352.5000000000046,47.90228200968138,0.5664662471475048,-2.079829863802844
353.6000000000046,48.00641392331606,0.563216479855307,-2.1284065730381307
354.70000000000465,48.11487079589608,0.55480980818849,-2.17742469905742
355.8000000000047,48.219597261046054,0.5442126526542221,-2.2255656894443017
356.9000000000047,48.32609211036316,0.5297239148894155,-2.275247792016416
358.00000000000466,48.432530110247804,0.5155803295763026,-2.31995077199714
359.1000000000047,48.53901356286627,0.49377377834155944,-2.367786727439741
360.2000000000047,48.64588988742398,0.46928980239077367,-2.409811219363505
361.30000000000473,48.74943434902193,0.440207248790109,-2.451145633759115
362.40000000000475,48.855645975166084,0.4140124530601075,-2.4903327589704256
363.5000000000048,48.96103447301244,0.38276933610470376,-2.527142221683853
364.6000000000048,49.06596390407566,0.3520771704469028,-2.5612642420112275
365.7000000000048,49.171342208416334,0.31837451027073294,-2.591767160025884
366.80000000000484,49.27591633920194,0.2876678853320478,-2.6186666128716074
367.9000000000048,49.38078478530788,0.2552816619327982,-2.6466517959465974
369.00000000000483,49.48728984355368,0.2276203070771896,-2.6694480693849796
370.10000000000485,49.5924649189183,0.19834798530610454,-2.6902246093521525
371.2000000000049,49.6968244858244,0.1714452702460767,-2.707543045473084
372.3000000000049,49.80317752576553,0.1470346225814041,-2.7231143643793008
373.4000000000049,49.909110462648236,0.12556567306694522,-2.738788567652081
374.50000000000495,50.01510669712286,0.10177697569870814,-2.7515322223115257
375.6000000000049,50.121797387707964,0.08035696453189978,-2.7621975744048477
376.70000000000493,50.22705160993321,0.06370205102980098,-2.7748407083568942
377.80000000000496,50.33367364824548,0.04420083866364055,-2.7819085105267694
378.900000000005,50.44021727618731,0.027588428009345023,-2.7895555292588186
380.000000000005,50.54543516185886,0.01448251659022004,-2.7965465620183085
381.100000000005,50.65281712309547,-0.00013067526289578524,-2.8037997236363275
382.20000000000505,50.758715209510406,-0.010502907425419483,-2.809182118197894
383.30000000000507,50.8658568046675,-0.017754353594402694,-2.8135288691476914
384.4000000000051,50.972692781769446,-0.02716013415520191,-2.819357541634922
385.50000000000506,51.080058601622994,-0.03178374144494556,-2.8222001295155463
386.6000000000051,51.18547044013299,-0.03542297045597409,-2.8251089289573956
387.7000000000051,51.29417659506777,-0.0399570330035548,-2.8299591279211667
388.8000000000051,51.401799458295436,-0.04378185594456574,-2.833368526201893
389.90000000000515,51.5074494304536,-0.048210577439298685,-2.8376779953329843
391.0000000000052,51.6148317842993,-0.04926387136668664,-2.8391192304686275
392.1000000000052,51.72312942291893,-0.05358097944264073,-2.843292604439267
393.20000000000516,51.829083684870895,-0.055545959466301253,-2.847178261963346
394.3000000000052,51.93427657912731,-0.05659047123993943,-2.8501466934146777
395.4000000000052,52.04321368508652,-0.05906809760414955,-2.8546269291302524
396.50000000000523,52.15096925953648,-0.06164992262792146,-2.8560098826247176
397.60000000000525,52.2591868126482,-0.06228013676302502,-2.858492788501324
398.7000000000053,52.365866216037446,-0.06588281345556202,-2.8637410916724892
399.8000000000053,52.47327685061109,-0.0675592122667803,-2.86808999291162
400.9000000000053,52.580795889311034,-0.0698076260182594,-2.873750322864945
402.00000000000534,52.68747420217487,-0.07325044726832353,-2.876305103568955
403.1000000000053,52.79640795267584,-0.07412539137414087,-2.8776285267044948
404.20000000000533,52.90422468879119,-0.07450977412297077,-2.8820290289770405
405.30000000000535,53.011604545225644,-0.07762950473764652,-2.8848032142409203
406.4000000000054,53.11906950742728,-0.07927035647653935,-2.8872653667793866
407.5000000000054,53.22692324700824,-0.08161455447839328,-2.890820306207733
408.6000000000054,53.3352239059924,-0.08217748276319137,-2.8931689758335404
409.70000000000545,53.443045438769516,-0.08187901635640515,-2.895007333547593
410.8000000000054,53.55062100803209,-0.08322825583079108,-2.9005978786740716
411.90000000000543,53.658782755556885,-0.08481517613896283,-2.903218369318435
413.00000000000546,53.76698727472243,-0.08642634807928928,-2.905862281717967
414.1000000000055,53.873662762233565,-0.08571758314222522,-2.908489256082767
415.2000000000055,53.98244131479622,-0.08793367970890698,-2.9113177995018846
416.3000000000055,54.0907416515651,-0.08545183454643568,-2.9156152190651636
417.40000000000555,54.19879815762324,-0.08542674413824436,-2.9194004150663684
418.50000000000557,54.30664857842962,-0.08638501786193697,-2.9216625030980206
419.6000000000056,54.414753689107364,-0.08602671783013638,-2.9229784051456797
420.70000000000556,54.52266730987573,-0.08575501721786183,-2.927410062557322
421.8000000000056,54.62856484467836,-0.08678594121600192,-2.932978775907852
422.9000000000056,54.73852197094232,-0.08613915308207787,-2.9343011917321484
424.0000000000056,54.8467438581326,-0.08511292688689287,-2.9356371289120555
425.10000000000565,54.955418242187704,-0.08506888364263743,-2.938046374909961
426.2000000000057,55.06277438160145,-0.08361219345022008,-2.941022656540054
427.3000000000057,55.16972854512428,-0.0807038391443069,-2.945494836279681
428.40000000000566,55.2790730473177,-0.08345288895454539,-2.946906819296155
429.5000000000057,55.38742240705652,-0.07925007302996612,-2.949659675884276
430.6000000000057,55.4942869399813,-0.07769259767912073,-2.951553035836513
431.70000000000573,55.60346474361531,-0.07564609851504289,-2.954725618710278
432.80000000000575,55.71206024548118,-0.07552904625545875,-2.9575665107496745
433.9000000000058,55.82117041658922,-0.07433175505565526,-2.961344738076894
435.0000000000058,55.92822915713677,-0.07392478552614068,-2.9616724123863234
436.1000000000058,56.03519857272832,-0.07425046703568072,-2.9632103994009125
437.20000000000584,56.144184575919276,-0.07248084790549636,-2.9672088520323463
438.3000000000058,56.253311377303994,-0.07208222546802356,-2.9732900652427805
439.40000000000583,56.36086172597339,-0.06627413502750823,-2.974848867924749
440.50000000000585,56.469413009947154,-0.06574585167791991,-2.977551541952345
441.6000000000059,56.57860009241324,-0.06391160897846038,-2.9788698816287096
442.7000000000059,56.68587658525747,-0.061694295108230435,-2.9801749499242316
443.8000000000059,56.794939667772326,-0.05765777363029967,-2.982540133961197
444.90000000000595,56.90409328619938,-0.057292288013783166,-2.9841476025226727
446.0000000000059,57.01281556390406,-0.05805521908801703,-2.9854499735229107
447.10000000000593,57.12178130843422,-0.05462131329447417,-2.986701003074244
448.20000000000596,57.229035342159946,-0.051263440669359284,-2.9908886508755543
449.300000000006,57.33898694846448,-0.050076432823876305,-2.992522210316248
450.400000000006,57.44793365945259,-0.04808895963198645,-2.9936836261358213
451.500000000006,57.55613158248431,-0.04846103894347209,-2.9978368407843283
452.60000000000605,57.66568433676912,-0.04705295159887957,-3.000491644967596
453.70000000000607,57.773975762277395,-0.04620015259826182,-3.002467842488531
454.8000000000061,57.882708203772495,-0.04617385368221183,-3.003113257196102
455.90000000000606,57.99217003652298,-0.04484524859827599,-3.0074369677341295
457.0000000000061,58.1015052698612,-0.0422779365278918,-3.007405616635667
458.1000000000061,58.20993702417465,-0.044750210022581616,-3.0092125050376852
459.2000000000061,58.319184695704145,-0.04303578167197708,-3.011359836132423
460.30000000000615,58.42721672760009,-0.04162640640662785,-3.013571989096725
461.4000000000062,58.5358535310454,-0.03823659694001069,-3.0139564012579565
462.5000000000062,58.64508159013251,-0.03511706086221,-3.0159453463552097
463.60000000000616,58.751803961529006,-0.03600592177051154,-3.0173172596103983
464.7000000000062,58.86214629977893,-0.036243281155599494,-3.021992529808143
465.8000000000062,58.971073079355776,-0.03352497545301314,-3.0239802900856017
466.90000000000623,59.08008941019899,-0.02960961767602832,-3.0239904182397215
468.00000000000625,59.18616547439797,-0.029407504115190664,-3.0239142312567298
469.1000000000063,59.297185631616784,-0.02642083499501857,-3.02761233145146
470.2000000000063,59.40646095857979,-0.023358713315770663,-3.030201184545559
471.3000000000063,59.515313675443686,-0.022801914099714216,-3.0302845871170883
472.40000000000634,59.6240836010089,-0.01934041021109989,-3.032882344038276
473.5000000000063,59.73287665973502,-0.013653240432524916,-3.032978171269745
474.60000000000633,59.84072935280579,-0.009609543133888954,-3.0363976332596314
475.70000000000636,59.95055669972197,-0.0018721330324407148,-3.0396465545643725
476.8000000000064,60.05954422885161,0.00232713220720826,-3.0402384003643808
477.9000000000064,60.167369461387096,0.00945418800583897,-3.0420238566166313
479.0000000000064,60.27691684653088,0.011057925204973174,-3.0424325681966637
480.10000000000645,60.38643771419033,0.013941899574961392,-3.0437533835299475
481.2000000000064,60.49527749159941,0.01850897678882335,-3.04506874409245
482.30000000000643,60.60444507592388,0.019725025228646498,-3.0477567276993422
483.40000000000646,60.712748267676325,0.01969667504157213,-3.0490138020597457
484.5000000000065,60.822622502872875,0.022426748860402856,-3.049350121935913
485.6000000000065,60.931551787043155,0.02403090395482188,-3.049011698936944
486.7000000000065,61.03936239578684,0.02617634947147418,-3.0516627541917156
487.80000000000655,61.14979764488059,0.025275987810936318,-3.055628068581339
488.90000000000657,61.258427087921156,0.027465741090844986,-3.055600493215183
490.0000000000066,61.36767843754568,0.03236897264370775,-3.0556963658339185
491.10000000000656,61.47777768750158,0.031534796457125314,-3.0571964366511257
492.2000000000066,61.58355304667519,0.03613735655331807,-3.0574362265408697
493.3000000000066,61.696350906002905,0.039883509743685375,-3.0611654764065706
494.4000000000066,61.80481826041766,0.04134161112216428,-3.0613071797470726
495.50000000000665,61.91529887084143,0.041696143938489305,-3.0626833329767025
496.6000000000067,62.0245490460128,0.04446924372796013,-3.065385007490224
497.7000000000067,62.133263352242835,0.04746423317853021,-3.065369152056859
498.80000000000666,62.24326486004558,0.048196623785886405,-3.0666897885735693
499.9000000000067,62.351732492848676,0.04806357386274818,-3.066695943856682
501.0000000000067,62.46231861776751,0.04965583134090168,-3.0693801385502164
502.10000000000673,62.570717930920644,0.050774613736213725,-3.070718716311159
503.20000000000675,62.6808472400686,0.052193665573721626,-3.070495925411977
504.3000000000068,62.79031935588475,0.04988461593955407,-3.072491132615519
505.4000000000068,62.89982352378223,0.04964859360705187,-3.0758338742286253
506.5000000000068,63.0093057182858,0.05117655430630186,-3.074255269157795
507.60000000000684,63.11877246205021,0.05258190355059078,-3.0760118946563093
508.7000000000068,63.22862258087713,0.05274611846745603,-3.0773399240487946
509.80000000000683,63.33863611550079,0.051837401118270066,-3.077677084367393
510.90000000000686,63.44713286356391,0.04866189847414093,-3.081193256779573
512.0000000000068,63.55658824504247,0.04768987345525111,-3.080968608122777
513.100000000007,63.6660231431132,0.04864511993125609,-3.0836217846419935
514.2000000000069,63.77553836347896,0.043447031695457605,-3.087144029689857
515.300000000007,63.88403313655697,0.04238284984257934,-3.0863832062612784
516.4000000000069,63.994239865295924,0.043100983735636866,-3.0864598075103915
517.5000000000069,64.10348556433357,0.041260787754216155,-3.088075284445032
518.600000000007,64.21146660792868,0.041846630630914206,-3.089301975948258
519.700000000007,64.32285177492308,0.033565587975666666,-3.0894200640054104
520.800000000007,64.43162138224201,0.024713628686404254,-3.0894206344124293
521.900000000007,64.54066737732572,0.01957396980098669,-3.0920698539256337
523.000000000007,64.65025748854575,0.015733278302948905,-3.0933738386685063
524.1000000000071,64.76057405211701,0.010432648139709677,-3.0933704285891803
525.2000000000071,64.86892265332442,0.0025648170609531284,-3.0946765987105684
526.300000000007,64.9787862469951,-0.00029280294720956945,-3.096011570614635
527.4000000000071,65.0887567977979,-0.007282185028754107,-3.0960124668685207
528.500000000007,65.19701628764916,-0.012394256936790082,-3.0986398714578605
529.6000000000072,65.30814134104095,-0.019631641950403678,-3.099299463723418
530.7000000000071,65.41843683777857,-0.02624031987549391,-3.099300077585049
531.8000000000072,65.52793189603594,-0.02870947152343839,-3.0986022188208486
532.9000000000071,65.63760568478507,-0.02990062640262825,-3.098640539691052
534.0000000000072,65.74742872198337,-0.03214664204398532,-3.09994991492279
535.1000000000072,65.85510534388459,-0.034950044878728326,-3.101269432476841
536.2000000000072,65.96724198545849,-0.03995783272414455,-3.10417041507998
537.3000000000072,66.07671415283974,-0.043351052097056586,-3.1052315842249563
538.4000000000073,66.18670443777884,-0.04891583073900341,-3.105231094444485
539.5000000000073,66.29685963225748,-0.0525374268225669,-3.1065401034860476
540.6000000000073,66.40660759824911,-0.05729114958441217,-3.106541084299629
541.7000000000073,66.51665525543424,-0.05924419322061514,-3.1078565760034724
542.8000000000073,66.6259989926928,-0.05909641460508319,-3.1091675618278583
543.9000000000074,66.73566651261869,-0.06214246875222451,-3.1104900705134586
545.0000000000074,66.84631319075945,-0.06739064717622179,-3.1131341231580256
546.1000000000074,66.95664463072772,-0.07047100721423893,-3.1131300597099476
547.2000000000073,67.0667493365332,-0.07158223407107611,-3.1144513643417295
548.3000000000073,67.17676594104489,-0.07399717491291424,-3.115046522505601
549.4000000000074,67.28484292554405,-0.07678204031076219,-3.1158718849925533
550.5000000000074,67.39727246868942,-0.08088815291494433,-3.115879498121652
551.6000000000074,67.50656118484733,-0.08060392706508956,-3.117191426387265
552.7000000000074,67.6176399217326,-0.08286096977484969,-3.115879881860085
553.8000000000075,67.72763194897061,-0.08484369831142957,-3.1165381138009467
554.9000000000075,67.83771029150425,-0.08518331420499048,-3.117868254657661
556.0000000000075,67.94616336214284,-0.08711713740499993,-3.1178467784097625
557.1000000000075,68.05864250426393,-0.08747167993260052,-3.1191708164736673
558.2000000000075,68.16980034416906,-0.09252388103096854,-3.12180894220975
559.3000000000076,68.27928949694102,-0.09422001236647715,-3.120424636529739
560.4000000000076,68.39054657148839,-0.09292739815760531,-3.119178086486535
561.5000000000076,68.50089987835733,-0.09478330245026556,-3.1218064333596347
562.6000000000076,68.61123991990861,-0.0976329265439475,-3.123486361160685
563.7000000000077,68.72249161447732,-0.09756038119451316,-3.1271985087715244
564.8000000000077,68.83168146880016,-0.0985887003188759,-3.126953456094781
565.9000000000076,68.94371798546547,-0.09672811596211495,-3.125545687463228
567.0000000000076,69.0544731895324,-0.09983842907367158,-3.125542033675734
568.1000000000076,69.16463892708279,-0.10219704839060961,-3.125538367114891
569.2000000000077,69.27538944338163,-0.10464334097392824,-3.126860687101186
570.3000000000077,69.38600777515111,-0.10371603733594115,-3.12918419465277
571.4000000000077,69.49729888107161,-0.10519756930183966,-3.1307228999582595
572.5000000000077,69.60814150631124,-0.10657883045087124,-3.1291228097000157
573.6000000000078,69.71884770814333,-0.1064835759742162,-3.129130348172694
574.7000000000078,69.8297572918379,-0.10945047217965964,-3.1316904964810925
575.8000000000078,69.94153288064095,-0.10889579667124383,-3.132598972564061
576.9000000000078,70.0517438183741,-0.10826624526976825,-3.1343263815620848
578.0000000000078,70.16250133752061,-0.10892735939660136,-3.1343435754508264
579.1000000000079,70.2733011010062,-0.10936800857536189,-3.1338597306963303
580.2000000000079,70.384051489181,-0.10990906644826359,-3.135127002399342
581.3000000000079,70.49474938485558,-0.11128153203937496,-3.1382707903998432
582.4000000000078,70.60680927047228,-0.11088987868158151,-3.138492640338046
583.5000000000078,70.71793520443144,-0.11442540633424847,-3.138929829178058
584.6000000000079,70.82741231964762,-0.11254120802765755,-3.1382297945101594
585.7000000000079,70.93920131516494,-0.11005870336513968,-3.1389191245436763
586.8000000000079,71.04977365344264,-0.11199437492859166,-3.1386477764984457
587.9000000000079,71.16111099810813,-0.11929600194140844,-3.138270547913821
589.000000000008,71.27075120141613,-0.13104552369694833,-3.1401208837686134
590.100000000008,71.3821496625592,-0.14816707169783716,-3.14085765343533
591.200000000008,71.49253979859456,-0.15712875064457665,-3.1390913571556855
592.300000000008,71.60232241861746,-0.15945424055856527,-3.1415678250663412
593.400000000008,71.71294100800188,-0.15724711169001182,-3.1435501973436106
594.5000000000081,71.82335086397106,-0.15446697987675195,-3.142490822132548
595.6000000000081,71.93457533577535,-0.15087474123768518,-3.142323899803374
596.7000000000081,72.04426278769688,-0.14649034124525917,-3.144856306943482
597.8000000000081,72.15574671706196,-0.1435456451519661,-3.1458244545477507
598.9000000000082,72.2668302934675,-0.14089281825171418,-3.147241826169231
600.0000000000082,72.37723095675183,-0.1373615946764417,-3.148498473771998
601.1000000000081,72.48863418048605,-0.13218638229439184,-3.1461719537055615
602.2000000000081,72.59948563510875,-0.13210915798957568,-3.1475353501719168
603.3000000000081,72.70951653596356,-0.1255771806093402,-3.1481806111631916
604.4000000000082,72.82125171895453,-0.11972930649712321,-3.1474993454464197
605.5000000000082,72.93280880818477,-0.11469543698959384,-3.1487946479152074
606.6000000000082,73.04450292265307,-0.11202038727467745,-3.148764567514261
607.7000000000082,73.155931422293,-0.10688345468688976,-3.151462565928434
608.8000000000083,73.26738049356244,-0.10254461636565426,-3.154074820354015
609.9000000000083,73.37852763064927,-0.09683137578512335,-3.15507018160147
611.0000000000083,73.48968753570833,-0.09267922556020047,-3.1554000470591785
612.1000000000083,73.60145869795723,-0.0814743607770918,-3.1540132205268234
613.2000000000083,73.7118906674486,-0.08092290821556558,-3.1535173588192036
614.3000000000084,73.82298752789816,-0.07580503342931655,-3.1521463058972725
615.4000000000084,73.93480509840617,-0.07179884261616887,-3.151317657676219
616.5000000000084,74.04614883922127,-0.0665273253332277,-3.1567437579442936
617.6000000000083,74.15641909781951,-0.06041530679393925,-3.1580398901890536
618.7000000000083,74.26811103921483,-0.05435438508888124,-3.156853784241911
619.8000000000084,74.37930551676853,-0.04556940404975229,-3.1581074839156336
620.9000000000084,74.4907919336801,-0.04246077013291183,-3.1603157150553214
622.0000000000084,74.60194291541775,-0.03702232854099785,-3.161647409270736
623.1000000000084,74.71436765285014,-0.0292513931707421,-3.1629465294313235
624.2000000000085,74.82512183806057,-0.02459167506487092,-3.1619150183527083
625.3000000000085,74.93436572090926,-0.01650260357532951,-3.16329580132136
626.4000000000085,75.04823723285129,-0.012352431775408013,-3.160450056535037
627.5000000000085,75.15881347506892,-0.007937579055076194,-3.163810472303852
628.6000000000085,75.27063690364336,-0.002947071082423758,-3.165584795128704
629.7000000000086,75.3816635921777,-0.0022225942989271275,-3.1634530101679545
630.8000000000086,75.4940669901693,0.011030322012336446,-3.165500913040556
631.9000000000086,75.60488233976692,0.02783035933664424,-3.169673843174937
633.0000000000086,75.71632094648562,0.05465873895945794,-3.1709886348504224
634.1000000000087,75.82723690606743,0.07604765961146209,-3.171622849884227
635.2000000000087,75.93812072595821,0.08514463255918558,-3.1709898400510306
636.3000000000086,76.05030301929587,0.08549607282616978,-3.173145021299045
637.4000000000086,76.16053469500503,0.08692189832269404,-3.17329012571216
638.5000000000086,76.27216500014954,0.08751967728660626,-3.1732900679982956
639.6000000000087,76.38158089828815,0.08892301498450594,-3.1732935680741337
640.7000000000087,76.49544481703127,0.08952536938354227,-3.1736314441553963
641.8000000000087,76.60651680363803,0.08944124735380954,-3.1749332065369726
642.9000000000087,76.71861247410553,0.08726211648737792,-3.175601323583804
644.0000000000088,76.83029994060396,0.08759667305202123,-3.179552289768215
645.1000000000088,76.94104788780072,0.08756564191754457,-3.1814802160005335
646.2000000000088,77.05226693651876,0.08774562849875678,-3.1821799515951863
647.3000000000088,77.16410326929905,0.08900669615358825,-3.1816184298786094
648.4000000000088,77.27557422916163,0.08710472168684613,-3.1780053718296277
649.5000000000089,77.38665005544398,0.08521058151299665,-3.178040919855391
650.6000000000089,77.4991270446833,0.08465344150934495,-3.1829691062291285
651.7000000000089,77.60918943577535,0.0793805252472386,-3.1821595150775703
652.8000000000088,77.7237753697134,0.08055122981493534,-3.1861940677412477
653.9000000000088,77.83539673214202,0.07693841394745715,-3.1874626900555976
655.0000000000089,77.94744022769802,0.07531726931947502,-3.1868916897670756
656.1000000000089,78.05854592687953,0.07180888556749099,-3.1861577517035964
657.2000000000089,78.17035385044645,0.06941923918607817,-3.1854770018359546
658.3000000000089,78.28177388070468,0.0673590173378269,-3.185584522539078
659.400000000009,78.39335004038934,0.061705970735754345,-3.185408030789108
660.500000000009,78.50585821915578,0.05871545611808138,-3.1898652643683496
661.600000000009,78.61744113577026,0.05119703505096651,-3.1902238635840594
662.700000000009,78.72906357663466,0.04694179705667123,-3.1901995817640403
663.800000000009,78.84156874072131,0.04111786870236167,-3.1901884196679657
664.9000000000091,78.95280052318404,0.03689065186212881,-3.1905357850634273
666.0000000000091,79.06553188790805,0.035946890011339994,-3.1918499039376336
667.1000000000091,79.17740624099216,0.030274826811147015,-3.191849888025126
668.2000000000091,79.28746381328759,0.03252242881306322,-3.1918046137489737
669.3000000000092,79.40091099859958,0.029582502974135005,-3.1941501037497377
670.4000000000092,79.5122992066473,0.03223140201850061,-3.1928405175487815
671.5000000000091,79.6241922599713,0.03320681765517186,-3.1930223054190146
672.6000000000091,79.73610340915302,0.03359338666410272,-3.1918638906177015
673.7000000000091,79.84720282960616,0.03164004030641965,-3.1945138160239415
674.8000000000092,79.95949382150295,0.030756580056653382,-3.1957910641141347
675.9000000000092,80.07181093740444,0.03163973782502927,-3.196121942069116
677.0000000000092,80.18391782552567,0.034527730978467286,-3.194506397729943
678.1000000000092,80.29535959104479,0.034117012514621514,-3.1944761742951044
679.2000000000093,80.40728089100318,0.0356853583635528,-3.1961298698235905
680.3000000000093,80.51977147393599,0.033923914098800356,-3.1948143640985447
681.4000000000093,80.632065303093,0.032519178951994965,-3.1977773876291105
682.5000000000093,80.74333069796636,0.03537998824828015,-3.1996840740530783
683.6000000000093,80.85643088913211,0.03682981476840741,-3.1974868954265063
684.7000000000094,80.9680277870287,0.03504944264300147,-3.1980018605828766
685.8000000000094,81.07955204429177,0.035432591699243066,-3.196306594374299
686.9000000000094,81.1926991462602,0.032439971235867615,-3.1980790966045465
688.0000000000093,81.30460834707766,0.034128723210133716,-3.199271089200174
689.1000000000093,81.41790080969675,0.036433054042136925,-3.2026396276133853
690.2000000000094,81.52778056730544,0.039827381109034166,-3.2053262092077084
691.3000000000094,81.64052546021657,0.04089081940707717,-3.2013939573188375
692.4000000000094,81.75190642849437,0.041913762023970236,-3.20133998079062
693.5000000000094,81.86388468953042,0.04504136432422445,-3.2020627073096
694.6000000000095,81.97697759930844,0.0481363087538913,-3.200516995097292
695.7000000000095,82.089177402728,0.04854803136099228,-3.2005200311865614
696.8000000000095,82.20165446133245,0.047834040739734185,-3.203253861425184
697.9000000000095,82.31421904287926,0.05271306236005113,-3.204470043525819
699.0000000000095,82.42371181726955,0.05255822816299993,-3.2035394014681646
700.1000000000096,82.5386390046183,0.05211526766353192,-3.204478485935006
701.2000000000096,82.65137012647826,0.05785574653825454,-3.2031598737365066
702.3000000000096,82.76324347769443,0.05739014740397885,-3.2018373426311695
703.4000000000096,82.8745201668053,0.05703918940719199,-3.203341052626696
704.5000000000097,82.98701364631175,0.05922041687897117,-3.2077753967748883
705.6000000000097,83.09960583719905,0.0640514998266597,-3.2067498213397108
706.7000000000096,83.21168074539783,0.0670094609265468,-3.2035894305934662
707.8000000000096,83.32340990270251,0.06866403815795685,-3.204227251032863
708.9000000000096,83.43631253802609,0.07327720630062462,-3.2019501477922505
710.0000000000097,83.54746874807716,0.07148625725576663,-3.205887990161044
711.1000000000097,83.66139579930524,0.06976652948836093,-3.210028338512224
712.2000000000097,83.7734510402441,0.07283809357531923,-3.2130146239014272
713.3000000000097,83.88592867693598,0.07750170946176249,-3.2117589218356093
714.4000000000098,83.99822409833811,0.0782208710367267,-3.207534310663715
715.5000000000098,84.1095736332312,0.08473120580961191,-3.2074262682179095
716.6000000000098,84.22245923836893,0.08643653521451755,-3.2084547267486947
717.7000000000098,84.33467114417093,0.09079245516311762,-3.20864855018371
718.8000000000098,84.44833101240972,0.08917223534744356,-3.209030116565254
719.9000000000099,84.56071278608755,0.09439416665688638,-3.2114321831095376
721.0000000000099,84.67303140197524,0.10002378715734395,-3.2109765085298365
722.1000000000099,84.78616483875084,0.09783935854463177,-3.2122657475856826
723.2000000000098,84.89865776517739,0.10101187794725996,-3.2140237831492993
724.3000000000098,85.01078269134192,0.10604167613999405,-3.212761979287694
725.4000000000099,85.12376565830695,0.10929459496208804,-3.211594258609887
726.5000000000099,85.2357107145021,0.1092415668652491,-3.2142390334143762
727.6000000000099,85.34874205375357,0.1121806342131686,-3.214062346379108
728.7000000000099,85.46217723783086,0.11414241540653203,-3.2142421037619235
729.80000000001,85.57384263155345,0.11817986521981982,-3.214129611993961
730.90000000001,85.68645572832786,0.12088908739991933,-3.2154498183669427
732.00000000001,85.79962815548375,0.12311670784648676,-3.2147818588913317
733.10000000001,85.91153057776987,0.126268059536216,-3.2141401620083276
734.20000000001,86.02468158325127,0.13128241945594832,-3.214084962045053
735.3000000000101,86.13722602440727,0.1319528710325888,-3.2157799410391164
736.4000000000101,86.24944159114365,0.13299609538025425,-3.2144600281311906
737.5000000000101,86.36097885585585,0.13361050821434262,-3.2157798110201656
738.6000000000101,86.47363623831234,0.13623813552657627,-3.2167776466724423
739.7000000000102,86.58733732237096,0.14092562990991375,-3.2193999972870926
740.8000000000102,86.69924653361436,0.14337681604027486,-3.2187400505063355
741.9000000000101,86.81127697476559,0.14666505193106927,-3.217372557951985
743.0000000000101,86.92366328170047,0.1524021715951509,-3.216828454206068
744.1000000000101,87.03665898018178,0.15017087661814577,-3.218576048093155
745.2000000000102,87.14823247576436,0.15083449980681518,-3.2181998237718914
746.0000000000102,87.23132528988462,0.1540383629424995,-3.218427784536575