File: 01_Data/Polyester_Carpet_Medium_Pile/STA/N2/10K_min/Polyester_Carpet_Medium_Pile_STA_N2_10KData_211216_R3.csv
##Temp./Â°C,Time/min,DSC/(mW/mg),Mass loss/mg
50.0,10.733841684920373,0.023672809381689364,-0.04232844724583407
51.100000000000016,11.044499230226409,0.06448578441042596,-0.04186264481782276
52.20000000000003,11.253328198450793,0.09540848303128235,-0.041942313319704994
53.30000000000005,11.431410612802436,0.11786450288091199,-0.041729347523544735
54.40000000000006,11.591127592859989,0.13695029783885848,-0.040601930707649725
55.50000000000008,11.737498546109139,0.14990068995851336,-0.04205853127475523
56.600000000000094,11.879521078713022,0.16179773987455603,-0.04258861775974099
57.70000000000011,12.012806679464651,0.16978937933176586,-0.0413966557310701
58.800000000000125,12.14256628232081,0.18058204013802548,-0.041926444545322905
59.90000000000014,12.27021925375246,0.18688134016883395,-0.043662543676382004
61.000000000000156,12.3947361814022,0.19276207055528538,-0.04367079485378467
62.10000000000017,12.519070596819436,0.19745582404532558,-0.04266143722105209
63.20000000000019,12.64103803452729,0.2027281043309211,-0.042433486705739654
64.30000000000021,12.761812439992342,0.2063887728622718,-0.043643662286777296
65.40000000000022,12.881656323009938,0.20928565437807795,-0.042206608892623176
66.50000000000023,13.00176019482177,0.21278476588915002,-0.04357615150934313
67.60000000000025,13.119797918543881,0.21682243677659274,-0.04467592588369129
68.70000000000027,13.238516741124766,0.22221907565715787,-0.04401143987266565
69.80000000000028,13.35639211404688,0.22319981219671764,-0.04344288545910757
70.90000000000029,13.473279775126256,0.2222291331874407,-0.04391184829198691
72.00000000000031,13.589802878092414,0.2209375868245722,-0.04508103654741813
73.10000000000034,13.706214579877471,0.22241246413109195,-0.04488761090550808
74.20000000000034,13.8238741522166,0.22295294736574817,-0.044863108299590504
75.30000000000035,13.936881046992548,0.2215414956155572,-0.04749034585657297
76.40000000000038,14.050677302841008,0.22019824720077025,-0.04617089253786766
77.5000000000004,14.16855977606203,0.2201297091493879,-0.04748299536834866
78.6000000000004,14.282027359984756,0.22181436720515607,-0.0481501830144726
79.70000000000041,14.396011408221987,0.22235122559374054,-0.04879677989233855
80.80000000000044,14.509330183128355,0.2225377788899816,-0.04751039596609408
81.90000000000046,14.621632202812915,0.22015326962614123,-0.047490863202812594
83.00000000000047,14.736773894516286,0.22170034661158294,-0.04743531627474784
84.10000000000048,14.848506777272725,0.22234647753493603,-0.04880531767393714
85.2000000000005,14.961116938323107,0.2187811928746894,-0.050094382159135975
86.30000000000052,15.072512138769659,0.21945788162623958,-0.048642786434450525
87.40000000000053,15.183607215694577,0.2207871182959088,-0.04879967867094814
88.50000000000054,15.294235490526173,0.22167686553276328,-0.051440639461908244
89.60000000000056,15.40468249460682,0.22295345061233246,-0.05139451770251613
90.70000000000059,15.515603775392695,0.22302351085703453,-0.052734492235828156
91.8000000000006,15.626086691480884,0.22414943454669134,-0.05143981119653551
92.9000000000006,15.731393411252181,0.22475189604066398,-0.052760195571539104
94.00000000000063,15.846072031620112,0.22516432479395815,-0.05245128891920681
95.10000000000065,15.954943367424267,0.22765852293073496,-0.05293276225965693
96.20000000000066,16.06362155356595,0.22922564427120257,-0.053070773961466866
97.30000000000067,16.17389077645108,0.23212790973214903,-0.052760092494997135
98.40000000000069,16.282815677622605,0.23300215054235573,-0.05404463003630866
99.50000000000071,16.391536205862064,0.23353580262495388,-0.05341203224178104
100.60000000000072,16.500379208233237,0.23756144600789914,-0.05342027618515921
101.70000000000073,16.60852296175036,0.23837636635052395,-0.05406997295309646
102.80000000000075,16.71705004618716,0.24032968284535805,-0.05539037881000519
103.90000000000077,16.82494750989589,0.24102492377739704,-0.05636283911808748
105.00000000000078,16.93281451828709,0.24451474531372533,-0.05505894671542633
106.10000000000079,17.041084347331594,0.24701603439217018,-0.05451272619557068
107.20000000000081,17.1489326308091,0.2473604054487948,-0.055389936013922725
108.30000000000084,17.255095168643958,0.25158950785227585,-0.056830649247396
109.40000000000084,17.36468275908374,0.2532416343272254,-0.05539009985849974
110.50000000000085,17.47450344746901,0.2527326776677702,-0.05656970500939007
111.60000000000088,17.581459823576413,0.25675743184511257,-0.05670009969659384
112.7000000000009,17.688280305913977,0.25807765365961,-0.05801707354553143
113.8000000000009,17.797166035638607,0.2599751612715798,-0.05669980572443345
114.90000000000092,17.905119758192185,0.2602285989290777,-0.05801627271228371
116.00000000000094,18.013846973874596,0.26328392261063605,-0.058019938497796186
117.10000000000096,18.119533948794682,0.26591149219110555,-0.05670923437622699
118.20000000000097,18.227266781150835,0.26583083628746296,-0.05691300014790679
119.30000000000098,18.336744847881242,0.2668792626138995,-0.05749747965873109
120.400000000001,18.44302313187873,0.26883025156851037,-0.05769018003996296
121.50000000000102,18.55079941980954,0.2702556818892063,-0.057690133269136634
122.60000000000103,18.657009895197593,0.2685451559553841,-0.05668148063893286
123.70000000000104,18.765193417592982,0.2729208598077703,-0.058030052208590366
124.80000000000106,18.873520073151724,0.2742851184362277,-0.05843581782929208
125.90000000000109,18.981187028664753,0.2776794787269615,-0.060319545066653824
127.0000000000011,19.087600939299023,0.2787295853520789,-0.0615623763061266
128.1000000000011,19.194722455801298,0.27946627345224784,-0.06023310864815734
129.20000000000113,19.300712193387756,0.2816055113211491,-0.05966984057732061
130.30000000000115,19.40925249040592,0.28147411680122736,-0.06098950683468951
131.40000000000117,19.51545928058664,0.2823516687047379,-0.06148379450073005
132.50000000000117,19.622006545241742,0.2824509311773744,-0.060650140440831724
133.6000000000012,19.729896839591838,0.28591407686281656,-0.059659938962494774
134.7000000000012,19.836537545947902,0.2882158261623932,-0.06107927108010136
135.8000000000012,19.941899639171993,0.2883402485817862,-0.061309997845886866
136.90000000000123,20.050000916104366,0.28869107847273423,-0.06130988402368853
138.00000000000125,20.15616581242322,0.29011674895401174,-0.06229831772033867
139.10000000000127,20.261988419038445,0.29237896162123467,-0.06229987053025132
140.2000000000013,20.365748544685395,0.2926766562196347,-0.06146169098729404
141.3000000000013,20.475076580742773,0.29406675985545017,-0.06133282221887937
142.4000000000013,20.58234949993156,0.29507699004438187,-0.06262940275694673
143.50000000000134,20.687541566980517,0.29487223453746875,-0.062299863724227134
144.60000000000133,20.794797531512984,0.2975495000400311,-0.06230010071213066
145.70000000000135,20.90066856720705,0.2978937944805281,-0.06262540135617956
146.80000000000138,21.007963729287425,0.30151275948321815,-0.06525980871683812
147.9000000000014,21.110650464737688,0.3030033584854691,-0.06393942333087343
149.00000000000142,21.21879578658773,0.3069626660282533,-0.06657983289775915
150.10000000000142,21.325030690999526,0.30607507697615927,-0.06527487510369356
151.20000000000144,21.431447169830218,0.3112543021013537,-0.06459942308131073
152.30000000000146,21.53815590544766,0.3129332234316736,-0.06328084022997249
153.40000000000146,21.64409073986207,0.3154788534470287,-0.06459994542404202
154.50000000000148,21.749602404788465,0.3200647978062746,-0.06459994996715235
155.6000000000015,21.855998535487544,0.3251442921196393,-0.0646097362652589
156.70000000000152,21.961649162853487,0.33111107886303504,-0.06558734142296485
157.80000000000155,22.068878626623754,0.33334682229868223,-0.06591106004892566
158.90000000000154,22.17298403570317,0.34065978202126507,-0.06624932503651904
160.00000000000156,22.2799032734413,0.34627240473562926,-0.06625003899745918
161.1000000000016,22.3845613661366,0.3529097703992067,-0.06591994353550623
162.20000000000158,22.49027091594882,0.3596126331194586,-0.06698959013906247
163.3000000000016,22.595080395404487,0.3652575389381991,-0.0669099395723749
164.40000000000163,22.702397468071016,0.3726020293648078,-0.06611371694296908
165.50000000000165,22.807944928706704,0.375234775782212,-0.06627762306233942
166.60000000000167,22.913112928736243,0.3748187633469101,-0.06739000469443379
167.70000000000167,23.02039213294017,0.37400040712566024,-0.06756012013533175
168.8000000000017,23.125638359877456,0.3672115004385116,-0.06756011999999023
169.9000000000017,23.230453898187744,0.35680120245384883,-0.06756012147213442
171.0000000000017,23.337239543780964,0.34555573962264385,-0.06722844136732942
172.10000000000173,23.4423220460469,0.3406640932309619,-0.0672285945155795
173.20000000000175,23.54737634725628,0.3343815625055774,-0.06592041456783093
174.30000000000177,23.653996568735963,0.33397249684917807,-0.06724026511856618
175.4000000000018,23.759465299569225,0.3315904805916107,-0.06724127520334555
176.5000000000018,23.86538428905347,0.3335208561358131,-0.06856017513605783
177.6000000000018,23.970707897976038,0.33472075860144823,-0.0685601699999685
178.70000000000184,24.075557621230615,0.33509514714109456,-0.06856016997943026
179.80000000000183,24.182008981454278,0.33612669757662805,-0.06857454472332503
180.90000000000185,24.288375040637675,0.3355973027647932,-0.06855226534835612
182.00000000000188,24.392660234425676,0.337723454783346,-0.06855002002154365
183.1000000000019,24.495092041640454,0.33814080848975375,-0.06858042073128123
184.20000000000192,24.60345353023297,0.3391338302200959,-0.06992365824050895
185.30000000000192,24.70785809376008,0.3389411625714114,-0.0688584835281949
186.40000000000194,24.814315366841914,0.3419278305912271,-0.06907565952682715
187.50000000000196,24.921118998318445,0.34048290253864555,-0.06855445829103379
188.60000000000196,25.02422500296597,0.3417439421764469,-0.06986993883007964
189.70000000000198,25.129650398400276,0.3423626154894561,-0.06987001989704966
190.800000000002,25.234702605497212,0.3421774688368501,-0.06914120461489004
191.90000000000202,25.340959339501122,0.34616420270638215,-0.06923098071040323
193.00000000000205,25.446056490357073,0.34577649282349815,-0.070520132406374
194.10000000000204,25.551007426379222,0.3461687061108231,-0.06986913064401667
195.20000000000206,25.656004900635,0.3456080519392322,-0.06854986337367253
196.3000000000021,25.76134754282363,0.34775196183534446,-0.06854993948952304
197.40000000000208,25.867720674031652,0.34475784193734677,-0.06986977181748433
198.5000000000021,25.97226244014257,0.3510123046900665,-0.07041057789467065
199.60000000000213,26.077804280143877,0.3496456451438235,-0.07117981529039552
200.70000000000215,26.183576180654242,0.35274902510435924,-0.06987122374358412
201.80000000000217,26.287938440385265,0.3545304975988215,-0.07118954257959853
202.90000000000217,26.39469060902292,0.3537023127855708,-0.07119709644412353
204.0000000000022,26.49980768038992,0.35595242853771614,-0.069870101089061
205.1000000000022,26.604813939050185,0.35982510783190175,-0.07059414870568936
206.2000000000022,26.710500478485024,0.36093911616190855,-0.0705175581165669
207.30000000000223,26.815343095192176,0.3636334002921678,-0.07141297936147106
208.40000000000225,26.921672857191957,0.3655066599948133,-0.0718498614538623
209.50000000000227,27.02617506037636,0.367130029433948,-0.07316930211104822
210.6000000000023,27.13090491698718,0.36878595101779765,-0.0731598600682779
211.7000000000023,27.237315402318416,0.37274061177406126,-0.07185666343658692
212.8000000000023,27.341929320560116,0.3759650742646205,-0.07184009998857332
213.90000000000234,27.447495307610694,0.3790500442772554,-0.07184009999816876
215.00000000000233,27.552513483400826,0.38084155961971505,-0.07184190056928408
216.10000000000235,27.65900797391154,0.3836061963430196,-0.07051996428144092
217.20000000000238,27.762451981697794,0.3859070055248178,-0.07051666898205644
218.3000000000024,27.86801631500825,0.39058424595578395,-0.07246430298879591
219.40000000000242,27.973397397495475,0.39088125548117814,-0.07250016013523997
220.50000000000242,28.079286912209934,0.39569758341320427,-0.07250015999999926
221.60000000000244,28.184136537217235,0.39748198604483653,-0.0725001600134596
222.70000000000246,28.28898400245575,0.3980805822996563,-0.07250422966563574
223.80000000000246,28.3951193508708,0.40212844530362707,-0.07414980849081632
224.90000000000248,28.499591924414815,0.4040038755088663,-0.07449288582758617
226.0000000000025,28.604838975196085,0.40526897457534744,-0.07447628371723125
227.10000000000252,28.709712010324573,0.40576902977220997,-0.07447050756833251
228.20000000000255,28.815076542721183,0.40896469689129994,-0.07309281440865734
229.30000000000254,28.919909476379125,0.41028971946037573,-0.07281994515816503
230.40000000000256,29.025093272877054,0.4112896601339849,-0.07445697387464456
231.5000000000026,29.130693101077824,0.41543584183243043,-0.07512922535411981
232.60000000000258,29.23529015973706,0.41953306450535727,-0.07413986484660207
233.7000000000026,29.340862495254736,0.4220480569609217,-0.075161704565057
234.80000000000263,29.44342097803405,0.42959192029136745,-0.0751330849913785
235.90000000000265,29.55095347783532,0.4344922093077389,-0.07376270349143699
237.00000000000267,29.656648732304053,0.4462457121513356,-0.07564200403502941
238.10000000000267,29.760883281612713,0.4544433507601285,-0.07579010004028763
239.2000000000027,29.867184624749736,0.4664474103030852,-0.07579009960685079
240.3000000000027,29.97235391371469,0.4819595686374256,-0.0771158279927926
241.4000000000027,30.077939675746137,0.5061723895935893,-0.07579018113519664
242.50000000000273,30.183901744642935,0.5362802467325183,-0.07678009389870066
243.60000000000275,30.289313655815945,0.5746635834567007,-0.07678010005375002
244.70000000000277,30.39442004685199,0.6276797437051935,-0.07635811852453989
245.8000000000028,30.50124207218854,0.6993540704588421,-0.07579028878337235
246.9000000000028,30.605967299156934,0.7790686431357929,-0.07711781385222638
248.0000000000028,30.71263979759658,0.838074326432411,-0.07711010005892938
249.10000000000284,30.818497807796547,0.8451384734073382,-0.07662440797823322
250.20000000000283,30.925265683629416,0.7913467184909403,-0.07710979103899795
251.30000000000285,31.030666672477896,0.7040063850553219,-0.07671514639592836
252.40000000000288,31.13545009603056,0.6147006551316329,-0.07738185328440661
253.5000000000029,31.240480788543138,0.5420798275115193,-0.0757675533882769
254.60000000000292,31.3447405390303,0.4974637792901264,-0.07579031331241204
255.70000000000292,31.450544149006397,0.46776729913134507,-0.07842009665656091
256.8000000000029,31.55495660590365,0.4479938144399491,-0.0792614177845623
257.90000000000293,31.661147652372506,0.43454113138104705,-0.07838474326923084
259.00000000000296,31.765073530781507,0.42623165595480184,-0.07972443019869857
260.100000000003,31.86989682382396,0.4172184874147336,-0.07842009905145453
261.200000000003,31.975240220126285,0.4115125335115909,-0.07852348011283672
262.300000000003,32.08009013569455,0.41122871388749277,-0.07940991997830205
263.40000000000305,32.18546833628336,0.4101547159183963,-0.07940992000000024
264.50000000000307,32.28848561106832,0.4091786338467805,-0.07940991999690272
265.6000000000031,32.394910353405486,0.40918433371183704,-0.07941134280223938
266.7000000000031,32.49961592233304,0.40709207858066576,-0.08040007104838898
267.8000000000031,32.60489228101791,0.41039943691981723,-0.08006998896935169
268.9000000000031,32.71152183826756,0.4083068086031374,-0.0797398601599193
270.0000000000031,32.81603328660074,0.4066682333563757,-0.07973985999999966
271.10000000000315,32.92102939064386,0.4103735182735166,-0.07973985999151623
272.2000000000032,33.025875836495594,0.41084213384255586,-0.07975346575220943
273.30000000000314,33.13134069276197,0.4119705718090564,-0.07974375124039002
274.40000000000316,33.23580715674982,0.41156218696939106,-0.08138862101859567
275.5000000000032,33.34235022911474,0.4124898343578758,-0.08204376186297901
276.6000000000032,33.447710161518145,0.4149666668341099,-0.08236986850409389
277.70000000000323,33.55351343220976,0.4171575426415174,-0.08236987000000351
278.80000000000325,33.65835347228125,0.41498913826435313,-0.08236986999999996
279.9000000000033,33.762987056242295,0.4142393653819713,-0.08236987000007012
281.0000000000033,33.870197813890535,0.41751534581535366,-0.08236986349747077
282.1000000000033,33.97472832757147,0.4157485149173745,-0.0836561242736149
283.20000000000334,34.0803698689322,0.4214226926063658,-0.0850118859669644
284.30000000000337,34.1866349392316,0.4204339591686256,-0.08502538287598682
285.40000000000333,34.29255279067874,0.42387774296766906,-0.08374830725691496
286.50000000000335,34.39722204253608,0.4228586253594526,-0.08339859518263548
287.6000000000034,34.503429811202246,0.4233919827879004,-0.08621017806065234
288.7000000000034,34.60903136610374,0.4261246538510502,-0.08617750339622932
289.8000000000034,34.715606772298,0.4260589938955982,-0.08390997390810906
290.9000000000034,34.82029613640992,0.4280669333052899,-0.0839099800000147
292.0000000000034,34.92591426969885,0.42688937114380565,-0.08391012325091651
293.10000000000343,35.03284720271097,0.43304757039590236,-0.08523011216164367
294.20000000000346,35.13701333733224,0.4326871159465482,-0.08654087158156809
295.3000000000035,35.243376324839296,0.43484955717606855,-0.08644393323295407
296.4000000000035,35.34898849034258,0.43743334343105406,-0.08719980977483655
297.5000000000035,35.45503553583525,0.43532486225143624,-0.08719980998121102
298.60000000000355,35.561695002941505,0.4379036883298121,-0.08608062414956841
299.70000000000357,35.66473999055485,0.43663713254945025,-0.08830344668443812
300.8000000000036,35.772409418898114,0.4379923530013279,-0.088519960910177
301.9000000000036,35.87776011895562,0.4392261374630946,-0.08851996017447661
303.0000000000036,35.98181506149838,0.43813185976298563,-0.08835803195186998
304.1000000000036,36.088789823301845,0.43927321482458337,-0.08752337946420585
305.2000000000036,36.19554078289167,0.44312871512337215,-0.09105789794443453
306.30000000000365,36.299619614428735,0.44551310354808854,-0.09016008617688209
307.4000000000037,36.40723829457324,0.4416695810246874,-0.09213140479598891
308.5000000000037,36.5126329714532,0.4425173372073057,-0.09148012170236441
309.60000000000366,36.6185855285678,0.444254707397413,-0.0914800616240834
310.7000000000037,36.72438035625757,0.4473650671436452,-0.09016350167673659
311.8000000000037,36.831298303968055,0.44970871458466544,-0.09157799950995082
312.90000000000373,36.93681480284675,0.4484429043393865,-0.09411486938501268
314.00000000000375,37.042614666231515,0.44857688436167104,-0.0941098193956349
315.1000000000038,37.149196292937255,0.45441364940770135,-0.09298798021371502
316.2000000000038,37.254889944048855,0.45398565451352396,-0.09279982000967912
317.3000000000038,37.36136774658966,0.4543690839424478,-0.09279981996917819
318.40000000000384,37.4667480605135,0.4579091545909806,-0.09384950384556845
319.5000000000038,37.57318231719529,0.4590479626915124,-0.09503738764469327
320.60000000000383,37.6803974634542,0.4595270048345861,-0.09783512945340478
321.70000000000385,37.786156136444355,0.4603204820039886,-0.09709286085366431
322.8000000000039,37.89371251578662,0.4634522175018505,-0.09544654973437838
323.9000000000039,37.99927793499063,0.46467933730013133,-0.09635676311392416
325.0000000000039,38.10673595104913,0.4649939262715694,-0.09773011644483276
326.10000000000394,38.213059526870516,0.46895752066376384,-0.09790155575587356
327.2000000000039,38.319458202991335,0.4713044445721336,-0.09903991213625396
328.30000000000393,38.42569181650784,0.4710571086885976,-0.09937975500639418
329.40000000000396,38.53111938678057,0.4715716778936243,-0.10069285366049918
330.500000000004,38.63757839540316,0.47255609618874006,-0.10198960154931269
331.600000000004,38.744660691777376,0.4707664640258631,-0.10163953735194875
332.700000000004,38.851161126995514,0.47233284873748804,-0.10201450999606188
333.80000000000405,38.95768359479377,0.47264615457915893,-0.10328852930330745
334.90000000000407,39.06379743382311,0.47431423888405494,-0.1047031300054071
336.0000000000041,39.17083891595768,0.47526840700957906,-0.10464035292127738
337.10000000000406,39.27702636217328,0.4725089124762141,-0.10594983135020053
338.2000000000041,39.38294694564155,0.4752521615420865,-0.10598017840774254
339.3000000000041,39.489728361839234,0.4741950367809503,-0.10858256242894182
340.4000000000041,39.59646108762428,0.4749199535193044,-0.1085536566747125
341.50000000000415,39.70321836910796,0.473419327402393,-0.10859014199938422
342.6000000000042,39.8068152913549,0.473309964725526,-0.11123005036818423
343.7000000000042,39.915121166552716,0.47244929446295947,-0.1125297458882657
344.80000000000416,40.02261366288137,0.4735332709782578,-0.11385104525672185
345.9000000000042,40.128522915189855,0.4743056400717995,-0.11516946182244947
347.0000000000042,40.23576890492469,0.4730400857697805,-0.11647905623390509
348.10000000000423,40.34294701028961,0.47207067050432927,-0.11780010384482198
349.20000000000425,40.449729173542764,0.4704581332727535,-0.11911955574750666
350.3000000000043,40.555754937636465,0.4730305415498567,-0.12177533700673804
351.4000000000043,40.66261017703324,0.472242868519728,-0.12174800656171625
352.5000000000043,40.77079002258802,0.4689596729487764,-0.12306290402521514
353.60000000000434,40.8777530260618,0.4738379609163509,-0.12434891706010287
354.7000000000043,40.984784216005465,0.4731547934328026,-0.12837498296627015
355.80000000000433,41.09255457242851,0.4737656792134011,-0.13080347427047245
356.90000000000435,41.198337849710676,0.4710124753890205,-0.1322807996604669
358.0000000000044,41.30592546506473,0.4730577913540009,-0.13369604457674766
359.1000000000044,41.41303485806336,0.47281865045580695,-0.13762882463746218
360.2000000000044,41.520407652890235,0.47418890050579665,-0.13755064968280273
361.30000000000445,41.62744177487337,0.4730109175632553,-0.14127021799841888
362.4000000000044,41.73407702670225,0.4724089670567692,-0.14523004429780473
363.50000000000443,41.8410365836084,0.473407414035393,-0.14743771847699128
364.60000000000446,41.947959401091374,0.4752001353168077,-0.1502443108246565
365.7000000000045,42.0556166520408,0.47789138540160575,-0.15380792796581
366.8000000000045,42.162264251352305,0.4772368030816238,-0.15705441681934618
367.9000000000045,42.269901870947294,0.47952390177345927,-0.16101920849019624
369.00000000000455,42.37585646769657,0.4799709794594878,-0.16485670065889746
370.10000000000457,42.482028247551035,0.483708752229497,-0.169405815197321
371.2000000000046,42.589901277886284,0.48592319495159386,-0.1721897213065331
372.30000000000456,42.697440950345744,0.4889501178391339,-0.17731169607968233
373.4000000000046,42.80423468740674,0.4896394558123814,-0.18100809511663796
374.5000000000046,42.91278966294742,0.4909430320110981,-0.18594365751780684
375.6000000000046,43.01848312174199,0.49102444897153086,-0.19044021856023763
376.70000000000465,43.12588702906146,0.4957074839517192,-0.19622420980008437
377.8000000000047,43.232569399712034,0.49630149454051387,-0.2008241136061324
378.9000000000047,43.34080317856381,0.4982047930716515,-0.20573998453671827
380.00000000000466,43.44727019849492,0.49891083001933667,-0.21028930681484193
381.1000000000047,43.55469565440838,0.503827127152881,-0.2181425115850537
382.2000000000047,43.66212432309251,0.5052592607748358,-0.2279116495349962
383.30000000000473,43.76878394508223,0.509034392419978,-0.23414009833116367
384.40000000000475,43.87732112192066,0.5121502274563043,-0.24031359535392438
385.5000000000048,43.98333866975244,0.5116537141950646,-0.2467284357798465
386.6000000000048,44.091118131146175,0.5150348105814603,-0.2534066868002953
387.7000000000048,44.198780210510265,0.5184167125163127,-0.2641755652459641
388.80000000000484,44.30494074524323,0.5188370024618559,-0.27142872745766056
389.9000000000048,44.41258028344449,0.5252594409937836,-0.2799125186875133
391.00000000000483,44.51944319607056,0.5250269063290116,-0.2869926748381886
392.10000000000485,44.627238619276724,0.5313301983766334,-0.2991038319288237
393.2000000000049,44.73431142213047,0.5315629107279274,-0.3062349283716945
394.3000000000049,44.841140805871916,0.5371320801934748,-0.3192865394694935
395.4000000000049,44.94871065414543,0.5395131744951094,-0.32994064757402963
396.50000000000495,45.05654304675477,0.5439347131043584,-0.3406375531204411
397.6000000000049,45.16260706643817,0.5462059705249812,-0.36464235388277677
398.70000000000493,45.26910593883547,0.5511870056955838,-0.37101972420109197
399.80000000000496,45.37698035204079,0.5539296121539989,-0.379011701260195
400.900000000005,45.48591687373694,0.5607591895617321,-0.38855772657393395
402.000000000005,45.59315496338013,0.5620626762690247,-0.40047088581720836
403.100000000005,45.70008494304788,0.5676185512932743,-0.41000484697961914
404.20000000000505,45.8081068348777,0.5723634759995708,-0.4232718832052922
405.30000000000507,45.91240412312142,0.5762486621623892,-0.4422317533655602
406.4000000000051,46.02241441048445,0.5830181022594528,-0.4598096232214819
407.50000000000506,46.1298882923708,0.5915860508359227,-0.4770047171571292
408.6000000000051,46.2377140764293,0.5968107269500251,-0.4922577133054169
409.7000000000051,46.345581989299,0.6065590539792739,-0.5119743267801331
410.8000000000051,46.452752228126045,0.6149524651504907,-0.5317323682943416
411.90000000000515,46.559392926827314,0.6238326458894611,-0.5508588029946306
413.0000000000052,46.66747019384178,0.6313265925779792,-0.57136230118779
414.1000000000052,46.77626925473563,0.6367008908197028,-0.5902592201266552
415.20000000000516,46.88221301559075,0.6427880690311292,-0.6101801006740368
416.3000000000052,46.98942122834202,0.6492876535935601,-0.6313340013742521
417.4000000000052,47.097684344495896,0.6543078104056597,-0.6542883150886425
418.50000000000523,47.2053220536744,0.6578597258231491,-0.6732109751917554
419.60000000000525,47.31248010628463,0.6616370926239372,-0.7015729831201445
420.7000000000053,47.42081280588911,0.6678348817603004,-0.7316771125611718
421.8000000000053,47.527462947787626,0.671880744634315,-0.7612965724584493
422.9000000000053,47.634802221806545,0.6782153827193736,-0.7898490415583526
424.00000000000534,47.74289580592694,0.6822544212166122,-0.8187587670300118
425.1000000000053,47.850607721696484,0.6887055401737634,-0.8466220706594334
426.20000000000533,47.95864783642624,0.692753477780292,-0.8807671691077799
427.30000000000535,48.06729911604973,0.698425248704321,-0.915386882199066
428.4000000000054,48.17494046727138,0.7079992059622016,-0.9466524138087489
429.5000000000054,48.2827608428021,0.7134283217360924,-0.9786916802757903
430.6000000000054,48.39133002144831,0.7208339004339719,-1.0143643261607993
431.70000000000545,48.49935018168132,0.7223653281150679,-1.050226682820036
432.8000000000054,48.60725306530777,0.730305947910975,-1.085862086350264
433.90000000000543,48.71551179825539,0.730919236767559,-1.122792802934843
435.00000000000546,48.822940052926434,0.7316207504906791,-1.1606228781773367
436.1000000000055,48.93222684312861,0.7368005398828874,-1.1985942339792923
437.2000000000055,49.03980495539409,0.7341236433904521,-1.2373117137571739
438.3000000000055,49.14716710655298,0.7304740924069053,-1.277728736580484
439.40000000000555,49.255122399498624,0.7284616185518076,-1.3169475561076447
440.50000000000557,49.362913596607044,0.7245614270758796,-1.3556091745209744
441.6000000000056,49.471222139487175,0.7173413667785038,-1.3944174277263262
442.70000000000556,49.579187008190836,0.7079435248767094,-1.4320882375501633
443.8000000000056,49.68687101347618,0.6964668828224931,-1.4680643419786406
444.9000000000056,49.79421646099812,0.6851503092362836,-1.501973905418895
446.0000000000056,49.902562254657305,0.6721422481363591,-1.533576351606599
447.10000000000565,50.01112064340772,0.6629998532793832,-1.563068546852267
448.2000000000057,50.11948584846406,0.6477807112029682,-1.58815039561811
449.3000000000057,50.22694383683387,0.6311979065757808,-1.6116009240180933
450.40000000000566,50.335842395500784,0.6105934263312826,-1.6318584053591136
451.5000000000057,50.44295188909045,0.590827903180775,-1.651698355384891
452.6000000000057,50.55197632092444,0.5713528991035479,-1.6690012061548258
453.70000000000573,50.6599991813708,0.5532782136608683,-1.6848802455530238
454.80000000000575,50.76800539893882,0.5323191993657741,-1.699447137913753
455.9000000000058,50.87407979938993,0.5183358137792354,-1.7138847897366793
457.0000000000058,50.98561560058877,0.5049685150525235,-1.727374721933558
458.1000000000058,51.09414603365596,0.49398090636345016,-1.7391702605072648
459.20000000000584,51.20196596964965,0.48313895560914644,-1.7508743855844249
460.3000000000058,51.3108323039673,0.4734676908539821,-1.7625126476623851
461.40000000000583,51.419586536654634,0.46890291306771736,-1.7726060139312105
462.50000000000585,51.52777618461382,0.46097978506567894,-1.785280619408847
463.6000000000059,51.636896063480876,0.45984285994412566,-1.7977423883434223
464.7000000000059,51.746080544430605,0.45568292304243707,-1.8087191793005375
465.8000000000059,51.85370759116865,0.4547962848968844,-1.8205691680059548
466.90000000000595,51.96266212286771,0.4515526201140657,-1.8314302973858303
468.0000000000059,52.070981283293214,0.45286298091113375,-1.842068075782695
469.10000000000593,52.179311304751536,0.4494376276793143,-1.8531995090280455
470.20000000000596,52.28837555709129,0.44772715888507064,-1.8649678852624616
471.300000000006,52.39683462600378,0.44096672037623363,-1.8753532396429473
472.400000000006,52.50457457683409,0.43968443353971565,-1.8837586433597187
473.500000000006,52.61325327106774,0.4277582911162465,-1.8924878925961095
474.60000000000605,52.72220108983967,0.4088138851530274,-1.9016183754628826
475.70000000000607,52.82973260052631,0.39076747535093526,-1.9071821994035791
476.8000000000061,52.93873277707666,0.36834810265893225,-1.9156540934350088
477.90000000000606,53.04769931298629,0.3430954861438814,-1.918684081076704
479.0000000000061,53.15641514375998,0.32093294126308614,-1.9219828279941107
480.1000000000061,53.263949792709546,0.3061733994254434,-1.9278793989119078
481.2000000000061,53.372998896320205,0.29051004964158256,-1.9288703026323575
482.30000000000615,53.48198698089845,0.28079105999411536,-1.9330010895362368
483.4000000000062,53.5897751371319,0.27592667772193735,-1.9346215056131064
484.5000000000062,53.699032815134835,0.2712611020340542,-1.9369678549243003
485.60000000000616,53.80833322403133,0.2669215345616286,-1.9383846169831083
486.7000000000062,53.916104228675366,0.2634859977841968,-1.9412190793243767
487.8000000000062,54.02547023684967,0.2616828475076305,-1.9412427087094413
488.90000000000623,54.1342552912206,0.2625612809067206,-1.944573046693604
490.00000000000625,54.24258132013683,0.2679628883605639,-1.9464903349851264
491.1000000000063,54.35110530770636,0.27219335306959025,-1.9478036559326182
492.2000000000063,54.460095074778955,0.27538261197789926,-1.9491316684326168
493.3000000000063,54.568602713608456,0.28265660739776977,-1.951085396471684
494.40000000000634,54.677037383069255,0.2863750214693721,-1.9511157117515456
495.5000000000063,54.78651381537142,0.2883307000290837,-1.9537693611089102
496.60000000000633,54.894470774966855,0.3001683906225566,-1.9551137158725713
497.70000000000636,55.004975001213616,0.3062376584818701,-1.957684409834025
498.8000000000064,55.11355819430973,0.31023764438655077,-1.9589984869930466
499.9000000000064,55.222739763531294,0.3121950278993245,-1.9602855981038818
501.0000000000064,55.33020634227871,0.3144975711541703,-1.9606297710116343
502.10000000000645,55.43990617422752,0.3169172265739544,-1.9619500372021899
503.2000000000064,55.548230083234735,0.3189702099343923,-1.9632774717427308
504.30000000000643,55.657992806620264,0.319887326332714,-1.9629421659320716
505.40000000000646,55.767407165245885,0.32343081082968084,-1.9642471354048898
506.5000000000065,55.87532781536715,0.3221537907650278,-1.9655699197264045
507.6000000000065,55.984340932475654,0.3295508106574184,-1.9668608943932182
508.7000000000065,56.09310795200102,0.32870388818271545,-1.9683086866323594
509.80000000000655,56.201657772510586,0.33370780361001484,-1.9704974773299495
510.90000000000657,56.311348362958974,0.334391122816447,-1.9691973871660733
512.0000000000066,56.42000000000073,0.3373752834791611,-1.9718299800000332
513.1000000000065,56.52961527674433,0.33873560219571575,-1.9731501313567514
514.2000000000066,56.637793589996456,0.34228798312519104,-1.973320912137623
515.3000000000065,56.7476744527111,0.34525478549346655,-1.973467758177965
516.4000000000067,56.85753500637446,0.34782076138055296,-1.9754750678483817
517.5000000000066,56.9666298097146,0.350452222730371,-1.9767853483046727
518.6000000000067,57.07282780694158,0.3542755652516444,-1.9793867930593994
519.7000000000066,57.18508075388699,0.35723491032118426,-1.9807095863745816
520.8000000000067,57.29368928891661,0.35401593629758255,-1.9807128785378179
521.9000000000067,57.40274323675757,0.35836956034115286,-1.9810170798661684
523.0000000000067,57.512135835742896,0.35608795624963274,-1.9823605338039192
524.1000000000067,57.62138077450964,0.3635462167881558,-1.9836682195244577
525.2000000000068,57.730704304010985,0.3634896698198492,-1.9849918685854286
526.3000000000068,57.841033480437645,0.3637441453203728,-1.9876229231685343
527.4000000000068,57.95064399267779,0.36697706607269576,-1.9889412228127044
528.5000000000068,58.0599025839014,0.3678569972415776,-1.9889394213608702
529.6000000000068,58.16894728969515,0.3704884484010932,-1.991258091139117
530.7000000000069,58.27850410413441,0.3707901727280327,-1.9912395171756827
531.8000000000068,58.38780869592666,0.3696684036782253,-1.9925628599448668
532.9000000000069,58.497650513550134,0.3704530832262597,-1.9938658530427953
534.0000000000068,58.60624185601439,0.3714806684908394,-1.9976407489523207
535.100000000007,58.71540230023285,0.37172440315222666,-1.9978164914963896
536.2000000000069,58.82581566346362,0.36555823374944685,-1.9991364118066386
537.300000000007,58.93476645484134,0.36494596243490574,-2.0001769681522292
538.4000000000069,59.04401698856369,0.3667125152275821,-2.0017594697005445
539.5000000000069,59.15401477949561,0.3666895425561748,-2.002497895873109
540.600000000007,59.262412894938684,0.3647589118452492,-2.0044030277976512
541.700000000007,59.373112901028115,0.36481474364659827,-2.005708106022384
542.800000000007,59.48108089539712,0.3641074191620173,-2.007030489690569
543.900000000007,59.591963538999366,0.36387276591318785,-2.0097200588899637
545.000000000007,59.7002245946517,0.3636302508499444,-2.009670789773602
546.1000000000071,59.80950466266577,0.3641499231751555,-2.009961341668914
547.2000000000071,59.92009743084693,0.36112837848625423,-2.012299092993614
548.300000000007,60.02948659425633,0.36148290018746854,-2.015039778858706
549.4000000000071,60.13875654574211,0.3611156153268733,-2.0183528545040335
550.500000000007,60.24790112076681,0.359520478324292,-2.0197543965072917
551.6000000000072,60.358541512639945,0.35813823074759266,-2.0222797255102005
552.7000000000071,60.46860945724146,0.3581881676084815,-2.0237100792488034
553.8000000000072,60.57829957001055,0.35857297184144565,-2.022347127562575
554.9000000000071,60.68847126627301,0.3589068332117412,-2.0262778868433813
556.0000000000072,60.798141724966676,0.35498082188619307,-2.0291187990929496
557.1000000000072,60.907833953380745,0.35682108871639584,-2.0318241005450837
558.2000000000072,61.01858414395103,0.3585911909981686,-2.0331401429254807
559.3000000000072,61.12719884613415,0.3580738581715507,-2.0351663492816945
560.4000000000073,61.23785994579868,0.3580971555918241,-2.037283525799304
561.5000000000073,61.34708571121609,0.3609059619208911,-2.0400430294822316
562.6000000000073,61.45744467537463,0.3617013063874497,-2.0416164947955284
563.7000000000073,61.56710053602326,0.3619025333493546,-2.0442593361854
564.8000000000073,61.67746241677991,0.36363805543882455,-2.0472471166596495
565.9000000000074,61.78738029202223,0.3633964560036932,-2.050981671066876
567.0000000000074,61.897626458882655,0.3664127028333868,-2.0549652434313312
568.1000000000074,62.00509972877484,0.3658299737543046,-2.059180172994866
569.2000000000073,62.11657698408416,0.3695152243214308,-2.0616194318374275
570.3000000000073,62.22658347952265,0.3723439158137538,-2.062975875514541
571.4000000000074,62.33672353313985,0.36943172454383966,-2.0679205444285493
572.5000000000074,62.448229729208244,0.3746663419341022,-2.0701345612404953
573.6000000000074,62.5570712052293,0.37736868138332214,-2.074242166412304
574.7000000000074,62.66833167646985,0.37489152282459726,-2.0772752701284367
575.8000000000075,62.77797362758049,0.3789389239112291,-2.0818594081882535
576.9000000000075,62.88811379380687,0.3823846543413423,-2.0879193335016017
578.0000000000075,62.997411315027925,0.38201038369957496,-2.0931799971736433
579.1000000000075,63.10707940109715,0.38420877672079434,-2.0988429027701536
580.2000000000075,63.21745442653597,0.3840514012395301,-2.1026103661821343
581.3000000000076,63.32755841523216,0.38251141358243856,-2.1082513263416027
582.4000000000076,63.43759547313012,0.37864297670729263,-2.1149255627033465
583.5000000000076,63.54836001287936,0.37982556638607967,-2.1200002973475502
584.6000000000076,63.65796090399612,0.37682182256971797,-2.126453804049892
585.7000000000077,63.76788117439747,0.37376981284602584,-2.1331270000709974
586.8000000000077,63.87709711821435,0.37723905004606384,-2.1397989164462103
587.9000000000076,63.98799703868007,0.37241157252493506,-2.145780609476576
589.0000000000076,64.09865504814364,0.3730658409512624,-2.15378621384628
590.1000000000076,64.20866074173132,0.36870531071682744,-2.160382385558728
591.2000000000077,64.31857338044321,0.3703052186085407,-2.168297595325487
592.3000000000077,64.42938513207199,0.36946801520559824,-2.1747217902469536
593.4000000000077,64.5397053701384,0.36901683047410594,-2.182936245997856
594.5000000000077,64.65075500217529,0.37271217126156286,-2.188951896809348
595.6000000000078,64.76093908628889,0.3695564287534292,-2.196237730226718
596.7000000000078,64.87075932629604,0.36755327079148126,-2.2042820700115078
597.8000000000078,64.98142442047323,0.3668479591247584,-2.2127492070064148
598.9000000000078,65.09162815223135,0.3676584354493859,-2.222324842877164
600.0000000000078,65.20258390099065,0.36770194175671134,-2.230915666564808
601.1000000000079,65.31137485743591,0.3630509576867873,-2.2386184492076255
602.2000000000079,65.42237730419731,0.3640547336903046,-2.2457667212224184
603.3000000000079,65.5325899262643,0.3604422623006518,-2.2540238519957976
604.4000000000078,65.64332876127685,0.35702835543215206,-2.2622411202666264
605.5000000000078,65.75342613830726,0.3556022747112779,-2.267957850963354
606.6000000000079,65.86416098606307,0.350258323784425,-2.275664828924301
607.7000000000079,65.97562539981837,0.35008776034247036,-2.282864847618886
608.8000000000079,66.0854240376159,0.34686293490996434,-2.289157527511459
609.9000000000079,66.19621917781657,0.35029115754816553,-2.2912495525365024
611.000000000008,66.30650227779378,0.35098718264821693,-2.2953865376330023
612.100000000008,66.41640816117332,0.3528376440196077,-2.298249899900137
613.200000000008,66.52727784125877,0.35975909564857655,-2.298250434311175
614.300000000008,66.63784125801722,0.35646114938817175,-2.299565091467077
615.400000000008,66.74762213711644,0.3640914226461831,-2.3013439510497156
616.5000000000081,66.8578681491048,0.3745820034242262,-2.302675656499906
617.6000000000081,66.96555668668589,0.38858770182279634,-2.3048314766898166
618.7000000000081,67.0784150802071,0.39834246499773496,-2.3061521251085444
619.8000000000081,67.18884664641975,0.4066791118781885,-2.3077723168214406
620.9000000000082,67.29894900374498,0.4206569345131057,-2.3074642997630392
622.0000000000082,67.41020740916734,0.4238966172714065,-2.3114263587588395
623.1000000000081,67.52039907015678,0.42616886094757866,-2.3114490412519717
624.2000000000081,67.63057893856056,0.43329548218648983,-2.3127332095245334
625.3000000000081,67.74210541856968,0.43846140584602766,-2.31411754199236
626.4000000000082,67.85187797886925,0.4401007780293311,-2.315444799741724
627.5000000000082,67.96207253627,0.45032290776577755,-2.3179716942067135
628.6000000000082,68.07274943582698,0.4529196855320241,-2.3193200451478995
629.7000000000082,68.1824892579486,0.46378403435578885,-2.3207222819556694
630.8000000000083,68.29243725582808,0.4679126108076437,-2.3240129613468667
631.9000000000083,68.4032560567261,0.4724043811480405,-2.3266649080021784
633.0000000000083,68.51232734456325,0.477803142206636,-2.3265443229208276
634.1000000000083,68.62377419101742,0.48170265313806526,-2.3278706590875986
635.2000000000083,68.73459926065968,0.48752595523951436,-2.329588930030112
636.3000000000084,68.84697601177942,0.4964729230755054,-2.3331715974629983
637.4000000000084,68.95694302996834,0.5023812325099968,-2.333782280520394
638.5000000000084,69.0677631692498,0.5114085901316971,-2.33588120032566
639.6000000000083,69.17734555714556,0.5173041555341622,-2.337869183771407
640.7000000000083,69.28878431851729,0.5263584355960429,-2.340493125453162
641.8000000000084,69.40000099999696,0.5367342252884693,-2.342570170922747
642.9000000000084,69.51087649738972,0.544965271722899,-2.3433144490355673
644.0000000000084,69.62138582191302,0.5565350700187555,-2.3469459436594375
645.1000000000084,69.73257445143169,0.5691158539366636,-2.351235030171443
646.2000000000085,69.84324253805777,0.5749481819116347,-2.354211764898407
647.3000000000085,69.95431709236047,0.5888168656199708,-2.35554022234549
648.4000000000085,70.06515015203587,0.6028687211696946,-2.358120928975575
649.5000000000085,70.1756214740024,0.6201213475650575,-2.3606805898771386
650.6000000000085,70.28647235638174,0.6331516881850638,-2.3637105601095856
651.7000000000086,70.3963774346859,0.6469807745632281,-2.3659526050412545
652.8000000000086,70.50771395654087,0.6622186993170103,-2.3705216522494563
653.9000000000086,70.61938913325838,0.6819628710491525,-2.3744910072404024
655.0000000000086,70.72896583610193,0.699003383002337,-2.3774180912663043
656.1000000000087,70.84020787002432,0.7196216420147195,-2.380408695842691
657.2000000000087,70.95052656134177,0.7352081413881031,-2.3844734603256574
658.3000000000086,71.06154537072275,0.7531582941463253,-2.388130861042363
659.4000000000086,71.1730670638887,0.7763146266050598,-2.391400205261246
660.5000000000086,71.2837007056324,0.7985754341048685,-2.394589813479053
661.6000000000087,71.39425112041462,0.817607987964964,-2.40093538469077
662.7000000000087,71.50443095108724,0.8373305464136189,-2.4050695742884978
663.8000000000087,71.6140622430973,0.857377228645889,-2.409443477001501
664.9000000000087,71.72517210068197,0.875487102905941,-2.414093027625321
666.0000000000088,71.83630246990548,0.8993935779230906,-2.4190334775027194
667.1000000000088,71.94674573396986,0.9250648679135012,-2.4247840071681064
668.2000000000088,72.05707869020114,0.9450866944962009,-2.4291274272012133
669.3000000000088,72.16837937646196,0.9691827187808284,-2.4354585871401415
670.4000000000088,72.28031770184337,0.9945126657525569,-2.441925440187087
671.5000000000089,72.39105401908624,1.021558598054384,-2.4454519162005184
672.6000000000089,72.50195449973353,1.0437963034305509,-2.4511757549508557
673.7000000000089,72.61283486019826,1.067906039667758,-2.4566014033357355
674.8000000000088,72.72384714528731,1.0921713145557033,-2.4638522469951933
675.9000000000088,72.83440335249988,1.119925148815666,-2.4720382794411098
677.0000000000089,72.94504602911252,1.1448052626312704,-2.477428443239783
678.1000000000089,73.05713355020204,1.1712651957154543,-2.4854367409681672
679.2000000000089,73.16702652947217,1.1967741948666135,-2.4916212447426354
680.3000000000089,73.2793708930726,1.2243647208926134,-2.4982604053154294
681.400000000009,73.3907287769511,1.2515088293631969,-2.506353960794799
682.500000000009,73.50148869703945,1.2782431842293007,-2.5131944360247687
683.600000000009,73.61324325312522,1.3075607109112393,-2.5215179949273865
684.700000000009,73.72409049390055,1.3339905720157654,-2.5273147118567314
685.800000000009,73.83511135647217,1.3671064119407375,-2.5361191005781967
686.9000000000091,73.94600687333788,1.393474328647844,-2.5445364804867197
688.0000000000091,74.05773568866768,1.4213694773953152,-2.5527774587729706
689.1000000000091,74.16863152842193,1.449227019633421,-2.5629475676025724
690.2000000000091,74.28010583924427,1.4755466592553366,-2.570056373353499
691.3000000000092,74.39041141100911,1.5023810709282273,-2.57831468981288
692.4000000000092,74.50302176511121,1.528366412958064,-2.5872492175142177
693.5000000000091,74.6132386287426,1.5565873754417594,-2.598364772376069
694.6000000000091,74.72475308524486,1.5825019006533863,-2.607852749557209
695.7000000000091,74.83332304990711,1.6067903778387271,-2.6163422197192667
696.8000000000092,74.94421490873347,1.6287166336069978,-2.6265386366971106
697.9000000000092,75.05888086403976,1.6466121205618203,-2.636408008647472
699.0000000000092,75.16911337026649,1.666345060680043,-2.647084669686709
700.1000000000092,75.28019322648568,1.682710093262851,-2.6567303095784744
701.2000000000093,75.39112402811074,1.7019363420890814,-2.6678469715999285
702.3000000000093,75.49966040653288,1.7077020161688599,-2.677424770158348
703.4000000000093,75.61340161387128,1.7146171942963133,-2.6877540374627236
704.5000000000093,75.72470805573863,1.71402675275527,-2.697283482547202
705.6000000000093,75.83533903238973,1.709509873089308,-2.7073456687859636
706.7000000000094,75.94621436844258,1.693295459105952,-2.717895750288747
707.8000000000094,76.05714239109382,1.6703265102619052,-2.7288520549598254
708.9000000000094,76.1680468039659,1.6311940290935465,-2.7377004198731045
710.0000000000093,76.27886842114208,1.5721276138040974,-2.7461984517570324
711.1000000000093,76.39052701642827,1.489633839065469,-2.7562234954389035
712.2000000000094,76.50135161378847,1.3769383964614044,-2.7649698368295064
713.3000000000094,76.61101293990968,1.2229141737959226,-2.772525070789329
714.4000000000094,76.72236356615919,0.9851120816947467,-2.7779761548173845
715.5000000000094,76.83292804535716,0.6930788175213105,-2.7842528960982835
716.6000000000095,76.94249817327679,0.43540923386476216,-2.7868886796673484
717.7000000000095,77.05335747097186,0.29744137090629685,-2.786905686825329
718.8000000000095,77.16395160551436,0.23548510240046272,-2.7881391218371636
719.9000000000095,77.27451376943569,0.20156462777915007,-2.7905202660991324
721.0000000000095,77.38586549331863,0.17835826567720825,-2.7918296680278
722.1000000000096,77.49748653488076,0.16627425567431486,-2.7918354213697647
723.2000000000096,77.60791182167155,0.1603518089830338,-2.7931601121091605
724.3000000000096,77.71863723956079,0.1537052133318011,-2.793231151303308
725.4000000000096,77.8305310690355,0.15125436674946058,-2.792360893725759
726.5000000000097,77.94235117268121,0.1505457645185606,-2.7934901097702856
727.6000000000097,78.05292304378727,0.1432374438925781,-2.792169763065166
728.7000000000096,78.16496240585852,0.1442824616568974,-2.7921877232735315
729.8000000000096,78.27673827582487,0.14149231860113032,-2.7931513817901807
730.9000000000096,78.38686236452347,0.14154741688248706,-2.7944698788998075
732.0000000000097,78.4985624154907,0.1439722568192945,-2.7944713803900845
733.1000000000097,78.61010744560194,0.15065426644868007,-2.7954600864391432
734.2000000000097,78.72032726349751,0.1473440662115162,-2.7957634985820894
735.3000000000097,78.8315050388092,0.1426262614308631,-2.7961100338998515
736.4000000000098,78.94325387760804,0.14644456614499735,-2.796110040000001
737.5000000000098,79.055211953362,0.14773477930860968,-2.796110050225045
738.6000000000098,79.16635474879094,0.15226361630845986,-2.79874741442684
739.7000000000098,79.27999898848263,0.14985288227033333,-2.797802123673789
740.8000000000098,79.390379399516,0.15017608882452493,-2.79682318042145
741.9000000000099,79.50294273600113,0.15311511971310732,-2.796744789227377
743.0000000000099,79.6137064932943,0.1556443066464095,-2.797440069985499
744.1000000000099,79.72543945564485,0.15264149400553162,-2.797439934496555
745.2000000000098,79.83658880671257,0.1542762200725194,-2.798475447761925
746.0000000000099,79.91873430978866,0.15720084369043485,-2.7987215519114756