File: 01_Data/Polyester_Carpet_Medium_Pile/STA/N2/10K_min/Polyester_Carpet_Medium_Pile_STA_N2_10KData_211216_R2.csv
##Temp./Â°C,Time/min,DSC/(mW/mg),Mass loss/mg
50.0,10.785053988985055,0.03710985037357295,-0.029555699128633428
51.100000000000016,11.073149487360686,0.0664708684574068,-0.029830984217671386
52.20000000000003,11.279849732391703,0.09001794603192426,-0.030674112597438796
53.30000000000005,11.45411808055797,0.11061239389051547,-0.03155247047260756
54.40000000000006,11.610523016768235,0.12614486521356494,-0.031168108715029508
55.50000000000008,11.757991531601473,0.13467133328992542,-0.03162935418353241
56.600000000000094,11.899273461249642,0.1462421507140821,-0.03170891705195533
57.70000000000011,12.030221225570617,0.15164098688781624,-0.03164921131798337
58.800000000000125,12.159480404569617,0.15979181049747931,-0.03436873939686791
59.90000000000014,12.286395216920933,0.16594735393331378,-0.03370004656747039
61.000000000000156,12.412483553364915,0.16920450885707433,-0.03367497029304456
62.10000000000017,12.53675905691896,0.17250654768827012,-0.033707823373684054
63.20000000000019,12.66000000000002,0.17653304266623993,-0.03436569587460703
64.30000000000021,12.779279540956283,0.18073892002613384,-0.03236414572005719
65.40000000000022,12.901349444897797,0.18514331413914675,-0.03472089310101145
66.50000000000023,13.020474720211586,0.1872000227649921,-0.0335600021614626
67.60000000000025,13.14000000000003,0.18850423949221673,-0.034875033299310854
68.70000000000027,13.257200541566872,0.192382081183047,-0.033772496233871685
69.80000000000028,13.37409817077365,0.1924168667029637,-0.034497097425432166
70.90000000000029,13.492069326788775,0.1940213568710708,-0.03488734776167046
72.00000000000031,13.608408028290949,0.19236323893641294,-0.03756458152745212
73.10000000000034,13.724809711564795,0.19322770454088356,-0.03588258644230269
74.20000000000034,13.840809370326681,0.19026476720085478,-0.036216712734911116
75.30000000000035,13.956618306349224,0.19029064442269128,-0.038719976802357614
76.40000000000038,14.072597710645018,0.19028969953075442,-0.036048131081285906
77.5000000000004,14.187153108222432,0.18726946645492593,-0.037633422947143114
78.6000000000004,14.300209976418586,0.18707183589637277,-0.03871985832979874
79.70000000000041,14.414086480460965,0.18608422964540872,-0.03828015516558114
80.80000000000044,14.526857323967285,0.18848158067138743,-0.03981311241810204
81.90000000000046,14.640290386975076,0.18607618496010264,-0.04113051777920296
83.00000000000047,14.753711947743446,0.18605587733292722,-0.03981689096266994
84.10000000000048,14.866485846422949,0.18622828596389096,-0.03982706382646306
85.2000000000005,14.978289175709959,0.18718835243719162,-0.03850325248389197
86.30000000000052,15.089171721006126,0.18525627063215272,-0.038498519515234975
87.40000000000053,15.200986997998047,0.18452575491765766,-0.039840479297607256
88.50000000000054,15.312595160748158,0.1866411663917177,-0.042483943704804794
89.60000000000056,15.422410982564417,0.18458916750676863,-0.03987073126655849
90.70000000000059,15.532541535664636,0.18565373227815868,-0.03970597084716587
91.8000000000006,15.64256471768746,0.18460249271234486,-0.04105044207183095
92.9000000000006,15.752880467450687,0.18602536751049334,-0.0396959324990358
94.00000000000063,15.858842948791228,0.1831032528732974,-0.04101698912854834
95.10000000000065,15.972271575528339,0.18465053353217942,-0.04066470347523943
96.20000000000066,16.08254031628158,0.1877193219707981,-0.041999753848176447
97.30000000000067,16.190215340797586,0.1855646670957318,-0.041012456606437375
98.40000000000069,16.299607156897512,0.187930499495694,-0.041013462090426334
99.50000000000071,16.408571060765976,0.1885592344086544,-0.04092448335411225
100.60000000000072,16.517468274451886,0.1922426481457996,-0.042330012334170775
101.70000000000073,16.625885924697254,0.19095480368621867,-0.04101368440458719
102.80000000000075,16.733606642464498,0.19474258102596284,-0.042022135416155404
103.90000000000077,16.842414272160564,0.19398357398879978,-0.04144052226024719
105.00000000000078,16.951654448535262,0.19552143762263466,-0.04358399440223648
106.10000000000079,17.057951475188627,0.19548960945580007,-0.04153274360027659
107.20000000000081,17.166094323416875,0.19919858764408135,-0.042346609795144374
108.30000000000084,17.274453356002738,0.19876935613416416,-0.04234003199681524
109.40000000000084,17.38323065201249,0.19945281029953849,-0.043616493151292346
110.50000000000085,17.490306802630272,0.20083184289212203,-0.04234016140107055
111.60000000000088,17.598019179724304,0.20384095316897646,-0.04230424387817422
112.7000000000009,17.706349468176505,0.20450451400531905,-0.04365017339037092
113.8000000000009,17.812337907497792,0.20291725179286763,-0.04233381834956251
114.90000000000092,17.921695305132175,0.20495694507299705,-0.04300452023143997
116.00000000000094,18.028689596899394,0.20502168889298383,-0.04431028690072836
117.10000000000096,18.136329561427544,0.20793600458933756,-0.04365010076477738
118.20000000000097,18.243938701719443,0.2099465590537718,-0.044237328310943624
119.30000000000098,18.35124354074734,0.2098858219625321,-0.04397985253628667
120.400000000001,18.4589650647866,0.21120282603416174,-0.04526370738938912
121.50000000000102,18.567498902856748,0.21186364946223676,-0.04364572475236095
122.60000000000103,18.67396884517975,0.21548051204081187,-0.04497006215307087
123.70000000000104,18.781493532435736,0.2147570348502395,-0.04497004500220525
124.80000000000106,18.888325373807234,0.2156328935122276,-0.04496435663955767
125.90000000000109,18.996696246684724,0.21895734422656538,-0.044966801420496694
127.0000000000011,19.10271938059405,0.21865947337523034,-0.0462800668317942
128.1000000000011,19.210268815698196,0.2180954807491119,-0.04527738056030728
129.20000000000113,19.316716463988502,0.2184064031523561,-0.0449652206112523
130.30000000000115,19.42416915116908,0.22132059427090017,-0.04629006754568277
131.40000000000117,19.530413797430846,0.2182752264659567,-0.04625634752086505
132.50000000000117,19.6369076915093,0.22000103403450136,-0.046279584615476654
133.6000000000012,19.744978408996477,0.21839387579974587,-0.04597056061129834
134.7000000000012,19.85191910350883,0.22093358777009142,-0.04592580884288733
135.8000000000012,19.95725881345824,0.22303518491334146,-0.04759629431179002
136.90000000000123,20.064713841995733,0.22005088611718462,-0.04760001467119013
138.00000000000125,20.170961301610923,0.22246040357494243,-0.04817809926925287
139.10000000000127,20.276844349444474,0.2250474905507051,-0.047599861221297335
140.2000000000013,20.38360823260926,0.22428511799225587,-0.047599860998399635
141.3000000000013,20.489245100482787,0.22733364156504235,-0.047613957508778615
142.4000000000013,20.59700941772039,0.2266052206794914,-0.048918213647966
143.50000000000134,20.702018145411536,0.2296729989232032,-0.04759981377694267
144.60000000000133,20.807945709155582,0.22989940423303512,-0.048589904924982275
145.70000000000135,20.915187627033006,0.2311294581821355,-0.04723738701725999
146.80000000000138,21.020299591487372,0.2330332427906918,-0.04815529752668368
147.9000000000014,21.128165209651772,0.23465989193057968,-0.048919991506294114
149.00000000000142,21.233366208178296,0.23830750205235499,-0.04905854903380957
150.10000000000142,21.338717742171873,0.2389458132181515,-0.04892005680129685
151.20000000000144,21.445794499289278,0.24171833966981787,-0.04795085484390116
152.30000000000146,21.551142755354952,0.24402239193162634,-0.04890982999698634
153.40000000000146,21.657353235109966,0.24684544820307536,-0.048909830812085886
154.50000000000148,21.763489995864816,0.2505833367479985,-0.047520545620530985
155.6000000000015,21.868296134050716,0.25404821839590325,-0.048920331894843905
156.70000000000152,21.974892026369613,0.25891347968592004,-0.0489200834251875
157.80000000000155,22.07922241325843,0.2641334231920367,-0.04952211992232591
158.90000000000154,22.18657885844916,0.27556077862797257,-0.049088331318305034
160.00000000000156,22.29110778804124,0.27743915571144295,-0.04891799876804592
161.1000000000016,22.397253915349598,0.2846601517001907,-0.04989983833840439
162.20000000000158,22.503664724255582,0.29089230338503047,-0.05026432915617285
163.3000000000016,22.60953731089264,0.30075962958655533,-0.04890122848531098
164.40000000000163,22.714433516010924,0.3087415278647564,-0.04891002507737152
165.50000000000165,22.820544436802034,0.31346812753252556,-0.05022658659854473
166.60000000000167,22.925624066805728,0.3136146681265022,-0.05023165883069858
167.70000000000167,23.031631710994297,0.3138648249766708,-0.0515499855009498
168.8000000000017,23.13401577633529,0.3038659520298726,-0.051544064576438675
169.9000000000017,23.243235778483704,0.29083014887963704,-0.05056039991540473
171.0000000000017,23.348365322597658,0.27706613074324193,-0.05186395861361559
172.10000000000173,23.454919157993434,0.2646333643373388,-0.051241064377849366
173.20000000000175,23.55930893033687,0.2552686749321875,-0.05056004919577406
174.30000000000177,23.66585313341624,0.24938367868657443,-0.05059094972842981
175.4000000000018,23.770643479503853,0.2446303282409265,-0.052540277098062305
176.5000000000018,23.876107772732315,0.24237782332405666,-0.05286517370596622
177.6000000000018,23.98167949500263,0.24260159912246726,-0.0528599919945294
178.70000000000184,24.087610093497478,0.24051032333123012,-0.05285101315129692
179.80000000000183,24.192491524113276,0.24183342953184597,-0.052529936661354526
180.90000000000185,24.29737750259271,0.24171133022899294,-0.05123387414818392
182.00000000000188,24.403853116820486,0.23969776292302095,-0.05254052305955925
183.1000000000019,24.509791090103242,0.24016305309072924,-0.05254000726538122
184.20000000000192,24.613347481558336,0.2415879825402666,-0.051219956175330594
185.30000000000192,24.71925064878299,0.24157028891393023,-0.0525516192645088
186.40000000000194,24.826427804260486,0.24375779450664736,-0.05319999813077514
187.50000000000196,24.93007901986088,0.24487847881983116,-0.05254007842048791
188.60000000000196,25.03580914416514,0.24671163347386033,-0.053199435950272544
189.70000000000198,25.141229533704283,0.24641092026328604,-0.052870013025867024
190.800000000002,25.247031921534933,0.24731291375552147,-0.052229399474785776
191.90000000000202,25.35245487777503,0.2463672805107885,-0.05392397507382585
193.00000000000205,25.457436470349947,0.24987843609405935,-0.0538502786141315
194.10000000000204,25.561658684783445,0.24834696652748037,-0.05253001844898053
195.20000000000206,25.668578440013597,0.2518494875315891,-0.05254012194229585
196.3000000000021,25.77218901701105,0.25235564265102406,-0.052540092999947774
197.40000000000208,25.879031361561907,0.2525677349703408,-0.05254009299999929
198.5000000000021,25.984770730987545,0.25103333733041666,-0.05254009315669883
199.60000000000213,26.088886560330646,0.2496291334638019,-0.05260196345420898
200.70000000000215,26.19368926206049,0.25171508956085564,-0.05253985850824083
201.80000000000217,26.300000000000214,0.2529860385487765,-0.052539492696377366
202.90000000000217,26.404893286047116,0.25392446927601736,-0.05517599493356684
204.0000000000022,26.509597471172228,0.2570414415557621,-0.0531904090453561
205.1000000000022,26.615289779071443,0.25609190101192686,-0.05291542307421215
206.2000000000022,26.721166359053658,0.25671279091591737,-0.05319004046012088
207.30000000000223,26.82534826067026,0.26030156945480654,-0.05313814720270571
208.40000000000225,26.930981193905225,0.26174135433494844,-0.052938996724168685
209.50000000000227,27.036316007314557,0.26391033007033493,-0.055616110752271464
210.6000000000023,27.141485609044878,0.26482965746536496,-0.05595709339855226
211.7000000000023,27.24687043948852,0.2685503370127372,-0.05592966422221579
212.8000000000023,27.3517438578682,0.26721258307146944,-0.054625207785789165
213.90000000000234,27.457486077706015,0.27197309313223667,-0.055930061887040416
215.00000000000233,27.562284084990416,0.27315766871046754,-0.05593005899998449
216.10000000000235,27.66786741117512,0.27303899110411556,-0.05593002208882236
217.20000000000238,27.772290206594572,0.2708856320224138,-0.05725026783937892
218.3000000000024,27.878378382515024,0.2745282389234682,-0.056963687521694784
219.40000000000242,27.984419751763628,0.2767489234119773,-0.05692000193320235
220.50000000000242,28.08850981014377,0.27585042731932585,-0.05692025292572689
221.60000000000244,28.19418686506341,0.2774626566784558,-0.05725889237693238
222.70000000000246,28.299403948885132,0.2792712097188084,-0.057240449867297816
223.80000000000246,28.40406532941412,0.28054697238896353,-0.056599904662028244
224.90000000000248,28.50931819744517,0.280818576275218,-0.05659989346166672
226.0000000000025,28.61419735089029,0.2798206310444944,-0.057608586493327785
227.10000000000252,28.719704961169008,0.2829915941075081,-0.05758718844207822
228.20000000000255,28.82403021313338,0.28634011991668207,-0.05785296495572778
229.30000000000254,28.92898035894813,0.2861648420451872,-0.05889990647372656
230.40000000000256,29.033709547154505,0.28673031776442504,-0.05892709760901793
231.5000000000026,29.139124617764093,0.2907273154903456,-0.0588369838746865
232.60000000000258,29.244237957506524,0.29229689943452475,-0.06021000567147494
233.7000000000026,29.350196963319494,0.29774077238227803,-0.05889872659951001
234.80000000000263,29.454933846824545,0.2996796683519854,-0.058899637063494215
235.90000000000265,29.55878167745186,0.30617536822475333,-0.06083080337468383
237.00000000000267,29.665023117708717,0.31215236806535274,-0.0608828431412336
238.10000000000267,29.769732904467368,0.3215464669445918,-0.059560141755191864
239.2000000000027,29.874434879752386,0.3285993597496871,-0.05956013800001658
240.3000000000027,29.9803907257217,0.34325670526010643,-0.05956013012707784
241.4000000000027,30.085816803055437,0.35687844320021256,-0.05955527189332699
242.50000000000273,30.189642235803216,0.37897342341824763,-0.060870128267517476
243.60000000000275,30.294652415638105,0.4086330418646734,-0.060869650655059004
244.70000000000277,30.398817211407913,0.4429257257916195,-0.06020999655191295
245.8000000000028,30.50532045895502,0.49457622058038453,-0.06021002531334707
246.9000000000028,30.611809916197647,0.558509896030196,-0.06150183633701056
248.0000000000028,30.71878089450231,0.6237876729354508,-0.06284290441153084
249.10000000000284,30.82363206896287,0.6672115334962154,-0.06120196372160036
250.20000000000283,30.9307621489231,0.6682771270653615,-0.061199909878763226
251.30000000000285,31.034975836651135,0.6144452388377779,-0.06161288224039785
252.40000000000288,31.14048266556428,0.533936544364289,-0.062179909716777004
253.5000000000029,31.24583817763346,0.45051676497894155,-0.06347408864754556
254.60000000000292,31.350783309221843,0.3893727024196999,-0.06350032824586105
255.70000000000292,31.454881100504256,0.34511663960843253,-0.061200107462176856
256.8000000000029,31.560276610047904,0.31902623657004414,-0.06123455769641328
257.90000000000293,31.66554850770352,0.30126008642401825,-0.06250991089076852
259.00000000000296,31.7700000000003,0.28753772908862435,-0.06321992113382358
260.100000000003,31.874236768339856,0.279405525816426,-0.06514953112006738
261.200000000003,31.980453999999337,0.2745863299087468,-0.06515013800066916
262.300000000003,32.08515906957558,0.26784965816072365,-0.06515701152142217
263.40000000000305,32.190904490162936,0.26678102755084676,-0.06456341246070929
264.50000000000307,32.295649089830775,0.2639450285149544,-0.06515013620321586
265.6000000000031,32.40027300112261,0.2619951354359565,-0.0665089148334368
266.7000000000031,32.5052889565908,0.2614600900799743,-0.06514879123640682
267.8000000000031,32.61081199171172,0.26135796295209646,-0.06514864227819261
268.9000000000031,32.7161143389898,0.26007105428750243,-0.06515002399858716
270.0000000000031,32.821344536812035,0.2600260081134098,-0.06515002445575524
271.10000000000315,32.92658372500331,0.25844509180686603,-0.06443112460430589
272.2000000000032,33.033270124604485,0.25643262663552757,-0.06448990961556733
273.30000000000314,33.13638023393838,0.2567133158328645,-0.06511659203788733
274.40000000000316,33.24213610900305,0.2567725982920094,-0.0651499102705877
275.5000000000032,33.34781666694776,0.256586694049839,-0.06550107928313631
276.6000000000032,33.45382525271837,0.2561559667540388,-0.06680013360189507
277.70000000000323,33.56009746538884,0.2565897867228547,-0.066800137999937
278.80000000000325,33.66407447798208,0.25834073603149466,-0.06679917013145831
279.9000000000033,33.76799048425083,0.2578823790651023,-0.0661401664647645
281.0000000000033,33.87627303415844,0.2575504616022046,-0.06745035958801715
282.1000000000033,33.98059033617059,0.2596856232163823,-0.0674501379996375
283.20000000000334,34.08663330826917,0.25775298039057176,-0.06745013800000033
284.30000000000337,34.19209315879343,0.26077885481909974,-0.06745013799983424
285.40000000000333,34.29725865869492,0.2577007986234817,-0.06744992192731702
286.50000000000335,34.39898171907298,0.2564141797286827,-0.06605876748646633
287.6000000000034,34.509089428208945,0.257743276902067,-0.06876987610946994
288.7000000000034,34.610175222998905,0.2585464106117307,-0.06745008080630521
289.8000000000034,34.7179491435983,0.25840043494011733,-0.06877611699174668
290.9000000000034,34.824407291383544,0.2607668501122307,-0.06954919120144165
292.0000000000034,34.93018290018019,0.2626366995729398,-0.07008996302266235
293.10000000000343,35.03411314882854,0.26139712190824616,-0.07008986904846948
294.20000000000346,35.140274643000254,0.2597922430092652,-0.07108030349394934
295.3000000000035,35.24588911926149,0.2599124067615202,-0.07238732548200888
296.4000000000035,35.35175152687221,0.2632315500100869,-0.07239011600259593
297.5000000000035,35.457459629022225,0.26016739069694933,-0.07239222748057639
298.60000000000355,35.5602390200628,0.26148182747818555,-0.07206045753099177
299.70000000000357,35.668831535188694,0.2599125919868458,-0.07337995178892909
300.8000000000036,35.77434740942027,0.2579548592847247,-0.0720596284076298
301.9000000000036,35.87933758222917,0.26086959815538474,-0.07206144888827204
303.0000000000036,35.98453638375738,0.2592402654824564,-0.07337987511555877
304.1000000000036,36.090400531310536,0.25921900926592756,-0.07337988377623095
305.2000000000036,36.19673635854928,0.257869556690741,-0.07468233105329425
306.30000000000365,36.30271842002069,0.2576133442829359,-0.07397374210377006
307.4000000000037,36.40753505515598,0.25743684830165525,-0.07403508403300929
308.5000000000037,36.51370965989244,0.2594292755201067,-0.07338060163296856
309.60000000000366,36.620685199410836,0.25883380233434716,-0.07470007843734905
310.7000000000037,36.72529370009916,0.25605807518019014,-0.07472108167893499
311.8000000000037,36.831228619948874,0.2571112236445691,-0.07673738133782138
312.90000000000373,36.937476558356664,0.25666796829579824,-0.07731986136806768
314.00000000000375,37.043815610413226,0.2549500875022779,-0.07731986200022511
315.1000000000038,37.14902260631442,0.2576100110369696,-0.07731978215304336
316.2000000000038,37.25654815800531,0.25404687374523666,-0.07996348357217276
317.3000000000038,37.36203504940483,0.2564732144549242,-0.0786365799087334
318.40000000000384,37.46813837139098,0.25682957070717993,-0.07995188232942096
319.5000000000038,37.573630057690494,0.2565503028578086,-0.0806480396951974
320.60000000000383,37.67989840760765,0.2568078727881485,-0.07765582765053392
321.70000000000385,37.785375070774414,0.2563220277055512,-0.08050203380935805
322.8000000000039,37.892123079714835,0.2573048359995288,-0.0831383982941638
323.9000000000039,37.99807521053588,0.2591520443816211,-0.08281778683705898
325.0000000000039,38.10371797385256,0.25875669860819034,-0.08280865447386754
326.10000000000394,38.209819919183744,0.25763287815207037,-0.08346098640556221
327.2000000000039,38.31620872883019,0.25653062310816127,-0.08591968653790394
328.30000000000393,38.42223362838612,0.26017501479666594,-0.08610008406590897
329.40000000000396,38.529677623995724,0.2592504791638048,-0.08609908139508482
330.500000000004,38.63474350731569,0.2589904436509731,-0.08544350422871982
331.600000000004,38.74188564465984,0.2572402146181804,-0.08661422904294236
332.700000000004,38.84737952404259,0.2586497049691592,-0.08874356204538136
333.80000000000405,38.952582318007444,0.2545081509341209,-0.09065006880543969
334.90000000000407,39.05873866211598,0.25670337030837936,-0.09049531245765774
336.0000000000041,39.166297230716346,0.25298100814193386,-0.08994058315139197
337.10000000000406,39.2720965529299,0.2548475182064178,-0.09115017155298455
338.2000000000041,39.37807116126297,0.2531788072875712,-0.09115094232666365
339.3000000000041,39.48408281283119,0.2523291692969612,-0.09397540408637495
340.4000000000041,39.59140140275003,0.25063339037632376,-0.09514846726446535
341.50000000000415,39.697473037707,0.2502132963024576,-0.09641997124934543
342.6000000000042,39.802900869124024,0.24789706262171918,-0.09637860997265824
343.7000000000042,39.91020033057927,0.2489705626359232,-0.09905137202864589
344.80000000000416,40.01731048644963,0.248211428088707,-0.1000485417766881
345.9000000000042,40.121100894477976,0.2488748782404142,-0.10068420991796412
347.0000000000042,40.22932153946221,0.24715845855183693,-0.10201089916836104
348.10000000000423,40.33605256976392,0.24676505429785967,-0.10421863763442962
349.20000000000425,40.44246386739644,0.24679513146665,-0.10594663065883658
350.3000000000043,40.54891402674024,0.24392583677716984,-0.10727170516858076
351.4000000000043,40.654485660665706,0.2448303544662458,-0.10859327310702849
352.5000000000043,40.76166075472312,0.2458087872541873,-0.10990434649710856
353.60000000000434,40.869170299140706,0.24322124710750048,-0.11206468885283671
354.7000000000043,40.973894183974984,0.245507841691622,-0.11680543023444967
355.80000000000433,41.0810460238628,0.241148109742102,-0.11587392212854608
356.90000000000435,41.18853903242498,0.24060214225825782,-0.1185864306090525
358.0000000000044,41.29616506110087,0.24260830909933706,-0.12119537969181815
359.1000000000044,41.40291844414578,0.24013898200888584,-0.1238451277061059
360.2000000000044,41.50942639070541,0.23893967523152482,-0.12646869045057363
361.30000000000445,41.616311119787866,0.23795104474664175,-0.12931957054621268
362.4000000000044,41.723795506516254,0.23888600500229573,-0.13327364919170304
363.50000000000443,41.82942230953639,0.24063266501634328,-0.13486743596465534
364.60000000000446,41.93670532439005,0.23982710215350012,-0.14005089374841617
365.7000000000045,42.043964708652446,0.2391341531009381,-0.14246182006304497
366.8000000000045,42.14938566492658,0.23960658915460975,-0.14440414286304515
367.9000000000045,42.25661487724287,0.23932119934840046,-0.14872896817036407
369.00000000000455,42.36344155430183,0.23976805988798078,-0.15392337456272465
370.10000000000457,42.47160792531793,0.24197278145416035,-0.15794995218249985
371.2000000000046,42.578097870189,0.24621355825085967,-0.16238495285572174
372.30000000000456,42.684969047521335,0.24534868924080633,-0.1666199492134819
373.4000000000046,42.791055481244555,0.2484354826253572,-0.17251997826476329
374.5000000000046,42.900298455825755,0.2495797214179375,-0.17618589496121917
375.6000000000046,43.00571426605828,0.2510706684774763,-0.18114880223651975
376.70000000000465,43.11349750701387,0.25078142187774866,-0.18777216268740693
377.8000000000047,43.22046921934326,0.25391660278491246,-0.19372246798521386
378.9000000000047,43.32906095798532,0.2536452222540353,-0.19899913808132075
380.00000000000466,43.43514438153674,0.2576896948977062,-0.20527956110687073
381.1000000000047,43.54281024478223,0.25702766511863373,-0.2120573450762544
382.2000000000047,43.6498132931061,0.26220266519702384,-0.21849506445327505
383.30000000000473,43.75697114659766,0.26194332133182185,-0.2273702900547061
384.40000000000475,43.86423896703559,0.26598636953345556,-0.23416998608246153
385.5000000000048,43.972113877001306,0.26674185281392526,-0.2425523892437611
386.6000000000048,44.07831395982632,0.26769305800751175,-0.250590085233914
387.7000000000048,44.185519312685145,0.27147539828391953,-0.2590467819870197
388.80000000000484,44.29373561736836,0.27392760761726065,-0.26694359724279915
389.9000000000048,44.39882835474567,0.27640581494404115,-0.27461122310591524
391.00000000000483,44.50767198040803,0.2798755929128208,-0.2868799823618051
392.10000000000485,44.61412528159472,0.28231471057792745,-0.29578799901168296
393.2000000000049,44.72180405613673,0.28346261197268285,-0.307684772210433
394.3000000000049,44.8292405340116,0.288266422775905,-0.3165748349258113
395.4000000000049,44.936788643834184,0.2928738049342142,-0.32759038378141714
396.50000000000495,45.04427274633669,0.2930906374783525,-0.33989366161671564
397.6000000000049,45.151940901459625,0.2969211878726453,-0.3516893634106113
398.70000000000493,45.2583262042916,0.2999685070782878,-0.3639019630212319
399.80000000000496,45.366052467016615,0.3049119740886942,-0.37550205032456496
400.900000000005,45.473926921508905,0.30857513714802065,-0.38917976876808025
402.000000000005,45.58081172896094,0.31178468509087887,-0.3994621061922614
403.100000000005,45.68898326226107,0.31583299115106056,-0.4173146470706479
404.20000000000505,45.795965396484974,0.32251948079967485,-0.432953064178625
405.30000000000507,45.90395388844106,0.32784302132702137,-0.4479550700578745
406.4000000000051,46.01089981699981,0.33623815379890587,-0.46460073572649874
407.50000000000506,46.11890539329408,0.3457226861914784,-0.48130268689115807
408.6000000000051,46.227016107588064,0.35123062906406877,-0.49890229178875023
409.7000000000051,46.33452688799479,0.35942023790418887,-0.5184821731533682
410.8000000000051,46.44221459328907,0.36890508796217103,-0.5371258634459246
411.90000000000515,46.54915768144522,0.3726767740797734,-0.5564449570249694
413.0000000000052,46.65798988829453,0.3802512028312439,-0.5782604850722373
414.1000000000052,46.76549383889512,0.3852447712266458,-0.5990187498956967
415.20000000000516,46.87382963645528,0.39422959849278527,-0.6214503703941348
416.3000000000052,46.98208883978543,0.4002561480432406,-0.646954840366166
417.4000000000052,47.08946215601985,0.4052007725480814,-0.671384668918654
418.50000000000523,47.19673835113307,0.4084185294129232,-0.6963403680166977
419.60000000000525,47.305082428489065,0.4145615166389166,-0.7231424420665609
420.7000000000053,47.412460423086486,0.4181947249010348,-0.7490324897786542
421.8000000000053,47.520195089062184,0.4217645108959007,-0.7770554857008722
422.9000000000053,47.62857786753686,0.43008506196748686,-0.80621760365909
424.00000000000534,47.73686727371791,0.4332964230542593,-0.836186596257233
425.1000000000053,47.84501636717249,0.4366355785694508,-0.8671390584797694
426.20000000000533,47.9542420432037,0.44299142062082153,-0.8986192416702115
427.30000000000535,48.06168336684169,0.44635195898213154,-0.9297245311913085
428.4000000000054,48.16968215931191,0.45386778971333674,-0.9624739096127621
429.5000000000054,48.27751654153191,0.45925124576349274,-0.9949947090459763
430.6000000000054,48.38598514862782,0.46537754794268604,-1.0314000079799
431.70000000000545,48.495058751243086,0.4730563893789841,-1.0681262512314893
432.8000000000054,48.6019972797722,0.4763663498500357,-1.1037871050648995
433.90000000000543,48.71075500946985,0.4830575606601192,-1.1418330429625079
435.00000000000546,48.81877888620514,0.48273449699782567,-1.1817043686453692
436.1000000000055,48.926655840995586,0.4841665200376032,-1.219289554427772
437.2000000000055,49.035153131238694,0.48190347975289993,-1.257842819841808
438.3000000000055,49.14316113608818,0.4786604056554771,-1.2981112782724455
439.40000000000555,49.25108346239635,0.47334575090530506,-1.3383611424137758
440.50000000000557,49.358458981802826,0.46909355197392544,-1.3780615417706423
441.6000000000056,49.46685837501271,0.45836714216078767,-1.4184375553198536
442.70000000000556,49.575794300018,0.4528700869200144,-1.4560148750576793
443.8000000000056,49.68386127027289,0.4412031386175215,-1.4917592668927284
444.9000000000056,49.79233312181412,0.4288098761048045,-1.5280695370562554
446.0000000000056,49.89990550580049,0.41724540158399626,-1.5623311251195298
447.10000000000565,50.00835310047911,0.4055693715322398,-1.5923308820485187
448.2000000000057,50.11543460054198,0.3921735712675567,-1.619794897359042
449.3000000000057,50.22350555044392,0.37543350079073423,-1.6463352675684977
450.40000000000566,50.33208473384146,0.3613170937811542,-1.6671491451582074
451.5000000000057,50.44052638970372,0.3346480293889402,-1.6877259851063209
452.6000000000057,50.54734347382912,0.31798242495144835,-1.7068790322073886
453.70000000000573,50.656561872924655,0.2971893397558739,-1.7232260170190932
454.80000000000575,50.76434160183442,0.28028298902359905,-1.7383585354823459
455.9000000000058,50.8726970383415,0.2624038397106465,-1.7530437414671622
457.0000000000058,50.980504741503225,0.2508844445311026,-1.7686466525341458
458.1000000000058,51.08839175745564,0.2403692471797486,-1.7825803491499266
459.20000000000584,51.19763115085259,0.22946948827510794,-1.7937266327180885
460.3000000000058,51.30531253837346,0.22463460587389217,-1.8063174857719728
461.40000000000583,51.41363162186425,0.21834815000844887,-1.8194721957601914
462.50000000000585,51.522876212731624,0.2148141485869467,-1.8347760222171554
463.6000000000059,51.631927730682065,0.21422657008273505,-1.8470943100858892
464.7000000000059,51.73999902369708,0.21068686195313424,-1.8604589018119162
465.8000000000059,51.84781719231784,0.20696944881495605,-1.8744033821409953
466.90000000000595,51.957239242987065,0.2057031871464695,-1.8874190871710996
468.0000000000059,52.065222114633265,0.20419225355603277,-1.9027966200984405
469.10000000000593,52.17372371756722,0.2042815227339584,-1.917155570633597
470.20000000000596,52.281834658190995,0.20304079702615385,-1.9308880879145955
471.300000000006,52.39101805988071,0.19884978386209484,-1.94515968060252
472.400000000006,52.49943467267702,0.19590194420539786,-1.9591191392702902
473.500000000006,52.60756547677303,0.19313295910708894,-1.9721926389068005
474.60000000000605,52.716311055218746,0.18520592978475925,-1.9842506876851198
475.70000000000607,52.82512486779189,0.16818854957845308,-1.9940001124840498
476.8000000000061,52.93387980572622,0.14432478992400366,-2.0022086800046224
477.90000000000606,53.04070165615569,0.11980033193379125,-2.010571276090803
479.0000000000061,53.15155769531296,0.09312764972406717,-2.0157837045243614
480.1000000000061,53.25952186661491,0.06833973906519186,-2.02049651252468
481.2000000000061,53.36905542862998,0.0475679270247199,-2.0276043863669964
482.30000000000615,53.47679657312726,0.023817847416564453,-2.030498981021191
483.4000000000062,53.58553143057311,0.008936148435064739,-2.0340756593298583
484.5000000000062,53.69510653283911,-0.0006120624715244549,-2.0366736431854435
485.60000000000616,53.80379696731015,-0.005705304919429222,-2.038065283511961
486.7000000000062,53.912626719359416,-0.01212391082060138,-2.040677639816119
487.8000000000062,54.02143561467261,-0.016325149073387446,-2.0421241154298553
488.90000000000623,54.129682923237254,-0.018506020301754855,-2.044649957953202
490.00000000000625,54.23911639991646,-0.018466095938357685,-2.045967813027703
491.1000000000063,54.3485308616549,-0.01659170781089736,-2.047279839517012
492.2000000000063,54.45712833100932,-0.015804275641956966,-2.0484965300686024
493.3000000000063,54.56487880053306,-0.01196988338168492,-2.049916710969461
494.40000000000634,54.674295255581676,-0.006470865783108848,-2.0519888717134482
495.5000000000063,54.78216805518808,-0.004785711653654379,-2.053900715135283
496.60000000000633,54.89079943916216,-0.00245726283008052,-2.053870218764377
497.70000000000636,54.99999908315131,0.00047238294951379434,-2.055189833269214
498.8000000000064,55.107262901102395,0.0017353427026182144,-2.056330142083656
499.9000000000064,55.2163014480725,0.004956541741124587,-2.057100804150321
501.0000000000064,55.32590880098414,0.009389979320436281,-2.0584811958344487
502.10000000000645,55.43465433492572,0.009243252417599601,-2.0597781181006067
503.2000000000064,55.5431735575866,0.013374525252841774,-2.0633454970955407
504.30000000000643,55.65199552670033,0.015958735908577992,-2.063210672376994
505.40000000000646,55.7604208755184,0.020256357615377363,-2.065059872640915
506.5000000000065,55.87000000000065,0.01969689218278603,-2.0676899750000652
507.6000000000065,55.97833013188239,0.02362760355408766,-2.0676900747608165
508.7000000000065,56.08805310746105,0.023438631278018596,-2.0689415222580854
509.80000000000655,56.19727923733221,0.025118434704770598,-2.0712666838551144
510.90000000000657,56.30650882313528,0.02542105763931657,-2.07086953672478
512.0000000000066,56.416480841004166,0.025186436062464512,-2.0722994591382653
513.1000000000065,56.5244730758663,0.033403850330107066,-2.073610317796402
514.2000000000066,56.63435093281213,0.03341817376034317,-2.076240031380001
515.3000000000065,56.743978073958594,0.03888347150831328,-2.0762509557522346
516.4000000000067,56.85318834042691,0.03746650457802558,-2.077559940593062
517.5000000000066,56.96285856714557,0.03922590160941475,-2.080193814296755
518.6000000000067,57.071926040323426,0.04121039929594428,-2.0815442252026912
519.7000000000066,57.18190834067679,0.041670211609347696,-2.0815157866745393
520.8000000000067,57.290971772122106,0.04322369005337823,-2.0828684892884115
521.9000000000067,57.400633971860216,0.042209320226996416,-2.082830002189078
523.0000000000067,57.509317858760596,0.04653721672931188,-2.0841386982636405
524.1000000000067,57.61878570190723,0.04679989812392926,-2.0853759423785623
525.2000000000068,57.72864231482792,0.04678472301790193,-2.086779961337547
526.3000000000068,57.83847745955847,0.051336308535715025,-2.0881003758787937
527.4000000000068,57.94657515098385,0.0484698526766465,-2.088162004405548
528.5000000000068,58.056855717874434,0.05087328441388572,-2.089506583364896
529.6000000000068,58.16630654232492,0.05153801291044746,-2.090721395019327
530.7000000000069,58.27586226045265,0.049207949995413225,-2.092040867940724
531.8000000000068,58.3851979499131,0.049827595553374016,-2.094657747156309
532.9000000000069,58.49441132386576,0.05098924711037345,-2.095976403845782
534.0000000000068,58.603140937758894,0.04886623340976248,-2.0973401223675787
535.100000000007,58.71329166707264,0.044093662713554416,-2.0986647564655048
536.2000000000069,58.82348913708365,0.04236548380258198,-2.0999399064552793
537.300000000007,58.93273109011987,0.03916452919791702,-2.1009199547783153
538.4000000000069,59.04208867538082,0.04072016784950372,-2.1038881640322113
539.5000000000069,59.15289916196504,0.04156778267469985,-2.1038873917599945
540.600000000007,59.26202613950655,0.038678137263794765,-2.1051999013628473
541.700000000007,59.37204682358335,0.03648018914374207,-2.1065234914027196
542.800000000007,59.48090911379684,0.03619010700667191,-2.1096728384722083
543.900000000007,59.59111713580798,0.037951549848597166,-2.109979372188242
545.000000000007,59.700468593530985,0.033118280109560416,-2.1122796965598134
546.1000000000071,59.81000193431406,0.0330589615973651,-2.1125501968765183
547.2000000000071,59.92050302911178,0.03275820576774957,-2.1138890222414206
548.300000000007,60.02820832628377,0.029605894525977616,-2.116884963412206
549.4000000000071,60.13847872962676,0.03131874130951107,-2.1184428257586947
550.500000000007,60.248537053954976,0.02875453470119793,-2.1194601194891973
551.6000000000072,60.35879888044667,0.026366538481551238,-2.12165566341712
552.7000000000071,60.468263846395494,0.02568228085770974,-2.123410184468482
553.8000000000072,60.57611312819111,0.025745983028657715,-2.125380015508265
554.9000000000071,60.687612964413006,0.025765258871557783,-2.1280190012915887
556.0000000000072,60.79732567597046,0.026088144578756856,-2.129241329588237
557.1000000000072,60.90728448676765,0.025849794230058842,-2.1319947958774312
558.2000000000072,61.01697697354027,0.02420752783381719,-2.13455548612992
559.3000000000072,61.12686433293896,0.025874074458516638,-2.137233393427274
560.4000000000073,61.2358218967506,0.023488482154486956,-2.1388450070877045
561.5000000000073,61.34698329185015,0.02907952680999104,-2.141123311174959
562.6000000000073,61.45637602726296,0.02754711617732508,-2.1444045326988608
563.7000000000073,61.56619938275132,0.030738623901191087,-2.147652394286374
564.8000000000073,61.676057963112584,0.03148179085216318,-2.1502844884582055
565.9000000000074,61.78664185387001,0.03386429166086957,-2.151913486085168
567.0000000000074,61.896078973103045,0.03408236357234351,-2.153203279588301
568.1000000000074,62.00592182707978,0.04034747025768759,-2.157550476564325
569.2000000000073,62.11591836593354,0.040297704648793564,-2.161371754578438
570.3000000000073,62.22593387712225,0.044196613369879234,-2.1643567909513117
571.4000000000074,62.33505331953624,0.04641829558908572,-2.1666956868580876
572.5000000000074,62.44587798446854,0.050277850391197365,-2.170887060782876
573.6000000000074,62.556496622888496,0.052675692031678434,-2.1752627928444728
574.7000000000074,62.66651457362641,0.05680413254711936,-2.1793477876583935
575.8000000000075,62.77695012579729,0.05924207193431452,-2.184338363140167
576.9000000000075,62.886607024840934,0.06026965988564448,-2.189419493360396
578.0000000000075,62.9965952698352,0.06212960554069036,-2.1920917029830997
579.1000000000075,63.106752265559564,0.066272230074512,-2.197287922023624
580.2000000000075,63.21756358821463,0.07149619769328175,-2.201956376190151
581.3000000000076,63.32783258138863,0.0689300409871767,-2.2094071120864567
582.4000000000076,63.437341350459185,0.07102511002155132,-2.2146991929376165
583.5000000000076,63.548240119221276,0.06876080690882147,-2.221823546875006
584.6000000000076,63.6582014448207,0.06557493040084483,-2.2267043050902826
585.7000000000077,63.76680659280551,0.06819147066467268,-2.231632853042967
586.8000000000077,63.878788247677,0.07021351592305258,-2.239116085196006
587.9000000000076,63.989461250863926,0.06606896277708807,-2.246297681209446
589.0000000000076,64.10020676248074,0.0682912929181807,-2.2536075601989767
590.1000000000076,64.21138251231531,0.0666947353036269,-2.261318241157006
591.2000000000077,64.32031365761911,0.06912002278067009,-2.268647455560265
592.3000000000077,64.43042445601351,0.0689804665960958,-2.2755560106244648
593.4000000000077,64.54187466114203,0.06820869225811133,-2.284394583311831
594.5000000000077,64.65205503841698,0.06679131134989125,-2.292780015918158
595.6000000000078,64.76244122502429,0.06518777472105253,-2.2987784792223636
596.7000000000078,64.87276104377824,0.06994011156113644,-2.3063765135012604
597.8000000000078,64.9818191062114,0.0699778399896458,-2.3145561344354455
598.9000000000078,65.09217300803247,0.07125946064661348,-2.324746728258722
600.0000000000078,65.2021300333284,0.07265845391796155,-2.3338016165684383
601.1000000000079,65.31306233380194,0.06968430805535175,-2.342564158144582
602.2000000000079,65.42343994766011,0.06679192465093342,-2.3508673464535037
603.3000000000079,65.53209426976215,0.06798973100377737,-2.3594568809433
604.4000000000078,65.64313976541081,0.06419447962020297,-2.365712968315699
605.5000000000078,65.75387594925573,0.06127515143676532,-2.373630792344615
606.6000000000079,65.86358714537887,0.05958613640049526,-2.3816319342849974
607.7000000000079,65.97345513105442,0.05821808096883374,-2.3914470679161535
608.8000000000079,66.08438667710139,0.05609987689189855,-2.395443813276268
609.9000000000079,66.19570719501141,0.05862552058781123,-2.4027592263040987
611.000000000008,66.30566510476774,0.05807992901140291,-2.408050865481417
612.100000000008,66.41559475949884,0.060937219847628565,-2.411311315675405
613.200000000008,66.52617780457777,0.06243794703367733,-2.4140346737428966
614.300000000008,66.63586980244014,0.06760967960755737,-2.4153908209861177
615.400000000008,66.74724178421512,0.06876071478835843,-2.4167357728330003
616.5000000000081,66.85719284500809,0.07278961892236224,-2.4180459618580468
617.6000000000081,66.96830119592978,0.08890955727586691,-2.4193398435152798
618.7000000000081,67.07809536475811,0.1003720148691929,-2.420661526768291
619.8000000000081,67.18759221498782,0.11409144323538101,-2.4219715922252543
620.9000000000082,67.29878387331115,0.12064417917898629,-2.4246329690941733
622.0000000000082,67.40920193339029,0.13325532289342035,-2.4259269181069527
623.1000000000081,67.51852493202969,0.13569340383615103,-2.425930988716676
624.2000000000081,67.63031416721095,0.14559016817472958,-2.4272517636506694
625.3000000000081,67.74176442283924,0.15144115457213148,-2.4298907190493924
626.4000000000082,67.85246990154306,0.15859696697151815,-2.429867537264683
627.5000000000082,67.96385674171498,0.16136227546127868,-2.431179490329978
628.6000000000082,68.07474490102611,0.16717101513518995,-2.4337852738002193
629.7000000000082,68.18402598638058,0.17258783869176875,-2.4377658426387576
630.8000000000083,68.29551812237538,0.1836155839307012,-2.4384313418398156
631.9000000000083,68.40495140665404,0.1844362101285859,-2.4393581037217893
633.0000000000083,68.51599684145839,0.19124814212271501,-2.442998612228375
634.1000000000083,68.6262771255139,0.19836456515590517,-2.444349709873131
635.2000000000083,68.73757175634304,0.20561585618475342,-2.444357641238838
636.3000000000084,68.84887557801713,0.2070200279747867,-2.4486083673814445
637.4000000000084,68.95798561313235,0.212909172186037,-2.449256772609174
638.5000000000084,69.06916258486734,0.22035590337481326,-2.451565813191336
639.6000000000083,69.1801005493464,0.2288930402870346,-2.454219834708277
640.7000000000083,69.28989306691764,0.23660356351842982,-2.456191419247676
641.8000000000084,69.40182030453056,0.24809097087310894,-2.458165750739854
642.9000000000084,69.51163083446994,0.2550403544288311,-2.4621234139279267
644.0000000000084,69.62337569554971,0.26491309589952183,-2.463452136661096
645.1000000000084,69.73358472704936,0.27231740736869425,-2.4637625609365146
646.2000000000085,69.84471461843162,0.28447813677732614,-2.4692897241454066
647.3000000000085,69.95551729294348,0.29530734305000683,-2.472208368565938
648.4000000000085,70.06586542049116,0.30730729475170615,-2.473542334582557
649.5000000000085,70.17710760696681,0.31977067412748306,-2.4761063512699617
650.6000000000085,70.2881025298747,0.33058863255126236,-2.4802655567443406
651.7000000000086,70.39943893668598,0.3431104509461842,-2.4829729526239483
652.8000000000086,70.50861980723212,0.35631866770066245,-2.4846202779778475
653.9000000000086,70.62048058014601,0.3742898587117589,-2.488884152991118
655.0000000000086,70.73108982074835,0.3901579152001782,-2.4932702736706562
656.1000000000087,70.842594880364,0.4056136432402002,-2.4967961706515203
657.2000000000087,70.95266805904596,0.41931431184942114,-2.5007463481632133
658.3000000000086,71.06457241079215,0.43361061582909977,-2.5039499467800113
659.4000000000086,71.17394484211829,0.45453930563705747,-2.5050847795605433
660.5000000000086,71.28559492939827,0.47108722645939993,-2.509918282064199
661.6000000000087,71.39650942552029,0.49456260604950675,-2.514082615473998
662.7000000000087,71.50700456187131,0.5068481379251331,-2.519217827035064
663.8000000000087,71.61839383130045,0.5265839100177259,-2.5250020451608375
664.9000000000087,71.72939572021089,0.5472512908775016,-2.527884019578112
666.0000000000088,71.84030328758155,0.5706659123008848,-2.5340817565153
667.1000000000088,71.95116052803095,0.5833199691802975,-2.538594640043223
668.2000000000088,72.06250673172292,0.6060693938660604,-2.543045566019888
669.3000000000088,72.1741952143748,0.6262566493481265,-2.5490942745323695
670.4000000000088,72.28482747817937,0.6477830874000712,-2.5552796334077406
671.5000000000089,72.39506136111605,0.668094896711372,-2.5606234069663856
672.6000000000089,72.50683929580735,0.6899633829900733,-2.566865930678592
673.7000000000089,72.61785446064711,0.7172712499688059,-2.5711933363793666
674.8000000000088,72.72944818331473,0.7372397034634255,-2.578382338425944
675.9000000000088,72.84118040061765,0.7600464832888956,-2.58602343393249
677.0000000000089,72.95110739546568,0.7862565983458643,-2.590939478355756
678.1000000000089,73.06347318013371,0.805579801187644,-2.5993156943978777
679.2000000000089,73.17380989642497,0.8305812974334845,-2.603008088104264
680.3000000000089,73.28566250110707,0.8578300652575199,-2.6103877437287353
681.400000000009,73.39706837203111,0.878336144302784,-2.6190224138232536
682.500000000009,73.50785456053752,0.9067086645810467,-2.6267803235282727
683.600000000009,73.61956719656578,0.931384843664228,-2.6354878236939365
684.700000000009,73.73010996349167,0.9581914934295375,-2.6440969894317923
685.800000000009,73.84083612660079,0.9790323530295355,-2.651135345393336
686.9000000000091,73.95279397205388,1.0058610232477871,-2.6581661993754344
688.0000000000091,74.06350552289302,1.0288400548970547,-2.667280530868556
689.1000000000091,74.17554079947767,1.0550769221241392,-2.6738677650895504
690.2000000000091,74.28654331581814,1.0805257313936907,-2.682516824007899
691.3000000000092,74.39797685486678,1.105081271177815,-2.6926179831841077
692.4000000000092,74.50869454754681,1.1301095341328198,-2.702291869194405
693.5000000000091,74.62045494639212,1.1536628474034771,-2.710609650675489
694.6000000000091,74.73068331299172,1.1724689343415304,-2.719659063136606
695.7000000000091,74.84259075089156,1.1928038338248408,-2.729248339919523
696.8000000000092,74.95395298083507,1.217710958984406,-2.737629478907876
697.9000000000092,75.06535002171077,1.23242155152934,-2.748943098739696
699.0000000000092,75.17625444117816,1.2525233395315387,-2.7581079514906786
700.1000000000092,75.28890219532991,1.2681991405337778,-2.7670831303763617
701.2000000000093,75.39989893049133,1.2810226262759967,-2.7776865417792016
702.3000000000093,75.51039910713413,1.295867228671698,-2.7885715951648216
703.4000000000093,75.62146185321005,1.3048398251471505,-2.798917271369834
704.5000000000093,75.7336028998815,1.3100222568388378,-2.8083244138773287
705.6000000000093,75.84499634001874,1.3129115781600766,-2.818392236440917
706.7000000000094,75.95611129274222,1.3138388483362315,-2.82920221120302
707.8000000000094,76.06799021574193,1.308834051560858,-2.839151645780989
708.9000000000094,76.17898851687156,1.2970069539193707,-2.8492900556048797
710.0000000000093,76.29059780911716,1.2750206246320581,-2.857930107993396
711.1000000000093,76.40119901791009,1.2542071178666552,-2.8676852627383815
712.2000000000094,76.51209975370674,1.2216277559699225,-2.8769770853765197
713.3000000000094,76.6230877573319,1.1723105003846888,-2.8865658512995336
714.4000000000094,76.73425527512732,1.1083705294454846,-2.8965947921775346
715.5000000000094,76.8444660614547,1.0281347119574042,-2.9030564593359243
716.6000000000095,76.95653301469737,0.9174369796394193,-2.9107030039864843
717.7000000000095,77.06570846332427,0.7703074164603914,-2.9198332137495044
718.8000000000095,77.17725056990727,0.5855844128750634,-2.9245584494284875
719.9000000000095,77.28625161277526,0.36076482945046573,-2.9287705869327665
721.0000000000095,77.39620865132922,0.15459649982561086,-2.9315809989142503
722.1000000000096,77.5082874473496,0.030244272962679286,-2.932912438364223
723.2000000000096,77.61777581401782,-0.026380017234992614,-2.9346911607419113
724.3000000000096,77.73139550057479,-0.060507997012842374,-2.935529936498586
725.4000000000096,77.84062718157041,-0.0803072132089464,-2.9355218740634568
726.5000000000097,77.95298477669992,-0.09264050102767607,-2.936848953248025
727.6000000000097,78.06319447543953,-0.1003746412144566,-2.9358600984604655
728.7000000000096,78.17401225693769,-0.1060412496121339,-2.9358618878162916
729.8000000000096,78.28505914708094,-0.11248494876053394,-2.9378259600403247
730.9000000000096,78.3940746938018,-0.11013731015015171,-2.9380840277237583
732.0000000000097,78.5072727992692,-0.11196619156879484,-2.936840120348726
733.1000000000097,78.61910680038291,-0.11880399477272041,-2.9381999312200975
734.2000000000097,78.72833517546356,-0.115403308183748,-2.9393781947205966
735.3000000000097,78.84113958367307,-0.11617233429111629,-2.9394800368443397
736.4000000000098,78.95218215202786,-0.12028549778619402,-2.94209605890138
737.5000000000098,79.06320155175257,-0.12141125492788696,-2.940788915771846
738.6000000000098,79.1746304391902,-0.12495145113288553,-2.9407902436634137
739.7000000000098,79.28666955763903,-0.12632984922286994,-2.94045767742855
740.8000000000098,79.39829602958623,-0.12294803624597117,-2.9404599370117754
741.9000000000099,79.50980563240749,-0.12775542871286927,-2.9404589899802325
743.0000000000099,79.62094035412899,-0.13087605960094661,-2.94343387928693
744.1000000000099,79.73341646030627,-0.1303746743491434,-2.943427608041098
745.2000000000098,79.84476437995168,-0.1299814688934946,-2.9421098292440018
746.0000000000099,79.92562595651776,-0.13249277727462871,-2.9421510277382885