File: 01_Data/Polyester_Carpet_Medium_Pile/STA/N2/10K_min/Polyester_Carpet_Medium_Pile_STA_N2_10KData_211216_R1.csv
##Temp./Â°C,Time/min,DSC/(mW/mg),Mass loss/mg
50.0,10.771436091395493,0.03644747003201021,0.015133146429445077
51.100000000000016,11.066427510418736,0.06936583569959198,0.016934033937432424
52.20000000000003,11.274782492228182,0.09377534185801495,0.017368817174371998
53.30000000000005,11.45014412737853,0.11273249490711612,0.017026816113202337
54.40000000000006,11.608574533900349,0.12867954252671743,0.015926520265352906
55.50000000000008,11.755851669983688,0.1424765775932182,0.016874569279490714
56.600000000000094,11.894904993223273,0.15269947315266635,0.016263674250891036
57.70000000000011,12.0286103614352,0.16237241392104373,0.016047841516948047
58.800000000000125,12.15940286442665,0.1690460983023782,0.014975348640526853
59.90000000000014,12.28597927717727,0.17475023102211618,0.017794886544752586
61.000000000000156,12.41265282733509,0.18091604100940278,0.016881389725631912
62.10000000000017,12.535983938822367,0.18574415053887028,0.017817490564362437
63.20000000000019,12.658985890006512,0.18923134552283427,0.017601851414291936
64.30000000000021,12.780226536071972,0.19366099338847492,0.0164534823970115
65.40000000000022,12.900000000000025,0.19535997229102475,0.01649822055195127
66.50000000000023,13.019888690697197,0.1990010304106169,0.015446944948098285
67.60000000000025,13.139900154004243,0.20347835523432134,0.015124351314701023
68.70000000000027,13.256244094371668,0.20423816203034095,0.015139774141721851
69.80000000000028,13.37581730337644,0.20498366340738688,0.01653388010315382
70.90000000000029,13.49532046720477,0.20897176696497965,0.016500959180272723
72.00000000000031,13.611097960145758,0.2088193546974893,0.016442221677342772
73.10000000000034,13.727466940236422,0.20543377570724636,0.01776983469352089
74.20000000000034,13.842512403460137,0.20764417257786782,0.016415528363941334
75.30000000000035,13.95912271502431,0.21012632486875937,0.017738363769586485
76.40000000000038,14.074567843812664,0.2077306693664513,0.016461124393578608
77.5000000000004,14.188149720435092,0.20867657691049468,0.018756282269108304
78.6000000000004,14.303642229776134,0.206606584389049,0.017642447023805907
79.70000000000041,14.415089530382879,0.20590862274923716,0.017268150096882984
80.80000000000044,14.529897092020667,0.20785226184102576,0.017430831274301006
81.90000000000046,14.642323630029031,0.20576291288072343,0.017430784696666812
83.00000000000047,14.754706386410898,0.20696354148452809,0.015999929893722786
84.10000000000048,14.867538441026383,0.20560631356484735,0.01743990275474161
85.2000000000005,14.97862999444928,0.20459536230858355,0.01743183298211992
86.30000000000052,15.091457984415282,0.20327252920236152,0.016905201061788944
87.40000000000053,15.203196601254394,0.20188580960674785,0.0183639469924195
88.50000000000054,15.313227057513386,0.20261056068946856,0.017439694913349513
89.60000000000056,15.424289560800977,0.20435302179689224,0.018749920401188724
90.70000000000059,15.533700833177928,0.2033755220066386,0.017884332551083126
91.8000000000006,15.645021344608338,0.2017342780495725,0.01721918282186241
92.9000000000006,15.753705366616149,0.20361579359077284,0.01852822611524374
94.00000000000063,15.863546325510814,0.20648404258486763,0.01720738360814611
95.10000000000065,15.97400547189938,0.20622909604394898,0.01722017034824841
96.20000000000066,16.08323566062003,0.20768678174974214,0.01723519461653833
97.30000000000067,16.19040280598709,0.210494896287284,0.017218891864457575
98.40000000000069,16.300000000000068,0.21092943629712393,0.01820003199973108
99.50000000000071,16.408662070962478,0.21318009191448276,0.01854886174635695
100.60000000000072,16.51834581262232,0.2129792854728034,0.01715176313476885
101.70000000000073,16.6252129226581,0.21499646146232526,0.017175002814744822
102.80000000000075,16.73446781716608,0.21764381245413678,0.01722281350740218
103.90000000000077,16.842163063824895,0.21773016062653505,0.017219863389095202
105.00000000000078,16.95185218336319,0.2198326389308155,0.016718096239525693
106.10000000000079,17.057845643537394,0.21924825138899917,0.01885938218932104
107.20000000000081,17.167584737682542,0.22239044355303306,0.017245717652638604
108.30000000000084,17.275942216486232,0.22368507452855768,0.017219836935297828
109.40000000000084,17.383587149270586,0.22671959918920337,0.018195637044374102
110.50000000000085,17.49154801622946,0.22734956627996838,0.01753992000382887
111.60000000000088,17.599081527553405,0.2303343858065165,0.01721011756388613
112.7000000000009,17.707720620774015,0.2313563201562679,0.015915939009609303
113.8000000000009,17.81605686394635,0.23366373104161065,0.018545088471119797
114.90000000000092,17.923821031406014,0.23555567143757916,0.018529642368274146
116.00000000000094,18.031755757984392,0.2374388644547685,0.018530174634165952
117.10000000000096,18.139709638299372,0.23862714115981362,0.01735594892416703
118.20000000000097,18.2468511348315,0.24206167227263042,0.017351133911944316
119.30000000000098,18.35524162080224,0.24389023001382548,0.018540960115020155
120.400000000001,18.46210647037753,0.2445861137829686,0.01722009117303802
121.50000000000102,18.569028801138455,0.24664135867808762,0.017221146328911807
122.60000000000103,18.676499880032022,0.24803548603344555,0.01748319977954882
123.70000000000104,18.78300496746947,0.25048569906172063,0.017219936103948008
124.80000000000106,18.890785676441222,0.24950688624296352,0.017603037512716746
125.90000000000109,18.99757813327198,0.2524754584901814,0.017209977534155207
127.0000000000011,19.105328213739412,0.2544751581787777,0.017875019882226617
128.1000000000011,19.21220211635351,0.2538199585712203,0.017245280051960243
129.20000000000113,19.31850827056183,0.2544378147075873,0.017219906835387988
130.30000000000115,19.426567788346958,0.255993652379541,0.018641314743786275
131.40000000000117,19.532434373633784,0.257728082348603,0.017209991896073085
132.50000000000117,19.640475879623956,0.25782962168919193,0.018559837721461747
133.6000000000012,19.745779615452577,0.2591203210320824,0.017219825755217855
134.7000000000012,19.85248856281134,0.25966705233547865,0.018540898327813693
135.8000000000012,19.9600000000001,0.26174732439195064,0.018540159999998806
136.90000000000123,20.06507807436139,0.26249101439003575,0.01788001117563809
138.00000000000125,20.171958875519874,0.263391425664129,0.019190616224332047
139.10000000000127,20.278016055620945,0.26441897458319036,0.017870084773623063
140.2000000000013,20.383194653212044,0.26373024003070744,0.017866824767371448
141.3000000000013,20.490432617420844,0.26771585475288395,0.01919016417096575
142.4000000000013,20.596870588443284,0.27032385663083625,0.017880266968034242
143.50000000000134,20.702845715545838,0.27007453195246844,0.0175417257254864
144.60000000000133,20.808702051333334,0.27410426772011304,0.01804407531133556
145.70000000000135,20.91456453993742,0.27534073896334865,0.01750269723883502
146.80000000000138,21.020829701438064,0.277414913992119,0.01629143640503017
147.9000000000014,21.12664086948488,0.2785578482565463,0.017882125481864186
149.00000000000142,21.232946274045272,0.2827529721653159,0.01820058672218483
150.10000000000142,21.338170739959196,0.28310035072724093,0.018199798482297247
151.20000000000144,21.44414889290015,0.2854846642862791,0.01787896478538986
152.30000000000146,21.550093214846818,0.2889444152364998,0.01787983009760108
153.40000000000146,21.65663167270743,0.2906096041957114,0.018954857375970136
154.50000000000148,21.76290919053565,0.29453250124761166,0.01788012078168144
155.6000000000015,21.867641344045328,0.2989522764639775,0.018342854288483146
156.70000000000152,21.9740670354855,0.30262707408633516,0.01919267335128083
157.80000000000155,22.079325708721687,0.30753586438765185,0.01786979051691162
158.90000000000154,22.18496721265811,0.3118920793078397,0.01786979999995797
160.00000000000156,22.290527341089156,0.32116150230468693,0.017869812666380547
161.1000000000016,22.39608506849461,0.32782561195587095,0.01788116274288143
162.20000000000158,22.503064248777292,0.3335828623869258,0.01689007874163373
163.3000000000016,22.607781223040462,0.3426888835987652,0.01820319117013547
164.40000000000163,22.715660605928235,0.3509700861276394,0.017926179745420434
165.50000000000165,22.820000000000157,0.3538341976030882,0.016560175212466888
166.60000000000167,22.92605659564898,0.35828431114654885,0.016560179114840423
167.70000000000167,23.032790299044606,0.3556099096288245,0.017887733068986833
168.8000000000017,23.136932313170902,0.34674094267194855,0.017880056011508216
169.9000000000017,23.24378059175397,0.3350133295682013,0.017876878495859394
171.0000000000017,23.34931762434879,0.3238122892052981,0.01886151600905439
172.10000000000173,23.454734511745862,0.3126778672432709,0.017579198726679124
173.20000000000175,23.560580415684264,0.3066817142336845,0.016493938010779807
174.30000000000177,23.66629454541025,0.3039592103422086,0.01622721997422083
175.4000000000018,23.77126647469701,0.30035921998679765,0.016570255587526894
176.5000000000018,23.87813671809598,0.2995861679230155,0.017869746904016992
177.6000000000018,23.98286248262066,0.2992937534983478,0.0178919634700625
178.70000000000184,24.087509588099522,0.2992531022657354,0.016557585099437944
179.80000000000183,24.19273292496082,0.3030818553126472,0.01656002400186196
180.90000000000185,24.298357463815034,0.2994609372559985,0.016560089700146108
182.00000000000188,24.404367752694892,0.3017869881103716,0.017876585627501385
183.1000000000019,24.508181273944412,0.30119822196271107,0.015565787090764616
184.20000000000192,24.614443082945392,0.3017049113916211,0.016559760029254633
185.30000000000192,24.720000000000184,0.3035757992538718,0.016563617572007416
186.40000000000194,24.82661712319923,0.30571478477614406,0.01623018257825226
187.50000000000196,24.931176225963885,0.30478291824686915,0.01609544900477644
188.60000000000196,25.037637346964594,0.3054809287527427,0.015910631466264036
189.70000000000198,25.13900299309129,0.30555263727578574,0.0172198470072491
190.800000000002,25.247189291106885,0.3072947813202894,0.017219871700483225
191.90000000000202,25.35166121802931,0.307312711877762,0.016499186372341157
193.00000000000205,25.45811149225504,0.307552724295497,0.017727486288615424
194.10000000000204,25.562742431379284,0.30916823697417717,0.017880177071364578
195.20000000000206,25.668759384701954,0.31265213672711467,0.01721999116214068
196.3000000000021,25.773883417343622,0.31151387382986306,0.015900012942053898
197.40000000000208,25.87901412596085,0.31369928009688935,0.015898725670806968
198.5000000000021,25.98300965717885,0.3149136066074174,0.01721972421481155
199.60000000000213,26.08969909094809,0.313464417405694,0.015899881665353277
200.70000000000215,26.19315018067029,0.3150828446058864,0.015889237515954058
201.80000000000217,26.29806097412759,0.3180100826807454,0.015906502785115073
202.90000000000217,26.40366390371551,0.3164715072357778,0.01688991850643351
204.0000000000022,26.50962759556028,0.31999090350866766,0.016892620189962848
205.1000000000022,26.61302950622948,0.3221034899935085,0.01590443040381473
206.2000000000022,26.718296832279737,0.3234308064918243,0.015899983994752453
207.30000000000223,26.82260516182585,0.3248983559677426,0.01590116434131339
208.40000000000225,26.927202427492634,0.3249309928788766,0.017219885861109674
209.50000000000227,27.032719374562596,0.3272566133281556,0.017223486859217374
210.6000000000023,27.138875610365815,0.3291286004094077,0.015240072946628658
211.7000000000023,27.243132190037183,0.33071398939456204,0.01524101609502182
212.8000000000023,27.34823424074988,0.33222436742030487,0.01654145936844742
213.90000000000234,27.45315455650062,0.3334900671875304,0.015250007273830413
215.00000000000233,27.560293898078438,0.33632216823354544,0.015250008000573523
216.10000000000235,27.66580058711617,0.3397450609768854,0.015256112371538677
217.20000000000238,27.77100774141663,0.34358209874455214,0.013929893742539612
218.3000000000024,27.876652651680484,0.344771496234339,0.015235023329291053
219.40000000000242,27.978764926183924,0.3477497969707277,0.015250238157956453
220.50000000000242,28.085287487785536,0.3498640353723266,0.01557095721143753
221.60000000000244,28.1899990161654,0.35048987687641353,0.01490969455931701
222.70000000000246,28.296829227288175,0.3495785098435896,0.01491002362584748
223.80000000000246,28.40204743670675,0.35628684408231526,0.013934395769912733
224.90000000000248,28.507917350925144,0.35542757374717604,0.013920023999181907
226.0000000000025,28.612254333336367,0.3572932267233747,0.013920024000494635
227.10000000000252,28.717586004318342,0.35767616120819334,0.013920577555930791
228.20000000000255,28.820548375303165,0.3588580671401787,0.014250098584684068
229.30000000000254,28.928302448456684,0.3610016410309717,0.013922033053342275
230.40000000000256,29.032616272276567,0.3636885989661681,0.015224854683955513
231.5000000000026,29.137437226196923,0.3671580746426937,0.012942850029037167
232.60000000000258,29.24291884701648,0.3703374621074293,0.01294016800101172
233.7000000000026,29.348553559181475,0.3730908722758377,0.012940168000000085
234.80000000000263,29.454395327132723,0.3805549951837832,0.011949172100869987
235.90000000000265,29.558924960566106,0.3851108066614489,0.011620010180809714
237.00000000000267,29.66504585744271,0.3941024255955756,0.01227489306284113
238.10000000000267,29.770663454671187,0.4052671975033636,0.014517374938735728
239.2000000000027,29.8754870294419,0.41344548520320246,0.012664000152478039
240.3000000000027,29.981324695582106,0.42787044966978105,0.012720136155262907
241.4000000000027,30.086815263921633,0.44704210017745877,0.012156660655283424
242.50000000000273,30.192508534877774,0.4711856317798886,0.012060122597118195
243.60000000000275,30.296111369302906,0.5036541214455945,0.013361361020188589
244.70000000000277,30.402868952256856,0.5481024022202537,0.013369816004676238
245.8000000000028,30.508857205113756,0.6070550554132936,0.01336981613951238
246.9000000000028,30.614527037340906,0.6816784051959467,0.013283614598740279
248.0000000000028,30.71782795672797,0.7558434663336517,0.012719816290025499
249.10000000000284,30.827055288299338,0.802507594632525,0.012719815999999717
250.20000000000283,30.932869066708452,0.7880330351215551,0.012719815999999717
251.30000000000285,31.037415089162884,0.7232884646574735,0.012719816505473602
252.40000000000288,31.14283394630991,0.6264310524010415,0.011577246486280224
253.5000000000029,31.248841370388377,0.5384822104588305,0.013609730448696844
254.60000000000292,31.35287876070455,0.4766769863674302,0.012719920535405826
255.70000000000292,31.45706112241116,0.4345106665216584,0.012830411430554634
256.8000000000029,31.562221047109816,0.40653366917438377,0.011399684997125625
257.90000000000293,31.666665713665818,0.38872381630120667,0.01266260082072801
259.00000000000296,31.77196306343853,0.37610558799489147,0.013292258783618394
260.100000000003,31.875584535823496,0.36880142103018304,0.0110698453275333
261.200000000003,31.980567855719542,0.36071503546053096,0.011069887717853888
262.300000000003,32.0854290150998,0.35603226384005426,0.012530747601017467
263.40000000000305,32.19074646361844,0.35442998069509474,0.011502850859320013
264.50000000000307,32.29554540082203,0.3521018181736266,0.01025821211367628
265.6000000000031,32.40066473309452,0.35350445158201593,0.010201336370352365
266.7000000000031,32.50528237137374,0.3491067245901869,0.0105232592649811
267.8000000000031,32.61039205149186,0.3532568032868288,0.010520119999703148
268.9000000000031,32.71531383514238,0.35200564486355745,0.010520512694333739
270.0000000000031,32.82097022175225,0.34980348298786523,0.009860117622264575
271.10000000000315,32.927326529833515,0.3503440984798283,0.009465750008995855
272.2000000000032,33.03223669493126,0.35087318935734263,0.010886913724366565
273.30000000000314,33.136982097491405,0.3523585224104367,0.011004581805427627
274.40000000000316,33.2423524282272,0.35043943245351766,0.0100062553805218
275.5000000000032,33.3478646630387,0.35173176332947387,0.009539976215759971
276.6000000000032,33.45332153715448,0.3531918704205541,0.00924965331509675
277.70000000000323,33.55805337414761,0.35324729728008375,0.009544458532520395
278.80000000000325,33.663974701250815,0.3517044710545974,0.008220698617215305
279.9000000000033,33.76907537001099,0.3554587107089771,0.008219975993290163
281.0000000000033,33.87435313723506,0.3559826975908752,0.0082419111497547
282.1000000000033,33.9793917299546,0.3536964765291517,0.010530315972294702
283.20000000000334,34.08518066064383,0.35383415599876455,0.010530472154258952
284.30000000000337,34.19084346647005,0.35507578772452264,0.009210029482856541
285.40000000000333,34.295477963464855,0.3569425547826548,0.009210191999959427
286.50000000000335,34.397054982408704,0.35485046270087667,0.009210191992152339
287.6000000000034,34.50639113790529,0.3594843845819659,0.009211385357444257
288.7000000000034,34.61140229218198,0.3578013536182848,0.007570226873447439
289.8000000000034,34.7173811959042,0.36073818240177924,0.007570104000089728
290.9000000000034,34.822061659757004,0.36061393131338304,0.0075699549825394286
292.0000000000034,34.92810445461844,0.3609364924970771,0.00657959938504149
293.10000000000343,35.03299042700843,0.3604151843860679,0.006580103999931808
294.20000000000346,35.13978759420175,0.361224470378887,0.006580107062164942
295.3000000000035,35.24492341586274,0.3603226431067967,0.0052593458851291075
296.4000000000035,35.3510691210787,0.35973323942648155,0.005588611989640668
297.5000000000035,35.45584383649102,0.36012345123902934,0.005354134716673897
298.60000000000355,35.560943795294996,0.3597889074158354,0.0026098679438915084
299.70000000000357,35.668058425505265,0.36015436815410506,0.0026298157756166063
300.8000000000036,35.77319412667486,0.3588855822947276,0.002899850629128231
301.9000000000036,35.87870684261005,0.3607811663976315,0.0026073031779763056
303.0000000000036,35.98530877965738,0.36137895690379707,0.0013006937865744916
304.1000000000036,36.090665331577775,0.3624757020985656,0.0026299271668044355
305.2000000000036,36.19715389421305,0.36301067988023916,0.0013118782017329522
306.30000000000365,36.30039258172867,0.3613065420906418,0.0013099360004957816
307.4000000000037,36.409171888837214,0.36283519343513015,0.0013099005342880332
308.5000000000037,36.51433986330265,0.36346491987092877,0.0026300955080493793
309.60000000000366,36.62070532324927,0.36528250630800574,0.0025847192550161324
310.7000000000037,36.72620824310026,0.36628630012233954,0.0006597943443340526
311.8000000000037,36.83274373783046,0.36538965593997447,0.0003270086614088896
312.90000000000373,36.938004541966436,0.36636314526300845,-0.0008238786152716671
314.00000000000375,37.043171066865035,0.3687211220720422,-2.1058890133929253e-06
315.1000000000038,37.14904393644035,0.3679962813684125,2.5193282437996345e-06
316.2000000000038,37.2521734085971,0.368041170671361,-0.0012687753750846298
317.3000000000038,37.36102950694549,0.368035944497799,-0.0013200542509395063
318.40000000000384,37.467647877142625,0.37010333697012837,-0.0026405545635475036
319.5000000000038,37.57287484337438,0.3706601709174215,-0.0052758897132791915
320.60000000000383,37.67853312471334,0.3722933339055748,-0.00427990955287072
321.70000000000385,37.78452646831929,0.3721915232605253,-0.004279911999996777
322.8000000000039,37.88882825744374,0.3686532357664639,-0.004279910699035661
323.9000000000039,37.99602608407219,0.3705615106685663,-0.0056037599265881255
325.0000000000039,38.10248875140879,0.36694570279169064,-0.004273777992582772
326.10000000000394,38.20887071410417,0.3700801023276095,-0.005590951368560582
327.2000000000039,38.31510586975978,0.37110648328861157,-0.006579932437188241
328.30000000000393,38.42107781284358,0.36960299071673214,-0.007902515770032537
329.40000000000396,38.52770343099251,0.3735669009623131,-0.009198133733369751
330.500000000004,38.63407688359445,0.36951653000358736,-0.008230080640291071
331.600000000004,38.739109244589606,0.3692058943104,-0.008552477846103912
332.700000000004,38.847168066224974,0.37077395953249287,-0.009868245336226877
333.80000000000405,38.95337472480308,0.36895333905670635,-0.012181149948140124
334.90000000000407,39.05950829000379,0.3726807273558747,-0.011522553594019769
336.0000000000041,39.166446270730276,0.3718856284025656,-0.01315839822601017
337.10000000000406,39.27263293866151,0.37113139401772777,-0.015142690424680971
338.2000000000041,39.37928880025284,0.3680632144023249,-0.01579996954751639
339.3000000000041,39.485916880374084,0.367147151752966,-0.017109884527444663
340.4000000000041,39.592390646603526,0.3705121702652379,-0.018480430983778717
341.50000000000415,39.698100429196074,0.36954009898977713,-0.01975268561053678
342.6000000000042,39.803724213003576,0.3683846168540511,-0.02073992064897734
343.7000000000042,39.9099102968692,0.37136694937023523,-0.021059871952637366
344.80000000000416,40.018299997306514,0.36890724327690083,-0.02238782776782955
345.9000000000042,40.12477068463448,0.3704068964458657,-0.023604613442029354
347.0000000000042,40.23110779830122,0.36812041400054485,-0.025004395127069756
348.10000000000423,40.33733083883217,0.36862792941296335,-0.02731743211509219
349.20000000000425,40.443833273479186,0.3670434760326295,-0.028648312417521637
350.3000000000043,40.548630266131745,0.36857476003702455,-0.03122519916849331
351.4000000000043,40.657129635832845,0.3687009993998186,-0.03126165971304662
352.5000000000043,40.763771818973325,0.36704423716028717,-0.032785362990614964
353.60000000000434,40.871510279955174,0.36599100498275994,-0.03567452327243359
354.7000000000043,40.97728449428696,0.368825761755801,-0.03782217772639562
355.80000000000433,41.084350037005706,0.36514935583004127,-0.040178991415378285
356.90000000000435,41.1900009275399,0.3646400852486992,-0.04048881936211668
358.0000000000044,41.2982011353919,0.36721934107348975,-0.04463315735966944
359.1000000000044,41.403725661882355,0.36402144873779596,-0.04802273949742464
360.2000000000044,41.510475435292804,0.36221282731375715,-0.04959984399804718
361.30000000000445,41.61764781622159,0.3649301077222511,-0.05331825477974039
362.4000000000044,41.72391347961852,0.3654994546579807,-0.054958798938487874
363.50000000000443,41.83047233354391,0.3650922643601583,-0.05726278173542099
364.60000000000446,41.9372259189184,0.3635471084769013,-0.06129521933040927
365.7000000000045,42.04384436654654,0.3641804026588882,-0.06548220424908457
366.8000000000045,42.15010503988866,0.3666430294365465,-0.06811371078206463
367.9000000000045,42.257595713974,0.36876951481585396,-0.07088112619888687
369.00000000000455,42.361671854008016,0.3668861198586467,-0.07561411450892486
370.10000000000457,42.471853151740994,0.36680880404904426,-0.0803425310029584
371.2000000000046,42.57725977701337,0.36648920279410746,-0.08407556151964002
372.30000000000456,42.68408144325456,0.37204056219016646,-0.08871658891821577
373.4000000000046,42.790884121525174,0.3712121087623339,-0.09271610929120122
374.5000000000046,42.89806585031648,0.373613263336639,-0.09745907686095112
375.6000000000046,43.00539128183566,0.37371763416486636,-0.10263450104807692
376.70000000000465,43.11204208720737,0.3769501265814862,-0.10742026185566766
377.8000000000047,43.218970038373755,0.3788383079667297,-0.11414538096690752
378.9000000000047,43.32527523217483,0.37901911171450664,-0.12025154544390304
380.00000000000466,43.43193800021745,0.3823398731658946,-0.12610957005481094
381.1000000000047,43.53971106095477,0.3842959305074203,-0.1323594271944537
382.2000000000047,43.64651250672702,0.3857837952800901,-0.13969254222759497
383.30000000000473,43.75333008965291,0.3877062663464027,-0.14597680492796483
384.40000000000475,43.8605190522754,0.3888886856226942,-0.15431707672022998
385.5000000000048,43.96727419668134,0.3890859338938192,-0.16049918603736213
386.6000000000048,44.07511449898526,0.3940049919795454,-0.16768978541334212
387.7000000000048,44.18143157186652,0.39319050704172853,-0.17645675560971252
388.80000000000484,44.2883526509806,0.3986733265454572,-0.18535529078789592
389.9000000000048,44.39614023048455,0.4013201745222267,-0.19558434377661316
391.00000000000483,44.503994170829614,0.40428384182939325,-0.203944986410443
392.10000000000485,44.611134005973305,0.40859119941224753,-0.21280543218047132
393.2000000000049,44.718542304689095,0.41035640208822444,-0.22253812963373054
394.3000000000049,44.82577003942721,0.4115492925078301,-0.2333153612433967
395.4000000000049,44.9329838346241,0.4144581895304753,-0.2433444034363066
396.50000000000495,45.0400000000005,0.418485531906701,-0.2572228670222141
397.6000000000049,45.147677784360084,0.42146500833729705,-0.26949893086461874
398.70000000000493,45.25252629419993,0.4237663826449226,-0.280601106273072
399.80000000000496,45.36182204273913,0.43064876673771424,-0.29383718554837346
400.900000000005,45.469120725207375,0.43342277252579164,-0.3052253766814452
402.000000000005,45.576330486565375,0.4398371389063832,-0.31982942120359015
403.100000000005,45.68354620297037,0.4431751980515575,-0.33405283406908737
404.20000000000505,45.7905818857968,0.4474467848269552,-0.34924615222949473
405.30000000000507,45.899151690548926,0.45565718555897883,-0.3649255463870862
406.4000000000051,46.00606754165964,0.4609141162169539,-0.38214636812731984
407.50000000000506,46.1136741297902,0.469171962902596,-0.3981201903520426
408.6000000000051,46.21772316083086,0.47501540584607826,-0.41563451216283864
409.7000000000051,46.32745400525198,0.4813839736293464,-0.4328583302337856
410.8000000000051,46.43519847076151,0.4941621137963952,-0.4506506955380858
411.90000000000515,46.54446622936063,0.5008669154480159,-0.47320091985635093
413.0000000000052,46.651511175590834,0.5079511468359732,-0.4943963480241709
414.1000000000052,46.759692351303165,0.5135584293963696,-0.5153556464730937
415.20000000000516,46.86671967296085,0.5198431783155367,-0.5378888394790069
416.3000000000052,46.97439734606844,0.52979535776495,-0.5616757106050856
417.4000000000052,47.08200803746014,0.5363924716015884,-0.585977551782435
418.50000000000523,47.18899695669679,0.5417959300482832,-0.6124473850536001
419.60000000000525,47.2967318669366,0.5459602218880918,-0.637989094065146
420.7000000000053,47.40385296581491,0.5510563126650297,-0.6652863671926217
421.8000000000053,47.511771676528824,0.5521553346553435,-0.6946832937170901
422.9000000000053,47.61989775237792,0.5584895994401361,-0.7239001572366313
424.00000000000534,47.727483971243444,0.5659439917981861,-0.7529958052175107
425.1000000000053,47.835863074011534,0.5733602770193496,-0.7840675228848597
426.20000000000533,47.94346680279889,0.5771750210529777,-0.8155526057061393
427.30000000000535,48.05194893031835,0.5845454694813288,-0.8467409880553047
428.4000000000054,48.159714860196324,0.5906706392677902,-0.8801538775175826
429.5000000000054,48.26737412612251,0.5996873728892045,-0.9149597844029187
430.6000000000054,48.375552085826925,0.6055316934889312,-0.9497260437343327
431.70000000000545,48.48375173819013,0.6118387317302466,-0.9867650057104234
432.8000000000054,48.59245245989957,0.6170455692065536,-1.0264902799504996
433.90000000000543,48.699801166396895,0.6189763120367083,-1.0633409130193252
435.00000000000546,48.80760305801752,0.6242007444608234,-1.101392518320751
436.1000000000055,48.91560507885436,0.6249821589179902,-1.1419494409046784
437.2000000000055,49.024109196542994,0.6255594715050412,-1.1810979413742517
438.3000000000055,49.1321656706204,0.6233923901125272,-1.2223707021435395
439.40000000000555,49.239239468369995,0.6179833344300306,-1.2631960805902156
440.50000000000557,49.34454377554973,0.6134611735456712,-1.3017303161831095
441.6000000000056,49.456158765514594,0.6055191110075707,-1.344673584928672
442.70000000000556,49.56333343463414,0.5942990091425675,-1.385176444631842
443.8000000000056,49.671539745735345,0.5807881658275061,-1.4230945051379038
444.9000000000056,49.779504758263684,0.57518597123691,-1.4596686384252742
446.0000000000056,49.88738457136732,0.5597014616756366,-1.4935383783059266
447.10000000000565,49.99548568638094,0.5469619305495589,-1.5269063882951395
448.2000000000057,50.10374412234871,0.5343168177775548,-1.5551715895171543
449.3000000000057,50.210968878272695,0.518422858296057,-1.5814257550945494
450.40000000000566,50.31952935471489,0.4973595658159211,-1.6045024205630116
451.5000000000057,50.42825222490302,0.47611590392330394,-1.6237410446332072
452.6000000000057,50.536235452648974,0.45690809849066816,-1.6429426591493117
453.70000000000573,50.64503156351285,0.43470873718610137,-1.6609571492391217
454.80000000000575,50.753547275038706,0.4136825265532643,-1.6780526046292183
455.9000000000058,50.8594502566134,0.39443578410095514,-1.691201801073281
457.0000000000058,50.96938332357824,0.37914144563788277,-1.7056378256994815
458.1000000000058,51.07768952665326,0.365663219367505,-1.7167457280997347
459.20000000000584,51.18680631347681,0.35408281311872636,-1.730972394964644
460.3000000000058,51.294930865502224,0.3446516902919925,-1.7429336360468528
461.40000000000583,51.40342706924588,0.33793245051921206,-1.7571335252285638
462.50000000000585,51.51234162881457,0.33308402686266025,-1.7698731415448958
463.6000000000059,51.621019780259275,0.32684985203017225,-1.7821090842486873
464.7000000000059,51.73089282628853,0.3250752262521053,-1.7938054098426375
465.8000000000059,51.83807368296406,0.32329815157318176,-1.8065834480230252
466.90000000000595,51.94688164052487,0.3168155538915157,-1.819279053648327
468.0000000000059,52.056387606726645,0.31577031898420493,-1.8330093697137135
469.10000000000593,52.16452547098453,0.3174428904752753,-1.8465123158409384
470.20000000000596,52.27228380171401,0.3115922240286514,-1.8596170888491397
471.300000000006,52.379050524555794,0.3112734158841629,-1.873673198571976
472.400000000006,52.48990222669847,0.3087695023724749,-1.8859405262188624
473.500000000006,52.598514859460664,0.30566678259258984,-1.895915081807578
474.60000000000605,52.70751099343168,0.2949241710348759,-1.9053646778311575
475.70000000000607,52.815644238368066,0.2713869105138411,-1.9149704437640898
476.8000000000061,52.92457380488859,0.25070320505610943,-1.922699329647112
477.90000000000606,53.03243730187658,0.22197924989089457,-1.931153865324771
479.0000000000061,53.13980807612165,0.1965115926028036,-1.937489259952891
480.1000000000061,53.24904432374547,0.17062952417405008,-1.9433694483903055
481.2000000000061,53.35645241575078,0.15240195231310116,-1.9466075286534568
482.30000000000615,53.46539960579749,0.13476127123901427,-1.948920367936616
483.4000000000062,53.575607598688215,0.1200197753401876,-1.9515505537697244
484.5000000000062,53.684696374885974,0.11382768643945573,-1.952191680818558
485.60000000000616,53.79318197325375,0.10596898410539435,-1.95418387002462
486.7000000000062,53.901430523676545,0.10334953074068676,-1.956260097036913
487.8000000000062,54.01103425571435,0.10259233580660743,-1.9591837942289292
488.90000000000623,54.11656772841708,0.10048442798213486,-1.9607493059415289
490.00000000000625,54.22776003234953,0.1000777620483464,-1.96328393479866
491.1000000000063,54.33636785602467,0.09808836014358902,-1.96604230880037
492.2000000000063,54.44534599702757,0.10279696711962982,-1.966033556855812
493.3000000000063,54.55362994260769,0.10582952646258403,-1.9673331203775697
494.40000000000634,54.66216743851523,0.10904491255628423,-1.9687032871777328
495.5000000000063,54.77041338919577,0.10947338728219447,-1.9699595864800346
496.60000000000633,54.87999904056648,0.1113441920354834,-1.9699600249246
497.70000000000636,54.9885981007212,0.11266022958760935,-1.97258969282285
498.8000000000064,55.09778568956038,0.11411464367977753,-1.973909299453493
499.9000000000064,55.206610533998614,0.11967162831462164,-1.975230148016812
501.0000000000064,55.31457575175889,0.12181361236913169,-1.975650613988373
502.10000000000645,55.42358477856715,0.12391161480117008,-1.9767670486779507
503.2000000000064,55.532114484498734,0.12601640222176247,-1.9794078163826638
504.30000000000643,55.6417885637027,0.12902028090035644,-1.9807159994539139
505.40000000000646,55.75000098080996,0.12771611231928104,-1.9810498710758466
506.5000000000065,55.8596993618083,0.13078415706823043,-1.9820301809515288
507.6000000000065,55.966938192130186,0.13312116888994663,-1.985008019799066
508.7000000000065,56.07634614316364,0.13072548897661418,-1.9856374474778717
509.80000000000655,56.18666130884755,0.13395262458037582,-1.985673094951526
510.90000000000657,56.29485514040091,0.1369879484747646,-1.9869812882037676
512.0000000000066,56.40287360633103,0.13601899552581942,-1.9889075369057445
513.1000000000065,56.51252955408227,0.138195887793771,-1.9895911088335185
514.2000000000066,56.622601995154646,0.1342707295353125,-1.9918999885468391
515.3000000000065,56.7318303824436,0.13794521381625569,-1.9932202574271756
516.4000000000067,56.84056731392908,0.13954496216042367,-1.9945296620468516
517.5000000000066,56.94989484241676,0.13996865891907628,-1.9971697367251093
518.6000000000067,57.06072624989959,0.14289874376269585,-1.9961800489452406
519.7000000000066,57.169424128608654,0.14168694417768557,-1.9974888600489504
520.8000000000067,57.27933535467092,0.14383619739114528,-1.9988099775780852
521.9000000000067,57.38828058666822,0.14452811707261448,-2.0001294033280126
523.0000000000067,57.49865620970971,0.14333182004494915,-2.0014877040437433
524.1000000000067,57.60706098559769,0.1461638690273941,-2.0027682790364296
525.2000000000068,57.717315991971354,0.14654934412799192,-2.0041000117797387
526.3000000000068,57.82593779687507,0.14507968459065723,-2.005388175532759
527.4000000000068,57.93493474700516,0.1452021051794441,-2.0067101074211786
528.5000000000068,58.04484984310909,0.14494336404835528,-2.008020811471608
529.6000000000068,58.1542540326179,0.14624195731528644,-2.010120550472169
530.7000000000069,58.26435560275531,0.148817766260275,-2.0106591154697955
531.8000000000068,58.373897707505705,0.1495502337752288,-2.011971689248858
532.9000000000069,58.48280482237296,0.14727690328763998,-2.014472036258118
534.0000000000068,58.59180062319985,0.14667072956958416,-2.0146106035364233
535.100000000007,58.70106318829798,0.14854061651357076,-2.0159221617104253
536.2000000000069,58.810415633622874,0.15163766663540112,-2.01723809747206
537.300000000007,58.919895874871365,0.14821984701986035,-2.018555519854394
538.4000000000069,59.03048723253241,0.14864489749898824,-2.020232403572253
539.5000000000069,59.13891969586301,0.15103909965926032,-2.0227473616634133
540.600000000007,59.2488671848071,0.15001964546443558,-2.0251387333277133
541.700000000007,59.355315344980156,0.14761789596490726,-2.026110031844025
542.800000000007,59.467767744187725,0.14997636558636307,-2.0264535033108158
543.900000000007,59.57710703718103,0.15233503316528418,-2.0277613276181703
545.000000000007,59.6859883181109,0.1509758154017362,-2.030399397940215
546.1000000000071,59.79662368343061,0.1511054088286281,-2.0317119454329147
547.2000000000071,59.90419200286124,0.15150679604134276,-2.033083013449162
548.300000000007,60.01515425749725,0.14970608553596643,-2.0356622948104155
549.4000000000071,60.124637646607766,0.15015709212573713,-2.03691874493054
550.500000000007,60.23393473713028,0.1486432663516557,-2.0396062665458308
551.6000000000072,60.34466604828387,0.14962953732809492,-2.0409303536588754
552.7000000000071,60.453334362708446,0.14807639753280077,-2.0435642562815852
553.8000000000072,60.56362815641936,0.149773679486211,-2.043568633800986
554.9000000000071,60.67465879927364,0.14788635042187193,-2.046126846448285
556.0000000000072,60.783840828907984,0.14414641592008248,-2.047523386910872
557.1000000000072,60.89389537212882,0.14301608951781675,-2.0505670742762847
558.2000000000072,61.00428043709399,0.14528688356275854,-2.051135434488642
559.3000000000072,61.11475176589912,0.1440927108388672,-2.0538155112829513
560.4000000000073,61.223614548645315,0.1445300921502679,-2.056574946561838
561.5000000000073,61.33466528422196,0.1454996352833815,-2.0591642836131707
562.6000000000073,61.443719872952066,0.14585305673347082,-2.061766512996098
563.7000000000073,61.55368739605622,0.1457337113155679,-2.065467690198875
564.8000000000073,61.664080316994664,0.14728575150149892,-2.065637512623197
565.9000000000074,61.774387663244745,0.14776971061406718,-2.0705747617624577
567.0000000000074,61.88403461117346,0.15250601253283613,-2.0731387733434063
568.1000000000074,61.99489759032247,0.15384419411775108,-2.0768440452320442
569.2000000000073,62.10416357503965,0.15795476802605402,-2.079547003810185
570.3000000000073,62.212918286961646,0.15909717184985794,-2.083123337317646
571.4000000000074,62.324717736431815,0.16076007617646781,-2.086702670862871
572.5000000000074,62.4347410398218,0.16421610896586358,-2.0914543476050675
573.6000000000074,62.54406017180227,0.16678657759222082,-2.096217910354448
574.7000000000074,62.65430813271971,0.16700924943367212,-2.1002126493025006
575.8000000000075,62.76464441096891,0.17513499659880516,-2.1034224382292948
576.9000000000075,62.87567423990431,0.17544488603265518,-2.1046350245641006
578.0000000000075,62.98516449842511,0.17755288401237945,-2.112244148013931
579.1000000000075,63.09520147742011,0.1807533135872339,-2.1168667775734944
580.2000000000075,63.206314127869376,0.18269691738794203,-2.1216500289167155
581.3000000000076,63.31588161585496,0.18149692069192302,-2.1263343690627474
582.4000000000076,63.425571704950436,0.1828372674605272,-2.131620646542673
583.5000000000076,63.53439499249172,0.1841891165709626,-2.1383601491644355
584.6000000000076,63.64625804720645,0.18172176620095648,-2.1443548688946334
585.7000000000077,63.75618631045311,0.1835144023673907,-2.15150608782306
586.8000000000077,63.865486223484616,0.18481505287733757,-2.158025228713976
587.9000000000076,63.97612772679026,0.18400326089845986,-2.164173569100556
589.0000000000076,64.08600114899644,0.18471006644770793,-2.1704941028166065
590.1000000000076,64.19593548632237,0.18304102090355734,-2.177280500041093
591.2000000000077,64.30711030889054,0.1835681786271106,-2.183484379032173
592.3000000000077,64.41733927295428,0.1855726974307279,-2.1924412616332987
593.4000000000077,64.52729516261336,0.1846006804388518,-2.2011447810159863
594.5000000000077,64.63664394372607,0.18708707845651795,-2.207077073762332
595.6000000000078,64.74790260078706,0.18447055740874507,-2.214298432746768
596.7000000000078,64.85837866038602,0.18758181192573353,-2.222719136811778
597.8000000000078,64.96859114271611,0.18629885663443102,-2.230333309958333
598.9000000000078,65.07829315780766,0.18575664568106998,-2.2383869798508367
600.0000000000078,65.18980474045645,0.18567083495811243,-2.2476614014587293
601.1000000000079,65.30062559363,0.18477890395140606,-2.255416753079686
602.2000000000079,65.41050224912132,0.1863283668926865,-2.2637533304565016
603.3000000000079,65.52316373782156,0.1795429463296867,-2.2713766311892356
604.4000000000078,65.63201170909896,0.1805563627242044,-2.281757066518889
605.5000000000078,65.74379277788186,0.17958231427615967,-2.2888267772200397
606.6000000000079,65.85421663313039,0.17988864598156096,-2.2967932659688195
607.7000000000079,65.9645855291131,0.17807006439542938,-2.3050828281030675
608.8000000000079,66.07511382665328,0.1750519080462387,-2.3125981831633613
609.9000000000079,66.18552756863234,0.17329574057428387,-2.320624489533496
611.000000000008,66.29586444497005,0.17393936181692182,-2.3254282680887215
612.100000000008,66.40666124167451,0.18028923527585095,-2.330070003143515
613.200000000008,66.51442232071096,0.18717339826367851,-2.3336185700950907
614.300000000008,66.62698266897168,0.18394356544382395,-2.335797481779191
615.400000000008,66.737827863375,0.18189258568516764,-2.3370896520457594
616.5000000000081,66.8478750697551,0.18037194168234705,-2.338713838731211
617.6000000000081,66.95863848593544,0.18397680548226636,-2.34106209128681
618.7000000000081,67.06940178558676,0.19229565167684792,-2.342353007613416
619.8000000000081,67.18037018676871,0.20465218484016634,-2.3423499123343747
620.9000000000082,67.29104549732628,0.21994136583486834,-2.3430918257152262
622.0000000000082,67.40136009771751,0.2284420313791038,-2.3449879512636578
623.1000000000081,67.51217335983945,0.23947320660778848,-2.3476254223268818
624.2000000000081,67.62268030683823,0.24736878712116384,-2.3489848455336224
625.3000000000081,67.73413496958484,0.25689865923697797,-2.3504366237092325
626.4000000000082,67.84381758333868,0.2592184040664547,-2.350590306900912
627.5000000000082,67.95425025502034,0.2669660435951755,-2.351898230498972
628.6000000000082,68.06556347514355,0.27004359525801314,-2.352973353914103
629.7000000000082,68.17719788041057,0.2764675008132902,-2.355545867335426
630.8000000000083,68.28678778013516,0.281655333703809,-2.359452206509226
631.9000000000083,68.39701931002955,0.28414745280012665,-2.3619833605576273
633.0000000000083,68.5085227157316,0.28991027970834327,-2.3633714155168937
634.1000000000083,68.61722526026573,0.29823308852386243,-2.365452092955285
635.2000000000083,68.73042981377675,0.30202472698018523,-2.366701484074639
636.3000000000084,68.84038392092741,0.3074786118273263,-2.367363256544103
637.4000000000084,68.95039854904671,0.31565754359633424,-2.37013363687457
638.5000000000084,69.06151608297186,0.32132568802285677,-2.3714180293008593
639.6000000000083,69.1727908943986,0.33043260928439744,-2.3740278405206543
640.7000000000083,69.28310312354336,0.3348637593411665,-2.3755151278789266
641.8000000000084,69.39393263239135,0.3445353139667213,-2.3784075919886662
642.9000000000084,69.50514749652903,0.352385047844501,-2.3803925244208335
644.0000000000084,69.61570747426255,0.36138839807509826,-2.3830287688747545
645.1000000000084,69.72768053072777,0.37036485947718356,-2.3856964891592503
646.2000000000085,69.839157180584,0.38056197800831026,-2.38698983990116
647.3000000000085,69.94927869442887,0.39161910568626546,-2.3897282464871137
648.4000000000085,70.05999813019504,0.4038813092271907,-2.391049851543589
649.5000000000085,70.1707582234608,0.4150763256414649,-2.394008866928005
650.6000000000085,70.28132125144539,0.42755485797459025,-2.396629397289672
651.7000000000086,70.39292014840461,0.4384109620278698,-2.3996352740747957
652.8000000000086,70.50311917077354,0.45528807258720083,-2.403742545707428
653.9000000000086,70.61512034968544,0.46601239653788795,-2.4055369316506816
655.0000000000086,70.72496702015547,0.47880879553339417,-2.4078275158455282
656.1000000000087,70.83579542464955,0.4959062272670707,-2.411758369201868
657.2000000000087,70.94736210736262,0.512750542901623,-2.41607331948073
658.3000000000086,71.05819996229738,0.5286877522742,-2.4202244607725065
659.4000000000086,71.169290104757,0.551169167327267,-2.4229306403350717
660.5000000000086,71.28052583365472,0.5671553298929561,-2.427146451634751
661.6000000000087,71.39195022037238,0.5819108197416838,-2.432501166887022
662.7000000000087,71.49900334453925,0.6022598524410461,-2.4364934509921925
663.8000000000087,71.61065657867063,0.6241373447107956,-2.4383988480106673
664.9000000000087,71.72342993799893,0.6452204917161091,-2.4408673062450403
666.0000000000088,71.83445708832764,0.6673772342581945,-2.450039368961272
667.1000000000088,71.94427960173549,0.6854663828866072,-2.4535169293886003
668.2000000000088,72.05609017478798,0.70710616617751,-2.4578981043589856
669.3000000000088,72.16625445353355,0.7309179264604535,-2.462266445600739
670.4000000000088,72.27705711602502,0.7536668383417306,-2.4681614132812313
671.5000000000089,72.38808844831458,0.7775829921668693,-2.4743729457501646
672.6000000000089,72.499624642548,0.8024640918464498,-2.4808882321041184
673.7000000000089,72.61020920747987,0.8252604706339555,-2.4850707251332604
674.8000000000088,72.72079846215706,0.850243666046463,-2.492280821063815
675.9000000000088,72.83206342069882,0.8719257113702068,-2.498926176429789
677.0000000000089,72.94309697051632,0.8948296022568718,-2.503191243274843
678.1000000000089,73.05454352857933,0.9179745687567664,-2.5104852855854425
679.2000000000089,73.16642677895172,0.9412315319066853,-2.5169078211141027
680.3000000000089,73.27701586181928,0.9687989357048878,-2.52421674057206
681.400000000009,73.38769875282517,0.9933652591204984,-2.529842748424918
682.500000000009,73.49934686523937,1.0228849910456037,-2.535665121881368
683.600000000009,73.6111468947176,1.047954909725985,-2.5440190620827554
684.700000000009,73.72198474884725,1.0753084445068672,-2.552545198839458
685.800000000009,73.8327348635431,1.0996183640425135,-2.5604951123207345
686.9000000000091,73.94429213896575,1.1272061865319531,-2.5671661561880565
688.0000000000091,74.05501857888532,1.1535945169586796,-2.575169166104936
689.1000000000091,74.16698525139282,1.1841701852434618,-2.5836510327786844
690.2000000000091,74.27835896869644,1.2091574954632645,-2.5924798056986402
691.3000000000092,74.38980287376991,1.2337143695624984,-2.6010606004454413
692.4000000000092,74.50083097355888,1.2655071920464172,-2.610078134681781
693.5000000000091,74.6115711665335,1.2929288322799024,-2.6214530721131215
694.6000000000091,74.72305803428426,1.3179010041220554,-2.6298920878208882
695.7000000000091,74.83413701165448,1.3439767070832793,-2.6398919787735933
696.8000000000092,74.94570709004411,1.3739684856810723,-2.6475588471829736
697.9000000000092,75.05455871119064,1.3975200115557183,-2.658247236293094
699.0000000000092,75.16756419787333,1.4236067716180225,-2.6682292393716427
700.1000000000092,75.27862512559804,1.4487935138653825,-2.6790643099137843
701.2000000000093,75.39093706214163,1.468684667469596,-2.6890730600705637
702.3000000000093,75.50292750189651,1.4923176147641997,-2.6990857434149618
703.4000000000093,75.61424905973873,1.5136315623879062,-2.711636981773507
704.5000000000093,75.72560189296529,1.529697400120719,-2.721501289797682
705.6000000000093,75.83709355774869,1.5447315268930042,-2.7314534278790275
706.7000000000094,75.94751692244546,1.5575053104911212,-2.7420015025258646
707.8000000000094,76.06039013532786,1.5691363147989155,-2.754289421542633
708.9000000000094,76.17019561090153,1.5753624022551933,-2.765975106553506
710.0000000000093,76.28231018614271,1.5739543125344326,-2.7764797424301477
711.1000000000093,76.39299728284232,1.5598912363383688,-2.7868526230210127
712.2000000000094,76.50511240665925,1.5419541145337397,-2.7982544688110886
713.3000000000094,76.61609621302026,1.5113820135806593,-2.8078568994279216
714.4000000000094,76.7278729291677,1.4578555964035924,-2.8171189992055843
715.5000000000094,76.8381747296947,1.389771143525508,-2.8273915783290082
716.6000000000095,76.94829861749665,1.2822873111976931,-2.8360694955736783
717.7000000000095,77.06042656554895,1.1231080274632617,-2.8433184977570507
718.8000000000095,77.17086839979162,0.8926994136050184,-2.8512317978533357
719.9000000000095,77.28156454276456,0.5879219677484098,-2.85840483966998
721.0000000000095,77.39146358266926,0.2886751859723611,-2.8601405541343468
722.1000000000096,77.50345944735805,0.1147318081229376,-2.8626966987732256
723.2000000000096,77.61284368486656,0.03037592406500167,-2.8640099529648975
724.3000000000096,77.72292619192955,-0.01354536354085778,-2.864927114883618
725.4000000000096,77.83383239324056,-0.03825251362771742,-2.863935465381914
726.5000000000097,77.94459133696387,-0.052698762640146946,-2.86624502136773
727.6000000000097,78.05601055802612,-0.061457417675726544,-2.8679607531299496
728.7000000000096,78.16767285643553,-0.07035477535088264,-2.8679601815465974
729.8000000000096,78.2766380315658,-0.07556162774585529,-2.8666492627015914
730.9000000000096,78.388779047653,-0.07489409042750439,-2.8666501982280543
732.0000000000097,78.5005075455849,-0.07960797537543751,-2.867970201441022
733.1000000000097,78.61177765024482,-0.08096860342277479,-2.8679704542312305
734.2000000000097,78.722255538295,-0.0933153832310527,-2.868639323682835
735.3000000000097,78.83541281480119,-0.09227374190812832,-2.870639516094501
736.4000000000098,78.94601178561894,-0.09299426405445876,-2.8692801583151937
737.5000000000098,79.05725282898433,-0.09457503968710457,-2.8702976016747446
738.6000000000098,79.16934302004486,-0.09496996104483868,-2.870269967997185
739.7000000000098,79.28010534843062,-0.09698605735251808,-2.870269967389892
740.8000000000098,79.3914522408586,-0.09735055321885278,-2.8689515998613535
741.9000000000099,79.50426954921316,-0.0980006473145667,-2.869279788823603
743.0000000000099,79.61557329637489,-0.09809718044847138,-2.8695663939106524
744.1000000000099,79.72716043074402,-0.10139356165460489,-2.872347105907827
745.2000000000098,79.83741965089678,-0.1021891768922143,-2.8733402002401194
746.0000000000099,79.92009368582958,-0.08530919696460826,-2.872024593816746