File: 01_Data/Cotton_Rug/STA/N2/30K_min/Cotton_Rug_STA_N2_30KData_220113_R1.csv
##Temp./Â°C,Time/min,DSC/(mW/mg),Mass loss/mg
49.0,10.54786321898488,0.04195560625206951,-0.00945500784794806
50.20000000000002,10.742561897346144,0.09389498783616179,-0.011270684099538464
51.400000000000034,10.866118543549847,0.13715607654926465,-0.011422131417275772
52.60000000000005,10.967547171540796,0.17896897211187857,-0.010470668001041794
53.80000000000007,11.051972215881781,0.2115701161818786,-0.011548597371668912
55.000000000000085,11.128146833357361,0.24566820854529237,-0.011598752355431508
56.2000000000001,11.19818019817561,0.2757620139783483,-0.011484771285790174
57.40000000000012,11.262611769202923,0.3012988151024496,-0.011392419384753438
58.600000000000136,11.325446826053224,0.3255809106054318,-0.011959523004075656
59.80000000000015,11.383680201674705,0.35075406485044935,-0.011252356073594427
61.00000000000017,11.440745395587738,0.37179044472373735,-0.011179914143617076
62.20000000000019,11.495007377699643,0.3926998623296013,-0.012162467021382461
63.400000000000205,11.547579153785987,0.4109252565749386,-0.012793085620887545
64.60000000000022,11.5991139414865,0.4279537362582482,-0.011602269351150163
65.80000000000024,11.649738212612247,0.4455524822965614,-0.012262615327559345
67.00000000000026,11.698890890707686,0.4633416486011423,-0.011288266602051067
68.20000000000027,11.74751711765001,0.47840729495276557,-0.011369570197608425
69.40000000000029,11.794747435355207,0.493793844298311,-0.012744598470775692
70.6000000000003,11.842168740339874,0.5093098726845801,-0.013033940923157239
71.80000000000032,11.888636340687667,0.519698478284352,-0.012658932040078064
73.00000000000034,11.93433289813048,0.5280672133563871,-0.013902387883228506
74.20000000000036,11.979604755332458,0.5352144765291799,-0.013298618146725616
75.40000000000038,12.02491041513721,0.5404377180964635,-0.012280704079113747
76.60000000000039,12.069345846343055,0.5488154332580165,-0.012155138745137073
77.80000000000041,12.11354014015128,0.5538592877056698,-0.013686269999349854
79.00000000000043,12.158049077023708,0.5588875604965308,-0.014616244497751119
80.20000000000044,12.20137064335851,0.5645721131868953,-0.013972556036926598
81.40000000000046,12.24458431584581,0.5691519676017738,-0.014106396352278061
82.60000000000048,12.287792361001978,0.5778083253486109,-0.014532040769520194
83.8000000000005,12.33067795863054,0.5813644133728368,-0.015589898530404156
85.00000000000051,12.372917106878283,0.5899051432828231,-0.014495657457074707
86.20000000000053,12.41516605130802,0.5928422594220353,-0.014588418720316909
87.40000000000055,12.457247089027247,0.5997711262104908,-0.014699670595107683
88.60000000000056,12.4989296818586,0.6062970609928695,-0.015103426694073718
89.80000000000058,12.540971544946357,0.6106973466371801,-0.015968390197351745
91.0000000000006,12.582433123681497,0.6147434593240949,-0.01601908928850193
92.20000000000061,12.624110382907423,0.6214713858968144,-0.015034005570205622
93.40000000000063,12.665673562907733,0.6262237109947664,-0.01570985379295209
94.60000000000065,12.707003890894232,0.6323884437795539,-0.01611903157965422
95.80000000000067,12.747270154867024,0.6360130083225575,-0.016789924451579452
97.00000000000068,12.788790185003142,0.6398078336681827,-0.016130719397972726
98.2000000000007,12.829455106063293,0.6429259678765684,-0.017541285887226366
99.40000000000072,12.870033300066332,0.6491280297640776,-0.017155752906664823
100.60000000000073,12.911442645490995,0.6504551349847236,-0.017386055147059487
101.80000000000075,12.951825220148818,0.6560361573992534,-0.018676893899021607
103.00000000000077,12.992470722637307,0.6613288387692449,-0.018725825786208183
104.20000000000078,13.032951677059499,0.6661976204420441,-0.018789475169060488
105.4000000000008,13.072938873447386,0.6689299192266123,-0.017478350397262865
106.60000000000082,13.113662897960554,0.6716188988974621,-0.018763266374824283
107.80000000000084,13.153844226732579,0.6753480877724256,-0.01877920637596464
109.00000000000085,13.19429633008975,0.6769769535163278,-0.020067407019934702
110.20000000000087,13.234852027937483,0.6821102630528812,-0.019930453060933218
111.40000000000089,13.27507321405195,0.682712321561726,-0.02006925479925492
112.6000000000009,13.315380589052436,0.6850002934292211,-0.020069878894975357
113.80000000000092,13.355590999280853,0.688275129911947,-0.020074474135767684
115.00000000000094,13.395827381820755,0.6901447443707465,-0.019344174423429727
116.20000000000095,13.436175214553645,0.690919748173035,-0.020077065860776067
117.40000000000097,13.475731152498515,0.695753460882506,-0.02008741497561317
118.60000000000099,13.515732596290821,0.6987256186148022,-0.021390198771138458
119.800000000001,13.555624285674234,0.700421956341844,-0.02139012737506274
121.00000000000102,13.594894055160502,0.7031926145162054,-0.021388260207766407
122.20000000000104,13.634366046456543,0.7043613227784332,-0.020983825068105144
123.40000000000106,13.674063464566629,0.7050946153478312,-0.02138393010253825
124.60000000000107,13.713605492676397,0.7070659010882596,-0.02139000096903665
125.80000000000109,13.753276117323843,0.7102582142765188,-0.021407832584519504
127.00000000000111,13.79324111037075,0.7122901608898007,-0.022717462970737845
128.20000000000113,13.831919620944818,0.7116153837587927,-0.022711398054497067
129.40000000000114,13.871459116586225,0.7147457966215358,-0.02193180468997724
130.60000000000116,13.91071633524165,0.714256593212846,-0.021907487130734538
131.80000000000118,13.949873132101562,0.718129211347046,-0.022700755252836657
133.0000000000012,13.98919381130726,0.7198399603503801,-0.02270020306668563
134.2000000000012,14.027972538507653,0.7199368937968473,-0.022700219565090052
135.40000000000123,14.067167075671577,0.7227467535609677,-0.02270483603608442
136.60000000000124,14.10598443731406,0.7274099481093113,-0.0214121971667387
137.80000000000126,14.145278324041575,0.7281251833595023,-0.021389613813023622
139.00000000000128,14.18414719258641,0.7314362493223097,-0.02265952761025325
140.2000000000013,14.222984620181794,0.7362609417214748,-0.024286227070218658
141.4000000000013,14.261285479564357,0.7373068746371452,-0.0242404066980777
142.60000000000133,14.300099401139418,0.7424423011660083,-0.024239529085527955
143.80000000000135,14.338717593081418,0.743107518126014,-0.0242212253834988
145.00000000000136,14.377198742595336,0.7483122029107354,-0.02259138943603567
146.20000000000138,14.415511315231909,0.7531329255078598,-0.022589920887429393
147.4000000000014,14.453829801035807,0.7557362503562821,-0.022589697347953575
148.60000000000142,14.492031105161221,0.7586862089646593,-0.022543476253307215
149.80000000000143,14.530255070405955,0.7645750624828043,-0.024002877712105963
151.00000000000145,14.568611840397194,0.7648297003411452,-0.024011876493740925
152.20000000000147,14.606933589568591,0.7691503862992883,-0.022562063898214024
153.40000000000148,14.645038089415943,0.77250988668883,-0.02266934634096085
154.6000000000015,14.683000210641776,0.7763503728255037,-0.023916654948953564
155.80000000000152,14.721019906315359,0.7810677820882139,-0.023910184921528632
157.00000000000153,14.759186362363764,0.7849630862924275,-0.0239101679052931
158.20000000000155,14.797204145072367,0.7898065997259185,-0.02391016800547119
159.40000000000157,14.835414454516767,0.7922790158301032,-0.023910167892585044
160.6000000000016,14.873111027473659,0.798080610956768,-0.023909954245429965
161.8000000000016,14.91096541275525,0.8012402311987349,-0.024662747543100494
163.00000000000162,14.948570231974479,0.8020098868650491,-0.02390446829944448
164.20000000000164,14.986973647889783,0.8063942716263008,-0.023919894098022976
165.40000000000165,15.024402389870607,0.8100559473177211,-0.023920048650504455
166.60000000000167,15.062363617256473,0.813936683229928,-0.023920032393252466
167.8000000000017,15.099812360359701,0.8171588572629256,-0.023918044578578268
169.0000000000017,15.137537695830595,0.8219312698186657,-0.024569607711277808
170.20000000000172,15.17510597840386,0.8234341498742768,-0.02522268304725417
171.40000000000174,15.21268638228801,0.8281378287742436,-0.02490894197434379
172.60000000000176,15.250196917216082,0.8336636794946112,-0.024871417609598545
173.80000000000177,15.288061997693095,0.8360586479973988,-0.02621817050344255
175.0000000000018,15.325443062308764,0.839118877903956,-0.026220022621641803
176.2000000000018,15.362893667332257,0.843860800234146,-0.026196509162050408
177.40000000000182,15.400491983361198,0.8443973921841021,-0.02489369799724095
178.60000000000184,15.437606258973808,0.8492602312547062,-0.024899940020393085
179.80000000000186,15.474950083613356,0.854330861456877,-0.02530286720723751
181.00000000000188,15.51223539648185,0.8579731492207221,-0.026142814889592803
182.2000000000019,15.54959199923447,0.8611090303819381,-0.02764716291226721
183.4000000000019,15.586760695641608,0.8650113418416542,-0.027630456132916148
184.60000000000193,15.624004854684177,0.8659758476370435,-0.02632678164384794
185.80000000000194,15.660718390413397,0.8708604312267562,-0.026329986217297652
187.00000000000196,15.697444636748681,0.8748071389618527,-0.026330998666747707
188.20000000000198,15.735017799573638,0.8753144093124611,-0.025639067825882655
189.400000000002,15.771925736831008,0.8807051087630061,-0.025341494951610866
190.600000000002,15.808839801444964,0.881946696759442,-0.02658150914863011
191.80000000000203,15.845626247780435,0.8855237011032396,-0.026658408129856426
193.00000000000205,15.882878291647046,0.8890520713581205,-0.026656574436199953
194.20000000000206,15.919109395729864,0.8932707815174138,-0.027986195073895104
195.40000000000208,15.956084080617064,0.8954997512903399,-0.027971122121095426
196.6000000000021,15.992955896251258,0.8988365360187588,-0.02803028463308932
197.80000000000211,16.0295469027065,0.9044237730521898,-0.027089548285125886
199.00000000000213,16.0663697262911,0.9059394434207326,-0.027982850672826576
200.20000000000215,16.1032997115035,0.908713438995421,-0.027980030680471835
201.40000000000217,16.139633738303313,0.9138713386495357,-0.027980925729553352
202.60000000000218,16.17654254743978,0.9185062424375995,-0.02900436300966902
203.8000000000022,16.213138249671786,0.9220998501104768,-0.029323938614430833
205.00000000000222,16.250031507305955,0.9261489077730747,-0.029290357776278864
206.20000000000223,16.28655129603505,0.9292759729108403,-0.029250299558390758
207.40000000000225,16.323415544130086,0.9356938164600509,-0.031274030969375755
208.60000000000227,16.359908587084036,0.9357077595207306,-0.0312711670757726
209.80000000000229,16.396628506697596,0.9433217377417473,-0.029933158239212165
211.0000000000023,16.432918781674,0.947388635897979,-0.029949587646905584
212.20000000000232,16.4697862513295,0.9526881926314282,-0.029949848014769742
213.40000000000234,16.506377703184203,0.9545798746466426,-0.029947980950813413
214.60000000000235,16.542698337838843,0.9580767879037974,-0.0303908014282972
215.80000000000237,16.579430217611222,0.961204991026618,-0.030610147448863145
217.0000000000024,16.615848192416426,0.9647483023532902,-0.030623969097171244
218.2000000000024,16.652514008562118,0.968992285077908,-0.031967108805705635
219.40000000000242,16.689117351839684,0.968763484832249,-0.031919890190548195
220.60000000000244,16.725432642801405,0.97089465726261,-0.03191980815930373
221.80000000000246,16.76210622107005,0.9758262053057783,-0.03188863088643945
223.00000000000247,16.798279057523683,0.9788394062054607,-0.033166582950881374
224.2000000000025,16.834860001543912,0.9852541052805112,-0.03454723125383019
225.4000000000025,16.871067139140045,0.9874962207485088,-0.0343432709566458
226.60000000000252,16.907501995382024,0.9911851954466332,-0.03324016103634664
227.80000000000254,16.943787076025277,0.9965930751038748,-0.03323984673930358
229.00000000000256,16.98065609113564,1.0006680691726322,-0.033241419537811456
230.20000000000258,17.016720012719976,1.0043987953044409,-0.034142819929830814
231.4000000000026,17.053569475809443,1.0081138346538818,-0.03421870213431166
232.6000000000026,17.089549609894096,1.0157077332528108,-0.034219702755839077
233.80000000000263,17.12610772953925,1.0215546547753214,-0.03519677764730167
235.00000000000264,17.162617218594555,1.0305210298618817,-0.03553823162730163
236.20000000000266,17.19886497381127,1.0406265941300852,-0.03553972168193775
237.40000000000268,17.235604613999918,1.0511900352621515,-0.035452913311450285
238.6000000000027,17.27173245563771,1.0620634715565882,-0.03684886056859549
239.8000000000027,17.30800650678918,1.0816040093416697,-0.03683625273187818
241.00000000000273,17.34454086042164,1.104346614343081,-0.037204261913878156
242.20000000000275,17.380696308724147,1.1294912611551124,-0.03850227368556336
243.40000000000276,17.41717859550028,1.1571649484473894,-0.03844853018188399
244.60000000000278,17.453586195012694,1.1871711048782332,-0.03980436780087526
245.8000000000028,17.489906785355444,1.2185447605458484,-0.04046242591683269
247.0000000000028,17.526404320680165,1.2579935786193235,-0.04113278164122036
248.20000000000283,17.562822687786433,1.319002597076754,-0.04113024533672682
249.40000000000285,17.599162270926218,1.3981997257972907,-0.04112709192399677
250.60000000000286,17.635484264255286,1.4817163123313746,-0.04239869695072951
251.80000000000288,17.67165704003529,1.5572229374793691,-0.04244845543042919
253.0000000000029,17.708222583595028,1.6160199590793813,-0.042964550629166265
254.20000000000292,17.744993923520305,1.6481760301288393,-0.043757213864002775
255.40000000000293,17.78110990083309,1.63798405199457,-0.044833473433742554
256.600000000003,17.81804414954093,1.5779836603327864,-0.04508009357267184
257.80000000000297,17.85446920469903,1.505832307331667,-0.04509161774423287
259.00000000000296,17.890368133397374,1.4290736855401553,-0.0440834811631472
260.200000000003,17.92670903396669,1.3633372041126945,-0.04553704058730812
261.40000000000305,17.96323136112472,1.3091146457504075,-0.04746892287531024
262.60000000000304,17.999053685614417,1.2614089033840878,-0.04985460055823898
263.800000000003,18.035382946604262,1.2246422787915203,-0.051510124510555144
265.00000000000307,18.07142910004925,1.1957595893114212,-0.054042034119115456
266.2000000000031,18.107883052490955,1.1739683902687337,-0.05541394211528594
267.4000000000031,18.144030744876893,1.1573539989981034,-0.056884114778975814
268.6000000000031,18.1798811906165,1.1448293555889244,-0.058362377744045624
269.80000000000314,18.216048320274535,1.133468385926461,-0.058351865966311145
271.0000000000032,18.252383088240027,1.1292585063702947,-0.05960556348691615
272.2000000000032,18.288371674040025,1.1227669807544767,-0.06101964814396155
273.40000000000316,18.324661036055417,1.1222342868578896,-0.06385261861254277
274.6000000000032,18.360818969954956,1.1196002458249097,-0.06540366246036067
275.80000000000325,18.39695303186204,1.118791296028652,-0.0668921742362274
277.00000000000324,18.43343973083381,1.1167759069524348,-0.06837681692354636
278.20000000000323,18.469453865880393,1.117792739958774,-0.07057976236028995
279.4000000000033,18.505810259577437,1.1230194603623327,-0.0727851530589958
280.6000000000033,18.541780273262727,1.1220570337093467,-0.07466070831315541
281.8000000000033,18.57826977726453,1.1244640329506195,-0.07791584467439616
283.0000000000033,18.614527285319767,1.1292243061229992,-0.08000366406500525
284.20000000000334,18.65057345877368,1.1335706156718708,-0.08165243747018991
285.4000000000034,18.686671500218402,1.1363551968726475,-0.08453028880300817
286.6000000000034,18.723137615279185,1.1405561100646187,-0.08725322089508225
287.80000000000337,18.7597298476661,1.1432852114448395,-0.09079090813564772
289.0000000000034,18.795780050013253,1.1493907085862558,-0.09470176534849406
290.20000000000346,18.832214659760734,1.152402240674003,-0.09788646426581504
291.40000000000344,18.868456779847442,1.1589357474390534,-0.10033199255370429
292.60000000000343,18.904422316015335,1.1658542210273979,-0.10367274980932395
293.8000000000035,18.94078381698506,1.1700015147657559,-0.10788248527679078
295.0000000000035,18.977283921510434,1.1789948178636085,-0.11178633982163122
296.2000000000035,19.01398345580933,1.1862436954665734,-0.11535164600103265
297.4000000000035,19.04987624931351,1.1914073360758808,-0.11954614276670572
298.60000000000355,19.086143246020992,1.1984459312526583,-0.12443963173095085
299.8000000000036,19.122311480293586,1.208960769047309,-0.1288201574984531
301.0000000000036,19.159151312835434,1.2162002180499385,-0.13411238220907507
302.20000000000357,19.19512978931753,1.2229480331649343,-0.1397267013743888
303.4000000000036,19.231538971294494,1.2317247997106415,-0.14508048297532739
304.60000000000366,19.26767977365517,1.2405995098980345,-0.15000308173205745
305.80000000000365,19.303539505551953,1.2497038384286843,-0.15618933971264237
307.00000000000364,19.340932726032335,1.2593943027680436,-0.16166739773709882
308.2000000000037,19.377032833159205,1.2674679612700077,-0.16823109508777323
309.40000000000373,19.413331830664724,1.2766733799346917,-0.17605993464431346
310.6000000000037,19.449880883239835,1.28701259194142,-0.18282397403548556
311.8000000000037,19.486086951145904,1.294695993974321,-0.18821435690341115
313.00000000000375,19.52267030956231,1.3056824020350395,-0.195622206234372
314.2000000000038,19.55896496987844,1.3165590895843797,-0.20165805085722432
315.4000000000038,19.595235091077257,1.3228555307101095,-0.20822576431900686
316.6000000000038,19.631670788194803,1.3307862262974222,-0.21891858553357801
317.8000000000038,19.668444439043945,1.341423900555075,-0.2284678545788883
319.00000000000387,19.70443004895453,1.3472436262385201,-0.2372497880624156
320.20000000000385,19.741433513955492,1.3545299157849076,-0.24589401373987352
321.40000000000384,19.777549702098916,1.3633521108223394,-0.25488687598349635
322.6000000000039,19.813999304114187,1.3711707438102751,-0.26540522996469784
323.80000000000393,19.849939500662774,1.377429548388819,-0.2751968100125941
325.0000000000039,19.88676757721613,1.388201459119485,-0.2868512530712364
326.2000000000039,19.923561119552712,1.3920449080117117,-0.29871842778549773
327.40000000000396,19.96033518395848,1.403039045531132,-0.3107131585467191
328.600000000004,19.996604417930214,1.411066336494477,-0.32216763893222744
329.800000000004,20.03319269234248,1.4192126669577885,-0.335136475345017
331.000000000004,20.06966941514775,1.4293786530078523,-0.3482394909168667
332.200000000004,20.106220570960275,1.4415588100146803,-0.3617852331109055
333.40000000000407,20.142857637994748,1.4563166531896867,-0.3756894894906915
334.60000000000406,20.179363774156805,1.471229158710252,-0.3898439431677825
335.80000000000405,20.21591057187138,1.4901294772315201,-0.405334457427748
337.0000000000041,20.25261569163283,1.508687226708704,-0.4212819595989812
338.20000000000414,20.289281429388566,1.532778089591037,-0.43840688525971316
339.4000000000041,20.325951542232442,1.5553222996934977,-0.4554500149060776
340.6000000000041,20.362408292504973,1.5799163713743227,-0.47358900435131623
341.80000000000416,20.39901492946338,1.6078360707940824,-0.4936733702530791
343.0000000000042,20.43586419437881,1.6405191219279345,-0.5148882302704978
344.2000000000042,20.472306369428704,1.667568866211003,-0.5363493886842807
345.4000000000042,20.509052027455468,1.7006067501571505,-0.5584713577463059
346.60000000000423,20.545987555235644,1.731155697159646,-0.5814108778106157
347.8000000000043,20.582485385033976,1.765976793608937,-0.6032037829178183
349.00000000000426,20.61942095883487,1.8030682531077322,-0.629806492183163
350.20000000000425,20.656197227199403,1.840879626374687,-0.6602946284379718
351.4000000000043,20.69287022097938,1.8809586704858214,-0.6887420588175779
352.60000000000434,20.73009202078029,1.9234253386120588,-0.7187346865658428
353.80000000000433,20.766257143935647,1.969015083184202,-0.750182958510512
355.0000000000043,20.8030119047603,2.0176255121140123,-0.7820859950388175
356.20000000000437,20.83990577758143,2.070222940242343,-0.8164963707635571
357.4000000000044,20.87726913260461,2.1272801519565365,-0.8592019746132422
358.6000000000044,20.91437779979649,2.187220837608092,-0.901605432239271
359.8000000000044,20.951118662267266,2.2469246797470275,-0.9429008785465713
361.00000000000443,20.98807309086594,2.3114793056957055,-0.9860969576801022
362.2000000000045,21.024878099464573,2.3764375258726487,-1.0305574894746865
363.40000000000447,21.06202297244282,2.441217774960454,-1.0779860498628135
364.60000000000446,21.098752292424777,2.5021181912295725,-1.1271491560768507
365.8000000000045,21.13593526842155,2.554828568223928,-1.1783428504604414
367.00000000000455,21.172958577728046,2.601911918819,-1.231465687068778
368.20000000000454,21.210182787687852,2.642287669266557,-1.2875537424531998
369.4000000000045,21.247291938426788,2.6703293919071083,-1.3442649236971436
370.60000000000457,21.284147387651842,2.6881030346598545,-1.401176433900868
371.8000000000046,21.321615937806865,2.700324339951541,-1.4608821208638565
373.0000000000046,21.35823602002588,2.6973887018161147,-1.5208224345008339
374.2000000000046,21.395626148690642,2.684970174730556,-1.58060716920575
375.40000000000464,21.432634708803104,2.6583760403038914,-1.641142484361854
376.6000000000047,21.469812337999787,2.6164181025483604,-1.6988646258797768
377.8000000000047,21.506608102048798,2.5570714497430305,-1.7550875417693792
379.00000000000466,21.543790090533335,2.474791096784379,-1.8106453873257031
380.2000000000047,21.580998965042546,2.378126088052973,-1.8658882563527124
381.40000000000475,21.618055626421288,2.256772372597763,-1.9185160237839898
382.60000000000474,21.65495483971165,2.1212577525835146,-1.9662697543208747
383.80000000000473,21.69204390371549,1.9701588370699543,-2.010038383853618
385.0000000000048,21.72900066260732,1.8133083224182172,-2.056309152444423
386.2000000000048,21.766097988508296,1.6508116517427032,-2.0963625587650196
387.4000000000048,21.802691873270714,1.4892770352151188,-2.1312513166805895
388.6000000000048,21.839729720324097,1.33501217633477,-2.1616289304062852
389.80000000000484,21.876402524367467,1.1923725226350488,-2.1893655337344877
391.0000000000049,21.913390648509225,1.0624354303370018,-2.2125111907372546
392.2000000000049,21.950598406857562,0.951280847478476,-2.2328621599288754
393.40000000000487,21.98725878258782,0.8588474547092186,-2.2505307104569416
394.6000000000049,22.02418469454275,0.7827712101818611,-2.2671719347346575
395.80000000000496,22.06098755638779,0.7212187027484245,-2.2814614435676783
397.00000000000495,22.098159245432136,0.673213192927739,-2.2941856376185816
398.20000000000493,22.1348567682756,0.6387997799747396,-2.3078098107325733
399.400000000005,22.171163223302603,0.6091281590805615,-2.3203538617901076
400.600000000005,22.208965683592492,0.5885940945129808,-2.3319292370633304
401.800000000005,22.24634191208586,0.5736054970946807,-2.3424816347146233
403.000000000005,22.28319577042151,0.5618576803002695,-2.354014178687907
404.20000000000505,22.320526792604586,0.5541489556871295,-2.3654127711987223
405.4000000000051,22.35742956351468,0.5504216114673903,-2.3774644156831695
406.6000000000051,22.394752961483523,0.5455853335571099,-2.389075882084352
407.80000000000507,22.432005155009264,0.5433823844582293,-2.4002699131052916
409.0000000000051,22.469307793920006,0.5426746405800402,-2.4117705785467933
410.20000000000516,22.506645664939086,0.5410731846822499,-2.423208277942183
411.40000000000515,22.544088445022865,0.5425548156867646,-2.4339601279482377
412.60000000000514,22.58144756558226,0.5419552747057506,-2.4455792240372776
413.8000000000052,22.618521110300076,0.5437561331978171,-2.4568935862518195
415.00000000000523,22.655940685057196,0.548015894614756,-2.469279661379204
416.2000000000052,22.693451643372132,0.5473313039859622,-2.4817367419259497
417.4000000000052,22.73069465358661,0.5513124398718816,-2.493387971367442
418.60000000000525,22.768118058798542,0.5507405375077181,-2.5058054588288172
419.8000000000053,22.805364766506464,0.5518615782026595,-2.5192081287967953
421.0000000000053,22.843138686396813,0.5561055201136393,-2.532648878976847
422.2000000000053,22.879561690351892,0.5590388931021553,-2.5471992597508852
423.4000000000053,22.91819145051448,0.5608287600571384,-2.559999085809777
424.60000000000537,22.955727116550857,0.5630780334223711,-2.5730862794037743
425.80000000000535,22.99310952134308,0.5636790116202379,-2.586157660930603
427.00000000000534,23.03073297055029,0.5694205936125751,-2.6008295105171255
428.2000000000054,23.06831718376754,0.5737605965413268,-2.6157032810612018
429.40000000000543,23.106276848176343,0.5759469839688227,-2.631447683069795
430.6000000000054,23.143433331254183,0.5785556734833077,-2.6475991606607985
431.8000000000054,23.181217531906956,0.5815427657487748,-2.662676468920295
433.00000000000546,23.218579821445072,0.5860404095765988,-2.678241958763025
434.2000000000055,23.256394094291906,0.5925350923394608,-2.695545000053404
435.4000000000055,23.294350736315756,0.5962476560803711,-2.714668489732459
436.6000000000055,23.33179741745267,0.5972074766140063,-2.7316340067630756
437.8000000000055,23.369593265384637,0.6019183760256763,-2.7486183730269182
439.00000000000557,23.407149321743546,0.6094760383033762,-2.7665552209303335
440.20000000000556,23.44487282407335,0.6141492346254471,-2.7861071939365205
441.40000000000555,23.482904297263,0.6175078380864072,-2.8050542311571647
442.6000000000056,23.520281208681777,0.6218848729270143,-2.824763321905902
443.80000000000564,23.55869317181649,0.6259216365978149,-2.8447526705716957
445.0000000000056,23.5962635873115,0.6258838540861822,-2.8639078506558477
446.2000000000056,23.633927998494475,0.6286414608550834,-2.8850390733345956
447.40000000000566,23.671675974176985,0.6306616130988156,-2.9050743702599258
448.6000000000057,23.70978523148103,0.6328857907076013,-2.9253027973213666
449.8000000000057,23.747692720734086,0.6356572388976267,-2.9459015359008514
451.0000000000057,23.785401951690044,0.6323307953226838,-2.9667323361597546
452.20000000000573,23.823284453674958,0.6316958419790732,-2.983592102604195
453.4000000000058,23.86134862690367,0.6266210968211912,-2.9999695918208857
454.60000000000576,23.899286273004634,0.6255965320986865,-3.01798193600636
455.80000000000575,23.937566340440256,0.6224198991379739,-3.0338908837697773
457.0000000000058,23.975258342111598,0.6160772976497599,-3.04947541795213
458.20000000000584,24.01342345936046,0.6099417062970605,-3.065702845798204
459.40000000000583,24.051378244706292,0.6015805564896088,-3.080603804143313
460.6000000000058,24.089073072129153,0.5922861475974333,-3.0939240582067304
461.80000000000587,24.127155968605834,0.5815621728008351,-3.106955169042652
463.0000000000059,24.16529679097803,0.5677642559145775,-3.1183265458715983
464.2000000000059,24.203357849794262,0.5559968112369491,-3.129895662012985
465.4000000000059,24.241368832044373,0.5423696349636933,-3.1405038574056308
466.60000000000593,24.27942152577057,0.5274194347282042,-3.150500565496794
467.800000000006,24.317690370811516,0.5083867319782907,-3.1603237797952186
469.00000000000597,24.355712302960168,0.48747341732336613,-3.1699683109457637
470.20000000000596,24.393737232014256,0.4695247992202811,-3.178332075385011
471.400000000006,24.431963002668045,0.44854145615810115,-3.1863118114733964
472.60000000000605,24.469661678677202,0.42629581672980543,-3.195003275041054
473.80000000000604,24.50769705605121,0.4073499075521021,-3.2011649719438373
475.000000000006,24.546022702958435,0.3805894313673488,-3.2065946878318776
476.20000000000607,24.584304148259537,0.3560959626473992,-3.2134108735381255
477.4000000000061,24.622321896164628,0.3363751592615125,-3.219228837848646
478.6000000000061,24.660568160164168,0.31658112099958613,-3.2243275062390104
479.8000000000061,24.698808015557262,0.2923341966627724,-3.2305616088857994
481.00000000000614,24.736785561919806,0.2722313684726585,-3.235043595146793
482.2000000000062,24.774939639247947,0.25421731939776615,-3.238088863046055
483.4000000000062,24.812976411477504,0.23624276945664713,-3.2425540944185993
484.60000000000616,24.851369768408844,0.22244641646390995,-3.246329771056816
485.8000000000062,24.88928602290134,0.20612189350178522,-3.2491423721060935
487.00000000000625,24.927585253751865,0.1921134207983819,-3.2517829462919265
488.20000000000624,24.96582239976262,0.17789682278632535,-3.255655425300069
489.40000000000623,25.00399039666591,0.16693906063677133,-3.2587478436208857
490.6000000000063,25.042391732241402,0.1568915533811286,-3.2613535449789266
491.8000000000063,25.08054126706115,0.14851050503197505,-3.2641745927816777
493.0000000000063,25.118940983121483,0.13703129600731057,-3.26735177159947
494.2000000000063,25.157171062374793,0.13039360574982872,-3.268982384950827
495.40000000000634,25.19552596148418,0.12352569924341172,-3.271745743105912
496.6000000000064,25.23395979497665,0.11649117917243124,-3.2738551577823456
497.8000000000064,25.272215984628552,0.11169985703736152,-3.275509290907304
499.00000000000637,25.31025487035196,0.10738397010156508,-3.2781082161147843
500.2000000000064,25.349108837659834,0.10224236401381925,-3.2813672948654578
501.40000000000646,25.387264879422144,0.09674721091318816,-3.282834409074462
502.60000000000645,25.425881719701245,0.09548610347456332,-3.2841594995631174
503.80000000000643,25.46387856206888,0.09063543196414758,-3.2843551921299956
505.0000000000065,25.502340676871867,0.08633087146106844,-3.2855488684749172
506.2000000000065,25.540675271472367,0.08492788661279049,-3.2868796993219913
507.4000000000065,25.57905166215042,0.08150360073338159,-3.2892159931453513
508.6000000000065,25.617551958652076,0.08376639123468288,-3.2906175892422524
509.80000000000655,25.656277344449933,0.08066033858191934,-3.291997743087494
511.0000000000066,25.69456426723688,0.07855598286268806,-3.293469116066352
512.2000000000066,25.733068199585198,0.07575958556991869,-3.2949506584727115
513.4000000000066,25.771495781649296,0.07478392986898408,-3.294859246109122
514.6000000000066,25.810065946206198,0.07074446332348572,-3.2962884181811574
515.8000000000067,25.847742950594174,0.06995696076259095,-3.297745946165937
517.0000000000066,25.8869040002812,0.0718095496832809,-3.298972715517217
518.2000000000066,25.92540252000628,0.06687826995979096,-3.3006569270619406
519.4000000000067,25.96418713301231,0.06725949981141421,-3.301327267549209
520.6000000000067,26.002828995318346,0.0647051663823357,-3.3018861301659506
521.8000000000068,26.04131445573788,0.0675625578627086,-3.303226340997835
523.0000000000067,26.0797376005507,0.06266632331760547,-3.305040569982981
524.2000000000068,26.11867764191693,0.06472847405005422,-3.306780098911023
525.4000000000068,26.15700601316836,0.05875927995069574,-3.306744646766286
526.6000000000067,26.195693701078554,0.059771994126347705,-3.3084045115129035
527.8000000000068,26.234500378161503,0.058032061022323056,-3.3115265775318177
529.0000000000068,26.272913052574285,0.055145330607283105,-3.310031010627303
530.2000000000069,26.31173474331319,0.052813133004347756,-3.3100018794493216
531.4000000000069,26.35029508375033,0.0528923944728279,-3.3114373066199554
532.6000000000068,26.389060900666756,0.05147869447461928,-3.3114294076548707
533.8000000000069,26.427993443082087,0.050549474630707136,-3.312588325253729
535.0000000000069,26.46633332215088,0.050057466062927825,-3.312751387178169
536.2000000000069,26.505253677472844,0.05079630714002348,-3.3142278434247734
537.4000000000069,26.54400706361801,0.04673596597403251,-3.3149146365266953
538.600000000007,26.58277339080738,0.04618182846679231,-3.31550245942608
539.800000000007,26.621531215870334,0.04895351229151235,-3.316806798854975
541.000000000007,26.66000000000022,0.04676711558284663,-3.3168001720027935
542.200000000007,26.69901664700395,0.045959525605203666,-3.318123999072712
543.400000000007,26.737625308723743,0.04555664025814887,-3.319453130887616
544.6000000000071,26.776335279757344,0.043303479618262974,-3.319376273381117
545.800000000007,26.815296378477573,0.04304527386077828,-3.3220422003952987
547.000000000007,26.854130031952263,0.04400693498008157,-3.3220572046909913
548.2000000000071,26.892904774111667,0.03953695133977542,-3.3234652119804413
549.4000000000071,26.931363997639885,0.04187758243422368,-3.3224889307227583
550.6000000000072,26.970597695871845,0.042055988748564976,-3.3237102809131094
551.8000000000071,27.00964861234528,0.039650675645005906,-3.3237087641317897
553.0000000000072,27.04844749756412,0.038837182622348365,-3.3250205205629344
554.2000000000072,27.087273238443608,0.0371648528498385,-3.32546533316758
555.4000000000071,27.126311085350306,0.0370286046520536,-3.3263464619040013
556.6000000000072,27.164813385403374,0.03602853156855246,-3.327649204286866
557.8000000000072,27.203908642432456,0.03616161750576308,-3.329029496063518
559.0000000000073,27.242700680270865,0.03265025084854756,-3.329309622728264
560.2000000000073,27.281703763222026,0.032184693687338006,-3.330610839568226
561.4000000000073,27.32073957814338,0.03302977491980985,-3.330611688595066
562.6000000000073,27.359488461422252,0.03128536167189511,-3.3329038172720944
563.8000000000073,27.39838007774796,0.030528910893545813,-3.332882180671189
565.0000000000073,27.437359009470686,0.029586973780072023,-3.3342343406298975
566.2000000000073,27.476531085790384,0.025459110696651965,-3.3356182764990914
567.4000000000074,27.515377324132082,0.028293723702941698,-3.3355437106578405
568.6000000000074,27.554334791029827,0.028142320968680856,-3.3367795022056246
569.8000000000075,27.593074163036164,0.027649110787995923,-3.336836933960808
571.0000000000074,27.631919756844752,0.027118887735858355,-3.338180300671916
572.2000000000074,27.671437969355615,0.025577471164074383,-3.3382870306844286
573.4000000000075,27.710591723364782,0.02658222983946712,-3.339500334186728
574.6000000000074,27.74946462195192,0.02377329887335744,-3.3394992126436907
575.8000000000075,27.788837480762197,0.02762407327491445,-3.340783534640363
577.0000000000075,27.82752683301665,0.0250219000968821,-3.339840304118857
578.2000000000075,27.86660638180735,0.027615067412811722,-3.339741963076485
579.4000000000076,27.905707673155447,0.025428633113676158,-3.341151269192241
580.6000000000075,27.945078958133607,0.029007904694471787,-3.341612053356564
581.8000000000076,27.98362093283898,0.024971837623907867,-3.342433874570893
583.0000000000076,28.023176861708833,0.02297905475816764,-3.3437762177603263
584.2000000000075,28.06227425493308,0.02414591901805352,-3.3437897899055686
585.4000000000076,28.101252847059992,0.023223283850184906,-3.343778710067869
586.6000000000076,28.140459210838358,0.023403325971032896,-3.345096186045321
587.8000000000077,28.179466348335982,0.020685983232837657,-3.3457141295490547
589.0000000000077,28.21874025521639,0.023835049443800216,-3.346416190058549
590.2000000000077,28.256930548752976,0.020225437950283975,-3.347725939072976
591.4000000000077,28.297033122620725,0.023099304275106647,-3.348424138078886
592.6000000000078,28.336003722698095,0.021647581297204788,-3.3490503889465204
593.8000000000077,28.37540527487047,0.021600431679053678,-3.3490434482873566
595.0000000000077,28.414676743073073,0.021238677267039652,-3.3502982594640107
596.2000000000078,28.45399299357643,0.021428379704476086,-3.3502924647913552
597.4000000000078,28.49304112195143,0.02020457601050696,-3.3516873215296714
598.6000000000079,28.532386948306527,0.019086645506439126,-3.353043971425701
599.8000000000078,28.57161949676892,0.021047522133509133,-3.353008710076404
601.0000000000078,28.610835451034138,0.024359482711661773,-3.3543226908078245
602.2000000000079,28.649802543066563,0.021934750855059804,-3.354319139229335
603.4000000000078,28.689360448883825,0.024240009289942854,-3.3556276484692544
604.6000000000079,28.728596567337185,0.02350278120463889,-3.356175013029179
605.8000000000079,28.768423562165314,0.028350723669755773,-3.3569508986499335
607.000000000008,28.807350921879276,0.025024954196762206,-3.356915419569106
608.200000000008,28.846826674870872,0.027331071474724578,-3.3579302120178625
609.4000000000079,28.88657060860537,0.029430481601176783,-3.3589541638219114
610.600000000008,28.92564701955589,0.028772087098109633,-3.359334775391448
611.800000000008,28.965131682832478,0.02704925200322128,-3.360591038992526
613.000000000008,29.004357214213265,0.024610025624750342,-3.362005629101986
614.200000000008,29.044061573643848,0.024174382001588057,-3.364405565754964
615.400000000008,29.083077211070517,0.021291994487840693,-3.3635475002465185
616.6000000000081,29.122621697400266,0.020571675258720834,-3.3640042005057382
617.8000000000081,29.16214841345906,0.017708219285617055,-3.3651166266087986
619.0000000000081,29.20143293427189,0.019845337380240746,-3.3663816708223235
620.2000000000081,29.240849202493084,0.022872323946148132,-3.36780449010498
621.4000000000082,29.280164769656885,0.02259813825737833,-3.3691216736337624
622.6000000000081,29.319711258180728,0.02209505373241294,-3.370579393535794
623.8000000000081,29.359236624498987,0.02792004178010954,-3.371699851299743
625.0000000000082,29.398904386902746,0.02726779068043106,-3.372740670862363
626.2000000000082,29.437900986369176,0.02712412083183935,-3.3729984348381117
627.4000000000083,29.47737347417909,0.027176854599620714,-3.374310507658172
628.6000000000082,29.51685921918618,0.026476564705758765,-3.375709147971922
629.8000000000083,29.556097657123235,0.026126421786977883,-3.3762917508237216
631.0000000000083,29.59566003765571,0.028431293820755155,-3.377021494251424
632.2000000000082,29.635092756297908,0.025737109238856082,-3.3772923318380412
633.4000000000083,29.674453489779083,0.025210766615015423,-3.378327622444539
634.6000000000083,29.71415693671198,0.027254323136550962,-3.37768711197239
635.8000000000084,29.753633244326256,0.029557656463132354,-3.3789632862585752
637.0000000000084,29.792880489798502,0.03143369825286957,-3.3789355637501974
638.2000000000083,29.832283129664727,0.02577039809391435,-3.3803085321506456
639.4000000000084,29.87224952882835,0.028213191726490727,-3.3803100303006053
640.6000000000084,29.911473500175912,0.026928629535209136,-3.380310312762962
641.8000000000084,29.950891126098835,0.025528838972249,-3.3803407865921677
643.0000000000084,29.990567129542594,0.026104767203719348,-3.3816311512153048
644.2000000000085,30.030097015853592,0.023687938644030737,-3.381665146328772
645.4000000000085,30.069602262671967,0.023381150056294597,-3.3822742605812266
646.6000000000085,30.108993097240038,0.022893712145466427,-3.382535598557788
647.8000000000085,30.148524551470473,0.022492300467249926,-3.3836017490898533
649.0000000000085,30.18809873763699,0.019159051145019035,-3.3835610074800915
650.2000000000086,30.227655593465855,0.01875965361575771,-3.3849035983684495
651.4000000000085,30.266797496037963,0.015091785724758555,-3.384909768950085
652.6000000000085,30.30611152261069,0.017187146265658537,-3.384911625322178
653.8000000000086,30.345601223587913,0.01269115413701849,-3.3854416049574905
655.0000000000086,30.385565803631764,0.01447420465066429,-3.3872040779687804
656.2000000000087,30.425073400591526,0.015141980841035352,-3.3872216103811095
657.4000000000086,30.464332810185734,0.012379798744150516,-3.3876120467873454
658.6000000000087,30.50413443561373,0.013324914575364666,-3.387407660561828
659.8000000000087,30.543885193682183,0.013846602349367743,-3.387221225334312
661.0000000000086,30.583327193080684,0.008691466769974898,-3.3872212170341744
662.2000000000087,30.62294608129073,0.007734014632359454,-3.388624960532632
663.4000000000087,30.66283638362366,0.010633938503081808,-3.388537584290073
664.6000000000088,30.70280954479135,0.008899492601043058,-3.3898999843965796
665.8000000000088,30.74240282878219,0.011075630753646148,-3.3898502624817803
667.0000000000088,30.782176696946536,0.007895639899579088,-3.3898500095083883
668.2000000000088,30.821874343160516,0.005989954998372848,-3.3898474977020085
669.4000000000088,30.86155661656353,0.007750511514094338,-3.3909568160894263
670.6000000000088,30.90107221887656,0.00145857806434746,-3.3911693077400082
671.8000000000088,30.940716985883434,-5.558917792614082e-05,-3.390998997050394
673.0000000000089,30.98045048169818,-0.0028324839868569818,-3.389846561592771
674.2000000000089,31.020098182113422,0.0018980369061560864,-3.3898529636888783
675.400000000009,31.059696709384358,-0.0023422743791474687,-3.391157094664646
676.6000000000089,31.099186912472383,-0.004148647569652386,-3.3902217803300925
677.8000000000089,31.139022705905848,-0.0050396896310904715,-3.38964522742084
679.000000000009,31.178823535730576,-0.004958528924410732,-3.3913034843169685
680.2000000000089,31.21824629364863,-0.005193607297317104,-3.392101261655869
681.400000000009,31.25786414000422,-0.003259293403638619,-3.39361998520077
682.600000000009,31.29821179950494,-0.004313204521095848,-3.3944513331089863
683.800000000009,31.338018416396952,-0.0047572049240747205,-3.3944498844606437
685.0000000000091,31.37759209439647,-0.009509397872204062,-3.3944498738663267
686.200000000009,31.417285368425297,-0.008659199668274997,-3.394449431924113
687.4000000000091,31.45711471874915,-0.004383393522394474,-3.394365215582977
688.6000000000091,31.496488839589418,-0.0075916914855618245,-3.3957685530127333
689.800000000009,31.53645324470057,-0.007348892383992389,-3.3957700340857535
691.0000000000091,31.57622281009118,-0.009567966451691223,-3.395769668825329
692.2000000000091,31.61585068415953,-0.007698595633947036,-3.3967271097037273
693.4000000000092,31.656178375211304,-0.004791354983276097,-3.397088256248984
694.6000000000092,31.695567210147203,-0.006376058170161958,-3.3970720337838376
695.8000000000092,31.73532125028797,-0.004970472087232558,-3.3957829189643047
697.0000000000092,31.775137022085033,-0.00596058737656735,-3.3944627706188797
698.2000000000093,31.815015382664896,-0.0065174574111726,-3.3955680401736372
699.4000000000092,31.85493245290126,-0.0069402568902559025,-3.396616132489016
700.6000000000092,31.894633371963586,-0.010131004452214043,-3.397527888147404
701.8000000000093,31.934386269830785,-0.006712094363373389,-3.3972677565822123
703.0000000000093,31.974142015315703,-0.007703061675744305,-3.398615522623982
704.2000000000094,32.01399443320359,-0.008083069705698165,-3.3986299158341464
705.4000000000093,32.054012982539334,-0.007063965647130743,-3.398629989462619
706.6000000000093,32.09372071268774,-0.008052312191918709,-3.398629965341354
707.8000000000094,32.13342891377499,-0.0075876127726206555,-3.3986257239989914
709.0000000000093,32.17324725220504,-0.010491071575940758,-3.399811034807287
710.2000000000094,32.2131296077312,-0.010798163188747267,-3.399939957502381
711.4000000000094,32.25330945344297,-0.013016392662383414,-3.3999401007607455
712.6000000000095,32.293419792705826,-0.014053971982346702,-3.3999389030517486
713.8000000000095,32.33330470991533,-0.014870984405357834,-3.3995827456152856
715.0000000000094,32.37311073933195,-0.016960807995666016,-3.399923648617581
716.2000000000095,32.413001640907986,-0.015347911760029032,-3.399939573791201
717.4000000000095,32.45310349949022,-0.01922554912811636,-3.3998974199682657
718.6000000000095,32.49309783243696,-0.022854921990216326,-3.402014130793183
719.8000000000095,32.53309898348648,-0.017202875750267577,-3.401920605842051
721.0000000000095,32.57296379700514,-0.021467255054401058,-3.401941268658227
722.2000000000096,32.61311610667814,-0.016636838615898597,-3.4032371225175755
723.4000000000096,32.6528361003904,-0.020491325897451507,-3.403230193808555
724.6000000000096,32.69295988169318,-0.020760762458076787,-3.4032301602887136
725.8000000000096,32.733422580477,-0.023712179645603015,-3.403230180002967
727.0000000000097,32.77330034873639,-0.024250315010116097,-3.4032341836211493
728.2000000000096,32.81363860241079,-0.02703812335545086,-3.40213956116943
729.4000000000096,32.853541032609456,-0.023022561159399046,-3.4019116360125494
730.6000000000097,32.89357453625102,-0.02546192666769098,-3.4020751169783106
731.8000000000097,32.93345919055983,-0.027348141120984604,-3.4032345679889984
733.0000000000098,32.97394609578053,-0.028791887416765416,-3.403409859941993
734.2000000000097,33.01433329671124,-0.03342388031252952,-3.4060611994187493
735.4000000000098,33.0543135909443,-0.03136975302417211,-3.4089424292369586
736.6000000000098,33.094375134692356,-0.03092751088163226,-3.410222525574018
737.8000000000097,33.134729735357894,-0.030942781653991336,-3.410249733706947
739.0000000000098,33.174642303480255,-0.03317344187525606,-3.410238244511123
740.2000000000098,33.21469121302044,-0.03415988906629508,-3.4088244978242703
741.4000000000099,33.254780960562485,-0.03346019939962419,-3.4076029700589343
742.6000000000099,33.29485170015053,-0.03634947656107412,-3.4076101344002625
743.8000000000098,33.33521562191505,-0.035570290863452314,-3.4076119556162157
745.0000000000099,33.3755238944623,-0.04143042893056714,-3.4063031810601743
746.2000000000099,33.41572828379491,-0.03993745571456797,-3.4047644399880275
747.4000000000099,33.45550742769846,-0.040094311444109465,-3.404760018051133
748.6000000000099,33.49590284862644,-0.04073966028359699,-3.4047624690558553
749.80000000001,33.535838481991384,-0.03890750522222941,-3.406214201935591
751.00000000001,33.576154560618775,-0.038044728647435466,-3.406090340318569
752.20000000001,33.61648961206037,-0.04088406697855529,-3.406418615074203
753.40000000001,33.65683152472667,-0.04016720549866948,-3.4064199079160398
754.60000000001,33.69699434835738,-0.039970813267613536,-3.4064198923759004
755.8000000000101,33.7373397938861,-0.04385047935777875,-3.4064158146969783
757.00000000001,33.77725686423119,-0.04132610666650116,-3.407715393679304
758.20000000001,33.81751194400457,-0.04479473535363754,-3.4077421626781934
759.4000000000101,33.857987832128195,-0.04187526215176751,-3.4090737860730336
760.6000000000101,33.89799206538871,-0.042942036134471895,-3.4087061324068593
761.8000000000102,33.938596838332614,-0.04572222690379801,-3.4087208045487447
763.0000000000101,33.97874937792515,-0.04792505683912518,-3.4092764465371364
764.2000000000102,34.01903592668015,-0.04999666714598394,-3.410034322237091
765.4000000000102,34.058995945132786,-0.04897145601032005,-3.4093216861218405
766.6000000000101,34.09946731072835,-0.055269769911035826,-3.410687672016445
767.8000000000102,34.13954105559099,-0.050970346514524145,-3.411997743180937
769.0000000000102,34.17966174353411,-0.054764347180699335,-3.411335798442733
770.2000000000103,34.21993161933357,-0.05473745461861679,-3.4113497784886473
771.4000000000103,34.26003296661019,-0.05365637053069694,-3.411349855345918
772.6000000000103,34.30017111011807,-0.0605431988464602,-3.411355331750248
773.8000000000103,34.34053203149906,-0.05587953164177328,-3.412661028622834
775.0000000000103,34.38078891436036,-0.057209138457763764,-3.4126599758723044
776.2000000000103,34.42086326577256,-0.05941178565499028,-3.4126600507703975
777.4000000000103,34.461034144789735,-0.05610902218763014,-3.412679421708627
778.6000000000104,34.50102850048432,-0.05447470973108759,-3.4111322459153124
779.8000000000104,34.54145177660797,-0.057090003497940245,-3.411187380899621
781.0000000000105,34.58188487435483,-0.06139791674836914,-3.4141471739332054
782.2000000000104,34.62206682307143,-0.058194852972116795,-3.4152477723987653
783.4000000000104,34.66216433849416,-0.05639949451995774,-3.416530661463706
784.6000000000105,34.70236325093161,-0.06233918443036046,-3.4161781421417805
785.8000000000104,34.74261149490888,-0.06603119647976685,-3.416179926224825
787.0000000000105,34.782806120106905,-0.0624752185780828,-3.416174385287503
788.2000000000105,34.82301151882094,-0.06229645566301745,-3.416767032096873
789.4000000000106,34.86324195069455,-0.06228901439110679,-3.417158881548537
790.6000000000106,34.90355060241701,-0.061768056918836134,-3.415564138204126
791.8000000000105,34.94361657585473,-0.06506380549123181,-3.4148616897932644
793.0000000000106,34.98396527974903,-0.06253606900693143,-3.4148599673025313