File: 01_Data/Cotton_Rug/STA/N2/30K_min/Cotton_Rug_STA_N2_30KData_220113_R2.csv
##Temp./Â°C,Time/min,DSC/(mW/mg),Mass loss/mg
49.0,10.534877564194161,0.045099935564275384,-0.0012894947365253984
50.20000000000002,10.73200838854089,0.09439876964935845,-0.002360235093696872
51.400000000000034,10.861172274696223,0.13998184591701368,-0.002998676980784154
52.60000000000005,10.961829995837558,0.18217196358368126,-0.0025910941843179103
53.80000000000007,11.047122645220565,0.21461814459726009,-0.004500085340939819
55.000000000000085,11.122822544116588,0.24718883473624315,-0.0032621223399003085
56.2000000000001,11.193941976155525,0.2799992333800632,-0.0025307917968921956
57.40000000000012,11.259709383739859,0.30466470547959995,-0.0032963040604867544
58.600000000000136,11.321410271069444,0.3329496330615054,-0.005370397094775825
59.80000000000015,11.381005827808735,0.3557644581494234,-0.0039722032461035894
61.00000000000017,11.43714162546556,0.38112953935981186,-0.004215613637404303
62.20000000000019,11.49231574710121,0.3998680918473579,-0.0034313368767264762
63.400000000000205,11.544930532032161,0.4234231961746171,-0.0030546767586914214
64.60000000000022,11.596130528008093,0.4397905307469002,-0.004053768091299759
65.80000000000024,11.646201905781496,0.4560017292500339,-0.004288206596112509
67.00000000000026,11.696041206474412,0.4758189871573135,-0.0041461334617682866
68.20000000000027,11.744355248486096,0.4909989916366808,-0.004084594647036255
69.40000000000029,11.79239710351309,0.5070604912449518,-0.004288465100330541
70.6000000000003,11.839049294958762,0.5204193835841929,-0.004476166547862981
71.80000000000032,11.885362242372585,0.5319513623476795,-0.0032557919265920887
73.00000000000034,11.931625653860157,0.5422978537477521,-0.0030959752293870935
74.20000000000036,11.976613010165211,0.5468563602080064,-0.002799985836229979
75.40000000000038,12.022089410811546,0.5579101464250469,-0.0044296951832674125
76.60000000000039,12.06568245338127,0.5614345745622283,-0.0037261284851135557
77.80000000000041,12.11071708098405,0.5709635829357231,-0.004030608163414051
79.00000000000043,12.154656857175071,0.5752849384500249,-0.004534457531656599
80.20000000000044,12.197944624349967,0.5826438465466464,-0.004274179354479379
81.40000000000046,12.241349915226808,0.5870897868094556,-0.004442761738816081
82.60000000000048,12.284659804586381,0.5933011744697418,-0.004428251116163295
83.8000000000005,12.3271874234999,0.5994374097954309,-0.004639530754487531
85.00000000000051,12.369550965665619,0.604287073684959,-0.006072925754855518
86.20000000000053,12.41088177134809,0.6118770517787657,-0.005208888364378161
87.40000000000055,12.454257185033434,0.6187265793469695,-0.004819590420456876
88.60000000000056,12.496264808329453,0.6248075238505781,-0.006054580822594247
89.80000000000058,12.538231266284201,0.6305093178204517,-0.006268717200997642
91.0000000000006,12.579484156340625,0.6360201941316659,-0.00586990378978669
92.20000000000061,12.621000979121185,0.6423485833680066,-0.005484695736346801
93.40000000000063,12.661889562891552,0.6495907443365702,-0.006479923769275864
94.60000000000065,12.703236765379751,0.6546385850025388,-0.0063575598518346155
95.80000000000067,12.744318883389079,0.6603055039858521,-0.007513518079932169
97.00000000000068,12.78538700735126,0.6658596239170539,-0.006424410770424771
98.2000000000007,12.826268982302487,0.6699009257563968,-0.006359777677569234
99.40000000000072,12.867293726940304,0.6763489184992888,-0.0077912060097817815
100.60000000000073,12.907734540136444,0.6828212014298202,-0.008315978935898194
101.80000000000075,12.948299860447719,0.6872469996187888,-0.007779216022520963
103.00000000000077,12.988969648772635,0.6908983344420572,-0.007778862086346372
104.20000000000078,13.029907357436207,0.695161217744849,-0.007827551472006533
105.4000000000008,13.070417986239242,0.6991183338987679,-0.007752633860642177
106.60000000000082,13.110635298714257,0.7056764118940153,-0.00913302083172507
107.80000000000084,13.150878412771805,0.7075501921848693,-0.009110183061396881
109.00000000000085,13.191901175952841,0.7109572946223488,-0.009713237157229493
110.20000000000087,13.23212895134429,0.715146227746088,-0.010420153014893963
111.40000000000089,13.272207359584261,0.7187434789737562,-0.010420153105667573
112.6000000000009,13.31221201407682,0.7217771678642044,-0.010420174324846432
113.80000000000092,13.352550712092446,0.7235249310971084,-0.010419270838788464
115.00000000000094,13.392841970597642,0.7269534690907682,-0.010522370072784781
116.20000000000095,13.432833102738265,0.7292994065411743,-0.010410189223331479
117.40000000000097,13.473097709334393,0.7321831504838348,-0.010405582918585399
118.60000000000099,13.512748550736104,0.7359033988958825,-0.011730888157727826
119.800000000001,13.552235297001868,0.7371332132949028,-0.011730063075954256
121.00000000000102,13.592574876249055,0.738785781461103,-0.011731467522479111
122.20000000000104,13.63248627354537,0.7406907842103526,-0.013082098423208066
123.40000000000106,13.671604416714576,0.7426015581538112,-0.011753794251029959
124.60000000000107,13.71182163012287,0.7444105438260117,-0.011740071044183509
125.80000000000109,13.751049817503764,0.7454932878163412,-0.011739994337841786
127.00000000000111,13.790250778043928,0.7462995386634852,-0.011739993996767062
128.20000000000113,13.829992645330767,0.747844390750524,-0.011739978646346572
129.40000000000114,13.869170333244183,0.7479747528797933,-0.011690775425134081
130.60000000000116,13.908595567253709,0.7500051097046915,-0.013049666474294508
131.80000000000118,13.94745131768314,0.7528970455814514,-0.0133725025321767
133.0000000000012,13.986792311769959,0.7519246694805231,-0.01337652325323857
134.2000000000012,14.025804062239544,0.7542536299698697,-0.01436958982195291
135.40000000000123,14.064851599374784,0.7563319550894256,-0.013459226927186485
136.60000000000124,14.10355464367385,0.7596629379440849,-0.013380701542171636
137.80000000000126,14.142500246682296,0.7615555517162684,-0.014694865784185662
139.00000000000128,14.180905479124686,0.7630715832962325,-0.014696559129105058
140.2000000000013,14.219741755306924,0.7670807847563712,-0.014373012783016392
141.4000000000013,14.258299363535565,0.7655326864570146,-0.014396041420662975
142.60000000000133,14.29733294921195,0.7709899194631633,-0.01534988452196151
143.80000000000135,14.335785142165681,0.7746448253043676,-0.015350451508840735
145.00000000000136,14.37401354168507,0.774658874889397,-0.014513744674763185
146.20000000000138,14.41201974175649,0.779522997092829,-0.012892740799729907
147.4000000000014,14.450386023154383,0.7808113423523393,-0.012729850933315134
148.60000000000142,14.488692125961727,0.7846232431272802,-0.01272983497791591
149.80000000000143,14.52716143089971,0.7856852357105967,-0.012729834999627876
151.00000000000145,14.565432197922123,0.7918613793897961,-0.012729834997647682
152.20000000000147,14.603343147635451,0.7931756725019432,-0.012729834768658854
153.40000000000148,14.641577645029185,0.7963054017483658,-0.012737196039638743
154.6000000000015,14.679463294980106,0.8012775398971179,-0.013713683578385094
155.80000000000152,14.717561542162786,0.8037397039853125,-0.014042964702333904
157.00000000000153,14.755974140355613,0.8071958673140844,-0.014039822501713317
158.20000000000155,14.793618026259756,0.8103046145870337,-0.014039688078927082
159.40000000000157,14.831652227828394,0.8158603848474963,-0.014004878535417653
160.6000000000016,14.869714312743737,0.8181794435733905,-0.014038705245353889
161.8000000000016,14.90725840311556,0.8185248653074959,-0.014040194951717488
163.00000000000162,14.945097213438803,0.8207490029946924,-0.014040144528901788
164.20000000000164,14.98255999827461,0.8239842028108331,-0.014040144003514055
165.40000000000165,15.020548760831298,0.828398539219371,-0.01404014400001019
166.60000000000167,15.058101703676527,0.8309946832806395,-0.014040144000001309
167.8000000000017,15.096233947253337,0.8341678556481787,-0.014040143999999533
169.0000000000017,15.133629186415302,0.8387044940041987,-0.014040143999998644
170.20000000000172,15.171307351154404,0.8437602552972309,-0.014040143999989763
171.40000000000174,15.20904441884743,0.8466647982680867,-0.01404014400007414
172.60000000000176,15.246247695569393,0.8501158400320795,-0.014040144190601733
173.80000000000177,15.283866749210446,0.8538661201877314,-0.014040178980516682
175.0000000000018,15.32153119699609,0.8578922708785671,-0.014043693464819373
176.2000000000018,15.358923288170477,0.8596774336948968,-0.01306617182541503
177.40000000000182,15.396438148348107,0.863485969212161,-0.013051208304934558
178.60000000000184,15.433561637706328,0.8675148339829976,-0.013050086246355175
179.80000000000186,15.470857342327681,0.8718713141354502,-0.013050182972833557
181.00000000000188,15.508252244386435,0.8708172411295841,-0.01438560970802838
182.2000000000019,15.545193552363166,0.8756711080357642,-0.014314469722358059
183.4000000000019,15.582457132003809,0.8821482687217809,-0.015676391306778115
184.60000000000193,15.619620731992162,0.8834735992969641,-0.015690401465005444
185.80000000000194,15.656724454476159,0.8865823916998459,-0.015234021415098553
187.00000000000196,15.693872676106581,0.8906925578241037,-0.012998549805918636
188.20000000000198,15.730408386720198,0.8918441814520556,-0.013050602669700151
189.400000000002,15.767675821917749,0.8958598396718547,-0.014261950617489472
190.600000000002,15.804337173800736,0.9002393560795409,-0.015361368000898601
191.80000000000203,15.841429845735455,0.9051121664532878,-0.015360159206197377
193.00000000000205,15.878443932803979,0.9089754927485328,-0.015361085988216061
194.20000000000206,15.915092929182435,0.9126343329782408,-0.015198044059516302
195.40000000000208,15.951717551953326,0.9135313216707245,-0.015359958817465547
196.6000000000021,15.989169691346067,0.9197664108400435,-0.01536014405962316
197.80000000000211,16.025682088831115,0.9229651026111143,-0.015360144012796617
199.00000000000213,16.0628752783022,0.9261621782158925,-0.015360143995341247
200.20000000000215,16.09926077705323,0.9308857190626814,-0.015360143980644558
201.40000000000217,16.135897980538694,0.9341536805076535,-0.015360217837446122
202.60000000000218,16.172720283004082,0.9372556586901744,-0.015369820226244002
203.8000000000022,16.209388047235777,0.9409462477654973,-0.016686379727667067
205.00000000000222,16.246031178511767,0.9451728606323141,-0.016679143259509033
206.20000000000223,16.28270046753934,0.9489463313488906,-0.016679829656113476
207.40000000000225,16.31950644422326,0.9511224361095041,-0.016679834994851817
208.60000000000227,16.356137586009428,0.9558063738646992,-0.01667983504675785
209.80000000000229,16.39285533927552,0.9626861708687948,-0.01667984210962281
211.0000000000023,16.429386589895074,0.9701974881648513,-0.016679901448529044
212.20000000000232,16.466076212707097,0.9737326288658421,-0.01658441219643425
213.40000000000234,16.50284360757695,0.979101462257792,-0.01798860992228679
214.60000000000235,16.53951532159729,0.9806589246474695,-0.017989900659492797
215.80000000000237,16.57604363679954,0.9872688504607778,-0.017989902107111266
217.0000000000024,16.612373903946583,0.9910829457275633,-0.017989904158137282
218.2000000000024,16.649170000000076,0.9957803009111239,-0.017990151333928228
219.40000000000242,16.685735861495345,1.0005225684806744,-0.017314654109241268
220.60000000000244,16.722177813749457,1.0032258510283776,-0.01700021738485935
221.80000000000246,16.75890384068048,1.008838812061392,-0.018829256864345556
223.00000000000247,16.795095477876934,1.0126868583199982,-0.02086216123718465
224.2000000000025,16.831617060034237,1.014079396616774,-0.01935396362399766
225.4000000000025,16.86838773824015,1.0182772864232539,-0.0193052701545251
226.60000000000252,16.90489005286117,1.02387870191982,-0.018324426274298755
227.80000000000254,16.941088288725492,1.02922564337632,-0.01883213240007109
229.00000000000256,16.977215715237463,1.0337041741726298,-0.01963270503680592
230.20000000000258,17.014020657266197,1.040546726179024,-0.019630100823433416
231.4000000000026,17.050413890383975,1.0467958554482928,-0.019630321136510087
232.6000000000026,17.08678110438752,1.055689037490819,-0.019605971732122196
233.80000000000263,17.123306523081542,1.0625248564833107,-0.022247300017091742
235.00000000000264,17.159821876075437,1.0709035663147084,-0.02226012820446055
236.20000000000266,17.19628910345244,1.08093461767105,-0.022260293929145192
237.40000000000268,17.23263017516441,1.0937959014365084,-0.022279039651145194
238.6000000000027,17.26880822315287,1.1098198841530653,-0.023578465273066396
239.8000000000027,17.305106462412056,1.1297721068779263,-0.023579712641418116
241.00000000000273,17.341679288208734,1.1526928481741234,-0.023576423500657473
242.20000000000275,17.37804766424918,1.1810255098689497,-0.024456090489069826
243.40000000000276,17.414261245176096,1.2092409014230134,-0.024890285634582288
244.60000000000278,17.45049323317939,1.2415923711871373,-0.02488849623143219
245.8000000000028,17.48706490010342,1.2719892151912502,-0.02625316901463437
247.0000000000028,17.523587518331876,1.3140896873632966,-0.026204281973929877
248.20000000000283,17.559871664272183,1.3793481282643687,-0.027254761016261675
249.40000000000285,17.596275869098285,1.4606597501729253,-0.02743918094333564
250.60000000000286,17.632597738610578,1.5479255673641013,-0.028839165706926906
251.80000000000288,17.668722950282604,1.6268649109593967,-0.027469767828113056
253.0000000000029,17.705504284816442,1.6933874210824376,-0.028841426085543187
254.20000000000292,17.742001966927525,1.7268636313790822,-0.029074241476829688
255.40000000000293,17.77825005906248,1.7165372446789524,-0.03015970919233535
256.600000000003,17.81459894717342,1.6607389852129382,-0.03015296627489983
257.80000000000297,17.851078466074956,1.5824777721651964,-0.031280207573775254
259.00000000000296,17.887510701918554,1.5008473648343479,-0.03213591198755017
260.200000000003,17.923557320040235,1.432904226765347,-0.03293118001758444
261.40000000000305,17.960022403466425,1.3747491733964374,-0.03345825192915086
262.60000000000304,17.995943638704542,1.3306107365651962,-0.03411103212495492
263.800000000003,18.031965313970165,1.2947124386604445,-0.03510511680165873
265.00000000000307,18.068482419082333,1.266286196818455,-0.03658282638456267
266.2000000000031,18.104466650599505,1.2456605881129195,-0.03823846841236822
267.4000000000031,18.14065752928146,1.230576591431255,-0.039518771206431325
268.6000000000031,18.176867392481707,1.217634912309971,-0.040293819007500176
269.80000000000314,18.213240784679698,1.2073653397670563,-0.04200398342928491
271.0000000000032,18.2492585289603,1.2018095519423402,-0.044437941008129034
272.2000000000032,18.28539496836586,1.198582924411499,-0.04585676936535421
273.40000000000316,18.321797441841284,1.1958135104506038,-0.04641428813482218
274.6000000000032,18.357782626793966,1.196154750974222,-0.049995412893497626
275.80000000000325,18.394224858016003,1.1959077030183451,-0.05168124412869535
277.00000000000324,18.43036153719165,1.198891042662289,-0.053082167218457155
278.20000000000323,18.46644966304247,1.1979367267138834,-0.055756507865534655
279.4000000000033,18.50256180388829,1.2007577192163061,-0.058351542687347546
280.6000000000033,18.538718356748124,1.2058735397832008,-0.060496555151525744
281.8000000000033,18.57530644031945,1.2088914307298637,-0.06267975372095158
283.0000000000033,18.61131739814207,1.2143367753421852,-0.06292297782194822
284.20000000000334,18.647731520820194,1.2169220509074936,-0.06489802907014264
285.4000000000034,18.684065035371695,1.222599359388813,-0.06762802586209427
286.6000000000034,18.720329600714884,1.2288860146481313,-0.07032351986540286
287.80000000000337,18.756582369794415,1.2310591703222813,-0.07413967200319771
289.0000000000034,18.792742680152237,1.2387390628943096,-0.07748570934227805
290.20000000000346,18.829077620752333,1.2426788214454714,-0.08006010181195933
291.40000000000344,18.865527863717332,1.2506681877922126,-0.08374034251154061
292.60000000000343,18.901895345377113,1.2572140948306667,-0.08803845759259232
293.8000000000035,18.93807369867809,1.2652639650411586,-0.09174653687898537
295.0000000000035,18.974261337156392,1.2715234961438509,-0.09507071172451864
296.2000000000035,19.010863540033295,1.2834027188124224,-0.0990909956503323
297.4000000000035,19.047137615302425,1.291950642897887,-0.10328740149717763
298.60000000000355,19.083406052235727,1.3025849493778825,-0.10792373403940436
299.8000000000036,19.11965499887596,1.3097464655847524,-0.11214571428797626
301.0000000000036,19.155950731670327,1.321489103188315,-0.11607647356262518
302.20000000000357,19.192568351144313,1.3308150900738696,-0.1222118397843559
303.4000000000036,19.22862868606115,1.339075801131658,-0.12704559213390443
304.60000000000366,19.265171435254747,1.3517707480492978,-0.13224837935228395
305.80000000000365,19.301795870646522,1.3599501412237007,-0.13839346101843653
307.00000000000364,19.33798816980888,1.3685548691161127,-0.14534696533568292
308.2000000000037,19.374531294852943,1.3805141728803807,-0.1506266582651734
309.40000000000373,19.41082312104899,1.391404465005542,-0.15749062017287851
310.6000000000037,19.447287058103864,1.4006789608603127,-0.1653158950583924
311.8000000000037,19.48379280851338,1.4117913717463935,-0.1714677628650918
313.00000000000375,19.520179868883528,1.4208653082752536,-0.17829958556853764
314.2000000000038,19.556592795301366,1.4292521231223205,-0.18642987053506177
315.4000000000038,19.593246783468537,1.4373348677254634,-0.1954937599784623
316.6000000000038,19.629858346387508,1.4467800357497138,-0.2038301026432756
317.8000000000038,19.666367447605523,1.456117173125426,-0.21292234078552186
319.00000000000387,19.70274194894294,1.4650756149145228,-0.22240196506879784
320.20000000000385,19.7391388895293,1.4729934905095492,-0.23209099236814223
321.40000000000384,19.775971403529166,1.4804955673981783,-0.2437008845915143
322.6000000000039,19.81228328796397,1.4879916463730807,-0.25270950608631804
323.80000000000393,19.848897970846423,1.4931529731525317,-0.263136313749992
325.0000000000039,19.88571383614195,1.5030263821529581,-0.2751120030134473
326.2000000000039,19.92214859337846,1.5092862340118192,-0.28719963503661283
327.40000000000396,19.958862548530757,1.516313664288513,-0.2984790852806092
328.600000000004,19.99533945036232,1.5226304236324253,-0.30863091087259864
329.800000000004,20.03169995043627,1.5324084416012687,-0.3219182779352714
331.000000000004,20.068237365607903,1.5427150945649277,-0.33709593434217355
332.200000000004,20.10494815640489,1.5546764880726072,-0.35215505765302835
333.40000000000407,20.141822077235375,1.5686931781719593,-0.3671655921825874
334.60000000000406,20.1787445605396,1.5843796120135822,-0.38205171292496276
335.80000000000405,20.21489195370412,1.5993137014224204,-0.39849899498931496
337.0000000000041,20.25171646709616,1.6211409433876376,-0.41508975717175156
338.20000000000414,20.288449716364966,1.6446144780927556,-0.4318626908364487
339.4000000000041,20.325254107647446,1.6669673566012722,-0.45032559197198996
340.6000000000041,20.362048950303766,1.6909461453685062,-0.4692154263735886
341.80000000000416,20.39847531866233,1.7196882225435246,-0.4898959432777761
343.0000000000042,20.43570982119713,1.7483537662063833,-0.5113549895717213
344.2000000000042,20.472265805707274,1.7780831393220524,-0.5336203996440885
345.4000000000042,20.50922983148922,1.8077896556149418,-0.5578918442563428
346.60000000000423,20.545814468115445,1.8394110762118736,-0.5826611871733345
347.8000000000043,20.582438746713038,1.8724393731389541,-0.6100296883395604
349.00000000000426,20.619637851958004,1.905050146488263,-0.6385805383591188
350.20000000000425,20.65638448471954,1.941471830970373,-0.6677541286010564
351.4000000000043,20.693328571554087,1.9789226910365423,-0.6954152576086261
352.60000000000434,20.72995854177793,2.019649196854653,-0.7257718206122306
353.80000000000433,20.766907020531757,2.0596375935131244,-0.7591182440405819
355.0000000000043,20.804220188951078,2.107111594195465,-0.7951640046629582
356.20000000000437,20.84085655815398,2.1554896574142175,-0.8318765604793295
357.4000000000044,20.87756093974245,2.202848154945098,-0.8703825688622313
358.6000000000044,20.914654514970287,2.255020316496406,-0.9123989836879964
359.8000000000044,20.95186311256341,2.310306046461446,-0.9553791889229153
361.00000000000443,20.988525080419656,2.3613268177205016,-1.000222135225218
362.2000000000045,21.025674250856834,2.4139887198225525,-1.0487234264424417
363.40000000000447,21.062609073060578,2.461541273642166,-1.0974650777762762
364.60000000000446,21.09971729578703,2.5046204917377914,-1.1481787473516807
365.8000000000045,21.136917396700735,2.539081128810842,-1.2004502759651805
367.00000000000455,21.17384325268941,2.5649816230016294,-1.251938471775126
368.20000000000454,21.211176000371513,2.585078999480475,-1.3054579011870242
369.4000000000045,21.248471264180367,2.5972477339381825,-1.3608478651822753
370.60000000000457,21.285277366600912,2.6013633195361123,-1.4154908142512204
371.8000000000046,21.32259920641225,2.5956763726298355,-1.4714262593729264
373.0000000000046,21.359544773472884,2.582475026280841,-1.528161178776891
374.2000000000046,21.396742818444856,2.557202133000186,-1.585336576717733
375.40000000000464,21.433716584394134,2.51492698190201,-1.6416809540958481
376.6000000000047,21.470698853091154,2.45475381993624,-1.698575431120858
377.8000000000047,21.50793355852426,2.3785389310660388,-1.7548243871103728
379.00000000000466,21.54511473435684,2.283884728987977,-1.8091694176441977
380.2000000000047,21.581783774869766,2.1720635255168013,-1.8609397919757011
381.40000000000475,21.619170309090904,2.0424016456413923,-1.9101800309163397
382.60000000000474,21.65630983940682,1.9037784146806125,-1.9529867550703846
383.80000000000473,21.69323737269336,1.754656673866221,-1.9945120406569719
385.0000000000048,21.73004168440231,1.602872663110701,-2.031971898195065
386.2000000000048,21.767041065128446,1.4523150276235772,-2.066160162153558
387.4000000000048,21.80425410691275,1.3083353530899597,-2.0967969260956596
388.6000000000048,21.84130230936114,1.1745317530477815,-2.1237903778259843
389.80000000000484,21.87769512761245,1.0597454285307297,-2.1469109376367563
391.0000000000049,21.914708290276565,0.9544093099719302,-2.166959144039029
392.2000000000049,21.951812071350165,0.8669264095914988,-2.18549606273605
393.40000000000487,21.98786064788577,0.7986953086299424,-2.2015053706622725
394.6000000000049,22.025696383683947,0.7402867515524445,-2.2168531787140484
395.80000000000496,22.062630253961878,0.6988683032073095,-2.230087261780712
397.00000000000495,22.09968562228384,0.6671964418990519,-2.2422604685508
398.20000000000493,22.136613070371542,0.6399433479420571,-2.2542421640397725
399.400000000005,22.173867425378965,0.623256875927765,-2.265986122288065
400.600000000005,22.210754567637704,0.609506909488152,-2.277329204231178
401.800000000005,22.247858496294093,0.5968200027513841,-2.2882538618653863
403.000000000005,22.28512015067568,0.5936624027390758,-2.2990774230887885
404.20000000000505,22.322139606366044,0.5883349919454492,-2.310061386183545
405.4000000000051,22.359291746806296,0.5873282348958213,-2.3216467980824897
406.6000000000051,22.396392206915735,0.5863230969449686,-2.3331642578396776
407.80000000000507,22.43381419791481,0.585705355910431,-2.3447565181707746
409.0000000000051,22.47144312524687,0.5850493880350955,-2.356155409544364
410.20000000000516,22.508387295799405,0.5862909330863062,-2.3666022256905133
411.40000000000515,22.545591085023922,0.5878572559690074,-2.378351111375429
412.60000000000514,22.5830500053209,0.5880259685678815,-2.3892973230453203
413.8000000000052,22.620655974311212,0.5923325481553405,-2.4009565264441273
415.00000000000523,22.657744478318016,0.5934957310151079,-2.4132568159931793
416.2000000000052,22.695363873428732,0.5960617987777779,-2.4253122366883133
417.4000000000052,22.73275949282791,0.597111470160345,-2.4369112167250986
418.60000000000525,22.770293014679012,0.6008401720059213,-2.448631750968647
419.8000000000053,22.807481019809096,0.6026569129017936,-2.4607143061355385
421.0000000000053,22.844922057056262,0.601348096475089,-2.473731809830083
422.2000000000053,22.882512721748938,0.6036820126467346,-2.4867597015172302
423.4000000000053,22.92014371009152,0.6081318693226894,-2.500654177132307
424.60000000000537,22.957291688373367,0.6094447148559572,-2.514098330341468
425.80000000000535,22.995119454528247,0.6118457848125929,-2.5275144731071597
427.00000000000534,23.032605083190756,0.6141660622090221,-2.541349740370508
428.2000000000054,23.070158867059583,0.6187835256294278,-2.556799798551365
429.40000000000543,23.10760495608485,0.6214624829561817,-2.5719838154543164
430.6000000000054,23.14556548615167,0.6261062187752309,-2.586870360484594
431.8000000000054,23.183051748901082,0.6330854290863335,-2.603265760996406
433.00000000000546,23.220401261450927,0.6322001972675375,-2.6196973317690952
434.2000000000055,23.25819444898626,0.6370596633734589,-2.63682100671341
435.4000000000055,23.2960361534599,0.6408879099752163,-2.6544590867538314
436.6000000000055,23.333850219198983,0.6439237116646745,-2.6711605426358562
437.8000000000055,23.371455193127687,0.6489437988413631,-2.6888773317651564
439.00000000000557,23.40885839504451,0.6536064185364943,-2.706539829633395
440.20000000000556,23.44658099730524,0.6577920068439655,-2.7254713143490035
441.40000000000555,23.484369946434335,0.6623896431547196,-2.7454465743780565
442.6000000000056,23.5222697250719,0.6674075134237334,-2.763913515748293
443.80000000000564,23.56009249317481,0.6727545177508254,-2.7828727361489802
445.0000000000056,23.5978122261326,0.6733574242269817,-2.802864613600054
446.2000000000056,23.635653684172528,0.6780474627928512,-2.8232062024392244
447.40000000000566,23.673482786336347,0.6787814644361538,-2.844502897794615
448.6000000000057,23.711403319640226,0.6804617516962534,-2.864914220928
449.8000000000057,23.74901208004688,0.6836064853696433,-2.8847848844532553
451.0000000000057,23.78706837679019,0.6829241870199558,-2.9036081589349596
452.20000000000573,23.824971159666603,0.6824186596875648,-2.9219113276000055
453.4000000000058,23.86267916386739,0.681749735384801,-2.938843456009362
454.60000000000576,23.90077913676444,0.6791076040495478,-2.9574264500960434
455.80000000000575,23.938529324632082,0.6758453326560896,-2.9736260627320186
457.0000000000058,23.976532169614792,0.6668819688997047,-2.989907035140478
458.20000000000584,24.01427216601304,0.664337578575225,-3.006707184993996
459.40000000000583,24.052474802871387,0.6547319538047012,-3.021312884180268
460.6000000000058,24.090411070985247,0.6449835406792641,-3.0340957274786486
461.80000000000587,24.128561620063177,0.6367579353646293,-3.046307721065558
463.0000000000059,24.16613055878512,0.6239295577697983,-3.0579476537207877
464.2000000000059,24.203818644398808,0.6069749859448952,-3.0700919566553226
465.4000000000059,24.242139063659213,0.592410305541269,-3.0810183858601468
466.60000000000593,24.28042659119605,0.5758037077795628,-3.090851727624547
467.800000000006,24.31868458033405,0.5565209945486509,-3.1012883210480373
469.00000000000597,24.356216824599443,0.5386769985677078,-3.1091772140368503
470.20000000000596,24.39455518550427,0.5158667834509649,-3.11807526010387
471.400000000006,24.432483591565266,0.4915235778626901,-3.126254279059124
472.60000000000605,24.470638151841673,0.46884327500988743,-3.1345381704747286
473.80000000000604,24.508411288989237,0.445555377404216,-3.140592344214128
475.000000000006,24.546592052178998,0.41967919507291995,-3.148127529397555
476.20000000000607,24.584898517143348,0.3970868591720107,-3.1535579054091936
477.4000000000061,24.62312771778001,0.37549131059251795,-3.1598676950580957
478.6000000000061,24.660998213516763,0.3510915341651024,-3.1646682264577475
479.8000000000061,24.699042350391807,0.32908747584019404,-3.170344052073572
481.00000000000614,24.737336778692615,0.30635503073020964,-3.1752931126595585
482.2000000000062,24.77563960685405,0.28682229421134764,-3.17920507081102
483.4000000000062,24.81374364521544,0.266938261680981,-3.1825281103862078
484.60000000000616,24.85175011006214,0.24839458594810804,-3.185974342628678
485.8000000000062,24.889991805398342,0.23030918740207063,-3.1896433823312504
487.00000000000625,24.92831125003699,0.21388408646526957,-3.1945097786773573
488.20000000000624,24.966576313218972,0.20007080021985235,-3.1976999944989752
489.40000000000623,25.00469939501339,0.18768053978395316,-3.200336745070546
490.6000000000063,25.04299792996069,0.17552678034200708,-3.202808885225041
491.8000000000063,25.081245664533377,0.16252391095942698,-3.205892755516739
493.0000000000063,25.11956081127238,0.1542546731347092,-3.2079787985085004
494.2000000000063,25.157772031567717,0.14512275081231918,-3.2101172080470635
495.40000000000634,25.19618089513144,0.13690608710941543,-3.2131016280351035
496.6000000000064,25.234233490965007,0.1298497668924321,-3.214807341283807
497.8000000000064,25.272715845846786,0.12261029174582116,-3.2183042175937686
499.00000000000637,25.310886196272094,0.12035619973516587,-3.2203440727308665
500.2000000000064,25.349296188465793,0.11304666815848097,-3.221756646270257
501.40000000000646,25.387566596301205,0.1085861958317873,-3.2244172721071536
502.60000000000645,25.425678765625488,0.10384839617397246,-3.22525149708732
503.80000000000643,25.464283764719564,0.10050650177890641,-3.225935334489065
505.0000000000065,25.502903974196542,0.09687190486274155,-3.227643815724383
506.2000000000065,25.540992942196105,0.09426938507345484,-3.229548423966775
507.4000000000065,25.579417710222454,0.09162180470393189,-3.2303677912412097
508.6000000000065,25.618059205786768,0.08953699626902001,-3.23162928377258
509.80000000000655,25.6565090693105,0.08561183841354181,-3.2332418495800126
511.0000000000066,25.694960162967337,0.0839478650347556,-3.234613884204803
512.2000000000066,25.73333417139494,0.08468887247810342,-3.2358948888295433
513.4000000000066,25.771719237745923,0.08201261059574017,-3.2375751424056185
514.6000000000066,25.810569461533962,0.07956063292014637,-3.2389029786893837
515.8000000000067,25.84869115344639,0.07660238746213932,-3.240120364815771
517.0000000000066,25.887436986200633,0.07291314967779683,-3.240939504131795
518.2000000000066,25.925806800166246,0.07466707244446735,-3.2416739518040765
519.4000000000067,25.964505268002025,0.06963323541005306,-3.2429004959513343
520.6000000000067,26.002829498889163,0.06646365251844122,-3.244186298011642
521.8000000000068,26.04160052886002,0.06650963022622336,-3.2441924626801404
523.0000000000067,26.080187253764667,0.06670883904871494,-3.245593306107366
524.2000000000068,26.11857316071103,0.06662824467556305,-3.2482485014574793
525.4000000000068,26.15730120993261,0.0640711568972856,-3.2494085937839667
526.6000000000067,26.19585181582217,0.05884959005579793,-3.2483616269950684
527.8000000000068,26.2344412201474,0.05736204630783326,-3.249590441506003
529.0000000000068,26.273243966992176,0.05570575447623205,-3.2508878551671794
530.2000000000069,26.311745715749346,0.055938026578556066,-3.252368589702311
531.4000000000069,26.350496334423422,0.05272269686447917,-3.2542725983619385
532.6000000000068,26.389104714742754,0.0497287261813002,-3.25494022669254
533.8000000000069,26.42770800843836,0.04681795820953316,-3.256274797361594
535.0000000000069,26.46648463454744,0.045382058470322395,-3.2553407259712914
536.2000000000069,26.504945734672248,0.04416404122128004,-3.256269576519085
537.4000000000069,26.54361136399908,0.04351178663879662,-3.25748172852165
538.600000000007,26.582434297501404,0.04181814542668372,-3.258841941910836
539.800000000007,26.62099578760912,0.04007546133143447,-3.259859562173353
541.000000000007,26.659920082980108,0.03919962498160623,-3.260588170837985
542.200000000007,26.69874091045751,0.03651894562702607,-3.2608659108278637
543.400000000007,26.737525663586318,0.03697061168183402,-3.262174918338778
544.6000000000071,26.776451646330116,0.03523241658894105,-3.2629197619677104
545.800000000007,26.81501382531416,0.032455850345701975,-3.262931062537044
547.000000000007,26.853866083248068,0.02974501565031784,-3.264228405794098
548.2000000000071,26.892830451626708,0.029504172248074445,-3.2656672468633285
549.4000000000071,26.931562461043953,0.028814454652762,-3.2656698539375197
550.6000000000072,26.970366299916183,0.02702508798944181,-3.2675488239755577
551.8000000000071,27.009136729308608,0.025664848102691096,-3.2682072570069725
553.0000000000072,27.048177454648012,0.02465030854747674,-3.2688172667819395
554.2000000000072,27.08719998003841,0.024518040561786414,-3.2701786622926585
555.4000000000071,27.12597109637112,0.023154828376020786,-3.270174190444889
556.6000000000072,27.164699560814288,0.022655736681772565,-3.27147759873781
557.8000000000072,27.20372207343631,0.019425304456965664,-3.271748911842851
559.0000000000073,27.242507145953358,0.01721916634800369,-3.272150894157038
560.2000000000073,27.2813998121908,0.017290598463704843,-3.2734431579098158
561.4000000000073,27.32039258438147,0.01413256802379137,-3.2745512554866423
562.6000000000073,27.359202120578782,0.013232055211131799,-3.2747795376643722
563.8000000000073,27.398326554712675,0.015461604384828576,-3.2761007912918187
565.0000000000073,27.43694183001765,0.017621813738691428,-3.2760997224326394
566.2000000000073,27.475952885028057,0.013658068713503502,-3.2760009949911137
567.4000000000074,27.51501034318575,0.012028114870643591,-3.2774332068276646
568.6000000000074,27.55395918103691,0.008667581091210463,-3.278777707594018
569.8000000000075,27.59300509926371,0.010063001753617629,-3.2786553754848153
571.0000000000074,27.632077125480436,0.00963555672799643,-3.2800476561714573
572.2000000000074,27.671274961382284,0.008164336163290598,-3.2800278767108906
573.4000000000075,27.71020544197394,0.009821501866769333,-3.2813635986470024
574.6000000000074,27.74835066465076,0.0064258842931845805,-3.2813280464600707
575.8000000000075,27.788357663118816,0.004110662501729312,-3.2826522915678247
577.0000000000075,27.82753233465607,0.008145766595466286,-3.283372772534456
578.2000000000075,27.866447636388102,0.00504445615958371,-3.2833411106388057
579.4000000000076,27.90525289650173,0.003459692958775795,-3.2836849963580192
580.6000000000075,27.944503898802626,0.004062248239870225,-3.2846022098153007
581.8000000000076,27.983682624156284,0.0025103719360710652,-3.2859581303592273
583.0000000000076,28.02258078611874,0.0006367799761251014,-3.286127502238618
584.2000000000075,28.061791894861205,0.0025689591265587453,-3.287269215820479
585.4000000000076,28.10084177139966,-0.00077208053387956,-3.2885900502401544
586.6000000000076,28.139964116781794,-0.0034408429483574476,-3.288600391832358
587.8000000000077,28.179170323618806,-0.005378469576962086,-3.2886001833002156
589.0000000000077,28.21838032024296,-0.007336603604066516,-3.289916133340054
590.2000000000077,28.257850204268244,-0.00926864517768844,-3.2912333700947065
591.4000000000077,28.2969858616892,-0.010592902633271839,-3.2912338574450084
592.6000000000078,28.336354961244023,-0.012973345722756768,-3.292529132713048
593.8000000000077,28.375144039771474,-0.013041634156819137,-3.2925510071419595
595.0000000000077,28.414482822928356,-0.01642805157489402,-3.292841119456649
596.2000000000078,28.453775606065985,-0.018370176237422875,-3.2938751028074433
597.4000000000078,28.4930809941177,-0.019689753083986794,-3.2952835877675506
598.6000000000079,28.532442110731072,-0.019394504960542625,-3.295176277562962
599.8000000000078,28.571468228312423,-0.018738883128589068,-3.296327228379528
601.0000000000078,28.610741757548865,-0.02065402794135407,-3.296559899101609
602.2000000000079,28.650096560991365,-0.019432910520043922,-3.2978206337919653
603.4000000000078,28.68936762575596,-0.019081569191313097,-3.2991271235891277
604.6000000000079,28.728416332328152,-0.014691793952267496,-3.2991299867029635
605.8000000000079,28.768034208485798,-0.01598025618921728,-3.29910209488073
607.000000000008,28.80727679271242,-0.019142941305691386,-3.300439373909234
608.200000000008,28.846518584689658,-0.017402960589342653,-3.3017472465909914
609.4000000000079,28.8860464635888,-0.015458184208385406,-3.302901835979977
610.600000000008,28.925529438886052,-0.01668397915678277,-3.3032153731039564
611.800000000008,28.964839780436485,-0.017093142787973914,-3.30451434958783
613.000000000008,29.004375674547184,-0.015462366709071862,-3.304458930308947
614.200000000008,29.043586357839597,-0.015965021856905404,-3.305674993682071
615.400000000008,29.08298630626028,-0.021130795950234038,-3.305931576214127
616.6000000000081,29.122350588842345,-0.021612209672027483,-3.3072648421128537
617.8000000000081,29.16163014612777,-0.02023405099393072,-3.309674699281603
619.0000000000081,29.201121095506092,-0.02462312868622396,-3.3112693815005274
620.2000000000081,29.240491234265093,-0.02592265547325856,-3.312619040371662
621.4000000000082,29.279860342909704,-0.02564947988409827,-3.314085167268916
622.6000000000081,29.319456808153287,-0.023877864841640006,-3.315063977256126
623.8000000000081,29.358843314114935,-0.024217515273797563,-3.3153701378516702
625.0000000000082,29.39836006107174,-0.019314097543741138,-3.316718957162532
626.2000000000082,29.437944391162457,-0.018517637762131667,-3.315477313891658
627.4000000000083,29.476837044644963,-0.015193316965632864,-3.3166304615656075
628.6000000000082,29.51666559880359,-0.012896735227720502,-3.3179177125669517
629.8000000000083,29.55612282205523,-0.009391620781646015,-3.3181341163717195
631.0000000000083,29.595808518442674,-0.007126733992409484,-3.3194348747725475
632.2000000000082,29.635132074146554,-0.006434955554209587,-3.3194309628610696
633.4000000000083,29.674885100013437,-0.00326096270448728,-3.3197643584407373
634.6000000000083,29.714496597189513,-0.0042573828449743445,-3.320425230234041
635.8000000000084,29.753829708054884,-0.002364755407479713,-3.3208399881937227
637.0000000000084,29.79316699750165,-0.002552963242281159,-3.3217312634354004
638.2000000000083,29.83291704504038,-0.00041890585469861463,-3.3218463724502545
639.4000000000084,29.87219153685715,2.7737112686221366e-05,-3.3220595589518647
640.6000000000084,29.912147482438748,-0.001493234562074175,-3.3220836095280486
641.8000000000084,29.95144834449401,-0.004273486667940585,-3.320740238017784
643.0000000000084,29.99105477144681,-0.0008550275855285783,-3.3224298681060964
644.2000000000085,30.030505811635813,-0.004817627634857047,-3.324017197216871
645.4000000000085,30.06982139775368,-0.006691454052436541,-3.3252403630309333
646.6000000000085,30.10981283163859,-0.008952617404175633,-3.3252463643066146
647.8000000000085,30.14917033347088,-0.012327524178337601,-3.3242500495004386
649.0000000000085,30.18859717264592,-0.0088683149530433,-3.3252907930606472
650.2000000000086,30.22838352817758,-0.014729631397339293,-3.327072956399376
651.4000000000085,30.26771334804385,-0.018718845223422154,-3.327319062136374
652.6000000000085,30.307325408070618,-0.022566104019989375,-3.3284226036282654
653.8000000000086,30.346805982835807,-0.023856228475616525,-3.328420065277411
655.0000000000086,30.386452346739926,-0.028939556599294924,-3.32842004881973
656.2000000000087,30.426197320259416,-0.030795674375808435,-3.3284201834867795
657.4000000000086,30.46602140945471,-0.03178330835709664,-3.328544742998842
658.6000000000087,30.505526066451,-0.033323427971690744,-3.32842784592958
659.8000000000087,30.545046484108,-0.03390781418607425,-3.329715257463445
661.0000000000086,30.58447973992007,-0.039100425231269664,-3.3308157191467673
662.2000000000087,30.62395483883391,-0.0391320638649959,-3.3320351623889324
663.4000000000087,30.66378953832407,-0.04470612443826294,-3.33203989128451
664.6000000000088,30.70362757189648,-0.043358478904829134,-3.332040010020203
665.8000000000088,30.74349993577844,-0.045222538992558015,-3.332061680423676
667.0000000000088,30.782950612662255,-0.04568247553502092,-3.3333671672756884
668.2000000000088,30.822525157382177,-0.04645671862703171,-3.3333575305236147
669.4000000000088,30.86220662832811,-0.04877268583940042,-3.334259651926052
670.6000000000088,30.9018246419625,-0.05081036704513808,-3.334668517881092
671.8000000000088,30.9416027129792,-0.04935936508873917,-3.3343477671731856
673.0000000000089,30.981113639016343,-0.054820822560196714,-3.3340264340161943
674.2000000000089,31.020858972579376,-0.05745586872781416,-3.3344986587575747
675.400000000009,31.060548326121964,-0.053768143900118304,-3.335009491369147
676.6000000000089,31.10033501635527,-0.06005503507469623,-3.335010162207309
677.8000000000089,31.13982164949073,-0.05952456036457132,-3.3350118603289927
679.000000000009,31.179301654184968,-0.05831573258441258,-3.3363233767831955
680.2000000000089,31.21926745071496,-0.060329929370052326,-3.336319828697449
681.400000000009,31.259040964055934,-0.06066843772667241,-3.3363198149016835
682.600000000009,31.29886751692277,-0.06402015649456194,-3.3363198150007585
683.800000000009,31.338470820429578,-0.0659994951491103,-3.3363198183213667
685.0000000000091,31.37834550633881,-0.06420657958527665,-3.33632530262929
686.200000000009,31.41817078803145,-0.06321181350053173,-3.3360019541428967
687.4000000000091,31.457917347816615,-0.06722374749103333,-3.3373116724430556
688.6000000000091,31.49767246061095,-0.06521144502065468,-3.337531736917775
689.800000000009,31.537491036051776,-0.0712696291147914,-3.3386338804015456
691.0000000000091,31.577419480260506,-0.073779324686996,-3.3376411820077525
692.2000000000091,31.61694271954143,-0.07367715598284041,-3.3376400196538025
693.4000000000092,31.65677684243426,-0.07788882263003227,-3.3376440685512767
694.6000000000092,31.696778156039763,-0.07473158379241074,-3.3386492500571423
695.8000000000092,31.736396098116547,-0.08074567173582414,-3.3386290538004135
697.0000000000092,31.775563444093482,-0.08204610861546602,-3.3389432069447524
698.2000000000093,31.816012772227005,-0.08460493156735849,-3.3389519674287023
699.4000000000092,31.85608097393022,-0.08550606979357234,-3.3396270619821946
700.6000000000092,31.895604229860165,-0.08853580154184515,-3.3400492541180986
701.8000000000093,31.935396796260015,-0.09286250230025983,-3.3409214085815213
703.0000000000093,31.975229973612873,-0.09535521075628317,-3.3409159900907963
704.2000000000094,32.01511042539845,-0.09777832682571086,-3.3399396244998965
705.4000000000093,32.05508089692347,-0.10260151853802668,-3.339940740032035
706.6000000000093,32.094649413186,-0.10366389469496795,-3.340231669366485
707.8000000000094,32.13448129527166,-0.10501269966669025,-3.3412534134107634
709.0000000000093,32.17435824146097,-0.1111301346440432,-3.3412500645310406
710.2000000000094,32.21423421667708,-0.11394170307604146,-3.3412757106065545
711.4000000000094,32.253825945100296,-0.11511077818002446,-3.342573315076341
712.6000000000095,32.29402866413112,-0.11939984530611802,-3.3425700269997334
713.8000000000095,32.33378947034766,-0.12405046713867485,-3.342570008082922
715.0000000000094,32.37391761210964,-0.1198047986982731,-3.3425700060041112
716.2000000000095,32.4136475296301,-0.12256658057196201,-3.342569570341656
717.4000000000095,32.453662674631744,-0.12675724295163437,-3.343181943558707
718.6000000000095,32.493468779070085,-0.12286122594264537,-3.3428981206852044
719.8000000000095,32.533561016335106,-0.12680362974144854,-3.3429016666953153
721.0000000000095,32.573591977878685,-0.13145018254030338,-3.3432819763538473
722.2000000000096,32.61347267923429,-0.12687266156650923,-3.344220599064771
723.4000000000096,32.65328900044259,-0.13300038922227797,-3.3442203564121105
724.6000000000096,32.69317984981048,-0.13389191141151713,-3.3438736195045067
725.8000000000096,32.73347363598296,-0.13774659481198404,-3.3452243907201975
727.0000000000097,32.77334391385184,-0.14026949750782558,-3.3452107274266947
728.2000000000096,32.81328534057156,-0.14398024422792766,-3.345405431833916
729.4000000000096,32.85327175126173,-0.14521541371361257,-3.346523633789074
730.6000000000097,32.89324732957042,-0.1503953956193267,-3.3465199450630787
731.8000000000097,32.933060370974104,-0.1527895551026872,-3.3465200169420584
733.0000000000098,32.97283296864641,-0.1561942065391082,-3.346554755826598
734.2000000000097,33.01311901145965,-0.15864743374554058,-3.3478475161657397
735.4000000000098,33.05264562593634,-0.1604253621492946,-3.3478400591215647
736.6000000000098,33.09297659709984,-0.16396282933387152,-3.3478413965589344
737.8000000000097,33.13302320833787,-0.1642932355648159,-3.3481800350601802
739.0000000000098,33.172836680189164,-0.1673730528829136,-3.3478395183876692
740.2000000000098,33.21294911935982,-0.16553642250080403,-3.3478401629796917
741.4000000000099,33.25295322160674,-0.1691176259714493,-3.3478502195593767
742.6000000000099,33.292954716340034,-0.1736324360868684,-3.349200870974958
743.8000000000098,33.333125380750694,-0.17357179993235228,-3.349150445716654
745.0000000000099,33.37280583924033,-0.17637515030221707,-3.3491501772616505
746.2000000000099,33.41312287025135,-0.1812712799708942,-3.3491501612850256
747.4000000000099,33.453041664470575,-0.17982064278397036,-3.349147300583262
748.6000000000099,33.49305580697391,-0.18027356199353362,-3.3501231843678037
749.80000000001,33.53317663978136,-0.18511403020203243,-3.3504656577609158
751.00000000001,33.573410560322294,-0.18520561149602033,-3.351466623760598
752.20000000001,33.61341886403062,-0.18895796316576385,-3.351778959701606
753.40000000001,33.65361819822075,-0.19380799156892925,-3.3517799287883774
754.60000000001,33.693644820907444,-0.19804252805782507,-3.351780133658969
755.8000000000101,33.73375115176486,-0.19926996849897272,-3.3508312223725136
757.00000000001,33.77386238936749,-0.2013781377445003,-3.3504697578628644
758.20000000001,33.81364270911454,-0.20103829456350342,-3.3504250487862692
759.4000000000101,33.85393098931374,-0.20838243719719785,-3.3517767206141578
760.6000000000101,33.89430816420782,-0.20546579108444485,-3.351789976929658
761.8000000000102,33.93428081985574,-0.20466840454401236,-3.3518417510157383
763.0000000000101,33.974509579198326,-0.2078008053239544,-3.350800331343301
764.2000000000102,34.015030542785254,-0.20669349820271954,-3.350794945399341
765.4000000000102,34.054840518803736,-0.21182529421967766,-3.3519124556961137
766.6000000000101,34.09508880984218,-0.2080447979936122,-3.3517864981758674
767.8000000000102,34.135215181110844,-0.20877829090380162,-3.3529017008824016
769.0000000000102,34.17528648498815,-0.21327454671320467,-3.3530991398549475
770.2000000000103,34.21559803233404,-0.2106423766140133,-3.3530444791023157
771.4000000000103,34.256077271355224,-0.2166611334843136,-3.354412051904188
772.6000000000103,34.29578740985536,-0.21910710702154734,-3.3544198378613874
773.8000000000103,34.33614840663847,-0.21385821573926123,-3.3544198758110935
775.0000000000103,34.37655541780735,-0.21558190546074218,-3.3544198970667454
776.2000000000103,34.416755343142306,-0.21800163360440328,-3.354480407789293
777.4000000000103,34.45684501185688,-0.21535520671112485,-3.353104518837108
778.6000000000104,34.49711248343707,-0.2180384167019822,-3.353291013261453
779.8000000000104,34.53717938503854,-0.2185325385975294,-3.354422627731445
781.0000000000105,34.57741562417478,-0.22061606428638303,-3.354420044342282
782.2000000000104,34.61761750737781,-0.22502763670746972,-3.3546258194246903
783.4000000000104,34.65823445711339,-0.22454504149311072,-3.3557312783172657
784.6000000000105,34.698552114187024,-0.22421910600179285,-3.35573002730134
785.8000000000104,34.73848772028656,-0.22635089564700683,-3.3557276201589135
787.0000000000105,34.77906794777631,-0.22965035827513436,-3.356962684713431
788.2000000000105,34.81926690869324,-0.23249984834670512,-3.355739853109645
789.4000000000106,34.859823812413985,-0.23255276498904065,-3.356097752782105
790.6000000000106,34.89993565351444,-0.23383390222724065,-3.3563999969685865
791.8000000000105,34.940317355479955,-0.2352899982261687,-3.35640392364453
793.0000000000106,34.980738143203965,-0.23776229995970866,-3.3570354858074594