File: 01_Data/Cotton_Rug/STA/N2/30K_min/Cotton_Rug_STA_N2_30KData_220113_R3.csv
##Temp./Â°C,Time/min,DSC/(mW/mg),Mass loss/mg
49.0,10.513482720554606,0.03498234565395664,0.003306774077223018
50.20000000000002,10.725460257784048,0.09013972000759174,0.0021023746660571163
51.400000000000034,10.854087825847364,0.13260282481819974,0.0006783702830119864
52.60000000000005,10.956251437328117,0.17161564909341553,0.00237986287904679
53.80000000000007,11.043527244127224,0.20772141896615737,0.0009483794116995625
55.000000000000085,11.121191489817116,0.2384012052680653,0.0019767738512799227
56.2000000000001,11.191086722119321,0.26575096896942346,0.0018615431521000758
57.40000000000012,11.257144874477763,0.2911896284259281,0.0011179517837875963
58.600000000000136,11.319787259142858,0.3166105250551343,0.0016586835220762097
59.80000000000015,11.378217879862099,0.33877032878343655,0.0015044201325133955
61.00000000000017,11.435150241133837,0.36096923723787844,0.001615840871846963
62.20000000000019,11.490276355307921,0.37975732095127435,0.000853973587144452
63.400000000000205,11.543179356880898,0.3981917709503202,0.0018405777544874269
64.60000000000022,11.594679139856105,0.4162649807122608,0.0024687623137875647
65.80000000000024,11.644703176184851,0.43191071711823226,0.0024660254422546046
67.00000000000026,11.694467548075377,0.45039117057556055,0.002611808231752555
68.20000000000027,11.743060859041247,0.4650103541264433,0.0010922146602254657
69.40000000000029,11.790689945709218,0.4787614646275917,0.000690738392275847
70.6000000000003,11.837861846916933,0.4925741815183347,0.0007532671982746209
71.80000000000032,11.88417331736728,0.5010443391602388,0.0019018668897796687
73.00000000000034,11.930398730415195,0.5091783122207988,0.0020270787369431886
74.20000000000036,11.975754139051425,0.5199888858373194,0.002717822241457668
75.40000000000038,12.020790293794231,0.5246671419611215,0.0018374034999437683
76.60000000000039,12.065378881310973,0.5313513269447727,0.00030278181268084126
77.80000000000041,12.109448223928132,0.5367199274161206,-0.00014410919985863302
79.00000000000043,12.153576195574097,0.5415205290379643,0.0006735277492806446
80.20000000000044,12.196897415311598,0.5479579010722695,-0.0008480975919145095
81.40000000000046,12.240249444671582,0.5547118849615575,-0.0008750375236896701
82.60000000000048,12.283456881491139,0.5612897770125493,-0.000891485652798174
83.8000000000005,12.326452221472245,0.5676700519612923,-0.0009018500245687733
85.00000000000051,12.368943415777098,0.5724171231014011,-0.0006310057299403482
86.20000000000053,12.410939274322219,0.5792820492764542,-0.0006636021175179252
87.40000000000055,12.452854492569962,0.584034912626876,0.0006687612373195151
88.60000000000056,12.495018764849021,0.58774378593235,0.0005983074150375245
89.80000000000058,12.536779704953954,0.593821102318716,0.00014385737250854902
91.0000000000006,12.578331955993473,0.6001035203448863,-9.400396880998585e-05
92.20000000000061,12.619897200500823,0.6048044441972449,0.0003467106202084125
93.40000000000063,12.661018325201049,0.6112569563156818,-0.0009910835876993929
94.60000000000065,12.702385632172337,0.6162999560868427,-0.0018270698468567659
95.80000000000067,12.74326624884791,0.6200777020017959,-0.0018784536573939192
97.00000000000068,12.78414165895883,0.6247159612465634,-0.0022808231850488525
98.2000000000007,12.825231102697442,0.6289940561767393,-0.0022985946922604583
99.40000000000072,12.866006015060027,0.6333357988785067,-0.002300433630974652
100.60000000000073,12.907248521092669,0.6376008258811257,-0.0031777121937448527
101.80000000000075,12.947781460035953,0.6413715211275871,-0.0022985739941345784
103.00000000000077,12.988252100398045,0.6446622168820271,-0.003454180028173326
104.20000000000078,13.028923201877939,0.64871248315001,-0.003610708283371622
105.4000000000008,13.069473234046555,0.6498028132230302,-0.002935414969229555
106.60000000000082,13.109600955173521,0.6558604352996922,-0.003620156881471104
107.80000000000084,13.150493498245902,0.6569949144336873,-0.003788009400173209
109.00000000000085,13.19089370234152,0.6582054083872245,-0.0035852684230750498
110.20000000000087,13.231641022334957,0.6626479177155097,-0.003805461732431681
111.40000000000089,13.271710579065406,0.6644312881012953,-0.004929734293825483
112.6000000000009,13.311857331600265,0.6670367576823365,-0.004929507065367211
113.80000000000092,13.351974454160182,0.6692399201665347,-0.004846531993580427
115.00000000000094,13.392550801203228,0.6715726688307511,-0.0036200993134185566
116.20000000000095,13.432562770553861,0.6731736223751037,-0.004938173925806311
117.40000000000097,13.472548963190809,0.677079442802314,-0.004939939403428184
118.60000000000099,13.513066611976738,0.6780475047044716,-0.004940189841157405
119.800000000001,13.552642553043206,0.6808652454809566,-0.006222150781989733
121.00000000000102,13.592913838615429,0.6824031658130895,-0.006249788533335909
122.20000000000104,13.63301048869253,0.6863018200985005,-0.006211872388442785
123.40000000000106,13.672401343294894,0.6848824699976901,-0.005256168192123489
124.60000000000107,13.711822614469428,0.6879168278336563,-0.005256752095256445
125.80000000000109,13.752072945998725,0.6917890951342045,-0.005253740902986692
127.00000000000111,13.791701820165608,0.693714800500091,-0.004867204835102612
128.20000000000113,13.830941482653053,0.6960326662122593,-0.005956423178899328
129.40000000000114,13.87043241060681,0.6947737463285876,-0.00625013534246488
130.60000000000116,13.909766170754903,0.6983546384359185,-0.006250199979907833
131.80000000000118,13.948596135211387,0.7018759689270826,-0.00625020173823021
133.0000000000012,13.988058524341453,0.7033077173555767,-0.006250597040271089
134.2000000000012,14.026800408492747,0.7043770925033453,-0.005191070133103715
135.40000000000123,14.066044032113767,0.7088744661085382,-0.004931452123687841
136.60000000000124,14.10540428565555,0.7132523915295713,-0.005037366768902096
137.80000000000126,14.14399666622098,0.7155699129960627,-0.0059201749839585815
139.00000000000128,14.182617450536478,0.7195229844385195,-0.005904174626283343
140.2000000000013,14.221684218097126,0.7221131026464169,-0.006575632913238927
141.4000000000013,14.260132050184152,0.7248781544343634,-0.006904507335574017
142.60000000000133,14.298764537898492,0.7298938816673187,-0.0069110322985119765
143.80000000000135,14.337210035521608,0.7331785137010548,-0.00813100096566366
145.00000000000136,14.37576641199895,0.733252240606671,-0.006903867144917086
146.20000000000138,14.414122325570647,0.7377448099193455,-0.006898538160639234
147.4000000000014,14.45150061935367,0.7424027004746556,-0.005572291063367096
148.60000000000142,14.490346161457065,0.7484091605220725,-0.005599958617206191
149.80000000000143,14.529055934472787,0.7522268839150678,-0.005604118963317362
151.00000000000145,14.567246471537151,0.7548041506989817,-0.008204465580728737
152.20000000000147,14.605310706707613,0.7587817810553042,-0.008219775847065236
153.40000000000148,14.642864792460367,0.7623240542798279,-0.00821991902843866
154.6000000000015,14.681355740160503,0.7679261425693071,-0.008221521581857516
155.80000000000152,14.719349677254456,0.7693700835503147,-0.006881255166944378
157.00000000000153,14.757295549883189,0.7755011185146691,-0.008231539753508876
158.20000000000155,14.795196613296978,0.7781137280882935,-0.008315723993982616
159.40000000000157,14.833405200456223,0.7825583238113052,-0.006912278309588515
160.6000000000016,14.871363753199843,0.786018395822616,-0.0069101667120108345
161.8000000000016,14.908983802148772,0.789928617372672,-0.00691016020179358
163.00000000000162,14.946505110727786,0.7924430823087509,-0.006910253982140624
164.20000000000164,14.984684764766179,0.7986801256003779,-0.006926403075921073
165.40000000000165,15.02238047650429,0.8010502574267204,-0.007553722591906009
166.60000000000167,15.060097245530192,0.8059744535158174,-0.0075698448536760665
167.8000000000017,15.097658658452577,0.8079487935976799,-0.007569850851746551
169.0000000000017,15.135503765916974,0.8094793456756393,-0.007569850010427537
170.20000000000172,15.172818872263429,0.8138742598245333,-0.007569753506152743
171.40000000000174,15.210307616425302,0.8189938784646452,-0.008096079032288372
172.60000000000176,15.247032706050863,0.8243404092801061,-0.008889780834340222
173.80000000000177,15.285487588082477,0.8262717737728242,-0.008889883232843232
175.0000000000018,15.32294213819023,0.8298839952513608,-0.008893907882799645
176.2000000000018,15.359968063522357,0.8337208787399896,-0.009549493483280713
177.40000000000182,15.397416515621778,0.8375586054044029,-0.009549692501066076
178.60000000000184,15.43474629040332,0.8388058790106293,-0.009549947568462613
179.80000000000186,15.472581807094352,0.8428069787844124,-0.009549951162707515
181.00000000000188,15.509539372519136,0.8475938778655788,-0.009549919579991517
182.2000000000019,15.546583144533667,0.8487006940105328,-0.009525968747880142
183.4000000000019,15.583920971460909,0.8515082761452698,-0.008220734567922605
184.60000000000193,15.62003139921217,0.8538819500712884,-0.00823015831423568
185.80000000000194,15.657773683703079,0.8604427414995974,-0.008227420710046118
187.00000000000196,15.694665603488106,0.8626804975885125,-0.009549098446881565
188.20000000000198,15.731847733990127,0.8682546037067496,-0.010206858014732312
189.400000000002,15.769010446103536,0.8699027411328265,-0.010528213371615358
190.600000000002,15.805636838530372,0.8735048147648447,-0.010402528950781864
191.80000000000203,15.842534008527926,0.8779014668410721,-0.009539740887585246
193.00000000000205,15.879495440718594,0.8819996659360028,-0.009539905127936343
194.20000000000206,15.91638627520767,0.8840854047466906,-0.009545284649746577
195.40000000000208,15.953212273608495,0.8878710729112369,-0.010851062316074689
196.6000000000021,15.989817170397693,0.891749289639453,-0.010859876421369208
197.80000000000211,16.02665245339472,0.8972628102559635,-0.010825741691835589
199.00000000000213,16.063713653594995,0.9021565473742721,-0.011191840023846211
200.20000000000215,16.100356545817608,0.9043245127289273,-0.009954023046384819
201.40000000000217,16.136752874571062,0.9071306086548254,-0.009870015781003438
202.60000000000218,16.17357611731478,0.9117816982012525,-0.00986993209688869
203.8000000000022,16.210365408342298,0.9157434287099668,-0.00986964805528956
205.00000000000222,16.247043185326902,0.919930340726187,-0.011236435703287917
206.20000000000223,16.283841085755064,0.9236412799006427,-0.011178146880583384
207.40000000000225,16.32044509248436,0.9290812829991288,-0.012521568327598764
208.60000000000227,16.35703201411257,0.934964779685874,-0.012499919204991272
209.80000000000229,16.393306810861038,0.9411693934116565,-0.012499899987625795
211.0000000000023,16.42996891164751,0.948683532476849,-0.012499900862050772
212.20000000000232,16.466506810587152,0.9507761486115454,-0.012499029683911367
213.40000000000234,16.5033421838524,0.9567765943751612,-0.011136184633509849
214.60000000000235,16.539692868795445,0.9621079384094045,-0.011179938667916112
215.80000000000237,16.576458809377055,0.9646517670480487,-0.01117985049484993
217.0000000000024,16.613110301283438,0.9704093817022039,-0.013006579227874404
218.2000000000024,16.649582511456508,0.9743906666665596,-0.013820531482643617
219.40000000000242,16.686213149318274,0.9782922973499286,-0.013812112356799133
220.60000000000244,16.72294367334985,0.9808292032586018,-0.014909593663261944
221.80000000000246,16.75950165920906,0.9830891905911359,-0.014809652866479617
223.00000000000247,16.795735556240974,0.9873630457020031,-0.01480982979399137
224.2000000000025,16.83245457778666,0.9897544619293593,-0.014809748296063852
225.4000000000025,16.869066496954424,0.9960917522284309,-0.014814231017532542
226.60000000000252,16.905409434669433,0.9982102920179173,-0.015122059000660215
227.80000000000254,16.941819985810813,1.003748296827137,-0.0151388462389912
229.00000000000256,16.977967707873276,1.0102886418794097,-0.01643842813705554
230.20000000000258,17.01484626417625,1.0147610858198797,-0.01645102469224291
231.4000000000026,17.05123848603272,1.0232227364363353,-0.01782747032407972
232.6000000000026,17.087391929187344,1.0286231176667608,-0.019105234239522595
233.80000000000263,17.12399789595353,1.0395243832848489,-0.018965042502641083
235.00000000000264,17.16043016437983,1.0476659799929258,-0.018760145617504165
236.20000000000266,17.196683938648626,1.0602216144781695,-0.018759980191458858
237.40000000000268,17.233151873842868,1.0746909942063403,-0.01875984348352766
238.6000000000027,17.269596274383236,1.0904609460173644,-0.018762598569035838
239.8000000000027,17.306052583996493,1.1171719647310128,-0.020220999931888528
241.00000000000273,17.342620179176844,1.1450443200863623,-0.021346154845995002
242.20000000000275,17.379071714861105,1.1725821956604636,-0.021501279692443198
243.40000000000276,17.415150474860692,1.203709822658112,-0.02290521102773635
244.60000000000278,17.451593930635266,1.23483631436303,-0.022806241360138202
245.8000000000028,17.487888230170274,1.267075528004515,-0.02262573877881202
247.0000000000028,17.524478627860248,1.3219038249532693,-0.023584630497348158
248.20000000000283,17.5608924569898,1.4084856837257627,-0.023579095863591526
249.40000000000285,17.597286637828617,1.511508984988444,-0.024952005131331667
250.60000000000286,17.633534552396895,1.603811486196978,-0.0249001560341906
251.80000000000288,17.670062696057883,1.6751614884569532,-0.02489933520919596
253.0000000000029,17.706578266135786,1.7077599080172816,-0.026243001525957155
254.20000000000292,17.74311630770449,1.704431443517056,-0.026206974859964483
255.40000000000293,17.77926598365915,1.6444206718481191,-0.027542008813560948
256.600000000003,17.815719211601113,1.5590033711592906,-0.027422703895148892
257.80000000000297,17.85176191083198,1.4741565191851556,-0.028854489622417212
259.00000000000296,17.88852232491752,1.3972377337953266,-0.030115121316864446
260.200000000003,17.924577100996764,1.3387718867019718,-0.030438313716638632
261.40000000000305,17.96080215486665,1.289156985745497,-0.03180469162377353
262.60000000000304,17.99745325740031,1.2518391976403755,-0.03300653459249592
263.800000000003,18.033679299546083,1.2216192440458755,-0.034182935838144246
265.00000000000307,18.06883435795529,1.2007828949894281,-0.0351005263988835
266.2000000000031,18.10580583270738,1.1821519777227225,-0.03663657035060819
267.4000000000031,18.141991725769163,1.169606013473067,-0.03741341866886483
268.6000000000031,18.17814739113419,1.1603992765175646,-0.038630128614794756
269.80000000000314,18.21432094926055,1.1528330428882283,-0.040628366386537884
271.0000000000032,18.250511391602597,1.1454443703087205,-0.041710585817685164
272.2000000000032,18.28657411622009,1.1442219570964487,-0.04380445182117576
273.40000000000316,18.322845742780604,1.1449118946382144,-0.045598402706538366
274.6000000000032,18.35914067056315,1.1453342415380714,-0.04757849699676431
275.80000000000325,18.395304902171244,1.1444081896217888,-0.04939935308517551
277.00000000000324,18.431377781944164,1.1453437500522023,-0.052175265458632936
278.20000000000323,18.467661197730617,1.1489322897057623,-0.054820214957659985
279.4000000000033,18.504015728532497,1.149579724676659,-0.05639991926521848
280.6000000000033,18.540510835336104,1.1543752757366712,-0.059170492368308736
281.8000000000033,18.576474158839392,1.15820820466912,-0.061185133833213
283.0000000000033,18.612626585802275,1.163188960496366,-0.06282570044421387
284.20000000000334,18.64900203267796,1.167299200298046,-0.06617965345046439
285.4000000000034,18.685481807499087,1.1718473692754445,-0.06725098166198151
286.6000000000034,18.721504987192564,1.1766521652326696,-0.07060295997692467
287.80000000000337,18.757974064631018,1.1809830492882916,-0.07283578614286235
289.0000000000034,18.794368506836022,1.188746587166761,-0.07645465439468957
290.20000000000346,18.830683536766593,1.1960302985985902,-0.07990830710037233
291.40000000000344,18.866736082801918,1.2019336518500137,-0.08323631524895525
292.60000000000343,18.903191987041563,1.2071438007795674,-0.08911159807738489
293.8000000000035,18.939583132117495,1.2157981355873897,-0.09231231221042169
295.0000000000035,18.976171708737606,1.2229985069934828,-0.0952243884988846
296.2000000000035,19.012108629529035,1.2309634000110432,-0.09890524351868368
297.4000000000035,19.048698182400017,1.2406919220220638,-0.10282750827888787
298.60000000000355,19.08521386680301,1.247545897377825,-0.10734649942810082
299.8000000000036,19.121276222328742,1.2572360257981585,-0.11233846305996709
301.0000000000036,19.157685107451027,1.2668219704111665,-0.11770914502281116
302.20000000000357,19.194008577906974,1.275580566033081,-0.12329176318025059
303.4000000000036,19.230666124282735,1.2847963668283913,-0.129491959246272
304.60000000000366,19.266723355695238,1.2942726479470061,-0.1352597938575144
305.80000000000365,19.302938192305174,1.302280765478947,-0.14110515481721952
307.00000000000364,19.339215015230113,1.3149315434402271,-0.1472205658364114
308.2000000000037,19.376076701882404,1.3240361226575432,-0.15397989683948765
309.40000000000373,19.41240528062921,1.3317329135437999,-0.15869596921907103
310.6000000000037,19.449018607303618,1.3435853105278877,-0.16564385080022648
311.8000000000037,19.485508475477545,1.354090483478926,-0.17229260349983377
313.00000000000375,19.521675855402723,1.3632863951647716,-0.18064560009874997
314.2000000000038,19.55805032870781,1.3733962295717226,-0.1891148934005491
315.4000000000038,19.594809461181047,1.383023249996413,-0.1968039935320336
316.6000000000038,19.631068291445644,1.3944127175005436,-0.20522583002033024
317.8000000000038,19.66748472182233,1.4029763488651112,-0.21417390098975098
319.00000000000387,19.70396102262002,1.4073312618958416,-0.22279437132863444
320.20000000000385,19.740188492148306,1.4198606419838318,-0.23214353227793705
321.40000000000384,19.77682687790068,1.426390109010379,-0.24036358780956402
322.6000000000039,19.812501927466293,1.4353000534596925,-0.2500034508980913
323.80000000000393,19.849817013603378,1.4417929211172256,-0.2611064677199608
325.0000000000039,19.88655002949395,1.4503091980947784,-0.2722398977189804
326.2000000000039,19.92291782177797,1.4610535149271704,-0.2834221670376844
327.40000000000396,19.9593685508404,1.4696969350820681,-0.2970044240803751
328.600000000004,19.995841437662833,1.4792104077622241,-0.3106005219744197
329.800000000004,20.031957664173678,1.490286331173037,-0.32231308507433853
331.000000000004,20.069146465900943,1.5032715396262293,-0.3347502083774683
332.200000000004,20.105466054364374,1.5161268633651857,-0.34827443705195016
333.40000000000407,20.142111498073632,1.5342253638292016,-0.36218325066500956
334.60000000000406,20.177877630557063,1.5542126906552443,-0.3753949590340313
335.80000000000405,20.21575257291026,1.578188518586558,-0.39101446272612383
337.0000000000041,20.25238767134156,1.5973137594519362,-0.40950999784903974
338.20000000000414,20.28865939990124,1.6255458066931245,-0.4272660310244327
339.4000000000041,20.32559734820083,1.652787723245317,-0.4455654240885276
340.6000000000041,20.36212012091293,1.6839864541637972,-0.46494454785402795
341.80000000000416,20.39890071041128,1.7178983111043769,-0.4847721152195592
343.0000000000042,20.435506302188664,1.7505607408891146,-0.5051463826524913
344.2000000000042,20.4721900082926,1.786050893061629,-0.52528629540264
345.4000000000042,20.50882983406649,1.8238447415040362,-0.5479397055273516
346.60000000000423,20.545251551754852,1.8643730201915971,-0.5731410756845468
347.8000000000043,20.58239724955874,1.9032572459962516,-0.5992900955536333
349.00000000000426,20.619483102994817,1.9461008351436184,-0.6265194701137053
350.20000000000425,20.65616810678397,1.9908046665955657,-0.653606543531486
351.4000000000043,20.692993733501428,2.0374147469751827,-0.6834534252957827
352.60000000000434,20.730061237026547,2.089120846439897,-0.7142107010118153
353.80000000000433,20.766812712737575,2.142710451926164,-0.7477862764063077
355.0000000000043,20.803667432212837,2.1990294583860486,-0.7838511223590912
356.20000000000437,20.840861946737583,2.2625681465958194,-0.8208453314790045
357.4000000000044,20.877745491228087,2.3289337681478606,-0.8598446870738004
358.6000000000044,20.91466388276335,2.3975835777084042,-0.9020704385287064
359.8000000000044,20.950695878328077,2.4685123231200934,-0.9441153710812973
361.00000000000443,20.988524467712327,2.5432220485732313,-0.9910055174245866
362.2000000000045,21.025697283994553,2.617411967260618,-1.038271389533417
363.40000000000447,21.06327460449306,2.6934753688744335,-1.0882902807732124
364.60000000000446,21.100031848950344,2.7597341979620067,-1.1400264347427873
365.8000000000045,21.136859680128783,2.818332567851542,-1.193146012748271
367.00000000000455,21.173853079773757,2.8689719556647333,-1.2482141743606152
368.20000000000454,21.211650203996005,2.9109114922465205,-1.307849288158263
369.4000000000045,21.248592780127716,2.9331159979130628,-1.3676122143950287
370.60000000000457,21.285650411280322,2.9525430076028965,-1.4282433526300706
371.8000000000046,21.322994775657342,2.954150498582044,-1.4896751121607243
373.0000000000046,21.360276569644917,2.9486624201947236,-1.5523262279946772
374.2000000000046,21.397327240102506,2.924972172731821,-1.6149848248546683
375.40000000000464,21.43437080918771,2.8815677486298283,-1.6768107977510018
376.6000000000047,21.471528519843226,2.8225251389424653,-1.7379471703586842
377.8000000000047,21.50876994219929,2.739926292601272,-1.7977527724294329
379.00000000000466,21.545872327091473,2.6333851512761086,-1.8560240544887905
380.2000000000047,21.583095521265125,2.5047907521484154,-1.91301827042258
381.40000000000475,21.620000306353113,2.36023678896427,-1.9639305997737986
382.60000000000474,21.656773343304398,2.19992653349114,-2.0127025211510094
383.80000000000473,21.694415940956915,2.027907140643565,-2.05900193560987
385.0000000000048,21.731151281377045,1.8516586892286855,-2.10038852697807
386.2000000000048,21.767995537746067,1.6801534961059588,-2.138051831150751
387.4000000000048,21.804092398722137,1.518528657699057,-2.1705632590371913
388.6000000000048,21.84176021991511,1.3621098731905572,-2.1998876182418226
389.80000000000484,21.878699941037382,1.2271843339919573,-2.225760437238642
391.0000000000049,21.915656066074234,1.1088640931636085,-2.247272293293184
392.2000000000049,21.95293842115397,1.0060061476629079,-2.266743229259964
393.40000000000487,21.98948319516129,0.9254907785210494,-2.284836716407194
394.6000000000049,22.026622099890773,0.8592231586773467,-2.3008061866982477
395.80000000000496,22.06336130308093,0.8112241760090357,-2.3144175433147662
397.00000000000495,22.100362025713576,0.7718395575724427,-2.3269126831858005
398.20000000000493,22.137499183038578,0.7419145890227293,-2.339274774915709
399.400000000005,22.174563401830788,0.7204528267842037,-2.35132820589625
400.600000000005,22.211737381639303,0.7054797574127802,-2.363338437645527
401.800000000005,22.248701197045335,0.6928901117338806,-2.3754979341436675
403.000000000005,22.28581652562605,0.6849345195390508,-2.3872759506787773
404.20000000000505,22.322877904900196,0.6810506191110882,-2.4000644455849995
405.4000000000051,22.36028136622295,0.6757201428776822,-2.4132885372513426
406.6000000000051,22.397373404903206,0.6760247653348247,-2.4242818046336705
407.80000000000507,22.433861507320955,0.6730875457589521,-2.4353563501790423
409.0000000000051,22.472077741190382,0.6736503045070343,-2.4479711297447015
410.20000000000516,22.509245807124863,0.6748441428048397,-2.4583527193166432
411.40000000000515,22.54672742868776,0.6744449157417652,-2.469985801798976
412.60000000000514,22.58402654285528,0.6789387637048842,-2.4813055381853273
413.8000000000052,22.62145014494255,0.6834734945164446,-2.492468383933711
415.00000000000523,22.65872147351365,0.6840194400523276,-2.5064743963949185
416.2000000000052,22.69636407191277,0.6855178294447055,-2.519175957684967
417.4000000000052,22.73347222618376,0.686788020902727,-2.5307888004284234
418.60000000000525,22.77059141996895,0.6926023003861561,-2.543495579369713
419.8000000000053,22.808692397594694,0.6932476221456051,-2.557398322995251
421.0000000000053,22.845939559236484,0.697726544138792,-2.57138074825723
422.2000000000053,22.88355119712002,0.698455440809087,-2.584044461158796
423.4000000000053,22.921211292923385,0.7050172489143918,-2.5979564652998395
424.60000000000537,22.958357177008665,0.7045853725810788,-2.611994919069803
425.80000000000535,22.995904418393835,0.7067003437792063,-2.625365783063984
427.00000000000534,23.033708434675646,0.713478763767639,-2.6394840444236385
428.2000000000054,23.0713363100167,0.716215984372273,-2.657951275615845
429.40000000000543,23.108005725711603,0.7176969099735403,-2.672658982322386
430.6000000000054,23.14649175357031,0.7235663732584947,-2.688678314029656
431.8000000000054,23.18429580171128,0.7271310934612004,-2.705072521590476
433.00000000000546,23.221769061568853,0.7337440815686254,-2.722352569198292
434.2000000000055,23.25933350451533,0.7384639768139181,-2.7389474964275946
435.4000000000055,23.297221914589127,0.7434043472168793,-2.7561531762844425
436.6000000000055,23.334576613565073,0.7495021050589417,-2.7734502006456876
437.8000000000055,23.37254851042248,0.7531350215565332,-2.7930617111212
439.00000000000557,23.409936526314894,0.7558228288928378,-2.8120958684130777
440.20000000000556,23.447829887094677,0.762974612144024,-2.8317707588565377
441.40000000000555,23.485495983927816,0.7660205786190954,-2.852349534761305
442.6000000000056,23.523353619423066,0.769694927889878,-2.873145148562151
443.80000000000564,23.560917454225695,0.773504623826601,-2.8927921098679166
445.0000000000056,23.598632849499833,0.7754576152790331,-2.9096691808711768
446.2000000000056,23.636474889229394,0.7766504923264932,-2.930847827889782
447.40000000000566,23.674176577634547,0.7782435396614111,-2.9540280897106372
448.6000000000057,23.712068805517752,0.7789907444509956,-2.974137337526541
449.8000000000057,23.749936726013317,0.7800981822768441,-2.9929766206651296
451.0000000000057,23.788146671310265,0.7769201082119098,-3.012606825859061
452.20000000000573,23.825324161530773,0.7758508531477204,-3.030502446604723
453.4000000000058,23.863538562313686,0.7704592161335657,-3.050068337165695
454.60000000000576,23.901709166434813,0.769243712112636,-3.067078305954028
455.80000000000575,23.93915816684966,0.7641841529991631,-3.0828765038942776
457.0000000000058,23.977174075021487,0.7570936629765346,-3.0964589236047138
458.20000000000584,24.015058464498246,0.7516051038701737,-3.1113652699881955
459.40000000000583,24.052573593608646,0.740214188650719,-3.127444166972455
460.6000000000058,24.090954809019635,0.7293234646549447,-3.1402628709120877
461.80000000000587,24.12868670766757,0.7182193245673645,-3.151282709002311
463.0000000000059,24.16663845589823,0.7038191864020769,-3.1636081830699165
464.2000000000059,24.204852278810936,0.6894549100290175,-3.1738665385324527
465.4000000000059,24.242457909859553,0.6711806595445347,-3.1843286497406513
466.60000000000593,24.280557570695958,0.6566846881577368,-3.1949364244547387
467.800000000006,24.318679281496756,0.6373118512122644,-3.2038952066322404
469.00000000000597,24.35699616525744,0.6154981545601657,-3.2130564995359454
470.20000000000596,24.394592570573558,0.5901542455276281,-3.2204751100532683
471.400000000006,24.432522701440053,0.5724079953456676,-3.227777259032293
472.60000000000605,24.470448144250966,0.5528549254040069,-3.2340315109660045
473.80000000000604,24.50862395674444,0.5303410691737238,-3.2424757653817617
475.000000000006,24.54664026398179,0.5096007252836245,-3.248210165517519
476.20000000000607,24.584533211934723,0.48891188532807184,-3.254499774881262
477.4000000000061,24.6229246538096,0.4670210477596952,-3.259543095753597
478.6000000000061,24.660944944931003,0.44519635366291577,-3.2650408500912405
479.8000000000061,24.699228207518296,0.4251417782624647,-3.269631712742163
481.00000000000614,24.737073726072197,0.41145396005931123,-3.273955230116494
482.2000000000062,24.775401227005126,0.390557058641785,-3.278920922009407
483.4000000000062,24.81361192913583,0.37685376721268504,-3.2828819416456696
484.60000000000616,24.85184193203404,0.360226761729733,-3.285487536235955
485.8000000000062,24.889836829891216,0.34828822877827714,-3.287934342563356
487.00000000000625,24.92789047645877,0.33549826166484853,-3.2918033313465296
488.20000000000624,24.966241656666483,0.32673503374744906,-3.2947143701538817
489.40000000000623,25.004663154786645,0.3136063997957852,-3.297128292989507
490.6000000000063,25.042655024692994,0.30567255281849315,-3.300363423832702
491.8000000000063,25.081011668915643,0.2966509779918258,-3.3028590980488435
493.0000000000063,25.11944832997205,0.29181223898319586,-3.3054986249871776
494.2000000000063,25.157512600392952,0.2825222832743324,-3.3072678009706165
495.40000000000634,25.1957919534926,0.27316749424673015,-3.309953449002805
496.6000000000064,25.23404732774941,0.2690483185331274,-3.3117953488767586
497.8000000000064,25.272446052304606,0.26460219464173873,-3.313978263937571
499.00000000000637,25.311180911958594,0.25827341525174585,-3.3170584483165744
500.2000000000064,25.349212134778373,0.2541303855828907,-3.3184482212299495
501.40000000000646,25.387714500284908,0.2515648614799839,-3.319777521953536
502.60000000000645,25.425893198885973,0.24874116450004613,-3.3212064017611436
503.80000000000643,25.464428876596994,0.2482386003258541,-3.3227141837370384
505.0000000000065,25.50270247240565,0.24472196745284513,-3.324593009144083
506.2000000000065,25.541090481613875,0.24320037171398856,-3.32709746512423
507.4000000000065,25.57961542669115,0.2420552804761118,-3.327440698504346
508.6000000000065,25.618119187088837,0.23874563093335377,-3.328816262326205
509.80000000000655,25.656772364728095,0.23663628523407865,-3.3310935298356843
511.0000000000066,25.69507095355126,0.23759736905987805,-3.332386052178963
512.2000000000066,25.73336738680597,0.2338807434922865,-3.333817205105435
513.4000000000066,25.772110251271215,0.23055156480275696,-3.335131015324386
514.6000000000066,25.810474597461038,0.23065687432243331,-3.3361133015300926
515.8000000000067,25.849125162246345,0.22981498187871918,-3.336099754665859
517.0000000000066,25.887797651255962,0.23056665551402222,-3.3372529484375177
518.2000000000066,25.926085911226934,0.22747242319970584,-3.3375124312313336
519.4000000000067,25.964742523401856,0.22739184453694428,-3.338663601559813
520.6000000000067,26.003344315220637,0.22579343939235264,-3.3400482214771374
521.8000000000068,26.041755668440608,0.22317556583180798,-3.340060144101062
523.0000000000067,26.080354770691425,0.22602740460353066,-3.3413728732777916
524.2000000000068,26.119045332913235,0.22354416430286128,-3.3426880444891687
525.4000000000068,26.157771388295085,0.22226255069701706,-3.344002531915854
526.6000000000067,26.196621570856653,0.2198201672980562,-3.3450289612679427
527.8000000000068,26.235099163075336,0.21985687718234637,-3.3452739595176073
529.0000000000068,26.273783473369207,0.21669379653027332,-3.3466176543830377
530.2000000000069,26.312229190577444,0.2174458246374973,-3.346804569448904
531.4000000000069,26.351189993237703,0.21356602969318428,-3.3480262996833567
532.6000000000068,26.389678050431094,0.21573074295571004,-3.349368762061374
533.8000000000069,26.428586221267352,0.2124426148768388,-3.3506826434286436
535.0000000000069,26.466821141416386,0.21164835312610863,-3.3521078644950206
536.2000000000069,26.505857422081686,0.21183208129979247,-3.3535311077230174
537.4000000000069,26.544676247771307,0.20642216253694623,-3.354632071323966
538.600000000007,26.583447301100815,0.20736070911228266,-3.355838574593397
539.800000000007,26.622072070873696,0.20712868109882132,-3.355895177421019
541.000000000007,26.66109202971872,0.20408258798657242,-3.3563259475722576
542.200000000007,26.699835582902587,0.20228721268380867,-3.3564867581864286
543.400000000007,26.738757690766956,0.20057345189827314,-3.3574912269112027
544.6000000000071,26.777504052669823,0.1984804879022921,-3.3574430373148423
545.800000000007,26.81618213769999,0.19603697331573877,-3.3599913348152564
547.000000000007,26.8549131915935,0.19489261632517874,-3.360119675211177
548.2000000000071,26.89399076750665,0.19284458097529078,-3.3600811158772377
549.4000000000071,26.9328335581383,0.18894432690577956,-3.3614145081838656
550.6000000000072,26.971679046151714,0.18935470000823962,-3.362228462833417
551.8000000000071,27.01068740586424,0.19131760721648727,-3.362755602544434
553.0000000000072,27.049115505692708,0.184593906619124,-3.362761575338157
554.2000000000072,27.088336016942478,0.18617989181789452,-3.364057829507381
555.4000000000071,27.127221379880528,0.18393260725424998,-3.3640693002314674
556.6000000000072,27.165911885352642,0.18076604143394825,-3.3650272171508373
557.8000000000072,27.20489318729903,0.1798317787923247,-3.36545233593163
559.0000000000073,27.243887089718303,0.17715035374835741,-3.3667202544371384
560.2000000000073,27.282655610512492,0.17408362355823992,-3.367321730405507
561.4000000000073,27.321491766856546,0.17341481548861348,-3.3686760153400956
562.6000000000073,27.360357413573364,0.17067886748688732,-3.3699893463425914
563.8000000000073,27.399271050230002,0.16983697372298945,-3.371311020280879
565.0000000000073,27.438238884987452,0.1665849982799692,-3.3713099889796747
566.2000000000073,27.477354868574768,0.167130471523931,-3.371304099326631
567.4000000000074,27.516258192655762,0.16191636437896983,-3.372610430793684
568.6000000000074,27.555192514814443,0.1632885419819996,-3.3725306530014203
569.8000000000075,27.59421431822498,0.1600994110873697,-3.3739485140453302
571.0000000000074,27.633314669664344,0.159118107820845,-3.3739513157431382
572.2000000000074,27.67251555660666,0.15462279314672456,-3.374145054363775
573.4000000000075,27.711514845392138,0.15776241864194462,-3.3752604881790864
574.6000000000074,27.75028974521648,0.15235951398806358,-3.3752699451044004
575.8000000000075,27.78979732737247,0.15180932985100415,-3.376579856829996
577.0000000000075,27.82856691886225,0.15180831762893487,-3.377918651802929
578.2000000000075,27.867436712596245,0.15252519162429024,-3.3778903975869747
579.4000000000076,27.906746348431646,0.15159155746042519,-3.3780021088223835
580.6000000000075,27.945778188015183,0.1511936350528642,-3.379340059571534
581.8000000000076,27.985127112141043,0.14422972359274833,-3.3806893752518103
583.0000000000076,28.023085691891637,0.14579898318253592,-3.3809699265769804
584.2000000000075,28.063358729299313,0.14244920985496168,-3.3819600135722534
585.4000000000076,28.102530204702077,0.1412521027705067,-3.382598130102788
586.6000000000076,28.141497097824487,0.13798216449817668,-3.3825851609962614
587.8000000000077,28.180561665520568,0.13986917232251295,-3.3839173873002126
589.0000000000077,28.21986811320683,0.13685812245209394,-3.385235833364798
590.2000000000077,28.259061612195406,0.13591969684579608,-3.3852404825400666
591.4000000000077,28.29827079117862,0.13709838149009212,-3.3865642632588204
592.6000000000078,28.337355457949574,0.13602373761516318,-3.387865829309174
593.8000000000077,28.376323503392182,0.13491456475356034,-3.389014632198099
595.0000000000077,28.415600077393194,0.13322524951539316,-3.3891958841598555
596.2000000000078,28.454810925432366,0.13278962005744654,-3.3891123130989125
597.4000000000078,28.49400600903457,0.13202961022212079,-3.3892018172635323
598.6000000000079,28.53345765132765,0.1257126910378379,-3.390507108163491
599.8000000000078,28.57243477113197,0.13075781588775337,-3.39050021335611
601.0000000000078,28.611548866136246,0.12911437159485684,-3.390498151671453
602.2000000000079,28.651086921639077,0.13260648427477006,-3.39180692548213
603.4000000000078,28.690392634742807,0.12963737826890553,-3.3918428879640135
604.6000000000079,28.729534574493506,0.1308057356543466,-3.3931297559054334
605.8000000000079,28.768821841315287,0.12987048300323467,-3.393130012322608
607.000000000008,28.808018850849464,0.1318027922863041,-3.393151935441797
608.200000000008,28.847607241361654,0.12983428554351484,-3.3931716681976583
609.4000000000079,28.886876370010565,0.12810536875983636,-3.3938033230599416
610.600000000008,28.92633759509448,0.1281699484287222,-3.396982048802837
611.800000000008,28.96574658679026,0.1257108190462577,-3.3984042629743865
613.000000000008,29.005219684284782,0.12257660294098094,-3.3991005509775554
614.200000000008,29.044581162132516,0.12211408513391131,-3.4008251309732733
615.400000000008,29.08382713779383,0.11781451254142605,-3.401947284187271
616.6000000000081,29.12322726445047,0.11514745744268806,-3.4033670464816415
617.8000000000081,29.16239923129224,0.1160505754720298,-3.4053380912304756
619.0000000000081,29.202205762202578,0.11594982009883248,-3.4052135228133995
620.2000000000081,29.241467179245053,0.11439835373161,-3.406090074499612
621.4000000000082,29.28083199030922,0.11633815367068334,-3.4074020120510182
622.6000000000081,29.320164042101812,0.11515337943633064,-3.4087174576179335
623.8000000000081,29.35969802613374,0.11294101115058375,-3.4093450966027006
625.0000000000082,29.399131718881026,0.11196314667355978,-3.409987992019032
626.2000000000082,29.43847453256536,0.10837292427112044,-3.4113605181432654
627.4000000000083,29.478155984212442,0.10732045847861627,-3.412687748730353
628.6000000000082,29.51766535009748,0.10635143695651705,-3.4131296245546796
629.8000000000083,29.556974808890345,0.10004953769834679,-3.4139820800094154
631.0000000000083,29.59676203676402,0.09869927068060225,-3.4139940499588364
632.2000000000082,29.635782059170516,0.09634766942323902,-3.4153469636140885
633.4000000000083,29.675538226802388,0.09462265951305615,-3.4156023652100984
634.6000000000083,29.71506917682826,0.09332140566878144,-3.416613758638986
635.8000000000084,29.75480534329946,0.0880760222964867,-3.417501840585317
637.0000000000084,29.794196798893164,0.08697005360493737,-3.4179201327678346
638.2000000000083,29.83358874406546,0.08462454243398776,-3.417945821331002
639.4000000000084,29.873242544950596,0.0822025946529914,-3.4166091612897467
640.6000000000084,29.912722502967135,0.07759118128017395,-3.4166100663158936
641.8000000000084,29.95161566355255,0.07873918432652083,-3.416608601653633
643.0000000000084,29.99124641836987,0.07254471735497225,-3.417915310303873
644.2000000000085,30.031389665049073,0.07268465238244781,-3.4179303648103483
645.4000000000085,30.070766341029866,0.06713418435622476,-3.419285210565275
646.6000000000085,30.110657197848866,0.06231133926754873,-3.419244180044651
647.8000000000085,30.15013192351978,0.061502682012395615,-3.420558979752748
649.0000000000085,30.189504933720468,0.057723057867841154,-3.420566984387562
650.2000000000086,30.229269607841417,0.053072890783986804,-3.4218807850562127
651.4000000000085,30.26901375613268,0.05207913653501439,-3.421879815837903
652.6000000000085,30.30878978551013,0.05262427207653997,-3.4218795159490014
653.8000000000086,30.34821975975243,0.04808736616463749,-3.423074888802156
655.0000000000086,30.38767912100844,0.04394530947009745,-3.423199178404097
656.2000000000087,30.42762031927461,0.04237706775312278,-3.4232000236270475
657.4000000000086,30.46750082103092,0.04018783130589054,-3.4232515409591713
658.6000000000087,30.507105666718715,0.0367495101431905,-3.421791921694399
659.8000000000087,30.54654807777084,0.03195647399191692,-3.4231822844357964
661.0000000000086,30.586303603461158,0.028693182899542702,-3.424471488899277
662.2000000000087,30.62542169975404,0.02574206806277224,-3.4245100997435878
663.4000000000087,30.66566056862927,0.028243190443886013,-3.42452461190564
664.6000000000088,30.705073393084746,0.025726994788751734,-3.4258643780440856
665.8000000000088,30.745155256314565,0.02469355552379393,-3.4258203279193835
667.0000000000088,30.784470083888014,0.01829346129022391,-3.425820119804032
668.2000000000088,30.824025359931245,0.019163307525263518,-3.4258217127149324
669.4000000000088,30.86397049241563,0.015101702136557593,-3.426166476613665
670.6000000000088,30.90383078663695,0.012959133164028414,-3.428461296351305
671.8000000000088,30.94276879238377,0.011887548166468864,-3.4284600754631454
673.0000000000089,30.98304551117095,0.009717146630420226,-3.427279598420776
674.2000000000089,31.02274144060761,0.006249561649408264,-3.4284636402870636
675.400000000009,31.06238619432156,0.003906758899677953,-3.428460116516335
676.6000000000089,31.102129723326026,0.004357136454938848,-3.4284601000810406
677.8000000000089,31.14178858990068,-0.00016397334526230267,-3.428460099317118
679.000000000009,31.181865297523153,-0.0005704140553093318,-3.4284599666309457
680.2000000000089,31.2212106981817,-0.0072542596550357885,-3.4289026208827167
681.400000000009,31.2608947087187,-0.008754162757155681,-3.4297691791530913
682.600000000009,31.300822025284745,-0.010333945351025609,-3.4297643934234876
683.800000000009,31.340165374725682,-0.013895662734018988,-3.4284543191900774
685.0000000000091,31.380191680817898,-0.013395835385327626,-3.429456171370839
686.200000000009,31.42016170188073,-0.015381707760676155,-3.4297704727909277
687.4000000000091,31.45959783368537,-0.018160814247222712,-3.4310882957302593
688.6000000000091,31.49910311771975,-0.02048334206972946,-3.431102946124601
689.800000000009,31.53962992009024,-0.021979772151634602,-3.433392931775889
691.0000000000091,31.579153790613134,-0.02719998886932329,-3.433719975684375
692.2000000000091,31.619176244923658,-0.02668546145452444,-3.433731145186444
693.4000000000092,31.65912200702581,-0.03291983006616506,-3.4350410700661858
694.6000000000092,31.698672709599663,-0.03524191778905239,-3.4350398906602866
695.8000000000092,31.738420552294354,-0.03731054251079979,-3.434969434848762
697.0000000000092,31.778277840753987,-0.04205776435951769,-3.435026433587938
698.2000000000093,31.818164714618035,-0.04405664942020904,-3.435030135776231
699.4000000000092,31.857685328250152,-0.04582015555174057,-3.4350301399159493
700.6000000000092,31.89780481293949,-0.04885371198337718,-3.4350301291218734
701.8000000000093,31.937710566811358,-0.05261686579741398,-3.4350279003315514
703.0000000000093,31.97758546696486,-0.05343689358105719,-3.4353772653127663
704.2000000000094,32.01757777768364,-0.05934159428873498,-3.4353602603286535
705.4000000000093,32.057253226611174,-0.06311787333703744,-3.435355900277431
706.6000000000093,32.09710571414971,-0.0667808683141713,-3.4363052789622763
707.8000000000094,32.137116738030166,-0.06902281561525414,-3.4357010542493
709.0000000000093,32.176732250473634,-0.07160638071340086,-3.4357148628369467
710.2000000000094,32.216780164409364,-0.07198717509334696,-3.4370547314487947
711.4000000000094,32.256398776311194,-0.07646986593143246,-3.437020324993023
712.6000000000095,32.2964193080218,-0.07966405721200376,-3.437020130993603
713.8000000000095,32.33626697505414,-0.08140115709401319,-3.4370201300079564
715.0000000000094,32.376325266021595,-0.08864727050771104,-3.437020131328647
716.2000000000095,32.41610955553426,-0.0885533196572752,-3.437022465214241
717.4000000000095,32.45624970254427,-0.09040725868074118,-3.4363727921929925
718.6000000000095,32.49589751751486,-0.09511171824356968,-3.4374614057958053
719.8000000000095,32.53585207818443,-0.09926932659285592,-3.43667908775095
721.0000000000095,32.575728666640686,-0.10036635073285449,-3.437429093886167
722.2000000000096,32.615659046805064,-0.10531764357991147,-3.4376782665293897
723.4000000000096,32.655819154375116,-0.10523228532009954,-3.4380069440600876
724.6000000000096,32.69548467419501,-0.10941947778524996,-3.4393535392076955
725.8000000000096,32.73536881202278,-0.10825531404238786,-3.43931003337979
727.0000000000097,32.775653627143804,-0.11006806349604714,-3.439309821002453
728.2000000000096,32.81545056669148,-0.11698417440826159,-3.4393098004587044
729.4000000000096,32.85553901154201,-0.12006480148877507,-3.4393061868103842
730.6000000000097,32.895455356045936,-0.12302552988140603,-3.4403976942949805
731.8000000000097,32.935531187030435,-0.12757270348340333,-3.440625368531787
733.0000000000098,32.97525721695024,-0.12828494729051032,-3.441703950959501
734.2000000000097,33.01544339218141,-0.13208049765603835,-3.4419488730509515
735.4000000000098,33.055246669318535,-0.13521081057137785,-3.4419497844010505
736.6000000000098,33.095477154542415,-0.13481568272264033,-3.4419457237715796
737.8000000000097,33.134955899111155,-0.138366638703586,-3.443234135155574
739.0000000000098,33.17537644169613,-0.14186948040169467,-3.4432600128726896
740.2000000000098,33.21539781141816,-0.14378932599681526,-3.4429533877407037
741.4000000000099,33.25516662212188,-0.14937346550038022,-3.442930145449543
742.6000000000099,33.29528874571471,-0.15368970944697358,-3.44233164904558
743.8000000000098,33.33525426923482,-0.15599171258966527,-3.4425063598369734
745.0000000000099,33.37553432636917,-0.1584288853418383,-3.442939251732584
746.2000000000099,33.41547765709338,-0.15908471737103325,-3.4432354122853077
747.4000000000099,33.455305709582596,-0.16740980434396713,-3.4442635243314235
748.6000000000099,33.49535886149926,-0.16837863546347132,-3.444260177495663
749.80000000001,33.53537614065363,-0.17097574855649,-3.4442601600872464
751.00000000001,33.5758781675289,-0.17800761250685504,-3.4442601585362276
752.20000000001,33.615757194564516,-0.17831811799710184,-3.4442598567998752
753.40000000001,33.6556258793787,-0.1852608558920661,-3.444916201574146
754.60000000001,33.69578697171732,-0.18437505416365108,-3.4468696444624087
755.8000000000101,33.73559579353323,-0.1885959066605798,-3.4455751770405025
757.00000000001,33.77566557451117,-0.19077438103846456,-3.445570112376292
758.20000000001,33.815831032567814,-0.19056571148681645,-3.4455701098221505
759.4000000000101,33.85601461041135,-0.1947674014430345,-3.4455700725589176
760.6000000000101,33.89612668121579,-0.1981066376351035,-3.4455630523889513
761.8000000000102,33.936169130336154,-0.20119778222408335,-3.44685448449539
763.0000000000101,33.97635914148718,-0.20612419185440478,-3.4468898249437223
764.2000000000102,34.01597920035658,-0.20980712509700394,-3.446891923322136
765.4000000000102,34.05668966659849,-0.21092935803570034,-3.447547473591986
766.6000000000101,34.09637529137796,-0.2139328573592576,-3.448200445379588
767.8000000000102,34.136946384827894,-0.215900680498597,-3.4472790464498355
769.0000000000102,34.177008407163,-0.21768513615477447,-3.448230821038967
770.2000000000103,34.21720812927644,-0.22285017204215452,-3.4482001930544444
771.4000000000103,34.25744720736835,-0.22319807010573367,-3.4481989051147903
772.6000000000103,34.29769164928797,-0.22230400529297834,-3.449075192424309
773.8000000000103,34.33791589135723,-0.22427166947021115,-3.4500669442006724
775.0000000000103,34.377825889891646,-0.22801689929995606,-3.45018017365144
776.2000000000103,34.41824843073263,-0.22972772199724378,-3.4501800705429324
777.4000000000103,34.45818007173205,-0.23166673927833736,-3.4501698284354934
778.6000000000104,34.49855606575243,-0.2340191543229957,-3.449189326086285
779.8000000000104,34.538496326424315,-0.23861031731205795,-3.4491976120738164
781.0000000000105,34.57886928034964,-0.24384716083481006,-3.4504114420174785
782.2000000000104,34.61919878322932,-0.24675737758737037,-3.452188261352218
783.4000000000104,34.659455044278346,-0.24670479021915392,-3.4525939769217002
784.6000000000105,34.69966102305673,-0.24992090677328394,-3.453103645912935
785.8000000000104,34.739839497432044,-0.25583387451390394,-3.452590026624346
787.0000000000105,34.78006798691119,-0.25327929224205636,-3.452590069966316
788.2000000000105,34.82065475827491,-0.25279623159355413,-3.452590069999342
789.4000000000106,34.86069885339791,-0.2555916673889107,-3.4525900700039482
790.6000000000106,34.901076007286754,-0.2612816681876633,-3.4525900712135695
791.8000000000105,34.94121974752805,-0.2596420030498847,-3.4525903407460383
793.0000000000106,34.98155518222172,-0.25527074882026524,-3.4526596311921534