File: 01_Data/EIFS_XPS/STA/N2/30K_min/EIFS_XPS_STA_N2_30KData_230901_R3.csv
##Temp./Â°C,Time/min,DSC/(mW/mg),Mass loss/mg
41.0,10.538835100862444,0.027042606497710953,0.0036631811732799058
42.100000000000016,10.742843826645982,0.06977920404988192,0.005096205130440623
43.20000000000003,10.870869263410924,0.1069818375215994,0.002816373379422199
44.30000000000005,10.967071045680667,0.13829396230784452,0.00436571657724194
45.40000000000006,11.0503461355699,0.1742703157453649,0.0037841047594056043
46.50000000000008,11.126492007648169,0.19974684352469163,0.0036742553154378577
47.600000000000094,11.196125717854699,0.2252583372976702,0.004024831800974571
48.70000000000011,11.259551471422183,0.2503494223236322,0.0032656752959527857
49.800000000000125,11.318541109619009,0.27039237984443387,0.004551821833835401
50.90000000000014,11.375761833294808,0.29149641234125734,0.003739767460801957
52.000000000000156,11.430562635153994,0.30854170896168953,0.0040738595487122
53.10000000000017,11.48290606814214,0.3272281276640092,0.0041785038575223865
54.20000000000019,11.53144125888374,0.3442338894257517,0.0038700795187058823
55.3000000000002,11.581725990000594,0.3587825593173706,0.0033818061003154654
56.40000000000022,11.630027635026934,0.37534165128000274,0.004342955527097292
57.500000000000234,11.676698444864105,0.3871583306409183,0.0036015559246553863
58.60000000000025,11.722742304767744,0.39861707444501304,0.00387471606267642
59.700000000000266,11.767382562155442,0.4100712837832625,0.003508109301785911
60.80000000000028,11.81149214351205,0.42029778590256517,0.004600121691713088
61.9000000000003,11.854745486873002,0.43035021988574007,0.004784094420321239
63.00000000000031,11.897446655889649,0.4407268836770937,0.005126143226727997
64.10000000000034,11.940791599576919,0.44702722617680357,0.00674905628919209
65.20000000000034,11.982526703898001,0.4553598134716663,0.005904845641075962
66.30000000000035,12.023712071676632,0.4638991054740089,0.004693365646023739
67.40000000000038,12.064367401350623,0.47068924227455344,0.005119719264881972
68.5000000000004,12.105606836947983,0.48028120271205643,0.004502450836645799
69.6000000000004,12.146072298942041,0.4860041835811595,0.004474898260432347
70.70000000000041,12.18524554882651,0.49209853108175095,0.0049302487880922286
71.80000000000044,12.226935560991679,0.49678671761115534,0.005055518953064997
72.90000000000046,12.266252735514092,0.505245457499071,0.004618115636614295
74.00000000000047,12.306108376366451,0.5089073310255867,0.0040546962761998095
75.10000000000048,12.345096663220716,0.5161254316473434,0.004585450291724413
76.2000000000005,12.384705316951774,0.5246996405501536,0.004052799922584782
77.30000000000052,12.423710877863966,0.5293944592720976,0.004843840544777489
78.40000000000053,12.462556935465312,0.5366204479219041,0.004776645858899364
79.50000000000054,12.501261585639243,0.5440580315080605,0.004368035699715556
80.60000000000056,12.540116558192958,0.5507233379679297,0.003689306552014493
81.70000000000059,12.578457708773474,0.560464269372474,0.0035341850116599183
82.8000000000006,12.617037339722977,0.5663861136959802,0.0033168929509890255
83.9000000000006,12.655227555726995,0.5763304517820962,0.0031481938381308083
85.00000000000063,12.693715017282928,0.5837934515488239,0.003480625371485413
86.10000000000065,12.73120896159575,0.5862515764281611,0.003510462489934252
87.20000000000066,12.76937600168677,0.5837405482250095,0.0036333578137281997
88.30000000000067,12.805729995359354,0.5756422938970303,0.0026903226013561543
89.40000000000069,12.844207634222162,0.5679161654803062,0.0035019599240628807
90.50000000000071,12.881182042643816,0.554260857834727,0.0022279082275038498
91.60000000000072,12.918474350084633,0.5491093435012382,0.002297844069895749
92.70000000000073,12.955425206918148,0.5493783325613739,0.002300829501831636
93.80000000000075,12.992410921024398,0.5435661532747953,0.0023145846896541755
94.90000000000077,13.029589096222928,0.5443020387943165,0.002296104203376892
96.00000000000078,13.066588033066273,0.5472540798562364,0.0023029774500602507
97.10000000000079,13.103587461376165,0.5527341835493071,0.002272243252566586
98.20000000000081,13.140659683503689,0.5539153946110249,0.002431681736986935
99.30000000000084,13.17759634541564,0.5620838773523746,0.0023100186306979076
100.40000000000084,13.214026357797062,0.5695154290419451,0.002306235469565099
101.50000000000085,13.251044263072297,0.578224332106761,0.002272165077576549
102.60000000000088,13.287934007067065,0.5896209839310385,0.0023128915320360655
103.7000000000009,13.32444863554236,0.6030861968456027,0.0018743031905184004
104.8000000000009,13.361495116369788,0.618579593462618,0.0022981388112155443
105.90000000000092,13.398302760389864,0.634197924142113,0.002299868393936144
107.00000000000094,13.43494987832609,0.6565674862774077,0.002293623700855729
108.10000000000096,13.472355233860096,0.6786580722776033,0.0028230970998559535
109.20000000000097,13.50897101588677,0.7029531163926266,0.0023099057070981033
110.30000000000098,13.546402033525867,0.7247705400739095,0.00230715555648775
111.400000000001,13.583305705410277,0.7478883576842531,0.0008973899927142703
112.50000000000102,13.61951428039826,0.7655128986924261,0.0009845009759912315
113.60000000000103,13.656364739702463,0.785634371717565,-0.00037564002918388795
114.70000000000104,13.693078213575786,0.8006439731072831,-0.0003189689704674592
115.80000000000106,13.728960020084813,0.8139305466710686,0.0009837915346406767
116.90000000000109,13.766525519893765,0.8244714081361507,0.000989515427900045
118.0000000000011,13.802923271054336,0.8437502754685606,0.0009901474714792968
119.1000000000011,13.839426844312067,0.8561424850045635,0.0009964295899487219
120.20000000000113,13.87602877776646,0.8707498148155796,-0.0009804899316581128
121.30000000000115,13.912326051025568,0.8830117446340616,-0.0011782462582541342
122.40000000000116,13.948671659074577,0.896838649044881,-0.0016505106986604012
123.50000000000117,13.98483634212275,0.9087581441059628,-0.0017343779028933248
124.60000000000119,14.020884023965642,0.9155787874551756,-0.002999287650565563
125.70000000000121,14.056795415445517,0.9207898764773885,-0.004286305148445635
126.80000000000122,14.092665399793573,0.9232370276435293,-0.004280164822683563
127.90000000000123,14.12861234027437,0.9185441976641059,-0.004302249757790033
129.00000000000125,14.164038630750598,0.907379477088687,-0.005277332659178846
130.10000000000127,14.199716635252216,0.9023189433818296,-0.005976255160697441
131.2000000000013,14.235121083205827,0.8888813459280022,-0.006592652442162006
132.3000000000013,14.270373989525602,0.8805532326035097,-0.0065888144837153995
133.4000000000013,14.30519085157653,0.8662251388652616,-0.007979424992416106
134.50000000000134,14.340529117169071,0.853459869409861,-0.007900412161579329
135.60000000000133,14.375755870894595,0.8413062097608868,-0.00790007046331409
136.70000000000135,14.409949710346028,0.831954042875812,-0.007900077190044819
137.80000000000138,14.445346279656077,0.8206772249196875,-0.007900106775393212
138.9000000000014,14.480995912185369,0.8116435816724646,-0.007898022177702302
140.00000000000142,14.515916161677204,0.8077226897871709,-0.008265024073145444
141.10000000000142,14.550936328261265,0.8003499631738457,-0.008243502674235348
142.20000000000144,14.584944341840545,0.7963441400131492,-0.008871327218683778
143.30000000000146,14.620761575403986,0.7905146620832854,-0.008890211060246234
144.40000000000146,14.655374268651384,0.7909227600611053,-0.008890739160945849
145.50000000000148,14.690297452080513,0.7901312549413154,-0.008836742992221591
146.6000000000015,14.724640366660836,0.7889154871896972,-0.009554695608747998
147.70000000000152,14.759542294344763,0.7890439602631227,-0.009550047646808224
148.80000000000155,14.794566291015007,0.7906411429725775,-0.009532801461634044
149.90000000000154,14.82920140384428,0.7932064619323662,-0.008890188086534412
151.00000000000156,14.863966542897966,0.7929225414418742,-0.008889512816038891
152.1000000000016,14.898361636916365,0.7967317370306628,-0.008889837964288994
153.20000000000158,14.932958915843345,0.7973800140854689,-0.008889837035924941
154.3000000000016,14.967535390355206,0.7969817705037026,-0.008889836999783185
155.40000000000163,15.002064956652484,0.8018099557893235,-0.00888983699987067
156.50000000000165,15.036264493863875,0.8033110941194956,-0.008889836853850142
157.60000000000167,15.070813549523754,0.804272179620567,-0.008889841100416795
158.70000000000167,15.105411943824835,0.8053521663513658,-0.008890899529823137
159.8000000000017,15.138922178477777,0.8074293418496011,-0.010011199148020289
160.9000000000017,15.17390883762874,0.8094455104103218,-0.010207795293442512
162.0000000000017,15.208674905078299,0.8112065154534761,-0.010216395153554991
163.10000000000173,15.242575694388648,0.8128054341733332,-0.009566324132635806
164.20000000000175,15.27720351444357,0.8147055088228222,-0.009559764786684966
165.30000000000177,15.311994789778039,0.8161603422135059,-0.009559814336114414
166.4000000000018,15.345009943267238,0.8184982373899593,-0.009559815438754615
167.5000000000018,15.379564568047098,0.819854180716999,-0.009559820217666992
168.6000000000018,15.414372578571543,0.8211690772955242,-0.00955545036164418
169.70000000000184,15.448360765626521,0.823494100082879,-0.010158970746469098
170.80000000000183,15.48281361665874,0.8250804123406231,-0.01054138047887676
171.90000000000185,15.516940691335895,0.8253484941972694,-0.01054007388186129
173.00000000000188,15.550785306381929,0.8270206612390502,-0.010535509031187829
174.1000000000019,15.58527514258852,0.8291567349263869,-0.011707652392813461
175.20000000000192,15.619324405660674,0.8326650778243952,-0.011850245141144189
176.30000000000192,15.653311758086964,0.8330177797080751,-0.011849958621237722
177.40000000000194,15.687242200296106,0.8337492032521551,-0.011849956949890661
178.50000000000196,15.721684384956127,0.8345384546171379,-0.011849957000194422
179.60000000000196,15.755372160299489,0.8376936089394565,-0.011849957000001243
180.70000000000198,15.78858067198879,0.839245645712321,-0.011849957000169997
181.800000000002,15.823288591343696,0.84136338951848,-0.011849957006335732
182.90000000000202,15.856966867513087,0.8451428833371278,-0.011849955253194544
184.00000000000205,15.89108979696247,0.8431485127351454,-0.01185001129675678
185.10000000000204,15.92480766102785,0.8438056439791647,-0.01185640123594478
186.20000000000206,15.95889134553294,0.844513592786379,-0.012563441408145692
187.3000000000021,15.992481356143964,0.8452020062118696,-0.01250980151048875
188.40000000000208,16.025995627312685,0.84593264222982,-0.012509936393692467
189.5000000000021,16.05968093778821,0.8462063128636385,-0.012509742802835344
190.60000000000213,16.093674712327704,0.8468104600553532,-0.012653844365895672
191.70000000000215,16.1271280117025,0.8473583492513448,-0.012849454518384373
192.80000000000217,16.160608441943527,0.8491559382531051,-0.013161213264659466
193.90000000000217,16.1940112423023,0.8524923832625189,-0.013651795756214558
195.0000000000022,16.22790915266256,0.8504961642769979,-0.013869294895437978
196.1000000000022,16.261893141721174,0.852302133535362,-0.012843329954475013
197.2000000000022,16.294918020772826,0.8514373941116842,-0.0128402248217232
198.30000000000223,16.328887659658065,0.8532149726484635,-0.012840125725916973
199.40000000000225,16.362165105521044,0.8531601218128538,-0.012840556996159158
200.50000000000227,16.395870413902006,0.8537754598122298,-0.01425345392041688
201.6000000000023,16.429230242590794,0.8569229316026956,-0.014160727362329872
202.7000000000023,16.463071199111607,0.8589854404948192,-0.015465074504942944
203.8000000000023,16.496348760152998,0.8599577292792526,-0.015480007777595617
204.90000000000234,16.530005057440814,0.8617029127678102,-0.015479858589170892
206.00000000000233,16.563347230762755,0.8621973196175978,-0.015479856823091165
207.10000000000235,16.59704206091805,0.8622213827578666,-0.015479915570906666
208.20000000000238,16.62987425036939,0.8660396607458066,-0.01548156759604824
209.3000000000024,16.663951997568642,0.8681573568193455,-0.016521376711629454
210.40000000000242,16.69769279112724,0.8709031704766057,-0.016751746076581586
211.50000000000242,16.73056361640597,0.8740604508301772,-0.017445361988387642
212.60000000000244,16.76431822013282,0.8738568310764094,-0.01745994287973085
213.70000000000246,16.797502159190984,0.8778351355518641,-0.017460019920452208
214.80000000000246,16.830824972503933,0.8804019870970656,-0.017467626343224296
215.90000000000248,16.864559926403356,0.8822736792175332,-0.01874358972099399
217.0000000000025,16.89797190824963,0.8843207356192928,-0.017910701594745504
218.10000000000252,16.931374195420332,0.887240516830559,-0.017779292077650943
219.20000000000255,16.964780219154623,0.8898945855673204,-0.01777981209644075
220.30000000000254,16.998060748119272,0.8927192847849301,-0.017779787370717504
221.40000000000256,17.031750406459462,0.8948683122903067,-0.017774700517772857
222.5000000000026,17.064070582986023,0.8974272697029502,-0.019183834600316363
223.60000000000258,17.098183302396716,0.899451450339255,-0.019099598067039647
224.7000000000026,17.13166393977993,0.9015219438193649,-0.019099701360479227
225.80000000000263,17.164504326765282,0.9036541823474538,-0.019169564779363935
226.90000000000265,17.198185619796472,0.9056048066760634,-0.02041513268802575
228.00000000000267,17.231682291714538,0.9060676806644204,-0.02041986574772725
229.10000000000267,17.26512416367921,0.9081018089693074,-0.020419990004511668
230.2000000000027,17.298381034098536,0.910583054868997,-0.020419994799548924
231.3000000000027,17.331667292328998,0.9120483584430812,-0.020420770769191243
232.4000000000027,17.364825107184117,0.9155609318273026,-0.020312710444242654
233.50000000000273,17.39809446573947,0.9158471508667105,-0.022051379417275196
234.60000000000275,17.43140577072473,0.9176622830259094,-0.0220599745604364
235.70000000000277,17.46456130135291,0.9186852925768882,-0.02205992633111986
236.8000000000028,17.497739464043402,0.9218453380097331,-0.022057477381457247
237.9000000000028,17.53126955597142,0.9226474486647025,-0.02289760098950344
239.0000000000028,17.56456828110958,0.9245086676632094,-0.023383102359209484
240.10000000000284,17.597891689135512,0.926498863738108,-0.02337992803210165
241.20000000000283,17.631134836343556,0.9265373139714232,-0.023379943967182903
242.30000000000285,17.664157072389894,0.9253669210764947,-0.02337991285779717
243.40000000000288,17.69758178150711,0.9266200726127964,-0.02338116748667307
244.5000000000029,17.730790548383727,0.9301403406873785,-0.024771639265443568
245.60000000000292,17.76419891247507,0.9307997220001,-0.025007702663225384
246.70000000000292,17.796881199589055,0.9321696819191111,-0.025372903463695362
247.80000000000294,17.830569722784496,0.9332992236426063,-0.026714738204308475
248.90000000000296,17.86362646659998,0.9343496817994452,-0.026679076704565485
250.00000000000296,17.89701595672376,0.9344069888391775,-0.026680189294829848
251.10000000000298,17.930124057044704,0.9367825452405445,-0.026682603856712284
252.200000000003,17.963441861818392,0.9372430928463235,-0.02768050231928454
253.30000000000302,17.99679923544497,0.9364067178417013,-0.027854930557608792
254.40000000000305,18.030025152775494,0.9390884015210927,-0.026675755878422525
255.50000000000304,18.063056222309935,0.9397550076323149,-0.027887935392177265
256.6000000000031,18.096472510294156,0.9404037544534828,-0.02799034801364675
257.7000000000031,18.129497033807915,0.9399176482236122,-0.02799004797322535
258.8000000000031,18.16255288191466,0.9401866666515353,-0.02800750792831641
259.9000000000031,18.19557612988714,0.9412094099606299,-0.029277384269595697
261.0000000000031,18.22904744425784,0.9428249985249986,-0.029514136919283285
262.10000000000315,18.262111499221547,0.9423028026186646,-0.03062822449991698
263.2000000000032,18.295387297385776,0.9434854076839602,-0.03099200602010166
264.30000000000314,18.32824595897833,0.9433416082003918,-0.03094455102367899
265.40000000000316,18.362133248399285,0.9453558906913648,-0.03064828265911146
266.5000000000032,18.394921249564764,0.9454639732519805,-0.030627969473477457
267.6000000000032,18.428260704612022,0.9469144373494834,-0.030906235449002395
268.70000000000323,18.461337154916844,0.9504380258138374,-0.03278363646220939
269.80000000000325,18.494628882745058,0.9511815944968669,-0.03326477904076652
270.9000000000033,18.52822668404096,0.952068713494939,-0.03378185300665493
272.0000000000033,18.560979846897318,0.9513969330667023,-0.035562234348156974
273.1000000000033,18.59450372176151,0.9524642974276487,-0.03557006794522666
274.20000000000334,18.627652565536778,0.9548797909120146,-0.03557414963137173
275.30000000000337,18.6608380587053,0.9550950803854347,-0.03415718153291536
276.40000000000333,18.6939755852346,0.954894207558552,-0.035608276621116985
277.50000000000335,18.727441002665504,0.9575561568491691,-0.03649775189085647
278.6000000000034,18.760893826533334,0.9600397007499109,-0.03819687492579371
279.7000000000034,18.79413761140862,0.9608483818300677,-0.03824094214759288
280.8000000000034,18.827362474646115,0.9630160193349432,-0.036903343976527836
281.9000000000034,18.860776742547934,0.9640915136906096,-0.03688976274651656
283.0000000000034,18.893562388674844,0.9662831598190221,-0.03688281837633278
284.10000000000343,18.92698167044544,0.9672562280822887,-0.03824387898831416
285.20000000000346,18.96034268273181,0.9689156294761415,-0.03820310409577532
286.3000000000035,18.993258069675036,0.9708365121190867,-0.039190328633573746
287.4000000000035,19.027025998513164,0.972315692273591,-0.03952164346907905
288.5000000000035,19.059725384923432,0.9747587816479246,-0.03951994324326735
289.60000000000355,19.092617490203974,0.9770255654643144,-0.0395212732979231
290.70000000000357,19.126748111745467,0.9791348293441489,-0.03943249391422876
291.8000000000036,19.16009593575849,0.9793925611314604,-0.04083927081807959
292.9000000000036,19.193495795034302,0.9813100602379623,-0.04084016452262196
294.0000000000036,19.226679708317626,0.9804850247329809,-0.040833685006291365
295.1000000000036,19.260041762654044,0.9825707215331665,-0.04189553453265349
296.2000000000036,19.293673467810535,0.9830499610584553,-0.04216075198226621
297.30000000000365,19.326468654250164,0.9849761171655196,-0.042159894015425525
298.4000000000037,19.36021347178024,0.9876517450153658,-0.04215192013648705
299.5000000000037,19.393431469049624,0.989248974157044,-0.04352858583155017
300.60000000000366,19.42697056883839,0.9906803723453915,-0.04365148341920699
301.7000000000037,19.460216683407452,0.99158126879442,-0.044793784375640744
302.8000000000037,19.493338554586,0.9933624135499184,-0.04479140548388072
303.90000000000373,19.52718834745829,0.995240904039379,-0.04595496747918881
305.00000000000375,19.560401597080823,0.9971029016096891,-0.04610905795839537
306.1000000000038,19.593709346674164,0.9988270623345661,-0.04611019425063345
307.2000000000038,19.62699456482019,0.9999621081138306,-0.046110163298790585
308.3000000000038,19.660231162506857,1.0012694143730052,-0.04611040020300505
309.40000000000384,19.693366480210877,1.0039531575036942,-0.046885540911410395
310.5000000000038,19.726805686108236,1.0057722232567214,-0.047443468287546864
311.60000000000383,19.760189423678412,1.009237265964148,-0.04876464619141796
312.70000000000385,19.79372010786344,1.0111322918248877,-0.048736211874886415
313.8000000000039,19.827070398208967,1.0119578416110688,-0.050099278762633315
314.9000000000039,19.86047262179207,1.0155187255981502,-0.05005637331695256
316.0000000000039,19.893944449874358,1.0169474134374465,-0.05063634971933384
317.10000000000394,19.927373172990162,1.0177335480694039,-0.05273686995508875
318.2000000000039,19.960809600313585,1.0184260583447908,-0.052704494660730905
319.30000000000393,19.99405218296771,1.0207074657597355,-0.05374983107122677
320.40000000000396,20.027898541824673,1.02306832813388,-0.054035421418258345
321.500000000004,20.061106694288195,1.024094596817988,-0.0553355880639641
322.600000000004,20.094364050793605,1.0248904695160845,-0.05532095655756297
323.700000000004,20.12770503299184,1.0272311090539363,-0.05654965186154426
324.80000000000405,20.161383598060365,1.0288256074619033,-0.05534020079536761
325.90000000000407,20.19491227511027,1.0322979475483167,-0.05535443815671037
327.0000000000041,20.228122904361634,1.032756525352322,-0.056643757800875605
328.10000000000406,20.261675952281102,1.0338438437698598,-0.05664590442848905
329.2000000000041,20.295003169967366,1.036126738899395,-0.05803391832420024
330.3000000000041,20.32850256765783,1.0388224880041732,-0.057959673429503145
331.4000000000041,20.36206429928597,1.0404678630669246,-0.05795518674441702
332.50000000000415,20.395741304747435,1.0422361066489847,-0.05934807228424788
333.6000000000042,20.42892002038831,1.044300582687209,-0.05927908815043503
334.7000000000042,20.46293954050585,1.0464786464819364,-0.0605719269342746
335.80000000000416,20.496322810291172,1.046775952004435,-0.06102259072717153
336.9000000000042,20.52963432338485,1.0493443594898475,-0.06193875757653311
338.0000000000042,20.563172813043483,1.05292274055404,-0.06357544436144646
339.10000000000423,20.597088798012845,1.0571066835798004,-0.06381262174237845
340.20000000000425,20.630576231281736,1.0605395871327257,-0.06519550285337328
341.3000000000043,20.663208982622134,1.0612518915561884,-0.06657458471328193
342.4000000000043,20.697180828320242,1.065328354834576,-0.06653042289615829
343.5000000000043,20.731174702873766,1.06785411841863,-0.06792879340170943
344.60000000000434,20.765059812596334,1.0709261547306024,-0.06839223150761997
345.7000000000043,20.79833172873775,1.0734993614930697,-0.06953219900369634
346.80000000000433,20.83210397863593,1.0787215657051488,-0.07053899467232272
347.90000000000435,20.865967116677496,1.0828582481200704,-0.07198483812039713
349.0000000000044,20.89944285720216,1.0857689906811085,-0.0734429780102217
350.1000000000044,20.933314018986202,1.0879945002698195,-0.07476762247984636
351.2000000000044,20.966338185624483,1.09218450004772,-0.07593432560339775
352.30000000000445,21.000545687761488,1.094719625938757,-0.0762864739540352
353.4000000000044,21.03441290121186,1.0971087291306856,-0.07741337665662318
354.50000000000443,21.068320160563413,1.0998214049279922,-0.07881350734741721
355.60000000000446,21.101439979483,1.1028360270025814,-0.08057990096019285
356.7000000000045,21.13503913230896,1.107901149289082,-0.0822432497339598
357.8000000000045,21.169104712599623,1.1123331820599223,-0.08387639869732721
358.9000000000045,21.20332626973254,1.1195670997400224,-0.0858020342017638
360.00000000000455,21.23642902591138,1.1210915573682132,-0.0877393932108359
361.10000000000457,21.27124123644213,1.1269841314543223,-0.08965663615258679
362.2000000000046,21.304821599418645,1.133266349685132,-0.09131351131154508
363.30000000000456,21.338677880398325,1.1382045435254908,-0.09360216484612627
364.4000000000046,21.37272632902438,1.1457555626960552,-0.09635214162036077
365.5000000000046,21.406417110106528,1.1516830691306175,-0.09840339088885619
366.6000000000046,21.440432328976197,1.1587805285427601,-0.10026039763966965
367.70000000000465,21.47419823966303,1.1666376794259052,-0.10172888890865339
368.8000000000047,21.508198947028486,1.1773616943412897,-0.10347493505649163
369.9000000000047,21.542653707167826,1.1858936136724625,-0.1055194530466701
371.00000000000466,21.576591383582517,1.1968778248407597,-0.10834039087996494
372.1000000000047,21.610648039090236,1.2056817808267932,-0.11137450430281959
373.2000000000047,21.644568778120167,1.219215889955598,-0.11397626085442303
374.30000000000473,21.678150324676654,1.2310967289396033,-0.11699862963315733
375.40000000000475,21.71286241207941,1.246565851814107,-0.12079504654150552
376.5000000000048,21.746830921157006,1.2594532218170142,-0.1240627335712805
377.6000000000048,21.781160122819713,1.2772118603995442,-0.12817474407694496
378.7000000000048,21.815167645676258,1.2956242844159236,-0.1315863721834214
379.80000000000484,21.849609362544346,1.3128976728950572,-0.13542170984306479
380.9000000000048,21.883964416709976,1.333067099805977,-0.13941713102424114
382.00000000000483,21.91798382866884,1.3582753196770632,-0.14366231994119794
383.10000000000485,21.95256279911026,1.38471279606376,-0.1473993504417912
384.2000000000049,21.98693081771855,1.4130211012211458,-0.15196854774525548
385.3000000000049,22.021208572437825,1.4384224182659082,-0.15707298851580997
386.4000000000049,22.055838981066977,1.470780245413514,-0.16328294443882552
387.50000000000495,22.08998494164832,1.5031831589664841,-0.16881702935869303
388.6000000000049,22.124740872371117,1.5407172979351074,-0.17604713147117135
389.70000000000493,22.15964161836477,1.5812763862708956,-0.18218777744629522
390.80000000000496,22.19414566273644,1.6265801973222085,-0.18868244857472005
391.900000000005,22.229106811293285,1.673738905830156,-0.19573747859730073
393.000000000005,22.263825677652136,1.724638270925105,-0.20389686574989385
394.100000000005,22.298716622173405,1.7830584271460936,-0.21452165273112422
395.20000000000505,22.33371429553692,1.8402055314654413,-0.2242550393413536
396.30000000000507,22.368579746761043,1.9051923330090943,-0.23454065008785419
397.4000000000051,22.403680784599057,1.974782630755404,-0.24533790647264553
398.50000000000506,22.439170000000168,2.052197590056756,-0.2567899370000619
399.6000000000051,22.474381940477713,2.1349271914204624,-0.26866936977204947
400.7000000000051,22.509978913159312,2.2292228403229073,-0.28247129153860406
401.8000000000051,22.545058972026826,2.3237849397228674,-0.2973085549897263
402.90000000000515,22.58080773256354,2.424835354849676,-0.3130983051861356
404.0000000000052,22.61643161245184,2.541122534626341,-0.33168828439783793
405.1000000000052,22.652507409791315,2.669805752861782,-0.35123805431345945
406.20000000000516,22.688664121723342,2.8073505372509637,-0.3709568639366676
407.3000000000052,22.725018084721103,2.9609465149047023,-0.3931368809350815
408.4000000000052,22.761489729708703,3.111813528002641,-0.4167817790587063
409.50000000000523,22.79746259053136,3.27507416166003,-0.4415618826361323
410.60000000000525,22.833874584815284,3.4568663651785774,-0.469092428119279
411.7000000000053,22.871394516518652,3.669640863090653,-0.5004615841366769
412.8000000000053,22.90841802883326,3.880548553018464,-0.5337444892299876
413.9000000000053,22.94595984635752,4.110843579325348,-0.5709263544908105
415.00000000000534,22.98348452390747,4.361177226793829,-0.6100666692921464
416.1000000000053,23.02155701289619,4.655239062824744,-0.6538653996387107
417.20000000000533,23.060031192650598,4.936000500220193,-0.70024287121417
418.30000000000535,23.098044126213857,5.23192859155832,-0.7515968163539042
419.4000000000054,23.136799199697904,5.555737194969325,-0.8077182017742373
420.5000000000054,23.17531076157272,5.862194012209105,-0.8684495557557175
421.6000000000054,23.213915319129626,6.203113013128753,-0.9330789342456889
422.70000000000545,23.252860753927404,6.536279449809244,-1.0025917733442782
423.8000000000054,23.292108616748635,6.8786256048099235,-1.0764203216229
424.90000000000543,23.330768973521938,7.180611171302766,-1.1546668730913687
426.00000000000546,23.370349661059464,7.52931429581611,-1.2397864946392616
427.1000000000055,23.409525304868602,7.890212136218605,-1.3276760325108543
428.2000000000055,23.447725423146473,8.144995203977082,-1.4184272644771263
429.3000000000055,23.486420130869984,8.424408352811842,-1.5070118128571086
430.40000000000555,23.525413603816993,8.751905056429907,-1.6363228369624654
431.50000000000557,23.564347082404417,9.035863674616749,-1.733564752968746
432.6000000000056,23.602465672676725,9.293432077524947,-1.8457509575658961
433.70000000000556,23.639741737808695,9.504523061234487,-1.9567097839841523
434.8000000000056,23.677686302732017,9.691946281974118,-2.07071898726932
435.9000000000056,23.714019161938573,9.804760256096653,-2.1810266049650577
437.0000000000056,23.75030235066431,9.868892458022291,-2.2945145240779063
438.10000000000565,23.785642565600895,9.879760285764045,-2.406717616389548
439.2000000000057,23.82019147197448,9.834967843256434,-2.5166246644451125
440.3000000000057,23.854439138135017,9.746045842076802,-2.622747875400556
441.40000000000566,23.887633090470146,9.579096174711019,-2.7244510304042775
442.5000000000057,23.92027336801465,9.352854262563502,-2.8253564803693214
443.6000000000057,23.952015725956638,9.071102176607235,-2.918047450173135
444.70000000000573,23.983085561643904,8.735290276745861,-3.0098965146035606
445.80000000000575,24.013449839478202,8.33946494910464,-3.0947214318369256
446.9000000000058,24.0433216627337,7.923559936529205,-3.173669073679629
448.0000000000058,24.073076933689382,7.427849547115105,-3.2467942303604063
449.1000000000058,24.102038545404145,6.935370091092339,-3.3151422224999942
450.20000000000584,24.13096080486103,6.409671212013153,-3.368367946846422
451.3000000000058,24.15943180304194,5.874273460314976,-3.4253303699213493
452.40000000000583,24.187792419172425,5.327930311605042,-3.4792368067209325
453.50000000000585,24.216168754965057,4.782701990243737,-3.5233069907484698
454.6000000000059,24.244344791873644,4.253581684770223,-3.563857577988817
455.7000000000059,24.272960597970187,3.7307953708981856,-3.6018184293059328
456.8000000000059,24.301689136967912,3.236603969028102,-3.633601505553571
457.90000000000595,24.330607630985075,2.77061880682839,-3.6620878371566508
459.0000000000059,24.359655844024207,2.3451558572429927,-3.688046708964484
460.10000000000593,24.389415388729656,1.9505941605485364,-3.710945491013514
461.20000000000596,24.41922403799029,1.6058932390885825,-3.729482497799655
462.300000000006,24.449007742577063,1.2990580755419963,-3.745389668406401
463.400000000006,24.48056719775555,1.0225112138496855,-3.760524515697184
464.500000000006,24.511711727450283,0.7870017827842812,-3.7727594854239497
465.60000000000605,24.543202706236,0.580461859957059,-3.781632008115507
466.70000000000607,24.575312853098044,0.4062873178817946,-3.79040207031602
467.8000000000061,24.607510156938446,0.259011700706875,-3.798369626440023
468.90000000000606,24.640153393141173,0.13488411401105754,-3.806319658443984
470.0000000000061,24.673243573902116,0.033892609539120766,-3.810873047765174
471.1000000000061,24.706277879873376,-0.047595540335802156,-3.8142097860248594
472.2000000000061,24.739231841594933,-0.11621814507147926,-3.8185963467414132
473.30000000000615,24.772972598717594,-0.1720677991282601,-3.82149009739905
474.4000000000062,24.80698016024101,-0.2157027739212313,-3.824619778260372
475.5000000000062,24.840383183160494,-0.25063677026385356,-3.827511235531606
476.60000000000616,24.874718737653115,-0.2801860630890871,-3.829445969472973
477.7000000000062,24.90882294041036,-0.30110566938921207,-3.831847438075208
478.8000000000062,24.942954178848858,-0.32413334578907077,-3.8337980774303566
479.90000000000623,24.977265595548392,-0.33735362166513955,-3.8356568331457215
481.00000000000625,25.01181791049978,-0.3486904806530082,-3.8364151549415353
482.1000000000063,25.04602041191413,-0.3611258251298518,-3.837062274311113
483.2000000000063,25.08043140142763,-0.37430613141047814,-3.8385541524886104
484.3000000000063,25.11508102770527,-0.3840847383429209,-3.8385769093453255
485.40000000000634,25.149557134365846,-0.39709127278331796,-3.8400237736738
486.5000000000063,25.184033988076912,-0.4084468674807983,-3.839955951745508
487.60000000000633,25.21901378119044,-0.42121405321100086,-3.8417549317922695
488.70000000000636,25.25271979455277,-0.4299442764107331,-3.842640090790832
489.8000000000064,25.287648808258147,-0.44171099138139086,-3.8426401594014106
490.9000000000064,25.32304641652811,-0.4469307800612114,-3.84263823970868
492.0000000000064,25.357965388729006,-0.45358266085740784,-3.8433275048412807
493.10000000000645,25.39206403438852,-0.45973578191693215,-3.843285901494729
494.2000000000064,25.427466277576286,-0.45990703930027943,-3.8446417204737267
495.30000000000643,25.46229219580736,-0.4638178571343965,-3.8446102923196497
496.40000000000646,25.497215459816168,-0.46313255844045587,-3.8446098003831453
497.5000000000065,25.532231542311244,-0.45826963264700094,-3.844609817504466
498.6000000000065,25.56742507273667,-0.4476587988965919,-3.84460897040103
499.7000000000065,25.601643840308125,-0.4384466602070184,-3.8444913388697866
500.80000000000655,25.637473567148085,-0.4337009778479192,-3.8432948853518223
501.90000000000657,25.672457098585326,-0.42746097219664886,-3.84329016268652
503.0000000000066,25.70773210051056,-0.42522281036608683,-3.843291275426493
504.10000000000656,25.74268688638906,-0.4203014165939436,-3.843588558629226
505.2000000000066,25.77771456830213,-0.4188453619102048,-3.8446097269768744
506.3000000000066,25.81295078540753,-0.41865708557150183,-3.8438935206121094
507.4000000000066,25.848063693448825,-0.4231989628674517,-3.8432867850969696
508.50000000000665,25.88342081049322,-0.4267053955232466,-3.8442912219145
509.6000000000067,25.918721359748105,-0.4352308653159794,-3.8446100856616483
510.7000000000067,25.953753012922995,-0.4385685131904632,-3.84461047963751
511.80000000000666,25.989105279994824,-0.44408971319674806,-3.844633030137549
512.9000000000067,26.024661755963027,-0.44743823700161295,-3.844941471819936
514.0000000000067,26.059892411572363,-0.45198545470491935,-3.844939813720674
515.1000000000067,26.094951008416324,-0.4543565835389161,-3.8449398038580176
516.2000000000068,26.13058507457243,-0.4614397826745879,-3.8449398039950182
517.3000000000068,26.165845724051497,-0.46646343671637214,-3.844939804743385
518.4000000000068,26.201314428779874,-0.46983844499007593,-3.8449398690368977
519.5000000000068,26.236775146874425,-0.47320933083921807,-3.844932743830836
520.6000000000068,26.272296379520018,-0.4813052179173281,-3.8460440723996827
521.7000000000069,26.30767374609918,-0.4835047346460308,-3.8446138369812224
522.8000000000068,26.34347124239405,-0.4890719396475841,-3.8446123021052188
523.9000000000069,26.37857311790285,-0.49355044218116984,-3.8459240654578224
525.0000000000068,26.414164410269688,-0.4971183986263089,-3.8459305862302555
526.100000000007,26.44976848060584,-0.5004209645495729,-3.8459301547547176
527.2000000000069,26.485220823069067,-0.5038345383517876,-3.8459328682744074
528.300000000007,26.520904632612133,-0.5125432088887184,-3.8455694255894812
529.4000000000069,26.556597921350374,-0.51420680483762,-3.8456004144802574
530.5000000000069,26.591864908300835,-0.5173765172103064,-3.8456001673733495
531.600000000007,26.627566753353133,-0.5213837422495634,-3.845600163986895
532.700000000007,26.6632581664711,-0.5262152182730515,-3.845600163999659
533.800000000007,26.698744201576893,-0.5310881408174669,-3.845600164
534.900000000007,26.73436857112366,-0.5377152056671245,-3.8456001640000004
536.000000000007,26.770169484007372,-0.5425148504383517,-3.8456001640000004
537.1000000000071,26.805442486286655,-0.5456410411645641,-3.845600164
538.2000000000071,26.84117313104833,-0.5509860902918778,-3.8456001640000004
539.300000000007,26.876952930095854,-0.5554267775565037,-3.845600164
540.4000000000071,26.912870291992572,-0.5574747175645501,-3.8456001639999813
541.500000000007,26.948087539789316,-0.5601421427617088,-3.8456001640006634
542.6000000000072,26.9833861591295,-0.5610362889446361,-3.845600164226604
543.7000000000071,27.01953260740202,-0.5643429140636311,-3.8456001668650215
544.8000000000072,27.055545142953807,-0.5668393218673391,-3.8455977501340777
545.9000000000071,27.09129351392328,-0.5670455719541273,-3.84596057183222
547.0000000000072,27.12689367805134,-0.5675754767356849,-3.84592961968916
548.1000000000072,27.162612726684127,-0.5704109363961507,-3.8459298878770922
549.2000000000072,27.198512298774506,-0.5736002511969494,-3.845929883400154
550.3000000000072,27.23413057417722,-0.5744634224533551,-3.8459258131531557
551.4000000000073,27.269879418356528,-0.5750523375796971,-3.8466330998047153
552.5000000000073,27.305576953897607,-0.5768672237241439,-3.846918270295432
553.6000000000073,27.34163556565675,-0.5733524551909154,-3.8472709612708496
554.7000000000073,27.37757678542603,-0.5726649655690215,-3.8472392774067496
555.8000000000073,27.413059261690776,-0.572847145961892,-3.847054625705523
556.9000000000074,27.448974178764093,-0.5721868561892043,-3.845930335759872
558.0000000000074,27.48500360809878,-0.5696360926895467,-3.845929952050257
559.1000000000074,27.520704853268203,-0.5678372493170265,-3.8459298914432885
560.2000000000073,27.556148308812745,-0.5658770798041013,-3.845929857009047
561.3000000000073,27.592272089426,-0.5660058309142336,-3.8459259476310703
562.4000000000074,27.627984671605503,-0.5647608738984407,-3.8468191992913465
563.5000000000074,27.66450728685749,-0.5682010236153229,-3.8472408823625246
564.6000000000074,27.700312636144137,-0.568421741169522,-3.8472401551629853
565.7000000000074,27.73603962895255,-0.5684421060681824,-3.8472401529503286
566.8000000000075,27.771461658951974,-0.5684418578663845,-3.847240152999681
567.9000000000075,27.808160373904222,-0.5692826604973409,-3.8472401530000018
569.0000000000075,27.843368811106313,-0.5688977637968222,-3.8472401530000058
570.1000000000075,27.87961003829796,-0.5696726868763471,-3.847240152998779
571.2000000000075,27.91584368921779,-0.5692658179849781,-3.8472401528447113
572.3000000000076,27.951850784619964,-0.5693255680064127,-3.8472401608898994
573.4000000000076,27.987829825979382,-0.5700004067510317,-3.8472426221150378
574.5000000000076,28.02392060994017,-0.5670675128455388,-3.8469077157535425
575.6000000000076,28.059679818276344,-0.5691646912448588,-3.846243130659176
576.7000000000077,28.095769607181616,-0.5711295820986302,-3.8462605129095864
577.8000000000077,28.131832051447187,-0.5712513701922624,-3.8462271732863
578.9000000000076,28.16773072107642,-0.5717018083570581,-3.8475571313368193
580.0000000000076,28.203717282923588,-0.5722825402494844,-3.8478071280058397
581.1000000000076,28.239899038814464,-0.5716569669658305,-3.848891277554542
582.2000000000077,28.275734696014574,-0.5711365754004766,-3.8488925856685086
583.3000000000077,28.312110164391317,-0.5704104673516949,-3.8475351755594787
584.4000000000077,28.348036338607052,-0.5714134218683244,-3.8475793491830017
585.5000000000077,28.38399198985002,-0.5722784487695962,-3.847579840522217
586.6000000000078,28.41994867025092,-0.5709637348733316,-3.8475867058441557
587.7000000000078,28.456057576767286,-0.5703407430972872,-3.846462759386006
588.8000000000078,28.492363960687157,-0.5690496199351702,-3.846259596163712
589.9000000000078,28.528541480644606,-0.569393872308984,-3.8462542160298883
591.0000000000078,28.564455377127523,-0.5687024914508942,-3.8472551949576674
592.1000000000079,28.600776189658642,-0.5697132178280763,-3.847580321064803
593.2000000000079,28.63688213724618,-0.5685859226707705,-3.847579849772568
594.3000000000079,28.673031459534837,-0.5712765873007953,-3.8475798312911773
595.4000000000078,28.70910593579647,-0.5691476017334736,-3.8475798856985737
596.5000000000078,28.745092890251954,-0.5698625477230199,-3.8479106175486035
597.6000000000079,28.781333980764817,-0.5718854377204883,-3.848903060595118
598.7000000000079,28.817614858086035,-0.5727643602983347,-3.8488999128405386
599.8000000000079,28.85363779473352,-0.573866631992298,-3.848899935835599
600.9000000000079,28.88972872983906,-0.5738205868143098,-3.8489003660376646
602.000000000008,28.926208691005836,-0.5739801095584421,-3.848913178433694
603.100000000008,28.96204277479773,-0.5738759092142754,-3.8479308949464337
604.200000000008,28.998471111165873,-0.5728117035002922,-3.847910740498229
605.300000000008,29.034764890446823,-0.5726732189341514,-3.849313951212513
606.400000000008,29.070864104933644,-0.574674065955493,-3.8492303922507487
607.5000000000081,29.10682811335443,-0.5729831191321834,-3.8492300058466817
608.6000000000081,29.143218260602314,-0.5740316677505228,-3.8492322952244535
609.7000000000081,29.179301685061507,-0.574947817717411,-3.8488667942932353
610.8000000000081,29.21554426025079,-0.5728192209484549,-3.848899078988118
611.9000000000082,29.251744100824766,-0.5739477770998331,-3.8503066341129233
613.0000000000082,29.28779576772952,-0.5734386263062934,-3.8503299021400306
614.1000000000081,29.32405400369871,-0.5722349365157713,-3.8503300221110894
615.2000000000081,29.360495892078653,-0.5748642054667438,-3.8503300210146105
616.3000000000081,29.39663932157505,-0.5729885904803109,-3.8503300210000218
617.4000000000082,29.43284986949174,-0.5733592808158965,-3.850330021000006
618.5000000000082,29.469235954312676,-0.5728616701906958,-3.8503300210000204
619.6000000000082,29.505408154911272,-0.5738834502289551,-3.8503300209055924
620.7000000000082,29.54164624815708,-0.5740723352257199,-3.8503300115130514
621.8000000000083,29.577844302759296,-0.5744903285686328,-3.850330647336834
622.9000000000083,29.61430384615427,-0.5729773690252902,-3.85060330333522
624.0000000000083,29.6505509065761,-0.5756091263893484,-3.8516406418600773
625.1000000000083,29.6865611047546,-0.5757450093137799,-3.8516158151305997
626.2000000000083,29.722769035655332,-0.5762707171313017,-3.850321226335151
627.3000000000084,29.759331678127275,-0.5738655579049055,-3.850319904676724
628.4000000000084,29.795443739616882,-0.5762424306913656,-3.850312509547856
629.5000000000084,29.831924159707633,-0.5776774190447098,-3.851493919758725
630.6000000000083,29.868271412098053,-0.5788600211767572,-3.851639547900394
631.7000000000083,29.904385730838868,-0.5794481009736958,-3.850066801062935
632.8000000000084,29.9408406758351,-0.5831948274538798,-3.8500980078747213
633.9000000000084,29.97689937402972,-0.5865937761054631,-3.8516284688742997
635.0000000000084,30.013391886132972,-0.5869893615912263,-3.8519611313248685
636.1000000000084,30.04989942433211,-0.5887982753340559,-3.851982359675385
637.2000000000085,30.08614016188328,-0.5922081490537494,-3.8526270486155845
638.3000000000085,30.122230894451395,-0.5948429051241816,-3.852564543886051
639.4000000000085,30.15840516058636,-0.5943600534227231,-3.853616305074924
640.5000000000085,30.19475361971068,-0.5967605362226394,-3.85361995146481
641.6000000000085,30.231260166129104,-0.600972970592741,-3.853624857120462
642.7000000000086,30.267219616906903,-0.6004441164356854,-3.852911085286676
643.8000000000086,30.304062681484957,-0.6050400627440465,-3.852957163011927
644.9000000000086,30.34019565056691,-0.6064116534047442,-3.8537056889526227
646.0000000000086,30.376980417361466,-0.6095613274208216,-3.8542817322066276
647.1000000000087,30.41337057866165,-0.6129413593479421,-3.854280170144893
648.2000000000087,30.44963621202971,-0.6151311287381779,-3.8542801511233655
649.3000000000086,30.486101237193427,-0.6164206506525718,-3.854280152405588
650.4000000000086,30.522555758148677,-0.6181571167307582,-3.8542788626230773
651.5000000000086,30.55900757363734,-0.6219517412627271,-3.8540925133971453
652.6000000000087,30.595284180289127,-0.6216393017307342,-3.8536196946534123
653.7000000000087,30.631889126648026,-0.622145992331214,-3.8536201315720024
654.8000000000087,30.668239342747444,-0.6274624316747817,-3.85362015088118
655.9000000000087,30.704796613622417,-0.6275144822007959,-3.8536201513697446
657.0000000000088,30.74113485343217,-0.6327305595064512,-3.8536201776562296
658.1000000000088,30.77794994526647,-0.629227037656919,-3.85361796734803
659.2000000000088,30.81411438105094,-0.6309294265723904,-3.85467170669897
660.3000000000088,30.85075525446076,-0.6347279434075026,-3.8549153399390663
661.4000000000088,30.88738758072273,-0.6387904415109169,-3.8539363930909265
662.5000000000089,30.923952438435055,-0.6403770044821329,-3.8539401723908195
663.6000000000089,30.96012318810898,-0.6473136366557635,-3.853940021570569
664.7000000000089,30.997234732800145,-0.6493228561128767,-3.8539400200026086
665.8000000000088,31.033603036125644,-0.6492661897625853,-3.853940019597281
666.9000000000088,31.07013287878095,-0.6518552705868845,-3.8539399784783486
668.0000000000089,31.10658065061376,-0.6554126925896302,-3.853941290636359
669.1000000000089,31.14304312086288,-0.6589611016138329,-3.853933294381775
670.2000000000089,31.180008671152958,-0.6615798439154438,-3.8549300490005787
671.3000000000089,31.216805514944298,-0.6604312449937285,-3.8549309496195963
672.400000000009,31.25328894329121,-0.6630409541082267,-3.8538762079232938
673.500000000009,31.28985074587757,-0.6666291304315417,-3.85399369873106
674.600000000009,31.326751236121694,-0.6673487795427053,-3.8552695469589735
675.700000000009,31.363137636675333,-0.668146752731032,-3.855270187012175
676.800000000009,31.39967017440017,-0.6686126694558037,-3.85527019619283
677.9000000000091,31.43647080617616,-0.6676832542984957,-3.855268953749053
679.0000000000091,31.473067132309534,-0.6725923384476646,-3.8550263348826763
680.1000000000091,31.509737288873552,-0.675779988744387,-3.8546101105757264
681.2000000000091,31.54630266708893,-0.6740011420469121,-3.8546226591048853
682.3000000000092,31.583329409429652,-0.6776414145389762,-3.8555670925696255
683.4000000000092,31.619907347184608,-0.6785985684112592,-3.8555915365353624
684.5000000000091,31.65632590428761,-0.6794010542011151,-3.8551704991531963
685.6000000000091,31.693347401330374,-0.6810239624096668,-3.855604284554327
686.7000000000091,31.72998692611283,-0.6871571411100724,-3.8556000396179626
687.8000000000092,31.76666068889391,-0.6874247537366557,-3.8556000595712714
688.9000000000092,31.80359564419598,-0.687852295861397,-3.8556066227481662
690.0000000000092,31.84018247513123,-0.6872722828466387,-3.8544645165266345
691.1000000000092,31.877427942818656,-0.6893209934086129,-3.854279945931544
692.2000000000093,31.913717040962556,-0.6898447676209212,-3.8542801154043205
693.3000000000093,31.950555419946074,-0.6923728734742836,-3.8542853446161938
694.0000000000093,31.97387719675371,-0.6906567004977422,-3.855690578095989