File: 01_Data/EIFS_XPS/STA/N2/30K_min/EIFS_XPS_STA_N2_30KData_230901_R2.csv
##Temp./Â°C,Time/min,DSC/(mW/mg),Mass loss/mg
41.0,10.562621881402361,0.006934463203529084,-0.004336623945533802
42.100000000000016,10.74938363344144,0.04288886041616635,0.0006771444640150115
43.20000000000003,10.873114707349963,0.06990141000483341,-0.0023784875105392622
44.30000000000005,10.970828010323597,0.09770968363097898,-0.0011590489390571612
45.40000000000006,11.055582335583146,0.12020429756780215,-0.0006285210654084494
46.50000000000008,11.129270986930253,0.14304264937215927,-0.0019909226633911814
47.600000000000094,11.196760753915443,0.163816654702722,-0.0030156813697810314
48.70000000000011,11.25868636931819,0.1824142866544658,-0.0013710998493703386
49.800000000000125,11.318783931430016,0.19757844581105743,-0.0033782422612431695
50.90000000000014,11.375628825049514,0.21312944402791167,-0.0014271224396695814
52.000000000000156,11.429758608630747,0.2291000098964049,-0.0019236654164118683
53.10000000000017,11.481016066250193,0.24033697918323882,-0.0020758669866549617
54.20000000000019,11.531580290858894,0.2544944588308935,-0.0061219178373033145
55.3000000000002,11.58098251775144,0.26614539665656434,-0.007980594637400085
56.40000000000022,11.628456734256684,0.2772076830172321,-0.005012437383975055
57.500000000000234,11.675020954458244,0.2836286119438083,-0.004073581498678536
58.60000000000025,11.720254959538297,0.2955481937663196,-0.0055139889471558234
59.700000000000266,11.765325687133101,0.3021326960637498,-0.0037850289024574657
60.80000000000028,11.809452478101347,0.30959021530952935,-0.002240772735296215
61.9000000000003,11.853007694757533,0.3174824772757274,-0.001622368812192132
63.00000000000031,11.895384219893778,0.32353757822520923,-0.0026310182722646402
64.10000000000034,11.93790520320221,0.3301174800043518,-0.0026187131148196485
65.20000000000034,11.979503019867538,0.3351679441753368,-0.0035942738645027283
66.30000000000035,12.021277270245541,0.34292310321195507,-0.0029301950072344596
67.40000000000038,12.06212795735773,0.3452151455931356,-0.003941545593906248
68.5000000000004,12.103099855873928,0.3491423262694837,-0.006368138480109753
69.6000000000004,12.142716770955907,0.35354662936007597,-0.005412684314114458
70.70000000000041,12.183319698420759,0.3609288836948885,-0.005316388909669456
71.80000000000044,12.222745751514026,0.36358784102623654,-0.0039207972029946525
72.90000000000046,12.262457427902964,0.36639806703089395,-0.004095752205060421
74.00000000000047,12.30187473953459,0.3717938185288281,-0.005412886908507275
75.10000000000048,12.341916300858841,0.37541456339325574,-0.0048039861497746195
76.2000000000005,12.380470493693911,0.37927912337431047,-0.0035162664044952052
77.30000000000052,12.419615201746296,0.38346748555813104,-0.0020025949057389525
78.40000000000053,12.457796281188687,0.3890058290044196,-0.0017612886119864335
79.50000000000054,12.496980238692087,0.3964980305177601,-0.003170407886305515
80.60000000000056,12.535753880327828,0.39985419534925093,-0.005186979506389466
81.70000000000059,12.57438576816186,0.40938504348629356,-0.005847467359052949
82.8000000000006,12.612698345862363,0.41856218952849944,-0.006087066678088782
83.9000000000006,12.650954589880941,0.4241035175780592,-0.004703131725295684
85.00000000000063,12.688428374557999,0.42992124507809026,-0.004290855669462967
86.10000000000065,12.726111921658973,0.428926769517721,-0.00425811114524155
87.20000000000066,12.763845622277396,0.4244820875451125,-0.005541939148360875
88.30000000000067,12.801368604696819,0.41629188306757525,-0.0041883736996570775
89.40000000000069,12.839063096045026,0.4021822429400741,-0.005609960165313677
90.50000000000071,12.875673278813176,0.39116595890680683,-0.0042881412888893244
91.60000000000072,12.912937078758727,0.38511951999009875,-0.004130980060773393
92.70000000000073,12.950065159751603,0.3798789845007977,-0.003106322130687289
93.80000000000075,12.98705036229442,0.3797769599819274,-0.004393687707880289
94.90000000000077,13.024160103712418,0.3763447352876492,-0.004865439695480145
96.00000000000078,13.060912233733816,0.37839467035319574,-0.00560617178375189
97.10000000000079,13.097265904352865,0.37983649511336814,-0.007019367100929319
98.20000000000081,13.134690344214667,0.3827643900577422,-0.007020557179611586
99.30000000000084,13.171665233748264,0.3907252998604822,-0.007762481309605551
100.40000000000084,13.208627978315508,0.39484960793670454,-0.0060098489881372785
101.50000000000085,13.245285027128919,0.4000378153460853,-0.006121487653762081
102.60000000000088,13.282655818579736,0.40975464866162903,-0.00472056101515772
103.7000000000009,13.318950969322621,0.4206538477846117,-0.0031491323436303453
104.8000000000009,13.355959417277345,0.43523056930167137,-0.0045095091485438665
105.90000000000092,13.39273699833166,0.4508495443099151,-0.004490242739592087
107.00000000000094,13.430068522943964,0.47233767187117415,-0.004489966731493045
108.10000000000096,13.466368936171968,0.4921854726981397,-0.004399017848780051
109.20000000000097,13.503643010905627,0.5155269094614163,-0.0031178169057786143
110.30000000000098,13.54019668012077,0.5337401719846746,-0.003056484040790952
111.400000000001,13.57730075583522,0.5563998421760004,-0.0033400147408850778
112.50000000000102,13.613619752187915,0.5692154530356437,-0.0030724593867517136
113.60000000000103,13.650224434791156,0.577629039106415,-0.003070156709965133
114.70000000000104,13.68685113246955,0.5851871760527348,-0.0030701598596061253
115.80000000000106,13.722932128302974,0.5846346772897175,-0.003070619669709451
116.90000000000109,13.759522497167374,0.5865670036072547,-0.003049280080465344
118.0000000000011,13.796090560977252,0.5961798678993314,-0.0043780044734984536
119.1000000000011,13.831756080492582,0.6063931842470422,-0.0043871610212424805
120.20000000000113,13.867964389098297,0.6160103884207865,-0.005763093692328525
121.30000000000115,13.904544460877531,0.625883731279359,-0.007252770286278132
122.40000000000116,13.940979899540752,0.6362218681964609,-0.007240471031065621
123.50000000000117,13.9771430870494,0.6461483511899164,-0.008328088739607331
124.60000000000119,14.013370907179784,0.6512092355562611,-0.008488739815335933
125.70000000000121,14.049627978191076,0.6566259959148687,-0.010316525395392961
126.80000000000122,14.085009774995068,0.6554085057489594,-0.012574321212169615
127.90000000000123,14.12033335800618,0.6499148445437399,-0.013940395333377431
129.00000000000125,14.156267935148046,0.6463865132700917,-0.013929132764235685
130.10000000000127,14.191633053015217,0.638303913933538,-0.013930137384158936
131.2000000000013,14.226888278150987,0.6285728549243114,-0.013901743505001285
132.3000000000013,14.262571281404753,0.6183774992997546,-0.012593890899637472
133.4000000000013,14.297683172609895,0.6060968661379609,-0.013947988901086283
134.50000000000134,14.33259647188834,0.597588905025807,-0.013628761909450393
135.60000000000133,14.367764301639113,0.5861984787454083,-0.01349244226605295
136.70000000000135,14.402984188707396,0.5725627607743732,-0.011494303386483828
137.80000000000138,14.437975465068622,0.5636641605651658,-0.011078321534733426
138.9000000000014,14.473040801041757,0.5543669365836011,-0.0110752504996956
140.00000000000142,14.50792494066434,0.5457357471802926,-0.012432395585319167
141.10000000000142,14.543142165924632,0.5423093722734045,-0.013592859191650764
142.20000000000144,14.577761914123657,0.5372573587563891,-0.013643791896281066
143.30000000000146,14.61295053577368,0.536257390678324,-0.015038228736157233
144.40000000000146,14.647762148099064,0.5340885081909981,-0.015009219298822263
145.50000000000148,14.682340084716724,0.5330978812335299,-0.01600553948148642
146.6000000000015,14.717003116064651,0.5322532546789108,-0.016692956099531475
147.70000000000152,14.751690858465835,0.5332134292953787,-0.016690006822932535
148.80000000000155,14.786844342324208,0.5338915687527417,-0.01668996967492964
149.90000000000154,14.821682806012578,0.5341906288266494,-0.01668997000652883
151.00000000000156,14.856110227486361,0.5349562703307219,-0.016689968460929627
152.1000000000016,14.890570193212033,0.5366742153430585,-0.016689939169556745
153.20000000000158,14.925421647769754,0.5361535221235487,-0.016706274275009037
154.3000000000016,14.959379831856534,0.5373879724206819,-0.017664524225233347
155.40000000000163,14.994246852202153,0.5383005464403512,-0.01935283050804637
156.50000000000165,15.028950538268187,0.5417650621910939,-0.020738566218548637
157.60000000000167,15.062920163091153,0.542200312932912,-0.0208101894450472
158.70000000000167,15.097681363108606,0.5438300678270649,-0.019428646539592087
159.8000000000017,15.132277872270143,0.545425417775627,-0.020836708745086252
160.9000000000017,15.166562941650477,0.545015480335455,-0.01971494195596568
162.0000000000017,15.200771229652693,0.5489011008417827,-0.01869834618982047
163.10000000000173,15.235290125893796,0.5495981132368299,-0.017612313014016667
164.20000000000175,15.269571319921873,0.5518070599546077,-0.01679024601408985
165.30000000000177,15.303966150849357,0.552964326203404,-0.01683205246374264
166.4000000000018,15.33831750679538,0.5521270425979056,-0.018069356023164396
167.5000000000018,15.371833258895498,0.5556660281519495,-0.019429222771373933
168.6000000000018,15.406700621665294,0.5571482231527746,-0.019335732642567383
169.70000000000184,15.441123003172793,0.5573106468253431,-0.020847070453869243
170.80000000000183,15.475120488693662,0.559944631967891,-0.020836909613533905
171.90000000000185,15.509524494293345,0.5623063689624801,-0.0195000085717556
173.00000000000188,15.543698315646225,0.5645639748350725,-0.019530802350121945
174.1000000000019,15.576838406885882,0.567772506897487,-0.019529801712899086
175.20000000000192,15.611780012180228,0.5673737124781938,-0.01952978550580209
176.30000000000192,15.645697456783447,0.5715740243602909,-0.01953285069684707
177.40000000000194,15.67939673598338,0.5728916338971697,-0.018926436586316875
178.50000000000196,15.71364822884341,0.573091823540092,-0.018367726150603225
179.60000000000196,15.747633865541593,0.5746497275504857,-0.017777396297341763
180.70000000000198,15.78122383021845,0.5769221475379832,-0.017784794872401477
181.800000000002,15.815408936837565,0.5752066214314149,-0.017053497267735196
182.90000000000202,15.849564919993671,0.5775402275010176,-0.01645962614741192
184.00000000000205,15.883738355511374,0.5774723042896893,-0.016452005095569433
185.10000000000204,15.917533527816259,0.5774933263149015,-0.017805064469927245
186.20000000000206,15.950945257516127,0.5769925486602229,-0.017781640793289366
187.3000000000021,15.983717905810941,0.5786612826792542,-0.017436946873513826
188.40000000000208,16.01843350731185,0.5789744458217487,-0.016460708196311735
189.5000000000021,16.052356683008576,0.5791747656944065,-0.01646049366848512
190.60000000000213,16.08595909419397,0.5812017377406362,-0.017560807224031194
191.70000000000215,16.119363948041034,0.5811424415452773,-0.01928222850185657
192.80000000000217,16.153071412763296,0.5814808750194012,-0.019318291068826987
193.90000000000217,16.186909847138537,0.5822178051545943,-0.01931999520323835
195.0000000000022,16.22054954951017,0.5797611559410609,-0.0193200565988505
196.1000000000022,16.25391431578015,0.5820064063367536,-0.019283184124719632
197.2000000000022,16.28783066592509,0.5836880596115808,-0.020644177434874678
198.30000000000223,16.32117855353332,0.5831949161691287,-0.01905211159723752
199.40000000000225,16.35499824524579,0.5842273989594708,-0.017848447328170813
200.50000000000227,16.388122606869082,0.5852854494230828,-0.017779632170773496
201.6000000000023,16.421785455331328,0.5873358524112187,-0.017777471757375096
202.7000000000023,16.4555191932322,0.5847030550315546,-0.018290779917927935
203.8000000000023,16.488961688529564,0.58530691450163,-0.01909972559234152
204.90000000000234,16.52245281605523,0.5876266176340581,-0.019113282280248
206.00000000000233,16.55605928438794,0.5883046801927243,-0.02037190159067226
207.10000000000235,16.589969105926016,0.5877409394393707,-0.020410172384878855
208.20000000000238,16.623107405516517,0.5898479183825559,-0.02041139689463467
209.3000000000024,16.656391560347778,0.5906434403881415,-0.020309184109621903
210.40000000000242,16.690180104639573,0.5925647293015097,-0.02172965602553134
211.50000000000242,16.723553875320277,0.5951337840976917,-0.021732522976485313
212.60000000000244,16.757243620174908,0.5989085973550677,-0.021297120578188
213.70000000000246,16.790624406369528,0.5995242761470886,-0.020409029236878595
214.80000000000246,16.824110201178037,0.6010436647490045,-0.020410239337547154
215.90000000000248,16.85753459387774,0.6024254381938111,-0.020410138405022593
217.0000000000025,16.891127580141116,0.6049730820928767,-0.02040871093043517
218.10000000000252,16.924366774575553,0.6081266490761899,-0.020796315308717617
219.20000000000255,16.958094230943367,0.6077747864212975,-0.021729091927278343
220.30000000000254,16.990642662408636,0.6122743592088085,-0.021729861661686556
221.40000000000256,17.025126754679476,0.6127058774579892,-0.021729866360508332
222.5000000000026,17.058469391904982,0.6164583967992716,-0.021729799824342422
223.60000000000258,17.091514881757863,0.6182148223608367,-0.021728358130336023
224.7000000000026,17.125087536759512,0.618805880642712,-0.020380085929794678
225.80000000000263,17.158331981161997,0.6201405866918668,-0.019418329387391964
226.90000000000265,17.19181314086913,0.6231735714029867,-0.019420017190515004
228.00000000000267,17.225148257220937,0.6254895368323637,-0.01942250989526695
229.10000000000267,17.25838516451634,0.6270086682746095,-0.020783147764376952
230.2000000000027,17.291591833743635,0.6283631649459271,-0.020738235307261377
231.3000000000027,17.325227171222135,0.6283934402452664,-0.02074011571503309
232.4000000000027,17.358601577997444,0.6286525788397271,-0.020736673689290885
233.50000000000273,17.391744421516353,0.6310142854947903,-0.022150425367707616
234.60000000000275,17.425217486353038,0.6323043391729903,-0.022116665001517433
235.70000000000277,17.45855751383941,0.6341413178423949,-0.02350438522875109
236.8000000000028,17.491166610306347,0.6356503377539545,-0.02349014988730147
237.9000000000028,17.52535704251025,0.6366454832349995,-0.023486760400344586
239.0000000000028,17.55852243140024,0.6354687518995484,-0.024013001717317017
240.10000000000284,17.591866038970366,0.6360949837573758,-0.026399251637985177
241.20000000000283,17.625214169332263,0.6398151493784141,-0.028990051803488015
242.30000000000285,17.658318495750915,0.6379790662354294,-0.030309272253687958
243.40000000000288,17.69172252143784,0.6417970492192702,-0.028672982709023742
244.5000000000029,17.725254396280203,0.6405652959271064,-0.02733838491310525
245.60000000000292,17.758705298850053,0.6424869234043467,-0.029575809205619752
246.70000000000292,17.791516158478377,0.6435702252485767,-0.030424954099127266
247.80000000000294,17.824731501871636,0.6458249740766207,-0.030963984987772974
248.90000000000296,17.858185838252652,0.6442360405584114,-0.030960108723995017
250.00000000000296,17.891228426895115,0.6454263201195533,-0.03096013424489774
251.10000000000298,17.92452988303706,0.6469243753664496,-0.030960249316279054
252.200000000003,17.95806475055478,0.648019678706896,-0.03095535874890487
253.30000000000302,17.990910876403472,0.648743275413309,-0.032017490249866665
254.40000000000305,18.02458773735505,0.6478157681124153,-0.03261583155320791
255.50000000000304,18.056840940583136,0.6477648902318078,-0.033690705222248596
256.6000000000031,18.090030900520528,0.6484043284094317,-0.033702150451278445
257.7000000000031,18.123838771100885,0.6487426555416046,-0.03369585923559226
258.8000000000031,18.157456071103358,0.6502191911250961,-0.03437272221374066
259.9000000000031,18.190833822225045,0.6488941060141453,-0.03523186348575358
261.0000000000031,18.22350153181106,0.6504744416785506,-0.03523009072625527
262.10000000000315,18.256904995545938,0.650705203966475,-0.03523144826259639
263.2000000000032,18.29029487538625,0.6526039448488001,-0.0367206966442164
264.30000000000314,18.322627501074503,0.6528879397926703,-0.03803450865678215
265.40000000000316,18.356595345532636,0.6506852236809264,-0.039412549402551456
266.5000000000032,18.389939613056896,0.6528601701110224,-0.03940997374924482
267.6000000000032,18.423187394632926,0.6534531736316249,-0.03941002344547462
268.70000000000323,18.456447701947408,0.6531149109910344,-0.039318005830092595
269.80000000000325,18.489758006699866,0.6544732521712986,-0.037870948085642286
270.9000000000033,18.522942437410645,0.6540918338174215,-0.03645587271515094
272.0000000000033,18.556218589155627,0.654256690508741,-0.036557698883971756
273.1000000000033,18.589253740458606,0.6558199678310667,-0.03524453315054643
274.20000000000334,18.62255529267638,0.6556839289575365,-0.03524095017732787
275.30000000000337,18.655525760086846,0.6564627192011252,-0.036413918784180765
276.40000000000333,18.68900753788292,0.6576328697373034,-0.03680327866203381
277.50000000000335,18.722334940992628,0.6582303998139574,-0.037849813209146266
278.6000000000034,18.75545522471144,0.6567715390537213,-0.03923448001922347
279.7000000000034,18.78878836969905,0.658187989903638,-0.04042771564141123
280.8000000000034,18.82199472175197,0.6597633634654148,-0.04066450189709592
281.9000000000034,18.855019491510514,0.6605367859873826,-0.04204412014749481
283.0000000000034,18.88873584536838,0.6606372928165077,-0.04099265854281775
284.10000000000343,18.92184426739569,0.6605085744064789,-0.038654009629804253
285.20000000000346,18.95512398966066,0.6629503092286826,-0.03875222228678776
286.3000000000035,18.98839502642101,0.6645710706107566,-0.03875013647690384
287.4000000000035,19.02153195131122,0.6644499156916076,-0.04038449967738522
288.5000000000035,19.05484765029268,0.6647098070639184,-0.042924046342365685
289.60000000000355,19.08777616552174,0.666187666950413,-0.04358082133752905
290.70000000000357,19.121350476320952,0.6666461414615565,-0.0422136515322169
291.8000000000036,19.15452612578635,0.6682414467305096,-0.042249950867858654
292.9000000000036,19.18804690270483,0.6706910805471159,-0.04092509513163023
294.0000000000036,19.22147837079723,0.67107517419077,-0.04082708807857882
295.1000000000036,19.2549214417298,0.671251956590634,-0.04164176995362778
296.2000000000036,19.288094242264265,0.6741609774355307,-0.04388353756471419
297.30000000000365,19.32138673909957,0.676819377884325,-0.045018101487829476
298.4000000000037,19.354998986012525,0.6783106535879027,-0.04362168831627233
299.5000000000037,19.387913413786563,0.6788804537396063,-0.043690155338824255
300.60000000000366,19.4209782734209,0.6805839773756039,-0.04368989710027327
301.7000000000037,19.45486756576976,0.6828069057786523,-0.043689889695526674
302.8000000000037,19.48821830281473,0.6826355262750761,-0.04368989692777925
303.90000000000373,19.52144571149116,0.6870233043600911,-0.043690363384560005
305.00000000000375,19.554737057169522,0.6871361706823613,-0.043606102476865694
306.1000000000038,19.58803984736393,0.6903285875170948,-0.04512239190555567
307.2000000000038,19.621611555758815,0.6923084572480456,-0.046408724615298436
308.3000000000038,19.654967910535877,0.6926987654637122,-0.046732491178388624
309.40000000000384,19.688146728287016,0.6943207390688171,-0.04774851818815806
310.5000000000038,19.721512349072803,0.6942144663675657,-0.047924061014923414
311.60000000000383,19.755002812726975,0.6966085515595284,-0.05039130130387104
312.70000000000385,19.788208048222174,0.6975072117988954,-0.05184206129552793
313.8000000000039,19.821705439726248,0.6981736782927219,-0.051928881407425465
314.9000000000039,19.855065865776616,0.6989121799775919,-0.05192331763892577
316.0000000000039,19.888361934887765,0.6994619055726117,-0.05276251508745755
317.10000000000394,19.921895053513477,0.7011947915921286,-0.05323834761505708
318.2000000000039,19.954987315289152,0.7016219148657636,-0.0547848019960826
319.30000000000393,19.98846084168815,0.7023795395646146,-0.05690068352630595
320.40000000000396,20.022073916221675,0.7024147747595156,-0.0584498690872195
321.500000000004,20.055657152414216,0.7044571763492489,-0.05841347924356377
322.600000000004,20.088799550948643,0.7076551266713846,-0.05967754595252295
323.700000000004,20.122333593413888,0.7075489764031049,-0.059133206528644955
324.80000000000405,20.155851697449055,0.7105568607078636,-0.05706834911835257
325.90000000000407,20.188623647867676,0.7105645734525243,-0.05708000981095962
327.0000000000041,20.222850611261766,0.7137367795528976,-0.05707599034869659
328.10000000000406,20.25617859146685,0.7167967906975138,-0.05762340589978132
329.2000000000041,20.289415400640586,0.7188432647612795,-0.0591292778440522
330.3000000000041,20.322955371442976,0.7184577646923469,-0.06238268723956253
331.4000000000041,20.356692124028225,0.7202643906371,-0.06485563737340927
332.50000000000415,20.390424322201643,0.7211801850546273,-0.06633644920673332
333.6000000000042,20.423715568831398,0.7236208594274539,-0.06631300082934732
334.7000000000042,20.457409587442932,0.725542755068451,-0.06557735377655804
335.80000000000416,20.49088557186734,0.7289827743325752,-0.06498996636584131
336.9000000000042,20.524380330427864,0.7291431952565584,-0.06499091352492492
338.0000000000042,20.5579527280521,0.7325879647633111,-0.06495237595856329
339.10000000000423,20.591591093501886,0.7381383835066737,-0.06647286667336116
340.20000000000425,20.625162985456573,0.7392434943989946,-0.06828935983254247
341.3000000000043,20.658884347394604,0.7401834074800246,-0.07058042009949927
342.4000000000043,20.69248858216714,0.7432833861099026,-0.07113882527330251
343.5000000000043,20.72630963339154,0.7473593447638636,-0.07150265984023374
344.60000000000434,20.759344869825156,0.7503085075616254,-0.07244928368139769
345.7000000000043,20.793452544422657,0.7536804885530094,-0.07207376584802994
346.80000000000433,20.827027651162435,0.757638398576792,-0.071407321853445
347.90000000000435,20.860712768912645,0.7619053175383862,-0.0727748788306215
349.0000000000044,20.89452428741818,0.76385920152675,-0.07278007175186296
350.1000000000044,20.92854901987683,0.767216892893763,-0.07277986943718817
351.2000000000044,20.96206454434074,0.7709601048098746,-0.07278524574276712
352.30000000000445,20.995989704743522,0.7754979583589157,-0.07395908599689349
353.4000000000044,21.02954690349602,0.7795403314773043,-0.07515704252740507
354.50000000000443,21.063429010826027,0.7845241921482033,-0.07663842438520385
355.60000000000446,21.09718662095331,0.7881492216723185,-0.0784386306659064
356.7000000000045,21.130817806200987,0.7903755243287847,-0.0812350449880963
357.8000000000045,21.164638091143242,0.7961416601003037,-0.08420145273645918
358.9000000000045,21.19839799037844,0.7999627264256829,-0.0861011663457667
360.00000000000455,21.23162138992152,0.8073106133519847,-0.08690013280480491
361.10000000000457,21.26632730511735,0.81234714218497,-0.089287263919132
362.2000000000046,21.299849368280885,0.8186899291754142,-0.09078512473260192
363.30000000000456,21.333765053345314,0.8236172233689931,-0.09231741161935103
364.4000000000046,21.36733725928118,0.8296154787530383,-0.09323458821331432
365.5000000000046,21.401701713408883,0.8359484513290698,-0.09384482822638507
366.6000000000046,21.43548385119555,0.8429902182018179,-0.09521574841707947
367.70000000000465,21.469502976948952,0.8509040193471548,-0.09659158824474945
368.8000000000047,21.503526585278415,0.8601189793433408,-0.09900906818216715
369.9000000000047,21.537597240101515,0.8678813026750001,-0.10288846838681787
371.00000000000466,21.571633602791255,0.8807134315749019,-0.10730118721579096
372.1000000000047,21.60579193475127,0.8893712252665528,-0.11054866560233112
373.2000000000047,21.639911044375275,0.9009199853730778,-0.11372277078916637
374.30000000000473,21.673849134977807,0.9145616477360237,-0.1167330319990394
375.40000000000475,21.70796908265938,0.9281555047007308,-0.11990388302552857
376.5000000000048,21.741982685251617,0.9402450207039512,-0.12247931403804246
377.6000000000048,21.77609576569821,0.9518924606267486,-0.12377824599686216
378.7000000000048,21.80972224417576,0.9677436486227887,-0.1266924702827441
379.80000000000484,21.844558530775416,0.9855557875556555,-0.13063364881617145
380.9000000000048,21.878908513815446,1.005290191499899,-0.13809497080961153
382.00000000000483,21.913154698115022,1.0287341333005646,-0.1435574199215015
383.10000000000485,21.947458440219535,1.0555392908622787,-0.14813517385584696
384.2000000000049,21.981971386799124,1.081025561647861,-0.15134561055328843
385.3000000000049,22.016503080408533,1.1102908724889375,-0.15487681505219353
386.4000000000049,22.05052571733567,1.142054066493126,-0.1610177590162274
387.50000000000495,22.084667112361693,1.1743894944749713,-0.16828403397102054
388.6000000000049,22.119867313658265,1.2128424396861046,-0.1750793818181151
389.70000000000493,22.154599275585568,1.2529521518759106,-0.17914239226487982
390.80000000000496,22.188975703386863,1.2970485785662642,-0.18460712749994013
391.900000000005,22.224062969436943,1.3435251688805292,-0.1935315736250316
393.000000000005,22.258986468721613,1.3960430035687685,-0.20375324206109235
394.100000000005,22.293770148539142,1.4521122245052174,-0.21289622823658005
395.20000000000505,22.328212901313453,1.507963757807549,-0.22266037102180825
396.30000000000507,22.363839414551652,1.5798327417004174,-0.23492730409695062
397.4000000000051,22.39910614095744,1.6511660728161344,-0.24684285344294787
398.50000000000506,22.43414142644883,1.7226234770967026,-0.25639829120266633
399.6000000000051,22.469515215619058,1.81166477443012,-0.2667356817379445
400.7000000000051,22.504856824151126,1.9023459893890013,-0.2802958539685183
401.8000000000051,22.54028887436567,1.9990002027639941,-0.2935707946235775
402.90000000000515,22.576200622366073,2.1119069540823077,-0.3120687724228448
404.0000000000052,22.611939274977626,2.232079752869247,-0.33140592452479467
405.1000000000052,22.6481479731727,2.365610479524369,-0.3514592339576641
406.20000000000516,22.684162503707537,2.487532010831454,-0.3719999214265739
407.3000000000052,22.71963775865461,2.6300775689123435,-0.3930100161113437
408.4000000000052,22.756589624503153,2.7974999535437064,-0.4179434606148895
409.50000000000523,22.793029599997368,2.9692419033446464,-0.44475553574795823
410.60000000000525,22.829829341657543,3.143199776434386,-0.47359308709559134
411.7000000000053,22.86738838256292,3.358913667636369,-0.5055461985683802
412.8000000000053,22.90424603068846,3.5635408809723272,-0.5377735818668539
413.9000000000053,22.94157198419378,3.7934487444731064,-0.5748179437652752
415.00000000000534,22.979307016108685,4.0580057612074105,-0.6169657668824602
416.1000000000053,23.017886448244095,4.352821682981224,-0.660188512977582
417.20000000000533,23.056139598159948,4.646406687003837,-0.7109669268655305
418.30000000000535,23.09401883182767,4.943703210709438,-0.7619170156816115
419.4000000000054,23.13223832345017,5.243639156377564,-0.8153599679855881
420.5000000000054,23.171201343708717,5.5182469067735225,-0.87420795453769
421.6000000000054,23.209861577660718,5.843219016930164,-0.9362775835021626
422.70000000000545,23.248909424499917,6.182480515391183,-1.0060372464513745
423.8000000000054,23.28824770146964,6.5357656652126765,-1.081104385917512
424.90000000000543,23.327713849356506,6.921195274517633,-1.1639374632296207
426.00000000000546,23.367138639158963,7.244059858019696,-1.251697519990107
427.1000000000055,23.406524281215248,7.623026828898797,-1.3417918833631122
428.2000000000055,23.44573280156167,7.96696116553588,-1.4335010143500737
429.3000000000055,23.485133388800485,8.293956714331085,-1.5609326360633329
430.40000000000555,23.524201988815108,8.61954963262341,-1.6659271417011876
431.50000000000557,23.56311426372067,8.930284507075276,-1.776277769115861
432.6000000000056,23.60144186819498,9.183567863307584,-1.8857710929269977
433.70000000000556,23.639489568461364,9.431718194221997,-1.9993078203198067
434.8000000000056,23.676836061241875,9.607616824039754,-2.114245314248268
435.9000000000056,23.71278028029247,9.688687435240213,-2.225827512071901
437.0000000000056,23.748970179361383,9.745352403227917,-2.341046000553753
438.10000000000565,23.784274138657008,9.726371219684967,-2.4517052633558483
439.2000000000057,23.81888011956764,9.661361752699726,-2.561362898949318
440.3000000000057,23.85263652176104,9.520643729386496,-2.665630309035994
441.40000000000566,23.885386812239517,9.325202691885014,-2.7701931811411145
442.5000000000057,23.9176995999655,9.05169407676331,-2.8701729992055514
443.6000000000057,23.94894236950886,8.73002574380963,-2.9591394729490244
444.70000000000573,23.979255575157616,8.365231172458476,-3.046180585746167
445.80000000000575,24.0097199818162,7.947433300591387,-3.1258807947375638
446.9000000000058,24.039706308199868,7.476747844894087,-3.2058951127673785
448.0000000000058,24.068562333717715,6.9903381815066234,-3.2766764542904268
449.1000000000058,24.09757386619723,6.460732194754401,-3.3463882008687342
450.20000000000584,24.12618633271968,5.919455136432259,-3.4016576519288
451.3000000000058,24.15465869046151,5.368877748533947,-3.454044705951225
452.40000000000583,24.183006415675017,4.821549238333448,-3.505432855583385
453.50000000000585,24.211217766791346,4.280062709438794,-3.5535205697299808
454.6000000000059,24.239604963044453,3.7577910397692103,-3.5912734943592786
455.7000000000059,24.268322232538374,3.2492500697270454,-3.625925495245759
456.8000000000059,24.296857533766293,2.7745304623556857,-3.6587866464874224
457.90000000000595,24.32585629807015,2.323417420480519,-3.6878968095547884
459.0000000000059,24.35522261185779,1.9210167981738735,-3.711177137752303
460.10000000000593,24.38511347176607,1.5458214920540434,-3.73266442842993
461.20000000000596,24.41524134686401,1.2109701147966936,-3.7512640483725055
462.300000000006,24.446012340770558,0.9123270358531232,-3.7655296025088973
463.400000000006,24.477010095759898,0.6488663828588974,-3.777019493897549
464.500000000006,24.508518385521207,0.42125510449671255,-3.789731455178417
465.60000000000605,24.540142872845124,0.2310383607377854,-3.8042579627778434
466.70000000000607,24.572116316387138,0.060660305086599364,-3.813289307062713
467.8000000000061,24.60482999297798,-0.07373123486554051,-3.8187950912678206
468.90000000000606,24.63666593609789,-0.18916922850732742,-3.82574954838357
470.0000000000061,24.67024826086982,-0.28449606736465277,-3.830032464490132
471.1000000000061,24.703569944680215,-0.3648902953084984,-3.832004479921412
472.2000000000061,24.73718036895794,-0.42845502764872295,-3.8348737844201355
473.30000000000615,24.77077329754831,-0.47737310964557533,-3.8372539474584118
474.4000000000062,24.804647398783548,-0.5165572959203293,-3.8404996230939528
475.5000000000062,24.83876280181235,-0.5476548012214897,-3.8476794846888676
476.60000000000616,24.872830882206742,-0.5720064128771161,-3.847920276583872
477.7000000000062,24.906678880329867,-0.5956610883092281,-3.8492250532908803
478.8000000000062,24.940904197925178,-0.6163683029899707,-3.8507297701394774
479.90000000000623,24.975412884039407,-0.6336125157955453,-3.852078667220893
481.00000000000625,25.0095922028967,-0.6495096293189048,-3.8523634779636327
482.1000000000063,25.04418805256456,-0.6592131527843513,-3.8540328186256856
483.2000000000063,25.07857892665492,-0.6741009172861908,-3.8567577948076144
484.3000000000063,25.11286033789301,-0.6867215780324951,-3.860130453622789
485.40000000000634,25.147364666919575,-0.7006674378987954,-3.861571210372822
486.5000000000063,25.181788880251947,-0.7149640401377662,-3.861521450322007
487.60000000000633,25.216767963183113,-0.7258948812969137,-3.8628128542728786
488.70000000000636,25.25145289301781,-0.7357487961626464,-3.8632940912955442
489.8000000000064,25.286066107299884,-0.7430185783795387,-3.8641556100768533
490.9000000000064,25.320547406032258,-0.7511822677327317,-3.8641500604175785
492.0000000000064,25.355764677863473,-0.755095866813198,-3.8641500490516143
493.10000000000645,25.39031422448033,-0.761320638030256,-3.864150046421376
494.2000000000064,25.42555149871245,-0.7614486457655366,-3.8641534604660683
495.30000000000643,25.46018693853378,-0.7593144173764333,-3.863474240631076
496.40000000000646,25.49508255046529,-0.7584930550632079,-3.862827172319058
497.5000000000065,25.530162053389994,-0.7476555370439688,-3.8628347573305675
498.6000000000065,25.56509579817191,-0.7410234505387976,-3.864135974292567
499.7000000000065,25.59964542616901,-0.7309077818806855,-3.8641500666825164
500.80000000000655,25.634470292972036,-0.7217344873861229,-3.864150011650887
501.90000000000657,25.669523554509382,-0.7163746156191624,-3.8641506660870153
503.0000000000066,25.705044728115688,-0.7100778342875859,-3.8655605162935602
504.10000000000656,25.7402853852288,-0.7135088715532575,-3.865472641181957
505.2000000000066,25.77541648237544,-0.7135109622043805,-3.8641046340218703
506.3000000000066,25.810644318505677,-0.717422420311437,-3.8641504903790196
507.4000000000066,25.84592548430021,-0.7201527413498181,-3.8621433106271144
508.50000000000665,25.880682447814962,-0.724433143990286,-3.86150621671286
509.6000000000067,25.915846796826784,-0.7275620247344028,-3.862845640367604
510.7000000000067,25.951237321850794,-0.7349841538004528,-3.8628396815099664
511.80000000000666,25.985965587069494,-0.7384104899099291,-3.862766430335114
512.9000000000067,26.02124712525443,-0.7425518236216591,-3.862825048751308
514.0000000000067,26.056506630358438,-0.7463921227105145,-3.86166987856508
515.1000000000067,26.092250741079134,-0.7532168301577286,-3.8615546166605754
516.2000000000068,26.12737984721052,-0.7609990114523779,-3.861609310600926
517.3000000000068,26.162995475810703,-0.76605717534868,-3.861536229970576
518.4000000000068,26.198098836617444,-0.7745713693658296,-3.8628164926526223
519.5000000000068,26.233633381126563,-0.7769088672799308,-3.8634996830185804
520.6000000000068,26.268309184283734,-0.7828621975189136,-3.8629349926543646
521.7000000000069,26.304167852569968,-0.7927247543222404,-3.8629401752673167
522.8000000000068,26.339436565376154,-0.7985788845469948,-3.8629401437055635
523.9000000000069,26.37469970903862,-0.8055849592997396,-3.86292719099951
525.0000000000068,26.410284683158533,-0.8111580358229046,-3.8615976522468447
526.100000000007,26.44558122581498,-0.8143635780923584,-3.859275311735087
527.2000000000069,26.48100856917399,-0.8193053961524437,-3.85856042425411
528.300000000007,26.516563125754153,-0.8219471083888894,-3.861220161405402
529.4000000000069,26.552099723966844,-0.8279726546252424,-3.862332350153269
530.5000000000069,26.58768103051792,-0.8303685969197521,-3.86402220101486
531.600000000007,26.62298893162181,-0.8341481798331609,-3.8639172894510003
532.700000000007,26.65771333062784,-0.8339424477092022,-3.8627092365162836
533.800000000007,26.693738899739998,-0.8402632013728065,-3.8612538649634107
534.900000000007,26.729673539924708,-0.8390428981519501,-3.85976879358136
536.000000000007,26.765295887958867,-0.8416137294828379,-3.860639412618266
537.1000000000071,26.80061221112982,-0.8445771177976046,-3.861120334479632
538.2000000000071,26.83614237498667,-0.8448747857160812,-3.8623884709277605
539.300000000007,26.871848799243168,-0.8472819493647851,-3.865212011754074
540.4000000000071,26.907254734446575,-0.8469479307929813,-3.8665131498189504
541.500000000007,26.943158970602774,-0.853345173106419,-3.8652466335687707
542.6000000000072,26.97880558362666,-0.8539401763618898,-3.8639115361357885
543.7000000000071,27.014350899640046,-0.8552230500888449,-3.8630073951938053
544.8000000000072,27.049869489089282,-0.8548226597173424,-3.861518623902187
545.9000000000071,27.085364322932897,-0.856872721765373,-3.8628368279094323
547.0000000000072,27.12117099936087,-0.8586193451173518,-3.8628301842090895
548.1000000000072,27.15686251088137,-0.8593460041143294,-3.862830164359581
549.2000000000072,27.192271997565697,-0.8597810580525715,-3.8628301562532585
550.3000000000072,27.22852126410878,-0.8607704690359604,-3.862832311319279
551.4000000000073,27.263947746841588,-0.8574962398254399,-3.862386077453481
552.5000000000073,27.299445679176827,-0.8599371625178436,-3.8639319988810055
553.6000000000073,27.335610204023336,-0.8606326548233465,-3.8639597563125267
554.7000000000073,27.37132403463367,-0.8594579309026134,-3.8645323199524353
555.8000000000073,27.407194038810758,-0.858037558205627,-3.8636221535112343
556.9000000000074,27.442886985162428,-0.8560374263681994,-3.86406775114987
558.0000000000074,27.478112327500604,-0.8549186998100925,-3.863597830057147
559.1000000000074,27.514038397845066,-0.8577644519584967,-3.863563035254354
560.2000000000073,27.550227928375776,-0.8557456993325938,-3.865027905407956
561.3000000000073,27.58615859170055,-0.8550297366774289,-3.8650304110286826
562.4000000000074,27.62220496929527,-0.8542612019099189,-3.8650320747781763
563.5000000000074,27.658155587060016,-0.8552008916844793,-3.8644960994876585
564.6000000000074,27.69409825626786,-0.8560517689576954,-3.864038726080286
565.7000000000074,27.729871198491885,-0.8556657528478034,-3.864040112344367
566.8000000000075,27.76551602825623,-0.8565085294780352,-3.8632397231853446
567.9000000000075,27.801364986789668,-0.8558543200209666,-3.862737268429063
569.0000000000075,27.83761094436537,-0.859322658092278,-3.864027360634279
570.1000000000075,27.873697649601347,-0.8585686072585048,-3.86403853414857
571.2000000000075,27.90957685749034,-0.8588093727643633,-3.8640629066962053
572.3000000000076,27.9454589892358,-0.860706729432488,-3.862731367491362
573.4000000000076,27.98158494454911,-0.860886456142083,-3.8627284941000815
574.5000000000076,28.01766406346973,-0.8592672899100469,-3.8632266559156108
575.6000000000076,28.053551125297574,-0.8605713040499435,-3.86372558327642
576.7000000000077,28.088960758187504,-0.8625250801500652,-3.862819646771771
577.8000000000077,28.125342355328943,-0.8606598882601404,-3.8623992737796753
578.9000000000076,28.1615045873317,-0.8615311514509105,-3.8624000763397133
580.0000000000076,28.197585546139713,-0.8598530662706537,-3.862392805882389
581.1000000000076,28.23292398713193,-0.8614882305059774,-3.8634921713405714
582.2000000000077,28.26999966344351,-0.8559639400035193,-3.8633798485939965
583.3000000000077,28.305943679122297,-0.8582354782811908,-3.8633800401955565
584.4000000000077,28.34190191159537,-0.8578871258003485,-3.8633800499638125
585.5000000000077,28.378142668499304,-0.8551977422505557,-3.8633800500005595
586.6000000000078,28.414138484879803,-0.8544654307499558,-3.863380050000006
587.7000000000078,28.450166296142946,-0.8536562321602577,-3.86338005
588.8000000000078,28.486336043726535,-0.8554083919041726,-3.8633800500000004
589.9000000000078,28.522410764913122,-0.8492955913896552,-3.863380050000017
591.0000000000078,28.558455072208275,-0.8502250929331678,-3.8633800499988147
592.1000000000079,28.594573067627184,-0.8490072556358362,-3.863380049700066
593.2000000000079,28.63069415760685,-0.8491956107599623,-3.863380042092291
594.3000000000079,28.666962924236064,-0.8499101943074086,-3.8633833905740005
595.4000000000078,28.703227207270828,-0.8468378983891448,-3.8623853611589056
596.5000000000078,28.739408144212582,-0.8466741309284392,-3.859033799105916
597.6000000000079,28.77530210212388,-0.8424894663041166,-3.85903173040725
598.7000000000079,28.81183716161696,-0.8435867637378223,-3.8613790539444524
599.8000000000079,28.84766149474227,-0.8445777111028255,-3.862094047033411
600.9000000000079,28.884317269071374,-0.8430836802072271,-3.863399737431433
602.000000000008,28.920459883812267,-0.8418600654333135,-3.8647236896407406
603.100000000008,28.956261683442126,-0.8401616629273276,-3.8650424299379305
604.200000000008,28.993232813128532,-0.8406179832580456,-3.8661346803649366
605.300000000008,29.029125106382786,-0.8356711766662248,-3.8661235857275145
606.400000000008,29.06463206835845,-0.8349707388765375,-3.8647646493364363
607.5000000000081,29.101915710510315,-0.8301300765628568,-3.8648332670271923
608.6000000000081,29.137948957335006,-0.8268457711128225,-3.8651411949432664
609.7000000000081,29.17441806013738,-0.8222814291109521,-3.8650761982723387
610.8000000000081,29.210629003743925,-0.8255579353793683,-3.866115027856431
611.9000000000082,29.24686748530082,-0.8209412604993755,-3.866795437643097
613.0000000000082,29.283131247593946,-0.8207677212060668,-3.8674358604850676
614.1000000000081,29.319475085038924,-0.8193125548831097,-3.8683838230497596
615.2000000000081,29.355831407779736,-0.8175852543336816,-3.868758975035926
616.3000000000081,29.39230363906994,-0.8142541002236555,-3.86741333821329
617.4000000000082,29.428154781933127,-0.813056173022737,-3.867449799920397
618.5000000000082,29.464559571595892,-0.8110878528251148,-3.867281461252437
619.6000000000082,29.501048681567305,-0.8122369892843682,-3.8667887674973906
620.7000000000082,29.537295818639965,-0.8097993874789705,-3.865686670981765
621.8000000000083,29.573464380589655,-0.8054376898214918,-3.8654724935484017
622.9000000000083,29.60973177186154,-0.8045799161643761,-3.865204303551063
624.0000000000083,29.646268971750068,-0.8054155208712646,-3.8647563781017302
625.1000000000083,29.682646059161613,-0.805833133075022,-3.866117723747699
626.2000000000083,29.71892062130023,-0.8042024566010773,-3.8661300039019864
627.3000000000084,29.755396149248988,-0.8031477342075575,-3.8661309031410944
628.4000000000084,29.792048094213197,-0.803974109768145,-3.8662095732557713
629.5000000000084,29.828119272644336,-0.8007184138744443,-3.867439779493336
630.6000000000083,29.864462074342732,-0.8001929692792491,-3.8669079937419664
631.7000000000083,29.900823164458618,-0.8032634377612535,-3.867449717161225
632.8000000000084,29.937338919062935,-0.8012574702775253,-3.8678704913665776
633.9000000000084,29.97381972115582,-0.801650269521186,-3.8700346956712135
635.0000000000084,30.00996707375641,-0.8063190829431921,-3.8705206378201398
636.1000000000084,30.046467268578755,-0.806913031199658,-3.871855188196969
637.2000000000085,30.082775818207455,-0.8073292912999304,-3.869614992116979
638.3000000000085,30.119229857483173,-0.8103229762980961,-3.867591320971818
639.4000000000085,30.15519981311637,-0.8117362146240219,-3.866427586272832
640.5000000000085,30.19175309190675,-0.8108923844543903,-3.8661370742796066
641.6000000000085,30.228045356744754,-0.8121268990452428,-3.864710864584954
642.7000000000086,30.264697207276587,-0.8137714944538896,-3.863407187277685
643.8000000000086,30.30088528512751,-0.816954572742159,-3.864759005199186
644.9000000000086,30.33751977624334,-0.8190337065107312,-3.8678029264260005
646.0000000000086,30.373834689263028,-0.817921275598871,-3.8705138191862853
647.1000000000087,30.410328104785595,-0.8230329465535765,-3.870519950674208
648.2000000000087,30.446743490265522,-0.8248583861591581,-3.8705199952262364
649.3000000000086,30.48304261599225,-0.8241570050572644,-3.8705199889505395
650.4000000000086,30.51959941374782,-0.8259257546381602,-3.8705201254585306
651.5000000000086,30.556155830880574,-0.8244597261612847,-3.870623631811153
652.6000000000087,30.592520434515997,-0.825721039260059,-3.8680919144705594
653.7000000000087,30.629128319784257,-0.8272106233379315,-3.8665443777287343
654.8000000000087,30.665422706867744,-0.8287626755740629,-3.867588754773921
655.9000000000087,30.70193481838851,-0.8327502124586548,-3.8696235137457737
657.0000000000088,30.73829865248759,-0.8346825194816438,-3.8707747612175427
658.1000000000088,30.77469990705214,-0.8387060718168644,-3.870839099144225
659.2000000000088,30.81135231876712,-0.8394235466175379,-3.8708400319153475
660.3000000000088,30.847631669897943,-0.8439020109907371,-3.870840034335549
661.4000000000088,30.884197015501307,-0.845319765256781,-3.87084044212324
662.5000000000089,30.920964306234016,-0.847390373081667,-3.8681116421544397
663.6000000000089,30.95716823237924,-0.8477569936009499,-3.868110933389354
664.7000000000089,30.993735830162294,-0.8479639653107777,-3.8681099903869702
665.8000000000088,31.030130979899127,-0.848927026350746,-3.8681098640852416
666.9000000000088,31.066575499603495,-0.8482273790553041,-3.8687538470218525
668.0000000000089,31.103209895951473,-0.8504253894878682,-3.8694263244988223
669.1000000000089,31.1396594317045,-0.850526015656868,-3.870745710504404
670.2000000000089,31.176407371098822,-0.8506027443404081,-3.8694590597137655
671.3000000000089,31.212696337493725,-0.8524370335870124,-3.8680471659039846
672.400000000009,31.249350651176428,-0.8547766671689634,-3.8678899493782763
673.500000000009,31.285773025805664,-0.8532435138563035,-3.867901620608294
674.600000000009,31.322393727993163,-0.8544045818233463,-3.8694513801610433
675.700000000009,31.35808397100088,-0.8548770966454942,-3.870870474150872
676.800000000009,31.39538721735357,-0.8545429884501643,-3.872497318179452
677.9000000000091,31.431820930896365,-0.8533700335017366,-3.8725000253975823
679.0000000000091,31.468392890558327,-0.8528621760248467,-3.8725003383858745
680.1000000000091,31.50515384384296,-0.8551905328344966,-3.871628286761541
681.2000000000091,31.54161566286004,-0.8535462306588448,-3.8711752075426977
682.3000000000092,31.578452829717534,-0.85352764033454,-3.870839231138156
683.4000000000092,31.614707992480028,-0.8538792445783407,-3.870839374595606
684.5000000000091,31.651400774989412,-0.853885542964606,-3.8692610162655847
685.6000000000091,31.687838003529198,-0.8579514679791274,-3.869307856608449
686.7000000000091,31.724517032015118,-0.85926537199573,-3.8724535629528987
687.8000000000092,31.761346140652396,-0.8603571734291289,-3.873600394270917
688.9000000000092,31.79766768670475,-0.8627878966786748,-3.8735998181701796
690.0000000000092,31.8343374439128,-0.8626272374793222,-3.873577876702868
691.1000000000092,31.87084109706186,-0.8661028633063259,-3.8722662147369054
692.2000000000093,31.907388199988397,-0.860610002777777,-3.869765263909289
693.3000000000093,31.944266465448486,-0.8606576687949473,-3.8705026318232574
694.0000000000093,31.967577225433665,-0.8588171611211228,-3.871312494554969