File: 01_Data/Corian_Countertop/STA/N2/10K_min/Corian_Countertop_STA_N2_10KData_220920_R2.csv
##Temp./Â°C,Time/min,DSC/(mW/mg),Mass loss/mg
51.0,10.859705950474893,0.038132231083683354,0.020425819251546073
52.20000000000002,11.212811564974452,0.07266291423894589,0.018806693018915688
53.400000000000034,11.469616455136254,0.0976196598037431,0.016567720367119954
54.60000000000005,11.686800587916306,0.11571017019118668,0.01687643306140263
55.80000000000007,11.880088608694452,0.13034378280033843,0.01914948571719588
57.000000000000085,12.060386747033684,0.14277332714499913,0.019599058037100825
58.2000000000001,12.235188943217862,0.15326962380478482,0.018452818519102188
59.40000000000012,12.397864649763083,0.16179686319037412,0.019336584106394383
60.600000000000136,12.558353830975948,0.16911496067698373,0.018762968535166458
61.80000000000015,12.713543700348248,0.17657448401136766,0.018299028808582918
63.00000000000017,12.864845856449605,0.18334611135628842,0.01811427165391688
64.20000000000019,13.014396024314367,0.18921542290999338,0.018257928763961928
65.4000000000002,13.161898521493708,0.1961324271910294,0.018177138076951316
66.60000000000022,13.30799369617564,0.2029405723182196,0.017040150668542253
67.80000000000024,13.448224195592017,0.2070385585355643,0.018293769638516366
69.00000000000026,13.590063897278368,0.21266951365849684,0.016924795252576175
70.20000000000027,13.729059181294389,0.21869000267563787,0.018253574028939568
71.40000000000029,13.866563877643113,0.2249042991477157,0.01681664022591356
72.6000000000003,14.001289684754923,0.22962914066389484,0.01683743438895391
73.80000000000032,14.138081890415005,0.23452352567037382,0.016797057147044825
75.00000000000034,14.270617327190946,0.23990360805947353,0.01812753134814482
76.20000000000036,14.403981387846331,0.2446807400474148,0.017194606795950307
77.40000000000038,14.534063946452768,0.25101882482224747,0.016790821534849343
78.60000000000039,14.665589213903603,0.25428394169820645,0.018066144322818722
79.80000000000041,14.794654316201347,0.2578815360968132,0.016626324868513898
81.00000000000043,14.923799886407055,0.2615747398889706,0.015399926529215513
82.20000000000044,15.04989879747164,0.2654370753123583,0.015264849382989887
83.40000000000046,15.178251657229916,0.2669159327495846,0.016580846107498104
84.60000000000048,15.30506171550192,0.27041896187507475,0.017838582956698268
85.8000000000005,15.429833124470656,0.272067968691477,0.01657123948531236
87.00000000000051,15.555005064758303,0.27418523755343027,0.016563779884811503
88.20000000000053,15.679786180473197,0.27608397467980283,0.015249136413222786
89.40000000000055,15.803904980828882,0.2798091349669659,0.012630363844580828
90.60000000000056,15.924688770057081,0.28266830896249273,0.012480260897270945
91.80000000000058,16.04994732323735,0.28478278288951997,0.013886867146141846
93.0000000000006,16.170837126287097,0.28848372294933433,0.013940189512145373
94.20000000000061,16.291901698216243,0.2908825704381912,0.013974619237491659
95.40000000000063,16.412165136217308,0.2936577480460193,0.01267608446379942
96.60000000000065,16.53358348570596,0.295518805466528,0.012618258900381818
97.80000000000067,16.653212160275004,0.2966851567936487,0.011351657097234735
99.00000000000068,16.77317749160359,0.29988730371755934,0.011331441019308386
100.2000000000007,16.89240520039617,0.3036279858517047,0.01129979768628786
101.40000000000072,17.012315606795042,0.30790340048892084,0.011299406682208968
102.60000000000073,17.131127221552852,0.308594396124123,0.00999115390155314
103.80000000000075,17.24980933919785,0.3123145759471757,0.009990013999909841
105.00000000000077,17.367795825196623,0.31333635295739204,0.008670035436965762
106.20000000000078,17.486890313775277,0.31551972104118176,0.00999301495211391
107.4000000000008,17.60438291827276,0.3158807006202917,0.008668388974112595
108.60000000000082,17.722248131574304,0.32133156041265765,0.008755775643515484
109.80000000000084,17.841397547984304,0.3224300723887009,0.00867079249318703
111.00000000000085,17.95889317965645,0.3251035475482186,0.008314295008744033
112.20000000000087,18.075159684498118,0.3281344009456527,0.007379213212804103
113.40000000000089,18.192475851004698,0.33124223776616946,0.007945492028266443
114.6000000000009,18.310197900821297,0.335587361292365,0.00736187140460931
115.80000000000092,18.426858907615163,0.33755472255228536,0.007163552418568031
117.00000000000094,18.544276886603093,0.3407439954825713,0.005381365961828699
118.20000000000095,18.662190343464484,0.3421475730199749,0.005380806306743757
119.40000000000097,18.78057013050215,0.3459627950694679,0.006012172920104142
120.60000000000099,18.896285858520443,0.3476002555894864,0.004719964697065926
121.800000000001,19.012499726008475,0.35215939318753464,0.004398630515869861
123.00000000000102,19.12693747187726,0.35213121856954765,0.004719885869594265
124.20000000000104,19.245115009910794,0.3545506736851536,0.003399857830582498
125.40000000000106,19.36142551835883,0.3548770113078473,0.00467450382106982
126.60000000000107,19.47529510066476,0.357274294211259,0.0011053405600156552
127.80000000000109,19.59397086198653,0.3592187472269611,0.001099924515883366
129.0000000000011,19.70946239787229,0.3586987844673162,0.0014266987682933774
130.20000000000113,19.82556360853686,0.359919272685174,0.0014293937849130245
131.40000000000114,19.941096136222868,0.36306056519487406,-0.00020192091858817207
132.60000000000116,20.05680948563328,0.3641383325145603,-0.0015402512500166665
133.80000000000118,20.17172683114322,0.36685387187289875,-0.0027384162419892277
135.0000000000012,20.287931309267215,0.36970393945332214,-0.004186903868037994
136.2000000000012,20.40348829454875,0.3716769020620725,-0.004170133627913408
137.40000000000123,20.518407869424177,0.3720823481242197,-0.005491418212761445
138.60000000000124,20.63488450226702,0.37522589727650446,-0.004844165324477956
139.80000000000126,20.75001233706051,0.3761885100157081,-0.006066229272738255
141.00000000000128,20.86441693635175,0.37919562820075153,-0.007190278162163999
142.2000000000013,20.979903177956945,0.3812789979277991,-0.008591425368898342
143.4000000000013,21.09280193071248,0.3843451790911624,-0.009769818761308002
144.60000000000133,21.20818153528375,0.3843333977303787,-0.00944428911715356
145.80000000000135,21.322772244887574,0.3879348575589074,-0.008752496477847593
147.00000000000136,21.436419341951773,0.3927027865431208,-0.010126585690498402
148.20000000000138,21.551511601689725,0.3941027143069878,-0.011410856746964626
149.4000000000014,21.666670501817144,0.397940269650065,-0.012737006266201334
150.60000000000142,21.780539937378755,0.401243905710342,-0.014050037368225965
151.80000000000143,21.894619697923652,0.40438998908158297,-0.015041535228450975
153.00000000000145,22.009643236187447,0.4072226129053958,-0.016359880868651366
154.20000000000147,22.12426844938777,0.4117957958962691,-0.01636200469060789
155.40000000000148,22.23821210173168,0.4148374882648958,-0.01794490243918645
156.6000000000015,22.351680059211926,0.41964447971218943,-0.0193301838657991
157.80000000000152,22.465122800868997,0.42456188781629717,-0.020270657400340397
159.00000000000153,22.580057253447368,0.42787049571408964,-0.021626243311221316
160.20000000000155,22.694125164090597,0.4326515607818612,-0.021997901727104363
161.40000000000157,22.807843330648303,0.43756733698640193,-0.023136371841697034
162.6000000000016,22.921991447416833,0.440367734117871,-0.024621117446117502
163.8000000000016,23.03587269617188,0.4463266309612737,-0.02822168275303305
165.00000000000162,23.14906754041101,0.4504995657914276,-0.02986971396399163
166.20000000000164,23.26473740920002,0.4553566681488526,-0.031179826629530005
167.40000000000165,23.375679992929133,0.4595815169394321,-0.031876037668366664
168.60000000000167,23.49304187275825,0.465026733952118,-0.03213568999124927
169.8000000000017,23.606820149712192,0.4712800219646782,-0.03573047991053091
171.0000000000017,23.720422250331758,0.47387999909605366,-0.039284381250610956
172.20000000000172,23.834255538179004,0.47959211629556425,-0.040841784390579505
173.40000000000174,23.948565841216368,0.48483068258654427,-0.04310087478233804
174.60000000000176,24.063538695817613,0.4916231338567813,-0.04380933958067512
175.80000000000177,24.17768008886666,0.4962481649947622,-0.0446945904091427
177.0000000000018,24.289834686558148,0.5007692584403388,-0.046093664763261266
178.2000000000018,24.40265730328194,0.5056684327170536,-0.05190023548509437
179.40000000000182,24.518442477347037,0.5134987935359088,-0.05586718677961233
180.60000000000184,24.632415430107276,0.5163860075916907,-0.05620809849587616
181.80000000000186,24.74589273359309,0.5193925918450435,-0.058791645525668734
183.00000000000188,24.859645805632148,0.5247487498822226,-0.0628091703971112
184.2000000000019,24.97416695269091,0.5271578863103454,-0.06673772880879092
185.4000000000019,25.08443665754039,0.5313766694752996,-0.06784402118999378
186.60000000000193,25.202032573242427,0.5347781780804114,-0.07082441260213779
187.80000000000194,25.314877132692118,0.5367304959086938,-0.07266207795946666
189.00000000000196,25.426859308671382,0.5391280197745982,-0.07596682052808923
190.20000000000198,25.54208077884526,0.5422597732022425,-0.07861633150663216
191.400000000002,25.656493748753913,0.5443201142506059,-0.08000880005099331
192.600000000002,25.770100956530005,0.5462713438655714,-0.08295808755025291
193.80000000000203,25.88415338552466,0.5481038536768704,-0.08552195137575325
195.00000000000205,25.99786393269235,0.5523449792784947,-0.08938623128016676
196.20000000000206,26.110969877489804,0.5529645083731137,-0.09079065870562619
197.40000000000208,26.22265451546862,0.5538398500804007,-0.09207270418802338
198.6000000000021,26.33796562653968,0.5590928409027143,-0.09606029742351652
199.80000000000211,26.45254128226744,0.5629190286280908,-0.09738036475969292
201.00000000000213,26.56586229091139,0.566969383804547,-0.09875969344569446
202.20000000000215,26.67988034952626,0.5706591966449965,-0.10075426953729583
203.40000000000217,26.7911550332092,0.575458205803733,-0.10264281578447942
204.60000000000218,26.90670011003069,0.5785160399955855,-0.10416499569974036
205.8000000000022,27.02124069901276,0.5857329695922993,-0.10525039514565115
207.00000000000222,27.132128254266725,0.5901359630858277,-0.10885352252463898
208.20000000000223,27.248130475189704,0.5989339874697543,-0.11054985558272845
209.40000000000225,27.362664240083138,0.6040779534574112,-0.11186894911567258
210.60000000000227,27.4752410625131,0.6120928624623642,-0.11585768624197446
211.80000000000229,27.589362827581187,0.6203585097276534,-0.11682917478707733
213.0000000000023,27.703228142268298,0.6276906305751849,-0.11977649394669587
214.20000000000232,27.81709213144944,0.6374272299383901,-0.1211036345070231
215.40000000000234,27.93103791946025,0.6498145889726288,-0.12240858059772997
216.60000000000235,28.044605276533062,0.6574469143324878,-0.12601239329687797
217.80000000000237,28.15868386350557,0.6683845664029294,-0.12809972927143543
219.0000000000024,28.271363387249558,0.6820899755912743,-0.13065809810225293
220.2000000000024,28.38577665064513,0.6943202780181426,-0.13272944144659027
221.40000000000242,28.500352774889766,0.7091354372572652,-0.13535062929696107
222.60000000000244,28.613915877101075,0.721576764557771,-0.13697348601362114
223.80000000000246,28.72917000000026,0.7370876878388419,-0.14095353412331812
225.00000000000247,28.841794001760487,0.7526033235238625,-0.14428369356988924
226.2000000000025,28.955352045920165,0.7672568011824172,-0.14763814890577454
227.4000000000025,29.06917097132193,0.7871160513769497,-0.15162000718008883
228.60000000000252,29.18277308666692,0.8034191649543032,-0.1529165307951259
229.80000000000254,29.297225572078673,0.8241771571228858,-0.1557165122428512
231.00000000000256,29.412604881708358,0.8447880070718385,-0.16106413398349462
232.20000000000258,29.526079781447578,0.8665679180900585,-0.1637087425609436
233.4000000000026,29.640646155725108,0.8946427317711314,-0.1685358938171615
234.6000000000026,29.754768781514912,0.9209286885604283,-0.17345948179472037
235.80000000000263,29.867927304369815,0.9503898677711786,-0.17619456603188555
237.00000000000264,29.982162040653908,0.983863412715547,-0.18224544196828907
238.20000000000266,30.094970379428627,1.0193394466780301,-0.18390373431515616
239.40000000000268,30.211356401771944,1.0613131648223262,-0.18958594531150563
240.6000000000027,30.325862605715322,1.1026720801667511,-0.1968274249106825
241.8000000000027,30.44070359757301,1.1493278363910266,-0.20161402651811278
243.00000000000273,30.553715068732213,1.1968613873084224,-0.20787371435847257
244.20000000000275,30.670192067367882,1.2535096599531157,-0.2143278473359298
245.40000000000276,30.78362130165288,1.3083350338619506,-0.21996825869351788
246.60000000000278,30.898980799882985,1.3679909695122443,-0.22789076494469285
247.8000000000028,31.01408126614087,1.4321449906568597,-0.23543852179056302
249.0000000000028,31.12935769277096,1.4988378709007337,-0.24471684647284864
250.20000000000283,31.244244172543304,1.5665352816743923,-0.2528990646699718
251.40000000000285,31.358112174463212,1.638875370536554,-0.2611957114722019
252.60000000000286,31.47306713167331,1.7140325432258448,-0.27152823627027
253.80000000000288,31.589079542651785,1.79169490211744,-0.28005066662244804
255.0000000000029,31.700986369658505,1.8691061113394694,-0.2893306281348984
256.2000000000029,31.818128831591135,1.9533151155866628,-0.30129212286053697
257.40000000000293,31.933392074861132,2.034532719248969,-0.3110904280550164
258.600000000003,32.048742826231674,2.123687754322141,-0.3248139575548321
259.80000000000297,32.163914790248654,2.2055272182192485,-0.33725694397972195
261.00000000000296,32.27896286981671,2.2925602111527184,-0.35160961229397625
262.200000000003,32.39510913753257,2.3831160462195498,-0.36444723845353133
263.40000000000305,32.510072853434146,2.4692574383295764,-0.3800475516144495
264.60000000000304,32.62519583681259,2.5603345373516135,-0.39507518333300107
265.800000000003,32.739740611759274,2.6497950276841062,-0.4085488752333153
267.00000000000307,32.856325651081036,2.7442677735733825,-0.42728390301129826
268.2000000000031,32.97236942039927,2.8401538761341856,-0.4440682077417373
269.4000000000031,33.08686338033366,2.9333490140085905,-0.46248884978925586
270.6000000000031,33.19977960127847,3.026486343867722,-0.4796624682191011
271.80000000000314,33.316852926874326,3.1248655718375566,-0.4992528937977463
273.0000000000032,33.43242436183035,3.225112263029782,-0.5204994660562017
274.2000000000032,33.547780200389504,3.3212946982955662,-0.5406079742516638
275.40000000000316,33.66408024996627,3.420526943214452,-0.5621636619899539
276.6000000000032,33.77938514861501,3.5135046334476097,-0.5890418740401642
277.80000000000325,33.89601127580935,3.606868137267362,-0.6101988875080919
279.00000000000324,34.01147437175387,3.687036885430717,-0.6357702476926725
280.20000000000323,34.12614069462261,3.7622223296060437,-0.6618736351981767
281.4000000000033,34.24240676801774,3.82432483532662,-0.6878708122013979
282.6000000000033,34.35705236514782,3.8647552895832575,-0.7137906909364404
283.8000000000033,34.47266896738471,3.877882943245549,-0.742242880463921
285.0000000000033,34.58782353957214,3.847747298413295,-0.7714175005547395
286.20000000000334,34.70361392162,3.7528665239312486,-0.7965178876003343
287.4000000000034,34.81766362319045,3.565650707375123,-0.822660927294506
288.6000000000034,34.93135129379001,3.2416803227802014,-0.8471350916900007
289.80000000000337,35.04536651671019,2.730882947994963,-0.8713420286477787
291.0000000000034,35.156766882289475,2.132110370685344,-0.8886704920611512
292.20000000000346,35.26846319150477,1.6617728302830623,-0.9063545299093292
293.40000000000344,35.378316604510324,1.376267107615222,-0.9186981547924771
294.60000000000343,35.49153327201442,1.2038523955660114,-0.932969951240993
295.8000000000035,35.60265896883636,1.103195852860851,-0.9473858845911223
297.0000000000035,35.71563447392142,1.0319982897858317,-0.9619665577388252
298.2000000000035,35.82944845432369,0.9838931344281575,-0.9765570070820426
299.4000000000035,35.94159396188859,0.9425485399005138,-0.9907245275406837
300.60000000000355,36.054369625675854,0.904976423261693,-1.0040051093170734
301.8000000000036,36.166365068465126,0.8729263661498569,-1.0151355029550717
303.0000000000036,36.281470195769394,0.837614577291828,-1.0270025075431541
304.20000000000357,36.39462003267496,0.8073777512909031,-1.038039463513683
305.4000000000036,36.50882403365294,0.7749342946879623,-1.048724716663175
306.60000000000366,36.62267691827681,0.744290382501835,-1.0591273244064472
307.80000000000365,36.73578357470124,0.7193411849039852,-1.0672153492478977
309.00000000000364,36.850266430170585,0.6907007700015778,-1.0767414286487798
310.2000000000037,36.96398238094317,0.6684920334569058,-1.0838364431156386
311.40000000000373,37.077927956579465,0.6479675922000316,-1.091515699651326
312.6000000000037,37.19132235091396,0.630571681938004,-1.1002484890153736
313.8000000000037,37.30581512905705,0.6166903191949454,-1.1020315209290263
315.00000000000375,37.41975106911467,0.6043231709880577,-1.1087061753097398
316.2000000000038,37.53435937749765,0.5931574314183439,-1.11629697447822
317.4000000000038,37.64927197445165,0.5864316719407574,-1.120568492355635
318.6000000000038,37.76407464510195,0.5800506876422027,-1.1268924799283697
319.8000000000038,37.87763048437711,0.5765642603918771,-1.1332228823155472
321.00000000000387,37.993116540258164,0.5742023418244492,-1.138499362721125
322.20000000000385,38.10724318832674,0.5715805927588168,-1.145951884482253
323.40000000000384,38.22235876134524,0.5694830913869319,-1.1503199135803701
324.6000000000039,38.337459187649685,0.5699364822979078,-1.1553393112193446
325.80000000000393,38.4525573898467,0.5718128543494012,-1.1635207523128153
327.0000000000039,38.56667587745618,0.5702205341680864,-1.1699313000999219
328.2000000000039,38.68331311438352,0.5737118496949603,-1.176573013245156
329.40000000000396,38.798281341916145,0.5745014852943323,-1.1825402227873196
330.600000000004,38.913385223494025,0.5748782427041389,-1.1901861244156406
331.800000000004,39.028892022858685,0.5779334817797284,-1.1970789999561982
333.000000000004,39.143891131196845,0.5801585393203931,-1.2027398317654314
334.200000000004,39.2594536504838,0.5814283256301107,-1.209701131366666
335.40000000000407,39.37517750954176,0.5827401523331817,-1.2177891188530001
336.60000000000406,39.49084538251651,0.5828529041188276,-1.225307548439631
337.80000000000405,39.606383674718494,0.5851687983985648,-1.232444631703141
339.0000000000041,39.722652048364516,0.5893446037968242,-1.2404407773831472
340.20000000000414,39.83807666405342,0.5912149766727371,-1.2491456719458083
341.4000000000041,39.95282094573485,0.5957809140553059,-1.256352673344019
342.6000000000041,40.06830083758648,0.5996448152037855,-1.2649785343540256
343.80000000000416,40.18475572081152,0.603623630157469,-1.2711365182921797
345.0000000000042,40.300459762733624,0.6062879077858111,-1.2817730140181811
346.2000000000042,40.41518473188089,0.6087887890341842,-1.2901064174096901
347.4000000000042,40.53034473687089,0.6129481251709233,-1.2985678111162775
348.60000000000423,40.646632912576315,0.6153304694127066,-1.3088643455952544
349.8000000000043,40.76199889015177,0.6181435081126854,-1.3186404679845625
351.00000000000426,40.87828287804529,0.6217933713549687,-1.3279318861044844
352.20000000000425,40.99313429044747,0.6267009902828309,-1.33810795919076
353.4000000000043,41.10848527356861,0.6315106611188586,-1.3481980649746657
354.60000000000434,41.22410062566622,0.6388069883647008,-1.3588335100591302
355.80000000000433,41.3407031643481,0.6415770527422562,-1.37004850379226
357.0000000000043,41.4567162863531,0.6454795894542211,-1.3794562294522845
358.20000000000437,41.57406687760746,0.654145051069369,-1.3905660990988262
359.4000000000044,41.689367344603106,0.6591282911902169,-1.4023833243576909
360.6000000000044,41.806698185113454,0.6646441221089978,-1.41535710949309
361.8000000000044,41.92324646059351,0.6710507608454462,-1.4297998628283932
363.00000000000443,42.03847153717574,0.6776666001563022,-1.4416124207443461
364.2000000000045,42.154004103806955,0.6840217953794345,-1.4536623349954643
365.40000000000447,42.270410309943806,0.6894004505003133,-1.4686895728256673
366.60000000000446,42.386690949686496,0.6946277023368292,-1.4794147119178458
367.8000000000045,42.50218271300391,0.701222513433101,-1.4933132701771878
369.00000000000455,42.61945311953027,0.7096491396021961,-1.5085724172525499
370.20000000000454,42.73497299042272,0.7152044394184301,-1.523121083443887
371.4000000000045,42.85190112307434,0.7223153588319834,-1.539395226806302
372.60000000000457,42.96704479972863,0.7292820243748521,-1.55380491167488
373.8000000000046,43.08325276030214,0.7349801063713534,-1.5690528429293096
375.0000000000046,43.19954791592144,0.7378447001801788,-1.5856460137293427
376.2000000000046,43.31587927851192,0.7409742852030871,-1.6036975589018083
377.40000000000464,43.43223422276621,0.7436356976778535,-1.6199215438437502
378.6000000000047,43.549438746726196,0.7458515384062744,-1.6372312776215354
379.8000000000047,43.66606607709246,0.7457051635460903,-1.6538934179996838
381.00000000000466,43.781199546778126,0.7471695023246859,-1.6686361151841909
382.2000000000047,43.895852026238344,0.7456258883338998,-1.6863994688170099
383.40000000000475,44.01384917141214,0.7412902484188758,-1.7041358307864094
384.60000000000474,44.1301471477507,0.7388867863313864,-1.7211643362322246
385.80000000000473,44.246630165102935,0.7371191185638973,-1.7388707619941965
387.0000000000048,44.36206923474327,0.7324505212767121,-1.7566126910865836
388.2000000000048,44.48020580517931,0.7265892537248295,-1.773450771752282
389.4000000000048,44.59574437791868,0.7199170433556181,-1.7912122440854072
390.6000000000048,44.71221500102738,0.7095243907346332,-1.808027541858527
391.80000000000484,44.829068235199536,0.699238716953726,-1.8248106115742266
393.0000000000049,44.94467516935059,0.6904191957785308,-1.8435736128675555
394.2000000000049,45.06177793940253,0.6761833709444676,-1.8588540084337777
395.40000000000487,45.17738480466244,0.6619268383543259,-1.8759449796275738
396.6000000000049,45.29362383328717,0.6501034244302083,-1.8913222452723217
397.80000000000496,45.40981573138763,0.6341517906567058,-1.9058896378880115
399.00000000000495,45.526572042244645,0.6175484941842154,-1.9227421963758884
400.20000000000493,45.64396835798992,0.6000558165838963,-1.9362701985524402
401.400000000005,45.75965541293446,0.5811578649478821,-1.9506944319334467
402.600000000005,45.876517132015266,0.5633019899523348,-1.9636745301131517
403.800000000005,45.993595806566226,0.5456373700821847,-1.9770854144481853
405.000000000005,46.1092731055759,0.5269006361936098,-1.989281575374045
406.20000000000505,46.22616562756168,0.5113333441832036,-2.0007022925372446
407.4000000000051,46.34275887219397,0.491862540229586,-2.0118004121766853
408.6000000000051,46.458703924364976,0.47483739661312135,-2.022360768898534
409.80000000000507,46.57614345726871,0.4572042429347203,-2.032828033591519
411.0000000000051,46.69213536747919,0.44132434170420826,-2.0404799184338662
412.20000000000516,46.808820327024534,0.4228228047890619,-2.0487731943647765
413.40000000000515,46.925403988448416,0.4064181655944803,-2.05889813172975
414.60000000000514,47.040138251144,0.39163156171273233,-2.065387932236942
415.8000000000052,47.157303695931866,0.3773526089819066,-2.072100578444073
417.00000000000523,47.275362736135904,0.36270593910286575,-2.0785831075533583
418.2000000000052,47.39340603973962,0.34991184189233965,-2.084784617082719
419.4000000000052,47.509448063798615,0.3370767235113774,-2.0891814247677605
420.60000000000525,47.62698861223605,0.32554044724411246,-2.095070873292522
421.8000000000053,47.744162592978924,0.31458762074833335,-2.0998571114610423
423.0000000000053,47.86194210293803,0.30390439853008,-2.104025014459887
424.2000000000053,47.978173619953026,0.29504262686632526,-2.1081577336741204
425.4000000000053,48.09556764419337,0.28642843345890723,-2.1109613266476055
426.60000000000537,48.21116558671391,0.2792827236057972,-2.1142250604140918
427.80000000000535,48.3275074112902,0.27336075672392696,-2.1186298879160583
429.00000000000534,48.44698202573212,0.26752373554471826,-2.122240255561187
430.2000000000054,48.563799005393975,0.26338140738120547,-2.124929246269298
431.40000000000543,48.68115527560315,0.25860648206944226,-2.1275755827310574
432.6000000000054,48.79957956758447,0.25517968438411637,-2.1302380516810997
433.8000000000054,48.91741229523532,0.2517533303947089,-2.131659417328853
435.00000000000546,49.033783947284824,0.24701141251480851,-2.13259420434896
436.2000000000055,49.150116079014126,0.2456125474605769,-2.135321646069948
437.4000000000055,49.26772893538515,0.2424735873185961,-2.136606327727144
438.6000000000055,49.38448831232578,0.24064435133487994,-2.140308293424881
439.8000000000055,49.5027060705128,0.24013314954820103,-2.141873998503196
441.00000000000557,49.61926699290542,0.23804275089685328,-2.1431955334796955
442.20000000000556,49.7346832863164,0.2371547442603592,-2.144445197515002
443.40000000000555,49.85447031117404,0.2335572136809039,-2.1495556691939086
444.6000000000056,49.97244492614519,0.23424408952220135,-2.149567231965032
445.80000000000564,50.088554989253865,0.23221250325804876,-2.150878348860563
447.0000000000056,50.2053390768176,0.23127122745989065,-2.1534988228486913
448.2000000000056,50.323599277032905,0.23190169295033541,-2.1535232123507813
449.40000000000566,50.440370930443784,0.23174010077791657,-2.15351031116841
450.6000000000057,50.55834460568921,0.23003323561015276,-2.152117335345025
451.8000000000057,50.67617727513699,0.22892721352645465,-2.1568256590462855
453.0000000000057,50.79386091861569,0.22926119088489277,-2.158332294624779
454.20000000000573,50.91118032984437,0.22954980797220811,-2.158345496308984
455.4000000000058,51.0295930260648,0.2294182067596201,-2.1596445833545537
456.60000000000576,51.14721076980261,0.22814910119577037,-2.162246237029909
457.80000000000575,51.26358563710295,0.22690689553218452,-2.1649269395234287
459.0000000000058,51.384327356589054,0.22394031458921107,-2.163624115243747
460.20000000000584,51.5002511247318,0.22489695993627506,-2.1662423767186603
461.40000000000583,51.6168793293301,0.22467117307275566,-2.168540664999261
462.6000000000058,51.73711026133651,0.225847830144623,-2.1713226186456884
463.80000000000587,51.854702879338554,0.22488072786045485,-2.1729129822910602
465.0000000000059,51.97294945314906,0.22505971788146667,-2.171525058819576
466.2000000000059,52.08946384097678,0.22421730678747145,-2.1741658243701107
467.4000000000059,52.20738971480065,0.22489825525818635,-2.1746564654671285
468.60000000000593,52.324050727453326,0.22569194898688852,-2.1767816328854335
469.800000000006,52.44291449900737,0.22761397224543042,-2.1781019134270334
471.00000000000597,52.56062562845781,0.228255763355837,-2.1794725012119867
472.20000000000596,52.67927583165775,0.2268290178597451,-2.182056283861362
473.400000000006,52.79610721706044,0.22839886214092542,-2.1833980774914545
474.60000000000605,52.913298206823804,0.22986676504956524,-2.1846800642866437
475.80000000000604,53.03201024130726,0.22978810890876175,-2.1861051958712103
477.000000000006,53.14850404414878,0.22721309381711258,-2.187317037602683
478.20000000000607,53.26666228547278,0.2279943687504171,-2.1886619884649265
479.4000000000061,53.38443569768518,0.22780450139149427,-2.19002826363713
480.6000000000061,53.502718215073216,0.23051728589419054,-2.19128957191771
481.8000000000061,53.620703832676284,0.23031521228314666,-2.1920523807673327
483.00000000000614,53.736652919378315,0.22953699315712206,-2.1955513705496754
484.2000000000062,53.85620486467354,0.23045116935790994,-2.1955434022458045
485.4000000000062,53.97206344660003,0.23145495361306057,-2.196871009905305
486.60000000000616,54.0909245064409,0.22861878439464217,-2.198189783009453
487.8000000000062,54.210706361056815,0.2285910293266251,-2.1995000245641116
489.00000000000625,54.32688941402061,0.22801376783789207,-2.2020583586658975
490.20000000000624,54.44554376554568,0.2299582174765071,-2.2025032010499137
491.40000000000623,54.56349590078206,0.2314390079678853,-2.203789881452091
492.6000000000063,54.6824699577714,0.2307314355184061,-2.204795300943376
493.8000000000063,54.79985833230393,0.23342486242078503,-2.2067496836294294
495.0000000000063,54.91623183402304,0.2334736503478668,-2.208058721198503
496.2000000000063,55.03549578837911,0.23208214316921416,-2.209285259960766
497.40000000000634,55.15277867102505,0.23480753594012682,-2.209389323080939
498.6000000000064,55.27222088008417,0.23209695066688493,-2.211410100015989
499.8000000000064,55.38997783338068,0.23545360014854497,-2.2133544014253044
501.00000000000637,55.508521371440864,0.23357027851269813,-2.2159638213905106
502.2000000000064,55.62621457519805,0.232462103955031,-2.214680116994799
503.40000000000646,55.74444067860831,0.23468633898303834,-2.2164613533586506
504.60000000000645,55.86362636041815,0.23435787957502355,-2.2173148912802043
505.80000000000643,55.981496323620426,0.23225576164264766,-2.219986017485766
507.0000000000065,56.09984520413948,0.2321978588505562,-2.2199298783335655
508.2000000000065,56.218217327452365,0.2337284449648686,-2.2212566620050977
509.4000000000065,56.337466447076245,0.23290933803588534,-2.2238811116866164
510.6000000000065,56.45543376877396,0.2319982929020449,-2.2252005791000107
511.80000000000655,56.57466495981605,0.23080656678309616,-2.226520180467606
513.0000000000066,56.6927743827078,0.2302336257250822,-2.2278284409281555
514.2000000000066,56.811633123536666,0.22903951091059668,-2.229164982472156
515.4000000000066,56.92936400329114,0.22799357239047874,-2.228994360804906
516.6000000000066,57.04820106330085,0.22864273989204484,-2.2303583283332413
517.8000000000067,57.16707411554482,0.2262249197371593,-2.2315665026007676
519.0000000000066,57.28517946371478,0.2264017396685356,-2.235300181287018
520.2000000000066,57.40398154174424,0.22562861677044332,-2.235629953215989
521.4000000000067,57.52255350904821,0.2258306908874272,-2.2359513163509117
522.6000000000067,57.64169342308963,0.2268003039044251,-2.237270105830839
523.8000000000068,57.760217740678016,0.225846819695799,-2.2379566000508575
525.0000000000067,57.87777396412732,0.2270181407918393,-2.2395808795116325
526.2000000000068,57.99620174196,0.2246797702831213,-2.242353303658774
527.4000000000068,58.114006642412164,0.2251631403628609,-2.2449553260168837
528.6000000000067,58.23395336967647,0.22302913567788968,-2.244450255942822
529.8000000000068,58.352719353795024,0.22404278038549744,-2.2457865558447074
531.0000000000068,58.471850120985806,0.22277845818629563,-2.2461121744598675
532.2000000000069,58.590260978646434,0.22341204739969728,-2.2461550606053327
533.4000000000069,58.708698746568864,0.22590794557606006,-2.247412120214288
534.6000000000068,58.828390820605755,0.2246291728384534,-2.250079444196814
535.8000000000069,58.945325794126866,0.22403397559339894,-2.2500556377854437
537.0000000000069,59.06665991450626,0.22185057891269222,-2.252753313394196
538.2000000000069,59.18499479274568,0.22059755680577342,-2.2540762963277983
539.4000000000069,59.303536717083134,0.2190028175871849,-2.2554446356314943
540.600000000007,59.4233440330418,0.21609199431687431,-2.255010593446484
541.800000000007,59.54020081143006,0.21364100069957764,-2.257028770241767
543.000000000007,59.658563052280414,0.21314240299800435,-2.259343672670855
544.200000000007,59.778067441822756,0.21190259274398868,-2.260650588274478
545.400000000007,59.897318881558114,0.21171366203511896,-2.2616429252811354
546.6000000000071,60.01620608297362,0.21282733754008654,-2.2633327506537224
547.800000000007,60.13635792318702,0.21159277935445414,-2.263429127750272
549.000000000007,60.25516517608871,0.21864436330497322,-2.2633997552925305
550.2000000000071,60.37326050592006,0.2228845136203957,-2.266101904165641
551.4000000000071,60.49172237809234,0.22212881200779555,-2.2686874959443855
552.6000000000072,60.60965561151439,0.2246146066639922,-2.2674233149100718
553.8000000000071,60.727740605676765,0.22705106910662046,-2.2673444442245385
555.0000000000072,60.847323291116275,0.2286640715385072,-2.269910427717563
556.2000000000072,60.966013022200045,0.2297440957285544,-2.269983930495642
557.4000000000071,61.084028463099244,0.229801000821689,-2.271309958261381
558.6000000000072,61.20313138820607,0.2319935221819351,-2.2726097886976424
559.8000000000072,61.322627573481455,0.23158415653501818,-2.2752605855132195
561.0000000000073,61.44024201063967,0.2290592268791916,-2.274018331406818
562.2000000000073,61.55916901131589,0.2245400945092692,-2.2752599303574454
563.4000000000073,61.678876935032676,0.22468039694986322,-2.276624145293601
564.6000000000073,61.797619137989074,0.2213175345734431,-2.2769001913768623
565.8000000000073,61.917388053587665,0.22227469104939074,-2.2771954173141253
567.0000000000073,62.035781590530405,0.21898677636469804,-2.2795346895767445
568.2000000000073,62.15399587241385,0.21464074314421594,-2.279983327980392
569.4000000000074,62.27402955572522,0.21350913757510243,-2.2808601573401353
570.6000000000074,62.39283392012464,0.21117212702953045,-2.2808601714359655
571.8000000000075,62.51141788409673,0.20790091951401798,-2.2821699484708757
573.0000000000074,62.63094936939678,0.20593795061477338,-2.284809314560488
574.2000000000074,62.748089919420764,0.2052575434806617,-2.2834803240079617
575.4000000000075,62.86936900621257,0.1982249045726784,-2.283467829856196
576.6000000000074,62.987652904130535,0.19564961376301776,-2.2821490229928663
577.8000000000075,63.10579689357434,0.18941394501601452,-2.2835011030758636
579.0000000000075,63.225704320356726,0.18711313325789783,-2.2861481683708567
580.2000000000075,63.34565361154176,0.18135898141657997,-2.287209917901081
581.4000000000076,63.46462496341341,0.1758605431506275,-2.2869960870300945
582.6000000000075,63.584054089458085,0.17151708378896902,-2.2887573513105743
583.8000000000076,63.70301326485144,0.16910842781206503,-2.2874501203162887
585.0000000000076,63.82250224070607,0.1652455078703591,-2.2877801343917272
586.2000000000075,63.941702078451264,0.16063702188326992,-2.2890536868638556
587.4000000000076,64.06034085504754,0.15626122094005876,-2.290400292428606
588.6000000000076,64.18036433244549,0.15213870262871343,-2.291390035801723
589.8000000000077,64.30074423045636,0.149048918463921,-2.290420921950206
591.0000000000077,64.41907587817626,0.14281314094920866,-2.293037624651147
592.2000000000077,64.53907514904338,0.1376901955573424,-2.293039915666859
593.4000000000077,64.65750507439003,0.1338286257185915,-2.2929810091935856
594.6000000000078,64.77730496370218,0.13006729376472786,-2.293061777894007
595.8000000000077,64.89689637473539,0.12731835448848125,-2.2930368219972754
597.0000000000077,65.01673684705236,0.12275688351342884,-2.293040428543911
598.2000000000078,65.13549277868816,0.11942514548146427,-2.295370976702225
599.4000000000078,65.25587312252398,0.11647710736675437,-2.295018197968925
600.6000000000079,65.3744775542756,0.11635096788438504,-2.2956802170715522
601.8000000000078,65.49478848315489,0.11462093893428715,-2.2956802064551836
603.0000000000078,65.6130319706026,0.11231134694890993,-2.2969973520075166
604.2000000000079,65.73359243470443,0.11082839809284592,-2.295667983733355
605.4000000000078,65.85360673688304,0.1073056340249032,-2.2982861210754266
606.6000000000079,65.97271962713931,0.10447374546878438,-2.2992649398095724
607.8000000000079,66.09239300276657,0.1022506701597597,-2.2987768944173403
609.000000000008,66.21150675913344,0.10164404290517906,-2.2982858778623254
610.200000000008,66.3313810292282,0.10164219889701986,-2.299569432428367
611.4000000000079,66.45070675693536,0.10079968388717625,-2.2992999480119574
612.600000000008,66.57103385783105,0.09979264789590381,-2.2993097958328717
613.800000000008,66.68991504184632,0.09625961531821858,-2.2992990057575815
615.000000000008,66.80978598545587,0.09853586401657422,-2.299620266400301
616.200000000008,66.92907599010378,0.09948360532561032,-2.301929599989492
617.400000000008,67.04815641330377,0.0992823304234377,-2.3002894480452003
618.6000000000081,67.16840825597649,0.10066251522875244,-2.300290312877246
619.8000000000081,67.28744007088531,0.09971661605274085,-2.3016098514862495
621.0000000000081,67.40578499561084,0.10468363222801827,-2.3016317269852924
622.2000000000081,67.52657827866578,0.10335157881418194,-2.3029301565818274
623.4000000000082,67.64531098596127,0.10547936045078771,-2.3029301285612336
624.6000000000081,67.76376720864725,0.10778660633598669,-2.303589938374379
625.8000000000081,67.88390331926108,0.1112574857025615,-2.3029150829668037
627.0000000000082,68.004052161445,0.11241266392437113,-2.3042399162371554
628.2000000000082,68.12269455867464,0.11521305769203152,-2.305617136267781
629.4000000000083,68.24246773194079,0.11598316940715359,-2.3043100108232304
630.6000000000082,68.35917221033725,0.12118645929796862,-2.303249924016963
631.8000000000083,68.4788742010085,0.12154424785403281,-2.3045701802677097
633.0000000000083,68.60137826127621,0.1250966220794073,-2.304900075664435
634.2000000000082,68.72076653585836,0.12790277431086639,-2.304900008908906
635.4000000000083,68.84056213865368,0.13053172693063972,-2.3062200297298032
636.6000000000083,68.96019736379777,0.13112632842447716,-2.3062073285504923
637.8000000000084,69.07927497684544,0.12769573871445167,-2.3075303808458187
639.0000000000084,69.19853500744708,0.12736412290082172,-2.3068775589386803
640.2000000000083,69.31777681988922,0.12700050733734886,-2.3063283262115815
641.4000000000084,69.43768024790572,0.12798236605300423,-2.306550325911809
642.6000000000084,69.55753749828213,0.1345279785630128,-2.307559923527343
643.8000000000084,69.67813504313096,0.13156348330466325,-2.3052299542110197
645.0000000000084,69.79777819481033,0.1357082688771451,-2.3052271162267663
646.2000000000085,69.91797714914811,0.1353894020979945,-2.306541405189557
647.4000000000085,70.03554795949624,0.13625476000246833,-2.3065398540007456
648.6000000000085,70.1566712258644,0.13457466506397012,-2.3065398530247676
649.8000000000085,70.27715364775572,0.13140194677960945,-2.307853161699903
651.0000000000085,70.39583498152297,0.1324008052749196,-2.307860165998611
652.2000000000086,70.51748515630689,0.1308897473564056,-2.3078602011408424
653.4000000000085,70.63707156100506,0.1322589100035096,-2.3082015651498358
654.6000000000085,70.7571752475255,0.12882094588528023,-2.3091800722217215
655.8000000000086,70.87630543094399,0.1274831603741708,-2.3091673759870575
657.0000000000086,70.997028668355,0.12859227312340568,-2.309179219225393
658.2000000000087,71.1162754606603,0.1296152932612598,-2.3098398197328964
659.4000000000086,71.23625520524989,0.12501804579436093,-2.3085202240865432
660.6000000000087,71.35502036032076,0.12546699719603577,-2.3096271380922357
661.8000000000087,71.47744071167995,0.12908807579897932,-2.309845497726264
663.0000000000086,71.59777278370281,0.12792311926168187,-2.3090752795956364
664.2000000000087,71.71702310747128,0.12495854580299057,-2.310804612355974
665.4000000000087,71.83438068097122,0.12636416579657586,-2.309510045537879
666.6000000000088,71.95547626460448,0.1257184965886193,-2.311638289949311
667.8000000000088,72.07586163530229,0.12617959478169535,-2.311822603834301
669.0000000000088,72.19569468118806,0.1276848790269498,-2.3117796693118913
670.2000000000088,72.3153118114547,0.12944142590124352,-2.3127969733749514
671.4000000000088,72.43678682991869,0.12953217161593442,-2.3121401143586144
672.6000000000088,72.55617630119343,0.12908259790623938,-2.311468122864417
673.8000000000088,72.67761948402818,0.1308888597838822,-2.3124521823723874
675.0000000000089,72.79720023629959,0.1293255978908411,-2.311162035770382
676.2000000000089,72.91679343269098,0.12790551374357226,-2.3116171274111466
677.400000000009,73.0375706308867,0.12533768933996037,-2.312470098122313
678.6000000000089,73.15768249029408,0.12612104836333962,-2.311426711735189
679.8000000000089,73.27760423532754,0.12796343755151537,-2.3111257418637443
681.000000000009,73.39775886562781,0.12542330980146946,-2.3118200442542918
682.2000000000089,73.51798859868546,0.1258008107908379,-2.311820004002257
683.400000000009,73.63662875024905,0.12693231213155376,-2.3118448913918765
684.600000000009,73.75710812258268,0.12777128686338396,-2.313130165908001
685.800000000009,73.87653216693245,0.1343152111561853,-2.314234501167804
687.0000000000091,73.99678159144699,0.1370959229776597,-2.3144542515042485
688.200000000009,74.11807350661479,0.13835485795200242,-2.313103102005714
689.4000000000091,74.23675130803497,0.13756708831579043,-2.312470086137546
690.6000000000091,74.35665637116016,0.1406434113226105,-2.312470071951605
691.800000000009,74.47604926329974,0.14241378139310001,-2.311949975201931
693.0000000000091,74.59583481659455,0.14413797162448827,-2.313130195287072
694.2000000000091,74.71706338381516,0.14142014827141874,-2.3133863154075507
695.4000000000092,74.83687315815109,0.14414924821002664,-2.313459977974481
696.6000000000092,74.95687464757401,0.14910870332418996,-2.314610554593263
697.8000000000092,75.07719629489628,0.14807144167384176,-2.3134698849563664
699.0000000000092,75.19822831543365,0.149163929493378,-2.31343033870424
700.2000000000093,75.31736778249461,0.15089952002034202,-2.3157477206705392
701.4000000000092,75.43790511398913,0.1515391347765264,-2.313471113851247
702.6000000000092,75.55808644961259,0.15440175675377665,-2.3147829256846384
703.8000000000093,75.67817789542563,0.15556470735588868,-2.3127856585834237
705.0000000000093,75.79907886230738,0.15940029418768537,-2.312799967990734
706.2000000000094,75.9201998512537,0.15986103265807244,-2.3141294362047686
707.4000000000093,76.03988268092154,0.166648933592029,-2.315104660031215
708.6000000000093,76.159868719579,0.1684736864879945,-2.3151101083286116
709.8000000000094,76.28011496149492,0.17191265913201173,-2.3141166204522396
711.0000000000093,76.40038252639062,0.17937831412182856,-2.314431267860548
712.2000000000094,76.52155031856844,0.1809351383368074,-2.314113383903786
713.4000000000094,76.6413061656617,0.18120924110397388,-2.314138494616059
714.6000000000095,76.76158734661882,0.18185266791993002,-2.3145477915565973
715.8000000000095,76.8817963796476,0.18683005340926592,-2.314120092039826
717.0000000000094,77.00057952784239,0.19238712945963352,-2.3141458959503756
718.2000000000095,77.12195651089735,0.19293482011671517,-2.3147813253225302
719.4000000000095,77.24303606627538,0.1946029359093408,-2.314978815812425
720.6000000000095,77.36339706087364,0.1967043810651557,-2.319600825895237
721.8000000000095,77.48408116006527,0.198215981841077,-2.3163762076756367
723.0000000000095,77.60363221161714,0.200161413065869,-2.3152192710756627
724.2000000000096,77.72382536317741,0.20348716920804374,-2.3152201326921045
725.4000000000096,77.84455709248886,0.20011012384396215,-2.3142298500545144
726.6000000000096,77.96426822837195,0.19836669925746828,-2.315879247290718
727.8000000000096,78.08521178846838,0.196076909611946,-2.3168702521503852
729.0000000000097,78.20475748968616,0.20117990032209696,-2.316870038069535
730.2000000000096,78.32607534167995,0.20329636935736653,-2.3168699720002643
731.4000000000096,78.4467050850378,0.1993258130976353,-2.316871829830159
732.6000000000097,78.56689953112226,0.1983194308393234,-2.3164992212331934
733.8000000000097,78.68706798332391,0.2038070236218888,-2.31686011370348
735.0000000000098,78.80717180632229,0.20518780806847742,-2.316860134267002
736.2000000000097,78.92666813105484,0.20790620671244261,-2.3124226491025297
737.4000000000098,79.04741160739893,0.20958927873036115,-2.3155500591748943
738.6000000000098,79.16926957822123,0.20723015025851227,-2.315903163892058
739.8000000000097,79.28917104524379,0.20439547701168584,-2.315880039904472
741.0000000000098,79.40907068429773,0.20735082685463663,-2.3171999465155246
742.2000000000098,79.53029603242132,0.2059022615686542,-2.317199910932005
743.4000000000099,79.65089280746022,0.20305863720526746,-2.316206839876945
744.6000000000099,79.77112899255643,0.20407488111358454,-2.317205461616968
745.8000000000098,79.89226898561076,0.1998875064646928,-2.317144095735178
747.0000000000099,80.01152002177308,0.19496084236310093,-2.3177178387881834
748.2000000000099,80.13249882012514,0.18823873732526702,-2.3175193784252692
749.4000000000099,80.25362537915505,0.19645940473409265,-2.317190016801768
750.6000000000099,80.37416105926135,0.19617938445316344,-2.3172042869957257
751.80000000001,80.49492339133195,0.19618187674178608,-2.31751983649707
753.00000000001,80.61528880144174,0.19855480429522607,-2.3175199199999907
754.20000000001,80.73655610457762,0.19573818773755905,-2.3175199200000005
755.40000000001,80.85523126025845,0.19461784413194366,-2.3175199199999934
756.60000000001,80.97746131050876,0.19117037975150747,-2.3175198858937147
757.8000000000101,81.09865144989288,0.18874152382522186,-2.318509837620649
759.00000000001,81.21815384892577,0.1846011224253536,-2.3158767621710648
760.20000000001,81.33948809805341,0.17695630091249487,-2.3171998271604615
761.4000000000101,81.4596853251089,0.1756939182177903,-2.315880439082049
762.6000000000101,81.5796687993891,0.1667418181499691,-2.317568214289401
763.8000000000102,81.70021607732694,0.15325814099899726,-2.3175301669218342
765.0000000000101,81.81978655947131,0.1486081053388721,-2.316207410973197
766.2000000000102,81.93983005302822,0.14661467859450972,-2.3168601692160706
767.4000000000102,82.05937692295929,0.1359743553240183,-2.317520171865997
768.6000000000101,82.17887442437652,0.13141699516245525,-2.3161881323633446
769.8000000000102,82.29959405792036,0.12627597385562145,-2.3168747344937732
771.0000000000102,82.41947072134792,0.11885328922170041,-2.3169878401204778
772.2000000000103,82.54082108996549,0.1159749356900085,-2.3168698000089547
773.4000000000103,82.66089230086229,0.1076791909405625,-2.3168683888524013
774.6000000000103,82.78019048177383,0.10194723757121055,-2.317203232338355
775.8000000000103,82.90094852049734,0.09408982879596484,-2.3172001120001773
777.0000000000103,83.021926338794,0.08522964368440838,-2.3172001119999965
778.2000000000103,83.14108098843164,0.08005961531622668,-2.317200092464817
779.4000000000103,83.26121045442932,0.07507095599099506,-2.3182049979939614
780.6000000000104,83.38221484368495,0.06677485461275195,-2.3180430200032625
781.8000000000104,83.50322666481041,0.06187334705913228,-2.319200881121033
783.0000000000105,83.62478301634962,0.05480942530777455,-2.3181718348161136
784.2000000000104,83.74530490390082,0.05026156459714404,-2.3181834370330305
785.4000000000104,83.86525366402364,0.04572400191043652,-2.3168600590094623
786.6000000000105,83.98626708682067,0.03420653513396932,-2.318174140087004
787.8000000000104,84.10653215805115,0.023939885644889802,-2.318180086574729
789.0000000000105,84.22727919835587,0.015560702881560196,-2.3195388408087534
790.2000000000105,84.34730577811364,0.008332576319387108,-2.3181715933324294
791.4000000000106,84.46832932679648,0.0006271980231885577,-2.3181797845176515
792.6000000000106,84.58938065056921,-0.009225825126677356,-2.3178467560249123
793.8000000000105,84.70926979232279,-0.016666376375462255,-2.31917014800279
795.0000000000106,84.830515117451,-0.02283004457964627,-2.3192042623553526
796.0000000000106,84.9307267349707,-0.032670259971885274,-2.3188500562939103