File: 01_Data/Corian_Countertop/STA/N2/10K_min/Corian_Countertop_STA_N2_10KData_220921_R3.csv
##Temp./Â°C,Time/min,DSC/(mW/mg),Mass loss/mg
51.0,10.770602017854811,0.04586806800029852,0.013336488919503786
52.000000000000014,11.100876180278444,0.08273659874244377,0.013420460982458415
53.00000000000003,11.348005984481897,0.11394800655559623,0.01325769564189816
54.00000000000004,11.540855126809259,0.1360303136983647,0.01108232261705222
55.00000000000006,11.714567801468947,0.1548926807899329,0.013037745090985986
56.00000000000007,11.877981935741996,0.16911438993758443,0.01240468568721731
57.000000000000085,12.029426536479516,0.18007994797605353,0.013359720448967494
58.0000000000001,12.172431466477379,0.19094922896221633,0.012719748276878384
59.000000000000114,12.313790400576227,0.19901914610448457,0.013072657814813482
60.00000000000013,12.446951286420035,0.20701584098596992,0.012331878723398582
61.00000000000014,12.579152908406998,0.21298641440414046,0.01308134414717621
62.000000000000156,12.708997193533895,0.22060585553792644,0.011479987369730438
63.00000000000017,12.835929742131865,0.22505691704547748,0.01344296514918586
64.00000000000018,12.961134531634599,0.23152570437361386,0.012304573889785786
65.0000000000002,13.0844130545882,0.23729398296551696,0.01257921786145122
66.00000000000021,13.205883145681598,0.24114981266484814,0.012468873366013433
67.00000000000023,13.325756602503795,0.2476136575109631,0.012653255498371152
68.00000000000024,13.444403908382176,0.254269146620663,0.010360560991221845
69.00000000000026,13.560229568920128,0.2583925334401913,0.0134685531013643
70.00000000000027,13.677317009847545,0.2667035602014929,0.010985239058290297
71.00000000000028,13.793609365154177,0.26765812115512255,0.012339988550341019
72.0000000000003,13.907647763677248,0.2743743518951157,0.01178340418099566
73.00000000000031,14.021075806379445,0.2802278151696853,0.012121344630577902
74.00000000000033,14.133608395729468,0.2830803708952846,0.012290675166392262
75.00000000000034,14.243909522093665,0.2886365519408177,0.011075462409551484
76.00000000000036,14.3552349045313,0.29195487047496194,0.011094823046818192
77.00000000000037,14.465263638095463,0.2965857837602702,0.011106300672249603
78.00000000000038,14.573930193298818,0.30148355917785596,0.011157221822386987
79.0000000000004,14.683067720114488,0.3065374827820553,0.009836449168765249
80.00000000000041,14.790000000000045,0.30943294371195496,0.010646264475963285
81.00000000000043,14.899033158728047,0.314339759374641,0.00965560558793932
82.00000000000044,15.006716632684109,0.31550161691651213,0.010828429974048426
83.00000000000045,15.113073206261204,0.3183057403932128,0.01026258804414315
84.00000000000047,15.218588963161068,0.3215740434100849,0.01097468574836391
85.00000000000048,15.324014557721979,0.321281749778801,0.009514450494807924
86.0000000000005,15.42781153899577,0.3243452124403221,0.009670800227905119
87.00000000000051,15.533726250542244,0.3270763182420744,0.010969664537825885
88.00000000000053,15.637616695210015,0.3273318930734537,0.009800788787266868
89.00000000000054,15.739768215965848,0.33266251183443984,0.009077439093388762
90.00000000000055,15.842099962649955,0.33293643820349517,0.009660165771760099
91.00000000000057,15.945496561851078,0.33426991307988485,0.008490247741469226
92.00000000000058,16.04652189692415,0.3380259550396185,0.0069491079955019686
93.0000000000006,16.1480484188471,0.34337281816326437,0.008337632491849156
94.00000000000061,16.24587910677794,0.34464022219910506,0.008225841974891956
95.00000000000063,16.350106188900476,0.34839101025838004,0.008361654997750101
96.00000000000064,16.450579873492018,0.3521617770936647,0.007020142821009934
97.00000000000065,16.550192204324727,0.35395934737690893,0.0063882475044607645
98.00000000000067,16.649462856834106,0.35827325323718084,0.007410059736585595
99.00000000000068,16.75198622867037,0.3588875388896716,0.005695577749420089
100.0000000000007,16.850550122006265,0.3632467146006455,0.005761322772799282
101.00000000000071,16.95000000000007,0.36270171612751434,0.0056998938820997935
102.00000000000072,17.04915089764989,0.3651816296601348,0.005708011432639992
103.00000000000074,17.147754066852453,0.36809899664461965,0.005713633999003598
104.00000000000075,17.247733230047555,0.3715531859617547,0.005710754574610455
105.00000000000077,17.346230836709374,0.3727377086220858,0.004394902148976421
106.00000000000078,17.4438914695697,0.3760658083982584,0.004388435102534061
107.0000000000008,17.543618111389375,0.3784281697047752,0.0057111752820615536
108.00000000000081,17.641009399092976,0.38064741393204704,0.003050080655616405
109.00000000000082,17.73941327890043,0.382501574259014,0.004057968944129797
110.00000000000084,17.837532064299733,0.3851308543239548,0.003069350177508312
111.00000000000085,17.93536415490031,0.3876263164868692,0.003401592686350874
112.00000000000087,18.03079133534371,0.38940564816700163,0.0030757853162750592
113.00000000000088,18.131624751766182,0.3932284540075458,0.0017600296073148058
114.0000000000009,18.228048891470944,0.3935310592042407,0.0022952599050949374
115.00000000000091,18.327411534559225,0.39700736095091926,0.0014272097085736846
116.00000000000092,18.424883970174452,0.40063931402535025,0.00011047486735282774
117.00000000000094,18.52414217298267,0.4026922322870339,0.00011067564951705577
118.00000000000095,18.620000000000086,0.4072851257689051,-0.0008805239249083385
119.00000000000097,18.717133347420667,0.4094923320334758,0.00030382094881353794
120.00000000000098,18.813627084474792,0.41180114957512426,-0.0008800031449132106
121.000000000001,18.9095263495156,0.4152264041521998,-0.002195807485890988
122.00000000000101,19.007029543233333,0.4164835424928989,-0.0022000029943676225
123.00000000000102,19.106564963433176,0.41621523966085383,-0.002677451096912975
124.00000000000104,19.203687810443732,0.419642120526747,-0.0025056389286639558
125.00000000000105,19.301581129193227,0.42216421903136836,-0.003849826014739932
126.00000000000107,19.39843049920453,0.4232400456882762,-0.0038478371190988625
127.00000000000108,19.494679058266627,0.42384687067082016,-0.0031621299594108976
128.00000000000108,19.591802237767187,0.42563456302903746,-0.0035078506564500955
129.0000000000011,19.687704346206033,0.42751590016153795,-0.004829843198378647
130.00000000000114,19.784686430545303,0.42829071997873613,-0.005040516962451669
131.00000000000114,19.88155102854135,0.4300101195992615,-0.00483361210612987
132.00000000000114,19.977988970702075,0.43119152650168746,-0.006145653906411752
133.00000000000117,20.074614512402377,0.43390030462902274,-0.007459939333711141
134.0000000000012,20.16990143992865,0.4350354590604719,-0.008850776185399312
135.0000000000012,20.26452577160929,0.43584437680653954,-0.00845377645632972
136.0000000000012,20.360499088610606,0.44048916181005027,-0.010092517467362505
137.00000000000122,20.458087872197247,0.44159908219708843,-0.010408809259997653
138.00000000000125,20.55376555691914,0.4438186349644295,-0.010762120680589682
139.00000000000125,20.650493142772266,0.44530986316110355,-0.012040073352697078
140.00000000000125,20.745666681172853,0.4459773913793438,-0.01075619903443581
141.00000000000128,20.841382160124795,0.44945640705738543,-0.013059922216797304
142.0000000000013,20.936378749037292,0.4506913124027464,-0.013060001609897398
143.0000000000013,21.033091459929537,0.45306189411059794,-0.013902808100234587
144.0000000000013,21.128969671543608,0.45464312774233906,-0.013720836104909928
145.00000000000134,21.22355315579691,0.45654515294308134,-0.01437826633769923
146.00000000000136,21.319221183857206,0.45806650898783907,-0.01636055066522424
147.00000000000136,21.414752988395307,0.46091076978205325,-0.01669225890656101
148.00000000000136,21.51067669719089,0.4620231208337134,-0.01668388779890062
149.0000000000014,21.60574646099781,0.4665948025616647,-0.018087314346344918
150.00000000000142,21.701362363079042,0.4669586549358608,-0.01932016705423223
151.00000000000142,21.79754232114786,0.4700917981838549,-0.020531947364300862
152.00000000000142,21.892236696716058,0.4734113136725209,-0.020640168031038186
153.00000000000145,21.987331072595403,0.47628617126213635,-0.02063730637743788
154.00000000000148,22.08433285146667,0.48027578895308587,-0.023328710685852627
155.00000000000148,22.1790319911476,0.482449453122505,-0.02327999990918439
156.00000000000148,22.274105861422726,0.48395355830611064,-0.024596054143716906
157.0000000000015,22.370195030227507,0.4870510517612002,-0.02610909226859004
158.00000000000153,22.465324377807264,0.4887859355011462,-0.0272298178005137
159.00000000000153,22.561544753797673,0.49225321561731383,-0.02722966742901889
160.00000000000153,22.657362864212335,0.4968139582933671,-0.02854331269085364
161.00000000000156,22.75193029133878,0.5003737918754043,-0.029866433654494706
162.0000000000016,22.847121243465796,0.5054006547157421,-0.03250064232348615
163.0000000000016,22.941913006594227,0.5095167489066355,-0.03190487759396543
164.0000000000016,23.03712133315671,0.5129694968397049,-0.035773406661030016
165.00000000000162,23.131485491242785,0.5177602041946466,-0.03579017406327045
166.00000000000165,23.226537223531814,0.5210028789970144,-0.03841349967539731
167.00000000000165,23.322519904024478,0.525193327407645,-0.038421119503424084
168.00000000000165,23.416965478662764,0.529729206788615,-0.0397338999801784
169.00000000000168,23.51280916066865,0.5325720932919396,-0.04105885203828574
170.0000000000017,23.60628242740339,0.53981423331065,-0.041684163717968126
171.0000000000017,23.702048375990802,0.5433652215204143,-0.044823260723249714
172.0000000000017,23.796661191595902,0.5488723895381565,-0.046716087896877756
173.00000000000173,23.892621510716605,0.5542082594879665,-0.04899941189393031
174.00000000000176,23.986929387353968,0.5596182137184729,-0.049952476350081376
175.00000000000176,24.08271315993208,0.5646623919161626,-0.052560023650808585
176.00000000000176,24.177868309355084,0.5695219297113896,-0.05456211478186557
177.0000000000018,24.272966002323866,0.5732303802778236,-0.05600444786563408
178.00000000000182,24.367896391446717,0.5775588651445778,-0.0571998690536617
179.00000000000182,24.462562379287956,0.5823887376820086,-0.05888198116241794
180.00000000000182,24.556894642566302,0.5864728774194607,-0.06297701659819532
181.00000000000185,24.651878768677005,0.5906332918719999,-0.06442699640345317
182.00000000000188,24.746335811267603,0.5935688230883973,-0.06628088235428731
183.00000000000188,24.839635761232003,0.5960821588488174,-0.06970513336446782
184.00000000000188,24.93652508776109,0.5997822484776487,-0.07103788004552314
185.0000000000019,25.031585332966852,0.6020791433009769,-0.07367569651035666
186.00000000000193,25.126254221548816,0.6051244569524697,-0.07620980027928281
187.00000000000193,25.220753184464396,0.6077201684965288,-0.07833886407775292
188.00000000000193,25.316228913414662,0.6112281574486049,-0.08024762237574246
189.00000000000196,25.40979734303488,0.6130429946417436,-0.08295524029664003
190.000000000002,25.505292053369832,0.6179273002130601,-0.08468870363634018
191.000000000002,25.59953481110357,0.6191164639061251,-0.08813231629029605
192.000000000002,25.694748296243137,0.620565996639563,-0.08897659461689633
193.00000000000202,25.789489132157243,0.6236595158636494,-0.09041800384344345
194.00000000000205,25.884191911314367,0.6272383741069221,-0.09267085217430893
195.00000000000205,25.97929162690573,0.6307077519759442,-0.09605760600113289
196.00000000000205,26.07443536996177,0.632038599417237,-0.09727341369712406
197.00000000000207,26.166502945062806,0.6358498254784792,-0.1000854149808239
198.0000000000021,26.262900233769237,0.6374597840515238,-0.10133716772053036
199.0000000000021,26.35760785117759,0.6425243057590018,-0.10267271675153156
200.0000000000021,26.45195580347154,0.647139322314723,-0.10513126297816067
201.00000000000213,26.546620357490777,0.6521947443499451,-0.10660110631449626
202.00000000000216,26.641972331397547,0.6550124816317777,-0.10792104447352724
203.00000000000216,26.735828645557028,0.6591257633992175,-0.10923006882429531
204.00000000000216,26.831360514603826,0.6635238941404161,-0.11186820199692704
205.0000000000022,26.92531438247495,0.6677013213221236,-0.11318503182696249
206.00000000000222,27.020452469912613,0.6742398023147023,-0.11451124203437812
207.00000000000222,27.114675727969367,0.6802180957895034,-0.11583930265300202
208.00000000000222,27.211102843866687,0.6857286768517356,-0.11712860403850689
209.00000000000225,27.305751255986628,0.6932669096854496,-0.11978048446706246
210.00000000000227,27.400083202570915,0.6994992067493114,-0.12109016382734339
211.00000000000227,27.495348695764903,0.7051155429665652,-0.1233793655977955
212.00000000000227,27.5898167462432,0.7125737874379038,-0.12471968725951887
213.0000000000023,27.685320700844567,0.7208947385979876,-0.1264245863833806
214.00000000000233,27.779908105269804,0.7300334195175195,-0.12899697442094427
215.00000000000233,27.87483403258138,0.7389286307447182,-0.13030986527740485
216.00000000000233,27.968944441495974,0.7495092732473294,-0.13162724212760546
217.00000000000236,28.063716388711224,0.7591306132467541,-0.1342630092388033
218.0000000000024,28.15927693083622,0.77202307125392,-0.13821689318007335
219.0000000000024,28.25404549517274,0.7851846763606694,-0.13852054212913334
220.0000000000024,28.34684306729397,0.7952724293595056,-0.13985811733252795
221.00000000000242,28.442752387590893,0.8073044413416944,-0.14335061301779817
222.00000000000244,28.538278098615322,0.8196092075441311,-0.14535956672793704
223.00000000000244,28.63357762270664,0.833927618797594,-0.1478825430136954
224.00000000000244,28.72656174777223,0.8475604334472352,-0.1492790710273857
225.00000000000247,28.822785943572228,0.8619715286815085,-0.15245700986969624
226.0000000000025,28.915942020390684,0.8761611229971211,-0.1551297019608029
227.0000000000025,29.013459237346034,0.8927459155960735,-0.15875260347923614
228.0000000000025,29.108272897279214,0.9087291999892313,-0.1612741414102099
229.00000000000253,29.203469786501344,0.924861465845401,-0.1648004519564208
230.00000000000256,29.29934879380818,0.9425832773310602,-0.16676800776549738
231.00000000000256,29.394193145375443,0.9628296706990593,-0.16930636918564668
232.00000000000256,29.489683349395815,0.9814326392717825,-0.17431143272282856
233.0000000000026,29.58441626135124,1.0041758623103436,-0.17515081078026018
234.00000000000261,29.678824540918836,1.0279238800781763,-0.179515283115256
235.00000000000261,29.774262891201552,1.052636191676316,-0.18387114760626844
236.00000000000261,29.869501681285122,1.0798303657194592,-0.1870986282065381
237.00000000000264,29.96555025145577,1.1109731293873475,-0.19234217293206513
238.00000000000267,30.059540692264513,1.1427669873243036,-0.19530667030192816
239.00000000000267,30.156330395228462,1.176463757580139,-0.19995971985851524
240.00000000000267,30.25167020354829,1.2155650611215123,-0.20566725443842904
241.0000000000027,30.347282093275147,1.2565941234947635,-0.20980689706164268
242.00000000000273,30.441367406905286,1.2973712545566558,-0.21435512268931722
243.00000000000273,30.537739511221936,1.3424876910927726,-0.21981588042730138
244.00000000000273,30.633990749291055,1.3873517633018595,-0.22551025105367772
245.00000000000276,30.729816429389114,1.4395410864574136,-0.2317451158912478
246.00000000000279,30.82549695747018,1.4886044248752417,-0.23660546853768327
247.00000000000279,30.92078213295982,1.5422808042173908,-0.24466920990907282
248.00000000000279,31.017122713606835,1.5998522450027077,-0.2506744622012591
249.0000000000028,31.112070875637578,1.6568294863993782,-0.25758078434020115
250.00000000000284,31.208510065502093,1.7165855133071357,-0.2644208575159568
251.00000000000284,31.3046639525469,1.7787802798363805,-0.2714013498770229
252.00000000000284,31.400701983425407,1.8432889963787884,-0.2810034066783693
253.00000000000287,31.495640135657897,1.9069561231592247,-0.28907957052993094
254.0000000000029,31.591914765947603,1.975883545188442,-0.29585484482851454
255.0000000000029,31.688127377107993,2.043168362408191,-0.30736902877545536
256.0000000000029,31.783131352497993,2.109939372520946,-0.31558596065409583
257.00000000000296,31.87866474223298,2.1814945120592846,-0.324952665925653
258.00000000000296,31.97515486459149,2.254947706548326,-0.33562200374795426
259.00000000000296,32.07108358426557,2.3276050117884983,-0.34705894513715174
260.00000000000296,32.167443011137024,2.402859136733799,-0.3581391328853556
261.00000000000296,32.2634358087654,2.4761558471334078,-0.36869346715909046
262.000000000003,32.360290730722035,2.55039705246612,-0.3814320294834692
263.000000000003,32.45505307894318,2.625666543882181,-0.39302177651480186
264.000000000003,32.55163942710383,2.702077382907511,-0.4051772342922044
265.00000000000307,32.64809057211393,2.7773327301321684,-0.41962227883637393
266.00000000000307,32.7437581325201,2.8546865398977017,-0.4324842409409433
267.00000000000307,32.840485099131655,2.934965348589,-0.4465969815784243
268.00000000000307,32.936035032586275,3.0116655847623117,-0.4616676746558048
269.00000000000307,33.03274196500931,3.0930385077959635,-0.4770460061007027
270.0000000000031,33.12888132994109,3.175305410982913,-0.4940638836187965
271.0000000000031,33.22467558368986,3.2539494698541764,-0.5090285209248893
272.0000000000031,33.320106072281256,3.3365025793627185,-0.5263213504260698
273.0000000000032,33.41800461100545,3.4170219917679105,-0.5434462508294224
274.0000000000032,33.51391495791736,3.4991655348414445,-0.5608567172036101
275.0000000000032,33.610095608995664,3.5775430013866947,-0.58077640528795
276.0000000000032,33.706569483621514,3.655841355473778,-0.5999135367771222
277.0000000000032,33.80345466278132,3.7304201545853455,-0.6193848321121056
278.00000000000324,33.899071784565926,3.8009564273147087,-0.6406645530494304
279.00000000000324,33.9944441907519,3.862920620294385,-0.661120219263093
280.00000000000324,34.09202358132249,3.916170652863811,-0.6817887783708438
281.0000000000033,34.18872855976078,3.953786137570027,-0.7054591114058546
282.0000000000033,34.28541535744957,3.97609452411851,-0.7266346149316081
283.0000000000033,34.38153394938072,3.973327798251028,-0.7520266486725284
284.0000000000033,34.47655487796931,3.93421973316488,-0.7737733203506449
285.0000000000033,34.570505524656724,3.853874219120047,-0.7957313720025136
286.00000000000335,34.6677603442768,3.70171170224323,-0.8185911115216302
287.00000000000335,34.762894006604114,3.4536247942457554,-0.8400306003355973
288.00000000000335,34.85473326424767,3.095993469667024,-0.858208177178049
289.0000000000034,34.951628438929454,2.595001676238333,-0.876713497863419
290.0000000000034,35.04376494127937,2.1094259791517675,-0.8895410599244942
291.0000000000034,35.13802141270413,1.7351797625975118,-0.9035961912808204
292.0000000000034,35.22935987188321,1.4980235564388193,-0.91420261392016
293.0000000000034,35.32288538158352,1.3418066309445134,-0.9263466474089723
294.00000000000347,35.416263400802315,1.2386657129874021,-0.9385210454511816
295.00000000000347,35.51029057437078,1.174122181573255,-0.9495537463890109
296.00000000000347,35.60472291036051,1.1241616981266516,-0.9635097754517572
297.0000000000035,35.6972936169913,1.0879823275358471,-0.9744071555891254
298.0000000000035,35.79206017013471,1.0549434762537162,-0.9860944807090615
299.0000000000035,35.886491695488594,1.0252452996431347,-0.9976227641841922
300.0000000000035,35.980259944072486,0.9965582075209729,-1.0086073817501178
301.0000000000035,36.07289051176543,0.9706281630738078,-1.0193070539892766
302.0000000000036,36.16937791490599,0.9437619008835941,-1.0289442869502223
303.0000000000036,36.26499075493569,0.9195596396274283,-1.0382774174378961
304.0000000000036,36.35938708150199,0.8945071034064882,-1.04813872979843
305.00000000000364,36.454417512289645,0.869914008127689,-1.0561163111150051
306.00000000000364,36.548942121344545,0.8423878538310912,-1.0651122608034096
307.00000000000364,36.64398512134908,0.8194886855061272,-1.0727476326933894
308.00000000000364,36.73851419617589,0.7973178920386685,-1.0796793968681109
309.00000000000364,36.833781945668946,0.7773653892102244,-1.086845523699131
310.0000000000037,36.92892653557277,0.7578018607093766,-1.0927544254396513
311.0000000000037,37.02397697444234,0.7375053762234306,-1.099266373494764
312.0000000000037,37.119478153578,0.7223044818780868,-1.1045327964816942
313.00000000000375,37.214858345840014,0.7087438163616232,-1.1103787292598195
314.00000000000375,37.30872669492137,0.6954116690002644,-1.1166051434327047
315.00000000000375,37.405028008114506,0.6866014338447924,-1.1210557129120344
316.00000000000375,37.50030684644827,0.6795138939814171,-1.1267041677376528
317.00000000000375,37.59553839909782,0.6715338044570154,-1.1314603003008905
318.0000000000038,37.69127066540961,0.667599969348839,-1.1356128764617992
319.0000000000038,37.787034524150016,0.6654720089690923,-1.141652882154197
320.0000000000038,37.88259990458241,0.6637838330783544,-1.1458609826282347
321.00000000000387,37.97797423796908,0.6651526183563105,-1.1508675689498977
322.00000000000387,38.07424137629371,0.6662528610675308,-1.1571039541657235
323.00000000000387,38.16852751325071,0.6702843456108649,-1.161506379739715
324.00000000000387,38.26425310163267,0.6724292272897284,-1.1662773215866062
325.00000000000387,38.35920253241292,0.6771971845044309,-1.1699336970522674
326.0000000000039,38.45572333569744,0.6822000611840195,-1.1752880906562435
327.0000000000039,38.552455532302055,0.6847804254759221,-1.1801053288284549
328.0000000000039,38.64880913875898,0.6880797717285523,-1.1855637149141298
329.000000000004,38.742924203653764,0.6910767620841591,-1.1912454524862426
330.000000000004,38.83936704426703,0.695153050916907,-1.1963684082908714
331.000000000004,38.93507637725103,0.6992525240249903,-1.2008583454879842
332.000000000004,39.03290160406773,0.702090456508586,-1.2089324379512716
333.000000000004,39.12896443194327,0.7047583392863914,-1.21387079690383
334.00000000000404,39.22580331326328,0.7068343913362238,-1.219821758214671
335.00000000000404,39.32110948153395,0.7116074655999046,-1.2259830388829562
336.00000000000404,39.41845547359339,0.7137484659324144,-1.23239223593208
337.0000000000041,39.51374395456372,0.7162715993358805,-1.2375677593827792
338.0000000000041,39.61030940604373,0.7198780587239546,-1.2441844235284938
339.0000000000041,39.70631407654019,0.7230157987428716,-1.2503289873934231
340.0000000000041,39.80195693427416,0.7253199356662606,-1.2577620538916983
341.0000000000041,39.89851273717361,0.7292589454698993,-1.2655615841450558
342.00000000000415,39.99596783056422,0.7351566163467546,-1.2707160180554231
343.00000000000415,40.09087199419653,0.7358932530606453,-1.2791786215913108
344.00000000000415,40.18909112144807,0.7411935494896478,-1.2852432385251142
345.0000000000042,40.28497128778381,0.7445959314026201,-1.2922467877346384
346.0000000000042,40.38151170297412,0.7498228236723858,-1.299316234567208
347.0000000000042,40.478274089414654,0.7559239485218452,-1.3072100335760055
348.0000000000042,40.57396349558822,0.7569289887139106,-1.3139573630194454
349.0000000000042,40.670448782172635,0.7625048808624946,-1.3223977985569282
350.00000000000426,40.76698479064252,0.7663009745775665,-1.3326745332507008
351.00000000000426,40.8614390116204,0.770104725614811,-1.3387989417567892
352.00000000000426,40.95928444293163,0.7758476383177751,-1.3461927177470612
353.0000000000043,41.05617938473654,0.7802972586860184,-1.3538629384095282
354.0000000000043,41.15279004576683,0.7832224507473908,-1.362799041393266
355.0000000000043,41.249314939527245,0.7888181114828803,-1.3717854795855802
356.0000000000043,41.345592903007244,0.7955169097595711,-1.381639688878129
357.0000000000043,41.44232989067648,0.7998540157921965,-1.3915424022276102
358.0000000000044,41.539263956131165,0.8030356498181375,-1.400538776123701
359.0000000000044,41.63553312418699,0.8108883638846598,-1.4091231692447086
360.0000000000044,41.73183160993476,0.8171996035965112,-1.4189189902672186
361.00000000000443,41.82869524284753,0.8212752857419592,-1.428610380132513
362.00000000000443,41.92599817852365,0.8271338637072262,-1.4409217798468283
363.00000000000443,42.02162333388361,0.8319446058612999,-1.4517756358114098
364.00000000000443,42.1186691771524,0.8378346165783542,-1.463259241718494
365.00000000000443,42.21630598603344,0.8439607343689497,-1.4738760195703482
366.0000000000045,42.31242373545499,0.8492978451691954,-1.4847346873976104
367.0000000000045,42.409472165356895,0.8545043513768017,-1.4970542427757114
368.0000000000045,42.506344042322254,0.8586578450730434,-1.5074110022000946
369.00000000000455,42.6038126783992,0.8642198612248345,-1.5210679948464971
370.00000000000455,42.70085818331912,0.8702324921923101,-1.5333595129124467
371.00000000000455,42.796684195900305,0.8718304859472376,-1.5446878781829447
372.00000000000455,42.893452629712634,0.876925880043005,-1.5571021863528065
373.00000000000455,42.991398021650355,0.8815644465975976,-1.5712418889957038
374.0000000000046,43.08852418125398,0.8835440737258289,-1.5826039681922097
375.0000000000046,43.185985965783814,0.8859711096974003,-1.5956609900752312
376.0000000000046,43.28330690732305,0.8896965529094959,-1.6109416008388315
377.00000000000466,43.38058633878173,0.8920141162875403,-1.625092254920903
378.00000000000466,43.47749146926454,0.8943353770733448,-1.638473841227134
379.00000000000466,43.57429612882424,0.8946761093397635,-1.652859835529953
380.00000000000466,43.671752666135006,0.8970206238781437,-1.6672239881473745
381.00000000000466,43.768493843183535,0.8972479763937835,-1.6814245969941597
382.0000000000047,43.865768158117156,0.8984767474295936,-1.697133470255452
383.0000000000047,43.961855622407874,0.8981912513755321,-1.7121763964505043
384.0000000000047,44.05970198166173,0.8942145625274439,-1.7265026444061813
385.0000000000048,44.15644052166901,0.8923497494059298,-1.7405528334152924
386.0000000000048,44.25399956464824,0.8880727193923085,-1.7545066967149578
387.0000000000048,44.35120575805333,0.8861565490943913,-1.7712767767400717
388.0000000000048,44.447708576869985,0.8796076251349362,-1.7853648082978433
389.0000000000048,44.54475101458909,0.8764776968789508,-1.8008933229108015
390.00000000000483,44.64108046639035,0.8696255163198069,-1.814970211030829
391.00000000000483,44.738777019350366,0.8619468608891064,-1.8287927734293778
392.00000000000483,44.83635882654167,0.8573304570414682,-1.8454623689134118
393.0000000000049,44.93260687017828,0.8486954160234057,-1.8576442487348515
394.0000000000049,45.02943858842727,0.8384148050878796,-1.8723726558400138
395.0000000000049,45.12677896703983,0.8273592598719371,-1.885343291074371
396.0000000000049,45.22420373699956,0.8165014001560048,-1.8999083471002414
397.0000000000049,45.320616699493065,0.8036035302295181,-1.9115487844325254
398.00000000000495,45.41916610553127,0.7927244738133444,-1.925501126958575
399.00000000000495,45.51547721757918,0.7801878261783548,-1.9382818135836226
400.00000000000495,45.61252066094323,0.7653091495905862,-1.9489224760707415
401.000000000005,45.70902514615785,0.7523848342797075,-1.9620410917766202
402.000000000005,45.80721110774169,0.7348209060291382,-1.9737195109524834
403.000000000005,45.90384017299691,0.7217781704201253,-1.9848644839773741
404.000000000005,46.00097000341235,0.7049359883932309,-1.9945166565854682
405.000000000005,46.097525077182894,0.6884460971556304,-2.0047265631765985
406.00000000000506,46.19510597472465,0.6757883009323046,-2.015093292274364
407.00000000000506,46.291411410804535,0.6589517104561762,-2.025004048761537
408.00000000000506,46.38941230416747,0.6443223054461401,-2.0342541589431526
409.0000000000051,46.48632251028305,0.6275306679056365,-2.042535080635566
410.0000000000051,46.58364050528742,0.6140198474980881,-2.050206414781027
411.0000000000051,46.680940998656645,0.5988364514652936,-2.0590102458602884
412.0000000000051,46.7787200447653,0.5854662716260683,-2.0651183224905205
413.0000000000051,46.87618318527956,0.5697878421170381,-2.072195528537557
414.0000000000052,46.97410700307123,0.5553244633416382,-2.0783839560435653
415.0000000000052,47.0710231869434,0.5437272998568727,-2.084143438022797
416.0000000000052,47.16905906611087,0.530933000249209,-2.0906834631054445
417.00000000000523,47.26601098333451,0.5183875410052603,-2.0955469014571415
418.00000000000523,47.363320223723534,0.5112314924921495,-2.1001246597075482
419.00000000000523,47.4610329644234,0.4982555929015706,-2.1058362935199835
420.00000000000523,47.558687401832685,0.48941508330939576,-2.111198697978306
421.00000000000523,47.65526439137061,0.48018005366966005,-2.115193936482119
422.0000000000053,47.75265554401092,0.4733858187951245,-2.1185695922181234
423.0000000000053,47.850478150543324,0.4640730531561308,-2.121343662944863
424.0000000000053,47.946615703350844,0.4585967128245409,-2.1265562365087955
425.00000000000534,48.04436062726845,0.4509618857226123,-2.1279225391189223
426.00000000000534,48.14237507077623,0.44414672817832446,-2.1305693234413026
427.00000000000534,48.24000000000055,0.43860606196270596,-2.133310082399169
428.00000000000534,48.33772487993977,0.4310206677982013,-2.1361020825500217
429.00000000000534,48.4352605920173,0.42748049924496834,-2.1395416457838077
430.0000000000054,48.53052462391344,0.4235328612710946,-2.142743612126186
431.0000000000054,48.62855850314341,0.4189908360453184,-2.1427721036849054
432.0000000000054,48.727423341680186,0.4171095860334775,-2.1453885836214255
433.00000000000546,48.82615406415659,0.4139378824908591,-2.1466981292471328
434.00000000000546,48.922074620627,0.41185434142082733,-2.150648424330516
435.00000000000546,49.02184184695239,0.4086504102186733,-2.1519828926309956
436.00000000000546,49.119090550615844,0.4088417850594979,-2.153278673843677
437.00000000000546,49.21677089021629,0.40686115283355395,-2.156097330956133
438.0000000000055,49.314059625546236,0.4046844986320842,-2.1561698425356384
439.0000000000055,49.410203335887026,0.40438177095063005,-2.157350815172813
440.0000000000055,49.509524979865205,0.40551554718025684,-2.158668278884137
441.00000000000557,49.60717903794572,0.4051872845746271,-2.1599892511873575
442.00000000000557,49.70529022325568,0.4041155395584687,-2.161287100027476
443.00000000000557,49.802897153426684,0.4068409595878027,-2.162619091063868
444.00000000000557,49.89949376403802,0.40868774098608124,-2.163940335191823
445.00000000000557,49.99858004184994,0.4123027121695467,-2.1652599296067088
446.0000000000056,50.09535128505693,0.410625293493192,-2.165544558588768
447.0000000000056,50.192139259586746,0.41178565470592865,-2.167412917370126
448.0000000000056,50.290383595693704,0.4121651677549814,-2.1685823959264274
449.0000000000057,50.38793802338663,0.41145006270764684,-2.170529540610699
450.0000000000057,50.48573477307957,0.4115616298987225,-2.1717860482754183
451.0000000000057,50.58360792249311,0.41134423597901026,-2.1732492392747234
452.0000000000057,50.681309660590856,0.41297350323581405,-2.172169793275157
453.0000000000057,50.779044170986275,0.4133354527512038,-2.173489930565139
454.00000000000574,50.876279567718186,0.41261390529703335,-2.1761293640406896
455.00000000000574,50.97588504409537,0.41270206362010514,-2.177440000951436
456.00000000000574,51.07257101278673,0.41238079206028416,-2.178739015088857
457.0000000000058,51.17073616032438,0.41261877211544573,-2.1797501495815945
458.0000000000058,51.26916724720106,0.4146609703923049,-2.1810711290444624
459.0000000000058,51.3667432100991,0.41355662671026044,-2.182380197164746
460.0000000000058,51.46512298713133,0.41347995722459463,-2.183796126289019
461.0000000000058,51.563848064841274,0.4153934521402478,-2.1850270430739984
462.00000000000585,51.661228975474145,0.41472924603125216,-2.185019822234635
463.00000000000585,51.75989848407892,0.41310061881722815,-2.186339648701474
464.00000000000585,51.857948672880944,0.41436124802716384,-2.1868224568453236
465.0000000000059,51.955530721550176,0.4121359653879658,-2.1869720835626674
466.0000000000059,52.053767306405035,0.4137162297831053,-2.190263226397837
467.0000000000059,52.15241934364877,0.4110062511738952,-2.190874086873177
468.0000000000059,52.25020010216016,0.41370749389748096,-2.1919307163284065
469.0000000000059,52.34911566119769,0.4133892862084668,-2.1929156062633286
470.00000000000597,52.446977680189185,0.4145063654713154,-2.1941828330558684
471.00000000000597,52.54615062217642,0.4115393382261523,-2.195559395125495
472.00000000000597,52.64376459124704,0.4135404085578606,-2.196774819608742
473.000000000006,52.7429041728499,0.41290305718765985,-2.1968695722608484
474.000000000006,52.84039662946971,0.4134241413707743,-2.1995096961884792
475.000000000006,52.93882595560295,0.41319260299887295,-2.2008298725397455
476.000000000006,53.035333707538285,0.4139194079265327,-2.202142828863688
477.000000000006,53.13529222006321,0.416180475772977,-2.2027986068975833
478.0000000000061,53.2332055639967,0.41579096465036713,-2.204120369437579
479.0000000000061,53.331763197871375,0.4146144998849574,-2.2040822955998123
480.0000000000061,53.43086832481471,0.4154191928413832,-2.2054423444197644
481.00000000000614,53.5282191445361,0.4148626527385274,-2.206773325233484
482.00000000000614,53.62653498174881,0.4119982209115549,-2.209421956078795
483.00000000000614,53.72546475466597,0.41267082649235487,-2.20938964548286
484.00000000000614,53.82351455987639,0.41437503443010243,-2.2107098214389964
485.00000000000614,53.92134674789399,0.4147613442644852,-2.210810792904264
486.0000000000062,54.01979853274055,0.4150547951519075,-2.2133274565724377
487.0000000000062,54.11769614446009,0.4153915982167322,-2.2138039448561266
488.0000000000062,54.216444433562955,0.4161688982876291,-2.215825920176974
489.00000000000625,54.31370965860834,0.4145493166335888,-2.2159809256551473
490.00000000000625,54.41091226982444,0.4150114572220226,-2.2172901740554423
491.00000000000625,54.51122722186789,0.4144485038072223,-2.218615677686946
492.00000000000625,54.60990724450035,0.4148935381450072,-2.219928614960763
493.00000000000625,54.70701842581008,0.41436362912024305,-2.219262259163914
494.0000000000063,54.80649551550288,0.41220705144104414,-2.2205809555951412
495.0000000000063,54.904820365486465,0.4129234029057751,-2.222911372388299
496.0000000000063,55.0047896740672,0.41584398904548403,-2.2242085907107922
497.00000000000637,55.10222991116382,0.4126155774402478,-2.2229086443279886
498.00000000000637,55.200595005375376,0.41479667709983603,-2.22420916376138
499.00000000000637,55.29912422992372,0.4168688952159271,-2.225530103502258
500.00000000000637,55.397718668907956,0.4169606091319751,-2.226855492004124
501.00000000000637,55.49726793097698,0.4203868927546669,-2.228597653495057
502.0000000000064,55.59371734923019,0.42052064629821484,-2.2294763005852545
503.0000000000064,55.69371927620373,0.4203378417956701,-2.230790003808734
504.0000000000064,55.79253648732017,0.4207387670379281,-2.2321163640055373
505.0000000000065,55.891683617525764,0.42100512655288647,-2.232204829992848
506.0000000000065,55.98946885944981,0.4192223483714048,-2.234769867555415
507.0000000000065,56.08830498696476,0.4195469212878773,-2.235740571987309
508.0000000000065,56.18642321498917,0.4229560333805385,-2.2349858255288173
509.0000000000065,56.284640804547095,0.42376002079880526,-2.237713174635867
510.00000000000654,56.38349111187413,0.42544113404325146,-2.236703271377265
511.00000000000654,56.482667164778114,0.4213706128862431,-2.2390363176653203
512.0000000000066,56.58120070204007,0.4193367245869071,-2.239115783039282
513.0000000000066,56.679796229765245,0.4191195137040329,-2.241660090488943
514.0000000000066,56.77825585742011,0.4217871147007915,-2.241583525754113
515.0000000000066,56.87688904754568,0.4195516349414087,-2.242982291042031
516.0000000000066,56.97555051177568,0.41841007793400653,-2.2429757206727787
517.0000000000066,57.0736730377664,0.4188296290218911,-2.2446234505899203
518.0000000000066,57.17318164357048,0.41881443892356707,-2.2456192765115763
519.0000000000066,57.27188430040999,0.4197597060003069,-2.247014754391712
520.0000000000066,57.37070204819047,0.41998752623675617,-2.2469173415292074
521.0000000000067,57.46946866876556,0.41820618803450743,-2.2491207319306628
522.0000000000067,57.56923388310401,0.41868617382483825,-2.250880147873435
523.0000000000067,57.66698150468753,0.4209802255020533,-2.2514668709573646
524.0000000000067,57.765892163935426,0.4215573224581274,-2.252016089501053
525.0000000000067,57.86508196933282,0.4229991977521259,-2.2535230116350506
526.0000000000068,57.9640250770168,0.4201749277624186,-2.253558845359021
527.0000000000068,58.06313807571423,0.4207555394813709,-2.25483231923965
528.0000000000068,58.16132981343631,0.4198309066644852,-2.2561500184390724
529.0000000000068,58.26044344784541,0.41954134921055974,-2.257469936014947
530.0000000000068,58.359806888068604,0.4193165060284517,-2.2587794304948803
531.0000000000068,58.457560861137644,0.41837320050932025,-2.2599117017974075
532.0000000000068,58.557500321848174,0.41777286235418387,-2.2601427616618897
533.0000000000068,58.655459420681055,0.4164279342577414,-2.260033070835944
534.0000000000068,58.755229385035264,0.4194130127215163,-2.2618067523689005
535.0000000000068,58.85254963775189,0.41811900380448896,-2.2617602057031903
536.0000000000068,58.95390442270395,0.4179020637127805,-2.2630872449950443
537.0000000000069,59.05158387123181,0.4164934681655146,-2.2650500587116333
538.0000000000069,59.15075910822053,0.4156042843440304,-2.2637489347753075
539.0000000000069,59.24940891265798,0.4152110181047606,-2.265990367612446
540.0000000000069,59.34923580374783,0.4158217926145929,-2.267959763163193
541.0000000000069,59.4478323347482,0.4138645140875252,-2.267576487203385
542.000000000007,59.54685339973037,0.4110889498499418,-2.268857397465295
543.000000000007,59.64583680366289,0.4111326797936881,-2.2704015789511534
544.000000000007,59.74541592336723,0.4097032400760314,-2.2703341009388813
545.000000000007,59.84400622945827,0.40953777817081405,-2.27295807511491
546.000000000007,59.943234152638624,0.4055634403048235,-2.2729819352758645
547.000000000007,60.043189868631586,0.4040092721216197,-2.2742697052328076
548.000000000007,60.141845259860595,0.4026568797167435,-2.274401002110264
549.000000000007,60.24188823986098,0.4013989925079665,-2.2755901263338405
550.000000000007,60.34098300143001,0.40186681979607275,-2.2755901093822626
551.000000000007,60.44069087763278,0.4014672634681983,-2.2755923698445
552.000000000007,60.53958838478763,0.3981705351183813,-2.276900099586297
553.0000000000072,60.638845386408086,0.39821849412066607,-2.2772038779014503
554.0000000000072,60.73781366760331,0.39567217495514984,-2.279209943599669
555.0000000000072,60.83648804157232,0.39725602891981365,-2.279807064314395
556.0000000000072,60.935876323844255,0.39328017899543977,-2.2805300095459975
557.0000000000072,61.0344908465334,0.3924917770144909,-2.2805560065362216
558.0000000000073,61.1346067108446,0.39108006127033745,-2.2818402378851332
559.0000000000073,61.23292660697338,0.3863377912209287,-2.2825799931293034
560.0000000000073,61.33146320256656,0.3840884629649446,-2.28249788722024
561.0000000000073,61.430772246933365,0.3800909023825284,-2.28382018904408
562.0000000000073,61.52908873139057,0.3785279704774789,-2.2851343068969987
563.0000000000073,61.628123927004616,0.3756949822465637,-2.2851300946425566
564.0000000000073,61.72781479350246,0.3722420887085648,-2.2864502991316233
565.0000000000073,61.82567643016647,0.3704690924873536,-2.2864501792421943
566.0000000000073,61.92647003526014,0.3688193001420402,-2.2871193154234204
567.0000000000073,62.025293668386055,0.3667534760242061,-2.288402662123416
568.0000000000074,62.12388321212041,0.3655222304215763,-2.288429672379692
569.0000000000074,62.22222481108495,0.3641652448591359,-2.2875541336088534
570.0000000000074,62.32048015683011,0.36024740612821615,-2.2900802808952987
571.0000000000074,62.421345065594636,0.3598036119879794,-2.2900103758294943
572.0000000000074,62.52143424095773,0.35811937464516685,-2.292714908667458
573.0000000000074,62.61982506891688,0.3577729914435831,-2.291399815687399
574.0000000000074,62.719278282883,0.355765506225205,-2.292719521183642
575.0000000000075,62.81798297506246,0.3551937021228705,-2.29307829158551
576.0000000000075,62.917125096849006,0.35217468556462095,-2.294652368232727
577.0000000000075,63.01646115728253,0.35000131572038173,-2.2946800016640205
578.0000000000075,63.1144934190501,0.34680667234675244,-2.295719086791208
579.0000000000075,63.21432559479858,0.34697685460120387,-2.296000020667641
580.0000000000075,63.313801919282646,0.34368715863461985,-2.2959960697510207
581.0000000000075,63.41323187609124,0.34105781086607173,-2.296670168371938
582.0000000000075,63.51224001500648,0.3388283359651031,-2.2979875131149172
583.0000000000075,63.613306702518706,0.33689852144761256,-2.2983215859342803
584.0000000000076,63.71325973733777,0.3329233030766785,-2.2993000565792947
585.0000000000076,63.81215003368021,0.3321487904114243,-2.297880385280474
586.0000000000076,63.91000000000079,0.3301784836259097,-2.2979759911697797
587.0000000000076,64.0116630851799,0.3267417127244663,-2.2999528879134985
588.0000000000076,64.11032495331776,0.3218261396629867,-2.2999598564299966
589.0000000000076,64.2095993477546,0.31855262544205243,-2.3012783101951504
590.0000000000076,64.30980808404117,0.3146727989067827,-2.3012801384720403
591.0000000000077,64.41050163587164,0.3090033005783585,-2.3009932380964466
592.0000000000077,64.5090943189198,0.3032706090465464,-2.3012843117249355
593.0000000000077,64.60902756429103,0.30435664014080566,-2.302590066543089
594.0000000000077,64.70889298354497,0.29575231767103655,-2.3025900620000077
595.0000000000077,64.80854559007228,0.2936108585507029,-2.3025900619875985
596.0000000000077,64.90770143331055,0.2894488953587973,-2.3025798388579664
597.0000000000077,65.00701641117163,0.2853341557675526,-2.303909902796482
598.0000000000077,65.10707378594019,0.28186419074473157,-2.3052336208282402
599.0000000000077,65.2068881295908,0.2814451870183421,-2.304190033985145
600.0000000000078,65.30473723575409,0.2791298377298167,-2.3052299338382967
601.0000000000078,65.40505216981667,0.2725466997833792,-2.305091822405629
602.0000000000078,65.50452076851727,0.2722198366358227,-2.305388940778246
603.0000000000078,65.6049152611993,0.2672898891046512,-2.3061944907218166
604.0000000000078,65.70410060407501,0.26754933317422724,-2.3062098031042204
605.0000000000078,65.8034655181161,0.26229403688099073,-2.3062098112889964
606.0000000000078,65.90302016748754,0.2616159234306697,-2.3075296695559615
607.000000000008,66.0030438672316,0.2575760502463941,-2.3108189805108745
608.000000000008,66.10206275117788,0.25608885719269914,-2.30797151699437
609.000000000008,66.20199218258539,0.2560505361865715,-2.3079837039491173
610.000000000008,66.30069635208291,0.25621533301259525,-2.3069489137616497
611.000000000008,66.40128888550932,0.2544043613838939,-2.306990064525762
612.000000000008,66.50125496701892,0.2524419066130741,-2.308309839990983
613.000000000008,66.60115842581665,0.2508328832495258,-2.30831032420884
614.000000000008,66.70067100872245,0.249514904306572,-2.309620078702559
615.000000000008,66.80009459224428,0.24917961950333498,-2.3096200670000444
616.0000000000081,66.89952658341514,0.2499718820612818,-2.30962009315797
617.0000000000081,66.99815947701062,0.2517636011167045,-2.3083009754575428
618.0000000000081,67.09865015644438,0.2532420126912541,-2.3109441451956005
619.0000000000081,67.19912554258663,0.2573294786557235,-2.3096169741556065
620.0000000000081,67.29795970642778,0.26061908417882024,-2.3096199769461943
621.0000000000081,67.39766070470208,0.2639131974210265,-2.3102794404700147
622.0000000000081,67.49708910045307,0.2647866082145065,-2.310609656610016
623.0000000000082,67.59633277772357,0.26769076261971286,-2.310620520220181
624.0000000000082,67.69653599933066,0.26949685032290804,-2.3102743804712014
625.0000000000082,67.79617289259876,0.2738304064675474,-2.3115998994542215
626.0000000000082,67.89503870669537,0.27559972245570163,-2.3115999440155823
627.0000000000082,67.99520716470576,0.2795333571823983,-2.311791955242046
628.0000000000082,68.09394656406694,0.2797421174411538,-2.312250097219554
629.0000000000082,68.19375268686628,0.2792048336121201,-2.3122500979999745
630.0000000000082,68.29433947270965,0.28338173438312997,-2.312250084610294
631.0000000000082,68.39348232385808,0.28439194216776076,-2.3135307669174345
632.0000000000083,68.4936577533916,0.2809178100153631,-2.3122499216656087
633.0000000000083,68.59229957834559,0.2808934772603529,-2.312249923000117
634.0000000000083,68.69193690499577,0.2789412019768062,-2.3122499776192837
635.0000000000083,68.79124818205618,0.2772099598637814,-2.3132388803439565
636.0000000000083,68.89120599962975,0.2785666104466319,-2.3135641751598177
637.0000000000083,68.99105709889463,0.2771214901130231,-2.3135701510932396
638.0000000000083,69.09021421008025,0.27528934608066746,-2.3136176877467465
639.0000000000084,69.19067948179236,0.2765651293594121,-2.312924673763262
640.0000000000084,69.29089381150538,0.2750094072070385,-2.313569907865754
641.0000000000084,69.39000000000082,0.2736803535586552,-2.3135699009999997
642.0000000000084,69.49019527982387,0.2725470906481068,-2.313570231323116
643.0000000000084,69.58752963432532,0.2746593406404924,-2.3148904406257396
644.0000000000084,69.6900000000008,0.2736038408121563,-2.314230096070456
645.0000000000084,69.78894301415868,0.2741346527409071,-2.314224896018198
646.0000000000084,69.88902360649823,0.27217305668338987,-2.31356632151934
647.0000000000084,69.98800119801827,0.27287805734346837,-2.3155547180397753