File: 01_Data/Corian_Countertop/STA/N2/10K_min/Corian_Countertop_STA_N2_10KData_220920_R1.csv
##Temp./Â°C,Time/min,DSC/(mW/mg),Mass loss/mg
51.0,10.873994898948125,0.05638442774294217,0.015440937361602458
52.20000000000002,11.191802327686647,0.08547913792367634,0.01296421477984211
53.400000000000034,11.452859911612506,0.114264791405295,0.01573320643908982
54.60000000000005,11.670110835247756,0.13518560533665336,0.014262796660135635
55.80000000000007,11.864753404496438,0.15038539812384677,0.014519019954269297
57.000000000000085,12.047957046574128,0.16576153060498422,0.015915411504626498
58.2000000000001,12.22156487809466,0.17671270338159095,0.015661612497577693
59.40000000000012,12.387092943311597,0.1838876652277912,0.014408569785287817
60.600000000000136,12.548370100211947,0.19187493297397595,0.013329353891214701
61.80000000000015,12.70323368288957,0.19881216141468827,0.01752353929659911
63.00000000000017,12.857698351949034,0.206820632920929,0.014259682366168924
64.20000000000019,13.00680537891597,0.21307452738603527,0.014028572633333347
65.4000000000002,13.153742681783852,0.2186426039714442,0.013548410465330285
66.60000000000022,13.29942394135881,0.22513365277677155,0.014414500899377458
67.80000000000024,13.441594337771338,0.23135171268294963,0.014470719318750547
69.00000000000026,13.579779898860792,0.23662684672804835,0.014593553570124485
70.20000000000027,13.720000000000027,0.2414117355149069,0.01331334005783269
71.40000000000029,13.857637935426077,0.24634580288102492,0.013247654119588503
72.6000000000003,13.993241288745017,0.25250549587598237,0.014086102210872475
73.80000000000032,14.128554114120673,0.25596960354257525,0.014472832198244134
75.00000000000034,14.264643802059496,0.26283915423720483,0.01449248946741477
76.20000000000036,14.396308697194424,0.2682817990425601,0.01331104553620932
77.40000000000038,14.527254066668487,0.27397220785873144,0.011983696948977496
78.60000000000039,14.657678134736088,0.2785099500221897,0.011864937010178878
79.80000000000041,14.788870066103154,0.28252042942838085,0.011501573972373613
81.00000000000043,14.915924837289067,0.28641715987792016,0.011774159752936164
82.20000000000044,15.045651955751984,0.2894591414110812,0.011600287818562371
83.40000000000046,15.170535967208554,0.29176497126649514,0.01053949582864444
84.60000000000048,15.298567335014859,0.29461133191960154,0.010543242093079108
85.8000000000005,15.425986045971012,0.2977551453339349,0.010650580364197637
87.00000000000051,15.550842926630468,0.29844120131500385,0.010687946496737766
88.20000000000053,15.673425513373855,0.29987702257941373,0.012159451253564768
89.40000000000055,15.798748979331895,0.3016216333599956,0.011865107367857952
90.60000000000056,15.921105452321425,0.3069011433914327,0.011850200100059105
91.80000000000058,16.0437699414146,0.30964346953660227,0.009950365204961287
93.0000000000006,16.166204016704647,0.31155086484425776,0.01052189513290891
94.20000000000061,16.287521652758148,0.31269491933820437,0.007900918481339225
95.40000000000063,16.40937386351298,0.3155135323201108,0.007910965079231502
96.60000000000065,16.527996977674015,0.3192685830986657,0.007909642442815112
97.80000000000067,16.649059443203992,0.3216686168814451,0.007480991872557574
99.00000000000068,16.765505359562834,0.3239048887835131,0.007899816951648653
100.2000000000007,16.888287152308106,0.3279485030720608,0.009221714939775083
101.40000000000072,17.00808152262814,0.33045394749495727,0.007960666257080362
102.60000000000073,17.127744486979342,0.33390595829028014,0.006618978696687705
103.80000000000075,17.24528955989515,0.3335272845291609,0.0052698949737362
105.00000000000077,17.364835050704233,0.33938989469442915,0.004953920145777779
106.20000000000078,17.482448369924402,0.3410022470499896,0.003962747876989248
107.4000000000008,17.599705458969208,0.34478870420610996,0.004376261969020412
108.60000000000082,17.718578533487417,0.3469198143225172,0.0041763679447965885
109.80000000000084,17.836712951644138,0.34860669382925746,0.0039510853809199276
111.00000000000085,17.95149040338096,0.35296379243949405,0.003960612551384912
112.20000000000087,18.070983853738824,0.3562069984091608,0.003048731438545893
113.40000000000089,18.188661220595108,0.35948581658858225,0.0039500115420247894
114.6000000000009,18.304861263934832,0.3607890333376297,0.0038790943390418775
115.80000000000092,18.423541047968357,0.3667919531031023,0.0023366387859207194
117.00000000000094,18.54019787770605,0.36830642199867114,0.0009860845008597963
118.20000000000095,18.65735359119109,0.37172225714279095,1.0561967391353733e-05
119.40000000000097,18.77231855227057,0.3758944963193773,0.0010871224440016647
120.60000000000099,18.89067115002333,0.37670884621352485,9.689935530143856e-05
121.800000000001,19.007772519929205,0.38024848519072607,-0.0026160776588568524
123.00000000000102,19.12455181396177,0.382687271926492,-0.0026318968048837377
124.20000000000104,19.241794440829267,0.3833548362441681,-0.0019368664982106765
125.40000000000106,19.35803365070641,0.3871889193092587,-0.0026188455002706945
126.60000000000107,19.47414556339247,0.39063832719290403,-0.0013201518641743348
127.80000000000109,19.589248597834654,0.39064056040296824,-0.0026518623961786503
129.0000000000011,19.70604507300672,0.3937782653278673,-0.002729992010223725
130.20000000000113,19.82239934670965,0.3966434485559621,-0.005252680034334212
131.40000000000114,19.938953159500226,0.3983067736968604,-0.0049290297932902405
132.60000000000116,20.05389629536317,0.39987618393685964,-0.00527015745130921
133.80000000000118,20.16838782392111,0.4010941105076842,-0.00659341355402443
135.0000000000012,20.283297751393373,0.40290530086087506,-0.005929619236925809
136.2000000000012,20.399026009308315,0.4052026946687045,-0.006893386063705265
137.40000000000123,20.51490568814804,0.40842668465173293,-0.010854738908220085
138.60000000000124,20.630712981264207,0.4097466844124412,-0.010859955998097526
139.80000000000126,20.74473517250287,0.411197047111018,-0.010860020424013683
141.00000000000128,20.860000000000127,0.4130867607998804,-0.012180320187352045
142.2000000000013,20.975450169412746,0.41486082374738964,-0.011861238343544578
143.4000000000013,21.090383814433572,0.4188694669423024,-0.011859711651974969
144.60000000000133,21.204706268049772,0.4215142514538843,-0.01483098390338089
145.80000000000135,21.319582673505884,0.42281547169417977,-0.015810178100909233
147.00000000000136,21.43313313237681,0.42560750295567845,-0.014474714451598203
148.20000000000138,21.548658327397554,0.4297317346643355,-0.015799872906997692
149.4000000000014,21.66139953089277,0.43064202110592853,-0.017123963473864023
150.60000000000142,21.776810191341607,0.43483277515962454,-0.017119878888903983
151.80000000000143,21.891611548182624,0.43740577198107805,-0.01791730976086381
153.00000000000145,22.00628682733685,0.4421296607001183,-0.019105685045313514
154.20000000000147,22.11949717816261,0.4468580309167426,-0.021263364386621575
155.40000000000148,22.233430930277592,0.4513722835405047,-0.02240008633877366
156.6000000000015,22.34805587352885,0.4526376890894867,-0.02371519946932832
157.80000000000152,22.461995764564897,0.45817176050100333,-0.025031349274604153
159.00000000000153,22.576208903533782,0.46333423707311905,-0.026680034916365614
160.20000000000155,22.689792015117433,0.4670820812323123,-0.027975795857103414
161.40000000000157,22.804251243147178,0.4699593866291797,-0.027990127421224642
162.6000000000016,22.918332248191973,0.4766123778056432,-0.028649672718259467
163.8000000000016,23.03219528668505,0.47853261440977346,-0.03030000576562486
165.00000000000162,23.146064200142764,0.4845672764775859,-0.031596310287739904
166.20000000000164,23.259905593386428,0.48889488651626184,-0.03272948412410148
167.40000000000165,23.373725610057246,0.49506265817373735,-0.0356011779560248
168.60000000000167,23.4874991038708,0.49898248968687586,-0.03602819557256076
169.8000000000017,23.60222126091024,0.5043538317118132,-0.03965256728019284
171.0000000000017,23.71478712150516,0.5092149632051501,-0.04215432832001387
172.20000000000172,23.82921730161514,0.5158177523481173,-0.04406200531229043
173.40000000000174,23.944756872609602,0.5205475136096556,-0.047405032992996254
174.60000000000176,24.05896648023776,0.5252043769574957,-0.05009117376544481
175.80000000000177,24.1722165689932,0.5315256231317338,-0.05140329045015957
177.0000000000018,24.287301670693996,0.5345432642816083,-0.05269990123070034
178.2000000000018,24.401055912093,0.5399400847972025,-0.054022204817302466
179.40000000000182,24.513727710051068,0.5437997630174037,-0.05794204736692343
180.60000000000184,24.62907228258523,0.5480967191147056,-0.05954430472418082
181.80000000000186,24.742909586967375,0.5527478211161189,-0.06187963549183273
183.00000000000188,24.857143983069115,0.5552337790058692,-0.06593056232188488
184.2000000000019,24.970586638742766,0.5597630935976206,-0.06986113753566148
185.4000000000019,25.08548261030478,0.5644281032998619,-0.07015861874264484
186.60000000000193,25.19844863500419,0.5665187400781848,-0.07315425408631793
187.80000000000194,25.31254068396691,0.5704752420031795,-0.07672867521228532
189.00000000000196,25.426010668773444,0.5718567018968603,-0.07936931489374555
190.20000000000198,25.54089859288476,0.5759471526489133,-0.08199681847512341
191.400000000002,25.654300321850833,0.576494114784063,-0.08579438877746348
192.600000000002,25.767739692766824,0.5815873708152111,-0.08805913858450465
193.80000000000203,25.88080816716601,0.5859241363223185,-0.08994426334855499
195.00000000000205,25.995362072655276,0.5883537900569658,-0.0918861007127445
196.20000000000206,26.107724269192158,0.5921020794286467,-0.09453371475876482
197.40000000000208,26.221965191767833,0.5961375375831861,-0.09715277769003183
198.6000000000021,26.335537796955524,0.601749333099735,-0.09943213961623032
199.80000000000211,26.446927362705637,0.6037448425588252,-0.10114673127991924
201.00000000000213,26.563569198048775,0.6099211878095395,-0.10242994746161838
202.20000000000215,26.677493441671512,0.6127694321017011,-0.10373332574511673
203.40000000000217,26.79064926571925,0.6177858306221167,-0.10509582558512554
204.60000000000218,26.90343901078979,0.6234854991087768,-0.10636975242359847
205.8000000000022,27.01766265434548,0.6287018458360116,-0.10903470286052253
207.00000000000222,27.132847364209965,0.6355148703502951,-0.11350862277476903
208.20000000000223,27.245158559383317,0.6402803036266163,-0.1138349070245126
209.40000000000225,27.359263539881717,0.6500896708162434,-0.11650921108072909
210.60000000000227,27.47286170165794,0.6567652802059025,-0.12096072993496243
211.80000000000229,27.586204109068543,0.6660803397331488,-0.12217235335237664
213.0000000000023,27.702488530791367,0.6737127853644936,-0.12481889194204854
214.20000000000232,27.81469622309505,0.6866260765101506,-0.1262301616620598
215.40000000000234,27.928908238608333,0.6956451501164307,-0.12747102709680913
216.60000000000235,28.042939761511594,0.7070420631741051,-0.13008536448692398
217.80000000000237,28.156481105466156,0.7218426134861611,-0.13276566230251463
219.0000000000024,28.269796989335383,0.7335285456323132,-0.13403403615037046
220.2000000000024,28.384846921730063,0.7477013078855042,-0.13666978046573908
221.40000000000242,28.498422096233966,0.7618732831890366,-0.14068792537731545
222.60000000000244,28.611689282977927,0.7757537497811889,-0.1433970147096555
223.80000000000246,28.72704161891197,0.7939145542263554,-0.14801021235877654
225.00000000000247,28.84047639893281,0.8101755535619797,-0.14996593087493615
226.2000000000025,28.954396023648673,0.827189873969284,-0.15406979114364994
227.4000000000025,29.0686376881065,0.8446153893663391,-0.15621040195459868
228.60000000000252,29.18095331949785,0.8661651291001624,-0.15882479072072364
229.80000000000254,29.297418642802644,0.885703309593756,-0.1604916021109517
231.00000000000256,29.410660870816958,0.9108935625880833,-0.1675597786971914
232.20000000000258,29.525914998851754,0.9362736873986289,-0.17066557094758839
233.4000000000026,29.63890847806178,0.9653691034525489,-0.17476361119283057
234.6000000000026,29.753802541029252,0.9965684198118293,-0.1791558417530652
235.80000000000263,29.86759095882659,1.0308834066386352,-0.18339010358344598
237.00000000000264,29.981830845356647,1.0677517253987783,-0.18799704876166023
238.20000000000266,30.096207462009946,1.1102985727368333,-0.19353191666613823
239.40000000000268,30.21100401970946,1.1522715835716741,-0.19938930112863495
240.6000000000027,30.32579781399983,1.199404940269291,-0.2068309661401826
241.8000000000027,30.44069767412155,1.2532781993908655,-0.210179241501542
243.00000000000273,30.552077599243592,1.3039743041723866,-0.21766959694204768
244.20000000000275,30.669628207173893,1.3650386967514727,-0.22384681140112184
245.40000000000276,30.783907732415162,1.4239604002305222,-0.231149734408445
246.60000000000278,30.898679834605108,1.4917799331099477,-0.23772359664724751
247.8000000000028,31.01157773901679,1.5590074432749506,-0.2468932977674192
249.0000000000028,31.128495744236723,1.6283795629473439,-0.2563082146988731
250.20000000000283,31.243549872265653,1.703474421675538,-0.2646565631898481
251.40000000000285,31.35907560090122,1.7804135126982996,-0.2717365732977024
252.60000000000286,31.47366478551954,1.8584429027495626,-0.281796075441032
253.80000000000288,31.587860528888072,1.9410534921174543,-0.29339101898559106
255.0000000000029,31.705054657981513,2.0266416873726283,-0.3055668550269157
256.2000000000029,31.819333587228087,2.111750335343997,-0.3182832215786031
257.40000000000293,31.934461196844595,2.1980687683887634,-0.32994415706780567
258.600000000003,32.050869342707315,2.287432690705428,-0.3440457825193577
259.80000000000297,32.16610710869386,2.3803147484489364,-0.35739143015194674
261.00000000000296,32.28105925180956,2.4694195181774434,-0.36864715918123325
262.200000000003,32.39609383197784,2.5617610301665614,-0.3829822046786795
263.40000000000305,32.51144122044155,2.654016103221808,-0.3988205581851494
264.60000000000304,32.627597941435106,2.747108288942745,-0.41551483901493436
265.800000000003,32.74267448735541,2.8422578409468073,-0.43062751831996193
267.00000000000307,32.85932564547817,2.939056953387617,-0.44871717098191644
268.2000000000031,32.974356251716415,3.037195969527118,-0.4677799227929742
269.4000000000031,33.089499101967675,3.1354840426660937,-0.48608671203719434
270.6000000000031,33.20272954701159,3.2308855155712877,-0.5056310079809734
271.80000000000314,33.32069194429522,3.333264966084404,-0.5254636565850048
273.0000000000032,33.436707076098585,3.4304839447382482,-0.5459541561636891
274.2000000000032,33.5521672278803,3.529765779955054,-0.5693235501293095
275.40000000000316,33.66734975460501,3.6249364266708053,-0.5913624663436701
276.6000000000032,33.78297201296888,3.7158864965054432,-0.6179003013266473
277.80000000000325,33.89884358682049,3.800118514268844,-0.6411755717630725
279.00000000000324,34.01458377594671,3.87255314712604,-0.6683617553231351
280.20000000000323,34.12999894262497,3.932052544520042,-0.6956998986316392
281.4000000000033,34.24604819509171,3.9669543240830456,-0.720064611129053
282.6000000000033,34.36010523735246,3.970703743640565,-0.7487652966655842
283.8000000000033,34.47662235726786,3.9291331867781847,-0.7760961617633888
285.0000000000033,34.59149977013636,3.8158557214159763,-0.8029667660121143
286.20000000000334,34.70580291970598,3.5956081581056103,-0.8289019317765867
287.4000000000034,34.82000099087155,3.2198375724242014,-0.8548804599126858
288.6000000000034,34.93125672987428,2.6571077105170526,-0.8757575085453273
289.80000000000337,35.04477402555421,2.0446231243657107,-0.8916089167198202
291.0000000000034,35.15507470713882,1.613666314977109,-0.9079404356205703
292.20000000000346,35.266222977587944,1.3552733782351956,-0.9237372826766506
293.40000000000344,35.37842967744344,1.2058736738564695,-0.936419954834077
294.60000000000343,35.49027530328565,1.1178065900038043,-0.9503118673352016
295.8000000000035,35.60231066060559,1.0579888615357915,-0.9647476578757548
297.0000000000035,35.71535355921979,1.0147623604500486,-0.9774043616341719
298.2000000000035,35.829044623372056,0.9754091799780971,-0.9897982403227408
299.4000000000035,35.94271394242984,0.9439003583028167,-1.0032483184010474
300.60000000000355,36.05497041230293,0.9119040478399018,-1.0163939921638208
301.8000000000036,36.167856719082636,0.882189101597004,-1.0265589824145174
303.0000000000036,36.28186625107001,0.8535279325016272,-1.0396727617728856
304.20000000000357,36.397093974362456,0.8238781201869115,-1.0511459479916438
305.4000000000036,36.510261011472124,0.793286421051266,-1.0601981037287884
306.60000000000366,36.622009297855776,0.765613834099147,-1.0685436520640228
307.80000000000365,36.73588065820589,0.7364201703612621,-1.0790430770869102
309.00000000000364,36.85377819035959,0.7110172157708593,-1.0886509746190618
310.2000000000037,36.96705885314287,0.6892092029279531,-1.0933602116333718
311.40000000000373,37.08151977077884,0.6675357537976034,-1.1013130398735687
312.6000000000037,37.19534600190448,0.6492379316039666,-1.1072622078104342
313.8000000000037,37.31000094535636,0.6348558840374157,-1.1132889816861322
315.00000000000375,37.42489576534169,0.6249574184572814,-1.1185079956484967
316.2000000000038,37.539014298434054,0.6131137546820769,-1.1249499659185789
317.4000000000038,37.65479684534393,0.6066563547458453,-1.1324677530499967
318.6000000000038,37.76836176298472,0.6016916217590141,-1.138316747255586
319.8000000000038,37.88364842484685,0.5966204274721361,-1.1426487696924492
321.00000000000387,37.99885480637067,0.5959947443725928,-1.1474245057812045
322.20000000000385,38.113270050012396,0.5933106158646927,-1.1563912857700998
323.40000000000384,38.22964999674108,0.5927859790067923,-1.1623585300308346
324.6000000000039,38.34328497523444,0.593580256479785,-1.1676701860851084
325.80000000000393,38.45814016184027,0.5915052160305961,-1.1719614088241586
327.0000000000039,38.572368476161806,0.5927960625386041,-1.1777315986430508
328.2000000000039,38.68970636292138,0.5947034958059927,-1.1846321099813881
329.40000000000396,38.80408459564552,0.5961906947715437,-1.192275813324616
330.600000000004,38.919409209563,0.5959003627936305,-1.1975597624502443
331.800000000004,39.03504698775077,0.5972530512448971,-1.2076789326932102
333.000000000004,39.14753974287702,0.5989086352585906,-1.212515612892334
334.200000000004,39.26465014307063,0.5994530167855028,-1.2179080470836512
335.40000000000407,39.38000098698642,0.6023229756495154,-1.2258399014552355
336.60000000000406,39.494525925867656,0.6049811090256668,-1.2338365925749941
337.80000000000405,39.6109907907297,0.6059211487501275,-1.2418933939749768
339.0000000000041,39.72578004248695,0.6054603683147792,-1.2470078110009606
340.20000000000414,39.84238803170883,0.6118798785440176,-1.258420383960849
341.4000000000041,39.95764896754551,0.613406807602215,-1.2656077694568233
342.6000000000041,40.07330088672094,0.6160319523087058,-1.274034806796383
343.80000000000416,40.18780586884398,0.6181685539786361,-1.2821298742842444
345.0000000000042,40.30319660348653,0.6211014292283226,-1.2907924537569762
346.2000000000042,40.42091628257652,0.6251755830433784,-1.3016421279621309
347.4000000000042,40.536781833968725,0.6275561493473262,-1.3074785269577647
348.60000000000423,40.652469541381784,0.6341532073886421,-1.318250397915472
349.8000000000043,40.76841579392715,0.638082845176333,-1.3279242400942266
351.00000000000426,40.88334242767868,0.6434568145709779,-1.3369269068518856
352.20000000000425,40.99950584903113,0.6469645729815529,-1.3465785998180686
353.4000000000043,41.115524040458794,0.6503025807129135,-1.3541279258407855
354.60000000000434,41.23236404548051,0.6548052127242405,-1.3642784771310645
355.80000000000433,41.34808728501272,0.6612996492746523,-1.3756845531617534
357.0000000000043,41.464480502384305,0.6664816272212419,-1.3899749743152263
358.20000000000437,41.578815282762186,0.6729152238149051,-1.399960570561201
359.4000000000044,41.6953997054562,0.6754282925955739,-1.411410609551928
360.6000000000044,41.81126918421825,0.6846987936513265,-1.4226856035466864
361.8000000000044,41.92817380448163,0.6926178150318425,-1.4344712640909747
363.00000000000443,42.04329373257292,0.6953464582069367,-1.4472047425022803
364.2000000000045,42.1603597009281,0.7034360754979979,-1.4608104100552803
365.40000000000447,42.276925792788134,0.7114760545158694,-1.4741467369847863
366.60000000000446,42.39161086111374,0.7159416938670642,-1.4876761781453363
367.8000000000045,42.50825765866314,0.7225723766990103,-1.502185659423945
369.00000000000455,42.624670308245754,0.7311560359472922,-1.5158597084473913
370.20000000000454,42.741900525761395,0.7355289981117428,-1.5288278462356217
371.4000000000045,42.85781667426448,0.7429407513802683,-1.544632589820623
372.60000000000457,42.973764559192716,0.7486789264492854,-1.5601190351731562
373.8000000000046,43.090000956298056,0.752490771190857,-1.5747301465153796
375.0000000000046,43.20555206750203,0.7590420064336287,-1.5907673465817993
376.2000000000046,43.32220176573106,0.762721672589631,-1.6075326070153206
377.40000000000464,43.43969434708474,0.7675015454539245,-1.6244365402603007
378.6000000000047,43.553903326510266,0.7711184580789886,-1.6419613864308755
379.8000000000047,43.67097030571791,0.7724316571711282,-1.6575985243245812
381.00000000000466,43.78673926029538,0.7735452398612775,-1.676582825621912
382.2000000000047,43.90425864733966,0.7739280574953563,-1.691178234106336
383.40000000000475,44.02068916526802,0.772554087066458,-1.7089707544164519
384.60000000000474,44.13658762158929,0.7705821489146976,-1.7278171527266215
385.80000000000473,44.252971242988366,0.7683806817310919,-1.744327835561411
387.0000000000048,44.369906632609286,0.7628524260041303,-1.7628828645727306
388.2000000000048,44.48613558312863,0.7604519735548493,-1.780655154249358
389.4000000000048,44.602484658608354,0.7539821977107722,-1.7977371464297027
390.6000000000048,44.71869607240442,0.745512006600562,-1.8153693822937598
391.80000000000484,44.836501555483636,0.7377117958707005,-1.831016369764631
393.0000000000049,44.95215517008338,0.7258685524775137,-1.8474958259059355
394.2000000000049,45.06936344143422,0.71450670820968,-1.8632915159270058
395.40000000000487,45.18576888838694,0.7022536493225364,-1.8808168756205195
396.6000000000049,45.301494589806815,0.6886667869700158,-1.8954973277136284
397.80000000000496,45.41943842926325,0.6751272162352218,-1.9097360285932892
399.00000000000495,45.53521922134013,0.6623483696817325,-1.9243719046463648
400.20000000000493,45.65147689816345,0.6439412979193935,-1.9399336776940874
401.400000000005,45.76805925155116,0.629091837639698,-1.9534959509648848
402.600000000005,45.88578803962775,0.6095844304485953,-1.9666527341254754
403.800000000005,45.999686067030794,0.59145671058574,-1.9805613220868823
405.000000000005,46.1181712400527,0.573182896236871,-1.9918505925326468
406.20000000000505,46.235377313124246,0.5546831189522995,-2.0023115855527838
407.4000000000051,46.351646699022844,0.5369008394325981,-2.0130057831677353
408.6000000000051,46.468444329600494,0.5216408623027314,-2.0245540870086685
409.80000000000507,46.585102333886816,0.5003797691188838,-2.0350700918320466
411.0000000000051,46.701207728453504,0.4852185323963225,-2.0421136369337467
412.20000000000516,46.81875725596507,0.466084358471275,-2.051848205757322
413.40000000000515,46.93625805829131,0.453584636219935,-2.05842636221004
414.60000000000514,47.0512051592581,0.43577194736288455,-2.067882885952696
415.8000000000052,47.1692503602554,0.4241778674368863,-2.0740565445998422
417.00000000000523,47.28667642222259,0.40864570740480083,-2.0808900403074384
418.2000000000052,47.40268357687525,0.3959068411160973,-2.0858451073335234
419.4000000000052,47.51895923056091,0.3846280724718395,-2.090654562334988
420.60000000000525,47.63628477186301,0.3732419131384246,-2.0966419789085826
421.8000000000053,47.75472136148476,0.36067113288282476,-2.1027524460204887
423.0000000000053,47.871616598060626,0.3519610475764703,-2.1081495650308093
424.2000000000053,47.98810067368354,0.3413130989599308,-2.1120620699817687
425.4000000000053,48.10524627547451,0.32972207098560147,-2.1160724322076563
426.60000000000537,48.22114275011479,0.32613272061968235,-2.11882206692949
427.80000000000535,48.338680064638844,0.320525202297419,-2.1220961771239164
429.00000000000534,48.454803792140744,0.3132208799467331,-2.123776029285696
430.2000000000054,48.571820806359206,0.30717872742604624,-2.125609019970662
431.40000000000543,48.6889497169401,0.302672328779091,-2.128225304592405
432.6000000000054,48.80602631039288,0.2957281114512579,-2.130154568857094
433.8000000000054,48.923715809278775,0.2947934172748319,-2.1335305504540694
435.00000000000546,49.04009109286482,0.2928646542855716,-2.136266572657322
436.2000000000055,49.15698708417502,0.2884711309160195,-2.1382402476794624
437.4000000000055,49.27428991934421,0.2885456982955372,-2.139298075079611
438.6000000000055,49.39147545970767,0.2864293647615194,-2.1423217162390924
439.8000000000055,49.51000090307082,0.28311305717246565,-2.1428615424119477
441.00000000000557,49.62730892887329,0.2817003210619919,-2.142850086075665
442.20000000000556,49.74365810489187,0.2803482708405588,-2.1443611073919464
443.40000000000555,49.861838051952326,0.27930935611080066,-2.146809771045077
444.6000000000056,49.979212264233965,0.2788265319508618,-2.149041539513834
445.80000000000564,50.096671050845316,0.2752405103442651,-2.1494027545157346
447.0000000000056,50.2149132157939,0.27371430726126056,-2.152051493843463
448.2000000000056,50.332301475026476,0.27362385583280047,-2.153218272856329
449.40000000000566,50.44990221763463,0.2749516965547619,-2.156030159710026
450.6000000000057,50.567081334256265,0.2747052585849068,-2.1573501802773234
451.8000000000057,50.68479942014698,0.27332717760793457,-2.158712733703032
453.0000000000057,50.802301965960396,0.2737031767162128,-2.1613052298918554
454.20000000000573,50.92053600547193,0.27077547340914254,-2.1613018891788993
455.4000000000058,51.03851511099729,0.27073739883485615,-2.163820742183822
456.60000000000576,51.15580815084418,0.270477903345136,-2.1653845416383857
457.80000000000575,51.273724639602165,0.2716352518312094,-2.165591468594527
459.0000000000058,51.391387117766,0.2706557839552044,-2.166900058786007
460.20000000000584,51.508981223239815,0.2699161221650176,-2.168210480758325
461.40000000000583,51.62656582780751,0.2697559125825389,-2.1695300755262643
462.6000000000058,51.74365513037,0.27086562284139115,-2.170852103849301
463.80000000000587,51.86118034284378,0.26753485655001874,-2.171835148741077
465.0000000000059,51.97951414203437,0.2682867619445839,-2.1718356977589433
466.2000000000059,52.097430948338946,0.2684537647088693,-2.1745089898359984
467.4000000000059,52.21494699661935,0.26896632738053683,-2.177109532892566
468.60000000000593,52.33246611219947,0.26829355039814906,-2.1771018224351786
469.800000000006,52.45038860064235,0.26725372064761765,-2.1791139663619465
471.00000000000597,52.569098415753096,0.2702094840499511,-2.1806476205744456
472.20000000000596,52.686209030726,0.26766549128119893,-2.1824434707563922
473.400000000006,52.80403105355169,0.2694395456790116,-2.184533060761725
474.60000000000605,52.92197396385796,0.27041742287050186,-2.1850245443415717
475.80000000000604,53.039683519190305,0.2714404290655836,-2.185660178177213
477.000000000006,53.158151925106324,0.27091587502992964,-2.1883094424480043
478.20000000000607,53.276229233691154,0.27070480097590977,-2.189619917534759
479.4000000000061,53.3938460001476,0.2686845800251856,-2.190940266918656
480.6000000000061,53.51129940933891,0.269877571339013,-2.1922498792120413
481.8000000000061,53.629643053059105,0.26991201690289357,-2.192249879310548
483.00000000000614,53.747054394170696,0.27040582200459506,-2.1935724180637446
484.2000000000062,53.86551866368461,0.26909201899315016,-2.1955462162476853
485.4000000000062,53.98263886723481,0.2696765349392366,-2.195560070134655
486.60000000000616,54.100876740934844,0.266473380734223,-2.1968686490316136
487.8000000000062,54.21821851255494,0.26731167488699514,-2.198699757889917
489.00000000000625,54.337056812993126,0.26560669718664687,-2.202178670900706
490.20000000000624,54.455234360975965,0.267454788091287,-2.2034816278832814
491.40000000000623,54.5724671169735,0.26751072062667647,-2.204769838132738
492.6000000000063,54.69112630304497,0.26413242472080634,-2.206144395584152
493.8000000000063,54.80918204323445,0.26534792790262196,-2.205373920327247
495.0000000000063,54.92788922051456,0.26460470470626396,-2.20608986973991
496.2000000000063,55.04537609314499,0.2664396647619563,-2.2064597751762354
497.40000000000634,55.16391318375605,0.2627769996266657,-2.2087670091980844
498.6000000000064,55.28314590318149,0.26379676387966117,-2.20999232685733
499.8000000000064,55.4003612223023,0.2614791380933055,-2.211282603115146
501.00000000000637,55.51989983369951,0.26249070182445144,-2.212669627952285
502.2000000000064,55.63723875549773,0.2611945944650511,-2.213999824305663
503.40000000000646,55.75532770720244,0.2621428647699444,-2.2152836258301245
504.60000000000645,55.87414530435379,0.26252605568692433,-2.2166461067258987
505.80000000000643,55.992242658196005,0.26110013454616876,-2.21894869527722
507.0000000000065,56.11039405826165,0.26175001233621364,-2.2202758614531017
508.2000000000065,56.22983131102756,0.260648552810854,-2.2215701636974625
509.4000000000065,56.3489794204558,0.2601609454340199,-2.2228853915360958
510.6000000000065,56.466185874006264,0.25998263950532424,-2.222784299685596
511.80000000000655,56.58438054907021,0.25875437316148653,-2.2227799003058752
513.0000000000066,56.7031686333825,0.2579598533599974,-2.22409295209233
514.2000000000066,56.82121433627119,0.25713564086362684,-2.2263953125980445
515.4000000000066,56.940892297869674,0.25727242730365363,-2.227718642991304
516.6000000000066,57.058989575201906,0.2572847376571354,-2.2276607273685203
517.8000000000067,57.17716676677573,0.2565109815261867,-2.229455609530111
519.0000000000066,57.29635468696216,0.25573548369153143,-2.231670223704186
520.2000000000066,57.41492139952888,0.25527856428558227,-2.2316668930825854
521.4000000000067,57.53379465990009,0.25366278341998527,-2.234359242777585
522.6000000000067,57.65177061507711,0.25278463392236744,-2.2348083763851214
523.8000000000068,57.77065138316186,0.2521409987632764,-2.2362808329733634
525.0000000000067,57.88860045651922,0.25176656874680015,-2.2375756262826907
526.2000000000068,58.00716499776879,0.24970768371658209,-2.2372811579359313
527.4000000000068,58.12544545461207,0.24755539818035133,-2.2376261425394937
528.6000000000067,58.24329030208351,0.24726714882328515,-2.237527292296033
529.8000000000068,58.363174924779315,0.24396466315917992,-2.240255870660062
531.0000000000068,58.479620554249436,0.2421153128982756,-2.2421757080684253
532.2000000000069,58.60010583293286,0.2434093159472033,-2.2435300230459356
533.4000000000069,58.71941237594343,0.24195170328195653,-2.2451333772496147
534.6000000000068,58.83865086567573,0.23962332294801003,-2.247480221026345
535.8000000000069,58.95798759601697,0.23845765154139792,-2.248800172849484
537.0000000000069,59.075386422302245,0.23533346632716107,-2.2487631131790367
538.2000000000069,59.19405579196961,0.23464127626255354,-2.249349600920535
539.4000000000069,59.31234819286329,0.2330555867181343,-2.2507937235541324
540.600000000007,59.43230666220144,0.23221837558904895,-2.252089959242584
541.800000000007,59.548476662575546,0.2322840588129854,-2.253404447384192
543.000000000007,59.67010169070971,0.2326126355844567,-2.25311600321372
544.200000000007,59.788863126357285,0.23349353739900305,-2.2534127947168887
545.400000000007,59.90696410674735,0.23474453552456537,-2.2560447929239316
546.6000000000071,60.026993300527266,0.24040521092541556,-2.257358975456513
547.800000000007,60.145888794893544,0.2417404611587895,-2.258680153347144
549.000000000007,60.264697683675394,0.2434720628601494,-2.2600248606355064
550.2000000000071,60.383164793636375,0.2431920927974232,-2.260989851682589
551.4000000000071,60.501638371752705,0.24336894808963205,-2.2596687158648567
552.6000000000072,60.62029888514594,0.2430917120385316,-2.258628524259244
553.8000000000071,60.73902608114755,0.2428835472281959,-2.2646450795961535
555.0000000000072,60.858493535985275,0.2421455885770071,-2.267019548152085
556.2000000000072,60.97712603443855,0.23969762496912994,-2.265822131736246
557.4000000000071,61.09526777500494,0.23932676759517638,-2.2643984708980227
558.6000000000072,61.21419792998283,0.23846760141682266,-2.2657003113124508
559.8000000000072,61.33291184195421,0.23566365052822968,-2.2670204016410263
561.0000000000073,61.45183127107765,0.23475506931643997,-2.265772385572932
562.2000000000073,61.570467482091814,0.2315112704815214,-2.268330079194108
563.4000000000073,61.690101485349196,0.2323776023016942,-2.2683300694274298
564.6000000000073,61.808464643110426,0.233302458160952,-2.2696456435199726
565.8000000000073,61.927138229511094,0.22957049706771754,-2.272348473575121
567.0000000000073,62.04671741698103,0.227782870231237,-2.2719600863379803
568.2000000000073,62.16563240514736,0.22747606873104667,-2.2736855744128945
569.4000000000074,62.284143296884075,0.2226648583102447,-2.276240423283731
570.6000000000074,62.40318422267598,0.2225108534812517,-2.273627212333818
571.8000000000075,62.52262354734489,0.21524344682486915,-2.2736098430009717
573.0000000000074,62.64191341553805,0.21216656460670594,-2.273608094946047
574.2000000000074,62.759474959596886,0.20803631060323727,-2.2739437707060275
575.4000000000075,62.88083349871888,0.20400164791665254,-2.2765743847564988
576.6000000000074,63.00020297237196,0.2000119433778596,-2.2765708191285623
577.8000000000075,63.11876214564983,0.19403085524392277,-2.2781292893197165
579.0000000000075,63.23924658255931,0.18947474877266873,-2.279216360203923
580.2000000000075,63.35791552373642,0.18560606327087062,-2.278876489009382
581.4000000000076,63.47723192162288,0.1802297710806338,-2.280186578717136
582.6000000000075,63.59696404977655,0.17874370836815973,-2.280145029916821
583.8000000000076,63.71420553391686,0.17334646481153687,-2.278868119541965
585.0000000000076,63.83453272880035,0.1669178096977031,-2.2821349625040828
586.2000000000075,63.95336915069113,0.16131125727800455,-2.2842347458414767
587.4000000000076,64.07162580257004,0.15530142022851512,-2.284150071141151
588.6000000000076,64.19304588124348,0.15002337972048577,-2.283819926932341
589.8000000000077,64.31137118357921,0.1474527098568735,-2.2849945399922285
591.0000000000077,64.43117617976876,0.1431008581524457,-2.2864599728222346
592.2000000000077,64.55194288026196,0.13780234881763542,-2.2851400365385404
593.4000000000077,64.67149342944131,0.13327037105733724,-2.2839295892836518
594.6000000000078,64.79052661474427,0.13037296018622188,-2.282828990445328
595.8000000000077,64.90815866851872,0.12414386984533154,-2.282795210182112
597.0000000000077,65.02922794052901,0.11868408054524154,-2.2854611670694434
598.2000000000078,65.14882489649492,0.11294022173451629,-2.288100073809548
599.4000000000078,65.26906652689242,0.11224230410285,-2.2894111158256862
600.6000000000079,65.38797725439706,0.11109975686849938,-2.289412602397401
601.8000000000078,65.50664282300562,0.10542367964579225,-2.2884784945271206
603.0000000000078,65.62612937032236,0.09971122842820213,-2.2884108677599153
604.2000000000079,65.74633056742273,0.09792057753081135,-2.2887601560292348
605.4000000000078,65.86659010850627,0.09610592681856495,-2.288760176978906
606.6000000000079,65.98422837311513,0.09593035701512248,-2.2900300576417214
607.8000000000079,66.10332151489203,0.09166787946526683,-2.290781683436678
609.000000000008,66.22180391901169,0.08825121958601057,-2.2900856931448335
610.200000000008,66.34302275471894,0.09004782210123596,-2.2913937173563244
611.4000000000079,66.46187543703711,0.08850714215311961,-2.2910699020923095
612.600000000008,66.58215588573181,0.08793217994141261,-2.292186478893356
613.800000000008,66.70199430806717,0.08931675927102384,-2.2909077224412853
615.000000000008,66.82000000000075,0.08863899813502313,-2.291071950548066
616.200000000008,66.94099428943804,0.09126716947380803,-2.2923843844171303
617.400000000008,67.06029670046553,0.09282740755875296,-2.293710442343613
618.6000000000081,67.18021387477603,0.09444620653535502,-2.2936998322025337
619.8000000000081,67.29940848358774,0.09628154933776012,-2.293699781948693
621.0000000000081,67.41812593334916,0.09851514710623535,-2.292379829628682
622.2000000000081,67.53837352495144,0.10011805936397536,-2.291074894938248
623.4000000000082,67.6582521277947,0.09952156934742695,-2.291055653900114
624.6000000000081,67.77681516702799,0.10001490701775886,-2.2917660790012646
625.8000000000081,67.89607657584337,0.10335369329470778,-2.2933582087939137
627.0000000000082,68.01605242209915,0.10310708023504803,-2.292405751425388
628.2000000000082,68.13634102530875,0.1053050797120822,-2.295028252045897
629.4000000000083,68.25389861199609,0.10367208109384118,-2.295010393354969
630.6000000000082,68.37498902314294,0.10573047811753467,-2.2937377517424173
631.8000000000083,68.4946763494198,0.10573733081029354,-2.295010309489843
633.0000000000083,68.61451855198919,0.10861596168312304,-2.2950095054182094
634.2000000000082,68.73488083266761,0.10889418440211801,-2.2954173950542645
635.4000000000083,68.85191232251215,0.11234405674737885,-2.298970045851123
636.6000000000083,68.97249061612742,0.11272737354929097,-2.2976501662479083
637.8000000000084,69.09333771192259,0.11468572982068007,-2.2997487224278266
639.0000000000084,69.21221937425004,0.11640732882365487,-2.300326508976835
640.2000000000083,69.33223775946725,0.11874550226950417,-2.2965593669225512
641.4000000000084,69.45216869699976,0.11566829049973973,-2.296560266506359
642.6000000000084,69.57216377489819,0.11880632965475546,-2.2968869305165414
643.8000000000084,69.69094302405799,0.11879865838206374,-2.299522653173688
645.0000000000084,69.81000000000076,0.11873739859753621,-2.2977597058031236
646.2000000000085,69.930279026586,0.11741064853198577,-2.296440004012281
647.4000000000085,70.05116613624568,0.1213466839637701,-2.2977517601374897
648.6000000000085,70.17064826338691,0.1214640004288294,-2.2967516085265136
649.8000000000085,70.29042383463639,0.12218199229644897,-2.300214323437542
651.0000000000085,70.40897362870174,0.12006092605004112,-2.299482621478595
652.2000000000086,70.52940150023115,0.11767079744735537,-2.3008403292086306
653.4000000000085,70.64790585996676,0.117429611351832,-2.299520208235835
654.6000000000085,70.76670964933346,0.11614290653684578,-2.299511883418009
655.8000000000086,70.88939853988835,0.11444376927354999,-2.2969055703182324
657.0000000000086,71.00704487621842,0.11553816352607324,-2.2995623743168077
658.2000000000087,71.12895529319559,0.11268056723395461,-2.2995099060080584
659.4000000000086,71.24877487740709,0.11335615298436785,-2.2995099107831045
660.6000000000087,71.36806727191528,0.1121121369953266,-2.300766525233814
661.8000000000087,71.48772805849937,0.10933940660410946,-2.2998682807833637
663.0000000000086,71.60775452102123,0.11002342673762994,-2.298577602531204
664.2000000000087,71.72702744562736,0.11000918440834578,-2.2985264463541624
665.4000000000087,71.84800750659183,0.10809624650637248,-2.301159310989595
666.6000000000088,71.96778987573911,0.10696726721043531,-2.3011778074816407
667.8000000000088,72.08676126437246,0.11071537261632836,-2.3011667208101017
669.0000000000088,72.20742866325516,0.11098442653509447,-2.2999011036919255
670.2000000000088,72.32662653108123,0.11041711745791183,-2.2989718569571043
671.4000000000088,72.44672413074194,0.1083104758299546,-2.2972617233049064
672.6000000000088,72.56716234633669,0.10840875146509951,-2.296878208780604
673.8000000000088,72.68722100968182,0.10603340966115324,-2.2979273012077766
675.0000000000089,72.80660697578558,0.10278507140770032,-2.302425883938517
676.2000000000089,72.9268375406677,0.10231907642897306,-2.301702325503741
677.400000000009,73.04694486120277,0.09769133934264992,-2.3011598190558393
678.6000000000089,73.16644176517023,0.09508599141514201,-2.3011725378834083
679.8000000000089,73.28657013350382,0.0908630713796211,-2.3038592998042122
681.000000000009,73.40745954930426,0.08575489220845606,-2.3015117158150664
682.2000000000089,73.52712582998402,0.08436289105215414,-2.3028084349786972
683.400000000009,73.64766655363212,0.0800673185822216,-2.3018200517509815
684.600000000009,73.76740908889565,0.07721087327900492,-2.301542670503554
685.800000000009,73.88618752086765,0.07464878714056955,-2.3024190349334654
687.0000000000091,74.00660878943037,0.07363954459196395,-2.302810005520326
688.200000000009,74.12793484946496,0.07456915639618295,-2.3020863492109553
689.4000000000091,74.24633119076208,0.07025426509159366,-2.302111824837082
690.6000000000091,74.36860579075442,0.07207827242140408,-2.3045182692016697
691.800000000009,74.48837501090671,0.07153275170719564,-2.3030331654468923
693.0000000000091,74.6082275270721,0.06851878146097695,-2.300542985715139
694.2000000000091,74.72748816594826,0.06817296403582218,-2.300719896627842
695.4000000000092,74.84921074948075,0.06916333058904023,-2.299396396404204
696.6000000000092,74.96923698194244,0.06565744415511288,-2.3000090137974194
697.8000000000092,75.08980132371866,0.06488655074360755,-2.2967701741896605
699.0000000000092,75.20836664391835,0.06482544636856752,-2.2986081727736236
700.2000000000093,75.32949003329549,0.06603496288916233,-2.30038948468835
701.4000000000092,75.44990586610076,0.06803422046550156,-2.3020362395417666
702.6000000000092,75.56942299324902,0.06562375878888371,-2.3046800947800996
703.8000000000093,75.69090153714626,0.061312111412089976,-2.305990226275174
705.0000000000093,75.8097890074854,0.058766338860938905,-2.3037060566218726
706.2000000000094,75.93026418234473,0.059949889605971696,-2.303373001467403
707.4000000000093,76.0507602006156,0.05332484399501075,-2.3010501182606884
708.6000000000093,76.17058751539315,0.04718965107291162,-2.302369689347643
709.8000000000094,76.29151367673768,0.050180056157325015,-2.3010498080592603
711.0000000000093,76.411559038473,0.04634269920976536,-2.3010499792724657
712.2000000000094,76.53231725713951,0.043799093678948575,-2.2982295262823675
713.4000000000094,76.65168062495032,0.04213187204650626,-2.297098954682041
714.6000000000095,76.77178784241345,0.03855462813258259,-2.297108158729264
715.8000000000095,76.8923538863473,0.04176734463446419,-2.299740886636208
717.0000000000094,77.01298087679928,0.04118098600606179,-2.301050968489243
718.2000000000095,77.1335955148325,0.039359685139139955,-2.3037984336076054
719.4000000000095,77.25377561719166,0.034684565146564095,-2.303785201029656
720.6000000000095,77.37305244633005,0.03410227582608727,-2.302532250523966
721.8000000000095,77.49427681173003,0.028592699020611345,-2.3012638232784663
723.0000000000095,77.61477760662682,0.030462108899282303,-2.2998208377010996
724.2000000000096,77.73550361835576,0.030038919811844755,-2.302026907569128
725.4000000000096,77.85507311393428,0.027756461286602807,-2.304712184186912
726.6000000000096,77.97608480953535,0.022827705177320357,-2.3033677289536922
727.8000000000096,78.09696303371797,0.01939647034771652,-2.3057437550708038
729.0000000000097,78.21695234999437,0.01821761590116666,-2.303603507105777
730.2000000000096,78.33771190448779,0.020102234861576807,-2.3038142075604493
731.4000000000096,78.45749072729723,0.02122735951496113,-2.3020462692175476
732.6000000000097,78.57855552911968,0.024597331385481425,-2.30500804466982
733.8000000000097,78.69819105111235,0.02108070748865748,-2.3050009050579474
735.0000000000098,78.81947254368347,0.021673219883610373,-2.3020903575167244
736.2000000000097,78.93941493804283,0.021696604156766275,-2.302361780374525
737.4000000000098,79.06018286324657,0.020071663018277452,-2.3040160715205835
738.6000000000098,79.18095074549122,0.018857246955343854,-2.30566872769617
739.8000000000097,79.29964483761103,0.015421934483566602,-2.304236263044868
741.0000000000098,79.42128041716461,0.01407560489744586,-2.301599705837965
742.2000000000098,79.54136196440967,0.016160070694337836,-2.302917953324889
743.4000000000099,79.66136383834966,0.018411425701400697,-2.3003629690673453
744.6000000000099,79.78221971350663,0.01855180643352433,-2.304228861814405
745.8000000000098,79.90236627100127,0.01638594229949153,-2.3055420900308965
747.0000000000099,80.02284061202408,0.01572626154764689,-2.306968614903731
748.2000000000099,80.14341801466037,0.014479998728084587,-2.3074876434857425
749.4000000000099,80.2640380900837,0.015557250216218788,-2.3062131269681148
750.6000000000099,80.38434180774111,0.008219512108857019,-2.305550151305102
751.80000000001,80.50443505047258,0.010978316427027235,-2.3055183435533495
753.00000000001,80.62591573073779,0.009880533466119057,-2.305550161827255
754.20000000001,80.74591324543499,0.01416808966857197,-2.3042298496688454
755.40000000001,80.86723660321259,0.013184918003710966,-2.302913708151465
756.60000000001,80.98859371722533,0.013834380637012866,-2.3051237325259444
757.8000000000101,81.10959365262464,0.01472001791102373,-2.306081418923662
759.00000000001,81.23021129739182,0.010666605884923519,-2.3066603255645135
760.20000000001,81.35084209699076,0.01142706449753933,-2.30731365783021
761.4000000000101,81.4717389741906,0.010525878170589309,-2.30708046519883
762.6000000000101,81.59175786176137,0.007936464419818767,-2.3074000057621546
763.8000000000102,81.71367697003105,0.009537858754718409,-2.307974664434574
765.0000000000101,81.83428911886351,0.009152157700485164,-2.3080465221932362
766.2000000000102,81.95477389346061,0.0031969874560722755,-2.305340715547886
767.4000000000102,82.075373802793,-0.0008108412458627812,-2.304679985598985
768.6000000000101,82.19554767111549,-0.004376591975772781,-2.3060526037408806
769.8000000000102,82.31639303903779,-0.011656170100148189,-2.3059810216634116
771.0000000000102,82.43740948952357,-0.010642182503104447,-2.307294989801235
772.2000000000103,82.55739623768541,-0.019362015770090835,-2.3059900322569966
773.4000000000103,82.677158164724,-0.02246565495913999,-2.3046873594801904
774.6000000000103,82.79702856490009,-0.029272757165980545,-2.3047943285635863
775.8000000000103,82.91736041887047,-0.029730502339377796,-2.3094742964252317
777.0000000000103,83.03986955998094,-0.03266283849594387,-2.3092943253152485
778.2000000000103,83.15967878914671,-0.038061853017195224,-2.3086288844063825
779.4000000000103,83.27945624246263,-0.03799050254045028,-2.3072881555339744
780.6000000000104,83.4005921031815,-0.03947216782688939,-2.3073098926886417
781.8000000000104,83.5218679818546,-0.03737303951159332,-2.3076717249324132
783.0000000000105,83.64192864389874,-0.03976842123832636,-2.308606742403599
784.2000000000104,83.76199627322525,-0.05032196100382713,-2.3086146756111146
785.4000000000104,83.88314496536674,-0.052663149548702326,-2.3089598690697666
786.6000000000105,84.0041435514709,-0.05602833418124309,-2.3089598690000006
787.8000000000104,84.12371848837803,-0.06020194355942621,-2.308959868509471
789.0000000000105,84.2426165104965,-0.06170066456704276,-2.309926545166311
790.2000000000105,84.36557006633669,-0.06080412515800726,-2.3085312107164633
791.4000000000106,84.48654562535631,-0.06725997086820978,-2.3086377658626485
792.6000000000106,84.60669942580301,-0.0718694953832652,-2.304666544855412
793.8000000000105,84.72808091312145,-0.0728168238980263,-2.306004068086116
795.0000000000106,84.84920127628163,-0.0737452782584665,-2.310027895316261
796.0000000000106,84.9489451408754,-0.08045305792336649,-2.3120432829138284