File: 01_Data/Nylon_Carpet_High_Pile/STA/N2/10K_min/Nylon_Carpet_High_Pile_STA_N2_10KData_220308_R3.csv
##Temp./Â°C,Time/min,DSC/(mW/mg),Mass loss/mg
50.0,10.598798106348706,0.008487913602398756,-0.011875891265622496
51.20000000000002,10.99742645252887,0.053944981279196,-0.011508775124829729
52.400000000000034,11.235613352103071,0.08508634934009007,-0.010098731211722445
53.60000000000005,11.428039543132167,0.11058577012453086,-0.01060902855285173
54.80000000000007,11.599290549418427,0.13132416679378578,-0.012031701927547545
56.000000000000085,11.759141694252039,0.14627867405600692,-0.011025235462776006
57.2000000000001,11.90761102836562,0.15793919019156344,-0.01209304575638992
58.40000000000012,12.052654795815627,0.17103856105966764,-0.011613412466202178
59.600000000000136,12.194030732559625,0.1791305613894858,-0.011784639687244969
60.80000000000015,12.330610874221254,0.18526879223911819,-0.013287058756581427
62.00000000000017,12.46552087548742,0.190784614909976,-0.012607952135686329
63.20000000000019,12.59988210289162,0.1978203165475948,-0.013600344964077582
64.4000000000002,12.732361823953541,0.20257837055530536,-0.012282041931125143
65.60000000000022,12.864280591091518,0.2096054257474126,-0.012284661165430144
66.80000000000024,12.99356624146681,0.21122468813052686,-0.013039531421157324
68.00000000000026,13.123680523116972,0.21698494189798923,-0.012290135999038831
69.20000000000027,13.253490293604523,0.2182351140823352,-0.012938838483014248
70.40000000000029,13.381600479845824,0.22235398241135074,-0.013600337651139771
71.6000000000003,13.511144123154661,0.2251740941107605,-0.01360199985895072
72.80000000000032,13.637126951594556,0.22988005121820243,-0.013548875057434628
74.00000000000034,13.765306429092474,0.23408147953913816,-0.013578901414672995
75.20000000000036,13.889451399371806,0.23460373205857155,-0.014952091873273954
76.40000000000038,14.01620575321911,0.2365439877827069,-0.014895162234938919
77.60000000000039,14.141087183039279,0.2417148755816756,-0.0155985642976475
78.80000000000041,14.266272529513008,0.2432297475374473,-0.01624005877212431
80.00000000000043,14.390757125109323,0.2466764126583717,-0.01756244507614113
81.20000000000044,14.513720526026226,0.2503299837720808,-0.017582112855073273
82.40000000000046,14.636081819582573,0.2525895807805191,-0.016529465108523045
83.60000000000048,14.760359115085064,0.25651513519161406,-0.01623012028302684
84.8000000000005,14.881595704368182,0.25846519560058134,-0.017551598024788007
86.00000000000051,15.003748718130321,0.2595157051720809,-0.01754773906159901
87.20000000000053,15.12521322570866,0.26184296787513067,-0.017550069004049984
88.40000000000055,15.245746662808724,0.26435270719380816,-0.020055753494044648
89.60000000000056,15.367602565684924,0.2654073979596228,-0.017090663902473935
90.80000000000058,15.488094724912088,0.26612227840458325,-0.018439243508266312
92.0000000000006,15.607171892936355,0.2680660249098043,-0.018614582360699128
93.20000000000061,15.726655268481041,0.26739332870991345,-0.020739872359091915
94.40000000000063,15.847312336446603,0.2670517526624491,-0.02075383493066152
95.60000000000065,15.966082303505054,0.2714591009613386,-0.021171175387690866
96.80000000000067,16.085127952362992,0.2693398548332509,-0.02336007104727722
98.00000000000068,16.205085116136303,0.2671036914829363,-0.023356884284438273
99.2000000000007,16.323710417821836,0.26980969933752313,-0.02204014552114808
100.40000000000072,16.441529941776952,0.26848562933128006,-0.0220402228472536
101.60000000000073,16.55944439216378,0.2672802467651938,-0.023360371250987555
102.80000000000075,16.677819731966306,0.2678115542257259,-0.0246787775346613
104.00000000000077,16.795875800091537,0.26603177780007636,-0.02369925829523556
105.20000000000078,16.91352713509804,0.2635498495749148,-0.024248074604807268
106.4000000000008,17.032035812768083,0.26161139966401015,-0.023359780934919527
107.60000000000082,17.15072480828365,0.2637832256081567,-0.024674501739683663
108.80000000000084,17.26734470191572,0.26236431991952297,-0.025999803213660577
110.00000000000085,17.384640664142676,0.26096222556291665,-0.025969554835316266
111.20000000000087,17.50219927094026,0.26098036058115087,-0.02682925099488509
112.40000000000089,17.619888175680366,0.2649818345364191,-0.026002462770736035
113.6000000000009,17.738215115358315,0.2597939508639043,-0.02787276516490289
114.80000000000092,17.85565679791866,0.26102229425803714,-0.028630646663153403
116.00000000000094,17.971754292133593,0.2591791728403711,-0.02858267394089742
117.20000000000095,18.088925084336676,0.2610410700672173,-0.027456425403811657
118.40000000000097,18.207361955056214,0.25782621293698643,-0.028740091482113428
119.60000000000099,18.324244970775144,0.2588868738414581,-0.0287423369052493
120.800000000001,18.441045229598263,0.26038881226209476,-0.027419835856955732
122.00000000000102,18.559366438670672,0.25973435379124477,-0.02741998419959968
123.20000000000104,18.67552801056136,0.26263845046535744,-0.03004666136701495
124.40000000000106,18.792857739306864,0.26239307911917253,-0.02939124408957161
125.60000000000107,18.90936789985235,0.262476830501996,-0.0300561082088171
126.80000000000109,19.026023926757496,0.26136872788878607,-0.028730321899788525
128.0000000000011,19.143763246617244,0.2612857459435884,-0.0274523228755017
129.20000000000113,19.256137347253503,0.26298211258157383,-0.02873820581292419
130.40000000000114,19.37557539457776,0.26554666200709764,-0.02875270091282145
131.60000000000116,19.49277961714189,0.2651200454577607,-0.03099091593028236
132.80000000000118,19.608048650547847,0.2664637329120403,-0.03170712878322535
134.0000000000012,19.7247800619438,0.2659621049034353,-0.03170017600263719
135.2000000000012,19.84065538564336,0.26726509388492026,-0.03170425811577937
136.40000000000123,19.957444956777305,0.2679489044444398,-0.030379985830346623
137.60000000000124,20.073397695696254,0.26833742542070865,-0.03317097605837738
138.80000000000126,20.188964530710454,0.270099366899378,-0.034420848058188014
140.00000000000128,20.30459909766268,0.27261766811906807,-0.03310580800825225
141.2000000000013,20.420000000000126,0.2742971929769983,-0.03182022172073973
142.4000000000013,20.536309050818918,0.27038155635303784,-0.0331272932475879
143.60000000000133,20.651115146630342,0.27328249731486554,-0.036342969002173486
144.80000000000135,20.767903077482845,0.27281604579646224,-0.0344713786217552
146.00000000000136,20.883008716500587,0.2754429675519695,-0.03445012290840266
147.20000000000138,20.998290987835716,0.27889400909536066,-0.03576005387460057
148.4000000000014,21.11322658851603,0.28213927933739846,-0.03456750823428845
149.60000000000142,21.22871117237928,0.2815690259737983,-0.034439881997348376
150.80000000000143,21.34420590256709,0.28503338564252634,-0.03443990354330673
152.00000000000145,21.457715432059537,0.2881119850700884,-0.03575979643670335
153.20000000000147,21.573944497969787,0.29098713592442194,-0.03575985753651434
154.40000000000148,21.68952097322349,0.29419957284779896,-0.035429235508730894
155.6000000000015,21.80528911837516,0.29795584267319297,-0.03685244517209929
156.80000000000152,21.92035242169562,0.3063597467330094,-0.036409979084135013
158.00000000000153,22.033245445073668,0.3130003787503447,-0.03773002993393737
159.20000000000155,22.15038102907397,0.3204833646528121,-0.037736704326684745
160.40000000000157,22.265472841049036,0.32876925265215445,-0.036741827620376366
161.6000000000016,22.38225803871387,0.33675617891869736,-0.03876832506339589
162.8000000000016,22.497193678249406,0.34393933397941523,-0.03739778509868685
164.00000000000162,22.61222203098649,0.34993943724171594,-0.03806006193317302
165.20000000000164,22.727964232184114,0.35045910898753846,-0.039379559249453244
166.40000000000165,22.84508513687238,0.34766783558438774,-0.03937998115134578
167.60000000000167,22.958387623593204,0.3357532674925125,-0.04067447889946951
168.8000000000017,23.07314636368995,0.322325737060654,-0.03938014064784667
170.0000000000017,23.188945492021915,0.3092850836390706,-0.04068543982809825
171.20000000000172,23.30269391825767,0.3016655637385234,-0.040689982000133185
172.40000000000174,23.418585183464252,0.29546235234194046,-0.040688578351328886
173.60000000000176,23.53427207830118,0.2909923145949876,-0.041680025683772826
174.80000000000177,23.64876242307388,0.29183816675706875,-0.04068984167710088
176.0000000000018,23.763110618665195,0.28957101674545715,-0.04200875009698679
177.2000000000018,23.878858084677418,0.2906351656375041,-0.04200977955931062
178.40000000000182,23.993466161514537,0.2931510170667215,-0.04091002887909889
179.60000000000184,24.10729884098852,0.29682785860145744,-0.043649985337788966
180.80000000000186,24.224306160460895,0.29545273285576484,-0.04234076330532943
182.00000000000188,24.33778057025444,0.2983658884043613,-0.04233989016689099
183.2000000000019,24.4518795307197,0.2991303506628793,-0.04239387168107589
184.4000000000019,24.56701435919004,0.30052905282393816,-0.04370588497215211
185.60000000000193,24.682611112947196,0.3052950992263554,-0.0445396595673242
186.80000000000194,24.79632283856094,0.3073793080176333,-0.044530032000642095
188.00000000000196,24.911001255763153,0.30692140510345395,-0.04453015809095451
189.20000000000198,25.025808134664793,0.31072050301950216,-0.047270238603826176
190.400000000002,25.140213411728936,0.31332070553013697,-0.047270082998616125
191.600000000002,25.254381765313084,0.3153369372318306,-0.047264086856085186
192.80000000000203,25.36890068767679,0.3155814396976209,-0.0458457267175314
194.00000000000205,25.483872453912156,0.3168406371121144,-0.04642820680559501
195.20000000000206,25.5976378127158,0.3177970553077391,-0.04653996700099361
196.40000000000208,25.71295097316227,0.32029688679176327,-0.04684097244431307
197.6000000000021,25.82725724744842,0.3241218272269864,-0.0478299351424214
198.80000000000211,25.942360963334743,0.32392529307191625,-0.04782655365951527
200.00000000000213,26.056208698330213,0.3287856237704803,-0.04682309572385179
201.20000000000215,26.171973959889744,0.33192833255005383,-0.0508746120541268
202.40000000000217,26.286832453587227,0.33447477591685193,-0.05222200262413246
203.60000000000218,26.40130394009182,0.3398025273836856,-0.0522203062661486
204.8000000000022,26.516370200702685,0.3447959217223865,-0.051238514496479315
206.00000000000222,26.63201453751638,0.3532982811349601,-0.05023897244382347
207.20000000000223,26.74560267921613,0.3569336166616225,-0.051657325643371
208.40000000000225,26.86128328063822,0.3654153807045597,-0.04957727801628886
209.60000000000227,26.975013118090022,0.3766776202088685,-0.05083853086580792
210.80000000000229,27.08973069291158,0.39022828939175463,-0.052225383971307604
212.0000000000023,27.204246760535025,0.409584127278105,-0.050899944782492046
213.20000000000232,27.31928300085378,0.43567487118086934,-0.05088528567188444
214.40000000000234,27.434138826710612,0.48666632353002315,-0.050905413079933126
215.60000000000235,27.548824240244603,0.5723478687186354,-0.052210221219983755
216.80000000000237,27.662124260869238,0.6985230451724329,-0.0535301938527466
218.0000000000024,27.78009699117658,0.8376921839116538,-0.052210471790744784
219.2000000000024,27.896339357259528,0.941890862075201,-0.053182271934446135
220.40000000000242,28.010000983129984,1.0013886835185306,-0.05090022020312768
221.60000000000244,28.12715051887642,0.9871737944843537,-0.05149638541205537
222.80000000000246,28.242133116730177,0.882890942987868,-0.05155433616896188
224.00000000000247,28.35759057695315,0.7064004419198396,-0.05286931416305629
225.2000000000025,28.470729578289596,0.5486689992618322,-0.05419009058393254
226.4000000000025,28.5841474548696,0.4520876529537155,-0.054063491503208105
227.60000000000252,28.697758392944948,0.3958571756781133,-0.05408364842019253
228.80000000000254,28.811124511408533,0.3685414002280231,-0.054502821664038414
230.00000000000256,28.925019180963833,0.3538415913497179,-0.05451003222914386
231.20000000000258,29.038525601007933,0.3431996811205261,-0.05581747611332455
232.4000000000026,29.15262687647579,0.341723354857871,-0.05682015525766149
233.6000000000026,29.266731400374518,0.33828847544820567,-0.056181597635394986
234.80000000000263,29.381250870168746,0.3361131365332416,-0.05549100057217249
236.00000000000264,29.49595334030597,0.3354540860055334,-0.055702271929739755
237.20000000000266,29.61000000000025,0.3346542118392027,-0.05686604489677194
238.40000000000268,29.72477708864766,0.3338545342163539,-0.0581400538031116
239.6000000000027,29.838844585764527,0.3360464766684885,-0.0581386536410724
240.8000000000027,29.9525197263362,0.33663355263822337,-0.059453497393562316
242.00000000000273,30.065634859126227,0.3386427676018177,-0.060770051564682515
243.20000000000275,30.179394202645284,0.3406358397505408,-0.06077058564122817
244.40000000000276,30.29356919574318,0.3396531262343028,-0.06394731505374018
245.60000000000278,30.4072646393648,0.34080768888691637,-0.06263982682386304
246.8000000000028,30.52121101412628,0.3395101808943877,-0.062222913741840635
248.0000000000028,30.635059332154256,0.34057638604539353,-0.0626300906979389
249.20000000000283,30.748153586132805,0.3420938457019801,-0.06234950850481091
250.40000000000285,30.86185580398777,0.34370792923579585,-0.06230015387969745
251.60000000000286,30.974820068448867,0.34094107475895424,-0.06364565915811138
252.80000000000288,31.090108205922093,0.3444628627543913,-0.06362001113570548
254.0000000000029,31.203057781085477,0.34407170630419914,-0.0636200040000019
255.20000000000292,31.317457794653038,0.3422115879381472,-0.06362000288908964
256.40000000000293,31.43067787939938,0.34535060873194184,-0.06488682239294663
257.600000000003,31.54487424801938,0.3430326154165138,-0.0690727054652367
258.80000000000297,31.65824632419156,0.34017677722380507,-0.0676799041005669
260.00000000000296,31.7717395681161,0.34246096747030047,-0.06740342566718338
261.200000000003,31.88774605766961,0.3446187803152002,-0.06916017678185815
262.40000000000305,32.00081173137362,0.34435321582296397,-0.06931997578069016
263.60000000000304,32.11437515962148,0.34534740041546186,-0.06799843783664583
264.800000000003,32.229208810474724,0.3436287762191983,-0.06931994545907427
266.00000000000307,32.3425462773603,0.34802324054462014,-0.06931573891656795
267.2000000000031,32.45605234437143,0.34252272249244536,-0.07063985392211913
268.4000000000031,32.571258143568905,0.34274928212218997,-0.0706398538981925
269.6000000000031,32.68401438111306,0.3420924396044891,-0.07202933053781413
270.80000000000314,32.79919602371111,0.3442908240476266,-0.07068821442167117
272.0000000000032,32.913732712600684,0.34200024413474905,-0.07063437000483486
273.2000000000032,33.02732742868969,0.34262722763594505,-0.07296653037100098
274.40000000000316,33.142200567978264,0.34129072597140514,-0.07394953907524693
275.6000000000032,33.25736296033799,0.3416092880846483,-0.07392632082283868
276.80000000000325,33.37134301360574,0.3400324725356095,-0.0752501444022462
278.00000000000324,33.486232565381336,0.3406629971034517,-0.07491176509800868
279.20000000000323,33.601552872896995,0.3408231633564154,-0.07590987934669302
280.4000000000033,33.71595970462604,0.3406978739132659,-0.07624171408136515
281.6000000000033,33.83084456888705,0.340149556177408,-0.07885930538374097
282.8000000000033,33.94570910191137,0.3396288433043661,-0.07886015386760148
284.0000000000033,34.06087499400873,0.3418064306514968,-0.077551995093319
285.20000000000334,34.17532110693471,0.3432541525482492,-0.07886009296975116
286.4000000000034,34.290104011120796,0.3405642685631015,-0.07952846136802938
287.6000000000034,34.40415870552891,0.3372673661822087,-0.08017999810965337
288.80000000000337,34.51923360896449,0.341921969880778,-0.08017995197895456
290.0000000000034,34.63493938058466,0.34258057545300635,-0.08018015487060737
291.20000000000346,34.74822272554924,0.3443827574774878,-0.08149006434686701
292.40000000000344,34.8636081184127,0.34552587119584666,-0.08150159683130465
293.60000000000343,34.9785976809765,0.3441522872763295,-0.08247975528342488
294.8000000000035,35.09249228293068,0.347569291005549,-0.08268221085189031
296.0000000000035,35.20753310275204,0.3474112123396752,-0.08379983044885853
297.2000000000035,35.321625270765495,0.3487776623411173,-0.08510938445309968
298.4000000000035,35.437344734092754,0.35410203708287813,-0.0852494638603094
299.60000000000355,35.55147868924571,0.3569604060489399,-0.08676019146159009
300.8000000000036,35.66696053076657,0.3595931250877341,-0.08811028862356007
302.0000000000036,35.78063496481831,0.36419590460061085,-0.08808011818303108
303.20000000000357,35.895283180251354,0.36531781602959346,-0.09070958357539594
304.4000000000036,36.0110459113301,0.36772013787654423,-0.0907037107977362
305.60000000000366,36.12603894181426,0.37071178613615313,-0.09216108682032598
306.80000000000365,36.2403948178234,0.37053631922228575,-0.09335970143517214
308.00000000000364,36.35462560591786,0.37051104423678544,-0.09597016808397996
309.2000000000037,36.47099145332484,0.3717350496294915,-0.09862878150344567
310.40000000000373,36.58569824974662,0.37501005263070064,-0.10296973686202682
311.6000000000037,36.700284221607994,0.3781086819453126,-0.1035886201190972
312.8000000000037,36.81447123029381,0.3809325944912617,-0.10561856951030402
314.00000000000375,36.93144078725961,0.3846436987050117,-0.10792314664637681
315.2000000000038,37.046694325607355,0.38791098585311934,-0.10915539554434694
316.4000000000038,37.16143917277896,0.3979816603491614,-0.11188121621373837
317.6000000000038,37.27697589373908,0.3959828184622587,-0.11449041053071074
318.8000000000038,37.3925103051696,0.3998925499265804,-0.1196208347126424
320.00000000000387,37.508149318641856,0.40375773174597496,-0.12259558630844891
321.20000000000385,37.623536487332856,0.4114718547328532,-0.12643626586182188
322.40000000000384,37.739289519768924,0.4157127847003883,-0.12904130286356486
323.6000000000039,37.85539770482328,0.4229200925146705,-0.1319852163609463
324.80000000000393,37.9703636713457,0.42508966395485126,-0.13658069188069177
326.0000000000039,38.08616344547935,0.43119376662970377,-0.14193592085164042
327.2000000000039,38.20246556363382,0.4394482971838267,-0.14786645653944497
328.40000000000396,38.31763818181172,0.4438589032032324,-0.15226622044335247
329.600000000004,38.43259496267325,0.4530882613957349,-0.15662019081528378
330.800000000004,38.549719693156746,0.46169935371923365,-0.16285852675074386
332.000000000004,38.66556880257,0.46876665270842216,-0.16841611260876643
333.200000000004,38.780573253445944,0.47902056975688334,-0.17664867735176193
334.40000000000407,38.89630046255045,0.48652214012095496,-0.1808808553141339
335.60000000000406,39.01299584435082,0.4950522030733931,-0.188336571981234
336.80000000000405,39.1294338173426,0.5037952436343879,-0.1956722217407183
338.0000000000041,39.24532216407184,0.5157683321791615,-0.2042405071694291
339.20000000000414,39.36170568357155,0.5275450908252846,-0.211864086182866
340.4000000000041,39.47825774350339,0.5390920283169509,-0.22112004866317614
341.6000000000041,39.59366823118836,0.5504547106806363,-0.2307685811023079
342.80000000000416,39.709345286828906,0.5629939887944353,-0.2403743836268748
344.0000000000042,39.826164781187856,0.576901493433686,-0.25253347602131315
345.2000000000042,39.9425040946039,0.5910811371905705,-0.2631127728263869
346.4000000000042,40.057842673988524,0.6034289228633478,-0.2747118311117376
347.60000000000423,40.17504375306779,0.6170440035264907,-0.28921805927073585
348.8000000000043,40.291126541957716,0.6290426721258222,-0.302496969887907
350.00000000000426,40.40763722439441,0.6409935439696547,-0.3156900182131297
351.20000000000425,40.52519314166244,0.6565117403913142,-0.33178623852737754
352.4000000000043,40.64090082702063,0.6690852890322769,-0.3457380106975916
353.60000000000434,40.75709239423059,0.6836420538731132,-0.3619217854225676
354.80000000000433,40.8728404637654,0.699155265360529,-0.37559222315075846
356.0000000000043,40.99088682498361,0.7163277132013766,-0.39212296189381046
357.20000000000437,41.10720536499108,0.7313437348791788,-0.40876874764837856
358.4000000000044,41.22298725278301,0.7471676700724974,-0.4281906603939998
359.6000000000044,41.33990551540595,0.7647646143572613,-0.448265907733413
360.8000000000044,41.45623982019685,0.7815561005364138,-0.46721740972307746
362.00000000000443,41.57336059761976,0.796580386607706,-0.48741109991453335
363.2000000000045,41.68950866051098,0.8126119663857886,-0.5075481394582697
364.40000000000447,41.80694014902601,0.8268645624197767,-0.5289292312075085
365.60000000000446,41.92224695183633,0.8458085911183771,-0.5499073532307333
366.8000000000045,42.03902246167645,0.8655270690840293,-0.5755407903676732
368.00000000000455,42.15598194555214,0.8834103763853318,-0.6011110151023487
369.20000000000454,42.27291082492413,0.9009510777166754,-0.6265682093505864
370.4000000000045,42.38741881578108,0.9202013510242788,-0.6512832804407895
371.60000000000457,42.50685218772591,0.9402035873946941,-0.6790409150093804
372.8000000000046,42.623605036153165,0.9606614371541473,-0.7108217995115047
374.0000000000046,42.740289766616975,0.9789695173223636,-0.737071365820237
375.2000000000046,42.857994580461956,1.003353948401605,-0.7682635140565774
376.40000000000464,42.97493796181381,1.0242308094332442,-0.8010626390665978
377.6000000000047,43.09256627848488,1.0451252137379172,-0.8354684026478427
378.8000000000047,43.20929233041997,1.0629744259871332,-0.8711308329610761
380.00000000000466,43.325780213346704,1.0839395047774714,-0.9055223833785044
381.2000000000047,43.44408942585604,1.102862841150302,-0.944038207678259
382.40000000000475,43.5608523779899,1.1196167784417106,-0.9836064071954072
383.60000000000474,43.67869353480203,1.1359692627265003,-1.0242112634599345
384.80000000000473,43.79630570421963,1.1496089922554231,-1.0662713977624159
386.0000000000048,43.9124779855081,1.1574331608554356,-1.110265100891024
387.2000000000048,44.02800627307997,1.1690110101027462,-1.1525004359827276
388.4000000000048,44.14731058996356,1.1757380793131875,-1.1962405750435776
389.6000000000048,44.26410285869554,1.1792698484837312,-1.2437578780032048
390.80000000000484,44.38234138271343,1.1775177289013619,-1.2894992934944356
392.0000000000049,44.50000000000046,1.1733302866711768,-1.3360901139997075
393.2000000000049,44.616820022350126,1.1658950244059365,-1.3851531123633256
394.40000000000487,44.73324578277906,1.1535901659411878,-1.431601304203626
395.6000000000049,44.849999045739374,1.134469728328489,-1.4799991764692422
396.80000000000496,44.9678479895012,1.1098482125308573,-1.532053114647319
398.00000000000495,45.08414711287462,1.078822653077595,-1.5783823358060238
399.20000000000493,45.2007827079109,1.0367876503694533,-1.6230847236239625
400.400000000005,45.317998652477485,0.9873354485010446,-1.6683297110925812
401.600000000005,45.43490767376031,0.9297974109125161,-1.710897424833147
402.800000000005,45.55197498726646,0.8669287073947332,-1.7515052927760655
404.000000000005,45.66780873540999,0.7956621884945752,-1.7898142510051818
405.20000000000505,45.78508586459369,0.719774012599421,-1.8256531191095888
406.4000000000051,45.900836796249344,0.6449511896785601,-1.8562345968878216
407.6000000000051,46.01706023161094,0.5675734216779939,-1.8842221337205451
408.80000000000507,46.13420303186269,0.4965345847547934,-1.9078219953604139
410.0000000000051,46.249906791284374,0.43148238121107274,-1.9271915380284734
411.20000000000516,46.36629754292789,0.3812945620585813,-1.9453574768872572
412.40000000000515,46.48312442602396,0.3355857153370186,-1.9616123873901674
413.60000000000514,46.59917706954736,0.3025682741053712,-1.9756921820554902
414.8000000000052,46.71648282053624,0.27458664485867607,-1.98634799241492
416.00000000000523,46.83269065799116,0.2549480709973645,-1.9963206248827576
417.2000000000052,46.95020900686453,0.24056436677525944,-2.0072579436082547
418.4000000000052,47.068421963100555,0.23035325326592015,-2.0179824290405373
419.60000000000525,47.18523405488998,0.219560309294775,-2.026688888757782
420.8000000000053,47.30379189947314,0.21196613173260964,-2.0326153205402937
422.0000000000053,47.41990071083141,0.21089661549383143,-2.0418091797330837
423.2000000000053,47.53680153436177,0.2063688615571571,-2.0476704367045793
424.4000000000053,47.65411085584268,0.20201526475905573,-2.054649497170134
425.60000000000537,47.77176578766825,0.19867339944797902,-2.066097595983928
426.80000000000535,47.88830764234083,0.1977816968612362,-2.073338036811781
428.00000000000534,48.00672034355033,0.19483850795148971,-2.08109315025642
429.2000000000054,48.12279778044137,0.19186917441629775,-2.087038530607317
430.40000000000543,48.24148773846428,0.1884982178276447,-2.094056138383891
431.6000000000054,48.358857781983126,0.19038177589676242,-2.101803729273814
432.8000000000054,48.47551815944651,0.18807220862612672,-2.1090055787066238
434.00000000000546,48.59462006931695,0.18766397728507456,-2.1141408021551973
435.2000000000055,48.71165913116437,0.18588000901988366,-2.1218202323299327
436.4000000000055,48.83019803714324,0.18424776952174293,-2.1286885125973414
437.6000000000055,48.94839652652959,0.18488573832673516,-2.1369388247825984
438.8000000000055,49.06644425118066,0.1833235713883477,-2.1420710738852122
440.00000000000557,49.184138237100626,0.18555290884063125,-2.1515672658877767
441.20000000000556,49.30208851896948,0.18327690865656326,-2.1593582632336465
442.40000000000555,49.42098344877007,0.1851999403291959,-2.16490592532207
443.6000000000056,49.539699337395476,0.1855497218531767,-2.1701244107233992
444.80000000000564,49.65644513217846,0.1874918738542486,-2.178887562428951
446.0000000000056,49.77499175049194,0.18779918789809436,-2.1843165174700845
447.2000000000056,49.89231328571785,0.18759120177310312,-2.1938932376764404
448.40000000000566,50.01047956317515,0.18797419713580293,-2.2018670625186454
449.6000000000057,50.12827659931856,0.18714004896287012,-2.210068062300822
450.8000000000057,50.244678823086296,0.1900124648256052,-2.216496027165917
452.0000000000057,50.36362016683674,0.190163074692336,-2.2256398310211294
453.20000000000573,50.48177159747829,0.1886504818334585,-2.2340851408322986
454.4000000000058,50.60028982433997,0.1895346779520935,-2.2422176688559876
455.60000000000576,50.71825411288779,0.19012852221805637,-2.249075208662532
456.80000000000575,50.83601881796498,0.19242194883193792,-2.259078472023961
458.0000000000058,50.955707746569445,0.1898062258909844,-2.2664472363962695
459.20000000000584,51.07375321111861,0.18963878748645252,-2.276007179950066
460.40000000000583,51.1923155207994,0.19247419521251696,-2.2821999566660978
461.6000000000058,51.31142663705376,0.19024251793942076,-2.291440544577098
462.80000000000587,51.42914696924781,0.1908048592092354,-2.3017847285657327
464.0000000000059,51.54927957922156,0.1916906395586946,-2.309807207951854
465.2000000000059,51.66788845817455,0.19095356724663848,-2.32115657740707
466.4000000000059,51.785393876601596,0.1908509507920187,-2.3313798035819735
467.60000000000593,51.90504010386432,0.1887072676485912,-2.3408017520710147
468.800000000006,52.02352774063402,0.18588602562856626,-2.3500217530932384
470.00000000000597,52.14122647485235,0.18457365688673744,-2.3585495667781076
471.20000000000596,52.26065198329696,0.17866686276415872,-2.3709106358567835
472.400000000006,52.37861566515709,0.16819694779510935,-2.378441071104713
473.60000000000605,52.497558905541204,0.1620578097286809,-2.3868407404703884
474.80000000000604,52.615316460088025,0.14535933214279045,-2.3951075546194542
476.000000000006,52.7338527263485,0.13284293327364521,-2.400549269734297
477.20000000000607,52.85233030142607,0.11624534248351026,-2.406979085029532
478.4000000000061,52.969271894525576,0.09916104918553881,-2.4122100002645013
479.6000000000061,53.08843288766717,0.08387992009562145,-2.4161712549789396
480.8000000000061,53.20683513021658,0.07081902095139819,-2.4204000810843214
482.00000000000614,53.324848971283465,0.06008650098259366,-2.4230002552477856
483.2000000000062,53.44377402238501,0.05011881662825385,-2.4236663973606922
484.4000000000062,53.56130099241986,0.04610321029499764,-2.425629815440911
485.60000000000616,53.680330187946744,0.03834896284100736,-2.4269096518793445
486.8000000000062,53.79930719455193,0.03712217179420518,-2.4269089398926464
488.00000000000625,53.917388683640375,0.0353308254790074,-2.4283582751084936
489.20000000000624,54.036536862357146,0.04230483926948714,-2.4288909587351117
490.40000000000623,54.15445147309096,0.051354685931687793,-2.4302050849695958
491.6000000000063,54.27329899085979,0.0559887214221359,-2.4301998899958535
492.8000000000063,54.38956690232503,0.06065105043367386,-2.430203526890256
494.0000000000063,54.51147567409106,0.05788985903823213,-2.430860233544579
495.2000000000063,54.63068718563538,0.05693456070510544,-2.432173303100144
496.40000000000634,54.74974860466807,0.0538714297684445,-2.4321800840010055
497.6000000000064,54.86969873607568,0.0512124789433035,-2.432183974398301
498.8000000000064,54.98620631423931,0.04693631067498205,-2.433554012182219
500.00000000000637,55.10689001479895,0.03976865712418087,-2.4328401302346307
501.2000000000064,55.22557886207512,0.03330872180339961,-2.4328370814463636
502.40000000000646,55.3445742167229,0.03126456068859007,-2.4321849494252095
503.60000000000645,55.463756531884115,0.027515946835800276,-2.4315796064233877
504.80000000000643,55.58333486235088,0.025764729033613376,-2.4322012554307726
506.0000000000065,55.70227223446685,0.01944323050591057,-2.4334999341642787
507.2000000000065,55.82127884835057,0.020526122549911374,-2.432222871503831
508.4000000000065,55.9369665483444,0.01675491338257662,-2.4335003623258444
509.6000000000065,56.059805774661996,0.0039868391298081285,-2.433499557783281
510.80000000000655,56.17818883840662,-0.0032785032537813175,-2.4334999839994644
512.0000000000066,56.29780734218502,-0.00659438103392862,-2.433500041598998
513.2000000000066,56.416497487940255,-0.007398105994572912,-2.4348041380486922
514.4000000000066,56.535330852040985,-0.006748699032729122,-2.434159885142898
515.6000000000066,56.65546960173456,-0.008083300093669421,-2.435496049607612
516.8000000000067,56.77345423858641,-0.007754327963590435,-2.436845613158381
518.0000000000066,56.893792952345734,-0.011264185419088135,-2.4366179779258377
519.2000000000066,57.011893823945556,-0.013395623527603817,-2.4377704660996913
520.4000000000067,57.1312472791255,-0.015399792965826276,-2.437772197589157
521.6000000000067,57.25116812795049,-0.015853007759778937,-2.439424030856281
522.8000000000068,57.36927594827238,-0.017266137290970707,-2.4381104395539945
524.0000000000067,57.48796437049686,-0.018149425905367722,-2.4381117885236443
525.2000000000068,57.60698302868865,-0.018569770343384695,-2.4389940033408744
526.4000000000068,57.7261788279284,-0.019758332429695713,-2.440730051999327
527.6000000000067,57.84622441913598,-0.01821766605226227,-2.439433116571203
528.8000000000068,57.96474473308101,-0.02118760047964441,-2.440740100333323
530.0000000000068,58.08227722966403,-0.023346080527556268,-2.440740078232359
531.2000000000069,58.2034573862416,-0.019708395859793226,-2.442109707437874
532.4000000000069,58.3231100898661,-0.024023338412966777,-2.4420599780344077
533.6000000000068,58.44243697430678,-0.01897613001950904,-2.442238449081806
534.8000000000069,58.56225847036801,-0.02344724728840386,-2.443370028005172
536.0000000000069,58.681477372802725,-0.02266387526314151,-2.4433700272938133
537.2000000000069,58.800527198031446,-0.022055981307359862,-2.444689591699758
538.4000000000069,58.92109282011594,-0.02279061445399888,-2.4433683512252764
539.600000000007,59.039628483367096,-0.021635014809719855,-2.4407367373822977
540.800000000007,59.15957439398521,-0.02388906445123784,-2.4420496180137947
542.000000000007,59.28010524213769,-0.022896070977891814,-2.444680138242277
543.200000000007,59.401203771987845,-0.02182760652751714,-2.4433600572084684
544.400000000007,59.52149106184836,-0.023353669799147436,-2.4446790039291386
545.6000000000071,59.640190237378484,-0.024984642762961307,-2.4460106928220267
546.800000000007,59.76243787539309,-0.024974035475074485,-2.4445911155003266
548.000000000007,59.88076911663504,-0.028537232232350385,-2.4444404784937905
549.2000000000071,60.00120106913563,-0.02502315089539142,-2.4446901719971814
550.4000000000071,60.12065687984152,-0.027558338941210514,-2.444685846829515
551.6000000000072,60.24137579952902,-0.02249631310516753,-2.445999407913229
552.8000000000071,60.36062758714754,-0.018485931561281865,-2.4437018276333298
554.0000000000072,60.4805297502372,-0.02234979890183697,-2.444680050860841
555.2000000000072,60.5994270657594,-0.017899356907961406,-2.446004346415721
556.4000000000071,60.71961681891797,-0.01885484068359944,-2.4466258209972116
557.6000000000072,60.83927417280563,-0.015188989502075145,-2.447320121878848
558.8000000000072,60.95894117178979,-0.01871311179126489,-2.4473206258823295
560.0000000000073,61.07830185957567,-0.014241190430813067,-2.448640028244011
561.2000000000073,61.197793268029706,-0.01759656196385484,-2.4486400215004838
562.4000000000073,61.318579862770335,-0.01700417939290444,-2.448987627391707
563.6000000000073,61.43802130557222,-0.017912771149836693,-2.448965503085735
564.8000000000073,61.55820490437305,-0.01584332874806693,-2.4502799782967997
566.0000000000073,61.67771765665506,-0.01483902641535062,-2.4502799717010424
567.2000000000073,61.79817909527682,-0.018801107587172572,-2.4489614425485025
568.4000000000074,61.917995116582986,-0.016859547676023712,-2.4502016210591915
569.6000000000074,62.038497157210614,-0.01520595766907229,-2.4502801408974575
570.8000000000075,62.15884086615464,-0.012973260594911329,-2.4515999288603503
572.0000000000074,62.279287000226375,-0.010024879150867583,-2.451599510921975
573.2000000000074,62.399675745032766,-0.013732092436427035,-2.450279947191166
574.4000000000075,62.52065031304172,-0.012128445946109845,-2.452919392692273
575.6000000000074,62.64083063278235,-0.010225985724983455,-2.4517804809966943
576.8000000000075,62.760996433087485,-0.012420187733254373,-2.4516242416261944
578.0000000000075,62.88114710988176,-0.012715975906644972,-2.4529108710018805
579.2000000000075,63.00189247192593,-0.012939790051176514,-2.4555523748412247
580.4000000000076,63.12084396497282,-0.01344885118241057,-2.4536484045181544
581.6000000000075,63.24326084845988,-0.014648804109547275,-2.456440444933453
582.8000000000076,63.362695443330985,-0.010773306946132766,-2.4555503355289074
584.0000000000076,63.48391114848422,-0.010353226840464025,-2.4545817777714998
585.2000000000075,63.60343123977857,-0.012995758017856462,-2.45587011620093
586.4000000000076,63.72337912294364,-0.00999177454239919,-2.4558696027495865
587.6000000000076,63.84378881490564,-0.009228187789199871,-2.4568605570649797
588.8000000000077,63.964046350773025,-0.012239173469601128,-2.455550024068767
590.0000000000077,64.08510900357913,-0.009016748928687424,-2.455487606530582
591.2000000000077,64.20479337065444,-0.008813587574971304,-2.456859416410034
592.4000000000077,64.32514585948861,-0.0018251313475901032,-2.458181296807136
593.6000000000078,64.44626838447944,-0.003906776973486181,-2.4594899636807335
594.8000000000077,64.56616003350354,-0.003812606359139936,-2.462128100569176
596.0000000000077,64.68652827729458,-0.0019079992989363692,-2.462475856091157
597.2000000000078,64.80698845696568,0.0006510973869562342,-2.4621199164104457
598.4000000000078,64.92781988579227,0.0018483803996647286,-2.463452730569076
599.6000000000079,65.0475884798635,0.0026676857074811045,-2.465740101050637
600.8000000000078,65.16860795333538,0.0037571451035144365,-2.4650647282912486
602.0000000000078,65.28951629687128,0.011561963447578316,-2.4657399669027074
603.2000000000079,65.40930507122971,0.016443222908100186,-2.4644309835937293
604.4000000000078,65.52999811006006,0.020215450438254123,-2.467093093223519
605.6000000000079,65.65114153198462,0.02369854309830921,-2.4653163326409127
606.8000000000079,65.77136967743601,0.02569864844318448,-2.4650732049456057
608.000000000008,65.89261923067203,0.02914518535840105,-2.4676911330485587
609.200000000008,66.01388513969913,0.03111900244051613,-2.467604127720995
610.4000000000079,66.13364647649728,0.0405917090710074,-2.468920802367223
611.600000000008,66.25469063224453,0.043641104961813504,-2.4715597841928427
612.800000000008,66.37283683519001,0.05054201777809941,-2.4721805152167926
614.000000000008,66.49560153524767,0.0563911930779446,-2.472966246630019
615.200000000008,66.6152759431589,0.06414419484150669,-2.473198308467497
616.400000000008,66.73557287503083,0.06968560064906537,-2.4745071901720914
617.6000000000081,66.85644582626003,0.0777063846619176,-2.4758398163591284
618.8000000000081,66.97731734431183,0.08582000109132959,-2.477306924037651
620.0000000000081,67.09772234357266,0.09320723596502645,-2.4797894689369215
621.2000000000081,67.2183040711283,0.09565049374685664,-2.481099799724479
622.4000000000082,67.33944144240571,0.11429957131186319,-2.4824198811352476
623.6000000000081,67.46048710324347,0.11942351837161003,-2.4833777372467933
624.8000000000081,67.58095938686478,0.12624929183696465,-2.4847197959562166
626.0000000000082,67.70175056541164,0.1345286493567951,-2.4873627492298214
627.2000000000082,67.82260126224497,0.1440663181987516,-2.487893690109762
628.4000000000083,67.94374651211429,0.1531129167510592,-2.490966963846194
629.6000000000082,68.06457871645893,0.16031115505557647,-2.4936142094067044
630.8000000000083,68.18552090212123,0.1730065360265931,-2.494705782928974
632.0000000000083,68.30627720130653,0.18285861193348896,-2.4962361635059844
633.2000000000082,68.42719963664325,0.19031022502315986,-2.4988532847339515
634.4000000000083,68.54832052166502,0.2035676826540963,-2.502762244368083
635.6000000000083,68.67000212060277,0.21193987966395555,-2.5054502003793853
636.8000000000084,68.79009979731919,0.2244363014293428,-2.5067692613312658
638.0000000000084,68.91211235993978,0.2374899084204336,-2.5108262341392287
639.2000000000083,69.03298816056139,0.2501206818320386,-2.512328705021857
640.4000000000084,69.15402591460033,0.2632092438396354,-2.51675047742511
641.6000000000084,69.274858246208,0.2783637649114902,-2.51830091622484
642.8000000000084,69.3954284132121,0.2951914363941316,-2.523247084568804
644.0000000000084,69.51525039454374,0.3075338042435505,-2.525327559513009
645.2000000000085,69.63717251535726,0.31827086000998206,-2.5287937089061874
646.4000000000085,69.75842437345838,0.3341534288938075,-2.532853875717085
647.6000000000085,69.87978336173546,0.35165593012285945,-2.535621629458027
648.8000000000085,69.99970718180606,0.3649349720059891,-2.5397486737236457
650.0000000000085,70.12082912716932,0.3783707456135159,-2.5425356666469527
651.2000000000086,70.24176346471981,0.39230476236878564,-2.549739151918782
652.4000000000085,70.36243932628645,0.4093002501416001,-2.552202902886128
653.6000000000085,70.48348199045218,0.4239175914009028,-2.5565977505100417
654.8000000000086,70.60393918944796,0.44136454500007605,-2.559866438902775
656.0000000000086,70.72421150103283,0.46178317994180795,-2.5651224851439762
657.2000000000087,70.84438166632543,0.4740932070750352,-2.571699858707954
658.4000000000086,70.96510471498381,0.4950874171681823,-2.576732149003008
659.6000000000087,71.08644990669556,0.5120574618918741,-2.580774696925098
660.8000000000087,71.20733390759197,0.5307114523320622,-2.5881920205565394
662.0000000000086,71.32723661222401,0.5540223315989814,-2.5926687392929013
663.2000000000087,71.44916719022275,0.5687605975720647,-2.598265365492407
664.4000000000087,71.56933266349075,0.5878013998494165,-2.6022464733635404
665.6000000000088,71.69010066273638,0.610212058815641,-2.6112892620393104
666.8000000000088,71.81107466724319,0.6289934666297563,-2.6162452404078005
668.0000000000088,71.93189886449153,0.6477085301185768,-2.6215910799247206
669.2000000000088,72.05203352040962,0.6651416824586669,-2.6300376426140417
670.4000000000088,72.17415470726296,0.6822707372586094,-2.6351326631658125
671.6000000000088,72.29161566053246,0.7006622740279382,-2.641286745460005
672.8000000000088,72.41541833226748,0.7187091042331353,-2.648216042313135
674.0000000000089,72.53654226570612,0.7284947400860573,-2.655411322759529
675.2000000000089,72.65757680111594,0.7420668839175688,-2.6604595518331013
676.400000000009,72.77959126946295,0.7548787773611649,-2.6674436004322395
677.6000000000089,72.89951370987812,0.7641084409237227,-2.674530393758527
678.8000000000089,73.02231011235486,0.7725097135902672,-2.6820085988342868
680.000000000009,73.14354488538807,0.7809802024152881,-2.6885058859917623
681.2000000000089,73.26467194952019,0.7848961308927465,-2.694551418971611
682.400000000009,73.38647990374955,0.7965166798960652,-2.7028738370524326
683.600000000009,73.50717915324864,0.8142257073233183,-2.708681638431126
684.800000000009,73.629398777434,0.8356874441554076,-2.7160428018730363
686.0000000000091,73.75116097703545,0.865354271819059,-2.725759843612127
687.200000000009,73.87309065142487,0.9025845965749928,-2.732075395756724
688.4000000000091,73.9920318973518,0.9467970296792272,-2.7391972613187043
689.6000000000091,74.11522759278647,0.9921138657924848,-2.7469321788371497
690.800000000009,74.2359108170124,1.0440653877570574,-2.7548542367479354
692.0000000000091,74.35869266420085,1.0894347981120693,-2.766153206600225
693.2000000000091,74.48010249528657,1.142505983720222,-2.775510573344441
694.4000000000092,74.60147093115557,1.194021862127061,-2.7836655450225263
695.6000000000092,74.72165010760949,1.2377599270060928,-2.7930914657333417
696.8000000000092,74.84352811105808,1.2876345884422613,-2.8026831247846715
698.0000000000092,74.96489167683072,1.3317675181168416,-2.813359812069764
699.2000000000093,75.08581003104666,1.378666671835578,-2.822531369598585
700.4000000000092,75.20632669241739,1.425187359908605,-2.836305485496082
701.6000000000092,75.32690252292171,1.4640997457321026,-2.8489859663041592
702.8000000000093,75.44894665424533,1.5030212702661951,-2.8620341031563887
704.0000000000093,75.56963229383345,1.5408766229659563,-2.8721123230270136
705.2000000000094,75.690714027812,1.5772076662717016,-2.8842606092989396
706.4000000000093,75.81152480707935,1.615100526335193,-2.8967275542951523
707.6000000000093,75.93370786885679,1.6461100141495355,-2.9117637799534997
708.8000000000094,76.05488986070199,1.6700580407145138,-2.9233088863287935
710.0000000000093,76.17503248825663,1.688288716046965,-2.9357146401134875
711.2000000000094,76.29616540922846,1.706370335714299,-2.9488848045662843
712.4000000000094,76.41732177211989,1.7164146415043868,-2.9640779993384623
713.6000000000095,76.53877621486123,1.7161551586179433,-2.9776481469361773
714.8000000000095,76.65881540790559,1.7018810454692066,-2.992953095059085
716.0000000000094,76.77971348267133,1.6798853130035436,-3.0055968414981313
717.2000000000095,76.90022565935891,1.6372420702904105,-3.019484351087638
718.4000000000095,77.02167692023335,1.574565990877595,-3.0318237272623927
719.6000000000095,77.14299779509078,1.4724344409440855,-3.043666353632108
720.8000000000095,77.2643548240122,1.320680187440067,-3.05615393631646
722.0000000000095,77.3852869327959,1.0871799714415986,-3.0658700929507976
723.2000000000096,77.50598486808691,0.7241504060105326,-3.0742279634402863
724.4000000000096,77.62705683893887,0.21283898879187468,-3.079968407887402
725.6000000000096,77.74734735941902,0.003879135079287943,-3.0822642894851504
726.8000000000096,77.86840204221899,-0.07237259615583103,-3.0826552418669255
728.0000000000097,77.98971657743863,-0.10438416041372234,-3.082620187082778
729.2000000000096,78.11125585823238,-0.11893686964674188,-3.0826117621448264
730.4000000000096,78.23237211379005,-0.12283675271800054,-3.0826198439997268
731.6000000000097,78.35323932245994,-0.1315607171409945,-3.0826197754211946
732.8000000000097,78.47396450060633,-0.13375940915495388,-3.081258853996035
734.0000000000098,78.59483431414867,-0.1337604468436966,-3.081312213404659
735.2000000000097,78.71768532656912,-0.13956473399697988,-3.081299762933662
736.4000000000098,78.83768918735244,-0.1410931759689864,-3.0826202657171273
737.6000000000098,78.9591649144798,-0.14291108124488594,-3.0839500098831003
738.8000000000097,79.0804881647012,-0.14374337204902932,-3.0826200427618824
740.0000000000098,79.20137837586458,-0.14691581650135688,-3.083279990284583
741.2000000000098,79.3231665143643,-0.15150803503742094,-3.082904813159938
742.4000000000099,79.44559273478859,-0.1496342135908597,-3.083280891660953
743.6000000000099,79.56855603501573,-0.15385183867990548,-3.083280400185143
744.8000000000098,79.690504486747,-0.15185671118836086,-3.083940037353943
746.0000000000099,79.8121934083238,-0.1521241940329805,-3.083940056527351
747.2000000000099,79.9345133886236,-0.155202900160599,-3.085074243150368
748.4000000000099,80.05549039732932,-0.155524805947576,-3.085799312444186
749.6000000000099,80.17779546720989,-0.15987570132955709,-3.0854699628607745
750.80000000001,80.29920826119212,-0.16084375699500386,-3.085523870424991
752.00000000001,80.42200758038686,-0.16137137244740418,-3.0845418335346158
753.20000000001,80.54223539808117,-0.1608759131437969,-3.0843294140636965
754.40000000001,80.664341190965,-0.1645295272213665,-3.0848099379689495
755.60000000001,80.7860751039061,-0.16547407601981878,-3.0848093963203693
756.8000000000101,80.90859918489117,-0.16346916047836646,-3.0861299091523153
758.00000000001,81.02948764393734,-0.16297306286881952,-3.0837575833793256
759.20000000001,81.15142888276938,-0.16729480806363028,-3.085808880002509
760.4000000000101,81.27347138351517,-0.1682043868759855,-3.085855205246549
761.6000000000101,81.39518435281819,-0.1700183966257811,-3.0864464517998034
762.8000000000102,81.51726468660443,-0.17124333547421755,-3.085148732371118
764.0000000000101,81.6392941084986,-0.17096235309882446,-3.0848111910387166
765.2000000000102,81.76120492743979,-0.1690621258609255,-3.086129889935041
766.4000000000102,81.88296838964025,-0.17101032396200067,-3.0861305167434834
767.6000000000101,82.00605029532372,-0.17804636811139174,-3.086130467187628
768.8000000000102,82.12827056610583,-0.1745612109745469,-3.0851498870543734
770.0000000000102,82.24948915465794,-0.17982414417602888,-3.086457815862693
771.2000000000103,82.37096056297457,-0.17921899876539382,-3.0851415716123167
772.4000000000103,82.492469226428,-0.18274856680336393,-3.0851402514290487
773.6000000000103,82.61487349845392,-0.18093430856374382,-3.0866125870962438
774.8000000000103,82.73695038519517,-0.18229740605540834,-3.0871198600415393
776.0000000000103,82.85782337758579,-0.1814415687931239,-3.0871198596505236
777.2000000000103,82.98051314200697,-0.18533493608341045,-3.0871203862392984
778.4000000000103,83.10209891163683,-0.18519129792129063,-3.0858098379534717
779.6000000000104,83.22422136535222,-0.182779090540647,-3.085809860529884
780.8000000000104,83.34542443887872,-0.1836853749971472,-3.0871086345575165
782.0000000000105,83.46701043360231,-0.18750579024239977,-3.0884397824346035
783.2000000000104,83.58880678433232,-0.1886308508019805,-3.0874733764145157
784.4000000000104,83.7112889124036,-0.18778092073267683,-3.0864600749298154
785.6000000000105,83.83078327252446,-0.1881039231323769,-3.086460297365789
786.8000000000104,83.95303925788558,-0.1926091208303511,-3.0876367453270577
788.0000000000105,84.0746332032166,-0.193081373798351,-3.0864680702674234
789.2000000000105,84.19557853375737,-0.19544384490979128,-3.086780081291002
790.4000000000106,84.31697018076395,-0.19361905294991621,-3.0877603257956188
791.6000000000106,84.43858871973514,-0.19349695065099337,-3.0876953651161267
792.8000000000105,84.55944758097111,-0.1948481746270252,-3.086459858777521
794.0000000000106,84.68170469694702,-0.19145350975537156,-3.0857788845127496
795.2000000000106,84.80469307333253,-0.19397265098595118,-3.087120103618512
796.4000000000106,84.92635761216623,-0.19378563906863944,-3.0876005062016065
797.0000000000106,84.98747942357157,-0.19129976149429084,-3.0884297666435856