File: 01_Data/Nylon_Carpet_High_Pile/STA/N2/10K_min/Nylon_Carpet_High_Pile_STA_N2_10KData_220308_R2.csv
##Temp./Â°C,Time/min,DSC/(mW/mg),Mass loss/mg
50.0,10.531492343261478,0.00919290722515198,-0.0013972110271822658
51.20000000000002,10.968869943469695,0.07095509668726407,-0.0006973746074381282
52.400000000000034,11.211832184280688,0.11010675930887315,0.002239801320242485
53.60000000000005,11.408874454644893,0.14164010463692678,0.002696069481899599
54.80000000000007,11.578359559104362,0.16359744136954146,-0.0005286485618114511
56.000000000000085,11.738947004277932,0.18227997844458443,0.002252766799370143
57.2000000000001,11.889379621466453,0.19701349129521384,0.002227115248716771
58.40000000000012,12.033472064720062,0.21054708527738852,0.0022178389249196684
59.600000000000136,12.173996112395487,0.21832696090465442,0.004315039244775498
60.80000000000015,12.312164981608673,0.23029119846783663,0.001505444562965863
62.00000000000017,12.447232025641004,0.2348528224514712,0.0010066025561163983
63.20000000000019,12.581368663319015,0.24389093847502064,-0.0005184008774437032
64.4000000000002,12.712848005542202,0.24896481938871473,-0.0007339521910267877
65.60000000000022,12.845489227484665,0.25284155054842017,0.006249691151413828
66.80000000000024,12.974006393692076,0.2595945391069895,0.0018760877004382337
68.00000000000026,13.104599462579511,0.2639527744814737,-0.0018828628351954535
69.20000000000027,13.234754492086807,0.2695257494411684,0.001990594497836895
70.40000000000029,13.364137299926172,0.27537782933133237,0.002457795491472403
71.6000000000003,13.490798110245422,0.2803704067893151,-0.0019647497444434947
72.80000000000032,13.619669468711619,0.28521582731964773,0.00200849502310696
74.00000000000034,13.744860739687672,0.28666581317136836,0.004831335163859585
75.20000000000036,13.871950644180178,0.289128191365302,0.0007637032479115291
76.40000000000038,13.997530538241863,0.29463825545589517,-0.0006002396905984142
77.60000000000039,14.123247358288184,0.2985832609670935,0.0007590444886247383
78.80000000000041,14.249068400085287,0.3017336542767141,-0.0018974105993301293
80.00000000000043,14.373666816713282,0.30622447006301656,-0.0020324115238699036
81.20000000000044,14.492653827956959,0.3111681090806129,-0.004390132207685582
82.40000000000046,14.619170000000047,0.31346231465268953,-0.00307999299957995
83.60000000000048,14.742436701564541,0.31890423368377546,-0.0030762583459100767
84.8000000000005,14.866088539180117,0.32292697281748717,-0.0044000373977803875
86.00000000000051,14.986202288453235,0.32374433492276417,-0.004352141252534025
87.20000000000053,15.10897171411356,0.32567350085522195,0.0022821226217351054
88.40000000000055,15.230453018785552,0.3266003197275118,0.0002344202453752331
89.60000000000056,15.350904139121582,0.3299267655799768,-0.008213385612117818
90.80000000000058,15.471043626680727,0.33235883688922874,-0.014867050888081046
92.0000000000006,15.591576317601378,0.3356411561383802,-0.009526247547545275
93.20000000000061,15.711551388642983,0.3338010523735998,-0.00029957161601945614
94.40000000000063,15.831710662972714,0.3371938715506721,0.002267106071795588
95.60000000000065,15.951548961742766,0.3362204858721318,0.00029717236248938406
96.80000000000067,16.07007901316417,0.3359485396673182,-0.002332148894841346
98.00000000000068,16.189274524210383,0.33736344219558195,-0.004817748237885056
99.2000000000007,16.307435990153767,0.3383583297482027,-0.006039996130515313
100.40000000000072,16.426049327177264,0.33834796369626796,-0.0060337760053306155
101.60000000000073,16.543899045639158,0.3378382246662398,-0.0030845108870689586
102.80000000000075,16.662047152403023,0.33687541219751094,-0.003959659355685652
104.00000000000077,16.7806608960911,0.3384218842766257,-0.006186313164745272
105.20000000000078,16.897669319702437,0.33593644865830186,-0.008412630952348898
106.4000000000008,17.01683657181818,0.3382674542266867,-0.005342347890976207
107.60000000000082,17.13468008277026,0.3333572525404217,-0.004510643789807922
108.80000000000084,17.251562418287538,0.33247390579526714,-0.005813352955473583
110.00000000000085,17.36937854180659,0.3344556399783999,-0.007132004088587607
111.20000000000087,17.48815088255344,0.3337834835596082,-0.005819855629102477
112.40000000000089,17.605275169268495,0.33589751692094294,-0.009860660365746732
113.6000000000009,17.72339856094316,0.335115019971819,-0.008078535002477238
114.80000000000092,17.840933832591105,0.33693253744547513,-0.00747226333209472
116.00000000000094,17.957383814087443,0.33805778978771817,-0.008381721161978106
117.20000000000095,18.075346602773767,0.3387293862059229,-0.0075823096053992955
118.40000000000097,18.192748269514084,0.3392095825172381,-0.00835044879813207
119.60000000000099,18.308797175105035,0.3382240421211216,-0.010087530005422174
120.800000000001,18.42448204393209,0.33833216920569786,-0.012384159286198404
122.00000000000102,18.5424506689254,0.3394207999306045,-0.011106363147517229
123.20000000000104,18.65966643109436,0.34192252343762214,-0.011089350533247
124.40000000000106,18.775955712467116,0.341396839963652,-0.006927984416766009
125.60000000000107,18.893530750015827,0.3403029899413102,-0.008551502882589546
126.80000000000109,19.00936630493152,0.34061561048984224,-0.00954014584131535
128.0000000000011,19.127304997878504,0.34063186801454437,-0.009879198690411428
129.20000000000113,19.243523471598802,0.34428802003410786,-0.012507989956451304
130.40000000000114,19.360788862461714,0.34338720730694083,-0.013671782968518897
131.60000000000116,19.476438925737884,0.34415861873311787,-0.008732960133952972
132.80000000000118,19.592820075684976,0.3444348663633833,-0.0074700224260544346
134.0000000000012,19.708801171255693,0.3482381454556093,-0.013944926182873019
135.2000000000012,19.825316993734283,0.34839225274535823,-0.011825649265864158
136.40000000000123,19.941169694672823,0.3485785034258863,-0.013313387313479197
137.60000000000124,20.057764291371875,0.35145104869021293,-0.014596654567993639
138.80000000000126,20.171877164328667,0.35092176052152435,-0.011958680985722836
140.00000000000128,20.290383870745202,0.35404708677507185,-0.013383284796323558
141.2000000000013,20.405699032010027,0.35461979229999985,-0.015125228246741784
142.4000000000013,20.522102623388783,0.35559890202097927,-0.014361975074336009
143.60000000000133,20.636977055105177,0.3599448955184786,-0.010230896820072388
144.80000000000135,20.75237134220713,0.3607098605438424,-0.00889018411220821
146.00000000000136,20.86953241500748,0.36354219359120676,-0.010205297521796552
147.20000000000138,20.984059849348082,0.3632343202027271,-0.013791385047420057
148.4000000000014,21.100137786063904,0.3684302096844923,-0.013752090575451348
149.60000000000142,21.214998300421115,0.3695156987658603,-0.013392501532229595
150.80000000000143,21.332044196868733,0.3747135266606494,-0.016575570993583533
152.00000000000145,21.44612424485927,0.3784610496726943,-0.014394320511784464
153.20000000000147,21.56217291303979,0.3841375772958772,-0.014772412899084486
154.40000000000148,21.67766824755251,0.3852626057524395,-0.017559772819661923
155.6000000000015,21.794053408730583,0.3925413312361535,-0.01718363588452032
156.80000000000152,21.908050937076705,0.40123443740585085,-0.011292329015778257
158.00000000000153,22.0241719816333,0.4093842051097535,-0.007818850064247762
159.20000000000155,22.138682767980235,0.41712193700040356,-0.012069871249599018
160.40000000000157,22.25416374497667,0.42978749899577484,-0.015230545932809036
161.6000000000016,22.369267921131904,0.4411577703845359,-0.017340187442698607
162.8000000000016,22.484774481763857,0.4495277828837687,-0.014598725685560865
164.00000000000162,22.600888467365404,0.4560424269238294,-0.013251570489391185
165.20000000000164,22.716441123386648,0.45720472883760577,-0.01064985229871418
166.40000000000165,22.83187865443934,0.4548056214851586,-0.010649876333656216
167.60000000000167,22.948302115649287,0.44303821808141686,-0.014475925455378125
168.8000000000017,23.06237446610093,0.4295099181974925,-0.0170905335904461
170.0000000000017,23.178218005600026,0.41424116823772983,-0.015842531140505045
171.20000000000172,23.292650490151843,0.4005525022033498,-0.014473408050863945
172.40000000000174,23.408277881146336,0.3945079523523229,-0.018571364942696178
173.60000000000176,23.52358981871789,0.3894675083252537,-0.01997001801737497
174.80000000000177,23.638689716921714,0.38929362396259354,-0.019683839896753597
176.0000000000018,23.753032073729415,0.38767704794224506,-0.017589736963253166
177.2000000000018,23.868633405343292,0.38846766212328326,-0.018440153026379136
178.40000000000182,23.98284890479546,0.3904818626253369,-0.015702776419342257
179.60000000000184,24.09870908569338,0.390783532804099,-0.013721427741160142
180.80000000000186,24.213275181659625,0.3940586599386521,-0.015152985547473463
182.00000000000188,24.328684446621487,0.39438168284538194,-0.01776943135625153
183.2000000000019,24.44360097245966,0.3989374013709851,-0.01672108606997913
184.4000000000019,24.557225257118343,0.4013305268813748,-0.016384162606525976
185.60000000000193,24.673793321582977,0.403187259839224,-0.017657501033162326
186.80000000000194,24.788485163055295,0.40750042959177646,-0.019970949848523212
188.00000000000196,24.90356700344504,0.4092873271161736,-0.018650087582976482
189.20000000000198,25.01750817349515,0.4094270856055092,-0.019970484273912348
190.400000000002,25.132700674608397,0.41358139953784173,-0.021294375310841218
191.600000000002,25.24765833974927,0.41598800149102555,-0.017010827497179193
192.80000000000203,25.362688763407007,0.4170910998005792,-0.01974987473897194
194.00000000000205,25.47739860068478,0.41961994547144765,-0.019185411131264374
195.20000000000206,25.59242195541117,0.42370715830093075,-0.02048208278977892
196.40000000000208,25.70728743384915,0.42576434988493894,-0.023546924484010745
197.6000000000021,25.82072425024516,0.429968733139737,-0.02297063201849081
198.80000000000211,25.93683106305921,0.4336210593313299,-0.019274199464478947
200.00000000000213,26.052329848495393,0.4390954969791735,-0.017736607517232272
201.20000000000215,26.166848995366077,0.43867814319158005,-0.01717952549317303
202.40000000000217,26.28112631312651,0.44211148789218035,-0.01962039045221342
203.60000000000218,26.394891552948998,0.4496561291871215,-0.021940174718197092
204.8000000000022,26.511550894967215,0.45274864687751093,-0.02325823892612089
206.00000000000222,26.62438789296379,0.4613017014085649,-0.025826140795526698
207.20000000000223,26.739885667244142,0.4660062793195974,-0.023150057816223146
208.40000000000225,26.855891492278687,0.4713043973635956,-0.021805039831294337
209.60000000000227,26.970336418471724,0.48262223385312025,-0.01920110245152884
210.80000000000229,27.084385206465075,0.4976929153294566,-0.020186018855812726
212.0000000000023,27.199993781882043,0.5146456907995831,-0.02052036770353638
213.20000000000232,27.314977579246506,0.5441072630650401,-0.023080259527588076
214.40000000000234,27.430297362428597,0.5873109267563558,-0.02514476612963712
215.60000000000235,27.545083984647615,0.6638528062046009,-0.02457006908681514
216.80000000000237,27.659670343628243,0.7783088959807405,-0.02325999439441162
218.0000000000024,27.776022963825245,0.9097655801932903,-0.021688276931701722
219.2000000000024,27.892818238048914,1.0213764777683745,-0.023264880912760688
220.40000000000242,28.007942721726,1.0890304068078833,-0.024573541410899402
221.60000000000244,28.123664116546735,1.0957838790421341,-0.024587811458069098
222.80000000000246,28.238301354222784,1.0249201194984328,-0.024570194261779754
224.00000000000247,28.35287863086006,0.8652733840127167,-0.02589243579677003
225.2000000000025,28.46762878165319,0.6976510537473277,-0.024239771881140015
226.4000000000025,28.581586908750815,0.5869288718456077,-0.025670257992850054
227.60000000000252,28.695885843058033,0.525711460922336,-0.02665986992925884
228.80000000000254,28.808005358953643,0.49388085711469615,-0.027775397970974502
230.00000000000256,28.92209194357211,0.47570205338881105,-0.027928378276397048
231.20000000000258,29.03604131314861,0.46772012999516177,-0.02535013139579778
232.4000000000026,29.15026629977054,0.4603775947353655,-0.025350129201139104
233.6000000000026,29.263721148445363,0.45782396119438706,-0.02984689752327352
234.80000000000263,29.378014005333313,0.4583428093779363,-0.02720813482443596
236.00000000000264,29.491573897274996,0.4565398720322872,-0.02730025513830725
237.20000000000266,29.606586010082953,0.4566155037459322,-0.029943006752057855
238.40000000000268,29.721461787988723,0.45474594960616394,-0.031204354776356524
239.6000000000027,29.8356781421338,0.4550458716091707,-0.029949852173469793
240.8000000000027,29.95007033299351,0.4563572335474885,-0.02994985200322553
242.00000000000273,30.064924283015515,0.4572998861602364,-0.029940171826726925
243.20000000000275,30.178574733247444,0.45529789421606587,-0.030280213747987617
244.40000000000276,30.293311036612213,0.45800925011380217,-0.03169155677171798
245.60000000000278,30.407634148717335,0.4587566036948413,-0.032028582952007056
246.8000000000028,30.523467488836946,0.4587309090200582,-0.029779950938812583
248.0000000000028,30.637229382454084,0.457465394605177,-0.033350135828655425
249.20000000000283,30.75282113609691,0.4582287532706062,-0.03523910323278212
250.40000000000285,30.86712285771862,0.4597509948767834,-0.03317055758138476
251.60000000000286,30.981925632861813,0.45737140895656125,-0.03433801885471244
252.80000000000288,31.096055857320152,0.4597614150742638,-0.036969752889632446
254.0000000000029,31.21183859085115,0.46068776844393194,-0.035663593863528575
255.20000000000292,31.32640762661974,0.45994175243395496,-0.03434015827301007
256.40000000000293,31.44111076005879,0.46384306746225823,-0.034340159478389864
257.600000000003,31.555808287845146,0.4631817630180579,-0.03498337344823188
258.80000000000297,31.670050150654678,0.4640734455084842,-0.03498661447238849
260.00000000000296,31.784728565331903,0.4656989557888107,-0.03774089202856512
261.200000000003,31.898979023719477,0.46853421229327497,-0.0397091456693861
262.40000000000305,32.014461440864864,0.46797766988338724,-0.03841541262264769
263.60000000000304,32.12810161872557,0.4695635633593288,-0.03971008379348362
264.800000000003,32.24123947295876,0.4697714647678782,-0.03971008399773357
266.00000000000307,32.35672296004983,0.47129867307274914,-0.039717857885021246
267.2000000000031,32.471998596687015,0.4698884811312157,-0.03838816571748893
268.4000000000031,32.586253774303515,0.4727125862726011,-0.04102857924609182
269.6000000000031,32.700221063459395,0.473054561892429,-0.04104682692442729
270.80000000000314,32.81374513515909,0.4736980824567439,-0.043669870941475786
272.0000000000032,32.92899151850676,0.4760321957704204,-0.043669885999763736
273.2000000000032,33.04319472611582,0.4753369006138618,-0.04365881117065307
274.40000000000316,33.157042692438246,0.4750357341138903,-0.04234998697212422
275.6000000000032,33.27210174297198,0.47563431831310127,-0.04234998284627878
276.80000000000325,33.386466738305145,0.4773568002019941,-0.04367336194446381
278.00000000000324,33.50086355844599,0.47388738213438125,-0.043668422688470265
279.20000000000323,33.61442216076307,0.47298308062233935,-0.04300988795596439
280.4000000000033,33.72961235535238,0.4756183351722061,-0.0445699314620942
281.6000000000033,33.84336186506661,0.47554880257857934,-0.04606989257484617
282.8000000000033,33.95818467772272,0.474738241974259,-0.046392698366560126
284.0000000000033,34.07422295535386,0.47448839413817595,-0.046703442502574966
285.20000000000334,34.18866565384454,0.47658811403338175,-0.04672975154957992
286.4000000000034,34.30022029295957,0.4747186776924521,-0.04738248203984696
287.6000000000034,34.41842743030189,0.4775957849157877,-0.04968750169212299
288.80000000000337,34.53242912503106,0.4771267045532003,-0.05133988397852818
290.0000000000034,34.64778969821329,0.4774197122832943,-0.05265902315625137
291.20000000000346,34.763006765095234,0.4766377099651608,-0.05137260700377233
292.40000000000344,34.87754224667935,0.47552599027341924,-0.05001986504112921
293.60000000000343,34.993533229583335,0.47597741975842284,-0.05131258545218298
294.8000000000035,35.108234636855656,0.4771012361580711,-0.048709423991085465
296.0000000000035,35.22410888255385,0.47904551948234647,-0.048945768398446
297.2000000000035,35.33962735773681,0.48140424836376033,-0.055073729324380594
298.4000000000035,35.45614498838588,0.4839852164200937,-0.05481311068755801
299.60000000000355,35.5718586155248,0.48340182575542173,-0.056387511038498594
300.8000000000036,35.68725943835687,0.4893981593379133,-0.061235810380156686
302.0000000000036,35.802679680238576,0.49349653753903977,-0.06127330619674787
303.20000000000357,35.91925939819338,0.4965831444036575,-0.0590123331775807
304.4000000000036,36.034339245235934,0.49927510464811303,-0.06018251366187943
305.60000000000366,36.14858685395562,0.506049614510911,-0.06165034964967919
306.80000000000365,36.2654880119063,0.5072202007824502,-0.06166300717376405
308.00000000000364,36.379170000000364,0.5079939134123718,-0.0629677053878126
309.2000000000037,36.495976402207305,0.5139906062671685,-0.06708590095754197
310.40000000000373,36.6107654883997,0.5154609224498052,-0.07044394371976415
311.6000000000037,36.727292022584535,0.5181544160056527,-0.07042977867661282
312.8000000000037,36.84169945471957,0.5217779190383108,-0.07074073053700447
314.00000000000375,36.95715099952177,0.5272625468272859,-0.07305147372581544
315.2000000000038,37.072793686201976,0.5299236345356606,-0.07702004537162965
316.4000000000038,37.188783366038976,0.5333281078570694,-0.08043410006343565
317.6000000000038,37.30425012600144,0.5378109999022752,-0.08372526011576076
318.8000000000038,37.41978321771529,0.5430817253746977,-0.08687751841975588
320.00000000000387,37.53499747459294,0.547236484176407,-0.08863235254169011
321.20000000000385,37.651343010791855,0.5531458046259523,-0.08961708525240963
322.40000000000384,37.767036847787764,0.5602159891309446,-0.09280519206049309
323.6000000000039,37.88377128701997,0.5625421118608098,-0.09991879487058775
324.80000000000393,37.99760162369535,0.568971114820901,-0.1061976225626271
326.0000000000039,38.11440971625594,0.577079201653207,-0.10879667658569048
327.2000000000039,38.23065926133581,0.5817864965811947,-0.11304880888834834
328.40000000000396,38.34657949762851,0.5871093728667558,-0.1173867394291852
329.600000000004,38.46157145941518,0.5945461327205855,-0.12173245769102525
330.800000000004,38.57725415625454,0.6019661429667335,-0.12517870203035653
332.000000000004,38.69433791542384,0.6092008755324889,-0.13142463508764735
333.200000000004,38.80957383309396,0.6180796936663326,-0.13626088234670686
334.40000000000407,38.925348928092816,0.6278005453542866,-0.14567321208161665
335.60000000000406,39.0410088385293,0.6364987368276125,-0.15262200051639097
336.80000000000405,39.15724888194799,0.6464064912198717,-0.15747850121772666
338.0000000000041,39.27361319308785,0.6545542293140983,-0.16610803748721947
339.20000000000414,39.3887587003904,0.665289704492757,-0.17381752640859016
340.4000000000041,39.505701482119974,0.674019247826001,-0.1825804033614835
341.6000000000041,39.62090944282428,0.6856140434735535,-0.1910299235540487
342.80000000000416,39.7382204765328,0.6990698933605918,-0.19970968159253077
344.0000000000042,39.85364131570631,0.7101826277962551,-0.2097548502503801
345.2000000000042,39.96991974890862,0.7221053951201796,-0.21685069182487826
346.4000000000042,40.08590780417154,0.7333216973326676,-0.2315001688771936
347.60000000000423,40.20238569029404,0.7495980881378885,-0.24193376510840237
348.8000000000043,40.3183162878615,0.7611179129647146,-0.2533912756856558
350.00000000000426,40.43537026399837,0.7742324377358918,-0.26816089517983954
351.20000000000425,40.552083044138556,0.7866454536437982,-0.2813006517565877
352.4000000000043,40.66771525897517,0.7977411289539023,-0.2936178195620607
353.60000000000434,40.78400628840472,0.8138322557634132,-0.30799519618426086
354.80000000000433,40.900074002647095,0.8238001743505109,-0.3234797688122484
356.0000000000043,41.01606005293904,0.8394586305350559,-0.33804282058618584
357.20000000000437,41.132186108930206,0.854665565011451,-0.35554331135304285
358.4000000000044,41.24938672116386,0.8704130852330716,-0.3713262930352115
359.6000000000044,41.365106590756795,0.8835288852142803,-0.38591673432267726
360.8000000000044,41.481119733913324,0.9004466016422783,-0.40587499544447203
362.00000000000443,41.59806484610809,0.9161389562169575,-0.42339597660548023
363.2000000000045,41.714162090389884,0.931850303242148,-0.4388595205095487
364.40000000000447,41.83034436901604,0.9464017692841318,-0.4588815964080193
365.60000000000446,41.94583250353543,0.9630736984707922,-0.47847921080057443
366.8000000000045,42.06219536611735,0.9777201496911581,-0.4970515832682647
368.00000000000455,42.17928428547318,0.996104573464553,-0.5235628572313553
369.20000000000454,42.29738184627064,1.0162858693223367,-0.5486151059160393
370.4000000000045,42.4114149513823,1.0355040000734381,-0.5732782401709793
371.60000000000457,42.53032918431676,1.0540036359607863,-0.6024672569472664
372.8000000000046,42.64717132241384,1.0732011844764655,-0.6272932848290091
374.0000000000046,42.764654751558425,1.095414053148553,-0.6522384529048613
375.2000000000046,42.88176883025531,1.114485983547718,-0.6786803148459097
376.40000000000464,42.997843510128,1.1371297340700437,-0.7078411913867191
377.6000000000047,43.11449035764395,1.1605348910556526,-0.740909292050739
378.8000000000047,43.230679189733934,1.1804935809439816,-0.7712179828932335
380.00000000000466,43.34789326815201,1.2008860130493304,-0.8037101552106489
381.2000000000047,43.46515938930306,1.218761701098298,-0.8364057111617478
382.40000000000475,43.5808979019486,1.2370846931720605,-0.8753255874321209
383.60000000000474,43.69808032884885,1.2589330925525146,-0.9117709516452561
384.80000000000473,43.81454750175903,1.2766986031863023,-0.9442303530511293
386.0000000000048,43.9318468990688,1.2923245085611141,-0.986818313410025
387.2000000000048,44.047695850720814,1.308585099519249,-1.0285152235054884
388.4000000000048,44.16528029113889,1.3226632488817749,-1.0744569098028363
389.6000000000048,44.28274615974994,1.3381153100015797,-1.11992005479952
390.80000000000484,44.3983056371533,1.3447085502951244,-1.1642948324154188
392.0000000000049,44.516006428239116,1.3485186331875294,-1.2097860299987158
393.2000000000049,44.633291256327944,1.3527178108410534,-1.25710846444826
394.40000000000487,44.75053970240322,1.3515080567759805,-1.3037075048449802
395.6000000000049,44.868131148366814,1.345649017163551,-1.348254695564338
396.80000000000496,44.984277345565715,1.333454283020207,-1.3940901470094378
398.00000000000495,45.10164651672516,1.3167249576132904,-1.44292355951215
399.20000000000493,45.21968642205622,1.2935311361716701,-1.4916037667004622
400.400000000005,45.335623398736196,1.2647531540873214,-1.5408499375382108
401.600000000005,45.45258663757929,1.2259613951715465,-1.5859937543974616
402.800000000005,45.570161118298465,1.1814729175363219,-1.6319528457312944
404.000000000005,45.686528746239944,1.1273118675362281,-1.6770271012381999
405.20000000000505,45.80335834070669,1.063480083443873,-1.7203199061243826
406.4000000000051,45.919074601810365,0.9923298732814949,-1.759883074356917
407.6000000000051,46.037024584072974,0.9190602865854536,-1.7922014545805025
408.80000000000507,46.15370642637169,0.8394038062153577,-1.8228888970854822
410.0000000000051,46.2706192243072,0.7675538537838353,-1.8509691285076162
411.20000000000516,46.38697280219336,0.6964908115788195,-1.8768264018295215
412.40000000000515,46.50365854109397,0.6327705372913246,-1.9010418186829834
413.60000000000514,46.62046624028375,0.5765666324083377,-1.9184766723577198
414.8000000000052,46.73611489082968,0.5371029306583803,-1.9352045086450942
416.00000000000523,46.85379813519883,0.5009225409890316,-1.9521794553064518
417.2000000000052,46.97030935098071,0.47518139881461713,-1.9642760498776317
418.4000000000052,47.08753446915333,0.4536591236659084,-1.9741005334207156
419.60000000000525,47.20475052566969,0.43989815122340686,-1.984151831307523
420.8000000000053,47.322530025120244,0.4299962999398729,-1.9928145675482272
422.0000000000053,47.439652196059875,0.42055666770039085,-2.000841048996416
423.2000000000053,47.557673925444135,0.4140842438882759,-2.013031033140491
424.4000000000053,47.67467518672285,0.4098730833476419,-2.0236279668036903
425.60000000000537,47.791279877026945,0.406283640790668,-2.031918718389437
426.80000000000535,47.908173037479045,0.4030374998019422,-2.0446613332441306
428.00000000000534,48.027054914511226,0.4023196074241699,-2.0492151268283196
429.2000000000054,48.14354658480116,0.39890160990368323,-2.0493267544773808
430.40000000000543,48.26131632862085,0.3983382378876757,-2.0597493334653483
431.6000000000054,48.37907834742582,0.3978858329061073,-2.0687987463852733
432.8000000000054,48.496634465354475,0.3991976814214648,-2.0789593005662006
434.00000000000546,48.61360086818698,0.39606206428344903,-2.084504557921985
435.2000000000055,48.73009676890126,0.396287128979475,-2.091676355027418
436.4000000000055,48.84869187250177,0.39744788225615574,-2.097163243715644
437.6000000000055,48.967198168229444,0.3986082741643121,-2.1061729079374905
438.8000000000055,49.084021953385054,0.4021960477933005,-2.1153684751945327
440.00000000000557,49.20214118093576,0.40103598489052883,-2.123791031963493
441.20000000000556,49.31907686012794,0.40135221671503274,-2.132083083788052
442.40000000000555,49.43808361724316,0.39992664824610563,-2.1392930096112317
443.6000000000056,49.555173376708524,0.40263504838094977,-2.146046959387193
444.80000000000564,49.673039713319994,0.40406144302796937,-2.155288579655674
446.0000000000056,49.79093833558707,0.40867743372756554,-2.1633823485802304
447.2000000000056,49.90856823570872,0.4091921124603556,-2.1751739612904313
448.40000000000566,50.025773797833835,0.4122074087525821,-2.1822100414615333
449.6000000000057,50.14289205948465,0.41417019494615537,-2.1914590396529574
450.8000000000057,50.26140618734904,0.4114982037610159,-2.1984644692900925
452.0000000000057,50.379259670402625,0.41261599283360506,-2.20754010235033
453.20000000000573,50.496322523991715,0.4129538888932431,-2.2163677939254924
454.4000000000058,50.61411275950756,0.41326825828408864,-2.22631264360344
455.60000000000576,50.732618196823374,0.4150229146858476,-2.2359608714913337
456.80000000000575,50.8504288731009,0.414639830214026,-2.243612908722466
458.0000000000058,50.968761855980574,0.41521306850206446,-2.257422057234961
459.20000000000584,51.08739928361056,0.4173907581236459,-2.269245152330402
460.40000000000583,51.20635592484776,0.41748768166692984,-2.2771284160514695
461.6000000000058,51.3247344493329,0.4161125562818449,-2.2861830977904893
462.80000000000587,51.44342980461238,0.41771362165337433,-2.298544796353668
464.0000000000059,51.56291958839373,0.4178763570230552,-2.310490227848904
465.2000000000059,51.680925841108355,0.4207234225130676,-2.3207399347813427
466.4000000000059,51.80031764887744,0.41929825170488016,-2.32950220404451
467.60000000000593,51.91969607388906,0.41615715534771036,-2.339729698271089
468.800000000006,52.03723914432335,0.41692855624875147,-2.3510253373778776
470.00000000000597,52.155647589972986,0.4195812649147958,-2.3656446724580924
471.20000000000596,52.2736315125688,0.41455707078564297,-2.376502157301097
472.400000000006,52.39112076659618,0.40908263573568304,-2.384925376679508
473.60000000000605,52.51131578534845,0.3997635758941488,-2.3936019178752055
474.80000000000604,52.62874994965692,0.3944248876375751,-2.4083485939906115
476.000000000006,52.74675736664508,0.3837641757157004,-2.4153660004956246
477.20000000000607,52.865753223172405,0.36594785226049936,-2.4274948830335847
478.4000000000061,52.98484516558516,0.3494957652111506,-2.4364351974578256
479.6000000000061,53.10372738178032,0.3308875858614879,-2.443859415621216
480.8000000000061,53.222369377489,0.3125662337630919,-2.4488508425257445
482.00000000000614,53.34147385942583,0.29588282014040806,-2.4482519729770598
483.2000000000062,53.45886256436053,0.2809581574170831,-2.45259938667662
484.4000000000062,53.57887232777486,0.2692900462712784,-2.453794065660501
485.60000000000616,53.69799287504145,0.2590193276653562,-2.4579758813149493
486.8000000000062,53.81660987864448,0.2535415319945653,-2.460579172990184
488.00000000000625,53.936123330588444,0.24645264063865957,-2.4588398579680146
489.20000000000624,54.05448473026573,0.24823685547521873,-2.459872989733922
490.40000000000623,54.17251561385242,0.24989816480744947,-2.4585111696345834
491.6000000000063,54.29282757387522,0.2503369663419479,-2.4599376217908357
492.8000000000063,54.41019827950562,0.25704426428572696,-2.462570073853608
494.0000000000063,54.530301047530436,0.26560086103469455,-2.4605906183072994
495.2000000000063,54.648420639135374,0.27314563611353165,-2.4628171576253584
496.40000000000634,54.7676079925274,0.2723306264561899,-2.4637702244572965
497.6000000000064,54.88581683346951,0.26924301466654776,-2.4657787635999453
498.8000000000064,55.00619486172956,0.26914350615328503,-2.4628034258529405
500.00000000000637,55.124095786064544,0.26887071597501394,-2.465445061432715
501.2000000000064,55.243869886119406,0.267683605101552,-2.466079837033316
502.40000000000646,55.36231121128099,0.26566001662467414,-2.462067138759934
503.60000000000645,55.48157374084758,0.25790753694102925,-2.465016241432121
504.80000000000643,55.59917103764962,0.2557335162539133,-2.4663000965522817
506.0000000000065,55.71850966038391,0.25247886085504734,-2.4649805707203005
507.2000000000065,55.83827084876421,0.2500038021169067,-2.466273364557779
508.4000000000065,55.95704637562415,0.24757408097029254,-2.468930184228908
509.6000000000065,56.077118518327225,0.24461782004456456,-2.4676106472974975
510.80000000000655,56.19609519964312,0.24627172752670556,-2.468791017063189
512.0000000000066,56.314915260025856,0.23919048224225486,-2.470579913682613
513.2000000000066,56.43428809973276,0.2325873395833885,-2.4705800487903655
514.4000000000066,56.55418980597506,0.22694146964838868,-2.4702751221978185
515.6000000000066,56.67399984273401,0.22637992554071018,-2.470237396061017
516.8000000000067,56.79025279732986,0.22532634902963655,-2.470243478376813
518.0000000000066,56.91244517500614,0.22128416727599343,-2.4683465572319663
519.2000000000066,57.030970374468936,0.2253324050075377,-2.4688948312983126
520.4000000000067,57.15074646359693,0.22813450169200822,-2.470139888085251
521.6000000000067,57.26985648258608,0.22547489121948405,-2.4705425093466356
522.8000000000068,57.38917102698075,0.2239904678442982,-2.4714598883607546
524.0000000000067,57.509258174019315,0.221677114099588,-2.473747856795765
525.2000000000068,57.62907336714616,0.22283384489029034,-2.475069944356881
526.4000000000068,57.747286976577676,0.22371798931261366,-2.476379330799398
527.6000000000067,57.8688616698495,0.2228680810271314,-2.4753995938043447
528.8000000000068,57.98798826779408,0.22089057745283103,-2.474953326480313
530.0000000000068,58.106686958775526,0.22012765434022252,-2.4726600335239364
531.2000000000069,58.227513624069175,0.22346446457980762,-2.471341430657322
532.4000000000069,58.34577951722636,0.22326304859097246,-2.471700430692585
533.6000000000068,58.465086406757855,0.22510262721187158,-2.474410042313931
534.8000000000069,58.58410801060197,0.223592506780387,-2.4744100791619585
536.0000000000069,58.70330870153677,0.2267164957382749,-2.475549503314296
537.2000000000069,58.822929914830866,0.22585451023236613,-2.473829433472384
538.4000000000069,58.9432774775759,0.22726032863475287,-2.475982142405314
539.600000000007,59.06210882486393,0.22998761188061634,-2.475080050719269
540.800000000007,59.18203544633282,0.23178811321394943,-2.476389730564385
542.000000000007,59.30095503805992,0.2332776517509748,-2.4763898995755347
543.200000000007,59.419913936318544,0.23194172102854316,-2.4754346766200896
544.400000000007,59.5405822833785,0.23325021841075289,-2.476750900941128
545.6000000000071,59.66023213239024,0.23150587727627137,-2.4752403018401274
546.800000000007,59.77953818576854,0.22971737340166132,-2.476399199933672
548.000000000007,59.898753365645305,0.23071757145647553,-2.4803823229605957
549.2000000000071,60.01828442888964,0.23358046650027042,-2.478932561718557
550.4000000000071,60.13967792059518,0.23162548910212122,-2.479459363648224
551.6000000000072,60.25968142455184,0.235196829552214,-2.4821276702488166
552.8000000000071,60.37867503865745,0.23370956878281757,-2.479460103550752
554.0000000000072,60.49856842656627,0.23083053256497998,-2.478743405023609
555.2000000000072,60.6188748460384,0.23375462628406218,-2.48078114101988
556.4000000000071,60.739671893576094,0.23357815040941288,-2.4830788590064983
557.6000000000072,60.85846478329678,0.23762035621897426,-2.483079969000248
558.8000000000072,60.97816812840777,0.23587768943242504,-2.483079964174607
560.0000000000073,61.09884194517037,0.23741135919236245,-2.481751919683391
561.2000000000073,61.21828754100689,0.2405189893937596,-2.4830783855427585
562.4000000000073,61.33810203024287,0.23823131222567884,-2.485710043383432
563.6000000000073,61.458260150403156,0.23947851520411823,-2.483083229582845
564.8000000000073,61.57863958579343,0.23768296648811116,-2.482539223831783
566.0000000000073,61.69765862877348,0.2368723266949545,-2.484613665917479
567.2000000000073,61.818564393883065,0.2354940573588481,-2.481948451679196
568.4000000000074,61.93906781605957,0.23963586264947878,-2.4819798909396384
569.6000000000074,62.05955935853147,0.23750342978501404,-2.483300767010454
570.8000000000075,62.17937573257378,0.238711558957019,-2.4846837134489634
572.0000000000074,62.29961507141049,0.24439686744152955,-2.4872337303742067
573.2000000000074,62.41944084310412,0.2436988028571745,-2.4885578156887336
574.4000000000075,62.5390760752413,0.24170444627712706,-2.48348842489772
575.6000000000074,62.659357359278516,0.24386219579931234,-2.482417764470708
576.8000000000075,62.779059032150855,0.24346986452437347,-2.484638536098686
578.0000000000075,62.899907257629835,0.25080628321434495,-2.487363772088573
579.2000000000075,63.01986137025385,0.2531573988746145,-2.4886698628218307
580.4000000000076,63.1391679965933,0.24884091541201603,-2.4884995833316954
581.6000000000075,63.25993593617031,0.25202225650786303,-2.4847302654588095
582.8000000000076,63.38113522680882,0.2538733344533779,-2.486039814950572
584.0000000000076,63.500482319429565,0.2568181005546978,-2.4873637507918605
585.2000000000075,63.62114256814064,0.25388145225930825,-2.488187652426574
586.4000000000076,63.74065890650178,0.25558786994510074,-2.4899893266028297
587.6000000000076,63.861067167901545,0.25576091169826976,-2.4912997936561707
588.8000000000077,63.98145463976182,0.25933154465633745,-2.4912421968068488
590.0000000000077,64.10212826978884,0.25959681879280416,-2.4956843315554695
591.2000000000077,64.22174258312127,0.25727520130126846,-2.49177257944082
592.4000000000077,64.34219060694538,0.25804931023898925,-2.4904300864498623
593.6000000000078,64.4634171617542,0.25873509247469517,-2.4918438350383614
594.8000000000077,64.5838160789492,0.2589998263112395,-2.495840335699003
596.0000000000077,64.70405313093633,0.2615038373584735,-2.49562485412396
597.2000000000078,64.8249589347593,0.2608689186552188,-2.4928483554333125
598.4000000000078,64.94699107259179,0.2659440806111366,-2.493995140865854
599.6000000000079,65.06784531615523,0.26564195925034706,-2.494794179869711
600.8000000000078,65.18847092016765,0.266976010347464,-2.496134826473428
602.0000000000078,65.3087793688924,0.26500062854786566,-2.4962850593669854
603.2000000000079,65.4286912751189,0.2707310608678415,-2.4961006498587195
604.4000000000078,65.54906685932139,0.2736234514276715,-2.500079838853498
605.6000000000079,65.6691719790881,0.27699978656130053,-2.5028199991339983
606.8000000000079,65.78984737528803,0.2763175354833757,-2.5038098586988484
608.000000000008,65.91101867884379,0.2825722210522569,-2.5050624560677908
609.200000000008,66.03117233501628,0.2858309178313829,-2.503606313313349
610.4000000000079,66.15220599598457,0.28691127396648963,-2.502531181720945
611.600000000008,66.27308814582825,0.2943770230512278,-2.502156074118303
612.800000000008,66.39320652857766,0.29826273513944135,-2.5025229143104815
614.000000000008,66.51393576276993,0.30417109451495783,-2.5064401394212417
615.200000000008,66.63127247516854,0.308115283589091,-2.5067799117478167
616.400000000008,66.75400286550938,0.31501957822645765,-2.507772023512737
617.6000000000081,66.87480680229544,0.32477078591855946,-2.5090644297400218
618.8000000000081,66.99542906430482,0.33307092880647193,-2.5094431609827756
620.0000000000081,67.11482901016035,0.3400886834875001,-2.513460263741877
621.2000000000081,67.23592339968044,0.3470320870155085,-2.5121500060722024
622.4000000000082,67.35562720846727,0.353643781164238,-2.5162670433744525
623.6000000000081,67.47585776108747,0.3599287712195166,-2.51751139396065
624.8000000000081,67.59681494612192,0.36780607633609597,-2.515432551052011
626.0000000000082,67.71670611240165,0.3747583977115405,-2.5195042943425894
627.2000000000082,67.83818084780107,0.3872461412090945,-2.5237570362783464
628.4000000000083,67.95856318327223,0.39324322010577784,-2.520033796623083
629.6000000000082,68.08048008374195,0.40033815834475095,-2.5187304519745553
630.8000000000083,68.20064592380197,0.40678951411810127,-2.5229639936325845
632.0000000000083,68.32084455199944,0.4140275091513872,-2.520295906824303
633.2000000000082,68.44216067081703,0.4263090684624039,-2.5253571984212537
634.4000000000083,68.56301894362444,0.4353682900260123,-2.5310923149222333
635.6000000000083,68.68323385297248,0.4455425183534303,-2.536470477728025
636.8000000000084,68.80424171859147,0.459752421554114,-2.5378177307358727
638.0000000000084,68.92567185372657,0.46792851591935003,-2.5355615373531073
639.2000000000083,69.04753699683228,0.4790037171582554,-2.5379872963053214
640.4000000000084,69.16861740668949,0.48936089976697106,-2.540650640352693
641.6000000000084,69.28907798006274,0.5018877947786422,-2.541322402194165
642.8000000000084,69.41069373282028,0.5128979981022026,-2.545082827451073
644.0000000000084,69.53176245403196,0.5278060694499488,-2.5493707319807966
645.2000000000085,69.65309432824235,0.5418628491754871,-2.5511819000190052
646.4000000000085,69.77429356913778,0.5554661617106776,-2.556604362317364
647.6000000000085,69.89452433303363,0.5708656473751038,-2.56066116582483
648.8000000000085,70.0159093776868,0.5870907784984124,-2.5631529792641423
650.0000000000085,70.13806062119349,0.5991903575603725,-2.5665603692923797
651.2000000000086,70.25822781569362,0.6105791200012496,-2.566665554209954
652.4000000000085,70.37897213724291,0.6232711167487932,-2.5652290955263286
653.6000000000085,70.4995565176122,0.6405430200229699,-2.5770231917643764
654.8000000000086,70.62118083696379,0.6585226723792152,-2.5811667121524087
656.0000000000086,70.7414329327414,0.6729886153606978,-2.5826478276769307
657.2000000000087,70.86298242792886,0.690421268144878,-2.5880091350571224
658.4000000000086,70.98425556951422,0.7085211438514419,-2.585824015331256
659.6000000000087,71.1044687731935,0.7266448504273725,-2.59770024480696
660.8000000000087,71.22492565249146,0.74687922318518,-2.6030182671605298
662.0000000000086,71.34614111100781,0.7669184930985298,-2.6049433767740564
663.2000000000087,71.46646713515564,0.7851424476789501,-2.6122457383118336
664.4000000000087,71.58801923013966,0.8049280936010524,-2.6198791879852426
665.6000000000088,71.70885622954098,0.8227024885086963,-2.6222091240076266
666.8000000000088,71.82962949727194,0.8437317973213421,-2.6200256923687064
668.0000000000088,71.95023941251746,0.8637577878123326,-2.6256880506975673
669.2000000000088,72.0701563951089,0.883800556890185,-2.635909789385805
670.4000000000088,72.19166564247496,0.9043545992470852,-2.642848310984028
671.6000000000088,72.31260355007234,0.9265440144816922,-2.6460585686455955
672.8000000000088,72.43332381689909,0.945454792240053,-2.6508917257943527
674.0000000000089,72.55345033355138,0.9637834517161423,-2.6549353461995198
675.2000000000089,72.67561044388562,0.983194632255461,-2.6654923526913454
676.400000000009,72.79571817602586,1.0045349174577047,-2.6685914240005553
677.6000000000089,72.91722692409142,1.020208824487347,-2.6738734675997633
678.8000000000089,73.03749800710457,1.0360936643712169,-2.6838403761160885
680.000000000009,73.15917000000098,1.054087185516881,-2.6915899502452403
681.2000000000089,73.27927820315941,1.066128137615968,-2.69938872957749
682.400000000009,73.40142019675973,1.0789052064813025,-2.7075381341634914
683.600000000009,73.5200791680729,1.0895657345721055,-2.7110583516400455
684.800000000009,73.64272813033084,1.1031295356738342,-2.7181548633707524
686.0000000000091,73.76336017739193,1.1123147992471474,-2.723300972687663
687.200000000009,73.88564948258785,1.1212704561155735,-2.7304576037075363
688.4000000000091,74.00680709088276,1.1339123099014619,-2.736878784938449
689.6000000000091,74.1274315354751,1.1427922915394946,-2.7441838578806435
690.800000000009,74.24949807345594,1.1582775764827777,-2.750042745009924
692.0000000000091,74.37080304637676,1.1789230257783812,-2.756638341952163
693.2000000000091,74.49296488946501,1.2021657461134176,-2.763910413611975
694.4000000000092,74.6146236732421,1.2394756114804322,-2.775540872866956
695.6000000000092,74.73662277867538,1.2761387729605649,-2.7859144200276202
696.8000000000092,74.85771009215021,1.317300121872937,-2.7906409120118005
698.0000000000092,74.97897357383687,1.3588609045081925,-2.795217280431141
699.2000000000093,75.09868394741395,1.4068564032840951,-2.8047453087988883
700.4000000000092,75.22055651477761,1.4517645369126146,-2.8122622214967747
701.6000000000092,75.34189405451512,1.503553856180547,-2.825826595403635
702.8000000000093,75.46394427167444,1.5515015308471152,-2.835107179883429
704.0000000000093,75.58511782998302,1.5934804855254838,-2.844021179500768
705.2000000000094,75.70571068668033,1.6461619895293806,-2.8574852343365604
706.4000000000093,75.82717753008089,1.688545808685505,-2.8644369457805903
707.6000000000093,75.94828737931964,1.730392817841533,-2.8722873472364903
708.8000000000094,76.06938658977163,1.7716993371124665,-2.8838113840307114
710.0000000000093,76.19067142286106,1.81024974533565,-2.8971853991599095
711.2000000000094,76.31132000737863,1.8530461920097525,-2.9095891259032625
712.4000000000094,76.43247635732405,1.891243884828898,-2.924008575316412
713.6000000000095,76.55408684877096,1.9271863661918447,-2.9364143540743575
714.8000000000095,76.67584814550273,1.9593225407235573,-2.948081669651504
716.0000000000094,76.79704163373185,1.9928800413844017,-2.9613163714717654
717.2000000000095,76.91828594299155,2.0168211308590513,-2.9745818279814378
718.4000000000095,77.03969681263892,2.0409094629867757,-2.9886822566000752
719.6000000000095,77.16108812031105,2.0619307229711596,-3.0063452026820285
720.8000000000095,77.28372261790203,2.073141619873242,-3.0188987568146857
722.0000000000095,77.4046277113379,2.078512355289473,-3.0313071899448336
723.2000000000096,77.5273408324844,2.070836926357897,-3.043203024044717
724.4000000000096,77.64928228948574,2.055471851696497,-3.05697248638876
725.6000000000096,77.77118999270076,2.0192421235346902,-3.0719369210997365
726.8000000000096,77.8917236186797,1.9595901828400615,-3.086374271933147
728.0000000000097,78.01377615921417,1.8759217004994349,-3.100350107212659
729.2000000000096,78.13485802063887,1.7305262292508252,-3.1112677500854904
730.4000000000096,78.25572792098083,1.5149623566732933,-3.123568923907626
731.6000000000097,78.37625330628963,1.1349234217888693,-3.131510903317499
732.8000000000097,78.49706586480193,0.5648092310846615,-3.135638974214266
734.0000000000098,78.6179203683126,0.34890296823948597,-3.137247111697324
735.2000000000097,78.73956228433266,0.27167222160727,-3.1390001043073887
736.4000000000098,78.86014421825442,0.2476523014798273,-3.13899518962035
737.6000000000098,78.98159814751517,0.2361169162378971,-3.136181346653411
738.8000000000097,79.10264001931556,0.23007893592957118,-3.1364244861551764
740.0000000000098,79.22290756195578,0.22554373278697248,-3.1360402570456505
741.2000000000098,79.34452424910124,0.22780750113812354,-3.137696389632962
742.4000000000099,79.46532083970153,0.2260216335098828,-3.139000143951584
743.6000000000099,79.58611430895905,0.2264833042610519,-3.137921869126188
744.8000000000098,79.70825837491633,0.22511490012609991,-3.135060454215833
746.0000000000099,79.82906946360204,0.22533798835824248,-3.1353900340603724
747.2000000000099,79.95162077263765,0.22712735153721564,-3.1367014539672904
748.4000000000099,80.07401411324246,0.22292531633398416,-3.140265758000494
749.6000000000099,80.19648712937177,0.2260424311171152,-3.1351387156695374
750.80000000001,80.31783929532602,0.22030267878977416,-3.1339513624347655
752.00000000001,80.43828152068438,0.2222507917439187,-3.1365829391679543
753.20000000001,80.56117267815739,0.22407077538079245,-3.1405402401874483
754.40000000001,80.68211454401039,0.22531266355050805,-3.137940497210948
755.60000000001,80.80410996944919,0.21775190295606572,-3.1339495004729896
756.8000000000101,80.92583915173395,0.22644667986762523,-3.140769763624089
758.00000000001,81.04794350705751,0.22016984714813925,-3.1365712414779248
759.20000000001,81.16955773199395,0.22171195278860178,-3.136589830926397
760.4000000000101,81.29098211492445,0.2239634886714752,-3.139622002928924
761.6000000000101,81.41244336882338,0.2219990900026847,-3.1397131765667576
762.8000000000102,81.53460933595316,0.2230054508993431,-3.140163051809649
764.0000000000101,81.65645648251096,0.2239906057058203,-3.143808097424621
765.2000000000102,81.77823179058191,0.22095594063350643,-3.141161742409534
766.4000000000102,81.90014000369214,0.22300724035663122,-3.141207056943185
767.6000000000101,82.02282035294529,0.22488095591273294,-3.14222052245034
768.8000000000102,82.14494701878421,0.22597008289890463,-3.13855664470119
770.0000000000102,82.26588832975148,0.22258407792264379,-3.1425541340024106
771.2000000000103,82.38896729026592,0.2220726104646713,-3.1412015402265308
772.4000000000103,82.51053516648193,0.2223319783274722,-3.148554084805044
773.6000000000103,82.63179713813854,0.2265573172509967,-3.1473750977843653
774.8000000000103,82.75223707369265,0.22514554908298723,-3.1458203268889413
776.0000000000103,82.87420926682286,0.22855059019119506,-3.143067303088549
777.2000000000103,82.99590627135122,0.22784919553721084,-3.143070002244628
778.4000000000103,83.11720553555354,0.2306795323330313,-3.1404863676721666
779.6000000000104,83.23896399332976,0.2300231402711026,-3.1383398785887544
780.8000000000104,83.3595881863417,0.2280265082071118,-3.1430906537091348
782.0000000000105,83.48112772934365,0.2307456675643591,-3.1443700119452083
783.2000000000104,83.60291996900888,0.23089146750401102,-3.1417498853814383
784.4000000000104,83.72543722657582,0.23345144338773305,-3.1417513892967017
785.6000000000105,83.84717866219339,0.23570300130161703,-3.1430603180474272
786.8000000000104,83.96814523006351,0.2382217553083632,-3.1444799775310095
788.0000000000105,84.0907589170149,0.23422780981367874,-3.144479970999999
789.2000000000105,84.21213394477643,0.23907373411659938,-3.144479970959498
790.4000000000106,84.3348833224721,0.2384819462263783,-3.143949927706462
791.6000000000106,84.4566990037147,0.24058159923418998,-3.1445071620237863
792.8000000000105,84.58051837869368,0.2409833800296659,-3.147016601215314
794.0000000000106,84.7008238742676,0.23953484465569708,-3.1457959957663477
795.2000000000106,84.82375939623633,0.2429028763032144,-3.1433147766504472
796.0000000000106,84.90447014750416,0.24141448094909013,-3.14025765961944