File: 01_Data/Nylon_Carpet_High_Pile/STA/N2/10K_min/Nylon_Carpet_High_Pile_STA_N2_10KData_220307_R1.csv
##Temp./Â°C,Time/min,DSC/(mW/mg),Mass loss/mg
50.0,10.575065847445524,-0.05765295811075988,-0.025404034899328742
51.20000000000002,10.987925395606132,0.01690076849354749,-0.017947689073497308
52.400000000000034,11.228362634404037,0.06194624039237917,-0.014245878823519575
53.60000000000005,11.41947322023394,0.09188092488953348,-0.013052540301620397
54.80000000000007,11.589600388859933,0.11726902587721688,-0.015298248626354649
56.000000000000085,11.748829824472638,0.13605673007384345,-0.017558507419019875
57.2000000000001,11.898552415131732,0.14853337679260126,-0.013478470380809071
58.40000000000012,12.041315172262832,0.16280996359371946,-0.010727982884338516
59.600000000000136,12.183035092108797,0.17125706398967766,-0.008656670709298098
60.80000000000015,12.318949427036735,0.17720604868552114,-0.011321854046967061
62.00000000000017,12.454669686946309,0.182120372796014,-0.011025725631410133
63.20000000000019,12.588174906038887,0.19175686128191327,-0.014444186649724244
64.4000000000002,12.71986229213918,0.1974614494002681,-0.009813815045935037
65.60000000000022,12.85209371868104,0.2019825538075012,-0.009663417569581334
66.80000000000024,12.981782741194479,0.20680333364437709,-0.010389014612710135
68.00000000000026,13.111344591843483,0.21161230337095127,-0.008208444281166294
69.20000000000027,13.240624464633651,0.21598448593707475,-0.012145865274700185
70.40000000000029,13.369598159492625,0.22204687161514614,-0.011606463864484162
71.6000000000003,13.497725304134326,0.22432812456343698,-0.010521565398081911
72.80000000000032,13.624154324059418,0.22757134232491738,-0.01197985535137569
74.00000000000034,13.749622941084635,0.2306549103878115,-0.013168340278136625
75.20000000000036,13.876520924909505,0.2340426995998891,-0.009321533597313802
76.40000000000038,14.003563046393754,0.23539323090358,-0.011840577668837504
77.60000000000039,14.127709943601829,0.2389664519218604,-0.016715982368724625
78.80000000000041,14.252969243504449,0.24348780698796296,-0.018107206542467225
80.00000000000043,14.37906984464901,0.24494147483059275,-0.017991019041460277
81.20000000000044,14.49917000000005,0.24763039135418496,-0.014260163051125652
82.40000000000046,14.621848707920135,0.2514639955289072,-0.015577185796156634
83.60000000000048,14.748329390962576,0.25172561843352004,-0.013874486860999014
84.8000000000005,14.871180925062463,0.25275490125114836,-0.014149961192029714
86.00000000000051,14.993885855748333,0.2547374681903847,-0.015434824681262782
87.20000000000053,15.114898148728116,0.2583969276753401,-0.01793009154531422
88.40000000000055,15.23590668642489,0.2616728709722182,-0.019381261818470108
89.60000000000056,15.356676715727586,0.2618039968330206,-0.016800138524285302
90.80000000000058,15.476836076194626,0.26513155859895715,-0.016709630593925162
92.0000000000006,15.59685726460624,0.26647054119320385,-0.01546004552730551
93.20000000000061,15.717017751500656,0.26513483051370595,-0.016779893543383828
94.40000000000063,15.834448765631967,0.2682004964348959,-0.016822064444760088
95.60000000000065,15.955131116621246,0.2694467263024542,-0.019440662046884327
96.80000000000067,16.073956135638735,0.2676088627337081,-0.019739662062677965
98.00000000000068,16.192136617316205,0.2687979898241832,-0.019745215968483443
99.2000000000007,16.31095736929122,0.26879379217271965,-0.017000255657674934
100.40000000000072,16.429834297770075,0.2672936356056246,-0.01962997169207359
101.60000000000073,16.547737363567506,0.26529340590491163,-0.023688550232624728
102.80000000000075,16.665433619387024,0.2639974844604472,-0.02336345464765799
104.00000000000077,16.784419749870125,0.2643210946274383,-0.023690099752566418
105.20000000000078,16.90244027566987,0.26069864978187096,-0.02399892539226567
106.4000000000008,17.020839041697588,0.26100355124929514,-0.01799585938190784
107.60000000000082,17.137824248370393,0.2576733941240467,-0.017108389545358982
108.80000000000084,17.258215600120376,0.25742674434024,-0.018545806568875278
110.00000000000085,17.373913618124313,0.25634135092967375,-0.022516974305196946
111.20000000000087,17.49233207932518,0.2572241413239536,-0.02247989688741736
112.40000000000089,17.60981997714272,0.2571669377297403,-0.020303938505144004
113.6000000000009,17.728290282293692,0.2578459160185219,-0.018331390561447947
114.80000000000092,17.844937803641017,0.25541690164149244,-0.01819639079444446
116.00000000000094,17.96263045771224,0.25776012248982183,-0.01969026708724453
117.20000000000095,18.078895647378342,0.25723009401311064,-0.021269897250487446
118.40000000000097,18.1972854612699,0.2556921612953092,-0.021273527622065913
119.60000000000099,18.315612115454158,0.258102625790692,-0.021579654460455622
120.800000000001,18.431282230347154,0.258930311171054,-0.019984102658423097
122.00000000000102,18.550010657758406,0.25932250419356845,-0.019959962607403625
123.20000000000104,18.665438124170525,0.25919559155568606,-0.019850486145673862
124.40000000000106,18.782445363836867,0.25812855523697187,-0.02051316804147696
125.60000000000107,18.899963192713024,0.2581376159129701,-0.02050978140713866
126.80000000000109,19.016864727311578,0.2587094216245895,-0.021830149070637184
128.0000000000011,19.133338602736718,0.26003554758063385,-0.023140152142917536
129.20000000000113,19.250255022021165,0.2601332098842043,-0.024560170616253707
130.40000000000114,19.365545567208148,0.2589450373942396,-0.023349775082392554
131.60000000000116,19.482600481740807,0.2644589295631292,-0.024560079088873366
132.80000000000118,19.59775692619286,0.2630830857500814,-0.02300936159033906
134.0000000000012,19.715019463079912,0.26340535581156366,-0.024352804713280385
135.2000000000012,19.831518710588476,0.2596204571263465,-0.022476486002106277
136.40000000000123,19.947385560742582,0.2623367074417248,-0.022242587207935927
137.60000000000124,20.063241407142907,0.26477530770582597,-0.02541644042095559
138.80000000000126,20.1793700666856,0.2662138200171382,-0.02611665252965878
140.00000000000128,20.291100119820403,0.2653211615776283,-0.023490034798268056
141.2000000000013,20.411320912614865,0.26696099950461094,-0.023470594981278126
142.4000000000013,20.526609154037807,0.26863324207508377,-0.026687157568296094
143.60000000000133,20.645322191179904,0.2706421040056038,-0.02883081005071464
144.80000000000135,20.755022775163418,0.2728846752846873,-0.028848847355273044
146.00000000000136,20.874805822351277,0.2736273343990949,-0.028839224238381256
147.20000000000138,20.991635448695398,0.2740581216393543,-0.02824620371960407
148.4000000000014,21.10802249013514,0.2773569195174937,-0.02598598858488721
149.60000000000142,21.223726707358185,0.2783717864038879,-0.024237962602290608
150.80000000000143,21.339076455847188,0.2823875443717976,-0.026542523961430753
152.00000000000145,21.455388274843745,0.2892021177287604,-0.028191750441514785
153.20000000000147,21.570458040439263,0.29238299665757345,-0.028264690385597646
154.40000000000148,21.686223257278087,0.2973189423777537,-0.02687248755399274
155.6000000000015,21.801319857495507,0.3032427407401741,-0.025531369870678056
156.80000000000152,21.91677121736161,0.3137705417873498,-0.02813561620332905
158.00000000000153,22.031778597105284,0.3238824153816705,-0.030160762849722467
159.20000000000155,22.147998141758645,0.33474611611665384,-0.026260863975554827
160.40000000000157,22.262643013488884,0.3443633029033309,-0.024149523241182358
161.6000000000016,22.377894495271054,0.35650417534672485,-0.028070800853929434
162.8000000000016,22.49387435643527,0.3639346607487648,-0.026331649094542442
164.00000000000162,22.608288501168218,0.37184257428841294,-0.03222684672605336
165.20000000000164,22.723518549934827,0.3746260996844462,-0.03192432211041041
166.40000000000165,22.839692387206412,0.3643627400965813,-0.029293120755454538
167.60000000000167,22.955527407699158,0.3480190330107397,-0.02928248117963861
168.8000000000017,23.069460615574275,0.329753665798354,-0.02680531921833129
170.0000000000017,23.1863127353075,0.3106678555798336,-0.03188842545614179
171.20000000000172,23.30041616071561,0.2979062085338178,-0.027532561877499973
172.40000000000174,23.415160730584223,0.29004675099171495,-0.026540063610026365
173.60000000000176,23.531109095180412,0.2873470864301938,-0.02819586296190213
174.80000000000177,23.64652291601926,0.2846814323755025,-0.032279952339902884
176.0000000000018,23.760261191096625,0.2861545894557399,-0.03593049780849267
177.2000000000018,23.876821520931937,0.2861015482812693,-0.03619004806096804
178.40000000000182,23.99201972726439,0.28812346618261137,-0.03434790356488193
179.60000000000184,24.106792454189787,0.2882314478313401,-0.030310320157825643
180.80000000000186,24.22122652546777,0.2885903169472392,-0.027624963636554867
182.00000000000188,24.336840416323007,0.29025409155491044,-0.02975676975254693
183.2000000000019,24.451327802731743,0.291055583301903,-0.031615588924800875
184.4000000000019,24.564182716173264,0.29502447719381036,-0.031589730458765786
185.60000000000193,24.68104131073263,0.29677866017041754,-0.031589909323359144
186.80000000000194,24.79501764842935,0.2974426355260849,-0.03159553150647376
188.00000000000196,24.908971988875642,0.3003795174599835,-0.03160230873402359
189.20000000000198,25.024319557524677,0.29991773408360256,-0.030062168069965978
190.400000000002,25.13906483794486,0.30507889892110374,-0.034218565592159855
191.600000000002,25.252290073778088,0.30602979499356736,-0.034206157956510275
192.80000000000203,25.36937641721017,0.3043533965094888,-0.03423230996656823
194.00000000000205,25.483869278383573,0.3066576991317927,-0.03158662507326149
195.20000000000206,25.598138016445088,0.30599874921805925,-0.030199775792753236
196.40000000000208,25.712741684959934,0.308120351481719,-0.02884409011587774
197.6000000000021,25.82751989429549,0.31501735639217454,-0.03114638540496628
198.80000000000211,25.94218822237543,0.31747060800850235,-0.03366995964774233
200.00000000000213,26.057351970776395,0.31832693126349454,-0.03367535514567166
201.20000000000215,26.171777477642607,0.3225049043522348,-0.03716558662495473
202.40000000000217,26.286364871667544,0.3257039368766001,-0.037180860757339396
203.60000000000218,26.401735867706247,0.3327496312061513,-0.035512617818795
204.8000000000022,26.516567622509474,0.3365926240233431,-0.030268206500323025
206.00000000000222,26.631119531015244,0.3411211031406514,-0.03207499522527879
207.20000000000223,26.746027222890792,0.3482289890813812,-0.0326343221726102
208.40000000000225,26.861399505954093,0.35353691683069965,-0.03454735511183582
209.60000000000227,26.975576351155347,0.36267957443443966,-0.03320572710556302
210.80000000000229,27.091915234677305,0.37464766468455174,-0.030491384560478174
212.0000000000023,27.205241181587276,0.387738401690215,-0.028224001650898778
213.20000000000232,27.320530071371877,0.41909045970155745,-0.027987780848028443
214.40000000000234,27.435805983826693,0.46645969441165613,-0.03701921047612622
215.60000000000235,27.550368641730127,0.5460105984143994,-0.03870157345180214
216.80000000000237,27.666549148752473,0.6676553982159706,-0.036298513987696346
218.0000000000024,27.781291719429742,0.7910056546747631,-0.03340838587032824
219.2000000000024,27.897241376072266,0.8906615793402601,-0.03337798902302325
220.40000000000242,28.01288868679708,0.9389187096499307,-0.03068732983473943
221.60000000000244,28.12790895822422,0.9264458714728627,-0.03477075062316004
222.80000000000246,28.242528300750237,0.8296688845620832,-0.03476384055356352
224.00000000000247,28.358611251458512,0.6641429820349402,-0.032485061563106044
225.2000000000025,28.472741066343907,0.5173875074427953,-0.03477582582104244
226.4000000000025,28.587040262946083,0.4258517282245113,-0.035023500410169106
227.60000000000252,28.70061477666622,0.37665775606292395,-0.03784477085223603
228.80000000000254,28.815165371017688,0.35135110706988415,-0.03664990449968197
230.00000000000256,28.928356576340196,0.3380952787368824,-0.035077478757195024
231.20000000000258,29.042727378372977,0.3287176258223672,-0.038086517462954994
232.4000000000026,29.156270972873138,0.32430839435125136,-0.038047791209582904
233.6000000000026,29.267838759995776,0.3222165047115847,-0.0368066795097306
234.80000000000263,29.38586533498907,0.3186818015283994,-0.04181254967137704
236.00000000000264,29.500094979731262,0.3205907100210389,-0.04315538320775403
237.20000000000266,29.613801269016164,0.32024962070901275,-0.04286926538203595
238.40000000000268,29.72806853832219,0.31931832957144574,-0.040485916643246966
239.6000000000027,29.84308989278441,0.32105796348211707,-0.04014574440451213
240.8000000000027,29.95680732613159,0.3198929428729496,-0.040560965649205194
242.00000000000273,30.071736094441885,0.31897163235207393,-0.03850067178694605
243.20000000000275,30.18639070720296,0.32084200061682605,-0.0430893093533431
244.40000000000276,30.300746219571487,0.322327054668041,-0.04736957112809037
245.60000000000278,30.414939405692092,0.31940824139461566,-0.04384676270666166
246.8000000000028,30.52917000000028,0.31812795929025295,-0.0428434470588277
248.0000000000028,30.64457278925335,0.31949247281872806,-0.041350040421374246
249.20000000000283,30.757767798888207,0.3209726873399287,-0.04320341563502428
250.40000000000285,30.87354879994253,0.3202375990775695,-0.042267788693217234
251.60000000000286,30.987678839195425,0.3218823627297442,-0.04415831120716085
252.80000000000288,31.102379587000417,0.3190638826890313,-0.0428833931405066
254.0000000000029,31.21632111880542,0.3199638359249091,-0.04288927850176716
255.20000000000292,31.331709929788943,0.31988090701839933,-0.040029438798782735
256.40000000000293,31.446126674431095,0.31590312475079424,-0.04005028648390674
257.600000000003,31.56088419167217,0.3201319120171958,-0.047005062404767095
258.80000000000297,31.675491317562187,0.3206220528844211,-0.04550164004440305
260.00000000000296,31.78917000000033,0.3187876178711145,-0.04550644396956649
261.200000000003,31.904484145646826,0.31772863899708215,-0.04430950864167116
262.40000000000305,32.020032070210405,0.318719091795313,-0.04420011053771855
263.60000000000304,32.133868554641694,0.3161560255651322,-0.04682609840595209
264.800000000003,32.24889843985074,0.3152254683576502,-0.0455195450012047
266.00000000000307,32.36381770990547,0.31695481187915425,-0.04575754940811194
267.2000000000031,32.47881157660459,0.3162540431145212,-0.04814743079311423
268.4000000000031,32.594362965212504,0.3146655810514105,-0.049480498309867116
269.6000000000031,32.70864677688661,0.3103032044148733,-0.04698543378050335
270.80000000000314,32.823828403003645,0.31219652713173507,-0.04793027990006227
272.0000000000032,32.938188379431395,0.31107425437705416,-0.04825606714512709
273.2000000000032,33.053473453201335,0.3116467966427118,-0.049580001916410765
274.40000000000316,33.16833049169845,0.31104538009366417,-0.051549843708658116
275.6000000000032,33.283925401888354,0.31088358523262816,-0.05155018005038681
276.80000000000325,33.39815383208842,0.3123874932437188,-0.05236759195058749
278.00000000000324,33.51342994482176,0.311010707029546,-0.051882340798817594
279.20000000000323,33.62769025271383,0.30975540404586105,-0.05056978263629697
280.4000000000033,33.74309113116682,0.31161579286833263,-0.056037961644586964
281.6000000000033,33.85751108414183,0.3137544273359179,-0.0533935925060689
282.8000000000033,33.973020497589154,0.3118849661103724,-0.052032262213749014
284.0000000000033,34.088240978205256,0.3115638100625877,-0.052100701425898954
285.20000000000334,34.20216534751857,0.3138174798656334,-0.05103680583689085
286.4000000000034,34.31770888980801,0.3120590442461703,-0.054749569708667956
287.6000000000034,34.43289655877303,0.3111552431344148,-0.056050971607986444
288.80000000000337,34.547983987534934,0.3122058011843373,-0.05736954819269968
290.0000000000034,34.6631992740014,0.31262155679226544,-0.055392465858327355
291.20000000000346,34.77792086841477,0.31331741861231643,-0.057215030641198705
292.40000000000344,34.89338470609826,0.31602298825361486,-0.0587506146805743
293.60000000000343,35.007718758797154,0.31604431223560747,-0.06017878553795253
294.8000000000035,35.12252544272165,0.31563643411980835,-0.06161706136346812
296.0000000000035,35.23781002812041,0.31901301520871767,-0.06154296517040425
297.2000000000035,35.35315898810969,0.31910430762630765,-0.059226350332739486
298.4000000000035,35.46804570909288,0.3196953041762202,-0.0602111860788197
299.60000000000355,35.584245000058424,0.3219852920507018,-0.06287651269394967
300.8000000000036,35.69907260913218,0.3240678125592161,-0.06559006145904256
302.0000000000036,35.814287170592934,0.3257739050112635,-0.06460320773910011
303.20000000000357,35.92997501868945,0.3249508098924761,-0.064279997430857
304.4000000000036,36.04576025529899,0.3298173446941625,-0.06423320872995086
305.60000000000366,36.160764089245795,0.3307520250268728,-0.06689539827524049
306.80000000000365,36.27603326069002,0.3313109981393897,-0.06939413722883003
308.00000000000364,36.38927131543215,0.33204373316540686,-0.07119850396157812
309.2000000000037,36.50805133281342,0.3332610192114023,-0.07357654766302568
310.40000000000373,36.62343245824182,0.3357490181607048,-0.07612595350301765
311.6000000000037,36.73740500418206,0.3376721843056481,-0.07521061825795616
312.8000000000037,36.85454655609759,0.3400767808053493,-0.07295247037945085
314.00000000000375,36.96962434184984,0.3443612105323862,-0.07780665957497801
315.2000000000038,37.08531545860643,0.34784977723996785,-0.08392902928939527
316.4000000000038,37.201501161662165,0.3518000544995965,-0.08495776417346868
317.6000000000038,37.31687222694155,0.35594999010462397,-0.08571240362374244
318.8000000000038,37.43337223467629,0.359634177885503,-0.0900722779880474
320.00000000000387,37.54832995658295,0.36527426262382257,-0.09017498092459153
321.20000000000385,37.66326394044715,0.37045038093399774,-0.095318966906484
322.40000000000384,37.779354104710336,0.3759243346271252,-0.09829694206085904
323.6000000000039,37.89506858524033,0.3772746392170352,-0.10352577293728071
324.80000000000393,38.0092767391265,0.38645034389241906,-0.10464994446563525
326.0000000000039,38.12583846438124,0.3891680334195105,-0.11243709981106198
327.2000000000039,38.241412594857174,0.39637038509157396,-0.11727140432209948
328.40000000000396,38.35764369197844,0.40423116329691733,-0.12128724196251905
329.600000000004,38.47329336045652,0.4077207302979263,-0.1250533055037355
330.800000000004,38.58853565636415,0.41497479959274897,-0.1256402249425541
332.000000000004,38.704177272244436,0.42009793824485797,-0.1349411340804152
333.200000000004,38.820009813162,0.43105373379369716,-0.14350936744269394
334.40000000000407,38.93551882669611,0.4399517792026169,-0.14972142301367386
335.60000000000406,39.05201452378966,0.44781453980259095,-0.15480156700992653
336.80000000000405,39.168562473531665,0.4560364522971909,-0.16468596154800386
338.0000000000041,39.28395927424061,0.46438377813990284,-0.17122569551644373
339.20000000000414,39.400230957638676,0.4721332728372517,-0.17575182600434314
340.4000000000041,39.5174178570042,0.4813071035461171,-0.18583162615356175
341.6000000000041,39.63272460891616,0.4912401690195304,-0.19691249673423927
342.80000000000416,39.748256758182755,0.5028496409335618,-0.20513999975676045
344.0000000000042,39.86607998868915,0.5141107546215049,-0.2216160118983801
345.2000000000042,39.983205129147244,0.5275749519282243,-0.22796640537971768
346.4000000000042,40.099654136161256,0.535499512941816,-0.2375748898170542
347.60000000000423,40.21448510465371,0.5500464244589053,-0.24900683520140277
348.8000000000043,40.33147343228512,0.5626708357518784,-0.259175991501682
350.00000000000426,40.44907674183755,0.573820882268927,-0.27233326464078456
351.20000000000425,40.56435940923657,0.5879926335731788,-0.2864175477870865
352.4000000000043,40.681451740113296,0.6002660107371324,-0.30211223583854174
353.60000000000434,40.79772131396393,0.6136565499257611,-0.3172081428723974
354.80000000000433,40.91464239422771,0.6266481908791334,-0.3316481561004969
356.0000000000043,41.03085931188966,0.6423102803776333,-0.34529924883509056
357.20000000000437,41.147402386915964,0.6568695485063988,-0.3618574810028563
358.4000000000044,41.263441132726975,0.6707064939513192,-0.3822236770279237
359.6000000000044,41.379071012787435,0.6898035315485895,-0.3989386232988976
360.8000000000044,41.49702954523802,0.7060100455301771,-0.42170470804613025
362.00000000000443,41.61226127210318,0.7168386881355593,-0.4379642886897148
363.2000000000045,41.72812578503438,0.7368910410172397,-0.45277482542938996
364.40000000000447,41.84477921142061,0.7499667372435692,-0.4731504455004165
365.60000000000446,41.96018113659233,0.7653628389503611,-0.4956132875141308
366.8000000000045,42.076964381703334,0.7846051951976154,-0.5192858918160406
368.00000000000455,42.19530128813736,0.8052094273162349,-0.5452157995485667
369.20000000000454,42.31094258774827,0.8219442699178655,-0.5668314742790965
370.4000000000045,42.426521505031026,0.8377244818792823,-0.5964258448717383
371.60000000000457,42.5436543159697,0.8567415213725058,-0.6193644922647925
372.8000000000046,42.66018500483789,0.8755770286853486,-0.651230468775605
374.0000000000046,42.77798618350982,0.8954820434589942,-0.6806928823725156
375.2000000000046,42.89446726519006,0.9165675849630073,-0.707986599627414
376.40000000000464,43.0117328014834,0.933853591288073,-0.7371380460686137
377.6000000000047,43.12746270782627,0.9537491708721291,-0.7704534347302006
378.8000000000047,43.2448883845446,0.9729061576901816,-0.8071157942423626
380.00000000000466,43.36228306634082,0.9939519581392087,-0.8404536195945584
381.2000000000047,43.47906483243605,1.0111570929032514,-0.8780007495604965
382.40000000000475,43.596579343887406,1.026127391686297,-0.9186338375199017
383.60000000000474,43.71381710546798,1.046705314295775,-0.956124540102735
384.80000000000473,43.83149730636504,1.0552740110422407,-0.9931442891547722
386.0000000000048,43.94819960310286,1.0650951049228785,-1.0330881769735463
387.2000000000048,44.065232934716654,1.0755500636793858,-1.0783151389323669
388.4000000000048,44.18245262348757,1.0817904277554853,-1.1228739077088679
389.6000000000048,44.29937283322011,1.0879491232658736,-1.1709685180932756
390.80000000000484,44.417776387004636,1.0877933712577046,-1.2181555767384853
392.0000000000049,44.53503445991819,1.0846343050891938,-1.264749379765008
393.2000000000049,44.6524889102726,1.0787072833275833,-1.3110832146386335
394.40000000000487,44.76927773608887,1.061665481212449,-1.3573971208171782
395.6000000000049,44.88648574334663,1.0448376768712324,-1.4008208725443345
396.80000000000496,45.003795861645486,1.0205686195562165,-1.4499394877073608
398.00000000000495,45.1218794595594,0.9884503057285956,-1.4995489334084078
399.20000000000493,45.23812866383736,0.9539541973769667,-1.5410850483891818
400.400000000005,45.353245032565226,0.9113912785396688,-1.583332794360353
401.600000000005,45.472640996271956,0.8545469767934262,-1.627897049074957
402.800000000005,45.58875958561191,0.7940304376006484,-1.6707281281104498
404.000000000005,45.70598594386752,0.7282041099822503,-1.7087457065655571
405.20000000000505,45.82246426191241,0.6565115492584543,-1.7400714285352938
406.4000000000051,45.938361273604265,0.586303271875976,-1.7711350656655171
407.6000000000051,46.05522305241114,0.5115880985997934,-1.7978762915891187
408.80000000000507,46.17110136620499,0.4480263306442387,-1.8213741298529094
410.0000000000051,46.287918736730646,0.38728209501225297,-1.8444631331618306
411.20000000000516,46.403604173498394,0.33605465690849434,-1.860658801044773
412.40000000000515,46.520284536500576,0.29647591615899077,-1.8741955627154465
413.60000000000514,46.63742178427067,0.2626668507080614,-1.8881857437294305
414.8000000000052,46.75224098169449,0.23977189159900347,-1.9022420182182667
416.00000000000523,46.87013969175897,0.2228245497522316,-1.9161377081510356
417.2000000000052,46.98822419210489,0.20831579869785832,-1.9274226059084452
418.4000000000052,47.10386391237996,0.19344347765171283,-1.9321478121621665
419.60000000000525,47.22227279979544,0.18536495972346556,-1.9399869431840449
420.8000000000053,47.33888419978872,0.18015641276070493,-1.949525351590629
422.0000000000053,47.45604154058665,0.17532544026657476,-1.9596482407179714
423.2000000000053,47.57356182451263,0.17318153450232193,-1.970168881740868
424.4000000000053,47.69187727505492,0.1717751719193923,-1.9794670001476846
425.60000000000537,47.8088230402974,0.1674483671051582,-1.9821303541040827
426.80000000000535,47.925885621249826,0.1649068322664124,-1.9884967510714677
428.00000000000534,48.04308410334574,0.16364934805357895,-1.9990318392472806
429.2000000000054,48.160964027620246,0.16170724751424792,-2.00816604358587
430.40000000000543,48.278982679818874,0.15923049011658658,-2.0155860139387336
431.6000000000054,48.397275721644625,0.16083595897387093,-2.0236033767011934
432.8000000000054,48.51588012928753,0.15827678687345192,-2.0289490291809678
434.00000000000546,48.63314921997282,0.16096186338335516,-2.0364843056322766
435.2000000000055,48.75091011600005,0.16022618356320506,-2.046996339114343
436.4000000000055,48.868487231682415,0.16278523416205093,-2.055865318955415
437.6000000000055,48.98603616750402,0.16171851034401302,-2.060957998515664
438.8000000000055,49.1035581475894,0.16370498020530816,-2.0680509225571675
440.00000000000557,49.22180483076319,0.1649619969967604,-2.0797261389273753
441.20000000000556,49.33946360793623,0.16543020566473227,-2.090421520956319
442.40000000000555,49.457199151823325,0.16855249456729543,-2.0961133071154894
443.6000000000056,49.57404220433893,0.16741589565157383,-2.1053658671651174
444.80000000000564,49.692293819601566,0.16926977579730462,-2.1124978534161034
446.0000000000056,49.80944839353149,0.1684040239507777,-2.1228284823055175
447.2000000000056,49.92693487336121,0.17071749525415703,-2.1326952231711997
448.40000000000566,50.04520140107546,0.17130711568189666,-2.1389924901769195
449.6000000000057,50.162874126530596,0.17235295762012576,-2.1431196378985753
450.8000000000057,50.280405889758654,0.17074433317318316,-2.15597095207317
452.0000000000057,50.39822835341831,0.17307982120698134,-2.168820285951057
453.20000000000573,50.51548846804924,0.17389199580547848,-2.1787599004858578
454.4000000000058,50.63526544945414,0.17369134714770657,-2.18730638721654
455.60000000000576,50.752683754149,0.17412477997847375,-2.1980148294729127
456.80000000000575,50.87110216817363,0.17420334326115178,-2.2068199474683414
458.0000000000058,50.989170000000485,0.17516732505957222,-2.216430144891106
459.20000000000584,51.10802697143871,0.17706511432970773,-2.229896349999658
460.40000000000583,51.2247944704676,0.17626661920740871,-2.2402996026009
461.6000000000058,51.34319339218844,0.17924085821763597,-2.2515897644881533
462.80000000000587,51.462024165239015,0.17667546073595325,-2.263174555625289
464.0000000000059,51.580699758286066,0.17853144995545156,-2.2765521793007784
465.2000000000059,51.698077970404256,0.17696800071126256,-2.2845116062200583
466.4000000000059,51.817417692059614,0.17619205063019033,-2.297137389780456
467.60000000000593,51.93553865472472,0.17690753509401924,-2.3087980908050056
468.800000000006,52.0539293818779,0.1740642721175104,-2.3225390004624407
470.00000000000597,52.172449280562915,0.17240947635658815,-2.334837636756393
471.20000000000596,52.29019028246761,0.16806454972283635,-2.3483437907877365
472.400000000006,52.40864473798802,0.16059459329735004,-2.359485502205372
473.60000000000605,52.52692356211597,0.15237416821457717,-2.3704672096860193
474.80000000000604,52.645735920063316,0.1398558245501379,-2.3811557785140325
476.000000000006,52.76293230753603,0.12846433496753262,-2.3890506572441526
477.20000000000607,52.88219415914232,0.10950334662775635,-2.397238294191889
478.4000000000061,53.0003581037964,0.0908933066738517,-2.412511071677252
479.6000000000061,53.118391532644964,0.0700497643564631,-2.4177121371917982
480.8000000000061,53.23761882556432,0.04970697923935197,-2.4192198339306192
482.00000000000614,53.35499196459336,0.03249871244239544,-2.4257756885608135
483.2000000000062,53.473586674229864,0.014122823935547202,-2.430939953306928
484.4000000000062,53.591906388842574,0.007690490246571591,-2.4317063267173484
485.60000000000616,53.71030298097542,-0.0019297404847434807,-2.4312012101536804
486.8000000000062,53.829270536881275,-0.010480546419321612,-2.4347027765802687
488.00000000000625,53.948806394083924,-0.012495738634700992,-2.4364535466797586
489.20000000000624,54.065436864074215,-0.013914750396042397,-2.4371568927753766
490.40000000000623,54.18498657999834,-0.011887019382955333,-2.4332752860131017
491.6000000000063,54.302111722682156,-0.0015416154961534478,-2.4381325494626935
492.8000000000063,54.42214981203619,0.003740924620567243,-2.439749132503887
494.0000000000063,54.54022828206222,0.00898630333380207,-2.4397471955907895
495.2000000000063,54.65926717804332,0.010604884923513247,-2.438429824942012
496.40000000000634,54.77751029089476,0.007416250773315536,-2.4371046101470313
497.6000000000064,54.89613023550325,0.0032754666531130683,-2.4347258895885053
498.8000000000064,55.014661105137456,0.0007040385502206647,-2.440202707128735
500.00000000000637,55.13362569173454,-0.00321337178078529,-2.4430397721294295
501.2000000000064,55.252076334466814,-0.009778908975785205,-2.44173436748004
502.40000000000646,55.37189457848171,-0.01795564757863799,-2.4417063593142787
503.60000000000645,55.49128850658556,-0.020301530756894393,-2.4417201999277225
504.80000000000643,55.60955485992474,-0.024918902893397432,-2.4403309090418475
506.0000000000065,55.72959444580138,-0.028475906632456305,-2.439075395849965
507.2000000000065,55.84866408376168,-0.0331451409945977,-2.4387611955201445
508.4000000000065,55.96753444108712,-0.03814879534727028,-2.4400798264753005
509.6000000000065,56.08766270941595,-0.04285024167421014,-2.440070300947987
510.80000000000655,56.20667477039634,-0.05056416363371785,-2.442515954532807
512.0000000000066,56.325331073707495,-0.056760437663107066,-2.44205246168333
513.2000000000066,56.44595237068269,-0.058733019644975626,-2.442719254865769
514.4000000000066,56.56449194824873,-0.06280564001521921,-2.4430401599304803
515.6000000000066,56.683895172880895,-0.06410462346042767,-2.444018652678624
516.8000000000067,56.803128578556596,-0.06588792204477084,-2.4443366404194387
518.0000000000066,56.922419027311264,-0.0677196671265281,-2.4428987813598138
519.2000000000066,57.041490906319424,-0.06907877518868721,-2.445338376818696
520.4000000000067,57.16068914095765,-0.07145741264662098,-2.4439206963959004
521.6000000000067,57.28012310482884,-0.06854258687759568,-2.4412805220960885
522.8000000000068,57.396815588510854,-0.06909483476056438,-2.441278368765475
524.0000000000067,57.51948950291511,-0.07168751246839133,-2.4412901889646403
525.2000000000068,57.63781663187876,-0.07199445588271908,-2.4452529367391223
526.4000000000068,57.75829345904057,-0.07510292563432175,-2.4465111128659007
527.6000000000067,57.877152862679516,-0.07232369658274557,-2.4478600181473427
528.8000000000068,57.996420194639086,-0.07329984866526845,-2.4478601076229913
530.0000000000068,58.116207035741226,-0.07522725884765746,-2.445231011684497
531.2000000000069,58.234051481846315,-0.07867806735594518,-2.4440299698639736
532.4000000000069,58.35391277814754,-0.07673309398702732,-2.445263114730643
533.6000000000068,58.47304787240431,-0.07996778861279907,-2.445339939521502
534.8000000000069,58.59267786754688,-0.07803433445507679,-2.4460814077043707
536.0000000000069,58.71131100640437,-0.07714515821594647,-2.44800569865874
537.2000000000069,58.83071990542575,-0.08123720767411824,-2.446979991581596
538.4000000000069,58.95052085887656,-0.08139609224905053,-2.444130723695586
539.600000000007,59.070515052913855,-0.08180595317564865,-2.4454489101722903
540.800000000007,59.18992331133268,-0.08323170500786292,-2.445405357519856
542.000000000007,59.31022437227795,-0.0841347330890988,-2.4466842852431854
543.200000000007,59.43018058239434,-0.08792200453905097,-2.4448213134190624
544.400000000007,59.54980453745688,-0.08708176005156454,-2.444492795905386
545.6000000000071,59.66944084363497,-0.09116312987971187,-2.4457802114993497
546.800000000007,59.78917105432874,-0.0911966707022388,-2.4464392784976026
548.000000000007,59.909262304139006,-0.09060635065648392,-2.449070053068672
549.2000000000071,60.02895272880471,-0.09024098626415122,-2.449401157265763
550.4000000000071,60.14916802260864,-0.08843955563204164,-2.4503899202381003
551.6000000000072,60.26965308353964,-0.09228773537343726,-2.450027421019053
552.8000000000071,60.388689173559754,-0.09263771136212384,-2.4460908982462874
554.0000000000072,60.50891421208111,-0.09245109295048581,-2.4464431618772
555.2000000000072,60.628952919185714,-0.09198165900640887,-2.4514607846607093
556.4000000000071,60.74829968254513,-0.09372391956154158,-2.4518116900315348
557.6000000000072,60.867521081900875,-0.09613869354837123,-2.4498375943837942
558.8000000000072,60.988344963254704,-0.09116655808253415,-2.4488476908273076
560.0000000000073,61.106801324904254,-0.0890922480504105,-2.4524696216011828
561.2000000000073,61.22654068892044,-0.09195592003365638,-2.4506229237984707
562.4000000000073,61.346796266918886,-0.0906666766040567,-2.4511495831080707
563.6000000000073,61.46644471582596,-0.09131519875572192,-2.453635509607377
564.8000000000073,61.58835763550624,-0.09275672355012754,-2.4531301620740518
566.0000000000073,61.707387246042444,-0.09454713640464596,-2.4531996149796678
567.2000000000073,61.827023164020645,-0.09078903798091342,-2.450512153882017
568.4000000000074,61.94742786343164,-0.09506836216136094,-2.451809968479237
569.6000000000074,62.06709109625617,-0.0923367409797109,-2.452470488093686
570.8000000000075,62.185936462772894,-0.09159498419778245,-2.449723731546578
572.0000000000074,62.30682745850411,-0.09066438030674295,-2.4497300849953776
573.2000000000074,62.42588889678614,-0.09425283462823941,-2.4497016035636827
574.4000000000075,62.546605832465495,-0.09341920356944122,-2.448640205195968
575.6000000000074,62.6666157516306,-0.08996218373266762,-2.4549941460785725
576.8000000000075,62.785954417679676,-0.09586726950639612,-2.4564848602067215
578.0000000000075,62.90673933680598,-0.09534169292527606,-2.453051030050199
579.2000000000075,63.025430362446095,-0.09491962641816032,-2.4489599451950257
580.4000000000076,63.14629759003549,-0.09240120199823643,-2.450300595835479
581.6000000000075,63.266429231858645,-0.09011967148606914,-2.4556045441902485
582.8000000000076,63.38589502369557,-0.08994046699489411,-2.4567135946180474
584.0000000000076,63.50685948309693,-0.09319288134587378,-2.452925099519941
585.2000000000075,63.62662838983459,-0.08855782366518006,-2.462780262717321
586.4000000000076,63.74587101672472,-0.08944689173649145,-2.470243449492065
587.6000000000076,63.86590760738334,-0.0895393995446151,-2.4618252820798827
588.8000000000077,63.98603236720815,-0.08915500655374586,-2.463575117950196
590.0000000000077,64.10553539830217,-0.09066241158544563,-2.4674013869296942
591.2000000000077,64.22580499868887,-0.08666614764275116,-2.465272112681184
592.4000000000077,64.34517283886613,-0.08886675277499612,-2.4634488251402695
593.6000000000078,64.46587657412012,-0.08657910425479254,-2.4594292975031564
594.8000000000077,64.58633339069273,-0.08605461588737495,-2.4635188410464
596.0000000000077,64.70658216355095,-0.08508496701756019,-2.46506121245214
597.2000000000078,64.8243506635546,-0.08122860169922796,-2.466285834595535
598.4000000000078,64.94716445184693,-0.0787043443027059,-2.467830148990614
599.6000000000079,65.06757990296123,-0.07545939362249598,-2.4733033949103205
600.8000000000078,65.18866795701739,-0.07147198305090063,-2.4726012689253487
602.0000000000078,65.30845623902727,-0.06991961094643995,-2.4719314776312693
603.2000000000079,65.42948820755852,-0.06378983859028586,-2.4709146630668517
604.4000000000078,65.55005637145891,-0.06058451825638045,-2.4718905971580987
605.6000000000079,65.67084041273421,-0.058711844568777094,-2.4720892267694925
606.8000000000079,65.7916454059111,-0.05395771205555189,-2.475079049246279
608.000000000008,65.91263961012307,-0.04857962783522962,-2.4737495867881076
609.200000000008,66.03326146701943,-0.042247005938504834,-2.4724309663477655
610.4000000000079,66.15426770920155,-0.036589116111950815,-2.4754116206125456
611.600000000008,66.27614882981479,-0.031822067056930026,-2.486639036221921
612.800000000008,66.39612626002159,-0.028028138787182022,-2.4844652750770795
614.000000000008,66.5173054499761,-0.02202665605872456,-2.4803268201595197
615.200000000008,66.63570153632877,-0.014376828740852665,-2.4816469151772815
616.400000000008,66.75775210093148,-0.00800527698355813,-2.4830180323769246
617.6000000000081,66.87816782983535,-4.8886041925988444e-05,-2.4869491644427155
618.8000000000081,66.99926628453137,0.0092035554985741,-2.4940280279348417
620.0000000000081,67.1188559615724,0.016577762444921706,-2.4895039917514197
621.2000000000081,67.24048447333978,0.022647998515642587,-2.491296361513242
622.4000000000082,67.36057428265954,0.029582689761408876,-2.489694439339212
623.6000000000081,67.48082969131848,0.03976615644165271,-2.492296240312714
624.8000000000081,67.60231726773448,0.0504538621502838,-2.4959958659325836
626.0000000000082,67.72214953810445,0.058140746066404736,-2.497864298386265
627.2000000000082,67.84231878149744,0.06610441100620645,-2.5019414678113043
628.4000000000083,67.96321580299589,0.07698466126783643,-2.505539304628216
629.6000000000082,68.08335503229361,0.08920365594941371,-2.507252725050835
630.8000000000083,68.2040593477292,0.09705526043068868,-2.503251034605126
632.0000000000083,68.32430940024831,0.11035874216550023,-2.509480989396776
633.2000000000082,68.44532983971047,0.1223786616012158,-2.5132713345994357
634.4000000000083,68.56557572032582,0.13324447530938943,-2.5133116165846014
635.6000000000083,68.687318635387,0.14395320022265423,-2.5131559050007937
636.8000000000084,68.80733292464602,0.15749964354055712,-2.519589389545017
638.0000000000084,68.9274858902244,0.16835870030775102,-2.518223783602062
639.2000000000083,69.04832305618683,0.18047685504664823,-2.520392388679916
640.4000000000084,69.16937353237608,0.1965623015889446,-2.529382698816394
641.6000000000084,69.28968944634603,0.20906989786473762,-2.5345548165281455
642.8000000000084,69.4116497668,0.22115799097547106,-2.5417327825316747
644.0000000000084,69.53328206612966,0.2349060102197401,-2.5417499080219197
645.2000000000085,69.65454958219736,0.24945133606277003,-2.545039399701691
646.4000000000085,69.776063841474,0.26222384482100014,-2.5458538329743257
647.6000000000085,69.897503323355,0.2769902948370102,-2.5530058916736817
648.8000000000085,70.01957609658983,0.29144512800206557,-2.5566571555139666
650.0000000000085,70.13981230899181,0.30531095698450317,-2.5649594823934976
651.2000000000086,70.2609932207888,0.31990186835239554,-2.5621263635874687
652.4000000000085,70.38035013759291,0.33442004432577854,-2.5619630728149723
653.6000000000085,70.50305872977985,0.3557034835353663,-2.571252650501101
654.8000000000086,70.62326943499738,0.37313118329556594,-2.583149988503124
656.0000000000086,70.74394347572542,0.3889278487569505,-2.586692491594154
657.2000000000087,70.86367929356379,0.40704507508600285,-2.592918076885276
658.4000000000086,70.98483451548272,0.4213691720133723,-2.5937503365227155
659.6000000000087,71.10589602229898,0.44188435710567053,-2.5987149116206285
660.8000000000087,71.22642197447388,0.46067025827084795,-2.6078923996329726
662.0000000000086,71.34755187565109,0.4798861279582418,-2.6107204121920526
663.2000000000087,71.46661355578355,0.4966056154484164,-2.6188690582479177
664.4000000000087,71.58846417113587,0.5166549007558232,-2.623570044626267
665.6000000000088,71.70937113355622,0.5372224928540448,-2.6285280719822026
666.8000000000088,71.8306086487352,0.5542183909892104,-2.6367063363554744
668.0000000000088,71.9515932767685,0.5677780345623658,-2.641233462237949
669.2000000000088,72.07147526669802,0.5871360265751748,-2.648352740915708
670.4000000000088,72.19216985175288,0.5977283341499537,-2.6571972012044585
671.6000000000088,72.31295833653262,0.6111430022361417,-2.6666464123458775
672.8000000000088,72.43461031796392,0.621336382746398,-2.6733851020818316
674.0000000000089,72.55587140001155,0.6321631610443987,-2.6775536065271566
675.2000000000089,72.67816402466259,0.6397249832738903,-2.6833541109306536
676.400000000009,72.7990688909368,0.6498181433872241,-2.693882124601403
677.6000000000089,72.91948662044847,0.6536821945424767,-2.6958547069377055
678.8000000000089,73.04138255158033,0.6609299603252661,-2.7033843784767013
680.000000000009,73.16292319128725,0.6729408700996207,-2.710121560684727
681.2000000000089,73.28376802921915,0.6873562007418759,-2.7166695957715796
682.400000000009,73.40483895955761,0.7079117144570841,-2.720761380906122
683.600000000009,73.5251306522218,0.7345007004433775,-2.724239551018753
684.800000000009,73.64686971633759,0.7692671282657786,-2.7410511305135614
686.0000000000091,73.767056801849,0.8046780328369174,-2.747196796397064
687.200000000009,73.8884237913814,0.8498621470272494,-2.7533949401685103
688.4000000000091,74.00990602788885,0.8900718216939754,-2.76254569691179
689.6000000000091,74.1309284878177,0.9360561539599528,-2.7758519031936526
690.800000000009,74.25147457888008,0.9778690665887602,-2.7829717577558273
692.0000000000091,74.3731030233193,1.0246183072802406,-2.7923205306686047
693.2000000000091,74.494486904544,1.0641895403375141,-2.79853220919812
694.4000000000092,74.61561914512293,1.1108890385553138,-2.812662296727477
695.6000000000092,74.73677190364405,1.148792171909944,-2.8201218373442045
696.8000000000092,74.85800205828667,1.1899620348103688,-2.828677693278564
698.0000000000092,74.97978086877029,1.2318454202690463,-2.8419616556135785
699.2000000000093,75.10121386897366,1.2680899822661862,-2.8517416535711524
700.4000000000092,75.22218124390156,1.3039632514572328,-2.8620374327876705
701.6000000000092,75.34333553720012,1.345865695017815,-2.876827829856742
702.8000000000093,75.4644754899285,1.3799090501311353,-2.89079841959542
704.0000000000093,75.58621524945103,1.4147672644273748,-2.9086280045653394
705.2000000000094,75.70799711841424,1.443419566709781,-2.9200480822949384
706.4000000000093,75.82955522883928,1.4712801896891794,-2.9343846444167867
707.6000000000093,75.95067301497211,1.4911389335861944,-2.9465393505114705
708.8000000000094,76.07191923773013,1.5084035436530658,-2.956163374517569
710.0000000000093,76.19252974147304,1.5251403985408616,-2.9713069423928067
711.2000000000094,76.31525208921222,1.5274320843542664,-2.9831777304402483
712.4000000000094,76.43542726066292,1.5192582837232442,-2.997365015772876
713.6000000000095,76.55706163133964,1.5040462165022648,-3.015229340318634
714.8000000000095,76.67765461387458,1.4636897069570114,-3.0244273524527348
716.0000000000094,76.79927171923089,1.4030532933974835,-3.036381241801652
717.2000000000095,76.91974526211925,1.3115792316302053,-3.0534312531086303
718.4000000000095,77.04139977781503,1.1690312630939146,-3.0670489965012933
719.6000000000095,77.16192236610034,0.9286000905219922,-3.0754064676403416
720.8000000000095,77.28281002137349,0.48611676776090107,-3.084272792175776
722.0000000000095,77.40324963166937,0.006393298291628824,-3.085580148004071
723.2000000000096,77.52388768810667,-0.14791514165528885,-3.086809109236354
724.4000000000096,77.64452178750395,-0.20005962906755625,-3.0882130488078183
725.6000000000096,77.76465092036031,-0.2269526221314513,-3.0882121747034432
726.8000000000096,77.88670611045265,-0.23834066137923648,-3.088616197626748
728.0000000000097,78.00741883856861,-0.2442082845827631,-3.0882100032385256
729.2000000000096,78.12798397447935,-0.25128543431357175,-3.088209800000031
730.4000000000096,78.2497660525662,-0.25453433365672806,-3.0882098163508083
731.6000000000097,78.37151764216568,-0.2591506156979382,-3.0886279358995896
732.8000000000097,78.49262853322018,-0.25879320931690897,-3.08524480243355
734.0000000000098,78.61486390762148,-0.2675732354424283,-3.0839301174741856
735.2000000000097,78.73659947406858,-0.2686883311627124,-3.085175240526334
736.4000000000098,78.85849754354558,-0.27249050034163025,-3.0906145898633546
737.6000000000098,78.97981914981956,-0.2706442323335998,-3.089573670439288
738.8000000000097,79.10035668949142,-0.27193316478354945,-3.0924455299724887
740.0000000000098,79.22258401086032,-0.273442422375058,-3.0894181923634276
741.2000000000098,79.34431647287643,-0.2780160513678729,-3.0918394462480885
742.4000000000099,79.46574454461926,-0.27877063985298056,-3.091841743873498
743.6000000000099,79.58662201702451,-0.28322171815254404,-3.0890897810692355
744.8000000000098,79.7085795077437,-0.28326763360891416,-3.090420506864974
746.0000000000099,79.83059798437266,-0.28833770300566175,-3.0890898333309544
747.2000000000099,79.95229016751217,-0.2869184577776389,-3.090398262333437
748.4000000000099,80.07453944392451,-0.29187753793017346,-3.0875083377532295
749.6000000000099,80.19625983802439,-0.29513833402804557,-3.0802940074975202
750.80000000001,80.31822359837888,-0.29479939149441514,-3.082626506215758
752.00000000001,80.44001988169052,-0.29883760248030633,-3.093986106660184
753.20000000001,80.56139094299634,-0.298069666611835,-3.0947144600557692
754.40000000001,80.68334972471288,-0.2997378236254229,-3.086785993779481
755.60000000001,80.8050417019168,-0.2992929137980782,-3.0948980304908282
756.8000000000101,80.92683254507142,-0.30499130678569086,-3.0944377991793766
758.00000000001,81.04784403792272,-0.3050184735812629,-3.087645416206459
759.20000000001,81.16759691872991,-0.30851953659698794,-3.0911680495901983
760.4000000000101,81.2904516069212,-0.31536834375787537,-3.091976721738328
761.6000000000101,81.41332873297685,-0.31619142958007895,-3.0937833477029386
762.8000000000102,81.53539963150313,-0.31582122742454577,-3.0924910094900095
764.0000000000101,81.65486175370506,-0.31961730276766787,-3.092192074280189
765.2000000000102,81.77764584612635,-0.3240504089027654,-3.0912484399607254
766.4000000000102,81.89622755857219,-0.3257230850727322,-3.0941321850867345
767.6000000000101,82.01812454189522,-0.3286554684044971,-3.0941298090651497
768.8000000000102,82.14225251268056,-0.3272729175068103,-3.092820326001053
770.0000000000102,82.26286903739849,-0.3299226249008709,-3.0911414487570767
771.2000000000103,82.38522978253714,-0.3294030489686177,-3.0913853307036794
772.4000000000103,82.50645489586053,-0.331977844153472,-3.0933541587228564
773.6000000000103,82.62876564522921,-0.33067903996781856,-3.094981713202205
774.8000000000103,82.75028975042066,-0.3346106253587666,-3.0932471857526824
776.0000000000103,82.8713834280945,-0.33278139825676356,-3.0919399290476908
777.2000000000103,82.99315429222005,-0.32796085689541754,-3.0919399985209552
778.4000000000103,83.11545789026135,-0.33149842752022796,-3.0919852160856216
779.6000000000104,83.23640232906433,-0.32866117304971043,-3.0906300341579267
780.8000000000104,83.35906956740035,-0.33072775461785753,-3.0919398511119693
782.0000000000105,83.48162024576699,-0.32676390961256363,-3.0932258801578962
783.2000000000104,83.60344507061265,-0.3307377528680766,-3.095223337187987
784.4000000000104,83.7256689217842,-0.3262242829653603,-3.0950117539405158
785.6000000000105,83.84647536734182,-0.32339868029238605,-3.0946781549389044
786.8000000000104,83.9696608577377,-0.32316969328659595,-3.095989698922067
788.0000000000105,84.09123914311728,-0.32434175142403365,-3.0949292380559434
789.2000000000105,84.21282323309588,-0.3217217423981866,-3.09468120802276
790.4000000000106,84.33474100145318,-0.321245686533308,-3.0946866039681438
791.6000000000106,84.4557173281144,-0.3255967104155133,-3.094666247956436
792.8000000000105,84.5781377175576,-0.3201397682148144,-3.0959667402685844
794.0000000000106,84.70027510350876,-0.3171526182401261,-3.095918222651392
795.2000000000106,84.82149644431686,-0.3188283604109985,-3.093331428082729
795.7000000000106,84.87145153738567,-0.32361593952289125,-3.090798000717154