File: 01_Data/EIFS_Coating/STA/N2/3K_min/EIFS_Coating_STA_N2_3KData_230915_R1.csv
##Temp./Â°C,Time/min,DSC/(mW/mg),Mass loss/mg
40.2,10.9328440951629,-0.012455604706088863,0.05281950115417189
41.60000000000002,11.745014629019876,0.03119051505816195,0.04876145004042787
43.00000000000004,12.333212926006823,0.04139734642359061,0.04851774554713639
44.40000000000006,12.874453611767505,0.04659509099833237,0.04983019530713939
45.80000000000008,13.403552666072688,0.05128308293558792,0.05063136358036324
47.2000000000001,13.903994307824373,0.052431755186998164,0.05204665593153557
48.60000000000012,14.411915048092414,0.057124806193745936,0.05280186251382091
50.00000000000014,14.906214436599079,0.06274500840447716,0.05212719893189366
51.40000000000016,15.390000000000054,0.06164381555396092,0.05478011523750492
52.80000000000018,15.868327592455639,0.06325579462134767,0.05377901730010315
54.2000000000002,16.345329269859043,0.06928043787111537,0.055135865912033566
55.60000000000022,16.8215378769202,0.06923021165926979,0.0560667353880584
57.00000000000024,17.299652391771904,0.07175284906632884,0.05612367100480675
58.40000000000026,17.755776478386117,0.07291459735418027,0.056067027892058974
59.80000000000028,18.240311709066464,0.07206530012826651,0.05738885026708651
61.2000000000003,18.699059849284282,0.07576624379250996,0.0568752030515709
62.60000000000032,19.18021910758198,0.07774976099365993,0.05708220533133712
64.00000000000034,19.645714738329016,0.08115903698464555,0.05741007907135298
65.40000000000036,20.111502831996646,0.08021682270522446,0.05674618831632383
66.80000000000038,20.575336113124532,0.07964095671205618,0.05740170375311493
68.2000000000004,21.04335972508765,0.07684719809014551,0.05675013500789028
69.60000000000042,21.5047130990938,0.07862007700047924,0.05543002984956136
71.00000000000044,21.97143416105964,0.07761198305263894,0.05543992497498351
72.40000000000046,22.441602935308858,0.07396035928996714,0.05445000031942371
73.80000000000048,22.903565527180053,0.06913439635312457,0.055760070022908614
75.2000000000005,23.37143898727034,0.06551819129092706,0.0575583815080849
76.60000000000052,23.83331171267534,0.060279229137389034,0.057080286348940135
78.00000000000054,24.2897763370929,0.0600610635678156,0.05575992999999979
79.40000000000056,24.753140250506316,0.059696989865983596,0.05708350176610644
80.80000000000058,25.21802506705367,0.06027949970137536,0.05707989504490385
82.2000000000006,25.68040149341384,0.05738195116366107,0.057735675240079054
83.60000000000062,26.143252713788286,0.05962052308234167,0.05708971232349036
85.00000000000064,26.60241246505676,0.05888238022638115,0.05850831381931609
86.40000000000066,27.06309751946361,0.05737605484464936,0.0587381861132279
87.80000000000068,27.52330002672101,0.060653752973432784,0.05873005480960902
89.2000000000007,27.992656635765158,0.05936623866555868,0.06138568498600527
90.60000000000072,28.457974548320948,0.058650091839088425,0.06004007315624715
92.00000000000074,28.91021573407801,0.062141237769488544,0.06005125374107578
93.40000000000076,29.379127869826178,0.06259575484977153,0.05840234110505005
94.80000000000078,29.839915364912056,0.06214759271097403,0.05872519005581012
96.2000000000008,30.301387053043932,0.0593707131284158,0.06003972008915426
97.60000000000082,30.762475298854664,0.058269282672298583,0.059709867069733136
99.00000000000084,31.22065054171753,0.057528599273307446,0.05939381522299936
100.40000000000086,31.676731088440754,0.058238961136537704,0.06127789837842457
101.80000000000088,32.13154825815918,0.057848516367821734,0.0595594869419207
103.2000000000009,32.597533458279,0.05642895723332764,0.05937981499576317
104.60000000000092,33.05220145080919,0.05858707967243015,0.061394185337694474
106.00000000000094,33.534494299391845,0.054430779756558856,0.061297900738289
107.40000000000096,33.97166129092026,0.05808293601620873,0.06071073707373831
108.80000000000098,34.43224025491776,0.05700855962068507,0.05887061138585459
110.200000000001,34.890217273671034,0.056080898616271746,0.06168990056414092
111.60000000000102,35.34908222124262,0.05701630036564742,0.060913604298543866
113.00000000000104,35.810000000000606,0.05797773640572945,0.06135982010782293
114.40000000000106,36.26489072740353,0.05685555455044078,0.059380564524777135
115.80000000000108,36.722963341127844,0.05645743691525151,0.06069807833066587
117.2000000000011,37.16999999999939,0.05574783075829837,0.06072929875559652
118.60000000000112,37.638502752747755,0.05609520661574119,0.06200895272699647
120.00000000000114,38.10095565890397,0.0570989116827505,0.06070991844070406
121.40000000000116,38.556570519674494,0.05619586321879311,0.061030159043396814
122.80000000000118,39.01763474544894,0.055827143971458826,0.06135922227432378
124.2000000000012,39.41420709108764,0.055796154458746194,0.056714246780351196
125.60000000000122,39.93380726595373,0.05326001786832224,0.05938012831677675
127.00000000000124,40.38629997665464,0.0551182624522073,0.05806980672191475
128.40000000000126,40.847024634607095,0.05716597158255987,0.060369663722548594
129.80000000000126,41.30476451455821,0.05547751364405262,0.06136020000000553
131.2000000000013,41.765488105261646,0.0535672006221648,0.06136009503618922
132.60000000000133,42.228509743776435,0.05427999935824879,0.05904994198003699
134.00000000000134,42.68072606690774,0.05463662838905625,0.06039180668325361
135.40000000000134,43.13525615278502,0.05276930568962257,0.05907676997366007
136.80000000000138,43.59193631834133,0.05530441151559273,0.05975475629418536
138.2000000000014,44.04491705546526,0.05710443365991935,0.06201905973078059
139.60000000000142,44.49920384752715,0.05629633184197114,0.05939028541184932
141.00000000000142,44.95479196326219,0.054828474525232984,0.06091405075318246
142.40000000000146,45.40792378310245,0.05470164769616925,0.06114007343954153
143.8000000000015,45.859735936873506,0.05379708166884112,0.06080995500011799
145.2000000000015,46.3229195145437,0.05596539438675374,0.059489954995207484
146.6000000000015,46.77465062203255,0.05192697919787803,0.06114513616049955
148.00000000000153,47.23194605557849,0.05319665249627148,0.06227704853672744
149.40000000000157,47.6858519087272,0.05756136214656027,0.06047992502297195
150.80000000000157,48.142696349715536,0.05917645907088609,0.06048887094449551
152.20000000000158,48.591295813369065,0.05923482196100349,0.05817999464520174
153.60000000000161,49.04673185174595,0.06016697860445652,0.06212858435670032
155.00000000000165,49.49317653877573,0.06091921245942489,0.05982989499976554
156.40000000000165,49.95753424762774,0.059187930889683216,0.05982006359432024
157.80000000000166,50.41423022637813,0.05826778877616112,0.059820069990446534
159.2000000000017,50.86571771273411,0.06049640567019532,0.059820170006249285
160.60000000000173,51.31999645249225,0.06180398786665586,0.0604798149896828
162.00000000000173,51.774713148879876,0.06169686450101186,0.059819650091311516
163.40000000000174,52.23507505626145,0.06498121602739015,0.06015025090383652
164.80000000000177,52.68403182402652,0.06030607810020383,0.05983019000003953
166.2000000000018,53.13782498621916,0.061642315494055744,0.05983018999999867
167.6000000000018,53.59164547877031,0.06386899568605786,0.06112713926797575
169.00000000000182,54.05125555208926,0.06292666640096822,0.05886075272892466
170.40000000000185,54.50241772134028,0.06369110203970685,0.060150034999646884
171.8000000000019,54.955908909456575,0.06577921462901792,0.06015017926499322
173.2000000000019,55.409146643578865,0.06554211554432876,0.05949018859267863
174.6000000000019,55.86146571378454,0.06569084666915259,0.05817390605174122
176.00000000000193,56.31435762455374,0.06475186594923943,0.05917069431348754
177.40000000000197,56.76859339149585,0.06255783203719645,0.057840186250471604
178.80000000000197,57.21777214239195,0.06287874477856081,0.05946464595754364
180.20000000000198,57.67346916320129,0.06509998031229092,0.05566504931714178
181.600000000002,58.1299966024125,0.0643884481145327,0.05740011000263312
183.00000000000205,58.586965437716024,0.06711583418851474,0.05773992999999944
184.40000000000205,59.034574432490075,0.0672094952406801,0.05690396344340343
185.80000000000206,59.49571081767784,0.06384506135292556,0.057740284628096994
187.2000000000021,59.94876060146001,0.06385465337949214,0.05774076460363897
188.60000000000213,60.40131786366294,0.06610870472703723,0.056419929999999674
190.00000000000213,60.86000000000075,0.06377729105265395,0.05627398280589624
191.40000000000214,61.310003370417334,0.06582645554124866,0.05576000499999978
192.80000000000217,61.76044280488111,0.06543703349477181,0.055495542285125765
194.2000000000022,62.221492748021475,0.06489749265027478,0.05479883154553633
195.6000000000022,62.67307367718875,0.06421208440761861,0.05378009230055536
197.00000000000222,63.12756190287124,0.06125282762665085,0.054770079903690316
198.40000000000225,63.577287358677694,0.06505673188962668,0.056062932606592675
199.80000000000229,64.03679185319704,0.06261645826986073,0.054110063182018386
201.2000000000023,64.4895890306922,0.06463284430527683,0.05342015316717408
202.6000000000023,64.94820899467433,0.0677484716524197,0.054110133064410704
204.00000000000233,65.40104807654929,0.06546811104312455,0.0527948154269815
205.40000000000236,65.85603924886213,0.06636468160815823,0.05443003043801031
206.80000000000237,66.30709681987655,0.06673542762972628,0.05450050738644663
208.20000000000238,66.76044037378927,0.06407130163158925,0.05410422403845683
209.6000000000024,67.21695146614351,0.06782421506560965,0.05247007999161113
211.00000000000244,67.67101376147313,0.06742220457528836,0.05279998591072932
212.40000000000245,68.1266920715785,0.06548526439619495,0.05214008000000181
213.80000000000246,68.5729308116415,0.06304608896840724,0.05082034778848499
215.2000000000025,69.02727819301981,0.06954303281238405,0.051490271460579606
216.60000000000252,69.48087537624336,0.06620750920997098,0.051810219247665934
218.00000000000253,69.93328232422624,0.06558879933179473,0.049536099113532295
219.40000000000254,70.38746960506256,0.06723479690306089,0.05699461217624968
220.80000000000257,70.83786861775174,0.06595796963641476,0.047530756043872024
222.2000000000026,71.28892138884082,0.0656050312848766,0.05156852232012188
223.6000000000026,71.74392272137601,0.06753346065369481,0.04894985499999649
225.00000000000261,72.1967684361266,0.06927625661549919,0.04929147304623083
226.40000000000265,72.65166932476113,0.07027491722852752,0.050930829602783945
227.80000000000268,73.10387673695128,0.06900849353063476,0.051598016388971324
229.2000000000027,73.55905386906649,0.06843267575503442,0.04828792356100653
230.6000000000027,74.01106738059258,0.07114721279330127,0.05019897996753375
232.00000000000273,74.4693206098638,0.06736814409014946,0.05027007870216771
233.40000000000276,74.9228135195549,0.06872449633710098,0.050338463292228575
234.80000000000277,75.37582338525682,0.06948242551406314,0.04927603854912199
236.20000000000277,75.82692367984072,0.06894388633867066,0.04828992999999926
237.6000000000028,76.28440956750484,0.06886836727296508,0.048289930000001036
239.00000000000284,76.73767912763608,0.06770268431121207,0.04745409401277456
240.40000000000285,77.18900805738483,0.06672370765762836,0.04664331571173275
241.80000000000285,77.64413514752552,0.06514322156236485,0.046455643873583696
243.2000000000029,78.09565072926758,0.06467879388015474,0.04730016617310806
244.60000000000292,78.54928367442189,0.060352627111721624,0.047960111915316794
246.00000000000293,79.00528216708605,0.06133220576910614,0.0459900375176181
247.40000000000293,79.45247419732205,0.06199043993336706,0.04696928175888271
248.80000000000297,79.9100000000006,0.06277918917212943,0.04762629040228106
250.200000000003,80.36684489221788,0.061131707602073426,0.04905315523169218
251.600000000003,80.81869471038642,0.05952742432389835,0.04468019739702811
253.000000000003,81.27557477138973,0.05991293619376803,0.04684523317808953
254.40000000000305,81.72637821390408,0.05938404323820823,0.04457887176151498
255.80000000000308,82.17210140854377,0.060636663369298294,0.04467011487240402
257.2000000000031,82.63686491758105,0.05710618077342655,0.045317064178218125
258.6000000000031,83.08616357802953,0.05794102282407754,0.04532996499939124
260.0000000000031,83.54242451605369,0.06283122282317,0.04400993571405731
261.40000000000316,83.99617540874011,0.05939512290940052,0.042690069010929754
262.80000000000314,84.45127298409487,0.05945290046806018,0.04269006426190103
264.2000000000032,84.90018618225113,0.058582178866190215,0.04375562627919383
265.6000000000032,85.35978774919639,0.05873124373160299,0.04235053875283512
267.00000000000324,85.81342670227215,0.05989044752286299,0.041298489998848
268.4000000000033,86.2670296309434,0.059258138896717494,0.04236960612157237
269.80000000000325,86.72109591505794,0.05756229078495956,0.04367992247406427
271.2000000000033,87.17856333627145,0.05986149765295301,0.0417098213020024
272.6000000000033,87.63313729308994,0.059059921838158,0.04200448089188047
274.0000000000033,88.08836017302303,0.058514313035136656,0.04170869660386778
275.40000000000333,88.54228913123414,0.05843625677306452,0.040060002453690124
276.80000000000337,88.99845918830916,0.05644694868612676,0.041049999978063134
278.2000000000034,89.45491369253995,0.056696540540009055,0.040060022540972184
279.60000000000343,89.90589531123645,0.05909083828191575,0.03939958577704772
281.0000000000034,90.36355765449913,0.057369191707837164,0.03939668198574342
282.40000000000344,90.81598033723472,0.05602560757896424,0.03939541773956279
283.8000000000035,91.27234646121568,0.056457529484260194,0.03810608800244086
285.20000000000346,91.7242114680744,0.05596743881194466,0.038412439021944245
286.6000000000035,92.1828929298623,0.05650959264695077,0.03808598879037195
288.0000000000035,92.63096397109246,0.05368511071454707,0.03841927543791179
289.40000000000356,93.09443099409599,0.053746737416656476,0.03413711676682851
290.8000000000036,93.54226185456031,0.05501840030329275,0.03578033961770366
292.20000000000357,94.00250660935757,0.05415360010399639,0.0357798099999771
293.6000000000036,94.45832267429205,0.0533699988229317,0.03416569888617982
295.00000000000364,94.91252479304231,0.05577770650189917,0.035120574071814126
296.4000000000036,95.37372663633988,0.05708664507149619,0.03429640211947138
297.80000000000365,95.82832960241885,0.05444049675633211,0.033800020033564415
299.2000000000037,96.28532045858644,0.053957122789773715,0.03380001999989801
300.6000000000037,96.74094867730932,0.05239869891092619,0.03248002611956835
302.00000000000375,97.19801686001527,0.05107596317126584,0.03182984500001851
303.40000000000373,97.65320426446166,0.05325127785880768,0.032819738402367626
304.80000000000376,98.11215867515315,0.051021501749742404,0.030503309618588048
306.2000000000038,98.56632224897682,0.04843554354319024,0.03183002203085383
307.6000000000038,99.02081968070816,0.05059957230395851,0.030510828052888073
309.0000000000038,99.47742419418269,0.05058728636543708,0.0307707781924611
310.40000000000384,99.93265056521037,0.05069879864901883,0.030180057899402257
311.8000000000039,100.38490820302006,0.052087912631835875,0.029522357363483742
313.2000000000039,100.84718964961628,0.05200179912778946,0.028983808160577773
314.6000000000039,101.29982276785756,0.05341829364660966,0.027549992157595682
316.0000000000039,101.75685568673357,0.05477760904519591,0.028209834999112893
317.40000000000396,102.21497781657862,0.05461718793456405,0.02623009000150578
318.80000000000393,102.66337345865641,0.05500137968439778,0.025569937465720116
320.20000000000397,103.12197459103149,0.05217042105670644,0.024910123694328767
321.600000000004,103.58325919418687,0.05361924247457073,0.023261209575394126
323.00000000000404,104.04081133562866,0.05216537492679785,0.023919895000001468
324.40000000000407,104.49794912325034,0.053348706215158304,0.022602781922922865
325.80000000000405,104.95631283998722,0.054861262660565124,0.021948197284616278
327.2000000000041,105.4082177738873,0.054330552615341476,0.023014229453897528
328.6000000000041,105.86800302116863,0.0560707602680508,0.020265751727683856
330.0000000000041,106.33029933343052,0.05935330411755135,0.0206167460065263
331.4000000000041,106.77179850193777,0.058197143074019575,0.020630131584035816
332.80000000000416,107.24650986246145,0.060760019610639926,0.01908699160585403
334.2000000000042,107.70503754287779,0.06409259338810336,0.016661022610558796
335.60000000000423,108.15921778521763,0.06390659046906078,0.014694811004489772
337.0000000000042,108.61706573313624,0.06885676642918526,0.014814446460165165
338.40000000000424,109.07549897673722,0.07138139742295158,0.014050117981756927
339.8000000000043,109.5335779349852,0.0607614310764375,0.012721636981188666
341.20000000000425,109.99440558657388,0.07732956256334766,0.01229629632113749
342.6000000000043,110.45056791287844,0.09162006149800983,0.010064111416828503
344.0000000000043,110.90681807591183,0.10027646478212993,0.00745980999481155
345.40000000000435,111.37256674142844,0.10628630499633895,0.0074557326045630035
346.8000000000044,111.83440735749733,0.10860415671702572,0.0041594767854196135
348.20000000000437,112.2933218126211,0.11130302369724987,0.004754004325235428
349.6000000000044,112.7553839517904,0.11351591251429505,0.0017773460496117721
351.00000000000443,113.21331513439317,0.11090018394939971,-0.0014168020527600689
352.4000000000044,113.67463353276918,0.11486943993685861,-0.0014398841740357327
353.80000000000445,114.12830705698956,0.11459890168428566,-0.005379733200557624
355.2000000000045,114.59236757872743,0.11608707289641229,-0.007920265373065227
356.6000000000045,115.04808658710344,0.11492243444213335,-0.011207732689364036
358.00000000000455,115.50882196143428,0.11408126232473892,-0.01526989545085744
359.4000000000045,115.96762356810281,0.11097849894923018,-0.0198095712200983
360.80000000000456,116.4276372288204,0.10989082436466391,-0.023834071543183732
362.2000000000046,116.88143917612462,0.11075137000348545,-0.029122959804608328
363.60000000000457,117.35103201612343,0.10423492422281289,-0.035690184740261977
365.0000000000046,117.80615771646613,0.10565782944072621,-0.04095330405837583
366.40000000000464,118.26746486364682,0.09883758553688748,-0.04987847628624742
367.8000000000047,118.73233235018306,0.09511117095196875,-0.055114502940347254
369.2000000000047,119.1921755145827,0.09515328228383968,-0.0632472645583313
370.6000000000047,119.65759325538849,0.09239778380921937,-0.07125375961890157
372.0000000000047,120.11901652653557,0.08963174921450623,-0.07977969608765312
373.40000000000475,120.57976996739632,0.0830000537795621,-0.08740190212490484
374.80000000000473,121.0410142124387,0.08043593645066482,-0.09674657230550343
376.20000000000476,121.50405045701099,0.07587491276258262,-0.10667326451776882
377.6000000000048,121.95795460541459,0.07605409453080592,-0.11580315686200882
379.00000000000483,122.4228343971277,0.07295098658711452,-0.12441900381275639
380.40000000000487,122.87857791059831,0.0676359052324893,-0.13138800449362265
381.80000000000484,123.34585884625656,0.06404209022119445,-0.13726947798619715
383.2000000000049,123.80857080663682,0.059357283486161316,-0.1461295855993896
384.6000000000049,124.26746808455837,0.054275320965732954,-0.1527195923011857
386.0000000000049,124.72856395131824,0.05284807414685,-0.15895368977116586
387.4000000000049,125.18872362242234,0.05096225707558655,-0.16437042056837514
388.80000000000496,125.64481290539906,0.047506830253498444,-0.1646985280032971
390.200000000005,126.10640556416419,0.04418804194823278,-0.1690892011013867
391.600000000005,126.56798453290831,0.039992417550684056,-0.17214985521709503
393.000000000005,127.03565853440075,0.03800126938886872,-0.17347015478492622
394.40000000000504,127.4902889723947,0.04776708634811189,-0.17345992042330582
395.80000000000507,127.95502022616952,0.0530576506584981,-0.17510981987556384
397.20000000000505,128.41496194523245,0.05310312415790497,-0.17643021398381542
398.6000000000051,128.8796635556338,0.05410785163995113,-0.1780800928566788
400.0000000000051,129.343080979745,0.05119451160657462,-0.17649937405320548
401.40000000000515,129.8068769937604,0.050106997255490615,-0.17896008524305085
402.8000000000052,130.26606482909733,0.04702632316166122,-0.17932554639574816
404.20000000000516,130.72655191014195,0.04921640976220987,-0.1832317172604192
405.6000000000052,131.18873304281865,0.04690646824851852,-0.18256982417327183
407.00000000000523,131.6494313593366,0.04560632222505756,-0.18455104980828718
408.4000000000052,132.1134835214817,0.04510614120614331,-0.18356246502806606
409.80000000000524,132.57784213270077,0.045051920686380864,-0.18620116285487054
411.2000000000053,133.0429016121735,0.04393593741615032,-0.18587001252577684
412.6000000000053,133.50401563822714,0.045668228398187516,-0.1845511464367351
414.00000000000534,133.96598865251474,0.04254903056009507,-0.18553943561440311
415.4000000000053,134.431008298358,0.042277188354718165,-0.18586991009964482
416.80000000000535,134.89283843913978,0.041261958118580466,-0.18751987999999242
418.2000000000054,135.3580385862296,0.039745457314883215,-0.18619988000001442
419.60000000000537,135.81360048223652,0.04418235747788324,-0.18685959105842365
421.0000000000054,136.28171346875956,0.039390306148954224,-0.18752017999048354
422.40000000000543,136.74575247711954,0.040997237826472466,-0.19014999154286816
423.80000000000547,137.21070539123437,0.04343285156136001,-0.18977562560436656
425.2000000000055,137.67290117681915,0.04334672084131075,-0.19015017501352016
426.6000000000055,138.13327688342443,0.0417307061227028,-0.1924891072204118
428.0000000000055,138.5996540225836,0.04091004166218459,-0.19312014711514447
429.40000000000555,139.06223423975953,0.04426706571922612,-0.192789890061265
430.8000000000055,139.53375940466793,0.04417328314096114,-0.19442953624006076
432.20000000000556,140.00101035424908,0.04399253034903583,-0.1923688277489881
433.6000000000056,140.46434774922696,0.04144098303820676,-0.19574996256037958
435.0000000000056,140.92686370557246,0.042580870640734236,-0.19542857089876842
436.40000000000566,141.39304624276224,0.04427297548991782,-0.1970676893773673
437.80000000000564,141.85970214826992,0.047585674575138404,-0.19643794013564708
439.2000000000057,142.32477291819117,0.04447883944474351,-0.1964213948577309
440.6000000000057,142.78625592732553,0.04546937533334461,-0.19739971155016
442.0000000000057,143.2524896706238,0.04436570189586386,-0.1995709966131174
443.4000000000057,143.72061493439003,0.04642239023347439,-0.2016800158058114
444.80000000000575,144.18492544592226,0.04287082778561091,-0.20037001252524744
446.2000000000058,144.65197333484605,0.04433050331812982,-0.20036995866382634
447.6000000000058,145.119647629368,0.0390428451071565,-0.2019888834096797
449.0000000000058,145.5856793773759,0.041723793100385764,-0.20125532235044563
450.40000000000583,146.04728732288015,0.037718936966266714,-0.20233982011024354
451.80000000000587,146.5129916618863,0.036488398681044254,-0.20405946821641274
453.20000000000584,146.97853246908187,0.03145087126378976,-0.2042101300003898
454.6000000000059,147.44109004238436,0.02517950139514391,-0.20454013012716787
456.0000000000059,147.90833009174725,0.021506406370978004,-0.20320989986835647
457.40000000000595,148.37826879351294,0.02035312494487629,-0.204524187313897
458.800000000006,148.84312639095504,0.02369008315910981,-0.20518616421725522
460.20000000000596,149.30310593730314,0.018866082466892475,-0.20481207134299728
461.600000000006,149.77302749883003,0.014105901053012238,-0.20715877046144016
463.000000000006,150.2355382282853,0.015910619750827193,-0.20618016999999966
464.400000000006,150.70326699743967,0.013018281077618044,-0.20716999000000014
465.80000000000604,151.16834589314135,0.008050936802115771,-0.2071699250106036
467.20000000000607,151.63749043728544,0.008366124865380575,-0.20983024269632455
468.6000000000061,152.1081052484836,0.00388896760880586,-0.2096290213575056
470.00000000000614,152.58000000000274,0.0035510133779286246,-0.20815981000000017
471.4000000000061,153.04620185985752,0.0017562041587400046,-0.20842649244072176
472.80000000000615,153.51221758734766,7.170250660437638e-05,-0.21211053651804068
474.2000000000062,153.97929738255095,0.002879222845982188,-0.21078993530010992
475.60000000000616,154.44497667661437,0.0016404972319901123,-0.20805012317498273
477.0000000000062,154.9126491465409,-0.0027228884645889018,-0.21140053703197248
478.40000000000623,155.37880140466268,-0.0007323504006053749,-0.21299078835003504
479.80000000000626,155.84917954220506,-0.0035324753461332126,-0.21101010513820473
481.2000000000063,156.31386728138446,-0.002566470392450393,-0.21298984914334795
482.6000000000063,156.78290661076036,0.001095729523077793,-0.21168263926995978
484.0000000000063,157.2494170367787,-0.00018276992550059212,-0.21364999979565136
485.40000000000634,157.71932128729264,0.002346636747538211,-0.21298986751038163
486.8000000000063,158.1809056882723,-0.0047405874273847015,-0.2133857914684376
488.20000000000636,158.65198595716316,0.0009254273902867816,-0.21330645829875072
489.6000000000064,159.12039000008068,0.0004537195449783038,-0.21331046462051617
491.0000000000064,159.58864355970098,-0.00021723559233777223,-0.21200017847901087
492.40000000000646,160.057352891248,-0.0003078024153295722,-0.2128782257108237
493.80000000000643,160.52566855891786,0.0005519286180901695,-0.2149600303273722
495.20000000000647,160.9943312865274,0.003295304233912333,-0.21429707042230906
496.6000000000065,161.46510769411617,-0.00035508207782486423,-0.2146402620210357
498.0000000000065,161.93334254070012,0.0028165736970136024,-0.21497020325074567
499.4000000000065,162.40177305837395,0.0009841158491004087,-0.2146399701477324
500.80000000000655,162.8657449714656,0.001530375348826496,-0.2146399674483761
502.2000000000066,163.33264515354276,8.264039081495866e-06,-0.2139798012296552
503.6000000000066,163.8035635552044,0.0012948060553061858,-0.21596010849698954
505.0000000000066,164.2724893576328,0.0027057208777199193,-0.2149855429263443
506.4000000000066,164.74055300772977,0.0018596888829511826,-0.21693981000119855
507.80000000000666,165.20521489960703,0.001542751726225422,-0.21630034814806498
509.20000000000664,165.67842885445452,0.005654529270541886,-0.21495982279891157
510.6000000000067,166.14670452568853,0.004722575046071764,-0.21857909893966587
512.0000000000067,166.61603619450133,0.007120309562905103,-0.21661018461517045
513.4000000000067,167.0822434269638,0.002034256836246584,-0.21694040893442912
514.8000000000068,167.55144402056948,0.001046738401162095,-0.21693985501517776
516.2000000000068,168.0184042281468,-0.0006360699882019816,-0.21693985554469997
517.6000000000067,168.4913287893412,0.0012332934054546385,-0.2166101824735973
519.0000000000068,168.96630063142032,0.0023749968559103607,-0.21730445387024844
520.4000000000068,169.43414274174356,0.0023719629192981984,-0.21826008000545816
521.8000000000068,169.90477933863485,0.00305400021453206,-0.21775536887037816
523.2000000000069,170.37275943946787,0.002462593353039999,-0.21925167739180162
524.600000000007,170.84201855057617,0.006166538517414999,-0.21825888799726112
526.0000000000069,171.30868567556308,0.0035267099143752034,-0.21695043889425403
527.4000000000069,171.7731937321212,0.0025108638745150458,-0.21891014999999303
528.800000000007,172.24457814382941,-0.0006014616747673784,-0.22056014951272473
530.200000000007,172.70319621201836,0.0008112079072337686,-0.2192385743505727
531.600000000007,173.18203953175924,-0.0014191956711053777,-0.21974764333504915
533.000000000007,173.65332228783348,-0.0038430657140877678,-0.22254304283490445
534.400000000007,174.12434652317677,-0.0021914341437283547,-0.22121994000736978
535.800000000007,174.59055128999069,-0.0027316598923605717,-0.22055548030015037
537.2000000000071,175.0672471120964,-0.0031306836439668473,-0.2217345155547652
538.6000000000071,175.53463386966013,-0.0032385233563854143,-0.2215499372336187
540.000000000007,176.00553092014349,-0.0007428085244316485,-0.22154978911523804
541.4000000000071,176.4754135181598,-0.0022880927269923745,-0.22221706243779682
542.8000000000071,176.94957737385292,-0.002962697093583433,-0.22122193043486105
544.2000000000071,177.41550734676687,-0.002054778495695686,-0.22318460353131453
545.6000000000072,177.89071809604548,-0.0007652633543187015,-0.22286993845172187
547.0000000000073,178.31617492279244,-0.0059023681769554415,-0.22320001540043943
548.4000000000073,178.83280580195438,0.0006407008583675378,-0.22188001000000002
549.8000000000072,179.2984718003605,0.0014906573186515004,-0.2222100099018851
551.2000000000073,179.76212985857202,-0.0005198079461292693,-0.22351291084604297
552.6000000000073,180.23113932319865,0.0014441888914733525,-0.22253123956994791
554.0000000000073,180.70476870232133,-0.001543862688481834,-0.22385431780994747
555.4000000000074,181.17704930962537,0.004323454390872783,-0.22353613335591227
556.8000000000073,181.65304724120813,0.0020421106077419537,-0.22484974813058267
558.2000000000073,182.12283060182787,0.0028753246739259275,-0.22352017782293254
559.6000000000074,182.60476072592638,0.007851725674778098,-0.22583997703249414
561.0000000000074,183.07382824387662,0.0067632209420960265,-0.22584002499999967
562.4000000000074,183.54561687369576,0.00201372502965258,-0.22584002499365363
563.8000000000075,184.0149396734609,0.006126930373935746,-0.2261601357759231
565.2000000000074,184.47570268891602,0.0017628324970706544,-0.2274722118599266
566.6000000000075,184.95107075219178,0.004502706913175558,-0.22879046206380416
568.0000000000075,185.4144512542843,-0.0011586872356348366,-0.2251720342497694
569.4000000000075,185.8939769091055,0.004372238342463586,-0.22748016995442244
570.8000000000076,186.36936101265454,0.0031835039484180427,-0.2278098399927413
572.2000000000075,186.84600922571096,0.007427255957939138,-0.22859089895501405
573.6000000000076,187.3132623462869,0.029585475682376572,-0.22813752438946278
575.0000000000076,187.77896431325908,0.005480015152450779,-0.2294601400180296
576.4000000000076,188.25719140157932,0.004314803044005444,-0.23176005528651933
577.8000000000077,188.73000340551675,0.003786272824018777,-0.2304303632588196
579.2000000000077,189.2067791948683,-0.00040922762887918296,-0.23239463198320243
580.6000000000076,189.67977978608457,0.00031152329302974735,-0.2337346604837771
582.0000000000077,190.14829821202756,-7.720887546946997e-05,-0.23238306823327148
583.4000000000077,190.61374622370658,0.0003827120529513728,-0.2343999326769617
584.8000000000077,191.0896707826976,-0.0018803656427022197,-0.23497453811110525
586.2000000000078,191.5696411676523,0.0011574298832703889,-0.23636984498356872
587.6000000000078,192.04193445048622,0.001996858981553551,-0.23634659477945696
589.0000000000078,192.51758360405466,0.005912922397864673,-0.23899485893526506
590.4000000000078,192.9882000011389,0.014718976035795972,-0.2376855285991879
591.8000000000078,193.46555684202409,0.01087503024381098,-0.2396599646477151
593.2000000000079,193.93750360071027,0.0120240087346839,-0.2386764718287857
594.6000000000079,194.4111479985148,0.008698778503566817,-0.2435259359409674
596.000000000008,194.88451223357967,0.014590176182244896,-0.246601368287084
597.4000000000079,195.35911772181584,0.016642610190492402,-0.2439400539671066
598.8000000000079,195.83113927157524,0.020985623354413452,-0.2455901201542976
600.200000000008,196.30571887790234,0.026064641397762767,-0.2472378639417232
601.600000000008,196.78164608842576,0.028375126604371026,-0.250859902546515
603.000000000008,197.25502122851032,0.034644492539010585,-0.2505299787010635
604.400000000008,197.72824647080304,0.04280269886088961,-0.2525221401288862
605.800000000008,198.20094434915381,0.045054099497270794,-0.252509870104062
607.200000000008,198.67891919382106,0.05312013549114347,-0.2554780378751689
608.6000000000081,199.15384907712448,0.056685885782144396,-0.25924949509933226
610.0000000000081,199.62721089247728,0.05697707691952614,-0.2607496308497863
611.4000000000082,200.0961295274651,0.060329777852294875,-0.26370993579671653
612.8000000000081,200.56496562403052,0.0622615135741329,-0.2650275015047452
614.2000000000081,201.03920533996362,0.06852819626101292,-0.2679903511052699
615.6000000000082,201.51517506628826,0.07576355947091074,-0.2703000500251047
617.0000000000082,201.9892580442521,0.07996597759118629,-0.2729301093495402
618.4000000000083,202.46683394384317,0.08922902054127402,-0.27820003559719897
619.8000000000083,202.93882854947242,0.09672149324472468,-0.2794862565459715
621.2000000000082,203.40900280711574,0.10349711576114817,-0.28478793174879646
622.6000000000083,203.8881540575821,0.11058732339762356,-0.28907008604133955
624.0000000000083,204.35915804760285,0.11610655944248816,-0.29105143754172325
625.4000000000083,204.83353659919698,0.1250193372015831,-0.29633979950500144
626.8000000000084,205.30635386163172,0.13499064663138638,-0.3015797385829475
628.2000000000083,205.78240071146854,0.14225987300513854,-0.30817027964425225
629.6000000000083,206.25583548648842,0.153144273058484,-0.3114291715500519
631.0000000000084,206.73034369361173,0.1907900311846955,-0.31743600891283874
632.4000000000084,207.2034429477256,0.22449712576006142,-0.32134169263216306
633.8000000000085,207.66937379063245,0.23602824331061178,-0.3279298960130652
635.2000000000085,208.15471767254078,0.24499019472125472,-0.3327868400380871
636.6000000000084,208.6272963948435,0.25195355364583394,-0.33928753164479986
638.0000000000085,209.1016566512404,0.26860406067455855,-0.3461126485166939
639.4000000000085,209.57647381190267,0.27339344658943165,-0.3546985378281251
640.8000000000086,210.05284020779894,0.287514142541474,-0.36338345827265117
642.2000000000086,210.5289244100841,0.2987276821119602,-0.3701270478018679
643.6000000000085,211.00800685874168,0.311819014396582,-0.3777925208511186
645.0000000000086,211.48678394288316,0.3228461379884515,-0.38897074402146714
646.4000000000086,211.96210126883162,0.3334661745831671,-0.3976544205055781
647.8000000000086,212.43582145301923,0.34799492032659574,-0.40554367412206327
649.2000000000087,212.91596290970278,0.359818479491973,-0.41812955669656615
650.6000000000087,213.38772037408287,0.37854806321012635,-0.4276154855304122
652.0000000000086,213.86438428522263,0.3918890170052589,-0.43862720324870175
653.4000000000087,214.34282525026902,0.410898622101846,-0.4511869962216055
654.8000000000087,214.81914110927488,0.4264651203236678,-0.46231015279151455
656.2000000000088,215.295157817841,0.4450972832953206,-0.4742911243669057
657.6000000000088,215.77127946541535,0.45531847528377867,-0.48857245101641533
659.0000000000088,216.2455929683829,0.47765810348744653,-0.5008281254248041
660.4000000000088,216.72351187659564,0.4906984220339976,-0.5145270627996972
661.8000000000088,217.19789604804953,0.5105062858675051,-0.5296502616425864
663.2000000000089,217.67617301302735,0.5314475151346545,-0.5437699044512012
664.6000000000089,218.16378353418457,0.5561561932215935,-0.5604023123096753
666.0000000000089,218.64619266489717,0.5714101615105398,-0.5773766603317596
667.400000000009,219.1217712680927,0.5846959364717188,-0.5942025750741737
668.8000000000089,219.59694108972312,0.6070465628398214,-0.611951264329833
670.2000000000089,220.0668707745449,0.6220035390075447,-0.6320928873031617
671.600000000009,220.5437106030565,0.645489840897425,-0.6490078942124091
673.000000000009,221.01781363444343,0.6632934802345227,-0.6670613975775406
674.400000000009,221.50352707595903,0.6899621790899695,-0.687342703494187
675.800000000009,221.9803691440253,0.7102229099645707,-0.7087828033774013
677.200000000009,222.4613251120891,0.7302793188891035,-0.7326675802041351
678.6000000000091,222.93429836313314,0.755024397524013,-0.7529181577662496
680.0000000000091,223.41128070898722,0.7747888203786948,-0.7759553726736841
681.4000000000091,223.88860062300168,0.7918997087360684,-0.8003052364380645
682.8000000000092,224.36613208611257,0.8106644972976236,-0.8250396368342834
684.2000000000091,224.84633411112569,0.8316052971409671,-0.8501090477226505
685.6000000000092,225.32571459077465,0.8533802764148581,-0.8748050408235906
687.0000000000092,225.80354241025685,0.8660672365617996,-0.9000415276983658
688.4000000000092,226.281524249527,0.881339399615308,-0.9295150493297184
689.8000000000093,226.7486234473437,0.892191339888472,-0.9567858210675175
691.2000000000093,227.2282954882735,0.9015184855589236,-0.9837348671294555
692.6000000000092,227.70579091991144,0.9101179626082314,-1.0110428318510167
694.0000000000093,228.18386026720333,0.9076492342147886,-1.037591844143316
695.4000000000093,228.6573281045927,0.9013500741231653,-1.0659787493674595
696.8000000000093,229.13282793884483,0.8856487088020737,-1.094301025763377
698.2000000000094,229.60442098219306,0.8565135259545946,-1.1218256581324915
699.6000000000093,230.08047781965354,0.8146538501277445,-1.1469181197036673
701.0000000000094,230.54708643348462,0.7559083361162222,-1.1692885855633826
702.4000000000094,231.00915588843193,0.6682913302216265,-1.1916562356849139
703.8000000000094,231.47640586058432,0.5508058010727814,-1.208695923930403
705.2000000000095,231.94439740169003,0.40037162100781565,-1.226187267992454
706.6000000000095,232.40735757500806,0.25403957290707835,-1.2347946657596376
708.0000000000095,232.87809636400476,0.15134052265004216,-1.2390211247652831
709.4000000000095,233.3528176383902,0.09096007671767437,-1.244299758267235
710.8000000000095,233.8248956369563,0.05279823179800802,-1.2462466041102442
712.2000000000096,234.30298519836919,0.02373097352210518,-1.246255660619454
713.6000000000096,234.77811068033918,0.018233160562078243,-1.2479205245890896
715.0000000000095,235.26166219283695,0.011554639072708817,-1.2476303598656013
716.4000000000096,235.74218090325581,0.00531855692269767,-1.2479307996737234
717.8000000000096,236.21069393154002,0.010147866002078398,-1.2479231645067919
719.2000000000096,236.68656628957555,0.008037050325933937,-1.2485796427589624
720.6000000000097,237.16650719035283,0.00027088616011639033,-1.2472598600000007
722.0000000000097,237.6415858455439,0.0037704716051969456,-1.24857985945973
723.4000000000098,238.1162505545659,0.005128142642659483,-1.2505335087666096
724.8000000000097,238.59076270964306,0.0069006090766343675,-1.250549885000383
726.2000000000097,239.07043252130208,-0.0017896203192329097,-1.2472681790085227
727.6000000000098,239.55408344374058,-0.0003005649692302548,-1.2509181234661981
729.0000000000098,240.0266819511117,0.0008994274348772535,-1.2495601869076123
730.4000000000099,240.4903921939004,-0.007640223040742633,-1.250215020814606
731.8000000000098,240.96698484661334,-0.005784741277500505,-1.2507464020619632
733.2000000000098,241.44999505573475,-0.003903090230259476,-1.2498900909606743
734.6000000000099,241.92950236431184,-0.0038910738387372135,-1.2512888207221442
736.0000000000099,242.4077374935461,1.6182241995732483e-05,-1.2498899788300264
737.4000000000099,242.88588170847356,0.002897972783781899,-1.2492311730901355
738.80000000001,243.3650295828884,0.005301748696322051,-1.2495593456434135
740.2000000000099,243.83418175574704,0.0024422364557659115,-1.2495599304011877
741.6000000000099,244.3165278411282,-0.003868176452667349,-1.2495595309283334
743.00000000001,244.7940572465077,0.001191824594931834,-1.2495896460508904
744.40000000001,245.27153768623413,-0.0005781506019677529,-1.2498899299999997
745.8000000000101,245.7438719291069,-0.0014915757171660715,-1.2485743117571109
747.20000000001,246.22199246670104,-0.006137789576341035,-1.2482499306978014
748.60000000001,246.69774509856336,-0.0002385413683172466,-1.2508599734615395
750.0000000000101,247.1800000000034,0.003489260233273672,-1.2512110858986807
751.4000000000101,247.66429516016882,0.004147282999050539,-1.250895436450191
752.8000000000102,248.14270649156333,0.0021253186987362227,-1.2515398276636538
754.2000000000102,248.62275651101663,-0.004436298843231601,-1.2504489054655155
755.6000000000101,249.09348786112918,-0.012022240264532247,-1.2515399001223497
757.0000000000102,249.56688460282615,-0.010760197942599081,-1.2515399005778702
758.4000000000102,250.04671172744347,-0.04201311516175821,-1.2512101251028391
759.8000000000102,250.52664900956862,-0.07369469870420353,-1.2508901249999012
761.2000000000103,251.00576596703223,-0.06494595505400502,-1.250890226679107
762.6000000000103,251.4818228524959,-0.06213343748923883,-1.2504589748913335
764.0000000000102,251.96134598864685,-0.059289706281482335,-1.250561973905039
765.4000000000103,252.44079394537349,-0.06030850545176447,-1.2525478095264249
766.8000000000103,252.91827100068923,-0.05787259068485007,-1.2512807202908567
768.2000000000104,253.39497700519183,-0.05511095623261575,-1.2525200904558158
769.6000000000104,253.87710071162067,-0.05358305314516354,-1.2521894343454947
771.0000000000103,254.3533948156473,-0.05981685618309118,-1.2498930770678016
772.4000000000104,254.82341748643762,-0.059743091582498575,-1.2521999752398751
773.8000000000104,255.30434813422116,-0.05896620158834143,-1.2502198411490566
775.2000000000105,255.78195398215829,-0.06294560321687914,-1.2518700449863647
776.6000000000105,256.2678830920554,-0.06653163722474398,-1.2518700450000018
778.0000000000105,256.74779761699943,-0.06767396597282671,-1.2511765513514135
779.4000000000106,257.22908541499567,-0.07102691577836051,-1.2522002017693574
780.8000000000105,257.7008569700258,-0.06902082512978147,-1.2515399390635578
782.2000000000105,258.18512349482785,-0.07070414848161288,-1.2519025747905528
783.6000000000106,258.66533246699316,-0.08116403762067703,-1.2495561838113023
785.0000000000106,259.14598130616696,-0.08154345511060423,-1.2504782757919446
786.4000000000106,259.61955014452667,-0.07913844751896715,-1.2521988747717447
787.8000000000106,260.09921283430475,-0.0765036098717995,-1.251871241077514
789.2000000000106,260.5782238571686,-0.07839884744562342,-1.2538507756270945
790.6000000000107,261.056572599717,-0.07727232019460795,-1.2511428304511267
792.0000000000107,261.5304066696355,-0.07681858301030431,-1.2525195997092284
793.4000000000107,262.01307479760044,-0.07716721698029749,-1.254839794860155
794.8000000000108,262.4910035360682,-0.08316393996809834,-1.2512101667342042
796.2000000000107,262.9743103587386,-0.08985776064082529,-1.253189834914215
797.6000000000108,263.4549210754039,-0.08693373484667699,-1.252199910002361
799.0000000000108,263.934956894879,-0.07969500710888777,-1.2548198678191675
800.4000000000108,264.4146793486062,-0.07674577612437616,-1.2538400851743878
801.8000000000109,264.89186172001723,-0.07348917808877298,-1.2548721675349395
803.2000000000108,265.3673603117767,-0.07155820804075264,-1.2535204607514245
804.6000000000108,265.84528215737447,-0.07717244444683047,-1.255159905775713
806.0000000000109,266.32065148027107,-0.0796153981812262,-1.2535131229309129
807.4000000000109,266.8012171422409,-0.08000783634007247,-1.253509832530018
808.8000000000109,267.2848587648353,-0.07905206437393675,-1.252860642792546
810.200000000011,267.7683296589993,-0.0756046385597755,-1.2548331269048791
811.6000000000109,268.24396768498406,-0.07088685530154226,-1.2522001363504498
813.000000000011,268.7183085630286,-0.06757787296529383,-1.25385012994824
814.400000000011,269.19999170712634,-0.0656514195567075,-1.2525304306264986
815.800000000011,269.681688764342,-0.0654582738250058,-1.2505341611492868
817.2000000000111,270.159107141487,-0.06573128459841904,-1.2531899500073211
818.600000000011,270.6416324970068,-0.06095759369146325,-1.2534488831039767
820.0000000000111,271.1182282541198,-0.06504028050294108,-1.2535198742964981
821.4000000000111,271.5972226276881,-0.06752848026645575,-1.2535202016916944
822.8000000000111,272.081559585064,-0.0680916869543231,-1.2521989981067159
824.2000000000112,272.55508202503296,-0.07342522104927651,-1.2538402174579502
825.6000000000112,273.0316777353671,-0.0737392791806668,-1.254499954823455
827.0000000000111,273.51205867956185,-0.0717294458401776,-1.2554900195385321
828.4000000000112,273.99646694996363,-0.06323662453286882,-1.2554896272083726
829.8000000000112,274.4741424420013,-0.06445186025663441,-1.2534801003798735
831.2000000000112,274.9554217121977,-0.06521557689806334,-1.2542800347989589
832.6000000000113,275.43349455252513,-0.05921367798768129,-1.251896926951011
834.0000000000113,275.9100000000041,-0.07012071094240735,-1.253620169991129
835.4000000000113,276.39570507664865,-0.06844441228942699,-1.2545302431591399
836.8000000000113,276.87679940440603,-0.0683107106032117,-1.2545100619565677
838.2000000000113,277.3514456421008,-0.06879531432972774,-1.2548823811013792
839.6000000000114,277.83224720834284,-0.06774765620576861,-1.2521972183882082
841.0000000000114,278.31393259782,-0.06863230256062502,-1.253520065003241
842.4000000000115,278.78721039792083,-0.06366614208558907,-1.252200067277339
843.8000000000114,279.2563886493076,-0.06275019066297904,-1.2528987146308013
845.2000000000114,279.7479431140418,-0.06052388832203448,-1.2552606566588933
846.6000000000115,280.2275941958558,-0.058541079970697574,-1.2531482486189036
848.0000000000115,280.7110881278986,-0.05742075698732396,-1.2538399850000141
849.4000000000115,281.1905220661643,-0.05515409385600201,-1.2541743841254727
850.8000000000116,281.66438242889865,-0.05434133182818268,-1.254168794533205
852.2000000000115,282.1399963826745,-0.05022092560218905,-1.2515248260424041
853.6000000000115,282.61670445789554,-0.04456201654394576,-1.2535098098832749
855.0000000000116,283.0956699478504,-0.04032893215704503,-1.2538518008756938
856.4000000000116,283.58146708163514,-0.03925780694563841,-1.2544971642565153
857.8000000000117,284.0600031136299,-0.03880778872813728,-1.2541699550355645
859.2000000000116,284.530944672339,-0.04812257430450728,-1.2538503239652732
860.6000000000116,285.015292724331,-0.04600841141314849,-1.2558199246745847
862.0000000000117,285.495853418153,-0.04813378015170766,-1.2548402446174332
863.4000000000117,285.98172122366,-0.048359840313036084,-1.2554495792880873
864.8000000000118,286.4500007388645,-0.046875927396601735,-1.2554899249980371
866.2000000000118,286.93633513151735,-0.045174852772122076,-1.2548400742367263
867.6000000000117,287.4172941154612,-0.041334565055468175,-1.2554999297076987
869.0000000000118,287.89606578943204,-0.05063000717523325,-1.25417982
870.4000000000118,288.3803209248764,-0.04526800270191611,-1.2531898199326492
871.8000000000118,288.86041674861235,-0.04621667792714268,-1.256809937057143
873.2000000000119,289.3397007732681,-0.043724446815395446,-1.254155242371025
874.6000000000118,289.81728036939523,-0.04317679724297241,-1.255489844977336
876.0000000000118,290.27193043407743,-0.04820965199092431,-1.254499844867111
877.4000000000119,290.77882366794734,-0.04164447556996853,-1.2564475829016963
878.8000000000119,291.25518952157614,-0.04595557100460601,-1.255489305337223
880.200000000012,291.7359116853509,-0.049439294344242324,-1.2571408049446933
881.600000000012,292.2113119396764,-0.043509741530539436,-1.2558165369450438
883.0000000000119,292.6869539500661,-0.04206144803093981,-1.2558198366071474
884.400000000012,293.1593107432599,-0.041952634635623376,-1.2554900404380174
885.800000000012,293.6494593924275,-0.037242433253090734,-1.257126391756791
887.2000000000121,294.1330996258602,-0.03681965215063299,-1.256480114990401
888.6000000000121,294.6112362302558,-0.041876552504342524,-1.2558201147748616
890.000000000012,295.0943932423473,-0.04020612542066493,-1.2568263073394723
891.4000000000121,295.57113593196823,-0.0362838137954431,-1.2577900350359812
892.8000000000121,296.05034065249555,-0.038098821009535655,-1.2555997028832029
894.0000000000122,296.4615775732136,-0.03579900331931185,-1.255164203974041