File: 01_Data/Vinyl_Tile/STA/N2/10K_min/Vinyl_Tile_STA_N2_10KData_220505_R2.csv
##Temp./Â°C,Time/min,DSC/(mW/mg),Mass loss/mg
50.0,10.4777939392758,-0.00548265069245546,-0.022711530521998036
51.100000000000016,10.939682068815712,0.043830739394387974,-0.021489450531963605
52.20000000000003,11.176024764721438,0.07490496993079132,-0.021361421521951307
53.30000000000005,11.363412037365045,0.09275057998133995,-0.02158923109419497
54.40000000000006,11.526116892119626,0.11222408595313949,-0.020420417213514952
55.50000000000008,11.677236429856853,0.12621842162052965,-0.022145783115706585
56.600000000000094,11.817288403234581,0.13478117904138354,-0.022233015694574476
57.70000000000011,11.950485608107508,0.144308454104781,-0.02122893992937236
58.800000000000125,12.082054585603787,0.151854685748414,-0.02180049280685825
59.90000000000014,12.209066422271725,0.1560661997879933,-0.021231889597090436
61.000000000000156,12.334272909479068,0.16265948062945912,-0.021143412725057154
62.10000000000017,12.457585370914819,0.16400819491915575,-0.02112367518645275
63.20000000000019,12.579798378808087,0.16991774595380482,-0.02115421830614217
64.30000000000021,12.699475514610182,0.16891150838895297,-0.021184642145656518
65.40000000000022,12.820660698709355,0.1710114948692144,-0.02117638760076357
66.50000000000023,12.940000000000023,0.1745069990708329,-0.021169817584834938
67.60000000000025,13.057838153676856,0.17724681230523942,-0.021360274494965914
68.70000000000027,13.174369431309913,0.17499076117432721,-0.02252601379503183
69.80000000000028,13.29219599751454,0.1759082921200813,-0.022476095066148893
70.90000000000029,13.412073488009412,0.17878770545430311,-0.022476368006575598
72.00000000000031,13.529145031629659,0.18177669552366515,-0.022997848353913497
73.10000000000034,13.644433926083751,0.18351480135409037,-0.023840640848960426
74.20000000000034,13.761014647678156,0.18615661064372013,-0.022426491218942246
75.30000000000035,13.875284681942144,0.1843482312246294,-0.022439068311014942
76.40000000000038,13.991265054139154,0.18762760361573982,-0.023837701622842822
77.5000000000004,14.09910458055805,0.188618063633885,-0.023630425437857205
78.6000000000004,14.218549127753622,0.19193560884240168,-0.025119613766833027
79.70000000000041,14.334143605778094,0.19463953251664834,-0.023810757735619248
80.80000000000044,14.446159786704388,0.19391919985387895,-0.025127604684318072
81.90000000000046,14.558464261686916,0.19712355891122568,-0.025117405596430054
83.00000000000047,14.670782048310269,0.19916631824099051,-0.02511624974712845
84.10000000000048,14.782800724954337,0.20141513199280736,-0.025128578644567412
85.2000000000005,14.894555189941922,0.2010356245493592,-0.02484140831752235
86.30000000000052,15.00683783584571,0.20520212485123146,-0.025120030555221717
87.40000000000053,15.116641964434331,0.2040577459465568,-0.0251200732009087
88.50000000000054,15.227880519402202,0.20456534963951878,-0.02684966258977539
89.60000000000056,15.339175640804333,0.20703272676444284,-0.02643948394049822
90.70000000000059,15.448086664632669,0.2079324537796674,-0.02780780788166748
91.8000000000006,15.559682729864956,0.20686083832679225,-0.027798737042551203
92.9000000000006,15.66921456741934,0.20923626434029996,-0.026453658375253042
94.00000000000063,15.779364903680746,0.20984684367058204,-0.02774989835160291
95.10000000000065,15.887438256817063,0.2094218890520545,-0.027106368318207785
96.20000000000066,15.996746681933782,0.21264679264962605,-0.027747816115925694
97.30000000000067,16.105837486818388,0.21277004349580697,-0.0270898913518538
98.40000000000069,16.21383581268597,0.21404204099905233,-0.027147357955726648
99.50000000000071,16.32332850152437,0.21571817519876274,-0.027432643966746717
100.60000000000072,16.432401757238384,0.21749915674057102,-0.026809618247034983
101.70000000000073,16.540565924995104,0.21691688551039368,-0.026439508561841407
102.80000000000075,16.648167749718553,0.2172594686668357,-0.027751266618543546
103.90000000000077,16.75734843641002,0.21873177408885996,-0.02863490779899802
105.00000000000078,16.863502270239476,0.222687466153218,-0.027761432395839947
106.10000000000079,16.973495450655243,0.2206677816226536,-0.02774848555582654
107.20000000000081,17.0812480928453,0.2211905235400901,-0.028080217442520095
108.30000000000084,17.188880609071887,0.22271140018333752,-0.028079914528752248
109.40000000000084,17.29609914311782,0.22463324146783697,-0.02939021301652378
110.50000000000085,17.403588673943066,0.22672913491107916,-0.029792366560543293
111.60000000000088,17.51129693898585,0.227283599556016,-0.029069823759093616
112.7000000000009,17.618957571599243,0.23016333654044435,-0.03040261756675333
113.8000000000009,17.726835413398206,0.23059429501672085,-0.029722349630626255
114.90000000000092,17.834612578325185,0.23071111465078709,-0.029175497665528738
116.00000000000094,17.940581077608186,0.2297320951443783,-0.028737948413692038
117.10000000000096,18.04920380260781,0.23130015207060733,-0.029126505216349408
118.20000000000097,18.15647962219341,0.23350006207326335,-0.030389860357463938
119.30000000000098,18.26345089611952,0.23513121964555728,-0.030752300815288347
120.400000000001,18.37183158224962,0.23744161238018197,-0.030390034940716237
121.50000000000102,18.47812796400656,0.233838950588188,-0.03038997160803536
122.60000000000103,18.584970269978548,0.23654617063803668,-0.031570379896869394
123.70000000000104,18.692460438775402,0.23849290611408624,-0.031143539829285416
124.80000000000106,18.799686398835515,0.23668674003406903,-0.030390057035568407
125.90000000000109,18.906279305397106,0.23649830444655517,-0.03039005701280706
127.0000000000011,19.012063317503205,0.237242155263376,-0.030375080660287157
128.1000000000011,19.119699935393236,0.2372217169791847,-0.0303806032651881
129.20000000000113,19.226317622479296,0.23669130697584617,-0.0316998537641382
130.30000000000115,19.3328810896862,0.2391157285555086,-0.03269065578915509
131.40000000000117,19.44000097203038,0.23924840350294801,-0.03137001070838741
132.50000000000117,19.54667481112898,0.23723189611338907,-0.031370051783115915
133.6000000000012,19.652752266722853,0.24055401622371225,-0.030339101144568836
134.7000000000012,19.76039968556189,0.24022428339789498,-0.03169985759091709
135.8000000000012,19.864997574359705,0.24151830924910134,-0.03169704412686514
136.90000000000123,19.97326516287283,0.24020414898880715,-0.03170007723301271
138.00000000000125,20.077382083837552,0.2424969961111299,-0.03170045120823861
139.10000000000127,20.18447741554141,0.24272803086520478,-0.032690192892272485
140.2000000000013,20.290493387819943,0.24388790553674466,-0.0340119241590604
141.3000000000013,20.396833827507358,0.24568261096858834,-0.03268999385319171
142.4000000000013,20.50341456951458,0.24403417755770257,-0.0330513936510517
143.50000000000134,20.609717056803696,0.24629535178899806,-0.033019875017082256
144.60000000000133,20.715491500520756,0.24881016476639478,-0.03287222837480064
145.70000000000135,20.821961258572802,0.2483966877648584,-0.034148081997243285
146.80000000000138,20.92652732102132,0.24952920504445156,-0.03367999134620625
147.9000000000014,21.032217059879315,0.24946038911053262,-0.03368333579528304
149.00000000000142,21.13916199752056,0.25076422806845866,-0.032675172277977005
150.10000000000142,21.242739216268482,0.25192650188749094,-0.034110672137868114
151.20000000000144,21.350189735387374,0.2524429546546959,-0.03531961624958191
152.30000000000146,21.456378529840084,0.25155166650299865,-0.03540508527606523
153.40000000000146,21.561625264727056,0.2520788914083013,-0.03531939287375341
154.50000000000148,21.666690755743353,0.25165527896190737,-0.03627184640031089
155.6000000000015,21.77288835590382,0.2534818469602553,-0.034990017933922424
156.70000000000152,21.87913127438704,0.2512368815011219,-0.03499001300000115
157.80000000000155,21.983918762767985,0.25266914022523435,-0.034990013011341414
158.90000000000154,22.09045905493988,0.25702089451870297,-0.034991048027971594
160.00000000000156,22.195270191135574,0.25676699867884584,-0.035322774832105
161.1000000000016,22.301833717995194,0.25507150490389585,-0.0353198918891251
162.20000000000158,22.40652246827302,0.25493908189171993,-0.0353201883407972
163.3000000000016,22.51149029427163,0.2572884236742888,-0.03615748396814622
164.40000000000163,22.617105248919664,0.25636765609166856,-0.03664018773150213
165.50000000000165,22.722604395732418,0.2570502167144181,-0.03664018395868185
166.60000000000167,22.82849035411198,0.2579273230902668,-0.03794158625148647
167.70000000000167,22.933355226816435,0.2600575883290155,-0.03794639695504953
168.8000000000017,23.038879611052266,0.2613005954180499,-0.03665438603785631
169.9000000000017,23.144310102173826,0.2615786801398523,-0.03763003315868341
171.0000000000017,23.249690076175344,0.2612073503098102,-0.037630652173817225
172.10000000000173,23.35552018311004,0.26250593735565353,-0.03796005003985403
173.20000000000175,23.460179977847357,0.2638418768393839,-0.03780284712330717
174.30000000000177,23.565789035707052,0.2637373983808782,-0.03959147272519381
175.4000000000018,23.670677851237112,0.2633600131772665,-0.03858389731358791
176.5000000000018,23.77574857436784,0.2657862161212769,-0.038619579638910384
177.6000000000018,23.88143418503302,0.26748405024119637,-0.03992992162628184
178.70000000000184,23.98519519714767,0.26868628312268156,-0.03993154505043828
179.80000000000183,24.09243803235212,0.26737297642650026,-0.038617609037643774
180.90000000000185,24.196386036771102,0.268482033199509,-0.03861009588908537
182.00000000000188,24.300853584868456,0.267354282233183,-0.03904089910874298
183.1000000000019,24.40656671462448,0.26746948400522713,-0.04124992077298062
184.20000000000192,24.510787182566542,0.2688489431097378,-0.04124992100184821
185.30000000000192,24.61589044730584,0.26921172448318875,-0.04125649637198059
186.40000000000194,24.721967312670333,0.26860242913043403,-0.03993009691134164
187.50000000000196,24.826076281075476,0.26897668219480286,-0.04263966337165259
188.60000000000196,24.932050548098655,0.2704306377475752,-0.042544232598758835
189.70000000000198,25.03369256260164,0.2681088651366545,-0.041282808734521836
190.800000000002,25.14215739320373,0.2709553478225017,-0.04387992384766104
191.90000000000202,25.2459026802557,0.2741503972643824,-0.04387992100000293
193.00000000000205,25.350739687331632,0.2732889494778878,-0.04387992099999316
194.10000000000204,25.456418682835995,0.2731761834356802,-0.04387993272462731
195.20000000000206,25.56074935675546,0.2733478408602726,-0.04520312679137417
196.3000000000021,25.66527328623319,0.27471050652958273,-0.04650090442916133
197.40000000000208,25.770558798332317,0.27406669062369343,-0.04617914684297997
198.5000000000021,25.875118797882575,0.2747188830765324,-0.046179324528694554
199.60000000000213,25.98057863677936,0.27466139734933354,-0.04749932092386455
200.70000000000215,26.08561059742372,0.27306971333650376,-0.04748936196589826
201.80000000000217,26.188678106943954,0.2771262970192255,-0.04880981865738043
202.90000000000217,26.294503541841852,0.2772136631227317,-0.04883611542273725
204.0000000000022,26.39958694800759,0.2804747552251256,-0.04979984299707363
205.1000000000022,26.504211317981397,0.28203333489404087,-0.05080868071389366
206.2000000000022,26.608209640205292,0.28014005870076913,-0.0507971992757037
207.30000000000223,26.713218700990208,0.2808899123911223,-0.051134386824618794
208.40000000000225,26.818375946571074,0.2810927373507726,-0.05244030821489476
209.50000000000227,26.922355978768934,0.2817234114167373,-0.0527589169223015
210.6000000000023,27.02762885245984,0.2808545363481856,-0.05538026652536976
211.7000000000023,27.13324361085234,0.2820822840346165,-0.055630263298376725
212.8000000000023,27.236818866551104,0.28379567529939265,-0.05670991872627473
213.90000000000234,27.34186391388016,0.2850015938295848,-0.05868049514929341
215.00000000000233,27.447232670012355,0.2871098316601446,-0.06004616967123022
216.10000000000235,27.552098221759547,0.28458973929143383,-0.06065950760507555
217.20000000000238,27.657222167382916,0.28567579920837977,-0.0619957923777239
218.3000000000024,27.762007378233083,0.28812061170707554,-0.06328986985666374
219.40000000000242,27.865848834408926,0.29128770131562465,-0.06597641297140999
220.50000000000242,27.97049315351987,0.29198416700678587,-0.0659298527397536
221.60000000000244,28.076025503915275,0.28905480941381195,-0.06854178577851933
222.70000000000246,28.181017534101045,0.29160441193199116,-0.06992925659338889
223.80000000000246,28.284232883539936,0.29466354039268794,-0.0712025087148831
224.90000000000248,28.390305116273243,0.2963894986551135,-0.0738187107794106
226.0000000000025,28.495435009976372,0.2964966406472103,-0.0751284613059946
227.10000000000252,28.600214257975797,0.2971750327582442,-0.07513873165155749
228.20000000000255,28.70491797725803,0.2994606790520808,-0.07907772188447382
229.30000000000254,28.809909554435976,0.30060475729121333,-0.08106032093438698
230.40000000000256,28.914690281238073,0.3038240655448448,-0.08344693374192991
231.5000000000026,29.01890900451556,0.30180896253810696,-0.08568194011271624
232.60000000000258,29.123085312513417,0.3042331917703273,-0.08828697670022878
233.7000000000026,29.22658662425084,0.30433239008063007,-0.09092002293141421
234.80000000000263,29.331557847708467,0.30629395488546973,-0.0935571234697874
235.90000000000265,29.436613930755907,0.30467926828201636,-0.09618301529904105
237.00000000000267,29.542989251340167,0.3072941967149576,-0.09829551181441243
238.10000000000267,29.64692414588945,0.3084546386162723,-0.10090445533509174
239.2000000000027,29.752636805071823,0.30887640429640373,-0.10497544271683434
240.3000000000027,29.85735986319467,0.3112605147387334,-0.10890747185604965
241.4000000000027,29.96223734536295,0.3114344543656289,-0.11023075435944918
242.50000000000273,30.067622237435426,0.31448894053050375,-0.11442097190281064
243.60000000000275,30.17294428680844,0.3132801804459167,-0.11886046958811303
244.70000000000277,30.277516681782604,0.31515858624746595,-0.12280364721350479
245.8000000000028,30.382469715783092,0.3177976452314281,-0.1270118504258826
246.9000000000028,30.487262126202666,0.32140739493974824,-0.13119536407990795
248.0000000000028,30.592080453265268,0.3223159368827835,-0.13557286454165451
249.10000000000284,30.69820639297339,0.3225396219584121,-0.13837262753451407
250.20000000000283,30.802465133410532,0.3224464876841411,-0.14158466059594543
251.30000000000285,30.907508191563878,0.3267534956225231,-0.14774419064620004
252.40000000000288,31.012293478586628,0.3291413236924675,-0.1544803596166764
253.5000000000029,31.11729477842542,0.3314144258919536,-0.15902245204516063
254.60000000000292,31.221885779705094,0.33230295388960623,-0.16337145174944157
255.70000000000292,31.32673619696688,0.33284039246471164,-0.16953568673793118
256.8000000000029,31.43160471999835,0.3322707919342753,-0.17455140230377797
257.90000000000293,31.53619215737478,0.3345071891126427,-0.18088050434726366
259.00000000000296,31.641620404656702,0.33250774682644646,-0.18555293012792218
260.100000000003,31.74511898094414,0.33465070760203497,-0.1940672572035309
261.200000000003,31.851395955365977,0.334312110446456,-0.20097659928680445
262.300000000003,31.957015727269543,0.33322999219367055,-0.20620485270029976
263.40000000000305,32.05990046143818,0.33215057956404825,-0.21508504161642472
264.50000000000307,32.16555923005179,0.3347383708751163,-0.22201668170448263
265.6000000000031,32.27181596421554,0.3331926208651159,-0.22883563556501452
266.7000000000031,32.375573404603415,0.333639177750868,-0.23710291808321093
267.8000000000031,32.48077864597386,0.3346389476981217,-0.24519534944571042
268.9000000000031,32.586518962845275,0.3338925187064927,-0.25395137044686367
270.0000000000031,32.691847026764854,0.3341873775455171,-0.2648276410418293
271.10000000000315,32.79588567876873,0.33362238517829573,-0.272685162113393
272.2000000000032,32.901303032026334,0.33162220754204014,-0.2834862659714905
273.30000000000314,33.006577112158226,0.3312218529358929,-0.2936649144795749
274.40000000000316,33.11205919271882,0.3344415029978948,-0.30381049157703055
275.5000000000032,33.21688824931575,0.33669043491496964,-0.31567697667391803
276.6000000000032,33.322419287614885,0.3419086206817753,-0.3294041784338564
277.70000000000323,33.42751955181332,0.3475062794888524,-0.34181517738591616
278.80000000000325,33.53265541517048,0.35597191839685627,-0.355761527571119
279.9000000000033,33.63849007058167,0.36463823097364273,-0.36893922698448245
281.0000000000033,33.74386696471904,0.3753672852465849,-0.3847848923318846
282.1000000000033,33.84883653019603,0.3873370387474706,-0.39904100650743546
283.20000000000334,33.95434437798824,0.40015497212584406,-0.41162300964581133
284.30000000000337,34.05990866604304,0.4096817604487111,-0.4277580888958772
285.40000000000333,34.16506923011734,0.4220774576683118,-0.4433207235173575
286.50000000000335,34.2702096003042,0.4312883175620995,-0.45885036422446523
287.6000000000034,34.376558644388766,0.4435952373824024,-0.47402111615177667
288.7000000000034,34.48173256802405,0.4511106907552793,-0.48765172108800225
289.8000000000034,34.58685214372692,0.45607225469903945,-0.5033341633651705
290.9000000000034,34.69236812390051,0.45905010964517456,-0.5168426951466909
292.0000000000034,34.79690881770083,0.4561798356339429,-0.529847480258963
293.10000000000343,34.90304913721531,0.4553774960502999,-0.5422989386567503
294.20000000000346,35.00806927075641,0.4530931195574334,-0.5554179454335677
295.3000000000035,35.11372862935243,0.444672781476736,-0.5665582437271168
296.4000000000035,35.218689935323866,0.43704710754526915,-0.5790963626149495
297.5000000000035,35.32484569577585,0.4259324208404331,-0.5873439165310952
298.60000000000355,35.42999899976144,0.4157690698030951,-0.5977328516619127
299.70000000000357,35.5351866129369,0.40454877370105485,-0.6054808874689184
300.8000000000036,35.641180867806824,0.3932492558307,-0.6140606746536283
301.9000000000036,35.74686952849137,0.3835239648901718,-0.6230756847713801
303.0000000000036,35.851637517553634,0.37169045969870657,-0.6305249769469059
304.1000000000036,35.957114671919534,0.36390547699429154,-0.6373029450169221
305.2000000000036,36.06235626806929,0.3558908590250458,-0.6443031119870315
306.30000000000365,36.16779305009254,0.34657040808411294,-0.6503722721017149
307.4000000000037,36.271782782008685,0.3375313560261392,-0.655227644653583
308.5000000000037,36.37758954173149,0.3312084039476455,-0.6605512510328082
309.60000000000366,36.48373895099935,0.32312139653883526,-0.6661521562805683
310.7000000000037,36.58782594133146,0.3155013053477245,-0.6701199974895369
311.8000000000037,36.693849059413054,0.307985636084283,-0.6748786517661935
312.90000000000373,36.79924891724291,0.30517784095081624,-0.6792932770970794
314.00000000000375,36.905250127999096,0.2993119911919584,-0.6826867085628892
315.1000000000038,37.01086758524097,0.2934847209333287,-0.6864855036699615
316.2000000000038,37.115024353474666,0.288328442796427,-0.6917806074161619
317.3000000000038,37.22082998283542,0.28662293045633236,-0.6958065131514455
318.40000000000384,37.32658684035001,0.2800712911315565,-0.6991957864330947
319.5000000000038,37.432673072254744,0.2713925756206714,-0.7004637559532303
320.60000000000383,37.537738334197584,0.26983488450568527,-0.7057768552865711
321.70000000000385,37.64385893920995,0.26729240753132344,-0.7086793372389466
322.8000000000039,37.74964003660279,0.261147965225207,-0.7099996269677602
323.9000000000039,37.85482880231469,0.25948047137432856,-0.7139211351824146
325.0000000000039,37.96110740531876,0.25623748331710366,-0.714358509129513
326.10000000000394,38.0671423904804,0.2536991460777146,-0.7194108015920242
327.2000000000039,38.17307585415066,0.24667878321133346,-0.7217677712625279
328.30000000000393,38.278155310723726,0.24653188424161016,-0.7248084041696816
329.40000000000396,38.3847366856487,0.24410200016996958,-0.726064361810538
330.500000000004,38.49030049982004,0.24050836889684366,-0.728749392981082
331.600000000004,38.59524675203106,0.23864810724730234,-0.7300599300825437
332.700000000004,38.70138579689676,0.23428885833270666,-0.7326977245061168
333.80000000000405,38.80843670890606,0.2340426290300345,-0.7340186455043702
334.90000000000407,38.91368550668502,0.23088015625393693,-0.7362870556175647
336.0000000000041,39.01961068859354,0.2272661285278661,-0.737970119852978
337.10000000000406,39.12521924622226,0.22621992158659343,-0.7392736402625455
338.2000000000041,39.231347021527874,0.22509611643967417,-0.7406148787110007
339.3000000000041,39.337461047915426,0.22169354669332933,-0.7435829900719115
340.4000000000041,39.443395141774715,0.22094037247204923,-0.7435302871427911
341.50000000000415,39.549082824959854,0.21893016928892517,-0.7461821825798842
342.6000000000042,39.655852924695665,0.2202817437448569,-0.7461899146017084
343.7000000000042,39.761681527107754,0.2164375040619055,-0.7468499042342027
344.80000000000416,39.867208929539835,0.21525875208151737,-0.748170544823691
345.9000000000042,39.972745344862716,0.21451619980471232,-0.7494797888929954
347.0000000000042,40.079899416278806,0.21238918118996783,-0.7494794500345359
348.10000000000423,40.186806127825264,0.2104264899838461,-0.7511200648070653
349.20000000000425,40.29123779712163,0.21371055664069005,-0.752785958290831
350.3000000000043,40.39963665493842,0.21128178782756152,-0.7540900742192074
351.4000000000043,40.504072606295104,0.21156907806796899,-0.7540900468894418
352.5000000000043,40.610880602787105,0.2118403795424563,-0.7554100219855577
353.60000000000434,40.71793008979913,0.21097313897193876,-0.755409906956277
354.7000000000043,40.824362426780546,0.2116631881606284,-0.7567267180218575
355.80000000000433,40.930576402241925,0.21305034276454246,-0.7580578217444707
356.90000000000435,41.037748479454976,0.21005160000524353,-0.7588172539468188
358.0000000000044,41.14377527855768,0.20860440155431048,-0.7593601049496193
359.1000000000044,41.25087187885339,0.20882930478588307,-0.7593601050185317
360.2000000000044,41.35724144713813,0.20602229993268933,-0.7595466157912139
361.30000000000445,41.46407331369737,0.20481749281323564,-0.7607095028016717
362.4000000000044,41.57080900494108,0.20110719149215966,-0.7619900827741057
363.50000000000443,41.67740971793892,0.201443564819496,-0.7619220850514474
364.60000000000446,41.78300170586734,0.2052544925679895,-0.7633103097435625
365.7000000000045,41.88999902865118,0.20263842216407446,-0.7633096366373948
366.8000000000045,41.99650691834302,0.2047360674616183,-0.7655830671926149
367.9000000000045,42.102162241133335,0.20510593264205865,-0.7642903182866334
369.00000000000455,42.2094867157659,0.20629014826277253,-0.7646198896398566
370.10000000000457,42.31541531445712,0.20651426188126998,-0.7672598495583429
371.2000000000046,42.42377810940951,0.20755000971805476,-0.7685816198670223
372.30000000000456,42.52966265227802,0.20575187518130034,-0.7679201745517679
373.4000000000046,42.63712285676013,0.20496155552535547,-0.7672616720705476
374.5000000000046,42.742190917297634,0.20477727904573265,-0.7685698558699317
375.6000000000046,42.85054953304386,0.205610631837139,-0.7696066065498086
376.70000000000465,42.957493183641326,0.20538078216606817,-0.7698900919894842
377.8000000000047,43.06406052443066,0.20385997144558365,-0.7698900918971221
378.9000000000047,43.17130846729394,0.20699893216575876,-0.7712682338620822
380.00000000000466,43.27655027256258,0.20606898292788636,-0.7711599914924396
381.1000000000047,43.384143550398285,0.2084328451517314,-0.7725200713712335
382.2000000000047,43.49076845781771,0.20814878664958475,-0.7725210375327278
383.30000000000473,43.59675684745755,0.20595236559061347,-0.773610596702694
384.40000000000475,43.70332473870887,0.20907462482300354,-0.773835022193484
385.5000000000048,43.80972119025279,0.20782735337697328,-0.7751500472635002
386.6000000000048,43.91645132369538,0.2091302779035064,-0.7751497300862966
387.7000000000048,44.02324204547605,0.20981586025046314,-0.7774610621515325
388.80000000000484,44.13065747970332,0.20851384839178777,-0.778781496636916
389.9000000000048,44.23727823691562,0.20821436774761243,-0.7784424218666937
391.00000000000483,44.34341883005097,0.21123847705011992,-0.7794299157330835
392.10000000000485,44.45111607607896,0.2083929916768909,-0.7797788913734536
393.2000000000049,44.55879519419845,0.21024873682853812,-0.7810808526069022
394.3000000000049,44.66475578730246,0.21066445381415758,-0.7810818598678573
395.4000000000049,44.77221761083937,0.2064262254955667,-0.781069600479869
396.50000000000495,44.8781427383566,0.2075841872719183,-0.783709306494615
397.6000000000049,44.985978982724106,0.20817117239475877,-0.7837095682924464
398.70000000000493,45.09298014325096,0.2076187281540515,-0.7850299113206698
399.80000000000496,45.19929426261165,0.2076016921853162,-0.7863371985604268
400.900000000005,45.30721227481607,0.20470147891118515,-0.786363623179803
402.000000000005,45.415382730222376,0.20428307705462692,-0.7876614680888672
403.100000000005,45.522275583773876,0.20401736019409922,-0.788001223377452
404.20000000000505,45.629604940468475,0.2034650064216302,-0.7902966843444692
405.30000000000507,45.73679960854224,0.2037784973558897,-0.7912917007001434
406.4000000000051,45.8441239729308,0.20228678805438527,-0.7926927526489673
407.50000000000506,45.952512559156354,0.20127255709735473,-0.7925976504681791
408.6000000000051,46.05961205581771,0.20076930859698935,-0.7939100315783141
409.7000000000051,46.16689540208256,0.20132688862023237,-0.7952271050358237
410.8000000000051,46.27503951839848,0.19936807417878585,-0.7962417092756775
411.90000000000515,46.382396859695135,0.19904647459177122,-0.7971984695087135
413.0000000000052,46.48969134453105,0.19852954892863064,-0.7985119343507794
414.1000000000052,46.59767003534979,0.19838155326827622,-0.7998298787463867
415.20000000000516,46.70473133535954,0.1950130454950968,-0.8011520624573247
416.3000000000052,46.813615650339166,0.1945472437990951,-0.8037775584327176
417.4000000000052,46.91916161679877,0.19396080384040815,-0.805109873822321
418.50000000000523,47.0290281826869,0.1935589641483107,-0.8064097530103389
419.60000000000525,47.13623906295772,0.19350687366857938,-0.8077411853564076
420.7000000000053,47.24256953425738,0.1933605045931413,-0.8089763217519899
421.8000000000053,47.350862540840346,0.19365478332245262,-0.8116799191166275
422.9000000000053,47.45858299379517,0.19568309089560942,-0.8129256979597486
424.00000000000534,47.5666697034496,0.1937822198983366,-0.81562859034364
425.1000000000053,47.67417659376408,0.19368707614781455,-0.8169363483809109
426.20000000000533,47.782102778304704,0.19529608526147396,-0.8194160628454452
427.30000000000535,47.888849438482396,0.19616184455708424,-0.8208340711633526
428.4000000000054,47.99620898586172,0.19811225476367111,-0.8236049163244847
429.5000000000054,48.1044580886797,0.19783747797010004,-0.8261627546477643
430.6000000000054,48.21227155180208,0.19770539972327184,-0.828767598742381
431.70000000000545,48.32099448684604,0.20112769938621788,-0.8301536771292377
432.8000000000054,48.42739586717249,0.19983177589270285,-0.8326216993030471
433.90000000000543,48.53589479839173,0.20156679597684057,-0.8354807145002319
435.00000000000546,48.643385426173424,0.20312999290436717,-0.8390760432848814
436.1000000000055,48.750286115504615,0.20448605058812525,-0.8418400427925823
437.2000000000055,48.85850326264834,0.2070158535148015,-0.8434081837033411
438.3000000000055,48.965335442782745,0.20579798149304562,-0.8472028737126553
439.40000000000555,49.07353404421764,0.20774894340658145,-0.8512690186051621
440.50000000000557,49.18127373772962,0.2091570084296251,-0.854000618998195
441.6000000000056,49.28899326957698,0.2102885609751704,-0.8597527411889478
442.70000000000556,49.39687231820493,0.21673276369216882,-0.862469458652039
443.8000000000056,49.50422159332384,0.21712087419665105,-0.8665151441456955
444.9000000000056,49.61230736814457,0.21941091288787357,-0.869053364647363
446.0000000000056,49.7195750486967,0.22344638984585402,-0.8737264305483676
447.10000000000565,49.82769908262334,0.22685882575748706,-0.8782789730563132
448.2000000000057,49.93592558251996,0.22916309302076143,-0.883578350643548
449.3000000000057,50.0441897599774,0.2319203188605461,-0.8883874294612784
450.40000000000566,50.15236993115878,0.23588128814343917,-0.8923625149652059
451.5000000000057,50.259796150716916,0.239768658518472,-0.8978222599556895
452.6000000000057,50.368658183308355,0.2417834002570859,-0.9016378802397611
453.70000000000573,50.47641254221015,0.24391637529215315,-0.9059766588729596
454.80000000000575,50.584722582409796,0.24724430031382905,-0.9112817387206791
455.9000000000058,50.692288300243675,0.2515899038601874,-0.9168244715789049
457.0000000000058,50.80077874402567,0.25571986342102515,-0.9216787673940496
458.1000000000058,50.90865399060591,0.2605126542414442,-0.9257542725142418
459.20000000000584,51.01760548258696,0.26301249524457676,-0.9313072217995257
460.3000000000058,51.12544800020224,0.26513715308559277,-0.9354175448596935
461.40000000000583,51.23457403740579,0.2703416971744813,-0.940113484255408
462.50000000000585,51.34294973039015,0.27045614036539983,-0.9459409820214466
463.6000000000059,51.45083548040035,0.2740626656188728,-0.9493149615269707
464.7000000000059,51.56038179208697,0.27591312726749867,-0.9552454215280473
465.8000000000059,51.66759408519615,0.2798384107067494,-0.9594147790920995
466.90000000000595,51.776298400084535,0.28264369038705156,-0.964141410421532
468.0000000000059,51.885183973460514,0.28789742481431846,-0.9682007616880739
469.10000000000593,51.993610489196534,0.2871722144431016,-0.9749774644035711
470.20000000000596,52.100796299935695,0.28826684410026954,-0.9779768912209268
471.300000000006,52.20924564619713,0.2902282813190427,-0.9802022444997767
472.400000000006,52.31726093961229,0.29058773243386027,-0.9851819447365613
473.500000000006,52.42584009271761,0.2913530873031023,-0.9896422247663361
474.60000000000605,52.533960145645175,0.29517527090325196,-0.992564970205728
475.70000000000607,52.6422084022856,0.29421223508989675,-0.9963574019711503
476.8000000000061,52.75087564506508,0.2958986333819754,-1.000779808735278
477.90000000000606,52.860492802356745,0.2971186624601875,-1.0028984109065058
479.0000000000061,52.96872584992357,0.2987456128483149,-1.0060623067882006
480.1000000000061,53.077632715324086,0.29847359153676756,-1.0101348971122315
481.2000000000061,53.18634644998452,0.29870719030961435,-1.0116331378119696
482.30000000000615,53.29542428636862,0.30164294515023904,-1.0148002148780626
483.4000000000062,53.403094635972785,0.3028770632608009,-1.018445630637102
484.5000000000062,53.511926386411744,0.3020435392189518,-1.0197569535027111
485.60000000000616,53.62071991004748,0.3086082253213018,-1.024046035766308
486.7000000000062,53.73048949805275,0.30806164768798455,-1.025348956573696
487.8000000000062,53.837773242689025,0.30741671421916544,-1.0280884359584168
488.90000000000623,53.947034504785094,0.30837588978730096,-1.0304667474602867
490.00000000000625,54.056014735064615,0.31070315472555493,-1.0320188720095458
491.1000000000063,54.16470453869165,0.3108052065469095,-1.0338380672166694
492.2000000000063,54.27154244596007,0.3122599274609456,-1.036041793368974
493.3000000000063,54.38112686352666,0.3138680592507252,-1.0371095449049523
494.40000000000634,54.489900789587224,0.31058728700309474,-1.0400500855516803
495.5000000000063,54.59875835280118,0.3154782149725409,-1.0422274072193556
496.60000000000633,54.707735064370915,0.3137267191892139,-1.0430113217498165
497.70000000000636,54.81670988943923,0.31252993843112264,-1.0443203426345984
498.8000000000064,54.92622787534448,0.31072019187428757,-1.044904016151197
499.9000000000064,55.03484430111253,0.3089429524320099,-1.0469480894986525
501.0000000000064,55.143117488477245,0.3151140309436311,-1.0479402871733914
502.10000000000645,55.25171688310173,0.31191268797311356,-1.0485987310799785
503.2000000000064,55.35999900770802,0.31202498034092896,-1.050020176832147
504.30000000000643,55.46871626354638,0.31066173313134804,-1.0526597015066907
505.40000000000646,55.57641214169799,0.31654454943514376,-1.0530170181095668
506.5000000000065,55.687168057039145,0.31652597682284667,-1.055291966667502
507.6000000000065,55.79524070260198,0.31894519555036727,-1.0556272195776866
508.7000000000065,55.90404779250851,0.3221331943976298,-1.0569646424649797
509.80000000000655,56.012959943851556,0.3200792782623184,-1.0584815015907645
510.90000000000657,56.12082507424814,0.3230454815575453,-1.0619775568668386
512.0000000000066,56.23072157761084,0.32340296269422386,-1.0601235773499011
513.1000000000065,56.33835192338259,0.32618914613835825,-1.0614572317726307
514.2000000000066,56.44840935872342,0.3291253716863679,-1.0627501131230277
515.3000000000065,56.55774917853084,0.3323680451004589,-1.0627559325039382
516.4000000000067,56.666161211013026,0.3350644670749846,-1.0663612364197368
517.5000000000066,56.77487224287685,0.343705325311882,-1.065648737552003
518.6000000000067,56.88438292006408,0.3497815967755805,-1.067989378944671
519.7000000000066,56.99275889795425,0.3609259249581358,-1.0694215229630637
520.8000000000067,57.1015916423703,0.3686201963411536,-1.070650154205251
521.9000000000067,57.21011033701114,0.37723750484479124,-1.0713193943224897
523.0000000000067,57.31989905353188,0.3830585485517013,-1.0736101884659872
524.1000000000067,57.429130471615125,0.38714073354828393,-1.075260822234723
525.2000000000068,57.53779342566401,0.39619050769569664,-1.0765939400610658
526.3000000000068,57.647497532809716,0.3976029064425092,-1.0768482864740205
527.4000000000068,57.75724773304127,0.39880939423523243,-1.0794226155656275
528.5000000000068,57.86644331562006,0.4080070254500687,-1.0821699721390545
529.6000000000068,57.97458037146354,0.4115498735195632,-1.0821577440734855
530.7000000000069,58.08394829272109,0.4141424010861964,-1.08601871502401
531.8000000000068,58.194602503808525,0.42080027014385357,-1.0874284776868994
532.9000000000069,58.30283618452779,0.42440607463533675,-1.087417118819225
534.0000000000068,58.412696740551695,0.42832280953116453,-1.08932551562528
535.100000000007,58.52280592595538,0.4316795645148941,-1.0913786668645713
536.2000000000069,58.631126883934144,0.4337274837023093,-1.09269645838959
537.300000000007,58.74053765146713,0.43598321610186896,-1.0953275820888089
538.4000000000069,58.850497986930584,0.4383571780861685,-1.0966407849980206
539.5000000000069,58.95957101916544,0.43934564083436844,-1.099276563976216
540.600000000007,59.067788678734416,0.44312827962991885,-1.101393836259661
541.700000000007,59.17833205938727,0.44228598624543214,-1.1011225498265982
542.800000000007,59.28820032410316,0.44348161332804503,-1.1042119945010658
543.900000000007,59.397280775773076,0.44000674175422827,-1.106833569718641
545.000000000007,59.50682635093372,0.43782077755979776,-1.1081598387957046
546.1000000000071,59.61711042341239,0.436740600339225,-1.1107724909386518
547.2000000000071,59.726273675012536,0.42925921996555405,-1.1121100350433348
548.300000000007,59.83546375959235,0.4293299104806265,-1.1147416085608097
549.4000000000071,59.94546380956057,0.4273527107075564,-1.1164775865343044
550.500000000007,60.05434911773922,0.42689632624048146,-1.117641002989675
551.6000000000072,60.16281858804246,0.4242668290871673,-1.1202758530815733
552.7000000000071,60.273436091296084,0.42445870673069463,-1.1212912037964946
553.8000000000072,60.38279600025674,0.4275640417014466,-1.1238686110935627
554.9000000000071,60.49262093310594,0.4262199392516939,-1.1252680379381843
556.0000000000072,60.60225234640534,0.42827165793655364,-1.1280947939242258
557.1000000000072,60.71274460459917,0.4279122126667817,-1.130646557986767
558.2000000000072,60.82304339284198,0.4257397278960341,-1.1331372861270776
559.3000000000072,60.932666026888924,0.4287185110291494,-1.133798128002843
560.4000000000073,61.04236457139416,0.4278079952711644,-1.1364609294927956
561.5000000000073,61.152258379454565,0.43137180743483816,-1.13893049155207
562.6000000000073,61.262405336484,0.43013099968381474,-1.1419289435408784
563.7000000000073,61.37234541788653,0.4353061146692042,-1.1432727721744214
564.8000000000073,61.48186354869009,0.440604112780583,-1.1447322704321006
565.9000000000074,61.591580604948454,0.4430019074825253,-1.1479626047541949
567.0000000000074,61.70114241635564,0.4491076458864267,-1.1506335763270132
568.1000000000074,61.811071533767304,0.45623813479691433,-1.1532848076950253
569.2000000000073,61.92019847267196,0.4665051868748301,-1.1549061713754263
570.3000000000073,62.029293296415176,0.4707151397877617,-1.1571404796320048
571.4000000000074,62.14030656025758,0.4830986895697773,-1.1591572963895471
572.5000000000074,62.251602430150236,0.4952902056535664,-1.1617980307403042
573.6000000000074,62.361983202490336,0.505661866391267,-1.1638268514496937
574.7000000000074,62.47186338777666,0.5152987906718905,-1.168021507800753
575.8000000000075,62.58207393573717,0.5242450425013161,-1.1706609970133286
576.9000000000075,62.69190371762807,0.5383756878322447,-1.1733735847432234
578.0000000000075,62.802080765186176,0.555316505407923,-1.1771760166167429
579.1000000000075,62.912869377054186,0.5731565953609472,-1.1799887536272373
580.2000000000075,63.0238112598252,0.5889956403347825,-1.1822554976286703
581.3000000000076,63.13306093553325,0.6002393772993758,-1.1853731889534154
582.4000000000076,63.24373442917115,0.6116402707923454,-1.1895560517643058
583.5000000000076,63.35325216664621,0.620147712107349,-1.1939103361674457
584.6000000000076,63.463008334144405,0.621434823908703,-1.1980394318739793
585.7000000000077,63.57355617860502,0.6110625401160891,-1.1998828741516463
586.8000000000077,63.68441019902769,0.5944094797580819,-1.2039335561956581
587.9000000000076,63.794015189619834,0.5616277366883381,-1.2084232716871974
589.0000000000076,63.904513147195274,0.5084541360758382,-1.2121648406168521
590.1000000000076,64.01311204623215,0.4564479206826104,-1.2138300812314924
591.2000000000077,64.12358147823232,0.4111753280358169,-1.2165242470549669
592.3000000000077,64.2328385895534,0.3761148004246325,-1.217850457831477
593.4000000000077,64.3441073560496,0.3541321234193734,-1.2204634472089926
594.5000000000077,64.45348184527884,0.3408442108359324,-1.220418410766773
595.6000000000078,64.5638288156887,0.33157385042534304,-1.2217998062157496
596.7000000000078,64.67272662510553,0.3274804443075514,-1.221711243995768
597.8000000000078,64.7840718974443,0.31893113562019426,-1.2221197801520796
598.9000000000078,64.89510012062797,0.31786056418229913,-1.2234451669997801
600.0000000000078,65.00426735084142,0.31668540459536343,-1.2247514341242791
601.1000000000079,65.11439233214413,0.3192649164127801,-1.225241510479857
602.2000000000079,65.22435640505775,0.31856483808310043,-1.224421049111403
603.3000000000079,65.33442639992778,0.32735402071238984,-1.2270599216598064
604.4000000000078,65.44521485058961,0.3325850985520752,-1.2278572596355692
605.5000000000078,65.55515239061486,0.3448828133939541,-1.227060257200269
606.6000000000079,65.66580547559491,0.3567954863875895,-1.228378762467805
607.7000000000079,65.77641650377163,0.3668085092503788,-1.2297002190319186
608.8000000000079,65.88678487899362,0.376966961376735,-1.231016910871738
609.9000000000079,65.99799072887981,0.391256753453711,-1.230979642332632
611.000000000008,66.10741144595399,0.39831571336608107,-1.231037257288191
612.100000000008,66.21897571946707,0.40702748165216707,-1.232320391193571
613.200000000008,66.32948930280686,0.4185427683478431,-1.2349628113321964
614.300000000008,66.43978104727685,0.4331910695806328,-1.2365999434568726
615.400000000008,66.55055297002438,0.4388533567515749,-1.237254674613983
616.5000000000081,66.66174248281257,0.4460248579509962,-1.2385770479382732
617.6000000000081,66.77173109695107,0.45576045379635133,-1.2406908516298283
618.7000000000081,66.88192713407174,0.4669928164949648,-1.2425689048745956
619.8000000000081,66.992317088088,0.4735390246593063,-1.2431135304472951
620.9000000000082,67.1030722099824,0.4829833498634557,-1.2457849534987946
622.0000000000082,67.21314227254554,0.4907579593483318,-1.2471580458481584
623.1000000000081,67.32447045877076,0.501451753645268,-1.248434996506477
624.2000000000081,67.43416833637421,0.5165528138439038,-1.2524749143130611
625.3000000000081,67.54394634364212,0.5221303041911635,-1.2537099169557506
626.4000000000082,67.65450962475573,0.5357598445391701,-1.2539385782138273
627.5000000000082,67.764605318901,0.5449795362155656,-1.2565744928760103
628.6000000000082,67.874897985075,0.5587886211401728,-1.2590370892707754
629.7000000000082,67.98529812879835,0.5728519297630248,-1.2625219702775654
630.8000000000083,68.0955078105195,0.5818099619015713,-1.2643402469418898
631.9000000000083,68.2071878688094,0.5968485809850472,-1.2698723032133805
633.0000000000083,68.31701998865127,0.6073986111167476,-1.2702870042412018
634.1000000000083,68.42775752816868,0.6194703182608815,-1.2723662443690267
635.2000000000083,68.53762293728147,0.6298781618569536,-1.2758316246617163
636.3000000000084,68.64907275273481,0.645991629094208,-1.279174663588249
637.4000000000084,68.75913035697565,0.657904215665537,-1.2821653242116327
638.5000000000084,68.86837604886739,0.6704109465579118,-1.2846674662346143
639.6000000000083,68.9786693220077,0.6831815857764247,-1.2882441068207076
640.7000000000083,69.08938451559223,0.700884997408098,-1.291420027480041
641.8000000000084,69.19959932819901,0.7177971128378011,-1.2974429333715434
642.9000000000084,69.31121230532545,0.7364078796726123,-1.3011726890116337
644.0000000000084,69.42266940079173,0.7565353025966819,-1.3041513477527702
645.1000000000084,69.5333979895838,0.7740771096409504,-1.3097162551796981
646.2000000000085,69.64406855370237,0.7927968102280829,-1.3099756521536694
647.3000000000085,69.75490826605922,0.8136966619415686,-1.316172436290611
648.4000000000085,69.86434680523287,0.8352820899125488,-1.320317425539368
649.5000000000085,69.97535683485195,0.8580658663595777,-1.325339374212474
650.6000000000085,70.08482586676199,0.8768578721834699,-1.3295075767327957
651.7000000000086,70.19649694718858,0.8976108823896096,-1.3343150320098522
652.8000000000086,70.30655995573858,0.920416616400662,-1.3386022899871364
653.9000000000086,70.41632982046143,0.9450123434810425,-1.3435756794081688
655.0000000000086,70.52839794398017,0.9687779095218878,-1.3486723822088882
656.1000000000087,70.63808823539412,0.989324702826893,-1.3543604100400453
657.2000000000087,70.7493791019202,1.0096921287858116,-1.3596001191844769
658.3000000000086,70.86087845670494,1.030559704579343,-1.3624534995931454
659.4000000000086,70.9703143032767,1.0570365029529605,-1.3686547688669513
660.5000000000086,71.08194623941154,1.0842073231003129,-1.3750087947961687
661.6000000000087,71.193530653532,1.1080567413012106,-1.3797057175997995
662.7000000000087,71.30316225371764,1.1345451703136933,-1.3848546288816488
663.8000000000087,71.41342489272509,1.1590687316185078,-1.3913040203621332
664.9000000000087,71.52572151569395,1.1883762958134387,-1.3945011469225692
666.0000000000088,71.63635163222716,1.22066041006966,-1.4024951452673937
667.1000000000088,71.74635681626563,1.2472749595429367,-1.4080743741776423
668.2000000000088,71.85798298276485,1.278390679562575,-1.4139682160942169
669.3000000000088,71.96894233329824,1.315986233609502,-1.4200686869720247
670.4000000000088,72.08074682108165,1.3573309911147027,-1.4262775361613418
671.5000000000089,72.19153744314237,1.396814476346294,-1.4316566729052527
672.6000000000089,72.30083132017481,1.4427957398970066,-1.4401637285368647
673.7000000000089,72.41130900737738,1.4979687557043389,-1.447137815646835
674.8000000000088,72.5243065016412,1.5497786687065886,-1.455925399664324
675.9000000000088,72.63557098342912,1.6086179326951147,-1.462072272533721
677.0000000000089,72.74577359269213,1.6680023535780752,-1.4725048214753529
678.1000000000089,72.85731377844071,1.7381653783800222,-1.481404286099088
679.2000000000089,72.96830755362524,1.8115301003798963,-1.4894664268761177
680.3000000000089,73.07987858173209,1.8937175895938962,-1.4991893585573437
681.400000000009,73.19161811376328,1.981745164513497,-1.5089627687648157
682.500000000009,73.30300906013224,2.081796224680134,-1.5192861014174421
683.600000000009,73.41396202563854,2.1874092324993346,-1.5306532773825223
684.700000000009,73.5248288688339,2.3121897432580214,-1.5414430833375046
685.800000000009,73.63685909693086,2.433905862757869,-1.553243658060318
686.9000000000091,73.74853820158509,2.5293025861802674,-1.5669937918063606
688.0000000000091,73.8597785088945,2.571479351850014,-1.5787828218772755
689.1000000000091,73.97172173305366,2.5696768083885697,-1.5930487180964024
690.2000000000091,74.08304356372714,2.563040226517999,-1.608135020582253
691.3000000000092,74.19440420341375,2.566077355933303,-1.6230699688567372
692.4000000000092,74.30558837661317,2.583359376682755,-1.6383694048908897
693.5000000000091,74.41654210812352,2.609792215845797,-1.6528195163209625
694.6000000000091,74.5280621001136,2.6440999267088636,-1.668142211237984
695.7000000000091,74.63967870982731,2.6785637126225064,-1.6845244269016493
696.8000000000092,74.75140568416404,2.7121139345397625,-1.6997426915365295
697.9000000000092,74.8626770224161,2.7485116168077557,-1.7160066990436142
699.0000000000092,74.97375737146453,2.7813707586429355,-1.7326192366992048
700.1000000000092,75.08425572228346,2.8130260235023856,-1.7495440064237906
701.2000000000093,75.19577766528367,2.843651799731154,-1.7669446498753247
702.3000000000093,75.30766529741084,2.8686193291603717,-1.7846314987921943
703.4000000000093,75.41794481680559,2.8931690746667282,-1.8016595890064524
704.5000000000093,75.52832959324157,2.912118113495234,-1.8187246079662098
705.6000000000093,75.64041085593847,2.924252390754292,-1.837103538688904
706.7000000000094,75.7519728795601,2.931912829077437,-1.8539969468145978
707.8000000000094,75.86309502103526,2.9342136456459316,-1.872271805640933
708.9000000000094,75.97453239803279,2.9348118355977344,-1.8904894829981789
710.0000000000093,76.0863408502388,2.9266353337043056,-1.9069127057083008
711.1000000000093,76.19725950303153,2.9173914967935195,-1.9260060662100371
712.2000000000094,76.30837945100087,2.9066107338635403,-1.943023080524751
713.3000000000094,76.41989635928276,2.888126376851722,-1.9609509295538023
714.4000000000094,76.53169081989735,2.8707109697068978,-1.9774836664730948
715.5000000000094,76.642295203533,2.8476466355697134,-1.9937276925764778
716.6000000000095,76.75403902036828,2.819553986387046,-2.0123614744771654
717.7000000000095,76.86496876463521,2.7701079153785373,-2.0288309273519873
718.8000000000095,76.97576658289272,2.7038909234277124,-2.0447291263436895
719.9000000000095,77.08737466176565,2.602346727660729,-2.0596909750045436
721.0000000000095,77.19818007255623,2.449688605801197,-2.0761664363362726
722.1000000000096,77.30917068846294,2.2314149480016865,-2.0895203061112113
723.2000000000096,77.42040871662995,1.8895516393629284,-2.1032752071870595
724.3000000000096,77.53059566742948,1.3760183026601323,-2.110537928756286
725.4000000000096,77.63979618910594,0.5895436092404593,-2.118903260311308
726.5000000000097,77.75009802608601,0.39359403532944737,-2.1218805346646388
727.6000000000097,77.85980174095403,0.3625465332011646,-2.1245200198415777
728.7000000000096,77.97093581096063,0.3535499113857321,-2.1258429083037997
729.8000000000096,78.08209069994604,0.3504520911372597,-2.1251656872093587
730.9000000000096,78.19327615036966,0.3522077938777093,-2.125483493848842
732.0000000000097,78.30374918634854,0.35218914003671986,-2.1258229607460697
733.1000000000097,78.41662972927574,0.3537283976166956,-2.1258943120730067
734.2000000000097,78.52844761530314,0.3511240795370638,-2.1268198849110833
735.3000000000097,78.6401180493816,0.3550221007960712,-2.126819885059355
736.4000000000098,78.75070147993677,0.35623465996920256,-2.1265044745352784
737.5000000000098,78.86200186751434,0.35699865243567763,-2.1261499802609585
738.6000000000098,78.97388931143169,0.3578506341504919,-2.1261499711723166
739.7000000000098,79.08618351711804,0.35526320276909207,-2.1264795584733385
740.8000000000098,79.19739932281752,0.35442860545921406,-2.1277860746305537
741.9000000000099,79.3078612026759,0.35238537779267887,-2.1278033013742492
743.0000000000099,79.41957410950756,0.34851450387741734,-2.1277981983323753
744.1000000000099,79.53259589982312,0.34858143558343824,-2.1278103361140706
745.2000000000098,79.64437552774665,0.34808527633192243,-2.126756029583191
746.3000000000098,79.75587097944529,0.3493385100181241,-2.1287518326582884
747.4000000000099,79.8678304887159,0.34865048721788283,-2.128789828042293
748.0000000000099,79.92896884496416,0.3419993791798961,-2.1287335710632025