File: 01_Data/Vinyl_Tile/STA/N2/10K_min/Vinyl_Tile_STA_N2_10KData_220505_R1.csv
##Temp./Â°C,Time/min,DSC/(mW/mg),Mass loss/mg
50.0,10.443548481727625,0.01852489685550962,0.002699163184948894
51.100000000000016,10.932375464912173,0.04503500481551059,0.0011324742699527768
52.20000000000003,11.171164102886937,0.0655547021059244,0.001188540309296826
53.30000000000005,11.357161435914064,0.082897069790276,0.00020159675066322436
54.40000000000006,11.521870596402675,0.0969808286426852,0.0005769977717231534
55.50000000000008,11.673052892340744,0.10761782387777508,0.0011871459437315934
56.600000000000094,11.809352313891088,0.11187689634356046,6.309553336070195e-05
57.70000000000011,11.947852279321987,0.1209954315780346,-6.344268459557156e-05
58.800000000000125,12.079714038130062,0.1258545558323334,0.00235222058796003
59.90000000000014,12.202444989090816,0.12944460443409156,0.0004204316806948327
61.000000000000156,12.331703766892504,0.1310588180217216,0.0010463311605772851
62.10000000000017,12.455025268869981,0.13603119079852521,0.0002764574929243757
63.20000000000019,12.575931126992716,0.1362589577030755,0.0005533704152016483
64.30000000000021,12.698630568754455,0.13955982564755842,-0.00019185949535893698
65.40000000000022,12.815647167944686,0.13829215724720356,-0.0005832495729012344
66.50000000000023,12.933974863839927,0.14034997012423378,-0.0019390662110625456
67.60000000000025,13.05503669666028,0.14073361295290943,-0.002310656764207497
68.70000000000027,13.174749278280688,0.14492002375476343,-0.001063768886930827
69.80000000000028,13.29184865178542,0.14388020694033254,0.0004394417860265065
70.90000000000029,13.409670514140542,0.14609882017358022,0.00043990786795067294
72.00000000000031,13.526362806030857,0.14752445252789825,-0.00025638629634272547
73.10000000000034,13.641828672690792,0.14921274754102076,-0.001307988634483781
74.20000000000034,13.759467452594091,0.15153244788834241,-0.0022932309002050566
75.30000000000035,13.873945222765188,0.1515768930273509,-0.0009274698415100424
76.40000000000038,13.988118923837186,0.1544391457600176,-0.0009921778078973986
77.5000000000004,14.103243565506133,0.1525908783942731,-0.000990045632154768
78.6000000000004,14.219603562298214,0.15442838041038953,-0.0008834488587581291
79.70000000000041,14.332325964940113,0.1548345194535944,-0.0013264466635263261
80.80000000000044,14.443891204881355,0.15569783729728226,-0.002310065802232586
81.90000000000046,14.559749067720574,0.1576877777523059,-0.0009893028571914542
83.00000000000047,14.671386915629878,0.15946376748887248,-0.0009896262485069585
84.10000000000048,14.782905524642013,0.1600165928508872,0.0003293874447201084
85.2000000000005,14.895488791328539,0.16139130236337096,-0.0009909143162816214
86.30000000000052,15.006310647051782,0.15859456077360334,-0.000978288820803641
87.40000000000053,15.119025642409579,0.16142148939535594,-0.0009933195635407621
88.50000000000054,15.228390011076925,0.16370905743029252,-0.0019784671592528724
89.60000000000056,15.338855744140027,0.16368190596134724,-0.0009907634586050484
90.70000000000059,15.448991992444151,0.16364923905825557,-0.00229911272281047
91.8000000000006,15.560000000000063,0.1660532930235179,-0.0022984453234733415
92.9000000000006,15.668769709103554,0.167103847950542,-0.0009900141133831752
94.00000000000063,15.777442242175962,0.16660543517587534,-0.0006135201305124127
95.10000000000065,15.88789828027394,0.1677094567502766,-0.0009884306904162088
96.20000000000066,15.997651571683068,0.16889051427435942,-0.0009896360104302282
97.30000000000067,16.104920822542407,0.17083617348798064,-0.0009626569212684011
98.40000000000069,16.213827351725726,0.17324286759640117,-0.0013201180137651924
99.50000000000071,16.322056782747346,0.17331154500492651,-0.0022999670003018835
100.60000000000072,16.429313389392053,0.17378014027391486,-0.000982401174332015
101.70000000000073,16.53810315081936,0.1735343878924961,-0.0022990178189803423
102.80000000000075,16.64511047207941,0.1763956175919349,-0.0023148180936778395
103.90000000000077,16.751884938796184,0.17745543443751477,-0.0009872675393052255
105.00000000000078,16.860861437779175,0.17804387417339407,-0.0009897825268700977
106.10000000000079,16.96844433917237,0.17851232854764842,-0.000979597805767174
107.20000000000081,17.072829147699164,0.18043687450360368,-0.0009799362859870264
108.30000000000084,17.18360779952494,0.1794923798393372,-0.0022997283682233416
109.40000000000084,17.290616638222616,0.1809736625612075,-0.0009900750933904412
110.50000000000085,17.397519926333807,0.18264126093815725,-0.0009965140217831348
111.60000000000088,17.504260678375978,0.18111545801880113,-0.0008520151052398006
112.7000000000009,17.614572514945127,0.1793782140519644,-0.0009920445891027363
113.8000000000009,17.722313959634413,0.181676128601992,-0.0009898519794218075
114.90000000000092,17.82867446756197,0.1819647897507798,-0.0016411707120429497
116.00000000000094,17.93644058574905,0.18347851703759654,-0.0023090634509421726
117.10000000000096,18.043383677967352,0.1816531606509466,-0.0017220504187065444
118.20000000000097,18.14899563668449,0.1831947619620931,-0.0023016280077987616
119.30000000000098,18.25768420949783,0.18308920877749263,-0.0023025453330602907
120.400000000001,18.364006510505984,0.1834118728511791,-0.0023002988808835667
121.50000000000102,18.47089612843836,0.1844840370161463,-0.001970122583612177
122.60000000000103,18.578864040291386,0.18304417934827044,-0.001996379593450115
123.70000000000104,18.684854046204176,0.1822347139822612,-0.0019801597470259225
124.80000000000106,18.791692493880625,0.1832749915322816,-0.003132652558591964
125.90000000000109,18.89973574697468,0.1860313963116389,-0.0019823695734784152
127.0000000000011,19.006503616430834,0.1862768090727302,-0.0029611600331689303
128.1000000000011,19.113592474191652,0.1866573239955025,-0.0029705218941042943
129.20000000000113,19.220948777888356,0.18532452423974166,-0.0032750011975077875
130.30000000000115,19.32881886865408,0.18673979462405688,-0.004560145715813757
131.40000000000117,19.434749122908567,0.18517478993927333,-0.005531093543001742
132.50000000000117,19.5413071252629,0.19092357571715562,-0.004295833253273873
133.6000000000012,19.646995377062815,0.1895083964072371,-0.003282222536830748
134.7000000000012,19.753519845411795,0.18885115824721638,-0.0033707770970226036
135.8000000000012,19.859680660627365,0.192400791851074,-0.0032984033764518195
136.90000000000123,19.965368577944787,0.19246870470320454,-0.0032901249715600045
138.00000000000125,20.070932471667778,0.19247478990360833,-0.004297862379224249
139.10000000000127,20.179265134339943,0.1937935051176788,-0.004600159952226068
140.2000000000013,20.283919320698697,0.1929870881284267,-0.00460016001007757
141.3000000000013,20.39115586914504,0.19429718614828517,-0.004594488138903063
142.4000000000013,20.496944924887508,0.19499237252735602,-0.004609972888051761
143.50000000000134,20.600263537612204,0.19266073915804838,-0.0046098487412606914
144.60000000000133,20.708562444615396,0.19472897099312758,-0.00590215169233721
145.70000000000135,20.815083818007295,0.19726160509597368,-0.00560070343511887
146.80000000000138,20.920303832673458,0.19442620502985974,-0.0046100733235352465
147.9000000000014,21.02602556968294,0.19631176203990408,-0.004279941841073498
149.00000000000142,21.132358730975614,0.19769683711539515,-0.004287357579659368
150.10000000000142,21.238837787713557,0.19807725249191377,-0.005919475621312564
151.20000000000144,21.343348163422178,0.19844867211717976,-0.006277877130488996
152.30000000000146,21.4501006578837,0.19840708928616785,-0.0062500329991430625
153.40000000000146,21.554441335971287,0.19945648199066351,-0.006250172789867836
154.50000000000148,21.6603789082231,0.19997879244469996,-0.006979370592257617
155.6000000000015,21.76651090391048,0.2023850487478278,-0.005930142815252282
156.70000000000152,21.87213949022022,0.20052127282260956,-0.005930143000012045
157.80000000000155,21.97719506689208,0.20135470403236294,-0.005930143443924507
158.90000000000154,22.083656763557315,0.20211791597751083,-0.007228989330173796
160.00000000000156,22.188541289567482,0.20357083294708117,-0.00723980676904068
161.1000000000016,22.294526995474538,0.20245111968929907,-0.006250230326726225
162.20000000000158,22.399834378906643,0.2043107779572887,-0.00790375831333856
163.3000000000016,22.505397047601253,0.20451375858268678,-0.0068214525578196294
164.40000000000163,22.609371355151403,0.20255705999176343,-0.006249848305287742
165.50000000000165,22.71571011706129,0.20821597980104312,-0.006431938136461035
166.60000000000167,22.82238021264625,0.2084208466220825,-0.007569851194066501
167.70000000000167,22.927011024777457,0.20833735173553652,-0.0075794072717334515
168.8000000000017,23.03285216626502,0.20886425609063852,-0.0075910523499973515
169.9000000000017,23.13834745402059,0.20900576682085292,-0.008879857142151337
171.0000000000017,23.244736484871975,0.21044101128710713,-0.008881187138645608
172.10000000000173,23.348509650657476,0.21396279464588164,-0.008559944865796698
173.20000000000175,23.455344831454617,0.21133592941620372,-0.008559937861276179
174.30000000000177,23.55873735962184,0.21194181813868812,-0.008878637107633924
175.4000000000018,23.664474440369887,0.21348978324206153,-0.009216360592986472
176.5000000000018,23.77120350797696,0.21555757123750735,-0.010363261062552809
177.6000000000018,23.875747619244194,0.21477782920144528,-0.01085993336995461
178.70000000000184,23.98064204230901,0.21572374248537815,-0.00954938992404486
179.80000000000183,24.08581111357088,0.21712316658142744,-0.01085984575825627
180.90000000000185,24.191322253971787,0.21839801447916599,-0.012170441400092269
182.00000000000188,24.295902937822568,0.2179786542997838,-0.012168823969429532
183.1000000000019,24.401436623361917,0.2187621920812446,-0.011189972977603713
184.20000000000192,24.506034627359053,0.21799779813502437,-0.011883166226420272
185.30000000000192,24.612214973661292,0.21870942923755066,-0.01185494517962482
186.40000000000194,24.716521161106197,0.21761158697749095,-0.01315993380147118
187.50000000000196,24.821343307188812,0.219140827031104,-0.013153507999925207
188.60000000000196,24.925871900369923,0.2192425180128977,-0.013820517512482589
189.70000000000198,25.03231352146251,0.2221132406220876,-0.015133269223409407
190.800000000002,25.136935559131004,0.2217756314840403,-0.01382137036186526
191.90000000000202,25.2407765347806,0.22165280094517262,-0.015129876779731877
193.00000000000205,25.345773973876174,0.2244789121540453,-0.01512981639362776
194.10000000000204,25.45089146545153,0.22479691003291333,-0.016450388849907682
195.20000000000206,25.55688253443625,0.2237617381329614,-0.016450169998381003
196.3000000000021,25.661166747283747,0.22393236945361614,-0.01695680126725163
197.40000000000208,25.76455568341793,0.22673526577385927,-0.017723390857392385
198.5000000000021,25.870213685392688,0.22612972331669706,-0.019080087123869216
199.60000000000213,25.975352601829268,0.2280122290897653,-0.019080086472643032
200.70000000000215,26.080095663416163,0.22652626305381957,-0.020441544449958826
201.80000000000217,26.18555213563251,0.22798157939024558,-0.02041657108233519
202.90000000000217,26.29056256537422,0.23106726893589472,-0.0207299318535048
204.0000000000022,26.394640958735106,0.22885488343466753,-0.02249209401036456
205.1000000000022,26.49990785613349,0.2326907040689991,-0.023367851687308594
206.2000000000022,26.603844377820284,0.22985768271906795,-0.024126759390430852
207.30000000000223,26.708487912095784,0.23180398325748455,-0.02561818537577043
208.40000000000225,26.814272004353857,0.23091617592373506,-0.025570267191598717
209.50000000000227,26.918396496098765,0.23181751991169322,-0.02468168909287094
210.6000000000023,27.024006814860833,0.23320990159422908,-0.027310350758679824
211.7000000000023,27.127799076304385,0.23527558732392242,-0.02846583781290324
212.8000000000023,27.23167436645664,0.2337628307700213,-0.029720098741841117
213.90000000000234,27.33808120880338,0.23667390762125365,-0.03125928887697205
215.00000000000233,27.44128971659762,0.2370514990273771,-0.03258017979322636
216.10000000000235,27.54690844918271,0.24027866790301328,-0.03387723818468347
217.20000000000238,27.65106272295148,0.23991651562931843,-0.03290035950853065
218.3000000000024,27.755765657773253,0.23852846241736142,-0.035521628756316925
219.40000000000242,27.861306027785986,0.2411127933241392,-0.036859952790337935
220.50000000000242,27.966006939507654,0.24244179364801968,-0.0381478419675374
221.60000000000244,28.071353759591496,0.24151909983159833,-0.03957222959203488
222.70000000000246,28.17604430651715,0.24795676803151878,-0.04183412443780021
223.80000000000246,28.280309193151204,0.2461860392404739,-0.04484315027668506
224.90000000000248,28.38597370555622,0.24717605086656885,-0.04474400911956211
226.0000000000025,28.489900916221828,0.24852134634674694,-0.047701843358481266
227.10000000000252,28.594620899314368,0.2518620579814526,-0.050009019467646354
228.20000000000255,28.70028812512747,0.2528711898382606,-0.052649807494799195
229.30000000000254,28.804341951194278,0.25452691689193135,-0.05528772611352828
230.40000000000256,28.909501749651266,0.25450240817645176,-0.05660007964096936
231.5000000000026,29.014405393122047,0.25667031036476873,-0.05957013917200671
232.60000000000258,29.118776391911247,0.25879015437008507,-0.062308437136977535
233.7000000000026,29.22318417711556,0.2598722501973478,-0.06493548215195277
234.80000000000263,29.3292256276416,0.26102995185398165,-0.06757039264853315
235.90000000000265,29.433761287327496,0.2621040315599411,-0.07020369600635368
237.00000000000267,29.537972968499417,0.26474772204999325,-0.07300656830750141
238.10000000000267,29.64306221951077,0.2625390251554264,-0.07674474045954849
239.2000000000027,29.746899628499392,0.26869164207795704,-0.0808396011510979
240.3000000000027,29.853126634832417,0.2682745382608893,-0.08345994351965969
241.4000000000027,29.957301870243786,0.2701989632151211,-0.08882374916673674
242.50000000000273,30.062476243087097,0.2726891183272996,-0.09268660104450888
243.60000000000275,30.167949746083032,0.2747476534983372,-0.09526334044610829
244.70000000000277,30.269735459360383,0.2764013143920772,-0.10022376947992173
245.8000000000028,30.37688514853051,0.28084950258857744,-0.10353358520919675
246.9000000000028,30.481019501178878,0.28157242299586316,-0.10821649080035023
248.0000000000028,30.586829184251965,0.28512628943801693,-0.11245381789093445
249.10000000000284,30.69061476084165,0.2869605108337243,-0.11940286599892591
250.20000000000283,30.794137390399825,0.28823643820789946,-0.12306732967027267
251.30000000000285,30.90035485142291,0.28750511062926737,-0.1287705897907232
252.40000000000288,31.00527427391915,0.28965346624692184,-0.13521126041315856
253.5000000000029,31.11055828511421,0.2906987302395339,-0.1391804071584275
254.60000000000292,31.21581128410074,0.2923874481054933,-0.14607626913898653
255.70000000000292,31.320501141807743,0.2919147810914782,-0.15216438629739715
256.8000000000029,31.424905457908388,0.29322284130593307,-0.15670652946554142
257.90000000000293,31.530595325873406,0.29200714907808956,-0.16322668091448023
259.00000000000296,31.63311836939218,0.2943105059170232,-0.16942008042694034
260.100000000003,31.738072396851862,0.29230775291342587,-0.17692871551903755
261.200000000003,31.84395190300105,0.29533033257552943,-0.18402675390900258
262.300000000003,31.949901065818604,0.2943827429424004,-0.1910655472188041
263.40000000000305,32.05547785084449,0.2948421420240925,-0.19778601851012434
264.50000000000307,32.160945244539185,0.2938587670241686,-0.20390331099016645
265.6000000000031,32.26492707613198,0.2924267615446049,-0.21112056859156247
266.7000000000031,32.37039738267994,0.29219231581269806,-0.22083544294887014
267.8000000000031,32.474860815385355,0.2933925228177797,-0.22829244737650445
268.9000000000031,32.58068045867945,0.2916099137652308,-0.23624310507168333
270.0000000000031,32.68660176584167,0.28878943360504683,-0.24549642585733
271.10000000000315,32.79029146626647,0.2883907835937072,-0.25427869273450643
272.2000000000032,32.89478941700147,0.28809886361242354,-0.26484923564291085
273.30000000000314,33.001309942885314,0.2861409601204068,-0.27424513334798517
274.40000000000316,33.106071709048294,0.2899187987955299,-0.2834244544054201
275.5000000000032,33.210564925971944,0.29113776691236853,-0.292929850227166
276.6000000000032,33.316304614143576,0.29386587991795504,-0.3064095194652534
277.70000000000323,33.42146409331299,0.2999938886431054,-0.31790209771939537
278.80000000000325,33.527077317621796,0.30782180862695563,-0.3296324068517773
279.9000000000033,33.63184302275427,0.3151128476804552,-0.3425240272925847
281.0000000000033,33.736308404172355,0.32441221866899106,-0.3549599610872649
282.1000000000033,33.84230780860404,0.33346641273464184,-0.36803787397523635
283.20000000000334,33.94757140947391,0.3460420704259646,-0.3809071819891927
284.30000000000337,34.051162613824715,0.356649537009442,-0.3931227058440636
285.40000000000333,34.15715627674149,0.3683790461675942,-0.4074862574234661
286.50000000000335,34.262978298639105,0.37918969974151817,-0.4216508300517443
287.6000000000034,34.36809385219284,0.3901615258571458,-0.4364564752816351
288.7000000000034,34.473661923512154,0.39475456018498045,-0.449709629592562
289.8000000000034,34.57888180733124,0.40144169480975445,-0.46296824530294467
290.9000000000034,34.6842435662462,0.40283035495252,-0.4752655444976597
292.0000000000034,34.79029119951707,0.4033510916446783,-0.48704554360611185
293.10000000000343,34.895931496271245,0.4006731216622419,-0.5010304750556651
294.20000000000346,35.001034172455356,0.3954196543740255,-0.5122207947153683
295.3000000000035,35.10483990803453,0.3929445116360512,-0.5217958722230049
296.4000000000035,35.21162402649657,0.3825472221582623,-0.5330315051500061
297.5000000000035,35.31681946275208,0.3766356993523572,-0.5418899904635412
298.60000000000355,35.42177903599832,0.36496689912523184,-0.5506434145164185
299.70000000000357,35.52599611622243,0.35382354759402906,-0.559749216194033
300.8000000000036,35.63144349704616,0.343639040934741,-0.568582994223962
301.9000000000036,35.73539612775551,0.33557552344052727,-0.5736235405162167
303.0000000000036,35.84387349976682,0.325986840873001,-0.5811042055736779
304.1000000000036,35.94915422806345,0.3152068409357254,-0.587665652632944
305.2000000000036,36.05489215851619,0.30522487762879447,-0.5953028044875266
306.30000000000365,36.16074378012945,0.2971224860516207,-0.5997751882102436
307.4000000000037,36.26520684598593,0.2897275850106881,-0.6044539166073744
308.5000000000037,36.37128244300084,0.2815585951267643,-0.6083072459452787
309.60000000000366,36.475882811964325,0.27557788478012557,-0.6148785147566804
310.7000000000037,36.58118094993224,0.2703811198255097,-0.6183076003128942
311.8000000000037,36.68629803545533,0.2631122846727388,-0.6238740738063426
312.90000000000373,36.79137012238321,0.2573974089532905,-0.6266749114842498
314.00000000000375,36.897031643589294,0.2515520251964098,-0.631566615291641
315.1000000000038,37.00293072136169,0.24883967055421408,-0.6352150970568902
316.2000000000038,37.10797106422369,0.24554287151505516,-0.6388362977071234
317.3000000000038,37.21286925111011,0.23943550285797366,-0.6413876821293396
318.40000000000384,37.32009276244784,0.23473075719533898,-0.6447733525896235
319.5000000000038,37.425328718208796,0.22951167112688795,-0.6472643572400312
320.60000000000383,37.53117704072286,0.22748681081573013,-0.6514941873793734
321.70000000000385,37.63677610019038,0.22134376446694382,-0.6540387940882142
322.8000000000039,37.74269040775463,0.21745121346445667,-0.6563472502297456
323.9000000000039,37.848376566887865,0.21538469021902068,-0.6589813089872818
325.0000000000039,37.953995451973555,0.21384030611212754,-0.6615577114624487
326.10000000000394,38.060188614084794,0.20695300039428988,-0.6630233350943144
327.2000000000039,38.16430856023167,0.20520256344750196,-0.6660120976329145
328.30000000000393,38.27190452639229,0.20426931736863263,-0.667345050527139
329.40000000000396,38.37693987549476,0.2004714110066991,-0.6710576172022003
330.500000000004,38.481670558026714,0.20109941320180927,-0.6723764490179702
331.600000000004,38.58850878233533,0.19615176180718835,-0.6743495767661232
332.700000000004,38.69356821338134,0.19583869791766695,-0.6755764392170347
333.80000000000405,38.79970904863641,0.1909972744076783,-0.6773099575357242
334.90000000000407,38.906004583051285,0.19059035070158314,-0.6789631524009336
336.0000000000041,39.01278641516277,0.1873459609678856,-0.6799571008765395
337.10000000000406,39.11711024545724,0.1845528092190285,-0.6825604589659267
338.2000000000041,39.223749515197646,0.18203724645560604,-0.6837666559565507
339.3000000000041,39.327638676900946,0.17919461724947172,-0.685540647883339
340.4000000000041,39.43367353341518,0.17619512553039388,-0.6868493507198403
341.50000000000415,39.53962631069092,0.17402070043128362,-0.6868501284408648
342.6000000000042,39.647768100511314,0.17133163230382548,-0.6893095570982175
343.7000000000042,39.75398450764258,0.17159681611456185,-0.6895013170330611
344.80000000000416,39.85730279638435,0.1685707213980441,-0.6913188212670214
345.9000000000042,39.96635196528439,0.1670910291952042,-0.6920411028262015
347.0000000000042,40.0723473086805,0.16354004500537375,-0.6934300748179014
348.10000000000423,40.17900286321937,0.16101103003853526,-0.6947482897868511
349.20000000000425,40.28463331297132,0.16363237428561817,-0.6954112881222172
350.3000000000043,40.39120551241711,0.16288416249007986,-0.6967298649510969
351.4000000000043,40.496728513104216,0.16247966830739577,-0.696729607277967
352.5000000000043,40.60358602461801,0.1606543366236658,-0.6980115284215316
353.60000000000434,40.70784731767022,0.16322833391565825,-0.6993604907655961
354.7000000000043,40.813805112496745,0.1629834784250192,-0.6979928525760593
355.80000000000433,40.920783648697864,0.16126126301836802,-0.7000262031868956
356.90000000000435,41.03085135566125,0.16292181674398198,-0.7000200601599285
358.0000000000044,41.135622617479356,0.16279964918757733,-0.7013303176857959
359.1000000000044,41.24277988247876,0.16564816598150478,-0.7013272747509682
360.2000000000044,41.349328046687084,0.16395685849724118,-0.7025949060544985
361.30000000000445,41.455330127835644,0.16376577848409235,-0.7033007555858366
362.4000000000044,41.56096868206603,0.16364927375663937,-0.702980158655861
363.50000000000443,41.66831151112494,0.16052353541254688,-0.7042885456558015
364.60000000000446,41.775337025481335,0.16013432435572525,-0.7066005904649999
365.7000000000045,41.88145026914184,0.16011557049797337,-0.7065999695000231
366.8000000000045,41.98831280120407,0.15908805396248146,-0.7079220973450324
367.9000000000045,42.09601683707967,0.1585204590985867,-0.7079198589970925
369.00000000000455,42.2022289453759,0.1600050080450291,-0.7079196750962113
370.10000000000457,42.30894353038879,0.1562999023697414,-0.7092301059248918
371.2000000000046,42.41577360246207,0.15599595683278747,-0.7078101614308099
372.30000000000456,42.52225441471008,0.15731901901502882,-0.710549191117912
373.4000000000046,42.629302712782874,0.15579346845066253,-0.7108937887014264
374.5000000000046,42.73569341566402,0.1564626384473216,-0.7111999840420293
375.6000000000046,42.84185645093547,0.15590970331568596,-0.7112024455159123
376.70000000000465,42.946980350724594,0.1558829490175589,-0.7121901410894846
377.8000000000047,43.055701776299365,0.156635430099534,-0.71210210357465
378.9000000000047,43.162890465465814,0.15378398384349412,-0.713510169823055
380.00000000000466,43.269693080655024,0.15519882615679345,-0.713510166999991
381.1000000000047,43.375969760392024,0.1585423002383367,-0.7135102913985798
382.2000000000047,43.482975291308485,0.15701762190820354,-0.7148199662174068
383.30000000000473,43.59074002293494,0.15565922699123447,-0.7148140633948317
384.40000000000475,43.69722525679209,0.15629297026752215,-0.7171301156288719
385.5000000000048,43.80500442159821,0.15309206013009796,-0.7155825361639256
386.6000000000048,43.911291301914,0.15445240085501138,-0.7174357507445763
387.7000000000048,44.01862683249942,0.1546413482595245,-0.7187091371925671
388.80000000000484,44.12506170594493,0.15396114922897283,-0.7201044415614701
389.9000000000048,44.23226304942964,0.1530369986083252,-0.7191965877483542
391.00000000000483,44.339422806898156,0.15300142849903284,-0.7204200491472492
392.10000000000485,44.446482273837056,0.15255808314345984,-0.7211441237224103
393.2000000000049,44.55347327453764,0.15253003268518897,-0.7223996466235807
394.3000000000049,44.66089854720491,0.15135709544291368,-0.7230519486818858
395.4000000000049,44.76682406770438,0.15202190036507982,-0.7230309499867982
396.50000000000495,44.874369326110624,0.15145512776433676,-0.7237097691262586
397.6000000000049,44.98150534906045,0.15100059241714972,-0.7243506010717651
398.70000000000493,45.08921323738799,0.1512483908172866,-0.724632734256835
399.80000000000496,45.19616759668513,0.1508391606345951,-0.7256799572294592
400.900000000005,45.302174189243715,0.1477645873625319,-0.7271341708068428
402.000000000005,45.41051807309842,0.1518567464302055,-0.7289702937008196
403.100000000005,45.51780497928836,0.1468965501895773,-0.7302919684006097
404.20000000000505,45.625020198305755,0.14412064024713286,-0.7301974597160878
405.30000000000507,45.73262046178362,0.1437440209192374,-0.7306198686462957
406.4000000000051,45.840183430281925,0.14280895142581537,-0.7319399012120327
407.50000000000506,45.94693639982849,0.14506126188652213,-0.7332361690196016
408.6000000000051,46.05453723064554,0.14153931980844933,-0.7346732784811887
409.7000000000051,46.16246523698712,0.14223952044227156,-0.7359778356046265
410.8000000000051,46.26782934492802,0.1414916483503303,-0.737193893388302
411.90000000000515,46.37736805122623,0.13859805536884623,-0.7376377512075631
413.0000000000052,46.48422900083225,0.13625165406172113,-0.739882707984342
414.1000000000052,46.59199699675131,0.13776457545872545,-0.7424633887183312
415.20000000000516,46.69906121402829,0.14091589957919065,-0.7434677674338319
416.3000000000052,46.807191073599235,0.13871182613280766,-0.7440998467784565
417.4000000000052,46.91464790433833,0.13386140621453063,-0.745183181423037
418.50000000000523,47.02259803824535,0.13710867848637875,-0.7478463544616014
419.60000000000525,47.12937499440465,0.13977245246708903,-0.7491598927517709
420.7000000000053,47.23818385230643,0.1389400632273601,-0.7504797469439932
421.8000000000053,47.344995134133605,0.13498946121906552,-0.7517792120740698
422.9000000000053,47.452507855022795,0.13524506066399827,-0.7517054584522391
424.00000000000534,47.560851996956444,0.13917016122722925,-0.7544073792003907
425.1000000000053,47.668124188735696,0.13784046087165308,-0.7559346484214737
426.20000000000533,47.77621203935819,0.1388000507229058,-0.7583617040988666
427.30000000000535,47.88328931288283,0.13797416435091986,-0.7610182081300474
428.4000000000054,47.99112306825604,0.1384876474162991,-0.7630704253682481
429.5000000000054,48.09879495430441,0.1378850058630367,-0.7639116544267761
430.6000000000054,48.20702149797216,0.14095028522564892,-0.7666159270729476
431.70000000000545,48.31503626456323,0.14402498086672583,-0.769294911360058
432.8000000000054,48.42186666035049,0.14290112351118095,-0.7733194736247571
433.90000000000543,48.530512701540154,0.14455099107651082,-0.7760224080452756
435.00000000000546,48.637983607441456,0.14355455412062165,-0.7774086447176454
436.1000000000055,48.74664660376811,0.14916532195568585,-0.780088430650614
437.2000000000055,48.85339193165254,0.14835782088923066,-0.7840513494269725
438.3000000000055,48.961360939769925,0.1509186601790791,-0.788054618930353
439.40000000000555,49.067202895088265,0.15199540576281007,-0.7893976813632189
440.50000000000557,49.17704174723033,0.1558924862297026,-0.7941256766992102
441.6000000000056,49.284235550002855,0.15854480860346576,-0.798276786705931
442.70000000000556,49.392584467773545,0.1611323331465938,-0.8022906877882665
443.8000000000056,49.50079418174497,0.16023705258237675,-0.8037157850681869
444.9000000000056,49.608154502173434,0.16852032800679304,-0.807749994539293
446.0000000000056,49.715518946008174,0.1705678381351199,-0.8119549118892997
447.10000000000565,49.82403101927828,0.17488402420482657,-0.815928296969485
448.2000000000057,49.93231582086296,0.17824457473306443,-0.8210957248812214
449.3000000000057,50.03959658287896,0.18086725262065634,-0.8252876654556931
450.40000000000566,50.14767244659338,0.18368055234559513,-0.8285436793900107
451.5000000000057,50.25611218956232,0.18655276490361417,-0.8331599176751832
452.6000000000057,50.36468861319741,0.19513004739690515,-0.8376630094350053
453.70000000000573,50.47286109530493,0.1968017604654102,-0.8425146624470199
454.80000000000575,50.5804893154393,0.1988626658771251,-0.8460470357850522
455.9000000000058,50.689467175132805,0.20502408474737752,-0.8534758175351045
457.0000000000058,50.797413727144736,0.20785938891886702,-0.8565175391592565
458.1000000000058,50.90573119004423,0.21098754075555914,-0.8608184569542865
459.20000000000584,51.0141146866162,0.2161132054699056,-0.8651066962820768
460.3000000000058,51.122605441779015,0.21941422755136258,-0.8697062236274684
461.40000000000583,51.23092144744389,0.22204646160342223,-0.8734148716785963
462.50000000000585,51.339160489225236,0.2258830901754797,-0.8785393973392286
463.6000000000059,51.44806574133651,0.22982902927936516,-0.8834730636019454
464.7000000000059,51.55620870637373,0.22866281861270793,-0.8859258476598657
465.8000000000059,51.66405164282039,0.2338296120088746,-0.8906119871895761
466.90000000000595,51.77309289369461,0.23522331895741055,-0.8960090615637242
468.0000000000059,51.88085788736818,0.23903718572826127,-0.8994237127012554
469.10000000000593,51.98981454254715,0.23887650915625583,-0.9033608641690605
470.20000000000596,52.09882900585025,0.24170195429941688,-0.9083300725171686
471.300000000006,52.20655786605192,0.2421829563208093,-0.9125993529958998
472.400000000006,52.31607891183624,0.2445593513498359,-0.9167145969264778
473.500000000006,52.42387898451598,0.24656099922230598,-0.9194776154357407
474.60000000000605,52.53240308001058,0.25084289608992894,-0.9220941954636475
475.70000000000607,52.63819131138233,0.24858864603189462,-0.9251052558409372
476.8000000000061,52.74732346302228,0.2523791414291212,-0.9290541978408999
477.90000000000606,52.8558662054,0.2520771697693601,-0.9319163622240034
479.0000000000061,52.964828974580364,0.25557313121425773,-0.9345626093438542
480.1000000000061,53.072276117301925,0.2573154815636609,-0.9387804101738455
481.2000000000061,53.18165194559632,0.2565216537550832,-0.9414559683060375
482.30000000000615,53.28880755480295,0.25927877682258826,-0.9442027291006467
483.4000000000062,53.39780859230389,0.25999813684585527,-0.9468612576199122
484.5000000000062,53.506358091766835,0.26087752798573116,-0.9481520889796466
485.60000000000616,53.61445763103045,0.2620458860400382,-0.9507495214740169
486.7000000000062,53.72294182034863,0.26364558775643265,-0.9534938154773331
487.8000000000062,53.83259506288749,0.2618838348306181,-0.9547121306891571
488.90000000000623,53.9416461268205,0.26267977484752725,-0.9560411420665864
490.00000000000625,54.049808503433006,0.26426752137064036,-0.9586525704918616
491.1000000000063,54.15884570669963,0.2647725641191072,-0.9604433418152061
492.2000000000063,54.267411912530626,0.2626400120212582,-0.9620261186661647
493.3000000000063,54.37651208955797,0.26774675643595053,-0.9652375384099336
494.40000000000634,54.48477366882469,0.26412364262821214,-0.9665630206846298
495.5000000000063,54.593119556214965,0.2652094043937653,-0.9674680940402598
496.60000000000633,54.702094920196,0.26401387202236876,-0.968184547002831
497.70000000000636,54.810385934308734,0.2648182811056226,-0.969209452937656
498.8000000000064,54.917795695500594,0.2659108255405672,-0.9718191039706259
499.9000000000064,55.02771278756947,0.26372388773584693,-0.9728649446850768
501.0000000000064,55.13627090796231,0.2705464724729662,-0.973106832843142
502.10000000000645,55.2454973569948,0.2662385607004239,-0.9757705561890488
503.2000000000064,55.354189711051,0.2712991102374789,-0.9757263655616537
504.30000000000643,55.462962527997576,0.26817391112252303,-0.9760480789428021
505.40000000000646,55.57227354465432,0.27168890201814966,-0.9770440189223155
506.5000000000065,55.681118370909786,0.27395415318416455,-0.9784052301771924
507.6000000000065,55.790515506517856,0.27369969987326553,-0.9797203398752634
508.7000000000065,55.899280150481,0.27448492468602004,-0.9823276879929792
509.80000000000655,56.008804438522525,0.27558219973251474,-0.9826724044390134
510.90000000000657,56.117886366672714,0.27562167748239197,-0.9840017542936828
512.0000000000066,56.2261431762769,0.2791986965265369,-0.9853938606860408
513.1000000000065,56.33563152756371,0.28019962761474204,-0.9882692505738171
514.2000000000066,56.445573702991595,0.28188394850554954,-0.9895898846507598
515.3000000000065,56.55453845616217,0.28654712337752675,-0.9895881121486862
516.4000000000067,56.663300146194,0.2894500915816404,-0.9922091022966022
517.5000000000066,56.77121793668637,0.2931501188424704,-0.9909003498269304
518.6000000000067,56.88163269348807,0.2985798825508025,-0.993522959323426
519.7000000000066,56.99170611152569,0.3022052631777304,-0.9948629874233004
520.8000000000067,57.100685341563505,0.3048021894303943,-0.9948493931418358
521.9000000000067,57.20886690265125,0.3111081182713264,-0.996180623310837
523.0000000000067,57.319676853231435,0.3184123019202677,-0.9981462251485342
524.1000000000067,57.42842077408292,0.32647853567852664,-0.9987950777372046
525.2000000000068,57.537023610708374,0.3365187035239432,-1.0000299495349068
526.3000000000068,57.645688526604665,0.3418841479971775,-1.002395300133128
527.4000000000068,57.75540642629949,0.351578694331493,-1.0037446124405602
528.5000000000068,57.86443376112361,0.36201499989200286,-1.006475126113783
529.6000000000068,57.97152460647948,0.38751978750335936,-1.0076943751517042
530.7000000000069,58.08216847262004,0.40102598456854294,-1.009072374326001
531.8000000000068,58.19178593574802,0.4039064060889659,-1.0093385835672741
532.9000000000069,58.3021975711972,0.4086468338848661,-1.0132913021999195
534.0000000000068,58.41062270203309,0.4107816793376518,-1.014608985688584
535.100000000007,58.520300844781396,0.410121627813818,-1.014589722680443
536.2000000000069,58.628960659656514,0.4137309048193603,-1.0172762217552527
537.300000000007,58.739699564545404,0.41321924610600613,-1.019966231820943
538.4000000000069,58.849519389807256,0.41115447619433887,-1.0199708589615026
539.5000000000069,58.95872415932534,0.41193544637649776,-1.0212319760037598
540.600000000007,59.06795783725341,0.41474707133563876,-1.0239187189994943
541.700000000007,59.1779667786311,0.4146055651764016,-1.0254365060204895
542.800000000007,59.28663981250181,0.4133588608047836,-1.0278542956465566
543.900000000007,59.39656537214647,0.4112001925841911,-1.028598618983565
545.000000000007,59.50664319433454,0.40899594116823756,-1.030870678753415
546.1000000000071,59.61678624383589,0.4140540612994237,-1.0328618770856024
547.2000000000071,59.72578628487908,0.41233444322057894,-1.0346665998662705
548.300000000007,59.83571293673032,0.4161466793986301,-1.0371583295187543
549.4000000000071,59.9449018967053,0.4165652688199827,-1.0383133431227192
550.500000000007,60.05457274977994,0.4170010607389977,-1.0410362059305571
551.6000000000072,60.1643423485896,0.41890035392733543,-1.043140187745438
552.7000000000071,60.27343411664134,0.4258619285741683,-1.0436910103502757
553.8000000000072,60.38349432625844,0.426628302157744,-1.0465680672101851
554.9000000000071,60.49297201577604,0.4309027135478905,-1.049723002020949
556.0000000000072,60.60217047497043,0.43669931720617516,-1.0509699806617685
557.1000000000072,60.712043889449426,0.4403654125344404,-1.0523162939399788
558.2000000000072,60.822121093462435,0.44426797981273736,-1.0550329809527623
559.3000000000072,60.93116239395533,0.44757833491100874,-1.0552789011730193
560.4000000000073,61.04171604056432,0.4534610367025557,-1.0592411193739242
561.5000000000073,61.151153468899125,0.46171113653138196,-1.0619104373905541
562.6000000000073,61.261121337158784,0.4642133694058681,-1.0636268807695806
563.7000000000073,61.37090185274163,0.47321437253339893,-1.0660046293323555
564.8000000000073,61.480213072172525,0.47840901966537297,-1.0685610753970969
565.9000000000074,61.59107937611028,0.48280603363424107,-1.0698994808821434
567.0000000000074,61.700412575739534,0.4870204036460317,-1.071192389741495
568.1000000000074,61.810748798560915,0.4939055950162212,-1.0739327989276637
569.2000000000073,61.92117688995048,0.5021625754055401,-1.0765532698805775
570.3000000000073,62.0312581574221,0.5128354078723787,-1.079198881138773
571.4000000000074,62.14128805147276,0.5214443429197959,-1.0818235129351983
572.5000000000074,62.25186351549028,0.5353773822487575,-1.0847113164206528
573.6000000000074,62.361763437181295,0.5477089271155682,-1.088891553833899
574.7000000000074,62.47233357410905,0.5609049869465614,-1.0901702446396113
575.8000000000075,62.58212722704486,0.5796716531863726,-1.093156837793233
576.9000000000075,62.691519556465245,0.5963518228354954,-1.0979790924050254
578.0000000000075,62.80236262098409,0.6132477264122622,-1.101227202411026
579.1000000000075,62.912661050093135,0.6293413172009705,-1.1034716074557709
580.2000000000075,63.02292638000566,0.634840954544321,-1.1082606015496226
581.3000000000076,63.1328720527589,0.6400933441215768,-1.111188832920249
582.4000000000076,63.243523806380225,0.6396409638373262,-1.1156455973495847
583.5000000000076,63.354131311885105,0.6278491338644195,-1.1198450983280885
584.6000000000076,63.46465953029962,0.5968823458006931,-1.1230926990241765
585.7000000000077,63.57499375699539,0.5316133383648656,-1.1270747478377654
586.8000000000077,63.68477084953486,0.4673012255151241,-1.132512093356043
587.9000000000076,63.794466195430935,0.41332562446099336,-1.13389447457903
589.0000000000076,63.90382315889863,0.37528867835896934,-1.1351444981030974
590.1000000000076,64.01258483745958,0.35098320621394985,-1.1351378387520619
591.2000000000077,64.12175882131406,0.339105835568834,-1.1351399423068846
592.3000000000077,64.2326934617671,0.3276867659395683,-1.1364480328114475
593.4000000000077,64.34188653472935,0.32068003495263697,-1.137772056391095
594.5000000000077,64.45418638994725,0.3173693750759914,-1.137134876065668
595.6000000000078,64.563763879002,0.313368783084735,-1.1390880079765537
596.7000000000078,64.67374145226144,0.30909044885452897,-1.1390899562904915
597.8000000000078,64.78364589078278,0.30905951368583695,-1.1400657267922667
598.9000000000078,64.89360396039875,0.3119397855607341,-1.1404091474629339
600.0000000000078,65.00439354518686,0.32171941871212195,-1.1413982538570413
601.1000000000079,65.11481631979603,0.3289375461257534,-1.1415196006104789
602.2000000000079,65.22493147968441,0.33926095289146724,-1.1426806380727195
603.3000000000079,65.33525359274667,0.35319396919224394,-1.14436040529249
604.4000000000078,65.4457714187956,0.3607520604196767,-1.1443609151723084
605.5000000000078,65.55637398964133,0.37634996023559786,-1.1446687459148723
606.6000000000079,65.66682431750324,0.3892486590124519,-1.1481521257309235
607.7000000000079,65.77667834818052,0.39904950079180923,-1.14806679418759
608.8000000000079,65.8873328389175,0.4150143055441126,-1.1480798356477613
609.9000000000079,65.99718665140897,0.42569878590993865,-1.1493998575074893
611.000000000008,66.10762737102004,0.4351129223498184,-1.1495197217640296
612.100000000008,66.21831304544988,0.4432426085360294,-1.1517244956862562
613.200000000008,66.32836433868341,0.45468877368809507,-1.1563574906761844
614.300000000008,66.43824330782616,0.4640989203424209,-1.1554926388772508
615.400000000008,66.54953039852712,0.4771623997984248,-1.157019855927821
616.5000000000081,66.65927695322242,0.4873043857770043,-1.1573006153636052
617.6000000000081,66.76988793189545,0.4990769356607316,-1.1609151344930448
618.7000000000081,66.88020789897134,0.51033117562351,-1.162587335458047
619.8000000000081,66.99189456340058,0.5203777997953639,-1.1648336340127208
620.9000000000082,67.10135339271214,0.5341875128345848,-1.1656620557318567
622.0000000000082,67.21263027495111,0.5425840404530866,-1.1677778161110242
623.1000000000081,67.32259865148464,0.5565069589356668,-1.170662034118107
624.2000000000081,67.4331206036367,0.5681154801605022,-1.1730920566434184
625.3000000000081,67.54368810732655,0.5831527464915607,-1.175577696273967
626.4000000000082,67.65370585947436,0.5946398107580088,-1.177958282455799
627.5000000000082,67.76475801325066,0.6115300082615424,-1.1807275022725467
628.6000000000082,67.87405684412464,0.6250275499832321,-1.183461537323475
629.7000000000082,67.98482015774229,0.636881563979968,-1.1860800683047827
630.8000000000083,68.09542452859027,0.6547538282735106,-1.188676335636579
631.9000000000083,68.20706488551252,0.6679725685627287,-1.191330760565057
633.0000000000083,68.3174333481832,0.6821453146880694,-1.1956615755399262
634.1000000000083,68.42770893613118,0.7019044190499296,-1.1976199776348193
635.2000000000083,68.5381919165619,0.717026015455336,-1.2017919217490056
636.3000000000084,68.64971743260601,0.7371945466524252,-1.206330145711799
637.4000000000084,68.76111153610269,0.7546206959026027,-1.2104504763668142
638.5000000000084,68.87126623561295,0.7751334060998981,-1.2155156728844223
639.6000000000083,68.9813634238287,0.7919107857410427,-1.2174665647919811
640.7000000000083,69.09209176497215,0.8124378238051874,-1.223094627954294
641.8000000000084,69.20293355918051,0.8307149969146339,-1.2285923557365042
642.9000000000084,69.31376401509932,0.8521651805258667,-1.2326564272113227
644.0000000000084,69.42384298447958,0.8725863241226238,-1.236090057738894
645.1000000000084,69.53409500852219,0.8934277039795117,-1.2409454983801362
646.2000000000085,69.64532065944927,0.9161292362884327,-1.2451782187883618
647.3000000000085,69.75547125763003,0.9388898083263485,-1.2489010966120588
648.4000000000085,69.8660995625589,0.9590811219670617,-1.254231008843914
649.5000000000085,69.97710690338803,0.9780869195090457,-1.2594562171292165
650.6000000000085,70.08805047466322,1.0004193207269387,-1.26358931657342
651.7000000000086,70.19935693764128,1.0239845830929406,-1.269852338831405
652.8000000000086,70.31009314372437,1.0432623539428367,-1.2760897854354614
653.9000000000086,70.4203852193257,1.0609403433390692,-1.2820374153767635
655.0000000000086,70.52934693252794,1.0854661057097585,-1.287433419669144
656.1000000000087,70.6402924136444,1.1014577491436794,-1.2925488419816071
657.2000000000087,70.752731299988,1.1202733116128583,-1.2967600264629255
658.3000000000086,70.86351894893713,1.1404841348911514,-1.3026675761301059
659.4000000000086,70.974247204891,1.158159432737418,-1.3090577587608467
660.5000000000086,71.08432742736576,1.1771148913101064,-1.3155583484847622
661.6000000000087,71.1952389232511,1.1980693993519194,-1.3198776869912772
662.7000000000087,71.30668976899815,1.2219784036734662,-1.3288600258655396
663.8000000000087,71.4174440089572,1.2496872328736581,-1.3331569389384499
664.9000000000087,71.52838446594313,1.2777886873816597,-1.3407105569104587
666.0000000000088,71.64029612721697,1.3091202159818218,-1.3470576273379558
667.1000000000088,71.75169315826385,1.3440610898685215,-1.3536672931265894
668.2000000000088,71.86173298227659,1.3856869512100034,-1.3623750635347966
669.3000000000088,71.97249678654062,1.4336898992038076,-1.3660161317722257
670.4000000000088,72.08320988611266,1.4793270031018628,-1.3743288644237945
671.5000000000089,72.19459991965324,1.5411549126339255,-1.3828489045664014
672.6000000000089,72.3064108268532,1.5982949440533987,-1.3899735332485963
673.7000000000089,72.41725874900105,1.6563777515090974,-1.3988025908783248
674.8000000000088,72.52945932940351,1.7165032697420088,-1.4077935891625124
675.9000000000088,72.63941262534007,1.7865770311333895,-1.4177729388927434
677.0000000000089,72.749561059639,1.8559414449973242,-1.4278729167456667
678.1000000000089,72.86090321121087,1.928764503090128,-1.4366823965401485
679.2000000000089,72.97263816832721,2.006026387812144,-1.4485538868611534
680.3000000000089,73.08423637676232,2.0915606215821967,-1.4585394911363148
681.400000000009,73.19627594519302,2.1928428477104958,-1.470158128862535
682.500000000009,73.30737921869506,2.2928346389298166,-1.4823502913767
683.600000000009,73.41878416251738,2.412679428012922,-1.4954402481707754
684.700000000009,73.53031890707909,2.541477153451919,-1.5076815533405457
685.800000000009,73.64163797041887,2.6705562080229983,-1.5236631618147358
686.9000000000091,73.75450541544531,2.775936284151065,-1.5380913563251042
688.0000000000091,73.86479615881727,2.8285646533137703,-1.5528287079163694
689.1000000000091,73.97636207269679,2.837522934608945,-1.5683116063224825
690.2000000000091,74.0881364606843,2.8336074321305715,-1.5837363857842206
691.3000000000092,74.19940370667248,2.846753411781806,-1.6013557124393194
692.4000000000092,74.30989191803177,2.8732018425226387,-1.617844393500456
693.5000000000091,74.42063173963942,2.91072039680261,-1.637667140813042
694.6000000000091,74.53287395895958,2.954192953372316,-1.6537062639695455
695.7000000000091,74.64433899178033,2.998360708306696,-1.6724160672914001
696.8000000000092,74.75520896130983,3.044047612289332,-1.691052522450542
697.9000000000092,74.86712134169763,3.0939532422566316,-1.7089458134722002
699.0000000000092,74.97748322521143,3.143323117343965,-1.7280709236194491
700.1000000000092,75.08919042512399,3.195592406723893,-1.747880639709932
701.2000000000093,75.20122353816846,3.2425549561945903,-1.76808453178975
702.3000000000093,75.31222669983383,3.288858506307495,-1.787573248974037
703.4000000000093,75.42414169805902,3.328961723369951,-1.8092394401919183
704.5000000000093,75.53536593518338,3.358823489986277,-1.8274989254848064
705.6000000000093,75.64738131314094,3.387759812629409,-1.8496823007784324
706.7000000000094,75.7578440538106,3.402296982536463,-1.8705833897568045
707.8000000000094,75.86919731426624,3.4015672618785304,-1.8932315618630455
708.9000000000094,75.98031378313124,3.380404783467645,-1.913967717797033
710.0000000000093,76.09173490397622,3.327146083163716,-1.9349129008183583
711.1000000000093,76.20300412990426,3.235435265778926,-1.9553607195886356
712.2000000000094,76.31291052531854,3.086329788449701,-1.9740584830164707
713.3000000000094,76.42482557858648,2.818966477566555,-1.9924304444395589
714.4000000000094,76.53529953453516,2.396242646483791,-2.009577505467434
715.5000000000094,76.64517644806264,1.7724647354831022,-2.0239646034015344
716.6000000000095,76.75450523342957,0.9463268766982406,-2.0337105969764115
717.7000000000095,76.86402757366723,0.47644215992556505,-2.040573069881495
718.8000000000095,76.97362256532625,0.377772419267581,-2.043108933053114
719.9000000000095,77.08433945584973,0.3168282629834016,-2.043120093407788
721.0000000000095,77.19254803606339,0.2892015518355656,-2.0441103382218317
722.1000000000096,77.30559837257732,0.28309264798277467,-2.0441125362284325
723.2000000000096,77.41634750054732,0.28490329691130356,-2.044170618273851
724.3000000000096,77.5278774492875,0.280289764161479,-2.044109869994685
725.4000000000096,77.63857192185066,0.2755626027256889,-2.044088544286717
726.5000000000097,77.74968196150618,0.27461599820345894,-2.044439991087774
727.6000000000097,77.86150431466778,0.2695620827702855,-2.044490748206544
728.7000000000096,77.97334840305399,0.2676360029919225,-2.044440159007464
729.8000000000096,78.08371408265522,0.2619827992678213,-2.0443954723182625
730.9000000000096,78.19630811858362,0.25871435217761096,-2.045760052097754
732.0000000000097,78.3087007267975,0.255577790847036,-2.0457600212049094
733.1000000000097,78.42000195749486,0.2520012960558182,-2.044440037059845
734.2000000000097,78.53117358984535,0.24824191874335044,-2.045759953825816
735.3000000000097,78.64315715664554,0.23882304946340094,-2.045759943007812
736.4000000000098,78.75474151222855,0.23818997811272746,-2.045738329683864
737.5000000000098,78.86566608580547,0.23958186786726898,-2.0470339281147196
738.6000000000098,78.97782935271643,0.23322614962000054,-2.045749862335783
739.7000000000098,79.0896025755568,0.22799591055128254,-2.047068258846782
740.8000000000098,79.20156057637047,0.23106566317948585,-2.047070145326093
741.9000000000099,79.31294671320263,0.22683836737961638,-2.045768060947016
743.0000000000099,79.42387233273959,0.21974286620693917,-2.048149217413319
744.1000000000099,79.53560044145871,0.22023996492439246,-2.0480500764892824
745.2000000000098,79.64632943321391,0.2157364777144697,-2.0490653649271464
746.3000000000098,79.75739466259698,0.2082536066183418,-2.0484813541579117
747.4000000000099,79.86904546772466,0.20736550286529876,-2.048389959958383
748.0000000000099,79.92990437986163,0.20649055686390794,-2.0483899542083193