File: 01_Data/Vinyl_Tile/STA/N2/10K_min/Vinyl_Tile_STA_N2_10KData_220506_R3.csv
##Temp./Â°C,Time/min,DSC/(mW/mg),Mass loss/mg
50.0,10.510691776756966,0.013049564494749255,0.04216073751419902
51.100000000000016,10.938587399637804,0.04874419402550978,0.04202717284642343
52.20000000000003,11.176285786729512,0.07752536262461063,0.04094994839171395
53.30000000000005,11.362369159697966,0.09836787188553386,0.041460032776904576
54.40000000000006,11.52675371836703,0.11587577106872227,0.04170644288700842
55.50000000000008,11.676170819874853,0.12987721310706057,0.04338388341257904
56.600000000000094,11.81742185566783,0.14144862929941704,0.0419623528111055
57.70000000000011,11.950837198344182,0.14999176762183275,0.04348753433390318
58.800000000000125,12.08191210946684,0.15526232525034556,0.04485619364255733
59.90000000000014,12.207654456458378,0.16266657230993575,0.04642758590087759
61.000000000000156,12.334471290133955,0.16791538911148596,0.046387639234414024
62.10000000000017,12.459202438396735,0.17363276385074644,0.04645644339033872
63.20000000000019,12.579503524614136,0.17578155429722597,0.04639955030110965
64.30000000000021,12.700103092741879,0.1782912541342644,0.047713015244930546
65.40000000000022,12.820593548292956,0.18059324481248185,0.046292496351711065
66.50000000000023,12.939011756248268,0.18143931337094243,0.0476168468961502
67.60000000000025,13.057710675385962,0.1825554803017484,0.04758948709009658
68.70000000000027,13.177198289173807,0.18596597270408954,0.047606984150807996
69.80000000000028,13.293574362380973,0.18642821529930054,0.047524973845938234
70.90000000000029,13.410681567166085,0.18770802683053323,0.04892001555034842
72.00000000000031,13.52604934394119,0.1906755746748523,0.04860183919699512
73.10000000000034,13.643082738571861,0.19256152680768834,0.047601513305709275
74.20000000000034,13.758762032528715,0.1938471301563347,0.04759599693555128
75.30000000000035,13.873728600721433,0.19411035595154502,0.0487878907569419
76.40000000000038,13.98809945582406,0.19865615725924413,0.04777509759809728
77.5000000000004,14.10216716659643,0.20068611468269915,0.050232358936719734
78.6000000000004,14.217794335850877,0.20229701156099922,0.04988569260692266
79.70000000000041,14.330990365012532,0.20375699303338557,0.050231693806570554
80.80000000000044,14.444764456630645,0.20565027784095213,0.05023262625749947
81.90000000000046,14.556110898683311,0.20414239922319344,0.0502381817593216
83.00000000000047,14.668934168419668,0.20683327460001244,0.05080420371557892
84.10000000000048,14.780532641570542,0.20838522906077495,0.051560259364705985
85.2000000000005,14.892810972280248,0.21013314417758056,0.05022874486568618
86.30000000000052,15.004201896878827,0.21150474401409858,0.05100100503074678
87.40000000000053,15.114615195806119,0.21356012988499773,0.05145976338259928
88.50000000000054,15.226745173490585,0.2150203114967535,0.05154978087444828
89.60000000000056,15.33585708708108,0.21836284706175602,0.05154258553139801
90.70000000000059,15.446181111699577,0.2173608896793131,0.052197927626298046
91.8000000000006,15.555104491177648,0.21885456093449163,0.05293435196515617
92.9000000000006,15.666305819695198,0.22073390260806502,0.05144328835431011
94.00000000000063,15.775970028096106,0.22142857624411372,0.05154721197310419
95.10000000000065,15.885274172065257,0.22277365747373679,0.05155000452466929
96.20000000000066,15.99384452698811,0.2255172322676101,0.05286887052878697
97.30000000000067,16.102172233594573,0.22451475748886518,0.05287298001349594
98.40000000000069,16.21068104495432,0.22739858200716756,0.05287020708342105
99.50000000000071,16.319012657425777,0.2296811856637625,0.052762506088072314
100.60000000000072,16.428629409882802,0.23008675817898916,0.052859941320593684
101.70000000000073,16.5359072324193,0.23098842050312607,0.054177023500260546
102.80000000000075,16.644172663131485,0.23177199299522533,0.05418709965939339
103.90000000000077,16.752819301917167,0.23294740907871148,0.054179998564610976
105.00000000000078,16.85972856993064,0.23562998000806012,0.05417901263675695
106.10000000000079,16.968576763474857,0.23542393414408325,0.055170241321608415
107.20000000000081,17.075675122851475,0.23893565061198618,0.05384951564873841
108.30000000000084,17.182945187521522,0.23826310811033202,0.05384994608293692
109.40000000000084,17.290569389778454,0.2393723418920699,0.052541262305509484
110.50000000000085,17.398590817900406,0.24271743232579635,0.05418115282775826
111.60000000000088,17.504663551099334,0.24412916529365092,0.0555061428689001
112.7000000000009,17.613669754068308,0.2441454131174411,0.056188206322786094
113.8000000000009,17.720304016994387,0.24504710192794743,0.05550012800528403
114.90000000000092,17.827411012966028,0.24731993948135522,0.054520579827568305
116.00000000000094,17.934978404639452,0.24844372881883026,0.054479802301109714
117.10000000000096,18.043304674781165,0.24632464914858898,0.05583200895828444
118.20000000000097,18.14928034144538,0.2480868543252408,0.05549823032067103
119.30000000000098,18.256756594309607,0.2463411060733085,0.05550494246123794
120.400000000001,18.363670765428385,0.24924370002125085,0.05448594226915926
121.50000000000102,18.47045589766647,0.24998611848199548,0.05548993819310866
122.60000000000103,18.578814275479246,0.25215155634518205,0.05504446988217637
123.70000000000104,18.685582685585516,0.2510491370516492,0.05549987001140355
124.80000000000106,18.791152176492073,0.25374939241984235,0.05549987235773646
125.90000000000109,18.899320397163315,0.25634565572941764,0.05682474421080119
127.0000000000011,19.00493372270126,0.2555827818197923,0.05550017401700824
128.1000000000011,19.111695293301594,0.2583926690492566,0.056565237416950964
129.20000000000113,19.21838389121096,0.25979066392048245,0.056480486241349936
130.30000000000115,19.324540668535644,0.26229422295651533,0.05516064744948679
131.40000000000117,19.43124925932834,0.26113879450714556,0.05681433307830197
132.50000000000117,19.537996400978486,0.2631815424954362,0.05678368357619856
133.6000000000012,19.644834163090394,0.26237543860677065,0.056809834922618485
134.7000000000012,19.75099706648022,0.2626286741109492,0.056814543350721
135.8000000000012,19.856754784127833,0.2638800104251888,0.05682284160722251
136.90000000000123,19.963196572910533,0.2632786672422871,0.05649006914998811
138.00000000000125,20.069898742917154,0.263391777589721,0.057799918901885405
139.10000000000127,20.176590104808756,0.26481341261287383,0.057822610977776634
140.2000000000013,20.283164342494043,0.26668809461968845,0.05647987368839669
141.3000000000013,20.388457947940672,0.2650794621899789,0.05648488626126014
142.4000000000013,20.494478615541166,0.26985997523943894,0.05649013000681613
143.50000000000134,20.59961376282313,0.27142084577138037,0.05649012178479129
144.60000000000133,20.70746336375414,0.2707194516049845,0.057811653028671195
145.70000000000135,20.812129973710555,0.2712855969826676,0.0584440213819617
146.80000000000138,20.918149817252736,0.27362035653171923,0.05714005259741484
147.9000000000014,21.02377675329335,0.27156471680821703,0.05714012416928416
149.00000000000142,21.128924843083993,0.2748350674590233,0.057800107799834244
150.10000000000142,21.234561587783016,0.27320393792089354,0.05780061820739668
151.20000000000144,21.340607725145457,0.27425035218015104,0.05779029511049938
152.30000000000146,21.446252227723356,0.2742071110354998,0.056490096760756
153.40000000000146,21.550824582107268,0.2746921742204599,0.05653761313844541
154.50000000000148,21.656568341118614,0.27418715183831094,0.05680984227141472
155.6000000000015,21.762331009778435,0.2760121997592468,0.05648077097881998
156.70000000000152,21.868110749170043,0.27792089857614577,0.056482497035604595
157.80000000000155,21.973629696203485,0.2779601055844967,0.057800080934954146
158.90000000000154,22.07932323874079,0.27931963321906256,0.057679777522304576
160.00000000000156,22.18496598867414,0.2838537946186525,0.057508698437640504
161.1000000000016,22.29009680342404,0.28168540372771067,0.057139830157409754
162.20000000000158,22.395536133688054,0.2823685545456667,0.056832845750273364
163.3000000000016,22.49990302630504,0.2840351768699301,0.05748426542460994
164.40000000000163,22.6052648043471,0.28598093150069254,0.05615997068116041
165.50000000000165,22.711212736330726,0.28793134019555255,0.0561562281494048
166.60000000000167,22.815665416977918,0.2879647793411986,0.05713963454193394
167.70000000000167,22.921767208823415,0.2873776675187276,0.05581999064926091
168.8000000000017,23.025889008677478,0.28776384184059134,0.05582008500013558
169.9000000000017,23.132069249849817,0.2920742670152107,0.055820085000497066
171.0000000000017,23.237392866001553,0.28955263917927876,0.055820983420033166
172.10000000000173,23.342843953012476,0.29249543600796307,0.05484066667258514
173.20000000000175,23.446964938485422,0.2956349663145018,0.05489870177441425
174.30000000000177,23.55196529086175,0.29468740550231803,0.05352703862325381
175.4000000000018,23.658152848541725,0.29527707717438767,0.05492582527431189
176.5000000000018,23.7624142057801,0.2941976705021471,0.05345606153275462
177.6000000000018,23.867390300561322,0.29724175949458437,0.054840055164005364
178.70000000000184,23.97351471144996,0.2989764052033685,0.054840054999999666
179.80000000000183,24.07833431035935,0.29772078677288216,0.054840054997128185
180.90000000000185,24.183541510404247,0.2994788552968985,0.05483836717742374
182.00000000000188,24.287918915982114,0.30007228725669555,0.054839905014755885
183.1000000000019,24.393535996015732,0.2993967255026603,0.05483995000005493
184.20000000000192,24.497891074998194,0.3008737052534876,0.05483994999999986
185.30000000000192,24.60417433973865,0.3025930270719873,0.054839950069575316
186.40000000000194,24.70858453577119,0.303728475447701,0.05361900384435003
187.50000000000196,24.81349917122073,0.30249421374186436,0.05220995798331973
188.60000000000196,24.91706776705996,0.30652086252186556,0.05275903311086605
189.70000000000198,25.02344067686216,0.30408149696147646,0.05295122697264354
190.800000000002,25.127323422610274,0.30347283367691624,0.05188005589859568
191.90000000000202,25.232702189422138,0.30416910369056294,0.051941022551439175
193.00000000000205,25.337532736218694,0.3067098622542582,0.05252441806197794
194.10000000000204,25.4425362506377,0.3074238655601757,0.0512187549477785
195.20000000000206,25.547664093162368,0.30939799691576303,0.04989988752876151
196.3000000000021,25.6511751543198,0.30901755178721063,0.049899923178611694
197.40000000000208,25.75584229066662,0.31096942669408945,0.05089122653044331
198.5000000000021,25.861104008603306,0.31185265514063537,0.05085260467605224
199.60000000000213,25.96500538525033,0.31229627849181063,0.04956982572100177
200.70000000000215,26.07060939093686,0.31415406691295855,0.048257209546560986
201.80000000000217,26.17494672698728,0.31427714913771376,0.04825864660858059
202.90000000000217,26.27990809330543,0.31561124247256095,0.046950104009197524
204.0000000000022,26.384580549609016,0.3160613747417704,0.04760003876333574
205.1000000000022,26.488911101846973,0.3173616152071337,0.04734626180349544
206.2000000000022,26.592598867618825,0.31890616608483124,0.04726991143080639
207.30000000000223,26.69815144139407,0.31580624057852413,0.045597047859716966
208.40000000000225,26.8017964105044,0.31991888985121375,0.04414421619512954
209.50000000000227,26.90751523283256,0.3177798978831859,0.04332983869156859
210.6000000000023,27.011724075205162,0.3203715986013181,0.04235658941461473
211.7000000000023,27.115562676325847,0.3195448887209428,0.041949212864575536
212.8000000000023,27.22099874762871,0.3239117971552286,0.04196344088289994
213.90000000000234,27.326009257062616,0.32573588915520696,0.04069666576418651
215.00000000000233,27.43082014605823,0.32648412918012776,0.03805965809668521
216.10000000000235,27.53593490023205,0.3279160318621795,0.03673993114304963
217.20000000000238,27.64051531585431,0.32871792057286375,0.03671972285536107
218.3000000000024,27.745675271252722,0.32960486670299916,0.03411069415478174
219.40000000000242,27.850850230969478,0.33092155846784926,0.032789859875819616
220.50000000000242,27.95633150498174,0.3312598769250905,0.032760983642298847
221.60000000000244,28.059999050873255,0.3316569812045393,0.03015986630637979
222.70000000000246,28.164685514071447,0.333047197540314,0.028409018662792995
223.80000000000246,28.26971270769278,0.3349641634231853,0.027521197257601493
224.90000000000248,28.37515060952351,0.33671548500053566,0.02481706856804511
226.0000000000025,28.47971818210977,0.3406473702564995,0.022494552788215216
227.10000000000252,28.584643459835576,0.34095918498689815,0.02111675537833335
228.20000000000255,28.69059075885206,0.34358179563856056,0.019504299739733
229.30000000000254,28.79458316955138,0.3425102600261112,0.018195180847900616
230.40000000000256,28.899299722207946,0.3443067607477991,0.01596301815154444
231.5000000000026,29.004721308775782,0.3474133994821324,0.013453333351413299
232.60000000000258,29.109009976834763,0.3489021336205705,0.009575908153720114
233.7000000000026,29.21397006785139,0.3526454564092577,0.007862176689990896
234.80000000000263,29.319219084877393,0.3530871250002585,0.0049591534941093585
235.90000000000265,29.42437163783363,0.35711853786287706,0.0008702010598256038
237.00000000000267,29.527794370601093,0.35665079841912617,-0.0017465156958778039
238.10000000000267,29.63302150394342,0.35872530080936654,-0.0037265037570159976
239.2000000000027,29.738021559556152,0.3623385562938573,-0.007356699184431825
240.3000000000027,29.84135797799434,0.3639374455129709,-0.011061848388478346
241.4000000000027,29.946643590244136,0.3658469733880741,-0.01586763928247148
242.50000000000273,30.052491179981132,0.37003126100918304,-0.018520335093587192
243.60000000000275,30.156840170723974,0.37296331883394956,-0.022682625560769942
244.70000000000277,30.262147518628865,0.3752276997939191,-0.0269672017055278
245.8000000000028,30.365856239951164,0.3760094773496012,-0.03138589381556045
246.9000000000028,30.470785544114882,0.38042914800408933,-0.03569626636549206
248.0000000000028,30.57602446805932,0.38232711104004524,-0.04044727587226138
249.10000000000284,30.680443466574744,0.38262664127449847,-0.0451896471926716
250.20000000000283,30.78560345222691,0.385975708030004,-0.051030552783898564
251.30000000000285,30.89036073371884,0.38853675923322667,-0.055973250585786616
252.40000000000288,30.99500286249024,0.3915511178535068,-0.05983890034090411
253.5000000000029,31.10046894397596,0.39361121851001973,-0.06564683729362031
254.60000000000292,31.20484761083017,0.393120233039436,-0.07128063580166
255.70000000000292,31.30910988985864,0.39814171179618535,-0.07665976203866265
256.8000000000029,31.414752073661532,0.39595685171823386,-0.0833189259906999
257.90000000000293,31.5177996702063,0.3964031550865282,-0.08811849481437495
259.00000000000296,31.62365932909473,0.396438488283242,-0.09501890795166723
260.100000000003,31.72731228526044,0.3979702781589023,-0.10170107248817306
261.200000000003,31.832549882724816,0.3960358449326109,-0.10982469304015297
262.300000000003,31.9375352472776,0.3972162197381313,-0.11621710170524224
263.40000000000305,32.04190297533721,0.39688861139803533,-0.12241576467337012
264.50000000000307,32.147098986943334,0.3969578986039729,-0.13111162278569566
265.6000000000031,32.25251040525907,0.3952417596196974,-0.1374792619875813
266.7000000000031,32.35751023991086,0.3966259468253222,-0.14602367524988624
267.8000000000031,32.4626286123299,0.3939956894036015,-0.15495657165315802
268.9000000000031,32.56710255835225,0.3913802078594872,-0.16305089109278548
270.0000000000031,32.671400370429886,0.3916697775657105,-0.17255842015142786
271.10000000000315,32.77842599832372,0.3907429277019697,-0.18202865956393932
272.2000000000032,32.883309428366715,0.39100215292428,-0.19119755893863655
273.30000000000314,32.98806592119891,0.3877431228403785,-0.20137501467429342
274.40000000000316,33.0937146797235,0.3903315608183594,-0.21106184185699917
275.5000000000032,33.198049860072906,0.3945438557865459,-0.22241136437566889
276.6000000000032,33.30335530385043,0.3979178038000626,-0.23449018662097076
277.70000000000323,33.408901967918695,0.4035812961412801,-0.2466411932911199
278.80000000000325,33.51492485174067,0.4107550134248388,-0.25957247294647967
279.9000000000033,33.620406234642,0.41797164381273594,-0.27120076064176457
281.0000000000033,33.725934768285796,0.4318938484221817,-0.2849999331830042
282.1000000000033,33.8296733423155,0.44203295085931027,-0.29698659953731354
283.20000000000334,33.936640579761935,0.4497775340733605,-0.3120278801894347
284.30000000000337,34.04080399856333,0.4630582188064265,-0.32575576233116044
285.40000000000333,34.14642417543273,0.47597362869078014,-0.3398134072062242
286.50000000000335,34.252957037873635,0.48853837900514685,-0.3545146517465487
287.6000000000034,34.358111617237505,0.4940722917618777,-0.3673099364534993
288.7000000000034,34.46259144590246,0.501780023804706,-0.3803700688519154
289.8000000000034,34.56770511351011,0.505929637840743,-0.394609902223348
290.9000000000034,34.67314584000897,0.5063934844812201,-0.4069906008421946
292.0000000000034,34.778424248141896,0.5069309594091153,-0.4202726186288839
293.10000000000343,34.88496238501455,0.5045425653783235,-0.4318884054991772
294.20000000000346,34.990535876464925,0.5017488223765613,-0.4438673335697696
295.3000000000035,35.095246499116534,0.4966433548709741,-0.4556300535293678
296.4000000000035,35.20019294498537,0.48861780377962505,-0.46421865962698483
297.5000000000035,35.30591643471585,0.4795882306827938,-0.47473307864740333
298.60000000000355,35.41027432329691,0.47278806554129005,-0.48364033555147934
299.70000000000357,35.51562000242203,0.4611299164715963,-0.4907009649542653
300.8000000000036,35.621056722067216,0.4495182645178975,-0.4997653236023205
301.9000000000036,35.726914665308996,0.4403305212418564,-0.5060925044498568
303.0000000000036,35.83122499603897,0.4296746874388627,-0.5143031887384031
304.1000000000036,35.937096884490494,0.4180242263598138,-0.5196877473351056
305.2000000000036,36.041797711733665,0.40936709092028023,-0.5248231964260643
306.30000000000365,36.14722574144232,0.40309049628968385,-0.5319651257901619
307.4000000000037,36.252831013165554,0.3917620888122177,-0.5361065438795856
308.5000000000037,36.35875864646813,0.3875682191221151,-0.5409356674986672
309.60000000000366,36.46353921206073,0.3803880040598371,-0.5449996436957454
310.7000000000037,36.5688048346128,0.37406225079924366,-0.5505556050861311
311.8000000000037,36.67561182864665,0.3690739639560553,-0.5521558111660254
312.90000000000373,36.7800902621181,0.3627410792760313,-0.5567766576540478
314.00000000000375,36.885571471426665,0.3588041192027115,-0.5623055447287078
315.1000000000038,36.99081176282738,0.35509598548114263,-0.5658785286182941
316.2000000000038,37.09733050868399,0.35079127924275516,-0.569472302420031
317.3000000000038,37.20356162208565,0.3470675948232379,-0.573137906222636
318.40000000000384,37.308279013289706,0.3429026371377273,-0.573743703268073
319.5000000000038,37.413351103030514,0.3410723818680206,-0.5776660971038834
320.60000000000383,37.51989904792945,0.3390901155004108,-0.5802475190051668
321.70000000000385,37.62521877504744,0.33521187885990045,-0.5839999277289674
322.8000000000039,37.73079623522086,0.33413966340893386,-0.585782435636208
323.9000000000039,37.83671256598093,0.332228069536172,-0.5885799452348333
325.0000000000039,37.941675120026694,0.33029064426148563,-0.5909963195772621
326.10000000000394,38.04738846318869,0.33000687411557683,-0.5942923558158064
327.2000000000039,38.15445206048025,0.32899632780578825,-0.5950939656569703
328.30000000000393,38.259612187988026,0.33375661125507694,-0.598010060049412
329.40000000000396,38.36494625318685,0.33169166916760556,-0.5993204378040038
330.500000000004,38.470626454170734,0.3343627280763496,-0.6019625027169568
331.600000000004,38.576815406567384,0.3321027346844292,-0.6043477245769289
332.700000000004,38.68270018977806,0.33074355395566296,-0.6059164756234776
333.80000000000405,38.788521552685246,0.3285048992661973,-0.6072300278473928
334.90000000000407,38.89364375186025,0.32808789431812063,-0.6079270408428772
336.0000000000041,39.00099169436266,0.3273300799753092,-0.608585612915864
337.10000000000406,39.105730239264915,0.32834897421486003,-0.6108321505390149
338.2000000000041,39.211466228336114,0.325881285314927,-0.6124926388381104
339.3000000000041,39.31859527341826,0.32372217217994426,-0.6143512637023045
340.4000000000041,39.42353041753173,0.32030373376512516,-0.614516431703386
341.50000000000415,39.5303740780974,0.32052576595210835,-0.615121637669684
342.6000000000042,39.636149509350744,0.3200482949681694,-0.6164649424752904
343.7000000000042,39.742549358526,0.3202494494257821,-0.6177510145918061
344.80000000000416,39.847943421173476,0.3161490534714806,-0.6190701584043921
345.9000000000042,39.954071870036586,0.3175097903850836,-0.6203866516822485
347.0000000000042,40.06073253408513,0.3186231329285517,-0.620450573611067
348.10000000000423,40.16656977066661,0.31608338925650153,-0.6230190244896785
349.20000000000425,40.27197076390324,0.314465253825995,-0.6235494397845356
350.3000000000043,40.37927056632677,0.3119773677990541,-0.6230299374412578
351.4000000000043,40.485184268840776,0.31523453238223936,-0.6243475606994457
352.5000000000043,40.590931516051846,0.3152310023643283,-0.6253007093561336
353.60000000000434,40.69700887433558,0.3153996049208142,-0.6266444197909165
354.7000000000043,40.8042754010039,0.31563878615893903,-0.625318100763252
355.80000000000433,40.91105264277485,0.316833452355208,-0.6287003379143576
356.90000000000435,41.01679380094612,0.3150844023510302,-0.6288035159686096
358.0000000000044,41.12226650259185,0.3144956727022502,-0.6293795773250892
359.1000000000044,41.22989751037328,0.3116525899073945,-0.6305355130453316
360.2000000000044,41.336193133069486,0.3090157636790068,-0.6305901508807401
361.30000000000445,41.441451550160785,0.3023723035845129,-0.6301017175051102
362.4000000000044,41.548556379759965,0.29720420283279453,-0.6312501764028884
363.50000000000443,41.65583006456142,0.2972864776472836,-0.6312498180447355
364.60000000000446,41.76203860341178,0.2763242945727087,-0.6324163126211189
365.7000000000045,41.869210741946574,0.2666299691143306,-0.6319102985669489
366.8000000000045,41.97487707327735,0.2567593381243342,-0.6319197757968542
367.9000000000045,42.08206656586556,0.254975062185678,-0.6333936226346837
369.00000000000455,42.18872384510758,0.2503477553234279,-0.6328899362637777
370.10000000000457,42.295814677250256,0.2510813388764104,-0.6328508777101471
371.2000000000046,42.40264584895272,0.2477577628615753,-0.6345300970556385
372.30000000000456,42.509068994245716,0.24717990169653653,-0.634530225615173
373.4000000000046,42.61689236645333,0.24482506764057443,-0.635849383582443
374.5000000000046,42.72337313393724,0.2456657330108965,-0.6358506599075953
375.6000000000046,42.83180807323806,0.24222677483822053,-0.6371699179890484
376.70000000000465,42.937351132060904,0.2423068417729157,-0.637154361430921
377.8000000000047,43.04461960077115,0.24075882063644832,-0.6365331754990122
378.9000000000047,43.152013797889815,0.2426447640078869,-0.6378297646493607
380.00000000000466,43.2590573837575,0.24137226039900161,-0.6391500246748572
381.1000000000047,43.364960797813666,0.24055472742477643,-0.6386153715060909
382.2000000000047,43.47208043096568,0.23798312303768349,-0.6385740791729937
383.30000000000473,43.57857600019918,0.2405569312305756,-0.6391496633913438
384.40000000000475,43.685957288576475,0.2406448284307952,-0.6403493270771232
385.5000000000048,43.79352007873668,0.24049143617626687,-0.6428699136878864
386.6000000000048,43.898980310994105,0.24044372351351936,-0.6406202670543766
387.7000000000048,44.005458592685834,0.24100233868158313,-0.6427518612336001
388.80000000000484,44.11239491936883,0.23962705898359637,-0.6440828412576547
389.9000000000048,44.22070444474294,0.23993692585576243,-0.6451279512689947
391.00000000000483,44.326545531379615,0.239358838976597,-0.6444097905382344
392.10000000000485,44.43437125104925,0.23720952844553483,-0.6456457128796393
393.2000000000049,44.53971966975251,0.24060051444806993,-0.647039836144919
394.3000000000049,44.647201949071146,0.23832808151277082,-0.6481428977266246
395.4000000000049,44.75384180902415,0.23808085833130635,-0.649685799408767
396.50000000000495,44.86155792840552,0.23817826243122558,-0.649212138880281
397.6000000000049,44.96814853831392,0.23745889746687424,-0.6482500114411107
398.70000000000493,45.07520068945021,0.23823049280940156,-0.6495380675221658
399.80000000000496,45.18292068818476,0.2377998616539082,-0.6517695767233169
400.900000000005,45.29018733648954,0.23745311957058035,-0.6535098936888972
402.000000000005,45.3977614827391,0.23892800711709014,-0.6535146288763114
403.100000000005,45.505922373768705,0.23816666203249937,-0.6548362533714776
404.20000000000505,45.61154701831307,0.2353935086594626,-0.6551492820365512
405.30000000000507,45.71970390634838,0.236529489742667,-0.6571259883071576
406.4000000000051,45.82634038738769,0.23502275636287584,-0.6591354461226366
407.50000000000506,45.93375105571994,0.237291987108139,-0.6591014920647464
408.6000000000051,46.04164973750568,0.23188595125825928,-0.6604972567131155
409.7000000000051,46.148565327977444,0.23378962379157256,-0.6617398708074611
410.8000000000051,46.25641047621351,0.23483174230155218,-0.6630499111502672
411.90000000000515,46.3641477160916,0.23527346037938235,-0.6643127075375852
413.0000000000052,46.47119397951232,0.2351279804381915,-0.6670147652774543
414.1000000000052,46.57937048544098,0.23709683733313106,-0.6676787557525938
415.20000000000516,46.686054982832864,0.23824276539579659,-0.6681294402733999
416.3000000000052,46.793314516331584,0.23833846792333901,-0.6697900783346062
417.4000000000052,46.90168839952356,0.24130852525910967,-0.6720689344180073
418.50000000000523,47.008629024847224,0.24222275523128872,-0.6734856854649109
419.60000000000525,47.115782065638776,0.24144666697044653,-0.6748622811219582
420.7000000000053,47.224397257300794,0.2442627877623038,-0.6776100309479607
421.8000000000053,47.331998358355555,0.24265921644139338,-0.6789391967063167
422.9000000000053,47.438296248259476,0.2466285153691007,-0.6794999295172981
424.00000000000534,47.54775602922397,0.246043582629081,-0.6809565022707922
425.1000000000053,47.65458569827152,0.246415686313899,-0.683571062190643
426.20000000000533,47.762106481268574,0.24879769092107645,-0.6848807675542594
427.30000000000535,47.87021471166842,0.24990377180457837,-0.6875112147369835
428.4000000000054,47.97846412631839,0.2514432115484974,-0.6901554546512094
429.5000000000054,48.08657866730507,0.25434573795104204,-0.6921055627586741
430.6000000000054,48.19470371770579,0.2544964954347809,-0.6941080213730517
431.70000000000545,48.30243120393005,0.25563618378080377,-0.6967759882906286
432.8000000000054,48.41064084091282,0.2591588562760301,-0.6994631845072163
433.90000000000543,48.5175365482817,0.26041874745174576,-0.7019026200959337
435.00000000000546,48.62590611294498,0.26233799560444726,-0.7046819666307798
436.1000000000055,48.733556785059484,0.26474235533919516,-0.7074976581302579
437.2000000000055,48.841063176341024,0.2714390213792367,-0.7105571202886005
438.3000000000055,48.94809964362142,0.27119333063858453,-0.7133558480238409
439.40000000000555,49.05525865060102,0.27418616745928226,-0.7172820259365746
440.50000000000557,49.1641097399999,0.2806611183946912,-0.721404985594539
441.6000000000056,49.272586414056796,0.28194872781301755,-0.7240840084051303
442.70000000000556,49.38140945917728,0.2875489757001919,-0.7273613681050413
443.8000000000056,49.488786536428705,0.2909558492112679,-0.7309177133037741
444.9000000000056,49.59573288032895,0.2973488960616607,-0.7350251315023058
446.0000000000056,49.70388453852892,0.3007784542989761,-0.7393916884388658
447.10000000000565,49.81194479863211,0.3044674283841506,-0.7453912607802913
448.2000000000057,49.92035185481398,0.3076654763825108,-0.7475553666670054
449.3000000000057,50.02816589694876,0.31110616142837866,-0.7515285791648121
450.40000000000566,50.13636646593604,0.3174237108596204,-0.7561396454828491
451.5000000000057,50.2450824078297,0.320303921357309,-0.7599321507145871
452.6000000000057,50.3520807850475,0.3262881628764171,-0.7655359451738661
453.70000000000573,50.46138338491637,0.3309152455012433,-0.7696531356819225
454.80000000000575,50.57050614693677,0.33545149665320884,-0.7736433541605736
455.9000000000058,50.677324115286225,0.34271253426050324,-0.7789704165283471
457.0000000000058,50.78537010203448,0.34665000824885794,-0.7835198337108888
458.1000000000058,50.89375234009488,0.34982124378944557,-0.7873229560899149
459.20000000000584,51.00284556430318,0.35199512620684703,-0.7925030552391439
460.3000000000058,51.11000097614177,0.35820144798124653,-0.7967599599002266
461.40000000000583,51.21816588397034,0.3626827522903902,-0.8017143431180922
462.50000000000585,51.32690175069299,0.367764988608411,-0.8077434549301135
463.6000000000059,51.434538662101545,0.3725534509464632,-0.8109361446654266
464.7000000000059,51.542566267443696,0.3770709006838655,-0.8166892969260204
465.8000000000059,51.65034320168626,0.3815242011651393,-0.8209016869129386
466.90000000000595,51.75911565553074,0.38482198602856527,-0.824891573911362
468.0000000000059,51.86683104317252,0.38963226762674297,-0.8282941693732302
469.10000000000593,51.97500816595839,0.3931232455436289,-0.833406394104601
470.20000000000596,52.08301971344754,0.39911126700519756,-0.8383514995649186
471.300000000006,52.19155806568599,0.40288919421835256,-0.8425318528850299
472.400000000006,52.300103119244845,0.40672637902204234,-0.8453556374932196
473.500000000006,52.4086336545166,0.4118890797050728,-0.8483609871306181
474.60000000000605,52.51803181236584,0.41523385541319513,-0.8533612593707427
475.70000000000607,52.62601210922614,0.41610881950569667,-0.855862218501255
476.8000000000061,52.73423571654305,0.42011748517574565,-0.857687378004699
477.90000000000606,52.842411368864205,0.4251193362103851,-0.8632084125052688
479.0000000000061,52.95054268319783,0.4287104875745992,-0.8656503606468098
480.1000000000061,53.0598978889027,0.4304172449490957,-0.8686063572077773
481.2000000000061,53.1686302401352,0.4358419767954579,-0.8713379844693145
482.30000000000615,53.2767272314315,0.4367954582033124,-0.8739501950188311
483.4000000000062,53.386167199906986,0.44330612660674734,-0.8766044553733652
484.5000000000062,53.49391047648427,0.4460418290038827,-0.8779309369529247
485.60000000000616,53.60321632832032,0.4498138942483185,-0.8818896111303149
486.7000000000062,53.71242192323694,0.45192487128340725,-0.8845076594684311
487.8000000000062,53.82000096622645,0.45560057256166314,-0.8858299582463212
488.90000000000623,53.92980742711554,0.4599183795245234,-0.888461767722081
490.00000000000625,54.0376088969249,0.4625612159597076,-0.8896585457257356
491.1000000000063,54.14671413877672,0.461853483413758,-0.8924090726267115
492.2000000000063,54.255712971880854,0.4665799382105786,-0.8937020571075958
493.3000000000063,54.3641245101237,0.46865411239331906,-0.8950400811609907
494.40000000000634,54.47326072347705,0.47120152326415704,-0.8969980615415487
495.5000000000063,54.581889275634765,0.4744967020072136,-0.8979987178546729
496.60000000000633,54.689428852581486,0.4753929168550862,-0.8992767271075381
497.70000000000636,54.79830764893803,0.4811373684610035,-0.901293187753347
498.8000000000064,54.90792907704028,0.48127638747929563,-0.9009386931904362
499.9000000000064,55.01685993970272,0.48669654483002495,-0.9026092925844256
501.0000000000064,55.12544665166335,0.4844998762368948,-0.9035959937338047
502.10000000000645,55.233938098984694,0.48793215250241173,-0.9041069869515139
503.2000000000064,55.34313450401297,0.49052954842786084,-0.9052404818373434
504.30000000000643,55.4524223999066,0.4956554857549323,-0.9065666807403465
505.40000000000646,55.56156277837818,0.4980013215792148,-0.9085289057113441
506.5000000000065,55.67073016294028,0.4999682406521841,-0.9085510762432651
507.6000000000065,55.77990346733612,0.500211299815153,-0.9101799380572451
508.7000000000065,55.888030666382036,0.5069322230240592,-0.912805965182113
509.80000000000655,55.99762067725918,0.5104049291757327,-0.912805043666256
510.90000000000657,56.106800843501794,0.5119302960994355,-0.9154499866843819
512.0000000000066,56.21622872953066,0.5151621667655512,-0.9168321678375397
513.1000000000065,56.324800410908786,0.5211534425983648,-0.9167590905767597
514.2000000000066,56.43346454059899,0.5209244339017565,-0.9180701823635511
515.3000000000065,56.54243867152032,0.5288615609162132,-0.9207738454286742
516.4000000000067,56.65126804563401,0.5320939358029139,-0.9207118941809647
517.5000000000066,56.76088624088641,0.5370560801659778,-0.9220508888042116
518.6000000000067,56.87041515267909,0.5425087421871676,-0.9233399729542535
519.7000000000066,56.97924952144904,0.5467479485843008,-0.9246607211048357
520.8000000000067,57.08747577542387,0.5542731209951755,-0.927334292674125
521.9000000000067,57.19680222800055,0.5540952854738423,-0.9286000841392079
523.0000000000067,57.306229591996996,0.5612921667920512,-0.9288562156191866
524.1000000000067,57.41500611239124,0.5683373636231467,-0.9299391884243269
525.2000000000068,57.524265721926476,0.5732491801011338,-0.9302896145233186
526.3000000000068,57.6329221202009,0.5793246331066337,-0.9314743007273498
527.4000000000068,57.741509187317064,0.5816132155693039,-0.9339894923580299
528.5000000000068,57.85087925839028,0.5910797326691193,-0.9373090424211159
529.6000000000068,57.95957939526874,0.5968092592605664,-0.9385895241356268
530.7000000000069,58.06894549602782,0.6077329781027164,-0.9412213056490923
531.8000000000068,58.17786384953052,0.6155448398101904,-0.941704684428033
532.9000000000069,58.28685417727944,0.6209252957664301,-0.9438453843411705
534.0000000000068,58.39621459816043,0.6287326992656909,-0.9465298034034908
535.100000000007,58.505713127075474,0.6356215038099372,-0.9465102355739314
536.2000000000069,58.61508969563891,0.637970405567767,-0.9504404425661304
537.300000000007,58.72359748904276,0.643752711043043,-0.9507594542820965
538.4000000000069,58.83212767644554,0.6535434490312892,-0.9530983719937378
539.5000000000069,58.94121079853712,0.6584281233130725,-0.954382616285486
540.600000000007,59.051730419992225,0.6640919959437701,-0.9564992888379349
541.700000000007,59.16104586748765,0.6700907783667571,-0.9583294044273938
542.800000000007,59.270399290317066,0.6738990838136726,-0.9596500008055378
543.900000000007,59.379491912175766,0.6732954905715374,-0.9622665441876626
545.000000000007,59.489899867347646,0.6751027375346105,-0.9635898973337365
546.1000000000071,59.59989838661213,0.6746440202783515,-0.9661563018113228
547.2000000000071,59.70894909916834,0.6774817153129443,-0.9665013733223566
548.300000000007,59.81840985426511,0.6783974274027466,-0.9697251636457356
549.4000000000071,59.928467361866126,0.683086494465377,-0.9719072084555891
550.500000000007,60.03748265425867,0.6840942847733482,-0.9739407322989608
551.6000000000072,60.147463066961464,0.6913114172764319,-0.9754435196593412
552.7000000000071,60.257343573456886,0.6969977590891877,-0.9777317580471285
553.8000000000072,60.36659312480751,0.7001845168656916,-0.9780742072734316
554.9000000000071,60.4765278322074,0.7029425826237629,-0.9807116952871979
556.0000000000072,60.586583975714895,0.7073293549681731,-0.9834464482926717
557.1000000000072,60.69640092594323,0.7080930036837503,-0.9861165549922566
558.2000000000072,60.80574507973479,0.7151031171593958,-0.9886937270359968
559.3000000000072,60.91534757263621,0.7185251968735438,-0.9900209134542517
560.4000000000073,61.026134459710555,0.7234010971418812,-0.9920243236132089
561.5000000000073,61.13539536011017,0.7275361476014038,-0.9975874451590152
562.6000000000073,61.24602186280857,0.736533569879151,-0.9973728719267441
563.7000000000073,61.35578128525926,0.7421938323576173,-0.997796063741855
564.8000000000073,61.466139169299,0.7505107305356181,-1.0006610943069254
565.9000000000074,61.57564971150772,0.7577520100785614,-1.003215407534885
567.0000000000074,61.68487200433387,0.7688387146215013,-1.0058691913698974
568.1000000000074,61.7964985493051,0.7790609088074536,-1.008441112623724
569.2000000000073,61.90575000440014,0.7862813409550723,-1.0114036026110007
570.3000000000073,62.01552909500153,0.80072508475878,-1.0135637625319283
571.4000000000074,62.125728835291945,0.8140609010281784,-1.0144931820853227
572.5000000000074,62.23493233435937,0.8299868142729184,-1.0220499623575767
573.6000000000074,62.345581355403596,0.8417869075012695,-1.0214297755236785
574.7000000000074,62.455156761893186,0.8595098814990768,-1.0239703969104248
575.8000000000075,62.56503082250756,0.8780540656726867,-1.0270382415473218
576.9000000000075,62.675461385097535,0.8971331795406413,-1.0294238437865393
578.0000000000075,62.78556848995359,0.9185558705091096,-1.0335089413361
579.1000000000075,62.895815179916845,0.9383532950691543,-1.038600089272634
580.2000000000075,63.00697374672484,0.954699054356768,-1.0414069650468876
581.3000000000076,63.11639103705967,0.9678299131357121,-1.0467310601815818
582.4000000000076,63.225835130158195,0.9778315733208786,-1.0510751074058624
583.5000000000076,63.336973429738286,0.979981692062349,-1.0527792761095802
584.6000000000076,63.447712442546134,0.9692098655615856,-1.057267815486286
585.7000000000077,63.557542924933216,0.9311780402409803,-1.0611129276660916
586.8000000000077,63.667864871325904,0.8541498629108412,-1.0657329800386637
587.9000000000076,63.77915325815234,0.7803714870595752,-1.0683179102830547
589.0000000000076,63.888404967921495,0.7313515095724009,-1.0708620395126407
590.1000000000076,63.99861227682452,0.7053525402240035,-1.0702205443630937
591.2000000000077,64.10838514374218,0.6850720607144766,-1.0713084013344125
592.3000000000077,64.21835381016261,0.6778104214108917,-1.0738743206327914
593.4000000000077,64.32813449529431,0.6719069911630677,-1.0739396481192194
594.5000000000077,64.43783664407151,0.6674846383271057,-1.073534447657872
595.6000000000078,64.54837967764492,0.6637881738958415,-1.0748235628651326
596.7000000000078,64.65749251601477,0.662139778101031,-1.0775430984487584
597.8000000000078,64.76778425757753,0.6603277052504823,-1.0751599155533373
598.9000000000078,64.87825287328717,0.6632970332814528,-1.0770273328905904
600.0000000000078,64.98837919069264,0.6696584897399721,-1.0777798747092997
601.1000000000079,65.09823401033117,0.6779822547713975,-1.0777797893858967
602.2000000000079,65.20811298505535,0.6918050141187762,-1.0789356730079631
603.3000000000079,65.31818625216795,0.7055864246391617,-1.0811271937777813
604.4000000000078,65.42900215964569,0.7191473386225417,-1.0826206072906572
605.5000000000078,65.53952353239848,0.7301083932186618,-1.0819529789054254
606.6000000000079,65.64928772333053,0.7467233647557998,-1.0832609555295498
607.7000000000079,65.7607571920555,0.7571898187338911,-1.084580091160884
608.8000000000079,65.8707602067449,0.7719866179723339,-1.085904927823203
609.9000000000079,65.98172877445528,0.7877174601108816,-1.0876952884827773
611.000000000008,66.09229826179443,0.7970725161483219,-1.089376290276714
612.100000000008,66.20239627011397,0.807229699520919,-1.0896118562240757
613.200000000008,66.31237372617566,0.8191045614778348,-1.0908427505794034
614.300000000008,66.42206089480068,0.8307912502922901,-1.0921633189193938
615.400000000008,66.53340328727616,0.8417735812064187,-1.09499754229926
616.5000000000081,66.64355359501126,0.8557744383955189,-1.09762095367121
617.6000000000081,66.75374308979585,0.8676992776375423,-1.0988888028748458
618.7000000000081,66.86473458098689,0.878109216618205,-1.1001564842173162
619.8000000000081,66.97531337818967,0.8931858565218039,-1.1027982882915088
620.9000000000082,67.08570840535312,0.9041249820744023,-1.102789010887434
622.0000000000082,67.1952208015271,0.9204544700742096,-1.1054229828225854
623.1000000000081,67.30642497815965,0.9320774197611303,-1.1083081189866437
624.2000000000081,67.41598382503419,0.9481162118926018,-1.1121067689877027
625.3000000000081,67.52623477746612,0.9633082489063697,-1.1125828441383323
626.4000000000082,67.63669816251137,0.9754574223619346,-1.114848543412466
627.5000000000082,67.74667500622644,0.9927073663689197,-1.1175074609942883
628.6000000000082,67.85858184116202,1.0073978308881313,-1.1206450574660587
629.7000000000082,67.96791274814056,1.0235768510984435,-1.12429593723347
630.8000000000083,68.07942675539414,1.0406221462668264,-1.1276833424040662
631.9000000000083,68.18939149225194,1.056925804798301,-1.1302842174827714
633.0000000000083,68.30048480537347,1.0751537311097197,-1.1343999668582843
634.1000000000083,68.4112935861364,1.0915985633160126,-1.1372800025249745
635.2000000000083,68.52161287566815,1.1121449119577094,-1.1409745628283283
636.3000000000084,68.63333681762731,1.1340700502201653,-1.1452015059481249
637.4000000000084,68.74436997465315,1.1527293376311027,-1.1477404720304167
638.5000000000084,68.85513912254682,1.172526445531727,-1.1522031336437353
639.6000000000083,68.96513885405898,1.197472248090799,-1.155458946443562
640.7000000000083,69.07626239949651,1.2217987540903716,-1.16120653297479
641.8000000000084,69.18670395907624,1.2447070741942645,-1.165580309517444
642.9000000000084,69.29731622608163,1.268211647503612,-1.168461609467455
644.0000000000084,69.40876761344879,1.2939762128140582,-1.17388630634699
645.1000000000084,69.51877292360327,1.3164002029632185,-1.1788933303136275
646.2000000000085,69.6293699997702,1.3407046156482008,-1.1830695953450445
647.3000000000085,69.74021449644522,1.3645446544794682,-1.1875829186701905
648.4000000000085,69.85084468090852,1.3919826798972232,-1.1934129023040878
649.5000000000085,69.96131058716014,1.414720400304719,-1.1961868555911512
650.6000000000085,70.07211555739693,1.437719769079913,-1.2047694880837887
651.7000000000086,70.18223954760938,1.4595243184453415,-1.2104947799384012
652.8000000000086,70.29418686371035,1.4849030423278653,-1.2143576890910182
653.9000000000086,70.40369965990335,1.5066500433964136,-1.2207169035973005
655.0000000000086,70.51549410578397,1.5288880086711443,-1.2268128385173585
656.1000000000087,70.62593258621364,1.5497068328656358,-1.2315624167928427
657.2000000000087,70.73554568223787,1.5717970671319768,-1.2378619761829208
658.3000000000086,70.8457532662225,1.5934089408806544,-1.2443618944274402
659.4000000000086,70.95628813285524,1.6140319222846384,-1.2481696568529146
660.5000000000086,71.06653893437806,1.631618332426567,-1.2563829660403467
661.6000000000087,71.17679163263062,1.6519930988208043,-1.2612055232966255
662.7000000000087,71.28641749051413,1.6755189248757003,-1.268364174518526
663.8000000000087,71.39787910438656,1.7095847837684819,-1.272234779238829
664.9000000000087,71.5091692455155,1.7340618919739672,-1.2787570954930558
666.0000000000088,71.61959728057626,1.768155413026519,-1.2848598389376846
667.1000000000088,71.73050369020277,1.8036584074044573,-1.2907941240242073
668.2000000000088,71.84061302705493,1.8495655649012939,-1.2984266011233871
669.3000000000088,71.95213998230909,1.8981914662542247,-1.3056293133181014
670.4000000000088,72.06399905463675,1.9563394402977872,-1.3141867347871061
671.5000000000089,72.1751624133356,2.015861885366864,-1.3223296516363527
672.6000000000089,72.28634998470615,2.079640637494686,-1.331680444982188
673.7000000000089,72.39711984555026,2.1405868680429907,-1.3387907621243675
674.8000000000088,72.50909372511747,2.206212636307791,-1.3486179109013108
675.9000000000088,72.62061023433787,2.2731838677194802,-1.358270657036806
677.0000000000089,72.73113541954197,2.347507781151973,-1.3664500299848203
678.1000000000089,72.8428638197285,2.424469433424722,-1.3771174945839895
679.2000000000089,72.95353659824961,2.5004090001957247,-1.3876336058277494
680.3000000000089,73.06547859053408,2.5860859777227945,-1.3988076395070532
681.400000000009,73.17712696126823,2.6796093274316317,-1.4098083293205965
682.500000000009,73.28887976833515,2.7832863427498733,-1.423367138121821
683.600000000009,73.40000203535077,2.89818883221836,-1.436669534190206
684.700000000009,73.51226232829276,3.0234943806644528,-1.4485729493676125
685.800000000009,73.62356554304122,3.1626815200729586,-1.4613696668540825
686.9000000000091,73.73425991609422,3.2953916882991603,-1.4752640311218355
688.0000000000091,73.84626506481833,3.3917155954061675,-1.490875471069684
689.1000000000091,73.95675296453865,3.4275485619040307,-1.505898843070001
690.2000000000091,74.06776141942503,3.424672805466314,-1.5233001464794782
691.3000000000092,74.17960354565119,3.422712691439902,-1.540338640845762
692.4000000000092,74.29068845953046,3.437880826546974,-1.5568395592809328
693.5000000000091,74.40046648887507,3.4705039853544526,-1.5755227941062917
694.6000000000091,74.51125703605453,3.512535173193831,-1.5934542358709267
695.7000000000091,74.62323041441581,3.5580732950323934,-1.6103897508749054
696.8000000000092,74.7344866015579,3.6054795789057152,-1.6287888819296543
697.9000000000092,74.84471469663471,3.661061687537569,-1.6473676089247467
699.0000000000092,74.95635970823865,3.709242660632808,-1.6661815268315645
700.1000000000092,75.0665470059382,3.7634142543835996,-1.685416458609705
701.2000000000093,75.17697854561696,3.8200036891286278,-1.7080868154007405
702.3000000000093,75.28826791080773,3.8797280608198284,-1.7283451450936247
703.4000000000093,75.3997992714331,3.9334717871496117,-1.7462596261632095
704.5000000000093,75.51069658203782,3.9861021926746023,-1.7675843963962268
705.6000000000093,75.62138263226956,4.026399372259528,-1.7880060295352225
706.7000000000094,75.73224541017247,4.065146077221661,-1.8105855341536214
707.8000000000094,75.84406769514271,4.091231917874435,-1.8327452842499152
708.9000000000094,75.95446816411517,4.0974528944571444,-1.854426482269508
710.0000000000093,76.06654359054326,4.076841089331956,-1.876109834659419
711.1000000000093,76.17738958841845,4.008466175993733,-1.896503327699273
712.2000000000094,76.2880565221707,3.8699317292066553,-1.9175400652452863
713.3000000000094,76.39938006473092,3.614872038051247,-1.9378075892775835
714.4000000000094,76.50979100330503,3.201588707001128,-1.9550217083524641
715.5000000000094,76.62009897493432,2.5886106052141375,-1.9695444356276117
716.6000000000095,76.73000185552999,1.6657266101782724,-1.9810527311698678
717.7000000000095,76.83841141169138,1.1590293601456971,-1.987930578380141
718.8000000000095,76.94867956280419,1.054788047523559,-1.9920255633349808
719.9000000000095,77.05867758061677,0.9814020981949773,-1.9908105794639708
721.0000000000095,77.17032035828359,0.959553436419925,-1.9925635932485322
722.1000000000096,77.28202226692115,0.9545855413821517,-1.9938701694792589
723.2000000000096,77.39246720056742,0.9618631279170999,-1.9938705483079961
724.3000000000096,77.50437595525219,0.970625118978473,-1.9948220488291009
725.4000000000096,77.6156162377261,0.9761438620517806,-1.9948618459752643
726.5000000000097,77.7265399033381,0.9822080408212799,-1.9962228828005237
727.6000000000097,77.83821297366791,0.9876997391911059,-1.996179959287546
728.7000000000096,77.94970387453856,0.9867647254121467,-1.9948938245056835
729.8000000000096,78.06130819385399,0.9927670995934668,-1.996182528421961
730.9000000000096,78.1726142919374,0.9972192043880856,-1.996180134997839
732.0000000000097,78.28435625763241,0.9966199989764001,-1.996180244888904
733.1000000000097,78.39644028242651,1.0034300892891275,-1.996173222185082
734.2000000000097,78.50734212120919,1.0057392542257015,-1.9962255143288252
735.3000000000097,78.61877142833248,1.006992556155335,-1.9988111159103044
736.4000000000098,78.73074132598273,1.0127846963474978,-1.9985433086417048
737.5000000000098,78.84227740693419,1.0173314961432103,-2.000153907550189
738.6000000000098,78.95470207644871,1.0196726904524311,-1.9974801145548478
739.7000000000098,79.06552254408577,1.01991103472825,-1.998817680869005
740.8000000000098,79.17697394119874,1.023743886348873,-1.9977759590282762
741.9000000000099,79.28859486379683,1.025247296241825,-1.99884733177552
743.0000000000099,79.40010234020367,1.0270059174953343,-1.9988451873642141
744.1000000000099,79.51071385538016,1.0245678148431776,-1.9998532154556972
745.2000000000098,79.62249671575813,1.025482384384552,-2.0001211037719475
746.3000000000098,79.73355404297202,1.0241434399685394,-2.00079001937377
747.4000000000099,79.84588541092334,1.023998498005068,-2.0007900648770476
748.0000000000099,79.90647111006868,1.0219248131559553,-2.000789668292614