File: 01_Data/Smoke_Explosion_Plywood/STA/N2/30K_min/Smoke_Explosion_Plywood_STA_N2_30KData_230729_R3.csv
##Temp./Â°C,Time/min,DSC/(mW/mg),Mass loss/mg
29.1,20.35565279576258,-2.3233995734149304,-0.19971110764505928
30.200000000000017,20.69370131070426,-2.291086968336054,-0.19926206264438084
31.300000000000033,20.839878290895868,-2.282960048327436,-0.20069015157802816
32.40000000000005,20.94549625127152,-2.2747999878358858,-0.20276979025444142
33.500000000000064,21.034457513992457,-2.272096849829698,-0.20419959459360815
34.60000000000008,21.11285072511715,-2.267218052750673,-0.20301289063058459
35.700000000000095,21.184260975597933,-2.2655373850724687,-0.2037774581313454
36.80000000000011,21.25034635837451,-2.26195509011281,-0.2030579837381068
37.90000000000013,21.312088987915693,-2.260210159653771,-0.20315898180160552
39.00000000000014,21.370432386810148,-2.257506488405813,-0.20458009769031227
40.10000000000016,21.426670000000012,-2.255450000000002,-0.2043278205080985
41.20000000000017,21.480098680975825,-2.255074922167284,-0.2061102266044088
42.30000000000019,21.532189515981187,-2.2554382741452565,-0.20495018147790844
43.400000000000205,21.582191193331326,-2.2549864861858215,-0.20640827059915923
44.50000000000022,21.631795529677998,-2.258404904986255,-0.20664676978346463
45.600000000000236,21.679955255429036,-2.259711405003061,-0.2075679621648927
46.70000000000025,21.726793060458114,-2.2624795777307556,-0.20871776691915223
47.80000000000027,21.772828951919962,-2.2675937387325726,-0.2094118224962993
48.90000000000028,21.81890152596963,-2.2717611720772206,-0.21186179004490668
50.0000000000003,21.863184752474382,-2.277772462110661,-0.2110673137479635
51.100000000000314,21.907567735899136,-2.2842014561701984,-0.21170429284865877
52.20000000000033,21.951038100524713,-2.294653012448789,-0.21215671480130016
53.300000000000345,21.9942223828845,-2.302939810890112,-0.21426892825905064
54.40000000000036,22.036882843622294,-2.3110380301457276,-0.21601743077832092
55.50000000000038,22.079359911532954,-2.32088430330053,-0.21639231245838175
56.60000000000039,22.121295024705272,-2.333247062069952,-0.216567086091366
57.70000000000041,22.1630999519628,-2.3457142552408987,-0.21712915768268726
58.80000000000042,22.204379220905423,-2.3604675575495833,-0.21941326981334708
59.90000000000044,22.2460326776409,-2.3725526365931784,-0.221002668068202
61.000000000000455,22.286250417920453,-2.387975657924166,-0.22116696777669764
62.10000000000047,22.32674626184738,-2.405512194190883,-0.22325174673976989
63.200000000000486,22.367062800871878,-2.4211419712493587,-0.22469512249779688
64.3000000000005,22.406709528042946,-2.437696903092755,-0.22548754813774208
65.40000000000052,22.447586456425373,-2.45393323925785,-0.22756692026579328
66.50000000000054,22.487266894456692,-2.4707566468284403,-0.22858001653597038
67.60000000000055,22.52729379435772,-2.489094995877783,-0.23044131742367435
68.70000000000056,22.566740597384648,-2.5062322603434386,-0.23306703422770347
69.80000000000058,22.606159354417823,-2.5217525319790868,-0.23472073360520884
70.9000000000006,22.64544558173528,-2.537422845785641,-0.23789012824988376
72.00000000000061,22.68513311794312,-2.5520538776764816,-0.24005164721910877
73.10000000000062,22.724395281796006,-2.5675891276960745,-0.23995024976271706
74.20000000000064,22.76325216987305,-2.5814820614732987,-0.24270811061952946
75.30000000000067,22.802286947660964,-2.594392712109387,-0.24598404270706897
76.40000000000067,22.84095352139129,-2.6059214560268162,-0.24804507887851912
77.50000000000068,22.880172118832277,-2.6154774775648417,-0.2500511015395719
78.6000000000007,22.918397696200422,-2.625525182398511,-0.25272299586078084
79.70000000000073,22.956833565845102,-2.6327653916944906,-0.2564115530477591
80.80000000000074,22.995158372883434,-2.6393709986342784,-0.2579964662187111
81.90000000000074,23.033642742285387,-2.643674953054488,-0.26097050668024524
83.00000000000077,23.071521361803924,-2.6468078649527396,-0.2623607596043973
84.10000000000079,23.10953143890371,-2.647469660005353,-0.26496952038790944
85.2000000000008,23.147359883620723,-2.644551097745229,-0.2669493794137492
86.30000000000081,23.185092131443454,-2.642875273260189,-0.27060955765026495
87.40000000000083,23.22233148779286,-2.6383500477578927,-0.2722834619713663
88.50000000000085,23.2602576408022,-2.63010503299399,-0.27357684646716773
89.60000000000086,23.297292539642203,-2.621156808708171,-0.2762625370081908
90.70000000000087,23.33440180729838,-2.611309701394721,-0.2776616892630024
91.80000000000089,23.37164334378632,-2.6003922282704415,-0.2802941504724221
92.90000000000092,23.40804063900855,-2.5872420020190456,-0.28337031853084405
94.00000000000092,23.44496945335706,-2.572143186650078,-0.2851642249179247
95.10000000000093,23.48166220633977,-2.5556917541209145,-0.2873200632712014
96.20000000000095,23.518676938251076,-2.537614557146879,-0.2887124916393371
97.30000000000098,23.555119620983255,-2.5171989162706803,-0.29187409405102205
98.40000000000099,23.58939924357379,-2.4973660322514664,-0.2935818350465791
99.500000000001,23.627677489709587,-2.4739966119426375,-0.29464524919849566
100.60000000000102,23.662852019881928,-2.45113884413668,-0.2959906470372209
101.70000000000104,23.700032349553638,-2.4267316713376648,-0.29904912491424795
102.80000000000105,23.73625634347701,-2.4003780783078983,-0.3002523525616372
103.90000000000106,23.772582869318086,-2.3750224413090533,-0.30273189341230733
105.00000000000108,23.808339599029356,-2.347741945249338,-0.3043355738025588
106.1000000000011,23.844453737007527,-2.322912846505187,-0.30492590866560887
107.20000000000111,23.880515847214806,-2.2962630048226758,-0.30587559911722284
108.30000000000112,23.916724319139988,-2.267646713714189,-0.3085555848898176
109.40000000000114,23.951965532202177,-2.2391532234442613,-0.30850247844262224
110.50000000000117,23.988069234482293,-2.2136975651548614,-0.30980538375503075
111.60000000000117,24.02381107549792,-2.186850390499135,-0.31106144390963353
112.70000000000118,24.059807788592614,-2.1591196098611256,-0.3124404604281348
113.8000000000012,24.095562773050382,-2.1298457014449643,-0.313813262758015
114.90000000000123,24.130813942783,-2.1029430414955703,-0.3137597045706384
116.00000000000124,24.166860001616257,-2.078799715481381,-0.3141764935618614
117.10000000000124,24.202670699397995,-2.051033564470624,-0.3163849548757609
118.20000000000127,24.238193184491987,-2.0259265131447872,-0.3163900289117696
119.30000000000129,24.27400332403213,-2.001970606784267,-0.3163897105258129
120.4000000000013,24.309469238145965,-1.9767636709304963,-0.3175744282553481
121.50000000000131,24.344688656581283,-1.955311732076433,-0.3177102573261532
122.60000000000133,24.38089445353163,-1.9331639747050742,-0.3177108676193341
123.70000000000135,24.416134291987422,-1.9128788931894674,-0.319045574970525
124.80000000000136,24.451516861865244,-1.8926974193339694,-0.3190452257332108
125.90000000000137,24.48700729317098,-1.8728848401329186,-0.3200202599579276
127.00000000000139,24.52203310801854,-1.855268414518107,-0.32001993850422217
128.10000000000142,24.55734405035413,-1.8392716546095818,-0.3200090515615668
129.2000000000014,24.592862932033924,-1.8236378995770663,-0.32132230757931035
130.30000000000143,24.628027706284698,-1.8079476154849987,-0.3213399219842299
131.40000000000146,24.6627844889938,-1.7956183787729374,-0.32133996006639265
132.50000000000148,24.698186750541726,-1.7822403973234302,-0.3213399599998499
133.6000000000015,24.733148415506076,-1.7699222020625078,-0.3213399601927418
134.7000000000015,24.768236084119643,-1.7598983451260874,-0.321339769792913
135.80000000000152,24.803409682623045,-1.7482508681588844,-0.3216636003420712
136.90000000000154,24.83838633280646,-1.74062790324521,-0.32166991151904334
138.00000000000153,24.87367969796852,-1.731300688887668,-0.3216699616067542
139.10000000000156,24.908338302823957,-1.7235079036361955,-0.3216688130370735
140.20000000000158,24.943134229913422,-1.7181991440289774,-0.3226532718175541
141.3000000000016,24.97725295046791,-1.7115083284446142,-0.3226499980925497
142.40000000000163,25.01198226692911,-1.7035044866357896,-0.32261965912955937
143.50000000000162,25.04753640787167,-1.6985042576313343,-0.32297948785024033
144.60000000000164,25.082263570557355,-1.6939915260427707,-0.3229799602447394
145.70000000000167,25.117294481823688,-1.689472823001715,-0.3229799600000631
146.80000000000166,25.151868073856097,-1.6862609169003924,-0.32297996001524165
147.90000000000168,25.186366602585515,-1.6828331729452466,-0.3229799419743573
149.0000000000017,25.221082588414376,-1.6786795183647305,-0.32299419973220367
150.10000000000173,25.255316081364576,-1.6757133292945479,-0.32481508262561976
151.20000000000175,25.289811249100097,-1.673585310323841,-0.32561970364122184
152.30000000000175,25.324348679055998,-1.670486975604967,-0.3256371097636763
153.40000000000177,25.35868389955299,-1.6685911946399805,-0.3243015205197084
154.5000000000018,25.39320709179435,-1.6670837285495903,-0.32429995982978976
155.60000000000178,25.427566621607596,-1.6652133566285174,-0.3242999599987719
156.7000000000018,25.46224925365514,-1.6624652442099725,-0.32429996000000294
157.80000000000183,25.496532809468835,-1.6600894238959156,-0.32429995999999983
158.90000000000185,25.53052114897688,-1.6597755728954393,-0.3242999600000047
160.00000000000188,25.56507050202987,-1.6576969015976855,-0.3242999599978398
161.10000000000187,25.599395538050604,-1.656367904916471,-0.3242999608874646
162.2000000000019,25.633489399462174,-1.6550529592334553,-0.3243001593266581
163.30000000000192,25.667686195946615,-1.6544110814038115,-0.32563253093671163
164.4000000000019,25.702093631865335,-1.653127550104005,-0.3256198560146246
165.50000000000193,25.736075024826317,-1.654003451048233,-0.32614294966425517
166.60000000000196,25.770209751617475,-1.6526326568390386,-0.3266019572807197
167.70000000000198,25.804683033524203,-1.6516731893165064,-0.32694009244971145
168.800000000002,25.838872053398656,-1.6518335599751435,-0.3269401277869175
169.900000000002,25.872650356255097,-1.6500397137990899,-0.32694012799888306
171.00000000000202,25.90660767796821,-1.6504340540279627,-0.3269401281133222
172.10000000000204,25.941153486787485,-1.6497489595082342,-0.3269418898621721
173.20000000000203,25.974535843059748,-1.6503890930401541,-0.32826529432539475
174.30000000000206,26.009243275557356,-1.6492344207161145,-0.32824981349031157
175.40000000000208,26.043233933095166,-1.6484755598528438,-0.32824959201950943
176.5000000000021,26.077237328611805,-1.648916688797098,-0.3285800435305104
177.60000000000213,26.110945143388545,-1.6488704483946768,-0.32956933560885426
178.70000000000212,26.14490426334055,-1.6489339333745836,-0.32957001281550413
179.80000000000214,26.178744427347112,-1.6495943189888038,-0.3295700119993361
180.90000000000217,26.212647923291676,-1.6504131958470019,-0.3295700120000018
182.00000000000216,26.24645661318699,-1.6503005246962632,-0.3295700119995053
183.10000000000218,26.28054780186609,-1.6509854054719166,-0.329570010925226
184.2000000000022,26.314319301760086,-1.651677768978119,-0.3295716074619506
185.30000000000223,26.347755942729407,-1.6522886142239357,-0.33090397169040564
186.40000000000225,26.38154101873538,-1.6520175968701099,-0.33089018547232296
187.50000000000225,26.414978532544147,-1.652859034419489,-0.3308700597641767
188.60000000000227,26.449174395802803,-1.6528798250568064,-0.33221429475280173
189.7000000000023,26.48218973224099,-1.6541491248624562,-0.33220994056377595
190.80000000000229,26.515441302845538,-1.6530093558217613,-0.3322097712808052
191.9000000000023,26.5498011918204,-1.6553130828052847,-0.33245238821985135
193.00000000000233,26.583045775342633,-1.6542597255679432,-0.3335192344187745
194.10000000000235,26.616873517765686,-1.6552751413275142,-0.3335247608495373
195.20000000000238,26.64986911948533,-1.6553084884838511,-0.33485548377829666
196.30000000000237,26.683886824831994,-1.6554718994371667,-0.3348401017416003
197.4000000000024,26.71704313634674,-1.6550638203232155,-0.3355292169525157
198.50000000000242,26.750564883234716,-1.654823432096378,-0.33681984848477287
199.6000000000024,26.78359211724902,-1.6559194512640087,-0.33693958898648946
200.70000000000243,26.817394634874713,-1.6561504573878447,-0.3381408698438628
201.80000000000246,26.850742188813356,-1.655919045131392,-0.33814019202522205
202.90000000000248,26.884025014607055,-1.6553067269104118,-0.3381180222276656
204.0000000000025,26.917534511167677,-1.6558808982959066,-0.3394468284058183
205.1000000000025,26.950636493568023,-1.6549501251651388,-0.3405911972840605
206.20000000000252,26.984255605326346,-1.6554135024929497,-0.34077009832761807
207.30000000000254,27.01810240835317,-1.6562043913256177,-0.34096097964037275
208.40000000000254,27.051254775655245,-1.6564107552472291,-0.34209597227866073
209.50000000000256,27.084735453698208,-1.656337871671153,-0.3434229351059064
210.60000000000258,27.11752970882501,-1.6572848749020375,-0.3453840398832879
211.7000000000026,27.151072982963385,-1.657132471351454,-0.34664907492671215
212.80000000000263,27.184501086815413,-1.6562743026907267,-0.34698105644938737
213.90000000000262,27.217552433389557,-1.6577478093277511,-0.3481091091570603
215.00000000000264,27.250563862283695,-1.6565921827081755,-0.34967143607588547
216.10000000000267,27.283593969558837,-1.6574706524869947,-0.35096888360648704
217.20000000000266,27.317537449031192,-1.6578268877997566,-0.3521318999937626
218.30000000000268,27.350958803218642,-1.6576937098768743,-0.35227868024556663
219.4000000000027,27.384381916772558,-1.6575280248463677,-0.3536208416221247
220.50000000000273,27.417580542296783,-1.658710552064976,-0.3551692011936072
221.60000000000275,27.450777813495346,-1.6596132644758752,-0.35674657289006273
222.70000000000275,27.483890739123865,-1.6590552166624624,-0.3583069120970208
223.80000000000277,27.51709850493644,-1.661498881024886,-0.3587425176487611
224.9000000000028,27.550470591491106,-1.6617115361991266,-0.36003786101257207
226.00000000000279,27.5837140807822,-1.663962665161962,-0.3619208042406705
227.1000000000028,27.617135682920583,-1.6632055669613204,-0.3643941854824697
228.20000000000283,27.650373068223878,-1.6639475161376365,-0.3664208559262536
229.30000000000285,27.68312426155226,-1.665746547234608,-0.3680352561585609
230.40000000000288,27.71699835418528,-1.6666112805129778,-0.3697353380252184
231.50000000000287,27.749979653696187,-1.6658351593096754,-0.37281368524026437
232.6000000000029,27.783345157905718,-1.667173932564192,-0.3750644860158894
233.70000000000292,27.816569060134956,-1.6680584257164435,-0.3774336679607182
234.8000000000029,27.849632114774522,-1.6690130932541842,-0.3802306683632417
235.90000000000293,27.88245846465019,-1.6693725495425062,-0.381937208310128
237.00000000000296,27.916293396775192,-1.6679502406622502,-0.384282379090108
238.10000000000298,27.94956880477014,-1.6680063887228316,-0.38705938405774054
239.200000000003,27.982414013294097,-1.6678230660776767,-0.38969154808121953
240.300000000003,28.015735062794203,-1.667259871387584,-0.39278280187224635
241.40000000000302,28.049298154919853,-1.668933952788929,-0.3957461904436763
242.50000000000304,28.082214682940283,-1.6695488969470291,-0.39732733044128477
243.60000000000304,28.1155615080368,-1.6704582711314564,-0.40138370019454417
244.70000000000306,28.148644060435238,-1.6703309487682225,-0.40418762910889017
245.80000000000308,28.181913354474883,-1.6729155214112053,-0.4073806748619635
246.9000000000031,28.21519524867262,-1.672088678401206,-0.4113421059895752
248.00000000000313,28.248201694816963,-1.6716935178207437,-0.4143230230537598
249.10000000000312,28.28185633239913,-1.6733786498733896,-0.4185856689754832
250.20000000000314,28.3147427831843,-1.672519607377957,-0.42175359160265247
251.30000000000317,28.3472037309435,-1.6744514664467105,-0.4245540460005457
252.40000000000316,28.380170735091852,-1.6745904791467683,-0.42850099766660676
253.50000000000318,28.41415367594962,-1.6734155234354964,-0.43232991251222286
254.6000000000032,28.447418473282394,-1.6761087065460725,-0.43651283547780473
255.70000000000323,28.480421968664906,-1.6734526197979123,-0.44056122958557253
256.80000000000325,28.513784602229553,-1.6733121035732492,-0.4444265432762742
257.9000000000033,28.547017752901336,-1.6723998018208768,-0.44882746590868106
259.0000000000033,28.579364148970733,-1.670718139846689,-0.4530287809159126
260.1000000000033,28.613121817643957,-1.6686048951507197,-0.45734239815336286
261.2000000000033,28.646016439777505,-1.6664510488717652,-0.4623454412616592
262.3000000000033,28.678656727473733,-1.6642672221123374,-0.46571933100429774
263.40000000000333,28.71242761924197,-1.6615599702692898,-0.4690744309223569
264.50000000000335,28.745745474487606,-1.660330131236549,-0.4741699095425149
265.6000000000034,28.77879975292966,-1.6570189333134462,-0.4793848279514017
266.70000000000334,28.8118329764677,-1.6558672121847993,-0.48418884855205
267.80000000000337,28.844820898605306,-1.6546389757970705,-0.48873316323858074
268.9000000000034,28.8778181507771,-1.6503765652236204,-0.49345436443767854
270.0000000000034,28.910832346157015,-1.647129155277066,-0.4986389371508526
271.10000000000343,28.944163789741527,-1.6449967411712312,-0.503963143587721
272.20000000000346,28.97720912564192,-1.6435175199874659,-0.511121301319788
273.3000000000035,29.010281253780278,-1.6404929374717232,-0.5172205160836922
274.4000000000035,29.043543956473542,-1.636964996879621,-0.5229257005005814
275.5000000000035,29.076495823130497,-1.6327945484555826,-0.5282718968457809
276.60000000000355,29.10952490894806,-1.6306710380537537,-0.5343292202501253
277.70000000000357,29.142721482334142,-1.627330558278023,-0.5409820390619968
278.80000000000354,29.175689819386818,-1.6219087270645896,-0.5468269420282579
279.90000000000356,29.20896575769311,-1.6209465761144513,-0.5523247270666238
281.0000000000036,29.242037281224082,-1.6182302170468696,-0.5594313233092851
282.1000000000036,29.275156181734065,-1.614263105311332,-0.5664122006981454
283.2000000000036,29.308187758391586,-1.6111592360563465,-0.573483606693463
284.3000000000036,29.341529567264725,-1.607636870925064,-0.5807503011926487
285.4000000000036,29.374931470050814,-1.6020338788290032,-0.5902070352377651
286.50000000000364,29.407601039070283,-1.598033067146958,-0.5993251545320732
287.60000000000366,29.440964173582728,-1.593919891046141,-0.607326098467162
288.7000000000037,29.474010520233136,-1.591827094039471,-0.6156430175625087
289.8000000000037,29.50705347360247,-1.5874698072454574,-0.625100203466495
290.90000000000373,29.540475755164024,-1.5826151927793453,-0.6340168513391897
292.00000000000375,29.573241449945975,-1.576040064247779,-0.6433059422211778
293.1000000000038,29.606967235451556,-1.5728714532130856,-0.6529715629633372
294.2000000000038,29.64005925920449,-1.5690894141206821,-0.6631088066796402
295.30000000000376,29.673005130876916,-1.5632311114059936,-0.6729868043724387
296.4000000000038,29.706257704832588,-1.5598220694563953,-0.6823436253156738
297.5000000000038,29.73949639107687,-1.554899225066101,-0.6930062136012216
298.60000000000383,29.77238683740654,-1.549676673779123,-0.7048829774287948
299.70000000000385,29.805574996708152,-1.5465301750156946,-0.7172586979528783
300.8000000000039,29.838758562552112,-1.5407010998126973,-0.7290587993572601
301.9000000000039,29.87202949902823,-1.5337207509770943,-0.741314828639065
303.00000000000387,29.905231795963346,-1.5298688303293044,-0.7546995370220277
304.1000000000039,29.938239238486574,-1.5260967187749308,-0.7676102362007784
305.2000000000039,29.97175205600883,-1.520860600859196,-0.7806898597353071
306.30000000000393,30.00485339587436,-1.5170849398405486,-0.7941796701156854
307.40000000000396,30.037878248479032,-1.5125000078482016,-0.8088240221866272
308.500000000004,30.071210779245025,-1.5075486400974303,-0.8236659560892359
309.600000000004,30.10412653797178,-1.5048873271129544,-0.8383483544441481
310.700000000004,30.13755350132775,-1.5017858181951684,-0.8540832479820182
311.80000000000405,30.17070139729122,-1.50069297453037,-0.8700521144533258
312.900000000004,30.20404134644188,-1.4969501157112162,-0.885726002750518
314.00000000000404,30.23726994051011,-1.4955934318223614,-0.9019694342920817
315.10000000000406,30.2705616194705,-1.4938891433072368,-0.9189361400658518
316.2000000000041,30.30364147972843,-1.4906128122813012,-0.9365241733271619
317.3000000000041,30.337073344383995,-1.4904127881910134,-0.9547737762400246
318.4000000000041,30.370270141900136,-1.4881964456912475,-0.972611508349396
319.50000000000415,30.403578653661146,-1.4879255001945395,-0.9914762582465264
320.6000000000041,30.437035366890107,-1.486823213582619,-1.0105963477584594
321.70000000000414,30.470312431655763,-1.485838232874134,-1.0303855566912294
322.80000000000416,30.50363079996648,-1.4853824098734596,-1.0508753796055328
323.9000000000042,30.536999350176195,-1.486896169238384,-1.0702690168251716
325.0000000000042,30.570527602778046,-1.4862388590979594,-1.0928590373063392
326.10000000000423,30.60349573149571,-1.4861593109987012,-1.1142422336451707
327.20000000000425,30.637307163095798,-1.4841941915447447,-1.135531543618547
328.3000000000043,30.670071357701776,-1.486256840631965,-1.154740418424708
329.4000000000043,30.70389420622099,-1.4850628976270643,-1.1767118490914856
330.50000000000426,30.73707238394718,-1.4839660257225264,-1.2004392911671404
331.6000000000043,30.770430269645665,-1.482749855693855,-1.2238475742060784
332.7000000000043,30.80402668041411,-1.4809840211111411,-1.2478722291219229
333.80000000000433,30.837687032816707,-1.480196309802615,-1.272891140196517
334.90000000000435,30.870960035076166,-1.4784985088548652,-1.2975625654431742
336.0000000000044,30.904436961725622,-1.4741720192059025,-1.3227368845780982
337.1000000000044,30.937785063399883,-1.472374429048338,-1.349055843997268
338.20000000000437,30.970943878935067,-1.4673361531161362,-1.3744869774005046
339.3000000000044,31.004629313038446,-1.4659360137332562,-1.400879659964108
340.4000000000044,31.037885289059187,-1.4595295862829218,-1.4274835897517018
341.50000000000443,31.071443553890393,-1.4534517363567545,-1.4544103239100976
342.60000000000446,31.104713688699235,-1.446896782548417,-1.4823181363725895
343.7000000000045,31.13815490730864,-1.4391438619462535,-1.5097678467226365
344.8000000000045,31.17209865745594,-1.4319386348880752,-1.5389626201859228
345.9000000000045,31.205626038825677,-1.423807242167268,-1.567388228501399
347.00000000000455,31.2388596948281,-1.416095992526692,-1.5954953873242181
348.1000000000045,31.272231387145546,-1.4052360000473492,-1.6243784157552241
349.20000000000454,31.30571462565821,-1.396362774733388,-1.6541635375625914
350.30000000000456,31.338927179994695,-1.3850910793373994,-1.681982294889587
351.4000000000046,31.372413063459643,-1.3751504875760625,-1.7109292692183802
352.5000000000046,31.406037869609264,-1.3628585810438,-1.740391743646907
353.6000000000046,31.439749840849963,-1.3520049059944985,-1.7700453702191168
354.70000000000465,31.473145519719175,-1.3402685601003526,-1.7988562443166378
355.8000000000046,31.506639975256256,-1.3291712904551882,-1.8288536886552942
356.90000000000464,31.539937126352257,-1.3199907932322492,-1.857486246808247
358.00000000000466,31.573723819500643,-1.3066726130383612,-1.88753228632629
359.1000000000047,31.607097287372756,-1.2959828471314288,-1.9170902669486054
360.2000000000047,31.640956644885502,-1.2834378127851263,-1.9460508494669893
361.30000000000473,31.674600036659836,-1.2695745793740407,-1.9746838539068294
362.40000000000475,31.708021132467014,-1.2599444476613435,-2.003817459443294
363.5000000000048,31.741657944845823,-1.2453393888605255,-2.032084076658766
364.6000000000048,31.77501612305617,-1.2339454538395749,-2.0604047540693253
365.70000000000476,31.80849756077136,-1.2209337224598267,-2.0891331480317445
366.8000000000048,31.842208550661564,-1.20656482994425,-2.117117507183334
367.9000000000048,31.875904379071965,-1.193526282771522,-2.1434806859182527
369.00000000000483,31.909707138143595,-1.1797864154953832,-2.170967847980937
370.10000000000485,31.942977050637285,-1.1642274769579415,-2.197295685895238
371.2000000000049,31.97669686123641,-1.148526537962432,-2.2233604090977073
372.3000000000049,32.01022026291612,-1.1322667592847122,-2.2487618211592357
373.40000000000487,32.04372079935217,-1.1140649736883628,-2.273329500416996
374.5000000000049,32.077291579832256,-1.0976100706339342,-2.298591644207489
375.6000000000049,32.11088525822182,-1.0787899986216218,-2.323324269780466
376.70000000000493,32.1446229666994,-1.06022906254999,-2.3466503298145405
377.80000000000496,32.17846091391774,-1.0421413437182998,-2.3688181700297273
378.900000000005,32.21218300800981,-1.0211499061200329,-2.3900255044833587
380.000000000005,32.24590804122761,-1.0014554410299876,-2.410890486496875
381.100000000005,32.279032177576575,-0.9829814110539105,-2.4312593950666628
382.20000000000505,32.31285505682531,-0.9627444441004047,-2.4499931636804675
383.300000000005,32.346515289893524,-0.9439771278126229,-2.468836922534619
384.40000000000504,32.3800940465396,-0.9246196496994471,-2.485766463456815
385.50000000000506,32.41345235818117,-0.9057791263014017,-2.5024594880745363
386.6000000000051,32.44785688028862,-0.8880719023163174,-2.518069977409486
387.7000000000051,32.481575663374876,-0.8734188559567385,-2.5324822322965597
388.8000000000051,32.515187739879025,-0.8569960752390361,-2.5475726424714553
389.90000000000515,32.54879619464772,-0.8445064582284907,-2.5607067610723395
391.0000000000051,32.582630720331494,-0.8322310812526922,-2.5731809815341258
392.10000000000514,32.61656471655347,-0.8208869807685857,-2.585002059726838
393.20000000000516,32.65021954661417,-0.8119559644392875,-2.594918208946072
394.3000000000052,32.68442368866799,-0.8029056103084263,-2.60485176157559
395.4000000000052,32.71826274603314,-0.798944448955726,-2.6136279969545306
396.50000000000523,32.75192991920696,-0.793674260146589,-2.621630102062014
397.60000000000525,32.78600619089016,-0.7913113595885534,-2.629813606608537
398.7000000000053,32.81972393777277,-0.7909659626946013,-2.637386678092394
399.8000000000053,32.85320288103106,-0.7896768560835767,-2.644118191446121
400.90000000000526,32.88759545610163,-0.7927856338161433,-2.650741406263607
402.0000000000053,32.92183517076467,-0.7954712983074133,-2.657187505691345
403.1000000000053,32.95549519197561,-0.7996085484234216,-2.6622064349901424
404.20000000000533,32.98965912214902,-0.7993280844308311,-2.66741892587829
405.30000000000535,33.023464954892695,-0.8034387022378066,-2.672471249728291
406.4000000000054,33.05721593743764,-0.8035875401043295,-2.6778660538618086
407.5000000000054,33.09152243562629,-0.8051828749847072,-2.6833648393806784
408.60000000000537,33.125335658493064,-0.8029848865352822,-2.6877574805276154
409.7000000000054,33.15950824638978,-0.7994888733609291,-2.692468843211855
410.8000000000054,33.19345169593074,-0.7953127333814108,-2.696837609123624
411.90000000000543,33.227571498129514,-0.788262050615162,-2.701845663313421
413.00000000000546,33.26167083830157,-0.7825484290854449,-2.7062780411232734
414.1000000000055,33.295594312876716,-0.7751532976803397,-2.7109996642842895
415.2000000000055,33.329640159166026,-0.7685930572723434,-2.715647216752043
416.3000000000055,33.36384922523283,-0.762513246851335,-2.719985871887039
417.40000000000555,33.39813433984354,-0.7527202000412095,-2.7235874638405506
418.5000000000055,33.43221931030237,-0.7455766112807201,-2.727100289689421
419.60000000000554,33.46626720218035,-0.7359958759253755,-2.7308261423698617
420.70000000000556,33.50067585521976,-0.7291639168613245,-2.735533260231416
421.8000000000056,33.5345361356812,-0.7220846842162355,-2.7400391982220107
422.9000000000056,33.56891897057201,-0.7134727347924538,-2.744387186560948
424.0000000000056,33.602976138716215,-0.7058974223659977,-2.7479472906162323
425.10000000000565,33.63740722537069,-0.6993099693948477,-2.7515448658002133
426.2000000000056,33.671703300453494,-0.6938169718898436,-2.755730657714371
427.30000000000564,33.7060565792364,-0.6879101719538829,-2.759681350679457
428.40000000000566,33.74056929895079,-0.6847960311192459,-2.7632316427672032
429.5000000000057,33.77502950520547,-0.6771244212659292,-2.7678021668774777
430.6000000000057,33.809056306431756,-0.6758905355068378,-2.771432760593938
431.70000000000573,33.843317683257624,-0.6726543726285263,-2.7751503990266295
432.80000000000575,33.877734776981086,-0.6687936955649852,-2.779231050780769
433.9000000000058,33.91216972631786,-0.6676877271881804,-2.783235579999262
435.0000000000058,33.94670088060282,-0.6665481116872752,-2.7874056677240295
436.10000000000576,33.98128681027162,-0.6660569009987465,-2.791595017580395
437.2000000000058,34.01561028282167,-0.6671048834151333,-2.7968036005043455
438.3000000000058,34.05033402534021,-0.6691692174329705,-2.800723900819076
439.40000000000583,34.084638378811626,-0.6702796598006462,-2.8042056023103292
440.50000000000585,34.11936733451869,-0.6747179038751443,-2.8080473446666607
441.6000000000059,34.15404252133487,-0.676687343526218,-2.810966855729858
442.7000000000059,34.18842466542874,-0.6823566614627453,-2.81324734888005
443.80000000000587,34.222167165999366,-0.6877634143104483,-2.816276863682254
444.9000000000059,34.25770934733969,-0.6939328190292716,-2.8191948118601884
446.0000000000059,34.292409823228766,-0.7036670052182675,-2.8230842287225917
447.10000000000593,34.32673468201565,-0.7177649231330516,-2.827037008111991
448.20000000000596,34.36181169329311,-0.7436836036383536,-2.8321249918292954
449.300000000006,34.39638034040355,-0.7753733560062211,-2.8345081555423657
450.400000000006,34.43118126872767,-0.8043737819382841,-2.837812753253039
451.500000000006,34.46572854957945,-0.8340153928504597,-2.83841239984193
452.60000000000605,34.50063279335712,-0.8589020501126478,-2.8417223152235644
453.700000000006,34.53467144726108,-0.8803838677742736,-2.845306364095576
454.80000000000604,34.57001395708315,-0.9010016800565761,-2.8492395628050966
455.90000000000606,34.60483254196779,-0.9210813321929776,-2.852312777948528
457.0000000000061,34.63960698080938,-0.9420511492451277,-2.8545610293161823
458.1000000000061,34.67416604001621,-0.9643672400825686,-2.859573357754357
459.2000000000061,34.70916194973842,-0.990698860179353,-2.8622313186539574
460.30000000000615,34.74393994529494,-1.014011626441543,-2.864680228917319
461.4000000000061,34.77874389418713,-1.036488255237576,-2.867608715761354
462.50000000000614,34.813297220613414,-1.056954388219679,-2.868384068697408
463.60000000000616,34.84846339043607,-1.0748818239551805,-2.8712263725681586
464.7000000000062,34.88300767087657,-1.0888260485386032,-2.873341583022423
465.8000000000062,34.91790162615119,-1.1023351038367395,-2.877033781113414
466.90000000000623,34.95301258392087,-1.112528631718537,-2.879185558582669
468.00000000000625,34.98764800841851,-1.1231382139744122,-2.880742022936379
469.1000000000063,35.0220836616664,-1.1318302361545693,-2.8844063577995263
470.2000000000063,35.057328631008396,-1.1409883210148695,-2.886829544840181
471.30000000000626,35.09201167079048,-1.1429485877467016,-2.8894472804083167
472.4000000000063,35.12729007951774,-1.149103465725196,-2.8909560671693906
473.5000000000063,35.16213810977372,-1.1508978282169762,-2.8933437466121283
474.60000000000633,35.19717420127941,-1.1550802634316104,-2.89554964900993
475.70000000000636,35.23206504909254,-1.1587981951367479,-2.898763502919155
476.8000000000064,35.26696303700939,-1.1634075010378786,-2.9009515005704873
477.9000000000064,35.3018232433158,-1.1694480056292686,-2.903298564658258
479.00000000000637,35.33635378239575,-1.1728030725531369,-2.9057052999777278
480.1000000000064,35.37144132620752,-1.1771745078606914,-2.90775093313461
481.2000000000064,35.40660336111977,-1.1811130654600095,-2.9109078638403765
482.30000000000643,35.44185133783762,-1.1862050369864556,-2.9126304818169597
483.40000000000646,35.47639935430342,-1.1916366112725905,-2.9144744513008494
484.5000000000065,35.511844191849846,-1.1990544485707548,-2.9176530831341507
485.6000000000065,35.54693092905249,-1.2083869052994867,-2.9193595921664093
486.7000000000065,35.581638387607505,-1.2136406563238356,-2.920669295741897
487.80000000000655,35.616785983764316,-1.2199975680465682,-2.922251647363563
488.9000000000065,35.65177300146218,-1.221922373009145,-2.923708849271123
490.00000000000654,35.68676623367616,-1.2263899613285751,-2.9264013448362665
491.10000000000656,35.72216768115202,-1.2306423041431251,-2.9285313692133124
492.2000000000066,35.75725732300846,-1.2337633151533018,-2.930356463736319
493.3000000000066,35.79219659132434,-1.234729796846457,-2.9313786759308034
494.4000000000066,35.82734843004919,-1.2359799671006129,-2.933880110764403
495.50000000000665,35.86234308095245,-1.2369443325552367,-2.935346045366782
496.6000000000066,35.897322931331075,-1.2353470783307328,-2.936939868707503
497.70000000000664,35.932785579188746,-1.2349136031639434,-2.939939513997212
498.80000000000666,35.967759220025556,-1.2324975513519931,-2.9416478347020028
499.9000000000067,36.00281229907611,-1.2306513232242338,-2.9432098172568244
501.0000000000067,36.038138976465994,-1.2273219815189274,-2.9448689119214015
502.10000000000673,36.07306080091416,-1.2219296138308455,-2.946257795451342
503.20000000000675,36.10847593753721,-1.212249723715257,-2.948905813772773
504.3000000000068,36.143392940934824,-1.1949356061522771,-2.9514363296808304
505.4000000000068,36.178738898903845,-1.173456081098668,-2.952961066358885
506.50000000000676,36.21357257758485,-1.151467281561691,-2.954269094952291
507.6000000000068,36.248669323971185,-1.137091733633921,-2.9547815535675133
508.7000000000068,36.28403276996579,-1.125147670173763,-2.955889062856923
509.80000000000683,36.31915091842866,-1.1104871548290376,-2.957584965776956
510.90000000000686,36.3543343206315,-1.0989786450037469,-2.9590838149431575
512.0000000000068,36.38976630504385,-1.0840094817516412,-2.960604343872305
513.100000000007,36.424000587886944,-1.070539989667708,-2.9622988358798157
514.2000000000069,36.46009606101965,-1.0576933245372475,-2.9650399717962213
515.3000000000069,36.495340684184754,-1.044835006093517,-2.965992926572415
516.4000000000069,36.53050164328124,-1.0292622750618818,-2.9676212445607746
517.5000000000069,36.565912084503125,-1.0154309795092382,-2.971065204438628
518.600000000007,36.60110175390607,-0.9975933223745181,-2.9727111123440135
519.700000000007,36.63662209279505,-0.9783067717650551,-2.9741242850851934
520.800000000007,36.67194272529443,-0.9607896381099711,-2.9753338242371834
521.900000000007,36.70714913355528,-0.9452429228628074,-2.9755062574859164
523.000000000007,36.74246761652722,-0.9300796617572767,-2.9777475711860184
524.100000000007,36.77746594910253,-0.9166277777142335,-2.979187737753601
525.2000000000071,36.81255916592976,-0.900438995056152,-2.98061671237102
526.300000000007,36.8478903555402,-0.8881180441894619,-2.9810596644745555
527.4000000000071,36.88311696597243,-0.8741974618536626,-2.983430005681296
528.500000000007,36.91937722358,-0.8634444663640272,-2.9850715480150574
529.6000000000072,36.954333626479254,-0.8515328205078875,-2.9859045718810564
530.7000000000071,36.990353765111884,-0.8445952156048049,-2.9867162205708295
531.8000000000071,37.02563365589761,-0.8354929165577655,-2.9889534783106297
532.9000000000071,37.06117442497297,-0.8251843936621671,-2.990317395638626
534.0000000000072,37.096584544313956,-0.8172720003272353,-2.9917128231681884
535.1000000000072,37.13183277962587,-0.8082915365632785,-2.9938720742497504
536.2000000000072,37.167822641186255,-0.8001588391550984,-2.9960512462862283
537.3000000000072,37.203161665459916,-0.7914066748390931,-2.9975521884198533
538.4000000000073,37.23871724992224,-0.7808410211541046,-2.998402250052225
539.5000000000073,37.27424288800258,-0.7701284392791864,-2.999253018931751
540.6000000000073,37.309839717777336,-0.7645038964058263,-2.999264509830206
541.7000000000073,37.345267782553016,-0.759667335475361,-3.0004878108177295
542.8000000000073,37.38116815535576,-0.7560502468038768,-3.0019100899434177
543.9000000000074,37.41654086662974,-0.7507480882414664,-3.0033292460795664
545.0000000000073,37.45224783688401,-0.7487707471376484,-3.004776960889777
546.1000000000073,37.48777373408588,-0.7452717563182205,-3.006188042191912
547.2000000000073,37.5234222647625,-0.7410749192908239,-3.007414929268297
548.3000000000073,37.55894134579574,-0.7406020178470327,-3.0075042862842274
549.4000000000074,37.594620557395494,-0.737204867527251,-3.009257393348646
550.5000000000074,37.63020811274968,-0.7350752707001752,-3.010794314740893
551.6000000000074,37.6661865734302,-0.7362418951941527,-3.012240415803002
552.7000000000074,37.70189441807668,-0.7323556933918973,-3.0137626271688345
553.8000000000075,37.73729092014856,-0.7321813713891316,-3.015015888878658
554.9000000000075,37.77300063972118,-0.7343416989225997,-3.015085090787138
556.0000000000075,37.8087527201862,-0.734520965313148,-3.016767554897445
557.1000000000075,37.8443331893708,-0.7387105827680717,-3.0180017304008677
558.2000000000075,37.8803285661234,-0.7419361798406917,-3.0193702361139594
559.3000000000076,37.91585987708489,-0.7474228967195141,-3.0209342993033137
560.4000000000076,37.951688106089954,-0.7488948555814393,-3.022191376930715
561.5000000000076,37.987298753949844,-0.7541245417184932,-3.0222221455991582
562.6000000000076,38.02324330757664,-0.7593293644707733,-3.023651328619558
563.7000000000075,38.05905116235396,-0.764506121819542,-3.0251853544773217
564.8000000000076,38.094933501615195,-0.7719107763100992,-3.0266055427241665
565.9000000000076,38.13065282417029,-0.7763167836670835,-3.027861388402078
567.0000000000076,38.166441807443945,-0.7807343866357531,-3.028562674966138
568.1000000000076,38.202399137825026,-0.7897125350499704,-3.0279243748006763
569.2000000000077,38.238201323179055,-0.795980677327846,-3.029259976996504
570.3000000000077,38.2738715832614,-0.8049022026150179,-3.030683899336096
571.4000000000077,38.30978243769798,-0.8108903524532444,-3.0329389653594414
572.5000000000077,38.34582829446504,-0.8166674859113642,-3.032958892660982
573.6000000000078,38.381680126136736,-0.8245232432443544,-3.034299204701197
574.7000000000078,38.41793632045837,-0.8292651830491857,-3.0342577935918262
575.8000000000078,38.453198096126734,-0.8366196313314042,-3.0356206434775626
576.9000000000078,38.489513554232616,-0.8474493756426926,-3.037045972926836
578.0000000000078,38.525232489623605,-0.8531167368451279,-3.037580553833412
579.1000000000079,38.561624292917834,-0.8599151023956356,-3.0385266172025793
580.2000000000078,38.597263599849576,-0.8677027625969259,-3.038453244052383
581.3000000000078,38.63326440162081,-0.8742481211760198,-3.0397899315904247
582.4000000000078,38.66893985930207,-0.8820277212004383,-3.04095080089565
583.5000000000078,38.70513492167854,-0.8890440614389385,-3.041065307503779
584.6000000000079,38.741018521079404,-0.8939804442123773,-3.0424191556921016
585.7000000000079,38.776863426769225,-0.9023400089681969,-3.0426912704687874
586.8000000000079,38.81289895327938,-0.9113692161919841,-3.0449019002729174
587.9000000000079,38.84916773721836,-0.9188288854770789,-3.0465585655978273
589.000000000008,38.885078645503405,-0.9267285774764882,-3.048288984281449
590.100000000008,38.92115703657476,-0.9345710389631041,-3.049625716631353
591.200000000008,38.95705703066432,-0.94028326227601,-3.0508796538278604
592.300000000008,38.99322893834687,-0.9484618471500582,-3.0517155003771084
593.400000000008,39.02912688429528,-0.9560413779225098,-3.050862794699016
594.5000000000081,39.06527388455882,-0.9615370341167263,-3.052195050736853
595.6000000000081,39.10142527292738,-0.9695233544799116,-3.053496381304104
596.7000000000081,39.137409835030596,-0.9757404363420104,-3.0535095930421114
597.8000000000081,39.17346770859004,-0.9840589342017027,-3.054186719500609
598.900000000008,39.20955727881609,-0.9890993528666214,-3.0548300082121553
600.0000000000081,39.24576178060241,-0.9964482546221203,-3.054474329285265
601.1000000000081,39.28171532501028,-1.002733622971569,-3.0559244109928354
602.2000000000081,39.317512227413026,-1.0070199438502534,-3.0573683989086766
603.3000000000081,39.3539564866096,-1.0146857869651993,-3.0588800659807847
604.4000000000082,39.390462641061994,-1.0201773653274537,-3.0599860567843957
605.5000000000082,39.42650554130919,-1.02819583900226,-3.0602197263724387
606.6000000000082,39.46285649470865,-1.0327875542886096,-3.060575258621958
607.7000000000082,39.49888281513337,-1.0373217466358384,-3.0605501919005933
608.8000000000083,39.53511769460983,-1.043942015755644,-3.0605901047062005
609.9000000000083,39.571606517227465,-1.0511416135421483,-3.0618605473356344
611.0000000000083,39.60776923530416,-1.0560521801836367,-3.0618813762615593
612.1000000000083,39.64354095331097,-1.0624653621006466,-3.06374213287223
613.2000000000083,39.68032170398674,-1.0687243115845197,-3.0655074611464594
614.3000000000084,39.71644125969478,-1.0733547729905317,-3.065894569316554
615.4000000000083,39.752665754806344,-1.0784525352061047,-3.0673196965079628
616.5000000000083,39.78905248806389,-1.0847593487738056,-3.067449084265216
617.6000000000083,39.82531219463442,-1.0874294772930229,-3.0687779659638155
618.7000000000083,39.86199738720319,-1.0945398484221285,-3.0687776779813367
619.8000000000084,39.89805607112922,-1.0984287061775115,-3.0701404615729877
620.9000000000084,39.93429453925191,-1.104094522568105,-3.0687841780130936
622.0000000000084,39.97073263084035,-1.1087554045390888,-3.0700837322484773
623.1000000000084,40.00712850371202,-1.1146492685087201,-3.0714051428638016
624.2000000000085,40.0433105388141,-1.1188094142711806,-3.0713926324763796
625.3000000000085,40.07980768279347,-1.1218772166663944,-3.0727298803587715
626.4000000000085,40.11632326241293,-1.1243730875036924,-3.072683353421711
627.5000000000085,40.152550019533464,-1.1277203398941875,-3.0740499907136987
628.6000000000085,40.18884161023081,-1.135649668162643,-3.0753746211365343
629.7000000000086,40.22554913470593,-1.1390489955024847,-3.0753574568905657
630.8000000000086,40.26207370790743,-1.1404889467089745,-3.0766652048527945
631.9000000000086,40.298399798748115,-1.1463293625115332,-3.0766840215621554
633.0000000000086,40.33461768843856,-1.1486428744476715,-3.0779952466752967
634.1000000000085,40.37135069061492,-1.1539192182431954,-3.077953913660311
635.2000000000086,40.40774112869174,-1.1538771807636221,-3.079319352505475
636.3000000000086,40.44405004328156,-1.1588673838246375,-3.07933416866844
637.4000000000086,40.48041812035679,-1.1637363307624522,-3.0806309744328213
638.5000000000086,40.51708889256812,-1.1641366749984199,-3.0806271063088544
639.6000000000087,40.55293443907948,-1.1685801835927137,-3.0799367340061696
640.7000000000087,40.58979374497053,-1.1694915185193715,-3.0806267730938806
641.8000000000087,40.62636969790722,-1.1733961234712478,-3.081953925201775
642.9000000000087,40.66268836038127,-1.176050882894889,-3.0819542776699413
644.0000000000088,40.699496683322224,-1.17680510195046,-3.083272645484084
645.1000000000088,40.73574200941737,-1.1781335186289488,-3.0842200814154515
646.2000000000088,40.77221654501123,-1.1816989393742243,-3.0845606415040416
647.3000000000088,40.808952695416686,-1.1798015748432606,-3.0855700847673244
648.4000000000088,40.84558476296218,-1.1844073023073267,-3.0855698886071563
649.5000000000089,40.881865985538965,-1.1857248324442737,-3.085695851555258
650.6000000000088,40.91843482256772,-1.188514706521438,-3.0868895017644884
651.7000000000088,40.954960000937085,-1.1896205162817344,-3.087373472286414
652.8000000000088,40.991472886072735,-1.1921680009876734,-3.088188637290454
653.9000000000088,41.02723546927096,-1.1896403458652889,-3.0885518579365683
655.0000000000089,41.064555906520624,-1.1919020827613553,-3.088530769170057
656.1000000000089,41.10108553271444,-1.1912553076855261,-3.089887705113309
657.2000000000089,41.137567425681425,-1.1914045306002667,-3.0898500358657177
658.3000000000089,41.17393812179952,-1.1945304980664662,-3.089862656588996
659.400000000009,41.21062834641195,-1.192667538896632,-3.0911709251293336
660.500000000009,41.24735816782791,-1.1948194715789682,-3.091560479623314
661.600000000009,41.283575205017804,-1.1953249550342935,-3.0924905481545633
662.700000000009,41.320332783611256,-1.1944536850366547,-3.0938154027962446
663.800000000009,41.35681766685422,-1.1923214267063258,-3.0938000171424394
664.9000000000091,41.393167893876864,-1.1922502925186715,-3.093803133706238
666.0000000000091,41.42987919259838,-1.193244921120294,-3.09377942969421
667.1000000000091,41.46663810730011,-1.1916615265409736,-3.0938098623848194
668.2000000000091,41.50296339478921,-1.1908553595485636,-3.0938068293539334
669.300000000009,41.53935713572306,-1.1909693145650047,-3.0952503816706636
670.4000000000091,41.57638883707503,-1.1920424556680669,-3.096437309235826
671.5000000000091,41.61286933886226,-1.1933019831166116,-3.096560100505519
672.6000000000091,41.64929720393684,-1.198788223941938,-3.097723885112391
673.7000000000091,41.6864000460523,-1.2029910291843442,-3.0978697845898484
674.8000000000092,41.72258931675426,-1.2032599637407604,-3.0992119616140394
675.9000000000092,41.758656734128216,-1.2104246777541807,-3.098222959660668
677.0000000000092,41.79590506531,-1.2126944895347866,-3.098838439946089
678.1000000000092,41.831999541219126,-1.2186541412234455,-3.0991926512239183
679.2000000000093,41.86871824631951,-1.2266445488233673,-3.100504711516506
680.3000000000093,41.9057598245969,-1.2352810915117132,-3.101419992510764
681.4000000000093,41.942626906099484,-1.2395186967324454,-3.101823827726135
682.5000000000093,41.979217877502656,-1.2453210338304717,-3.1031468962772992
683.6000000000093,42.01589412121129,-1.2537003081723808,-3.1024748921812755
684.7000000000094,42.05229509474332,-1.2589406173934354,-3.1027237314772984
685.8000000000093,42.088864852876064,-1.2663827403845516,-3.103799734173556
686.9000000000093,42.12591373361398,-1.273997237000068,-3.1038024740319803
688.0000000000093,42.16248940659793,-1.2799030715057467,-3.1051147344212424
689.1000000000093,42.1992785752801,-1.288961436278322,-3.105120042880352
690.2000000000094,42.23618750014339,-1.2992145806308302,-3.106304452931575
691.3000000000094,42.27278662174596,-1.3049829079637512,-3.106428611972966
692.4000000000094,42.309316391478326,-1.3146329165875668,-3.1077356377638443
693.5000000000094,42.34620088825816,-1.3247459133192179,-3.1077546322830605
694.5000000000094,42.379419917103085,-1.3326628192652645,-3.10906782913381