File: 01_Data/Smoke_Explosion_Plywood/STA/N2/30K_min/Smoke_Explosion_Plywood_STA_N2_30KData_230729_R2.csv
##Temp./Â°C,Time/min,DSC/(mW/mg),Mass loss/mg
29.0,20.378729252278713,-2.3239552322993964,-0.18548919615377413
30.100000000000016,20.686281784599323,-2.2865840599714464,-0.1845570965148311
31.20000000000003,20.836637491465535,-2.267383891015715,-0.1843457210606525
32.30000000000005,20.943161983185405,-2.258194374661256,-0.18551331594980391
33.40000000000006,21.032500000000013,-2.2494700000000005,-0.1854594931739908
34.50000000000008,21.112201837758434,-2.240150747510215,-0.18578626387173403
35.600000000000094,21.1828874667865,-2.2375583984297553,-0.1856589927659389
36.70000000000011,21.248778020358717,-2.231058651817087,-0.18714773242369986
37.800000000000125,21.30961870718926,-2.2253783860314407,-0.1856372291886026
38.90000000000014,21.368501912664783,-2.2231244036992472,-0.18758435795741457
40.000000000000156,21.424974616871964,-2.2181495043424273,-0.18754967265860278
41.10000000000017,21.478427074758148,-2.2167013243699367,-0.18687903188815547
42.20000000000019,21.53030966472743,-2.2168210778419644,-0.1883339353948945
43.3000000000002,21.58116760771152,-2.217223312275436,-0.1891074194012421
44.40000000000022,21.630182660406593,-2.217492683250772,-0.1891026508245348
45.500000000000234,21.678725376541223,-2.219050873809683,-0.19088403385525998
46.60000000000025,21.72583000000001,-2.221530000000002,-0.19105222190593985
47.700000000000266,21.771988582905564,-2.2251193056000256,-0.19222261718894185
48.80000000000028,21.81759463174745,-2.228642446672897,-0.1921389519312311
49.9000000000003,21.863122916791397,-2.234286683152888,-0.19339161433572105
51.00000000000031,21.907051575289344,-2.243204070218967,-0.19574626537220263
52.10000000000033,21.950399830864285,-2.2497897466567762,-0.19785193171428617
53.200000000000344,21.994441265403317,-2.2592393542511657,-0.1990387228692292
54.30000000000036,22.03772582783589,-2.26955567103601,-0.19930395366080988
55.400000000000375,22.079936513124256,-2.2807555429269066,-0.19830265973669636
56.50000000000039,22.12205958189694,-2.2922795534162423,-0.19991649351850826
57.600000000000406,22.1636950577167,-2.305526215240166,-0.20176061674682577
58.70000000000042,22.205398936169715,-2.3195374430759945,-0.20363361556900283
59.80000000000044,22.246523939262953,-2.3348906318397478,-0.20678089862790783
60.90000000000045,22.28728366050489,-2.350053472137367,-0.20708677291078414
62.00000000000047,22.328231168007047,-2.366430741198448,-0.208556859331952
63.100000000000485,22.36845379275518,-2.3834117346703176,-0.21012983873012603
64.2000000000005,22.409074681196305,-2.4008852897760016,-0.2114421731498788
65.30000000000052,22.449192427042288,-2.417211807580762,-0.21426994173068747
66.40000000000053,22.489427616646644,-2.4357171909125426,-0.21731443104259185
67.50000000000054,22.527919792472126,-2.452593827624217,-0.21987455228390917
68.60000000000056,22.568805558733054,-2.4728053790928755,-0.22120201852079457
69.70000000000059,22.608558875674582,-2.4894050501421394,-0.22270701903390044
70.8000000000006,22.6482038799645,-2.5077141683889423,-0.2246915653606325
71.9000000000006,22.68683693858413,-2.524302433108618,-0.22672544563544728
73.00000000000063,22.726066462698633,-2.5390264184882745,-0.22801509879800452
74.10000000000065,22.765696154057174,-2.556325616324892,-0.22933075248016088
75.20000000000066,22.803956124897056,-2.570308998091425,-0.23102112410531372
76.30000000000067,22.8433423366847,-2.5845079592435107,-0.2325358725028499
77.40000000000069,22.88180895331314,-2.5960899187387207,-0.23488646810114
78.50000000000071,22.92102793718733,-2.6085070587529775,-0.2370329157616866
79.60000000000072,22.95941917184046,-2.6164106612452565,-0.23989684583635995
80.70000000000073,22.997898419486376,-2.6241435181332022,-0.2423142764279893
81.80000000000075,23.036119810354755,-2.629612620911247,-0.24470090058000293
82.90000000000077,23.074649260007078,-2.634030302518365,-0.2476609072516669
84.00000000000078,23.113183628437508,-2.636801037854025,-0.24937473608962435
85.10000000000079,23.15107153712188,-2.6373482947214453,-0.2520028659311162
86.20000000000081,23.18843506372525,-2.6356577738124334,-0.2551787332520523
87.30000000000084,23.226137057389884,-2.6332016944487937,-0.2583600937695496
88.40000000000084,23.263711273188974,-2.6271400217725436,-0.2594716341071277
89.50000000000085,23.300781325896754,-2.620241234722812,-0.26188986777373424
90.60000000000088,23.33821435631087,-2.6120105379871057,-0.2651513237394547
91.7000000000009,23.375094392581428,-2.6016584419219777,-0.26717706630711247
92.8000000000009,23.41217187806648,-2.5891455946528428,-0.27035482635324826
93.90000000000092,23.44932106593343,-2.575393555020725,-0.2723952423047904
95.00000000000094,23.48589770748612,-2.5601720052799126,-0.2754394415640884
96.10000000000096,23.522088027379933,-2.543304612378588,-0.27678851820404926
97.20000000000097,23.558960046212682,-2.524209185071214,-0.27825766491311965
98.30000000000098,23.59546569372064,-2.503689449496662,-0.28125197634124355
99.400000000001,23.631507118344214,-2.4835954201365933,-0.2826484974650567
100.50000000000102,23.668006975007415,-2.4591282004122728,-0.28519037504867795
101.60000000000103,23.70322340682165,-2.4363951207423944,-0.28714185345172627
102.70000000000104,23.74031207921421,-2.4109082140170517,-0.28878831630233615
103.80000000000106,23.776502804206466,-2.3853259216145943,-0.2904026535719546
104.90000000000109,23.812369158354173,-2.358848421426729,-0.2915800656068841
106.0000000000011,23.848568479045003,-2.3319554981090937,-0.2921640365893863
107.1000000000011,23.883296083274104,-2.305043012201772,-0.29511657705984895
108.20000000000113,23.91985437213267,-2.278074345124067,-0.295665495827528
109.30000000000115,23.955732034550856,-2.2498893362803623,-0.29695803430415113
110.40000000000116,23.99154320449956,-2.2201902027684746,-0.29828802569433277
111.50000000000117,24.02758760071019,-2.1924788865873825,-0.30100050318828764
112.60000000000119,24.06317626492412,-2.164651475510141,-0.3023953362374221
113.70000000000121,24.098766770008158,-2.1356389314937596,-0.3023427853234031
114.80000000000122,24.134907931370282,-2.1084675627771254,-0.30492179753130255
115.90000000000123,24.170461462230584,-2.0811433978604796,-0.30497915143904386
117.00000000000125,24.206029483098636,-2.052485724687519,-0.3059672521799093
118.10000000000127,24.241837446267287,-2.025514779396735,-0.3059700965802956
119.20000000000128,24.277343434194712,-1.9998005672144477,-0.3059286291629184
120.30000000000129,24.31250000000005,-1.9751899999999791,-0.30760650046970595
121.40000000000131,24.347275882965217,-1.9504291623695063,-0.3076082470049868
122.50000000000134,24.383390517926646,-1.9274738041768398,-0.30896175139909365
123.60000000000134,24.418349551726905,-1.9053149717234465,-0.30893011958234196
124.70000000000135,24.45371424418259,-1.8821746442413305,-0.30889878927268866
125.80000000000138,24.489123611463256,-1.861713274291655,-0.31091439670156795
126.9000000000014,24.52338406961077,-1.8426454127289627,-0.31091004410586676
128.00000000000142,24.55975496618453,-1.823208477501836,-0.31019856867544515
129.10000000000142,24.594504323506303,-1.8061829792214645,-0.3102498838233698
130.20000000000144,24.629746908985044,-1.7896333697531588,-0.31024980193889506
131.30000000000146,24.665115329807353,-1.7732512735974795,-0.31024980199995733
132.40000000000146,24.700242818303114,-1.7598840765517563,-0.3102498019653237
133.50000000000148,24.73520116281138,-1.7459741390966967,-0.3102498700620271
134.6000000000015,24.770050429665147,-1.7340922980346256,-0.3101840481299125
135.70000000000152,24.805141926765273,-1.720950875916454,-0.31090898579891313
136.80000000000155,24.83994574412104,-1.7101690559754936,-0.3121286208111793
137.90000000000154,24.874631380793137,-1.7003470930028834,-0.31353555063691196
139.00000000000156,24.909565721666624,-1.6925293669184578,-0.31353992058528
140.1000000000016,24.94431849289233,-1.68426951371344,-0.31353991616799215
141.20000000000158,24.978495531267,-1.6748633842787488,-0.31353941157190324
142.3000000000016,25.01361213461917,-1.6682064395467084,-0.3121915266027706
143.40000000000163,25.0483463576736,-1.6619630611716056,-0.31222993828058776
144.50000000000165,25.082721195180813,-1.6573449285316146,-0.3122110279918955
145.60000000000167,25.117300381926224,-1.6523513529099862,-0.31353727938797205
146.70000000000167,25.151682839470844,-1.6466274605299136,-0.3135399164556367
147.8000000000017,25.186041090891088,-1.6430174200957044,-0.31353991451576
148.9000000000017,25.220692138905136,-1.639507376240297,-0.31354008466554184
150.0000000000017,25.255237201989583,-1.6353154310325124,-0.3145325126440577
151.10000000000173,25.28960553013598,-1.6312396202068409,-0.3148599860502923
152.20000000000175,25.324003007128006,-1.6279297620197732,-0.31485991484273557
153.30000000000177,25.358344156936052,-1.625450546501273,-0.31485994229591086
154.4000000000018,25.392826121726763,-1.6250253284523513,-0.31484170660630717
155.5000000000018,25.426672331359555,-1.6219824463380772,-0.31616892598476953
156.6000000000018,25.461375169419355,-1.6189696987330888,-0.3161699106119604
157.70000000000184,25.495469293898417,-1.617695577354033,-0.3161735952125424
158.80000000000183,25.529520549105058,-1.617059803402033,-0.31516718736700167
159.90000000000185,25.563541213004438,-1.613962506157061,-0.3151798566887001
161.00000000000188,25.59821545068819,-1.6150032801363612,-0.3151798459673958
162.1000000000019,25.632379306951787,-1.61324258128327,-0.3151798490126825
163.20000000000192,25.666287601992202,-1.6105250160709585,-0.31518852314950774
164.30000000000192,25.700810184257325,-1.608636425112329,-0.31650121477740756
165.40000000000194,25.73428794980387,-1.6088955683206956,-0.3164999738788503
166.50000000000196,25.768311457641666,-1.6060560408534155,-0.3164583813297459
167.60000000000196,25.80296682464835,-1.6074894850497166,-0.31782353381595785
168.70000000000198,25.83700423254119,-1.6060330220886987,-0.31781802593821595
169.800000000002,25.871065254196235,-1.6041809961592037,-0.31849818711834654
170.90000000000202,25.90508023686049,-1.603116873662623,-0.31848001180689023
172.00000000000205,25.939078449715005,-1.6042958681779542,-0.31848003001508696
173.10000000000204,25.973412942093603,-1.601912460537517,-0.31848002999934666
174.20000000000206,26.007543491503558,-1.6017945913256855,-0.3184800309306963
175.3000000000021,26.041174372210886,-1.6013237881279443,-0.31847931468488166
176.40000000000208,26.07502124543555,-1.6008975118556203,-0.3196504116201959
177.5000000000021,26.10924659277365,-1.6001881236577913,-0.31980021309686446
178.60000000000213,26.142835010903823,-1.5996500885364608,-0.3198001218918112
179.70000000000215,26.17652632682734,-1.6000217307720364,-0.3198001220001503
180.80000000000217,26.210263053139787,-1.5999355240273767,-0.3198001219999984
181.90000000000217,26.244249784118125,-1.599677376738035,-0.31980012200059615
183.0000000000022,26.27822706543085,-1.600249689443427,-0.3198001216848465
184.1000000000022,26.311555417135406,-1.5990056850330774,-0.31980038296060354
185.2000000000022,26.345248590476025,-1.6017380644395602,-0.32073974065444144
186.30000000000223,26.379110238002273,-1.5989239078665594,-0.32111018484835485
187.40000000000225,26.412376901607125,-1.6018462469731347,-0.3211078832048875
188.50000000000227,26.44644773146063,-1.6005147117953156,-0.32243053612425365
189.6000000000023,26.4799758727247,-1.6016318555739486,-0.32243081662760265
190.7000000000023,26.5133388236644,-1.6011844664075179,-0.323409512019567
191.8000000000023,26.546931706661475,-1.602447083026761,-0.32346402089098536
192.90000000000234,26.580430672602564,-1.6024134145401683,-0.3237501191745271
194.00000000000233,26.613846906719015,-1.6028104860037753,-0.3237499694792638
195.10000000000235,26.647602794406385,-1.6027956441768176,-0.32375235698649085
196.20000000000238,26.6808613404375,-1.6036139623275956,-0.3250839817636364
197.3000000000024,26.714343019981,-1.6055829930982173,-0.325070226201539
198.40000000000242,26.747700784986854,-1.6044086073163322,-0.3255806701470281
199.50000000000242,26.781029841473416,-1.605642757440061,-0.3263807906820575
200.60000000000244,26.81449452925679,-1.6061036271333375,-0.32618610495740574
201.70000000000246,26.848010921702972,-1.607575795206695,-0.32639000299678944
202.80000000000246,26.881375349656437,-1.6072192758626482,-0.32639057197756705
203.90000000000248,26.915124019413746,-1.6079904565450853,-0.3273714165743624
205.0000000000025,26.948384230338707,-1.6102500436626326,-0.3277489425423403
206.10000000000252,26.98148129976862,-1.6105357606260602,-0.3298473852855688
207.20000000000255,27.014998829163073,-1.6123364654007075,-0.33001041349624627
208.30000000000254,27.048251809441055,-1.612775864284158,-0.3305683092673921
209.40000000000256,27.081514121917845,-1.6125404337882947,-0.331301835946471
210.5000000000026,27.115026359672278,-1.6143553472179195,-0.33238360308475823
211.60000000000258,27.148480319802033,-1.6160201623101136,-0.33374401085390515
212.7000000000026,27.181464086569214,-1.6174954341173904,-0.33374017544202816
213.80000000000263,27.21516141464731,-1.6181122483863684,-0.3336985198657971
214.90000000000265,27.248099179971675,-1.618693340125033,-0.3351839225481399
216.00000000000267,27.281419075756403,-1.6193538936905834,-0.3365704138786558
217.10000000000267,27.314791793820397,-1.6223804442137755,-0.33797433460290494
218.2000000000027,27.347979825524998,-1.6244137507724774,-0.337491176653562
219.3000000000027,27.381375875968995,-1.625205593299823,-0.339465383155368
220.4000000000027,27.414483223339875,-1.6260121298561947,-0.34128583204025986
221.50000000000273,27.448107724366146,-1.6286047352585158,-0.34309819645851336
222.60000000000275,27.480953333882805,-1.6298658440976692,-0.34458588853828065
223.70000000000277,27.514428495259207,-1.6320213861216029,-0.34683351767018467
224.8000000000028,27.547698272813854,-1.63544472614691,-0.3483096049443124
225.9000000000028,27.581008148127182,-1.635894917947299,-0.34974841106116994
227.0000000000028,27.614143618020634,-1.6387929944060962,-0.35126332111882297
228.10000000000284,27.647425286833904,-1.6396386962912273,-0.3529939725908311
229.20000000000283,27.680662399396585,-1.6417866388211981,-0.354462755357313
230.30000000000285,27.713972887335284,-1.6441102026153505,-0.35697989114645967
231.40000000000288,27.746905188493923,-1.6455217675515186,-0.35968704478740277
232.5000000000029,27.780114718161194,-1.6456093483232308,-0.36410355250977
233.60000000000292,27.81345124036423,-1.6444625931300954,-0.36583968287713864
234.70000000000292,27.846574536112914,-1.6456447237613663,-0.3681101026820959
235.80000000000294,27.879577893975906,-1.6447393817773495,-0.3710247310700958
236.90000000000296,27.912390015724036,-1.645164700886538,-0.37412569849322175
238.00000000000296,27.9461309142925,-1.6438013563190945,-0.37622578440667587
239.10000000000298,27.979110948873096,-1.6418390204679016,-0.3778707764388418
240.200000000003,28.012620133306825,-1.643095193743849,-0.3794109078852079
241.30000000000302,28.04564290829253,-1.6417567811180953,-0.38179115309460565
242.40000000000305,28.0786588642172,-1.6428732254664569,-0.3845470328914402
243.50000000000304,28.11210309740271,-1.641565060546736,-0.38789726621666176
244.60000000000306,28.145253073064843,-1.639883217993934,-0.39120137610412486
245.7000000000031,28.178199115289242,-1.6378102298957438,-0.395054501520681
246.80000000000308,28.2116689645672,-1.636889018668778,-0.39827206336013576
247.9000000000031,28.24459718764348,-1.6365382504937938,-0.40115698044213266
249.00000000000313,28.277925336588993,-1.6327275094450973,-0.4050400427070677
250.10000000000315,28.310990221385772,-1.6307013971629427,-0.40767674680285815
251.20000000000317,28.34394634989055,-1.6269524435303893,-0.41077758701748834
252.30000000000317,28.377026805824464,-1.6217132148038114,-0.4145120742354833
253.4000000000032,28.40995605808679,-1.617496466475129,-0.41874402869184557
254.5000000000032,28.443487162739807,-1.612692221753742,-0.4229114170578052
255.6000000000032,28.476629616035126,-1.6079023531340673,-0.42708211309474153
256.70000000000323,28.50965823582602,-1.603763013380152,-0.43079925477966885
257.80000000000325,28.542044029244707,-1.6005316244544947,-0.4350356397404349
258.9000000000033,28.575932887453522,-1.597096732944322,-0.4387484650606659
260.0000000000033,28.609029373331563,-1.5955179421114998,-0.4423908270788326
261.1000000000033,28.642165308077978,-1.5917513165064257,-0.4476061316985853
262.20000000000334,28.675595952514456,-1.5895127235377196,-0.4523355202070163
263.30000000000337,28.708687783908523,-1.5844560149316052,-0.4567043994414237
264.40000000000333,28.741795357508458,-1.5818086077982225,-0.46147721726592605
265.50000000000335,28.775011954499284,-1.5787310604710112,-0.4659292449929975
266.6000000000034,28.807551869364087,-1.5768769421012279,-0.47014430935718154
267.7000000000034,28.840630380559578,-1.5735257416776296,-0.47513938513205867
268.8000000000034,28.873972277568054,-1.5705459636776318,-0.48105760067764214
269.9000000000034,28.90703255962871,-1.5657878662159073,-0.4870132870981565
271.0000000000034,28.9400575925042,-1.5631968217967347,-0.4925956160449285
272.10000000000343,28.973151688260966,-1.5590199691580795,-0.4969320203227885
273.20000000000346,29.006390616865186,-1.5557852130596403,-0.5010044366902986
274.3000000000035,29.03896462419683,-1.5533593923776867,-0.5075208698985332
275.4000000000035,29.072324377891547,-1.5481733539102411,-0.5147224383231208
276.5000000000035,29.105598104571012,-1.5445827420311002,-0.5205364344098009
277.60000000000355,29.138800212348855,-1.5409623186227335,-0.5261905400284546
278.70000000000357,29.171778454821407,-1.5373923607279218,-0.5322462797173206
279.8000000000036,29.20502411102292,-1.5306882011818623,-0.5389438964222624
280.9000000000036,29.237998831276133,-1.5278452909495936,-0.5451504223848538
282.0000000000036,29.270200698200583,-1.523530096876838,-0.5521102154645927
283.1000000000036,29.303767931489954,-1.5198842879334626,-0.5595020522016161
284.2000000000036,29.336921693505165,-1.5131820030804513,-0.5670474649723127
285.30000000000365,29.370042512098557,-1.5095794586030635,-0.5746995132319901
286.4000000000037,29.40341969769214,-1.5057355108549557,-0.5829434221075203
287.5000000000037,29.436662244310902,-1.498826064473999,-0.5910643939230549
288.60000000000366,29.469382068700284,-1.494866950994272,-0.5985538083227593
289.7000000000037,29.501965757804754,-1.4906277852289276,-0.6071386460979555
290.8000000000037,29.535963526434156,-1.4831311044252495,-0.6161947192599788
291.90000000000373,29.568840216088695,-1.476926887237115,-0.6270537052037586
293.00000000000375,29.601831895125233,-1.4705065655918665,-0.6373569816498752
294.1000000000038,29.635035482690192,-1.4653443353260676,-0.6478476706542966
295.2000000000038,29.66814594456853,-1.4608962683690665,-0.6587249084842921
296.3000000000038,29.701234771402117,-1.4527224659625617,-0.6697839305521085
297.40000000000384,29.734466354189983,-1.4474698582545678,-0.6806835116236951
298.5000000000038,29.767689529461354,-1.4417846355593833,-0.6919965589399837
299.60000000000383,29.800510459910754,-1.4343134797405008,-0.7025303431010252
300.70000000000385,29.83363071404462,-1.4276596871937919,-0.7135795895729684
301.8000000000039,29.86696423782682,-1.420604345665644,-0.725505976769671
302.9000000000039,29.89976878985612,-1.4149641304205127,-0.7370894896616575
304.0000000000039,29.93326033441799,-1.4075691064939426,-0.7499140284992003
305.10000000000394,29.966366634265537,-1.4010771503659922,-0.7635590870057847
306.2000000000039,29.999494841159418,-1.3949781959384873,-0.7773129429933263
307.30000000000393,30.032469833551044,-1.3892313099313967,-0.7914195474681813
308.40000000000396,30.065830310587742,-1.3838999350482712,-0.8047095387247816
309.500000000004,30.098787716048633,-1.3783709305731706,-0.8188133452865491
310.600000000004,30.13174032900366,-1.3729477303900115,-0.8340071363860391
311.700000000004,30.165344384494574,-1.3692479770126194,-0.8500359144101051
312.80000000000405,30.198831618562497,-1.3644847099540724,-0.8667903241834232
313.90000000000407,30.231508437695414,-1.3597442842325338,-0.8824917672913277
315.0000000000041,30.264926241707492,-1.3559738010800064,-0.8996453848677213
316.10000000000406,30.2980794999509,-1.3511166884655181,-0.9177386699397929
317.2000000000041,30.331616019371193,-1.3489777462215042,-0.9357775568035254
318.3000000000041,30.364729391495835,-1.3439794670383156,-0.953856969811659
319.4000000000041,30.39787437439436,-1.342611803093231,-0.9726774758890318
320.50000000000415,30.431341933808984,-1.3399511176607557,-0.9922420490581114
321.6000000000042,30.464598902656864,-1.3382845171647715,-1.010552695223769
322.7000000000042,30.49729458142152,-1.3346356459718534,-1.0294109669436287
323.80000000000416,30.531181052569437,-1.3349502991380107,-1.0500290163529042
324.9000000000042,30.564498672832585,-1.3317615959442464,-1.0720734814887458
326.0000000000042,30.597847181043225,-1.3303548276071644,-1.093259606647217
327.10000000000423,30.630961077270523,-1.3259910724631936,-1.115326124182324
328.20000000000425,30.664419457760616,-1.3243744316692503,-1.1372072132647326
329.3000000000043,30.69806071972533,-1.3202612034567835,-1.159318726005222
330.4000000000043,30.73158769512043,-1.3184935059025131,-1.181099180037005
331.5000000000043,30.76457668416849,-1.3159785274575215,-1.2034553214267163
332.60000000000434,30.798276666852974,-1.3132341542610595,-1.2270672628747956
333.7000000000043,30.83158231303147,-1.311080744779255,-1.2510916734967537
334.80000000000433,30.86490154986643,-1.3072909229933385,-1.2752164495121048
335.90000000000435,30.898308403711255,-1.3010626561657135,-1.3001507489619342
337.0000000000044,30.93143958974353,-1.2948807055957767,-1.3253677715833567
338.1000000000044,30.965192619196603,-1.2894983467642585,-1.351700569201272
339.2000000000044,30.998628333655603,-1.284534781357253,-1.3776870565573813
340.30000000000445,31.032233147919115,-1.2772217245547204,-1.4047858327727267
341.4000000000044,31.06558370546692,-1.2717735802617771,-1.4311522167254687
342.50000000000443,31.09877042971683,-1.2658918707953095,-1.458570781630073
343.60000000000446,31.1321749355287,-1.2568086666326403,-1.4860844370566255
344.7000000000045,31.165768596912805,-1.2455170475563633,-1.5138583246209225
345.8000000000045,31.199198915933792,-1.2378910285171114,-1.5417043979830019
346.9000000000045,31.2327164923495,-1.2279424455557415,-1.5701945110262359
348.00000000000455,31.26628304839182,-1.2158326310063496,-1.5992821360984184
349.10000000000457,31.299859941310444,-1.20559830616335,-1.6288078034837001
350.2000000000046,31.333136172713807,-1.193856473064346,-1.6585144406357064
351.30000000000456,31.36673446366108,-1.1824356892860577,-1.6881358787009457
352.4000000000046,31.400125130044508,-1.1706086943800864,-1.7169934156194304
353.5000000000046,31.433512290008203,-1.160382986473234,-1.7469960463377414
354.6000000000046,31.467198335068698,-1.1483385496744534,-1.7768598466518335
355.70000000000465,31.500987876043006,-1.1341473532227313,-1.8063879391026858
356.8000000000047,31.534567654481656,-1.1215163055968018,-1.8355954422330325
357.9000000000047,31.56730051923082,-1.110890988917725,-1.8633429791962017
359.00000000000466,31.600833755986848,-1.0988336637206106,-1.8918175525936891
360.1000000000047,31.635174139970168,-1.0858344514191611,-1.921561263771117
361.2000000000047,31.66882756887942,-1.072380787164451,-1.9516512401965396
362.30000000000473,31.70214103638994,-1.0615743641277704,-1.9810881197350927
363.40000000000475,31.735631538864737,-1.0500787104208376,-2.0090274787456996
364.5000000000048,31.76955977330428,-1.0371038633820575,-2.0369727913352706
365.6000000000048,31.803086749473863,-1.0247343055979754,-2.0650432437236717
366.7000000000048,31.836653694184502,-1.0112875019573542,-2.0929416751218266
367.80000000000484,31.87045765107582,-0.9984391419026246,-2.1216657416567273
368.9000000000048,31.9038251447717,-0.9837526832861953,-2.148758581860845
370.00000000000483,31.937662997792053,-0.9693338253936832,-2.175353581414989
371.10000000000485,31.971557542400657,-0.9523660689778242,-2.201964340213439
372.2000000000049,32.005072959103245,-0.9372229359412931,-2.228224512920356
373.3000000000049,32.03848386693046,-0.9224235820039501,-2.2535498940386924
374.4000000000049,32.07215710744176,-0.9056590514585363,-2.2797186936724128
375.50000000000495,32.106106500714205,-0.8889277891188475,-2.303769838583459
376.6000000000049,32.13979990461729,-0.8694253604632408,-2.3269602326658108
377.70000000000493,32.17353466781138,-0.8519995922546854,-2.349052921480361
378.80000000000496,32.20703719197941,-0.8348009937649795,-2.3705506079214
379.900000000005,32.24082894595592,-0.8158673744922058,-2.391799152562764
381.000000000005,32.274484679439546,-0.7990227852866941,-2.412214306819366
382.100000000005,32.30810141240425,-0.7823290253638762,-2.4311999391482386
383.20000000000505,32.341896227642636,-0.763702936443124,-2.449397202563294
384.30000000000507,32.375658268184395,-0.7464277925776136,-2.4675168738481976
385.4000000000051,32.40938339723488,-0.730729282052808,-2.4836084034148573
386.50000000000506,32.4431785548145,-0.719060902099614,-2.498818170051975
387.6000000000051,32.476751326514744,-0.706049127012833,-2.5129766112756995
388.7000000000051,32.51028136158452,-0.6959014072324177,-2.526348609407168
389.8000000000051,32.54432019189652,-0.6871326238141493,-2.5387707537867708
390.90000000000515,32.57832995663945,-0.6806585396676799,-2.5509337465241524
392.0000000000052,32.6121545933236,-0.675938786897716,-2.5627708434984875
393.1000000000052,32.64604173365923,-0.6714549686654226,-2.5737115691849723
394.20000000000516,32.679849435255825,-0.6720299215284824,-2.58416138877484
395.3000000000052,32.7140979827761,-0.6745272195773174,-2.5933498543478675
396.4000000000052,32.74801833048405,-0.6775608295619984,-2.601637256367363
397.50000000000523,32.781681516008106,-0.6822580573929604,-2.6098530236868736
398.60000000000525,32.8156106999812,-0.690028604589994,-2.61773328628635
399.7000000000053,32.84926049777503,-0.6940993106114555,-2.6250507728225245
400.8000000000053,32.88289747161523,-0.6970778410665223,-2.6316618171771147
401.9000000000053,32.91748000069051,-0.7009626464022451,-2.6378258993478227
403.00000000000534,32.95144211917536,-0.7050518380721063,-2.6447847259547954
404.1000000000053,32.985545839343224,-0.7047315217535276,-2.6510401618471375
405.20000000000533,33.019663621561286,-0.7009838161973401,-2.6543972572899914
406.30000000000535,33.053480231606265,-0.6972171965263555,-2.659647656542157
407.4000000000054,33.0876838775792,-0.69384113296685,-2.66492921385454
408.5000000000054,33.12170143602337,-0.6852780920473972,-2.6701859561378067
409.6000000000054,33.155819034712906,-0.6794988902318718,-2.674094217792782
410.70000000000545,33.19003175067293,-0.671202323389568,-2.678098327953043
411.8000000000054,33.223832028117364,-0.662641228885579,-2.6839313152166575
412.90000000000543,33.25788308541398,-0.6511290106281991,-2.68737683487224
414.00000000000546,33.29224757411002,-0.642497957232625,-2.691650739061303
415.1000000000055,33.32576604069399,-0.6334751220381775,-2.694793498467617
416.2000000000055,33.360722849034175,-0.6233476413126965,-2.6990566903904676
417.3000000000055,33.3947599075139,-0.6136941244211147,-2.7048014061848473
418.40000000000555,33.429123854416886,-0.6053377998573518,-2.7093831008000526
419.50000000000557,33.46324694665353,-0.5956783270505737,-2.7141234989876946
420.6000000000056,33.49745067131125,-0.587375364789848,-2.717900798955766
421.70000000000556,33.53196957488713,-0.5783211586451117,-2.7218883336964437
422.8000000000056,33.56621435116935,-0.571195390699505,-2.725817127359443
423.9000000000056,33.6007675973791,-0.5633031190704916,-2.7291750936682035
425.0000000000056,33.63473550147098,-0.557493546889241,-2.73368763295049
426.10000000000565,33.66879000392582,-0.5527630520960123,-2.736611164963638
427.2000000000057,33.70410441174839,-0.5468288058618117,-2.7397581720553843
428.3000000000057,33.73824024294187,-0.5435707233964098,-2.7445554259527585
429.40000000000566,33.772837082383525,-0.5401645706960595,-2.749120649188174
430.5000000000057,33.80720977540263,-0.5419178077776644,-2.7522296530443997
431.6000000000057,33.84159943298981,-0.5483569880784348,-2.755549163820868
432.70000000000573,33.87603929916228,-0.5545921680863781,-2.7599019682697112
433.80000000000575,33.91072088892014,-0.573689067485501,-2.7639396608949376
434.9000000000058,33.945384372191704,-0.5930058430038087,-2.7676636891527853
436.0000000000058,33.979727599137526,-0.614200951831858,-2.7714405765852748
437.1000000000058,34.014293753458745,-0.6368674124187763,-2.775049217922584
438.20000000000584,34.048873700251384,-0.655090819527745,-2.779107524766413
439.3000000000058,34.082788153125065,-0.6715334058405993,-2.7837323016445836
440.40000000000583,34.11831881234308,-0.6876409557716392,-2.7887661875709266
441.50000000000585,34.15307002616022,-0.7015491106646632,-2.792683638311531
442.6000000000059,34.18737605033533,-0.7129698915287785,-2.796551139509789
443.7000000000059,34.22219481942797,-0.7310268999060946,-2.8003483833633926
444.8000000000059,34.25709499712655,-0.7498015146371573,-2.8030177562767453
445.90000000000595,34.29166637900702,-0.7691650254335848,-2.806734978869514
447.0000000000059,34.32640385987846,-0.7917922429962931,-2.8087287976075723
448.10000000000593,34.360922334326645,-0.8119858661267128,-2.8114696412213833
449.20000000000596,34.39491391351507,-0.8296668180979213,-2.814516928525373
450.300000000006,34.43033817185778,-0.8483392489538397,-2.8183946996054514
451.400000000006,34.46518550564555,-0.8640441724584096,-2.8209951927096286
452.500000000006,34.499900400373825,-0.8788537716193084,-2.823988511205804
453.60000000000605,34.53487018933888,-0.8876927372498228,-2.827587093357551
454.70000000000607,34.569028018142866,-0.8995142875596608,-2.830017020192928
455.8000000000061,34.604756905653346,-0.9118852407515962,-2.833011930145923
456.90000000000606,34.63945972032557,-0.9206324681552476,-2.836737378471982
458.0000000000061,34.67433313731047,-0.9302054052009846,-2.839895143452136
459.1000000000061,34.70876243526227,-0.9323154953917772,-2.8430515339486613
460.2000000000061,34.74400560598407,-0.9359977628458309,-2.846396273805489
461.30000000000615,34.778708006745354,-0.9426282184172036,-2.8483958067410224
462.4000000000062,34.81306825857193,-0.9456773699995513,-2.8514306272384005
463.5000000000062,34.848482234784015,-0.9501678033627224,-2.8533708640646154
464.60000000000616,34.883660117831276,-0.9518656080501144,-2.857000319073965
465.7000000000062,34.918608161781954,-0.9579668127060318,-2.860214905243704
466.8000000000062,34.95355207042031,-0.9640671230224198,-2.862570567551902
467.90000000000623,34.9885105023223,-0.9676325192528588,-2.8647669093001724
469.00000000000625,35.023556368352324,-0.9783917251227551,-2.8677081485688563
470.1000000000063,35.05831434434664,-0.9858197291416008,-2.8700413346196436
471.2000000000063,35.09331475961294,-0.9933661892466292,-2.872853503388142
472.3000000000063,35.12772153104468,-1.0001395162644917,-2.874150372487332
473.40000000000634,35.16325381029924,-1.00800958578667,-2.8756238248898196
474.5000000000063,35.19838673084284,-1.0150746832734991,-2.8765198829394842
475.60000000000633,35.23316284176217,-1.017280890592543,-2.8792152979257857
476.70000000000636,35.26820741305807,-1.023862057294855,-2.882676581466589
477.8000000000064,35.30312442167819,-1.0267692768298708,-2.8857818634480807
478.9000000000064,35.33833498546583,-1.0298157260528562,-2.8873999355688884
480.0000000000064,35.37346291872171,-1.0278247014663386,-2.889107862278514
481.10000000000645,35.40829666197108,-1.0284011994458389,-2.891221107568417
482.2000000000064,35.44295475464362,-1.0276409880962565,-2.8940701003476343
483.30000000000643,35.47852471131484,-1.0224076293336906,-2.896516361845402
484.40000000000646,35.5135907284578,-1.0176200100869868,-2.8997289788486618
485.5000000000065,35.548132738441915,-1.0106495079242281,-2.9013403614255786
486.6000000000065,35.58353905165269,-1.0046126066124037,-2.9028609002032892
487.7000000000065,35.6190385508407,-0.9918689208405449,-2.9042098443577187
488.80000000000655,35.65394557232349,-0.9740025380351858,-2.905766242441875
489.90000000000657,35.688750022596885,-0.9417361301030841,-2.9075952295825034
491.0000000000066,35.7237556788121,-0.908033107152804,-2.9120331190921958
492.10000000000656,35.75872868441869,-0.8877578017868922,-2.9142510884563575
493.2000000000066,35.79381857927038,-0.87443679285611,-2.915651431940825
494.3000000000066,35.82891657391505,-0.8590650627870492,-2.916638402739765
495.4000000000066,35.86388119011362,-0.8481276661421098,-2.918770195234247
496.50000000000665,35.89923532642368,-0.8372061340087683,-2.9204642088857815
497.6000000000067,35.934422521767125,-0.8281322621911834,-2.92221399035434
498.7000000000067,35.96963735249804,-0.8169810767605001,-2.924054328735849
499.80000000000666,36.00477066616703,-0.8097689339476617,-2.9254297532106914
500.9000000000067,36.04020367981142,-0.8026127597088638,-2.9288364848446466
502.0000000000067,36.075479638453295,-0.7955145047186732,-2.9315528460566664
503.10000000000673,36.11091038082392,-0.7894189967764714,-2.93295158974309
504.20000000000675,36.14618437721705,-0.7833970416255297,-2.9342883732362814
505.3000000000068,36.18130341664378,-0.7787048548883616,-2.935594984464881
506.4000000000068,36.21679944878395,-0.7745349032984842,-2.9375044969934807
507.5000000000068,36.25166920713437,-0.7651918930591288,-2.9402292356291317
508.60000000000684,36.28703165924897,-0.7624409129801547,-2.942230104682962
509.7000000000068,36.32248695673312,-0.7536725509127021,-2.942685965762187
510.80000000000683,36.357868555441165,-0.7402261889019773,-2.944014591105349
511.90000000000686,36.39330619349064,-0.7277337966192543,-2.946998282380435
513.0000000000068,36.42842907597269,-0.7197459345528523,-2.9492001667805
514.100000000007,36.46384581181524,-0.7110574263359318,-2.9511259145486846
515.2000000000069,36.4994891317563,-0.7053043176652927,-2.95429025424406
516.300000000007,36.53463204316227,-0.7007797571862617,-2.955787000185171
517.4000000000069,36.57020942344381,-0.6960943655236326,-2.9572850224454688
518.5000000000069,36.6052584191717,-0.6927629874485532,-2.95875882569477
519.600000000007,36.640885941853696,-0.6880769547530122,-2.960135601552542
520.700000000007,36.67643386960884,-0.6836157381326551,-2.9601048697730885
521.800000000007,36.71195810694875,-0.6773243932656298,-2.961410367251875
522.900000000007,36.74761765579626,-0.6750547937580029,-2.962716711275279
524.000000000007,36.7829162512703,-0.6713663890486959,-2.9644247419163854
525.1000000000071,36.8184796464763,-0.6661226911762148,-2.966020815908718
526.2000000000071,36.853981477696934,-0.662638888200957,-2.966019245319841
527.300000000007,36.889635190568384,-0.659184268695069,-2.967250478165555
528.4000000000071,36.92495059482338,-0.6548287052011451,-2.9688041460637473
529.500000000007,36.960633929194266,-0.6506385455120045,-2.970327575753036
530.6000000000072,36.99612291702438,-0.6518302774279231,-2.9702636831631404
531.7000000000071,37.03177131931547,-0.6504056680206646,-2.97293970206255
532.8000000000072,37.067424632175126,-0.6465887665126572,-2.972919562802259
533.9000000000071,37.10245334020114,-0.646289608174381,-2.972938883275792
535.0000000000072,37.138525947485135,-0.644728675646124,-2.9735082331821574
536.1000000000072,37.173996136371656,-0.645993791284258,-2.9743375743102938
537.2000000000072,37.209442037812046,-0.6457697485178728,-2.976055789404924
538.3000000000072,37.245127022037735,-0.6463805151130247,-2.97789187975272
539.4000000000073,37.281185583930615,-0.6448544839849484,-2.979815148761589
540.5000000000073,37.31663039327711,-0.6441505833479921,-2.9818307626580953
541.6000000000073,37.35211839089895,-0.6400618408419201,-2.9834814592281953
542.7000000000073,37.38795051885052,-0.6394605415080435,-2.9850744014331885
543.8000000000073,37.42344252532324,-0.637427584886866,-2.9863843995887835
544.9000000000074,37.45936931174567,-0.6377795906595879,-2.9882182654810183
546.0000000000074,37.49499769155852,-0.640026304732737,-2.990396977294539
547.1000000000074,37.53078183432419,-0.6397217026330114,-2.9922076792607486
548.2000000000073,37.566609246179006,-0.643872270820661,-2.9927767734643904
549.3000000000073,37.60231491545029,-0.64866738805746,-2.9949888077605813
550.4000000000074,37.6380365275986,-0.6537031035672525,-2.9962084385795076
551.5000000000074,37.674015269325764,-0.6557249104298022,-2.9972341845095354
552.6000000000074,37.70973139726152,-0.6618601302322947,-2.998072181288733
553.7000000000074,37.74557467318314,-0.6660081756907725,-2.9977116582916565
554.8000000000075,37.78175461685811,-0.671754471908699,-2.999183039591089
555.9000000000075,37.81682761397359,-0.6755122459871206,-2.999773473755387
557.0000000000075,37.85253473261397,-0.6827878342034819,-3.0008938493303674
558.1000000000075,37.889332179026525,-0.6869713088013704,-3.003577664272377
559.2000000000075,37.92500535440196,-0.6928692624979274,-3.005098224613858
560.3000000000076,37.96095998108762,-0.6983448978526262,-3.006414070005613
561.4000000000076,37.99697938962177,-0.7071162392277803,-3.0077633809896933
562.5000000000076,38.03279258227879,-0.7117664947994676,-3.0085747365952242
563.6000000000076,38.068809093277764,-0.7161276339312572,-3.007847567870601
564.7000000000077,38.10515589017308,-0.7218458383086017,-3.0092695182427165
565.8000000000077,38.14050809679794,-0.7327135078071453,-3.01069996454164
566.9000000000076,38.176552768354064,-0.7384157178296886,-3.0120092406539385
568.0000000000076,38.21263001472463,-0.7456167461007471,-3.0133321345952204
569.1000000000076,38.248813615380506,-0.7534489376241484,-3.0133307690472337
570.2000000000077,38.28476874441092,-0.7609493353730825,-3.014585197118387
571.3000000000077,38.32094012767299,-0.7703005982331913,-3.0146501210411016
572.4000000000077,38.35652101951148,-0.7768232728386056,-3.015373910623865
573.5000000000077,38.392870817172714,-0.7829589470848611,-3.0167901147993694
574.6000000000078,38.42886953607245,-0.7927628454100514,-3.018116791570291
575.7000000000078,38.46512285364672,-0.8009907907374905,-3.0189202680158402
576.8000000000078,38.50045391920719,-0.8084131595986315,-3.0202496126770675
577.9000000000078,38.537458625295905,-0.8162769668674151,-3.0217145176136144
579.0000000000078,38.5733466899414,-0.8234173384202015,-3.023227943750618
580.1000000000079,38.609445069848,-0.8324097466523598,-3.0246694501473868
581.2000000000079,38.64563201863677,-0.8383190556722077,-3.025960725260015
582.3000000000079,38.68178681159927,-0.847263394362433,-3.0258763982636157
583.4000000000078,38.71845995036933,-0.8553580313814577,-3.0259649204989234
584.5000000000078,38.75431873759546,-0.8621111516500624,-3.0260718172612364
585.6000000000079,38.790642722809224,-0.8689023039268163,-3.027790718438422
586.7000000000079,38.82693235849242,-0.8766747231046923,-3.0289440417387814
587.8000000000079,38.862856730216734,-0.8845258741873404,-3.030197719971706
588.9000000000079,38.898947340176626,-0.8898935078031323,-3.0317606620791095
590.000000000008,38.93496993814745,-0.8972092498898016,-3.0330898209881862
591.100000000008,38.97120508316639,-0.9005230671521509,-3.0343357471241212
592.200000000008,39.007249991901055,-0.9084599472654464,-3.034410139695234
593.300000000008,39.04373875591766,-0.9139127073742399,-3.0344101923887736
594.400000000008,39.07982212843258,-0.9249818659732338,-3.034410358108352
595.5000000000081,39.11611535250597,-0.9299179989452175,-3.0354937911734603
596.6000000000081,39.15231261213197,-0.9363189668166368,-3.0357299010999075
597.7000000000081,39.18879190412551,-0.9442563391856835,-3.0358162546198866
598.8000000000081,39.2251428338653,-0.946854769151536,-3.0370382478367497
599.9000000000082,39.26098020578059,-0.9545365807452383,-3.038347008034963
601.0000000000082,39.297447646897425,-0.9623322005203006,-3.037720410711601
602.1000000000081,39.33359597653652,-0.9697431665275172,-3.039020669264456
603.2000000000081,39.369749427902775,-0.9752308475630516,-3.040148972863053
604.3000000000081,39.40605492819523,-0.9808677737172101,-3.0403467834692344
605.4000000000082,39.442589305056465,-0.9899749708116505,-3.041663222047626
606.5000000000082,39.47870816469527,-0.9965764249249969,-3.0416648271641584
607.6000000000082,39.515284166130854,-1.006596707553108,-3.0429804737625976
608.7000000000082,39.551311279906265,-1.010566835654467,-3.044426016280688
609.8000000000083,39.58751793986142,-1.0174191145154254,-3.045905964925346
610.9000000000083,39.624347417886355,-1.0238592594118834,-3.047467728537479
612.0000000000083,39.66018096941109,-1.0316999829067082,-3.0488009982104103
613.1000000000083,39.69667028769197,-1.0381042529084927,-3.0487998153551015
614.2000000000083,39.733044251364824,-1.0472912030658053,-3.049527523418272
615.3000000000084,39.76957365990989,-1.0507012105724949,-3.050119030589107
616.4000000000084,39.80547771392497,-1.057902357309892,-3.0514237448632513
617.5000000000084,39.84192718427245,-1.0669431026753855,-3.05277333424194
618.6000000000083,39.87844734557456,-1.072742360232961,-3.0540266879274522
619.7000000000083,39.91420733517883,-1.0783278153111524,-3.0545801978277587
620.8000000000084,39.95065032107281,-1.0845818369499352,-3.0564147616759367
621.9000000000084,39.98747533079372,-1.0917330679026893,-3.057086938202681
623.0000000000084,40.02408796404413,-1.0965333854496842,-3.0579109777864466
624.1000000000084,40.060475719011976,-1.104001903077672,-3.0589144281396248
625.2000000000085,40.09655872453713,-1.110542550994589,-3.058900106679546
626.3000000000085,40.13327255043142,-1.1144298537169908,-3.058801071157605
627.4000000000085,40.169668978666486,-1.1218108778368434,-3.0585994927126503
628.5000000000085,40.20592517542688,-1.1275465819898982,-3.058569677239883
629.6000000000085,40.241915260043726,-1.1351934299119326,-3.0598763679983634
630.7000000000086,40.278900961146164,-1.1400518572384457,-3.0598790397579587
631.8000000000086,40.31510733413365,-1.147857258279825,-3.0611858390805273
632.9000000000086,40.35167898456862,-1.1552314109056407,-3.0611993432734232
634.0000000000086,40.38731142444229,-1.1606293202527749,-3.061620682121372
635.1000000000087,40.42440526112758,-1.165448273184692,-3.06282816857432
636.2000000000087,40.46044827280127,-1.1705907123278956,-3.063290424301816
637.3000000000086,40.497522496369875,-1.179906734371206,-3.064496788329565
638.4000000000086,40.53383699451365,-1.183258899791331,-3.064600321517232
639.5000000000086,40.57017045549111,-1.1901424193829626,-3.065753289051391
640.6000000000087,40.60655501402992,-1.1985022406911991,-3.065921126154432
641.7000000000087,40.6430166898912,-1.2046996549169022,-3.0672590008505423
642.8000000000087,40.679705073029574,-1.2091337077724418,-3.066259407183478
643.9000000000087,40.715983916393164,-1.2146130401867024,-3.067570851904305
645.0000000000088,40.752602005814886,-1.2215214221353967,-3.068242494372684
646.1000000000088,40.78871236849404,-1.2293443451862587,-3.06888033914933
647.2000000000088,40.82509915156804,-1.231878991900148,-3.0688569891202895
648.3000000000088,40.861924003033266,-1.237007558141651,-3.0701989590888874
649.4000000000088,40.89816987882837,-1.2413255291097824,-3.0704484057353265
650.5000000000089,40.93490872909812,-1.2486220496872458,-3.0715198640843795
651.6000000000089,40.97092019224659,-1.251727688399498,-3.0715201567779484
652.7000000000089,41.00765035603279,-1.2610203116847376,-3.071510805882638
653.8000000000088,41.04423685921065,-1.2682800557408325,-3.0724733348801028
654.9000000000088,41.08049147300119,-1.2718682791275133,-3.0725086905355923
656.0000000000089,41.11730956247413,-1.2735182512018322,-3.073857014906324
657.1000000000089,41.15370214495518,-1.2825817392089187,-3.073819948169475
658.2000000000089,41.19002025496756,-1.285458524612687,-3.07379854725733
659.3000000000089,41.22649841435431,-1.2914268436480574,-3.0751406923967695
660.400000000009,41.26295734261014,-1.2979539812848098,-3.0752737990832446
661.500000000009,41.29936126219938,-1.2987204479341907,-3.0764636395738223
662.600000000009,41.33575529817599,-1.306899846720873,-3.0751493024571097
663.700000000009,41.37205689207681,-1.3105250061970217,-3.0764621793469074
664.800000000009,41.40877305776602,-1.3134928062826692,-3.0770720451982108
665.9000000000091,41.44486026416179,-1.3197562750288534,-3.0777795171288274
667.0000000000091,41.48149820088237,-1.3232614084160796,-3.079080779880921
668.1000000000091,41.517828266951625,-1.3274877923527126,-3.080625044282706
669.2000000000091,41.554116063907564,-1.3295526945842369,-3.082032091542957
670.3000000000092,41.590849004138306,-1.3349425543172755,-3.083395541261469
671.4000000000092,41.62754892940659,-1.338360209504736,-3.084242504308542
672.5000000000091,41.663410091273484,-1.342300401773952,-3.083329670043354
673.6000000000091,41.700137722781996,-1.3445812279431302,-3.0833799367505303
674.7000000000091,41.7365628825893,-1.3487220709274925,-3.0833799204180132
675.8000000000092,41.77294083489245,-1.353792485022836,-3.083380034213478
676.9000000000092,41.80933165088944,-1.3559499325348712,-3.0844585516969825
678.0000000000092,41.845628505933846,-1.360362748194257,-3.084700025215498
679.1000000000092,41.882474309460214,-1.3661343002508122,-3.084713012299841
680.2000000000093,41.918845122675634,-1.3676167014972846,-3.0860085875764343
681.3000000000093,41.954635399889135,-1.3721555060161137,-3.0874610720559867
682.4000000000093,41.99160104519312,-1.3736987029588024,-3.088887267794555
683.5000000000093,42.02823178286452,-1.3786210732260566,-3.090192379275007
684.6000000000093,42.06504636322266,-1.383475627218963,-3.090218829409915
685.7000000000094,42.10111011589579,-1.3879680943999912,-3.0906201292377653
686.8000000000094,42.13768677072762,-1.3930485970208457,-3.0906200439466374
687.9000000000094,42.17426758939859,-1.3964205405982657,-3.090620043999958
689.0000000000093,42.210773431627665,-1.3967165490895488,-3.090620044000335
690.1000000000093,42.247146863441095,-1.3986055279176968,-3.090620044014667
691.2000000000094,42.284042947499486,-1.4035564818062916,-3.090619394391423
692.3000000000094,42.320111879854615,-1.409305776737325,-3.090290567337961
693.4000000000094,42.35672711241385,-1.4126968805749343,-3.0902851889561447
694.0000000000094,42.376769721777485,-1.414244025941728,-3.089633020280696