File: 01_Data/Smoke_Explosion_Plywood/STA/N2/30K_min/Smoke_Explosion_Plywood_STA_N2_30KData_230729_R1.csv
##Temp./Â°C,Time/min,DSC/(mW/mg),Mass loss/mg
29.0,20.55578895739557,-2.3484275991151837,-0.2619321516977209
30.100000000000016,20.766644344814928,-2.3058625456564723,-0.24563534950161703
31.20000000000003,20.894616994985363,-2.2823669830909314,-0.23947824545834617
32.30000000000005,20.997580590321004,-2.2642020413626516,-0.23519679569538088
33.40000000000006,21.08329961254145,-2.2500360332848204,-0.2328923035966115
34.50000000000008,21.161194639128876,-2.2394702569147737,-0.23145560599010873
35.600000000000094,21.230643020163615,-2.226653688858093,-0.22764829871123382
36.70000000000011,21.298243914793648,-2.2173048406187084,-0.22573661732151296
37.800000000000125,21.358705236678254,-2.2112222972305875,-0.22502720922691344
38.90000000000014,21.417637816058743,-2.202313937258075,-0.2235472041940918
40.000000000000156,21.47468151394865,-2.198256956611248,-0.22199819500944828
41.10000000000017,21.528350138785438,-2.1937789304078423,-0.22015854193834183
42.20000000000019,21.580791656040113,-2.1903816083628107,-0.22209424996921534
43.3000000000002,21.631651869497784,-2.189494053601457,-0.22156410769155377
44.40000000000022,21.681524177959794,-2.1909482886186544,-0.2217045209087738
45.500000000000234,21.730541151645863,-2.1883130739978083,-0.22304813372823418
46.60000000000025,21.778491564365204,-2.191222630484299,-0.22298359520671251
47.700000000000266,21.824491821270087,-2.1938329240900005,-0.22349316118945017
48.80000000000028,21.871653603542423,-2.197221019897817,-0.22513146685993668
49.9000000000003,21.91679613627205,-2.2017322475976644,-0.2263805989685599
51.00000000000031,21.961182822251295,-2.2081896069786757,-0.22568126727645987
52.10000000000033,22.006272256273995,-2.2141247242178603,-0.22649985945931572
53.200000000000344,22.050104296704376,-2.2234533314483076,-0.2272719714254574
54.30000000000036,22.09420593697372,-2.2337286232897324,-0.22963922531081948
55.400000000000375,22.136604070965728,-2.2447362936597326,-0.22955629714146442
56.50000000000039,22.178853017286556,-2.255713988083398,-0.22988755558362906
57.600000000000406,22.221782533945664,-2.268606715172238,-0.23164023989362148
58.70000000000042,22.2634274500343,-2.281204065242153,-0.2331674491256872
59.80000000000044,22.30523888720809,-2.296348972660348,-0.2331746375770707
60.90000000000045,22.34641798077979,-2.311519809127116,-0.23488075398622632
62.00000000000047,22.387991607996007,-2.323697047098843,-0.23693845083639475
63.100000000000485,22.428639940120227,-2.3406956532283645,-0.23897450584465973
64.2000000000005,22.469699344588854,-2.355672325246188,-0.24105673741174583
65.30000000000052,22.5099313143656,-2.372652612695785,-0.2404705938553824
66.40000000000053,22.550422079715347,-2.386865640021009,-0.2418401322041377
67.50000000000054,22.59022085078077,-2.4023572699840203,-0.24448260198415728
68.60000000000056,22.630221305427305,-2.417053958026996,-0.24576966046614146
69.70000000000059,22.670800652283813,-2.431980728007777,-0.248619773177857
70.8000000000006,22.71079312140892,-2.446479390852011,-0.25135275953763436
71.9000000000006,22.74997438283598,-2.4585062217944476,-0.2533066638230954
73.00000000000063,22.789470496755108,-2.471231347614958,-0.2538689499202724
74.10000000000065,22.829059570928067,-2.4827608797526026,-0.25589305525004935
75.20000000000066,22.868294486973955,-2.490792325964974,-0.2578581490358731
76.30000000000067,22.907412959354318,-2.500596837531398,-0.26004907584248294
77.40000000000069,22.94583000000003,-2.5070300000000065,-0.26238967602521335
78.50000000000071,22.985588937325886,-2.513807164288541,-0.26491809650587284
79.60000000000072,23.02410356433258,-2.516498515195709,-0.2675521880409484
80.70000000000073,23.062683031893066,-2.5199586167825654,-0.26939347639897804
81.80000000000075,23.101282798958497,-2.519071853868064,-0.2734931699425287
82.90000000000077,23.139522435974907,-2.518242066031544,-0.27566281815790106
84.00000000000078,23.178070994913643,-2.5138383607692085,-0.27787711891293077
85.10000000000079,23.215857137498755,-2.507840686717419,-0.2790000929968568
86.20000000000081,23.253222766686932,-2.5010854349844593,-0.28167821776088786
87.30000000000084,23.291372799759696,-2.491744166895696,-0.2836855085824488
88.40000000000084,23.32848869530408,-2.481456102947751,-0.2864098039197498
89.50000000000085,23.36620087713789,-2.4683728478661533,-0.2898497874854842
90.60000000000088,23.40375072442898,-2.452163435637472,-0.2928229676615013
91.7000000000009,23.440433762471045,-2.4375540027468294,-0.29441918696028235
92.8000000000009,23.477279519813,-2.4213714346676194,-0.29585120490989825
93.90000000000092,23.51412152446248,-2.3997635124201593,-0.29859704750945903
95.00000000000094,23.551032952292502,-2.379277794758325,-0.30031901937262173
96.10000000000096,23.587708661025303,-2.3571258198030827,-0.30352214260811694
97.20000000000097,23.6241564157558,-2.332017414709191,-0.3059296367678135
98.30000000000098,23.66048160372459,-2.3075882103280954,-0.30755846268929243
99.400000000001,23.69638611615951,-2.2817360192780454,-0.30885931339577954
100.50000000000102,23.733212005729488,-2.252736597678895,-0.3101220050018889
101.60000000000103,23.769126153290212,-2.2260050398462763,-0.3116312874887277
102.70000000000104,23.805187858676653,-2.1982244530045154,-0.31321404876040493
103.80000000000106,23.841502709231193,-2.167417596370687,-0.31586396763816627
104.90000000000109,23.87714705428426,-2.1393934907010315,-0.3158498838376249
106.0000000000011,23.913206085509934,-2.1083090878845,-0.3165871068091919
107.1000000000011,23.949164632439942,-2.076712836040551,-0.31715755354968955
108.20000000000113,23.98533545191666,-2.0470801114314345,-0.3190778990313117
109.30000000000115,24.021182641183163,-2.0151441649070674,-0.3198086570938301
110.40000000000116,24.056708401797582,-1.9839158576786013,-0.3223752170284504
111.50000000000117,24.092263058844072,-1.953463199517346,-0.3224410227492176
112.60000000000119,24.128310748356608,-1.9244155721275336,-0.32374378768161316
113.70000000000121,24.164084619939555,-1.8929686237655445,-0.3250305464764298
114.80000000000122,24.199815903226092,-1.8638424701820524,-0.3250597628447083
115.90000000000123,24.235029602441,-1.8354329100381723,-0.32695677909260557
117.00000000000125,24.27086089678943,-1.806449340114919,-0.32769977497530167
118.10000000000127,24.30661813328124,-1.7798555677376202,-0.3277001726751916
119.20000000000128,24.342010859907564,-1.7515618588992639,-0.328568132759957
120.30000000000129,24.377605031243355,-1.7272115423690733,-0.3293254261528187
121.40000000000131,24.412323646427005,-1.7026829698039456,-0.3300101913632507
122.50000000000134,24.44859426166171,-1.679099810666431,-0.33000993578444326
123.60000000000134,24.48354479226525,-1.6565749665012621,-0.33000993599995665
124.70000000000135,24.519324886078984,-1.6343320987239067,-0.33000993600000017
125.80000000000138,24.55460600786599,-1.610476304453345,-0.3300099359999993
126.9000000000014,24.589784874830116,-1.590206952472438,-0.3300099360000015
128.00000000000142,24.62526069867425,-1.5746046610794857,-0.3300099359949793
129.10000000000142,24.660300528131156,-1.5564772989051943,-0.3300099414404869
130.20000000000144,24.695683836187346,-1.540715203792619,-0.3300096593420445
131.30000000000146,24.72962032180398,-1.5225977594776186,-0.3315120435047598
132.40000000000146,24.76487851373581,-1.5071112316250634,-0.33291710443453404
133.50000000000148,24.79994414407856,-1.4942788449096978,-0.3329701434960759
134.6000000000015,24.83550332145186,-1.4803246833413148,-0.332970181093005
135.70000000000152,24.870733915841267,-1.4684497091915596,-0.3329701809999319
136.80000000000155,24.905636459303622,-1.4577725946604492,-0.3329701810000003
137.90000000000154,24.939995891315363,-1.4466341785577277,-0.3329701810000003
139.00000000000156,24.97469454913258,-1.4380115280112296,-0.3329701810000012
140.1000000000016,25.009831933429464,-1.4273461766157445,-0.3329701810000003
141.20000000000158,25.044553394494066,-1.4178311741822431,-0.3329701810000576
142.3000000000016,25.078968529554,-1.412378779163861,-0.332970180969701
143.40000000000163,25.11406195048413,-1.404105108133145,-0.33297016317172057
144.50000000000165,25.148334907965644,-1.3965540977622086,-0.33302218735982425
145.60000000000167,25.183153980559748,-1.3913686102438263,-0.3339624896742892
146.70000000000167,25.217730681989917,-1.383626266310822,-0.33262920655398664
147.8000000000017,25.2525631963202,-1.3797418849477943,-0.33264993901122963
148.9000000000017,25.286673817529348,-1.373109936558033,-0.3326490519264742
150.0000000000017,25.32115591355596,-1.3685044185953508,-0.33400609832512984
151.10000000000173,25.35532183590135,-1.3632770076426854,-0.33432744156281435
152.20000000000175,25.390206719617908,-1.3592593004500728,-0.3342950921913852
153.30000000000177,25.423502300019244,-1.3540333563314741,-0.33560961416287993
154.4000000000018,25.458850173711284,-1.35104493159243,-0.33560017014970667
155.5000000000018,25.493194780888082,-1.3458901992437597,-0.33560018100271094
156.6000000000018,25.526693831783547,-1.3429459789141742,-0.3356001810000131
157.70000000000184,25.561820768332474,-1.338633184236634,-0.33560018099935407
158.80000000000183,25.59642427447317,-1.3354345284397726,-0.33560018155871907
159.90000000000185,25.63078418341171,-1.332366405677932,-0.3355998060089038
161.00000000000188,25.66460717825955,-1.3294011826443228,-0.3347325182723666
162.1000000000019,25.699072647027393,-1.3260276403542206,-0.33428994929814504
163.20000000000192,25.733454643470235,-1.3218710839474757,-0.33429007917024345
164.30000000000192,25.767483030448957,-1.319850533036049,-0.3347229862581047
165.40000000000194,25.80136091262184,-1.316262691670579,-0.3349500749771761
166.50000000000196,25.83566503906325,-1.3134871573697466,-0.33494995442190145
167.60000000000196,25.869674987658147,-1.3103156539552063,-0.33494446490527974
168.70000000000198,25.904091628672,-1.3070911502269271,-0.33560947031755006
169.800000000002,25.938136058236775,-1.3059588907195452,-0.33650629233635154
170.90000000000202,25.972006110327175,-1.304064906572552,-0.33692012440800756
172.00000000000205,26.00624741217954,-1.2998135234274686,-0.3369202957614288
173.10000000000204,26.040333989600654,-1.2977925163184412,-0.337730265783156
174.20000000000206,26.074235024427303,-1.2950628729803917,-0.33824510431368093
175.3000000000021,26.108434662924235,-1.2933377642698733,-0.33692337563347685
176.40000000000208,26.14221050080135,-1.2900452497858428,-0.33690346410808303
177.5000000000021,26.17657988103273,-1.2892652060913272,-0.3382345420962021
178.60000000000213,26.210445550851222,-1.287717382851187,-0.33823982205143155
179.70000000000215,26.24436052176277,-1.2841418515524996,-0.3382341087061862
180.80000000000217,26.27801497817847,-1.2825857092937136,-0.33758300389705953
181.90000000000217,26.311853170531002,-1.2824688539670777,-0.33758018733681405
183.0000000000022,26.345799192924193,-1.2805358416812522,-0.3375801822496949
184.1000000000022,26.37901522128421,-1.2774784312670668,-0.33822046697061703
185.2000000000022,26.413036806475937,-1.2751788731507139,-0.3389269382329627
186.30000000000223,26.446511431528172,-1.2739889391848391,-0.34032920341309625
187.40000000000225,26.480185513357128,-1.2713267680495075,-0.34208048903921906
188.50000000000227,26.51344798170802,-1.2709120910107254,-0.34231221121663946
189.6000000000023,26.547424935372444,-1.269856234463617,-0.342964142913615
190.7000000000023,26.580891463101466,-1.2672522678906908,-0.3429701054675518
191.8000000000023,26.614401685960704,-1.2664431489058527,-0.34297761742518595
192.90000000000234,26.648276022885703,-1.2662284084642077,-0.3442638294907452
194.00000000000233,26.681825692935227,-1.2628052524583662,-0.3457713211416795
195.10000000000235,26.715351993097034,-1.2622812745567464,-0.345585017490305
196.20000000000238,26.748461164642144,-1.2615710896549857,-0.3467018974709055
197.3000000000024,26.782137764958495,-1.2595644642909503,-0.3456944061969831
198.40000000000242,26.815667406564664,-1.2585902572509642,-0.34570988282478066
199.50000000000242,26.848939419117112,-1.2598702121590444,-0.34570884186068795
200.60000000000244,26.882525310216085,-1.2592592172019148,-0.34692340551956624
201.70000000000246,26.915753917580176,-1.25981682962235,-0.34700550676412645
202.80000000000246,26.949300482115152,-1.2595986300226452,-0.3479766115349556
203.90000000000248,26.982519281452426,-1.258415773207232,-0.34970673007047814
205.0000000000025,27.015945768588196,-1.259296304677074,-0.34965981566189175
206.10000000000252,27.04901063870803,-1.2591902853329255,-0.34990743825734416
207.20000000000255,27.08262506313971,-1.2601117623157132,-0.3509758716436755
208.30000000000254,27.115570747923538,-1.2598283186047163,-0.35234994294744526
209.40000000000256,27.148908494485333,-1.2608349739168236,-0.35239821347497857
210.5000000000026,27.1826527043158,-1.2614658962212193,-0.3535966431282702
211.60000000000258,27.215859881420418,-1.2617456736302268,-0.3551548235457598
212.7000000000026,27.249173972451825,-1.2617431888162376,-0.3565637763453253
213.80000000000263,27.282592606284517,-1.26113287000512,-0.3566890977904298
214.90000000000265,27.315711360539495,-1.261767487094644,-0.35790204102447687
216.00000000000267,27.34876229618365,-1.2636990509778618,-0.3588967318735685
217.10000000000267,27.382110021200784,-1.2646552613208895,-0.3593044117597639
218.2000000000027,27.415485326482532,-1.2662303673055026,-0.36062437175309636
219.3000000000027,27.449225303082727,-1.268041588894621,-0.3620257376964724
220.4000000000027,27.482355770107564,-1.2694827581709245,-0.36370317530622387
221.50000000000273,27.51550958043115,-1.2733658655951123,-0.36524392072580936
222.60000000000275,27.54871442063955,-1.2743063622730169,-0.3665323084254357
223.70000000000277,27.581926705593464,-1.276889319861497,-0.3681252966815327
224.8000000000028,27.615186384650606,-1.2793435489240754,-0.368689330649024
225.9000000000028,27.648520713646178,-1.2841257087352476,-0.36960540425710686
227.0000000000028,27.6808090212699,-1.286971539893041,-0.3698017308789834
228.10000000000284,27.714812435743585,-1.2894536337747808,-0.37123462127217755
229.20000000000283,27.747693579239716,-1.2922156521838435,-0.3732393035229835
230.30000000000285,27.780811056611316,-1.29313307294487,-0.37632714144565416
231.40000000000288,27.81419269866417,-1.2965363865733288,-0.3791915346767909
232.5000000000029,27.847617952117798,-1.3011079736324507,-0.3822562220477428
233.60000000000292,27.880608137289357,-1.3035274070431357,-0.3843734655717532
234.70000000000292,27.913529938690278,-1.3035645612052107,-0.385947743380628
235.80000000000294,27.94711696720859,-1.3072648395937758,-0.3891263554297173
236.90000000000296,27.980309600456128,-1.3063755461453532,-0.39132219322344497
238.00000000000296,28.013477960389814,-1.3091649009358717,-0.39402170181494656
239.10000000000298,28.046217574230713,-1.3116491803656494,-0.39631741238927765
240.200000000003,28.079080252750824,-1.3119384616832568,-0.3988715627952977
241.30000000000302,28.112472516120363,-1.3130183591237257,-0.3999375730911021
242.40000000000305,28.145710445865962,-1.3133168435842104,-0.4022406247386314
243.50000000000304,28.178783762898817,-1.3124359818123574,-0.40501313783314874
244.60000000000306,28.211782770629874,-1.30989920093878,-0.40921292575191437
245.7000000000031,28.24473826870348,-1.3077164473728138,-0.413324647912483
246.80000000000308,28.2780364002533,-1.3063182532895996,-0.41705502883108014
247.9000000000031,28.31096671769005,-1.3044471397812143,-0.41946878347267713
249.00000000000313,28.343903844612488,-1.3006733311467347,-0.42306653858096777
250.10000000000315,28.377318103856847,-1.2982722256822643,-0.4259582416020198
251.20000000000317,28.410206974418593,-1.2944051194875053,-0.4294901068740167
252.30000000000317,28.44323585568559,-1.291361343221296,-0.4332837598110797
253.4000000000032,28.476364297631413,-1.2870770873581818,-0.43634355815654846
254.5000000000032,28.509385245079585,-1.2805604136544573,-0.4399499130185567
255.6000000000032,28.542224286035935,-1.274994739804872,-0.4437290258829667
256.70000000000323,28.57540296788979,-1.2668732404929726,-0.4482691597210091
257.80000000000325,28.60856917821266,-1.2594565644001647,-0.45272130719818593
258.9000000000033,28.641567101917428,-1.2510409144043946,-0.45690121096481295
260.0000000000033,28.67488089973862,-1.2440622845612925,-0.46019733059550694
261.1000000000033,28.707647119164008,-1.2372596922396197,-0.46439568379246365
262.20000000000334,28.740763445470435,-1.229613892217109,-0.46881532556530603
263.30000000000337,28.7740832205425,-1.2231619303411627,-0.4727601813228359
264.40000000000333,28.806964856955133,-1.2151198016926126,-0.47733757797923415
265.50000000000335,28.839886888887975,-1.2067176287390013,-0.4816916255755128
266.6000000000034,28.87247053635065,-1.1987019525549278,-0.4864455630738598
267.7000000000034,28.906288628211836,-1.1881472565183797,-0.49134211289445906
268.8000000000034,28.938911354407953,-1.177010792169473,-0.4960757966607159
269.9000000000034,28.972144248079047,-1.1660449504017207,-0.5003566083242057
271.0000000000034,29.004787427945452,-1.1561510118071054,-0.5040611394300121
272.10000000000343,29.038224858662996,-1.1486488848608252,-0.5094884573025271
273.20000000000346,29.071253319549847,-1.1402616448004539,-0.51528308762627
274.3000000000035,29.10413579359985,-1.1351082321038966,-0.5209440614500367
275.4000000000035,29.137150909894654,-1.1283752090347094,-0.5267115090644756
276.5000000000035,29.170388858270762,-1.1217041217905095,-0.5338865895414404
277.60000000000355,29.203446658030238,-1.1159313308749443,-0.5404464456356264
278.70000000000357,29.236625429950948,-1.1113108529957139,-0.5469606881549494
279.8000000000036,29.269619081428758,-1.1057403104071153,-0.5527932698766835
280.9000000000036,29.30302216569631,-1.0984947605192106,-0.558966146023745
282.0000000000036,29.336076918181107,-1.0932982631897101,-0.5657929756790567
283.1000000000036,29.369110152938717,-1.0868460069555805,-0.5726902296437095
284.2000000000036,29.401968010887934,-1.0826704657166684,-0.580634171820817
285.30000000000365,29.435521632009348,-1.078023951545983,-0.5888634841582494
286.4000000000037,29.46828605138952,-1.0719159624948325,-0.5965377675395169
287.5000000000037,29.501401354434456,-1.0659046754142292,-0.6051327301992879
288.60000000000366,29.534651843019404,-1.0613321616183855,-0.6138420148217731
289.7000000000037,29.567666627746775,-1.0549890714838095,-0.6222996711868221
290.8000000000037,29.60075200185604,-1.0487383925720368,-0.6308870972580141
291.90000000000373,29.634145931916116,-1.0432232464673938,-0.6397348780162333
293.00000000000375,29.667163994220086,-1.0376071140712655,-0.6489641818263476
294.1000000000038,29.700611618216126,-1.0299207955162735,-0.6582718316314966
295.2000000000038,29.73343899084696,-1.0258216024199593,-0.6684510232003986
296.3000000000038,29.766888312311153,-1.01844712903963,-0.6787923888955252
297.40000000000384,29.799848237748336,-1.0111164796055787,-0.68866406094756
298.5000000000038,29.833011976575587,-1.0039062690541267,-0.6995046378940719
299.60000000000383,29.866361176576667,-0.9974047219718893,-0.7107907802353606
300.70000000000385,29.899706428965295,-0.9893654183813304,-0.7209256234619019
301.8000000000039,29.93285214704776,-0.9837602465009947,-0.7327118229471545
302.9000000000039,29.965830316485803,-0.9781699945509219,-0.7449901643958894
304.0000000000039,29.998983996331237,-0.9695082367079291,-0.7576579146120603
305.10000000000394,30.032381851931195,-0.9638521804594122,-0.7709616171003075
306.2000000000039,30.06567859816387,-0.9547075491721961,-0.7842432157618608
307.30000000000393,30.098588212054256,-0.9480908495391669,-0.7971180082451719
308.40000000000396,30.130969987275357,-0.9410088615343195,-0.8107328227929944
309.500000000004,30.165509493993227,-0.9350623441399193,-0.8254256374079754
310.600000000004,30.19853721616942,-0.928792917572718,-0.8405440568237825
311.700000000004,30.231644231206175,-0.9221385498458898,-0.8556925752549067
312.80000000000405,30.264684430092192,-0.916703305097861,-0.8714179022003252
313.90000000000407,30.298366676631687,-0.9113801311866231,-0.8883006371513522
315.0000000000041,30.33136832474521,-0.9069551481452504,-0.9045940356487785
316.10000000000406,30.36451124516148,-0.9013452099932708,-0.9214165846647568
317.2000000000041,30.398146712967158,-0.8974049863956511,-0.9387782656081525
318.3000000000041,30.43164720885575,-0.8934343630809369,-0.9564353797281968
319.4000000000041,30.464598319578414,-0.8889516933294712,-0.9743167246220215
320.50000000000415,30.497867638507994,-0.8837673101997444,-0.991997936420451
321.6000000000042,30.531201549976455,-0.8806799497201655,-1.0097384695019045
322.7000000000042,30.564744518748487,-0.8780960759030899,-1.0286034818816843
323.80000000000416,30.59834909976012,-0.8754430022149862,-1.048856063159287
324.9000000000042,30.63144736760556,-0.8716115892218222,-1.069310796140798
326.0000000000042,30.66452585167243,-0.8682990598354638,-1.0897595981788166
327.10000000000423,30.698058825003976,-0.8635401367407562,-1.1109463335726781
328.20000000000425,30.731610440277386,-0.8593367198256079,-1.1315259636110389
329.3000000000043,30.76478091425618,-0.8531794607383215,-1.1530503311300908
330.4000000000043,30.797584909697893,-0.8485184520283597,-1.174617975644809
331.5000000000043,30.831653270768015,-0.8446499200847953,-1.197334969619595
332.60000000000434,30.865061072606405,-0.837240945814591,-1.2212157116152103
333.7000000000043,30.89840136089086,-0.8298454918536001,-1.2455851790245043
334.80000000000433,30.932020563329623,-0.8241106584549627,-1.2705089401348673
335.90000000000435,30.96531786595436,-0.8181253098872197,-1.293226362695338
337.0000000000044,30.998644783013525,-0.8112552191337782,-1.3166810278144432
338.1000000000044,31.032194684085304,-0.8027121931076616,-1.3411063571860362
339.2000000000044,31.065798381572755,-0.7931471045478402,-1.3665559313649558
340.30000000000445,31.099231435553044,-0.7851036689147225,-1.390995026848267
341.4000000000044,31.132682453943733,-0.7765856897886945,-1.4163443121752461
342.50000000000443,31.16579631540485,-0.7675382203623546,-1.4429624023317964
343.60000000000446,31.19962058955199,-0.7568990780338405,-1.4709045125939801
344.7000000000045,31.23271837775621,-0.7489706593222692,-1.4970623277760593
345.8000000000045,31.266186112485855,-0.736235771148876,-1.5236340411603648
346.9000000000045,31.299773190953523,-0.7245033714704596,-1.550875915017298
348.00000000000455,31.333451653855537,-0.7127733843207734,-1.5787810586553888
349.10000000000457,31.3669510747636,-0.7024415401300708,-1.6066564746486067
350.2000000000046,31.400578930021155,-0.689968372623773,-1.6350316980436177
351.30000000000456,31.433818890650954,-0.6776858549660535,-1.6618782676581323
352.4000000000046,31.467205506200855,-0.6673997476267552,-1.6900987658899655
353.5000000000046,31.500989851820773,-0.6560327004948038,-1.7175819045595389
354.6000000000046,31.53386417561723,-0.642268630616536,-1.745934527823839
355.70000000000465,31.568136978567193,-0.6304408440956254,-1.7746041873987672
356.8000000000047,31.60102327268623,-0.6175787028477844,-1.8015978081798876
357.9000000000047,31.635147785041617,-0.6061716583915033,-1.828420945091458
359.00000000000466,31.668643746670057,-0.5958572301676411,-1.8566292020538184
360.1000000000047,31.702067271185797,-0.5840985339588942,-1.8847642786264505
361.2000000000047,31.73601712215104,-0.5710850433792222,-1.912020896461398
362.30000000000473,31.76962430897099,-0.5584280329769797,-1.9381634272571355
363.40000000000475,31.802936731221383,-0.5474074991842972,-1.9649919192833682
364.5000000000048,31.836465755812526,-0.5369426354409486,-1.9931212833402865
365.6000000000048,31.870266141674122,-0.5244032045226366,-2.0202911794423697
366.7000000000048,31.90336200559866,-0.5118470092947512,-2.046030729374743
367.80000000000484,31.937674607833394,-0.4972093296986034,-2.072233418517202
368.9000000000048,31.971317672750178,-0.4836433924604992,-2.09835529832539
370.00000000000483,32.004341756304655,-0.4703881462148626,-2.1233266625381875
371.10000000000485,32.03854262651479,-0.45527034817472456,-2.1481103380394533
372.2000000000049,32.07221213943905,-0.44165739366438655,-2.171962501336348
373.3000000000049,32.10573941772454,-0.4249594231799381,-2.1964744915600374
374.4000000000049,32.13944075733897,-0.40689371741983865,-2.220547495403344
375.50000000000495,32.17320777392967,-0.39094301289440914,-2.242993352357578
376.6000000000049,32.20667452155655,-0.3753686100055483,-2.264410011558396
377.70000000000493,32.24024486914868,-0.35733987782775045,-2.2872630440213095
378.80000000000496,32.27377897655621,-0.33938986210478866,-2.308418711841117
379.900000000005,32.30768413039679,-0.3225368655315663,-2.328240747755543
381.000000000005,32.34146254633915,-0.3059434716630921,-2.347675572630594
382.100000000005,32.37500742964343,-0.2852792129882394,-2.366614567416009
383.20000000000505,32.408799645817304,-0.2699164759231824,-2.3838864148097776
384.30000000000507,32.44158717269694,-0.2527298354352902,-2.3997803133517523
385.4000000000051,32.47632326600241,-0.23769578996810595,-2.416394504444809
386.50000000000506,32.50923386995802,-0.22314687194052277,-2.4316801293684325
387.6000000000051,32.543584069051626,-0.21231641221011044,-2.447054852312468
388.7000000000051,32.577309622863226,-0.20260982756595147,-2.460699803076647
389.8000000000051,32.61109841412942,-0.19542520022923,-2.47269810921855
390.90000000000515,32.64482354794088,-0.18917237716797808,-2.484386277464113
392.0000000000052,32.678618793574316,-0.18759762132795932,-2.4954162927911194
393.1000000000052,32.71220876107152,-0.1854575031457012,-2.504875562984093
394.20000000000516,32.746192760743874,-0.18646684503508248,-2.513679652676713
395.3000000000052,32.77982459070783,-0.18981838165389944,-2.5216719588313516
396.4000000000052,32.813587052766664,-0.19386695732182435,-2.528973121440442
397.50000000000523,32.84729547666478,-0.19439764391841224,-2.536750148158547
398.60000000000525,32.88111024889021,-0.19853745320309102,-2.544151721439775
399.7000000000053,32.91482824123729,-0.19730740773943595,-2.5515629093691317
400.8000000000053,32.94854839484833,-0.196404452479628,-2.558246744513542
401.9000000000053,32.98235336421551,-0.1939916930637893,-2.5636007660657087
403.00000000000534,33.01619634440103,-0.19006951926707083,-2.5693571061967413
404.1000000000053,33.05000016137998,-0.18729137485109917,-2.574296692381118
405.20000000000533,33.083548128889284,-0.18577441592769484,-2.5791159923419187
406.30000000000535,33.1179096696205,-0.19263622669057617,-2.5849438244504013
407.4000000000054,33.15182275056167,-0.20554172460298842,-2.5905209634705084
408.5000000000054,33.185950373599624,-0.2191974137899353,-2.594849743521369
409.6000000000054,33.220044753776364,-0.23027629401721603,-2.5995315828027996
410.70000000000545,33.25385926039681,-0.24318409380814185,-2.6041843721910194
411.8000000000054,33.288022342244,-0.25282351384699747,-2.6090857712018556
412.90000000000543,33.32194702503646,-0.25535062546899967,-2.6127285303134626
414.00000000000546,33.35606378742499,-0.2572807764984959,-2.616477469005168
415.1000000000055,33.390310314004495,-0.2569165695494681,-2.6200718322546797
416.2000000000055,33.4246653280666,-0.2516285549555969,-2.6237256715328323
417.3000000000055,33.45846316142053,-0.2484593980274255,-2.6278135531204887
418.40000000000555,33.49292217973377,-0.2443583598303309,-2.632515157387326
419.50000000000557,33.52713470217555,-0.2423808349077396,-2.6362730392399776
420.6000000000056,33.561665163910625,-0.23722203534894087,-2.639803784341693
421.70000000000556,33.59543074614951,-0.2329499128200384,-2.643791322428159
422.8000000000056,33.63004227646964,-0.23013181347031186,-2.647576312405566
423.9000000000056,33.664049825482884,-0.22753338911283402,-2.651000422852805
425.0000000000056,33.69883347632043,-0.22479742508948874,-2.654089243227247
426.10000000000565,33.73286187816331,-0.2254220678752763,-2.6584223693192626
427.2000000000057,33.76728027149756,-0.2262844480679544,-2.662905076938052
428.3000000000057,33.80155689639132,-0.22714146734096738,-2.6668938346056734
429.40000000000566,33.836335762117066,-0.23073284266360988,-2.6715581345059096
430.5000000000057,33.87057017743133,-0.23802978768978533,-2.674832794331712
431.6000000000057,33.90503773297171,-0.24610553894638926,-2.6787823580874863
432.70000000000573,33.9395423053856,-0.25735743675670036,-2.682393906375604
433.80000000000575,33.97388741469682,-0.2675063687023827,-2.68606249287245
434.9000000000058,34.008505148130155,-0.2738092497976636,-2.689788231215986
436.0000000000058,34.043158195318696,-0.2828667691995642,-2.693347937516154
437.1000000000058,34.077824906647685,-0.2914873608192021,-2.696619948410552
438.20000000000584,34.11226921415555,-0.3019978107813345,-2.69954737112948
439.3000000000058,34.146871340264404,-0.31114822967099115,-2.703253289008051
440.40000000000583,34.181567087302795,-0.32063623459036167,-2.7067399586662795
441.50000000000585,34.21555746709119,-0.3283553414780174,-2.7093190441937507
442.6000000000059,34.250970371474764,-0.3338577396747378,-2.713210486617627
443.7000000000059,34.28576723659799,-0.33897736692541025,-2.716580656754741
444.8000000000059,34.320486545532276,-0.3449024212912668,-2.7196919585587893
445.90000000000595,34.355183953282285,-0.3460742462063841,-2.722729164622401
447.0000000000059,34.38989011334227,-0.3502742846269712,-2.726398653048347
448.10000000000593,34.42476623162917,-0.3545494961609502,-2.730029160637425
449.20000000000596,34.45940006520573,-0.35899758334183657,-2.7331943665253506
450.300000000006,34.49460981056539,-0.36212106628575325,-2.7364279425175697
451.400000000006,34.5293244660454,-0.36533105054878195,-2.739794156326971
452.500000000006,34.56390461410338,-0.3700862374311137,-2.742003766475263
453.60000000000605,34.5992026089477,-0.38025437723223826,-2.745242650717845
454.70000000000607,34.633602750831486,-0.38621680635767214,-2.747337876454803
455.8000000000061,34.668652793038056,-0.391111040685329,-2.7507507904162463
456.90000000000606,34.70371017165749,-0.39741281968000586,-2.7546129279277243
458.0000000000061,34.738253022464264,-0.4030008998386696,-2.757420508473717
459.1000000000061,34.77315605708654,-0.4090307185642278,-2.7607581728810136
460.2000000000061,34.808145886975666,-0.41913133406260794,-2.762981619268162
461.30000000000615,34.84304535022239,-0.42767412682087386,-2.7654047284749526
462.4000000000062,34.87833347733798,-0.432232014312711,-2.7677203619437862
463.5000000000062,34.913313739886085,-0.43886763131269296,-2.7683978624206365
464.60000000000616,34.948109324702735,-0.44301668266259503,-2.771332985147356
465.7000000000062,34.98289985840344,-0.44553251023237056,-2.772736052800633
466.8000000000062,35.017738970064435,-0.44376437865558194,-2.774453851228255
467.90000000000623,35.052862775062856,-0.4420064037775912,-2.7757752006061236
469.00000000000625,35.087823433538496,-0.4385363653646541,-2.779451836749719
470.1000000000063,35.12300615930631,-0.4337222725131895,-2.7820188258211997
471.2000000000063,35.1573613405331,-0.42699997238646775,-2.7843464262544773
472.3000000000063,35.19268782408341,-0.4175715219778452,-2.786205385814918
473.40000000000634,35.227674023544274,-0.4081052876810749,-2.7897250962939846
474.5000000000063,35.26255451941179,-0.39114214819199794,-2.7923568417632585
475.60000000000633,35.29745359312185,-0.35188477802704216,-2.795566447296366
476.70000000000636,35.33188100616986,-0.3034929193116417,-2.7972839396853963
477.8000000000064,35.366787013418154,-0.27625208243000754,-2.799374470644519
478.9000000000064,35.40174068692967,-0.25152070535602167,-2.802865638575595
480.0000000000064,35.43658018092557,-0.23417725335622916,-2.8042129147838244
481.10000000000645,35.47205166467451,-0.21724388875056652,-2.8067939507356203
482.2000000000064,35.506234924655836,-0.20676395139417814,-2.808648802269743
483.30000000000643,35.542088394632955,-0.19212661517524918,-2.8108547390483567
484.40000000000646,35.57726422269853,-0.18643338831998388,-2.8120457829345558
485.5000000000065,35.61175022083477,-0.17758420489180624,-2.813757909115171
486.6000000000065,35.64753223224701,-0.17154999062546547,-2.8165482480981625
487.7000000000065,35.682449012082074,-0.16471825747601082,-2.818980457667301
488.80000000000655,35.71744730024349,-0.15542302214913503,-2.819746423415599
489.90000000000657,35.752249487707694,-0.14837437681707488,-2.821843143934596
491.0000000000066,35.787716934266726,-0.14126089101188938,-2.824612537325274
492.10000000000656,35.8232822135354,-0.13675884278922545,-2.8263102254926107
493.2000000000066,35.858601963073085,-0.1332145226289672,-2.827825017218325
494.3000000000066,35.89373198349877,-0.12299530952339181,-2.8278935692032094
495.4000000000066,35.92917856605535,-0.10382930043269362,-2.8295437950021136
496.50000000000665,35.96425667214553,-0.09103041978368127,-2.8334397549968666
497.6000000000067,35.99895005141004,-0.07931602107919715,-2.835814952331485
498.7000000000067,36.03443087445368,-0.0732572626486736,-2.837313757775294
499.80000000000666,36.069929605580036,-0.0689636098185744,-2.8390287424655396
500.9000000000067,36.10487869047617,-0.06220151638771007,-2.839205763444511
502.0000000000067,36.13973677770907,-0.054834708550315615,-2.8406775009289857
503.10000000000673,36.17548789152931,-0.04760472895770095,-2.8434569691486695
504.20000000000675,36.21111786136463,-0.03965859961370995,-2.845743016296437
505.3000000000068,36.246197658029516,-0.03418002045867913,-2.8481414970956354
506.4000000000068,36.28136000785736,-0.028850642679568203,-2.8498211830090874
507.5000000000068,36.31682901355302,-0.022632591661958197,-2.851190949036532
508.60000000000684,36.35223852353895,-0.020545155393972253,-2.851815038215754
509.7000000000068,36.38768907440858,-0.012419755225285241,-2.8535542093064556
510.80000000000683,36.42342338520598,-0.007987934964144384,-2.85543471073382
511.90000000000686,36.45861327899105,-0.001248752026405323,-2.857127428021794
513.0000000000068,36.49406715700503,0.0014816993822136667,-2.8585221780407326
514.100000000007,36.529129505748955,0.002007914403132961,-2.8599041799719718
515.2000000000069,36.564917549347875,0.007180398366627616,-2.860397085793035
516.300000000007,36.600118147295305,0.007617045873817444,-2.861569033177619
517.4000000000069,36.63556642572847,0.01111856858876387,-2.8628335994598078
518.5000000000069,36.670955182728065,0.012858307554090209,-2.8646251143114085
519.600000000007,36.706378290432056,0.01320095917545476,-2.8667941940114945
520.700000000007,36.74200897196874,0.01623469397762595,-2.8681835642393834
521.800000000007,36.77743014644558,0.015747136121025886,-2.868647409807521
522.900000000007,36.81304303639837,0.014731711090784671,-2.8699026970603576
524.000000000007,36.848610313098746,0.014520897909636921,-2.8711457484821463
525.1000000000071,36.884286758653,0.01468250008967614,-2.872374398771818
526.2000000000071,36.91962950111186,0.0167970633259041,-2.8736887319748563
527.300000000007,36.95529336901578,0.017541549007380485,-2.875025923148277
528.4000000000071,36.99076469166274,0.020841844677138982,-2.876352594284391
529.500000000007,37.02643119033961,0.02634040997962774,-2.877545239693345
530.6000000000072,37.06190212473446,0.02926848184040716,-2.878703807315405
531.7000000000071,37.09747200174069,0.035317943646866766,-2.8800605385854925
532.8000000000072,37.13280013292982,0.03927603080212745,-2.8814993149452133
533.9000000000071,37.16868983597746,0.0373281355489126,-2.8829497662008814
535.0000000000072,37.20432662901188,0.038958832597524876,-2.8841946215571794
536.1000000000072,37.240158808675396,0.03857644010246054,-2.8857118311648535
537.2000000000072,37.27557432566268,0.0347765874597052,-2.8871178181421904
538.3000000000072,37.31131153064028,0.030236052534636397,-2.8885187774610173
539.4000000000073,37.3466613125628,0.02683789840849941,-2.888917285614659
540.5000000000073,37.38296934144224,0.023824068082112286,-2.8898338030874333
541.6000000000073,37.41856210595526,0.01908625933696747,-2.8911547437371223
542.7000000000073,37.45430649467861,0.015084569670868485,-2.8925708299006008
543.8000000000073,37.49013859530926,0.010091587424488872,-2.8938843884854313
544.9000000000074,37.52592829438886,0.006255317122299387,-2.895209397943889
546.0000000000074,37.561845472913184,-0.0012187067646579164,-2.8951775875026478
547.1000000000074,37.597636734118545,-0.004259848486317043,-2.89653886885977
548.2000000000073,37.633210020828116,-0.012119165087198923,-2.899255814409605
549.3000000000073,37.6689036141748,-0.017992864127451495,-2.9005783268157073
550.4000000000074,37.704649898251944,-0.027273747358916425,-2.9007163705972703
551.5000000000074,37.74098133641199,-0.03109665961395665,-2.9020051008091317
552.6000000000074,37.77615157750534,-0.03889303502809194,-2.9032375480616786
553.7000000000074,37.812729586399804,-0.04570500120757089,-2.9043400868345874
554.8000000000075,37.84818203437855,-0.055797664556771945,-2.904801494819145
555.9000000000075,37.88395285949996,-0.0641434030786887,-2.90698835639342
557.0000000000075,37.920155495708784,-0.07040037780565392,-2.907610111594762
558.1000000000075,37.95603066303124,-0.07951824120313405,-2.9076219689259917
559.2000000000075,37.9919770317348,-0.08640399509591715,-2.908927995411675
560.3000000000076,38.02803956217894,-0.09509107349476562,-2.9100837249731994
561.4000000000076,38.0639749855728,-0.1034834706481621,-2.9104448716803626
562.5000000000076,38.099675392215595,-0.11071700722331386,-2.9119434362840027
563.6000000000076,38.13597551636264,-0.1170289724270516,-2.9141153300066907
564.7000000000077,38.171722577204946,-0.12681765262384392,-2.9153328223630783
565.8000000000077,38.20751397050815,-0.13415264449158323,-2.9159595262324247
566.9000000000076,38.24363254339285,-0.14234744623145076,-2.9172737306530774
568.0000000000076,38.27989748220708,-0.15164323750490308,-2.9185871039570355
569.1000000000076,38.31586091982509,-0.15634689310496538,-2.918540680845375
570.2000000000077,38.35179533838197,-0.16596130364820205,-2.919910720709943
571.3000000000077,38.38801870892743,-0.17186410166450924,-2.9198712281272643
572.4000000000077,38.423688883236174,-0.18081271596996307,-2.9212334692816384
573.5000000000077,38.460134699939765,-0.1865673234010146,-2.9225780111869843
574.6000000000078,38.49588142899393,-0.19757542812687326,-2.922812541403183
575.7000000000078,38.53227757318537,-0.20224349433163166,-2.923862748503603
576.8000000000078,38.56811018947804,-0.21122965687431128,-2.9251873227911203
577.9000000000078,38.604174086224205,-0.21698888463630206,-2.926506744080774
579.0000000000078,38.640485651993856,-0.22641684683957228,-2.9258249858636725
580.1000000000079,38.67634294730338,-0.228964544662759,-2.927150167065842
581.2000000000079,38.71273512731249,-0.2359455959740605,-2.928134394331853
582.3000000000079,38.74869971624746,-0.24474654528346065,-2.929631519702336
583.4000000000078,38.78501491763358,-0.2490188646468488,-2.9308400517337265
584.5000000000078,38.82077677280661,-0.2530795430258377,-2.930879973875168
585.6000000000079,38.85702291736319,-0.2621356364980236,-2.9321968468447954
586.7000000000079,38.89341710224683,-0.2681506851522065,-2.932610126064409
587.8000000000079,38.92942197942555,-0.27578215709069914,-2.933607282476771
588.9000000000079,38.965621203446375,-0.2811950771285557,-2.9349496234727264
590.000000000008,39.002012822818635,-0.287859134778691,-2.934925434313035
591.100000000008,39.03829352039003,-0.29192638320317893,-2.935937858991335
592.200000000008,39.07466467255819,-0.2953740597202279,-2.936334136172767
593.300000000008,39.11121491543636,-0.30194716792775866,-2.935952493624435
594.400000000008,39.14710069975208,-0.3091467653986974,-2.9372628128992377
595.5000000000081,39.183703535154,-0.3134466910988386,-2.937389856574187
596.6000000000081,39.21991358068947,-0.31852732644655496,-2.9398895794407123
597.7000000000081,39.25639360150714,-0.3246334044338084,-2.941246358657728
598.8000000000081,39.2922178894229,-0.3315291287694773,-2.9418256066587896
599.9000000000082,39.32883727743558,-0.3348111803528202,-2.9414005267314076
601.0000000000082,39.36486658845789,-0.3387470847298366,-2.9425122327372364
602.1000000000081,39.40124796687214,-0.34533267632107284,-2.9428528683818422
603.2000000000081,39.43754795685076,-0.34599917625542626,-2.9438384532306388
604.3000000000081,39.47394262393147,-0.35049147742736103,-2.94517190764466
605.4000000000082,39.51044441023938,-0.357541619121208,-2.9451070593584934
606.5000000000082,39.546674216278184,-0.36067744136205265,-2.9451775901475754
607.6000000000082,39.58306092210255,-0.36512242881660506,-2.946477304355928
608.7000000000082,39.61926961726119,-0.3691093705080835,-2.9477988410737885
609.8000000000083,39.65549152310981,-0.37476070090128677,-2.947799752847471
610.9000000000083,39.69186702400671,-0.37874302505211205,-2.9483812607051676
612.0000000000083,39.72805162775122,-0.3838087850468198,-2.949188949949063
613.1000000000083,39.764554755211385,-0.38773988952500915,-2.9504142361187498
614.2000000000083,39.80066358114323,-0.39096502110859,-2.9517510830564895
615.3000000000084,39.83714721351625,-0.39504566759015397,-2.951932641124475
616.4000000000084,39.87356371134295,-0.40187359509088766,-2.9530739933020183
617.5000000000084,39.9096010196333,-0.40569684844401854,-2.954378577696824
618.6000000000083,39.94629988831923,-0.40956533455540134,-2.95439961033627
619.7000000000083,39.9825567200855,-0.4154113551384278,-2.9557014205649623
620.8000000000084,40.01874745935078,-0.420065819181586,-2.9559940236421456
621.9000000000084,40.054873891893926,-0.42456147336105765,-2.9570198579879676
623.0000000000084,40.09073544147175,-0.4274501922515927,-2.9570261714411377
624.1000000000084,40.12734106416683,-0.43267267080864785,-2.958335531096966
625.2000000000085,40.163396522579,-0.4384473096363112,-2.958706386656979
626.3000000000085,40.20022038290406,-0.44303114510209446,-2.9596640775148617
627.4000000000085,40.23584493942005,-0.4461028054632156,-2.9609600014948465
628.5000000000085,40.27282578242972,-0.4515438045854684,-2.96230339098664
629.6000000000085,40.309132011027245,-0.45524169114004187,-2.9622887759048386
630.7000000000086,40.344815376359314,-0.4580309780147792,-2.9635904090507226
631.8000000000086,40.38211224127507,-0.4638502848301849,-2.963610012757446
632.9000000000086,40.4182182278497,-0.4660121305619239,-2.963619133560255
634.0000000000086,40.454426975289586,-0.4723226694956558,-2.964933910938802
635.1000000000087,40.49095714366961,-0.4761551017459359,-2.9649312044999543
636.2000000000087,40.52702240686988,-0.4799781210738992,-2.9655428505925268
637.3000000000086,40.56359670777722,-0.4870553280222393,-2.9649304184222043
638.4000000000086,40.59966300731302,-0.48914563677836836,-2.9649198967718124
639.5000000000086,40.63632796824352,-0.4960468340841567,-2.9650584608188084
640.6000000000087,40.67283036868639,-0.4991367738779655,-2.9662382977002997
641.7000000000087,40.70914686735593,-0.5077942646177477,-2.9675560482021863
642.8000000000087,40.745485103718856,-0.5121394793762484,-2.968852099424106
643.9000000000087,40.78170720755565,-0.5183094342660995,-2.968867119025279
645.0000000000088,40.818060734482614,-0.5198416586792812,-2.970205145313279
646.1000000000088,40.85388574860043,-0.5239176442091816,-2.9701716785518313
647.2000000000088,40.89109121838503,-0.529345554313125,-2.9715113594099485
648.3000000000088,40.927286829955534,-0.5352962807769963,-2.9723495082409
649.4000000000088,40.96388585641968,-0.5384057877791303,-2.9728300091585136
650.5000000000089,41.000220051077676,-0.5450920490836345,-2.972829764636633
651.6000000000089,41.036656239991004,-0.5499699625563311,-2.9731815260393932
652.7000000000089,41.073002914923926,-0.5612027476084117,-2.9741400287491953
653.8000000000088,41.109669848205016,-0.5754600251792917,-2.975377170865579
654.9000000000088,41.14586315933278,-0.5886599124113489,-2.9754601042501583
656.0000000000089,41.18252951940326,-0.5937258354979379,-2.9754601062246797
657.1000000000089,41.219002423820534,-0.602476943793944,-2.975459971529031
658.2000000000089,41.25513648500012,-0.6061634040835154,-2.9770094536459624
659.3000000000089,41.29171724639637,-0.611227419510011,-2.9785281775893533
660.400000000009,41.32826420605553,-0.6197276723482151,-2.979962261583879
661.500000000009,41.364713656638415,-0.621429374420989,-2.97996017237738
662.600000000009,41.40123120880896,-0.6286247587012262,-2.980097830954538
663.700000000009,41.43754790280003,-0.6322067438145882,-2.9814867306234465
664.800000000009,41.47400924411408,-0.63595073852383,-2.9825992625855764
665.9000000000091,41.51057202544873,-0.6407867326046894,-2.9812069409266604
667.0000000000091,41.54698463055065,-0.644353693252607,-2.982269834668945
668.1000000000091,41.58300814424262,-0.6462243358047441,-2.982467355203064
669.2000000000091,41.619980728825446,-0.6485652253770994,-2.9825998533593725
670.3000000000092,41.6562024308537,-0.6514206867191571,-2.9838181423714705
671.4000000000092,41.69286445313475,-0.6602460099137275,-2.9839158698749686
672.5000000000091,41.72944506213774,-0.6632454101691948,-2.985129779314486
673.6000000000091,41.765665117370325,-0.6686795388905284,-2.985229643175956
674.7000000000091,41.802204680798425,-0.6710166460155522,-2.986253277393759
675.8000000000092,41.8385654720787,-0.675383017540704,-2.9865398025585543
676.9000000000092,41.874534367542246,-0.6777166374019238,-2.985378956451887
678.0000000000092,41.911754659604966,-0.6822424026367275,-2.985229884762326
679.1000000000092,41.948169557145576,-0.6834589644519171,-2.9852298254822895
680.2000000000093,41.98474969716967,-0.684211500397085,-2.9854753544314647
681.3000000000093,42.020929198472224,-0.6839570192532488,-2.986549535517521
682.4000000000093,42.05793456226262,-0.6887374642474006,-2.9865499284518116
683.5000000000093,42.09448646419249,-0.689734902237865,-2.986570630959827
684.6000000000093,42.13107817695578,-0.6936776480144471,-2.986547427737156
685.7000000000094,42.16764063140924,-0.6950209867358986,-2.9879219155477865
686.8000000000094,42.20408377632552,-0.6982751275442696,-2.9878744948676297
687.9000000000094,42.240581981628125,-0.7002485274317892,-2.989175892302617
689.0000000000093,42.277327979297674,-0.7001789457359266,-2.9896130041885614
690.1000000000093,42.31383645844021,-0.7065108306531364,-2.9918076711273898
691.2000000000094,42.35032452221816,-0.709193298824611,-2.991766354302669
692.3000000000094,42.38704161034299,-0.7125044191354433,-2.9931390716353694
693.4000000000094,42.42378763975781,-0.7164754416059221,-2.9933263277869684
694.0000000000094,42.44283314202262,-0.7183639859979305,-2.9944770703492596