File: 01_Data/PE_Foam_Pipe_Insulation/STA/N2/10K_min/PE_Foam_Pipe_Insulation_STA_N2_10KData_220926_R3.csv
##Temp./Â°C,Time/min,DSC/(mW/mg),Mass loss/mg
51.0,10.77917,0.06184446095046936,0.019198451060650434
51.80000000000001,11.06436758925596,0.11916257239647465,0.014910778746283881
52.60000000000002,11.25596046881028,0.156814728163305,0.014423732818212187
53.400000000000034,11.43148201762155,0.19326897306062607,0.015328863964188422
54.200000000000045,11.579938996908702,0.22355294015413052,0.016269197900729004
55.00000000000006,11.71815076711176,0.25255020268387596,0.014540129087638576
55.80000000000007,11.848548913316197,0.2761868869290498,0.013331007391585104
56.60000000000008,11.97164564092767,0.2986956542324828,0.013580915929122028
57.40000000000009,12.09019020313019,0.3166222084026211,0.014258071591906507
58.2000000000001,12.203224854261723,0.3371757474844359,0.016287395893114898
59.000000000000114,12.31575590219275,0.35231405919271275,0.018754150873814268
59.800000000000125,12.423192237665459,0.36361245793952723,0.018315032296588818
60.600000000000136,12.53100281960714,0.3748688653707908,0.017994484135400057
61.40000000000015,12.636130521243572,0.3839587201925104,0.01754144242215272
62.20000000000016,12.739290477884479,0.38800271152353294,0.018462572761984042
63.00000000000017,12.84023837235425,0.39074582720280526,0.01712896712331169
63.80000000000018,12.938292496288291,0.39281426967635424,0.018256874260764278
64.6000000000002,13.040356968410048,0.39653296501281965,0.017348980990994356
65.4000000000002,13.138058763496046,0.39915797965471844,0.01604236628959299
66.20000000000022,13.236844289907552,0.4048613110084325,0.017373727112731885
67.00000000000023,13.332005194491368,0.4086096468995364,0.01723971431377791
67.80000000000024,13.427015799195157,0.41185469152016185,0.0175718680136292
68.60000000000025,13.520828064366397,0.41658083010493874,0.016313800534478062
69.40000000000026,13.613253378124133,0.4236907170621689,0.01646730872645019
70.20000000000027,13.705924095877858,0.42891487934447436,0.017346176413029823
71.00000000000028,13.797788955327169,0.4356975958516969,0.016212055508246337
71.8000000000003,13.889170000000034,0.43929662365234634,0.01690225145950297
72.6000000000003,13.980557296921798,0.44892114453028853,0.017573303838489984
73.40000000000032,14.070929478111857,0.4559391461338542,0.018857107950300822
74.20000000000033,14.158088838857596,0.4628492312044201,0.01817960052483336
75.00000000000034,14.24975409361593,0.4705921045520207,0.017539849490191273
75.80000000000035,14.337960126457103,0.4794377887337654,0.01784297608049723
76.60000000000036,14.42583817073365,0.48652178667859314,0.01823236616954116
77.40000000000038,14.514463684681258,0.49380129227383396,0.018370665996886082
78.20000000000039,14.60231345707257,0.503415318718422,0.01857892964278829
79.0000000000004,14.689285458537814,0.5106439708246902,0.019559627925139544
79.80000000000041,14.773596206276384,0.5183774667290675,0.020162235628823133
80.60000000000042,14.862770871874476,0.5284329278079011,0.0196623590093008
81.40000000000043,14.947305564084791,0.5369390618091295,0.019788537920007343
82.20000000000044,15.034158736757977,0.5444443032623878,0.01904461094162979
83.00000000000045,15.11906311900619,0.5532409764995817,0.020200837778037162
83.80000000000047,15.202650577938309,0.5630778989077203,0.018982744531247597
84.60000000000048,15.287394172620022,0.5730685777152905,0.02037106079526918
85.40000000000049,15.370572912933934,0.5824208662943624,0.020802214890543347
86.2000000000005,15.454888586236573,0.5921065901586371,0.02030845097936229
87.00000000000051,15.538149315390346,0.6003651920238842,0.01895096079364844
87.80000000000052,15.622079922549839,0.6097115986251181,0.020310364988316287
88.60000000000053,15.704934530789858,0.6203186808544803,0.020326669768336636
89.40000000000055,15.788186865572081,0.6291853778519326,0.019290674797289853
90.20000000000056,15.869719549249371,0.6376235411606047,0.02027451646593814
91.00000000000057,15.948920708248362,0.6531004560043558,0.02029602896627125
91.80000000000058,16.03231307574868,0.6628623000564096,0.020297201094114037
92.60000000000059,16.11487492234999,0.6766091694672751,0.02040061908782853
93.4000000000006,16.195925026226302,0.6921476204616206,0.02044080610200627
94.20000000000061,16.275731515168214,0.7072712029911064,0.02162333338630873
95.00000000000063,16.35760184258971,0.7232007623366481,0.020304602651560977
95.80000000000064,16.43879480787337,0.7412664138408787,0.02031761764460338
96.60000000000065,16.517602383494186,0.7562074867003029,0.021650633323845092
97.40000000000066,16.598857313060112,0.7684984930908911,0.02032003598783305
98.20000000000067,16.678282551229927,0.7779265936676587,0.021367156683583133
99.00000000000068,16.759075270923837,0.7820205359623549,0.02030543870727275
99.8000000000007,16.837417118509208,0.7897146039204108,0.020311500622250733
100.6000000000007,16.918489552838466,0.8039682279231599,0.021357119965236926
101.40000000000072,16.99867970430941,0.8185715903781147,0.021639521862999445
102.20000000000073,17.07634866300451,0.8363311722194322,0.020647957951316798
103.00000000000074,17.156898829004486,0.8628743672334449,0.01924296292080463
103.80000000000075,17.23315551537321,0.8878647945514878,0.020319260690212282
104.60000000000076,17.314248893585052,0.9189423646863384,0.020375601406629862
105.40000000000077,17.39471841060418,0.9556427778989534,0.020349401907099995
106.20000000000078,17.473404623992806,0.9939624077873964,0.020717603367987003
107.0000000000008,17.550030410907716,1.0370458479035016,0.021637911215500516
107.80000000000081,17.632468993736488,1.0923243600121795,0.020320141239301925
108.60000000000082,17.711602447296368,1.1511987003646418,0.01901454684402193
109.40000000000083,17.79076445301261,1.2149499581579888,0.02031498501097495
110.20000000000084,17.867558830499267,1.2876447890239926,0.020201530671609902
111.00000000000085,17.947377927790093,1.3649637613308552,0.021662273025472523
111.80000000000086,18.027413582120253,1.4513365795377213,0.02197178351455964
112.60000000000088,18.105892092083224,1.5365992595578424,0.02268842940413407
113.40000000000089,18.185906834043873,1.6094455162851495,0.021626485159144337
114.2000000000009,18.26471113843945,1.6444242492628254,0.02254475882656326
115.00000000000091,18.343669346449293,1.6003930262473547,0.022948691978492697
115.80000000000092,18.422081789494463,1.4047161662039283,0.022948033496838605
116.60000000000093,18.49955313253842,1.1150210926798072,0.021652383309625378
117.40000000000094,18.576096203645797,0.899092785338347,0.022758263878685625
118.20000000000095,18.654882522212997,0.7443377980271039,0.022181976068577747
119.00000000000097,18.731053584848222,0.6542706209583303,0.021639907768953748
119.80000000000098,18.808418237344263,0.5905144410106439,0.021638645809468393
120.60000000000099,18.885754751259167,0.550874592386367,0.022277070524149956
121.400000000001,18.961719539651416,0.5249553150573629,0.021579054533827247
122.20000000000101,19.03898135283071,0.5081217604735762,0.02030977729570793
123.00000000000102,19.115080394327073,0.5015611609600644,0.021617567285512784
123.80000000000103,19.19304627120745,0.4937617955351291,0.021636744186740664
124.60000000000105,19.26896768378848,0.4914273311665768,0.021284017055512194
125.40000000000106,19.347362235466875,0.4882137071831788,0.02027616762178308
126.20000000000107,19.42502376979427,0.4873975299240515,0.019019374754106977
127.00000000000108,19.501289360186064,0.486384380244949,0.01904466612688971
127.80000000000109,19.577232712553545,0.48627849694808856,0.020265376060040197
128.6000000000011,19.655285401951183,0.48401238597812823,0.023285882301479432
129.4000000000011,19.731306747393113,0.48657032083736995,0.024249578741998512
130.20000000000113,19.806300836905443,0.4870419379202515,0.02408360430853751
131.00000000000114,19.886408498279987,0.4869111966934292,0.024267298386114078
131.80000000000115,19.96222041011184,0.48797254253535993,0.02426342998608888
132.60000000000116,20.03947480347453,0.4883317446037394,0.023274359969080116
133.40000000000117,20.115418762800324,0.4927766797410271,0.023298529368566356
134.20000000000118,20.192227253703205,0.4923343640386957,0.02294866635171111
135.0000000000012,20.267830467069423,0.49241424056032823,0.0226563118237042
135.8000000000012,20.346279012964253,0.49524498134619055,0.022949778612052718
136.60000000000122,20.421281864783666,0.49596378776877703,0.022949806251060245
137.40000000000123,20.49765457816756,0.49840329834835007,0.022944905770680535
138.20000000000124,20.574363631619,0.4986255873543143,0.022952703620235937
139.00000000000125,20.651940740301097,0.5014862489374877,0.021570714085583198
139.80000000000126,20.728964397119697,0.4997636050157862,0.022602262246025795
140.60000000000127,20.804909356513445,0.5011511051893746,0.02294904032852596
141.40000000000128,20.881641760295892,0.5024646779844281,0.021639509029049542
142.2000000000013,20.95895729673563,0.5025205205919859,0.021639989204444987
143.0000000000013,21.0335445391321,0.5040287466444701,0.02163977378465809
143.80000000000132,21.11047794136672,0.5064832335318318,0.022941633915688264
144.60000000000133,21.18605922882758,0.5057417708089005,0.022485909214053024
145.40000000000134,21.26108349295578,0.5077000601140443,0.020120227535326052
146.20000000000135,21.339649941660607,0.5083060645839514,0.021411444413844016
147.00000000000136,21.415560525568544,0.5080381855868441,0.023884391085439383
147.80000000000138,21.49242479445672,0.512464037277218,0.023055336358319245
148.6000000000014,21.567733177669407,0.5123097051691161,0.02273136029574907
149.4000000000014,21.644920847687846,0.5105714008141298,0.022730533498246608
150.2000000000014,21.72101449040005,0.5151759225667338,0.023228815391968638
151.00000000000142,21.797011520213267,0.5150557440432293,0.024041913054539954
151.80000000000143,21.86902815297875,0.5147227360523019,0.024050130721334106
152.60000000000144,21.948270783118694,0.5156223631633143,0.02345757121135339
153.40000000000146,22.02415139605805,0.5166897481908522,0.0243838865746957
154.20000000000147,22.098987567110495,0.517860642387961,0.02438008099013622
155.00000000000148,22.176465941715133,0.518941162963007,0.0243800366719924
155.8000000000015,22.2534577706968,0.5223175166554377,0.02405788696623201
156.6000000000015,22.328166629613396,0.5224730139622767,0.02273032301828959
157.4000000000015,22.403389544783344,0.5230017275656913,0.022726010809406283
158.20000000000152,22.48075186956528,0.5252721955813158,0.024053276298008797
159.00000000000153,22.555681289017762,0.5249500714562115,0.022729910718908286
159.80000000000155,22.632125555860156,0.5287737387582919,0.023063024719681025
160.60000000000156,22.70831735563145,0.5287792339556935,0.024040351989495612
161.40000000000157,22.783625129932897,0.5304412306281946,0.02404381490609353
162.20000000000158,22.85983929295514,0.5324101584386914,0.022729980200799638
163.0000000000016,22.935980428506284,0.5326871684176024,0.02272743805714761
163.8000000000016,23.01214142363597,0.5335624992674437,0.023060031087388744
164.60000000000161,23.08722838368226,0.5341390507380452,0.023060154504494612
165.40000000000163,23.16365986596776,0.5350760764747418,0.022736343357850686
166.20000000000164,23.239170000000158,0.5339201673653006,0.023720099890154778
167.00000000000165,23.316195458685296,0.5359561553579,0.023723023419696787
167.80000000000166,23.391912511437358,0.5394253483980653,0.022401067134182107
168.60000000000167,23.46779006522525,0.5359478010859906,0.022398750512022225
169.40000000000168,23.542806086019933,0.538548052623832,0.024171130484615944
170.2000000000017,23.61967342600551,0.5379389576029492,0.022729956510044502
171.0000000000017,23.694728168418536,0.5394344853119041,0.022729958878619172
171.80000000000172,23.771584030488235,0.5396760408408687,0.023279360168123375
172.60000000000173,23.84650071432573,0.5389704161075048,0.02403993458771403
173.40000000000174,23.922051859902545,0.5417462301051452,0.022685769037533277
174.20000000000175,23.996533132558273,0.5429222592573426,0.021414696127433075
175.00000000000176,24.074368518510877,0.5425397278497859,0.022691741374820218
175.80000000000177,24.149867894974665,0.5427968419395011,0.023719649367500928
176.60000000000178,24.227324405886158,0.5442642607972339,0.02471049706150996
177.4000000000018,24.301973503472034,0.5455776291678902,0.024682740756106547
178.2000000000018,24.379260139894573,0.5464496606786566,0.0233862944178016
179.00000000000182,24.452979676400037,0.54782920095289,0.02281049752115294
179.80000000000183,24.53153818800456,0.5475394528600717,0.02141015453962325
180.60000000000184,24.605520458307062,0.5474454697070205,0.021318407126221572
181.40000000000185,24.682448230368667,0.5515073573993347,0.02206688615184227
182.20000000000186,24.758407443204856,0.5499571011732156,0.022729838649356182
183.00000000000188,24.83458274800547,0.5486989338558719,0.02148933133156561
183.8000000000019,24.909170000000167,0.5518976432170994,0.022079989861240712
184.6000000000019,24.98617885318515,0.5503844841963268,0.022659098130203503
185.4000000000019,25.060916403686726,0.5518041286422632,0.022729954299648192
186.20000000000192,25.137048722962195,0.5507711427400857,0.022699395016462454
187.00000000000193,25.21355954138765,0.5512731759118112,0.021739604016577374
187.80000000000194,25.289265480754437,0.5518022357887247,0.021739927986297758
188.60000000000196,25.365204581646648,0.5535603785556082,0.021739930383924744
189.40000000000197,25.44099639657273,0.5547314272397936,0.0218077405631103
190.20000000000198,25.515748404787047,0.5544756469764951,0.021224463579270214
191.000000000002,25.591764273368174,0.5575255510826418,0.021409835415295397
191.800000000002,25.667162111369407,0.5565721672699111,0.02140984700020443
192.600000000002,25.743645556123255,0.5561432749195327,0.020089908348865038
193.40000000000202,25.81907195407389,0.5572680087370601,0.020089847287515283
194.20000000000203,25.894084144452464,0.5566596278345388,0.02149689872250793
195.00000000000205,25.97091744266451,0.5580245946194222,0.021410136151768455
195.80000000000206,26.046530597029786,0.5576879002214479,0.021432678789277126
196.60000000000207,26.12197277419158,0.5576267809702966,0.019104821761576574
197.40000000000208,26.19821450229442,0.5605587222456905,0.01910982976266684
198.2000000000021,26.272766595346155,0.5605112381828966,0.020213348206348236
199.0000000000021,26.34917000000021,0.5594011124105024,0.01878014568543307
199.80000000000211,26.424750466913128,0.560598930002848,0.018780137963035237
200.60000000000213,26.500233243692808,0.5615613755959807,0.018778730730310222
201.40000000000214,26.576567890460986,0.5641605871794377,0.017460228973591008
202.20000000000215,26.652513214354652,0.5638435490059783,0.01746018090613255
203.00000000000216,26.728046247654632,0.5643011614854088,0.017799645938776365
203.80000000000217,26.804412039186097,0.565057658350022,0.017790112193568852
204.60000000000218,26.879940186557118,0.5647523926146709,0.0177901110000116
205.4000000000022,26.95551579494709,0.5647464898582687,0.017790110999934328
206.2000000000022,27.030683602176968,0.5665621706264201,0.017790107990536264
207.00000000000222,27.10551953142925,0.567502794330203,0.017819740930794303
207.80000000000223,27.183216416418386,0.566943911854228,0.01746135185437847
208.60000000000224,27.25926857175416,0.5692490221009386,0.01647121570801957
209.40000000000225,27.33431454297311,0.5686193468091516,0.01647051141620892
210.20000000000226,27.41028113322016,0.5714258249824504,0.015491609018524422
211.00000000000227,27.48658594619721,0.5688701445394304,0.015161466607354512
211.80000000000229,27.562237876912672,0.5695263168855065,0.016480525563704163
212.6000000000023,27.63802209769111,0.5711520477204126,0.01651196398829846
213.4000000000023,27.71437819467801,0.5731151938636412,0.01380014101467264
214.20000000000232,27.79019647980759,0.5725599388337101,0.013840109147055024
215.00000000000233,27.86579872941801,0.5735817904596865,0.013840111000028799
215.80000000000234,27.939336002936482,0.5734013279974627,0.013840111000507527
216.60000000000235,28.017602637802653,0.5775833646817117,0.013840115847447265
217.40000000000236,28.093368902425567,0.5781392576414737,0.013357053368041605
218.20000000000238,28.16735403831201,0.577535792488635,0.01318008642113444
219.0000000000024,28.246247781299278,0.5783466567189219,0.012836123546859035
219.8000000000024,28.32088924858664,0.5783418170702127,0.012520161767888283
220.6000000000024,28.397622307110982,0.579621286263188,0.012520263534179676
221.40000000000242,28.472731581784217,0.5767355153729516,0.011202118567154251
222.20000000000243,28.54879114980116,0.5804258643354689,0.011202126991769035
223.00000000000244,28.62460236015541,0.5791950425765606,0.008657578435075752
223.80000000000246,28.701027999723856,0.5792548641906414,0.010889936043677828
224.60000000000247,28.776570644250523,0.5810410955187468,0.01084436399199884
225.40000000000248,28.85211620661293,0.5806862146557243,0.009549849636022234
226.2000000000025,28.92617303494126,0.5805136491828152,0.009527226378684528
227.0000000000025,29.00474443086103,0.582987857501136,0.008568720636100924
227.8000000000025,29.079883916467125,0.5829094436010048,0.008569321537988728
228.60000000000252,29.157454234384833,0.5833822187655657,0.007909799885449154
229.40000000000254,29.23194726645565,0.5850066318170067,0.005932550167905504
230.20000000000255,29.307524945140422,0.5834269874842247,0.005929928031981113
231.00000000000256,29.384597345526714,0.5850308795837967,0.00592992890820998
231.80000000000257,29.459627162784248,0.5847796054073866,0.005963443389048972
232.60000000000258,29.53549162198252,0.5863597903159792,0.006387922316267058
233.4000000000026,29.61196584712344,0.5858592394127015,0.004226389777515216
234.2000000000026,29.68816564070901,0.5843813158092149,0.00430612016252141
235.00000000000261,29.76395006936653,0.5845545911870744,0.0027966012721329925
235.80000000000263,29.840338022482428,0.5857601535118069,0.0016268876916480934
236.60000000000264,29.916429244007226,0.5831638052218662,0.0016503029009662384
237.40000000000265,29.99270941944695,0.5846555283390109,0.0013171980971207198
238.20000000000266,30.068244571371157,0.58374182561251,0.0013213910257507955
239.00000000000267,30.14486633369545,0.58441254582863,-0.0009020590625303804
239.80000000000268,30.22077913588183,0.5850545310574551,-0.000946722091436758
240.6000000000027,30.294704824970243,0.5853296601290777,-0.0023100207860302646
241.4000000000027,30.372903076989086,0.5859650754342443,-0.0023100370011381877
242.20000000000272,30.449170000000265,0.5866982182116252,-0.0023100369999928816
243.00000000000273,30.525057603979867,0.5864681176443836,-0.0034235714471093637
243.80000000000274,30.60115858637677,0.5879823315993415,-0.003624970541928896
244.60000000000275,30.67705512118891,0.5872885108245556,-0.004929318908197811
245.40000000000276,30.7535475979426,0.5873678813400126,-0.006248204297049309
246.20000000000277,30.829374473760218,0.5876231290934979,-0.006262181392168387
247.00000000000279,30.903398364552622,0.5883891578160392,-0.007570130724871227
247.8000000000028,30.979833635736735,0.5882911372552924,-0.007569213654359697
248.6000000000028,31.05829395708426,0.5886839328887863,-0.01020177246462417
249.40000000000282,31.134017082788716,0.5884883597454185,-0.010200059841129594
250.20000000000283,31.20956034887253,0.5880921993338821,-0.008880110471980895
251.00000000000284,31.285744106021006,0.5895690501706995,-0.0101090838680844
251.80000000000285,31.361917536813824,0.588255712805572,-0.011752244337079443
252.60000000000286,31.43822637259086,0.5875554691382675,-0.012829712138612948
253.40000000000288,31.51504015141653,0.5890923147652023,-0.012509901101953602
254.2000000000029,31.58936441152904,0.5895002738856444,-0.012514633558847077
255.0000000000029,31.666445511261458,0.5911132726393381,-0.014473109195087375
255.8000000000029,31.74269998891874,0.5887815573722655,-0.01454901760798677
256.6000000000029,31.81916911580395,0.5916969886891126,-0.016460049455280235
257.40000000000293,31.89471277905154,0.5909677852964678,-0.016367212542490073
258.20000000000294,31.970882587790083,0.5900971561342859,-0.017776636713777272
259.00000000000296,32.046985585275834,0.5917440178977373,-0.020460871175972617
259.80000000000297,32.122904615076756,0.5928871666657338,-0.020419833166397616
260.600000000003,32.19785503922142,0.5925180942067174,-0.02041723775679305
261.400000000003,32.27445795163556,0.5928444957292742,-0.021739400981193757
262.200000000003,32.35113845781913,0.5927189838963205,-0.021740222905543227
263.000000000003,32.42756962540353,0.593203030938002,-0.023048327253192724
263.800000000003,32.50261128452472,0.5929729115461448,-0.022968487587105013
264.60000000000304,32.57897913362038,0.5917789599085574,-0.024359071446836467
265.40000000000305,32.65446207953435,0.5914874137976353,-0.02567949860363461
266.20000000000306,32.729065572045776,0.5927375635163645,-0.027000370884574743
267.00000000000307,32.8065102389743,0.5907704953651569,-0.026895217644670844
267.8000000000031,32.88128658170123,0.5900375021122939,-0.029699321814317337
268.6000000000031,32.95992152920127,0.5905507323956971,-0.028975595508817342
269.4000000000031,33.033920099706876,0.5898919629205447,-0.028320081886842985
270.2000000000031,33.10936102311629,0.5898184356285834,-0.02962721728741302
271.0000000000031,33.187300552163265,0.5908559062955692,-0.03101565813797702
271.80000000000314,33.26299590901043,0.5891142314653411,-0.030963107880976892
272.60000000000315,33.33988447191774,0.5872967918558346,-0.03226988701469047
273.40000000000316,33.41553244653249,0.5865150348750552,-0.03359291213246607
274.2000000000032,33.49163350523352,0.5881341108957648,-0.034281170800310345
275.0000000000032,33.56814937915392,0.5873138411937024,-0.03553955483898452
275.8000000000032,33.64423847018704,0.5878485116694642,-0.035570122909857727
276.6000000000032,33.72058022897132,0.5853118412093686,-0.03658531088964878
277.4000000000032,33.79700199943406,0.5882583657643029,-0.03687603457259048
278.20000000000323,33.87349142555634,0.5874098456747596,-0.03696341178656759
279.00000000000324,33.94934782902258,0.5880374902286014,-0.0381999171842935
279.80000000000325,34.02615799433002,0.587675163215452,-0.03819989801331758
280.60000000000326,34.102749264331344,0.5871486304719575,-0.039299458302362034
281.4000000000033,34.17897484261059,0.5856163409879934,-0.040494878860794614
282.2000000000033,34.25496731726878,0.5874051000627116,-0.042799906244147756
283.0000000000033,34.3308651642124,0.5867123070703648,-0.04281837449378667
283.8000000000033,34.407241887490876,0.5860849195006071,-0.04314021478858443
284.6000000000033,34.483346882806146,0.586536888594527,-0.04184100496556553
285.40000000000333,34.56047067590648,0.5870338093800939,-0.043218143420561184
286.20000000000334,34.63603962857813,0.5880497156621627,-0.04412010785713427
287.00000000000335,34.71100828083531,0.5854528985620424,-0.04408482404131009
287.80000000000337,34.788780919043546,0.5861824971483189,-0.04509361981566551
288.6000000000034,34.86510940908077,0.5860588837259105,-0.04542196233914142
289.4000000000034,34.940814428706695,0.5870098796349597,-0.04675931578692527
290.2000000000034,35.0181836645692,0.5876610966369303,-0.048413227966135786
291.0000000000034,35.09414695869573,0.5865683056737158,-0.0470948419434829
291.8000000000034,35.169644427666626,0.587630335826737,-0.04841241160739296
292.60000000000343,35.24658690181659,0.5882538947297068,-0.048211933947730934
293.40000000000344,35.32270846804104,0.5866473822655848,-0.047955426074477
294.20000000000346,35.3999676841272,0.5872514369107973,-0.048740542870016945
295.00000000000347,35.47565529047779,0.5858246014370619,-0.050059775694801356
295.8000000000035,35.55170778026832,0.5880245602444978,-0.05136223465564349
296.6000000000035,35.62907068061672,0.5888342761799993,-0.05269318880400675
297.4000000000035,35.70495739248489,0.5890871810118401,-0.05268945208582565
298.2000000000035,35.781470051527734,0.5877772781799817,-0.05137014535954609
299.0000000000035,35.85730457871339,0.5886030114093138,-0.0510424478754028
299.80000000000354,35.93394687933486,0.5861463311055869,-0.052027897916584465
300.60000000000355,36.010351975349295,0.5881990858052781,-0.0521169744495249
301.40000000000356,36.08767673384525,0.5876132268941459,-0.05335000832890646
302.20000000000357,36.16375631164734,0.5890896788849678,-0.05331930502462434
303.0000000000036,36.24148874530801,0.5888626246452047,-0.05452632686633807
303.8000000000036,36.317028051270675,0.5873744905423388,-0.05499985074431191
304.6000000000036,36.39372863223186,0.5880427113517713,-0.05499984400034208
305.4000000000036,36.47048971682874,0.5878219784176404,-0.05499984400000013
306.2000000000036,36.54725676032924,0.5886254096005558,-0.05499984400000191
307.00000000000364,36.62362148513606,0.5888089770946767,-0.05499984404253855
307.80000000000365,36.70046315937501,0.5877747632568299,-0.055000278783032375
308.60000000000366,36.777065557873854,0.5884411016310124,-0.05599075878035764
309.4000000000037,36.853820208076456,0.5890317179446687,-0.056320322725430305
310.2000000000037,36.931165485315155,0.5920162301342595,-0.05772961095706641
311.0000000000037,37.0072104756796,0.5925461865911045,-0.057630047882403446
311.8000000000037,37.084679092573815,0.5953402599685971,-0.057628228958083394
312.6000000000037,37.162356962724076,0.5954601421348246,-0.05631780982803125
313.40000000000373,37.237284930895896,0.5963619389854543,-0.05756768920231847
314.20000000000374,37.31414112503461,0.5964141062100723,-0.058941379683327355
315.00000000000375,37.39127293760792,0.5991191575206621,-0.06027761026884937
315.80000000000376,37.46748419346175,0.598506553227339,-0.05894829939262802
316.6000000000038,37.54462417135407,0.6011840236936312,-0.06026998910676262
317.4000000000038,37.621745522438786,0.5994741145312996,-0.06026999566212954
318.2000000000038,37.69832685932032,0.5978297219632978,-0.06158555882721606
319.0000000000038,37.77512443755588,0.6006575941319976,-0.06366348973428693
319.8000000000038,37.849820480074726,0.6016017412298535,-0.06388991721041304
320.60000000000383,37.92898188783234,0.6018827586934361,-0.06259057306809801
321.40000000000384,38.0064572907777,0.6038704455339043,-0.06258012715516736
322.20000000000385,38.08271740134881,0.6064207291385706,-0.06326003450919382
323.00000000000387,38.15945407199004,0.6083398224305692,-0.06522320086733213
323.8000000000039,38.23639171381765,0.6117922849257073,-0.06555807254035306
324.6000000000039,38.31258714872895,0.6130915615916445,-0.06684980044612221
325.4000000000039,38.38917102493478,0.6159200165698516,-0.06717991053712513
326.2000000000039,38.466725999759745,0.6173886112542311,-0.0682197610116404
327.0000000000039,38.54347608500714,0.620951542150521,-0.06817086251113036
327.80000000000393,38.61986356263601,0.6243293712836844,-0.06916179719662541
328.60000000000394,38.697208591013705,0.6261758219620082,-0.06948970496876328
329.40000000000396,38.7739694404825,0.6267465674727147,-0.07081460880795554
330.20000000000397,38.85096338172644,0.6305446817681256,-0.07212016946981059
331.000000000004,38.92791879833777,0.6317457570046963,-0.07343039333332513
331.800000000004,39.004854582621235,0.6348976206016353,-0.0734335831571098
332.600000000004,39.08188472672276,0.6370689183973881,-0.07474995692091913
333.400000000004,39.15886616313845,0.6377984158469028,-0.07475013750870962
334.200000000004,39.234890538609825,0.6389172667745414,-0.07531231953889028
335.00000000000404,39.31303067781517,0.6410433407713568,-0.07736066841782474
335.80000000000405,39.389424622258204,0.6431895977592025,-0.0786989695507927
336.60000000000406,39.46656860735146,0.6427261481420086,-0.07875381399769621
337.40000000000407,39.54252707484424,0.6427894572560339,-0.0800298829726489
338.2000000000041,39.62051707309413,0.6452387276010917,-0.08122049164615941
339.0000000000041,39.69772324782528,0.6450416087703543,-0.08134779186765773
339.8000000000041,39.774061193722275,0.6486353630807551,-0.08402833137353216
340.6000000000041,39.851701540698514,0.6476318631091247,-0.0845469504921037
341.4000000000041,39.928574232839026,0.6478290417504459,-0.08595529330314022
342.20000000000414,40.005489290912955,0.6490248386917796,-0.0888125768124235
343.00000000000415,40.08289260534003,0.6491504633937157,-0.08881866223479884
343.80000000000416,40.160346505804824,0.6497772829797289,-0.08991133536192297
344.6000000000042,40.23719223729742,0.6486525512064268,-0.09209982492992408
345.4000000000042,40.315152887020915,0.6495017512877227,-0.09500206035552639
346.2000000000042,40.39034200612152,0.651705466683101,-0.0967350932055302
347.0000000000042,40.46888862499464,0.6488572577834126,-0.09803256632520574
347.8000000000042,40.54637820879198,0.6507204085047984,-0.09934910152868293
348.60000000000423,40.622907444040095,0.6506370586016433,-0.1007160774623288
349.40000000000424,40.70106503630291,0.6497381260428114,-0.10196686303995373
350.20000000000425,40.77844448458639,0.6516849576117985,-0.10485792670952421
351.00000000000426,40.855480626732664,0.6511714331858249,-0.10701070331116247
351.8000000000043,40.93188489499623,0.6506157345485382,-0.10940030288990599
352.6000000000043,41.00935862193717,0.6525055742328713,-0.1114464250145053
353.4000000000043,41.087229384078015,0.6510903512549625,-0.11472804323228303
354.2000000000043,41.164085619044286,0.6541741089967051,-0.11619547243130945
355.0000000000043,41.240472895363155,0.652167744596357,-0.11733405024051757
355.80000000000433,41.31846250444791,0.6517707093907534,-0.11867073941072892
356.60000000000434,41.396384042424756,0.6509013198113162,-0.12001046037602237
357.40000000000435,41.47428212770007,0.6493614975575668,-0.12361544699519245
358.20000000000437,41.551231107860374,0.6466873638524938,-0.12576172544319775
359.0000000000044,41.628363674648035,0.6469850738614626,-0.12690523675256404
359.8000000000044,41.70592558375774,0.6458737360463745,-0.12751430320503854
360.6000000000044,41.78276035255928,0.6455104560593459,-0.12888019630776482
361.4000000000044,41.86013359549971,0.6429323096360208,-0.13018820881235094
362.2000000000044,41.938201935882894,0.6401779324005871,-0.13279044684428953
363.00000000000443,42.01488333356856,0.6393573959007126,-0.13525719349933985
363.80000000000445,42.09347886463804,0.6361215335546173,-0.1382429542271888
364.60000000000446,42.170685267984425,0.6355124208517461,-0.14093276830943768
365.40000000000447,42.248946549551206,0.633773453082773,-0.14087462302346498
366.2000000000045,42.32559628991818,0.63045005739701,-0.14304237105275197
367.0000000000045,42.40164747833011,0.6289645308411355,-0.14438389247369132
367.8000000000045,42.480212978542326,0.6262090174349894,-0.1448852479452123
368.6000000000045,42.55715608963143,0.6207465266049437,-0.14807396208011214
369.4000000000045,42.632861522095105,0.6204897236339304,-0.1495152224892733
370.20000000000454,42.712830031223675,0.6165409414800389,-0.15084063565296146
371.00000000000455,42.78975866397617,0.6148670371158699,-0.15216307910744886
371.80000000000456,42.86681869297621,0.6116971444545118,-0.15361211016168141
372.60000000000457,42.944955866837596,0.6091524166229723,-0.15473722394071432
373.4000000000046,43.02174402896348,0.6066575433854797,-0.15677035217082258
374.2000000000046,43.09976863571411,0.6042544168197602,-0.15808953357773703
375.0000000000046,43.17658284350928,0.600493066458521,-0.15931137418729557
375.8000000000046,43.25538733240584,0.5983145297829583,-0.1620063867895878
376.6000000000046,43.330831537144334,0.5953658658760247,-0.1635079603541647
377.40000000000464,43.4100639339191,0.5940424494582492,-0.16379644278695782
378.20000000000465,43.48735146204753,0.5887205817893859,-0.16477436697628045
379.00000000000466,43.5651666648973,0.5850259700161778,-0.1660995757491488
379.8000000000047,43.64221051252218,0.5782553212412934,-0.16745465921699498
380.6000000000047,43.718781323964556,0.5764186129616967,-0.16871721387827998
381.4000000000047,43.7970746133617,0.5751383258831223,-0.17004994479622093
382.2000000000047,43.87437584867089,0.572103004391773,-0.16870135433087619
383.0000000000047,43.95131536547076,0.5671402968969732,-0.17138417772502335
383.80000000000473,44.03044930585057,0.5634124621689561,-0.1713705719819174
384.60000000000474,44.106216992071836,0.5642511597810442,-0.17268867173502045
385.40000000000475,44.18545625788865,0.5617507418647926,-0.17269181918966447
386.20000000000476,44.26016893358137,0.5606744747254458,-0.17408138572344223
387.0000000000048,44.3400175679943,0.5615879343522481,-0.17436640108453672
387.8000000000048,44.4165428019103,0.5601842868645426,-0.1743300175404756
388.6000000000048,44.49462424339298,0.5591601426658914,-0.174320386485046
389.4000000000048,44.57282583833221,0.5582675855684593,-0.17685228155779953
390.2000000000048,44.65052232204408,0.5590148317840768,-0.17828313876094803
391.00000000000483,44.7278163444766,0.5583710119912392,-0.17982952968858967
391.80000000000484,44.80651512939717,0.557317009811623,-0.18091950450809868
392.60000000000485,44.881132659235874,0.5574440406149457,-0.18059587476659855
393.40000000000487,44.96173516943602,0.5565728924654352,-0.180600628812158
394.2000000000049,45.03897671135363,0.5562524078797118,-0.1812508438681193
395.0000000000049,45.1167206291149,0.5563331393325275,-0.1812495141097612
395.8000000000049,45.194232627193124,0.5558920041033616,-0.18265663812817223
396.6000000000049,45.27164231373443,0.555734737439711,-0.1825698069418107
397.4000000000049,45.350799559458586,0.5542088705300169,-0.1825677960176142
398.20000000000493,45.42782889158131,0.5534479746110825,-0.183880218530875
399.00000000000495,45.505719323315766,0.5527113243164745,-0.18491174362711282
399.80000000000496,45.58377966673063,0.5525066302436548,-0.1851998515566864
400.60000000000497,45.661868301959046,0.5522331512225626,-0.18648201354827476
401.400000000005,45.73888060427127,0.5539762117808282,-0.18783806890537535
402.200000000005,45.81744195437591,0.554155510976835,-0.189113251867429
403.000000000005,45.895395047377804,0.5542352185711361,-0.1918204153630243
403.800000000005,45.973210236594866,0.5542583652681468,-0.19277826388937402
404.600000000005,46.05049083699091,0.5533821061792416,-0.1940904125653442
405.40000000000504,46.1298820290291,0.5510146598551023,-0.19409374810727664
406.20000000000505,46.20660263023929,0.5507716184569833,-0.196534942718682
407.00000000000506,46.284260782069495,0.5510645616070936,-0.19810836081274008
407.80000000000507,46.36272006121532,0.5506198126254336,-0.19937872175865934
408.6000000000051,46.44023519446748,0.5511153478441588,-0.20067779210675285
409.4000000000051,46.516291183687215,0.5534856630612739,-0.20248769544870004
410.2000000000051,46.595909449845095,0.5540475012966698,-0.20622695979634997
411.0000000000051,46.674098510574304,0.5527232455572818,-0.2063324118060592
411.8000000000051,46.752144597492006,0.5474283808536571,-0.20902954751176317
412.60000000000514,46.82985408902519,0.5463804369798207,-0.21105631963928273
413.40000000000515,46.90727453493717,0.5496056891301804,-0.213007805159092
414.20000000000516,46.982415561254776,0.5510936325708802,-0.21432106838092757
415.0000000000052,47.063670390262,0.5515542486231406,-0.21709649004877196
415.8000000000052,47.14043396456001,0.5540723555338725,-0.21878982627642607
416.6000000000052,47.21955821059208,0.5543365735507426,-0.21966750208396402
417.4000000000052,47.29717803107536,0.5582482080943579,-0.22127354311867498
418.2000000000052,47.374668112989895,0.5609917722695443,-0.22375337820453467
419.00000000000523,47.452784678923884,0.5647382747992628,-0.22790317103185975
419.80000000000524,47.53050581251155,0.5668900678105245,-0.22947390734313533
420.60000000000525,47.6088081610333,0.5695167331249062,-0.23219403726364796
421.40000000000526,47.68682850077181,0.5719470920122833,-0.23509187766243222
422.2000000000053,47.76430516417825,0.5744013294635616,-0.23848810035263668
423.0000000000053,47.842441782996254,0.5773631634624019,-0.24195530050555547
423.8000000000053,47.92002902665291,0.5810364140759039,-0.24718519433430242
424.6000000000053,47.99906433509133,0.585058830412141,-0.2513907479591322
425.4000000000053,48.076788468779505,0.5880678045356484,-0.2535721377671969
426.20000000000533,48.155791691062376,0.589432886256713,-0.25787097180670804
427.00000000000534,48.232751403271166,0.5959246975577583,-0.26247646034653815
427.80000000000535,48.31146898735752,0.5995768310611047,-0.2673761778826016
428.60000000000537,48.387831648067554,0.6051703383992787,-0.2699344877281984
429.4000000000054,48.466805955829045,0.6089667242702149,-0.27404240056551554
430.2000000000054,48.5428704934761,0.6124931197662454,-0.27993595625187506
431.0000000000054,48.62199697695306,0.618991131691551,-0.2846366020936726
431.8000000000054,48.701741161727675,0.6242698254464372,-0.29229332210809567
432.6000000000054,48.77985038625614,0.6286059158042882,-0.29802446905459856
433.40000000000543,48.856893484518594,0.6336217680470021,-0.304209993283711
434.20000000000545,48.936406520930255,0.6392149681943021,-0.31000742631039513
435.00000000000546,49.013780907234946,0.6460691882436548,-0.31799018154933334
435.80000000000547,49.09306934650826,0.6513139879693844,-0.32390941800235185
436.6000000000055,49.17045888617032,0.6577511199294125,-0.3317361082338244
437.4000000000055,49.24972083230733,0.665534526493017,-0.3394873649238992
438.2000000000055,49.326698680007446,0.6701804858607608,-0.348854156352298
439.0000000000055,49.40570336625916,0.6770662947424428,-0.356983621592986
439.8000000000055,49.48389880959586,0.6848147468525719,-0.3669768776039555
440.60000000000554,49.56147493477316,0.6919986398767299,-0.3769076933804545
441.40000000000555,49.640114942130495,0.7000698862900383,-0.38720521643486094
442.20000000000556,49.71816821610838,0.7073816676562258,-0.3979689362715919
443.00000000000557,49.79639196962236,0.7183593076455779,-0.4077041944522253
443.8000000000056,49.87462588296105,0.7287927862253867,-0.4197209376547919
444.6000000000056,49.953372096997526,0.7382242075233303,-0.43276383608955404
445.4000000000056,50.031064169272526,0.7486580127655798,-0.44612122763397855
446.2000000000056,50.10962871424242,0.7609644436235913,-0.46017446160233577
447.0000000000056,50.188158869909834,0.7742418033050177,-0.47538283973220263
447.80000000000564,50.267076899959676,0.7901219188051075,-0.48964225551876206
448.60000000000565,50.34454173532543,0.8025284060480995,-0.507211291378638
449.40000000000566,50.42357686337781,0.8184213370937318,-0.5256734398201623
450.2000000000057,50.501579710025396,0.8342733802216,-0.5431967814713596
451.0000000000057,50.580167436469,0.8522266036305898,-0.5617180101058725
451.8000000000057,50.658605925251514,0.8705757668213434,-0.581229887491189
452.6000000000057,50.737174922634196,0.8903064257492428,-0.60466173641331
453.4000000000057,50.81596078306205,0.9124309540009103,-0.6259608452148395
454.20000000000573,50.89410479236757,0.9366256759202194,-0.6486134544160427
455.00000000000574,50.9714810887581,0.9607982967752053,-0.6755809174275482
455.80000000000575,51.05091091707499,0.9882383896636372,-0.7018581377707482
456.60000000000576,51.131049598611504,1.0192420648695646,-0.7321989222585321
457.4000000000058,51.208680912096554,1.046337696706899,-0.7631302753178
458.2000000000058,51.28780347239238,1.0730937496996404,-0.796285389661223
459.0000000000058,51.36569930614991,1.1009429559665085,-0.8287388184590108
459.8000000000058,51.44447377556384,1.1276151209772154,-0.8652701176050539
460.6000000000058,51.523231002979706,1.1535861184388285,-0.9027579478187575
461.40000000000583,51.60203729253126,1.1889930278148828,-0.9417470533734065
462.20000000000584,51.68115271427828,1.2193602055334516,-0.9833269824825184
463.00000000000585,51.760087279639905,1.249758042429094,-1.028323113035904
463.80000000000587,51.83609554652805,1.2771755099814301,-1.071434188271326
464.6000000000059,51.91791167205653,1.3101906744357121,-1.1214935399382657
465.4000000000059,51.996744361559585,1.342989009937216,-1.1712168167485077
466.2000000000059,52.074545172393115,1.3742947557956213,-1.22510849653069
467.0000000000059,52.153545609472985,1.408226184339199,-1.2806714191102762
467.8000000000059,52.23169470992554,1.4394432108108914,-1.3371918075117608
468.60000000000593,52.3110434680574,1.4742763622609707,-1.3975019219350004
469.40000000000595,52.39006721384436,1.5022295100970189,-1.4599624711949257
470.20000000000596,52.46843851762224,1.5316445916970896,-1.5242342596984297
471.00000000000597,52.54593791238178,1.5551556232650974,-1.5897017671387816
471.800000000006,52.624897213099594,1.5807735994196608,-1.6600200438928563
472.600000000006,52.70358946916754,1.6051068984447636,-1.733108146082781
473.400000000006,52.78252510366467,1.628889293954115,-1.8077556731785647
474.200000000006,52.86214076644973,1.6460123641763427,-1.88584472838025
475.000000000006,52.940953309830626,1.6631724210399237,-1.9653262526226025
475.80000000000604,53.01908083759808,1.676776980928571,-2.045365737808673
476.60000000000605,53.09835646143725,1.684762357489669,-2.1292132525426997
477.40000000000606,53.176453954298395,1.68966819788261,-2.211062932653098
478.20000000000607,53.25589241440295,1.6880054275094916,-2.2975399957141076
479.0000000000061,53.33437851774403,1.6813741477910835,-2.3859077765386463
479.8000000000061,53.41318634398904,1.6689292819074315,-2.473992438942748
480.6000000000061,53.492635271973526,1.656222937902742,-2.5645844496614916
481.4000000000061,53.57035326808039,1.6343959511548203,-2.652993768196137
482.2000000000061,53.64971015901189,1.610022546073104,-2.743075972722784
483.00000000000614,53.72716725189422,1.5745115842005917,-2.8306417078788693
483.80000000000615,53.80588181993514,1.5331432112125616,-2.9180382641811144
484.60000000000616,53.88496180750638,1.4851031489184265,-3.0057525463170967
485.4000000000062,53.963479764728184,1.4309062144767626,-3.088877410787286
486.2000000000062,54.03983662903956,1.371398152162948,-3.1699057846395533
487.0000000000062,54.12050125633085,1.302084795036352,-3.2497913221013146
487.8000000000062,54.19866684632598,1.232032044359224,-3.3240763156974054
488.6000000000062,54.27682998931261,1.1536445598052332,-3.3935018929427696
489.40000000000623,54.355839144254816,1.0699963379290813,-3.4624208178454827
490.20000000000624,54.43336181760343,0.9892419245301928,-3.5245603340403178
491.00000000000625,54.511787636731384,0.9040994344981433,-3.5813408503949415
491.80000000000626,54.59003954954242,0.817944785314543,-3.634420013291858
492.6000000000063,54.66775563053841,0.7375380157424684,-3.678886314685759
493.4000000000063,54.74691567097799,0.6566424651263676,-3.7192521822263473
494.2000000000063,54.824850440774334,0.5820109289389434,-3.755719862374
495.0000000000063,54.90384063986315,0.5147350343451906,-3.7856064357017023
495.8000000000063,54.98177341370639,0.453192712713469,-3.813038724477377
496.60000000000633,55.06020607223998,0.39766712893741224,-3.8358259670557127
497.40000000000634,55.139078072880935,0.34671928136673286,-3.8565341247237286
498.20000000000636,55.21574858789662,0.29800685924712256,-3.871428551880569
499.00000000000637,55.295119461427674,0.2559570883836059,-3.883015568173845
499.8000000000064,55.37412904081202,0.21921040298400696,-3.8932658322441007
500.6000000000064,55.45223748787472,0.18834554530643777,-3.9010135764067213
501.4000000000064,55.52982498979785,0.16144108325932655,-3.9078909973620575
502.2000000000064,55.609260399258304,0.1395630422335829,-3.9112348307285036
503.0000000000064,55.68798131200091,0.12065988440152353,-3.916305863929441
503.80000000000643,55.76647084943095,0.10741852260639939,-3.919333734816045
504.60000000000645,55.844431123149036,0.09829858179857015,-3.9190900282636845
505.40000000000646,55.92348783593538,0.09167121330187644,-3.9204185345805445
506.20000000000647,56.00262604457135,0.08667808890926704,-3.922944787453547
507.0000000000065,56.08088023841336,0.08415534069921221,-3.923084495144703
507.8000000000065,56.15925413515166,0.08689248613400663,-3.9211339092232373
508.6000000000065,56.237731117032475,0.08651448030135683,-3.9211200980362357
509.4000000000065,56.3169855646059,0.08842651938109491,-3.921120342067143
510.2000000000065,56.39597403259297,0.08526520208097715,-3.9221131622071095
511.00000000000654,56.474557775602904,0.0837675102461477,-3.9224249845307213
511.80000000000655,56.554161781203675,0.08289582247845739,-3.9224802396391913
512.6000000000065,56.63252903671975,0.0800056352914637,-3.9238555880911967
513.4000000000066,56.71064495524376,0.07966013433080138,-3.924738729071017
514.2000000000066,56.79148154543234,0.07546677308562816,-3.9245669103805665
515.0000000000066,56.87000353326581,0.07437840658678024,-3.9227699963226708
515.8000000000065,56.950177449684396,0.07276106712073649,-3.9227699091352326
516.6000000000066,57.026760797180785,0.07326217543706692,-3.9227594855375423
517.4000000000067,57.10680756832757,0.0719400122353232,-3.924079771100077
518.2000000000066,57.18680013194796,0.07027175125569424,-3.9240798259985286
519.0000000000066,57.26366887187484,0.07078313217115939,-3.924079826
519.8000000000067,57.345494953915974,0.06961756987155987,-3.9240798259880965
520.6000000000067,57.423974828013854,0.06687039041088355,-3.924079471141977
521.4000000000067,57.50365016742209,0.06782135639527626,-3.9234178532594988
522.2000000000066,57.58216995741809,0.06752108317833322,-3.923419825951356
523.0000000000067,57.658751560001576,0.0658520274667092,-3.923419826035373
523.8000000000068,57.740697352599256,0.06343735031563874,-3.9234119676599755
524.6000000000067,57.8201283373742,0.061585556688789456,-3.9221099677987383
525.4000000000067,57.897827132086015,0.06384992894475372,-3.9210175027120537
526.2000000000068,57.97722972553602,0.06400511218705834,-3.922099842276089
527.0000000000068,58.057333980371034,0.0625080142761284,-3.9221014075643
527.8000000000068,58.13446424499966,0.05887264791140151,-3.9227520790885504
528.6000000000067,58.21651529165692,0.05919192540272178,-3.924738767324245
529.4000000000068,58.29525019627586,0.05878928482504531,-3.924739686701716
530.2000000000069,58.375139755065526,0.055563193701797464,-3.924410787824401
531.0000000000068,58.4541011017137,0.05504369037784346,-3.924410135868036
531.8000000000068,58.53324131026461,0.053612203088261645,-3.923415514694192
532.6000000000068,58.61262971512363,0.05236897789490813,-3.9234201170120184
533.4000000000069,58.69260391904693,0.04889768871021227,-3.9234200632856475
534.2000000000069,58.770269256083246,0.048478020379696396,-3.924392785538908
535.0000000000068,58.84959176390265,0.047128480954716556,-3.925727905420161
535.8000000000069,58.930024601990574,0.04443398027763634,-3.9230949799634445
536.600000000007,59.00662687652981,0.04022623535756831,-3.9230901433836207
537.4000000000069,59.088037046664155,0.04037861460165515,-3.9230901305418415
538.2000000000069,59.167776483919916,0.037609760390606595,-3.9233494964140503
539.0000000000069,59.24593576656062,0.03655580792695046,-3.9230900425365833
539.800000000007,59.326617874606214,0.03459224565472441,-3.9230900360001315
540.600000000007,59.4052819522989,0.034679020357701096,-3.9230900360000125
541.4000000000069,59.484559234411094,0.03277470540246252,-3.92309003639925
542.200000000007,59.56375800592849,0.03237947177669631,-3.923104495370925
543.000000000007,59.64298814705415,0.03370019678524394,-3.925070355032423
543.800000000007,59.72252303257095,0.03244517833552407,-3.9250699653290244
544.600000000007,59.80104040599156,0.03246536454260762,-3.9242504977443007
545.400000000007,59.879804139051195,0.031757861496992,-3.9237517950878646
546.000000000007,59.93936198820362,0.030386384818746892,-3.9247391690702558