File: 01_Data/PE_Foam_Pipe_Insulation/STA/N2/10K_min/PE_Foam_Pipe_Insulation_STA_N2_10KData_220923_R2.csv
##Temp./Â°C,Time/min,DSC/(mW/mg),Mass loss/mg
51.0,10.76300835701429,0.019718242926494822,-0.04005346346238081
51.80000000000001,11.054620833745252,0.08414889998625119,-0.037201943093642775
52.60000000000002,11.261730963361758,0.13177067928199127,-0.034083391216891634
53.400000000000034,11.427463565451498,0.1658316887463429,-0.036413129912201025
54.200000000000045,11.576822923752493,0.19615356140633167,-0.03412114147788303
55.00000000000006,11.716565212331108,0.22611753971863613,-0.03533949206806186
55.80000000000007,11.845714725186903,0.25032551737900355,-0.03303977689669457
56.60000000000008,11.96749971200267,0.271154892602951,-0.03488097098405163
57.40000000000009,12.085591559041465,0.29218031259495425,-0.03711143127854788
58.2000000000001,12.201081358992658,0.3070281436810065,-0.03579494634678815
59.000000000000114,12.310555596051413,0.32555185836575085,-0.03525314673598556
59.800000000000125,12.424680855243105,0.3396245121504935,-0.033916858508194814
60.600000000000136,12.529292799276956,0.34936386653930884,-0.035159269322448505
61.40000000000015,12.634880455876461,0.35501018997696554,-0.03586600427182729
62.20000000000016,12.734768524948807,0.3606219538187274,-0.03664877579405701
63.00000000000017,12.837371608329306,0.3645490305180613,-0.036283634321738756
63.80000000000018,12.938894286477565,0.36592767873732424,-0.03507780272555916
64.6000000000002,13.038549063828725,0.3698919160562121,-0.036244454275756954
65.4000000000002,13.135779318804897,0.3723835906285444,-0.03603054797033689
66.20000000000022,13.232717140569632,0.37723361080841766,-0.036195893843350646
67.00000000000023,13.328961740195757,0.37845909289610147,-0.03773828847548577
67.80000000000024,13.423927669368618,0.38630080086433716,-0.036603569312367856
68.60000000000025,13.516270132711842,0.3903879334510434,-0.037694822809682726
69.40000000000026,13.612256473982374,0.39566644722236977,-0.03665061680773585
70.20000000000027,13.704576151632285,0.40068685702618034,-0.03641500076194859
71.00000000000028,13.79409030171328,0.4055778520879143,-0.036524467788710435
71.8000000000003,13.888701068653349,0.4150919409046723,-0.03666640500790619
72.6000000000003,13.979123107942055,0.41870389510515105,-0.03666022198742347
73.40000000000032,14.069772502204707,0.42740893705704375,-0.03703972662340016
74.20000000000033,14.159008539279673,0.4355642186836993,-0.03817946496210256
75.00000000000034,14.248138662568328,0.4416885055563522,-0.037972699512850205
75.80000000000035,14.337415557201078,0.45041419956568396,-0.03935233648904779
76.60000000000036,14.426352622815086,0.45820766751343955,-0.03937445474651069
77.40000000000038,14.513454019784445,0.46582906649080424,-0.037877902332187574
78.20000000000039,14.600720988294741,0.47319693385929074,-0.037936338170048156
79.0000000000004,14.686425507546007,0.4824239872591234,-0.038741407937996186
79.80000000000041,14.774298037903872,0.49036130650856113,-0.039413970194903225
80.60000000000042,14.860642004261088,0.49781963572040033,-0.04062101422830722
81.40000000000043,14.945546958722337,0.507351760879994,-0.03952852578599009
82.20000000000044,15.032814496064452,0.5153400677400751,-0.040419008068567575
83.00000000000045,15.114852807670461,0.526777283543686,-0.04065604501633535
83.80000000000047,15.201358162680705,0.533176796875173,-0.03931743891945816
84.60000000000048,15.285258001512808,0.5450762826016532,-0.03917202024997879
85.40000000000049,15.370000000000049,0.5537953191526728,-0.04073682383078614
86.2000000000005,15.453395712082354,0.5627903931291376,-0.04074409683456137
87.00000000000051,15.536386887756661,0.5743752144912814,-0.041113439914395755
87.80000000000052,15.620301627094383,0.5818550473845282,-0.04131081357494182
88.60000000000053,15.703369645784866,0.5905288077497902,-0.040062420288386136
89.40000000000055,15.783342877747055,0.5995442814013557,-0.039409502633537485
90.20000000000056,15.866988441098691,0.6121188720788926,-0.0394055574037071
91.00000000000057,15.948727910675391,0.6246482776449408,-0.04161531133924168
91.80000000000058,16.031217549012503,0.6342825553964567,-0.04196566374848976
92.60000000000059,16.112704755540207,0.6483230590525126,-0.04199698469882396
93.4000000000006,16.193453964245222,0.6649206070189186,-0.04205115919653579
94.20000000000061,16.274910026787357,0.681168105842469,-0.04197584774604568
95.00000000000063,16.356504286106098,0.6939969649164088,-0.04344215434311938
95.80000000000064,16.437278579209252,0.7102707877996397,-0.04203977400319481
96.60000000000065,16.518885843349423,0.7252297083078054,-0.042019965962139416
97.40000000000066,16.598696081905516,0.7398851460408646,-0.04203956253127128
98.20000000000067,16.678856915840722,0.7499423850927397,-0.04205344324379423
99.00000000000068,16.757842121770498,0.7545801002715832,-0.04315975094675073
99.8000000000007,16.838872316730946,0.762487808087335,-0.04212717724857784
100.6000000000007,16.91923401976206,0.7734425233635498,-0.04346948419718011
101.40000000000072,16.998450382228857,0.7882811425304128,-0.04478901192711371
102.20000000000073,17.076586021311908,0.80922835541536,-0.04486994552750767
103.00000000000074,17.15708785391634,0.831176201203983,-0.044789095966129455
103.80000000000075,17.235420283842906,0.8602612294932882,-0.044906403491597136
104.60000000000076,17.315214387519113,0.891403122245825,-0.04470307420866648
105.40000000000077,17.394898902969643,0.9254464234443012,-0.04479104096565001
106.20000000000078,17.470535823961725,0.9636898443087781,-0.04346976548687653
107.0000000000008,17.552445613832514,1.0051276520608794,-0.04295680492267717
107.80000000000081,17.63177459235163,1.0501826747015353,-0.04307661403445051
108.60000000000082,17.7116032308238,1.1073160919016456,-0.041771666087006665
109.40000000000083,17.790974686195437,1.167773879320155,-0.04273118294931422
110.20000000000084,17.870673012126897,1.2346991951053492,-0.04313885696738673
111.00000000000085,17.949017562640666,1.309923530336119,-0.04411573105439315
111.80000000000086,18.029360159796518,1.3936934549025348,-0.04615508124006462
112.60000000000088,18.107632851783393,1.480916262398478,-0.045961221432667454
113.40000000000089,18.186255782555747,1.5582841485270016,-0.04750398790027699
114.2000000000009,18.266010213517216,1.613744155877163,-0.04709968451375124
115.00000000000091,18.34582926332308,1.599009350568361,-0.04582266413175251
115.80000000000092,18.42225741002028,1.450036450232048,-0.04577994843515132
116.60000000000093,18.50122207491286,1.148677354788827,-0.04380311612128507
117.40000000000094,18.57901428048066,0.9042571731244136,-0.045153570939652
118.20000000000095,18.65501437902455,0.742322219679761,-0.04511974756917647
119.00000000000097,18.73276438899989,0.6372299752489277,-0.0433130514910367
119.80000000000098,18.80932927336224,0.5701222226009752,-0.04508126206388052
120.60000000000099,18.887865049012913,0.5254360575042145,-0.047551623798484766
121.400000000001,18.964062177634716,0.49772711828749866,-0.047530113925244866
122.20000000000101,19.040792296390205,0.48134989633010417,-0.047529823131228
123.00000000000102,19.117999100649165,0.46911716747699916,-0.047518216912701305
123.80000000000103,19.195132682729852,0.46178928182693724,-0.04752949149935137
124.60000000000105,19.27246363456854,0.4572999876599422,-0.04884347592164229
125.40000000000106,19.34937603383106,0.45272846410641454,-0.04884586595757945
126.20000000000107,19.427046309249846,0.4523314802816346,-0.04752542254236136
127.00000000000108,19.50358572426274,0.45209603327592374,-0.04852029757085097
127.80000000000109,19.580971592256386,0.45214950865357695,-0.047865005463384236
128.6000000000011,19.657116597006194,0.4513909226656553,-0.048850208514054305
129.4000000000011,19.733975653856042,0.4506498458172038,-0.0475220169089714
130.20000000000113,19.811780092150293,0.45154074024113766,-0.04753026060954291
131.00000000000114,19.888628767341434,0.4524139923305026,-0.04885721848060731
131.80000000000115,19.965991752949467,0.4524958178116292,-0.048849926657577036
132.60000000000116,20.043069704832806,0.4548967965299495,-0.049303911406236356
133.40000000000117,20.11945058584028,0.4552410511889915,-0.0505128309734455
134.20000000000118,20.196090074266014,0.45566844532130524,-0.0495394272536509
135.0000000000012,20.27222878422789,0.45903021806840966,-0.049523646692234635
135.8000000000012,20.34809353338304,0.45917386269917476,-0.04949914533407229
136.60000000000122,20.426975032634882,0.45899330170861885,-0.048189627859301254
137.40000000000123,20.502752079589598,0.4600767670847652,-0.048163303504438204
138.20000000000124,20.580176945794694,0.4609468728851413,-0.04951007824306686
139.00000000000125,20.657395408268368,0.46329615384189204,-0.04945701521732149
139.80000000000126,20.73435433111204,0.4651113930260964,-0.049250106578551556
140.60000000000127,20.809364630369874,0.46384274383908564,-0.048772808998284845
141.40000000000128,20.88584296840249,0.465841237993124,-0.049784860427839916
142.2000000000013,20.959536650304006,0.46583374842551184,-0.04958486531757034
143.0000000000013,21.03520479921101,0.46650415135825846,-0.05016559338119864
143.80000000000132,21.114535474658854,0.46834302133307265,-0.050588318032212864
144.60000000000133,21.190458375202276,0.4676865983355077,-0.05083003843768452
145.40000000000134,21.26670620223475,0.4672882618277957,-0.05078432600193228
146.20000000000135,21.342931866645213,0.46876581251604327,-0.050761450336050284
147.00000000000136,21.41838288234063,0.47144910024261527,-0.05214943842303965
147.80000000000138,21.494994716164204,0.46971616214481166,-0.050321853824655705
148.6000000000014,21.569128735354724,0.4712755132342949,-0.05016654307140156
149.4000000000014,21.64635894401667,0.47085150347583044,-0.05077986117599842
150.2000000000014,21.72316602455828,0.47083163352569035,-0.05189393056394609
151.00000000000142,21.799316742594947,0.4722647073176897,-0.05082016465392947
151.80000000000143,21.874159764871102,0.4744784337781373,-0.05076615312067956
152.60000000000144,21.95038681728104,0.4752679304927191,-0.0508290335254058
153.40000000000146,22.02692090555059,0.4780282386407589,-0.052158391708357676
154.20000000000147,22.103628115109625,0.47647748075944735,-0.05214996848042297
155.00000000000148,22.179073411054933,0.47626087275468515,-0.05083430506751396
155.8000000000015,22.254856064215577,0.4775777375337476,-0.05083017727949768
156.6000000000015,22.33080476000285,0.4777893774459538,-0.052109035165464945
157.4000000000015,22.40603543627468,0.47938946133768257,-0.052140184778084464
158.20000000000152,22.483166892386773,0.4810121791894912,-0.05212397675232516
159.00000000000153,22.55910938188891,0.482278563242729,-0.050861677977987796
159.80000000000155,22.63578178211017,0.48338706303332857,-0.05082094340645682
160.60000000000156,22.710831175541678,0.48406454734789334,-0.050817398646972656
161.40000000000157,22.787702596326053,0.4854384792242643,-0.0521400984210616
162.20000000000158,22.860359963322086,0.4856039842419199,-0.0521401522736733
163.0000000000016,22.939070220505634,0.48686687373862464,-0.050906130808948014
163.8000000000016,23.01447636315824,0.49007581673033673,-0.05215011843131512
164.60000000000161,23.09037879784143,0.4878822399899009,-0.05342938501750849
165.40000000000163,23.167531467624656,0.48723399225187136,-0.05411820364326436
166.20000000000164,23.242712185420086,0.4899771346222068,-0.053461749057092334
167.00000000000165,23.317816987317517,0.49179289794512426,-0.054782387085699824
167.80000000000166,23.39387531047497,0.4923972860776374,-0.054779564236181244
168.60000000000167,23.47144438081703,0.495804069283741,-0.05611130923406682
169.40000000000168,23.54631614372841,0.4943862021162464,-0.05580838447117875
170.2000000000017,23.622748227641143,0.4950681598255649,-0.05434708885442863
171.0000000000017,23.699187378530112,0.498335113778721,-0.05183825885517246
171.80000000000172,23.774270116976332,0.5004516760812194,-0.05116051918839526
172.60000000000173,23.849311654975246,0.4991103338541641,-0.0505143917687807
173.40000000000174,23.924716625476044,0.4999840792618597,-0.050767396411727006
174.20000000000175,24.00045793736937,0.4996975523584999,-0.05183449967203524
175.00000000000176,24.07808948608901,0.5010857305034031,-0.0546415559419553
175.80000000000177,24.15397889297532,0.5022977145634959,-0.05467013248379082
176.60000000000178,24.229798917814545,0.5023819933814041,-0.05534693759911846
177.4000000000018,24.306830260408507,0.5033621494060766,-0.054670121909988545
178.2000000000018,24.37930649989029,0.5037338973060693,-0.05347773698974123
179.00000000000182,24.45760133904894,0.5064469952926146,-0.05259529818851538
179.80000000000183,24.53344098231714,0.5053065983345659,-0.053827074520199414
180.60000000000184,24.608854899785385,0.5071690448456159,-0.05434495247284987
181.40000000000185,24.68510382951097,0.5074252623327846,-0.05433957944012047
182.20000000000186,24.76135784060347,0.5095578079246106,-0.05422184077743886
183.00000000000188,24.836776509981604,0.5084161704409096,-0.0556498124929794
183.8000000000019,24.911438686816137,0.5088305106877252,-0.055649816975162913
184.6000000000019,24.98910829700099,0.5073640790372819,-0.056884119848551684
185.4000000000019,25.064705988444587,0.5097649408976967,-0.055653915334984205
186.20000000000192,25.140519900573732,0.5097369862620912,-0.055659663263575965
187.00000000000193,25.216042848835265,0.5098031047449758,-0.056386375135032196
187.80000000000194,25.292244490962712,0.5116256756995056,-0.05795993466675142
188.60000000000196,25.368175438780604,0.5112411421512916,-0.05796018302180039
189.40000000000197,25.442037843327793,0.5111669349981556,-0.057960470599702774
190.20000000000198,25.518920146466023,0.5131697677878876,-0.05795084146094265
191.000000000002,25.59525036939137,0.5134197566158905,-0.057970029533573886
191.800000000002,25.6701886770236,0.512674473581951,-0.057970042374315245
192.600000000002,25.7467217786624,0.513884389202757,-0.05818345032309047
193.40000000000202,25.823026976850276,0.5137441814773501,-0.057900445207159645
194.20000000000203,25.89830627353464,0.5145606837673073,-0.059276731618396195
195.00000000000205,25.974502590550486,0.5158399679186594,-0.05928290889001042
195.80000000000206,26.047198569201154,0.517890091228205,-0.05927680768850152
196.60000000000207,26.125975307436512,0.515632408233961,-0.06040104122339596
197.40000000000208,26.201075848209996,0.5196087634335174,-0.0605998028731114
198.2000000000021,26.276778638537067,0.5185292212385433,-0.06059980200003601
199.0000000000021,26.352568260436808,0.5183906336056441,-0.06059980199834758
199.80000000000211,26.42962693382089,0.5176252791430143,-0.06059980896897876
200.60000000000213,26.503897370359137,0.5193441773877323,-0.05951748688134151
201.40000000000214,26.580200013029533,0.5212026291019932,-0.059279720316371964
202.20000000000215,26.656117104044515,0.5199191544523323,-0.059279959463193865
203.00000000000216,26.731315368236242,0.5202773047771921,-0.05791004590838433
203.80000000000217,26.806770504185916,0.5203323184608135,-0.059474178645253506
204.60000000000218,26.882708990969945,0.5224584750783151,-0.0608533837714913
205.4000000000022,26.958562305468163,0.5243373598544745,-0.06219084809186981
206.2000000000022,27.0347177501322,0.5236595366173369,-0.06389007950087677
207.00000000000222,27.109820153546117,0.5248588569555921,-0.06389041398838291
207.80000000000223,27.186335453948093,0.5257733402565765,-0.06322811800316863
208.60000000000224,27.262826159172047,0.5273624659492919,-0.06323035191310744
209.40000000000225,27.3375488903371,0.5268554386871376,-0.06422314823538855
210.20000000000226,27.413718650001456,0.5273918210975563,-0.06429378001129127
211.00000000000227,27.490182282687826,0.5300485943377046,-0.06355966044568717
211.80000000000229,27.565456253280733,0.5293054358596891,-0.06488146671326955
212.6000000000023,27.641548675158486,0.5298248945514128,-0.06718232363209387
213.4000000000023,27.71644002297581,0.5307896788908408,-0.06850488176004621
214.20000000000232,27.79265690352941,0.5311464271433356,-0.0684854399835384
215.00000000000233,27.869737478904455,0.5330677344632027,-0.06721290604522068
215.80000000000234,27.944920043883798,0.5327072569454254,-0.06586999878642796
216.60000000000235,28.018691451395668,0.5329832346386956,-0.06588938200767736
217.40000000000236,28.096661346208624,0.5347319268401467,-0.06653003830940696
218.20000000000238,28.172248038075626,0.5349165141117541,-0.06719831431931889
219.0000000000024,28.24948276487218,0.5363830482259728,-0.06723271597155156
219.8000000000024,28.3232514038666,0.5347877321880802,-0.06847316438659012
220.6000000000024,28.399719372993143,0.5365717130504992,-0.06883020843577459
221.40000000000242,28.47553596017249,0.5383699250327365,-0.06981931512511563
222.20000000000243,28.551101296994904,0.537863427873762,-0.07014188011324762
223.00000000000244,28.625029007879373,0.5389225320863206,-0.0715606468019061
223.80000000000246,28.703396448541444,0.5395603237489747,-0.07280884794825138
224.60000000000247,28.778965399564544,0.5400878365123711,-0.07133690762587008
225.40000000000248,28.855097101513646,0.5420573202637322,-0.07047939800338465
226.2000000000025,28.93092928293438,0.5423265390820339,-0.0717981912315806
227.0000000000025,29.00711044831937,0.5420723407925484,-0.0744211278280158
227.8000000000025,29.08309380746558,0.5414259419571525,-0.07571935129377216
228.60000000000252,29.159360748356008,0.5422930303389081,-0.07706065938086715
229.40000000000254,29.2344115532123,0.5416684207126479,-0.07574734872863509
230.20000000000255,29.31210624971652,0.5437473251304791,-0.07574986867857803
231.00000000000256,29.38659411100084,0.5442868457881523,-0.07703666380794694
231.80000000000257,29.46314811193486,0.5444974790816844,-0.07706000923272871
232.60000000000258,29.53999906674067,0.5449101246156907,-0.0770702835682675
233.4000000000026,29.615228011152475,0.5459872271843355,-0.0783544919843342
234.2000000000026,29.692427709836704,0.5453657538480849,-0.07937003493039807
235.00000000000261,29.767510448074052,0.5447623145787149,-0.07969506407455906
235.80000000000263,29.844030231235195,0.5458139204923531,-0.07969978618016249
236.60000000000264,29.920667619665306,0.5457820787446246,-0.08211067348314494
237.40000000000265,29.995076629569013,0.5476684687115414,-0.08200904745493842
238.20000000000266,30.071988581848583,0.5472413219566302,-0.08503857928938485
239.00000000000267,30.1481520142621,0.5484388680463506,-0.08496981266337666
239.80000000000268,30.224417082112918,0.5505966421036039,-0.08496957776737979
240.6000000000027,30.299890625753573,0.5497421459258544,-0.08629066498492177
241.4000000000027,30.37633895607595,0.551117895146076,-0.08629003997310303
242.20000000000272,30.45210179614218,0.5516098091124769,-0.08629950586569946
243.00000000000273,30.528514832422335,0.5508111606367578,-0.08660978446518852
243.80000000000274,30.604072663226976,0.5522293524842499,-0.0886548802929128
244.60000000000275,30.68009636418642,0.5529814429315025,-0.08891999771272108
245.40000000000276,30.755665481378035,0.554350759968898,-0.09058243623744167
246.20000000000277,30.831544927908595,0.5534737096138528,-0.09264616280882354
247.00000000000279,30.907995882082332,0.5550219728347843,-0.09286984368245221
247.8000000000028,30.98487515523948,0.5528244489431499,-0.09286935627911097
248.6000000000028,31.059251500120972,0.554706023658914,-0.09512282237881431
249.40000000000282,31.136742468096713,0.5521250203366422,-0.09469716220452051
250.20000000000283,31.212589467086264,0.5524646720371102,-0.0944251382998802
251.00000000000284,31.289377871175173,0.5533916121464956,-0.09682878759094171
251.80000000000285,31.364261163723416,0.5541155051227742,-0.09815307512016735
252.60000000000286,31.44084549496319,0.5552348298544346,-0.09947903538355174
253.40000000000288,31.516573972283854,0.5569713126793533,-0.09946006800659557
254.2000000000029,31.592740922908,0.55631709804568,-0.1009091404601472
255.0000000000029,31.669895749991372,0.555837768293553,-0.10077816008581486
255.8000000000029,31.744869015857187,0.5544669139072015,-0.10177019245481489
256.6000000000029,31.821312505574067,0.5561553931656273,-0.10286670544858945
257.40000000000293,31.89619358491692,0.5568208869545973,-0.10275009716753969
258.20000000000294,31.97330834768385,0.5563821122791364,-0.1040882263721179
259.00000000000296,32.048197993475334,0.5580284681412864,-0.10538993378062678
259.80000000000297,32.12552612424762,0.5569650590628459,-0.10677797013978552
260.600000000003,32.20085247778682,0.5582914733790398,-0.10802191473963196
261.400000000003,32.2772187155336,0.556972641273361,-0.10801755298629345
262.200000000003,32.353129821755964,0.5608207987744164,-0.1106586497608002
263.000000000003,32.42904564116931,0.5620176992223691,-0.11066024448929568
263.800000000003,32.50578277086824,0.5604257341145414,-0.11199735722050352
264.60000000000304,32.58038213819208,0.5615222020898059,-0.11198001410336023
265.40000000000305,32.656916823789,0.561388766004399,-0.11198001395063661
266.20000000000306,32.733308886778836,0.5614321794007138,-0.11198329632100279
267.00000000000307,32.81009187853797,0.5616237153404261,-0.1146101654054199
267.8000000000031,32.88505111698234,0.5621156510633022,-0.11593105024259653
268.6000000000031,32.9612437314564,0.5624387625363835,-0.1159300264723524
269.4000000000031,33.03828680191908,0.5618919159584226,-0.1185698670176718
270.2000000000031,33.11311423900644,0.5615421944569334,-0.1185589730188279
271.0000000000031,33.189684285334245,0.5639390953384799,-0.1198803213219568
271.80000000000314,33.267595500801455,0.5628841053917593,-0.12086653824569993
272.60000000000315,33.34320964252933,0.5635396179399487,-0.12118167937765101
273.40000000000316,33.41775169194437,0.5633865016696747,-0.12249991216625622
274.2000000000032,33.494838651809175,0.5631664415781547,-0.12380258510668884
275.0000000000032,33.57150576695869,0.5655050328181228,-0.1251502263662223
275.8000000000032,33.64745098110751,0.5662951809923823,-0.12389996949709614
276.6000000000032,33.72384694325173,0.5660819826677842,-0.12504274353091027
277.4000000000032,33.79959012850728,0.5658264208015418,-0.12646976559598544
278.20000000000323,33.87607679518767,0.5659102385326493,-0.12778998240255746
279.00000000000324,33.951806004503254,0.5647738948148557,-0.12779007599775882
279.80000000000325,34.029106129702924,0.5651991955422814,-0.12779007544899956
280.60000000000326,34.1029643531741,0.5668260221252586,-0.1277554018431375
281.4000000000033,34.17870417192807,0.566703050978769,-0.12910804885488192
282.2000000000033,34.25616538516941,0.5676917947671403,-0.1290992150020127
283.0000000000033,34.3340105668137,0.5665639999473626,-0.12911054212730777
283.8000000000033,34.41000097402709,0.5666961384176844,-0.13174200737572495
284.6000000000033,34.48649982470539,0.5662971853179011,-0.13309945780620902
285.40000000000333,34.56255720804597,0.5667655842144277,-0.13306009457505574
286.20000000000334,34.6393336962028,0.5664918399797114,-0.13386221888952443
287.00000000000335,34.715412243578946,0.5671689474423476,-0.1336118332609071
287.80000000000337,34.79124516154841,0.568467505624962,-0.13451699718662047
288.6000000000034,34.86862180149624,0.5652795994054354,-0.13568333044107872
289.4000000000034,34.94484404594032,0.5668587636026742,-0.13699977515922912
290.2000000000034,35.0207132960033,0.5664848729137649,-0.13804646222183292
291.0000000000034,35.09794352179305,0.568480038991079,-0.13860646820135614
291.8000000000034,35.17400675514253,0.5694061396211499,-0.1389800899423741
292.60000000000343,35.25135573977176,0.5683053197242655,-0.13922739426480835
293.40000000000344,35.32716196304866,0.5690961463257576,-0.14062999680033927
294.20000000000346,35.40362977485325,0.5684722636668293,-0.14062985300665787
295.00000000000347,35.480655736281456,0.5682631867899207,-0.14062985300001163
295.8000000000035,35.55614690479238,0.5672054777045257,-0.14062985195595612
296.6000000000035,35.63210565843988,0.5687484222863131,-0.1406126167499373
297.4000000000035,35.709051952722696,0.5682517308350025,-0.14228516868830354
298.2000000000035,35.78628026001033,0.5664322751978644,-0.14227006344279758
299.0000000000035,35.862310829777634,0.569076628280114,-0.14224887118359497
299.80000000000354,35.93916270329852,0.5697124463287496,-0.14358992345955368
300.60000000000355,36.014856827839715,0.5672153989431165,-0.14358905382648945
301.40000000000356,36.09167100514826,0.5675655456273337,-0.14490888882455266
302.20000000000357,36.16691329894837,0.5680225004726916,-0.14491011613076576
303.0000000000036,36.24490656982524,0.5714999865138698,-0.1449101160625501
303.8000000000036,36.322036483227954,0.5716300202047027,-0.14491097044321943
304.6000000000036,36.39876238437325,0.5732447449915661,-0.14458019580057346
305.4000000000036,36.47422642329443,0.573954250385143,-0.14458126110535874
306.2000000000036,36.551422178091954,0.5732539069567857,-0.1471141711286741
307.00000000000364,36.62659564438755,0.5763975054551035,-0.14722008518625707
307.80000000000365,36.704499861079,0.5764004890133388,-0.14986486934936494
308.60000000000366,36.781720329616,0.5762803498593291,-0.14987089120243358
309.4000000000037,36.85808441340401,0.5781141255087384,-0.14854020502146303
310.2000000000037,36.934167080973545,0.5781723540020003,-0.14854018278463244
311.0000000000037,37.01105187075933,0.5778874787718429,-0.14987438458920854
311.8000000000037,37.0876127523642,0.5791012274411358,-0.14980910756241705
312.6000000000037,37.163922744056734,0.5802725129833364,-0.15050310698653924
313.40000000000373,37.24099395983436,0.5828716814032029,-0.15216139774630788
314.20000000000374,37.31746501975205,0.5826361292029252,-0.1533758259213429
315.00000000000375,37.392280012836196,0.5886775191715107,-0.15347002951201416
315.80000000000376,37.470000909496015,0.5922313384977899,-0.15446411211481959
316.6000000000038,37.54701625999464,0.5942195600909461,-0.15487932342215194
317.4000000000038,37.623542255836185,0.5941835143142908,-0.1551197912467508
318.2000000000038,37.6999990596362,0.5958910401619735,-0.15511993786283806
319.0000000000038,37.77615101329716,0.5982725618994928,-0.1549310404895503
319.8000000000038,37.853648662569626,0.5971268800404969,-0.15513058628583654
320.60000000000383,37.92999903502172,0.6007884103828899,-0.15643978706005424
321.40000000000384,38.005820880710445,0.6014909875489864,-0.15775817104517031
322.20000000000385,38.082282009674394,0.6034251894062377,-0.15777472398016013
323.00000000000387,38.160099123253254,0.6060618092394496,-0.1590697990533978
323.8000000000039,38.23644768112903,0.6077323315009876,-0.15800997926643312
324.6000000000039,38.312714892890334,0.6087761689314602,-0.15940040669886013
325.4000000000039,38.39059227660573,0.6086575321603664,-0.15939950248428536
326.2000000000039,38.467054077936,0.6121181388005208,-0.16169425399014292
327.0000000000039,38.54245329483956,0.6136348306197722,-0.16302595377558315
327.80000000000393,38.61962361544867,0.613752868267712,-0.16302031921662374
328.60000000000394,38.69656157092744,0.6161573427418916,-0.1643428376900382
329.40000000000396,38.773821477354126,0.6169580211795237,-0.16404179977153044
330.20000000000397,38.85009988352485,0.6202763290532378,-0.16467013665834607
331.000000000004,38.92745726751446,0.6208297085382223,-0.1648040588188011
331.800000000004,39.00403158261484,0.6235711772676723,-0.165919639828211
332.600000000004,39.081203224217326,0.6271199628514271,-0.16734924792562111
333.400000000004,39.157917171254084,0.6261812381162872,-0.16828888427079125
334.200000000004,39.23553044530628,0.6276001939540391,-0.17092970042379685
335.00000000000404,39.31207433541922,0.6297458574320541,-0.17225767345278697
335.80000000000405,39.38900179009153,0.631113845644019,-0.17355139354436933
336.60000000000406,39.46708557291718,0.6326358280507086,-0.1748507595832569
337.40000000000407,39.5434317286178,0.6344456218953324,-0.17603037033718438
338.2000000000041,39.62017139371565,0.6360321018229216,-0.17752026454586733
339.0000000000041,39.69778650106813,0.6375762554386575,-0.17966009377136327
339.8000000000041,39.772700490975886,0.6399086538330752,-0.1813034104382263
340.6000000000041,39.852137856176064,0.6418504593059656,-0.18279788750839954
341.4000000000041,39.92832199961453,0.6431826321483937,-0.18410562815645548
342.20000000000414,40.00418557564699,0.6414864301504859,-0.18413225770941732
343.00000000000415,40.08325913725613,0.64351484257142,-0.18542105504058481
343.80000000000416,40.16000091896551,0.6449254015924792,-0.1880242035642854
344.6000000000042,40.23681369763165,0.6487319011418213,-0.18932944113178518
345.4000000000042,40.31480715324069,0.6472625072171015,-0.19072608561908666
346.2000000000042,40.3909496983616,0.6513546589172138,-0.1935561563613919
347.0000000000042,40.46727729706693,0.6539866533034473,-0.1948696680805453
347.8000000000042,40.54589864186346,0.6522480965683719,-0.1951246737603647
348.60000000000423,40.622872993640314,0.6527787114534721,-0.1966281703923074
349.40000000000424,40.698528144782685,0.6533922144053228,-0.19916286691954888
350.20000000000425,40.77484967950557,0.6530487118565375,-0.20176200421611368
351.00000000000426,40.855114636756326,0.6511536144990221,-0.20446392927131063
351.8000000000043,40.93178698890568,0.6505276046042449,-0.20815303234387672
352.6000000000043,41.01018434180685,0.6508321114137468,-0.20967975891388857
353.4000000000043,41.086047591712735,0.6500630696033451,-0.21100254308888022
354.2000000000043,41.163904214846866,0.6469867298699479,-0.21262146035209817
355.0000000000043,41.2409055289854,0.6488464651479761,-0.21374329660176272
355.80000000000433,41.31823672428703,0.6482143515334675,-0.2150494896394477
356.60000000000434,41.395387915377725,0.6470048446564284,-0.2162655883614799
357.40000000000435,41.47267950920566,0.6463434627565554,-0.21902930515017038
358.20000000000437,41.54920674312531,0.6445436189131085,-0.22318473748320322
359.0000000000044,41.62601798330284,0.644157971168726,-0.22305367589469327
359.8000000000044,41.70483718434395,0.6412286311330986,-0.22552634330359256
360.6000000000044,41.78186584858123,0.6416125508590086,-0.22843556984345215
361.4000000000044,41.859794198430876,0.6400012229867004,-0.22975908883320084
362.2000000000044,41.93687814898335,0.6372111454869037,-0.23238406930972655
363.00000000000443,42.01340574083679,0.6354750588353222,-0.2337600401154427
363.80000000000445,42.09267042724549,0.6312099711467022,-0.23505478459628604
364.60000000000446,42.17041201379788,0.6298495627704219,-0.23599276059774654
365.40000000000447,42.246823720043245,0.6262344855061746,-0.23770486463837948
366.2000000000045,42.324208642696036,0.6219505746299111,-0.24068897959846147
367.0000000000045,42.400605884294265,0.6189612131742959,-0.24297199367461042
367.8000000000045,42.479363112893374,0.6155524602528777,-0.24294771474070487
368.6000000000045,42.55690321923612,0.6133406587748238,-0.24576341379943134
369.4000000000045,42.63419149527371,0.6117888480099214,-0.2468970727896349
370.20000000000454,42.71186835311761,0.6091611240837407,-0.2500675392272851
371.00000000000455,42.789330294638354,0.607362248811586,-0.25230631545135207
371.80000000000456,42.865455568127366,0.6030850853742443,-0.25356829474659204
372.60000000000457,42.94456417986835,0.5997504563389913,-0.25500363154774996
373.4000000000046,43.021364331444744,0.5975499046602695,-0.2562810313254249
374.2000000000046,43.09935389171338,0.593915401043254,-0.25754951942490667
375.0000000000046,43.17614980314508,0.5927284112126714,-0.2592157628726559
375.8000000000046,43.252902171594094,0.5872105041352133,-0.26003011498404316
376.6000000000046,43.33122556415399,0.5858950501205111,-0.26017945460032355
377.40000000000464,43.40848067482106,0.5812129310320703,-0.26016832808147417
378.20000000000465,43.485751564580916,0.5788846604957034,-0.26391247538557394
379.00000000000466,43.563851045819256,0.5737953194748128,-0.2655950758121981
379.8000000000047,43.64052145625632,0.5687623716520885,-0.26555718853490884
380.6000000000047,43.71777487591957,0.5648038094178759,-0.2673468246967521
381.4000000000047,43.79566358493233,0.5590897039954359,-0.26823806444594034
382.2000000000047,43.87291818992668,0.5567511369081727,-0.2668875352542881
383.0000000000047,43.951460775352615,0.5529633089882449,-0.2687482322310548
383.80000000000473,44.02755894898607,0.5503683213632208,-0.2702664395863854
384.60000000000474,44.10465349169363,0.548142223451997,-0.27082350948096856
385.40000000000475,44.18353514657155,0.5457936994282218,-0.2727406779579087
386.20000000000476,44.26030841083844,0.5429350828462297,-0.2747924524325529
387.0000000000048,44.33838889309225,0.5403174591935735,-0.2761149390133064
387.8000000000048,44.41567346373232,0.5404082259815579,-0.27478009390925706
388.6000000000048,44.49344785989955,0.5383151823533873,-0.27477487754675556
389.4000000000048,44.570884093469985,0.5365943064891152,-0.2760997592247527
390.2000000000048,44.64781055928177,0.5347299489794684,-0.2772420413912613
391.00000000000483,44.723592285295126,0.5351441785440145,-0.2774200491069605
391.80000000000484,44.80361353240805,0.5351482627142817,-0.2774273795104376
392.60000000000485,44.880973186254394,0.5343475259569234,-0.2787312198294698
393.40000000000487,44.95814588226177,0.5358060398206832,-0.2800445137487553
394.2000000000049,45.03538855039223,0.5340717829326862,-0.28071465551070807
395.0000000000049,45.11484404471545,0.536434612249947,-0.2807015722130215
395.8000000000049,45.191274828485554,0.5363845005446415,-0.2820301856668159
396.6000000000049,45.26990467744932,0.5375770649688575,-0.2847139101420306
397.4000000000049,45.34775955794023,0.538352627077982,-0.2846697355664509
398.20000000000493,45.42409805576978,0.5403006847318446,-0.28596258466698377
399.00000000000495,45.50332508079866,0.5406127509769134,-0.2874090737455215
399.80000000000496,45.58075929440914,0.5412567524525648,-0.28838211298196814
400.60000000000497,45.658167268341465,0.5420615882990513,-0.28994123725220744
401.400000000005,45.73674757546971,0.5426327338593504,-0.2912604553644105
402.200000000005,45.813643236829115,0.5441842697050049,-0.29125148229830167
403.000000000005,45.88936301328455,0.5443178637535999,-0.2932895222326173
403.800000000005,45.96941392280746,0.5462095455021525,-0.29400008370088226
404.600000000005,46.047088676166254,0.5468562489516828,-0.29530275676072204
405.40000000000504,46.12506983395285,0.5489569652883731,-0.29668371173300834
406.20000000000505,46.20304174582242,0.549815058829064,-0.29662935926828027
407.00000000000506,46.28099337863548,0.5491378610760923,-0.29927408945674827
407.80000000000507,46.35816488676558,0.5521194658594755,-0.3014557716658026
408.6000000000051,46.43667084315438,0.5559889885021189,-0.3030055401348477
409.4000000000051,46.514658962178714,0.5577027606483307,-0.30545379550559026
410.2000000000051,46.59211014285612,0.5584837135648715,-0.3055488566410314
411.0000000000051,46.67009283214356,0.5616174230336566,-0.30752330967777386
411.8000000000051,46.74830266016801,0.5622948399248378,-0.3098148665992446
412.60000000000514,46.826718791580724,0.5642916437538851,-0.31331885612100185
413.40000000000515,46.90463126961545,0.5670935966539606,-0.31599248111076017
414.20000000000516,46.980515344646754,0.5681454124802036,-0.3162978412422066
415.0000000000052,47.05938920808861,0.5693669578044263,-0.31628428090391036
415.8000000000052,47.13896779512054,0.5725446194957098,-0.3195581361188933
416.6000000000052,47.217251516944884,0.5750118337701772,-0.32271280085986254
417.4000000000052,47.29297397245989,0.5779149920032173,-0.3247444447839758
418.2000000000052,47.37283848674755,0.5798694027136284,-0.326790348094248
419.00000000000523,47.45000000000047,0.5821568061854878,-0.32836005057478523
419.80000000000524,47.52870163961959,0.5875796410169958,-0.3313146042113053
420.60000000000525,47.60614997157233,0.590208619275383,-0.33433075360998155
421.40000000000526,47.684225269700654,0.5960636221149159,-0.3374099227035243
422.2000000000053,47.76280158782207,0.5994270080409981,-0.3410031840596721
423.0000000000053,47.84039092412566,0.6056949572873478,-0.3454914243581131
423.8000000000053,47.91844844834406,0.6101510340382436,-0.3493180913391032
424.6000000000053,47.99655609110589,0.6169259137727174,-0.35164135582546896
425.4000000000053,48.07412443844947,0.6227975979740403,-0.3548820256073868
426.20000000000533,48.15252799812131,0.6300777173338163,-0.35932921710469845
427.00000000000534,48.23070315282883,0.6321263649459076,-0.36332069958789104
427.80000000000535,48.309000989628686,0.6422443776411707,-0.36810774245309785
428.60000000000537,48.385965751837254,0.6463911854951793,-0.3761089038958212
429.4000000000054,48.463771019308666,0.6519075006833518,-0.37987569598536997
430.2000000000054,48.54167223843422,0.6606495094913802,-0.3830645439083771
431.0000000000054,48.62040644612645,0.6648577108030047,-0.38820699000089354
431.8000000000054,48.69791947324483,0.6750606774566874,-0.39339290994507836
432.6000000000054,48.77619084335351,0.682646832503687,-0.4003801735527559
433.40000000000543,48.85460353350745,0.6893820329599956,-0.4073300646965077
434.20000000000545,48.932613171254296,0.6973200074199317,-0.41299635873497653
435.00000000000546,49.01162139619703,0.705734164494456,-0.4206217857131622
435.80000000000547,49.08798333876261,0.7160516759742737,-0.42696679716253527
436.6000000000055,49.16723752942246,0.7259545150721995,-0.434523029765014
437.4000000000055,49.245985210967724,0.7332763267537521,-0.44542796943080765
438.2000000000055,49.32400361366501,0.7435628293667473,-0.4544842510643745
439.0000000000055,49.402001751616275,0.7519229658430813,-0.463388421178919
439.8000000000055,49.48038581325859,0.7633738954133298,-0.4722259844950827
440.60000000000554,49.558851590856946,0.7728887888296864,-0.48085843592028077
441.40000000000555,49.63675902426152,0.7842258182517505,-0.49076188450507585
442.20000000000556,49.71565045249931,0.7984135234549328,-0.5004592674862725
443.00000000000557,49.79380161467451,0.8132087238249519,-0.5132446456682103
443.8000000000056,49.870423897384946,0.8238965117874362,-0.5252462468174062
444.6000000000056,49.95010818700064,0.8362015061912702,-0.5378735383352962
445.4000000000056,50.02853393746564,0.8525613573508692,-0.5498578337224167
446.2000000000056,50.10756615864137,0.8682500132791641,-0.5654038568730906
447.0000000000056,50.185431424283166,0.8812251042185222,-0.5792749896278453
447.80000000000564,50.263102630578075,0.8998860531902486,-0.597025554756792
448.60000000000565,50.34093122560557,0.9147687864699439,-0.612981189899005
449.40000000000566,50.4199039904171,0.9325504814777854,-0.6271937751643581
450.2000000000057,50.49811048231516,0.9516248486520476,-0.6460189698296732
451.0000000000057,50.57583649830645,0.9688114267449958,-0.665360926814166
451.8000000000057,50.655361645266915,0.987579853183532,-0.6876167090233376
452.6000000000057,50.73252662434585,1.0063546681376179,-0.7074596307125725
453.4000000000057,50.811121722191494,1.0288098119037241,-0.7301110338127708
454.20000000000573,50.88990892678855,1.050889844022729,-0.7535121371144631
455.00000000000574,50.96896812798953,1.078764634577396,-0.7787260018485052
455.80000000000575,51.04780438338014,1.102100749200082,-0.808841921724893
456.60000000000576,51.12482335936921,1.1288447564506487,-0.8370385122524397
457.4000000000058,51.2036747544945,1.1526016519588187,-0.8667498137334788
458.2000000000058,51.282013036321025,1.1782628511155333,-0.8975698749250398
459.0000000000058,51.35982969951576,1.202204182227398,-0.9301398427284813
459.8000000000058,51.43917345503661,1.228714551635985,-0.9653877770967711
460.6000000000058,51.51939234716337,1.2576483761713437,-1.0033434022818986
461.40000000000583,51.597472573726264,1.283945907039499,-1.0418336359272327
462.20000000000584,51.674278295417736,1.3097122839698492,-1.08260314339869
463.00000000000585,51.75486679115628,1.3379832748371117,-1.125978143463524
463.80000000000587,51.83350394614927,1.367171036817529,-1.1737338290229369
464.6000000000059,51.91255007720885,1.395758801949224,-1.2210172202974454
465.4000000000059,51.99095195700564,1.4243156893230742,-1.2715849036694196
466.2000000000059,52.06928207527203,1.4547521415209466,-1.3239256190947883
467.0000000000059,52.147158392777406,1.4835518352491925,-1.3771357620209725
467.8000000000059,52.22551191693454,1.5096164326976627,-1.4336366284577036
468.60000000000593,52.3053687569302,1.5382472457524354,-1.4955713805080242
469.40000000000595,52.38295177990452,1.5641226909877464,-1.5557199949546554
470.20000000000596,52.46175810135417,1.5879209446036682,-1.620483510632364
471.00000000000597,52.54009680935848,1.6126639277232087,-1.6860174297283042
471.800000000006,52.619171483304726,1.6327731691592366,-1.7577051488352287
472.600000000006,52.69834587672502,1.6564406497954076,-1.8303301107769583
473.400000000006,52.776308554486135,1.6750219470003112,-1.9032631022345488
474.200000000006,52.855279741284754,1.6891039677958044,-1.980341309866287
475.000000000006,52.93437324511522,1.702340899566021,-2.0593462301136505
475.80000000000604,53.012390298835946,1.7101014833575046,-2.139675022343754
476.60000000000605,53.09126352348215,1.7167900300768855,-2.2226066593807303
477.40000000000606,53.169622012392665,1.7158076151962192,-2.307268181011705
478.20000000000607,53.24710559443672,1.7121817975836695,-2.3913229755235874
479.0000000000061,53.32681470442154,1.7018583770870612,-2.4790500173226055
479.8000000000061,53.40587529352036,1.6925990948284122,-2.5701655188900574
480.6000000000061,53.48398575933842,1.674141843890392,-2.658947948483182
481.4000000000061,53.562521704840584,1.6560219970255843,-2.75070199390424
482.2000000000061,53.64033615087484,1.6271727538248544,-2.8396921475208843
483.00000000000614,53.71952862858537,1.5944405338814476,-2.9290025048967463
483.80000000000615,53.79826933772439,1.5561007852890119,-3.0188943544457647
484.60000000000616,53.87640940896164,1.5096729357197136,-3.107590320144119
485.4000000000062,53.95531558040956,1.4549219687708574,-3.1941098383064936
486.2000000000062,54.03321438932298,1.3923883473600656,-3.2755924595700323
487.0000000000062,54.11184872944852,1.3308577156536303,-3.3561396425574266
487.8000000000062,54.18934722926809,1.2590487881326895,-3.4336946969354116
488.6000000000062,54.267666930649774,1.1828205827261784,-3.507612656277583
489.40000000000623,54.347113473643816,1.0991522447643742,-3.5801398963598468
490.20000000000624,54.42528939876854,1.015144706708246,-3.6439304404366446
491.00000000000625,54.50334808805375,0.9276504236831873,-3.703379068808016
491.80000000000626,54.58180318402815,0.8399960807603992,-3.757474204772712
492.6000000000063,54.65950787549771,0.7547250820604686,-3.8046660959281726
493.4000000000063,54.7353396140367,0.6751258881705238,-3.846410252362022
494.2000000000063,54.81512290890654,0.5961754023095343,-3.886199092377563
495.0000000000063,54.894050390048555,0.5268086229183595,-3.919069788704577
495.8000000000063,54.97238237604883,0.46158593584734436,-3.946412259937013
496.60000000000633,55.05048586702292,0.4025971607080762,-3.9698949557328502
497.40000000000634,55.129134070753175,0.34742208466098695,-3.9925770969616576
498.20000000000636,55.20654253963659,0.30045241656478483,-4.009271775687236
499.00000000000637,55.28586979774863,0.2587101405505037,-4.0202013346059555
499.8000000000064,55.36439173637411,0.21898493168042915,-4.030892644367999
500.6000000000064,55.441918271342146,0.18910259025576126,-4.03875750149706
501.4000000000064,55.521728436175884,0.15921847623583787,-4.045370930250364
502.2000000000064,55.599802874863485,0.13466436209915184,-4.050464534191216
503.0000000000064,55.679111513680766,0.11509321708183845,-4.055410595097251
503.80000000000643,55.75849199363549,0.10117656022144006,-4.058029350670287
504.60000000000645,55.836350161717455,0.08629485635744644,-4.060970132453991
505.40000000000646,55.915194726114976,0.07756868247264032,-4.060893450852506
506.20000000000647,55.99381051309911,0.07372988419295862,-4.062299945848799
507.0000000000065,56.0731244821406,0.0702513938831153,-4.062300109986827
507.8000000000065,56.151852497267306,0.06993418756816505,-4.0636243203187945
508.6000000000065,56.231525947678286,0.06932910569012946,-4.062240918002644
509.4000000000065,56.308620033702326,0.07276049207702256,-4.062631344690416
510.2000000000065,56.38890348134257,0.07467286983693128,-4.063619729462484
511.00000000000654,56.46684372922328,0.07895259872771476,-4.062882971945078
511.80000000000655,56.54548434079769,0.07864162748893044,-4.061639620034128
512.6000000000065,56.623915324743756,0.07979246087118802,-4.060330706822039
513.4000000000066,56.7035888839532,0.08068336238246065,-4.061639967208552
514.2000000000066,56.7818212795372,0.07872995645944797,-4.061639967909111
515.0000000000066,56.858872632510064,0.07729378819910182,-4.063006595072201
515.8000000000065,56.93718028950153,0.07548733926705781,-4.062959377386327
516.6000000000066,57.01877371545703,0.0731236574592038,-4.064277340768903
517.4000000000067,57.0974503635726,0.06878549809745865,-4.0642798899403045
518.2000000000066,57.17693523499326,0.0639188138046275,-4.064279890184356
519.0000000000066,57.255855288783884,0.06007732081432099,-4.0642867507862235
519.8000000000067,57.33537489509346,0.05744786550493736,-4.06494009509933
520.6000000000067,57.414579509195946,0.05027633972242668,-4.063619516407105
521.4000000000067,57.49337821269751,0.04354677186546957,-4.063620003988178
522.2000000000066,57.572876786909326,0.04107148289947843,-4.063621402746192
523.0000000000067,57.65167872755754,0.03831240707846867,-4.062301759069949
523.8000000000068,57.73057870836221,0.03118710826650606,-4.063665569050017
524.6000000000067,57.81060620119686,0.028959561062808725,-4.06458925577457
525.4000000000067,57.88777805959583,0.024412489986380292,-4.06559019436822
526.2000000000068,57.96886828630642,0.02188591230717435,-4.064596262618016
527.0000000000068,58.047609296384714,0.01907052549492244,-4.0625374005572805
527.8000000000068,58.1267870583242,0.016627610634099677,-4.063276002695758
528.6000000000067,58.205943877850466,0.015477465325613615,-4.06328125453054
529.4000000000068,58.28587722351163,0.012064305714587609,-4.064602987586788
530.2000000000069,58.36544271484526,0.012680054791493922,-4.064599982081451
531.0000000000068,58.44437039531066,0.009752995850627444,-4.064599982014682
531.8000000000068,58.52369605640405,0.007901971981548517,-4.0646004879688595
532.6000000000068,58.60338560730213,0.0059189323966497565,-4.063290548886205
533.4000000000069,58.68189402655475,0.005443428504023573,-4.062516499866223
534.2000000000069,58.76169362064841,0.005975992521966511,-4.062754516149893
535.0000000000068,58.84089346952699,0.00513546234432205,-4.063946933389454
535.8000000000069,58.91745277880857,0.0031764650749082635,-4.064609796650914
536.600000000007,58.99990635961191,0.003647261561031623,-4.065915030992149
537.4000000000069,59.07776198895879,0.0034980592381085307,-4.065919792548566
538.2000000000069,59.15803286847341,0.0043945040187781115,-4.066913768745601
539.0000000000069,59.236839117197306,0.002735070347294033,-4.067610385257318
539.800000000007,59.31721960481465,0.004293595914557413,-4.067547943490004
540.600000000007,59.39557158886682,0.002842784684114863,-4.066247207572514
541.4000000000069,59.47492558809481,0.0031845969755478487,-4.065840983000984
542.200000000007,59.55477496269206,0.0006701965502116103,-4.064939913320022
543.000000000007,59.63349142125611,0.001675419984924209,-4.064922492138273
543.800000000007,59.712423648367526,-0.0008298099425599337,-4.066913873974259
544.600000000007,59.79089728578824,-0.0015101178205447208,-4.06560768187806
545.400000000007,59.87010277834234,-0.0026571368445020283,-4.066741719584058
546.000000000007,59.93064924588128,-0.002995075612314213,-4.066910029291697