File: 01_Data/PE_Foam_Pipe_Insulation/STA/N2/10K_min/PE_Foam_Pipe_Insulation_STA_N2_10KData_220923_R1.csv
##Temp./Â°C,Time/min,DSC/(mW/mg),Mass loss/mg
51.0,10.741411923731906,0.048618924018251075,0.003379427917476363
52.100000000000016,11.127555144421555,0.11870418797358351,0.0017924833620783787
53.20000000000003,11.376632227340556,0.16689750641280576,0.00044551301299744495
54.30000000000005,11.584902374759404,0.20312705739429515,0.003417393142880698
55.40000000000006,11.774379476589854,0.23809742053959693,0.003786064394476263
56.50000000000008,11.944971217571256,0.264703488860083,0.00027364200439095043
57.600000000000094,12.110551065015517,0.28972911058046,0.0038036349204553233
58.70000000000011,12.264560997232802,0.31249956539982326,0.0038150983062177346
59.800000000000125,12.414529291289238,0.3288706649552342,0.002741225753636556
60.90000000000014,12.560674558235323,0.3395053761592125,0.0011570243512757372
62.000000000000156,12.704229630016913,0.34564119912460123,-0.00037456068709040835
63.10000000000017,12.840628174725776,0.35153919452807947,0.004138209159841644
64.20000000000019,12.981345549703581,0.35548088136012335,0.004947765889875555
65.30000000000021,13.11793719617511,0.35745894481036034,0.004895911668405084
66.40000000000022,13.251703691881627,0.36204381379511275,0.004051658197106178
67.50000000000023,13.382072631800593,0.3669018913811799,0.0064077110874309895
68.60000000000025,13.512951688902739,0.3714721009356854,0.005055606643050048
69.70000000000027,13.640540154580165,0.3776959346439115,0.0036045189425539803
70.80000000000028,13.76905207542409,0.38344025144964533,0.0023994645082154875
71.90000000000029,13.893987579309933,0.3932117436234046,0.0011173206105130618
73.00000000000031,14.020586076024406,0.40115106998212235,0.0016311148875622905
74.10000000000034,14.143801011866275,0.41384494866846666,0.0017633101214080682
75.20000000000034,14.265005753731865,0.42248737433721306,0.0033547713879205077
76.30000000000035,14.38639865359747,0.43158919405643015,0.0024148625437963034
77.40000000000038,14.503766655592122,0.441825513913926,0.0038279265603380352
78.5000000000004,14.628829986002852,0.4548774423688118,0.005158924638250184
79.6000000000004,14.747046765329836,0.46636350960971207,0.006505597669851149
80.70000000000041,14.865944657594095,0.4760138050253101,0.0025273370097007586
81.80000000000044,14.982863160981646,0.48595125636735514,0.0012034313347735193
82.90000000000046,15.101233341181956,0.49928909431043955,0.004231305220000259
84.00000000000047,15.21797353111971,0.5112899349632514,0.0036783020917585674
85.10000000000048,15.333904613826853,0.52408506527674,0.002862603506122774
86.2000000000005,15.44917000000005,0.5372457958594143,0.004169998812981746
87.30000000000052,15.56326735680957,0.5486616312029063,0.002761855733759866
88.40000000000053,15.677108595098034,0.5625914347133176,0.0041616751743838165
89.50000000000054,15.790220461320429,0.5758712519360115,0.005501646765408097
90.60000000000056,15.903411181276617,0.5872296438924907,0.005386315122042795
91.70000000000059,16.01480449617953,0.6022113875120275,0.005479068282602029
92.8000000000006,16.127743148517432,0.6224379932117662,0.004808982682173557
93.9000000000006,16.2400894362306,0.6418423048476665,0.0035916778404745386
95.00000000000063,16.34937538452374,0.6624566909323248,0.005600915420069796
96.10000000000065,16.46094851708362,0.6845790919420671,0.007355025843192031
97.20000000000066,16.571418005682716,0.7007371987435838,0.005997769351565374
98.30000000000067,16.682376014644397,0.7125883186352544,0.004720013676514867
99.40000000000069,16.79191159829024,0.7202555555175802,0.002086691393849982
100.50000000000071,16.902105321639855,0.7361415874037937,0.003620444598170458
101.60000000000072,17.010979445525944,0.7581075436033651,0.003289248261128641
102.70000000000073,17.12007711083507,0.7881711280839944,0.0010972710940393426
103.80000000000075,17.229760320245028,0.8274774945308805,0.0036348950441871253
104.90000000000077,17.338244378513078,0.8718021007669199,0.0023000664240520052
106.00000000000078,17.44445177991127,0.9209508793617351,0.002300019522516905
107.10000000000079,17.555837960299254,0.9850549596336959,0.003632782736306517
108.20000000000081,17.66439434727374,1.0572312413037885,0.004927757221667939
109.30000000000084,17.773845913098956,1.142557850548426,0.006416321659419744
110.40000000000084,17.881524976345048,1.2428745085782453,0.0061462542935881714
111.50000000000085,17.991122136104796,1.3525906789255084,0.005204262711650642
112.60000000000088,18.098837710251622,1.4714881489733465,0.006460628885153419
113.7000000000009,18.209453890703035,1.5588872039920196,0.007789729614869678
114.8000000000009,18.31795971063058,1.5289730568299493,0.006479892931467113
115.90000000000092,18.425274577238937,1.2312431828899875,0.006482839996244216
117.00000000000094,18.532089683010028,0.8631539863012219,0.006246877062381806
118.10000000000096,18.636750993817728,0.6580063763288353,0.004829981907523262
119.20000000000097,18.74381477650588,0.538966374389446,0.00484181566807429
120.30000000000098,18.848963384145083,0.4780333983364921,0.006517000614503665
121.400000000001,18.95531365644026,0.4440301829234805,0.005155154023707809
122.50000000000102,19.05873097959816,0.4290734862141793,0.005223587285902553
123.60000000000103,19.16704736081927,0.4171875016225144,0.005821067539818259
124.70000000000104,19.27245553790144,0.4133133289926322,0.005771043974672985
125.80000000000106,19.377814123706152,0.4092869866145161,0.007017855523825389
126.90000000000109,19.484147770365876,0.40920327976456783,0.006467788457936052
128.00000000000108,19.59073782691263,0.40802176150788405,0.005149353429131587
129.1000000000011,19.69637372025677,0.41076066747814455,0.0038399982180639114
130.20000000000113,19.80282425342556,0.4104265172491862,0.003840011205738847
131.30000000000115,19.908093061305074,0.4109598143994335,0.003512639404987361
132.40000000000117,20.0136047562314,0.4105937491924573,0.005167055557477873
133.50000000000117,20.119063668063617,0.4116624748539812,0.005149859538937207
134.6000000000012,20.224380544593544,0.4110370672046958,0.004887081324898901
135.7000000000012,20.32994636363863,0.41234107508880724,0.0020962549297962596
136.8000000000012,20.436224915357172,0.41174584726408303,0.0008705853315928991
137.90000000000123,20.540485502932498,0.41489930446624756,-0.0004622930413802351
139.00000000000125,20.646265187593393,0.4166919367623062,0.001978732806061423
140.10000000000127,20.75165560873303,0.41566968277512995,0.0035925285097491155
141.2000000000013,20.857512943581966,0.4176145045541407,0.004924034253736664
142.3000000000013,20.961136185529277,0.4200657751020129,0.0011054626094217923
143.4000000000013,21.06779554143512,0.41992120200979166,-0.00027692361984499314
144.50000000000134,21.172561083141684,0.421992912851854,0.0011009041025946686
145.60000000000133,21.27553529643933,0.4231721102442609,0.0043996054037922505
146.70000000000135,21.382464315691696,0.42434749583061704,0.005050708182917418
147.80000000000138,21.487448642447273,0.42458379206646907,0.003742224204810185
148.9000000000014,21.59332652565485,0.4270679405034456,0.003567775742483903
150.00000000000142,21.696746511840402,0.4276124385929413,0.0024245777771110255
151.10000000000142,21.802669668534374,0.4291490489102986,0.003406195942379675
152.20000000000144,21.906081921075575,0.4283132590362102,0.0051023980215374465
153.30000000000146,22.011206413385004,0.4305926867788887,0.006470108220643311
154.40000000000146,22.115588507262657,0.43388644452620034,0.0050552322843469
155.50000000000148,22.220361685133344,0.4326835710854766,0.0028573135685734385
156.6000000000015,22.32374860316026,0.4337328348967858,0.0024101196818708814
157.70000000000152,22.42851640208776,0.43539340769421553,0.0010908968266694075
158.80000000000155,22.532908023791524,0.43648529387487994,0.0010864394318543802
159.90000000000154,22.636726322412493,0.4359277082824614,0.0036944845587933983
161.00000000000156,22.73886091932578,0.43653380060181074,0.003730157979259907
162.1000000000016,22.847394314890522,0.43609675673326426,0.0037303613639636524
163.20000000000158,22.9510694371962,0.4389354995982024,0.003730319560680151
164.3000000000016,23.055148996822094,0.43925772403136537,0.003745376960692326
165.40000000000163,23.159661641508,0.44172793431545676,0.0013837499247015828
166.50000000000165,23.26465975548345,0.4402937626204628,0.0011294146137679206
167.60000000000167,23.36898016786874,0.44232384993297164,0.0032419902943230383
168.70000000000167,23.474424430994183,0.44314941877300695,0.0031794046474447057
169.8000000000017,23.578073306071538,0.44286907465235215,0.002774271901121672
170.9000000000017,23.6822902694131,0.4437093895061743,0.0031796273079596205
172.0000000000017,23.78567895177491,0.4451830338614468,0.0031801515744778186
173.10000000000173,23.891280733825614,0.4471806456883102,0.0018612000076734248
174.20000000000175,23.996425528376154,0.4482293106542321,0.0015300563240074894
175.30000000000177,24.100336767964304,0.448728129567887,0.0015308436277905457
176.4000000000018,24.20479657113306,0.44933010458489697,0.0018708445085779957
177.5000000000018,24.30966925748711,0.4513742843147954,0.0005435407845455487
178.6000000000018,24.414702711479602,0.4520156061078265,-0.0007799321128718617
179.70000000000184,24.519488858907494,0.45441526962651296,-0.0007798619390797512
180.80000000000183,24.620579809671735,0.4534123341304695,0.0005405789144514728
181.90000000000185,24.727519319015435,0.4539344570405576,0.0018611317239738412
183.00000000000188,24.829539599016115,0.45339830763511835,0.0015301763384094613
184.1000000000019,24.93535732398343,0.4536235135612754,0.0005608811308102091
185.20000000000192,25.03935935370615,0.4555107141743841,0.0015077120239537223
186.30000000000192,25.143765889434587,0.4557569661969189,0.0008808150305448237
187.40000000000194,25.247497135193754,0.45580265795317493,0.0021803690367656614
188.50000000000196,25.352085125389127,0.45777289405268096,0.0018601776862050556
189.60000000000196,25.456838318974352,0.4567366684223504,0.0018621956760949132
190.70000000000198,25.560402800551742,0.4572604308499735,-0.0006978193751763229
191.800000000002,25.660995179083333,0.4570643995954363,-0.0007798360139243954
192.90000000000202,25.768011914315487,0.4580719010959266,-0.000779835999994205
194.00000000000205,25.871929281079186,0.45797928863649023,-0.0007798350188910064
195.10000000000204,25.97735985899048,0.45779117148088133,-0.0015314825022541
196.20000000000206,26.07926460960864,0.45944397617545,-0.0004399967371542246
197.3000000000021,26.1865223253293,0.4613837770605227,0.0005520064390118762
198.40000000000208,26.289011624034146,0.46012092775872754,-0.002412538656522578
199.5000000000021,26.393705889899174,0.4610153382606926,-0.0024211783295857714
200.60000000000213,26.498758735550037,0.4629014555680581,-0.00275012808031061
201.70000000000215,26.603360827682543,0.4631741782830619,-0.004041026916244306
202.80000000000217,26.70682154587556,0.4616329317718117,-0.0037357055259743532
203.90000000000217,26.811824207119123,0.46446449316053906,-0.003734571565164657
205.0000000000022,26.9164542072771,0.46599731265850025,-0.003739839999448158
206.1000000000022,27.02059637877114,0.46576059470146575,-0.0037364514612061583
207.2000000000022,27.125672478782672,0.46486567686776276,-0.002420011740273509
208.30000000000223,27.22938796598599,0.4702132484989708,-0.004719910479671796
209.40000000000225,27.33353956781386,0.467707813141562,-0.004733968514146092
210.50000000000227,27.438394792348284,0.46968187831013686,-0.005710188504213676
211.6000000000023,27.54136216084453,0.4696641848941218,-0.005710185937148005
212.7000000000023,27.64578462270765,0.4709521492310361,-0.005744805897965222
213.8000000000023,27.750438048618612,0.47101077510275124,-0.006033225405228215
214.90000000000234,27.854697123738365,0.46989831984103547,-0.007360280693327503
216.00000000000233,27.957279868371785,0.46932230945967307,-0.0073598400922536555
217.10000000000235,28.06302983300666,0.46781084900354963,-0.007182556356733372
218.20000000000238,28.167555204988282,0.46707080651853794,-0.0063225347646787
219.3000000000024,28.27170817434077,0.4698695265801204,-0.006356121257111269
220.40000000000242,28.37504719907506,0.47064887166832514,-0.01044852402034202
221.50000000000242,28.479079514654526,0.47331864083680053,-0.011212012664838511
222.60000000000244,28.584281444187045,0.4727070910820018,-0.011198749223681581
223.70000000000246,28.689459538544366,0.47142009399317986,-0.011546342244479035
224.80000000000246,28.792846708296548,0.4748389064223101,-0.012871697573627827
225.90000000000248,28.897419879981243,0.47458809668734103,-0.012850106702063435
227.0000000000025,29.00167030627776,0.47671786575655495,-0.011851260241580341
228.10000000000252,29.105735398231197,0.47516567467446247,-0.01218191194042717
229.20000000000255,29.209549907412452,0.4761629216471237,-0.012849344473894853
230.30000000000254,29.314191931932243,0.47446056261422653,-0.015141748678312084
231.40000000000256,29.418516116074816,0.47505051079445915,-0.01690754261616423
232.5000000000026,29.5234180182767,0.47594667331200446,-0.01952929682649973
233.60000000000258,29.624337441794165,0.4765675769890072,-0.019520036910689598
234.7000000000026,29.732253176577338,0.47575616317339453,-0.01814688066385184
235.80000000000263,29.83653849166233,0.47647868132950233,-0.01790026710863568
236.90000000000265,29.93958412065949,0.47610216755425705,-0.019219844380996776
238.00000000000267,30.04259475520266,0.47547827388082964,-0.01922441022716015
239.10000000000267,30.148652309149437,0.47898909644694987,-0.02185628395947603
240.2000000000027,30.25376744034119,0.47751771916008,-0.023197856227056945
241.3000000000027,30.35856833769801,0.48123151499894745,-0.02185125223484441
242.4000000000027,30.462799131800825,0.4824506528246105,-0.024530539751272507
243.50000000000273,30.56765542151548,0.4807690334837771,-0.025136129580188182
244.60000000000275,30.671094103173974,0.4822591642221812,-0.027119954333091556
245.70000000000277,30.775540224498602,0.4812646717503099,-0.02717478619823588
246.8000000000028,30.879848926885753,0.481017001750761,-0.02816708575345217
247.9000000000028,30.9856213539039,0.4793539592624011,-0.02977325949316434
249.0000000000028,31.09041717577881,0.4798803606119738,-0.031069879041679016
250.10000000000284,31.193256111032458,0.4790501906351927,-0.031999235763926936
251.20000000000283,31.298270835978663,0.4796026638475276,-0.03206487564124849
252.30000000000285,31.40368945454942,0.47977068741411183,-0.03651971047213687
253.40000000000288,31.50802726059793,0.47983947874021704,-0.036449952119818274
254.5000000000029,31.6123175869696,0.4794241680217305,-0.0363693050867786
255.60000000000292,31.71749061080365,0.4800445413540583,-0.040277174361603496
256.7000000000029,31.822209361167328,0.4795506610534381,-0.04172019974758978
257.8000000000029,31.925733157241385,0.48081285291071096,-0.04105981049166729
258.90000000000293,32.03122193822074,0.4801666903427955,-0.041054301363410595
260.00000000000296,32.13570622366604,0.48112132617860337,-0.04378158215114958
261.100000000003,32.24059528631477,0.48061040957970835,-0.04511986789115641
262.200000000003,32.34479736210924,0.48153529657850647,-0.046484210058437725
263.300000000003,32.450359617711676,0.4801804645370164,-0.048572799410182554
264.40000000000305,32.554451745983066,0.4792937460238866,-0.049114489179479026
265.50000000000307,32.659900242133325,0.47709432221926096,-0.05036104675329245
266.6000000000031,32.765359859225335,0.47659608044331747,-0.050326395495009724
267.7000000000031,32.869169010316206,0.4746489969479154,-0.054371742832358905
268.8000000000031,32.97604862132083,0.47690073393460486,-0.05566039684389423
269.9000000000031,33.08016433465167,0.47546331850230517,-0.0536895367293031
271.0000000000031,33.18511554657545,0.4770888429777608,-0.05689426696390365
272.10000000000315,33.28965904843874,0.47724682834665233,-0.05963675372396704
273.2000000000032,33.394821372275715,0.47759969094295035,-0.05822807921800699
274.30000000000314,33.49981894716247,0.47550072734406235,-0.05929034040093173
275.40000000000316,33.60570324330088,0.4756399542180501,-0.05994848011123555
276.5000000000032,33.7088758440495,0.47775968272899993,-0.060934478869114184
277.6000000000032,33.81453099030909,0.47607852510933624,-0.06353961545221232
278.70000000000323,33.919594747529125,0.4766602609856848,-0.06523216874257853
279.80000000000325,34.024320943687,0.4782047392969394,-0.06715068253402645
280.9000000000033,34.129931223454825,0.4786887075567782,-0.06587546988473969
282.0000000000033,34.23512036025117,0.4783972564237463,-0.06716724129015272
283.1000000000033,34.33926491909012,0.47889633550552857,-0.06719038193267668
284.20000000000334,34.4444390619901,0.47791121591993113,-0.06634867565950708
285.30000000000337,34.549468507859295,0.47527250477277333,-0.06619985177695176
286.40000000000333,34.65502311875782,0.4758495496277988,-0.06752007171798535
287.50000000000335,34.75981250921923,0.47597154991360346,-0.06752195532632133
288.6000000000034,34.86398205216354,0.4779095300347237,-0.06882371629649597
289.7000000000034,34.968519800647016,0.4790349779672376,-0.07147392607131797
290.8000000000034,35.07434948022456,0.47940711594884056,-0.07014946299894964
291.9000000000034,35.17917088640769,0.4783080907966475,-0.07281069867055878
293.0000000000034,35.28482789852154,0.47704282047177904,-0.07541724575129205
294.10000000000343,35.38948598074006,0.4778295370024152,-0.07806133403473048
295.20000000000346,35.49558145487668,0.4809822709372866,-0.07938103479327197
296.3000000000035,35.59873559955747,0.47934584103117883,-0.08069568742572564
297.4000000000035,35.70451771175291,0.4798324859968131,-0.08068545679823069
298.5000000000035,35.81009043703713,0.4810626485284995,-0.08069001754093108
299.60000000000355,35.9150642148439,0.47813165864173657,-0.07937008122359135
300.70000000000357,36.02102095094234,0.47869528912984566,-0.08035632015472816
301.8000000000036,36.12554411479445,0.4807946300836846,-0.08101984671861961
302.9000000000036,36.22958984928081,0.4776031956341762,-0.08101982706260591
304.0000000000036,36.334279157036285,0.4783805836009636,-0.08142003797479491
305.1000000000036,36.44199914401649,0.4765010173120505,-0.08226688317367792
306.2000000000036,36.547722296191736,0.47893972036648474,-0.08531141781118956
307.30000000000365,36.65317347119615,0.4787618780833976,-0.08564125320427607
308.4000000000037,36.75891603629548,0.47750738004263005,-0.08550749267387614
309.5000000000037,36.86415820179143,0.47898527690639525,-0.08182186401380909
310.60000000000366,36.969482549463244,0.4796054642086433,-0.08504851617828901
311.7000000000037,37.075642819021475,0.4803930916313774,-0.08841494910776104
312.8000000000037,37.18092968294586,0.4818152383033589,-0.09053858305973339
313.90000000000373,37.2864456175197,0.4837765512021861,-0.09102041139434958
315.00000000000375,37.392680850965334,0.48378087861390406,-0.09003712797882502
316.1000000000038,37.49863385668175,0.4854043732037373,-0.09004207531102804
317.2000000000038,37.60391549257028,0.48679922365912043,-0.08871002493988733
318.3000000000038,37.709548736881665,0.4871877487455678,-0.09134321501950415
319.40000000000384,37.81610489467636,0.48805163637713667,-0.09133990734435571
320.5000000000038,37.92106132245984,0.4890730083160423,-0.09135576117842747
321.60000000000383,38.02743005003211,0.49205145139441697,-0.09497706845301224
322.70000000000385,38.13383015929068,0.49454109604895413,-0.09754902467983051
323.8000000000039,38.23998556915088,0.4980999870865797,-0.09865569275790209
324.9000000000039,38.34557148949757,0.4981117241662869,-0.09923976263794998
326.0000000000039,38.449170000000365,0.49945118883734674,-0.09792983349620332
327.10000000000394,38.55672227556027,0.5013122165395164,-0.09792007674805436
328.2000000000039,38.66379826559609,0.5025635437287602,-0.09799601071747022
329.30000000000393,38.76934880314311,0.5049398616328415,-0.1019971550728882
330.40000000000396,38.87457104852746,0.5072047216786061,-0.10246972035708968
331.500000000004,38.98128723236808,0.5094734598795425,-0.10593806504433001
332.600000000004,39.08648876537838,0.5121345186049155,-0.10567228138199614
333.700000000004,39.191094498415794,0.5140296165829679,-0.10677697388623031
334.80000000000405,39.29842619600802,0.5149828525054782,-0.10890971470150967
335.90000000000407,39.40450690409399,0.5188565256190079,-0.110016253159535
337.0000000000041,39.51020599369662,0.5212561949718206,-0.11451102453065598
338.10000000000406,39.615473537098815,0.5227505593547133,-0.11653287080950925
339.2000000000041,39.721480699732936,0.5240753000858184,-0.116602923538494
340.3000000000041,39.82834342110969,0.5270701409080131,-0.11879006398149006
341.4000000000041,39.93335003580957,0.5288063769461905,-0.11944295755997825
342.50000000000415,40.03944427325868,0.528668835045056,-0.12296981607026414
343.6000000000042,40.1455449144988,0.53165219034436,-0.1263331617266208
344.7000000000042,40.252591664478196,0.5336993429657424,-0.12740627958047535
345.80000000000416,40.357906751688986,0.5354260400776665,-0.1314014022473966
346.9000000000042,40.46362320288228,0.5371972430349423,-0.13060616217964327
348.0000000000042,40.56960179889366,0.5364935933435299,-0.13301875326323476
349.10000000000423,40.67505568959966,0.5380357953388413,-0.13576356123024436
350.20000000000425,40.782290496224626,0.539664630017386,-0.13876471084026676
351.3000000000043,40.88853894782227,0.5384264737378982,-0.14176242560388497
352.4000000000043,40.9947269269741,0.540859164624727,-0.14813278943775732
353.5000000000043,41.10069370963209,0.5397218403175852,-0.15200173344051038
354.60000000000434,41.207615333722444,0.5407731908830011,-0.153924683834739
355.7000000000043,41.313632317243616,0.5406624722751371,-0.15429168638887436
356.80000000000433,41.41993126645872,0.5366674622355411,-0.1568668552769985
357.90000000000435,41.52652753718603,0.53594648089815,-0.15951529728608982
359.0000000000044,41.63251550141593,0.5353307565612819,-0.16183352810624463
360.1000000000044,41.7392645186809,0.5333530399019342,-0.1644586433705455
361.2000000000044,41.844904691650946,0.5317342708936524,-0.1658617064936565
362.30000000000445,41.951946946471764,0.5283385528803552,-0.16971379299557698
363.4000000000044,42.05907143649065,0.5300747073403951,-0.17236618485696553
364.50000000000443,42.16437208473941,0.5255753575676821,-0.1734403792770567
365.60000000000446,42.27027074996192,0.5218317060599016,-0.1748444477201101
366.7000000000045,42.3766714261594,0.5198689026843798,-0.18009632534837738
367.8000000000045,42.48373913499004,0.5142265803905063,-0.1848274900130571
368.9000000000045,42.58926993871819,0.5120814287256362,-0.18872016315523465
370.00000000000455,42.69645538677301,0.5100399951878124,-0.19020333192102257
371.10000000000457,42.80259554023909,0.5054397032178406,-0.19422939272113027
372.2000000000046,42.908275887359395,0.502807152366353,-0.1928384250351951
373.30000000000456,43.015534232661786,0.49647983569056287,-0.19157653838467104
374.4000000000046,43.122255682847666,0.4911399954082718,-0.19026248555095915
375.5000000000046,43.22926587995467,0.4878204323622481,-0.19223731524261556
376.6000000000046,43.335716365706695,0.48003107189325905,-0.19707124372022244
377.70000000000465,43.44300283408443,0.47373346375415226,-0.20009076875860954
378.8000000000047,43.54907946638241,0.4701977789404186,-0.19991977564512053
379.9000000000047,43.65600095074727,0.46404691838577655,-0.20280286380852086
381.00000000000466,43.76249173705309,0.4601057545973422,-0.20650509510848813
382.1000000000047,43.8702128661131,0.4553730916306206,-0.2065609198339473
383.2000000000047,43.97717338915629,0.4529735123340978,-0.20777036102575064
384.30000000000473,44.084926032334614,0.45146281489985907,-0.2090301804727508
385.40000000000475,44.19020567393007,0.4484353926805306,-0.20924784164500698
386.5000000000048,44.296919671045195,0.4469175945355962,-0.20667460470335453
387.6000000000048,44.404351853514406,0.4429023873546,-0.20903511934167307
388.7000000000048,44.51016286498251,0.442521188610831,-0.21395153074741824
389.80000000000484,44.61739478575624,0.44290829874608695,-0.21749714266074083
390.9000000000048,44.72355666120714,0.4426313139947742,-0.21352616727514695
392.00000000000483,44.83134825111489,0.4426457578554217,-0.2148503428917321
393.10000000000485,44.93756727620726,0.4419842539235477,-0.21617223573008149
394.2000000000049,45.04489445619827,0.4417060849662411,-0.21745910153833226
395.3000000000049,45.15152852947607,0.43985400390766816,-0.21752822377824854
396.4000000000049,45.2585529392466,0.44132426665502994,-0.2185150456483509
397.50000000000495,45.36465265186456,0.43890681074099325,-0.22067274740733467
398.6000000000049,45.472613937983425,0.4403130397337848,-0.22486100158618028
399.70000000000493,45.57966373699715,0.4414864923464719,-0.22747636207486188
400.80000000000496,45.68613575510323,0.44017433059771205,-0.2269900405368559
401.900000000005,45.79159067766176,0.44069102365464385,-0.22608090374735657
403.000000000005,45.900467009817085,0.4417658085954319,-0.22879999819979613
404.100000000005,46.007426778040276,0.44211196982427237,-0.23011148265734027
405.20000000000505,46.11415748685091,0.4407210317367307,-0.23117010149133455
406.30000000000507,46.221326048777655,0.4419273363243581,-0.234060769844203
407.4000000000051,46.3286961260937,0.44272624892392676,-0.23733236862727036
408.50000000000506,46.436101646957006,0.44860077967775425,-0.23866980521536796
409.6000000000051,46.54255356208373,0.44688252783881005,-0.2399737319854478
410.7000000000051,46.65097544933746,0.44635888361734904,-0.2433690901096912
411.8000000000051,46.75780875766485,0.446948042981817,-0.24855158928084187
412.90000000000515,46.86498873666512,0.44872614763790714,-0.2498769602540758
414.0000000000052,46.972191099471814,0.45022466906974645,-0.2540768497731496
415.1000000000052,47.07916904385973,0.4538734305491816,-0.25639341444922037
416.20000000000516,47.18586724561258,0.45634985854664245,-0.2581328618368013
417.3000000000052,47.29265307091473,0.45958329611873827,-0.26221032480128104
418.4000000000052,47.39862126547983,0.46097211849164793,-0.26677631086451425
419.50000000000523,47.507745409903386,0.46383363100430225,-0.26675735264849987
420.60000000000525,47.61501503275171,0.46686095432187164,-0.2693135779477336
421.7000000000053,47.722617118670996,0.470701484885659,-0.27422160924301986
422.8000000000053,47.83019520879124,0.474405111493476,-0.2770711257960876
423.9000000000053,47.93691224170072,0.47994370527144486,-0.2809504145436845
425.00000000000534,48.044252545480646,0.4842078314585718,-0.28660207277653615
426.1000000000053,48.15151899390411,0.4876801189751153,-0.2942689529617266
427.20000000000533,48.258552016396195,0.49267549331380217,-0.302428715232657
428.30000000000535,48.36633209433772,0.4953477815264735,-0.30698551976472377
429.4000000000054,48.473546089738605,0.5017443386279566,-0.3135994203724102
430.5000000000054,48.580521415955616,0.5063197192029446,-0.32162396274545735
431.6000000000054,48.68820942563962,0.5117111283467561,-0.3276250302944441
432.70000000000545,48.795333135654474,0.5148743106453759,-0.3359125564002605
433.8000000000054,48.90248993654208,0.5196992241858046,-0.3453208424032792
434.90000000000543,49.010883122429,0.5274649829760583,-0.3546406769169099
436.00000000000546,49.118578248385305,0.5350009139897979,-0.36476192980208255
437.1000000000055,49.22697782134198,0.5451756919455235,-0.3756236156717794
438.2000000000055,49.33360984833593,0.5514536622045917,-0.3843838269548665
439.3000000000055,49.43906261643772,0.5603038496078006,-0.3967474809163978
440.40000000000555,49.548989009244934,0.5706575959561309,-0.40881672392319146
441.50000000000557,49.656161809304905,0.5833774345673522,-0.4247278760556559
442.6000000000056,49.763652943400075,0.5948271341506797,-0.43846757053042307
443.70000000000556,49.872037719728795,0.6064381988997726,-0.45488906168110876
444.8000000000056,49.97917097520457,0.6204211270058522,-0.4752605366400191
445.9000000000056,50.08768169236018,0.6352490495092973,-0.4920974972317729
447.0000000000056,50.19345921863952,0.6507709083598674,-0.5081794940709443
448.10000000000565,50.302245299841246,0.6710155252949863,-0.5313262993032501
449.2000000000057,50.410271123100074,0.6883540483078181,-0.5569298065510297
450.3000000000057,50.517612542998314,0.7091194261963534,-0.5803882685900374
451.40000000000566,50.625304231334184,0.7296764557966147,-0.6057066127515345
452.5000000000057,50.733440655789124,0.7556280139938933,-0.6341333611757767
453.6000000000057,50.8406629438857,0.7785890726869195,-0.6651554876390269
454.70000000000573,50.948454866408284,0.8041460479965244,-0.6982191166603231
455.80000000000575,51.05681335359037,0.8346944466514852,-0.7347063646299445
456.9000000000058,51.163223925759226,0.8657699127428804,-0.7692008840813922
458.0000000000058,51.271675052490224,0.9019089042554402,-0.8120397964285058
459.1000000000058,51.38105992761346,0.9336301764171304,-0.8596238921426194
460.20000000000584,51.48859682015487,0.9675812076828161,-0.9051476203844842
461.3000000000058,51.59666619446024,1.0042204820985954,-0.9591851760194134
462.40000000000583,51.70452795200355,1.0412501544904758,-1.0170841041791445
463.50000000000585,51.81278220371351,1.0805129338482953,-1.076441412879762
464.6000000000059,51.92022452694884,1.1186348067232605,-1.1399845000261863
465.7000000000059,52.0271030087651,1.1535849950842503,-1.2047195761639742
466.8000000000059,52.137579925885625,1.191566138212523,-1.276179895932764
467.90000000000595,52.24576680694581,1.232622715624221,-1.353293092735138
469.0000000000059,52.353622778811186,1.2703206152062378,-1.431584163641996
470.10000000000593,52.46142831966662,1.3068779228443013,-1.520021961072541
471.20000000000596,52.570782298743985,1.3414320037530905,-1.6108912129389292
472.300000000006,52.6788706726493,1.3743928389636149,-1.706446313754514
473.400000000006,52.78774883406382,1.4018180481040867,-1.809155489028612
474.500000000006,52.89589312399812,1.4304679546139125,-1.914132106298167
475.60000000000605,53.00461722502369,1.454524998510409,-2.0227711206000394
476.70000000000607,53.113359885420714,1.4785610734104169,-2.135544479455827
477.8000000000061,53.22106478816951,1.492066499170232,-2.2561522092242225
478.90000000000606,53.32945840417048,1.4952420221585307,-2.3735956746035827
480.0000000000061,53.43794860136002,1.4963517509971123,-2.4948649359309916
481.1000000000061,53.5463666976432,1.4864926803375482,-2.6229490543549074
482.2000000000061,53.65424943001662,1.4654995028110616,-2.7480420183355974
483.30000000000615,53.76350674399072,1.4326047176750192,-2.8757822081522404
484.4000000000062,53.871647969421446,1.3888680322487923,-3.001375850643933
485.5000000000062,53.979448701317,1.3280272679477823,-3.128033690166213
486.60000000000616,54.086875230783505,1.2626857963158997,-3.2402943741256642
487.7000000000062,54.19398185525861,1.1774226744701475,-3.3546975539129056
488.8000000000062,54.302271452594674,1.0728876402131842,-3.4671113472102495
489.90000000000623,54.41051380242465,0.9614393097586453,-3.5651840709216076
491.00000000000625,54.51701170876572,0.8399044475983368,-3.6526261632689883
492.1000000000063,54.623443305129335,0.7243086024811911,-3.7294153214031383
493.2000000000063,54.728004043123974,0.6115259265601527,-3.793390565729589
494.3000000000063,54.83799824087717,0.4997989221544028,-3.8528502891788916
495.40000000000634,54.94506618261588,0.4010840958538443,-3.8984034980080335
496.5000000000063,55.05238122159823,0.3153070202273929,-3.939920546502992
497.60000000000633,55.16003157353176,0.22965451600026165,-3.9685466082869034
498.70000000000636,55.26808261381528,0.15190566294929497,-3.989415313914625
499.8000000000064,55.375262442921986,0.08822642306037298,-4.003120758319657
500.9000000000064,55.483544289630515,0.037983874951195984,-4.0163604618226145
502.0000000000064,55.591780540563455,0.0015983537294373962,-4.023752580713892
503.10000000000645,55.69927207138463,-0.028161455330394047,-4.028618332619995
504.2000000000064,55.80784364904468,-0.04853445985147031,-4.029259976415229
505.30000000000643,55.914999012559946,-0.06283764343276,-4.030580147804899
506.40000000000646,56.02371005603225,-0.07269135852172759,-4.02926117475041
507.5000000000065,56.1322399505818,-0.0797711405474526,-4.0279098934277195
508.6000000000065,56.240462826583375,-0.08207542874013973,-4.029273544845156
509.7000000000065,56.347854650790275,-0.08354764192670405,-4.029269789419998
510.80000000000655,56.4566738153336,-0.07992841897019964,-4.030582864864311
511.90000000000657,56.565719173870846,-0.07745000880187153,-4.031899806049615
513.0000000000066,56.67387798083919,-0.07578020017702952,-4.031916469446291
514.1000000000065,56.78276009256385,-0.07458998480802465,-4.034530376971634
515.2000000000066,56.89164095685569,-0.07234386787396774,-4.033209739810625
516.3000000000065,57.00051923920022,-0.07227751804883298,-4.032688085145198
517.4000000000067,57.109355151009574,-0.07254586461197643,-4.031879425629056
518.5000000000066,57.21738877437104,-0.07139720923160675,-4.030470239100435
519.6000000000067,57.32604780802077,-0.07210256330249892,-4.030465383117234
520.7000000000066,57.435431032260304,-0.07565091537820329,-4.030446190604018
521.8000000000067,57.54558122317273,-0.07969181836649625,-4.032769923979139
522.9000000000067,57.653179680971114,-0.08336162899216071,-4.03082343679353
524.0000000000067,57.76219352712797,-0.08426697809960776,-4.027523710680349
525.1000000000067,57.870672401960874,-0.08764113419581643,-4.0275092426565715
526.2000000000068,57.98080991040627,-0.08948175669441949,-4.033018608856247
527.3000000000068,58.088115502120985,-0.08668978242695458,-4.03419982815468
528.4000000000068,58.19886170767346,-0.08544760506868893,-4.034528498222051
529.5000000000068,58.308846826162096,-0.08821007918839596,-4.03583958294357
530.6000000000068,58.41622040144881,-0.08634506838320766,-4.035839819000563
531.7000000000069,58.52616850374142,-0.08344358444449712,-4.035846196368999
532.8000000000068,58.63525516985598,-0.08307867542648795,-4.036500157414673
533.9000000000069,58.744091675256435,-0.08440159971334477,-4.0365100009424975
535.0000000000068,58.85329467559185,-0.08194710176912157,-4.035066150034638
536.100000000007,58.962129626940246,-0.07992314744872314,-4.034012336779729
537.2000000000069,59.07099302627823,-0.0772339387911481,-4.037388597624855
538.300000000007,59.17986807604707,-0.07741206468303702,-4.0373769848041885
539.4000000000069,59.288732073302654,-0.07769207418637075,-4.037380019256669
540.5000000000069,59.3986650816084,-0.07864945279914426,-4.034747660543664
541.600000000007,59.506555112438924,-0.0781014888197683,-4.033443541516729
542.700000000007,59.61664515982775,-0.07747131016936248,-4.034750025860087
543.800000000007,59.72590272949179,-0.07724901959566816,-4.034750027999973
544.900000000007,59.83404416168218,-0.07933513433510758,-4.034750090395842
546.000000000007,59.941737032034624,-0.0808629939852829,-4.033429387391919
547.1000000000071,60.05345430916657,-0.07981602532021131,-4.0347482416067315
548.2000000000071,60.16174388042125,-0.07991898377054663,-4.0349619180333836
549.300000000007,60.27101688309773,-0.07737246449046525,-4.037379789591169
550.4000000000071,60.377228041500146,-0.07823268735804811,-4.036070029912591
551.500000000007,60.489934191862055,-0.0758450803837315,-4.036069199016607
552.6000000000072,60.59917235249132,-0.07303330167868677,-4.034750032320078
553.7000000000071,60.70806010962142,-0.07467590327055379,-4.034750027248545
554.8000000000072,60.81742454366499,-0.07227196990381546,-4.036087567821374
555.9000000000071,60.92757772566924,-0.07167972320835936,-4.036069854973358
557.0000000000072,61.03299239663921,-0.07226431648141302,-4.034749509275934
558.1000000000072,61.14517531624325,-0.0715299894809781,-4.033774683840539
559.2000000000072,61.25414511354323,-0.07218272121943398,-4.034738191114134
560.3000000000072,61.360938852627044,-0.07051427320522241,-4.034655254114732
561.4000000000073,61.469063290395106,-0.0697052800883658,-4.034749853131115
562.5000000000073,61.58068535750519,-0.07272682979696965,-4.034749673547013
563.6000000000073,61.68882786674911,-0.07079895194949987,-4.036070078702556
564.7000000000073,61.79847780527893,-0.06984576063664888,-4.03607942859275
565.8000000000073,61.90438509046568,-0.06847596808688167,-4.038699791548577
566.9000000000074,62.01624337190968,-0.06920637692503728,-4.03869955899013
568.0000000000074,62.12568480356393,-0.06848857167566524,-4.040019085143431
569.1000000000074,62.234449511023705,-0.06806025053178394,-4.038706417472841
570.2000000000073,62.34246522386966,-0.06553932333376222,-4.037332011946271
571.3000000000073,62.450749418652464,-0.06680364653582516,-4.034742341812758
572.4000000000074,62.55998457514107,-0.06675259830772873,-4.034747473152839
573.5000000000074,62.66917000000075,-0.06613658319595744,-4.035740002435989
574.6000000000074,62.77803262856955,-0.06609074582810703,-4.0360698347640005
575.7000000000074,62.887193501299144,-0.0659855703770223,-4.037111687797856
576.8000000000075,62.99693578587445,-0.0662651849777427,-4.035740001971628
577.9000000000075,63.105097345320225,-0.06368097265575401,-4.035740001999701
579.0000000000075,63.21425126925743,-0.06277708488059774,-4.035740453169473
580.1000000000075,63.32355170127024,-0.06430116782431666,-4.037644005584114
581.2000000000075,63.433014376907906,-0.06403920670643393,-4.038377446440118
582.3000000000076,63.542539217715714,-0.06549579574281444,-4.037059703778753
583.4000000000076,63.65124543622387,-0.06708909800616597,-4.034417332500251
584.5000000000076,63.760365196529435,-0.06890983038871545,-4.033452531938928
585.6000000000076,63.8694708796483,-0.0666363795074007,-4.034749838590587
586.7000000000077,63.977209005679704,-0.06705712866741587,-4.037388696070416
587.8000000000077,64.0885152312832,-0.06884086341164658,-4.036097162638073
588.9000000000076,64.1983972436727,-0.06865961912396001,-4.033419518243087
590.0000000000076,64.30819029395002,-0.07028021076324464,-4.032110412063682
591.1000000000076,64.41749567818162,-0.069449914809178,-4.03549095896063
592.2000000000077,64.52648322220294,-0.06772151760081946,-4.036279912593273
593.3000000000077,64.63564205137162,-0.06701740403184808,-4.036263170518346
594.4000000000077,64.74543522829586,-0.06613006211389494,-4.037280272522771
595.5000000000077,64.85513841691807,-0.06548885162096568,-4.035959864159557
596.6000000000078,64.96435393380425,-0.06498026489753989,-4.035960093000123
597.7000000000078,65.07283501154161,-0.06777564625060778,-4.035960093001559
598.8000000000078,65.18376236343784,-0.06601908954356395,-4.035958057317246
599.9000000000078,65.29337127058712,-0.06520928389382918,-4.038784778242626
601.0000000000078,65.40072981252085,-0.0654656724525125,-4.0399100707547495
602.1000000000079,65.51182321989343,-0.06535813458131895,-4.039883780706985
603.2000000000079,65.62201024420943,-0.0660968430813822,-4.039901164515667
604.3000000000079,65.73206375082131,-0.06737726133132466,-4.0376793324529485
605.4000000000078,65.8406102099267,-0.06651209654679596,-4.0372700709221245
606.5000000000078,65.94989059290691,-0.06563252306201678,-4.0372700653909686
607.6000000000079,66.0595781732831,-0.06697198560393985,-4.038259393337939
608.7000000000079,66.16775271075304,-0.06596758166274386,-4.038259841572351
609.8000000000079,66.27835990590556,-0.06622862637268356,-4.0372810480898185
610.9000000000079,66.38889790498354,-0.06656589723695067,-4.038594798683632
612.000000000008,66.49780166508161,-0.06567283675938546,-4.037609952294358
613.100000000008,66.60584198030026,-0.06470370405503245,-4.037610812820803
614.200000000008,66.71838706518093,-0.06918964607239714,-4.037956242930284
615.300000000008,66.82748956086077,-0.06914504417797945,-4.040243339383849
616.400000000008,66.93657651928973,-0.0705262791605401,-4.039282506591493
617.5000000000081,67.04752300005268,-0.07268940030813797,-4.037940392179734
618.6000000000081,67.15674096237599,-0.07399838166354067,-4.039259981300576
619.7000000000081,67.26601761883967,-0.07317043731334688,-4.04056876890503
620.8000000000081,67.3759397845523,-0.07741217890815683,-4.037912098524133
621.9000000000082,67.48459553088088,-0.07861145175614898,-4.037939913730096
623.0000000000082,67.59493097444745,-0.0776479432905931,-4.0392492853703565
624.1000000000081,67.70417238705883,-0.07581927054191523,-4.039249988000477
625.2000000000081,67.81429724994331,-0.07439819111964996,-4.039249895007579
626.3000000000081,67.92344453928008,-0.07717017685684352,-4.037930129241221
627.4000000000082,68.03304889346624,-0.07785893200779082,-4.0368677539623326
628.5000000000082,68.14257131268644,-0.07833036904059693,-4.036237388832713
629.6000000000082,68.25218077210235,-0.07841366160610924,-4.03990948585531
630.7000000000082,68.36191921443299,-0.07378147538279933,-4.040236007378108
631.8000000000083,68.4706934278111,-0.07675939830101774,-4.040240173615084
632.9000000000083,68.58014757657189,-0.07860232496231578,-4.038920075675574
634.0000000000083,68.68974942817508,-0.08038691945483206,-4.038920390262172
635.1000000000083,68.79917213384236,-0.08196794814490344,-4.0376016340016205
636.2000000000083,68.90784701567335,-0.08152707189374786,-4.040350174758609
637.3000000000084,69.0168132198216,-0.08285849297820436,-4.0408519694368845
638.4000000000084,69.12734383249591,-0.08225381260192544,-4.042998514066281
639.5000000000084,69.23607899386097,-0.08098688361226808,-4.042978382625997
640.6000000000083,69.34553236293364,-0.08358933332259888,-4.041777236305869
641.7000000000083,69.45528261262274,-0.08432082852735712,-4.040353473438665
642.8000000000084,69.5641696371496,-0.08225675370183239,-4.037440316093854
643.9000000000084,69.67468381988009,-0.08197902152746878,-4.039537255067144
645.0000000000084,69.7834201292923,-0.08128637039830477,-4.043079115565833
646.1000000000084,69.89451189552776,-0.08242857520315322,-4.0430630977672335
647.2000000000085,70.00366829818219,-0.08413347983042474,-4.04187389952068
648.3000000000085,70.11262895872493,-0.07985179371801149,-4.040459980970583
649.4000000000085,70.22326052686702,-0.07995312792206205,-4.0404599809991435
650.5000000000085,70.33306757299975,-0.08305316216984482,-4.040461410860641
651.6000000000085,70.44210325303227,-0.08281372059994663,-4.041779781764985
652.7000000000086,70.55230024730425,-0.08190491363193081,-4.043088829544457
653.8000000000086,70.66170593574707,-0.08225654232843238,-4.044410227266804
654.9000000000086,70.77186087701135,-0.08371733016686717,-4.047040016751116
656.0000000000086,70.88210849898276,-0.07990782443310634,-4.048031317016954
657.1000000000087,70.99238658690653,-0.0798369560111073,-4.043657399519469
658.2000000000087,71.10171476768234,-0.07780710612877317,-4.039313122825843
659.3000000000086,71.21143833610755,-0.07510461471456387,-4.039050947514852
660.4000000000086,71.3217457932816,-0.07291817113756005,-4.039518458433335
661.5000000000086,71.43132334223016,-0.07139831709881428,-4.041312529532541
662.6000000000087,71.54101555078891,-0.07229826305933301,-4.040023505696684
663.7000000000087,71.65020273074609,-0.07008456782251665,-4.0387002587269505
664.8000000000087,71.75725999301906,-0.0688988280588963,-4.040004674339851
665.9000000000087,71.86748937175138,-0.06884767242366724,-4.039689424591418
667.0000000000088,71.9785037955505,-0.0673692617983383,-4.03858981515191
668.1000000000088,72.08877158221689,-0.07073192076489732,-4.038679363977891
669.2000000000088,72.19906932858784,-0.06767903244522028,-4.04122959125956
670.3000000000088,72.30807573387838,-0.06961413934081345,-4.039909855877434
671.4000000000088,72.41692171401765,-0.0718260732476137,-4.0399096914251675
672.5000000000089,72.52821362937866,-0.07034918720200878,-4.042885146706906
673.6000000000089,72.63937801795488,-0.06967491907784001,-4.0418790719857425
674.7000000000089,72.7477714434909,-0.06724565295062412,-4.040570220631337
675.8000000000088,72.85883366280622,-0.06837351300830147,-4.040240221771331
676.9000000000088,72.96833833751205,-0.07256723731612069,-4.0389728601718655
678.0000000000089,73.0779966575355,-0.07443282619468405,-4.040816219832129
679.1000000000089,73.18732873639802,-0.07695934106833163,-4.042692956832865
680.2000000000089,73.2985949438278,-0.07918549064163999,-4.041333877750018
681.3000000000089,73.40866364732712,-0.08184291218998624,-4.038699617096388
682.400000000009,73.51842962961369,-0.0831845279094865,-4.039946929696637
683.500000000009,73.62803077177584,-0.08259063387285426,-4.040036122755233
684.600000000009,73.73917222767209,-0.08106876926161849,-4.0400199510823285
685.700000000009,73.84859711857015,-0.08210548166305326,-4.040011181483864
686.800000000009,73.959370491832,-0.08517577902359874,-4.040680280464424
687.9000000000091,74.06938943766458,-0.08421749288363861,-4.041337316277183
689.0000000000091,74.1797900214933,-0.08371133859799496,-4.041978383532114
690.1000000000091,74.2888905058257,-0.08292572370088591,-4.040002258411584
691.2000000000091,74.39980145623234,-0.08530881010625674,-4.038699930348764
692.3000000000092,74.50939263337384,-0.09113301858101042,-4.041383298329038
693.4000000000092,74.61987631713288,-0.09068126363808243,-4.040028792754329
694.5000000000091,74.73078517414345,-0.09517925491395662,-4.039359583026026
695.6000000000091,74.84050494108745,-0.09786891163985606,-4.040439830735373
696.7000000000091,74.95116951056654,-0.09571460413016597,-4.043395505864678
697.8000000000092,75.06120485512584,-0.09723003467313945,-4.044807513249534
698.9000000000092,75.17123733546006,-0.09443143443973862,-4.044284238767
700.0000000000092,75.28208751853886,-0.09305731278496965,-4.0459472724435
701.1000000000092,75.39262839109058,-0.09547176253351286,-4.046130425934028
702.2000000000093,75.5035222707356,-0.09363411822130185,-4.044853643458458
703.3000000000093,75.61310625965076,-0.09907829527183298,-4.043865540966147
704.4000000000093,75.72442503110953,-0.1015808092797435,-4.043714123975318
705.5000000000093,75.83387133097303,-0.10069851430170096,-4.043540133796781
706.6000000000093,75.94520862407458,-0.10279513185832995,-4.041930866034653
707.7000000000094,76.05532282810654,-0.10129196907935434,-4.040704009278348
708.8000000000094,76.1661853162868,-0.1020797028017244,-4.0420001150566165
709.9000000000094,76.27504809854618,-0.10570114323441893,-4.041939594151291
711.0000000000093,76.38652441876496,-0.10390759529587085,-4.0393619609082245
712.1000000000093,76.49575419227075,-0.10057311040864769,-4.040871404233697
713.2000000000094,76.60661142550957,-0.10192205375441721,-4.041155008547906
714.3000000000094,76.71666573724526,-0.10394908023402083,-4.043566684300517
715.4000000000094,76.82695927410987,-0.10141597512666861,-4.0461160443342035
716.5000000000094,76.93732237357014,-0.10405263765454348,-4.045620126773466
717.6000000000095,77.04651090443384,-0.10723058206997121,-4.0431906326198135
718.7000000000095,77.1570154566278,-0.10937318391347961,-4.042992626772867
719.8000000000095,77.26671183459291,-0.11124065519319498,-4.042792875733602
720.9000000000095,77.37847107779955,-0.11070453444827966,-4.041504168930045
722.0000000000095,77.48803302061069,-0.11069195157826278,-4.042400942728733
723.1000000000096,77.59773892417178,-0.10643057647243159,-4.041631472991359
724.2000000000096,77.70854472312888,-0.10704991641717831,-4.04035038694185
725.3000000000096,77.81917091085973,-0.10413518977220737,-4.041659564367065
726.4000000000096,77.92927074120587,-0.10815510210446411,-4.043431157861313
727.5000000000097,78.03978457561952,-0.10904922027395364,-4.044530089035393
728.6000000000097,78.15063825869942,-0.11338470060026962,-4.044343825325537
729.7000000000096,78.26106954081273,-0.11146298351218997,-4.042172978956411
730.8000000000096,78.37143962382986,-0.11332969532516446,-4.04362445370991
731.9000000000096,78.48118121226545,-0.11313162928787862,-4.043739513855202
733.0000000000097,78.5919063670163,-0.1097550870957934,-4.037180735575189
734.1000000000097,78.70269311500944,-0.10692552026219448,-4.037489274859369
735.2000000000097,78.81271999249356,-0.10417195769649318,-4.038455088646076
736.3000000000097,78.9226495049069,-0.1017873068597216,-4.042435438957175
737.4000000000098,79.03375750541176,-0.09916594993855943,-4.042430067339763
738.5000000000098,79.14421830692291,-0.09743714028796929,-4.041118506912485
739.6000000000098,79.25524921577973,-0.09491566165478582,-4.042809747799209
740.7000000000098,79.36619152877137,-0.09784766226511676,-4.043987417968123
741.8000000000098,79.47578911537016,-0.0997099633997901,-4.040683268992808
742.9000000000099,79.58715823039707,-0.0982498813619756,-4.039166127302905
744.0000000000099,79.69753599764955,-0.10035112203545243,-4.04068885590795
745.1000000000099,79.80751156475965,-0.10226092479144272,-4.0419984700521265
746.2000000000098,79.91778735662142,-0.10103346393074703,-4.039275432660145
747.0000000000099,79.99864516416275,-0.10288642787243846,-4.039385092769854