File: 01_Data/EIFS_Mesh/STA/N2/3K_min/EIFS_Mesh_STA_N2_3KData_230907_R1.csv
##Temp./Â°C,Time/min,DSC/(mW/mg),Mass loss/mg
41.0,11.272792596778483,0.014045227350841571,0.002677625235751435
42.100000000000016,11.840580711953326,0.02957235667838143,0.003951205269420832
43.20000000000003,12.309170000000018,0.038112218374846574,0.00394860705658262
44.30000000000005,12.74128555736905,0.04334620928330013,0.0032864604357780713
45.40000000000006,13.159170000000056,0.047280301573254135,0.0026300164021351158
46.50000000000008,13.577669281573788,0.04897149483361529,0.003157596050752609
47.600000000000094,13.97873471713251,0.05257668910399316,0.0021976573929580745
48.70000000000011,14.367154665607027,0.05423679659604863,0.0022974105730471095
49.800000000000125,14.765376119092911,0.05648983273189634,0.002636733608563091
50.90000000000014,15.148533207454097,0.058084019307130585,0.00231006402651035
52.000000000000156,15.538534326683902,0.06262547400037288,0.0009818044448048902
53.10000000000017,15.953623578752286,0.06248899662334528,0.0009938626388512617
54.20000000000019,16.296333872924183,0.062588756130463,1.45599190926049e-07
55.3000000000002,16.66742911393511,0.06503916974344692,0.0003124915462260347
56.40000000000022,17.041795233591127,0.06729348321875417,0.0012016195091257842
57.500000000000234,17.411088102905715,0.06980652079809557,0.00019238101429097654
58.60000000000025,17.792174703250343,0.0702886154747282,0.00032999665304611625
59.700000000000266,18.149862237781463,0.07090598167251017,-0.0003306798885458484
60.80000000000028,18.530948349256203,0.0710702868311226,-0.0009814998015715837
61.9000000000003,18.91237871652024,0.07337975987930045,-0.0008803890240041135
63.00000000000031,19.270483326400825,0.07414126112523522,-0.002001045782410671
64.10000000000034,19.640393172339643,0.0772319533590271,-0.002200395564130986
65.20000000000034,20.00406593095127,0.07771963485202527,-0.0031675112383311443
66.30000000000035,20.376868104162902,0.07728514621409976,-0.0031800305675848684
67.40000000000038,20.744580930098977,0.0768278487073406,-0.004240126594035498
68.5000000000004,21.10736948466067,0.07748907176609343,-0.004839932207589381
69.6000000000004,21.47561338546258,0.07570150809990306,-0.004596486955367851
70.70000000000041,21.837667545615197,0.07623953395079885,-0.004276047943744921
71.80000000000044,22.207883058998306,0.07605451357172166,-0.004819457496600954
72.90000000000046,22.569164762764775,0.07516451368421695,-0.005361771366194645
74.00000000000047,22.93738339850192,0.0773373280471259,-0.0065857382652509955
75.10000000000048,23.305518884386366,0.0778510581844607,-0.00638315283444868
76.2000000000005,23.6694470737153,0.07874052862390712,-0.0064798320046235425
77.30000000000052,24.033682434944723,0.07827704741968233,-0.0067353708765227616
78.40000000000053,24.40261423231609,0.07925989740280093,-0.007799963999999271
79.50000000000054,24.775734101680293,0.07807200256626379,-0.008119410525087911
80.60000000000056,25.140848697481697,0.07838871038604456,-0.008450116942139818
81.70000000000059,25.505525972911173,0.0793728603221191,-0.008193288280419875
82.8000000000006,25.869511809786303,0.07823400932975089,-0.0067272449123003675
83.9000000000006,26.23414566250328,0.07772595916372227,-0.009675313701917876
85.00000000000063,26.598247023096,0.07821475540510159,-0.008131081138914809
86.10000000000065,26.963058857123478,0.0792471474014107,-0.009439997466384575
87.20000000000066,27.324735119842668,0.07872546517013923,-0.01142922027321358
88.30000000000067,27.68917000000013,0.0797297648797528,-0.012062891091524808
89.40000000000069,28.051502624982533,0.08108739408555943,-0.010757612583694787
90.50000000000071,28.418839646312364,0.07973290125949761,-0.012399994867048125
91.60000000000072,28.785310479604952,0.08115681776961425,-0.013719826375470312
92.70000000000073,29.147649442221898,0.08170542234924572,-0.013261297067092226
93.80000000000075,29.50415142671131,0.08076616642686929,-0.012302543890923445
94.90000000000077,29.85852062616943,0.08121183486630157,-0.01230000953709931
96.00000000000078,30.23797015148982,0.08099293096706583,-0.014928166699842649
97.10000000000079,30.602367497885417,0.08174807531034967,-0.014599489493718476
98.20000000000081,30.965754117420484,0.08354484100606596,-0.015332310537761185
99.30000000000084,31.324859297922764,0.08328360864689577,-0.014269281013298496
100.40000000000084,31.689751514805202,0.08024628343314077,-0.014281192534796094
101.50000000000085,32.04992925303538,0.08328740985106009,-0.014914448710318329
102.60000000000088,32.41037971606804,0.08134677120812839,-0.014907205642742838
103.7000000000009,32.77095968948945,0.08046914215752876,-0.015589840004656352
104.8000000000009,33.13300930645452,0.07940887566434984,-0.015502573352452753
105.90000000000092,33.492526416819025,0.08064307269606008,-0.01691054843518769
107.00000000000094,33.85874621438538,0.08011849828788975,-0.016580335084225073
108.10000000000096,34.21790163134636,0.08004903909379069,-0.016632814036831256
109.20000000000097,34.58163299430013,0.07840941719064087,-0.017239971907397234
110.30000000000098,34.93643866801146,0.07830645696712413,-0.01826223376989322
111.400000000001,35.297127295862786,0.07748533770962229,-0.0172296141456445
112.50000000000102,35.66036470724213,0.0787684483887725,-0.01821974377169866
113.60000000000103,36.02104205593701,0.07786946948273776,-0.018219840000002208
114.70000000000104,36.379568223179724,0.07872639588000974,-0.018243697348846233
115.80000000000106,36.743525003979734,0.07983672633092542,-0.018560136000015603
116.90000000000109,37.101921062161345,0.08012632358956351,-0.01822994802822997
118.0000000000011,37.465649596602645,0.08041686118956282,-0.019550151877574695
119.1000000000011,37.82176600124848,0.08036874800271265,-0.02092600151511137
120.20000000000113,38.175070656047815,0.0808655277520165,-0.019869835015615234
121.30000000000115,38.54731667371638,0.08162961279528824,-0.019539922050995973
122.40000000000116,38.90429688578871,0.08042689167549044,-0.019540003999998667
123.50000000000117,39.26813990126932,0.08046175802302447,-0.020840666446526157
124.60000000000119,39.62949158613261,0.07870482029295145,-0.019540136323852764
125.70000000000121,39.9885394066957,0.08025665723523412,-0.020532675017740143
126.80000000000122,40.35590179045348,0.078812552010465,-0.020199874510681948
127.90000000000123,40.709581658844044,0.07670566708715176,-0.02019987694345904
129.00000000000125,41.06800894846593,0.08007330241962762,-0.02184987199986299
130.10000000000127,41.42956009623853,0.0770790826317973,-0.021849871881151284
131.2000000000013,41.79159769638863,0.07765074110481729,-0.020800006647102798
132.3000000000013,42.146539621994044,0.07932912893689403,-0.022116698254557754
133.4000000000013,42.50771576445875,0.07922614573482845,-0.0226429407378288
134.50000000000134,42.85963332952599,0.07837575940357988,-0.022279620902542874
135.60000000000133,43.22545410843195,0.07681059243164823,-0.02098732205405085
136.70000000000135,43.58185809396442,0.07739646030782721,-0.021298223980557918
137.80000000000138,43.94220698369099,0.07662170793356626,-0.024285284656942352
138.9000000000014,44.30271160260908,0.07720806536269142,-0.02261990399995728
140.00000000000142,44.660170409632514,0.0756837178411165,-0.021960168828787374
141.10000000000142,45.014437672342936,0.0773471252894331,-0.0232801650329435
142.20000000000144,45.37585133160702,0.07697290448446825,-0.02328052863241936
143.30000000000146,45.735106267094665,0.07843597331088681,-0.021960115260514446
144.40000000000146,46.09601963975902,0.08033982504366621,-0.02328168749941195
145.50000000000148,46.45081513281284,0.07840786344087292,-0.022259622211427743
146.6000000000015,46.811043866933616,0.08095530403439088,-0.024602305010637426
147.70000000000152,47.16651724006714,0.07946465285771476,-0.024590538782687688
148.80000000000155,47.518704827011895,0.07993987854357743,-0.023269904001170794
149.90000000000154,47.879252998421926,0.0808231679479694,-0.02525133696827142
151.00000000000156,48.24271074735997,0.08101903512206299,-0.02525003600000275
152.1000000000016,48.599165545249626,0.08011094878396419,-0.024920168000001297
153.20000000000158,48.95304336851551,0.0795534960198534,-0.02492016800000041
154.3000000000016,49.31155132753712,0.07942392279228105,-0.024920162091095044
155.40000000000163,49.66864785276195,0.08190950656456097,-0.025579041245791245
156.50000000000165,50.02528852081301,0.08223015832394909,-0.02690425065310542
157.60000000000167,50.39089009463123,0.08301998189883308,-0.026900199493578913
158.70000000000167,50.735894197077755,0.08593568582028865,-0.02690003725464507
159.8000000000017,51.09889878407793,0.08699862312707163,-0.026900052370489203
160.9000000000017,51.45724560629526,0.08527851397740571,-0.026240575813905043
162.0000000000017,51.813855163731965,0.08781771795138527,-0.02630143095596127
163.10000000000173,52.17579111270956,0.08791792161853751,-0.02659644805854189
164.20000000000175,52.53215657705774,0.0913066317475022,-0.026566143113269547
165.30000000000177,52.885759634844625,0.08918619938549055,-0.026499971415848478
166.4000000000018,53.24636102870149,0.09028071339651711,-0.027889904993014802
167.5000000000018,53.608717866301134,0.09192830189631107,-0.02689990439459322
168.6000000000018,53.96738871612617,0.09055679444772702,-0.027560043447318883
169.70000000000184,54.31917000000075,0.09030122104037686,-0.02789003600000184
170.80000000000183,54.67844851157669,0.0942605413204387,-0.02789003512071897
171.90000000000185,55.0329332823722,0.089910004092979,-0.027220174531222163
173.00000000000188,55.38943833245182,0.09252312669291207,-0.028870041888735543
174.1000000000019,55.740666393168354,0.09159320409500515,-0.027551250276230732
175.20000000000192,56.097294212759444,0.09233158992401536,-0.02789942500498377
176.30000000000192,56.453128804034975,0.09463571361347745,-0.027550031483976944
177.40000000000194,56.81151550573422,0.09639809371640218,-0.029199904000000387
178.50000000000196,57.16820598906618,0.09613818845140765,-0.0291999039999995
179.60000000000196,57.53152662097954,0.09651205534519258,-0.029199904119797893
180.70000000000198,57.888130088493064,0.0964428891709721,-0.02817369500080691
181.800000000002,58.23896529598328,0.09675808956860332,-0.029529903882066222
182.90000000000202,58.59999082646069,0.09683881598346944,-0.030901916621704828
184.00000000000205,58.951299643421585,0.09704624188747424,-0.03095771312224249
185.10000000000204,59.31070493208695,0.09789983631858279,-0.030520035999993755
186.20000000000206,59.66672730228785,0.09633638571134773,-0.03052003561410599
187.3000000000021,60.02408498853404,0.09769438169815214,-0.03019003600154324
188.40000000000208,60.384911658869925,0.09769436168506629,-0.03051993797418895
189.5000000000021,60.741438416010894,0.09912418814496493,-0.030189874101316683
190.60000000000213,61.09415988117639,0.09928043111148832,-0.030179928842654302
191.70000000000215,61.452683399473095,0.09862810357571794,-0.031180168000001007
192.80000000000217,61.812278126773855,0.0980388213150285,-0.02986016688520632
193.90000000000217,62.16815625656063,0.0996043776206923,-0.031179598809646603
195.0000000000022,62.52558810263031,0.102677452768688,-0.029531146819290033
196.1000000000022,62.87797482199815,0.10130628506984496,-0.03085589599257199
197.2000000000022,63.23800482479898,0.09869926873811274,-0.031368926776680794
198.30000000000223,63.60186399944919,0.10089057182947347,-0.03150990400000664
199.40000000000225,63.95204068293783,0.09903339988005988,-0.030519864831646704
200.50000000000227,64.30890800765347,0.09931985205691296,-0.03258480429167676
201.6000000000023,64.67315957427864,0.09955602244324702,-0.032171318113795255
202.7000000000023,65.02190923990517,0.10035446426529049,-0.03315016799998993
203.8000000000023,65.3781047839476,0.10036540595506604,-0.033152825995163226
204.90000000000234,65.73230053482926,0.10250263200785548,-0.03282016799999976
206.00000000000233,66.08365578422679,0.10296495048112808,-0.032820168214610757
207.10000000000235,66.44534610013262,0.10454434284549641,-0.03483773817915514
208.20000000000238,66.79499308138719,0.10460529350150516,-0.03248990396601048
209.3000000000024,67.15629807120612,0.10656345311558146,-0.0324899744237821
210.40000000000242,67.4460524532014,0.10626171067028811,-0.03479997804849999
211.50000000000242,67.85596475989017,0.1050573791214171,-0.03480016799998209
212.60000000000244,68.21979189771717,0.10497837517703679,-0.035130168000002904
213.70000000000246,68.57531413221517,0.10673825557553962,-0.03513016799749602
214.80000000000246,68.93593509004761,0.10788726797874215,-0.03447600450632882
215.90000000000248,69.29045256932234,0.10759220077655063,-0.035286351787366055
217.0000000000025,69.63803389526475,0.10857646567237977,-0.035130164766878025
218.10000000000252,70.00283710549282,0.1076984476227445,-0.03513016806059133
219.20000000000255,70.35623386097004,0.10913958849055638,-0.03546016762302129
220.30000000000254,70.71204139800997,0.11159814621549913,-0.035128494218399364
221.40000000000256,71.0677525655604,0.11010309190216527,-0.03611966815740164
222.5000000000026,71.42785301676973,0.11212777559505804,-0.03581271836645161
223.60000000000258,71.78326371625656,0.11103072958720372,-0.0346387727321007
224.7000000000026,72.1429090854888,0.11228894971174874,-0.03549850407084332
225.80000000000263,72.4938197329775,0.11345136691782409,-0.036716410117538345
226.90000000000265,72.85143303710545,0.11607209345376868,-0.037953380536235315
228.00000000000267,73.2082996402197,0.11280061258771679,-0.03792514360062693
229.10000000000267,73.56523709092725,0.11496649914523549,-0.038529965828693946
230.2000000000027,73.92484874303148,0.11539772524043257,-0.03721994601171641
231.3000000000027,74.27954953299954,0.11461796815982561,-0.03592103162969895
232.4000000000027,74.63699260941777,0.11563073348450392,-0.03719556807689006
233.50000000000273,74.99439798707594,0.11341387775598122,-0.03788007999963616
234.60000000000275,75.34556406486514,0.11517518473357535,-0.03930004902764228
235.70000000000277,75.70372501713096,0.11447948665225027,-0.03930004799792375
236.8000000000028,76.05046925993294,0.11505529810928361,-0.039315416254077196
237.9000000000028,76.41180590981972,0.11421050270189581,-0.03929818295596599
239.0000000000028,76.76224614459225,0.11773560569302988,-0.03996018000000001
240.10000000000284,77.11596218235702,0.11543493931460813,-0.03996017990409095
241.20000000000283,77.47519726463602,0.11391851569807687,-0.041276872446281754
242.30000000000285,77.82917000000083,0.11703230897177064,-0.04227035951776381
243.40000000000288,78.18782582105143,0.11672680963837756,-0.043294264054847265
244.5000000000029,78.54380708988788,0.11677311178079952,-0.040496712105186905
245.60000000000292,78.90219402200863,0.11382916245439967,-0.043149827999999335
246.70000000000292,79.25334834021182,0.11438004436830185,-0.04314983141897866
247.80000000000294,79.61313841129669,0.114203856396067,-0.04412916679318979
248.90000000000296,79.9659235921602,0.11560693819586088,-0.04347998210064441
250.00000000000296,80.32251681585134,0.11538645627802069,-0.04379821957573293
251.10000000000298,80.67999689109196,0.11485834225876146,-0.04379992798437504
252.200000000003,81.03643226137213,0.11707487779521197,-0.04444240645163777
253.30000000000302,81.38917000000103,0.1177921637888586,-0.04512019199999928
254.40000000000305,81.7502531748178,0.11808143386010128,-0.04512019199998507
255.50000000000304,82.10538756088332,0.11982573348505077,-0.045120191999998394
256.6000000000031,82.45813307183239,0.1177409481824947,-0.04512019673453738
257.7000000000031,82.81208148606319,0.11860328884230631,-0.045120192034952655
258.8000000000031,83.17157323447813,0.11679916786198685,-0.045120191094466744
259.9000000000031,83.52608229830619,0.11924750611344126,-0.04743005901262487
261.0000000000031,83.88387702122992,0.11883222961845186,-0.04544633923993002
262.10000000000315,84.23771878258374,0.12070606729254707,-0.048018839082102804
263.2000000000032,84.59416818205105,0.12432968088039531,-0.04875002254312166
264.30000000000314,84.94446247693823,0.12265578098544672,-0.049950428876258446
265.40000000000316,85.30453430672677,0.12208247779679682,-0.04973992741274724
266.5000000000032,85.66174627571054,0.12430967664070236,-0.048419966352577504
267.6000000000032,86.0180491065165,0.12223815778937275,-0.04973226261100905
268.70000000000323,86.37366270469602,0.1252415561295528,-0.04948896327472374
269.80000000000325,86.72775456496589,0.12398311444411547,-0.050720028048403254
270.9000000000033,87.08855130678376,0.1240805570047574,-0.050720038034745674
272.0000000000033,87.4467942517687,0.12560471434869092,-0.0512127044592976
273.1000000000033,87.80369820743594,0.12449304954666984,-0.05108490771762808
274.20000000000334,88.1626273087416,0.12764626816547775,-0.052478507274278385
275.30000000000337,88.52116727552412,0.12732176331946854,-0.05379985200000004
276.40000000000333,88.88462610142308,0.12792724255158405,-0.05379979629848952
277.50000000000335,89.24169878629525,0.1282725502939439,-0.055432974346131925
278.6000000000034,89.59850843689392,0.13129968532249348,-0.054120897917135924
279.7000000000034,89.95411573071496,0.13004213132401343,-0.05411982369653767
280.8000000000034,90.31296006090106,0.1301388954766547,-0.05677098719067075
281.9000000000034,90.66686113453288,0.13226461911522236,-0.05678829084210557
283.0000000000034,91.02457820181628,0.1299789654938266,-0.05837087230692761
284.10000000000343,91.38048866782728,0.1306456209541038,-0.06088991184816983
285.20000000000346,91.74337473320422,0.13075357856122172,-0.05949925334791706
286.3000000000035,92.1005719339544,0.13176140289486304,-0.059836873084812225
287.4000000000035,92.46202881586235,0.13394179244780413,-0.06385106618703862
288.5000000000035,92.81402023129446,0.1360234684906949,-0.06251182485631235
289.60000000000355,93.17416370238564,0.13464095014214905,-0.06247000794292212
290.70000000000357,93.53028525618491,0.1392436984647667,-0.06312980693092074
291.8000000000036,93.88585329190946,0.1408546950052938,-0.06309746826542684
292.9000000000036,94.24129464810909,0.14245737233500932,-0.0653788352003315
294.0000000000036,94.60289080778234,0.1461369628056337,-0.06676485326269432
295.1000000000036,94.95901618505238,0.14639770091327797,-0.06872982882706191
296.2000000000036,95.31955997096598,0.14808533479282526,-0.07136053680343579
297.30000000000365,95.6807132466854,0.14699057272150728,-0.07004006921687234
298.4000000000037,96.0382341264729,0.15199959075104963,-0.0723499520150237
299.5000000000037,96.39545432087864,0.15111901332562527,-0.07436257587901007
300.60000000000366,96.75579710897945,0.15413244715413632,-0.07530926148796002
301.7000000000037,97.11472239445044,0.15688263852439777,-0.07596923192404326
302.8000000000037,97.4666157292906,0.1597545554454789,-0.07892129140594051
303.90000000000373,97.82004078774621,0.1643297564982451,-0.08024988000002375
305.00000000000375,98.18782776649728,0.16905384404945822,-0.0802498799239717
306.1000000000038,98.54414740036337,0.1712711490401153,-0.08161246232011177
307.2000000000038,98.9019172590259,0.1745534861054956,-0.08419991631687473
308.3000000000038,99.26106372705344,0.1793478897264711,-0.08749029507414585
309.40000000000384,99.6201507587467,0.1789024086393738,-0.08946997476692031
310.5000000000038,99.9766272593359,0.18385255980992987,-0.09277224398519612
311.60000000000383,100.33590397009479,0.18710490686193082,-0.0944290491180233
312.70000000000385,100.69423346412555,0.18590322420659677,-0.09737544301505086
313.8000000000039,101.05051530915365,0.18722974285684324,-0.09968155063667972
314.9000000000039,101.40708360972725,0.18793507988156,-0.10132708586113415
316.0000000000039,101.76953215130264,0.18586560680313524,-0.10629146512094634
317.10000000000394,102.12004402712854,0.1869054946508828,-0.11021982716709067
318.2000000000039,102.48821465989485,0.1882583686397552,-0.1129035390503983
319.30000000000393,102.8431103689753,0.18885446857801957,-0.11724616115644837
320.40000000000396,103.19788382871722,0.1863210267362274,-0.11854734701305825
321.500000000004,103.5579844678679,0.1856599836397188,-0.12284995371382124
322.600000000004,103.91527374131316,0.184345893066989,-0.1254956002265466
323.700000000004,104.27385459174845,0.18577214821078503,-0.1304462648948701
324.80000000000405,104.63449764307917,0.1833336548933866,-0.13431172687538107
325.90000000000407,104.99667328634857,0.1840805505760068,-0.1380000053571071
327.0000000000041,105.35806322197904,0.1818246799354577,-0.14315948005534196
328.10000000000406,105.71284426876335,0.18352470130005716,-0.14600995220785906
329.2000000000041,106.07508808836421,0.17866274692575335,-0.1486452108480747
330.3000000000041,106.43232555625612,0.17722136666323185,-0.15260062231248694
331.4000000000041,106.79213147413714,0.17525251817115128,-0.15555983887080016
332.50000000000415,107.14917000000155,0.1749484156049106,-0.15819803368659446
333.6000000000042,107.50913480572109,0.17418611336794276,-0.16149681546074834
334.7000000000042,107.87030030782749,0.17285866496417346,-0.16542656710741888
335.80000000000416,108.23267939291418,0.16831004028881646,-0.16840927303715603
336.9000000000042,108.58886917180742,0.16662422069062988,-0.16942448691530076
338.0000000000042,108.94917000000112,0.16646098939661558,-0.17202987605989728
339.10000000000423,109.30883137422146,0.1604399328619921,-0.1766393960488002
340.20000000000425,109.67055134929048,0.16053666171459424,-0.17665118726828855
341.3000000000043,110.02953262208449,0.16122696183073693,-0.17829003910534924
342.4000000000043,110.3915179174571,0.15628467306531935,-0.17967638232674954
343.5000000000043,110.74955581126915,0.1546125954458808,-0.18228501359284843
344.60000000000434,111.10806798572486,0.155257464042434,-0.18486120186331512
345.7000000000043,111.46827506040998,0.15408570364404506,-0.18421065626881816
346.80000000000433,111.82740800618598,0.1533202274457761,-0.1855301746640028
347.90000000000435,112.18883640112935,0.15100615873546186,-0.1861890262914141
349.0000000000044,112.54611922854575,0.15205671523332498,-0.18948496634976175
350.1000000000044,112.90896100611509,0.1540630136844756,-0.19047957821868522
351.2000000000044,113.26866072231405,0.15222320297298042,-0.1921198789605829
352.30000000000445,113.63249909820202,0.15244225668180955,-0.1934398402660551
353.4000000000044,113.98924736197455,0.15460922256484122,-0.19367435520976972
354.50000000000443,114.34853531378269,0.1501581034057906,-0.19387997999807371
355.60000000000446,114.70882819433042,0.1508049404127738,-0.19629629363396006
356.7000000000045,115.07104435022367,0.1503045131032401,-0.1978339552886963
357.8000000000045,115.43241573823586,0.15224849830801546,-0.1971797098746193
358.9000000000045,115.78803506046677,0.15440257988105355,-0.19719553753814534
360.00000000000455,116.1516113172862,0.15424552060300845,-0.19909071547683066
361.10000000000457,116.50548789483608,0.15544834470550706,-0.20122689688897877
362.2000000000046,116.87435829304823,0.15175051295508357,-0.2021057270652089
363.30000000000456,117.23507678760168,0.15137997681378934,-0.20212024581507304
364.4000000000046,117.5995155266453,0.1531607642403292,-0.2034290427814951
365.5000000000046,117.96350787504343,0.14985709686861504,-0.20473950570113786
366.6000000000046,118.3257022286135,0.15380836830225886,-0.20643387256824575
367.70000000000465,118.69252961100841,0.15185160772608297,-0.20786263021030793
368.8000000000047,119.05008000418036,0.15189611631110767,-0.2070499159937449
369.9000000000047,119.40679046055122,0.15546396407271068,-0.20673004625200253
371.00000000000466,119.76783836879073,0.15586102083200437,-0.20739023712429372
372.1000000000047,120.12236956916298,0.15433751316090727,-0.20870014800045666
373.2000000000047,120.48989782535594,0.15598785728321074,-0.2109863279927886
374.30000000000473,120.84285171736215,0.15745053512167217,-0.21166012787324462
375.40000000000475,121.21511482829551,0.15751032557494193,-0.2109974631274958
376.5000000000048,121.57329098113007,0.15625193297982753,-0.2110154016871424
377.6000000000048,121.93642947678217,0.1593934836105697,-0.21199950326107775
378.7000000000048,122.29873219493172,0.1588104439387339,-0.21330851350924274
379.80000000000484,122.6616680832581,0.15969036256920655,-0.21467913127158234
380.9000000000048,123.02374535311402,0.1595651013098771,-0.21594998417786915
382.00000000000483,123.38572744055693,0.15987364429361484,-0.21628011600000097
383.10000000000485,123.74719213340846,0.16233920086340659,-0.21923981988498653
384.2000000000049,124.10837164155774,0.16117746354363938,-0.21957010981836245
385.3000000000049,124.46996685785119,0.16033739338233532,-0.2208803585416348
386.4000000000049,124.82828384371975,0.16247090359449667,-0.22088978977445528
387.50000000000495,125.18593645741204,0.16406688437359263,-0.22319024229408457
388.6000000000049,125.5537033415537,0.16170033064958433,-0.22319018400034274
389.70000000000493,125.9157144591172,0.16532413979296767,-0.2245221961008217
390.80000000000496,126.27630258951085,0.16539483818202894,-0.2254999200020653
391.900000000005,126.64372298511906,0.16772328611713094,-0.22681446253366033
393.000000000005,127.00664770234906,0.1654241228606277,-0.2287652997430789
394.100000000005,127.36817176799639,0.16410302472976923,-0.22903146228196647
395.20000000000505,127.73176931965563,0.16351800105416348,-0.2291201519999948
396.30000000000507,128.09498252845364,0.16477059901960822,-0.23044003709717042
397.4000000000051,128.45293737031952,0.16564179475135798,-0.23044221611044646
398.50000000000506,128.82148225789012,0.16293783497760672,-0.2327401699811089
399.6000000000051,129.1845364132064,0.16392413998244915,-0.23439011999999915
400.7000000000051,129.54716270895892,0.16247071419625803,-0.23438518266712283
401.8000000000051,129.9078156030787,0.16322876001054332,-0.2370356889353653
402.90000000000515,130.26756594784385,0.16128132030278652,-0.2376804436912643
404.0000000000052,130.63084436625192,0.16162419644168513,-0.23800995780524126
405.1000000000052,130.99240548021314,0.16120568044333217,-0.23830867248497478
406.20000000000516,131.35302567730818,0.16120919582996196,-0.2393569800691866
407.3000000000052,131.71740182196848,0.16272291145358886,-0.2399899476180689
408.4000000000052,132.07887390022762,0.16126090037083785,-0.23932993031500605
409.50000000000523,132.4391700000022,0.1609327170522301,-0.24328348374650766
410.60000000000525,132.80428904937304,0.16048131962629553,-0.24748306310960855
411.7000000000053,133.16510875535886,0.1644594813114859,-0.2449300560000589
412.8000000000053,133.5295231360559,0.1641093577250663,-0.24658018800027381
413.9000000000053,133.89685597242476,0.164194385070902,-0.24690015390628917
415.00000000000534,134.26220221980486,0.16687251668039327,-0.24789002274378635
416.1000000000053,134.60589744874255,0.16529111127630802,-0.2505299227829041
417.20000000000533,134.98916736508156,0.1620302473696411,-0.25316054625537676
418.30000000000535,135.3546597096139,0.16443098200556805,-0.25381997813205004
419.4000000000054,135.71846454522847,0.16383417170071413,-0.25381942316061057
420.5000000000054,136.07917000000208,0.16445655173425244,-0.25547012393794954
421.6000000000054,136.4428815863157,0.16496845409562866,-0.25678009200237106
422.70000000000545,136.80833228124908,0.16555950475350856,-0.25743995651884743
423.8000000000054,137.17152923270203,0.16391831725026296,-0.25972765553833943
424.90000000000543,137.53386345238187,0.16314087080085438,-0.26238014738023274
426.00000000000546,137.90230193065597,0.16472156180053243,-0.2627112760981154
427.1000000000055,138.26387149037663,0.1647702636293049,-0.2625789297078227
428.2000000000055,138.6313648942828,0.16544922248776772,-0.2640131908907657
429.3000000000055,138.99007660396003,0.16520258063367788,-0.26666002605627215
430.40000000000555,139.35443144802338,0.16501548838140745,-0.2693006173874499
431.50000000000557,139.7206071187898,0.16457589805580786,-0.2719300171884753
432.6000000000056,140.08034086137383,0.16407033627652923,-0.2732499066473282
433.70000000000556,140.45689210323116,0.16589504300735802,-0.2748999633175888
434.8000000000056,140.82453289723014,0.16777537891885808,-0.2775294692022796
435.9000000000056,141.1870426948641,0.16582793370834636,-0.2795106108335954
437.0000000000056,141.55009982570797,0.16711255467848463,-0.27918265585172497
438.10000000000565,141.91118847148795,0.16424210476707413,-0.2804875872845569
439.2000000000057,142.27889236249374,0.1675846297040553,-0.2824444117878131
440.3000000000057,142.640243603195,0.16615395753048912,-0.2864204924583831
441.40000000000566,142.99978630050376,0.1652975724257688,-0.2870798688168801
442.5000000000057,143.3649649767547,0.16699558227207678,-0.28829974387389834
443.6000000000057,143.72990103486558,0.1672345141970084,-0.2896100276711602
444.70000000000573,144.09457201227704,0.16857095947142398,-0.2923085437725228
445.80000000000575,144.45569223056606,0.16575351191959387,-0.2953544871449423
446.9000000000058,144.8262008208517,0.1639896292976215,-0.2952098045926137
448.0000000000058,145.18630691276408,0.16436683729402457,-0.30080735784557433
449.1000000000058,145.54975210664983,0.1645362279903937,-0.2982898391282123
450.20000000000584,145.91321065335387,0.16307131172247535,-0.3009098038718152
451.3000000000058,146.2829730125058,0.16249797292022805,-0.30354993538860287
452.40000000000583,146.64666152792,0.16104919526631623,-0.3042100235368368
453.50000000000585,147.01808495392686,0.16169564911890166,-0.3045400381635779
454.6000000000059,147.38371463370672,0.16330707418977042,-0.30583200666525157
455.7000000000059,147.74693884210433,0.16010469561761376,-0.30751001587839255
456.8000000000059,148.11185539702998,0.16035094689135931,-0.3084999247372817
457.90000000000595,148.47312912958208,0.16042920817400574,-0.309810212977367
459.0000000000059,148.8375927994149,0.16409714849517165,-0.3104698719958119
460.10000000000593,149.20546671511497,0.165362079018458,-0.3124501360007166
461.20000000000596,149.56454972185793,0.16804165407789018,-0.31244341598286995
462.300000000006,149.933643396179,0.1695954220667346,-0.3133786876654594
463.400000000006,150.29747297199503,0.16589287769630845,-0.3149789146794282
464.500000000006,150.66243189871838,0.17005219765789858,-0.3139826784650772
465.60000000000605,151.02949558551907,0.1719574294642543,-0.31529983999588573
466.70000000000607,151.3968021151635,0.17210215227462822,-0.316289839999945
467.8000000000061,151.76196955241318,0.1731443019700758,-0.3171422857556956
468.90000000000606,152.1315719130197,0.17329782396446536,-0.31760984000003667
470.0000000000061,152.49320706206578,0.1723613249951499,-0.3182721098351342
471.1000000000061,152.85998409565508,0.17380122178819413,-0.31924993995180184
472.2000000000061,153.22386347575588,0.17149494249566377,-0.3192493511108774
473.30000000000615,153.5891798311361,0.17041395316287744,-0.3192499541129137
474.4000000000062,153.95320919637578,0.1704782975603476,-0.32056482393516417
475.5000000000062,154.31952391055228,0.1664186871516824,-0.32188985355877175
476.60000000000616,154.68318004686478,0.16043836775768883,-0.3229645209506655
477.7000000000062,155.05062937897335,0.15572499097924997,-0.3232552942751803
478.8000000000062,155.41947480324538,0.1482419632971781,-0.3218900476687314
479.90000000000623,155.789587444874,0.14549501483044658,-0.3245214665455234
481.00000000000625,156.1526766785095,0.14242353191195845,-0.3232017852294815
482.1000000000063,156.5219622948681,0.13812531817435536,-0.32417035936490723
483.2000000000063,156.88660449729713,0.13675172728869978,-0.3245199088121713
484.3000000000063,157.25202366521137,0.13857341838031445,-0.3258594477289356
485.40000000000634,157.61800112108364,0.1378980532978593,-0.32515384397732694
486.5000000000063,157.9856115021687,0.13974713652907012,-0.32696742103406873
487.60000000000633,158.34916627336594,0.13933765898836858,-0.3255099079999968
488.70000000000636,158.7147013807544,0.1430364556760062,-0.32681940317468117
489.8000000000064,159.07724485475975,0.1431040884309085,-0.32551693537391735
490.9000000000064,159.44135799734522,0.1451189650622009,-0.3267726524251686
492.0000000000064,159.8098551459489,0.1480114658462166,-0.3282117583278903
493.10000000000645,160.18009226408924,0.1508443754247346,-0.32737048961171933
494.2000000000064,160.54288538894207,0.15502087975751433,-0.3273700425432873
495.30000000000643,160.90213525411588,0.1566681419511471,-0.32704989198651413
496.40000000000646,161.28134875017275,0.15426645524225435,-0.32892441823712737
497.5000000000065,161.64486491528467,0.1581051641675657,-0.32857635405871033
498.6000000000065,162.00916606270994,0.15944803992392398,-0.3299030168204191
499.7000000000065,162.37384679727066,0.15898602433802367,-0.3298990090178955
500.80000000000655,162.74557561733553,0.15880228693818044,-0.3308900085623425
501.90000000000657,163.11198863807024,0.15819546586632693,-0.33023014000026185
503.0000000000066,163.48161408891718,0.16160774624169782,-0.330255282669778
504.10000000000656,163.84948437232174,0.1622016896845686,-0.3308798440000005
505.2000000000066,164.21832144640436,0.1652885660743495,-0.3299248204144227
506.3000000000066,164.5848333079761,0.16711235228996468,-0.3305591742023255
507.4000000000066,164.9523345437754,0.16927071866543209,-0.33048561694767464
508.50000000000665,165.31984616598527,0.1702200003927783,-0.32989984399999894
509.6000000000067,165.68971101810288,0.17077497671162645,-0.32989526173820805
510.7000000000067,166.0578217891473,0.17269889697889562,-0.3318798439998951
511.80000000000666,166.42586605627503,0.17290392321167047,-0.3312213393818739
512.9000000000067,166.7961740899862,0.1745599338063304,-0.33285995087770237
514.0000000000067,167.16099602755313,0.17921443833622153,-0.33107021036974515
515.1000000000067,167.5264278094251,0.1795487206159132,-0.33287010799999894
516.2000000000068,167.89266562742938,0.17842946616067223,-0.3330781346675309
517.3000000000068,168.2610234487435,0.1764284813558894,-0.33282872889665693
518.4000000000068,168.62518460535247,0.18041676280206342,-0.332969203575729
519.5000000000068,168.9955614641311,0.18513583784794774,-0.33429007625719054
520.6000000000068,169.3679950078139,0.18412363103232687,-0.3343086504477375
521.7000000000069,169.73437694085052,0.18660738263266108,-0.3349529325762153
522.8000000000068,170.10271210446385,0.18481518304540812,-0.33735180850037594
523.9000000000069,170.47276834324282,0.18508932688331736,-0.3351718403954713
525.0000000000068,170.83875913822007,0.18573157290103426,-0.33650714407335247
526.100000000007,171.2037616231304,0.18464017442051706,-0.33582992300798553
527.2000000000069,171.56503742080184,0.18497546704848844,-0.3345099484760321
528.300000000007,171.9376891063062,0.18915339774491047,-0.33616016608953947
529.4000000000069,172.30976295641204,0.18985501420144768,-0.334840076008033
530.5000000000069,172.67766336393495,0.19305507010730505,-0.3354998001404983
531.600000000007,173.04801798178454,0.19380220109834578,-0.3371493988490655
532.700000000007,173.42291115084402,0.19318618078227834,-0.3358300759632593
533.800000000007,173.78166199169357,0.19693725834496245,-0.33583135423021027
534.900000000007,174.14875791322413,0.19680702043046683,-0.33615994400000027
536.000000000007,174.51017817796054,0.19666347657082284,-0.33763611592700515
537.1000000000071,174.87720526598858,0.19819624022461602,-0.33988989236933786
538.2000000000071,175.24559947734426,0.19984703815697324,-0.3380782906405795
539.300000000007,175.61131707639666,0.19796552692079095,-0.33861592380485606
540.4000000000071,175.9784185317734,0.19953103089191426,-0.34121629250392127
541.500000000007,176.34797487577723,0.20040708599315726,-0.3304490532841071
542.6000000000072,176.71895907112585,0.2018853697327212,-0.3379148155652243
543.7000000000071,177.08880658107094,0.20339019757808297,-0.33791013199706876
544.8000000000072,177.4491340210693,0.2044201228267153,-0.33856987421834495
545.9000000000071,177.83009471885106,0.20452442356960132,-0.33867993353023573
547.0000000000072,178.19778917450725,0.20620584851859425,-0.3403184196034883
548.1000000000072,178.56984351182314,0.20748083658432526,-0.33974683067242983
549.2000000000072,178.94311780967388,0.2067426017861851,-0.3386067803697923
550.3000000000072,179.31317862043545,0.20615882042772116,-0.3395314491797716
551.4000000000073,179.67916609353435,0.20310364034799955,-0.3381398680015355
552.5000000000073,180.04917000000307,0.2045162875523432,-0.3381374432125708
553.6000000000073,180.41586420170304,0.20487762376677265,-0.3394574970364701
554.7000000000073,180.78881323454522,0.20589806347914985,-0.34077004593441407
555.8000000000073,181.1651980812293,0.2083750818020702,-0.3401105950447283
556.9000000000074,181.52916273571657,0.2059713241197878,-0.33977966558309003
558.0000000000074,181.89810687525673,0.20796396800405725,-0.3401238902494854
559.1000000000074,182.26844375685477,0.21028797289373902,-0.34043983831327873
560.2000000000073,182.63685456141428,0.21048616767675066,-0.34077009834249194
561.3000000000073,183.00569960024205,0.21132937798489726,-0.3391198352895244
562.4000000000074,183.37680805421564,0.21315044063388955,-0.34050324926434783
563.5000000000074,183.74804697806974,0.2173561836597071,-0.3392159085001367
564.6000000000074,184.1184682813569,0.21799184037823105,-0.3404401000000008
565.7000000000074,184.48974556298077,0.2202005458379399,-0.33980016318527806
566.8000000000075,184.8586609027379,0.21863969825986862,-0.34060425179227805
567.9000000000075,185.21946515138598,0.2182326469239224,-0.3404398290135582
569.0000000000075,185.5857819757735,0.21882691787941733,-0.34179682768978603
570.1000000000075,185.95994435132684,0.22193771958480069,-0.3420899756721587
571.2000000000075,186.32916561929986,0.22241974841324463,-0.34208946813489494
572.3000000000076,186.69875009119556,0.22152001474355565,-0.34241996799999974
573.4000000000076,187.06630530400147,0.22241595217748467,-0.34263142720421147
574.5000000000076,187.43234695923417,0.22000915636620766,-0.3417599680006287
575.6000000000076,187.80733229659617,0.2252320223747235,-0.34208996801598524
576.7000000000077,188.17957253876952,0.22396175344350633,-0.3401114611790961
577.8000000000077,188.5485702815284,0.22136590703858783,-0.34274895979937803
578.9000000000076,188.9126383278166,0.22386732699592837,-0.34143032137772433
580.0000000000076,189.28234744532418,0.22665189837089894,-0.3420898362826579
581.1000000000076,189.65464658213037,0.2290986688525729,-0.34119219964175906
582.2000000000077,190.02394740241232,0.23043830136964027,-0.34241983600488
583.3000000000077,190.39274283339782,0.23090398542958512,-0.34076995579699343
584.4000000000077,190.76162914460744,0.23153854918584216,-0.34208996798296765
585.5000000000077,191.13564047048166,0.23086982993220495,-0.34209018635658905
586.6000000000078,191.50485127300038,0.23519674150271896,-0.3417137702283388
587.7000000000078,191.87029603545577,0.23564453567670185,-0.34143170129926803
588.8000000000078,192.24456836664595,0.23432162229343456,-0.3404400834362029
589.9000000000078,192.61670362100932,0.2350624420576799,-0.3401102123504596
591.0000000000078,192.98541672281476,0.2378477038806932,-0.33912967418386897
592.1000000000079,193.3536876274656,0.24116777879710538,-0.3401100680013993
593.2000000000079,193.7188199678717,0.2432938546016663,-0.3387996623613052
594.3000000000079,194.09217949138562,0.24259023476749997,-0.3410900675794033
595.4000000000078,194.46747624102574,0.2414266206743001,-0.3394598082944249
596.5000000000078,194.83828715357936,0.24220106063649993,-0.3407697983182598
597.6000000000079,195.21467115702796,0.24292225590702943,-0.3407678084175827
598.7000000000079,195.5787148810066,0.24407973653205328,-0.34174993596726466
599.8000000000079,195.95026515008297,0.24239065887781308,-0.3410899359999999
600.9000000000079,196.32114365563277,0.24232518862050956,-0.3410899359999999
602.000000000008,196.68839905840926,0.24500114821959196,-0.3424097818722953
603.100000000008,197.05621451238693,0.24256436262726044,-0.34269955060584545
604.200000000008,197.42489280830995,0.2446401754362988,-0.3420799359977602
605.300000000008,197.79752236524027,0.24334195848709905,-0.34174993056612646
606.400000000008,198.16945856105977,0.24610097174440915,-0.3424100640360086
607.5000000000081,198.53980771663103,0.2460370430519565,-0.3411000680001002
608.6000000000081,198.91466865597337,0.24647205528789895,-0.3424084153817626
609.7000000000081,199.28203790549205,0.24840699278168366,-0.3417600680020465
610.8000000000081,199.65165363253377,0.24731487742834135,-0.34176270844568224
611.9000000000082,200.01841440543464,0.25080234139456214,-0.34239992315624246
613.0000000000082,200.38886300359133,0.2512168992740804,-0.341099934242993
614.1000000000081,200.76206321882844,0.25146199551796844,-0.3419356438370351
615.2000000000081,201.12851965809745,0.2531713264510138,-0.34105314375845364
616.3000000000081,201.5053244740136,0.25550335010749725,-0.34166298345844703
617.4000000000082,201.87576077385035,0.25518352958546675,-0.3413198041062242
618.5000000000082,202.25109603379474,0.2559023386733421,-0.3429762120710014
619.6000000000082,202.6222771847916,0.25236789600625853,-0.34132156246507916
620.7000000000082,202.99361391104392,0.2539360255340042,-0.34264006811749237
621.8000000000083,203.36312258980746,0.25252472731020026,-0.3412087477482393
622.9000000000083,203.73275458459548,0.2540156925356092,-0.34186723853102974
624.0000000000083,204.10679335123,0.25586699527429735,-0.3408076309132393
625.1000000000083,204.47790156201253,0.2554373107142247,-0.34086343066577784
626.2000000000083,204.84879431758364,0.25733237740089354,-0.34319006800002194
627.3000000000084,205.21743020136623,0.2598439551963154,-0.34319006153492815
628.4000000000084,205.59160261760752,0.25717299574632335,-0.34285532844627786
629.5000000000084,205.96087209734347,0.2588029587072578,-0.34154058930767617
630.6000000000083,206.33362015855118,0.26047068158309905,-0.3431900679815141
631.7000000000083,206.70563081267585,0.26106251837733874,-0.34187006800689534
632.8000000000084,207.07217233873007,0.26124314308348895,-0.34187006842221024
633.9000000000084,207.446671028497,0.2599960147966387,-0.34154397769600475
635.0000000000084,207.8201360290119,0.26195290961740314,-0.3418599029264824
636.1000000000084,208.19244046156027,0.26296875195461356,-0.34086990436839804
637.2000000000085,208.56442394124593,0.25971620393121997,-0.34284989454476644
638.3000000000085,208.93212540171155,0.26249550138629907,-0.34317732485128083
639.4000000000085,209.30320760492336,0.26340032142549763,-0.34218943757811804
640.5000000000085,209.67453900939694,0.26186313643397297,-0.34264000430589636
641.6000000000085,210.04675632733503,0.26383699045011877,-0.34284990399693216
642.7000000000086,210.41726960365443,0.26338782219447676,-0.3428499040000008
643.8000000000086,210.79224743398578,0.270851904172571,-0.341539151865919
644.9000000000086,211.16990992937963,0.3533853492239274,-0.34153990492928443
646.0000000000086,211.54272453939836,0.3543721985984174,-0.3422072499295523
647.1000000000087,211.9095329578072,0.35833955467685374,-0.3422000675453294
648.2000000000087,212.2733568473241,0.35497406155804434,-0.34220003442718694
649.3000000000086,212.64310640834572,0.3577919152707616,-0.3459352980361299
650.4000000000086,213.01840508621032,0.35723843898915586,-0.34208990401217365
651.5000000000086,213.37955265400728,0.359438655660302,-0.3434470999769723
652.6000000000087,213.76137944576774,0.3612773644720835,-0.34274461773823495
653.7000000000087,214.13681740216097,0.3646580817103713,-0.3444366003641641
654.8000000000087,214.5112785115404,0.3656421447157303,-0.34398829328314484
655.9000000000087,214.88264749473942,0.36990893818031756,-0.3430801680001654
657.0000000000088,215.2545725442441,0.36723906527012806,-0.34505058744616246
658.1000000000088,215.62767097737753,0.3719602785014402,-0.34317246532079126
659.2000000000088,215.996910386658,0.373001033903376,-0.3445094055742768
660.3000000000088,216.36959776197662,0.3728925038835702,-0.3447301663420217
661.4000000000088,216.7444480525048,0.3757476027525972,-0.34342275856647353
662.5000000000089,217.1178987207015,0.3749681057669427,-0.3434101679999997
663.6000000000089,217.48529393308291,0.38187598929243016,-0.34439997596559335
664.7000000000089,217.8512872982355,0.38253357904919394,-0.3443848403973808
665.8000000000088,218.22012380846513,0.3837814536282833,-0.34373340733484126
666.9000000000088,218.59140438740502,0.38438984830373,-0.3438176621687634
668.0000000000089,218.96338269126753,0.3854776191965552,-0.3437316336436229
669.1000000000089,219.3388299888763,0.38442028650256566,-0.3450475557751904
670.2000000000089,219.7169998029988,0.3830029069895251,-0.34414793325815474
671.3000000000089,220.09484440585396,0.38445954578103736,-0.34570987186297897
672.400000000009,220.4651008727822,0.38179194674123096,-0.34724877797838394
673.500000000009,220.83527120361964,0.3821011557303762,-0.3470416480823384
674.600000000009,221.21003777477637,0.38472075574790576,-0.34436552263369036
675.700000000009,221.57916678044896,0.38414280923855015,-0.34768987746256697
676.800000000009,221.94754259765895,0.3835341945882673,-0.3473591420702986
677.9000000000091,222.32501158306187,0.3871994865946151,-0.34735986321790024
679.0000000000091,222.6983486604773,0.3886340862374742,-0.3477011040112403
680.1000000000091,223.0701970461074,0.3912218296684169,-0.3470299820749756
681.2000000000091,223.44332441635032,0.38807841746552185,-0.3463600425104243
682.3000000000092,223.81427489879746,0.3888525371186553,-0.3483216296416436
683.4000000000092,224.18269971908325,0.389990836917395,-0.34734871253677424
684.5000000000091,224.55655394582965,0.39287856360591267,-0.34722561517766115
685.6000000000091,224.93219551060668,0.38972735963896765,-0.34818785732017066
686.7000000000091,225.30604731341793,0.3912823132621157,-0.34910062263154007
687.8000000000092,225.6829305017952,0.3905832826485529,-0.3463699751040732
688.9000000000092,226.05175084203017,0.3927642327102445,-0.3456696423922465
690.0000000000092,226.4245766327071,0.3917467104402772,-0.35003358267336004
691.1000000000092,226.78954867572793,0.3944684611798497,-0.34867010351728744
692.2000000000093,227.17126018435775,0.39275929227045037,-0.34798405031508395
693.3000000000093,227.5412938590635,0.39082027509561224,-0.3469125435444176
694.4000000000093,227.91732389125826,0.3924389422501888,-0.348700846693895
695.5000000000093,228.29297072224438,0.39278215036236075,-0.34833983999999996
696.6000000000093,228.665881082997,0.39243645970479113,-0.348339839566556
697.7000000000094,229.03989180660741,0.38962347097284633,-0.3496601646549711
698.8000000000094,229.40871823574992,0.3929067788736691,-0.3483079232110571
699.9000000000094,229.78495377364698,0.39523108633894344,-0.34867998845165404
701.0000000000093,230.1602049623598,0.3928124851205923,-0.3490085382100121
702.1000000000093,230.5361873838574,0.393400808854679,-0.34831056963239915
703.2000000000094,230.9040276075409,0.3962499987731021,-0.3499899732380021
704.3000000000094,231.26769208719617,0.393662575226184,-0.3499991746720368
705.4000000000094,231.64134685858966,0.39946599812392014,-0.34868012136838544
706.5000000000094,232.01996210993283,0.3952548201437134,-0.3483398079987534
707.6000000000095,232.3917117142759,0.3960930062451893,-0.3493299405799397
708.7000000000095,232.76376938911574,0.39660179102696924,-0.34932954860524124
709.8000000000095,233.13807444986458,0.3964395774166509,-0.3512247598967182
710.9000000000095,233.51255084218707,0.40156972719178485,-0.3490107254777164
712.0000000000095,233.88345596723423,0.3978232570354434,-0.35127070060602117
713.1000000000096,234.2580933200548,0.40028014536554535,-0.3519700721304102
714.2000000000096,234.63298838189476,0.39767696121160023,-0.3509808059996238
715.3000000000096,235.00568115533528,0.3988162684463137,-0.350573708293624
716.4000000000096,235.37887560535341,0.3969898941179295,-0.3509798975745273
717.5000000000097,235.75158241691508,0.3937614283153601,-0.35262540633489614
718.6000000000097,236.12684999768553,0.39702190374398016,-0.35194154290775304
719.7000000000096,236.50132633302186,0.3972977874984176,-0.35162980752925943
720.8000000000096,236.87076537772012,0.38614540363980066,-0.3532801719951646
721.9000000000096,237.2372192477145,0.30290768566745774,-0.3513180235495441
723.0000000000097,237.60534668052586,0.30377663968334234,-0.3519599731100693
724.1000000000097,237.9767576297508,0.3030063536572092,-0.3529469564696952
725.2000000000097,238.35127338020072,0.3049507223552017,-0.3532798457091557
726.3000000000097,238.7233378791861,0.3066972124083116,-0.3532800250274364
727.4000000000098,239.09531229190014,0.30638810933048743,-0.35394017152693014
728.5000000000098,239.46655306836303,0.3048009642054912,-0.35426990885842313
729.6000000000098,239.852020357745,0.30847672502743695,-0.3536200353034107
730.7000000000098,240.2211264887808,0.3109196026743648,-0.3538698950298893
731.8000000000098,240.5923043428855,0.3107279070759721,-0.3569101610633565
732.9000000000099,240.96050904370279,0.31698014339252145,-0.35393041937704117
734.0000000000099,241.3337813678637,0.31967473644157707,-0.3550294512897594
735.1000000000099,241.70744335500285,0.3181914763748295,-0.3561458075547703
736.2000000000098,242.08281137686174,0.3187368108254751,-0.35636084792621414
737.3000000000098,242.4588031740718,0.32324033677110187,-0.35526002269796164
738.4000000000099,242.82952460487223,0.32119406687953456,-0.3562362167802906
739.5000000000099,243.2095937366921,0.32363314736455084,-0.35492989056725
740.6000000000099,243.58340213621784,0.3238669483890235,-0.3549300117668328
741.7000000000099,243.95506239016032,0.3271665817450189,-0.355920008
742.80000000001,244.32786822019239,0.32927770958696856,-0.3562229209769314
743.90000000001,244.69866828411674,0.326386708567572,-0.35724013999969184
745.00000000001,245.0684177751863,0.3253801740683202,-0.35724013996024206
746.10000000001,245.44207059001522,0.3296627420315934,-0.356504285287377
747.20000000001,245.81859285984544,0.32845873101483836,-0.35691008637029764
748.3000000000101,246.19917359186667,0.32992254175564417,-0.35658000788634103
749.00000000001,246.43657502691013,0.3304790537065041,-0.3578998759951526