File: 01_Data/Memory_Foam_Carpet_Pad/STA/N2/10K_min/Memory_Foam_Carpet_Pad_STA_N2_10KData_221006_R2.csv
##Temp./Â°C,Time/min,DSC/(mW/mg),Mass loss/mg
51.0,10.592177968986315,0.00587014839686173,0.01450703270913234
52.000000000000014,11.032156169767964,0.06104653385976566,0.01947816230485966
53.00000000000003,11.28830963831571,0.09852898355803252,0.018973844711287935
54.00000000000004,11.490252765814212,0.12662870866731812,0.01846140840976407
55.00000000000006,11.667830510789809,0.14746986794951167,0.019129942030011726
56.00000000000007,11.833762422183778,0.16460453715906342,0.0184822629520065
57.000000000000085,11.985674224076474,0.1760874024712118,0.019643483491921465
58.0000000000001,12.131346741178465,0.18723303042760797,0.019126675961973927
59.000000000000114,12.272174200877382,0.19791489277825325,0.018867585597100778
60.00000000000013,12.409058678693023,0.20438589483660685,0.018272760234108176
61.00000000000014,12.540844847885012,0.21129085805427517,0.019514223282733667
62.000000000000156,12.669770978780413,0.21527639898537698,0.01921959749295965
63.00000000000017,12.797524219486988,0.2225817541008528,0.019276994332482644
64.00000000000018,12.924133153249514,0.22569689938554238,0.0208435387836321
65.0000000000002,13.048600602772563,0.2315842586691581,0.018165081665615368
66.00000000000021,13.17102474311676,0.23665381611394198,0.020072833965111947
67.00000000000023,13.291121487247896,0.23848037760893748,0.019422586954430887
68.00000000000024,13.411664788344988,0.24411413204297694,0.01946536812900046
69.00000000000026,13.527617182127274,0.2474282544677573,0.020862533228191094
70.00000000000027,13.64419524200396,0.2519712248775434,0.020843079262696573
71.00000000000028,13.757298876576943,0.25589718551907525,0.021099858986440623
72.0000000000003,13.874680543904974,0.25733709173898367,0.02144600177489986
73.00000000000031,13.987887101934657,0.26155442834694087,0.022103337789891153
74.00000000000033,14.098972651549069,0.2634504235274724,0.020874101873031403
75.00000000000034,14.209848689644483,0.26644733338776905,0.020860617224760514
76.00000000000036,14.324246192660956,0.27032353423192834,0.022229812498574475
77.00000000000037,14.434882435745427,0.2732750738770182,0.02076771860230897
78.00000000000038,14.539370362420074,0.27592276432185714,0.021491687218142097
79.0000000000004,14.651658798603648,0.27769659718901685,0.022664934112736734
80.00000000000041,14.75956847134455,0.27917007275210604,0.02206065412600422
81.00000000000043,14.867296243548493,0.2848548517143631,0.02338271317951479
82.00000000000044,14.974484699912404,0.2877713063683047,0.023268980186090804
83.00000000000045,15.081260586000369,0.28880935275743624,0.022165814144353924
84.00000000000047,15.187442929803746,0.2908601256260167,0.021925716045253285
85.00000000000048,15.292959015162264,0.29285086287523054,0.02358529960264244
86.0000000000005,15.398096300330096,0.29634509608696513,0.02338559326117995
87.00000000000051,15.502296765402546,0.29826321933603905,0.022907249303114607
88.00000000000053,15.605050968900034,0.29984302410796415,0.023379713954327475
89.00000000000054,15.708683704380164,0.3005438677556169,0.023444379624641076
90.00000000000055,15.811598263933003,0.30358075112871774,0.023388830418997753
91.00000000000057,15.915479327401794,0.30582678473547187,0.02266721141144057
92.00000000000058,16.01653225571397,0.3077546831502541,0.02243204365464191
93.0000000000006,16.11858363108735,0.30997299440817916,0.023410937997206283
94.00000000000061,16.21991117116696,0.31278789998187395,0.02305616629885643
95.00000000000063,16.320506197769237,0.3158147497001538,0.022235660503084453
96.00000000000064,16.42249705561214,0.3156014607559138,0.02206679994576044
97.00000000000065,16.52327297651478,0.31906927290323606,0.023366575197908634
98.00000000000067,16.62326318556088,0.3220764350480829,0.02341453131561133
99.00000000000068,16.723411283332364,0.32437218358859743,0.023397729907791653
100.0000000000007,16.822691800892613,0.3241896570129028,0.022078679141658508
101.00000000000071,16.92228985385465,0.32294153970267114,0.023380881054299696
102.00000000000072,17.02219809470653,0.32580888328984303,0.02459077355217998
103.00000000000074,17.12043299203821,0.32620497937546955,0.02339017348131689
104.00000000000075,17.2190620817182,0.328786955832691,0.023380062596614515
105.00000000000077,17.317648240138123,0.32856961722334166,0.02355175952938149
106.00000000000078,17.41777527998074,0.32964984825034294,0.024698301523951027
107.0000000000008,17.5154077900673,0.3318529550863901,0.02475193944266474
108.00000000000081,17.612291942959388,0.3342176621391143,0.023389568528586313
109.00000000000082,17.711138782796645,0.3338643420241767,0.023380194282048627
110.00000000000084,17.809115548024774,0.33638936226562943,0.02302179743949706
111.00000000000085,17.907660156347454,0.33833523558021794,0.023380969503109306
112.00000000000087,18.006484474457455,0.34200861929504756,0.024677224319402224
113.00000000000088,18.104396227213847,0.34339566306770486,0.023992608414842742
114.0000000000009,18.20125478062368,0.3438191317088438,0.022102728161398577
115.00000000000091,18.300657731474175,0.34653866164042746,0.023379912595496766
116.00000000000092,18.397133072663323,0.34758325421697434,0.02349642403943797
117.00000000000094,18.494760007941853,0.3487424388696647,0.0233871174249769
118.00000000000095,18.593654866299033,0.3515012576209492,0.022287474428591025
119.00000000000097,18.688393498953754,0.3533295844064812,0.023380123416933074
120.00000000000098,18.788408610051263,0.35320034272848944,0.022901180750622085
121.000000000001,18.887260426570286,0.3537886932691158,0.022398491680630794
122.00000000000101,18.983962102793253,0.3546809572725683,0.023752203794285
123.00000000000102,19.080380259011175,0.3541731459750207,0.02339050759517347
124.00000000000104,19.178907240515578,0.3531573053920787,0.023380239416761484
125.00000000000105,19.2754855971587,0.35288437801088224,0.02469697406709548
126.00000000000107,19.372417538831066,0.3547522257075456,0.02338997606432036
127.00000000000108,19.470274395433073,0.35216805514484717,0.0237211898474472
128.00000000000108,19.56625535072186,0.3516541748924231,0.025011760228266677
129.0000000000011,19.663302893515567,0.35119033495949803,0.025029207499130735
130.00000000000114,19.75959745631709,0.3514689000642055,0.02332174263057185
131.00000000000114,19.856724150956037,0.35467878137312936,0.024704793290520666
132.00000000000114,19.95210600497051,0.353807730449051,0.02518654865219716
133.00000000000117,20.0502094202581,0.3544346820737989,0.02469999581633875
134.0000000000012,20.145573305867224,0.35470975658235304,0.023390088247178475
135.0000000000012,20.240984406970995,0.35590589038918063,0.024761723920958545
136.0000000000012,20.338247594508072,0.35609727240941025,0.023390066939383836
137.00000000000122,20.43395872539354,0.35701453283635476,0.02469982480058519
138.00000000000125,20.528113752484263,0.35681789723276425,0.023250332644604743
139.00000000000125,20.626706945785365,0.35591855178577725,0.022702907503904246
140.00000000000125,20.723239258700403,0.358420078279719,0.024046279832925066
141.00000000000128,20.81865818606586,0.3600925863510668,0.024040024303299656
142.0000000000013,20.91515122518195,0.35796306131786226,0.02437443471070999
143.0000000000013,21.00912662371801,0.3611174965727135,0.023610511280457658
144.0000000000013,21.104876769633343,0.36113377303197025,0.02343337715662308
145.00000000000134,21.201049855613682,0.3608918008124177,0.024764169163060235
146.00000000000136,21.296817669510606,0.3628781831437379,0.02469818115182898
147.00000000000136,21.393164381541997,0.3650739891042354,0.024698660940640327
148.00000000000136,21.487798060674024,0.365800605502664,0.023382298864600415
149.0000000000014,21.58414959274419,0.3658218267189979,0.02340517075827986
150.00000000000142,21.67854681256586,0.36853646496697956,0.023380026475775306
151.00000000000142,21.775183598873827,0.368016031037222,0.023872233332787207
152.00000000000142,21.87027048791995,0.3686380447662333,0.023389916496795227
153.00000000000145,21.967784806682147,0.37186931067961004,0.022084831499851187
154.00000000000148,22.062404051179385,0.3731735004973933,0.02338025310337999
155.00000000000148,22.158533459737715,0.37256016965483074,0.023379976010123205
156.00000000000148,22.254159314135926,0.37161928301400315,0.023386329193445743
157.0000000000015,22.349082510023393,0.37495896690121766,0.02305024665536992
158.00000000000153,22.445265258714706,0.3739745709469017,0.021752960660379905
159.00000000000153,22.54072321073543,0.37466556935523854,0.021731382190433024
160.00000000000153,22.63561150593896,0.37413976565055196,0.022080276995105397
161.00000000000156,22.731113169948706,0.37848301441981813,0.02207004619559161
162.0000000000016,22.825513861141303,0.3780669858453831,0.02207017599914085
163.0000000000016,22.921939147679915,0.37878257614297495,0.023438759220948846
164.0000000000016,23.015866841771743,0.3796196312743336,0.022069727947173767
165.00000000000162,23.113010127914006,0.3803687463281087,0.022070070002456532
166.00000000000165,23.207587577063496,0.3825023977133388,0.022073617018475655
167.00000000000165,23.30210494031762,0.3820413470153817,0.01944132699662582
168.00000000000165,23.39805241024257,0.3815016745372193,0.020742459281976267
169.00000000000168,23.494401208400365,0.38378491315174057,0.022042977603854652
170.0000000000017,23.588424384582616,0.3857828809434374,0.020740120146860885
171.0000000000017,23.68105822282286,0.3854860657799841,0.020756663374839057
172.0000000000017,23.77901184466822,0.3856281396105288,0.020844137650640082
173.00000000000173,23.87397353317479,0.3855275872250221,0.020750010007180908
174.00000000000176,23.966603043411247,0.388610073536527,0.020086866635964817
175.00000000000176,24.06342761033954,0.38973144805122517,0.020090019714393392
176.00000000000176,24.159380512489307,0.3899097778672975,0.019513928785239276
177.0000000000018,24.2549119031109,0.39108229921387094,0.020324719682228487
178.00000000000182,24.348717959688834,0.3923533049123846,0.019100135226383763
179.00000000000182,24.44414023119334,0.39405749532893175,0.0194323535612293
180.00000000000182,24.538824981687153,0.392886241530801,0.019429909059021533
181.00000000000185,24.634316597302092,0.39323941718356703,0.018120942231468096
182.00000000000188,24.729015226038406,0.396003643457004,0.01806490371897551
183.00000000000188,24.82354100369589,0.3959122849331913,0.018119800966603705
184.00000000000188,24.918159576785023,0.3953584106111925,0.018119804364142844
185.0000000000019,25.01206202296016,0.3967667959683087,0.016796354604492247
186.00000000000193,25.108011271546864,0.39630684080571527,0.0171245850213535
187.00000000000193,25.203520415934342,0.397199172187016,0.016830311924182162
188.00000000000193,25.298367693166966,0.39780497570084605,0.01668220294108158
189.00000000000196,25.393105319351086,0.3986630186972174,0.016684348373495528
190.000000000002,25.48918070357818,0.40022920617172625,0.015479816365945975
191.000000000002,25.583445958858874,0.3996191964306172,0.014153386778237298
192.000000000002,25.678552394093742,0.40054798558991683,0.015477634241418237
193.00000000000202,25.773432491928187,0.4006965298996938,0.015402645449003938
194.00000000000205,25.866593936274317,0.40135906535029664,0.013509863780593268
195.00000000000205,25.96367320613346,0.4023662912535389,0.012850274598368294
196.00000000000205,26.058883597615715,0.4034319874447353,0.012190013778930364
197.00000000000207,26.153095977281588,0.40366915614802695,0.01152296760914373
198.0000000000021,26.248748623202204,0.4030191289511458,0.011529941280776335
199.0000000000021,26.343084417425356,0.4049877961934154,0.01020920827829741
200.0000000000021,26.439211477484783,0.40673286228823463,0.010212512336073676
201.00000000000213,26.533163009065895,0.40782386886268335,0.008880816320339324
202.00000000000216,26.62819526814358,0.4099707235161658,0.007392376721328642
203.00000000000216,26.722296702119166,0.41098838662543674,0.006260021268861937
204.00000000000216,26.818091425179865,0.4116628736066357,0.0062600200006759366
205.0000000000022,26.91409387579254,0.41277565970362445,0.006260344581022537
206.00000000000222,27.008916364419857,0.4139489151575807,0.004940013873620419
207.00000000000222,27.103709401339092,0.4163606191149696,0.004934531767477601
208.00000000000222,27.197845142024047,0.4176983626238162,0.0036200988200052464
209.00000000000225,27.292796948462506,0.41922178458532117,0.00362036730231452
210.00000000000227,27.387753810127045,0.41779793893267136,0.0022215487310353055
211.00000000000227,27.482518811974057,0.4193804394462733,0.0009900245701928156
212.00000000000227,27.57803755629996,0.42089362123678037,0.0010251088174242362
213.0000000000023,27.67291204448561,0.42286860885122923,-0.00035942718253645367
214.00000000000233,27.76780636460996,0.42454826471326934,-0.0029791553610074573
215.00000000000233,27.86158926097626,0.4263929037444299,-0.002970115606172108
216.00000000000233,27.956908288491945,0.42817252530176114,-0.004295886235536006
217.00000000000236,28.052637856378485,0.43123459746055387,-0.00429098594373345
218.0000000000024,28.147227277227167,0.4328864898265046,-0.005666869815446507
219.0000000000024,28.24284596418396,0.435626521662963,-0.006910828949693748
220.0000000000024,28.337346527657708,0.4377224522944123,-0.008229896967344885
221.00000000000242,28.43293433959468,0.4362462916655905,-0.009252117784743774
222.00000000000244,28.526906424741465,0.43834836444387554,-0.010209128994884686
223.00000000000244,28.621799618505218,0.4399790178140953,-0.01186001948394777
224.00000000000244,28.717435422575473,0.4419935129029268,-0.011816094753486883
225.00000000000247,28.813434680533483,0.44504525189331856,-0.013178334748716214
226.0000000000025,28.90704887604637,0.4439606416114529,-0.016248662743181264
227.0000000000025,29.001211135139545,0.4481742834859261,-0.01756999409117732
228.0000000000025,29.09759138364027,0.4500869427177767,-0.018816948703451075
229.00000000000253,29.191985421148416,0.4523471273610051,-0.018187429904612973
230.00000000000256,29.287101074301386,0.4562653952071132,-0.021882179107531652
231.00000000000256,29.379638348715822,0.4566854144447342,-0.02216667689892038
232.00000000000256,29.476671163030176,0.4621738923006544,-0.023518210728068034
233.0000000000026,29.572353777407137,0.46565123381558216,-0.027138389840931865
234.00000000000261,29.666582786791217,0.4663219159353125,-0.02710416944064198
235.00000000000261,29.76199593095962,0.4692960054838959,-0.029267806246313643
236.00000000000261,29.857003208713362,0.4733476367606928,-0.0302245458373811
237.00000000000264,29.952213879106946,0.4789405547836493,-0.03408370815168871
238.00000000000267,30.04671408865512,0.4805977585027642,-0.035452713994241325
239.00000000000267,30.141245805461462,0.4855102956369882,-0.03667012251405177
240.00000000000267,30.23657813806044,0.48787662795814096,-0.03933272624328099
241.0000000000027,30.331887343436232,0.49271736050517634,-0.04198133923542979
242.00000000000273,30.42690250371444,0.49543804471569813,-0.04392516628584797
243.00000000000273,30.52250842833738,0.5020328706091071,-0.04540956209489444
244.00000000000273,30.617109178657152,0.5083957670858174,-0.04932197982959696
245.00000000000276,30.712444619850313,0.5114296793646433,-0.051485398606872845
246.00000000000279,30.80778975042009,0.5170618078781306,-0.054201050398413386
247.00000000000279,30.903105672990083,0.5248642400083295,-0.056782421894945756
248.00000000000279,30.99833204070135,0.5310204340457833,-0.06155833373609054
249.0000000000028,31.09354821756214,0.5343592427867514,-0.06403138335777214
250.00000000000284,31.18862131323788,0.5441224333435787,-0.06742680831558845
251.00000000000284,31.284058094920077,0.5515559229615119,-0.07074716700402028
252.00000000000284,31.37971243414966,0.5546859886689077,-0.07378422155084907
253.00000000000287,31.474791092935273,0.5627183980096957,-0.0766190277951746
254.0000000000029,31.569712814107447,0.5694723470528932,-0.0794796239513822
255.0000000000029,31.665207960693106,0.5765410602399909,-0.0852462792816504
256.0000000000029,31.760347899985245,0.5837562587499388,-0.09071765392274767
257.00000000000296,31.856076629269825,0.5946376186290235,-0.09453351778783814
258.00000000000296,31.952021652030115,0.6007036281802928,-0.10053346784527006
259.00000000000296,32.04748547930757,0.6129993241979641,-0.10488612773415884
260.00000000000296,32.143481536188744,0.6241664454282045,-0.10943216380878606
261.00000000000296,32.23711976361657,0.6307851586500461,-0.11416858519371953
262.000000000003,32.3310696967831,0.6407467591901385,-0.1204255911640808
263.000000000003,32.427527186495624,0.6547884002633856,-0.12703214740888757
264.000000000003,32.52177533226713,0.6648189456801256,-0.1331081713773825
265.00000000000307,32.619181895498194,0.6764750982128022,-0.1387971998496127
266.00000000000307,32.71419631076983,0.6880224706654194,-0.14554989030007626
267.00000000000307,32.81066149982856,0.6991533643713562,-0.151906283738378
268.00000000000307,32.90565432031847,0.7150967672463742,-0.15988393253193678
269.00000000000307,33.00129594164334,0.7265094374018144,-0.1678541235233415
270.0000000000031,33.09688014538376,0.7427031222011055,-0.17550707226209505
271.0000000000031,33.192688336504744,0.7559191980254846,-0.18374158565956078
272.0000000000031,33.286553293339736,0.7711734211077497,-0.19170055157965393
273.0000000000032,33.38351017660082,0.7843136138570874,-0.20184585474540784
274.0000000000032,33.47829016483061,0.8006144179182608,-0.21103332557681576
275.0000000000032,33.57464597466446,0.8166073845620128,-0.22095901910802063
276.0000000000032,33.67064400299613,0.8319133445256027,-0.23101550294751272
277.0000000000032,33.76663971344029,0.8522089444510559,-0.24062010491735153
278.00000000000324,33.86141177258703,0.8705292441255617,-0.2537376910130602
279.00000000000324,33.95732424062647,0.8869156946009038,-0.26426770997967663
280.00000000000324,34.05230092579292,0.9029214791004909,-0.27649913844768337
281.0000000000033,34.148567834902416,0.923167083372431,-0.2883903194134785
282.0000000000033,34.24395656270164,0.9390382738413199,-0.30133334664570866
283.0000000000033,34.34083861470319,0.9582695799457281,-0.31464014334247503
284.0000000000033,34.43640066327347,0.9755030270268787,-0.3281543125643229
285.0000000000033,34.530796779454974,0.9946903764537144,-0.3424875203375497
286.00000000000335,34.62830493279675,1.0122603350330643,-0.35704491736557875
287.00000000000335,34.72378504706889,1.0274217524795732,-0.37141293180942325
288.00000000000335,34.81950683380839,1.043026214713007,-0.38556792466392453
289.0000000000034,34.91558610573859,1.0577198825590866,-0.40162695123044934
290.0000000000034,35.009086252981966,1.0694010283311872,-0.41802777364888666
291.0000000000034,35.10708057534556,1.076684844011131,-0.4341784135019462
292.0000000000034,35.20227275063997,1.0792710551011306,-0.4493290019975982
293.0000000000034,35.29921719849946,1.0825982105625775,-0.4658663631684212
294.00000000000347,35.39430521536321,1.0788216714183143,-0.48153965783622477
295.00000000000347,35.489414329145134,1.0762786801933482,-0.49779329507030834
296.00000000000347,35.58464374562278,1.0741602194526028,-0.5157371141972895
297.0000000000035,35.679785544598666,1.0686762889619934,-0.534062222370022
298.0000000000035,35.77493456676075,1.0610521886994464,-0.550461471099426
299.0000000000035,35.872166771066254,1.0517355936769341,-0.5675614596869218
300.0000000000035,35.96898960781442,1.0389588023722283,-0.5842779957804303
301.0000000000035,36.06527446927843,1.0239177458673128,-0.6016291594724215
302.0000000000036,36.1611055772745,1.0058337741912076,-0.6187694518300013
303.0000000000036,36.256800801597024,0.9856139443207232,-0.6357443023751004
304.0000000000036,36.351839185785316,0.962660876731448,-0.6523152929826863
305.00000000000364,36.44831447319985,0.9387491107288803,-0.668880133032776
306.00000000000364,36.5443300144935,0.915399072326406,-0.6854119202453348
307.00000000000364,36.640469034694604,0.8889652448061792,-0.6995791800632891
308.00000000000364,36.735908919206956,0.8649817828269714,-0.7166405267596287
309.00000000000364,36.83225595188658,0.8437402519617412,-0.7305131493386239
310.0000000000037,36.928310765174786,0.8205275456175699,-0.7453824540959775
311.0000000000037,37.02282581602365,0.7977467185570475,-0.7586574996893627
312.0000000000037,37.11916960578888,0.7788641048921257,-0.7743874347147486
313.00000000000375,37.21535462506162,0.7602925307003319,-0.7846341219865418
314.00000000000375,37.31046213227136,0.7385754754927483,-0.7978506941672308
315.00000000000375,37.40754676588852,0.7210827114381748,-0.8123597283795299
316.00000000000375,37.503020832377324,0.7029807446172268,-0.8237315960276979
317.00000000000375,37.59802956053029,0.6868325698962209,-0.8351004418417194
318.0000000000038,37.69456365960671,0.6692902214029604,-0.8478869718314512
319.0000000000038,37.79087515737864,0.6587715264113421,-0.8591736488190675
320.0000000000038,37.88617259348324,0.642256387776023,-0.8707150945784892
321.00000000000387,37.98321956267544,0.6303893758603613,-0.8835072196112073
322.00000000000387,38.07723086836411,0.6195048358381958,-0.8945292185016971
323.00000000000387,38.173584871504794,0.6107971823887032,-0.9079125465003863
324.00000000000387,38.271318112302666,0.5992173131408877,-0.9162651725446991
325.00000000000387,38.368387891958626,0.5919462227926545,-0.9277682758361419
326.0000000000039,38.46469814367938,0.584028696469299,-0.9409895266507946
327.0000000000039,38.5615198353595,0.5748785336542777,-0.9527347543136768
328.0000000000039,38.65758135548885,0.5694341738470015,-0.9634707395866284
329.000000000004,38.75443612464868,0.56427754465596,-0.9736209057260647
330.000000000004,38.8501983524722,0.5587895433179481,-0.9866432216244014
331.000000000004,38.947909570477464,0.5552096629771935,-0.9979889060273455
332.000000000004,39.04418286818626,0.548885349885923,-1.0097839024503839
333.000000000004,39.14078473024808,0.545058266992559,-1.0211147051119203
334.00000000000404,39.23693088246612,0.5415087771498583,-1.0333363182591504
335.00000000000404,39.33303725578275,0.5379208116234268,-1.045814755516608
336.00000000000404,39.42966364675453,0.5312345303472712,-1.0579965463104108
337.0000000000041,39.52694529274973,0.5269486375638572,-1.0711876939062597
338.0000000000041,39.624185577969435,0.5247368578808062,-1.0839688088669255
339.0000000000041,39.72000000000042,0.5196878431716757,-1.0956582278669464
340.0000000000041,39.81729585195175,0.516370282779751,-1.1099095977579467
341.0000000000041,39.91297207084143,0.5107888165166453,-1.122682281583272
342.00000000000415,40.010874925113654,0.5053635235698333,-1.1375433041941014
343.00000000000415,40.106689482670944,0.5005246237728466,-1.151495420146626
344.00000000000415,40.203851289861504,0.49452167301184174,-1.1656544097171437
345.0000000000042,40.30042465288803,0.4889937311176429,-1.1789020446523475
346.0000000000042,40.39868592834309,0.4834228084171668,-1.1947563831703811
347.0000000000042,40.49529304557471,0.4769714970143201,-1.2091093770084123
348.0000000000042,40.59206626620811,0.46732654823396147,-1.2231006331240093
349.0000000000042,40.689206275857615,0.45980258098883253,-1.2375641634130918
350.00000000000426,40.78596634261008,0.45234086707012267,-1.2535908940466873
351.00000000000426,40.881202358236926,0.4478142578011457,-1.2695545310463587
352.00000000000426,40.979911780246894,0.43971152888661535,-1.286427241609437
353.0000000000043,41.07755832570594,0.4309562265460025,-1.3021612612116829
354.0000000000043,41.17340771193707,0.42520403974396614,-1.3196462584278712
355.0000000000043,41.27049364891267,0.41790810933803035,-1.3363880884951693
356.0000000000043,41.36862304136793,0.41381814684574336,-1.3538776302724371
357.0000000000043,41.46559157029491,0.40956718076448284,-1.3712002458824237
358.0000000000044,41.56182986241823,0.40543818991686564,-1.3895904535253631
359.0000000000044,41.65915788070177,0.4029951837919674,-1.4089488100101124
360.0000000000044,41.75579183927067,0.4005004791698716,-1.4279819284159188
361.00000000000443,41.853000623875566,0.40055623047726535,-1.449967261319899
362.00000000000443,41.949627927832765,0.3983820329446939,-1.470134426355917
363.00000000000443,42.046625530364956,0.39865500231013584,-1.4888441713838274
364.00000000000443,42.14391782204648,0.3980295187389218,-1.509432010755492
365.00000000000443,42.240533989736065,0.39987704471977514,-1.5340254333949042
366.0000000000045,42.33827256287917,0.404264006076465,-1.5546355139685422
367.0000000000045,42.43494057093454,0.40781128055821636,-1.5792279429039273
368.0000000000045,42.53214536637879,0.41098034462709093,-1.602284957427098
369.00000000000455,42.62915101206684,0.4160262833539774,-1.6246606099996286
370.00000000000455,42.725885721500056,0.4193475929631536,-1.6497418033314943
371.00000000000455,42.82266852104102,0.42565927826330974,-1.674067585398697
372.00000000000455,42.9192537843875,0.4292960889876545,-1.6994679153647216
373.00000000000455,43.017300906567904,0.4342381206573135,-1.7263485380450825
374.0000000000046,43.1148266563071,0.4424511526490052,-1.7548532160850976
375.0000000000046,43.21132461645055,0.4464935146980931,-1.7812217853639014
376.0000000000046,43.30853887935812,0.45422333144952526,-1.8109479070622574
377.00000000000466,43.406323159325915,0.4599082366409589,-1.841450008458232
378.00000000000466,43.50276710934164,0.4662386106108961,-1.8709935972882143
379.00000000000466,43.601012075029246,0.4721798700281649,-1.9028631067842814
380.00000000000466,43.69783892057765,0.4780034410323546,-1.933367692840552
381.00000000000466,43.79310403074136,0.48245738458985093,-1.9669196661188297
382.0000000000047,43.89364373478573,0.48754158801562286,-2.000487762790661
383.0000000000047,43.99069481265478,0.49661005603794556,-2.0344779591709883
384.0000000000047,44.08726998638846,0.5009944658316968,-2.069458407481495
385.0000000000048,44.184522619377184,0.5032686651283339,-2.104634330030355
386.0000000000048,44.2831674803569,0.5079272744611716,-2.142941394609698
387.0000000000048,44.380096157149424,0.5098871495084742,-2.1799957980291973
388.0000000000048,44.477976006551664,0.5123377287814433,-2.218084288753554
389.0000000000048,44.576058004105704,0.513785453921368,-2.2563904524903466
390.00000000000483,44.67282413129406,0.5134255196887749,-2.295361446067299
391.00000000000483,44.76959852768523,0.5114670957591689,-2.3336152517850843
392.00000000000483,44.8667807749811,0.5069948156874508,-2.3721653259429294
393.0000000000049,44.96451123618817,0.5052227602762407,-2.415499587658994
394.0000000000049,45.06283581112355,0.49850624761383955,-2.4538335474128212
395.0000000000049,45.16000000000052,0.4941961664519252,-2.495149942000224
396.0000000000049,45.25482766066772,0.48728322515317857,-2.532525956498068
397.0000000000049,45.354590162897644,0.4787508694746996,-2.57435255969709
398.00000000000495,45.45208826853798,0.46966909869266293,-2.6142130417594567
399.00000000000495,45.54943118815626,0.45847582087294836,-2.652404397515701
400.00000000000495,45.64673392443043,0.445705749573723,-2.6908335240012335
401.000000000005,45.744648686841664,0.4358595560281683,-2.727552660934232
402.000000000005,45.84246060335084,0.42113153355690436,-2.7656008555030054
403.000000000005,45.94073652499934,0.40793984775433256,-2.8010620875599193
404.000000000005,46.037926334081625,0.39325255751150245,-2.8370541455031733
405.000000000005,46.13523432822106,0.3811788934773133,-2.870519069725794
406.00000000000506,46.232786964013535,0.3652232559434935,-2.903134336376069
407.00000000000506,46.33000000000049,0.34999761960412584,-2.9331800253649596
408.00000000000506,46.42819540520301,0.3359371100293115,-2.962765488369528
409.0000000000051,46.52639521940219,0.31964579993621367,-2.9934938153561244
410.0000000000051,46.623511354920225,0.30531807275097345,-3.020103937980802
411.0000000000051,46.72072604626959,0.29119428460512686,-3.046771117995745
412.0000000000051,46.81883539867938,0.2729394727221964,-3.0697979552275854
413.0000000000051,46.91648496488924,0.2602627033331223,-3.0950655605004656
414.0000000000052,47.01409694984835,0.24877064164163826,-3.1170440913333826
415.0000000000052,47.11128524779455,0.23440310268340503,-3.1384933089401965
416.0000000000052,47.21059414134345,0.22416637523345334,-3.1589221460285057
417.00000000000523,47.306921350850295,0.20958855663139386,-3.1757233705086314
418.00000000000523,47.40542853983016,0.20013708104125766,-3.1938471752711015
419.00000000000523,47.50288468233468,0.1883778799342099,-3.210382360780673
420.00000000000523,47.60147647215478,0.17893152881521396,-3.2254761159292635
421.00000000000523,47.698951922594624,0.16545629596334355,-3.2385664971090486
422.0000000000053,47.79699332531045,0.1587737950479789,-3.250868303791536
423.0000000000053,47.895957576529796,0.1498677054859247,-3.2633967631026413
424.0000000000053,47.99381435374568,0.14436698067246473,-3.273985389630701
425.00000000000534,48.090427611688824,0.13673487525987166,-3.283848890972701
426.00000000000534,48.18912767409249,0.1304383583445442,-3.2929595696745206
427.00000000000534,48.286793113488564,0.12507130057336874,-3.301191208323427
428.00000000000534,48.384375532032614,0.11931494329411396,-3.309990091212063
429.00000000000534,48.48288381837891,0.11265222272055897,-3.314969994276842
430.0000000000054,48.579595359015975,0.10967768821103169,-3.3220370594011324
431.0000000000054,48.67889780194395,0.10661756303129405,-3.3277501000465
432.0000000000054,48.77724183533569,0.1006723341817296,-3.334075827416991
433.00000000000546,48.875066953064476,0.09649876968631543,-3.33842995880702
434.00000000000546,48.973532458264565,0.0924705747772997,-3.3446511235279255
435.00000000000546,49.06978585872013,0.09147278004642678,-3.3499275453422652
436.00000000000546,49.168380799683455,0.08920886004513773,-3.3529105339685374
437.00000000000546,49.266121448557506,0.085041928801874,-3.35698794751837
438.0000000000055,49.3631006724908,0.08352914717056581,-3.360023292806939
439.0000000000055,49.46168396241135,0.08178793608343715,-3.362829181330855
440.0000000000055,49.559902262139516,0.08157051536088972,-3.3682535445720756
441.00000000000557,49.65775259578093,0.07903369474385952,-3.371078389684826
442.00000000000557,49.756130319852396,0.0793254951321512,-3.3737489212604665
443.00000000000557,49.853855679057524,0.07804122352524245,-3.376448041978934
444.00000000000557,49.95242874767297,0.07935647168856796,-3.379507682297602
445.00000000000557,50.05019821430848,0.07754115147612467,-3.379669971001483
446.0000000000056,50.14760885816167,0.07907945310120867,-3.382685279505366
447.0000000000056,50.245264230065125,0.07720110684226966,-3.3862597893075597
448.0000000000056,50.343623777194274,0.07771696509173187,-3.388957441662601
449.0000000000057,50.4418804842379,0.0788024557816942,-3.3916062884773917
450.0000000000057,50.54029855997148,0.07873598251748842,-3.3915305766517294
451.0000000000057,50.63969685293273,0.0793106198996334,-3.3954776982374817
452.0000000000057,50.7365051740213,0.07805626478346162,-3.3974060696232935
453.0000000000057,50.83667223886995,0.08011565795812953,-3.400860538852335
454.00000000000574,50.93424515590811,0.0798305546176935,-3.4035994599860953
455.00000000000574,51.03274895799233,0.08226586289659577,-3.404827261920351
456.00000000000574,51.13058161986037,0.08101815224143522,-3.406085896346931
457.0000000000058,51.229251286492804,0.0799419574782288,-3.4100603994798164
458.0000000000058,51.32699437785663,0.0811257071332,-3.412708535145686
459.0000000000058,51.4255986519982,0.07984579031297206,-3.4141071009369175
460.0000000000058,51.522788862412995,0.08264974387350021,-3.416779179604607
461.0000000000058,51.62209073412091,0.08228572152775404,-3.42013751269981
462.00000000000585,51.72095077967142,0.08349767301730665,-3.4234598620998966
463.00000000000585,51.81853464976155,0.08294232419661773,-3.427226041127056
464.00000000000585,51.9145179981427,0.08514417541666741,-3.4300162349803403
465.0000000000059,52.015851617647215,0.08487508691328277,-3.4326397466477876
466.0000000000059,52.112989633921565,0.08485668073427172,-3.435314057150561
467.0000000000059,52.21223299796409,0.08693868411399192,-3.438173241144722
468.0000000000059,52.31164459469108,0.08704388482656145,-3.442306465702587
469.0000000000059,52.409809947193274,0.08663061251907589,-3.444976794158189
470.00000000000597,52.507238506267214,0.08788363716273634,-3.4465597683734113
471.00000000000597,52.60663921422752,0.08709590688903135,-3.4508533618400485
472.00000000000597,52.704900222462854,0.08763285907228108,-3.454241697258059
473.000000000006,52.80326179128359,0.08662808945663336,-3.4567967772292008
474.000000000006,52.90259103761271,0.08609506417546448,-3.460423927021143
475.000000000006,53.001318154077985,0.08563064566006673,-3.4634562695944062
476.000000000006,53.09910140329901,0.08365754796613367,-3.4678141505194233
477.000000000006,53.197920913188696,0.08279809692960705,-3.4704688221081605
478.0000000000061,53.296707226550346,0.08351904849998315,-3.473842849727073
479.0000000000061,53.394893462815524,0.07928437441220637,-3.476979156041129
480.0000000000061,53.49402402783355,0.08117714141395826,-3.479648831334361
481.00000000000614,53.59227952824133,0.07877069860037894,-3.4826268314608333
482.00000000000614,53.69127826578495,0.07451618612017719,-3.486796660536113
483.00000000000614,53.78877456870664,0.07219213746501418,-3.4900267351675964
484.00000000000614,53.88790950053865,0.07084345095063954,-3.4927540520003095
485.00000000000614,53.9872651595543,0.06760260578275795,-3.4943324770383595
486.0000000000062,54.08566500901007,0.06319172876919721,-3.4957120043381416
487.0000000000062,54.18373230575635,0.0625053334643455,-3.499443565720382
488.0000000000062,54.28339318115727,0.06153221642158779,-3.5015893805438427
489.00000000000625,54.38113154969247,0.061413991491505115,-3.503289472534082
490.00000000000625,54.479571285857496,0.0558388335178977,-3.505243091654737
491.00000000000625,54.57817329568691,0.05578382343843824,-3.506573637141671
492.00000000000625,54.678704539090376,0.0535619198057361,-3.5072406238711817
493.00000000000625,54.77627059462485,0.05165075199785146,-3.5085677456176505
494.0000000000063,54.87535906892243,0.05107198510859895,-3.5098727293904095
495.0000000000063,54.97360506566008,0.05054233014299675,-3.511190108556797
496.0000000000063,55.07290717662773,0.04971197334445093,-3.5125546718535423
497.00000000000637,55.171305528449416,0.05123779512288962,-3.5138189671809505
498.00000000000637,55.27176599820387,0.04928032356160694,-3.513820159212467
499.00000000000637,55.370832411650696,0.048894552062540564,-3.5151401186373183
500.00000000000637,55.46958544129373,0.04974262657511341,-3.516460435491866
501.00000000000637,55.56832286400445,0.04868795568261847,-3.515149437970709
502.0000000000064,55.66675346761905,0.04997930449168403,-3.51718229400571
503.0000000000064,55.76548075102361,0.047798188717532886,-3.517132273747201
504.0000000000064,55.86479788165329,0.04745153386597262,-3.5184301842034826
505.0000000000065,55.9637154775013,0.04827069015553498,-3.5198307753828777
506.0000000000065,56.062176576397945,0.04883548201485566,-3.519098752839226
507.0000000000065,56.161981991830224,0.04654435083539665,-3.5204257246854627
508.0000000000065,56.26130071507216,0.0456279990886031,-3.5203102344426025
509.0000000000065,56.36053353665602,0.0443517514595691,-3.5217945436075713
510.00000000000654,56.45909334976998,0.04383512530037725,-3.521741561264672
511.00000000000654,56.55751455005732,0.0443388794709792,-3.5229488689136006
512.0000000000066,56.65687170890467,0.04621342946756324,-3.524403930356918
513.0000000000066,56.75560341278284,0.04347714516404483,-3.5243698160947745
514.0000000000066,56.855253793445534,0.042454962596953305,-3.524370694176578
515.0000000000066,56.95451090779185,0.04175181835038844,-3.5256906237195698
516.0000000000066,57.05220082326637,0.04258888921425169,-3.5276609384176387
517.0000000000066,57.152290567800016,0.04033148587324492,-3.5276600100104534
518.0000000000066,57.25177858835295,0.04233206177922538,-3.527665740060041
519.0000000000066,57.34990595475618,0.04090710486582666,-3.527989654802706
520.0000000000066,57.45020712947139,0.041769387453364615,-3.5293099467671336
521.0000000000067,57.550000000000665,0.043033493182650984,-3.52930996000043
522.0000000000067,57.64875174309254,0.04168883587135619,-3.5293270165641553
523.0000000000067,57.74779164490202,0.04102890495647599,-3.5319405890813984
524.0000000000067,57.84530410656294,0.042945871016890014,-3.5306310954245976
525.0000000000067,57.94470520047818,0.040771032801112383,-3.531940378943076
526.0000000000068,58.043375508108326,0.03957535883857094,-3.5322328714469204
527.0000000000068,58.14334661127541,0.03765504569105271,-3.533259924637993
528.0000000000068,58.242261448295224,0.03860321935663341,-3.534580526917609
529.0000000000068,58.34226495560486,0.03686795958019384,-3.5335896083490157
530.0000000000068,58.44166548745807,0.03689071977508307,-3.533590103965889
531.0000000000068,58.5407513714809,0.037523579510559124,-3.53358272583008
532.0000000000068,58.6383742665019,0.041080206930946495,-3.5349099967756223
533.0000000000068,58.73885740232227,0.040640841440913844,-3.5362127225134365
534.0000000000068,58.83754019974952,0.040354462998875074,-3.5355721179665016
535.0000000000068,58.93750039582076,0.03692068880716365,-3.536882388108336
536.0000000000068,59.036990788619526,0.035020698197566424,-3.5368820947300357
537.0000000000069,59.13612674681556,0.03551769611316252,-3.5368799540463045
538.0000000000069,59.23506346109107,0.03703859428279732,-3.536900631628562
539.0000000000069,59.33429477017989,0.035885295626387204,-3.537433070506583
540.0000000000069,59.43378683487795,0.03404115108096817,-3.5383109429204356
541.0000000000069,59.5337688686198,0.0338450706922106,-3.539519243826276
542.000000000007,59.63271735017676,0.03341909648399022,-3.5395170672673424
543.000000000007,59.73225945406248,0.03130049769924881,-3.5395117679602484
544.000000000007,59.83133700517653,0.028841529756447104,-3.539509806643447
545.000000000007,59.93094780622851,0.03054301694614059,-3.5408306108899974
546.000000000007,60.03067489196224,0.03148111511271939,-3.54215007566898
547.000000000007,60.128879699101695,0.031442377075606154,-3.541473693907088
548.000000000007,60.22961106375106,0.030201940302328034,-3.5421499111821086
549.000000000007,60.328465095164596,0.02802881823167852,-3.542149997999301
550.000000000007,60.42793271566362,0.031067041656357985,-3.5421499979954807
551.000000000007,60.52750286557749,0.030341434644110266,-3.542147060886047
552.000000000007,60.62735221250716,0.02873226407336027,-3.5434697761653573
553.0000000000072,60.727342263405845,0.032110665950434825,-3.542065655789133
554.0000000000072,60.82578291689113,0.03165185802172482,-3.544782070962339
555.0000000000072,60.925244261835026,0.03303107374654635,-3.544593843411269
556.0000000000072,61.02424637035597,0.03491802752582779,-3.54543984817815
557.0000000000072,61.12336029784897,0.033878633154585946,-3.5454398479999982
558.0000000000073,61.220932003999245,0.0345182353163353,-3.545439847754814
559.0000000000073,61.32213029802742,0.032861039678385884,-3.5461449082381176
560.0000000000073,61.4223908687989,0.034646800692002044,-3.545468729506697
561.0000000000073,61.520582252953545,0.032494102811206294,-3.546103347151783
562.0000000000073,61.62042792809952,0.033444195739337323,-3.5461100191902
563.0000000000073,61.720190309659195,0.035568714232981025,-3.5474249590764404
564.0000000000073,61.819456978170685,0.03639209065000554,-3.548740092184686
565.0000000000073,61.91840111174287,0.03667994761093368,-3.547216446342021
566.0000000000073,62.01843131879998,0.03760323777817015,-3.5471077355859775
567.0000000000073,62.1180771879728,0.03659088553627399,-3.5480794430581843
568.0000000000074,62.21762204176171,0.036294706295776136,-3.549399756235041
569.0000000000074,62.3163280987015,0.03722556401136179,-3.5493998200120744
570.0000000000074,62.416609310142064,0.037436346848178426,-3.549406938403524
571.0000000000074,62.51527234414038,0.04056963835428434,-3.5496722195849113
572.0000000000074,62.614038296692094,0.0395407794224481,-3.5507313702562673
573.0000000000074,62.713394852509516,0.03870277562549013,-3.5493753571383406
574.0000000000074,62.81428626566433,0.03676349146245306,-3.5513583187992923
575.0000000000075,62.913711191931235,0.03860814089866771,-3.5522150402899264
576.0000000000075,63.01306201871318,0.03965410849759804,-3.5523599666994308
577.0000000000075,63.11224378225539,0.03849725928006842,-3.551020202200028
578.0000000000075,63.21258368308357,0.035210544362174856,-3.55173182629137
579.0000000000075,63.312230222010996,0.03590502713398719,-3.5539905413674515
580.0000000000075,63.4118506975384,0.03547801999946998,-3.5539861653380522
581.0000000000075,63.51148912854199,0.03442312487257215,-3.554009866079354
582.0000000000075,63.61147006973054,0.03255323313450881,-3.552687943629716
583.0000000000075,63.7102999633721,0.029464674167497873,-3.5526898639949556
584.0000000000076,63.80927045101221,0.02765347539414925,-3.5526898642322577
585.0000000000076,63.908952673231326,0.02633400490884058,-3.554027798047933
586.0000000000076,64.00935744795434,0.023423686296543123,-3.5540101580226624
587.0000000000076,64.10824671219524,0.024297878053465394,-3.5540112530039987
588.0000000000076,64.20859427644646,0.021789018189168785,-3.555340032320869
589.0000000000076,64.30792207411606,0.020747943223630716,-3.5539957704587652
590.0000000000076,64.40853419513753,0.01878049505951329,-3.5559766645983237
591.0000000000077,64.50738181475874,0.01506220857931112,-3.5559802435264936
592.0000000000077,64.60709371184072,0.01602384129565726,-3.555382935689101
593.0000000000077,64.7072461844122,0.01433148747111207,-3.5566401023508427
594.0000000000077,64.80550247617107,0.012483494537982753,-3.556640008000274
595.0000000000077,64.9067143100899,0.010352465960490442,-3.5566400087005343
596.0000000000077,65.00267592967168,0.00756590180008665,-3.557967098002065
597.0000000000077,65.10527930788334,0.006365927460453613,-3.556670049929103
598.0000000000077,65.20504445804306,0.005503639842135033,-3.557906646536575
599.0000000000077,65.3045218225863,0.003698390743169244,-3.559266828726064
600.0000000000078,65.4038139691077,0.001139729058037775,-3.5579599441257135
601.0000000000078,65.50360136499744,0.001627789109095501,-3.557952774961949
602.0000000000078,65.60265506538244,-0.0027087469046901957,-3.560593455763734
603.0000000000078,65.70330069748434,-0.0035107536316644206,-3.558651102173305
604.0000000000078,65.80262334064011,-0.004126390234264199,-3.559975433397812
605.0000000000078,65.90283329689335,-0.007082639655762946,-3.561251470099139
606.0000000000078,66.00092536944823,-0.010411274417092387,-3.5599402341937787
607.000000000008,66.10104665723966,-0.008312028553397743,-3.5612601118948644
608.000000000008,66.20124458945511,-0.010865631589734748,-3.562625227140204
609.000000000008,66.3011266494452,-0.01276079896957194,-3.561910158456032
610.000000000008,66.40009177716938,-0.012828799843074834,-3.56191015151344
611.000000000008,66.50046422787995,-0.014910113277989911,-3.56157864923623
612.000000000008,66.59945624144986,-0.016099356184816616,-3.562576250285092
613.000000000008,66.69883100614271,-0.018230788680779986,-3.5625700520156016
614.000000000008,66.7988987678906,-0.01995792921682893,-3.5625666627272903
615.000000000008,66.89867626434355,-0.019119243262226082,-3.563889949583033
616.0000000000081,66.99814765279405,-0.0186195881934878,-3.563843282279563
617.0000000000081,67.09793080027252,-0.021428419875554938,-3.565212640116818
618.0000000000081,67.19775243910462,-0.020815215379192564,-3.5648700007292815
619.0000000000081,67.29705957395487,-0.020788262868637053,-3.5658384877219307
620.0000000000081,67.39709284113388,-0.0212667694591136,-3.5661979609518584
621.0000000000081,67.49664925770989,-0.024846042120151624,-3.566447196246741
622.0000000000081,67.59583539911607,-0.020941567079725387,-3.5665201959164308
623.0000000000082,67.69598254816185,-0.01952798557872132,-3.5665198715106587
624.0000000000082,67.79545889299085,-0.02198758364094,-3.5678391479969536
625.0000000000082,67.89498966287262,-0.02284909257726203,-3.5668502181635575
626.0000000000082,67.99488819405947,-0.022583540602144236,-3.5667505534645705
627.0000000000082,68.09384081819081,-0.019787105249040204,-3.5678500987846244
628.0000000000082,68.1932117685154,-0.019255302219422288,-3.569176642296252
629.0000000000082,68.29269990604038,-0.016694205608186075,-3.5690675854675056
630.0000000000082,68.39297473794329,-0.01416428735471792,-3.5704601349685614
631.0000000000082,68.49244774411659,-0.014457180586405605,-3.5706926921557867
632.0000000000083,68.59216558887788,-0.011914945373085573,-3.5704798462618155
633.0000000000083,68.69140735540584,-0.00795654144957414,-3.570483763830968
634.0000000000083,68.79049983852104,-0.005386397984221525,-3.5717899152742216
635.0000000000083,68.89043874257574,-0.0033942340956148453,-3.573107153133311
636.0000000000083,68.99113598825943,0.0005490479192938325,-3.571790191951329
637.0000000000083,69.08864210335683,0.0028297681882790138,-3.57310692809593
638.0000000000083,69.19039598908418,0.007306120013231998,-3.573110017075444
639.0000000000084,69.29099661092529,0.012784092572449335,-3.575089792526194
640.0000000000084,69.39052599506006,0.015742309005130878,-3.576399460593571
641.0000000000084,69.4901827797836,0.024414893899413204,-3.5777197802498995
642.0000000000084,69.59036403752901,0.02634989121162412,-3.5764014037084997
643.0000000000084,69.69019846947043,0.03529349250675473,-3.5777178098475506
644.0000000000084,69.78950736735504,0.03957354472594746,-3.5790401353630354
645.0000000000084,69.89022058118888,0.04490723686027562,-3.57904512596636
646.0000000000084,69.98979202351428,0.051529917172762785,-3.5809956495106556