File: 01_Data/Memory_Foam_Carpet_Pad/STA/N2/10K_min/Memory_Foam_Carpet_Pad_STA_N2_10KData_221005_R1.csv
##Temp./Â°C,Time/min,DSC/(mW/mg),Mass loss/mg
51.0,10.739254682892954,0.052190350967998844,-0.002245892661789206
52.000000000000014,11.100526881817899,0.10227912931723426,-0.0003660095859583379
53.00000000000003,11.337022047545211,0.13668221206068187,-0.001454826760030059
54.00000000000004,11.532813309822966,0.16094319725524997,0.00041319959988950217
55.00000000000006,11.706466441275245,0.18255434615730004,-0.0002312391510299605
56.00000000000007,11.868845739646137,0.19990020041620182,-0.000778550589286553
57.000000000000085,12.02036095876454,0.212429302560885,-0.001249011771980335
58.0000000000001,12.165882144664279,0.22465868425411872,-0.0012480051634282674
59.000000000000114,12.305496048920505,0.23482352118456729,-0.0020419325894316387
60.00000000000013,12.441110219100901,0.24460609082465856,-0.0034955222244876794
61.00000000000014,12.572760431145829,0.25116179685645057,-0.0019193638987831108
62.000000000000156,12.704790435990642,0.25591610452250646,-0.0020454633467830163
63.00000000000017,12.83132764507596,0.2628013831855962,-0.0009849061548754534
64.00000000000018,12.956996950899551,0.26781237500276744,-0.0030886259267335348
65.0000000000002,13.077880518058715,0.27231709118031877,-0.0033394049250583535
66.00000000000021,13.199651477036412,0.278540424672014,-0.0027929254079106514
67.00000000000023,13.321382139944655,0.28146185833919923,-0.003157438349778552
68.00000000000024,13.440118731326223,0.28701710611289344,-0.0032630203761243592
69.00000000000026,13.557226938841328,0.29058908659730454,-0.0018605118440184754
70.00000000000027,13.674203372138379,0.2928432726348382,-0.0018235245652196141
71.00000000000028,13.788316118697558,0.29835005886006993,-0.0018593101515316235
72.0000000000003,13.90178852733559,0.30301405449645513,-0.0018509987317552046
73.00000000000031,14.015371093577267,0.3049623174453091,-0.003220625161103108
74.00000000000033,14.128820938764612,0.30804272275087097,-0.0029307894762435893
75.00000000000034,14.239328719669297,0.31059779847559166,-0.00319077606439766
76.00000000000036,14.35082614263681,0.31676258954059355,-0.0028416433095275195
77.00000000000037,14.460100066108257,0.31822376216512205,-0.0018624472471415743
78.00000000000038,14.569078451812606,0.32168802995641443,-0.0020196765082332035
79.0000000000004,14.678917435719853,0.3242382824685175,-0.001795215647469206
80.00000000000041,14.786880787719486,0.32604280886388237,-0.0031732228325038747
81.00000000000043,14.894790383192172,0.3315355222816604,-0.003319815943148896
82.00000000000044,15.000229767044653,0.33131421317789334,-0.004236203549292661
83.00000000000045,15.10738863698331,0.33413573538444363,-0.003380936841464788
84.00000000000047,15.212328331547313,0.33566257888040407,-0.0033223684809264853
85.00000000000048,15.318400186911841,0.33946726338379085,-0.0040809703303263944
86.0000000000005,15.423490143809971,0.3426194109063416,-0.0032963389279556665
87.00000000000051,15.527357513316218,0.3440731338944907,-0.0031819081946791172
88.00000000000053,15.63037759940096,0.346795261137546,-0.003189954897244718
89.00000000000054,15.734234179143543,0.34728090718723437,-0.0032152477371010235
90.00000000000055,15.836308272860279,0.3508418486948127,-0.004194338752525617
91.00000000000057,15.935021571444997,0.3531949887870687,-0.0040625588101272925
92.00000000000058,16.040401501833635,0.35644217364683783,-0.004528118122285818
93.0000000000006,16.143562127911235,0.35892541349395735,-0.002563499732960217
94.00000000000061,16.243690665518553,0.36300780404142896,-0.004500036174591493
95.00000000000063,16.345234643659026,0.36331472674113097,-0.003184802034815526
96.00000000000064,16.445689680675443,0.36834516631015923,-0.0031610207168384363
97.00000000000065,16.545509768570042,0.3689272511964201,-0.003187981083064173
98.00000000000067,16.64517731276571,0.37078071120281786,-0.0031900313225667887
99.00000000000068,16.74351124329219,0.37053795113584254,-0.0031813278871029027
100.0000000000007,16.84570434291244,0.3733564627546109,-0.0035138587362464335
101.00000000000071,16.94478011202794,0.37319981455290074,-0.00315171206552467
102.00000000000072,17.045033647235037,0.3740580401110364,-0.003194124573130175
103.00000000000074,17.14389510042103,0.37574964992945625,-0.003675063739473572
104.00000000000075,17.241973483715956,0.3764267241402621,-0.004512489258729602
105.00000000000077,17.34142303619859,0.37816124321475286,-0.0044929378866109815
106.00000000000078,17.440751265055784,0.3790872578179675,-0.004486643132322499
107.0000000000008,17.539517076098015,0.38171916568882225,-0.004510391240975409
108.00000000000081,17.637191383205355,0.38212432304385646,-0.003191115890548879
109.00000000000082,17.73537311840136,0.38491140589712425,-0.001850182556269786
110.00000000000084,17.83334874756943,0.38679869976334746,-0.0034563837958607735
111.00000000000085,17.930388606345467,0.38987382914584645,-0.004375140583602111
112.00000000000087,18.028110872826744,0.3914908342022074,-0.0032005074915391063
113.00000000000088,18.12637164227536,0.3942500437784745,-0.0034157269913350774
114.0000000000009,18.227075975117593,0.39411486147740904,-0.0045006382538010925
115.00000000000091,18.32318858697704,0.39587795335350595,-0.004507667378941704
116.00000000000092,18.420511911717735,0.39766153013196426,-0.004514544273275689
117.00000000000094,18.518369180497878,0.3994501802775823,-0.003981975933553983
118.00000000000095,18.61714002175573,0.40284681411181045,-0.0031763544281924183
119.00000000000097,18.713628026061713,0.4028627678218877,-0.0033104912282837518
120.00000000000098,18.811536296862553,0.4061430113435992,-0.004509451452526569
121.000000000001,18.908707669951873,0.40560015941861916,-0.004489345676469192
122.00000000000101,19.005376298493758,0.4040639270430594,-0.004500160329437897
123.00000000000102,19.10311342614362,0.40770253042877036,-0.0036179788341295094
124.00000000000104,19.200577495217544,0.40740212281085786,-0.00582984738254666
125.00000000000105,19.296309426967994,0.4104529816300323,-0.00546469092984303
126.00000000000107,19.393971259058212,0.40578749477600595,-0.004499776283332757
127.00000000000108,19.490567921572282,0.4049929901051662,-0.004498634858830286
128.00000000000108,19.5873115121684,0.40268058625768366,-0.005919246033708525
129.0000000000011,19.68343199406568,0.4019121358011081,-0.004832420370219914
130.00000000000114,19.777600667783723,0.40311015590471366,-0.005660166645348852
131.00000000000114,19.87624311115093,0.40282612512194693,-0.005829084775720084
132.00000000000114,19.97115184051961,0.4027810008285613,-0.004840104826564051
133.00000000000117,20.068116489296628,0.40414966869814006,-0.004569365329561315
134.0000000000012,20.16608827505126,0.40599376423121525,-0.005508516936910013
135.0000000000012,20.263549610962894,0.40420436529869164,-0.004532441140412402
136.0000000000012,20.359891976673143,0.40524174522951883,-0.005647619861393949
137.00000000000122,20.455168234857695,0.40868534330946216,-0.004603864651140377
138.00000000000125,20.5528099650005,0.4077317866672986,-0.006249400279203954
139.00000000000125,20.647785632151898,0.40675454713279047,-0.005773071779287875
140.00000000000125,20.744990695349458,0.4092905890126993,-0.006153505629784561
141.00000000000128,20.840309177942792,0.40782652638339534,-0.0061501060435373844
142.0000000000013,20.9367461031233,0.41183673139955146,-0.0059297405668568
143.0000000000013,21.031973373286593,0.4101097754724824,-0.004501178015263285
144.0000000000013,21.127133408398933,0.41163471328633305,-0.005813101708075585
145.00000000000134,21.224498202770466,0.40981805796037307,-0.004722207318777372
146.00000000000136,21.32000000000012,0.41206457207329994,-0.0058194662828547905
147.00000000000136,21.413915464300036,0.41279099949876874,-0.006184492856069035
148.00000000000136,21.509622940722416,0.41500630173563324,-0.007139841407208358
149.0000000000014,21.60579587481416,0.4151989933048001,-0.007138163918792628
150.00000000000142,21.699033297524096,0.41657488955867084,-0.00714543894201114
151.00000000000142,21.79592843851828,0.41667492911649606,-0.007209567487154622
152.00000000000142,21.89222707994619,0.4178701932697579,-0.005820172888087782
153.00000000000145,21.98738276882479,0.41910774829041963,-0.005907521522595438
154.00000000000148,22.08244905939249,0.4193167196669409,-0.006480178657324309
155.00000000000148,22.177724167858884,0.4209176892796132,-0.006668564151105727
156.00000000000148,22.272471719380235,0.4229603110057705,-0.006490047461268134
157.0000000000015,22.3687470005313,0.4233326960003475,-0.007479154832851442
158.00000000000153,22.463512711280753,0.4239958471512575,-0.007124387160040158
159.00000000000153,22.55877180540794,0.42700110953557735,-0.00779980861771179
160.00000000000153,22.654719405235525,0.4274157360539678,-0.008731949352075219
161.00000000000156,22.749697476874633,0.42944004723145407,-0.00911981227299119
162.0000000000016,22.844932487168933,0.4299735542219509,-0.008839247319901489
163.0000000000016,22.940559142986505,0.4300483972789815,-0.008699330700467023
164.0000000000016,23.034436453252955,0.42894344066419055,-0.009120015605154741
165.00000000000162,23.130000000000173,0.43080961692994557,-0.00779723427646406
166.00000000000165,23.2254920217303,0.4329928112512004,-0.009110157735754854
167.00000000000165,23.320000000000157,0.43071835542503606,-0.009110162157629276
168.00000000000165,23.415916429615297,0.43174490925883796,-0.009591972873900012
169.00000000000168,23.51148306446765,0.43337475272197656,-0.009120030604804263
170.0000000000017,23.6035970174876,0.43465683052697635,-0.009121281449681717
171.0000000000017,23.701068346458538,0.4368961056631384,-0.009781550777923975
172.0000000000017,23.796330367022748,0.4382320107211461,-0.010402280302367117
173.00000000000173,23.891169580944123,0.44003139789192725,-0.01043809853758404
174.00000000000176,23.986041530325423,0.4394161419989554,-0.010440184026358601
175.00000000000176,24.080265465984862,0.4391186598202098,-0.010439758232736907
176.00000000000176,24.17660329443998,0.442267567181921,-0.01174999390037712
177.0000000000018,24.27152635248868,0.44279607527078185,-0.011750174394217439
178.00000000000182,24.366623462328732,0.4413958745278788,-0.01246497841644345
179.00000000000182,24.461378255706002,0.44299827947833587,-0.011749955887754737
180.00000000000182,24.557223910087867,0.44255166491238485,-0.011699556265382327
181.00000000000185,24.64931188318698,0.44350362097767554,-0.013069956681311723
182.00000000000188,24.747157605759103,0.44295851890441135,-0.013084015366015223
183.00000000000188,24.84122729901327,0.4463946955818161,-0.014059967820942987
184.00000000000188,24.936689714882917,0.447355408150866,-0.014059955956999381
185.0000000000019,25.03202971211066,0.4468258408965543,-0.014066851850421003
186.00000000000193,25.1269359371073,0.44904768777696236,-0.01438438183050117
187.00000000000193,25.221484621996385,0.44851475450703915,-0.01569995435142335
188.00000000000193,25.316080665106156,0.4501874900123722,-0.015711972261951423
189.00000000000196,25.410000000000167,0.45016819490820226,-0.017019948522411177
190.000000000002,25.504152459791886,0.4517435937364544,-0.016689906277298938
191.000000000002,25.6003589238751,0.4517536638907957,-0.017899248665615985
192.000000000002,25.69604485236243,0.4542233487603443,-0.01862832931074987
193.00000000000202,25.79037866710064,0.45376081497813936,-0.01932990044598526
194.00000000000205,25.88496135654252,0.4544811262456025,-0.01932989900000326
195.00000000000205,25.979800847005436,0.4583983383137155,-0.019329899000001483
196.00000000000205,26.074457708634917,0.4561315724489045,-0.01932989915241823
197.00000000000207,26.170846162038394,0.45899912872941484,-0.01929206215307744
198.0000000000021,26.26439446759838,0.4603053866467956,-0.020639895407029485
199.0000000000021,26.35711271782924,0.46066304879731507,-0.020639897963238063
200.0000000000021,26.453688506285545,0.46076454783958537,-0.021603595970502987
201.00000000000213,26.549197155611097,0.46316018019050936,-0.023280115739642504
202.00000000000216,26.644606992577813,0.4640558311439837,-0.02328016768369512
203.00000000000216,26.738557815840288,0.4661278802292564,-0.024597788916241647
204.00000000000216,26.83381448851677,0.46552479112159717,-0.02461724988868852
205.0000000000022,26.92836815869014,0.46796034122607344,-0.025925239867287786
206.00000000000222,27.02265474577182,0.4686541047079357,-0.027239944665665483
207.00000000000222,27.11875042468123,0.4686439179317905,-0.027239952001665735
208.00000000000222,27.213564924617078,0.4720338854661734,-0.02723953508478516
209.00000000000225,27.306888362073906,0.4734178006388982,-0.029527906884073474
210.00000000000227,27.40261690311292,0.47388288357188213,-0.029530046305453084
211.00000000000227,27.497351246703133,0.47567539514023416,-0.03120248521317226
212.00000000000227,27.59213540322685,0.4771351222876852,-0.03249764451541992
213.0000000000023,27.68727571965508,0.47810515704396167,-0.03322088274974755
214.00000000000233,27.782063453924447,0.4815202513485604,-0.03384706292374062
215.00000000000233,27.87722516036066,0.48271907549619764,-0.03377885904614519
216.00000000000233,27.971070921656672,0.4867442505059565,-0.035132086193496725
217.00000000000236,28.066810017256643,0.48723505659374056,-0.035143618736628746
218.0000000000024,28.160504391289553,0.4897933424449938,-0.03678252292712747
219.0000000000024,28.25576504360751,0.49123670396921254,-0.03939494010496691
220.0000000000024,28.34992466842931,0.49316504952800244,-0.03941019296084036
221.00000000000242,28.44529794079214,0.4938425987205904,-0.04049034871075419
222.00000000000244,28.540749393769936,0.495791896044262,-0.043104318763527605
223.00000000000244,28.635333376590623,0.49632902505852405,-0.043370267703175536
224.00000000000244,28.729836403668216,0.49903265419767495,-0.04467995422698934
225.00000000000247,28.826200579791543,0.4990824748442959,-0.046006891919618376
226.0000000000025,28.920393274718307,0.5012456644835271,-0.0476808656455141
227.0000000000025,29.015501100689608,0.5014280347959816,-0.047980036582190966
228.0000000000025,29.109903441224997,0.5061226254769993,-0.04995880176977474
229.00000000000253,29.20539957282551,0.5067796925662306,-0.05129137576961185
230.00000000000256,29.30041065391335,0.508911402791054,-0.05226111023204005
231.00000000000256,29.39488524890236,0.513128147012359,-0.05486158969839927
232.00000000000256,29.491042549693706,0.5143888917400532,-0.05622435208545218
233.0000000000026,29.586385348059817,0.5169671991435651,-0.05900796177627754
234.00000000000261,29.68183352173782,0.5214190208991457,-0.061877570486772004
235.00000000000261,29.775439170846983,0.5239218588907069,-0.06271958415950074
236.00000000000261,29.871488541399827,0.5289401542313243,-0.06543140934128333
237.00000000000264,29.96700101616435,0.5302616828828994,-0.06613788081385952
238.00000000000267,30.062151119553324,0.5350584994939763,-0.06745703174918649
239.00000000000267,30.158350177988,0.5376535468678729,-0.0707003794390153
240.00000000000267,30.252889468725243,0.5427141604205995,-0.07354209923238386
241.0000000000027,30.34777622257325,0.5493390621838334,-0.07755328148343033
242.00000000000273,30.443661710937278,0.5532424862324454,-0.07883704676811742
243.00000000000273,30.537432817631995,0.558345430354803,-0.080040460334323
244.00000000000273,30.633393515108963,0.5630726796501966,-0.08346682573321296
245.00000000000276,30.72990961279405,0.5694883844788416,-0.08739012427570492
246.00000000000279,30.824887489920687,0.5761160504807891,-0.08945890105634424
247.00000000000279,30.919312500499608,0.5809920924187039,-0.0925077176046698
248.00000000000279,31.01522804675539,0.5876824045144718,-0.09656548739005055
249.0000000000028,31.1105897674783,0.5911485778591198,-0.0994707848670604
250.00000000000284,31.20646419267099,0.5974384673535155,-0.10414595058028153
251.00000000000284,31.30121120538402,0.604840128026089,-0.10702303742846553
252.00000000000284,31.396197042128616,0.6120851069762325,-0.11148544520287818
253.00000000000287,31.492236667986862,0.6183126744877708,-0.11556916367750159
254.0000000000029,31.588367452333706,0.6277889284096055,-0.12024577394945712
255.0000000000029,31.682216777173583,0.6349897667684513,-0.12295260621879756
256.0000000000029,31.777021843779835,0.6431854180509882,-0.12777010815653966
257.00000000000296,31.873785370091053,0.6520387879797819,-0.1334578141847187
258.00000000000296,31.96894473381123,0.6617103440746412,-0.13944605683697864
259.00000000000296,32.06594771279232,0.6692431175454698,-0.14537902986059237
260.00000000000296,32.16097041241206,0.6779060919014828,-0.14986885358989044
261.00000000000296,32.254954380088066,0.6890846095582652,-0.15452722145584463
262.000000000003,32.35133491108121,0.6991544762068785,-0.1605240516197921
263.000000000003,32.446426942399974,0.7103426938930971,-0.16667295340762323
264.000000000003,32.541742398870376,0.7213032714001103,-0.1726561337237107
265.00000000000307,32.63812089048134,0.7322955891549788,-0.17971286284637733
266.00000000000307,32.73400407337216,0.7449340812527514,-0.18623887011058837
267.00000000000307,32.827593913584735,0.759836771580525,-0.1939716309091586
268.00000000000307,32.924270033688025,0.7742546519540932,-0.20132784473287124
269.00000000000307,33.01879908368794,0.7867079034737012,-0.21077491324329145
270.0000000000031,33.11463277014333,0.8002459724874011,-0.21828988521212
271.0000000000031,33.21000000000029,0.814603614099725,-0.22625989800002522
272.0000000000031,33.30526057408303,0.8316194197970498,-0.2351592629398942
273.0000000000032,33.40051682895475,0.8492947221804845,-0.24454438404070444
274.0000000000032,33.49505026634425,0.8605099297073981,-0.25353093964426066
275.0000000000032,33.59247275211359,0.8801899551417008,-0.2647573528552365
276.0000000000032,33.68747384898065,0.8962624426441197,-0.2766690394943301
277.0000000000032,33.785602070213294,0.9154840013372748,-0.2869049928030627
278.00000000000324,33.88143953288137,0.9316150321744141,-0.2981676443901913
279.00000000000324,33.977398064699486,0.9503972349571492,-0.3100383083207938
280.00000000000324,34.07263979948277,0.9685880613976713,-0.3209676179807608
281.0000000000033,34.1683972221979,0.9883919998513375,-0.33570531222870903
282.0000000000033,34.26418728132173,1.005853729188776,-0.3485323556067117
283.0000000000033,34.360303615969485,1.0224075495623632,-0.36287456865415413
284.0000000000033,34.45638330097697,1.0414371503437703,-0.3753652973141728
285.0000000000033,34.55074123452978,1.059092419909243,-0.3892825529303767
286.00000000000335,34.647679046191314,1.0782907916913778,-0.4038382757673098
287.00000000000335,34.74295933383398,1.0973522370244049,-0.41808700385666375
288.00000000000335,34.83892935048883,1.1099427300517466,-0.4339429119775877
289.0000000000034,34.93355759431442,1.1234528775287766,-0.45015496376926745
290.0000000000034,35.029795933770615,1.1361027423135068,-0.46667063916235696
291.0000000000034,35.13762855443555,1.1405641953549042,-0.4813940955957694
292.0000000000034,35.232832210739936,1.1410914541154338,-0.4985394187360068
293.0000000000034,35.32742739972538,1.134102704848103,-0.5153977153266149
294.00000000000347,35.424183449742884,1.1306927698674563,-0.530620502131792
295.00000000000347,35.520636298191555,1.1269354947348078,-0.5487773875836197
296.00000000000347,35.616304082272016,1.1216207659051376,-0.5656932904032246
297.0000000000035,35.713047761965775,1.1150813462021099,-0.5834842260890327
298.0000000000035,35.80774946872641,1.109422846242313,-0.5998676125039402
299.0000000000035,35.90406904914011,1.099440838767403,-0.6159388289144756
300.0000000000035,35.998865183120245,1.0869988415012286,-0.6326484712184852
301.0000000000035,36.09570336236053,1.068890574963225,-0.6515386150554741
302.0000000000036,36.190608896910845,1.0499606447694325,-0.6700951645094078
303.0000000000036,36.28712323384685,1.0286408615213718,-0.6857242611296912
304.0000000000036,36.382386346668,1.006469150459168,-0.7017059269012349
305.00000000000364,36.477916577707816,0.9846637011040379,-0.7159457184895346
306.00000000000364,36.574512613588745,0.9649002586527493,-0.732477905709124
307.00000000000364,36.67030308727844,0.9408340385179985,-0.7482168668152029
308.00000000000364,36.76621950978631,0.920654461996337,-0.7648750701491482
309.00000000000364,36.86105273988983,0.9024321850676117,-0.779521773107366
310.0000000000037,36.955391990562866,0.8787997621457013,-0.7923472743870614
311.0000000000037,37.052953463624654,0.8593386941407299,-0.8063603915588811
312.0000000000037,37.1497176974942,0.8396007037776253,-0.820488393768342
313.00000000000375,37.24421935978638,0.8200346228592025,-0.8336420100573121
314.00000000000375,37.34126496025332,0.8004033763755114,-0.8466679724302857
315.00000000000375,37.435699968651065,0.7877407326547546,-0.8603922225900487
316.00000000000375,37.532429773121606,0.7712663497258683,-0.872504079425819
317.00000000000375,37.62778543434474,0.7555226176790262,-0.8854430849289048
318.0000000000038,37.72336654481473,0.7432268117571953,-0.8961263277264231
319.0000000000038,37.81960357215798,0.7330501740515383,-0.9092018849312948
320.0000000000038,37.9158474558303,0.7186301107688469,-0.9216170751347486
321.00000000000387,38.01096797835956,0.7065948183550426,-0.9327319054614716
322.00000000000387,38.10815888521571,0.6972846156658774,-0.9450759159457589
323.00000000000387,38.20255936915038,0.6872643303273918,-0.9563972057003829
324.00000000000387,38.29990018976339,0.6773933385236449,-0.9682869340204272
325.00000000000387,38.39559522865814,0.6694785101065566,-0.9798667603152018
326.0000000000039,38.492782968487305,0.66130223833771,-0.993115183184492
327.0000000000039,38.5900986422939,0.6538857988924067,-1.0056317394116596
328.0000000000039,38.68593095193348,0.6475105612513454,-1.0164583695448575
329.000000000004,38.782448064212495,0.6428800381623385,-1.0269362429351125
330.000000000004,38.87892035114007,0.6351979377673468,-1.040012363173549
331.000000000004,38.974777614939285,0.6309266843396568,-1.0523420019742589
332.000000000004,39.07166786178742,0.6273900550021704,-1.0644454713401288
333.000000000004,39.16859311844511,0.622765993297569,-1.0776771898982158
334.00000000000404,39.26560418485751,0.6173503812525446,-1.090535306171681
335.00000000000404,39.36171803692335,0.6123207251155917,-1.1040125984327127
336.00000000000404,39.45836928679969,0.6068630060366689,-1.1165234923490912
337.0000000000041,39.55263426936108,0.6024556236918146,-1.1287771096097017
338.0000000000041,39.65067806549966,0.5972651481633083,-1.1438581785256394
339.0000000000041,39.7480240714127,0.5928807604411214,-1.1558631928724616
340.0000000000041,39.84501218400785,0.5881024202872711,-1.169132870756202
341.0000000000041,39.942180454108744,0.5835120281271134,-1.1840351438401377
342.00000000000415,40.03870468241422,0.577283140674556,-1.1985237936582172
343.00000000000415,40.13509984048136,0.5735804524962512,-1.213123274534289
344.00000000000415,40.23277119086924,0.5658815157223116,-1.2278796178265483
345.0000000000042,40.32973019935058,0.5613867606197223,-1.2424980822804654
346.0000000000042,40.4261363581224,0.5580218020563472,-1.2572963944200182
347.0000000000042,40.52307018245838,0.5501348814151725,-1.2724705883632104
348.0000000000042,40.620101131865056,0.5453267329200497,-1.2883286201980755
349.0000000000042,40.71676075593356,0.5367088908405374,-1.3035112381504974
350.00000000000426,40.81366634985653,0.5325651849610453,-1.320137440360635
351.00000000000426,40.91048845468574,0.5253008145236113,-1.3349583692108293
352.00000000000426,41.006512529342025,0.5195500329622982,-1.3514760709225784
353.0000000000043,41.10306831723065,0.5121726866761737,-1.3684186159952718
354.0000000000043,41.20091391165608,0.5063389775803451,-1.3850497245298827
355.0000000000043,41.29783862700896,0.4992709762302382,-1.4035454484845036
356.0000000000043,41.39461360459815,0.49487262389560976,-1.4209775626855947
357.0000000000043,41.491336528155365,0.48954784042322846,-1.4366736781689067
358.0000000000044,41.58738860388227,0.4865428854183077,-1.4549753722749
359.0000000000044,41.68448869090153,0.4847855266850379,-1.47447104927471
360.0000000000044,41.78295853238257,0.4818097501487391,-1.4939644424450957
361.00000000000443,41.87821811350572,0.4805423324930258,-1.5147994291698104
362.00000000000443,41.97576664663042,0.4821097541488295,-1.5341115256552902
363.00000000000443,42.07343579446613,0.4830181228599217,-1.555732410121685
364.00000000000443,42.17036110976602,0.4834830499632832,-1.5781650471326092
365.00000000000443,42.26680363164131,0.48724544084252147,-1.600703032420998
366.0000000000045,42.36394403052194,0.4911526878856631,-1.6227647390797846
367.0000000000045,42.461206398346384,0.49445867044864367,-1.6459027668377235
368.0000000000045,42.55768164297741,0.49748835234124794,-1.670248814802362
369.00000000000455,42.655813936036026,0.5040533402587072,-1.6940964455526424
370.00000000000455,42.752320458274156,0.5078558753299216,-1.7215400742926814
371.00000000000455,42.84962152856342,0.514709962034548,-1.7465515496930832
372.00000000000455,42.9476732080106,0.5193486701445579,-1.77480463390309
373.00000000000455,43.04354048251739,0.5248061921342508,-1.8001769055585592
374.0000000000046,43.1407837279629,0.531281283681925,-1.828492509563917
375.0000000000046,43.23734474840535,0.5391156397193936,-1.858362362341146
376.0000000000046,43.33528824582886,0.5448722288160536,-1.8882030183473955
377.00000000000466,43.433403836488644,0.5513888008993205,-1.9196239433648192
378.00000000000466,43.52962318855088,0.5583105788852479,-1.9496389353882666
379.00000000000466,43.62659856468415,0.5660935098262199,-1.9814825250215327
380.00000000000466,43.72433893725322,0.5725430615462737,-2.015503523601078
381.00000000000466,43.82113102540125,0.5773279437782058,-2.049788320905614
382.0000000000047,43.91860975249262,0.5829385677597281,-2.084401637276758
383.0000000000047,44.01498097563677,0.5897685866544138,-2.1210322166715296
384.0000000000047,44.11271589259596,0.5944376121812844,-2.1579050034905856
385.0000000000048,44.21106022771594,0.5989831638256267,-2.1954143769166126
386.0000000000048,44.30795588823419,0.6004768298612058,-2.2341016065846766
387.0000000000048,44.40471899532823,0.6029146443937481,-2.273376913080231
388.0000000000048,44.50230589170638,0.6052132349126486,-2.3138572590570985
389.0000000000048,44.59937251714706,0.6028189954624776,-2.3528884903811758
390.00000000000483,44.69728868686895,0.604565404438469,-2.3941633179424415
391.00000000000483,44.79469947017291,0.605083319753634,-2.4344521695714736
392.00000000000483,44.89337372346775,0.6013929103873372,-2.478361785257752
393.0000000000049,44.98920245844982,0.597988303603939,-2.51827235305626
394.0000000000049,45.08728265098615,0.5929235453447667,-2.560465062301606
395.0000000000049,45.18431259760454,0.5837005338648434,-2.603643836437131
396.0000000000049,45.282739536746256,0.5781948660210123,-2.644736754371036
397.0000000000049,45.37931004851395,0.5674658828376556,-2.6867340048031885
398.00000000000495,45.47718383770811,0.5556390237303249,-2.728090573045946
399.00000000000495,45.5746671796231,0.5459075248922822,-2.768566997402792
400.00000000000495,45.671764509004404,0.5318667050780128,-2.807860523992552
401.000000000005,45.76782343399565,0.5186275102359322,-2.845261659836633
402.000000000005,45.86811211286114,0.5050466177917319,-2.883979008753488
403.000000000005,45.96496642920422,0.4919627879125609,-2.9204085657177994
404.000000000005,46.062334572337974,0.4727037235948735,-2.9559296736644343
405.000000000005,46.15932377616595,0.459305601378616,-2.9889562878572153
406.00000000000506,46.257370625741686,0.4421785717385038,-3.0231354499183785
407.00000000000506,46.355077820897975,0.4278474504802005,-3.0543364291382886
408.00000000000506,46.45139645152078,0.412602303661994,-3.084223999313309
409.0000000000051,46.54906445052041,0.3957343984073312,-3.1129988245752744
410.0000000000051,46.6465271082766,0.38091061686632777,-3.140013764495693
411.0000000000051,46.74497907248486,0.3633548164915754,-3.1664893854253746
412.0000000000051,46.842461636936406,0.3483445592428504,-3.189555101375897
413.0000000000051,46.93886879914401,0.33293977816931175,-3.213186170637042
414.0000000000052,47.036677219207505,0.31801680325640735,-3.2340188683628837
415.0000000000052,47.13318956891874,0.3070935804920459,-3.2546373123889314
416.0000000000052,47.23291146787087,0.2910955572376021,-3.2740564259354423
417.00000000000523,47.330424574972795,0.27877448049031106,-3.290583539231445
418.00000000000523,47.428765582812126,0.2670598273951216,-3.3083177583832493
419.00000000000523,47.52534129196506,0.2594641246706765,-3.3240576862351245
420.00000000000523,47.624514006353735,0.2484351910601058,-3.3369962594023104
421.00000000000523,47.72146494890951,0.23869523782079727,-3.350265213357147
422.0000000000053,47.81859670612213,0.23058886371775483,-3.3635195853857756
423.0000000000053,47.91714491253491,0.2247168002964034,-3.3727408559263807
424.0000000000053,48.01359292930346,0.218222541301286,-3.3823923738908706
425.00000000000534,48.113402929368505,0.21001791366251416,-3.3914851866495037
426.00000000000534,48.211117441343696,0.2066256152555475,-3.401763692546208
427.00000000000534,48.30903793177148,0.19983857267542876,-3.407741270711619
428.00000000000534,48.4077841227627,0.19626909872473303,-3.4151033458388946
429.00000000000534,48.50600612829276,0.19304094771839325,-3.422231357368476
430.0000000000054,48.60348209832858,0.19046613375805993,-3.4282247170161506
431.0000000000054,48.70148181243898,0.18703914661444876,-3.4347875829391414
432.0000000000054,48.80098811165813,0.18344451724896244,-3.4410062628608094
433.00000000000546,48.898243101126795,0.18250597445813432,-3.4442240366461956
434.00000000000546,48.99373667694093,0.18083711390740215,-3.4480308831286814
435.00000000000546,49.09400288906332,0.1781588342787604,-3.4527685555135834
436.00000000000546,49.19137785941003,0.17564816845745373,-3.457433101347866
437.00000000000546,49.29031185456172,0.17397918124047818,-3.461938985278283
438.0000000000055,49.38795255751734,0.1723221454257765,-3.4657840929290407
439.0000000000055,49.48538707474689,0.17421749968888228,-3.4696366060966097
440.0000000000055,49.58445094942691,0.17303658984822867,-3.471713040457187
441.00000000000557,49.680985181506756,0.17347373011440165,-3.4757054950940427
442.00000000000557,49.78049684887255,0.17311238271633012,-3.47863100322927
443.00000000000557,49.87789656013962,0.1715367489856348,-3.4808992621475596
444.00000000000557,49.975282349788955,0.17135054822986995,-3.484548220872867
445.00000000000557,50.073822771648096,0.17064132255874126,-3.485121466286293
446.0000000000056,50.17246187700182,0.17299226898511783,-3.487568848976943
447.0000000000056,50.26887490115634,0.17249109201849339,-3.490229961886878
448.0000000000056,50.36613117274426,0.1722403503969907,-3.4941780326158565
449.0000000000057,50.466146286475286,0.17367445935095482,-3.496808301607593
450.0000000000057,50.56452853197873,0.17408222061304507,-3.497649248452674
451.0000000000057,50.66207364912313,0.17602005731042214,-3.501363180797986
452.0000000000057,50.76073512786896,0.17449296627737382,-3.502690251783423
453.0000000000057,50.85941265032269,0.17448354878343236,-3.504940068405876
454.00000000000574,50.95699275117491,0.17616700899258714,-3.5075785320236914
455.00000000000574,51.05547775781717,0.17615911899315767,-3.508886934934169
456.00000000000574,51.153365153093965,0.17772845530403797,-3.513247778551162
457.0000000000058,51.251175606234355,0.17792335228586598,-3.5112510074630974
458.0000000000058,51.34954052609559,0.17943673665111193,-3.51343446723729
459.0000000000058,51.44831081067536,0.17866836291213878,-3.516671888739787
460.0000000000058,51.5461601215868,0.1789180947790387,-3.519198186907216
461.0000000000058,51.64453605289043,0.18358563949454976,-3.5247110228577063
462.00000000000585,51.742397401867336,0.18491025765234365,-3.5273047543173615
463.00000000000585,51.841950119504865,0.18480311903771124,-3.530522775734178
464.00000000000585,51.939367235567424,0.18612045725500692,-3.5342567173786064
465.0000000000059,52.03916484910782,0.18553788430565518,-3.5381817458493106
466.0000000000059,52.13734215651337,0.18710180260928272,-3.541508434096613
467.0000000000059,52.235444734957326,0.18586090057054894,-3.5448358364409476
468.0000000000059,52.333701245080434,0.18733238964933382,-3.547868673215561
469.0000000000059,52.432177716059975,0.18901491358368588,-3.5521847186586513
470.00000000000597,52.530583190857186,0.18827540667011042,-3.5531121499310006
471.00000000000597,52.628542309783214,0.18750212482888926,-3.5553201684633247
472.00000000000597,52.72769451411992,0.18838376212898927,-3.557673158070723
473.000000000006,52.825799064507265,0.18731022334573766,-3.5610896694385072
474.000000000006,52.925539964495925,0.1867645087776384,-3.5683541026573478
475.000000000006,53.02215397774224,0.1877060965579014,-3.5750257112962474
476.000000000006,53.12059448080521,0.18553575098985572,-3.578774150538343
477.000000000006,53.21959059985057,0.18643350833276176,-3.5864533436963586
478.0000000000061,53.31769846897656,0.18587903881165663,-3.591489489794559
479.0000000000061,53.41736279281358,0.18330359951183958,-3.593485831040509
480.0000000000061,53.51752846494936,0.18216071028804648,-3.5942927733529064
481.00000000000614,53.61584937440541,0.1803073256341671,-3.595369409482082
482.00000000000614,53.71399509723401,0.17744989450930693,-3.5976416014743116
483.00000000000614,53.81344300554793,0.17481707265468058,-3.5995577259552114
484.00000000000614,53.91179189635675,0.17272620975103314,-3.601705440586922
485.00000000000614,54.01029117538707,0.17168516787918764,-3.604288340942478
486.0000000000062,54.10950563792575,0.1696510566561591,-3.6056164355876206
487.0000000000062,54.20875074351911,0.16420885976891875,-3.608248066768271
488.0000000000062,54.30778072069026,0.16489333081815788,-3.6106458671657777
489.00000000000625,54.406454535625976,0.16255322386701454,-3.611270749937689
490.00000000000625,54.502639065585505,0.16207691284377734,-3.6142686072893766
491.00000000000625,54.60371276851445,0.16022241540230053,-3.6168073807277725
492.00000000000625,54.70191753968582,0.15568810193780425,-3.616916812179454
493.00000000000625,54.80071787445554,0.15753444118692633,-3.6182402159663143
494.0000000000063,54.899704104981275,0.15463466074187426,-3.618231656380024
495.0000000000063,54.99926208311534,0.15400855934103014,-3.6195599081520196
496.0000000000063,55.09752134372074,0.15561826584845545,-3.6208693479474503
497.00000000000637,55.195810326204864,0.15957523185831352,-3.6214323103557127
498.00000000000637,55.29427286383902,0.15795271085112056,-3.6221896397395175
499.00000000000637,55.39274921401237,0.15900489261748846,-3.623509172127535
500.00000000000637,55.491724177089004,0.15999631926968774,-3.623634033992279
501.00000000000637,55.59169196979042,0.15854978366031253,-3.62482995438947
502.0000000000064,55.69048496172128,0.1592016636793,-3.626133047604332
503.0000000000064,55.78909117804444,0.15535235484991106,-3.6261452024650125
504.0000000000064,55.88864934214486,0.15688382027472858,-3.6271298684261732
505.0000000000065,55.985596644257406,0.15688826798385302,-3.6274627663797303
506.0000000000065,56.086615300080005,0.1555700607830333,-3.628780478174154
507.0000000000065,56.1848524211111,0.15843525219211102,-3.630100200396422
508.0000000000065,56.284300683554875,0.15889480530173575,-3.6314076677526064
509.0000000000065,56.38339464743547,0.16009077517082854,-3.630243838693488
510.00000000000654,56.48220482604331,0.15906696901266826,-3.631413535585388
511.00000000000654,56.58040270123869,0.15737834444103083,-3.632730587062299
512.0000000000066,56.680289147416886,0.15781034238222538,-3.6327301920007464
513.0000000000066,56.778919058479445,0.15910838959952264,-3.6327299645544864
514.0000000000066,56.87808552422034,0.1564518187947113,-3.634065325768913
515.0000000000066,56.976941496829916,0.15653798828712995,-3.6333901473385546
516.0000000000066,57.076769742950916,0.15940257238670263,-3.6347001223473034
517.0000000000066,57.17588586554795,0.15760798217635638,-3.6347011137907055
518.0000000000066,57.27433854383303,0.15695566050189766,-3.637340601426157
519.0000000000066,57.37386470476238,0.15766405357474012,-3.6360148073049268
520.0000000000066,57.47182437354985,0.15573560660062657,-3.6373398092131533
521.0000000000067,57.571914976153224,0.15545045724262901,-3.637339842942532
522.0000000000067,57.67144704422082,0.15323944909113388,-3.6363875993047348
523.0000000000067,57.77026512279353,0.15425817297785277,-3.6373401371276533
524.0000000000067,57.87045891448155,0.15294208788813315,-3.6373400480002216
525.0000000000067,57.96957860547509,0.15065566443107833,-3.6373400614621896
526.0000000000068,58.06912964966629,0.14962733112187881,-3.6386465365283676
527.0000000000068,58.16848902738728,0.15174880674751834,-3.6399702320877525
528.0000000000068,58.26765115864213,0.1521960569703409,-3.640495362197657
529.0000000000068,58.36703113600124,0.150353418934769,-3.6399847696993817
530.0000000000068,58.466287535656505,0.15039797292711254,-3.64127362295241
531.0000000000068,58.56647897272416,0.14903547639630507,-3.6412970750892693
532.0000000000068,58.66426022019834,0.1516103315002195,-3.6426003056812046
533.0000000000068,58.764061303946555,0.15056328290551785,-3.643920252438646
534.0000000000068,58.86278455403386,0.1502028911903078,-3.64260736939259
535.0000000000068,58.96205437579801,0.15191808569668738,-3.643928504863102
536.0000000000068,59.061933054504806,0.1513730902003097,-3.6439485073063107
537.0000000000069,59.162438590116174,0.1495060197234272,-3.6432593754173395
538.0000000000069,59.260302482446406,0.15142492453095857,-3.6445783213760152
539.0000000000069,59.35844099454821,0.15055995443342868,-3.643270054671871
540.0000000000069,59.45913161740072,0.15135122633214212,-3.6439116324715153
541.0000000000069,59.558133353340054,0.15011984887520824,-3.644489451238343
542.000000000007,59.6573214074197,0.1481588629795036,-3.6452521150053694
543.000000000007,59.75681787663316,0.15101411703227632,-3.6459206121866035
544.000000000007,59.855449501801594,0.15057486959324262,-3.645899651340085
545.000000000007,59.955955998911946,0.1508437432609583,-3.6472196469288027
546.000000000007,60.0548520749331,0.1525067587236221,-3.6472198603444093
547.000000000007,60.15541470013845,0.1537813374923457,-3.6475039733525416
548.000000000007,60.253752515197924,0.15262679568980977,-3.6485400895623137
549.000000000007,60.353908921605615,0.15607553906957441,-3.6482100879999746
550.000000000007,60.45279757528695,0.15672879537862522,-3.6478800879677595
551.000000000007,60.55139686205372,0.1570071521333065,-3.6478800878700315
552.000000000007,60.651549279663435,0.15559644687725366,-3.6483412338878436
553.0000000000072,60.74938625064552,0.15828263014332902,-3.649199976752218
554.0000000000072,60.84958311246521,0.15878010198362508,-3.6505100977515657
555.0000000000072,60.948824973477976,0.1574373720434532,-3.6505100660002148
556.0000000000072,61.04788007407011,0.16074269787602438,-3.650510066035311
557.0000000000072,61.14627938354984,0.1599631416111581,-3.6505357592596015
558.0000000000073,61.2463639060789,0.16072702367928146,-3.651829948118471
559.0000000000073,61.344718005363376,0.16206908907267256,-3.6505378013454584
560.0000000000073,61.44466683497254,0.16018489639256087,-3.6518301218361304
561.0000000000073,61.54421725388975,0.16142098621251666,-3.6518301188265125
562.0000000000073,61.64307020419545,0.16231957353511914,-3.6517692113192775
563.0000000000073,61.74243163338904,0.16099761679424732,-3.6544538292340705
564.0000000000073,61.84181117477553,0.1630466173404298,-3.6538000965547415
565.0000000000073,61.94172392125731,0.16207547204270467,-3.653800096997585
566.0000000000073,62.04093257117981,0.1629253168992184,-3.6537993914340525
567.0000000000073,62.14069173883496,0.1620479533133877,-3.65480494019952
568.0000000000074,62.240321235271004,0.16503513218503613,-3.6544606217675843
569.0000000000074,62.34057627792668,0.16460529358685894,-3.657113113420032
570.0000000000074,62.439588677128555,0.1649432387447206,-3.655780042138934
571.0000000000074,62.53864396706506,0.16483699640908805,-3.657099947429444
572.0000000000074,62.63894272733417,0.16623498067188483,-3.6570999749677977
573.0000000000074,62.73854767166071,0.16568677467830772,-3.657198680349378
574.0000000000074,62.837366235002065,0.16534539155236683,-3.6557899784631362
575.0000000000075,62.936705285153174,0.166680274037786,-3.658441669101288
576.0000000000075,63.037532397627,0.16619664221796546,-3.658410242016332
577.0000000000075,63.136852234327826,0.16793537813606074,-3.657100233774145
578.0000000000075,63.23787542816989,0.16815468628186392,-3.6571112704151254
579.0000000000075,63.33661147735334,0.16623761815945523,-3.659708993291752
580.0000000000075,63.43704203818395,0.16592440446556378,-3.658419936813054
581.0000000000075,63.536557194670166,0.16642267121108192,-3.6574829379304794
582.0000000000075,63.63698999153566,0.1649206446191456,-3.659774872127289
583.0000000000075,63.73391677387883,0.16531431918607584,-3.659716313493586
584.0000000000076,63.83597150859774,0.16363622290920452,-3.659740032785279
585.0000000000076,63.93582062571064,0.1639659381255468,-3.65974000600003
586.0000000000076,64.03523828651942,0.16386431032476295,-3.6597399924262572
587.0000000000076,64.13365881593988,0.16286204696312817,-3.661030052120705
588.0000000000076,64.23302055832136,0.16327769944699727,-3.661050158970003
589.0000000000076,64.33367578303681,0.16277329822268846,-3.6610501589997284
590.0000000000076,64.43206327562812,0.16301875963646692,-3.661049955727417
591.0000000000077,64.5316231880209,0.16298857557654328,-3.6597303602917455
592.0000000000077,64.63142334470861,0.15999252746298423,-3.661050010628302
593.0000000000077,64.7306619328416,0.16054861172124676,-3.6610494142085397
594.0000000000077,64.83042951745993,0.1566297908657224,-3.660994562737326
595.0000000000077,64.93042852012103,0.15537450199800257,-3.6610498088961614
596.0000000000077,65.02989955137103,0.15238080631298187,-3.661051622389992
597.0000000000077,65.12890659552346,0.1493836588322367,-3.6633603050511416
598.0000000000077,65.23018900423696,0.14671580225029185,-3.6633599800004895
599.0000000000077,65.32902374488505,0.14360967165590885,-3.6633599374999113
600.0000000000078,65.42865646418801,0.13989455125968892,-3.662698811310668
601.0000000000078,65.52958046355843,0.13777757358208248,-3.663020588713211
602.0000000000078,65.628394688357,0.13648874357912036,-3.6643401991332767
603.0000000000078,65.72843081515371,0.13608752384359823,-3.6643401880510433
604.0000000000078,65.82774909253399,0.13559439438528517,-3.6650183034471815
605.0000000000078,65.92893628822937,0.1325637617343437,-3.666334109218828
606.0000000000078,66.0277405026522,0.1319661199442601,-3.6650099429966927
607.000000000008,66.12721506274306,0.13116536684733177,-3.6650098400001574
608.000000000008,66.22537811491786,0.12677677734737863,-3.6650098311538843
609.000000000008,66.32754580293772,0.12761089234578005,-3.6660133711679834
610.000000000008,66.42461052122972,0.1298506355142909,-3.666650321733764
611.000000000008,66.52641865243304,0.1285906011323642,-3.66523920489732
612.000000000008,66.62625967152357,0.12814764073876087,-3.6664662786095152
613.000000000008,66.72569833703291,0.12733178424317634,-3.6666498177204603
614.000000000008,66.8256974925206,0.12737495221724043,-3.6666451498640007
615.000000000008,66.92534268071527,0.12612180956021424,-3.667969986953213
616.0000000000081,67.02514177663821,0.1234420373706289,-3.6679578822475563
617.0000000000081,67.12458328902338,0.1238951097217176,-3.6679769193054943
618.0000000000081,67.22418243152947,0.12400651251392925,-3.667969380970625
619.0000000000081,67.32351562559776,0.12304605040808675,-3.669279847539906
620.0000000000081,67.4241776303529,0.1251275642131866,-3.6692800238480046
621.0000000000081,67.52355975084939,0.12302770000394747,-3.6692037514453677
622.0000000000081,67.62386102515582,0.12254343621482336,-3.670599852186897
623.0000000000082,67.72288353836036,0.12431158927538163,-3.6707334921921095
624.0000000000082,67.82272951503751,0.12587527264534074,-3.670600077145516
625.0000000000082,67.92277905197588,0.1245920818977444,-3.6706000769413505
626.0000000000082,68.02198003673868,0.12468318942306106,-3.670576299934441
627.0000000000082,68.12224681302925,0.12581528264979475,-3.6719165207528253
628.0000000000082,68.2212193944083,0.12649255829796324,-3.6729000145432407
629.0000000000082,68.32171853844103,0.12758187317643313,-3.6732320570924797
630.0000000000082,68.42141299694983,0.129438411988172,-3.673228042937627
631.0000000000082,68.52009543971062,0.13092887459288052,-3.6752180052232837
632.0000000000083,68.62039600231736,0.13415048430203227,-3.675870525420541
633.0000000000083,68.72038782586792,0.13628933737582097,-3.6748824851943906
634.0000000000083,68.82031697681455,0.13750363129749457,-3.6762055209164464
635.0000000000083,68.91990344410188,0.14004800352523586,-3.6775200858727817
636.0000000000083,69.0193884170522,0.14582189890885044,-3.6773948261398073
637.0000000000083,69.12010140652362,0.15155257673062816,-3.6774084401288523
638.0000000000083,69.2185834340322,0.15690340408520803,-3.677406999789072
639.0000000000084,69.31968978934971,0.16176871657016417,-3.6791499016026465
640.0000000000084,69.41863304417808,0.16873049127416856,-3.679828813140184
641.0000000000084,69.51877678167327,0.17527650755613047,-3.6807917230476077
642.0000000000084,69.61910795248174,0.18124103809862935,-3.6824165686078945
643.0000000000084,69.71831775889558,0.1872839769400598,-3.682428585556574
644.0000000000084,69.81765098985166,0.1941944196926502,-3.68369037178792
645.0000000000084,69.91847127586666,0.20130445246713363,-3.68378798339323