File: 01_Data/Memory_Foam_Carpet_Pad/STA/N2/10K_min/Memory_Foam_Carpet_Pad_STA_N2_10KData_221013_R3.csv
##Temp./Â°C,Time/min,DSC/(mW/mg),Mass loss/mg
51.0,10.804742564569308,0.06307447616589879,0.013685377881731853
52.000000000000014,11.126005184352188,0.10793988427062562,0.013261173212262278
53.00000000000003,11.360335598163486,0.15115773974558055,0.015507067320131185
54.00000000000004,11.551961578660489,0.1718446575615198,0.013984033887207481
55.00000000000006,11.724820339604358,0.1935999195337046,0.014755047530927712
56.00000000000007,11.884318987646726,0.20791367031938424,0.014126735096075649
57.000000000000085,12.03697072652147,0.2275017533413426,0.013689157512929206
58.0000000000001,12.179123473500999,0.23690667321466807,0.012355101796179824
59.000000000000114,12.31861593730275,0.24830601604206226,0.014075136413214118
60.00000000000013,12.455080108686818,0.2559005948530675,0.013111895923577421
61.00000000000014,12.587592967799244,0.26637879466846615,0.014224424349492892
62.000000000000156,12.715103941493506,0.2709546466156558,0.013117886355179742
63.00000000000017,12.84205643081873,0.2756282691948859,0.015707971698494916
64.00000000000018,12.96760617235105,0.28121300226891854,0.014205594666156784
65.0000000000002,13.08892099042121,0.28852045186990694,0.014056337934534646
66.00000000000021,13.211467912617227,0.29353571246013144,0.014327322684303923
67.00000000000023,13.330984089792414,0.2977571210091281,0.013440582894105546
68.00000000000024,13.450116243089962,0.3013133533758052,0.01323249279142047
69.00000000000026,13.566565579246218,0.306183044654436,0.015147850855811384
70.00000000000027,13.68354327005725,0.3095696585781613,0.016453379748576857
71.00000000000028,13.798758032112449,0.31347467592672484,0.016719025023139267
72.0000000000003,13.91343249708247,0.3183204092529637,0.015870526291149822
73.00000000000031,14.026085760148092,0.32236073625926986,0.015011120919955268
74.00000000000033,14.138610521652726,0.3251988403711098,0.015479818218556929
75.00000000000034,14.249631445523427,0.33038824531565214,0.016104132688154138
76.00000000000036,14.355866226979714,0.33427323901074657,0.01540528759977633
77.00000000000037,14.47023954044809,0.33745674841586093,0.015480449139077201
78.00000000000038,14.57978088562656,0.34234767673229927,0.016134474596970705
79.0000000000004,14.687448528657574,0.34583248531073785,0.01659916344687673
80.00000000000041,14.79636924590371,0.34463249240358296,0.015511828610665468
81.00000000000043,14.903310444143258,0.3478543791704285,0.01613901591743261
82.00000000000044,15.009210562405526,0.3507924988363017,0.016799596049551724
83.00000000000045,15.116047611741699,0.3554778118987155,0.016801164767513477
84.00000000000047,15.221568667660922,0.35719764771818974,0.015439869995846678
85.00000000000048,15.328026322382934,0.3609937790083846,0.016798381315934918
86.0000000000005,15.43209639094476,0.36411090656418565,0.016782287910897864
87.00000000000051,15.53530411476515,0.36430622699247917,0.015542163740244419
88.00000000000053,15.63954531743928,0.36594416366431326,0.01547397974820619
89.00000000000054,15.741857233696111,0.36876060164376334,0.015480110792822188
90.00000000000055,15.846274461572683,0.37038323006136675,0.015793169748372193
91.00000000000057,15.94695431098145,0.3757258982704257,0.015340937985769187
92.00000000000058,16.050000000000065,0.37756757147596676,0.015411930706608956
93.0000000000006,16.152014154982176,0.37985937527654456,0.0167524773262544
94.00000000000061,16.25320770190797,0.3818376633870709,0.01574945985102527
95.00000000000063,16.354851754220768,0.3831886342377935,0.01676691684804421
96.00000000000064,16.45516225959008,0.38527269541106246,0.01678994658461974
97.00000000000065,16.5553532784873,0.38965221631240354,0.015551356514218462
98.00000000000067,16.652129340216828,0.3906369022679246,0.016458452224716424
99.00000000000068,16.75574509739996,0.3946788098233177,0.016075690289817146
100.0000000000007,16.855050145267306,0.393280782365097,0.01678995521843163
101.00000000000071,16.955241053865823,0.3965382828070869,0.015851926896854884
102.00000000000072,17.052421511425276,0.3979603512042478,0.016792902146055333
103.00000000000074,17.151500150182116,0.4024667301079833,0.016800114854988557
104.00000000000075,17.24947308663302,0.401631235572945,0.016415214190724114
105.00000000000077,17.34829087741989,0.40675582055524073,0.015447146635921172
106.00000000000078,17.447616955222397,0.4073890418301054,0.015418741111522749
107.0000000000008,17.54657420814409,0.40937618411224297,0.016800449699441167
108.00000000000081,17.64403663905221,0.410201704227639,0.016708412749928847
109.00000000000082,17.74292962615546,0.41315401153676057,0.016781094543547148
110.00000000000084,17.84103091450103,0.41383470076783524,0.01678983325474359
111.00000000000085,17.938996833942518,0.4148409990074817,0.01810257255966441
112.00000000000087,18.036709754630326,0.41856852912372045,0.016846965914309564
113.00000000000088,18.13445245761398,0.419683376066448,0.018120633155940702
114.0000000000009,18.22888790558848,0.4198880589213283,0.018344670211424052
115.00000000000091,18.32991607983255,0.4218884506758196,0.018110038614548074
116.00000000000092,18.428142508149925,0.42418640459668455,0.01812811437415629
117.00000000000094,18.52478722992585,0.424949951729934,0.018123493704157667
118.00000000000095,18.623100843040703,0.42776366835524826,0.01942990447545956
119.00000000000097,18.719884959695282,0.4300615901394794,0.018108271834824663
120.00000000000098,18.81850183127035,0.43163029836226463,0.01808991917494218
121.000000000001,18.915250217835663,0.43501995499082646,0.017721345495594676
122.00000000000101,19.0137338563124,0.43681214028092064,0.018112936544423697
123.00000000000102,19.111683871780976,0.4401087662679857,0.01941630996926058
124.00000000000104,19.204501158737756,0.4425638181241647,0.01809965193858254
125.00000000000105,19.30456035748496,0.44508238098635566,0.018108323379292912
126.00000000000107,19.401292227733663,0.44344167275394875,0.019414489063349194
127.00000000000108,19.49889493544208,0.4401683899205161,0.018109965258948257
128.00000000000108,19.594852184200555,0.435053762978302,0.018001933834732142
129.0000000000011,19.691955839994993,0.4345589113811029,0.018114663753012294
130.00000000000114,19.788729427551793,0.4337127852105528,0.01675960274429844
131.00000000000114,19.88548453110951,0.43229645902241853,0.01774288934893864
132.00000000000114,19.981745415376178,0.43450776930133195,0.01877872495174593
133.00000000000117,20.078333797735144,0.43463305369536787,0.018770088756336456
134.0000000000012,20.17376621959329,0.43506086988808057,0.01846061531832177
135.0000000000012,20.270756803263417,0.43691321272396555,0.018439897122080495
136.0000000000012,20.36627636902783,0.4388450580490162,0.0187212620514714
137.00000000000122,20.461574406447788,0.4398632905892127,0.0190953902607518
138.00000000000125,20.557335490787075,0.440381488530439,0.01999839898055278
139.00000000000125,20.65408390806256,0.4419929233875719,0.01877059116017854
140.00000000000125,20.750097947018645,0.44080295381234014,0.017456420661102534
141.00000000000128,20.845803247587078,0.4417575068276498,0.01745035818780316
142.0000000000013,20.941782575777875,0.4436104850427457,0.016138844792365603
143.0000000000013,21.035987664616908,0.44402319592042727,0.017460954756788105
144.0000000000013,21.133390607857226,0.4463081935277228,0.017456863343014994
145.00000000000134,21.227480113777695,0.4441649895927565,0.017450174769309434
146.00000000000136,21.3237632091531,0.4480831146473635,0.018772185723475943
147.00000000000136,21.41924751682293,0.44904610306989023,0.017447059489783534
148.00000000000136,21.515304612979858,0.44983650562045463,0.016791053674378276
149.0000000000014,21.610822361159208,0.45074336883541666,0.016782450724562636
150.00000000000142,21.70468532760298,0.45053491561158887,0.0161398787732443
151.00000000000142,21.800349603373135,0.45096531621451563,0.017459094586833146
152.00000000000142,21.895145538541122,0.454806362013936,0.01706971761390097
153.00000000000145,21.991079236250336,0.45221059204451275,0.0161400824719502
154.00000000000148,22.087820209544446,0.455149586770185,0.016877468582889854
155.00000000000148,22.181998335969407,0.4551227751457144,0.016130197660451984
156.00000000000148,22.277163198539764,0.4561109964806024,0.016130198931970874
157.0000000000015,22.37302016712491,0.45889887092454784,0.016226401415575964
158.00000000000153,22.467910656636974,0.459799037260911,0.016129787690640995
159.00000000000153,22.563136721654192,0.4615209788157264,0.01729990538711057
160.00000000000153,22.658874384434238,0.4621839792125979,0.017399683064224902
161.00000000000156,22.75355340519254,0.46368285814994925,0.015748750937940592
162.0000000000016,22.849910964281815,0.4637127924035974,0.014820106296194346
163.0000000000016,22.944645434145407,0.46502693238837245,0.01472753164022933
164.0000000000016,23.039629961155605,0.4652837345069266,0.014825260909022475
165.00000000000162,23.13348392868923,0.4683358737823635,0.016130145916931404
166.00000000000165,23.230707732750076,0.46875793823218953,0.014855655914297827
167.00000000000165,23.325366366527746,0.46914138778993253,0.016123827959957815
168.00000000000165,23.419191718336783,0.4705368371020464,0.014819737197320215
169.00000000000168,23.514367533796076,0.47114418184889134,0.013832379283288176
170.0000000000017,23.610000000000163,0.47216010577436696,0.015151478344963998
171.0000000000017,23.70523891019897,0.47238427749506,0.01382972254892767
172.0000000000017,23.8006379448917,0.4736269528213734,0.013829855867740548
173.00000000000173,23.896319933071542,0.4756685636104427,0.013380573602506551
174.00000000000176,23.990293415678185,0.4747227926746365,0.013829952072401674
175.00000000000176,24.08594767321829,0.4764478398986121,0.015145027825473
176.00000000000176,24.180620739407114,0.4785556614624238,0.013829885603081848
177.0000000000018,24.276147448970647,0.4794913060179964,0.012591834316125983
178.00000000000182,24.370971085399265,0.47833921520993244,0.011860082423756246
179.00000000000182,24.466010971417983,0.4792178066851175,0.013169047876959716
180.00000000000182,24.559023862083635,0.48063907630324354,0.012503351931336226
181.00000000000185,24.65341347462929,0.4826820900188189,0.012510014043232154
182.00000000000188,24.751269809723496,0.4829055460572665,0.01250911874413152
183.00000000000188,24.845244751123374,0.48419035491664114,0.011190065261755144
184.00000000000188,24.940828911105637,0.48402989621710374,0.011177542610166569
185.0000000000019,25.036167773512474,0.48521386591324134,0.009870034671811467
186.00000000000193,25.130545097547177,0.4873454549716494,0.009855722499917619
187.00000000000193,25.225495297531936,0.48572085736448206,0.011190106351998352
188.00000000000193,25.32009560703191,0.48720137801243857,0.0111901061008286
189.00000000000196,25.414232839883738,0.48908338481293073,0.011019639582491081
190.000000000002,25.509514792540582,0.4886131919414417,0.008850629142772348
191.000000000002,25.605166642124402,0.4903491912659669,0.008876377502256894
192.000000000002,25.69930729334872,0.49021770479064,0.008891206357711567
193.00000000000202,25.793800422224688,0.4912679781401536,0.007899913663511171
194.00000000000205,25.88864193873851,0.49252514595872937,0.006907053884671832
195.00000000000205,25.982544941405514,0.49353821703115475,0.0069100600228013676
196.00000000000205,26.079280843317047,0.4940674382050283,0.006910059999999163
197.00000000000207,26.172742062765433,0.49485510969100793,0.006904335859677424
198.0000000000021,26.26807841932012,0.4987615592017652,0.005257821079307057
199.0000000000021,26.36334645981069,0.49719068808677164,0.005184834718066966
200.0000000000021,26.45854730039016,0.4992687503229863,0.00460001475646532
201.00000000000213,26.55199798822861,0.5008155782388577,0.004576103879697868
202.00000000000216,26.647896583114427,0.5031557442736618,0.001985506573784157
203.00000000000216,26.739637948984413,0.5047875340317549,0.0005660275120140668
204.00000000000216,26.837020539871563,0.5052687412408978,0.000698761010706761
205.0000000000022,26.931291153652754,0.5058642858532643,-0.0006629323379945262
206.00000000000222,27.02671116974285,0.507528898695301,-0.000660144973263499
207.00000000000222,27.12141156119877,0.5093662012266019,-0.0006601449996148645
208.00000000000222,27.215301984759012,0.5122479567806034,-0.0006601567152424437
209.00000000000225,27.310000000000212,0.5117750083022623,-0.0033024533809413725
210.00000000000227,27.406082082917607,0.5137682496046634,-0.0026417908416922486
211.00000000000227,27.500000000000245,0.5130483602966367,-0.0026398397017199926
212.00000000000227,27.595365524571513,0.5182875914708776,-0.0049578963228942285
213.0000000000023,27.689615906495554,0.5191170715315776,-0.005279927820497576
214.00000000000233,27.784903567274057,0.5202517997307241,-0.005279928434516634
215.00000000000233,27.879032737942225,0.5224669594278266,-0.006531404996424683
216.00000000000233,27.97471469746767,0.5234042179984892,-0.006589994523555021
217.00000000000236,28.068892399240006,0.5243973412085989,-0.006611484772406584
218.0000000000024,28.1630956020066,0.5265245089471434,-0.009219905369976189
219.0000000000024,28.258269924090804,0.5288997428150313,-0.010542231928987178
220.0000000000024,28.35350814346086,0.5319758040061605,-0.012498717099917123
221.00000000000242,28.44893444513476,0.533218591047928,-0.013833614289251894
222.00000000000244,28.5434072539272,0.5321175557503715,-0.015150738969222033
223.00000000000244,28.638232371208645,0.5358921232617662,-0.014489682668912707
224.00000000000244,28.733853007433126,0.5380546222019337,-0.01581794592828878
225.00000000000247,28.828323754947668,0.5368077550853492,-0.017014097107058035
226.0000000000025,28.923583808921737,0.5388355608574356,-0.017790185056534735
227.0000000000025,29.017712261468816,0.5411507749603683,-0.01909453249947246
228.0000000000025,29.113994858708015,0.5419757843004773,-0.02042579117741994
229.00000000000253,29.2086601497982,0.5466411488337539,-0.022414966269187264
230.00000000000256,29.303136337768372,0.5493336937959512,-0.02504773345301503
231.00000000000256,29.397651934293286,0.5530852262128314,-0.02634305599994846
232.00000000000256,29.493305800351532,0.5545172837151956,-0.027669134993841382
233.0000000000026,29.5873218282691,0.5582900664154902,-0.03029775814471458
234.00000000000261,29.682689493822732,0.5614996567149754,-0.0312588631125319
235.00000000000261,29.77774979033216,0.5648433145440577,-0.03230698000670307
236.00000000000261,29.873279185300696,0.5660936824891509,-0.03359748969240295
237.00000000000264,29.969140159637114,0.5711070073347755,-0.036235454848216
238.00000000000267,30.06342748472597,0.5743139172588725,-0.038867299188193094
239.00000000000267,30.15874957462152,0.5782272612981819,-0.04017966639542392
240.00000000000267,30.253447612345802,0.583082473801356,-0.04149767656226855
241.0000000000027,30.3484599876205,0.5869063678394635,-0.04407611996767491
242.00000000000273,30.44352519377553,0.5917643058189661,-0.04678089686566711
243.00000000000273,30.53954041991082,0.5964191494870672,-0.04950880465399621
244.00000000000273,30.634086093275503,0.602574684153675,-0.0508801575744644
245.00000000000276,30.729818735660913,0.6081962242568828,-0.05346130180527453
246.00000000000279,30.824488054760426,0.6133048219432611,-0.05611028799642126
247.00000000000279,30.920084830086832,0.6192056880650638,-0.060059989882953246
248.00000000000279,31.01482630835275,0.6247538712109122,-0.06305714892185232
249.0000000000028,31.109912687379456,0.6338232905567668,-0.06587143873883905
250.00000000000284,31.205803985014228,0.6389434913353134,-0.0710277418574905
251.00000000000284,31.301565197551877,0.6466335862283467,-0.07236388915190695
252.00000000000284,31.396199215499138,0.6544135155888113,-0.07597160825475457
253.00000000000287,31.490886251405357,0.6613280885152933,-0.08055745886270671
254.0000000000029,31.586085315024327,0.6697875182721234,-0.08620472590381345
255.0000000000029,31.682185130161233,0.6769100510452642,-0.08867954623075613
256.0000000000029,31.777115768712324,0.6868308916756762,-0.09330882964988607
257.00000000000296,31.87270621115475,0.6944372928585509,-0.09774851628039327
258.00000000000296,31.967348341699488,0.7028586605605931,-0.10222314135857591
259.00000000000296,32.062116294387366,0.7138707927435645,-0.10657313937957724
260.00000000000296,32.15849829562474,0.7213374434275691,-0.11080954916031471
261.00000000000296,32.253414601180054,0.7314778648259312,-0.11750013598343223
262.000000000003,32.3486494481758,0.7432352925107516,-0.12340122423469957
263.000000000003,32.44427986303726,0.7540662820557446,-0.12984211190120787
264.000000000003,32.540094306896364,0.7664841711336484,-0.13548193092362393
265.00000000000307,32.635007062677005,0.7760790278276514,-0.14301542340919804
266.00000000000307,32.73039608630848,0.7896412435163156,-0.1496506746778219
267.00000000000307,32.825127957295514,0.8024843998759041,-0.15614013310177777
268.00000000000307,32.92139533891608,0.8158294317997444,-0.16328605630000448
269.00000000000307,33.01708288515092,0.8315912692646831,-0.1718927734429614
270.0000000000031,33.11279572098988,0.8428717589987129,-0.17944284016117873
271.0000000000031,33.20762816158294,0.8594950508919375,-0.1866777803413977
272.0000000000031,33.30383103809662,0.8730152342851017,-0.19714172761208237
273.0000000000032,33.39969936425597,0.8898340602286281,-0.20549842137697372
274.0000000000032,33.49517778826714,0.9090891321929824,-0.21530487734667236
275.0000000000032,33.59094994303166,0.9226697909743933,-0.2268995948862349
276.0000000000032,33.686433189895766,0.9401753344875672,-0.23614283566038763
277.0000000000032,33.78230222362125,0.9598262999400629,-0.2477191376108019
278.00000000000324,33.878538262043634,0.9767640420340364,-0.2586396178433894
279.00000000000324,33.97437986973129,0.9930572554283383,-0.27141650857705235
280.00000000000324,34.07041748527791,1.0101706510912414,-0.2846302457323735
281.0000000000033,34.165813208006135,1.0303211546598907,-0.29660471731087323
282.0000000000033,34.26198280645109,1.0505320248471888,-0.30950634348060824
283.0000000000033,34.3570844586561,1.0659607507325939,-0.322201787846792
284.0000000000033,34.45356882887704,1.0871345045299519,-0.3368563649742353
285.0000000000033,34.55009242463243,1.101575171686255,-0.3521497394893802
286.00000000000335,34.64492265374871,1.1206965148122943,-0.36785402586099014
287.00000000000335,34.74107869485583,1.1381357714442495,-0.38290121665164856
288.00000000000335,34.837730876014405,1.1535663480726888,-0.3976459834422639
289.0000000000034,34.93284502100526,1.166631038851926,-0.41225836139203675
290.0000000000034,35.029896832823155,1.1760156933001373,-0.42891660235968754
291.0000000000034,35.12437523534156,1.183530314840751,-0.44702520043225036
292.0000000000034,35.22103431655365,1.1898322265605912,-0.4642426042164267
293.0000000000034,35.31385358813394,1.1930283476825998,-0.47982912906782227
294.00000000000347,35.412173207559874,1.194035610121329,-0.49678565069016933
295.00000000000347,35.505901488690874,1.195429815683513,-0.513875141487782
296.00000000000347,35.60282740364225,1.191522666369887,-0.5306525447144779
297.0000000000035,35.699725717235,1.1878743603631117,-0.5484363017264342
298.0000000000035,35.79512798991736,1.1787943923005115,-0.5651443290540596
299.0000000000035,35.891471284641405,1.1701993052680084,-0.5825229035281705
300.0000000000035,35.986693929025435,1.1580737590669339,-0.601481061673522
301.0000000000035,36.07961403412795,1.1424020184984662,-0.6185709008398907
302.0000000000036,36.17804728347649,1.1236394670091816,-0.6364094540084051
303.0000000000036,36.27436783905482,1.1023023078059673,-0.6539945938165395
304.0000000000036,36.3706296975122,1.0812770513867243,-0.671878838737535
305.00000000000364,36.46583658089091,1.0547508427770698,-0.6880974960686919
306.00000000000364,36.56260173272092,1.0303656909500223,-0.7041258837074582
307.00000000000364,36.65714030290301,1.0060028957156104,-0.7199322197102376
308.00000000000364,36.753344772721654,0.9835910440194282,-0.7361650484053288
309.00000000000364,36.84968206049787,0.9580581962294501,-0.7505463179978058
310.0000000000037,36.943355090273116,0.9363419009062136,-0.766263141516625
311.0000000000037,37.04028191298361,0.9119033635515253,-0.7799502392139708
312.0000000000037,37.135772775182524,0.891428046485123,-0.7931251400204657
313.00000000000375,37.231636322100094,0.8711961597602796,-0.8065710923087743
314.00000000000375,37.32547763892125,0.8525601530844586,-0.8216541632423948
315.00000000000375,37.42377868047934,0.8373308470107962,-0.8341064200742361
316.00000000000375,37.51865254550927,0.8179029993111716,-0.8462199013742486
317.00000000000375,37.615666643992014,0.8030161948524348,-0.8584632685731917
318.0000000000038,37.71059392536438,0.786838450427886,-0.8702500551009966
319.0000000000038,37.80674408769464,0.7735897913917795,-0.8827197565559781
320.0000000000038,37.902734521843826,0.7606465307891035,-0.8950486346247408
321.00000000000387,37.99956861597275,0.7490838427339241,-0.9057712950516366
322.00000000000387,38.09505857830516,0.735239236799463,-0.9165799017921348
323.00000000000387,38.1913812631035,0.7251564192114215,-0.9284790571232335
324.00000000000387,38.287269982041714,0.7148785279402473,-0.9407054705992293
325.00000000000387,38.38345609112078,0.7045882429545915,-0.9523821058837956
326.0000000000039,38.47902949297633,0.6953884258686923,-0.9634444006017366
327.0000000000039,38.576528819666024,0.6873334914150185,-0.9748375907946194
328.0000000000039,38.672816872184335,0.6796578552352421,-0.9862617587017262
329.000000000004,38.76902005894985,0.673042058189808,-0.9971510103201262
330.000000000004,38.86633333896437,0.6702575418235641,-1.0087849661247925
331.000000000004,38.96244852218571,0.6613918406291498,-1.0207175594374958
332.000000000004,39.05849489978559,0.6571059168952174,-1.0326108256220614
333.000000000004,39.15442496783239,0.6511076860248801,-1.044833965812023
334.00000000000404,39.25094866445304,0.6462081708451219,-1.0558494281622806
335.00000000000404,39.34660294008722,0.6389234610733758,-1.0680453539308488
336.00000000000404,39.443651521715324,0.6335908318583002,-1.083089744381466
337.0000000000041,39.539909986874896,0.628012948601977,-1.0953037755578139
338.0000000000041,39.636917350397944,0.6221978049519808,-1.108022829327357
339.0000000000041,39.7329788986072,0.617599545868231,-1.1205720303255884
340.0000000000041,39.82920447484159,0.6120976220095465,-1.13506556460773
341.0000000000041,39.92573618467374,0.6082489114683488,-1.1476382611628635
342.00000000000415,40.02345189771827,0.6066143360688622,-1.162599807862851
343.00000000000415,40.11924999917463,0.599027211672693,-1.1769203989477788
344.00000000000415,40.21637596282881,0.5924193256762516,-1.1913915986806765
345.0000000000042,40.31287691033015,0.5867058946321373,-1.2053863146648789
346.0000000000042,40.40982355865536,0.5827715750975109,-1.220095345272659
347.0000000000042,40.505369585016915,0.5727082534217312,-1.2344901962720494
348.0000000000042,40.60217613738982,0.5671958139979116,-1.2491583842519844
349.0000000000042,40.69968458866048,0.5610711805557136,-1.2658845421011224
350.00000000000426,40.795692894345834,0.5516986805180586,-1.2809792263955466
351.00000000000426,40.891695795331145,0.5484733189547999,-1.2990027316949804
352.00000000000426,40.988977653486344,0.5389639084406773,-1.3153236010485707
353.0000000000043,41.08523884028055,0.534312259188281,-1.3315899714992518
354.0000000000043,41.18186943406674,0.5290641786625023,-1.3496276568516477
355.0000000000043,41.279037859819425,0.5238878510228834,-1.36756116651335
356.0000000000043,41.375106037173715,0.519914724458556,-1.38631572472848
357.0000000000043,41.471575016881026,0.519145670228454,-1.4050432802314625
358.0000000000044,41.56840389993702,0.5169895394322064,-1.4248169842094196
359.0000000000044,41.665341828836624,0.5175524951473451,-1.4439198625130847
360.0000000000044,41.761160011973836,0.5185385147569948,-1.462922129165824
361.00000000000443,41.85887019656872,0.5189057210786265,-1.4851027753221815
362.00000000000443,41.95562352915341,0.5191168341580898,-1.5056479867067276
363.00000000000443,42.05241031404004,0.5226754154218416,-1.528378992384154
364.00000000000443,42.14836244356409,0.5244604259645202,-1.5491873039027384
365.00000000000443,42.24585775289782,0.5288756230161935,-1.5711433135287627
366.0000000000045,42.34022940335074,0.5331171249033618,-1.5935759260946636
367.0000000000045,42.4400000000004,0.535188452267036,-1.6194096757072565
368.0000000000045,42.536042999771425,0.5399060431197773,-1.641775885365682
369.00000000000455,42.633639181737394,0.5456630925235363,-1.668089423178741
370.00000000000455,42.73123335467495,0.5497797085594072,-1.6926391335021456
371.00000000000455,42.82816289464064,0.556350740969721,-1.7189495692597863
372.00000000000455,42.92497418644916,0.5635719654875128,-1.7446792793541372
373.00000000000455,43.02230000837264,0.5696738865843822,-1.7718077672007122
374.0000000000046,43.11990484071403,0.5763798501356769,-1.7998780793960716
375.0000000000046,43.216604671204955,0.5816835372105837,-1.828780296721121
376.0000000000046,43.3143333143539,0.5896713425526328,-1.858287349346063
377.00000000000466,43.41081532828143,0.5958360741345117,-1.8874400140370695
378.00000000000466,43.508089077203934,0.6052064836289135,-1.9204428501703843
379.00000000000466,43.604826209521846,0.6116364531328093,-1.9502654236179815
380.00000000000466,43.70238544403966,0.6187844667100207,-1.9831208430553993
381.00000000000466,43.79942051010761,0.6277609629786864,-2.0157840832849434
382.0000000000047,43.89717373107791,0.6342441100206647,-2.050544103108418
383.0000000000047,43.99418006001088,0.6425055366235541,-2.0872315607281617
384.0000000000047,44.092180954731994,0.6477043967767038,-2.1226709633260046
385.0000000000048,44.18847906204463,0.6546340750689923,-2.1605280987806648
386.0000000000048,44.28585038645926,0.6563042113866612,-2.197488521178573
387.0000000000048,44.383277718745155,0.6594932788146054,-2.237038870808636
388.0000000000048,44.4804981425586,0.6664115413646055,-2.2754109624854872
389.0000000000048,44.576748631902646,0.6677477607358066,-2.31360615072211
390.00000000000483,44.675671695116414,0.6717873413756635,-2.354996574286959
391.00000000000483,44.7726526915656,0.6722946114164179,-2.3951767915921147
392.00000000000483,44.86885346870406,0.6721218052885146,-2.4375386333603677
393.0000000000049,44.96641453133651,0.6692835929972345,-2.478527797637987
394.0000000000049,45.06418600237092,0.6662985595998546,-2.5203575828919735
395.0000000000049,45.1611216932563,0.6630477630695699,-2.5603204375051547
396.0000000000049,45.25814188611627,0.6553881712887246,-2.6007022068096655
397.0000000000049,45.354877686021425,0.6480539457389006,-2.6437931190320088
398.00000000000495,45.452546799334684,0.6400496389504973,-2.683880719322017
399.00000000000495,45.550468867394756,0.6305476314661846,-2.7228061031552975
400.00000000000495,45.64734148596169,0.6215554794882139,-2.762307140549691
401.000000000005,45.744303010188105,0.6107829097926706,-2.801366975577987
402.000000000005,45.84296027191312,0.5981270841657553,-2.838582934906371
403.000000000005,45.9397029808318,0.5872676314907764,-2.876537574814889
404.000000000005,46.03743964534253,0.5722505374196094,-2.9128541110790547
405.000000000005,46.135767628118536,0.5569813075632739,-2.947390698278686
406.00000000000506,46.2334411289373,0.5453484100828953,-2.9808654439670956
407.00000000000506,46.330309110503286,0.5311048292784193,-3.0112768736549613
408.00000000000506,46.427754427138446,0.5146849681205978,-3.0414311688597255
409.0000000000051,46.525859915298916,0.5039202925937314,-3.070042657887989
410.0000000000051,46.622507100586205,0.4915554496458545,-3.0999957521976738
411.0000000000051,46.720391452983186,0.47552730675784644,-3.124735443010495
412.0000000000051,46.81787644343368,0.4643031224673756,-3.148720905596357
413.0000000000051,46.916549700295015,0.45087753476108905,-3.1740208652473068
414.0000000000052,47.013121517791106,0.4392325610098708,-3.1968563540391974
415.0000000000052,47.11086669022177,0.42897709775703147,-3.218201366273896
416.0000000000052,47.209161132256654,0.42018906600122935,-3.2377759801713304
417.00000000000523,47.30699573136636,0.40818547165978947,-3.2554615268179425
418.00000000000523,47.40472308384761,0.4006544580250191,-3.2725730548370673
419.00000000000523,47.50209471630578,0.38939947973314426,-3.290421311423473
420.00000000000523,47.600214044167515,0.38506649590214564,-3.304933133715001
421.00000000000523,47.69767913902664,0.3756106749049441,-3.3182742716108606
422.0000000000053,47.79519753176247,0.37031416168995573,-3.3295722528452685
423.0000000000053,47.8923570278089,0.3664246868701439,-3.340754723710326
424.0000000000053,47.991179978797526,0.3605672126137444,-3.3506277073008475
425.00000000000534,48.08817183219855,0.35796995614740085,-3.361002088486873
426.00000000000534,48.1855223495745,0.35402053628146424,-3.369869690848068
427.00000000000534,48.28283166705013,0.3522348161437356,-3.3788459150513654
428.00000000000534,48.38042870942045,0.3490989934640784,-3.3860675638605455
429.00000000000534,48.47837687912621,0.34740531480826,-3.392760071105798
430.0000000000054,48.57698632806062,0.3461065964012354,-3.399989331415075
431.0000000000054,48.67176347263665,0.34494085348163317,-3.405470010244035
432.0000000000054,48.77132745483491,0.3439178321834506,-3.4109994717685055
433.00000000000546,48.869517658782904,0.3434201383667635,-3.415656631577521
434.00000000000546,48.96741339892988,0.3426929385331011,-3.42167700287267
435.00000000000546,49.064949622188244,0.3444130927506475,-3.4248427729058926
436.00000000000546,49.162016778792044,0.342952115201827,-3.4291858165788494
437.00000000000546,49.25970860672939,0.3450521010376443,-3.4331138448763925
438.0000000000055,49.356383557810894,0.3434643882622439,-3.4376377954510144
439.0000000000055,49.4557227320089,0.34805538117544904,-3.4408894040775992
440.0000000000055,49.552784573260496,0.3469893330665188,-3.442068241146709
441.00000000000557,49.65060445642035,0.34758274248665944,-3.4463614488518575
442.00000000000557,49.74897978300092,0.3479700242588126,-3.4497302033488735
443.00000000000557,49.84646003174088,0.348637593162767,-3.453017208027467
444.00000000000557,49.94423070683549,0.3477922134935768,-3.4546948239958275
445.00000000000557,50.04180279832563,0.3509598693101203,-3.458197831732581
446.0000000000056,50.139600383271805,0.3513917705022566,-3.4585304953849096
447.0000000000056,50.23801614308015,0.35143257963752234,-3.4610433766323307
448.0000000000056,50.335822846308155,0.35346893495071685,-3.4627816703282974
449.0000000000057,50.433598083479865,0.3539218715579842,-3.465379775606867
450.0000000000057,50.53193733999059,0.3583338626121244,-3.4680377163673626
451.0000000000057,50.63000000000058,0.3601638053031925,-3.4706900370000033
452.0000000000057,50.72689472322206,0.362006026578686,-3.472406745667487
453.0000000000057,50.825846363814655,0.36413573379446057,-3.4753008127268687
454.00000000000574,50.92327326545681,0.3637077021567515,-3.477539223152875
455.00000000000574,51.02146581259314,0.3647664183570953,-3.4806303924214412
456.00000000000574,51.118870546622894,0.36909422486394394,-3.4818711908688074
457.0000000000058,51.214973674947565,0.36946305639873267,-3.4855652856013144
458.0000000000058,51.315180893413,0.37183406162930116,-3.488142490899719
459.0000000000058,51.41375919430384,0.3741145462468533,-3.4895029583112214
460.0000000000058,51.51159283459415,0.3765598285641678,-3.492206019132002
461.0000000000058,51.60691816846964,0.3767875703094432,-3.494521411647705
462.00000000000585,51.70833582737987,0.3803975525756183,-3.4983815939692797
463.00000000000585,51.80637704205969,0.38316620778758886,-3.4989895727198004
464.00000000000585,51.90567511428136,0.3834087272788481,-3.503188901372334
465.0000000000059,52.00272915210362,0.3846694139877517,-3.5083560936091613
466.0000000000059,52.10148413208824,0.3867635263221913,-3.510564869922092
467.0000000000059,52.199534180499825,0.3890455040420945,-3.5138917710005257
468.0000000000059,52.29731082046028,0.3898445742963389,-3.515992363428184
469.0000000000059,52.39566541688135,0.39231027846833877,-3.518517806879552
470.00000000000597,52.49391896660091,0.3930148262291913,-3.524249425842276
471.00000000000597,52.59213848671728,0.39378282420059263,-3.5266212526784932
472.00000000000597,52.690281486830536,0.39574733083950675,-3.529642307908267
473.000000000006,52.789344075006916,0.39652906267536425,-3.5337584249472775
474.000000000006,52.88710790184275,0.39719477968321637,-3.536529948542581
475.000000000006,52.98654678073496,0.3973201578553127,-3.54082476682061
476.000000000006,53.08434718901148,0.397284401978621,-3.543585011033552
477.000000000006,53.18375251000126,0.39750719804621554,-3.546039075773709
478.0000000000061,53.282623556634725,0.39780977523260563,-3.547979276078708
479.0000000000061,53.38134344432562,0.3999545448279659,-3.5508873500512603
480.0000000000061,53.48000000000063,0.3983530111321345,-3.555167467969711
481.00000000000614,53.579056222508996,0.39880900342591064,-3.559109967948518
482.00000000000614,53.677327645549454,0.39745874813924426,-3.560506765782292
483.00000000000614,53.775864535236195,0.39598522470562464,-3.5635903037375796
484.00000000000614,53.874727288071476,0.39852336978393477,-3.5662319959677813
485.00000000000614,53.97463739678971,0.39582476392561283,-3.5674976937379057
486.0000000000062,54.07191160451093,0.39805035205950046,-3.569942647922722
487.0000000000062,54.17174363660205,0.3968659982020885,-3.571386132167615
488.0000000000062,54.270202789313,0.3950775906507773,-3.573219732363457
489.00000000000625,54.36899266483614,0.39611918747025676,-3.5751167281658116
490.00000000000625,54.46847759717267,0.3925575084555794,-3.5768413999112285
491.00000000000625,54.567316172894714,0.3942202045120984,-3.578160287665421
492.00000000000625,54.66479351078909,0.39508901430804205,-3.5794867743850443
493.00000000000625,54.76431898827161,0.39349630978991185,-3.5807843245130537
494.0000000000063,54.86243723375683,0.3928096883875959,-3.5811180734080086
495.0000000000063,54.961101890155575,0.39934801802744935,-3.582438486415204
496.0000000000063,55.05960154683814,0.39976486998924804,-3.5847385841728316
497.00000000000637,55.15933818879131,0.4039353922014387,-3.5863869062559655
498.00000000000637,55.256807169462114,0.4069768821793213,-3.586391338234192
499.00000000000637,55.355801619361245,0.41256743603819684,-3.5863957589109825
500.00000000000637,55.4540523798356,0.4151126638300845,-3.587710340239227
501.00000000000637,55.553226825075114,0.4137203075577815,-3.587710040428177
502.0000000000064,55.65201228498163,0.4168553820820351,-3.589036980568779
503.0000000000064,55.750875151637466,0.4218335523458701,-3.589008545753057
504.0000000000064,55.85000000000063,0.4247944959832086,-3.5890301867832965
505.0000000000065,55.94841186868266,0.424595226348275,-3.5893508415993987
506.0000000000065,56.04734378944013,0.42630551824745144,-3.590679886410869
507.0000000000065,56.14548147770609,0.4286578220814524,-3.5906707668997035
508.0000000000065,56.24523963848792,0.42996899982365305,-3.5913482111375488
509.0000000000065,56.344894437934904,0.4324821521930213,-3.591670736880662
510.00000000000654,56.44315715881545,0.4330180664280219,-3.5929945108690857
511.00000000000654,56.54198973402244,0.4344755941787725,-3.5921490710912893
512.0000000000066,56.6412268441028,0.43705934022239945,-3.5933169370446034
513.0000000000066,56.74028003901618,0.4383207756815566,-3.594655808908053
514.0000000000066,56.83906197960271,0.44055272700847886,-3.596590378387434
515.0000000000066,56.938527196470915,0.44307894294153183,-3.5959525039535514
516.0000000000066,57.03618769963196,0.44541036130759787,-3.5972719681174192
517.0000000000066,57.13655426147928,0.44910612188207283,-3.5985900498759107
518.0000000000066,57.23307512957612,0.44728064981238513,-3.5985912063396164
519.0000000000066,57.33370282445232,0.4509621241720246,-3.598556770249278
520.0000000000066,57.43349540998214,0.45408164395853273,-3.5986042407730596
521.0000000000067,57.531869229500224,0.4517724831735618,-3.599988896949019
522.0000000000067,57.628772839067864,0.45537598924671907,-3.5998994425029722
523.0000000000067,57.730881469770196,0.45345348400726593,-3.5995689442776793
524.0000000000067,57.8290643147095,0.45232211711119913,-3.600889872549362
525.0000000000067,57.92846650045771,0.4561911045802769,-3.6008842167527737
526.0000000000068,58.027250929285394,0.45630083574760155,-3.602206430420404
527.0000000000068,58.12619194557912,0.4575235503364393,-3.6045458795593195
528.0000000000068,58.225137376292764,0.4575104932782571,-3.603519579811
529.0000000000068,58.324783718552084,0.4610829909987522,-3.6043549235893493
530.0000000000068,58.42387394170545,0.4612021374287091,-3.606266506214344
531.0000000000068,58.52292833004475,0.4620734514944253,-3.606854490513729
532.0000000000068,58.6206804745259,0.46293342489106004,-3.6074823381320895
533.0000000000068,58.7219716222054,0.46314101906051364,-3.607799643373282
534.0000000000068,58.821195036717256,0.4665697137497231,-3.609119397460015
535.0000000000068,58.919588419273246,0.4638528749672784,-3.6091199680004733
536.0000000000068,59.01950507458696,0.4641377306003019,-3.6091199637964753
537.0000000000069,59.119036698872144,0.46784725691546236,-3.610437480048726
538.0000000000069,59.21750762053638,0.47028809232890983,-3.6104400615375836
539.0000000000069,59.317091970783025,0.46940873053819193,-3.61182520262025
540.0000000000069,59.415524751098495,0.47175801120609173,-3.6114269942208908
541.0000000000069,59.51527484285836,0.4717034870765514,-3.611747656013154
542.000000000007,59.614238712160436,0.4714508850974589,-3.6114276819415982
543.000000000007,59.71398488097546,0.4740967613544583,-3.611419809712943
544.000000000007,59.812734810296234,0.4780859723283554,-3.6114160021621213
545.000000000007,59.91341643513476,0.4836953426376483,-3.6127398989187647
546.000000000007,60.01202713048323,0.48763206311529417,-3.6129047874095415
547.000000000007,60.111016362034164,0.49064932972461966,-3.6137551075192107
548.000000000007,60.211173126386,0.4924878976827859,-3.614052733839882
549.000000000007,60.30979854566877,0.49568268160476026,-3.6143900286325583
550.000000000007,60.40936572708272,0.49777850913404365,-3.614390009391562
551.000000000007,60.509387767093386,0.5011359770175151,-3.6162574039497093
552.000000000007,60.60775102360301,0.5018038511628196,-3.617019332497551
553.0000000000072,60.705257819513015,0.5019643062625703,-3.6156999134777146
554.0000000000072,60.80614526074025,0.5065837850259876,-3.617265264802411
555.0000000000072,60.90592482127357,0.5090874535387857,-3.618315470235158
556.0000000000072,61.005140813690275,0.5125882728916009,-3.618298949778177
557.0000000000072,61.10406468620366,0.5137022808962791,-3.618339943988549
558.0000000000073,61.203241436062136,0.5158942756399629,-3.6183362459564745
559.0000000000073,61.30308610185685,0.5188839232392221,-3.6186801326643923
560.0000000000073,61.40218476666774,0.518240386533075,-3.618627330788722
561.0000000000073,61.50178017888626,0.5203036406933594,-3.6191827592288273
562.0000000000073,61.600930837541384,0.5188933739253928,-3.620029893690942
563.0000000000073,61.70017943666829,0.5228932938457642,-3.6209801720547605
564.0000000000073,61.800439756828816,0.5221355742161389,-3.620980171933194
565.0000000000073,61.89838348279765,0.5237792478776588,-3.621272752010407
566.0000000000073,61.99889601449987,0.5253045887304466,-3.6226255821371423
567.0000000000073,62.09810248264316,0.524083827455904,-3.622629885987924
568.0000000000074,62.19741309625412,0.5246492674409164,-3.622629886
569.0000000000074,62.296996467351384,0.523015753184337,-3.6226298859996837
570.0000000000074,62.39636308626053,0.5212925186390658,-3.6226297409968673
571.0000000000074,62.496529890684556,0.5213617391886083,-3.6227042724097607
572.0000000000074,62.596064885336475,0.5202569085606297,-3.6219669556423124
573.0000000000074,62.694458860897456,0.5202966574706486,-3.6232801367555427
574.0000000000074,62.795333663008535,0.5228125384556521,-3.623280044986255
575.0000000000075,62.894654697726935,0.5230223157380527,-3.623272874211246
576.0000000000075,62.99444793076404,0.5214672355502041,-3.6255974023065867
577.0000000000075,63.09422880785146,0.5196077999305271,-3.625590300864148
578.0000000000075,63.19348905346593,0.5211874009713611,-3.6253386785276946
579.0000000000075,63.29261223705964,0.520953268499643,-3.6252644826399156
580.0000000000075,63.39252244354346,0.5214728097719783,-3.6255898154194712
581.0000000000075,63.49120261769464,0.5205814390696554,-3.6273659216716077
582.0000000000075,63.59117994185391,0.5228927175327469,-3.6269101070311383
583.0000000000075,63.69087812058475,0.5231321755425871,-3.6269098707011054
584.0000000000076,63.790359163290866,0.5243241898610249,-3.62821998459997
585.0000000000076,63.89032581055791,0.5259018844955906,-3.6282200055024485
586.0000000000076,63.99111429555647,0.5285312370359446,-3.6285866201787615
587.0000000000076,64.08880358588293,0.5301387034556773,-3.6302001156969146
588.0000000000076,64.18938428220432,0.5300376548476822,-3.6315206310288897
589.0000000000076,64.2890907664004,0.5337273754197185,-3.6302001007051303
590.0000000000076,64.38837529153083,0.5329496463764896,-3.6302001741312457
591.0000000000077,64.48667805697119,0.5361830405426266,-3.6315165458209124
592.0000000000077,64.58793217088393,0.5350865921131456,-3.631509837003878
593.0000000000077,64.68908844854376,0.53376639535955,-3.6315092222758323
594.0000000000077,64.78842813801278,0.5339852689848823,-3.631519574350504
595.0000000000077,64.88760315521986,0.5329558050894512,-3.631519929002038
596.0000000000077,64.98808943384743,0.5330539197129232,-3.6315211909168146
597.0000000000077,65.08799457292045,0.5353014965884847,-3.632840041305249
598.0000000000077,65.1874297766362,0.5308221113027813,-3.6328400210000535
599.0000000000077,65.28705999548744,0.5313662181152576,-3.6328400210018543
600.0000000000078,65.38704994843037,0.52912812325813,-3.6328408806149977
601.0000000000078,65.48665483307724,0.5290343006444008,-3.6348001902954987
602.0000000000078,65.58678568968102,0.5276171909861571,-3.6354701800704663
603.0000000000078,65.68739511933525,0.5296490585609068,-3.635431545247166
604.0000000000078,65.78673066879853,0.5320631805104554,-3.6367898683977544
605.0000000000078,65.88589138532743,0.532272812818986,-3.6373646945540314
606.0000000000078,65.9860791041679,0.5353106214072462,-3.6381099690954843
607.000000000008,66.08663474469257,0.5332186702706593,-3.6387588577762684
608.000000000008,66.1858313826782,0.534560661243458,-3.6377466513912307
609.000000000008,66.28458367031278,0.5374604885001736,-3.6381130875907135
610.000000000008,66.38567097423847,0.5382129463980672,-3.639442332898816
611.000000000008,66.4865059059405,0.5427924424080722,-3.6381028826076918
612.000000000008,66.5859198286822,0.5414350593819328,-3.63942010326628
613.000000000008,66.68543489641092,0.5474677691741914,-3.6397556622073104
614.000000000008,66.78632691512608,0.5494072297417336,-3.639750013459565
615.000000000008,66.88545982160228,0.5486768271129316,-3.639419684852842
616.0000000000081,66.98552197878355,0.5530954351528895,-3.640089007735941
617.0000000000081,67.08592778543911,0.5557370090007759,-3.6407399000231893
618.0000000000081,67.18601788538271,0.5587187497972279,-3.6407389375873778
619.0000000000081,67.28607494253083,0.5613033452982867,-3.642059907984647
620.0000000000081,67.38502566257368,0.5625418296600038,-3.642059996346699
621.0000000000081,67.4859820130325,0.5633168873693293,-3.642615313696764
622.0000000000081,67.58602264016857,0.5660512049414652,-3.643421730860815
623.0000000000082,67.685730695811,0.5708463065879804,-3.6446878521969466
624.0000000000082,67.78610280540077,0.5718598981353735,-3.6446901798876183
625.0000000000082,67.88556749957365,0.5748234532230057,-3.645996337251799
626.0000000000082,67.98643663264318,0.5765148250974665,-3.6450198563695193
627.0000000000082,68.08591528084946,0.5789090778113732,-3.645020881345406
628.0000000000082,68.18415693534483,0.5816417220833303,-3.6462747828565827
629.0000000000082,68.2865817253881,0.586591647857264,-3.646011683928566
630.0000000000082,68.3850925884113,0.5899545598196863,-3.6473200637220655
631.0000000000082,68.48700451380925,0.5951042549725643,-3.648625224020897
632.0000000000083,68.58670852135016,0.6008702044365248,-3.6486433780182557
633.0000000000083,68.68716830013776,0.6017113902302756,-3.6473270452982876
634.0000000000083,68.78677394518918,0.6069766572997461,-3.648649658015823
635.0000000000083,68.88665875714997,0.6105210402731668,-3.649971744778626
636.0000000000083,68.98802098786224,0.6164379501691202,-3.6512799630290016
637.0000000000083,69.08676633250116,0.6211392995370322,-3.6512799388595423
638.0000000000083,69.18729643891662,0.6283636999212898,-3.653249510952021
639.0000000000084,69.2876960061171,0.6348296639887079,-3.653252531351526
640.0000000000084,69.38608274790577,0.6416001358367807,-3.6545702443103574
641.0000000000084,69.48722091698411,0.6472280711170209,-3.6545635876567975
642.0000000000084,69.58709584781747,0.6548901619748582,-3.6546801525416805
643.0000000000084,69.68724146881318,0.6578706770404151,-3.655890115430099
644.0000000000084,69.78784697936673,0.6659271601798733,-3.6572471640285587
645.0000000000084,69.8883167427257,0.6734039538090386,-3.657736195825379
646.0000000000084,69.98827669297567,0.6797008075993383,-3.658530074884887