File: 01_Data/Nylon_Carpet_High_Pile/STA/N2/30K_min/Nylon_Carpet_High_Pile_STA_N2_30KData_220309_R2.csv
##Temp./Â°C,Time/min,DSC/(mW/mg),Mass loss/mg
49.0,10.345735380937846,0.015565334815527576,0.002602372127405772
50.20000000000002,10.671696050611832,0.09153245678246624,0.0010397037391518538
51.400000000000034,10.815584988644046,0.14694776867429338,0.0012590728868007162
52.60000000000005,10.92332690404253,0.19724857474930735,0.0011996772897147068
53.80000000000007,11.013518095706731,0.24073141374315077,0.0006737911042677958
55.000000000000085,11.093685250307548,0.2849735137646573,0.0006947932146288416
56.2000000000001,11.16660611298582,0.32142744627778036,0.0019889662467185154
57.40000000000012,11.232656672944394,0.3558220130503765,0.0008971254918530569
58.600000000000136,11.29599097080624,0.3886618275951868,0.0010197931022872808
59.80000000000015,11.355738778857033,0.42095744320583334,0.002054169802061079
61.00000000000017,11.412229798882658,0.44740584754963897,0.0007249236669322201
62.20000000000019,11.467308662451114,0.47585724456427836,0.0018627129591464175
63.400000000000205,11.52012449587071,0.5012035856577892,0.0014759652504747756
64.60000000000022,11.572302570248633,0.5237660292600432,0.001959592827280421
65.80000000000024,11.622743018116322,0.5486136753474832,0.0022490320070520653
67.00000000000026,11.672147519769371,0.5705844488721644,0.0020494152110805963
68.20000000000027,11.720744695909271,0.5898422778754527,0.00246556071548909
69.40000000000029,11.76850220102578,0.6105990991346468,0.0034191791866304833
70.6000000000003,11.815322085071928,0.6299912464162633,0.0023044342752824853
71.80000000000032,11.861496845024831,0.6476186389367798,0.001360335921277489
73.00000000000034,11.907822902681643,0.668147890371003,0.002034170568440352
74.20000000000036,11.953149800023528,0.6835144467552081,0.0008056813082806258
75.40000000000038,11.997542926186373,0.6993921202641606,0.0002573188825096828
76.60000000000039,12.042563024021888,0.714891824735,0.0011829254379152054
77.80000000000041,12.08623990355883,0.7280002045584107,-0.0003479770732277565
79.00000000000043,12.130869536512561,0.7416213912442265,0.0006092694810617694
80.20000000000044,12.173845977062003,0.753283523288937,0.0013035045900027242
81.40000000000046,12.217276923222459,0.7669364563604897,0.001412192497022069
82.60000000000048,12.260613837732617,0.7797628844709842,0.0016418678920357976
83.8000000000005,12.303364843987584,0.7907044295782921,0.0015022556417414457
85.00000000000051,12.345471741295192,0.8039402559308897,0.0015293317693667596
86.20000000000053,12.387754161091959,0.8139594588892028,0.0011995240740247937
87.40000000000055,12.429725355468511,0.8255199178572091,0.00033411680066475213
88.60000000000056,12.471187443398609,0.8339470816367243,0.0008757256578659778
89.80000000000058,12.512750550078398,0.8444889571811177,0.0012910377372605808
91.0000000000006,12.554279400478142,0.8541793244743189,1.603588428311653e-05
92.20000000000061,12.595874476742683,0.8624491744921441,-0.00026342645370158735
93.40000000000063,12.637383537306164,0.8750664651637597,-1.917448032795477e-06
94.60000000000065,12.678354801707439,0.8846755534037731,-0.00012093815864133717
95.80000000000067,12.719474943571065,0.8940164293735477,-8.631529925562376e-05
97.00000000000068,12.760705162460841,0.9012627275681226,-0.00010983357093374835
98.2000000000007,12.801297364127702,0.9077555119925063,-0.00011986003048924943
99.40000000000072,12.84202845378432,0.9148372650451888,0.00040243314758914295
100.60000000000073,12.882975514794293,0.9210483898339844,5.653590181742274e-05
101.80000000000075,12.923479404190111,0.9244163291288459,-0.00011512955888548504
103.00000000000077,12.96407190797738,0.9269530873790763,-0.0014798786165255429
104.20000000000078,13.004863117373962,0.9286152035972455,-0.001435269495021707
105.4000000000008,13.045209301650942,0.9310068912022701,-0.0007370989305730546
106.60000000000082,13.085339061218896,0.9305544087008243,-0.0014296707543204334
107.80000000000084,13.125915529122677,0.9320671825011213,-0.0014299612655892524
109.00000000000085,13.166638315659025,0.9318715785845824,-0.001962616254560956
110.20000000000087,13.207008318125848,0.9333403928503561,-0.002750024604255774
111.40000000000089,13.24670350738003,0.9311564484054877,-0.0027499099190806398
112.6000000000009,13.286960689460487,0.9325580933916319,-0.0017557168701305415
113.80000000000092,13.327437995405086,0.9352386132265281,-0.0030728952099541296
115.00000000000094,13.367440688822317,0.9362308013002582,-0.0030698939179218954
116.20000000000095,13.407932311006892,0.9390574918031348,-0.0027259997344795117
117.40000000000097,13.447652339856758,0.9403710742001141,-0.0040597961487467416
118.60000000000099,13.487914185437699,0.9427747438939239,-0.0037028847387090558
119.800000000001,13.527912838761093,0.9442294818300282,-0.0030650175118895895
121.00000000000102,13.567329580349016,0.9491611172304183,-0.0040587982151700785
122.20000000000104,13.607441086617621,0.948694596744216,-0.004060014084928731
123.40000000000106,13.647240251142534,0.9495135454601297,-0.004068416698185029
124.60000000000107,13.686869500020796,0.9528043807530483,-0.0034021702907343077
125.80000000000109,13.72614777553099,0.9535667014125554,-0.004089750425187777
127.00000000000111,13.766060939956771,0.9553335525876082,-0.004389507057253272
128.20000000000113,13.805185669841762,0.9597794738982791,-0.0044061018714107725
129.40000000000114,13.844835737456606,0.9620837271390937,-0.005387339107196354
130.60000000000116,13.884002759933315,0.9648863841173045,-0.005709706737258902
131.80000000000118,13.923033441799372,0.9702651075020662,-0.005710139941617065
133.0000000000012,13.962327403252042,0.9693671541517092,-0.005710149499100314
134.2000000000012,14.001517886404196,0.9748370501017228,-0.005724721489713591
135.40000000000123,14.040159589451106,0.9803401177756612,-0.005379896327903033
136.60000000000124,14.079229144367018,0.9836234451095296,-0.005379822452927119
137.80000000000126,14.118007099361314,0.9890194385289213,-0.005692537985083845
139.00000000000128,14.15729662120726,0.991504975677415,-0.005370079140270434
140.2000000000013,14.195735120123064,0.9978884460043889,-0.005369824440311977
141.4000000000013,14.234331524898058,1.00299494047955,-0.0053512336571373
142.60000000000133,14.272887771930483,1.0095187310055032,-0.0066910564011415374
143.80000000000135,14.311296633977744,1.0152137283991178,-0.00668983029124437
145.00000000000136,14.349519174356535,1.0228890087131632,-0.0066898189272399655
146.20000000000138,14.387780933188662,1.0298156215125027,-0.006677882710677707
147.4000000000014,14.426435042732722,1.038598269511655,-0.007351824460648082
148.60000000000142,14.464562058322837,1.0483968973529625,-0.007410473718337585
149.80000000000143,14.50309691161906,1.061082956083435,-0.008678709842440124
151.00000000000145,14.541055988792055,1.0743753471783197,-0.008669887226304684
152.20000000000147,14.579364956571677,1.085913659708511,-0.008669875009348793
153.40000000000148,14.617539736037285,1.1077279788999048,-0.008669897785042568
154.6000000000015,14.655279558595218,1.1246573714274832,-0.008708121316170825
155.80000000000152,14.693675619959452,1.1447687950625234,-0.007680098676678959
157.00000000000153,14.731918021916336,1.1667806598935544,-0.007680002047239842
158.20000000000155,14.769853578083467,1.1932434159609584,-0.007671248410484388
159.40000000000157,14.807775196666837,1.218059599243045,-0.007350697124755445
160.6000000000016,14.845485661837746,1.2440006279695126,-0.007350179680601254
161.8000000000016,14.883135943379212,1.264420997260959,-0.007350174353533134
163.00000000000162,14.921365341669645,1.2777576422558443,-0.007331244549879656
164.20000000000164,14.95913615591914,1.2872274131016832,-0.008660870255520425
165.40000000000165,14.996895081183528,1.2826787992631252,-0.008632983332060196
166.60000000000167,15.034549560137856,1.2689143835002077,-0.009319473278418311
167.8000000000017,15.072502070224404,1.2465438333172623,-0.009319830150342767
169.0000000000017,15.110430541438465,1.2221855225441831,-0.009319830000186435
170.20000000000172,15.147894816911599,1.2003786053077616,-0.009319829999998142
171.40000000000174,15.185753127745285,1.1851108949972602,-0.009319829999999474
172.60000000000176,15.223023537926304,1.1692716920791844,-0.009319834482356626
173.80000000000177,15.260765954159682,1.157181821907534,-0.009325981868592681
175.0000000000018,15.298413112947967,1.1510474500699035,-0.010637133115437347
176.2000000000018,15.335639917135648,1.146985735502775,-0.01063982491545623
177.40000000000182,15.372410967520466,1.1443239760631854,-0.010639828904565718
178.60000000000184,15.410367937939506,1.1424016806344135,-0.010635185733163244
179.80000000000186,15.447489519347762,1.140486562603474,-0.011312102012968506
181.00000000000188,15.484825816153279,1.1417009623311083,-0.009980498679988514
182.2000000000019,15.521608909071526,1.1453722966326056,-0.009979876861989645
183.4000000000019,15.559053946439345,1.1478550828491056,-0.009979874994909821
184.60000000000193,15.596090432015794,1.1509868226435325,-0.009979923970294458
185.80000000000194,15.633485008070533,1.154213367283591,-0.010017863718259967
187.00000000000196,15.67033029971748,1.160402141463239,-0.010309972637661424
188.20000000000198,15.707278390572721,1.1654232605643788,-0.010309875060643847
189.400000000002,15.743922558060374,1.1689039005134099,-0.01030987497342073
190.600000000002,15.781127268524768,1.1744214275578322,-0.010309851139457038
191.80000000000203,15.818071454029576,1.1838546460299804,-0.010484700139907766
193.00000000000205,15.854994707144224,1.1878557519606971,-0.011300429000944412
194.20000000000206,15.891707243747858,1.198048635309038,-0.011300139774649054
195.40000000000208,15.928494872503908,1.2081421172052773,-0.01130013983751521
196.6000000000021,15.965739927645801,1.2152110682587038,-0.011300286952031335
197.80000000000211,16.00201924192246,1.224272909426125,-0.010390386981439015
199.00000000000213,16.039295976484468,1.2356850161466235,-0.00998000571047486
200.20000000000215,16.07578399002569,1.2484257958589815,-0.01067621271130692
201.40000000000217,16.112617401249725,1.2610147373731802,-0.011243470653469867
202.60000000000218,16.149316569922732,1.2733549623984763,-0.012284480366866468
203.8000000000022,16.186136186605346,1.2877919243515632,-0.010972007276829121
205.00000000000222,16.223248362987828,1.308829124445515,-0.010970133185017605
206.20000000000223,16.25984517533289,1.3280384082046963,-0.01097013999872587
207.40000000000225,16.296413454419245,1.351336809274641,-0.010970140350318403
208.60000000000227,16.333092374226613,1.3788837410094508,-0.010970169099616456
209.80000000000229,16.369596092080133,1.4159912521996023,-0.012036938467059333
211.0000000000023,16.40560940466272,1.4603145773286568,-0.012276479481104108
212.20000000000232,16.442951670792745,1.5281679528085574,-0.010745070765387332
213.40000000000234,16.47965195630555,1.6233007462783804,-0.010743975465028033
214.60000000000235,16.516562334216044,1.751477556000855,-0.010947728346122787
215.80000000000237,16.553072822783225,1.902240711365014,-0.012275820971151319
217.0000000000024,16.589693172944322,2.0729215553659555,-0.012279938934516732
218.2000000000024,16.626729320159836,2.2528416237227424,-0.01227996196964476
219.40000000000242,16.663543213115425,2.4187723695609233,-0.012291432775770605
220.60000000000244,16.699632718774865,2.5497243157052285,-0.014571074630903347
221.80000000000246,16.737171010830455,2.609661514942177,-0.014920215168563455
223.00000000000247,16.774359272852806,2.56556188180721,-0.014920049259520507
224.2000000000025,16.810656424368602,2.4181183586179733,-0.014921855128820383
225.4000000000025,16.84747098948433,2.2273346226123003,-0.01358973091944593
226.60000000000252,16.883942526104043,2.049884995633998,-0.013599973728076531
227.80000000000254,16.9211058807706,1.9012175155121191,-0.013594740534979
229.00000000000256,16.957309996467767,1.7800313768477527,-0.014915583002004684
230.20000000000258,16.993916043365665,1.684103737650245,-0.014920049815359437
231.4000000000026,17.030152264503258,1.6117753880659489,-0.014916732765776874
232.6000000000026,17.066757332021425,1.5526665562028996,-0.01623888824558728
233.80000000000263,17.102846078895826,1.5091324532504407,-0.0162401617397947
235.00000000000264,17.13866744152358,1.4724352277018058,-0.01623999569140988
236.20000000000266,17.175144082878845,1.4437150580472426,-0.016569064808781064
237.40000000000268,17.211262047559526,1.422536539380353,-0.01690211466197855
238.6000000000027,17.2476941210215,1.4044335164685697,-0.015830841359615988
239.8000000000027,17.284036609173036,1.3950482208061663,-0.01557669076032786
241.00000000000273,17.320091768651917,1.3850589036238665,-0.017118715156906106
242.20000000000275,17.356401392204496,1.3773903841275081,-0.018446654211089264
243.40000000000276,17.392727621330536,1.37108106638416,-0.018822304333707685
244.60000000000278,17.429114468007757,1.36647113889864,-0.018430938867774582
245.8000000000028,17.465270373237107,1.3633097254904212,-0.01955143994371511
247.0000000000028,17.501360743514486,1.3633424919582544,-0.019750544543077897
248.20000000000283,17.537573764552363,1.3618124342124152,-0.018716400674299027
249.40000000000285,17.57393409339166,1.3617308407084874,-0.018760184530810964
250.60000000000286,17.609933998506264,1.363371926174788,-0.01876019502937032
251.80000000000288,17.645962920394464,1.3616173593031076,-0.01876019499982995
253.0000000000029,17.682189015821532,1.3652634035641509,-0.01876019535944451
254.20000000000292,17.718416217381396,1.3630664760510953,-0.018760086181148328
255.40000000000293,17.754628968399214,1.3652369194538956,-0.020731371200200854
256.600000000003,17.79090003604911,1.3662345195348324,-0.020729868592776146
257.80000000000297,17.826882963361744,1.367949725692723,-0.020727102921889173
259.00000000000296,17.86302881626781,1.3683226856858068,-0.022043479703230506
260.200000000003,17.899342737880673,1.3741320781049795,-0.022040015155270876
261.40000000000305,17.93519540031874,1.3757248405908535,-0.02136282163398384
262.60000000000304,17.971524878273375,1.3741751186721916,-0.02137026649629048
263.800000000003,18.00756499230518,1.3797024097195287,-0.022711032159598243
265.00000000000307,18.04401033425328,1.3787526635519194,-0.022710193555967262
266.2000000000031,18.079999697969196,1.3813016411365706,-0.0227101950000006
267.4000000000031,18.116239488997156,1.3820063193512535,-0.022710195019768786
268.6000000000031,18.152274946457254,1.3842025959955522,-0.022710182891632957
269.80000000000314,18.18867459867751,1.3864955716652183,-0.022684348465094484
271.0000000000032,18.22467212683956,1.3922099883629824,-0.024032309912828342
272.2000000000032,18.261128389955257,1.3918747021612605,-0.024030024636449543
273.40000000000316,18.297267160689767,1.3944126466380053,-0.024746773966600077
274.6000000000032,18.3333869684552,1.3951085952027817,-0.02534009075548349
275.80000000000325,18.369919861106176,1.3996550553542366,-0.026545975995058146
277.00000000000324,18.4057758300202,1.3981585644193193,-0.026660219835252352
278.20000000000323,18.442154921281485,1.4018136725825436,-0.02666019503639694
279.4000000000033,18.47797886751857,1.4025239449285911,-0.026660194905792967
280.6000000000033,18.514343059374387,1.405387859196151,-0.02666011478883279
281.8000000000033,18.550909992818035,1.4059767120025977,-0.027027519165855995
283.0000000000033,18.586823628804005,1.4066564799937744,-0.027979919252868246
284.20000000000334,18.623368403978823,1.4078133961419084,-0.027979917490330575
285.4000000000034,18.659389789101162,1.4118782590787378,-0.027969557926696087
286.6000000000034,18.695631508817975,1.4094898775535023,-0.029402196819074522
287.80000000000337,18.731989896721522,1.41430205939854,-0.02939678751630792
289.0000000000034,18.76838518233825,1.4129101291000445,-0.030707427168824797
290.20000000000346,18.8047650074652,1.4159125769865106,-0.030720014789693995
291.40000000000344,18.84130595843804,1.4156560864088403,-0.030718440888274134
292.60000000000343,18.87742404301275,1.4175772948316148,-0.032068880349279016
293.8000000000035,18.91369506462165,1.4189400745422422,-0.03202983052991959
295.0000000000035,18.94968835321407,1.4181828072096248,-0.03202983039362062
296.2000000000035,18.986301575070826,1.4175744778028465,-0.032028561350434526
297.4000000000035,19.02257088534374,1.4203438206651384,-0.033014805478457365
298.60000000000355,19.058524761931235,1.423024664101999,-0.033018115417026817
299.8000000000036,19.095221736641474,1.4194131248968171,-0.03335195812729408
301.0000000000036,19.13136009336122,1.4214053448883055,-0.033350968683535154
302.20000000000357,19.167491793551065,1.4206455402365528,-0.03469806923633323
303.4000000000036,19.204194237860698,1.4212188500777025,-0.03466996440547154
304.60000000000366,19.240421368345213,1.4214945108228791,-0.03467126412353361
305.80000000000365,19.276839675350303,1.4205676260435136,-0.036178154986762134
307.00000000000364,19.313243362296543,1.4207003221733292,-0.03751835404019799
308.2000000000037,19.349481369199307,1.4229470177366195,-0.037503883900412927
309.40000000000373,19.385713358633247,1.4229160071267142,-0.03882824694572706
310.6000000000037,19.422521932942253,1.4269065946919883,-0.03883019240399532
311.8000000000037,19.458884059679658,1.424800123768069,-0.03879509971772199
313.00000000000375,19.495258639505728,1.4243108529479391,-0.040148878125832343
314.2000000000038,19.531626276674825,1.4242904169024615,-0.040150148384942685
315.4000000000038,19.568054371292682,1.42381353742186,-0.04124753820136151
316.6000000000038,19.60438469387943,1.4270701259286978,-0.04141227592571761
317.8000000000038,19.640953758257197,1.4313376770467716,-0.042779520722793674
319.00000000000387,19.67752176670801,1.4327731865735445,-0.04278015253088485
320.20000000000385,19.713607188800424,1.4351032845679381,-0.04278130639998734
321.40000000000384,19.750205778237234,1.4402082417269964,-0.04408867215704326
322.6000000000039,19.786761614919488,1.444192736507985,-0.044102220388623437
323.80000000000393,19.823119074510462,1.4461046089704217,-0.04666027357654823
325.0000000000039,19.85956524838574,1.4534001966338592,-0.047013578884000484
326.2000000000039,19.896171437291752,1.4590623880741684,-0.04682329112883066
327.40000000000396,19.933070382008978,1.4640042758138945,-0.04816542739920715
328.600000000004,19.969201514436147,1.4717351812731123,-0.04986381716002697
329.800000000004,20.005922353066875,1.4807599264235143,-0.051193937721838
331.000000000004,20.042691839157474,1.488325868071393,-0.051849517462196015
332.200000000004,20.078982913113077,1.498892664546191,-0.05329961086279322
333.40000000000407,20.115725237373958,1.5045191821201283,-0.054910947054866543
334.60000000000406,20.15238028641778,1.5146730518281808,-0.05635351396786925
335.80000000000405,20.188793692505698,1.5252575362317555,-0.05806123956283882
337.0000000000041,20.225168705601376,1.538246613539208,-0.06104452011258088
338.20000000000414,20.262216932762573,1.5459653573474696,-0.0631322821956557
339.4000000000041,20.298646978623125,1.5560234240191486,-0.06602209296358819
340.6000000000041,20.33523493200815,1.5719010208573092,-0.06762896495544313
341.80000000000416,20.371998537981394,1.5796734241167865,-0.07047464079637544
343.0000000000042,20.408829844754507,1.5948330206431058,-0.07353052501218116
344.2000000000042,20.445522364865187,1.6068371161579922,-0.07699893471527508
345.4000000000042,20.48197139514477,1.6183673612332397,-0.07897008402393046
346.60000000000423,20.518652462757316,1.6339842928130297,-0.0825927640469768
347.8000000000043,20.55544282499176,1.6504312173041362,-0.08683970228457882
349.00000000000426,20.59208993213638,1.6641644476094755,-0.0909442283442381
350.20000000000425,20.628806896931724,1.6773391231839867,-0.09343441946434439
351.4000000000043,20.665668501695922,1.6934283646709352,-0.0965629830455863
352.60000000000434,20.70245554940335,1.7106131638125084,-0.10046792254465764
353.80000000000433,20.73956716583127,1.7291950866203836,-0.10577813190891572
355.0000000000043,20.77620115145049,1.7453585440972472,-0.11058216027713774
356.20000000000437,20.812811370644642,1.7652271825064685,-0.11608762211755996
357.4000000000044,20.849503089799725,1.7858310436229206,-0.1202655318442063
358.6000000000044,20.886426770589143,1.8049806844299137,-0.12502529275219443
359.8000000000044,20.92329859152529,1.8268872542721648,-0.1304608711884696
361.00000000000443,20.96012891905121,1.848851627204844,-0.13669776174754622
362.2000000000045,20.997301170804196,1.8693310334061821,-0.14230494640232072
363.40000000000447,21.03406988039492,1.8941610264391984,-0.14754626563293316
364.60000000000446,21.07074315420199,1.9180052892606203,-0.15778019438874713
365.8000000000045,21.107068712998444,1.9431053190150984,-0.16604338906414773
367.00000000000455,21.144640455663232,1.9681135161652368,-0.1740764995115387
368.20000000000454,21.18171570796362,1.9935564656585485,-0.1820447641756462
369.4000000000045,21.21876357922354,2.0202042354970615,-0.19049708290525436
370.60000000000457,21.255692788440037,2.0484618825982066,-0.1994222527070555
371.8000000000046,21.291991064989716,2.077093950468838,-0.20792019764807312
373.0000000000046,21.329981304187392,2.1069433779605493,-0.21722367782558738
374.2000000000046,21.367069586361808,2.1372479300273755,-0.22672777934825472
375.40000000000464,21.404117255400962,2.164390682254011,-0.23945885945331202
376.6000000000047,21.44123522976399,2.1944194346389256,-0.2504648381270602
377.8000000000047,21.47825060769103,2.223256380957317,-0.26169677094723953
379.00000000000466,21.515330903649293,2.2542087847158125,-0.27150566656206987
380.2000000000047,21.552433409496945,2.2852790982706574,-0.28274875219937323
381.40000000000475,21.58975622170326,2.319201806311092,-0.2957493377697813
382.60000000000474,21.62670155135993,2.3519787953590363,-0.30889076200433596
383.80000000000473,21.66403889604974,2.3851737154278374,-0.3220626557023114
385.0000000000048,21.701215600816713,2.418489024451283,-0.33508557430524233
386.2000000000048,21.7387397678341,2.4516529307897996,-0.349054418839426
387.4000000000048,21.775748909039,2.489869355399859,-0.3654419755272871
388.6000000000048,21.813233564640175,2.528140407503175,-0.3814840739530543
389.80000000000484,21.850434677836134,2.5658913344193435,-0.3980272055323919
391.0000000000049,21.887955855532297,2.607275474547873,-0.41475713491642896
392.2000000000049,21.925177197516614,2.6485040771825723,-0.4316751637101435
393.40000000000487,21.962352668989812,2.6897056094365164,-0.45040035981335613
394.6000000000049,21.999999689598788,2.7399127301969886,-0.46911990612774446
395.80000000000496,22.037291736910888,2.784897314980504,-0.48842965717098696
397.00000000000495,22.074602252963402,2.82796323670637,-0.5086638680192634
398.20000000000493,22.111823446441647,2.8789748262135513,-0.5294934588260309
399.400000000005,22.149392476789306,2.9311071121698826,-0.5531781955596018
400.600000000005,22.187103285146183,2.9803791603086296,-0.5768637706923632
401.800000000005,22.22461657110287,3.0361290106579375,-0.599944718063635
403.000000000005,22.261903424135095,3.085548334283561,-0.6231428345995891
404.20000000000505,22.299453994952405,3.1417250181863974,-0.6484438301335604
405.4000000000051,22.3367515457002,3.196023663071896,-0.676310016956617
406.6000000000051,22.37419496100008,3.249073111662995,-0.7050638532460649
407.80000000000507,22.412000778734505,3.29856351568459,-0.733249693962696
409.0000000000051,22.449524924528202,3.350296225912299,-0.7615390891649376
410.20000000000516,22.487196459441996,3.3991652939902544,-0.7931959226370435
411.40000000000515,22.524476192362048,3.446529961537899,-0.8262950429922737
412.60000000000514,22.562153321667633,3.494776579394755,-0.8599071993722598
413.8000000000052,22.59953630726976,3.536933981052491,-0.8934679702728192
415.00000000000523,22.637041616101335,3.5782052237498467,-0.9280499575749999
416.2000000000052,22.674784402382876,3.615859315640483,-0.963901731240731
417.4000000000052,22.712423342383865,3.6449058038275286,-1.0017473046180463
418.60000000000525,22.750014993240104,3.675767135548929,-1.041493070302915
419.8000000000053,22.787484348649855,3.695233569923233,-1.0823672771236108
421.0000000000053,22.825263697909108,3.7110145765605065,-1.1236590183654256
422.2000000000053,22.862782593608184,3.7165525251128333,-1.1633439725535943
423.4000000000053,22.900193350938103,3.7144002320059717,-1.2036966806658929
424.60000000000537,22.938108285582622,3.7067217002853354,-1.2469244821887822
425.80000000000535,22.97571099269211,3.684617418435298,-1.2920577973965521
427.00000000000534,23.013425258833404,3.6474056548253935,-1.3359767370485822
428.2000000000054,23.051129037829753,3.603234665555937,-1.3786666065765614
429.40000000000543,23.08851378229176,3.545047531441776,-1.4212795487970897
430.6000000000054,23.12620460254932,3.4695192630187295,-1.4644714127277982
431.8000000000054,23.163619160224727,3.3807567360934505,-1.5092548903157543
433.00000000000546,23.201426655212604,3.270193011628179,-1.5527526095498096
434.2000000000055,23.239050620746955,3.1497974950040932,-1.59280843207776
435.4000000000055,23.27640186171862,3.01057906587255,-1.6305315061835057
436.6000000000055,23.31436669411521,2.8575143971456827,-1.6667494746153784
437.8000000000055,23.351681744993986,2.6947235278895807,-1.7007524764653787
439.00000000000557,23.3892783642877,2.524817606544909,-1.7349305888889108
440.20000000000556,23.42663983601649,2.3491657034832008,-1.7650473382148233
441.40000000000555,23.464430957715045,2.1785794425596423,-1.7913215761085515
442.6000000000056,23.501430519911143,2.0176170651224528,-1.8151878814630216
443.80000000000564,23.539062048737264,1.8661107924575722,-1.836307648590226
445.0000000000056,23.5764613428441,1.7307438714863883,-1.8540873629058496
446.2000000000056,23.61391874689243,1.615110208796264,-1.8710243330533105
447.40000000000566,23.651588690535384,1.5154384984694735,-1.886793272309812
448.6000000000057,23.689069071784864,1.4312548649066943,-1.9004114733892497
449.8000000000057,23.726516057600456,1.3617471680123467,-1.9123313391621357
451.0000000000057,23.764158359576065,1.3052062451835578,-1.9253357696955264
452.20000000000573,23.802008378695312,1.2570092685362848,-1.9368672512779375
453.4000000000058,23.839543685194798,1.218550291968663,-1.9476700546266175
454.60000000000576,23.87682287623432,1.189764221813915,-1.9571044906114372
455.80000000000575,23.914896944325655,1.1646185657441952,-1.9666463536613477
457.0000000000058,23.952543062442793,1.1468181465220073,-1.9774709716594223
458.20000000000584,23.990473576528593,1.129228602980688,-1.9866298391228965
459.40000000000583,24.02816453606888,1.114640386944105,-1.9959226521728428
460.6000000000058,24.06595360613752,1.1064576601992673,-2.005409957442709
461.80000000000587,24.10374065565253,1.1006292855943018,-2.013976527209148
463.0000000000059,24.141309962727938,1.0936762958975315,-2.022822276884389
464.2000000000059,24.179181858193175,1.0895692758056523,-2.031984104321482
465.4000000000059,24.217191125684703,1.0863128573977776,-2.041026435049494
466.60000000000593,24.25505937347633,1.0846021673073276,-2.050025553494004
467.800000000006,24.293140372224798,1.0809129496520857,-2.060081584358627
469.00000000000597,24.331012031270554,1.078019238950378,-2.0684940957048576
470.20000000000596,24.368951548012834,1.0775383497203863,-2.076739254049934
471.400000000006,24.407031381276195,1.0767252792748012,-2.0859909106588397
472.60000000000605,24.444887527659777,1.075011856400546,-2.0954166799474327
473.80000000000604,24.483289713747432,1.0759533207169303,-2.105965735147114
475.000000000006,24.521194726620987,1.0766573778498436,-2.115214938470743
476.20000000000607,24.55903058464739,1.0748544598725378,-2.1244486793086397
477.4000000000061,24.597340062390064,1.0752756826336858,-2.1336946651051782
478.6000000000061,24.635457391135564,1.072890076891322,-2.1434482282019838
479.8000000000061,24.67365529436153,1.0711864159608961,-2.153554756066077
481.00000000000614,24.71159579041579,1.0714462614017983,-2.162994340853227
482.2000000000062,24.749892731384982,1.068625840420996,-2.1731608233237782
483.4000000000062,24.788045000987328,1.0686484379592558,-2.183044122044226
484.60000000000616,24.82632218700402,1.064344847218487,-2.1935124451466534
485.8000000000062,24.864359048052822,1.060114366147813,-2.202589522872278
487.00000000000625,24.902723348201622,1.0585308583594524,-2.211755775571763
488.20000000000624,24.940838804887473,1.052747004944405,-2.226479725964971
489.40000000000623,24.978942152603743,1.0438815389690865,-2.2377435462962496
490.6000000000063,25.01717923877952,1.0381691462849738,-2.2475351967288386
491.8000000000063,25.055655759999436,1.0306548996323632,-2.2580463802162147
493.0000000000063,25.093986920685065,1.0201386004749569,-2.2676151564577927
494.2000000000063,25.132191225722572,1.0073471896058228,-2.2778251678333405
495.40000000000634,25.170549114223398,0.9930789347860263,-2.2882130625675927
496.6000000000064,25.20892345843995,0.974130738279366,-2.2992301375937108
497.8000000000064,25.247154936022923,0.9542111533558495,-2.3093372459279173
499.00000000000637,25.285917663089894,0.9302879078547575,-2.3192102008761823
500.2000000000064,25.323877278164396,0.8977922793701987,-2.328188914906383
501.40000000000646,25.362393939310948,0.8605275857935306,-2.3372223058396058
502.60000000000645,25.400595933715618,0.8214996232881135,-2.3452850067407525
503.80000000000643,25.43914695612163,0.7776013913434539,-2.3513980189235406
505.0000000000065,25.477408457763058,0.7342112054395453,-2.3576933543852077
506.2000000000065,25.51574145950646,0.6876107808906569,-2.3637634320996455
507.4000000000065,25.553888451139052,0.6464777191835624,-2.368682967116004
508.6000000000065,25.592461595840515,0.6062216696632019,-2.372049244222813
509.80000000000655,25.631060493456697,0.571031908420141,-2.3753315908308688
511.0000000000066,25.66845573039546,0.5399517216355301,-2.378168959943145
512.2000000000066,25.707786651676734,0.513598702383576,-2.3791995428783634
513.4000000000066,25.7460325592567,0.4946204832254113,-2.3800864853264097
514.6000000000066,25.784415281894734,0.4765599956162192,-2.3814008924586227
515.8000000000067,25.822995690399825,0.4661261375587582,-2.3828593331402077
517.0000000000066,25.861497133488054,0.4564633360957986,-2.383919858615768
518.2000000000066,25.90043319015746,0.445392403163261,-2.3841399140893524
519.4000000000067,25.93875555448303,0.43738087806547354,-2.384140011389641
520.6000000000067,25.9772272983428,0.4322089001079963,-2.38344348683099
521.8000000000068,26.01593730644417,0.429591513989527,-2.382176617037235
523.0000000000067,26.054320379566544,0.42805020350064993,-2.382170078186211
524.2000000000068,26.0931717982915,0.4216137201443051,-2.382476993425783
525.4000000000068,26.131422646651462,0.42141612947715656,-2.383478372126644
526.6000000000067,26.17018780526411,0.4184407507066552,-2.38481908287232
527.8000000000068,26.208701436432836,0.42135574163452727,-2.3848000483579437
529.0000000000068,26.24769888214494,0.4185794535376055,-2.384864036070265
530.2000000000069,26.286087314144062,0.42311039911614334,-2.3861198077549384
531.4000000000069,26.324223349765184,0.431924579931662,-2.3862652268623137
532.6000000000068,26.363574283025564,0.4409421560275173,-2.386087492004052
533.8000000000069,26.40202037813903,0.4436384350997373,-2.3855792121012698
535.0000000000069,26.440834103203176,0.44958238056690947,-2.385129893115714
536.2000000000069,26.479645354932437,0.45257834477045256,-2.3851298399891574
537.4000000000069,26.517965711827042,0.45784223004058844,-2.3851298399999736
538.600000000007,26.557037986102564,0.46325019483782115,-2.3851298400000003
539.800000000007,26.595383647885356,0.46301565204559636,-2.385129840000089
541.000000000007,26.634221961321682,0.4627765949051539,-2.3851298400941863
542.200000000007,26.67306243491845,0.4544212863969741,-2.3851297814398613
543.400000000007,26.71187328450207,0.44775034034519345,-2.386350097206624
544.6000000000071,26.75080488072863,0.4423489329047201,-2.3864400040136804
545.800000000007,26.78978728383695,0.4381236583238992,-2.3864438116270916
547.000000000007,26.828472390554346,0.4339418652203353,-2.3890875787242485
548.2000000000071,26.867511505313832,0.4285887553301093,-2.3890801490357387
549.4000000000071,26.90660736416898,0.42623073340846185,-2.3890801446914813
550.6000000000072,26.944998446666506,0.4243271693266586,-2.389079789956086
551.8000000000071,26.98443202882775,0.4194826864101189,-2.3877489627637267
553.0000000000072,27.02313948468506,0.4205460619542123,-2.38776015989511
554.2000000000072,27.06194052859292,0.41768676357058476,-2.3877601450123978
555.4000000000071,27.10099279926347,0.41123002162520006,-2.3877601449998886
556.6000000000072,27.140000654167206,0.4075707734150549,-2.387760144999829
557.8000000000072,27.179134888234252,0.4065793910495785,-2.3877606042258828
559.0000000000073,27.21785959040085,0.3999740446073121,-2.3893481470336755
560.2000000000073,27.25668880962488,0.3974462093630744,-2.390596945157455
561.4000000000073,27.296027337832808,0.39030818613098783,-2.3906100645556227
562.6000000000073,27.33497412751664,0.3882154475632782,-2.39061006999833
563.8000000000073,27.373922798033668,0.3877649949008457,-2.3906100699999993
565.0000000000073,27.413361004160762,0.3838432429279195,-2.3906100699999993
566.2000000000073,27.452446756250396,0.37826410349234996,-2.3906100702321016
567.4000000000074,27.49120617142254,0.37451584175973074,-2.390611142049724
568.6000000000074,27.530445001003677,0.37145576252562096,-2.3919854049951805
569.8000000000075,27.56965736555234,0.3717543859678072,-2.391270231854759
571.0000000000074,27.608589367083532,0.3734338679886453,-2.391270160133073
572.2000000000074,27.64765703698198,0.3713658385069367,-2.391270159932195
573.4000000000075,27.68697116210248,0.3691652176817022,-2.39127010903607
574.6000000000074,27.72611571060315,0.36886053016125486,-2.3909346798921343
575.8000000000075,27.764311006914692,0.36785412103490334,-2.390945954882546
577.0000000000075,27.804676819377384,0.3678348835570906,-2.391601752567772
578.2000000000075,27.84382711048621,0.36402462879648234,-2.3915958373055433
579.4000000000076,27.882991656407228,0.3636255627200544,-2.3928960998578392
580.6000000000075,27.922306411537217,0.36309036647682524,-2.3929108415665112
581.8000000000076,27.96169656426538,0.3665127872377141,-2.3942273319475964
583.0000000000076,28.000630786655368,0.3655397721664657,-2.3967688528457165
584.2000000000075,28.039676247084827,0.36588595519438427,-2.39641179469942
585.4000000000076,28.07908598365314,0.36431684881702897,-2.3940244205288472
586.6000000000076,28.118403949556274,0.3660486405688468,-2.393899881686835
587.8000000000077,28.1574681878525,0.36827816512637357,-2.3938995391774
589.0000000000077,28.1963426250127,0.3692233428667502,-2.3932219205756247
590.2000000000077,28.235875039526203,0.36893191028331196,-2.393238930626517
591.4000000000077,28.27532461370467,0.37161630006167057,-2.3945787806024743
592.6000000000078,28.314218394946895,0.3740159741848528,-2.394559944643539
593.8000000000077,28.35355083604259,0.373507037652385,-2.3945599400005104
595.0000000000077,28.393038361851254,0.37896144815449917,-2.3945599399923587
596.2000000000078,28.43225777765244,0.38156903981834445,-2.394559914648741
597.4000000000078,28.471433934037805,0.38218953935499256,-2.3944912245395225
598.6000000000079,28.510802706382197,0.38217245545108103,-2.3968503232406357
599.8000000000078,28.550107930526742,0.38564096359248023,-2.396860150151921
601.0000000000078,28.589231066821934,0.392126021295933,-2.3968600543231195
602.2000000000079,28.628824122495384,0.39169692023641245,-2.3972130758212478
603.4000000000078,28.66805372639939,0.3915172995499847,-2.398728660810524
604.6000000000079,28.70766985980269,0.3905705343737844,-2.3985043849280085
605.8000000000079,28.74653891054849,0.39477792286160085,-2.396968777999838
607.000000000008,28.786048977237044,0.3962702059615095,-2.3956590256802435
608.200000000008,28.824628623844184,0.3986294968621418,-2.3968921122310594
609.4000000000079,28.864860054935576,0.3981387267494203,-2.3983000382577098
610.600000000008,28.904485861454976,0.40242554669180164,-2.3982898399032546
611.800000000008,28.94378920956281,0.40657347692971735,-2.3989905850571294
613.000000000008,28.983090966500132,0.40693105750062974,-2.3996002565490593
614.200000000008,29.022260855517963,0.4109327773254372,-2.3996001546901518
615.400000000008,29.061720153415436,0.4149976700819631,-2.399599428259269
616.6000000000081,29.101452516583624,0.41765998867794996,-2.4009390615020285
617.8000000000081,29.141006597503544,0.41792304986803397,-2.4009198251701265
619.0000000000081,29.180100845780213,0.4213755689123375,-2.40125857003635
620.2000000000081,29.219402669188934,0.42447859468649596,-2.402230004905397
621.4000000000082,29.25892481214525,0.4291106476864801,-2.4022300649564174
622.6000000000081,29.298410747218885,0.43039147465661953,-2.4022300665676157
623.8000000000081,29.338107255718647,0.4322343839551661,-2.402234887525318
625.0000000000082,29.377710327433693,0.4405335318198942,-2.4035468110180913
626.2000000000082,29.417098195805426,0.44124507080935027,-2.4035465518671844
627.4000000000083,29.456610775470274,0.44471289554620586,-2.404857310780283
628.6000000000082,29.495921631105738,0.452404693291087,-2.404869763849578
629.8000000000083,29.535710344229177,0.45174518363951854,-2.405428095424567
631.0000000000083,29.575403167415608,0.4559965645632209,-2.406180167799961
632.2000000000082,29.61499027618431,0.4665748462856518,-2.406180065038994
633.4000000000083,29.65480130193672,0.47317894436770325,-2.406180067399056
634.6000000000083,29.694281098135047,0.4761327083233782,-2.4061837497037035
635.8000000000084,29.73379422295444,0.48300012761464695,-2.407501423305879
637.0000000000084,29.773330000000286,0.49291136028259785,-2.4075001549999975
638.2000000000083,29.812955925176187,0.4988501839419266,-2.4088191527812652
639.4000000000084,29.8525390110641,0.5111107981627854,-2.410127583153243
640.6000000000084,29.89203911500432,0.5187679466416231,-2.411469793744314
641.8000000000084,29.931769224468646,0.5341182998460674,-2.413009671178954
643.0000000000084,29.971332135740457,0.5459200542997338,-2.4144307773717033
644.2000000000085,30.01104269040314,0.5614027491616393,-2.4156684975021934
645.4000000000085,30.05055822754007,0.5725514979093287,-2.4158664794862212
646.6000000000085,30.090171784956073,0.5895563774502297,-2.417044769224753
647.8000000000085,30.12994121287226,0.6042114375979046,-2.4184429563400287
649.0000000000085,30.16964651658209,0.6221256302774427,-2.4189375833937214
650.2000000000086,30.209015844173216,0.6389608905998314,-2.4198875246377654
651.4000000000085,30.248991102902057,0.6560711164448549,-2.419887474924608
652.6000000000085,30.2886693641121,0.675699680921479,-2.421219214817249
653.8000000000086,30.328528144640767,0.6973661288509612,-2.422575947229361
655.0000000000086,30.36792215638819,0.7178435578054556,-2.4238713058502057
656.2000000000087,30.407629838315803,0.7386192672875174,-2.426073046251216
657.4000000000086,30.44723310677063,0.7627455378710801,-2.4282944164188938
658.6000000000087,30.48670139836644,0.7864566158181201,-2.428239961969407
659.8000000000087,30.526834688874814,0.809996316733804,-2.429657755070461
661.0000000000086,30.566702048695095,0.8376871716880789,-2.4310899638118224
662.2000000000087,30.60627413402871,0.863446021886964,-2.4325125331647497
663.4000000000087,30.645000010942496,0.890751834814248,-2.433942930862433
664.6000000000088,30.685670059658754,0.922779417526719,-2.4356262712284877
665.8000000000088,30.72537063719694,0.9535134761700477,-2.4382105054062944
667.0000000000088,30.764934247765456,0.9838199112731529,-2.4402578755121325
668.2000000000088,30.804762398594498,1.0177220954702861,-2.4432838357712807
669.4000000000088,30.8446479843922,1.0498483294219974,-2.445075306530282
670.6000000000088,30.884015596417456,1.0870220119577276,-2.446830626712645
671.8000000000088,30.924020925321933,1.1197284447461895,-2.449929617210054
673.0000000000089,30.96345705135331,1.1563439943305722,-2.4532868728517707
674.2000000000089,31.003424166473433,1.1900792391214974,-2.455484623691979
675.400000000009,31.04297651494154,1.229127876865816,-2.457754779871567
676.6000000000089,31.082611508472553,1.2597982593331594,-2.4585726385502156
677.8000000000089,31.12236219838275,1.2984690506263445,-2.462404041562861
679.000000000009,31.16212400189104,1.3380289371607763,-2.4662000078248845
680.2000000000089,31.20195976620161,1.3764450744930967,-2.4688810812946604
681.400000000009,31.241597817010128,1.4167382652707923,-2.4716679921458615
682.600000000009,31.281346835475794,1.4548745133699832,-2.4750112049787227
683.800000000009,31.321555007798548,1.4974886598274606,-2.479309140737082
685.0000000000091,31.36114207491364,1.5406555734401037,-2.482805958368587
686.200000000009,31.401060677205205,1.5775553673284413,-2.4849659589501885
687.4000000000091,31.44056274211663,1.6159849025063404,-2.4887312868427633
688.6000000000091,31.48054091494733,1.6537297408572795,-2.490643381778242
689.800000000009,31.52046713451659,1.6936810355915788,-2.4942808086141444
691.0000000000091,31.560130632487276,1.7357081743730896,-2.496908930033684
692.2000000000091,31.60016163054593,1.7758263670118004,-2.500861554158802
693.4000000000092,31.640231135862958,1.8186663644638597,-2.5053459496085715
694.6000000000092,31.67929982716822,1.851675168416668,-2.5102527645719057
695.8000000000092,31.720000322253696,1.894782706899827,-2.5144400568465897
697.0000000000092,31.759901269808246,1.935865164194392,-2.5188227108185903
698.2000000000093,31.79952732976861,1.9760145876172706,-2.5232178518212334
699.4000000000092,31.83993225304057,2.0232470501746533,-2.528809022831854
700.6000000000092,31.87961066532108,2.0642055539055564,-2.5332760184326806
701.8000000000093,31.919375278036668,2.105212161783245,-2.537754598056855
703.0000000000093,31.959386396657113,2.1450282248770636,-2.543520499586038
704.2000000000094,31.999649642704806,2.1874857152151357,-2.5486493807077113
705.4000000000093,32.039400567266895,2.2346869735475003,-2.553444452227607
706.6000000000093,32.07953428828983,2.279318489920929,-2.559120171431357
707.8000000000094,32.1194806893082,2.3185463223110157,-2.563583474192608
709.0000000000093,32.1595277793639,2.3610659004720267,-2.5698723628332827
710.2000000000094,32.19939633091039,2.3979115843768524,-2.574067727683806
711.4000000000094,32.23977193437353,2.4428339798402785,-2.578457749730026
712.6000000000095,32.27948627741341,2.486339160048981,-2.5844913068928146
713.8000000000095,32.31954867713634,2.52413096694628,-2.590249175759406
715.0000000000094,32.359470542268554,2.5719869446418206,-2.5967333376905506
716.2000000000095,32.39963250219971,2.6094772573559517,-2.602808184657016
717.4000000000095,32.439692580724106,2.657583828914591,-2.6099024470302012
718.6000000000095,32.47973230903362,2.6969400845979226,-2.61434436791932
719.8000000000095,32.52013615926429,2.750497450249056,-2.620429588509776
721.0000000000095,32.560350829939985,2.798320720497276,-2.6264697710152003
722.2000000000096,32.60009818153736,2.849938646592075,-2.632801702240797
723.4000000000096,32.6405363490199,2.9136272974888198,-2.6393627170751808
724.6000000000096,32.68026939000756,2.978534947471651,-2.645551953036071
725.8000000000096,32.72051207338199,3.05807158350415,-2.6522288866031287
727.0000000000097,32.760533085722656,3.14454261011645,-2.659305301465591
728.2000000000096,32.80083455361786,3.2376954424850277,-2.6666078575932732
729.4000000000096,32.84104018883348,3.3425259607597493,-2.6741760835568575
730.6000000000097,32.88119880860051,3.4549401786158676,-2.681753404374626
731.8000000000097,32.92120971172534,3.5643111205580853,-2.6896801297262547
733.0000000000098,32.96144910322526,3.680700883442496,-2.698916151889425
734.2000000000097,33.001801569148704,3.7993909296770125,-2.707345865745591
735.4000000000098,33.04199235818238,3.913301518383662,-2.7173650018004283
736.6000000000098,33.082101196185135,4.028920693117595,-2.727382976490838
737.8000000000097,33.12245596039652,4.146268911129629,-2.737219609348555
739.0000000000098,33.16268544798357,4.258257853947187,-2.7469542564426863
740.2000000000098,33.20307093525427,4.362926032749092,-2.757303576942477
741.4000000000099,33.24329048988936,4.4730571485320505,-2.7676959410178155
742.6000000000099,33.28344554759497,4.574530334767041,-2.778125661122252
743.8000000000098,33.32391727823454,4.672682552133782,-2.789610251148509
745.0000000000099,33.36411399997161,4.765329386378999,-2.8013694899586836
746.2000000000099,33.40478885280637,4.85219165495522,-2.812682959788398
747.4000000000099,33.44508815967328,4.939809101884633,-2.8250006342830414
748.6000000000099,33.484925043602146,5.014197047887768,-2.8363870689879804
749.80000000001,33.5256973669207,5.087656538050831,-2.8487300654380543
751.00000000001,33.56626073542512,5.14853163192891,-2.862260715088277
752.20000000001,33.60627037174859,5.19763686827902,-2.8744284007902285
753.40000000001,33.646836744830445,5.234507572227125,-2.8865268431246536
754.60000000001,33.68718806558354,5.250816987613599,-2.8980836167415225
755.8000000000101,33.72749353086701,5.252158967692596,-2.911028694682179
757.00000000001,33.76756440630598,5.226283486201012,-2.9233357450871935
758.20000000001,33.807978256759,5.171201994927383,-2.936191078927216
759.4000000000101,33.84833654684987,5.07270432502676,-2.9503859937113073
760.6000000000101,33.88780373407724,4.919535677382992,-2.95987730174531
761.8000000000102,33.929061594407266,4.683143975652772,-2.972173679113048
763.0000000000101,33.969369728318675,4.354687446417523,-2.9864743508839933
764.2000000000102,34.009230762109596,3.9043887550610954,-2.996429977428226
765.4000000000102,34.04916021652696,3.195311000455372,-3.0062418542292164
766.6000000000101,34.0894632443632,2.146669576465441,-3.014317272112401
767.8000000000102,34.129188344635565,1.4044245082207012,-3.018193253813056
769.0000000000102,34.16882130782779,0.9633624522193043,-3.0187287746515477
770.2000000000103,34.20887399238758,0.6957295255372737,-3.0199896980062104
771.4000000000103,34.24902141476212,0.5290858079408045,-3.0199900991006317
772.6000000000103,34.28908006010939,0.4273822670931444,-3.020157809409864
773.8000000000103,34.32958307378028,0.3595661345971175,-3.0213001441359557
775.0000000000103,34.36947636524349,0.3184262101824493,-3.021299870093329
776.2000000000103,34.40980272590011,0.2829466025668248,-3.0212998726187377
777.4000000000103,34.450250593085855,0.26088583460713766,-3.0213122657992133
778.6000000000104,34.49044054164076,0.24534708575926834,-3.0203201454024495
779.8000000000104,34.530638804360464,0.22905180652149637,-3.0199683380372946
781.0000000000105,34.571082150161004,0.221701989336486,-3.0199898613089067
782.2000000000104,34.61137509881988,0.2121368248402593,-3.0199898699950376
783.4000000000104,34.651838725060934,0.2068602701268083,-3.0199898688390525
784.6000000000105,34.69199188213701,0.20145001689390263,-3.0199869833262323
785.8000000000104,34.73258885597365,0.19604045960467031,-3.0213070204996715
787.0000000000105,34.77268817544252,0.19644232856400778,-3.0213099590782155
788.2000000000105,34.81323331167715,0.1894315294373774,-3.021309958272038
789.4000000000106,34.85332934628819,0.18803343856199461,-3.021309927288574
790.6000000000106,34.89379048985615,0.18669231906765704,-3.0226202629056393
791.8000000000105,34.93414119997318,0.18099995300178806,-3.022620181506299
793.0000000000106,34.97434774462161,0.18133742378410922,-3.022637882448119