File: 01_Data/Nylon_Carpet_High_Pile/STA/N2/30K_min/Nylon_Carpet_High_Pile_STA_N2_30KData_220308_R1.csv
##Temp./Â°C,Time/min,DSC/(mW/mg),Mass loss/mg
49.0,10.367651306436825,0.012809846529293845,-0.0015737162804967397
50.20000000000002,10.674621273298477,0.09525390887615082,-0.0012799665585108144
51.400000000000034,10.816959966340377,0.16259469596350418,-0.003037465269710271
52.60000000000005,10.92517069475976,0.2256052476350764,-0.0027242711880877124
53.80000000000007,11.01506280299391,0.27876931452643905,-0.0019419664209077148
55.000000000000085,11.093913366641136,0.32570672820106816,-0.0022155110704527026
56.2000000000001,11.165943628409146,0.3670006767966928,-0.001894400121554174
57.40000000000012,11.233155855503764,0.4079164602677506,-0.0009097213165571993
58.600000000000136,11.29614208337914,0.44580814806808133,-0.001303226671856006
59.80000000000015,11.355643302166417,0.4810103397516052,-0.001110684227254577
61.00000000000017,11.412789418277374,0.5132316487222879,-0.0025269315368388057
62.20000000000019,11.468119709044721,0.5435865947602859,-0.002377992889605718
63.400000000000205,11.519958510158398,0.5732806042251266,-0.0018806784604343818
64.60000000000022,11.572202878812519,0.599887472748096,-0.0028849617631028224
65.80000000000024,11.62304854537604,0.6261325838194862,-0.003336182637260876
67.00000000000026,11.672311060506347,0.6525273532720536,-0.0028381536364987525
68.20000000000027,11.720686071567243,0.6758372521195954,-0.001934685760548227
69.40000000000029,11.7684394932448,0.7018716105784524,-0.0013208161077336023
70.6000000000003,11.815670554055393,0.7236077272375944,-0.0021341620037982345
71.80000000000032,11.861791376693215,0.7452938190293823,-0.002257717251960667
73.00000000000034,11.906257186315749,0.7641369008729472,-0.0016065856064630957
74.20000000000036,11.952879638366849,0.7851690853368989,-0.0019891875776796297
75.40000000000038,11.997926512769954,0.8028549430993065,-0.001489935149184607
76.60000000000039,12.042366165435332,0.8219548805463888,-0.0019703950375014045
77.80000000000041,12.086251741110328,0.8394669324690647,-0.002476836620647571
79.00000000000043,12.130452007706685,0.8546935056003455,-0.002074718081917837
80.20000000000044,12.174144806145982,0.87043033402213,-0.0032718363082175905
81.40000000000046,12.217429460334596,0.8872953853930163,-0.0032786401462643333
82.60000000000048,12.260493970843454,0.9016827223949953,-0.003703733248530572
83.8000000000005,12.303382229364106,0.9154073089514791,-0.0036537763699837633
85.00000000000051,12.345405644628082,0.9307001735452136,-0.003224120124890817
86.20000000000053,12.387191736623148,0.9421700145201122,-0.0037063384621491835
87.40000000000055,12.429577311821896,0.9583600411690658,-0.0037228606427586186
88.60000000000056,12.471392151826967,0.9708685606622827,-0.003754025953798479
89.80000000000058,12.513060509523253,0.9828706995530689,-0.003832634400370072
91.0000000000006,12.554089069340387,0.9948475554236925,-0.004093142065505706
92.20000000000061,12.595928990167362,1.0068930711131383,-0.004581896624797466
93.40000000000063,12.637118584369142,1.0205081120412434,-0.005147001785480221
94.60000000000065,12.677807916830327,1.0318656809274926,-0.005135343333004361
95.80000000000067,12.718961690452968,1.0404994036488953,-0.0040697033564089935
97.00000000000068,12.759643945933162,1.0506554596824007,-0.005149892064256978
98.2000000000007,12.800792935065395,1.0604695260871322,-0.005142594905803044
99.40000000000072,12.841328312823498,1.0664550000094282,-0.005160067617860253
100.60000000000073,12.882002031487563,1.0714155572909623,-0.004669927100085403
101.80000000000075,12.922662908751464,1.0790178035750384,-0.005148730382464439
103.00000000000077,12.963015738673368,1.0813279110512737,-0.0037722896127636574
104.20000000000078,13.00357141183344,1.0845594674044918,-0.005151264860641547
105.4000000000008,13.044152139552118,1.0847537372350402,-0.00632954129927521
106.60000000000082,13.084616126031152,1.0873987873524151,-0.006469613809674701
107.80000000000084,13.125249967380345,1.0880750958080772,-0.007511158746440039
109.00000000000085,13.165272485466142,1.090781995821883,-0.006505007641059102
110.20000000000087,13.205648073804815,1.0919090764519281,-0.007748219367917475
111.40000000000089,13.244852174525441,1.091050985748278,-0.006470572307887945
112.6000000000009,13.286006847846188,1.095578564119896,-0.006865423364280421
113.80000000000092,13.326380927017341,1.0953434565681825,-0.007774193945034202
115.00000000000094,13.366437299020259,1.0988634888733992,-0.007775729131079601
116.20000000000095,13.406055748895776,1.100142242579768,-0.00969507105547196
117.40000000000097,13.446245208954682,1.102415521825357,-0.00976012046480923
118.60000000000099,13.486206022847504,1.1035432792161612,-0.009760137442891281
119.800000000001,13.52623248937493,1.1091770110018107,-0.009761604249618916
121.00000000000102,13.566112414708524,1.1102440822698465,-0.00980069440861886
122.20000000000104,13.605802679188884,1.1150861871780702,-0.00976006461515544
123.40000000000106,13.645702404659842,1.1163069542150283,-0.009760050005099608
124.60000000000107,13.685370692492585,1.1190988762420062,-0.009760048763438611
125.80000000000109,13.724867600910306,1.1224509339200466,-0.009756180682239712
127.00000000000111,13.764405675647712,1.128747459386936,-0.00877695200521389
128.20000000000113,13.803758507866272,1.132503220664459,-0.008783659683688327
129.40000000000114,13.843001663795274,1.134659446691699,-0.010089704464219196
130.60000000000116,13.882411870817045,1.1420930159320564,-0.010089907756842376
131.80000000000118,13.921448980996312,1.1442334702192367,-0.010089908057382413
133.0000000000012,13.960557216229605,1.1499811786249154,-0.010090011529034548
134.2000000000012,13.999649787435938,1.1544699965702292,-0.010032706330020957
135.40000000000123,14.038707475742907,1.1585358031147122,-0.011080447709774344
136.60000000000124,14.077404413304007,1.1610661901166346,-0.011080181090473928
137.80000000000126,14.116442966888226,1.1678281626796518,-0.01108018096683061
139.00000000000128,14.155074705618478,1.1744412231947923,-0.011080130291938772
140.2000000000013,14.193861359999252,1.1802726008064497,-0.011040160354863549
141.4000000000013,14.232571330060575,1.1852751100484653,-0.011601182965796042
142.60000000000133,14.270451381592501,1.1920414746620953,-0.011739804585733982
143.80000000000135,14.309538237358227,1.20011467844828,-0.011460468651093514
145.00000000000136,14.34787595914553,1.2071852403260328,-0.011080167826056364
146.20000000000138,14.386538272403882,1.2155289040654673,-0.011080093996217233
147.4000000000014,14.42469043942891,1.2249437178746794,-0.011080094750699487
148.60000000000142,14.463222559265944,1.2343615745676972,-0.011079467315925573
149.80000000000143,14.501308847701463,1.2451174658225654,-0.012401897863389966
151.00000000000145,14.539290002587295,1.2585805308534384,-0.012390100658223435
152.20000000000147,14.577643779625399,1.2713089642860975,-0.012390366668100228
153.40000000000148,14.615699168399138,1.2921711836516434,-0.013644618395563857
154.6000000000015,14.6534568913957,1.3099482315751543,-0.013710031226798147
155.80000000000152,14.691861360638963,1.3319423231942933,-0.013710093993599681
157.00000000000153,14.729605414439362,1.3490521998944385,-0.013710094000010109
158.20000000000155,14.767465251519525,1.3729909644667162,-0.013710094009272922
159.40000000000157,14.805848743061578,1.397772565783264,-0.013710107749727474
160.6000000000016,14.843204610182745,1.4201248910303264,-0.013702708793702723
161.8000000000016,14.881307587228548,1.4391410484237583,-0.014699237052828718
163.00000000000162,14.919045897350424,1.453536012690465,-0.01470009357860258
164.20000000000164,14.956804240035737,1.4639638031700903,-0.014700094000033026
165.40000000000165,14.994560587583353,1.456726392171377,-0.014700094000001052
166.60000000000167,15.032326957883607,1.4428880245613398,-0.01470009399999972
167.8000000000017,15.070128301660793,1.4246453713333262,-0.014700093999998831
169.0000000000017,15.107965298531079,1.405023017421588,-0.01470009399999972
170.20000000000172,15.14528546787658,1.38535839753801,-0.014700094000000608
171.40000000000174,15.18312767138749,1.3700794538499415,-0.014700094000000608
172.60000000000176,15.220275663703639,1.3585425733994747,-0.01470009400000416
173.80000000000177,15.258071413651829,1.3526212826681367,-0.014700094001992792
175.0000000000018,15.295472786679886,1.3486766350592423,-0.01470008057253569
176.2000000000018,15.332809910240139,1.3450031123381838,-0.01468049025737539
177.40000000000182,15.36994358845563,1.3423837102211844,-0.015019958835199798
178.60000000000184,15.407355233637933,1.3439697917270137,-0.015020093766605402
179.80000000000186,15.444658395999145,1.3455219648946568,-0.01502009399997739
181.00000000000188,15.481756170058931,1.3469639425319628,-0.01502009400000004
182.2000000000019,15.518994338883669,1.349877773424542,-0.015020093999999595
183.4000000000019,15.555974434039113,1.3561555407885704,-0.01502009400000004
184.60000000000193,15.593134012006782,1.361872746328686,-0.015020094000000483
185.80000000000194,15.630196786304976,1.366947609739826,-0.01502009399987747
187.00000000000196,15.667082435295642,1.3711643281962014,-0.015020092558755582
188.20000000000198,15.703871985110775,1.379560243379781,-0.01501968472873294
189.400000000002,15.74080145335312,1.3851568619375496,-0.016380886007922868
190.600000000002,15.777758078797106,1.3937346667602433,-0.017510823809999465
191.80000000000203,15.814886054629529,1.4003490721616503,-0.017660123410101924
193.00000000000205,15.851566900518971,1.4099063576517874,-0.01766018104999789
194.20000000000206,15.888260781621067,1.4184703316541671,-0.017660179157713785
195.40000000000208,15.925019190648722,1.4289188870043532,-0.017657960199912726
196.6000000000021,15.961710853053466,1.4398472106484381,-0.016330781032118935
197.80000000000211,15.998507849097953,1.4477072609870953,-0.016338263893179494
199.00000000000213,16.035328687365347,1.4627659505383561,-0.01767731510032622
200.20000000000215,16.071949532698188,1.4714553603356113,-0.01766019950178155
201.40000000000217,16.108746445843952,1.489070837579127,-0.017660180990354046
202.60000000000218,16.14551483794086,1.5036984692256774,-0.017660181018160692
203.8000000000022,16.181969860641274,1.518389444535772,-0.01766022145249524
205.00000000000222,16.21891853481781,1.5382626454003911,-0.017628884306906567
206.20000000000223,16.255354257815615,1.5549761071017933,-0.018968993777450205
207.40000000000225,16.291932307719545,1.5826081261768201,-0.01897005059478607
208.60000000000227,16.328621597403707,1.6133395581670422,-0.018970050000511218
209.80000000000229,16.365222480122632,1.6474568671291692,-0.018970050000000516
211.0000000000023,16.402093000497775,1.6994838873967655,-0.018970050000001404
212.20000000000232,16.438235532700634,1.764920160195966,-0.01897004999980867
213.40000000000234,16.47514253089431,1.865037773752915,-0.018970049705128833
214.60000000000235,16.51186049914371,1.993456340873852,-0.018970400046132152
215.80000000000237,16.548231315407655,2.146835786645162,-0.02008484671231736
217.0000000000024,16.585109927379445,2.329764202935601,-0.02029017276843037
218.2000000000024,16.621736514431934,2.5178496929885665,-0.0202901358149159
219.40000000000242,16.657420465224142,2.6923795749806683,-0.020288577609870462
220.60000000000244,16.695223999763684,2.833937105193661,-0.021650328155758736
221.80000000000246,16.732027644573417,2.887355760144211,-0.021610421098103405
223.00000000000247,16.768919973897088,2.818503416373857,-0.022768635581333907
224.2000000000025,16.805410794360693,2.6427053733750414,-0.021904155168642525
225.4000000000025,16.842393040722285,2.439912553378516,-0.021051647014115105
226.60000000000252,16.878622836915696,2.2663258697438335,-0.020290195457946414
227.80000000000254,16.915382699834254,2.1217887665187285,-0.0208112387946211
229.00000000000256,16.95134096547877,2.0098902123986835,-0.0216096265702439
230.20000000000258,16.987742927942765,1.9159440824591394,-0.02160983091491886
231.4000000000026,17.023960535589413,1.8459211201428651,-0.02160983099324376
232.6000000000026,17.060354747118385,1.7883909173361743,-0.021609828659524766
233.80000000000263,17.09629880453164,1.7456790537466487,-0.02162111212594997
235.00000000000264,17.132791476306082,1.713823279028285,-0.024282229681765966
236.20000000000266,17.1688987643123,1.6841107287936832,-0.024240047009957966
237.40000000000268,17.20472859372872,1.664188671727117,-0.02423976989305432
238.6000000000027,17.24109772889669,1.6485761800184218,-0.02311559352695225
239.8000000000027,17.276624616801058,1.6390157866623836,-0.023030141228929324
241.00000000000273,17.31355286090129,1.628624395088633,-0.02424007648117099
242.20000000000275,17.34957969775342,1.6219539814455728,-0.024240180774735887
243.40000000000276,17.385730215978825,1.6195252808985368,-0.02424007590327326
244.60000000000278,17.422301654377282,1.616405954462647,-0.024496757754883358
245.8000000000028,17.4581300652799,1.6142136454001657,-0.024900347281037405
247.0000000000028,17.493780212663104,1.6120723345720318,-0.02490730371419758
248.20000000000283,17.530533624304688,1.6122467290872824,-0.026875466160221073
249.40000000000285,17.566790595287145,1.613696394442791,-0.02687988072667391
250.60000000000286,17.603033882812277,1.6146017846416623,-0.026879873777642338
251.80000000000288,17.638908106191487,1.6135493206910834,-0.026880933036713017
253.0000000000029,17.6751936863035,1.6171306930439577,-0.0258828104725759
254.20000000000292,17.711047753052302,1.618807403425201,-0.02590510930139045
255.40000000000293,17.747365438701497,1.6197421131887237,-0.02720184233720868
256.600000000003,17.783493956230725,1.622633141921285,-0.02720013136114785
257.80000000000297,17.819817807603055,1.6259407480754984,-0.02720013600031157
259.00000000000296,17.8555630942049,1.6282682116386802,-0.027200135998298958
260.200000000003,17.891691978232046,1.6301230845956476,-0.027200137590264628
261.40000000000305,17.927771439158622,1.6320957336843578,-0.02720164926266344
262.60000000000304,17.963986644213303,1.6331471815652403,-0.028531210194730594
263.800000000003,18.000383893191824,1.6350494849103612,-0.028795624679217813
265.00000000000307,18.036534467085843,1.6374657288871366,-0.029822586064883083
266.2000000000031,18.07243121562151,1.6365874552041166,-0.03049000771303456
267.4000000000031,18.108354081069187,1.6411077287943543,-0.030490092085694087
268.6000000000031,18.144553100805844,1.6443118038433475,-0.0304898178589581
269.80000000000314,18.18077661537463,1.645604589612044,-0.031246937639676897
271.0000000000032,18.216722043409597,1.6489084657457556,-0.030473766575011663
272.2000000000032,18.25283554860456,1.6519314943105754,-0.030490182229004237
273.40000000000316,18.288995175675048,1.6535836386264273,-0.03049001739003243
274.6000000000032,18.325356831353183,1.6543168272458173,-0.03095815528761303
275.80000000000325,18.3613385310297,1.656426541153011,-0.03313128357472639
277.00000000000324,18.397456418216294,1.6602928158389745,-0.033129871297396196
278.20000000000323,18.433636925766944,1.660752841366136,-0.033129873008451494
279.4000000000033,18.469678947245963,1.6612817233282757,-0.033129801214498045
280.6000000000033,18.505954037899176,1.6642840918949477,-0.033398901759465804
281.8000000000033,18.54193016245043,1.6663895268865663,-0.03443975062230464
283.0000000000033,18.578019066567492,1.6693741158112803,-0.034440135172468356
284.20000000000334,18.614517284436097,1.6721483743905732,-0.03444004170279458
285.4000000000034,18.65049823663217,1.673589468363478,-0.03475589222766162
286.6000000000034,18.686977766911152,1.6774009730421358,-0.03575986464115699
287.80000000000337,18.72327604664725,1.678832518443472,-0.0358228762213626
289.0000000000034,18.75889154747739,1.6807111087470328,-0.035099873874751
290.20000000000346,18.795182753843445,1.6830053166112549,-0.03522063638441475
291.40000000000344,18.831362468808557,1.6849088851504572,-0.03641932062930442
292.60000000000343,18.867727296030314,1.6868955952659876,-0.036415344386595994
293.8000000000035,18.903842458295358,1.686859255564682,-0.03772636916461458
295.0000000000035,18.939880212966315,1.6876537189612155,-0.037730221121585306
296.2000000000035,18.97601661001678,1.6943938763993422,-0.0389087827287371
297.4000000000035,19.012207338070247,1.6938610952915394,-0.03905229347305772
298.60000000000355,19.048423478123762,1.6953461662422113,-0.040426893781456474
299.8000000000036,19.08471133212641,1.6945363133815055,-0.041680942266648646
301.0000000000036,19.121061565227368,1.6946118748308427,-0.04166692335918887
302.20000000000357,19.157237797459445,1.6957951157810842,-0.043003120767034275
303.4000000000036,19.193565403080758,1.6996172101915596,-0.043004464318944
304.60000000000366,19.22954800045344,1.698963156268404,-0.04302466552508255
305.80000000000365,19.2659052220182,1.70321527069546,-0.04332996178676263
307.00000000000364,19.3020857097334,1.7020530999056107,-0.04332976281429257
308.2000000000037,19.338246069651372,1.7033405570386475,-0.043764402617501474
309.40000000000373,19.374250398752075,1.7050723215171568,-0.04553984224862262
310.6000000000037,19.41066829222672,1.7075256344108107,-0.045634951606303265
311.8000000000037,19.446552923376505,1.7066091855657852,-0.046950471015721806
313.00000000000375,19.48289217223907,1.7107946262616105,-0.046949879152777374
314.2000000000038,19.51934922727595,1.7096699912319342,-0.04694986156415748
315.4000000000038,19.555658877690554,1.7124539610976406,-0.046911609041645264
316.6000000000038,19.592032959885593,1.7135151611096786,-0.04827212509134249
317.8000000000038,19.62850631289443,1.7171272098369035,-0.04963217783745577
319.00000000000387,19.6646425749599,1.718871784213925,-0.049575778990081254
320.20000000000385,19.7012272583414,1.724838993911884,-0.05088946761170288
321.40000000000384,19.737570748697564,1.7285364743904776,-0.05126793940973151
322.6000000000039,19.7741858479952,1.7299303936551613,-0.05221002355622151
323.80000000000393,19.810542505461033,1.7377271562060266,-0.05344800048562215
325.0000000000039,19.846700871786204,1.7425579401285856,-0.053529495660119775
326.2000000000039,19.88307335935546,1.7459751868514672,-0.05496424525362187
327.40000000000396,19.919718882355866,1.7532745360840136,-0.05605009693628782
328.600000000004,19.955970518574034,1.762561731477959,-0.0576249936926323
329.800000000004,19.992464593985524,1.7700545011251831,-0.05913049445376206
331.000000000004,20.028924265841816,1.7769322061071482,-0.06082240871228439
332.200000000004,20.065595728912175,1.7872842352618068,-0.0625478133214421
333.40000000000407,20.101999679249015,1.7962266570934293,-0.06378517419514029
334.60000000000406,20.138425809731164,1.8055200544688284,-0.06525797651452336
335.80000000000405,20.174902123259056,1.8170072806661686,-0.06783379316027638
337.0000000000041,20.211617918635675,1.8265392359322314,-0.06957300231652219
338.20000000000414,20.248476667975112,1.8375359969344411,-0.07152470266079591
339.4000000000041,20.285068426505713,1.8451705569160917,-0.07446114971329054
340.6000000000041,20.321706306744527,1.8590801706644224,-0.07635145030562862
341.80000000000416,20.358171141167087,1.871496968375444,-0.080018924495592
343.0000000000042,20.394775442974193,1.8846517704601977,-0.08473328606678043
344.2000000000042,20.43151237237504,1.8972915916587625,-0.08776112763684951
345.4000000000042,20.468132973825895,1.9123842147289882,-0.09094292010553895
346.60000000000423,20.50497648951122,1.9273458461708988,-0.09433250493022705
347.8000000000043,20.54180621271362,1.9421017080591705,-0.09698607626949984
349.00000000000426,20.5786794773893,1.9570648432816173,-0.10045743542456664
350.20000000000425,20.615427723131184,1.9760028183939862,-0.10472137971166573
351.4000000000043,20.65215655525165,1.990855263041237,-0.10842556365629497
352.60000000000434,20.689320911651123,2.0071171260655767,-0.1123686113386344
353.80000000000433,20.7257668816422,2.0296411330321362,-0.11695136181176524
355.0000000000043,20.762656015151578,2.0470875406037403,-0.12243462589708942
356.20000000000437,20.799268554241596,2.067411645560623,-0.12707302583247415
357.4000000000044,20.83615643442202,2.087042599167871,-0.13224335201551218
358.6000000000044,20.8734255399018,2.111428616518752,-0.13732987489680282
359.8000000000044,20.91025189727635,2.130770497288102,-0.14297394035885258
361.00000000000443,20.946950671417838,2.1549054093914624,-0.1491211953546574
362.2000000000045,20.98404008698995,2.1770880644784123,-0.15565348869798568
363.40000000000447,21.020609827688233,2.2032884151769285,-0.16197518152302282
364.60000000000446,21.05753797691938,2.2284260523680652,-0.16907669064811204
365.8000000000045,21.094517641597328,2.2563242745938448,-0.17640402717097547
367.00000000000455,21.131371888745022,2.2839388349622194,-0.18443015580105104
368.20000000000454,21.16859880516052,2.310285848421164,-0.19307978702480977
369.4000000000045,21.20583899338243,2.34167837816013,-0.20094107698877695
370.60000000000457,21.24261822996908,2.3683308630801214,-0.21044846232183678
371.8000000000046,21.279687840013995,2.3995152511486526,-0.22027556448954755
373.0000000000046,21.316745206733664,2.426478047182207,-0.22986591185372074
374.2000000000046,21.35351461265454,2.4579575400307965,-0.2402603356535189
375.40000000000464,21.390904729408685,2.488928197692916,-0.25143951450660484
376.6000000000047,21.427918691591504,2.519558447956441,-0.262828994927395
377.8000000000047,21.46497488734652,2.550314755390382,-0.2739113021758892
379.00000000000466,21.502013555067947,2.581880265274186,-0.284921333583839
380.2000000000047,21.53929162200542,2.615418206980129,-0.29712686017606593
381.40000000000475,21.576069728874305,2.649236798367231,-0.3102084425142726
382.60000000000474,21.61339539017843,2.681456206348079,-0.32370464269091936
383.80000000000473,21.65075337034412,2.713862061439454,-0.3373375947807009
385.0000000000048,21.688037775251885,2.751215938115353,-0.3507650154684203
386.2000000000048,21.72524104509442,2.785206612913382,-0.36622059296777376
387.4000000000048,21.761792512157776,2.8230405112954085,-0.38132147171051356
388.6000000000048,21.79967500556636,2.861175069683697,-0.3975810560429598
389.80000000000484,21.83689983657808,2.9013907079709846,-0.4136784011217385
391.0000000000049,21.873979037360368,2.944130195393451,-0.4310402897438479
392.2000000000049,21.911387036011984,2.9840118245309775,-0.4484852949927438
393.40000000000487,21.94894945557581,3.0284726934165405,-0.4670324486525108
394.6000000000049,21.986230437368878,3.073365167189067,-0.4852467066109716
395.80000000000496,22.023472263877146,3.1190620528226933,-0.5043991820070342
397.00000000000495,22.06055467618394,3.166156017617348,-0.5253823467838288
398.20000000000493,22.098065458294453,3.216064841866164,-0.5470082490242301
399.400000000005,22.13536657445564,3.2632834710954635,-0.5690292659422864
400.600000000005,22.17286821034738,3.3188952428649614,-0.5915687702649377
401.800000000005,22.21027252742469,3.369156349103984,-0.6156876330261114
403.000000000005,22.247768547252704,3.424761654613597,-0.6400060124590241
404.20000000000505,22.28535216376205,3.478166538215456,-0.666604569176477
405.4000000000051,22.322996973137517,3.5350652606042368,-0.6942742917042657
406.6000000000051,22.360436369364642,3.586061751238687,-0.7228401823871207
407.80000000000507,22.39802119884031,3.6394379928634417,-0.7524759962357099
409.0000000000051,22.435549296350338,3.695276538296687,-0.7825919965619237
410.20000000000516,22.47296058491324,3.7432194274042034,-0.8136725861617751
411.40000000000515,22.510718995830196,3.792705792828744,-0.8463955184931113
412.60000000000514,22.5479200623137,3.8424478517887426,-0.88014107226142
413.8000000000052,22.58562122470692,3.88493104194035,-0.9159591508339049
415.00000000000523,22.623398247659996,3.9259992813482483,-0.9526394829402247
416.2000000000052,22.660992064162365,3.9594920880812543,-0.9902593683400389
417.4000000000052,22.69869358817166,3.996934512619492,-1.0287455996155948
418.60000000000525,22.736207216224347,4.024514797518268,-1.068782220690291
419.8000000000053,22.774004303573125,4.0434786514148735,-1.1100851858687881
421.0000000000053,22.81166381976119,4.058428705429829,-1.1514556329748498
422.2000000000053,22.849187149835075,4.060436000004592,-1.1932431740760325
423.4000000000053,22.886823655537786,4.056309038709847,-1.2364500841732196
424.60000000000537,22.924211718835046,4.042160093236805,-1.2808711079568451
425.80000000000535,22.96220107072669,4.016584733423315,-1.3259544047947989
427.00000000000534,22.999812968991378,3.9759379869680003,-1.3699684274997685
428.2000000000054,23.037513739414813,3.9222549474737707,-1.4148567255234061
429.40000000000543,23.074963114916855,3.8538254261400158,-1.4572103069436984
430.6000000000054,23.11275039776905,3.7735114197046813,-1.5015753444658988
431.8000000000054,23.15022762606599,3.6733286378449606,-1.5457959717975478
433.00000000000546,23.187719738213314,3.5552246945943304,-1.5870419509267282
434.2000000000055,23.225617417977716,3.4153996302695973,-1.6268502085819923
435.4000000000055,23.263132370525106,3.2686214464197363,-1.6651521942298668
436.6000000000055,23.300384829198695,3.102441966401895,-1.7009265914258966
437.8000000000055,23.33813906747583,2.9276763067912883,-1.7345744544065682
439.00000000000557,23.375789935912962,2.7495769217168444,-1.7659829893425565
440.20000000000556,23.412786061164663,2.5753412359685033,-1.7934190207169172
441.40000000000555,23.450277414352488,2.404582784233994,-1.8190733100558862
442.6000000000056,23.488038999248765,2.241759854464628,-1.8413757927535377
443.80000000000564,23.52537066681771,2.100554299180123,-1.8605314158142163
445.0000000000056,23.562937904020476,1.975470658163104,-1.8785530664355785
446.2000000000056,23.60040602448063,1.873220281505593,-1.893775998664526
447.40000000000566,23.637948975074373,1.7822993174430082,-1.9074864545799168
448.6000000000057,23.675386915981207,1.7086012096306629,-1.9201314697715235
449.8000000000057,23.713045165599457,1.648270629939132,-1.9330212669105646
451.0000000000057,23.750538457462635,1.5994602219423948,-1.943378028198307
452.20000000000573,23.787934082944496,1.5582605616889693,-1.9531633499354386
453.4000000000058,23.825681719050188,1.524100819868819,-1.9635315658520878
454.60000000000576,23.863599129858166,1.498184798924791,-1.9737159002273954
455.80000000000575,23.901252197271024,1.4765071316656475,-1.9821074965180852
457.0000000000058,23.939220640426704,1.4583321863642964,-1.991811095011241
458.20000000000584,23.976565905660337,1.4467031609520082,-2.000285528411797
459.40000000000583,24.014585168789058,1.4356770965132188,-2.00873916049209
460.6000000000058,24.05236065344413,1.4240392767631342,-2.0173479757785744
461.80000000000587,24.09005568298792,1.4173398776531307,-2.025748147139282
463.0000000000059,24.127938357954076,1.411976290043297,-2.033370947369577
464.2000000000059,24.166191251441745,1.4090918496716052,-2.0429913749217983
465.4000000000059,24.203608348163346,1.402522648298763,-2.0516643042882645
466.60000000000593,24.24132706682182,1.4025593623099322,-2.059803880003501
467.800000000006,24.27917491605084,1.3991987537834882,-2.0683862668201467
469.00000000000597,24.317435239100647,1.3970559471636042,-2.077702135221666
470.20000000000596,24.355333792658502,1.3961077481452175,-2.085641225091629
471.400000000006,24.39310326721865,1.3924563715462948,-2.0947672646168143
472.60000000000605,24.431386608680754,1.3956245919928505,-2.1027518693231864
473.80000000000604,24.469429693335844,1.3902954249806836,-2.11202432896847
475.000000000006,24.50767403829888,1.3886416642100876,-2.1195132584255694
476.20000000000607,24.545503993413956,1.387056086020463,-2.127434933170947
477.4000000000061,24.583724912608936,1.3857568068931112,-2.1358194130009878
478.6000000000061,24.621633089269615,1.3848808602726463,-2.145351596865915
479.8000000000061,24.66000030278563,1.382450368681495,-2.1545692219438197
481.00000000000614,24.69839551682077,1.382083790332842,-2.161476412836719
482.2000000000062,24.736180709486174,1.3832767053236728,-2.171047591214413
483.4000000000062,24.77457619473794,1.379871510698584,-2.1807557760688874
484.60000000000616,24.81305221933009,1.376544218330943,-2.1899231914348354
485.8000000000062,24.850901497718535,1.3720880108182159,-2.1983504366965447
487.00000000000625,24.889515712096202,1.3649728162123709,-2.207459917840452
488.20000000000624,24.927650057560626,1.3618047429760045,-2.2168531415907538
489.40000000000623,24.965676762549776,1.3578635120372995,-2.225923515144486
490.6000000000063,25.00384515466308,1.3511189621191222,-2.235802390968895
491.8000000000063,25.042209639964884,1.3426290930707558,-2.245769275667291
493.0000000000063,25.08081842515018,1.333563053719968,-2.2550654738883895
494.2000000000063,25.118565917176145,1.3226571229188244,-2.2653065194413737
495.40000000000634,25.157197721002962,1.310111890864266,-2.2747248869605317
496.6000000000064,25.195260224598332,1.2916163500688196,-2.283120297907604
497.8000000000064,25.233580744467556,1.2689386341781979,-2.2910457913369147
499.00000000000637,25.272212681737088,1.2416871508427827,-2.2997550125929993
500.2000000000064,25.310560988352734,1.214808845029871,-2.307507080726542
501.40000000000646,25.349030719094078,1.1768859048676925,-2.3157352320180795
502.60000000000645,25.38725926257338,1.139930379960881,-2.3218968548349688
503.80000000000643,25.425527392764863,1.105017056360492,-2.3276541321785693
505.0000000000065,25.46403700122602,1.0616664852960707,-2.333346827672808
506.2000000000065,25.502484028319525,1.023352784557709,-2.3369243591682913
507.4000000000065,25.54106384872856,0.9914130990153502,-2.3404365835799332
508.6000000000065,25.57956538643409,0.9587353813894702,-2.3442003519447008
509.80000000000655,25.617745591317846,0.9330866688565383,-2.3453742191058495
511.0000000000066,25.656593961408067,0.9076350977715981,-2.34576818189136
512.2000000000066,25.69496837383459,0.8890217156005353,-2.3470508146185063
513.4000000000066,25.73380019575539,0.8708927101265355,-2.348270053068351
514.6000000000066,25.77206850930566,0.8612203689798685,-2.3495515936984512
515.8000000000067,25.810646794169298,0.8515679918589083,-2.349599175321231
517.0000000000066,25.84922932904987,0.8439037824412303,-2.35024382176755
518.2000000000066,25.888019204153053,0.8381498441433254,-2.350901559599847
519.4000000000067,25.92620993862879,0.8310732431028856,-2.350888047168727
520.6000000000067,25.96515325339962,0.8303179650114701,-2.3532032809599848
521.8000000000068,26.003632429106943,0.827091058821923,-2.353210161456124
523.0000000000067,26.042148280583323,0.8214120307091057,-2.3532101660243034
524.2000000000068,26.081086025227922,0.8188559687086236,-2.3532101621340606
525.4000000000068,26.119744865396324,0.8218826229179128,-2.3529300124840713
526.6000000000067,26.15800139927143,0.8201649279711529,-2.3528802315078354
527.8000000000068,26.196890682302787,0.8196607511855457,-2.353001246054071
529.0000000000068,26.23541945234827,0.8229601734382439,-2.3541896954394153
530.2000000000069,26.273900488104537,0.8325101580956913,-2.354189985503929
531.4000000000069,26.312328378021682,0.838431466042334,-2.3547509955700603
532.6000000000068,26.351147733264973,0.8465518341205365,-2.3551800567012524
533.8000000000069,26.38982625217846,0.8512890143733455,-2.3551459288526075
535.0000000000069,26.428398131972227,0.8545201373311989,-2.3555102921769064
536.2000000000069,26.466836663630634,0.8622967161557892,-2.3555101220817916
537.4000000000069,26.50599315850228,0.8652217573499643,-2.3555095137182933
538.600000000007,26.54449584663497,0.868056559520714,-2.3568442614066503
539.800000000007,26.58326444761338,0.8723851108037328,-2.356829602697405
541.000000000007,26.62176428608636,0.8721186532015007,-2.357692716861904
542.200000000007,26.66064077891346,0.8644898600635439,-2.358138636148399
543.400000000007,26.699615159453423,0.8627266378409931,-2.3574802408852373
544.6000000000071,26.738201529467933,0.8565245830196373,-2.357480078991789
545.800000000007,26.777038668131727,0.8523067508236029,-2.357480078000772
547.000000000007,26.816093540412393,0.8487134495054653,-2.357480078006869
548.2000000000071,26.855175577928428,0.8435350905811464,-2.3574800914894505
549.4000000000071,26.894076957322127,0.8397534254381988,-2.3574932836578046
550.6000000000072,26.93311386093077,0.8371817144282904,-2.3584694091374843
551.8000000000071,26.971591403943535,0.8366841053048348,-2.35880180738991
553.0000000000072,27.01064668118177,0.8318495094712681,-2.358805477410887
554.2000000000072,27.04991675748035,0.8307171615086913,-2.3601056132313323
555.4000000000071,27.088845063365817,0.8233390747986681,-2.360110032424483
556.6000000000072,27.127895907510418,0.8200657459797455,-2.36011003399949
557.8000000000072,27.166936128801495,0.815802122973836,-2.360110033992283
559.0000000000073,27.205829420461768,0.8126403171875739,-2.3601100886589386
560.2000000000073,27.245056345773904,0.8034635297471939,-2.3605978259748452
561.4000000000073,27.283833394621695,0.8034349465358533,-2.3611096607180873
562.6000000000073,27.323290018710107,0.7945392431010959,-2.361429405782358
563.8000000000073,27.36222782327044,0.7910693269330223,-2.361871705853675
565.0000000000073,27.401336925438134,0.7889624833700948,-2.363756223439654
566.2000000000073,27.440234877618924,0.7845277050563704,-2.362737169123213
567.4000000000074,27.479764511901408,0.7822784812161739,-2.3627498061163292
568.6000000000074,27.518520917740613,0.7784133475665685,-2.3627534322602046
569.8000000000075,27.557595019276373,0.7783360968355402,-2.361443164359552
571.0000000000074,27.59718478471141,0.7795190959587968,-2.3613828068508007
572.2000000000074,27.636266100380343,0.7771355197202241,-2.3627390921372378
573.4000000000075,27.675489356727365,0.7751265515486693,-2.362797137330746
574.6000000000074,27.714675371901638,0.7742309287952572,-2.36405990352784
575.8000000000075,27.75390941420717,0.7687372383806134,-2.364070375489624
577.0000000000075,27.793165600037682,0.769570794766103,-2.3634000102948507
578.2000000000075,27.832215911535684,0.7683312143959188,-2.3635787902295453
579.4000000000076,27.871520453502747,0.7674876780260899,-2.364060073793396
580.6000000000075,27.911251648503125,0.7653356829051708,-2.364241228132469
581.8000000000076,27.950595570152224,0.7692286269746935,-2.365379675482188
583.0000000000076,27.98952689238382,0.7676765701818961,-2.3653808688068936
584.2000000000075,28.029035074417493,0.7682080219321095,-2.3667422716042577
585.4000000000076,28.068313738360725,0.7693658565065986,-2.3666898970793335
586.6000000000076,28.107652145305646,0.7687714375232272,-2.366689880038666
587.8000000000077,28.14680358513149,0.7697327328956963,-2.3666898905350724
589.0000000000077,28.186480033560272,0.7721564092722929,-2.36766801530837
590.2000000000077,28.225611031666286,0.7722998945951101,-2.367686385322879
591.4000000000077,28.26514487609673,0.7725595439190409,-2.3680097261727733
592.6000000000078,28.30456846509098,0.7782440950242571,-2.368414758161971
593.8000000000077,28.34370459265057,0.7762331106125147,-2.3693302636454887
595.0000000000077,28.38332683584709,0.7778538173749817,-2.369330158131815
596.2000000000078,28.422555090371127,0.7787912780065832,-2.3686113862124634
597.4000000000078,28.46175078387391,0.7821025925386991,-2.3696930187103558
598.6000000000079,28.501137411015723,0.7847388195794391,-2.3696498367748275
599.8000000000078,28.541106697926907,0.7861155852867057,-2.370450443340178
601.0000000000078,28.580032302030457,0.7896206989191199,-2.3709700087458843
602.2000000000079,28.61939268049075,0.7940243874473683,-2.370941459365285
603.4000000000078,28.659077477139245,0.7905079020633691,-2.3722899380031754
604.6000000000079,28.69887290586542,0.7943102047328076,-2.3726612675406082
605.8000000000079,28.73739091724516,0.800264907466157,-2.3729490390865724
607.000000000008,28.7771049887947,0.8009578120183486,-2.3742742375549493
608.200000000008,28.8172592691201,0.8030129038516636,-2.374259996280522
609.4000000000079,28.856869725555345,0.8053353763468268,-2.3743790289690048
610.600000000008,28.896493082794063,0.809766646452225,-2.3752476025619997
611.800000000008,28.935658323757302,0.80805024530902,-2.375250099485143
613.000000000008,28.97552323648991,0.8117681203187892,-2.375403563024567
614.200000000008,29.01531366912478,0.814416954744295,-2.376560199786385
615.400000000008,29.054674688927882,0.8153553596954867,-2.376559919272988
616.6000000000081,29.094327795513856,0.8205774113497446,-2.3765545324212325
617.8000000000081,29.134244315101807,0.8253138976354847,-2.3778806401134047
619.0000000000081,29.17373329302219,0.8282065008185538,-2.376874934358597
620.2000000000081,29.21352986395148,0.8296028791101504,-2.3782191701233524
621.4000000000082,29.253155774577987,0.8306992171242351,-2.3782200965477402
622.6000000000081,29.292775387065433,0.8352374948161736,-2.378222399838283
623.8000000000081,29.332182252030556,0.8388620480493529,-2.3795284072744414
625.0000000000082,29.37177937780972,0.8387008310104694,-2.379529863909058
626.2000000000082,29.41167036813738,0.845821943265845,-2.380362878930871
627.4000000000083,29.451123496293828,0.8499997278654178,-2.3808500300616537
628.6000000000082,29.491093718583606,0.8541051730390607,-2.381624693159094
629.8000000000083,29.530781421474657,0.8578930564497727,-2.3821743965106776
631.0000000000083,29.570451426608212,0.8608608094114146,-2.3834833449202772
632.2000000000082,29.61021338655071,0.8675303794566663,-2.3841616164618853
633.4000000000083,29.649734097667974,0.8738911007411152,-2.384800209449966
634.6000000000083,29.689801650132253,0.8801315115541135,-2.3848979778444357
635.8000000000084,29.729040621058015,0.8896922094871508,-2.386110257918963
637.0000000000084,29.76885841010491,0.8982017688376073,-2.387483560903675
638.2000000000083,29.808650210636433,0.9067377727495297,-2.3874279907419624
639.4000000000084,29.848260121804138,0.9220252483173292,-2.388736420866143
640.6000000000084,29.888009099793432,0.9335345554107114,-2.388755485508206
641.8000000000084,29.92798748805844,0.9434571885204796,-2.3900680437524615
643.0000000000084,29.967582637433406,0.9592409774977949,-2.3914930258895586
644.2000000000085,30.007420800570976,0.9730993240432582,-2.3914929463578485
645.4000000000085,30.04696434124201,0.9881694368567236,-2.3928007796941815
646.6000000000085,30.086979583396147,1.0007646743739627,-2.3941248727945177
647.8000000000085,30.1264984611534,1.0192575732983804,-2.3941120812513184
649.0000000000085,30.166226233372257,1.0314610798695392,-2.3954439715346307
650.2000000000086,30.2062764242202,1.0488896493722322,-2.395375332296982
651.4000000000085,30.246106162853465,1.070382554521594,-2.396756175281041
652.6000000000085,30.285581380777746,1.0867196581580318,-2.3981412694440856
653.8000000000086,30.325404707463264,1.1107713276048714,-2.3994733240472117
655.0000000000086,30.365522227734864,1.1307876951312656,-2.4014323730103637
656.2000000000087,30.405251439899445,1.1503869667588993,-2.4031999501827004
657.4000000000086,30.444821679432202,1.1788143312826613,-2.404071603513377
658.6000000000087,30.485054291156438,1.2024206624982186,-2.4066721757996734
659.8000000000087,30.524580346027648,1.2279439240343137,-2.408083378106473
661.0000000000086,30.564192144709562,1.2532889852736613,-2.409357619338693
662.2000000000087,30.604295652650723,1.2816072979213242,-2.4109000469881723
663.4000000000087,30.644048881584773,1.3114188818872352,-2.4123825773656185
664.6000000000088,30.68361351145631,1.346997199177766,-2.414817893017558
665.8000000000088,30.723434301778422,1.3731774216304493,-2.417230669740978
667.0000000000088,30.763181642120784,1.4068325227351648,-2.418890792073842
668.2000000000088,30.802746269564818,1.440912075793125,-2.422281026861307
669.4000000000088,30.841922443652194,1.4756809714379215,-2.424100851573508
670.6000000000088,30.88256240497582,1.5097576721110837,-2.4269095754729584
671.8000000000088,30.922117910601894,1.5477507827090993,-2.4273740388822054
673.0000000000089,30.961794350781652,1.5827398860000863,-2.431052361991441
674.2000000000089,31.00168888093817,1.619795860072013,-2.4339424900482047
675.400000000009,31.041558702496275,1.6572277687536245,-2.4364130326224718
676.6000000000089,31.08060846463104,1.695647421998933,-2.4391448796712534
677.8000000000089,31.121098384035683,1.7372967424892485,-2.441748168731831
679.000000000009,31.16085251930824,1.7782367742458334,-2.4451606896003852
680.2000000000089,31.200840869712746,1.8174838084640297,-2.4478370235410547
681.400000000009,31.24066246355748,1.8646688291619906,-2.4509375006060345
682.600000000009,31.280497912909464,1.9047876804555648,-2.454320025201989
683.800000000009,31.320234390518223,1.9496691015122996,-2.4579805070006073
685.0000000000091,31.360370951217412,1.9904916217694,-2.4611386654596767
686.200000000009,31.399606073659065,2.031506791142281,-2.46496111315129
687.4000000000091,31.439795203697308,2.0728043343240445,-2.468689727697442
688.6000000000091,31.479692678717782,2.1155885443713673,-2.473180477015963
689.800000000009,31.51934359741807,2.155683771592879,-2.4779815695467624
691.0000000000091,31.55929412921536,2.1934892281729272,-2.481930478970378
692.2000000000091,31.59912688343229,2.234654044471749,-2.4864582912046282
693.4000000000092,31.639104143841703,2.2768837670458244,-2.4889149585869075
694.6000000000092,31.67896330026898,2.3228991329614868,-2.4928714349560117
695.8000000000092,31.71905685801792,2.36624420591393,-2.4974453017544276
697.0000000000092,31.758956179567555,2.405140118033468,-2.502527372205073
698.2000000000093,31.799115846937955,2.4495875611133453,-2.507976301812767
699.4000000000092,31.83868142325772,2.4894793745120847,-2.512706794918215
700.6000000000092,31.878930052908704,2.5371530573695393,-2.5174106415633934
701.8000000000093,31.919049476688397,2.580936126919445,-2.5217573554126935
703.0000000000093,31.958863266893236,2.62050638750099,-2.5261675064698017
704.2000000000094,31.998641244242236,2.665349864280146,-2.534201570881926
705.4000000000093,32.038983065264595,2.7063920642955615,-2.539603451519538
706.6000000000093,32.078958201880695,2.7512492529043167,-2.544706385074006
707.8000000000094,32.11906597016773,2.7905792055385414,-2.5493699930323306
709.0000000000093,32.15907729337008,2.831000634980586,-2.5545031487870835
710.2000000000094,32.19908975808242,2.8723199243379467,-2.5605340917861676
711.4000000000094,32.238898238079656,2.9073461967251584,-2.567558258224431
712.6000000000095,32.27908606073981,2.9446049848160714,-2.5730437778838526
713.8000000000095,32.31857161876583,2.986987777054432,-2.5783431520350284
715.0000000000094,32.3593191649927,3.0283351571896286,-2.584239547823546
716.2000000000095,32.399597678265195,3.064900657849286,-2.5912268018509366
717.4000000000095,32.43959415036197,3.103475830081894,-2.5980798708208415
718.6000000000095,32.47963956444295,3.1417591058305723,-2.603476279875828
719.8000000000095,32.52000033597195,3.186012991114732,-2.610420030834121
721.0000000000095,32.560033579068545,3.233923930584537,-2.617553436781305
722.2000000000096,32.60003471410734,3.286982052241501,-2.6232680131402764
723.4000000000096,32.64034174794119,3.349212181386612,-2.629561013105218
724.6000000000096,32.68043054490778,3.4228677276994497,-2.636250314978126
725.8000000000096,32.720470494917535,3.507602217416758,-2.6429945416075045
727.0000000000097,32.76057230597888,3.602701064655833,-2.65130914095044
728.2000000000096,32.80090997381243,3.7068939253214648,-2.6589347875784832
729.4000000000096,32.841496847137876,3.8271710162219925,-2.6674559745016575
730.6000000000097,32.881660629819585,3.947137278609163,-2.6747688780668613
731.8000000000097,32.92152978361665,4.066586928427856,-2.682283956945887
733.0000000000098,32.96183458096036,4.192762846279262,-2.691228559545075
734.2000000000097,33.0020939775963,4.319637633030097,-2.700395135334605
735.4000000000098,33.04260076144622,4.4438677941289555,-2.711463582239025
736.6000000000098,33.0820389161985,4.565610093992541,-2.7216951822522955
737.8000000000097,33.12286565118307,4.684040355684977,-2.731010664887613
739.0000000000098,33.16324555131805,4.801163056199096,-2.7408973150891986
740.2000000000098,33.203536275398555,4.9109159319304965,-2.7523835063061597
741.4000000000099,33.243543582880775,5.020631451292786,-2.7631989024664305
742.6000000000099,33.284107478678024,5.125987354875996,-2.775066511670186
743.8000000000098,33.324561847369374,5.2264884667562415,-2.787180634425857
745.0000000000099,33.36462391864665,5.314506809347126,-2.7989903042373867
746.2000000000099,33.4051774651119,5.398090618926868,-2.811973212431577
747.4000000000099,33.44516608689975,5.476171755272861,-2.8240153142720392
748.6000000000099,33.485301606626585,5.542323227982974,-2.83632954207288
749.80000000001,33.52543451063871,5.600530053651412,-2.8482000863503485
751.00000000001,33.56592102077687,5.648606432809792,-2.8616326719323557
752.20000000001,33.606260256946044,5.679353305551198,-2.874728371518021
753.40000000001,33.6460464818518,5.694037132936877,-2.887266460289096
754.60000000001,33.68630662395239,5.682852598222039,-2.900299070435758
755.8000000000101,33.72653469287073,5.644752559484217,-2.914092600368675
757.00000000001,33.766971406938914,5.57665137330066,-2.9276141463105896
758.20000000001,33.8067395458925,5.463579079386348,-2.94037186225098
759.4000000000101,33.847341278514556,5.283885184603775,-2.9520578572675684
760.6000000000101,33.88722519951234,5.023782029400998,-2.964079243126678
761.8000000000102,33.927365338266966,4.642871528777821,-2.9749786963238805
763.0000000000101,33.96755006218443,4.095079383205422,-2.984970024213045
764.2000000000102,34.007549959675984,3.15038460995685,-2.9937890382747523
765.4000000000102,34.047199297768124,2.1984533984605226,-2.9987593425415873
766.6000000000101,34.087001986193265,1.6025341767191896,-3.0017744522020138
767.8000000000102,34.12683589335415,1.2537862851167492,-3.0031072609936347
769.0000000000102,34.16653582410416,1.0398621907090098,-3.0031000016758638
770.2000000000103,34.206536215759655,0.9150174962044315,-3.0044103758581313
771.4000000000103,34.246802465489715,0.8315018394686533,-3.0040786389464276
772.6000000000103,34.28677424471113,0.7803367572792406,-3.004100888669559
773.8000000000103,34.326899095008606,0.7458223970525055,-3.0030927103317264
775.0000000000103,34.36710595471998,0.7208240678652391,-3.003089434532112
776.2000000000103,34.40746569055489,0.7040378525223301,-3.0044015628364606
777.4000000000103,34.44787757614242,0.6912669322005016,-3.004409915151374
778.6000000000104,34.48802032021798,0.6830559829350218,-3.0044099189988027
779.8000000000104,34.52855178904084,0.6745576179908666,-3.0044099188146856
781.0000000000105,34.56903640897718,0.6681810318705934,-3.0044061087933036
782.2000000000104,34.6092804722036,0.662068752532575,-3.003090036086942
783.4000000000104,34.64966179987656,0.6619910146109851,-3.0030757284764946
784.6000000000105,34.689910598272185,0.659067944011174,-3.0044111371913402
785.8000000000104,34.73019464651483,0.6603120634187547,-3.0044100062900942
787.0000000000105,34.77074145564306,0.6571888402619988,-3.004409736633879
788.2000000000105,34.81072158152693,0.6566701435310229,-3.0055275257102316
789.4000000000106,34.85122327083134,0.6566114840098438,-3.0057198279295694
790.6000000000106,34.89166366035802,0.653228947262031,-3.0057198749869527
791.8000000000105,34.93209290255555,0.6567508304937493,-3.0057198749999965
793.0000000000106,34.972672474347725,0.6587918128101036,-3.0057198750000005