File: 01_Data/Nylon_Carpet_High_Pile/STA/N2/30K_min/Nylon_Carpet_High_Pile_STA_N2_30KData_220309_R3.csv
##Temp./Â°C,Time/min,DSC/(mW/mg),Mass loss/mg
49.0,10.42,0.026244126512691368,-0.0035872338309612672
50.20000000000002,10.683402283262145,0.08482310504062263,-0.0024562986546254884
51.400000000000034,10.82243367326294,0.13737085956930062,-0.0038793283747833307
52.60000000000005,10.9305294856821,0.18357267864633653,-0.006684674221819176
53.80000000000007,11.019443610637468,0.2233248716267725,-0.005104922089745223
55.000000000000085,11.098403388677044,0.2599554770561724,-0.005048181434271104
56.2000000000001,11.171266953393387,0.29542876034865306,-0.003888492956794387
57.40000000000012,11.238863505493084,0.3277562748879078,-0.004100371433141348
58.600000000000136,11.300997315648818,0.3581567977652802,-0.0049151563401830245
59.80000000000015,11.35848002344024,0.38190702935894144,-0.004797735982481566
61.00000000000017,11.417118462840747,0.41066659226873914,-0.004795586113520933
62.20000000000019,11.472603009213334,0.43474725722660357,-0.005055573209728159
63.400000000000205,11.52583901078854,0.45588815863368815,-0.0053371882986832375
64.60000000000022,11.577598040671644,0.48044341730628815,-0.0046376936415502
65.80000000000024,11.628031157682361,0.5005160251304049,-0.00632161716978219
67.00000000000026,11.677482173809398,0.5207740230783535,-0.0054520528069059715
68.20000000000027,11.7256984769561,0.538828188765714,-0.005450026354742565
69.40000000000029,11.77374568679367,0.5584044700729776,-0.006329066467819278
70.6000000000003,11.820496111790117,0.5742450447852587,-0.006902747905124684
71.80000000000032,11.867621913226971,0.5921147680388708,-0.005892067970195036
73.00000000000034,11.912980703729497,0.6066097148650079,-0.005056778224033387
74.20000000000036,11.958502898531254,0.6224133985672455,-0.005636715068941811
75.40000000000038,12.00316539476504,0.6376338707632487,-0.005888514786881238
76.60000000000039,12.04837961428087,0.6524412462987311,-0.006952241766092548
77.80000000000041,12.091858940776632,0.6639404525846303,-0.005596358870862517
79.00000000000043,12.136159837812519,0.6757700802246764,-0.005369574880330408
80.20000000000044,12.179924604207189,0.6893415391714072,-0.005590301805062925
81.40000000000046,12.222485614989672,0.702707913278289,-0.005088763820414677
82.60000000000048,12.266018848967745,0.7124549470701859,-0.005990232042930366
83.8000000000005,12.30824041690796,0.7250643417362447,-0.00567353743235488
85.00000000000051,12.351045249608738,0.7354097633517305,-0.006327603857673836
86.20000000000053,12.393188250526444,0.7480644407913053,-0.007131412332283205
87.40000000000055,12.434970371979563,0.7578005986020484,-0.007101379277195896
88.60000000000056,12.476854457537419,0.7658762081905259,-0.0074444281105350285
89.80000000000058,12.518414147985675,0.7780585113440459,-0.008549899625296842
91.0000000000006,12.560171635753674,0.7882799795000281,-0.008557415126391188
92.20000000000061,12.601861925132447,0.7982808818373928,-0.007419474971666062
93.40000000000063,12.642518746773925,0.8075901028506416,-0.008550169974153476
94.60000000000065,12.684203527486245,0.8187912480636004,-0.007198074607885019
95.80000000000067,12.724873700717387,0.8254572650880312,-0.008638378417030523
97.00000000000068,12.765714853949508,0.8334378705245884,-0.008769724163919967
98.2000000000007,12.806195848290743,0.843131941153272,-0.009034884731849768
99.40000000000072,12.847301688411648,0.8470726098428096,-0.008769787310356936
100.60000000000073,12.887836494217186,0.8528620222231175,-0.009665327047990946
101.80000000000075,12.928468697095168,0.8552514925400648,-0.010081557416188325
103.00000000000077,12.969039056832045,0.8589453661253644,-0.008771238771248413
104.20000000000078,13.009660084612996,0.857906954158649,-0.0100660130485406
105.4000000000008,13.049834457872517,0.8592220268878613,-0.00875647398884416
106.60000000000082,13.090560547158008,0.8597239276615105,-0.008759408268846247
107.80000000000084,13.130898080381927,0.8581141301743622,-0.008941414237982226
109.00000000000085,13.171268898432963,0.8587566798312776,-0.008768395864930056
110.20000000000087,13.211357843359488,0.8599080726108428,-0.01007422704340133
111.40000000000089,13.251220798754872,0.8569406337013576,-0.009318122461884126
112.6000000000009,13.291944323544532,0.858444614384997,-0.010080007927339985
113.80000000000092,13.332097774823369,0.8595432552721406,-0.010079924026247244
115.00000000000094,13.371384074500115,0.8599093097342514,-0.010079923569892735
116.20000000000095,13.412288585406909,0.8617722611072691,-0.010078717951916616
117.40000000000097,13.4521102111805,0.859808869862754,-0.010906462700495556
118.60000000000099,13.492426471866427,0.859969205380979,-0.009530746130719248
119.800000000001,13.532289340676762,0.8638732522377411,-0.010067301264054862
121.00000000000102,13.572263082467664,0.8621901338898323,-0.011397751367238307
122.20000000000104,13.61164371569009,0.8651062359433374,-0.012721177640549808
123.40000000000106,13.651653999605188,0.8669880456568075,-0.012719956214337635
124.60000000000107,13.69155257848532,0.8696599724710505,-0.012719955990354137
125.80000000000109,13.730529629204726,0.8721114932678677,-0.012719934181885328
127.00000000000111,13.770191673749261,0.8732302356656614,-0.013068167100477535
128.20000000000113,13.80944698718607,0.8765895965241607,-0.014039913598906661
129.40000000000114,13.848928546152923,0.8799317313795864,-0.014046915123674175
130.60000000000116,13.88845900478897,0.8805351376387494,-0.01206780295155152
131.80000000000118,13.927369170480693,0.8820926638771773,-0.012060090067210094
133.0000000000012,13.966568600126688,0.8840549459544516,-0.012063901571720326
134.2000000000012,14.005747607312218,0.889910699466472,-0.013375579700502183
135.40000000000123,14.045039860052235,0.8924708274842975,-0.013380086405798686
136.60000000000124,14.083492623790116,0.8979990061919896,-0.013380855273699588
137.80000000000126,14.122233112394259,0.9002990799877024,-0.014713541204551372
139.00000000000128,14.161186574699071,0.9051917163918448,-0.01469010342282795
140.2000000000013,14.2001266592641,0.9107224180679079,-0.014690088007510038
141.4000000000013,14.238531393493673,0.9145556769824721,-0.014690088000001822
142.60000000000133,14.276996303666873,0.9185643715849257,-0.014690087999999157
143.80000000000135,14.31559968054699,0.9267279406362291,-0.014690087999924106
145.00000000000136,14.354132881604892,0.9321044944697843,-0.014690087924420947
146.20000000000138,14.391894692021317,0.9357201623608438,-0.014690294224305234
147.4000000000014,14.430581748537312,0.9460300824564813,-0.013570331051519169
148.60000000000142,14.468870473117915,0.9516592953694357,-0.014687460794220897
149.80000000000143,14.507239121508752,0.9637454755800485,-0.014689822184256851
151.00000000000145,14.544832035616,0.976454503676506,-0.014689836684226076
152.20000000000147,14.583497112843661,0.9897411274489375,-0.0146830074821227
153.40000000000148,14.621587673941905,1.0050245552798978,-0.01601076029186599
154.6000000000015,14.659736544913768,1.0246043621980598,-0.01600982450863553
155.80000000000152,14.69753032428533,1.043806167784465,-0.016009824015512653
157.00000000000153,14.735677570816378,1.064092777118376,-0.01600972698687153
158.20000000000155,14.773615545794645,1.0857083345057446,-0.01667546720933588
159.40000000000157,14.811675918361571,1.111806939182933,-0.016989785535124646
160.6000000000016,14.849680321729473,1.1337376789152604,-0.016989682090995384
161.8000000000016,14.88727666314627,1.1531605865613557,-0.0173385722650945
163.00000000000162,14.925415386034274,1.1683462899299282,-0.019081613522697882
164.20000000000164,14.963194897972363,1.1723265214599814,-0.01907720001865698
165.40000000000165,15.001140086557383,1.1663251150052985,-0.017764757038881918
166.60000000000167,15.038593245714452,1.148579707493246,-0.016962688601309228
167.8000000000017,15.076371245866497,1.124726018424873,-0.015136618087437714
169.0000000000017,15.113841062198313,1.1031912736079712,-0.015129626712961919
170.20000000000172,15.15165127097956,1.0818327460924397,-0.015854379489876003
171.40000000000174,15.189258763057945,1.0640690610393824,-0.01645004208200218
172.60000000000176,15.226894302337527,1.047531270756022,-0.01644987392433883
173.80000000000177,15.264106834461918,1.035929916755745,-0.017221266438172567
175.0000000000018,15.301666547411326,1.028674056763578,-0.017429885388744015
176.2000000000018,15.338796518617874,1.023419018306313,-0.017429956034753946
177.40000000000182,15.37641589111624,1.0178995475731996,-0.01742995750397114
178.60000000000184,15.413552574073828,1.0171203135809734,-0.017435077989751413
179.80000000000186,15.450942953397576,1.015959790044914,-0.018748454508756396
181.00000000000188,15.487925241281257,1.0161101662196133,-0.018766215014098364
182.2000000000019,15.525070674415069,1.0175058772730083,-0.017429015643811052
183.4000000000019,15.562434385150935,1.0198268259356125,-0.01742995669463676
184.60000000000193,15.599673628880481,1.0226425084122033,-0.017429956000606595
185.80000000000194,15.636542342771577,1.0279419042173776,-0.017429955998963464
187.00000000000196,15.673517162761096,1.0351728029185583,-0.01742994966328615
188.20000000000198,15.710465686585879,1.037440834627223,-0.017428520596884045
189.400000000002,15.747272762910825,1.0427739548863348,-0.01876760210459949
190.600000000002,15.78411614317764,1.0499338536954794,-0.01907996704342141
191.80000000000203,15.821334569220722,1.0579529446434446,-0.019084829626413224
193.00000000000205,15.85802688115517,1.0643112893514752,-0.02038723005429155
194.20000000000206,15.894651961680927,1.071624088278603,-0.019071190112468273
195.40000000000208,15.931653827321977,1.0806060709819922,-0.019080309504167836
196.6000000000021,15.96849023744132,1.0896026503134977,-0.019942534472371598
197.80000000000211,16.005332676542903,1.0993880943592371,-0.0203900655031215
199.00000000000213,16.04214075220257,1.1081974319496515,-0.018979642575844835
200.20000000000215,16.07857177637061,1.116543589441338,-0.017662568107961185
201.40000000000217,16.11565641243976,1.129075374558446,-0.01766016626206568
202.60000000000218,16.152368979325548,1.1400103672651973,-0.017661373906486588
203.8000000000022,16.18868754831004,1.155909420184893,-0.016363632923709126
205.00000000000222,16.22545519886749,1.1747445543528616,-0.01762424887872882
206.20000000000223,16.2622882462045,1.1925073636859964,-0.017650101275178187
207.40000000000225,16.299113799965053,1.215644024473339,-0.017653597462414794
208.60000000000227,16.335464872429366,1.2411567449372267,-0.018964399807706478
209.80000000000229,16.372265461108785,1.2724091101264967,-0.01998926277628099
211.0000000000023,16.409037713083222,1.3206279469181217,-0.02029032466777103
212.20000000000232,16.445502141593728,1.3840520265329244,-0.02117757645827556
213.40000000000234,16.48225453865176,1.4764947010863287,-0.022922881438725895
214.60000000000235,16.518596119721238,1.600236221140753,-0.02291987520530725
215.80000000000237,16.555261347633078,1.746544972445922,-0.022919868003263844
217.0000000000024,16.592105095193848,1.9197411273202492,-0.022919858286530204
218.2000000000024,16.629023003142475,2.0972235602528198,-0.022909170291509184
219.40000000000242,16.66542548840415,2.2657368742980637,-0.025747087574479632
220.60000000000244,16.7024119538627,2.3902414474101277,-0.02706601473285053
221.80000000000246,16.7392478087387,2.4393000177605373,-0.02473591102849948
223.00000000000247,16.77605621886902,2.3942019668445385,-0.023460098650586847
224.2000000000025,16.813140797510485,2.2567269316908,-0.0234598362488736
225.4000000000025,16.84978721358118,2.0800674560650636,-0.02345983599975998
226.60000000000252,16.886207486086942,1.9106583007519855,-0.02345983600067658
227.80000000000254,16.922490474077684,1.7649824505831622,-0.02345983982956401
229.00000000000256,16.959039715348215,1.6429171603063977,-0.023457309464241405
230.20000000000258,16.99538722529813,1.5466727880796143,-0.024766131130660618
231.4000000000026,17.031013362483638,1.471153347634947,-0.024780114030618527
232.6000000000026,17.067845664324352,1.410776269721107,-0.02478010000540909
233.80000000000263,17.104086693527538,1.3630463014051055,-0.024780100011998485
235.00000000000264,17.140377177486386,1.3258778294134732,-0.02478010306194456
236.20000000000266,17.176423521600977,1.2960144466387922,-0.02475818496414206
237.40000000000268,17.212842877158813,1.2740670072878038,-0.02608942734582609
238.6000000000027,17.249254450238844,1.2563003091601213,-0.026090066111601473
239.8000000000027,17.285238426087982,1.2439485859492294,-0.026090068001088262
241.00000000000273,17.321817408034605,1.2325617336333918,-0.026090068000048205
242.20000000000275,17.357825851541623,1.224633662032502,-0.0260900679290339
243.40000000000276,17.39424997537602,1.217636404467723,-0.026090017832502976
244.60000000000278,17.43045212634724,1.2129291468224412,-0.026283593615989087
245.8000000000028,17.466511136604836,1.2079765733324634,-0.027424653684265277
247.0000000000028,17.503006564731713,1.203971921335704,-0.02872828659066551
248.20000000000283,17.539547754067698,1.2030808967707445,-0.02872993105727728
249.40000000000285,17.575742295008688,1.202286252818838,-0.028729936003127676
250.60000000000286,17.612026936558525,1.2024129577939155,-0.0287299362039386
251.80000000000288,17.648115039996622,1.2033663599874558,-0.02872950489515258
253.0000000000029,17.6844776334061,1.202802569226021,-0.027844461548331534
254.20000000000292,17.719917519122077,1.2045087803598058,-0.02872973834592152
255.40000000000293,17.756840169957172,1.2037270455293354,-0.029799253348866017
256.600000000003,17.79311547290816,1.2060196739934241,-0.030040177265663992
257.80000000000297,17.829517934803622,1.2070250122279864,-0.02995154187054494
259.00000000000296,17.865549658863625,1.206727601416496,-0.02872930487344849
260.200000000003,17.90192838664054,1.2074483719535696,-0.028727012160584486
261.40000000000305,17.93801941425715,1.2098419229216644,-0.029748641829278277
262.60000000000304,17.97441089360338,1.2104856601972496,-0.02972016844780434
263.800000000003,18.01083942645319,1.2110912993227738,-0.02972016813623668
265.00000000000307,18.047231055117162,1.2128291569833762,-0.029720227927806597
266.2000000000031,18.083358230321128,1.2146373797490844,-0.030382394735607665
267.4000000000031,18.119411045039506,1.2160488653597623,-0.031039976993242124
268.6000000000031,18.155952740873918,1.219461407619002,-0.03104003584642756
269.80000000000314,18.19207461831084,1.2211930380078297,-0.03104003563077873
271.0000000000032,18.22837113158487,1.2220744869598412,-0.03103935954031911
272.2000000000032,18.26465363610217,1.225361488870424,-0.032307811929930264
273.40000000000316,18.300484382595105,1.2236543101414101,-0.03230549665170912
274.6000000000032,18.337098963003637,1.2263973229980858,-0.03366606621646806
275.80000000000325,18.373394867527754,1.2274055271679363,-0.03497930111645342
277.00000000000324,18.409477953168537,1.2295461503125646,-0.034979886932492654
278.20000000000323,18.446029479257767,1.2279685386944432,-0.0349798714090519
279.4000000000033,18.482357632246778,1.2314297749872893,-0.034980899680001176
280.6000000000033,18.51855565821474,1.2318741328022527,-0.036319994754869356
281.8000000000033,18.55491684621661,1.2337944856404643,-0.03629802219197664
283.0000000000033,18.59121169587013,1.234470595043918,-0.03765479567109642
284.20000000000334,18.62750798299416,1.237054362584549,-0.036304128593226626
285.4000000000034,18.663616133145542,1.2360418196096856,-0.03630016341781639
286.6000000000034,18.699764772579083,1.239832091934194,-0.03629593790917296
287.80000000000337,18.736475588919955,1.2417859303634,-0.037611354885513926
289.0000000000034,18.772684585609802,1.2420080231994275,-0.03761010370078388
290.20000000000346,18.809223324688713,1.2427169074849576,-0.03761010399421005
291.40000000000344,18.8454066931295,1.2421776457886422,-0.03761010822841504
292.60000000000343,18.88176234072368,1.245958636621757,-0.03761731890745734
293.8000000000035,18.918313496869125,1.2452809208877555,-0.038922809699531324
295.0000000000035,18.95434194793263,1.246565913017024,-0.03892362682561101
296.2000000000035,18.990739000423115,1.244365923235422,-0.04024260508948396
297.4000000000035,19.027145592413245,1.2467251975737041,-0.04176559401892321
298.60000000000355,19.063843452737085,1.248840482489099,-0.04378938509058816
299.8000000000036,19.100000301506512,1.2492339829454322,-0.04495986389811213
301.0000000000036,19.13666105858121,1.2497762997891817,-0.044959864495243806
302.20000000000357,19.17311135973492,1.2513465144459852,-0.04495986499806959
303.4000000000036,19.209069871195943,1.2496040107663386,-0.044971282269319346
304.60000000000366,19.245724757981233,1.2531252336347298,-0.04594859281601105
305.80000000000365,19.282207544285466,1.2506345026723733,-0.04594979156017631
307.00000000000364,19.318556510505616,1.2525840228654548,-0.045953947308548404
308.2000000000037,19.355135693192107,1.2530949635767343,-0.04464080754251709
309.40000000000373,19.391401834713903,1.2532972164420264,-0.04463979245911043
310.6000000000037,19.427591374450444,1.2544571026883955,-0.04561994993858409
311.8000000000037,19.46399596997024,1.2542128841550864,-0.046613378399122496
313.00000000000375,19.500888221727926,1.255780964759883,-0.047600168312837976
314.2000000000038,19.536805221110544,1.2579236274443542,-0.04760002061087443
315.4000000000038,19.573330308393828,1.2578828527064148,-0.047600001239212375
316.6000000000038,19.6102831294131,1.2588498352186195,-0.04891220698049725
317.8000000000038,19.646546974577078,1.2606726909193982,-0.05022411884907152
319.00000000000387,19.6831107430355,1.2619642179374269,-0.05022978993051197
320.20000000000385,19.719660451674095,1.2693384029376757,-0.05022433826696604
321.40000000000384,19.756088644632776,1.2710650517081132,-0.05154278043316518
322.6000000000039,19.79280880046733,1.2737855513673122,-0.05283292099405301
323.80000000000393,19.829270739381972,1.278527112396413,-0.052858911910857564
325.0000000000039,19.86577892463174,1.2834160889834136,-0.05416194322832446
326.2000000000039,19.90221581317237,1.2903568091325015,-0.05510964796007567
327.40000000000396,19.938648911159078,1.2936666272872182,-0.05598026300402337
328.600000000004,19.975471127004734,1.3043518836658168,-0.05694875566581459
329.800000000004,20.012059279678525,1.3101948454509664,-0.05936338802159247
331.000000000004,20.04842855169725,1.3179236903029379,-0.06149790593446758
332.200000000004,20.085142350601725,1.3273542630740445,-0.0629904572434663
333.40000000000407,20.121694847691295,1.3348873548246067,-0.06497027995605409
334.60000000000406,20.15808414952657,1.3451138191138148,-0.06646210339663794
335.80000000000405,20.19485743912775,1.355489054042208,-0.06794077005191435
337.0000000000041,20.231480136314797,1.3670233686254136,-0.06996167486950045
338.20000000000414,20.26827602766526,1.3764220255202286,-0.07302330464551288
339.4000000000041,20.304688965286463,1.3865663165422057,-0.07516221766807218
340.6000000000041,20.34146015398521,1.3975585920829576,-0.07686748231372897
341.80000000000416,20.37839721448907,1.409347846183617,-0.0792226709536501
343.0000000000042,20.41508293693142,1.419126960478806,-0.08169362277753978
344.2000000000042,20.452019796173577,1.434127700369633,-0.08566816580731418
345.4000000000042,20.48869022423202,1.44808723748867,-0.0892412977902084
346.60000000000423,20.52537972067722,1.4587183309522747,-0.0913921924249892
347.8000000000043,20.562114271437878,1.4724862727355021,-0.09462821421267176
349.00000000000426,20.598734420056864,1.486902636623623,-0.09834295898781953
350.20000000000425,20.63573216810646,1.5029834050285784,-0.10179410594956995
351.4000000000043,20.67224689822133,1.5205068683500853,-0.10610178933072589
352.60000000000434,20.70922834677968,1.5346700244958622,-0.11234860052194362
353.80000000000433,20.74604156231745,1.551678767402253,-0.11663972881317175
355.0000000000043,20.782654675178335,1.5703402446626473,-0.1203092280252136
356.20000000000437,20.81962387975672,1.586772067605835,-0.12543004865546648
357.4000000000044,20.85651565014294,1.6073205457406345,-0.12944299157318273
358.6000000000044,20.89324028597116,1.626032389527198,-0.13523146615094017
359.8000000000044,20.93040578666366,1.6465264661879484,-0.14067373952743623
361.00000000000443,20.96722112896646,1.6687215553224988,-0.14642229428986253
362.2000000000045,21.004128413621462,1.6947424336148293,-0.15252561902984718
363.40000000000447,21.040928374315403,1.7143547892700632,-0.15770879085170764
364.60000000000446,21.077937936813985,1.739604357109548,-0.16472465738230158
365.8000000000045,21.114756034597345,1.7628775638433867,-0.17244721304189436
367.00000000000455,21.151783713400146,1.788089283464212,-0.18061042863327215
368.20000000000454,21.188865045277595,1.816047643310715,-0.1889089585573731
369.4000000000045,21.225843477176326,1.8420877799860769,-0.1960074035211603
370.60000000000457,21.26286433030575,1.871413971845568,-0.20556936266548842
371.8000000000046,21.29977572450526,1.8992765840647663,-0.2159150921823545
373.0000000000046,21.336906035402745,1.925998284312742,-0.22452213746698213
374.2000000000046,21.373611149636545,1.9570293834452244,-0.2339320907343745
375.40000000000464,21.41106711411464,1.984068377138782,-0.24451729284483603
376.6000000000047,21.448189299178836,2.015569925243235,-0.25499267281712035
377.8000000000047,21.485534309815435,2.044563391817019,-0.2661951941098968
379.00000000000466,21.52239336334245,2.0756578697539925,-0.2761962224170267
380.2000000000047,21.559506863363904,2.106179450213607,-0.2879682845085574
381.40000000000475,21.59687458239992,2.1390287896762237,-0.3011535900221567
382.60000000000474,21.63390892285533,2.1696083203983276,-0.31399466618133953
383.80000000000473,21.671461766343473,2.2030847657277137,-0.32788594846012353
385.0000000000048,21.708338190709004,2.2404538268975687,-0.3408207293987058
386.2000000000048,21.74572812633861,2.274024363174755,-0.3541453273381454
387.4000000000048,21.782924788892522,2.310088458423163,-0.3692675051156753
388.6000000000048,21.81977870040869,2.347361480908244,-0.38551652016530635
389.80000000000484,21.85738577825541,2.3852929236911686,-0.4011422389279984
391.0000000000049,21.894414903697847,2.4260888964254725,-0.41685189527690936
392.2000000000049,21.9318059056012,2.4679645064293765,-0.433881121230558
393.40000000000487,21.96913211946829,2.51387288722329,-0.45163553133441736
394.6000000000049,22.00648370686269,2.555643537527059,-0.46870570286990354
395.80000000000496,22.043842715796305,2.60123587412901,-0.48770771885720965
397.00000000000495,22.081129856821597,2.64734699059888,-0.5077310179015013
398.20000000000493,22.117736527065688,2.6920015320625956,-0.5277852246296124
399.400000000005,22.1559053360477,2.7405718641872134,-0.5492700528231778
400.600000000005,22.193041436332205,2.793437439694208,-0.5712809756135235
401.800000000005,22.23080989733579,2.8416964642020117,-0.5945889840062284
403.000000000005,22.268260874979273,2.8922190463382123,-0.6191738967798295
404.20000000000505,22.305703571644912,2.9429786059672547,-0.644315643562873
405.4000000000051,22.343143368530917,2.9963366849393283,-0.6695597505908712
406.6000000000051,22.380698785830393,3.0474312084197988,-0.6965736855301761
407.80000000000507,22.417859402352722,3.0958054000941093,-0.725123475311702
409.0000000000051,22.45556201144315,3.146129639087366,-0.7539081255903737
410.20000000000516,22.492939066231084,3.1949763934299527,-0.7825353075491632
411.40000000000515,22.530778195968168,3.2412805197263435,-0.8128881154676018
412.60000000000514,22.568564426611225,3.2880470447410675,-0.8458925849188503
413.8000000000052,22.605783377954463,3.329396117950182,-0.8792755565565882
415.00000000000523,22.6435364801324,3.371590444052652,-0.9147990523698546
416.2000000000052,22.681049237967986,3.4141420030775746,-0.9516806259850106
417.4000000000052,22.71852774684802,3.44672542633107,-0.9880505392004317
418.60000000000525,22.75623046270833,3.4725073067864867,-1.027104855807802
419.8000000000053,22.793991371037883,3.4971277809641865,-1.067937222978049
421.0000000000053,22.83157255713421,3.513135112019933,-1.1081785876370605
422.2000000000053,22.86909256162242,3.524967381183358,-1.148724819293336
423.4000000000053,22.906328665414286,3.5258235045931614,-1.1899310243651202
424.60000000000537,22.944279185995867,3.518821078082092,-1.2324480618642601
425.80000000000535,22.982030382469038,3.500207486592506,-1.2755558480154523
427.00000000000534,23.019558998178965,3.4725756755705666,-1.3198734760160469
428.2000000000054,23.05768031758408,3.4282825892783766,-1.3634324607299462
429.40000000000543,23.09485913543421,3.3770818007718684,-1.406235658318582
430.6000000000054,23.132602911163488,3.3073001649915823,-1.4495474526282557
431.8000000000054,23.169939489224298,3.2232374998133335,-1.491658100734035
433.00000000000546,23.207925271169767,3.12432317853158,-1.5347377865876863
434.2000000000055,23.245338841597224,3.012218014661082,-1.5754652801093671
435.4000000000055,23.282529063642922,2.881943272327618,-1.6150799238111238
436.6000000000055,23.31966783758795,2.739165035679696,-1.6529799095260884
437.8000000000055,23.35822399895423,2.577661855348701,-1.6892506145533703
439.00000000000557,23.395655330343185,2.412824470420534,-1.7224740153511116
440.20000000000556,23.433174563562833,2.2429309360161267,-1.7526612485814246
441.40000000000555,23.47073489981927,2.0714550518123556,-1.7804804393650553
442.6000000000056,23.50787962896312,1.909410027878651,-1.8035698389171793
443.80000000000564,23.545489769692743,1.7521785619088168,-1.825847957147857
445.0000000000056,23.582956855070726,1.6102662290740473,-1.8458076382840263
446.2000000000056,23.620151286838144,1.488392857110571,-1.8627534016686358
447.40000000000566,23.65741704448702,1.3802649986684647,-1.8769876939960595
448.6000000000057,23.69523549607967,1.2902045864448746,-1.890989858971802
449.8000000000057,23.732705620722438,1.2160672714960818,-1.9046092898474178
451.0000000000057,23.770125111379997,1.1536520797968506,-1.9153624479794766
452.20000000000573,23.807937290221798,1.1011912841061815,-1.9278220788461473
453.4000000000058,23.845425013692076,1.0647724202284479,-1.9382638089498747
454.60000000000576,23.883062966811494,1.027593235883278,-1.9478781635233453
455.80000000000575,23.920902160688353,0.9980771347712172,-1.958478319692099
457.0000000000058,23.95845576560129,0.9786674926914347,-1.9680530810176682
458.20000000000584,23.996295401804698,0.9616960262791987,-1.977382348464107
459.40000000000583,24.033894639016157,0.9450550148128181,-1.986762473158817
460.6000000000058,24.071797094788963,0.9327364938936886,-1.9957182733337533
461.80000000000587,24.109452946762662,0.9245777102768544,-2.004311063625509
463.0000000000059,24.147429365675453,0.9162883922863625,-2.0136857065133453
464.2000000000059,24.185268468925944,0.9144506774328274,-2.022199856204474
465.4000000000059,24.223309297052946,0.9047185062124479,-2.030765426184635
466.60000000000593,24.261261493910474,0.9031477508731078,-2.040019023665624
467.800000000006,24.299068856806805,0.9004226128006567,-2.048501791979418
469.00000000000597,24.33695025760147,0.899644686658988,-2.0570836623662623
470.20000000000596,24.375132264264685,0.8967849306135329,-2.0662512815332787
471.400000000006,24.412960961146315,0.8970101165907067,-2.0744965522604044
472.60000000000605,24.45132100873524,0.8940508649711438,-2.0839080550207294
473.80000000000604,24.489345938841055,0.8929879298210031,-2.0955639416180474
475.000000000006,24.52740856591704,0.891990089165634,-2.103249573722982
476.20000000000607,24.565281697290484,0.8905450024423416,-2.113784769324397
477.4000000000061,24.603421162243052,0.8882561121019015,-2.1228877292509156
478.6000000000061,24.641582015005465,0.8861020673226754,-2.1312660745352243
479.8000000000061,24.679872966074136,0.8841743434107945,-2.139940499488863
481.00000000000614,24.717764999214264,0.8820220391706415,-2.1495455157895123
482.2000000000062,24.75601644732258,0.8804378836384261,-2.15959421924696
483.4000000000062,24.794388364273633,0.8775001070079291,-2.169853785752143
484.60000000000616,24.832508431497907,0.8740182892086139,-2.178721762125304
485.8000000000062,24.870607933242926,0.8698418546263769,-2.188173985436943
487.00000000000625,24.909207260285356,0.8654167735792797,-2.1980710876034184
488.20000000000624,24.947430267699122,0.8576132180574476,-2.2064625391938097
489.40000000000623,24.985803774571874,0.854739199076604,-2.2192758172085303
490.6000000000063,25.023875719628997,0.8433592431669323,-2.231011132269209
491.8000000000063,25.062144686957495,0.8369768949644301,-2.2412725395106694
493.0000000000063,25.10031451690232,0.8254123420791994,-2.2506122952469494
494.2000000000063,25.138839824766166,0.8135368122155264,-2.2610793985567286
495.40000000000634,25.17721667731231,0.8015368495837258,-2.270325150179647
496.6000000000064,25.215356240428072,0.7834142747932642,-2.2798924540242913
497.8000000000064,25.253788780823548,0.7622133276865963,-2.2892551770178393
499.00000000000637,25.29232356108928,0.7370667174451542,-2.298886122596328
500.2000000000064,25.330694966801353,0.7082204772046776,-2.3077935555428515
501.40000000000646,25.3684668768237,0.675036024226968,-2.3165284816155753
502.60000000000645,25.40749490055296,0.6359332539404037,-2.3252894366634247
503.80000000000643,25.44543684194828,0.593847118107125,-2.3322832105193396
505.0000000000065,25.484146767288106,0.5502655554793516,-2.339055488493673
506.2000000000065,25.52235236318747,0.5086172476588595,-2.344516918271589
507.4000000000065,25.560983269099708,0.4707567694853261,-2.34882663107798
508.6000000000065,25.599271203041415,0.4336976794904772,-2.351031436719607
509.80000000000655,25.63789181695729,0.39882112504531064,-2.3545527665945363
511.0000000000066,25.67639868445571,0.37114085543736897,-2.3562758663627315
512.2000000000066,25.714919398372455,0.3441986726404769,-2.3575075733408264
513.4000000000066,25.753460899738027,0.32379436224369895,-2.35864769522027
514.6000000000066,25.7920038010311,0.308374077882581,-2.359114173493167
515.8000000000067,25.82949330933433,0.295322184312641,-2.3591200026908057
517.0000000000066,25.868982728379187,0.28567376986615134,-2.359119880729729
518.2000000000066,25.907031178934314,0.27857273194664756,-2.361101176853478
519.4000000000067,25.946054653778177,0.27261578662131924,-2.3617503868308676
520.6000000000067,25.984772364767565,0.2659502198870547,-2.363098703870169
521.8000000000068,26.023613939620198,0.2606022470554197,-2.363070157275569
523.0000000000067,26.061959614358525,0.2595111649107993,-2.3630701400060805
524.2000000000068,26.100557409608463,0.2581805840091751,-2.363070140000028
525.4000000000068,26.13844834228834,0.25778381633089187,-2.3630701398986824
526.6000000000067,26.177892283353376,0.2510752643356018,-2.3630698195749513
527.8000000000068,26.216786848004336,0.2563687464910154,-2.363964163422644
529.0000000000068,26.2551046268392,0.26461387536180014,-2.3640502162590087
530.2000000000069,26.293746913018296,0.27034528486648624,-2.364376747012968
531.4000000000069,26.332458418753106,0.2784080520578016,-2.364380132816572
532.6000000000068,26.370786919829474,0.28483064535026337,-2.36453567043354
533.8000000000069,26.40933456926542,0.29134660761992115,-2.365699628355686
535.0000000000069,26.44831083360335,0.301061505796256,-2.3656999758704575
536.2000000000069,26.4869693862989,0.30010968386347026,-2.365699968743443
537.4000000000069,26.525872123404234,0.30622279820679776,-2.365962210104989
538.600000000007,26.564440409015166,0.30383183654046797,-2.3666587591708317
539.800000000007,26.60305284958335,0.30265677357167453,-2.3670200121827714
541.000000000007,26.642045959280146,0.29401265878710303,-2.367019857402309
542.200000000007,26.680894090459848,0.2858976289189361,-2.3670356794214453
543.400000000007,26.719765452476114,0.2793551169411823,-2.368321518527827
544.6000000000071,26.758718806351617,0.27481935005152436,-2.36965045042321
545.800000000007,26.797041440474732,0.27315267773038343,-2.369649812345445
547.000000000007,26.83623224566924,0.2686328928404962,-2.3696495802691535
548.2000000000071,26.875376557869036,0.2653786127893336,-2.3723676705649357
549.4000000000071,26.91403706204601,0.2651693616775652,-2.3722899404453908
550.6000000000072,26.952826586913954,0.2618078201577734,-2.3712807721401727
551.8000000000071,26.991699555429665,0.2622425078669377,-2.370032656749419
553.0000000000072,27.03072117173052,0.25716189964390423,-2.368809369721741
554.2000000000072,27.069460189622454,0.25093276893833316,-2.3683411112464006
555.4000000000071,27.108771310341375,0.24771856591901487,-2.368626861572305
556.6000000000072,27.147101756169505,0.24569741465687955,-2.3683300468405504
557.8000000000072,27.186537161089156,0.24045586745487713,-2.368797390774654
559.0000000000073,27.225591344032075,0.23503742994787324,-2.3696496676339898
560.2000000000073,27.264404616501604,0.22781111905504425,-2.370966559100375
561.4000000000073,27.30338790914871,0.22652786310614048,-2.3709600549856926
562.6000000000073,27.342345390654405,0.22244422167568145,-2.3709697398687473
563.8000000000073,27.38159532318701,0.22140619702525766,-2.372302441636794
565.0000000000073,27.420494683526897,0.22481592796175498,-2.373626971955746
566.2000000000073,27.459506351395202,0.21716568541614611,-2.3735999216286707
567.4000000000074,27.497739804498504,0.2155050859654657,-2.373599798101795
568.6000000000074,27.537499174288577,0.21236435005743637,-2.3743488723577713
569.8000000000075,27.576476676871003,0.20813796204207846,-2.37491760538076
571.0000000000074,27.615643617938083,0.21125257408188003,-2.373602540758732
572.2000000000074,27.65442462050782,0.2131696839513415,-2.373600177329487
573.4000000000075,27.693876805304264,0.2105899335257666,-2.373600176000715
574.6000000000074,27.732712963917884,0.20972458335269306,-2.3736001757377956
575.8000000000075,27.772097280336983,0.20864118407168708,-2.3735990858044236
577.0000000000075,27.81092959520851,0.20741593406736336,-2.374858791893473
578.2000000000075,27.8503419873861,0.2050707595641501,-2.373930145314723
579.4000000000076,27.889245021691387,0.20956125729060449,-2.3739289580500627
580.6000000000075,27.92849479328128,0.20711154105428542,-2.375269408940513
581.8000000000076,27.967633833200484,0.20952707284921535,-2.3762407027638717
583.0000000000076,28.006933526593727,0.20904509829025342,-2.376230017377593
584.2000000000075,28.045870662193206,0.2072667843716023,-2.376227655898138
585.4000000000076,28.085274720547165,0.21214882572908733,-2.3775446869504657
586.6000000000076,28.12430214743687,0.21032336813354013,-2.377549876757863
587.8000000000077,28.163689435899784,0.21006595031617836,-2.3775498799986163
589.0000000000077,28.202639297001543,0.21195040542395782,-2.377549880108172
590.2000000000077,28.24223107580701,0.21172438410005157,-2.377550109910755
591.4000000000077,28.281155079943314,0.2140396773492308,-2.378620757843262
592.6000000000078,28.320713423225097,0.21537531025568657,-2.3788600150784305
593.8000000000077,28.360064308783784,0.2182547190198778,-2.3785034367191704
595.0000000000077,28.3994177177679,0.21637267122769654,-2.3788121224621595
596.2000000000078,28.438649198400547,0.2181646360796432,-2.3798500036493566
597.4000000000078,28.477915595855507,0.22034447637386712,-2.380069702724422
598.6000000000079,28.517206927132978,0.22257596071207542,-2.3824795788515574
599.8000000000078,28.556797094582524,0.22406660155470348,-2.382480079980452
601.0000000000078,28.5959321842025,0.2239790306035061,-2.382480165659239
602.2000000000079,28.63551455277126,0.22506818370527215,-2.3812333845709817
603.4000000000078,28.674087726272685,0.22930869044315605,-2.382211156420089
604.6000000000079,28.71402291136185,0.23010973150563485,-2.3824788026638624
605.8000000000079,28.753816594160572,0.2309459841438155,-2.3814854963293968
607.000000000008,28.792945075056878,0.23481205884918355,-2.3828138836178443
608.200000000008,28.832403370773367,0.2360395075354944,-2.3828198104398757
609.4000000000079,28.87182678802401,0.23837888344607894,-2.3828198191484264
610.600000000008,28.91120447946949,0.23903469301850944,-2.3828295181264987
611.800000000008,28.950720975065515,0.24018372227804718,-2.383434026181461
613.000000000008,28.990267432426588,0.2416366852037095,-2.3854411223357945
614.200000000008,29.029553095786305,0.24715377415482176,-2.385439122570344
615.400000000008,29.06911173624648,0.24876399264402305,-2.3867782316603354
616.6000000000081,29.108530846873897,0.24903367027305356,-2.3867600539090277
617.8000000000081,29.147986885717284,0.25158739836069244,-2.3867599409992026
619.0000000000081,29.187659315234935,0.2561341850034462,-2.387541824075863
620.2000000000081,29.226904190613364,0.2571896402608653,-2.388080212183476
621.4000000000082,29.266422239233506,0.2599925055032546,-2.3893912745297996
622.6000000000081,29.305861864497135,0.26149489590251496,-2.3893898860254414
623.8000000000081,29.345193227391647,0.2635183401637131,-2.389390724627943
625.0000000000082,29.384947700467542,0.2666233295160507,-2.3907378178884415
626.2000000000082,29.424308407557653,0.268226569067084,-2.3907101565946496
627.4000000000083,29.46399046961737,0.2728580908914371,-2.390695011548944
628.6000000000082,29.503190348224376,0.27378762076832586,-2.392020999525031
629.8000000000083,29.542722141292128,0.27589873043589774,-2.3930208619888056
631.0000000000083,29.582310572736024,0.28332689006072376,-2.3932997467482364
632.2000000000082,29.62160890198008,0.2852907150822779,-2.394658187723871
633.4000000000083,29.661618404522724,0.2877300011063759,-2.397093654973577
634.6000000000083,29.700980042244392,0.2951529110576332,-2.397259275964256
635.8000000000084,29.740736772710108,0.2977284102970821,-2.397286783457444
637.0000000000084,29.780256663349327,0.3057457938014254,-2.3972900815258193
638.2000000000083,29.819679372820893,0.31107552319836485,-2.397294056275678
639.4000000000084,29.85923948742289,0.32139226932131026,-2.398610746209876
640.6000000000084,29.899238862286456,0.3318994612240054,-2.399162374280412
641.8000000000084,29.93829990537771,0.34268771927191155,-2.400565890218452
643.0000000000084,29.977405529968316,0.35242752256909693,-2.4019013330979897
644.2000000000085,30.017841901320672,0.36777037590789696,-2.4020735979250576
645.4000000000085,30.057120222318556,0.38058208401203,-2.403210803268249
646.6000000000085,30.097085944551786,0.3915188397994771,-2.4045788917337445
647.8000000000085,30.136696854858908,0.4055208059442117,-2.404542809982096
649.0000000000085,30.176270335754765,0.42267787177830396,-2.4045403003278167
650.2000000000086,30.215988590335986,0.43583558691740465,-2.405945387974087
651.4000000000085,30.255824802708304,0.4521340680827839,-2.4073594318198275
652.6000000000085,30.295333476888842,0.47343262395519425,-2.4064833318461036
653.8000000000086,30.33527695827657,0.4925984647783035,-2.4073986195000154
655.0000000000086,30.375013862242714,0.5086305654486789,-2.4078642931908916
656.2000000000087,30.414685128343844,0.5292067277513663,-2.408895000641169
657.4000000000086,30.454233668416393,0.5488370033671472,-2.411384940694391
658.6000000000087,30.49414777733443,0.5770545216236971,-2.413651883486901
659.8000000000087,30.533874699264572,0.6001728974490423,-2.415951855554818
661.0000000000086,30.5737592263252,0.6239387188608478,-2.4173653795073466
662.2000000000087,30.613196438607382,0.6491457439390165,-2.4188991455875306
663.4000000000087,30.65336415522924,0.6753461732624564,-2.420220018654387
664.6000000000088,30.692964432092932,0.7079600827773931,-2.421741881907578
665.8000000000088,30.73263571763942,0.7361912999289182,-2.4240557981933644
667.0000000000088,30.772286617643125,0.767661365149729,-2.4267131253615224
668.2000000000088,30.812266848675556,0.8000609199112458,-2.428262894251856
669.4000000000088,30.85178595079127,0.8330788195798358,-2.4299683616161767
670.6000000000088,30.891804870735207,0.8658161910329931,-2.432125059273628
671.8000000000088,30.931312916712795,0.9024877491606262,-2.43425767217056
673.0000000000089,30.97123739024563,0.9387507788496521,-2.434858706532452
674.2000000000089,31.011011871074114,0.9761585082759034,-2.437844029765798
675.400000000009,31.050666628256216,1.0084409062151498,-2.4409965454318674
676.6000000000089,31.09010445727508,1.0480311528627384,-2.4437895019794604
677.8000000000089,31.12999246533999,1.0849279898539532,-2.446717653039567
679.000000000009,31.170322181130576,1.1219169422796436,-2.451214265410097
680.2000000000089,31.209511697306798,1.1614063484887558,-2.4540055699579457
681.400000000009,31.249572446428207,1.2028806075974718,-2.4562038253780747
682.600000000009,31.289214311564827,1.2408228140996698,-2.4597726162008913
683.800000000009,31.328783863909425,1.2821189693008241,-2.4617330822307726
685.0000000000091,31.36853789344474,1.3218705402738913,-2.464565579677388
686.200000000009,31.40859524315831,1.3641091182065719,-2.4671616163008796
687.4000000000091,31.448407306627335,1.4043178884662069,-2.470237453572928
688.6000000000091,31.487915124552703,1.4463742399755877,-2.4740447434371786
689.800000000009,31.527805040160008,1.48558018742783,-2.4776524094527996
691.0000000000091,31.567582212742877,1.525088350913036,-2.482029850530167
692.2000000000091,31.607404290237934,1.564072981769724,-2.486629913617966
693.4000000000092,31.647307148971063,1.601982934827821,-2.4897380613170323
694.6000000000092,31.686957094077414,1.6411724435922652,-2.4927794516679436
695.8000000000092,31.72683184465176,1.683770796908964,-2.497574739576508
697.0000000000092,31.766862937564984,1.7228740719942641,-2.501969326055089
698.2000000000093,31.806669659333295,1.766748536814028,-2.5063198468066092
699.4000000000092,31.84630392010318,1.806331648094638,-2.511449124946645
700.6000000000092,31.886247183239156,1.8498201278453676,-2.516478667263503
701.8000000000093,31.92607088753865,1.8891858569907323,-2.520843732939552
703.0000000000093,31.965931988754956,1.9296855623953302,-2.524948854872986
704.2000000000094,32.005817399568244,1.9716644066399862,-2.5291423229114836
705.4000000000093,32.04561455051076,2.0148692504594923,-2.533428353022144
706.6000000000093,32.0856197293187,2.0570053848383187,-2.5390007541654604
707.8000000000094,32.12567985462564,2.0952828226941413,-2.546697805287409
709.0000000000093,32.165600162482455,2.1386345395212176,-2.55187075497179
710.2000000000094,32.205554996579764,2.1780028942960667,-2.5578207068063477
711.4000000000094,32.24541704202672,2.219690371413324,-2.5630550424269027
712.6000000000095,32.28516837374842,2.257892627325452,-2.568760843159891
713.8000000000095,32.325320487870925,2.3008427722014675,-2.574320665739894
715.0000000000094,32.36541868250344,2.345749667740016,-2.578146383536886
716.2000000000095,32.4054543948233,2.3866756158140547,-2.5849417159614476
717.4000000000095,32.445278825256764,2.427814672862236,-2.5906914136900543
718.6000000000095,32.485296078687426,2.4747342451686736,-2.5966354639950113
719.8000000000095,32.5253507870551,2.5163247783969425,-2.603448557272209
721.0000000000095,32.56518668699377,2.563305816726977,-2.6096276601628388
722.2000000000096,32.605536378194344,2.614727356932131,-2.6165635447723123
723.4000000000096,32.64568461224894,2.6763180677694796,-2.623058178986929
724.6000000000096,32.685452367265874,2.7359433115813614,-2.6298695346482455
725.8000000000096,32.72566345116771,2.8093570313044083,-2.63695929539018
727.0000000000097,32.765744005129775,2.8912346741212955,-2.644116607090141
728.2000000000096,32.80555839351356,2.978222957854147,-2.6514192490606057
729.4000000000096,32.846064970323084,3.0703044290376074,-2.657519416890913
730.6000000000097,32.885863324578565,3.16903804197595,-2.665161595434423
731.8000000000097,32.926159077003085,3.277708440464205,-2.673187147098744
733.0000000000098,32.96629588392934,3.384990891468526,-2.6816990227413537
734.2000000000097,33.00635087291206,3.5044504291652334,-2.6908525248618456
735.4000000000098,33.046604352642596,3.614394914992708,-2.6979292836299162
736.6000000000098,33.08676953656439,3.7278916999227896,-2.707620232829957
737.8000000000097,33.12687128677446,3.8371158075244107,-2.7159781344281217
739.0000000000098,33.167324877832066,3.9446486313492444,-2.7251989425783565
740.2000000000098,33.2076028818244,4.0549911278556285,-2.7353671752931468
741.4000000000099,33.24767517080536,4.157389377817964,-2.745899664013657
742.6000000000099,33.288039624417884,4.258856795374161,-2.756014924871855
743.8000000000098,33.3283030019637,4.3592294228814925,-2.767383502257887
745.0000000000099,33.368619358546226,4.448521535196524,-2.7784990719368023
746.2000000000099,33.40912670490744,4.540369899578043,-2.7901100401143233
747.4000000000099,33.44934082885646,4.626227901935663,-2.8013599868088015
748.6000000000099,33.489706618519676,4.706596643652421,-2.8141054364569946
749.80000000001,33.5301773013818,4.778590916025585,-2.8267516569942384
751.00000000001,33.57032556869226,4.838384515808514,-2.8397631530530303
752.20000000001,33.61047909810207,4.895689596166417,-2.8521287916155855
753.40000000001,33.650948306483535,4.938184085111187,-2.8664325655526457
754.60000000001,33.69135358627753,4.9684263896409355,-2.878890669151316
755.8000000000101,33.73143306077893,4.979597023667509,-2.890490235212087
757.00000000001,33.77188956088449,4.975038873028527,-2.9033101926367237
758.20000000001,33.81215273369543,4.9519541528413775,-2.9164074462795155
759.4000000000101,33.852118251179945,4.891019717266522,-2.928442723219346
760.6000000000101,33.892467854725254,4.798829333581668,-2.9408548534567376
761.8000000000102,33.93278410532542,4.658072225756387,-2.953327704679041
763.0000000000101,33.97300120957207,4.455147500304752,-2.9647149341152144
764.2000000000102,34.013158915562315,4.1699521458404325,-2.975514353018906
765.4000000000102,34.05332930799985,3.772192140912208,-2.986090187543394
766.6000000000101,34.093431137268084,3.198647159976138,-2.9945618061832717
767.8000000000102,34.13322927745127,2.2876736144001772,-3.002866847694793
769.0000000000102,34.17309544139087,1.433369522520242,-3.0079236958154167
770.2000000000103,34.212822723300434,0.902721375995605,-3.0106048888047345
771.4000000000103,34.25254677705477,0.5876426861394783,-3.0111000167950133
772.6000000000103,34.29304099773873,0.38581979113714615,-3.0110999447490174
773.8000000000103,34.332868233692885,0.26624201349130994,-3.011192605137565
775.0000000000103,34.3729498155043,0.19220593205882608,-3.012089854826088
776.2000000000103,34.41308764923592,0.13616726510515953,-3.012089883706188
777.4000000000103,34.4535560328929,0.10287745495982481,-3.011424920715647
778.6000000000104,34.49366798212135,0.07580405991659545,-3.0114312647728907
779.8000000000104,34.53396618122075,0.06173472820915782,-3.0101018441530383
781.0000000000105,34.574261916548714,0.049127831088926044,-3.009454702621495
782.2000000000104,34.61479322905202,0.03426676181078259,-3.0108368015833067
783.4000000000104,34.654892996491185,0.027267977241719255,-3.0125673060436697
784.6000000000105,34.69528460724167,0.017971784474136943,-3.0125230354359616
785.8000000000104,34.735700652416426,0.010118478043745771,-3.0138343824294225
787.0000000000105,34.77614516006303,0.008178801039544936,-3.013840043533374
788.2000000000105,34.81640495002216,0.007034452605753305,-3.0138444642228532
789.4000000000106,34.856451643480774,0.0030956636264298787,-3.014833768623442
790.6000000000106,34.89708093752394,-0.0022721425775169557,-3.0148300453447545
791.8000000000105,34.937212064707055,-0.002429759058088621,-3.0148300440004894
793.0000000000106,34.97758016143541,-0.004241688446647185,-3.014830044