File: 01_Data/Corrugated_Cardboard/STA/N2/30K_min/Corrugated_Cardboard_STA_N2_30KData_230922_R3.csv
##Temp./Â°C,Time/min,DSC/(mW/mg),Mass loss/mg
41.0,10.550414357626128,0.04286597059106345,-0.034095640648922565
42.100000000000016,10.74652505869371,0.09633646346253055,-0.03547629169630051
43.20000000000003,10.872650325788724,0.14286732603972618,-0.03742259056758046
44.30000000000005,10.969214151136041,0.1800152209361734,-0.03907882631599913
45.40000000000006,11.053255458579326,0.21892050599713198,-0.037025802447505196
46.50000000000008,11.12745525577678,0.24887583093389098,-0.038740652400162556
47.600000000000094,11.195839000316715,0.2801195115282338,-0.0376110223137176
48.70000000000011,11.259351760533686,0.3086403667726356,-0.03957527004902506
49.800000000000125,11.3188212208605,0.3331389266306457,-0.039449217668789505
50.90000000000014,11.375814422723218,0.3576509237915584,-0.03995818441060095
52.000000000000156,11.42985588679378,0.38424566292256634,-0.03995116984484204
53.10000000000017,11.482178698255627,0.407876768085796,-0.041031136808798774
54.20000000000019,11.532970193091343,0.4278138153663511,-0.041200128633057
55.3000000000002,11.580949418964027,0.4497513229519894,-0.04087164649599195
56.40000000000022,11.62962603120437,0.4711207186382911,-0.04006999679375056
57.500000000000234,11.676308387206594,0.49397852199050307,-0.041075073251968686
58.60000000000025,11.72221020809462,0.5119236544162626,-0.04171832341879522
59.700000000000266,11.76717665467293,0.5328066617711571,-0.042334163386212875
60.80000000000028,11.811644650235397,0.5489385079624469,-0.04344599854075737
61.9000000000003,11.854766013064014,0.5675814999542641,-0.041929076176277835
63.00000000000031,11.898041666775779,0.586517897822078,-0.04202754078802462
64.10000000000034,11.940829008331503,0.6047241366299128,-0.04279463420961305
65.20000000000034,11.982599390592114,0.6232078249578363,-0.04462251954118779
66.30000000000035,12.024033746342358,0.6393132462625593,-0.04691328305705911
67.40000000000038,12.065085781604111,0.6550517348889882,-0.0461446249779911
68.5000000000004,12.106322258290987,0.6740986284988899,-0.045578321010631306
69.6000000000004,12.14722362996318,0.6915408348352805,-0.047734401774220725
70.70000000000041,12.187295394080715,0.7084321527427067,-0.04932204011092001
71.80000000000044,12.227570147062057,0.7252396388506339,-0.0506129054036486
72.90000000000046,12.267720059048118,0.7419858712165353,-0.051820362723789426
74.00000000000047,12.306656438962104,0.7594424178724046,-0.05200375783414657
75.10000000000048,12.346963735976791,0.7773987414526047,-0.05334664632563202
76.2000000000005,12.386726005881265,0.7920881171149194,-0.05441022057947542
77.30000000000052,12.426064393418367,0.8076829819802014,-0.054860535722998094
78.40000000000053,12.464927749067767,0.8220200238003048,-0.05640335127338503
79.50000000000054,12.503627694019611,0.8402799130360683,-0.056334181501700886
80.60000000000056,12.542949797943782,0.855844027695563,-0.05633664670764693
81.70000000000059,12.581274991415633,0.8701258702949921,-0.056215363885197434
82.8000000000006,12.620070000099881,0.8824246227954158,-0.05631825064399498
83.9000000000006,12.658240912918172,0.8973015768484209,-0.056488959101105074
85.00000000000063,12.696428597527621,0.910371213679847,-0.05631863299728668
86.10000000000065,12.734553673209309,0.9226621363282066,-0.05748368651529612
87.20000000000066,12.772799065787154,0.9344074981470671,-0.06042640927896503
88.30000000000067,12.810104324398903,0.9460702109445704,-0.06046676220282565
89.40000000000069,12.848258600629519,0.9563128928575739,-0.061814696531130586
90.50000000000071,12.885243537765342,0.9649465136096402,-0.06443127600491083
91.60000000000072,12.923021612112757,0.9737204082136037,-0.06436852170433127
92.70000000000073,12.960357190224071,0.9812329617750462,-0.06707596670909721
93.80000000000075,12.997565338527101,0.9873458018677403,-0.06706943077862082
94.90000000000077,13.034889852435056,0.9926972795180888,-0.06934166170629297
96.00000000000078,13.07172869035408,0.9963440763333542,-0.06971326200632122
97.10000000000079,13.108874608427223,1.003517602238267,-0.0723481260739649
98.20000000000081,13.145414729317219,1.0061278863666276,-0.0723458519058604
99.30000000000084,13.182266493266406,1.0082017023273324,-0.0748507442578017
100.40000000000084,13.219419722440005,1.0079736352692192,-0.07497888349989124
101.50000000000085,13.256169892206533,1.0081654662199666,-0.0762156115000816
102.60000000000088,13.292599118547455,1.0080626146483258,-0.07729200906344502
103.7000000000009,13.329397609141433,1.0046905238690476,-0.0772960777192031
104.8000000000009,13.365992354713521,1.0039665245448148,-0.07857302043173053
105.90000000000092,13.401771468506203,1.0000777599912432,-0.07938856172371267
107.00000000000094,13.438402761543488,0.9942468268527,-0.08026429677220648
108.10000000000096,13.474145691891502,0.990429496680082,-0.0816560425993802
109.20000000000097,13.510769722193345,0.9860338893614184,-0.08157089103535897
110.30000000000098,13.54766355543709,0.9791638090707215,-0.08354486652457505
111.400000000001,13.583988240117186,0.9737365028888976,-0.08420963330172748
112.50000000000102,13.620462554372553,0.9677940872159665,-0.08421121622617855
113.60000000000103,13.656218700242498,0.9561929726536742,-0.08550826698416669
114.70000000000104,13.692506870666323,0.949051126005896,-0.08772737981178524
115.80000000000106,13.728482968824899,0.939928576092657,-0.08817206930374955
116.90000000000109,13.764708815431923,0.9305690375074487,-0.08947784247391954
118.0000000000011,13.800782943134092,0.9208405760268441,-0.08945842130151194
119.1000000000011,13.83653115932858,0.9112992612448787,-0.09080605427420041
120.20000000000113,13.87247782716702,0.9044867764419435,-0.09165401798158745
121.30000000000115,13.908413418387395,0.89320010595099,-0.09211085216879367
122.40000000000116,13.944484577958224,0.8839164873694456,-0.09206655977180933
123.50000000000117,13.980062415364932,0.8759731448308039,-0.0934295636318705
124.60000000000119,14.015819217549184,0.8618466655008674,-0.09345814993837287
125.70000000000121,14.051530089218343,0.8541815443313174,-0.09474463738653416
126.80000000000122,14.086892006840126,0.8458116791648533,-0.09473713605193756
127.90000000000123,14.122745700938207,0.8360530749839152,-0.09604688596334743
129.00000000000125,14.158117773229572,0.8309666981463715,-0.09608206133621522
130.10000000000127,14.193743792845174,0.8197096737358835,-0.09702143966801113
131.2000000000013,14.22840669058985,0.8134808423971918,-0.09704646767993763
132.3000000000013,14.264085049257524,0.8051045696139238,-0.09840678720789553
133.4000000000013,14.299416443208782,0.7992967812717098,-0.0983730089305368
134.50000000000134,14.334756134681609,0.7909030368253926,-0.09708509570071522
135.60000000000133,14.36990783038799,0.7854611730184275,-0.09706015747627772
136.70000000000135,14.405079035842725,0.7773333342397433,-0.09571355967461503
137.80000000000138,14.440374234389497,0.7731591367005068,-0.09605056202372886
138.9000000000014,14.475008147862109,0.7669382599096393,-0.09619121169095646
140.00000000000142,14.510222313717392,0.7599660974021478,-0.09749723918694109
141.10000000000142,14.545206955742486,0.7588142341688053,-0.09878694642613706
142.20000000000144,14.580272917500345,0.7521347780258092,-0.09879965466343688
143.30000000000146,14.614187681290588,0.7500664445536204,-0.10020758004908314
144.40000000000146,14.649842818094507,0.7445214577326617,-0.10012003459831575
145.50000000000148,14.684861206249844,0.7413110182972783,-0.10012006972289678
146.6000000000015,14.719316799845409,0.7409401118323137,-0.10012008420198892
147.70000000000152,14.75395468509501,0.7393018364605297,-0.10012282945585893
148.80000000000155,14.788442195176787,0.7374983756681699,-0.09959253491792053
149.90000000000154,14.823265452955331,0.7356542861011162,-0.10001741068911496
151.00000000000156,14.857555880311873,0.7346644357541082,-0.10011834912165263
152.1000000000016,14.892519135583873,0.7345456307405613,-0.10012044437843493
153.20000000000158,14.926871396746696,0.734732920269984,-0.10009448748675887
154.3000000000016,14.961503067701699,0.7335753732936561,-0.09880565885131887
155.40000000000163,14.995146078005734,0.7335157231918429,-0.09880997464777508
156.50000000000165,15.03075592685357,0.7340527661202996,-0.09880987024387355
157.60000000000167,15.064557484836458,0.7337162303890813,-0.09880986989795204
158.70000000000167,15.099142437138347,0.7346656813357557,-0.09880987234860861
159.8000000000017,15.133750795472428,0.7357250732245205,-0.09881065696913982
160.9000000000017,15.168256961086747,0.738496679816975,-0.09999063186332702
162.0000000000017,15.20223132411516,0.7401867048914267,-0.10011913332691824
163.10000000000173,15.236767826197891,0.7413465244282842,-0.1004535848357424
164.20000000000175,15.271025990671363,0.7421556046527885,-0.10143934814995248
165.30000000000177,15.305532230896247,0.7432325819131719,-0.10144067117153321
166.4000000000018,15.339790356663281,0.7432051148148103,-0.10112734654561217
167.5000000000018,15.373838157136682,0.7467928049852838,-0.10012321313628192
168.6000000000018,15.407831234136818,0.7498177456911683,-0.10013156936040879
169.70000000000184,15.442562770658903,0.7516329116243157,-0.10032937924791918
170.80000000000183,15.476600070813605,0.7555888505284,-0.10143858253613036
171.90000000000185,15.511077577455382,0.7554492433732571,-0.10144017943121764
173.00000000000188,15.545035199109646,0.75785064839252,-0.10144018622301054
174.1000000000019,15.579003891266062,0.7614882196528314,-0.10144018599918558
175.20000000000192,15.613065186108445,0.7625733138179708,-0.10144018599997562
176.30000000000192,15.647138206345234,0.7643759911360394,-0.10144018600001559
177.40000000000194,15.681351601872525,0.7672596425902911,-0.10144018599924332
178.50000000000196,15.71550109667142,0.7695650794230819,-0.10144018589689008
179.60000000000196,15.749340888245785,0.7713854704226291,-0.10144019619501732
180.70000000000198,15.78356438345779,0.7744529653148414,-0.10144035644725857
181.800000000002,15.817513903685997,0.7766822881329661,-0.10221725557896555
182.90000000000202,15.85130141919099,0.7799596402642371,-0.10276321190107884
184.00000000000205,15.885053484773632,0.7806903509366476,-0.102760211971479
185.10000000000204,15.919047351275946,0.7853474366851931,-0.10276019125173619
186.20000000000206,15.952871697540978,0.7879935360380325,-0.10276009599375335
187.3000000000021,15.98671351808943,0.7902540591286502,-0.10272126341043641
188.40000000000208,16.020504755849934,0.7926095747092723,-0.10183717645641188
189.5000000000021,16.054275446804233,0.7955681972167382,-0.10274515098068049
190.60000000000213,16.088102065815836,0.7973188406217877,-0.10276020072249548
191.70000000000215,16.121562550599428,0.8022147111161324,-0.10276188989701218
192.80000000000217,16.15507798355716,0.8034188876400167,-0.10411354929448091
193.90000000000217,16.188713176417018,0.8053602630358216,-0.10407933932803903
195.0000000000022,16.222565166029533,0.8085717576676867,-0.10428065472450765
196.1000000000022,16.256029967259455,0.8109336278363688,-0.10539842581615
197.2000000000022,16.28955602866393,0.813226801169467,-0.10539997326037343
198.30000000000223,16.322446149620596,0.8155432602173707,-0.10540003476620408
199.40000000000225,16.35678622991801,0.8184372423502216,-0.1053931650720683
200.50000000000227,16.39026849578781,0.820330458791553,-0.10641224325912679
201.6000000000023,16.4239525397563,0.8234291797626525,-0.10672033881321896
202.7000000000023,16.45749638710319,0.8235431015067193,-0.1067200244612434
203.8000000000023,16.491218997153872,0.828549770871496,-0.10672771872208786
204.90000000000234,16.524440650147874,0.8297212031331629,-0.10639773327595003
206.00000000000233,16.55781358470757,0.8333025986458268,-0.10648316328655616
207.10000000000235,16.591449131650325,0.8375044640428813,-0.10539494046318998
208.20000000000238,16.624964711481468,0.8360944263212639,-0.10540010877083406
209.3000000000024,16.65825996217195,0.8383355286598243,-0.10539976181799604
210.40000000000242,16.69182765966344,0.8417463947732241,-0.10538037677527035
211.50000000000242,16.725152409388862,0.843796899905994,-0.10676664103852707
212.60000000000244,16.758718166398737,0.8460101618729453,-0.10671961964555221
213.70000000000246,16.791647695784263,0.848715466916387,-0.10671985846068699
214.80000000000246,16.8253204781521,0.849596078369859,-0.10671986208980533
215.90000000000248,16.858690492036715,0.8512663112810992,-0.10671986199732197
217.0000000000025,16.892330599898383,0.8537301417131105,-0.10671986167468406
218.10000000000252,16.92524313773644,0.8546511143465217,-0.10671989803684179
219.20000000000255,16.95916552012481,0.857040018371478,-0.10671904214819827
220.30000000000254,16.992742948306468,0.8572485104534678,-0.10800294852207992
221.40000000000256,17.02547876534848,0.8587355948188108,-0.10802359343851498
222.5000000000026,17.059127263613963,0.8607568945669727,-0.10894261372424774
223.60000000000258,17.092557004341923,0.8647017414354459,-0.10935058288498345
224.7000000000026,17.125700374831784,0.8633040023425881,-0.10935005893525629
225.80000000000263,17.15900780639509,0.8634645702372954,-0.10935012616813156
226.90000000000265,17.192117719013957,0.8653721818222408,-0.10935967632806998
228.00000000000267,17.224893206803088,0.8654789624959387,-0.110584367400405
229.10000000000267,17.25882004126195,0.8663024524945857,-0.11068417986626455
230.2000000000027,17.292236061056865,0.8686164122150424,-0.1119987834249323
231.3000000000027,17.32516160676589,0.8716537952231656,-0.1119372174555644
232.4000000000027,17.358429006656564,0.870769461685062,-0.11331531916131965
233.50000000000273,17.39155225129964,0.8712607028622362,-0.11330035247177861
234.60000000000275,17.425140878440924,0.8726747741990787,-0.1132996875708896
235.70000000000277,17.458313308011373,0.8735213071423539,-0.11332016727564298
236.8000000000028,17.491341955378534,0.873843305903528,-0.11462302931281876
237.9000000000028,17.52440064476507,0.875772310433613,-0.11461573047907248
239.0000000000028,17.557984332292136,0.8744167957056457,-0.1149375023299446
240.10000000000284,17.591108393305745,0.8765062930251738,-0.11494526863429222
241.20000000000283,17.624191088083705,0.8755811197101447,-0.1157206435179039
242.30000000000285,17.657552018144823,0.8770022461969335,-0.1162700193233488
243.40000000000288,17.69081340939985,0.8747890387409419,-0.11698756375588548
244.5000000000029,17.72400015477041,0.8758460757099933,-0.11758562705204278
245.60000000000292,17.757076755822926,0.8751379410515951,-0.11767484097290293
246.70000000000292,17.790391050956696,0.8760170756023365,-0.11888747904220409
247.80000000000294,17.823356160556713,0.8748741001252245,-0.12064940930053814
248.90000000000296,17.856662667422814,0.8729621206520453,-0.12196740547317919
250.00000000000296,17.889718915667366,0.8730389565160828,-0.12339045664675474
251.10000000000298,17.923068181946235,0.8716328041065035,-0.12340727658326411
252.200000000003,17.956199006494867,0.8741327433675505,-0.1246754147788236
253.30000000000302,17.98918577967632,0.8733292888667087,-0.12530304112169954
254.40000000000305,18.02277831891003,0.8740740756025364,-0.12626226020803344
255.50000000000304,18.055541220976906,0.8737945760182861,-0.12812792434960585
256.6000000000031,18.08867797588986,0.8744373192622268,-0.12995514843074396
257.7000000000031,18.1219343735818,0.8739792844887787,-0.13137139948772525
258.8000000000031,18.154993391291896,0.871783352057062,-0.1329297479158349
259.9000000000031,18.188253822436018,0.8741794109008346,-0.13468325755674648
261.0000000000031,18.22114807357117,0.8703715013964158,-0.1343805344043112
262.10000000000315,18.254537741925176,0.8681627858242166,-0.1350456046125137
263.2000000000032,18.287620269958186,0.8690233590503588,-0.139681923733332
264.30000000000314,18.3205382654885,0.868063095997781,-0.14197682564702063
265.40000000000316,18.353869994504734,0.8672010333712972,-0.14394685172911892
266.5000000000032,18.386848298632064,0.8654385663650063,-0.14586330948560544
267.6000000000032,18.41950869024017,0.8658852080134177,-0.14837892067915526
268.70000000000323,18.452183505239223,0.8648545108929769,-0.150992366966205
269.80000000000325,18.486030234055256,0.8642186601905275,-0.15313363859486673
270.9000000000033,18.51943644100343,0.8607817721613865,-0.15451644283448074
272.0000000000033,18.552653278984018,0.860452185564456,-0.1572367758091251
273.1000000000033,18.585609538527905,0.8608309457971235,-0.1605263019803127
274.20000000000334,18.618124050186402,0.8583539204582905,-0.16229595000966013
275.30000000000337,18.650986382838582,0.859382056133089,-0.16304953402511657
276.40000000000333,18.684995377773348,0.8566986767095497,-0.1666345863687244
277.50000000000335,18.717909660373266,0.8560548630576819,-0.1694550910912036
278.6000000000034,18.750972736201547,0.8552523631531551,-0.17352474929643869
279.7000000000034,18.78430120659139,0.852977189413344,-0.17730042695623682
280.8000000000034,18.817478220952957,0.853905685084637,-0.17954162071002644
281.9000000000034,18.85058878413522,0.8535169998967791,-0.18388709755621502
283.0000000000034,18.883817453813702,0.8499353545980678,-0.189316156508482
284.10000000000343,18.916783400604707,0.8512679821313907,-0.19310887213251338
285.20000000000346,18.950310058028517,0.8468428791562546,-0.19902705024713052
286.3000000000035,18.98337745554928,0.8477256518053118,-0.2031730734424766
287.4000000000035,19.01644133520703,0.8490686612709536,-0.20762867302586585
288.5000000000035,19.049969268557774,0.8474999285725817,-0.21264471535688
289.60000000000355,19.08290049244842,0.8468750389378376,-0.21788514297968176
290.70000000000357,19.116221569154167,0.8464110415415228,-0.2229096205144887
291.8000000000036,19.149298463169366,0.8439231971544914,-0.2267047497855308
292.9000000000036,19.182737920461904,0.8427561138101876,-0.23279080960150722
294.0000000000036,19.21606073673445,0.8440713893983587,-0.2392609393264622
295.1000000000036,19.249327467184425,0.8437013120672058,-0.2444502586856463
296.2000000000036,19.282618907374754,0.8426412171779161,-0.25253367101000146
297.30000000000365,19.315869396392102,0.8429068777441756,-0.25987293252674615
298.4000000000037,19.349303166588424,0.8426049316117139,-0.2662686028623864
299.5000000000037,19.38214297577901,0.8395641714708098,-0.27389804322388134
300.60000000000366,19.415695823772012,0.8397900078162894,-0.2791456652812281
301.7000000000037,19.44918885799172,0.8411167060363081,-0.2834435079631006
302.8000000000037,19.48206172439252,0.8418483643146183,-0.29109334764230965
303.90000000000373,19.51564928538045,0.8414940110492529,-0.30450139317726066
305.00000000000375,19.549070198612764,0.8425434000327988,-0.3153765393736161
306.1000000000038,19.582641916930463,0.8436993545443282,-0.3247225307794963
307.2000000000038,19.615604780558968,0.8445063201982993,-0.33442606025536703
308.3000000000038,19.649183420279922,0.8465880182576653,-0.3430462352830852
309.40000000000384,19.682468305136968,0.8477651427226458,-0.3527004398660889
310.5000000000038,19.715859362804512,0.8531543363037519,-0.3633326599925568
311.60000000000383,19.749542976596697,0.8527362957464937,-0.37390236832219514
312.70000000000385,19.782526044412382,0.8565823920488976,-0.38458198086441175
313.8000000000039,19.81609948335514,0.8601541163639171,-0.39711691798455595
314.9000000000039,19.849273295855784,0.8629856898718591,-0.4099783149366001
316.0000000000039,19.882961846256848,0.8676056574555795,-0.4234911109439614
317.10000000000394,19.916261098101995,0.8725846229676387,-0.4361472938868305
318.2000000000039,19.95006072230129,0.8772923071536245,-0.44915969355360597
319.30000000000393,19.983546168480846,0.8809903912022429,-0.46434462143269606
320.40000000000396,20.016986286720932,0.8862341153586255,-0.4785523942574095
321.500000000004,20.050179293258786,0.8896483652845559,-0.4928944051968034
322.600000000004,20.083940489193623,0.8942434124879564,-0.506875126261392
323.700000000004,20.117403560271566,0.9014221150174955,-0.5211188697113034
324.80000000000405,20.150950514211594,0.9086487922972338,-0.535178931358562
325.90000000000407,20.184212658526807,0.9108739534480793,-0.5516817411191939
327.0000000000041,20.218028915387357,0.9187907060560524,-0.5688525219825284
328.10000000000406,20.251608835895823,0.9259947635378414,-0.5857890466155675
329.2000000000041,20.28501967490087,0.9330369080889154,-0.6032050222398446
330.3000000000041,20.31869441759389,0.9390448808927723,-0.6208924227560293
331.4000000000041,20.35235632193699,0.9458185997783878,-0.6398804888001437
332.50000000000415,20.385742096974706,0.950578717777744,-0.6590508741176984
333.6000000000042,20.4196235471113,0.9599952217677358,-0.678285337755105
334.7000000000042,20.453582554102105,0.965812570015073,-0.699616973737085
335.80000000000416,20.48706942363444,0.9724940670619687,-0.7201452528380847
336.9000000000042,20.520700686093072,0.9821045624027352,-0.7393058584937919
338.0000000000042,20.55452029967543,0.9889951784532143,-0.7580892508070596
339.10000000000423,20.58822303070552,0.9941203232942143,-0.7828333477065952
340.20000000000425,20.621661044539692,1.0051742124806338,-0.8076324447785628
341.3000000000043,20.655454208183823,1.0138026949297663,-0.8314124205915698
342.4000000000043,20.68924576006355,1.02417892922529,-0.8560631373485168
343.5000000000043,20.723198931055588,1.0340400198824493,-0.8805140203543225
344.60000000000434,20.756638239147627,1.044711058782455,-0.9047138147532063
345.7000000000043,20.790563565859202,1.0543163189484575,-0.9300747683947197
346.80000000000433,20.82424165864185,1.0670827037627508,-0.9564242859608605
347.90000000000435,20.85850639633014,1.0796277138635357,-0.984660670746925
349.0000000000044,20.8922329851454,1.0935755854819544,-1.0133314361502297
350.1000000000044,20.926188277090308,1.1061607617764266,-1.041494136364029
351.2000000000044,20.959408453821307,1.1194233397448001,-1.0688430327868406
352.30000000000445,20.994139612186803,1.1367907767505008,-1.1013243239149317
353.4000000000044,21.027834901062402,1.1526940443227591,-1.1318090239795526
354.50000000000443,21.06171636791047,1.1716483846547514,-1.1640029296026926
355.60000000000446,21.095967469102924,1.190182041155646,-1.1978336112169852
356.7000000000045,21.130124031186586,1.2072913652386568,-1.2325412208211626
357.8000000000045,21.164266347893015,1.2272354481288505,-1.2667310224568213
358.9000000000045,21.19806810053167,1.2480058420537743,-1.3009470401729084
360.00000000000455,21.232174363210888,1.271031509173426,-1.3371134814558063
361.10000000000457,21.2662130950021,1.2907700928774455,-1.374240361496772
362.2000000000046,21.30051059605631,1.3131900297467798,-1.4129528179794408
363.30000000000456,21.334760820605673,1.33523230379188,-1.453376422473137
364.4000000000046,21.36902472481385,1.357784930473045,-1.4930532383788844
365.5000000000046,21.40297290688353,1.3797121789205367,-1.532530084048143
366.6000000000046,21.43735920268809,1.399981335478749,-1.5739165838509215
367.70000000000465,21.47152278415183,1.4223373545190272,-1.6163744219124037
368.8000000000047,21.505799407413996,1.4415008983939872,-1.6599795526942551
369.9000000000047,21.539841224434536,1.457978211655599,-1.7044391237307424
371.00000000000466,21.5740287231243,1.471977928793745,-1.7512718287871718
372.1000000000047,21.608122448084384,1.4804977602353804,-1.7979399593847893
373.2000000000047,21.64233358858417,1.4860929831319827,-1.8405768138395011
374.30000000000473,21.676022284562546,1.48604487815311,-1.883583435715952
375.40000000000475,21.710369116752084,1.481676699827156,-1.9346041638037192
376.5000000000048,21.744169138937632,1.4690255309090345,-1.9834131038423775
377.6000000000048,21.77778875260598,1.4526769728201732,-2.0303632080717575
378.7000000000048,21.811702257394842,1.4239335650117653,-2.0781354756943795
379.80000000000484,21.845064883663593,1.389578376196189,-2.12168992121001
380.9000000000048,21.878707734684994,1.3454802925113876,-2.1634703819890806
382.00000000000483,21.912169635276594,1.2979759235174215,-2.2060448542481077
383.10000000000485,21.945590322821435,1.2363636458005516,-2.247078355663149
384.2000000000049,21.979011762791462,1.1734622708843079,-2.2862277463386143
385.3000000000049,22.01247319998518,1.1044402055278664,-2.3251691577413443
386.4000000000049,22.04501656487604,1.0316621638989267,-2.3584993880222753
387.50000000000495,22.078346689354404,0.9504585412410727,-2.3887521889268433
388.6000000000049,22.11125653931694,0.8728979341680736,-2.417967516176866
389.70000000000493,22.14458935007125,0.7936343010241076,-2.4461424211872576
390.80000000000496,22.177475789036663,0.7151085601463589,-2.471916424673123
391.900000000005,22.21070717281546,0.6386880537630676,-2.4948179331489837
393.000000000005,22.243988907189035,0.566396622884866,-2.5136364835646208
394.100000000005,22.277184844786095,0.4965615958279028,-2.5323251269312936
395.20000000000505,22.310449536450182,0.4332276177065627,-2.548721453219998
396.30000000000507,22.343742907763215,0.37015059709815623,-2.5633222732482945
397.4000000000051,22.377287179384272,0.3074272009785789,-2.5766130679117243
398.50000000000506,22.410670943233434,0.25326873517729775,-2.587703995951463
399.6000000000051,22.44401673672814,0.20249309766854318,-2.597183906608489
400.7000000000051,22.477899490889488,0.15135822063490934,-2.6071801821919953
401.8000000000051,22.51111314453399,0.10799745153424578,-2.6160442279546925
402.90000000000515,22.544296561395672,0.06682765840104321,-2.6233170143829074
404.0000000000052,22.57871232057502,0.02915331739980187,-2.6300176849053614
405.1000000000052,22.61245772833107,-0.004654670242976056,-2.6347788241842593
406.20000000000516,22.646335365863493,-0.033751700739122925,-2.6404006799717203
407.3000000000052,22.680241853359764,-0.058706654174470185,-2.6447122838135186
408.4000000000052,22.714468740613928,-0.08267081470891702,-2.6487545304944318
409.50000000000523,22.74837666787059,-0.10106015915850375,-2.6526241140705102
410.60000000000525,22.782396211534618,-0.12162433384703153,-2.655297506050485
411.7000000000053,22.816635527951075,-0.13883678552521128,-2.658800950012698
412.8000000000053,22.85062906179862,-0.14602394449808953,-2.6622052549798836
413.9000000000053,22.884646845119903,-0.16301834664398074,-2.664716426656165
415.00000000000534,22.918934393967156,-0.1724393782933039,-2.668479601979334
416.1000000000053,22.95322290407209,-0.18343291415571716,-2.671659065274896
417.20000000000533,22.98754713240922,-0.1947024663584188,-2.6750278925826745
418.30000000000535,23.02177741357025,-0.20177524643586198,-2.6779425883068444
419.4000000000054,23.056217877685544,-0.21035992932410807,-2.681090128533543
420.5000000000054,23.090602315293246,-0.2197993664245924,-2.6854895750995604
421.6000000000054,23.12495385574838,-0.22936850821455446,-2.6876956882968446
422.70000000000545,23.159350272030363,-0.23551748624891278,-2.69084200937625
423.8000000000054,23.19363416293568,-0.24235836402804933,-2.6940359932767883
424.90000000000543,23.227837788229827,-0.24695991983592402,-2.696440149765041
426.00000000000546,23.262275740505466,-0.25474168022107524,-2.700183135379403
427.1000000000055,23.296707918710723,-0.26257801280234006,-2.7037504777101056
428.2000000000055,23.331020366408605,-0.2681593269565993,-2.7067519533236406
429.3000000000055,23.365558379713384,-0.27496765628810793,-2.709244624528513
430.40000000000555,23.399872836005773,-0.27809770140884393,-2.7125192753989067
431.50000000000557,23.434465557762124,-0.2827047784873602,-2.715397663154709
432.6000000000056,23.46926766729354,-0.2883826401880649,-2.7181020542460206
433.70000000000556,23.503489886540674,-0.29028075559478794,-2.7208041410364388
434.8000000000056,23.538018727576763,-0.2947123628987992,-2.72390218635417
435.9000000000056,23.572974646461734,-0.29854731852673655,-2.727824758207024
437.0000000000056,23.607331629379097,-0.29971036601718326,-2.729013331046252
438.10000000000565,23.641830998079453,-0.304786359950481,-2.73254114679437
439.2000000000057,23.676263956325833,-0.3054167217266138,-2.735106606567319
440.3000000000057,23.711109724508304,-0.3073478955784792,-2.738388593930563
441.40000000000566,23.745699482155175,-0.30800919512865055,-2.7405348919914143
442.5000000000057,23.780315338232043,-0.3098376137138832,-2.7439443153974032
443.6000000000057,23.815097526839473,-0.30889817774893336,-2.745649763087628
444.70000000000573,23.849711507944296,-0.3116806041170368,-2.74774178608373
445.80000000000575,23.88440591671905,-0.3089422289586674,-2.750415667908603
446.9000000000058,23.91909154007782,-0.3101700628333961,-2.753195241593357
448.0000000000058,23.95392094698959,-0.31363933548115186,-2.7566167969486366
449.1000000000058,23.988697596013253,-0.3127900831638577,-2.76077398728654
450.20000000000584,24.023529518162583,-0.30793138356869465,-2.7638624688505624
451.3000000000058,24.058153132495534,-0.30838611186972076,-2.7668898431547846
452.40000000000583,24.09304167451805,-0.30370539968111343,-2.768917327026495
453.50000000000585,24.127972265199645,-0.30115467819905783,-2.771587502701847
454.6000000000059,24.1627260291488,-0.29990221472786716,-2.772761142751185
455.7000000000059,24.19772124569568,-0.298022228737192,-2.774960259311478
456.8000000000059,24.23218429057089,-0.29546889904223406,-2.778493134696805
457.90000000000595,24.26726236358795,-0.28767068607171253,-2.7802765537183527
459.0000000000059,24.302407773499798,-0.28571828834930824,-2.782860601028733
460.10000000000593,24.337050317597818,-0.28263780822757867,-2.7854091638048035
461.20000000000596,24.37204983137193,-0.2806527863576552,-2.787725007389141
462.300000000006,24.40717430828801,-0.27884748632770995,-2.789988022873662
463.400000000006,24.441985995633566,-0.2731338920683781,-2.792003343070206
464.500000000006,24.476770089878286,-0.2711117887826485,-2.793773065869471
465.60000000000605,24.511889280111795,-0.26577972308896736,-2.794929442385088
466.70000000000607,24.546793314198325,-0.2620603291282302,-2.796732770515682
467.8000000000061,24.58181396419848,-0.2598655817023461,-2.799164728186165
468.90000000000606,24.61677028232138,-0.254555509900257,-2.80200371000508
470.0000000000061,24.65195063190028,-0.2492440966139431,-2.8036917302336715
471.1000000000061,24.68681989680646,-0.24580599043428186,-2.8064714518912766
472.2000000000061,24.722009204475007,-0.2425411788298677,-2.8084477928688596
473.30000000000615,24.757127327248725,-0.2388980455716585,-2.810751906261743
474.4000000000062,24.792189512980467,-0.24059670080622086,-2.8131003680168556
475.5000000000062,24.82730927281045,-0.23310077343287572,-2.8148183652356003
476.60000000000616,24.86256296316604,-0.2322638262045995,-2.81853513074031
477.7000000000062,24.897158743544324,-0.229675271235666,-2.820264786026879
478.8000000000062,24.932733684233625,-0.22595435941677922,-2.8230217050427413
479.90000000000623,24.9681067191041,-0.2201849694672623,-2.8241354792600797
481.00000000000625,25.003054845592082,-0.21864131764343897,-2.824890070179442
482.1000000000063,25.038331625098376,-0.21489853093505396,-2.826670384433764
483.2000000000063,25.07367774935781,-0.2124234420813783,-2.828167831604425
484.3000000000063,25.1088832380409,-0.2085831759235407,-2.8293838248709458
485.40000000000634,25.144102380970104,-0.2077699717890752,-2.8325145945680865
486.5000000000063,25.178990560899763,-0.20288646260197807,-2.8353732671133565
487.60000000000633,25.214322327220007,-0.20300009909346373,-2.836626449726621
488.70000000000636,25.249617966004728,-0.20295264898101917,-2.8388884246587507
489.8000000000064,25.284896440856752,-0.19918414223328362,-2.8402154365302272
490.9000000000064,25.320312903598424,-0.19630001826132182,-2.840204380844208
492.0000000000064,25.355349641531514,-0.1935191436062461,-2.84163142210471
493.10000000000645,25.3906646539113,-0.19261845512979214,-2.8434379203760116
494.2000000000064,25.425403622572908,-0.19120063613773974,-2.844590345027724
495.30000000000643,25.461167225613984,-0.1893988673168452,-2.846745226053029
496.40000000000646,25.496665480812354,-0.18839788088364529,-2.84820874528348
497.5000000000065,25.532411229568446,-0.18887445871634057,-2.849453823267992
498.6000000000065,25.567221667540856,-0.18749188237697734,-2.850714691311948
499.7000000000065,25.602173650972233,-0.18701480095709322,-2.851908797033463
500.80000000000655,25.63798927678868,-0.18498027493988423,-2.8547751001047743
501.90000000000657,25.67348003966324,-0.18462683589098494,-2.8566017498601464
503.0000000000066,25.7087876769857,-0.1847345040689231,-2.8581112593010958
504.10000000000656,25.743988837978407,-0.18402979317342194,-2.859357977780949
505.2000000000066,25.77961376297229,-0.18197964710082148,-2.860859637543711
506.3000000000066,25.814756653550564,-0.18112178971795112,-2.8622837519446356
507.4000000000066,25.850162873374384,-0.18094260019544928,-2.8638077698609488
508.50000000000665,25.88558016596979,-0.17978841287756242,-2.865080830410651
509.6000000000067,25.92089439990452,-0.18193685100272394,-2.8651609956046062
510.7000000000067,25.95658305065454,-0.1798716944243699,-2.8664557514383167
511.80000000000666,25.991611415999788,-0.1821854547782904,-2.8678655115602485
512.9000000000067,26.027393701638836,-0.1787981773992393,-2.869214551178243
514.0000000000067,26.062844230144997,-0.17939973298053413,-2.870081565508829
515.1000000000067,26.098277389396962,-0.1782241836802927,-2.870441356577171
516.2000000000068,26.133728140725943,-0.18159467212618363,-2.8719733346700793
517.3000000000068,26.169264981008034,-0.18107238362768996,-2.8740483698657906
518.4000000000068,26.204420500868466,-0.178627188550311,-2.8762916377904584
519.5000000000068,26.240031147636653,-0.18218762404205857,-2.876431706928214
520.6000000000068,26.27556207084311,-0.17996140891780055,-2.877725770677004
521.7000000000069,26.31126881036998,-0.18271732320679113,-2.8790700059395293
522.8000000000068,26.34646645094472,-0.18365397873536216,-2.8801801214042793
523.9000000000069,26.381977573424543,-0.18468835957390772,-2.881231528924917
525.0000000000068,26.417494273428495,-0.18404055601175573,-2.883023503673898
526.100000000007,26.453175412388504,-0.1821516857870682,-2.8839184930652624
527.2000000000069,26.48863764977485,-0.18417173470213677,-2.88521172929578
528.300000000007,26.52430318869758,-0.18080722185627263,-2.886311354278398
529.4000000000069,26.560097759851644,-0.18102940586859773,-2.8867834946407047
530.5000000000069,26.595499382456097,-0.1830268944629081,-2.886699754403823
531.600000000007,26.63099260099928,-0.18284551509440994,-2.888054090318742
532.700000000007,26.666607478675658,-0.1832711026849334,-2.8894951950009062
533.800000000007,26.701502152091454,-0.17689404454905877,-2.89147276097027
534.900000000007,26.737728006227357,-0.1723683136763845,-2.893143373185001
536.000000000007,26.773183423152787,-0.1701586494875964,-2.8937763602671036
537.1000000000071,26.808937755499368,-0.16472178386786118,-2.895012070546949
538.2000000000071,26.844615450349128,-0.16228997290744185,-2.8956807171064263
539.300000000007,26.879693331425777,-0.15851738540064209,-2.8970688888898084
540.4000000000071,26.915675735234068,-0.1557983778522012,-2.8983342726067804
541.500000000007,26.951425614432555,-0.15280534817344282,-2.898393136412728
542.6000000000072,26.987129547871767,-0.15031998444784045,-2.8984783991120047
543.7000000000071,27.023076644906105,-0.1480266504803054,-2.898387702119109
544.8000000000072,27.058442854340687,-0.1448418052955518,-2.8989042701638894
545.9000000000071,27.094479360265744,-0.14445966096945195,-2.900122725857471
547.0000000000072,27.13000000000023,-0.14298626451895613,-2.90255581368433
548.1000000000072,27.165458714588322,-0.14313615371082378,-2.904007739530507
549.2000000000072,27.20102640583433,-0.14295457216016505,-2.9043117410956887
550.3000000000072,27.236910270286668,-0.1388270288733653,-2.905628448352716
551.4000000000073,27.272791033845103,-0.13812622030624477,-2.9071092582356712
552.5000000000073,27.308615524642608,-0.1377363291685192,-2.908363851308091
553.6000000000073,27.34415119496007,-0.13796278971191245,-2.909695169567163
554.7000000000073,27.37996727403987,-0.13604045048907443,-2.9108005196898814
555.8000000000073,27.41575682017868,-0.13487377097196096,-2.912119580526735
556.9000000000074,27.45147891226063,-0.13398795371166017,-2.912107701837451
558.0000000000074,27.487227939081322,-0.1318563500743548,-2.913475225936611
559.1000000000074,27.522933201099015,-0.13361404153119794,-2.9149630422966806
560.2000000000073,27.558604977144984,-0.1298478751092509,-2.9149150632744054
561.3000000000073,27.594304130712118,-0.13160975087882965,-2.9149072179670923
562.4000000000074,27.630560692492548,-0.13271114386099137,-2.9163098897968522
563.5000000000074,27.666194398855968,-0.13137970927825937,-2.9175926170816004
564.6000000000074,27.702312149292226,-0.1310462374061232,-2.918915803371838
565.7000000000074,27.73800245177657,-0.13163647307949922,-2.9208578603135864
566.8000000000075,27.7731076357082,-0.12967151373745445,-2.920614662478731
567.9000000000075,27.80963863915674,-0.13593288792205982,-2.919358538988405
569.0000000000075,27.845462683774816,-0.1351961330314826,-2.920981477058869
570.1000000000075,27.88131159403275,-0.1362260111500877,-2.922604270407205
571.2000000000075,27.917229065070156,-0.13952014432716386,-2.9239702813387978
572.3000000000076,27.95283169889824,-0.14275799931469302,-2.924868197878352
573.4000000000076,27.989075660957052,-0.14410798452460605,-2.9252908616448883
574.5000000000076,28.02510033995531,-0.15083923677632116,-2.9255588040774203
575.6000000000076,28.060740925705332,-0.15362879028602716,-2.926584991277579
576.7000000000077,28.09662772508838,-0.15011825321081074,-2.927279972486926
577.8000000000077,28.132798418237034,-0.15601792431308592,-2.927270645554576
578.9000000000076,28.168604411947527,-0.15467631228650047,-2.9272378642440104
580.0000000000076,28.204710664317865,-0.15878849416575203,-2.9286779632172264
581.1000000000076,28.240598870668776,-0.16079390951124517,-2.929737498954333
582.2000000000077,28.276481664672318,-0.16255266773915578,-2.929923320806561
583.3000000000077,28.312496546354446,-0.16680481076804976,-2.9313373100469025
584.4000000000077,28.34865225014048,-0.1698886907221855,-2.9320387149756293
585.5000000000077,28.38475431160924,-0.16832878947637409,-2.931991411979818
586.6000000000078,28.42091791823542,-0.17244202791255137,-2.9334713907808387
587.7000000000078,28.4567848928656,-0.1713468445160371,-2.93446596705395
588.8000000000078,28.49286489870126,-0.17196961218998275,-2.9356117080091826
589.9000000000078,28.529082675579634,-0.17466176812660095,-2.9360289922176968
591.0000000000078,28.565022517478965,-0.17815483233030682,-2.9373462572056814
592.1000000000079,28.60113065571619,-0.1797747466804629,-2.937357551895592
593.2000000000079,28.63730597490926,-0.1821557178440174,-2.93660841450342
594.3000000000079,28.67355484964468,-0.1811279888506261,-2.93738435984731
595.4000000000078,28.709605210837033,-0.18062357228995007,-2.9386769626812677
596.5000000000078,28.745424118858878,-0.1843748601440256,-2.9392024825443333
597.6000000000079,28.78174108863643,-0.18394611028221752,-2.940009457185596
598.7000000000079,28.817818189458414,-0.18512812484949293,-2.941307699863052
599.8000000000079,28.85398841144445,-0.1846385373956061,-2.941277240307029
600.9000000000079,28.890367634277833,-0.18944034331457904,-2.9426370671711464
602.000000000008,28.926275692815263,-0.18852382841756232,-2.942631976891715
603.100000000008,28.962813851644686,-0.18996258660373067,-2.9439369713458876
604.200000000008,28.99860569005125,-0.19279902503939805,-2.9451782557351365
605.300000000008,29.035004424748607,-0.19366999614853242,-2.945269284490887
606.400000000008,29.071596187804793,-0.19556788170540051,-2.9453309309022186
607.5000000000081,29.1074542024911,-0.18901805733426458,-2.946583199162969
608.6000000000081,29.143734618522387,-0.19112343981531454,-2.946592931022338
609.7000000000081,29.17999966701867,-0.19513130792361433,-2.9475812485033934
610.8000000000081,29.216199651161894,-0.19560572678563481,-2.9475885796788885
611.9000000000082,29.252424028635343,-0.19595412829382575,-2.9479148534265587
613.0000000000082,29.288314247321335,-0.19824060270978916,-2.948934614316026
614.1000000000081,29.32504206328899,-0.1975725313624359,-2.9491664762646863
615.2000000000081,29.360912872197776,-0.19876424203002618,-2.9502115144125582
616.3000000000081,29.397463347447584,-0.2015771717831596,-2.9502328116537315
617.4000000000082,29.433606387543172,-0.19686469376941385,-2.951534821898375
618.5000000000082,29.46974230971561,-0.19934720092160485,-2.952966871050067
619.6000000000082,29.506292583607575,-0.19890229363941603,-2.9543214835158484
620.7000000000082,29.54271856548247,-0.19534145506916611,-2.95567395461699
621.8000000000083,29.579145158867668,-0.19485665952995745,-2.9565029515863133
622.9000000000083,29.614767808256534,-0.19521578003445894,-2.9569727403338244
624.0000000000083,29.651709207121012,-0.19215286206236848,-2.955923336025327
625.1000000000083,29.688295946754835,-0.19062779197464508,-2.9561242934880463
626.2000000000083,29.724401448455055,-0.19105393794338577,-2.957253128000864
627.3000000000084,29.76096843287493,-0.1873929302599886,-2.9561910872875004
628.4000000000084,29.7973585408581,-0.1849361931173641,-2.9576021949708418
629.5000000000084,29.833789672880332,-0.18186895759510024,-2.9578841893620402
630.6000000000083,29.870302568956827,-0.1781429847750442,-2.9590090002478173
631.7000000000083,29.906452925424702,-0.17715693833883006,-2.961365968029147
632.8000000000084,29.94308431863296,-0.17729639464931535,-2.9613007125576285
633.9000000000084,29.979506118674145,-0.17482276499529004,-2.9613001995670496
635.0000000000084,30.01554106780413,-0.1755771813604876,-2.9613273311752177
636.1000000000084,30.052001661200794,-0.1760819679371417,-2.962624863491877
637.2000000000085,30.088786355754543,-0.17639572597215802,-2.962316545620678
638.3000000000085,30.124591491155307,-0.1760367980216595,-2.9635384266379465
639.4000000000085,30.161546741784758,-0.17569245058749416,-2.96359457611723
640.5000000000085,30.197778211981355,-0.17487354210386674,-2.9649424879102444
641.6000000000085,30.23441607454519,-0.1724763047633362,-2.9649201850677365
642.7000000000086,30.27078250172311,-0.16789520904375776,-2.9649218381817355
643.8000000000086,30.307342043262064,-0.17509861409373495,-2.9661220364353937
644.9000000000086,30.343819631498352,-0.1722757703045963,-2.9662405103879435
646.0000000000086,30.380163689438536,-0.16981915749629928,-2.9662497599852395
647.1000000000087,30.416462782160693,-0.1674482964206796,-2.967666903495647
648.2000000000087,30.453285294968175,-0.16334635554070975,-2.967670003149133
649.3000000000086,30.48945890548054,-0.15769513149186132,-2.9676736634687364
650.4000000000086,30.52578934543245,-0.15672095548348208,-2.9708138025437627
651.5000000000086,30.562660567393575,-0.1489682021786496,-2.972282076888524
652.6000000000087,30.599211770026887,-0.14928535292177703,-2.97359470944866
653.7000000000087,30.635971135759434,-0.14497911923970075,-2.9748597285876266
654.8000000000087,30.672339844356916,-0.14012146580235596,-2.974909773374132
655.9000000000087,30.7087408760218,-0.13677588040445565,-2.97490992343064
657.0000000000088,30.745328270406517,-0.13209675005527344,-2.974902859127863
658.1000000000088,30.781986003766885,-0.1277709054436984,-2.9759915452060097
659.2000000000088,30.81826379212516,-0.12310107113586799,-2.9762410658826077
660.3000000000088,30.854867181886046,-0.11759797441723574,-2.976230134115113
661.4000000000088,30.891593430828284,-0.11239730913284118,-2.9762391785047644
662.5000000000089,30.928159781576205,-0.11038268139585128,-2.9775402030204527
663.6000000000089,30.964406764741028,-0.1044482316527846,-2.977509618520793
664.7000000000089,31.001045589961524,-0.09819251002224894,-2.977550655926772
665.8000000000088,31.037953869083395,-0.09357264394299047,-2.9783291811597614
666.9000000000088,31.074110934956625,-0.08686753442659012,-2.978881359020031
668.0000000000089,31.11091252956071,-0.07998331934161662,-2.9801832887345876
669.1000000000089,31.14724631152357,-0.0727814502124553,-2.9803289779078534
670.2000000000089,31.1838099854809,-0.06994917659214739,-2.981502034563186
671.3000000000089,31.2207140069133,-0.06056413968488683,-2.9825376773587755
672.400000000009,31.257083327634103,-0.05860107728499875,-2.9828103258894814
673.500000000009,31.29376247365913,-0.05231431188366309,-2.9828171257803975
674.600000000009,31.330370650173734,-0.04683933239814375,-2.981511708199989
675.700000000009,31.36713456142086,-0.041173015188476825,-2.982689615403208
676.800000000009,31.40360303158143,-0.03880970509811621,-2.983517459671866
677.9000000000091,31.44033222454914,-0.03348636382254644,-2.9841410236775077
679.0000000000091,31.476738913723608,-0.0328204172310993,-2.985456515408954
680.1000000000091,31.51352214265375,-0.030892059176379716,-2.9868378017510606
681.2000000000091,31.550169592114266,-0.03125261958332359,-2.989723684577166
682.3000000000092,31.58661256431182,-0.031953664765621115,-2.9911769670016666
683.4000000000092,31.623058493437316,-0.031647173516589744,-2.992231140022752
684.5000000000091,31.659675217177725,-0.032927785789047315,-2.9908304426034946
685.6000000000091,31.696453760683582,-0.035841636238101326,-2.9911800911620583
686.7000000000091,31.733064168855048,-0.038789686345717334,-2.992664959601619
687.8000000000092,31.7696308189687,-0.04292307767044634,-2.994025564808527
688.9000000000092,31.80669016383373,-0.04714810383338319,-2.9940446026015968
690.0000000000092,31.842914579189646,-0.05455504234915054,-2.99534417218442
691.1000000000092,31.87950065924752,-0.06217164210864068,-2.9959488710704036
692.2000000000093,31.916155864148422,-0.06941776470141536,-2.9966660651317527
693.3000000000093,31.95267487755687,-0.07796252684323979,-2.998000910713389
694.4000000000093,31.98938336366884,-0.09315576173585716,-2.9966467303307485
695.5000000000093,32.02595688580232,-0.10801210712425258,-2.99792428417879
696.6000000000093,32.06201433409783,-0.11578560752980449,-2.99910036341591
697.7000000000094,32.098258873119505,-0.13027215893311483,-2.999291069710646
698.8000000000094,32.13584444165286,-0.14721064390219474,-2.999607593699842
699.9000000000094,32.17212198092014,-0.16328883225480872,-3.000599604693284
701.0000000000093,32.20894827233273,-0.18102950965603637,-3.001938580377442
702.1000000000093,32.24515970572227,-0.19447556558956736,-3.002801991129389
703.2000000000094,32.28207260657745,-0.2164430346941144,-3.003235048094209
704.3000000000094,32.3188112217411,-0.2306407573031175,-3.004096968030561
705.4000000000094,32.35535437834666,-0.2415345445628545,-3.006449837537165
706.5000000000094,32.391949075743774,-0.25196146428920674,-3.007110345939618
707.6000000000095,32.42852790559318,-0.2645000275894054,-3.0056539783145526
708.7000000000095,32.46527966976311,-0.2740809623288436,-3.0043410533552413
709.8000000000095,32.5021382458082,-0.2753288544685313,-3.0043298260465177
710.9000000000095,32.53891061872508,-0.2793460228424931,-3.0043386004362738
712.0000000000095,32.57560088698417,-0.27802238297165127,-3.004975188215474
713.1000000000096,32.61212877163341,-0.28182101562589845,-3.0049934189125613
714.2000000000096,32.648865826395046,-0.28365632563154985,-3.005058285962514
715.3000000000096,32.685605975868896,-0.28341072457122785,-3.0076304784088292
716.4000000000096,32.72270694212281,-0.28808835179392434,-3.006535402622978
717.5000000000097,32.75911044753766,-0.28742246284037587,-3.006307323834645
718.6000000000097,32.79610876427286,-0.2886616339064647,-3.0075926009399705
719.7000000000096,32.83288316432171,-0.2929721348340488,-3.0087982558434447
720.8000000000096,32.8696929595926,-0.2914920013989786,-3.0089444851977865
721.9000000000096,32.906586176000864,-0.29330022499446584,-3.010263654733449
723.0000000000097,32.94348266281107,-0.2942482387724723,-3.010256837957547
724.1000000000097,32.98026154819697,-0.29614764787509906,-3.0109304510813732
725.2000000000097,33.01715239855592,-0.2958782631279073,-3.01091923781057
726.3000000000097,33.05418568828656,-0.29646631210564256,-3.0109202284256718
727.4000000000098,33.09095337354092,-0.2970676021162286,-3.010929569434628
728.5000000000098,33.12773986313661,-0.300383265205028,-3.009579418350178
729.6000000000098,33.16395814233872,-0.3033704591869364,-3.0095998687296404
730.7000000000098,33.201757528266654,-0.3022721762899465,-3.0096007558326714
731.8000000000098,33.23826943306176,-0.3023045562957236,-3.0095248838891435
732.9000000000099,33.275183988196666,-0.30336135302769174,-3.0106946244789055
734.0000000000099,33.312453877935006,-0.3030662424345427,-3.0110808681148558
735.1000000000099,33.3490952595187,-0.30417691479701325,-3.012592158538325
736.2000000000098,33.38642004516915,-0.3054983868516947,-3.01390036712979
737.3000000000098,33.4228038636526,-0.3033342700472603,-3.0152936778218455
738.4000000000099,33.46006691117673,-0.3050697783846008,-3.0152100260428703
739.5000000000099,33.497101283967204,-0.3046246197842917,-3.0151240962566743
740.6000000000099,33.533646109726,-0.3047847664481693,-3.0150696608609007
741.7000000000099,33.57079064205061,-0.30891090963714163,-3.01651895909103
742.80000000001,33.60779082967185,-0.30617768923079813,-3.016474495316227
743.90000000001,33.64467277064613,-0.3084115586604428,-3.017826707115097
744.00000000001,33.647900476838906,-0.3081053805196956,-3.0178343914401