File: 01_Data/Corrugated_Cardboard/STA/N2/30K_min/Corrugated_Cardboard_STA_N2_30KData_230920_R1.csv
##Temp./Â°C,Time/min,DSC/(mW/mg),Mass loss/mg
28.200000000000003,15.453145724847174,0.019117864454699873,-0.031538250214071084
29.30000000000002,15.71017062120304,0.09604334167166684,-0.0410602038046175
30.400000000000034,15.850465114755808,0.13940875390039897,-0.039903423353425005
31.50000000000005,15.95228405800374,0.18157867967471075,-0.0368349001422823
32.600000000000065,16.041093217072156,0.22211915482901423,-0.0398278430078598
33.70000000000008,16.117733807271506,0.26135911811581836,-0.04045094810676453
34.8000000000001,16.186569449546987,0.29485395995728747,-0.04130658886812455
35.90000000000011,16.25159213344482,0.326519641196491,-0.04042443653736871
37.00000000000013,16.31176487302797,0.35882628389076743,-0.040563710210512305
38.10000000000014,16.37026393989778,0.3878256663071815,-0.04055320662640849
39.20000000000016,16.425230360417064,0.4159255529604948,-0.041622932412369806
40.300000000000175,16.47801872084853,0.4398724565799106,-0.04193576372560592
41.40000000000019,16.528921326581198,0.4684698598461581,-0.042084713585055944
42.500000000000206,16.578334762148103,0.49292612392408586,-0.043603462299484974
43.60000000000022,16.627763862008205,0.5181707057670539,-0.04361240646782516
44.70000000000024,16.674966685180397,0.5393647212144157,-0.04482622693859817
45.80000000000025,16.72271698912988,0.563798190279406,-0.045205978897215005
46.90000000000027,16.767493307813712,0.5881156233863329,-0.045861144596268666
48.000000000000284,16.813059358700666,0.6089791946317842,-0.04519359235374587
49.1000000000003,16.856857510398264,0.6321185901829973,-0.04599024946655739
50.200000000000315,16.901272920021924,0.6530425362413657,-0.04703577920449664
51.30000000000033,16.94431964667899,0.6757350997630143,-0.04825861289301958
52.40000000000035,16.98784704857274,0.6986280870538095,-0.0473556818887495
53.50000000000036,17.030196484213334,0.7201065205519752,-0.04903856414207031
54.60000000000038,17.07179807939807,0.7421358770061679,-0.04772284137157534
55.700000000000394,17.113770733433906,0.7629227009488415,-0.04959879020632396
56.80000000000041,17.155310622422416,0.7858999630857288,-0.053806922136219626
57.900000000000425,17.196702862213865,0.8097583624525548,-0.05397628456675374
59.00000000000044,17.23714375954535,0.8297726107156032,-0.053531007405904774
60.100000000000456,17.278216656016674,0.8522709467864322,-0.053683694682214345
61.20000000000047,17.31795826960571,0.8757344417114472,-0.05504711559309605
62.30000000000049,17.358559536743726,0.9002873940039566,-0.05704736699203661
63.4000000000005,17.399309622883848,0.9242809840232,-0.05768803273268741
64.50000000000051,17.438726255540036,0.9468266491538258,-0.059237123859309015
65.60000000000053,17.477921699262467,0.9709783899098607,-0.060149725378773944
66.70000000000056,17.51734777222834,0.9930115749296398,-0.061590230736863205
67.80000000000057,17.55633066250434,1.0135509343780411,-0.06307314009194265
68.90000000000057,17.596123845537054,1.0393949206181021,-0.06455303034959226
70.0000000000006,17.63566129508956,1.0616251643100485,-0.06582078804018465
71.10000000000062,17.674652518102413,1.082614611171547,-0.06718124725189423
72.20000000000063,17.713793678021407,1.1078370096504562,-0.0675680107297234
73.30000000000064,17.752284917464287,1.1282640691415327,-0.06859989121673671
74.40000000000066,17.791155119096228,1.1484257733818661,-0.07110253451777471
75.50000000000068,17.830288203275423,1.1667914813654765,-0.07251606549782963
76.60000000000069,17.86935326713335,1.1873131426676133,-0.07397692087658925
77.7000000000007,17.908023455353636,1.206162806345963,-0.07583436457683934
78.80000000000072,17.946479715297052,1.2252777489313438,-0.07806359452372114
79.90000000000074,17.98428873852506,1.2432302059774962,-0.08012698796919882
81.00000000000075,18.0229324518084,1.257563594350744,-0.08169419638085529
82.10000000000076,18.060984400332373,1.2739383993739024,-0.08308658280659831
83.20000000000078,18.099512919408266,1.2869428856741472,-0.08477328239959547
84.30000000000081,18.137215829491968,1.3007744473123297,-0.0872868999887988
85.40000000000082,18.175229261783972,1.3117908866628003,-0.08869984382232055
86.50000000000082,18.2126878595417,1.3263239350635017,-0.09012068031803366
87.60000000000085,18.250525633709188,1.3360118900585112,-0.09171676166529519
88.70000000000087,18.288205393652053,1.3434840092356202,-0.09436045830315187
89.80000000000088,18.324828259684626,1.3485917558124247,-0.09617165242251247
90.90000000000089,18.36279057970792,1.3537007697241668,-0.09802802835999191
92.00000000000091,18.399556743554637,1.3599327940681885,-0.10137808876039678
93.10000000000093,18.43642210763232,1.3619497679962602,-0.10365312066209764
94.20000000000094,18.473493293011327,1.3639123923059047,-0.10504934542518951
95.30000000000095,18.51053172976558,1.3649161372557501,-0.10763175281015736
96.40000000000097,18.547088386803605,1.36185828614099,-0.1096856983836294
97.500000000001,18.58421764011156,1.3595970070988683,-0.11176063608890408
98.600000000001,18.62059383344965,1.3576275646675644,-0.11208486329449396
99.70000000000101,18.657118808928747,1.3541779392843607,-0.11344763919959755
100.80000000000103,18.693500180290023,1.3502814889631278,-0.1161974002877244
101.90000000000106,18.729592727718472,1.3453236015815926,-0.11745799896509412
103.00000000000107,18.766182387629822,1.336477640784117,-0.11952389917738682
104.10000000000107,18.80221787002624,1.3289393345160776,-0.1202655980848264
105.2000000000011,18.837688894195434,1.3196301566662108,-0.1214318222057873
106.30000000000112,18.87436908584458,1.3079082174264234,-0.12285602708357457
107.40000000000113,18.910033078869997,1.2965514249657635,-0.12426989352189421
108.50000000000114,18.9462404539654,1.2863878937527833,-0.12540798373337925
109.60000000000116,18.98223582651175,1.274912471315964,-0.12664467414968605
110.70000000000118,19.018340617826237,1.2627302925926325,-0.12823601109270033
111.80000000000119,19.05481325969729,1.2492377949625548,-0.12822225551839805
112.9000000000012,19.09081618055644,1.2366154749502634,-0.13007963145658064
114.00000000000122,19.12654871839886,1.2238023382017846,-0.1325776984486886
115.10000000000124,19.162653255812153,1.2112046969535588,-0.1330942784426723
116.20000000000125,19.19799096406187,1.195593858259267,-0.1338509589036878
117.30000000000126,19.233743577011563,1.180391633316842,-0.1351491050164415
118.40000000000128,19.269438471877873,1.16765044349725,-0.13514083816280653
119.50000000000131,19.30487203479076,1.1542186291639185,-0.13596230942429965
120.60000000000132,19.340712336217614,1.140960181178293,-0.1377584834086658
121.70000000000132,19.375987399316823,1.1264983789021445,-0.13777244019447998
122.80000000000135,19.41149641245931,1.1131024009299515,-0.1389772438231791
123.90000000000137,19.446985424022962,1.0997968363406176,-0.14040740022505682
125.00000000000138,19.481370081190178,1.0871106438988705,-0.14040930520835637
126.10000000000139,19.51762958658562,1.0708081812895873,-0.14177883515317946
127.20000000000141,19.552128360500724,1.0627499055655902,-0.14173044690561065
128.30000000000143,19.588253765996054,1.049666973562231,-0.14172460570815515
129.40000000000146,19.623497481592597,1.0380745865481962,-0.14293464039179726
130.50000000000145,19.65849220938933,1.027802722933648,-0.1430399665249955
131.60000000000147,19.693486669737847,1.0186029961007947,-0.14304059421627757
132.7000000000015,19.72838347823882,1.0096973325163403,-0.14407499918491995
133.8000000000015,19.763608194189302,1.0003526441266737,-0.1457799602774119
134.9000000000015,19.7981383671035,0.9911703579691586,-0.14567945858358033
136.00000000000153,19.833034448837918,0.985622164109771,-0.14568008315211367
137.10000000000156,19.86798465657656,0.9786631887850457,-0.14567993734116857
138.20000000000158,19.902909484798673,0.9714936236494728,-0.14565830811117397
139.30000000000157,19.937541891397114,0.9665834484721647,-0.14600746098742956
140.4000000000016,19.972274877875304,0.958784492846812,-0.14612712052879662
141.50000000000162,20.006987384272083,0.957031519353773,-0.1473290171141235
142.60000000000161,20.04173276668263,0.9491902407724249,-0.14733013604434753
143.70000000000164,20.07629109291833,0.9451365665154862,-0.14733014012348056
144.80000000000166,20.111118810271876,0.9413057269270789,-0.14733014000020184
145.90000000000168,20.14557129836265,0.9391540812059829,-0.14733013999998557
147.0000000000017,20.18018588747183,0.9356231102463742,-0.14733014000000288
148.1000000000017,20.214674817730828,0.9351951748097335,-0.14733014000283262
149.20000000000172,20.249129002430998,0.9322556588004008,-0.14733013987854848
150.30000000000175,20.283702752232543,0.9364657241970068,-0.14733012012730917
151.40000000000174,20.317992011695175,0.933745859507974,-0.1473319685332597
152.50000000000176,20.351529286857556,0.9336173683052522,-0.1474501710814109
153.60000000000178,20.3861049730987,0.9324472028490992,-0.14864024268906828
154.7000000000018,20.420877476093498,0.9358323422879923,-0.14825254584394632
155.80000000000183,20.45526147355823,0.9350959314080862,-0.14764611687175044
156.90000000000182,20.489594852008217,0.9351900532417958,-0.14764999549968483
158.00000000000185,20.52388427817116,0.9357723647450035,-0.14764989278483887
159.10000000000187,20.557921946369653,0.9381342729225953,-0.14765737387486233
160.20000000000186,20.59227864656889,0.9427546806636112,-0.1465819619180868
161.3000000000019,20.626309386405293,0.9437913424062445,-0.14666172812204747
162.4000000000019,20.660694027006244,0.9440213682613171,-0.1466578918881205
163.50000000000193,20.694839996718795,0.9445957637105561,-0.1476650002282307
164.60000000000196,20.729124115768066,0.9482053563186882,-0.14825928607171512
165.70000000000195,20.76330285519172,0.949390638622719,-0.1489741221219658
166.80000000000197,20.797941892373032,0.952250508056457,-0.14908517948743594
167.900000000002,20.831758979973834,0.955690751658446,-0.1502914178282455
169.000000000002,20.865613259351193,0.9571112417964055,-0.1502899034928573
170.100000000002,20.89978931149328,0.9607026057558863,-0.15029457639318133
171.20000000000203,20.933878015131278,0.9647148662753292,-0.1491509312359196
172.30000000000206,20.96799284331915,0.9669065921476122,-0.14896970672822052
173.40000000000208,21.00187351510508,0.9688468727292981,-0.14896957100006114
174.50000000000207,21.035670490315916,0.9732448487952589,-0.14904164304754186
175.6000000000021,21.069936800710725,0.976375082374334,-0.14831023878102512
176.70000000000212,21.103815328747224,0.9790221179917834,-0.14831014008567056
177.80000000000211,21.137914533028926,0.9779460110978822,-0.14831004603779796
178.90000000000214,21.171928476068757,0.9840095696698414,-0.14830999016862112
180.00000000000216,21.205690007145694,0.9874741163769024,-0.14826013967063645
181.10000000000218,21.23939242011563,0.9909067326864218,-0.14896014921069733
182.2000000000022,21.27330785173908,0.993238931130881,-0.14896999722432147
183.3000000000022,21.307110983123426,1.001095854533618,-0.1489700417481341
184.40000000000222,21.34083114547063,1.0025855093766827,-0.14897003998991964
185.50000000000225,21.374525347991753,1.005526595803055,-0.1489700399998548
186.60000000000224,21.408258937785448,1.0088057645420931,-0.1489700399988929
187.70000000000226,21.44224941856528,1.0136890602751074,-0.14897004002742875
188.80000000000229,21.47575806615107,1.0170824813874328,-0.1489700454906968
189.9000000000023,21.509595550827513,1.0194891302775642,-0.148969488846042
191.00000000000233,21.542836072399567,1.0228774071825533,-0.14898330574439678
192.10000000000232,21.576432169297167,1.025933784909717,-0.1483107217498767
193.20000000000235,21.610088566474047,1.0301090160510733,-0.14930739669315507
194.30000000000237,21.643805671776587,1.0322524869047682,-0.1496304683824352
195.40000000000236,21.67727944341011,1.0335843805586056,-0.14962982371171174
196.5000000000024,21.710184715899214,1.0384478499527583,-0.14962983040997013
197.6000000000024,21.744288612773452,1.0416943046890506,-0.14962983890060455
198.70000000000243,21.777730658080344,1.0445667349751964,-0.14962629258738858
199.80000000000246,21.8115932469941,1.0467807942693805,-0.15098860394825042
200.90000000000245,21.844731060360505,1.05014954685137,-0.15094432830161741
202.00000000000247,21.878637679188945,1.053274490503519,-0.15229725675203643
203.1000000000025,21.91209463981717,1.05666337671167,-0.15227048889080042
204.2000000000025,21.945431203524713,1.0595219670400757,-0.15227152455772996
205.3000000000025,21.9785956591548,1.063331393900207,-0.15085993608953796
206.40000000000254,22.012211861729092,1.067021260926543,-0.15095058550981255
207.50000000000256,22.045535063907845,1.0711093216549181,-0.15095003887274272
208.60000000000258,22.079178930571235,1.074119635020568,-0.15094995286872948
209.70000000000258,22.112448153601246,1.0771824677728188,-0.15095242343844983
210.8000000000026,22.146213546468093,1.0786351896939073,-0.1519930440424706
211.90000000000262,22.179243382595168,1.081791054338569,-0.1519389150369599
213.00000000000261,22.21264726927261,1.0839750209748447,-0.1519467656209179
214.10000000000264,22.246058353217794,1.08790897234661,-0.1531169770739762
215.20000000000266,22.279431247485515,1.0919814963786956,-0.15336026986300277
216.30000000000268,22.31290206984372,1.0926308971410876,-0.15333204560578473
217.4000000000027,22.346223071845,1.09571500949584,-0.15472009789692054
218.5000000000027,22.379405488517794,1.1006388091201345,-0.15467995974769044
219.60000000000272,22.413001471702543,1.099972090942103,-0.15467982047845164
220.70000000000275,22.44615212479173,1.1025088946574262,-0.15477689041444087
221.80000000000274,22.479311094203435,1.1072517864198945,-0.15599666814705015
222.90000000000276,22.512597268263956,1.107431029621608,-0.15599967776283297
224.00000000000279,22.54544789567517,1.1107786871509342,-0.1559859423691181
225.1000000000028,22.579661567663656,1.1145767042835362,-0.15473943214908026
226.20000000000283,22.612623590873657,1.116275362687683,-0.15468071019100194
227.30000000000283,22.645916053236544,1.1184655255356197,-0.1545220906974123
228.40000000000285,22.679217813468846,1.120317647515903,-0.1573253441721434
229.50000000000287,22.712314053901235,1.12388972404869,-0.15732005893933776
230.60000000000286,22.745445166371805,1.1234687144982156,-0.15732130611200335
231.7000000000029,22.779095330743047,1.124068545516362,-0.15856886798728942
232.8000000000029,22.81209856235526,1.125040871240738,-0.1586344014403065
233.90000000000293,22.845474980846177,1.128745466540753,-0.15971496784452155
235.00000000000296,22.87837307158161,1.126554428199195,-0.15995115079493427
236.10000000000295,22.911307419884945,1.12996685952156,-0.16040647133282793
237.20000000000297,22.94483753855444,1.1293666327654803,-0.1612767220097564
238.300000000003,22.977838779826612,1.1304152987952645,-0.1612333640328325
239.400000000003,23.01069016305628,1.1314446093488386,-0.16166228187730747
240.500000000003,23.044531787821562,1.1304600229980184,-0.1615984122832148
241.60000000000304,23.077583388091316,1.1318818688161607,-0.16295933295787446
242.70000000000306,23.110607821187145,1.1356258367989214,-0.16293205344872197
243.80000000000308,23.143851070501654,1.1353824349306443,-0.1642136711989428
244.90000000000308,23.17704772925981,1.134742440398044,-0.164637125285223
246.0000000000031,23.210336645128574,1.1355380671534205,-0.16566250980525954
247.10000000000312,23.243323053192547,1.1330161187648207,-0.1669419578654776
248.20000000000312,23.276291413188115,1.1329282744181088,-0.16736302171459227
249.30000000000314,23.30948917820844,1.1328351442486406,-0.16796947642391746
250.40000000000316,23.342515113229148,1.132694098817856,-0.16928419567481923
251.50000000000318,23.376095152044858,1.1327431059686472,-0.16961497819460503
252.6000000000032,23.408771177494643,1.134069469636751,-0.1709290347713992
253.7000000000032,23.441995001959757,1.1327017615254569,-0.17278813469641774
254.80000000000322,23.475168542042738,1.1330928346338613,-0.17362865345405432
255.90000000000325,23.508056097368407,1.131405930628207,-0.17502283079753145
257.00000000000324,23.541384422790856,1.134007212932272,-0.17646222462164918
258.10000000000326,23.574618747099517,1.134335304760698,-0.178030895268944
259.2000000000033,23.60726789982816,1.1331048936238306,-0.17970828169493824
260.3000000000033,23.640186991657963,1.134029345758788,-0.18124873380523
261.40000000000333,23.673443450772982,1.1343612577325624,-0.18249844205191934
262.5000000000033,23.70664536676887,1.1315968794745208,-0.18411105131883598
263.6000000000033,23.739068932877903,1.1332656128666434,-0.18610420677705708
264.70000000000334,23.772013053740103,1.131796658898636,-0.18860078713423256
265.80000000000337,23.80548227614892,1.1300765832292168,-0.1902912268720165
266.9000000000034,23.83895872191766,1.1293492199890134,-0.19187253407580984
268.0000000000034,23.871471446504746,1.131784296978486,-0.1944813224739823
269.10000000000343,23.90506066853511,1.1284216872866315,-0.19674143448961745
270.20000000000346,23.938366138109284,1.1273538620169634,-0.20016781947261464
271.3000000000035,23.971142186057968,1.1274786062377866,-0.20193055585613662
272.4000000000035,24.004464102093756,1.1279962781269246,-0.20348739779381209
273.5000000000035,24.03761937409984,1.1291779098963322,-0.20619351450706347
274.6000000000035,24.0700319243852,1.126659552194868,-0.2092540167537078
275.7000000000035,24.103763340673357,1.1251901879624668,-0.21341178203529276
276.80000000000354,24.13689888759436,1.1256898434102194,-0.21660671549730726
277.90000000000356,24.169939695559442,1.123825456332399,-0.21905475221024107
279.0000000000036,24.203203636366013,1.1210804181429455,-0.2223126059693481
280.10000000000355,24.235997886632493,1.1197152286247047,-0.22631646639188618
281.20000000000357,24.26926615974954,1.1208020152366593,-0.22993481450537256
282.3000000000036,24.30245576638113,1.1214689342586552,-0.2340253310524072
283.4000000000036,24.335778595772847,1.121653587620599,-0.23920241678158982
284.50000000000364,24.36866087246898,1.120218986893976,-0.24336125312112777
285.60000000000366,24.40213240619072,1.1174920430629391,-0.2488477899904158
286.7000000000037,24.434957891942638,1.1185519799258947,-0.25426336247146875
287.8000000000037,24.46824348767027,1.1188847196202487,-0.2590807379662152
288.90000000000373,24.501299296260513,1.1176851959580691,-0.2648079011902529
290.00000000000375,24.53432420942685,1.1180348882075444,-0.2695232433454038
291.1000000000037,24.567668188977876,1.117544764787182,-0.27424750479212356
292.20000000000374,24.600677734334703,1.116881831694541,-0.2806690293473153
293.30000000000376,24.633861157807896,1.117386045470587,-0.2884551424854065
294.4000000000038,24.666994343416782,1.1164962685965198,-0.2943464201978463
295.5000000000038,24.700565667465128,1.1154797175364721,-0.2996279760104916
296.60000000000383,24.733527544607792,1.1176087371036023,-0.30688252005998384
297.70000000000385,24.76668589152683,1.1176255642021902,-0.3134453770651944
298.8000000000038,24.8001477334581,1.1188085505841403,-0.32267935179866436
299.90000000000384,24.833252262776302,1.1176887838220915,-0.3304816053879449
301.00000000000387,24.866366176599698,1.1235239811831828,-0.33889678783400434
302.1000000000039,24.899553112693965,1.124423892648377,-0.34908593950131017
303.2000000000039,24.932770122004175,1.1276498485560587,-0.35713097571254426
304.30000000000393,24.966272592418868,1.1289093581231109,-0.3656292005433106
305.40000000000396,24.999435598993497,1.1336928498012078,-0.375392286310694
306.500000000004,25.03203377992408,1.1373813479111046,-0.38567458054499815
307.600000000004,25.066099534841392,1.1392467220143152,-0.39660204953855205
308.70000000000397,25.09910147898671,1.141977558850415,-0.4073023778495921
309.800000000004,25.132632890067867,1.1475326965815886,-0.4174010071497065
310.900000000004,25.166043180740523,1.1500878262274528,-0.4284963687962504
312.00000000000404,25.198964781833997,1.1535020101030071,-0.44020784439630667
313.10000000000406,25.23256059890315,1.1564814196920552,-0.4516680586227553
314.2000000000041,25.26622827084711,1.1608182810367975,-0.46490394657738454
315.3000000000041,25.29875028799394,1.165113221845078,-0.4786789542900749
316.40000000000407,25.332816242089457,1.1697566343191625,-0.4922774597586428
317.5000000000041,25.366152068937534,1.1766433988336473,-0.5062567667427329
318.6000000000041,25.398888512738786,1.180481496080642,-0.5191599031501357
319.70000000000414,25.43302056001957,1.1855478365048628,-0.5342448396740451
320.80000000000416,25.466465115839746,1.1911782003753284,-0.5500275434153936
321.9000000000042,25.499212985348017,1.1946180599335474,-0.5651905456324795
323.0000000000042,25.533351277381065,1.2015121451687862,-0.5820359733680687
324.10000000000423,25.56672357592508,1.207063891622587,-0.5976449685346537
325.20000000000425,25.600092706878247,1.2126204322427203,-0.6141760817163879
326.3000000000042,25.633737493886848,1.2192943540072856,-0.6323897658678934
327.40000000000424,25.66720496310324,1.2273835186027093,-0.6516956950451975
328.50000000000426,25.700825961840312,1.2328474654195853,-0.6705695939356167
329.6000000000043,25.734282431068,1.2423921602970547,-0.6884565825514763
330.7000000000043,25.76711826746975,1.2516731760509794,-0.7074705695769214
331.80000000000433,25.800517101314682,1.259447214206106,-0.7278408728798214
332.90000000000435,25.83412677872437,1.2718609938590595,-0.7493404810384652
334.0000000000043,25.868116612507592,1.2802483450300082,-0.7703458542543151
335.10000000000434,25.9012070989653,1.2905061122315522,-0.7918551476659248
336.20000000000437,25.935153280258756,1.2990640777360767,-0.8135579188466551
337.3000000000044,25.968704456066096,1.3092500042621908,-0.8356655369525492
338.4000000000044,26.002267700871478,1.3166615467435292,-0.8599171415127413
339.50000000000443,26.036148721093245,1.3258039662983305,-0.8846126724731187
340.60000000000446,26.069939754576676,1.3352719665685058,-0.9098437462216937
341.7000000000045,26.103405080067944,1.3431368924764993,-0.9353520479749795
342.8000000000045,26.137250165571853,1.3556221609793,-0.9612690667800172
343.90000000000447,26.17074566207648,1.3643333362429375,-0.9869969629800472
345.0000000000045,26.204649820717535,1.3741376543862414,-1.0137837915135286
346.1000000000045,26.23909941009195,1.384778769845526,-1.0423039831731713
347.20000000000454,26.27272422219029,1.3974075116081306,-1.071203643520584
348.30000000000456,26.30690414941466,1.4124052238763767,-1.1017761328281992
349.4000000000046,26.34037616692378,1.4246937749981474,-1.1322061621080275
350.5000000000046,26.374639169279295,1.4378067982236127,-1.1617506646788738
351.60000000000457,26.408328340664585,1.4521563839159846,-1.1911953096209875
352.7000000000046,26.442557196949572,1.466536407904451,-1.2249802677823403
353.8000000000046,26.476393570129282,1.4842125230218521,-1.2590283819915853
354.90000000000464,26.51021835380355,1.502596967445734,-1.2936583701342612
356.00000000000466,26.544396792488634,1.5210310758201242,-1.3309001990910692
357.1000000000047,26.577613620094443,1.5399548836623969,-1.3668276652030262
358.2000000000047,26.61144531794598,1.5564549330106907,-1.4037662268816846
359.30000000000473,26.64583164395685,1.5799378267129842,-1.4413229050220764
360.40000000000475,26.6802830680152,1.6015953152211624,-1.4806344023111269
361.5000000000047,26.71440728620331,1.6198682187698703,-1.5211568301449918
362.60000000000474,26.748674819895307,1.6427452695043137,-1.5627005438309993
363.70000000000476,26.782853425611524,1.665882206369457,-1.6066172894640043
364.8000000000048,26.816895261203776,1.6866913568971449,-1.6491797029900854
365.9000000000048,26.851158883726665,1.7051684844297057,-1.6914403617010092
367.00000000000483,26.88512102345885,1.725783415545381,-1.73422718269171
368.10000000000485,26.91928446191794,1.7440875310377968,-1.7804765367028432
369.2000000000048,26.953401415899023,1.7618395229753012,-1.8282047520834928
370.30000000000484,26.98746281297226,1.7741911338938858,-1.8776392124890098
371.40000000000487,27.02154314435961,1.7847654105418556,-1.9273954979742998
372.5000000000049,27.055590245239117,1.7908178173428944,-1.9752315555100433
373.6000000000049,27.089725619129936,1.792921256067813,-2.0219657039574956
374.70000000000493,27.123639334309654,1.79126052267377,-2.070668433318885
375.80000000000496,27.15762392037724,1.7806853433003975,-2.120367146006502
376.900000000005,27.19140484564833,1.7606084660806964,-2.17050300297396
378.000000000005,27.225056946168163,1.738018855663215,-2.2213746533187884
379.10000000000497,27.258438801024667,1.7072495250367183,-2.2701951762414376
380.200000000005,27.291994981033074,1.6703706858268337,-2.3148122695655697
381.300000000005,27.325804274987117,1.6262005425964108,-2.360432379333446
382.40000000000504,27.358882801002114,1.5744052728623834,-2.404671129918153
383.50000000000506,27.39217493562994,1.5131300695649161,-2.4480849314670037
384.6000000000051,27.425329633661434,1.4485069894758011,-2.4902488573907786
385.7000000000051,27.45868655746756,1.3787050458996701,-2.527798308555166
386.80000000000507,27.491522821823363,1.3070466250176942,-2.5605835419479375
387.9000000000051,27.524764611947088,1.2327129937598296,-2.5940711624182127
389.0000000000051,27.55779420899936,1.1583183702117634,-2.6250758746093124
390.10000000000514,27.590974074296167,1.081108800789539,-2.6532249725444212
391.20000000000516,27.624128663836878,1.0076165989548016,-2.6788835049042956
392.3000000000052,27.657228592150418,0.9380455433543333,-2.7008552396720638
393.4000000000052,27.690431971384953,0.8707510839251891,-2.7198416183193603
394.50000000000523,27.723765062179243,0.8058005971516864,-2.738512445236651
395.60000000000525,27.757202990916312,0.7442808965169756,-2.7556019344361644
396.7000000000052,27.79024236834997,0.6857479866169047,-2.7700189178559675
397.80000000000524,27.823466792288574,0.6290694743506111,-2.7838016243289854
398.90000000000526,27.85694825729484,0.5757705648387129,-2.7955202653002575
400.0000000000053,27.89027431517877,0.5280438020704639,-2.8056164865109334
401.1000000000053,27.923941692356326,0.48306255845355084,-2.815453703346476
402.20000000000533,27.95756830186972,0.43902730195748435,-2.8228713765495748
403.30000000000535,27.991437444411215,0.3983808420513394,-2.8306203498766895
404.4000000000053,28.02456094298748,0.366160745961825,-2.836083634498426
405.50000000000534,28.058268170326237,0.3318242571543794,-2.841813019971454
406.60000000000537,28.092557929022277,0.3041615328717028,-2.8480023871365248
407.7000000000054,28.125940220643415,0.2796503794949323,-2.8522435045618355
408.8000000000054,28.159813865971863,0.257342033923738,-2.8567611236477077
409.90000000000543,28.193707713314744,0.23916981140011245,-2.861345956159375
411.00000000000546,28.227817994209513,0.2249299327663219,-2.8634497674770607
412.1000000000055,28.261914563956427,0.21044782891040914,-2.867563254151343
413.2000000000055,28.295926581863252,0.19737788162915698,-2.8718467915992685
414.30000000000547,28.329812290840902,0.18589676433918728,-2.8758705745680153
415.4000000000055,28.364563524364367,0.17538479378591038,-2.8787969673539493
416.5000000000055,28.3985695534404,0.1670572016613432,-2.881278306930293
417.60000000000554,28.432691047593565,0.15721265015169944,-2.8845505212241354
418.70000000000556,28.467077003533728,0.14811008661123992,-2.8871185774503205
419.8000000000056,28.501271499956243,0.1412043758854834,-2.8918116589365797
420.9000000000056,28.535018873781134,0.13454352778214346,-2.8950565250123628
422.00000000000557,28.5694756242737,0.12698027302084536,-2.897493946145785
423.1000000000056,28.60412714873058,0.12076363707951493,-2.8997220199067497
424.2000000000056,28.63831555940926,0.11245207713232946,-2.9029359866916744
425.30000000000564,28.672649582311013,0.10884950160456108,-2.9078481670186016
426.40000000000566,28.706946251261233,0.10066762893688408,-2.910821492164052
427.5000000000057,28.74126647785208,0.0947054848083363,-2.913939343848474
428.6000000000057,28.774943605944415,0.09045197254874121,-2.9171825289161086
429.70000000000573,28.81025799007237,0.08374566251303067,-2.9204758391438257
430.80000000000575,28.844392373788377,0.07646702896618285,-2.9232799714148445
431.9000000000057,28.878742568700503,0.07507842715049196,-2.9263423929516112
433.00000000000574,28.913533104460807,0.06843094884500722,-2.9301767507758756
434.10000000000576,28.947816600392457,0.0652810984767156,-2.933465822901813
435.2000000000058,28.981720882021357,0.06254239742091117,-2.9353834560820697
436.3000000000058,29.016881350872918,0.05946142295169887,-2.939628337186666
437.40000000000583,29.05142123636196,0.05347916125877883,-2.9433111438301935
438.50000000000585,29.086045733825028,0.055277793696450306,-2.9461621858397034
439.6000000000058,29.120523021222578,0.05074500102097923,-2.949589194605153
440.70000000000584,29.15503339798909,0.050300250833983595,-2.952729225294644
441.80000000000587,29.189814376537885,0.050942795557791465,-2.954910686827215
442.9000000000059,29.22433602325831,0.049961937510269616,-2.9582496505552043
444.0000000000059,29.25910533690904,0.05284669012491172,-2.961186625202475
445.10000000000593,29.293561013205377,0.05350695482754603,-2.9632196301213236
446.20000000000596,29.328321177445197,0.05386568294781746,-2.9661454192566685
447.300000000006,29.36232170168114,0.05363150391503224,-2.968870502053801
448.400000000006,29.397674258604656,0.05682970595257658,-2.971845657594533
449.50000000000597,29.432201533074345,0.057942546217182145,-2.974336684096701
450.600000000006,29.467092063882905,0.05804959569630902,-2.977404462874526
451.700000000006,29.50159691443984,0.061452913082638116,-2.9792184088766946
452.80000000000604,29.536334021201938,0.060181587296008865,-2.9821796849795996
453.90000000000606,29.57083261815978,0.06421816092447707,-2.9851214593269972
455.0000000000061,29.605966458184106,0.06904280426943998,-2.989368144547334
456.1000000000061,29.640725525790486,0.06935765822588819,-2.9923222826816507
457.20000000000607,29.675029104359183,0.07240313549400723,-2.994692801379514
458.3000000000061,29.7098015807031,0.07672303556588156,-2.9963346271262434
459.4000000000061,29.74493407140991,0.08111919510978699,-2.9971113942203385
460.50000000000614,29.78015782029623,0.08439350904242349,-2.9999454484567947
461.60000000000616,29.814985485075418,0.08960755348134641,-3.002356498480623
462.7000000000062,29.849840133760498,0.09245326455657699,-3.0067325516807433
463.8000000000062,29.884528972162023,0.0964149481804712,-3.0085707642140767
464.90000000000623,29.919595232663834,0.10184551355643362,-3.011518420406549
466.00000000000625,29.95465613029786,0.10833398678166373,-3.01366567975217
467.1000000000062,29.989454778560088,0.11321389019563421,-3.0159105290531465
468.20000000000624,30.024033772409947,0.11521932261213452,-3.018496114409139
469.30000000000626,30.0590985385371,0.12052114443328021,-3.019919893570605
470.4000000000063,30.094055769146802,0.1243469281889234,-3.021367497686004
471.5000000000063,30.129206927068246,0.12804960032662277,-3.023794896622112
472.60000000000633,30.16339272699088,0.13302173410013868,-3.0262459786029043
473.70000000000636,30.1988235129828,0.13785288826566844,-3.027919529929571
474.8000000000063,30.23391629905813,0.14326061481424185,-3.0300190904875124
475.90000000000634,30.2688279612818,0.1440057025352185,-3.032809591434757
477.00000000000637,30.303998661270626,0.14678702332159843,-3.034858913989969
478.1000000000064,30.339042742147438,0.1514706462488069,-3.0360044953033816
479.2000000000064,30.373962795045106,0.155894244367755,-3.0375698188819875
480.30000000000643,30.408826136124027,0.15523354748777862,-3.040565058272589
481.40000000000646,30.44379959816998,0.1603688713408406,-3.0422384222152914
482.5000000000065,30.479018589145802,0.16118598233744286,-3.0436986390294303
483.6000000000065,30.514309189962155,0.16511320438612076,-3.0455754852579533
484.70000000000647,30.549111372058746,0.16754842122411473,-3.0468764249960603
485.8000000000065,30.584067906012866,0.16960470656104853,-3.0487528525640366
486.9000000000065,30.619308246068183,0.17279863290764086,-3.0516006773520474
488.00000000000654,30.654558800135113,0.17684869870349085,-3.053102175538858
489.10000000000656,30.689159587373176,0.1770184607306199,-3.0546453982407114
490.2000000000066,30.72445698953653,0.17867259193737184,-3.0554489491007746
491.3000000000066,30.75970858966508,0.1828993615632225,-3.0570061296723594
492.40000000000657,30.794789736327907,0.1856645673775722,-3.0590174615855403
493.5000000000066,30.829968577125875,0.18746055622364066,-3.0611868530824697
494.6000000000066,30.865108832401262,0.18989195397367975,-3.0628071673664943
495.70000000000664,30.90003119866054,0.193127532707272,-3.0653261159059637
496.80000000000666,30.935525926490115,0.19561447644200525,-3.0665846940625032
497.9000000000067,30.9706471276499,0.19678697094258424,-3.068577982406378
499.0000000000067,31.005683634999105,0.19967702482140803,-3.070660226083417
500.10000000000673,31.040874806425563,0.20316018477933484,-3.0718433999056405
501.20000000000675,31.076280377750212,0.2045591040015472,-3.073349545925037
502.3000000000067,31.111195316580794,0.20292512899435422,-3.0747977747219224
503.40000000000674,31.146775986296063,0.20586501771066346,-3.0761087968358214
504.50000000000676,31.181870441214674,0.206838315035054,-3.0779056754829153
505.6000000000068,31.21717319341989,0.21061491786280084,-3.0783799833485856
506.7000000000068,31.252486064950542,0.21078768590276253,-3.079269096432112
507.80000000000683,31.28734672609077,0.21440191764619465,-3.080780603703246
508.90000000000686,31.32268747183602,0.21672173332145395,-3.0833236911523128
510.0000000000068,31.358587516850854,0.21914614297639357,-3.084676347621497
511.10000000000684,31.393619913139762,0.21756802878267656,-3.0864982628445903
512.2000000000069,31.428907351284618,0.2204623744316161,-3.087656803989184
513.3000000000069,31.464083608063515,0.21869429552885922,-3.089014217792731
514.4000000000069,31.49960067922637,0.21833589219988914,-3.0899236014718334
515.5000000000069,31.534931496143518,0.22212409554954216,-3.091354373941846
516.600000000007,31.570063491261113,0.2227015545748683,-3.0920799200275084
517.700000000007,31.605858862830864,0.22311292942326721,-3.0936752233871125
518.800000000007,31.64099984486164,0.2264794916618632,-3.0949774301518405
519.9000000000069,31.67634152699637,0.22464279290204425,-3.096493356506378
521.000000000007,31.711862115639562,0.23014031441831206,-3.098410740676223
522.100000000007,31.747308744036566,0.2300793085409163,-3.098550735911572
523.2000000000071,31.782672089679473,0.2309291000809175,-3.099866442121505
524.300000000007,31.81821616497462,0.23199096758672466,-3.1011626431042565
525.4000000000071,31.853684265381474,0.23141904391117563,-3.1026696766271487
526.500000000007,31.8892266743918,0.23749730162515004,-3.1041386890828493
527.6000000000071,31.924536458918926,0.23466474275432325,-3.1055273945446977
528.7000000000071,31.960512442511565,0.24030327347548353,-3.1069606693522793
529.8000000000071,31.995790300618854,0.2400801058127099,-3.1083326247341083
530.9000000000071,32.03147006005576,0.24353632853888185,-3.108392175381697
532.0000000000072,32.06649734035933,0.2441447289071912,-3.109600818063151
533.1000000000072,32.1023651146808,0.24691048132598903,-3.1107499183795335
534.2000000000072,32.13798964910808,0.2546304434464668,-3.111722068322357
535.3000000000072,32.17355879896514,0.26097503290492985,-3.113004950215063
536.4000000000073,32.209219520402485,0.2690271025521882,-3.114371734028778
537.5000000000073,32.2448207741599,0.27411228754640327,-3.115461274700559
538.6000000000072,32.28062042068277,0.2799611162390836,-3.1169745264382036
539.7000000000073,32.31576063330353,0.2862425352479744,-3.118300580103039
540.8000000000072,32.35170015287911,0.2920192982828078,-3.119638469539634
541.9000000000073,32.387459579914335,0.29402551282296496,-3.11955694784156
543.0000000000073,32.423122572325966,0.2975091573326498,-3.121136527328198
544.1000000000073,32.45860999814147,0.2995464155585922,-3.1225484784801667
545.2000000000073,32.49447502439477,0.3010591962206747,-3.1238507443778225
546.3000000000073,32.53053689721498,0.3035804655320764,-3.124585460913295
547.4000000000074,32.56601916682027,0.3086507191062946,-3.1251533522500354
548.5000000000074,32.60172862521876,0.30958178817287896,-3.1263530349362854
549.6000000000074,32.637430483648444,0.31312876358708874,-3.126647183554318
550.7000000000074,32.673465977641314,0.3171662432684581,-3.126564702642434
551.8000000000075,32.708973922998446,0.3182556446029201,-3.1279502726255637
552.9000000000075,32.74453183675996,0.3171435879433214,-3.1289840725832647
554.0000000000075,32.7805953423727,0.32165246879353526,-3.130603946241429
555.1000000000075,32.81640745141727,0.32498661146888175,-3.1319911579322044
556.2000000000075,32.85226562043611,0.3261648141167466,-3.1333016418750956
557.3000000000076,32.88787056702152,0.3275806002194833,-3.1346427471302185
558.4000000000076,32.92388389646754,0.33049558336934237,-3.1347903235311168
559.5000000000075,32.9594502271087,0.3342915407581796,-3.136057404838747
560.6000000000075,32.994700256922805,0.33456874941034687,-3.135664665765938
561.7000000000075,33.0305772339119,0.33489773252116684,-3.1370934367618917
562.8000000000076,33.06711746492086,0.33516077262036426,-3.137576531645202
563.9000000000076,33.10285337944221,0.3353090576607626,-3.13832300989043
565.0000000000076,33.13891267564106,0.33667797481517203,-3.1392729243454944
566.1000000000076,33.1746295329807,0.34376816363260587,-3.1404629435034566
567.2000000000077,33.210391797457994,0.3416800611247264,-3.1417643828640793
568.3000000000077,33.24659335541861,0.34474633646019026,-3.1416717101309075
569.4000000000077,33.28235535844523,0.34519404985615176,-3.1430436032679587
570.5000000000077,33.31857896528037,0.34511994398924484,-3.1445250680570997
571.6000000000078,33.354297509364315,0.34681814195774285,-3.145298153347738
572.7000000000078,33.39048510381177,0.3466485400890046,-3.1458297388373753
573.8000000000078,33.42630658574626,0.34648748538732166,-3.1468307681249272
574.9000000000078,33.46239335387158,0.34435454465617443,-3.1477326530739074
576.0000000000077,33.49823350960949,0.34407544886830876,-3.148584008042824
577.1000000000078,33.534401240626494,0.3447264838576697,-3.1499953448303244
578.2000000000078,33.57031536731483,0.34738107692011344,-3.149568325712657
579.3000000000078,33.60610781346164,0.3485816135200641,-3.1507065671321275
580.4000000000078,33.64233225481938,0.3446331088910791,-3.150900476873103
581.5000000000078,33.67825065159345,0.34414073594890915,-3.15219639306109
582.6000000000079,33.71450673283399,0.3431528490061643,-3.1530074647068176
583.7000000000079,33.75051480792743,0.3448784093262217,-3.1535607536728265
584.8000000000079,33.78649262278824,0.34622051085041006,-3.1547518018324268
585.9000000000079,33.822431134351376,0.34539558711103613,-3.1549934209118162
587.000000000008,33.858543115489276,0.34647745661110263,-3.155167744573172
588.100000000008,33.895050176931605,0.3470645359400535,-3.156276408911359
589.200000000008,33.93086591745949,0.34560126825660975,-3.157656492896663
590.300000000008,33.96723143682568,0.3456758925865998,-3.1580713428661493
591.400000000008,34.00309149732123,0.3456878384741435,-3.159255622798324
592.5000000000081,34.0395819926257,0.3469024767249529,-3.160536521830407
593.6000000000081,34.07553903511657,0.3443813321296817,-3.1605510210419965
594.700000000008,34.11172308411741,0.3432629090941085,-3.161935648131826
595.800000000008,34.14799417649481,0.3441384407573449,-3.1618693590683487
596.900000000008,34.184245317827106,0.34762028721364324,-3.1618701171132955
598.0000000000081,34.22050214528039,0.34551832660319326,-3.1618715811874005
599.1000000000081,34.256395133977975,0.3461351547297584,-3.1632764132713618
600.2000000000081,34.29270916188537,0.34458375699521826,-3.1645867159536825
601.3000000000081,34.32915463777505,0.3455106016753674,-3.1658743157083586
602.4000000000082,34.365252169508345,0.3459681319531175,-3.165952395229213
603.5000000000082,34.40127021975617,0.34433228762334456,-3.1672536345602538
604.6000000000082,34.43777711488753,0.34624197869728934,-3.1669293828045175
605.7000000000082,34.47438804079979,0.3442382073537694,-3.168276455566474
606.8000000000083,34.51049259624634,0.3448064186864841,-3.1669277214866325
607.9000000000083,34.546547324302566,0.3410841453320582,-3.1682128106338476
609.0000000000083,34.58299190767303,0.3436104668047184,-3.168238231937348
610.1000000000083,34.6192708957097,0.34416361768504966,-3.169525392164992
611.2000000000082,34.65554142757501,0.3432944441530468,-3.169495327126174
612.3000000000083,34.69215030493144,0.34031757500558035,-3.1708578033958936
613.4000000000083,34.72845567900246,0.3456834561809391,-3.1708661658459323
614.5000000000083,34.76474809129282,0.34117232501688866,-3.1721621799755684
615.6000000000083,34.80086736110338,0.34023175591802524,-3.172921843058983
616.7000000000083,34.837229834057005,0.3381013563264128,-3.1735042380851888
617.8000000000084,34.873895725866824,0.3433547311797329,-3.173780379278214
618.9000000000084,34.90993267289547,0.34175819277994657,-3.1758115255764916
620.0000000000084,34.94630504898173,0.3443492399975553,-3.17590558318406
621.1000000000084,34.98293380462474,0.3444552514870892,-3.1744671744628348
622.2000000000085,35.019449551976955,0.34349039781004664,-3.176421409688946
623.3000000000085,35.05563476180565,0.34478116536902925,-3.1789011746815414
624.4000000000085,35.0922274468621,0.3466271675435235,-3.179324957530886
625.5000000000085,35.128473592359036,0.3488561667917105,-3.1794575122562705
626.6000000000085,35.16450198776323,0.3500019004591496,-3.1792743266178407
627.7000000000086,35.20133816851181,0.3535106613144172,-3.1806312748215797
628.8000000000086,35.23759442454889,0.3553721866395032,-3.1806398363573334
629.9000000000085,35.273889914200865,0.35521307579346784,-3.181380625858511
631.0000000000085,35.310564743878125,0.3559285455104745,-3.181631111001472
632.1000000000085,35.346688679615966,0.3585227291723724,-3.180944562290177
633.2000000000086,35.383423147290344,0.3611399489294127,-3.1819662742678507
634.3000000000086,35.4201008863482,0.35871099320735933,-3.1832730891720105
635.4000000000086,35.456325211136544,0.36164683556596733,-3.1832703385816297
636.5000000000086,35.49296527221129,0.36366049765350494,-3.183402195764073
637.6000000000087,35.5294108390581,0.363097516415258,-3.1845905962644405
638.7000000000087,35.56574413562857,0.3656705196858675,-3.183306927728383
639.8000000000087,35.602311330502054,0.3666196716426262,-3.184554599064874
640.9000000000087,35.63811521062148,0.36470199463682507,-3.1862824294299514
642.0000000000088,35.67532384246196,0.36735479757253187,-3.1875947204539865
643.1000000000088,35.71180029225706,0.3707105281762695,-3.188668276712411
644.2000000000088,35.747841380017995,0.3699708411971887,-3.188778229552509
645.3000000000088,35.78510852582226,0.3722605019256712,-3.1901400735980454
646.4000000000087,35.821198720573605,0.37959479775534655,-3.1915022501823422
647.5000000000088,35.857978909373685,0.3802574041188592,-3.1915838463010875
648.6000000000088,35.894740478619326,0.3873958195510653,-3.1902029393220515
649.7000000000088,35.93137491229848,0.39285768691476974,-3.190646078544188
650.8000000000088,35.967804132146725,0.3966439599843262,-3.1915126141476255
651.9000000000088,36.004628854056584,0.39820145714906374,-3.1923757603771596
653.0000000000089,36.04057174475515,0.4058098296499243,-3.1929590911320833
654.1000000000089,36.07782382560708,0.40995242505472884,-3.1942530056024205
655.2000000000089,36.114618094832885,0.41730153772885736,-3.1942571379642435
656.3000000000089,36.15062281758085,0.42289480960645076,-3.1949721235964192
657.400000000009,36.18773044328548,0.42922092699474523,-3.1955714126930985
658.500000000009,36.22459094789864,0.4321300474705213,-3.1954838198211712
659.600000000009,36.261276587724865,0.4368909188046698,-3.196889276202093
660.700000000009,36.298022080338754,0.44693073739289013,-3.198060458339134
661.800000000009,36.334414452512526,0.4522407923045709,-3.198162179521971
662.9000000000091,36.37107080742629,0.455957552006075,-3.199522596073365
664.0000000000091,36.40776394231751,0.46607075162105605,-3.199529581814795
665.100000000009,36.44449656765926,0.47272202817967723,-3.200725260619717
666.200000000009,36.48129851838905,0.4788044882228921,-3.1999617403425944
667.300000000009,36.517924595126736,0.48670145080936045,-3.2019484151575384
668.4000000000091,36.55468862392716,0.4926997238077826,-3.2037078073990557
669.5000000000091,36.591458375763054,0.5006710618624648,-3.2050603604196186
670.6000000000091,36.62793297382571,0.5050398927859943,-3.2041296345127783
671.7000000000091,36.664708149007254,0.5091884017428474,-3.205349252083381
672.8000000000092,36.70116592140631,0.5176684370925053,-3.2064190373403787
673.9000000000092,36.73777041092849,0.5188946788087905,-3.2050247516758095
675.0000000000092,36.77445302884229,0.525474762017025,-3.2064295209324767
676.1000000000092,36.81093159787387,0.5306347043840942,-3.2063211458595524
677.2000000000093,36.84757194190831,0.53573196509068,-3.2076764353479197
678.3000000000093,36.88356925554717,0.5418735211963808,-3.207951851429006
679.4000000000093,36.920741061757994,0.542725845694219,-3.209465623870888
680.5000000000093,36.95752518729042,0.5444007324647282,-3.210420208341639
681.6000000000092,36.99420216695218,0.5528595147721311,-3.2117270333481347
682.7000000000093,37.0310985458223,0.5545747933275147,-3.213065256685746
683.8000000000093,37.067522029783106,0.5556291739829753,-3.214403198992085
684.9000000000093,37.10428263806005,0.5568126490581806,-3.2156779109963565
686.0000000000093,37.140882111603936,0.5563081205593476,-3.215839983783965
687.1000000000093,37.17765023898508,0.5531343330624645,-3.2161511152606677
688.2000000000094,37.213734592369505,0.5490166362275988,-3.216422631839192
689.3000000000094,37.25138018222265,0.5426091867686207,-3.217415876141586
690.4000000000094,37.2879507490284,0.5423895374446837,-3.2187164521416443
691.5000000000094,37.324498419699566,0.5338685603987445,-3.219748864128463
692.6000000000095,37.36118126492195,0.5225888334656166,-3.220054386589954
693.7000000000095,37.39774844648009,0.5143957166724273,-3.221371393296555
694.8000000000095,37.43428526146948,0.510436322843949,-3.222728283884808
695.9000000000095,37.471170924547536,0.49770746854182013,-3.2226594742664334
697.0000000000095,37.5076655063827,0.4861592964230512,-3.2240028083897028
698.1000000000096,37.54411803599394,0.4771981665521774,-3.2240502143732206
699.2000000000096,37.58068510181238,0.4594820814351501,-3.224998143213781
700.3000000000095,37.61731441224867,0.4438606264038907,-3.2263610644621092
701.4000000000095,37.654285039875944,0.4259561748032501,-3.226299628486274
702.5000000000095,37.69071041373243,0.4086177177204937,-3.2260470569315727
703.6000000000096,37.72755811729368,0.3963518294231052,-3.2263115456699127
704.7000000000096,37.76378526824488,0.38401230483765336,-3.2265008047689476
705.8000000000096,37.80063800955823,0.3763047628827245,-3.227631215200864
706.9000000000096,37.83760754565258,0.36554608938480193,-3.227631618399177
708.0000000000097,37.8738574055343,0.36091737160031845,-3.227968853566629
709.1000000000097,37.910743254656836,0.3593580262104328,-3.2289537817953904
710.2000000000097,37.94741733446347,0.35211206617655444,-3.2302534771729174
711.3000000000097,37.98433814979114,0.35626379889830617,-3.2302646004994164
712.4000000000098,38.02092221187002,0.34947838876085924,-3.231305766719693
713.5000000000098,38.057340316658504,0.34795568883579997,-3.2302541174866413
714.6000000000098,38.09413789336837,0.3464937029970454,-3.2303114642386745
715.7000000000098,38.131383731794514,0.3481480039363458,-3.231584491538478
716.8000000000097,38.168429037630666,0.3490569078867265,-3.2315800591174564
717.9000000000098,38.204777455076986,0.34681823751786567,-3.231580198961807
719.0000000000098,38.24190789018084,0.34643606372836877,-3.2315901384942576
720.1000000000098,38.27848204836444,0.3476581967235748,-3.2328920251139532
721.2000000000098,38.31471766469747,0.3459801405444054,-3.232892220973678
722.3000000000098,38.35177689801161,0.3477108932347508,-3.233905448481262
723.4000000000099,38.38876011112877,0.3491331402307991,-3.2328934631345283
724.5000000000099,38.42555402323587,0.3455202695499733,-3.233984024324548
725.6000000000099,38.462523030202945,0.34892200116268457,-3.2342091132909387
726.7000000000099,38.49862846270736,0.34491582205021554,-3.2342106627298897
727.80000000001,38.53617063616208,0.34628785841385357,-3.2345466652915125
728.90000000001,38.5728293444367,0.34847071005078534,-3.2356442569793704
730.00000000001,38.61020216358862,0.34353328767388613,-3.235640121776282
731.10000000001,38.646994945060975,0.34573912926143935,-3.2356417056872253
732.20000000001,38.68397946738298,0.3387683750547723,-3.2370584090353707
733.3000000000101,38.72074929118501,0.3409663791949018,-3.2369649997169514
734.4000000000101,38.75800044934275,0.33899081315395185,-3.238322469026914
735.50000000001,38.794946956623065,0.3401540104659615,-3.2369722729551045
736.60000000001,38.832068923996694,0.33724181411735366,-3.236958314818466
737.70000000001,38.868950080325355,0.33559805157307254,-3.238289108935188
738.8000000000101,38.90633617284518,0.33590563263985285,-3.2382704378511167
739.9000000000101,38.94293024038329,0.33315900081085825,-3.238269704701131
741.0000000000101,38.98030145804259,0.3331838295314682,-3.238631460595422
742.1000000000101,39.01735380626795,0.3300097115213907,-3.2383098382445263
743.2000000000102,39.05423796377922,0.32620085350692407,-3.23827995461546
744.0000000000102,39.081157725928264,0.32380727778416474,-3.2382798524717975