File: 01_Data/Basswood_Panel/STA/N2/3K_min/Basswood_Panel_STA_N2_3KData_220314_R1.csv
##Temp./Â°C,Time/min,DSC/(mW/mg),Mass loss/mg
51.0,11.266456787632398,0.041107596303366245,-0.06100737644198784
52.100000000000016,11.802908628274777,0.05857462451177975,-0.06429499235650615
53.20000000000003,12.253971543159336,0.06471339877023885,-0.06306932250830899
54.30000000000005,12.680429174401219,0.06871818576599353,-0.0655434660154075
55.40000000000006,13.093146579777724,0.07155310115170632,-0.0657310250333043
56.50000000000008,13.303298647416131,0.06576549970863077,-0.06700994399803628
57.600000000000094,13.90170073746855,0.07567492357581385,-0.0683203894985942
58.70000000000011,14.298683074235802,0.07613747805793336,-0.06963707594105761
59.800000000000125,14.682810745125913,0.07674283282430217,-0.07096011643974842
60.90000000000014,15.06406973106884,0.08072615213976808,-0.0716071033986041
62.000000000000156,15.445287919908619,0.0781316211032499,-0.07381098340491077
63.10000000000017,15.824006607762325,0.08033186420295846,-0.07359020763589053
64.20000000000019,16.200827943608534,0.08253690424430749,-0.07458014699548388
65.30000000000021,16.568531155790645,0.08247095224325396,-0.07491568976264062
66.40000000000022,16.948855365492044,0.07985042176798052,-0.07588806764025069
67.50000000000023,17.328044990045765,0.08017767824300781,-0.08181614525194814
68.60000000000025,17.6981828136434,0.08034039328227938,-0.08247187159149316
69.70000000000027,18.063090417292116,0.08093382741478239,-0.08050034530931649
70.80000000000028,18.43884834134698,0.07940305378750467,-0.08274799356085083
71.90000000000029,18.809399337895357,0.08059973745846993,-0.08039608014946831
73.00000000000031,19.18160658718679,0.07956235714209148,-0.08379394566287335
74.10000000000034,19.54779625859,0.07704068373592676,-0.08446616053248679
75.20000000000034,19.92123025646736,0.0799558474515647,-0.08530731540683378
76.30000000000035,20.285155950957495,0.07805065928325872,-0.08510434226995756
77.40000000000038,20.65034997546173,0.07620558560832424,-0.08771625786071846
78.5000000000004,21.01800202680167,0.07343941332776616,-0.08839915955937672
79.6000000000004,21.390978796748225,0.07228795918782405,-0.08848002622678486
80.70000000000041,21.75664203127243,0.07320167872069205,-0.08698693579401207
81.80000000000044,22.12453398159348,0.07228695939860386,-0.0879611356603105
82.90000000000046,22.4898701671261,0.07224602093052135,-0.08938774129433957
84.00000000000047,22.84608539602956,0.07339343105487117,-0.08907299936122293
85.10000000000048,23.21413546750715,0.07418038757092527,-0.09023078308020649
86.2000000000005,23.58050622265085,0.07032679713799839,-0.09111853141682902
87.30000000000052,23.95440299232375,0.06768762341815582,-0.0916375733192738
88.40000000000053,24.316430734737498,0.07043340705511869,-0.09169293627922581
89.50000000000054,24.68214368704555,0.0686690902881727,-0.09201983820200743
90.60000000000056,25.049929224131873,0.06812554390179637,-0.09298170919322324
91.70000000000059,25.418364729008395,0.0719811129229172,-0.09432923078726851
92.8000000000006,25.781456220867575,0.07079552035481951,-0.09366023059718875
93.9000000000006,26.146115408911506,0.07421722841405642,-0.09305134308666085
95.00000000000063,26.510220371315523,0.0703607157122591,-0.09436164837985084
96.10000000000065,26.874078916453872,0.07211060844958528,-0.09432117661084849
97.20000000000066,27.236745809110975,0.069241978694224,-0.0956400683128864
98.30000000000067,27.60407330430765,0.07110494372271292,-0.0949733183697492
99.40000000000069,27.967637783450336,0.06688425007953847,-0.09621239422046024
100.50000000000071,28.332500000000373,0.06843597421484315,-0.09596006045761118
101.60000000000072,28.698047153215835,0.06983039983474593,-0.0982699999490797
102.70000000000073,29.06837267983605,0.07053256475025294,-0.09786320450796193
103.80000000000075,29.43213582183785,0.07031577373844367,-0.09960201447975603
104.90000000000077,29.797457751778964,0.07300591195098904,-0.09875401869138667
106.00000000000078,30.161639522752036,0.07329716631546279,-0.09846298646275686
107.10000000000079,30.52943679896208,0.07407006078739464,-0.09860273222434834
108.20000000000081,30.886021402523784,0.07207272990273639,-0.09829029350461216
109.30000000000084,31.255611791971894,0.07302148160060151,-0.0995345321342187
110.40000000000084,31.615830000000287,0.07160383504966594,-0.09863301340043451
111.50000000000085,31.974876937686354,0.0740931752521482,-0.09919667313293301
112.60000000000088,32.337006640916165,0.07455694150621839,-0.09925988080814774
113.7000000000009,32.699170000000315,0.07589672238008638,-0.09992014678391703
114.8000000000009,33.05901442229891,0.07824093400786736,-0.10128200670453325
115.90000000000092,33.42243229736126,0.07270018867957273,-0.10248633426873743
117.00000000000094,33.78815869679453,0.07510410686469782,-0.10151517831923274
118.10000000000096,34.15052632690793,0.07083874590419359,-0.10319980789005223
119.20000000000097,34.521179695747946,0.07546311249079629,-0.10417704390149973
120.30000000000098,34.87937766502095,0.0765849073628807,-0.10188972644480376
121.400000000001,35.240436260008835,0.08008230919569892,-0.10434440302779624
122.50000000000102,35.601932586215895,0.0786842147837189,-0.10385983602628723
123.60000000000103,35.963324111716325,0.07556259505061547,-0.10378576369678827
124.70000000000104,36.32139257147354,0.07521599369260457,-0.10692120287873408
125.80000000000106,36.68607560844989,0.07663486783282758,-0.10550951197394287
126.90000000000109,37.04637226187786,0.07731530739036296,-0.10485275516668446
128.00000000000108,37.4106390392974,0.07499313277881248,-0.10620904570578515
129.1000000000011,37.772243441333714,0.0741509803021132,-0.10656168411618028
130.20000000000113,38.1286350244545,0.08005583212592016,-0.10748986400027549
131.30000000000115,38.49003404604773,0.07578096999231998,-0.10650111014344255
132.40000000000117,38.853438375851006,0.07491307848276041,-0.1078315407425019
133.50000000000117,39.218532883387844,0.07893390336109429,-0.10808604486663143
134.6000000000012,39.58099286160132,0.07794709287192159,-0.10847426533021975
135.7000000000012,39.943248934320344,0.07582779302468667,-0.108799927999772
136.8000000000012,40.304125754605444,0.07555545193592195,-0.10945829194130008
137.90000000000123,40.661030742160875,0.07481383972456057,-0.10930516422987235
139.00000000000125,41.028060270656376,0.07716002775437103,-0.1101102168927266
140.10000000000127,41.39053530361829,0.07692201209797422,-0.11038950256528901
141.2000000000013,41.74768116979339,0.07943406581418655,-0.11041333013357812
142.3000000000013,42.1067888011936,0.07835366660686749,-0.11076951938416757
143.4000000000013,42.468288420796995,0.07718692346203848,-0.11230980253320322
144.50000000000134,42.82783032909195,0.07820636996905705,-0.11329790600889478
145.60000000000133,43.19173852272945,0.0789746126757559,-0.11198811435873512
146.70000000000135,43.55162571128478,0.07870240725581368,-0.11284801736665262
147.80000000000138,43.9132789617742,0.07969820229183511,-0.11429566947673653
148.9000000000014,44.27136575382249,0.07742280085248743,-0.11363095158695025
150.00000000000142,44.6314539144067,0.07599559905267284,-0.11427152362101056
151.10000000000142,44.9897308163531,0.08003871042166832,-0.11645647373079315
152.20000000000144,45.35323109723452,0.07820908708573904,-0.11614020733838082
153.30000000000146,45.71296706112588,0.08196914814376066,-0.11602420611974784
154.40000000000146,46.06998305825797,0.08357229047359016,-0.11669298556080143
155.50000000000148,46.426938610317386,0.08246939851143031,-0.11617190331328464
156.6000000000015,46.78690249748313,0.08349629105926404,-0.11637109556961489
157.70000000000152,47.145153644162484,0.08432735313690187,-0.11504107225521842
158.80000000000155,47.50971811437613,0.08237620097294962,-0.11735748831002235
159.90000000000154,47.86148463371741,0.08190761022748927,-0.1177373788842031
161.00000000000156,48.22306772514384,0.08475644667651261,-0.11798320285703623
162.1000000000016,48.57951320562095,0.08125063811034505,-0.11966615577999917
163.20000000000158,48.938582009829446,0.08293949176041526,-0.11982669910925914
164.3000000000016,49.303677024741305,0.08119840658733601,-0.11866156789850635
165.40000000000163,49.66052905278535,0.08304613198638389,-0.12103279680054824
166.50000000000165,50.02359219189647,0.0851795661808814,-0.11998631943724103
167.60000000000167,50.381348795349346,0.0852864751585779,-0.11998005999999961
168.70000000000167,50.739461465194445,0.08555566093674105,-0.12130617859294146
169.8000000000017,51.092775196426864,0.08535722686258673,-0.12130114820909421
170.9000000000017,51.45526558804498,0.08660585807373455,-0.1226107371642926
172.0000000000017,51.81205601937691,0.08633457347036344,-0.12283577340059981
173.10000000000173,52.1738396751425,0.08818594284129799,-0.12315828527151274
174.20000000000175,52.53115156171462,0.08777221872272067,-0.12474820064799141
175.30000000000177,52.88812318871181,0.08835564405564178,-0.1259099679283473
176.4000000000018,53.25136051175398,0.08985673717423692,-0.1255800313280968
177.5000000000018,53.61099764987778,0.08716365218960398,-0.1282097772266133
178.6000000000018,53.97275573353049,0.09044378285768584,-0.12820983686667198
179.70000000000184,54.326960143153656,0.09063281110766408,-0.13012410512271133
180.80000000000183,54.69030597005231,0.09391348549647893,-0.1305223538923861
181.90000000000185,55.03889690994625,0.09183927665851865,-0.13010157650956522
183.00000000000188,55.39862120766089,0.09192565094132632,-0.13215765184955552
184.1000000000019,55.755698088012394,0.09475920386823566,-0.1331500799430656
185.20000000000192,56.11348129403235,0.09357503237226317,-0.13309931870180725
186.30000000000192,56.47185944052081,0.09323706121674347,-0.13449681621255394
187.40000000000194,56.824737356704546,0.09598546446820355,-0.13643225937636316
188.50000000000196,57.180392241310045,0.09678944122048339,-0.13578034456356658
189.60000000000196,57.54457381235314,0.09392806349862437,-0.13839586514327173
190.70000000000198,57.90349413086882,0.09499136299835975,-0.1384128138725531
191.800000000002,58.248211637139,0.09562519346458864,-0.14073490186150872
192.90000000000202,58.61697408759465,0.09837509806478029,-0.1433565828292549
194.00000000000205,58.97284425945641,0.09793397881785104,-0.14280751231802657
195.10000000000204,59.33423657959693,0.0999847865846406,-0.14564882917398947
196.20000000000206,59.69204161005443,0.10118000103132463,-0.1459854750629046
197.3000000000021,60.04747696321047,0.10299448987742177,-0.14791346170517494
198.40000000000208,60.40289527969135,0.10166095533921149,-0.15058267787732715
199.5000000000021,60.76221946087169,0.1022682631912103,-0.1526237483450883
200.60000000000213,61.117582712888876,0.10681104897543003,-0.15454007607983034
201.70000000000215,61.47762965806763,0.10668022210395178,-0.1557105927272482
202.80000000000217,61.831768400097516,0.10816403574475197,-0.15750233693746596
203.90000000000217,62.187491324324505,0.10676067727330207,-0.16059861021853417
205.0000000000022,62.546009382146494,0.10461215708219562,-0.1621042209438901
206.1000000000022,62.90602731125378,0.1027403130902711,-0.16395126186172115
207.2000000000022,63.268330578016524,0.10482253704019973,-0.16671005708882003
208.30000000000223,63.62371156156202,0.10729656382961694,-0.17023744393572215
209.40000000000225,63.98250341780446,0.1061066289202911,-0.17215406406747258
210.50000000000227,64.33342832259525,0.10989805046474915,-0.1738920484638946
211.6000000000023,64.68722374236232,0.11182584540594709,-0.17704388683362682
212.7000000000023,65.04643527134088,0.10753036967801538,-0.17981465549186915
213.8000000000023,65.40425108874255,0.10336367388607293,-0.18252662476204629
214.90000000000234,65.76463712178212,0.10438668441787546,-0.18478169090003593
216.00000000000233,66.12158342032748,0.10943909789637568,-0.1870965525788879
217.10000000000235,66.47703688557463,0.10738640614464673,-0.18987630525342958
218.20000000000238,66.8338004183826,0.10966107979580325,-0.19369943907292253
219.3000000000024,67.18891815241433,0.10883647363035781,-0.19619542220063835
220.40000000000242,67.55009128768103,0.10853115784093659,-0.20027409198943324
221.50000000000242,67.90532937506981,0.10835580707899467,-0.20290281651217557
222.60000000000244,68.25957585059359,0.10434811841878922,-0.20487950548014622
223.70000000000246,68.6181202610431,0.1067446349259843,-0.20883182627654762
224.80000000000246,68.97728116474867,0.10655675469606657,-0.2132270089378796
225.90000000000248,69.33286005954177,0.10339916641803526,-0.2170600587360676
227.0000000000025,69.69379606263547,0.10456709769808925,-0.21944135376843388
228.10000000000252,70.05226515770948,0.10745628851979272,-0.22295224682561932
229.20000000000255,70.4113005512167,0.10675898812874551,-0.22745513407921747
230.30000000000254,70.76653980690617,0.10576075907976895,-0.23153234787091925
231.40000000000256,71.12294445400427,0.10581120229033136,-0.23515499510469873
232.5000000000026,71.47570010390427,0.10507250840937904,-0.24072628419022113
233.60000000000258,71.83350724493128,0.10232270501861579,-0.24538810015111245
234.7000000000026,72.19113372128606,0.1031690348764413,-0.24827252655892362
235.80000000000263,72.54822755140653,0.10007419192692951,-0.2532015842104287
236.90000000000265,72.90597600872653,0.10075282732833252,-0.25786268460880013
238.00000000000267,73.26192211333651,0.10032847545624834,-0.2631085436915468
239.10000000000267,73.62077266239177,0.10312719468041492,-0.26978068817512435
240.2000000000027,73.97750502572711,0.10338471527364929,-0.2748312205010395
241.3000000000027,74.32956341030558,0.10399261275224769,-0.28021440162190414
242.4000000000027,74.68896332413246,0.10267492187058963,-0.2857079981456785
243.50000000000273,75.04312674623182,0.10409836715151666,-0.2931630398893055
244.60000000000275,75.40360609974718,0.10555012387189411,-0.29961531955140375
245.70000000000277,75.76252203631546,0.10171234886123998,-0.3056429803346443
246.8000000000028,76.11622145902685,0.10109858646232284,-0.31349633895343887
247.9000000000028,76.47247702318644,0.10211050783897202,-0.31984032587827693
249.0000000000028,76.83460576196524,0.10472972353985621,-0.328238747121103
250.10000000000284,77.188248617268,0.1054584114129879,-0.3360677337172455
251.20000000000283,77.53251718994824,0.10407877340226884,-0.3433285214379418
252.30000000000285,77.89812252068546,0.1064172146972931,-0.35367481125255784
253.40000000000288,78.25449929312012,0.10527374087712321,-0.36209245639688925
254.5000000000029,78.61165755611609,0.10465359808943925,-0.37422497058005266
255.60000000000292,78.96973794268747,0.10744822596457615,-0.38332001241841906
256.7000000000029,79.32908773741015,0.10589815694134058,-0.3950208535121553
257.8000000000029,79.6834570252537,0.10575912457655168,-0.4049579765278768
258.90000000000293,80.04219665014197,0.10394756062275845,-0.4174597079480393
260.00000000000296,80.39968815916902,0.10694608835997599,-0.42963597004906173
261.100000000003,80.75317903709163,0.10683169970888945,-0.44369705905779133
262.200000000003,81.10562764618103,0.10850918671303594,-0.45601567813979793
263.300000000003,81.46201863674347,0.10816368866333348,-0.4707943321815793
264.40000000000305,81.81724459586502,0.10610072414846528,-0.4862610092156361
265.50000000000307,82.17994390542701,0.10744671530603678,-0.4996850752392503
266.6000000000031,82.53627321117239,0.10447978370428423,-0.5173984055501566
267.7000000000031,82.89134635782011,0.10451126388754678,-0.5330008396033641
268.8000000000031,83.25321015453773,0.10629085957228629,-0.5515226357525389
269.9000000000031,83.61095742935616,0.10570220894611637,-0.5679508054588096
271.0000000000031,83.96779554817446,0.10484269488800041,-0.5848096684067112
272.10000000000315,84.32510200690713,0.10431258520134706,-0.6057410720176013
273.2000000000032,84.67966668801142,0.1017723213880265,-0.6252937168111745
274.30000000000314,85.03683887572575,0.10190060434706039,-0.6407471107836487
275.40000000000316,85.39225466832588,0.10279114156761177,-0.6618488688315556
276.5000000000032,85.7491700000011,0.10112762376234508,-0.6824600920000683
277.6000000000032,86.10717915100786,0.1003800711841018,-0.7018379102024044
278.70000000000323,86.46478569284317,0.09906706647042995,-0.724694168083488
279.80000000000325,86.82575063501285,0.09820122250944235,-0.7453915163544829
280.9000000000033,87.1806049084415,0.0998529381519499,-0.7658787318646465
282.0000000000033,87.53360604529098,0.10163953905282208,-0.7862908343069348
283.1000000000033,87.89097440390786,0.10157082284905694,-0.8092568561427989
284.20000000000334,88.24553346163043,0.10000889086044945,-0.8299745893920241
285.30000000000337,88.60280684626322,0.09829858602575009,-0.8512864531213697
286.40000000000333,88.96074173763866,0.10243872819397398,-0.8747737287515394
287.50000000000335,89.32092592983486,0.10255300751436919,-0.8974491571262817
288.6000000000034,89.67747405574947,0.09689196749714213,-0.9177048096882454
289.7000000000034,90.0362089015981,0.09491453199381011,-0.9410395286641919
290.8000000000034,90.39781740498782,0.09894015350025315,-0.9633018912722711
291.9000000000034,90.75621512377383,0.10098563646992348,-0.9843515418032771
293.0000000000034,91.1097261940595,0.10224086797818249,-1.0080888362166807
294.10000000000343,91.46024412634223,0.10334915371204506,-1.0299399254239892
295.20000000000346,91.82328357108837,0.10398927669195407,-1.0500438423161684
296.3000000000035,92.18108361612994,0.10420628228676021,-1.0740195123325704
297.4000000000035,92.54005716459477,0.10836864757381659,-1.0954550673264483
298.5000000000035,92.89605070828097,0.10991224507602698,-1.119883582169265
299.60000000000355,93.25303246654005,0.10978237048582792,-1.1427255005918866
300.70000000000357,93.61101343251863,0.10868872239785693,-1.1642415498039025
301.8000000000036,93.96163383045246,0.11504523303722441,-1.1864528639816094
302.9000000000036,94.32898877526513,0.11672465254057945,-1.2117391183005153
304.0000000000036,94.68764963089086,0.11862692796086766,-1.2356117016429073
305.1000000000036,95.05091318253471,0.123381290062747,-1.2609464113039168
306.2000000000036,95.40504475669314,0.1266778524406543,-1.2858641053664406
307.30000000000365,95.76149572432047,0.126115827118615,-1.310047033038778
308.4000000000037,96.12333842433225,0.12936437056494582,-1.3360978315572338
309.5000000000037,96.47882889867226,0.13218658999419042,-1.3628969915320575
310.60000000000366,96.83629297995924,0.13561093598096854,-1.3886185128896384
311.7000000000037,97.19625403531991,0.14049788601176627,-1.4167816972638931
312.8000000000037,97.55331978837516,0.1449911387698809,-1.4436126725319873
313.90000000000373,97.91301036401089,0.14879199208868688,-1.4728379456657237
315.00000000000375,98.27186047348104,0.15286791825634388,-1.5026381490796745
316.1000000000038,98.62749306003546,0.15652619004098178,-1.5321415597038999
317.2000000000038,98.98626650459613,0.1569047836231765,-1.5659190827373681
318.3000000000038,99.34689268615855,0.1600336790898733,-1.5979948293423973
319.40000000000384,99.71187644843248,0.16402491625353433,-1.6297312616368838
320.5000000000038,100.07167462025916,0.1680957882821721,-1.6650917776742715
321.60000000000383,100.42708542444852,0.17505930276611553,-1.699985325338873
322.70000000000385,100.7848918631193,0.1821180251832945,-1.7368179399778274
323.8000000000039,101.14483738795349,0.18531297709313688,-1.7743018840440623
324.9000000000039,101.5069027065924,0.18759423592828917,-1.8142970979994528
326.0000000000039,101.86418018158083,0.1905973309722358,-1.8530586217988776
327.10000000000394,102.22741260719182,0.19905672063422308,-1.8967735642017058
328.2000000000039,102.58752391085316,0.2008318354137273,-1.938037928446735
329.30000000000393,102.94731294636301,0.2049387904933985,-1.9819793903817318
330.40000000000396,103.30970154591756,0.2077768148855926,-2.028336424559717
331.500000000004,103.66684981260155,0.21462478218973524,-2.074167701496406
332.600000000004,104.02266768608223,0.2162399818170662,-2.1217049626629123
333.700000000004,104.38167652245505,0.21944649063872118,-2.169587818553294
334.80000000000405,104.74390841324829,0.222559989545918,-2.2183830064005217
335.90000000000407,105.09566786448973,0.22106008124452098,-2.2697294723025934
337.0000000000041,105.45808469635539,0.22160506706002608,-2.320817316600592
338.10000000000406,105.81910443476396,0.21920831375934807,-2.372260278119183
339.2000000000041,106.1788747691568,0.21777488848808607,-2.4233980242076094
340.3000000000041,106.53117782848693,0.21187251617866754,-2.4748778646474543
341.4000000000041,106.89880707208158,0.20808409064792194,-2.526231014823723
342.50000000000415,107.26056072607815,0.20096632720096988,-2.57566253608584
343.6000000000042,107.62271496558259,0.1907214940928849,-2.6263593351037766
344.7000000000042,107.98059383551897,0.18132506349774113,-2.6727119432016124
345.80000000000416,108.33944633547532,0.16833299922576186,-2.717823641329793
346.9000000000042,108.69880745456302,0.15296524851642854,-2.7620431934299994
348.0000000000042,109.05745378828249,0.14028548994990364,-2.7992046720369883
349.10000000000423,109.41458338923613,0.1196176080851665,-2.8346727150944586
350.20000000000425,109.7737432170369,0.10223553846773784,-2.867986411409314
351.3000000000043,110.13644774504779,0.08261381820314412,-2.8976422019399046
352.4000000000043,110.49451506969153,0.06348778354143483,-2.922669234564408
353.5000000000043,110.8549020862011,0.04646677210626313,-2.9448528282070052
354.60000000000434,111.21774715646511,0.03033079628828131,-2.9628762162846702
355.7000000000043,111.57724069494238,0.017213300274481924,-2.978403781143248
356.80000000000433,111.93684372184754,0.007286217031061248,-2.9896262374542966
357.90000000000435,112.29751392408777,0.0017417113924892702,-3.0002758208267735
359.0000000000044,112.65045533282704,-0.004198642299856364,-3.0084657420417202
360.1000000000044,113.00930345714737,-0.007386172314649525,-3.013746636794539
361.2000000000044,113.37289804854572,-0.010309818175306185,-3.0209201527208713
362.30000000000445,113.73517501034378,-0.01482922204702422,-3.027162633955233
363.4000000000044,114.09709087399763,-0.016657465259925758,-3.0328096306099734
364.50000000000443,114.4538644449501,-0.016501847952772708,-3.038047570508949
365.60000000000446,114.81672494363968,-0.014457368349064859,-3.042018804113998
366.7000000000045,115.175870343591,-0.01734024420450131,-3.0485636336478255
367.8000000000045,115.5379084865861,-0.017557214582392816,-3.052541279510785
368.9000000000045,115.89974182002115,-0.01897539385968902,-3.0564889549371226
370.00000000000455,116.26535561795374,-0.020221389999730943,-3.0604620742050574
371.10000000000457,116.62451155983038,-0.022990066394557113,-3.064728760715597
372.2000000000046,116.98352151020617,-0.021177808975681667,-3.0690493728663526
373.30000000000456,117.34659015213848,-0.021574988360149927,-3.072943533092822
374.4000000000046,117.70496262681667,-0.02355695539041816,-3.075572639304517
375.5000000000046,118.06686057499353,-0.024004932967056525,-3.08084006545916
376.6000000000046,118.42938239400607,-0.025283195804814224,-3.083553093645687
377.70000000000465,118.79265124244688,-0.027567514623841605,-3.0887517567657428
378.8000000000047,119.15324784345863,-0.027230616093433732,-3.09255342319205
379.9000000000047,119.51647655991023,-0.028358465148755382,-3.0956667857207645
381.00000000000466,119.88390101207023,-0.029001467868785644,-3.098292325465953
382.1000000000047,120.2428465610511,-0.03209127157520465,-3.1032295964193874
383.2000000000047,120.59955344381405,-0.03159290884983239,-3.107181447351788
384.30000000000473,120.95992252105817,-0.030661734904587193,-3.1108342858518405
385.40000000000475,121.32208035052139,-0.03134312656275848,-3.1137567335855043
386.5000000000048,121.6800511651029,-0.03248276434694383,-3.1177107354364364
387.6000000000048,122.0443714174041,-0.0354924081700768,-3.120220970537143
388.7000000000048,122.40046035208253,-0.03604728283708529,-3.123000685685036
389.80000000000484,122.76494334773993,-0.03561959581542978,-3.125609367200492
390.9000000000048,123.13072134165931,-0.0371759586142401,-3.132174936954578
392.00000000000483,123.48978463726259,-0.037309960315761434,-3.1338156325051565
393.10000000000485,123.85636807556305,-0.036339073381167264,-3.1380098276862407
394.2000000000049,124.2189165198365,-0.03841361748202708,-3.141542254854549
395.3000000000049,124.58379875205905,-0.037256543704915754,-3.145789163586758
396.4000000000049,124.94254047066225,-0.037718604516715146,-3.149086271004479
397.50000000000495,125.30190328641469,-0.03706662949159892,-3.149285828314524
398.6000000000049,125.66899306318506,-0.0381471906389763,-3.1556469413517236
399.70000000000493,126.02957295909154,-0.038491846095814235,-3.157203754200719
400.80000000000496,126.39112237997978,-0.03838505359949693,-3.1618100630915644
401.900000000005,126.75407366586612,-0.038319523708075946,-3.164100627357721
403.000000000005,127.11583000000181,-0.04105545348895296,-3.1694357090161205
404.100000000005,127.47748958039486,-0.03906497585007735,-3.171345764057767
405.20000000000505,127.84015294873626,-0.040466451672438106,-3.175306816027889
406.30000000000507,128.20318238417582,-0.0404924683166558,-3.176661270737021
407.4000000000051,128.56791247882452,-0.04081416002186614,-3.179252721150048
408.50000000000506,128.93405060692123,-0.040925453103948434,-3.1841642645233477
409.6000000000051,129.29202705342425,-0.038106019492152365,-3.185378697616911
410.7000000000051,129.65642341083344,-0.04068199537262352,-3.1893935378917133
411.8000000000051,130.02206198845772,-0.040464309289198135,-3.1932721054998723
412.90000000000515,130.38012003706467,-0.039111100309558326,-3.194700979842672
414.0000000000052,130.74591644263103,-0.039215777023957954,-3.198636886721285
415.1000000000052,131.1020233807979,-0.03875887086594404,-3.2022803980886128
416.20000000000516,131.46467889855614,-0.03879172896879451,-3.2042519380238295
417.3000000000052,131.82820972862348,-0.04045480510865709,-3.205531034135371
418.4000000000052,132.18906472602487,-0.036461995996137905,-3.2075079093679024
419.50000000000523,132.54819187221636,-0.03674683775770105,-3.2107734113023083
420.60000000000525,132.90722418725719,-0.0370155138700957,-3.2134984153870874
421.7000000000053,133.26956204349108,-0.03517262247441545,-3.2155366347137453
422.8000000000053,133.63364265194247,-0.035800289800765585,-3.219300223002462
423.9000000000053,133.9981144537632,-0.0386260950829489,-3.2210326545041807
425.00000000000534,134.36547876876037,-0.036691765565086534,-3.2226002060684893
426.1000000000053,134.72652832901755,-0.035355989166111296,-3.227651081184353
427.20000000000533,135.08654531948628,-0.03605781906711866,-3.23026114439095
428.30000000000535,135.45551200105822,-0.038695476964954206,-3.2302413065255062
429.4000000000054,135.81542555225857,-0.03458806277054703,-3.2351617632253085
430.5000000000054,136.17732463147905,-0.035499376383933176,-3.2357890957164024
431.6000000000054,136.54421692691227,-0.03300633243298968,-3.2371595659620116
432.70000000000545,136.91269619085497,-0.03411341372933621,-3.2397838829459973
433.8000000000054,137.27343123417413,-0.034178372011092986,-3.2417711470134973
434.90000000000543,137.6411767609763,-0.03345381775883162,-3.243079946643671
436.00000000000546,138.00318733403427,-0.033685244209961426,-3.245068217125604
437.1000000000055,138.36646759661923,-0.033660696136568725,-3.2465895042784587
438.2000000000055,138.72884578728772,-0.0326230866236524,-3.2480165309465705
439.3000000000055,139.09385354140798,-0.03412311569797781,-3.252954874328924
440.40000000000555,139.4566744255325,-0.030055127393002798,-3.2516460550356387
441.50000000000557,139.82211307674208,-0.031123746311460775,-3.2552580265015085
442.6000000000056,140.18097847191115,-0.03114729353417136,-3.2565439214767897
443.70000000000556,140.542730003013,-0.029299398266846285,-3.2592002549503816
444.8000000000056,140.90850912253444,-0.0277917605016699,-3.2591612749771013
445.9000000000056,141.2758198878777,-0.029444306812999296,-3.262467710327904
447.0000000000056,141.63890179231956,-0.02838421268417586,-3.264787089947976
448.10000000000565,142.00033130889875,-0.027975256562600845,-3.265771074136783
449.2000000000057,142.36739125879205,-0.02715084401859527,-3.2661945894897775
450.3000000000057,142.7327998555016,-0.02726900179497778,-3.2687383008105595
451.40000000000566,143.098852804217,-0.024299878795838795,-3.2707350214397115
452.5000000000057,143.4624615223405,-0.024252036634598073,-3.272148011412541
453.6000000000057,143.82749544712783,-0.020919646454144264,-3.273316581601693
454.70000000000573,144.1928715186325,-0.018598655832751734,-3.2769495231607118
455.80000000000575,144.5588641954328,-0.01729440197972723,-3.2756402402377285
456.9000000000058,144.92503178010855,-0.015638657501025027,-3.278278418744436
458.0000000000058,145.28535145110993,-0.017548066536184362,-3.279347832722181
459.1000000000058,145.6499034838369,-0.01741562417892592,-3.2809137050595285
460.20000000000584,146.0095019881516,-0.015040432133244658,-3.2828505672350765
461.3000000000058,146.3743806129985,-0.015564236563589545,-3.2848675587671896
462.40000000000583,146.73649290121125,-0.012920757234805846,-3.2855278460190567
463.50000000000585,147.10383575146142,-0.01152991320315025,-3.2868476932336916
464.6000000000059,147.46659698973343,-0.012792034497399046,-3.2881484321825716
465.7000000000059,147.83411157021558,-0.010278326619977463,-3.2884951319772764
466.8000000000059,148.19852744397065,-0.00863031260668487,-3.290655886421329
467.90000000000595,148.5612946983682,-0.01305403034137495,-3.290679706541194
469.0000000000059,148.93208859778602,-0.013107942922107901,-3.2920006125196113
470.10000000000593,149.2930069752915,-0.016384983987309698,-3.2943035410116632
471.20000000000596,149.6643955144968,-0.018122442001239886,-3.2956199610730317
472.300000000006,150.03135303997595,-0.021318400712824148,-3.296278581282502
473.400000000006,150.3956721663982,-0.025072138168729552,-3.2972622892648853
474.500000000006,150.76670041721354,-0.025202774360749497,-3.297811794280746
475.60000000000605,151.13281979224166,-0.029503679987327835,-3.2991250177177944
476.70000000000607,151.49555342966232,-0.03133570116260065,-3.300440036017629
477.8000000000061,151.85920453067703,-0.03484640464525787,-3.3016904626894714
478.90000000000606,152.2178441746155,-0.03856354876819701,-3.30201720938873
480.0000000000061,152.58194774262702,-0.035243095882156156,-3.303290230430714
481.1000000000061,152.94615341439538,-0.033717314477298865,-3.3046198568341643
482.2000000000061,153.31311145683605,-0.039546540372226185,-3.3072400642182034
483.30000000000615,153.68632519803893,-0.04326451193736344,-3.3072498872286213
484.4000000000062,154.05471329570545,-0.04519442117391592,-3.308574232839751
485.5000000000062,154.42134341405531,-0.04870035779274218,-3.308898030672053
486.60000000000616,154.78368542979513,-0.05083241501398339,-3.3102100750264727
487.7000000000062,155.1488286904449,-0.05308182370354367,-3.3102095053389466
488.8000000000062,155.51308504225125,-0.05134808026226817,-3.312512818651746
489.90000000000623,155.87901896606286,-0.054254380526464835,-3.3115211555147717
491.00000000000625,156.24988203622308,-0.05683803492560077,-3.3131645922535315
492.1000000000063,156.61618281188615,-0.058168621050719654,-3.3134836794137374
493.2000000000063,156.9834698072568,-0.05732641536696595,-3.315469884598035
494.3000000000063,157.3511730251785,-0.058787819347598996,-3.3167890620368397
495.40000000000634,157.7165987293913,-0.06232213588565785,-3.3167877332753375
496.5000000000063,158.07842985722044,-0.06340644357433028,-3.317779836067973
497.60000000000633,158.43878807588482,-0.06023329532572186,-3.3187654634879897
498.70000000000636,158.80411244278736,-0.06172006429636806,-3.320740079480167
499.8000000000064,159.17023200587562,-0.06205871116466824,-3.3194200528125393
500.9000000000064,159.539260562312,-0.06300380256027507,-3.322049922935783
502.0000000000064,159.89952284681925,-0.06276584385082817,-3.3223266914592053
503.10000000000645,160.27057377635117,-0.06516636065967801,-3.3231726881682113
504.2000000000064,160.63850643929615,-0.0648103309912782,-3.324690003931021
505.30000000000643,160.99325349306235,-0.06533407705556682,-3.3246899802250165
506.40000000000646,161.36873557828434,-0.06503696589527452,-3.3253402662954827
507.5000000000065,161.73142758089458,-0.06853594570906552,-3.326990945486221
508.6000000000065,162.10295776951097,-0.06270475956935362,-3.3289727012891954
509.7000000000065,162.47075143809107,-0.06474233840034327,-3.328310967236307
510.80000000000655,162.84087175385372,-0.06157817189651299,-3.3289864070474504
511.90000000000657,163.20685301296345,-0.06606933547379684,-3.3302793741259444
513.0000000000066,163.57205767254803,-0.06573917649596234,-3.3327074038083517
514.1000000000065,163.93754855915574,-0.0655997866616227,-3.333239547563551
515.2000000000066,164.30383465272,-0.06399836889327826,-3.332529685724112
516.3000000000065,164.66677847464283,-0.06464728785984458,-3.3329100296678007
517.4000000000067,165.03600002522555,-0.062120363343240226,-3.3342426694888263
518.5000000000066,165.4033271851501,-0.06407514936308895,-3.3352869709474326
519.6000000000067,165.77082539671338,-0.06625442110097224,-3.3363215501630403
520.7000000000066,166.13804514105797,-0.060974282728438634,-3.336838017841289
521.8000000000067,166.5054824737865,-0.06392707864769959,-3.3388290477041958
522.9000000000067,166.87476432311178,-0.0642485154831916,-3.338170108
524.0000000000067,167.24263079665045,-0.062054760689543687,-3.3395992185297256
525.1000000000067,167.6095783990706,-0.061765243523323465,-3.3392197758534916
526.2000000000068,167.96923732309423,-0.06216023269732568,-3.339795401084683
527.3000000000068,168.3408109669654,-0.06370139754769688,-3.34131130580801
528.4000000000068,168.7079258188362,-0.06153014922412209,-3.342739824171548
529.5000000000068,169.07399896043216,-0.06293758849885067,-3.3427776315887563
530.6000000000068,169.4444579797308,-0.06229155008940418,-3.344099952367458
531.7000000000069,169.81284291856403,-0.06289753503001783,-3.3454319819813367
532.8000000000068,170.17920262352945,-0.060025013622316215,-3.3454121938948833
533.9000000000069,170.54655103778668,-0.06040493638221084,-3.3467286248895927
535.0000000000068,170.9094890167068,-0.061285661753656684,-3.34573676227332
536.100000000007,171.2837756629098,-0.06219052402350289,-3.34837039060699
537.2000000000069,171.6513034927929,-0.06013265909979232,-3.3490300313136334
538.300000000007,172.0228602101435,-0.06128602925380605,-3.3503889899318353
539.4000000000069,172.3872095258982,-0.060997099874405325,-3.3516392109568596
540.5000000000069,172.7528179414922,-0.05889756087743153,-3.3523301786856385
541.600000000007,173.11961905486064,-0.057362136728732416,-3.350967371973198
542.700000000007,173.48838704794835,-0.05838182477937631,-3.353314293516283
543.800000000007,173.85141601821562,-0.05656112657014467,-3.353318558387765
544.900000000007,174.22034630870223,-0.05997493095473144,-3.353724006383871
546.000000000007,174.58628989031712,-0.061058114201683056,-3.3552904590916994
547.1000000000071,174.95308717900133,-0.05594270434824056,-3.3546864189611156
548.2000000000071,175.31975308723364,-0.058942484536038176,-3.355949847059257
549.300000000007,175.6925202833972,-0.057715798377197314,-3.3565941499323513
550.4000000000071,176.05744196125605,-0.05645632759277763,-3.357590120627502
551.500000000007,176.42470305166609,-0.05918856242118614,-3.3598922640366347
552.6000000000072,176.79114175434802,-0.053657585218171655,-3.3598966527692746
553.7000000000071,177.1569680968325,-0.05669492194390602,-3.3608791251226595
554.8000000000072,177.52655665738155,-0.05624367866441593,-3.3608899990211603
555.9000000000071,177.89669592233003,-0.053966296235368916,-3.3612199884477274
557.0000000000072,178.26873547629597,-0.05549061851311893,-3.362520593666594
558.1000000000072,178.63882833304666,-0.056537440612351886,-3.363380375133695
559.2000000000072,179.00537938960483,-0.0552335829500476,-3.362849978618133
560.3000000000072,179.3750365164945,-0.05833245370579676,-3.3628118532727846
561.4000000000073,179.74328526763753,-0.05505456418301585,-3.3654732393880122
562.5000000000073,180.10824317157574,-0.05436117303296123,-3.3641698508679
563.6000000000073,180.4737790159443,-0.05633970066988769,-3.364793616401613
564.7000000000073,180.84167789923504,-0.054813409493339516,-3.3654901079997948
565.8000000000073,181.21034128513097,-0.05424805918524106,-3.36779035354364
566.9000000000074,181.57827418602096,-0.05089445009751847,-3.3677869764749255
568.0000000000074,181.944868544705,-0.05122229230770303,-3.36812057942377
569.1000000000074,182.31701898357423,-0.0525768371564751,-3.3697347827578383
570.2000000000073,182.68438528113538,-0.052257256052708256,-3.3694413215976895
571.3000000000073,183.05120570079748,-0.047903207343576226,-3.3694400155059485
572.4000000000074,183.42556596944243,-0.04942345405957571,-3.3701194931259373
573.5000000000074,183.7968966308366,-0.050671221107712716,-3.3700973031658332
574.6000000000074,184.165527539841,-0.0525006713966617,-3.370589465594499
575.7000000000074,184.5316932000844,-0.04921719535571689,-3.3704201240020417
576.8000000000075,184.899801054372,-0.04857807752462873,-3.370420099166286
577.9000000000075,185.27116034580908,-0.04960333537150241,-3.372877753464767
579.0000000000075,185.64065280976615,-0.05020932243283671,-3.3730650012670895
580.1000000000075,186.00705099514522,-0.044145646643915404,-3.373920504781685
581.2000000000075,186.37804878914324,-0.0461051484530538,-3.371897838889103
582.3000000000076,186.74602910233926,-0.0449584881184234,-3.3743131886179496
583.4000000000076,187.11835881755997,-0.04670867723754024,-3.3747000363404824
584.5000000000076,187.48287650924638,-0.045951983680569075,-3.3746999871472765
585.6000000000076,187.84438577405123,-0.04435779325159228,-3.3750296513755185
586.7000000000077,188.2198014982279,-0.04644798094159941,-3.375380610778929
587.8000000000077,188.5812252168824,-0.043770427675587587,-3.3756884640629963
588.9000000000076,188.95496316308422,-0.04590948150569829,-3.3766052872788714
590.0000000000076,189.32089464205845,-0.044406181238097475,-3.376663711373938
591.1000000000076,189.69426874197956,-0.04358348118091526,-3.3773303209447096
592.2000000000077,190.06392553531794,-0.04229869801900177,-3.38052195749402
593.3000000000077,190.4349794551223,-0.04331052536748625,-3.3782266647528667
594.4000000000077,190.8093496722442,-0.04221846129222373,-3.3799044147560298
595.5000000000077,191.1814352640054,-0.04437822094938004,-3.379630061904295
596.6000000000078,191.55177652768586,-0.04497946422095289,-3.3795989734605563
597.7000000000078,191.92032268106223,-0.0433717069697791,-3.3806896758382257
598.8000000000078,192.28997181238114,-0.04465783679029112,-3.380877361259785
599.9000000000078,192.658164455998,-0.04223267030981681,-3.3819784148744327
601.0000000000078,193.02693542123598,-0.04051275916725672,-3.381944594051702
602.1000000000079,193.3934652871388,-0.03955754068574202,-3.3805968651055336
603.2000000000079,193.76379084767478,-0.03970380046874611,-3.383260087985933
604.3000000000079,194.1318427717951,-0.043100589163913794,-3.3826002189056137
605.4000000000078,194.50436892830515,-0.04065415504032632,-3.38391976545838
606.5000000000078,194.87269569977516,-0.039865203487219,-3.3837271304812493
607.6000000000079,195.24032119049946,-0.03992664623641029,-3.3847999714844965
608.7000000000079,195.61500942760117,-0.040677204791233934,-3.3848001751549965
609.8000000000079,195.98653585624237,-0.04075432793931211,-3.3854596458093265
610.9000000000079,196.35599843074417,-0.03915637534840999,-3.384959216723851
612.000000000008,196.72641588036302,-0.03982389511816742,-3.3861435240221107
613.100000000008,197.08959187735442,-0.04122064945725301,-3.3874302052541374
614.200000000008,197.4624269956287,-0.042245073773051534,-3.3867701999912208
615.300000000008,197.83060305474805,-0.03826987049568609,-3.3874299305455597
616.400000000008,198.20286876585888,-0.03702135751974289,-3.386770296814479
617.5000000000081,198.57748485214123,-0.04060405219581775,-3.38841018887798
618.6000000000081,198.94500159632554,-0.03579188608664774,-3.3872358322384772
619.7000000000081,199.31908509284838,-0.03439254786561041,-3.385719917038459
620.8000000000081,199.6866520212844,-0.03874311289388965,-3.3881165430252267
621.9000000000082,200.05257849371944,-0.03849072504041817,-3.3894274817104177
623.0000000000082,200.42359861921472,-0.035493521835206265,-3.388967828830438
624.1000000000081,200.79148692044134,-0.03441468710015427,-3.3894003261363514
625.2000000000081,201.16373421671554,-0.03130370893687662,-3.3900478268603815
626.3000000000081,201.53321920168474,-0.03153827361584105,-3.3916999613939844
627.4000000000082,201.90159641693415,-0.030255246040620576,-3.3913715614987034
628.5000000000082,202.28007460566567,-0.027971607165135026,-3.3897304633672047
629.6000000000082,202.64849409318717,-0.03184946386739884,-3.3910431878005696
630.7000000000082,203.01270491346267,-0.032499321780809276,-3.3913824563867045
631.8000000000083,203.3813581245892,-0.03017966216211576,-3.3923609295568378
632.9000000000083,203.74625830266538,-0.027005610556768755,-3.392663378128831
634.0000000000083,204.11985183094853,-0.02822662905429496,-3.393115347969491
635.1000000000083,204.49133208209432,-0.030542161899864695,-3.3926756540218843
636.2000000000083,204.86287430288348,-0.029380285453431854,-3.3940002479567575
637.3000000000084,205.22887396423337,-0.031549499116625745,-3.3928837510678553
638.4000000000084,205.60445167256321,-0.029260811630891004,-3.3949895970948436
639.5000000000084,205.97562948558345,-0.027631105274254608,-3.396310121886953
640.6000000000083,206.35215330066026,-0.03337381025756614,-3.396310123998504
641.7000000000083,206.72035612933564,-0.03158143979312611,-3.3972755792184675
642.8000000000084,207.09345958482385,-0.032119014568522064,-3.396969803247708
643.9000000000084,207.46446247431666,-0.02923939112626517,-3.3976054754812455
645.0000000000084,207.83641318129574,-0.03437683803957192,-3.397955382366149
646.1000000000084,208.20589417577304,-0.03300651455343473,-3.3979690018667013
647.2000000000085,208.5760638232113,-0.034271907520501244,-3.3986202018454303
648.3000000000085,208.94580488354669,-0.03530108161235879,-3.396871938077188
649.4000000000085,209.31851239675012,-0.03514533609175452,-3.3982906833253503
650.5000000000085,209.6931412017416,-0.034784965144700974,-3.400014097504735
651.6000000000085,210.06583712539506,-0.03504814755393759,-3.3976298300208816
652.7000000000086,210.43566003022968,-0.03273622555505373,-3.397127922212844
653.8000000000086,210.80534870786823,-0.03419512716496653,-3.398939850147774
654.9000000000086,211.16426805249117,-0.03186414771986479,-3.3985712455187014
656.0000000000086,211.54885729239936,-0.0315477430405704,-3.3986202478406007
657.1000000000087,211.91948494970282,-0.0322433846403154,-3.3999297481965707
658.2000000000087,212.30470283969137,-0.03569623498206276,-3.3992788239193383
659.3000000000086,212.67829651879154,-0.03856588619506607,-3.39958816645691
660.4000000000086,213.0507517892396,-0.03504359788226408,-3.3982883501707377
661.5000000000086,213.420356742529,-0.038148725202984624,-3.4002084046515546
662.6000000000087,213.7917340618967,-0.040017352624807434,-3.4001501491866
663.7000000000087,214.15882967918193,-0.0384676895556908,-3.4004783720188696
664.8000000000087,214.5298457569057,-0.03729611543551914,-3.4004875320496524
665.9000000000087,214.89916378240878,-0.03643445643111298,-3.399500047640104
667.0000000000088,215.2700783947187,-0.03537718218916841,-3.4014581825695833
668.1000000000088,215.6396222750175,-0.03343419934540215,-3.4006647170109634
669.2000000000088,216.01546289277428,-0.03193932667332677,-3.398390204484094
670.3000000000088,216.38699452506415,-0.03170307997484101,-3.399709955387999
671.4000000000088,216.74566127134392,-0.029576707846765915,-3.400355663739934
672.5000000000089,217.1258013561896,-0.0314492469487051,-3.4013601585469013
673.6000000000089,217.4980474938405,-0.03240030448006137,-3.4000402141531567
674.7000000000089,217.86549027640208,-0.0305157314625617,-3.401350041338244
675.8000000000088,218.2400271171776,-0.027523311505488923,-3.4000278384497107
676.9000000000088,218.60771891782412,-0.024249187819860296,-3.399127878297171
678.0000000000089,218.9789170897456,-0.023730969442925742,-3.3998188633220625
679.1000000000089,219.35017764294,-0.019796975817311102,-3.4000723313688814
680.2000000000089,219.7220711308518,-0.01873058565045671,-3.4015956599971546
681.3000000000089,220.0924454366196,-0.01832526788883837,-3.399479270901406
682.400000000009,220.46464227307584,-0.015808177650748823,-3.3995117303952154
683.500000000009,220.84018118975985,-0.013751117964323933,-3.3979109045748337
684.600000000009,221.207615132965,-0.011873375144711096,-3.397730004272039
685.700000000009,221.58151137833,-0.006393054798672804,-3.4036634705675017
686.800000000009,221.94659405662566,-0.010775979804656055,-3.399366372119739
687.9000000000091,222.3252923357363,-0.006816247645158313,-3.3970685365426774
689.0000000000091,222.6973961040747,-0.0013818922283839186,-3.411371689744685
690.1000000000091,223.06663252063433,-0.0007060176999142964,-3.403101303384583
691.2000000000091,223.43148173118735,0.0003752956793072748,-3.400803155149474
692.3000000000092,223.80828341004653,-0.0008417211269735603,-3.400817494901635
693.4000000000092,224.1781421253072,0.0007246333442623154,-3.4011298296845824
694.5000000000091,224.54990372199907,-0.004386426368267582,-3.401789807279183
695.6000000000091,224.91692464811993,-0.0012074287402172867,-3.4008110121220616
696.7000000000091,225.2918687942045,-5.9414236593058334e-05,-3.4014700104061486
697.8000000000092,225.66547481510776,-0.0006247448292209246,-3.402125566562275
698.9000000000092,226.03899900463622,0.000388191624657086,-3.402119572086206
700.0000000000092,226.4106422017865,-0.0011034046171003453,-3.402456352490405
701.1000000000092,226.78701805893337,-0.002381205600709091,-3.402450393657212
702.2000000000093,227.1635100881325,-0.003321915714104673,-3.4040234966545455
703.3000000000093,227.5363035678901,-0.00408102636433938,-3.4037745554093455
704.4000000000093,227.90124458707993,-0.004191940079562917,-3.4032566419278223
705.5000000000093,228.2710847498359,-0.0003026798122549579,-3.4040925833926132
706.6000000000093,228.63860170026194,-0.00397977681036088,-3.4040382376730722
707.7000000000094,229.01307951642244,-0.002325859556418397,-3.404750092457842
708.8000000000094,229.38283240430263,-0.007478568292050847,-3.404430159994988
709.9000000000094,229.75559566512138,-0.002418585743659607,-3.404734543006206
711.0000000000093,230.13218993191856,-0.006449857724455166,-3.404355972783165
712.1000000000093,230.50031688410255,-0.00515632738388927,-3.407050112548796
713.2000000000094,230.87860301397419,-0.01071395353609006,-3.407720100072334
714.3000000000094,231.24917358756858,-0.00877375012040571,-3.4077207875677935
715.4000000000094,231.61871248118754,-0.011725299735153794,-3.4080584038959625
716.5000000000094,231.9862355788912,-0.012303846607955471,-3.4073801999974678
717.6000000000095,232.35999641301646,-0.01269709430151722,-3.4086284255584904
718.7000000000095,232.73318296452575,-0.01686899158503352,-3.408381122709947
719.8000000000095,233.10841140724474,-0.01436176768513664,-3.4084054912837662
720.9000000000095,233.47418507037204,-0.018682051987623627,-3.4083801033964223
722.0000000000095,233.8427883050644,-0.018327515220061708,-3.40969993599534
723.1000000000096,234.21291418602948,-0.020566093098294935,-3.411007449406339
724.2000000000096,234.57063836682616,-0.02094122549462818,-3.4100388793002576
725.3000000000096,234.95852388224606,-0.020321842728978856,-3.411016556990614
726.4000000000096,235.3283634887042,-0.020739397014334582,-3.4110099080369594
727.5000000000097,235.70288645711884,-0.021732809857972546,-3.411669902226463
728.6000000000097,236.07639991661608,-0.024943100226484383,-3.41198930795707
729.7000000000096,236.4504421284385,-0.024326976428713953,-3.411352998566705
730.8000000000096,236.8253414854721,-0.02739787209471345,-3.4133101847477856
731.9000000000096,237.20283634026507,-0.026271899885532246,-3.4139645227521815
733.0000000000097,237.57064699808427,-0.033216517536649226,-3.413239961608898
734.1000000000097,237.94236345409797,-0.03230750862016829,-3.413967272961511
735.2000000000097,238.31407740654302,-0.03563612401147598,-3.4146301496790747
736.3000000000097,238.68700286123456,-0.042828067867620945,-3.4139698632148825
737.4000000000098,239.05641857091481,-0.03894985459146705,-3.416618669151555
738.5000000000098,239.4338038608053,-0.04251600539691225,-3.415285325001161
739.6000000000098,239.80233442738344,-0.04185400155410224,-3.4162307695603404
740.7000000000098,240.17337960510355,-0.045800450659643666,-3.416922618309472
741.8000000000098,240.54486336252955,-0.05037313298382351,-3.416600578813576
742.9000000000099,240.9184259929976,-0.05335092573647082,-3.4179667090155155
744.0000000000099,241.29043107193468,-0.05559620010789956,-3.417797019829587
745.1000000000099,241.66446717954295,-0.0505990045508482,-3.417589859984724
746.2000000000098,242.04102824913414,-0.05975686344236064,-3.4189745873977166
747.3000000000098,242.4137589119763,-0.06191247200164973,-3.4182400630028487
748.4000000000099,242.78953540549867,-0.06317973691127143,-3.4199698209503104
749.5000000000099,243.15819946215768,-0.06468548078998748,-3.4179379202330438
749.90000000001,243.29065451788833,-0.070215678436234,-3.4195595306016062