File: 01_Data/EIFS_Mesh/STA/N2/30K_min/EIFS_Mesh_STA_N2_30KData_230906_R1.csv
##Temp./Â°C,Time/min,DSC/(mW/mg),Mass loss/mg
41.0,10.569398041146709,0.030071965604614004,0.0020455809738271213
42.100000000000016,10.756674920571978,0.0700231499565005,0.0030483700088268506
43.20000000000003,10.879872413357562,0.1021178931912039,0.00491013708357535
44.30000000000005,10.975841735217166,0.12802411854217466,0.003615769043216588
45.40000000000006,11.059525400050294,0.1543017955456576,0.002265257618826233
46.50000000000008,11.133977664106137,0.1741872605669763,0.003030038079670838
47.600000000000094,11.201722325123693,0.19634066792432536,0.0034707547056047616
48.70000000000011,11.264414569577404,0.2141149449169577,0.002409662871246887
49.800000000000125,11.323802659083807,0.23156498689351035,0.0033712183931751127
50.90000000000014,11.380584788946615,0.24626780897498612,0.0025238719712668
52.000000000000156,11.432742800182794,0.26517956662751674,0.002980390926641263
53.10000000000017,11.486184355206463,0.27750122779226727,0.004262663910072462
54.20000000000019,11.537836772230555,0.2889622196438686,0.0041279412269563664
55.3000000000002,11.586621681563294,0.30087644530463176,0.0033441957746882522
56.40000000000022,11.634332164367974,0.31585899306783727,0.001310504941538504
57.500000000000234,11.68130567559607,0.3262503284072382,0.0015804383028825697
58.60000000000025,11.72667833559794,0.3407907380879709,0.003059209138866592
59.700000000000266,11.771136990854277,0.3492610773013014,0.0030204607100667857
60.80000000000028,11.816247248922922,0.36115900874398976,0.0022565054703909126
61.9000000000003,11.859725970161255,0.3715590548957919,0.003396965075346259
63.00000000000031,11.902200676786794,0.38247861776675585,0.0037662943158540685
64.10000000000034,11.943711574044379,0.3949157638746552,0.0017144801707784652
65.20000000000034,11.98684738434922,0.40197149767488427,0.0016324425844009838
66.30000000000035,12.028374824784528,0.4151888163570243,0.0012957148391246065
67.40000000000038,12.069554825605726,0.425554719990223,0.0017310613592798063
68.5000000000004,12.110450863335197,0.4333256208454266,0.001457720395919182
69.6000000000004,12.150888964835644,0.4439753592222857,0.0011847414754138086
70.70000000000041,12.191550382327078,0.45592917617708295,0.0013481434703903616
71.80000000000044,12.231521962077414,0.4641438467707173,0.0011051702624955695
72.90000000000046,12.27157878619547,0.47218186488115177,-0.00014067854826560477
74.00000000000047,12.311170151307438,0.4827145768265195,-0.00033015946588133005
75.10000000000048,12.350618094938469,0.49034177760539843,-0.00019031802835645095
76.2000000000005,12.389705344232421,0.49769017852174735,-0.0019123714141784376
77.30000000000052,12.428775033119818,0.5033668471565635,-0.002312191547469311
78.40000000000053,12.467462752781183,0.513790718721234,-0.0036049678130023466
79.50000000000054,12.507028246533125,0.5204872980933402,-0.002158559857764253
80.60000000000056,12.544501682820789,0.5267897900662899,-0.002386698518231256
81.70000000000059,12.58301334688798,0.5318927401662932,-0.002547476740075716
82.8000000000006,12.62206405132129,0.5340239625674947,-0.003721428792810677
83.9000000000006,12.660706077529056,0.540857266444414,-0.0045981533210470715
85.00000000000063,12.698880062201113,0.5435087646214578,-0.004832465244939854
86.10000000000065,12.736576287771166,0.5472890218058986,-0.00505314788332889
87.20000000000066,12.774281410534165,0.5513465990555901,-0.006345315072713298
88.30000000000067,12.81219840859943,0.553154160458404,-0.005079795537252352
89.40000000000069,12.849699619667035,0.555094758097237,-0.006388131239306816
90.50000000000071,12.887396763048,0.5588839936084755,-0.007753415179880818
91.60000000000072,12.924793584242762,0.5596256918117919,-0.007631872410780893
92.70000000000073,12.96186641816657,0.5597412293546205,-0.009007704817986628
93.80000000000075,12.99841058515088,0.5618493493042465,-0.009044256090682268
94.90000000000077,13.03518873736492,0.5627870321626354,-0.00770292837683062
96.00000000000078,13.072551054203405,0.5603806260111899,-0.0090416028472049
97.10000000000079,13.109654736461719,0.5609207003937751,-0.009959121051826614
98.20000000000081,13.146036000438196,0.5600677959118032,-0.010319127995884969
99.30000000000084,13.182418868065223,0.561028467521302,-0.011124002286545753
100.40000000000084,13.219871903339225,0.561566510879606,-0.010320377199111164
101.50000000000085,13.256537594638164,0.5605405754390356,-0.010319991670265871
102.60000000000088,13.29303644072034,0.5602211021787618,-0.010320091724824287
103.7000000000009,13.3298713414083,0.5614748570827619,-0.010338420792564307
104.8000000000009,13.366475019448862,0.5581862507712945,-0.011640306561762515
105.90000000000092,13.40257160784691,0.5581915478434505,-0.011632404339765756
107.00000000000094,13.439222315351795,0.5578148699592922,-0.012933384473083898
108.10000000000096,13.475506890145102,0.5565312768652309,-0.012962416125454013
109.20000000000097,13.510895876972251,0.5553854185042217,-0.014313410927653258
110.30000000000098,13.54750756170482,0.5536888859015668,-0.014275750071549353
111.400000000001,13.58493427795816,0.5514898963543556,-0.015148277093119944
112.50000000000102,13.621237295974405,0.5526000169028022,-0.015590196564773784
113.60000000000103,13.658190264601338,0.5515334022537441,-0.015589338803937203
114.70000000000104,13.694548450807446,0.5503507901950734,-0.0158360294667359
115.80000000000106,13.730479212441205,0.5481806603594348,-0.015222456799139472
116.90000000000109,13.766800085805045,0.548701745267707,-0.0149287531394382
118.0000000000011,13.803136973731188,0.5484231771088548,-0.015591478269720405
119.1000000000011,13.839024284922047,0.5456432060414245,-0.016902808959814664
120.20000000000113,13.87549416531009,0.5447773900248652,-0.01745375570736396
121.30000000000115,13.91126776582253,0.5422988785546157,-0.018192351788117733
122.40000000000116,13.947323154218964,0.5407770365608215,-0.019545624557284036
123.50000000000117,13.983278306615631,0.5383934275455673,-0.019552933760987656
124.60000000000119,14.019097358869796,0.5363621179938576,-0.018948981444881774
125.70000000000121,14.0548459685403,0.5342068379532611,-0.018558874194169128
126.80000000000122,14.090504147632407,0.5355690271975638,-0.018560086154400857
127.90000000000123,14.125996061663916,0.535835377524192,-0.018560088100269212
129.00000000000125,14.161950006353386,0.5319252551960596,-0.018560087991234653
130.10000000000127,14.197482903271256,0.5288697532253779,-0.01856008843480339
131.2000000000013,14.232723504102136,0.5280846202355417,-0.018560198043283904
132.3000000000013,14.268077227311078,0.5271420465906944,-0.01856092516519059
133.4000000000013,14.304273624055304,0.5251066166001543,-0.020728695457902013
134.50000000000134,14.339081578568182,0.5233197995221419,-0.021189595825078733
135.60000000000133,14.37475624946229,0.5208739727497321,-0.021189997223760138
136.70000000000135,14.409808282854272,0.5166003009652116,-0.021191757142728918
137.80000000000138,14.444866382095348,0.5158497538548776,-0.02207128216310128
138.9000000000014,14.479628188238209,0.5121358406776221,-0.02215617109779444
140.00000000000142,14.514823462658025,0.5123376833208184,-0.02250847593784755
141.10000000000142,14.549673251380355,0.5110252603489163,-0.022490286713101604
142.20000000000144,14.58447876229014,0.5078478231758898,-0.023508504701239552
143.30000000000146,14.619621867294363,0.506065044331971,-0.023500200013343076
144.40000000000146,14.65442769183228,0.5019360147645654,-0.023495408731058376
145.50000000000148,14.68925416958265,0.5012575624545297,-0.024231629422734713
146.6000000000015,14.723751191643608,0.49784265127068594,-0.024159331072797663
147.70000000000152,14.75891422591792,0.49592456252303785,-0.024160502995909106
148.80000000000155,14.79336935589076,0.4929845219480492,-0.02426044960027607
149.90000000000154,14.828027227006618,0.49069674549755515,-0.024490818457677754
151.00000000000156,14.86252169821157,0.48969734842384305,-0.02448819823329007
152.1000000000016,14.89717648709028,0.48611005854471,-0.024818437098385715
153.20000000000158,14.93152269295087,0.48567331276950865,-0.025147116664639313
154.3000000000016,14.966029103321862,0.48420573094145836,-0.02614591034092051
155.40000000000163,15.000281455938064,0.47975999199048314,-0.026795244355634296
156.50000000000165,15.03468982994808,0.479443456876094,-0.026789882741899085
157.60000000000167,15.068206733621958,0.475820628849695,-0.026789927569105032
158.70000000000167,15.102948752093802,0.47453050324971047,-0.02678992801654445
159.8000000000017,15.137741798705582,0.4757645140478328,-0.026789927231044786
160.9000000000017,15.172356606118544,0.4717484640171685,-0.026789848027423346
162.0000000000017,15.206584089480604,0.47233704422955447,-0.026798671825288167
163.10000000000173,15.240908336868538,0.4707122080084212,-0.02711611348187759
164.20000000000175,15.275187030295367,0.46891110451102525,-0.027120147407162953
165.30000000000177,15.309468742363062,0.46669477843943097,-0.027119999610281553
166.4000000000018,15.34377602214702,0.46615175103732776,-0.02712209415171518
167.5000000000018,15.377838873483686,0.4637373017023485,-0.026849758156741288
168.6000000000018,15.411816466592995,0.4643797883421402,-0.02679048646894433
169.70000000000184,15.446335997529834,0.46217378717470936,-0.026789920986737492
170.80000000000183,15.479710193705955,0.46296086633704003,-0.02679090222884284
171.90000000000185,15.514441887390428,0.46204916321906264,-0.02672756356380379
173.00000000000188,15.548898850753607,0.4621318158889559,-0.02879478156016635
174.1000000000019,15.582630646776737,0.4583233201408994,-0.028770611492335618
175.20000000000192,15.61683592420598,0.4591888573655172,-0.02877019327840813
176.30000000000192,15.650737690315413,0.45896808818021095,-0.028770199990874268
177.40000000000194,15.684784553893488,0.45848864236131615,-0.028770200002544932
178.50000000000196,15.718688953676152,0.45734114866365083,-0.02877019993951002
179.60000000000196,15.752763665432719,0.4562607176205994,-0.028770189685211278
180.70000000000198,15.78670953554686,0.4567744615825273,-0.028771116594862534
181.800000000002,15.82061039448699,0.4566996607924608,-0.028790614705568096
182.90000000000202,15.854077582861619,0.4546491787324929,-0.03007583083232568
184.00000000000205,15.887918756879882,0.45530819539810774,-0.03009017539886738
185.10000000000204,15.921800089068153,0.4558231475023069,-0.03009009955392461
186.20000000000206,15.955325559258458,0.4564977467022482,-0.03008584005572512
187.3000000000021,15.989015600935495,0.45593157477575774,-0.03068539105930146
188.40000000000208,16.02308512492273,0.45517527542203984,-0.03108150539067367
189.5000000000021,16.05655601526557,0.4558419095765366,-0.031093604576022393
190.60000000000213,16.090657750757778,0.45558555176878224,-0.03043904793896779
191.70000000000215,16.123674533191515,0.45386822048786635,-0.03041978479723717
192.80000000000217,16.157337727124517,0.45704589737254253,-0.030417360020364548
193.90000000000217,16.190972187323872,0.453651320708202,-0.030766839960883807
195.0000000000022,16.2244592853889,0.4568357597570163,-0.030749222406021737
196.1000000000022,16.2579846678137,0.45551352883948115,-0.03074561165393952
197.2000000000022,16.291401912574234,0.4551526938965167,-0.03141978407377177
198.30000000000223,16.3252926507487,0.45321304247848326,-0.032056758740031555
199.40000000000225,16.358898020005622,0.4557870250846293,-0.03339016421228891
200.50000000000227,16.39244375413743,0.45454497145545925,-0.0333705569995697
201.6000000000023,16.425278316879865,0.4548645705184784,-0.033370100260699864
202.7000000000023,16.459238906913686,0.45210027802363506,-0.033370107370289226
203.8000000000023,16.492527127524692,0.45807302850434506,-0.033370131070247666
204.90000000000234,16.52605009638433,0.45598677212695493,-0.033372698745883334
206.00000000000233,16.559168650630625,0.4563377718872139,-0.032824268886952446
207.10000000000235,16.592968011414186,0.4577505978359443,-0.03206040993745596
208.20000000000238,16.626344658890257,0.4579252126560707,-0.03205363916216797
209.3000000000024,16.659729239006495,0.4574750860600584,-0.03343561694956332
210.40000000000242,16.693054802317366,0.4602125289066284,-0.03350812906671585
211.50000000000242,16.726779828208763,0.45913205478966257,-0.03467981994805669
212.60000000000244,16.759940240353263,0.4611078499902888,-0.03468997896067627
213.70000000000246,16.793348927888797,0.46054398199338764,-0.03468956819125246
214.80000000000246,16.826994509012682,0.4624751072879136,-0.034831370134765116
215.90000000000248,16.860031299290107,0.4630960926073621,-0.03600996343011076
217.0000000000025,16.89367211840665,0.46287178844388954,-0.03600970797876357
218.10000000000252,16.92691400483721,0.46343061734294966,-0.036009845591174816
219.20000000000255,16.96021731815091,0.46285248952317715,-0.036009843995108426
220.30000000000254,16.993457563661778,0.46623629983399845,-0.03600985108054289
221.40000000000256,17.027181626530062,0.4669060984826336,-0.036009376974854845
222.5000000000026,17.05956226919621,0.46650029242265,-0.03601655631785228
223.60000000000258,17.092893360575946,0.46916086268324764,-0.03733460672702815
224.7000000000026,17.126458298031142,0.46749246945251965,-0.03733004476421087
225.80000000000263,17.15996957728416,0.4690606725332741,-0.03733011600899072
226.90000000000265,17.19354227968449,0.4684619446487952,-0.03733011420753929
228.00000000000267,17.22669777534515,0.4702515375041749,-0.037330249975100926
229.10000000000267,17.25994171901665,0.47048243601930717,-0.03732986672314009
230.2000000000027,17.293231614889613,0.47334612717440966,-0.0385146267810752
231.3000000000027,17.32663902307924,0.4735499719404953,-0.038640177846444246
232.4000000000027,17.359670730539367,0.4752909864548247,-0.03863979799964845
233.50000000000273,17.393059310339996,0.47487319107981374,-0.03857908361189377
234.60000000000275,17.426093431186768,0.4761513394183887,-0.039874720883890546
235.70000000000277,17.459518239378852,0.4784348236289414,-0.04128284966750906
236.8000000000028,17.492273709213084,0.47818704640596066,-0.04128017648592319
237.9000000000028,17.52587995959174,0.4796904633214774,-0.04128038360893438
239.0000000000028,17.559147617193492,0.48152915679943464,-0.0412696587024457
240.10000000000284,17.592709193024756,0.48371421426092515,-0.03992922041849667
241.20000000000283,17.62565162806507,0.4845279899388397,-0.039908186347106245
242.30000000000285,17.658944182486948,0.48251107319649894,-0.04129004237229461
243.40000000000288,17.691941523620727,0.48488191873765213,-0.04128023492713773
244.5000000000029,17.724187778147364,0.48581184818411244,-0.0412800179887185
245.60000000000292,17.758721313299542,0.4846224059477884,-0.041280062854409216
246.70000000000292,17.791632151838634,0.488231752072459,-0.04128451893965934
247.80000000000294,17.824933312093805,0.4886097630910227,-0.04232837176965809
248.90000000000296,17.85825768437488,0.4888115475756904,-0.04259142502699209
250.00000000000296,17.89171412234692,0.491315682537606,-0.04259184265345439
251.10000000000298,17.924645043774888,0.4925263129842745,-0.04229399917270715
252.200000000003,17.957785366164885,0.4944568484762593,-0.04193789915960888
253.30000000000302,17.991090122001694,0.49364827716231097,-0.04194017319834131
254.40000000000305,18.024211035919837,0.4954420732319732,-0.0419344971816864
255.50000000000304,18.05731535233541,0.4969782482018912,-0.042656802785077996
256.6000000000031,18.09033537396268,0.4986140162679113,-0.043250009476957896
257.7000000000031,18.123960609439692,0.49908339383441963,-0.043250013739441595
258.8000000000031,18.15701137891173,0.500813819976442,-0.04324394746723259
259.9000000000031,18.190030180417555,0.5006870316613355,-0.04456952777213585
261.0000000000031,18.22308503773634,0.502190991897947,-0.04452207662285668
262.10000000000315,18.256514917609362,0.5026967642299992,-0.0459009804867998
263.2000000000032,18.289243121561718,0.505339143574919,-0.047161780498006234
264.30000000000314,18.321948372440104,0.504159370313511,-0.0472085178285373
265.40000000000316,18.355250903898988,0.507430504810477,-0.047217671194554
266.5000000000032,18.388852689013504,0.507570330887632,-0.04636025575358582
267.6000000000032,18.421873376111687,0.5096348892507672,-0.04700876273482013
268.70000000000323,18.455685146200786,0.5117107003237158,-0.04721050017706929
269.80000000000325,18.48851652849826,0.5127496041562134,-0.047209967877675396
270.9000000000033,18.521591629963684,0.5120530957910474,-0.047211378532867165
272.0000000000033,18.554737902089343,0.5126137281050761,-0.04693289006401491
273.1000000000033,18.58796360172842,0.5140399775846711,-0.04719610423076226
274.20000000000334,18.62121554217128,0.5171946904691659,-0.04721026410649509
275.30000000000337,18.654288073456158,0.5166881788350703,-0.04789620432130892
276.40000000000333,18.687578568306723,0.5163262297542264,-0.049890564386620095
277.50000000000335,18.720587978279294,0.5170083260254902,-0.04984022908133978
278.6000000000034,18.754040990672564,0.5173636285092643,-0.04980312425737443
279.7000000000034,18.78702934912935,0.5173780631180364,-0.05119201962683473
280.8000000000034,18.82046199139945,0.5171446638357224,-0.051159912129274066
281.9000000000034,18.85330491679336,0.5173801613823863,-0.051159838847140815
283.0000000000034,18.885944970401482,0.5177966088144994,-0.05115983109565736
284.10000000000343,18.919417381365008,0.5202230213341343,-0.05116011227160078
285.20000000000346,18.95295067373487,0.5195195339438679,-0.05123540416402328
286.3000000000035,18.98639916401601,0.5185129951037759,-0.05149182646093342
287.4000000000035,19.01891655899332,0.5210416351582385,-0.05150011933281773
288.5000000000035,19.052934118381774,0.5198390839674483,-0.051501167659444125
289.60000000000355,19.08610350159468,0.5191568716851578,-0.051407009475596954
290.70000000000357,19.119406064511466,0.5193478015584756,-0.05280949911623445
291.8000000000036,19.152721199878417,0.5183763451144412,-0.053685931313332436
292.9000000000036,19.185826831050434,0.5195840524883263,-0.05523775201951553
294.0000000000036,19.219270411881702,0.5185841558642459,-0.05544060745312418
295.1000000000036,19.252545578385043,0.5194473170345295,-0.05544017232361931
296.2000000000036,19.285548038952143,0.5196669945753176,-0.05544015593292251
297.30000000000365,19.319215946212452,0.5205929739597426,-0.05544015006995595
298.4000000000037,19.352124822571277,0.5208496785094389,-0.055439023964382717
299.5000000000037,19.385415811322545,0.520039776083529,-0.05555324083536117
300.60000000000366,19.41867137074016,0.5219570638184726,-0.05573906756900193
301.7000000000037,19.451885880946712,0.5203169684096896,-0.05578001764651663
302.8000000000037,19.485355036768237,0.5209226884808607,-0.055696151824419005
303.90000000000373,19.51878148145948,0.5237291191402097,-0.05706738197480732
305.00000000000375,19.55199259981303,0.5233311752725702,-0.05838782999748071
306.1000000000038,19.585280593912472,0.5231460863450892,-0.05840043914137594
307.2000000000038,19.61874585092034,0.5262666073653697,-0.05840040899993948
308.3000000000038,19.652232805784365,0.5257889190086737,-0.05835519933640798
309.40000000000384,19.685248755296833,0.5269177104827565,-0.058732408409323256
310.5000000000038,19.718797206527853,0.5289945267261349,-0.05874009729534624
311.60000000000383,19.752069740825043,0.5289183190419604,-0.05874044500272646
312.70000000000385,19.78532351344007,0.5305041609412109,-0.058690498945719316
313.8000000000039,19.81889537386847,0.5317455833587812,-0.060071361154766745
314.9000000000039,19.851943236776158,0.5326531864277261,-0.06004010059980125
316.0000000000039,19.885596609151687,0.5366812746862362,-0.06142619985230935
317.10000000000394,19.919127947135436,0.5403889807953238,-0.06138027250579059
318.2000000000039,19.952742432680566,0.5419689248070994,-0.0627865132992187
319.30000000000393,19.985728570754173,0.5442246588943067,-0.06268816680480649
320.40000000000396,20.019170925702014,0.5474319748209979,-0.06269576292958368
321.500000000004,20.053133045027483,0.5522591088921205,-0.06406092472833746
322.600000000004,20.086275177473816,0.5530785882389206,-0.06400448307083595
323.700000000004,20.11990959556776,0.5559352370909312,-0.06533158581865228
324.80000000000405,20.153062407691944,0.559305792075338,-0.0652960850299813
325.90000000000407,20.186848906185144,0.5621282638630991,-0.06668107543393376
327.0000000000041,20.21943965689429,0.5673070842687873,-0.06693532946641945
328.10000000000406,20.253057983110796,0.5707909648086849,-0.06796855278217162
329.2000000000041,20.287364159737752,0.5731898619800488,-0.06787089094264998
330.3000000000041,20.32060588763677,0.5760841323573536,-0.06927970091833346
331.4000000000041,20.353954189468727,0.5812143185201273,-0.07003536517555897
332.50000000000415,20.388078289255482,0.585414216148583,-0.07193262412490586
333.6000000000042,20.421405291829164,0.5901584056405313,-0.07237051348505164
334.7000000000042,20.455146284560914,0.5948537041135487,-0.073507979597502
335.80000000000416,20.488568812611277,0.5990487585006528,-0.07446230048674662
336.9000000000042,20.522446486235253,0.6040662186213452,-0.07447256048067974
338.0000000000042,20.55607172079149,0.6079809063251318,-0.07590840124917131
339.10000000000423,20.589701646693225,0.6120472608354302,-0.07650472318641954
340.20000000000425,20.62289126735515,0.6163226330768921,-0.07731634170236168
341.3000000000043,20.65696921698208,0.6193732153839517,-0.07851029876277993
342.4000000000043,20.690809747287513,0.6229034051015524,-0.07992252269027311
343.5000000000043,20.72378292691782,0.6273591730293132,-0.08138114992913525
344.60000000000434,20.757795347351923,0.6303461552702931,-0.0828823456308001
345.7000000000043,20.791574376825263,0.6335970989362769,-0.08447217171794152
346.80000000000433,20.82550814518398,0.6382175309642316,-0.08611583098632014
347.90000000000435,20.85917385910107,0.6382658079665071,-0.08806594041225724
349.0000000000044,20.892760825554127,0.6401269306100864,-0.09079446204811248
350.1000000000044,20.926383000029862,0.6397176784159968,-0.09316957714310226
351.2000000000044,20.960398616098544,0.6399621794971587,-0.09496723015528241
352.30000000000445,20.993882823710283,0.639983472194644,-0.09736004446930124
353.4000000000044,21.027515146189117,0.6401602225653475,-0.09991802202931988
354.50000000000443,21.06153939166533,0.6339761948147807,-0.10227308583262795
355.60000000000446,21.094781872093407,0.6310657111251764,-0.10501269608032082
356.7000000000045,21.12866591189638,0.6291318292641593,-0.10583182522963819
357.8000000000045,21.162792903851805,0.6244117519593884,-0.1088302613866774
358.9000000000045,21.196079739583485,0.6194873648407766,-0.11127128282058552
360.00000000000455,21.229447117011908,0.6114401126286002,-0.11389450666783896
361.10000000000457,21.26354714727721,0.6057085934936695,-0.11679074657318322
362.2000000000046,21.297633259903744,0.5949848050300288,-0.12047628894135753
363.30000000000456,21.33127375070104,0.5913432165661419,-0.123241382055705
364.4000000000046,21.364711775935444,0.5839859516368673,-0.1254118997052296
365.5000000000046,21.39851504525563,0.5758462557872787,-0.12841007279914063
366.6000000000046,21.432386983902145,0.5679900978238321,-0.13068533818788453
367.70000000000465,21.466172582907735,0.5633118145281639,-0.13410417153759635
368.8000000000047,21.49987566868883,0.5586745982541541,-0.1356809511125281
369.9000000000047,21.53391521853666,0.5519558459148891,-0.13965905376643617
371.00000000000466,21.567638190902805,0.5431791745699082,-0.1426716384855351
372.1000000000047,21.601698333467755,0.540653376890132,-0.14480014352816983
373.2000000000047,21.635608150888235,0.5364425014981477,-0.14727514294069488
374.30000000000473,21.669391037968783,0.5342319359777117,-0.1509167489368335
375.40000000000475,21.702856446561782,0.5310885322125773,-0.15375958885775454
376.5000000000048,21.73695637451716,0.526576350952551,-0.1561877733446324
377.6000000000048,21.770992949857597,0.5260433323539855,-0.15824383213229165
378.7000000000048,21.804828500591835,0.5243636472444682,-0.16115908710928561
379.80000000000484,21.839274341909086,0.521170919937896,-0.16356726151461443
380.9000000000048,21.873433139014942,0.5212727670067102,-0.1640048276339341
382.00000000000483,21.907337015460175,0.5200668396343906,-0.16585304694771796
383.10000000000485,21.9412105273461,0.5164050900163166,-0.16833029782184683
384.2000000000049,21.975222595819638,0.5143603026254797,-0.17096504949937108
385.3000000000049,22.009568733072882,0.5139080710278563,-0.17311727200664073
386.4000000000049,22.04355600155213,0.5121324845243201,-0.17468234929813464
387.50000000000495,22.077391175063795,0.5093120225814752,-0.17682189915710023
388.6000000000049,22.11175184798656,0.5088951535387506,-0.1787970182936367
389.70000000000493,22.14579489954987,0.5062561530418148,-0.1795964956384295
390.80000000000496,22.17972131449943,0.5066572998798013,-0.1811160348384071
391.900000000005,22.21424909463169,0.5070945859262317,-0.18234407312714884
393.000000000005,22.24817576016409,0.5038384630773411,-0.18362524080684572
394.100000000005,22.28247592625369,0.5038778860189805,-0.1858963714512436
395.20000000000505,22.31667068953743,0.5040432861454985,-0.1875627865702838
396.30000000000507,22.350744355788848,0.5035963253686198,-0.18788767025326214
397.4000000000051,22.3849823128643,0.5039796519986901,-0.18911752032343276
398.50000000000506,22.419099819017738,0.5067186155823644,-0.18994875101107933
399.6000000000051,22.453586694975012,0.5065114741894369,-0.19093334575170573
400.7000000000051,22.487584179903745,0.5057410690893438,-0.1925340466208212
401.8000000000051,22.521932502718833,0.5055958873701621,-0.19380979939073217
402.90000000000515,22.55552593066717,0.5075730288750828,-0.1956429881958499
404.0000000000052,22.58990683110958,0.5085983467148528,-0.19640004568490754
405.1000000000052,22.624949290416218,0.5109054835164407,-0.1977061985474058
406.20000000000516,22.65905614624744,0.5104971705883217,-0.19780488936125673
407.3000000000052,22.69339125702825,0.5123546441481659,-0.19913073993246622
408.4000000000052,22.72794829020694,0.5126567547131959,-0.19994589658194695
409.50000000000523,22.762057948897304,0.5171838722176391,-0.20064041661168375
410.60000000000525,22.796686570812337,0.5152788714366439,-0.20199052614967528
411.7000000000053,22.83084583623926,0.5176085121304344,-0.2033093368081289
412.8000000000053,22.86542009329737,0.5202035607796157,-0.20427844407429996
413.9000000000053,22.899115961234916,0.522049829920047,-0.20500188448678447
415.00000000000534,22.934254508383358,0.5224588740514546,-0.20632817627886135
416.1000000000053,22.96860518899549,0.524414263941209,-0.2076098726145421
417.20000000000533,23.00275452873014,0.5273345872660586,-0.20892129949096327
418.30000000000535,23.0374803957602,0.5296592248539093,-0.2096621959837992
419.4000000000054,23.071924737318792,0.531582134251596,-0.2102112572482615
420.5000000000054,23.10641011708652,0.5336088989691095,-0.2128813846384605
421.6000000000054,23.1409792321477,0.5365238882400576,-0.2143223309341642
422.70000000000545,23.175540523353146,0.5399184155491552,-0.21468898941293757
423.8000000000054,23.209461120515527,0.541961893066454,-0.21438223712465643
424.90000000000543,23.244082039800873,0.5426399838611817,-0.21575369901241492
426.00000000000546,23.27895396144553,0.5466882757872273,-0.21723186640092385
427.1000000000055,23.313271124642938,0.5479251260579732,-0.21892763572583895
428.2000000000055,23.347795666994827,0.5511221990499997,-0.22040243412357974
429.3000000000055,23.382493352266614,0.553673642066044,-0.221656187532691
430.40000000000555,23.417300892005404,0.5574401960905718,-0.22276644744924656
431.50000000000557,23.4516383016049,0.5618635810631991,-0.22419036493836053
432.6000000000056,23.48648458540461,0.5654885416364326,-0.22550938098652384
433.70000000000556,23.52099218130983,0.5678285757357623,-0.22701921656947288
434.8000000000056,23.55573059564499,0.5720790858204738,-0.2285033990612364
435.9000000000056,23.5902484999989,0.576100893237087,-0.2310076652387414
437.0000000000056,23.624819851908434,0.5803900482084831,-0.2327568016333159
438.10000000000565,23.659458611713774,0.5799405814779752,-0.2338948368197009
439.2000000000057,23.694558497368867,0.5812910575882962,-0.23640622195435945
440.3000000000057,23.729418022855036,0.5805946422507152,-0.2381423755565657
441.40000000000566,23.763867828877444,0.5797498542571501,-0.23957984422119027
442.5000000000057,23.79856225088614,0.5786236426351663,-0.24256474706217546
443.6000000000057,23.833542229562838,0.5770552180239321,-0.24458356068069032
444.70000000000573,23.868076861651918,0.5731302512376752,-0.24587236604924367
445.80000000000575,23.902759044935426,0.5671999587195944,-0.2475959100588061
446.9000000000058,23.937597195474293,0.5598835025556324,-0.24924660460303683
448.0000000000058,23.97235614394331,0.5545192075431218,-0.25090970831022164
449.1000000000058,24.007034253870145,0.548019801405438,-0.25306380991226307
450.20000000000584,24.041689454485837,0.5417044675165714,-0.2543092418470585
451.3000000000058,24.076392661475566,0.5347932230028944,-0.25509283593956766
452.40000000000583,24.111112139617372,0.5286299869729928,-0.25783161925000364
453.50000000000585,24.14600831153603,0.524710477128229,-0.2592347410189024
454.6000000000059,24.18025649396144,0.5169060932394731,-0.26005877619466977
455.7000000000059,24.215113250577176,0.512398892019877,-0.2608526047621944
456.8000000000059,24.24977978360658,0.5082501176877331,-0.2622812030924928
457.90000000000595,24.284820326295062,0.5074763382883347,-0.26394621724322676
459.0000000000059,24.31928198144224,0.5037416689810457,-0.26521479154732575
460.10000000000593,24.35446206839715,0.500191884988626,-0.2663530638619376
461.20000000000596,24.389617320602234,0.5007463080694031,-0.26827912439697954
462.300000000006,24.424205582737184,0.4990770084839363,-0.2690761677323392
463.400000000006,24.459234868810526,0.49610145623033786,-0.26990232705537975
464.500000000006,24.494167202154554,0.4966074212782686,-0.271150550422667
465.60000000000605,24.529041536393233,0.49838243309210994,-0.2723431269579786
466.70000000000607,24.56387443170139,0.4952385385447414,-0.2737031125842404
467.8000000000061,24.59879987200451,0.4964606338340094,-0.27528160774280686
468.90000000000606,24.633747464135006,0.49606361994580095,-0.27704612789470584
470.0000000000061,24.66875859295138,0.49429539243043297,-0.2783044940809165
471.1000000000061,24.70411844718744,0.4953874854590731,-0.27967029775232044
472.2000000000061,24.739233095492317,0.4964094425874387,-0.2810460586438217
473.30000000000615,24.77419359350454,0.4957642713574072,-0.2816715158302183
474.4000000000062,24.809453007277703,0.49215887385519363,-0.2833438881047319
475.5000000000062,24.84422116950586,0.49452943238304536,-0.28485651664872647
476.60000000000616,24.879275934923776,0.4969802428258139,-0.28634201924529945
477.7000000000062,24.914380840571322,0.4947131432603533,-0.2879764634940658
478.8000000000062,24.949641631346683,0.49473144027916494,-0.29023835574519596
479.90000000000623,24.984641189336777,0.4941477988945975,-0.29274477010338185
481.00000000000625,25.01970346756855,0.4928090440949806,-0.29464669714988956
482.1000000000063,25.054806301262527,0.4940721906844092,-0.29634005974471034
483.2000000000063,25.090159373204273,0.49337445628847965,-0.2977305876689069
484.3000000000063,25.125069919534237,0.49406623971717367,-0.2992974286910606
485.40000000000634,25.16016043526349,0.4928304736000737,-0.3008127217818384
486.5000000000063,25.195030699319275,0.4934798065002233,-0.3025644036341011
487.60000000000633,25.230637367032536,0.4896950835499859,-0.30460760949438725
488.70000000000636,25.265658391590904,0.48719200242386207,-0.3068863255224672
489.8000000000064,25.300913557724027,0.485880258648571,-0.3082957731987359
490.9000000000064,25.335716636399614,0.4845099703347103,-0.3094324535258983
492.0000000000064,25.371115643525663,0.4806515700614331,-0.31045027905683
493.10000000000645,25.405418846126164,0.4776435618330559,-0.3115329071660269
494.2000000000064,25.441333796829465,0.4765151748878801,-0.31244314429477305
495.30000000000643,25.476763513792214,0.47289164026298836,-0.3139528934110114
496.40000000000646,25.511691633134582,0.4691777615750302,-0.3155470321398628
497.5000000000065,25.547003862624493,0.4636165529825904,-0.31735334573807883
498.6000000000065,25.582208540033026,0.46196901077935404,-0.3182744280075158
499.7000000000065,25.617341910800704,0.45733381979858867,-0.3195925038003482
500.80000000000655,25.65198454909877,0.4541875538165847,-0.32089699039509556
501.90000000000657,25.68806778489074,0.4497696370167279,-0.32225641787854054
503.0000000000066,25.723184552407226,0.44512395682918826,-0.3221568838599791
504.10000000000656,25.75852791536267,0.4449845901798395,-0.3235311376918837
505.2000000000066,25.793975741641013,0.4400377958106616,-0.32345617418241757
506.3000000000066,25.828949972369173,0.43719309808322493,-0.32485173040983284
507.4000000000066,25.864264632478836,0.4355112924756447,-0.325627542301115
508.50000000000665,25.89936432587299,0.4321457951042209,-0.3263141402454308
509.6000000000067,25.935094863906315,0.43231377669828086,-0.32676615179917334
510.7000000000067,25.97009838844812,0.42886351767370623,-0.32782006947101205
511.80000000000666,26.005160034163747,0.42704536212952604,-0.3280909072018794
512.9000000000067,26.0404376970597,0.423758982140343,-0.32913096359023664
514.0000000000067,26.076432736031173,0.4224794762492188,-0.3291301243222797
515.1000000000067,26.111618481224173,0.41916455824439125,-0.3291369211549511
516.2000000000068,26.146746841740537,0.418062572973222,-0.33043147974436016
517.3000000000068,26.182520823315745,0.41638974489068126,-0.33102995851511885
518.4000000000068,26.217778368852137,0.41277180590924534,-0.331773590504731
519.5000000000068,26.25298169753019,0.40931355958424875,-0.33190299447154414
520.6000000000068,26.288609475476385,0.40861772027532484,-0.333076193016169
521.7000000000069,26.32380051461161,0.4060918722185385,-0.33307992088120475
522.8000000000068,26.359383360367865,0.40175487168818946,-0.3330799962641966
523.9000000000069,26.394780890849532,0.40445299930615175,-0.33308005848496647
525.0000000000068,26.430124883688364,0.39920927741753665,-0.3330802835618645
526.100000000007,26.46571450607617,0.400782753591558,-0.33418494813930355
527.2000000000069,26.501172158921698,0.40378197431545915,-0.3343993002672141
528.300000000007,26.536787919953653,0.41123124442225056,-0.3343998635145313
529.4000000000069,26.57228695978951,0.41488184381542004,-0.3343968420013925
530.5000000000069,26.60768749366525,0.41998761879728685,-0.33474857913642
531.600000000007,26.64306592678604,0.4223077915877401,-0.33506055148050296
532.700000000007,26.678470890965578,0.4243538073703539,-0.33506009191430985
533.800000000007,26.71406703534397,0.42324669218357047,-0.3350601356894525
534.900000000007,26.749473599861542,0.4240057548388956,-0.33506010864338576
536.000000000007,26.785100324180576,0.42597016763835815,-0.335060701397369
537.1000000000071,26.820499020913456,0.42730062304494887,-0.3345341047210706
538.2000000000071,26.85624643629557,0.42736329377020565,-0.3344002668502255
539.300000000007,26.891483096208574,0.4250828359574429,-0.3343966396721756
540.4000000000071,26.927576100925172,0.42648842138962384,-0.33516650180313645
541.500000000007,26.96308520334217,0.42772382060430947,-0.3357241391832315
542.6000000000072,26.9988627496141,0.4241057251541167,-0.3369588375352661
543.7000000000071,27.033509324467726,0.42005787981017984,-0.3370380943540625
544.8000000000072,27.06921704134051,0.4171470197376116,-0.3370400228349566
545.9000000000071,27.105273225395166,0.4158624093521174,-0.3370397195763335
547.0000000000072,27.141210710654537,0.4108477936190388,-0.33676989702784077
548.1000000000072,27.17675110682105,0.4070541214967942,-0.3357238315694291
549.2000000000072,27.21243218866535,0.40545091237542297,-0.3367462117337876
550.3000000000072,27.24826044274329,0.4041651755235851,-0.3370361719563384
551.4000000000073,27.28406579006529,0.40204320702973273,-0.3383326798801112
552.5000000000073,27.31950279283298,0.40036107307928903,-0.33835002913106615
553.6000000000073,27.355326239705427,0.3967306413216195,-0.3383501902812682
554.7000000000073,27.391305628791418,0.39635669632422865,-0.3383546589826909
555.8000000000073,27.42699623338719,0.39380894881214124,-0.33767618104605557
556.9000000000074,27.46186989485102,0.3907047333639049,-0.33769165082169295
558.0000000000074,27.498616177731204,0.3854147245868379,-0.33765884530502754
559.1000000000074,27.53439922707806,0.38340465050710193,-0.3389956210172791
560.2000000000073,27.570063915254877,0.3821681554615677,-0.33901004117279276
561.3000000000073,27.6061400828845,0.379014831169432,-0.33901004509858534
562.4000000000074,27.641859712218896,0.375649576978623,-0.3390100440055823
563.5000000000074,27.677650304515936,0.3704286806695365,-0.33901004402535495
564.6000000000074,27.713171376549,0.3676288696506733,-0.3390100478477831
565.7000000000074,27.749259707884804,0.3635263430981138,-0.33900992973421307
566.8000000000075,27.784829669027282,0.36195547255866234,-0.338952961406485
567.9000000000075,27.82141739394995,0.3588830513445007,-0.34032070657154634
569.0000000000075,27.856850996161935,0.34898510881720735,-0.340323371254581
570.1000000000075,27.892735809074175,0.34889704925843146,-0.3414940761588636
571.2000000000075,27.928866946516163,0.3459990764512142,-0.34165031947035107
572.3000000000076,27.964717754870584,0.34375845345093803,-0.3416501872615205
573.4000000000076,28.00062672562519,0.33803283855760224,-0.3416501840055983
574.5000000000076,28.036487068780886,0.3369731437497655,-0.341650183999767
575.6000000000076,28.07267704283903,0.3322427650061165,-0.34165018399999836
576.7000000000077,28.10857475351282,0.32869793600147523,-0.341650184000001
577.8000000000077,28.144628991238765,0.32470767636178,-0.3416501840002475
578.9000000000076,28.180595305615956,0.323629977633175,-0.3416501840052888
580.0000000000076,28.216736464427107,0.3211002419578688,-0.34165018130418856
581.1000000000076,28.252839367410015,0.31629198144107773,-0.3416498816297695
582.2000000000077,28.288222898816684,0.3180398847435083,-0.34167315490340533
583.3000000000077,28.324610218084242,0.31406555589223106,-0.34296491120223793
584.4000000000077,28.36089481433295,0.3121907028148726,-0.3429599845608049
585.5000000000077,28.396710987142086,0.31519490114620563,-0.3429601183278148
586.6000000000078,28.432978347987476,0.3173479564080326,-0.3425174387327168
587.7000000000078,28.469244160762905,0.31508671030797497,-0.342301216027332
588.8000000000078,28.50533211764476,0.31775122006320655,-0.3422999372471103
589.9000000000078,28.541112510939197,0.31692069526453126,-0.34229954881879365
591.0000000000078,28.577483714411994,0.3239753931982189,-0.3425271662458269
592.1000000000079,28.613716865143054,0.32049852270493207,-0.3430490964953017
593.2000000000079,28.649732136319635,0.32724115363782147,-0.3436136271264427
594.3000000000079,28.68592977357178,0.3265349997413898,-0.3429687110111965
595.4000000000078,28.722281921082185,0.3308161654600562,-0.34264752834079326
596.5000000000078,28.75807519581038,0.3355858945927096,-0.34263987419179553
597.6000000000079,28.794664293359496,0.34062437723045724,-0.34263981985062797
598.7000000000079,28.830653037172624,0.3460399338882698,-0.3426398199950982
599.8000000000079,28.866915909997473,0.3486182541222338,-0.3426398201197891
600.9000000000079,28.90311682667304,0.3513717029797071,-0.3426398351746105
602.000000000008,28.93940769472595,0.35645817768649557,-0.34263942679025794
603.100000000008,28.975510863025686,0.36114292689120553,-0.34337071109528106
604.200000000008,29.01150629804862,0.3669542160639312,-0.3436286659823842
605.300000000008,29.04814445376418,0.3701589339714443,-0.34351884149448564
606.400000000008,29.084385071096243,0.37225042875591297,-0.34329988039983306
607.5000000000081,29.1209891560049,0.3798245629626882,-0.34330001423785816
608.6000000000081,29.157175840795155,0.38708724646316217,-0.34330002312359964
609.7000000000081,29.19350277461987,0.3926141754932435,-0.34329989205178
610.8000000000081,29.229966181869823,0.3965481115514292,-0.34329896139399985
611.9000000000082,29.266251799789927,0.4016414001856694,-0.3435207866390275
613.0000000000082,29.302105499475086,0.4087881835062974,-0.34264127316990844
614.1000000000081,29.33884791279563,0.41334601582527775,-0.3426401129834553
615.2000000000081,29.375129219596587,0.41678696386610625,-0.3426400906436555
616.3000000000081,29.411345949840104,0.4214856761676855,-0.34264001754970996
617.4000000000082,29.447804404695255,0.42659985075810336,-0.3426532678544447
618.5000000000082,29.484076176537133,0.4298506059150353,-0.34400842410139365
619.6000000000082,29.52046186587438,0.43417843865532235,-0.3438915902460935
620.7000000000082,29.557135763307734,0.43934308141221423,-0.34462502084090874
621.8000000000083,29.593473996574446,0.4440965827621203,-0.34461995948044155
622.9000000000083,29.629538222142045,0.4500383726728189,-0.34462045997908186
624.0000000000083,29.66607325023311,0.4557752687964638,-0.3446721351340507
625.1000000000083,29.70224550444488,0.4599788341479676,-0.3432985553925336
626.2000000000083,29.7390739264967,0.46579389746893674,-0.34329991687992933
627.3000000000084,29.77538434549171,0.4692751255703632,-0.34329737321555287
628.4000000000084,29.811858176312885,0.47580453375449483,-0.3436581300034547
629.5000000000084,29.84794456779417,0.47973990570465364,-0.34362974302699456
630.6000000000083,29.884524106581015,0.4822571880462536,-0.3436300245449395
631.7000000000083,29.920910570149054,0.4863383082461302,-0.34363002799158604
632.8000000000084,29.957126910070382,0.49041899581728765,-0.34363002803291876
633.9000000000084,29.993813325830654,0.49326225925040623,-0.34363003321414043
635.0000000000084,30.030233322380198,0.4979531894678626,-0.3436300766654776
636.1000000000084,30.066795037055428,0.5003316393144888,-0.3435661156401091
637.2000000000085,30.102529243484213,0.5014414232867296,-0.3442687170641143
638.3000000000085,30.138956675727393,0.5057367307442964,-0.3446085344538279
639.4000000000085,30.175948863337112,0.5067874567354268,-0.34463606156535764
640.5000000000085,30.21199045835282,0.5051169263740044,-0.3459354315089693
641.6000000000085,30.247728544738855,0.5067500061377445,-0.34592993968540675
642.7000000000086,30.284753244104007,0.507561027760663,-0.3459299860212228
643.8000000000086,30.321272472317045,0.5036704713658302,-0.3459334904051139
644.9000000000086,30.357940935692458,0.5059518789250503,-0.34505881598314847
646.0000000000086,30.393995931545977,0.5039629080055958,-0.3449401488739512
647.1000000000087,30.430606197526153,0.5036224841659631,-0.34493999637479344
648.2000000000087,30.466743765990387,0.5021696854793083,-0.34493999983987456
649.3000000000086,30.503453477267037,0.4997474703996244,-0.3449399991320612
650.4000000000086,30.539489446455846,0.4995111061929727,-0.344941878924129
651.5000000000086,30.576028676905135,0.5002405729930033,-0.3452001625617611
652.6000000000087,30.612767615797143,0.4983635094511897,-0.3469018961699324
653.7000000000087,30.649216983785095,0.49662356053876433,-0.3475809208705929
654.8000000000087,30.68531251848352,0.4985570873628238,-0.34670995337016386
655.9000000000087,30.72236896569502,0.49855920251763886,-0.34625933524468433
657.0000000000088,30.758801702477186,0.49940296392814787,-0.34625985042303054
658.1000000000088,30.795375565194615,0.4969046601512903,-0.3462598679119888
659.2000000000088,30.83161678943433,0.49628963777555235,-0.34625986800075603
660.3000000000088,30.86804535072839,0.49597702891395623,-0.3462598680002231
661.4000000000088,30.904681738919813,0.4962689222555057,-0.34625986804708964
662.5000000000089,30.941086033544625,0.49928890457365926,-0.34625986995371516
663.6000000000089,30.977476332890713,0.49801892693354644,-0.3462593956737847
664.7000000000089,31.013751863738626,0.4955557817538221,-0.3461859857419256
665.8000000000088,31.05050302875371,0.4962845193911627,-0.34764337758480446
666.9000000000088,31.087052575914857,0.498740348039306,-0.34659564208568616
668.0000000000089,31.123370675712742,0.4960676213319799,-0.3462503008374411
669.1000000000089,31.160169211761517,0.4977366923015738,-0.3462606015781571
670.2000000000089,31.196436165947475,0.49580844659291556,-0.34626014885070155
671.3000000000089,31.232901764895207,0.498289193040931,-0.3462607057178171
672.400000000009,31.26959863093748,0.4994445435882875,-0.3462518336204212
673.500000000009,31.306256623293717,0.4978663282810205,-0.3471987075215828
674.600000000009,31.342521477408116,0.497809965783506,-0.34691476235597296
675.700000000009,31.37931244971979,0.49616418432380915,-0.34652020715190623
676.800000000009,31.415910362010283,0.4958314045526033,-0.34626116729076806
677.9000000000091,31.452223802424175,0.4985802150069014,-0.3462599002804789
679.0000000000091,31.488944260999226,0.4981183814251746,-0.34625990789201255
680.1000000000091,31.52486775608994,0.49424936964197563,-0.34625990799944173
681.2000000000091,31.561612090478622,0.4925955707974796,-0.3462599080000066
682.3000000000092,31.5986367651509,0.49358836866086864,-0.34625990799957895
683.4000000000092,31.635392302566842,0.49335818160976186,-0.34625990787459093
684.5000000000091,31.672031283822385,0.49355162731461943,-0.3462598977852491
685.6000000000091,31.708513134368435,0.4874250377104228,-0.3462607641854163
686.7000000000091,31.74516780262647,0.4894895564067965,-0.34660246034031106
687.8000000000092,31.781700993216784,0.4870994221265117,-0.3469190900202612
688.9000000000092,31.818415345734074,0.4864572681591661,-0.3469204001671966
690.0000000000092,31.855150765946448,0.4869344266027906,-0.34705596490615953
691.1000000000092,31.891846835500665,0.48816135199602506,-0.34758162165729756
692.2000000000093,31.928109583808048,0.48819025574863106,-0.3475801384792918
693.3000000000093,31.964861234577157,0.48356927111801307,-0.34757365958876374
694.4000000000093,32.00177840308284,0.48605142084628916,-0.3487006955905265
695.5000000000093,32.0382566762231,0.48373905998713895,-0.3489001720165188
696.6000000000093,32.07486294593578,0.483964098937532,-0.3488998353543167
697.7000000000094,32.11169588789487,0.48543174952587775,-0.3489451018815126
698.8000000000094,32.148367533161746,0.4868296948701032,-0.347068130503946
699.9000000000094,32.18509669018578,0.4893470496220953,-0.3462585741846751
701.0000000000093,32.22178613844389,0.48927143229356873,-0.3463919191669187
702.1000000000093,32.25837850591155,0.48742924977129687,-0.3475793536655547
703.2000000000094,32.29522171948167,0.4864691566911068,-0.34757372102932527
704.3000000000094,32.331606140383734,0.4841666163546794,-0.3486833372337599
705.4000000000094,32.36868186951456,0.4836447422331518,-0.34890008849285925
706.5000000000094,32.404763149423594,0.48544863989111176,-0.3488999118206242
707.6000000000095,32.442029707410754,0.48513540654262033,-0.34890071039907955
708.7000000000095,32.47857811056626,0.4821179137153202,-0.34819571153499984
709.8000000000095,32.51572705110664,0.4831604600281627,-0.3479107939566952
710.9000000000095,32.55243529481496,0.48528546493659586,-0.34790990952696843
712.0000000000095,32.58906731044348,0.48537876134373814,-0.34790991567283847
713.1000000000096,32.6259497519576,0.482149251289812,-0.34790989674879613
714.2000000000096,32.662830722233345,0.4829197588326757,-0.347911385554585
715.3000000000096,32.699454386779074,0.48160468951097424,-0.34755046928180766
716.4000000000096,32.736098970731604,0.47617196081023705,-0.347602802307704
717.5000000000097,32.77293148400686,0.4771093235145982,-0.34889697614789217
718.6000000000097,32.810000673936756,0.48082618849788106,-0.3474931617832522
719.7000000000096,32.84692131619716,0.4790007583922393,-0.3475696467762792
720.8000000000096,32.88368666572243,0.4775777473770264,-0.347570861447005
721.9000000000096,32.92081285555281,0.47787316185620066,-0.3477029261132589
723.0000000000097,32.95751611041826,0.4763254987669423,-0.3502096724007635
724.1000000000097,32.99419873246183,0.47230555148314846,-0.35020408852517493
725.2000000000097,33.03121144837784,0.47419162550368665,-0.3488846339325171
726.3000000000097,33.068105640641605,0.4748892283401869,-0.3488899152029732
727.4000000000098,33.10492852484997,0.4728476828890378,-0.34888995600842154
728.5000000000098,33.141787011858725,0.47079263727101517,-0.348889956011321
729.6000000000098,33.17879148711078,0.4713943373719083,-0.34888995523613575
730.7000000000098,33.21563217104743,0.47072601517941304,-0.3488896952485794
731.8000000000098,33.25255260117649,0.4697534202373326,-0.34886444710123854
732.9000000000099,33.288853606575245,0.46680011078040606,-0.35021945575990365
734.0000000000099,33.32603506813908,0.4670066356169791,-0.35021047266242533
735.1000000000099,33.3632058786932,0.46357921882773745,-0.3497447574416883
736.2000000000098,33.39945004246821,0.46448535685932324,-0.34925804657704607
737.3000000000098,33.436442897438475,0.46170544672082814,-0.34889777273373346
738.4000000000099,33.474145767524995,0.45940553967724584,-0.34882418693182915
739.5000000000099,33.51113231141135,0.45933906853816486,-0.3502090526475903
740.6000000000099,33.54813398126285,0.45491916960164813,-0.3502100211354642
741.7000000000099,33.584812919157685,0.45416765082360944,-0.3502094570280714
742.80000000001,33.621866221562,0.4544990485040328,-0.34880854000665096
743.90000000001,33.65896396740016,0.45101814830405895,-0.34888944967364255
744.00000000001,33.662310794206995,0.45144824313660625,-0.348889565034737