File: 01_Data/EIFS_Mesh/STA/N2/30K_min/EIFS_Mesh_STA_N2_30KData_230908_R2.csv
##Temp./Â°C,Time/min,DSC/(mW/mg),Mass loss/mg
41.0,10.57637844904236,0.04459841048343627,0.025326411578022956
42.100000000000016,10.759702617219897,0.09440068938539747,0.026033794813279165
43.20000000000003,10.881093119797901,0.13240793362625602,0.024598882014958967
44.30000000000005,10.97561403759381,0.1665788403238202,0.025799554392834878
45.40000000000006,11.056929578707745,0.19786406287305902,0.02398718398584787
46.50000000000008,11.133706530199097,0.22215178493373688,0.024092228923053405
47.600000000000094,11.202237165889445,0.24703783267370705,0.025544515044773952
48.70000000000011,11.265159272362787,0.27085603581699247,0.026065111380026096
49.800000000000125,11.324122287781904,0.29048567701793093,0.02454351905462815
50.90000000000014,11.380414453523699,0.31133493260193257,0.024599417310086302
52.000000000000156,11.435392705410504,0.3290800161712475,0.02426920273581512
53.10000000000017,11.487173629192053,0.34558744521907725,0.02436333434191873
54.20000000000019,11.537676587750719,0.3629728146561473,0.024322477256627728
55.3000000000002,11.58647302837443,0.3777281945233044,0.024842839336134404
56.40000000000022,11.63415898720931,0.3925164800447849,0.024062357674283774
57.500000000000234,11.680567750923483,0.4083722521156059,0.02302524304914666
58.60000000000025,11.726560677862691,0.42127112203522654,0.023433679756863057
59.700000000000266,11.771343432822208,0.4367194848108369,0.023923127007162925
60.80000000000028,11.81610298464627,0.45171139240916225,0.02601923513526483
61.9000000000003,11.859202509952938,0.4648992862264114,0.0248898687003809
63.00000000000031,11.902209277407016,0.47812971618234834,0.023848508797128076
64.10000000000034,11.944544545349785,0.49123533892202254,0.02442196487864745
65.20000000000034,11.98627619735794,0.5029320028622681,0.02212569377935658
66.30000000000035,12.027673237422892,0.5160939117772303,0.022879403946829413
67.40000000000038,12.069295698327831,0.5280283022853252,0.02356474116876317
68.5000000000004,12.109927311773914,0.5411615331318227,0.02314921670190717
69.6000000000004,12.150548121175953,0.5532698982074002,0.023565511869277245
70.70000000000041,12.190895011075916,0.566053960921191,0.02305305363690735
71.80000000000044,12.230907406358064,0.5749875579569175,0.022603347445953048
72.90000000000046,12.270632419615879,0.5865787028735987,0.02225813282159983
74.00000000000047,12.310493399999078,0.5985099013483062,0.021972594439599646
75.10000000000048,12.349859053380225,0.6054558173701861,0.021854865700176695
76.2000000000005,12.389572119936465,0.6197974072592038,0.021534449105525155
77.30000000000052,12.427915096441891,0.6286897885612894,0.02154022261796662
78.40000000000053,12.468082215407058,0.6403706011424815,0.021095889783130595
79.50000000000054,12.506167158729342,0.6501326256324549,0.020334351559675667
80.60000000000056,12.544793034084863,0.6572744892697624,0.020006730809556394
81.70000000000059,12.583338917104768,0.6651227881419997,0.018681168026534856
82.8000000000006,12.62226941979905,0.6729480006349988,0.018157952242227715
83.9000000000006,12.660141899029467,0.6810864025651195,0.018764712907814562
85.00000000000063,12.698515775719324,0.6838619037574043,0.01875107044496005
86.10000000000065,12.736534162615069,0.69127826335127,0.01801058874167083
87.20000000000066,12.773992399862646,0.6968642829383811,0.017449849642557247
88.30000000000067,12.811905805368259,0.7035675372449695,0.017448421896060218
89.40000000000069,12.84930306295444,0.7065636958272206,0.01744916329698576
90.50000000000071,12.887062809222948,0.711192726297234,0.0166523004021073
91.60000000000072,12.924240714183643,0.7144575083988507,0.01616884821296516
92.70000000000073,12.961150068538613,0.7167068112727171,0.01586479656075568
93.80000000000075,12.998534851218066,0.7225531404432974,0.016137534704129486
94.90000000000077,13.035843862375916,0.7226018963116572,0.014815810115885064
96.00000000000078,13.072667287139435,0.7256465884151226,0.014824539030196426
97.10000000000079,13.109489043982862,0.7278842346375718,0.0135101225470029
98.20000000000081,13.146514749562439,0.7297178893895877,0.014651834840980094
99.30000000000084,13.183693958670904,0.7315042725839787,0.013381513661373745
100.40000000000084,13.220573767161273,0.7354476420725626,0.013489664554859893
101.50000000000085,13.256966119101152,0.7345786458602492,0.013492828005875701
102.60000000000088,13.292984243297258,0.7379460683360077,0.012496299831701307
103.7000000000009,13.330199181779351,0.7374868982691645,0.012175599317074237
104.8000000000009,13.366692124529319,0.7403455964107857,0.01087880578480771
105.90000000000092,13.40314799360387,0.7398089716855734,0.010909171157285513
107.00000000000094,13.439637250936613,0.741952137881065,0.011805083692310703
108.10000000000096,13.476420386207288,0.7429042614516821,0.010531181894553931
109.20000000000097,13.512531672822748,0.7421842382152627,0.010530010098793952
110.30000000000098,13.549176712529375,0.7438182707012532,0.010530000011427454
111.400000000001,13.585287519114766,0.7450328775703393,0.010530028075597997
112.50000000000102,13.621909603435771,0.7454849288681977,0.01053324011432899
113.60000000000103,13.658141437630764,0.7455018112290515,0.00919996024623071
114.70000000000104,13.694218965489968,0.74638734399082,0.009207823299814955
115.80000000000106,13.730591742357912,0.749620553440038,0.007821828831286126
116.90000000000109,13.76697361381007,0.7474414515264788,0.007900913502713713
118.0000000000011,13.803428585768529,0.7486474672822645,0.007900009743718961
119.1000000000011,13.839178457602532,0.74872794864614,0.007900000303087573
120.20000000000113,13.875236793887796,0.7465471064042013,0.007900339742834106
121.30000000000115,13.911406361262525,0.7491376068951762,0.007917695757820198
122.40000000000116,13.947450512361263,0.7505839676697588,0.007246118354191644
123.50000000000117,13.98337788846452,0.7498578893809139,0.007224618709423147
124.60000000000119,14.019098585069464,0.7492170606102502,0.006580755407025407
125.70000000000121,14.055233567170578,0.7497581557665488,0.006583111060974645
126.80000000000122,14.090705105763524,0.7502609444926478,0.005855962449269114
127.90000000000123,14.126977212784997,0.7494454069526301,0.004055180556936655
129.00000000000125,14.16154681990722,0.7513697195319561,0.003941031946409268
130.10000000000127,14.197973028844594,0.7511686704670525,0.00393999320008831
131.2000000000013,14.233371896141751,0.7516335522535244,0.003939999893994184
132.3000000000013,14.268830349777694,0.7503852096576473,0.003940000002212507
133.4000000000013,14.30463867913347,0.7501709435319917,0.003940001512398261
134.50000000000134,14.339495436994076,0.7470938144014563,0.003939995135563201
135.60000000000133,14.374792664314018,0.7453019343309375,0.00392317189531699
136.70000000000135,14.409805379390159,0.7488327669051511,0.0025912688104199333
137.80000000000138,14.444888022238807,0.7461717712864402,0.0026207318141358016
138.9000000000014,14.480498620672568,0.743389362769517,0.0026200051512725864
140.00000000000142,14.515724867381905,0.7446939110678826,0.0026181679131811464
141.10000000000142,14.550418885255576,0.7443109458518647,0.0025939265687346946
142.20000000000144,14.585727156886,0.7434943111290313,0.0013116329840050511
143.30000000000146,14.620456532997197,0.7418617248551036,0.0013110548886352547
144.40000000000146,14.655197187496015,0.7417397011975475,0.0023756326031323383
145.50000000000148,14.68977724617667,0.7422813359694385,0.0026201327175954248
146.6000000000015,14.724830718694976,0.741227049419422,0.002620018221144882
147.70000000000152,14.759483031181142,0.7410102064960783,0.0026199999684441977
148.80000000000155,14.794224176052465,0.740289899703428,0.002620000002456102
149.90000000000154,14.82904549850533,0.7395523134017803,0.002619999818164409
151.00000000000156,14.863229851966349,0.7386183695854057,0.002619969019267643
152.1000000000016,14.897863684870787,0.7381846621421455,0.002622834400632712
153.20000000000158,14.932804092782956,0.7393411653384865,0.0015490995412870134
154.3000000000016,14.96659175355417,0.7365355115588971,1.3699862098093263e-06
155.40000000000163,15.00183549814566,0.7368232355740499,5.837135219621814e-08
156.50000000000165,15.036261125207902,0.7386352636819695,-4.2198466942977575e-10
157.60000000000167,15.070806905700728,0.7400990036052018,-4.345857007592713e-12
158.70000000000167,15.104869459975037,0.7390009256995334,7.935874180020619e-12
159.8000000000017,15.13975158032907,0.7381816890895141,2.6979662948178884e-10
160.9000000000017,15.17404179361819,0.7394551632184957,-7.728830642150797e-08
162.0000000000017,15.208148992452427,0.7381209428486322,3.1191776894701206e-07
163.10000000000173,15.242648855775624,0.740205882987586,-0.0012926551988368118
164.20000000000175,15.275875766263134,0.7384446050243871,-0.001320117757245498
165.30000000000177,15.31103587284951,0.741332556971562,-0.0013200093087348819
166.4000000000018,15.34547112229204,0.74016418480821,-0.0013193393920452046
167.5000000000018,15.3788080455601,0.7425949402092384,-0.001288653115667504
168.6000000000018,15.414011865411846,0.7444795306712226,-0.0009876115674121166
169.70000000000184,15.448066273461016,0.7437016778420048,-0.0011816501100971877
170.80000000000183,15.482337087133478,0.7447433697923639,-0.002316142474667604
171.90000000000185,15.51641847637828,0.743820084867411,-0.0023099062396076953
173.00000000000188,15.550521616749721,0.7452108556302202,-0.0023099998011950618
174.1000000000019,15.58459087626122,0.7467174034248071,-0.0023100000110467533
175.20000000000192,15.6186189240611,0.7492802763521463,-0.002310000072698326
176.30000000000192,15.652787789025739,0.7488435302675723,-0.002310013217978746
177.40000000000194,15.686811673243474,0.7513682296975467,-0.00230880118661414
178.50000000000196,15.720862393147145,0.752108635824697,-0.0026930868418446607
179.60000000000196,15.754214976794335,0.7528728396386148,-0.0046782991172578114
180.70000000000198,15.788802907872373,0.7525522259482186,-0.00462059007924287
181.800000000002,15.8225156475829,0.7556201482683498,-0.004691186994079555
182.90000000000202,15.856157174021131,0.7559674666261813,-0.004955082972207148
184.00000000000205,15.890147090087476,0.7570219228350935,-0.003653734436659839
185.10000000000204,15.92419229553001,0.7601456089443427,-0.003629645262197556
186.20000000000206,15.957795687031064,0.7616561543441367,-0.003630031395521538
187.3000000000021,15.991489622121568,0.7615799828852491,-0.004360609942440696
188.40000000000208,16.025101310537806,0.7643615993622157,-0.004954477005507663
189.5000000000021,16.058316546142173,0.7636535043226852,-0.004949434270358655
190.60000000000213,16.092200629517947,0.7672423453540516,-0.004645675560153162
191.70000000000215,16.12593681315266,0.7661930272714002,-0.004954338958334414
192.80000000000217,16.159845895154863,0.7680562768578674,-0.004950788478859103
193.90000000000217,16.193054158582495,0.7719982683274802,-0.004850046988063017
195.0000000000022,16.22705990007863,0.773361701395222,-0.006268571331296879
196.1000000000022,16.260752455649815,0.7730890364924701,-0.00621950624231804
197.2000000000022,16.29397275653452,0.7758934772055,-0.0052730762292396705
198.30000000000223,16.327524893837097,0.777512536925337,-0.005280072057214369
199.40000000000225,16.361237815627103,0.7766814483982879,-0.005280008195034824
200.50000000000227,16.3947102948883,0.7787784409790482,-0.005278456334077308
201.6000000000023,16.427790147568295,0.7808853101742768,-0.005517765287816889
202.7000000000023,16.461732344453882,0.7814696996527285,-0.00599066910363355
203.8000000000023,16.494970136143383,0.7805785790030251,-0.004919190963732056
204.90000000000234,16.528266286729945,0.7875216828133229,-0.005619356421474375
206.00000000000233,16.561732901425515,0.7856811499893126,-0.005609836005209257
207.10000000000235,16.595120009965214,0.7894205879245852,-0.0056206105754035285
208.20000000000238,16.628688860048424,0.7891498578027103,-0.006611703922873247
209.3000000000024,16.662372703948364,0.7886237557205746,-0.006599733643896766
210.40000000000242,16.695531779214814,0.7911092429709117,-0.006599731042186807
211.50000000000242,16.728522507447337,0.7927677089123566,-0.006609569616321753
212.60000000000244,16.76209135871779,0.7930976176834071,-0.007948491197264929
213.70000000000246,16.79564477571193,0.7945900474258203,-0.008220917319694987
214.80000000000246,16.82903253273438,0.7952112149258272,-0.008239264099481058
215.90000000000248,16.862489780050186,0.7989139883278247,-0.008240011158668459
217.0000000000025,16.895407884405078,0.802313027759117,-0.008240000737904651
218.10000000000252,16.92943744501439,0.7988431010874848,-0.008240296000954217
219.20000000000255,16.961786162238905,0.8015589672408714,-0.008211361123202199
220.30000000000254,16.99511765045737,0.803861954211214,-0.007244448995031405
221.40000000000256,17.02925814453609,0.8055176342295383,-0.00852143727046073
222.5000000000026,17.06295259773857,0.8096135101782612,-0.008568072450800823
223.60000000000258,17.095976047336897,0.8098152983762662,-0.00856955513246982
224.7000000000026,17.129297548748134,0.8099444051242894,-0.008579031647195645
225.80000000000263,17.162289480869774,0.8126079433163506,-0.009898071391437835
226.90000000000265,17.195675870232563,0.8132277242294425,-0.00986685884691596
228.00000000000267,17.22920317351064,0.8162029191867095,-0.01055483929917278
229.10000000000267,17.262610640616725,0.8155146263897759,-0.010547960818906965
230.2000000000027,17.295685503648183,0.8171430302771863,-0.010857321430774558
231.3000000000027,17.329046092881875,0.8210464199750962,-0.01121140203521076
232.4000000000027,17.362357674348004,0.8236283275538018,-0.011209962982627442
233.50000000000273,17.395417616989118,0.8237053938730277,-0.011210901770501103
234.60000000000275,17.429104272197492,0.8242772029905552,-0.011187872055706816
235.70000000000277,17.462083843071664,0.825304034994308,-0.0125589894680731
236.8000000000028,17.495451093094452,0.8273863317611687,-0.011187064132799573
237.9000000000028,17.528416972509373,0.8303133225369261,-0.011199789367108526
239.0000000000028,17.561793590065466,0.832578192375585,-0.011200004733335156
240.10000000000284,17.594983289022366,0.8324107468491068,-0.011200000641077512
241.20000000000283,17.628272688226296,0.834877811546286,-0.011199973320219936
242.30000000000285,17.661617275997376,0.835170599244214,-0.011197767027477656
243.40000000000288,17.694785264234554,0.8358844699298846,-0.011638654704423157
244.5000000000029,17.728175155387113,0.8391486446886425,-0.012519368159693123
245.60000000000292,17.76106103327693,0.8413720717669195,-0.012520021076618093
246.70000000000292,17.794155913343307,0.839913589294236,-0.012514383859141276
247.80000000000294,17.827674438722706,0.8434146553503548,-0.013281173725181894
248.90000000000296,17.860442794862703,0.8444677707665827,-0.013840115710201495
250.00000000000296,17.894015085374477,0.8445422113010275,-0.01384009581441692
251.10000000000298,17.92683530184394,0.8456145419881844,-0.013833276367860137
252.200000000003,17.960183776193034,0.8462110166314212,-0.015157285805369902
253.30000000000302,17.99310561107888,0.8485009430018133,-0.015160497576997223
254.40000000000305,18.026491338179063,0.8497034394243278,-0.015159993177790376
255.50000000000304,18.059673171903523,0.8524390141427054,-0.015160000010538965
256.6000000000031,18.092253524107583,0.851755814009049,-0.01516000002366713
257.7000000000031,18.126055513278065,0.8547291916950066,-0.015159997347659271
258.8000000000031,18.159119100151237,0.8555512001378642,-0.015160056992662874
259.9000000000031,18.192384424917012,0.8575029828432246,-0.015176115677924429
261.0000000000031,18.225568613603183,0.8583310554138608,-0.01644776457496544
262.10000000000315,18.2583622196662,0.8609273423170276,-0.016470154150770355
263.2000000000032,18.292077640641413,0.860267815339224,-0.01647000212129779
264.30000000000314,18.32498586727094,0.8621183008180265,-0.016469998626013727
265.40000000000316,18.35802886889703,0.8629065909586868,-0.016470053618842684
266.5000000000032,18.391496981498126,0.8657170750083769,-0.016473800452349252
267.6000000000032,18.42437704573148,0.8670327082317852,-0.017481990068127118
268.70000000000323,18.457824154911684,0.8658585269823507,-0.01779164533951949
269.80000000000325,18.49101661194798,0.8682729651892271,-0.017792624747837493
270.9000000000033,18.52428159127669,0.8690220471018517,-0.018794681586336903
272.0000000000033,18.55733955859902,0.8702808950885261,-0.01911202594689687
273.1000000000033,18.590302746777436,0.8716923746816032,-0.019081494762537954
274.20000000000334,18.623386714347628,0.8717245170545715,-0.01780711898059728
275.30000000000337,18.656791387110545,0.872044990981123,-0.017790017271996472
276.40000000000333,18.69000030112723,0.8730741915075293,-0.01778999726665287
277.50000000000335,18.72317997542653,0.8735713016321859,-0.017756228821865783
278.6000000000034,18.75628416742561,0.8737397929826156,-0.019143153683669034
279.7000000000034,18.78961006932866,0.874921744320926,-0.019135272754197352
280.8000000000034,18.823109347962696,0.8752400775765128,-0.021045973237467486
281.9000000000034,18.855875945839426,0.8749335875897313,-0.021745532372507093
283.0000000000034,18.888987529316395,0.8763108447306502,-0.021739978611345023
284.10000000000343,18.922501659440705,0.8756023723443904,-0.021739981114225593
285.20000000000346,18.955095214229125,0.8751207905901772,-0.021741945409447627
286.3000000000035,18.988327892737168,0.8757012597052909,-0.021671536478721887
287.4000000000035,19.022069971922843,0.8771275009940765,-0.023058391153184754
288.5000000000035,19.05522054976189,0.8790841952621786,-0.023060035562795456
289.60000000000355,19.088300024343436,0.8775610269426062,-0.023060006061355054
290.70000000000357,19.12171704538586,0.876870529356879,-0.023060703565538798
291.8000000000036,19.154488520801237,0.8764867079557326,-0.022980926155768966
292.9000000000036,19.18834137222246,0.8770147287831285,-0.023338303635008995
294.0000000000036,19.221625240017627,0.8779223062802598,-0.023391718167873776
295.1000000000036,19.25481053230565,0.8781890294471869,-0.02330471531524747
296.2000000000036,19.28772621911188,0.8793593326039446,-0.024712611099651838
297.30000000000365,19.32127564865855,0.8790668578937063,-0.024710018503252495
298.4000000000037,19.354631631336726,0.8791582605942014,-0.024709999453411235
299.5000000000037,19.387986022203368,0.8809456919019532,-0.02471000057574768
300.60000000000366,19.421218152254358,0.8785112439879142,-0.024710028649781446
301.7000000000037,19.454526983531697,0.8800514483557185,-0.02470410648752841
302.8000000000037,19.48794003583461,0.878910348505332,-0.02549061989588486
303.90000000000373,19.520913028130483,0.8807112414347958,-0.02602051340948952
305.00000000000375,19.554246779506247,0.8809708608031901,-0.025936571159195676
306.1000000000038,19.587737966107035,0.8817502129793634,-0.027343680011184812
307.2000000000038,19.620887998090748,0.8831111530652644,-0.02734003084286618
308.3000000000038,19.65433418086259,0.883931248690366,-0.027336765528531703
309.40000000000384,19.68760098544348,0.8835528638235954,-0.027805439010318178
310.5000000000038,19.72075133769382,0.8849536367019402,-0.02866145882834159
311.60000000000383,19.754111467388284,0.8874378882638393,-0.028659930877607653
312.70000000000385,19.7875680380879,0.8874186576132936,-0.02866011509400801
313.8000000000039,19.82088776811743,0.889778355180079,-0.02866424493885722
314.9000000000039,19.854405796845256,0.8930738229710946,-0.02995383634430704
316.0000000000039,19.887504988785228,0.8927380772144042,-0.030142815131643186
317.10000000000394,19.921123874261877,0.8942521007494748,-0.031294057054281676
318.2000000000039,19.954463266168332,0.8983063866055825,-0.031249238802696144
319.30000000000393,19.987834200763906,0.8999812534294621,-0.032635193579143795
320.40000000000396,20.021151158231895,0.9023273231824203,-0.032612917950231246
321.500000000004,20.054343068105275,0.9058764868630792,-0.03361828858317839
322.600000000004,20.08797580441868,0.9059956954941069,-0.033948086663571964
323.700000000004,20.121344302367483,0.9079325266242319,-0.035010950784335026
324.80000000000405,20.154915118128663,0.9124606971418228,-0.03498844244210719
325.90000000000407,20.187748006632432,0.9124306037194889,-0.03622995553803765
327.0000000000041,20.221853154493513,0.9153944181320257,-0.03623880008759972
328.10000000000406,20.255465180756897,0.9176086629050412,-0.03764679390040371
329.2000000000041,20.288949834087322,0.9184509260920934,-0.03754614313625115
330.3000000000041,20.322284001437843,0.9247813607123652,-0.038697046307419214
331.4000000000041,20.355688083907108,0.9275649317391566,-0.03895366621565843
332.50000000000415,20.388961753745463,0.9303254644041875,-0.04018615110195034
333.6000000000042,20.422998630224953,0.9320511203297172,-0.041608912038686885
334.7000000000042,20.456544204971813,0.9371444149392292,-0.04152235555251238
335.80000000000416,20.49012274395431,0.9408978283031001,-0.042823252634491826
336.9000000000042,20.523413973783896,0.9455988804805977,-0.04384770294907936
338.0000000000042,20.557070644419397,0.9481434324839,-0.044728206267980575
339.10000000000423,20.590756403956114,0.9543532346273677,-0.04533208580796755
340.20000000000425,20.624413580875036,0.9578627105540997,-0.04571292539024707
341.3000000000043,20.65810148105704,0.9626109490919537,-0.046915618361729194
342.4000000000043,20.69195519028535,0.9673379595348055,-0.0485192907776395
343.5000000000043,20.72540183496956,0.9718178156359292,-0.04976467546191454
344.60000000000434,20.759006945293013,0.9761417613633702,-0.051382714233421556
345.7000000000043,20.792585242104316,0.9791667272464355,-0.05292910356572422
346.80000000000433,20.82648658328766,0.9829448939999201,-0.05444933512205408
347.90000000000435,20.860153752750502,0.9864709669672107,-0.0558814126735343
349.0000000000044,20.89350821512167,0.9885498575302692,-0.05771939374133117
350.1000000000044,20.92722193986259,0.9911128550436095,-0.06041874161546712
351.2000000000044,20.960976499173576,0.990196349669376,-0.06219785604697181
352.30000000000445,20.99488293921058,0.9909127256075417,-0.06374296620329734
353.4000000000044,21.028711207289753,0.9895668422843926,-0.06532416354302839
354.50000000000443,21.06198342641068,0.9869238588681659,-0.06743462209521267
355.60000000000446,21.095540672030797,0.9841563661463603,-0.07040835119275624
356.7000000000045,21.129049559668175,0.9809621682578911,-0.07238774568327644
357.8000000000045,21.162711863558577,0.9778627225800596,-0.07578366011838922
358.9000000000045,21.196456034113645,0.969913066712905,-0.0783780989670051
360.00000000000455,21.230244334497673,0.9662138758132746,-0.07972914712433221
361.10000000000457,21.264524759602715,0.9581348489499404,-0.08201407864618648
362.2000000000046,21.297692442483566,0.9517245795243658,-0.08405262263640756
363.30000000000456,21.33122595246574,0.9460332082612128,-0.08672943228349839
364.4000000000046,21.365383315816068,0.9403003312274537,-0.0894575810239413
365.5000000000046,21.39905171759791,0.9316074555119673,-0.09267143535022404
366.6000000000046,21.432619221891986,0.9258744309029759,-0.09584847763932114
367.70000000000465,21.46646662417388,0.9196511901537019,-0.09859645291078722
368.8000000000047,21.499969112053105,0.9148926873300699,-0.10089665044563301
369.9000000000047,21.534244050158943,0.9076119364146716,-0.1040463460654224
371.00000000000466,21.56784585452551,0.905264571984306,-0.10753395536746213
372.1000000000047,21.60167895957593,0.901349303947955,-0.11070993464100942
373.2000000000047,21.635577151870358,0.89624241249458,-0.11380378032506577
374.30000000000473,21.66966102963928,0.8933569138242603,-0.11581473869716419
375.40000000000475,21.703430395341442,0.8898659761528063,-0.11896031179997024
376.5000000000048,21.737412028318218,0.8882808334251852,-0.12111714223053172
377.6000000000048,21.771090034656396,0.886301926517493,-0.12320398888586626
378.7000000000048,21.805070524501197,0.8850455380298055,-0.12611737894345865
379.80000000000484,21.838919296943907,0.8835096179636124,-0.12778900387451353
380.9000000000048,21.87291666250713,0.8837856133768789,-0.12963318455953265
382.00000000000483,21.90722914553467,0.8831454622865992,-0.1325323870742432
383.10000000000485,21.941209368777297,0.8817951178922845,-0.1344398023941884
384.2000000000049,21.975286912409924,0.8831144039533072,-0.1358878891259767
385.3000000000049,22.008688069544448,0.8849522379675943,-0.13776937723468885
386.4000000000049,22.043144591287056,0.8842093154719837,-0.14019840705333309
387.50000000000495,22.07707900618782,0.8836398045938882,-0.14154431082576124
388.6000000000049,22.111409137481292,0.8825044003062509,-0.1431438228104458
389.70000000000493,22.145153469680324,0.8836987720827036,-0.14471750121176896
390.80000000000496,22.17895249510669,0.883986722888265,-0.14465299613571903
391.900000000005,22.21389886692492,0.8848744063067313,-0.14629481688188672
393.000000000005,22.2478438799392,0.8853098606165293,-0.14745811837985645
394.100000000005,22.281718208959468,0.8864756962029431,-0.14909683785865502
395.20000000000505,22.31611463730321,0.8889376357891445,-0.15040826386102424
396.30000000000507,22.350469928473995,0.891973523652239,-0.15235446119991192
397.4000000000051,22.384555755163237,0.89126269874461,-0.15561734034853503
398.50000000000506,22.418670069593375,0.8930802783082852,-0.15624180856025083
399.6000000000051,22.452865541025187,0.8954076636244575,-0.15733265767271032
400.7000000000051,22.48704396348483,0.8963089951424776,-0.15801858526819235
401.8000000000051,22.521168998386422,0.9001149208679673,-0.15867906043197832
402.90000000000515,22.555780921977323,0.9033978749098679,-0.1601133902248777
404.0000000000052,22.589852157924714,0.9026661442118004,-0.1615014293421284
405.1000000000052,22.624121317841208,0.9027935683707253,-0.16141793047040132
406.20000000000516,22.65836020906051,0.9066403057108152,-0.16284050037179032
407.3000000000052,22.69289919255647,0.9109004138764019,-0.16410935335648835
408.4000000000052,22.72698750987677,0.9145204377037255,-0.16566797568906155
409.50000000000523,22.76127326276074,0.9173430023655407,-0.167089154983719
410.60000000000525,22.795922546669765,0.9214704089877656,-0.16849231315945712
411.7000000000053,22.830227291061927,0.9230184836975875,-0.1684263099261596
412.8000000000053,22.86461132460255,0.924233979426362,-0.16877279484580665
413.9000000000053,22.899043123078236,0.9276442795764455,-0.16899632487751814
415.00000000000534,22.933156654190938,0.933143653514144,-0.170082052650808
416.1000000000053,22.96788438382425,0.9353410559310692,-0.1714749992229616
417.20000000000533,23.00206790616655,0.9369549070974637,-0.17289302822364183
418.30000000000535,23.036694718102495,0.9394918733741129,-0.17407102257288765
419.4000000000054,23.071125516497364,0.9436474802979813,-0.17559030417392174
420.5000000000054,23.105687035533304,0.9467305082227744,-0.17854605845192895
421.6000000000054,23.13983361933078,0.9485778163889651,-0.17993015117998645
422.70000000000545,23.174706563451082,0.9508111347084277,-0.17996566243339673
423.8000000000054,23.209152499056948,0.9520477580061592,-0.18136569760836085
424.90000000000543,23.24363912961985,0.9590947752799598,-0.18186547501006922
426.00000000000546,23.278260642133304,0.9618019819893266,-0.18305423423686706
427.1000000000055,23.312785246490463,0.9634212549671445,-0.18324165290242433
428.2000000000055,23.347302021695533,0.96905769639533,-0.18439149156051515
429.3000000000055,23.381935707732055,0.9727428179245023,-0.18737537261243897
430.40000000000555,23.41647976886557,0.976483380254201,-0.18900867112442876
431.50000000000557,23.45099385094809,0.9815381785553416,-0.190482800952251
432.6000000000056,23.48590942234875,0.9838654627406835,-0.191893421550287
433.70000000000556,23.52035628162056,0.9891317412904796,-0.19323816952713146
434.8000000000056,23.555306628763407,0.9927013641540074,-0.1935528786820795
435.9000000000056,23.59003231871099,0.9986823356647414,-0.1949804564200308
437.0000000000056,23.624217316774462,1.0014717920651652,-0.1965246185252565
438.10000000000565,23.659343597048842,1.0050615072115332,-0.19831522700800885
439.2000000000057,23.693822243900232,1.0098203974486555,-0.20036591911641732
440.3000000000057,23.72869495748658,1.0138606232043363,-0.20198099375749035
441.40000000000566,23.76353495407005,1.015611597078415,-0.20409441613284685
442.5000000000057,23.79828700551439,1.0164255136750115,-0.20651581048167023
443.6000000000057,23.832774055643807,1.0119099041593222,-0.2077940350619354
444.70000000000573,23.867432771501512,1.0102051734881443,-0.20932288945810118
445.80000000000575,23.90207166657437,1.0067621852845405,-0.21105998662651126
446.9000000000058,23.93672478698095,1.0022089682045563,-0.21346525418866946
448.0000000000058,23.971652371312693,0.9983538414898039,-0.21567226355158997
449.1000000000058,24.00618846141396,0.9932667669899987,-0.21757588456986277
450.20000000000584,24.041006342283573,0.9832621593217175,-0.21923567226955143
451.3000000000058,24.075791176983326,0.9813229275943782,-0.22022519180196198
452.40000000000583,24.11056645577008,0.9753061166896417,-0.220989567218993
453.50000000000585,24.145106608147273,0.9680945063145855,-0.22237686301997694
454.6000000000059,24.180254825727296,0.963166567687122,-0.22363907549991735
455.7000000000059,24.214773851228202,0.9584871497903087,-0.22529600092538615
456.8000000000059,24.249777304796975,0.9565952739982136,-0.22779458106523265
457.90000000000595,24.284841166893855,0.9536244939156999,-0.228691074296687
459.0000000000059,24.31927215967234,0.9525178290657781,-0.2295374205731795
460.10000000000593,24.354430221069915,0.9478660063846716,-0.22970307852669425
461.20000000000596,24.38936831672153,0.9494165977486211,-0.2309715443956155
462.300000000006,24.42398926019754,0.9456836969005697,-0.23221001229360638
463.400000000006,24.45922612554966,0.9445908402745812,-0.23384068441634476
464.500000000006,24.49391743571176,0.9441702387481732,-0.2351324053966053
465.60000000000605,24.52924039412883,0.9431475729530963,-0.23671641444757086
466.70000000000607,24.56393527127178,0.9429984983051451,-0.23802975384829672
467.8000000000061,24.599012268408412,0.9432166213082105,-0.23956549941419736
468.90000000000606,24.633776328255696,0.9406068353295629,-0.2409184429247091
470.0000000000061,24.668857481623906,0.9411391836269689,-0.24363061385789342
471.1000000000061,24.703675394408748,0.9396410897329803,-0.24541761600963374
472.2000000000061,24.738672976857153,0.9413900627449477,-0.2469094499155684
473.30000000000615,24.77362203959681,0.9417796418504498,-0.24814841197405624
474.4000000000062,24.80866577535646,0.9406023384055132,-0.249485882043742
475.5000000000062,24.843829658044704,0.9417697709516915,-0.25134533147127813
476.60000000000616,24.878606736847733,0.943295942951693,-0.253775663418228
477.7000000000062,24.91357909818721,0.9438238506557018,-0.2553260853271482
478.8000000000062,24.94885890420645,0.9432325922537161,-0.2559214679614743
479.90000000000623,24.984011647692167,0.9413397428186787,-0.2581022119340628
481.00000000000625,25.01891197564276,0.9400650331075999,-0.26012481323091396
482.1000000000063,25.053808740486847,0.941185384374164,-0.26125147690049255
483.2000000000063,25.089017276047247,0.9435700247048667,-0.26321787571024835
484.3000000000063,25.12443792630091,0.9403327465520875,-0.2639363436671345
485.40000000000634,25.159021870944454,0.9408944765109337,-0.26423778707314627
486.5000000000063,25.194116388429556,0.9386142273594937,-0.2659664695744133
487.60000000000633,25.22902673161462,0.9371467039324275,-0.26788436634672763
488.70000000000636,25.26459153634938,0.9339846318539644,-0.2694783837966397
489.8000000000064,25.299771485933906,0.9331475759918281,-0.27312756599663013
490.9000000000064,25.334872541178175,0.9320774396223378,-0.27492493198486434
492.0000000000064,25.369904966211838,0.9284668857871766,-0.2761022956528407
493.10000000000645,25.40497042182812,0.9289263270723681,-0.2772318329732988
494.2000000000064,25.43987081205412,0.9251942710240574,-0.27808931739260156
495.30000000000643,25.475373297311567,0.9232964537618085,-0.2793869403039624
496.40000000000646,25.510542131910675,0.9183791085781473,-0.28093080544889926
497.5000000000065,25.54489024772399,0.9167491459214216,-0.2826578595161511
498.6000000000065,25.58074443942224,0.910257972962621,-0.28285005332089996
499.7000000000065,25.615823507827393,0.9097872965099909,-0.28312582788251284
500.80000000000655,25.651164088758474,0.9065762337272153,-0.28411102812840383
501.90000000000657,25.686220854620746,0.9034532014298816,-0.2854401016561914
503.0000000000066,25.721072255356415,0.9046572734449381,-0.2867398957420604
504.10000000000656,25.75665550224318,0.9016697970138329,-0.2880859470985837
505.2000000000066,25.79164781756214,0.8993212724570195,-0.2894107765303251
506.3000000000066,25.826568822420718,0.8953160026407847,-0.2905688158504405
507.4000000000066,25.862257944011784,0.8939407160778985,-0.29069733714108814
508.50000000000665,25.897697967215233,0.889289025134253,-0.2920540089773236
509.6000000000067,25.932727074697482,0.8858635796406147,-0.29215157406939696
510.7000000000067,25.96821028283807,0.8873152832870912,-0.2933453394601848
511.80000000000666,26.00320452041124,0.8825857990109118,-0.2933499210068775
512.9000000000067,26.038635888472637,0.8804670687352719,-0.29335059398534913
514.0000000000067,26.073934178292742,0.881651644191232,-0.29354038050621245
515.1000000000067,26.109161899953804,0.8787760355630154,-0.2942831780957116
516.2000000000068,26.144613059376375,0.8754117706903274,-0.29367125287521745
517.3000000000068,26.179480143077793,0.8731683585982954,-0.294626984840221
518.4000000000068,26.215534210187883,0.8716521076541806,-0.295000705041208
519.5000000000068,26.250643804688973,0.8706966381780372,-0.2949992672844206
520.6000000000068,26.2861327195906,0.8684602814585469,-0.2955860821125458
521.7000000000069,26.32153386015919,0.8677884572037527,-0.29631046621371926
522.8000000000068,26.356788085627567,0.8645942409373285,-0.2963099882167364
523.9000000000069,26.392353046122395,0.8635032485517722,-0.29630967655633844
525.0000000000068,26.428040902018054,0.863623025150866,-0.296507005072292
526.100000000007,26.463070304785315,0.862311884457466,-0.29763646170171976
527.2000000000069,26.49864200132539,0.8686045160730674,-0.29762996843603284
528.300000000007,26.53414771805441,0.8739133130981969,-0.29762999936437584
529.4000000000069,26.56944743336605,0.880532944853121,-0.2976299993113001
530.5000000000069,26.605066945110185,0.8842692406514144,-0.2976295735452221
531.600000000007,26.640443087350807,0.8882694170193339,-0.2979988576269119
532.700000000007,26.676155265639913,0.890881806333838,-0.2989555598548179
533.800000000007,26.711475932069444,0.8876844749955115,-0.29895002271952453
534.900000000007,26.746925847620265,0.8921902610770462,-0.29895000027591667
536.000000000007,26.782724253707915,0.8964941243878318,-0.2989500777957135
537.1000000000071,26.818283884808086,0.8944825630077188,-0.29894466109941975
538.2000000000071,26.853731898048416,0.8983932908048722,-0.30016700193870705
539.300000000007,26.889280365281923,0.8986971176803051,-0.30027005027615816
540.4000000000071,26.924701856924685,0.9016138095270984,-0.3002700018273061
541.500000000007,26.96050807000429,0.8988744220363942,-0.3002700000028864
542.6000000000072,26.996074304715492,0.8971458646829102,-0.30026999999985016
543.7000000000071,27.03173142459109,0.8970109097229768,-0.30026999999999804
544.8000000000072,27.066854533086758,0.8964997399826234,-0.3002700000002352
545.9000000000071,27.1029090348285,0.8945932462711463,-0.30027000002861914
547.0000000000072,27.13862511229211,0.8945453728043554,-0.30026999849889124
548.1000000000072,27.174153322057006,0.8928461730250841,-0.30026959739090353
549.2000000000072,27.20975397975328,0.8935024581227463,-0.3002733490513232
550.3000000000072,27.24511898852751,0.8926643733283323,-0.3016163811823964
551.4000000000073,27.28169918147312,0.8915304677708794,-0.30124786350424104
552.5000000000073,27.31693255451297,0.89019590352896,-0.3012479896299962
553.6000000000073,27.352709731980784,0.8921948473210378,-0.29992616677557127
554.7000000000073,27.3884986055091,0.8933001513571802,-0.29992914683394645
555.8000000000073,27.423709807787297,0.8930634090108666,-0.30032301665530525
556.9000000000074,27.460132841749772,0.8953159948827393,-0.3012532652830613
558.0000000000074,27.496110711954024,0.8938591848401184,-0.30125264800582396
559.1000000000074,27.53122591132319,0.8958785514268082,-0.3002684812182279
560.2000000000073,27.56726162391402,0.8921466727073389,-0.2999310962814352
561.3000000000073,27.603595939136788,0.89015893585289,-0.3002345862536404
562.4000000000074,27.63941849066817,0.8872390101282639,-0.30123944545010506
563.5000000000074,27.67500611372872,0.8868238954779493,-0.30157483678314856
564.6000000000074,27.711135799204023,0.8838461673356114,-0.3015796155519399
565.7000000000074,27.747009162757596,0.8794241054085419,-0.30159568861027886
566.8000000000075,27.78273946178622,0.8776655017644749,-0.30255296032946033
567.9000000000075,27.81827896496205,0.875003406705502,-0.30353967629187784
569.0000000000075,27.854529481598334,0.8725181389722946,-0.30355971239889534
570.1000000000075,27.890295375675166,0.8674954644445259,-0.30355999943010437
571.2000000000075,27.926289790741443,0.8630963998876353,-0.3035600263359175
572.3000000000076,27.962284462700058,0.8615285883928439,-0.30356570814035777
573.4000000000076,27.99788576243831,0.8551223335152105,-0.30256452404923584
574.5000000000076,28.034057224147315,0.8503169861844655,-0.3022396261671987
575.6000000000076,28.07003345827843,0.8459753599471461,-0.3022399978636394
576.7000000000077,28.106177846131615,0.8449845761800469,-0.3022400000204759
577.8000000000077,28.14192102874616,0.8403813939381035,-0.3022400000000247
578.9000000000076,28.17801941364059,0.8398228741105175,-0.30223999994036443
580.0000000000076,28.214188381516465,0.8390073776414502,-0.30223999848079774
581.1000000000076,28.250484173795233,0.839386545071037,-0.3022403003276257
582.2000000000077,28.286430720690003,0.8385735415317069,-0.3022272798730672
583.3000000000077,28.322376311565492,0.8413383991313624,-0.30190746191127404
584.4000000000077,28.358408896571937,0.8406207808538305,-0.30191006582580915
585.5000000000077,28.394586399371775,0.8405028930282887,-0.3019239398429838
586.6000000000078,28.4304145707376,0.8397745111074851,-0.3032314335700632
587.7000000000078,28.466315834848952,0.8422716216963343,-0.3032192933136977
588.8000000000078,28.502665830048915,0.8391542777293313,-0.3032199953414154
589.9000000000078,28.53809903095726,0.8416792830870675,-0.30322000003401106
591.0000000000078,28.575179857074154,0.8429531985434584,-0.3032199999883014
592.1000000000079,28.611016976873035,0.8478109510782039,-0.3032199995480176
593.2000000000079,28.647242158650112,0.8463243830540506,-0.30322012130814
594.3000000000079,28.683545685939364,0.8500962477447718,-0.30323794386713576
595.4000000000078,28.719433807126386,0.8535553563402707,-0.3045258107496598
596.5000000000078,28.755659193077275,0.8549431034976601,-0.303892333534558
597.6000000000079,28.791836944171692,0.8562557291949223,-0.3037603031032905
598.7000000000079,28.82790285748591,0.8606785749282647,-0.302544034838224
599.8000000000079,28.864501761954536,0.8659523056050382,-0.30510507356848304
600.9000000000079,28.90050512541434,0.8669536279184962,-0.30519991215583087
602.000000000008,28.936906652988547,0.8726516188129763,-0.30520022686141735
603.100000000008,28.973108728592585,0.8762900657355438,-0.30524570705169696
604.200000000008,29.009277454195434,0.8836925921341395,-0.30296864115696653
605.300000000008,29.045577639077255,0.8903300420977206,-0.30258267484621637
606.400000000008,29.081628957800906,0.895586897023297,-0.30392784518432236
607.5000000000081,29.117841479191572,0.9000004501479326,-0.3038895317767025
608.6000000000081,29.15407752784167,0.9047429898534198,-0.3038900033130769
609.7000000000081,29.19050714023092,0.9088052811625382,-0.3038901901163147
610.8000000000081,29.226572382762082,0.9131123785306345,-0.3037776833640149
611.9000000000082,29.262810728266302,0.9178929614563143,-0.3048874304534248
613.0000000000082,29.299206475407843,0.9210197914258885,-0.30487997898085606
614.1000000000081,29.335592207191162,0.9249464136755292,-0.3048799842793679
615.2000000000081,29.371682010357695,0.9303224555131661,-0.3048780353319449
616.3000000000081,29.40810980930015,0.9374883248156385,-0.30358421747156816
617.4000000000082,29.44405344235203,0.9424232910013671,-0.3035615147083601
618.5000000000082,29.48090151635711,0.9469849380721244,-0.3035596270188612
619.6000000000082,29.516504895484413,0.9536480255059503,-0.30378537105199843
620.7000000000082,29.55349324417561,0.9564237979673985,-0.304786956523698
621.8000000000083,29.590098412441545,0.9632019059641559,-0.30620535772271085
622.9000000000083,29.626449085413448,0.9719340589820115,-0.30619867684096347
624.0000000000083,29.662747296532004,0.9782565975895984,-0.3061992821726722
625.1000000000083,29.699129608710727,0.9847380775978979,-0.3061700239968501
626.2000000000083,29.735483849377804,0.9896207644457323,-0.30488794299227084
627.3000000000084,29.771402927188657,0.9933261720536664,-0.30488007188566346
628.4000000000084,29.808059046760672,0.9959612304028866,-0.30487999995485726
629.5000000000084,29.84412898883006,1.0019417036810927,-0.3048799999951308
630.6000000000083,29.88021137278765,1.0084812492926503,-0.3048799999999625
631.7000000000083,29.917300416966185,1.0131004295311945,-0.30488000000025295
632.8000000000084,29.95377240682401,1.0123236376541538,-0.3048800000394447
633.9000000000084,29.98996656574433,1.017290097163984,-0.3048800000574299
635.0000000000084,30.02659170362563,1.022674449092162,-0.3048794928644143
636.1000000000084,30.062896970585857,1.0256970812786337,-0.3054936882868313
637.2000000000085,30.09950525514729,1.025663893697855,-0.3060415584506533
638.3000000000085,30.135876819793893,1.0288575240554811,-0.3044811871009765
639.4000000000085,30.17219722527382,1.0317896968975497,-0.3042212293013846
640.5000000000085,30.208551993373646,1.032775846838947,-0.304220490593357
641.6000000000085,30.245206734430397,1.0330613337822965,-0.3053757802889079
642.7000000000086,30.28149049885745,1.032467048772265,-0.30553823773092903
643.8000000000086,30.31780178618683,1.031907075307743,-0.3055400479410775
644.9000000000086,30.354463940694185,1.0310561004764265,-0.30552806329429893
646.0000000000086,30.390749417017663,1.0328260295605338,-0.30416606387058964
647.1000000000087,30.427218086568423,1.030950383981697,-0.3042117086372951
648.2000000000087,30.46380033583251,1.0342912818622954,-0.3055038977989799
649.3000000000086,30.50036453000474,1.0333436631776136,-0.3055299726401399
650.4000000000086,30.536749110548115,1.0324869807086272,-0.3055300017095113
651.5000000000086,30.573153891848783,1.033463445393624,-0.3055300000134662
652.6000000000087,30.609445605454738,1.036827172543148,-0.3055300000008878
653.7000000000087,30.645991305209524,1.036037200640104,-0.3055300005594561
654.8000000000087,30.68275264795661,1.0354195383086862,-0.305530060630947
655.9000000000087,30.71862556235794,1.0360880510888206,-0.305526254377948
657.0000000000088,30.755592306671698,1.0401297419606124,-0.3068291084515926
658.1000000000088,30.792339093879363,1.0362786353089324,-0.30684987773436223
659.2000000000088,30.828585042657725,1.0375254221076418,-0.30685000180377653
660.3000000000088,30.865160720089577,1.039054770139346,-0.30684996351442173
661.4000000000088,30.901765652406574,1.0452949250923218,-0.30675077356233293
662.5000000000089,30.93830597968618,1.047091723773708,-0.30552307638143317
663.6000000000089,30.974997696475473,1.0412250088787558,-0.3055300123006006
664.7000000000089,31.01143176835181,1.0383647535199043,-0.30553052594348395
665.8000000000088,31.048092116159797,1.0390697825472461,-0.3055899612456505
666.9000000000088,31.08465520357492,1.0370700545922529,-0.3061883232141738
668.0000000000089,31.12081773490585,1.0319118998296113,-0.30618997285721283
669.1000000000089,31.157638708713737,1.0309628715755312,-0.30618997434145045
670.2000000000089,31.194247097063663,1.0320608673218703,-0.3061851399615665
671.3000000000089,31.23058810682619,1.0352423460942628,-0.30748762530618823
672.400000000009,31.266992597390907,1.0361817644196385,-0.3061585902902304
673.500000000009,31.303656053562694,1.039230678191017,-0.30620019101258
674.600000000009,31.340234891388814,1.0393370371081243,-0.3062000039621444
675.700000000009,31.376863243887637,1.0375947476207323,-0.3062000000212888
676.800000000009,31.41338978673188,1.0389976232278975,-0.30619999999991965
677.9000000000091,31.450033741573257,1.0376445619517287,-0.3061999999999965
679.0000000000091,31.486598592909587,1.0414664279625738,-0.3061999999999996
680.1000000000091,31.522331733839216,1.0397362931506993,-0.30620000000012837
681.2000000000091,31.5596355248511,1.0385242665276475,-0.3061999999971614
682.3000000000092,31.59637478175861,1.036560630455086,-0.3061999974130254
683.4000000000092,31.63287914436879,1.0376249033193783,-0.30619969631647814
684.5000000000091,31.669647768873187,1.038285073032179,-0.30650107497829726
685.6000000000091,31.706206310702953,1.0391168258073211,-0.3075244890520952
686.7000000000091,31.742516263972373,1.04074608777888,-0.3075550574241852
687.8000000000092,31.779373290743504,1.0402048933593215,-0.3062134087513577
688.9000000000092,31.815712658687197,1.0441688531046482,-0.3062000312831561
690.0000000000092,31.85241411829981,1.0424845072658864,-0.30619999949478327
691.1000000000092,31.889065240834594,1.0414116430887284,-0.30619999999332537
692.2000000000093,31.92567398865831,1.0402464778017126,-0.30619999998757885
693.3000000000093,31.96233542801221,1.0410841669718363,-0.30619999886766225
694.4000000000093,31.999180875395588,1.0441626465702356,-0.30620004989375404
695.5000000000093,32.03560895683217,1.0441016870824122,-0.3062242534366706
696.6000000000093,32.07223710700985,1.045453183642469,-0.30751799103713795
697.7000000000094,32.10900407319243,1.0422257928374528,-0.3075083683134725
698.8000000000094,32.1450346508838,1.0432766243876221,-0.3074468470254237
699.9000000000094,32.18235126847348,1.0480480856189276,-0.30619087590061955
701.0000000000093,32.218666152744504,1.0471419940278976,-0.3061900104134363
702.1000000000093,32.25571632107712,1.0477539289106592,-0.30619000008530195
703.2000000000094,32.29231972400571,1.0477460764665443,-0.30619000500441773
704.3000000000094,32.329052456267554,1.0486672251445885,-0.30618973960693374
705.4000000000094,32.365728803224634,1.0483914646118364,-0.3071337270505192
706.5000000000094,32.40249861814666,1.0463753157488558,-0.30750823169156627
707.6000000000095,32.43953203867075,1.0450484756263012,-0.30751000288626473
708.7000000000095,32.47598314104975,1.046931337649651,-0.3075100005189948
709.8000000000095,32.51260077073298,1.0452484620601392,-0.3075100351431628
710.9000000000095,32.54960943925873,1.0448318966369896,-0.3075091845125546
712.0000000000095,32.5864997246808,1.0439341504093897,-0.30866286404616305
713.1000000000096,32.62302739207798,1.0426854348773453,-0.30882897038442225
714.2000000000096,32.659702964150945,1.0442669121526418,-0.3088300009601599
715.3000000000096,32.696794595152205,1.044421807281388,-0.3088299958199632
716.4000000000096,32.733395727269944,1.0469553089023829,-0.30883037471696584
717.5000000000097,32.770398907911336,1.0461615766131505,-0.30788537425087403
718.6000000000097,32.80695372569309,1.0460748777359754,-0.3075118051624983
719.7000000000096,32.843801457241675,1.0468540178113606,-0.3075099982072924
720.8000000000096,32.880819968982514,1.042239837684722,-0.307509999848135
721.9000000000096,32.91735371283384,1.042443127129736,-0.30751000017222463
723.0000000000097,32.95423292916434,1.04097138155118,-0.3075100300916942
724.1000000000097,32.991148822817806,1.0403505077982687,-0.3075115273543547
725.2000000000097,33.02821305488629,1.040865802463744,-0.3081328510733803
726.3000000000097,33.06493420482361,1.0462428679293503,-0.3081671240778472
727.4000000000098,33.10171437132112,1.042415944564694,-0.3068831778147829
728.5000000000098,33.138557302522,1.0420692052455465,-0.3068600784235045
729.6000000000098,33.1752346876624,1.0415548928216698,-0.306832552017668
730.7000000000098,33.21226534862129,1.0418150778244732,-0.3075044361569379
731.8000000000098,33.24920748690806,1.043715774737095,-0.3075097911740179
732.9000000000099,33.286113540257666,1.0437705154314416,-0.307489717181225
734.0000000000099,33.32306557022107,1.0431760449573266,-0.30653725453445846
735.1000000000099,33.36003444067344,1.0433018143708503,-0.3071796913571334
736.2000000000098,33.39678669139911,1.044297436546775,-0.3071802442632454
737.3000000000098,33.43367446282263,1.0437689483005346,-0.30718007380404844
738.4000000000099,33.470698939426725,1.042949329061266,-0.30718236604883575
739.5000000000099,33.50782632959126,1.0427174644159645,-0.3078695530952107
740.6000000000099,33.54492067189116,1.0407345932420982,-0.3078432042528818
741.7000000000099,33.581708905011006,1.044490524133824,-0.30750812118094295
742.80000000001,33.61853281865939,1.037199196622514,-0.3075099876258194
743.90000000001,33.65552018268119,1.040596247520822,-0.30750999996137507
744.00000000001,33.658802858346014,1.0408338712187855,-0.3075099999216331