File: 01_Data/EIFS_Mesh/STA/N2/10K_min/EIFS_Mesh_STA_N2_10KData_230206_R1.csv
##Temp./Â°C,Time/min,DSC/(mW/mg),Mass loss/mg
50.0,10.850288863745037,0.017374484678492008,-0.008300146870517722
51.100000000000016,11.16660118611569,0.03681979590164519,-0.007890045244562494
52.20000000000003,11.402084298810504,0.05593903905636166,-0.006774637112783921
53.30000000000005,11.602613228798809,0.069761446742159,-0.008690977061141414
54.40000000000006,11.78228794107172,0.08303675295982527,-0.009658149162868224
55.50000000000008,11.944776052539678,0.08926728187301292,-0.006416136868387046
56.600000000000094,12.10600555556016,0.09453549720091314,-0.006021967869694667
57.70000000000011,12.255979924805747,0.10003744936841041,-0.006118790938416829
58.800000000000125,12.404747191930252,0.10525909364339237,-0.004828765236390087
59.90000000000014,12.54398582331687,0.1111094362477616,-0.007053954848574406
61.000000000000156,12.685549747597182,0.11631031596668873,-0.007315720896288624
62.10000000000017,12.823409642421,0.12155218458707218,-0.010863635708996622
63.20000000000019,12.957914674809366,0.1241031304675062,-0.006386296993767804
64.30000000000021,13.091068614738198,0.12557449135004606,-0.00735515276589549
65.40000000000022,13.221903166793316,0.12791670391625365,-0.008819466021526168
66.50000000000023,13.351308382341013,0.1356203837065939,-0.009098442429546605
67.60000000000025,13.478871342224576,0.1323755006668903,-0.008985271140913742
68.70000000000027,13.604126628356687,0.13651831783238388,-0.007360953672555848
69.80000000000028,13.730043984825512,0.13953560278218524,-0.008605630028576172
70.90000000000029,13.85351008195939,0.14271660331885183,-0.008493954997422115
72.00000000000031,13.978084751062292,0.14514255203550186,-0.00997950808858361
73.10000000000034,14.099748942739481,0.14670313244737954,-0.00656990102256394
74.20000000000034,14.221926194487917,0.14990353965965242,-0.003025155525671952
75.30000000000035,14.337670841131509,0.1501250860799206,-0.008658108023839706
76.40000000000038,14.460920269088092,0.15904307276563645,-0.011304562095735271
77.5000000000004,14.577986604611398,0.16036924042362455,-0.013863874929083586
78.6000000000004,14.696146104241262,0.16220491455989872,-0.011243597524127846
79.70000000000041,14.812726006652966,0.1658174024262633,-0.009877074259617036
80.80000000000044,14.928257922084844,0.16751166342183432,-0.011223039954475045
81.90000000000046,15.045166978992171,0.16841259069841596,-0.012627352289149574
83.00000000000047,15.158629620695805,0.1676762150483022,-0.012630597941011068
84.10000000000048,15.275796058016681,0.17188607425471814,-0.011164903191360764
85.2000000000005,15.387449300320043,0.17243917930440067,-0.011865176104749242
86.30000000000052,15.50059740141576,0.17499074612456056,-0.013864532114403971
87.40000000000053,15.614388739363994,0.17580906381091777,-0.015327979065521191
88.50000000000054,15.725917810446223,0.1785996907060068,-0.013683003531208549
89.60000000000056,15.837167500757886,0.17880435887323265,-0.013940099334478262
90.70000000000059,15.947358688106364,0.17976751106949163,-0.013940162040955162
91.8000000000006,16.057800117751626,0.1783126565405302,-0.013957614175566846
92.9000000000006,16.167317214564566,0.18042046646612864,-0.013968183805703305
94.00000000000063,16.278724495259674,0.17877861782306237,-0.015282215062414561
95.10000000000065,16.386936035197472,0.18053716311643275,-0.013818627244094994
96.20000000000066,16.49812215492299,0.17953869931546818,-0.015149407327367026
97.30000000000067,16.604226685732435,0.17993756834311836,-0.015924970277341632
98.40000000000069,16.711731096349528,0.18136426170745934,-0.017045190411412392
99.50000000000071,16.82210785028256,0.18084807102889355,-0.01898617589256979
100.60000000000072,16.92807637489392,0.18105998985897664,-0.016216284437836403
101.70000000000073,17.0376672677945,0.17995974990894048,-0.01328187505641365
102.80000000000075,17.144334080434827,0.18087409943694777,-0.014789702142643524
103.90000000000077,17.251337418387443,0.18111905654675198,-0.017450728528815684
105.00000000000078,17.358160359636372,0.18152073722751005,-0.017872026594674573
106.10000000000079,17.466586885602695,0.1770847090096268,-0.01645991050722362
107.20000000000081,17.57281280843336,0.17644625593262053,-0.01923290938912947
108.30000000000084,17.680109386886112,0.17740124648114708,-0.02145569879886633
109.40000000000084,17.786965046095922,0.17788459869311068,-0.025020212815124676
110.50000000000085,17.893284480709724,0.17848433465137603,-0.024751152428332812
111.60000000000088,17.999272537661746,0.17647039832072808,-0.022057915168931075
112.7000000000009,18.1057630246717,0.17359069563662977,-0.020748601633833186
113.8000000000009,18.211616262154593,0.1716498921757732,-0.02005601562760484
114.90000000000092,18.315564612650643,0.17032230881092614,-0.020813394457661172
116.00000000000094,18.4240657767861,0.17037501069558147,-0.019425069346427737
117.10000000000096,18.530270972616037,0.17077901199028012,-0.019430171642652816
118.20000000000097,18.636834525796566,0.16774879683526556,-0.01953405984068457
119.30000000000098,18.743080790810538,0.16737583078437612,-0.020774007840175468
120.400000000001,18.84736366724706,0.16849657996498923,-0.022069095471954903
121.50000000000102,18.954928558210675,0.16774886657022703,-0.022066108431501252
122.60000000000103,19.059746821451515,0.16666075692588012,-0.02478339528775031
123.70000000000104,19.16626718112639,0.16852055990204984,-0.024703211740086495
124.80000000000106,19.271937061396383,0.16697586933933417,-0.02231559780253667
125.90000000000109,19.37692658882749,0.16320595306988284,-0.02337877423376966
127.0000000000011,19.483359762638752,0.16458112567235683,-0.02491452511869241
128.1000000000011,19.58723459327231,0.16277039585836472,-0.021145354263307325
129.20000000000113,19.69227690891905,0.16126741639906006,-0.02119166808159445
130.30000000000115,19.797162134918445,0.159775822157617,-0.01887999954518893
131.40000000000117,19.90277163993788,0.16101201167491885,-0.02173822609842002
132.50000000000117,20.00714760307653,0.16111388579433328,-0.022731035382308473
133.6000000000012,20.11243433276459,0.1604870515814777,-0.025673160270427875
134.7000000000012,20.216208250518395,0.16184568964686208,-0.024207779022442644
135.8000000000012,20.320920358650923,0.16294432102402134,-0.02426089168475709
136.90000000000123,20.426631996481255,0.16283613471270741,-0.02424914612152973
138.00000000000125,20.530579385028872,0.16184578009542816,-0.02558222980512692
139.10000000000127,20.634342849291137,0.16111935329825522,-0.025954586458178497
140.2000000000013,20.73932331828687,0.15978822818873173,-0.02426063083125518
141.3000000000013,20.84326525812642,0.160685705780225,-0.025682953626239957
142.4000000000013,20.948136021308837,0.1604304636560423,-0.02691312417161118
143.50000000000134,21.051813223795115,0.1601488783768673,-0.02700982791118589
144.60000000000133,21.155802810849327,0.16097273056567496,-0.024592444191265272
145.70000000000135,21.25918697606748,0.15991759935610306,-0.02908082647188248
146.80000000000138,21.362685282281024,0.1613651139566119,-0.02811131666587041
147.9000000000014,21.46731471603319,0.1614970163949856,-0.028089275634034294
149.00000000000142,21.570331290380047,0.15996319089261213,-0.025199573156463373
150.10000000000142,21.675797830446324,0.159361210179072,-0.024826421874809323
151.20000000000144,21.776579284987555,0.16064214181618297,-0.024804264615575278
152.30000000000146,21.882366486287744,0.15788954328044635,-0.025944239819255976
153.40000000000146,21.9866000689912,0.16058172533984394,-0.027890267181727157
154.50000000000148,22.08982311222924,0.15924909319141534,-0.02920983934396082
155.6000000000015,22.194137604671663,0.16200925671825783,-0.029179548566984792
156.70000000000152,22.29753440287646,0.15984763774642796,-0.021904517423879888
157.80000000000155,22.40204887729647,0.15935617828766646,-0.022491409599956214
158.90000000000154,22.50567191331024,0.16029777203419238,-0.02415307283102397
160.00000000000156,22.609811207775437,0.16086050018277764,-0.028762530040946643
161.1000000000016,22.71352701802571,0.161850727636635,-0.028757097185969194
162.20000000000158,22.816404515744733,0.16488553197749878,-0.028655884569206425
163.3000000000016,22.920257254647403,0.16509586941587184,-0.029073233873480042
164.40000000000163,23.02357709844472,0.1660966641855035,-0.02901033594075475
165.50000000000165,23.126773469748667,0.16293217055301645,-0.027780107901647977
166.60000000000167,23.23082884982165,0.1657992005277098,-0.027780107950740707
167.70000000000167,23.334469970381004,0.16283325149587513,-0.028847893354707832
168.8000000000017,23.439232299054577,0.16230739815499828,-0.028100224475786195
169.9000000000017,23.541560486476584,0.1636545758682576,-0.028099924999859027
171.0000000000017,23.645498080819213,0.16543650724262882,-0.02875582233397722
172.10000000000173,23.748676213667945,0.16212721042461353,-0.030679214594476978
173.20000000000175,23.850830000000137,0.16332601309462846,-0.028100448108602016
174.30000000000177,23.95549329428497,0.1620689320550548,-0.029452839704937173
175.4000000000018,24.059837987197376,0.16343247419488938,-0.031414563419200014
176.5000000000018,24.16414064451968,0.16450500556857317,-0.031183551851742486
177.6000000000018,24.267043197921815,0.16564058017834893,-0.03322154355719498
178.70000000000184,24.370220004263267,0.16608803514882997,-0.03163558338234296
179.80000000000183,24.47380436401595,0.1667766680397894,-0.031204191573370288
180.90000000000185,24.57549668325217,0.16712158764781382,-0.03174232709115943
182.00000000000188,24.67966063052905,0.1670078631287214,-0.032289395151710476
183.1000000000019,24.782820122639492,0.1685541906643807,-0.031681071690485396
184.20000000000192,24.886416510855764,0.1673330576509141,-0.028769414747787714
185.30000000000192,24.990542748956216,0.16660489973569603,-0.031591833699009086
186.40000000000194,25.09147166804987,0.1674774537228121,-0.033770851005677116
187.50000000000196,25.196604758714663,0.1678584157930042,-0.03151370875779813
188.60000000000196,25.299939944361125,0.16812808326948625,-0.03293167526751395
189.70000000000198,25.404028551453624,0.16931402507189686,-0.03556872190755067
190.800000000002,25.507442028763034,0.16893633518443274,-0.03426705517593298
191.90000000000202,25.611010902320857,0.17005722204402696,-0.03162001330406783
193.00000000000205,25.71354302184219,0.16842769887257647,-0.03160442566472632
194.10000000000204,25.817154126808713,0.17044511099075,-0.03161756735896404
195.20000000000206,25.92039227842436,0.16970679459935112,-0.03524308538420806
196.3000000000021,26.024119120042506,0.17263453169697895,-0.032567388243651685
197.40000000000208,26.127513183748423,0.17066227575347115,-0.03127959123080126
198.5000000000021,26.23072889319251,0.17069686607428203,-0.03002320658528479
199.60000000000213,26.33467104598267,0.1699112402011832,-0.0298295479519326
200.70000000000215,26.438371262273243,0.17390647175358542,-0.0355969764877857
201.80000000000217,26.540372516097893,0.17240466950779754,-0.035468585556048815
202.90000000000217,26.644443818021028,0.17378089393520968,-0.034323338393395186
204.0000000000022,26.747454086492507,0.1752394304440099,-0.03520550202752615
205.1000000000022,26.851521954573297,0.1736775055353197,-0.0367834807460965
206.2000000000022,26.95519903686524,0.17603749361798993,-0.03637317298895448
207.30000000000223,27.05836237594568,0.17383098734746427,-0.03532500970396146
208.40000000000225,27.161294425541897,0.17297191335650364,-0.03524005114966
209.50000000000227,27.265632232559053,0.17450015496617244,-0.03524005099991978
210.6000000000023,27.3690089745061,0.174000733729073,-0.03524001997910231
211.7000000000023,27.471816646521248,0.17596931365922086,-0.032869072157768464
212.8000000000023,27.576395493619703,0.17510315248674613,-0.031581790913760344
213.90000000000234,27.67944740873152,0.17526817579595833,-0.03292494065437834
215.00000000000233,27.782903825605143,0.17747068712030978,-0.04039248453649913
216.10000000000235,27.884617768995415,0.1776176707135554,-0.03962378095682029
217.20000000000238,27.98958152752816,0.17602986470386106,-0.03743876207372576
218.3000000000024,28.09156236246839,0.17490503677036096,-0.034886502791095175
219.40000000000242,28.19632041495694,0.17798131181533328,-0.038253701455389866
220.50000000000242,28.300923859988025,0.17948979681656818,-0.04116994297890697
221.60000000000244,28.403742701165477,0.17878390373516895,-0.03985004424943783
222.70000000000246,28.50713563113955,0.18032479523590028,-0.04016486934893626
223.80000000000246,28.611013224357343,0.17884302104083005,-0.04017057519541556
224.90000000000248,28.714048192745793,0.17971381179122958,-0.04017974164059446
226.0000000000025,28.816959697024508,0.17818180641331727,-0.037290277502981084
227.10000000000252,28.92276948029957,0.17976835762349785,-0.03856795617441966
228.20000000000255,29.024494802746208,0.17984215389030989,-0.037329802873963924
229.30000000000254,29.129849064638197,0.18030737353817627,-0.040164511387297264
230.40000000000256,29.232491931655375,0.1798408299113955,-0.041500195886201574
231.5000000000026,29.336721641264415,0.18217948506473713,-0.04281053060161133
232.60000000000258,29.44104372407288,0.18305147067377792,-0.0400681907780287
233.7000000000026,29.543810747951298,0.18234225676705995,-0.04006523152234953
234.80000000000263,29.648072403960256,0.18316833357537632,-0.041389785169920756
235.90000000000265,29.752031660977536,0.18189657304936002,-0.03875197071116787
237.00000000000267,29.854532501132148,0.18235889932945987,-0.03874996067073866
238.10000000000267,29.959602286508364,0.18228525896210312,-0.040057648521383715
239.2000000000027,30.063296436287924,0.1834989335686742,-0.0400719661859581
240.3000000000027,30.167216928415957,0.18495200035744064,-0.04006977068352224
241.4000000000027,30.270738961458918,0.1821792667735741,-0.04137983892642172
242.50000000000273,30.37534817362701,0.1830443955918602,-0.04399990438790846
243.60000000000275,30.47928972999197,0.18502130284081186,-0.044035330688672936
244.70000000000277,30.58386443698679,0.18396312061783743,-0.044694759676630724
245.8000000000028,30.687801780842108,0.1839901107125887,-0.04495685380671599
246.9000000000028,30.791442673006625,0.1839005893254551,-0.043966949620199536
248.0000000000028,30.894125840117372,0.18379237942878385,-0.043335034057152555
249.10000000000284,30.999139975440606,0.18282757492449042,-0.042049596457442995
250.20000000000283,31.103899445392308,0.1852489301101885,-0.04270015553509854
251.30000000000285,31.207093982395076,0.18411316313985082,-0.044019653058646746
252.40000000000288,31.312118617640763,0.1832421653298445,-0.044019477940242524
253.5000000000029,31.417073154497643,0.18244278060783026,-0.0440214730063655
254.60000000000292,31.52105687022321,0.18536660437025265,-0.04678063550814349
255.70000000000292,31.625391432124953,0.1856293514453185,-0.0481554844925518
256.8000000000029,31.729783654539997,0.18443371529587693,-0.04676996261723909
257.90000000000293,31.834514873943515,0.1848547714888305,-0.04644765999001432
259.00000000000296,31.937622871106807,0.18713292803949533,-0.04615765834354857
260.100000000003,32.04253124471213,0.18900655579510478,-0.04775598671178605
261.200000000003,32.145232552410555,0.18662502764060968,-0.04775924704762291
262.300000000003,32.250136802988536,0.1880490479889937,-0.047813735565517046
263.40000000000305,32.354891463395674,0.18948102159446217,-0.049047098539381384
264.50000000000307,32.45825546212863,0.18833986527988877,-0.04884883761076608
265.6000000000031,32.56258756883377,0.18854314973284503,-0.04753025725933835
266.7000000000031,32.66727188651349,0.1884753935581916,-0.04883670801740392
267.8000000000031,32.77132343079295,0.19027038059971496,-0.05039228927277506
268.9000000000031,32.87548918917163,0.18710364781798577,-0.05179307711095493
270.0000000000031,32.97985387882406,0.18887429286989316,-0.04751701610235415
271.10000000000315,33.08327843881063,0.18962293099133076,-0.0450638372080876
272.2000000000032,33.18783373334685,0.18891622838498368,-0.04892029471155146
273.30000000000314,33.29210139323405,0.19193685953503803,-0.053799674270305076
274.40000000000316,33.39618866433208,0.19120193670008118,-0.0544876651092836
275.5000000000032,33.50120902296427,0.19042325109392644,-0.0500591207740273
276.6000000000032,33.60518846916977,0.1932023078707597,-0.05391036080438649
277.70000000000323,33.70940503843023,0.19240239413793386,-0.052252306762314404
278.80000000000325,33.81413463367214,0.19209343957201536,-0.050710715721183686
279.9000000000033,33.91890621611399,0.1913510052782323,-0.05335030929572149
281.0000000000033,34.02363906845206,0.19225857801656693,-0.05301766295228072
282.1000000000033,34.12800988596952,0.19278037122231662,-0.05494988944229462
283.20000000000334,34.23356702740868,0.19381647187981227,-0.05466045445126522
284.30000000000337,34.337752980379896,0.19445064589147576,-0.054662843778496395
285.40000000000333,34.44293513200738,0.19518425540139456,-0.05959932049596306
286.50000000000335,34.5470989345273,0.19718058335266836,-0.05747945135890209
287.6000000000034,34.65123757044307,0.19640766618006106,-0.05543963494574555
288.7000000000034,34.757223292979596,0.1962164985521428,-0.05687365337222383
289.8000000000034,34.86178771004048,0.1958557444530855,-0.05728384519310925
290.9000000000034,34.9652260558995,0.19526742117069779,-0.05278969155288582
292.0000000000034,35.07073448990364,0.1962974727611273,-0.05268983036147201
293.10000000000343,35.17497691128761,0.19682095983839365,-0.0540102946112877
294.20000000000346,35.277459217782045,0.19832516371932862,-0.054003462195139296
295.3000000000035,35.38471926110152,0.20059473077808038,-0.05946221327235479
296.4000000000035,35.48982209206178,0.19987772360642042,-0.060589922660441164
297.5000000000035,35.593730066318756,0.2025399848432584,-0.059136096040934394
298.60000000000355,35.699224215686186,0.20110550525542692,-0.057200044391785276
299.70000000000357,35.8035905570909,0.20336332283896202,-0.059827195359575924
300.8000000000036,35.90795764911931,0.20467914085382966,-0.061798967185616505
301.9000000000036,36.0129406936407,0.2051114155544791,-0.06046847387850551
303.0000000000036,36.1172482806689,0.20471439664319552,-0.06246348422652881
304.1000000000036,36.22290985295444,0.20671898048107534,-0.06407603887706248
305.2000000000036,36.326642666426366,0.2070344609872039,-0.061496493516869144
306.30000000000365,36.43173049377922,0.20811657448805698,-0.060267968160126806
307.4000000000037,36.53678517152474,0.21016618267182519,-0.06300130894470968
308.5000000000037,36.641841140608335,0.21219721740006686,-0.064556003181508
309.60000000000366,36.74609688300312,0.21465901196407056,-0.06442877159752403
310.7000000000037,36.851988065268756,0.21424001983627944,-0.06841563135034123
311.8000000000037,36.956582556427605,0.21777866618983227,-0.06806437072245641
312.90000000000373,37.06232875515971,0.21776606000316395,-0.06806089367546919
314.00000000000375,37.16786467501546,0.21814874689571745,-0.06937977568124776
315.1000000000038,37.27285496382683,0.2222619172827182,-0.06806025081226208
316.2000000000038,37.37777011610813,0.22585233428678708,-0.06804990242135345
317.3000000000038,37.48224734124648,0.22699109385040778,-0.0693479458922508
318.40000000000384,37.58882798962034,0.2300358961399615,-0.07202119630958137
319.5000000000038,37.693093257612745,0.2333726697408654,-0.07417735327866604
320.60000000000383,37.79849230557447,0.237852187019584,-0.07531855367006202
321.70000000000385,37.903144508544905,0.2432308495907506,-0.07786060282202945
322.8000000000039,38.008754754403014,0.2463510075333435,-0.07872005972959295
323.9000000000039,38.114081931888,0.25124679154677876,-0.07742243827807638
325.0000000000039,38.21917666331143,0.25331142490523545,-0.07822652753108983
326.10000000000394,38.324964317684056,0.25939272168384786,-0.08139746383133195
327.2000000000039,38.42954095774198,0.2640810240917643,-0.08364834540739219
328.30000000000393,38.53454390407702,0.26709664378807096,-0.08663370651495139
329.40000000000396,38.640385836704006,0.27344255310263044,-0.08793387986401324
330.500000000004,38.744082787463014,0.27556460011592976,-0.08924813211712124
331.600000000004,38.850141599285315,0.2786966949318376,-0.09057018188244292
332.700000000004,38.95500624620708,0.2822849748220573,-0.09311428381711462
333.80000000000405,39.0614264546368,0.2837036023363725,-0.09584013222042387
334.90000000000407,39.166963340619176,0.2868626485231004,-0.09841275972811037
336.0000000000041,39.271953748772006,0.2880336095963457,-0.10199318678092828
337.10000000000406,39.378058327749464,0.2913508770346168,-0.10340994145056559
338.2000000000041,39.48242102594295,0.28963076893879763,-0.10604877828920678
339.3000000000041,39.58970104886494,0.28797078808028187,-0.11055203439733541
340.4000000000041,39.69412807075623,0.2877913297914195,-0.11026627038453274
341.50000000000415,39.79968530668637,0.2858740862927853,-0.11228265644707625
342.6000000000042,39.90573797737006,0.28449620742261994,-0.11913357902135369
343.7000000000042,40.01186388885169,0.28544110216371044,-0.11903754294759361
344.80000000000416,40.1164620256062,0.28115802706356813,-0.1203199741765375
345.9000000000042,40.220728203931266,0.2768846316182574,-0.12228976100019473
347.0000000000042,40.3276943263518,0.2745254500170493,-0.1295071893483244
348.10000000000423,40.4337909054788,0.27098572946114996,-0.13105970147588408
349.20000000000425,40.539692528079264,0.2655847745987422,-0.13361324568164878
350.3000000000043,40.64489408560103,0.26327631878095337,-0.13890698810841373
351.4000000000043,40.75212986436334,0.25730829743666395,-0.1415478549863538
352.5000000000043,40.857211926509414,0.25385983408856216,-0.1421369263078054
353.60000000000434,40.96292910487189,0.2497970251340546,-0.14532360376139675
354.7000000000043,41.06948033285572,0.24682890175274114,-0.1501686569511005
355.80000000000433,41.174137905914364,0.2435731131922603,-0.15259991451438637
356.90000000000435,41.28120489752524,0.23963840938113803,-0.15527138161000353
358.0000000000044,41.386838070634134,0.2391757938247858,-0.1552340195997708
359.1000000000044,41.49343498189924,0.23815055160648452,-0.15385827186232248
360.2000000000044,41.59886094097527,0.23728342389810284,-0.16581835651556354
361.30000000000445,41.703384066533154,0.23730454697704836,-0.16863394613922766
362.4000000000044,41.807762550606135,0.23600856419440885,-0.1692895575061799
363.50000000000443,41.91742107425071,0.23770991967134897,-0.1703550942931633
364.60000000000446,42.023448995878816,0.23336991990506367,-0.17323471273033686
365.7000000000045,42.12947067318375,0.23061232999423611,-0.17322996202125074
366.8000000000045,42.23577095211924,0.22946333376642483,-0.17315353290322566
367.9000000000045,42.342623149855235,0.22760282677221333,-0.1732239028221101
369.00000000000455,42.448319196062954,0.22713987323321044,-0.17693058856593158
370.10000000000457,42.55393912953767,0.22619637510974983,-0.1803749485106385
371.2000000000046,42.66062570332003,0.2254866395663118,-0.1829782260738959
372.30000000000456,42.76654772640058,0.22502034188139133,-0.18421609681827977
373.4000000000046,42.87326430070138,0.224452688301716,-0.18421088208389902
374.5000000000046,42.97897994337224,0.22326081961538544,-0.18584638146378873
375.6000000000046,43.08622180434524,0.22360996429849028,-0.18522017222298626
376.70000000000465,43.19204612633557,0.22769775173853157,-0.18796100925570602
377.8000000000047,43.298097098727105,0.2329153135878982,-0.18893112791315847
378.9000000000047,43.40543860204506,0.23410401560256452,-0.1899425881905028
380.00000000000466,43.510281348861945,0.23422179586914416,-0.1915704332472168
381.1000000000047,43.616671873938806,0.23648253015577395,-0.18927990645263693
382.2000000000047,43.72306123758712,0.23984555241957567,-0.1879201955367713
383.30000000000473,43.82992401582877,0.23873287133758248,-0.18892973886650433
384.40000000000475,43.93631031495484,0.2410457191067458,-0.19190136649353207
385.5000000000048,44.042317643044946,0.2401982548307113,-0.19613500446319465
386.6000000000048,44.14979896939346,0.23975392289626374,-0.198731777449904
387.7000000000048,44.25643722927716,0.23872710850890663,-0.19744231696033232
388.80000000000484,44.36138337997116,0.24114292450581457,-0.1979766465937236
389.9000000000048,44.469358976081494,0.242125339419835,-0.20134216301724406
391.00000000000483,44.575356477261884,0.2428261532238366,-0.19980365622155505
392.10000000000485,44.68231510306176,0.24278966376726324,-0.1973899028924242
393.2000000000049,44.78848887622712,0.2454690163973484,-0.1986119281822356
394.3000000000049,44.89579848712405,0.24483921201665007,-0.20151400788007567
395.4000000000049,45.00352731857913,0.24708151539926346,-0.20562055129902568
396.50000000000495,45.10933296647275,0.24675569031814687,-0.20420073078526935
397.6000000000049,45.21655190061019,0.24808998632942247,-0.20419971814560434
398.70000000000493,45.32277898085396,0.25134225622820233,-0.20638066334289018
399.80000000000496,45.43034213810644,0.25254715109673287,-0.20792092907057258
400.900000000005,45.53363743568718,0.25251087023959473,-0.21174660410445423
402.000000000005,45.64349945388431,0.2536799364097714,-0.2117700283722317
403.100000000005,45.75111449527942,0.2562573864668321,-0.21561634938702445
404.20000000000505,45.8575532980478,0.25810541528084807,-0.21599665415352476
405.30000000000507,45.964759944064646,0.26193077469756326,-0.21726579212842312
406.4000000000051,46.071325621239694,0.2640488115622721,-0.2157918209698515
407.50000000000506,46.17871075447608,0.2637516949370894,-0.213406711011924
408.6000000000051,46.285850842072634,0.26736059481551855,-0.2155834034194286
409.7000000000051,46.39321334519763,0.26947891818613295,-0.22202233535370608
410.8000000000051,46.50063992937747,0.2715580790948251,-0.22316321960749574
411.90000000000515,46.606456204147754,0.2724454230904899,-0.2227347197170637
413.0000000000052,46.71432969567225,0.2760545842450506,-0.22499333175796465
414.1000000000052,46.821368072199604,0.2757234085774304,-0.2278534164467887
415.20000000000516,46.92907504013292,0.275960062733904,-0.23021072661118946
416.3000000000052,47.03676419697301,0.27364556946474244,-0.23152985669138593
417.4000000000052,47.14374794461876,0.2727200713933341,-0.2325243138518962
418.50000000000523,47.25091601486837,0.2693346105208598,-0.23351783803544013
419.60000000000525,47.35755564486789,0.2668680513584949,-0.23966381142784332
420.7000000000053,47.46548159745094,0.2624520305839265,-0.2383870937639312
421.8000000000053,47.57420980787704,0.259457791980686,-0.24042602102238986
422.9000000000053,47.680529487176116,0.2527564559213391,-0.2424951568117346
424.00000000000534,47.78790908326249,0.25077200339051875,-0.24117143134531416
425.1000000000053,47.89558842770965,0.2454292796299437,-0.23854481754135026
426.20000000000533,48.00336191613327,0.24318279427193856,-0.23848839727495585
427.30000000000535,48.111120617670466,0.24242696437723205,-0.24120116573503658
428.4000000000054,48.21866745176949,0.2365181417655427,-0.243660127979191
429.5000000000054,48.32623482592815,0.23781999509593857,-0.24645820397131857
430.6000000000054,48.43436933227558,0.23505346692030116,-0.24644335691085217
431.70000000000545,48.542117789784164,0.2325390869924911,-0.2478989661431661
432.8000000000054,48.651039633804864,0.23001469375680367,-0.24843981231366508
433.90000000000543,48.75829669770066,0.23059700488566742,-0.2524586515465117
435.00000000000546,48.86615851509306,0.22834155030785455,-0.2539556180341216
436.1000000000055,48.97234895708409,0.22882206675072306,-0.2527277717213021
437.2000000000055,49.081222604644616,0.23046462748822305,-0.25140684377467926
438.3000000000055,49.18903140409137,0.23311459419525088,-0.2514209892430266
439.40000000000555,49.296783447437285,0.23142582900696035,-0.25422584202658793
440.50000000000557,49.4043632882886,0.2326606944247236,-0.25699993814938127
441.6000000000056,49.51213515565294,0.23115841315936836,-0.256862899951944
442.70000000000556,49.61863312499256,0.23427569569669987,-0.25541855804173075
443.8000000000056,49.72590846656574,0.23511184621444564,-0.26104108818910454
444.9000000000056,49.833136778525976,0.23743251672216323,-0.26224938352010874
446.0000000000056,49.9418533062179,0.2407873347991349,-0.26544999580030115
447.10000000000565,50.04783830362484,0.2388436159671858,-0.26282183056804653
448.2000000000057,50.15740868950774,0.24116637382088446,-0.2648874247211528
449.3000000000057,50.264869226456085,0.24191319574382003,-0.2654383993778686
450.40000000000566,50.37236439322069,0.24396625035771202,-0.2684249163051269
451.5000000000057,50.47977204212539,0.24407962105247338,-0.2715680756127017
452.6000000000057,50.58786409095398,0.24783917056685034,-0.2739084841682824
453.70000000000573,50.69528416566376,0.24897098442343255,-0.27530877997945913
454.80000000000575,50.80251174885045,0.24787165003706793,-0.2762397475802447
455.9000000000058,50.91063487001644,0.24943060764261304,-0.27938984773144515
457.0000000000058,51.01837534729064,0.25076988507387066,-0.2793899612346369
458.1000000000058,51.12651928199464,0.2509218832793421,-0.28070173884922855
459.20000000000584,51.233465013220204,0.25258072721172903,-0.2828111829241915
460.3000000000058,51.34178390227062,0.2510687665311035,-0.2841010974675231
461.40000000000583,51.449743391981976,0.25151524095417815,-0.28128276692577625
462.50000000000585,51.556763860465985,0.2519527782040683,-0.28642331712113567
463.6000000000059,51.665501134438,0.2514702094177392,-0.2918117745734583
464.7000000000059,51.772743751342304,0.25148424741625575,-0.29377617572759807
465.8000000000059,51.88064114247382,0.25164083360755146,-0.2976123074656529
466.90000000000595,51.9891666387742,0.25073929923044924,-0.2940124208404167
468.0000000000059,52.09749048796203,0.24675812894447638,-0.29659003328411826
469.10000000000593,52.20534991182007,0.24961472906015167,-0.2994899001963751
470.20000000000596,52.312857973923876,0.2500880256178872,-0.29670422592423806
471.300000000006,52.420926332277695,0.24728010620783575,-0.2983550226877183
472.400000000006,52.52874586685718,0.24899968630120703,-0.3046984628568734
473.500000000006,52.636531976003454,0.24720473614565655,-0.3087730167545599
474.60000000000605,52.74467108421541,0.24974257574153189,-0.30628668218152644
475.70000000000607,52.85221049473959,0.2459476224550894,-0.3049896244847785
476.8000000000061,52.961199667656224,0.2442715224336406,-0.3062903656258458
477.90000000000606,53.069205836673554,0.2445661417138455,-0.308932017944771
479.0000000000061,53.177652582056204,0.24255838056591544,-0.31058890923754134
480.1000000000061,53.28514323086364,0.2406602052420343,-0.31156017899872523
481.2000000000061,53.393756507012874,0.2401085317723548,-0.31420717533053955
482.30000000000615,53.50150163161628,0.23708283707380834,-0.31684489305679975
483.4000000000062,53.60934689715801,0.23772309732039806,-0.3141359089445803
484.5000000000062,53.71711689615399,0.2514480707952068,-0.3100219174642236
485.60000000000616,53.825550045686306,0.2552529522128152,-0.3115235466012214
486.7000000000062,53.93403088281411,0.25949081365005955,-0.3157354685545859
487.8000000000062,54.0411376396733,0.26083649939815295,-0.31837244990770186
488.90000000000623,54.150730569097114,0.25302510429644404,-0.31562995508193215
490.00000000000625,54.25901586840257,0.24857955591129435,-0.314327621774269
491.1000000000063,54.36735930885753,0.24304486186959276,-0.31955796657447566
492.2000000000063,54.47528947806863,0.2378099570101371,-0.3208755900288476
493.3000000000063,54.584544533742225,0.23197808390696076,-0.3185986758827699
494.40000000000634,54.69221894842262,0.2235632973717524,-0.3159775933505582
495.5000000000063,54.799063947163276,0.217645718792606,-0.3118904861493337
496.60000000000633,54.90899101001472,0.2105294762533013,-0.3185151154043586
497.70000000000636,55.018070443921204,0.2070702282759771,-0.31770552514088246
498.8000000000064,55.12687935716331,0.19867587802175923,-0.3231511132908098
499.9000000000064,55.23612983037723,0.19188529275279684,-0.32198786786248634
501.0000000000064,55.342683964500054,0.18583769457440685,-0.3218791052147423
502.10000000000645,55.453598145264436,0.1812568971591622,-0.3232160365464547
503.2000000000064,55.56124805854517,0.17857791420938177,-0.32487540033324036
504.30000000000643,55.670178341601336,0.1704077982844494,-0.32323321550697814
505.40000000000646,55.77772612095921,0.16747604766560603,-0.3246325480551753
506.5000000000065,55.88707588603632,0.1608362203072013,-0.32497050629394275
507.6000000000065,55.994188204674124,0.1573891399391824,-0.32232246722618507
508.7000000000065,56.103536549985485,0.14901100557475982,-0.3228818484798541
509.80000000000655,56.211442510708245,0.14626383243934188,-0.32153507292991534
510.90000000000657,56.321227445719856,0.14102478428306592,-0.3215631443110203
512.0000000000066,56.43052073437322,0.13710983369531166,-0.32419003032981486
513.1000000000065,56.540080694070596,0.134916323780147,-0.32682152646186147
514.2000000000066,56.64883338134268,0.13156630622034496,-0.3268299890057009
515.3000000000065,56.75577619744686,0.12986772677658837,-0.32682998952775755
516.4000000000067,56.8652407399719,0.12875292627469995,-0.32536376645117704
517.5000000000066,56.9744178159012,0.12339611135142886,-0.32198952998160957
518.6000000000067,57.08386461217343,0.12282273557642456,-0.32379373795764943
519.7000000000066,57.192533211709275,0.12200504106910538,-0.3265994282146245
520.8000000000067,57.30171796797634,0.11947041697949001,-0.3253007599004083
521.9000000000067,57.41117891703916,0.11531312784004431,-0.3265998387861573
523.0000000000067,57.519853041717674,0.1140922179808905,-0.32659990690065
524.1000000000067,57.62745204420954,0.11215051818753734,-0.3252507902232171
525.2000000000068,57.7374501323282,0.10975046913104598,-0.32396990698177897
526.3000000000068,57.8442886869028,0.10881047426037285,-0.3239061709724598
527.4000000000068,57.95625634090327,0.10672492764169374,-0.3263802270446594
528.5000000000068,58.06231834703448,0.10311256294424721,-0.3250749994335327
529.6000000000068,58.17346066726479,0.10220920815934445,-0.32505990588029876
530.7000000000069,58.282200779443954,0.09982008409664127,-0.32635017596784444
531.8000000000068,58.39218040774105,0.1043644782511609,-0.32643330739805565
532.9000000000069,58.500828049098175,0.10359965720295114,-0.329349951537647
534.0000000000068,58.60974114174042,0.10211452259569141,-0.3264644524552316
535.100000000007,58.71800912242269,0.09976390889353094,-0.3253899185485509
536.2000000000069,58.82786518321714,0.10049222418252447,-0.32407704614428745
537.300000000007,58.93731422280514,0.10324538695938802,-0.3240802075561624
538.4000000000069,59.04569186259964,0.10469309216464137,-0.3261090808836129
539.5000000000069,59.15602455260398,0.10653345659462546,-0.3261682539138806
540.600000000007,59.26217535892496,0.10750926707194994,-0.32891030837576496
541.700000000007,59.373968596080054,0.10896372021664921,-0.32890994734397827
542.800000000007,59.48289619935942,0.10940943321210597,-0.3303367570002922
543.900000000007,59.59250928088502,0.10956022457117208,-0.3315842016717716
545.000000000007,59.70223704047623,0.110567353376083,-0.33153990208055495
546.1000000000071,59.81170092341343,0.11111259704088536,-0.3330773171586521
547.2000000000071,59.92000178176035,0.11190199395855718,-0.3349822700355545
548.300000000007,60.02973840502696,0.1122948759222982,-0.3340473481677053
549.4000000000071,60.13985840813642,0.11533569339416153,-0.3300722379761396
550.500000000007,60.248486737618265,0.11448061109065857,-0.32770985722750856
551.6000000000072,60.35773713589078,0.11294661295689618,-0.3273796954128212
552.7000000000071,60.46600065994414,0.11518475822398014,-0.3273798596533477
553.8000000000072,60.57419716699797,0.11678618750395105,-0.32748250834051396
554.9000000000071,60.68406648470698,0.11970974351930433,-0.3290402419207519
556.0000000000072,60.79346441773816,0.11620934842296773,-0.33165994835080514
557.1000000000072,60.902153457001305,0.12015237935269946,-0.33165995764907574
558.2000000000072,61.0119410633325,0.1198317764037277,-0.3322672409778482
559.3000000000072,61.12104646273685,0.12128436690045372,-0.33330984818934706
560.4000000000073,61.2291454937968,0.12192548905239488,-0.3355878781751307
561.5000000000073,61.33950758230371,0.12049747546386144,-0.33696334671783257
562.6000000000073,61.44708499694326,0.12193828803262761,-0.3356960247806984
563.7000000000073,61.55812482506021,0.12059156583887863,-0.33309142690070503
564.8000000000073,61.6674559464974,0.12504024353715767,-0.3320998273059961
565.9000000000074,61.77460054980485,0.12310197703677671,-0.3334146087676517
567.0000000000074,61.886868352328484,0.12476010137830658,-0.3307803845084307
568.1000000000074,61.99584366904203,0.12607744486026545,-0.3307801809998958
569.2000000000073,62.10552500212476,0.12687198543028094,-0.3307801811249056
570.3000000000073,62.215115948796885,0.1262036840767713,-0.3293787243848958
571.4000000000074,62.324348126563244,0.1262114514148977,-0.3309637625633157
572.5000000000074,62.43388884530332,0.12564277572782168,-0.3347120505576604
573.6000000000074,62.543909450781186,0.126863066852209,-0.3348402661329133
574.7000000000074,62.652988273077334,0.12549185227996792,-0.33169728716355396
575.8000000000075,62.763421748783266,0.1287816310623215,-0.33176001238533015
576.9000000000075,62.872133082862206,0.13164621309399147,-0.33175999000015377
578.0000000000075,62.981522202771274,0.12777741072933052,-0.331759686309943
579.1000000000075,63.09140081840286,0.1335394012731073,-0.3345427563001646
580.2000000000075,63.20210866696548,0.12881315102171087,-0.33651222827945126
581.3000000000076,63.311437616018196,0.12949390091295684,-0.33384862041785945
582.4000000000076,63.421259666013114,0.12900715899517232,-0.3312346228035419
583.5000000000076,63.53092512004523,0.1323144178360938,-0.3311399151063523
584.6000000000076,63.639363403897825,0.1321523906084482,-0.33253079035973965
585.7000000000077,63.7499315561944,0.136141115452054,-0.33252659792714345
586.8000000000077,63.85915603163631,0.13483030934053797,-0.33384923019315194
587.9000000000076,63.969380040564445,0.13614588935003183,-0.331220282547251
589.0000000000076,64.079440720154,0.13767778699349206,-0.33055966680906756
590.1000000000076,64.18798708201044,0.13975163592368398,-0.3372210864756551
591.2000000000077,64.29866832030828,0.13829622620813933,-0.34188760511855776
592.3000000000077,64.4093867040047,0.1384539157403012,-0.3359337333198811
593.4000000000077,64.51946540311305,0.1391975445696102,-0.3315889741759568
594.5000000000077,64.6289874795171,0.13905870143758858,-0.33232191160915736
595.6000000000078,64.73951435347577,0.13913903590674875,-0.3323083052063618
596.7000000000078,64.84790831929492,0.14065095898700605,-0.33372175686944505
597.8000000000078,64.95884703180796,0.14682666881345757,-0.33383586691293665
598.9000000000078,65.06938423588176,0.14545806536828126,-0.33628475866288143
600.0000000000078,65.17760519159674,0.14782889585725906,-0.3326762954259239
601.1000000000079,65.28909731641544,0.1491270334014138,-0.3303298690926786
602.2000000000079,65.3985906992443,0.14822668442165005,-0.3316409439296528
603.3000000000079,65.50944177006578,0.1499552969671467,-0.3349563284506809
604.4000000000078,65.61950914950829,0.15242699669672977,-0.33572034030999554
605.5000000000078,65.72976129477482,0.15474211163354967,-0.33858783204189535
606.6000000000079,65.8396227530958,0.15470793857677945,-0.33999027594940134
607.7000000000079,65.9501945075094,0.15476004019692885,-0.3351228308702501
608.8000000000079,66.06062739102802,0.1560842705871297,-0.3300209955235749
609.9000000000079,66.17093072880928,0.15979812648481206,-0.3260930428918303
611.000000000008,66.27987387037071,0.16104403616713775,-0.3260913472315474
612.100000000008,66.39134219095627,0.16233764402520173,-0.3313615505942593
613.200000000008,66.50175378151513,0.16578571795257702,-0.3367305863995744
614.300000000008,66.61225638924027,0.16800696546979263,-0.33451051304254875
615.400000000008,66.72298340662769,0.17424376810632403,-0.33717145875144805
616.5000000000081,66.83428392159233,0.1751319356375914,-0.3371398958397185
617.6000000000081,66.94357037224067,0.17844008890776378,-0.3377046698135153
618.7000000000081,67.0534460070311,0.18073425648632666,-0.3355076868770599
619.8000000000081,67.1640489946644,0.18381037745781095,-0.33654798430563915
620.9000000000082,67.27490738461337,0.18187902819988278,-0.3372597501013397
622.0000000000082,67.3849041649049,0.1861091845623545,-0.33594584350502465
623.1000000000081,67.4948823813175,0.18417230068284046,-0.33375388162209907
624.2000000000081,67.6044637878539,0.1833232516420904,-0.33724333814872276
625.3000000000081,67.7154748861332,0.18244383723211388,-0.33362905880732185
626.4000000000082,67.82530046470063,0.18682271047619997,-0.3349551487283611
627.5000000000082,67.93611454281906,0.1872773942829783,-0.3359396330153612
628.6000000000082,68.04614131451171,0.18853950434679853,-0.33754339801728017
629.7000000000082,68.15693458278989,0.18847283547040944,-0.33899525093400085
630.8000000000083,68.26741449267378,0.18827072923135912,-0.3355911007178465
631.9000000000083,68.37799002207386,0.1880751492852965,-0.3317672731216983
633.0000000000083,68.48793653175136,0.1883147817593816,-0.33175999102605136
634.1000000000083,68.59960866599543,0.1898339072105333,-0.33307992012972987
635.2000000000083,68.70943997095306,0.19073225325542298,-0.3349377128163633
636.3000000000084,68.82001154604062,0.1929842247974263,-0.3383528795173625
637.4000000000084,68.92821191549758,0.19064726709173627,-0.337059057694693
638.5000000000084,69.03959551233399,0.19177899943734789,-0.3322911500708372
639.6000000000083,69.15000018038317,0.1888279529999023,-0.3299000320896113
640.7000000000083,69.26103921551729,0.19309749184356859,-0.3325530042298528
641.8000000000084,69.37053267636746,0.19109195416966293,-0.33253051796666666
642.9000000000084,69.48029165293848,0.19320239829884836,-0.33518825068842073
644.0000000000084,69.59178180809262,0.19418145038990647,-0.3365077856705261
645.1000000000084,69.70103604257493,0.19331663426993667,-0.3325267626587718
646.2000000000085,69.81013103731546,0.1954050013704762,-0.3351813374956061
647.3000000000085,69.92194441519503,0.198089883806535,-0.33598872872447894
648.4000000000085,70.03197578153137,0.19866036083735295,-0.33439992832091914
649.5000000000085,70.14238199948204,0.19506034862982605,-0.3361725378101008
650.6000000000085,70.25237737094893,0.19592702700431647,-0.3373663436041294
651.7000000000086,70.36260644257887,0.19517061384773093,-0.3319343031610167
652.8000000000086,70.4729414831792,0.19572402234109773,-0.3316876273073057
653.9000000000086,70.58346773500809,0.1943815011381089,-0.3332234473004192
655.0000000000086,70.69351407199076,0.1972205517280653,-0.33480222537907256
656.1000000000087,70.8039123419049,0.19749418661744791,-0.3361497736236321
657.2000000000087,70.91327688918368,0.2000753374276411,-0.33909710411862237
658.3000000000086,71.02411766468737,0.19810708081851527,-0.3436200938785148
659.4000000000086,71.13391054755733,0.1989601262969802,-0.34033791518880596
660.5000000000086,71.2444063244996,0.19755557116597874,-0.33328659609523426
661.6000000000087,71.35504271102916,0.1973975931577685,-0.33332919977326814
662.7000000000087,71.46567984801683,0.19606090299655882,-0.33462046001106094
663.8000000000087,71.57620882485853,0.19623646353803437,-0.3330671279095023
664.9000000000087,71.68597713600498,0.19760773010032273,-0.334895151698384
666.0000000000088,71.79599037103269,0.19528358962424583,-0.3334133024508654
667.1000000000088,71.90648925088392,0.19643096474558625,-0.332534654997505
668.2000000000088,72.01661057396745,0.19741041428232792,-0.33390076594497486
669.3000000000088,72.12725161735062,0.19709213035404577,-0.33647941765710554
670.4000000000088,72.23763710569555,0.2001653601511604,-0.33550013988567784
671.5000000000089,72.3473386903781,0.19967244901436917,-0.3367682289985643
672.6000000000089,72.45781049826381,0.19957756903532586,-0.3381400147701008
673.7000000000089,72.5660209256882,0.2005708064573246,-0.3383836581409607
674.8000000000088,72.67902223930051,0.1953878506099531,-0.33549968911654515
675.9000000000088,72.78993298046376,0.19897895221315223,-0.3383907705620075
677.0000000000089,72.89960091392328,0.19829858101658734,-0.3384603121054668
678.1000000000089,73.0093813984975,0.1990768212619897,-0.33582553664302006
679.2000000000089,73.12071434839852,0.19797219332055999,-0.3358307627482029
680.3000000000089,73.23003005829747,0.1985521780692169,-0.33582903930066976
681.400000000009,73.34216048661258,0.19842508476504095,-0.3370427443820354
682.500000000009,73.45268311231025,0.19925318207431256,-0.33550098063133404
683.600000000009,73.56337030485476,0.20003817301305374,-0.33370485660864
684.700000000009,73.67324219088636,0.20024603961326715,-0.33395935375230357
685.800000000009,73.78480244138892,0.20305825973492198,-0.3384920691372608
686.9000000000091,73.89471383345077,0.20429046024812852,-0.346932975063452
688.0000000000091,74.0055384192159,0.2045791967651519,-0.3423163595582426
689.1000000000091,74.11590949825697,0.2033708204576014,-0.3341097592533071
690.2000000000091,74.22652024310295,0.2016381295747654,-0.32997133643274656
691.3000000000092,74.3379709758926,0.2025685349457233,-0.3317637979661936
692.4000000000092,74.44784119259232,0.19778530714947362,-0.3362867850761564
693.5000000000091,74.55878576603378,0.20235941692305123,-0.33462003399036977
694.6000000000091,74.66937353683628,0.1990696160126564,-0.3347363482825667
695.7000000000091,74.77979934409362,0.20171805165153472,-0.3361957585696511
696.8000000000092,74.88980275412979,0.19984317874807656,-0.33530529543119725
697.9000000000092,74.9999099148372,0.2062360838298261,-0.3367992519500618
699.0000000000092,75.1114199425002,0.20614360134117404,-0.3362052864922993
700.1000000000092,75.22153647034413,0.20487518872283117,-0.33614085574224184
701.2000000000093,75.3319593087934,0.2053600015667545,-0.3361501289906177
702.3000000000093,75.44385675361734,0.2016235220525691,-0.3374516979662574
703.4000000000093,75.55360583198897,0.2005627948794729,-0.33365595355230315
704.5000000000093,75.66521079523288,0.20487613339986355,-0.3333032046438431
705.6000000000093,75.77628875945678,0.20359552071717307,-0.33924286667590575
706.7000000000094,75.88737487106107,0.20429210364741623,-0.3399791181311369
707.8000000000094,75.9981176833992,0.19983878420294954,-0.34132357699598836
708.9000000000094,76.10973369752463,0.2001227535963593,-0.34253780065944595
710.0000000000093,76.22053242577798,0.20223353851392067,-0.3365007741611872
711.1000000000093,76.33143911536676,0.2029374841842263,-0.33682049338395004
712.2000000000094,76.4421726437155,0.20183913380499055,-0.33899635241616943
713.3000000000094,76.55296323251861,0.20196676970739996,-0.3380179755292323
714.4000000000094,76.66365222369345,0.20115051374631016,-0.33531307994188264
715.5000000000094,76.77235371326228,0.20195670954995656,-0.3342055352241373
716.6000000000095,76.88464270002676,0.20311500580414538,-0.3383391746614026
717.7000000000095,76.99522435508581,0.20184584402007105,-0.3357205409843331
718.8000000000095,77.10578604627516,0.20541141335514873,-0.33433690272516037
719.9000000000095,77.21604253403352,0.20145325229172034,-0.3343827316520249
721.0000000000095,77.32645265098652,0.20295559650940195,-0.33591792770439577
722.1000000000096,77.4368517292999,0.2049037593364299,-0.33461425425410507
723.2000000000096,77.54782789587003,0.20340343725344423,-0.3359293732447801
724.3000000000096,77.65869423851105,0.20183245823106166,-0.33886871765348614
725.4000000000096,77.76948880836898,0.20769556579331683,-0.3415003606082956
726.5000000000097,77.88032109031813,0.2101106929874214,-0.3419046966406305
727.6000000000097,77.99055559340921,0.20940021976583445,-0.33856994439618004
728.7000000000096,78.10161921333669,0.2090852591258478,-0.3395148841603741
729.8000000000096,78.21306147003223,0.20705810684489162,-0.3390891402011067
730.9000000000096,78.32381764510866,0.20923852015300548,-0.34078556292782114
732.0000000000097,78.43433983885443,0.20330751156336324,-0.34275005322723073
733.1000000000097,78.54560039330173,0.2021342176411311,-0.34004814319439935
734.2000000000097,78.65650164799214,0.20339272510592202,-0.34142798456001033
735.3000000000097,78.76727990678651,0.20201214192259154,-0.3394368440062743
736.4000000000098,78.87827942910764,0.20705084535371743,-0.3374145756620677
737.5000000000098,78.98743762362525,0.20352933447797555,-0.33856980940908166
738.6000000000098,79.10035256310688,0.2068004831134148,-0.3385696636113802
739.7000000000098,79.2114359331358,0.20671014305837104,-0.3412008828142583
740.8000000000098,79.32204445330157,0.2075676293404976,-0.34244522891696416
741.9000000000099,79.43296238452571,0.20559505714063459,-0.3381318232087467
743.0000000000099,79.54352894601907,0.20207179044679285,-0.34078815861948364
744.1000000000099,79.65502537379639,0.20211854891571052,-0.34207491380944566
745.2000000000098,79.76646973270941,0.2020828976596316,-0.34081713603169694
746.3000000000098,79.87733402603294,0.19675526950290795,-0.33977826274212175
746.9000000000099,79.93677918457867,0.19882820812215785,-0.3410999436417095