File: 01_Data/EIFS_Mesh/STA/N2/10K_min/EIFS_Mesh_STA_N2_10KData_230206_R2.csv
##Temp./Â°C,Time/min,DSC/(mW/mg),Mass loss/mg
50.0,10.826443595697283,0.0035927874446393115,-0.009880858143235471
50.90000000000001,11.102201079640528,0.018968945687900307,-0.005470855538180608
51.800000000000026,11.30939851883182,0.028978304242808894,-0.008291308767344852
52.70000000000004,11.486037354267019,0.03657281978948257,-0.007334421479179731
53.60000000000005,11.639092730950766,0.04328254638109286,-0.00576597558967773
54.500000000000064,11.783729226875407,0.044887227269506,-0.012253474926662733
55.40000000000008,11.922546078244395,0.05294855856921998,-0.012690897581561167
56.30000000000009,12.054429635835103,0.056418544161868533,-0.010913093114032435
57.2000000000001,12.181028009032191,0.059427699166363146,-0.007522067959721657
58.100000000000115,12.303410289261986,0.061557303957261666,-0.00905396086320387
59.00000000000013,12.42219630356335,0.0624540640509339,-0.009828702056675631
59.90000000000014,12.538897855395666,0.0662031699127299,-0.0055139200228215834
60.80000000000015,12.65387085799372,0.06830264020802246,-0.006766101276960423
61.700000000000166,12.765381838362808,0.06658846588280287,-0.0084335652051859
62.60000000000018,12.876064271705372,0.07352784181939098,-0.008446153496795006
63.50000000000019,12.98602533056528,0.07135455319855599,-0.008506998628141638
64.4000000000002,13.093683539427923,0.07364050835882852,-0.009028838769918668
65.30000000000021,13.200962490437547,0.07373568576192291,-0.011428315237023146
66.20000000000023,13.306905556831119,0.07572457568417867,-0.008304247948041521
67.10000000000025,13.412961050116595,0.07650082261657709,-0.008469631255004106
68.00000000000026,13.515423770817044,0.07890471061734106,-0.008440645657767476
68.90000000000026,13.619433725546983,0.07971407407384712,-0.008885872514475146
69.80000000000028,13.721893850001992,0.07927478852129077,-0.008426198831475773
70.7000000000003,13.824735448233861,0.08327199900367233,-0.008558846110212404
71.6000000000003,13.92541514117185,0.08456495513483331,-0.009667297361774185
72.50000000000031,14.025457034177972,0.08689253237685635,-0.010826339737076474
73.40000000000033,14.126528451703948,0.08856024683156538,-0.01289126896707371
74.30000000000035,14.222637215616501,0.08898950320244503,-0.011460043558555011
75.20000000000036,14.321337133329687,0.0888421121735965,-0.009077336377767864
76.10000000000036,14.419459328608921,0.09235632600630783,-0.008826025227029355
77.00000000000038,14.516793214361158,0.09464291623839127,-0.010005203354417347
77.9000000000004,14.614159780840032,0.09605819934393378,-0.013015157695972501
78.80000000000041,14.71044011034342,0.09442057655090319,-0.012444171232685264
79.70000000000041,14.805093223562105,0.09756741926259438,-0.010435890716280483
80.60000000000043,14.900630738432387,0.09963220413598539,-0.010441724963841992
81.50000000000045,14.995970507323625,0.10043005002435557,-0.0104300162659543
82.40000000000046,15.089420845101763,0.10188707892045978,-0.010414966128398095
83.30000000000047,15.183420625597183,0.1013537277436114,-0.013022206828207317
84.20000000000049,15.273235441104747,0.10347143021677208,-0.01182314404855056
85.1000000000005,15.370927626122546,0.1026050937447267,-0.011769494531806757
86.00000000000051,15.461121867573889,0.10377850255197463,-0.013079819238996038
86.90000000000052,15.554175608062145,0.10475312034332807,-0.011763706152697395
87.80000000000054,15.64591545467152,0.10370674629121357,-0.013059430786504844
88.70000000000056,15.738465888999377,0.10697416600686815,-0.01306551512297549
89.60000000000056,15.828897124211846,0.10683464383689345,-0.013070047952546293
90.50000000000057,15.918862792644974,0.10769602174293103,-0.013039416010142357
91.40000000000059,16.010097405911647,0.10972082081759993,-0.01472715139152525
92.30000000000061,16.099880752100617,0.1072625851086324,-0.014790322260187061
93.20000000000061,16.189407604450036,0.10979715687412006,-0.014362992415211995
94.10000000000062,16.280349045432377,0.108744688024768,-0.014269841691064045
95.00000000000064,16.369224751914054,0.10722708221708199,-0.015595560992463842
95.90000000000066,16.45849503012802,0.10977570942888559,-0.014227097376833253
96.80000000000067,16.54858015495953,0.10516455622308296,-0.014508909079033128
97.70000000000067,16.637100036718085,0.10544285841135048,-0.013148601682719363
98.60000000000069,16.724939189405923,0.1041688291987275,-0.011224049815225179
99.50000000000071,16.812988730089153,0.10497735107541217,-0.012961001239249814
100.40000000000072,16.901073075353594,0.1050704604966779,-0.015282930135404715
101.30000000000072,16.989693263788258,0.10272426783383559,-0.015586516723122834
102.20000000000074,17.078758146322244,0.10272580064536352,-0.015546784011400305
103.10000000000076,17.166246584416296,0.10382348686665943,-0.016406678297882227
104.00000000000077,17.255120470494333,0.10294925207969041,-0.015139982321107581
104.90000000000077,17.342156322576475,0.10073666198309827,-0.01691572166766875
105.8000000000008,17.42966231046912,0.09907795855367318,-0.015958553179200585
106.70000000000081,17.516359487950947,0.09810302377813729,-0.017027228687434004
107.60000000000082,17.605451992286426,0.09885186142431901,-0.016242853118479506
108.50000000000082,17.691979884884443,0.09611866615440445,-0.01559011854534953
109.40000000000084,17.779943567983977,0.09559681128068198,-0.01688917200817519
110.30000000000086,17.866817387204353,0.09304764009495337,-0.019763438403050504
111.20000000000087,17.95514481094751,0.09406236280791047,-0.0210710216669594
112.10000000000088,18.04140318339177,0.09353213522505222,-0.020099656235538
113.0000000000009,18.12919108723879,0.09059423551644497,-0.019380892337946598
113.90000000000092,18.216899994547052,0.08931291226121396,-0.015814547009191937
114.80000000000092,18.30456022800359,0.0878994447595639,-0.015940240742763123
115.70000000000093,18.39129908882369,0.0869748777488395,-0.018719359971483218
116.60000000000095,18.477906199976612,0.0878553177216711,-0.0214133662236744
117.50000000000097,18.561976585782183,0.08556019913707669,-0.022729325481091855
118.40000000000097,18.651438946790712,0.08669541020525984,-0.02272062710852385
119.30000000000098,18.737541870093406,0.08504280550276022,-0.02142612815479339
120.200000000001,18.825966056012057,0.08390924869665961,-0.0228318504295828
121.10000000000102,18.912195784985457,0.08319431355509066,-0.020061393839278185
122.00000000000102,18.997372262772984,0.0829346808842284,-0.01736521307667438
122.90000000000103,19.085229584744184,0.08070563507130724,-0.01802939693845218
123.80000000000105,19.17267577211833,0.07841140595905116,-0.01669041578463837
124.70000000000107,19.255812711869346,0.0799003750187317,-0.019086929388869134
125.60000000000107,19.34462783591836,0.07722698807712902,-0.020848422018756363
126.50000000000108,19.430722333967942,0.07707675700108085,-0.020100480094721096
127.4000000000011,19.5156782934607,0.07937849267113017,-0.02009322524787338
128.30000000000112,19.604033174046407,0.07800128926863426,-0.02273521774015741
129.20000000000113,19.69034002507592,0.07844554001022508,-0.02301731178874311
130.10000000000113,19.776292153197723,0.07678344879026178,-0.023726875009930204
131.00000000000114,19.862945896401882,0.07792118470804343,-0.022399723431345997
131.90000000000117,19.947670050795214,0.0763367277731456,-0.02371799511373851
132.80000000000118,20.033798149208092,0.07641088992202616,-0.02371981489135644
133.70000000000118,20.11888398940823,0.07609108179854607,-0.023770253500714045
134.60000000000122,20.20508827077514,0.07656755577985164,-0.02373912665906408
135.50000000000122,20.29000503032721,0.07677171326225707,-0.025029919032510062
136.40000000000123,20.374288714899986,0.07550804060585481,-0.02492388031847792
137.30000000000123,20.461221474997668,0.07541372433567406,-0.02502991156565937
138.20000000000124,20.545456875263987,0.07660670013405535,-0.02371996268299803
139.10000000000127,20.6312274945013,0.07643458879128373,-0.02372012329777018
140.00000000000128,20.716605383756946,0.07454572601170961,-0.02517269301424996
140.90000000000128,20.802181079132094,0.07352409902375734,-0.02383478337892342
141.80000000000132,20.88724586433739,0.07278233587625715,-0.025039826543246324
142.70000000000132,20.97173691841425,0.07230185200002837,-0.024978571351934598
143.60000000000133,21.057781539391957,0.0745096575276627,-0.026525021532181725
144.50000000000134,21.14318847715788,0.0723224213570135,-0.02798604452083575
145.40000000000134,21.227401875336312,0.07239350287577495,-0.027999793760015823
146.30000000000138,21.31273435404634,0.07276335847503346,-0.026681364801554697
147.20000000000138,21.396948135155693,0.07186117408268189,-0.025843522410414543
148.1000000000014,21.483287148027305,0.07235260955419742,-0.025674085474627795
149.00000000000142,21.567277987761628,0.07328140922595738,-0.025802820270960147
149.90000000000143,21.653324737103375,0.07156164797471198,-0.026380105788578856
150.80000000000143,21.73807362174518,0.07149178827350366,-0.026348152250343926
151.70000000000144,21.822096375291384,0.0696724296306408,-0.025002587978439017
152.60000000000144,21.90791275009619,0.06899056155879613,-0.025041188838843098
153.50000000000148,21.99248107934995,0.07004286954039862,-0.026348899126390712
154.40000000000148,22.07809859869321,0.07251717357684773,-0.028047119285337985
155.3000000000015,22.162177668865976,0.072186521152245,-0.030090178032998516
156.20000000000152,22.24880856242342,0.07350192881427342,-0.02908612158166113
157.10000000000153,22.32931089858724,0.07154139926042635,-0.029098977131644332
158.00000000000153,22.416674910345957,0.0725147652418131,-0.027780109290704846
158.90000000000154,22.50175486677108,0.07185174413378981,-0.02711899607714363
159.80000000000155,22.586214803909648,0.07082432315408427,-0.026096865424342308
160.70000000000158,22.67210823767926,0.07167034407368822,-0.02713185451270217
161.6000000000016,22.75591093453968,0.07081838506482074,-0.028447633308953613
162.5000000000016,22.84102379269678,0.07134953017900192,-0.029760116662293612
163.40000000000163,22.92624743349267,0.07151956207976995,-0.031116324446569532
164.30000000000163,23.00994710643728,0.07272068685618815,-0.029765893394726906
165.20000000000164,23.095320179736373,0.06979203393824929,-0.029759964203678546
166.10000000000164,23.180112105140253,0.07070697769650247,-0.031069391758691278
167.00000000000165,23.26468138973876,0.07041052263583303,-0.030889182776216106
167.90000000000168,23.350345375082924,0.07009246241968259,-0.02912772583045653
168.8000000000017,23.433960950037108,0.07084156777356365,-0.027450392488433728
169.7000000000017,23.519764587881166,0.07077462850638028,-0.0287254315708112
170.60000000000173,23.604233117865235,0.07193384125726665,-0.030145634478206507
171.50000000000173,23.68869485600656,0.07288162085324812,-0.032740706756228644
172.40000000000174,23.77415914823632,0.07215463220581697,-0.0333803857305206
173.30000000000175,23.859770317350083,0.07335738871619824,-0.033370027181772066
174.20000000000175,23.941848593310702,0.07273464743673363,-0.03337699328522614
175.10000000000178,24.028827992840508,0.07183503982370243,-0.03205996838146641
176.0000000000018,24.11432118914286,0.07016479790706998,-0.030596693148250864
176.9000000000018,24.19855177935602,0.07205150555416495,-0.030616474250013237
177.80000000000183,24.283178550594176,0.07127295630493691,-0.028903131424238282
178.70000000000184,24.36582971726296,0.07148531621255849,-0.03185792807013721
179.60000000000184,24.45276630677885,0.07145682382766749,-0.031840477327639505
180.50000000000185,24.536459000475233,0.07231008207092426,-0.03040391405595866
181.40000000000185,24.62186753253192,0.07315929620713124,-0.030460834191977426
182.3000000000019,24.70660785635272,0.07295291262928927,-0.032656570184817824
183.2000000000019,24.791928897284958,0.07475530417306031,-0.03566821848996016
184.1000000000019,24.876226426221805,0.07317670327684833,-0.038428899140488415
185.00000000000193,24.9616453881155,0.07565075930256093,-0.038430072008922345
185.90000000000194,25.045818105634666,0.07503952656598256,-0.03637116003410812
186.80000000000194,25.131096421817826,0.07168180684291481,-0.03204965523457082
187.70000000000195,25.215525606654747,0.07412013405318807,-0.032522401914781174
188.60000000000196,25.300198335467268,0.0730970298607615,-0.03317715713401981
189.500000000002,25.385278952873673,0.07177330240305546,-0.032509416612868325
190.400000000002,25.470301929318367,0.07228064394874223,-0.03283024660009071
191.300000000002,25.554435398030886,0.07209775493475568,-0.034150888182109096
192.20000000000203,25.638347483860603,0.07309362501476302,-0.035462106168098195
193.10000000000204,25.72440552018222,0.0715556728228065,-0.03625766285789256
194.00000000000205,25.80770028169301,0.07418481579901703,-0.03852907799931282
194.90000000000205,25.89241517161953,0.07353664366036827,-0.03836407937428454
195.80000000000206,25.977218812521023,0.07293823251835951,-0.03676895327666152
196.7000000000021,26.061470878700046,0.07313947421158185,-0.03463177271901374
197.6000000000021,26.14764876829977,0.07474829893823765,-0.03590067319910828
198.5000000000021,26.231206112280397,0.07440815207103646,-0.036228879935954694
199.40000000000214,26.31556680672398,0.07415211965232871,-0.03490702117360822
200.30000000000214,26.400421918593338,0.0734698283729952,-0.03623000040789126
201.20000000000215,26.484951757793485,0.07491099874551888,-0.03687555595962966
202.10000000000215,26.57065520546973,0.07630598530153399,-0.03689021016853511
203.00000000000216,26.654135019159902,0.07749014074172211,-0.036319619951834525
203.9000000000022,26.738780509089192,0.07498445976593482,-0.03555282933516679
204.8000000000022,26.82306831049064,0.07517476117464761,-0.03685832895008723
205.7000000000022,26.908224096423947,0.0766028397508467,-0.0368665566401396
206.60000000000224,26.992983356444782,0.07661172952900341,-0.03437061765904881
207.50000000000225,27.078123681726733,0.07821617712051698,-0.03827582892216874
208.40000000000225,27.161090024291227,0.0785745540550461,-0.03678189801088427
209.30000000000226,27.247078372080523,0.07653724934727912,-0.032785633021546357
210.20000000000226,27.331717087442588,0.07714827771802157,-0.03702377460998818
211.1000000000023,27.416218455898555,0.07670065468023024,-0.03971134018408273
212.0000000000023,27.501183941151318,0.07767911746472544,-0.039455975257515874
212.9000000000023,27.586675113060245,0.07780054223534227,-0.04084128034220802
213.80000000000234,27.668671142934123,0.0771306184978644,-0.04169213869344768
214.70000000000235,27.755193311854683,0.07751352216354646,-0.03682177602820769
215.60000000000235,27.83936081737452,0.08004510989086189,-0.03612068532552515
216.50000000000236,27.924815005969503,0.07798972927815562,-0.03714610721315381
217.40000000000236,28.009126594950565,0.07740153719825893,-0.037488027808985525
218.3000000000024,28.094438447137094,0.07874148239225942,-0.037382950851378105
219.2000000000024,28.17660959934804,0.07853833239185837,-0.038761347619282294
220.1000000000024,28.26170516582202,0.07901970800423874,-0.04293234944382451
221.00000000000244,28.34758368111469,0.07876122723234968,-0.04293019610918147
221.90000000000245,28.432279739744704,0.07996285487464383,-0.042928247704181466
222.80000000000246,28.516880438000115,0.08052166264178273,-0.04152625005237143
223.70000000000246,28.603065786127313,0.08004419272056718,-0.04029991485887141
224.60000000000247,28.687678075717194,0.07970781531115678,-0.04029990102883385
225.5000000000025,28.77226167731535,0.0788357000393125,-0.03794395220413227
226.4000000000025,28.857707200697007,0.07773852077090315,-0.039447344277918184
227.3000000000025,28.941622666772094,0.07960102462960428,-0.04374847739857346
228.20000000000255,29.025715203002346,0.07616781925237615,-0.04268168844444942
229.10000000000255,29.111743679953292,0.07823084584970219,-0.041390106849502395
230.00000000000256,29.1971953987334,0.07916092791427631,-0.04274659842930184
230.90000000000256,29.282278816138582,0.07771623524105298,-0.039711538990282236
231.80000000000257,29.36638934403204,0.07911823276699537,-0.03843044327714651
232.7000000000026,29.45073483614099,0.07935258842939297,-0.040207019424936874
233.6000000000026,29.536065043598068,0.07914044557438393,-0.04272062535190546
234.50000000000261,29.62073503612351,0.08059431682867857,-0.044031078207686036
235.40000000000265,29.7061119072116,0.07857107718134937,-0.04663793192351573
236.30000000000265,29.789955734739376,0.08137720878934496,-0.04666416676682594
237.20000000000266,29.874414682086627,0.07904082896549058,-0.04487529765673948
238.10000000000267,29.959828693044166,0.07924826066013257,-0.04127989195004478
239.00000000000267,30.04611089216812,0.07944736550665521,-0.04128395887023517
239.9000000000027,30.13092164695297,0.07812460251857267,-0.04413052769301151
240.8000000000027,30.215842122758293,0.08048390956485807,-0.045706676139004365
241.70000000000272,30.300917112211426,0.0798497983433315,-0.04677214325616319
242.60000000000275,30.3866364012435,0.07867196424650746,-0.04530125869261559
243.50000000000276,30.470319963839952,0.0794710982644472,-0.0446626712005167
244.40000000000276,30.555308696380546,0.07858482518335985,-0.04535859396049391
245.30000000000277,30.641006866322797,0.07961216092029033,-0.04540186846573491
246.20000000000277,30.72653258572769,0.08105721126379861,-0.045328363081183376
247.1000000000028,30.811725444637144,0.08169287805300685,-0.046659821206583185
248.0000000000028,30.89603970456113,0.08097043831061179,-0.0453415262428547
248.90000000000282,30.980830916919306,0.08050940071355406,-0.04538428304759412
249.80000000000285,31.06638815898163,0.08078207371068713,-0.04292459586846231
250.70000000000286,31.152559140916416,0.08224232129085729,-0.047822013307991185
251.60000000000286,31.236271621485738,0.08169975091380599,-0.04890562294208234
252.50000000000287,31.32228732254031,0.0801765171469675,-0.04754941772334087
253.40000000000288,31.40697913550811,0.08076186047210832,-0.04655923354271119
254.3000000000029,31.492489308475367,0.08152797585561511,-0.0491806059555131
255.20000000000292,31.577786651884153,0.08004538414642459,-0.049203670276687816
256.1000000000029,31.663158834734435,0.08165828651962415,-0.05017004184956253
257.00000000000296,31.749123707206923,0.08241491478793594,-0.050170000625931355
257.90000000000293,31.834691289232435,0.082468754198607,-0.04887704636029788
258.80000000000297,31.92054587581079,0.08166202458726524,-0.04885106620362478
259.700000000003,32.004796462547084,0.08148743615094434,-0.050162515596746005
260.600000000003,32.0896307489049,0.08194964196834298,-0.05006157771853603
261.500000000003,32.175463481413374,0.07967315756704918,-0.050170121087950825
262.40000000000305,32.26132961923908,0.08130762483561421,-0.05016573583835182
263.300000000003,32.347035278652804,0.0842494187760035,-0.050882688032534595
264.20000000000306,32.433026886661,0.08191646578456524,-0.05185055357762547
265.1000000000031,32.5174629021906,0.08302519553077775,-0.0501795841642898
266.00000000000307,32.60374146644186,0.0828778652083762,-0.05246742105228108
266.90000000000305,32.68859877110468,0.08149127686741858,-0.05248017365437496
267.8000000000031,32.77425158623556,0.08311456913416193,-0.05243911427724646
268.7000000000031,32.8596487360773,0.08442451164759968,-0.053040480410687874
269.6000000000031,32.94472571570027,0.08323364605876216,-0.05247834580122168
270.5000000000031,33.029581890658164,0.08254854227314645,-0.05248014802162304
271.40000000000316,33.116360809310116,0.0832069024920869,-0.05248014799273415
272.30000000000314,33.2012125868387,0.08239982377850968,-0.05248175745228334
273.2000000000032,33.286714023100444,0.08304370728979898,-0.053790160349358906
274.1000000000032,33.37218360977837,0.082914996641206,-0.05375777788138425
275.0000000000032,33.45754282350555,0.08098460043300137,-0.05248014866476636
275.9000000000032,33.54416252393212,0.08334992502182742,-0.05234695781004994
276.80000000000325,33.629253694332604,0.08279095125250541,-0.05645767872373586
277.70000000000323,33.71458178991623,0.08465829811347275,-0.056430041948866805
278.60000000000326,33.799153406738995,0.08260431961211251,-0.056430039999853854
279.5000000000033,33.88545932502009,0.08319192032328315,-0.05643003181899786
280.4000000000033,33.97125627922753,0.08243695465820339,-0.05519173735503102
281.30000000000325,34.05652422722018,0.08240639006108202,-0.05510988225641311
282.2000000000033,34.14248392588193,0.08340585311263843,-0.05503326767702177
283.1000000000033,34.22703063390128,0.08264807163315441,-0.05511097841007029
284.0000000000033,34.31264302762925,0.08397915887850765,-0.056429344191933684
284.90000000000333,34.39868056353348,0.08313339407916592,-0.05708107996861811
285.80000000000337,34.48414417284635,0.08467738910568356,-0.057083740570421426
286.70000000000334,34.56994311067474,0.08647575536797703,-0.057751810273564796
287.6000000000034,34.65661932656386,0.08624115682868133,-0.05907012904799558
288.5000000000034,34.74221838626356,0.08821801428739173,-0.059069939618203726
289.4000000000034,34.82747931985564,0.08708784869175573,-0.057765835577807234
290.3000000000034,34.91278695800595,0.08998894170770072,-0.05775004026122099
291.20000000000346,34.998180136833916,0.08935667157529209,-0.05762214649657649
292.10000000000343,35.08452370075838,0.08996526468719035,-0.0589909279091847
293.00000000000347,35.17062313932549,0.09071876696548647,-0.06038004247530404
293.9000000000035,35.25557896042181,0.08765677148803569,-0.06038004976814282
294.8000000000035,35.34145034641627,0.0891826609215906,-0.06140029620135756
295.70000000000346,35.428371125817335,0.09085846182254409,-0.061369960318391925
296.6000000000035,35.51351468814403,0.09089142131408484,-0.06136996112276005
297.5000000000035,35.599536591751296,0.09017844290962868,-0.06166650084892744
298.4000000000035,35.68521398081234,0.09056387750033768,-0.06041963750818402
299.30000000000354,35.77184841025596,0.0911908431601402,-0.06137984196105073
300.20000000000357,35.856747872450256,0.09180944578865824,-0.06137985100019083
301.10000000000355,35.94228679287992,0.09162258147067498,-0.061379821516856836
302.0000000000036,36.02892799241315,0.0907019647188742,-0.062324547222493365
302.9000000000036,36.115423788409515,0.09350832580593071,-0.0630320042083321
303.8000000000036,36.19944996563639,0.0945694477490846,-0.06355541527123698
304.7000000000036,36.28742262841565,0.0965178908291005,-0.0656500934066857
305.60000000000366,36.372753783883454,0.09685318078190158,-0.06697368919382019
306.50000000000364,36.459383500754605,0.09801564337272528,-0.06697637551697788
307.4000000000037,36.54479640604476,0.09794288925679645,-0.06694226945783832
308.30000000000365,36.63142374370134,0.10118799111601257,-0.0682888034839304
309.2000000000037,36.71634508420879,0.09959931309808534,-0.0669700439996701
310.1000000000037,36.8023391044528,0.10188643438920236,-0.0669682149149331
311.0000000000037,36.88915751327663,0.10168784323327956,-0.06824175874378646
311.90000000000373,36.974574700897016,0.10493434638288834,-0.06961000436755072
312.8000000000037,37.06164928297868,0.10527369480662963,-0.0695863548381519
313.70000000000374,37.146543472425776,0.10570298847291643,-0.07158031757901195
314.6000000000038,37.23242530022111,0.11031528048572015,-0.07158024145653519
315.50000000000375,37.318619768336426,0.11054821832607514,-0.073547587753509
316.4000000000038,37.40546954005133,0.11347522842441837,-0.07618701017063678
317.3000000000038,37.49101734758121,0.11380649734884135,-0.07619003334789021
318.2000000000038,37.57605418932997,0.11649134524978083,-0.07751553059723326
319.10000000000383,37.66401397098101,0.11930614112223159,-0.07881500031542599
320.00000000000387,37.74928919906981,0.12126031768845569,-0.07619101694059527
320.90000000000384,37.83314097697685,0.12222666540731758,-0.07751055478451452
321.8000000000039,37.92193417430043,0.12394579066224598,-0.07655168598254658
322.70000000000385,38.007716102266244,0.13072374856519892,-0.07750912826964829
323.6000000000039,38.094235994864995,0.13086113170093677,-0.07869449298688025
324.5000000000039,38.18037134822129,0.13357980747744247,-0.08043968115406797
325.4000000000039,38.267373731119,0.13421515584287275,-0.08147273873060001
326.30000000000393,38.35286413109458,0.13703611985220038,-0.08416229389001062
327.2000000000039,38.43849883409816,0.13855014392649806,-0.08672607653684983
328.10000000000394,38.52533954985003,0.13918755487845236,-0.09060925941881193
329.000000000004,38.611919270017,0.14079521571148962,-0.08934968129879062
329.90000000000396,38.69713705046379,0.14044705553813058,-0.09190944776371435
330.800000000004,38.78501271534536,0.14148516584790521,-0.09463980508704672
331.700000000004,38.870068224273524,0.1396469564148442,-0.09591948663897609
332.600000000004,38.95649523163795,0.14106641222902783,-0.09764663822424735
333.50000000000404,39.04437614883598,0.1411506804929909,-0.0986591810382067
334.40000000000407,39.130650415986615,0.14031534367721216,-0.0999005832975075
335.30000000000405,39.216520351685425,0.13844313317807339,-0.1021008364158642
336.2000000000041,39.30292511544546,0.13745575825308398,-0.10396842646807825
337.10000000000406,39.39041217050889,0.1354314093841168,-0.10621785646898729
338.0000000000041,39.475314144084436,0.1353435376737877,-0.10932001331641361
338.9000000000041,39.562695146550936,0.13126368437518127,-0.11068976288310184
339.8000000000041,39.64908853890523,0.1326046592420378,-0.11205260949325746
340.70000000000414,39.73471485582284,0.13045280286705663,-0.11607122285561555
341.6000000000041,39.82064243308776,0.12777878805003745,-0.11833466938849391
342.50000000000415,39.90538415092551,0.1279535379852514,-0.12146790238557337
343.4000000000042,39.99471053641997,0.12756959709297083,-0.12289366873899965
344.30000000000416,40.079793058512486,0.12483107497020901,-0.12416248216858872
345.2000000000042,40.16739623896793,0.12204499199433472,-0.12521832679821232
346.10000000000423,40.25360473379411,0.12233263976082676,-0.12899783700647838
347.0000000000042,40.340178659142325,0.11832048797819172,-0.13409458777124694
347.90000000000424,40.42426662764431,0.11672317223255357,-0.13580724404640065
348.8000000000043,40.51283498752292,0.11513482097124089,-0.13875676074302756
349.70000000000425,40.59959268412768,0.11572984327195224,-0.14139162676536987
350.6000000000043,40.685493830405875,0.11432449660824773,-0.143982187670034
351.50000000000426,40.77327168278261,0.111338663562916,-0.1453400308074837
352.4000000000043,40.85953214353208,0.11075764285325485,-0.14664193327821895
353.30000000000433,40.94570954215366,0.10987473942403969,-0.14943108839539132
354.2000000000043,41.032732432427736,0.11049266587492268,-0.14927046962979107
355.10000000000434,41.120000800168334,0.10837929574334765,-0.15099137871246082
356.0000000000043,41.20677102467356,0.10920083374652118,-0.155796587637834
356.90000000000435,41.29255591309175,0.10907738382135218,-0.15865379066279228
357.8000000000044,41.37996090706304,0.10695758285437673,-0.1624504833353595
358.70000000000437,41.4667009702739,0.10858271466433933,-0.1651315827095199
359.6000000000044,41.553830508156416,0.11021524058852078,-0.16645766748246293
360.50000000000443,41.639545509229045,0.11053585926264026,-0.1663404328742324
361.4000000000044,41.7278680784994,0.1102336283794898,-0.16761716773047075
362.30000000000445,41.81437356417266,0.10899429178508074,-0.17032821151836153
363.2000000000045,41.90170393987908,0.10841359797175287,-0.1689669657399726
364.10000000000446,41.98853420817242,0.11068001589144255,-0.17159936504658946
365.0000000000045,42.0743760071401,0.1106605477050196,-0.17545216023547727
365.90000000000447,42.161751563051794,0.11165968449831787,-0.17848282830719864
366.8000000000045,42.24846286381471,0.11073589673983847,-0.17808077542790413
367.70000000000454,42.3346249796537,0.10989836091651994,-0.17808000674601
368.6000000000045,42.42100811823204,0.10984662114146782,-0.1780811796801478
369.50000000000455,42.508349575444214,0.11034545370499521,-0.17938938624135625
370.4000000000045,42.59670467206127,0.11161483291772561,-0.18073761940971167
371.30000000000456,42.68269920515388,0.11035420572438809,-0.18204014350529052
372.2000000000046,42.769936767599965,0.11214217342194704,-0.18334197182709122
373.10000000000457,42.85790771379648,0.11343963463438062,-0.18701067984790232
374.0000000000046,42.94337095157072,0.11140091653104917,-0.18806236259620146
374.90000000000464,43.03045653485904,0.11209508805120016,-0.18971103135715817
375.8000000000046,43.11810393671463,0.11504914326145843,-0.18829530363062785
376.70000000000465,43.20542266374123,0.11359709323941031,-0.18970602614728316
377.6000000000047,43.291718787603,0.11301088809786186,-0.19102097853913502
378.50000000000466,43.378751147336956,0.11292816300954267,-0.1910166062664702
379.4000000000047,43.46589414341651,0.11376277800603662,-0.19234023661649502
380.3000000000047,43.55127273164892,0.11338557534597132,-0.1930374275665172
381.2000000000047,43.63980193283555,0.11033690941715368,-0.19366007140763086
382.10000000000474,43.7272935186235,0.11378533166248966,-0.1949831957740269
383.0000000000047,43.81529005891899,0.11418411264257017,-0.19399959986979542
383.90000000000475,43.90248559858142,0.11725150558473466,-0.19661732688535505
384.80000000000473,43.988751948083426,0.11435725951395409,-0.19729876183818584
385.70000000000476,44.07666860846819,0.1161656015333778,-0.19860003360351008
386.6000000000048,44.16349425775217,0.1155693516372994,-0.1972788157243306
387.5000000000048,44.25100049691321,0.11713883550049747,-0.1972906404330983
388.4000000000048,44.338147607540556,0.11722208491679942,-0.19854917235229053
389.30000000000484,44.42519064147397,0.11705090861907091,-0.20124355757606338
390.2000000000048,44.51326295003464,0.1170841421129982,-0.20188804902637436
391.10000000000485,44.60039769095292,0.11740127252253052,-0.20254829574862576
392.0000000000049,44.688214401422115,0.11858674995579196,-0.2030172506346668
392.90000000000487,44.77459750370859,0.11826695561177605,-0.2028797470594097
393.8000000000049,44.86267283215574,0.11850759074224512,-0.20420117984115205
394.7000000000049,44.94981517827969,0.11873124686965886,-0.20550834166431242
395.6000000000049,45.03751235096592,0.1185468967523545,-0.2081778127412761
396.50000000000495,45.12474005563326,0.12119366842232188,-0.20815003767549722
397.4000000000049,45.209384769530935,0.12359908171939951,-0.20782118841197583
398.30000000000496,45.29781404766793,0.12346164176095537,-0.20913965450729677
399.20000000000493,45.38667629298106,0.12276040054473569,-0.20913581381171475
400.10000000000497,45.47428070042735,0.12352100369713151,-0.2117864216534171
401.000000000005,45.562457757749435,0.12403459242740944,-0.2130897891744814
401.900000000005,45.64879366078448,0.12583321307957407,-0.21303062005649442
402.800000000005,45.73634599590703,0.12708362245424554,-0.21270954919375296
403.70000000000505,45.82480191454303,0.12959191592090435,-0.21439778490506356
404.600000000005,45.912202726747594,0.1307293600922303,-0.21516199596218355
405.50000000000506,46.00011217359689,0.13267365561941277,-0.21441044808134668
406.4000000000051,46.086555421542364,0.1344468037181371,-0.21628306233138161
407.30000000000507,46.175200361194385,0.13703362594157972,-0.21836160851320185
408.2000000000051,46.26217537796081,0.13634017155775127,-0.21959767665228958
409.1000000000051,46.35031950350792,0.14024399942376148,-0.22063249119328443
410.0000000000051,46.43742993889866,0.140335168301105,-0.2216715860957641
410.90000000000515,46.52534496757238,0.13942088725593885,-0.2243826160146165
411.8000000000051,46.61083081928734,0.13905553843610322,-0.22308016451716295
412.70000000000516,46.700828984770126,0.13840312392481172,-0.22440091259282235
413.60000000000514,46.78833686267399,0.13671297536517857,-0.22704019059616165
414.5000000000052,46.876700158778796,0.13603364993581163,-0.22834740139451037
415.4000000000052,46.96479062762125,0.1337326176802991,-0.22966862258429543
416.3000000000052,47.052307510693886,0.13206152098961152,-0.23097081449594858
417.2000000000052,47.13989583168532,0.1304051057108075,-0.23166207433408692
418.10000000000525,47.22791193393914,0.13281565505687598,-0.23298804350564906
419.00000000000523,47.31511688737653,0.13140793372382575,-0.23453427121120018
419.90000000000526,47.40325794047502,0.13071472839476805,-0.23693005062811334
420.8000000000053,47.491489017986964,0.12734374035672616,-0.23598895928776553
421.7000000000053,47.57939638031939,0.1255240192856588,-0.2382213908827273
422.6000000000053,47.6671156701132,0.12333037142808315,-0.23701516259153
423.5000000000053,47.7559241715185,0.12140493367611321,-0.23822995633727295
424.4000000000053,47.84375003587168,0.12080356295500536,-0.23902442892435793
425.30000000000535,47.931492672887046,0.11876050694748846,-0.2408633187476763
426.20000000000533,48.01787767687461,0.11418718240752881,-0.24086023369548837
427.10000000000537,48.10655155327563,0.11508151087027213,-0.24283870295199605
428.00000000000534,48.19456237102303,0.11344044607329698,-0.24416036258511653
428.9000000000054,48.2824813768281,0.11567785607821712,-0.2454785222839253
429.8000000000054,48.370074039718844,0.11372194091762472,-0.24580869743524403
430.7000000000054,48.45888496127291,0.11375863143954912,-0.2461046271278713
431.6000000000054,48.54585300987764,0.11524374914658353,-0.24537387959508106
432.50000000000546,48.63470030818603,0.11455974167569744,-0.24680370062048107
433.40000000000543,48.72152901515351,0.11377024277098194,-0.24811010316378468
434.30000000000547,48.80945623066334,0.11647436748993795,-0.24943172166253147
435.2000000000055,48.897649337755695,0.11405318910451465,-0.2517185839997005
436.1000000000055,48.985484804441136,0.11484533225297744,-0.25205404691735245
437.0000000000055,49.073336156107075,0.11445198108875762,-0.25338015503922984
437.9000000000055,49.1616423472052,0.11628801318494053,-0.2532899880496604
438.8000000000055,49.248966679008646,0.11352001081234275,-0.25470162801526985
439.70000000000556,49.33680844905525,0.11605040010857365,-0.2534922495140579
440.60000000000554,49.42477381544498,0.11531195389715515,-0.25243108050214635
441.50000000000557,49.511986117368075,0.11403032946336927,-0.2533801150035093
442.40000000000555,49.599579540907136,0.11488765368087162,-0.25525721258039047
443.3000000000056,49.68717832844832,0.11576736612321312,-0.2572702478521518
444.2000000000056,49.77578160673497,0.11620522449804818,-0.25996609275467986
445.1000000000056,49.86338202228891,0.11439006177220257,-0.2638216401726803
446.0000000000056,49.95181324097668,0.11323505043635576,-0.26402403538634456
446.90000000000566,50.03967163215547,0.11355579125042847,-0.2624946455571009
447.80000000000564,50.128927290107015,0.11301092998172871,-0.26407598209006355
448.7000000000057,50.216870852452615,0.11008924311797491,-0.26776619675295166
449.6000000000057,50.30508409852201,0.10982844052701773,-0.2676538774087467
450.5000000000057,50.39363770883714,0.11257575309809756,-0.2677485398469659
451.4000000000057,50.4820496358477,0.11067388048123383,-0.2690892740141395
452.3000000000057,50.57044323273669,0.11078922288004503,-0.2713569592430889
453.20000000000573,50.658078646880966,0.11200537909708005,-0.2724288117013751
454.10000000000576,50.74668345733276,0.10928157314180911,-0.27671053550242597
455.00000000000574,50.83544043900704,0.11125011345918054,-0.27700139502561427
455.9000000000058,50.9232715913456,0.10896971000421996,-0.27793489117245107
456.80000000000575,51.01161679705895,0.10915240511074487,-0.28032879585434634
457.7000000000058,51.10046914188221,0.10701365634592977,-0.28294945173442176
458.6000000000058,51.188670383738256,0.11044967709403167,-0.280933858635402
459.5000000000058,51.27803193865745,0.10886199899565122,-0.2813728022827169
460.40000000000583,51.36613517990841,0.10654012699479443,-0.2813958474472704
461.30000000000587,51.45510646326509,0.10848454802215624,-0.28420562816581096
462.20000000000584,51.543203118744934,0.10949534039182976,-0.28544007734999566
463.1000000000059,51.6319435636982,0.11076843908807182,-0.28679075299977885
464.0000000000059,51.720368411847495,0.10942479210088442,-0.2867577983807781
464.9000000000059,51.808162049916085,0.11008143071440547,-0.28868954951665815
465.8000000000059,51.897447154459854,0.10859905350938835,-0.29071501160289426
466.7000000000059,51.985292728698944,0.10900782949374249,-0.2932702254504349
467.60000000000593,52.073170433087014,0.10877982290791136,-0.29429664398035493
468.50000000000597,52.16241324172185,0.11030480206740337,-0.2953636950233882
469.40000000000595,52.250316054193505,0.10554647445003841,-0.2969733102197263
470.300000000006,52.33853660283992,0.10673353097801065,-0.29824119924093484
471.20000000000596,52.42667138058117,0.10818663799344856,-0.2996990999333722
472.100000000006,52.51540438124734,0.10730808067376957,-0.3012991891800936
473.000000000006,52.60391372236109,0.1074640771116641,-0.3035733563787124
473.900000000006,52.69190081751586,0.10708971659982273,-0.3048791063497349
474.80000000000604,52.77985319776991,0.10676954290134552,-0.30709067766518494
475.70000000000607,52.8684397475656,0.10597612684484191,-0.30750977114255473
476.60000000000605,52.95638754630461,0.10622086165241316,-0.3070833670464723
477.5000000000061,53.04474267855821,0.10581938949027267,-0.3078711749676164
478.4000000000061,53.13331583734962,0.10726215904026142,-0.3065771059767304
479.3000000000061,53.22257434962266,0.10593150846256019,-0.3078486055037071
480.2000000000061,53.3108290649144,0.10858986670368594,-0.31055552455136803
481.1000000000061,53.398239076311576,0.10747791008243324,-0.3105800002382044
482.00000000000614,53.48779723782052,0.1074758796384883,-0.310989894716049
482.9000000000062,53.575444841405506,0.10552990313359906,-0.31190002457560073
483.80000000000615,53.6640093145278,0.105850902003067,-0.31191813994115414
484.7000000000062,53.75198468526955,0.10673776772795157,-0.31322308880533445
485.60000000000616,53.840724643992736,0.10388909358033518,-0.3145311599521814
486.5000000000062,53.928593967677635,0.10219919305695656,-0.3171729569379722
487.40000000000623,54.01680729410054,0.1017152847194304,-0.31574953460218325
488.3000000000062,54.106376604085106,0.09930207546462072,-0.31581463251465625
489.20000000000624,54.195099049267284,0.09852853096539486,-0.3170846181740061
490.1000000000063,54.283329771805434,0.09888045956653188,-0.315740769856125
491.00000000000625,54.37283057375492,0.09763350456008534,-0.31703777461123694
491.9000000000063,54.46062773623308,0.09811030756598874,-0.3181736137859317
492.8000000000063,54.54829639929615,0.1043587569921418,-0.3196988340870113
493.7000000000063,54.637031907888705,0.1101257475647985,-0.319589934560939
494.60000000000633,54.725943926362746,0.11343749660427038,-0.3170440381034645
495.5000000000063,54.81473739434752,0.11690187278111294,-0.3170651720213349
496.40000000000634,54.90318372007792,0.11027873185256651,-0.31837967747852236
497.3000000000064,54.989536047533946,0.11323286493001962,-0.3197738451353942
498.20000000000636,55.080726456780184,0.10675640316206672,-0.3210082471323883
499.1000000000064,55.16937803204447,0.10465968210023519,-0.32101012100797766
500.00000000000637,55.25893789573712,0.10146373515354275,-0.3210113836468107
500.9000000000064,55.34776199616921,0.0973660604551104,-0.32365020925211185
501.80000000000643,55.436458809345375,0.0927088811467904,-0.32270813991144776
502.7000000000064,55.52591330419147,0.09107986163770548,-0.3196857707025811
503.60000000000645,55.61512185565188,0.08599930912577083,-0.3222089833108668
504.5000000000065,55.7041151974036,0.08082436252757544,-0.3235207829277238
505.40000000000646,55.793689946244946,0.0747501426109702,-0.3222054603183233
506.3000000000065,55.88224328158237,0.07116654017564852,-0.32211468476914895
507.2000000000065,55.97110127292405,0.06645338789572412,-0.32221480147640813
508.1000000000065,56.058765248357076,0.06315946513243974,-0.32287860568653004
509.00000000000654,56.14933167430345,0.05928465156738899,-0.3228696563439337
509.9000000000065,56.239540077416855,0.05571114886505439,-0.3228812613618821
510.80000000000655,56.327570585937224,0.05245505330103564,-0.3222240730502599
511.7000000000066,56.417045730076566,0.047473807123257245,-0.3226368499286041
512.6000000000065,56.50565820481714,0.04685788265472586,-0.3222201716750672
513.5000000000066,56.59449262353179,0.039109682425275766,-0.3221409567926359
514.4000000000066,56.68449676519354,0.03545471286194632,-0.3241987129167345
515.3000000000065,56.77289936807079,0.033276064941676176,-0.3248499588281115
516.2000000000066,56.86276774883975,0.02985627340490947,-0.3235401426284583
517.1000000000066,56.95172423763296,0.02410497476467227,-0.3235400583940735
518.0000000000066,57.041121499135706,0.016903457178860562,-0.32359600512795383
518.9000000000067,57.130501631621854,0.014952895438924585,-0.3219999461577694
519.8000000000067,57.21864895198705,0.012523154569234973,-0.3246427880120559
520.7000000000066,57.308233347567096,0.009145201352505627,-0.3253481259420683
521.6000000000067,57.39692983129365,0.008478799616595228,-0.32596028856290626
522.5000000000067,57.48627146711315,0.0052710366549210685,-0.3253241752857208
523.4000000000067,57.574616833903384,0.00280950144739725,-0.325933289324686
524.3000000000068,57.66346710063287,0.0018181698079947073,-0.32390619195804327
525.2000000000068,57.75202709260434,-0.002465368266791501,-0.3233172938651121
526.1000000000067,57.8415025391965,-0.0016712579899929025,-0.32399600711399135
527.0000000000068,57.93103053272207,-0.004752996169308299,-0.32413092105912744
527.9000000000068,58.01991526568491,-0.006486739034160513,-0.3273852378957254
528.8000000000068,58.10780727221396,-0.00954972028029634,-0.327269562767333
529.7000000000069,58.1973929875486,-0.011589022527572573,-0.32595025015254997
530.6000000000068,58.28556679742758,-0.010909993414549346,-0.3272707770542409
531.5000000000068,58.37656662013748,-0.015225987247472594,-0.32462976771761953
532.4000000000069,58.465524786886725,-0.020710901559740355,-0.32414097130657993
533.3000000000069,58.55453327096985,-0.02255315826624843,-0.32617134713174156
534.2000000000069,58.643858587900056,-0.022361501409239426,-0.32749013876686295
535.100000000007,58.730712083598746,-0.023617717115383102,-0.32746261533923526
536.0000000000069,58.82190761974969,-0.022363462220226935,-0.32484824162699155
536.9000000000069,58.9110240691224,-0.02169240270420668,-0.3261961512723279
537.800000000007,59.00034367577332,-0.021932286359212072,-0.32880993307775075
538.7000000000069,59.08997361995081,-0.01832458255227533,-0.32723522839895614
539.600000000007,59.178103487426846,-0.015052385916235742,-0.3275150057102789
540.500000000007,59.26755841421732,-0.01693203856634498,-0.32844187924051926
541.4000000000069,59.356555850152,-0.01658244726522938,-0.3284744011634264
542.300000000007,59.44652326078303,-0.014127945866750508,-0.3295538537969329
543.200000000007,59.536249791924696,-0.013646227816362017,-0.32717141649785964
544.100000000007,59.624350641219905,-0.01206310417472653,-0.32754426299787465
545.000000000007,59.71399412909597,-0.009312284209697597,-0.3257552285785774
545.900000000007,59.803081826524426,-0.009376609542082623,-0.3265094377184363
546.800000000007,59.89114354222455,-0.006587165811467038,-0.32835986179674226
547.7000000000071,59.98251521036579,-0.010299215334239012,-0.3283533473178677
548.6000000000071,60.071140759980324,-0.009084044285212978,-0.32840779914670515
549.500000000007,60.160537813893676,-0.006302620574765147,-0.3268297529876061
550.4000000000071,60.25043163444115,-0.00712891575835535,-0.32815018334734836
551.3000000000071,60.33920793655625,-0.005497413039017879,-0.32815015099885025
552.2000000000071,60.428353658260214,-0.0058730912759132475,-0.32815015100000045
553.1000000000072,60.51801821730177,-0.00834935253390337,-0.3281501510004601
554.0000000000072,60.60754310607196,-0.007403366974657655,-0.3281500676709035
554.9000000000071,60.69649166447101,-0.00981944809260965,-0.32480454507322953
555.8000000000072,60.7862225407413,-0.0065834070158215935,-0.32856107978954086
556.7000000000072,60.87496420578464,-0.009451437708407867,-0.3332321223995254
557.6000000000072,60.96382456524329,-0.007505424339672079,-0.3313194162866253
558.5000000000073,61.05473021232036,-0.010753857397052799,-0.32991009371171653
559.4000000000073,61.144632676276544,-0.009537637071044283,-0.32997324707644626
560.3000000000072,61.23316361616511,-0.008397904504645018,-0.3298991077106397
561.2000000000073,61.32303665164583,-0.008296508940316194,-0.32990020255189334
562.1000000000073,61.41312392897842,-0.008992036321681295,-0.3307217202446293
563.0000000000073,61.50270613333835,-0.010031933887273366,-0.32990952054881717
563.9000000000073,61.592227965930334,-0.006983148238448533,-0.32990996200165057
564.8000000000073,61.67983854425516,-0.010289383895801918,-0.32990993336441576
565.7000000000073,61.771729116786716,-0.010439888230939769,-0.3285894717779332
566.6000000000073,61.8589336859871,-0.007663161105693005,-0.3285995290538466
567.5000000000074,61.949574164993514,-0.008597912391220493,-0.3272682837798011
568.4000000000074,62.039072004154754,-0.007366357578090829,-0.3272716808938094
569.3000000000073,62.12915551295343,-0.00505862206900131,-0.32992477610862103
570.2000000000074,62.218969605647345,-0.004010007165721724,-0.32989987810854116
571.1000000000074,62.30853953992021,-0.003113838089075005,-0.33003941531479875
572.0000000000074,62.39738170800505,-0.005786426578604058,-0.3285798786817211
572.9000000000075,62.486554233986524,-0.003034300071344996,-0.32857987901286645
573.8000000000075,62.576841519421365,-0.0035009704807058423,-0.3285781439570745
574.7000000000074,62.665688830629044,-0.0015433617754720408,-0.3299014211472455
575.6000000000074,62.75561461437188,-0.0002718678033536842,-0.3312257210963616
576.5000000000075,62.84425224388469,-0.0002893581996427086,-0.3312201717274914
577.4000000000075,62.933806993538575,-0.0021508792892982187,-0.3307884755150594
578.3000000000075,63.0238735546553,-0.0018567770098961225,-0.3299001745270438
579.2000000000075,63.11343405033933,-0.0013798248554917902,-0.3308764504959547
580.1000000000075,63.20371866178193,-0.0010167156643890798,-0.33050531824813856
581.0000000000075,63.29252234947807,-0.0037195046042281174,-0.33121158636022763
581.9000000000076,63.38172242814143,-0.0033521883819566493,-0.3298527287066535
582.8000000000076,63.47224770543394,-0.0040905778885698026,-0.33056031256942253
583.7000000000075,63.56071425935478,-0.0013503280681977509,-0.3315159741954492
584.6000000000076,63.65092708911465,0.00105130478327679,-0.331621426568832
585.5000000000076,63.7407312067223,-0.002858638723520681,-0.33155008606154546
586.4000000000076,63.83137215665339,0.0005778079041561558,-0.3305768850230226
587.3000000000077,63.91859346286457,0.0008092235401312674,-0.3278166201810948
588.2000000000077,64.01034876460871,0.002162179153484871,-0.327861939869174
589.1000000000076,64.10042565989349,0.005663079625362678,-0.3293506257391554
590.0000000000077,64.19123041864657,0.007718425228433601,-0.33110989851812844
590.9000000000077,64.28013789793667,0.005786071503629191,-0.33110992635018244
591.8000000000077,64.3698201165237,0.005933755681770686,-0.3318337931937414
592.7000000000077,64.46049038418408,0.007137389271334915,-0.3337233123850387
593.6000000000078,64.55041446029074,0.00959542285146926,-0.33472984333235045
594.5000000000077,64.64083000000076,0.006940402157607763,-0.3347298471408924
595.4000000000077,64.72994915229995,0.007627577264526014,-0.33331062234958786
596.3000000000078,64.81712897187583,0.008661998317940438,-0.3306636740327993
597.0000000000077,64.88957578702428,0.01202575293493538,-0.33066916659832124