File: 01_Data/EIFS_Mesh/STA/N2/10K_min/EIFS_Mesh_STA_N2_10KData_230207_R3.csv
##Temp./Â°C,Time/min,DSC/(mW/mg),Mass loss/mg
50.0,10.834997879722637,0.028432927030932253,0.009400225363042303
50.90000000000001,11.111858117382823,0.04732955655483684,0.00903215365843213
51.800000000000026,11.315222413614432,0.05995165460043261,0.007502471014418255
52.70000000000004,11.488230287733003,0.06811847628023782,0.007127073058748046
53.60000000000005,11.640654496106656,0.07168895459085944,0.006839184096098627
54.500000000000064,11.788130509814556,0.08030160488048277,0.007434691322829146
55.40000000000008,11.926136897360706,0.0843859759860126,0.006838918312126019
56.30000000000009,12.055565355014421,0.08857377619219253,0.005756874500124631
57.2000000000001,12.182202409794302,0.09246411604174676,0.006631853412526034
58.100000000000115,12.29884676385728,0.09604683221257271,0.006839398144149023
59.00000000000013,12.423179498949736,0.10040285827898976,0.006608672967033158
59.90000000000014,12.539731958156942,0.10287387871693854,0.005378736547569041
60.80000000000015,12.654557780337738,0.10516369829515315,0.004109230652609597
61.700000000000166,12.767832141869146,0.10874120997317416,0.005640470729177061
62.60000000000018,12.879737449554222,0.10998009302218859,0.004616117588248869
63.50000000000019,12.98869066752324,0.11189939469183874,0.004374284433653841
64.4000000000002,13.098045982933826,0.11580306402829854,0.004302533071924408
65.30000000000021,13.204487343974193,0.11714844898763999,0.0045179820949536875
66.20000000000023,13.310596982694893,0.11958389589057816,0.003708413538555
67.10000000000025,13.416581724375973,0.12253394431887021,0.004319634853752419
68.00000000000026,13.520951463693786,0.1252348633506768,0.004062075358801209
68.90000000000026,13.62400624868147,0.12688037266508134,0.003061739959419718
69.80000000000028,13.721630136784398,0.13055625791657266,0.004387619328440451
70.7000000000003,13.826333284871088,0.13052932693067287,0.0037712456723753007
71.6000000000003,13.927796502620357,0.13577133802121355,0.0030641941146116736
72.50000000000031,14.028588549350985,0.13400451919475942,0.004198439315837632
73.40000000000033,14.127871483104762,0.1367396923083326,0.003093111655184444
74.30000000000035,14.226349300444838,0.1391217081460714,0.003082363318573478
75.20000000000036,14.322905319007763,0.1413817481124484,0.004298415927767252
76.10000000000036,14.422137979135645,0.14339181014345437,0.003074238805558238
77.00000000000038,14.519139542916909,0.14364505040117792,0.0022683080969221336
77.9000000000004,14.61688822886307,0.1470348166926998,0.003089113788697695
78.80000000000041,14.712463064735642,0.14991126129504062,0.0030658427326510918
79.70000000000041,14.80550904511629,0.1513028527589262,0.0030712493659059703
80.60000000000043,14.90266489870312,0.154961778595752,0.002842704321030176
81.50000000000045,14.998130363932322,0.15373572051136297,0.001831351849166829
82.40000000000046,15.091606915492147,0.15393756087951393,0.001683804181747739
83.30000000000047,15.185710736301548,0.15689893326535365,0.0005161004545586323
84.20000000000049,15.278446054720238,0.15747487949135208,0.0011797336257641788
85.1000000000005,15.370830000000055,0.16002699291862532,0.0017527794677363318
86.00000000000051,15.463145656752195,0.1577729972808608,0.0015364372092419032
86.90000000000052,15.555730477065614,0.15617937043128727,0.0018526170788240037
87.80000000000054,15.647746448208768,0.158202162202022,0.00042853471404313837
88.70000000000056,15.737029623882496,0.1597592849526832,0.0004309784838589792
89.60000000000056,15.830633534831964,0.15869376270571944,0.00043134069364736405
90.50000000000057,15.920724339146936,0.1607224824906368,0.0004257029965373249
91.40000000000059,16.01154430048709,0.1618834870147705,0.0017651160474363436
92.30000000000061,16.102171662867065,0.1616219291827352,0.002049478343804978
93.20000000000061,16.190925468154475,0.16064166216998377,0.00041703732137232663
94.10000000000062,16.280014766147556,0.16128503409131523,0.00040377845413352986
95.00000000000064,16.371593362243207,0.1629091389347721,-0.00026734340319034544
95.90000000000066,16.460399715403007,0.16480028713387052,0.00043033087736343845
96.80000000000067,16.549013107705807,0.1636594729962313,-0.0008956828762505253
97.70000000000067,16.637199504953436,0.16327575955923446,-0.0008802995161429905
98.60000000000069,16.727127784132353,0.16428762074186087,-0.0008855117716546346
99.50000000000071,16.81362063208206,0.16273199010366068,-0.0021994466215611297
100.40000000000072,16.90222616929328,0.16295510027569304,-0.0008872536599406899
101.30000000000072,16.990921799443335,0.16341874213847096,-0.002117093598529074
102.20000000000074,17.079475509534735,0.16210198936729514,-0.0021967365158177543
103.10000000000076,17.166071935470708,0.1607439988448216,-0.002192087774672835
104.00000000000077,17.25233580510568,0.16160364773597813,-0.002215692139794889
104.90000000000077,17.3436234400993,0.1613377229562195,-0.0025474770271207703
105.8000000000008,17.43024085324716,0.16042538099303671,-0.00220582008190906
106.70000000000081,17.518460171253793,0.15843317419321112,-0.001770054991427017
107.60000000000082,17.60512797969645,0.15905303176666763,-0.0009089768794705577
108.50000000000082,17.69275369915692,0.16022234121855716,-0.002200037535006416
109.40000000000084,17.77970934893002,0.1608300477801392,-0.0022028156626126005
110.30000000000086,17.86684609869857,0.1596736260185596,-0.003498596586095637
111.20000000000087,17.95513689901894,0.15887322970530027,-0.0028478294531266712
112.10000000000088,18.042130087796263,0.15789171393581336,-0.002557521778243199
113.0000000000009,18.128883666009397,0.15683840515453318,-0.0035229451225164965
113.90000000000092,18.21370364134246,0.15653431548451535,-0.0022035925768397746
114.80000000000092,18.302891385088,0.15619682268912682,-0.003519951911063579
115.70000000000093,18.38956952613789,0.15480125095408703,-0.004838606902199061
116.60000000000095,18.476466387759945,0.15600321324533784,-0.0035203971991943916
117.50000000000097,18.566008885119743,0.15332092257716123,-0.0036220191400664348
118.40000000000097,18.65102543732511,0.15408091042400995,-0.003529875192855414
119.30000000000098,18.73775430572452,0.15322918711239553,-0.004844976047762017
120.200000000001,18.82452794397356,0.15258227126752366,-0.003622192666607127
121.10000000000102,18.90980174567309,0.15331459740313658,-0.0035265352074098644
122.00000000000102,18.998559552085684,0.1535039372288992,-0.004847505299974131
122.90000000000103,19.083484719150476,0.15338154719483266,-0.005964073139447024
123.80000000000105,19.17120637530079,0.15326042548525176,-0.004839851693844821
124.70000000000107,19.256688394461307,0.15261882444071873,-0.006242255351970094
125.60000000000107,19.343927723275854,0.15210009780612055,-0.004839698286164484
126.50000000000108,19.429985429294565,0.15012833330778697,-0.00615305503441288
127.4000000000011,19.51625313385154,0.14897797996007578,-0.006150129833319085
128.30000000000112,19.602581089637894,0.14961929433723842,-0.006159302400159383
129.20000000000113,19.687608829175105,0.14947911804129588,-0.006160009964659707
130.10000000000113,19.77484938414746,0.15053704438977455,-0.006165861027300323
131.00000000000114,19.860013746663068,0.14824164178524368,-0.004839639886801805
131.90000000000117,19.94646481735929,0.14813421948028938,-0.005850538081669576
132.80000000000118,20.033135197343892,0.14832923389822839,-0.005988037536943658
133.70000000000118,20.119108752918557,0.14872415967358743,-0.006161856035435953
134.60000000000122,20.203311350671424,0.14851484992924235,-0.006131940435762928
135.50000000000122,20.28863825240367,0.15018090008871798,-0.0074682559124266135
136.40000000000123,20.375814350008557,0.14828945455365272,-0.006149927031620983
137.30000000000123,20.461302401832818,0.1492230442000545,-0.006148707180210877
138.20000000000124,20.545218817126354,0.14650577596273662,-0.0061631597713649455
139.10000000000127,20.632495417971988,0.14728342903358727,-0.004840011149982004
140.00000000000128,20.714438972270738,0.14874662938056094,-0.005706064043581094
140.90000000000128,20.80262204371411,0.14863155145139773,-0.00616002337620003
141.80000000000132,20.887512473418102,0.14746582966809463,-0.00622383801357973
142.70000000000132,20.972499079603697,0.14727197589222485,-0.0059372644592947665
143.60000000000133,21.057547903101014,0.14710549776236082,-0.0061884555604905245
144.50000000000134,21.143579261933688,0.14767454589182993,-0.006150089546242299
145.40000000000134,21.2276705644041,0.1458235679759441,-0.006150034433717089
146.30000000000138,21.31460397501666,0.14653773074399912,-0.004849381938814901
147.20000000000138,21.398618245853083,0.14589006090891932,-0.006204139658219532
148.1000000000014,21.48388350222371,0.14517695104832573,-0.007487908064383042
149.00000000000142,21.568781878337518,0.14523185627188562,-0.006109637748092922
149.90000000000143,21.653709515438507,0.1491535233912128,-0.006159229310585879
150.80000000000143,21.737974936736254,0.14810852944813124,-0.007469270486917701
151.70000000000144,21.82164661529022,0.14821358966486897,-0.0074698035302516175
152.60000000000144,21.907756819282334,0.14631012730344617,-0.007547828212172369
153.50000000000148,21.994223875966924,0.14684098349106622,-0.007470042934133225
154.40000000000148,22.078633796347834,0.14830487355065158,-0.008344948820591114
155.3000000000015,22.1633988784364,0.14916461487926835,-0.008768610960005141
156.20000000000152,22.248028372101114,0.14826311759055733,-0.007645281024857731
157.10000000000153,22.33226390881173,0.14845981483245407,-0.008789973032583553
158.00000000000153,22.417559043093018,0.14791442476688554,-0.008751896629423328
158.90000000000154,22.501991567270384,0.14796642043036168,-0.009449832121522839
159.80000000000155,22.586811949249874,0.1506284192936337,-0.008764425636946349
160.70000000000158,22.67101350716129,0.15030025820216764,-0.00812127345160718
161.6000000000016,22.756583341941916,0.15127352591404608,-0.008666416809354871
162.5000000000016,22.841402817180086,0.15220318740504202,-0.010244769501650097
163.40000000000163,22.926388858783984,0.15033594478100132,-0.010109992058102257
164.30000000000163,23.011353418616654,0.15337514710110367,-0.008750533134683991
165.20000000000164,23.095376666186556,0.15296705410866418,-0.009449732027361435
166.10000000000164,23.180655284100816,0.1520992393703059,-0.009449818000319077
167.00000000000165,23.264610432281334,0.1529386613297633,-0.009449818002480903
167.90000000000168,23.349483726391284,0.15249105843119204,-0.00944988584399109
168.8000000000017,23.434797399761113,0.15328879964379316,-0.009506966307074372
169.7000000000017,23.518815632414963,0.1529079600339499,-0.010773244010831462
170.60000000000173,23.60436125448813,0.15444512130334342,-0.011426866472259434
171.50000000000173,23.689441350751387,0.15365853909722949,-0.011420052013083826
172.40000000000174,23.774515359000986,0.15570782225834845,-0.01141998837101088
173.30000000000175,23.858066226553422,0.15379576282755691,-0.010433283379220448
174.20000000000175,23.943330554211958,0.15523605523356643,-0.011819615311986276
175.10000000000178,24.029041572500876,0.15414528665669835,-0.011759976021791019
176.0000000000018,24.113479988597398,0.15395020355453903,-0.011760003469690972
176.9000000000018,24.19808883713778,0.15641943581599071,-0.012420894026509366
177.80000000000183,24.28303644505453,0.15511853655951713,-0.013108669164181741
178.70000000000184,24.367389716378376,0.15476078313873587,-0.012750468265172898
179.60000000000184,24.45225076528418,0.15552525925676208,-0.012654041781686054
180.50000000000185,24.537872334287695,0.15815034956926433,-0.012740167944553349
181.40000000000185,24.62273990742721,0.15870076985739334,-0.012740167999939267
182.3000000000019,24.706879291119627,0.15543636725417298,-0.012740164508761254
183.2000000000019,24.793177603648015,0.15563110725775553,-0.013782648014324828
184.1000000000019,24.87664584372195,0.15473395461045103,-0.013720985413966602
185.00000000000193,24.96083000000019,0.1571875653161684,-0.013070004268670665
185.90000000000194,25.04656767362328,0.1551776693181559,-0.013070664828207512
186.80000000000194,25.129660773543783,0.1572586697174989,-0.014096716840189316
187.70000000000195,25.215352475028762,0.15742956582152323,-0.012766169344310185
188.60000000000196,25.29970811607443,0.1577323535791263,-0.014059639195143525
189.500000000002,25.384743661129008,0.15788479943151879,-0.012693480893646303
190.400000000002,25.468614016680043,0.16024194437901917,-0.012750115180091726
191.300000000002,25.55454838336196,0.16098773872812744,-0.012751787233174383
192.20000000000203,25.63921175768404,0.16101906586386516,-0.014060193810434107
193.10000000000204,25.72168334810788,0.1592320962456134,-0.014060114057323325
194.00000000000205,25.807742496628315,0.15971842711166273,-0.01387229424606673
194.90000000000205,25.89284934480268,0.15954557890769883,-0.014059956799209239
195.80000000000206,25.975777755822936,0.15846346680662093,-0.014059947588580535
196.7000000000021,26.06119071544116,0.15901754231972132,-0.014063615652135653
197.6000000000021,26.145658737512537,0.1587218160854228,-0.012740254473689205
198.5000000000021,26.230287520894493,0.15886560802846472,-0.013768285543535264
199.40000000000214,26.315079736556424,0.1582703340622228,-0.013730185275188767
200.30000000000214,26.398808463419734,0.15806326562175044,-0.01376524302707871
201.20000000000215,26.48409462276852,0.15990437836869342,-0.013900216771515872
202.10000000000215,26.568007462087703,0.159709326504211,-0.013410178869036393
203.00000000000216,26.651408955268533,0.15786534720363143,-0.014065441153209512
203.9000000000022,26.73699794950786,0.1598390246457616,-0.012750041980355675
204.8000000000022,26.820533711780516,0.1595370053541515,-0.014048285345573674
205.7000000000022,26.905941412844136,0.16116016268944477,-0.0140598957978888
206.60000000000224,26.990828776829225,0.16219138242940956,-0.014058326050725434
207.50000000000225,27.07499982908419,0.16362351349688165,-0.014060193478280247
208.40000000000225,27.1594937736948,0.16365737419266935,-0.01406013000110562
209.30000000000226,27.24445963677482,0.16317554104790022,-0.014060130696050166
210.20000000000226,27.32848724084372,0.16198534777069862,-0.014057533850837522
211.1000000000023,27.413801564317907,0.16194937874619642,-0.014389255202516438
212.0000000000023,27.497803217050915,0.16491736126871548,-0.014388837077966343
212.9000000000023,27.58244706822943,0.1647318126512448,-0.01570105799485244
213.80000000000234,27.666925718225205,0.16471012341937796,-0.015369806825836996
214.70000000000235,27.7509247440152,0.16389723432199932,-0.014084446667124162
215.60000000000235,27.835654857826178,0.1657819935601239,-0.015205347306180172
216.50000000000236,27.920919605427805,0.16550863451872366,-0.014384069062959526
217.40000000000236,28.005253902088633,0.16775608654002738,-0.014059743194947849
218.3000000000024,28.090162761333787,0.16766188931080872,-0.014698549654595716
219.2000000000024,28.175179443949286,0.16880687926119853,-0.015049849480384125
220.1000000000024,28.259625281044666,0.16758622564871295,-0.015049843999406676
221.00000000000244,28.34458973362796,0.1674980431208375,-0.015049927416272979
221.90000000000245,28.427961346516263,0.16565743207330852,-0.013745805670302147
222.80000000000246,28.51291050741342,0.1659685183962737,-0.013730077888338243
223.70000000000246,28.59832630222664,0.16564687579757864,-0.013729736909900758
224.60000000000247,28.681885061316542,0.16594555651615972,-0.014060278069692345
225.5000000000025,28.76853125657166,0.16711506580658064,-0.015437356956672588
226.4000000000025,28.853387926797698,0.16406549414873706,-0.015380216585353601
227.3000000000025,28.93720411841329,0.1639109960635089,-0.014065021565689229
228.20000000000255,29.022783123948308,0.16503944278641292,-0.015050475532772722
229.10000000000255,29.108337149239237,0.16630413871575234,-0.01667675276883429
230.00000000000256,29.19017609771133,0.16632207814256006,-0.016428352760372356
230.90000000000256,29.277431547486916,0.16633255242959716,-0.015379927257952453
231.80000000000257,29.362372334075328,0.16718944852368373,-0.016482074662736323
232.7000000000026,29.446383948970116,0.16757608027201187,-0.016700077165672234
233.6000000000026,29.531881739304765,0.16738327537536735,-0.018122873841230458
234.50000000000261,29.617555871878114,0.16922217995115058,-0.016690450618891184
235.40000000000265,29.70203443044964,0.16854072426171834,-0.016689876941360815
236.30000000000265,29.785940205415155,0.167616899893885,-0.018007199653238715
237.20000000000266,29.871632358383675,0.16838906384997598,-0.01800991014534148
238.10000000000267,29.95696538853908,0.1673540782067589,-0.01800991000000174
239.00000000000267,30.042367637504885,0.16867652994825266,-0.018009909988008665
239.9000000000027,30.125938860029915,0.16820166370821255,-0.018009488730584167
240.8000000000027,30.21238377716547,0.16651845980302288,-0.019330252403149117
241.70000000000272,30.29801366808588,0.16713213105649427,-0.01800995245702186
242.60000000000275,30.380348850501157,0.1695485831727832,-0.018025296928830592
243.50000000000276,30.467758433227612,0.1698218259193559,-0.01932991758090985
244.40000000000276,30.553772262439793,0.17046248964674898,-0.01938618561328287
245.30000000000277,30.63752391449556,0.17063625772135227,-0.020649930596922328
246.20000000000277,30.72373769888578,0.17020778735580017,-0.02184465746874409
247.1000000000028,30.807221308478024,0.17082559816272763,-0.020147964673037144
248.0000000000028,30.89416742111617,0.17126275203203145,-0.019989908908114806
248.90000000000282,30.9795535047478,0.17002995717546254,-0.01998837060299774
249.80000000000285,31.064100699782912,0.1699398215395047,-0.021644902373669783
250.70000000000286,31.149925608027104,0.17026090056869803,-0.021639951994940176
251.60000000000286,31.235970911893606,0.16963890309258534,-0.021639873675659338
252.50000000000287,31.321346184284458,0.1718239160304188,-0.021629045112049994
253.40000000000288,31.405650136695826,0.1715229293981264,-0.021630186002041363
254.3000000000029,31.492285697760476,0.17415046714402027,-0.0216302170739886
255.20000000000292,31.576126053773407,0.17324104660807654,-0.024394964331444502
256.1000000000029,31.66175998008619,0.17529859410799742,-0.02526358511263238
257.00000000000296,31.746945712766546,0.17398719783293704,-0.025164004746404345
257.90000000000293,31.833249469424967,0.17484257126725672,-0.025171474627692092
258.80000000000297,31.918457026487772,0.17541548930648165,-0.025525093825094824
259.700000000003,32.003247828384495,0.17471928070433645,-0.025919604169892807
260.600000000003,32.08932186888682,0.17580318210352663,-0.026569699916279
261.500000000003,32.174656793651785,0.17482642378369556,-0.026569909967638417
262.40000000000305,32.25860061074405,0.17475763305462838,-0.02656990999999831
263.300000000003,32.34555585913427,0.17567302373703453,-0.026569909999999197
264.20000000000306,32.430356254474994,0.17464499879141454,-0.02656990999999831
265.1000000000031,32.51612079906641,0.17534293465707018,-0.026569909999999197
266.00000000000307,32.6017141488544,0.1731170445667034,-0.026569910000187047
266.90000000000305,32.687512287403486,0.1750963326633398,-0.02656996330587269
267.8000000000031,32.77175436600796,0.17359072129189207,-0.026902138835260825
268.7000000000031,32.858362923058294,0.17402102206409814,-0.02689991002137626
269.6000000000031,32.94254298301012,0.17469506548744657,-0.026899908179222276
270.5000000000031,33.028594551007444,0.17472355220942637,-0.026852457693493204
271.40000000000316,33.11380367562934,0.17332753011000646,-0.027889900236623966
272.30000000000314,33.19900054858384,0.17306538522196135,-0.027889927572869677
273.2000000000032,33.28479990538449,0.17572935753849317,-0.02875232640888914
274.1000000000032,33.36950567422348,0.1751966724857431,-0.029209909166587167
275.0000000000032,33.45595357403518,0.17461689693121563,-0.02789949351083454
275.9000000000032,33.54228354994013,0.17606549537500799,-0.029216006470967226
276.80000000000325,33.627020975734325,0.1783137294903342,-0.03053034484269146
277.70000000000323,33.71294785678427,0.18007553949221533,-0.02938359594774509
278.60000000000326,33.796501875932655,0.1762577975318539,-0.029214974896942802
279.5000000000033,33.883267396131764,0.1777085023793578,-0.027889968059592096
280.4000000000033,33.968331388621316,0.1781686090039809,-0.027889661905694307
281.30000000000325,34.05433269107089,0.17649400625410944,-0.02921141301767527
282.2000000000033,34.139111087776016,0.17825806320564624,-0.0305299485093542
283.1000000000033,34.22527121904377,0.17845011124365429,-0.030529909421871615
284.0000000000033,34.311139870175225,0.17864393755259161,-0.030523947470122437
284.90000000000333,34.39742720671154,0.17801540648003616,-0.029837033098254473
285.80000000000337,34.48135268187528,0.17963706232296855,-0.031186652531517645
286.70000000000334,34.56878125359016,0.17912193194671017,-0.03256954255284317
287.6000000000034,34.6536743562959,0.18108308691793562,-0.029819176025977168
288.5000000000034,34.74034602441184,0.18061712816539321,-0.032510371316078146
289.4000000000034,34.82619815948433,0.1807653563691506,-0.033934831712037816
290.3000000000034,34.9119907178588,0.18154146433899104,-0.03327521427735114
291.20000000000346,34.99633937416798,0.1829052553890434,-0.031203408326898163
292.10000000000343,35.08326771628579,0.18316833882672212,-0.03249994250717547
293.00000000000347,35.168006276883105,0.1829469251714808,-0.03258659878040371
293.9000000000035,35.25431468226721,0.18607815361288255,-0.032510091756584814
294.8000000000035,35.341022504598406,0.18621622674866672,-0.03250800696478473
295.70000000000346,35.42534425909746,0.18889462699209658,-0.033820309593980635
296.6000000000035,35.51211952340899,0.1889033373381131,-0.03273251789211784
297.5000000000035,35.59550285957038,0.1898493600593107,-0.03249514711897472
298.4000000000035,35.68265307875515,0.19110011447280995,-0.033833045370269765
299.30000000000354,35.76838704927234,0.1901253543464267,-0.03481219732186025
300.20000000000357,35.85446696611347,0.1910916484892639,-0.034809847374442704
301.10000000000355,35.93899208803723,0.19301838838168883,-0.0354098977943047
302.0000000000036,36.02602662773838,0.194565681771592,-0.03747451529889734
302.9000000000036,36.10983783476903,0.19540722827896145,-0.03743996185236176
303.8000000000036,36.19803411936869,0.19736164793588917,-0.037430305706407374
304.7000000000036,36.283763203244966,0.19854630712702565,-0.038429991458211354
305.60000000000366,36.369965085034,0.19696339885635666,-0.03842996199997728
306.50000000000364,36.45632948189993,0.2001124270998113,-0.038430005383997656
307.4000000000037,36.54146583765539,0.20147270358257835,-0.03876060988783303
308.30000000000365,36.62800529324147,0.20431733100387178,-0.04008354662003022
309.2000000000037,36.71356197162127,0.20535768623756362,-0.04008013068109362
310.1000000000037,36.79939675640081,0.20760996322367392,-0.04008796250507718
311.0000000000037,36.88533499994424,0.20626439197200463,-0.041145311335454515
311.90000000000373,36.97092867621992,0.21011856558665476,-0.0423883144027104
312.8000000000037,37.05746083394525,0.21030068723044076,-0.042713431234524535
313.70000000000374,37.1426926410237,0.2129220562446667,-0.042720309171746074
314.6000000000038,37.230278719998026,0.2126719726888452,-0.04371189987402646
315.50000000000375,37.31578728399472,0.2146935044472973,-0.045019945680048856
316.4000000000038,37.40123539923815,0.21593065201374267,-0.04501998416392183
317.3000000000038,37.48789542625456,0.2199677779574607,-0.04533533232032161
318.2000000000038,37.57474197948765,0.21991203735525394,-0.04534995552555143
319.10000000000383,37.660829089217486,0.2212483404917056,-0.046339870716528786
320.00000000000387,37.74647880962424,0.22363407897252124,-0.04799050660705095
320.90000000000384,37.833741290703934,0.22494720601464546,-0.04866091535644124
321.8000000000039,37.919096562263654,0.22874143021878457,-0.04915025804624751
322.70000000000385,38.006735884252365,0.23090846663486153,-0.04995999572792176
323.6000000000039,38.092229251612906,0.23041833344769652,-0.04995071095982384
324.5000000000039,38.17701521439035,0.23411083008808387,-0.05257801152690922
325.4000000000039,38.26427246623323,0.23422778066218128,-0.05512040195023493
326.30000000000393,38.35049248495232,0.2353611175771726,-0.05652911526642068
327.2000000000039,38.434528871528975,0.23444354490918703,-0.05773998301043237
328.10000000000394,38.52263617023072,0.23687082052140332,-0.05785998640201662
329.000000000004,38.60991826899138,0.23644965988361916,-0.05811626202505149
329.90000000000396,38.69551746338723,0.23678918987133413,-0.06059666114055906
330.800000000004,38.782457050743695,0.23820106167828115,-0.0632248943134126
331.700000000004,38.868371380848586,0.23915434746464376,-0.0658603704842986
332.600000000004,38.95434721292248,0.23873652479038313,-0.0658654936490568
333.50000000000404,39.0404684338218,0.2385701912630614,-0.06719237060234162
334.40000000000407,39.12744562877393,0.2397302712134127,-0.06947816214513436
335.30000000000405,39.21339368764109,0.2389661943477681,-0.0711360569590882
336.2000000000041,39.30020274703469,0.23900585770122487,-0.07246783383182587
337.10000000000406,39.38662392889031,0.23866043494437006,-0.07404010393157279
338.0000000000041,39.47357106925801,0.23853786237648195,-0.07848481353565262
338.9000000000041,39.560034908923825,0.23816856698591563,-0.07998519439135254
339.8000000000041,39.645895485471264,0.23746227568489017,-0.08101429456641096
340.70000000000414,39.73246836195556,0.23677527823947844,-0.08589597123367287
341.6000000000041,39.81853694913248,0.23388952871098234,-0.08814386859213519
342.50000000000415,39.905299472594024,0.23299236020203945,-0.09068641678052902
343.4000000000042,39.992105553086844,0.23111369552932634,-0.09347563500381195
344.30000000000416,40.07967966189801,0.22955571020744542,-0.09606968178802733
345.2000000000042,40.1626782524972,0.22749738314539458,-0.09698503304346584
346.10000000000423,40.25173387959084,0.2246372134255645,-0.10039602105991108
347.0000000000042,40.33871524836087,0.22374557484162494,-0.10163428544002917
347.90000000000424,40.4229856553854,0.22193546784299875,-0.10426731951867696
348.8000000000043,40.51116260641943,0.2222091657813696,-0.10695551281796511
349.70000000000425,40.598826662018,0.2193329275095393,-0.11132316737359016
350.6000000000043,40.685495983645815,0.21919185671562305,-0.1141702686941577
351.50000000000426,40.77252775327114,0.21825436962142505,-0.11547101055380837
352.4000000000043,40.85873787604725,0.2168910173348623,-0.11680461246259632
353.30000000000433,40.94596477626397,0.21695419133835944,-0.12066592316561797
354.2000000000043,41.03275093061182,0.2173044892866351,-0.1220879091121283
355.10000000000434,41.116817949630246,0.2148610862641843,-0.12352036303854552
356.0000000000043,41.205917793839696,0.21502529920813404,-0.12588550899345652
356.90000000000435,41.292311910262256,0.21582889311289583,-0.12883521136835618
357.8000000000044,41.37940488107079,0.21500696753337897,-0.1313611119502207
358.70000000000437,41.46565823641374,0.21060119887174616,-0.13276706504025437
359.6000000000044,41.55321970175199,0.21420549420895785,-0.13534914191464997
360.50000000000443,41.6405372978536,0.2119342357374726,-0.13667573885214157
361.4000000000044,41.72649667556157,0.2132123068968122,-0.13854337919351067
362.30000000000445,41.81334574086544,0.21169341671026773,-0.1406449604284754
363.2000000000045,41.90032708377566,0.21319923398142562,-0.14196063310849327
364.10000000000446,41.98754049807647,0.2124452559702899,-0.1432808355848354
365.0000000000045,42.07398646558803,0.21316181589015745,-0.14727030494965287
365.90000000000447,42.16148819092988,0.21375801429749236,-0.14827183251759157
366.8000000000045,42.24821429294387,0.21287459896047503,-0.14850016383025144
367.70000000000454,42.33481706616233,0.21191717447526798,-0.14986671835164156
368.6000000000045,42.4220990836903,0.2110068682122315,-0.15118018765813845
369.50000000000455,42.50958444562685,0.21177059670649762,-0.15173826528068401
370.4000000000045,42.596460590537625,0.21175829462755222,-0.15251783991629253
371.30000000000456,42.68186794401677,0.20985562438434,-0.15587873664343688
372.2000000000046,42.76996466417251,0.2121992277386264,-0.15772067410785606
373.10000000000457,42.85731338231576,0.2127188479986779,-0.15908015446064017
374.0000000000046,42.94363297352057,0.21398821850665875,-0.15900090020811586
374.90000000000464,43.03092687985586,0.21621921169598152,-0.16171026673735156
375.8000000000046,43.117602510758346,0.2161615009443459,-0.16305813524606538
376.70000000000465,43.20395097901684,0.2178376383609775,-0.16200509465584245
377.6000000000047,43.2928237602772,0.21724217193034373,-0.1634214842478281
378.50000000000466,43.37942715797692,0.21651837160004953,-0.16337009699014526
379.4000000000047,43.46625276658929,0.21800672684298858,-0.16526502342750105
380.3000000000047,43.5539832894308,0.21770531713888377,-0.16567016966373194
381.2000000000047,43.64170275003423,0.21702677541976106,-0.16633258298028153
382.10000000000474,43.72760281993365,0.2181007114700411,-0.16633312677974033
383.0000000000047,43.81584304276286,0.21885068023937854,-0.16762792450781205
383.90000000000475,43.90324058239203,0.2221734020069084,-0.16763997792897944
384.80000000000473,43.990624620342025,0.2198183370053048,-0.16763855587292342
385.70000000000476,44.07731420220794,0.22107539220147782,-0.170259454192772
386.6000000000048,44.16496640002599,0.22268680952468875,-0.17038652525800035
387.5000000000048,44.25224776293296,0.22176686864491868,-0.17233351214876036
388.4000000000048,44.3396570406785,0.22116781226336954,-0.17159003122994232
389.30000000000484,44.426197337698554,0.2225319747043355,-0.17267026932420304
390.2000000000048,44.51454812147321,0.2227784450876154,-0.17288413874103803
391.10000000000485,44.60123053694201,0.22161119489703904,-0.1742299689938802
392.0000000000049,44.68965126658802,0.22466500370720113,-0.17422996400012147
392.90000000000487,44.776461943625456,0.22539351395113216,-0.17422996440616956
393.8000000000049,44.862570234339216,0.2255682851892129,-0.17473036948528664
394.7000000000049,44.9509365550027,0.22749546336470808,-0.17621014559187032
395.6000000000049,45.03840428731878,0.22923529738526838,-0.1775201857886235
396.50000000000495,45.125410021861,0.23233237047262423,-0.1762095445340135
397.4000000000049,45.21307962708326,0.2298293307255651,-0.17638598964859042
398.30000000000496,45.297685817599444,0.23153717020367984,-0.17883711379390066
399.20000000000493,45.38799652206086,0.23432539785930973,-0.18016035153475363
400.10000000000497,45.475070968208364,0.2349594638143672,-0.18145461892020354
401.000000000005,45.56354859972059,0.23528420808398612,-0.1814928233264963
401.900000000005,45.64998532133432,0.23524567160929083,-0.18278852550583125
402.800000000005,45.73722697617672,0.23789563620291115,-0.18410938285784084
403.70000000000505,45.82703138344666,0.24114836495973904,-0.18543034215906795
404.600000000005,45.9139495998075,0.23975972105425536,-0.18543046305915034
405.50000000000506,46.00201940709069,0.24060960413640287,-0.18408082074620324
406.4000000000051,46.08951307066225,0.24371696430153575,-0.18603919717081974
407.30000000000507,46.17775179525349,0.24476015222608535,-0.18706343234616662
408.2000000000051,46.265944570151426,0.2465426323385786,-0.18845918430384945
409.1000000000051,46.353022398283585,0.24651856604203487,-0.1880520603443574
410.0000000000051,46.43974480410383,0.24799915553095334,-0.19093530699374472
410.90000000000515,46.5287324217,0.2495236496077438,-0.19331972877005832
411.8000000000051,46.616423952799416,0.250046396339072,-0.19386145894060913
412.70000000000516,46.70335267088434,0.2513003163367402,-0.19465142720334994
413.60000000000514,46.791221577778295,0.24863268571982405,-0.19596961270676205
414.5000000000052,46.87947807929579,0.24851885577454774,-0.19861473102220462
415.4000000000052,46.966387756020346,0.24952695097431718,-0.2000047940325369
416.3000000000052,47.055036867344704,0.24812671870779665,-0.1999173030321395
417.2000000000052,47.14198031295741,0.24738878008079143,-0.2002613617146629
418.10000000000525,47.23082904105811,0.24808031785648593,-0.20289011061675177
419.00000000000523,47.31497604803783,0.2463719325674885,-0.20365075639105834
419.90000000000526,47.40447421934923,0.2439842205762386,-0.20545347477191855
420.8000000000053,47.49378518681494,0.24196413988072257,-0.20686140247065854
421.7000000000053,47.580925530682435,0.2409371035479576,-0.20815019547212632
422.6000000000053,47.668875316382696,0.23839383243610418,-0.2081016653870158
423.5000000000053,47.75793310124541,0.2382067289484016,-0.2094641130915429
424.4000000000053,47.84411976055612,0.23572730870079944,-0.21081040975266152
425.30000000000535,47.932633250191365,0.235219159027313,-0.21291760382596792
426.20000000000533,48.020608132090466,0.234923679936742,-0.2134200138229847
427.10000000000537,48.10864066396755,0.23447956597374983,-0.2134200122785268
428.00000000000534,48.19641442043635,0.2351136974507013,-0.21482483554927523
428.9000000000054,48.28462821642521,0.23376717456465956,-0.2160576071873468
429.8000000000054,48.371889699706955,0.2334195882119603,-0.21605994967095832
430.7000000000054,48.460413115916,0.23373873090339792,-0.21738629060511538
431.6000000000054,48.54833800326896,0.23286053191631345,-0.21782977893498767
432.50000000000546,48.63571286287034,0.23433066180726367,-0.2186858054597316
433.40000000000543,48.72345818344601,0.23555849547906488,-0.2200075898705407
434.30000000000547,48.81146172998252,0.23387862773214232,-0.22133024818975144
435.2000000000055,48.900084754713625,0.23236739990627908,-0.22133017001768351
436.1000000000055,48.98747411719855,0.23401308085551623,-0.22263075353670336
437.0000000000055,49.07556516760776,0.2326230451835648,-0.22468849231880483
437.9000000000055,49.16462590167527,0.23172707931025974,-0.22496399469722883
438.8000000000055,49.252436163649705,0.23103471285058574,-0.22594016221112767
439.70000000000556,49.340356671293605,0.23184557765572988,-0.22593155060371473
440.60000000000554,49.427591203885484,0.23293437354133628,-0.22758886964883196
441.50000000000557,49.5163096060659,0.2320010846173401,-0.2276152559946909
442.40000000000555,49.60491241269949,0.22973868121126415,-0.23029504063532702
443.3000000000056,49.693616984331804,0.22941264938700612,-0.23223049944913265
444.2000000000056,49.78206455009211,0.23057516981506232,-0.23330228914325346
445.1000000000056,49.869642266954834,0.23083976644709236,-0.23329958119243566
446.0000000000056,49.95777082277081,0.2304361593798567,-0.23460722573088066
446.90000000000566,50.0464639968883,0.2328893494927533,-0.23595179950240475
447.80000000000564,50.13402548746191,0.23339709265033554,-0.23659023007425883
448.7000000000057,50.22278906659309,0.23381817985488582,-0.2379106121761838
449.6000000000057,50.31082898841933,0.23514574439869151,-0.23821018466805244
450.5000000000057,50.39780678641343,0.23441472905187435,-0.2418925492716606
451.4000000000057,50.487382342654065,0.2352191281865688,-0.24317497318033876
452.3000000000057,50.57670793860863,0.23550951698031794,-0.2431811483645916
453.20000000000573,50.664109210572455,0.23601488936808465,-0.24316552931332414
454.10000000000576,50.752660668035986,0.237247345281363,-0.24268748444111754
455.00000000000574,50.84122621783909,0.2368626783832335,-0.24584063675740486
455.9000000000058,50.93023653554743,0.23971100241855525,-0.24745960516513232
456.80000000000575,51.018319196497266,0.23979391833886132,-0.24879576809657866
457.7000000000058,51.10742068011612,0.2398878291056868,-0.2500947004191163
458.6000000000058,51.19348690988557,0.24183768131903433,-0.25140967636774025
459.5000000000058,51.2830720469951,0.2417528550375723,-0.25270457794867607
460.40000000000583,51.37131290996538,0.2437094639745389,-0.2544127314428817
461.30000000000587,51.45995083134678,0.24341044197962186,-0.2563584572028592
462.20000000000584,51.54979904348842,0.24192365991822143,-0.2563549317540259
463.1000000000059,51.637028626294835,0.24331468775298795,-0.25762204288358426
464.0000000000059,51.72571605262113,0.24180998240901116,-0.2594397336936298
464.9000000000059,51.81448395402729,0.24390567221805687,-0.2615286868267601
465.8000000000059,51.90235516736042,0.24418086457916252,-0.2629392244746418
466.7000000000059,51.9911357916667,0.24527679394281682,-0.26426950282920725
467.60000000000593,52.079213932356545,0.24622521483248935,-0.2668999442979918
468.50000000000597,52.16815186628115,0.2454065080311779,-0.26731914814843183
469.40000000000595,52.25725251720233,0.24351796164065462,-0.26814470931014434
470.300000000006,52.34490873942057,0.24551927849323935,-0.26914049029732867
471.20000000000596,52.43329668806561,0.24525148783654263,-0.27216552530259497
472.100000000006,52.52172899026877,0.24650988415841235,-0.27214970878572897
473.000000000006,52.610217723184306,0.24956953966996753,-0.27480501560074666
473.900000000006,52.698924189642455,0.24906721450446004,-0.2749943256872238
474.80000000000604,52.78500984423063,0.2489072019241089,-0.2749220642639272
475.70000000000607,52.876028379333896,0.24531078353317756,-0.2747716558300102
476.60000000000605,52.96364717611426,0.24644807738718194,-0.27885990391084725
477.5000000000061,53.050830000000666,0.24555531582008364,-0.28018012178591434
478.4000000000061,53.140725599771436,0.24479256915501005,-0.2814982497128802
479.3000000000061,53.22808840162408,0.24617953864442682,-0.2814956916118856
480.2000000000061,53.31769571302309,0.24501653039611548,-0.28413135876679574
481.1000000000061,53.405341347366786,0.2445183290197894,-0.28413746504611614
482.00000000000614,53.49475071112485,0.24791961526752831,-0.2841303223548044
482.9000000000062,53.58239233210823,0.24588672764660044,-0.2855933149472052
483.80000000000615,53.6715761212705,0.24563499883498136,-0.2864300585876767
484.7000000000062,53.75955353731736,0.24185946807683212,-0.2876642562971057
485.60000000000616,53.84815553138383,0.2429409147534282,-0.28775734477809056
486.5000000000062,53.935955680938896,0.24183102726444622,-0.2867647332044365
487.40000000000623,54.023411597176235,0.23921591474229803,-0.28808026023063826
488.3000000000062,54.11360452751537,0.239385915069249,-0.2893868083094975
489.20000000000624,54.202817844773776,0.23908536810984946,-0.29072018865738425
490.1000000000063,54.288784042471704,0.23772956465393624,-0.29072015721002664
491.00000000000625,54.37907886718918,0.2365773727251107,-0.29205806094911857
491.9000000000063,54.468133634721845,0.23483391859868147,-0.29202987566012384
492.8000000000063,54.555925772165686,0.2333642681641743,-0.29202957149050723
493.7000000000063,54.645411759449026,0.2328195870343536,-0.29103988178272777
494.60000000000633,54.73347004664305,0.23373337401240346,-0.2923656067074658
495.5000000000063,54.82252306996722,0.23180144576773193,-0.2933483986569052
496.40000000000634,54.91208042054792,0.23305286949253798,-0.2933502251564537
497.3000000000064,54.99971594437262,0.2361953205013688,-0.2946527925013678
498.20000000000636,55.08824654097667,0.2410125343716077,-0.29235980471427503
499.1000000000064,55.17695671117029,0.24115156423319759,-0.2935352477481219
500.00000000000637,55.26551647533137,0.24115408526765142,-0.2936798257662656
500.9000000000064,55.35435471888419,0.2402135194312017,-0.29436888494479696
501.80000000000643,55.44113226657279,0.23686346417353737,-0.29498992840570315
502.7000000000064,55.53268572071136,0.23749164065315598,-0.2949899280175807
503.60000000000645,55.62133941615035,0.23385540145528874,-0.2949893901862617
504.5000000000065,55.71005582745217,0.2316620753317548,-0.2963100671253418
505.40000000000646,55.798619735810796,0.23078312177938579,-0.2963100914589196
506.3000000000065,55.88662166232596,0.22837970929515947,-0.29755523861832245
507.2000000000065,55.97597590059848,0.22277168939416037,-0.2966396847576296
508.1000000000065,56.06546971226617,0.21942622618717927,-0.2966398590263464
509.00000000000654,56.153814150807555,0.2187204544882159,-0.2962732410207929
509.9000000000065,56.24322686976164,0.21503969380986285,-0.29762982035774677
510.80000000000655,56.33274129710052,0.21250096609442132,-0.297629820000179
511.7000000000066,56.420642939350756,0.20910507215640337,-0.29763008067177443
512.6000000000065,56.510167046831754,0.20358064253049085,-0.29630910470779037
513.5000000000066,56.599732085060765,0.2013473126532328,-0.2989497972865922
514.4000000000066,56.6879546978801,0.19893364966400734,-0.2992530935248574
515.3000000000065,56.77648964176856,0.1961743922215702,-0.2979600483683864
516.2000000000066,56.865366280421206,0.1933132220004456,-0.29796003069417054
517.1000000000066,56.95603827844477,0.18915579731921744,-0.2978516240608129
518.0000000000066,57.044573637903405,0.18539996317293775,-0.2989507425005371
518.9000000000067,57.133541004411434,0.1828452907127229,-0.3012201266768382
519.8000000000067,57.22263697978559,0.17967442892151397,-0.29908769369013033
520.7000000000066,57.31244641885628,0.17685086325195593,-0.298619828414338
521.6000000000067,57.4020136100034,0.17468526253052336,-0.2982694407778368
522.5000000000067,57.49008839321317,0.1745753620561897,-0.298290190648804
523.4000000000067,57.57935517895353,0.1718960943448178,-0.2989542961138132
524.3000000000068,57.66993965741479,0.1696802892586416,-0.3008806830556967
525.2000000000068,57.75981441374498,0.1694956927315403,-0.3009199563424647
526.1000000000067,57.84921101276619,0.16679321347827725,-0.30090455581199604
527.0000000000068,57.938463849064,0.16258425138240806,-0.30224027668992015
527.9000000000068,58.02784352350221,0.15996477449249732,-0.30224503154221916
528.8000000000068,58.11700481475541,0.1562653698804075,-0.30126003513460775
529.7000000000069,58.20644302790013,0.15393736026457427,-0.30126012400650737
530.6000000000068,58.29531190001124,0.14917978911743024,-0.30125445851096266
531.5000000000068,58.38361620113687,0.14848226129107517,-0.30389067146095083
532.4000000000069,58.474014918184075,0.1446054799846922,-0.30388992182724195
533.3000000000069,58.56321145379752,0.14145107576084798,-0.3025699489818452
534.2000000000069,58.65010543393957,0.14115821019419683,-0.30391078378752523
535.100000000007,58.74222248893587,0.14048528804353336,-0.30299972859170454
536.0000000000069,58.831481205224144,0.13760897103954187,-0.302239997427443
536.9000000000069,58.920618927854235,0.13485002120477646,-0.30223996599977276
537.800000000007,59.00889768759215,0.13277915489145026,-0.302239966031864
538.7000000000069,59.099095924870255,0.1335161206847723,-0.30223480176752693
539.600000000007,59.18856125433585,0.1309203245284356,-0.30158822763450077
540.500000000007,59.27681701974061,0.13178680704317602,-0.3019095624800472
541.4000000000069,59.36692414958358,0.13131314553630635,-0.3045277315500998
542.300000000007,59.45624405542404,0.1306401328342039,-0.30363636620979007
543.200000000007,59.54537061074734,0.1324175234476731,-0.30322999846086773
544.100000000007,59.635361869823655,0.13002634543506425,-0.3019379419879078
545.000000000007,59.72387299102875,0.1306586295619683,-0.30191003104123215
545.900000000007,59.81455965229163,0.12983197931259527,-0.303899298570649
546.800000000007,59.90300544369029,0.12964775781617374,-0.30389017596099865
547.7000000000071,59.992770218415096,0.13185838991939325,-0.3038901759898933
548.6000000000071,60.08167229443844,0.13260035971711365,-0.30389184454717766
549.500000000007,60.17180856554386,0.13519336648320143,-0.3025700726511604
550.4000000000071,60.2611283475213,0.13451543960407333,-0.3039034357072037
551.3000000000071,60.35136178171638,0.13590009152749558,-0.30521115373516716
552.2000000000071,60.439154502707126,0.1375211264382157,-0.3060576242632238
553.1000000000072,60.5298621101466,0.1358794530712797,-0.30653215388911725
554.0000000000072,60.61879417046962,0.13585761820538997,-0.3039378929565828
554.9000000000071,60.70905128807523,0.1363653017952887,-0.30516539142150023
555.8000000000072,60.79849414710808,0.13301916669131814,-0.30520993674732155
556.7000000000072,60.88793445618457,0.13723779960922933,-0.3052099343592265
557.6000000000072,60.97708484011932,0.13838785173444282,-0.3038806125581397
558.5000000000073,61.06663034421942,0.13658903414487614,-0.30488080667322626
559.4000000000073,61.155894335207705,0.14075474705785773,-0.3051189239323371
560.3000000000072,61.2453361195493,0.14070624696201978,-0.3065198251217933
561.2000000000073,61.335150508552836,0.13958235402668656,-0.3058665800393996
562.1000000000073,61.425326909563545,0.13808163287827468,-0.3052137101254724
563.0000000000073,61.513812006458004,0.1408821497202453,-0.3052060642671095
563.9000000000073,61.60314286342642,0.13990970628725044,-0.3051917290317028
564.8000000000073,61.693527075449396,0.1408812106983446,-0.30389047581588846
565.7000000000073,61.78227577733509,0.1408060914026415,-0.30520395895366637
566.6000000000073,61.87281449026798,0.14248108805701978,-0.3038897922291568
567.5000000000074,61.9614201924962,0.14274772093686222,-0.3038898261534766
568.4000000000074,62.051125737934626,0.1439727936906044,-0.30389224313869123
569.3000000000073,62.14083097131457,0.14375004160455288,-0.30421982011942816
570.2000000000074,62.2311319519469,0.141562800924865,-0.304472205217142
571.1000000000074,62.319793119084636,0.14241386203993,-0.304219994477287
572.0000000000074,62.40912210380912,0.1422437736155526,-0.3042197642908757
572.9000000000075,62.499848893144765,0.14032213424313345,-0.3055402574770838
573.8000000000075,62.58891681042098,0.13885780075544474,-0.30554019115528597
574.7000000000074,62.678740480268225,0.14001192222483722,-0.30421852816524364
575.6000000000074,62.76925332516876,0.13757833947545833,-0.3015778349476874
576.5000000000075,62.85956452062208,0.13809927195672891,-0.3042323078238858
577.4000000000075,62.94835637562059,0.14114090744178875,-0.3055402695493732
578.3000000000075,63.0382962619757,0.1432417124867003,-0.30685860199873183
579.2000000000075,63.128967046309604,0.14020469106230954,-0.30685997725483816
580.1000000000075,63.21829308552971,0.14125767524965166,-0.3055368717521949
581.0000000000075,63.306397889774566,0.14105673864349066,-0.3068583820786581
581.9000000000076,63.39916430367166,0.1409390932605,-0.30553995577715254
582.8000000000076,63.48830044766433,0.1393241174236586,-0.30553659426036806
583.7000000000075,63.57829445613728,0.14197257021497184,-0.30619990915012485
584.6000000000076,63.66896733439492,0.1413112855871888,-0.3061999262313577
585.5000000000076,63.75764622327738,0.142037705421053,-0.30679127330478906
586.4000000000076,63.84863333170218,0.14206173828129046,-0.30677515631713526
587.3000000000077,63.93773699390937,0.1412496069981851,-0.3081688580057529
588.2000000000077,64.02692092283054,0.14170300792683047,-0.30551246751454064
589.1000000000076,64.11820630763079,0.14445334997873513,-0.3070592244251831
590.0000000000077,64.20842250046867,0.1427359405100852,-0.30758131934459687
590.9000000000077,64.2987440059787,0.14276159439337688,-0.3071800468476047
591.8000000000077,64.3882514281341,0.14287094744758533,-0.306826854489064
592.7000000000077,64.47818919528594,0.145836161887332,-0.30647711863378335
593.6000000000078,64.56819463054023,0.14878679573323872,-0.3075098143145558
594.5000000000077,64.65844550166402,0.14537755967144317,-0.3063679966403501
595.4000000000077,64.74735365161823,0.1516084409176477,-0.3075106091512052
596.3000000000078,64.8384824606913,0.15128696122531723,-0.30750993243894786
597.0000000000077,64.90783704324618,0.15151172362380758,-0.3061592603446477