File: 01_Data/Bamboo_Rug_Bamboo/STA/N2/30K_min/Bamboo_Rug_Bamboo_STA_N2_30KData_220121_R2.csv
##Temp./Â°C,Time/min,DSC/(mW/mg),Mass loss/mg
49.0,10.5110009491493,0.05822121049925644,-0.0019783427883499627
50.20000000000002,10.721370417657301,0.11314443302632471,-0.0015712829234111325
51.400000000000034,10.851397894147514,0.1594729620792611,-0.0026637741450628027
52.60000000000005,10.954326995435997,0.20546650770876795,-0.005216649105622473
53.80000000000007,11.039780507662915,0.240531680980833,-0.006672019475589153
55.000000000000085,11.116620187034677,0.27281359949287326,-0.006158205101223224
56.2000000000001,11.186900034701708,0.30575184934183786,-0.005846500541630384
57.40000000000012,11.252951863226766,0.33520292364981935,-0.005806668143757854
58.600000000000136,11.313996715462654,0.3625042602136972,-0.005838350762293665
59.80000000000015,11.37310152583372,0.3854805076827373,-0.006764665192411812
61.00000000000017,11.430067874961772,0.41173137773289437,-0.00787414576737433
62.20000000000019,11.482732246378195,0.4326705752006841,-0.00794556650571554
63.400000000000205,11.537469926412827,0.45205791238019505,-0.006489629466296165
64.60000000000022,11.588698241852297,0.47376410044957495,-0.008121623953905477
65.80000000000024,11.638650334361921,0.4928839439629121,-0.00826134091206665
67.00000000000026,11.687919976290463,0.5090098778866494,-0.008317086925303308
68.20000000000027,11.736486672659687,0.5238545887723647,-0.0075329443408262975
69.40000000000029,11.783947422811458,0.542134143069423,-0.008129189637047674
70.6000000000003,11.830948628427993,0.5562998714373297,-0.008348549484651357
71.80000000000032,11.876871092733774,0.5682703031550772,-0.008883345028818823
73.00000000000034,11.923097189585082,0.5810137170083205,-0.007861474143122216
74.20000000000036,11.968073579298542,0.5966381120599519,-0.007972304891091575
75.40000000000038,12.013350360805173,0.6080605607294591,-0.00952087497563081
76.60000000000039,12.058108258926712,0.6181828942936626,-0.009712462561048518
77.80000000000041,12.101990465526349,0.6318454753336382,-0.00948076265093789
79.00000000000043,12.146183883587756,0.6409222682546897,-0.009423887458704705
80.20000000000044,12.189409693309745,0.6539785079374459,-0.010254685498071403
81.40000000000046,12.2325332168169,0.6633779507361043,-0.009356684375572577
82.60000000000048,12.275899427597942,0.673193015297419,-0.009045194620365571
83.8000000000005,12.318540623668232,0.684446315740685,-0.011052611227174047
85.00000000000051,12.361005875214204,0.6947417537628104,-0.01112636253493271
86.20000000000053,12.403427502244453,0.7030048979506087,-0.01273671682458577
87.40000000000055,12.445920977877373,0.7128666869513207,-0.013884337406977032
88.60000000000056,12.487180821266167,0.7208270591204601,-0.013036093269057858
89.80000000000058,12.52920636275787,0.7292394420846326,-0.012830091288376977
91.0000000000006,12.570670943965931,0.7376613963629686,-0.013033489338993398
92.20000000000061,12.611880552658944,0.7477999666067583,-0.013009608809738005
93.40000000000063,12.653393023607277,0.7533186810685071,-0.013144885815774998
94.60000000000065,12.694332378290463,0.7621374059377276,-0.013296667519248295
95.80000000000067,12.735946908754066,0.7687612275779541,-0.013341943156831348
97.00000000000068,12.776646516135449,0.7733873232532504,-0.013211333244411705
98.2000000000007,12.817630980361939,0.7807592086619896,-0.014481067458178565
99.40000000000072,12.858346338270925,0.7848291786416144,-0.015790722666007895
100.60000000000073,12.898591991454918,0.7897970707247289,-0.015194568724734125
101.80000000000075,12.939205824111472,0.7963897702616924,-0.015788677358384184
103.00000000000077,12.979940764204551,0.8011099948730699,-0.017091911794095083
104.20000000000078,13.020785311771816,0.8063646943472111,-0.017110238795099875
105.4000000000008,13.061405563442266,0.807289037241385,-0.017216579626550654
106.60000000000082,13.101991719362793,0.8128782951870273,-0.01842450133578133
107.80000000000084,13.142757694658341,0.8126022795232306,-0.018429575064072168
109.00000000000085,13.183050227773128,0.8149572052504586,-0.01846960794905872
110.20000000000087,13.223107843485472,0.8146566247108676,-0.01712477122587952
111.40000000000089,13.263382412923315,0.8183363485667182,-0.01634653251637097
112.6000000000009,13.303851687314971,0.817532828790132,-0.01551325230825018
113.80000000000092,13.344233366382387,0.8185854052671749,-0.016517603961899496
115.00000000000094,13.384276684960685,0.8193275523537704,-0.016735196371606698
116.20000000000095,13.424167084057387,0.8203908806006712,-0.01807353917972243
117.40000000000097,13.464705910723909,0.8197758430637534,-0.020022333797827585
118.60000000000099,13.504192483667914,0.8195809582176462,-0.020269092992283966
119.800000000001,13.544654280633587,0.8184929629401039,-0.02008710320746765
121.00000000000102,13.58442386188631,0.8213421007738679,-0.02039848692257973
122.20000000000104,13.62464581974149,0.822139330559358,-0.020400003242135867
123.40000000000106,13.664662950775508,0.8226415835741759,-0.020402132361519776
124.60000000000107,13.704097499684922,0.8242052025530364,-0.021800936896418932
125.80000000000109,13.743779918326895,0.8259028665635662,-0.021710506051415557
127.00000000000111,13.783426246458474,0.8259232601847446,-0.021715256639704528
128.20000000000113,13.822729737544657,0.8238433216192802,-0.020426351248834074
129.40000000000114,13.86180625082369,0.8263431261927365,-0.020401344179035164
130.60000000000116,13.901562072495246,0.8261815523899465,-0.020580483055469223
131.80000000000118,13.940896400049471,0.829866465992015,-0.021720390136646728
133.0000000000012,13.98010324472212,0.8295871754097962,-0.02171997044432139
134.2000000000012,14.018938667774867,0.8309398585109817,-0.020416240068111158
135.40000000000123,14.058403437189074,0.8348561459096692,-0.02171852800909857
136.60000000000124,14.097136754528677,0.8376939934090277,-0.021720103335606922
137.80000000000126,14.136385163309983,0.8400164397776599,-0.021717669772471027
139.00000000000128,14.17506567680132,0.8422521534588432,-0.02207954372348997
140.2000000000013,14.213943149883109,0.8451698264503966,-0.02206751653166794
141.4000000000013,14.253113221327762,0.8503398196232177,-0.02278589022132671
142.60000000000133,14.29118253227349,0.8522904453846494,-0.023029435599349668
143.80000000000135,14.32981908804895,0.8572843644385586,-0.023030128624776935
145.00000000000136,14.368291766375139,0.8608765970424008,-0.02303013100477269
146.20000000000138,14.406675647391085,0.8656366523288741,-0.023030128777723036
147.4000000000014,14.445505308289171,0.8686816845858072,-0.023029618119080553
148.60000000000142,14.483306351581666,0.8723076969573224,-0.022938373330707584
149.80000000000143,14.521549081209383,0.8752641050738841,-0.024349132186474165
151.00000000000145,14.559794002701764,0.8817665836214774,-0.024350121495134935
152.20000000000147,14.597878340015331,0.885232472597437,-0.02435154527950978
153.40000000000148,14.636052634940427,0.8914395526473351,-0.02417899767782572
154.6000000000015,14.674466489695122,0.8952074307673288,-0.025345802647104954
155.80000000000152,14.711325441746933,0.9005824661881463,-0.025340124528066
157.00000000000153,14.750653473276055,0.9050171146757524,-0.025342143697347552
158.20000000000155,14.788701483476956,0.9092862435892066,-0.02468633314673152
159.40000000000157,14.82637028556728,0.9152696120549939,-0.025530830575434926
160.6000000000016,14.864394604610723,0.9199082008850401,-0.025668826734474237
161.8000000000016,14.901934972444614,0.924538242640359,-0.025669651847201713
163.00000000000162,14.939201727472206,0.9286888717111408,-0.025653303871684408
164.20000000000164,14.977895917708175,0.9335094978270351,-0.026987218740329944
165.40000000000165,15.015575786745721,0.9395237635728371,-0.026944958756390136
166.60000000000167,15.053087660287868,0.9451240071736635,-0.028724071015348684
167.8000000000017,15.090988309946914,0.947714450784856,-0.02863925465155681
169.0000000000017,15.128707765456138,0.9543330564949153,-0.02828141132929929
170.20000000000172,15.165960469395781,0.9610994918972218,-0.02829821621599038
171.40000000000174,15.20393138576938,0.9637021254542515,-0.02941782860676323
172.60000000000176,15.241041163351232,0.9686818369749122,-0.02961913002166039
173.80000000000177,15.278768275528083,0.9744659360054629,-0.029618581495148177
175.0000000000018,15.316448774952478,0.9794568957248416,-0.030966881461953477
176.2000000000018,15.353787597837236,0.9849936087274413,-0.03094100185427351
177.40000000000182,15.391219705569002,0.9882449733456534,-0.030995208706753985
178.60000000000184,15.428666340379353,0.9978114084106713,-0.0312703781606638
179.80000000000186,15.465373635348188,0.9996031516020663,-0.031270153464802775
181.00000000000188,15.50296255109444,1.0034569318566615,-0.031267408262626084
182.2000000000019,15.540202389168678,1.0101821612476067,-0.032565852808623674
183.4000000000019,15.577269076802207,1.0142195051845129,-0.03259097598936744
184.60000000000193,15.614354146784951,1.018749503316475,-0.03394931911539434
185.80000000000194,15.651187039445164,1.0248971313613802,-0.034726475889466535
187.00000000000196,15.688236163829073,1.0302494743818431,-0.035210661440864044
188.20000000000198,15.725343131312497,1.0363185192297386,-0.03521007553377409
189.400000000002,15.76232896955822,1.041848027535416,-0.03521014475793205
190.600000000002,15.7991069185628,1.0458528831234575,-0.03520981445472682
191.80000000000203,15.835846775142233,1.0517225083294182,-0.036497412373162064
193.00000000000205,15.872858136499921,1.0583990156631002,-0.03653457677131744
194.20000000000206,15.909699725887265,1.0657985285406426,-0.03579495624231388
195.40000000000208,15.946563047829802,1.07230423797544,-0.03719351893853862
196.6000000000021,15.98316700622295,1.0771313004378018,-0.03723656870000358
197.80000000000211,16.02016106477922,1.0843804383852902,-0.03849486553611925
199.00000000000213,16.05657625129607,1.0912619912403945,-0.039847578642493
200.20000000000215,16.093124143086957,1.0974171972369082,-0.04055592481350523
201.40000000000217,16.130045011823203,1.10176338149238,-0.0415441450144165
202.60000000000218,16.166642996954835,1.1097734610500043,-0.04251312366154991
203.8000000000022,16.203265640118147,1.1157710647372565,-0.04460503532008353
205.00000000000222,16.238822732582822,1.1228562378618667,-0.04582103102336088
206.20000000000223,16.276334151572918,1.1285376687405435,-0.04659374084018708
207.40000000000225,16.312776241665933,1.1333647746216475,-0.047642176937476854
208.60000000000227,16.349680775461252,1.1410621274908999,-0.04893325675717364
209.80000000000229,16.385469485371445,1.1497030863232953,-0.05007889509779062
211.0000000000023,16.422462844886663,1.154230724298886,-0.051167003751449336
212.20000000000232,16.459459371096873,1.1610858805653694,-0.051569692964451797
213.40000000000234,16.49543873165995,1.166155298837126,-0.05275990546600973
214.60000000000235,16.53159576242441,1.1719534596551964,-0.05382204098840759
215.80000000000237,16.56913951873102,1.1758618317791245,-0.054296287801602006
217.0000000000024,16.605430975772997,1.1848159310420414,-0.05528540975087726
218.2000000000024,16.641815856314626,1.187522743950436,-0.05615106581803886
219.40000000000242,16.678301942034672,1.1936671295241352,-0.05971038719433608
220.60000000000244,16.714666772323223,1.1946427243051057,-0.06157844745967367
221.80000000000246,16.75137577627201,1.202737840224383,-0.06336751111623506
223.00000000000247,16.787769353628924,1.209059706996895,-0.06525688133713281
224.2000000000025,16.824350933785325,1.2093060670093234,-0.06757232347452025
225.4000000000025,16.86069785589577,1.2151608475495945,-0.06857706732787872
226.60000000000252,16.89711554561932,1.2184483586843207,-0.07076813219550804
227.80000000000254,16.9334407230495,1.2254965381226544,-0.07300343057628744
229.00000000000256,16.96985504883912,1.224901178246502,-0.0743593011465391
230.20000000000258,17.006383178604235,1.2290002358658745,-0.07665368317937471
231.4000000000026,17.04269024559533,1.2316489349706439,-0.0794110815065805
232.6000000000026,17.07862593452543,1.2358323431513374,-0.08122678666451666
233.80000000000263,17.11574067327585,1.2378039672971295,-0.08400571129909729
235.00000000000264,17.15179146284299,1.2416969729567002,-0.08578982959961046
236.20000000000266,17.188280545440517,1.2426816370645088,-0.0879705734571603
237.40000000000268,17.22453431197445,1.2453994481151351,-0.09106276369750255
238.6000000000027,17.260761580156203,1.2480792123069575,-0.09385910008791942
239.8000000000027,17.29728945303969,1.254263476745007,-0.09617350067187935
241.00000000000273,17.333518653566546,1.2601854169008988,-0.09804797204234017
242.20000000000275,17.370140995043506,1.262959859310751,-0.10064859405090676
243.40000000000276,17.40627557031502,1.2700971999271404,-0.10399813511059186
244.60000000000278,17.44264846421216,1.2766062378759453,-0.10713927153304237
245.8000000000028,17.47880960703613,1.2833812550987647,-0.11063763550952999
247.0000000000028,17.515280107365765,1.293299548831525,-0.11390535485994935
248.20000000000283,17.551369961865344,1.2984212860319932,-0.11604103249365316
249.40000000000285,17.588030238415165,1.3054142676020122,-0.11976792950637805
250.60000000000286,17.624051700460356,1.3028185475852574,-0.12275865687034493
251.80000000000288,17.66047649042205,1.3001363494802045,-0.12543024104240796
253.0000000000029,17.696541114540807,1.2918132471889057,-0.12857584426502733
254.20000000000292,17.733036258497393,1.2804035255169952,-0.13170229558864932
255.40000000000293,17.76905535980985,1.2734580260019108,-0.13566691511808848
256.600000000003,17.80577862086738,1.265041756121125,-0.14018801086744226
257.80000000000297,17.84098692706229,1.256184115774978,-0.1436677975906182
259.00000000000296,17.877639701925133,1.2536548215491712,-0.1463735787808651
260.200000000003,17.91390814695736,1.2478985957008941,-0.15010043676974494
261.40000000000305,17.950185597374197,1.2460818427408953,-0.15462281974431624
262.60000000000304,17.98664699237417,1.2422444895104197,-0.15990988103375958
263.800000000003,18.022441419044576,1.2397400092588293,-0.1643881139611434
265.00000000000307,18.059050663652087,1.2373711915382926,-0.1697671218251675
266.2000000000031,18.09508308347044,1.2361125751282858,-0.17575168383646034
267.4000000000031,18.131398385413824,1.2340567457056877,-0.18211165372337312
268.6000000000031,18.167695270318905,1.2350784523272806,-0.1878114162268596
269.80000000000314,18.203635460744422,1.2301247754719198,-0.1923931859882959
271.0000000000032,18.24002764915441,1.2270009997254054,-0.19953993706755213
272.2000000000032,18.27580763833377,1.225364115001369,-0.20552486362678613
273.40000000000316,18.312273074307953,1.224134792746084,-0.21247176708879856
274.6000000000032,18.34840300572883,1.2209483135379227,-0.2200271060465009
275.80000000000325,18.38456276989516,1.219205936217445,-0.228449594491686
277.00000000000324,18.42099116594006,1.2149082676162457,-0.235130249438114
278.20000000000323,18.4572451263843,1.2099018868859015,-0.24375838557554896
279.4000000000033,18.493275303484296,1.2078025188304282,-0.25437911961556425
280.6000000000033,18.529633636159183,1.2006326564235075,-0.2633301160136665
281.8000000000033,18.565624471585583,1.1965036160475409,-0.27213302212481594
283.0000000000033,18.60211937628506,1.1903902745068757,-0.28123791314388935
284.20000000000334,18.63817883548942,1.18248786509864,-0.2919916933936113
285.4000000000034,18.67440114805368,1.1770833399541223,-0.30260331858206424
286.6000000000034,18.71064017104239,1.1702484363639594,-0.31432746206787554
287.80000000000337,18.747127156222504,1.161587936929344,-0.32636200559655126
289.0000000000034,18.783082653660006,1.154510946473087,-0.33998228216720694
290.20000000000346,18.819262781548836,1.1460047351034848,-0.35234420297529034
291.40000000000344,18.85564090348331,1.1379063340948097,-0.36622579149110157
292.60000000000343,18.891696082561822,1.1273686056197898,-0.3800355350256992
293.8000000000035,18.92798579116628,1.1174165516568395,-0.3950208173558374
295.0000000000035,18.964391325304774,1.108654390008578,-0.4112164873300621
296.2000000000035,19.00059553384076,1.0998212088133479,-0.4280664621840158
297.4000000000035,19.03671759895346,1.0908438438864325,-0.4443209139753659
298.60000000000355,19.073172370222846,1.078873690814371,-0.4610704829571075
299.8000000000036,19.109408428604056,1.0686729926631557,-0.47803859649033154
301.0000000000036,19.145471291382997,1.056329747081545,-0.49544806268921127
302.20000000000357,19.181880119361566,1.0489810739637555,-0.5131498642728736
303.4000000000036,19.217762016740146,1.0368968749475393,-0.5323145671578344
304.60000000000366,19.25441316577607,1.0244928730781868,-0.5532053666514098
305.80000000000365,19.290721591909698,1.0157521355018058,-0.5736450331022227
307.00000000000364,19.327037493591,1.0044354978960721,-0.5961964167893643
308.2000000000037,19.36318454066871,0.9944253141041599,-0.6180677961853296
309.40000000000373,19.3995061633934,0.9814776737199928,-0.6398930495240069
310.6000000000037,19.43576365966975,0.9732408414589877,-0.6620743498141888
311.8000000000037,19.471901216115636,0.9636635838834249,-0.6843101495631161
313.00000000000375,19.508369676841976,0.9528999516155598,-0.7063543437774511
314.2000000000038,19.544499413288545,0.9483765592011337,-0.7290388909645462
315.4000000000038,19.580915212575537,0.9392723405606287,-0.7525704008391707
316.6000000000038,19.61729644023327,0.9314341101447587,-0.777482181101858
317.8000000000038,19.653729882027072,0.9241311980860274,-0.8026135776770063
319.00000000000387,19.690043162284553,0.9189764275422756,-0.8280887068608909
320.20000000000385,19.726390323723937,0.9125896452029096,-0.8539728720459059
321.40000000000384,19.762708272459612,0.9097449295387947,-0.8803616327882691
322.6000000000039,19.799321025237532,0.9072598782056593,-0.9058923205102318
323.80000000000393,19.835699967270834,0.90094438706337,-0.9304593186225345
325.0000000000039,19.87200058500136,0.9009184042990208,-0.9555841484103755
326.2000000000039,19.908347769855748,0.90133415114718,-0.9799235546365015
327.40000000000396,19.944673758434487,0.9005575529830692,-1.0065194259907062
328.600000000004,19.98118414379473,0.9024647633358605,-1.0325404295831264
329.800000000004,20.018052562657534,0.9039399161474047,-1.0589163397687251
331.000000000004,20.054336403057974,0.9061544399978212,-1.082787119305281
332.200000000004,20.091072144091765,0.9098884375311127,-1.1072799275949259
333.40000000000407,20.127043641000387,0.9159618933226517,-1.1323439360835685
334.60000000000406,20.164022411543783,0.917999229597672,-1.1580461770439583
335.80000000000405,20.20037879084516,0.9238515650293471,-1.1834358469261956
337.0000000000041,20.23721124070827,0.9297510701726235,-1.2084937837890717
338.20000000000414,20.2734919004865,0.9391925632423277,-1.234582866511715
339.4000000000041,20.31051814206344,0.945444444987767,-1.2591825352415156
340.6000000000041,20.346966390304395,0.9551130084837665,-1.2837127771179357
341.80000000000416,20.383747693676053,0.9643108994826042,-1.3096722129884597
343.0000000000042,20.420512166915223,0.9781033074441543,-1.3352239785473583
344.2000000000042,20.456956481845022,0.9883184673419714,-1.359770741172551
345.4000000000042,20.493663729425126,1.002908776794063,-1.3849807100811238
346.60000000000423,20.53055145530189,1.0149200950752237,-1.4114031828008873
347.8000000000043,20.567401985906795,1.0296169572097176,-1.4362300725340145
349.00000000000426,20.60399258378387,1.0457534605083258,-1.463348141988838
350.20000000000425,20.640562697758693,1.0641070852274253,-1.4915949232561623
351.4000000000043,20.67774079887691,1.0793367526280682,-1.5185898465958587
352.60000000000434,20.7145971671093,1.099832134411607,-1.5458106198435666
353.80000000000433,20.751432256191308,1.1211193871815313,-1.5744127408323476
355.0000000000043,20.78823482226574,1.147485407694294,-1.6024159981107715
356.20000000000437,20.825420981261782,1.1715747772227796,-1.6322481211668745
357.4000000000044,20.862291073663002,1.1996946627248708,-1.6622985181468035
358.6000000000044,20.899497442878417,1.2300458287505813,-1.6938412685189017
359.8000000000044,20.935989459804365,1.2609716030222708,-1.7269551985362614
361.00000000000443,20.97277968621031,1.294059481442043,-1.7609520899193596
362.2000000000045,21.009969730813946,1.3299218445466956,-1.797893464398586
363.40000000000447,21.04679680655427,1.367506609529971,-1.8356809417276976
364.60000000000446,21.083941118076176,1.4100134385021785,-1.8751883319787277
365.8000000000045,21.12083810779664,1.4499231403246378,-1.9171690797646082
367.00000000000455,21.157911738549455,1.4930037228965898,-1.9608551311736648
368.20000000000454,21.19515947931571,1.534977897755504,-2.0071042551244327
369.4000000000045,21.232056925043263,1.5701906161073278,-2.054278725568018
370.60000000000457,21.26907706742832,1.6034870578676572,-2.104066582877337
371.8000000000046,21.306192456116996,1.621496434643015,-2.1565516994972525
373.0000000000046,21.34316040156819,1.6258013136292557,-2.211207439788173
374.2000000000046,21.380602381553764,1.6104026792402657,-2.2670678958684682
375.40000000000464,21.417644724547,1.57208824856676,-2.324264186730941
376.6000000000047,21.454516369377316,1.5094359283477727,-2.380004863129428
377.8000000000047,21.491706112126668,1.4244234298569334,-2.4365894334437574
379.00000000000466,21.528921297761947,1.3182556968857457,-2.4887273711279967
380.2000000000047,21.565847293629695,1.2001501387435443,-2.5368100497683375
381.40000000000475,21.603076721322306,1.0753854528120306,-2.580786935394394
382.60000000000474,21.64011790954889,0.953202904329989,-2.6201861768558263
383.80000000000473,21.677077322484376,0.8378503710559702,-2.6531231804172837
385.0000000000048,21.714145212467567,0.7368678898862393,-2.6809400103499663
386.2000000000048,21.750937969282056,0.6437724657339718,-2.7043055341721143
387.4000000000048,21.78737663018986,0.5674520714370719,-2.7238381617536502
388.6000000000048,21.825477189922555,0.4995418135179437,-2.740344722363903
389.80000000000484,21.862192357681383,0.44771982454358583,-2.7544064814056544
391.0000000000049,21.898354429578138,0.3995680470385945,-2.7658026140778373
392.2000000000049,21.936445269904738,0.3610478839799989,-2.777294105556248
393.40000000000487,21.973496237186776,0.3268604577458367,-2.7863328106319147
394.6000000000049,22.0104859419284,0.2998021461113092,-2.7938089914147777
395.80000000000496,22.04747009551425,0.2743833769066153,-2.8011305003650455
397.00000000000495,22.08485606650046,0.25319927616025195,-2.807138459675915
398.20000000000493,22.121876545991782,0.23327227230192293,-2.8119077787832563
399.400000000005,22.15901440730437,0.21470327786039567,-2.817930467744353
400.600000000005,22.196164277705535,0.20084495447016204,-2.8235429466527555
401.800000000005,22.233146487284074,0.18559805797697715,-2.828121343541951
403.000000000005,22.270497362540937,0.1698433999275255,-2.8345228820666435
404.20000000000505,22.307862640016527,0.15692338954571072,-2.838893753793105
405.4000000000051,22.345221596703524,0.145627637026587,-2.8427777164693553
406.6000000000051,22.38261624418948,0.1322873282720467,-2.8475260907983126
407.80000000000507,22.41969525332184,0.12032348739702248,-2.8521455180157096
409.0000000000051,22.456904043301527,0.11180434166438369,-2.8564674245118793
410.20000000000516,22.494152270463136,0.09970494849575262,-2.8606917903653013
411.40000000000515,22.53169760836692,0.0877474820108104,-2.8649454179528253
412.60000000000514,22.56896054351307,0.07826352432555983,-2.8694674516805487
413.8000000000052,22.606037694275997,0.0707318530957941,-2.873137509670813
415.00000000000523,22.64349965520566,0.059978293972181795,-2.877151867516278
416.2000000000052,22.681040500910935,0.05158477717930876,-2.8822178492200647
417.4000000000052,22.718828215602034,0.04144227553051438,-2.88635204736813
418.60000000000525,22.755885048497653,0.034076964204888816,-2.8904674107289217
419.8000000000053,22.79330374034663,0.023729478074998145,-2.894154596530583
421.0000000000053,22.830620582496323,0.01848919075906763,-2.8989483693666376
422.2000000000053,22.868441919201818,0.008735257755902781,-2.902456386013476
423.4000000000053,22.905678966217156,0.0009227061498657818,-2.9040997737846643
424.60000000000537,22.943359212763117,-0.005588960281464717,-2.9085356906610986
425.80000000000535,22.980679081431123,-0.011842839423702234,-2.911655453887187
427.00000000000534,23.01815634205574,-0.02068214300961757,-2.914253771853869
428.2000000000054,23.05609376224526,-0.024980306934802465,-2.9180066750629914
429.40000000000543,23.09354556770319,-0.029500194530139856,-2.9228526430703416
430.6000000000054,23.130941623973783,-0.03574679496954736,-2.925311918925445
431.8000000000054,23.168702598566803,-0.04109046098690183,-2.9277273191676265
433.00000000000546,23.20628766107421,-0.04784255453827657,-2.9316773098037414
434.2000000000055,23.243666095264714,-0.04948973330674944,-2.93586921266857
435.4000000000055,23.281460870239922,-0.05399265105130224,-2.937453539680103
436.6000000000055,23.319264923076645,-0.05657400830510495,-2.9403679964845324
437.8000000000055,23.357041582137995,-0.06237895605345001,-2.9437331023109623
439.00000000000557,23.39452754645732,-0.06180146298338496,-2.9476450315006693
440.20000000000556,23.432321174900025,-0.06758414858994244,-2.950976293652328
441.40000000000555,23.469815104829262,-0.06725645324975904,-2.9529785926455707
442.6000000000056,23.507822900540944,-0.07040601151268677,-2.9563404244260783
443.80000000000564,23.545292259947363,-0.07082338626979601,-2.9598688995619242
445.0000000000056,23.583214551671663,-0.07037492681734014,-2.9635097990690813
446.2000000000056,23.620653460182325,-0.07197904358601437,-2.9661328688816604
447.40000000000566,23.65872237104452,-0.06785400608405978,-2.9685178373435708
448.6000000000057,23.696307820478307,-0.07067597176771545,-2.97173108056119
449.8000000000057,23.734228374447486,-0.0683342600986725,-2.9738643053036284
451.0000000000057,23.77231193728015,-0.06673443821502967,-2.9784373526656056
452.20000000000573,23.809866703494187,-0.06581972967330363,-2.9820018576519836
453.4000000000058,23.847767040654002,-0.06252476141213026,-2.984285864890902
454.60000000000576,23.88583356306216,-0.06165102751128493,-2.9861621235242124
455.80000000000575,23.923757632715056,-0.057601007390407855,-2.9914376351480683
457.0000000000058,23.961506559994106,-0.05420284879553683,-2.9953991246400484
458.20000000000584,23.999543578875496,-0.048633222200835435,-2.997877654892875
459.40000000000583,24.03743238364572,-0.04925598695852096,-3.0003822577898145
460.6000000000058,24.07541637972058,-0.04290513623874981,-3.00165974626139
461.80000000000587,24.11323295687751,-0.03943851726843439,-3.003863918425928
463.0000000000059,24.15100171980584,-0.035705473284871614,-3.0070690564388767
464.2000000000059,24.189169681847034,-0.0325962319555706,-3.0090918823827195
465.4000000000059,24.22737775514934,-0.026333454523616018,-3.0108515105288745
466.60000000000593,24.264957484138694,-0.023531267399559352,-3.0124006091095685
467.800000000006,24.302991545575257,-0.018273889437763202,-3.0150010953547604
469.00000000000597,24.341008780086216,-0.013272364632997302,-3.0183427097646325
470.20000000000596,24.379106771419558,-0.011021777595396687,-3.0220776872935264
471.400000000006,24.417110662370803,-0.005019109733350291,-3.0239017251571356
472.60000000000605,24.455335461160544,-0.0005844146796809557,-3.0241031339559568
473.80000000000604,24.49320108422511,0.0020237635239153118,-3.0258682982765306
475.000000000006,24.531195802695454,0.004279185870910807,-3.0300356768843804
476.20000000000607,24.569268250597002,0.010056243073560456,-3.0319482996308063
477.4000000000061,24.607365268004475,0.014388715339712643,-3.0340456450389723
478.6000000000061,24.6455390006091,0.019550607799989184,-3.0368614031092376
479.8000000000061,24.6838367051433,0.024633814568857826,-3.03888428399998
481.00000000000614,24.72192626536058,0.027267548318542056,-3.0410291473795423
482.2000000000062,24.760126349705775,0.029608914358138172,-3.043863773951739
483.4000000000062,24.798252020818246,0.03185191227309536,-3.0445485055835473
484.60000000000616,24.83659156099523,0.03489938300065942,-3.047159056078765
485.8000000000062,24.87488046772889,0.036829370793544314,-3.0499062471525535
487.00000000000625,24.912812178403826,0.041178296870630016,-3.0514139892809578
488.20000000000624,24.95146121652541,0.043851465777921206,-3.054445764866046
489.40000000000623,24.989526219741112,0.04423836815939297,-3.056302817511469
490.6000000000063,25.027792816491413,0.046477346652603835,-3.0568374679542325
491.8000000000063,25.06604810499718,0.048204013975190696,-3.058941792453138
493.0000000000063,25.104503373327287,0.049196970776830495,-3.0603370635792366
494.2000000000063,25.142214177473278,0.05303059150862821,-3.062891381804385
495.40000000000634,25.18094321900254,0.054883048696793724,-3.0640251607746074
496.6000000000064,25.219331746062227,0.05241678955647111,-3.06616577248585
497.8000000000064,25.257815957164468,0.058117937318122426,-3.067686191019729
499.00000000000637,25.295933301898575,0.05856998941531355,-3.068964236278646
500.2000000000064,25.334520430546643,0.06118545619251847,-3.0705962723171023
501.40000000000646,25.37258702476018,0.05954833704616025,-3.0721291477706076
502.60000000000645,25.411503004928864,0.06385056194458905,-3.07413471756354
503.80000000000643,25.449610219905267,0.05969503761024164,-3.0767198355107017
505.0000000000065,25.48834211248726,0.06243987751847291,-3.0779543051033253
506.2000000000065,25.52631758467008,0.06420503577526304,-3.0787164819000785
507.4000000000065,25.5648506750876,0.06441162168492998,-3.0793957937693746
508.6000000000065,25.603632726806726,0.06843455849160485,-3.08174577847295
509.80000000000655,25.641970756405538,0.06562650473018117,-3.0830037843498803
511.0000000000066,25.680505804657727,0.06660982126149184,-3.084165861679074
512.2000000000066,25.71897823177506,0.06597725493594897,-3.086325008748044
513.4000000000066,25.757377875253827,0.06677368049039156,-3.08759299863095
514.6000000000066,25.796312004691444,0.06735950396507784,-3.088623880140486
515.8000000000067,25.834631863535165,0.07035928404376479,-3.0901398011902477
517.0000000000066,25.873165337535863,0.07020411174431618,-3.0920890759555215
518.2000000000066,25.911811639276216,0.06977909568473928,-3.093909851117587
519.4000000000067,25.950480049054978,0.07015789467501832,-3.0951526015144744
520.6000000000067,25.98887926714476,0.06973535927664365,-3.0966656799872783
521.8000000000068,26.027517978541756,0.06662387567335193,-3.0981147670001308
523.0000000000067,26.06624029097272,0.06975521653227923,-3.099593731455719
524.2000000000068,26.104623601077268,0.06844371295316143,-3.1010943477627118
525.4000000000068,26.142804295348807,0.06718885859877677,-3.102330968122725
526.6000000000067,26.1821134935697,0.0662416318111061,-3.103264455629337
527.8000000000068,26.220690039030558,0.06591433390925228,-3.1046917551500632
529.0000000000068,26.2592993746863,0.06748869743085506,-3.1075257117444264
530.2000000000069,26.29821849702823,0.06825515694452977,-3.1088065229300814
531.4000000000069,26.33665940739891,0.06461943092369737,-3.1092827370140923
532.6000000000068,26.375008565066267,0.06781450976667558,-3.1098855521580666
533.8000000000069,26.414250912607475,0.0675489008145993,-3.110141894911389
535.0000000000069,26.45279732462097,0.06635230878743181,-3.1114538671735814
536.2000000000069,26.491713510639784,0.06594953882338062,-3.1141386985990653
537.4000000000069,26.53048440371023,0.06795194765469659,-3.115653393034548
538.600000000007,26.56965108833639,0.0673987760489958,-3.1169655557125338
539.800000000007,26.608361230439257,0.06986354031179332,-3.1169293886320815
541.000000000007,26.647031464978603,0.06606215986377673,-3.1182610574187626
542.200000000007,26.68581359085584,0.07078404300833308,-3.1189621444011983
543.400000000007,26.724537333055377,0.07006086380856824,-3.119426832182532
544.6000000000071,26.763269434866576,0.06819999884780059,-3.120262130478894
545.800000000007,26.8020593663111,0.07332574205715758,-3.121578799927512
547.000000000007,26.84106833368363,0.06908152924034261,-3.1229835686332166
548.2000000000071,26.87981099956742,0.07155184063930164,-3.1237860680121603
549.4000000000071,26.919236699338086,0.07182826447024193,-3.1250721889066657
550.6000000000072,26.957803014541955,0.07396030805894172,-3.125606809792896
551.8000000000071,26.99650159222655,0.07366225029931317,-3.1262873658117503
553.0000000000072,27.03547781020953,0.0759140043306552,-3.1276468167441394
554.2000000000072,27.074307601088286,0.07745595518438009,-3.1290107583037985
555.4000000000071,27.113019005912705,0.07731057396441132,-3.1303919730475176
556.6000000000072,27.15207218680419,0.07769909338427827,-3.13294854176985
557.8000000000072,27.19098603293984,0.0813804410056056,-3.1338536961303785
559.0000000000073,27.229900001136993,0.08030908300702921,-3.133840069750338
560.2000000000073,27.268809359946914,0.08085429591035065,-3.133833245131911
561.4000000000073,27.307495665518218,0.08132707858258215,-3.13469232118707
562.6000000000073,27.346676004936832,0.0811249124337361,-3.1354052486040915
563.8000000000073,27.38565860903643,0.08054731990763808,-3.1368238351484403
565.0000000000073,27.424552592656234,0.07787010566513874,-3.138139124482223
566.2000000000073,27.463507890575926,0.07556601927389095,-3.1397493068735205
567.4000000000074,27.502731008872235,0.0766307153068333,-3.141159453067705
568.6000000000074,27.541764300901153,0.07653967646528481,-3.1425297076923835
569.8000000000075,27.5803565670458,0.07758917691716882,-3.143870667894504
571.0000000000074,27.619735649044795,0.07579110707988357,-3.1438397795025192
572.2000000000074,27.658569274146885,0.07491980486667815,-3.1451383868213103
573.4000000000075,27.697647515775326,0.07325952341928321,-3.145105256257236
574.6000000000074,27.73668581516628,0.07131883753073764,-3.146450154092566
575.8000000000075,27.776153347909478,0.06915332484255621,-3.1476313379880656
577.0000000000075,27.815010164715595,0.07059088295118743,-3.1467474340975548
578.2000000000075,27.8539502922414,0.0654400975908942,-3.1478288913759247
579.4000000000076,27.893050115083824,0.06477447807834147,-3.1492395443989545
580.6000000000075,27.932043993020294,0.06474276368862575,-3.1505320850746683
581.8000000000076,27.970870610517093,0.06073784354229983,-3.151834692858542
583.0000000000076,28.009952628900628,0.061387083724637304,-3.1518318791318016
584.2000000000075,28.049237206898866,0.057945798532069936,-3.1531421735077716
585.4000000000076,28.0880213268991,0.0585065097889208,-3.1531404564272556
586.6000000000076,28.12738533857676,0.056867154273590126,-3.1536517619305
587.8000000000077,28.166475590019637,0.0570341116192401,-3.154463807626077
589.0000000000077,28.205721260315965,0.05298861585020642,-3.15584392049016
590.2000000000077,28.245096396758335,0.04986574559203816,-3.1556947116302667
591.4000000000077,28.283889095868442,0.048020983722809385,-3.15710111837292
592.6000000000078,28.322822739762973,0.047611939274373016,-3.1571637479646864
593.8000000000077,28.362137139175292,0.04423178125443794,-3.157098929197068
595.0000000000077,28.401326593090825,0.03912415159833493,-3.158507574059234
596.2000000000078,28.440345703775723,0.04245463750496414,-3.161198206376161
597.4000000000078,28.479583820906093,0.03749243067643149,-3.1615167995151063
598.6000000000079,28.51897205851835,0.03660239866060011,-3.1624696326582153
599.8000000000078,28.55795665294722,0.0343112037722586,-3.163782082102296
601.0000000000078,28.597287983572745,0.029023052724198806,-3.16511887801461
602.2000000000079,28.636636058034775,0.02923425424930226,-3.1651031945578665
603.4000000000078,28.675758606223518,0.02791251941874151,-3.165134005783365
604.6000000000079,28.715285777371612,0.027145726725350983,-3.165443436601433
605.8000000000079,28.754536454677698,0.02285543106409138,-3.1668342948006343
607.000000000008,28.793767290147947,0.02099033598615252,-3.167838219294052
608.200000000008,28.83327141868794,0.01940338397249164,-3.1688321280726566
609.4000000000079,28.872672029370808,0.015723318891170734,-3.170476113206945
610.600000000008,28.911968917926536,0.015199584295821467,-3.170470389595992
611.800000000008,28.951492092377418,0.012401254006088713,-3.1705681607398093
613.000000000008,28.990673642592256,0.011635732684727396,-3.1717906212781513
614.200000000008,29.03043840319417,0.010810122990781101,-3.172875863719062
615.400000000008,29.06990652984955,0.008058072869141064,-3.1731089455961277
616.6000000000081,29.109301175791153,0.007218528699512561,-3.1741008810473264
617.8000000000081,29.148627512177164,0.003880647871634224,-3.1743908522200983
619.0000000000081,29.18784688915021,0.0023675239767935174,-3.1757384937034896
620.2000000000081,29.227677441502134,-0.0013653168595215703,-3.17487217170631
621.4000000000082,29.267026706415322,-0.0017481466891249298,-3.1757743345009635
622.6000000000081,29.306471596451747,-0.003562226224436582,-3.1767117252555206
623.8000000000081,29.34582030685983,-0.005621008873026412,-3.1770868288492102
625.0000000000082,29.385322571897753,-0.009557981830159878,-3.1776517315106125
626.2000000000082,29.424688470929052,-0.006956144853267787,-3.1784590631728173
627.4000000000083,29.464175462765457,-0.00896195294207125,-3.179698209244499
628.6000000000082,29.503673202394232,-0.015518841108535852,-3.18110894621353
629.8000000000083,29.54318299172394,-0.013735899253874084,-3.181040486550768
631.0000000000083,29.58259468511298,-0.01808461564634367,-3.182476903306294
632.2000000000082,29.62223543647943,-0.022359445509377185,-3.1838669704716636
633.4000000000083,29.66152633510874,-0.019412423440622106,-3.1838610190864935
634.6000000000083,29.70113544855788,-0.0231788827449666,-3.1852585854504962
635.8000000000084,29.740599286370035,-0.024996232818350617,-3.1851808429264192
637.0000000000084,29.780097641887068,-0.02466055163528491,-3.1865326018561184
638.2000000000083,29.81983429088667,-0.028412669401326696,-3.1864936291816357
639.4000000000084,29.85967132322421,-0.02799764293644058,-3.187811624016792
640.6000000000084,29.89880270652491,-0.03214622448144988,-3.1878098093720206
641.8000000000084,29.93833729458331,-0.029638376335123784,-3.187808307188691
643.0000000000084,29.977899166649305,-0.03290457422784687,-3.1890826861250963
644.2000000000085,30.01744264909468,-0.03634124820995588,-3.1891296947731855
645.4000000000085,30.057185428758174,-0.03358447434721956,-3.1891227369283968
646.6000000000085,30.096484759941532,-0.03517883465840743,-3.187783823320514
647.8000000000085,30.13639990309952,-0.03866099810077639,-3.1891239142086922
649.0000000000085,30.17594437593983,-0.03654798701550588,-3.1891348646703506
650.2000000000086,30.215594649986542,-0.04161097502529243,-3.190481242322345
651.4000000000085,30.255209795805786,-0.041814380512464666,-3.1904420093028865
652.6000000000085,30.294697221601577,-0.04461015246351474,-3.1898928177446946
653.8000000000086,30.334468704306857,-0.046059547327382155,-3.1909521304097788
655.0000000000086,30.373946039026727,-0.04764267527881394,-3.192697369059647
656.2000000000087,30.413699982327593,-0.04961982869810999,-3.1926870866870383
657.4000000000086,30.45319714071562,-0.048476364498783564,-3.192826940758257
658.6000000000087,30.49310558653842,-0.04854290658659988,-3.1939491593525
659.8000000000087,30.53250699946868,-0.05208921411919576,-3.195246541279879
661.0000000000086,30.57223123826134,-0.05227244502551054,-3.194268703166565
662.2000000000087,30.611815548554656,-0.05496688198675681,-3.1955884221482718
663.4000000000087,30.6512267963995,-0.05710914042805415,-3.1955898449022375
664.6000000000088,30.691037220921334,-0.05847957474035237,-3.195589757257674
665.8000000000088,30.730795314410717,-0.06076737879464922,-3.1955742704205377
667.0000000000088,30.77012399527634,-0.05951400048989486,-3.196905347741038
668.2000000000088,30.81018420129357,-0.060617038444795046,-3.1983685428514814
669.4000000000088,30.84983837460917,-0.06349094514704001,-3.1995450177150073
670.6000000000088,30.889624789548815,-0.0659424812563878,-3.2008617239741377
671.8000000000088,30.92923621959197,-0.06320706831652823,-3.2008599758503395
673.0000000000089,30.968731632005785,-0.06562506812435176,-3.200858335950726
674.2000000000089,31.008614062544243,-0.06790747916620132,-3.202177299843025
675.400000000009,31.04829590684863,-0.06686486456462326,-3.2024462430178953
676.6000000000089,31.08757359847029,-0.06921741874053078,-3.202411142027107
677.8000000000089,31.1274884508311,-0.07337430441578663,-3.2024595679611947
679.000000000009,31.167232396742005,-0.07463769013219235,-3.203814945158923
680.2000000000089,31.207079703126393,-0.07741880672869694,-3.2038200663197554
681.400000000009,31.246839842659874,-0.07869521219704012,-3.2038202169569843
682.600000000009,31.286799188571365,-0.08368369333365866,-3.2038442607248463
683.800000000009,31.326493897144037,-0.08450670901661006,-3.2051433302290624
685.0000000000091,31.366028626865578,-0.08472970370495947,-3.2051473008360922
686.200000000009,31.405823961505078,-0.08868723200561268,-3.2038378055997057
687.4000000000091,31.44525187833079,-0.0948855030663176,-3.20383384405704
688.6000000000091,31.485184102953497,-0.09249113770393924,-3.2053095181758566
689.800000000009,31.525038807565615,-0.09790698540098663,-3.206602586357837
691.0000000000091,31.56466656919791,-0.09853195645906654,-3.2068603172042884
692.2000000000091,31.604441725770556,-0.10418849121231455,-3.2079117461109146
693.4000000000092,31.644255988423556,-0.10211999607583078,-3.2064264948116197
694.6000000000092,31.683953041228094,-0.10434918632197077,-3.2062407901175645
695.8000000000092,31.723834869995088,-0.10870228330497111,-3.2062398009398185
697.0000000000092,31.763599996281954,-0.11046088528579201,-3.2062334465502658
698.2000000000093,31.803521753112555,-0.11397972631079867,-3.207514932607334
699.4000000000092,31.84324625643169,-0.11771961016456078,-3.2059375307014073
700.6000000000092,31.883009765000605,-0.12094450877888763,-3.2060195246357495
701.8000000000093,31.922971639402174,-0.12148041243269869,-3.207676650367694
703.0000000000093,31.96271373792879,-0.12829710675961747,-3.2087607137934437
704.2000000000094,32.002341975181885,-0.12867382097574387,-3.2091544639018066
705.4000000000093,32.042065371872376,-0.13087260184446414,-3.211556212900017
706.6000000000093,32.08207975853699,-0.13240450595884834,-3.2114960972495377
707.8000000000094,32.122036286678274,-0.1346268538703561,-3.2126629694700934
709.0000000000093,32.161826316883555,-0.13414754598335898,-3.2128098394291564
710.2000000000094,32.20177256058283,-0.1407425400032638,-3.212809977304982
711.4000000000094,32.24156155849022,-0.14059830547695995,-3.212809978172257
712.6000000000095,32.28145758245098,-0.14669455386306662,-3.2128100105154465
713.8000000000095,32.321398381382686,-0.14723409926618602,-3.2128160882172243
715.0000000000094,32.36097182015182,-0.1531837978513808,-3.214172557871774
716.2000000000095,32.400597943379616,-0.1516587198391366,-3.212924835319237
717.4000000000095,32.44107955015656,-0.15310670774360347,-3.2128199808028906
718.6000000000095,32.48080695495007,-0.15808015289531818,-3.2128175421376506
719.8000000000095,32.52087868265031,-0.15731061061182006,-3.2139357630208156
721.0000000000095,32.56092593196138,-0.16117973762154225,-3.214139997862681
722.2000000000096,32.600738503103464,-0.16396205102961758,-3.214140405467015
723.4000000000096,32.640662963495565,-0.16732274352637955,-3.2142055017473012
724.6000000000096,32.6802324415752,-0.1665791686784397,-3.215113580458822
725.8000000000096,32.720352624826596,-0.16820420033866545,-3.2154511286613756
727.0000000000097,32.76053190298131,-0.17234494007619805,-3.2166424849862656
728.2000000000096,32.800749355430746,-0.1736553728754502,-3.2154468924700454
729.4000000000096,32.84028234066522,-0.17570797919195247,-3.2165472184852426
730.6000000000097,32.879865701266134,-0.18031949426857752,-3.218080060498665
731.8000000000097,32.920023525520755,-0.17960686493840372,-3.2180808199367896
733.0000000000098,32.95978725911622,-0.18359581512969392,-3.217998426925443
734.2000000000097,32.99993286241429,-0.18374941043550042,-3.2180794146563434
735.4000000000098,33.03979417642067,-0.1836631127753603,-3.218082733447165
736.6000000000098,33.07989850954717,-0.18652120107205583,-3.21940217735124
737.8000000000097,33.12017465872599,-0.1881516138317405,-3.219400079444996
739.0000000000098,33.1601645383444,-0.1927636977874463,-3.2194000785092136
740.2000000000098,33.199938620283476,-0.19782817739939285,-3.2194020127946654
741.4000000000099,33.23979404815181,-0.20202994317692502,-3.2207262720271657
742.6000000000099,33.280211446215446,-0.20073774232851527,-3.220773581678077
743.8000000000098,33.32005995077745,-0.20233371478648365,-3.220456377009195
745.0000000000099,33.360509854753666,-0.20430122297664077,-3.221368602697196
746.2000000000099,33.40039073894846,-0.20335908625649068,-3.221343866984663
747.4000000000099,33.44060312704287,-0.20524605463495948,-3.2226893878368887
748.6000000000099,33.48061768024794,-0.2062098430482182,-3.2226889728736126
749.80000000001,33.52087443046823,-0.2072527964766686,-3.2223495577266292
751.00000000001,33.560668772424705,-0.21098833760376534,-3.222041224303063
752.20000000001,33.601234825309916,-0.21245676308166583,-3.221999706585378
753.40000000001,33.641600135483124,-0.21157633043697688,-3.2233484898335973
754.60000000001,33.6812894629067,-0.21836330969497686,-3.2233502182873313
755.8000000000101,33.72168013473233,-0.2192022736221344,-3.2234556899220803
757.00000000001,33.761489378359094,-0.21744969390801616,-3.2247738400508332
758.20000000001,33.801915987236974,-0.21399138342475954,-3.223351327852685
759.4000000000101,33.842366783440355,-0.2147483984118428,-3.2233088835982717
760.6000000000101,33.88220107768699,-0.22101230464582278,-3.2254726502962847
761.8000000000102,33.92248102007729,-0.2235916020191291,-3.225649321744096
763.0000000000101,33.96236555437523,-0.2235650835268994,-3.2256500198811646
764.2000000000102,34.00293299712708,-0.22460453490271037,-3.2256505212981037
765.4000000000102,34.043213222617624,-0.22513788642245647,-3.2257779466904655
766.6000000000101,34.083226460314044,-0.2244668103016143,-3.225990589168794
767.8000000000102,34.12355950944285,-0.22600341322079665,-3.2273506227204107
769.0000000000102,34.163988709846876,-0.22913553957628485,-3.227284470490381
770.2000000000103,34.20397032296679,-0.22806310255530882,-3.2262435716379207
771.4000000000103,34.244355267358216,-0.2310351385773899,-3.2251682676190003
772.6000000000103,34.28478747806233,-0.2292247561329228,-3.2273602406191007
773.8000000000103,34.324859023459446,-0.2316935950635557,-3.2283301482732822
775.0000000000103,34.36512106716458,-0.23229836240264756,-3.228731650349415
776.2000000000103,34.40570534548594,-0.2287672422947451,-3.230078149743112
777.4000000000103,34.44621384656616,-0.23144932435884824,-3.2300402363892586
778.6000000000104,34.486713968088125,-0.23421112192023275,-3.230040061106294
779.8000000000104,34.52677571391951,-0.23310023077428177,-3.2300381827011653
781.0000000000105,34.56709615295861,-0.23884119369264756,-3.2287224012823854
782.2000000000104,34.60727138283613,-0.23669650035161194,-3.2287200858644534
783.4000000000104,34.64799781391079,-0.23537778983846813,-3.2287211121878805
784.6000000000105,34.68846457042952,-0.2384993186520834,-3.2296476122409565
785.8000000000104,34.72860711641483,-0.24041261498474675,-3.2300301320632996
787.0000000000105,34.769068805513385,-0.23998572402387452,-3.2300300970644216
788.2000000000105,34.808721487041424,-0.23886313468756226,-3.2300301247744385
789.4000000000106,34.84985135549341,-0.23503744830251305,-3.2304203179066224
790.6000000000106,34.890325188758816,-0.24065810662173126,-3.231348080632412
791.8000000000105,34.93043981757364,-0.23723884614816004,-3.2321166821235336
793.0000000000106,34.97135204862085,-0.2389316462714417,-3.2326692926325347