File: 01_Data/Bamboo_Rug_Bamboo/STA/N2/30K_min/Bamboo_Rug_Bamboo_STA_N2_30KData_220121_R3.csv
##Temp./Â°C,Time/min,DSC/(mW/mg),Mass loss/mg
49.0,10.46844190530169,0.0233949518355534,-0.00021052725166192943
50.20000000000002,10.704645219935296,0.09582802117710654,0.001342125293595231
51.400000000000034,10.838397274178151,0.1512653034408904,-0.0006722371207974476
52.60000000000005,10.943016150429333,0.19508826870231344,0.0009304368533706864
53.80000000000007,11.031728342770252,0.23746456270881022,0.0025997957185044385
55.000000000000085,11.109299536503498,0.2751079314892823,0.002837388551411024
56.2000000000001,11.180871833322703,0.30998385840676207,0.003190572259727631
57.40000000000012,11.247059280899261,0.34150363493219393,0.001863334145135731
58.600000000000136,11.308619996199551,0.3687377187308704,0.003882352570379055
59.80000000000015,11.36771734296536,0.39381410200673,0.003574935133387136
61.00000000000017,11.424984425445684,0.42103712039187746,0.004407501214709342
62.20000000000019,11.479968018226756,0.44358576696058616,0.0035897698775793074
63.400000000000205,11.533244558735708,0.4650940321490732,0.0024330282811781956
64.60000000000022,11.584350867628826,0.48623044648101854,0.0027540412671553938
65.80000000000024,11.634722888075217,0.5051560023988496,0.003689852100794866
67.00000000000026,11.684189774453756,0.5243485273960414,0.0038598535553697744
68.20000000000027,11.732723743187494,0.5415108167298384,0.003214071031558241
69.40000000000029,11.78075743767666,0.5583124511321448,0.0027897301283372755
70.6000000000003,11.827673814448403,0.5713145862035929,0.0028341961621878298
71.80000000000032,11.873843044169154,0.5861097436175758,0.002073410865190972
73.00000000000034,11.919775171736184,0.5994508524435941,0.002487170585729004
74.20000000000036,11.965482298268299,0.6156406566226508,0.00297357511972951
75.40000000000038,12.008578242466989,0.6256328875800519,0.004630770937852802
76.60000000000039,12.05484076763481,0.6397670625433407,0.004303244019626895
77.80000000000041,12.099315889056554,0.6513329983556253,0.0014483839496719497
79.00000000000043,12.143309906624086,0.6622981429968214,0.0013823331628630697
80.20000000000044,12.186910248687006,0.6724051007429366,0.001931533091701354
81.40000000000046,12.229632974742536,0.6825713848164661,0.001929002826217996
82.60000000000048,12.272948310390376,0.6953973393188639,0.0019074190445929062
83.8000000000005,12.315634350768747,0.7033390362368186,0.0016522679474268998
85.00000000000051,12.357541552364303,0.7141282668495418,0.0016268605905613853
86.20000000000053,12.400521953045883,0.7232145955447089,0.0009437512197711939
87.40000000000055,12.442512066015354,0.7323942176413427,0.0014267731171999642
88.60000000000056,12.484583619694517,0.7451783770788385,-0.0009377696520127543
89.80000000000058,12.52608195659721,0.753044515349612,-0.00020296231241623275
91.0000000000006,12.567360852371877,0.7589843344352121,0.0006279144081782206
92.20000000000061,12.607685516280423,0.7658607351891986,0.0006418369182457084
93.40000000000063,12.649934500100567,0.776406484152801,0.001812753773263509
94.60000000000065,12.690962921457137,0.7848065092013594,0.0006514574696492303
95.80000000000067,12.732330292455948,0.7914030522877644,-0.0006633499480077631
97.00000000000068,12.773246047943646,0.7961382524739635,0.0005568713200760911
98.2000000000007,12.813931187361987,0.8049826504488526,-0.0006935347215559773
99.40000000000072,12.854794636341731,0.8090994195663981,-0.0012218075793937189
100.60000000000073,12.894671071025945,0.8153725168324497,-0.001982172578029129
101.80000000000075,12.935950087705738,0.8202975801497042,-0.0009600299650127653
103.00000000000077,12.976551297325107,0.8281558658789333,-0.001993767839786109
104.20000000000078,13.017297341088067,0.8290215707713965,-0.00328308389192955
105.4000000000008,13.057866058084503,0.836156232499894,-0.0028710624285466224
106.60000000000082,13.09770602390815,0.83914116817162,-0.0031789232369705545
107.80000000000084,13.138875506650061,0.843529902185094,-0.003259744013852206
109.00000000000085,13.179103070202032,0.8444354886700072,-0.004495913979929433
110.20000000000087,13.219170000000025,0.8471457696774454,-0.0048199941776774224
111.40000000000089,13.259687307041434,0.8489174024131337,-0.004820015134494149
112.6000000000009,13.299995031175012,0.8529172528535592,-0.004819695087872056
113.80000000000092,13.340314656549747,0.8538558157683246,-0.004743886838784128
115.00000000000094,13.380236425682966,0.854660070394251,-0.004897163378151603
116.20000000000095,13.420680325631707,0.8552239902010561,-0.004856271973999071
117.40000000000097,13.461025923128409,0.8570157497470166,-0.006170871614727069
118.60000000000099,13.500863046241427,0.8544637525246079,-0.004839404356840049
119.800000000001,13.540879854943107,0.8567636060819008,-0.004850373271341191
121.00000000000102,13.581033217945846,0.8573722215085621,-0.005464795050687421
122.20000000000104,13.620587866296352,0.8592814419608886,-0.00541027906643432
123.40000000000106,13.660522787332,0.8620851079636029,-0.006145847066616916
124.60000000000107,13.70032226085882,0.8630363491455508,-0.0065973071173983655
125.80000000000109,13.739939237013305,0.862908374787449,-0.0071561659789987075
127.00000000000111,13.778968633419183,0.8660678154661339,-0.008445351692726533
128.20000000000113,13.818715178239422,0.8668100146969002,-0.008439848139275341
129.40000000000114,13.857900153364671,0.8663717414539184,-0.008439871745449246
130.60000000000116,13.89775163941442,0.8702038930552307,-0.008446847372878707
131.80000000000118,13.936996999313276,0.8719639831000429,-0.007448508801048526
133.0000000000012,13.976128555067849,0.872945560164759,-0.00648769310110886
134.2000000000012,14.015229189421056,0.8763600956181667,-0.006470092127223381
135.40000000000123,14.0541824004827,0.8789350186482394,-0.0077026665311557
136.60000000000124,14.093255150041573,0.8800200988925787,-0.007778982001421575
137.80000000000126,14.132032710096263,0.8847545293499502,-0.0077655481539258275
139.00000000000128,14.170820806478947,0.8857107159058649,-0.010455863622648387
140.2000000000013,14.20952149114114,0.8902255487793733,-0.010420130804560834
141.4000000000013,14.248386957806177,0.8956974000202096,-0.010419150530817767
142.60000000000133,14.287012899502443,0.9003717293940041,-0.009641164376906985
143.80000000000135,14.325669443375007,0.9036203539061579,-0.00909970148331496
145.00000000000136,14.364302658169958,0.9076631023385322,-0.009099994244382792
146.20000000000138,14.402768459346943,0.9124704704794921,-0.009100972080686276
147.4000000000014,14.441000999021533,0.917870143580355,-0.009331748360993153
148.60000000000142,14.4791042308186,0.9222734248045301,-0.010423562511884477
149.80000000000143,14.517652598637987,0.9255349755616178,-0.01042000279336186
151.00000000000145,14.555886230874972,0.9327289515269424,-0.010419991965994413
152.20000000000147,14.593981043406233,0.9359863512109615,-0.010419991985729737
153.40000000000148,14.632316406903824,0.9392379629568055,-0.010419990344362695
154.6000000000015,14.670316334350735,0.9464132369433864,-0.010419881200461667
155.80000000000152,14.708438990986144,0.9508351224644367,-0.010430867086566487
157.00000000000153,14.746272617135991,0.9560734599529055,-0.011742830390101489
158.20000000000155,14.784333733971732,0.9600132432865891,-0.011740821850948713
159.40000000000157,14.822256885056907,0.9660996871784733,-0.012059945940465333
160.6000000000016,14.860186201379951,0.967603044715422,-0.0127118198892342
161.8000000000016,14.898505050292087,0.9745677762711007,-0.012391337201821173
163.00000000000162,14.936032006757655,0.9792896059369125,-0.012390150146307732
164.20000000000164,14.973954799174725,0.9843896202993814,-0.012373131200329901
165.40000000000165,15.01229569386199,0.9899459061209721,-0.01336340862889962
166.60000000000167,15.049075517101633,0.9946164706325199,-0.013735273929335712
167.8000000000017,15.08697898418122,0.9986667369418518,-0.014698212601240712
169.0000000000017,15.124980958751944,1.00446363263604,-0.014699946634242345
170.20000000000172,15.162507894654476,1.010987735828502,-0.014698290730005503
171.40000000000174,15.200113014734425,1.0159225910974148,-0.015045861863209886
172.60000000000176,15.238107407583305,1.0221085809261148,-0.01502992458147645
173.80000000000177,15.27511023533801,1.0254236538125339,-0.015029796977286125
175.0000000000018,15.312997487191478,1.032248746115029,-0.014965828792520064
176.2000000000018,15.350568002807627,1.0349062225296035,-0.01762002295775833
177.40000000000182,15.388047474523214,1.0415349708325903,-0.017649878023827448
178.60000000000184,15.42510524012539,1.0475125486940517,-0.017650876574032637
179.80000000000186,15.462587306752832,1.0519235469655794,-0.01781193736244191
181.00000000000188,15.499071502465885,1.0568466705223765,-0.018432463337963334
182.2000000000019,15.537183655941645,1.0637506015544331,-0.01765984987748137
183.4000000000019,15.574578241001257,1.0682034847044162,-0.017660026701627807
184.60000000000193,15.61180268842933,1.0728581080857116,-0.01764742762412652
185.80000000000194,15.649014902024607,1.080773381111284,-0.019679751037323
187.00000000000196,15.685681859986735,1.0862684330831476,-0.020242038890304848
188.20000000000198,15.72321943703376,1.092177808303779,-0.02158783852854196
189.400000000002,15.760107252889316,1.0977685177740961,-0.021600186249997044
190.600000000002,15.797092225126173,1.1042239529598996,-0.021593645142613305
191.80000000000203,15.83415486421119,1.1099797429253826,-0.022895261504438658
193.00000000000205,15.871111596766694,1.1170762954046425,-0.022903587102244494
194.20000000000206,15.907948402312497,1.1234421406621906,-0.024250169420531265
195.40000000000208,15.945075252293034,1.131950428551755,-0.02534714960856732
196.6000000000021,15.98175818788885,1.1377746193993032,-0.025549261583206473
197.80000000000211,16.018730340607362,1.14397468099781,-0.025550056711101554
199.00000000000213,16.055479333528528,1.1509024046080274,-0.02655920177184079
200.20000000000215,16.092637616388153,1.161180668660554,-0.026800835106151055
201.40000000000217,16.12929638355754,1.1675430821454729,-0.028183337860376412
202.60000000000218,16.166122755973557,1.1757578084782878,-0.02917497288338744
203.8000000000022,16.202661991775493,1.1838975060827344,-0.030497462935400677
205.00000000000222,16.23913825469843,1.1887826075844479,-0.03081710054876119
206.20000000000223,16.275971130351593,1.1939698674374233,-0.03182835688263719
207.40000000000225,16.312515936982695,1.2052269663042927,-0.03316706797286617
208.60000000000227,16.34934934822607,1.2072241041729357,-0.03445028803345984
209.80000000000229,16.3861623326934,1.2179373276636716,-0.035769816710668145
211.0000000000023,16.422722289555843,1.2226219225202544,-0.03720110646890884
212.20000000000232,16.459383446018343,1.2273577340424384,-0.038412514462097036
213.40000000000234,16.496188899694328,1.2360442463934793,-0.03906670813046542
214.60000000000235,16.532822633120745,1.2443124257814913,-0.03940796595055929
215.80000000000237,16.569292362805562,1.2496878996403162,-0.04068947478726237
217.0000000000024,16.605953696793506,1.2550404794651173,-0.04218792088477308
218.2000000000024,16.642804652054004,1.2614919682357155,-0.045061977562168565
219.40000000000242,16.678714376320833,1.2673140156363025,-0.04626378427929101
220.60000000000244,16.715423075018702,1.2740220808939382,-0.047496133629675974
221.80000000000246,16.752081521530886,1.280946304119135,-0.04938084564765699
223.00000000000247,16.788364690279586,1.2870611384551929,-0.0507769937158411
224.2000000000025,16.825235988908574,1.2899540547701212,-0.05241123281060833
225.4000000000025,16.861496706766506,1.2946466608039007,-0.05382370764163369
226.60000000000252,16.898229942502496,1.3002763631565184,-0.05526350379050626
227.80000000000254,16.934430301625536,1.3047567795930282,-0.05698370178987311
229.00000000000256,16.970822058780332,1.3094586721643156,-0.059728957707747554
230.20000000000258,17.00739113262344,1.314095010326628,-0.06060284945133576
231.4000000000026,17.043747984957427,1.318655402433064,-0.06241012381374622
232.6000000000026,17.080369272473636,1.324107051691171,-0.06572047108912527
233.80000000000263,17.116438834298517,1.32360376190737,-0.06857607990162728
235.00000000000264,17.15275172712005,1.3304000682054997,-0.07022625402654903
236.20000000000266,17.18902328827014,1.3322186819938482,-0.07226177524583166
237.40000000000268,17.225677611544146,1.3386191715338236,-0.07490089955940471
238.6000000000027,17.261943578228955,1.339287988181677,-0.07778461041322693
239.8000000000027,17.298030397469233,1.3459365772156384,-0.08036723427043935
241.00000000000273,17.334635111176173,1.353427601796997,-0.08335357751557382
242.20000000000275,17.370750441753554,1.3588550183799368,-0.08535299079470082
243.40000000000276,17.4072338676502,1.3672594726918899,-0.08860863984193124
244.60000000000278,17.443753929222872,1.3699990788766456,-0.09180696213942063
245.8000000000028,17.479963723963003,1.3786574970304748,-0.09391930086241285
247.0000000000028,17.516050987879062,1.388326959721082,-0.09713541513026058
248.20000000000283,17.55234798735239,1.3961794924772322,-0.1009662900986994
249.40000000000285,17.58866336550222,1.401586984313893,-0.10332622109545486
250.60000000000286,17.62504176599625,1.402664275429676,-0.10544850811890871
251.80000000000288,17.661620350943288,1.399529519746821,-0.10925053119036754
253.0000000000029,17.69751248692302,1.3894408497147879,-0.11310392487041643
254.20000000000292,17.73288336895072,1.3830174524219632,-0.11703519079504865
255.40000000000293,17.770113953719974,1.3716835925187372,-0.12074791432235532
256.600000000003,17.806491893243138,1.3657930239092617,-0.12437893493107843
257.80000000000297,17.84245399614215,1.3579962342623526,-0.12793047865252927
259.00000000000296,17.878750560344216,1.3534037684721518,-0.1319933560579365
260.200000000003,17.915164704658043,1.3493377716371335,-0.136952278607418
261.40000000000305,17.951073972007404,1.3476452564630788,-0.1408982265153389
262.60000000000304,17.98748394467545,1.3430476780149316,-0.1453289809961973
263.800000000003,18.023785225557095,1.3413282512063271,-0.1506327437344046
265.00000000000307,18.059746503790294,1.3395422158251757,-0.1551535765586305
266.2000000000031,18.096004288798024,1.3357515527074484,-0.16055486774068495
267.4000000000031,18.13257795780208,1.3360721375612652,-0.16542929468823253
268.6000000000031,18.168506404833124,1.3335663221209106,-0.17064933717234165
269.80000000000314,18.20451543118695,1.3341539435032428,-0.17726496417662885
271.0000000000032,18.241131136448264,1.330118564834725,-0.1831962444523465
272.2000000000032,18.276950497280474,1.3302230607185872,-0.19005228951576614
273.40000000000316,18.3131080076838,1.3248235504316903,-0.19631248465446172
274.6000000000032,18.349538785815714,1.3223683087358635,-0.20564227639063581
275.80000000000325,18.385729955906754,1.3209298982983406,-0.21231400678547674
277.00000000000324,18.421824189678212,1.317620447872836,-0.2188509292179357
278.20000000000323,18.457647772778657,1.3149040489913915,-0.22627551939442903
279.4000000000033,18.49429290538898,1.3110494405967197,-0.2345543297251118
280.6000000000033,18.53034555684743,1.3071257382490797,-0.2445937300963803
281.8000000000033,18.566502688467647,1.300229616573429,-0.2555582865620867
283.0000000000033,18.602562675295008,1.29412972770711,-0.2654595609516974
284.20000000000334,18.639050461310795,1.2873492199217904,-0.2767085409902519
285.4000000000034,18.67538857264308,1.2829722579743879,-0.28755707231665406
286.6000000000034,18.71131241638518,1.276131131134381,-0.2995049047195444
287.80000000000337,18.74770347384455,1.2691744470740436,-0.31198547279568567
289.0000000000034,18.783348998684318,1.2632018264379135,-0.32301771065788953
290.20000000000346,18.8202052467958,1.2545218296905971,-0.33590122027143154
291.40000000000344,18.856531109754364,1.2442786039110583,-0.3500205153744358
292.60000000000343,18.892311478289322,1.2361974584539628,-0.36342979069425185
293.8000000000035,18.928633094816693,1.2248625150325219,-0.3780902199771812
295.0000000000035,18.964922938522072,1.215201226100032,-0.3935063343637881
296.2000000000035,19.001111270460363,1.2055580042119864,-0.4088556381933377
297.4000000000035,19.037467578883383,1.1945008317993917,-0.42567036619013754
298.60000000000355,19.07355581794832,1.181319873340588,-0.4436180172283466
299.8000000000036,19.109886571282697,1.1742116429846698,-0.45990795096884796
301.0000000000036,19.14629722953869,1.1615974413286647,-0.4774931987052109
302.20000000000357,19.18231147733829,1.1520430535226012,-0.49577848364246213
303.4000000000036,19.218514944951355,1.1427828082395441,-0.5143539815823526
304.60000000000366,19.25515150794973,1.1304260859227622,-0.5340280039490013
305.80000000000365,19.291263477285465,1.122804474711101,-0.5548933490989536
307.00000000000364,19.327302681080894,1.110148471874764,-0.5755812626265455
308.2000000000037,19.36365493355527,1.101899955069421,-0.5971010505159864
309.40000000000373,19.40001704837059,1.088682811421767,-0.6189847630277878
310.6000000000037,19.43642965369874,1.0775659815884508,-0.6425364246106127
311.8000000000037,19.47226496921783,1.072103387897578,-0.6655454228481066
313.00000000000375,19.50892826558528,1.0616218973040448,-0.6896482895876255
314.2000000000038,19.5450525696301,1.051832074276488,-0.712102222023439
315.4000000000038,19.581540025442592,1.0444670698165575,-0.7354400887865671
316.6000000000038,19.617758420881753,1.0391430544483051,-0.7581401537839163
317.8000000000038,19.654152979587977,1.0312338405187196,-0.7818848339388667
319.00000000000387,19.69030396993338,1.0248120808653418,-0.8068466761197723
320.20000000000385,19.72665402751618,1.018584675637586,-0.8325100684186997
321.40000000000384,19.763003094168905,1.016610574103459,-0.8579529161570969
322.6000000000039,19.79950694653612,1.0097420614127037,-0.8837178741643248
323.80000000000393,19.835910725382455,1.0078427906642746,-0.9097527774445533
325.0000000000039,19.87239859804231,1.0059209039709016,-0.9358832830794466
326.2000000000039,19.908773048015647,1.0066916556370475,-0.9612210339471825
327.40000000000396,19.94510432513304,1.0072741971811274,-0.9865612545134468
328.600000000004,19.981661631174653,1.0101240030942262,-1.0119381784557904
329.800000000004,20.018080542779416,1.0083963638350264,-1.036527172290874
331.000000000004,20.054998952196165,1.0141976119673437,-1.0622813138285903
332.200000000004,20.09099437107943,1.0190661696021772,-1.0868962644026827
333.40000000000407,20.127697346193617,1.0239732195856401,-1.1124964963490114
334.60000000000406,20.164342802892655,1.0294960313052797,-1.1378220045728202
335.80000000000405,20.20049287883399,1.0354504955354198,-1.1623314158394322
337.0000000000041,20.23727690349436,1.042162124019309,-1.1880629098500348
338.20000000000414,20.27385107379253,1.0498283633977619,-1.2132262361202804
339.4000000000041,20.310354419465217,1.0595227083200391,-1.2377016170566133
340.6000000000041,20.347316319011902,1.0688117431088473,-1.2632923818379793
341.80000000000416,20.383747896265067,1.0814031940824902,-1.2892581013304478
343.0000000000042,20.420463727001675,1.0924840433388645,-1.3140366166107609
344.2000000000042,20.45699242001083,1.1052470680219806,-1.338577474508297
345.4000000000042,20.49385294066816,1.1184962131001868,-1.3633546006408834
346.60000000000423,20.53032254648744,1.1319228162577168,-1.3891481566206898
347.8000000000043,20.567176778457572,1.1473511296779546,-1.415896808306797
349.00000000000426,20.60394125135139,1.1667529652533515,-1.441780028279128
350.20000000000425,20.640619119365503,1.1812924230283515,-1.4683735590568152
351.4000000000043,20.677779814319592,1.1990550604674328,-1.4959583979076294
352.60000000000434,20.714350385848338,1.2183670849851143,-1.5219958183920075
353.80000000000433,20.751231462156355,1.2442081882718838,-1.5508176609526
355.0000000000043,20.788147948615038,1.264566407660572,-1.5802768652881287
356.20000000000437,20.824973878610216,1.2911675948561105,-1.6092010475806897
357.4000000000044,20.86206920380459,1.320940296307752,-1.6402534461450986
358.6000000000044,20.898450303018734,1.350051961354395,-1.6701459393778504
359.8000000000044,20.93557268869902,1.3805782247399017,-1.7018610439125297
361.00000000000443,20.97242583573676,1.4138460429493267,-1.736451932499988
362.2000000000045,21.009508054203724,1.4507350529477256,-1.7730779776001704
363.40000000000447,21.04647759552221,1.4892424099805275,-1.8105661871369012
364.60000000000446,21.08361827360039,1.5286419743199802,-1.850077123310852
365.8000000000045,21.120787881265496,1.5735564024482716,-1.8922551268204746
367.00000000000455,21.157881940559584,1.6131841582209445,-1.9365569347100875
368.20000000000454,21.194920802838585,1.6540254484375427,-1.9829679010773988
369.4000000000045,21.23190140839212,1.6918718472743508,-2.0305254846966214
370.60000000000457,21.269010804666667,1.7233465088524218,-2.081172109612484
371.8000000000046,21.30605908404507,1.7415094751304336,-2.133180744897353
373.0000000000046,21.34330920799418,1.7446698144926702,-2.1872030029017746
374.2000000000046,21.379966271207117,1.7270184736898062,-2.2421318402882946
375.40000000000464,21.41738469310625,1.6885746999750832,-2.29861891305384
376.6000000000047,21.454360242886676,1.62279594623283,-2.3545397025646686
377.8000000000047,21.49162532256564,1.5367071112490476,-2.4082020686590835
379.00000000000466,21.528831976447215,1.4284595144247874,-2.459374018583099
380.2000000000047,21.565659600819906,1.3138330342017326,-2.5072132369001188
381.40000000000475,21.602265792869222,1.1923467041175102,-2.5503141286372926
382.60000000000474,21.640019516851094,1.0662499253953106,-2.5902490568667753
383.80000000000473,21.67688873120568,0.9548335564568096,-2.623250071364211
385.0000000000048,21.714138176028502,0.8514029178982858,-2.6510506560335663
386.2000000000048,21.751051515059935,0.7655374869729437,-2.675241337518363
387.4000000000048,21.788022708664656,0.6889255136271595,-2.69539718837574
388.6000000000048,21.825373041184907,0.62394594641849,-2.711903997465239
389.80000000000484,21.862307390468192,0.5716722348248124,-2.727275393638788
391.0000000000049,21.89960027441253,0.5288454636891649,-2.739122419863953
392.2000000000049,21.936350565174692,0.4921685239234428,-2.7481056617189443
393.40000000000487,21.97355189003714,0.4613530338214451,-2.756232454754571
394.6000000000049,22.010591412640835,0.4368404632605347,-2.7653134498904173
395.80000000000496,22.04784780955053,0.410743191708129,-2.771898732322581
397.00000000000495,22.084986207295934,0.38971128209240735,-2.7787103039190963
398.20000000000493,22.122257915205832,0.3739787162810546,-2.785853324640703
399.400000000005,22.158613146208268,0.3553841860050442,-2.790431740126942
400.600000000005,22.19636170038159,0.34229395320787637,-2.7959793500620034
401.800000000005,22.233516744509703,0.32801233702351706,-2.800756991232607
403.000000000005,22.270893147129257,0.31202995589450544,-2.8048515295646377
404.20000000000505,22.308018491259624,0.3020320584551166,-2.809962263807991
405.4000000000051,22.345569256209995,0.2886286554673587,-2.8157495869961586
406.6000000000051,22.382783570003063,0.27826177601574065,-2.8211440522989664
407.80000000000507,22.420233789234086,0.2667852450306396,-2.8247719261979585
409.0000000000051,22.457428586818402,0.25754567799538175,-2.828927214282041
410.20000000000516,22.494508328669696,0.24548944150787366,-2.8324907115941897
411.40000000000515,22.53210742051883,0.23575924841630558,-2.8372258064140596
412.60000000000514,22.569265932987612,0.2284709155563951,-2.8418647354280795
413.8000000000052,22.60659912511755,0.2182181079613048,-2.845896381740456
415.00000000000523,22.644200673333966,0.20995529741496344,-2.849858630492231
416.2000000000052,22.68147003750256,0.19983752644670538,-2.852755148457767
417.4000000000052,22.718920249369543,0.19333275086584756,-2.855750985890084
418.60000000000525,22.75643121534596,0.18374656338589546,-2.8612139652791644
419.8000000000053,22.793635663004665,0.17700953184101254,-2.8648038339395345
421.0000000000053,22.831331904077974,0.1700154039331172,-2.8672925416946784
422.2000000000053,22.868469591694446,0.1614933424112701,-2.8700756229427515
423.4000000000053,22.90604405398432,0.15373430666306098,-2.873829102459764
424.60000000000537,22.943525168583097,0.14627859787947162,-2.8777755093259962
425.80000000000535,22.980934833932714,0.13781625751383264,-2.8816864807689777
427.00000000000534,23.01810938786666,0.1367804349467625,-2.8863831803372912
428.2000000000054,23.05595162990998,0.13027982401052918,-2.8902189173586033
429.40000000000543,23.09327397338499,0.1264585269278773,-2.892887320035441
430.6000000000054,23.130897502426443,0.11991655274804525,-2.896300895747024
431.8000000000054,23.168277508136967,0.1171899529752165,-2.9003301281882203
433.00000000000546,23.205995478557366,0.10945782813280491,-2.9042324956939285
434.2000000000055,23.243564011577867,0.10888038107910658,-2.907478641650144
435.4000000000055,23.280893392281303,0.10430408993518725,-2.910271674475556
436.6000000000055,23.31870008834091,0.10169286241524467,-2.9140868529610104
437.8000000000055,23.356196879901514,0.10036784329413972,-2.9180790472475744
439.00000000000557,23.394016671662122,0.09520033328526556,-2.921212478940048
440.20000000000556,23.431541410582867,0.09512649661143024,-2.923744945749074
441.40000000000555,23.468784976306754,0.09658122949804948,-2.9279181348124346
442.6000000000056,23.506629285355952,0.09302525555535945,-2.9315870780949504
443.80000000000564,23.544629734778947,0.09407128452485813,-2.933577020465062
445.0000000000056,23.582067936800748,0.09604309647358988,-2.936743643973948
446.2000000000056,23.619999822919272,0.09704669920312536,-2.940326551358079
447.40000000000566,23.657669297265485,0.09756083832946572,-2.943913111660724
448.6000000000057,23.69560676145703,0.10049217448134629,-2.9474101075784755
449.8000000000057,23.733102968675382,0.10241648124270353,-2.9505416680001577
451.0000000000057,23.770797043545745,0.10236368865624845,-2.952951714191482
452.20000000000573,23.808792308270462,0.10605748046519303,-2.9561150982940596
453.4000000000058,23.846613262975787,0.10622755722761346,-2.9592686192006683
454.60000000000576,23.884332179694074,0.11166735144151474,-2.9613732654231844
455.80000000000575,23.922475487633637,0.11176258819786034,-2.963871348319536
457.0000000000058,23.959930854890516,0.11668006903361561,-2.9666354869674434
458.20000000000584,23.998085371665244,0.12337915315622783,-2.9700801418545852
459.40000000000583,24.03608159807048,0.12686141819983665,-2.973145947969204
460.6000000000058,24.07408183132609,0.13069967269740768,-2.974423901415533
461.80000000000587,24.11201780032697,0.13551456159050046,-2.9763688977395164
463.0000000000059,24.149823394157842,0.1423471318083933,-2.9795867283814457
464.2000000000059,24.18798907136184,0.14646934063969286,-2.9830845343206116
465.4000000000059,24.226118563957893,0.15323757528156068,-2.985333096656112
466.60000000000593,24.263806605797953,0.15741606946652165,-2.9880719703848624
467.800000000006,24.302257740438254,0.16516054485327802,-2.990325941672852
469.00000000000597,24.340049229277845,0.17028181011116605,-2.992580999780386
470.20000000000596,24.378163968509554,0.1763591788278498,-2.9953711573699815
471.400000000006,24.41603186312845,0.18116345606161066,-2.998340448592569
472.60000000000605,24.454229972956025,0.1870308912330072,-3.0007187501755794
473.80000000000604,24.492482489911822,0.19443915761111308,-3.003360211099083
475.000000000006,24.530453529270673,0.1983468457809352,-3.00499005043387
476.20000000000607,24.568725737867588,0.20594508379103282,-3.0064779092677787
477.4000000000061,24.60672779901233,0.21130420699033348,-3.0110491904012773
478.6000000000061,24.645306073224223,0.2156403525114594,-3.0131092854550197
479.8000000000061,24.683164553738752,0.2206908185312526,-3.0147641267840335
481.00000000000614,24.721629286908726,0.2246499324450344,-3.0171832722174297
482.2000000000062,24.759840022403274,0.23218075051319387,-3.018038375436738
483.4000000000062,24.79779894920482,0.23527000161705813,-3.019578623555214
484.60000000000616,24.836196572299407,0.23883276751592408,-3.021074169231595
485.8000000000062,24.874385657836516,0.24327094466667276,-3.023848332747066
487.00000000000625,24.91268366534237,0.24741833905204103,-3.025577754221281
488.20000000000624,24.95102032791657,0.24923199756892012,-3.0281637363189486
489.40000000000623,24.9892344124856,0.25366616663916486,-3.0293878349815575
490.6000000000063,25.027555575736738,0.2569111827339692,-3.030368367292818
491.8000000000063,25.06586489301024,0.25986309823416054,-3.0332354762857023
493.0000000000063,25.104193604354133,0.2630637082595457,-3.0334867685295173
494.2000000000063,25.142578999419175,0.26848661803715546,-3.035419040243335
495.40000000000634,25.180739909666713,0.2713226653496468,-3.037885071850157
496.6000000000064,25.219234937202035,0.2739038036656778,-3.04084072538185
497.8000000000064,25.257757409494477,0.2748514804035156,-3.0424027957113706
499.00000000000637,25.296124977451854,0.27840257086577647,-3.043831810714118
500.2000000000064,25.334601594426108,0.279691386838282,-3.0451861073960975
501.40000000000646,25.37289257611804,0.28193264404160545,-3.0469598044910406
502.60000000000645,25.411741930495154,0.2851937370962907,-3.049952386576498
503.80000000000643,25.44988990965281,0.287902604016105,-3.0513476500718273
505.0000000000065,25.48821420618863,0.2914740757561354,-3.052863989312322
506.2000000000065,25.526631606440915,0.2926974088387333,-3.0543285054802563
507.4000000000065,25.565016894632873,0.29369044347087625,-3.0557465763050566
508.6000000000065,25.603989520938836,0.29689737296034724,-3.0571662060971447
509.80000000000655,25.64116357258294,0.2977295607939636,-3.058551948002382
511.0000000000066,25.680684854387604,0.2989348711075557,-3.060122951022908
512.2000000000066,25.719234027135222,0.29950972469524517,-3.061563839502321
513.4000000000066,25.757677250889355,0.3026162085155466,-3.0629447412566106
514.6000000000066,25.796218928341787,0.30175466213083,-3.064283995942021
515.8000000000067,25.83475752799499,0.30386001445058697,-3.065622509051609
517.0000000000066,25.873230351743743,0.30566292903199765,-3.0669353087008258
518.2000000000066,25.912091484498646,0.3061749130013931,-3.0682683928771715
519.4000000000067,25.950077585788385,0.30690086037374,-3.069872023382739
520.6000000000067,25.989105541085753,0.3097010485176983,-3.0712100708643257
521.8000000000068,26.027617143266344,0.3073612810519015,-3.0726726762384633
523.0000000000067,26.06597979660246,0.31079594400106725,-3.0741408689833465
524.2000000000068,26.10464563903965,0.3119964259807477,-3.075568031208015
525.4000000000068,26.143010474067438,0.3104439970455257,-3.076813200583135
526.6000000000067,26.1820076842362,0.312260679456861,-3.0790038606641503
527.8000000000068,26.220765881780817,0.31138921761376803,-3.079698268879456
529.0000000000068,26.25913768998544,0.31424829757675976,-3.080856812130637
530.2000000000069,26.298022775738616,0.3159294261720189,-3.083511575944245
531.4000000000069,26.336765325671635,0.31717007104257045,-3.0848117485705613
532.6000000000068,26.37520844819043,0.31727126833478514,-3.0849271363174102
533.8000000000069,26.41389356989877,0.31621926756630336,-3.0837250017257363
535.0000000000069,26.452545433647092,0.32019992625959914,-3.084855237576278
536.2000000000069,26.491354616663052,0.32004363589736107,-3.086452118629664
537.4000000000069,26.529830133883078,0.3221129462031316,-3.0893711862114586
538.600000000007,26.568970904159833,0.3217920295801402,-3.09074063087797
539.800000000007,26.60758897337324,0.32242536222486984,-3.0920835842826304
541.000000000007,26.645936146789886,0.3196542705135026,-3.0933683661662474
542.200000000007,26.684723764284595,0.3229161718632765,-3.094705229081577
543.400000000007,26.723617419836962,0.3283346857600007,-3.0939444841818564
544.6000000000071,26.762432560160157,0.3270370741488293,-3.095346908601152
545.800000000007,26.80130881780245,0.32775484384053954,-3.0967073669390244
547.000000000007,26.840212041392856,0.32991352309818023,-3.09813642712226
548.2000000000071,26.878568610231632,0.3342082410569591,-3.0995893004669752
549.4000000000071,26.917647065773174,0.334195632408111,-3.1009314415429436
550.6000000000072,26.956465782888763,0.33432841079935205,-3.1022001510550776
551.8000000000071,26.995499054304865,0.3375342028224031,-3.103077718930428
553.0000000000072,27.03391026352152,0.3422557661903234,-3.1037902589459576
554.2000000000072,27.073165047107054,0.3440024317258672,-3.1045597630605855
555.4000000000071,27.111932774845673,0.3436140054139951,-3.1063781786759375
556.6000000000072,27.1507269795281,0.34774459472920016,-3.1065138909486434
557.8000000000072,27.189716835470428,0.34611220632196216,-3.1078461721750466
559.0000000000073,27.22849266603516,0.3485637225280409,-3.109221180799338
560.2000000000073,27.26772875602322,0.35330021727805483,-3.1104826819370746
561.4000000000073,27.306340060512607,0.35290385596537077,-3.1105010988810173
562.6000000000073,27.345461949817572,0.3545943646477956,-3.111899440187596
563.8000000000073,27.384544230319477,0.3586040806622868,-3.1121903547344445
565.0000000000073,27.423517330581088,0.35879031620561785,-3.1132730552510828
566.2000000000073,27.462143032455714,0.3618681580458252,-3.114492145482835
567.4000000000074,27.501190270615446,0.36039185667442375,-3.1158082192419467
568.6000000000074,27.539890597389356,0.3612176299283809,-3.1171724983422084
569.8000000000075,27.57926959981544,0.3612986448685356,-3.118490287036221
571.0000000000074,27.618485803875686,0.3628406720470938,-3.1184885509676414
572.2000000000074,27.65742284241027,0.36501559491390956,-3.1197315406115376
573.4000000000075,27.69637824999459,0.3635125732687352,-3.119941661724828
574.6000000000074,27.73524926043798,0.36375800748800313,-3.1211274081908984
575.8000000000075,27.774634266169933,0.36704734069141964,-3.121632007872108
577.0000000000075,27.81366360557021,0.37101227044730556,-3.1224239495029824
578.2000000000075,27.853098777727862,0.3682464352256878,-3.123648751778745
579.4000000000076,27.891956444861066,0.36723513441886246,-3.124773116214346
580.6000000000075,27.930918974153407,0.36935023672614875,-3.126023906197829
581.8000000000076,27.970340116975137,0.3721690169562186,-3.1273585200847838
583.0000000000076,28.009335658424654,0.37117897949123724,-3.128795684004587
584.2000000000075,28.04861651979763,0.3683361335186832,-3.1287885409513088
585.4000000000076,28.087933444160726,0.36895650179241013,-3.128789910379062
586.6000000000076,28.12688814466186,0.3705565827273176,-3.129930651072988
587.8000000000077,28.165075678034487,0.3698058478805395,-3.131820415718117
589.0000000000077,28.204323142439904,0.3673623757892204,-3.1330289746289828
590.2000000000077,28.243552235610537,0.36833193039668455,-3.134064508174289
591.4000000000077,28.283319129457638,0.36639211496896795,-3.1342648261611394
592.6000000000078,28.322500363860506,0.3643994454957722,-3.1348773942336
593.8000000000077,28.362103456185686,0.3672128373242616,-3.1360187609702868
595.0000000000077,28.40112366958311,0.366334615896738,-3.1367865232235244
596.2000000000078,28.440154002460964,0.36498350802052193,-3.136726262592008
597.4000000000078,28.47966622449361,0.36594880789118656,-3.13801067098278
598.6000000000079,28.518808828117244,0.3648065217666896,-3.138639741193786
599.8000000000078,28.558074144208497,0.3636419434484195,-3.1406180018050343
601.0000000000078,28.597239838767113,0.3614421705979889,-3.1408288382230607
602.2000000000079,28.636496692910413,0.3599352408989087,-3.1419767109948142
603.4000000000078,28.67643844432493,0.3591132269935513,-3.1433064624971587
604.6000000000079,28.715178977054375,0.3616519698242515,-3.1444566653124033
605.8000000000079,28.75458990350379,0.35704223470537544,-3.1432731171572383
607.000000000008,28.79343157708813,0.355988194448436,-3.1445686665675625
608.200000000008,28.832994709212375,0.35735544901393257,-3.144591476862235
609.4000000000079,28.87248468899886,0.3583380298354977,-3.1459998078042983
610.600000000008,28.912101413155685,0.3576047783867482,-3.146796594057059
611.800000000008,28.95142536208426,0.35601155054117384,-3.147178630523836
613.000000000008,28.99074823868248,0.35797735078652604,-3.14853853544044
614.200000000008,29.030028587517105,0.3551303816420013,-3.1485403526641544
615.400000000008,29.069369052965392,0.35456372846106854,-3.1498603174148228
616.6000000000081,29.108835314282448,0.35638469014160545,-3.1498504070902396
617.8000000000081,29.148348600094458,0.354404788410452,-3.1507662382719293
619.0000000000081,29.187985890795314,0.35785023711840025,-3.151411946845771
620.2000000000081,29.227127287623745,0.35748091294504425,-3.1524926243319102
621.4000000000082,29.266829216587865,0.35843687438045535,-3.1525019730650206
622.6000000000081,29.30603189718576,0.35359727854675116,-3.1538323884701747
623.8000000000081,29.345759762382674,0.35547883492076027,-3.1537118126721597
625.0000000000082,29.385227958444073,0.35529081884214153,-3.155144532918012
626.2000000000082,29.424696146866168,0.355683563763481,-3.1565654715281255
627.4000000000083,29.46404569762218,0.3574732821653839,-3.157955565237637
628.6000000000082,29.503263925399136,0.3572916106228252,-3.15786041447611
629.8000000000083,29.54300533895787,0.35811165446516546,-3.15781821029134
631.0000000000083,29.582499364925617,0.35720117378449756,-3.1591662439200356
632.2000000000082,29.621815180957213,0.35924463478920665,-3.1592027964424423
633.4000000000083,29.661259213478605,0.36052690484803396,-3.16049529694474
634.6000000000083,29.7010101818595,0.36010456464243856,-3.16048967110578
635.8000000000084,29.740418515937336,0.3609682737014752,-3.1609354061324195
637.0000000000084,29.780194428315507,0.35874494499667,-3.1618141249250895
638.2000000000083,29.8197646305863,0.3635320737922909,-3.1631264676675306
639.4000000000084,29.85896223966297,0.36433845431920386,-3.164441733322457
640.6000000000084,29.898367651615168,0.3653893869497964,-3.1644409638961326
641.8000000000084,29.938149725431984,0.36251518899537283,-3.165338170923602
643.0000000000084,29.977853956518,0.3629446630184432,-3.1657599104257583
644.2000000000085,30.017479317751278,0.36305167223362234,-3.165693138800284
645.4000000000085,30.056905283364458,0.3609800029247463,-3.1670812768266656
646.6000000000085,30.096467618318712,0.36121225329826956,-3.166719915901444
647.8000000000085,30.136255817832083,0.3595078348004028,-3.1674066108824652
649.0000000000085,30.175479571049895,0.3599792408906133,-3.1670680945149017
650.2000000000086,30.215179883741165,0.3580040587854134,-3.167084205613887
651.4000000000085,30.254781891695053,0.35879546969745446,-3.1684449305966
652.6000000000085,30.29440642422593,0.3615210736247514,-3.1697486252973257
653.8000000000086,30.33409100558729,0.3607096901495228,-3.170966492605002
655.0000000000086,30.37372054085437,0.3622735843712206,-3.1697704796513335
656.2000000000087,30.41327964482676,0.36145123129526446,-3.1696915707973785
657.4000000000086,30.452797629688234,0.3587347195301098,-3.170997354827435
658.6000000000087,30.492763678638543,0.3625310775659307,-3.1709538073020225
659.8000000000087,30.531971466975683,0.3613660627380395,-3.1723384362955827
661.0000000000086,30.572179769786633,0.3580346764939437,-3.1723354705668676
662.2000000000087,30.61148440491961,0.35629917194166927,-3.1736477795814126
663.4000000000087,30.651527308366482,0.35945383988912116,-3.174973240899778
664.6000000000088,30.691182854246875,0.35968100543595605,-3.175793414570254
665.8000000000088,30.730686019941476,0.3599364051298193,-3.1756192014123235
667.0000000000088,30.7705620126808,0.3611651185916418,-3.176955056839761
668.2000000000088,30.809999628254022,0.35920027782112407,-3.1769500199931207
669.4000000000088,30.849862031551538,0.3579124737581296,-3.176949579718621
670.6000000000088,30.889407777453286,0.356937162251568,-3.177618101828366
671.8000000000088,30.929170337195828,0.35459327324650824,-3.1779255676434373
673.0000000000089,30.96865748725709,0.35567636716927464,-3.1776002406690402
674.2000000000089,31.008454227266803,0.3554359242913856,-3.1778754285656703
675.400000000009,31.04808460731806,0.35618174771723354,-3.178921445172052
676.6000000000089,31.087472922741373,0.3590938512367763,-3.1789198782070818
677.8000000000089,31.127311601180843,0.360223552422009,-3.180095834209612
679.000000000009,31.166917029581477,0.3599695667971816,-3.180223097055852
680.2000000000089,31.206770289883195,0.3573545874930977,-3.181532256192114
681.400000000009,31.246488616922644,0.3585757813257189,-3.18155006149411
682.600000000009,31.286173146062197,0.35819793885090934,-3.1815511509713588
683.800000000009,31.32597929598439,0.35701086888094724,-3.1817811278637835
685.0000000000091,31.36580717817214,0.35579968547152174,-3.181558232974681
686.200000000009,31.405428185943187,0.35692291242250196,-3.1815594989528515
687.4000000000091,31.4450594723875,0.3552203915068053,-3.18260329212681
688.6000000000091,31.484420014317834,0.35452552480271904,-3.183760926769566
689.800000000009,31.524110626512638,0.3530651016396118,-3.1842701316644426
691.0000000000091,31.56397007676622,0.35263916519580385,-3.183315750917539
692.2000000000091,31.603935911770513,0.34898067354122997,-3.1841906291978934
693.4000000000092,31.6434864715253,0.34794968779415303,-3.1841901193520803
694.6000000000092,31.68300140303081,0.348653530957137,-3.1841902128836446
695.8000000000092,31.722851356091784,0.34408644854506276,-3.1842085465767624
697.0000000000092,31.76279123689594,0.34347607130058844,-3.1855087969524263
698.2000000000093,31.801801479096817,0.3400747433083757,-3.185499908979779
699.4000000000092,31.84215127543577,0.3429071581935026,-3.185499562338811
700.6000000000092,31.88212415915457,0.3435263830655959,-3.1854422371137328
701.8000000000093,31.92175434749804,0.33873943081030067,-3.1868185088424137
703.0000000000093,31.961698302380896,0.33531185234599503,-3.1868201704316323
704.2000000000094,32.00161068109671,0.33349616240172164,-3.1868190070471374
705.4000000000093,32.04123592613246,0.33329000617233673,-3.185943165253394
706.6000000000093,32.08116281726762,0.3309898176647508,-3.1868193418450335
707.8000000000094,32.12076422823036,0.32909436700492645,-3.188197164017777
709.0000000000093,32.16083672592524,0.3278675157974291,-3.188129995341396
710.2000000000094,32.20050527220722,0.3254721449679665,-3.188088100902318
711.4000000000094,32.24028895934993,0.32562780914369505,-3.19079553938728
712.6000000000095,32.28065412670677,0.323083963803509,-3.1907703324824515
713.8000000000095,32.32022317555634,0.32115240990142535,-3.190771192803805
715.0000000000094,32.36001210679849,0.3214771009428863,-3.190712234388277
716.2000000000095,32.40020897942213,0.31924533241493247,-3.190770087327045
717.4000000000095,32.4400352337363,0.31926500593463025,-3.1907699906720968
718.6000000000095,32.480166825287675,0.31776439879249807,-3.1907532912218874
719.8000000000095,32.519899452735466,0.3166169168574253,-3.1920788935820856
721.0000000000095,32.55978706592432,0.31449349921371716,-3.1920798235917407
722.2000000000096,32.59967523080634,0.3141349706808012,-3.192080996220791
723.4000000000096,32.639725656005425,0.3100786058201286,-3.193415466149555
724.6000000000096,32.67973251448025,0.31096740554297675,-3.1934002115093456
725.8000000000096,32.719921284196936,0.3058102584273845,-3.193400388051513
727.0000000000097,32.75953855981346,0.31012664970350956,-3.1934243609971817
728.2000000000096,32.7999597350206,0.3088417848239784,-3.194710008711815
729.4000000000096,32.83983989638594,0.30384235417453676,-3.1947091228049924
730.6000000000097,32.87958208643245,0.30203493350152044,-3.1957315019725696
731.8000000000097,32.91992069524285,0.2988694473816853,-3.1960301130874385
733.0000000000098,32.96006058250886,0.29845979241916476,-3.1960301985697734
734.2000000000097,32.99994743711018,0.29946335060349316,-3.1960300175061387
735.4000000000098,33.040131535518725,0.3022940430274925,-3.1959935855018125
736.6000000000098,33.08026004790539,0.29706522144312064,-3.195679136630246
737.8000000000097,33.12035081694914,0.29821150819583364,-3.197018891271851
739.0000000000098,33.16021660628923,0.29592447144493494,-3.1970200941368834
740.2000000000098,33.20034440487287,0.29278359932380393,-3.1970186942920575
741.4000000000099,33.24051587537764,0.28857997858963147,-3.198102514080625
742.6000000000099,33.280900696004274,0.29347223474915207,-3.1973591372193226
743.8000000000098,33.32084432417672,0.28965865908777033,-3.198454783215362
745.0000000000099,33.361175432457806,0.2880694510144308,-3.1986700133819954
746.2000000000099,33.40125139122791,0.2892785442611223,-3.1986701720568185
747.4000000000099,33.441200137071434,0.2869960257226083,-3.198669956677785
748.6000000000099,33.48138442695668,0.2851340365401107,-3.1992184917289377
749.80000000001,33.52181635329678,0.28685266014717214,-3.199984719925643
751.00000000001,33.56180635489125,0.2850916407659052,-3.201137291655368
752.20000000001,33.60203422789144,0.28425794349740574,-3.2012995793447896
753.40000000001,33.641917004319794,0.28095048603863315,-3.201282951682832
754.60000000001,33.68242166166995,0.2879046285778979,-3.1999921698833425
755.8000000000101,33.72265763565822,0.2899633455686783,-3.201307010903843
757.00000000001,33.76253177918619,0.2813164690299219,-3.2012993021292733
758.20000000001,33.80290549923202,0.28337855162717807,-3.201899598113047
759.4000000000101,33.84340956143815,0.28328169332450015,-3.2022885575679614
760.6000000000101,33.883409442004265,0.28550400020640376,-3.203054945168276
761.8000000000102,33.92363540406963,0.284318868696011,-3.2036097540610875
763.0000000000101,33.96396531249283,0.28581625558517,-3.2049666912055397
764.2000000000102,34.00424418703753,0.2872444473753384,-3.204920468689581
765.4000000000102,34.04454881043363,0.286366282661183,-3.204054511031026
766.6000000000101,34.084754589170004,0.28561533832969754,-3.203601559495363
767.8000000000102,34.12538127135577,0.28458198917747746,-3.2036138087245067
769.0000000000102,34.16571021480366,0.28608027907799016,-3.2049567306504367
770.2000000000103,34.20554341888267,0.2787422592225459,-3.204920319588243
771.4000000000103,34.24574779401155,0.27785742430350524,-3.2049201298790493
772.6000000000103,34.28615057052014,0.27740491722906624,-3.2049214701321596
773.8000000000103,34.32657228976674,0.27941923925522083,-3.206109195738745
775.0000000000103,34.36692580779318,0.2784785399746772,-3.20556869122078
776.2000000000103,34.40690409690356,0.27849863370260497,-3.2055698363633534
777.4000000000103,34.44730739025329,0.27796705121710463,-3.2055632545400705
778.6000000000104,34.48771198190683,0.2751153535963713,-3.206864892391599
779.8000000000104,34.527951138356016,0.2795446227729217,-3.207447066350284
781.0000000000105,34.568270112092776,0.2764225477642861,-3.208213940464913
782.2000000000104,34.60852075113998,0.2808369132334687,-3.2069784661542218
783.4000000000104,34.64900328748941,0.27641575235314875,-3.206890602039365
784.6000000000105,34.6894422741904,0.27815584393594994,-3.206890274824566
785.8000000000104,34.72933590694656,0.27975404212591215,-3.2069001971951505
787.0000000000105,34.769900439188724,0.27782759989005923,-3.2082098622765804
788.2000000000105,34.80965489798565,0.2803772605218433,-3.2089007843651842
789.4000000000106,34.84950029446935,0.28001692124337696,-3.209519654094072
790.6000000000106,34.890875604025524,0.2833001052400883,-3.2094961303398426
791.8000000000105,34.93125493250951,0.28082932192232457,-3.2098623362699956
793.0000000000106,34.97141344679388,0.2855107333119462,-3.209495672725584