File: 01_Data/Bamboo_Rug_Bamboo/STA/N2/30K_min/Bamboo_Rug_Bamboo_STA_N2_30KData_220121_R1.csv
##Temp./Â°C,Time/min,DSC/(mW/mg),Mass loss/mg
49.0,10.472847557012274,0.009226106665972234,-0.01141206393421168
50.20000000000002,10.70491771913302,0.0448906535126965,-0.010252717563758118
51.400000000000034,10.841452267254923,0.07771147265865619,-0.010803678036918729
52.60000000000005,10.945418677842625,0.10895398332772699,-0.011930108669282458
53.80000000000007,11.034205524589238,0.1362288443847839,-0.01367530695266872
55.000000000000085,11.11228672483361,0.1588898538770236,-0.013159908813355603
56.2000000000001,11.184338385306143,0.1822742783546688,-0.013236212968183114
57.40000000000012,11.250443916789141,0.20135764725765903,-0.014424311901485076
58.600000000000136,11.312808445101354,0.2200989608186915,-0.01300295856125011
59.80000000000015,11.372389114366522,0.23562629247569894,-0.013259722709094923
61.00000000000017,11.429121912839364,0.25374170561375176,-0.013211863373446597
62.20000000000019,11.484152743496786,0.26853900108999124,-0.013267222982065174
63.400000000000205,11.537260763951933,0.2804242166041142,-0.011514329888927755
64.60000000000022,11.58844016876794,0.29478051438915276,-0.013201220269510205
65.80000000000024,11.638927157826028,0.3052532465942568,-0.01395458633723301
67.00000000000026,11.688136735419143,0.31709998790644073,-0.01317923148449518
68.20000000000027,11.736959453520551,0.3285573693414269,-0.012806414664822796
69.40000000000029,11.78487659324004,0.33877455651201,-0.01228313372551737
70.6000000000003,11.831565712110885,0.3470890648635901,-0.014015085129893468
71.80000000000032,11.877969733897615,0.3587754210522392,-0.01410282938602947
73.00000000000034,11.924479634189906,0.3667491811894922,-0.012527226619423182
74.20000000000036,11.969447090744453,0.37633965782984613,-0.012918835570850717
75.40000000000038,12.014316476966105,0.38370607100225523,-0.013666483546083796
76.60000000000039,12.058660311671815,0.3911507088268902,-0.012726022758557498
77.80000000000041,12.103181190180276,0.3993097061600019,-0.013411562009665978
79.00000000000043,12.147234709146936,0.40564049210304015,-0.014156852144525445
80.20000000000044,12.190785599636653,0.4151789054364404,-0.014243253647054033
81.40000000000046,12.23404169239282,0.4190199651727121,-0.0132914619546467
82.60000000000048,12.277022945650803,0.4267182596520789,-0.013532376870637908
83.8000000000005,12.319466146439092,0.4326252740893932,-0.014345283451836721
85.00000000000051,12.362155763915116,0.4410984531222177,-0.014387620396411283
86.20000000000053,12.40492151495451,0.4432166642449238,-0.01689657994658278
87.40000000000055,12.446697391541376,0.4491760690501031,-0.017151360784056102
88.60000000000056,12.48903198171657,0.45764058255520745,-0.016330051265545098
89.80000000000058,12.530463857505415,0.4599749466963303,-0.01673084802303748
91.0000000000006,12.57205963891167,0.46545216976671533,-0.01632211280822693
92.20000000000061,12.612978231883188,0.47093026557137974,-0.016196586765027998
93.40000000000063,12.65464194974834,0.4756559350469962,-0.017754557923012282
94.60000000000065,12.695855080945188,0.4771512952174201,-0.017777352722660122
95.80000000000067,12.736830903482165,0.48127649687713214,-0.018028526471195683
97.00000000000068,12.777569376366952,0.4843712360855673,-0.01771728659466465
98.2000000000007,12.818410247216384,0.48646802691328744,-0.019096776905657364
99.40000000000072,12.859438850633204,0.48903769428942473,-0.01908218868376066
100.60000000000073,12.899923417528237,0.4893631415639215,-0.01827275071735812
101.80000000000075,12.940682062645397,0.4934470746183911,-0.018879773721587334
103.00000000000077,12.980776228110845,0.4957359781464103,-0.01885260415285117
104.20000000000078,13.021775359547219,0.4968243007430025,-0.01887027435852051
105.4000000000008,13.062030318199659,0.4960456265252475,-0.018984293250065676
106.60000000000082,13.10260987780979,0.49817747162509907,-0.01922497061051498
107.80000000000084,13.1432658453655,0.49790423190733957,-0.020517000716107958
109.00000000000085,13.183773409883212,0.4998330161090113,-0.020510030722949324
110.20000000000087,13.22377567139702,0.4979428739700852,-0.02051001822225995
111.40000000000089,13.264104092908743,0.5008147490586811,-0.02051598005165811
112.6000000000009,13.304511264603079,0.49762005869776993,-0.021206659645914172
113.80000000000092,13.345003351146996,0.5002590806450251,-0.022545641891807744
115.00000000000094,13.384991656899906,0.4990581390709836,-0.02249059540765508
116.20000000000095,13.425129048028694,0.5022926928639109,-0.022527496664320523
117.40000000000097,13.465299130484976,0.5003363787244759,-0.022148008382481432
118.60000000000099,13.50535979193418,0.50020243654266,-0.022329709124472075
119.800000000001,13.543975285813481,0.4989066301713467,-0.02208629375801774
121.00000000000102,13.583720486540589,0.5010929504525623,-0.022488275465471386
122.20000000000104,13.624938010623238,0.5009358074576016,-0.022540169445027125
123.40000000000106,13.664844133093954,0.500310079451258,-0.021185159539347964
124.60000000000107,13.704732736705207,0.5016483469395339,-0.022571025355707874
125.80000000000109,13.743927503042274,0.5025209884464839,-0.022480501500223404
127.00000000000111,13.783292204766589,0.5011769738130796,-0.02248002689708173
128.20000000000113,13.822644467071665,0.5007190185705525,-0.02248003103739382
129.40000000000114,13.862314521634888,0.5019348969660434,-0.02248122754688353
130.60000000000116,13.901323166625941,0.5016171870537182,-0.02265645510923653
131.80000000000118,13.940415527046918,0.5059665151654466,-0.022807164814932612
133.0000000000012,13.980102687717181,0.5073954021979052,-0.02281029150670788
134.2000000000012,14.018811028864073,0.5083705272374512,-0.022813274697126573
135.40000000000123,14.057901076309271,0.5115751274359079,-0.0241585281371961
136.60000000000124,14.097054769832315,0.5132158289576845,-0.023808381410097113
137.80000000000126,14.136232165677445,0.5151864062596598,-0.02380762014586235
139.00000000000128,14.174748210883472,0.5170790915444307,-0.024175702307650315
140.2000000000013,14.213605443161914,0.5188973125018712,-0.022946101795543683
141.4000000000013,14.252202499842852,0.5215820172938848,-0.023556032263459592
142.60000000000133,14.291197075269325,0.5249856161414271,-0.02379949288997185
143.80000000000135,14.329207000984574,0.5286477140461076,-0.02380018562029962
145.00000000000136,14.367427014180878,0.5299696757513023,-0.023800186621998343
146.20000000000138,14.406349014808027,0.5353309781976696,-0.023799888210656484
147.4000000000014,14.444665279300317,0.5370723058226938,-0.02375018925195782
148.60000000000142,14.483104743931733,0.5388385357006191,-0.02501446050657652
149.80000000000143,14.521506373162579,0.5425945884635708,-0.026439010265484786
151.00000000000145,14.560000000000047,0.5465699800481203,-0.026440051701878797
152.20000000000147,14.597706316453817,0.5508191888108455,-0.026440034840975013
153.40000000000148,14.63556385771609,0.5540470985609491,-0.026613326239069313
154.6000000000015,14.67409924570939,0.5563889206127611,-0.028985360103001234
155.80000000000152,14.71235121823562,0.5616983599039613,-0.029069969302382148
157.00000000000153,14.750587525829598,0.5641842992291357,-0.029072097667225183
158.20000000000155,14.788510026363374,0.5692205445073022,-0.028415191795081896
159.40000000000157,14.826419698748374,0.5719711437723971,-0.027035603776969452
160.6000000000016,14.864280806851152,0.5750868466972112,-0.027099499836402696
161.8000000000016,14.901310441991772,0.5776801509515179,-0.027094970072380598
163.00000000000162,14.94048668338754,0.5832480234986612,-0.02805954516905862
164.20000000000164,14.978073999763511,0.5858469076019517,-0.02939774497439185
165.40000000000165,15.016041838923867,0.5910326908104376,-0.02939164155871099
166.60000000000167,15.053941709453335,0.5930592793063246,-0.030801757776825145
167.8000000000017,15.091093101609278,0.5949819664713917,-0.030709723103227837
169.0000000000017,15.128034808718102,0.6000655889810733,-0.029362838866224816
170.20000000000172,15.166571219932006,0.6047021132905878,-0.029387911236819608
171.40000000000174,15.204411680955136,0.6084000732297897,-0.030507725380739537
172.60000000000176,15.2423078882103,0.612045940761806,-0.030692325650734986
173.80000000000177,15.279438813178828,0.6154324062504043,-0.03103823326864541
175.0000000000018,15.317211763624366,0.6203310667374671,-0.033762048583430904
176.2000000000018,15.354562026108756,0.6243332047613721,-0.03368070820107372
177.40000000000182,15.392142322957259,0.6251931639831058,-0.03367989923949777
178.60000000000184,15.429215340159688,0.633111465560688,-0.033679733437172565
179.80000000000186,15.466473834676407,0.6363155528981473,-0.0346954844104892
181.00000000000188,15.504069216041268,0.639662487858419,-0.03498802545491664
182.2000000000019,15.541389310497308,0.6442794828206841,-0.03499328155249515
183.4000000000019,15.578008624570295,0.6466702734053695,-0.036233424366943545
184.60000000000193,15.61546792358292,0.6500649911946378,-0.036309276217795006
185.80000000000194,15.652598393858183,0.655575838100769,-0.036309976537781896
187.00000000000196,15.689814640631962,0.6604661531169342,-0.036311637505998196
188.20000000000198,15.726959188807763,0.6668028810118332,-0.037664431270890475
189.400000000002,15.76408235592329,0.6708802076717553,-0.037969143536891625
190.600000000002,15.800808110036556,0.6740630847915773,-0.03894012809434688
191.80000000000203,15.8379131188487,0.6781486764369389,-0.03894007841157032
193.00000000000205,15.874730158338972,0.6845772483426285,-0.03896831091270414
194.20000000000206,15.911562806759408,0.6894631299125773,-0.03953860234716711
195.40000000000208,15.948293655512412,0.6965178552270048,-0.03959704026440569
196.6000000000021,15.985040392455828,0.7002371149690247,-0.04066493073195154
197.80000000000211,16.021706020459963,0.7063601486577088,-0.04091987053666868
199.00000000000213,16.058615074888,0.7119617864916341,-0.042137203166674464
200.20000000000215,16.095480981400048,0.7175418908269011,-0.04225110264239884
201.40000000000217,16.131957392307463,0.7220767963596019,-0.043556227430776584
202.60000000000218,16.169092655092644,0.727102649341685,-0.04354634716164796
203.8000000000022,16.205950789116994,0.734953543563666,-0.045563927415134486
205.00000000000222,16.242954391215775,0.7422643800372501,-0.04739640602387407
206.20000000000223,16.27984593313989,0.7483550233671497,-0.048703482434086176
207.40000000000225,16.31631697447341,0.748832484147476,-0.04931138463431983
208.60000000000227,16.353230719951892,0.7587342871176352,-0.0509937324473313
209.80000000000229,16.389567434900137,0.7630767671901414,-0.05297925744740439
211.0000000000023,16.42639467350142,0.768843103370612,-0.05458760358416903
212.20000000000232,16.46262739947391,0.7747190257832287,-0.05588470306405746
213.40000000000234,16.49920850121396,0.7796444551880028,-0.055840282345279046
214.60000000000235,16.53628296760243,0.7861907896313491,-0.05637501874402773
215.80000000000237,16.572931474055203,0.7888962194438858,-0.0560454395342731
217.0000000000024,16.609125027260927,0.7967931414880518,-0.05751800246573424
218.2000000000024,16.64571052948392,0.7987817783952067,-0.05851728302908921
219.40000000000242,16.682458817177235,0.804584422418208,-0.06131366090118151
220.60000000000244,16.71928893883419,0.8080519565940528,-0.06317802628444324
221.80000000000246,16.7553485464481,0.8157461008840813,-0.06530215759623381
223.00000000000247,16.792545779493786,0.8207694759673608,-0.06706709565412972
224.2000000000025,16.827690715460122,0.8242448399972286,-0.06922658166109708
225.4000000000025,16.86499896482675,0.8292352224117253,-0.0707276608126941
226.60000000000252,16.901571032818417,0.8316229994914947,-0.0719543326245633
227.80000000000254,16.938342375269723,0.8390081053110392,-0.0740720354649258
229.00000000000256,16.97457556920421,0.8382857856074518,-0.07594685094295706
230.20000000000258,17.01096199841917,0.8426240457760047,-0.07900590343990022
231.4000000000026,17.047479561363144,0.8471098272054172,-0.08104777147211095
232.6000000000026,17.08397256510424,0.852884358383758,-0.0832356058935142
233.80000000000263,17.120405024671474,0.8545726977254732,-0.08634685629000094
235.00000000000264,17.156760032373956,0.8575118535405228,-0.08821101798483921
236.20000000000266,17.19293980493644,0.8595771775352236,-0.0909551388732055
237.40000000000268,17.229583859553696,0.8615357704035876,-0.09352557582354581
238.6000000000027,17.265943836791852,0.8652269203294495,-0.09703074336717421
239.8000000000027,17.302186541295494,0.8704244793578324,-0.10059479143593286
241.00000000000273,17.33883159057248,0.8775918729113531,-0.10339948669999277
242.20000000000275,17.375133668209262,0.8801236358986371,-0.1059475689724998
243.40000000000276,17.411403398688766,0.886100224587921,-0.10894731076324415
244.60000000000278,17.447828804128655,0.8942298759573755,-0.11148575266511962
245.8000000000028,17.48420588139855,0.9002975375828173,-0.11489580318984238
247.0000000000028,17.52046101966479,0.9081327716817349,-0.11828470606650843
248.20000000000283,17.556545641649585,0.9155266707748057,-0.12119886384767309
249.40000000000285,17.592976861421523,0.9210811475023803,-0.12374937983015766
250.60000000000286,17.629339774195373,0.9200373314491277,-0.12607992829954817
251.80000000000288,17.665560721638293,0.9179790905942189,-0.13014766964105995
253.0000000000029,17.701960449953013,0.9105356164895408,-0.13417797542216814
254.20000000000292,17.738438932955177,0.9007617147637168,-0.13802830195048177
255.40000000000293,17.77440064771628,0.8938313845971562,-0.14085483032818047
256.600000000003,17.810599278800794,0.8852243829218613,-0.14572807035540425
257.80000000000297,17.84704325757095,0.8797038327461599,-0.14953839105500055
259.00000000000296,17.883040157774374,0.8762817555936462,-0.15203130448497637
260.200000000003,17.919366164926767,0.8709677504806448,-0.15587665501218329
261.40000000000305,17.95570221498267,0.8695948822200865,-0.16014941783151881
262.60000000000304,17.992047024209874,0.866625446970646,-0.1649798414287833
263.800000000003,18.02797321074541,0.8658824336610922,-0.16891189695117959
265.00000000000307,18.064467233592804,0.8634898900775689,-0.17357625385052833
266.2000000000031,18.100394809498734,0.8625946518339731,-0.1795143608995744
267.4000000000031,18.13686429558504,0.8636482641054752,-0.18594425673202064
268.6000000000031,18.173084045940783,0.860536916535857,-0.1918627525457235
269.80000000000314,18.209222913748167,0.8579585847354536,-0.19829753931374405
271.0000000000032,18.24544537419966,0.8583073530863188,-0.20424519076125236
272.2000000000032,18.28164281670931,0.8560140940197773,-0.21075329948814447
273.40000000000316,18.31771936222448,0.8560761567186876,-0.21710839058183762
274.6000000000032,18.35373303475725,0.8556960609391973,-0.22493415900161473
275.80000000000325,18.390208800413536,0.855033408660336,-0.2320206020940856
277.00000000000324,18.426359170706096,0.8534188797673539,-0.24012965095834948
278.20000000000323,18.462598987116266,0.8509614103524741,-0.2475705292233159
279.4000000000033,18.498858343625514,0.8482955805551435,-0.2558082384811162
280.6000000000033,18.53483336897921,0.8442156940725205,-0.26556617483226175
281.8000000000033,18.571275406524325,0.8420650278588235,-0.2774109438616299
283.0000000000033,18.606750311584182,0.8391093873531739,-0.28656373845843675
284.20000000000334,18.643974742437273,0.8362702856982211,-0.29847236450313863
285.4000000000034,18.679880030383504,0.8303736628143137,-0.30807747666383367
286.6000000000034,18.716228350520705,0.8253976487115309,-0.3187065172766239
287.80000000000337,18.752616005413103,0.8190749651607736,-0.33079656823970227
289.0000000000034,18.78876703382504,0.8147140450988517,-0.3455746772005144
290.20000000000346,18.825337730166506,0.8075653157810714,-0.35819320176862757
291.40000000000344,18.86155654506471,0.8012268861098701,-0.3706342537065548
292.60000000000343,18.897762962732955,0.7935943734279207,-0.3847401845419438
293.8000000000035,18.93426417368105,0.7867863852528281,-0.39934687629459864
295.0000000000035,18.97039254286238,0.7791092227034844,-0.4132688669889455
296.2000000000035,19.00659977453634,0.7717594452466794,-0.4286231708669308
297.4000000000035,19.043225726341213,0.7646660857931198,-0.4446406979498221
298.60000000000355,19.078972115863742,0.7560407704864767,-0.4611805504009556
299.8000000000036,19.11544369916863,0.7462332492602668,-0.47890229219485425
301.0000000000036,19.151543981768672,0.7360076996964919,-0.49628901553215377
302.20000000000357,19.187673569796733,0.72956670896192,-0.5140745987153874
303.4000000000036,19.22428335407487,0.7179513376854265,-0.5326796669859455
304.60000000000366,19.260296927231654,0.7065637762113506,-0.5513621124737473
305.80000000000365,19.2966052732247,0.6983100858242928,-0.5712570032881388
307.00000000000364,19.33284433926601,0.6905473977350336,-0.5923180433189432
308.2000000000037,19.36891453440728,0.6796973329365854,-0.6136203819656227
309.40000000000373,19.404845314095926,0.6724693280770324,-0.6342552867263103
310.6000000000037,19.442047761505478,0.6633842259795808,-0.6565135170844516
311.8000000000037,19.478151650789115,0.6555795366797927,-0.678829199767371
313.00000000000375,19.514266998699675,0.6475386860608554,-0.7010167616073542
314.2000000000038,19.55054581015045,0.6423764374414931,-0.724121950367528
315.4000000000038,19.586777519706306,0.6355067851551257,-0.7483684014184213
316.6000000000038,19.622474663689083,0.6296364811026112,-0.7716621339459335
317.8000000000038,19.659412935223045,0.6212157931844124,-0.7947956625711874
319.00000000000387,19.69548498770885,0.6164135338526044,-0.8183940829245384
320.20000000000385,19.7318700310547,0.6126317506573105,-0.8420167431618366
321.40000000000384,19.768330338468946,0.6102546145820014,-0.8659851525420805
322.6000000000039,19.80475745835737,0.6076278992230437,-0.890702972870399
323.80000000000393,19.839904924084777,0.6009579327448262,-0.9150552601774478
325.0000000000039,19.87715742791905,0.6014764490488602,-0.9406748463215489
326.2000000000039,19.913596774922343,0.6015129256542104,-0.9649046794481397
327.40000000000396,19.949877655464846,0.6004731589813703,-0.9900490561386173
328.600000000004,19.986746641200334,0.6027664902481762,-1.0166213599700775
329.800000000004,20.023176784758135,0.6054231021152674,-1.0424707066160788
331.000000000004,20.059575915541092,0.6078997325018174,-1.0658809771488915
332.200000000004,20.09616233726428,0.6112365658555066,-1.0906806890002239
333.40000000000407,20.13249930525691,0.6161039700441564,-1.1156245036241903
334.60000000000406,20.169078140606764,0.6192495768062158,-1.140329426301114
335.80000000000405,20.205498137965417,0.6236751976435952,-1.1651179687792284
337.0000000000041,20.242056115003603,0.6276036977508066,-1.1903083156364578
338.20000000000414,20.278642766125962,0.6366729577901391,-1.21623044260097
339.4000000000041,20.315200420790184,0.6444406030562975,-1.2395885996065412
340.6000000000041,20.351570052145878,0.6506755528796315,-1.2647022910207184
341.80000000000416,20.388237362981076,0.6605433054185774,-1.2904805763887612
343.0000000000042,20.424814931555602,0.6742466960398348,-1.3159820869074408
344.2000000000042,20.461455655936913,0.6848721984114774,-1.3413667374602545
345.4000000000042,20.498207839444092,0.6953948046932605,-1.368149871779503
346.60000000000423,20.53475985293193,0.7072266493616222,-1.3921469373612432
347.8000000000043,20.571431198434652,0.7234003220716159,-1.4154032724891707
349.00000000000426,20.60828959782848,0.7395757994003942,-1.4409662929376497
350.20000000000425,20.644774083044933,0.75533713655957,-1.4674172024040648
351.4000000000043,20.681458640671384,0.7699879148324409,-1.4936684570416676
352.60000000000434,20.718282199672657,0.7919133959036988,-1.521236560521098
353.80000000000433,20.75511388174959,0.815972391129907,-1.5509507825685098
355.0000000000043,20.791633958456295,0.8412917336009751,-1.5784663374810695
356.20000000000437,20.828603659845044,0.8638156640620307,-1.608516063316543
357.4000000000044,20.865484402355168,0.8916865983728863,-1.638364933830525
358.6000000000044,20.902221734867084,0.9241631601111331,-1.6679628324334477
359.8000000000044,20.939064480600656,0.954873470578754,-1.7004775486788852
361.00000000000443,20.975033651095853,0.9881891207285307,-1.7321830320285683
362.2000000000045,21.01270486123222,1.0277074780596478,-1.7663370467838289
363.40000000000447,21.04988111472296,1.0689581534991937,-1.8004748203179006
364.60000000000446,21.086429348114038,1.1106871282444868,-1.8374632644908044
365.8000000000045,21.123350207857982,1.1561736356227597,-1.8769096128353628
367.00000000000455,21.160429201755036,1.2055441701057978,-1.917669394282667
368.20000000000454,21.197423108761097,1.251043728826681,-1.9596514579842252
369.4000000000045,21.234469753548648,1.2976871579588267,-2.0052966802530525
370.60000000000457,21.271496312045404,1.341219698890724,-2.054259919744519
371.8000000000046,21.308744209100965,1.3730408608789557,-2.104518355152488
373.0000000000046,21.345627896136648,1.393381881050864,-2.155880640726048
374.2000000000046,21.38270208179395,1.3999287472678752,-2.2103200092433664
375.40000000000464,21.41993840781258,1.3840091819351152,-2.2654782431158855
376.6000000000047,21.456882323614575,1.3399598088261344,-2.318998208800606
377.8000000000047,21.494137154165177,1.272175445780616,-2.373942630658871
379.00000000000466,21.531131865913654,1.174950703237554,-2.426631985866485
380.2000000000047,21.568103322798894,1.0593064388533666,-2.4753771225097685
381.40000000000475,21.605410733505956,0.9265445774957732,-2.5209022438778774
382.60000000000474,21.642651240505955,0.7861048868102083,-2.563092460457329
383.80000000000473,21.679625501949207,0.6474437320637467,-2.6003029660592123
385.0000000000048,21.716611783453995,0.5173334881984566,-2.6320071114312102
386.2000000000048,21.75317946428133,0.3961020193716369,-2.6575047885835823
387.4000000000048,21.790537076373532,0.2879179132428089,-2.6805437342527982
388.6000000000048,21.827217244307917,0.19728058804906823,-2.6992129499069755
389.80000000000484,21.864042863547102,0.11900257416852145,-2.714470609400343
391.0000000000049,21.901322654395848,0.05320157395401459,-2.728320097352844
392.2000000000049,21.938493484539467,-0.0025456777565118216,-2.7393242053237215
393.40000000000487,21.97567160553167,-0.04964268971713515,-2.747988381856513
394.6000000000049,22.01249500195437,-0.08740040349577738,-2.7552723249816244
395.80000000000496,22.049779438367683,-0.12007371207049844,-2.762524020751136
397.00000000000495,22.086659690285472,-0.14627790712959743,-2.768810483160393
398.20000000000493,22.123703972564297,-0.17173876299393576,-2.7734448606113897
399.400000000005,22.16091778872503,-0.19266932341029697,-2.780096284090383
400.600000000005,22.198326856048688,-0.21001553183149801,-2.785340851186003
401.800000000005,22.23537612704339,-0.22661036105499544,-2.7905561717597553
403.000000000005,22.27264540748162,-0.24274695432852078,-2.795999221285792
404.20000000000505,22.309711574908142,-0.2589882281403477,-2.80123252201874
405.4000000000051,22.347444152430853,-0.27069175016826663,-2.8066252757862715
406.6000000000051,22.38418420626168,-0.28231699441491376,-2.8098985491275768
407.80000000000507,22.421173079902328,-0.2950285909446002,-2.8131312932055206
409.0000000000051,22.458706886707706,-0.30530332249558034,-2.8168514855572644
410.20000000000516,22.496031658742158,-0.31725965519005483,-2.820833849063536
411.40000000000515,22.533365857394898,-0.32948103139982066,-2.8246594433242094
412.60000000000514,22.570613118626998,-0.33754683221777326,-2.82950196969108
413.8000000000052,22.60801880837397,-0.3490643593148677,-2.83319173776732
415.00000000000523,22.64554513729788,-0.3567554397964836,-2.8363944599810935
416.2000000000052,22.68267486467563,-0.3654776849047787,-2.8395545962132616
417.4000000000052,22.720559413678718,-0.3756554251217459,-2.8442135167821196
418.60000000000525,22.757807586396133,-0.38292549563681266,-2.8475134125025274
419.8000000000053,22.795205414403238,-0.39398027577822914,-2.8512874733816744
421.0000000000053,22.83252918064066,-0.3994472161748013,-2.856684568001846
422.2000000000053,22.870218480869934,-0.40593406272395427,-2.860528481366117
423.4000000000053,22.907398150522315,-0.4133167694729256,-2.8620224782165025
424.60000000000537,22.945349804853638,-0.4191067873311429,-2.8649975652184745
425.80000000000535,22.982517181410465,-0.4272646479652631,-2.8681458402968385
427.00000000000534,23.020091381444605,-0.4329880273042448,-2.870929052831451
428.2000000000054,23.05756961101385,-0.4395563148490105,-2.8738045179939498
429.40000000000543,23.095376425915145,-0.44437967032134496,-2.878075129280445
430.6000000000054,23.132675948770416,-0.4485502797635206,-2.8813846325160712
431.8000000000054,23.17024438183805,-0.45314382423912436,-2.8847740722791575
433.00000000000546,23.20804047928328,-0.4575901591508684,-2.8874641042191764
434.2000000000055,23.244978334202315,-0.46061441925622604,-2.890576712471388
435.4000000000055,23.283287148022385,-0.46533209300880785,-2.8926650694182414
436.6000000000055,23.32047373689976,-0.4658397712432101,-2.8948753176783995
437.8000000000055,23.357743497641476,-0.4696034413316761,-2.8984955746589725
439.00000000000557,23.396187671345324,-0.47060305862035534,-2.902256156063398
440.20000000000556,23.434169505394966,-0.47401106889231137,-2.9052713796387764
441.40000000000555,23.471729545690835,-0.47451756536656653,-2.9081046700596938
442.6000000000056,23.509189306911306,-0.4750445750636658,-2.910650200828379
443.80000000000564,23.546048425226235,-0.473088444094691,-2.912856288157887
445.0000000000056,23.5850033032237,-0.4740416455280754,-2.916444258344981
446.2000000000056,23.62257319204223,-0.47566239767234575,-2.91966119682227
447.40000000000566,23.660438512724685,-0.47158618265268437,-2.9213085819864864
448.6000000000057,23.698438895036084,-0.473096255509057,-2.924238048032911
449.8000000000057,23.73594743605729,-0.4708360853689042,-2.92711535414941
451.0000000000057,23.77401977297068,-0.46727373600265043,-2.931679600167499
452.20000000000573,23.812244660523664,-0.4663584230365334,-2.934631018902197
453.4000000000058,23.848999273774854,-0.46590393980668776,-2.9363655320126196
454.60000000000576,23.88756578874196,-0.46119983604608406,-2.938307017981523
455.80000000000575,23.92556649316996,-0.4597588197800768,-2.9427038693612997
457.0000000000058,23.96362633085965,-0.4556860708673425,-2.9449364030421994
458.20000000000584,24.001413832027115,-0.44998537464515964,-2.9482038511411526
459.40000000000583,24.03917977674138,-0.44739309897136215,-2.9517934952008607
460.6000000000058,24.077256715704692,-0.44361874128152334,-2.9545074819815227
461.80000000000587,24.11541215049788,-0.43954477823097826,-2.9569277565181973
463.0000000000059,24.15308044594517,-0.43325735975763147,-2.9584438778483895
464.2000000000059,24.19127327585969,-0.4321018874089684,-2.9607448276660704
465.4000000000059,24.229084720428325,-0.42793926250925973,-2.9617225664465368
466.60000000000593,24.267178220728987,-0.42137925877438787,-2.964818273443522
467.800000000006,24.305361183232208,-0.4151369737810846,-2.9669754952020697
469.00000000000597,24.343156137303644,-0.41234265568863915,-2.9697862898340586
470.20000000000596,24.381426952697037,-0.40837987059728387,-2.9728278568932147
471.400000000006,24.419415229226136,-0.403407270687419,-2.9741892874508573
472.60000000000605,24.457487231432832,-0.3957533912286231,-2.9747773563627495
473.80000000000604,24.495625684432913,-0.3936989123699488,-2.9759744652443585
475.000000000006,24.533510075755423,-0.3896715448599888,-2.978880547496443
476.20000000000607,24.571670444683647,-0.3841965114722421,-2.981777181260365
477.4000000000061,24.609873076464602,-0.38042031630803885,-2.9835668811736484
478.6000000000061,24.648045092791012,-0.3785035363889371,-2.9864308690058388
479.8000000000061,24.686437988190153,-0.3707123572090232,-2.9882887183085116
481.00000000000614,24.724541037533676,-0.3704880136806339,-2.9900163164757427
482.2000000000062,24.762514683031537,-0.3660227334069517,-2.9925156285297927
483.4000000000062,24.800995686510838,-0.3616306835863228,-2.993214629959005
484.60000000000616,24.83868893152615,-0.3609880323056964,-2.995171346191281
485.8000000000062,24.877529587064792,-0.3567732557446721,-2.997370492205748
487.00000000000625,24.915605322953677,-0.35384231853460135,-2.999248181737243
488.20000000000624,24.954200271352043,-0.35089732064440105,-3.00137453784033
489.40000000000623,24.992426393292316,-0.3512485563046104,-3.0033056306906283
490.6000000000063,25.030397011129367,-0.3483553866114122,-3.005087156476375
491.8000000000063,25.06881166444725,-0.3460814610780574,-3.0063464908615782
493.0000000000063,25.10661345327621,-0.34341245214745686,-3.0080660101067878
494.2000000000063,25.14537270098543,-0.3389969481444395,-3.010357373593199
495.40000000000634,25.18366700778171,-0.33681623356463497,-3.0121510460667342
496.6000000000064,25.221994855071916,-0.34051313182751364,-3.0135605716014
497.8000000000064,25.260389498155792,-0.33793433688950003,-3.015037190606721
499.00000000000637,25.29881589999885,-0.33523503105324903,-3.016493400451534
500.2000000000064,25.337099439083556,-0.3337416490485836,-3.0178225614517973
501.40000000000646,25.37559527386666,-0.33483086702638576,-3.0191877798500673
502.60000000000645,25.414193805980723,-0.3321103982199345,-3.0205118509684867
503.80000000000643,25.452242040853164,-0.3337386534712141,-3.0215642398577187
505.0000000000065,25.49076401706196,-0.33190891578720505,-3.0221445322371947
506.2000000000065,25.529306327053273,-0.33174471557320584,-3.024646163956525
507.4000000000065,25.567686821904626,-0.33010714962679555,-3.026420437306042
508.6000000000065,25.60609779044693,-0.3299362913911734,-3.0276905098589255
509.80000000000655,25.644617446266302,-0.32877842732908147,-3.028907745707099
511.0000000000066,25.683090082812353,-0.32951972133864715,-3.0292349538200236
512.2000000000066,25.721774333538455,-0.3306247451781754,-3.0320046468608393
513.4000000000066,25.760063062545473,-0.3302294825794061,-3.0340283829290744
514.6000000000066,25.798477665790625,-0.32958261455640314,-3.035368463581281
515.8000000000067,25.83716890389276,-0.3266807456767349,-3.035754061238198
517.0000000000066,25.87573081207727,-0.32853229565514774,-3.037979392408899
518.2000000000066,25.91464604100303,-0.32814991619532896,-3.0401415021369838
519.4000000000067,25.952994920488592,-0.3272817569832014,-3.0414825497417572
520.6000000000067,25.991638687538398,-0.32834681817318767,-3.0427271435783982
521.8000000000068,26.029869218527438,-0.3286753657761716,-3.0426918213147216
523.0000000000067,26.068783565953485,-0.3305916170781682,-3.0440195350998103
524.2000000000068,26.107213724316374,-0.3307452491298808,-3.0454574911152834
525.4000000000068,26.14572169453655,-0.33173113994313197,-3.0467279895021058
526.6000000000067,26.184607422621514,-0.33162464275195114,-3.0467523224432327
527.8000000000068,26.223119751413638,-0.33339147689768023,-3.0475347901663103
529.0000000000068,26.26203981396507,-0.3356635724041359,-3.0491417322353684
530.2000000000069,26.300790895501564,-0.3346256685598208,-3.050396555172206
531.4000000000069,26.339097545155344,-0.33514811825225266,-3.051751469676531
532.6000000000068,26.37794011253397,-0.3357081679847016,-3.052996937278037
533.8000000000069,26.41645071804081,-0.3368159097438357,-3.053209772285079
535.0000000000069,26.4554641746931,-0.33754132744554743,-3.0547537096309005
536.2000000000069,26.494202874315803,-0.3395425496109179,-3.0573914997014784
537.4000000000069,26.532724798051824,-0.3389165006151571,-3.058162444985874
538.600000000007,26.57172863304969,-0.3405053636551787,-3.0585969821193997
539.800000000007,26.61019976089065,-0.3385721145145999,-3.059605653664372
541.000000000007,26.649317073825323,-0.3363428322726356,-3.060508626253827
542.200000000007,26.6877973458239,-0.335012525727131,-3.060464965452684
543.400000000007,26.726661941991388,-0.33677985193922066,-3.062095492300383
544.6000000000071,26.765229426188885,-0.33763978510033343,-3.0636072174845546
545.800000000007,26.80461969396934,-0.3346271410207404,-3.0648684504571464
547.000000000007,26.843132019714538,-0.33481248426247157,-3.0662083230596133
548.2000000000071,26.88196103697428,-0.3357058639986996,-3.066029531820483
549.4000000000071,26.920737094584975,-0.3365993909632665,-3.06754550697739
550.6000000000072,26.95970627508457,-0.33460426425326917,-3.068556342504251
551.8000000000071,26.99870172651559,-0.3356145933585002,-3.069561769177338
553.0000000000072,27.037399120033115,-0.33463522128828904,-3.0695596806166012
554.2000000000072,27.07619913596266,-0.3335244816474232,-3.070559116329319
555.4000000000071,27.115222819702712,-0.3374553470955204,-3.0713674241558477
556.6000000000072,27.153960024620314,-0.335457254698756,-3.073149879819974
557.8000000000072,27.193011564609332,-0.33492748940065153,-3.0744864783389194
559.0000000000073,27.231878289453793,-0.33391035907666966,-3.0750100626965247
560.2000000000073,27.270940731750315,-0.3329853721420797,-3.0758113410597696
561.4000000000073,27.30999933734785,-0.333021948585112,-3.0771398781792656
562.6000000000073,27.348055441041733,-0.33396940482074244,-3.078608654918313
563.8000000000073,27.3878621966169,-0.33457771387349267,-3.0798822206046323
565.0000000000073,27.426911095391997,-0.3358555199043851,-3.079829325900632
566.2000000000073,27.465875130004527,-0.33587582845529784,-3.081180693821219
567.4000000000074,27.50492240199069,-0.33562732809636353,-3.0816300248554103
568.6000000000074,27.543889659652557,-0.33636172053082647,-3.0828130299528507
569.8000000000075,27.582942926859225,-0.33517344316729614,-3.0846111459633647
571.0000000000074,27.622131697590866,-0.3387414013745329,-3.086303366949705
572.2000000000074,27.660672001182288,-0.33700898715026706,-3.0868150391559825
573.4000000000075,27.699967180252816,-0.33634027858381077,-3.08809987991851
574.6000000000074,27.739380287538488,-0.3418627236413252,-3.0880696135083774
575.8000000000075,27.778314213536273,-0.3430351627836723,-3.0894239273710578
577.0000000000075,27.816662743603988,-0.3410357725245954,-3.088960009907549
578.2000000000075,27.856455606436622,-0.3463486181608142,-3.0894224301791446
579.4000000000076,27.895454439508182,-0.34588700388457716,-3.089927351049663
580.6000000000075,27.934636647575896,-0.34617878275658254,-3.0907322849687153
581.8000000000076,27.973646237324285,-0.3514901757375264,-3.091045530524697
583.0000000000076,28.01186920471638,-0.3511535127358645,-3.0921955405139165
584.2000000000075,28.051701346805764,-0.3567883188027854,-3.0933608280304714
585.4000000000076,28.091278836850353,-0.35563092115538475,-3.093443853857465
586.6000000000076,28.130096503503808,-0.35824435120893106,-3.0946801474839516
587.8000000000077,28.169238807081214,-0.35827484713304947,-3.0952770435899017
589.0000000000077,28.20867470691148,-0.36078368228872115,-3.0960159919528794
590.2000000000077,28.24783992914757,-0.36605715822925533,-3.097313138868042
591.4000000000077,28.286646073281766,-0.3663208815670145,-3.0983498712079647
592.6000000000078,28.325818229339934,-0.36876502501539843,-3.0973241008722043
593.8000000000077,28.365201873393183,-0.37189032021792356,-3.098204061697599
595.0000000000077,28.40430281468718,-0.3754214185377025,-3.0988592481677184
596.2000000000078,28.443517065032342,-0.375113050591968,-3.1015844807168875
597.4000000000078,28.482893132587982,-0.37979387094819383,-3.1025762047814847
598.6000000000079,28.522145779624807,-0.37901355185396257,-3.1038690140583407
599.8000000000078,28.561181288522192,-0.38327741731692866,-3.1038890468550098
601.0000000000078,28.60042179198266,-0.38502181399700564,-3.1045856065362543
602.2000000000079,28.639836313422887,-0.38920353220984727,-3.1052067046203
603.4000000000078,28.67908576181246,-0.39361129417996366,-3.105913354010788
604.6000000000079,28.71811188580053,-0.39161958883771164,-3.105551088843358
605.8000000000079,28.756577531687707,-0.3993891723036038,-3.1055496013888346
607.000000000008,28.79656576998061,-0.3981805449316831,-3.105455703131846
608.200000000008,28.83584767592004,-0.40076168572854076,-3.10749259750341
609.4000000000079,28.875097735752004,-0.40079779570740937,-3.1078415390915457
610.600000000008,28.914562256152877,-0.4042286768681522,-3.1092525169292715
611.800000000008,28.953672881204483,-0.4054925021577118,-3.1094757750692574
613.000000000008,28.99283491085064,-0.40847527128513716,-3.110476830294336
614.200000000008,29.032618125885403,-0.40993719618459523,-3.1116332008357004
615.400000000008,29.071824549709824,-0.40925087140225447,-3.111924426187043
616.6000000000081,29.111194916728877,-0.41376796046162,-3.113116219493196
617.8000000000081,29.15055338078447,-0.4164969609055369,-3.114422765162056
619.0000000000081,29.189837736048947,-0.41910943764763053,-3.115847498831034
620.2000000000081,29.22933273076235,-0.42228877240727725,-3.1157772194821662
621.4000000000082,29.268837336008907,-0.42246565019124027,-3.115861001078329
622.6000000000081,29.308068553349603,-0.42498580575246114,-3.117204697430984
623.8000000000081,29.347437499509184,-0.42799206547882074,-3.117081161617013
625.0000000000082,29.386662352395664,-0.42952461063604885,-3.1184884276746105
626.2000000000082,29.426237509955634,-0.4272242385521168,-3.1183898962529515
627.4000000000083,29.465654647841074,-0.4302414609213041,-3.1198214546018166
628.6000000000082,29.50538175587275,-0.4358716228546742,-3.1211715142489895
629.8000000000083,29.544620522110858,-0.43608172160578595,-3.1211201457298774
631.0000000000083,29.584127474801598,-0.4391236315721252,-3.121119491694437
632.2000000000082,29.6236038094749,-0.4470034121116111,-3.1210514897008483
633.4000000000083,29.662931264062387,-0.44600399893417464,-3.1225442094861684
634.6000000000083,29.702493355756097,-0.44810335150043623,-3.1230518016010373
635.8000000000084,29.741939349526678,-0.4500085330515897,-3.1235326374560497
637.0000000000084,29.781320158893863,-0.4522071045012208,-3.1238535754044516
638.2000000000083,29.820756390866485,-0.45633359029847376,-3.124581853857684
639.4000000000084,29.860513930215173,-0.45740229468837623,-3.1251789239069567
640.6000000000084,29.900065942074043,-0.4606108360509935,-3.1264989622515515
641.8000000000084,29.93964533220347,-0.46015107483770645,-3.1268014589498474
643.0000000000084,29.979054616607023,-0.4636262422544408,-3.1278093274699796
644.2000000000085,30.018663746318143,-0.46703483511523713,-3.1290800118007676
645.4000000000085,30.05825327617122,-0.4672375149117336,-3.129122384238954
646.6000000000085,30.097880714098174,-0.468692145813443,-3.1277588500591103
647.8000000000085,30.137465083781642,-0.4727089944228533,-3.127809911177143
649.0000000000085,30.17691584081575,-0.47482914716852576,-3.1278047647377516
650.2000000000086,30.216550564977485,-0.47790465173445384,-3.1291118375370037
651.4000000000085,30.256057371175057,-0.47875777198292147,-3.1290386646622514
652.6000000000085,30.29558691751063,-0.47971802132498675,-3.13043808265504
653.8000000000086,30.335094913994908,-0.4813663922970304,-3.1317180122263064
655.0000000000086,30.3746473619288,-0.4856677270243328,-3.1331690790786744
656.2000000000087,30.414125993727044,-0.4881711729892597,-3.131804167047683
657.4000000000086,30.45375211146006,-0.4887042215672188,-3.132960798987517
658.6000000000087,30.493432160697278,-0.4910656796120685,-3.133035288811228
659.8000000000087,30.533033114076535,-0.49036592598397744,-3.1343802308529902
661.0000000000086,30.572768820709374,-0.49526335889915796,-3.1334491419508974
662.2000000000087,30.612249873099547,-0.4961095736184271,-3.1334003642736405
663.4000000000087,30.65218226140345,-0.4984471721467081,-3.133411325876536
664.6000000000088,30.691430885979084,-0.5004916221226821,-3.134724679824158
665.8000000000088,30.731154885158528,-0.5034182880714648,-3.136080292192114
667.0000000000088,30.770871428777937,-0.5035306226787064,-3.137088688467924
668.2000000000088,30.81053209198464,-0.50492304973287,-3.138791370096425
669.4000000000088,30.85050458021013,-0.5085303407341992,-3.1399816792037107
670.6000000000088,30.889146802456708,-0.5078981544474455,-3.139980135026482
671.8000000000088,30.92953800347856,-0.5109456433665733,-3.139979142204173
673.0000000000089,30.969154605085254,-0.5117093965503514,-3.14127219000746
674.2000000000089,31.00890701826315,-0.5110528202557039,-3.1413003950077427
675.400000000009,31.04881670755708,-0.5100245200904425,-3.1418650217403963
676.6000000000089,31.088389595364912,-0.5138301516449435,-3.141540422089144
677.8000000000089,31.128267800113647,-0.5188510548600507,-3.1416294562639635
679.000000000009,31.16794095414982,-0.5172095825111476,-3.1416298695703295
680.2000000000089,31.207428994382482,-0.5189204311329283,-3.1416263624034917
681.400000000009,31.247329693753322,-0.5205847446143332,-3.1428224348786196
682.600000000009,31.287033672206174,-0.5253416865735849,-3.142938745657737
683.800000000009,31.326677725417042,-0.5285974192399008,-3.1439791339071257
685.0000000000091,31.366359019996658,-0.5311025956483635,-3.1442587716093646
686.200000000009,31.405976817593352,-0.5330019928613539,-3.1442596260418143
687.4000000000091,31.445790209829156,-0.5350019795946523,-3.1441717887142047
688.6000000000091,31.485536041501074,-0.53606467294888,-3.145578634333737
689.800000000009,31.525050256828195,-0.5402325745341441,-3.145579981229259
691.0000000000091,31.564925035073145,-0.5418582414223698,-3.1455801211663825
692.2000000000091,31.60467058697382,-0.5477201266149725,-3.145608164711814
693.4000000000092,31.644624060175907,-0.5478839724243154,-3.144089106882972
694.6000000000092,31.684279132154256,-0.5494509494832687,-3.144993962083131
695.8000000000092,31.72375672554695,-0.5534944595370472,-3.1449204924564302
697.0000000000092,31.76358896416418,-0.5556823504480031,-3.144926700686655
698.2000000000093,31.80362328678063,-0.5566518465372723,-3.14524223184927
699.4000000000092,31.843398789694707,-0.5592075409269195,-3.1455385214876053
700.6000000000092,31.883403225106566,-0.5633419992343287,-3.146570500564767
701.8000000000093,31.92335938793795,-0.5644151565503412,-3.1465786346677285
703.0000000000093,31.963011493032525,-0.5689859572678495,-3.1479336771905295
704.2000000000094,32.0026775885509,-0.5705015528110027,-3.1479088913903355
705.4000000000093,32.04254478875483,-0.5720465279991,-3.150567475917409
706.6000000000093,32.082583144483166,-0.5763847629664742,-3.1516769527161124
707.8000000000094,32.1224244850049,-0.5771230455045646,-3.151842216137606
709.0000000000093,32.16232412622439,-0.5804728262837657,-3.153147148132227
710.2000000000094,32.20209441243292,-0.5843518894668358,-3.1531399272527345
711.4000000000094,32.241873802379054,-0.5847891021576828,-3.153139892161186
712.6000000000095,32.28166336278611,-0.5911088320100186,-3.153139892148366
713.8000000000095,32.32196896001235,-0.5908260915340637,-3.1531399197032
715.0000000000094,32.361932697809245,-0.5949116193201731,-3.1531453413971704
716.2000000000095,32.402172969506,-0.5957148572762052,-3.1519330688114815
717.4000000000095,32.44198179124397,-0.5966322559652166,-3.152653882133635
718.6000000000095,32.48171413607226,-0.6012232487437879,-3.153115260014274
719.8000000000095,32.52197921043914,-0.5996110318195802,-3.1544687898892816
721.0000000000095,32.561737310826445,-0.6029734132158873,-3.154470018108565
722.2000000000096,32.60176249357099,-0.6073950536192338,-3.154470023512167
723.4000000000096,32.641579233862,-0.6086200323582691,-3.1544699390112507
724.6000000000096,32.68182095681097,-0.6091410117972598,-3.1544525363244005
725.8000000000096,32.722125416868266,-0.612714592821916,-3.155767645107531
727.0000000000097,32.76174763462469,-0.6172701918273167,-3.1555900746209127
728.2000000000096,32.80201463495395,-0.622470488357906,-3.154457678356745
729.4000000000096,32.841856877849224,-0.6204931518155954,-3.1548043575785742
730.6000000000097,32.88183255462738,-0.6253631951684193,-3.155793412478358
731.8000000000097,32.92203656197444,-0.6237854281522086,-3.157104513576656
733.0000000000098,32.96221173776585,-0.628168955964366,-3.1557730296926447
734.2000000000097,33.00206209229493,-0.63032304709589,-3.1570922462229305
735.4000000000098,33.042185474176144,-0.6298685773349697,-3.157067540261543
736.6000000000098,33.081886286498744,-0.6341080750071035,-3.1583978738451925
737.8000000000097,33.12241504658859,-0.6327752784591105,-3.159289373261917
739.0000000000098,33.16247327930674,-0.63733346084683,-3.160985846969652
740.2000000000098,33.202572607979796,-0.6414468018162958,-3.161149898631902
741.4000000000099,33.24244248805231,-0.6454818313358501,-3.1611503313322458
742.6000000000099,33.2825631350701,-0.6464157451608488,-3.1612134624783255
743.8000000000098,33.32310121340442,-0.6479239867619082,-3.160484846264
745.0000000000099,33.36308579615324,-0.6463214056785294,-3.1604899905646375
746.2000000000099,33.40311159496432,-0.6489829148694901,-3.1604900192938112
747.4000000000099,33.4428468201917,-0.6523335166419595,-3.1604906421285004
748.6000000000099,33.482985021532016,-0.6544187736396068,-3.160625433476601
749.80000000001,33.523121968328944,-0.6557145339890931,-3.161472857272684
751.00000000001,33.56331102472478,-0.659840271589855,-3.1611610725556627
752.20000000001,33.60381240911685,-0.6597414511988471,-3.161157323822178
753.40000000001,33.643726044039695,-0.661293671176526,-3.1621203140547243
754.60000000001,33.68404597208911,-0.6662108735109693,-3.162479130465747
755.8000000000101,33.7241293026658,-0.666715354410754,-3.1624806411198554
757.00000000001,33.76448182749784,-0.6623243366624769,-3.1625808298863487
758.20000000001,33.80448598127772,-0.6593930081370236,-3.1611587413312803
759.4000000000101,33.84497021851852,-0.6633643279196253,-3.1621983709657453
760.6000000000101,33.88498647128905,-0.6681549070861994,-3.1636162860794173
761.8000000000102,33.925434894689595,-0.6668366790382008,-3.1637894265458364
763.0000000000101,33.96549049050319,-0.6706787148234521,-3.1637882322892605
764.2000000000102,34.005901821603175,-0.673669650657061,-3.162402873658027
765.4000000000102,34.046032931342616,-0.670303679778641,-3.162472290894665
766.6000000000101,34.08652759536843,-0.6727642854067328,-3.1637722311381493
767.8000000000102,34.126717797253434,-0.6688341040484973,-3.1637917344759554
769.0000000000102,34.1670310136923,-0.6751666916167176,-3.1651527375474977
770.2000000000103,34.20754096437702,-0.6784367729980709,-3.164114162128092
771.4000000000103,34.24750220461826,-0.6778388983808301,-3.1638384390938996
772.6000000000103,34.287647138520846,-0.6792962391771051,-3.163957308136104
773.8000000000103,34.328353182655924,-0.6816492439857997,-3.1651021928935474
775.0000000000103,34.36849178149211,-0.6815695860508848,-3.1650999622098026
776.2000000000103,34.40878593939584,-0.6793200354603677,-3.1650999566757765
777.4000000000103,34.4492027208553,-0.6812644288042589,-3.165100566211786
778.6000000000104,34.489766789673396,-0.6818419135750191,-3.1664236821011293
779.8000000000104,34.52979725257259,-0.6833858178658496,-3.166417898908599
781.0000000000105,34.570199050425806,-0.6843139508358078,-3.16643367254746
782.2000000000104,34.61020488435287,-0.6842040869288502,-3.166419817275516
783.4000000000104,34.65046675490101,-0.6844076116847329,-3.1677238005653026
784.6000000000105,34.69094183495569,-0.684822383634621,-3.1677286845254837
785.8000000000104,34.73136071172788,-0.6849127064319429,-3.168786319901039
787.0000000000105,34.77185184457091,-0.6874440381407076,-3.168723866905603
788.2000000000105,34.811930654413615,-0.6830313701596502,-3.169047755599024
789.4000000000106,34.85194724010526,-0.6826173464986449,-3.1704092052629864
790.6000000000106,34.89261535769279,-0.6852435136531909,-3.170389450272848
791.8000000000105,34.93307697119146,-0.6858996961002384,-3.171687453782032
793.0000000000106,34.97306653546356,-0.685937084669578,-3.1717354496757477