File: 01_Data/PEVA/STA/N2/30K_min/PEVA_STA_N2_30KData_240731_R1.csv
##Temp./Â°C,Time/min,DSC/(mW/mg),Mass loss/mg
51.0,10.550998090779284,0.05463071904582817,-0.002063763090306203
52.100000000000016,10.7368695622464,0.1402220183642191,-0.003912390933908938
53.20000000000003,10.864610904613361,0.21360796305926089,-0.004543847992350081
54.30000000000005,10.963154550943441,0.2752678729159288,-0.004647242609736146
55.40000000000006,11.046897913852815,0.3273866883279539,-0.0035599712843135123
56.50000000000008,11.119827915591951,0.37425686324103413,-0.0045599036879595545
57.600000000000094,11.18800912905918,0.421307776636874,-0.003724749775678049
58.70000000000011,11.250471224782443,0.4617344774985521,-0.0013825906488316164
59.800000000000125,11.308802017596724,0.5009237469435583,-0.0055214810989099306
60.90000000000014,11.364157683595208,0.5361996104339788,-0.0034386589826649328
62.000000000000156,11.417980618749363,0.5705459214586432,-0.004604628029157176
63.10000000000017,11.468915227151816,0.6009680874698802,-0.004076300466938854
64.20000000000019,11.51718816420855,0.6336414069666931,-0.004394525163544216
65.30000000000021,11.566592916847679,0.6631301853876725,-0.003115518347178714
66.40000000000022,11.613446655622344,0.6891704597377064,-0.0033983464252722584
67.50000000000023,11.659222705639845,0.7128856308909022,-0.003374335901334291
68.60000000000025,11.704529765130538,0.7377677561003324,-0.003283433746269715
69.70000000000027,11.748646890605846,0.7594723335298905,-0.0031149304349975537
70.80000000000028,11.791526009332786,0.7800179589555021,-0.003188976927865461
71.90000000000029,11.83350327768392,0.7970446941142892,-0.004787752060607886
73.00000000000031,11.876624410280716,0.815656754020941,-0.0042644076895888006
74.10000000000034,11.916913463236645,0.8331227885305441,-0.0040785731545120996
75.20000000000034,11.958542008362691,0.8469143452028784,-0.005342802416191006
76.30000000000035,11.999339235018429,0.8641920223984283,-0.005951319803218169
77.40000000000038,12.040070618437115,0.8772115855053602,-0.005323370805621508
78.5000000000004,12.080109813592712,0.8935217822816521,-0.004226827368447594
79.6000000000004,12.119551718252799,0.9059119123292245,-0.0043708624386669115
80.70000000000041,12.159118241882556,0.9195244030216174,-0.003974605890673111
81.80000000000044,12.198285764841515,0.9282699857256511,-0.003816332535945044
82.90000000000046,12.23654900240793,0.9396859747379551,-0.003608079636766348
84.00000000000047,12.275101132263513,0.9542809525554568,-0.004646344885767206
85.10000000000048,12.313981056945817,0.9665800093315615,-0.00418402771503068
86.2000000000005,12.352076646510167,0.9758306211674048,-0.0044832848426317184
87.30000000000052,12.389966171471691,0.9865849880667836,-0.004202570291838015
88.40000000000053,12.427899836610512,0.9981163855414854,-0.004157986609333975
89.50000000000054,12.465056732650837,1.0062569624001667,-0.004189463081337941
90.60000000000056,12.502810510472516,1.0200603055593636,-0.0043785835484921876
91.70000000000059,12.539967295558291,1.0276007271145633,-0.004590512179237116
92.8000000000006,12.57714325984035,1.0395715336782692,-0.004442108405225298
93.9000000000006,12.61388355493733,1.0490344171142547,-0.004571708886181192
95.00000000000063,12.650588868234053,1.0609322479854102,-0.0045955706322509116
96.10000000000065,12.68722998964379,1.0731522622121885,-0.004506555667177281
97.20000000000066,12.724184791330702,1.0812466694482687,-0.004446729691687246
98.30000000000067,12.759930504346393,1.0961930497073573,-0.0045239579669678065
99.40000000000069,12.79774627940679,1.1043235196831387,-0.004527438353718161
100.50000000000071,12.833910290044846,1.1130695751432267,-0.004459601778044053
101.60000000000072,12.870856224652327,1.1221977962251324,-0.004444489575791799
102.70000000000073,12.90667474430606,1.1285007276581056,-0.004731623883038161
103.80000000000075,12.943191915742341,1.13556630760714,-0.005558949844118644
104.90000000000077,12.97938180828658,1.140537934949816,-0.005815524902054392
106.00000000000078,13.01500444664008,1.1422908192853163,-0.004774213120138704
107.10000000000079,13.051274838791457,1.1460090070858027,-0.004509429188612302
108.20000000000081,13.0874382894642,1.1502350092295486,-0.005114851684576038
109.30000000000084,13.12355117364212,1.1554347164696888,-0.004510598364948493
110.40000000000084,13.15996533257675,1.1613053256593735,-0.004526499683983332
111.50000000000085,13.195870473144991,1.1654553530256477,-0.004512845792893572
112.60000000000088,13.231813348800149,1.1702302147841948,-0.00449783882892163
113.7000000000009,13.268081689889474,1.1755820950784295,-0.0038831980484479445
114.8000000000009,13.304315369485133,1.1799900638786194,-0.003514872805185476
115.90000000000092,13.33996676049156,1.184939219914414,-0.004520371359897801
117.00000000000094,13.376064277181358,1.1921923224634423,-0.004507517896780833
118.10000000000096,13.41216313581813,1.1983043366297488,-0.0031047259848140385
119.20000000000097,13.448028023961761,1.2036210629610853,-0.0031906729141910617
120.30000000000098,13.483840301707627,1.2106812273329686,-0.003189914841700947
121.400000000001,13.51983959677001,1.2135155993887194,-0.0031896819572647672
122.50000000000102,13.555660406331436,1.2211872026052042,-0.004040151180812579
123.60000000000103,13.591293068877576,1.227476932944824,-0.004508901297898937
124.70000000000104,13.626845958757695,1.2326817508557621,-0.004509924141573585
125.80000000000106,13.662787337515919,1.2394053590396203,-0.0045098932377953815
126.90000000000109,13.698727659191366,1.242415431764363,-0.00451016129958326
128.00000000000108,13.73313053243156,1.2473193385849235,-0.0038570195954825692
129.1000000000011,13.769424497612619,1.2553460187544965,-0.0031894849964162475
130.20000000000113,13.80492999754356,1.2601988208026003,-0.0031917201794664507
131.30000000000115,13.840255475754253,1.2675224859245855,-0.004423858766656963
132.40000000000117,13.875517912210668,1.271882579554927,-0.004508645764270014
133.50000000000117,13.910940174373698,1.2768029390893347,-0.004521881610886069
134.6000000000012,13.946233952449084,1.28501378370785,-0.003864370021672947
135.7000000000012,13.981596959736462,1.2889898707796468,-0.0038706016714735725
136.8000000000012,14.016623385862855,1.2965284204077467,-0.004607867377114161
137.90000000000123,14.052131560283174,1.3016463173143926,-0.004501546925835598
139.00000000000125,14.086129575506513,1.3059152553853204,-0.003443883345122245
140.10000000000127,14.12228369287654,1.3105217209930071,-0.003190030823744472
141.2000000000013,14.15706825147461,1.3186436811140965,-0.0031899488875524185
142.3000000000013,14.192338607821487,1.3228993070119672,-0.003189963744418378
143.4000000000013,14.226732251767334,1.330218332405787,-0.003189702275869344
144.50000000000134,14.26173395854639,1.3338968345198416,-0.0031926550150878086
145.60000000000133,14.29609586055183,1.3391243866500202,-0.004187973842834758
146.70000000000135,14.330824885266138,1.3452463435535291,-0.00416991430010949
147.80000000000138,14.365241457704201,1.3511691246522406,-0.004156515871789779
148.9000000000014,14.400221190859089,1.355717828495398,-0.002853959158084507
150.00000000000142,14.435067925168207,1.3629402202897332,-0.0028608264690390683
151.10000000000142,14.469601902538566,1.3672070183011893,-0.002858661614813407
152.20000000000144,14.504145453637056,1.375543070858771,-0.004144550498368815
153.30000000000146,14.538906351112995,1.3784422681978257,-0.004169906809963209
154.40000000000146,14.573158772464787,1.384653591068886,-0.004174842177145699
155.50000000000148,14.607752721747117,1.3882722223989081,-0.003470549338613793
156.6000000000015,14.641918497135194,1.3947238622398452,-0.0035097046218632855
157.70000000000152,14.676554634319304,1.3994867089012886,-0.0036355475784857205
158.80000000000155,14.71091128842495,1.4030016446203777,-0.003840766733765655
159.90000000000154,14.744931175051802,1.4066810420152451,-0.0038398500486316323
161.00000000000156,14.779248263087498,1.414450751194668,-0.0038398378525217325
162.1000000000016,14.813782382447442,1.417470971019909,-0.0038398379992754528
163.20000000000158,14.847807081496832,1.4248475194160282,-0.0038398379998119125
164.3000000000016,14.882070713489806,1.42603989898488,-0.003839837892278375
165.40000000000163,14.916442923505606,1.433309150316676,-0.0038398436272446546
166.50000000000165,14.95034039035011,1.4377655647190248,-0.0038403262510913194
167.60000000000167,14.984914843792907,1.439284430003238,-0.0037287899358782184
168.70000000000167,15.018867925600297,1.4450051691035855,-0.004172933553743263
169.8000000000017,15.053129486590558,1.4465834360798975,-0.004032445047322142
170.9000000000017,15.087053526329182,1.4499739917651158,-0.0028680163341823217
172.0000000000017,15.121216780515388,1.4560528178585816,-0.0028615208522211333
173.10000000000173,15.155047157267493,1.4612686927425642,-0.0023901079473231945
174.20000000000175,15.189660745056846,1.4645967446904606,-0.0015403811521528255
175.30000000000177,15.223245896914877,1.4698806152252208,-0.0029602781124866695
176.4000000000018,15.257479469586986,1.4741782236190035,-0.002860760088231551
177.5000000000018,15.291554026760625,1.478455419175382,-0.0029627042649442714
178.6000000000018,15.324379925954027,1.4814788531460392,-0.004178428144064661
179.70000000000184,15.358672670106717,1.486279973098145,-0.004179853727951155
180.80000000000183,15.392580094094813,1.4898080183720463,-0.004179845645555069
181.90000000000185,15.426921024315568,1.495046520954964,-0.004178425550769305
183.00000000000188,15.460316534960274,1.4981850689117238,-0.003000677937508023
184.1000000000019,15.493843373724749,1.5024219518497621,-0.002861156868539716
185.20000000000192,15.52780091843515,1.5055815053899362,-0.0028593425368157455
186.30000000000192,15.561219171568874,1.50683279792556,-0.0028793827749353795
187.40000000000194,15.594890018057415,1.5122612843633643,-0.004187408066994358
188.50000000000196,15.62826499819521,1.5148291928499904,-0.004179722028894162
189.60000000000196,15.66220808948172,1.5173330424896267,-0.00417983519707299
190.70000000000198,15.695540801369138,1.5202756734583476,-0.004181115419145343
191.800000000002,15.729339984035061,1.5227100521555257,-0.004155892926935856
192.90000000000202,15.76276706561945,1.5260113651168947,-0.004835058022491623
194.00000000000205,15.796230553485742,1.52803679189883,-0.004273586536286622
195.10000000000204,15.829695013722372,1.5302485147482126,-0.004827947963796042
196.20000000000206,15.863232335143879,1.5356370108217297,-0.004829865164468039
197.3000000000021,15.896296248189266,1.5373644382882006,-0.004829965579982165
198.40000000000208,15.929941816317072,1.5431160801912829,-0.004829963997184272
199.5000000000021,15.963329350369245,1.541449772458837,-0.004829962171393198
200.60000000000213,15.996806668190983,1.5430493895924744,-0.004830096969026698
201.70000000000215,16.030470622911903,1.5467230257606883,-0.004831978460394737
202.80000000000217,16.063491167595295,1.5491602597697673,-0.00603666313362794
203.90000000000217,16.0970410154512,1.55178293587473,-0.006133142494601174
205.0000000000022,16.130418586621275,1.5547884541391808,-0.00409938690417988
206.1000000000022,16.16362663140205,1.5580273208142252,-0.004171801631954963
207.2000000000022,16.19699730272185,1.5580273963945963,-0.004169936789614859
208.30000000000223,16.229879326905067,1.5604421667221084,-0.00417000499900233
209.40000000000225,16.263682635463564,1.5644335347397451,-0.0057087751600146674
210.50000000000227,16.297076199984254,1.5672162651268922,-0.00551279788452419
211.6000000000023,16.33006170226895,1.5679529441364428,-0.006919940477041919
212.7000000000023,16.36364398422765,1.5726508991335764,-0.007090570809706875
213.8000000000023,16.396517331415822,1.5757129702090715,-0.008220694581765997
214.90000000000234,16.42948873580078,1.5758842463174356,-0.008230187344969053
216.00000000000233,16.46360850263178,1.5772276375591447,-0.008230165470738626
217.10000000000235,16.496327979362647,1.5818880096988446,-0.008230161718964624
218.20000000000238,16.529499773244673,1.5851079992761126,-0.008230194694823112
219.3000000000024,16.563178721938986,1.5864612586027271,-0.008254962445077396
220.40000000000242,16.5961183015708,1.587860585142411,-0.009530233277439848
221.50000000000242,16.629482388110375,1.59155656963478,-0.009549847171379966
222.60000000000244,16.662667207727267,1.5943760220594039,-0.010142720236753888
223.70000000000246,16.696055992153894,1.5959645838134846,-0.01088695642601678
224.80000000000246,16.729059446593677,1.6000915561901354,-0.010189947650181885
225.90000000000248,16.762791501921217,1.6027829383550267,-0.010327996465006706
227.0000000000025,16.79543870765175,1.6049187033938508,-0.011519809742772225
228.10000000000252,16.828773694731986,1.6097408952300456,-0.01147386026210473
229.20000000000255,16.861951834598916,1.612218986605943,-0.012838652013653196
230.30000000000254,16.89538012446603,1.6124467725021179,-0.012833448573794648
231.40000000000256,16.92840377568603,1.6165436278898895,-0.013839955840154516
232.5000000000026,16.960700814930856,1.619637545861412,-0.01383970398634915
233.60000000000258,16.994596784458746,1.6208509935764104,-0.015256141482903551
234.7000000000026,17.02796782635037,1.622673375558589,-0.01500418032463724
235.80000000000263,17.060982054747328,1.626361646459397,-0.016244405765293735
236.90000000000265,17.094082543501266,1.6284266084038046,-0.016615515300921757
238.00000000000267,17.12719382643746,1.6312663605921998,-0.017985617187825653
239.10000000000267,17.16052591580963,1.6329263287061924,-0.0190376209510692
240.2000000000027,17.193561252725498,1.6327537702235912,-0.019770332339198227
241.3000000000027,17.226847005269672,1.6336208103307603,-0.021176644352353335
242.4000000000027,17.260154524608282,1.6313117792460723,-0.022508198299380666
243.50000000000273,17.292595197423648,1.634794583931281,-0.023696469279786747
244.60000000000275,17.32593245874364,1.633689278885083,-0.024904455572946738
245.70000000000277,17.35924741177172,1.634046417672688,-0.025852754680370627
246.8000000000028,17.392075190678217,1.636117985476864,-0.027704355174813955
247.9000000000028,17.425328498545,1.634362816029733,-0.030089677257620906
249.0000000000028,17.458658375181372,1.6341464378245951,-0.03166608234496815
250.10000000000284,17.491575684648897,1.6312948159448866,-0.03328913671092293
251.20000000000283,17.5244190459259,1.6288427705175677,-0.034862221817590466
252.30000000000285,17.556833728403674,1.626213966643245,-0.03632804615632512
253.40000000000288,17.590867906238376,1.6219116929986461,-0.03870716735111879
254.5000000000029,17.623662696757346,1.618654769983204,-0.04040902733374585
255.60000000000292,17.656858406486553,1.6127468373639529,-0.04229852578717841
256.7000000000029,17.690120837497748,1.6079981835531503,-0.044036772258247314
257.8000000000029,17.722993200850187,1.6014414293967976,-0.04610832115596786
258.90000000000293,17.756136418872636,1.596068713823246,-0.04757650654336576
260.00000000000296,17.789155014551543,1.5890995154504723,-0.049599900163512345
261.100000000003,17.822382243857124,1.5804137332552166,-0.05277539220062
262.200000000003,17.854626651203176,1.5740326681475372,-0.05601440350325815
263.300000000003,17.88726503554085,1.566822790752695,-0.058928547264369247
264.40000000000305,17.92125428572873,1.5626509335270282,-0.06240625944981515
265.50000000000307,17.95432449553162,1.5704001969351375,-0.06741240178646635
266.6000000000031,17.987959794417673,1.598331591746002,-0.07133805172423324
267.7000000000031,18.021407543625436,1.6437297200346985,-0.07501708894119563
268.8000000000031,18.055423375602526,1.6958446709672708,-0.08046576101659975
269.9000000000031,18.089331367038795,1.746185110036766,-0.0851316090638079
271.0000000000031,18.122854732907896,1.786766780720197,-0.09001371032401151
272.10000000000315,18.15653093405727,1.824386009095264,-0.09494378743922915
273.2000000000032,18.190429109302844,1.8579386230311306,-0.10152654155272156
274.30000000000314,18.22380182650382,1.8868379000617428,-0.10791137147689334
275.40000000000316,18.257444365911482,1.9147548519681088,-0.11430360238502324
276.5000000000032,18.291013077911742,1.9426957103962375,-0.12288724543053364
277.6000000000032,18.324276868035838,1.96878614030435,-0.13113494978234197
278.70000000000323,18.357947252756645,1.9972310435549372,-0.14071848594810898
279.80000000000325,18.391612701893482,2.0238956315954897,-0.15010829107235013
280.9000000000033,18.4252551823876,2.048507970757319,-0.15984702433262887
282.0000000000033,18.458781051936402,2.0781751978878313,-0.16964494715292489
283.1000000000033,18.49246191147484,2.1094589780136834,-0.17987469163305603
284.20000000000334,18.52637121868748,2.1432494841939955,-0.1923166148097506
285.30000000000337,18.560061395262597,2.1754320440668122,-0.20499898127727745
286.40000000000333,18.593847810106773,2.2176750321428296,-0.21846695982029596
287.50000000000335,18.627882720456217,2.2566288453530845,-0.23449217783535437
288.6000000000034,18.661508860956726,2.298693606448289,-0.2514126870700055
289.7000000000034,18.69554777044168,2.3423562556018567,-0.27025657752753585
290.8000000000034,18.729437614987688,2.384694078038586,-0.2905813291319914
291.9000000000034,18.763452230248543,2.423442746323249,-0.3106943997564824
293.0000000000034,18.797152511790664,2.459571892854756,-0.3326417047098986
294.10000000000343,18.830818369353487,2.4948672458351284,-0.35661900594757245
295.20000000000346,18.86475480118704,2.532647828287645,-0.3829893695200277
296.3000000000035,18.898526489222252,2.5669672662989633,-0.40889230202656
297.4000000000035,18.9324647341912,2.6023917172469115,-0.43797690794205435
298.5000000000035,18.96621635440023,2.635107099946409,-0.46837420821752573
299.60000000000355,19.000151137679683,2.671515256908668,-0.49836623256390755
300.70000000000357,19.033847380976958,2.708936311313107,-0.5302073264812517
301.8000000000036,19.067886723739402,2.7449055389056083,-0.5652515149681174
302.9000000000036,19.10131745103643,2.777038977937196,-0.6008080969756233
304.0000000000036,19.135714020693246,2.8150389918365484,-0.6382831881566511
305.1000000000036,19.169097548869985,2.852972555754834,-0.6764066006129088
306.2000000000036,19.202894742216273,2.8896307517777853,-0.7149185477048161
307.30000000000365,19.237242696904975,2.9254445869216603,-0.7566151332348845
308.4000000000037,19.270856314427935,2.962902713047209,-0.7996679992448361
309.5000000000037,19.304678323485202,2.9980884279619326,-0.8462782260912318
310.60000000000366,19.33849810301536,3.0334701014544088,-0.8953153952333364
311.7000000000037,19.37251463738088,3.0661099207991973,-0.9467666918887052
312.8000000000037,19.406012430174115,3.1001529273323913,-0.9974645407227616
313.90000000000373,19.43996919911972,3.131516749561688,-1.0481624017009632
315.00000000000375,19.473822965440803,3.160124413658418,-1.1024737305457615
316.1000000000038,19.507290847822148,3.1846978658314113,-1.158874992430659
317.2000000000038,19.54114020771644,3.203636033691379,-1.2178431104817617
318.3000000000038,19.574680952490816,3.21975679917738,-1.279633820952045
319.40000000000384,19.607626929202873,3.2340839954391782,-1.3396306663731479
320.5000000000038,19.641722424893977,3.23997493379382,-1.399932798171803
321.60000000000383,19.675133588928936,3.2353712092837386,-1.4609450322972664
322.70000000000385,19.70893602990613,3.2391871071500895,-1.5254299004703458
323.8000000000039,19.742724558268364,3.2573957436346177,-1.5902831439183576
324.9000000000039,19.775637893600287,3.28539980708849,-1.6558949235023057
326.0000000000039,19.810803625797273,3.352970513381335,-1.7270471216734418
327.10000000000394,19.844561495106863,3.363820121113142,-1.7928528845650944
328.2000000000039,19.877540858763364,3.3254002407016876,-1.8561431245411675
329.30000000000393,19.91000029808108,3.2564881744498164,-1.9182503712685146
330.40000000000396,19.942568534863362,3.1558011481267747,-1.9799917939523843
331.500000000004,19.97461579170555,3.037323005485391,-2.041099686648918
332.600000000004,20.00663617134299,2.9024919256708337,-2.095739996769197
333.700000000004,20.03850253074299,2.767570905657162,-2.142731500621513
334.80000000000405,20.07052748153241,2.644843817839254,-2.1882658799535886
335.90000000000407,20.102645938514552,2.529366687531673,-2.2307417216158605
337.0000000000041,20.134634512378838,2.4269660933437383,-2.2699272242706057
338.10000000000406,20.167399210683286,2.335399026469092,-2.3055983757664347
339.2000000000041,20.20002816922238,2.256645293690272,-2.3373231367068463
340.3000000000041,20.232225508010448,2.1824957619555674,-2.367015126311347
341.4000000000041,20.265034996840257,2.118731006770271,-2.395654112918852
342.50000000000415,20.29760582871156,2.0569026070528764,-2.4245104824616286
343.6000000000042,20.32988392066059,1.997429807415806,-2.451478152183792
344.7000000000042,20.36291097841241,1.9431440942201497,-2.475469165632746
345.80000000000416,20.395747374937372,1.8877014560076506,-2.4987367536648004
346.9000000000042,20.428842005085794,1.8333726462080118,-2.522210597600819
348.0000000000042,20.46176945631349,1.781118979889648,-2.543868124420376
349.10000000000423,20.494297631530728,1.7295233316892231,-2.5655507678923897
350.20000000000425,20.527155002658777,1.678064297142821,-2.5859751382255762
351.3000000000043,20.559970514954184,1.6250432130801586,-2.603820303233367
352.4000000000043,20.592708720434768,1.5762238551185375,-2.6215268838638757
353.5000000000043,20.62571556727527,1.5272571449896761,-2.6382653631377897
354.60000000000434,20.658739098712378,1.4780069114479697,-2.655253548738376
355.7000000000043,20.69152094310144,1.4294735876224856,-2.67249002707194
356.80000000000433,20.724293026569214,1.3815894147040833,-2.686792750510852
357.90000000000435,20.757559617180966,1.3351213942658784,-2.6995482313465615
359.0000000000044,20.790649993046255,1.2915286466408464,-2.7133310744896404
360.1000000000044,20.823581779571146,1.249319156771825,-2.726438354612193
361.2000000000044,20.856642496857585,1.2070081392456309,-2.7394297183126817
362.30000000000445,20.88981830363286,1.1681010551517341,-2.7505637686522424
363.4000000000044,20.92292478304302,1.133360982166047,-2.7596162189497253
364.50000000000443,20.95628662375297,1.1001191037369709,-2.768417957552309
365.60000000000446,20.989261648770068,1.0651686776788034,-2.7773278968252004
366.7000000000045,21.023086260833736,1.0314285456735943,-2.786052497750789
367.8000000000045,21.05647047119963,1.000159418616369,-2.793246312696053
368.9000000000045,21.08987901062813,0.9708144398161199,-2.7997696922220334
370.00000000000455,21.123393821810243,0.9446890611226224,-2.8067895074299787
371.10000000000457,21.15675656912419,0.9166311560398386,-2.81218622851085
372.2000000000046,21.19017986104809,0.8920876766363763,-2.8171859806447648
373.30000000000456,21.22386473327548,0.8649188715999867,-2.8228601023393605
374.4000000000046,21.257396649291557,0.840219428804921,-2.8268418540996643
375.5000000000046,21.291036542492694,0.8183256253055524,-2.8306732979876665
376.6000000000046,21.32444695858744,0.798371230201973,-2.8345954087457637
377.70000000000465,21.358121430783463,0.7784252567919996,-2.8387400294995904
378.8000000000047,21.391928327294956,0.7607387232057278,-2.8415031481051387
379.9000000000047,21.425779070890265,0.7426675608308717,-2.8446870110229545
381.00000000000466,21.45940822828393,0.7267909998591114,-2.847605627129758
382.1000000000047,21.49323536677119,0.7098300457451692,-2.850246031864754
383.2000000000047,21.527115533904944,0.69832756887857,-2.8521947011367024
384.30000000000473,21.56089742938267,0.6865361126068332,-2.852736897436571
385.40000000000475,21.595035627111113,0.6787282998450329,-2.8548442941937466
386.5000000000048,21.62882241496589,0.669537699809265,-2.8563387863882723
387.6000000000048,21.663092428088,0.6650389472237868,-2.8585488689082035
388.7000000000048,21.69696237335578,0.6563216130443955,-2.8598310703076275
389.80000000000484,21.731284625248627,0.6540757266750669,-2.86120408037148
390.9000000000048,21.76532933542153,0.647612307897085,-2.862142358546011
392.00000000000483,21.799221750472643,0.6475073088102328,-2.863358231715239
393.10000000000485,21.83338268689816,0.6438207491211454,-2.8648561681444136
394.2000000000049,21.86779796381576,0.643428503790159,-2.866254171089814
395.3000000000049,21.901902287636407,0.6422221813376852,-2.866239604097268
396.4000000000049,21.936062574923838,0.6403895598809148,-2.867543192501122
397.50000000000495,21.97006250532719,0.6388688913860349,-2.8689721181522554
398.6000000000049,22.004097826936963,0.6381110914311491,-2.8689951527502946
399.70000000000493,22.038838718056745,0.636533731609599,-2.870291084743749
400.80000000000496,22.072996500921686,0.6333032804369251,-2.8716638717783756
401.900000000005,22.10752720404653,0.6325703773013226,-2.872730638061533
403.000000000005,22.141383064309977,0.6290875348822106,-2.872932516825185
404.100000000005,22.176042713869847,0.6258519371431466,-2.874053058610048
405.20000000000505,22.21036770321217,0.6198311108626071,-2.8742518965172366
406.30000000000507,22.244622678084887,0.6199763891840393,-2.8755705647529792
407.4000000000051,22.2792618317069,0.6188531745804312,-2.8766074669557105
408.50000000000506,22.313442297524084,0.6148200367621092,-2.8755531842627367
409.6000000000051,22.347928670922947,0.6124151888070362,-2.876879431166641
410.7000000000051,22.382186148188705,0.6057044374212031,-2.878454601665521
411.8000000000051,22.416596635928617,0.6030668568811135,-2.8799929214808015
412.90000000000515,22.451171853652042,0.5994164212773466,-2.881261569330827
414.0000000000052,22.485143534340853,0.5967005541557863,-2.882736255836566
415.1000000000052,22.519480228110186,0.5912981020444279,-2.8843348618234677
416.20000000000516,22.55393031455611,0.585918136269755,-2.884656710315322
417.3000000000052,22.58824747012002,0.5844646393033517,-2.885385875791781
418.4000000000052,22.623458454980803,0.5802921766039076,-2.88687415025411
419.50000000000523,22.657791997874952,0.5750424977403066,-2.8887578425374927
420.60000000000525,22.692663598801047,0.5702671505256806,-2.890188029483843
421.7000000000053,22.72696152256543,0.5662248211155319,-2.890319401610048
422.8000000000053,22.761805887687213,0.5623746071750684,-2.8921433408788952
423.9000000000053,22.796055582553798,0.55762918749878,-2.89409276631023
425.00000000000534,22.83062166556357,0.5518788255444682,-2.8969099643475027
426.1000000000053,22.865253096376527,0.5482438250985665,-2.8989100854449896
427.20000000000533,22.90015485938601,0.550343099589759,-2.8994893749470374
428.30000000000535,22.93464462438431,0.5433231133135166,-2.9013694902797873
429.4000000000054,22.968656064733636,0.5405330109328104,-2.9041997514656552
430.5000000000054,23.0042079760047,0.5315370328017955,-2.9053133243794633
431.6000000000054,23.038382020534204,0.5297574080656053,-2.9070519204399234
432.70000000000545,23.073092633910395,0.5236253540317279,-2.9087380737640327
433.8000000000054,23.10806294196345,0.5166675141185432,-2.910406000220645
434.90000000000543,23.14262563163832,0.5120352585816493,-2.9130953900687206
436.00000000000546,23.177349214979927,0.5072273989352948,-2.915271148203291
437.1000000000055,23.212097925683977,0.5018895801517597,-2.917192781714964
438.2000000000055,23.246910970374433,0.497399413279614,-2.9201337119836706
439.3000000000055,23.281614049363267,0.48795087081264554,-2.922309557111181
440.40000000000555,23.316298068018924,0.4821907647920296,-2.9240749906194465
441.50000000000557,23.351227883151054,0.4738487902896372,-2.927069812533702
442.6000000000056,23.386134585331092,0.4708081336113955,-2.9311070625556717
443.70000000000556,23.420739446367875,0.4633614318411772,-2.932780519304386
444.8000000000056,23.455687885142492,0.45707535643411534,-2.9361933172928936
445.9000000000056,23.49029068439794,0.4520625230507096,-2.9393690775370307
447.0000000000056,23.525456504398544,0.44554637356206683,-2.9432757324145
448.10000000000565,23.560637857584666,0.44277008357264,-2.9472105773131183
449.2000000000057,23.595089443234944,0.4381795323457064,-2.9512681783431183
450.3000000000057,23.630215873254276,0.4384511919655256,-2.9557214520469763
451.40000000000566,23.665302843305664,0.4370527179187401,-2.9601467563606363
452.5000000000057,23.70009617066246,0.4356286471586457,-2.964056772927136
453.6000000000057,23.735216900542557,0.434444061817027,-2.9679071902399174
454.70000000000573,23.770129998248972,0.43630175462766396,-2.972395854703391
455.80000000000575,23.80528892334848,0.43820552571910665,-2.9771937795276213
456.9000000000058,23.840311765644586,0.441807928646316,-2.983528075813254
458.0000000000058,23.875462431389526,0.4480405476792616,-2.9889973574213107
459.1000000000058,23.91069638539359,0.4532358501720799,-2.9953756088346974
460.20000000000584,23.945928155832362,0.46345361249404604,-3.0023413240936323
461.3000000000058,23.980984670796786,0.4719418238341756,-3.008703904843977
462.40000000000583,24.016111616776556,0.4827406561720904,-3.0150918717111734
463.50000000000585,24.0512860808561,0.4923859768661838,-3.0218690810617472
464.6000000000059,24.086290402577454,0.5063816342946355,-3.0289136319742505
465.7000000000059,24.1221146921189,0.520903714259985,-3.035411798004098
466.8000000000059,24.15756625302713,0.5419672976193759,-3.0429481271862437
467.90000000000595,24.193121035832238,0.5610268107363322,-3.0519352246779268
469.0000000000059,24.22824489384905,0.5835273550167976,-3.0594544560482233
470.10000000000593,24.263742726804043,0.6052602461048983,-3.0679215284673136
471.20000000000596,24.299547725757858,0.626068098257035,-3.077006868579713
472.300000000006,24.335173404065547,0.656849707853099,-3.0856825761339426
473.400000000006,24.370676766097766,0.6949589027277413,-3.094962623937983
474.500000000006,24.4065000476423,0.7442424016239555,-3.105472867645555
475.60000000000605,24.443401647154264,0.8422326741875492,-3.1169909850707884
476.70000000000607,24.479834403580266,0.9263577471922806,-3.130959977207105
477.8000000000061,24.51562774885434,0.9517799210584272,-3.1474741194558806
478.90000000000606,24.550885839599513,0.9490605607748747,-3.166106775521348
480.0000000000061,24.586199224036328,0.9269846139620206,-3.1862802302147135
481.1000000000061,24.621416437543733,0.9002495426100784,-3.2053766804815673
482.2000000000061,24.656549725432402,0.8839971630513992,-3.221872044949506
483.30000000000615,24.69189817158191,0.8597846439580139,-3.236710476505383
484.4000000000062,24.727205904649498,0.8448035023225875,-3.251364698977175
485.5000000000062,24.762726988545925,0.8339945411044319,-3.265383067393353
486.60000000000616,24.79808900728574,0.825305184938022,-3.276095121790623
487.7000000000062,24.833450267226542,0.8152944120555399,-3.286881053724625
488.8000000000062,24.869046445211552,0.8058464428168319,-3.2983100764535993
489.90000000000623,24.90444075115386,0.8011005489910901,-3.3093328350628877
491.00000000000625,24.940000000000207,0.7904933770775915,-3.320619964000066
492.1000000000063,24.975473120197467,0.7850681375324906,-3.3320034744135194
493.2000000000063,25.01085385387868,0.7779837563978913,-3.342569890829701
494.3000000000063,25.04627430262674,0.7703362631302058,-3.353005886798384
495.40000000000634,25.081715452403117,0.7596706277896295,-3.362900388214378
496.5000000000063,25.117014966715328,0.7509733731683577,-3.3724170999490397
497.60000000000633,25.15250294285697,0.7447111373134081,-3.3819393319627435
498.70000000000636,25.187807214176104,0.7326637307428403,-3.390565650814586
499.8000000000064,25.223529618918192,0.7233124786163108,-3.399758049272513
500.9000000000064,25.2591437365486,0.7150662777422467,-3.4091616239565252
502.0000000000064,25.294324556080145,0.7080839212996568,-3.4171991883422055
503.10000000000645,25.330190518937652,0.6972560868475801,-3.4253878201133308
504.2000000000064,25.365537205720496,0.6888727611107925,-3.433580825357777
505.30000000000643,25.40130673517007,0.6801722131666355,-3.4413202775035336
506.40000000000646,25.436842814381283,0.6714145960452014,-3.449097204952804
507.5000000000065,25.472308199845067,0.6629520272143254,-3.4572962989151956
508.6000000000065,25.50809312553909,0.6523211829498947,-3.464573726900767
509.7000000000065,25.54327415514437,0.6435237360594006,-3.471389853443573
510.80000000000655,25.57842348457258,0.6371748233105019,-3.478514145032004
511.90000000000657,25.6142706514311,0.6313366218872429,-3.484287681698038
513.0000000000066,25.650264490147077,0.6233225929404043,-3.490841586643602
514.1000000000065,25.68570927794074,0.6154028746035765,-3.4959582462897325
515.2000000000066,25.72152106053986,0.6047802042073842,-3.5012377358844025
516.3000000000065,25.75703743196255,0.5955008843853558,-3.5068694371038465
517.4000000000067,25.79263936178924,0.590285133689681,-3.512035176715094
518.5000000000066,25.828329719958187,0.5833546402955061,-3.5172720674908353
519.6000000000067,25.86405541740581,0.5754185081468219,-3.520738656415208
520.7000000000066,25.899766272124445,0.5683617633345819,-3.5242492682205864
521.8000000000067,25.934817194195624,0.5598670986215568,-3.528046942959085
522.9000000000067,25.971011237170337,0.5534747349080611,-3.532156604194679
524.0000000000067,26.006743875016333,0.5480435841362947,-3.5361243360733132
525.1000000000067,26.042647519463074,0.5425164029323009,-3.5407782818340587
526.2000000000068,26.078344347692582,0.5384121101443631,-3.544400653590304
527.3000000000068,26.114536256953954,0.5327619104113752,-3.547644833013794
528.4000000000068,26.150329527912557,0.528755245438258,-3.5497237115569584
529.5000000000068,26.185904980107146,0.5215812114763152,-3.5519909155087728
530.6000000000068,26.22158623890957,0.5166694510243237,-3.5547377104924167
531.7000000000069,26.257235150045823,0.5133367141564822,-3.5579725419280646
532.8000000000068,26.292977573193014,0.5055607740574033,-3.560916542478815
533.9000000000069,26.329013953847436,0.5035290521917715,-3.563497064814239
535.0000000000068,26.364632916494376,0.49913226071800443,-3.5653603583370113
536.100000000007,26.400624024726813,0.4959449256244679,-3.5679852249706694
537.2000000000069,26.436621460741613,0.4945855930737608,-3.56884165133386
538.300000000007,26.472434295363076,0.49313069815000965,-3.5692867838839577
539.4000000000069,26.508484216809563,0.4884454917042549,-3.57080763946628
540.5000000000069,26.544459621220845,0.48487028777868546,-3.5724905822678785
541.600000000007,26.58019581556638,0.47971148265741315,-3.5751400433780276
542.700000000007,26.616262804995973,0.4784257212442977,-3.576869347133349
543.800000000007,26.65202696554872,0.47659880127276844,-3.578825665468676
544.900000000007,26.688304905044852,0.4749577194304233,-3.5809169006996577
546.000000000007,26.72421072426986,0.4738084047070852,-3.5820154119560814
547.1000000000071,26.76010024730907,0.4729395579181044,-3.5826789035786772
548.2000000000071,26.795743255391024,0.4698850620927002,-3.5837670609400334
549.300000000007,26.83111178542083,0.47061570038790324,-3.5849693579283364
550.4000000000071,26.868061517003255,0.472199972071103,-3.5836814444216634
551.500000000007,26.904020555314258,0.4702424327845143,-3.5853729881791567
552.6000000000072,26.940032449671868,0.47161356127462506,-3.587802898581706
553.7000000000071,26.975845140925443,0.4699704435620975,-3.589189519414255
554.8000000000072,27.011677293325256,0.47226607847280144,-3.589960601315924
555.9000000000071,27.047989924281207,0.4734441463836969,-3.5910644573727755
557.0000000000072,27.08418261226132,0.47571670231749175,-3.5918930863769174
558.1000000000072,27.120100521997806,0.47692302900916883,-3.5921682962754353
559.2000000000072,27.156278912342913,0.47683188788218756,-3.59232868061268
560.3000000000072,27.192347662858843,0.47580954149294974,-3.5935459746987455
561.4000000000073,27.22839678394927,0.4747925721129289,-3.593539968962343
562.5000000000073,27.264544660584928,0.47836426117173514,-3.5936019897660936
563.6000000000073,27.300667236342907,0.47896631804527945,-3.594852560856876
564.7000000000073,27.336609831566317,0.47861796255332445,-3.5958878018521165
565.8000000000073,27.37275272589141,0.4775742592565948,-3.59616453306628
566.9000000000074,27.40883806878812,0.47582468823204294,-3.5970571534760265
568.0000000000074,27.44512394436905,0.47933293461771087,-3.597514187842378
569.1000000000074,27.48142008196264,0.47857440633636594,-3.598816038856892
570.2000000000073,27.517247844245105,0.47953199949729486,-3.5988101254917586
571.3000000000073,27.55346697696979,0.4760222399430567,-3.5988274655093035
572.4000000000074,27.589736646158023,0.4756041397514441,-3.600118590047676
573.5000000000074,27.62598549381843,0.47882425091673175,-3.6010903190991845
574.6000000000074,27.661922996956086,0.4749106821968734,-3.6014390375569008
575.7000000000074,27.698054251035614,0.4740081484092087,-3.602620415026685
576.8000000000075,27.73456676859649,0.4724894114860154,-3.6027595264769454
577.9000000000075,27.7707135469475,0.47087103847054324,-3.6024615437273417
579.0000000000075,27.80687685499842,0.4718743770063347,-3.6037413014639155
580.1000000000075,27.843287331187906,0.4702937314822919,-3.603749835655539
581.2000000000075,27.87948331741959,0.47016581353306086,-3.603750178219167
582.3000000000076,27.915676340650307,0.46580011334576166,-3.6040550392919326
583.4000000000076,27.95235080971895,0.466558460895387,-3.6050635920330842
584.5000000000076,27.988458517328752,0.46337394170581647,-3.605059207960122
585.6000000000076,28.024858026435766,0.46026388777260063,-3.605055506505947
586.7000000000077,28.061116255417055,0.46047736512437787,-3.6037398434199592
587.8000000000077,28.097782859028364,0.4599667644151959,-3.605033737820974
588.9000000000076,28.13433575907135,0.4597187264977065,-3.605727253220641
590.0000000000076,28.170545678104492,0.45612486346639614,-3.605730111630323
591.1000000000076,28.206421324197716,0.45873927545721527,-3.6057296994635073
592.2000000000077,28.242986412783967,0.45856543606136935,-3.6063629221043207
593.3000000000077,28.279464376030923,0.45688745896907323,-3.605756851438295
594.4000000000077,28.316115540697993,0.4529202089559272,-3.606700225604361
595.5000000000077,28.352670706484638,0.45442649147329717,-3.607034631736129
596.6000000000078,28.388751515906982,0.4509546300102918,-3.607916409993736
597.7000000000078,28.425560534347504,0.45158389839387847,-3.6083654322508614
598.8000000000078,28.461968940885345,0.4493620490409833,-3.6086886521657227
599.9000000000078,28.498530337355735,0.4487982763690712,-3.610037119815724
601.0000000000078,28.535059442194438,0.4451219227724177,-3.6100312471708733
602.1000000000079,28.57151948225003,0.44395434349050156,-3.6113383288064065
603.2000000000079,28.608185186163688,0.4414847863024527,-3.611330096239232
604.3000000000079,28.644658964303456,0.4373515191291508,-3.6113305059379055
605.4000000000078,28.68077511127984,0.437237808955774,-3.611417303945812
606.5000000000078,28.71780163216339,0.4326873476906741,-3.6113105763964772
607.6000000000079,28.754303344088612,0.43106066506256213,-3.6113182227234066
608.7000000000079,28.791228576800982,0.43122016915223904,-3.6112382652154937
609.8000000000079,28.827673382188355,0.43167063353371016,-3.610011227431539
610.9000000000079,28.864283622915018,0.4265809277513821,-3.6100317341799295
612.000000000008,28.900849794315675,0.42367160721653874,-3.611322888095368
613.100000000008,28.937414490120204,0.42237863929145236,-3.61122934341122
614.200000000008,28.974023946932466,0.4232292641278146,-3.6119541723296544
615.300000000008,29.01073731459169,0.41934037281183545,-3.611657889650389
616.400000000008,29.04746130021529,0.4176999857072454,-3.611813015399798
617.5000000000081,29.08418094385847,0.41741706154004765,-3.612976837919871
618.6000000000081,29.12060812455453,0.4114180756414756,-3.6129699475253654
619.7000000000081,29.157559010032916,0.409564138757913,-3.6129245954538156
620.8000000000081,29.19449522600274,0.4083923855874112,-3.6142755896560663
621.9000000000082,29.231110589016335,0.4059237974519949,-3.6142894979339233
623.0000000000082,29.26768836473002,0.40813343599738405,-3.6145411911126106
624.1000000000081,29.304463444010345,0.4023125233350222,-3.6155839880534852
625.2000000000081,29.341230746497857,0.4003635735957578,-3.615600021723767
626.3000000000081,29.37795706177281,0.3992346364217485,-3.6155956455743663
627.4000000000082,29.414505159622617,0.39614827391646035,-3.6152657852173578
628.5000000000082,29.45145722105561,0.3966707665883169,-3.6152699659126544
629.6000000000082,29.487996521476614,0.39450741555496394,-3.6152691896123117
630.7000000000082,29.524992684129696,0.39180678586395334,-3.6139581572742
631.8000000000083,29.56153051745875,0.38728235852636494,-3.6139514086287168
632.9000000000083,29.598126918461908,0.387641246266063,-3.6139502255271694
634.0000000000083,29.63480664860314,0.3869257718408621,-3.6140095929247877
635.1000000000083,29.67133833494608,0.38372364938658254,-3.6152740031217934
636.2000000000083,29.708216423272564,0.3819712800663859,-3.6152694957387577
637.3000000000084,29.744981618274014,0.38124670344814016,-3.615179935115962
638.4000000000084,29.782102384542732,0.3793211944697088,-3.616588290955617
639.5000000000084,29.81857801391691,0.37626545881596485,-3.616590068858687
640.6000000000083,29.855473680498548,0.3737306232132629,-3.6165902188867287
641.7000000000083,29.89227221892779,0.3722854407462719,-3.6165684219072745
642.8000000000084,29.928867340230376,0.37042055652274186,-3.6172464374772657
643.9000000000084,29.965880395868176,0.3725191532033887,-3.6178079034282913
645.0000000000084,30.00260709497902,0.3668952179376499,-3.618569813617268
646.1000000000084,30.039140943691187,0.3661051755091278,-3.618205758376435
647.2000000000085,30.076413882541058,0.36397050385912655,-3.617256211089921
648.3000000000085,30.112844905189466,0.3609020715576725,-3.6172607399837373
649.4000000000085,30.149787113888614,0.35969386492048594,-3.6172485159642744
650.5000000000085,30.186496430819737,0.3574684246323645,-3.618567047083999
651.6000000000085,30.223606393889217,0.36063594210707306,-3.618580333863427
652.7000000000086,30.260231691244634,0.355888568816243,-3.6198955775540065
653.8000000000086,30.29698827144821,0.35269911546885124,-3.618495209646497
654.9000000000086,30.333954619451987,0.3536888650550174,-3.6199414096024745
656.0000000000086,30.370633998927577,0.3519824256545683,-3.6198899645249676
657.1000000000087,30.407548185505934,0.3491499815938872,-3.6198898715375645
658.2000000000087,30.44434203061411,0.34595452753559397,-3.619889873974476
659.3000000000086,30.481078209267658,0.34537129335841565,-3.6198898740006125
660.4000000000086,30.517848944040523,0.3414895164892846,-3.619889873843772
661.5000000000086,30.554922092073994,0.3445010767846648,-3.6198898406739892
662.6000000000087,30.591987612673343,0.3435283995440779,-3.6198872209310595
663.7000000000087,30.628716444972845,0.3446714215676532,-3.6212326849304612
664.8000000000087,30.665605099666024,0.3368782756125841,-3.6212106075825843
665.9000000000087,30.70231050487494,0.3389582584249582,-3.6212221324571763
667.0000000000088,30.73913746758725,0.34142884796012574,-3.6205462908883588
668.1000000000088,30.77632893750734,0.341150023959089,-3.620549863883961
669.2000000000088,30.813320534723434,0.33479228489222,-3.620549957693825
670.3000000000088,30.850032532731667,0.33816329890933705,-3.6205499602818056
671.4000000000088,30.886744920956513,0.33629863055962783,-3.6205449604515665
672.5000000000089,30.92421428988931,0.3370454804569203,-3.6212848490875227
673.6000000000089,30.960909802621078,0.3373636999128826,-3.620536750767728
674.7000000000089,30.997904230958728,0.334519455940004,-3.6205401227660383
675.8000000000088,31.03490687999418,0.33637819713438866,-3.620546516241193
676.9000000000088,31.07218856299192,0.3381666812915143,-3.621225053915526
678.0000000000089,31.108876652434503,0.33720115232590553,-3.6212000430825038
679.1000000000089,31.145868442688222,0.33793441563899007,-3.6212065715526243
680.2000000000089,31.182780202268276,0.33797936064705913,-3.619976386820834
681.3000000000089,31.21993369046757,0.33834648094394915,-3.6202087383879333
682.400000000009,31.25651372627423,0.33636573380718016,-3.6192016047521913
683.500000000009,31.29356451449502,0.33620323330815727,-3.619226196171713
684.600000000009,31.33108999182154,0.3378545075874795,-3.620098817882184
685.700000000009,31.368060278981005,0.3391174298022419,-3.6204645448216057
686.800000000009,31.405153666611234,0.3396292190712691,-3.6218589558307928
687.9000000000091,31.441950940230676,0.3395518108495108,-3.621943515453233
689.0000000000091,31.479051287151158,0.3422849001148105,-3.62087693131214
690.1000000000091,31.516256230626965,0.34085986573924254,-3.6222750034353175
691.2000000000091,31.55323979197936,0.34565759162035925,-3.6222007117065287
692.3000000000092,31.590243779307862,0.34349323611493054,-3.6222001783504094
693.4000000000092,31.627513795413723,0.34492345101345956,-3.6222001779750235
694.5000000000091,31.664275043828138,0.3510257967464403,-3.6222001780214375
695.6000000000091,31.701580450146693,0.35397541642236474,-3.6222001794541945
696.7000000000091,31.738364954384448,0.3581017438183469,-3.622200000695906
697.8000000000092,31.775713867693433,0.35664332763095685,-3.6221529806733463
698.9000000000092,31.81273409080349,0.3633031651263319,-3.6234958734508145
700.0000000000092,31.849934224730017,0.36877947606814954,-3.623509586975185
701.1000000000092,31.886528032934045,0.3780619318916938,-3.6235169385491988
702.2000000000093,31.923936414927866,0.3834561841205051,-3.623069331629673
703.3000000000093,31.961185785033614,0.3873411553435746,-3.621852565884538
704.4000000000093,31.997985754168326,0.3899529797670105,-3.6218598739102843
705.5000000000093,32.0350568588172,0.39511355342094445,-3.6218599635063264
706.6000000000093,32.072396157640675,0.4003431814071783,-3.6218714150897293
707.7000000000094,32.1093837377267,0.3983216110068435,-3.6231771891154643
708.8000000000094,32.14642205426427,0.40009983600031784,-3.623179957084004
709.9000000000094,32.18377937603702,0.3980519102097353,-3.6231733142623384
711.0000000000093,32.22090431532724,0.3958141432214277,-3.6224943122403808
712.1000000000093,32.258088551800874,0.39844958591433555,-3.6225200495274326
713.2000000000094,32.29508188956079,0.39534886357911536,-3.6225849812198563
714.3000000000094,32.33233087623175,0.394414790468929,-3.623845958728343
715.4000000000094,32.36957050544708,0.3952042968668916,-3.623839817579947
716.5000000000094,32.40689703508379,0.3922303656012529,-3.623839821992181
717.6000000000095,32.44401735500043,0.3932674786570072,-3.6238411148285556
718.7000000000095,32.48081578719998,0.39012786382815734,-3.623304243754733
719.8000000000095,32.51846485817196,0.3868806418078976,-3.623182137121193
720.9000000000095,32.55558693229625,0.3899312341163932,-3.6225226687169907
722.0000000000095,32.592697020989064,0.3894563620123652,-3.6218574142860085
723.1000000000096,32.62982720344233,0.38564903402698203,-3.6218598099704717
724.2000000000096,32.66729754620444,0.3821879012209355,-3.6218598262427397
725.3000000000096,32.70435519445732,0.38147901477213675,-3.621859562281933
726.4000000000096,32.74134508242097,0.3827595762718883,-3.621847625911945
727.5000000000097,32.778732069809514,0.38232429510829813,-3.621888107160357
728.6000000000097,32.81611155474344,0.3784849803689887,-3.621541293108061
729.7000000000096,32.85295224037096,0.37402250220624955,-3.6216266074843326
730.8000000000096,32.89036870966407,0.37662019837922545,-3.6218771062615276
731.9000000000096,32.92782229078981,0.38038992884880884,-3.6225536260189166
733.0000000000097,32.96518030817016,0.3757836564285437,-3.6228856001634875
734.1000000000097,33.002414622160295,0.3769119390371358,-3.623932324411771
735.2000000000097,33.039649824202606,0.37372664247395204,-3.623894951260498
736.3000000000097,33.076721148912014,0.3696961376167476,-3.6225312453182212
737.4000000000098,33.114200087520224,0.3676638176983287,-3.6224407550055124
738.5000000000098,33.15153140909589,0.3718009506108897,-3.623838574005165
739.6000000000098,33.18865192161837,0.3708644129563896,-3.6238398891469052
740.7000000000098,33.226082958172526,0.36776199978946167,-3.6238398801511154
741.8000000000098,33.26376948275324,0.36651782043206804,-3.6238398800009683
742.9000000000099,33.301169405038095,0.3643798665959481,-3.623839880000003
743.0000000000098,33.30450193632136,0.3636069796674488,-3.6238398800000047