File: 01_Data/PEVA/STA/N2/30K_min/PEVA_STA_N2_30KData_240801_R2.csv
##Temp./Â°C,Time/min,DSC/(mW/mg),Mass loss/mg
51.0,10.55369750963895,0.041321591994921913,0.007443133871732677
52.100000000000016,10.743517819783408,0.11429248478102494,0.006931258861805567
53.20000000000003,10.865767102081572,0.17516966337106155,0.00640489114942433
54.30000000000005,10.962894005854753,0.23247038912942397,0.0069004528708020985
55.40000000000006,11.044849468605882,0.27892817101105827,0.0053986740571208
56.50000000000008,11.11881452183978,0.3211219120858346,0.006153550988511114
57.600000000000094,11.185673894016317,0.3640177070016355,0.0062718220581139406
58.70000000000011,11.248334683735475,0.40202367078743695,0.006639943030755546
59.800000000000125,11.307374697692808,0.4360691749205339,0.008105290267422127
60.90000000000014,11.362821472134833,0.46782838198119236,0.007714229244276893
62.000000000000156,11.415715423874875,0.5007002948499761,0.007699244900957858
63.10000000000017,11.467655700643622,0.5291697442809165,0.005312186756718518
64.20000000000019,11.516948701984118,0.5590389860684462,0.00605977676015268
65.30000000000021,11.565258741668904,0.5836328213781852,0.006417513041631295
66.40000000000022,11.61172653720821,0.6090636345768403,0.00671057725749602
67.50000000000023,11.657959594588156,0.6321903389892687,0.005487163006971052
68.60000000000025,11.70293686207924,0.6573286207616302,0.005860967269589956
69.70000000000027,11.746622232152685,0.674758943624092,0.005640023681941386
70.80000000000028,11.789919274765142,0.6952851129682616,0.005085301073353143
71.90000000000029,11.833036461116226,0.7127614037760972,0.0054559309982931126
73.00000000000031,11.87514322739785,0.7299481464196522,0.005392951716037153
74.10000000000034,11.916670761564962,0.7440896774046721,0.005899344556178576
75.20000000000034,11.957575213317956,0.7609423673251743,0.005595732761669581
76.30000000000035,11.997983334900326,0.7747395967920765,0.005357340444689385
77.40000000000038,12.03864838043058,0.7848562882098233,0.004880748442714911
78.5000000000004,12.078413828118887,0.7974138780826996,0.005727859410496805
79.6000000000004,12.118512166795423,0.8117186106774086,0.005341022154370378
80.70000000000041,12.157891229398338,0.8215886769296612,0.00509957531791283
81.80000000000044,12.196533264974313,0.8338245065374328,0.005838125184146392
82.90000000000046,12.235233607729782,0.8440781995446758,0.00690646067431544
84.00000000000047,12.273833312193073,0.8549357280689254,0.00702150494675724
85.10000000000048,12.312287802964304,0.8644949231299282,0.005840297252306392
86.2000000000005,12.349927066173652,0.8750434098706783,0.004721201313832246
87.30000000000052,12.388548037276344,0.8852510797474562,0.004489838248971978
88.40000000000053,12.425677123266402,0.8937504002920573,0.005341291891740596
89.50000000000054,12.463292897978482,0.9043326589671195,0.005235822655343725
90.60000000000056,12.500649289377716,0.9109328755938451,0.006165776785321597
91.70000000000059,12.53794589216829,0.9199677552908085,0.006730492945377087
92.8000000000006,12.574857006908553,0.9278910643578793,0.006220500436119103
93.9000000000006,12.611671578709249,0.9371785928173211,0.005256359290861212
95.00000000000063,12.648489718336537,0.9463971459564935,0.006768497460026168
96.10000000000065,12.685990392018077,0.9573352924207632,0.0053115698609103035
97.20000000000066,12.721328231635024,0.9666973363247902,0.005792553735587624
98.30000000000067,12.759269545064111,0.9748263587609334,0.005333990608654027
99.40000000000069,12.7957033097549,0.9852502884153111,0.006042857236374211
100.50000000000071,12.832100377506928,0.9943783238709183,0.006715974981351458
101.60000000000072,12.86834781131189,1.0013472123481835,0.005372316549901335
102.70000000000073,12.904617388797075,1.0070926590961657,0.006737463158986046
103.80000000000075,12.941086869930828,1.0135354349809989,0.005786189437395173
104.90000000000077,12.977419470696264,1.0188174468647702,0.006320970235597301
106.00000000000078,13.013303052721161,1.0197372859388758,0.005367447616038135
107.10000000000079,13.049385518356772,1.0232046548839933,0.005340661076215447
108.20000000000081,13.085808040320618,1.0270516448940359,0.006639936411639624
109.30000000000084,13.121727536035792,1.0305237885359286,0.005267933427202998
110.40000000000084,13.157746532737775,1.0360206751711687,0.0051443513177877875
111.50000000000085,13.19377852634445,1.0393617217859437,0.005356859065520858
112.60000000000088,13.229608497358663,1.0442877370536678,0.005275220402787717
113.7000000000009,13.265725741682543,1.0478233831991,0.003973458662016149
114.8000000000009,13.301607950962385,1.0549264272871013,0.004743781332604335
115.90000000000092,13.338009072493804,1.0578226238899369,0.005261296496496648
117.00000000000094,13.373034402383665,1.0612110950544107,0.005258135682622012
118.10000000000096,13.410000000000034,1.0667390669590424,0.0058201713730303695
119.20000000000097,13.445884983897976,1.0732284164372996,0.0061654968821240885
120.30000000000098,13.48139660127056,1.076859091323831,0.00657990258450436
121.400000000001,13.517238034721133,1.0818858399020739,0.006073130948590411
122.50000000000102,13.553296971315715,1.0860113416565997,0.005284152200459857
123.60000000000103,13.588835339541001,1.093545341008571,0.0066528869173012595
124.70000000000104,13.623648593073474,1.0977661547888489,0.005261542550497822
125.80000000000106,13.660511097264925,1.1016320207456767,0.005258222269723056
126.90000000000109,13.695705511296211,1.108415106872778,0.006307274401524232
128.00000000000108,13.731904166498083,1.11297237724894,0.006575755605338074
129.1000000000011,13.766805156589072,1.1167447394905432,0.005601316108248433
130.20000000000113,13.802341655715749,1.122243615951615,0.005269589975182676
131.30000000000115,13.837749877321752,1.127654902265985,0.005270090019124929
132.40000000000117,13.872707542038654,1.1306039349686983,0.005272720358982852
133.50000000000117,13.908762885002812,1.1346592581226862,0.006204366485053292
134.6000000000012,13.943643770747526,1.1433876261680516,0.006258705297438105
135.7000000000012,13.97923888400694,1.1480572526151338,0.006259628240020909
136.8000000000012,14.01447385451611,1.153316309126096,0.006255414899764666
137.90000000000123,14.049715975710363,1.158087144103944,0.004959387494204215
139.00000000000125,14.084237233949631,1.1643798364240858,0.004939935258003736
140.10000000000127,14.119428375551424,1.1709132931981387,0.004939886300455498
141.2000000000013,14.154064568674388,1.1758186806190978,0.00493993096335732
142.3000000000013,14.189226920728053,1.1824932208180061,0.00493845319496522
143.4000000000013,14.224540571149456,1.1861570475927885,0.00530268070569484
144.50000000000134,14.25911042097088,1.1931291942862667,0.006233530708839474
145.60000000000133,14.293764225755764,1.1968789671263653,0.006259960034854295
146.70000000000135,14.328602356104444,1.2011240399629792,0.006259958673483723
147.80000000000138,14.36369361789308,1.2070091586798248,0.006259956732867167
148.9000000000014,14.398131961486806,1.2150793772768664,0.006259914419387336
150.00000000000142,14.432748018451356,1.2195418413336314,0.006254278038182015
151.10000000000142,14.467332481206894,1.226591347180741,0.007615713026649651
152.20000000000144,14.502215627453344,1.2315798114236605,0.00757115704155531
153.30000000000146,14.536472057602355,1.235359922155081,0.007033651246206141
154.40000000000146,14.571149495253811,1.2432956283767853,0.0062355285987365505
155.50000000000148,14.605513575241151,1.2477805793492436,0.0076194017578545825
156.6000000000015,14.639837840972497,1.253484336678686,0.007569833314370555
157.70000000000152,14.674293109063278,1.259571905325528,0.007546614447219824
158.80000000000155,14.708592868984613,1.2667923065540183,0.005336482698818479
159.90000000000154,14.742796003296844,1.2731516049939464,0.005270544106974029
161.00000000000156,14.77724624638985,1.2777064912670337,0.00662060326732572
162.1000000000016,14.811683094162396,1.2848906200283021,0.0065796164935871815
163.20000000000158,14.845980049910606,1.291044694322206,0.006580169705364902
164.3000000000016,14.88015605677024,1.29633751134131,0.0065800839337892825
165.40000000000163,14.914482310499075,1.3053865235139352,0.006841255413398528
166.50000000000165,14.948592998842607,1.3089720690268978,0.007568723956448586
167.60000000000167,14.982900731924605,1.315388451644399,0.0075699629270449265
168.70000000000167,15.016852139910464,1.3175072173093212,0.007569179817150662
169.8000000000017,15.051347376390993,1.318418015394781,0.007674557944151061
170.9000000000017,15.08508874705247,1.3216090649804892,0.006250393348770089
172.0000000000017,15.11943974711399,1.3264266751139353,0.006198700731370188
173.10000000000173,15.153338905182164,1.3277686551156929,0.006170624431327987
174.20000000000175,15.187236760797274,1.3324118602926325,0.006251422089159853
175.30000000000177,15.22132976113453,1.333882806458767,0.006250130413675947
176.4000000000018,15.255247351279143,1.3368116534400534,0.006250132708158773
177.5000000000018,15.289212188879093,1.3399428475789583,0.006248353958872244
178.6000000000018,15.32307484793079,1.345602941758935,0.006324129281165547
179.70000000000184,15.357128244856469,1.3446356830723007,0.005237446273996582
180.80000000000183,15.39081113372548,1.3506722751032871,0.006243391601781667
181.90000000000185,15.424254042366877,1.3553550749301198,0.006250244114084147
183.00000000000188,15.458243318227082,1.360243361699307,0.006249928984596309
184.1000000000019,15.492204266358343,1.3614675747245906,0.006249768114545695
185.20000000000192,15.525676381760523,1.3686714279190197,0.00623976870083176
186.30000000000192,15.55941480568736,1.3718729496948334,0.006571734522340833
187.40000000000194,15.592949826025992,1.3750185356511735,0.005678132758469623
188.50000000000196,15.626704292766581,1.3784933809705264,0.005267615404953574
189.60000000000196,15.659999696164881,1.3822207926746053,0.0052701599865336846
190.70000000000198,15.693454621249007,1.3865190378830778,0.005270160349707176
191.800000000002,15.72746395786191,1.385720559697954,0.005270159996451085
192.90000000000202,15.760667742545188,1.387619384113922,0.005270159999986923
194.00000000000205,15.794245827902618,1.3905525598970665,0.005270159999875013
195.10000000000204,15.82776549688952,1.3911771064392302,0.005270160006014102
196.20000000000206,15.860933590239489,1.3923545459425164,0.00527016023321103
197.3000000000021,15.894398276623187,1.3951406480693826,0.005270096969804072
198.40000000000208,15.928050724460972,1.3992459058353155,0.005273283946257479
199.5000000000021,15.961433933408964,1.4014683393708864,0.004491335490049764
200.60000000000213,15.993798081601424,1.401626360114721,0.003952254502623376
201.70000000000215,16.027894499965146,1.4064623972592816,0.0025689522108471863
202.80000000000217,16.06135217217407,1.4055112355344983,0.0026328324376478918
203.90000000000217,16.094799520689772,1.4074819886854306,0.003982272737067305
205.0000000000022,16.128165268961645,1.4119233597137075,0.003947761910375824
206.1000000000022,16.16127673236663,1.414732673364278,0.003949909390628115
207.2000000000022,16.194507745231896,1.416796471253528,0.003949888026652637
208.30000000000223,16.2276706787369,1.4195041002509472,0.0039498892280924736
209.40000000000225,16.26137695000504,1.4210370011520532,0.0039499573186612125
210.50000000000227,16.293883336035293,1.423033092561612,0.003938374931734323
211.6000000000023,16.327438975719854,1.4242177659780824,0.002735137475625926
212.7000000000023,16.36096695366997,1.428917686388615,0.0026301540302000603
213.8000000000023,16.39405214672142,1.431725281279736,0.0027080380110184876
214.90000000000234,16.42722362102446,1.4329856738744453,0.0013058610403913207
216.00000000000233,16.460797644672635,1.4344142644698452,0.001310136700026554
217.10000000000235,16.493904180875436,1.4363767347628293,0.0013101522832750234
218.20000000000238,16.52709380536254,1.4391974401360659,0.0013101813064118062
219.3000000000024,16.56000000000007,1.44316616743242,0.0013101520000002864
220.40000000000242,16.59332289743461,1.4458393802392282,-9.924467525568303e-05
221.50000000000242,16.626497832938743,1.4493696865583918,1.2629891150695016e-06
222.60000000000244,16.659511488093877,1.451754009709719,-1.742199540188949e-08
223.70000000000246,16.692409723580308,1.4539070311493743,2.054675579010734e-06
224.80000000000246,16.72614805008507,1.4550613295291586,-0.001401034188556416
225.90000000000248,16.75960832708558,1.4560101622039596,-0.001319669153684977
227.0000000000025,16.79243377059715,1.4604432510512253,-0.0012933586768228977
228.10000000000252,16.825586137782164,1.4616826701439019,-0.0021979517960657446
229.20000000000255,16.858820068482505,1.4663460335271257,-0.0016411346563538487
230.30000000000254,16.891876246535578,1.4682660375589527,-0.00295119155781709
231.40000000000256,16.925103242750378,1.4703270569616538,-0.0030426163911858595
232.5000000000026,16.95820246445046,1.4715640553614482,-0.004266165979933234
233.60000000000258,16.991291852211642,1.4752206859285248,-0.005584770472705891
234.7000000000026,17.02442177523256,1.474990288563038,-0.005518022139228584
235.80000000000263,17.0575816053049,1.4792645141635505,-0.006925397796129218
236.90000000000265,17.090359899643435,1.480842537201149,-0.008258505937617677
238.00000000000267,17.12375088067847,1.4812876177415006,-0.008231538433426167
239.10000000000267,17.156689462346872,1.4835170995507139,-0.00961361399434324
240.2000000000027,17.189746718247378,1.4836489438256404,-0.009859748115687239
241.3000000000027,17.222886762554754,1.4846083923839506,-0.010872675665252629
242.4000000000027,17.25575172729293,1.4842301307195975,-0.012276002597616298
243.50000000000273,17.28905960562563,1.483923920227629,-0.01357922688755675
244.60000000000275,17.321954505326346,1.484410066238072,-0.01523988764202322
245.70000000000277,17.354907435023783,1.4838739141451167,-0.016801750383224068
246.8000000000028,17.388470737580747,1.486497184757158,-0.01826632952685614
247.9000000000028,17.42106058188448,1.4857898778385503,-0.01974890438029142
249.0000000000028,17.45445499898421,1.4851329024601463,-0.020996443010875332
250.10000000000284,17.487163828988635,1.4813965406203986,-0.022340987843866955
251.20000000000283,17.520264061224456,1.4773926047958972,-0.024145744729795027
252.30000000000285,17.552989539267905,1.4741483538296076,-0.026095071386420976
253.40000000000288,17.585768824025536,1.4704546823055111,-0.029105123153502888
254.5000000000029,17.619277905725806,1.4653655336692197,-0.031172615394798875
255.60000000000292,17.652039975536898,1.4622142825451632,-0.03320747438289384
256.7000000000029,17.685295879884528,1.456065471541815,-0.03593643979629668
257.8000000000029,17.71748006151051,1.4503348335196864,-0.036581067354946484
258.90000000000293,17.750927756517417,1.4447059927480388,-0.038678371844648396
260.00000000000296,17.783667647383403,1.4376235257865957,-0.041238839914291336
261.100000000003,17.816866239256342,1.4298764630494705,-0.04446185214233633
262.200000000003,17.84970228830544,1.4217142828024079,-0.048817158118059645
263.300000000003,17.882401750405975,1.4147494269016931,-0.05074378840181204
264.40000000000305,17.915687835262265,1.4092966173258206,-0.053755461176919095
265.50000000000307,17.94863590941703,1.4149307264371607,-0.058145828975103786
266.6000000000031,17.98202589684493,1.4378768040787213,-0.06085622717674655
267.7000000000031,18.01577865783434,1.48113099552192,-0.06521263312751824
268.8000000000031,18.0493204154949,1.532511655112701,-0.06987334555679459
269.9000000000031,18.083154130537512,1.5839913349414259,-0.07395247871479693
271.0000000000031,18.116741769559265,1.6315944597023804,-0.07935057187861583
272.10000000000315,18.15047912277188,1.6705608737720723,-0.08582127823895469
273.2000000000032,18.184193672301255,1.707281233426245,-0.09230124971811504
274.30000000000314,18.217896017256447,1.7404851532651775,-0.09893198428219474
275.40000000000316,18.251439889307356,1.7711930089608106,-0.10625796899364381
276.5000000000032,18.28466778990044,1.7991705339815527,-0.11461616354434723
277.6000000000032,18.318322976365458,1.82846337076593,-0.12198153561080582
278.70000000000323,18.3517707887977,1.8565216913074174,-0.1300945212840836
279.80000000000325,18.385213509336353,1.8841151142312254,-0.13893429757353104
280.9000000000033,18.418984022507107,1.9117907968514114,-0.14903224273475013
282.0000000000033,18.452681334985638,1.9394744580565206,-0.16009580006193325
283.1000000000033,18.485740672059382,1.9715729649958431,-0.1717042637821269
284.20000000000334,18.519658340973375,2.0050034092299387,-0.18400638454020424
285.30000000000337,18.553245400434815,2.038479398832085,-0.19771673878111207
286.40000000000333,18.58709543900465,2.078072606729185,-0.21186924048558753
287.50000000000335,18.620980027945368,2.1163852378050794,-0.22729379798767546
288.6000000000034,18.6545879532651,2.1582372353345165,-0.24457468604782173
289.7000000000034,18.688194258617663,2.197077406013691,-0.26359876052148845
290.8000000000034,18.721964172058705,2.2346201550930815,-0.28302661768105564
291.9000000000034,18.755730814620197,2.270151934375674,-0.3053937257424182
293.0000000000034,18.789519966010687,2.3093208114354296,-0.3281182165240746
294.10000000000343,18.823380393248293,2.3423352039500975,-0.3517537741077694
295.20000000000346,18.857046252246825,2.376225481934163,-0.37643878946725895
296.3000000000035,18.890683832022678,2.4090885162806384,-0.4032509795359278
297.4000000000035,18.92464478300117,2.445374889045292,-0.43192775215553825
298.5000000000035,18.958505686448845,2.4784684199824185,-0.4621054040652779
299.60000000000355,18.991981374292706,2.511221831399614,-0.4947371733556394
300.70000000000357,19.02556373535889,2.5453567078493338,-0.5269150143254335
301.8000000000036,19.0592125267854,2.580108543339765,-0.5601466869638774
302.9000000000036,19.09293365746055,2.613724296737658,-0.5949188454507439
304.0000000000036,19.126630259885502,2.6460545882670807,-0.6320139070409896
305.1000000000036,19.16059382839196,2.681612240176717,-0.6698405080441061
306.2000000000036,19.19382572695418,2.716780503447019,-0.7115505237406392
307.30000000000365,19.228025029513034,2.753140168989518,-0.7531624166851212
308.4000000000037,19.261702790675436,2.7875867627377904,-0.7954827146280712
309.5000000000037,19.295509279961845,2.821235843765948,-0.8395597714895762
310.60000000000366,19.329211027069064,2.855332157037957,-0.8870393000739516
311.7000000000037,19.36312199098602,2.8905951835882133,-0.9375014807304192
312.8000000000037,19.39721261001843,2.919662232180882,-0.9914036652765899
313.90000000000373,19.4306817318378,2.950701730870538,-1.0453582750068922
315.00000000000375,19.464726672734084,2.9784765645045934,-1.0981252915552506
316.1000000000038,19.498306885494802,3.003504286507044,-1.152578175940996
317.2000000000038,19.531517658672477,3.0246516169384075,-1.2093491402065282
318.3000000000038,19.565538551998472,3.04509042421245,-1.269833454381696
319.40000000000384,19.59919560220243,3.062871100518196,-1.3326626522370142
320.5000000000038,19.63284596298562,3.0755748115742714,-1.3972033607272434
321.60000000000383,19.666299368571995,3.085264126244968,-1.459096228970751
322.70000000000385,19.700030261054096,3.1012994112817505,-1.5198989330798205
323.8000000000039,19.73426272755683,3.1672590684293573,-1.5848424354416197
324.9000000000039,19.76811822254248,3.213428472069652,-1.652550692022266
326.0000000000039,19.80192227171547,3.218089181630381,-1.7220755997870176
327.10000000000394,19.83485596478731,3.1825265986847966,-1.7909581518113726
328.2000000000039,19.8676331614077,3.115713958250921,-1.8564093552198222
329.30000000000393,19.900122549306932,3.0376526776220842,-1.9148455810965865
330.40000000000396,19.932302235543716,2.9377796080394996,-1.972005802082255
331.500000000004,19.964537378042763,2.8199842015575887,-2.0292399423061993
332.600000000004,19.996306813168463,2.6930649003958433,-2.084320103129221
333.700000000004,20.02843049213344,2.561871724648288,-2.135611364645853
334.80000000000405,20.060286438825663,2.4379681494390093,-2.178290511471789
335.90000000000407,20.09229976906401,2.3239289171219357,-2.218650655753776
337.0000000000041,20.124594685647292,2.224045966588993,-2.2577016300267214
338.10000000000406,20.15670185442383,2.1335050942116744,-2.2937524805766105
339.2000000000041,20.18970594480086,2.0561234114386835,-2.327866283503969
340.3000000000041,20.222010275790094,1.984789028374821,-2.357729429006211
341.4000000000041,20.254503373385067,1.9239517265780521,-2.3865102223395165
342.50000000000415,20.28711600685565,1.8670005903380322,-2.414133103419235
343.6000000000042,20.319590631422905,1.8123324533460616,-2.4406613507933472
344.7000000000042,20.35262237642773,1.7565697437062842,-2.466902854243367
345.80000000000416,20.385330569929817,1.7070823731737383,-2.4906411045863583
346.9000000000042,20.418332049599172,1.6541663883836981,-2.5125579007951666
348.0000000000042,20.450996906730726,1.60318352115687,-2.5332198128903674
349.10000000000423,20.483872366654797,1.554708042533378,-2.554671620602966
350.20000000000425,20.515969958572768,1.505865653914086,-2.575686410553608
351.3000000000043,20.54969307608926,1.4584700662452263,-2.5960893868381465
352.4000000000043,20.582344593830644,1.4094639730366931,-2.6138089680119947
353.5000000000043,20.61537727303324,1.361788712160754,-2.6301899747526596
354.60000000000434,20.647902834578424,1.3137169918747151,-2.6468836222775165
355.7000000000043,20.68127142030246,1.268240394603841,-2.6634873593931405
356.80000000000433,20.71423945250213,1.2222828159529513,-2.6787264109848783
357.90000000000435,20.747148585104533,1.1779508497194575,-2.69305096108556
359.0000000000044,20.780422629603695,1.1349981895409273,-2.7068072430503296
360.1000000000044,20.813284577068288,1.0934576437625982,-2.7195946314801844
361.2000000000044,20.846706021586524,1.0556793448175443,-2.731281088669586
362.30000000000445,20.879883464288113,1.0164118416997943,-2.7431161642789514
363.4000000000044,20.912787689573577,0.9837578644196775,-2.754471593287912
364.50000000000443,20.94642967932201,0.9508153507627406,-2.7644501251301925
365.60000000000446,20.9793086158042,0.9194432860776692,-2.773465603294045
366.7000000000045,21.011964637102288,0.8892285596067658,-2.7814060520207367
367.8000000000045,21.045517514902546,0.8603686699233237,-2.7888329577113993
368.9000000000045,21.079481618041285,0.8321619166831831,-2.7964180156001888
370.00000000000455,21.11283793011366,0.8046290783345227,-2.803734061135006
371.10000000000457,21.14646850447618,0.7793480611795375,-2.809345578125179
372.2000000000046,21.179787346342998,0.7534088172656456,-2.81556072457463
373.30000000000456,21.21343186349007,0.7309503714275039,-2.821747999687654
374.4000000000046,21.247025610572305,0.7080183922875033,-2.8258034645878496
375.5000000000046,21.280735797778895,0.6868937713163882,-2.830384120238045
376.6000000000046,21.31436897374795,0.6634136651227993,-2.8329828382905533
377.70000000000465,21.34786655986405,0.6447042801904055,-2.838500717303809
378.8000000000047,21.381667678229093,0.6237004934823884,-2.8417806610518834
379.9000000000047,21.415347162474173,0.6071476825330758,-2.845830504978074
381.00000000000466,21.448958485176895,0.5915056130836331,-2.849826320556931
382.1000000000047,21.48268440439211,0.5780322300756361,-2.851894539889477
383.2000000000047,21.516453991658185,0.563985252521755,-2.8541409665095934
384.30000000000473,21.55059117939611,0.5510969078204513,-2.8564578633541107
385.40000000000475,21.584232867843497,0.5417775258424375,-2.857968565412415
386.5000000000048,21.61791204160476,0.5358526652115558,-2.8596696506619823
387.6000000000048,21.652080200740258,0.5281592779210039,-2.860432829884026
388.7000000000048,21.686035608924477,0.5221969854603461,-2.862236036599153
389.80000000000484,21.720377347695,0.5175590275649601,-2.8635491321143025
390.9000000000048,21.75442062942829,0.5147970891221247,-2.8634408266978832
392.00000000000483,21.78837039040285,0.5119713643355687,-2.8650783595184066
393.10000000000485,21.822465362346076,0.5112240903049071,-2.8668507878980556
394.2000000000049,21.856814887370522,0.511083044046753,-2.869396018773915
395.3000000000049,21.89096939397622,0.5107461885902322,-2.8707563493568706
396.4000000000049,21.925154489849707,0.5085980603089175,-2.8706428345485495
397.50000000000495,21.959175897457612,0.5073713250522596,-2.872046566737771
398.6000000000049,21.99344339938317,0.5075574885072415,-2.873407402971273
399.70000000000493,22.027753496220825,0.5058737642222285,-2.872764688515913
400.80000000000496,22.062114517497754,0.5066110588146006,-2.8734399684833054
401.900000000005,22.096329575041803,0.507950199627209,-2.8748377677932555
403.000000000005,22.130420616777037,0.508800915676266,-2.876980105204744
404.100000000005,22.164662515669423,0.5056570838205834,-2.8778086500960556
405.20000000000505,22.1994058476706,0.5041078115297127,-2.8783005495705725
406.30000000000507,22.233639614296095,0.5044515880015322,-2.879354551512664
407.4000000000051,22.26797991661563,0.5013798521725904,-2.879083450976934
408.50000000000506,22.3026862871956,0.4982978490801906,-2.880657416402883
409.6000000000051,22.33686102871067,0.49809123764318464,-2.882436486837238
410.7000000000051,22.37134579187283,0.49284056553504085,-2.8833493881071868
411.8000000000051,22.405443113944074,0.4920181732329486,-2.8840317138575804
412.90000000000515,22.439906049340312,0.4895173798865118,-2.883905916380046
414.0000000000052,22.47456500369626,0.48452559704817577,-2.885207005621738
415.1000000000052,22.508991276271345,0.4826037404749842,-2.8865228978898974
416.20000000000516,22.54327171353251,0.4795730259441342,-2.887452778774703
417.3000000000052,22.57765918047895,0.47806808916453536,-2.8886109652840504
418.4000000000052,22.6123795338431,0.4727993243046762,-2.889143890273753
419.50000000000523,22.6467261068526,0.4743779615778638,-2.889817961330618
420.60000000000525,22.6816559291848,0.47308393875326016,-2.8914648388036888
421.7000000000053,22.71604742196715,0.47120483437591343,-2.8932906023850458
422.8000000000053,22.75079234913905,0.46664996369910927,-2.8958388049902326
423.9000000000053,22.785194455861998,0.4642346304489924,-2.8978964665386417
425.00000000000534,22.81971785082301,0.46079571438018163,-2.899482708671691
426.1000000000053,22.854419831282367,0.4574730681494056,-2.9008273116126673
427.20000000000533,22.888992057971084,0.45317449925985365,-2.901696476329235
428.30000000000535,22.923747966328325,0.45134045876587714,-2.9034050155807027
429.4000000000054,22.958319200994737,0.4473069089578674,-2.9053717903106873
430.5000000000054,22.993186261635227,0.44312756138649956,-2.906991342785786
431.6000000000054,23.02759915780051,0.43831032736418907,-2.908344831591199
432.70000000000545,23.06230508192295,0.43460153494181875,-2.909761312845036
433.8000000000054,23.097330848693268,0.4278172968269942,-2.9111785872586555
434.90000000000543,23.131925338393653,0.4238900174528546,-2.9138400480453788
436.00000000000546,23.166669058399766,0.4192565403120697,-2.91588511361541
437.1000000000055,23.2016090769442,0.4138627721554653,-2.9180041672958383
438.2000000000055,23.235919035547017,0.40742409343361297,-2.9209837235558194
439.3000000000055,23.27072908732702,0.4005277213775116,-2.9232069047256033
440.40000000000555,23.305734842673125,0.3956673824074728,-2.925198193356624
441.50000000000557,23.34060122931333,0.39035285376089435,-2.9286326861499887
442.6000000000056,23.375283485695203,0.3839636549385942,-2.93160969028227
443.70000000000556,23.41006453074611,0.3760347613465198,-2.934516798092819
444.8000000000056,23.445092426760013,0.37318298411114004,-2.9382953256730313
445.9000000000056,23.479742195669548,0.3685745822054679,-2.942147124924201
447.0000000000056,23.51495679756858,0.3618899147841069,-2.943533582479577
448.10000000000565,23.54974815593097,0.3600244958399589,-2.946668018657087
449.2000000000057,23.584415501419954,0.35899455453501616,-2.9501225394840693
450.3000000000057,23.619781722808096,0.3545476429134865,-2.954685205806906
451.40000000000566,23.654690236957887,0.35487652191193353,-2.958711672733677
452.5000000000057,23.68996849580214,0.35376074696202986,-2.963705430127881
453.6000000000057,23.724852247304852,0.3543132301102535,-2.9680246651258173
454.70000000000573,23.759775896936215,0.3559956897673646,-2.972890862118196
455.80000000000575,23.79451576661846,0.35965722404853906,-2.9787671144091226
456.9000000000058,23.830221323680462,0.3636123938052087,-2.9843920610306847
458.0000000000058,23.865412889294355,0.3674217034276198,-2.9890434887568884
459.1000000000058,23.900232467850657,0.37302499930513844,-2.9939308981398285
460.20000000000584,23.935489117384726,0.380024412508006,-3.0010116728122997
461.3000000000058,23.970797356167033,0.3909076786642759,-3.00612829330064
462.40000000000583,24.006315214737626,0.39992005567494393,-3.0111809647840353
463.50000000000585,24.041373721495773,0.4125243554843113,-3.01819449698231
464.6000000000059,24.076483858593733,0.4292156451591792,-3.0245922609885327
465.7000000000059,24.111901930074087,0.44405422248879167,-3.031650109373129
466.8000000000059,24.147355450686852,0.4618178724426161,-3.039898969912233
467.90000000000595,24.18304695299246,0.47898434362513065,-3.0476744490969505
469.0000000000059,24.21840922290783,0.5042983386952822,-3.0554692914824786
470.10000000000593,24.25394857840368,0.5373868521080571,-3.061504064178145
471.20000000000596,24.28955741285157,0.5767948607959215,-3.070304728367649
472.300000000006,24.32528118046292,0.6306657494931589,-3.080553729142128
473.400000000006,24.361722717507728,0.7130062515709752,-3.092421386051126
474.500000000006,24.398270450552307,0.8022350216787264,-3.106935320100317
475.60000000000605,24.434015756231318,0.8531054749724853,-3.1226067708466854
476.70000000000607,24.468789504278405,0.8724064920173586,-3.141831592909649
477.8000000000061,24.504616206747887,0.8664851660462083,-3.1623731432838857
478.90000000000606,24.54006496361333,0.8489183091805492,-3.1814491544061196
480.0000000000061,24.575163967222437,0.8288235398620627,-3.198236191655382
481.1000000000061,24.610424933244836,0.8082983237985146,-3.2143042245769426
482.2000000000061,24.645345949884973,0.790874832774737,-3.2294830800599597
483.30000000000615,24.6810059177618,0.7796807243803932,-3.2438547728545477
484.4000000000062,24.716014384295978,0.7679670110709746,-3.2570437445002325
485.5000000000062,24.751438592964355,0.7570618708196135,-3.269366022309652
486.60000000000616,24.78664498914154,0.7479673878989286,-3.279734641187491
487.7000000000062,24.8220442304132,0.7413827203371988,-3.290696326826244
488.8000000000062,24.85737052518765,0.7342185070132672,-3.301980476754468
489.90000000000623,24.892387471989256,0.7288916483857388,-3.3137211272495986
491.00000000000625,24.92810907569902,0.719933733567373,-3.325381832951176
492.1000000000063,24.96327563329583,0.7177707582388084,-3.336654015939131
493.2000000000063,24.998790933176533,0.7097819777779775,-3.3472138769320505
494.3000000000063,25.03397378286795,0.7054045871025287,-3.358602297032273
495.40000000000634,25.069672833114822,0.6994129624909304,-3.369159496419287
496.5000000000063,25.103962208347287,0.6920705553316722,-3.3780144431558154
497.60000000000633,25.140251714590313,0.683336260924762,-3.387433814950569
498.70000000000636,25.175525228791905,0.6775263836133902,-3.3956988495349254
499.8000000000064,25.211083474669806,0.6693764107875233,-3.4056733319150974
500.9000000000064,25.246369150663096,0.6657303628459428,-3.413771179547248
502.0000000000064,25.28177259543515,0.6556873437804986,-3.42230044986231
503.10000000000645,25.317357357619684,0.6475288174137306,-3.4305060197541737
504.2000000000064,25.35238428918291,0.6406775621037653,-3.4386174047316826
505.30000000000643,25.387451024076714,0.6317974874297738,-3.447093768703934
506.40000000000646,25.423505675116278,0.6220422389555533,-3.455236141438853
507.5000000000065,25.458548497480045,0.6133266360476615,-3.462801738117581
508.6000000000065,25.494312749466687,0.6056108504222937,-3.470060149864983
509.7000000000065,25.529488157749032,0.5993364966809263,-3.475736612388898
510.80000000000655,25.56477744627779,0.5912548336291612,-3.48124886618675
511.90000000000657,25.60044418819196,0.5820901442564717,-3.4882129719075765
513.0000000000066,25.635960053377225,0.5790298023584894,-3.4953873372383546
514.1000000000065,25.67152610867982,0.5710468569482516,-3.5032954675871153
515.2000000000066,25.70701710561671,0.5616770975772245,-3.508251875936248
516.3000000000065,25.74271218438204,0.5562353426529127,-3.5137945427312327
517.4000000000067,25.778017297268004,0.5448849746855697,-3.519507593140786
518.5000000000066,25.81368346093597,0.5424367080352566,-3.525059891239443
519.6000000000067,25.84842131970576,0.5339675056888626,-3.5286344852380624
520.7000000000066,25.884698066274353,0.5286446306180514,-3.532765530758123
521.8000000000067,25.920353926269616,0.5231212469966733,-3.536922074119353
522.9000000000067,25.955735453179404,0.5160218583963379,-3.540897099420892
524.0000000000067,25.991538339379513,0.5152534956187949,-3.5452822609187393
525.1000000000067,26.02715944813873,0.5100485660368499,-3.54929395661435
526.2000000000068,26.062579471165005,0.5054499954846823,-3.5527824389288076
527.3000000000068,26.098198046274646,0.5032106531337064,-3.5556507781557407
528.4000000000068,26.13430540472478,0.4965273512133386,-3.5573839413267985
529.5000000000068,26.1697121537188,0.496383877770473,-3.560147234197664
530.6000000000068,26.205364250323232,0.4888011791509477,-3.5626637416253786
531.7000000000069,26.24050714329487,0.48719129114330095,-3.5663888176560032
532.8000000000068,26.276661717904688,0.48237202724092487,-3.568212694926855
533.9000000000069,26.312681232752645,0.48020090735416376,-3.5711853188912808
535.0000000000068,26.348406870473077,0.478528765093996,-3.5724496515100483
536.100000000007,26.384344978507006,0.47648948674268476,-3.575034607486302
537.2000000000069,26.420163392524163,0.47317620730199716,-3.576315650321499
538.300000000007,26.455774659488025,0.47192531402209026,-3.5777407015025413
539.4000000000069,26.491659753935526,0.4708344835305258,-3.5790318645473667
540.5000000000069,26.527600600765812,0.47306719671751174,-3.5812799141158167
541.600000000007,26.56324455153456,0.47211740040076533,-3.5815995658980926
542.700000000007,26.599356425664535,0.46954292923681495,-3.583483182356553
543.800000000007,26.63520958565999,0.4703477347854135,-3.5860713706312835
544.900000000007,26.67049794710936,0.46808664489059315,-3.587722050339779
546.000000000007,26.707093262574894,0.47202036770708844,-3.5898823206316894
547.1000000000071,26.742582616786432,0.4703169580146773,-3.5895719234407877
548.2000000000071,26.779121428127368,0.4698242754229338,-3.5898423827792167
549.300000000007,26.81498760832896,0.4704954684994411,-3.591876594578268
550.4000000000071,26.85090844870741,0.4688966687156282,-3.5928505152825947
551.500000000007,26.8869809096633,0.4697085472868865,-3.5937676304648463
552.6000000000072,26.923310165603525,0.4723117091085036,-3.5953792308926054
553.7000000000071,26.959058951558912,0.4713833727988186,-3.5972992819152037
554.8000000000072,26.99514241056437,0.47256877589602775,-3.5980545626492617
555.9000000000071,27.031246390933855,0.47031064506061315,-3.598483099291481
557.0000000000072,27.06715264366239,0.4780187930272366,-3.599346356491598
558.1000000000072,27.103495343029884,0.47470051125952595,-3.6006429895735317
559.2000000000072,27.139425014832316,0.47525570438298415,-3.600670154045085
560.3000000000072,27.175567505856083,0.47524829139898794,-3.6006642174433385
561.4000000000073,27.211569830119636,0.47441165119334694,-3.6019711113138513
562.5000000000073,27.247876741679523,0.4755314113091633,-3.6027572215085786
563.6000000000073,27.284094177644942,0.4786548381081954,-3.602280523056784
564.7000000000073,27.319932920254665,0.4763832207813863,-3.6036305609459007
565.8000000000073,27.35632897447825,0.4778213489647922,-3.603657271429859
566.9000000000074,27.392350328559168,0.4777241869700062,-3.6049538502405403
568.0000000000074,27.428670051256702,0.4772564782467703,-3.604949956131444
569.1000000000074,27.465011174288474,0.4758540141869678,-3.605017648433466
570.2000000000073,27.50117142007461,0.47747586680215703,-3.6062741352833445
571.3000000000073,27.537246508343454,0.47995243683245725,-3.6062631357907886
572.4000000000074,27.573506087319934,0.4783511312505073,-3.607564348537503
573.5000000000074,27.609703924954225,0.47851217985361316,-3.607589794946403
574.6000000000074,27.64526697798055,0.47677119981999394,-3.6075609610130037
575.7000000000074,27.68226934074105,0.47941070826101684,-3.608927301303001
576.8000000000075,27.718833767514237,0.47713406818953263,-3.610315112651606
577.9000000000075,27.75508920416398,0.4798613521023303,-3.6089011081342983
579.0000000000075,27.791398823458927,0.4773705594881883,-3.6089006719964054
580.1000000000075,27.827409037897176,0.47676694079376136,-3.610018112966455
581.2000000000075,27.864043189972897,0.47748536987635415,-3.6088644536605248
582.3000000000076,27.900360302760294,0.4802098875811738,-3.6102256608484007
583.4000000000076,27.936657040791584,0.4785430656237617,-3.6102223478996556
584.5000000000076,27.972798742916027,0.47802031440537296,-3.6115158204462054
585.6000000000076,28.009440626996867,0.4773990068346321,-3.612120581295514
586.7000000000077,28.04572023103161,0.4756031699712435,-3.6125185908177615
587.8000000000077,28.082527381100242,0.4768883583053749,-3.6125199814388127
588.9000000000076,28.11865426620117,0.4772168927113749,-3.612528696411041
590.0000000000076,28.155024038432085,0.4758800587277012,-3.6138907735183214
591.1000000000076,28.191522099218513,0.4763703268060884,-3.61305149484481
592.2000000000077,28.227946872894243,0.4754242128879336,-3.612529357971557
593.3000000000077,28.26439571433707,0.47330179024619246,-3.6125308439273445
594.4000000000077,28.300763673670293,0.47310244354245135,-3.612556993628408
595.5000000000077,28.337019843134783,0.47532990491785876,-3.6138417504525044
596.6000000000078,28.37386602216306,0.4729284373983298,-3.6138497455386847
597.7000000000078,28.41016359843697,0.47435538868005067,-3.6138496474187596
598.8000000000078,28.44659813781609,0.47463831577486504,-3.6152327781674694
599.9000000000078,28.483268600299272,0.47725939548283836,-3.615170578725453
601.0000000000078,28.519643448311673,0.47560641404483706,-3.615170142103772
602.1000000000079,28.556293866713165,0.4790467425548035,-3.6152785952778257
603.2000000000079,28.59282258786949,0.4751646622046828,-3.616482484974249
604.3000000000079,28.629461993996763,0.4775117533195292,-3.6174232142815916
605.4000000000078,28.666005490933845,0.47897967945713904,-3.6178005395745894
606.5000000000078,28.702229783511466,0.48048960567744703,-3.617799992587469
607.6000000000079,28.738797210060692,0.4794931647757543,-3.6178603281191615
608.7000000000079,28.775419153334898,0.4808782235247897,-3.6170859912390183
609.8000000000079,28.81181324561247,0.48113077817479555,-3.6177713115518917
610.9000000000079,28.8485405882539,0.48288293696148266,-3.6178008149092666
612.000000000008,28.885231632602817,0.48502182662983184,-3.617800009799697
613.100000000008,28.921523685400796,0.4867201816207607,-3.6177992331714606
614.200000000008,28.958307750618637,0.48892897849517913,-3.618307554822103
615.300000000008,28.99483973792426,0.4869096917522322,-3.61847446686605
616.400000000008,29.030778541419718,0.48745927657102217,-3.619109672431953
617.5000000000081,29.067893710345977,0.490443535299413,-3.6207203392204215
618.6000000000081,29.10368002495738,0.48970272170483686,-3.6221398781723693
619.7000000000081,29.141257150380238,0.49253421787302476,-3.621755770402267
620.8000000000081,29.17786788237283,0.49083535032305337,-3.6220814144410753
621.9000000000082,29.214468914349972,0.490565335102795,-3.6220851892805404
623.0000000000082,29.250685912707144,0.4877577786168348,-3.620775426899316
624.1000000000081,29.287316725307157,0.4884277780130235,-3.6206613610483696
625.2000000000081,29.324106047895366,0.4901315466918943,-3.622972522059624
626.3000000000081,29.360637779115315,0.4894826720212022,-3.6230696578546637
627.4000000000082,29.397644679786804,0.491906191539057,-3.6230695630590426
628.5000000000082,29.433948366932086,0.48757704981699646,-3.6238111337076857
629.6000000000082,29.470630649902102,0.4893150925933927,-3.6243895012666503
630.7000000000082,29.507659664272346,0.4883517663048176,-3.624390079499119
631.8000000000083,29.54325451834744,0.48617333977205623,-3.6243783562033625
632.9000000000083,29.580693493944743,0.4859179236583402,-3.625359530432729
634.0000000000083,29.617325499483734,0.48892969607098014,-3.625692268513349
635.1000000000083,29.65410266330422,0.484254903625005,-3.6243739685426903
636.2000000000083,29.69079938238698,0.48443771689387094,-3.6243834818899923
637.3000000000084,29.727558039123462,0.48518083446655846,-3.6256815807849945
638.4000000000084,29.764230652742658,0.48654728064863173,-3.625691653988523
639.5000000000084,29.800622378929425,0.48368332530826774,-3.626994054679758
640.6000000000083,29.837424979666878,0.4821889838889859,-3.6270023023003297
641.7000000000083,29.874089160111843,0.48158580105957816,-3.6280019062325315
642.8000000000084,29.910970167173055,0.47674582825681155,-3.6267166615709248
643.9000000000084,29.947778683694793,0.4758014206679224,-3.626697941959615
645.0000000000084,29.98433907103211,0.4763948927008683,-3.627021310101521
646.1000000000084,30.020272998791963,0.47202279582758755,-3.6283471821540694
647.2000000000085,30.05800175303886,0.47725481633651934,-3.62833953528618
648.3000000000085,30.09476784681813,0.4725793880037945,-3.6283398619408
649.4000000000085,30.131668288159666,0.47156747408972954,-3.6283238172451737
650.5000000000085,30.168413855818542,0.4727016010019398,-3.626987726667366
651.6000000000085,30.205124274548385,0.46805560732337415,-3.627030031377999
652.7000000000086,30.24183722469478,0.4690065679050084,-3.627029965949912
653.8000000000086,30.278735333693962,0.46376714721576406,-3.6270258753820452
654.9000000000086,30.315720018728857,0.4606417136897598,-3.628291378510028
656.0000000000086,30.352681683877137,0.4606494123966802,-3.628339954665308
657.1000000000087,30.389302756770128,0.45899970312380844,-3.6283400883333847
658.2000000000087,30.425753604108124,0.4588769226134697,-3.6283400880163694
659.3000000000086,30.463205332803554,0.4553988251912966,-3.6283400885911266
660.4000000000086,30.500033956552937,0.45594383621996726,-3.6283400890086193
661.5000000000086,30.53706846663231,0.4506011602389497,-3.6283305983540304
662.6000000000087,30.574010781973595,0.45022100402577037,-3.628019284782575
663.7000000000087,30.61074974395126,0.44568670622885787,-3.6280100388580583
664.8000000000087,30.647916751997773,0.4423966231417997,-3.6280100184431516
665.9000000000087,30.684791912223865,0.44018454893588066,-3.6280097664458104
667.0000000000088,30.721422150044113,0.4371266965057523,-3.6279952187316784
668.1000000000088,30.75868867318632,0.4345774160767626,-3.6293417035586177
669.2000000000088,30.795297073402175,0.43195728658747634,-3.6293301106525955
670.3000000000088,30.832700854528593,0.43003276474027374,-3.6293296044561414
671.4000000000088,30.869305021589785,0.43150590580512826,-3.629339855912531
672.5000000000089,30.90619042409093,0.42990926716404076,-3.6306544299969494
673.6000000000089,30.94334723969105,0.42517731799095637,-3.630652443188819
674.7000000000089,30.980099894974423,0.4252190486789036,-3.629931011018429
675.8000000000088,31.0168261417654,0.42064399137456143,-3.6299900158515146
676.9000000000088,31.054063231020603,0.41950240629822244,-3.629987627066549
678.0000000000089,31.09110333782945,0.41892749529249396,-3.629342056728893
679.1000000000089,31.127246557551096,0.41468629489119446,-3.6293301312845414
680.2000000000089,31.165044308638766,0.41257898324532616,-3.629322561451572
681.3000000000089,31.20190070866764,0.40758263062175226,-3.628425368455594
682.400000000009,31.23875681498936,0.40162182461966434,-3.628670362073116
683.500000000009,31.275840064120057,0.3946967398933141,-3.6286699999870766
684.600000000009,31.312930215169455,0.38508823218000243,-3.6286810840461587
685.700000000009,31.349661038464845,0.377937695918251,-3.629333983038565
686.800000000009,31.386551525166812,0.3730636769810174,-3.629330276829332
687.9000000000091,31.42388037608703,0.36112443085517243,-3.629330028343855
689.0000000000091,31.46053496855122,0.3568515681751008,-3.62932999106967
690.1000000000091,31.49763316014952,0.35095569343373767,-3.629491646438302
691.2000000000091,31.53473824626013,0.34325935009149044,-3.6306468484782206
692.3000000000092,31.571917507292042,0.33616354673248217,-3.6306336262069334
693.4000000000092,31.60901827588538,0.3322910563404282,-3.630023362105391
694.5000000000091,31.64574709421423,0.330109739630043,-3.629320254952585
695.6000000000091,31.68294166294483,0.32838319603005317,-3.6286339470046687
696.7000000000091,31.719929655268086,0.3261165636387182,-3.6286600691118487
697.8000000000092,31.756891687777756,0.3212493777113261,-3.6286600642557456
698.9000000000092,31.793843398698733,0.32088884276489793,-3.6286598533178154
700.0000000000092,31.830883916070107,0.3185757882581288,-3.6286518323127774
701.1000000000092,31.86855047364625,0.31884408588757984,-3.629994255618613
702.2000000000093,31.905487170496915,0.3166031851330684,-3.6299801631765574
703.3000000000093,31.942561317865568,0.31709478278682157,-3.6299797827578155
704.4000000000093,31.9797628791907,0.312841318075193,-3.6300174738502275
705.5000000000093,32.016995840936104,0.3121381218519006,-3.628709733659433
706.6000000000093,32.05362705076979,0.3123226468952707,-3.6299955725273323
707.7000000000094,32.0911952860555,0.3108033443667355,-3.62998981611599
708.8000000000094,32.12832786353078,0.31069205421161517,-3.6299897847257108
709.9000000000094,32.16553150146634,0.30518088153566536,-3.629985804866683
711.0000000000093,32.20265668634796,0.3039178608800088,-3.6308670713858318
712.1000000000093,32.239832567795716,0.30453232902910754,-3.6313101688867544
713.2000000000094,32.277091276308084,0.30359827743329193,-3.631308575302497
714.3000000000094,32.314460606042424,0.29986009355498044,-3.6298964059892205
715.4000000000094,32.35163670877104,0.30031411967634813,-3.6299902816388547
716.5000000000094,32.38819323338599,0.3012686189278262,-3.629991320069373
717.6000000000095,32.42613160876704,0.2975463832159071,-3.6313766082369954
718.7000000000095,32.46321990022398,0.2923814601842647,-3.6313003576222584
719.8000000000095,32.50040554253326,0.2911155368478697,-3.6312998412871518
720.9000000000095,32.53797673904141,0.29124444049705867,-3.631300103031113
722.0000000000095,32.57484580772515,0.29137390001627894,-3.631337464123227
723.1000000000096,32.61219005321106,0.28751894536170663,-3.6299519436400844
724.2000000000096,32.649703159912846,0.28636940161074476,-3.630963783217885
725.3000000000096,32.686406124619545,0.2857874618122245,-3.6312924369896367
726.4000000000096,32.72399492642059,0.2834581699851202,-3.631299871128939
727.5000000000097,32.76180154575663,0.28233377648945446,-3.631301433049871
728.6000000000097,32.79900883458473,0.2769340060621053,-3.6322996857685723
729.7000000000096,32.83624032394328,0.2786162013767477,-3.6322901990571275
730.8000000000096,32.87340784407527,0.27423186789815723,-3.632290217662038
731.9000000000096,32.91086200263023,0.26886367186671567,-3.6322849836740376
733.0000000000097,32.94826172629666,0.2660498066241921,-3.630936658675846
734.1000000000097,32.98554269583959,0.26589818174646496,-3.630961717309777
735.2000000000097,33.02265354114587,0.2632349077003777,-3.6322757793208567
736.3000000000097,33.06003419169171,0.2611936588058139,-3.6336055246054
737.4000000000098,33.097375683055695,0.2607251897311933,-3.63361053106893
738.5000000000098,33.135053758673656,0.25797062871042975,-3.6328999469721692
739.6000000000098,33.17209250289502,0.2597084146457247,-3.632291038049014
740.7000000000098,33.21003516411988,0.26538037442903306,-3.632272242489301
741.8000000000098,33.247450280649566,0.26414459728038686,-3.630964043076906
742.9000000000099,33.28449726945137,0.26110767304248306,-3.630969942693394
744.0000000000099,33.32199096801549,0.26164080765939124,-3.6309699799600725