File: 01_Data/Bamboo_Rug_Bamboo/STA/N2/10K_min/Bamboo_Rug_Bamboo_STA_N2_10KData_220120_R2.csv
##Temp./Â°C,Time/min,DSC/(mW/mg),Mass loss/mg
50.0,10.793803603524083,0.038745269969112095,-0.04390890717690077
51.20000000000002,11.09412908895879,0.07437866777545932,-0.04423267303939138
52.400000000000034,11.31349776490767,0.09983078217843311,-0.044880555021459045
53.60000000000005,11.49622573776676,0.12141258557896328,-0.044861772151111534
54.80000000000007,11.661050490887504,0.13709690332493607,-0.045572735597025904
56.000000000000085,11.815717031360458,0.14788715113883988,-0.047116412467556934
57.2000000000001,11.96248715748288,0.15878036700562637,-0.046816884122590885
58.40000000000012,12.106571899107514,0.16921275069661212,-0.04651325470341039
59.600000000000136,12.244387728642536,0.17634691557596582,-0.04631092759211475
60.80000000000015,12.38227194058738,0.1804948614628039,-0.046150206791106374
62.00000000000017,12.516725462445658,0.18732873535436145,-0.04845551756617805
63.20000000000019,12.650215489878708,0.1902137400450531,-0.048167422896005174
64.4000000000002,12.781746497674527,0.1982876358584178,-0.04874041542278684
65.60000000000022,12.912564091887445,0.20242317204627835,-0.04939859960086235
66.80000000000024,13.042408009634135,0.20486925878080453,-0.050020172652391004
68.00000000000026,13.172138362664002,0.20896077052490492,-0.051329689040400694
69.20000000000027,13.300000000000027,0.21247767036909126,-0.05275982495072462
70.40000000000029,13.428103687995245,0.21651362326829604,-0.05418307968549341
71.6000000000003,13.554784476104512,0.2192602553486036,-0.05293407504909986
72.80000000000032,13.682392085431403,0.22089679863545675,-0.05418209453604517
74.00000000000034,13.805144501865493,0.22517430077232276,-0.054191948071544704
75.20000000000036,13.934847312390644,0.22791910379645258,-0.05686527452289036
76.40000000000038,14.06119430078238,0.23010185863530613,-0.05548060815546929
77.60000000000039,14.185301151186723,0.23199945503507163,-0.05595639229668192
78.80000000000041,14.309597731463738,0.23458281039766293,-0.05681840455163245
80.00000000000043,14.434432499314559,0.23369095745888274,-0.058359818991903456
81.20000000000044,14.557949427253519,0.23387525325064923,-0.05953624404202973
82.40000000000046,14.682544172944409,0.23710227810461693,-0.05974760670883139
83.60000000000048,14.804470752592406,0.23970382024954712,-0.06044014921430385
84.8000000000005,14.926428957295956,0.2402627636581262,-0.05957039072510284
86.00000000000051,15.048206936384661,0.24186541673165662,-0.06241034412109814
87.20000000000053,15.16923162042728,0.24169592456196304,-0.06247896634165917
88.40000000000055,15.29025651718409,0.24006814318487518,-0.06182634443999291
89.60000000000056,15.409899244200849,0.23953768352074556,-0.06208914143172439
90.80000000000058,15.53114334931214,0.23956069259451712,-0.06481750756840876
92.0000000000006,15.652244263046107,0.2405509727089737,-0.06504256991957735
93.20000000000061,15.77098232128612,0.23866263383448777,-0.06494013479621819
94.40000000000063,15.889622169005664,0.2357840964931064,-0.06361105088295549
95.60000000000065,16.008275984421367,0.2376685209709477,-0.0636201770336231
96.80000000000067,16.127599660738234,0.23526781609600506,-0.06496525274118703
98.00000000000068,16.246614911632477,0.23467539692274547,-0.06494883335001322
99.2000000000007,16.36363519846654,0.232622741179017,-0.06627423515116249
100.40000000000072,16.481512163769317,0.2328226535175173,-0.06822234239593206
101.60000000000073,16.60010372610432,0.23404347354845023,-0.06790030415972526
102.80000000000075,16.719152705025927,0.23200737503654473,-0.06691963482952756
104.00000000000077,16.83719566417514,0.22896743426468663,-0.06562187809712094
105.20000000000078,16.95494055546126,0.22979218316133232,-0.06559665585207686
106.4000000000008,17.072073623035248,0.23015943493171181,-0.06690894417152515
107.60000000000082,17.19059639246323,0.23166309002340668,-0.0669170753679098
108.80000000000084,17.309326162819904,0.23107325744893248,-0.06821141299251687
110.00000000000085,17.425941472612212,0.23278098628581156,-0.06690397897572886
111.20000000000087,17.54422473108763,0.2316305627121033,-0.06822986706874445
112.40000000000089,17.661273788074347,0.23006042305725777,-0.06954686342221583
113.6000000000009,17.77676944346041,0.22873878409213022,-0.07046479462072996
114.80000000000092,17.89508469478668,0.23087997120581394,-0.06985448729444688
116.00000000000094,18.013027135062284,0.2320555475613058,-0.06987012099762024
117.20000000000095,18.13126928720887,0.23145847054935142,-0.06987115168092872
118.40000000000097,18.248270299429606,0.23177110207697577,-0.07119208806267485
119.60000000000099,18.36416473625359,0.23368051064499462,-0.06957211324561774
120.800000000001,18.482750884626572,0.2343713768706973,-0.07088812940426026
122.00000000000102,18.59981520190498,0.23601264198225907,-0.06954091074020718
123.20000000000104,18.71627710734358,0.23457158843571413,-0.07108748032423318
124.40000000000106,18.83375094399184,0.23593677565333454,-0.07137131913166783
125.60000000000107,18.949814426830766,0.2385660501439496,-0.07217948823638842
126.80000000000109,19.066477569166246,0.23731619914335692,-0.07118991670030006
128.0000000000011,19.182692552888877,0.24010255289498367,-0.07250989694028043
129.20000000000113,19.299434260603086,0.24087119347983968,-0.07382000936768396
130.40000000000114,19.416630386593695,0.24274705041793504,-0.07505633208190998
131.60000000000116,19.532479288627353,0.2467433176547883,-0.07481047959582154
132.80000000000118,19.648313431786928,0.24620559474145895,-0.07452419640426156
134.0000000000012,19.76502219335717,0.2465308510840229,-0.07348903138872709
135.2000000000012,19.881052901915744,0.24766969769497524,-0.072201525642134
136.40000000000123,19.996586420937636,0.24671199784482903,-0.07356848106963909
137.60000000000124,20.11231109613373,0.2477727023510552,-0.07514184889193709
138.80000000000126,20.22981326647026,0.2485806590274464,-0.07581020044614295
140.00000000000128,20.34478465447799,0.2491252293402395,-0.07599060061620166
141.2000000000013,20.461597886746357,0.2529394153788323,-0.07732934713341111
142.4000000000013,20.577635330918532,0.2520946774393501,-0.07597195111210109
143.60000000000133,20.6934224945248,0.2526818940793998,-0.07699984244138935
144.80000000000135,20.809256548229136,0.25465798243304494,-0.07733070478032955
146.00000000000136,20.92515082417079,0.2561478457577577,-0.07996996839599424
147.20000000000138,21.04116274808218,0.25785891612278417,-0.08127724228830946
148.4000000000014,21.154553728128857,0.2570479527853076,-0.08129178043855667
149.60000000000142,21.271951505982493,0.25986621105813285,-0.07995984531881062
150.80000000000143,21.38728540061495,0.2609460543257084,-0.07995981560678533
152.00000000000145,21.50320152648084,0.2643106016059919,-0.08127998791715552
153.20000000000147,21.620000000000143,0.26603860956404124,-0.08122491614431837
154.40000000000148,21.735136425094538,0.26792806897496974,-0.08129014213244545
155.6000000000015,21.850314258302028,0.2701476431070406,-0.08129113680932099
156.80000000000152,21.964380694800397,0.2709343000576649,-0.08257453443137619
158.00000000000153,22.08122882898548,0.2751321608292491,-0.08676980317552907
159.20000000000155,22.196057229766883,0.2750245266389322,-0.08677013693749736
160.40000000000157,22.310317234408174,0.27722909051697203,-0.08549373441781194
161.6000000000016,22.426827890046614,0.2784503467342784,-0.0851205193053115
162.8000000000016,22.540620355159348,0.2798977212205919,-0.08446228673695355
164.00000000000162,22.655753584821614,0.28101166301513997,-0.08576987413904735
165.20000000000164,22.772536155158342,0.28443286715060956,-0.08708999512176385
166.40000000000165,22.88595109008057,0.286014940698197,-0.08707908289799171
167.60000000000167,23.001050210509266,0.2881410492473172,-0.08808023025748835
168.8000000000017,23.115944332061193,0.2884035290275442,-0.08939009753071403
170.0000000000017,23.231029361484612,0.2911736578631008,-0.08907394126952672
171.20000000000172,23.3459833547906,0.2943788616909874,-0.09039005723250071
172.40000000000174,23.460788097298863,0.29629017849110506,-0.09103335024410786
173.60000000000176,23.576390062184224,0.29736100001978244,-0.09236018021548764
174.80000000000177,23.691800997387045,0.29727640946438794,-0.09236017999993384
176.0000000000018,23.80718657423886,0.29918545996958135,-0.09236047666187108
177.2000000000018,23.921361831096,0.30129049700329774,-0.09168557415499601
178.40000000000182,24.035257087778902,0.30315372989560363,-0.09301458986712108
179.60000000000184,24.1515039841013,0.3087038375091361,-0.09367017903962882
180.80000000000186,24.265318623007825,0.3066096680970256,-0.09430765172350775
182.00000000000188,24.38094227100634,0.31031931184113987,-0.09698664507419386
183.2000000000019,24.49594126607165,0.31299188420431523,-0.09828124530677895
184.4000000000019,24.612046241144213,0.31321890753920983,-0.09926990547210623
185.60000000000193,24.72680797258941,0.31663251865425157,-0.09958063857384891
186.80000000000194,24.840770940356258,0.31988918366070357,-0.10218395152154214
188.00000000000196,24.95586044984527,0.3209983774872829,-0.09948181457004024
189.20000000000198,25.0703923075691,0.3246748767904051,-0.10213107118524345
190.400000000002,25.185502525296688,0.3250046285267265,-0.10336675315961896
191.600000000002,25.296611359939345,0.3272217888690688,-0.10585124469649854
192.80000000000203,25.415227285913762,0.33064318075996757,-0.10737981962663357
194.00000000000205,25.529478804685333,0.3307412659474724,-0.10869406544898652
195.20000000000206,25.644026449438616,0.3338310280163864,-0.11134009453022742
196.40000000000208,25.758887359755263,0.3384289874433216,-0.11034448833109956
197.6000000000021,25.872887510101236,0.33918423119939156,-0.11166048597476497
198.80000000000211,25.988390029089025,0.3432245997692479,-0.11397651465980907
200.00000000000213,26.102356096578113,0.3439527108707418,-0.11560550341028009
201.20000000000215,26.217625079599742,0.346597370088328,-0.11902841544515308
202.40000000000217,26.33169911699892,0.3481651199303035,-0.11975280025458535
203.60000000000218,26.446234950144966,0.35033291756859775,-0.1209177539159918
204.8000000000022,26.560271133602043,0.35351365216340813,-0.12087484518339853
206.00000000000222,26.67565444818817,0.35868228628082816,-0.12365310811420605
207.20000000000223,26.788672428923242,0.3570178151505642,-0.12765644027537526
208.40000000000225,26.9042707627414,0.36294216374543453,-0.1284400961140646
209.60000000000227,27.018344600132462,0.3642587365008305,-0.13096990388930818
210.80000000000229,27.133301121236176,0.3670327146607582,-0.13359164123441536
212.0000000000023,27.247458525416608,0.3682944215997011,-0.13353683615758838
213.20000000000232,27.362377498869158,0.3702185608711288,-0.13628620701524774
214.40000000000234,27.47683484876086,0.37155037024276016,-0.13898012107456426
215.60000000000235,27.59162506479732,0.3708797285745329,-0.1418514154434387
216.80000000000237,27.70604880758907,0.3708946789197404,-0.1454313262705802
218.0000000000024,27.82029039084773,0.36899351814601816,-0.14709006313611095
219.2000000000024,27.935427447473536,0.3706883449356188,-0.14950988409154986
220.40000000000242,28.05028665472327,0.3710802550500427,-0.15105501151913536
221.60000000000244,28.164831929022622,0.37080287297106784,-0.15644718239969402
222.80000000000246,28.278716108585737,0.369704428949663,-0.1564127360867391
224.00000000000247,28.39387585037503,0.3708455782223019,-0.1591102706422265
225.2000000000025,28.509642326720932,0.37198161518934103,-0.16286290552013094
226.4000000000025,28.62350977559213,0.3692186377448322,-0.16659509829187424
227.60000000000252,28.738027881952185,0.37278175030598404,-0.1692589411541432
228.80000000000254,28.8525978177364,0.37184804631385615,-0.17070069132674837
230.00000000000256,28.968541979861875,0.3728191338314997,-0.17334281117657513
231.20000000000258,29.082350054054405,0.3723398499611874,-0.17857041730043788
232.4000000000026,29.19766001476315,0.3736261188843766,-0.18139340690245032
233.6000000000026,29.31268545322419,0.3741347296752665,-0.18611003269418758
234.80000000000263,29.42657892871322,0.3752678540054174,-0.1900163395611396
236.00000000000264,29.542214694210273,0.37540166732900765,-0.19117155519458118
237.20000000000266,29.65593074343308,0.3751809340326979,-0.1956663213361507
238.40000000000268,29.77106789472997,0.37631657819071007,-0.19797108511785444
239.6000000000027,29.884804929759646,0.378477220974207,-0.20211119805914102
240.8000000000027,29.999590532681953,0.38009394370087324,-0.20654495333899936
242.00000000000273,30.114324383751597,0.3839131503231582,-0.2122495230195307
243.20000000000275,30.228515836585782,0.384321734054572,-0.21810628758154715
244.40000000000276,30.342770973108387,0.38945656507600845,-0.22441836006828497
245.60000000000278,30.457086877742928,0.3895227699675916,-0.22843901246927212
246.8000000000028,30.572901271305017,0.3926460121794189,-0.23204153628384372
248.0000000000028,30.686774950665352,0.3957696489151646,-0.2359620167536023
249.20000000000283,30.800703524968448,0.3984599627118605,-0.2418875463010166
250.40000000000285,30.916475564935592,0.4009799899949814,-0.2509803878812997
251.60000000000286,31.030791440758986,0.4082780940997792,-0.25922826205286986
252.80000000000288,31.144168976793193,0.4099418578195866,-0.265718567055794
254.0000000000029,31.25916110899098,0.4058574800149479,-0.2741471844700136
255.20000000000292,31.37356960773437,0.4014543006460033,-0.28062062011292355
256.40000000000293,31.487979872004978,0.39263472836094426,-0.2868296454176984
257.600000000003,31.602677889983934,0.3873117410027915,-0.2944359817094573
258.80000000000297,31.717386652774792,0.38688313187671275,-0.3049172566060445
260.00000000000296,31.832348449842613,0.3828966170084209,-0.31281715779626174
261.200000000003,31.94624229228556,0.3823886611030848,-0.32453955768674314
262.40000000000305,32.06068853173028,0.3814894620249744,-0.3326109021231072
263.60000000000304,32.175262118862776,0.3817329846145078,-0.34344922415942936
264.800000000003,32.290000970513226,0.38116682821693876,-0.3551702018828502
266.00000000000307,32.4041989233176,0.3815128213860975,-0.3645988663313293
267.2000000000031,32.51917335400501,0.3794575471429204,-0.37646420385822355
268.4000000000031,32.63501465040372,0.3798764569748115,-0.3881427212562545
269.6000000000031,32.74948029328626,0.37831802378745555,-0.40303211964136754
270.80000000000314,32.86437857139183,0.3782225048102718,-0.41736689087726786
272.0000000000032,32.97858752687674,0.37654959971480867,-0.43207634766308844
273.2000000000032,33.0932096565512,0.3793415553624227,-0.44500997443511947
274.40000000000316,33.208331007746395,0.37432757006382605,-0.460365140804905
275.6000000000032,33.32238826789243,0.3734476764059519,-0.4752643854432299
276.80000000000325,33.437441152840805,0.37159996202418666,-0.4900493657754126
278.00000000000324,33.55180193600776,0.3695610697612937,-0.5049832671047567
279.20000000000323,33.666338608434046,0.36990522189763986,-0.5222544307327124
280.4000000000033,33.78158701492816,0.36965868965885307,-0.53940347281734
281.6000000000033,33.89611667915565,0.36735260182737683,-0.5583196306020164
282.8000000000033,34.01073736541343,0.36673824251015846,-0.5754830699591791
284.0000000000033,34.125576420695104,0.36396828997717023,-0.596151508681503
285.20000000000334,34.239999071722636,0.36437598251967984,-0.6146793041247656
286.4000000000034,34.35352331511734,0.36515757807901034,-0.6350618856012775
287.6000000000034,34.47061432761745,0.36428877336158844,-0.6541734183303562
288.80000000000337,34.58525171908957,0.36134934827822063,-0.6756139434862298
290.0000000000034,34.69710927420137,0.36028745102436643,-0.6961003193124413
291.20000000000346,34.81513926819204,0.3612922800307218,-0.7180933919968666
292.40000000000344,34.930781943045226,0.3595713042674056,-0.7415970877956961
293.60000000000343,35.046260061745784,0.3608271807810498,-0.7634386062419516
294.8000000000035,35.16151364438006,0.364793757614048,-0.7866309550259829
296.0000000000035,35.276864746608354,0.3608354898571714,-0.8108680538048874
297.2000000000035,35.391449848418986,0.3599351916487914,-0.8343382707937241
298.4000000000035,35.506324128899074,0.3613929376354274,-0.8593038973777953
299.60000000000355,35.622441364339196,0.35814317700597026,-0.8838643065506906
300.8000000000036,35.73767686359626,0.36332136661125786,-0.9073454368227987
302.0000000000036,35.85331892257422,0.36474403507185993,-0.9319777799258016
303.20000000000357,35.96791398668342,0.3613712934204868,-0.9574019592024761
304.4000000000036,36.08409214882161,0.36526907213458576,-0.9807038414777884
305.60000000000366,36.19872560404379,0.36500117046623803,-1.007470346514514
306.80000000000365,36.31446649348208,0.36751630330871676,-1.0340069716699078
308.00000000000364,36.430627358497915,0.36958338926937206,-1.0601474302965577
309.2000000000037,36.545757606501525,0.3709342589163768,-1.0834346388909353
310.40000000000373,36.661656781981165,0.3727958480547303,-1.1090745432938567
311.6000000000037,36.77603000546241,0.37169835606355467,-1.1328959281612008
312.8000000000037,36.89107951617513,0.3743856506701623,-1.1582442377445203
314.00000000000375,37.005858021999096,0.3756117911567149,-1.1840128314413945
315.2000000000038,37.122975681441446,0.3778501731270755,-1.2099960204858262
316.4000000000038,37.237904539671604,0.38236580719946794,-1.235812586110677
317.6000000000038,37.353148646819676,0.38297446639117416,-1.2603789147793245
318.8000000000038,37.46883950051098,0.38982872604227004,-1.2858353806170824
320.00000000000387,37.585060887085234,0.3927260975025625,-1.3118054337063492
321.20000000000385,37.700790163766996,0.3940516633331005,-1.3355152009333175
322.40000000000384,37.81722975942981,0.39952238385662664,-1.3621378652498484
323.6000000000039,37.93210539601126,0.40146639302729914,-1.3873586297740954
324.80000000000393,38.04703629838601,0.40685765023640574,-1.4118746799637187
326.0000000000039,38.1625372181167,0.4109419299003825,-1.437632858058553
327.2000000000039,38.278933953046256,0.4152844948054123,-1.465280399033368
328.40000000000396,38.393796242360445,0.42415874287296684,-1.491582590151887
329.600000000004,38.50949348655721,0.4309793428689519,-1.515645393002778
330.800000000004,38.62523630824354,0.43836258399949135,-1.541437463459392
332.000000000004,38.740279415892424,0.4459262173805679,-1.5694884645252443
333.200000000004,38.85667066624866,0.45306144173842366,-1.598820702620464
334.40000000000407,38.972011774499485,0.46019245338548265,-1.6278275272704517
335.60000000000406,39.0881022042436,0.469559072297306,-1.6566511395297039
336.80000000000405,39.20400440712578,0.4803375123438177,-1.6874504448873489
338.0000000000041,39.320276068605565,0.49073341740306,-1.7167868320843427
339.20000000000414,39.43558940854555,0.5021557992439454,-1.7491045996731032
340.4000000000041,39.55209568217726,0.5151878354896797,-1.7824884739456888
341.6000000000041,39.66896450322514,0.5263389341084628,-1.8163077658013136
342.80000000000416,39.78500967598233,0.5392698122427606,-1.852639113634778
344.0000000000042,39.90129664905838,0.5550146247553902,-1.890899490701679
345.2000000000042,40.01730950791346,0.5742256344168989,-1.9303250152682243
346.4000000000042,40.13344043863797,0.5891827194671073,-1.970651585232043
347.60000000000423,40.250529626300136,0.6093277828122134,-2.0125011704765763
348.8000000000043,40.36569602442047,0.6275917119974692,-2.057600777171444
350.00000000000426,40.48243877895872,0.647810467007867,-2.1047118045212567
351.20000000000425,40.599813362739994,0.6661241987014637,-2.156775066845271
352.4000000000043,40.716536597829496,0.680183675222803,-2.2101691118899316
353.60000000000434,40.83223766689177,0.694000306209675,-2.265649144641727
354.80000000000433,40.94734345681742,0.6945145087132547,-2.3256089245379648
356.0000000000043,41.06500556234962,0.6845695522492621,-2.3821180467732734
357.20000000000437,41.18138422824834,0.6588385439012132,-2.439651292005195
358.4000000000044,41.297478252035155,0.6156924655300302,-2.496505802042493
359.6000000000044,41.41322139042756,0.5578653232532418,-2.5476047862402225
360.8000000000044,41.52856195897239,0.4942030578517723,-2.5941138886407478
362.00000000000443,41.64471576216706,0.42722504086101964,-2.635385285040554
363.2000000000045,41.76008987151974,0.3686252156691674,-2.6675660866135087
364.40000000000447,41.875387225526936,0.3137819812469551,-2.696844277071251
365.60000000000446,41.99125796713429,0.2640048250953714,-2.7220730169371334
366.8000000000045,42.107462288995244,0.228720294979874,-2.73982043914391
368.00000000000455,42.22287033546873,0.1959181607976243,-2.7548444778433474
369.20000000000454,42.33825039355975,0.17370696504623662,-2.766363666408659
370.4000000000045,42.453856610149934,0.15365562593420878,-2.777200250676445
371.60000000000457,42.57019506421061,0.1370375082043948,-2.784947748272276
372.8000000000046,42.68683722746507,0.12466569102441716,-2.7942684695758078
374.0000000000046,42.801942452483964,0.11694892793602446,-2.8005441779114446
375.2000000000046,42.91763657278923,0.10633119093456589,-2.807972561307117
376.40000000000464,43.033823821986765,0.09942088689471756,-2.813189957901436
377.6000000000047,43.15160943452821,0.0946615969298375,-2.8207988478950456
378.8000000000047,43.26769269859689,0.08823359065822756,-2.826413033179878
380.00000000000466,43.38320656232704,0.08572449464298881,-2.8306453219870376
381.2000000000047,43.499998990041384,0.08054085340738526,-2.834840098668457
382.40000000000475,43.61627968109218,0.0768525119595832,-2.837864569119013
383.60000000000474,43.733642022919824,0.07227676185205456,-2.843314500130878
384.80000000000473,43.85059201211221,0.06871375527102142,-2.846292726622167
386.0000000000048,43.96815592567064,0.06602603359920245,-2.8503031756624964
387.2000000000048,44.08532087626476,0.05999748396353466,-2.8568389441829463
388.4000000000048,44.20163974515871,0.059350186578039754,-2.8617906015481727
389.6000000000048,44.31933438466762,0.05586838973181074,-2.8671697685270163
390.80000000000484,44.43614322365132,0.0523407123914339,-2.867242551256118
392.0000000000049,44.55385466353172,0.05033201492529238,-2.873218416136675
393.2000000000049,44.671039857551946,0.05161764669035884,-2.8774806981786174
394.40000000000487,44.787728863266395,0.048406032372352026,-2.8814660613610936
395.6000000000049,44.903547133966484,0.044699118494517465,-2.8841937077087083
396.80000000000496,45.021349435766396,0.043017428971193705,-2.8868317576502145
398.00000000000495,45.137229478327185,0.041636853871002466,-2.891617846781334
399.20000000000493,45.25417027574768,0.039318293858485176,-2.8965713745122916
400.400000000005,45.371393178885775,0.039829919802390035,-2.9003288525211612
401.600000000005,45.487950619468954,0.04047500652239516,-2.9026576599358296
402.800000000005,45.60354635117833,0.037998502853086924,-2.9071590192477177
404.000000000005,45.72081419871664,0.03529377777342052,-2.910351821938861
405.20000000000505,45.83743589331327,0.03344142675479844,-2.9129644450433743
406.4000000000051,45.954884239695915,0.03169621305884707,-2.918764989889267
407.6000000000051,46.0708696774446,0.031866471208524316,-2.9221275948433023
408.80000000000507,46.18759343042399,0.026027766947784248,-2.924353409856579
410.0000000000051,46.30529444134313,0.027258760544559446,-2.926963489828637
411.20000000000516,46.42251431615131,0.027986659391423474,-2.930855772059389
412.40000000000515,46.538834947159074,0.025902373349293906,-2.9350994325413398
413.60000000000514,46.657472880011795,0.022341266059763776,-2.9406628489244433
414.8000000000052,46.77369162100638,0.023321251885234207,-2.9428405051216027
416.00000000000523,46.89185175948619,0.022281444239829862,-2.9467793429815408
417.2000000000052,47.00905518862091,0.02236382654559721,-2.950350052248494
418.4000000000052,47.12658379506528,0.02302285849034008,-2.9523189235563274
419.60000000000525,47.243135430059034,0.020808508447130558,-2.956287570975598
420.8000000000053,47.35945675903167,0.020795271253420733,-2.9606507996595472
422.0000000000053,47.47785885454598,0.023722182830846983,-2.9619711234145205
423.2000000000053,47.59217681924856,0.02527264357008885,-2.964808964343111
424.4000000000053,47.708333566011774,0.02520523515205636,-2.9678846161610952
425.60000000000537,47.82920679202782,0.028337886119518596,-2.972262511625429
426.80000000000535,47.945509752795495,0.027080552772986544,-2.9748002924628567
428.00000000000534,48.06274297684233,0.02880307782851016,-2.9777629336468827
429.2000000000054,48.18018111118424,0.02904175683521376,-2.982476038847542
430.40000000000543,48.29747163809732,0.02735087314499096,-2.9836859300538245
431.6000000000054,48.4157621123135,0.029508436486817058,-2.9888404208131902
432.8000000000054,48.53385899086087,0.028998890180891523,-2.990370297132153
434.00000000000546,48.65093263619407,0.028653557269467056,-2.9924261962194887
435.2000000000055,48.767592602421665,0.03208559845560127,-2.994319691723903
436.4000000000055,48.885769596111,0.03516950190495077,-2.9969334418430247
437.6000000000055,49.00266050661873,0.03640173152968651,-3.0020227803049675
438.8000000000055,49.12047937012158,0.03837546668916386,-3.006832983605729
440.00000000000557,49.238595184069894,0.040375919240525304,-3.008128163665228
441.20000000000556,49.35611207239144,0.039371020682827385,-3.010769515121061
442.40000000000555,49.47506496618045,0.0378818824784109,-3.013505544375758
443.6000000000056,49.59240283220633,0.042922378484310464,-3.014809417327605
444.80000000000564,49.710197383516544,0.0446181402932343,-3.0154514099224166
446.0000000000056,49.82803611008668,0.04581959442960887,-3.0178093706507187
447.2000000000056,49.94720653988195,0.04540591973919328,-3.022517773455932
448.40000000000566,50.064325986009194,0.050360102857579025,-3.0257803919970794
449.6000000000057,50.181589816979454,0.050328276316699116,-3.027101277891008
450.8000000000057,50.29938096751849,0.05319020777064709,-3.028439723140188
452.0000000000057,50.41890875703084,0.05156333204360952,-3.032066970221289
453.20000000000573,50.537359312319495,0.05264761631610382,-3.0338199409402002
454.4000000000058,50.6554281928465,0.05506907839616937,-3.0375562134257823
455.60000000000576,50.77392239133081,0.053855988278281974,-3.0391931630495748
456.80000000000575,50.89166216217331,0.058463171100059275,-3.0403997745702913
458.0000000000058,51.010102265139054,0.05864265657165035,-3.041826451214427
459.20000000000584,51.12857739394484,0.06149162836282274,-3.044459596208527
460.40000000000583,51.246686670675196,0.05986534734890503,-3.0447485518802964
461.6000000000058,51.36529108740361,0.06282196363723491,-3.0475253197883347
462.80000000000587,51.48423402944695,0.061404642383988906,-3.04956796179592
464.0000000000059,51.602073307419495,0.06627926531340989,-3.050819889318209
465.2000000000059,51.72114725912563,0.06657563238584108,-3.0521365214107368
466.4000000000059,51.836122190414976,0.06666531101991702,-3.0547652829879732
467.60000000000593,51.958102378176186,0.06798559141262328,-3.0566779940189424
468.800000000006,52.07507751108188,0.0693800004019568,-3.0594062394954324
470.00000000000597,52.1929130757777,0.06889865148622343,-3.0585824909617507
471.20000000000596,52.31236426923953,0.07127230655525485,-3.0614629769531625
472.400000000006,52.43060921103859,0.07470550820367461,-3.0635339472051784
473.60000000000605,52.54816465767096,0.07344501649090718,-3.0643709358208966
474.80000000000604,52.66705464049968,0.07458163154731934,-3.0654012530053447
476.000000000006,52.78621007798928,0.0778795154258306,-3.066810030574744
477.20000000000607,52.90256862567716,0.08487049703560168,-3.0695496230113433
478.4000000000061,53.02118545694071,0.08669555614142888,-3.0722001932549876
479.6000000000061,53.138933448319904,0.09026140183017795,-3.070879939072486
480.8000000000061,53.25493339917103,0.09111013748837737,-3.0735657903074145
482.00000000000614,53.374789936584655,0.09305859953557638,-3.0754948140289873
483.2000000000062,53.49307236964308,0.09412519467194547,-3.0763893076664637
484.4000000000062,53.610870419597134,0.09938719215461089,-3.0780144685859674
485.60000000000616,53.72860930184641,0.10323333621657416,-3.079329820290554
486.8000000000062,53.84738772095571,0.10709381033623455,-3.080638471892784
488.00000000000625,53.965008502261135,0.10684808374039045,-3.081959820256095
489.20000000000624,54.08359611402865,0.11090601106566622,-3.0833644631030004
490.40000000000623,54.201517989931794,0.10996736701440901,-3.086050026695341
491.6000000000063,54.32129773704945,0.11510895054541714,-3.0885952905421803
492.8000000000063,54.440552318199686,0.12159577255453025,-3.0898592444697845
494.0000000000063,54.558261001813285,0.12502891355436552,-3.091156090275369
495.2000000000063,54.677799971991156,0.12529468619715323,-3.0938135512246134
496.40000000000634,54.79647487258704,0.12664975581259819,-3.0947423268578698
497.6000000000064,54.914070358539895,0.130836479978077,-3.0951202282792196
498.8000000000064,55.03351552236621,0.13043217888460457,-3.096447938641032
500.00000000000637,55.15195617711978,0.1313724485365826,-3.0991602501858386
501.2000000000064,55.26852173968399,0.13124852051708036,-3.100464183574397
502.40000000000646,55.39020918009845,0.13161152219632744,-3.100829846754616
503.60000000000645,55.50862426627812,0.13262754758194772,-3.0997342843495668
504.80000000000643,55.62761944347058,0.12922800990090422,-3.102152229434689
506.0000000000065,55.74708382778942,0.12804253255811937,-3.10478809989381
507.2000000000065,55.86575494782717,0.12041997498095214,-3.1061003274240098
508.4000000000065,55.98553296212121,0.11225535173557333,-3.107362231071449
509.6000000000065,56.103928422755494,0.10765632303154382,-3.110014259835108
510.80000000000655,56.22370095883897,0.10603495297313537,-3.1087298530037524
512.0000000000066,56.34215735379203,0.1061683253055501,-3.110047474528356
513.2000000000066,56.46147011092163,0.1049105372015331,-3.111417061722041
514.4000000000066,56.58049707181389,0.10178492682275331,-3.112748952331468
515.6000000000066,56.700204482921755,0.10178593155790672,-3.1134502775456996
516.8000000000067,56.81954524799429,0.10017733571302345,-3.1130473407579213
518.0000000000066,56.93817382875625,0.09661047752631091,-3.115421426916664
519.2000000000066,57.05647439687227,0.09791667707763119,-3.11669003064981
520.4000000000067,57.17673272785594,0.09904271144147181,-3.1193751271010846
521.6000000000067,57.29559868733239,0.09771704065299869,-3.119370088771415
522.8000000000068,57.41388456300461,0.09766796909801301,-3.1206799242354677
524.0000000000067,57.53365376065721,0.0990613139549481,-3.120700540754858
525.2000000000068,57.65285437797061,0.0985494862657712,-3.120816503669496
526.4000000000068,57.77257757522287,0.10056057098125126,-3.1220032933977104
527.6000000000067,57.89117291677991,0.09939061811092964,-3.123310153772368
528.8000000000068,58.01030678966126,0.09951149896753098,-3.1246292279604875
530.0000000000068,58.12896198971553,0.10275993968026875,-3.1246002606379095
531.2000000000069,58.24771091619653,0.09933474357846794,-3.1266879951952404
532.4000000000069,58.366392734200396,0.10057741884214011,-3.125949884472191
533.6000000000068,58.48577297195519,0.09873444999515657,-3.1278277219795094
534.8000000000069,58.60550888644922,0.10089394251309669,-3.130014631087518
536.0000000000069,58.723724415661145,0.09946787728734319,-3.1299007103311007
537.2000000000069,58.843549089403794,0.10163537490433949,-3.131220146627157
538.4000000000069,58.9614702892377,0.10280289914047847,-3.1325863285669406
539.600000000007,59.079895583909575,0.09972177951487504,-3.1302300815834294
540.800000000007,59.19979350229653,0.09942459175583973,-3.132203596279109
542.000000000007,59.31898539463919,0.09802985580154955,-3.133520142105236
543.200000000007,59.438345578505846,0.09818461890069652,-3.1335121068644964
544.400000000007,59.558580591243064,0.09753490439772272,-3.13488376277002
545.6000000000071,59.67649271106217,0.09967801609755167,-3.1361329477035955
546.800000000007,59.79784219082014,0.09892316484720831,-3.1374685773197815
548.000000000007,59.91781199918429,0.09946102159945336,-3.1401003392499023
549.2000000000071,60.03690954688854,0.09915636358630475,-3.140135312465574
550.4000000000071,60.15662583985858,0.10050668784753469,-3.140100014740883
551.6000000000072,60.27728389970739,0.09972942388909178,-3.141402826584471
552.8000000000071,60.397333142242,0.09649079512412262,-3.141411100849542
554.0000000000072,60.5170522522695,0.0970713252594505,-3.1440285205225247
555.2000000000072,60.63472204150477,0.09493415791165549,-3.144027054897089
556.4000000000071,60.75570204233682,0.09805848100810233,-3.1459293590555326
557.6000000000072,60.87614011044114,0.0958607010819027,-3.1466953358740595
558.8000000000072,60.995189899061174,0.0970643392417434,-3.148006597653029
560.0000000000073,61.11413260519557,0.09636624537466154,-3.14861242767759
561.2000000000073,61.234259429643345,0.10033228094631363,-3.1501513912864905
562.4000000000073,61.3532302818384,0.09706035091752774,-3.1492102123078936
563.6000000000073,61.47303565281898,0.09852037924752954,-3.151688302955709
564.8000000000073,61.59260167420251,0.09709134906387185,-3.1531583705965733
566.0000000000073,61.71212812715229,0.09295535655498699,-3.153150169293423
567.2000000000073,61.83188575691814,0.09492015714017965,-3.154581994146586
568.4000000000074,61.951139462368225,0.09220881873443199,-3.154662824793412
569.6000000000074,62.07147448976775,0.09386612312032527,-3.1575365104582485
570.8000000000075,62.19175074418002,0.0920506269649296,-3.157539966990135
572.0000000000074,62.31128374594802,0.09270823123644756,-3.158860083782131
573.2000000000074,62.431539800157154,0.09287821790474238,-3.1575367707470523
574.4000000000075,62.551330468012615,0.09189560711463274,-3.158850438167603
575.6000000000074,62.67050995500277,0.091138315492715,-3.1611115169940263
576.8000000000075,62.790773791672656,0.09229070494653457,-3.161493583917389
578.0000000000075,62.91072442412619,0.0925771127265611,-3.1628101660922376
579.2000000000075,63.030218703337255,0.09119198407875373,-3.1628114517006636
580.4000000000076,63.15053540129105,0.08964064885842327,-3.1641198711713137
581.6000000000075,63.27079823364285,0.0911770613336208,-3.164147428542536
582.8000000000076,63.389726242080386,0.09161043287040005,-3.1641198939359536
584.0000000000076,63.51155929118644,0.09067744413468914,-3.1654444434896845
585.2000000000075,63.63066113072103,0.08972682181784808,-3.165440321004218
586.4000000000076,63.75080999449232,0.0933978608930981,-3.1667500203049066
587.6000000000076,63.87129337807092,0.09100929489395926,-3.165528380531734
588.8000000000077,63.991454973358785,0.09587194951780453,-3.16675004413099
590.0000000000077,64.11009174808989,0.09300604597934181,-3.166750044001672
591.2000000000077,64.23103559365515,0.09693628526766573,-3.1668215390820786
592.4000000000077,64.3506910534709,0.0976949755642621,-3.168390143712876
593.6000000000078,64.46979116868057,0.09729693246281657,-3.168204712245789
594.8000000000077,64.58963074467323,0.09790886643360897,-3.168400191201766
596.0000000000077,64.70949439860388,0.10114990497669529,-3.169720197239574
597.2000000000078,64.82868735997069,0.10231357185106504,-3.1697200081968786
598.4000000000078,64.94910717206903,0.10021513579582186,-3.1697088506573587
599.6000000000079,65.06839605460289,0.10254464863516222,-3.1710308747207785
600.8000000000078,65.1888961319801,0.10309902690767503,-3.171964344364102
602.0000000000078,65.30894590080472,0.10249572719758149,-3.1723499470451975
603.2000000000079,65.42944647635761,0.10262449715815447,-3.172349934253239
604.4000000000078,65.54937692821392,0.10129370240365976,-3.1736600390478227
605.6000000000079,65.66962645328675,0.10739995650554213,-3.173660043828981
606.8000000000079,65.79072805951857,0.10916263870801934,-3.174980181934744
608.000000000008,65.91121216139163,0.10649397092013735,-3.176321603395519
609.200000000008,66.03171764939812,0.11010408285366635,-3.1762972060761827
610.4000000000079,66.15170837091783,0.11058878025814134,-3.178930210486737
611.600000000008,66.2725492292322,0.11292158912028749,-3.179593122126935
612.800000000008,66.39283725954947,0.11290155664226353,-3.178934503101628
614.000000000008,66.51295472538925,0.11412106954997481,-3.1789299111750573
615.200000000008,66.63350844385994,0.1131239898055898,-3.179575092263946
616.400000000008,66.75365777775856,0.11573354719851614,-3.1818580228007987
617.6000000000081,66.8738578303827,0.11751237932337544,-3.183530078199034
618.8000000000081,66.99395595025882,0.12038238404193558,-3.1836133548618117
620.0000000000081,67.114198409374,0.11852258228576518,-3.180570907094866
621.2000000000081,67.23476342203983,0.11993999234692931,-3.180249975211032
622.4000000000082,67.35200474750454,0.12292428361591035,-3.1805515057972045
623.6000000000081,67.47458917535499,0.12094438971783839,-3.182869629521189
624.8000000000081,67.59492211937123,0.12465489515838124,-3.1853418966925187
626.0000000000082,67.71583383616121,0.12479679702767177,-3.1854896010741487
627.2000000000082,67.83518224740945,0.12644825146029937,-3.1861535095720477
628.4000000000083,67.95578709564857,0.12966963154559386,-3.186144634107838
629.6000000000082,68.0761104778729,0.12833216823268123,-3.185402147079242
630.8000000000083,68.19733513563183,0.1263705457077655,-3.186499862531025
632.0000000000083,68.31694665030355,0.13078197625121413,-3.1878102059008935
633.2000000000082,68.43787211537963,0.12959495130988485,-3.18813742234049
634.4000000000083,68.55832513456113,0.13237872057897726,-3.1894599742890324
635.6000000000083,68.67910198685937,0.13202237221788926,-3.1907799794225635
636.8000000000084,68.79860477163116,0.13291397598397925,-3.1907577364218613
638.0000000000084,68.92092423732478,0.1352421220530997,-3.189459845852516
639.2000000000083,69.04061365547368,0.13459022020662648,-3.190778151096314
640.4000000000084,69.16192605985121,0.13487903045411653,-3.1933986341083624
641.6000000000084,69.2825704551994,0.1336155851353391,-3.1933985202287847
642.8000000000084,69.40359276396838,0.13752302715575904,-3.193395835726313
644.0000000000084,69.52425487585812,0.1347753606913329,-3.1924098306706767
645.2000000000085,69.64487485604931,0.13839152583951853,-3.1924098309989994
646.4000000000085,69.7656840432011,0.13350941324193322,-3.192077776923218
647.6000000000085,69.88656743188359,0.13826088729808705,-3.1934153158328678
648.8000000000085,70.00608157610642,0.13570662128057065,-3.19560422062388
650.0000000000085,70.1269813063908,0.13787392350109928,-3.1942649573860757
651.2000000000086,70.24766560173033,0.1398177043318165,-3.195599818613364
652.4000000000085,70.36784791375618,0.13802634393821522,-3.1953624073840974
653.6000000000085,70.48856574919087,0.14061588715428175,-3.19559182955324
654.8000000000086,70.60776045549315,0.13796534210365152,-3.1942760097550362
656.0000000000086,70.7287117277004,0.1397934991891181,-3.195701873758104
657.2000000000087,70.84942122220934,0.13784203257177374,-3.1977407506908553
658.4000000000086,70.96879542399908,0.1419374842399157,-3.1984500069422817
659.6000000000087,71.08903078762785,0.14043198959522019,-3.197448956798539
660.8000000000087,71.20920013663873,0.14334765053625764,-3.2000992188723596
662.0000000000086,71.33038689738206,0.1388973904141988,-3.201419468676086
663.2000000000087,71.45049715870255,0.14339213485806046,-3.2027337188487195
664.4000000000087,71.57106389305929,0.14440238585680132,-3.201417653817579
665.6000000000088,71.69104292781797,0.14350788286551475,-3.201397148815925
666.8000000000088,71.81197728954673,0.14450277619815521,-3.2027270069180815
668.0000000000088,71.93372686379618,0.14065598216918063,-3.2017606845905315
669.2000000000088,72.05422650792383,0.14463444470721964,-3.202400171441801
670.4000000000088,72.17499151292812,0.14383726560355803,-3.2024001819994794
671.6000000000088,72.29623400664548,0.146083532875676,-3.2023947023692143
672.8000000000088,72.41950962893281,0.14516400795754492,-3.2030760446242534
674.0000000000089,72.54073948554303,0.14851881518642407,-3.205342491572907
675.2000000000089,72.66022054702574,0.15115812274318552,-3.2054178968948506
676.400000000009,72.78326165469313,0.14811870836061436,-3.205687827937843
677.6000000000089,72.90343184109874,0.14956436007991347,-3.207006699964964
678.8000000000089,73.02545777260602,0.15176183227885698,-3.204049864086987
680.000000000009,73.14668420652795,0.1491270868101986,-3.2040498168205502
681.2000000000089,73.26785350840757,0.15228424709332367,-3.2053460391897723
682.400000000009,73.38904002230394,0.1523531747813942,-3.204041281691502
683.600000000009,73.50916810036641,0.15302100060475898,-3.206679942974506
684.800000000009,73.63052678495796,0.1539852907301129,-3.2070455453971576
686.0000000000091,73.75093586067918,0.15347679466985786,-3.208980034873495
687.200000000009,73.87240390353276,0.15026201777128434,-3.2076755082244035
688.4000000000091,73.99281078833768,0.14968862709953568,-3.205030064125601
689.6000000000091,74.11372409699933,0.15203764620246352,-3.206350262024275
690.800000000009,74.23415845990189,0.14998769922604738,-3.2076601637356026
692.0000000000091,74.35488325784104,0.1578967354048657,-3.2099543963951325
693.2000000000091,74.47568721778691,0.15699953491737229,-3.2102169899421895
694.4000000000092,74.59586442553203,0.15108302106064886,-3.2075836794878865
695.6000000000092,74.71739865312124,0.15208203039573487,-3.2088589066702893
696.8000000000092,74.83761288208082,0.1580465679009846,-3.208482658367256
698.0000000000092,74.95858734965879,0.15352965510184546,-3.2098599069118485
699.2000000000093,75.07877703470362,0.15498100812610205,-3.2085498444613325
700.4000000000092,75.20069179764302,0.15573231099804796,-3.2098599003570287
701.6000000000092,75.32260470779241,0.15899289981776965,-3.2087671748250504
702.8000000000093,75.44366358215112,0.1583950956355975,-3.2087614582770074
704.0000000000093,75.5661267707085,0.15755519140582552,-3.2113756636491186
705.2000000000094,75.68797068961979,0.1556895587029119,-3.213361657796165
706.4000000000093,75.80817579667698,0.15686278469387616,-3.212003647546207
707.6000000000093,75.92857843379755,0.15748928940774332,-3.213370198733188
708.8000000000094,76.05051667128684,0.1551219635793879,-3.212050035106161
710.0000000000093,76.17141739748828,0.15794238356025336,-3.212150154290538
711.2000000000094,76.29207659497953,0.16113658509583262,-3.213608692476016
712.4000000000094,76.4141062719172,0.16222567173235825,-3.2146747352683853
713.6000000000095,76.53578721712759,0.16311637238518784,-3.214680187998802
714.8000000000095,76.65742146422546,0.16415046114963694,-3.214675349931615
716.0000000000094,76.77855346659831,0.16437055818580748,-3.2168504673778173
717.2000000000095,76.89914507831253,0.16707641352657165,-3.2146796749787203
718.4000000000095,77.02215220452307,0.1646211091203822,-3.2145777222277183
719.6000000000095,77.14399716204976,0.16716302854056275,-3.2145610205122344
720.8000000000095,77.26472113562322,0.1679592590662884,-3.215889915913416
722.0000000000095,77.38647485922756,0.1664894349945314,-3.2158836448678496
723.2000000000096,77.50819546173855,0.1697010592982049,-3.2185184009435246
724.4000000000096,77.62980845607905,0.16616653924797964,-3.218507716922252
725.6000000000096,77.75107868027486,0.16661356230397106,-3.2182002902237294
726.8000000000096,77.87306278723186,0.1670473561225494,-3.218196466998223
728.0000000000097,77.99330494081804,0.1737498673273472,-3.216880041671225
729.2000000000096,78.11600800192011,0.17056611199178184,-3.2184195206523616
730.4000000000096,78.23743124365654,0.17136010319869688,-3.217100112073859
731.6000000000097,78.35666228889438,0.16853972404934114,-3.217407635637578
732.8000000000097,78.47959617925868,0.17121050595020892,-3.2187400659539764
734.0000000000098,78.60178043264305,0.17361863159348223,-3.2187400659993077
735.2000000000097,78.72317318030706,0.17255931752682985,-3.2187475123308964
736.4000000000098,78.84327997549488,0.17336081195987418,-3.2174209710349677
737.6000000000098,78.96565094637124,0.18083559250053427,-3.2175000858113356
738.8000000000097,79.0871186080982,0.17396337806623552,-3.218710534502764
740.0000000000098,79.20961145221041,0.17691790597656842,-3.2200035588230236
741.2000000000098,79.33010819897287,0.17668415155490313,-3.220058711561567
742.4000000000099,79.45230706579649,0.17892641026290335,-3.2187400842254745
743.6000000000099,79.57316989752677,0.17989168950759726,-3.219402420403893
744.8000000000098,79.69606109321342,0.17556699026322642,-3.219729664023705
746.0000000000099,79.8177862137882,0.18040284427303832,-3.2199444253989107
747.2000000000099,79.9392287879596,0.18049702906089116,-3.2212954001308933
748.4000000000099,80.06030222448263,0.17674943041520152,-3.220382057702677
749.6000000000099,80.18230348639662,0.1843933148081187,-3.220670186691434
750.80000000001,80.30307917583,0.18113510569986246,-3.219519581623916
752.00000000001,80.42527255507531,0.17962934809330622,-3.219438290736
753.20000000001,80.54688143594268,0.17958389748922277,-3.2228197066492044
754.40000000001,80.66769848309318,0.1818459424098413,-3.2184095158423345
755.60000000001,80.78932883155282,0.17901947975468557,-3.2210644874880936
756.8000000000101,80.91134336160722,0.18098111987093324,-3.2220331056831597
758.00000000001,81.03329082714421,0.18027089536816376,-3.221689290815234
759.20000000001,81.15499875619307,0.18251473913575866,-3.2230202562178114
760.4000000000101,81.27628858329784,0.18730809038826446,-3.223020052702907
761.6000000000101,81.39962632272415,0.1840994833761216,-3.224340019700058
762.8000000000102,81.5206302487315,0.18868434800784728,-3.223018778953446
764.0000000000101,81.64284842002756,0.18968269371146973,-3.2243301585389337
765.2000000000102,81.76555064107976,0.18942946757240353,-3.225755313015731
766.4000000000102,81.88740794356642,0.18948668725515017,-3.2229097353293272
767.6000000000101,82.00911569162331,0.18626900625555676,-3.222906475716265
768.8000000000102,82.13078986287688,0.1853586484701495,-3.225575029400642
770.0000000000102,82.25182914283009,0.19489272931420043,-3.225201378743662
771.2000000000103,82.37441428687673,0.19425684978030944,-3.2252062163878517
772.4000000000103,82.49620677024912,0.1915416278682951,-3.226520715920889
773.6000000000103,82.617487673642,0.19390203868702027,-3.2261823955793263
774.8000000000103,82.73988990226687,0.19567352082640355,-3.2262004813875085
776.0000000000103,82.86146887494355,0.19592853016557799,-3.224217462982918
777.2000000000103,82.98237717313286,0.19539133865340874,-3.224556153149213
778.4000000000103,83.10420005958485,0.19650543841426993,-3.22620014376038
779.6000000000104,83.22478959487631,0.1967348941269571,-3.226860021258977
780.8000000000104,83.34663336670461,0.19818848331878902,-3.2270201098799753
782.0000000000105,83.4691144541845,0.19688006268472158,-3.227850457504572
783.2000000000104,83.59051327782292,0.19811528533147582,-3.227190049644828
784.4000000000104,83.71152193708842,0.20024741658703427,-3.2281752154771537
785.6000000000105,83.83376619072611,0.19959963644632328,-3.2285001485126354
786.8000000000104,83.95650889721104,0.20223280355231044,-3.2294896223307936
788.0000000000105,84.07773887921945,0.20014478177141992,-3.230201343927855
789.2000000000105,84.19881244817205,0.20335142689712082,-3.229165070920843
790.4000000000106,84.32134388694496,0.20584132909278852,-3.230568708680173
791.6000000000106,84.44375045327868,0.2078185400633643,-3.2294964516781905
792.8000000000105,84.56578418595083,0.2094486049241917,-3.230919981433628
794.0000000000106,84.68757856850128,0.2063947060787048,-3.2301773142825336
795.2000000000106,84.80987878890613,0.20777881037688228,-3.2293900817345738
796.4000000000106,84.93239125506442,0.21271681508892204,-3.2319657805130113
797.0000000000106,84.99325524390885,0.21558949226438573,-3.2315155326917777