File: 01_Data/Bamboo_Rug_Bamboo/STA/N2/10K_min/Bamboo_Rug_Bamboo_STA_N2_10KData_220120_R3.csv
##Temp./Â°C,Time/min,DSC/(mW/mg),Mass loss/mg
50.0,10.756996514148813,0.035577874919180186,-0.055069365412268034
51.20000000000002,11.079170000000003,0.07999817976172507,-0.054760337991794916
52.400000000000034,11.29594726689816,0.10859793284498309,-0.054117319983382206
53.60000000000005,11.485832103733733,0.12993083578555975,-0.05182705605675331
54.80000000000007,11.65146391220246,0.14699265982169596,-0.05263956092864719
56.000000000000085,11.805516110974143,0.15880102711217092,-0.055552998777501195
57.2000000000001,11.955793172816545,0.17278937656431792,-0.05568177252539952
58.40000000000012,12.096867930461608,0.18072255247760194,-0.056361608265642626
59.600000000000136,12.23664413268238,0.18820545839747993,-0.055296605254807396
60.80000000000015,12.373027221792526,0.19641482504402508,-0.056427894244419186
62.00000000000017,12.507052104114804,0.20308650601325884,-0.05689807481619891
63.20000000000019,12.640509292488215,0.20808734869135648,-0.05643302235163672
64.4000000000002,12.773074472723424,0.21356275910728773,-0.05915332874519841
65.60000000000022,12.90407539584899,0.21802827416200976,-0.05781126382695945
66.80000000000024,13.034799268646944,0.22138665612138475,-0.057746254722319534
68.00000000000026,13.164494459470307,0.22539587185864984,-0.0591204952922908
69.20000000000027,13.293378579735286,0.22746968099155962,-0.060440491447392386
70.40000000000029,13.422535539970776,0.23166699533388552,-0.060159781978526894
71.6000000000003,13.550943917444425,0.2361352691756572,-0.060386030062274276
72.80000000000032,13.677144047072211,0.2371610470321508,-0.06295256542920713
74.00000000000034,13.80458287923666,0.23817616544560838,-0.0631248197755152
75.20000000000036,13.929770986672937,0.24548592982473755,-0.06438990979298032
76.40000000000038,14.055335175877048,0.24556354680496095,-0.06439144752177173
77.60000000000039,14.180210815412808,0.2466768080786319,-0.06404899720392487
78.80000000000041,14.305157601409313,0.25036383328383083,-0.06373980515707167
80.00000000000043,14.428905853234104,0.25482033645863567,-0.06570557184938819
81.20000000000044,14.552556935554891,0.25429475533154733,-0.06701846925330601
82.40000000000046,14.674764101502278,0.2559786105640497,-0.06703052998220382
83.60000000000048,14.798253891094301,0.25803556248784604,-0.06833019466250612
84.8000000000005,14.920244544854057,0.25654204682389914,-0.06822270106836692
86.00000000000051,15.041469010972115,0.25769523008479056,-0.0690311151954659
87.20000000000053,15.161037726221153,0.25677883877760604,-0.0696647265609065
88.40000000000055,15.28400658047588,0.2559051679522962,-0.06965082227732733
89.60000000000056,15.403212797543954,0.2564210311591502,-0.07096947944431431
90.80000000000058,15.524422670712958,0.2555819613013056,-0.07032930969636064
92.0000000000006,15.644798151089908,0.25278399731485884,-0.07226571903987633
93.20000000000061,15.76507155313311,0.25537450387165544,-0.07224409084248684
94.40000000000063,15.883969694426638,0.2529218108811858,-0.07318025231278913
95.60000000000065,16.000283436019675,0.2537005368066946,-0.07360027835477556
96.80000000000067,16.121354118967325,0.25184851424431065,-0.07491979326001275
98.00000000000068,16.23935736322398,0.2500335870163641,-0.0736000410365869
99.2000000000007,16.356169603279227,0.24851298053799686,-0.07322891077999527
100.40000000000072,16.475866954415928,0.2469161167226292,-0.07359989138565348
101.60000000000073,16.593590539606108,0.24412681859744306,-0.07490703109073982
102.80000000000075,16.71114019720595,0.24620987167147673,-0.07367276304989456
104.00000000000077,16.827005803122727,0.24580323945101584,-0.07622998498962597
105.20000000000078,16.946211641357174,0.24516556321995753,-0.0762298400219108
106.4000000000008,17.062175940657745,0.24455757278345952,-0.07622991000002122
107.60000000000082,17.179271468333102,0.2430092447242494,-0.07622989647288758
108.80000000000084,17.29741964968055,0.24521202171380968,-0.07623051742258147
110.00000000000085,17.413344498982052,0.24512763810412053,-0.07754038261915852
111.20000000000087,17.53233883246245,0.24297437789224735,-0.07973441752151844
112.40000000000089,17.6476523550785,0.24202866802699102,-0.0792284955417264
113.6000000000009,17.765926318269738,0.24041267792711019,-0.07755019806623942
114.80000000000092,17.883303846364818,0.23922628092937026,-0.07755286456248589
116.00000000000094,18.000008442429685,0.23884689601297826,-0.0781351130070207
117.20000000000095,18.116272449079045,0.23801546037467336,-0.07887070254126805
118.40000000000097,18.233985114843197,0.24016531348780817,-0.0801730551368669
119.60000000000099,18.3512645010585,0.2407029969948677,-0.08116006074241078
120.800000000001,18.469067829095653,0.2418943559816443,-0.08117814374528676
122.00000000000102,18.584590287906458,0.24434768782859448,-0.08117676952351438
123.20000000000104,18.701870857366263,0.24442732257707064,-0.08080664703438112
124.40000000000106,18.819779173118242,0.24454805522235626,-0.08208335684133283
125.60000000000107,18.93423919559384,0.24725157757832253,-0.08116006586181435
126.80000000000109,19.05248639430192,0.24733509847156188,-0.08132472331753027
128.0000000000011,19.16856467257103,0.249315280303452,-0.08149976008914939
129.20000000000113,19.283120287664087,0.2503760278812296,-0.08116983455565441
130.40000000000114,19.400011761922286,0.25186503663349125,-0.08204516891619207
131.60000000000116,19.51558727538731,0.2496278969994512,-0.0818257840162726
132.80000000000118,19.632834327218074,0.25074954803480404,-0.0824800676348838
134.0000000000012,19.74846453149843,0.25178515830405857,-0.08347562861761171
135.2000000000012,19.865780008587937,0.25323658147937206,-0.08312528064035885
136.40000000000123,19.981342264511312,0.2528914772517267,-0.08378725897056638
137.60000000000124,20.097507267179775,0.25514640608564465,-0.0824898701756882
138.80000000000126,20.213958990749255,0.25588928748648476,-0.08380212532983089
140.00000000000128,20.328040212568183,0.25741151574109633,-0.08249388940891977
141.2000000000013,20.443553742494107,0.25583243395549193,-0.08511440973172091
142.4000000000013,20.559812849324242,0.2592934070049876,-0.08471137362751335
143.60000000000133,20.67554792795349,0.2601130171100166,-0.0847900979495182
144.80000000000135,20.79121847303468,0.2621641394624429,-0.08479009793850212
146.00000000000136,20.906045695796692,0.2651172398226269,-0.08512562976735794
147.20000000000138,21.021505017098512,0.26551800104345014,-0.08643009882138575
148.4000000000014,21.136075559548345,0.26678415821103274,-0.08643009375613175
149.60000000000142,21.252297455767792,0.2662605875379069,-0.0864294013037532
150.80000000000143,21.364800531924768,0.26886705892710255,-0.08512010633051403
152.00000000000145,21.480853670341492,0.2717137028412784,-0.08643977452877571
153.20000000000147,21.596924218123853,0.27193915618635833,-0.08775041702188835
154.40000000000148,21.7111426581774,0.27514226021671573,-0.08798892289623117
155.6000000000015,21.826315986173103,0.2768708711253076,-0.08924978009615048
156.80000000000152,21.940788028447557,0.2767205749611082,-0.09004975110744384
158.00000000000153,22.05580545832736,0.27692502858706747,-0.0907068155521018
159.20000000000155,22.17147648909093,0.2797068738584136,-0.09071143715756413
160.40000000000157,22.286208797153144,0.27883894720861685,-0.09071005600198712
161.6000000000016,22.401421262250874,0.2841499804520229,-0.08980389093041019
162.8000000000016,22.515953431361858,0.2833131678486788,-0.09202118256097513
164.00000000000162,22.63172172420867,0.2817454889150833,-0.09234950399965047
165.20000000000164,22.74664669319988,0.2857788557428037,-0.09334984650390421
166.40000000000165,22.862247356374766,0.28490319537581665,-0.09203104258985562
167.60000000000167,22.977778256120175,0.2885367474379621,-0.0933398732988735
168.8000000000017,23.093846012202288,0.29107964039216017,-0.09463849732937124
170.0000000000017,23.206117600744893,0.29123310989162915,-0.094659824276488
171.20000000000172,23.321995187309657,0.2922645203085296,-0.09596997840437504
172.40000000000174,23.4372688081606,0.2927616814522028,-0.0959390903676689
173.60000000000176,23.5515351266997,0.2954143954666627,-0.09629997323732242
174.80000000000177,23.66704909294179,0.29350356815415324,-0.09859943421531847
176.0000000000018,23.782672219118833,0.2968048491744188,-0.0999195884081141
177.2000000000018,23.897868069017857,0.29876926738957965,-0.09992003999995402
178.40000000000182,24.011922034111812,0.2986585223628398,-0.09992109817370265
179.60000000000184,24.12747033306957,0.30089853013498835,-0.1025269983461814
180.80000000000186,24.242064954449706,0.30197922997954807,-0.10123305647438396
182.00000000000188,24.357355887043884,0.30386229652527497,-0.10222017988832688
183.2000000000019,24.472079914106565,0.30686971704771604,-0.10355687529458635
184.4000000000019,24.586436386768852,0.3081319102111,-0.10638870868692774
185.60000000000193,24.701441763602286,0.31113703720049174,-0.10782020877889842
186.80000000000194,24.816723426700165,0.3129720785944013,-0.1078232350952435
188.00000000000196,24.93163867526727,0.3137283661795072,-0.10848170485212805
189.20000000000198,25.046118114493957,0.3156527985382471,-0.10982063850863666
190.400000000002,25.160641631999287,0.3163041946623008,-0.1112180870635684
191.600000000002,25.274708541681033,0.3195412932838093,-0.11245939929293636
192.80000000000203,25.389784077127686,0.3216771149286255,-0.11407408560398347
194.00000000000205,25.503889218861264,0.32448175432788373,-0.11571270043193493
195.20000000000206,25.61908125471418,0.32506889331516076,-0.1144001557317007
196.40000000000208,25.733062959244254,0.32735505960423694,-0.11539997618512787
197.6000000000021,25.84812364600604,0.3300197897196394,-0.11771333586304555
198.80000000000211,25.961901834848696,0.33056201265195484,-0.11967146749305124
200.00000000000213,26.07669588788154,0.3330843299009107,-0.12156091635043165
201.20000000000215,26.190653240820343,0.33760859934042203,-0.12358688768743953
202.40000000000217,26.305040828490192,0.3369551900571053,-0.12220158346741083
203.60000000000218,26.418874503497168,0.34011691297581714,-0.12495662278487174
204.8000000000022,26.534725454739203,0.34353693991262424,-0.12887420164261076
206.00000000000222,26.648445707790923,0.3465495822764918,-0.13019939853539242
207.20000000000223,26.76351549836874,0.34809011999219364,-0.13028066113402526
208.40000000000225,26.87718407778235,0.3479346798878068,-0.13283280080315452
209.60000000000227,26.992074697761606,0.34924006489182435,-0.13547003524133405
210.80000000000229,27.107591660261328,0.3511250860792223,-0.13676701621700582
212.0000000000023,27.222252881687876,0.3536767792586497,-0.13941480772812698
213.20000000000232,27.336145537402203,0.35737612182867484,-0.14073433158710902
214.40000000000234,27.45050292226512,0.3591488694579429,-0.1433503023232774
215.60000000000235,27.565174416054415,0.3613296775105709,-0.1446519912542068
216.80000000000237,27.680157829154556,0.3624352688819776,-0.14861149120695583
218.0000000000024,27.793950721119046,0.36151695765293523,-0.1501814823609382
219.2000000000024,27.90860075908057,0.36028058231385846,-0.1538891225849981
220.40000000000242,28.02222967866493,0.3588032676634896,-0.15651821050508197
221.60000000000244,28.136848200901618,0.35692176538753073,-0.15785355989803973
222.80000000000246,28.25216893149197,0.357141572230547,-0.16190597968212828
224.00000000000247,28.36662296433834,0.35611509527818697,-0.16583677934477725
225.2000000000025,28.481319412028057,0.3571252301547546,-0.17020741661334515
226.4000000000025,28.594189161168373,0.3576256229872339,-0.17141118689595203
227.60000000000252,28.70951582076645,0.35683846990137635,-0.17549443757556382
228.80000000000254,28.82374712794551,0.35695429304763815,-0.17807914369255018
230.00000000000256,28.937869522796255,0.3565941993550465,-0.17945831851595528
231.20000000000258,29.052326958783812,0.356689057345002,-0.1833729412306977
232.4000000000026,29.166237094974772,0.3563909350667934,-0.18682051419976586
233.6000000000026,29.281002172560548,0.3590312475642783,-0.19201195211463506
234.80000000000263,29.394162762429826,0.35622256116426,-0.19636538101855416
236.00000000000264,29.50854892907702,0.3577637029894037,-0.20127059100913858
237.20000000000266,29.622416257291256,0.36009280132443794,-0.20392516773861802
238.40000000000268,29.73623233426308,0.35639701331461565,-0.20848175989631423
239.6000000000027,29.851858807430457,0.3588272071481374,-0.21409950949686696
240.8000000000027,29.96539956758619,0.3588716528790986,-0.21947084006341155
242.00000000000273,30.080494965042735,0.35829708848021735,-0.22083519636457316
243.20000000000275,30.194466503331785,0.36152340151307466,-0.22546293059953326
244.40000000000276,30.30907243213489,0.3611575418080232,-0.22967199994506204
245.60000000000278,30.422909672816864,0.36584575989423335,-0.23417345966684033
246.8000000000028,30.537700635789253,0.3704878834773385,-0.2412807846255629
248.0000000000028,30.65122193731617,0.3748521781986222,-0.25787330865513924
249.20000000000283,30.765207532145315,0.37784963541911487,-0.25786743839677007
250.40000000000285,30.880446356202107,0.37937008183130944,-0.25920016730844875
251.60000000000286,30.994361697424363,0.38355616290377276,-0.26468478841726784
252.80000000000288,31.109170000000248,0.3836813099279596,-0.27092994763132916
254.0000000000029,31.222999210726574,0.3790686231840706,-0.2746099323011837
255.20000000000292,31.337389399037495,0.3715396359468414,-0.28397185866656827
256.40000000000293,31.452434631003403,0.36448699628950776,-0.29447176746425097
257.600000000003,31.565521307401163,0.3605796579677913,-0.3031817035276827
258.80000000000297,31.68135722036525,0.3593519458768898,-0.3127853220627328
260.00000000000296,31.79519658402486,0.35486137106865756,-0.3210756387097029
261.200000000003,31.907973697728988,0.35208258844538565,-0.3305850892759845
262.40000000000305,32.02242300793652,0.3552840924793149,-0.3424134852873517
263.60000000000304,32.13685324051016,0.35251435332944087,-0.35347883367068667
264.800000000003,32.24973069878838,0.3518173070817815,-0.362586646882356
266.00000000000307,32.363790936927934,0.34972366027313506,-0.36874585708131
267.2000000000031,32.477592779009925,0.3494097866610415,-0.3792025436931836
268.4000000000031,32.59234971430405,0.34605233496601806,-0.3892217913397418
269.6000000000031,32.70615608003986,0.3450185275059139,-0.3988213787971717
270.80000000000314,32.82120888977761,0.34350643519626334,-0.41835213253596715
272.0000000000032,32.93610112162417,0.3385492843038432,-0.43471355327381644
273.2000000000032,33.051347585337936,0.33656246313952104,-0.4496471306564884
274.40000000000316,33.166420608717694,0.33554836608452515,-0.4654962214700382
275.6000000000032,33.28181955456256,0.33242995227986827,-0.48097938450746236
276.80000000000325,33.39790838508088,0.33116370637723036,-0.49689443109973297
278.00000000000324,33.51355657938407,0.3279247948624699,-0.5144119213417087
279.20000000000323,33.63016083405892,0.32613180049502005,-0.5297346773392704
280.4000000000033,33.74400111967766,0.3223534102975391,-0.5489299197910493
281.6000000000033,33.86105529011935,0.32041645662231216,-0.56851579655447
282.8000000000033,33.97804420200346,0.31886315976099855,-0.5862878530329696
284.0000000000033,34.093798241442606,0.318799120555637,-0.6064157244470563
285.20000000000334,34.20935558250457,0.315906359935745,-0.6253475653623957
286.4000000000034,34.32516512157071,0.3155143630877089,-0.6450049178795365
287.6000000000034,34.44139803925701,0.315678228494811,-0.6678150731902699
288.80000000000337,34.55700271454038,0.3157476389036638,-0.6884900308760464
290.0000000000034,34.67217244386523,0.31685954908896974,-0.70833408680681
291.20000000000346,34.78743159164896,0.3154084391351808,-0.7316082534202644
292.40000000000344,34.90368112758672,0.3142174891703023,-0.7525957418769482
293.60000000000343,35.018338072428065,0.3153403623989721,-0.776197914041115
294.8000000000035,35.13326727827451,0.31581284787664526,-0.7988299205522966
296.0000000000035,35.24750812179752,0.31519177277225213,-0.8217905468379376
297.2000000000035,35.36267730486603,0.31674234890083935,-0.8466189552488412
298.4000000000035,35.477884198874946,0.3164353679291634,-0.8689545502861948
299.60000000000355,35.59242169173226,0.319299167482598,-0.8945114586237217
300.8000000000036,35.70736886532655,0.3154622031501543,-0.9178115573512158
302.0000000000036,35.8230353952835,0.31818923395396215,-0.9427669411227555
303.20000000000357,35.93839204205092,0.31827091912604044,-0.9675754430008765
304.4000000000036,36.05313609435568,0.32038791336396477,-0.9900924573237138
305.60000000000366,36.16864664476888,0.32090276973455667,-1.0175555343502003
306.80000000000365,36.283471262058505,0.32138887660546495,-1.0430732575281039
308.00000000000364,36.39978743750593,0.3236506342289802,-1.0701397461902773
309.2000000000037,36.51514982692491,0.326159300018104,-1.0950765500914827
310.40000000000373,36.6302682807491,0.32578674278145003,-1.1180931083242913
311.6000000000037,36.74558076499006,0.32684339958289393,-1.1447326973427114
312.8000000000037,36.86147528999085,0.33089642598988844,-1.1688742386379092
314.00000000000375,36.97658016550038,0.33178187033560813,-1.1938793840427069
315.2000000000038,37.0919431299079,0.3305585524556486,-1.2192168021896044
316.4000000000038,37.208169420495025,0.33295288967381304,-1.244432513827208
317.6000000000038,37.32366576936136,0.3373932493394252,-1.2674861939241269
318.8000000000038,37.43979593135008,0.3423677201066824,-1.291276804147226
320.00000000000387,37.554795661654474,0.34415003844156694,-1.3161490350495852
321.20000000000385,37.670189616164926,0.3464925104068405,-1.3431514388962826
322.40000000000384,37.785355276809234,0.3491588160394218,-1.3687318662253238
323.6000000000039,37.90430337057513,0.3553133421654957,-1.395146130536709
324.80000000000393,38.018991432882004,0.3573050290395634,-1.4208289380421637
326.0000000000039,38.134692031266624,0.3652922891840449,-1.44622538847138
327.2000000000039,38.25129072361863,0.3711284028296603,-1.471221821751767
328.40000000000396,38.36603290039202,0.37889339822893875,-1.4957290406611485
329.600000000004,38.481360706450225,0.38553682536438194,-1.5218273606614936
330.800000000004,38.59778473489737,0.39152980434119333,-1.551120017637177
332.000000000004,38.71284961522236,0.4011943290314376,-1.5797210035202816
333.200000000004,38.828473475423394,0.4080600320382437,-1.6049690049844556
334.40000000000407,38.94420118703403,0.4171274844352847,-1.6350988445989274
335.60000000000406,39.05735748940075,0.423410910190532,-1.6629145000397094
336.80000000000405,39.17472471820758,0.43437008465285903,-1.6931351574846363
338.0000000000041,39.29163993290894,0.4440387675526172,-1.722580662626402
339.20000000000414,39.40813527147173,0.4567709523894446,-1.7544610682251598
340.4000000000041,39.52392500057439,0.4685656469502746,-1.7908931976717293
341.6000000000041,39.63986734225625,0.48037558103091754,-1.825262783625638
342.80000000000416,39.755619973906164,0.49323339949871514,-1.8603340321360538
344.0000000000042,39.87266453977414,0.5064826887651479,-1.8970129147033723
345.2000000000042,39.9882720419959,0.5220259745356415,-1.936854149193683
346.4000000000042,40.104929029517145,0.5396858355466603,-1.9782848310018655
347.60000000000423,40.221313317135404,0.5550606533160198,-2.021598867975705
348.8000000000043,40.338182378689126,0.5730844711369858,-2.067227241526661
350.00000000000426,40.45411421791561,0.5925869827461456,-2.115020806597853
351.20000000000425,40.57042723395947,0.6061191613336154,-2.1657421201507256
352.4000000000043,40.68758631199188,0.6214036754925932,-2.2197543866579528
353.60000000000434,40.803627126569616,0.6292035074484416,-2.2764672884520887
354.80000000000433,40.91994444132505,0.63016089847914,-2.33299245062639
356.0000000000043,41.03594539536351,0.617609439489099,-2.391828031790545
357.20000000000437,41.15159554733084,0.5923912024383925,-2.4515676598834295
358.4000000000044,41.26851257279607,0.5508527487467123,-2.5088631983241942
359.6000000000044,41.38357201558201,0.49766417929817347,-2.559330894652664
360.8000000000044,41.4990758226477,0.4393351521582955,-2.6048864709404485
362.00000000000443,41.61512428904832,0.37899544161419924,-2.6449366660488556
363.2000000000045,41.73052896697203,0.31944477254371956,-2.6799046866738268
364.40000000000447,41.84576346639959,0.26788232548865387,-2.709826946509289
365.60000000000446,41.961328929250875,0.22197298548194191,-2.733604264135647
366.8000000000045,42.07729257597076,0.185773087747256,-2.749418913884739
368.00000000000455,42.193038224390534,0.1562747012020006,-2.7660491294616802
369.20000000000454,42.309358787617185,0.1344185005457351,-2.7797883764566347
370.4000000000045,42.42489675275877,0.11697384779298525,-2.791316246064458
371.60000000000457,42.541315051181,0.10094335094216303,-2.8014468024998864
372.8000000000046,42.657728611928,0.08869628980497624,-2.81013481556161
374.0000000000046,42.77375472445655,0.08101188265359327,-2.816850556355111
375.2000000000046,42.89140504061082,0.07025454744837742,-2.822837612884265
376.40000000000464,43.00420145421965,0.0643022803112547,-2.827434625293005
377.6000000000047,43.122971614289135,0.058185204507693045,-2.83408582593001
378.8000000000047,43.23962428189094,0.05342996913404441,-2.839812380380102
380.00000000000466,43.357385341469,0.04683273443817221,-2.8447021319494374
381.2000000000047,43.47258060006185,0.04420215672621622,-2.850068251643952
382.40000000000475,43.58857070363085,0.04044324510070957,-2.853450111041305
383.60000000000474,43.70499075950297,0.03404985113612771,-2.8585554548690677
384.80000000000473,43.82240613685582,0.03199143746320332,-2.861989586509265
386.0000000000048,43.93871032722309,0.029966361072938597,-2.8672585235832835
387.2000000000048,44.05653008353784,0.02405564160365342,-2.8707542856589225
388.4000000000048,44.17224089959077,0.022059103242527578,-2.872910799218051
389.6000000000048,44.28936609860471,0.016699327523139962,-2.876962829789999
390.80000000000484,44.406909944818736,0.012794552334882914,-2.8830550894804867
392.0000000000049,44.523240783870314,0.01217832502337629,-2.8884720549205274
393.2000000000049,44.64094180268728,0.008467995849102794,-2.892442426650828
394.40000000000487,44.757537778105096,0.005014613422019865,-2.897132932592739
395.6000000000049,44.87474620713465,0.0028538122651611264,-2.8997002031583907
396.80000000000496,44.991042877123704,0.00044140249327234704,-2.90302435818632
398.00000000000495,45.10795533755923,-0.002974775110472616,-2.9064823738474956
399.20000000000493,45.22462482658457,-0.006876167292834856,-2.9115820966099353
400.400000000005,45.34193498966985,-0.009572280488638119,-2.9132374402253136
401.600000000005,45.459463523773984,-0.01127511555459526,-2.917340950028135
402.800000000005,45.575852206161215,-0.013598721636726041,-2.918578897597608
404.000000000005,45.692870392529045,-0.017495772180168734,-2.9216004701049556
405.20000000000505,45.810333346172584,-0.015942901732381498,-2.928102826205605
406.4000000000051,45.92785494709548,-0.02117957107263485,-2.9309217510748025
407.6000000000051,46.0440332432024,-0.020298605227686617,-2.9346459572301082
408.80000000000507,46.157061226649134,-0.023325894514405032,-2.935685540993047
410.0000000000051,46.278501175736494,-0.025072866917563164,-2.9385032471642405
411.20000000000516,46.394339108968325,-0.02455769738434105,-2.9430835931773998
412.40000000000515,46.512805632716805,-0.02632391794439165,-2.9486678150543746
413.60000000000514,46.63066859900232,-0.025034199054264183,-2.952736913557932
414.8000000000052,46.74714226004434,-0.027768705442270114,-2.9541728178431743
416.00000000000523,46.86524691889726,-0.031003270959280016,-2.9574747064851987
417.2000000000052,46.982793696075234,-0.03173827347124203,-2.9594766803050923
418.4000000000052,47.09956278138938,-0.031601180633297754,-2.9655873671860684
419.60000000000525,47.21688174946218,-0.03158009560110253,-2.970117857444861
420.8000000000053,47.33489465779953,-0.031612723328978354,-2.97418233936241
422.0000000000053,47.45194678706522,-0.032670506757837336,-2.9763347389889265
423.2000000000053,47.56887433456566,-0.02966613533475243,-2.979730186743923
424.4000000000053,47.68629084738954,-0.02927170511164373,-2.9824703089171027
425.60000000000537,47.804463515828914,-0.032123827989207765,-2.98246994249487
426.80000000000535,47.92214681131056,-0.0335555123039088,-2.9851888318135713
428.00000000000534,48.0397763351261,-0.03372112934599658,-2.9894137688406035
429.2000000000054,48.15768126831171,-0.03194023318540662,-2.9908564829151176
430.40000000000543,48.27538592808628,-0.032318198011739074,-2.99619038756551
431.6000000000054,48.39486415874993,-0.029916429670222566,-2.9988114561993124
432.8000000000054,48.51104976656756,-0.03196480409151603,-3.0030620510310464
434.00000000000546,48.630425782113086,-0.026543399401231904,-3.0047397832861478
435.2000000000055,48.74828978214791,-0.02797778642606169,-3.005674907956038
436.4000000000055,48.865769217589914,-0.02432811291227327,-3.0097477888471955
437.6000000000055,48.98338062381544,-0.023325795580727615,-3.0124179188093287
438.8000000000055,49.10198756560924,-0.0204751507472129,-3.015642681307133
440.00000000000557,49.21978408280839,-0.01945053475053482,-3.0177012975820605
441.20000000000556,49.338787936130785,-0.019761751336849154,-3.020507395620805
442.40000000000555,49.455999463368855,-0.017469201756201813,-3.024362396950403
443.6000000000056,49.57434706611086,-0.015258815614159205,-3.027003039501997
444.80000000000564,49.69280515436838,-0.012964023586121864,-3.028671432040018
446.0000000000056,49.811109523810295,-0.01390319541132684,-3.0296381384015323
447.2000000000056,49.92926791916946,-0.00998450438736087,-3.0332635454522214
448.40000000000566,50.04679110186339,-0.008296732113609595,-3.0388924044889047
449.6000000000057,50.163998814415805,-0.010651079600166091,-3.0390303260019804
450.8000000000057,50.2837767927529,-0.007778602801050194,-3.04084267259125
452.0000000000057,50.40161074166352,-0.00568385758845158,-3.0418219498756627
453.20000000000573,50.52029852998771,-0.006337234540643943,-3.0431304511772685
454.4000000000058,50.63827750534998,-0.0038404920880968363,-3.045035786506037
455.60000000000576,50.75716508194297,-0.00045399517478805773,-3.0470798681813114
456.80000000000575,50.87588570966499,-0.0012164510537073792,-3.048255053860937
458.0000000000058,50.99390472280623,-0.0003787947154600957,-3.0540184155137493
459.20000000000584,51.111925960461285,0.0012475158898009875,-3.0564360279495126
460.40000000000583,51.229871374540984,-0.001483329498560948,-3.056801315209421
461.6000000000058,51.348298934611414,0.0013495966041617846,-3.057976787263551
462.80000000000587,51.466679557102154,0.0011477643784602032,-3.0603831284037324
464.0000000000059,51.58531397463652,0.0007778012704736104,-3.0626326039064713
465.2000000000059,51.70390332811143,0.0012059920560660298,-3.0643029929024506
466.4000000000059,51.8212274277635,0.004357955123802104,-3.064627990965827
467.60000000000593,51.93983771307958,0.0037738769125239546,-3.0672597898187814
468.800000000006,52.05739601928187,0.004285564429835298,-3.0685725489311353
470.00000000000597,52.17469581793978,0.006444258706414352,-3.0713205529575527
471.20000000000596,52.292570712628475,0.008632309129477544,-3.07265736067244
472.400000000006,52.41054477370015,0.012478770499531944,-3.074279184201088
473.60000000000605,52.52804044605887,0.012889518986124393,-3.0769206589172446
474.80000000000604,52.6464160916875,0.016298944913257896,-3.078601095112613
476.000000000006,52.76283921776227,0.02141206437449622,-3.0812021652188957
477.20000000000607,52.88161880922449,0.025014492971361713,-3.081767374628559
478.4000000000061,52.99993869355628,0.024491796654192988,-3.0828541840007855
479.6000000000061,53.11832789605065,0.023416669617975783,-3.084149887284762
480.8000000000061,53.23628819813162,0.028313103806236195,-3.086601692290433
482.00000000000614,53.35405373270757,0.030550956311118926,-3.0888326542420894
483.2000000000062,53.472594742020476,0.03335930979916546,-3.0890389077244302
484.4000000000062,53.5905842382926,0.03640752575051065,-3.0899284520928205
485.60000000000616,53.70656452070831,0.03770958152650106,-3.090639394864847
486.8000000000062,53.827304499533255,0.039464757030941766,-3.093359877484054
488.00000000000625,53.946409861425856,0.04363377919474387,-3.094679447071987
489.20000000000624,54.06363815444373,0.04556347452799281,-3.0960007853623646
490.40000000000623,54.18252936525642,0.04600339056225178,-3.098626065534786
491.6000000000063,54.30108909381072,0.05069663047658457,-3.101260446928375
492.8000000000063,54.420262511950405,0.05480173893288931,-3.102580224286029
494.0000000000063,54.53866506367494,0.05641916597371999,-3.1038901845567377
495.2000000000063,54.65747368843278,0.05644429943412477,-3.1052100930548416
496.40000000000634,54.77656329819387,0.058511556615794325,-3.1065346401527307
497.6000000000064,54.89469019565239,0.05684514597120438,-3.1065578667078126
498.8000000000064,55.01327066002879,0.05851856135312894,-3.107858334776737
500.00000000000637,55.13269926805603,0.05952284398255925,-3.1081845842273257
501.2000000000064,55.251450870749494,0.061521246863618595,-3.110415522412656
502.40000000000646,55.37153620532328,0.058467536853055835,-3.1118067017841704
503.60000000000645,55.49012424606989,0.06001951762793345,-3.1144189865962706
504.80000000000643,55.6084325513141,0.0611292248196903,-3.1144146059345585
506.0000000000065,55.72709284714264,0.05903588981419372,-3.115749999243215
507.2000000000065,55.84586804368115,0.058437332375366524,-3.1170585196687837
508.4000000000065,55.965820749407285,0.057198691173271476,-3.1183711087138226
509.6000000000065,56.08343498984544,0.055049148962635464,-3.1187665666234263
510.80000000000655,56.203057217445696,0.054527115831169426,-3.1205379216742344
512.0000000000066,56.32216281490877,0.05714602771193367,-3.1217780564730635
513.2000000000066,56.441309724853376,0.05321375163338771,-3.1243982705538733
514.4000000000066,56.55971827545018,0.05305125680830858,-3.1244099569043016
515.6000000000066,56.67867943586559,0.05001712330085151,-3.124408264512881
516.8000000000067,56.79785814366584,0.04181002457086502,-3.1270394441023672
518.0000000000066,56.917456000692255,0.03171500204263822,-3.127039961104499
519.2000000000066,57.036301735331435,0.02794905599829922,-3.128360219812902
520.4000000000067,57.15537615477518,0.026021685413957885,-3.129999865681971
521.6000000000067,57.27444669797141,0.021412584341146568,-3.130074147795261
522.8000000000068,57.39409804623846,0.019048987860687205,-3.131319985528082
524.0000000000067,57.51275806045584,0.016896652640443266,-3.132949840192804
525.2000000000068,57.63139693953664,0.016644009493743228,-3.135269102248132
526.4000000000068,57.75057781381559,0.01690542765196046,-3.13525937324492
527.6000000000067,57.87077352990795,0.013913785373584897,-3.137058861979015
528.8000000000068,57.98984287769078,0.01261039329922542,-3.1384024578805416
530.0000000000068,58.10888215410836,0.012394272495774628,-3.140198495244775
531.2000000000069,58.228225226290164,0.011818489676035826,-3.1402014056485417
532.4000000000069,58.34665055380045,0.01024400451153007,-3.1402091263829908
533.6000000000068,58.46584514926219,0.011316437350373687,-3.1415198270063485
534.8000000000069,58.58479617092762,0.009714990910732024,-3.1426136782814176
536.0000000000069,58.70412508381554,0.009279510720597517,-3.1428413234607326
537.2000000000069,58.82351420654163,0.005777468983250378,-3.144160401715717
538.4000000000069,58.94314628940505,0.0028820324993957813,-3.144011787930979
539.600000000007,59.061166939677676,0.008859632292197328,-3.1442008437141338
540.800000000007,59.18094060101647,0.004515257797977568,-3.1466686612980563
542.000000000007,59.30034077645243,0.005044088103238198,-3.147989226977204
543.200000000007,59.41944920357931,-0.0008633496795344975,-3.1479899324032434
544.400000000007,59.539167996093035,0.001119953284833608,-3.1486540076222695
545.6000000000071,59.65855784822318,0.0024924363008027584,-3.1525977003308783
546.800000000007,59.77720638666181,-0.0010583071568677216,-3.1522700834635757
548.000000000007,59.89696556280394,0.0005959043724104163,-3.152269387063301
549.2000000000071,60.01786052650263,-0.0002077875375817717,-3.153573038098128
550.4000000000071,60.13737018906271,-0.0011230377853405082,-3.153588135151277
551.6000000000072,60.25720992762841,-0.002247012757586875,-3.1548383601096424
552.8000000000071,60.37670792362868,-0.005800855087553347,-3.156227973196249
554.0000000000072,60.49616779057535,-0.008569567742739537,-3.1562121437403814
555.2000000000072,60.61603189136726,-0.006922259302642675,-3.1575320955040764
556.4000000000071,60.7354747171926,-0.007901778781322366,-3.1615502475921122
557.6000000000072,60.85457597594649,-0.010098188068704661,-3.160827685032004
558.8000000000072,60.97474128226111,-0.011099135105948954,-3.1608487072588125
560.0000000000073,61.093855357881296,-0.012003412483789333,-3.1619529550381977
561.2000000000073,61.21321153837263,-0.010587096094357706,-3.161403918119832
562.4000000000073,61.33245432728016,-0.00883363124021741,-3.162748190048391
563.6000000000073,61.45232197572563,-0.009045432205575077,-3.1643973980849833
564.8000000000073,61.571213897595186,-0.012525565355758217,-3.165760101506148
566.0000000000073,61.691034226024975,-0.014039770658764938,-3.1644346742810865
567.2000000000073,61.81167268824853,-0.013844058946068771,-3.166632173471168
568.4000000000074,61.93021176992421,-0.013054449558604464,-3.168390326210538
569.6000000000074,62.05047134912043,-0.011986748834275973,-3.168390057104963
570.8000000000075,62.16894175411244,-0.013766847869965515,-3.169380475204957
572.0000000000074,62.2904218970749,-0.01589428076121724,-3.1704762858245017
573.2000000000074,62.40853797042,-0.015547057373863526,-3.1704649768026
574.4000000000075,62.5301146427771,-0.017909249738431998,-3.169701128979274
575.6000000000074,62.64947851759616,-0.018372504933340528,-3.172018137919031
576.8000000000075,62.76965013752112,-0.017265062767542694,-3.1746476241353063
578.0000000000075,62.88917000000076,-0.017573733515653944,-3.1733300098078585
579.2000000000075,63.008751920993646,-0.017291485281522356,-3.174639862015109
580.4000000000076,63.12880645363221,-0.01930545414857532,-3.1746398244643617
581.6000000000075,63.247999001881475,-0.017532887160936705,-3.1736578422224415
582.8000000000076,63.367726366050626,-0.01789979678623177,-3.1749675101996404
584.0000000000076,63.48723589279771,-0.019855858801909876,-3.177615460972543
585.2000000000075,63.607287369690916,-0.020340370050569656,-3.1775999466173968
586.4000000000076,63.72749523532601,-0.021846669259964147,-3.179579535806641
587.6000000000076,63.84817512834085,-0.02326569519375099,-3.18024234322571
588.8000000000077,63.967495363719266,-0.022516808224294138,-3.1815594531812232
590.0000000000077,64.08648701614302,-0.022113076424400524,-3.1809820280509102
591.2000000000077,64.20602723327475,-0.0211522701018807,-3.1828686784183953
592.4000000000077,64.32758567625693,-0.021853960747320822,-3.1841704683249965
593.6000000000078,64.44702687954569,-0.022861177731107962,-3.1826819049270156
594.8000000000077,64.56706093013565,-0.02083998060637926,-3.1841635892155304
596.0000000000077,64.68742145195206,-0.017831752811181212,-3.1828702183948696
597.2000000000078,64.80749960436916,-0.015129966773079873,-3.1868206041825538
598.4000000000078,64.92675057540607,-0.01677284318388017,-3.1868198050578584
599.6000000000079,65.0478391671004,-0.018155242430513363,-3.1868685940250163
600.8000000000078,65.16759574730418,-0.016790699898361572,-3.1868816942562486
602.0000000000078,65.28856477968228,-0.01770196836637339,-3.1864900299293972
603.2000000000079,65.40753005823268,-0.01681058570841165,-3.189164591880144
604.4000000000078,65.52856705598548,-0.019363483721511976,-3.189504999869027
605.6000000000079,65.6482524714293,-0.01670762628100597,-3.1918659020607176
606.8000000000079,65.7685643380971,-0.016636333842663165,-3.1918699331413065
608.000000000008,65.88957616229838,-0.009747878170237145,-3.1931798445282986
609.200000000008,66.00926238775423,-0.012229714242142253,-3.1918645530870564
610.4000000000079,66.12946346526495,-0.008526393322696335,-3.1918700332104253
611.600000000008,66.24927151379987,-0.008129525113114155,-3.193184518478259
612.800000000008,66.36827162484617,-0.006497828579551501,-3.1935104997245123
614.000000000008,66.48857898452692,-0.00652634955186393,-3.1948301723683343
615.200000000008,66.60960431509945,-0.006641444149932618,-3.195477764781333
616.400000000008,66.73002425099128,-0.00726688920919627,-3.195809987446977
617.6000000000081,66.85063755892625,-0.004443163823632301,-3.198424078398556
618.8000000000081,66.9710580972585,-0.0023150784593469753,-3.199767307756474
620.0000000000081,67.0901257278062,-0.0015618804135898445,-3.19843997471796
621.2000000000081,67.2103600220293,-0.0030346495587760813,-3.197117035408579
622.4000000000082,67.33060965783788,-0.00015824528613983535,-3.1997639636525372
623.6000000000081,67.45154702816855,-0.002049938111805427,-3.1999515783801042
624.8000000000081,67.57120190729485,-0.0012975820665844795,-3.19976019114914
626.0000000000082,67.69249980195333,-0.0017706983811128785,-3.201409103774796
627.2000000000082,67.81404566104204,2.4393616912865568e-05,-3.201421645480923
628.4000000000083,67.9339063206011,-0.0035562422476709266,-3.2033845845883047
629.6000000000082,68.05537405586486,-0.0019302034859223216,-3.20206033864053
630.8000000000083,68.17413938577464,-0.003026757195442986,-3.202072883216443
632.0000000000083,68.29532864937237,-0.0007821165932209162,-3.201175441152647
633.2000000000082,68.41474825690405,-0.0011906290660910201,-3.20280228155696
634.4000000000083,68.53557747027071,-0.003439310241975191,-3.205130124511955
635.6000000000083,68.65510879249611,0.00014403752352776245,-3.2041395276242106
636.8000000000084,68.77462911538717,-0.0019421606193694707,-3.2054610980484117
638.0000000000084,68.89687558200825,-0.001394198235582067,-3.2080945951254036
639.2000000000083,69.01553883168908,-0.0003696747114816379,-3.209458955180218
640.4000000000084,69.13603682601143,0.0003302800121065541,-3.2071100819818326
641.6000000000084,69.25704381798349,0.0012165289441599114,-3.206765492857036
642.8000000000084,69.37884132431037,0.0004294843265577608,-3.2067800499916648
644.0000000000084,69.498984410852,-0.0011460496956614552,-3.206780686866302
645.2000000000085,69.61757745835158,0.00010453964636347735,-3.2094193697550857
646.4000000000085,69.73692313593922,0.0018888534188394868,-3.2103998573318533
647.6000000000085,69.8594727232126,-0.004649580450142521,-3.2104601645308266
648.8000000000085,69.98060361895809,-0.0017941328784463195,-3.210057199794636
650.0000000000085,70.10194018202921,-0.005219073599415536,-3.2123900319392122
651.2000000000086,70.22206078086236,-0.006084286635445135,-3.214140595084976
652.4000000000085,70.34306528774749,-0.003060590295199006,-3.2104134821507393
653.6000000000085,70.46272386188222,-0.004273796705430266,-3.2077702239313357
654.8000000000086,70.58387547250337,-0.006335566426034944,-3.2118011464088445
656.0000000000086,70.70500762166478,-0.005013185221322214,-3.213340505824768
657.2000000000087,70.82546613736501,-0.006968547434558214,-3.213689834667909
658.4000000000086,70.94714236244424,-0.007112825017859814,-3.2136898340226936
659.6000000000087,71.06715252872647,-0.007880636732489954,-3.214191169527808
660.8000000000087,71.18887274766907,-0.003630144911161315,-3.2150000495201736
662.0000000000086,71.30953791667132,-0.004716258795475214,-3.21437758262346
663.2000000000087,71.43054513524281,-0.005785205292053952,-3.2156703533567836
664.4000000000087,71.55155336834378,-0.003487502320478786,-3.2156597231877417
665.6000000000088,71.67183257709091,-0.00705813200126526,-3.215659801992997
666.8000000000088,71.79328882434201,-0.0005843489973254012,-3.2156182728229705
668.0000000000088,71.91456092322588,-0.0021692695057895506,-3.2169979608487833
669.2000000000088,72.03501501845004,-0.004543797543473227,-3.2209390966923928
670.4000000000088,72.15572219782632,-0.002425077751065041,-3.218298682879351
671.6000000000088,72.27645122628788,-0.008699726863901525,-3.218299967999834
672.8000000000088,72.39785139363234,-0.006722979064035517,-3.2182999680040294
674.0000000000089,72.51897587304879,-0.005854279746435376,-3.216943841810342
675.2000000000089,72.64000275426315,-0.005129453159685049,-3.2196228109390326
676.400000000009,72.76068331306553,-0.00516579796796468,-3.219609801382283
677.6000000000089,72.88067955961947,-0.004101054862350795,-3.219609972363687
678.8000000000089,73.00258827676524,-0.004824788869262964,-3.2182998836262313
680.000000000009,73.123983739692,-0.005363607083518573,-3.220929994574833
681.2000000000089,73.24412343211783,-0.001721359592274041,-3.2222438725668416
682.400000000009,73.36544766542173,-0.004159526077962994,-3.2222399727379587
683.600000000009,73.48421313608416,-0.005839404710828333,-3.2196201932431023
684.800000000009,73.60645304375433,-0.0019316569058958066,-3.220732192903366
686.0000000000091,73.72818530822501,-0.0025625530090902515,-3.222211166006728
687.200000000009,73.84831856976281,-0.004745311211450831,-3.2235780318490006
688.4000000000091,73.96977664645725,-0.005534578071584972,-3.223569855634138
689.6000000000091,74.09053246467907,-0.00568557809290593,-3.2248790225004704
690.800000000009,74.21144505568749,-0.007404515634687137,-3.2222518326683134
692.0000000000091,74.3335614978906,-0.012889829216136572,-3.2222545359359556
693.2000000000091,74.45380358339304,-0.007033896458361832,-3.2221407714872
694.4000000000092,74.57574938384113,-0.010264187414984471,-3.2239026772524495
695.6000000000092,74.69720860368088,-0.01291622566564965,-3.224884740036832
696.8000000000092,74.81783364194132,-0.010972417111070998,-3.224880135445065
698.0000000000092,74.9389729697704,-0.010279254439239383,-3.2248069332547473
699.2000000000093,75.060688926451,-0.013473864674892422,-3.2258696516650502
700.4000000000092,75.18243307418399,-0.016923477287182465,-3.2255368172508394
701.6000000000092,75.30294594629322,-0.01836370938627785,-3.2255400782463814
702.8000000000093,75.42376762218072,-0.013197046220722042,-3.226307149305406
704.0000000000093,75.54372996819556,-0.016812295842650427,-3.229804432905782
705.2000000000094,75.66696793644361,-0.01611850957706351,-3.229951067455752
706.4000000000093,75.7876367971206,-0.016066186263423488,-3.2288299839981045
707.6000000000093,75.90757064619493,-0.012001628610138981,-3.227518402352288
708.8000000000094,76.0299856129162,-0.015081835888451023,-3.2301402713304403
710.0000000000093,76.15044381577067,-0.013362448503159374,-3.2288202107909596
711.2000000000094,76.27241489209011,-0.01650130259427529,-3.231459542146694
712.4000000000094,76.39339559870005,-0.019294697284231166,-3.230140911852352
713.6000000000095,76.51383423528956,-0.017877918969334772,-3.230142107652707
714.8000000000095,76.63535508351525,-0.017522782891439048,-3.2314780074857063
716.0000000000094,76.75410432221858,-0.016129206611399383,-3.232119913877236
717.2000000000095,76.87776691461191,-0.019297913774499076,-3.2321115063680717
718.4000000000095,76.99967691071116,-0.015362014754296993,-3.2314615180666633
719.6000000000095,77.12127922810528,-0.019589962351018286,-3.2327653849736104
720.8000000000095,77.24198965846146,-0.01925244274030935,-3.2340541538857845
722.0000000000095,77.36378016423596,-0.015743568984313505,-3.2327788941008313
723.2000000000096,77.48587962511857,-0.019358987791157967,-3.232779272563087
724.4000000000096,77.60598185992885,-0.021086606769392446,-3.231460060859326
725.6000000000096,77.72917184893619,-0.0203176826230953,-3.233430135686202
726.8000000000096,77.84984467051748,-0.01969383937756053,-3.2340574322888287
728.0000000000097,77.97136194887673,-0.023584192862876607,-3.235323469258388
729.2000000000096,78.09230435965073,-0.02722610129627867,-3.2340900324652657
730.4000000000096,78.21387413180108,-0.024893794775036282,-3.2327658416717093
731.6000000000097,78.33495190199258,-0.02139338173691896,-3.2354113608291923
732.8000000000097,78.45770461459165,-0.029256580383666186,-3.2354390628431196
734.0000000000098,78.57855403167403,-0.027990462557035523,-3.2367223463235932
735.2000000000097,78.7001612492892,-0.025278819073794256,-3.238039014358653
736.4000000000098,78.8219764011245,-0.025302493245964452,-3.2367298149128816
737.6000000000098,78.94301001892367,-0.025521689177071982,-3.2367383637712814
738.8000000000097,79.06368327719966,-0.023087508188348593,-3.236730000430436
740.0000000000098,79.18653405805294,-0.02888809826216221,-3.235930778651085
741.2000000000098,79.30820359553117,-0.02930128055019532,-3.2354099828068157
742.4000000000099,79.42926778110211,-0.02840961028989919,-3.236734821232404
743.6000000000099,79.55087704014392,-0.0325086486898154,-3.2380256274065538
744.8000000000098,79.6716256386456,-0.034038182553207674,-3.238040386292406
746.0000000000099,79.79360269373689,-0.03053069548412468,-3.2367293873800778
747.2000000000099,79.91608076547777,-0.033170262896260905,-3.2354103968375174
748.4000000000099,80.0381264270146,-0.03321480720146375,-3.2367295994183163
749.6000000000099,80.16037245410389,-0.032344061932342516,-3.238039074303483
750.80000000001,80.28176219039601,-0.03495905206192074,-3.2380368184692907
752.00000000001,80.40381014596673,-0.03450860198973604,-3.2390786687744364
753.20000000001,80.52673859245715,-0.034002352826210336,-3.2393599499899217
754.40000000001,80.64665684246654,-0.03833872818654682,-3.2393600855022466
755.60000000001,80.76917186155131,-0.04103634873203865,-3.2372175328692787
756.8000000000101,80.89010269165865,-0.03936564976957779,-3.2380301497992283
758.00000000001,81.00996999881903,-0.04042797350217153,-3.2394533821530374
759.20000000001,81.13283860574553,-0.03911441398033144,-3.2380354133514615
760.4000000000101,81.25414801401311,-0.04297038727134406,-3.2380401791730566
761.6000000000101,81.37608896113812,-0.04230660192865754,-3.238710794680922
762.8000000000102,81.49801070226285,-0.04389478659252721,-3.2396894384842865
764.0000000000101,81.61962318674709,-0.045356411366121785,-3.2396900132495716
765.2000000000102,81.74087700177684,-0.04712106251047743,-3.2396827363599323
766.4000000000102,81.86322183250121,-0.04876468045493265,-3.240995509742918
767.6000000000101,81.98465773677499,-0.04599657258478329,-3.2410090415083657
768.8000000000102,82.10591634500636,-0.04996484672340107,-3.2429799846023073
770.0000000000102,82.22888818794267,-0.05148034564002302,-3.2420016718277944
771.2000000000103,82.35002538665054,-0.05205483789249521,-3.2423627336056775
772.4000000000103,82.47170323687192,-0.05203722248533782,-3.240006410376355
773.6000000000103,82.593308649958,-0.052304040469122626,-3.2406700160486275
774.8000000000103,82.71541358551275,-0.05155000689542999,-3.241980262756744
776.0000000000103,82.83746333296921,-0.052637108887406914,-3.2416598521014204
777.2000000000103,82.95937653856296,-0.05371269881241458,-3.2416598520000086
778.4000000000103,83.08127273612699,-0.05948025768532483,-3.241660676530145
779.6000000000104,83.20362983348556,-0.05411073821008827,-3.242970084863322
780.8000000000104,83.3259319487438,-0.05304875120323893,-3.241990470285412
782.0000000000105,83.44755243007555,-0.05304550221523119,-3.2433259194750157
783.2000000000104,83.56979498157153,-0.05710731332737429,-3.244950174059628
784.4000000000104,83.69233908176541,-0.05498748780826368,-3.2456099878009907
785.6000000000105,83.81415877232149,-0.06238615916526724,-3.243951484757392
786.8000000000104,83.9362739573917,-0.06302849686897893,-3.240351168800208
788.0000000000105,84.0588421869207,-0.06292351687553954,-3.2422743194737897
789.2000000000105,84.17928259101268,-0.06080264987134765,-3.245601670896001
790.4000000000106,84.30188836950535,-0.06732119290011473,-3.2465470220867245
791.6000000000106,84.42365494074217,-0.06422252950156793,-3.2458904180296817
792.8000000000105,84.54472847943165,-0.06349328491415718,-3.2456032801224333
794.0000000000106,84.66609937494425,-0.06705517791725857,-3.245609922093622
795.2000000000106,84.78782725154217,-0.0677969716596869,-3.244299917886949
796.4000000000106,84.91024776932781,-0.06915821181824633,-3.2456098651059246
797.0000000000106,84.97033194335285,-0.07085123651594549,-3.2463631227932703