File: 01_Data/Bamboo_Rug_Bamboo/STA/N2/10K_min/Bamboo_Rug_Bamboo_STA_N2_10KData_220120_R1.csv
##Temp./Â°C,Time/min,DSC/(mW/mg),Mass loss/mg
50.0,10.792319483436085,0.04862162952067228,0.001618281195896465
51.20000000000002,11.096818074697872,0.08434722961391583,-0.0007594358338631757
52.400000000000034,11.314561178917963,0.11096284629816677,-0.000859192794846475
53.60000000000005,11.498757931082912,0.12923439255860347,-0.0032663866859587998
54.80000000000007,11.664788971055719,0.14672741184296179,-0.002823968379134012
56.000000000000085,11.819761926781961,0.1594039245708675,-0.003476078556358786
57.2000000000001,11.968138414650761,0.17075971226107245,-0.0032990020227696704
58.40000000000012,12.110413247904724,0.17838963842961486,-0.002790654455592012
59.600000000000136,12.25031230111555,0.18737154461174277,-0.002721174806139537
60.80000000000015,12.388712116841178,0.19668767777434182,-0.0035213829084783654
62.00000000000017,12.522300945869025,0.20121840902391142,-0.0027085159024333727
63.20000000000019,12.65570476788592,0.2072176413821194,-0.0036884549339673
64.4000000000002,12.787637241008062,0.21147163660904933,-0.004171797079815409
65.60000000000022,12.918002535461543,0.21703816556820765,-0.004179277380862434
66.80000000000024,13.048581728262384,0.21874981257783233,-0.0028510640854499947
68.00000000000026,13.176877212864479,0.22299352702084457,-0.004136238334531139
69.20000000000027,13.30676998787187,0.2276988828945502,-0.0023555779844159908
70.40000000000029,13.43351154794737,0.23187392761461578,-0.002955492736553378
71.6000000000003,13.560106393756755,0.23669464940957707,-0.00284065479802198
72.80000000000032,13.686986720846527,0.24196827745347388,-0.002638122197878623
74.00000000000034,13.812777043480867,0.24362019062595802,-0.0027425480565197446
75.20000000000036,13.93947115787504,0.2461364681407433,-0.0027397482828912523
76.40000000000038,14.06457030822316,0.24895785099010137,-0.0040601221926630515
77.60000000000039,14.189815121237736,0.2510765764681952,-0.004053457265912996
78.80000000000041,14.313690335961676,0.25205805063190445,-0.004049620424121159
80.00000000000043,14.437403860479794,0.25716730995904874,-0.005369645332547801
81.20000000000044,14.562642709880015,0.2583122040101873,-0.005365161433100063
82.40000000000046,14.685017125182652,0.260752762928916,-0.005372696007978739
83.60000000000048,14.808300063328652,0.26023410019924775,-0.005382667480723136
84.8000000000005,14.929280697276665,0.2604682944705112,-0.007009876015966032
86.00000000000051,15.049989785887318,0.26202381214637577,-0.00895574106855479
87.20000000000053,15.172692885316721,0.26224823704813854,-0.008990859492630232
88.40000000000055,15.292732150260845,0.26096084607174624,-0.010130460326681856
89.60000000000056,15.414621181159708,0.2630352171803207,-0.007681135588238686
90.80000000000058,15.535644133381375,0.2612847330044783,-0.00983403181731246
92.0000000000006,15.654708165130197,0.25931893492171665,-0.00988207503278149
93.20000000000061,15.77427381479484,0.2575325520412491,-0.009952266433506995
94.40000000000063,15.894082180862965,0.25623616360006185,-0.010310461598879161
95.60000000000065,16.01345176701675,0.2550387740989972,-0.010282655375249306
96.80000000000067,16.13318317773965,0.2523964635524453,-0.011621558747477057
98.00000000000068,16.251522933398473,0.2513632478885701,-0.012273251321319734
99.2000000000007,16.369352119762837,0.25167599074665137,-0.011300109367591737
100.40000000000072,16.48866009356181,0.2509048022288344,-0.011300122099555221
101.60000000000073,16.60647840410185,0.2491137108454225,-0.011226636020443603
102.80000000000075,16.723689311419715,0.24862405060413956,-0.011655966002370732
104.00000000000077,16.84331629769373,0.25041339561969367,-0.011258461608932624
105.20000000000078,16.960350796114422,0.2509625983865857,-0.011311538628275386
106.4000000000008,17.07771332187441,0.2511714899546139,-0.011629159842009518
107.60000000000082,17.19549722095617,0.25312199120586876,-0.011290852843590216
108.80000000000084,17.3126044487292,0.2510563748581623,-0.01129005826512186
110.00000000000085,17.42787829991896,0.25217404726620807,-0.012628945785563062
111.20000000000087,17.547348353607518,0.2522969566773722,-0.013571159937989297
112.40000000000089,17.664221642670416,0.25015563720583656,-0.012418968465243374
113.6000000000009,17.780933034393925,0.25117116817639373,-0.012612822305691385
114.80000000000092,17.89955704118014,0.2489136915566242,-0.01260978461168527
116.00000000000094,18.017211349081453,0.25112241779111777,-0.013270024146581072
117.20000000000095,18.13448201772921,0.2516665343484329,-0.012740097345584012
118.40000000000097,18.252135154440193,0.25463924044318476,-0.012645052855677186
119.60000000000099,18.368650657893642,0.2538371916728366,-0.012610231392291116
120.800000000001,18.484627280030928,0.2552829506912654,-0.013933055886305556
122.00000000000102,18.602357651196243,0.2555936341129482,-0.013930423866816533
123.20000000000104,18.71943557176441,0.25535774019816343,-0.01294206391487629
124.40000000000106,18.83606330956948,0.2534051738208961,-0.013949768885481717
125.60000000000107,18.953144486407385,0.2569816373956547,-0.01267623039386967
126.80000000000109,19.069991276368327,0.2560116570810133,-0.013572601143879925
128.0000000000011,19.18620721194903,0.2580712042806016,-0.013916012422551916
129.20000000000113,19.302021914601625,0.2580389725507365,-0.013929979918182234
130.40000000000114,19.420029517016214,0.2604419456889192,-0.0139299760001661
131.60000000000116,19.535754797585245,0.2593034597477545,-0.01392574594372853
132.80000000000118,19.653660833250434,0.2626180342984002,-0.015249366487369631
134.0000000000012,19.769170000000113,0.2611780563180928,-0.013930107376321832
135.2000000000012,19.88441023546776,0.2648674724437602,-0.01391826278187347
136.40000000000123,20.000531196903868,0.26576793020115363,-0.0152617911949684
137.60000000000124,20.11752513985598,0.26696929305646466,-0.015369939707402747
138.80000000000126,20.232463417263347,0.26863108950620196,-0.015245148740109737
140.00000000000128,20.34866755420565,0.26770613689436384,-0.013928580451483263
141.2000000000013,20.464328969249294,0.270567932317089,-0.015239877219725972
142.4000000000013,20.579522227212383,0.2707978702126345,-0.015239875673559222
143.60000000000133,20.694707605830914,0.2735204659694709,-0.013932366111851557
144.80000000000135,20.810221602280457,0.27183369262235546,-0.016584370563629047
146.00000000000136,20.927321788886697,0.27284905076967525,-0.015387995555189438
147.20000000000138,21.041762145991395,0.273031525076778,-0.01654780669337219
148.4000000000014,21.157507239885874,0.2755275432121451,-0.015258048160658788
149.60000000000142,21.274185113782025,0.2759620643899619,-0.01655395603320242
150.80000000000143,21.388979585534518,0.2788922926019927,-0.01590068841736736
152.00000000000145,21.504692438374253,0.2766203036334366,-0.01754015779710283
153.20000000000147,21.61671804567681,0.276777404718798,-0.01689688294045011
154.40000000000148,21.735629967250823,0.2772628152737281,-0.018209908025728527
155.6000000000015,21.850863459586407,0.2795948370865638,-0.018209542495674746
156.80000000000152,21.9662030682659,0.2828145145685272,-0.017523092123869155
158.00000000000153,22.08068474664637,0.28282987367296303,-0.016560172439356258
159.20000000000155,22.196867838076976,0.285743186992087,-0.016560310228728614
160.40000000000157,22.313177029592122,0.28844193031656584,-0.018874108477723528
161.6000000000016,22.427771602190013,0.2884057859777614,-0.017768923029891415
162.8000000000016,22.543831199215344,0.291067330593188,-0.020400810449861417
164.00000000000162,22.658266908846652,0.2916645112272576,-0.02040026278044893
165.20000000000164,22.773170745373562,0.29502121926407443,-0.019080091930255616
166.40000000000165,22.888128452945438,0.2944196606194757,-0.01908028821570884
167.60000000000167,23.003261223318393,0.2971579309293524,-0.02170793650860725
168.8000000000017,23.117673434485027,0.29929958539190327,-0.021065452385397698
170.0000000000017,23.23307556146189,0.3015390324869518,-0.019739725808471054
171.20000000000172,23.348730229494358,0.3005109411272945,-0.021060180061525102
172.40000000000174,23.464773482745137,0.30425217155406836,-0.022359061325568863
173.60000000000176,23.579673649835573,0.30260654314661395,-0.023680184174936336
174.80000000000177,23.693512606916947,0.3065940041443757,-0.023680183999974957
176.0000000000018,23.810188126650786,0.3089076484836391,-0.02368018092329338
177.2000000000018,23.923748034873107,0.31082678650062634,-0.02600035161586023
178.40000000000182,24.039170913493262,0.3119663411265375,-0.02599018399982933
179.60000000000184,24.154834117902602,0.3136851614361337,-0.025991517894852656
180.80000000000186,24.26899622031696,0.3153793698202564,-0.02731017928154511
182.00000000000188,24.384189328010873,0.3188476378684986,-0.02731018400001295
183.2000000000019,24.499077875365717,0.3185453115702619,-0.027310183996601456
184.4000000000019,24.61354761400232,0.3223367767715649,-0.027704582863656402
185.60000000000193,24.72861330467336,0.3253729134093666,-0.03169166271785562
186.80000000000194,24.843876835673733,0.32561936783491885,-0.03300984342924895
188.00000000000196,24.95708412406906,0.3264255292646899,-0.03301002821573862
189.20000000000198,25.071565486806854,0.32512057701564845,-0.03253189539193624
190.400000000002,25.18607209162053,0.33152303821600526,-0.034332572112139026
191.600000000002,25.300897321754,0.3325639132087149,-0.034265197804755676
192.80000000000203,25.4141972319348,0.3331340160590055,-0.036969009806473
194.00000000000205,25.528807484215086,0.334613952050859,-0.0369760925163618
195.20000000000206,25.641960037036693,0.33665299695498196,-0.03828034326195828
196.40000000000208,25.758932833117118,0.33859391434937924,-0.040909932798189
197.6000000000021,25.872910480371132,0.33854537272526547,-0.04222221647518154
198.80000000000211,25.98828255611347,0.3415643181323682,-0.043540457372713615
200.00000000000213,26.10237555406327,0.3436319862958181,-0.04611454355201561
201.20000000000215,26.217896250153863,0.345554383284999,-0.04617117637413104
202.40000000000217,26.331871141985886,0.3478735579096215,-0.04748583958914132
203.60000000000218,26.447496024912624,0.34765683573515915,-0.05011530108808504
204.8000000000022,26.562464871039662,0.34977757464446263,-0.05144768552014867
206.00000000000222,26.676306531853367,0.3509979502506754,-0.052760723751158256
207.20000000000223,26.791534417349766,0.3542933036722448,-0.05559535433610252
208.40000000000225,26.906190019938563,0.3549879115665649,-0.05743307001120623
209.60000000000227,27.02027599235933,0.35795498478114157,-0.0586803645266496
210.80000000000229,27.13518215940701,0.3603144792437796,-0.05858334815409716
212.0000000000023,27.249651357489896,0.36058761331412054,-0.06132401349533412
213.20000000000232,27.36407699319627,0.36517873596726796,-0.06404812321734132
214.40000000000234,27.47942984546347,0.36613735018492966,-0.06671310241996142
215.60000000000235,27.593296527533013,0.36658512401534976,-0.06993329863852615
216.80000000000237,27.70746620865458,0.36744921077095366,-0.06998353326875595
218.0000000000024,27.82181409910734,0.36721113815294887,-0.07267178879691594
219.2000000000024,27.936285558142256,0.3631806307852583,-0.07401988415964578
220.40000000000242,28.051736371488555,0.36043869762900427,-0.07685937472401871
221.60000000000244,28.164798477796694,0.3606829178130273,-0.08040717812891884
222.80000000000246,28.27991057345726,0.3602731006371311,-0.08419795330077307
224.00000000000247,28.39465254461684,0.35951759880889067,-0.0889796478593512
225.2000000000025,28.508083815675597,0.3618877523582036,-0.09037747977107102
226.4000000000025,28.62341892829927,0.3605007605401512,-0.09301823861018788
227.60000000000252,28.738285695013044,0.3593405611353599,-0.09432044798053463
228.80000000000254,28.852945822208127,0.3616014007390811,-0.09713264389018095
230.00000000000256,28.966310392937938,0.3599098755404203,-0.10142638148989569
231.20000000000258,29.0819267269017,0.35985859855583524,-0.10496311569583794
232.4000000000026,29.195373571408144,0.36128366851172156,-0.1082492339603407
233.6000000000026,29.310248570856444,0.36132541996411643,-0.11219966909541457
234.80000000000263,29.42137229781733,0.36182303391508586,-0.11637016614493367
236.00000000000264,29.539069111483673,0.3609321442290889,-0.11977113943741102
237.20000000000266,29.654533541191903,0.36251806942197273,-0.12290412708943377
238.40000000000268,29.768061387662588,0.3624309064985855,-0.1260746555581429
239.6000000000027,29.882664319263423,0.36330517469017726,-0.1319844693751433
240.8000000000027,29.997793678609742,0.36417952698460615,-0.13574291944364525
242.00000000000273,30.112088531852983,0.3650958844584217,-0.140828609029227
243.20000000000275,30.22594646587759,0.36842804365516163,-0.14576966371115097
244.40000000000276,30.341803642085033,0.3714492029491193,-0.15049158690974318
245.60000000000278,30.456872456009652,0.37469590312623574,-0.15380071669020667
246.8000000000028,30.569649886097338,0.3769006146949274,-0.1603034376851702
248.0000000000028,30.684959072384544,0.37991094087685484,-0.1674204399863859
249.20000000000283,30.799370571014173,0.3816122492438239,-0.17320861149036748
250.40000000000285,30.91350658207562,0.38378024639133096,-0.17789791015551426
251.60000000000286,31.02897766622538,0.3868125308784899,-0.1844941245564442
252.80000000000288,31.14290346922028,0.3887347179583369,-0.1910074279179952
254.0000000000029,31.257577349032164,0.3887873626548958,-0.19705209943172974
255.20000000000292,31.372332261033094,0.38150779323573564,-0.20439504987385515
256.40000000000293,31.486882700937763,0.37107522043500774,-0.211894255303946
257.600000000003,31.601358397841512,0.36652186709231127,-0.22079371289830618
258.80000000000297,31.7174084216929,0.3632710101271962,-0.22991167523274436
260.00000000000296,31.83018362655121,0.36293639706766945,-0.23914475101966248
261.200000000003,31.945520185353313,0.358867158463997,-0.2458983997896107
262.40000000000305,32.05967746737328,0.3573985413002245,-0.25756337691058073
263.60000000000304,32.17395472719142,0.362051015655925,-0.26721980563130554
264.800000000003,32.28815189451695,0.35934321846556333,-0.2779723394169067
266.00000000000307,32.403385032696036,0.36044878848481726,-0.28957537713291037
267.2000000000031,32.51774310971427,0.3584044883811817,-0.30162186241544564
268.4000000000031,32.63257742333675,0.3579617558826945,-0.31346697799128664
269.6000000000031,32.74733892445345,0.35478625507527745,-0.3244239281088461
270.80000000000314,32.86231941960524,0.3553422738003536,-0.3378297665952297
272.0000000000032,32.97721326145116,0.35291903169717254,-0.3516908608079006
273.2000000000032,33.091447814183525,0.349452192081238,-0.3651474441710252
274.40000000000316,33.20639228899972,0.34812155516547816,-0.3791129162606319
275.6000000000032,33.32127435102956,0.34478648087919084,-0.3956108524375148
276.80000000000325,33.436013772536555,0.34550371810583397,-0.41035350748709876
278.00000000000324,33.551924378871824,0.34287779117273454,-0.42864917945725534
279.20000000000323,33.66576991743223,0.3397226583225059,-0.44313708587589495
280.4000000000033,33.77985989357986,0.33865258374257445,-0.4605723442159335
281.6000000000033,33.89537160621007,0.3361893934824195,-0.47595888943750486
282.8000000000033,34.01038707210939,0.3344994929268164,-0.4944803706820471
284.0000000000033,34.12505933286205,0.3332887195704482,-0.5145806250255736
285.20000000000334,34.239848020261036,0.33179943868451056,-0.5343363664280161
286.4000000000034,34.35430583154951,0.33011846200043715,-0.5535778065355217
287.6000000000034,34.46886140760202,0.3297226260339722,-0.5732641013601762
288.80000000000337,34.58384792563597,0.3257521293874747,-0.5928978418964554
290.0000000000034,34.69860247899279,0.32676877178101515,-0.6144170212485678
291.20000000000346,34.81328571704228,0.3255877711048497,-0.6356181300357595
292.40000000000344,34.9278625324573,0.32522479127086773,-0.6573594955268551
293.60000000000343,35.043460727815344,0.32461946195224717,-0.67935593729666
294.8000000000035,35.158070842998654,0.3226332215742906,-0.7021475614065498
296.0000000000035,35.27237023304262,0.3238416241486588,-0.7274715778218503
297.2000000000035,35.38766754274706,0.32422449869558156,-0.7501690120973379
298.4000000000035,35.50207999231156,0.3210142711280945,-0.7733096402429185
299.60000000000355,35.61816421607166,0.31817119600002297,-0.7987904332699323
300.8000000000036,35.73256290796258,0.32110356747686086,-0.824261694329171
302.0000000000036,35.847265563428735,0.32238287337068483,-0.8489135691517267
303.20000000000357,35.96260176201399,0.32397045373053224,-0.8731572591620465
304.4000000000036,36.078007688133866,0.3246068327077327,-0.8984694474445214
305.60000000000366,36.193895597351734,0.32451267269824824,-0.9230021661027026
306.80000000000365,36.30937406799466,0.32571683901972825,-0.9480397490147192
308.00000000000364,36.42302459127477,0.3235305324693265,-0.9717732961491499
309.2000000000037,36.537871930056134,0.3238341048680565,-0.9959815132296717
310.40000000000373,36.65506468821654,0.32737591307289127,-1.0216459519012724
311.6000000000037,36.76947341148969,0.3296425528640572,-1.0478923029475968
312.8000000000037,36.884150408292456,0.32961443139278535,-1.070592970720396
314.00000000000375,37.00018640917876,0.3305403148693058,-1.094392379948367
315.2000000000038,37.11480824092129,0.33430247393747936,-1.1205591003402064
316.4000000000038,37.22993336454085,0.3356598980737324,-1.1455378988753142
317.6000000000038,37.345225187158235,0.3385843463135897,-1.1703571623208093
318.8000000000038,37.46082446780547,0.34091788826469394,-1.194516824391461
320.00000000000387,37.57646616093374,0.3436449971507264,-1.2183655344751654
321.20000000000385,37.6898658723277,0.34239328387357226,-1.242466276588039
322.40000000000384,37.80805939756728,0.34693518458910916,-1.268550471265574
323.6000000000039,37.923246839670064,0.350329619767323,-1.2932291495627029
324.80000000000393,38.03897346098168,0.35612851677624224,-1.3192649901312166
326.0000000000039,38.15133715586274,0.3603746975538936,-1.3443448415454746
327.2000000000039,38.270608452893214,0.3642450944584773,-1.3689679767619363
328.40000000000396,38.38620553994682,0.3694910050727478,-1.394889611228614
329.600000000004,38.50122181823379,0.3766688507061866,-1.4196100667657148
330.800000000004,38.6151205156771,0.3840277927574964,-1.4472479724588103
332.000000000004,38.73242232264518,0.38954872338841073,-1.4751732383824279
333.200000000004,38.84868705112296,0.3968443915141644,-1.50333324511347
334.40000000000407,38.963401762007486,0.404238998707127,-1.5314132162013188
335.60000000000406,39.08024713239198,0.4111549595647872,-1.5595956669582578
336.80000000000405,39.195121868394956,0.4211529257613279,-1.588393128305742
338.0000000000041,39.31012760019065,0.4318154850318448,-1.6185593391465742
339.20000000000414,39.426398582218354,0.442037425123963,-1.6501797972498617
340.4000000000041,39.54193264981063,0.4573100100363067,-1.6827587553584102
341.6000000000041,39.656809844771956,0.47020627082634703,-1.716666455327926
342.80000000000416,39.77312137420476,0.4805577663167632,-1.752527002072238
344.0000000000042,39.88812703176066,0.4953453926909101,-1.7904012805100717
345.2000000000042,40.00432578924707,0.5102095125638362,-1.8283748506782973
346.4000000000042,40.12099181909768,0.5240457529669232,-1.8684371649981424
347.60000000000423,40.236395915321786,0.5388816501391018,-1.9091524537274807
348.8000000000043,40.35288229659584,0.5584292227985855,-1.9540907249368518
350.00000000000426,40.46791961561411,0.5739074753432827,-2.0003526371811287
351.20000000000425,40.58452904822178,0.590074322509371,-2.0530747966466514
352.4000000000043,40.70050650180103,0.6051520388819036,-2.1036476935278783
353.60000000000434,40.81668944280251,0.6134637867400904,-2.1602528501916884
354.80000000000433,40.93284270780462,0.6156577431473006,-2.216410478873911
356.0000000000043,41.05012946260232,0.6037512830482503,-2.276012178196477
357.20000000000437,41.16562943436252,0.5803376084140897,-2.333054685298269
358.4000000000044,41.28178718509589,0.537164934575894,-2.38719270724902
359.6000000000044,41.3974896834355,0.48284056293558,-2.4384938555135847
360.8000000000044,41.512759768542885,0.42050965635877147,-2.483814610446679
362.00000000000443,41.627997355094266,0.35786039672067155,-2.5250271997902534
363.2000000000045,41.744328081611485,0.29747901675901,-2.5611555612806427
364.40000000000447,41.860893035471925,0.2411544592245674,-2.5892512497271536
365.60000000000446,41.97680681392215,0.1950768254893488,-2.6124126246906716
366.8000000000045,42.09163137946408,0.15721638258074871,-2.6308481604458116
368.00000000000455,42.20706278634541,0.12643330696033617,-2.647535940969349
369.20000000000454,42.32354859235508,0.10468411197502853,-2.6613852184306586
370.4000000000045,42.44016487028091,0.08563740989614554,-2.671949809143033
371.60000000000457,42.55486987737929,0.0708347403946688,-2.6803001022557797
372.8000000000046,42.67249398144119,0.05896779730941498,-2.687207440245731
374.0000000000046,42.7881251676841,0.04782101696038088,-2.696657823088665
375.2000000000046,42.905256959134064,0.04117366757820845,-2.7013041715280277
376.40000000000464,43.021379297493446,0.03404785003567001,-2.7070106187817373
377.6000000000047,43.137531516828524,0.0262136270392635,-2.7128216997798154
378.8000000000047,43.25458149690576,0.022823265535030446,-2.718332210867161
380.00000000000466,43.37091491863307,0.016486402843989056,-2.7230823984783106
381.2000000000047,43.48829915052099,0.012887620516464637,-2.728638394252472
382.40000000000475,43.604285535819415,0.008118040293589757,-2.7326653816088635
383.60000000000474,43.720468650759294,0.004357006727584878,-2.7372178686242528
384.80000000000473,43.83516482939483,0.0016879788457765943,-2.7415407963542
386.0000000000048,43.95525965016855,-0.001513145005799521,-2.7461913558822943
387.2000000000048,44.07149120784225,-0.007322480123850228,-2.750696971970987
388.4000000000048,44.18926874558968,-0.011226079320614812,-2.7546552348727857
389.6000000000048,44.307328708069306,-0.012335187050959429,-2.7559705345370227
390.80000000000484,44.423053945720184,-0.015954904571296002,-2.7612120177380346
392.0000000000049,44.54069006263738,-0.018750726248993377,-2.764956040140432
393.2000000000049,44.65818724852825,-0.02067722041930914,-2.7675984893224777
394.40000000000487,44.774921700255895,-0.023147743914214425,-2.773301520666578
395.6000000000049,44.89088258581727,-0.0259582430905837,-2.7761156459622027
396.80000000000496,45.00827422368844,-0.028118296548550192,-2.778809253363619
398.00000000000495,45.125208412543834,-0.029643491559861956,-2.781405775845898
399.20000000000493,45.24055832143235,-0.03544939828215826,-2.7857111019669047
400.400000000005,45.35725469103036,-0.03494633939678948,-2.789761344815985
401.600000000005,45.47289911064251,-0.03606805400504798,-2.7918909867568846
402.800000000005,45.58980801155053,-0.03916674547248972,-2.796430666117196
404.000000000005,45.70655945060966,-0.04125671037056772,-2.8008304611526476
405.20000000000505,45.8233135946067,-0.045089754477507904,-2.8037314028326654
406.4000000000051,45.93962253738644,-0.04666489559137932,-2.8070796567161223
407.6000000000051,46.056206512842486,-0.05024462190733303,-2.810071310415341
408.80000000000507,46.17373887523739,-0.051621645377896264,-2.8160964744829817
410.0000000000051,46.28683660685059,-0.055587961323599944,-2.8167590989265405
411.20000000000516,46.40626625346856,-0.054612526962157126,-2.820313928744145
412.40000000000515,46.52344360320339,-0.056365957610970574,-2.8256476350939823
413.60000000000514,46.64066235624805,-0.05715369695952949,-2.826404054093265
414.8000000000052,46.758290511434915,-0.062106301613146675,-2.8302593683128743
416.00000000000523,46.876103392812354,-0.05960605919405554,-2.8352551556755783
417.2000000000052,46.99270460384513,-0.06129684106333022,-2.837182032341143
418.4000000000052,47.11026942341723,-0.06251952183449161,-2.841621128508258
419.60000000000525,47.226659459055824,-0.06230798496223555,-2.8440612307109494
420.8000000000053,47.34632765220055,-0.06387954298022114,-2.8480741232581694
422.0000000000053,47.46384351818684,-0.06501643280585678,-2.8509676641383948
423.2000000000053,47.58129792925661,-0.06547198580569147,-2.853302821447622
424.4000000000053,47.69926397789099,-0.06607891000102961,-2.8571055367480582
425.60000000000537,47.81769948825039,-0.06500522494508165,-2.861034692346567
426.80000000000535,47.93455806209448,-0.06891869979350734,-2.863772017827126
428.00000000000534,48.052531551880165,-0.06512634787416682,-2.8658797958711886
429.2000000000054,48.17021407191465,-0.06541917109329465,-2.8681051941150635
430.40000000000543,48.28854363269906,-0.06432782871991405,-2.871993427101823
431.6000000000054,48.406269116558164,-0.06376975430328713,-2.874728503467606
432.8000000000054,48.524236720629375,-0.062043636916339295,-2.8761058897252427
434.00000000000546,48.64251858949868,-0.06076180723481839,-2.8799627144995092
435.2000000000055,48.75982570776614,-0.060637548548214404,-2.881331158834811
436.4000000000055,48.878167911292984,-0.061161378600876726,-2.885621439010305
437.6000000000055,48.99504025789488,-0.06168250048445845,-2.889270950154904
438.8000000000055,49.113257912641046,-0.060317963884278014,-2.8905639753701178
440.00000000000557,49.231558850993416,-0.05914711429613345,-2.8922505093436266
441.20000000000556,49.3484377298206,-0.05790703258767249,-2.895279285151868
442.40000000000555,49.46623339134122,-0.05819857502223591,-2.8979435132664886
443.6000000000056,49.58423629778618,-0.050969913126031274,-2.9005270569017982
444.80000000000564,49.70120544701367,-0.04996925235198618,-2.901868934513901
446.0000000000056,49.819070319453346,-0.049434638103962925,-2.9044864207563634
447.2000000000056,49.93708671111026,-0.04969507788367661,-2.906453780002172
448.40000000000566,50.053272110834634,-0.04692307028872572,-2.9098372032100883
449.6000000000057,50.17264327244612,-0.046800900460306216,-2.911773615520387
450.8000000000057,50.29061782094013,-0.04799566327452176,-2.9143481112391716
452.0000000000057,50.408122343398624,-0.043335346860897905,-2.91494018890438
453.20000000000573,50.526443407331996,-0.04401449722037265,-2.919376560099036
454.4000000000058,50.64499915982017,-0.045302691021739006,-2.9195453407709473
455.60000000000576,50.76329277263808,-0.045394512369671014,-2.922613465248104
456.80000000000575,50.882020391579985,-0.04376812061397933,-2.924879992496914
458.0000000000058,51.001118391395096,-0.04527970983093199,-2.9268267225595874
459.20000000000584,51.11896480190621,-0.041062522248377975,-2.928179525523886
460.40000000000583,51.23823506349598,-0.04210492568526769,-2.9308099123540368
461.6000000000058,51.35738127333557,-0.03937702519963321,-2.933466413281036
462.80000000000587,51.475951825535596,-0.040490780562502104,-2.9348160827194647
464.0000000000059,51.593752939652084,-0.03832557220270005,-2.9361012481577724
465.2000000000059,51.71276312413762,-0.04029277604576953,-2.9381322687656963
466.4000000000059,51.83194845677478,-0.03742087769802416,-2.942876776683688
467.60000000000593,51.950661106053616,-0.03345552234003524,-2.9440727744807327
468.800000000006,52.06906960950876,-0.031666173761988436,-2.9454282564166085
470.00000000000597,52.186698643448324,-0.03393983615080631,-2.9473669295571727
471.20000000000596,52.30623923657998,-0.03160653619577658,-2.949096965104025
472.400000000006,52.424481763039445,-0.031053489828675507,-2.9500130507047526
473.60000000000605,52.5421387509533,-0.02986768023926689,-2.952628318965929
474.80000000000604,52.660853499886045,-0.027254602091688174,-2.9536784778346803
476.000000000006,52.77852810226972,-0.02757501667094009,-2.955193721381226
477.20000000000607,52.897285309556715,-0.02425202474303445,-2.9569217848627645
478.4000000000061,53.014133447845246,-0.021329974525016282,-2.9580710228408966
479.6000000000061,53.132782992805076,-0.01743008732522089,-2.960506859410867
480.8000000000061,53.251966160673575,-0.0165379692600347,-2.962176076150058
482.00000000000614,53.369963295515134,-0.01281623078297589,-2.963506849534752
483.2000000000062,53.48742876212388,-0.00926266746472304,-2.9647713115571834
484.4000000000062,53.6064183952689,-0.011996611624066178,-2.9671445232179963
485.60000000000616,53.725444901430365,-0.007870235709394158,-2.9683916028195814
486.8000000000062,53.84434593020806,-0.00463880033545816,-2.9697385686484115
488.00000000000625,53.961239249615,-0.000967657253667098,-2.971070463647486
489.20000000000624,54.07972036493145,-0.0014885458276550079,-2.972381395170056
490.40000000000623,54.197931728224084,-0.0004260192869335322,-2.973627755208214
491.6000000000063,54.316667743125784,0.0008576888329631105,-2.974350439537042
492.8000000000063,54.43574144439765,0.0077256183354939,-2.976823680837203
494.0000000000063,54.55426847772487,0.00829019550059229,-2.9791757227801288
495.2000000000063,54.67214066470254,0.00932562287391292,-2.979619645300432
496.40000000000634,54.79009067435193,0.013424898339118863,-2.9809229914829487
497.6000000000064,54.90832606411095,0.013273934544939192,-2.9815896388834107
498.8000000000064,55.02788036113268,0.010866656819210174,-2.980803211623017
500.00000000000637,55.1456153179325,0.013430823862693897,-2.9844915333010733
501.2000000000064,55.26420078915045,0.01695217806764049,-2.985992730942879
502.40000000000646,55.382685497257285,0.012904170548686422,-2.9872997784471185
503.60000000000645,55.501986598557465,0.01444509463787591,-2.986397108258929
504.80000000000643,55.620363139651964,0.013146099092714136,-2.9899321622314714
506.0000000000065,55.73957626147113,0.014277243684258978,-2.990383112362771
507.2000000000065,55.85718827255747,0.015018696907050044,-2.9912455553171102
508.4000000000065,55.976584868477985,0.014853137790803439,-2.9938735079755046
509.6000000000065,56.09580353497382,0.017825211332991087,-2.995101335640797
510.80000000000655,56.21366741117149,0.014417846781685895,-2.996510091771021
512.0000000000066,56.332944667658275,0.015887613207407947,-2.997829915769726
513.2000000000066,56.45311473624412,0.016160975479336037,-2.9978280221372184
514.4000000000066,56.57211210849015,0.012976175668674483,-2.9994643994973695
515.6000000000066,56.69021146179399,0.008640859038680837,-2.999030739474688
516.8000000000067,56.81146558672818,0.009573780048610536,-2.9990457457954367
518.0000000000066,56.93110867531083,0.005576583264811696,-3.001669915941625
519.2000000000066,57.05034307826009,0.0018115320141547375,-3.0029919884920417
520.4000000000067,57.16958368142169,-0.008052053502236034,-3.0043222827170144
521.6000000000067,57.28927360468426,-0.011926711692253789,-3.0069302372445916
522.8000000000068,57.40936362324095,-0.02095994488204478,-3.0082383985547447
524.0000000000067,57.52698632745077,-0.025515316153821743,-3.0082986990572493
525.2000000000068,57.64761011953233,-0.026762026814192263,-3.0088752705889616
526.4000000000068,57.766039487406445,-0.03031418295967825,-3.009567449136889
527.6000000000067,57.88576406985816,-0.035522263459522474,-3.0106000660172887
528.8000000000068,58.00452155175218,-0.03649252580480178,-3.0115395214523617
530.0000000000068,58.12426498858099,-0.03645716369344898,-3.012857898908484
531.2000000000069,58.24351904163835,-0.03956175559384234,-3.012133611070986
532.4000000000069,58.36248011834423,-0.03796157011393575,-3.0154719245682173
533.6000000000068,58.482289250818,-0.03894263678422316,-3.0171042887903443
534.8000000000069,58.600742657702305,-0.041643203158883924,-3.016208513807171
536.0000000000069,58.71674190550539,-0.041951626493623495,-3.0171299021774
537.2000000000069,58.83815490864272,-0.046906197189254484,-3.01845216489016
538.4000000000069,58.959065437935024,-0.047333420666836545,-3.020658272593903
539.600000000007,59.0770004608988,-0.04337396976748398,-3.019760179838014
540.800000000007,59.19675042380975,-0.04956663534587058,-3.021090522017645
542.000000000007,59.31538270322338,-0.051265010555488155,-3.0223999889229844
543.200000000007,59.43533640513323,-0.05433980473592792,-3.0233806807681445
544.400000000007,59.55435145701053,-0.054546454398234356,-3.023369932603553
545.6000000000071,59.67348186666965,-0.0548969310652756,-3.0252497734798194
546.800000000007,59.79310397828489,-0.05545065653808723,-3.026568785912933
548.000000000007,59.91265134804473,-0.056719632856669144,-3.029206469982352
549.2000000000071,60.03249622915682,-0.05743050175254216,-3.028173358051078
550.4000000000071,60.15157847949723,-0.05836479030873609,-3.0298496170219447
551.6000000000072,60.27130703343757,-0.05628875838065395,-3.0311698088519106
552.8000000000071,60.39025409349402,-0.05670858136620682,-3.0311698122620316
554.0000000000072,60.51096937813423,-0.05594824660528197,-3.0329785050627494
555.2000000000072,60.63036751808804,-0.059650392499703164,-3.0337998197950466
556.4000000000071,60.7466750434425,-0.060639601851141256,-3.035119849902597
557.6000000000072,60.86878646667837,-0.06337182039701361,-3.0371572731800063
558.8000000000072,60.98898182148125,-0.06459373312054784,-3.038126754287532
560.0000000000073,61.108682587782866,-0.07162561463137274,-3.0394140215177434
561.2000000000073,61.22762505102869,-0.06753385861483319,-3.0393636782158273
562.4000000000073,61.34801440223363,-0.07039382691263196,-3.039399640954027
563.6000000000073,61.46669222718762,-0.07129697672013768,-3.0393999836503784
564.8000000000073,61.587076156477806,-0.073192560389166,-3.041681422837362
566.0000000000073,61.70617468860075,-0.07125658338005636,-3.0430189709634394
567.2000000000073,61.82631590713128,-0.07531939128595966,-3.0443301108306144
568.4000000000074,61.945883095578345,-0.0754624798379625,-3.0430199370849906
569.6000000000074,62.065972012271004,-0.0740507205860893,-3.044450639728298
570.8000000000075,62.18507058795086,-0.07532214103037438,-3.045613367954151
572.0000000000074,62.305662256454085,-0.07738403147607764,-3.0479459815940175
573.2000000000074,62.42526408482781,-0.0789427597067196,-3.0479501840005825
574.4000000000075,62.545273646450894,-0.07995352804842415,-3.0479490298453866
575.6000000000074,62.66428881017088,-0.08074387648607884,-3.0490097867920753
576.8000000000075,62.78388256081764,-0.08200965167357366,-3.049209469287718
578.0000000000075,62.90375982420583,-0.08212023160000015,-3.050651776786782
579.2000000000075,63.023538370420255,-0.08111865045704536,-3.0531978282868897
580.4000000000076,63.144357634605065,-0.08025836805359132,-3.053220119997021
581.6000000000075,63.2647172437008,-0.08362495431149386,-3.0532201199999958
582.8000000000076,63.384716878470925,-0.08521780922385391,-3.0532200846227457
584.0000000000076,63.50345262696985,-0.08349388325512619,-3.0545398616875294
585.2000000000075,63.62341122746356,-0.08424380951667643,-3.0545399879999815
586.4000000000076,63.74461244103095,-0.08730939644316571,-3.054539988567038
587.6000000000076,63.86455437838385,-0.08557526319430886,-3.05585970151732
588.8000000000077,63.985214259803335,-0.08686513120763495,-3.054608831181154
590.0000000000077,64.10534414478865,-0.0847273031517034,-3.0571523076553975
591.2000000000077,64.22461139224792,-0.0858922259786914,-3.058374858592984
592.4000000000077,64.34472957767677,-0.08471700981554942,-3.0574983296783165
593.6000000000078,64.46489281713731,-0.08431476346110045,-3.059783587669945
594.8000000000077,64.58467717666294,-0.08594790305405942,-3.0601300569578163
596.0000000000077,64.70488168751766,-0.08756910112898608,-3.059943990618051
597.2000000000078,64.82481694403639,-0.08984471879397415,-3.0608009668291967
598.4000000000078,64.94464049293236,-0.09027217041552305,-3.0624943044775508
599.6000000000079,65.06474797652346,-0.08648582598137067,-3.062758598090052
600.8000000000078,65.18497812412704,-0.08728362139565626,-3.065276610176735
602.0000000000078,65.30447391832539,-0.08668139688689147,-3.0639701233212397
603.2000000000079,65.42604783241698,-0.08427485820545133,-3.063970155999985
604.4000000000078,65.54484595999904,-0.08688535089245275,-3.0639699194091947
605.6000000000079,65.66555491727821,-0.08663499432992505,-3.0652812148969426
606.8000000000079,65.78551402209825,-0.08868431604313298,-3.063982730143593
608.000000000008,65.90509083739414,-0.08446949667664394,-3.065876460830927
609.200000000008,66.02598120000462,-0.08402713938712136,-3.0665992007681364
610.4000000000079,66.14638314677484,-0.08484640646740382,-3.0692002920375137
611.600000000008,66.26577517427863,-0.08486613148763944,-3.0718813088853416
612.800000000008,66.38633426770016,-0.08291827065551627,-3.070550091982093
614.000000000008,66.50612403769351,-0.08233007736445452,-3.0705500981570153
615.200000000008,66.62735816653378,-0.08362793297537352,-3.0695795311957434
616.400000000008,66.74712918604044,-0.07454231801683275,-3.070794083804879
617.6000000000081,66.86801203130679,-0.07573835326044964,-3.0721899279965874
618.8000000000081,66.98896341781219,-0.07809967485250247,-3.0721894978425506
620.0000000000081,67.10888037068563,-0.07889884592661267,-3.074820182892019
621.2000000000081,67.22559435427083,-0.07987731367155337,-3.07482014393643
622.4000000000082,67.3485610883105,-0.07778837874135158,-3.076588748924186
623.6000000000081,67.46887367800105,-0.07741355546396766,-3.0751601390896868
624.8000000000081,67.58803024909197,-0.07875180435208495,-3.075381476028606
626.0000000000082,67.70944483450678,-0.07668899715977484,-3.075153797682062
627.2000000000082,67.82965618237736,-0.07724368235131784,-3.077789857073918
628.4000000000083,67.95019920274181,-0.07855525699337451,-3.0781905312850566
629.6000000000082,68.07104995962783,-0.07783291253428981,-3.0787858146961056
630.8000000000083,68.19156177358512,-0.07926876800711513,-3.0777817609914506
632.0000000000083,68.31106105294533,-0.08009551807040616,-3.080138770766572
633.2000000000082,68.4319255637644,-0.08171017115040646,-3.080210865970673
634.4000000000083,68.5520381408012,-0.07896844894926347,-3.0800512204508976
635.6000000000083,68.67239794749624,-0.0802334365797881,-3.0815607338294537
636.8000000000084,68.79284977723475,-0.0780394576875072,-3.0826722483243048
638.0000000000084,68.91351636172001,-0.079934142678594,-3.0830559153243993
639.2000000000083,69.03327221325554,-0.07861151542864486,-3.0821253041688896
640.4000000000084,69.15415517308108,-0.07888351687684292,-3.0843696962707665
641.6000000000084,69.27574540761236,-0.08417584675960232,-3.0837186220882193
642.8000000000084,69.3962408682079,-0.08523481479161732,-3.084131676934752
644.0000000000084,69.51720405367132,-0.08333597307838336,-3.0850300640337447
645.2000000000085,69.6380913046678,-0.08669778841849651,-3.0850233215096092
646.4000000000085,69.76024682789784,-0.0824223048411814,-3.0863397708860276
647.6000000000085,69.87957072257615,-0.0845615999522753,-3.086340177985493
648.8000000000085,70.00065795245978,-0.08686456038023316,-3.0863393498365985
650.0000000000085,70.12141692372968,-0.08744704843870621,-3.0876584782348195
651.2000000000086,70.2412240669183,-0.0904706556182513,-3.0868726406133504
652.4000000000085,70.36196142040248,-0.09480858032671668,-3.0863442373337167
653.6000000000085,70.48346866210436,-0.09582107550953789,-3.0876878774197802
654.8000000000086,70.60377374367886,-0.09430694429446818,-3.088913469516063
656.0000000000086,70.7247644889437,-0.09503810158507142,-3.090009918841175
657.2000000000087,70.84556317546988,-0.09594862314822494,-3.0893000270787763
658.4000000000086,70.96633726813661,-0.1013396137443483,-3.0886842135792403
659.6000000000087,71.08694404794515,-0.09897080796787883,-3.0893097569680545
660.8000000000087,71.20754672887747,-0.1008381254195101,-3.090289868749694
662.0000000000086,71.32853234291728,-0.09817208459175131,-3.0915940736239156
663.2000000000087,71.44865534955144,-0.10063566626907705,-3.091607648021581
664.4000000000087,71.56842977003004,-0.1033725262245293,-3.0916100999993965
665.6000000000088,71.68777876240638,-0.10451748811473438,-3.091609687200228
666.8000000000088,71.80858385114182,-0.10360279311484089,-3.0929472080237206
668.0000000000088,71.92917000000088,-0.10556438919706257,-3.094572806699506
669.2000000000088,72.04982330450248,-0.10775589328239699,-3.094569936000748
670.4000000000088,72.16967297037623,-0.10949727894328776,-3.0945722344422646
671.6000000000088,72.2897826410105,-0.11085129936634908,-3.095889754916744
672.8000000000088,72.41036504098207,-0.11329762437795576,-3.09431214313646
674.0000000000089,72.53044267756702,-0.11269940031975278,-3.09555112101752
675.2000000000089,72.65134689332297,-0.11623437691462746,-3.095560068420112
676.400000000009,72.77319909319493,-0.1153113167917661,-3.0957740268172347
677.6000000000089,72.89456525826908,-0.11924927732018986,-3.0961772956209694
678.8000000000089,73.01582746778976,-0.12035690636390428,-3.0962629966614332
680.000000000009,73.13697362467717,-0.12099659203376523,-3.0974201740240725
681.2000000000089,73.25723552086535,-0.12434967508700323,-3.0997300994999195
682.400000000009,73.3783557849949,-0.12428245158096174,-3.0997327633404526
683.600000000009,73.50055400878156,-0.12701048531830805,-3.0987653530379546
684.800000000009,73.62228928123666,-0.12788614149123156,-3.1007089053732995
686.0000000000091,73.74251350083306,-0.127942458042285,-3.100772526097986
687.200000000009,73.8638051131915,-0.13092335963424473,-3.100710048008118
688.4000000000091,73.98517360588892,-0.13343449745744573,-3.1007101684428404
689.6000000000091,74.10664361887761,-0.1365577276804384,-3.101825392960804
690.800000000009,74.22766659738917,-0.13673297625708103,-3.1036699367703964
692.0000000000091,74.34856646129911,-0.13879459923958337,-3.1042037364473853
693.2000000000091,74.4697165513868,-0.1404181460715046,-3.1022175463818336
694.4000000000092,74.59005494769143,-0.14328729099819748,-3.101027603338809
695.6000000000092,74.71182415065142,-0.14506836079743057,-3.1023206483772845
696.8000000000092,74.8334702788552,-0.14447684388020354,-3.103670015681333
698.0000000000092,74.9546746050268,-0.15010310308302444,-3.103669943246791
699.2000000000093,75.07622416101067,-0.15228946613402528,-3.1040099038225097
700.4000000000092,75.1969785781435,-0.15746391507258428,-3.1040067903450757
701.6000000000092,75.31878549111244,-0.15856601012277127,-3.105319072602724
702.8000000000093,75.43937378010698,-0.16314751640356273,-3.106634404396579
704.0000000000093,75.56070005606675,-0.16308664800989958,-3.1052734970283775
705.2000000000094,75.68089388758827,-0.16504469664289112,-3.1062000260538554
706.4000000000093,75.80247899533305,-0.16466436639494075,-3.1042452328489865
707.6000000000093,75.9236280817676,-0.17218878804363213,-3.1042150817542407
708.8000000000094,76.04504493683011,-0.17243443165989358,-3.1062001764985823
710.0000000000093,76.16623804802805,-0.17149183310645788,-3.106200159812423
711.2000000000094,76.28595110824136,-0.17426339084073805,-3.10750364753937
712.4000000000094,76.40716446263666,-0.17512129682398614,-3.1063390373715185
713.6000000000095,76.52787934513313,-0.18202028514424073,-3.1052098956184557
714.8000000000095,76.64794414272585,-0.18030873776274636,-3.106520126273364
716.0000000000094,76.77047354111997,-0.18403354000295513,-3.1078395332521134
717.2000000000095,76.89121352975661,-0.18585530289225938,-3.10783999618022
718.4000000000095,77.01215902976404,-0.18567906219573338,-3.10882368424324
719.6000000000095,77.1341176592783,-0.1887099496785245,-3.109195515779993
720.8000000000095,77.25467830339295,-0.19324536953220806,-3.108829901615627
722.0000000000095,77.3764371499373,-0.1914762301408679,-3.107239359629929
723.2000000000096,77.49741094304227,-0.19508864717596852,-3.110139830078072
724.4000000000096,77.61936183029792,-0.19965359357109635,-3.1101398319999998
725.6000000000096,77.74132429496906,-0.20058867091537236,-3.1101398320038736
726.8000000000096,77.86232295226164,-0.20414155101924147,-3.110177316548725
728.0000000000097,77.98506720619234,-0.20389908225821496,-3.1104097769064643
729.2000000000096,78.1067361315032,-0.21004207732428526,-3.1108000959364834
730.4000000000096,78.22863347172601,-0.209581267886374,-3.1103204054816223
731.6000000000097,78.35030433368749,-0.20967726469014214,-3.1114688591404436
732.8000000000097,78.47141331853766,-0.21075988049657712,-3.1111017157194203
734.0000000000098,78.59281896100025,-0.21527048293280537,-3.111789741820161
735.2000000000097,78.7139577002588,-0.21760539247540045,-3.1105059928326693
736.4000000000098,78.83602061311237,-0.21683167025125027,-3.1131135786835826
737.6000000000098,78.95743333304539,-0.21959193452114434,-3.1121198519567956
738.8000000000097,79.07875853562376,-0.21987765383806912,-3.1121199323795405
740.0000000000098,79.19960111306825,-0.22523582451406354,-3.113109399361547
741.2000000000098,79.32143916435744,-0.22341040770821152,-3.1142012765803253
742.4000000000099,79.44240126363705,-0.22678998811530926,-3.113440208856802
743.6000000000099,79.56481185284807,-0.23048039220333938,-3.1127734585527853
744.8000000000098,79.68651181912745,-0.2322006783797621,-3.1128838033813375
746.0000000000099,79.80619477829435,-0.2337115208216245,-3.1147497719565544
747.2000000000099,79.92711463733343,-0.23343463931325292,-3.1140754095627763
748.4000000000099,80.0496366546833,-0.23351230888422037,-3.113767227240538
749.6000000000099,80.17049257130726,-0.23700453877614058,-3.113770163998831
750.80000000001,80.29217857422431,-0.23849650307197856,-3.11376427063562
752.00000000001,80.41404697688031,-0.23664122029527856,-3.114091615150076
753.20000000001,80.53477772650004,-0.2420373569278902,-3.1154101294941494
754.40000000001,80.6561353312875,-0.2392216709203041,-3.117913689522066
755.60000000001,80.77804767446254,-0.23844109446771156,-3.1180682774702753
756.8000000000101,80.89938702504502,-0.24319117308932503,-3.118047678579741
758.00000000001,81.02080329050453,-0.24427097857427316,-3.1170598678763923
759.20000000001,81.1433245722341,-0.2445356118116051,-3.1177979558109485
760.4000000000101,81.26481112328777,-0.24792850009937406,-3.118439517557197
761.6000000000101,81.38701372058404,-0.24976528720153834,-3.1183699544029313
762.8000000000102,81.50819263641061,-0.2508000842926539,-3.118369836000019
764.0000000000101,81.63024702971617,-0.2569615230854534,-3.118369829431627
765.2000000000102,81.75211060322569,-0.25793003082298394,-3.119689951279721
766.4000000000102,81.87392711161175,-0.2576159840499741,-3.12200269303718
767.6000000000101,81.99580633510087,-0.2577895024547576,-3.1206421494655547
768.8000000000102,82.11731966975209,-0.26110836221053013,-3.120018923887624
770.0000000000102,82.23917000000105,-0.26434121525985654,-3.1185957994674833
771.2000000000103,82.36119021232808,-0.2652548171039928,-3.1217704841254506
772.4000000000103,82.48249497912973,-0.2641186908149127,-3.1217700240002335
773.6000000000103,82.60463566121092,-0.26553372622717863,-3.1217719975089695
774.8000000000103,82.7266008210277,-0.27192881409378056,-3.1227600177388686
776.0000000000103,82.84786695966645,-0.26798465327903354,-3.1214386566874657
777.2000000000103,82.96980950130505,-0.2686995533988543,-3.1220684865222417
778.4000000000103,83.09246124575444,-0.2705073348679241,-3.1224298462000775
779.6000000000104,83.21421439749082,-0.27225689790191865,-3.123737872867302
780.8000000000104,83.33673074043358,-0.27166511989258213,-3.123739862670525
782.0000000000105,83.45888004031447,-0.2752462589774367,-3.1224300737734163
783.2000000000104,83.5810562155505,-0.2733384412688098,-3.122429743577207
784.4000000000104,83.70383152514958,-0.27741787005702156,-3.1237500646723397
785.6000000000105,83.82498664866034,-0.2769076190277451,-3.123750123999987
786.8000000000104,83.94803918607079,-0.27279081154150076,-3.123750107079329
788.0000000000105,84.06992938451582,-0.282996100615341,-3.125070014310376
789.2000000000105,84.19213455373378,-0.2813194141650963,-3.1241857807195474
790.4000000000106,84.31368017059896,-0.2836147828889355,-3.1240799920045355
791.6000000000106,84.43587994212403,-0.2817615654361796,-3.1240799919996216
792.8000000000105,84.55683631756554,-0.2837650797339608,-3.1240767818245563
794.0000000000106,84.67989848238528,-0.2856456931914473,-3.125389983728921
795.2000000000106,84.8013114156861,-0.28821057394827765,-3.126709803936238
796.4000000000106,84.92368490650253,-0.2915638631025077,-3.126379852907352
797.0000000000106,84.98491692312541,-0.29102683885326375,-3.12507388534617