File: 01_Data/Polyester_Carpet_High_Pile/STA/N2/3K_min/Polyester_Carpet_High_Pile_STA_N2_3KData_230926_R1.csv
##Temp./Â°C,Time/min,DSC/(mW/mg),Mass loss/mg
51.0,11.367182290667824,0.016699422801556896,-0.03133303221864914
52.100000000000016,11.879842545068906,0.02556092535492871,-0.031279874293415055
53.20000000000003,12.323761086106677,0.0312862817557491,-0.032599880323017416
54.30000000000005,12.770256998280797,0.0327261208880798,-0.03383172959943881
55.40000000000006,13.16833456779646,0.037557926440341394,-0.03257217743888141
56.50000000000008,13.585538600414857,0.03471887099722881,-0.03364480893005428
57.600000000000094,13.977356834732065,0.04038298391899131,-0.035230027418267085
58.70000000000011,14.361922742997416,0.03926264544407321,-0.03655197609248351
59.800000000000125,14.743838651411663,0.03962836384596091,-0.0351900946018846
60.90000000000014,15.12604775387648,0.04119040253450024,-0.037868839788508524
62.000000000000156,15.505246088439863,0.0411550533647449,-0.03814228053141466
63.10000000000017,15.873679488565088,0.04187312264175347,-0.038200336218712216
64.20000000000019,16.251098878673442,0.04155185375231829,-0.03918986926303791
65.30000000000021,16.620727837466557,0.04270862941189213,-0.03918998888977221
66.40000000000022,16.99297053411224,0.042472110329791146,-0.03920503247023621
67.50000000000023,17.360858851586528,0.04156424428582817,-0.0401766541903239
68.60000000000025,17.726487596006727,0.042364515015099524,-0.04084009959770629
69.70000000000027,18.09587669237948,0.042630461979365375,-0.04049986501290359
70.80000000000028,18.46139150668537,0.0439194492954198,-0.04182995511863119
71.90000000000029,18.831665769724523,0.04511911429490256,-0.04084019624715385
73.00000000000031,19.179934503484226,0.04095905829609103,-0.045548620476017376
74.10000000000034,19.56382338253244,0.04131624408126422,-0.04239311281347202
75.20000000000034,19.92738119241737,0.04260112572565111,-0.043689145980084554
76.30000000000035,20.299170000000128,0.03857123622327174,-0.04276961730730022
77.40000000000038,20.669170000000154,0.04089577951400836,-0.04369019999556034
78.5000000000004,21.030950266495584,0.038044900374488044,-0.04468005031651234
79.6000000000004,21.394958936729562,0.03748234881371326,-0.04466951761425708
80.70000000000041,21.759410525111935,0.03596732440356698,-0.04532998906419561
81.80000000000044,22.124236053357397,0.04035660585332712,-0.04500103253780807
82.90000000000046,22.490093877971766,0.0382769631559734,-0.04435000547311141
84.00000000000047,22.85824228069402,0.03694491140540679,-0.04664944709036423
85.10000000000048,23.222731961135825,0.03655138773957933,-0.045330302252654775
86.2000000000005,23.584894917426865,0.036600586952742376,-0.04632014499985093
87.30000000000052,23.946052826407062,0.03629166215944002,-0.046454135095792104
88.40000000000053,24.30984778650859,0.033981296022203455,-0.04732738965386485
89.50000000000054,24.67687829120608,0.03497126829495478,-0.04846781837356051
90.60000000000056,25.039170000000077,0.03364259259259228,-0.048299924999999355
91.70000000000059,25.40165501968978,0.040028407433299495,-0.04908040103682065
92.8000000000006,25.770411534298052,0.03196693293813091,-0.04759426675570655
93.9000000000006,26.136140863842186,0.033605929275877244,-0.049189521438194994
95.00000000000063,26.489507152034385,0.033871389519986916,-0.04806691417606501
96.10000000000065,26.85783805370344,0.03567970126491282,-0.04851998151603887
97.20000000000066,27.223509061329608,0.036598873933948006,-0.04950955721454697
98.30000000000067,27.57831684607284,0.03597723195309266,-0.05114999136400922
99.40000000000069,27.954714715833628,0.03462382043672507,-0.04983981437405394
100.50000000000071,28.310930933250248,0.0354581613583318,-0.04981998361531126
101.60000000000072,28.670769051163372,0.03618651265000539,-0.05297284351308651
102.70000000000073,29.035320198114746,0.03551745016159291,-0.04885372775312202
103.80000000000075,29.396951906234786,0.03584659655147293,-0.0487652900089488
104.90000000000077,29.761133113973365,0.03748963136218464,-0.05116854337912047
106.00000000000078,30.122737707231387,0.03689837544154173,-0.049738172183260154
107.10000000000079,30.48406634903222,0.03633516336861309,-0.05280325713454026
108.20000000000081,30.84617095206849,0.0346038832702682,-0.051820060085929764
109.30000000000084,31.20890798031483,0.03354700736084082,-0.05115542350106628
110.40000000000084,31.57023047189738,0.03356557461813381,-0.05017009000431383
111.50000000000085,31.93636410440775,0.0356498189163057,-0.051810014335795795
112.60000000000088,32.292878102394866,0.03548459252066838,-0.05181019498966766
113.7000000000009,32.65793738081031,0.03480839830041349,-0.050829982302059484
114.8000000000009,33.01577856488665,0.03521040871421999,-0.052146073821184746
115.90000000000092,33.373043498785044,0.0334232332606601,-0.051133313791857926
117.00000000000094,33.72263385022982,0.03400239975522057,-0.049834465760722146
118.10000000000096,34.094373096860856,0.03625991810325502,-0.052158361195906444
119.20000000000097,34.45058794585617,0.03496737361597102,-0.05214005804821564
120.30000000000098,34.8163819528366,0.03725586317907181,-0.051788458648368785
121.400000000001,35.17978667428504,0.03376251901301908,-0.05181260217983574
122.50000000000102,35.532716032726455,0.035044282573519325,-0.051933197319479873
123.60000000000103,35.903991796062776,0.03652074078539069,-0.05192989776876411
124.70000000000104,36.263550907844426,0.035947709600288924,-0.05257998318595414
125.80000000000106,36.62368978229836,0.03682698090205694,-0.05591427227470014
126.90000000000109,36.96963001408995,0.03679330265233549,-0.05133566396419642
128.00000000000108,37.33758160015494,0.03532098171142506,-0.0513651753293054
129.1000000000011,37.69728373502156,0.03688151310985033,-0.05268980892142672
130.20000000000113,38.05082076914382,0.036452821661755674,-0.052755868116316496
131.30000000000115,38.41742430941472,0.03893799162073419,-0.05269412153189501
132.40000000000117,38.778761640021024,0.03726419480620313,-0.053350117551083986
133.50000000000117,39.138259523459304,0.037322747540051715,-0.054330968347231945
134.6000000000012,39.48877723602177,0.03436453343714696,-0.054662451489284614
135.7000000000012,39.85172039165049,0.03510638528155585,-0.05335132948009935
136.8000000000012,40.21023715184438,0.033472025899668356,-0.05334928054712096
137.90000000000123,40.56716371148779,0.032312043251496725,-0.052359880340810516
139.00000000000125,40.92393087072649,0.035295379462437104,-0.053681413614771856
140.10000000000127,41.287451141478805,0.03461057475726248,-0.05203051434118322
141.2000000000013,41.644601866686415,0.03362078660647283,-0.0540098778651692
142.3000000000013,42.00488264129364,0.0353467282257478,-0.05302066741246758
143.4000000000013,42.365510013490194,0.03514069129251496,-0.053665468560415874
144.50000000000134,42.71846726779194,0.03857618504518756,-0.054989880861432194
145.60000000000133,43.079903305272694,0.03641801425764113,-0.05498988006783989
146.70000000000135,43.43816464430275,0.03364998172730482,-0.0553199988818478
147.80000000000138,43.789813380988974,0.03502218445652483,-0.054336953617224015
148.9000000000014,44.15374947467322,0.03634059175728055,-0.055654979502441915
150.00000000000142,44.51247880824746,0.03983844577215434,-0.05766171680533905
151.10000000000142,44.86788361911592,0.0387670774299278,-0.05632012333781633
152.20000000000144,45.22941678852943,0.03974726341750934,-0.05499981001813259
153.30000000000146,45.583276643817726,0.03935103059643996,-0.055989838823796045
154.40000000000146,45.94324078921766,0.04008589748353408,-0.05631988502314256
155.50000000000148,46.29835612087399,0.04089985114317729,-0.056644176705217486
156.6000000000015,46.653420780242485,0.04517655604604265,-0.05538006179411292
157.70000000000152,47.01126960452639,0.04423465537524063,-0.0546698394458871
158.80000000000155,47.362120320495855,0.04794475531792397,-0.055080313684507054
159.90000000000154,47.72728236299848,0.04848622730694929,-0.05597967706789042
161.00000000000156,48.08341685454559,0.051060794897070494,-0.055302925790752244
162.1000000000016,48.43724189573196,0.05572935212674368,-0.055559454645964124
163.20000000000158,48.79599078976144,0.06013276790543465,-0.05566006999996498
164.3000000000016,49.15705287986388,0.06132148860307307,-0.05631872960534423
165.40000000000163,49.511035552801886,0.06663593825330771,-0.0563199194750994
166.50000000000165,49.872520333489454,0.0665624328337775,-0.05563114616363363
167.60000000000167,50.227598797957484,0.06671241497693892,-0.05664982366763294
168.70000000000167,50.57740730136865,0.0627291330326396,-0.056005589742119
169.8000000000017,50.93713349792976,0.05534511399912745,-0.055989951643116154
170.9000000000017,51.294007331826066,0.04805703368464487,-0.05663819157056693
172.0000000000017,51.64956225171121,0.04471422716226092,-0.05598987504454289
173.10000000000173,52.00158175536893,0.03931015441741881,-0.054669704709386924
174.20000000000175,52.3575505516957,0.038639366205341474,-0.05533236127978691
175.30000000000177,52.71551378850705,0.03903988197050845,-0.05433977196761619
176.4000000000018,53.078203991984154,0.034665877100393594,-0.0553098215361536
177.5000000000018,53.42681000813404,0.03749947666437681,-0.055649904868700695
178.6000000000018,53.78640579811073,0.03846681834682997,-0.05655622688731787
179.70000000000184,54.14358797569299,0.03782677040729343,-0.05696990495787446
180.80000000000183,54.499170000000696,0.03625253137220685,-0.054999805087125875
181.90000000000185,54.85656314555866,0.03895721377748895,-0.05564982998548906
183.00000000000188,55.21025658130892,0.039218015427067154,-0.056970661530002076
184.1000000000019,55.56787562407771,0.03917284403681753,-0.05558316891484827
185.20000000000192,55.924789755856246,0.041141663709924,-0.05762433121105426
186.30000000000192,56.280960081161695,0.040150982551832914,-0.055330163651533315
187.40000000000194,56.63767931909739,0.039739783945688334,-0.056975504417307477
188.50000000000196,56.996774851034274,0.040579770636329116,-0.05565929442202844
189.60000000000196,57.346201399737005,0.040025556087083025,-0.054065557441895784
190.70000000000198,57.70768928608642,0.04097270974709,-0.05632013499999644
191.800000000002,58.0642046804534,0.0437093840843783,-0.05632013489434806
192.90000000000202,58.42012924526086,0.04220067540407646,-0.05599006000000051
194.00000000000205,58.77544459254513,0.04261428387660482,-0.05598889584588029
195.10000000000204,59.13226676085725,0.04198432839690369,-0.056001726449056655
196.20000000000206,59.48429043547203,0.04182713642709368,-0.056320058769463
197.3000000000021,59.84446971436902,0.04323022119719244,-0.0552829226677356
198.40000000000208,60.19990260180496,0.03983843462084291,-0.0546698204663425
199.5000000000021,60.5563192050065,0.04187594817458118,-0.057310129237140295
200.60000000000213,60.91236363324625,0.03802170947558947,-0.05565849118606403
201.70000000000215,61.269170000000805,0.04043319880709273,-0.055329834999969574
202.80000000000217,61.62557315453789,0.04123040430969516,-0.05769519010945334
203.90000000000217,61.98458627072191,0.040425692600339236,-0.05500018855373057
205.0000000000022,62.342723750359085,0.04089198985366993,-0.05631754935205313
206.1000000000022,62.69816419678692,0.038783701798643655,-0.055000898795348085
207.2000000000022,63.051380729340245,0.037481718882261816,-0.053406496482399035
208.30000000000223,63.415724090297736,0.035244356343958394,-0.05477790605177191
209.40000000000225,63.76690618682806,0.03809234294341657,-0.057409909988295205
210.50000000000227,64.12481905318948,0.039238570423105745,-0.0583281953239525
211.6000000000023,64.47971475987111,0.040531401314725546,-0.055990090087445044
212.7000000000023,64.83520066159359,0.039695380307570804,-0.05729863679913905
213.8000000000023,65.19225122433978,0.0382954456793243,-0.05662489303223639
214.90000000000234,65.54814777211601,0.0381648233114138,-0.05664000887210152
216.00000000000233,65.90322903897855,0.03761103347202521,-0.05795990999999967
217.10000000000235,66.25678230878064,0.039886179347667916,-0.0566606918131356
218.20000000000238,66.61277849106632,0.036605954698389453,-0.05716624535599113
219.3000000000024,66.96786512573391,0.03665913874764115,-0.05861991522662846
220.40000000000242,67.32356393972894,0.037013053357147996,-0.05760518418153726
221.50000000000242,67.68234452130328,0.03880078563634992,-0.05814424557289266
222.60000000000244,68.03356025836023,0.0405918398177505,-0.058950059985472425
223.70000000000246,68.38992689709924,0.041340791839051594,-0.05798957379735059
224.80000000000246,68.74155641782735,0.04310225842149107,-0.05993998505731568
225.90000000000248,69.10643431072945,0.04165292934441833,-0.059391443214644735
227.0000000000025,69.46024753230732,0.0422679638893686,-0.05928013500383811
228.10000000000252,69.8156931595532,0.03990211013908418,-0.05961020987459209
229.20000000000255,70.17277701436852,0.040490577967952746,-0.05939012536702171
230.30000000000254,70.52563756668994,0.04239227213628194,-0.059390128820245636
231.40000000000256,70.88548000180185,0.044085859752707623,-0.06004998073583767
232.5000000000026,71.23772010075945,0.04418563013207333,-0.06004987870202383
233.60000000000258,71.59681808615566,0.045827960925088895,-0.06239282130907009
234.7000000000026,71.96029729301212,0.04631246923944987,-0.06026358646534735
235.80000000000263,72.3102264037402,0.04761954259730761,-0.06103845793237994
236.90000000000265,72.66717527303337,0.04744850650581878,-0.06105225914560597
238.00000000000267,73.02799134531364,0.050625271223013524,-0.06257265515316623
239.10000000000267,73.38259804712371,0.051414601063083154,-0.06189469013992799
240.2000000000027,73.7408686169974,0.05298145644724217,-0.06157538230601256
241.3000000000027,74.0991700000014,0.0563760508632285,-0.061249978493654655
242.4000000000027,74.45253474901214,0.06005015003312719,-0.06136015092264824
243.50000000000273,74.81108538906979,0.06188687956718519,-0.0618108855192494
244.60000000000275,75.16866994179466,0.07031377191903321,-0.06333992706803615
245.70000000000277,75.52399918199815,0.0756967086796081,-0.060041030101598114
246.8000000000028,75.87760764276386,0.08231672355020692,-0.06301979289975357
247.9000000000028,76.23539837853745,0.09768517330296556,-0.06377956127892359
249.0000000000028,76.59917000000124,0.11539757649368276,-0.06212980878380048
250.10000000000284,76.95613300521913,0.14219859451854155,-0.0634489650958181
251.20000000000283,77.32040337995106,0.15797425815474275,-0.06410986542984043
252.30000000000285,77.67558017232336,0.15242374609257636,-0.06411101887354098
253.40000000000288,78.03063187623115,0.12741305466023967,-0.0651353732120481
254.5000000000029,78.38232659634924,0.10067079672329848,-0.06378058897731975
255.60000000000292,78.73307840831357,0.08261026994128251,-0.06501423110392457
256.7000000000029,79.0832241730337,0.06880182587254957,-0.06480556306572316
257.8000000000029,79.44358610980854,0.060108621022255004,-0.0657600700000005
258.90000000000293,79.80001700350441,0.05296231129808504,-0.06674141436716896
260.00000000000296,80.15569961236463,0.0501474590906148,-0.06696637324620802
261.100000000003,80.51593211594768,0.04541716994136413,-0.06707009499985883
262.200000000003,80.87027785817925,0.04269695025560294,-0.06641009141296061
263.300000000003,81.22407593132742,0.04236630610432135,-0.06718001547882091
264.40000000000305,81.57860222334583,0.040130641214920715,-0.06717991504656773
265.50000000000307,81.93449113701416,0.040794379278236814,-0.0691588714040563
266.6000000000031,82.28731647232767,0.03938777923104242,-0.06920441725947146
267.7000000000031,82.64177967321251,0.0395463039557038,-0.06916005879484644
268.8000000000031,82.99775567163475,0.03801366723847277,-0.06900605638357993
269.9000000000031,83.35712961940386,0.03884194025399568,-0.07342060256868255
271.0000000000031,83.717826514837,0.03589278695717457,-0.06852270189389431
272.10000000000315,84.07272310375737,0.038347655401504976,-0.07212216548450678
273.2000000000032,84.43252014395112,0.03778957922908566,-0.07092001499999778
274.30000000000314,84.81774406674145,0.042788476560876365,-0.07190993087168884
275.40000000000316,85.14781100644416,0.037583035984896096,-0.073548323875539
276.5000000000032,85.50632824821531,0.0406961013853846,-0.07157018989307451
277.6000000000032,85.8668868223429,0.04323641327807115,-0.07333125546501806
278.70000000000323,86.21919852506848,0.03944738245251189,-0.07322247824687
279.80000000000325,86.5684817022649,0.041022796108111326,-0.07289000778960508
280.9000000000033,86.92345058757921,0.04295376639531234,-0.07322835247437842
282.0000000000033,87.28169083902702,0.04329696575249731,-0.0745455899527343
283.1000000000033,87.6393852078801,0.043558459462208265,-0.07486605750045872
284.20000000000334,88.00376349732058,0.04271724322830073,-0.07408350790593587
285.30000000000337,88.36139878245679,0.04303070505375883,-0.07464985245823375
286.40000000000333,88.71441460174988,0.044065998661594996,-0.07695535852240587
287.50000000000335,89.07414143393211,0.042958408163372486,-0.0762891530051566
288.6000000000034,89.43331115417487,0.04697060877656911,-0.07892992310295632
289.7000000000034,89.78842025685897,0.046174919069110754,-0.07921817434464185
290.8000000000034,90.14337315756539,0.04881449288430151,-0.08112843500011868
291.9000000000034,90.50483506203815,0.04973056525375252,-0.08090009289150712
293.0000000000034,90.86348173443864,0.051533693156236904,-0.0812299203746627
294.10000000000343,91.22445929523106,0.054039685125077064,-0.083497225339773
295.20000000000346,91.57789179553819,0.055719695799307356,-0.08585010716672015
296.3000000000035,91.93698110790845,0.05704767522927501,-0.08585010509563196
297.4000000000035,92.29368171157239,0.06259222528302555,-0.0865620647853933
298.5000000000035,92.64882289662945,0.0654225978382641,-0.08815018896005977
299.60000000000355,93.00751584555702,0.06991673916999375,-0.0907899674237469
300.70000000000357,93.36584486384673,0.0725399379242,-0.09078666353147424
301.8000000000036,93.72314055215249,0.08003737939630673,-0.09209979238538812
302.9000000000036,94.08197987866546,0.07835481606916117,-0.09605982503155053
304.0000000000036,94.43119574395062,0.0831349743591061,-0.09976177564722333
305.1000000000036,94.80007257446786,0.0859782319801119,-0.10099976269863209
306.2000000000036,95.15560881364182,0.09014929338041267,-0.10263045253543801
307.30000000000365,95.51235495671068,0.09174230940895445,-0.1039599199934802
308.4000000000037,95.86917350200444,0.09036491592372853,-0.10792214780263887
309.5000000000037,96.2230229813445,0.08983566138273202,-0.11634140247962055
310.60000000000366,96.58230408989839,0.08979160761070393,-0.1158837237519359
311.7000000000037,96.94192948890668,0.08935206148453156,-0.1166089028054138
312.8000000000037,97.29730373145648,0.09123213033770217,-0.12200349020613599
313.90000000000373,97.65568651411043,0.08906222786045292,-0.12459958726112985
315.00000000000375,98.01434447298081,0.08791190708297325,-0.12857140768297093
316.1000000000038,98.37002724040178,0.08436818296211168,-0.13248819028167214
317.2000000000038,98.72478026838368,0.07899105826560238,-0.13513392735782181
318.3000000000038,99.08797432068236,0.07917961271873475,-0.14041005077098978
319.40000000000384,99.44540151739326,0.07645755844234392,-0.1452566315662871
320.5000000000038,99.80528820276974,0.0719899203795662,-0.15062530486855463
321.60000000000383,100.1679058719715,0.06849577015051356,-0.1558939980341445
322.70000000000385,100.52714260872162,0.06621858009056414,-0.16085528053434794
323.8000000000039,100.8870934953315,0.0635411971985742,-0.16477096195270446
324.9000000000039,101.24620443098485,0.059706095018719374,-0.1687508163593341
326.0000000000039,101.60517870328299,0.05567049677271596,-0.17498072530728148
327.10000000000394,101.96454838293859,0.05533945178755939,-0.17927279966012843
328.2000000000039,102.32508475857824,0.05191034374338477,-0.18452712905648205
329.30000000000393,102.68285896247232,0.051137900452341345,-0.18880973826070457
330.40000000000396,103.04548309321144,0.044916926404225954,-0.19684210474349229
331.500000000004,103.3995585940979,0.04647970823168013,-0.20048699147796434
332.600000000004,103.7519311868286,0.040529429072352574,-0.20668798944687872
333.700000000004,104.1163904677174,0.038183152789871055,-0.21329546549180467
334.80000000000405,104.48202031198622,0.03558169793297017,-0.2185161772015216
335.90000000000407,104.83639565337982,0.03282571779192445,-0.22251397638573422
337.0000000000041,105.1924887422961,0.030691197862707575,-0.22845004932359458
338.10000000000406,105.55601337208857,0.03291528977012792,-0.23372092991944404
339.2000000000041,105.91816194700556,0.031193475687388617,-0.23900641117677468
340.3000000000041,106.2793773424881,0.02961420573023954,-0.24451622337369772
341.4000000000041,106.64101241191398,0.03315331594030191,-0.2500802770331991
342.50000000000415,106.99879177245553,0.03163422660437165,-0.2586753498109271
343.6000000000042,107.35640748653088,0.027543663464352885,-0.26322387626960797
344.7000000000042,107.71456583567756,0.027373442031985107,-0.2673167745631684
345.80000000000416,108.07562168177782,0.026781095574194058,-0.2706425865843798
346.9000000000042,108.43473387384103,0.025395183352154405,-0.27752142954739023
348.0000000000042,108.7949420275137,0.028260493439074885,-0.2827929167828902
349.10000000000423,109.15640031594236,0.028269755132050545,-0.2885017224792956
350.20000000000425,109.51738536678248,0.023677025418290754,-0.29608030076220615
351.3000000000043,109.878878904248,0.0299514239510299,-0.29969990227637755
352.4000000000043,110.2398183718209,0.024629258580217694,-0.30595884940737506
353.5000000000043,110.5967536256031,0.02064008996388722,-0.31012071399316543
354.60000000000434,110.95654872807683,0.020692106397555143,-0.31640531536179095
355.7000000000043,111.30721531449406,0.01932318443587633,-0.32254086151825057
356.80000000000433,111.6732763284966,0.01744786259204556,-0.3277302883235591
357.90000000000435,112.02820104531341,0.01840391522506435,-0.3343900137352458
359.0000000000044,112.39216592996469,0.017636493267700004,-0.3409236375514353
360.1000000000044,112.7536301260006,0.017774453818524272,-0.3435727633624617
361.2000000000044,113.11493272092757,0.019518174480110062,-0.35197185154397737
362.30000000000445,113.4794694368876,0.01867745559462408,-0.35855001747646087
363.4000000000044,113.8391737719256,0.020683701135061572,-0.3664876515186615
364.50000000000443,114.1984685013121,0.018077660903338177,-0.3703614727418416
365.60000000000446,114.56016797843378,0.018767900915656277,-0.3784076159288925
366.7000000000045,114.91641522639782,0.017389390448623754,-0.38422370234527836
367.8000000000045,115.27630693001461,0.018713776259037918,-0.3948490870280925
368.9000000000045,115.64485808951474,0.01619023284476606,-0.3977437906701189
370.00000000000455,116.00557989307953,0.01579964806343881,-0.4082549218357152
371.10000000000457,116.36657206112203,0.01816821600362495,-0.41420587212388504
372.2000000000046,116.72565236079451,0.017179235743281396,-0.4235151541879718
373.30000000000456,117.082077638879,0.01529203490008113,-0.4320629827659621
374.4000000000046,117.45191273646913,0.016241192528831938,-0.44018359426988507
375.5000000000046,117.8108222183893,0.017538244627355315,-0.4510358912844836
376.6000000000046,118.17567902163495,0.014810896789569483,-0.4596729954152239
377.70000000000465,118.53468046018877,0.015343034822270507,-0.46928094471665327
378.8000000000047,118.89882466279678,0.014197214734292807,-0.4785260084777967
379.9000000000047,119.25826401452596,0.014505155090164923,-0.4891977545905486
381.00000000000466,119.6222134028284,0.018975194669375917,-0.5014071771201976
382.1000000000047,119.98403768134095,0.019157635789063043,-0.5120203493130133
383.2000000000047,120.34321078743291,0.023004785913956827,-0.5241823397364249
384.30000000000473,120.70713062531107,0.021702254910503704,-0.5367836896958527
385.40000000000475,121.06668220166846,0.021399623448329574,-0.5494677947701301
386.5000000000048,121.42059002289244,0.0257961022294948,-0.5597721740329491
387.6000000000048,121.78890205811179,0.02392103755942543,-0.5766315324151003
388.7000000000048,122.14521106675515,0.026672334276375498,-0.5904628827550318
389.80000000000484,122.513058839104,0.02801884035995217,-0.6058670758530478
390.9000000000048,122.87760441209598,0.030529430301424743,-0.6197130680409808
392.00000000000483,123.2424912737761,0.03295258246441435,-0.6369688452557765
393.10000000000485,123.60334681186107,0.03539375569175096,-0.653166751621927
394.2000000000049,123.96190393603935,0.03624616876051645,-0.671223681384252
395.3000000000049,124.33091957783273,0.04052396010590664,-0.6884119229715613
396.4000000000049,124.6887858196335,0.039887638191933306,-0.7074436741211945
397.50000000000495,125.05120613289242,0.04250397587585164,-0.7280278891992018
398.6000000000049,125.41326877310104,0.04263847959769196,-0.749854544408433
399.70000000000493,125.7826115936286,0.046035527113824415,-0.768845172340757
400.80000000000496,126.14299029332312,0.046907062473594774,-0.7932150291108542
401.900000000005,126.49974677664028,0.04766068326835171,-0.8150454738799704
403.000000000005,126.87307518154924,0.05062785879847409,-0.8389158939774499
404.100000000005,127.23111219213723,0.052284951991771855,-0.8634849683711678
405.20000000000505,127.59326063,0.05047101518343888,-0.8881879636261325
406.30000000000507,127.95642330935691,0.05454599647170477,-0.9141950693572065
407.4000000000051,128.31054828636974,0.05631687831886323,-0.9424886440791562
408.50000000000506,128.6814613842335,0.06174605588481663,-0.9699007396857349
409.6000000000051,129.0455324728827,0.06056530867015608,-0.9987840763376665
410.7000000000051,129.40819613995453,0.058175890136727304,-1.0281516696237931
411.8000000000051,129.7691735209474,0.06298033937386904,-1.0573201890803454
412.90000000000515,130.1341264743888,0.06410780971147467,-1.0900867262798504
414.0000000000052,130.49917000000104,0.06540323130227854,-1.1186799550000086
415.1000000000052,130.86057957837238,0.06430179673531278,-1.149046003662241
416.20000000000516,131.22074858403295,0.0650517943558393,-1.178584436655012
417.3000000000052,131.5864814898507,0.06106929599648403,-1.2054265855109478
418.4000000000052,131.94453505066483,0.05865316552804778,-1.233765695247535
419.50000000000523,132.29234000467042,0.05796406488496064,-1.2597584946407863
420.60000000000525,132.6696357835128,0.053614258533656756,-1.2826766426359586
421.7000000000053,133.0348824334392,0.05055683222133034,-1.306703213595593
422.8000000000053,133.4025686912287,0.0447604521092555,-1.3293441726188813
423.9000000000053,133.76971520506856,0.04248495485102266,-1.346927173201598
425.00000000000534,134.1325838368955,0.035913719019512236,-1.3637319691604706
426.1000000000053,134.4977589050249,0.029077245958545106,-1.3784102969679601
427.20000000000533,134.8553954431172,0.02273649027528979,-1.3946944523395106
428.30000000000535,135.22142435520144,0.021545732200252132,-1.4075199854563998
429.4000000000054,135.58684008477098,0.013835154124164362,-1.4189834264078542
430.5000000000054,135.9471834528287,0.011742806477799128,-1.4312602035513198
431.6000000000054,136.30850149886868,0.00466573859053776,-1.4431459900612311
432.70000000000545,136.66879201314208,0.005206980681720985,-1.4552792768001712
433.8000000000054,137.03330917288412,0.002520868202272819,-1.4661776191121532
434.90000000000543,137.39528065531601,0.0019445208380020063,-1.4786684830795718
436.00000000000546,137.76553725230931,0.003940120322249552,-1.4898672569719653
437.1000000000055,138.13236158845555,0.0015651781042715918,-1.5022116243625838
438.2000000000055,138.49726370127027,0.003987297671118384,-1.5146126014114945
439.3000000000055,138.86111170023813,0.001793920558353257,-1.5261698984991
440.40000000000555,139.22417369850916,-0.0001324190516229784,-1.5422991762639566
441.50000000000557,139.58992983510444,-0.0019747627276114343,-1.5543399495667214
442.6000000000056,139.9501371752735,-0.0009976865495078258,-1.5649824437542987
443.70000000000556,140.31641119651997,-0.0032762370996870516,-1.5796057848029865
444.8000000000056,140.68288908941207,-0.0009532021437874683,-1.5953671278883035
445.9000000000056,141.0488307266115,-0.004589019495786051,-1.6101978446794143
447.0000000000056,141.40744515188098,-0.0004917613043660118,-1.6268684070264263
448.10000000000565,141.7781545087546,-0.00256926881861963,-1.6413640131409197
449.2000000000057,142.1383492036169,-0.0045777038318259855,-1.6643678036498666
450.3000000000057,142.50444821269036,-0.006692339953759507,-1.6750530911731762
451.40000000000566,142.87483059417494,-0.011092874008886255,-1.6925490940595749
452.5000000000057,143.24388710766664,-0.014868704132504185,-1.70720103822483
453.6000000000057,143.60960441662365,-0.021727394440430814,-1.719197569913511
454.70000000000573,143.97620444402327,-0.03145487848282169,-1.7289008289201084
455.80000000000575,144.3425847834193,-0.04076351456708771,-1.7355674015886473
456.9000000000058,144.70638316771544,-0.048857736772442095,-1.7421322381502717
458.0000000000058,145.07094444958852,-0.055731154579062636,-1.7473199567923396
459.1000000000058,145.43157999386435,-0.06251127806770773,-1.7500608198367535
460.20000000000584,145.79410004957396,-0.0682233316789671,-1.7537209551980384
461.3000000000058,146.16121216970726,-0.06624979035248746,-1.7564657832183066
462.40000000000583,146.5283646385878,-0.07006072265635854,-1.7590598499974575
463.50000000000585,146.88934268375027,-0.07257574552062662,-1.7603816618124069
464.6000000000059,147.25977495566806,-0.052772282326784214,-1.7611392377942927
465.7000000000059,147.626234395922,-0.04893851257760673,-1.7626907423725102
466.8000000000059,147.98632605786307,-0.048007568527034916,-1.765285125272198
467.90000000000595,148.35882336936453,-0.04843039664904447,-1.7666308409107239
469.0000000000059,148.7266789577983,-0.048013095235172276,-1.767096830267315
470.10000000000593,149.0952679606148,-0.05346253538901857,-1.7683008933383686
471.20000000000596,149.45835808741194,-0.051169695146109806,-1.7709094315156966
472.300000000006,149.82682721877794,-0.052995157970015416,-1.7706875292324593
473.400000000006,150.19013592291373,-0.05064005414179196,-1.7706005065348873
474.500000000006,150.5571027574653,-0.05337107827027543,-1.7735508635545436
475.60000000000605,150.92087706499714,-0.05065918446423945,-1.773645661336014
476.70000000000607,151.28547327789735,-0.04984485536103822,-1.7771710746757328
477.8000000000061,151.65300839719976,-0.052535487588268204,-1.777499967376234
478.90000000000606,152.01954243687234,-0.051308001545364856,-1.7774998472270247
480.0000000000061,152.38825187755157,-0.04807934469766639,-1.7807753159957849
481.1000000000061,152.75941277468738,-0.05288935805973782,-1.780129820513908
482.2000000000061,153.12134313315153,-0.04728438088312581,-1.7812441660557616
483.30000000000615,153.4879253198472,-0.04904441264230197,-1.7839398809201628
484.4000000000062,153.85483382137085,-0.049670081261805166,-1.7837266935123943
485.5000000000062,154.2257267560282,-0.052250578988769725,-1.7864999250162343
486.60000000000616,154.58674936938942,-0.0512194710916547,-1.7873511913960454
487.7000000000062,154.9506074811048,-0.05010657525124618,-1.7887941942713952
488.8000000000062,155.30881082575115,-0.051524721941980545,-1.7900103517497987
489.90000000000623,155.6876870583437,-0.05176478330459,-1.7887691195731943
491.00000000000625,156.0529172195753,-0.0521447371772461,-1.7923201817137113
492.1000000000063,156.42105854489074,-0.05730614307528459,-1.7990481704333643
493.2000000000063,156.7851115455796,-0.05386636176990267,-1.7897595617145927
494.3000000000063,157.14726524261744,-0.053807130020565364,-1.789481495583345
495.40000000000634,157.52140438713562,-0.05495508536223337,-1.7975893568931127
496.5000000000063,157.8895705388369,-0.05411112979243926,-1.7989564362251644
497.60000000000633,158.25651117971142,-0.0558744888334588,-1.7988237553663966
498.70000000000636,158.62730889742105,-0.05633536346635015,-1.8012121214485477
499.8000000000064,158.9958797797055,-0.056497043873683594,-1.80220005547246
500.9000000000064,159.36552017147872,-0.06100607759161658,-1.8045010913077055
502.0000000000064,159.7329772168696,-0.06215705381861225,-1.8071399798126548
503.10000000000645,160.105987544192,-0.0594214865670053,-1.8074717421394588
504.2000000000064,160.47796759070374,-0.05949978002471923,-1.8073977494795264
505.30000000000643,160.84117009859065,-0.06027555229875059,-1.8098500075802737
506.40000000000646,161.210226973894,-0.061082547527025355,-1.8139602380788786
507.5000000000065,161.5759993549202,-0.056838511977796546,-1.8139500161913977
508.6000000000065,161.9380000876077,-0.05680265072788071,-1.8159392312874694
509.7000000000065,162.30763139634476,-0.056947669640802,-1.8152700455414692
510.80000000000655,162.67529134586445,-0.056972485273616424,-1.8177827356261105
511.90000000000657,163.04308391629718,-0.04932257765920767,-1.8185607601255311
513.0000000000066,163.41287694786143,-0.05325458796915283,-1.8208942180640983
514.1000000000065,163.781362979568,-0.04828491425134995,-1.8232799666738604
515.2000000000066,164.14916684020505,-0.05143138309906359,-1.8237204960842868
516.3000000000065,164.51809924835447,-0.0466593131534383,-1.8265699398144486
517.4000000000067,164.88945842514138,-0.04450134890073887,-1.8282214275448987
518.5000000000066,165.2547917425803,-0.04137010169329347,-1.8295398049946927
519.6000000000067,165.62194692047194,-0.037362789307253674,-1.8321698765426948
520.7000000000066,165.98655858777556,-0.031290307923684146,-1.8338891350526385
521.8000000000067,166.356637463133,-0.027500732189044808,-1.8359915270494813
522.9000000000067,166.72770531338145,-0.021779621752798572,-1.8376026087386026
524.0000000000067,167.09296878040675,-0.020238742686673472,-1.8400912659856932
525.1000000000067,167.4665442086487,-0.02549436547166062,-1.8412823144955128
526.2000000000068,167.8287709908799,-0.02694715257672442,-1.8449026034953042
527.3000000000068,168.2073594792526,-0.029970867495936915,-1.8475399498232998
528.4000000000068,168.56418255711344,-0.03419062154688435,-1.8514921113169738
529.5000000000068,168.9326940965893,-0.0385561029125534,-1.8531399865409344
530.6000000000068,169.2939669488391,-0.03891382870733251,-1.8552149011691563
531.7000000000069,169.6657575564486,-0.040222008717313074,-1.8577099030959685
532.8000000000068,170.03577908358267,-0.04384992825479683,-1.8622351742503969
533.9000000000069,170.40362462278492,-0.04384512087301351,-1.8661997392377279
535.0000000000068,170.7744829698721,-0.050340118298528136,-1.8701442575795064
536.100000000007,171.14111964662277,-0.049235542610645666,-1.875200892302432
537.2000000000069,171.51510623014713,-0.05253486410084296,-1.8782801814188281
538.300000000007,171.88538930559872,-0.05842870290588209,-1.8841493886190062
539.4000000000069,172.2537438489691,-0.05586323002844118,-1.888524345613583
540.5000000000069,172.62809449923319,-0.060317280812876906,-1.8918821427224453
541.600000000007,172.9976576287578,-0.056850773856994774,-1.8969365364125368
542.700000000007,173.36787418832333,-0.05741603626198977,-1.9040900999559152
543.800000000007,173.73327438943252,-0.06031177035204749,-1.9085782819270798
544.900000000007,174.10205548256556,-0.06199282421659369,-1.916004974356008
546.000000000007,174.46831351670338,-0.06311239785194633,-1.922960683418553
547.1000000000071,174.83102351097497,-0.06222866602186761,-1.9308297057197206
548.2000000000071,175.20274170585245,-0.06981973228670357,-1.9368766538788464
549.300000000007,175.5730658502344,-0.07094713389019836,-1.9454931646822335
550.4000000000071,175.9397726308744,-0.07672740355597929,-1.9534842158770038
551.500000000007,176.3106704043006,-0.07855664471426893,-1.964902840696951
552.6000000000072,176.67745179521526,-0.08588815300093877,-1.971705098053576
553.7000000000071,177.04855934388084,-0.0919145463097486,-1.9818268358283482
554.8000000000072,177.41264448052777,-0.09496937281214901,-1.992837995873825
555.9000000000071,177.78716308526225,-0.09408798071595736,-2.0014735914016692
557.0000000000072,178.15692295276796,-0.10481194455684584,-2.01078416694669
558.1000000000072,178.52997394458998,-0.10644187934109084,-2.020676462844604
559.2000000000072,178.8998963220851,-0.10383931327268003,-2.0317590374727055
560.3000000000072,179.2693816055349,-0.10745379512074704,-2.0407556789132273
561.4000000000073,179.6318316933892,-0.11017640423276953,-2.05361456054578
562.5000000000073,180.0062138845354,-0.10918118341082428,-2.0631838142838768
563.6000000000073,180.37457110105996,-0.11015733671206318,-2.074315013407366
564.7000000000073,180.7446428607488,-0.113436256263173,-2.0862133901694064
565.8000000000073,181.11173703480193,-0.11342309085851188,-2.0954767708684896
566.9000000000074,181.48133067557347,-0.11284320868739606,-2.1072262543927742
568.0000000000074,181.85080693835485,-0.1164087353275054,-2.1183389863950075
569.1000000000074,182.2180317428653,-0.11712400317623661,-2.1271031216094016
570.2000000000073,182.57877617159457,-0.11832508275367326,-2.1370412906472884
571.3000000000073,182.95385547504193,-0.12340132742067844,-2.1491623515873974
572.4000000000074,183.32014684171745,-0.11900337674936479,-2.15834197575578
573.5000000000074,183.68609097964736,-0.12135538283424596,-2.1663439367879747
574.6000000000074,184.06148660680063,-0.12139013836787615,-2.173213779851026
575.7000000000074,184.4291659148169,-0.11290091506060174,-2.180620041398725
576.8000000000075,184.80215567342614,-0.07916996058299564,-2.183238537606294
577.9000000000075,185.17321520355176,-0.05756366657320777,-2.185889810079191
579.0000000000075,185.54339837848042,-0.04356918822600386,-2.187869985985085
580.1000000000075,185.90682287933325,-0.04051751623280131,-2.188190152310647
581.2000000000075,186.28112610591336,-0.05023382004629662,-2.188193742946212
582.3000000000076,186.6464273342413,-0.05748339655211243,-2.190827436896425
583.4000000000076,187.01416118588511,-0.06737788015299939,-2.192149970695122
584.5000000000076,187.38700695120014,-0.07186873813031935,-2.191841568030977
585.6000000000076,187.7538949849592,-0.07919805479123898,-2.1947899889273774
586.7000000000077,188.1255717153616,-0.08414765921297063,-2.195120504008777
587.8000000000077,188.49499209760552,-0.09394890913449538,-2.196212041227762
588.9000000000076,188.86829848068913,-0.11165231418745103,-2.197530273741961
590.0000000000076,189.23864546906705,-0.12016136403644895,-2.198186793144134
591.1000000000076,189.60553517766667,-0.12866421234930137,-2.202436668757148
592.2000000000077,189.97425205877627,-0.13133220813376978,-2.2018102251532135
593.3000000000077,190.34536092095172,-0.14076898233080248,-2.2041199095127144
594.4000000000077,190.7180324644142,-0.14172323003706166,-2.2056561159425008
595.5000000000077,191.08381930255564,-0.14794741372064424,-2.2073000681691965
596.6000000000078,191.45147063935795,-0.1484220352652832,-2.209278827582968
597.7000000000078,191.8183169377171,-0.1554866251226299,-2.2099398829629466
598.8000000000078,192.1908371570066,-0.1620706274286432,-2.212569989999982
599.9000000000078,192.56527824199875,-0.1625334991501144,-2.215199215049738
601.0000000000078,192.93799963426213,-0.16186824878186634,-2.2165281926980973
602.1000000000079,193.3081917165681,-0.16185111720409395,-2.2204385443210763
603.2000000000079,193.67590075841895,-0.1535025880732377,-2.221790111313165
604.3000000000079,194.0477607992587,-0.15270626451733804,-2.2244300099180454
605.4000000000078,194.42022729286435,-0.14855049770169737,-2.2260699359106475
606.5000000000078,194.79639332542254,-0.14214050862366445,-2.228668621030433
607.6000000000079,195.17391493568712,-0.14036258430203397,-2.2313404913440547
608.7000000000079,195.54281429244855,-0.13904026658147428,-2.235305392867849
609.8000000000079,195.911186935929,-0.13275510470647678,-2.237299581719957
610.9000000000079,196.27802869318253,-0.13190258438950186,-2.240240122431577
612.000000000008,196.6501496793422,-0.12425287688746112,-2.243554024429775
613.100000000008,197.01374513954502,-0.12133004370251887,-2.246489944955352
614.200000000008,197.38525207434697,-0.11380182793863547,-2.2507642230307647
615.300000000008,197.75230643995474,-0.11119849599347242,-2.2534085418700567
616.400000000008,198.11974333842096,-0.10383879661273054,-2.2567488855763003
617.5000000000081,198.49121859419708,-0.094091203975049,-2.260851632783482
618.6000000000081,198.86812873475253,-0.09144945354381173,-2.2652596422889926
619.7000000000081,199.2445337500625,-0.08029810261216452,-2.270200576227216
620.8000000000081,199.61280673179678,-0.07406677167475095,-2.274803560616186
621.9000000000082,199.98916332644234,-0.06098182398795027,-2.278109997798163
623.0000000000082,200.36067090771755,-0.05927828249634448,-2.287452351625479
624.1000000000081,200.73015681005907,-0.051586041302418284,-2.2885167403756923
625.2000000000081,201.10148161000035,-0.04631219140982967,-2.2941576594527535
626.3000000000081,201.46634519984798,-0.08574100753152258,-2.299027258269911
627.4000000000082,201.8353683467593,-0.08789768117380303,-2.30367278929336
628.5000000000082,202.2069735525398,-0.07508672700912689,-2.311355469034873
629.6000000000082,202.57993912230378,-0.06998835348691657,-2.3155491863205473
630.7000000000082,202.95399560863268,-0.056718245829501246,-2.320728342022367
631.8000000000083,203.32405744114223,-0.0459248611098837,-2.3269673946987623
632.9000000000083,203.69916199692213,-0.03629190072292188,-2.333660310668101
634.0000000000083,204.07116940470738,-0.02828141069929968,-2.339606863813402
635.1000000000083,204.44532875524578,-0.014681455535599408,-2.347472155258493
636.2000000000083,204.81668035927842,-0.0061021912763079555,-2.3540595549069185
637.3000000000084,205.18766055922933,-0.0020081550299462236,-2.3619907840463816
638.4000000000084,205.55725771297023,0.010927274842829515,-2.369992832124404
639.5000000000084,205.9326845607217,0.024949155557936198,-2.3769155709079888
640.6000000000083,206.30258666426354,0.03615341837280539,-2.3837409847881696
641.7000000000083,206.67375046482388,0.04785559736686951,-2.392770729404668
642.8000000000084,207.0391719351634,0.05878340234515056,-2.401619945602298
643.9000000000084,207.41389738201752,0.06647492346310413,-2.4098137497040564
645.0000000000084,207.7844114084348,0.07766951811659384,-2.416120361972726
646.1000000000084,208.16086527677237,0.08735242775182872,-2.425508730230721
647.2000000000085,208.53530584388423,0.0930495949690302,-2.434996579404939
648.3000000000085,208.90860841427397,0.10158811089821462,-2.443770386207043
649.4000000000085,209.28418271651717,0.11493107493348553,-2.452968334975016
650.5000000000085,209.6544862124775,0.12442713786026971,-2.4628695621024943
651.6000000000085,210.0291788957033,0.13963396336026968,-2.472328344473203
652.7000000000086,210.39916656972616,0.1473666534756095,-2.4802297968112006
653.8000000000086,210.77299713920627,0.1653767710746803,-2.48971645857338
654.9000000000086,211.14992313349248,0.17769410250777096,-2.5009234832921488
656.0000000000086,211.52035072377663,0.18957798600058284,-2.5103402137935067
657.1000000000087,211.88917623169874,0.21080126835247448,-2.521069874029767
658.2000000000087,212.26554077152755,0.22550202984864587,-2.531823583468134
659.3000000000086,212.63955133792132,0.2445809748227914,-2.543153948868317
660.4000000000086,213.01125622154265,0.2528853592374727,-2.552355481962867
661.5000000000086,213.38442257395073,0.2678453197417756,-2.564231307997643
662.6000000000087,213.7560683461405,0.2837251212641858,-2.5753584770186437
663.7000000000087,214.12799238449588,0.295443200495185,-2.588919249940004
664.8000000000087,214.4986426215674,0.30541395981042196,-2.600401404706469
665.9000000000087,214.8757470033423,0.3170900013917408,-2.6141736040900083
667.0000000000088,215.2477847688865,0.3182385803247403,-2.623986771965678
668.1000000000088,215.62082631865127,0.33338218718161095,-2.638054142704126
669.2000000000088,215.99916677183072,0.34030489406912023,-2.6511498148917045
670.3000000000088,216.37315084588454,0.34051215470223317,-2.6619925728338414
671.4000000000088,216.74864290429514,0.3379617349941064,-2.6749787274115757
672.5000000000089,217.11770414119013,0.3429763634438223,-2.691665828194789
673.6000000000089,217.4921853663214,0.3388491566341494,-2.701405079381913
674.7000000000089,217.86133106876503,0.3380328423099148,-2.712742520622152
675.8000000000088,218.2325222913695,0.3237035002109714,-2.7268802506433643
676.9000000000088,218.60500020881028,0.32100029903941474,-2.738449213590843
678.0000000000089,218.9725721599001,0.31559213559913335,-2.750916880853997
679.1000000000089,219.3471409048249,0.31066987814631464,-2.760704185439401
680.2000000000089,219.71916684493863,0.30130762013391843,-2.7731199362620096
681.3000000000089,220.0994548111917,0.2893833546838884,-2.7852191464456144
682.400000000009,220.47265375640774,0.26955102811004084,-2.7975627496952393
683.500000000009,220.84563520230373,0.24422318019535538,-2.8060532685112887
684.600000000009,221.21138506956817,0.21251907125202862,-2.818095049753251
685.700000000009,221.5823941296603,0.16101224810713788,-2.827736309988433
686.800000000009,221.94575045251332,0.08545400661638869,-2.8368959947416514
687.9000000000091,222.3062033024392,-0.06651111408770483,-2.8437385789668257
689.0000000000091,222.66265854668612,-0.18989608489535215,-2.8450721007140567
690.1000000000091,223.0300078509957,-0.21061727389173868,-2.8450301736059442
691.2000000000091,223.40214809822893,-0.2206377936216133,-2.846351198667065
692.3000000000092,223.7700860873993,-0.2245883740818675,-2.8466799400270815
693.4000000000092,224.1488218441143,-0.22680872159931287,-2.8456897136071797
694.5000000000091,224.51917000000174,-0.23741950592618632,-2.8473046976337617
695.6000000000091,224.88594994774596,-0.24100570524736442,-2.8481098049646425
696.7000000000091,225.25621557602776,-0.24247225596034916,-2.847772209534054
697.8000000000092,225.6334759735901,-0.24392915404011983,-2.848759701999439
698.9000000000092,226.00764085667274,-0.23578222371748359,-2.8481142655262395
700.0000000000092,226.37679233943635,-0.2417053148222572,-2.8497600412827016
701.1000000000092,226.75574554877673,-0.24527799917788817,-2.8496499999744653
702.2000000000093,227.12504870082896,-0.24673874196569967,-2.851086939265814
703.3000000000093,227.4950113966114,-0.2487520407245416,-2.849969283014914
704.4000000000093,227.87359019646567,-0.2483066431154599,-2.849969844973719
705.5000000000093,228.2446860381813,-0.25162644589185446,-2.850960069999609
706.6000000000093,228.6177216479967,-0.25373738065226226,-2.850999459949021
707.7000000000094,228.9924258604607,-0.2561488505620564,-2.8522800342300534
708.8000000000094,229.37029151779055,-0.2600959134280929,-2.85239004195222
709.9000000000094,229.74123238801425,-0.26151809099547574,-2.8534308332544702
711.0000000000093,230.1131755955429,-0.27025853602217387,-2.8530477541960453
712.1000000000093,230.49048767423514,-0.27262429959426937,-2.854027892473553
713.2000000000094,230.86097530524572,-0.27837760859966965,-2.852709959606143
714.3000000000094,231.23524644015092,-0.26627448823267175,-2.853370109914069
715.4000000000094,231.6068074479592,-0.26880327742820453,-2.8563401479694615
716.5000000000094,231.9798077458077,-0.2649943685495231,-2.8553450618367675
717.6000000000095,232.35377141497816,-0.26357617320115656,-2.855870027976149
718.7000000000095,232.72653735632025,-0.26591540213079545,-2.855679956547499
719.8000000000095,233.094039836552,-0.2637592593590625,-2.8569899999940698
720.9000000000095,233.4673301836299,-0.26619579764998447,-2.855679975311702
722.0000000000095,233.84132719785228,-0.26867804725835054,-2.856999893401775
723.1000000000096,234.21476943135764,-0.2684862865270574,-2.85822318847214
724.2000000000096,234.58823134365082,-0.2629185750098766,-2.8576594093879173
725.3000000000096,234.96136602543916,-0.26263260337064986,-2.8593101650060397
726.4000000000096,235.33539118093344,-0.2627238623357204,-2.8604090995533413
727.5000000000097,235.70524288926143,-0.26642641545323587,-2.8589754228783733
728.6000000000097,236.083891976421,-0.26140086306904564,-2.859960557964
729.7000000000096,236.45954743728487,-0.258333993235758,-2.861249647708803
730.8000000000096,236.83334364389262,-0.2627937000327396,-2.861611212307679
731.9000000000096,237.20643302888251,-0.2640891304215476,-2.8625930589412762
733.0000000000097,237.5800927513867,-0.2598543777659508,-2.863259923887984
734.1000000000097,237.94829563223902,-0.18740776485343424,-2.863759854747501
735.2000000000097,238.32850993307514,-0.17033201913922635,-2.862269070292672
736.3000000000097,238.70476786829005,-0.17494627675832497,-2.8645702015968624
737.4000000000098,239.07204867952518,-0.1760735942945022,-2.8655606376373823
738.5000000000098,239.44738287491006,-0.17488793549729476,-2.865560132477467
739.6000000000098,239.81624078956744,-0.17772896158688267,-2.865890095000391
740.7000000000098,240.19036443611645,-0.18207415319914944,-2.865889998183126
741.8000000000098,240.5660853416528,-0.17528528467079552,-2.866220064735095
742.9000000000099,240.94244347214303,-0.18177130643031525,-2.8662162688700836
744.0000000000099,241.3137722186104,-0.1787970765346918,-2.8675427357643857
745.1000000000099,241.68846389980988,-0.18118344806518882,-2.867927344720491
746.2000000000098,242.06620289418092,-0.18801873253587198,-2.8688599621910216
747.3000000000098,242.43773555294888,-0.18614181467392532,-2.8701699550494437
748.4000000000099,242.81156156903526,-0.18681057746439578,-2.868200106844478
749.0000000000099,243.0175316391633,-0.18562279467377385,-2.869520210256626