File: 01_Data/Nylon_Carpet_High_Pile/STA/N2/3K_min/Nylon_Carpet_High_Pile_STA_N2_3KData_220309_R1.csv
##Temp./Â°C,Time/min,DSC/(mW/mg),Mass loss/mg
51.0,11.300511691892144,0.032715400290948216,-0.031855840441077365
52.20000000000002,11.868549991078938,0.04851061005045976,-0.03181891816226701
53.400000000000034,12.358414230499317,0.056468109613217354,-0.03184415454311518
54.60000000000005,12.794048771545778,0.058315755782881284,-0.03393958128920893
55.80000000000007,13.262985689315713,0.06318086448338978,-0.03577278848761756
57.000000000000085,13.705475495730774,0.06679874232549454,-0.036817511501498146
58.2000000000001,14.125790518496494,0.06768567992143981,-0.03488071261807546
59.40000000000012,14.556790899805657,0.06910778173940713,-0.03971489507192816
60.600000000000136,14.974150292953814,0.0710017663302539,-0.032915955902395044
61.80000000000015,15.38964285457217,0.07385746414156724,-0.03799311656920601
63.00000000000017,15.795004817190568,0.07140862417636651,-0.0356660706723364
64.20000000000019,16.20247351683008,0.0717349998246396,-0.02995881477908613
65.4000000000002,16.611333442061124,0.07390076308229154,-0.03839342994986339
66.60000000000022,17.014438629908526,0.07813182703942889,-0.039436021006719724
67.80000000000024,17.420043670439316,0.077094971254698,-0.04034100554382025
69.00000000000026,17.818129285464924,0.07730923858463745,-0.04058494024125725
70.20000000000027,18.22065970142381,0.07640662524946007,-0.0405901936852513
71.40000000000029,18.629304195716088,0.07694773288446588,-0.041848164408523125
72.6000000000003,19.032876854385517,0.0721731453675839,-0.04345850458984257
73.80000000000032,19.436637001983875,0.07624812825470728,-0.04201007742198559
75.00000000000034,19.83301371693668,0.07681970114292191,-0.042986034816587804
76.20000000000036,20.237359471338742,0.07597652963530388,-0.044339771020841745
77.40000000000038,20.641572563598313,0.0759335752299587,-0.04402315352980235
78.60000000000039,21.048676768309683,0.07726843262744076,-0.046758946417933434
79.80000000000041,21.451750216625328,0.07377519768888152,-0.045897111209312946
81.00000000000043,21.857434740150826,0.07351842010921006,-0.0466349067083236
82.20000000000044,22.263504699942295,0.07542358782448588,-0.049250377567021
83.40000000000046,22.667033386740876,0.07591792669337794,-0.04793881674458955
84.60000000000048,23.066147705946417,0.07749351178299313,-0.048929693535304075
85.8000000000005,23.46711309617023,0.07742835234548506,-0.05057529255846527
87.00000000000051,23.867043841888457,0.07516561710829417,-0.05067780106413711
88.20000000000053,24.26715484803923,0.07410108022011475,-0.050711438847061974
89.40000000000055,24.674411837972574,0.07323621947870929,-0.05176988868315169
90.60000000000056,25.063441340344994,0.0762783264058623,-0.051999378799183926
91.80000000000058,25.463866118380942,0.07642754425899856,-0.052438798370595396
93.0000000000006,25.8625144076646,0.07510150475419564,-0.054957420410711055
94.20000000000061,26.262116888911713,0.07419608446185189,-0.05348220852807106
95.40000000000063,26.665252097996156,0.07511291828724687,-0.054974107828509755
96.60000000000065,27.061471224764524,0.07321082416425351,-0.05508200525864071
97.80000000000067,27.46005561481539,0.07183479013650362,-0.05649387834550179
99.00000000000068,27.861940281515384,0.06862728743392832,-0.05583772863151948
100.2000000000007,28.258652214501822,0.07010505642297615,-0.05503722938187883
101.40000000000072,28.658755880641802,0.07166843379664822,-0.057593473459381705
102.60000000000073,29.05222002725224,0.07162861785871177,-0.056379451134658254
103.80000000000075,29.451597000697703,0.07132956879338315,-0.05636889132260148
105.00000000000077,29.843342766547124,0.07259412923519915,-0.056292855702028355
106.20000000000078,30.239465056605752,0.07480129693370374,-0.0560624393672704
107.4000000000008,30.636938866951773,0.07199521796932551,-0.057700902483646566
108.60000000000082,31.03137794483954,0.06936704576014674,-0.05767747054132899
109.80000000000084,31.43182740490044,0.07221722213576642,-0.05769956446367708
111.00000000000085,31.82717281550876,0.07336172623291581,-0.05896892620911265
112.20000000000087,32.22459737348959,0.0719849721410305,-0.06085902640330154
113.40000000000089,32.61618807704414,0.07354769959242258,-0.058996801662132725
114.6000000000009,33.01178298475065,0.07013234247880484,-0.05999483122361182
115.80000000000092,33.405928616897874,0.0746570869982025,-0.060995934388216266
117.00000000000094,33.7994509607972,0.07550519211666884,-0.060659907937735014
118.20000000000095,34.20085154730862,0.07405481255335866,-0.06153344221374102
119.40000000000097,34.59375385982417,0.07522665229125003,-0.06268678710338005
120.60000000000099,34.98996717586327,0.07637226861686608,-0.061964744989662535
121.800000000001,35.37641725509348,0.0774637437833392,-0.06328995754166478
123.00000000000102,35.77565980546721,0.07388365174914613,-0.06555685029610325
124.20000000000104,36.171842778517046,0.07530960309160761,-0.06429097030113784
125.40000000000106,36.5642150173976,0.07734485751519171,-0.06529382190789423
126.60000000000107,36.965043310773176,0.07707308503298094,-0.0652911357848267
127.80000000000109,37.35307811941774,0.07860378329864126,-0.06659071810693229
129.0000000000011,37.74716932424695,0.08295070143385841,-0.06452370581230227
130.20000000000113,38.13756906820563,0.0834232851769362,-0.06600245706117613
131.40000000000114,38.534739299301386,0.08164836421059662,-0.0673930861883858
132.60000000000116,38.93074787804482,0.08140049022756435,-0.06622893767420734
133.80000000000118,39.32599596139965,0.08209644513227887,-0.06625999427764473
135.0000000000012,39.713300693918505,0.07994666644320203,-0.0669013200001598
136.2000000000012,40.10474512281231,0.07949973733046489,-0.06824002463641898
137.40000000000123,40.50472694194843,0.07988710875045846,-0.0685572297801369
138.60000000000124,40.89381420377887,0.07944032702111004,-0.06822998200314734
139.80000000000126,41.29301629539492,0.07990625089561199,-0.0705437616038962
141.00000000000128,41.689853232621616,0.07929053648071538,-0.07087465432587736
142.2000000000013,42.08014192983292,0.083258629067401,-0.06955004725406333
143.4000000000013,42.471951472765184,0.08702743422645898,-0.07018364401329968
144.60000000000133,42.865826074635294,0.08387984423678674,-0.07020998204950235
145.80000000000135,43.2561897309833,0.08596877799968794,-0.069543918498161
147.00000000000136,43.65369465697759,0.08769131175591571,-0.07086270694335406
148.20000000000138,44.04254444661681,0.08919151659868363,-0.07186153129818962
149.4000000000014,44.439847870488286,0.0875959356660807,-0.0721375142926699
150.60000000000142,44.83080194498803,0.08599444717761984,-0.07251008942806214
151.80000000000143,45.22156501672367,0.08993527396225665,-0.07155340850067082
153.00000000000145,45.61787414455901,0.0887350078905409,-0.07166658436125894
154.20000000000147,45.99917000000081,0.09043668551648898,-0.07152136702788026
155.40000000000148,46.39796332962427,0.09128973210312163,-0.07141003167042514
156.6000000000015,46.78871665710419,0.09351646031514449,-0.07239002996163313
157.80000000000152,47.181755351779536,0.09847229473226116,-0.07105137777964066
159.00000000000153,47.570496640776746,0.10228348212303429,-0.07338255047923026
160.20000000000155,47.9642499259591,0.10507806713412948,-0.07175012871956454
161.40000000000157,48.352088793926654,0.1102809203249181,-0.07306011976490723
162.6000000000016,48.731349195953186,0.11338983646147394,-0.07221822247906617
163.8000000000016,49.13528714168679,0.12098902628736619,-0.07505197118702078
165.00000000000162,49.53118316584925,0.12230518573391325,-0.07229015324808996
166.20000000000164,49.920246600496306,0.1261353112870428,-0.07494561822416701
167.40000000000165,50.31454991890763,0.1283816288635793,-0.07466252124085404
168.60000000000167,50.707027898581806,0.11883670055868067,-0.07491947252004838
169.8000000000017,51.100361451252624,0.11310823993882901,-0.07755352775428781
171.0000000000017,51.48823818571449,0.10125880775434504,-0.07525472386659748
172.20000000000172,51.87994323883014,0.09749615644968501,-0.07759803328169301
173.40000000000174,52.26880415974837,0.09569270714307843,-0.07886918785584163
174.60000000000176,52.66157733387959,0.09426868583042769,-0.07789163342279437
175.80000000000177,53.0484706918312,0.093239916773591,-0.0785068800324682
177.0000000000018,53.438366614964366,0.09350151269562823,-0.07932953332042025
178.2000000000018,53.83031537740986,0.09387922976051011,-0.07887058525995405
179.40000000000182,54.226551236366404,0.09181014935781828,-0.0786479108609881
180.60000000000184,54.613992509464765,0.09434639626159436,-0.07898026748732656
181.80000000000186,55.00666434658694,0.09415716283055553,-0.07898426336568098
183.00000000000188,55.3985290901735,0.09156172496750348,-0.08024759856155805
184.2000000000019,55.79077561727693,0.09300719775228361,-0.0812902359199863
185.4000000000019,56.17828324280531,0.09598760732227885,-0.08073007899516416
186.60000000000193,56.57296596760081,0.09566898123933865,-0.07941994883902481
187.80000000000194,56.96099638554924,0.09663414732294973,-0.08074011807049875
189.00000000000196,57.348857957375046,0.09857859727829066,-0.08040014847104393
190.20000000000198,57.73569598660542,0.0961599249222227,-0.08105441493899734
191.400000000002,58.128257990970596,0.09732007089647976,-0.08117835338070734
192.600000000002,58.514419887038976,0.09722192111759131,-0.08083194697468477
193.80000000000203,58.90500771472748,0.09942831959786069,-0.07995824726435741
195.00000000000205,59.295067542342956,0.09657943321638829,-0.0813440775000327
196.20000000000206,59.687383013628,0.0977844883495127,-0.08228018990761266
197.40000000000208,60.07889711939935,0.0989095561890756,-0.08195019052719177
198.6000000000021,60.46954858407317,0.09992848715219305,-0.08163504694536217
199.80000000000211,60.86284406955811,0.10081800243608485,-0.08128997899639279
201.00000000000213,61.257097925673804,0.10012665801434117,-0.08027508067239175
202.20000000000215,61.63945798788572,0.10189147456896497,-0.08228019643051399
203.40000000000217,62.03190872512866,0.10292644062695622,-0.08096019259035092
204.60000000000218,62.42038639942626,0.10466056687086889,-0.0829022992538686
205.8000000000022,62.811850031406735,0.10572800373967184,-0.08291159747602839
207.00000000000222,63.20420223469603,0.1063397758547906,-0.08293011923266036
208.20000000000223,63.59621441008333,0.10762768758987229,-0.08293007900010663
209.40000000000225,63.98942428899306,0.10858698251167731,-0.0841520891110239
210.60000000000227,64.37713115803055,0.11041523496415595,-0.0838107639621457
211.80000000000229,64.76644133271397,0.11670815339264884,-0.08475993683438299
213.0000000000023,65.15741112782693,0.12254920759178062,-0.08339634496893789
214.20000000000232,65.54337383495536,0.1302627732953508,-0.08412431714032831
215.40000000000234,65.93218788248704,0.14436640699261233,-0.08447019724309701
216.60000000000235,66.32531734433232,0.1829719270479614,-0.08446431227255324
217.80000000000237,66.71698500754533,0.2627244726967474,-0.08514788775653592
219.0000000000024,67.11201173216533,0.33511246161644187,-0.083782523670906
220.2000000000024,67.50478294195081,0.34591569626223917,-0.08577530766532204
221.40000000000242,67.89470922225598,0.2956377695512683,-0.08708619755891611
222.60000000000244,68.28759563470805,0.24697821620891386,-0.08581395106790835
223.80000000000246,68.67694459166259,0.22291715251705807,-0.08644108028448949
225.00000000000247,69.06972827249217,0.18440431812083286,-0.08738219184667484
226.2000000000025,69.4592080840167,0.14066966494309557,-0.08790543858405409
227.4000000000025,69.84188846087144,0.1136413735305602,-0.0880862707074348
228.60000000000252,70.22906501471007,0.10933982376125462,-0.08808001793638986
229.80000000000254,70.62254211832112,0.10570860282199102,-0.08971071461763191
231.00000000000256,71.00402478202344,0.10232487555297898,-0.0892631662566381
232.20000000000258,71.39249312683707,0.10632471689077327,-0.08809140898164092
233.4000000000026,71.78495836315862,0.1058099246115311,-0.09104561497874686
234.6000000000026,72.17516768396695,0.10316657396432366,-0.09085658283600218
235.80000000000263,72.56583000000083,0.10040223753670274,-0.09038988644017687
237.00000000000264,72.95485831017766,0.10391954467829057,-0.08925453751381607
238.20000000000266,73.34666504692106,0.1038423309301828,-0.091710067862937
239.40000000000268,73.73079132558662,0.10435167086689873,-0.09105498442871562
240.6000000000027,74.12092254505437,0.10319974330543552,-0.0910394286488243
241.8000000000027,74.51028348334115,0.10240752648294466,-0.09248149149542195
243.00000000000273,74.90781956406852,0.10131072482177128,-0.09298965704474416
244.20000000000275,75.2959070733807,0.10329277243138446,-0.09203450872049235
245.40000000000276,75.68465474420394,0.1018626514295134,-0.09433983077109298
246.60000000000278,76.07407965767027,0.10122556330095028,-0.09290610588261572
247.8000000000028,76.46149003746659,0.10223755841002363,-0.09328030626508976
249.0000000000028,76.85455098489437,0.10087241874078667,-0.09529379839497709
250.20000000000283,77.24242254744422,0.1021046294756881,-0.09664984650913233
251.40000000000285,77.62981405472998,0.10333991563841827,-0.09436984121280334
252.60000000000286,78.01897237351209,0.10346316318965859,-0.09631810920662787
253.80000000000288,78.40389947028227,0.10474235161711426,-0.09700983129040175
255.0000000000029,78.79417276502738,0.10341065200974031,-0.09728250219733248
256.2000000000029,79.18875334582408,0.10234170114134916,-0.09927102361025142
257.40000000000293,79.58281581495338,0.10454980096555172,-0.09761959402591724
258.600000000003,79.97103626560285,0.10630704823297871,-0.09961528279430576
259.80000000000297,80.35758515243951,0.1052217567400715,-0.10123082249627524
261.00000000000296,80.7419230891615,0.10398502120303132,-0.10190068008070297
262.200000000003,81.13703521484298,0.10264799193662821,-0.10321994975515558
263.40000000000305,81.52955441024069,0.10006256799858926,-0.1048261558696395
264.60000000000304,81.91893381316339,0.10349312417131068,-0.10415402398236884
265.800000000003,82.30906667678994,0.10308525964500226,-0.10409997806275362
267.00000000000307,82.69842988122357,0.10549377398561866,-0.10543087010456853
268.2000000000031,83.08787628713121,0.10549603464767077,-0.10627139231707172
269.4000000000031,83.4741891614734,0.10448971132059742,-0.106103766948074
270.6000000000031,83.86650410009645,0.10041439591703072,-0.10594217019017371
271.80000000000314,84.2579920649743,0.1009774708624887,-0.10578488826687504
273.0000000000032,84.64558140710173,0.10512701712680539,-0.10760832454745106
274.2000000000032,85.03249705763693,0.10422018463562321,-0.10859996174800379
275.40000000000316,85.42284843205235,0.10622011988524982,-0.10860029349231715
276.6000000000032,85.80896255976774,0.10540653104421227,-0.10990013154369871
277.80000000000325,86.19917344470899,0.1052409728316735,-0.11188994881772052
279.00000000000324,86.58939749300032,0.10821318713444861,-0.11250152773896804
280.20000000000323,86.97562460081035,0.10939723642524984,-0.11369490617853151
281.4000000000033,87.36966048950978,0.10994156236624147,-0.11353882105882152
282.6000000000033,87.76135024684055,0.1071242222670622,-0.11553801986947887
283.8000000000033,88.15478313739222,0.11226496832336286,-0.11618589291168169
285.0000000000033,88.54369312187191,0.11452010393974338,-0.11913018358347305
286.20000000000334,88.93599922337185,0.11953195257255639,-0.12145966378526518
287.4000000000034,89.32158275428213,0.12022539825912226,-0.12102485770627291
288.6000000000034,89.71447137423792,0.12101744061603198,-0.12392611541530574
289.80000000000337,90.09690475583771,0.12137380370391543,-0.12602844874225516
291.0000000000034,90.49275382058188,0.12361119486264882,-0.12834983382188359
292.20000000000346,90.88339946424999,0.12389039473398467,-0.1322910040087817
293.40000000000344,91.27395170741995,0.12815549839514545,-0.13364174111248683
294.60000000000343,91.66137880741235,0.1259113254678681,-0.13551221863024976
295.8000000000035,92.05232425324935,0.1292906177521287,-0.13963841081005057
297.0000000000035,92.43970187629606,0.131302571951813,-0.14332963169240198
298.2000000000035,92.82894284549809,0.12856750314935117,-0.14720150691909106
299.4000000000035,93.22381107468432,0.12782806579531947,-0.15066552530714183
300.60000000000355,93.61358114862986,0.13489781991023378,-0.15547966779413125
301.8000000000036,94.00162093351027,0.1351028603397121,-0.15902418267951868
303.0000000000036,94.39294761932588,0.1377566323939613,-0.1654510621672518
304.20000000000357,94.78057874286884,0.13845571970865514,-0.17092096154765768
305.4000000000036,95.17377407636336,0.140530732024703,-0.1750931146854886
306.60000000000366,95.57022348695486,0.14248353146887527,-0.1826505525070492
307.80000000000365,95.9581147894325,0.14650924195465628,-0.18758171477827723
309.00000000000364,96.34572181989864,0.15187126184064464,-0.19505913984488243
310.2000000000037,96.73945992270919,0.15586490748438075,-0.20114272276248757
311.40000000000373,97.1293816751648,0.1585055230448568,-0.20967653814895026
312.6000000000037,97.52061954548014,0.16518434290903417,-0.2182817639786827
313.8000000000037,97.91383109178528,0.1671022966807387,-0.22747943243690605
315.00000000000375,98.30369648778331,0.17329863491035977,-0.23823211426687863
316.2000000000038,98.69637302865043,0.17694876417283378,-0.24700199950578217
317.4000000000038,99.08532325753725,0.18228897145103512,-0.2576080864425192
318.6000000000038,99.47947333294765,0.18893115456532567,-0.2724344297899588
319.8000000000038,99.86852479650142,0.19324404916082297,-0.28428419318677234
321.00000000000387,100.2632367162743,0.2018417724484351,-0.29730258566402235
322.20000000000385,100.65706824255354,0.20822824065895676,-0.31177590011528133
323.40000000000384,101.0374757957917,0.21465742876112687,-0.3253370454753779
324.6000000000039,101.44507340433661,0.21971439929577652,-0.3436444181561136
325.80000000000393,101.83537687876223,0.23180091731554076,-0.3611941204430287
327.0000000000039,102.22451256488038,0.23577090348722732,-0.3777432732421291
328.2000000000039,102.61792386968108,0.24258809465900655,-0.3979040781504031
329.40000000000396,103.0099929467294,0.24782555667009834,-0.42029934029189375
330.600000000004,103.3991669631846,0.2554107943830798,-0.43907990790270235
331.800000000004,103.79380000334395,0.2620809659917062,-0.46273213394670387
333.000000000004,104.18618175072397,0.2691121091065765,-0.4862521886065907
334.200000000004,104.57868308778032,0.2795992451606246,-0.5111595506610609
335.40000000000407,104.97149288347225,0.28639642341279753,-0.5385367350117902
336.60000000000406,105.3623434202556,0.2914968996105503,-0.5654476582403185
337.80000000000405,105.75713319825209,0.3019355399417433,-0.5953535191748762
339.0000000000041,106.14947718116781,0.3111753584387936,-0.624133711208466
340.20000000000414,106.54439465003686,0.3182628501103888,-0.6572846412989937
341.4000000000041,106.93655434677186,0.32499141988722235,-0.690510112228711
342.6000000000041,107.32668839666297,0.33351716604112625,-0.7216704944599566
343.80000000000416,107.72225213043794,0.3397126040946265,-0.7569897596916024
345.0000000000042,108.11368552225645,0.3461606840237508,-0.7947703582449512
346.2000000000042,108.49978908438155,0.3509939857266189,-0.8308584749925996
347.4000000000042,108.90043335712117,0.3586537821385477,-0.8700813125865983
348.60000000000423,109.29517040455998,0.36977937648085835,-0.9123446124467862
349.8000000000043,109.68756909842264,0.3718274432890348,-0.9554684372317364
351.00000000000426,110.07668762110619,0.379486049350117,-0.9969638979907245
352.20000000000425,110.46618368116951,0.38274913561847196,-1.0413124096472828
353.4000000000043,110.8597702946194,0.38548977988633326,-1.0873851746095582
354.60000000000434,111.25313860697973,0.38685260844397745,-1.1361637129301903
355.80000000000433,111.65239145880156,0.3855359986451429,-1.1834205162359437
357.0000000000043,112.0464094719346,0.38527930558942725,-1.2320353922972518
358.20000000000437,112.43946237153125,0.3834463539782637,-1.278971341678513
359.4000000000044,112.83325400478778,0.380809624634464,-1.3288516098575607
360.6000000000044,113.22546439988683,0.377236397789431,-1.3769472033506642
361.8000000000044,113.61797100703544,0.36673017150655146,-1.4256740412468596
363.00000000000443,114.01078192997606,0.35588696907209827,-1.4755674058149029
364.2000000000045,114.40654682095027,0.348658922724984,-1.5234767135918887
365.40000000000447,114.7991742688735,0.3336074708734601,-1.569015896042408
366.60000000000446,115.18682718926345,0.3163347698410686,-1.6110957414130276
367.8000000000045,115.5815433975182,0.29733478291520626,-1.6530900848309207
369.00000000000455,115.97362345996903,0.2762193140371246,-1.6911055598447269
370.20000000000454,116.36470451715864,0.25636208856777043,-1.7255109331310545
371.4000000000045,116.75773271019925,0.22937352482634338,-1.7598784788832949
372.60000000000457,117.152731665608,0.20502400110172914,-1.7898291636816288
373.8000000000046,117.54692505533197,0.17879454595839944,-1.8153151866350354
375.0000000000046,117.93763089597908,0.15522099475775902,-1.8361674667947065
376.2000000000046,118.33183454717843,0.13489421930724327,-1.8526896902307168
377.40000000000464,118.7253920708847,0.11658952843113662,-1.8670435227206132
378.6000000000047,119.11695261554038,0.10295716844587031,-1.8806574594351204
379.8000000000047,119.51553426186716,0.09731146520742832,-1.8909969145469634
381.00000000000466,119.90950567661262,0.08992168034504683,-1.8990588025829318
382.2000000000047,120.30285609482749,0.08774080898559482,-1.907942142889909
383.40000000000475,120.6958409287524,0.0883842876413285,-1.9165674940657067
384.60000000000474,121.09410566712201,0.08484308514576833,-1.9239223424842526
385.80000000000473,121.49977171725095,0.08429366732042294,-1.9315667270535202
387.0000000000048,121.8825000000016,0.08148927635645137,-1.935530090959226
388.2000000000048,122.27707046038668,0.08257946431520967,-1.9427949962944204
389.4000000000048,122.670721227853,0.0785586476391275,-1.9466942102072142
390.6000000000048,123.06371892027602,0.0812886690212951,-1.954638976460212
391.80000000000484,123.45674286155014,0.08028637215831852,-1.9612024496999783
393.0000000000049,123.84855856483243,0.07924899524257772,-1.9677707440282375
394.2000000000049,124.24197974645726,0.07832392164611764,-1.973019638363664
395.40000000000487,124.6325035026153,0.07835695036665202,-1.9802798147663223
396.6000000000049,125.02476262955439,0.08018170013733097,-1.9868733547165953
397.80000000000496,125.41995215368046,0.07747781070529132,-1.990796577981724
399.00000000000495,125.81428960641452,0.07873812139823605,-1.998611894156226
400.20000000000493,126.21363878401776,0.07566742269134644,-2.003529532359119
401.400000000005,126.61047333437911,0.07334480888281926,-2.009243851011386
402.600000000005,127.00532004364241,0.07405255428631655,-2.015682836178207
403.800000000005,127.4051100321233,0.0736042458978903,-2.0215150075593056
405.000000000005,127.80145656883901,0.07493299564786751,-2.028205048148157
406.20000000000505,128.1959348195758,0.07579093758687885,-2.034720173683855
407.4000000000051,128.58517095735783,0.07838133467413402,-2.0400466027335087
408.6000000000051,128.97717027821025,0.07982284563011223,-2.046997016372501
409.80000000000507,129.37055982093548,0.07719889064842896,-2.054979488936164
411.0000000000051,129.77097991173156,0.07784739094499149,-2.062441137889845
412.20000000000516,130.17063903535413,0.07618895547598087,-2.070834892901088
413.40000000000515,130.56787308307221,0.07605792086955818,-2.0767870074116175
414.60000000000514,130.9670785639585,0.07544201914939948,-2.084043628017091
415.8000000000052,131.36115276115095,0.07741423808800126,-2.0915478241881056
417.00000000000523,131.75856677439077,0.0785828724813712,-2.097853723245888
418.2000000000052,132.1518764307738,0.08040068331461214,-2.105585055222151
419.4000000000052,132.5471803008555,0.08235570917194411,-2.113510899691671
420.60000000000525,132.93674866860948,0.08362245292093914,-2.1216852582524908
421.8000000000053,133.33562286474879,0.082178179068143,-2.128190063698459
423.0000000000053,133.72920039376882,0.08567389198158752,-2.138286393757192
424.2000000000053,134.12664065191618,0.08633393961828939,-2.146504821244725
425.4000000000053,134.52534406339464,0.0864721710152106,-2.154605143483498
426.60000000000537,134.92410269053298,0.085638738166395,-2.1637474964435333
427.80000000000535,135.3243183643758,0.0859738468113041,-2.1729750114359083
429.00000000000534,135.71988442229414,0.08892994709922745,-2.181687672276839
430.2000000000054,136.11582683959998,0.08623647669828374,-2.192965628268415
431.40000000000543,136.5085500919648,0.08807585867246771,-2.20187115705824
432.6000000000054,136.90900332843265,0.08883771689255271,-2.211887612356443
433.8000000000054,137.3043551409054,0.08926430347659992,-2.222820669333572
435.00000000000546,137.69768142752918,0.09013418525396681,-2.2338675515760364
436.2000000000055,138.0970942184532,0.09035297870560345,-2.2474588545398704
437.4000000000055,138.4912026511459,0.09191907734299792,-2.2574236166727366
438.6000000000055,138.88735291272945,0.09231544600477604,-2.2695641759454857
439.8000000000055,139.2850838122961,0.09775150240326506,-2.283903578001004
441.00000000000557,139.67630025219262,0.09809233008631524,-2.29480496359754
442.20000000000556,140.07595670670514,0.09635305803435208,-2.3073668890564996
443.40000000000555,140.4712859326083,0.0997842136149114,-2.321855017337742
444.6000000000056,140.8695019655282,0.09879627349243165,-2.3368541090959125
445.80000000000564,141.26959926858976,0.10049303749499365,-2.3504899597295092
447.0000000000056,141.67006311421514,0.09837244346583446,-2.3667238403563555
448.2000000000056,142.0669940150108,0.09569683125662114,-2.379573930503767
449.40000000000566,142.46135809300523,0.09231249969922087,-2.3945956365524177
450.6000000000057,142.85609217969136,0.09085857166308167,-2.407604653464745
451.8000000000057,143.25139007107893,0.0793690433827524,-2.4216927235406303
453.0000000000057,143.65059153081486,0.07100340984592089,-2.4299265857264714
454.20000000000573,144.04486274618503,0.062552431774512,-2.439827013229424
455.4000000000058,144.44384111137288,0.052885650434723944,-2.443876294011776
456.60000000000576,144.8421231877478,0.04641087603787417,-2.4500203101594478
457.80000000000575,145.2426420220771,0.042789383156283514,-2.4539880654216595
459.0000000000058,145.64111934199607,0.038254579796442395,-2.4542300248194167
460.20000000000584,146.03941397451786,0.04045578387130169,-2.455867642577586
461.40000000000583,146.43765894970193,0.04331631274587999,-2.456541748356743
462.6000000000058,146.8379581292794,0.05416400503376786,-2.458049039424437
463.80000000000587,147.2332443719742,0.05166013599847326,-2.457520067038966
465.0000000000059,147.6271582530767,0.04654192318977257,-2.4585265085598396
466.2000000000059,148.02224912359537,0.04196893941575104,-2.4596675093078315
467.4000000000059,148.41810633756208,0.03814902666379934,-2.4601615759225535
468.60000000000593,148.8193284299141,0.039177604637421024,-2.460809069329207
469.800000000006,149.21721295581105,0.0366490833460959,-2.4605294142258147
471.00000000000597,149.62258080927384,0.02571917713307273,-2.4622631319199573
472.20000000000596,150.02520138577805,0.018487567873662653,-2.461790959630851
473.400000000006,150.42214591830037,0.013865618086322057,-2.46147938159913
474.60000000000605,150.82222209334734,0.014953836339877138,-2.461799938207573
475.80000000000604,151.22321558980357,0.014487298070638338,-2.4617034591498257
477.000000000006,151.62077909077667,0.011889156361784586,-2.463106854224841
478.20000000000607,152.02023828809294,0.015782665658258407,-2.46322040350239
479.4000000000061,152.42100086422352,0.015156826179179739,-2.4627871889579076
480.6000000000061,152.8194418451024,0.01433164243745938,-2.462786394486527
481.8000000000061,153.21839874818738,0.013802435512073427,-2.4641000729919105
483.00000000000614,153.61418683871145,0.013860121893266464,-2.464770177522925
484.2000000000062,154.00960293510929,0.012910054254023917,-2.4647831049185336
485.4000000000062,154.4057746257133,0.017429817482695315,-2.464770181220617
486.60000000000616,154.80618047339127,0.016866622600791165,-2.4664130853024857
487.8000000000062,155.20552140485088,0.01631640541934906,-2.4657715706707766
489.00000000000625,155.60781136659452,0.01749234929627297,-2.466397896262892
490.20000000000624,156.00784727410158,0.017551805177963786,-2.466780611793003
491.40000000000623,156.40959507810854,0.019981698215389254,-2.466663049708344
492.6000000000063,156.8082900638385,0.021336813607778893,-2.4679663678872137
493.8000000000063,157.2116517455064,0.019804217722677153,-2.468708797203671
495.0000000000063,157.6091994271919,0.02021664762542924,-2.4683464249014886
496.2000000000063,158.0067763430959,0.020998109827595812,-2.468389841034252
497.40000000000634,158.40452270306037,0.019025505845391893,-2.469699823419492
498.6000000000064,158.80251430670359,0.018867195088069083,-2.468709095793817
499.8000000000064,159.20463086012762,0.020658875642992153,-2.468701853381658
501.00000000000637,159.60263958275033,0.02164230446305529,-2.4699522560814056
502.2000000000064,160.0065159786642,0.02031061486477448,-2.4707369754391006
503.40000000000646,160.4072269589512,0.02079633853335905,-2.471174328785398
504.60000000000645,160.80721137942749,0.01976338065197572,-2.4696066405357846
505.80000000000643,161.20478355189843,0.019366529441527697,-2.4710803035363034
507.0000000000065,161.59996200859808,0.02090745358631868,-2.4726547512569628
508.2000000000065,161.9938537507693,0.021973516901708012,-2.47167070459361
509.4000000000065,162.39108638967312,0.019928608117483093,-2.47324926439072
510.6000000000065,162.79215986857264,0.01957683696187895,-2.47213476033602
511.80000000000655,163.19361299906882,0.018528501579208295,-2.4727741042721707
513.0000000000066,163.58558742308801,0.019265925990075705,-2.47228882004452
514.2000000000066,164.00145030479914,0.015648246727373888,-2.473319097849041
515.4000000000066,164.40221519091307,0.017631471673934584,-2.4747105092838053
516.6000000000066,164.80201715335497,0.01980351840965386,-2.4744198153864443
517.8000000000067,165.19720775946863,0.01978481069834334,-2.4748709505061317
519.0000000000066,165.59759960673875,0.019729162265590267,-2.4750633027324334
520.2000000000066,165.9953342151162,0.020334117983159622,-2.47408358770154
521.4000000000067,166.39713668479206,0.019821224208721955,-2.4767199895540006
522.6000000000067,166.79151356775637,0.022096550205288612,-2.4770338502915656
523.8000000000068,167.18994307688652,0.021702381962184214,-2.477049922145758
525.0000000000067,167.59844507440891,0.019115084433565188,-2.47804164519793
526.2000000000068,168.0028693915675,0.018861354305509948,-2.4773709441784533
527.4000000000068,168.4003886399215,0.021057774668453932,-2.479266515552983
528.6000000000067,168.81271445913762,0.017983201367298307,-2.479676925656806
529.8000000000068,169.21583368615268,0.015705217705443975,-2.479351490665115
531.0000000000068,169.61196692466297,0.019735987056767323,-2.479963524202603
532.2000000000069,170.01331663968855,0.01926673595715822,-2.4800098679378513
533.4000000000069,170.41284569836856,0.01998159248477238,-2.4819410473957113
534.6000000000068,170.8161928703564,0.01724196714930304,-2.481000680482562
535.8000000000069,171.21762654992895,0.015303864104567633,-2.4819757802601177
537.0000000000069,171.61859920067928,0.020385131841555437,-2.481650044163538
538.2000000000069,172.0214012646085,0.021135001980375823,-2.482652676340045
539.4000000000069,172.4189544730384,0.017984700559561195,-2.4821578530381716
540.600000000007,172.81464936088346,0.021806117772966427,-2.4819887428368106
541.800000000007,173.21146844027868,0.019807429479895444,-2.4826515324699026
543.000000000007,173.61250452394816,0.01852732943939983,-2.485162922193525
544.200000000007,174.0171168756161,0.01864584369164346,-2.4837480237799383
545.400000000007,174.41968589672126,0.016519445740803995,-2.484061190985238
546.6000000000071,174.82118995301065,0.02022689444661302,-2.485647578209142
547.800000000007,175.2222512687335,0.0208559936888002,-2.4840279606803772
549.000000000007,175.62518865240955,0.01957492593015081,-2.484389895402896
550.2000000000071,176.02709063260346,0.020225371359939848,-2.4856410132395705
551.4000000000071,176.43277409592469,0.01878145062383718,-2.4847433726741404
552.6000000000072,176.8343703510464,0.024560254889259614,-2.487137422418537
553.8000000000071,177.2318956133367,0.02043957840652061,-2.4876589295335068
555.0000000000072,177.63214761852328,0.025498957782791265,-2.4880148327420244
556.2000000000072,178.0324962733423,0.02258694984276355,-2.4895686082649116
557.4000000000071,178.4370068520557,0.024336483857716695,-2.4896685996294625
558.6000000000072,178.83592982139976,0.025916272583192235,-2.491598701986434
559.8000000000072,179.23939114666342,0.029555984395621182,-2.492300397155197
561.0000000000073,179.64300860151582,0.029318921044130863,-2.4909802422426077
562.2000000000073,180.04800776839443,0.030827687448965024,-2.4919580043729335
563.4000000000073,180.45413073269825,0.03438213694323761,-2.492300256235601
564.6000000000073,180.8557757874825,0.03197057804565395,-2.492961034507129
565.8000000000073,181.25756463082826,0.03506957631159924,-2.492598118113675
567.0000000000073,181.65873588575747,0.03704824925367539,-2.4913099439017663
568.2000000000073,182.05464574018677,0.036580006954104405,-2.4939399317211413
569.4000000000074,182.45529266579257,0.03822074183879676,-2.4952918914411164
570.6000000000074,182.86408811113898,0.038728813997954525,-2.496235008709281
571.8000000000075,183.25518195468834,0.043044821621211926,-2.4977835566475353
573.0000000000074,183.66982639842234,0.0426370315233085,-2.4987243491039806
574.2000000000074,184.0725338816831,0.04391443467953027,-2.5005201140000137
575.4000000000075,184.47157067861417,0.04777637875635421,-2.5011575624541993
576.6000000000074,184.87193025638686,0.05281764073821632,-2.5018249143705114
577.8000000000075,185.27379704750186,0.05549776359953568,-2.5028801054905436
579.0000000000075,185.6788707759967,0.05445897620739237,-2.503798884795025
580.2000000000075,186.0577402460352,0.0606544634656091,-2.5044420626169828
581.4000000000076,186.4884373843104,0.0644480806208036,-2.5062527742582867
582.6000000000075,186.8917409543248,0.06463501011307793,-2.5091032870669414
583.8000000000076,187.29235827811078,0.06535634354411579,-2.510399373034982
585.0000000000076,187.69455043668637,0.06687354350301905,-2.511730743629216
586.2000000000075,188.10014716592153,0.06948006607880597,-2.513074782080205
587.4000000000076,188.50337791348804,0.07512025623028656,-2.515660198125017
588.6000000000076,188.90632560757493,0.07612827606431927,-2.516942892000885
589.8000000000077,189.306483314434,0.07823005082104673,-2.5196102147245725
591.0000000000077,189.709735049609,0.08369885904644486,-2.519589299110625
592.2000000000077,190.11918910249744,0.09008851841444487,-2.523566287784732
593.4000000000077,190.52645178850204,0.09647729214538081,-2.52575581137929
594.6000000000078,190.92715489227692,0.10097193599762744,-2.5275018163062457
595.8000000000077,191.32861065800267,0.10321017783611652,-2.531561171021151
597.0000000000077,191.72885168567962,0.10991050158684568,-2.534381850045394
598.2000000000078,192.13384064849757,0.11502417926713793,-2.5360511403219252
599.4000000000078,192.5348245519995,0.11918578234129873,-2.5406600680613862
600.6000000000079,192.9424811924351,0.12379015300592877,-2.5426506403578384
601.8000000000078,193.34551760572398,0.1284208182202955,-2.545905805290394
603.0000000000078,193.75082495444335,0.1304840777137133,-2.550182714256406
604.2000000000079,194.15332069615656,0.14105691071056292,-2.552441124889909
605.4000000000078,194.55577165620994,0.1428183323829787,-2.5593532080481753
606.6000000000079,194.95717871996825,0.14915700705854218,-2.561552292860486
607.8000000000079,195.36095262068181,0.15474552609767278,-2.5660121949388968
609.000000000008,195.76898073045245,0.15725441171241128,-2.569949069341921
610.200000000008,196.17331760850763,0.16735612794801324,-2.574898897015963
611.4000000000079,196.5776511729599,0.17348287715198163,-2.580490334185437
612.600000000008,196.9815975303965,0.1796939121623392,-2.584429570164014
613.800000000008,197.3869880444373,0.18359869800890083,-2.589673835127769
615.000000000008,197.79136066194275,0.18931553820431735,-2.5944862706959766
616.200000000008,198.1952703397203,0.19513324317375136,-2.598695745542325
617.400000000008,198.59840531774617,0.20441319470265729,-2.606261766844261
618.6000000000081,199.00270170845621,0.21136569477432499,-2.6129119102752205
619.8000000000081,199.40475911871656,0.21630933307427302,-2.618119962762436
621.0000000000081,199.81193649969612,0.2218292500828163,-2.625869358155608
622.2000000000081,200.21118521980813,0.23168864394583977,-2.633085846287701
623.4000000000082,200.61809330547024,0.23871008952976547,-2.6391643653629004
624.6000000000081,201.02055459103633,0.2452683655367861,-2.6457319398958807
625.8000000000081,201.42560467581634,0.24974078074455486,-2.652002329595069
627.0000000000082,201.82970913173259,0.2570025525426649,-2.659566936068461
628.2000000000082,202.23477012663028,0.2648691517565769,-2.667481876032161
629.4000000000083,202.64095058233414,0.267250931799233,-2.674631449467661
630.6000000000082,203.0427326558552,0.27347151554678584,-2.6824958792233153
631.8000000000083,203.44989070365986,0.27599805349369866,-2.6901920579997274
633.0000000000083,203.84917000000226,0.28501051732360105,-2.698180054977235
634.2000000000082,204.2576430840483,0.28722921534878365,-2.707621209220383
635.4000000000083,204.66273688737738,0.29241847065602555,-2.715190642786137
636.6000000000083,205.0613808926327,0.2969145277224401,-2.7237375015429044
637.8000000000084,205.4652098082914,0.3034996574282003,-2.732185117940481
639.0000000000084,205.86369128235575,0.30099468592314926,-2.739642472151224
640.2000000000083,206.27171103046004,0.3084368786076015,-2.7481236741897987
641.4000000000084,206.6745095949595,0.3146242911154201,-2.7566275264389377
642.6000000000084,207.08283054196687,0.31752443009797104,-2.765211992648588
643.8000000000084,207.48614675092463,0.3231653315123535,-2.7757688796529334
645.0000000000084,207.89503181084245,0.3303272563604307,-2.784029526106426
646.2000000000085,208.29670672945002,0.3427425466653906,-2.7931656869051658
647.4000000000085,208.70382075488064,0.35396423225461493,-2.8043547974544376
648.6000000000085,209.11125335001418,0.3687425033349513,-2.814914011574614
649.8000000000085,209.51551883875175,0.3798418289259725,-2.8268284921871674
651.0000000000085,209.91658943163577,0.3947784489784788,-2.837399882210101
652.2000000000086,210.3226896963997,0.40696564971700844,-2.8490582616048847
653.4000000000085,210.72652900417438,0.4214526672884591,-2.8607107942043815
654.6000000000085,211.1298145983249,0.43729293255133495,-2.873038832892319
655.8000000000086,211.53250359369486,0.452475385565982,-2.885644003115318
657.0000000000086,211.93833766530074,0.4648479647019481,-2.89887783092657
658.2000000000087,212.34244601257384,0.4734592678780015,-2.9106120449134485
659.4000000000086,212.74856103090895,0.4819273944736815,-2.92630398235145
660.6000000000087,213.1549685493034,0.49678856507681324,-2.940418125018524
661.8000000000087,213.55614932520663,0.5045290139260689,-2.9553768882198588
663.0000000000086,213.96298669585246,0.5139205802357295,-2.96992232794684
664.2000000000087,214.36784919510308,0.5204611746119862,-2.9836996434532557
665.4000000000087,214.76801198520482,0.522952694655159,-2.998463367327144
666.6000000000088,215.1745412900326,0.5268572191362463,-3.0145755926392894
667.8000000000088,215.58072881552192,0.525806230732149,-3.0274532566964134
669.0000000000088,215.98699325929337,0.5115788013508271,-3.040726513910614
670.2000000000088,216.39550039683473,0.4993371751574912,-3.055403539064949
671.4000000000088,216.79886390125273,0.46610516954616454,-3.0709804064318926
672.6000000000088,217.20638613673262,0.42298817645350206,-3.081284790034948
673.8000000000088,217.60447202085626,0.3513689593812378,-3.0934359095950295
675.0000000000089,218.01075407457807,0.23396357259201384,-3.1016023911936057
676.2000000000089,218.4110955273516,0.054969073865383744,-3.105671446503953
677.400000000009,218.81477834069713,-0.01443362126895209,-3.108294584666421
678.6000000000089,219.21960702847454,-0.028110563387016674,-3.109280010977843
679.8000000000089,219.62628232555912,-0.032274485777333606,-3.1105999629893626
681.000000000009,220.03398996250883,-0.037642861927970284,-3.1106223337196983
682.2000000000089,220.43921174653175,-0.04088265239517952,-3.110599835075235
683.400000000009,220.84625125297106,-0.041138008847074414,-3.1119168662029137
684.600000000009,221.24947031802927,-0.0365193798868545,-3.113229995932575
685.800000000009,221.6597912407624,-0.038254107210068056,-3.112907742187638
687.0000000000091,222.06124614073173,-0.03873528376919477,-3.1132295188993453
688.200000000009,222.46764521166108,-0.041806269070090996,-3.1137946305661997
689.4000000000091,222.86520220990673,-0.038444718995217064,-3.1129000633156947
690.6000000000091,223.26738513315064,-0.04089886438406032,-3.1132304825396018
691.800000000009,223.6755257471453,-0.037875935237349556,-3.1136526726081204
693.0000000000091,224.07554396736276,-0.04213316865905525,-3.1132413637216945
694.2000000000091,224.48885378347956,-0.044820522482637126,-3.1135497563712553
695.4000000000092,224.89186022153555,-0.04256032626464601,-3.1137591252488352
696.6000000000092,225.30101661629712,-0.046671214323570465,-3.1145499089842197
697.8000000000092,225.70307232799985,-0.0461325234919191,-3.1135598654946173
699.0000000000092,226.11153165516802,-0.04787021037143202,-3.1148576694950454
700.2000000000093,226.51132445181184,-0.045587398802585444,-3.1141978290353016
701.4000000000092,226.9139982051441,-0.04295498840576373,-3.1145496663570387
702.6000000000092,227.32331884388722,-0.047281896246242794,-3.115536140414951
703.8000000000093,227.72856512005086,-0.04342916424170706,-3.114455766014781
705.0000000000093,228.1312567664976,-0.04647244162619768,-3.114540032432349
706.2000000000094,228.54067302601226,-0.0467971289243444,-3.115859988799004
707.4000000000093,228.9471578146024,-0.04786703822447358,-3.1158601358178455
708.6000000000093,229.34989077229298,-0.05150559894667339,-3.117170172477526
709.8000000000094,229.75976767213996,-0.04825709950929857,-3.1177422473892658
711.0000000000093,230.16639089302677,-0.04631511529400412,-3.117168391261903
712.2000000000094,230.56790938366441,-0.041875560739107254,-3.118490187465949
713.4000000000094,230.9682235294117,-0.04574794583072672,-3.119809857319815
714.6000000000095,231.3687751500441,-0.04773756223139103,-3.1191415732932732
715.8000000000095,231.78106577041862,-0.04578839011854663,-3.1204686039414753
717.0000000000094,232.18989450381386,-0.04596962000920457,-3.1202040453271414
718.2000000000095,232.5965857219495,-0.049153582458618006,-3.1207900976985066
719.4000000000095,233.00551214627507,-0.046430429193491385,-3.1214499122069337
720.6000000000095,233.41136127598557,-0.04872090609233215,-3.120139912440297
721.8000000000095,233.81439572544986,-0.05075750328608386,-3.12044868153996
723.0000000000095,234.2203584430385,-0.05046613724787763,-3.1203151130357876
724.2000000000096,234.62334298375313,-0.056644608056102275,-3.120673036734013
725.4000000000096,235.02682016390867,-0.05516898986738972,-3.121790352900421
726.6000000000096,235.4364442612106,-0.05807078526472931,-3.1224497931062833
727.8000000000096,235.8379494326031,-0.05481964877635548,-3.1221198167018085
729.0000000000097,236.2440699215009,-0.05450984521322777,-3.1227167557153024
730.2000000000096,236.65253455696546,-0.04971950834708916,-3.124410062601045
731.4000000000096,237.05585212940855,-0.049934562537949034,-3.122388529603221
732.6000000000097,237.46514437846844,-0.051368316170356865,-3.1237617047200072
733.8000000000097,237.86833981032777,-0.054211742733191626,-3.1250687588974353
735.0000000000098,238.27548686245765,-0.055567125553171115,-3.1263214310237903
736.2000000000097,238.68527633196373,-0.05605554792448619,-3.1257399407003255
737.4000000000098,239.09279203269347,-0.05748730448918904,-3.1256909377665285
738.6000000000098,239.49432611896486,-0.05930879701202496,-3.125680624460851
739.8000000000097,239.8982459512315,-0.05516283939768085,-3.1260659696668176
741.0000000000098,240.30918145644475,-0.05654321783107763,-3.1270564466485236
742.2000000000098,240.71241572814046,-0.05839728186729598,-3.12562499110148
743.4000000000099,241.12056816543225,-0.05841238126026882,-3.126727290015987
744.6000000000099,241.52906526778304,-0.054833717504984225,-3.1286997825237437
745.8000000000098,241.93292979202835,-0.059708955441240885,-3.1270500288321132
747.0000000000099,242.34237950274516,-0.05878774184386426,-3.1273701319786404
748.2000000000099,242.7518528569265,-0.060502715932553075,-3.1283863400007084
749.4000000000099,243.15694106658614,-0.0616332097682879,-3.126645918632757
750.6000000000099,243.56543081745647,-0.061061487101518264,-3.1280276600173873
751.80000000001,243.9694136812602,-0.06116754527329982,-3.127036988173079
753.00000000001,244.37293676939083,-0.0581660548783649,-3.1283406368053805
754.20000000001,244.77745492837974,-0.05727950628588663,-3.1283601512268797
755.40000000001,245.18156150302164,-0.05320418947129801,-3.128389055999378
756.60000000001,245.5938412336011,-0.051693064322480886,-3.130343443223147
757.8000000000101,245.99744537459023,-0.05129009965141229,-3.12836982916635
759.00000000001,246.40693269143222,-0.05321320226101367,-3.1282499398114023
760.20000000001,246.8155187067309,-0.050348869625542525,-3.128364901657811
761.4000000000101,247.22483486687432,-0.052171806494013984,-3.129367452769954
762.6000000000101,247.6315193262554,-0.04992070196993148,-3.1296811864514096
763.8000000000102,248.04303777000717,-0.04848350593180051,-3.128039989984614
765.0000000000101,248.44378626505616,-0.05311921707884082,-3.1287063194045865
766.2000000000102,248.85922513321125,-0.0529897388392202,-3.1285165490982205
767.4000000000102,249.25364236738264,-0.04818088974088597,-3.129334888034439
768.6000000000101,249.66634490473726,-0.043867447924418324,-3.130681009542414
769.8000000000102,250.07450136395536,-0.04650690573331784,-3.1306701150055356
771.0000000000102,250.48250000000382,-0.04511545598960032,-3.1316601375411723
772.2000000000103,250.88652655203242,-0.04695690373151984,-3.1319850667194657
773.4000000000103,251.28817738001504,-0.04527648240526405,-3.1306665415464394
774.6000000000103,251.70608656656637,-0.04071775116568621,-3.130973439505113
775.8000000000103,252.11679742546517,-0.0418675067295764,-3.132970121561993
777.0000000000103,252.5215593018505,-0.041797659418369326,-3.131604163234106
778.2000000000103,252.92201846133148,-0.03641343872005609,-3.133302487725776
779.4000000000103,253.32877771280178,-0.04362419655727612,-3.1319800400960984
780.6000000000104,253.73485234581187,-0.04330810038585442,-3.1334166974039133
781.8000000000104,254.13592877588846,-0.040571934062642256,-3.1346221667363934
783.0000000000105,254.54639606480126,-0.03776684426055987,-3.1326411053427377
784.2000000000104,254.95450629138165,-0.03619006745938069,-3.13395685229794
785.4000000000104,255.3592742725882,-0.0389428105191969,-3.133630172008869
786.6000000000105,255.76782970363922,-0.03522247465961237,-3.132969821511567
787.8000000000104,256.17784944930673,-0.03473470506657872,-3.133630179906123
789.0000000000105,256.58663666611835,-0.03382132006837013,-3.134280060999859
790.2000000000105,256.9926163855306,-0.032607235468274265,-3.134280060999933
791.4000000000106,257.40206156350666,-0.03258054509912367,-3.1342908949667203
792.6000000000106,257.80128993735053,-0.0346346809951128,-3.133253190490998
793.8000000000105,258.22127124331377,-0.03636962441818237,-3.1346201950039543
795.0000000000106,258.6322095562108,-0.04059506976974925,-3.1333001885631404
796.2000000000106,259.0387947044322,-0.038562012581460525,-3.13426444516256
797.4000000000106,259.4403211603336,-0.03794728786343704,-3.133960240836479
798.6000000000106,259.84276453090257,-0.03887734009765054,-3.1339600531710703
798.9000000000107,259.94435433162243,-0.04118103620433744,-3.133977916160515