File: 01_Data/PEVA/STA/N2/10K_min/PEVA_STA_N2_10KData_240801_R2.csv
##Temp./Â°C,Time/min,DSC/(mW/mg),Mass loss/mg
51.0,10.85,0.041777075436894684,0.003234314695946594
52.100000000000016,11.126395788246333,0.08171887923555632,0.005085888564808627
53.20000000000003,11.329073956566528,0.11685625014782142,0.005141577329053071
54.30000000000005,11.498671473037383,0.13967472993437147,0.005586460854269504
55.40000000000006,11.652797942315946,0.16497609727584095,0.00594729966327634
56.50000000000008,11.797774928046428,0.17774142653463443,0.00598897853051561
57.600000000000094,11.932390797346454,0.192890606289426,0.004933912193272327
58.70000000000011,12.063162156906845,0.20493520705707224,0.004449843195415859
59.800000000000125,12.191121149584559,0.21420580561971736,0.00494502517882367
60.90000000000014,12.313711192611628,0.22325714747186165,0.004746111161805011
62.000000000000156,12.436354496963284,0.23004852858321545,0.004758347441969235
63.10000000000017,12.557383151825118,0.23477860591343802,0.004679190750253248
64.20000000000019,12.679650631384451,0.23830612093837455,0.006028803611628497
65.30000000000021,12.79616123453344,0.24168547347809488,0.0047189870144075385
66.40000000000022,12.91570016439351,0.24401493496559468,0.005645323650566247
67.50000000000023,13.032199823990329,0.24580808431809587,0.004711586082250641
68.60000000000025,13.149514920038104,0.2449991219770653,0.004771067976165888
69.70000000000027,13.265345967850285,0.2482407474411792,0.004729620721122707
70.80000000000028,13.381931264528593,0.24811273497436392,0.00601698730306488
71.90000000000029,13.496847724662901,0.2523781479608176,0.0047174652599615285
73.00000000000031,13.610644015375517,0.2532420027472,0.004707263132758932
74.10000000000034,13.726943218073178,0.2550614648915275,0.004632300762144936
75.20000000000034,13.840641512009844,0.25952027849895964,0.0034369580363922125
76.30000000000035,13.954087155449288,0.2599771819012475,0.004757557598149553
77.40000000000038,14.069740392361327,0.26108349843676937,0.004699473652101993
78.5000000000004,14.180700706915708,0.26309477306055307,0.004718780356507857
79.6000000000004,14.293683738715506,0.2632404609481185,0.003979992875936311
80.70000000000041,14.407604212045904,0.26516665813952045,0.005751347563415443
81.80000000000044,14.520693518702098,0.2675688626420283,0.004709693491055766
82.90000000000046,14.630703005744287,0.270251345286447,0.0033905997616621164
84.00000000000047,14.743253569382054,0.27102304138185485,0.003361762896782139
85.10000000000048,14.854994447168426,0.274409821244066,0.003469718822390888
86.2000000000005,14.964837060523216,0.27746051720818343,0.0047204587294382705
87.30000000000052,15.074091008140737,0.2759838357942046,0.006023944588231522
88.40000000000053,15.186375342575637,0.27928257630232034,0.004030121917665497
89.50000000000054,15.295196554754678,0.2798770578799159,0.004050572242027428
90.60000000000056,15.405154108339682,0.2815025137379461,0.003413392521359526
91.70000000000059,15.515082026557932,0.28513000002237954,0.0048835061983822925
92.8000000000006,15.621230248256557,0.2849565738650761,0.005391428819853772
93.9000000000006,15.733705605166172,0.28816130879001234,0.0053727092524553655
95.00000000000063,15.840704175085534,0.29244260973730807,0.005039680370284572
96.10000000000065,15.95066776869629,0.2937709719432524,0.0043807896832746
97.20000000000066,16.057957908211215,0.2959416585458885,0.004046497483838785
98.30000000000067,16.166251504830992,0.2981989906787237,0.005369968541714343
99.40000000000069,16.27434969034726,0.2995620079094543,0.004424706404755341
100.50000000000071,16.38243470578928,0.30073002938900206,0.005478058655397078
101.60000000000072,16.489811996535305,0.30226282111443714,0.004057709670445497
102.70000000000073,16.59613509376471,0.3025015394861046,0.005370092676167282
103.80000000000075,16.70415368616669,0.30117339638118823,0.004437835344850427
104.90000000000077,16.811953669649576,0.30129691924956603,0.00533929068050476
106.00000000000078,16.919071175311036,0.30356582618602257,0.004060567420267169
107.10000000000079,17.026238684107618,0.30069740343045215,0.0040340446229931715
108.20000000000081,17.132789667072135,0.30267563906462414,0.004390899478038612
109.30000000000084,17.239714861959296,0.3025690021051366,0.0053785637033909595
110.40000000000084,17.347861161188263,0.3053267426657973,0.004060277764536657
111.50000000000085,17.454251605520486,0.30786118515410577,0.0052127296133654966
112.60000000000088,17.56210148410232,0.30909378474865346,0.005369915325325714
113.7000000000009,17.66899876258545,0.31218423211929913,0.003983445782971273
114.8000000000009,17.77496882845424,0.3133957152924758,0.005370289416714691
115.90000000000092,17.881414738271896,0.3134948389294907,0.005370420002189569
117.00000000000094,17.990000000000094,0.31318558949397124,0.005538621355777984
118.10000000000096,18.096774510445062,0.3143227224489942,0.005362785027320349
119.20000000000097,18.20293599595373,0.3156419205415566,0.005527208177753984
120.30000000000098,18.30626573642623,0.31662351299164415,0.0053800158323378255
121.400000000001,18.416112782574128,0.31799114798430184,0.005380019261198576
122.50000000000102,18.522395616514274,0.32177741443742836,0.005370467392832978
123.60000000000103,18.62963763986048,0.3207165496373703,0.00544134984566913
124.70000000000104,18.735399916022306,0.3209478391109508,0.006029933265160103
125.80000000000106,18.842257539461794,0.3221093513963811,0.006030043610739
126.90000000000109,18.949553620962593,0.32233095993001726,0.00570292848294951
128.00000000000108,19.055525472481122,0.32444104517532457,0.005370027392247678
129.1000000000011,19.161100606509915,0.32725052111981157,0.00438048030964211
130.20000000000113,19.267527331634636,0.32904133751794573,0.005718325620972742
131.30000000000115,19.37291752682724,0.3282286974403563,0.007010134560842651
132.40000000000117,19.478613538177466,0.3297313126616963,0.0066417692652986915
133.50000000000117,19.58470045515903,0.3307660356447455,0.005700184661948882
134.6000000000012,19.688611074747314,0.330976648150175,0.005656054288006196
135.7000000000012,19.795168519063726,0.3347235799444306,0.008449840607828385
136.8000000000012,19.90159601295035,0.33492746280153485,0.008372005504739377
137.90000000000123,20.007988556286655,0.33676577509769867,0.005383338394275405
139.00000000000125,20.11329151839461,0.3379287813336327,0.006690152349172251
140.10000000000127,20.21910136384912,0.3412007517172033,0.006690027921624875
141.2000000000013,20.32291790156901,0.3382274638170393,0.008009973815018334
142.3000000000013,20.429725245294676,0.34251287820611287,0.0066900432906003005
143.4000000000013,20.534353276391627,0.3426299038490752,0.0066898859220749785
144.50000000000134,20.640280297888822,0.3416372731356163,0.006699527672215488
145.60000000000133,20.74592689086393,0.3425462956272596,0.007670019840574582
146.70000000000135,20.851728944656607,0.3449079033790965,0.006689918410518025
147.80000000000138,20.957330829022148,0.34473964721117767,0.008007450507214742
148.9000000000014,21.061338017164566,0.34708385834194555,0.008010173239392238
150.00000000000142,21.16455752467406,0.34679722499080023,0.00670958332289473
151.10000000000142,21.27094880220735,0.34839261422080314,0.006696295845959099
152.20000000000144,21.376867146531435,0.3496102787584716,0.00800993954329865
153.30000000000146,21.480451473245683,0.35138320952692403,0.008049577581479284
154.40000000000146,21.58673236217262,0.350975864353138,0.007302048221944801
155.50000000000148,21.691071621546307,0.3527553410070614,0.008010131027224254
156.6000000000015,21.796796603725397,0.35279184443397593,0.008988857519027782
157.70000000000152,21.89978839947735,0.3524461202877167,0.008989862723774777
158.80000000000155,22.006080308059943,0.35380357653731664,0.008002699761235021
159.90000000000154,22.111568253546338,0.35587085423877474,0.0073155311160713055
161.00000000000156,22.215377094319344,0.35461245156823606,0.007347234703313887
162.1000000000016,22.320894826243148,0.3541940436768911,0.008659913538243913
163.20000000000158,22.424295111782587,0.3589234873580467,0.008660717995984335
164.3000000000016,22.529202206874295,0.35825580445193594,0.008625518080765282
165.40000000000163,22.635004623398295,0.3583609101564025,0.00965006344911501
166.50000000000165,22.739536583501998,0.3610126766667934,0.00867009474444913
167.60000000000167,22.845089667642938,0.3590601613369766,0.007240104663733149
168.70000000000167,22.9488667064956,0.3576916556863483,0.007240073652680756
169.8000000000017,23.053857744304526,0.35774562778405183,0.00856695737260349
170.9000000000017,23.157605128940872,0.36196780231921233,0.008559460353469106
172.0000000000017,23.26175277470501,0.3624472606724449,0.007239822888166714
173.10000000000173,23.367192689222435,0.3626828775658568,0.005921588554872237
174.20000000000175,23.472364941178007,0.3627490281877921,0.007234024477437373
175.30000000000177,23.577775129923232,0.3620897268268126,0.007239839998005593
176.4000000000018,23.682085078729948,0.3633141617616915,0.007558928378685437
177.5000000000018,23.786862329467606,0.36319657617232703,0.008550667913564958
178.6000000000018,23.89158839271027,0.36471927384293856,0.008549829774832318
179.70000000000184,23.997994768674676,0.366530420853163,0.005919945235061341
180.80000000000183,24.101166031510562,0.3669657614870836,0.007864427725959189
181.90000000000185,24.205721346675315,0.36666794452725693,0.007229964898718855
183.00000000000188,24.310156814766774,0.3637317121774597,0.007229958004943526
184.1000000000019,24.415286269373645,0.36352356164221433,0.007229777404797133
185.20000000000192,24.518654794995758,0.3623614546018512,0.00591985914885651
186.30000000000192,24.622269826057224,0.3646339772280931,0.007229665992950274
187.40000000000194,24.72951668387711,0.3634362719659636,0.005935680260458653
188.50000000000196,24.83302793761007,0.36237842041899304,0.007239380494582726
189.60000000000196,24.936368647415527,0.364661217203071,0.006208253145205234
190.70000000000198,25.042037004317265,0.36353755037120905,0.006250000201206696
191.800000000002,25.147132176635836,0.3629258386468299,0.0066925674614877195
192.90000000000202,25.249119262442257,0.36229795542519705,0.005919996967058694
194.00000000000205,25.354949292402683,0.3649520314585839,0.005546850500839362
195.10000000000204,25.458398690136132,0.36430977280139665,0.003938488214236813
196.20000000000206,25.563207544388632,0.36373195979020956,0.005259898607075542
197.3000000000021,25.66801318623725,0.36514163557965507,0.0052589635874555896
198.40000000000208,25.771697535640513,0.3635308444255472,0.004266518351109028
199.5000000000021,25.875678132432594,0.3659778297979659,0.005259068447034387
200.60000000000213,25.981939361825,0.3622877235521109,0.003934066808912284
201.70000000000215,26.087285358173126,0.3635924721077788,0.0021966855906816463
202.80000000000217,26.192132466112408,0.36256121376806316,0.0019698400787584447
203.90000000000217,26.295850512520115,0.3641629025593307,0.001969840000003664
205.0000000000022,26.401467734952174,0.365790407752562,0.0019698514996706606
206.1000000000022,26.50490567901396,0.3648710228750476,0.0013104715641274467
207.2000000000022,26.609435212943765,0.36154799241752666,-0.0012898982881175414
208.30000000000223,26.714133546351068,0.364325001045974,-0.0006699305891579854
209.40000000000225,26.81862406651516,0.36169933708758695,-0.0006699260011346908
210.50000000000227,26.922851417494226,0.36142497973848275,-0.0006679213269915607
211.6000000000023,27.02870418632525,0.3640750527672272,-0.0033914027225954158
212.7000000000023,27.132766338549406,0.36305350055631447,-0.004710080772124314
213.8000000000023,27.23613500134712,0.36432615561105663,-0.004610942100947035
214.90000000000234,27.341847431327867,0.3643482503725659,-0.005930144619400224
216.00000000000233,27.4459353996867,0.36189038156574505,-0.00728139700257735
217.10000000000235,27.550750992504007,0.3640660069414712,-0.007265335106765747
218.20000000000238,27.65608014494921,0.363537818372774,-0.008239824521155015
219.3000000000024,27.760000000000232,0.3655141041934904,-0.00955991200000117
220.40000000000242,27.86565408100627,0.36608562737731765,-0.010870050403882558
221.50000000000242,27.970000000000198,0.36433634146467586,-0.012190198163056998
222.60000000000244,28.073981104237852,0.36464060582618085,-0.013433231868818396
223.70000000000246,28.1786118005831,0.3640687668646847,-0.01482779190300132
224.80000000000246,28.282871179537445,0.3607244226159816,-0.01746110671260581
225.90000000000248,28.386583469043064,0.36011984086116655,-0.019936180253754543
227.0000000000025,28.492093056085128,0.36507421253114414,-0.021075280743438896
228.10000000000252,28.594568613579266,0.3612047887723171,-0.022394287709297966
229.20000000000255,28.700805651714283,0.36098980726057617,-0.02506056189059036
230.30000000000254,28.80469991839161,0.35993991334598663,-0.02870819117619572
231.40000000000256,28.908133300023906,0.3599586668827155,-0.030313769070811958
232.5000000000026,29.013749639677766,0.3575847553064184,-0.032978680757281165
233.60000000000258,29.116413545554924,0.3558998955142938,-0.03555852788998681
234.7000000000026,29.222469851296253,0.35144839587060606,-0.03826582346585017
235.80000000000263,29.326585774509496,0.3484437416492101,-0.04114358189600864
236.90000000000265,29.430851091026103,0.3480653534221094,-0.04381540239725723
238.00000000000267,29.535389084744033,0.34562925041302783,-0.04748549694753512
239.10000000000267,29.641217756429754,0.3430913160059368,-0.05060484202284421
240.2000000000027,29.74536626888996,0.33760873045697215,-0.05353130729751632
241.3000000000027,29.848938002736215,0.33478974585925814,-0.05755737507854963
242.4000000000027,29.953439187625314,0.33359073386426497,-0.0630564004836689
243.50000000000273,30.05789974665332,0.32972769927579737,-0.0677036999966858
244.60000000000275,30.16194677268895,0.3293898276591207,-0.07094521975947243
245.70000000000277,30.267486236027487,0.3301705866638933,-0.07681038900536796
246.8000000000028,30.37171600659862,0.3383150023343289,-0.08114874580922082
247.9000000000028,30.476932243355513,0.36318880968271205,-0.08752794541404674
249.0000000000028,30.58361696418812,0.39323870300568675,-0.09405483544232274
250.10000000000284,30.69070362403523,0.4165927352659309,-0.10061125834317286
251.20000000000283,30.795053315419946,0.4343025658645465,-0.10834751974740531
252.30000000000285,30.90060324194406,0.44456505939397495,-0.11640200419131963
253.40000000000288,31.004415345135598,0.4550461825279406,-0.12578374230287936
254.5000000000029,31.11149173701111,0.46198761525901855,-0.13521253633559116
255.60000000000292,31.21594887479528,0.4677158318686909,-0.14482393449531683
256.7000000000029,31.32191670296696,0.47598478924139576,-0.1536614435617385
257.8000000000029,31.426323116584236,0.4808019011746616,-0.16307129561724087
258.90000000000293,31.531938484363984,0.48942314529921793,-0.17523187160004827
260.00000000000296,31.637751406690604,0.4975618562857811,-0.18799785883673836
261.100000000003,31.740979080905102,0.5061415027739216,-0.1996598969314478
262.200000000003,31.848347472400416,0.5151782228100381,-0.21384850766687258
263.300000000003,31.954566165928227,0.5245812459745993,-0.22583547093456158
264.40000000000305,32.06066821500701,0.5390350041339826,-0.24175352874173894
265.50000000000307,32.16473867313446,0.5507435306807995,-0.2581826528702962
266.6000000000031,32.27175961306431,0.5649563232066916,-0.27658037783549005
267.7000000000031,32.37658639865116,0.5823338970634566,-0.29461748575220037
268.8000000000031,32.482851783475084,0.5985810591678438,-0.3152911029541019
269.9000000000031,32.58897727747672,0.6162481678212761,-0.33845945525558907
271.0000000000031,32.69412674874479,0.6331025528553833,-0.3600199673462887
272.10000000000315,32.800303171073054,0.6512547290447839,-0.3872928263200648
273.2000000000032,32.906038690998685,0.6700327522605747,-0.4144024510695212
274.30000000000314,33.011997135195735,0.6869238778764197,-0.44437816313187284
275.40000000000316,33.11786295780695,0.704066958898574,-0.4761435734721018
276.5000000000032,33.224299175427056,0.7207739496639816,-0.5099208516599774
277.6000000000032,33.33049507900251,0.7383463567117494,-0.5463697725879877
278.70000000000323,33.43512850180144,0.758108173292773,-0.5834434840071427
279.80000000000325,33.544459660074736,0.7769544432030213,-0.6231827956972649
280.9000000000033,33.64918719527332,0.7969281971204749,-0.6647868994661916
282.0000000000033,33.755739963487756,0.8176770228909938,-0.7078244022000693
283.1000000000033,33.861182776229754,0.8349508545955415,-0.7548097247965231
284.20000000000334,33.968607013863206,0.8576423727862901,-0.8027101809937389
285.30000000000337,34.07618486699903,0.8765415447461744,-0.8526644751864838
286.40000000000333,34.183415414947746,0.8958560025846989,-0.9088740654174425
287.50000000000335,34.29029538058212,0.9195432655893718,-0.9635343389385733
288.6000000000034,34.39646501114301,0.9468664173641517,-1.0219525433788959
289.7000000000034,34.50381828090961,1.0049297335202363,-1.0857973328758006
290.8000000000034,34.612056238419065,1.0285668609678211,-1.1483041762048822
291.9000000000034,34.71705796688191,1.0353934375084202,-1.2139855978005198
293.0000000000034,34.8238608521273,1.0485750080143008,-1.2831459480070144
294.10000000000343,34.928895577740136,1.0517430663600509,-1.3510822625561167
295.20000000000346,35.035943080932434,1.0538859517930281,-1.4226668499844952
296.3000000000035,35.141373975122626,1.0532187198035015,-1.495654081445534
297.4000000000035,35.246906452833024,1.0463453516788435,-1.5665316539554537
298.5000000000035,35.352900245394544,1.0341815071745484,-1.641939112495872
299.60000000000355,35.45658686183812,1.015062567299272,-1.7145131819444837
300.70000000000357,35.55922729689275,0.984426001062797,-1.7835888077505473
301.8000000000036,35.66453179078752,0.9375654679761136,-1.8537547612429988
302.9000000000036,35.76813296080246,0.8951855120756744,-1.9179225885635587
304.0000000000036,35.870482820843044,0.8354007692425705,-1.97986123368513
305.1000000000036,35.973737061435116,0.7926076947493916,-2.0379370212297254
306.2000000000036,36.077079829563566,0.7501338501774435,-2.091521308835324
307.30000000000365,36.18076067143581,0.7061832841729938,-2.140566929129462
308.4000000000037,36.28423775638012,0.6674962296654483,-2.1841910684772126
309.5000000000037,36.38703861212736,0.629093395970322,-2.2254590084504127
310.60000000000366,36.490681237010506,0.5930370606534408,-2.260828230865159
311.7000000000037,36.59172486688395,0.5631540590585109,-2.2931760920754747
312.8000000000037,36.696548222451675,0.5363558723695068,-2.3260967235092482
313.90000000000373,36.800923115598884,0.5099978559242699,-2.353984929547453
315.00000000000375,36.90453275948387,0.4860607588468935,-2.3810092410925017
316.1000000000038,37.01009128056094,0.4659049636906927,-2.4052787194574226
317.2000000000038,37.115104386989984,0.4457681060383183,-2.430804787617434
318.3000000000038,37.22066676810017,0.42993939952694493,-2.45303761967273
319.40000000000384,37.32448776096934,0.41238501883946155,-2.4743507863075633
320.5000000000038,37.429526183283656,0.3964782003733056,-2.493017296295063
321.60000000000383,37.534481830465715,0.3825096337501126,-2.513088001212661
322.70000000000385,37.639324600902484,0.3705217374965475,-2.531681153952106
323.8000000000039,37.74380472976059,0.3546533107591965,-2.548478812750112
324.9000000000039,37.84929635807964,0.3398966399584302,-2.5648860383169994
326.0000000000039,37.95525870110736,0.32842313082549257,-2.5803419114139468
327.10000000000394,38.0594995574207,0.31545309024505785,-2.596083458837702
328.2000000000039,38.16476218703965,0.3041054183117846,-2.6117866685868805
329.30000000000393,38.26962172647949,0.291273003629652,-2.625968874501046
330.40000000000396,38.374330050956644,0.2819279268036774,-2.6375849429432856
331.500000000004,38.48074365806166,0.27071724480297554,-2.651191511578749
332.600000000004,38.58486225288051,0.25650513595474367,-2.6636138718191327
333.700000000004,38.69055474849727,0.2471175406163062,-2.6752806470719
334.80000000000405,38.7957637679702,0.2313858194416354,-2.6860537906713726
335.90000000000407,38.901541749191715,0.22117818419675173,-2.697290247464381
337.0000000000041,39.00663215634976,0.21114496233833036,-2.7073002715570436
338.10000000000406,39.11329307730174,0.20030921401082802,-2.718852859159397
339.2000000000041,39.218997385898916,0.18560293111366777,-2.727054964383292
340.3000000000041,39.32411264071339,0.1764286987817969,-2.735379066063044
341.4000000000041,39.429632173166475,0.1620105363674118,-2.743280724053929
342.50000000000415,39.53464589573828,0.15049820518126333,-2.753103889673077
343.6000000000042,39.640481177768166,0.14301166227301199,-2.7594183148919162
344.7000000000042,39.74605578655905,0.13239529092731894,-2.7660003963293684
345.80000000000416,39.85091558214507,0.12330265226772541,-2.773642896866656
346.9000000000042,39.95540004118944,0.11242505428395644,-2.779939282754526
348.0000000000042,40.06310024511742,0.10514173440858698,-2.7857610371551664
349.10000000000423,40.168862407977024,0.0975292840157711,-2.790026132437819
350.20000000000425,40.27522263570594,0.08948357734960188,-2.796511058448296
351.3000000000043,40.38077906490002,0.08209936516364413,-2.7982947708658066
352.4000000000043,40.48786641743387,0.07938781391427474,-2.802836806097482
353.5000000000043,40.592114127486354,0.07161897240901771,-2.8074471551946596
354.60000000000434,40.700930143758725,0.06759454207115878,-2.8100465185757315
355.7000000000043,40.80552001558556,0.061169719696467784,-2.814072523308307
356.80000000000433,40.911184762524826,0.05917957041908917,-2.8182335175907607
357.90000000000435,41.01881104099862,0.05216487956464544,-2.8195068317554908
359.0000000000044,41.122361749737635,0.050494441132098,-2.8221674168971886
360.1000000000044,41.23040447914777,0.04559693329737646,-2.824839974354463
361.2000000000044,41.339157806802085,0.04239205188954598,-2.8274763181587788
362.30000000000445,41.4458112557676,0.042988797413252566,-2.8287858639463717
363.4000000000044,41.55139505566567,0.03906208296694258,-2.8314222975899153
364.50000000000443,41.65950262318086,0.037366104297437364,-2.831427602280021
365.60000000000446,41.765296799525615,0.03668510721574059,-2.8340629436696902
366.7000000000045,41.873403052980514,0.03593098714759435,-2.8341946531032485
367.8000000000045,41.97882249192295,0.036356692816777336,-2.8366231483285214
368.9000000000045,42.087070423813216,0.035301703344646995,-2.8380070619068194
370.00000000000455,42.193198669141445,0.03733832914311641,-2.838020274688139
371.10000000000457,42.29981503159705,0.036093094841266105,-2.8403203350866235
372.2000000000046,42.40672565443199,0.03418064627867512,-2.840986102073313
373.30000000000456,42.51422794003925,0.03444628410879513,-2.842395542577639
374.4000000000046,42.62037824788894,0.03318338483931038,-2.8416252126699595
375.5000000000046,42.72795039515139,0.034459061035362115,-2.8426458396308822
376.6000000000046,42.834708072796495,0.034617072102896884,-2.843989733034441
377.70000000000465,42.941661939403154,0.03284345294648139,-2.8429826313025712
378.8000000000047,43.04939813925289,0.03305145125459896,-2.844270726446034
379.9000000000047,43.1560007580331,0.029958381305135173,-2.844269465918258
381.00000000000466,43.26367512990521,0.031102565447684416,-2.845758459820568
382.1000000000047,43.371303920454146,0.03070599843849786,-2.8469099137684215
383.2000000000047,43.476582649998704,0.027015819404096586,-2.8469098774453574
384.30000000000473,43.58505807971455,0.028824605145645776,-2.8478125895661544
385.40000000000475,43.69209783027266,0.026847778575274983,-2.846900183755131
386.5000000000048,43.79969640534745,0.028381495053645178,-2.848211277723398
387.6000000000048,43.90789746242883,0.028867372393459156,-2.8482201966212837
388.7000000000048,44.01465745707529,0.025401450702258632,-2.8495464117616716
389.80000000000484,44.122163834395316,0.022711167059962012,-2.8509030937311683
390.9000000000048,44.228225008980324,0.02113110483003,-2.85086023986046
392.00000000000483,44.3376709446986,0.019946176421226536,-2.8504856878598304
393.10000000000485,44.444569311673604,0.018035551086760027,-2.852110055062969
394.2000000000049,44.551500006769004,0.01635173298924064,-2.8528673707488483
395.3000000000049,44.658223802269895,0.013937100338582642,-2.85315577398895
396.4000000000049,44.76601651891413,0.011449461369424263,-2.8531570983560712
397.50000000000495,44.87311597081831,0.009283707338070712,-2.8544796728220305
398.6000000000049,44.980470523036864,0.006303280516464671,-2.8557900785514976
399.70000000000493,45.08804901248699,0.003047688227099332,-2.8557900736723516
400.80000000000496,45.195572972542664,0.0004359393675996692,-2.8570996548171075
401.900000000005,45.30315351327408,-0.0017416529553986315,-2.8584333182435078
403.000000000005,45.41117678407922,-0.0035708862637613414,-2.8584406328603364
404.100000000005,45.51893654104728,-0.0070845513990858144,-2.860407258168319
405.20000000000505,45.625728913250256,-0.008528061149458921,-2.8601946757985917
406.30000000000507,45.733618745461435,-0.009707584410623582,-2.860632231730114
407.4000000000051,45.840820540008856,-0.010707586419489434,-2.8617283035165646
408.50000000000506,45.94797708442849,-0.009592833761093544,-2.863049963051605
409.6000000000051,46.0556962062842,-0.012820526657799203,-2.864359611550662
410.7000000000051,46.16317260460747,-0.014353021531689159,-2.8650155977801095
411.8000000000051,46.27000095862007,-0.01888957987122586,-2.8663400408806283
412.90000000000515,46.37895229640217,-0.017505622315383107,-2.8676598446634882
414.0000000000052,46.48787977355729,-0.02052508303730427,-2.868969228596794
415.1000000000052,46.593524587854944,-0.02658554566695681,-2.8706497224028116
416.20000000000516,46.70249217192084,-0.02328514592115294,-2.871157067253339
417.3000000000052,46.810912707134285,-0.02554512149398569,-2.872536652802812
418.4000000000052,46.91851708622904,-0.02852078390823376,-2.8735797816796635
419.50000000000523,47.02456428028529,-0.03160863825121263,-2.8762087258608737
420.60000000000525,47.13458097079399,-0.035102882604457264,-2.8788537137401535
421.7000000000053,47.24267374680869,-0.040273446863312135,-2.880174267827331
422.8000000000053,47.35052289509417,-0.04336116533432932,-2.8827979974397655
423.9000000000053,47.4586299910037,-0.04448486218227998,-2.8854358886390052
425.00000000000534,47.56678957433133,-0.045372292593475194,-2.8879329488942855
426.1000000000053,47.674455280707974,-0.04731458046182313,-2.8908166596665184
427.20000000000533,47.7824806486616,-0.05385844197148382,-2.8924407495217723
428.30000000000535,47.89058655424167,-0.0554447093170487,-2.8950982374076286
429.4000000000054,47.99876839860791,-0.05698206781250148,-2.897753490224728
430.5000000000054,48.10641513493952,-0.05816798086974906,-2.9005814734062945
431.6000000000054,48.21436224297673,-0.06217158918176846,-2.9044456739753923
432.70000000000545,48.32212833041895,-0.06395161240207248,-2.9086241821670393
433.8000000000054,48.43019615752631,-0.0690924067508858,-2.9120685953067964
434.90000000000543,48.53860058742561,-0.0648921134530327,-2.91600634176039
436.00000000000546,48.647983893380925,-0.06843807386858458,-2.9203148667266188
437.1000000000055,48.75517072470741,-0.06712247204014865,-2.9251243744760442
438.2000000000055,48.86405195256809,-0.0654823082865219,-2.9294296268682154
439.3000000000055,48.97220198818023,-0.06458243773472505,-2.935180082976573
440.40000000000555,49.08059527586115,-0.059665068719014336,-2.941384110598025
441.50000000000557,49.1894544754636,-0.058147188989965404,-2.9464973011825295
442.6000000000056,49.29671696749661,-0.05480297520520683,-2.9541767386639344
443.70000000000556,49.406241429110715,-0.04825359043251831,-2.9596178491984837
444.8000000000056,49.51568477775402,-0.040980093737099654,-2.9665345454989485
445.9000000000056,49.62536346953809,-0.0316869325518665,-2.9742641198749644
447.0000000000056,49.7334518344841,-0.024474993960341695,-2.980595663758782
448.10000000000565,49.83962864642885,-0.014607458840033338,-2.9870752271906875
449.2000000000057,49.952460254005665,-0.0037173279627129574,-2.995105987433531
450.3000000000057,50.06092387145731,0.008234192322264633,-3.0063546347269794
451.40000000000566,50.17075101665675,0.024048629549629386,-3.0131960250024736
452.5000000000057,50.28041198867398,0.06040096073543477,-3.0245812136463384
453.6000000000057,50.387559503734536,0.09110697511345434,-3.0408034395620667
454.70000000000573,50.499901666921346,0.11158650823610783,-3.058439893753776
455.80000000000575,50.607559682209896,0.13362080812156885,-3.0774105616560083
456.9000000000058,50.71951888101052,0.16926554146609618,-3.0987234351516326
458.0000000000058,50.82874966088169,0.18656279856043367,-3.127321883365904
459.1000000000058,50.9377480968663,0.18048887830129434,-3.1514961681958047
460.20000000000584,51.04646772957156,0.16215267338949113,-3.172161604448226
461.3000000000058,51.15524283966291,0.14757779447695718,-3.1905479813824114
462.40000000000583,51.26460583903235,0.13828094524613066,-3.206508129058146
463.50000000000585,51.37237078042917,0.1278612429847228,-3.221701648973971
464.6000000000059,51.48144556234356,0.12556891509430645,-3.237011582557946
465.7000000000059,51.59127935914625,0.12163241323053331,-3.250472505011026
466.8000000000059,51.69787689402762,0.11546984406598293,-3.262774981267914
467.90000000000595,51.80894809342291,0.1154486815868423,-3.2764401363626656
469.0000000000059,51.918480643871106,0.10897222546638519,-3.2888708493206784
470.10000000000593,52.02564645445304,0.10422971470814879,-3.299885276148616
471.20000000000596,52.13461689151059,0.10309447854255938,-3.3109551794014727
472.300000000006,52.242886789269924,0.09893332218858131,-3.321436365664499
473.400000000006,52.352506758005596,0.096087883600537,-3.3319506787820856
474.500000000006,52.46039452458179,0.09086071203884494,-3.3432656214171983
475.60000000000605,52.570476986082504,0.08929425643535538,-3.352499572948976
476.70000000000607,52.68009081194571,0.0862982938238428,-3.362333099705242
477.8000000000061,52.788215359792105,0.08607216599478074,-3.372095618776707
478.90000000000606,52.89765199478518,0.08275881720470757,-3.380453335811871
480.0000000000061,53.00580519333999,0.0804127626310569,-3.3892808475557663
481.1000000000061,53.11531365461362,0.07576093923588623,-3.3977653105615557
482.2000000000061,53.22451805781033,0.07225631135766619,-3.4064296567261336
483.30000000000615,53.33319485425657,0.07155286653156967,-3.412250191377654
484.4000000000062,53.44200003981516,0.06523392885006363,-3.4205751887045963
485.5000000000062,53.550448684137216,0.061887973996047396,-3.429101491305358
486.60000000000616,53.658566131632114,0.05580706067301833,-3.4339793750638385
487.7000000000062,53.770095732908,0.05643900120518941,-3.441170704617282
488.8000000000062,53.87694414821942,0.054363467621099115,-3.4483409012000976
489.90000000000623,53.98725278448007,0.04995935861483325,-3.453829983753875
491.00000000000625,54.095737026592275,0.04725215087363033,-3.4592791136182632
492.1000000000063,54.204962035075134,0.04558630736341529,-3.465695957389742
493.2000000000063,54.31498113948123,0.04392230335739811,-3.4713565219820675
494.3000000000063,54.42399772650277,0.037096096691598746,-3.4773994068979137
495.40000000000634,54.53401012466126,0.03765123388059832,-3.4804925039843546
496.5000000000063,54.643502875507856,0.03353957875483138,-3.4859919431232536
497.60000000000633,54.75254779712874,0.03370363723028591,-3.490835013083368
498.70000000000636,54.8632656085828,0.02827730635524439,-3.4951220287210965
499.8000000000064,54.970636631783115,0.027971746001383302,-3.498193248592014
500.9000000000064,55.081347758981735,0.028171980535458552,-3.5010993779781683
502.0000000000064,55.18886282050868,0.025947863962964224,-3.505086334426343
503.10000000000645,55.30054068548422,0.025014377753115102,-3.509333411931348
504.2000000000064,55.40941201109242,0.021221482340362474,-3.5121405784687725
505.30000000000643,55.519297664191335,0.023526137954349657,-3.5153630906983144
506.40000000000646,55.628632420598855,0.022039440945564426,-3.5161413444923215
507.5000000000065,55.737479286659195,0.023534435232435147,-3.5187618652250547
508.6000000000065,55.84687796837162,0.02494982294368242,-3.521269859875736
509.7000000000065,55.95678657805924,0.024900405721989927,-3.5240539545075342
510.80000000000655,56.06678591067595,0.029465861434382568,-3.5268045777744876
511.90000000000657,56.1754612351361,0.03165492935331082,-3.529434956217294
513.0000000000066,56.28631829268902,0.03593756618519839,-3.529375540369311
514.1000000000065,56.39561382687981,0.04915420148996663,-3.5321600265144024
515.2000000000066,56.504519537682555,0.0647989974015366,-3.534674604549649
516.3000000000065,56.61415471113956,0.06659955653226879,-3.5367758567797907
517.4000000000067,56.72451899902509,0.0685268495477458,-3.5375622174880452
518.5000000000066,56.834205349175456,0.06844435226377099,-3.5376806906211837
519.6000000000067,56.943780150773335,0.07041055061701496,-3.5412440513441363
520.7000000000066,57.05342873764961,0.06957253117223683,-3.541281495855623
521.8000000000067,57.16341573275196,0.07044784561431605,-3.5425998857909367
522.9000000000067,57.273978666301524,0.06941485325168628,-3.543911169022067
524.0000000000067,57.38251070477563,0.06975777991918841,-3.5453253986039317
525.1000000000067,57.49236328304943,0.07143746242287152,-3.5471862782383523
526.2000000000068,57.601865834306906,0.0710404786378902,-3.548529268280781
527.3000000000068,57.712386381740494,0.07103691640097853,-3.5498363182084396
528.4000000000068,57.82152752655828,0.068762319765733,-3.551157956921765
529.5000000000068,57.93000000000059,0.07101000637935417,-3.549850005030241
530.6000000000068,58.04009003666338,0.07200356612142755,-3.5508480434232603
531.7000000000069,58.15045550053373,0.07156050668277825,-3.551170174817613
532.8000000000068,58.26045390294489,0.07091655784248285,-3.552488773522941
533.9000000000069,58.36999797820959,0.07023801743055946,-3.5531185595738988
535.0000000000068,58.47960245604446,0.06774133915351754,-3.5531089094509243
536.100000000007,58.58769945855557,0.06560467404484127,-3.5548311464581803
537.2000000000069,58.69919150691469,0.06418475208081764,-3.5547175149172956
538.300000000007,58.809251698880836,0.06892211579680607,-3.5537980864688303
539.4000000000069,58.919248532219555,0.06213571174503807,-3.5551160751195883
540.5000000000069,59.02923423826823,0.06371143123173795,-3.5590683451409095
541.600000000007,59.13945217273753,0.06198570936388892,-3.5590698761277473
542.700000000007,59.249794530028545,0.06063287455662625,-3.5603836802574804
543.800000000007,59.359804724204906,0.06310367982684628,-3.5590700143841127
544.900000000007,59.4691971271587,0.060882494654825425,-3.5590706249668007
546.000000000007,59.57876032799987,0.057975862631895136,-3.5603869573481486
547.1000000000071,59.68899465828914,0.05844461590445382,-3.5616459976852664
548.2000000000071,59.800711391680856,0.059361685992755486,-3.5619936352355976
549.300000000007,59.90981979735576,0.05868554970937856,-3.5601322344583077
550.4000000000071,60.019331524841625,0.05949310328766089,-3.5607141634471424
551.500000000007,60.13009823253253,0.057048685713212866,-3.562363242104555
552.6000000000072,60.240294336600584,0.057044239146882614,-3.5616932886134234
553.7000000000071,60.35060248590579,0.05916385516412381,-3.5624099799783977
554.8000000000072,60.46060943947586,0.05563434994574168,-3.5619547888476255
555.9000000000071,60.56967636713398,0.05406175179183137,-3.5616211157816906
557.0000000000072,60.67833668483684,0.056274765487437595,-3.5643392178797266
558.1000000000072,60.79207915958258,0.052187667256531345,-3.5651623877892007
559.2000000000072,60.90181189303832,0.05368342179842678,-3.5656499140740894
560.3000000000072,61.01212332628628,0.04936145819312099,-3.56564991382216
561.4000000000073,61.121859056504874,0.051056388354879356,-3.5670571519671697
562.5000000000073,61.23131198309355,0.0502257237411583,-3.5656597575101285
563.6000000000073,61.34066410330536,0.04977582403378422,-3.565661426043747
564.7000000000073,61.45139369559549,0.04822169175477864,-3.5659907887942883
565.8000000000073,61.56133877675292,0.052521131390850684,-3.566979998724089
566.9000000000074,61.67169190099112,0.050875290709451626,-3.5669790576158262
568.0000000000074,61.78202886486409,0.04862640844761623,-3.567298082831879
569.1000000000074,61.89267252475566,0.04835477856094128,-3.569977836545225
570.2000000000073,62.002953388588665,0.048971781415930504,-3.568620133781182
571.3000000000073,62.11319955359006,0.048721421433466805,-3.5686144285069545
572.4000000000074,62.22373630673987,0.043487651609303235,-3.567957498711745
573.5000000000074,62.33467402474871,0.0450713643376921,-3.569279902789241
574.6000000000074,62.44490036263506,0.04804693160518658,-3.5692744631835245
575.7000000000074,62.55463571147209,0.04945437151555643,-3.570600072367626
576.8000000000075,62.66560013295164,0.04818168249352528,-3.570600067999998
577.9000000000075,62.77512835125396,0.04707480799118269,-3.5706000680003602
579.0000000000075,62.8863168399212,0.04654611508491202,-3.5705993275548753
580.1000000000075,62.99718472536424,0.04280764245015689,-3.5712437762468365
581.2000000000075,63.10760563739342,0.041242191316054555,-3.5698804608742845
582.3000000000076,63.218885066895396,0.04498655989183753,-3.57223426435592
583.4000000000076,63.32649048927696,0.04210213461623624,-3.571671411885654
584.5000000000076,63.43853881847693,0.04029312150231901,-3.572846458754225
585.6000000000076,63.55071193033839,0.04228442886244954,-3.572903071100674
586.7000000000077,63.66070048699602,0.03923670874277274,-3.5742198856084326
587.8000000000077,63.77104105408731,0.03714681152911181,-3.5742194041007695
588.9000000000076,63.88103521413056,0.03668658264701952,-3.5743230433279685
590.0000000000076,63.992028221241014,0.03941557962742781,-3.5735699699983545
591.1000000000076,64.10368870766344,0.03764201465494876,-3.5735752067605686
592.2000000000077,64.21416334992756,0.03797814475018413,-3.574119923220475
593.3000000000077,64.3236487673843,0.03780432997348049,-3.57554017206466
594.4000000000077,64.435165150237,0.03451787361067682,-3.5755403349727093
595.5000000000077,64.54697017087756,0.03258224243429986,-3.576376032978167
596.6000000000078,64.65771996382693,0.029337749551128223,-3.5761998985081305
597.7000000000078,64.76751783179938,0.02797136894502783,-3.5764824126387333
598.8000000000078,64.8781925208403,0.026539960221324765,-3.577850106474573
599.9000000000078,64.98921019022956,0.02300380317696371,-3.5778492333679686
601.0000000000078,65.10030726354941,0.01800539574430271,-3.5778393063490572
602.1000000000079,65.21000199914171,0.01902348455247571,-3.578829741904559
603.2000000000079,65.3203139317535,0.012027405968951133,-3.577840920594759
604.3000000000079,65.43067140319944,0.005827536127919863,-3.5778398222048873
605.4000000000078,65.54019405922222,0.00550660063725994,-3.577520118676028
606.5000000000078,65.65277706224477,0.002883134804758658,-3.5771791729116735
607.6000000000079,65.7631169975486,0.0008630822698312279,-3.578517015003759
608.7000000000079,65.87374754764208,-0.0023476189876086018,-3.5784978071738363
609.8000000000079,65.98446356257512,-0.012171138520979952,-3.579009603327236
610.9000000000079,66.09538587664709,-0.013197764680686674,-3.5791601298936477
612.000000000008,66.20559848749501,-0.01953343215458725,-3.580583925663738
613.100000000008,66.3162399957622,-0.025374956271949856,-3.5797452240573895
614.200000000008,66.42735929697862,-0.02529616393238765,-3.5798200583073303
615.300000000008,66.53792242229122,-0.03140646949762882,-3.5799145698363954
616.400000000008,66.64756880142005,-0.03704189589409568,-3.5794899999999217
617.5000000000081,66.75927091165362,-0.04719111222177297,-3.579489941347513
618.6000000000081,66.86943036000014,-0.0484948472431328,-3.578493768565357
619.7000000000081,66.98074986000778,-0.05656641236441873,-3.580730328829834
620.8000000000081,67.09061875025574,-0.06284617353082256,-3.580809736798277
621.9000000000082,67.20206884070616,-0.07237789405863415,-3.5821286875267866
623.0000000000082,67.31157517367676,-0.07862586362293911,-3.580809793368817
624.1000000000081,67.42246760144732,-0.0940461597030473,-3.581144285270294
625.2000000000081,67.53143263670047,-0.10967217857417744,-3.5798334281231527
626.3000000000081,67.64513819000469,-0.11865070146216006,-3.581455599366507
627.4000000000082,67.75556291702148,-0.12056186271895619,-3.5811412731324808
628.5000000000082,67.86556186161101,-0.12562577257775143,-3.5804584844940317
629.6000000000082,67.97404845840914,-0.12677796545936282,-3.5814253816586206
630.7000000000082,68.08466140858258,-0.12879565216967181,-3.5811406389879727
631.8000000000083,68.19826235077518,-0.1304110082530987,-3.58247658832732
632.9000000000083,68.30953936007782,-0.13551239852401187,-3.5817901781231893
634.0000000000083,68.42041522069452,-0.13381286865442688,-3.5824484252118642
635.1000000000083,68.53177100750828,-0.13764426841442434,-3.5824498600022463
636.2000000000083,68.64336208619433,-0.1403225562850814,-3.5824498600000068
637.3000000000084,68.75374313074815,-0.13974301064053707,-3.5824498410362784
638.4000000000084,68.86383578393423,-0.14200924753440347,-3.5834407655565763
639.5000000000084,68.97579040159553,-0.1439105503053808,-3.583769946343763
640.6000000000083,69.08707626193181,-0.14821846108304815,-3.584099822432866
641.7000000000083,69.19715978243441,-0.15034072281195288,-3.5841002005313944
642.8000000000084,69.30880671878396,-0.1460828737162707,-3.5841022699574654
643.9000000000084,69.41839080041474,-0.14731791138619643,-3.5847907318909358
645.0000000000084,69.53177392871515,-0.15068403535574193,-3.5831102783320867
646.1000000000084,69.64198435852683,-0.15210937424968352,-3.5827801998724356
647.2000000000085,69.75279499212768,-0.15334160964832133,-3.5840726734670203
648.3000000000085,69.86484223685758,-0.15622205269032685,-3.584099982126996
649.4000000000085,69.97602514418281,-0.15819749998352384,-3.5835837408568993
650.5000000000085,70.08719508940159,-0.1627639882822507,-3.583450098466096
651.6000000000085,70.20010136801537,-0.16165343343630267,-3.5844300291842117
652.7000000000086,70.31130688022864,-0.1620609827778594,-3.584433577812159
653.8000000000086,70.4224884169,-0.16537609028018485,-3.5844321932969927
654.9000000000086,70.53476805581106,-0.16734162627650262,-3.5844301639992873
656.0000000000086,70.64545777266079,-0.1677735104498841,-3.584430164049544
657.1000000000087,70.7569947082702,-0.16992077910155823,-3.584107449099749
658.2000000000087,70.86843798224987,-0.17520873517206947,-3.5827797874031195
659.3000000000086,70.97966917345327,-0.17354646955272557,-3.58278509505189
660.4000000000086,71.09060876689347,-0.17926628427990732,-3.5844268164533153
661.5000000000086,71.20260564696122,-0.1831411223366355,-3.583776050413565
662.6000000000087,71.31375047092997,-0.18094333134418594,-3.584430008036012
663.7000000000087,71.42344267952286,-0.1799271421700488,-3.583109389529744
664.8000000000087,71.5356989201992,-0.1807304868663393,-3.5831099719989283
665.9000000000087,71.64756652481579,-0.1853219211496282,-3.583111886363942
667.0000000000088,71.75989885341261,-0.18490166469042535,-3.5844301072032394
668.1000000000088,71.8701164683032,-0.18396931184567444,-3.5844299362217265
669.2000000000088,71.98144214296717,-0.19136694497940754,-3.5838439070484953
670.3000000000088,72.092814174762,-0.1963888099194837,-3.5840166797248796
671.4000000000088,72.20232717108718,-0.1974402266609694,-3.5850930582005027
672.5000000000089,72.31674941348977,-0.19463136348561738,-3.585089855999297
673.6000000000089,72.42785319045292,-0.1951166305488803,-3.5850898560001716
674.7000000000089,72.53852200063467,-0.19926870113594974,-3.5850896219849164
675.8000000000088,72.6490233110655,-0.20040146084168553,-3.5857560123528796
676.9000000000088,72.7613084825727,-0.2053875309097264,-3.585750023996636
678.0000000000089,72.87213407928047,-0.20986462133081485,-3.585750023997131
679.1000000000089,72.98379428953622,-0.20889319320325628,-3.5857543681398028
680.2000000000089,73.09447626405483,-0.21628560682518305,-3.586319348650843
681.3000000000089,73.20630105134612,-0.21633112403645427,-3.585091174449971
682.400000000009,73.31809982565196,-0.21247680988763396,-3.5849564700377288
683.500000000009,73.42912350085088,-0.21288189654654532,-3.5850901920697997
684.600000000009,73.5413846583689,-0.21186334620614522,-3.58509007449328
685.700000000009,73.65263589752865,-0.2124320051748545,-3.586399940310124
686.800000000009,73.76387682845042,-0.2153756621459375,-3.5863999079999793
687.9000000000091,73.87519418085569,-0.21371277517762843,-3.5863999079999997
689.0000000000091,73.9872291878449,-0.22068339008080518,-3.5863999080026914
690.1000000000091,74.09813206560732,-0.21854962125119526,-3.586396401940944
691.2000000000091,74.21052319600896,-0.22107781989212372,-3.5870599925105116
692.3000000000092,74.32150869938637,-0.22180516769105996,-3.587067615706984
693.4000000000092,74.43387775830521,-0.2188042730765436,-3.5857399920880377
694.5000000000091,74.54620169365654,-0.22190303794110022,-3.5864778432649627
695.6000000000091,74.65801864821456,-0.2252416292349726,-3.5863576281475913
696.7000000000091,74.76989520263402,-0.228276387326801,-3.585089433236334
697.8000000000092,74.88141831365616,-0.22158825971527518,-3.5867301461221497
698.9000000000092,74.99139788380515,-0.2259491921238137,-3.5867060689507015
700.0000000000092,75.10542024750407,-0.22729513373620236,-3.5860798470466615
701.1000000000092,75.21743044736715,-0.23075819216366655,-3.58607984200252
702.2000000000093,75.32927633604073,-0.23096765289004484,-3.586077794246628
703.3000000000093,75.4408505204851,-0.23091372227349405,-3.587400009734056
704.4000000000093,75.55351241200252,-0.23136989530378527,-3.5874000100000742
705.5000000000093,75.66439316052319,-0.23707201721745186,-3.587399854418038
706.6000000000093,75.77598365733013,-0.23653480570592844,-3.5860840099940816
707.7000000000094,75.8880782899653,-0.2379541597463879,-3.5867618102730408
708.8000000000094,75.99898334959899,-0.23550963116138313,-3.5880501279175956
709.9000000000094,76.1109779755524,-0.2418473720855574,-3.587392014841154
711.0000000000093,76.22010537558344,-0.23840968373147975,-3.5867301278706893
712.1000000000093,76.33328831279256,-0.2400506378832703,-3.5867301300317513
713.2000000000094,76.44602262066644,-0.23483199717721925,-3.585403554906218
714.3000000000094,76.55762188311661,-0.24033216434993632,-3.586729895173866
715.4000000000094,76.67065049913546,-0.24317832926674665,-3.5867298939999963
716.5000000000094,76.7822791514102,-0.2428006367623583,-3.586729926511719
717.6000000000095,76.89356781174466,-0.2413183581047158,-3.5880490807755967
718.7000000000095,77.00545616154267,-0.2338897793177388,-3.5880500620003795
719.8000000000095,77.11794084984555,-0.2300963509279197,-3.58805006200004
720.9000000000095,77.23019342261658,-0.22876009551135068,-3.588049951588994
722.0000000000095,77.34226519033888,-0.22634493574748982,-3.5897037715083684
723.1000000000096,77.45457388156261,-0.2247954373060126,-3.5890608786365665
724.2000000000096,77.56727709074082,-0.2206459325155099,-3.5890406716574255
725.3000000000096,77.67932044513822,-0.21943122988990327,-3.587729810753536
726.4000000000096,77.79075000382615,-0.21093632779059712,-3.5877298280000085
727.5000000000097,77.90371269166322,-0.2071114858634866,-3.587729828091394
728.6000000000097,78.01555246829938,-0.2020813333905731,-3.5884632568775374
729.7000000000096,78.12742274119,-0.20075281595385386,-3.588709899814286
730.8000000000096,78.23945953558008,-0.19667172264651,-3.587390720409098
731.9000000000096,78.35331185195251,-0.19426173696564675,-3.5867398286649768
733.0000000000097,78.46561531361033,-0.19181399582169778,-3.5880388587014562
734.1000000000097,78.57774662104403,-0.1882734644992694,-3.5880472813495703
735.2000000000097,78.69087342431263,-0.18305038142271668,-3.5880489826847954
736.3000000000097,78.8031021322097,-0.17761893620183455,-3.5880501666152265
737.4000000000098,78.91355534283574,-0.1738059523172879,-3.588050156017497
738.5000000000098,79.02757406095168,-0.17344909986187274,-3.5880111684860276
739.6000000000098,79.13971761430076,-0.17590958009314184,-3.589369922075564
740.7000000000098,79.25140234890672,-0.17202065305441794,-3.588100238589432
741.8000000000098,79.36392576594798,-0.17434842818876906,-3.5867261396206565
742.9000000000099,79.47533793626151,-0.17990959540520457,-3.587892993638948
744.0000000000099,79.58733122560591,-0.17882168720478075,-3.5869048277194158
745.1000000000099,79.69958799989199,-0.18108113624570032,-3.588049921995433
746.2000000000098,79.81244959520627,-0.18291042593138052,-3.587600401008534
747.3000000000098,79.92408161731198,-0.18157095425475145,-3.58825308378209
747.7000000000099,79.96471516226818,-0.18048025506573007,-3.589373361392981