File: 01_Data/PEVA/STA/N2/10K_min/PEVA_STA_N2_10KData_240731_R1.csv
##Temp./Â°C,Time/min,DSC/(mW/mg),Mass loss/mg
51.0,10.844356946741748,0.04448406890304124,0.0020903893315198374
52.100000000000016,11.118918326425739,0.09445882793393068,8.40771621417602e-05
53.20000000000003,11.319561913135047,0.13064170621287685,0.002535596633093995
54.30000000000005,11.493642429751475,0.160765371073603,0.0014843598299245642
55.40000000000006,11.642855417555001,0.18304913308202364,0.0017125559707418248
56.50000000000008,11.790563636171516,0.20112691915398972,0.0013367045191134963
57.600000000000094,11.925440245003346,0.2184119071631776,0.0003229078830591092
58.70000000000011,12.055602149949289,0.23055767448062126,0.00048085525062191437
59.800000000000125,12.18270593664064,0.23856734503969879,0.0020049170111819947
60.90000000000014,12.308614818548579,0.24886584968938408,0.0011664942675029266
62.000000000000156,12.43141177259378,0.25600218939148744,0.0015084573561274794
63.10000000000017,12.551409222420535,0.2638473993000314,0.0002255705283049636
64.20000000000019,12.671575781595218,0.2684616871314107,0.0006046785994273662
65.30000000000021,12.790209903853473,0.2701231888705653,0.00021635209308357162
66.40000000000022,12.909130157346956,0.2748014419419609,0.001643745380359718
67.50000000000023,13.024507742485648,0.2762313394149656,0.0003191203860035685
68.60000000000025,13.143571183933801,0.2775401355793021,0.001560514881873587
69.70000000000027,13.258943824402685,0.28040484155977685,0.00031515200486076367
70.80000000000028,13.374373763464279,0.2808850270630452,0.00033067244573281585
71.90000000000029,13.490911006361861,0.2843173372556045,0.00036944282360362735
73.00000000000031,13.605828007971935,0.28531051339773716,0.000330202649654332
74.10000000000034,13.72000000000004,0.2888675351077308,0.0003191681132994617
75.20000000000034,13.833870896824395,0.28880977388898676,0.00032971311004192927
76.30000000000035,13.946829214888517,0.29365449011735745,0.0006581086171397743
77.40000000000038,14.060290835767328,0.2963557633222731,0.0016340689786771279
78.5000000000004,14.174224592837072,0.29484165552905406,0.0020568382789196704
79.6000000000004,14.286595523533155,0.30052661212726983,0.001649635297476415
80.70000000000041,14.399133076776854,0.30350167747437595,0.0016462257325748908
81.80000000000044,14.511771224428974,0.3077939790553277,0.00034154173574219016
82.90000000000046,14.623238125078561,0.3112060372572536,0.0016601964973625982
84.00000000000047,14.731065369367077,0.312984899653475,0.002945067332443152
85.10000000000048,14.84630203046154,0.314565581719779,0.002960313962575789
86.2000000000005,14.957633937079299,0.31704666979237794,0.0016401060684829716
87.30000000000052,15.06682319201407,0.3206963127705236,0.0006823562774309622
88.40000000000053,15.172943875889732,0.3233509867388187,0.0029706454104623248
89.50000000000054,15.28659715172337,0.3262833472323252,0.0016511780394790065
90.60000000000056,15.395343059338456,0.3261322202118704,0.002904494646042366
91.70000000000059,15.50582208619124,0.329924780059379,0.001640084677442033
92.8000000000006,15.615261124044382,0.33290122911760944,0.002955085181456596
93.9000000000006,15.722883180277183,0.33499207387891605,0.0016401091955025038
95.00000000000063,15.83186153974087,0.3372644056911729,0.002960291942841309
96.10000000000065,15.94069877615587,0.3390907673210508,0.002896409684146839
97.20000000000066,16.049584202953994,0.3413316511059463,0.0016505693115211884
98.30000000000067,16.154388382488296,0.3454673552097556,0.0029599042112042895
99.40000000000069,16.265986258998826,0.34847960050560367,0.0029608146353456988
100.50000000000071,16.3739633776201,0.3494341319100167,0.0018748734416389468
101.60000000000072,16.481529574607098,0.34931419824703,0.0029814368614706765
102.70000000000073,16.59000000000008,0.34966817445930554,0.0029599552129209172
103.80000000000075,16.696915415519243,0.3493625606468811,0.002959854343309587
104.90000000000077,16.8031996718041,0.35230613060033145,0.003013827369479749
106.00000000000078,16.91027699642248,0.35180183842794444,0.0029698040288197447
107.10000000000079,17.017688669314943,0.35239017501270986,0.0043263213995974326
108.20000000000081,17.12458197004762,0.35180132677766496,0.004279958596923095
109.30000000000084,17.231845978506854,0.3563135978006913,0.005257583423317058
110.40000000000084,17.340083572748174,0.3572319861428723,0.003950606857647365
111.50000000000085,17.445725150386956,0.35699013476404673,0.0054290751781937985
112.60000000000088,17.55264550880679,0.35931434174561483,0.004280010147530433
113.7000000000009,17.659713591556507,0.36030790009739855,0.004282322421562235
114.8000000000009,17.766076377098663,0.3617665384568096,0.004293863401725773
115.90000000000092,17.873021190740623,0.3649242809337472,0.005589983079567595
117.00000000000094,17.978890859847027,0.36501754734378355,0.005590163842978058
118.10000000000096,18.08476909192307,0.36895328597479615,0.004279714120291267
119.20000000000097,18.190684906118445,0.3704699315282296,0.00427988368559884
120.30000000000098,18.29989783920464,0.37047640806141846,0.0055998346605710125
121.400000000001,18.405362093094496,0.37417878720103426,0.004287319538795131
122.50000000000102,18.512258604027608,0.3739315553763336,0.0056169007340090005
123.60000000000103,18.618757337445405,0.37479867610218953,0.00525310741781837
124.70000000000104,18.725144361531623,0.37879423484601427,0.005599955336756501
125.80000000000106,18.831791849765327,0.3772820627506661,0.004610189915518426
126.90000000000109,18.93678098286812,0.3803195521735159,0.005920515115613867
128.00000000000108,19.04409303593304,0.38241399374458274,0.005921902784659316
129.1000000000011,19.15078046801599,0.38216420706290544,0.0055902844081838765
130.20000000000113,19.256248087353626,0.384737655199328,0.005595842584583011
131.30000000000115,19.36199109542787,0.38449988739266905,0.005600018935509432
132.40000000000117,19.46610794950727,0.3886853918375297,0.005304570766433869
133.50000000000117,19.574261350691017,0.39119217947658536,0.005589816430435768
134.6000000000012,19.6800987510644,0.39287354484205705,0.006258921271660611
135.7000000000012,19.786490568310562,0.3919540453999537,0.006294910282891308
136.8000000000012,19.892630911537665,0.39635184792516087,0.006595161546872674
137.90000000000123,19.99740875806984,0.3976470691107803,0.005600048711410288
139.00000000000125,20.103348463376424,0.4002242764665507,0.005600078922876506
140.10000000000127,20.207390397529714,0.3997876566805161,0.006913385423220397
141.2000000000013,20.313527969264694,0.40150384040752307,0.00658815931038248
142.3000000000013,20.419257207874537,0.4031011128090136,0.005589595108334677
143.4000000000013,20.52524565890909,0.40430071999002815,0.006910081281885638
144.50000000000134,20.628540394411235,0.40561526000896375,0.006910269892911991
145.60000000000133,20.735139502515825,0.4081523329930712,0.007899756256765755
146.70000000000135,20.84109181552321,0.4072100073168574,0.007899837203615867
147.80000000000138,20.944770890267066,0.4111991403224695,0.006589630915573963
148.9000000000014,21.051129897779273,0.4103702743957056,0.006591491465897548
150.00000000000142,21.155955612709036,0.41106819218059076,0.006919872172514552
151.10000000000142,21.26039946182196,0.4137684194875466,0.008257113667850646
152.20000000000144,21.366022681592803,0.4154332092881359,0.005548393981256616
153.30000000000146,21.471999798319736,0.4169806445423947,0.006920480145164554
154.40000000000146,21.57660454299002,0.41818503727874745,0.008269775349857511
155.50000000000148,21.680656832939242,0.41928322923384975,0.008205374936001597
156.6000000000015,21.78580011460183,0.42366218048014215,0.006524858431014913
157.70000000000152,21.89094901347577,0.4241207000354148,0.007182120691292759
158.80000000000155,21.9953975658543,0.4238940714146313,0.009218256499305966
159.90000000000154,22.100386165862627,0.4242548482636166,0.009223689966991522
161.00000000000156,22.20394209966528,0.4260605536376594,0.008129512585861143
162.1000000000016,22.310295808175653,0.42790292547297293,0.007592516650506198
163.20000000000158,22.415641423884043,0.42738731846966305,0.007569905950046696
164.3000000000016,22.519727898855777,0.42741507850779215,0.007816823455383037
165.40000000000163,22.62357435697202,0.430474595419418,0.008019342030740617
166.50000000000165,22.730000000000157,0.4309256345259498,0.007579963048096161
167.60000000000167,22.833474434587522,0.4327408628092262,0.007579962994152645
168.70000000000167,22.93989545401942,0.43244190161442697,0.007579672763189826
169.8000000000017,23.044121585637306,0.4337413397458949,0.008570012985031461
170.9000000000017,23.149511816872042,0.432876927947349,0.007249862305553023
172.0000000000017,23.25331483820046,0.4333748811491871,0.008570407070610742
173.10000000000173,23.358419779517796,0.43763236810625283,0.007642317344633831
174.20000000000175,23.463042514540454,0.4377549154840956,0.007580190907269468
175.30000000000177,23.568494967107252,0.4352905542054133,0.007563916007395477
176.4000000000018,23.67334886392038,0.4388667292272732,0.004929093946882013
177.5000000000018,23.777344743193925,0.44192420606163174,0.00494019098589682
178.6000000000018,23.882394086202435,0.44145870834613077,0.004946731140012872
179.70000000000184,23.98712328175706,0.44357472578758395,0.0062498892859084165
180.80000000000183,24.09165470593238,0.4438953266182599,0.004945677785491043
181.90000000000185,24.196738612545907,0.4451577906354516,0.006247723548692186
183.00000000000188,24.30117169106353,0.444381941372604,0.005269821743328684
184.1000000000019,24.40533219052769,0.44318334241527224,0.004279894870110823
185.20000000000192,24.510090771520908,0.44359082757246227,0.004280172999618692
186.30000000000192,24.614594613189468,0.4425911927037134,0.00427950064380056
187.40000000000194,24.718366281037927,0.44122783881778327,0.003950173345821817
188.50000000000196,24.824184128749376,0.4453989881719649,0.005253770887797771
189.60000000000196,24.92802976298945,0.44590880870412497,0.005269997934818527
190.70000000000198,25.032406175833344,0.44638995908429546,0.00470242990105163
191.800000000002,25.137210465792432,0.44589286566221076,0.0052739252168922945
192.90000000000202,25.241879750924873,0.44797093916507014,0.005269994032787828
194.00000000000205,25.345611802357702,0.4486765284919696,0.003941626185978819
195.10000000000204,25.45116430922335,0.44922570572649345,0.003950367367186125
196.20000000000206,25.55477015603713,0.45023464820159576,0.0028962361178992424
197.3000000000021,25.659544208925062,0.4537103592885028,0.0016401826682370668
198.40000000000208,25.76364376765577,0.4501826480274369,0.002332165460622093
199.5000000000021,25.86597062104809,0.45136834110449464,0.002299887621462382
200.60000000000213,25.973040014258448,0.4503907754302876,0.0009845070971179481
201.70000000000215,26.076493792713173,0.4526951728729638,0.0009901339909417217
202.80000000000217,26.181368996177262,0.4494909313676141,0.0009901339962565814
203.90000000000217,26.286796541361216,0.4519308830200579,0.000975277548097786
205.0000000000022,26.391520350288147,0.4537110372002082,-0.0019104475866038584
206.1000000000022,26.494371106210295,0.45263458967580217,-0.001210472497688464
207.2000000000022,26.600644616581192,0.45368032546384707,-0.001209804999904307
208.30000000000223,26.704843388125624,0.45781886040350495,-0.001206710934628319
209.40000000000225,26.80825871824014,0.45550126570123406,-0.0031896731560960845
210.50000000000227,26.912869529090422,0.4560389513136158,-0.005121887427921301
211.6000000000023,27.016728327046984,0.45947795545531167,-0.005820303337298327
212.7000000000023,27.122044205354825,0.461160457470146,-0.007129743300599678
213.8000000000023,27.225483648437248,0.46159361086975936,-0.006480220698349193
214.90000000000234,27.32858962062818,0.4591640786204221,-0.006477166320196126
216.00000000000233,27.43557829543392,0.4621810759742413,-0.007800132224304868
217.10000000000235,27.539460554285355,0.46497556479019164,-0.009712169556407524
218.20000000000238,27.643933482253928,0.4627519950292718,-0.009767788939290867
219.3000000000024,27.74780101293531,0.46476209714821515,-0.010398524874092097
220.40000000000242,27.85264159920975,0.4647895841204934,-0.014490062535961634
221.50000000000242,27.958502663965117,0.4664582352272293,-0.013038543601564534
222.60000000000244,28.062884011895985,0.4652507267923165,-0.013502978860057802
223.70000000000246,28.166673361549687,0.46412836189803786,-0.017425574869683658
224.80000000000246,28.270879722983057,0.4646522033142475,-0.020091478342823876
225.90000000000248,28.37419414869852,0.4649001847979948,-0.021413625106164957
227.0000000000025,28.481023807222304,0.4679087906109478,-0.023375459871084914
228.10000000000252,28.58448829763017,0.46780572305373447,-0.025085306594147205
229.20000000000255,28.688795967953567,0.4672628091492492,-0.027042140357239397
230.30000000000254,28.794512098728426,0.4674105758118001,-0.02871596604590998
231.40000000000256,28.89818069913681,0.46835684784224485,-0.0319414030640055
232.5000000000026,29.002306419535635,0.4654540295282046,-0.033367111845890474
233.60000000000258,29.108062902358355,0.46170531585188623,-0.03502465050123238
234.7000000000026,29.21064595116344,0.45824320159604803,-0.038698737435444386
235.80000000000263,29.31523677215523,0.4584757400481907,-0.04167543031007259
236.90000000000265,29.421021668428857,0.45580668038281535,-0.044239733658816505
238.00000000000267,29.52481086522238,0.4536746470216686,-0.04710345382347336
239.10000000000267,29.628525833073777,0.4495752650832858,-0.053255254462967194
240.2000000000027,29.733022523453645,0.4462331348754063,-0.056423660962170885
241.3000000000027,29.838230966238065,0.4448501275700374,-0.05932657424020338
242.4000000000027,29.943256602366944,0.44280394981269633,-0.06476043752412819
243.50000000000273,30.047260192895912,0.4386837081817436,-0.06806273430540788
244.60000000000275,30.15169532408119,0.43726909928179225,-0.07212521205893507
245.70000000000277,30.2573475147397,0.4386577284191635,-0.07697789535369459
246.8000000000028,30.362326907275936,0.446981705095818,-0.08129597705988534
247.9000000000028,30.46804317653373,0.46675916592130107,-0.08573134657955661
249.0000000000028,30.572379761214776,0.49592284156579614,-0.09286198708794569
250.10000000000284,30.680429363259098,0.5236462612277584,-0.09935954105060407
251.20000000000283,30.78610210941023,0.5442953374994433,-0.1079450086196565
252.30000000000285,30.89113333876173,0.5533624355665305,-0.11482332715340604
253.40000000000288,30.995655385148368,0.5655104188092845,-0.12333418793950335
254.5000000000029,31.102189625772102,0.5751759237007972,-0.13278740735205874
255.60000000000292,31.207121872341403,0.5840474275237775,-0.14321980305821214
256.7000000000029,31.31278800051322,0.588676341834782,-0.1519721229604185
257.8000000000029,31.41760930584317,0.5955491559541557,-0.16294018105678454
258.90000000000293,31.522359636660454,0.6042161389696432,-0.17402519452782617
260.00000000000296,31.629790628476385,0.6111196147108473,-0.18552220111365392
261.100000000003,31.735094406510576,0.6200125680973756,-0.19848107216695077
262.200000000003,31.840592448138647,0.6326590839192356,-0.21186371107884883
263.300000000003,31.94587914664033,0.6390007511404052,-0.22608890788284075
264.40000000000305,32.05150965412661,0.652754102659185,-0.2406001506700104
265.50000000000307,32.15727509254544,0.6637636038471477,-0.25712309648243004
266.6000000000031,32.263437665035795,0.6793869608410201,-0.275055693502285
267.7000000000031,32.368960478575104,0.6942668946798793,-0.2925190707125469
268.8000000000031,32.47498799709877,0.7121830259004365,-0.31312282748056885
269.9000000000031,32.58123530259187,0.727050641421505,-0.33614671767759674
271.0000000000031,32.686648551508505,0.7452554637101649,-0.35854708778878086
272.10000000000315,32.789342184185955,0.7582820998782516,-0.38505269661047414
273.2000000000032,32.899807302173016,0.7756291740085153,-0.41263283759859926
274.30000000000314,33.00384085282997,0.7897200017422461,-0.4418692044105521
275.40000000000316,33.11100846671261,0.805274711496313,-0.47116107823409026
276.5000000000032,33.218124475602316,0.8220039111637452,-0.5056279403986084
277.6000000000032,33.323821922384134,0.8334901186489736,-0.5411080424804164
278.70000000000323,33.430540135047686,0.8488435226608813,-0.5756397246349918
279.80000000000325,33.53618319523253,0.865318549136648,-0.6151424812511768
280.9000000000033,33.64256324681422,0.8826517727535219,-0.6550412514543704
282.0000000000033,33.74871386238251,0.8971911326817497,-0.696570087610298
283.1000000000033,33.85449794848637,0.9136376381386788,-0.7394137591796364
284.20000000000334,33.96019767121757,0.9294847166477238,-0.7825693669141933
285.30000000000337,34.06581970230486,0.9480351900429471,-0.8311954769665908
286.40000000000333,34.171621626387804,0.960494726370074,-0.8809330977395731
287.50000000000335,34.279525470299845,0.9752970594246047,-0.9327885269931784
288.6000000000034,34.38503776573929,0.9899588261714898,-0.9839627456659881
289.7000000000034,34.49283410106242,1.0045166387582474,-1.0403487962590576
290.8000000000034,34.59903734002966,1.019318236044676,-1.0964537027742383
291.9000000000034,34.70488818237714,1.0368833019802248,-1.1581875313927106
293.0000000000034,34.81105428207636,1.0526578565292621,-1.2226021576204036
294.10000000000343,34.91865291220462,1.071091625873914,-1.2853844314149714
295.20000000000346,35.02266844737239,1.103566563702701,-1.3489240692087852
296.3000000000035,35.130381468763666,1.109271504381978,-1.4176273471593217
297.4000000000035,35.23744801386936,1.1135664990610183,-1.483753954963881
298.5000000000035,35.34556288515741,1.1537095998062943,-1.5564218126621694
299.60000000000355,35.44862116327754,1.1483875917203956,-1.6266217992900311
300.70000000000357,35.555810728011686,1.1382462019159005,-1.6946800007461298
301.8000000000036,35.66085921515404,1.1109481672716923,-1.7645661484809825
302.9000000000036,35.76494869088741,1.0841226602782947,-1.8324308292819853
304.0000000000036,35.868366208046616,1.046269957222622,-1.89670408658011
305.1000000000036,35.972160925076054,1.0021002032399526,-1.9615603432017674
306.2000000000036,36.07629824554276,0.9604117173122473,-2.0216152869463695
307.30000000000365,36.17943790238784,0.9128664915675793,-2.0745713681430678
308.4000000000037,36.28343953684118,0.8675435033544612,-2.127287896112045
309.5000000000037,36.38604240910679,0.8189481157001663,-2.1742317027800535
310.60000000000366,36.489372874676725,0.7767022876258896,-2.218010760234936
311.7000000000037,36.59244738021996,0.7388099244746527,-2.2554787004771857
312.8000000000037,36.69664088337716,0.7018053176878032,-2.2925501536532717
313.90000000000373,36.800000997698994,0.6731702184986379,-2.3255402205204594
315.00000000000375,36.90485702653154,0.6436445738838783,-2.3563586719755816
316.1000000000038,37.007935120301646,0.6234855569197608,-2.3845611797992077
317.2000000000038,37.11266752342747,0.6023398032600378,-2.407991074303479
318.3000000000038,37.21680435411702,0.5800268995971314,-2.4353392376432574
319.40000000000384,37.321896931143996,0.5626034220028375,-2.4635832428399005
320.5000000000038,37.42655332422868,0.5473742448816459,-2.48449378783443
321.60000000000383,37.52882276913709,0.5314376971604182,-2.504150842535129
322.70000000000385,37.63629508498291,0.5217806852387237,-2.5251285324939605
323.8000000000039,37.74109278474232,0.5034030799276616,-2.544756409708956
324.9000000000039,37.84608760802379,0.4917642103047004,-2.561939014946527
326.0000000000039,37.95186031425334,0.47608572822091166,-2.579076709004488
327.10000000000394,38.056269778210876,0.4645585144398148,-2.5971088604979715
328.2000000000039,38.161299874390046,0.4503305506988413,-2.6141606876261703
329.30000000000393,38.266821605971856,0.43267977402758606,-2.63120120905069
330.40000000000396,38.372479515393636,0.4222092511660809,-2.645038475453637
331.500000000004,38.477893850785144,0.40947119100645635,-2.661457923397739
332.600000000004,38.582489516263855,0.39517700814070644,-2.6727397091998526
333.700000000004,38.68837059914643,0.3848744786354992,-2.684949260565929
334.80000000000405,38.7937754839682,0.3690913819221502,-2.6988127357720595
335.90000000000407,38.89960633221349,0.35699611831200717,-2.7113876686543588
337.0000000000041,39.004272439324296,0.34301242781740204,-2.7236098747380106
338.10000000000406,39.11124462208712,0.3332045913174295,-2.734605949897934
339.2000000000041,39.2172240671285,0.32033870152108124,-2.7445802109565474
340.3000000000041,39.32262782713463,0.3062568055314192,-2.756542860495962
341.4000000000041,39.42769363026723,0.29254986065220656,-2.7658118186852714
342.50000000000415,39.53285304118968,0.278712775491319,-2.7761672119024996
343.6000000000042,39.64056433965128,0.2678793840689462,-2.7837165196693325
344.7000000000042,39.742344861490196,0.2570389809511209,-2.791866728071835
345.80000000000416,39.85206414063965,0.2421925139182437,-2.7998577897860133
346.9000000000042,39.95731177659804,0.23112280224290727,-2.807093660612998
348.0000000000042,40.063519721113984,0.2214530114017732,-2.81498558368462
349.10000000000423,40.168909565069654,0.20965843895255976,-2.8201043124465333
350.20000000000425,40.27578272593797,0.1992493237952413,-2.826987734141035
351.3000000000043,40.380974708230305,0.1927263359441982,-2.832608565070161
352.4000000000043,40.48835479428699,0.18234190830174146,-2.836681829233001
353.5000000000043,40.59382179158052,0.17665115194557757,-2.8408477519585853
354.60000000000434,40.700383082948946,0.16902196109826395,-2.844354895071596
355.7000000000043,40.80671838623152,0.1606935298315899,-2.8484996409449126
356.80000000000433,40.91394401050189,0.15384519788748063,-2.8515806866789113
357.90000000000435,41.02026354467552,0.14630229101787773,-2.8568025417187966
359.0000000000044,41.12766027538643,0.14177886372949366,-2.8576233034754304
360.1000000000044,41.23241693717818,0.13838173624657735,-2.861266133313613
361.2000000000044,41.339895878352486,0.13612363421079055,-2.8640144706167665
362.30000000000445,41.44442819511739,0.12874420315915946,-2.8658661819237876
363.4000000000044,41.55320737999208,0.12710379347625533,-2.868241620732995
364.50000000000443,41.66096181834563,0.12379199907358585,-2.8707728641487402
365.60000000000446,41.76854789314155,0.12111722129180436,-2.870742782346639
366.7000000000045,41.87466148078432,0.12133058802560504,-2.8727959373551544
367.8000000000045,41.9820211537867,0.1207249244068671,-2.873680681945241
368.9000000000045,42.08736902146105,0.12251400090834696,-2.8760056026514125
370.00000000000455,42.19741953368149,0.11632524319442794,-2.875004836118098
371.10000000000457,42.302952352230385,0.11556166876423246,-2.8751540411996945
372.2000000000046,42.41104319463305,0.11532766481089007,-2.877695686516061
373.30000000000456,42.51816579567194,0.11200467980363271,-2.8786351689264293
374.4000000000046,42.62577894370062,0.11321773543545666,-2.879919656675466
375.5000000000046,42.73345642700633,0.11303316806449804,-2.880338071330437
376.6000000000046,42.83999901802691,0.10922549112745195,-2.8789583939010663
377.70000000000465,42.947543605078025,0.10827014202780916,-2.881641446329554
378.8000000000047,43.05443385763977,0.10862436921279306,-2.8815915583484104
379.9000000000047,43.161652711440766,0.10754197815717781,-2.8804449358191597
381.00000000000466,43.26931808635444,0.1053306071087654,-2.8815731151210144
382.1000000000047,43.37466757199761,0.10495580200014931,-2.8829099441072428
383.2000000000047,43.484175742689786,0.10304587958900413,-2.884259665113213
384.30000000000473,43.5920580649864,0.09886011250353866,-2.8828970070105107
385.40000000000475,43.698875808661725,0.09805344121770476,-2.8842017406243556
386.5000000000048,43.80456206217334,0.09766236406582074,-2.8855375337644515
387.6000000000048,43.911718600817565,0.09752347468867173,-2.885560466037789
388.7000000000048,44.021517216852146,0.09550737566505196,-2.88456939757141
389.80000000000484,44.129413335349035,0.09490747545892475,-2.883520847475578
390.9000000000048,44.23605073089187,0.0914918418027435,-2.887743180313484
392.00000000000483,44.341859526972186,0.08922064569275312,-2.8890604059682206
393.10000000000485,44.4516015476316,0.08691833868348109,-2.887723815518857
394.2000000000049,44.55901779432761,0.08419339353126354,-2.8877397258197135
395.3000000000049,44.66692752425417,0.08279984544442565,-2.8890598368803295
396.4000000000049,44.774141511695625,0.07979502619459478,-2.88905805665365
397.50000000000495,44.881694054304404,0.0768016592274825,-2.8890602434848067
398.6000000000049,44.987086816659364,0.07528779630348392,-2.889139615457001
399.70000000000493,45.09677683821517,0.07633521710384938,-2.8903809546053028
400.80000000000496,45.20454739499685,0.07259898698122846,-2.893009439033899
401.900000000005,45.310101267820784,0.06860732693454574,-2.893009845508188
403.000000000005,45.41881488265361,0.06696968279946924,-2.8943296220008476
404.100000000005,45.5264023499959,0.06323241867400675,-2.8943311959753872
405.20000000000505,45.634269481864266,0.06305440544809082,-2.894319396419344
406.30000000000507,45.74170893552761,0.05983358719342169,-2.894644873735069
407.4000000000051,45.84928075628946,0.05915100847215404,-2.8956470460922783
408.50000000000506,45.957971310720254,0.05537891230660996,-2.899700517635788
409.6000000000051,46.0651169999009,0.052479254627195715,-2.898381996505012
410.7000000000051,46.17210210595463,0.04915274732622743,-2.898718500013083
411.8000000000051,46.2800009814207,0.04729041309965032,-2.9000399291687815
412.90000000000515,46.38779098845541,0.04306424791497143,-2.9013500457617747
414.0000000000052,46.495859364207504,0.04163341546257193,-2.9026369352680645
415.1000000000052,46.6042743834849,0.039932464157459435,-2.9066173392708485
416.20000000000516,46.711845469029036,0.033893787298706624,-2.9069157292511227
417.3000000000052,46.81919912848087,0.0316900075640314,-2.907939931110402
418.4000000000052,46.927746860362944,0.026376850683577313,-2.9092701492471007
419.50000000000523,47.0354564677867,0.02559569842188303,-2.911504215541302
420.60000000000525,47.14289335809308,0.016838283084612993,-2.9118901298600965
421.7000000000053,47.25135127636044,0.016963087229174167,-2.912566030757282
422.8000000000053,47.35861451048843,0.012763970049638473,-2.9138783707121876
423.9000000000053,47.467798793631964,0.014499972069945244,-2.917905302088286
425.00000000000534,47.574756076347775,0.0072895160096280165,-2.920572023462522
426.1000000000053,47.68410581938593,0.006761520596755943,-2.9212099466820582
427.20000000000533,47.79177900977233,0.005791911444852804,-2.923964293485141
428.30000000000535,47.898883459665164,0.002765579422826292,-2.9261776064096683
429.4000000000054,48.0086179782352,-0.0009863351506078644,-2.9301301199384024
430.5000000000054,48.11421475819113,-0.0010323966422318698,-2.9350680726500604
431.6000000000054,48.22356617946754,-0.0021159849912555373,-2.9376123921228676
432.70000000000545,48.33217762668961,-0.000302963775201448,-2.940321099287612
433.8000000000054,48.44018327664201,-0.0034107248279466873,-2.9441640393402944
434.90000000000543,48.548254966096955,0.0006698788376260367,-2.947126751342192
436.00000000000546,48.65586536769899,0.002677442727787138,-2.951011104677884
437.1000000000055,48.76379015879259,0.009027561126432548,-2.9574387358039456
438.2000000000055,48.87418705614335,0.015569482386450506,-2.9619117975698197
439.3000000000055,48.982117686980196,0.025651857230137853,-2.9660333077244783
440.40000000000555,49.09210728154928,0.034412167590781806,-2.9742195559539173
441.50000000000557,49.200200699362334,0.044982935960271586,-2.9777655557979132
442.6000000000056,49.3097227044011,0.05234676407251637,-2.9846538074391384
443.70000000000556,49.41840889167352,0.06782979244591258,-2.9927272579938657
444.8000000000056,49.5268914626494,0.07270104531881483,-2.998601784953562
445.9000000000056,49.63656825794397,0.08371582636714381,-3.006036901444585
447.0000000000056,49.74503715564652,0.0944614746730239,-3.0145610068862685
448.10000000000565,49.8534503386338,0.1033261732403008,-3.0240299357718445
449.2000000000057,49.962969231453336,0.1129304317541222,-3.0332617712864516
450.3000000000057,50.0727614723349,0.1258679921965702,-3.0427456383908815
451.40000000000566,50.181676984254395,0.1469612424940121,-3.0508147198836952
452.5000000000057,50.291529976537404,0.18028574618590998,-3.0647331946531327
453.6000000000057,50.40171260329189,0.2152749604739519,-3.080942339419916
454.70000000000573,50.512926866383175,0.2772145265745629,-3.1025839917812785
455.80000000000575,50.623499787722274,0.29995241070696466,-3.1291470913468986
456.9000000000058,50.73205478062392,0.28664409338150953,-3.1560654180395744
458.0000000000058,50.84048297967494,0.2593928580261582,-3.179340610655464
459.1000000000058,50.948560456579,0.24422041739858713,-3.19802619313449
460.20000000000584,51.056669788124765,0.22710757686200145,-3.218689498248871
461.3000000000058,51.16604750188676,0.21878832650919788,-3.2338970646048266
462.40000000000583,51.273851775368904,0.21065880495350342,-3.2477835509403015
463.50000000000585,51.382604701945155,0.2079969762208691,-3.2611213361228497
464.6000000000059,51.49194457721457,0.20187623258658238,-3.2740419656558224
465.7000000000059,51.60135819981964,0.20193791995715316,-3.2864977966060254
466.8000000000059,51.7097980867406,0.19729644546963065,-3.2986392503199524
467.90000000000595,51.818671104504,0.19670896069795063,-3.312124352646781
469.0000000000059,51.92756901431954,0.19261140637606156,-3.322632842366116
470.10000000000593,52.03656342296136,0.1905760775651575,-3.333920627843491
471.20000000000596,52.14369647913136,0.19019537021576483,-3.3437885218075722
472.300000000006,52.25516805166824,0.1840740674188881,-3.3567419237425113
473.400000000006,52.36356793757378,0.18021121817536168,-3.368247043249851
474.500000000006,52.47261085688372,0.18226630500728236,-3.3776051870961643
475.60000000000605,52.581470178032454,0.17498538050619583,-3.3869901566869043
476.70000000000607,52.68877936311458,0.17278605458123542,-3.39680526276433
477.8000000000061,52.799288321818025,0.1668097927328498,-3.4068150998952675
478.90000000000606,52.9063571807614,0.16065024510839843,-3.4143577919999064
480.0000000000061,53.0150190040586,0.15764609050909106,-3.423739237699828
481.1000000000061,53.12336022269525,0.15265501424570438,-3.431227931759759
482.2000000000061,53.23395939076146,0.14807698205176312,-3.440179899256856
483.30000000000615,53.34255686648281,0.14354705209925323,-3.4471165381264384
484.4000000000062,53.451028363278304,0.141085006083844,-3.4559665911169333
485.5000000000062,53.56097989440519,0.136513940397748,-3.464595807253463
486.60000000000616,53.669999031777806,0.13626362448485096,-3.4715599423530086
487.7000000000062,53.77928765226086,0.13278459735094295,-3.4782420586139198
488.8000000000062,53.88922768534941,0.1314502348106088,-3.4845220524677685
489.90000000000623,53.99729372431754,0.13016960849157222,-3.489237193035118
491.00000000000625,54.10707433756094,0.128090619879619,-3.4943115802195566
492.1000000000063,54.2159459415594,0.13011130206141353,-3.5003053271308686
493.2000000000063,54.324412381780135,0.12653703939793504,-3.50838308334094
494.3000000000063,54.433953830765184,0.12511017287992887,-3.512053377865964
495.40000000000634,54.54178851659144,0.125147076801571,-3.5173504451473505
496.5000000000063,54.65298021038228,0.12219319672934015,-3.5203270182462014
497.60000000000633,54.76256470665502,0.12293726237474445,-3.528211276118482
498.70000000000636,54.87187257921621,0.12563426905599995,-3.5312865801883655
499.8000000000064,54.98141339461991,0.12682597231670156,-3.5339055491812013
500.9000000000064,55.09171509036074,0.1317749170327196,-3.5381061669929728
502.0000000000064,55.201015180508726,0.14032473714072546,-3.542429980827336
503.10000000000645,55.310387999175326,0.14371688323650522,-3.5451411067640333
504.2000000000064,55.41928831430066,0.13915439001606789,-3.5469654716045897
505.30000000000643,55.530310377506936,0.14303533535440272,-3.5496358514693425
506.40000000000646,55.638315651155885,0.13979389505741224,-3.5522048497285645
507.5000000000065,55.749126090236444,0.13492682829126856,-3.554167397263724
508.6000000000065,55.85901047332968,0.13610076142561223,-3.557547353590426
509.7000000000065,55.96745591067476,0.13507633809202657,-3.5601605839388433
510.80000000000655,56.07779843014372,0.13537576800255202,-3.562274470330483
511.90000000000657,56.186937601568935,0.13393109204260512,-3.562472448411561
513.0000000000066,56.29761186506474,0.13261045916866898,-3.5651231846766867
514.1000000000065,56.40508079865194,0.12925349595807045,-3.567741942605037
515.2000000000066,56.51586683648682,0.13147154067582845,-3.569376464541823
516.3000000000065,56.62576416262484,0.13059840729187266,-3.5703690265630446
517.4000000000067,56.735775184366965,0.12245139453524123,-3.571692058188881
518.5000000000066,56.84492804440309,0.12468910928719978,-3.5729621568460344
519.6000000000067,56.95502796473061,0.1236843393643916,-3.5742929758595205
520.7000000000066,57.06275442063805,0.11939564989089924,-3.575662648550347
521.8000000000067,57.17469806956794,0.12044865852771602,-3.578268060626669
522.9000000000067,57.283451621634946,0.11593941631200666,-3.5795910078584665
524.0000000000067,57.39429466731583,0.11589444524206804,-3.580909538372375
525.1000000000067,57.50333536396933,0.11450561966061246,-3.5822279536390607
526.2000000000068,57.61212560028712,0.1123681516180679,-3.5822207927870884
527.3000000000068,57.72167842652153,0.11122546229187513,-3.583548526042188
528.4000000000068,57.832104847555854,0.10960022369763456,-3.583534910978867
529.5000000000068,57.94218026728902,0.10496045109721841,-3.5836063512004817
530.6000000000068,58.050957819992476,0.100944080936467,-3.5848701365121505
531.7000000000069,58.160921872920134,0.08808052158790236,-3.584869969447225
532.8000000000068,58.27098957663037,0.0841174039137873,-3.5861798784179872
533.9000000000069,58.37989316455375,0.07320932492935706,-3.587500067705538
535.0000000000068,58.49099536872021,0.06635174392630949,-3.587499417768494
536.100000000007,58.60030499766002,0.06235092386281549,-3.588819926756653
537.2000000000069,58.709901034339794,0.06532565710688853,-3.589143461004542
538.300000000007,58.81961742015957,0.06202250087973127,-3.5901420294813446
539.4000000000069,58.9280971856659,0.062046912482786265,-3.5901301569086517
540.5000000000069,59.03872898761764,0.06115513961550212,-3.591449975634204
541.600000000007,59.15010403363077,0.06208215416445828,-3.590460224793914
542.700000000007,59.25933717166313,0.0631745676968043,-3.593074917552883
543.800000000007,59.36880663517483,0.06218781431356568,-3.592705379945138
544.900000000007,59.4788011918304,0.06228266090544787,-3.593098415883025
546.000000000007,59.59043085327399,0.05729481534576886,-3.5931026291197594
547.1000000000071,59.70072328044393,0.05918443691085029,-3.5947980440702048
548.2000000000071,59.810532135493524,0.05691814680759988,-3.595142405517018
549.300000000007,59.92172255251893,0.05422532069704644,-3.594410161021517
550.4000000000071,60.03011938672955,0.05423644449007803,-3.594410160993916
551.500000000007,60.142896951282026,0.053734976590756656,-3.5957022498918274
552.6000000000072,60.252332473812054,0.053900687467329345,-3.597049870742127
553.7000000000071,60.36326934340226,0.051431140249524,-3.5970530036085893
554.8000000000072,60.473317542509314,0.05166464291299455,-3.5970264129140443
555.9000000000071,60.584934170317574,0.05210152229912568,-3.5970492056106598
557.0000000000072,60.69447471184111,0.05256873611771962,-3.5983596365556907
558.1000000000072,60.805281448800265,0.05244254857110375,-3.5989578759547296
559.2000000000072,60.9157448276335,0.05068083385793454,-3.598040134901647
560.3000000000072,61.02679972704428,0.052267889655872146,-3.5980408413898504
561.4000000000073,61.13673454592349,0.05109988222321116,-3.5983282623559436
562.5000000000073,61.24589944847251,0.05030870107326679,-3.5996908950954323
563.6000000000073,61.35843947430317,0.04944205698005755,-3.599690950171919
564.7000000000073,61.469100594190124,0.04946282191239115,-3.600987175322408
565.8000000000073,61.57812660708235,0.047577747730246145,-3.6009923419510317
566.9000000000074,61.68895724858269,0.046928187355637085,-3.6010619766471677
568.0000000000074,61.80000000000065,0.04346213399542842,-3.6003399952801045
569.1000000000074,61.91062759125165,0.047275912301057765,-3.600371022725388
570.2000000000073,62.02065253872157,0.04347378255476686,-3.5997121326909363
571.3000000000073,62.130607414326235,0.04535395564553202,-3.601000433089231
572.4000000000074,62.240572772116714,0.04512993828886369,-3.6009998199977624
573.5000000000074,62.352345760968504,0.041346805667937137,-3.601022265945976
574.6000000000074,62.46252310075758,0.040444134120158015,-3.602320046257757
575.7000000000074,62.57321534599791,0.03855777062034216,-3.6036365189142643
576.8000000000075,62.684510501762226,0.03841064358851698,-3.6036302071715247
577.9000000000075,62.79519186990856,0.03738921291292163,-3.6023097893947775
579.0000000000075,62.90575287182207,0.0360527376086659,-3.6035692880136336
580.1000000000075,63.01496861268589,0.04257576873936397,-3.602320088663895
581.2000000000075,63.127491970641856,0.040410699855135235,-3.60368145022008
582.3000000000076,63.238337128431624,0.04113316195655248,-3.6036398509848624
583.4000000000076,63.348575232652635,0.03865491264818344,-3.6036440239777154
584.5000000000076,63.45980732666534,0.03663878648271224,-3.602321607181782
585.6000000000076,63.56909769437058,0.034319494204709144,-3.6046299630696716
586.7000000000077,63.68117852014244,0.030225208676010862,-3.6046300793986146
587.8000000000077,63.791139224259446,0.03106845810712988,-3.603640762968227
588.9000000000076,63.90199919437553,0.0284260729474739,-3.6049508857131056
590.0000000000076,64.01221594754534,0.02498965817816101,-3.6061710946021353
591.1000000000076,64.1206557158428,0.022339075400207076,-3.604839828271677
592.2000000000077,64.2336080087101,0.020241794641984612,-3.6061685276016866
593.3000000000077,64.34469512693478,0.018288093450122833,-3.6048401141257616
594.4000000000077,64.45464585867848,0.018608481233655993,-3.6047846230931215
595.5000000000077,64.56592667176369,0.01877720564745422,-3.607480563058326
596.6000000000078,64.6762135261023,0.014969092572085785,-3.6061598776298505
597.7000000000078,64.78817693792675,0.014173840085397682,-3.606159671057809
598.8000000000078,64.89864320186966,0.010784887613943361,-3.6061593780759886
599.9000000000078,65.0086684407742,0.010012156281309803,-3.606393693139389
601.0000000000078,65.11900102784095,0.006400580381009657,-3.607424961015392
602.1000000000079,65.2297891825207,0.005217569588340076,-3.608675240120669
603.2000000000079,65.33838789263656,0.0022975413858388194,-3.6060142634429693
604.3000000000079,65.45072959931487,0.00557180159659687,-3.6084129724787664
605.4000000000078,65.56127413793665,0.005676456142975184,-3.6086900875711967
606.5000000000078,65.67292302198479,0.005117796506416639,-3.6093347768063353
607.6000000000079,65.7830320114131,0.0024191935494832784,-3.6106633916891107
608.7000000000079,65.89435534157171,0.0012055733398752544,-3.6106599129980013
609.8000000000079,66.00603450490834,0.0014335026405349893,-3.61065991299176
610.9000000000079,66.11400140975493,-0.001714573484974391,-3.6106815545128796
612.000000000008,66.22499429098374,-0.0027685516201572113,-3.611000172703915
613.100000000008,66.33676894013732,-0.00048353359220421055,-3.611000101874174
614.200000000008,66.44768830032154,-0.0023783538928987547,-3.610670068408779
615.300000000008,66.55968759011301,-0.0031573872441077455,-3.609397236950395
616.400000000008,66.67059824938528,-0.006452532254802357,-3.6096915666871316
617.5000000000081,66.78219893050395,-0.007906044478617869,-3.610605820236048
618.6000000000081,66.89190502062668,-0.006553752030472371,-3.6106598910293415
619.7000000000081,67.00304773383478,-0.009409673125667872,-3.610659897533434
620.8000000000081,67.11407813851632,-0.00846653174930534,-3.6119804617554543
621.9000000000082,67.22543196057099,-0.011316317777545493,-3.611980126286648
623.0000000000082,67.33627481710059,-0.017074737683442365,-3.611298149201381
624.1000000000081,67.44732108807112,-0.014841635205000703,-3.6119720506480024
625.2000000000081,67.55848146186959,-0.017610795335610163,-3.6119799440022984
626.3000000000081,67.66846212038485,-0.023204059320696135,-3.611979944
627.4000000000082,67.77922655857003,-0.02380234514807711,-3.6119799439999922
628.5000000000082,67.89028255909021,-0.025449288601346876,-3.6119799408235043
629.6000000000082,68.00155941985413,-0.02418409310176095,-3.611981089277048
630.7000000000082,68.11369706920819,-0.027257009633619766,-3.610683744424514
631.8000000000083,68.22314831133538,-0.032398949321381654,-3.612110142453897
632.9000000000083,68.33459553730015,-0.03314562524025,-3.613296627855851
634.0000000000083,68.44596157216216,-0.033437107187146875,-3.613421476003102
635.1000000000083,68.55699733742446,-0.033204195278936144,-3.613146169736368
636.2000000000083,68.6676437025208,-0.035519807230938394,-3.6129117635926598
637.3000000000084,68.7785001467392,-0.034678618112137904,-3.612749981048808
638.4000000000084,68.88999789215667,-0.03850069338771078,-3.613729859402663
639.5000000000084,69.00040760644472,-0.03514757616772268,-3.6147521926569235
640.6000000000083,69.11082541887531,-0.041098192498849606,-3.6146489214537882
641.7000000000083,69.22287243397889,-0.043367852118699535,-3.6124196697497415
642.8000000000084,69.33381004897923,-0.04265811007064224,-3.613410074492425
643.9000000000084,69.44518296986804,-0.04456280273458635,-3.613410169001258
645.0000000000084,69.55712044741887,-0.04307362675694559,-3.613130330874067
646.1000000000084,69.66703190609775,-0.04379907278781481,-3.6120901688025406
647.2000000000085,69.7787972390553,-0.04516430105733393,-3.612090157558063
648.3000000000085,69.88832277755122,-0.044013126041464457,-3.6134111751544156
649.4000000000085,70.00202505531911,-0.04730907812898888,-3.613027386091522
650.5000000000085,70.11354318792978,-0.04801257319518415,-3.6127497571179674
651.6000000000085,70.22469134754198,-0.05054207173978709,-3.614060407610026
652.7000000000086,70.33571286784898,-0.0541328080930672,-3.614064390745864
653.8000000000086,70.44751782546176,-0.0560611493730887,-3.613400146891368
654.9000000000086,70.55837444940151,-0.06039595067478798,-3.6134001470000006
656.0000000000086,70.66978770759229,-0.05806899950370781,-3.613400146362417
657.1000000000087,70.78074232128539,-0.06030700488492613,-3.6120993318157657
658.2000000000087,70.89249978483608,-0.06273059579216733,-3.6143899931457
659.3000000000086,71.00411655920684,-0.057834116434535954,-3.614060665901592
660.4000000000086,71.11618395321736,-0.06510263907444713,-3.6140599150032537
661.5000000000086,71.2277533927243,-0.05850317185069365,-3.6140068083801786
662.6000000000087,71.33942927619648,-0.061581782415017106,-3.614390202843826
663.7000000000087,71.44859893683224,-0.06485656455814137,-3.6140300284929894
664.8000000000087,71.56227952068127,-0.06660638032465904,-3.61407014303768
665.9000000000087,71.6730044767596,-0.06914197796765542,-3.614014676104697
667.0000000000088,71.78400020263732,-0.06751548150942277,-3.6140699680822204
668.1000000000088,71.89616370262122,-0.07124531435058623,-3.6140694145172665
669.2000000000088,72.00733630986149,-0.0716086931986335,-3.6134106148970737
670.3000000000088,72.11924980603283,-0.06913960447793066,-3.6134065869769945
671.4000000000088,72.23020855056527,-0.07165482441151783,-3.6134100250022723
672.5000000000089,72.34204072180253,-0.07587357401788308,-3.613394238139355
673.6000000000089,72.45317403451035,-0.07355662907365046,-3.6147201793202117
674.7000000000089,72.56490189942977,-0.0765260661034386,-3.6147201779999993
675.8000000000088,72.67627906113226,-0.07594445569325581,-3.6147201780000002
676.9000000000088,72.78739876054563,-0.07597746751193357,-3.6147201779999993
678.0000000000089,72.89870876654885,-0.07477506995893135,-3.6147201807281526
679.1000000000089,73.01086555098232,-0.07899054938568106,-3.6147261116692566
680.2000000000089,73.12092210570663,-0.07922152100912294,-3.6160419920507936
681.3000000000089,73.23290716500765,-0.08482525935136742,-3.6160260101093344
682.400000000009,73.34376023387182,-0.08351968441309365,-3.6147200037191087
683.500000000009,73.45578941467302,-0.08318208659410198,-3.6147418166812346
684.600000000009,73.56677896490177,-0.08041701050505923,-3.6153801183979932
685.700000000009,73.67846844311083,-0.08068450287031892,-3.6153662805853415
686.800000000009,73.79030726830746,-0.07978343325245518,-3.6153798221953215
687.9000000000091,73.90088989836192,-0.08089167239567496,-3.6157188363503328
689.0000000000091,74.01333508284763,-0.08020076046917346,-3.6157199990017803
690.1000000000091,74.12497418751973,-0.0786325414163449,-3.615719998810058
691.2000000000091,74.23602490679919,-0.08228425673336393,-3.615343301519704
692.3000000000092,74.34761481796768,-0.08351046896118364,-3.6170287301277284
693.4000000000092,74.46019962224503,-0.08063794774516664,-3.61603108265347
694.5000000000091,74.57254257693147,-0.07450146254601231,-3.6157293857405404
695.6000000000091,74.68261643099788,-0.07495555591093206,-3.6154784425685706
696.7000000000091,74.79562534506469,-0.07644237816034627,-3.6157097209706053
697.8000000000092,74.90801603620619,-0.07620712312509648,-3.615709920000046
698.9000000000092,75.0194796751616,-0.0750306672953247,-3.61570992
700.0000000000092,75.13038928579412,-0.07633093858458162,-3.61570992
701.1000000000092,75.24296334926098,-0.07441100390193611,-3.6157099260630265
702.2000000000093,75.35421729043641,-0.07899888530463572,-3.617027252064525
703.3000000000093,75.46519990762765,-0.08001595644932458,-3.6184573007652134
704.4000000000093,75.57492136467795,-0.07582862556852188,-3.6167039192807375
705.5000000000093,75.6877489145565,-0.07973388431913131,-3.6153764342151957
706.6000000000093,75.80000191125244,-0.0773075029625554,-3.6167099850246567
707.7000000000094,75.91110607389108,-0.07727285501016334,-3.6166203134116817
708.8000000000094,76.02011289938888,-0.07843489509544277,-3.615927039192342
709.9000000000094,76.13274049037064,-0.07908553816024311,-3.614852623223851
711.0000000000093,76.24572092965053,-0.07617052904086741,-3.6156100301513936
712.1000000000093,76.35699099896556,-0.0768247931638828,-3.6156100178893325
713.2000000000094,76.46867551687448,-0.08059461006898871,-3.6171585804276996
714.3000000000094,76.58057930259763,-0.07701925780300733,-3.6159298336685906
715.4000000000094,76.69322717100451,-0.07648491558493431,-3.6166001965320604
716.5000000000094,76.80337512677329,-0.07765427387372359,-3.61527944350167
717.6000000000095,76.91755544229514,-0.07768150651489503,-3.6165902082597
718.7000000000095,77.02899019919862,-0.07608251062853588,-3.61658995099996
719.8000000000095,77.14187925096935,-0.07454542287102939,-3.616589951000051
720.9000000000095,77.25162790947734,-0.07612628679423894,-3.6165898838320114
722.0000000000095,77.36548766623137,-0.07555673333497825,-3.6152699044484136
723.1000000000096,77.47627852661311,-0.07743181668085652,-3.616474347759748
724.2000000000096,77.59011042737451,-0.07642570528814874,-3.616589612290549
725.3000000000096,77.7020703432516,-0.07492576062990741,-3.615269347290379
726.4000000000096,77.8138992217091,-0.07176546641734838,-3.6152704124033646
727.5000000000097,77.92671586697816,-0.07213491342525158,-3.6162700989648817
728.6000000000097,78.03849020976969,-0.06839953282209343,-3.6175799632251637
729.7000000000096,78.150391470365,-0.07114532178482147,-3.6175725134025067
730.8000000000096,78.26224846147628,-0.07149966928144913,-3.618878242680613
731.9000000000096,78.3751532029637,-0.06654349470450649,-3.6175701568941876
733.0000000000097,78.48671352205047,-0.06761344980912609,-3.617570157310623
734.1000000000097,78.59960525915238,-0.06863139240764493,-3.616528011845038
735.2000000000097,78.71059568179459,-0.07099489199373288,-3.617579983417369
736.3000000000097,78.82229615915355,-0.06961405476007032,-3.6175799819973182
737.4000000000098,78.93555708634109,-0.06976426588756413,-3.6175892744613405
738.5000000000098,79.04674729882832,-0.0641639585871503,-3.618888966283223
739.6000000000098,79.15875921931722,-0.06213298041979298,-3.617568264000113
740.7000000000098,79.27142333106457,-0.06313654078452391,-3.6173563294481332
741.8000000000098,79.38365222071141,-0.06235419532664377,-3.618578079861637
742.9000000000099,79.49622944899495,-0.06290434186064653,-3.6172504924891054
744.0000000000099,79.60792407331277,-0.05974195694311479,-3.616530354696775
745.1000000000099,79.72054476453553,-0.06050215867687081,-3.61758015310974
746.2000000000098,79.83284731716259,-0.06257634627961606,-3.6162477780667484
747.0000000000099,79.91627581957668,-0.06076081565425673,-3.6169235760532734