File: 01_Data/PEVA/STA/N2/10K_min/PEVA_STA_N2_10KData_240802_R3.csv
##Temp./Â°C,Time/min,DSC/(mW/mg),Mass loss/mg
51.0,10.833543496587236,0.042885977203496406,0.006049440528163252
52.100000000000016,11.121907159454402,0.09451601353275763,0.006586930649908673
53.20000000000003,11.32540429792068,0.1298653914882828,0.006166572886499466
54.30000000000005,11.494923442098019,0.1610499393614866,0.005499308231847522
55.40000000000006,11.648126925585338,0.18405616135687453,0.006681658799550405
56.50000000000008,11.7913082217664,0.20255832294065979,0.0049652995336693095
57.600000000000094,11.927881288284032,0.21717742206177704,0.004826029352166472
58.70000000000011,12.058455169398385,0.2307466627892718,0.005000936855736882
59.800000000000125,12.182778226711498,0.24533444317085396,0.004310992658925095
60.90000000000014,12.311555457259933,0.25187527795312814,0.003726409838323619
62.000000000000156,12.434835606623126,0.26109222637379004,0.003451866034658302
63.10000000000017,12.555469211582336,0.2667525936194366,0.004659418034823837
64.20000000000019,12.675405902776482,0.2711200567774381,0.004899875475866899
65.30000000000021,12.793654209773159,0.2761839130789303,0.00614571884689763
66.40000000000022,12.909413695225524,0.27969279782614365,0.004128046450230016
67.50000000000023,13.02907516597191,0.2838975848408336,0.004508691773154716
68.60000000000025,13.14362100256595,0.28524636223897826,0.004846486587164023
69.70000000000027,13.262167578954603,0.2885536719124375,0.005127671816857138
70.80000000000028,13.378415441308158,0.2910192200755177,0.006145782779649167
71.90000000000029,13.493672108786189,0.29543450866649534,0.005782257979272565
73.00000000000031,13.609275922105729,0.29568476079310324,0.006152621105038669
74.10000000000034,13.723600074379457,0.2973778287349562,0.006159931691914977
75.20000000000034,13.837763615270477,0.29785463820977265,0.00616155478438607
76.30000000000035,13.95111874212132,0.2998351987754515,0.005604884069036586
77.40000000000038,14.065942817530523,0.3046948167477068,0.006150290243088108
78.5000000000004,14.17827349781469,0.30844618446883576,0.0061494231675620625
79.6000000000004,14.291899186456355,0.30824327461707357,0.005834244016468482
80.70000000000041,14.403478622228224,0.3104209262830828,0.007495960263019796
81.80000000000044,14.514580029588938,0.3116356488311025,0.007140267454961879
82.90000000000046,14.626897288176428,0.31515430050101223,0.006143412679772808
84.00000000000047,14.738857546099677,0.31853435750222125,0.004500240005210543
85.10000000000048,14.850622311224535,0.3224607513981077,0.006147338765686072
86.2000000000005,14.960095585698955,0.32524094058009245,0.006173253249284194
87.30000000000052,15.070610253324025,0.3290560274682566,0.007478301663399911
88.40000000000053,15.18166724638851,0.3308505288231851,0.0074719602368960025
89.50000000000054,15.291727795689527,0.33403868778361323,0.008789341916498827
90.60000000000056,15.400093145804332,0.33729965961832686,0.007469959967342454
91.70000000000059,15.50716791498648,0.3407806501446,0.007462791855581408
92.8000000000006,15.618572177006122,0.34245747093093115,0.008599056412060158
93.9000000000006,15.727189327906071,0.3426104051128229,0.0077998427923517966
95.00000000000063,15.835367097286882,0.348544717783414,0.009151086317397805
96.10000000000065,15.944701831951823,0.3504152704242527,0.00747527557073191
97.20000000000066,16.05275166963622,0.35526373437954906,0.006759734981368837
98.30000000000067,16.160522976760056,0.3570665579935417,0.007800101660021319
99.40000000000069,16.268150969542283,0.35729112580202527,0.007470088537259834
100.50000000000071,16.375939703017835,0.3603148976907624,0.006147280861631188
101.60000000000072,16.483346728754288,0.36335576754471344,0.007469021036001777
102.70000000000073,16.59092526478564,0.36179486091716173,0.006978329633403391
103.80000000000075,16.698631444490122,0.36163247189033054,0.007581697382290642
104.90000000000077,16.80655734965957,0.36203645745568425,0.007891546910283154
106.00000000000078,16.91303851809282,0.3623220324987271,0.008896899185313778
107.10000000000079,17.019342308298263,0.36396364608716825,0.007573144512613261
108.20000000000081,17.128314908736733,0.3640450662390142,0.009560856649355465
109.30000000000084,17.234916292151524,0.3659305163631581,0.00955981093845093
110.40000000000084,17.340567570636043,0.3660869429028848,0.008239984146667823
111.50000000000085,17.44578150414619,0.371129531218513,0.009547875883746393
112.60000000000088,17.555749987919345,0.3742943979648965,0.01086500444649019
113.7000000000009,17.662509863128225,0.37160032783047736,0.009560108871987438
114.8000000000009,17.770000000000103,0.3751610358368769,0.010220154042456464
115.90000000000092,17.877106378200928,0.3780273058747947,0.009935826807454973
117.00000000000094,17.982739482332196,0.37865538742539506,0.007580162781029465
118.10000000000096,18.090467166174594,0.38108668530222767,0.0075730451970059676
119.20000000000097,18.196739926586663,0.3833898066197885,0.008869391571318275
120.30000000000098,18.303519810437283,0.38557981685522824,0.009270669183697677
121.400000000001,18.41073767589017,0.38756925056452296,0.010542941744160927
122.50000000000102,18.51699700944041,0.3873033207572809,0.011860097243048706
123.60000000000103,18.623334352358277,0.3889382037541469,0.011856892035120303
124.70000000000104,18.730613666674675,0.3925249731887317,0.010236921902028406
125.80000000000106,18.834590080970198,0.3937008859275779,0.010220095981932964
126.90000000000109,18.938297281616844,0.395945111810164,0.010215281596352987
128.00000000000108,19.047610269311424,0.39783836895353275,0.011211510558260862
129.1000000000011,19.15422453437395,0.400841520089974,0.011870905499559825
130.20000000000113,19.261158410925916,0.40101702763789726,0.01163316978647888
131.30000000000115,19.366709734150668,0.40183249634722396,0.010869964616533778
132.40000000000117,19.472781293990572,0.40322480243640246,0.010869594889966194
133.50000000000117,19.578205535827887,0.4049379327614684,0.01218830544118088
134.6000000000012,19.68490861989435,0.407218932661364,0.00949283165221182
135.7000000000012,19.791544057695507,0.40691982303521756,0.010870149254475159
136.8000000000012,19.896837668347334,0.4075565574323221,0.012192404644252974
137.90000000000123,20.002373469985912,0.40804958352496046,0.012175285241752931
139.00000000000125,20.108149336360626,0.4112192039281535,0.01086994663505969
140.10000000000127,20.212914609046777,0.4147718046700861,0.012197429456898945
141.2000000000013,20.317898806319256,0.41457795165663924,0.012847705569397405
142.3000000000013,20.421925483130238,0.4150765014080706,0.01220057297693078
143.4000000000013,20.529646136018325,0.41788360707518857,0.010879606877679748
144.50000000000134,20.636165100398177,0.4186272629634864,0.010878759488900158
145.60000000000133,20.73777916879629,0.4198760037110194,0.010909770452363965
146.70000000000135,20.84522429243095,0.4205904764395174,0.012190710511040592
147.80000000000138,20.951423885761088,0.4238369683344714,0.013287546395151395
148.9000000000014,21.056061168442216,0.426481990949481,0.01351006133414856
150.00000000000142,21.162193671459622,0.43031468234384995,0.012189954764100897
151.10000000000142,21.2678749940346,0.42898730283912867,0.012189887999911164
152.20000000000144,21.370792739980175,0.42961655578370994,0.012189887997301696
153.30000000000146,21.475930401190624,0.4314862297375135,0.012194151326984759
154.40000000000146,21.580860484736064,0.43367218835650423,0.010869889659208098
155.50000000000148,21.685456145361098,0.4357939909882371,0.010869888005835548
156.6000000000015,21.79183262663643,0.4365936305727911,0.010866315778264912
157.70000000000152,21.89555656156956,0.43687935582438264,0.01207851736338661
158.80000000000155,21.99979948126043,0.437883770222963,0.012200063385707338
159.90000000000154,22.105500291891044,0.44059152205346086,0.012227031649942433
161.00000000000156,22.209909246015997,0.4413740671301434,0.013510139034957014
162.1000000000016,22.315024174706213,0.44246124834158174,0.013506358934168183
163.20000000000158,22.41830246433218,0.4429180360782454,0.011214592935589351
164.3000000000016,22.525009807535135,0.4447376797269298,0.012519134270574384
165.40000000000163,22.6299070100022,0.44879086011502034,0.013509811530089344
166.50000000000165,22.734246190589673,0.4468030381556898,0.013508665115524288
167.60000000000167,22.838297576427145,0.447085547617764,0.011860273469989302
168.70000000000167,22.943518277380612,0.44937696204581945,0.01088116697806818
169.8000000000017,23.04839511704114,0.4527429854931895,0.010870116003824926
170.9000000000017,23.153094485191176,0.4528751192912672,0.010870113945311566
172.0000000000017,23.257249192127354,0.451582569630379,0.010543273834890066
173.10000000000173,23.3630536516297,0.4536968383264237,0.010539432274206284
174.20000000000175,23.467025880389638,0.4551860944990347,0.012683938552442875
175.30000000000177,23.572743726702083,0.4546842659692363,0.011529887103240988
176.4000000000018,23.677378535287936,0.45559573004447396,0.011509867890446834
177.5000000000018,23.78101075298651,0.4574108125269887,0.010221217726590126
178.6000000000018,23.887798936782787,0.46079758207966837,0.011530830517550328
179.70000000000184,23.99064418091971,0.46066624372757214,0.010549876771047906
180.80000000000183,24.095856989122808,0.459806716096566,0.010549898997769702
181.90000000000185,24.201079446077994,0.46318362174600036,0.010551127753372747
183.00000000000188,24.30617694389777,0.45961361437721004,0.010550056677200104
184.1000000000019,24.40891983264573,0.4601868274457628,0.009242265486888002
185.20000000000192,24.515501454997455,0.45904380084396257,0.009229899041032219
186.30000000000192,24.618600570993618,0.4598607324486501,0.009267286267486519
187.40000000000194,24.723700282123527,0.4599386941420418,0.010256223987131108
188.50000000000196,24.82861439337622,0.46012361142612734,0.007957510684269309
189.60000000000196,24.931531511378974,0.4586009423213073,0.0086934220220245
190.70000000000198,25.03873127553645,0.46063174784786964,0.007915296449705345
191.800000000002,25.141360160698135,0.46017930468412027,0.007910099966627726
192.90000000000202,25.246528812307307,0.46423799608157035,0.009230177027805375
194.00000000000205,25.35181624043502,0.4624213317997823,0.009229968156267532
195.10000000000204,25.455116777323106,0.46284152446201965,0.00890736104312051
196.20000000000206,25.56088452047486,0.4644185892043655,0.007579971129755059
197.3000000000021,25.665705034849847,0.4666978939116395,0.007579967970011481
198.40000000000208,25.77029112614738,0.46496558547611544,0.007583031053978395
199.5000000000021,25.873973219852783,0.46633908723410245,0.006903168155805162
200.60000000000213,25.978993977422114,0.46682210106035726,0.00824003205916135
201.70000000000215,26.082684113937653,0.4698890914788427,0.006919932422126074
202.80000000000217,26.187744485980776,0.46569698357695977,0.0055148347097526695
203.90000000000217,26.292090421932613,0.46568761259366953,0.0057800894217026055
205.0000000000022,26.39719379832961,0.4679569454555572,0.002860655969961101
206.1000000000022,26.499252126329846,0.4681996774612309,0.0028593220140660236
207.2000000000022,26.605469826048857,0.4682831130510554,0.0028752737779251802
208.30000000000223,26.71000000000022,0.4707032547584251,0.0015361323961808893
209.40000000000225,26.813972684259376,0.469112135900434,0.00023050238018296199
210.50000000000227,26.919558341378693,0.4706121488885895,-0.0010922785128970602
211.6000000000023,27.02435988376568,0.4735622150062271,-0.0010872805683561637
212.7000000000023,27.127867402696836,0.4727149352356925,-9.594861055628456e-05
213.8000000000023,27.233162188442915,0.4752941059574938,-0.0029943357801966997
214.90000000000234,27.337620778105634,0.47457159247476377,-0.004806196550418029
216.00000000000233,27.441490786828226,0.47517278651712713,-0.005370166613931637
217.10000000000235,27.546606183859897,0.47722851004181654,-0.006692388615489264
218.20000000000238,27.65091090368113,0.476314444088076,-0.008510870284538896
219.3000000000024,27.75551373121225,0.47504262857390156,-0.009989475504244894
220.40000000000242,27.860188674163897,0.47662635538188525,-0.010965513702726692
221.50000000000242,27.964237203140886,0.47605604378138255,-0.011598985960505015
222.60000000000244,28.068596928367203,0.4779962206911492,-0.012358672164659357
223.70000000000246,28.173170872696808,0.47555542160308506,-0.013294446491686873
224.80000000000246,28.27741307554933,0.4761881295894854,-0.015909845330911665
225.90000000000248,28.38188027075892,0.47663587219378045,-0.017229143474067232
227.0000000000025,28.48695783216591,0.47584096591391,-0.0185781783797907
228.10000000000252,28.592134391957675,0.4773642072881079,-0.01985231946291144
229.20000000000255,28.697019526482055,0.4771802795869675,-0.02251139032676397
230.30000000000254,28.800357721413835,0.4770561654826424,-0.026450738798641016
231.40000000000256,28.904932391543113,0.47591494008104296,-0.02955858361425312
232.5000000000026,29.01000000000026,0.4718924889864693,-0.03270014100002028
233.60000000000258,29.114471822383013,0.4697206837276364,-0.03475864246981253
234.7000000000026,29.21906468726906,0.46787467095039403,-0.03711845042937201
235.80000000000263,29.32303424663186,0.4653605489476911,-0.03978149031352096
236.90000000000265,29.428112899795533,0.46431129660589643,-0.04324219991062295
238.00000000000267,29.532659417015214,0.4622726433437707,-0.045163528585920876
239.10000000000267,29.637683815337624,0.4598144278571126,-0.04948623589691303
240.2000000000027,29.741771799506164,0.45815625110304015,-0.05386348555501286
241.3000000000027,29.84516263086241,0.45587472074280666,-0.05794990599456318
242.4000000000027,29.948488210190753,0.45457227236441944,-0.060088717414093384
243.50000000000273,30.055155121646816,0.45410399805940793,-0.06712595999903881
244.60000000000275,30.160799429100063,0.4524811593668221,-0.07286221870479714
245.70000000000277,30.264240771740763,0.453459873925423,-0.07865917943696132
246.8000000000028,30.36859054741344,0.46192946917818434,-0.08436953788093682
247.9000000000028,30.47524231995021,0.48682083730946824,-0.08866165675612603
249.0000000000028,30.582130042309423,0.5175532611690437,-0.09741822942900535
250.10000000000284,30.684265613756757,0.5411485225178851,-0.10367306592762526
251.20000000000283,30.79279102869366,0.559872274724406,-0.11204641327347753
252.30000000000285,30.898013316175227,0.5719940852001488,-0.11950162347357818
253.40000000000288,31.003079281038055,0.5805049448407236,-0.12850568424768172
254.5000000000029,31.108497675240102,0.5885676612737019,-0.13782314303339094
255.60000000000292,31.213279643632653,0.5957379690134055,-0.14719927911519504
256.7000000000029,31.31714703409004,0.6050855715834671,-0.15818191551397875
257.8000000000029,31.422755189610502,0.6135681300410336,-0.1694291594452948
258.90000000000293,31.527492660359552,0.6242529997594428,-0.18140133938142666
260.00000000000296,31.632580440800105,0.6312230417516707,-0.19438925189930156
261.100000000003,31.73805618218634,0.6444813526241537,-0.20795554285644613
262.200000000003,31.84413537791413,0.6532601263279243,-0.22209679848885688
263.300000000003,31.948513072869385,0.6668494675394139,-0.23766826182166545
264.40000000000305,32.054637405385435,0.6786782152395663,-0.25345857641626424
265.50000000000307,32.15944454462822,0.6940793339319742,-0.27094154726669517
266.6000000000031,32.265245996859164,0.7090944088578441,-0.29013534359870263
267.7000000000031,32.371759323878734,0.7251095568388257,-0.31090071015280385
268.8000000000031,32.47807836503565,0.7419261584907753,-0.3345018987604771
269.9000000000031,32.58334014812343,0.7595746355936879,-0.35948270833318885
271.0000000000031,32.69050091361512,0.7794082757130045,-0.38470321552312425
272.10000000000315,32.796406469615114,0.7996936896076563,-0.40982845078308205
273.2000000000032,32.9013078133706,0.816215124063469,-0.4407312652388553
274.30000000000314,33.00688609833013,0.8311673456360416,-0.47250287152005166
275.40000000000316,33.11445658664722,0.8490985044210859,-0.5053273982344444
276.5000000000032,33.22097328998298,0.8626484558952352,-0.541123780858618
277.6000000000032,33.32623655264757,0.8800833995892516,-0.5753419155958839
278.70000000000323,33.434185776303515,0.9000527541779808,-0.6141380119903426
279.80000000000325,33.53967941442029,0.913873166179691,-0.6569095375570724
280.9000000000033,33.64615173304818,0.9312641643152266,-0.6991284973202729
282.0000000000033,33.751837629475965,0.9475333862547004,-0.7438573808031936
283.1000000000033,33.857771125634315,0.9644833326148046,-0.7891823696974121
284.20000000000334,33.96396722158033,0.977462322207703,-0.8369951407069935
285.30000000000337,34.070388405956486,0.9926376105786474,-0.8869705421733936
286.40000000000333,34.17705017052442,1.0088919073583156,-0.940676894739799
287.50000000000335,34.283105491160406,1.022295274982414,-0.9953650347746561
288.6000000000034,34.38980663964513,1.04078613072851,-1.0525086618246369
289.7000000000034,34.497218347293504,1.078581889246341,-1.1125342693569111
290.8000000000034,34.60444648656623,1.1082089169238263,-1.174088328544073
291.9000000000034,34.710315824743965,1.106677032452903,-1.2337881428979403
293.0000000000034,34.81698895289827,1.1198088867743814,-1.3012034892670568
294.10000000000343,34.919796467658244,1.1203385920054236,-1.3642306337684937
295.20000000000346,35.029059153371,1.1411123081885945,-1.4348023444544515
296.3000000000035,35.13472261477369,1.159505421123536,-1.5033396849497067
297.4000000000035,35.240293710248274,1.14847568327125,-1.5692081889754879
298.5000000000035,35.34564870755248,1.1460913607374912,-1.6400071418590394
299.60000000000355,35.45161660925111,1.1192905177510228,-1.7105892255025097
300.70000000000357,35.55513206893421,1.0860806833495822,-1.7774855609354532
301.8000000000036,35.660094189937546,1.059020024736516,-1.8448466074694583
302.9000000000036,35.76314539243624,1.0287361836921949,-1.9070037883650865
304.0000000000036,35.866375318761,0.9882716956296849,-1.969013451246418
305.1000000000036,35.970502621752914,0.9461997086470879,-2.0282248814773287
306.2000000000036,36.07400937864321,0.90430285780931,-2.0831970574812995
307.30000000000365,36.17693052356386,0.8627482748706314,-2.1322875014693428
308.4000000000037,36.28076294529948,0.8242083260287698,-2.176416633273967
309.5000000000037,36.38279751342125,0.7848335309111603,-2.2180298092487085
310.60000000000366,36.48712568313412,0.7491562171280348,-2.2590117033958927
311.7000000000037,36.589999081956314,0.7192457754333246,-2.292702113107737
312.8000000000037,36.69395311304257,0.6882094265003234,-2.3262616108497385
313.90000000000373,36.7974061338707,0.6574613293101883,-2.355375522005593
315.00000000000375,36.901810380574354,0.6341761035364124,-2.3852441384870016
316.1000000000038,37.005698084995586,0.6131071291085703,-2.410577232197477
317.2000000000038,37.10963959143629,0.5927468029552561,-2.436234659590145
318.3000000000038,37.21402810867355,0.5769322943370332,-2.458675978900808
319.40000000000384,37.3175594500037,0.5593748804125833,-2.4829528102611333
320.5000000000038,37.42298124917278,0.5441156954457593,-2.5032164463790485
321.60000000000383,37.528369460963305,0.5271539372569807,-2.524334224489245
322.70000000000385,37.63271401863721,0.5137895098457359,-2.544742362398117
323.8000000000039,37.737697679437886,0.5015518394211775,-2.5636726514917223
324.9000000000039,37.8423792742945,0.48993652641255325,-2.5824692597271452
326.0000000000039,37.9472930731768,0.4731409268460398,-2.5971166954319496
327.10000000000394,38.0528469948725,0.46151312186446214,-2.613129908876126
328.2000000000039,38.15860005835612,0.4477740297031416,-2.6290648704625914
329.30000000000393,38.262983166348235,0.4363965795571958,-2.6464232109097763
330.40000000000396,38.368009493904125,0.4207671746855812,-2.659162739251668
331.500000000004,38.473873875342825,0.40846867125131503,-2.6735364006293687
332.600000000004,38.57931412070933,0.3946581787721657,-2.6856342646376676
333.700000000004,38.683289977942195,0.3805055697556572,-2.698689066067821
334.80000000000405,38.78921769468919,0.36783028252844785,-2.710815803200694
335.90000000000407,38.89510392035171,0.3555994378460583,-2.7247063770304973
337.0000000000041,39.000455247955315,0.3430480683916848,-2.73598580462561
338.10000000000406,39.106417135226266,0.3306138018830569,-2.7446224324699022
339.2000000000041,39.21210460423141,0.3157074401007436,-2.7573268676935205
340.3000000000041,39.31786315881412,0.301139011210632,-2.7664075833871937
341.4000000000041,39.423707568734734,0.2889550484131074,-2.77538616351751
342.50000000000415,39.529186544979275,0.27499959342752245,-2.783294832944807
343.6000000000042,39.63439501563298,0.2647314983701201,-2.7926557879339797
344.7000000000042,39.74075929267545,0.25291641851047775,-2.800323665140746
345.80000000000416,39.84635531201914,0.2415406156416875,-2.8079917511319055
346.9000000000042,39.951930728745474,0.23049775512022785,-2.8141633783595266
348.0000000000042,40.05741944180606,0.2191633551478569,-2.8207108897240945
349.10000000000423,40.16368313603101,0.2083619058619144,-2.827750676308108
350.20000000000425,40.27053041326593,0.1958352511877921,-2.8311924910978687
351.3000000000043,40.3761538980811,0.19065904032178116,-2.8341724719174612
352.4000000000043,40.48242556732643,0.17917341791512964,-2.8388391240420505
353.5000000000043,40.58922794071087,0.16978522496663873,-2.8449052651339306
354.60000000000434,40.69519104692313,0.16382584243642295,-2.849427799767977
355.7000000000043,40.801852661824434,0.1571821518405625,-2.85379230158367
356.80000000000433,40.90794586884462,0.15057025636997468,-2.856485907096324
357.90000000000435,41.014526335203826,0.14368453987572227,-2.860719998127892
359.0000000000044,41.120795748172704,0.1405372450793827,-2.8632429946724307
360.1000000000044,41.226897212891174,0.13487700732052366,-2.8660303817334554
361.2000000000044,41.334031910865775,0.13214597374166015,-2.868585639439515
362.30000000000445,41.4404587931495,0.1257691967184189,-2.8683410557910767
363.4000000000044,41.54756782907121,0.12240090216524013,-2.8719145787390383
364.50000000000443,41.65394843143513,0.12404894333585048,-2.8746105134046878
365.60000000000446,41.760973942227984,0.11959282800243454,-2.8773711326736118
366.7000000000045,41.86587962160046,0.11681583949500629,-2.8772996476971304
367.8000000000045,41.975119399139004,0.11613432418695524,-2.878677974701803
368.9000000000045,42.08220004551458,0.11715975891789787,-2.8799408396445214
370.00000000000455,42.18880917790718,0.11653014331583611,-2.8809301035285007
371.10000000000457,42.29639733942532,0.11430340823436103,-2.879615354938796
372.2000000000046,42.40278569149511,0.11448203369978982,-2.879748038313628
373.30000000000456,42.50926679607341,0.11298253305393846,-2.880920784667815
374.4000000000046,42.61704331080323,0.1130669944251057,-2.881290454611137
375.5000000000046,42.72442437741734,0.1158274598348985,-2.8809327750531666
376.6000000000046,42.830760158652346,0.11443380564736305,-2.8835617547886705
377.70000000000465,42.93778373135587,0.11509251388229158,-2.8862134723470634
378.8000000000047,43.04520983192214,0.11640626247498798,-2.885870880884433
379.9000000000047,43.15234380143455,0.11243737931385756,-2.887518839825818
381.00000000000466,43.25855853620676,0.11194595864316392,-2.8875199048130744
382.1000000000047,43.36703310847885,0.1115076373266124,-2.88619672975735
383.2000000000047,43.473719726949234,0.109171647083397,-2.8861998109925806
384.30000000000473,43.58163039680758,0.10939556435572984,-2.8862122564451047
385.40000000000475,43.687749832386366,0.10885313847924216,-2.8861998252541987
386.5000000000048,43.79548629847869,0.10178826248992223,-2.8868184905685346
387.6000000000048,43.900945101632544,0.10196896558614821,-2.8892927888608027
388.7000000000048,44.00973483667284,0.10180019979338706,-2.890595632319038
389.80000000000484,44.11458884960978,0.09978465558987804,-2.8905901199430524
390.9000000000048,44.22398642929478,0.09858460726148932,-2.890590107614451
392.00000000000483,44.33160003071431,0.09667642059511916,-2.891902897662283
393.10000000000485,44.43952290707826,0.09218985085271436,-2.8922302849472468
394.2000000000049,44.5464518389101,0.0932234792313138,-2.8935499680901247
395.3000000000049,44.651366438227015,0.08804721385189396,-2.892840577558694
396.4000000000049,44.76237473489298,0.08596469117616845,-2.8912497562113857
397.50000000000495,44.867075403946146,0.08652582833855016,-2.8925626747754687
398.6000000000049,44.97595589242946,0.08120121451474205,-2.893880051481105
399.70000000000493,45.08391574709248,0.0779775950450321,-2.895200641513769
400.80000000000496,45.19076708410257,0.07628177688764781,-2.8952520712129797
401.900000000005,45.298761369950626,0.07462503597008174,-2.895199852866683
403.000000000005,45.40633700704136,0.06848980297682328,-2.89652420855952
404.100000000005,45.51328460167567,0.06718515063560782,-2.8991510043724156
405.20000000000505,45.62162486103063,0.06418435912556797,-2.8978300178646874
406.30000000000507,45.729796275706654,0.061811628905251936,-2.8991503913104157
407.4000000000051,45.83791607744813,0.05752052972833965,-2.900477058495369
408.50000000000506,45.94465073073748,0.0561645207129744,-2.900469428071964
409.6000000000051,46.05269845079871,0.05225998178074409,-2.9017799996762217
410.7000000000051,46.160581364454,0.05004700456891209,-2.903111763731476
411.8000000000051,46.268374635196466,0.04663882174379852,-2.904315032396158
412.90000000000515,46.376081491683394,0.04312392084326788,-2.9052602867165707
414.0000000000052,46.483494853061714,0.03872478651345235,-2.9042040274369563
415.1000000000052,46.590983271262466,0.036804125484982464,-2.9056918968231984
416.20000000000516,46.69894017391026,0.0325040168975832,-2.907400910476306
417.3000000000052,46.806135373483,0.026978230262028724,-2.909595691210116
418.4000000000052,46.91496147465274,0.022154780446582034,-2.911148106452565
419.50000000000523,47.02291354287922,0.020019120732174933,-2.913545499921679
420.60000000000525,47.13009259154289,0.01580603588961127,-2.9148507715386067
421.7000000000053,47.237922590926246,0.01107177996900921,-2.9148569622936367
422.8000000000053,47.34664567181777,0.006321416730279417,-2.9170155681500867
423.9000000000053,47.45454955183232,0.0016436674003652563,-2.9185960428345714
425.00000000000534,47.56185658876368,-0.0022925715854835715,-2.921089020095481
426.1000000000053,47.67019106309922,-0.0035596558519728205,-2.9237403870087775
427.20000000000533,47.77698020815662,-0.00715295048444764,-2.9251475345611775
428.30000000000535,47.88622704990058,-0.010574360632848112,-2.9281819006015724
429.4000000000054,47.99473997241091,-0.012962480860579717,-2.9293408303898905
430.5000000000054,48.10049876376912,-0.019069689443121263,-2.9332186586058886
431.6000000000054,48.209678286092355,-0.017899670091715336,-2.9379897771152717
432.70000000000545,48.31871677780637,-0.0202301013422157,-2.9405608986011345
433.8000000000054,48.426627020454696,-0.0216686692943302,-2.944522444832312
434.90000000000543,48.535219796715545,-0.021869791617775025,-2.9473657394187245
436.00000000000546,48.64364129566068,-0.017062592836743384,-2.953278166559406
437.1000000000055,48.75129908201103,-0.019664678384995415,-2.9562949790838253
438.2000000000055,48.86029802663056,-0.015047916206236689,-2.9623771433957664
439.3000000000055,48.96775467031,-0.003445471420974844,-2.966183851973993
440.40000000000555,49.07639167710653,0.004802336526392725,-2.9711627056451464
441.50000000000557,49.18527779202187,0.01013537913348106,-2.975377842684708
442.6000000000056,49.29259678558719,0.020164424234568212,-2.9804461871911543
443.70000000000556,49.401991116703094,0.026938061820498405,-2.9869584816016705
444.8000000000056,49.51137190575884,0.03710237708162056,-2.9946947309205108
445.9000000000056,49.619076149639994,0.04442291074382121,-3.0017909761926225
447.0000000000056,49.72928201633634,0.05840794205891919,-3.0081260195024386
448.10000000000565,49.837338803669,0.07058358815874133,-3.0157184450166237
449.2000000000057,49.945882728698784,0.07901130754431707,-3.024183686185792
450.3000000000057,50.05604405252721,0.09298321232662099,-3.0321105040186005
451.40000000000566,50.165904460592586,0.12449599149522861,-3.044095177484981
452.5000000000057,50.27539245152854,0.15625598798147422,-3.0597619941466503
453.6000000000057,50.38625674459882,0.1927633075997477,-3.0768078995405617
454.70000000000573,50.49702227958665,0.24918541422303564,-3.096903538399392
455.80000000000575,50.6076199717067,0.2925624059706733,-3.124663645983328
456.9000000000058,50.71646478541618,0.28188507878459435,-3.155109571216431
458.0000000000058,50.82462681661409,0.25950345554699616,-3.1802390083900938
459.1000000000058,50.932614001336276,0.23154379267587766,-3.2030497537852685
460.20000000000584,51.04137178528172,0.2135515800015888,-3.219933892191853
461.3000000000058,51.14965100532014,0.20750571033485565,-3.23611814249451
462.40000000000583,51.25778787448388,0.1994637236557435,-3.2507708429358733
463.50000000000585,51.36614132174331,0.19848531206445408,-3.266939539574137
464.6000000000059,51.4753635110494,0.19589357515336348,-3.281539048528576
465.7000000000059,51.58384769454684,0.19738232634618402,-3.2923548664622646
466.8000000000059,51.69206989787883,0.1971894551709097,-3.306390154699747
467.90000000000595,51.80164709282148,0.20297843107109337,-3.319090880254902
469.0000000000059,51.910779472461,0.20173695544396608,-3.3294825832398343
470.10000000000593,52.01921242154695,0.19918434598366508,-3.3420272148080223
471.20000000000596,52.1289713702227,0.19629725068558201,-3.354109559410609
472.300000000006,52.236792714706624,0.1913217899257167,-3.3633554650938278
473.400000000006,52.3455787480917,0.18631498876318364,-3.374049949282278
474.500000000006,52.454300206893016,0.1830848382530661,-3.384339649185702
475.60000000000605,52.56417820521944,0.18176788047439807,-3.394679565200059
476.70000000000607,52.67246837211487,0.17562984589859454,-3.4045708913340924
477.8000000000061,52.781630263696385,0.17373972535957227,-3.414084148323883
478.90000000000606,52.89130131779521,0.16713557250306055,-3.4243703296183985
480.0000000000061,53.00123555714862,0.1609329430991382,-3.435000024405977
481.1000000000061,53.10885706236334,0.1605054295014927,-3.443774017177107
482.2000000000061,53.21919242373764,0.15505868979604465,-3.45134141721263
483.30000000000615,53.326848129427745,0.15157425974201955,-3.457886510035496
484.4000000000062,53.43731907607003,0.14746766245254594,-3.4655294563299117
485.5000000000062,53.54636698178435,0.14254397835907628,-3.4747059834278002
486.60000000000616,53.65484126197315,0.14119264616291316,-3.4817215380221587
487.7000000000062,53.7640605743025,0.13556642223347914,-3.485868489037878
488.8000000000062,53.87299312302738,0.12830855035821287,-3.494181252772033
489.90000000000623,53.981972503072974,0.12922878516049874,-3.5002168847868855
491.00000000000625,54.09166590212183,0.12529238744837867,-3.5063238781657877
492.1000000000063,54.20050929252318,0.12037259940720135,-3.510117242735142
493.2000000000063,54.30990234053817,0.12150929609200434,-3.5176610633198973
494.3000000000063,54.418086653412814,0.11417717253228599,-3.5218978324290062
495.40000000000634,54.52722555667122,0.11575092974803569,-3.527933787845626
496.5000000000063,54.63765249120033,0.11480929302120257,-3.532200720005759
497.60000000000633,54.74582587997467,0.10958248674424631,-3.5362993225319173
498.70000000000636,54.85583843016372,0.10578473154896928,-3.543484758115505
499.8000000000064,54.96368028449648,0.10750203834763372,-3.547594679466406
500.9000000000064,55.073466257811795,0.10484623042610641,-3.548853409266311
502.0000000000064,55.1836085118002,0.1002047701009583,-3.550072561275044
503.10000000000645,55.29345597297027,0.09960388769267592,-3.553160077170413
504.2000000000064,55.40286108274887,0.09708155748359015,-3.5572038075427903
505.30000000000643,55.5122240988065,0.09480979954785518,-3.5597150890716707
506.40000000000646,55.62230628232728,0.09299756360802558,-3.5609987077743344
507.5000000000065,55.73169904984273,0.09306525954820932,-3.563891722861824
508.6000000000065,55.84111487628417,0.09336877441313263,-3.5679358330672017
509.7000000000065,55.95146443829996,0.08952794716424961,-3.573309138718125
510.80000000000655,56.06095964417317,0.09018465007019838,-3.574648386168869
511.90000000000657,56.17037608550778,0.08854447635361584,-3.5733535792823643
513.0000000000066,56.280770598413014,0.08919412279769467,-3.576243462236478
514.1000000000065,56.390848999866854,0.08418321947312091,-3.5779027139924464
515.2000000000066,56.50031036830155,0.08349041206209185,-3.5811557116777886
516.3000000000065,56.610586562277135,0.0801485881434254,-3.5815628457287976
517.4000000000067,56.71999790303194,0.07991634181484963,-3.5792597386688305
518.5000000000066,56.829565095344506,0.07931371798397846,-3.580569942570912
519.6000000000067,56.93928358436895,0.0781580439566647,-3.581888432031599
520.7000000000066,57.04914991980136,0.07941915583717396,-3.583227325292074
521.8000000000067,57.15957926806564,0.07827528373815573,-3.585825373543147
522.9000000000067,57.268891359679586,0.076371940213666,-3.5857855075413987
524.0000000000067,57.378561134632136,0.07695675512243616,-3.588481551178372
525.1000000000067,57.48947521007119,0.07589516095519588,-3.588182007351852
526.2000000000068,57.598001554267526,0.07384933467957211,-3.589790669362135
527.3000000000068,57.70855327890084,0.0739620518240276,-3.591112302372687
528.4000000000068,57.81936602125629,0.0743760377425815,-3.5924302654045253
529.5000000000068,57.929708747797015,0.07072345908354816,-3.59249626399416
530.6000000000068,58.03916245825889,0.06947475529101821,-3.593712891774149
531.7000000000069,58.149224358435916,0.06949340341885968,-3.595060492502997
532.8000000000068,58.25798029519969,0.06797633655739377,-3.5963782574366805
533.9000000000069,58.36624475075296,0.07117243223537528,-3.5940840231110553
535.0000000000068,58.477797862673874,0.07236054796895752,-3.595379717977515
536.100000000007,58.58773430271675,0.07105512451123541,-3.596739888887222
537.2000000000069,58.69847315835197,0.07003340653883727,-3.59671989393828
538.300000000007,58.80738078376948,0.07020337496330642,-3.5976988552880163
539.4000000000069,58.91823713007228,0.07026368126313498,-3.596710970269923
540.5000000000069,59.02759125083702,0.06782698752376426,-3.599169993432186
541.600000000007,59.13825269062364,0.06834231811365532,-3.5993470081269607
542.700000000007,59.2484166420013,0.0693535555841045,-3.600662738496628
543.800000000007,59.35812628341912,0.06880418799508403,-3.599350146919938
544.900000000007,59.4681342141247,0.06594070184195555,-3.6016548734821976
546.000000000007,59.57833457503782,0.0664319472908792,-3.601670020008276
547.1000000000071,59.6887043640247,0.06762081130885367,-3.6029696601529873
548.2000000000071,59.79912899585925,0.0661591111734312,-3.604290051827739
549.300000000007,59.90685531921389,0.06251470383659363,-3.6042900409999774
550.4000000000071,60.01813055791369,0.061200060170901516,-3.6042900500578803
551.500000000007,60.12896895490742,0.061733722967468374,-3.6039748861606338
552.6000000000072,60.23788444742355,0.06065187984156317,-3.601529876813927
553.7000000000071,60.34766264756984,0.059486144372735694,-3.6057667204868036
554.8000000000072,60.45877878539373,0.05991113091803868,-3.605720098988702
555.9000000000071,60.568694184740366,0.05618857157745971,-3.605720110867894
557.0000000000072,60.67779737993192,0.05830190332867469,-3.6035062241427545
558.1000000000072,60.78761142260357,0.055051251076419394,-3.602991608646107
559.2000000000072,60.89755862562933,0.0585509092312142,-3.605657475340034
560.3000000000072,61.00823788902416,0.05147585318593073,-3.607851005082208
561.4000000000073,61.11789396853845,0.053364981417286295,-3.6085243303439616
562.5000000000073,61.22766790674247,0.05225976405000843,-3.6082386819019
563.6000000000073,61.33859744942053,0.05231910147868968,-3.6072496393363207
564.7000000000073,61.448583781007905,0.054292744634418355,-3.6072490560840826
565.8000000000073,61.560001318412404,0.05188032126563158,-3.607250182429492
566.9000000000074,61.66874038862968,0.04972843735803112,-3.607250098005039
568.0000000000074,61.77885113921598,0.0520547269432412,-3.6072440392995744
569.1000000000074,61.889699560056684,0.05166111316655675,-3.6085700821920916
570.2000000000073,62.000379602579926,0.049802185459491,-3.6098926392272186
571.3000000000073,62.10969409082961,0.049875571073771496,-3.609228481779335
572.4000000000074,62.21941946016773,0.05131298658355021,-3.610549933426462
573.5000000000074,62.33020529356236,0.051865767462910384,-3.6105397220445177
574.6000000000074,62.44129566158739,0.04807321066648118,-3.6098542278514234
575.7000000000074,62.55100935171962,0.04432783948672725,-3.6098927017782727
576.8000000000075,62.66212946412982,0.04492495756285031,-3.6110908780461464
577.9000000000075,62.77278450589571,0.045438827351636846,-3.612242945131503
579.0000000000075,62.88303427262783,0.04364309873755756,-3.6139407145605738
580.1000000000075,62.9938556848678,0.04252540036427854,-3.6138401989590023
581.2000000000075,63.10526212973772,0.04143015686405027,-3.613840251645555
582.3000000000076,63.21591864901971,0.038319459823111135,-3.6147204479072332
583.4000000000076,63.32594224118322,0.04027147042582557,-3.6148028828313667
584.5000000000076,63.43729527054781,0.04057994292993694,-3.614833823804121
585.6000000000076,63.548085972452405,0.03825956508847428,-3.6151594872459465
586.7000000000077,63.6589160271132,0.03544266600755597,-3.6159420243379614
587.8000000000077,63.76906558422614,0.038099631690846625,-3.613840554567159
588.9000000000076,63.87947781987359,0.03645989617292367,-3.613845169473606
590.0000000000076,63.99065826620056,0.03277978101780521,-3.6144999588043696
591.1000000000076,64.10153993125917,0.03641669332272057,-3.614499963672364
592.2000000000077,64.21301820821913,0.03496098887929522,-3.613837881469727
593.3000000000077,64.32370527079833,0.034564627299014106,-3.6157712645305855
594.4000000000077,64.43378412828649,0.03413837643638162,-3.615810026019201
595.5000000000077,64.54364426642044,0.03264209406701868,-3.615810777302995
596.6000000000078,64.65486408354023,0.02954841761801008,-3.6165800173006653
597.7000000000078,64.76601475468374,0.031843091066012796,-3.615849675500979
598.8000000000078,64.87672798437214,0.028175354981645917,-3.614972741880866
599.9000000000078,64.98631165917729,0.02815499853996517,-3.6162500831632576
601.0000000000078,65.09776385777442,0.025964546223294693,-3.6162500840000003
602.1000000000079,65.20883977268372,0.024124328226254654,-3.6159301028812596
603.2000000000079,65.32009084578117,0.019417446599444776,-3.6179074523054084
604.3000000000079,65.43041990738375,0.023352922111062657,-3.618233468423816
605.4000000000078,65.54133886354992,0.0204623454969326,-3.618229841997714
606.5000000000078,65.65310784498024,0.016966428302283454,-3.618229842001794
607.6000000000079,65.76354679336897,0.021001651926725984,-3.618225424137538
608.7000000000079,65.87368592783126,0.016466534714655534,-3.6183635689860054
609.8000000000079,65.98517146824148,0.014064662308108211,-3.618232516703161
610.9000000000079,66.09641665775507,0.015132577027936467,-3.6168944129844465
612.000000000008,66.20759909031821,0.013173713951873278,-3.6169069998109595
613.100000000008,66.31647299294046,0.011172960774767038,-3.6198978349362387
614.200000000008,66.42733584916586,0.005674191396815242,-3.6196831254039705
615.300000000008,66.53731905405137,0.0073447603602248,-3.618669642081527
616.400000000008,66.64981059180121,0.005362997467388997,-3.6199899157721402
617.5000000000081,66.76050209631579,0.0029751950800243065,-3.621020795079361
618.6000000000081,66.87211122030841,-0.0016770554165264073,-3.6213005061180272
619.7000000000081,66.9825672476335,-0.005953998006588357,-3.6219597273087905
620.8000000000081,67.09325917589052,-0.011788566856081761,-3.6219600827832226
621.9000000000082,67.20389843454146,-0.012129718264222156,-3.6232667099222344
623.0000000000082,67.3159574481146,-0.013946132000818068,-3.623280699731902
624.1000000000081,67.42636816832825,-0.014740596770027814,-3.6219699317215515
625.2000000000081,67.53776691816853,-0.013749653862114908,-3.620640043128252
626.3000000000081,67.64901741942548,-0.015094008509584533,-3.621959773398003
627.4000000000082,67.75900238631887,-0.019321844197424998,-3.6213001180174214
628.5000000000082,67.87103898773792,-0.018407834972286263,-3.621605778045089
629.6000000000082,67.98172784814062,-0.020183399175347283,-3.6226093073027776
630.7000000000082,68.09212233395708,-0.0244850967980077,-3.621299852069672
631.8000000000083,68.20217707464673,-0.020566044201574485,-3.6226201972980627
632.9000000000083,68.31365491275635,-0.022604231834149502,-3.6226201782545795
634.0000000000083,68.42476935874777,-0.021382396170614548,-3.6239283385496712
635.1000000000083,68.53475634899952,-0.020618073376091228,-3.622619606953199
636.2000000000083,68.64632162739818,-0.0219712257359177,-3.6239556881056982
637.3000000000084,68.75529061753124,-0.02262316070205861,-3.625249946003754
638.4000000000084,68.86732285480824,-0.023860623623012778,-3.6240487081556902
639.5000000000084,68.97900253059458,-0.023014820433636896,-3.6226198667598988
640.6000000000083,69.09000202829009,-0.02265247029429318,-3.6226198462963066
641.7000000000083,69.19865753405465,-0.019821756295963056,-3.623929935879157
642.8000000000084,69.31188860254154,-0.019309515353261197,-3.621308839576443
643.9000000000084,69.42229987306855,-0.02353664762514862,-3.622620318567442
645.0000000000084,69.53370028591284,-0.022852172630278833,-3.623916565226625
646.1000000000084,69.64489376875507,-0.02332526049586736,-3.62525920403694
647.2000000000085,69.75590605759385,-0.02453339071376881,-3.6252613449604247
648.3000000000085,69.86722462402521,-0.026302562066471857,-3.6272194358826217
649.4000000000085,69.97714774549293,-0.025923694629409688,-3.6259150317042232
650.5000000000085,70.08976710026931,-0.026002293945359245,-3.6242697683190697
651.6000000000085,70.19927350329394,-0.02561617131230509,-3.624929583518772
652.7000000000086,70.30999888165098,-0.02548813921594384,-3.624930141614727
653.8000000000086,70.42314943981901,-0.026227398181060124,-3.6236054663683084
654.9000000000086,70.53393325466826,-0.026381217753649988,-3.6248058454760246
656.0000000000086,70.64572228112159,-0.029449801113708762,-3.627227405880279
657.1000000000087,70.7576482502746,-0.028924366437732996,-3.6272298970008423
658.2000000000087,70.86778687438357,-0.029910398653986814,-3.6272294801661986
659.3000000000086,70.97788788296775,-0.02917281274610728,-3.6293661238393815
660.4000000000086,71.09158330400487,-0.029812049960674436,-3.6285468781271724
661.5000000000086,71.20208733825355,-0.0292705944067011,-3.6269026561566484
662.6000000000087,71.31384762756102,-0.02331651758578568,-3.6248712062069495
663.7000000000087,71.42584742303396,-0.02904826988511955,-3.6242679108202744
664.8000000000087,71.5378384942512,-0.028811563289925957,-3.625587617678786
665.9000000000087,71.6485148018208,-0.029179780369029462,-3.625579965056981
667.0000000000088,71.7603949357426,-0.030621829709195136,-3.6269859217826874
668.1000000000088,71.87150242345541,-0.03328032201225728,-3.625684623302165
669.2000000000088,71.9829536985896,-0.034223704609110506,-3.6260013684225574
670.3000000000088,72.09518947657688,-0.03524277780162688,-3.6255796574484416
671.4000000000088,72.2072491782332,-0.03545637709359628,-3.6269001313133415
672.5000000000089,72.31827674766596,-0.03664052759312364,-3.6268994851441496
673.6000000000089,72.42897916813877,-0.03423180732231623,-3.6275828456394215
674.7000000000089,72.5398985803185,-0.03727025545389928,-3.6265700533635594
675.8000000000088,72.65298825937911,-0.039373233176181355,-3.6265700580027747
676.9000000000088,72.76362740369781,-0.03779752623075172,-3.625256837707194
678.0000000000089,72.87506509132226,-0.0393585611679681,-3.626907885583375
679.1000000000089,72.98720832007066,-0.03995872355283803,-3.629755638563972
680.2000000000089,73.09595212185037,-0.041084457987892176,-3.6297498298475346
681.3000000000089,73.21010211251833,-0.0439451239074069,-3.6284413134656246
682.400000000009,73.32092258358794,-0.04278102615841606,-3.6271302033706143
683.500000000009,73.43261762246668,-0.03951328904122775,-3.62843941263149
684.600000000009,73.54251989728135,-0.04117608637430292,-3.6284445339945206
685.700000000009,73.65572350216311,-0.0379252016830991,-3.6284399310025375
686.800000000009,73.76652588508499,-0.04327038448365972,-3.6284270386210355
687.9000000000091,73.87952876659264,-0.040611682426387574,-3.6258218545595904
689.0000000000091,73.99086363921903,-0.038018734245711894,-3.627779901724411
690.1000000000091,74.1019537923675,-0.038128380789471894,-3.627779931000029
691.2000000000091,74.2141408631076,-0.035724580965271535,-3.6277799310247185
692.3000000000092,74.32553031981047,-0.037703663742314486,-3.6276631485085926
693.4000000000092,74.43766597736784,-0.03834693546606438,-3.6287700182699356
694.5000000000091,74.54835691826686,-0.03981268408054062,-3.627872665329715
695.6000000000091,74.66071224487983,-0.04359985350290474,-3.629100224423678
696.7000000000091,74.77202749932337,-0.03783993480913361,-3.6291002015874563
697.8000000000092,74.8839065339489,-0.0387328448240396,-3.628095599778493
698.9000000000092,74.99447960521088,-0.037460023577306156,-3.6287890547862376
700.0000000000092,75.10810634094096,-0.03967768562196472,-3.628043652308188
701.1000000000092,75.21979301854185,-0.03847223412863787,-3.6294303059340405
702.2000000000093,75.33153692983872,-0.03670104252434836,-3.629100438048007
703.3000000000093,75.44405727465832,-0.039772578714674545,-3.6277905666354853
704.4000000000093,75.55619311795293,-0.03787464500562043,-3.6295162455727734
705.5000000000093,75.66787638515366,-0.040530920501772094,-3.629100181936015
706.6000000000093,75.78009983184519,-0.036356999887432906,-3.6291001820017836
707.7000000000094,75.89194227706687,-0.03800530477770181,-3.6290082008541993
708.8000000000094,76.00379169569102,-0.04251662087057895,-3.629747778261306
709.9000000000094,76.11633766342787,-0.036450380549311934,-3.6307173856144352
711.0000000000093,76.22842697833326,-0.03873520965922728,-3.629540064032511
712.1000000000093,76.33884029640086,-0.03560614934668482,-3.6295394618158525
713.2000000000094,76.45118610246544,-0.03846444839206242,-3.629539904379473
714.3000000000094,76.56404834267829,-0.03865639967479595,-3.62821993618667
715.4000000000094,76.67543405251027,-0.03913250180292138,-3.628233744115446
716.5000000000094,76.78730171865223,-0.03822395638217335,-3.6308632678549837
717.6000000000095,76.89882909240046,-0.040336195746487835,-3.6295399257170087
718.7000000000095,77.01073417704418,-0.04177751069003266,-3.6295498585933914
719.8000000000095,77.12283117813352,-0.03753191403018352,-3.6294975589239957
720.9000000000095,77.23504817218678,-0.0394769517284721,-3.6308328948776265
722.0000000000095,77.34681675695013,-0.039299188334828816,-3.63109062404128
723.1000000000096,77.46020886900831,-0.03848314413419329,-3.631556731073783
724.2000000000096,77.57167151952667,-0.04111135260879628,-3.6315101469994047
725.3000000000096,77.68490020125387,-0.03937726197547331,-3.631510146970271
726.4000000000096,77.79437437978116,-0.041776655638852134,-3.631545763369527
727.5000000000097,77.90669360988514,-0.03617114235420882,-3.6285594662142975
728.6000000000097,78.02104195942032,-0.04012320730224328,-3.6292020235369487
729.7000000000096,78.13315505108851,-0.04248809630982198,-3.629529821810878
730.8000000000096,78.24302733652151,-0.04179739414162942,-3.632177978862696
731.9000000000096,78.35725898571192,-0.04067657002639802,-3.630778662199639
733.0000000000097,78.46979680091624,-0.044989380496871956,-3.6308500517894884
734.1000000000097,78.58147832935141,-0.04430590741678131,-3.632228610605911
735.2000000000097,78.69148232096249,-0.044829021209632725,-3.6308580901680387
736.3000000000097,78.8050506033681,-0.04510304388618547,-3.6305302909396504
737.4000000000098,78.91781879776799,-0.0429425054185506,-3.630531013628207
738.5000000000098,79.02911017547247,-0.041148389864078094,-3.631849914116292
739.6000000000098,79.14143652022027,-0.0451153795395931,-3.6318499300000053
740.7000000000098,79.25274263059008,-0.044382989924662386,-3.6318499301134084
741.8000000000098,79.36466081459358,-0.04678310025543375,-3.631420990660986
742.9000000000099,79.47642132581511,-0.043568942004421185,-3.6304762844953355
744.0000000000099,79.58817425282767,-0.045559682641614696,-3.6292087926932806
745.1000000000099,79.700518052945,-0.04376284999432967,-3.630533014882212
746.2000000000098,79.81293652741832,-0.05006230247080712,-3.6318257853572984
747.3000000000098,79.92496738490973,-0.05024334900855365,-3.6318375378186474
747.9000000000099,79.98617363508015,-0.04629554437657113,-3.631840087955118