File: 01_Data/Cardboard/STA/N2/30K_min/Cardboard_STA_N2_30KData_230921_R2.csv
##Temp./Â°C,Time/min,DSC/(mW/mg),Mass loss/mg
41.0,10.527643172727956,0.05066123873683459,-0.017333941184503487
42.100000000000016,10.736947726372076,0.1027180101938372,-0.016906647340506176
43.20000000000003,10.863322712493657,0.1502548855990704,-0.017772035615087667
44.30000000000005,10.963841894083028,0.19399458747468756,-0.018165645626098126
45.40000000000006,11.048773742372756,0.22936691176345114,-0.018816266113562463
46.50000000000008,11.124246965014336,0.2621457462400736,-0.01768264276664988
47.600000000000094,11.192371156137407,0.2927019736034122,-0.017907278143036276
48.70000000000011,11.255767584929073,0.32097774258288614,-0.018116731056972313
49.800000000000125,11.315634309131642,0.3496748023467857,-0.018932283261652305
50.90000000000014,11.373267045493643,0.37475915903472123,-0.01949817053814762
52.000000000000156,11.42735244725541,0.3987512097336632,-0.01851333446743908
53.10000000000017,11.479875831872475,0.41942150841075,-0.020301275171096478
54.20000000000019,11.530505090602734,0.4422407053309849,-0.019773523206575216
55.3000000000002,11.579520595519877,0.46233886367707955,-0.020552636714426864
56.40000000000022,11.627528743715782,0.48613297692956015,-0.02030551903073219
57.500000000000234,11.674634646495166,0.5027766115872934,-0.01987622251631027
58.60000000000025,11.719992846687955,0.5216922849323051,-0.022088584243132647
59.700000000000266,11.765621079053503,0.5417796699860744,-0.022443588250471436
60.80000000000028,11.809718040897707,0.5601484213026477,-0.023111458089297265
61.9000000000003,11.853051548894781,0.5782208736065748,-0.023012596090245196
63.00000000000031,11.896455484353892,0.5967973692370288,-0.02356922203069578
64.10000000000034,11.938257157785642,0.6141455511619376,-0.02336183745182252
65.20000000000034,11.980575841067079,0.6313328411691868,-0.023593824419780862
66.30000000000035,12.022436218207005,0.6496542636396212,-0.023291200580731086
67.40000000000038,12.063461222784795,0.6631670867231994,-0.024519819838011436
68.5000000000004,12.104416749213351,0.6819071036594742,-0.025575349170868567
69.6000000000004,12.145423166215854,0.6973668270385358,-0.026701854897440036
70.70000000000041,12.18491622446556,0.7134352811396516,-0.026821363829855116
71.80000000000044,12.225705527378077,0.7315975529687446,-0.026771137166454295
72.90000000000046,12.26547816848119,0.7468604961323928,-0.02680120558120036
74.00000000000047,12.30553236658675,0.7652256416755725,-0.028630689067098203
75.10000000000048,12.34472224845026,0.7807953078716405,-0.02951950286775684
76.2000000000005,12.384399737496096,0.7978409110653666,-0.02915794372422864
77.30000000000052,12.423791025752445,0.8142892426966284,-0.03044141351805063
78.40000000000053,12.462962407137745,0.8320541230612604,-0.030997488354326475
79.50000000000054,12.501814928827656,0.846656718299214,-0.03291303693473946
80.60000000000056,12.540755075715282,0.8622205063448103,-0.03453743513066598
81.70000000000059,12.579566629287456,0.8786795967893419,-0.03315060185166718
82.8000000000006,12.61826423748665,0.8937063366510767,-0.033335940495609506
83.9000000000006,12.65640566409179,0.9065355038486287,-0.03447017982362155
85.00000000000063,12.694630919634553,0.9203624636001912,-0.03442736745983144
86.10000000000065,12.73288736866902,0.9362521025793538,-0.035777419886343864
87.20000000000066,12.771276195668701,0.9483313601018768,-0.03678531735757584
88.30000000000067,12.808901131778061,0.9624429257557936,-0.03706953127617796
89.40000000000069,12.846681579526157,0.9760884134472108,-0.03973281482279356
90.50000000000071,12.883826306265684,0.9837949576583456,-0.039741589191237825
91.60000000000072,12.921594904225397,0.9947049304207591,-0.04116617918678189
92.70000000000073,12.959268447032787,1.0037187709270028,-0.0414764653531523
93.80000000000075,12.996355799790582,1.0115967355545479,-0.04267591876971899
94.90000000000077,13.033059964660074,1.021213476973547,-0.04386175968034367
96.00000000000078,13.069663976551237,1.0265779310276977,-0.0451448726265391
97.10000000000079,13.107735010620974,1.0330583832536766,-0.04643272755328187
98.20000000000081,13.144534724444524,1.0381556877271507,-0.04772743419218051
99.30000000000084,13.18131638173351,1.0426465303932622,-0.04989762835795242
100.40000000000084,13.21818136684626,1.0459231467294055,-0.05039114687416024
101.50000000000085,13.255040395010791,1.0500859987872033,-0.05069931260029703
102.60000000000088,13.291145871698502,1.0501783032159664,-0.05301382833613122
103.7000000000009,13.328268334735329,1.050076007371832,-0.0530392148161587
104.8000000000009,13.364687736917308,1.0502843935459762,-0.05438662632587565
105.90000000000092,13.401614186200252,1.0507939692272896,-0.05568095290285591
107.00000000000094,13.437693024067062,1.0463886414908934,-0.05563643681866992
108.10000000000096,13.474254677128776,1.0445862501268564,-0.0569783604406342
109.20000000000097,13.510804424456406,1.0415868423502015,-0.05699049542686341
110.30000000000098,13.546717769346508,1.0397793936305544,-0.05693941876099329
111.400000000001,13.582879096683333,1.0332988622800934,-0.059691928949440864
112.50000000000102,13.61923459953919,1.0280904094886418,-0.05994593068810339
113.60000000000103,13.655331157136835,1.0212317338169647,-0.060944485281064775
114.70000000000104,13.691825532289357,1.0151413374557339,-0.06358885566125583
115.80000000000106,13.727958407400141,1.0079260047454655,-0.06356994807955108
116.90000000000109,13.763775666323275,0.9999166441970839,-0.06403767211848521
118.0000000000011,13.799873436250762,0.990567810642492,-0.06621170817639843
119.1000000000011,13.835911433218197,0.9813472980615898,-0.06620352572403077
120.20000000000113,13.87183785063814,0.972716873913029,-0.0673659625756442
121.30000000000115,13.908020021990948,0.9652991611864064,-0.06752020825674876
122.40000000000116,13.943526266491972,0.9586847473768647,-0.06751971556909186
123.50000000000117,13.979504185974402,0.945498486320753,-0.06818448418221035
124.60000000000119,14.014759805823449,0.939072001803265,-0.06952146182868457
125.70000000000121,14.050975218356479,0.9293597958680251,-0.0695006876263431
126.80000000000122,14.086076054761302,0.9224649298748067,-0.0694279742515409
127.90000000000123,14.121827825270937,0.9142150393171868,-0.07016512199176406
129.00000000000125,14.157333176337898,0.9053824057107223,-0.07015849892282722
130.10000000000127,14.192573299363794,0.8959354710588161,-0.0706362937020284
131.2000000000013,14.227833450680786,0.8867040532543173,-0.07077480404231684
132.3000000000013,14.263732202049084,0.8818157833300426,-0.07150212230092068
133.4000000000013,14.298645891145675,0.8740183659251293,-0.07279766880102878
134.50000000000134,14.334510509830137,0.866601553842121,-0.07279136802417963
135.60000000000133,14.36942884703034,0.8630695281748151,-0.07390033504528803
136.70000000000135,14.40448910858424,0.8533993406988976,-0.07541801497712575
137.80000000000138,14.439557181761987,0.8480296396142886,-0.07543018235613097
138.9000000000014,14.474330545170302,0.842547329441949,-0.07543018320969974
140.00000000000142,14.509389318666798,0.836392858473489,-0.07543018269139434
141.10000000000142,14.544267741578246,0.8349035377075595,-0.07543022072272443
142.20000000000144,14.57930027670192,0.8266167204687507,-0.07542299320800483
143.30000000000146,14.614269847001522,0.8222670794846003,-0.07475398627734808
144.40000000000146,14.649170322973502,0.8182473430237254,-0.07477051062200468
145.50000000000148,14.683800103959634,0.8158941955478667,-0.0747777767619815
146.6000000000015,14.718762452640402,0.8138020130773054,-0.07344315345898877
147.70000000000152,14.753300506974567,0.8121643680014627,-0.07344940402223443
148.80000000000155,14.788231019647714,0.8112854929171935,-0.07344367629551796
149.90000000000154,14.822850403850548,0.8094879602797667,-0.07480912696168618
151.00000000000156,14.857391175302528,0.8083268791883746,-0.07609021434560592
152.1000000000016,14.891910329175323,0.8080380363884949,-0.07609017523119999
153.20000000000158,14.92603420757034,0.8082843363615606,-0.07609018185708516
154.3000000000016,14.961084780166805,0.8073700485470907,-0.07609018433339099
155.40000000000163,14.995758600352305,0.8089335101735795,-0.07609179128902932
156.50000000000165,15.02964055813235,0.8090328128481195,-0.07730856637974792
157.60000000000167,15.06429445049241,0.8077338057957393,-0.07740827518129834
158.70000000000167,15.098904607777063,0.8095996952944025,-0.07741020071669746
159.8000000000017,15.132936723241961,0.8093225124515626,-0.07741018214674922
160.9000000000017,15.167862073233422,0.8119209256472995,-0.07741018199745175
162.0000000000017,15.201814741305723,0.8151556728835041,-0.0774101819999915
163.10000000000173,15.236332942415519,0.8177532926963146,-0.07741018200000171
164.20000000000175,15.270394279998943,0.8170707117796603,-0.07741018199999594
165.30000000000177,15.30453776791163,0.8208050679238343,-0.07741018200099248
166.4000000000018,15.339010310652647,0.8221477713220696,-0.07741018199654803
167.5000000000018,15.373707171802616,0.8247147697207451,-0.07741017280832008
168.6000000000018,15.407374898375094,0.8261040088735797,-0.07741058591048366
169.70000000000184,15.441992563691983,0.8277179036588788,-0.07679822838298778
170.80000000000183,15.476450858205535,0.8308488054023626,-0.0763966927679367
171.90000000000185,15.510529518984741,0.8325553096035387,-0.07706855097379828
173.00000000000188,15.544632777677158,0.8329786967172421,-0.07736536517591075
174.1000000000019,15.578397238176983,0.8382849570484878,-0.07838831699864279
175.20000000000192,15.61300875592389,0.8392003298747179,-0.07839011349253244
176.30000000000192,15.646322736691342,0.8422904563118827,-0.0783901827769764
177.40000000000194,15.680976194832999,0.8449891886175307,-0.07839018200534387
178.50000000000196,15.715032961755202,0.8494148199242926,-0.07839018199988246
179.60000000000196,15.748953906961786,0.8512565599022742,-0.07839018200000059
180.70000000000198,15.781837586947153,0.8551677736967179,-0.0783901819999997
181.800000000002,15.81641978256607,0.856218379310341,-0.07839018200000192
182.90000000000202,15.85076746542228,0.8583836049910512,-0.0783901819999917
184.00000000000205,15.884769993889233,0.8638323313932573,-0.07839018198945968
185.10000000000204,15.917870052384586,0.8668451101865786,-0.0783901826448048
186.20000000000206,15.951887481732172,0.8689769615031833,-0.07839021901064269
187.3000000000021,15.985985242244308,0.8701682538593022,-0.07838344866708002
188.40000000000208,16.019744759556062,0.8731398169954392,-0.07776127788589449
189.5000000000021,16.05324547044192,0.8746788683762373,-0.077737509820901
190.60000000000213,16.086965571630202,0.8781172542921498,-0.07821207840489874
191.70000000000215,16.120613962789765,0.8811425311383061,-0.07905266109238385
192.80000000000217,16.154327039816636,0.8851294058174835,-0.07905003305209357
193.90000000000217,16.187543327071282,0.8853839170981112,-0.07905010475918184
195.0000000000022,16.221697672890006,0.8880865658574695,-0.07905015022195894
196.1000000000022,16.255076877129056,0.8941481684750121,-0.07900411628075421
197.2000000000022,16.28873226411735,0.8953848580736884,-0.0800375786907872
198.30000000000223,16.322406134355465,0.8979649511351555,-0.08003015324813978
199.40000000000225,16.355012021631616,0.9009117384763012,-0.0800300973125827
200.50000000000227,16.389231445325567,0.9031035271999032,-0.0800300990107985
201.6000000000023,16.422592926159478,0.9035262814703643,-0.08003009901921398
202.7000000000023,16.455649530207925,0.9088399536317884,-0.08003009748584455
203.8000000000023,16.48977673510705,0.9111399002519633,-0.0800300711344617
204.90000000000234,16.52338420451625,0.9110797751504542,-0.0800417724015281
206.00000000000233,16.55664274329691,0.9128703794971341,-0.0812407152428154
207.10000000000235,16.590167515514707,0.9158349130383795,-0.08134947533599401
208.20000000000238,16.62324634298808,0.918601335201818,-0.08135000972482143
209.3000000000024,16.65704414645195,0.9185818150530457,-0.08134998565941398
210.40000000000242,16.690291554981993,0.9204350730546451,-0.08134973495812226
211.50000000000242,16.72386056758167,0.9260321859758487,-0.08144010057587092
212.60000000000244,16.757233717881736,0.9272243775692199,-0.08234137789681828
213.70000000000246,16.79044409961508,0.9292122672166472,-0.08266418814926091
214.80000000000246,16.823850854682387,0.9306364723961249,-0.08267017269442967
215.90000000000248,16.857430598779402,0.9325018203170878,-0.08266452764770182
217.0000000000025,16.89071955011561,0.9352709408351789,-0.08377620966758759
218.10000000000252,16.92411743983372,0.9357662899499126,-0.08399049161174466
219.20000000000255,16.95739540249035,0.9406162751058802,-0.08399017884499616
220.30000000000254,16.990692051034934,0.9414710032423905,-0.08399756420952365
221.40000000000256,17.0240916268629,0.9427421697674414,-0.08455619932187863
222.5000000000026,17.057463376188053,0.9461094830556935,-0.08465107138742667
223.60000000000258,17.090689834686767,0.945875089045737,-0.08465009391611344
224.7000000000026,17.124189212726623,0.9470369862124728,-0.0846500615659056
225.80000000000263,17.157261597223147,0.9488536714098953,-0.08465135917815836
226.90000000000265,17.190712627057735,0.9517572189268421,-0.08603780459723742
228.00000000000267,17.223907004385556,0.9487306136678325,-0.08596828926408584
229.10000000000267,17.257510931915895,0.9517746024679032,-0.08596514846687509
230.2000000000027,17.29042381979517,0.9548124668537055,-0.08705212548308028
231.3000000000027,17.323461623501426,0.9556098593216774,-0.0872873627427575
232.4000000000027,17.35701007846252,0.9572209526582064,-0.08776879336299093
233.50000000000273,17.390614136914138,0.9580208196571699,-0.0886023501650306
234.60000000000275,17.423468487525877,0.9589657222873376,-0.08860013024030966
235.70000000000277,17.45672644632391,0.9611869294787646,-0.08860019590314439
236.8000000000028,17.489591360448802,0.9629645672809066,-0.08860025560317375
237.9000000000028,17.52219299049403,0.9638819436796969,-0.08857209672475941
239.0000000000028,17.55635626523764,0.9630099101985334,-0.0900813546974435
240.10000000000284,17.589502199842922,0.9663345933299462,-0.09191921603987963
241.20000000000283,17.622536952301257,0.9665366610037062,-0.09315790859809603
242.30000000000285,17.65581220640688,0.9669577541499256,-0.0945348910904058
243.40000000000288,17.688991472228587,0.9681580864127382,-0.09452972617509392
244.5000000000029,17.722415135232445,0.968941975536305,-0.09545436011777841
245.60000000000292,17.755641615964453,0.9694007359326342,-0.0958802292719092
246.70000000000292,17.788559136946905,0.9691565067128045,-0.0971678967408538
247.80000000000294,17.821716967781715,0.9699540137333241,-0.0971246059957771
248.90000000000296,17.854842441585443,0.9693743985250699,-0.09849508600600965
250.00000000000296,17.888129351221416,0.9716315843289544,-0.0984964401175299
251.10000000000298,17.921054457735583,0.9741079256008788,-0.09996265839883378
252.200000000003,17.954245296976925,0.9737118432348162,-0.10102653260380245
253.30000000000302,17.98683892044593,0.972847058360298,-0.10256297266998082
254.40000000000305,18.020926421508353,0.9711676181782812,-0.10401720040872409
255.50000000000304,18.05383834358634,0.9725699834826516,-0.10430007794711704
256.6000000000031,18.086721649100884,0.9720941372527914,-0.10433104105920687
257.7000000000031,18.119956118513937,0.9729389495006506,-0.10591974232927193
258.8000000000031,18.152920836105793,0.9733219110491012,-0.10928694651738446
259.9000000000031,18.18635541637191,0.9731642637431245,-0.1120526387923837
261.0000000000031,18.219618323779088,0.9735413198420948,-0.11357273921864497
262.10000000000315,18.252157920165754,0.9732005902139331,-0.11417381494844303
263.2000000000032,18.28572731991837,0.9732502928274072,-0.11538764398054768
264.30000000000314,18.318837598339307,0.9727595683962003,-0.11692084023417415
265.40000000000316,18.352033463762393,0.9733887125842968,-0.11933089895084947
266.5000000000032,18.384964505288487,0.9733960364702305,-0.12302579992076801
267.6000000000032,18.41775268210711,0.9714448340842513,-0.12502193930172956
268.70000000000323,18.450849428863314,0.9724706050925217,-0.12795928476524976
269.80000000000325,18.48438114553243,0.9721960098577334,-0.12972970815819806
270.9000000000033,18.51756234866476,0.9719557097117649,-0.13229694447647145
272.0000000000033,18.55048895031138,0.971601051111088,-0.1348940200403752
273.1000000000033,18.583785057815476,0.9699657745734399,-0.1370497221006448
274.20000000000334,18.616630723785978,0.9732823009373337,-0.14014020009887318
275.30000000000337,18.649859178533227,0.972249886172198,-0.14347924581464344
276.40000000000333,18.68311050535143,0.9713114150633437,-0.14736460461992396
277.50000000000335,18.715874986784875,0.9703195469447086,-0.15007678134764202
278.6000000000034,18.749290293552786,0.969899486331176,-0.1531740943426101
279.7000000000034,18.78246351794756,0.9706738129074792,-0.15629950050330788
280.8000000000034,18.815641499588963,0.970438760297966,-0.16028572757044435
281.9000000000034,18.84878030446697,0.9683977790372159,-0.164761617961783
283.0000000000034,18.88186685529739,0.9672584161542066,-0.16703912001645937
284.10000000000343,18.91523091150859,0.9684304190460155,-0.169205648896122
285.20000000000346,18.948288417852858,0.9673561180281859,-0.17532137060729047
286.3000000000035,18.981260678058238,0.9668931243417465,-0.1822115011686618
287.4000000000035,19.0145562925448,0.9686519674348063,-0.1860082113215471
288.5000000000035,19.04767218779557,0.969206929805279,-0.19085775642610336
289.60000000000355,19.080897416404717,0.9665309107006873,-0.19632944571564126
290.70000000000357,19.114392864944662,0.9656858386672555,-0.20314705382472997
291.8000000000036,19.147668577589585,0.9678255675306806,-0.20823707779946732
292.9000000000036,19.180661789751127,0.9651412655795284,-0.2138553246053867
294.0000000000036,19.213340473236485,0.9661182907892376,-0.22066512376985692
295.1000000000036,19.247179031147752,0.9637652295768064,-0.22686232004664664
296.2000000000036,19.280678731294056,0.9657720505098185,-0.23330410487279396
297.30000000000365,19.313854358064695,0.9670219728549678,-0.24008841815392845
298.4000000000037,19.347003066219447,0.9665828523501772,-0.24480769798707902
299.5000000000037,19.380277426191885,0.9653611219104306,-0.25236581641787703
300.60000000000366,19.4132870801772,0.9662246847194785,-0.26305784060953163
301.7000000000037,19.446663458159378,0.9660269877256116,-0.2726429463803046
302.8000000000037,19.480235963491374,0.9689263775643224,-0.2807081119778716
303.90000000000373,19.513292385389505,0.9674898861268952,-0.28905653079842786
305.00000000000375,19.54667994015902,0.9705974931953664,-0.29800832171556424
306.1000000000038,19.580100160475986,0.9707103635778602,-0.3074176905724699
307.2000000000038,19.61320626748181,0.972808669935613,-0.3172283174026611
308.3000000000038,19.64674312158519,0.9759405161145787,-0.3264759453096291
309.40000000000384,19.67973690691482,0.9789757993799041,-0.3365195778714005
310.5000000000038,19.71330351635505,0.9817210213028307,-0.3474159777298813
311.60000000000383,19.746717771461743,0.983274060139672,-0.36116054866827385
312.70000000000385,19.780028834019927,0.9864800587702721,-0.3725274738691917
313.8000000000039,19.813834931607783,0.9913757504219503,-0.38421783393162956
314.9000000000039,19.847350575182357,0.99383432411795,-0.397275793974349
316.0000000000039,19.880403921475015,0.9974205543879386,-0.4100943837401698
317.10000000000394,19.91416443135408,1.0016170947220218,-0.42358046342276
318.2000000000039,19.947425496575974,1.0074046380379733,-0.4375613565764409
319.30000000000393,19.980792988586632,1.0113631035161872,-0.4509120979673309
320.40000000000396,20.01419971714501,1.0165352831962284,-0.46479341543265074
321.500000000004,20.047449180910945,1.0202432155989238,-0.47954835985264577
322.600000000004,20.08116633385236,1.0260783988977447,-0.49474144238289997
323.700000000004,20.114767761785366,1.0316516443180708,-0.5121180716899478
324.80000000000405,20.14808571007007,1.0352081384492466,-0.5291346261323073
325.90000000000407,20.18112038989035,1.0411856053385895,-0.5449191134611895
327.0000000000041,20.21521478504464,1.0446275715170938,-0.5609508173476065
328.10000000000406,20.24859717525272,1.0508289687708494,-0.5773481501144255
329.2000000000041,20.282323788991132,1.058625456721635,-0.5961321783746603
330.3000000000041,20.315748218157808,1.0638991650898253,-0.6153431857231353
331.4000000000041,20.349477756925502,1.0717670807893263,-0.634069888256235
332.50000000000415,20.38278042843228,1.0781978017780265,-0.6521313209348585
333.6000000000042,20.416519780353845,1.0865634700921685,-0.6725161247221081
334.7000000000042,20.45046737692729,1.0935670756043492,-0.6932984000701468
335.80000000000416,20.48382484230699,1.100478829389671,-0.7139177138715778
336.9000000000042,20.517784152787648,1.1078129278473476,-0.7362396910246836
338.0000000000042,20.551441904887707,1.1134188940128653,-0.7598383027695186
339.10000000000423,20.58492790877773,1.1224247174513209,-0.783105083340927
340.20000000000425,20.618114981956502,1.129813203196366,-0.8050913064474234
341.3000000000043,20.652304286368242,1.1406297469016187,-0.8301467150334791
342.4000000000043,20.686039983559514,1.146693380089954,-0.85469951844604
343.5000000000043,20.719994969941713,1.1582764688684826,-0.8795527977532256
344.60000000000434,20.753339793405207,1.1703588858748863,-0.9062570589678987
345.7000000000043,20.787271273607338,1.1821210119094454,-0.9340153303374827
346.80000000000433,20.82113607649782,1.194986529121768,-0.960073633077454
347.90000000000435,20.854879601025406,1.2068636904635195,-0.9862848443705197
349.0000000000044,20.888736663369272,1.2169152274589883,-1.0155615207483222
350.1000000000044,20.922936311567728,1.2342275150138462,-1.0462776778053073
351.2000000000044,20.956575886549643,1.2481344050465084,-1.0774362394975423
352.30000000000445,20.99078758666997,1.263036309378889,-1.10924383103587
353.4000000000044,21.02457382877524,1.2810276820816835,-1.139982089539258
354.50000000000443,21.0586996747785,1.2959998762461993,-1.1715082459981514
355.60000000000446,21.092595719741567,1.3169369564636302,-1.2052715754552192
356.7000000000045,21.126627011037296,1.3368055974503548,-1.239815717324524
357.8000000000045,21.160604627622497,1.3542388510378482,-1.2750682055964795
358.9000000000045,21.194433152367964,1.3756602275146503,-1.3123573960391997
360.00000000000455,21.228551118496142,1.393997121935085,-1.350506675801805
361.10000000000457,21.262984939135354,1.417627038647336,-1.3878991870960027
362.2000000000046,21.297081010421,1.4366575769936096,-1.4253887296884553
363.30000000000456,21.330959849897443,1.4583781196803522,-1.4640660271572061
364.4000000000046,21.365107703046643,1.4805278008034901,-1.5048669648791524
365.5000000000046,21.399472935141695,1.5016006936191553,-1.547930378150114
366.6000000000046,21.43351184156261,1.5224868112083882,-1.5917618511545784
367.70000000000465,21.467802041715636,1.5394510128169892,-1.6359243457944102
368.8000000000047,21.50166075784496,1.5565040215379868,-1.679611528031808
369.9000000000047,21.53576307677734,1.5728088218007628,-1.7240642162683564
371.00000000000466,21.569853709613124,1.5811744951374183,-1.769605333589538
372.1000000000047,21.603934328761248,1.5904750846911748,-1.8150480815841545
373.2000000000047,21.638102147155042,1.5964380816889285,-1.8631399576473386
374.30000000000473,21.671709308598842,1.5965662636340094,-1.9124439724156992
375.40000000000475,21.706055539994246,1.589973427394804,-1.9612772078410665
376.5000000000048,21.739905879286106,1.5763052971769147,-2.0058712770162126
377.6000000000048,21.7737125308148,1.5563254566380482,-2.0525601161108256
378.7000000000048,21.807251059103123,1.5299419213576466,-2.098792800166599
379.80000000000484,21.840854875312935,1.4964889229487859,-2.145110497716916
380.9000000000048,21.874499866175604,1.4509968056690523,-2.1914382181051453
382.00000000000483,21.907863976084375,1.4036647739044403,-2.236364368868262
383.10000000000485,21.941598065538184,1.3441777383649551,-2.2774663719705193
384.2000000000049,21.974891385225035,1.282198539695278,-2.316376993488829
385.3000000000049,22.008008672388307,1.213088012907908,-2.3529739502884013
386.4000000000049,22.041345545356766,1.1387761227069446,-2.3884246926530883
387.50000000000495,22.073853337910162,1.0655359858003108,-2.420725277717561
388.6000000000049,22.10700756217823,0.9878645622945565,-2.451260558933175
389.70000000000493,22.14032166128892,0.9134486630285836,-2.4785541128195265
390.80000000000496,22.173732688702525,0.8380178694884621,-2.5054260806838564
391.900000000005,22.206916437323613,0.7631041111119693,-2.5283344548844218
393.000000000005,22.240127380118153,0.6945832326638935,-2.5501948657401368
394.100000000005,22.273754660288514,0.6274114569509159,-2.5696186506425978
395.20000000000505,22.307066760250045,0.5646993285377211,-2.5862382897475387
396.30000000000507,22.340320019728097,0.5002853600569291,-2.5999112671442632
397.4000000000051,22.373559385965926,0.4434738598892991,-2.613496685769509
398.50000000000506,22.407285228954084,0.38847286418917915,-2.6265686702804008
399.6000000000051,22.44069750155647,0.3345560339373328,-2.637823575967528
400.7000000000051,22.474285028617263,0.2840280305399211,-2.6473392453074567
401.8000000000051,22.507829408023746,0.2412406926137607,-2.654799257065037
402.90000000000515,22.541442448027365,0.19768581728310708,-2.662602253810821
404.0000000000052,22.575357426224034,0.1615739064988897,-2.6701163097713874
405.1000000000052,22.608901264167883,0.12728436221801742,-2.675933600081387
406.20000000000516,22.642607992131687,0.09697726821286112,-2.6802969404202344
407.3000000000052,22.676593627585422,0.07104735788411598,-2.6860151125847747
408.4000000000052,22.710754400861067,0.04775283716728218,-2.689987335942113
409.50000000000523,22.744236172673123,0.030277006175546406,-2.6939161278308474
410.60000000000525,22.778072472432832,0.009901689263779767,-2.697926505392131
411.7000000000053,22.812345685359144,-0.007782485031192943,-2.7010055771971007
412.8000000000053,22.8469972685538,-0.018509814640574107,-2.7041229252560663
413.9000000000053,22.88084823946773,-0.032260537963770264,-2.7072361449159943
415.00000000000534,22.915216287903593,-0.04256234267576564,-2.7098507727934567
416.1000000000053,22.94926370506504,-0.053889451982830794,-2.713651708118134
417.20000000000533,22.983679332259193,-0.06303527857012448,-2.7172931525186264
418.30000000000535,23.01806773682288,-0.07260897638130559,-2.720533444020286
419.4000000000054,23.052170748075934,-0.08170126958764945,-2.724082770136337
420.5000000000054,23.08662179260952,-0.08853063439463205,-2.7271397559894583
421.6000000000054,23.12090948640166,-0.09822943308170451,-2.730265910006378
422.70000000000545,23.15480265493731,-0.10650339608540016,-2.7333766756498328
423.8000000000054,23.189785949426096,-0.11121771967735228,-2.7372889186880913
424.90000000000543,23.223956290022688,-0.11649304024170548,-2.7405918236914015
426.00000000000546,23.258696613139648,-0.1228037682904618,-2.74453693634706
427.1000000000055,23.293017831280316,-0.12859651134415873,-2.7469462497103594
428.2000000000055,23.3272994041349,-0.13593159780320596,-2.74836895963918
429.3000000000055,23.361746129879375,-0.13936037009944702,-2.7513270127751177
430.40000000000555,23.396117061622014,-0.14580930222422506,-2.7548659131829822
431.50000000000557,23.429844184097355,-0.14962694864167936,-2.7583758178989535
432.6000000000056,23.46506359707484,-0.15523792785085722,-2.7613055724578297
433.70000000000556,23.499828269163768,-0.1592932763092484,-2.7640974712707047
434.8000000000056,23.534268984263495,-0.16296765439881278,-2.767928766063696
435.9000000000056,23.5688179822912,-0.1680602732860449,-2.7707668762611792
437.0000000000056,23.603223434703565,-0.16942945685895916,-2.771818214990879
438.10000000000565,23.637846723706634,-0.17274575529933012,-2.7744105061478166
439.2000000000057,23.672323836350596,-0.17345539055232095,-2.778735799066731
440.3000000000057,23.707085533328623,-0.17450017608595547,-2.7809097172848993
441.40000000000566,23.74185466855393,-0.17927024158148408,-2.7844484075689384
442.5000000000057,23.776314751774603,-0.1772832838231776,-2.7876806967278287
443.6000000000057,23.81088521294137,-0.18001363597945952,-2.7909055816457418
444.70000000000573,23.845622189433787,-0.17907023777524245,-2.7937842546775693
445.80000000000575,23.88015490403394,-0.179499075987952,-2.7956053271933587
446.9000000000058,23.915272595219786,-0.1827531437413611,-2.7991619849623133
448.0000000000058,23.9497989560734,-0.18070915455765912,-2.80216457375856
449.1000000000058,23.984564640858252,-0.1794851592823984,-2.8046740533263717
450.20000000000584,24.01926674310592,-0.17907441504584276,-2.8079421936578335
451.3000000000058,24.054093656671068,-0.17870226053477833,-2.8102069534943945
452.40000000000583,24.088876478538857,-0.1731566535537148,-2.812283223588927
453.50000000000585,24.12387000928665,-0.17540005191339558,-2.8149024538141263
454.6000000000059,24.158501600423655,-0.17161225423033732,-2.8176351643354716
455.7000000000059,24.19345942056472,-0.16840406607609026,-2.8189987510073387
456.8000000000059,24.22812207816141,-0.1669301965716221,-2.8218921126458527
457.90000000000595,24.263315540900873,-0.1634851646680595,-2.824075924665819
459.0000000000059,24.298086374867374,-0.16136798979737055,-2.826787398873586
460.10000000000593,24.33307089027377,-0.15719602462105375,-2.829433409397545
461.20000000000596,24.367478806409466,-0.15279534297020092,-2.832004662445116
462.300000000006,24.40288241514073,-0.15111150906666881,-2.83450686252345
463.400000000006,24.43820474228756,-0.14730051821278378,-2.8362148837306975
464.500000000006,24.47292258584336,-0.14168860691364737,-2.83924960192721
465.60000000000605,24.50792583908702,-0.13955334990050416,-2.841644072661606
466.70000000000607,24.543067487016224,-0.13673793313882432,-2.8447422700465106
467.8000000000061,24.578000838961323,-0.1336891833919478,-2.847097223213418
468.90000000000606,24.612975736057326,-0.12797422583293083,-2.8499266978057145
470.0000000000061,24.648122586857422,-0.12332921442334421,-2.8516700982269074
471.1000000000061,24.683071557118687,-0.11992849657299454,-2.8519002759903485
472.2000000000061,24.718047346557952,-0.11546425687031969,-2.8528374875854237
473.30000000000615,24.753357054472154,-0.112012614780016,-2.8553059738198074
474.4000000000062,24.788515772876295,-0.10692443407375807,-2.859103599079978
475.5000000000062,24.823504402076576,-0.10403914403264336,-2.8617329269546894
476.60000000000616,24.85859303209847,-0.10038335872170912,-2.8633428562303243
477.7000000000062,24.893730220908424,-0.09721465757850178,-2.8660179840553974
478.8000000000062,24.92907521397563,-0.09473209302546626,-2.8686386020526258
479.90000000000623,24.96398831071717,-0.09391269721866058,-2.870065095779957
481.00000000000625,24.999401015253884,-0.0893752115531612,-2.8729320879091507
482.1000000000063,25.034398599131254,-0.08632102340839154,-2.874197499727812
483.2000000000063,25.069808160120086,-0.08576667121389336,-2.874839819529372
484.3000000000063,25.105131497565786,-0.08031098029568717,-2.8761778585710744
485.40000000000634,25.13999538529426,-0.07513080682630102,-2.8785969645336738
486.5000000000063,25.175614349276103,-0.07720408662225897,-2.8806237724014077
487.60000000000633,25.210687767052914,-0.07245243096920873,-2.881827428646784
488.70000000000636,25.246181578139026,-0.06902838705635861,-2.8833781654402704
489.8000000000064,25.281189765573167,-0.06855637662214797,-2.885039501709103
490.9000000000064,25.316332353143128,-0.06648178148593575,-2.886831303296412
492.0000000000064,25.351725241605628,-0.06324729945224372,-2.8886524262165434
493.10000000000645,25.387004208182336,-0.06489295587361021,-2.891246111895602
494.2000000000064,25.422210332312602,-0.05862698272320488,-2.8930066329829147
495.30000000000643,25.457580862268756,-0.06017813003231254,-2.8938221964963793
496.40000000000646,25.492708779562772,-0.059215621861659296,-2.8959340389524093
497.5000000000065,25.52813863938892,-0.056914444286869426,-2.8975755042578903
498.6000000000065,25.563294950855365,-0.05612368632107434,-2.8983935413363624
499.7000000000065,25.59910594403648,-0.05882118226713917,-2.898276528130725
500.80000000000655,25.634063806286157,-0.05528045636174794,-2.89973577284922
501.90000000000657,25.669463887800493,-0.05295225177806073,-2.9016077984145587
503.0000000000066,25.704951887062734,-0.05297796049254888,-2.9029973377722684
504.10000000000656,25.74027179642571,-0.05315381334111846,-2.9044384309980114
505.2000000000066,25.77523659052371,-0.05409231230474831,-2.9065128132855778
506.3000000000066,25.811330223209165,-0.05180923623615197,-2.9073845660723716
507.4000000000066,25.846246978863835,-0.05143359554428928,-2.9085619519192907
508.50000000000665,25.881731639097758,-0.0501976186986659,-2.911463357125706
509.6000000000067,25.917161459722454,-0.04708847988780396,-2.912745666105724
510.7000000000067,25.952861565810927,-0.04833147942420024,-2.9140113635367166
511.80000000000666,25.987917188323657,-0.05135135237706634,-2.9152477357161386
512.9000000000067,26.023487933582917,-0.04601756365862841,-2.9160532959531302
514.0000000000067,26.058816778630035,-0.04597305277707786,-2.9167874460104866
515.1000000000067,26.09423036929836,-0.04948006936533966,-2.9184084622750817
516.2000000000068,26.129466828331676,-0.05004714555150702,-2.9201142987541306
517.3000000000068,26.16457081754806,-0.052159453545955525,-2.9226496153808204
518.4000000000068,26.200502007216503,-0.04706031984674319,-2.9240534889099905
519.5000000000068,26.236143419942685,-0.04713442439104365,-2.9256301215963774
520.6000000000068,26.27139284518956,-0.046922500568820524,-2.9256235709951914
521.7000000000069,26.305817095294138,-0.04600632958105377,-2.9278579683181567
522.8000000000068,26.34225122616811,-0.04770595529540356,-2.930211062972093
523.9000000000069,26.377810725342528,-0.04798034567025233,-2.931073919168747
525.0000000000068,26.4131949700546,-0.04835920577608133,-2.932451521502607
526.100000000007,26.448594190378515,-0.04929430539659996,-2.933371258577219
527.2000000000069,26.48418398265435,-0.0516556414935192,-2.9347831032887055
528.300000000007,26.519770430866448,-0.049333112420318015,-2.9358313652589296
529.4000000000069,26.55512863444429,-0.052710554616012706,-2.9357281389757337
530.5000000000069,26.59098857565499,-0.05128848149304477,-2.9368168067860063
531.600000000007,26.626606922756505,-0.05173061185055117,-2.9371833108989773
532.700000000007,26.661923572227064,-0.05248802635211458,-2.938628302189412
533.800000000007,26.697576923648832,-0.04788745729273747,-2.9394087683543404
534.900000000007,26.73332762494541,-0.043677283095245656,-2.9402307232805986
536.000000000007,26.76848618753147,-0.0468960893050514,-2.942354821726378
537.1000000000071,26.80422906465642,-0.04524014896083606,-2.944616227184367
538.2000000000071,26.839774687892152,-0.042441225801622684,-2.9447097852965345
539.300000000007,26.875612406545006,-0.04047020216751673,-2.9460478330511117
540.4000000000071,26.910892100426096,-0.04030301404140468,-2.9474293176548194
541.500000000007,26.94618226378987,-0.035108360619498624,-2.9477651087401853
542.6000000000072,26.98240772939574,-0.036256433605101,-2.949049000014147
543.7000000000071,27.017853597322894,-0.032579165150759426,-2.9501085851056033
544.8000000000072,27.053661341344796,-0.029494942918802725,-2.9514717404560704
545.9000000000071,27.089073128374004,-0.030976789221027756,-2.9514215349804824
547.0000000000072,27.125092859667454,-0.02945072861429443,-2.952771001526285
548.1000000000072,27.160349598787448,-0.027284488171186894,-2.9540526659267274
549.2000000000072,27.196219066825932,-0.022594753898392383,-2.9540717201488187
550.3000000000072,27.232144367785512,-0.025162249142166804,-2.9553940532547367
551.4000000000073,27.267597803019097,-0.02362504320729908,-2.956741882482995
552.5000000000073,27.303144626555746,-0.022901901558280313,-2.95671953459214
553.6000000000073,27.339202829730937,-0.020414284496857116,-2.9575170988713113
554.7000000000073,27.374841804702193,-0.020212927834011518,-2.9594339575004254
555.8000000000073,27.410607622649533,-0.022223481388062627,-2.9598925306557575
556.9000000000074,27.446445714125286,-0.022057101776768118,-2.9608847311272335
558.0000000000074,27.48209386967479,-0.019472138410010054,-2.962950521300086
559.1000000000074,27.518052162863864,-0.021292747138414336,-2.963725056222013
560.2000000000073,27.553501468751495,-0.02011539404158902,-2.9650377867609894
561.3000000000073,27.589497852338198,-0.017979321820909888,-2.965037870084178
562.4000000000074,27.62517134054163,-0.01533165378696899,-2.964861944982899
563.5000000000074,27.66078648115384,-0.01571820290134207,-2.9651026411068675
564.6000000000074,27.69685637810938,-0.018026463542468285,-2.96637552627589
565.7000000000074,27.732884401633296,-0.018024637614840078,-2.9676803692769615
566.8000000000075,27.76842376622933,-0.020168386486985268,-2.968942859460469
567.9000000000075,27.804246322424262,-0.019576624873872905,-2.9698165219335007
569.0000000000075,27.84013356864348,-0.020085463529133207,-2.9716276355620037
570.1000000000075,27.8764949755398,-0.02283934101311136,-2.9728185941367093
571.2000000000075,27.912218197734052,-0.021889852502460894,-2.9735690980631784
572.3000000000076,27.947541406352983,-0.022992189203987046,-2.974249644231862
573.4000000000076,27.983790484137348,-0.026960659836285927,-2.975275363425816
574.5000000000076,28.019744800740188,-0.025097734697871132,-2.975573656077996
575.6000000000076,28.05567081500153,-0.03012817594019901,-2.975478829802154
576.7000000000077,28.091536191910112,-0.03268670997259426,-2.9771074160188986
577.8000000000077,28.127663200881106,-0.03243361325677907,-2.978370412679147
578.9000000000076,28.16335338031196,-0.029879772499118662,-2.9784257560929572
580.0000000000076,28.19956064575761,-0.03396011757731876,-2.9791228248917614
581.1000000000076,28.23583056562255,-0.035395005763005694,-2.979754150470907
582.2000000000077,28.27162639147153,-0.037526635460234825,-2.981155186950465
583.3000000000077,28.30764203685665,-0.037912445921845395,-2.9810643292750885
584.4000000000077,28.34353678784383,-0.04246497272225014,-2.9823664601427513
585.5000000000077,28.37982448801718,-0.0424462376535224,-2.9837193029054707
586.6000000000078,28.41589928283507,-0.04602702360765143,-2.983692480757637
587.7000000000078,28.45177305693335,-0.04498556375983287,-2.9848632754322093
588.8000000000078,28.487693190277998,-0.04509222904189092,-2.9850211725992306
589.9000000000078,28.523845547996952,-0.048341167093619575,-2.986433613658394
591.0000000000078,28.55977434893662,-0.046480551807106085,-2.987679075158414
592.1000000000079,28.59604576240612,-0.05262125645962934,-2.987780633901987
593.2000000000079,28.632289529854663,-0.050507205079039386,-2.988976222450389
594.3000000000079,28.66811323530919,-0.050448843137072874,-2.9889663475834096
595.4000000000078,28.704491491897354,-0.05448806983925647,-2.9902280231587186
596.5000000000078,28.740734970172564,-0.05074038385752089,-2.9902823191929873
597.6000000000079,28.776673820163197,-0.05407973271246158,-2.9893794206004127
598.7000000000079,28.81302731434006,-0.056415185866120154,-2.99029509810258
599.8000000000079,28.84889842533262,-0.061275699426308616,-2.991607050396218
600.9000000000079,28.8851271864779,-0.058284027043782105,-2.992916316647677
602.000000000008,28.921286237557204,-0.05930374054656706,-2.994217762971552
603.100000000008,28.957416241348056,-0.06246730017674862,-2.994753329998269
604.200000000008,28.993782087477857,-0.06317005511352036,-2.9955579937889403
605.300000000008,29.029849362722164,-0.06312434403050027,-2.996603721074421
606.400000000008,29.06605193043127,-0.0655268054403031,-2.9968799183045265
607.5000000000081,29.10216157004881,-0.06276258966876291,-2.9968235644583285
608.6000000000081,29.138356186217536,-0.0624020953731077,-2.9983080054341715
609.7000000000081,29.17445096044043,-0.06298077332519147,-2.9987830983832593
610.8000000000081,29.211069850091015,-0.06884739489654623,-2.998436389988419
611.9000000000082,29.246353995778147,-0.0704357207006654,-2.9996181696173605
613.0000000000082,29.28271726652806,-0.06972024444922331,-2.9995781613786194
614.1000000000081,29.319962699654127,-0.0708154428991441,-3.0009345294514773
615.2000000000081,29.35589500066437,-0.0715965833701071,-3.0009541845541525
616.3000000000081,29.392721801207568,-0.06777082675140567,-3.002301193774669
617.4000000000082,29.42794596852509,-0.06932103662237021,-3.0028065202078107
618.5000000000082,29.46521451671133,-0.06606577396279079,-3.0035728672777715
619.6000000000082,29.501395100863494,-0.06621235255657587,-3.0041180463746113
620.7000000000082,29.53775096382705,-0.06651037143706895,-3.004887300648338
621.8000000000083,29.574057989055397,-0.06717048770368006,-3.006136813729238
622.9000000000083,29.610641926652026,-0.061869842660766006,-3.0066616172517455
624.0000000000083,29.646695345164677,-0.06197101454649734,-3.007524719304059
625.1000000000083,29.683105230567147,-0.06179907901562798,-3.007846730245734
626.2000000000083,29.719683126775926,-0.05925605958770719,-3.008522571179072
627.3000000000084,29.756202972970776,-0.053600045534835106,-3.008177494594536
628.4000000000084,29.792357865519715,-0.05408875270779734,-3.0081813873347842
629.5000000000084,29.828717157248082,-0.052944777178091984,-3.009473052625882
630.6000000000083,29.86556668784516,-0.05128356220123664,-3.0094919648212417
631.7000000000083,29.9015608417626,-0.04932605324538075,-3.0106464753379956
632.8000000000084,29.937898888379905,-0.04840626464176978,-3.010804901636002
633.9000000000084,29.974558723335484,-0.048271569593101527,-3.0115299340412065
635.0000000000084,30.010549818257456,-0.04903906122214696,-3.0114682091675484
636.1000000000084,30.04709258351983,-0.04569602862798394,-3.0121175859722493
637.2000000000085,30.084049362246684,-0.04413285999125982,-3.0121318151494645
638.3000000000085,30.1202014448968,-0.03977943099599224,-3.0121980989270165
639.4000000000085,30.156950907060867,-0.03867049374844944,-3.013547619179144
640.5000000000085,30.19325298288554,-0.03573812544345767,-3.0138652268546133
641.6000000000085,30.229542712225456,-0.03159764787225061,-3.0142114760451486
642.7000000000086,30.266221820384363,-0.03149737551787313,-3.0154116170168836
643.8000000000086,30.3024026355536,-0.029950100687047287,-3.0168503367372663
644.9000000000086,30.339431851639507,-0.02361058789350534,-3.0168658990832604
646.0000000000086,30.37573636811721,-0.02432537519818667,-3.018168410155612
647.1000000000087,30.412340979670052,-0.020259487069401505,-3.0188156793769427
648.2000000000087,30.448640010286297,-0.013876336723291027,-3.0194923375933653
649.3000000000086,30.485196961458495,-0.010089337253460506,-3.019430833037518
650.4000000000086,30.521515504907633,-0.00520221943928223,-3.0196628041744003
651.5000000000086,30.558350216591297,-0.0037158464543727288,-3.0207998027946386
652.6000000000087,30.594858271368697,0.0005565523516768422,-3.0207575581739032
653.7000000000087,30.63135356780572,0.0019435840844872487,-3.0221073073735036
654.8000000000087,30.668040031069104,0.004382612795706509,-3.022105708090604
655.9000000000087,30.70429066003464,0.01616269675518822,-3.0227923236047953
657.0000000000088,30.74090645097758,0.026884737745444198,-3.023421427275364
658.1000000000088,30.77757629943156,0.03186128312937608,-3.0232898509902286
659.2000000000088,30.8140486116839,0.038720912855445766,-3.0234028712796146
660.3000000000088,30.85095058713533,0.04467305589523152,-3.026078688279906
661.4000000000088,30.88680035768691,0.05239534523576861,-3.0260619446594985
662.5000000000089,30.923686372270463,0.05851665604116585,-3.0273876891634113
663.6000000000089,30.960320276641962,0.06503886471403542,-3.0287135993268235
664.7000000000089,30.997180440456486,0.07374608380932202,-3.0289109684316333
665.8000000000088,31.033635747582547,0.07799779938654261,-3.0287349294810766
666.9000000000088,31.070209328138162,0.0866538728230779,-3.02945626663116
668.0000000000089,31.106782059490634,0.09405901806515216,-3.0299840361730968
669.1000000000089,31.143185352553235,0.10153034484798207,-3.031338038704444
670.2000000000089,31.18009624561642,0.10468273223426694,-3.0314122723388977
671.3000000000089,31.216848987047566,0.11740929381898146,-3.0326691642984347
672.400000000009,31.2536702992727,0.1257571887075759,-3.032723062088597
673.500000000009,31.29010251028537,0.1313154440094113,-3.033981900834487
674.600000000009,31.326520009955473,0.13633322513735546,-3.0347087136767517
675.700000000009,31.363604382324123,0.14488084788616717,-3.0353758679373355
676.800000000009,31.40029802514128,0.1515702351702033,-3.0352738407485127
677.9000000000091,31.43695213500552,0.158430283309142,-3.036758370866658
679.0000000000091,31.47351636874228,0.161020292752164,-3.0382023077813374
680.1000000000091,31.510063402508457,0.1663220511235024,-3.039208727039901
681.2000000000091,31.54692661801075,0.1740584275359831,-3.039463345052035
682.3000000000092,31.583533652602743,0.1761797449346787,-3.0407588883827588
683.4000000000092,31.620184980043415,0.17986475015899073,-3.041850250550444
684.5000000000091,31.656720575888553,0.18275366567903983,-3.0421022324726072
685.6000000000091,31.69323978986058,0.18635798395625702,-3.0435096936253005
686.7000000000091,31.73004979623272,0.18368957658412688,-3.04447844321087
687.8000000000092,31.76663407305432,0.1831499159417076,-3.045948508638425
688.9000000000092,31.803166849160274,0.1790209965720595,-3.046202102499848
690.0000000000092,31.839858626594413,0.17486398740259634,-3.047482334971354
691.1000000000092,31.876821375953742,0.17110031129772496,-3.04747416367911
692.2000000000093,31.912917158903667,0.16423814178153862,-3.0486789073885423
693.3000000000093,31.949984150878752,0.15548037567870132,-3.049533928846535
694.4000000000093,31.986338205942342,0.14313999737542016,-3.05092854480075
695.5000000000093,32.02315118280074,0.13283892413695852,-3.0523916804649764
696.6000000000093,32.059646094867745,0.12473092980470346,-3.0521357265666764
697.7000000000094,32.09618670485698,0.10820637716107617,-3.053332781185522
698.8000000000094,32.13300149069729,0.09858824753132023,-3.0533205972096997
699.9000000000094,32.16939803451203,0.08358872471858048,-3.0546205285540795
701.0000000000093,32.20606136926997,0.06663417329588173,-3.0550228003510034
702.1000000000093,32.242951947715106,0.04750193577017292,-3.055933935990224
703.2000000000094,32.2794999650486,0.0338338923650654,-3.055931346085594
704.3000000000094,32.315883539626626,0.013204448134975788,-3.0572240155144184
705.4000000000094,32.35270750275093,-0.008377268358608969,-3.057250138836528
706.5000000000094,32.38927259270635,-0.01612987834382329,-3.057243612042545
707.6000000000095,32.426061363517135,-0.024130663119457996,-3.0581125263782925
708.7000000000095,32.4628219609018,-0.01985295136649512,-3.0582670694024032
709.8000000000095,32.499672395594786,-0.024468935876438724,-3.0582375378104687
710.9000000000095,32.53636763518485,-0.02974834330263576,-3.058233416328202
712.0000000000095,32.57262794364454,-0.031044934252202783,-3.0594298343633644
713.1000000000096,32.60976710493953,-0.03383722923282351,-3.0595497795578446
714.2000000000096,32.64669521807673,-0.034562380717886754,-3.0595515494867738
715.3000000000096,32.68338058947416,-0.03186515172803528,-3.0599300350644465
716.4000000000096,32.72038420428771,-0.031299457699867084,-3.060870379261104
717.5000000000097,32.75741955920984,-0.031159986694625275,-3.060869767380346
718.6000000000097,32.79418517417496,-0.032320329027307526,-3.060779417820813
719.7000000000096,32.830837562496036,-0.02638173272338662,-3.0621885277067733
720.8000000000096,32.86800314045656,-0.029527170964224858,-3.0621874230687727
721.9000000000096,32.904186261394464,-0.02683662106772733,-3.0631557354427503
723.0000000000097,32.94173868237304,-0.029223850097037207,-3.062208730233278
724.1000000000097,32.97841960316622,-0.028189711925754146,-3.0634836543372117
725.2000000000097,33.01509681354939,-0.03111790234782852,-3.063509023367775
726.3000000000097,33.05236081265851,-0.02818360012860932,-3.0635098291509157
727.4000000000098,33.08867530248528,-0.03138593835516845,-3.0635098249919652
728.5000000000098,33.12632133664584,-0.0297577591475231,-3.0635033755648156
729.6000000000098,33.16291351892334,-0.03146990431269536,-3.0647168664536846
730.7000000000098,33.2000335252803,-0.02745308062557994,-3.0648299595842694
731.8000000000098,33.23700844969809,-0.02749734024422823,-3.0650120638073033
732.9000000000099,33.273689397017456,-0.0306071182237182,-3.066150540423877
734.0000000000099,33.310384534916345,-0.02642849087846022,-3.0672276650852526
735.1000000000099,33.34740901726632,-0.026918180368450617,-3.0674701414319765
736.2000000000098,33.38368954884886,-0.027084613310013772,-3.0674699049268117
737.3000000000098,33.42149880952504,-0.028202190612986566,-3.067473843512037
738.4000000000099,33.45865249274613,-0.024973430905582905,-3.0667498419797936
739.5000000000099,33.495326626052275,-0.027275599088916636,-3.0681569788805283
740.6000000000099,33.532536320887864,-0.02731263998743705,-3.0677787106594403
741.7000000000099,33.56930575931504,-0.028330563850919255,-3.06778787283063
742.80000000001,33.60640226126063,-0.02873352775545346,-3.069086589802749
743.90000000001,33.64270768746142,-0.031596736006079595,-3.0687798537872193
744.00000000001,33.6459894001263,-0.0317674512489976,-3.0687809471580256